Workbook

Sheet 29.07 Kisaasi-Ntinda
B1: Consultancy services for Preparation of Expressway Development Master Plan (EDMP) for Uganda
B2: MANUAL CLASSIFIED COUNT (MCC)
B3: ROAD NAME: | C3: MCC - C1 - STN33 - NTINDA ROAD
C5: Date | D5: 29.07.19 | F5: Location | G5: Ndere Center | J5: Surveyor | K5: Omaset Jerome& Jonathan
C6: Dir. From | D6: Kisaasi | F6: Dir. To | G6: Ntinda | J6: Supervisor | K6: Steven
B8: Time / Veh Type | R8: SUMMARY TRAFFIC VOLUMES
C9: 1. Car | D9: 2. Station Wagon | E9: 3. Pickups | F9: 4. Minibus, matatu | G9: 5. Medium bus | H9: 6. Large Bus | I9: 7. Light Truck | J9: 8. Medium Truck | K9: 9. Heavy truck | L9: 10. Truck Trailer | M9: 11. Motor cycles | N9: 12. Tractors | O9: Total Excl M/Cycles | P9: Total All | R9: Time | S9: 1. Car | T9: 2. Station Wagon | U9: 3. Pickups | V9: 4. Minibus, matatu | W9: 5. Medium bus | X9: 6. Large Bus | Y9: 7. Light Truck | Z9: 8. Medium Truck | AA9: 9. Heavy truck | AB9: 10. Truck Trailer | AC9: 11. Motorcycles | AD9: 12. Tractors, Graders | AE9: Total Excl M/ Cycles | AF9: Total All
B10: 07.00 - 07.15 | C10: 140 | D10: 80 | E10: 16 | F10: 26 | G10: 0 | H10: 0 | I10: 2 | J10: 1 | K10: 0 | L10: 2 | M10: 100 | N10: 0 | O10: =SUM(C10:L10,N10) -> 267 | P10: =SUM(C10:N10) -> 367 | R10: 0700-0800 | S10: =SUM(C10:C13) -> 580 | T10: =SUM(D10:D13) -> 248 | U10: =SUM(E10:E13) -> 48 | V10: =SUM(F10:F13) -> 83 | W10: =SUM(G10:G13) -> 0 | X10: =SUM(H10:H13) -> 0 | Y10: =SUM(I10:I13) -> 12 | Z10: =SUM(J10:J13) -> 1 | ... AF10: =SUM(P10:P13) -> 1338
B11: 07.15 - 07.30 | C11: 145 | D11: 60 | E11: 7 | F11: 23 | G11: 0 | H11: 0 | I11: 4 | J11: 0 | K11: 0 | L11: 0 | M11: 95 | N11: 0 | O11: =SUM(C11:L11,N11) -> 239 | P11: =SUM(C11:N11) -> 334 | R11: 0800-0900 | S11: =SUM(C14:C17) -> 273 | T11: =SUM(D14:D17) -> 163 | U11: =SUM(E14:E17) -> 40 | V11: =SUM(F14:F17) -> 60 | W11: =SUM(G14:G17) -> 3 | X11: =SUM(H14:H17) -> 0 | Y11: =SUM(I14:I17) -> 10 | Z11: =SUM(J14:J17) -> 4 | ... AF11: =SUM(P14:P17) -> 1409
B12: 07.30 - 07.45 | C12: 160 | D12: 60 | E12: 7 | F12: 23 | G12: 0 | H12: 0 | I12: 4 | J12: 0 | K12: 0 | L12: 0 | M12: 105 | N12: 0 | O12: =SUM(C12:L12,N12) -> 254 | P12: =SUM(C12:N12) -> 359 | R12: 0900-1000 | S12: =SUM(C18:C21) -> 211 | T12: =SUM(D18:D21) -> 112 | U12: =SUM(E18:E21) -> 34 | V12: =SUM(F18:F21) -> 46 | W12: =SUM(G18:G21) -> 0 | X12: =SUM(H18:H21) -> 0 | Y12: =SUM(I18:I21) -> 9 | Z12: =SUM(J18:J21) -> 2 | ... AF12: =SUM(P18:P21) -> 1035
B13: 07.45 - 08.00 | C13: 135 | D13: 48 | E13: 18 | F13: 11 | G13: 0 | H13: 0 | I13: 2 | J13: 0 | K13: 0 | L13: 0 | M13: 64 | N13: 0 | O13: =SUM(C13:L13,N13) -> 214 | P13: =SUM(C13:N13) -> 278 | R13: 1000-1100 | S13: =SUM(C22:C25) -> 192 | T13: =SUM(D22:D25) -> 74 | U13: =SUM(E22:E25) -> 26 | V13: =SUM(F22:F25) -> 40 | W13: =SUM(G22:G25) -> 0 | X13: =SUM(H22:H25) -> 0 | Y13: =SUM(I22:I25) -> 11 | Z13: =SUM(J22:J25) -> 7 | ... AF13: =SUM(P22:P25) -> 665
B14: 08.00 - 08.15 | C14: 80 | D14: 52 | E14: 10 | F14: 19 | G14: 1 | H14: 0 | I14: 3 | J14: 2 | K14: 1 | L14: 2 | M14: 185 | N14: 0 | O14: =SUM(C14:L14,N14) -> 170 | P14: =SUM(C14:N14) -> 355 | R14: 1100-1200 | S14: =SUM(C26:C29) -> 170 | T14: =SUM(D26:D29) -> 78 | U14: =SUM(E26:E29) -> 16 | V14: =SUM(F26:F29) -> 35 | W14: =SUM(G26:G29) -> 0 | X14: =SUM(H26:H29) -> 0 | Y14: =SUM(I26:I29) -> 8 | Z14: =SUM(J26:J29) -> 8 | ... AF14: =SUM(P26:P29) -> 773
B15: 08.15 - 08.30 | C15: 81 | D15: 49 | E15: 10 | F15: 15 | G15: 2 | H15: 0 | I15: 1 | J15: 1 | K15: 0 | L15: 0 | M15: 220 | N15: 0 | O15: =SUM(C15:L15,N15) -> 159 | P15: =SUM(C15:N15) -> 379 | R15: 1200-1300 | S15: =SUM(C30:C33) -> 169 | T15: =SUM(D30:D33) -> 65 | U15: =SUM(E30:E33) -> 19 | V15: =SUM(F30:F33) -> 30 | W15: =SUM(G30:G33) -> 0 | X15: =SUM(H30:H33) -> 0 | Y15: =SUM(I30:I33) -> 13 | Z15: =SUM(J30:J33) -> 8 | ... AF15: =SUM(P30:P33) -> 687
B16: 08.30 - 08.45 | C16: 60 | D16: 31 | E16: 13 | F16: 12 | G16: 0 | H16: 0 | I16: 3 | J16: 0 | K16: 0 | L16: 0 | M16: 255 | N16: 0 | O16: =SUM(C16:L16,N16) -> 119 | P16: =SUM(C16:N16) -> 374 | R16: 1300-1400 | S16: =SUM(C34:C37) -> 96 | T16: =SUM(D34:D37) -> 43 | U16: =SUM(E34:E37) -> 25 | V16: =SUM(F34:F37) -> 29 | W16: =SUM(G34:G37) -> 0 | X16: =SUM(H34:H37) -> 0 | Y16: =SUM(I34:I37) -> 10 | Z16: =SUM(J34:J37) -> 10 | ... AF16: =SUM(P34:P37) -> 562
B17: 08.45 - 9.00 | C17: 52 | D17: 31 | E17: 7 | F17: 14 | G17: 0 | H17: 0 | I17: 3 | J17: 1 | K17: 0 | L17: 2 | M17: 191 | N17: 0 | O17: =SUM(C17:L17,N17) -> 110 | P17: =SUM(C17:N17) -> 301 | R17: 1400-1500 | S17: =SUM(C38:C41) -> 149 | T17: =SUM(D38:D41) -> 65 | U17: =SUM(E38:E41) -> 27 | V17: =SUM(F38:F41) -> 38 | W17: =SUM(G38:G41) -> 1 | X17: =SUM(H38:H41) -> 0 | Y17: =SUM(I38:I41) -> 13 | Z17: =SUM(J38:J41) -> 12 | ... AF17: =SUM(P38:P41) -> 664
B18: 09.00 - 09.15 | C18: 52 | D18: 32 | E18: 7 | F18: 11 | G18: 0 | H18: 0 | I18: 4 | J18: 0 | K18: 0 | L18: 3 | M18: 182 | N18: 0 | O18: =SUM(C18:L18,N18) -> 109 | P18: =SUM(C18:N18) -> 291 | R18: 1500-1600 | S18: =SUM(C42:C45) -> 169 | T18: =SUM(D42:D45) -> 61 | U18: =SUM(E42:E45) -> 18 | V18: =SUM(F42:F45) -> 30 | W18: =SUM(G42:G45) -> 1 | X18: =SUM(H42:H45) -> 0 | Y18: =SUM(I42:I45) -> 11 | Z18: =SUM(J42:J45) -> 8 | ... AF18: =SUM(P42:P45) -> 683
B19: 09.15 - 09.30 | C19: 57 | D19: 33 | E19: 12 | F19: 12 | G19: 0 | H19: 0 | I19: 3 | J19: 1 | K19: 0 | L19: 0 | M19: 148 | N19: 0 | O19: =SUM(C19:L19,N19) -> 118 | P19: =SUM(C19:N19) -> 266 | R19: 1600-1700 | S19: =SUM(C46:C49) -> 196 | T19: =SUM(D46:D49) -> 86 | U19: =SUM(E46:E49) -> 17 | V19: =SUM(F46:F49) -> 36 | W19: =SUM(G46:G49) -> 0 | X19: =SUM(H46:H49) -> 0 | Y19: =SUM(I46:I49) -> 8 | Z19: =SUM(J46:J49) -> 5 | ... AF19: =SUM(P46:P49) -> 762
B20: 09.30 - 09.45 | C20: 48 | D20: 24 | E20: 6 | F20: 10 | G20: 0 | H20: 0 | I20: 1 | J20: 0 | K20: 0 | L20: 1 | M20: 154 | N20: 0 | O20: =SUM(C20:L20,N20) -> 90 | P20: =SUM(C20:N20) -> 244 | R20: 1700-1800 | S20: =SUM(C50:C53) -> 199 | T20: =SUM(D50:D53) -> 69 | U20: =SUM(E50:E53) -> 12 | V20: =SUM(F50:F53) -> 37 | W20: =SUM(G50:G53) -> 1 | X20: =SUM(H50:H53) -> 0 | Y20: =SUM(I50:I53) -> 6 | Z20: =SUM(J50:J53) -> 4 | ... AF20: =SUM(P50:P53) -> 706
B21: 09.45 - 10.00 | C21: 54 | D21: 23 | E21: 9 | F21: 13 | G21: 0 | H21: 0 | I21: 1 | J21: 1 | K21: 0 | L21: 0 | M21: 133 | N21: 0 | O21: =SUM(C21:L21,N21) -> 101 | P21: =SUM(C21:N21) -> 234 | R21: 1800-1900 | S21: =SUM(C54:C57) -> 130 | T21: =SUM(D54:D57) -> 67 | U21: =SUM(E54:E57) -> 17 | V21: =SUM(F54:F57) -> 40 | W21: =SUM(G54:G57) -> 1 | X21: =SUM(H54:H57) -> 0 | Y21: =SUM(I54:I57) -> 4 | Z21: =SUM(J54:J57) -> 2 | ... AF21: =SUM(P54:P57) -> 642
B22: 10.00 - 10.15 | C22: 46 | D22: 11 | E22: 5 | F22: 11 | G22: 0 | H22: 0 | I22: 1 | J22: 2 | K22: 2 | L22: 2 | M22: 45 | N22: 0 | O22: =SUM(C22:L22,N22) -> 80 | P22: =SUM(C22:N22) -> 125 | R22: AM Peak Hr | S22: =MAX(S10:S12) -> 580 | T22: =MAX(T10:T12) -> 248 | U22: =MAX(U10:U12) -> 48 | V22: =MAX(V10:V12) -> 83 | W22: =MAX(W10:W12) -> 3 | X22: =MAX(X10:X12) -> 0 | Y22: =MAX(Y10:Y12) -> 12 | Z22: =MAX(Z10:Z12) -> 4 | ... AF22: =MAX(AF10:AF12) -> 1409
B23: 10.15 - 10.30 | C23: 37 | D23: 20 | E23: 9 | F23: 8 | G23: 0 | H23: 0 | I23: 4 | J23: 2 | K23: 0 | L23: 1 | M23: 110 | N23: 0 | O23: =SUM(C23:L23,N23) -> 81 | P23: =SUM(C23:N23) -> 191 | R23: IP Peak Hr | S23: =MAX(S13:S18) -> 192 | T23: =MAX(T13:T18) -> 78 | U23: =MAX(U13:U18) -> 27 | V23: =MAX(V13:V18) -> 40 | W23: =MAX(W13:W18) -> 1 | X23: =MAX(X13:X18) -> 0 | Y23: =MAX(Y13:Y18) -> 13 | Z23: =MAX(Z13:Z18) -> 12 | ... AF23: =MAX(AF13:AF18) -> 773
B24: 10.30 - 10.45 | C24: 65 | D24: 25 | E24: 7 | F24: 11 | G24: 0 | H24: 0 | I24: 3 | J24: 2 | K24: 0 | L24: 1 | M24: 82 | N24: 0 | O24: =SUM(C24:L24,N24) -> 114 | P24: =SUM(C24:N24) -> 196 | R24: PM Peak Hr | S24: =MAX(S19:S21) -> 199 | T24: =MAX(T19:T21) -> 86 | U24: =MAX(U19:U21) -> 17 | V24: =MAX(V19:V21) -> 40 | W24: =MAX(W19:W21) -> 1 | X24: =MAX(X19:X21) -> 0 | Y24: =MAX(Y19:Y21) -> 8 | Z24: =MAX(Z19:Z21) -> 5 | ... AF24: =MAX(AF19:AF21) -> 762
B25: 10.45 - 11.00 | C25: 44 | D25: 18 | E25: 5 | F25: 10 | G25: 0 | H25: 0 | I25: 3 | J25: 1 | K25: 1 | L25: 0 | M25: 71 | N25: 0 | O25: =SUM(C25:L25,N25) -> 82 | P25: =SUM(C25:N25) -> 153 | R25: AM Period | S25: =SUM(S10:S12) -> 1064 | T25: =SUM(T10:T12) -> 523 | U25: =SUM(U10:U12) -> 122 | V25: =SUM(V10:V12) -> 189 | W25: =SUM(W10:W12) -> 3 | X25: =SUM(X10:X12) -> 0 | Y25: =SUM(Y10:Y12) -> 31 | Z25: =SUM(Z10:Z12) -> 7 | ... AF25: =SUM(AF10:AF12) -> 3782
B26: 11.00 - 11.15 | C26: 38 | D26: 20 | E26: 5 | F26: 9 | G26: 0 | H26: 0 | I26: 1 | J26: 0 | K26: 0 | L26: 0 | M26: 121 | N26: 0 | O26: =SUM(C26:L26,N26) -> 73 | P26: =SUM(C26:N26) -> 194 | R26: IP Period | S26: =SUM(S13:S18) -> 945 | T26: =SUM(T13:T18) -> 386 | U26: =SUM(U13:U18) -> 131 | V26: =SUM(V13:V18) -> 202 | W26: =SUM(W13:W18) -> 2 | X26: =SUM(X13:X18) -> 0 | Y26: =SUM(Y13:Y18) -> 66 | Z26: =SUM(Z13:Z18) -> 53 | ... AF26: =SUM(AF13:AF18) -> 4034
B27: 11.15 - 11.30 | C27: 60 | D27: 22 | E27: 3 | F27: 6 | G27: 0 | H27: 0 | I27: 1 | J27: 1 | K27: 1 | L27: 0 | M27: 113 | N27: 0 | O27: =SUM(C27:L27,N27) -> 94 | P27: =SUM(C27:N27) -> 207 | R27: PM Period | S27: =SUM(S19:S21) -> 525 | T27: =SUM(T19:T21) -> 222 | U27: =SUM(U19:U21) -> 46 | V27: =SUM(V19:V21) -> 113 | W27: =SUM(W19:W21) -> 2 | X27: =SUM(X19:X21) -> 0 | Y27: =SUM(Y19:Y21) -> 18 | Z27: =SUM(Z19:Z21) -> 11 | ... AF27: =SUM(AF19:AF21) -> 2110
B28: 11.30 - 11.45 | C28: 34 | D28: 15 | E28: 5 | F28: 10 | G28: 0 | H28: 0 | I28: 1 | J28: 1 | K28: 0 | L28: 0 | M28: 111 | N28: 0 | O28: =SUM(C28:L28,N28) -> 66 | P28: =SUM(C28:N28) -> 177 | R28: 12 Hours | S28: =SUM(S10:S21) -> 2534 | T28: =SUM(T10:T21) -> 1131 | U28: =SUM(U10:U21) -> 299 | V28: =SUM(V10:V21) -> 504 | W28: =SUM(W10:W21) -> 7 | X28: =SUM(X10:X21) -> 0 | Y28: =SUM(Y10:Y21) -> 115 | Z28: =SUM(Z10:Z21) -> 71 | ... AF28: =SUM(AF10:AF21) -> 9926
B29: 11.45 - 12.00 | C29: 38 | D29: 21 | E29: 3 | F29: 10 | G29: 0 | H29: 0 | I29: 5 | J29: 6 | K29: 0 | L29: 1 | M29: 111 | N29: 0 | O29: =SUM(C29:L29,N29) -> 84 | P29: =SUM(C29:N29) -> 195
B30: 12.00 - 12.15 | C30: 39 | D30: 21 | E30: 7 | F30: 8 | G30: 0 | H30: 0 | I30: 0 | J30: 0 | K30: 1 | L30: 2 | M30: 85 | N30: 0 | O30: =SUM(C30:L30,N30) -> 78 | P30: =SUM(C30:N30) -> 163
B31: 12.15 - 12.30 | C31: 33 | D31: 20 | E31: 5 | F31: 5 | G31: 0 | H31: 0 | I31: 3 | J31: 2 | K31: 0 | L31: 4 | M31: 60 | N31: 0 | O31: =SUM(C31:L31,N31) -> 72 | P31: =SUM(C31:N31) -> 132
B32: 12.30 - 12.45 | C32: 52 | D32: 12 | E32: 2 | F32: 7 | G32: 0 | H32: 0 | I32: 8 | J32: 5 | K32: 1 | L32: 2 | M32: 106 | N32: 0 | O32: =SUM(C32:L32,N32) -> 89 | P32: =SUM(C32:N32) -> 195
B33: 12.45 - 13.00 | C33: 45 | D33: 12 | E33: 5 | F33: 10 | G33: 0 | H33: 0 | I33: 2 | J33: 1 | K33: 2 | L33: 5 | M33: 115 | N33: 0 | O33: =SUM(C33:L33,N33) -> 82 | P33: =SUM(C33:N33) -> 197
B34: 13.00 - 13.15 | C34: 22 | D34: 8 | E34: 3 | F34: 3 | G34: 0 | H34: 0 | I34: 1 | J34: 0 | K34: 1 | L34: 1 | M34: 86 | N34: 0 | O34: =SUM(C34:L34,N34) -> 39 | P34: =SUM(C34:N34) -> 125
B35: 13.15 - 13.30 | C35: 28 | D35: 13 | E35: 9 | F35: 8 | G35: 0 | H35: 0 | I35: 3 | J35: 5 | K35: 1 | L35: 0 | M35: 90 | N35: 0 | O35: =SUM(C35:L35,N35) -> 67 | P35: =SUM(C35:N35) -> 157
B36: 13.30 - 13.45 | C36: 26 | D36: 11 | E36: 4 | F36: 8 | G36: 0 | H36: 0 | I36: 3 | J36: 2 | K36: 0 | L36: 1 | M36: 84 | N36: 0 | O36: =SUM(C36:L36,N36) -> 55 | P36: =SUM(C36:N36) -> 139
B37: 13.45 - 14.00 | C37: 20 | D37: 11 | E37: 9 | F37: 10 | G37: 0 | H37: 0 | I37: 3 | J37: 3 | K37: 1 | L37: 1 | M37: 83 | N37: 0 | O37: =SUM(C37:L37,N37) -> 58 | P37: =SUM(C37:N37) -> 141
B38: 14.00 - 14.15 | C38: 33 | D38: 17 | E38: 13 | F38: 10 | G38: 0 | H38: 0 | I38: 5 | J38: 4 | K38: 0 | L38: 2 | M38: 75 | N38: 0 | O38: =SUM(C38:L38,N38) -> 84 | P38: =SUM(C38:N38) -> 159
B39: 14.15 - 14.30 | C39: 46 | D39: 19 | E39: 5 | F39: 11 | G39: 1 | H39: 0 | I39: 1 | J39: 1 | K39: 2 | L39: 4 | M39: 65 | N39: 0 | O39: =SUM(C39:L39,N39) -> 90 | P39: =SUM(C39:N39) -> 155
B40: 14.30 - 14.45 | C40: 33 | D40: 15 | E40: 5 | F40: 8 | G40: 0 | H40: 0 | I40: 5 | J40: 5 | K40: 0 | L40: 0 | M40: 98 | N40: 0 | O40: =SUM(C40:L40,N40) -> 71 | P40: =SUM(C40:N40) -> 169
... B57: 18.45 - 19.00 | C57: 21 | D57: 20 | E57: 2 | F57: 10 | G57: 1 | H57: 0 | I57: 0 | J57: 0 | K57: 0 | L57: 0 | M57: 0 | N57: 0 | O57: =SUM(C57:L57,N57) -> 54 | P57: =SUM(C57:N57) -> 54
B58: Totals | C58: =SUM(C10:C57) -> 2534 | D58: =SUM(D10:D57) -> 1131 | E58: =SUM(E10:E57) -> 299 | F58: =SUM(F10:F57) -> 504 | G58: =SUM(G10:G57) -> 7 | H58: =SUM(H10:H57) -> 0 | I58: =SUM(I10:I57) -> 115 | J58: =SUM(J10:J57) -> 71 | ... P58: =SUM(P10:P57) -> 9926
...

Sheet 29.07 Ntinda-Kisaasi
B1: Consultancy services for Preparation of Expressway Development Master Plan (EDMP) for Uganda
B2: MANUAL CLASSIFIED COUNT (MCC)
B3: ROAD NAME: | C3: ='29.07 Kisaasi-Ntinda'!C3:G3 -> MCC - C1 - STN33 - NTINDA ROAD
C5: Date | D5: ='29.07 Kisaasi-Ntinda'!D5 -> 29.07.19 | F5: Location | G5: ='29.07 Kisaasi-Ntinda'!G5:H5 -> Ndere Center | J5: Surveyor | K5: Okello Peter
C6: Dir. From | D6: Ntinda | F6: Dir. To | G6: Kisaasi | J6: Supervisor | K6: ='29.07 Kisaasi-Ntinda'!K6:L6 -> Steven
B8: Time / Veh Type | R8: SUMMARY TRAFFIC VOLUMES
C9: 1. Car | D9: 2. Station Wagon | E9: 3. Pickups | F9: 4. Minibus, matatu | G9: 5. Medium bus | H9: 6. Large Bus | I9: 7. Light Truck | J9: 8. Medium Truck | K9: 9. Heavy truck | L9: 10. Truck Trailer | M9: 11. Motor cycles | N9: 12. Tractors | O9: Total Excl M/Cycles | P9: Total All | R9: Time | S9: 1. Car | T9: 2. Station Wagon | U9: 3. Pickups | V9: 4. Minibus, matatu | W9: 5. Medium bus | X9: 6. Large Bus | Y9: 7. Light Truck | Z9: 8. Medium Truck | AA9: 9. Heavy truck | AB9: 10. Truck Trailer | AC9: 11. Motorcycles | AD9: 12. Tractors, Graders | AE9: Total Excl M/ Cycles | AF9: Total All
B10: 07.00 - 07.15 | C10: 68 | D10: 31 | E10: 9 | F10: 24 | G10: 0 | H10: 0 | I10: 2 | J10: 0 | K10: 2 | L10: 0 | M10: 96 | N10: 0 | O10: =SUM(C10:L10,N10) -> 136 | P10: =SUM(C10:N10) -> 232 | R10: 0700-0800 | S10: =SUM(C10:C13) -> 172 | T10: =SUM(D10:D13) -> 75 | U10: =SUM(E10:E13) -> 25 | V10: =SUM(F10:F13) -> 91 | W10: =SUM(G10:G13) -> 1 | X10: =SUM(H10:H13) -> 0 | Y10: =SUM(I10:I13) -> 8 | Z10: =SUM(J10:J13) -> 2 | ... AF10: =SUM(P10:P13) -> 744
B11: 07.15 - 07.30 | C11: 45 | D11: 17 | E11: 7 | F11: 26 | G11: 1 | H11: 0 | I11: 4 | J11: 0 | K11: 4 | L11: 0 | M11: 71 | N11: 0 | O11: =SUM(C11:L11,N11) -> 104 | P11: =SUM(C11:N11) -> 175 | R11: 0800-0900 | S11: =SUM(C14:C17) -> 103 | T11: =SUM(D14:D17) -> 58 | U11: =SUM(E14:E17) -> 8 | V11: =SUM(F14:F17) -> 135 | W11: =SUM(G14:G17) -> 0 | X11: =SUM(H14:H17) -> 0 | Y11: =SUM(I14:I17) -> 7 | Z11: =SUM(J14:J17) -> 5 | ... AF11: =SUM(P14:P17) -> 931
B12: 07.30 - 07.45 | C12: 26 | D12: 12 | E12: 4 | F12: 19 | G12: 0 | H12: 0 | I12: 2 | J12: 0 | K12: 0 | L12: 0 | M12: 74 | N12: 0 | O12: =SUM(C12:L12,N12) -> 63 | P12: =SUM(C12:N12) -> 137 | R12: 0900-1000 | S12: =SUM(C18:C21) -> 135 | T12: =SUM(D18:D21) -> 53 | U12: =SUM(E18:E21) -> 27 | V12: =SUM(F18:F21) -> 102 | W12: =SUM(G18:G21) -> 0 | X12: =SUM(H18:H21) -> 5 | Y12: =SUM(I18:I21) -> 16 | Z12: =SUM(J18:J21) -> 6 | ... AF12: =SUM(P18:P21) -> 910
B13: 07.45 - 08.00 | C13: 33 | D13: 15 | E13: 5 | F13: 22 | G13: 0 | H13: 0 | I13: 0 | J13: 2 | K13: 4 | L13: 1 | M13: 118 | N13: 0 | O13: =SUM(C13:L13,N13) -> 82 | P13: =SUM(C13:N13) -> 200 | R13: 1000-1100 | S13: =SUM(C22:C25) -> 109 | T13: =SUM(D22:D25) -> 61 | U13: =SUM(E22:E25) -> 32 | V13: =SUM(F22:F25) -> 94 | W13: =SUM(G22:G25) -> 0 | X13: =SUM(H22:H25) -> 0 | Y13: =SUM(I22:I25) -> 18 | Z13: =SUM(J22:J25) -> 6 | ... AF13: =SUM(P22:P25) -> 751
B14: 08.00 - 08.15 | C14: 31 | D14: 19 | E14: 2 | F14: 36 | G14: 0 | H14: 0 | I14: 1 | J14: 0 | K14: 1 | L14: 0 | M14: 139 | N14: 0 | O14: =SUM(C14:L14,N14) -> 90 | P14: =SUM(C14:N14) -> 229 | R14: 1100-1200 | S14: =SUM(C26:C29) -> 148 | T14: =SUM(D26:D29) -> 48 | U14: =SUM(E26:E29) -> 21 | V14: =SUM(F26:F29) -> 67 | W14: =SUM(G26:G29) -> 1 | X14: =SUM(H26:H29) -> 0 | Y14: =SUM(I26:I29) -> 27 | Z14: =SUM(J26:J29) -> 12 | ... AF14: =SUM(P26:P29) -> 636
B15: 08.15 - 08.30 | C15: 19 | D15: 9 | E15: 1 | F15: 28 | G15: 0 | H15: 0 | I15: 3 | J15: 3 | K15: 0 | L15: 0 | M15: 158 | N15: 0 | O15: =SUM(C15:L15,N15) -> 63 | P15: =SUM(C15:N15) -> 221 | R15: 1200-1300 | S15: =SUM(C30:C33) -> 155 | T15: =SUM(D30:D33) -> 81 | U15: =SUM(E30:E33) -> 29 | V15: =SUM(F30:F33) -> 57 | W15: =SUM(G30:G33) -> 0 | X15: =SUM(H30:H33) -> 0 | Y15: =SUM(I30:I33) -> 32 | Z15: =SUM(J30:J33) -> 8 | ... AF15: =SUM(P30:P33) -> 666
B16: 08.30 - 08.45 | C16: 25 | D16: 16 | E16: 3 | F16: 45 | G16: 0 | H16: 0 | I16: 1 | J16: 1 | K16: 0 | L16: 0 | M16: 160 | N16: 0 | O16: =SUM(C16:L16,N16) -> 91 | P16: =SUM(C16:N16) -> 251 | R16: 1300-1400 | S16: =SUM(C34:C37) -> 133 | T16: =SUM(D34:D37) -> 75 | U16: =SUM(E34:E37) -> 35 | V16: =SUM(F34:F37) -> 65 | W16: =SUM(G34:G37) -> 0 | X16: =SUM(H34:H37) -> 1 | Y16: =SUM(I34:I37) -> 25 | Z16: =SUM(J34:J37) -> 6 | ... AF16: =SUM(P34:P37) -> 604
B17: 08.45 - 9.00 | C17: 28 | D17: 14 | E17: 2 | F17: 26 | G17: 0 | H17: 0 | I17: 2 | J17: 1 | K17: 0 | L17: 0 | M17: 157 | N17: 0 | O17: =SUM(C17:L17,N17) -> 73 | P17: =SUM(C17:N17) -> 230 | R17: 1400-1500 | S17: =SUM(C38:C41) -> 137 | T17: =SUM(D38:D41) -> 80 | U17: =SUM(E38:E41) -> 28 | V17: =SUM(F38:F41) -> 60 | W17: =SUM(G38:G41) -> 2 | X17: =SUM(H38:H41) -> 0 | Y17: =SUM(I38:I41) -> 19 | Z17: =SUM(J38:J41) -> 14 | ... AF17: =SUM(P38:P41) -> 551
B18: 09.00 - 09.15 | C18: 36 | D18: 16 | E18: 7 | F18: 27 | G18: 0 | H18: 0 | I18: 9 | J18: 3 | K18: 1 | L18: 0 | M18: 146 | N18: 0 | O18: =SUM(C18:L18,N18) -> 99 | P18: =SUM(C18:N18) -> 245 | R18: 1500-1600 | S18: =SUM(C42:C45) -> 154 | T18: =SUM(D42:D45) -> 77 | U18: =SUM(E42:E45) -> 30 | V18: =SUM(F42:F45) -> 51 | W18: =SUM(G42:G45) -> 2 | X18: =SUM(H42:H45) -> 1 | Y18: =SUM(I42:I45) -> 12 | Z18: =SUM(J42:J45) -> 5 | ... AF18: =SUM(P42:P45) -> 508
B19: 09.15 - 09.30 | C19: 28 | D19: 15 | E19: 3 | F19: 28 | G19: 0 | H19: 5 | I19: 1 | J19: 0 | K19: 0 | L19: 1 | M19: 112 | N19: 0 | O19: =SUM(C19:L19,N19) -> 81 | P19: =SUM(C19:N19) -> 193 | R19: 1600-1700 | S19: =SUM(C46:C49) -> 260 | T19: =SUM(D46:D49) -> 128 | U19: =SUM(E46:E49) -> 33 | V19: =SUM(F46:F49) -> 62 | W19: =SUM(G46:G49) -> 2 | X19: =SUM(H46:H49) -> 0 | Y19: =SUM(I46:I49) -> 14 | Z19: =SUM(J46:J49) -> 9 | ... AF19: =SUM(P46:P49) -> 697
B20: 09.30 - 09.45 | C20: 33 | D20: 7 | E20: 11 | F20: 24 | G20: 0 | H20: 0 | I20: 4 | J20: 1 | K20: 0 | L20: 1 | M20: 167 | N20: 0 | O20: =SUM(C20:L20,N20) -> 81 | P20: =SUM(C20:N20) -> 248 | R20: 1700-1800 | S20: =SUM(C50:C53) -> 315 | T20: =SUM(D50:D53) -> 139 | U20: =SUM(E50:E53) -> 36 | V20: =SUM(F50:F53) -> 50 | W20: =SUM(G50:G53) -> 4 | X20: =SUM(H50:H53) -> 0 | Y20: =SUM(I50:I53) -> 23 | Z20: =SUM(J50:J53) -> 3 | ... AF20: =SUM(P50:P53) -> 812
B21: 09.45 - 10.00 | C21: 38 | D21: 15 | E21: 6 | F21: 23 | G21: 0 | H21: 0 | I21: 2 | J21: 2 | K21: 1 | L21: 0 | M21: 137 | N21: 0 | O21: =SUM(C21:L21,N21) -> 87 | P21: =SUM(C21:N21) -> 224 | R21: 1800-1900 | S21: =SUM(C54:C57) -> 245 | T21: =SUM(D54:D57) -> 92 | U21: =SUM(E54:E57) -> 20 | V21: =SUM(F54:F57) -> 50 | W21: =SUM(G54:G57) -> 0 | X21: =SUM(H54:H57) -> 0 | Y21: =SUM(I54:I57) -> 10 | Z21: =SUM(J54:J57) -> 4 | ... AF21: =SUM(P54:P57) -> 706
B22: 10.00 - 10.15 | C22: 33 | D22: 19 | E22: 11 | F22: 24 | G22: 0 | H22: 0 | I22: 5 | J22: 2 | K22: 0 | L22: 1 | M22: 100 | N22: 0 | O22: =SUM(C22:L22,N22) -> 95 | P22: =SUM(C22:N22) -> 195 | R22: AM Peak Hr | S22: =MAX(S10:S12) -> 172 | T22: =MAX(T10:T12) -> 75 | U22: =MAX(U10:U12) -> 27 | V22: =MAX(V10:V12) -> 135 | W22: =MAX(W10:W12) -> 1 | X22: =MAX(X10:X12) -> 5 | Y22: =MAX(Y10:Y12) -> 16 | Z22: =MAX(Z10:Z12) -> 6 | ... AF22: =MAX(AF10:AF12) -> 931
B23: 10.15 - 10.30 | C23: 28 | D23: 12 | E23: 7 | F23: 19 | G23: 0 | H23: 0 | I23: 8 | J23: 2 | K23: 1 | L23: 0 | M23: 105 | N23: 0 | O23: =SUM(C23:L23,N23) -> 77 | P23: =SUM(C23:N23) -> 182 | R23: IP Peak Hr | S23: =MAX(S13:S18) -> 155 | T23: =MAX(T13:T18) -> 81 | U23: =MAX(U13:U18) -> 35 | V23: =MAX(V13:V18) -> 94 | W23: =MAX(W13:W18) -> 2 | X23: =MAX(X13:X18) -> 1 | Y23: =MAX(Y13:Y18) -> 32 | Z23: =MAX(Z13:Z18) -> 14 | ... AF23: =MAX(AF13:AF18) -> 751
B24: 10.30 - 10.45 | C24: 26 | D24: 21 | E24: 8 | F24: 30 | G24: 0 | H24: 0 | I24: 3 | J24: 2 | K24: 0 | L24: 2 | M24: 106 | N24: 0 | O24: =SUM(C24:L24,N24) -> 92 | P24: =SUM(C24:N24) -> 198 | R24: PM Peak Hr | S24: =MAX(S19:S21) -> 315 | T24: =MAX(T19:T21) -> 139 | U24: =MAX(U19:U21) -> 36 | V24: =MAX(V19:V21) -> 62 | W24: =MAX(W19:W21) -> 4 | X24: =MAX(X19:X21) -> 0 | Y24: =MAX(Y19:Y21) -> 23 | Z24: =MAX(Z19:Z21) -> 9 | ... AF24: =MAX(AF19:AF21) -> 812
B25: 10.45 - 11.00 | C25: 22 | D25: 9 | E25: 6 | F25: 21 | G25: 0 | H25: 0 | I25: 2 | J25: 0 | K25: 1 | L25: 0 | M25: 115 | N25: 0 | O25: =SUM(C25:L25,N25) -> 61 | P25: =SUM(C25:N25) -> 176 | R25: AM Period | S25: =SUM(S10:S12) -> 410 | T25: =SUM(T10:T12) -> 186 | U25: =SUM(U10:U12) -> 60 | V25: =SUM(V10:V12) -> 328 | W25: =SUM(W10:W12) -> 1 | X25: =SUM(X10:X12) -> 5 | Y25: =SUM(Y10:Y12) -> 31 | Z25: =SUM(Z10:Z12) -> 13 | ... AF25: =SUM(AF10:AF12) -> 2585
B26: 11.00 - 11.15 | C26: 36 | D26: 9 | E26: 7 | F26: 8 | G26: 0 | H26: 0 | I26: 4 | J26: 3 | K26: 1 | L26: 2 | M26: 79 | N26: 0 | O26: =SUM(C26:L26,N26) -> 70 | P26: =SUM(C26:N26) -> 149 | R26: IP Period | S26: =SUM(S13:S18) -> 836 | T26: =SUM(T13:T18) -> 422 | U26: =SUM(U13:U18) -> 175 | V26: =SUM(V13:V18) -> 394 | W26: =SUM(W13:W18) -> 5 | X26: =SUM(X13:X18) -> 2 | Y26: =SUM(Y13:Y18) -> 133 | Z26: =SUM(Z13:Z18) -> 51 | ... AF26: =SUM(AF13:AF18) -> 3716
B27: 11.15 - 11.30 | C27: 31 | D27: 15 | E27: 3 | F27: 28 | G27: 0 | H27: 0 | I27: 5 | J27: 3 | K27: 0 | L27: 3 | M27: 50 | N27: 0 | O27: =SUM(C27:L27,N27) -> 88 | P27: =SUM(C27:N27) -> 138 | R27: PM Period | S27: =SUM(S19:S21) -> 820 | T27: =SUM(T19:T21) -> 359 | U27: =SUM(U19:U21) -> 89 | V27: =SUM(V19:V21) -> 162 | W27: =SUM(W19:W21) -> 6 | X27: =SUM(X19:X21) -> 0 | Y27: =SUM(Y19:Y21) -> 47 | Z27: =SUM(Z19:Z21) -> 16 | ... AF27: =SUM(AF19:AF21) -> 2215
B28: 11.30 - 11.45 | C28: 34 | D28: 12 | E28: 5 | F28: 17 | G28: 0 | H28: 0 | I28: 11 | J28: 3 | K28: 0 | L28: 5 | M28: 69 | N28: 0 | O28: =SUM(C28:L28,N28) -> 87 | P28: =SUM(C28:N28) -> 156 | R28: 12 Hours | S28: =SUM(S10:S21) -> 2066 | T28: =SUM(T10:T21) -> 967 | U28: =SUM(U10:U21) -> 324 | V28: =SUM(V10:V21) -> 884 | W28: =SUM(W10:W21) -> 12 | X28: =SUM(X10:X21) -> 7 | Y28: =SUM(Y10:Y21) -> 211 | Z28: =SUM(Z10:Z21) -> 80 | ... AF28: =SUM(AF10:AF21) -> 8516
B29: 11.45 - 12.00 | C29: 47 | D29: 12 | E29: 6 | F29: 14 | G29: 1 | H29: 0 | I29: 7 | J29: 3 | K29: 0 | L29: 3 | M29: 100 | N29: 0 | O29: =SUM(C29:L29,N29) -> 93 | P29: =SUM(C29:N29) -> 193
B30: 12.00 - 12.15 | C30: 36 | D30: 19 | E30: 6 | F30: 12 | G30: 0 | H30: 0 | I30: 2 | J30: 0 | K30: 0 | L30: 4 | M30: 80 | N30: 0 | O30: =SUM(C30:L30,N30) -> 79 | P30: =SUM(C30:N30) -> 159
B31: 12.15 - 12.30 | C31: 37 | D31: 20 | E31: 3 | F31: 12 | G31: 0 | H31: 0 | I31: 5 | J31: 5 | K31: 2 | L31: 2 | M31: 45 | N31: 0 | O31: =SUM(C31:L31,N31) -> 86 | P31: =SUM(C31:N31) -> 131
B32: 12.30 - 12.45 | C32: 35 | D32: 18 | E32: 7 | F32: 15 | G32: 0 | H32: 0 | I32: 10 | J32: 3 | K32: 1 | L32: 1 | M32: 83 | N32: 0 | O32: =SUM(C32:L32,N32) -> 90 | P32: =SUM(C32:N32) -> 173
B33: 12.45 - 13.00 | C33: 47 | D33: 24 | E33: 13 | F33: 18 | G33: 0 | H33: 0 | I33: 15 | J33: 0 | K33: 0 | L33: 5 | M33: 81 | N33: 0 | O33: =SUM(C33:L33,N33) -> 122 | P33: =SUM(C33:N33) -> 203
B34: 13.00 - 13.15 | C34: 32 | D34: 13 | E34: 10 | F34: 27 | G34: 0 | H34: 1 | I34: 6 | J34: 1 | K34: 0 | L34: 0 | M34: 53 | N34: 0 | O34: =SUM(C34:L34,N34) -> 90 | P34: =SUM(C34:N34) -> 143
B35: 13.15 - 13.30 | C35: 34 | D35: 19 | E35: 8 | F35: 15 | G35: 0 | H35: 0 | I35: 6 | J35: 2 | K35: 1 | L35: 0 | M35: 67 | N35: 0 | O35: =SUM(C35:L35,N35) -> 85 | P35: =SUM(C35:N35) -> 152
B36: 13.30 - 13.45 | C36: 38 | D36: 17 | E36: 13 | F36: 12 | G36: 0 | H36: 0 | I36: 10 | J36: 0 | K36: 1 | L36: 1 | M36: 66 | N36: 0 | O36: =SUM(C36:L36,N36) -> 92 | P36: =SUM(C36:N36) -> 158
B37: 13.45 - 14.00 | C37: 29 | D37: 26 | E37: 4 | F37: 11 | G37: 0 | H37: 0 | I37: 3 | J37: 3 | K37: 1 | L37: 1 | M37: 73 | N37: 0 | O37: =SUM(C37:L37,N37) -> 78 | P37: =SUM(C37:N37) -> 151
B38: 14.00 - 14.15 | C38: 35 | D38: 20 | E38: 7 | F38: 13 | G38: 1 | H38: 0 | I38: 6 | J38: 4 | K38: 0 | L38: 2 | M38: 40 | N38: 0 | O38: =SUM(C38:L38,N38) -> 88 | P38: =SUM(C38:N38) -> 128
B39: 14.15 - 14.30 | C39: 36 | D39: 20 | E39: 7 | F39: 19 | G39: 1 | H39: 0 | I39: 1 | J39: 4 | K39: 2 | L39: 2 | M39: 64 | N39: 0 | O39: =SUM(C39:L39,N39) -> 92 | P39: =SUM(C39:N39) -> 156
B40: 14.30 - 14.45 | C40: 33 | D40: 15 | E40: 10 | F40: 16 | G40: 0 | H40: 0 | I40: 7 | J40: 0 | K40: 1 | L40: 3 | M40: 35 | N40: 0 | O40: =SUM(C40:L40,N40) -> 85 | P40: =SUM(C40:N40) -> 120
... B57: 18.45 - 19.00 | C57: 71 | D57: 17 | E57: 2 | F57: 11 | G57: 0 | H57: 0 | I57: 2 | J57: 1 | K57: 0 | L57: 9 | M57: 55 | N57: 0 | O57: =SUM(C57:L57,N57) -> 113 | P57: =SUM(C57:N57) -> 168
B58: Totals | C58: =SUM(C10:C57) -> 2066 | D58: =SUM(D10:D57) -> 967 | E58: =SUM(E10:E57) -> 324 | F58: =SUM(F10:F57) -> 884 | G58: =SUM(G10:G57) -> 12 | H58: =SUM(H10:H57) -> 7 | I58: =SUM(I10:I57) -> 211 | J58: =SUM(J10:J57) -> 80 | ... P58: =SUM(P10:P57) -> 8516
...

Sheet 30.07 Kisaasi-Ntinda
B1: Consultancy services for Preparation of Expressway Development Master Plan (EDMP) for Uganda
B2: MANUAL CLASSIFIED COUNT (MCC)
B3: ROAD NAME: | C3: ='29.07 Kisaasi-Ntinda'!C3:G3 -> MCC - C1 - STN33 - NTINDA ROAD
C5: Date | D5: 30.07.19 | F5: Location | G5: ='29.07 Kisaasi-Ntinda'!G5:H5 -> Ndere Center | J5: Surveyor | K5: Jonathan &Omuset Jerome
C6: Dir. From | D6: ='29.07 Kisaasi-Ntinda'!D6:E6 -> Kisaasi | F6: Dir. To | G6: ='29.07 Kisaasi-Ntinda'!G6:H6 -> Ntinda | J6: Supervisor | K6: ='29.07 Kisaasi-Ntinda'!K6:L6 -> Steven
B8: Time / Veh Type | R8: SUMMARY TRAFFIC VOLUMES
C9: 1. Car | D9: 2. Station Wagon | E9: 3. Pickups | F9: 4. Minibus, matatu | G9: 5. Medium bus | H9: 6. Large Bus | I9: 7. Light Truck | J9: 8. Medium Truck | K9: 9. Heavy truck | L9: 10. Truck Trailer | M9: 11. Motor cycles | N9: 12. Tractors | O9: Total Excl M/Cycles | P9: Total All | R9: Time | S9: 1. Car | T9: 2. Station Wagon | U9: 3. Pickups | V9: 4. Minibus, matatu | W9: 5. Medium bus | X9: 6. Large Bus | Y9: 7. Light Truck | Z9: 8. Medium Truck | AA9: 9. Heavy truck | AB9: 10. Truck Trailer | AC9: 11. Motorcycles | AD9: 12. Tractors, Graders | AE9: Total Excl M/ Cycles | AF9: Total All
B10: 07.00 - 07.15 | C10: 69 | D10: 58 | E10: 5 | F10: 10 | G10: 0 | H10: 0 | I10: 5 | J10: 3 | K10: 4 | L10: 1 | M10: 70 | N10: 0 | O10: =SUM(C10:L10,N10) -> 155 | P10: =SUM(C10:N10) -> 225 | R10: 0700-0800 | S10: =SUM(C10:C13) -> 331 | T10: =SUM(D10:D13) -> 190 | U10: =SUM(E10:E13) -> 41 | V10: =SUM(F10:F13) -> 55 | W10: =SUM(G10:G13) -> 1 | X10: =SUM(H10:H13) -> 0 | Y10: =SUM(I10:I13) -> 19 | Z10: =SUM(J10:J13) -> 5 | ... AF10: =SUM(P10:P13) -> 1235
B11: 07.15 - 07.30 | C11: 90 | D11: 68 | E11: 8 | F11: 24 | G11: 1 | H11: 0 | I11: 3 | J11: 0 | K11: 0 | L11: 1 | M11: 142 | N11: 0 | O11: =SUM(C11:L11,N11) -> 195 | P11: =SUM(C11:N11) -> 337 | R11: 0800-0900 | S11: =SUM(C14:C17) -> 287 | T11: =SUM(D14:D17) -> 157 | U11: =SUM(E14:E17) -> 30 | V11: =SUM(F14:F17) -> 52 | W11: =SUM(G14:G17) -> 3 | X11: =SUM(H14:H17) -> 0 | Y11: =SUM(I14:I17) -> 21 | Z11: =SUM(J14:J17) -> 9 | ... AF11: =SUM(P14:P17) -> 1283
B12: 07.30 - 07.45 | C12: 81 | D12: 30 | E12: 18 | F12: 7 | G12: 0 | H12: 0 | I12: 5 | J12: 1 | K12: 1 | L12: 2 | M12: 170 | N12: 0 | O12: =SUM(C12:L12,N12) -> 145 | P12: =SUM(C12:N12) -> 315 | R12: 0900-1000 | S12: =SUM(C18:C21) -> 227 | T12: =SUM(D18:D21) -> 106 | U12: =SUM(E18:E21) -> 26 | V12: =SUM(F18:F21) -> 56 | W12: =SUM(G18:G21) -> 0 | X12: =SUM(H18:H21) -> 0 | Y12: =SUM(I18:I21) -> 22 | Z12: =SUM(J18:J21) -> 9 | ... AF12: =SUM(P18:P21) -> 934
B13: 07.45 - 08.00 | C13: 91 | D13: 34 | E13: 10 | F13: 14 | G13: 0 | H13: 0 | I13: 6 | J13: 1 | K13: 1 | L13: 1 | M13: 200 | N13: 0 | O13: =SUM(C13:L13,N13) -> 158 | P13: =SUM(C13:N13) -> 358 | R13: 1000-1100 | S13: =SUM(C22:C25) -> 161 | T13: =SUM(D22:D25) -> 86 | U13: =SUM(E22:E25) -> 20 | V13: =SUM(F22:F25) -> 29 | W13: =SUM(G22:G25) -> 0 | X13: =SUM(H22:H25) -> 0 | Y13: =SUM(I22:I25) -> 16 | Z13: =SUM(J22:J25) -> 12 | ... AF13: =SUM(P22:P25) -> 751
B14: 08.00 - 08.15 | C14: 95 | D14: 51 | E14: 9 | F14: 15 | G14: 3 | H14: 0 | I14: 7 | J14: 3 | K14: 1 | L14: 3 | M14: 185 | N14: 0 | O14: =SUM(C14:L14,N14) -> 187 | P14: =SUM(C14:N14) -> 372 | R14: 1100-1200 | S14: =SUM(C26:C29) -> 153 | T14: =SUM(D26:D29) -> 67 | U14: =SUM(E26:E29) -> 18 | V14: =SUM(F26:F29) -> 32 | W14: =SUM(G26:G29) -> 0 | X14: =SUM(H26:H29) -> 0 | Y14: =SUM(I26:I29) -> 8 | Z14: =SUM(J26:J29) -> 11 | ... AF14: =SUM(P26:P29) -> 642
B15: 08.15 - 08.30 | C15: 96 | D15: 40 | E15: 11 | F15: 17 | G15: 0 | H15: 0 | I15: 6 | J15: 2 | K15: 0 | L15: 0 | M15: 190 | N15: 0 | O15: =SUM(C15:L15,N15) -> 172 | P15: =SUM(C15:N15) -> 362 | R15: 1200-1300 | S15: =SUM(C30:C33) -> 148 | T15: =SUM(D30:D33) -> 59 | U15: =SUM(E30:E33) -> 19 | V15: =SUM(F30:F33) -> 28 | W15: =SUM(G30:G33) -> 2 | X15: =SUM(H30:H33) -> 0 | Y15: =SUM(I30:I33) -> 12 | Z15: =SUM(J30:J33) -> 10 | ... AF15: =SUM(P30:P33) -> 686
B16: 08.30 - 08.45 | C16: 60 | D16: 31 | E16: 7 | F16: 12 | G16: 0 | H16: 0 | I16: 5 | J16: 2 | K16: 0 | L16: 0 | M16: 230 | N16: 0 | O16: =SUM(C16:L16,N16) -> 117 | P16: =SUM(C16:N16) -> 347 | R16: 1300-1400 | S16: =SUM(C34:C37) -> 123 | T16: =SUM(D34:D37) -> 42 | U16: =SUM(E34:E37) -> 17 | V16: =SUM(F34:F37) -> 28 | W16: =SUM(G34:G37) -> 0 | X16: =SUM(H34:H37) -> 0 | Y16: =SUM(I34:I37) -> 9 | Z16: =SUM(J34:J37) -> 7 | ... AF16: =SUM(P34:P37) -> 676
B17: 08.45 - 9.00 | C17: 36 | D17: 35 | E17: 3 | F17: 8 | G17: 0 | H17: 0 | I17: 3 | J17: 2 | K17: 0 | L17: 0 | M17: 115 | N17: 0 | O17: =SUM(C17:L17,N17) -> 87 | P17: =SUM(C17:N17) -> 202 | R17: 1400-1500 | S17: =SUM(C38:C41) -> 150 | T17: =SUM(D38:D41) -> 50 | U17: =SUM(E38:E41) -> 16 | V17: =SUM(F38:F41) -> 30 | W17: =SUM(G38:G41) -> 2 | X17: =SUM(H38:H41) -> 0 | Y17: =SUM(I38:I41) -> 12 | Z17: =SUM(J38:J41) -> 11 | ... AF17: =SUM(P38:P41) -> 625
B18: 09.00 - 09.15 | C18: 48 | D18: 28 | E18: 6 | F18: 11 | G18: 0 | H18: 0 | I18: 6 | J18: 3 | K18: 0 | L18: 1 | M18: 105 | N18: 0 | O18: =SUM(C18:L18,N18) -> 103 | P18: =SUM(C18:N18) -> 208 | R18: 1500-1600 | S18: =SUM(C42:C45) -> 134 | T18: =SUM(D42:D45) -> 53 | U18: =SUM(E42:E45) -> 21 | V18: =SUM(F42:F45) -> 26 | W18: =SUM(G42:G45) -> 0 | X18: =SUM(H42:H45) -> 0 | Y18: =SUM(I42:I45) -> 13 | Z18: =SUM(J42:J45) -> 12 | ... AF18: =SUM(P42:P45) -> 613
B19: 09.15 - 09.30 | C19: 63 | D19: 30 | E19: 6 | F19: 15 | G19: 0 | H19: 0 | I19: 7 | J19: 2 | K19: 0 | L19: 0 | M19: 115 | N19: 0 | O19: =SUM(C19:L19,N19) -> 123 | P19: =SUM(C19:N19) -> 238 | R19: 1600-1700 | S19: =SUM(C46:C49) -> 179 | T19: =SUM(D46:D49) -> 69 | U19: =SUM(E46:E49) -> 23 | V19: =SUM(F46:F49) -> 31 | W19: =SUM(G46:G49) -> 0 | X19: =SUM(H46:H49) -> 0 | Y19: =SUM(I46:I49) -> 13 | Z19: =SUM(J46:J49) -> 6 | ... AF19: =SUM(P46:P49) -> 787
B20: 09.30 - 09.45 | C20: 61 | D20: 25 | E20: 8 | F20: 14 | G20: 0 | H20: 0 | I20: 7 | J20: 2 | K20: 0 | L20: 0 | M20: 160 | N20: 0 | O20: =SUM(C20:L20,N20) -> 117 | P20: =SUM(C20:N20) -> 277 | R20: 1700-1800 | S20: =SUM(C50:C53) -> 178 | T20: =SUM(D50:D53) -> 66 | U20: =SUM(E50:E53) -> 25 | V20: =SUM(F50:F53) -> 24 | W20: =SUM(G50:G53) -> 1 | X20: =SUM(H50:H53) -> 0 | Y20: =SUM(I50:I53) -> 10 | Z20: =SUM(J50:J53) -> 10 | ... AF20: =SUM(P50:P53) -> 739
B21: 09.45 - 10.00 | C21: 55 | D21: 23 | E21: 6 | F21: 16 | G21: 0 | H21: 0 | I21: 2 | J21: 2 | K21: 1 | L21: 1 | M21: 105 | N21: 0 | O21: =SUM(C21:L21,N21) -> 106 | P21: =SUM(C21:N21) -> 211 | R21: 1800-1900 | S21: =SUM(C54:C57) -> 141 | T21: =SUM(D54:D57) -> 54 | U21: =SUM(E54:E57) -> 23 | V21: =SUM(F54:F57) -> 40 | W21: =SUM(G54:G57) -> 2 | X21: =SUM(H54:H57) -> 0 | Y21: =SUM(I54:I57) -> 2 | Z21: =SUM(J54:J57) -> 3 | ... AF21: =SUM(P54:P57) -> 699
B22: 10.00 - 10.15 | C22: 47 | D22: 14 | E22: 9 | F22: 6 | G22: 0 | H22: 0 | I22: 5 | J22: 2 | K22: 2 | L22: 3 | M22: 128 | N22: 0 | O22: =SUM(C22:L22,N22) -> 88 | P22: =SUM(C22:N22) -> 216 | R22: AM Peak Hr | S22: =MAX(S10:S12) -> 331 | T22: =MAX(T10:T12) -> 190 | U22: =MAX(U10:U12) -> 41 | V22: =MAX(V10:V12) -> 56 | W22: =MAX(W10:W12) -> 3 | X22: =MAX(X10:X12) -> 0 | Y22: =MAX(Y10:Y12) -> 22 | Z22: =MAX(Z10:Z12) -> 9 | ... AF22: =MAX(AF10:AF12) -> 1283
B23: 10.15 - 10.30 | C23: 51 | D23: 27 | E23: 5 | F23: 9 | G23: 0 | H23: 0 | I23: 3 | J23: 2 | K23: 0 | L23: 2 | M23: 110 | N23: 0 | O23: =SUM(C23:L23,N23) -> 99 | P23: =SUM(C23:N23) -> 209 | R23: IP Peak Hr | S23: =MAX(S13:S18) -> 161 | T23: =MAX(T13:T18) -> 86 | U23: =MAX(U13:U18) -> 21 | V23: =MAX(V13:V18) -> 32 | W23: =MAX(W13:W18) -> 2 | X23: =MAX(X13:X18) -> 0 | Y23: =MAX(Y13:Y18) -> 16 | Z23: =MAX(Z13:Z18) -> 12 | ... AF23: =MAX(AF13:AF18) -> 751
B24: 10.30 - 10.45 | C24: 40 | D24: 22 | E24: 5 | F24: 8 | G24: 0 | H24: 0 | I24: 4 | J24: 5 | K24: 1 | L24: 1 | M24: 80 | N24: 0 | O24: =SUM(C24:L24,N24) -> 86 | P24: =SUM(C24:N24) -> 166 | R24: PM Peak Hr | S24: =MAX(S19:S21) -> 179 | T24: =MAX(T19:T21) -> 69 | U24: =MAX(U19:U21) -> 25 | V24: =MAX(V19:V21) -> 40 | W24: =MAX(W19:W21) -> 2 | X24: =MAX(X19:X21) -> 0 | Y24: =MAX(Y19:Y21) -> 13 | Z24: =MAX(Z19:Z21) -> 10 | ... AF24: =MAX(AF19:AF21) -> 787
B25: 10.45 - 11.00 | C25: 23 | D25: 23 | E25: 1 | F25: 6 | G25: 0 | H25: 0 | I25: 4 | J25: 3 | K25: 1 | L25: 2 | M25: 97 | N25: 0 | O25: =SUM(C25:L25,N25) -> 63 | P25: =SUM(C25:N25) -> 160 | R25: AM Period | S25: =SUM(S10:S12) -> 845 | T25: =SUM(T10:T12) -> 453 | U25: =SUM(U10:U12) -> 97 | V25: =SUM(V10:V12) -> 163 | W25: =SUM(W10:W12) -> 4 | X25: =SUM(X10:X12) -> 0 | Y25: =SUM(Y10:Y12) -> 62 | Z25: =SUM(Z10:Z12) -> 23 | ... AF25: =SUM(AF10:AF12) -> 3452
B26: 11.00 - 11.15 | C26: 34 | D26: 17 | E26: 3 | F26: 6 | G26: 0 | H26: 0 | I26: 3 | J26: 3 | K26: 0 | L26: 2 | M26: 100 | N26: 0 | O26: =SUM(C26:L26,N26) -> 68 | P26: =SUM(C26:N26) -> 168 | R26: IP Period | S26: =SUM(S13:S18) -> 869 | T26: =SUM(T13:T18) -> 357 | U26: =SUM(U13:U18) -> 111 | V26: =SUM(V13:V18) -> 173 | W26: =SUM(W13:W18) -> 4 | X26: =SUM(X13:X18) -> 0 | Y26: =SUM(Y13:Y18) -> 70 | Z26: =SUM(Z13:Z18) -> 63 | ... AF26: =SUM(AF13:AF18) -> 3993
B27: 11.15 - 11.30 | C27: 49 | D27: 13 | E27: 4 | F27: 9 | G27: 0 | H27: 0 | I27: 1 | J27: 2 | K27: 0 | L27: 1 | M27: 77 | N27: 0 | O27: =SUM(C27:L27,N27) -> 79 | P27: =SUM(C27:N27) -> 156 | R27: PM Period | S27: =SUM(S19:S21) -> 498 | T27: =SUM(T19:T21) -> 189 | U27: =SUM(U19:U21) -> 71 | V27: =SUM(V19:V21) -> 95 | W27: =SUM(W19:W21) -> 3 | X27: =SUM(X19:X21) -> 0 | Y27: =SUM(Y19:Y21) -> 25 | Z27: =SUM(Z19:Z21) -> 19 | ... AF27: =SUM(AF19:AF21) -> 2225
B28: 11.30 - 11.45 | C28: 35 | D28: 23 | E28: 4 | F28: 9 | G28: 0 | H28: 0 | I28: 0 | J28: 2 | K28: 3 | L28: 4 | M28: 98 | N28: 0 | O28: =SUM(C28:L28,N28) -> 80 | P28: =SUM(C28:N28) -> 178 | R28: 12 Hours | S28: =SUM(S10:S21) -> 2212 | T28: =SUM(T10:T21) -> 999 | U28: =SUM(U10:U21) -> 279 | V28: =SUM(V10:V21) -> 431 | W28: =SUM(W10:W21) -> 11 | X28: =SUM(X10:X21) -> 0 | Y28: =SUM(Y10:Y21) -> 157 | Z28: =SUM(Z10:Z21) -> 105 | ... AF28: =SUM(AF10:AF21) -> 9670
B29: 11.45 - 12.00 | C29: 35 | D29: 14 | E29: 7 | F29: 8 | G29: 0 | H29: 0 | I29: 4 | J29: 4 | K29: 0 | L29: 3 | M29: 65 | N29: 0 | O29: =SUM(C29:L29,N29) -> 75 | P29: =SUM(C29:N29) -> 140
B30: 12.00 - 12.15 | C30: 45 | D30: 13 | E30: 5 | F30: 8 | G30: 1 | H30: 0 | I30: 4 | J30: 1 | K30: 1 | L30: 6 | M30: 70 | N30: 0 | O30: =SUM(C30:L30,N30) -> 84 | P30: =SUM(C30:N30) -> 154
B31: 12.15 - 12.30 | C31: 36 | D31: 13 | E31: 4 | F31: 7 | G31: 1 | H31: 0 | I31: 3 | J31: 1 | K31: 1 | L31: 0 | M31: 102 | N31: 1 | O31: =SUM(C31:L31,N31) -> 67 | P31: =SUM(C31:N31) -> 169
B32: 12.30 - 12.45 | C32: 36 | D32: 17 | E32: 6 | F32: 7 | G32: 0 | H32: 0 | I32: 3 | J32: 4 | K32: 1 | L32: 5 | M32: 95 | N32: 0 | O32: =SUM(C32:L32,N32) -> 79 | P32: =SUM(C32:N32) -> 174
B33: 12.45 - 13.00 | C33: 31 | D33: 16 | E33: 4 | F33: 6 | G33: 0 | H33: 0 | I33: 2 | J33: 4 | K33: 0 | L33: 1 | M33: 125 | N33: 0 | O33: =SUM(C33:L33,N33) -> 64 | P33: =SUM(C33:N33) -> 189
B34: 13.00 - 13.15 | C34: 44 | D34: 13 | E34: 5 | F34: 7 | G34: 0 | H34: 0 | I34: 3 | J34: 3 | K34: 0 | L34: 1 | M34: 107 | N34: 0 | O34: =SUM(C34:L34,N34) -> 76 | P34: =SUM(C34:N34) -> 183
B35: 13.15 - 13.30 | C35: 32 | D35: 6 | E35: 4 | F35: 6 | G35: 0 | H35: 0 | I35: 4 | J35: 2 | K35: 0 | L35: 2 | M35: 115 | N35: 0 | O35: =SUM(C35:L35,N35) -> 56 | P35: =SUM(C35:N35) -> 171
B36: 13.30 - 13.45 | C36: 24 | D36: 11 | E36: 3 | F36: 7 | G36: 0 | H36: 0 | I36: 1 | J36: 1 | K36: 1 | L36: 2 | M36: 125 | N36: 0 | O36: =SUM(C36:L36,N36) -> 50 | P36: =SUM(C36:N36) -> 175
B37: 13.45 - 14.00 | C37: 23 | D37: 12 | E37: 5 | F37: 8 | G37: 0 | H37: 0 | I37: 1 | J37: 1 | K37: 1 | L37: 6 | M37: 90 | N37: 0 | O37: =SUM(C37:L37,N37) -> 57 | P37: =SUM(C37:N37) -> 147
B38: 14.00 - 14.15 | C38: 34 | D38: 11 | E38: 9 | F38: 11 | G38: 0 | H38: 0 | I38: 3 | J38: 3 | K38: 2 | L38: 3 | M38: 80 | N38: 0 | O38: =SUM(C38:L38,N38) -> 76 | P38: =SUM(C38:N38) -> 156
B39: 14.15 - 14.30 | C39: 32 | D39: 8 | E39: 2 | F39: 6 | G39: 1 | H39: 0 | I39: 3 | J39: 3 | K39: 3 | L39: 2 | M39: 110 | N39: 0 | O39: =SUM(C39:L39,N39) -> 60 | P39: =SUM(C39:N39) -> 170
B40: 14.30 - 14.45 | C40: 46 | D40: 19 | E40: 1 | F40: 7 | G40: 1 | H40: 0 | I40: 1 | J40: 2 | K40: 1 | L40: 2 | M40: 81 | N40: 0 | O40: =SUM(C40:L40,N40) -> 80 | P40: =SUM(C40:N40) -> 161
... B57: 18.45 - 19.00 | C57: 34 | D57: 18 | E57: 4 | F57: 8 | G57: 1 | H57: 0 | I57: 1 | J57: 2 | K57: 1 | L57: 1 | M57: 85 | N57: 0 | O57: =SUM(C57:L57,N57) -> 70 | P57: =SUM(C57:N57) -> 155
B58: Totals | C58: =SUM(C10:C57) -> 2212 | D58: =SUM(D10:D57) -> 999 | E58: =SUM(E10:E57) -> 279 | F58: =SUM(F10:F57) -> 431 | G58: =SUM(G10:G57) -> 11 | H58: =SUM(H10:H57) -> 0 | I58: =SUM(I10:I57) -> 157 | J58: =SUM(J10:J57) -> 105 | ... P58: =SUM(P10:P57) -> 9670
...

Sheet 30.07 Ntinda-Kisaasi
B1: Consultancy services for Preparation of Expressway Development Master Plan (EDMP) for Uganda
B2: MANUAL CLASSIFIED COUNT (MCC)
B3: ROAD NAME: | C3: ='29.07 Ntinda-Kisaasi'!C3:G3 -> MCC - C1 - STN33 - NTINDA ROAD
C5: Date | D5: ='30.07 Kisaasi-Ntinda'!D5 -> 30.07.19 | F5: Location | G5: ='29.07 Kisaasi-Ntinda'!G5:H5 -> Ndere Center | J5: Surveyor | K5: Okello Peter
C6: Dir. From | D6: ='29.07 Ntinda-Kisaasi'!D6:E6 -> Ntinda | F6: Dir. To | G6: ='29.07 Ntinda-Kisaasi'!G6:H6 -> Kisaasi | J6: Supervisor | K6: ='29.07 Kisaasi-Ntinda'!K6:L6 -> Steven
B8: Time / Veh Type | R8: SUMMARY TRAFFIC VOLUMES
C9: 1. Car | D9: 2. Station Wagon | E9: 3. Pickups | F9: 4. Minibus, matatu | G9: 5. Medium bus | H9: 6. Large Bus | I9: 7. Light Truck | J9: 8. Medium Truck | K9: 9. Heavy truck | L9: 10. Truck Trailer | M9: 11. Motor cycles | N9: 12. Tractors | O9: Total Excl M/Cycles | P9: Total All | R9: Time | S9: 1. Car | T9: 2. Station Wagon | U9: 3. Pickups | V9: 4. Minibus, matatu | W9: 5. Medium bus | X9: 6. Large Bus | Y9: 7. Light Truck | Z9: 8. Medium Truck | AA9: 9. Heavy truck | AB9: 10. Truck Trailer | AC9: 11. Motorcycles | AD9: 12. Tractors, Graders | AE9: Total Excl M/ Cycles | AF9: Total All
B10: 07.00 - 07.15 | C10: 22 | D10: 10 | E10: 5 | F10: 10 | G10: 0 | H10: 0 | I10: 10 | J10: 0 | K10: 0 | L10: 0 | M10: 50 | N10: 0 | O10: =SUM(C10:L10,N10) -> 57 | P10: =SUM(C10:N10) -> 107 | R10: 0700-0800 | S10: =SUM(C10:C13) -> 107 | T10: =SUM(D10:D13) -> 57 | U10: =SUM(E10:E13) -> 25 | V10: =SUM(F10:F13) -> 73 | W10: =SUM(G10:G13) -> 2 | X10: =SUM(H10:H13) -> 0 | Y10: =SUM(I10:I13) -> 16 | Z10: =SUM(J10:J13) -> 2 | ... AF10: =SUM(P10:P13) -> 539
B11: 07.15 - 07.30 | C11: 33 | D11: 16 | E11: 7 | F11: 9 | G11: 1 | H11: 0 | I11: 1 | J11: 1 | K11: 1 | L11: 1 | M11: 54 | N11: 0 | O11: =SUM(C11:L11,N11) -> 70 | P11: =SUM(C11:N11) -> 124 | R11: 0800-0900 | S11: =SUM(C14:C17) -> 94 | T11: =SUM(D14:D17) -> 38 | U11: =SUM(E14:E17) -> 14 | V11: =SUM(F14:F17) -> 86 | W11: =SUM(G14:G17) -> 1 | X11: =SUM(H14:H17) -> 0 | Y11: =SUM(I14:I17) -> 7 | Z11: =SUM(J14:J17) -> 5 | ... AF11: =SUM(P14:P17) -> 519
B12: 07.30 - 07.45 | C12: 26 | D12: 21 | E12: 10 | F12: 26 | G12: 1 | H12: 0 | I12: 4 | J12: 0 | K12: 0 | L12: 0 | M12: 71 | N12: 0 | O12: =SUM(C12:L12,N12) -> 88 | P12: =SUM(C12:N12) -> 159 | R12: 0900-1000 | S12: =SUM(C18:C21) -> 141 | T12: =SUM(D18:D21) -> 59 | U12: =SUM(E18:E21) -> 32 | V12: =SUM(F18:F21) -> 111 | W12: =SUM(G18:G21) -> 3 | X12: =SUM(H18:H21) -> 0 | Y12: =SUM(I18:I21) -> 13 | Z12: =SUM(J18:J21) -> 7 | ... AF12: =SUM(P18:P21) -> 720
B13: 07.45 - 08.00 | C13: 26 | D13: 10 | E13: 3 | F13: 28 | G13: 0 | H13: 0 | I13: 1 | J13: 1 | K13: 0 | L13: 0 | M13: 80 | N13: 0 | O13: =SUM(C13:L13,N13) -> 69 | P13: =SUM(C13:N13) -> 149 | R13: 1000-1100 | S13: =SUM(C22:C25) -> 131 | T13: =SUM(D22:D25) -> 58 | U13: =SUM(E22:E25) -> 38 | V13: =SUM(F22:F25) -> 92 | W13: =SUM(G22:G25) -> 3 | X13: =SUM(H22:H25) -> 0 | Y13: =SUM(I22:I25) -> 19 | Z13: =SUM(J22:J25) -> 5 | ... AF13: =SUM(P22:P25) -> 657
B14: 08.00 - 08.15 | C14: 23 | D14: 13 | E14: 8 | F14: 28 | G14: 1 | H14: 0 | I14: 0 | J14: 1 | K14: 2 | L14: 0 | M14: 85 | N14: 0 | O14: =SUM(C14:L14,N14) -> 76 | P14: =SUM(C14:N14) -> 161 | R14: 1100-1200 | S14: =SUM(C26:C29) -> 143 | T14: =SUM(D26:D29) -> 60 | U14: =SUM(E26:E29) -> 45 | V14: =SUM(F26:F29) -> 77 | W14: =SUM(G26:G29) -> 0 | X14: =SUM(H26:H29) -> 0 | Y14: =SUM(I26:I29) -> 26 | Z14: =SUM(J26:J29) -> 8 | ... AF14: =SUM(P26:P29) -> 667
B15: 08.15 - 08.30 | C15: 25 | D15: 7 | E15: 2 | F15: 32 | G15: 0 | H15: 0 | I15: 1 | J15: 1 | K15: 0 | L15: 1 | M15: 95 | N15: 0 | O15: =SUM(C15:L15,N15) -> 69 | P15: =SUM(C15:N15) -> 164 | R15: 1200-1300 | S15: =SUM(C30:C33) -> 144 | T15: =SUM(D30:D33) -> 72 | U15: =SUM(E30:E33) -> 41 | V15: =SUM(F30:F33) -> 80 | W15: =SUM(G30:G33) -> 0 | X15: =SUM(H30:H33) -> 0 | Y15: =SUM(I30:I33) -> 17 | Z15: =SUM(J30:J33) -> 14 | ... AF15: =SUM(P30:P33) -> 689
B16: 08.30 - 08.45 | C16: 32 | D16: 16 | E16: 3 | F16: 15 | G16: 0 | H16: 0 | I16: 5 | J16: 2 | K16: 0 | L16: 0 | M16: 55 | N16: 0 | O16: =SUM(C16:L16,N16) -> 73 | P16: =SUM(C16:N16) -> 128 | R16: 1300-1400 | S16: =SUM(C34:C37) -> 138 | T16: =SUM(D34:D37) -> 51 | U16: =SUM(E34:E37) -> 26 | V16: =SUM(F34:F37) -> 58 | W16: =SUM(G34:G37) -> 1 | X16: =SUM(H34:H37) -> 0 | Y16: =SUM(I34:I37) -> 18 | Z16: =SUM(J34:J37) -> 17 | ... AF16: =SUM(P34:P37) -> 641
B17: 08.45 - 9.00 | C17: 14 | D17: 2 | E17: 1 | F17: 11 | G17: 0 | H17: 0 | I17: 1 | J17: 1 | K17: 0 | L17: 1 | M17: 35 | N17: 0 | O17: =SUM(C17:L17,N17) -> 31 | P17: =SUM(C17:N17) -> 66 | R17: 1400-1500 | S17: =SUM(C38:C41) -> 138 | T17: =SUM(D38:D41) -> 71 | U17: =SUM(E38:E41) -> 18 | V17: =SUM(F38:F41) -> 56 | W17: =SUM(G38:G41) -> 4 | X17: =SUM(H38:H41) -> 0 | Y17: =SUM(I38:I41) -> 18 | Z17: =SUM(J38:J41) -> 9 | ... AF17: =SUM(P38:P41) -> 635
B18: 09.00 - 09.15 | C18: 31 | D18: 8 | E18: 6 | F18: 28 | G18: 2 | H18: 0 | I18: 4 | J18: 2 | K18: 0 | L18: 2 | M18: 100 | N18: 0 | O18: =SUM(C18:L18,N18) -> 83 | P18: =SUM(C18:N18) -> 183 | R18: 1500-1600 | S18: =SUM(C42:C45) -> 119 | T18: =SUM(D42:D45) -> 65 | U18: =SUM(E42:E45) -> 32 | V18: =SUM(F42:F45) -> 60 | W18: =SUM(G42:G45) -> 3 | X18: =SUM(H42:H45) -> 0 | Y18: =SUM(I42:I45) -> 7 | Z18: =SUM(J42:J45) -> 8 | ... AF18: =SUM(P42:P45) -> 542
B19: 09.15 - 09.30 | C19: 37 | D19: 12 | E19: 9 | F19: 32 | G19: 1 | H19: 0 | I19: 4 | J19: 3 | K19: 0 | L19: 0 | M19: 85 | N19: 0 | O19: =SUM(C19:L19,N19) -> 98 | P19: =SUM(C19:N19) -> 183 | R19: 1600-1700 | S19: =SUM(C46:C49) -> 222 | T19: =SUM(D46:D49) -> 137 | U19: =SUM(E46:E49) -> 33 | V19: =SUM(F46:F49) -> 50 | W19: =SUM(G46:G49) -> 2 | X19: =SUM(H46:H49) -> 0 | Y19: =SUM(I46:I49) -> 26 | Z19: =SUM(J46:J49) -> 10 | ... AF19: =SUM(P46:P49) -> 851
B20: 09.30 - 09.45 | C20: 47 | D20: 23 | E20: 10 | F20: 29 | G20: 0 | H20: 0 | I20: 2 | J20: 1 | K20: 0 | L20: 0 | M20: 91 | N20: 0 | O20: =SUM(C20:L20,N20) -> 112 | P20: =SUM(C20:N20) -> 203 | R20: 1700-1800 | S20: =SUM(C50:C53) -> 338 | T20: =SUM(D50:D53) -> 133 | U20: =SUM(E50:E53) -> 40 | V20: =SUM(F50:F53) -> 48 | W20: =SUM(G50:G53) -> 4 | X20: =SUM(H50:H53) -> 0 | Y20: =SUM(I50:I53) -> 8 | Z20: =SUM(J50:J53) -> 9 | ... AF20: =SUM(P50:P53) -> 1118
B21: 09.45 - 10.00 | C21: 26 | D21: 16 | E21: 7 | F21: 22 | G21: 0 | H21: 0 | I21: 3 | J21: 1 | K21: 0 | L21: 1 | M21: 75 | N21: 0 | O21: =SUM(C21:L21,N21) -> 76 | P21: =SUM(C21:N21) -> 151 | R21: 1800-1900 | S21: =SUM(C54:C57) -> 274 | T21: =SUM(D54:D57) -> 145 | U21: =SUM(E54:E57) -> 40 | V21: =SUM(F54:F57) -> 67 | W21: =SUM(G54:G57) -> 1 | X21: =SUM(H54:H57) -> 0 | Y21: =SUM(I54:I57) -> 11 | Z21: =SUM(J54:J57) -> 7 | ... AF21: =SUM(P54:P57) -> 886
B22: 10.00 - 10.15 | C22: 25 | D22: 9 | E22: 8 | F22: 22 | G22: 1 | H22: 0 | I22: 5 | J22: 2 | K22: 0 | L22: 5 | M22: 77 | N22: 0 | O22: =SUM(C22:L22,N22) -> 77 | P22: =SUM(C22:N22) -> 154 | R22: AM Peak Hr | S22: =MAX(S10:S12) -> 141 | T22: =MAX(T10:T12) -> 59 | U22: =MAX(U10:U12) -> 32 | V22: =MAX(V10:V12) -> 111 | W22: =MAX(W10:W12) -> 3 | X22: =MAX(X10:X12) -> 0 | Y22: =MAX(Y10:Y12) -> 16 | Z22: =MAX(Z10:Z12) -> 7 | ... AF22: =MAX(AF10:AF12) -> 720
B23: 10.15 - 10.30 | C23: 56 | D23: 17 | E23: 19 | F23: 34 | G23: 0 | H23: 0 | I23: 7 | J23: 1 | K23: 0 | L23: 0 | M23: 110 | N23: 0 | O23: =SUM(C23:L23,N23) -> 134 | P23: =SUM(C23:N23) -> 244 | R23: IP Peak Hr | S23: =MAX(S13:S18) -> 144 | T23: =MAX(T13:T18) -> 72 | U23: =MAX(U13:U18) -> 45 | V23: =MAX(V13:V18) -> 92 | W23: =MAX(W13:W18) -> 4 | X23: =MAX(X13:X18) -> 0 | Y23: =MAX(Y13:Y18) -> 26 | Z23: =MAX(Z13:Z18) -> 17 | ... AF23: =MAX(AF13:AF18) -> 689
B24: 10.30 - 10.45 | C24: 21 | D24: 15 | E24: 8 | F24: 16 | G24: 1 | H24: 0 | I24: 3 | J24: 1 | K24: 1 | L24: 1 | M24: 35 | N24: 0 | O24: =SUM(C24:L24,N24) -> 67 | P24: =SUM(C24:N24) -> 102 | R24: PM Peak Hr | S24: =MAX(S19:S21) -> 338 | T24: =MAX(T19:T21) -> 145 | U24: =MAX(U19:U21) -> 40 | V24: =MAX(V19:V21) -> 67 | W24: =MAX(W19:W21) -> 4 | X24: =MAX(X19:X21) -> 0 | Y24: =MAX(Y19:Y21) -> 26 | Z24: =MAX(Z19:Z21) -> 10 | ... AF24: =MAX(AF19:AF21) -> 1118
B25: 10.45 - 11.00 | C25: 29 | D25: 17 | E25: 3 | F25: 20 | G25: 1 | H25: 0 | I25: 4 | J25: 1 | K25: 0 | L25: 5 | M25: 77 | N25: 0 | O25: =SUM(C25:L25,N25) -> 80 | P25: =SUM(C25:N25) -> 157 | R25: AM Period | S25: =SUM(S10:S12) -> 342 | T25: =SUM(T10:T12) -> 154 | U25: =SUM(U10:U12) -> 71 | V25: =SUM(V10:V12) -> 270 | W25: =SUM(W10:W12) -> 6 | X25: =SUM(X10:X12) -> 0 | Y25: =SUM(Y10:Y12) -> 36 | Z25: =SUM(Z10:Z12) -> 14 | ... AF25: =SUM(AF10:AF12) -> 1778
B26: 11.00 - 11.15 | C26: 45 | D26: 15 | E26: 13 | F26: 23 | G26: 0 | H26: 0 | I26: 10 | J26: 3 | K26: 0 | L26: 5 | M26: 95 | N26: 0 | O26: =SUM(C26:L26,N26) -> 114 | P26: =SUM(C26:N26) -> 209 | R26: IP Period | S26: =SUM(S13:S18) -> 813 | T26: =SUM(T13:T18) -> 377 | U26: =SUM(U13:U18) -> 200 | V26: =SUM(V13:V18) -> 423 | W26: =SUM(W13:W18) -> 11 | X26: =SUM(X13:X18) -> 0 | Y26: =SUM(Y13:Y18) -> 105 | Z26: =SUM(Z13:Z18) -> 61 | ... AF26: =SUM(AF13:AF18) -> 3831
B27: 11.15 - 11.30 | C27: 60 | D27: 14 | E27: 13 | F27: 16 | G27: 0 | H27: 0 | I27: 3 | J27: 2 | K27: 0 | L27: 7 | M27: 77 | N27: 0 | O27: =SUM(C27:L27,N27) -> 115 | P27: =SUM(C27:N27) -> 192 | R27: PM Period | S27: =SUM(S19:S21) -> 834 | T27: =SUM(T19:T21) -> 415 | U27: =SUM(U19:U21) -> 113 | V27: =SUM(V19:V21) -> 165 | W27: =SUM(W19:W21) -> 7 | X27: =SUM(X19:X21) -> 0 | Y27: =SUM(Y19:Y21) -> 45 | Z27: =SUM(Z19:Z21) -> 26 | ... AF27: =SUM(AF19:AF21) -> 2855
B28: 11.30 - 11.45 | C28: 23 | D28: 16 | E28: 12 | F28: 29 | G28: 0 | H28: 0 | I28: 6 | J28: 2 | K28: 1 | L28: 3 | M28: 71 | N28: 0 | O28: =SUM(C28:L28,N28) -> 92 | P28: =SUM(C28:N28) -> 163 | R28: 12 Hours | S28: =SUM(S10:S21) -> 1989 | T28: =SUM(T10:T21) -> 946 | U28: =SUM(U10:U21) -> 384 | V28: =SUM(V10:V21) -> 858 | W28: =SUM(W10:W21) -> 24 | X28: =SUM(X10:X21) -> 0 | Y28: =SUM(Y10:Y21) -> 186 | Z28: =SUM(Z10:Z21) -> 101 | ... AF28: =SUM(AF10:AF21) -> 8464
B29: 11.45 - 12.00 | C29: 15 | D29: 15 | E29: 7 | F29: 9 | G29: 0 | H29: 0 | I29: 7 | J29: 1 | K29: 1 | L29: 3 | M29: 45 | N29: 0 | O29: =SUM(C29:L29,N29) -> 58 | P29: =SUM(C29:N29) -> 103
B30: 12.00 - 12.15 | C30: 40 | D30: 16 | E30: 12 | F30: 21 | G30: 0 | H30: 0 | I30: 6 | J30: 6 | K30: 0 | L30: 7 | M30: 80 | N30: 0 | O30: =SUM(C30:L30,N30) -> 108 | P30: =SUM(C30:N30) -> 188
B31: 12.15 - 12.30 | C31: 27 | D31: 10 | E31: 11 | F31: 24 | G31: 0 | H31: 0 | I31: 1 | J31: 1 | K31: 0 | L31: 1 | M31: 70 | N31: 0 | O31: =SUM(C31:L31,N31) -> 75 | P31: =SUM(C31:N31) -> 145
B32: 12.30 - 12.45 | C32: 38 | D32: 24 | E32: 8 | F32: 17 | G32: 0 | H32: 0 | I32: 4 | J32: 4 | K32: 1 | L32: 5 | M32: 72 | N32: 0 | O32: =SUM(C32:L32,N32) -> 101 | P32: =SUM(C32:N32) -> 173
B33: 12.45 - 13.00 | C33: 39 | D33: 22 | E33: 10 | F33: 18 | G33: 0 | H33: 0 | I33: 6 | J33: 3 | K33: 1 | L33: 3 | M33: 81 | N33: 0 | O33: =SUM(C33:L33,N33) -> 102 | P33: =SUM(C33:N33) -> 183
B34: 13.00 - 13.15 | C34: 39 | D34: 17 | E34: 3 | F34: 20 | G34: 1 | H34: 0 | I34: 9 | J34: 7 | K34: 2 | L34: 2 | M34: 88 | N34: 0 | O34: =SUM(C34:L34,N34) -> 100 | P34: =SUM(C34:N34) -> 188
B35: 13.15 - 13.30 | C35: 31 | D35: 15 | E35: 6 | F35: 16 | G35: 0 | H35: 0 | I35: 1 | J35: 4 | K35: 2 | L35: 3 | M35: 100 | N35: 0 | O35: =SUM(C35:L35,N35) -> 78 | P35: =SUM(C35:N35) -> 178
B36: 13.30 - 13.45 | C36: 28 | D36: 11 | E36: 6 | F36: 7 | G36: 0 | H36: 0 | I36: 5 | J36: 2 | K36: 0 | L36: 3 | M36: 45 | N36: 0 | O36: =SUM(C36:L36,N36) -> 62 | P36: =SUM(C36:N36) -> 107
B37: 13.45 - 14.00 | C37: 40 | D37: 8 | E37: 11 | F37: 15 | G37: 0 | H37: 0 | I37: 3 | J37: 4 | K37: 0 | L37: 0 | M37: 87 | N37: 0 | O37: =SUM(C37:L37,N37) -> 81 | P37: =SUM(C37:N37) -> 168
B38: 14.00 - 14.15 | C38: 40 | D38: 17 | E38: 5 | F38: 15 | G38: 0 | H38: 0 | I38: 4 | J38: 3 | K38: 0 | L38: 1 | M38: 78 | N38: 0 | O38: =SUM(C38:L38,N38) -> 85 | P38: =SUM(C38:N38) -> 163
B39: 14.15 - 14.30 | C39: 34 | D39: 13 | E39: 7 | F39: 11 | G39: 0 | H39: 0 | I39: 3 | J39: 1 | K39: 0 | L39: 2 | M39: 80 | N39: 0 | O39: =SUM(C39:L39,N39) -> 71 | P39: =SUM(C39:N39) -> 151
B40: 14.30 - 14.45 | C40: 39 | D40: 24 | E40: 2 | F40: 16 | G40: 4 | H40: 0 | I40: 7 | J40: 2 | K40: 0 | L40: 2 | M40: 91 | N40: 0 | O40: =SUM(C40:L40,N40) -> 96 | P40: =SUM(C40:N40) -> 187
... B57: 18.45 - 19.00 | C57: 66 | D57: 32 | E57: 6 | F57: 11 | G57: 1 | H57: 0 | I57: 2 | J57: 0 | K57: 0 | L57: 1 | M57: 75 | N57: 0 | O57: =SUM(C57:L57,N57) -> 119 | P57: =SUM(C57:N57) -> 194
B58: Totals | C58: =SUM(C10:C57) -> 1989 | D58: =SUM(D10:D57) -> 946 | E58: =SUM(E10:E57) -> 384 | F58: =SUM(F10:F57) -> 858 | G58: =SUM(G10:G57) -> 24 | H58: =SUM(H10:H57) -> 0 | I58: =SUM(I10:I57) -> 186 | J58: =SUM(J10:J57) -> 101 | ... P58: =SUM(P10:P57) -> 8464
...

Sheet 31.07 Kisaasi-Ntinda
B1: Consultancy services for Preparation of Expressway Development Master Plan (EDMP) for Uganda
B2: MANUAL CLASSIFIED COUNT (MCC)
B3: ROAD NAME: | C3: ='29.07 Kisaasi-Ntinda'!C3:G3 -> MCC - C1 - STN33 - NTINDA ROAD
C5: Date | D5: 31.07.19 | F5: Location | G5: ='29.07 Kisaasi-Ntinda'!G5:H5 -> Ndere Center | J5: Surveyor | K5: Jonathan & Omaset Jerome
C6: Dir. From | D6: ='29.07 Kisaasi-Ntinda'!D6:E6 -> Kisaasi | F6: Dir. To | G6: ='29.07 Kisaasi-Ntinda'!G6:H6 -> Ntinda | J6: Supervisor | K6: ='29.07 Kisaasi-Ntinda'!K6:L6 -> Steven
B8: Time / Veh Type | R8: SUMMARY TRAFFIC VOLUMES
C9: 1. Car | D9: 2. Station Wagon | E9: 3. Pickups | F9: 4. Minibus, matatu | G9: 5. Medium bus | H9: 6. Large Bus | I9: 7. Light Truck | J9: 8. Medium Truck | K9: 9. Heavy truck | L9: 10. Truck Trailer | M9: 11. Motor cycles | N9: 12. Tractors | O9: Total Excl M/Cycles | P9: Total All | R9: Time | S9: 1. Car | T9: 2. Station Wagon | U9: 3. Pickups | V9: 4. Minibus, matatu | W9: 5. Medium bus | X9: 6. Large Bus | Y9: 7. Light Truck | Z9: 8. Medium Truck | AA9: 9. Heavy truck | AB9: 10. Truck Trailer | AC9: 11. Motorcycles | AD9: 12. Tractors, Graders | AE9: Total Excl M/ Cycles | AF9: Total All
B10: 07.00 - 07.15 | C10: 103 | D10: 51 | E10: 14 | F10: 19 | G10: 0 | H10: 0 | I10: 1 | J10: 1 | K10: 0 | L10: 0 | M10: 105 | N10: 0 | O10: =SUM(C10:L10,N10) -> 189 | P10: =SUM(C10:N10) -> 294 | R10: 0700-0800 | S10: =SUM(C10:C13) -> 459 | T10: =SUM(D10:D13) -> 256 | U10: =SUM(E10:E13) -> 59 | V10: =SUM(F10:F13) -> 70 | W10: =SUM(G10:G13) -> 2 | X10: =SUM(H10:H13) -> 0 | Y10: =SUM(I10:I13) -> 14 | Z10: =SUM(J10:J13) -> 6 | ... AF10: =SUM(P10:P13) -> 1487
B11: 07.15 - 07.30 | C11: 112 | D11: 62 | E11: 16 | F11: 14 | G11: 0 | H11: 0 | I11: 5 | J11: 1 | K11: 0 | L11: 1 | M11: 135 | N11: 0 | O11: =SUM(C11:L11,N11) -> 211 | P11: =SUM(C11:N11) -> 346 | R11: 0800-0900 | S11: =SUM(C14:C17) -> 330 | T11: =SUM(D14:D17) -> 135 | U11: =SUM(E14:E17) -> 32 | V11: =SUM(F14:F17) -> 63 | W11: =SUM(G14:G17) -> 3 | X11: =SUM(H14:H17) -> 0 | Y11: =SUM(I14:I17) -> 14 | Z11: =SUM(J14:J17) -> 7 | ... AF11: =SUM(P14:P17) -> 1213
B12: 07.30 - 07.45 | C12: 130 | D12: 68 | E12: 14 | F12: 22 | G12: 1 | H12: 0 | I12: 4 | J12: 2 | K12: 0 | L12: 1 | M12: 195 | N12: 0 | O12: =SUM(C12:L12,N12) -> 242 | P12: =SUM(C12:N12) -> 437 | R12: 0900-1000 | S12: =SUM(C18:C21) -> 234 | T12: =SUM(D18:D21) -> 130 | U12: =SUM(E18:E21) -> 21 | V12: =SUM(F18:F21) -> 45 | W12: =SUM(G18:G21) -> 0 | X12: =SUM(H18:H21) -> 0 | Y12: =SUM(I18:I21) -> 21 | Z12: =SUM(J18:J21) -> 14 | ... AF12: =SUM(P18:P21) -> 1042
B13: 07.45 - 08.00 | C13: 114 | D13: 75 | E13: 15 | F13: 15 | G13: 1 | H13: 0 | I13: 4 | J13: 2 | K13: 1 | L13: 2 | M13: 181 | N13: 0 | O13: =SUM(C13:L13,N13) -> 229 | P13: =SUM(C13:N13) -> 410 | R13: 1000-1100 | S13: =SUM(C22:C25) -> 165 | T13: =SUM(D22:D25) -> 58 | U13: =SUM(E22:E25) -> 14 | V13: =SUM(F22:F25) -> 31 | W13: =SUM(G22:G25) -> 0 | X13: =SUM(H22:H25) -> 0 | Y13: =SUM(I22:I25) -> 18 | Z13: =SUM(J22:J25) -> 7 | ... AF13: =SUM(P22:P25) -> 665
B14: 08.00 - 08.15 | C14: 120 | D14: 52 | E14: 12 | F14: 21 | G14: 0 | H14: 0 | I14: 4 | J14: 2 | K14: 1 | L14: 0 | M14: 150 | N14: 0 | O14: =SUM(C14:L14,N14) -> 212 | P14: =SUM(C14:N14) -> 362 | R14: 1100-1200 | S14: =SUM(C26:C29) -> 129 | T14: =SUM(D26:D29) -> 45 | U14: =SUM(E26:E29) -> 19 | V14: =SUM(F26:F29) -> 27 | W14: =SUM(G26:G29) -> 0 | X14: =SUM(H26:H29) -> 0 | Y14: =SUM(I26:I29) -> 16 | Z14: =SUM(J26:J29) -> 11 | ... AF14: =SUM(P26:P29) -> 595
B15: 08.15 - 08.30 | C15: 92 | D15: 35 | E15: 10 | F15: 17 | G15: 1 | H15: 0 | I15: 2 | J15: 3 | K15: 0 | L15: 1 | M15: 180 | N15: 0 | O15: =SUM(C15:L15,N15) -> 161 | P15: =SUM(C15:N15) -> 341 | R15: 1200-1300 | S15: =SUM(C30:C33) -> 156 | T15: =SUM(D30:D33) -> 64 | U15: =SUM(E30:E33) -> 15 | V15: =SUM(F30:F33) -> 30 | W15: =SUM(G30:G33) -> 1 | X15: =SUM(H30:H33) -> 0 | Y15: =SUM(I30:I33) -> 13 | Z15: =SUM(J30:J33) -> 11 | ... AF15: =SUM(P30:P33) -> 662
B16: 08.30 - 08.45 | C16: 59 | D16: 28 | E16: 2 | F16: 13 | G16: 0 | H16: 0 | I16: 4 | J16: 1 | K16: 1 | L16: 4 | M16: 140 | N16: 0 | O16: =SUM(C16:L16,N16) -> 112 | P16: =SUM(C16:N16) -> 252 | R16: 1300-1400 | S16: =SUM(C34:C37) -> 130 | T16: =SUM(D34:D37) -> 65 | U16: =SUM(E34:E37) -> 29 | V16: =SUM(F34:F37) -> 36 | W16: =SUM(G34:G37) -> 0 | X16: =SUM(H34:H37) -> 0 | Y16: =SUM(I34:I37) -> 13 | Z16: =SUM(J34:J37) -> 8 | ... AF16: =SUM(P34:P37) -> 690
B17: 08.45 - 9.00 | C17: 59 | D17: 20 | E17: 8 | F17: 12 | G17: 2 | H17: 0 | I17: 4 | J17: 1 | K17: 0 | L17: 2 | M17: 150 | N17: 0 | O17: =SUM(C17:L17,N17) -> 108 | P17: =SUM(C17:N17) -> 258 | R17: 1400-1500 | S17: =SUM(C38:C41) -> 169 | T17: =SUM(D38:D41) -> 59 | U17: =SUM(E38:E41) -> 19 | V17: =SUM(F38:F41) -> 31 | W17: =SUM(G38:G41) -> 10 | X17: =SUM(H38:H41) -> 0 | Y17: =SUM(I38:I41) -> 16 | Z17: =SUM(J38:J41) -> 7 | ... AF17: =SUM(P38:P41) -> 700
B18: 09.00 - 09.15 | C18: 62 | D18: 48 | E18: 6 | F18: 10 | G18: 0 | H18: 0 | I18: 6 | J18: 4 | K18: 0 | L18: 1 | M18: 153 | N18: 0 | O18: =SUM(C18:L18,N18) -> 137 | P18: =SUM(C18:N18) -> 290 | R18: 1500-1600 | S18: =SUM(C42:C45) -> 175 | T18: =SUM(D42:D45) -> 58 | U18: =SUM(E42:E45) -> 29 | V18: =SUM(F42:F45) -> 34 | W18: =SUM(G42:G45) -> 0 | X18: =SUM(H42:H45) -> 0 | Y18: =SUM(I42:I45) -> 20 | Z18: =SUM(J42:J45) -> 9 | ... AF18: =SUM(P42:P45) -> 679
B19: 09.15 - 09.30 | C19: 56 | D19: 17 | E19: 3 | F19: 11 | G19: 0 | H19: 0 | I19: 4 | J19: 3 | K19: 1 | L19: 1 | M19: 141 | N19: 0 | O19: =SUM(C19:L19,N19) -> 96 | P19: =SUM(C19:N19) -> 237 | R19: 1600-1700 | S19: =SUM(C46:C49) -> 203 | T19: =SUM(D46:D49) -> 76 | U19: =SUM(E46:E49) -> 16 | V19: =SUM(F46:F49) -> 36 | W19: =SUM(G46:G49) -> 1 | X19: =SUM(H46:H49) -> 0 | Y19: =SUM(I46:I49) -> 17 | Z19: =SUM(J46:J49) -> 8 | ... AF19: =SUM(P46:P49) -> 803
B20: 09.30 - 09.45 | C20: 66 | D20: 30 | E20: 7 | F20: 11 | G20: 0 | H20: 0 | I20: 6 | J20: 3 | K20: 1 | L20: 1 | M20: 160 | N20: 0 | O20: =SUM(C20:L20,N20) -> 125 | P20: =SUM(C20:N20) -> 285 | R20: 1700-1800 | S20: =SUM(C50:C53) -> 225 | T20: =SUM(D50:D53) -> 69 | U20: =SUM(E50:E53) -> 15 | V20: =SUM(F50:F53) -> 48 | W20: =SUM(G50:G53) -> 2 | X20: =SUM(H50:H53) -> 0 | Y20: =SUM(I50:I53) -> 20 | Z20: =SUM(J50:J53) -> 7 | ... AF20: =SUM(P50:P53) -> 843
B21: 09.45 - 10.00 | C21: 50 | D21: 35 | E21: 5 | F21: 13 | G21: 0 | H21: 0 | I21: 5 | J21: 4 | K21: 0 | L21: 0 | M21: 118 | N21: 0 | O21: =SUM(C21:L21,N21) -> 112 | P21: =SUM(C21:N21) -> 230 | R21: 1800-1900 | S21: =SUM(C54:C57) -> 151 | T21: =SUM(D54:D57) -> 52 | U21: =SUM(E54:E57) -> 17 | V21: =SUM(F54:F57) -> 38 | W21: =SUM(G54:G57) -> 0 | X21: =SUM(H54:H57) -> 0 | Y21: =SUM(I54:I57) -> 12 | Z21: =SUM(J54:J57) -> 5 | ... AF21: =SUM(P54:P57) -> 663
B22: 10.00 - 10.15 | C22: 30 | D22: 7 | E22: 1 | F22: 3 | G22: 0 | H22: 0 | I22: 4 | J22: 2 | K22: 0 | L22: 0 | M22: 90 | N22: 0 | O22: =SUM(C22:L22,N22) -> 47 | P22: =SUM(C22:N22) -> 137 | R22: AM Peak Hr | S22: =MAX(S10:S12) -> 459 | T22: =MAX(T10:T12) -> 256 | U22: =MAX(U10:U12) -> 59 | V22: =MAX(V10:V12) -> 70 | W22: =MAX(W10:W12) -> 3 | X22: =MAX(X10:X12) -> 0 | Y22: =MAX(Y10:Y12) -> 21 | Z22: =MAX(Z10:Z12) -> 14 | ... AF22: =MAX(AF10:AF12) -> 1487
B23: 10.15 - 10.30 | C23: 55 | D23: 21 | E23: 3 | F23: 8 | G23: 0 | H23: 0 | I23: 3 | J23: 1 | K23: 0 | L23: 1 | M23: 100 | N23: 0 | O23: =SUM(C23:L23,N23) -> 92 | P23: =SUM(C23:N23) -> 192 | R23: IP Peak Hr | S23: =MAX(S13:S18) -> 175 | T23: =MAX(T13:T18) -> 65 | U23: =MAX(U13:U18) -> 29 | V23: =MAX(V13:V18) -> 36 | W23: =MAX(W13:W18) -> 10 | X23: =MAX(X13:X18) -> 0 | Y23: =MAX(Y13:Y18) -> 20 | Z23: =MAX(Z13:Z18) -> 11 | ... AF23: =MAX(AF13:AF18) -> 700
B24: 10.30 - 10.45 | C24: 52 | D24: 24 | E24: 5 | F24: 8 | G24: 0 | H24: 0 | I24: 3 | J24: 1 | K24: 0 | L24: 3 | M24: 81 | N24: 0 | O24: =SUM(C24:L24,N24) -> 96 | P24: =SUM(C24:N24) -> 177 | R24: PM Peak Hr | S24: =MAX(S19:S21) -> 225 | T24: =MAX(T19:T21) -> 76 | U24: =MAX(U19:U21) -> 17 | V24: =MAX(V19:V21) -> 48 | W24: =MAX(W19:W21) -> 2 | X24: =MAX(X19:X21) -> 0 | Y24: =MAX(Y19:Y21) -> 20 | Z24: =MAX(Z19:Z21) -> 8 | ... AF24: =MAX(AF19:AF21) -> 843
B25: 10.45 - 11.00 | C25: 28 | D25: 6 | E25: 5 | F25: 12 | G25: 0 | H25: 0 | I25: 8 | J25: 3 | K25: 0 | L25: 0 | M25: 97 | N25: 0 | O25: =SUM(C25:L25,N25) -> 62 | P25: =SUM(C25:N25) -> 159 | R25: AM Period | S25: =SUM(S10:S12) -> 1023 | T25: =SUM(T10:T12) -> 521 | U25: =SUM(U10:U12) -> 112 | V25: =SUM(V10:V12) -> 178 | W25: =SUM(W10:W12) -> 5 | X25: =SUM(X10:X12) -> 0 | Y25: =SUM(Y10:Y12) -> 49 | Z25: =SUM(Z10:Z12) -> 27 | ... AF25: =SUM(AF10:AF12) -> 3742
B26: 11.00 - 11.15 | C26: 34 | D26: 12 | E26: 7 | F26: 6 | G26: 0 | H26: 0 | I26: 2 | J26: 1 | K26: 0 | L26: 1 | M26: 90 | N26: 0 | O26: =SUM(C26:L26,N26) -> 63 | P26: =SUM(C26:N26) -> 153 | R26: IP Period | S26: =SUM(S13:S18) -> 924 | T26: =SUM(T13:T18) -> 349 | U26: =SUM(U13:U18) -> 125 | V26: =SUM(V13:V18) -> 189 | W26: =SUM(W13:W18) -> 11 | X26: =SUM(X13:X18) -> 0 | Y26: =SUM(Y13:Y18) -> 96 | Z26: =SUM(Z13:Z18) -> 53 | ... AF26: =SUM(AF13:AF18) -> 3991
B27: 11.15 - 11.30 | C27: 31 | D27: 14 | E27: 6 | F27: 9 | G27: 0 | H27: 0 | I27: 5 | J27: 2 | K27: 0 | L27: 1 | M27: 76 | N27: 0 | O27: =SUM(C27:L27,N27) -> 68 | P27: =SUM(C27:N27) -> 144 | R27: PM Period | S27: =SUM(S19:S21) -> 579 | T27: =SUM(T19:T21) -> 197 | U27: =SUM(U19:U21) -> 48 | V27: =SUM(V19:V21) -> 122 | W27: =SUM(W19:W21) -> 3 | X27: =SUM(X19:X21) -> 0 | Y27: =SUM(Y19:Y21) -> 49 | Z27: =SUM(Z19:Z21) -> 20 | ... AF27: =SUM(AF19:AF21) -> 2309
