Workbook
Name Veh_Type: Soroti!$H$8:$H$153
Name zones: #REF!
Name Zones_Ndeke: #REF!

Sheet Soroti
C1: Consultancy services for Preparation of Expressway Development Master Plan (EDMP) for Uganda
C2: Stated Preferance Survey
D4: Town | E4: SOROTI | I4: Interviewer: | J4: ROBINAH | N4: Supervisor: | O4: DENIS | R4: Coded By: | S4: RUTH | W4: Chkd By: | X4: Deo B. M
B6: Date | C6: Time (24-h format) | D6: Veh_Reg_No. | E6: Driver or Passenger? D/P | F6: Mode No. | G6: Mode Description | H6: Veh_Type | I6: Veh_Type Desc | J6: Gender (M/F) | K6: Age Bracket No. | L6: Age Bracket Desc. | M6: Origin_Address | P6: Origin_Purpose | Q6: Origin-Purpose Desc | R6: Destination_Address | U6: Destination_Purpose | V6: Destination_Purpose Desc | W6: Journey_Purpose | X6: Cost of Trip (UGX) | Y6: Journey Dist (Km) | Z6: Journey Time (Hrs) | AA6: Profession No. | AB6: Profession Desc. | AC6: Monthly Income No. | AD6: Monthly Income | AE6: Rank of Issues NOT OK with Journey | AJ6: Would You Use Xpressways? Y/N | AK6: Pay How Much? (UGX) | AL6: Origin_Zone | AM6: Dest_Zone
M7: Village or Town | N7: District | O7: Country | R7: Village or Town | S7: District | T7: Country | AE7: Journey Time | AF7: Cost of Journey | AG7: Comfort | AH7: Safety | AI7: Reliability
B8: 43696 | C8: 0.375 | E8: D | F8: 2 | G8: =VLOOKUP(F8,Key!$A$17:$B$21,2,FALSE) -> Road Vehicle | H8: 1 | I8: =VLOOKUP(H8,Key!$A$2:$B$13,2,FALSE) -> Car | J8: F | K8: 1 | L8: =VLOOKUP(K8,Key!$A$24:$B$29,2,FALSE) -> 20-29 | M8: KOBIL | N8: KOBIL | O8: UGA | P8: 1 | Q8: =VLOOKUP(P8,Key!$E$2:$F$9,2,FALSE) -> Home | R8: SOROTI | S8: SOROTI | T8: UGA | U8: 2 | V8: =VLOOKUP(U8,Key!$E$2:$F$9,2,FALSE) -> Work | W8: =Q8&"-"&V8 -> Home-Work | X8: 40000 | Y8: 10 | Z8: 0.5 | AA8: 4 | AB8: =VLOOKUP(AA8,Key!$C$20:$D$29,2,FALSE) -> Office Worker | AC8: 4 | AD8: =VLOOKUP(AC8,Key!$E$20:$F$24,2,FALSE) -> 750,000-1,000,000 | AE8: 3 | AF8: 1 | AG8: 2 | AH8: 4 | AI8: 5 | AJ8: Y | AK8: 4000
B9: 43695 | C9: 0.3875 | E9: P | F9: 2 | G9: =VLOOKUP(F9,Key!$A$17:$B$21,2,FALSE) -> Road Vehicle | H9: 1 | I9: =VLOOKUP(H9,Key!$A$2:$B$13,2,FALSE) -> Car | J9: F | K9: 1 | L9: =VLOOKUP(K9,Key!$A$24:$B$29,2,FALSE) -> 20-29 | M9: SOROTI | N9: SOROTI | O9: UGA | P9: 1 | Q9: =VLOOKUP(P9,Key!$E$2:$F$9,2,FALSE) -> Home | R9: KATAKWI | S9: KATAKWI | T9: UGA | U9: 2 | V9: =VLOOKUP(U9,Key!$E$2:$F$9,2,FALSE) -> Work | W9: =Q9&"-"&V9 -> Home-Work | X9: 10000 | Y9: 70 | Z9: 2 | AA9: 6 | AB9: =VLOOKUP(AA9,Key!$C$20:$D$29,2,FALSE) -> Businessman | AC9: 2 | AD9: =VLOOKUP(AC9,Key!$E$20:$F$24,2,FALSE) -> 300,000-500,000 | AE9: 3 | AF9: 1 | AG9: 4 | AH9: 2 | AI9: 5 | AJ9: Y
B10: 43695 | C10: 0.54166667 | E10: D | F10: 2 | G10: =VLOOKUP(F10,Key!$A$17:$B$21,2,FALSE) -> Road Vehicle | H10: 1 | I10: =VLOOKUP(H10,Key!$A$2:$B$13,2,FALSE) -> Car | J10: M | K10: 1 | L10: =VLOOKUP(K10,Key!$A$24:$B$29,2,FALSE) -> 20-29 | M10: SOROTI | N10: SOROTI | O10: UGA | P10: 2 | Q10: =VLOOKUP(P10,Key!$E$2:$F$9,2,FALSE) -> Work | R10: AMURA | S10: AMURA | T10: UGA | U10: 4 | V10: =VLOOKUP(U10,Key!$E$2:$F$9,2,FALSE) -> Commercial | W10: =Q10&"-"&V10 -> Work-Commercial | X10: 75000 | Y10: 10 | Z10: 0.8 | AA10: 10 | AB10: =VLOOKUP(AA10,Key!$C$20:$D$29,2,FALSE) -> Other | AC10: 2 | AD10: =VLOOKUP(AC10,Key!$E$20:$F$24,2,FALSE) -> 300,000-500,000 | AE10: 1 | AF10: 2 | AG10: 3 | AH10: 5 | AI10: 4 | AJ10: Y
B11: 43695 | C11: 0.625 | E11: D | F11: 2 | G11: =VLOOKUP(F11,Key!$A$17:$B$21,2,FALSE) -> Road Vehicle | H11: 1 | I11: =VLOOKUP(H11,Key!$A$2:$B$13,2,FALSE) -> Car | J11: M | K11: 1 | L11: =VLOOKUP(K11,Key!$A$24:$B$29,2,FALSE) -> 20-29 | M11: SOROTI | N11: SOROTI | O11: UGA | P11: 1 | Q11: =VLOOKUP(P11,Key!$E$2:$F$9,2,FALSE) -> Home | R11: MBALE | S11: MBALE | T11: UGA | U11: 2 | V11: =VLOOKUP(U11,Key!$E$2:$F$9,2,FALSE) -> Work | W11: =Q11&"-"&V11 -> Home-Work | X11: 70000 | Z11: 3 | AA11: 10 | AB11: =VLOOKUP(AA11,Key!$C$20:$D$29,2,FALSE) -> Other | AC11: 2 | AD11: =VLOOKUP(AC11,Key!$E$20:$F$24,2,FALSE) -> 300,000-500,000 | AE11: 1 | AF11: 2 | AG11: 4 | AH11: 3 | AI11: 5 | AJ11: Y
B12: 43695 | C12: 0.76458333 | E12: D | F12: 2 | G12: =VLOOKUP(F12,Key!$A$17:$B$21,2,FALSE) -> Road Vehicle | H12: 1 | I12: =VLOOKUP(H12,Key!$A$2:$B$13,2,FALSE) -> Car | J12: M | K12: 1 | L12: =VLOOKUP(K12,Key!$A$24:$B$29,2,FALSE) -> 20-29 | M12: LIRA | N12: LIRA | O12: UGA | P12: 2 | Q12: =VLOOKUP(P12,Key!$E$2:$F$9,2,FALSE) -> Work | R12: SOROTI | S12: SOROTI | T12: UGA | U12: 4 | V12: =VLOOKUP(U12,Key!$E$2:$F$9,2,FALSE) -> Commercial | W12: =Q12&"-"&V12 -> Work-Commercial | X12: 120000 | Y12: 110 | Z12: 1.5 | AA12: 6 | AB12: =VLOOKUP(AA12,Key!$C$20:$D$29,2,FALSE) -> Businessman | AC12: 2 | AD12: =VLOOKUP(AC12,Key!$E$20:$F$24,2,FALSE) -> 300,000-500,000 | AE12: 2 | AF12: 1 | AG12: 4 | AH12: 3 | AI12: 5 | AJ12: Y | AK12: 500
B13: 43695 | C13: 0.76458333 | E13: D | F13: 2 | G13: =VLOOKUP(F13,Key!$A$17:$B$21,2,FALSE) -> Road Vehicle | H13: 1 | I13: =VLOOKUP(H13,Key!$A$2:$B$13,2,FALSE) -> Car | J13: M | K13: 1 | L13: =VLOOKUP(K13,Key!$A$24:$B$29,2,FALSE) -> 20-29 | M13: AMURA | N13: AMURA | O13: UGA | P13: 1 | Q13: =VLOOKUP(P13,Key!$E$2:$F$9,2,FALSE) -> Home | R13: SOROTI | S13: SOROTI | T13: UGA | U13: 2 | V13: =VLOOKUP(U13,Key!$E$2:$F$9,2,FALSE) -> Work | W13: =Q13&"-"&V13 -> Home-Work | X13: 20000 | Z13: 0.7 | AA13: 3 | AB13: =VLOOKUP(AA13,Key!$C$20:$D$29,2,FALSE) -> Artisan/Domestic | AC13: 1 | AD13: =VLOOKUP(AC13,Key!$E$20:$F$24,2,FALSE) -> <300,000 | AE13: 7 | AF13: 2 | AG13: 3 | AH13: 4 | AI13: 5 | AJ13: Y
B14: 43697 | C14: 0.58333333 | E14: P | F14: 2 | G14: =VLOOKUP(F14,Key!$A$17:$B$21,2,FALSE) -> Road Vehicle | H14: 1 | I14: =VLOOKUP(H14,Key!$A$2:$B$13,2,FALSE) -> Car | J14: F | K14: 2 | L14: =VLOOKUP(K14,Key!$A$24:$B$29,2,FALSE) -> 30-39 | M14: SOROTI | N14: SOROTI | O14: UGA | P14: 1 | Q14: =VLOOKUP(P14,Key!$E$2:$F$9,2,FALSE) -> Home | R14: TORORO | S14: TORORO | T14: UGA | U14: 4 | V14: =VLOOKUP(U14,Key!$E$2:$F$9,2,FALSE) -> Commercial | W14: =Q14&"-"&V14 -> Home-Commercial | X14: 100000 | Y14: 40 | Z14: 2 | AA14: 6 | AB14: =VLOOKUP(AA14,Key!$C$20:$D$29,2,FALSE) -> Businessman | AC14: 1 | AD14: =VLOOKUP(AC14,Key!$E$20:$F$24,2,FALSE) -> <300,000 | AE14: 5 | AF14: 1 | AG14: 2 | AH14: 5 | AI14: 1 | AJ14: Y | AK14: 5000
B15: 43695 | C15: 0.59166667 | E15: D | F15: 2 | G15: =VLOOKUP(F15,Key!$A$17:$B$21,2,FALSE) -> Road Vehicle | H15: 1 | I15: =VLOOKUP(H15,Key!$A$2:$B$13,2,FALSE) -> Car | J15: M | K15: 2 | L15: =VLOOKUP(K15,Key!$A$24:$B$29,2,FALSE) -> 30-39 | M15: SOROTI | N15: SOROTI | O15: UGA | P15: 2 | Q15: =VLOOKUP(P15,Key!$E$2:$F$9,2,FALSE) -> Work | R15: LIRA | S15: LIRA | T15: UGA | U15: 1 | V15: =VLOOKUP(U15,Key!$E$2:$F$9,2,FALSE) -> Home | W15: =Q15&"-"&V15 -> Work-Home | X15: 50000 | Z15: 1 | AA15: 10 | AB15: =VLOOKUP(AA15,Key!$C$20:$D$29,2,FALSE) -> Other | AC15: 1 | AD15: =VLOOKUP(AC15,Key!$E$20:$F$24,2,FALSE) -> <300,000 | AE15: 2 | AF15: 1 | AG15: 3 | AH15: 5 | AI15: 4 | AJ15: Y | AK15: 1000
B16: 43695 | C16: 0.68402778 | D16: UBB 721D | E16: D | F16: 2 | G16: =VLOOKUP(F16,Key!$A$17:$B$21,2,FALSE) -> Road Vehicle | H16: 1 | I16: =VLOOKUP(H16,Key!$A$2:$B$13,2,FALSE) -> Car | J16: M | K16: 2 | L16: =VLOOKUP(K16,Key!$A$24:$B$29,2,FALSE) -> 30-39 | M16: SOROTI | N16: SOROTI | O16: UGA | P16: 2 | Q16: =VLOOKUP(P16,Key!$E$2:$F$9,2,FALSE) -> Work | R16: ATIRIRI | S16: SOROTI | T16: UGA | U16: 1 | V16: =VLOOKUP(U16,Key!$E$2:$F$9,2,FALSE) -> Home | W16: =Q16&"-"&V16 -> Work-Home | X16: 50000 | Y16: 5 | Z16: 0.7 | AA16: 10 | AB16: =VLOOKUP(AA16,Key!$C$20:$D$29,2,FALSE) -> Other | AC16: 1 | AD16: =VLOOKUP(AC16,Key!$E$20:$F$24,2,FALSE) -> <300,000 | AE16: 2 | AF16: 4 | AG16: 4 | AH16: 4 | AI16: 2 | AJ16: Y | AK16: 1000
B17: 43695 | C17: 0.64791667 | D17: UAT272T | E17: D | F17: 2 | G17: =VLOOKUP(F17,Key!$A$17:$B$21,2,FALSE) -> Road Vehicle | H17: 1 | I17: =VLOOKUP(H17,Key!$A$2:$B$13,2,FALSE) -> Car | J17: M | K17: 2 | L17: =VLOOKUP(K17,Key!$A$24:$B$29,2,FALSE) -> 30-39 | M17: SOROTI | N17: SOROTI | O17: UGA | P17: 2 | Q17: =VLOOKUP(P17,Key!$E$2:$F$9,2,FALSE) -> Work | R17: KAPELEBYONG | S17: KAPRLEBYONG | T17: UGA | U17: 8 | V17: =VLOOKUP(U17,Key!$E$2:$F$9,2,FALSE) -> Others | W17: =Q17&"-"&V17 -> Work-Others | X17: 70000 | Y17: 50 | Z17: 2 | AA17: 10 | AB17: =VLOOKUP(AA17,Key!$C$20:$D$29,2,FALSE) -> Other | AC17: 1 | AD17: =VLOOKUP(AC17,Key!$E$20:$F$24,2,FALSE) -> <300,000 | AE17: 5 | AF17: 2 | AG17: 2 | AH17: 5 | AI17: 2 | AJ17: Y
B18: 43695 | C18: 0.60069444 | D18: UAZ 618T | E18: D | F18: 2 | G18: =VLOOKUP(F18,Key!$A$17:$B$21,2,FALSE) -> Road Vehicle | H18: 1 | I18: =VLOOKUP(H18,Key!$A$2:$B$13,2,FALSE) -> Car | J18: M | K18: 2 | L18: =VLOOKUP(K18,Key!$A$24:$B$29,2,FALSE) -> 30-39 | M18: ABIM | N18: ABIM | O18: UGA | P18: 2 | Q18: =VLOOKUP(P18,Key!$E$2:$F$9,2,FALSE) -> Work | R18: SOROTI | S18: SOROTI | T18: UGA | U18: 2 | V18: =VLOOKUP(U18,Key!$E$2:$F$9,2,FALSE) -> Work | W18: =Q18&"-"&V18 -> Work-Work | X18: 80000 | Y18: 53 | Z18: 2 | AA18: 10 | AB18: =VLOOKUP(AA18,Key!$C$20:$D$29,2,FALSE) -> Other | AC18: 2 | AD18: =VLOOKUP(AC18,Key!$E$20:$F$24,2,FALSE) -> 300,000-500,000 | AE18: 5 | AF18: 2 | AG18: 3 | AH18: 5 | AI18: 3 | AJ18: Y | AK18: 2000
B19: 43696 | C19: 0.74930556 | D19: UAU 680B | E19: D | F19: 2 | G19: =VLOOKUP(F19,Key!$A$17:$B$21,2,FALSE) -> Road Vehicle | H19: 1 | I19: =VLOOKUP(H19,Key!$A$2:$B$13,2,FALSE) -> Car | J19: M | K19: 2 | L19: =VLOOKUP(K19,Key!$A$24:$B$29,2,FALSE) -> 30-39 | M19: SOROTI | N19: SOROTI | O19: UGA | P19: 2 | Q19: =VLOOKUP(P19,Key!$E$2:$F$9,2,FALSE) -> Work | R19: OCAPA | S19: SERERE | T19: UGA | U19: 2 | V19: =VLOOKUP(U19,Key!$E$2:$F$9,2,FALSE) -> Work | W19: =Q19&"-"&V19 -> Work-Work | X19: 60000 | Y19: 20 | Z19: 0.8 | AA19: 10 | AB19: =VLOOKUP(AA19,Key!$C$20:$D$29,2,FALSE) -> Other | AC19: 1 | AD19: =VLOOKUP(AC19,Key!$E$20:$F$24,2,FALSE) -> <300,000 | AE19: 5 | AF19: 2 | AG19: 3 | AH19: 5 | AI19: 2 | AJ19: Y | AK19: 1000
B20: 43697 | C20: 0.59930556 | E20: D | F20: 2 | G20: =VLOOKUP(F20,Key!$A$17:$B$21,2,FALSE) -> Road Vehicle | H20: 1 | I20: =VLOOKUP(H20,Key!$A$2:$B$13,2,FALSE) -> Car | J20: M | K20: 2 | L20: =VLOOKUP(K20,Key!$A$24:$B$29,2,FALSE) -> 30-39 | M20: SOROTI | N20: SOROTI | O20: UGA | P20: 2 | Q20: =VLOOKUP(P20,Key!$E$2:$F$9,2,FALSE) -> Work | R20: KUMI | S20: KUMI | T20: UGA | U20: 1 | V20: =VLOOKUP(U20,Key!$E$2:$F$9,2,FALSE) -> Home | W20: =Q20&"-"&V20 -> Work-Home | X20: 20000 | Y20: 30 | Z20: 0.8 | AA20: 6 | AB20: =VLOOKUP(AA20,Key!$C$20:$D$29,2,FALSE) -> Businessman | AC20: 2 | AD20: =VLOOKUP(AC20,Key!$E$20:$F$24,2,FALSE) -> 300,000-500,000 | AE20: 1 | AF20: 1 | AG20: 5 | AH20: 5 | AI20: 5 | AJ20: Y | AK20: 1000
B21: 43697 | C21: 0.59513889 | E21: D | F21: 2 | G21: =VLOOKUP(F21,Key!$A$17:$B$21,2,FALSE) -> Road Vehicle | H21: 1 | I21: =VLOOKUP(H21,Key!$A$2:$B$13,2,FALSE) -> Car | J21: M | K21: 2 | L21: =VLOOKUP(K21,Key!$A$24:$B$29,2,FALSE) -> 30-39 | M21: SOROTI | N21: SOROTI | O21: UGA | P21: 2 | Q21: =VLOOKUP(P21,Key!$E$2:$F$9,2,FALSE) -> Work | R21: MAGRORO | S21: MAGRORO | T21: UGA | U21: 1 | V21: =VLOOKUP(U21,Key!$E$2:$F$9,2,FALSE) -> Home | W21: =Q21&"-"&V21 -> Work-Home | X21: 30000 | Y21: 32 | Z21: 2 | AA21: 6 | AB21: =VLOOKUP(AA21,Key!$C$20:$D$29,2,FALSE) -> Businessman | AC21: 2 | AD21: =VLOOKUP(AC21,Key!$E$20:$F$24,2,FALSE) -> 300,000-500,000 | AE21: 5 | AF21: 1 | AG21: 5 | AH21: 5 | AI21: 1 | AJ21: Y | AK21: 2000
B22: 43697 | C22: 0.62986111 | E22: D | F22: 2 | G22: =VLOOKUP(F22,Key!$A$17:$B$21,2,FALSE) -> Road Vehicle | H22: 1 | I22: =VLOOKUP(H22,Key!$A$2:$B$13,2,FALSE) -> Car | J22: M | K22: 2 | L22: =VLOOKUP(K22,Key!$A$24:$B$29,2,FALSE) -> 30-39 | M22: SOROTI | N22: SOROTI | O22: UGA | P22: 1 | Q22: =VLOOKUP(P22,Key!$E$2:$F$9,2,FALSE) -> Home | R22: ORUMGO | S22: AMURIA | T22: UGA | U22: 4 | V22: =VLOOKUP(U22,Key!$E$2:$F$9,2,FALSE) -> Commercial | W22: =Q22&"-"&V22 -> Home-Commercial | X22: 20000 | Y22: 32 | Z22: 2 | AA22: 10 | AB22: =VLOOKUP(AA22,Key!$C$20:$D$29,2,FALSE) -> Other | AC22: 2 | AD22: =VLOOKUP(AC22,Key!$E$20:$F$24,2,FALSE) -> 300,000-500,000 | AE22: 5 | AF22: 1 | AG22: 5 | AH22: 3 | AI22: 5 | AJ22: Y
B23: 43696 | C23: 0.43055556 | E23: P | F23: 2 | G23: =VLOOKUP(F23,Key!$A$17:$B$21,2,FALSE) -> Road Vehicle | H23: 1 | I23: =VLOOKUP(H23,Key!$A$2:$B$13,2,FALSE) -> Car | J23: M | K23: 3 | L23: =VLOOKUP(K23,Key!$A$24:$B$29,2,FALSE) -> 40-49 | M23: SOROTI | N23: SOROTI | O23: UGA | P23: 2 | Q23: =VLOOKUP(P23,Key!$E$2:$F$9,2,FALSE) -> Work | R23: MOROTO | S23: MOROTO | T23: UGA | U23: 2 | V23: =VLOOKUP(U23,Key!$E$2:$F$9,2,FALSE) -> Work | W23: =Q23&"-"&V23 -> Work-Work | X23: 20000 | Z23: 2 | AA23: 6 | AB23: =VLOOKUP(AA23,Key!$C$20:$D$29,2,FALSE) -> Businessman | AC23: 2 | AD23: =VLOOKUP(AC23,Key!$E$20:$F$24,2,FALSE) -> 300,000-500,000 | AE23: 2 | AF23: 1 | AG23: 4 | AH23: 3 | AI23: 5 | AJ23: Y
B24: 43695 | C24: 0.67291667 | D24: UAW 979W | E24: D | F24: 2 | G24: =VLOOKUP(F24,Key!$A$17:$B$21,2,FALSE) -> Road Vehicle | H24: 1 | I24: =VLOOKUP(H24,Key!$A$2:$B$13,2,FALSE) -> Car | J24: M | K24: 3 | L24: =VLOOKUP(K24,Key!$A$24:$B$29,2,FALSE) -> 40-49 | M24: KAPELEBYONG | N24: KAPELEBYONG | O24: UGA | P24: 1 | Q24: =VLOOKUP(P24,Key!$E$2:$F$9,2,FALSE) -> Home | R24: SOROTI | S24: SOROTI | T24: UGA | U24: 6 | V24: =VLOOKUP(U24,Key!$E$2:$F$9,2,FALSE) -> Leisure/Social | W24: =Q24&"-"&V24 -> Home-Leisure/Social | X24: 60000 | Y24: 40 | Z24: 2 | AA24: 10 | AB24: =VLOOKUP(AA24,Key!$C$20:$D$29,2,FALSE) -> Other | AC24: 1 | AD24: =VLOOKUP(AC24,Key!$E$20:$F$24,2,FALSE) -> <300,000 | AE24: 2 | AF24: 2 | AG24: 4 | AH24: 4 | AI24: 2 | AJ24: Y | AK24: 1000
B25: 43695 | C25: 0.61458333 | D25: UAU 095V | E25: D | F25: 2 | G25: =VLOOKUP(F25,Key!$A$17:$B$21,2,FALSE) -> Road Vehicle | H25: 1 | I25: =VLOOKUP(H25,Key!$A$2:$B$13,2,FALSE) -> Car | J25: M | K25: 3 | L25: =VLOOKUP(K25,Key!$A$24:$B$29,2,FALSE) -> 40-49 | M25: AMURIA | N25: AMURIA | O25: UGA | P25: 2 | Q25: =VLOOKUP(P25,Key!$E$2:$F$9,2,FALSE) -> Work | R25: SOROTI | S25: SOROTI | T25: UGA | U25: 2 | V25: =VLOOKUP(U25,Key!$E$2:$F$9,2,FALSE) -> Work | W25: =Q25&"-"&V25 -> Work-Work | X25: 70000 | Y25: 35 | Z25: 1 | AA25: 10 | AB25: =VLOOKUP(AA25,Key!$C$20:$D$29,2,FALSE) -> Other | AC25: 1 | AD25: =VLOOKUP(AC25,Key!$E$20:$F$24,2,FALSE) -> <300,000 | AE25: 2 | AF25: 2 | AG25: 3 | AH25: 3 | AI25: 2 | AJ25: Y | AK25: 1000
B26: 43696 | C26: 0.73611111 | D26: UBA 376V | E26: D | F26: 2 | G26: =VLOOKUP(F26,Key!$A$17:$B$21,2,FALSE) -> Road Vehicle | H26: 1 | I26: =VLOOKUP(H26,Key!$A$2:$B$13,2,FALSE) -> Car | J26: M | K26: 3 | L26: =VLOOKUP(K26,Key!$A$24:$B$29,2,FALSE) -> 40-49 | M26: OLILIM | N26: KATAKWI | O26: UGA | P26: 2 | Q26: =VLOOKUP(P26,Key!$E$2:$F$9,2,FALSE) -> Work | R26: SOROTI | S26: SOROTI | T26: UGA | U26: 1 | V26: =VLOOKUP(U26,Key!$E$2:$F$9,2,FALSE) -> Home | W26: =Q26&"-"&V26 -> Work-Home | X26: 60000 | Y26: 85 | Z26: 2 | AA26: 10 | AB26: =VLOOKUP(AA26,Key!$C$20:$D$29,2,FALSE) -> Other | AC26: 1 | AD26: =VLOOKUP(AC26,Key!$E$20:$F$24,2,FALSE) -> <300,000 | AE26: 5 | AF26: 5 | AG26: 5 | AH26: 5 | AI26: 5 | AJ26: Y
B27: 43696 | C27: 0.76041667 | D27: UAX 363N | E27: D | F27: 2 | G27: =VLOOKUP(F27,Key!$A$17:$B$21,2,FALSE) -> Road Vehicle | H27: 1 | I27: =VLOOKUP(H27,Key!$A$2:$B$13,2,FALSE) -> Car | J27: M | K27: 3 | L27: =VLOOKUP(K27,Key!$A$24:$B$29,2,FALSE) -> 40-49 | M27: SERERE | N27: SERERE | O27: UGA | P27: 2 | Q27: =VLOOKUP(P27,Key!$E$2:$F$9,2,FALSE) -> Work | R27: SOROTI | S27: SOROTI | T27: UGA | U27: 1 | V27: =VLOOKUP(U27,Key!$E$2:$F$9,2,FALSE) -> Home | W27: =Q27&"-"&V27 -> Work-Home | X27: 80000 | Y27: 45 | Z27: 2 | AA27: 10 | AB27: =VLOOKUP(AA27,Key!$C$20:$D$29,2,FALSE) -> Other | AC27: 1 | AD27: =VLOOKUP(AC27,Key!$E$20:$F$24,2,FALSE) -> <300,000 | AE27: 5 | AF27: 2 | AG27: 3 | AH27: 5 | AI27: 2 | AJ27: Y
B28: 43696 | C28: 0.74097222 | E28: D | F28: 2 | G28: =VLOOKUP(F28,Key!$A$17:$B$21,2,FALSE) -> Road Vehicle | H28: 1 | I28: =VLOOKUP(H28,Key!$A$2:$B$13,2,FALSE) -> Car | J28: M | K28: 3 | L28: =VLOOKUP(K28,Key!$A$24:$B$29,2,FALSE) -> 40-49 | M28: SOROTI | N28: SOROTI | O28: UGA | P28: 2 | Q28: =VLOOKUP(P28,Key!$E$2:$F$9,2,FALSE) -> Work | R28: SOROTI | S28: SOROTI | T28: UGA | U28: 2 | V28: =VLOOKUP(U28,Key!$E$2:$F$9,2,FALSE) -> Work | W28: =Q28&"-"&V28 -> Work-Work | X28: 70000 | Y28: 30 | Z28: 0.7 | AA28: 10 | AB28: =VLOOKUP(AA28,Key!$C$20:$D$29,2,FALSE) -> Other | AC28: 1 | AD28: =VLOOKUP(AC28,Key!$E$20:$F$24,2,FALSE) -> <300,000 | AE28: 5 | AF28: 5 | AG28: 5 | AH28: 5 | AI28: 5 | AJ28: Y
B29: 43696 | C29: 0.72430556 | D29: UAV 814S | E29: D | F29: 2 | G29: =VLOOKUP(F29,Key!$A$17:$B$21,2,FALSE) -> Road Vehicle | H29: 1 | I29: =VLOOKUP(H29,Key!$A$2:$B$13,2,FALSE) -> Car | J29: M | K29: 3 | L29: =VLOOKUP(K29,Key!$A$24:$B$29,2,FALSE) -> 40-49 | M29: SOROTI | N29: SOROTI | O29: UGA | P29: 2 | Q29: =VLOOKUP(P29,Key!$E$2:$F$9,2,FALSE) -> Work | R29: OLILIM | S29: KATAKWI | T29: UGA | U29: 2 | V29: =VLOOKUP(U29,Key!$E$2:$F$9,2,FALSE) -> Work | W29: =Q29&"-"&V29 -> Work-Work | X29: 70000 | Y29: 85 | Z29: 2 | AA29: 10 | AB29: =VLOOKUP(AA29,Key!$C$20:$D$29,2,FALSE) -> Other | AC29: 2 | AD29: =VLOOKUP(AC29,Key!$E$20:$F$24,2,FALSE) -> 300,000-500,000 | AE29: 5 | AF29: 5 | AG29: 5 | AH29: 5 | AI29: 5 | AJ29: Y
B30: 43696 | C30: 0.69305556 | D30: UBE 301G | E30: D | F30: 2 | G30: =VLOOKUP(F30,Key!$A$17:$B$21,2,FALSE) -> Road Vehicle | H30: 9 | I30: =VLOOKUP(H30,Key!$A$2:$B$13,2,FALSE) -> Heavy truck | J30: M | K30: 2 | L30: =VLOOKUP(K30,Key!$A$24:$B$29,2,FALSE) -> 30-39 | M30: SOROTI | N30: SOROTI | O30: UGA | P30: 2 | Q30: =VLOOKUP(P30,Key!$E$2:$F$9,2,FALSE) -> Work | R30: ABIM | S30: ABIM | T30: UGA | U30: 2 | V30: =VLOOKUP(U30,Key!$E$2:$F$9,2,FALSE) -> Work | W30: =Q30&"-"&V30 -> Work-Work | X30: 70000 | Y30: 50 | Z30: 1.5 | AA30: 10 | AB30: =VLOOKUP(AA30,Key!$C$20:$D$29,2,FALSE) -> Other | AC30: 2 | AD30: =VLOOKUP(AC30,Key!$E$20:$F$24,2,FALSE) -> 300,000-500,000 | AE30: 5 | AF30: 5 | AG30: 5 | AH30: 5 | AI30: 5 | AJ30: Y | AK30: 1000
B31: 43695 | C31: 0.48263889 | D31: UBA 700G | E31: D | F31: 2 | G31: =VLOOKUP(F31,Key!$A$17:$B$21,2,FALSE) -> Road Vehicle | H31: 9 | I31: =VLOOKUP(H31,Key!$A$2:$B$13,2,FALSE) -> Heavy truck | J31: M | K31: 3 | L31: =VLOOKUP(K31,Key!$A$24:$B$29,2,FALSE) -> 40-49 | M31: SOROTI | N31: SOROTI | O31: UGA | P31: 2 | Q31: =VLOOKUP(P31,Key!$E$2:$F$9,2,FALSE) -> Work | R31: KAMPALA | S31: KAMPALA | T31: UGA | U31: 2 | V31: =VLOOKUP(U31,Key!$E$2:$F$9,2,FALSE) -> Work | W31: =Q31&"-"&V31 -> Work-Work | X31: 100000 | Y31: 380 | Z31: 6.5 | AA31: 10 | AB31: =VLOOKUP(AA31,Key!$C$20:$D$29,2,FALSE) -> Other | AC31: 2 | AD31: =VLOOKUP(AC31,Key!$E$20:$F$24,2,FALSE) -> 300,000-500,000 | AE31: 5 | AF31: 5 | AG31: 5 | AH31: 5 | AI31: 5 | AJ31: Y | AK31: 1000
B32: 43695 | C32: 0.39513889 | E32: P | F32: 2 | G32: =VLOOKUP(F32,Key!$A$17:$B$21,2,FALSE) -> Road Vehicle | H32: 6 | I32: =VLOOKUP(H32,Key!$A$2:$B$13,2,FALSE) -> Large Bus | J32: F | K32: 1 | L32: =VLOOKUP(K32,Key!$A$24:$B$29,2,FALSE) -> 20-29 | M32: SOROTI | N32: SOROTI | O32: UGA | P32: 1 | Q32: =VLOOKUP(P32,Key!$E$2:$F$9,2,FALSE) -> Home | R32: BUSIA | S32: BUSIA | T32: UGA | U32: 2 | V32: =VLOOKUP(U32,Key!$E$2:$F$9,2,FALSE) -> Work | W32: =Q32&"-"&V32 -> Home-Work | X32: 17000 | Y32: 140 | Z32: 4 | AA32: 6 | AB32: =VLOOKUP(AA32,Key!$C$20:$D$29,2,FALSE) -> Businessman | AC32: 1 | AD32: =VLOOKUP(AC32,Key!$E$20:$F$24,2,FALSE) -> <300,000 | AE32: 5 | AF32: 1 | AG32: 2 | AH32: 5 | AI32: 2 | AJ32: Y
B33: 43696 | C33: 0.4375 | E33: P | F33: 2 | G33: =VLOOKUP(F33,Key!$A$17:$B$21,2,FALSE) -> Road Vehicle | H33: 6 | I33: =VLOOKUP(H33,Key!$A$2:$B$13,2,FALSE) -> Large Bus | J33: F | K33: 1 | L33: =VLOOKUP(K33,Key!$A$24:$B$29,2,FALSE) -> 20-29 | M33: SOROTI | N33: SOROTI | O33: UGA | P33: 1 | Q33: =VLOOKUP(P33,Key!$E$2:$F$9,2,FALSE) -> Home | R33: KABONG | S33: KABONG | T33: UGA | U33: 8 | V33: =VLOOKUP(U33,Key!$E$2:$F$9,2,FALSE) -> Others | W33: =Q33&"-"&V33 -> Home-Others | X33: 30000 | Y33: 230 | Z33: 8.2 | AA33: 6 | AB33: =VLOOKUP(AA33,Key!$C$20:$D$29,2,FALSE) -> Businessman | AC33: 1 | AD33: =VLOOKUP(AC33,Key!$E$20:$F$24,2,FALSE) -> <300,000 | AE33: 5 | AF33: 4 | AG33: 3 | AH33: 5 | AI33: 2 | AJ33: Y
B34: 43696 | C34: 0.38541667 | E34: P | F34: 2 | G34: =VLOOKUP(F34,Key!$A$17:$B$21,2,FALSE) -> Road Vehicle | H34: 6 | I34: =VLOOKUP(H34,Key!$A$2:$B$13,2,FALSE) -> Large Bus | J34: F | K34: 1 | L34: =VLOOKUP(K34,Key!$A$24:$B$29,2,FALSE) -> 20-29 | M34: BUSIA | N34: BUSIA | O34: UGA | P34: 1 | Q34: =VLOOKUP(P34,Key!$E$2:$F$9,2,FALSE) -> Home | R34: GULU | S34: GULU | T34: UGA | U34: 2 | V34: =VLOOKUP(U34,Key!$E$2:$F$9,2,FALSE) -> Work | W34: =Q34&"-"&V34 -> Home-Work | X34: 30000 | Y34: 300 | Z34: 4 | AA34: 6 | AB34: =VLOOKUP(AA34,Key!$C$20:$D$29,2,FALSE) -> Businessman | AC34: 1 | AD34: =VLOOKUP(AC34,Key!$E$20:$F$24,2,FALSE) -> <300,000 | AE34: 5 | AF34: 2 | AG34: 4 | AH34: 5 | AI34: 3 | AJ34: Y
B35: 43696 | C35: 0.38055556 | E35: P | F35: 2 | G35: =VLOOKUP(F35,Key!$A$17:$B$21,2,FALSE) -> Road Vehicle | H35: 6 | I35: =VLOOKUP(H35,Key!$A$2:$B$13,2,FALSE) -> Large Bus | J35: F | K35: 1 | L35: =VLOOKUP(K35,Key!$A$24:$B$29,2,FALSE) -> 20-29 | M35: SOROTI | N35: SOROTI | O35: UGA | P35: 1 | Q35: =VLOOKUP(P35,Key!$E$2:$F$9,2,FALSE) -> Home | R35: LIRA | S35: LIRA | T35: UGA | U35: 2 | V35: =VLOOKUP(U35,Key!$E$2:$F$9,2,FALSE) -> Work | W35: =Q35&"-"&V35 -> Home-Work | X35: 12000 | Y35: 130 | Z35: 3.5 | AA35: 6 | AB35: =VLOOKUP(AA35,Key!$C$20:$D$29,2,FALSE) -> Businessman | AC35: 1 | AD35: =VLOOKUP(AC35,Key!$E$20:$F$24,2,FALSE) -> <300,000 | AE35: 2 | AF35: 4 | AG35: 3 | AH35: 3 | AI35: 2 | AJ35: Y
B36: 43696 | C36: 0.33888889 | E36: P | F36: 2 | G36: =VLOOKUP(F36,Key!$A$17:$B$21,2,FALSE) -> Road Vehicle | H36: 6 | I36: =VLOOKUP(H36,Key!$A$2:$B$13,2,FALSE) -> Large Bus | J36: F | K36: 1 | L36: =VLOOKUP(K36,Key!$A$24:$B$29,2,FALSE) -> 20-29 | M36: SOROTI | N36: SOROTI | O36: UGA | P36: 1 | Q36: =VLOOKUP(P36,Key!$E$2:$F$9,2,FALSE) -> Home | R36: NAMUTUMBA | S36: IGANGA | T36: UGA | U36: 2 | V36: =VLOOKUP(U36,Key!$E$2:$F$9,2,FALSE) -> Work | W36: =Q36&"-"&V36 -> Home-Work | X36: 18000 | Y36: 200 | Z36: 5 | AA36: 6 | AB36: =VLOOKUP(AA36,Key!$C$20:$D$29,2,FALSE) -> Businessman | AC36: 1 | AD36: =VLOOKUP(AC36,Key!$E$20:$F$24,2,FALSE) -> <300,000 | AE36: 2 | AF36: 4 | AG36: 3 | AH36: 5 | AI36: 2 | AJ36: Y
B37: 43695 | C37: 0.45833333 | E37: P | F37: 2 | G37: =VLOOKUP(F37,Key!$A$17:$B$21,2,FALSE) -> Road Vehicle | H37: 6 | I37: =VLOOKUP(H37,Key!$A$2:$B$13,2,FALSE) -> Large Bus | J37: M | K37: 1 | L37: =VLOOKUP(K37,Key!$A$24:$B$29,2,FALSE) -> 20-29 | M37: SOROTI | N37: SOROTI | O37: UGA | P37: 2 | Q37: =VLOOKUP(P37,Key!$E$2:$F$9,2,FALSE) -> Work | R37: KOTIDO | S37: KOTIDO | T37: UGA | U37: 4 | V37: =VLOOKUP(U37,Key!$E$2:$F$9,2,FALSE) -> Commercial | W37: =Q37&"-"&V37 -> Work-Commercial | X37: 25000 | Z37: 2.5 | AA37: 6 | AB37: =VLOOKUP(AA37,Key!$C$20:$D$29,2,FALSE) -> Businessman | AC37: 3 | AD37: =VLOOKUP(AC37,Key!$E$20:$F$24,2,FALSE) -> 500,000-750,000 | AJ37: Y | AK37: 1000
B38: 43695 | C38: 0.3875 | E38: P | F38: 2 | G38: =VLOOKUP(F38,Key!$A$17:$B$21,2,FALSE) -> Road Vehicle | H38: 6 | I38: =VLOOKUP(H38,Key!$A$2:$B$13,2,FALSE) -> Large Bus | J38: M | K38: 1 | L38: =VLOOKUP(K38,Key!$A$24:$B$29,2,FALSE) -> 20-29 | M38: KITGUM | N38: KITGUM | O38: UGA | P38: 1 | Q38: =VLOOKUP(P38,Key!$E$2:$F$9,2,FALSE) -> Home | R38: GULU | S38: GULU | T38: UGA | U38: 2 | V38: =VLOOKUP(U38,Key!$E$2:$F$9,2,FALSE) -> Work | W38: =Q38&"-"&V38 -> Home-Work | AA38: 6 | AB38: =VLOOKUP(AA38,Key!$C$20:$D$29,2,FALSE) -> Businessman | AC38: 1 | AD38: =VLOOKUP(AC38,Key!$E$20:$F$24,2,FALSE) -> <300,000 | AE38: 5 | AF38: 5 | AG38: 5 | AH38: 5 | AI38: 5 | AJ38: Y
B39: 43695 | C39: 0.37152778 | E39: P | F39: 2 | G39: =VLOOKUP(F39,Key!$A$17:$B$21,2,FALSE) -> Road Vehicle | H39: 6 | I39: =VLOOKUP(H39,Key!$A$2:$B$13,2,FALSE) -> Large Bus | J39: M | K39: 1 | L39: =VLOOKUP(K39,Key!$A$24:$B$29,2,FALSE) -> 20-29 | M39: KAMPALA | N39: KAMPALA | O39: UGA | P39: 1 | Q39: =VLOOKUP(P39,Key!$E$2:$F$9,2,FALSE) -> Home | R39: KABONG | S39: KABONG | T39: UGA | U39: 2 | V39: =VLOOKUP(U39,Key!$E$2:$F$9,2,FALSE) -> Work | W39: =Q39&"-"&V39 -> Home-Work | X39: 60000 | Y39: 600 | Z39: 12 | AA39: 6 | AB39: =VLOOKUP(AA39,Key!$C$20:$D$29,2,FALSE) -> Businessman | AC39: 1 | AD39: =VLOOKUP(AC39,Key!$E$20:$F$24,2,FALSE) -> <300,000 | AE39: 5 | AF39: 5 | AG39: 5 | AH39: 5 | AI39: 5 | AJ39: Y
B40: 43696 | C40: 0.36805556 | E40: P | F40: 2 | G40: =VLOOKUP(F40,Key!$A$17:$B$21,2,FALSE) -> Road Vehicle | H40: 6 | I40: =VLOOKUP(H40,Key!$A$2:$B$13,2,FALSE) -> Large Bus | J40: M | K40: 1 | L40: =VLOOKUP(K40,Key!$A$24:$B$29,2,FALSE) -> 20-29 | M40: SOROTI | N40: SOROTI | O40: UGA | P40: 1 | Q40: =VLOOKUP(P40,Key!$E$2:$F$9,2,FALSE) -> Home | R40: KAMPALA | S40: KAMPALA | T40: UGA | U40: 2 | V40: =VLOOKUP(U40,Key!$E$2:$F$9,2,FALSE) -> Work | W40: =Q40&"-"&V40 -> Home-Work | X40: 30000 | Y40: 385 | Z40: 6.5 | AA40: 10 | AB40: =VLOOKUP(AA40,Key!$C$20:$D$29,2,FALSE) -> Other | AC40: 2 | AD40: =VLOOKUP(AC40,Key!$E$20:$F$24,2,FALSE) -> 300,000-500,000 | AE40: 5 | AF40: 2 | AG40: 2 | AH40: 4 | AI40: 2 | AJ40: Y
B41: 43695 | C41: 0.38194444 | E41: P | F41: 2 | G41: =VLOOKUP(F41,Key!$A$17:$B$21,2,FALSE) -> Road Vehicle | H41: 6 | I41: =VLOOKUP(H41,Key!$A$2:$B$13,2,FALSE) -> Large Bus | J41: F | K41: 2 | L41: =VLOOKUP(K41,Key!$A$24:$B$29,2,FALSE) -> 30-39 | M41: SOROTI | N41: SOROTI | O41: UGA | P41: 1 | Q41: =VLOOKUP(P41,Key!$E$2:$F$9,2,FALSE) -> Home | R41: KABONG | S41: KABONG | T41: UGA | U41: 2 | V41: =VLOOKUP(U41,Key!$E$2:$F$9,2,FALSE) -> Work | W41: =Q41&"-"&V41 -> Home-Work | X41: 30000 | Y41: 205 | Z41: 8 | AA41: 6 | AB41: =VLOOKUP(AA41,Key!$C$20:$D$29,2,FALSE) -> Businessman | AC41: 1 | AD41: =VLOOKUP(AC41,Key!$E$20:$F$24,2,FALSE) -> <300,000 | AE41: 2 | AF41: 2 | AG41: 2 | AH41: 3 | AI41: 2 | AJ41: Y
B42: 43695 | C42: 0.36111111 | E42: P | F42: 2 | G42: =VLOOKUP(F42,Key!$A$17:$B$21,2,FALSE) -> Road Vehicle | H42: 6 | I42: =VLOOKUP(H42,Key!$A$2:$B$13,2,FALSE) -> Large Bus | J42: F | K42: 2 | L42: =VLOOKUP(K42,Key!$A$24:$B$29,2,FALSE) -> 30-39 | M42: KAMPALA | N42: KAMPALA | O42: UGA | P42: 1 | Q42: =VLOOKUP(P42,Key!$E$2:$F$9,2,FALSE) -> Home | R42: MOROTO | S42: MOROTO | T42: UGA | U42: 6 | V42: =VLOOKUP(U42,Key!$E$2:$F$9,2,FALSE) -> Leisure/Social | W42: =Q42&"-"&V42 -> Home-Leisure/Social | X42: 45000 | Y42: 400 | Z42: 7 | AA42: 6 | AB42: =VLOOKUP(AA42,Key!$C$20:$D$29,2,FALSE) -> Businessman | AC42: 1 | AD42: =VLOOKUP(AC42,Key!$E$20:$F$24,2,FALSE) -> <300,000 | AE42: 5 | AF42: 1 | AG42: 2 | AH42: 5 | AI42: 2 | AJ42: Y
...

Sheet RSI FORM
B1: Feasibility Study and Detailed Design of Kampala - Jinja Highway
B2: Roadside OD Interview Survey
B4: Date: | C4: 40465 | D4: Interviewer: | G4: Survey Station: | H4: Bweyogerere | J4: Direction: | K4: Bweyogerere-Kireka | L4: Coded By: | N4: Chkd By:
B7: Time Period | C7: Veh_Type | D7: Veh_Other | E7: Occupancy | F7: Origin_Address | H7: Origin_Purpose | I7: Origin_other | J7: Destination_Address | L7: Destination_Purpose | M7: Destination_Other | N7: Origin_Zone | O7: Dest_Zone | P7: WTP
F8: Village/Town | G8: City/Country | J8: Village/Town | K8: City/Country
B9: AM | C9: 3 | E9: 2 | F9: Entebbe | G9: Kla, Ug | H9: 1 | J9: Kla | K9: Kla, Ug | L9: 2 | N9: Blank | O9: Blank | P9: Yes | Q9: 3000
B10: AM | C10: 1 | E10: 1 | F10: Kiwanga | G10: Kla, Ug | H10: 1 | J10: Kla | K10: Kla, Ug | L10: 2 | N10: Blank | O10: Blank | P10: Yes | Q10: 2000
B11: AM | E11: 1 | F11: Bukoto | G11: Kla, Ug | H11: 3 | J11: Kla | K11: Kla, Ug | L11: 1 | N11: Blank | O11: Blank
B12: AM
B13: AM
B14: AM
B15: AM
B16: AM
B17: AM
B18: AM
B19: AM
B20: AM
B21: AM
B22: AM
B23: AM
... B53: AM

Sheet Key
B1: Vehicle Type | D1: Establishment Type | F1: Origin / Destination Purpose | H1: Trip Frequency | J1: Goods Type
A2: 1 | B2: Car | C2: 1 | D2: Residential | E2: 1 | F2: Home | G2: 1 | H2: more than 2 times every day | I2: 1 | J2: Food crop (Maize,rice,wheat etc)
A3: 2 | B3: Station Wagon | C3: 2 | D3: Office | E3: 2 | F3: Work | G3: 2 | H3: Daily (Up and Down) | I3: 2 | J3: Cash Crops (coffee,tea etc)
A4: 3 | B4: Pickups | C4: 3 | D4: Factory | E4: 3 | F4: Study | G4: 3 | H4: 2/3 times a week | I4: 3 | J4: Perishable (fish,milk,tea etc)
A5: 4 | B5: Minibus | C5: 4 | D5: Educational Facility | E5: 4 | F5: Commercial | G5: 4 | H5: Once a week | I5: 4 | J5: Construction Material (cement, gravel,stones,gravel,pipes)
A6: 5 | B6: Medium bus | C6: 5 | D6: Hospital | E6: 5 | F6: Tourism | G6: 5 | H6: Once a month | I6: 5 | J6: Metal/machinery
A7: 6 | B7: Large Bus | C7: 6 | D7: Bus / Taxi Park | E7: 6 | F7: Leisure/Social | G7: 6 | H7: Once in a while | I7: 6 | J7: Forestry products (timber & charcoal)
A8: 7 | B8: Light Truck | C8: 7 | D8: Wholesale shopping | E8: 7 | F8: Hospital | I8: 7 | J8: Fuels (any petroleum products)
A9: 8 | B9: Medium Truck | C9: 8 | D9: Boda boda stage | E9: 8 | F9: Others | I9: 8 | J9: Chemical Products (fertilizer,paints)
A10: 9 | B10: Heavy truck | C10: 9 | D10: Farm | I10: 9 | J10: Livestock (cows,goats,camel etc)
A11: 10 | B11: Truck Trailer | C11: 10 | D11: Construction Site | I11: 10 | J11: Household retail products (beverage,oil,sugar,salt,flour)
A12: 11 | B12: Motor cycles | C12: 11 | D12: Retail Shop/Market | I12: 11 | J12: Empty
A13: 12 | B13: Tractors | C13: 12 | D13: Warehouse | I13: 12 | J13: Others (Pl specify)
C14: 13 | D14: Harbour
C15: 14 | D15: Timber Centre
B16: Mode Number | C16: 15 | D16: Quarry
A17: 1 | B17: Walking/Cycling | C17: 16 | D17: Others (to be specified)
A18: 2 | B18: Road Vehicle
A19: 3 | B19: Rail | D19: Profession | F19: Monthly Income
A20: 4 | B20: Water/Ferry | C20: 1 | D20: Unemployed | E20: 1 | F20: <300,000
A21: 5 | B21: Air | C21: 2 | D21: Manual Labour | E21: 2 | F21: 300,000-500,000
C22: 3 | D22: Artisan/Domestic | E22: 3 | F22: 500,000-750,000
B23: Age Bracket No. | C23: 4 | D23: Office Worker | E23: 4 | F23: 750,000-1,000,000
A24: 1 | B24: 20-29 | C24: 5 | D24: Professional | E24: 5 | F24: >1,000,000
A25: 2 | B25: 30-39 | C25: 6 | D25: Businessman
A26: 3 | B26: 40-49 | C26: 7 | D26: Farmer
A27: 4 | B27: 50-59 | C27: 8 | D27: Student
A28: 5 | B28: 60-69 | C28: 9 | D28: Retired
A29: 6 | B29: 70- | C29: 10 | D29: Other
