Workbook

Sheet 22.07 KALERWE-GAYAZA
B1: Consultancy services for Preparation of Expressway Development Master Plan (EDMP) for Uganda
B2: MANUAL CLASSIFIED COUNT (MCC)
B3: ROAD NAME: | C3: MCC - C1 - STN26 - Gayaza Road Kanyanya
C5: Date | D5: 22.07.19 | F5: Location | G5: DELTA KYEBANDO | J5: Surveyor | K5: NALUBEGA JOSEPHINE
C6: Dir. From | D6: KALERWE | F6: Dir. To | G6: GAYAZA | J6: Supervisor | K6: WALAKIRA
B8: Time / Veh Type | R8: SUMMARY TRAFFIC VOLUMES
C9: 1. Car | D9: 2. Station Wagon | E9: 3. Pickups | F9: 4. Minibus, matatu | G9: 5. Medium bus | H9: 6. Large Bus | I9: 7. Light Truck | J9: 8. Medium Truck | K9: 9. Heavy truck | L9: 10. Truck Trailer | M9: 11. Motor cycles | N9: 12. Tractors | O9: Total Excl M/Cycles | P9: Total All | R9: Time | S9: 1. Car | T9: 2. Station Wagon | U9: 3. Pickups | V9: 4. Minibus, matatu | W9: 5. Medium bus | X9: 6. Large Bus | Y9: 7. Light Truck | Z9: 8. Medium Truck | AA9: 9. Heavy truck | AB9: 10. Truck Trailer | AC9: 11. Motorcycles | AD9: 12. Tractors, Graders | AE9: Total Excl M/ Cycles | AF9: Total All
B10: 07.00 - 07.15 | C10: 27 | D10: 8 | E10: 2 | F10: 44 | G10: 0 | H10: 5 | I10: 6 | J10: 0 | K10: 1 | L10: 1 | M10: 215 | N10: 0 | O10: =SUM(C10:L10,N10) -> 94 | P10: =SUM(C10:N10) -> 309 | R10: 0700-0800 | S10: =SUM(C10:C13) -> 91 | T10: =SUM(D10:D13) -> 31 | U10: =SUM(E10:E13) -> 9 | V10: =SUM(F10:F13) -> 205 | W10: =SUM(G10:G13) -> 4 | X10: =SUM(H10:H13) -> 6 | Y10: =SUM(I10:I13) -> 19 | Z10: =SUM(J10:J13) -> 10 | ... AF10: =SUM(P10:P13) -> 1470
B11: 07.15 - 07.30 | C11: 16 | D11: 2 | E11: 0 | F11: 27 | G11: 3 | H11: 0 | I11: 1 | J11: 2 | K11: 0 | L11: 1 | M11: 155 | N11: 0 | O11: =SUM(C11:L11,N11) -> 52 | P11: =SUM(C11:N11) -> 207 | R11: 0800-0900 | S11: =SUM(C14:C17) -> 69 | T11: =SUM(D14:D17) -> 46 | U11: =SUM(E14:E17) -> 10 | V11: =SUM(F14:F17) -> 206 | W11: =SUM(G14:G17) -> 3 | X11: =SUM(H14:H17) -> 3 | Y11: =SUM(I14:I17) -> 23 | Z11: =SUM(J14:J17) -> 13 | ... AF11: =SUM(P14:P17) -> 1663
B12: 07.30 - 07.45 | C12: 35 | D12: 11 | E12: 5 | F12: 82 | G12: 1 | H12: 1 | I12: 10 | J12: 6 | K12: 1 | L12: 2 | M12: 550 | N12: 0 | O12: =SUM(C12:L12,N12) -> 154 | P12: =SUM(C12:N12) -> 704 | R12: 0900-1000 | S12: =SUM(C18:C21) -> 67 | T12: =SUM(D18:D21) -> 42 | U12: =SUM(E18:E21) -> 20 | V12: =SUM(F18:F21) -> 264 | W12: =SUM(G18:G21) -> 1 | X12: =SUM(H18:H21) -> 1 | Y12: =SUM(I18:I21) -> 30 | Z12: =SUM(J18:J21) -> 17 | ... AF12: =SUM(P18:P21) -> 723
B13: 07.45 - 08.00 | C13: 13 | D13: 10 | E13: 2 | F13: 52 | G13: 0 | H13: 0 | I13: 2 | J13: 2 | K13: 0 | L13: 0 | M13: 169 | N13: 0 | O13: =SUM(C13:L13,N13) -> 81 | P13: =SUM(C13:N13) -> 250 | R13: 1000-1100 | S13: =SUM(C22:C25) -> 165 | T13: =SUM(D22:D25) -> 108 | U13: =SUM(E22:E25) -> 53 | V13: =SUM(F22:F25) -> 324 | W13: =SUM(G22:G25) -> 4 | X13: =SUM(H22:H25) -> 1 | Y13: =SUM(I22:I25) -> 45 | Z13: =SUM(J22:J25) -> 18 | ... AF13: =SUM(P22:P25) -> 1492
B14: 08.00 - 08.15 | C14: 18 | D14: 8 | E14: 3 | F14: 53 | G14: 1 | H14: 2 | I14: 5 | J14: 4 | K14: 1 | L14: 1 | M14: 299 | N14: 0 | O14: =SUM(C14:L14,N14) -> 96 | P14: =SUM(C14:N14) -> 395 | R14: 1100-1200 | S14: =SUM(C26:C29) -> 159 | T14: =SUM(D26:D29) -> 53 | U14: =SUM(E26:E29) -> 30 | V14: =SUM(F26:F29) -> 206 | W14: =SUM(G26:G29) -> 2 | X14: =SUM(H26:H29) -> 3 | Y14: =SUM(I26:I29) -> 59 | Z14: =SUM(J26:J29) -> 21 | ... AF14: =SUM(P26:P29) -> 1423
B15: 08.15 - 08.30 | C15: 7 | D15: 2 | E15: 1 | F15: 13 | G15: 0 | H15: 0 | I15: 0 | J15: 0 | K15: 0 | L15: 0 | M15: 285 | N15: 0 | O15: =SUM(C15:L15,N15) -> 23 | P15: =SUM(C15:N15) -> 308 | R15: 1200-1300 | S15: =SUM(C30:C33) -> 197 | T15: =SUM(D30:D33) -> 49 | U15: =SUM(E30:E33) -> 39 | V15: =SUM(F30:F33) -> 203 | W15: =SUM(G30:G33) -> 2 | X15: =SUM(H30:H33) -> 3 | Y15: =SUM(I30:I33) -> 38 | Z15: =SUM(J30:J33) -> 15 | ... AF15: =SUM(P30:P33) -> 1364
B16: 08.30 - 08.45 | C16: 26 | D16: 19 | E16: 1 | F16: 60 | G16: 1 | H16: 0 | I16: 9 | J16: 4 | K16: 0 | L16: 2 | M16: 342 | N16: 0 | O16: =SUM(C16:L16,N16) -> 122 | P16: =SUM(C16:N16) -> 464 | R16: 1300-1400 | S16: =SUM(C34:C37) -> 141 | T16: =SUM(D34:D37) -> 47 | U16: =SUM(E34:E37) -> 32 | V16: =SUM(F34:F37) -> 221 | W16: =SUM(G34:G37) -> 5 | X16: =SUM(H34:H37) -> 0 | Y16: =SUM(I34:I37) -> 51 | Z16: =SUM(J34:J37) -> 13 | ... AF16: =SUM(P34:P37) -> 1282
B17: 08.45 - 9.00 | C17: 18 | D17: 17 | E17: 5 | F17: 80 | G17: 1 | H17: 1 | I17: 9 | J17: 5 | K17: 4 | L17: 6 | M17: 350 | N17: 0 | O17: =SUM(C17:L17,N17) -> 146 | P17: =SUM(C17:N17) -> 496 | R17: 1400-1500 | S17: =SUM(C38:C41) -> 217 | T17: =SUM(D38:D41) -> 43 | U17: =SUM(E38:E41) -> 34 | V17: =SUM(F38:F41) -> 210 | W17: =SUM(G38:G41) -> 3 | X17: =SUM(H38:H41) -> 5 | Y17: =SUM(I38:I41) -> 81 | Z17: =SUM(J38:J41) -> 16 | ... AF17: =SUM(P38:P41) -> 1138
B18: 09.00 - 09.15 | C18: 13 | D18: 13 | E18: 3 | F18: 47 | G18: 1 | H18: 0 | I18: 11 | J18: 4 | K18: 2 | L18: 1 | M18: 45 | N18: 0 | O18: =SUM(C18:L18,N18) -> 95 | P18: =SUM(C18:N18) -> 140 | R18: 1500-1600 | S18: =SUM(C42:C45) -> 198 | T18: =SUM(D42:D45) -> 37 | U18: =SUM(E42:E45) -> 24 | V18: =SUM(F42:F45) -> 142 | W18: =SUM(G42:G45) -> 1 | X18: =SUM(H42:H45) -> 3 | Y18: =SUM(I42:I45) -> 61 | Z18: =SUM(J42:J45) -> 5 | ... AF18: =SUM(P42:P45) -> 635
B19: 09.15 - 09.30 | C19: 16 | D19: 8 | E19: 4 | F19: 60 | G19: 0 | H19: 1 | I19: 6 | J19: 6 | K19: 3 | L19: 0 | M19: 90 | N19: 0 | O19: =SUM(C19:L19,N19) -> 104 | P19: =SUM(C19:N19) -> 194 | R19: 1600-1700 | S19: =SUM(C46:C49) -> 238 | T19: =SUM(D46:D49) -> 83 | U19: =SUM(E46:E49) -> 33 | V19: =SUM(F46:F49) -> 210 | W19: =SUM(G46:G49) -> 2 | X19: =SUM(H46:H49) -> 7 | Y19: =SUM(I46:I49) -> 62 | Z19: =SUM(J46:J49) -> 3 | ... AF19: =SUM(P46:P49) -> 1482
B20: 09.30 - 09.45 | C20: 18 | D20: 11 | E20: 8 | F20: 62 | G20: 0 | H20: 0 | I20: 7 | J20: 4 | K20: 1 | L20: 1 | M20: 135 | N20: 0 | O20: =SUM(C20:L20,N20) -> 112 | P20: =SUM(C20:N20) -> 247 | R20: 1700-1800 | S20: =SUM(C50:C53) -> 296 | T20: =SUM(D50:D53) -> 75 | U20: =SUM(E50:E53) -> 35 | V20: =SUM(F50:F53) -> 200 | W20: =SUM(G50:G53) -> 3 | X20: =SUM(H50:H53) -> 2 | Y20: =SUM(I50:I53) -> 74 | Z20: =SUM(J50:J53) -> 4 | ... AF20: =SUM(P50:P53) -> 1710
B21: 09.45 - 10.00 | C21: 20 | D21: 10 | E21: 5 | F21: 95 | G21: 0 | H21: 0 | I21: 6 | J21: 3 | K21: 3 | L21: 0 | M21: 0 | N21: 0 | O21: =SUM(C21:L21,N21) -> 142 | P21: =SUM(C21:N21) -> 142 | R21: 1800-1900 | S21: =SUM(C54:C57) -> 370 | T21: =SUM(D54:D57) -> 99 | U21: =SUM(E54:E57) -> 31 | V21: =SUM(F54:F57) -> 258 | W21: =SUM(G54:G57) -> 11 | X21: =SUM(H54:H57) -> 7 | Y21: =SUM(I54:I57) -> 59 | Z21: =SUM(J54:J57) -> 2 | ... AF21: =SUM(P54:P57) -> 2079
B22: 10.00 - 10.15 | C22: 39 | D22: 25 | E22: 19 | F22: 135 | G22: 1 | H22: 1 | I22: 1 | J22: 2 | K22: 4 | L22: 1 | M22: 130 | N22: 0 | O22: =SUM(C22:L22,N22) -> 228 | P22: =SUM(C22:N22) -> 358 | R22: AM Peak Hr | S22: =MAX(S10:S12) -> 91 | T22: =MAX(T10:T12) -> 46 | U22: =MAX(U10:U12) -> 20 | V22: =MAX(V10:V12) -> 264 | W22: =MAX(W10:W12) -> 4 | X22: =MAX(X10:X12) -> 6 | Y22: =MAX(Y10:Y12) -> 30 | Z22: =MAX(Z10:Z12) -> 17 | ... AF22: =MAX(AF10:AF12) -> 1663
B23: 10.15 - 10.30 | C23: 41 | D23: 36 | E23: 10 | F23: 75 | G23: 1 | H23: 0 | I23: 11 | J23: 9 | K23: 5 | L23: 0 | M23: 230 | N23: 0 | O23: =SUM(C23:L23,N23) -> 188 | P23: =SUM(C23:N23) -> 418 | R23: IP Peak Hr | S23: =MAX(S13:S18) -> 217 | T23: =MAX(T13:T18) -> 108 | U23: =MAX(U13:U18) -> 53 | V23: =MAX(V13:V18) -> 324 | W23: =MAX(W13:W18) -> 5 | X23: =MAX(X13:X18) -> 5 | Y23: =MAX(Y13:Y18) -> 81 | Z23: =MAX(Z13:Z18) -> 21 | ... AF23: =MAX(AF13:AF18) -> 1492
B24: 10.30 - 10.45 | C24: 44 | D24: 26 | E24: 3 | F24: 61 | G24: 0 | H24: 0 | I24: 6 | J24: 3 | K24: 0 | L24: 0 | M24: 182 | N24: 0 | O24: =SUM(C24:L24,N24) -> 143 | P24: =SUM(C24:N24) -> 325 | R24: PM Peak Hr | S24: =MAX(S19:S21) -> 370 | T24: =MAX(T19:T21) -> 99 | U24: =MAX(U19:U21) -> 35 | V24: =MAX(V19:V21) -> 258 | W24: =MAX(W19:W21) -> 11 | X24: =MAX(X19:X21) -> 7 | Y24: =MAX(Y19:Y21) -> 74 | Z24: =MAX(Z19:Z21) -> 4 | ... AF24: =MAX(AF19:AF21) -> 2079
B25: 10.45 - 11.00 | C25: 41 | D25: 21 | E25: 21 | F25: 53 | G25: 2 | H25: 0 | I25: 27 | J25: 4 | K25: 2 | L25: 0 | M25: 220 | N25: 0 | O25: =SUM(C25:L25,N25) -> 171 | P25: =SUM(C25:N25) -> 391 | R25: AM Period | S25: =SUM(S10:S12) -> 227 | T25: =SUM(T10:T12) -> 119 | U25: =SUM(U10:U12) -> 39 | V25: =SUM(V10:V12) -> 675 | W25: =SUM(W10:W12) -> 8 | X25: =SUM(X10:X12) -> 10 | Y25: =SUM(Y10:Y12) -> 72 | Z25: =SUM(Z10:Z12) -> 40 | ... AF25: =SUM(AF10:AF12) -> 3856
B26: 11.00 - 11.15 | C26: 24 | D26: 11 | E26: 8 | F26: 58 | G26: 0 | H26: 0 | I26: 25 | J26: 3 | K26: 0 | L26: 0 | M26: 155 | N26: 0 | O26: =SUM(C26:L26,N26) -> 129 | P26: =SUM(C26:N26) -> 284 | R26: IP Period | S26: =SUM(S13:S18) -> 1077 | T26: =SUM(T13:T18) -> 337 | U26: =SUM(U13:U18) -> 212 | V26: =SUM(V13:V18) -> 1306 | W26: =SUM(W13:W18) -> 17 | X26: =SUM(X13:X18) -> 15 | Y26: =SUM(Y13:Y18) -> 335 | Z26: =SUM(Z13:Z18) -> 88 | ... AF26: =SUM(AF13:AF18) -> 7334
B27: 11.15 - 11.30 | C27: 46 | D27: 11 | E27: 10 | F27: 43 | G27: 0 | H27: 0 | I27: 6 | J27: 4 | K27: 0 | L27: 0 | M27: 223 | N27: 0 | O27: =SUM(C27:L27,N27) -> 120 | P27: =SUM(C27:N27) -> 343 | R27: PM Period | S27: =SUM(S19:S21) -> 904 | T27: =SUM(T19:T21) -> 257 | U27: =SUM(U19:U21) -> 99 | V27: =SUM(V19:V21) -> 668 | W27: =SUM(W19:W21) -> 16 | X27: =SUM(X19:X21) -> 16 | Y27: =SUM(Y19:Y21) -> 195 | Z27: =SUM(Z19:Z21) -> 9 | ... AF27: =SUM(AF19:AF21) -> 5271
B28: 11.30 - 11.45 | C28: 45 | D28: 24 | E28: 8 | F28: 54 | G28: 1 | H28: 1 | I28: 8 | J28: 7 | K28: 1 | L28: 0 | M28: 260 | N28: 0 | O28: =SUM(C28:L28,N28) -> 149 | P28: =SUM(C28:N28) -> 409 | R28: 12 Hours | S28: =SUM(S10:S21) -> 2208 | T28: =SUM(T10:T21) -> 713 | U28: =SUM(U10:U21) -> 350 | V28: =SUM(V10:V21) -> 2649 | W28: =SUM(W10:W21) -> 41 | X28: =SUM(X10:X21) -> 41 | Y28: =SUM(Y10:Y21) -> 602 | Z28: =SUM(Z10:Z21) -> 137 | ... AF28: =SUM(AF10:AF21) -> 16461
B29: 11.45 - 12.00 | C29: 44 | D29: 7 | E29: 4 | F29: 51 | G29: 1 | H29: 2 | I29: 20 | J29: 7 | K29: 2 | L29: 0 | M29: 249 | N29: 0 | O29: =SUM(C29:L29,N29) -> 138 | P29: =SUM(C29:N29) -> 387
B30: 12.00 - 12.15 | C30: 47 | D30: 10 | E30: 11 | F30: 49 | G30: 0 | H30: 0 | I30: 12 | J30: 6 | K30: 2 | L30: 2 | M30: 195 | N30: 0 | O30: =SUM(C30:L30,N30) -> 139 | P30: =SUM(C30:N30) -> 334
B31: 12.15 - 12.30 | C31: 39 | D31: 11 | E31: 13 | F31: 51 | G31: 0 | H31: 2 | I31: 11 | J31: 3 | K31: 1 | L31: 0 | M31: 225 | N31: 0 | O31: =SUM(C31:L31,N31) -> 131 | P31: =SUM(C31:N31) -> 356
B32: 12.30 - 12.45 | C32: 53 | D32: 17 | E32: 7 | F32: 52 | G32: 0 | H32: 1 | I32: 6 | J32: 4 | K32: 2 | L32: 0 | M32: 200 | N32: 0 | O32: =SUM(C32:L32,N32) -> 142 | P32: =SUM(C32:N32) -> 342
B33: 12.45 - 13.00 | C33: 58 | D33: 11 | E33: 8 | F33: 51 | G33: 2 | H33: 0 | I33: 9 | J33: 2 | K33: 1 | L33: 0 | M33: 190 | N33: 0 | O33: =SUM(C33:L33,N33) -> 142 | P33: =SUM(C33:N33) -> 332
B34: 13.00 - 13.15 | C34: 43 | D34: 13 | E34: 5 | F34: 65 | G34: 1 | H34: 0 | I34: 15 | J34: 2 | K34: 0 | L34: 0 | M34: 215 | N34: 0 | O34: =SUM(C34:L34,N34) -> 144 | P34: =SUM(C34:N34) -> 359
B35: 13.15 - 13.30 | C35: 53 | D35: 8 | E35: 12 | F35: 52 | G35: 2 | H35: 0 | I35: 12 | J35: 1 | K35: 1 | L35: 0 | M35: 220 | N35: 0 | O35: =SUM(C35:L35,N35) -> 141 | P35: =SUM(C35:N35) -> 361
B36: 13.30 - 13.45 | C36: 29 | D36: 11 | E36: 6 | F36: 53 | G36: 2 | H36: 0 | I36: 16 | J36: 2 | K36: 1 | L36: 0 | M36: 204 | N36: 0 | O36: =SUM(C36:L36,N36) -> 120 | P36: =SUM(C36:N36) -> 324
B37: 13.45 - 14.00 | C37: 16 | D37: 15 | E37: 9 | F37: 51 | G37: 0 | H37: 0 | I37: 8 | J37: 8 | K37: 1 | L37: 0 | M37: 130 | N37: 0 | O37: =SUM(C37:L37,N37) -> 108 | P37: =SUM(C37:N37) -> 238
B38: 14.00 - 14.15 | C38: 40 | D38: 7 | E38: 6 | F38: 35 | G38: 0 | H38: 1 | I38: 19 | J38: 4 | K38: 3 | L38: 0 | M38: 95 | N38: 0 | O38: =SUM(C38:L38,N38) -> 115 | P38: =SUM(C38:N38) -> 210
B39: 14.15 - 14.30 | C39: 67 | D39: 9 | E39: 17 | F39: 70 | G39: 1 | H39: 2 | I39: 25 | J39: 5 | K39: 3 | L39: 0 | M39: 148 | N39: 0 | O39: =SUM(C39:L39,N39) -> 199 | P39: =SUM(C39:N39) -> 347
B40: 14.30 - 14.45 | C40: 53 | D40: 15 | E40: 4 | F40: 50 | G40: 2 | H40: 1 | I40: 16 | J40: 1 | K40: 0 | L40: 0 | M40: 170 | N40: 0 | O40: =SUM(C40:L40,N40) -> 142 | P40: =SUM(C40:N40) -> 312
... B57: 18.45 - 19.00 | C57: 94 | D57: 37 | E57: 13 | F57: 75 | G57: 2 | H57: 0 | I57: 17 | J57: 2 | K57: 2 | L57: 0 | M57: 245 | N57: 0 | O57: =SUM(C57:L57,N57) -> 242 | P57: =SUM(C57:N57) -> 487
B58: Totals | C58: =SUM(C10:C57) -> 2208 | D58: =SUM(D10:D57) -> 713 | E58: =SUM(E10:E57) -> 350 | F58: =SUM(F10:F57) -> 2649 | G58: =SUM(G10:G57) -> 41 | H58: =SUM(H10:H57) -> 41 | I58: =SUM(I10:I57) -> 602 | J58: =SUM(J10:J57) -> 137 | ... P58: =SUM(P10:P57) -> 16461
...

Sheet 22.07 GAYAZA-KALERWE
B1: Consultancy services for Preparation of Expressway Development Master Plan (EDMP) for Uganda
B2: MANUAL CLASSIFIED COUNT (MCC)
B3: ROAD NAME: | C3: ='22.07 KALERWE-GAYAZA'!C3:G3 -> MCC - C1 - STN26 - Gayaza Road Kanyanya
C5: Date | D5: ='22.07 KALERWE-GAYAZA'!D5 -> 22.07.19 | F5: Location | G5: ='22.07 KALERWE-GAYAZA'!G5:H5 -> DELTA KYEBANDO | J5: Surveyor | K5: MORREEN
C6: Dir. From | D6: GAYAZA | F6: Dir. To | G6: KALERWE | J6: Supervisor | K6: LAWRENCE
B8: Time / Veh Type | R8: SUMMARY TRAFFIC VOLUMES
C9: 1. Car | D9: 2. Station Wagon | E9: 3. Pickups | F9: 4. Minibus, matatu | G9: 5. Medium bus | H9: 6. Large Bus | I9: 7. Light Truck | J9: 8. Medium Truck | K9: 9. Heavy truck | L9: 10. Truck Trailer | M9: 11. Motor cycles | N9: 12. Tractors | O9: Total Excl M/Cycles | P9: Total All | R9: Time | S9: 1. Car | T9: 2. Station Wagon | U9: 3. Pickups | V9: 4. Minibus, matatu | W9: 5. Medium bus | X9: 6. Large Bus | Y9: 7. Light Truck | Z9: 8. Medium Truck | AA9: 9. Heavy truck | AB9: 10. Truck Trailer | AC9: 11. Motorcycles | AD9: 12. Tractors, Graders | AE9: Total Excl M/ Cycles | AF9: Total All
B10: 07.00 - 07.15 | C10: 50 | D10: 20 | E10: 18 | F10: 36 | G10: 0 | H10: 0 | I10: 1 | J10: 5 | K10: 0 | L10: 0 | M10: 131 | N10: 0 | O10: =SUM(C10:L10,N10) -> 130 | P10: =SUM(C10:N10) -> 261 | R10: 0700-0800 | S10: =SUM(C10:C13) -> 222 | T10: =SUM(D10:D13) -> 61 | U10: =SUM(E10:E13) -> 27 | V10: =SUM(F10:F13) -> 138 | W10: =SUM(G10:G13) -> 0 | X10: =SUM(H10:H13) -> 3 | Y10: =SUM(I10:I13) -> 17 | Z10: =SUM(J10:J13) -> 12 | ... AF10: =SUM(P10:P13) -> 921
B11: 07.15 - 07.30 | C11: 60 | D11: 15 | E11: 5 | F11: 29 | G11: 0 | H11: 1 | I11: 6 | J11: 3 | K11: 0 | L11: 0 | M11: 110 | N11: 0 | O11: =SUM(C11:L11,N11) -> 119 | P11: =SUM(C11:N11) -> 229 | R11: 0800-0900 | S11: =SUM(C14:C17) -> 234 | T11: =SUM(D14:D17) -> 22 | U11: =SUM(E14:E17) -> 8 | V11: =SUM(F14:F17) -> 175 | W11: =SUM(G14:G17) -> 6 | X11: =SUM(H14:H17) -> 4 | Y11: =SUM(I14:I17) -> 15 | Z11: =SUM(J14:J17) -> 18 | ... AF11: =SUM(P14:P17) -> 982
B12: 07.30 - 07.45 | C12: 45 | D12: 14 | E12: 2 | F12: 30 | G12: 0 | H12: 1 | I12: 5 | J12: 0 | K12: 0 | L12: 0 | M12: 95 | N12: 0 | O12: =SUM(C12:L12,N12) -> 97 | P12: =SUM(C12:N12) -> 192 | R12: 0900-1000 | S12: =SUM(C18:C21) -> 269 | T12: =SUM(D18:D21) -> 30 | U12: =SUM(E18:E21) -> 31 | V12: =SUM(F18:F21) -> 155 | W12: =SUM(G18:G21) -> 4 | X12: =SUM(H18:H21) -> 3 | Y12: =SUM(I18:I21) -> 19 | Z12: =SUM(J18:J21) -> 28 | ... AF12: =SUM(P18:P21) -> 1050
B13: 07.45 - 08.00 | C13: 67 | D13: 12 | E13: 2 | F13: 43 | G13: 0 | H13: 1 | I13: 5 | J13: 4 | K13: 0 | L13: 0 | M13: 105 | N13: 0 | O13: =SUM(C13:L13,N13) -> 134 | P13: =SUM(C13:N13) -> 239 | R13: 1000-1100 | S13: =SUM(C22:C25) -> 227 | T13: =SUM(D22:D25) -> 22 | U13: =SUM(E22:E25) -> 21 | V13: =SUM(F22:F25) -> 203 | W13: =SUM(G22:G25) -> 4 | X13: =SUM(H22:H25) -> 1 | Y13: =SUM(I22:I25) -> 46 | Z13: =SUM(J22:J25) -> 34 | ... AF13: =SUM(P22:P25) -> 1011
B14: 08.00 - 08.15 | C14: 75 | D14: 6 | E14: 2 | F14: 50 | G14: 0 | H14: 1 | I14: 5 | J14: 7 | K14: 0 | L14: 0 | M14: 115 | N14: 0 | O14: =SUM(C14:L14,N14) -> 146 | P14: =SUM(C14:N14) -> 261 | R14: 1100-1200 | S14: =SUM(C26:C29) -> 224 | T14: =SUM(D26:D29) -> 30 | U14: =SUM(E26:E29) -> 26 | V14: =SUM(F26:F29) -> 169 | W14: =SUM(G26:G29) -> 1 | X14: =SUM(H26:H29) -> 4 | Y14: =SUM(I26:I29) -> 52 | Z14: =SUM(J26:J29) -> 33 | ... AF14: =SUM(P26:P29) -> 865
B15: 08.15 - 08.30 | C15: 39 | D15: 1 | E15: 1 | F15: 17 | G15: 2 | H15: 0 | I15: 4 | J15: 0 | K15: 0 | L15: 0 | M15: 135 | N15: 0 | O15: =SUM(C15:L15,N15) -> 64 | P15: =SUM(C15:N15) -> 199 | R15: 1200-1300 | S15: =SUM(C30:C33) -> 133 | T15: =SUM(D30:D33) -> 30 | U15: =SUM(E30:E33) -> 24 | V15: =SUM(F30:F33) -> 131 | W15: =SUM(G30:G33) -> 3 | X15: =SUM(H30:H33) -> 1 | Y15: =SUM(I30:I33) -> 50 | Z15: =SUM(J30:J33) -> 25 | ... AF15: =SUM(P30:P33) -> 694
B16: 08.30 - 08.45 | C16: 50 | D16: 9 | E16: 2 | F16: 51 | G16: 2 | H16: 2 | I16: 2 | J16: 5 | K16: 1 | L16: 0 | M16: 133 | N16: 0 | O16: =SUM(C16:L16,N16) -> 124 | P16: =SUM(C16:N16) -> 257 | R16: 1300-1400 | S16: =SUM(C34:C37) -> 145 | T16: =SUM(D34:D37) -> 29 | U16: =SUM(E34:E37) -> 27 | V16: =SUM(F34:F37) -> 144 | W16: =SUM(G34:G37) -> 1 | X16: =SUM(H34:H37) -> 1 | Y16: =SUM(I34:I37) -> 68 | Z16: =SUM(J34:J37) -> 32 | ... AF16: =SUM(P34:P37) -> 736
B17: 08.45 - 9.00 | C17: 70 | D17: 6 | E17: 3 | F17: 57 | G17: 2 | H17: 1 | I17: 4 | J17: 6 | K17: 1 | L17: 0 | M17: 115 | N17: 0 | O17: =SUM(C17:L17,N17) -> 150 | P17: =SUM(C17:N17) -> 265 | R17: 1400-1500 | S17: =SUM(C38:C41) -> 166 | T17: =SUM(D38:D41) -> 19 | U17: =SUM(E38:E41) -> 29 | V17: =SUM(F38:F41) -> 146 | W17: =SUM(G38:G41) -> 2 | X17: =SUM(H38:H41) -> 3 | Y17: =SUM(I38:I41) -> 59 | Z17: =SUM(J38:J41) -> 30 | ... AF17: =SUM(P38:P41) -> 824
B18: 09.00 - 09.15 | C18: 63 | D18: 12 | E18: 21 | F18: 42 | G18: 3 | H18: 1 | I18: 1 | J18: 11 | K18: 2 | L18: 0 | M18: 145 | N18: 0 | O18: =SUM(C18:L18,N18) -> 156 | P18: =SUM(C18:N18) -> 301 | R18: 1500-1600 | S18: =SUM(C42:C45) -> 151 | T18: =SUM(D42:D45) -> 13 | U18: =SUM(E42:E45) -> 11 | V18: =SUM(F42:F45) -> 111 | W18: =SUM(G42:G45) -> 5 | X18: =SUM(H42:H45) -> 1 | Y18: =SUM(I42:I45) -> 48 | Z18: =SUM(J42:J45) -> 26 | ... AF18: =SUM(P42:P45) -> 473
B19: 09.15 - 09.30 | C19: 55 | D19: 7 | E19: 6 | F19: 47 | G19: 1 | H19: 1 | I19: 5 | J19: 5 | K19: 2 | L19: 1 | M19: 130 | N19: 0 | O19: =SUM(C19:L19,N19) -> 130 | P19: =SUM(C19:N19) -> 260 | R19: 1600-1700 | S19: =SUM(C46:C49) -> 122 | T19: =SUM(D46:D49) -> 25 | U19: =SUM(E46:E49) -> 22 | V19: =SUM(F46:F49) -> 135 | W19: =SUM(G46:G49) -> 2 | X19: =SUM(H46:H49) -> 1 | Y19: =SUM(I46:I49) -> 63 | Z19: =SUM(J46:J49) -> 35 | ... AF19: =SUM(P46:P49) -> 892
B20: 09.30 - 09.45 | C20: 70 | D20: 4 | E20: 1 | F20: 38 | G20: 0 | H20: 1 | I20: 9 | J20: 5 | K20: 1 | L20: 0 | M20: 110 | N20: 0 | O20: =SUM(C20:L20,N20) -> 129 | P20: =SUM(C20:N20) -> 239 | R20: 1700-1800 | S20: =SUM(C50:C53) -> 182 | T20: =SUM(D50:D53) -> 27 | U20: =SUM(E50:E53) -> 9 | V20: =SUM(F50:F53) -> 228 | W20: =SUM(G50:G53) -> 6 | X20: =SUM(H50:H53) -> 1 | Y20: =SUM(I50:I53) -> 69 | Z20: =SUM(J50:J53) -> 31 | ... AF20: =SUM(P50:P53) -> 1192
B21: 09.45 - 10.00 | C21: 81 | D21: 7 | E21: 3 | F21: 28 | G21: 0 | H21: 0 | I21: 4 | J21: 7 | K21: 2 | L21: 0 | M21: 118 | N21: 0 | O21: =SUM(C21:L21,N21) -> 132 | P21: =SUM(C21:N21) -> 250 | R21: 1800-1900 | S21: =SUM(C54:C57) -> 162 | T21: =SUM(D54:D57) -> 18 | U21: =SUM(E54:E57) -> 17 | V21: =SUM(F54:F57) -> 246 | W21: =SUM(G54:G57) -> 10 | X21: =SUM(H54:H57) -> 6 | Y21: =SUM(I54:I57) -> 56 | Z21: =SUM(J54:J57) -> 45 | ... AF21: =SUM(P54:P57) -> 1273
B22: 10.00 - 10.15 | C22: 60 | D22: 3 | E22: 5 | F22: 60 | G22: 2 | H22: 0 | I22: 9 | J22: 4 | K22: 1 | L22: 0 | M22: 130 | N22: 0 | O22: =SUM(C22:L22,N22) -> 144 | P22: =SUM(C22:N22) -> 274 | R22: AM Peak Hr | S22: =MAX(S10:S12) -> 269 | T22: =MAX(T10:T12) -> 61 | U22: =MAX(U10:U12) -> 31 | V22: =MAX(V10:V12) -> 175 | W22: =MAX(W10:W12) -> 6 | X22: =MAX(X10:X12) -> 4 | Y22: =MAX(Y10:Y12) -> 19 | Z22: =MAX(Z10:Z12) -> 28 | ... AF22: =MAX(AF10:AF12) -> 1050
B23: 10.15 - 10.30 | C23: 51 | D23: 3 | E23: 3 | F23: 39 | G23: 1 | H23: 0 | I23: 12 | J23: 10 | K23: 3 | L23: 0 | M23: 115 | N23: 0 | O23: =SUM(C23:L23,N23) -> 122 | P23: =SUM(C23:N23) -> 237 | R23: IP Peak Hr | S23: =MAX(S13:S18) -> 227 | T23: =MAX(T13:T18) -> 30 | U23: =MAX(U13:U18) -> 29 | V23: =MAX(V13:V18) -> 203 | W23: =MAX(W13:W18) -> 5 | X23: =MAX(X13:X18) -> 4 | Y23: =MAX(Y13:Y18) -> 68 | Z23: =MAX(Z13:Z18) -> 34 | ... AF23: =MAX(AF13:AF18) -> 1011
B24: 10.30 - 10.45 | C24: 66 | D24: 12 | E24: 4 | F24: 58 | G24: 1 | H24: 1 | I24: 13 | J24: 8 | K24: 1 | L24: 0 | M24: 110 | N24: 0 | O24: =SUM(C24:L24,N24) -> 164 | P24: =SUM(C24:N24) -> 274 | R24: PM Peak Hr | S24: =MAX(S19:S21) -> 182 | T24: =MAX(T19:T21) -> 27 | U24: =MAX(U19:U21) -> 22 | V24: =MAX(V19:V21) -> 246 | W24: =MAX(W19:W21) -> 10 | X24: =MAX(X19:X21) -> 6 | Y24: =MAX(Y19:Y21) -> 69 | Z24: =MAX(Z19:Z21) -> 45 | ... AF24: =MAX(AF19:AF21) -> 1273
B25: 10.45 - 11.00 | C25: 50 | D25: 4 | E25: 9 | F25: 46 | G25: 0 | H25: 0 | I25: 12 | J25: 12 | K25: 3 | L25: 0 | M25: 90 | N25: 0 | O25: =SUM(C25:L25,N25) -> 136 | P25: =SUM(C25:N25) -> 226 | R25: AM Period | S25: =SUM(S10:S12) -> 725 | T25: =SUM(T10:T12) -> 113 | U25: =SUM(U10:U12) -> 66 | V25: =SUM(V10:V12) -> 468 | W25: =SUM(W10:W12) -> 10 | X25: =SUM(X10:X12) -> 10 | Y25: =SUM(Y10:Y12) -> 51 | Z25: =SUM(Z10:Z12) -> 58 | ... AF25: =SUM(AF10:AF12) -> 2953
B26: 11.00 - 11.15 | C26: 50 | D26: 10 | E26: 11 | F26: 44 | G26: 0 | H26: 1 | I26: 15 | J26: 8 | K26: 2 | L26: 0 | M26: 45 | N26: 0 | O26: =SUM(C26:L26,N26) -> 141 | P26: =SUM(C26:N26) -> 186 | R26: IP Period | S26: =SUM(S13:S18) -> 1046 | T26: =SUM(T13:T18) -> 143 | U26: =SUM(U13:U18) -> 138 | V26: =SUM(V13:V18) -> 904 | W26: =SUM(W13:W18) -> 16 | X26: =SUM(X13:X18) -> 11 | Y26: =SUM(Y13:Y18) -> 323 | Z26: =SUM(Z13:Z18) -> 180 | ... AF26: =SUM(AF13:AF18) -> 4603
B27: 11.15 - 11.30 | C27: 57 | D27: 7 | E27: 6 | F27: 48 | G27: 1 | H27: 1 | I27: 13 | J27: 9 | K27: 0 | L27: 0 | M27: 85 | N27: 0 | O27: =SUM(C27:L27,N27) -> 142 | P27: =SUM(C27:N27) -> 227 | R27: PM Period | S27: =SUM(S19:S21) -> 466 | T27: =SUM(T19:T21) -> 70 | U27: =SUM(U19:U21) -> 48 | V27: =SUM(V19:V21) -> 609 | W27: =SUM(W19:W21) -> 18 | X27: =SUM(X19:X21) -> 8 | Y27: =SUM(Y19:Y21) -> 188 | Z27: =SUM(Z19:Z21) -> 111 | ... AF27: =SUM(AF19:AF21) -> 3357
B28: 11.30 - 11.45 | C28: 70 | D28: 6 | E28: 4 | F28: 37 | G28: 0 | H28: 2 | I28: 12 | J28: 8 | K28: 2 | L28: 0 | M28: 80 | N28: 0 | O28: =SUM(C28:L28,N28) -> 141 | P28: =SUM(C28:N28) -> 221 | R28: 12 Hours | S28: =SUM(S10:S21) -> 2237 | T28: =SUM(T10:T21) -> 326 | U28: =SUM(U10:U21) -> 252 | V28: =SUM(V10:V21) -> 1981 | W28: =SUM(W10:W21) -> 44 | X28: =SUM(X10:X21) -> 29 | Y28: =SUM(Y10:Y21) -> 562 | Z28: =SUM(Z10:Z21) -> 349 | ... AF28: =SUM(AF10:AF21) -> 10913
B29: 11.45 - 12.00 | C29: 47 | D29: 7 | E29: 5 | F29: 40 | G29: 0 | H29: 0 | I29: 12 | J29: 8 | K29: 1 | L29: 0 | M29: 111 | N29: 0 | O29: =SUM(C29:L29,N29) -> 120 | P29: =SUM(C29:N29) -> 231
B30: 12.00 - 12.15 | C30: 50 | D30: 12 | E30: 13 | F30: 49 | G30: 3 | H30: 0 | I30: 17 | J30: 9 | K30: 1 | L30: 0 | M30: 114 | N30: 0 | O30: =SUM(C30:L30,N30) -> 154 | P30: =SUM(C30:N30) -> 268
B31: 12.15 - 12.30 | C31: 25 | D31: 8 | E31: 3 | F31: 13 | G31: 0 | H31: 0 | I31: 4 | J31: 2 | K31: 1 | L31: 0 | M31: 83 | N31: 0 | O31: =SUM(C31:L31,N31) -> 56 | P31: =SUM(C31:N31) -> 139
B32: 12.30 - 12.45 | C32: 44 | D32: 8 | E32: 6 | F32: 49 | G32: 0 | H32: 1 | I32: 21 | J32: 10 | K32: 1 | L32: 0 | M32: 66 | N32: 0 | O32: =SUM(C32:L32,N32) -> 140 | P32: =SUM(C32:N32) -> 206
B33: 12.45 - 13.00 | C33: 14 | D33: 2 | E33: 2 | F33: 20 | G33: 0 | H33: 0 | I33: 8 | J33: 4 | K33: 1 | L33: 0 | M33: 30 | N33: 0 | O33: =SUM(C33:L33,N33) -> 51 | P33: =SUM(C33:N33) -> 81
B34: 13.00 - 13.15 | C34: 40 | D34: 10 | E34: 6 | F34: 35 | G34: 0 | H34: 1 | I34: 21 | J34: 7 | K34: 0 | L34: 0 | M34: 71 | N34: 0 | O34: =SUM(C34:L34,N34) -> 120 | P34: =SUM(C34:N34) -> 191
B35: 13.15 - 13.30 | C35: 29 | D35: 4 | E35: 4 | F35: 25 | G35: 1 | H35: 0 | I35: 16 | J35: 5 | K35: 0 | L35: 0 | M35: 69 | N35: 0 | O35: =SUM(C35:L35,N35) -> 84 | P35: =SUM(C35:N35) -> 153
B36: 13.30 - 13.45 | C36: 37 | D36: 8 | E36: 13 | F36: 46 | G36: 0 | H36: 0 | I36: 13 | J36: 6 | K36: 0 | L36: 0 | M36: 78 | N36: 0 | O36: =SUM(C36:L36,N36) -> 123 | P36: =SUM(C36:N36) -> 201
B37: 13.45 - 14.00 | C37: 39 | D37: 7 | E37: 4 | F37: 38 | G37: 0 | H37: 0 | I37: 18 | J37: 14 | K37: 2 | L37: 0 | M37: 69 | N37: 0 | O37: =SUM(C37:L37,N37) -> 122 | P37: =SUM(C37:N37) -> 191
B38: 14.00 - 14.15 | C38: 37 | D38: 5 | E38: 8 | F38: 36 | G38: 0 | H38: 1 | I38: 16 | J38: 7 | K38: 0 | L38: 0 | M38: 97 | N38: 0 | O38: =SUM(C38:L38,N38) -> 110 | P38: =SUM(C38:N38) -> 207
B39: 14.15 - 14.30 | C39: 50 | D39: 6 | E39: 4 | F39: 40 | G39: 0 | H39: 1 | I39: 12 | J39: 10 | K39: 1 | L39: 1 | M39: 110 | N39: 0 | O39: =SUM(C39:L39,N39) -> 125 | P39: =SUM(C39:N39) -> 235
B40: 14.30 - 14.45 | C40: 42 | D40: 3 | E40: 4 | F40: 47 | G40: 0 | H40: 0 | I40: 16 | J40: 9 | K40: 1 | L40: 0 | M40: 86 | N40: 0 | O40: =SUM(C40:L40,N40) -> 122 | P40: =SUM(C40:N40) -> 208
... B57: 18.45 - 19.00 | C57: 38 | D57: 7 | E57: 9 | F57: 79 | G57: 4 | H57: 1 | I57: 10 | J57: 12 | K57: 0 | L57: 0 | M57: 213 | N57: 0 | O57: =SUM(C57:L57,N57) -> 160 | P57: =SUM(C57:N57) -> 373
B58: Totals | C58: =SUM(C10:C57) -> 2237 | D58: =SUM(D10:D57) -> 326 | E58: =SUM(E10:E57) -> 252 | F58: =SUM(F10:F57) -> 1981 | G58: =SUM(G10:G57) -> 44 | H58: =SUM(H10:H57) -> 29 | I58: =SUM(I10:I57) -> 562 | J58: =SUM(J10:J57) -> 349 | ... P58: =SUM(P10:P57) -> 10913
...

Sheet 23.07 KALERWE-GAYAZA
B1: Consultancy services for Preparation of Expressway Development Master Plan (EDMP) for Uganda
B2: MANUAL CLASSIFIED COUNT (MCC)
B3: ROAD NAME: | C3: ='22.07 KALERWE-GAYAZA'!C3:G3 -> MCC - C1 - STN26 - Gayaza Road Kanyanya
C5: Date | D5: 23.07.19 | F5: Location | G5: ='22.07 KALERWE-GAYAZA'!G5:H5 -> DELTA KYEBANDO | J5: Surveyor | K5: ='22.07 KALERWE-GAYAZA'!K5:L5 -> NALUBEGA JOSEPHINE
C6: Dir. From | D6: ='22.07 KALERWE-GAYAZA'!D6:E6 -> KALERWE | F6: Dir. To | G6: ='22.07 KALERWE-GAYAZA'!G6:H6 -> GAYAZA | J6: Supervisor | K6: WALAKILA
B8: Time / Veh Type | R8: SUMMARY TRAFFIC VOLUMES
C9: 1. Car | D9: 2. Station Wagon | E9: 3. Pickups | F9: 4. Minibus, matatu | G9: 5. Medium bus | H9: 6. Large Bus | I9: 7. Light Truck | J9: 8. Medium Truck | K9: 9. Heavy truck | L9: 10. Truck Trailer | M9: 11. Motor cycles | N9: 12. Tractors | O9: Total Excl M/Cycles | P9: Total All | R9: Time | S9: 1. Car | T9: 2. Station Wagon | U9: 3. Pickups | V9: 4. Minibus, matatu | W9: 5. Medium bus | X9: 6. Large Bus | Y9: 7. Light Truck | Z9: 8. Medium Truck | AA9: 9. Heavy truck | AB9: 10. Truck Trailer | AC9: 11. Motorcycles | AD9: 12. Tractors, Graders | AE9: Total Excl M/ Cycles | AF9: Total All
B10: 07.00 - 07.15 | C10: 31 | D10: 9 | E10: 6 | F10: 75 | G10: 4 | H10: 1 | I10: 9 | J10: 2 | K10: 1 | L10: 1 | M10: 150 | N10: 0 | O10: =SUM(C10:L10,N10) -> 139 | P10: =SUM(C10:N10) -> 289 | R10: 0700-0800 | S10: =SUM(C10:C13) -> 113 | T10: =SUM(D10:D13) -> 31 | U10: =SUM(E10:E13) -> 16 | V10: =SUM(F10:F13) -> 250 | W10: =SUM(G10:G13) -> 7 | X10: =SUM(H10:H13) -> 4 | Y10: =SUM(I10:I13) -> 22 | Z10: =SUM(J10:J13) -> 8 | ... AF10: =SUM(P10:P13) -> 1204
B11: 07.15 - 07.30 | C11: 27 | D11: 4 | E11: 2 | F11: 55 | G11: 3 | H11: 1 | I11: 2 | J11: 1 | K11: 1 | L11: 0 | M11: 161 | N11: 0 | O11: =SUM(C11:L11,N11) -> 96 | P11: =SUM(C11:N11) -> 257 | R11: 0800-0900 | S11: =SUM(C14:C17) -> 137 | T11: =SUM(D14:D17) -> 28 | U11: =SUM(E14:E17) -> 30 | V11: =SUM(F14:F17) -> 325 | W11: =SUM(G14:G17) -> 1 | X11: =SUM(H14:H17) -> 1 | Y11: =SUM(I14:I17) -> 29 | Z11: =SUM(J14:J17) -> 2 | ... AF11: =SUM(P14:P17) -> 1694
B12: 07.30 - 07.45 | C12: 35 | D12: 7 | E12: 2 | F12: 53 | G12: 0 | H12: 2 | I12: 10 | J12: 1 | K12: 0 | L12: 0 | M12: 235 | N12: 0 | O12: =SUM(C12:L12,N12) -> 110 | P12: =SUM(C12:N12) -> 345 | R12: 0900-1000 | S12: =SUM(C18:C21) -> 102 | T12: =SUM(D18:D21) -> 54 | U12: =SUM(E18:E21) -> 20 | V12: =SUM(F18:F21) -> 244 | W12: =SUM(G18:G21) -> 3 | X12: =SUM(H18:H21) -> 3 | Y12: =SUM(I18:I21) -> 39 | Z12: =SUM(J18:J21) -> 11 | ... AF12: =SUM(P18:P21) -> 1462
B13: 07.45 - 08.00 | C13: 20 | D13: 11 | E13: 6 | F13: 67 | G13: 0 | H13: 0 | I13: 1 | J13: 4 | K13: 2 | L13: 0 | M13: 202 | N13: 0 | O13: =SUM(C13:L13,N13) -> 111 | P13: =SUM(C13:N13) -> 313 | R13: 1000-1100 | S13: =SUM(C22:C25) -> 192 | T13: =SUM(D22:D25) -> 50 | U13: =SUM(E22:E25) -> 40 | V13: =SUM(F22:F25) -> 284 | W13: =SUM(G22:G25) -> 2 | X13: =SUM(H22:H25) -> 3 | Y13: =SUM(I22:I25) -> 60 | Z13: =SUM(J22:J25) -> 7 | ... AF13: =SUM(P22:P25) -> 1643
B14: 08.00 - 08.15 | C14: 43 | D14: 8 | E14: 6 | F14: 96 | G14: 1 | H14: 0 | I14: 3 | J14: 1 | K14: 0 | L14: 0 | M14: 269 | N14: 0 | O14: =SUM(C14:L14,N14) -> 158 | P14: =SUM(C14:N14) -> 427 | R14: 1100-1200 | S14: =SUM(C26:C29) -> 155 | T14: =SUM(D26:D29) -> 21 | U14: =SUM(E26:E29) -> 22 | V14: =SUM(F26:F29) -> 182 | W14: =SUM(G26:G29) -> 2 | X14: =SUM(H26:H29) -> 5 | Y14: =SUM(I26:I29) -> 43 | Z14: =SUM(J26:J29) -> 14 | ... AF14: =SUM(P26:P29) -> 1120
B15: 08.15 - 08.30 | C15: 30 | D15: 5 | E15: 7 | F15: 63 | G15: 0 | H15: 1 | I15: 11 | J15: 1 | K15: 1 | L15: 0 | M15: 352 | N15: 0 | O15: =SUM(C15:L15,N15) -> 119 | P15: =SUM(C15:N15) -> 471 | R15: 1200-1300 | S15: =SUM(C30:C33) -> 174 | T15: =SUM(D30:D33) -> 36 | U15: =SUM(E30:E33) -> 26 | V15: =SUM(F30:F33) -> 329 | W15: =SUM(G30:G33) -> 1 | X15: =SUM(H30:H33) -> 0 | Y15: =SUM(I30:I33) -> 35 | Z15: =SUM(J30:J33) -> 18 | ... AF15: =SUM(P30:P33) -> 1339
B16: 08.30 - 08.45 | C16: 32 | D16: 8 | E16: 11 | F16: 73 | G16: 0 | H16: 0 | I16: 7 | J16: 0 | K16: 1 | L16: 0 | M16: 207 | N16: 0 | O16: =SUM(C16:L16,N16) -> 132 | P16: =SUM(C16:N16) -> 339 | R16: 1300-1400 | S16: =SUM(C34:C37) -> 156 | T16: =SUM(D34:D37) -> 61 | U16: =SUM(E34:E37) -> 32 | V16: =SUM(F34:F37) -> 186 | W16: =SUM(G34:G37) -> 2 | X16: =SUM(H34:H37) -> 1 | Y16: =SUM(I34:I37) -> 54 | Z16: =SUM(J34:J37) -> 24 | ... AF16: =SUM(P34:P37) -> 1249
B17: 08.45 - 9.00 | C17: 32 | D17: 7 | E17: 6 | F17: 93 | G17: 0 | H17: 0 | I17: 8 | J17: 0 | K17: 0 | L17: 0 | M17: 311 | N17: 0 | O17: =SUM(C17:L17,N17) -> 146 | P17: =SUM(C17:N17) -> 457 | R17: 1400-1500 | S17: =SUM(C38:C41) -> 138 | T17: =SUM(D38:D41) -> 63 | U17: =SUM(E38:E41) -> 41 | V17: =SUM(F38:F41) -> 199 | W17: =SUM(G38:G41) -> 1 | X17: =SUM(H38:H41) -> 4 | Y17: =SUM(I38:I41) -> 72 | Z17: =SUM(J38:J41) -> 5 | ... AF17: =SUM(P38:P41) -> 1202
B18: 09.00 - 09.15 | C18: 24 | D18: 11 | E18: 8 | F18: 58 | G18: 0 | H18: 2 | I18: 7 | J18: 3 | K18: 1 | L18: 4 | M18: 295 | N18: 0 | O18: =SUM(C18:L18,N18) -> 118 | P18: =SUM(C18:N18) -> 413 | R18: 1500-1600 | S18: =SUM(C42:C45) -> 185 | T18: =SUM(D42:D45) -> 61 | U18: =SUM(E42:E45) -> 49 | V18: =SUM(F42:F45) -> 214 | W18: =SUM(G42:G45) -> 1 | X18: =SUM(H42:H45) -> 4 | Y18: =SUM(I42:I45) -> 53 | Z18: =SUM(J42:J45) -> 15 | ... AF18: =SUM(P42:P45) -> 1279
B19: 09.15 - 09.30 | C19: 23 | D19: 19 | E19: 7 | F19: 57 | G19: 0 | H19: 0 | I19: 8 | J19: 5 | K19: 0 | L19: 0 | M19: 225 | N19: 0 | O19: =SUM(C19:L19,N19) -> 119 | P19: =SUM(C19:N19) -> 344 | R19: 1600-1700 | S19: =SUM(C46:C49) -> 240 | T19: =SUM(D46:D49) -> 63 | U19: =SUM(E46:E49) -> 49 | V19: =SUM(F46:F49) -> 188 | W19: =SUM(G46:G49) -> 6 | X19: =SUM(H46:H49) -> 5 | Y19: =SUM(I46:I49) -> 39 | Z19: =SUM(J46:J49) -> 11 | ... AF19: =SUM(P46:P49) -> 1237
B20: 09.30 - 09.45 | C20: 22 | D20: 13 | E20: 2 | F20: 69 | G20: 0 | H20: 0 | I20: 13 | J20: 0 | K20: 0 | L20: 0 | M20: 160 | N20: 0 | O20: =SUM(C20:L20,N20) -> 119 | P20: =SUM(C20:N20) -> 279 | R20: 1700-1800 | S20: =SUM(C50:C53) -> 306 | T20: =SUM(D50:D53) -> 85 | U20: =SUM(E50:E53) -> 35 | V20: =SUM(F50:F53) -> 205 | W20: =SUM(G50:G53) -> 6 | X20: =SUM(H50:H53) -> 6 | Y20: =SUM(I50:I53) -> 28 | Z20: =SUM(J50:J53) -> 11 | ... AF20: =SUM(P50:P53) -> 1476
B21: 09.45 - 10.00 | C21: 33 | D21: 11 | E21: 3 | F21: 60 | G21: 3 | H21: 1 | I21: 11 | J21: 3 | K21: 1 | L21: 0 | M21: 300 | N21: 0 | O21: =SUM(C21:L21,N21) -> 126 | P21: =SUM(C21:N21) -> 426 | R21: 1800-1900 | S21: =SUM(C54:C57) -> 322 | T21: =SUM(D54:D57) -> 93 | U21: =SUM(E54:E57) -> 46 | V21: =SUM(F54:F57) -> 201 | W21: =SUM(G54:G57) -> 8 | X21: =SUM(H54:H57) -> 4 | Y21: =SUM(I54:I57) -> 45 | Z21: =SUM(J54:J57) -> 7 | ... AF21: =SUM(P54:P57) -> 2001
B22: 10.00 - 10.15 | C22: 32 | D22: 13 | E22: 9 | F22: 57 | G22: 0 | H22: 2 | I22: 15 | J22: 0 | K22: 3 | L22: 0 | M22: 300 | N22: 1 | O22: =SUM(C22:L22,N22) -> 132 | P22: =SUM(C22:N22) -> 432 | R22: AM Peak Hr | S22: =MAX(S10:S12) -> 137 | T22: =MAX(T10:T12) -> 54 | U22: =MAX(U10:U12) -> 30 | V22: =MAX(V10:V12) -> 325 | W22: =MAX(W10:W12) -> 7 | X22: =MAX(X10:X12) -> 4 | Y22: =MAX(Y10:Y12) -> 39 | Z22: =MAX(Z10:Z12) -> 11 | ... AF22: =MAX(AF10:AF12) -> 1694
B23: 10.15 - 10.30 | C23: 56 | D23: 18 | E23: 15 | F23: 61 | G23: 0 | H23: 1 | I23: 13 | J23: 2 | K23: 0 | L23: 1 | M23: 205 | N23: 0 | O23: =SUM(C23:L23,N23) -> 167 | P23: =SUM(C23:N23) -> 372 | R23: IP Peak Hr | S23: =MAX(S13:S18) -> 192 | T23: =MAX(T13:T18) -> 63 | U23: =MAX(U13:U18) -> 49 | V23: =MAX(V13:V18) -> 329 | W23: =MAX(W13:W18) -> 2 | X23: =MAX(X13:X18) -> 5 | Y23: =MAX(Y13:Y18) -> 72 | Z23: =MAX(Z13:Z18) -> 24 | ... AF23: =MAX(AF13:AF18) -> 1643
B24: 10.30 - 10.45 | C24: 55 | D24: 8 | E24: 11 | F24: 105 | G24: 1 | H24: 0 | I24: 22 | J24: 2 | K24: 4 | L24: 0 | M24: 330 | N24: 0 | O24: =SUM(C24:L24,N24) -> 208 | P24: =SUM(C24:N24) -> 538 | R24: PM Peak Hr | S24: =MAX(S19:S21) -> 322 | T24: =MAX(T19:T21) -> 93 | U24: =MAX(U19:U21) -> 49 | V24: =MAX(V19:V21) -> 205 | W24: =MAX(W19:W21) -> 8 | X24: =MAX(X19:X21) -> 6 | Y24: =MAX(Y19:Y21) -> 45 | Z24: =MAX(Z19:Z21) -> 11 | ... AF24: =MAX(AF19:AF21) -> 2001
B25: 10.45 - 11.00 | C25: 49 | D25: 11 | E25: 5 | F25: 61 | G25: 1 | H25: 0 | I25: 10 | J25: 3 | K25: 0 | L25: 0 | M25: 161 | N25: 0 | O25: =SUM(C25:L25,N25) -> 140 | P25: =SUM(C25:N25) -> 301 | R25: AM Period | S25: =SUM(S10:S12) -> 352 | T25: =SUM(T10:T12) -> 113 | U25: =SUM(U10:U12) -> 66 | V25: =SUM(V10:V12) -> 819 | W25: =SUM(W10:W12) -> 11 | X25: =SUM(X10:X12) -> 8 | Y25: =SUM(Y10:Y12) -> 90 | Z25: =SUM(Z10:Z12) -> 21 | ... AF25: =SUM(AF10:AF12) -> 4360
B26: 11.00 - 11.15 | C26: 39 | D26: 5 | E26: 6 | F26: 18 | G26: 0 | H26: 3 | I26: 19 | J26: 2 | K26: 0 | L26: 0 | M26: 205 | N26: 0 | O26: =SUM(C26:L26,N26) -> 92 | P26: =SUM(C26:N26) -> 297 | R26: IP Period | S26: =SUM(S13:S18) -> 1000 | T26: =SUM(T13:T18) -> 292 | U26: =SUM(U13:U18) -> 210 | V26: =SUM(V13:V18) -> 1394 | W26: =SUM(W13:W18) -> 9 | X26: =SUM(X13:X18) -> 17 | Y26: =SUM(Y13:Y18) -> 317 | Z26: =SUM(Z13:Z18) -> 83 | ... AF26: =SUM(AF13:AF18) -> 7832
B27: 11.15 - 11.30 | C27: 27 | D27: 9 | E27: 5 | F27: 32 | G27: 1 | H27: 1 | I27: 7 | J27: 4 | K27: 0 | L27: 0 | M27: 195 | N27: 0 | O27: =SUM(C27:L27,N27) -> 86 | P27: =SUM(C27:N27) -> 281 | R27: PM Period | S27: =SUM(S19:S21) -> 868 | T27: =SUM(T19:T21) -> 241 | U27: =SUM(U19:U21) -> 130 | V27: =SUM(V19:V21) -> 594 | W27: =SUM(W19:W21) -> 20 | X27: =SUM(X19:X21) -> 15 | Y27: =SUM(Y19:Y21) -> 112 | Z27: =SUM(Z19:Z21) -> 29 | ... AF27: =SUM(AF19:AF21) -> 4714
B28: 11.30 - 11.45 | C28: 43 | D28: 5 | E28: 5 | F28: 57 | G28: 0 | H28: 0 | I28: 9 | J28: 5 | K28: 2 | L28: 1 | M28: 145 | N28: 0 | O28: =SUM(C28:L28,N28) -> 127 | P28: =SUM(C28:N28) -> 272 | R28: 12 Hours | S28: =SUM(S10:S21) -> 2220 | T28: =SUM(T10:T21) -> 646 | U28: =SUM(U10:U21) -> 406 | V28: =SUM(V10:V21) -> 2807 | W28: =SUM(W10:W21) -> 40 | X28: =SUM(X10:X21) -> 40 | Y28: =SUM(Y10:Y21) -> 519 | Z28: =SUM(Z10:Z21) -> 133 | ... AF28: =SUM(AF10:AF21) -> 16906
B29: 11.45 - 12.00 | C29: 46 | D29: 2 | E29: 6 | F29: 75 | G29: 1 | H29: 1 | I29: 8 | J29: 3 | K29: 1 | L29: 2 | M29: 125 | N29: 0 | O29: =SUM(C29:L29,N29) -> 145 | P29: =SUM(C29:N29) -> 270
B30: 12.00 - 12.15 | C30: 25 | D30: 3 | E30: 4 | F30: 104 | G30: 1 | H30: 0 | I30: 5 | J30: 2 | K30: 2 | L30: 0 | M30: 190 | N30: 0 | O30: =SUM(C30:L30,N30) -> 146 | P30: =SUM(C30:N30) -> 336
B31: 12.15 - 12.30 | C31: 65 | D31: 12 | E31: 9 | F31: 60 | G31: 0 | H31: 0 | I31: 10 | J31: 3 | K31: 2 | L31: 1 | M31: 180 | N31: 0 | O31: =SUM(C31:L31,N31) -> 162 | P31: =SUM(C31:N31) -> 342
B32: 12.30 - 12.45 | C32: 54 | D32: 14 | E32: 8 | F32: 90 | G32: 0 | H32: 0 | I32: 10 | J32: 4 | K32: 0 | L32: 0 | M32: 200 | N32: 0 | O32: =SUM(C32:L32,N32) -> 180 | P32: =SUM(C32:N32) -> 380
B33: 12.45 - 13.00 | C33: 30 | D33: 7 | E33: 5 | F33: 75 | G33: 0 | H33: 0 | I33: 10 | J33: 9 | K33: 2 | L33: 3 | M33: 140 | N33: 0 | O33: =SUM(C33:L33,N33) -> 141 | P33: =SUM(C33:N33) -> 281
B34: 13.00 - 13.15 | C34: 30 | D34: 20 | E34: 8 | F34: 38 | G34: 0 | H34: 0 | I34: 13 | J34: 16 | K34: 0 | L34: 0 | M34: 155 | N34: 0 | O34: =SUM(C34:L34,N34) -> 125 | P34: =SUM(C34:N34) -> 280
B35: 13.15 - 13.30 | C35: 41 | D35: 16 | E35: 4 | F35: 37 | G35: 0 | H35: 1 | I35: 10 | J35: 6 | K35: 0 | L35: 2 | M35: 160 | N35: 0 | O35: =SUM(C35:L35,N35) -> 117 | P35: =SUM(C35:N35) -> 277
B36: 13.30 - 13.45 | C36: 32 | D36: 16 | E36: 11 | F36: 54 | G36: 2 | H36: 0 | I36: 12 | J36: 1 | K36: 2 | L36: 0 | M36: 230 | N36: 0 | O36: =SUM(C36:L36,N36) -> 130 | P36: =SUM(C36:N36) -> 360
B37: 13.45 - 14.00 | C37: 53 | D37: 9 | E37: 9 | F37: 57 | G37: 0 | H37: 0 | I37: 19 | J37: 1 | K37: 1 | L37: 0 | M37: 183 | N37: 0 | O37: =SUM(C37:L37,N37) -> 149 | P37: =SUM(C37:N37) -> 332
B38: 14.00 - 14.15 | C38: 31 | D38: 12 | E38: 9 | F38: 48 | G38: 1 | H38: 0 | I38: 22 | J38: 4 | K38: 0 | L38: 2 | M38: 105 | N38: 0 | O38: =SUM(C38:L38,N38) -> 129 | P38: =SUM(C38:N38) -> 234
B39: 14.15 - 14.30 | C39: 37 | D39: 16 | E39: 4 | F39: 52 | G39: 0 | H39: 2 | I39: 15 | J39: 0 | K39: 4 | L39: 0 | M39: 172 | N39: 0 | O39: =SUM(C39:L39,N39) -> 130 | P39: =SUM(C39:N39) -> 302
B40: 14.30 - 14.45 | C40: 45 | D40: 15 | E40: 14 | F40: 55 | G40: 0 | H40: 2 | I40: 20 | J40: 0 | K40: 9 | L40: 0 | M40: 165 | N40: 0 | O40: =SUM(C40:L40,N40) -> 160 | P40: =SUM(C40:N40) -> 325
... B57: 18.45 - 19.00 | C57: 65 | D57: 17 | E57: 2 | F57: 55 | G57: 2 | H57: 1 | I57: 5 | J57: 0 | K57: 0 | L57: 0 | M57: 265 | N57: 0 | O57: =SUM(C57:L57,N57) -> 147 | P57: =SUM(C57:N57) -> 412
B58: Totals | C58: =SUM(C10:C57) -> 2220 | D58: =SUM(D10:D57) -> 646 | E58: =SUM(E10:E57) -> 406 | F58: =SUM(F10:F57) -> 2807 | G58: =SUM(G10:G57) -> 40 | H58: =SUM(H10:H57) -> 40 | I58: =SUM(I10:I57) -> 519 | J58: =SUM(J10:J57) -> 133 | ... P58: =SUM(P10:P57) -> 16906
...

Sheet 23.07 GAYAZA-KALERWE
B1: Consultancy services for Preparation of Expressway Development Master Plan (EDMP) for Uganda
B2: MANUAL CLASSIFIED COUNT (MCC)
B3: ROAD NAME: | C3: ='22.07 GAYAZA-KALERWE'!C3:G3 -> MCC - C1 - STN26 - Gayaza Road Kanyanya
C5: Date | D5: ='23.07 KALERWE-GAYAZA'!D5 -> 23.07.19 | F5: Location | G5: ='22.07 KALERWE-GAYAZA'!G5:H5 -> DELTA KYEBANDO | J5: Surveyor | K5: MORREEN
C6: Dir. From | D6: ='22.07 GAYAZA-KALERWE'!D6:E6 -> GAYAZA | F6: Dir. To | G6: ='22.07 GAYAZA-KALERWE'!G6:H6 -> KALERWE | J6: Supervisor | K6: LAWRENCE
B8: Time / Veh Type | R8: SUMMARY TRAFFIC VOLUMES
C9: 1. Car | D9: 2. Station Wagon | E9: 3. Pickups | F9: 4. Minibus, matatu | G9: 5. Medium bus | H9: 6. Large Bus | I9: 7. Light Truck | J9: 8. Medium Truck | K9: 9. Heavy truck | L9: 10. Truck Trailer | M9: 11. Motor cycles | N9: 12. Tractors | O9: Total Excl M/Cycles | P9: Total All | R9: Time | S9: 1. Car | T9: 2. Station Wagon | U9: 3. Pickups | V9: 4. Minibus, matatu | W9: 5. Medium bus | X9: 6. Large Bus | Y9: 7. Light Truck | Z9: 8. Medium Truck | AA9: 9. Heavy truck | AB9: 10. Truck Trailer | AC9: 11. Motorcycles | AD9: 12. Tractors, Graders | AE9: Total Excl M/ Cycles | AF9: Total All
B10: 07.00 - 07.15 | C10: 70 | D10: 11 | E10: 8 | F10: 58 | G10: 1 | H10: 2 | I10: 7 | J10: 1 | K10: 0 | L10: 0 | M10: 335 | N10: 0 | O10: =SUM(C10:L10,N10) -> 158 | P10: =SUM(C10:N10) -> 493 | R10: 0700-0800 | S10: =SUM(C10:C13) -> 499 | T10: =SUM(D10:D13) -> 44 | U10: =SUM(E10:E13) -> 22 | V10: =SUM(F10:F13) -> 178 | W10: =SUM(G10:G13) -> 3 | X10: =SUM(H10:H13) -> 3 | Y10: =SUM(I10:I13) -> 17 | Z10: =SUM(J10:J13) -> 9 | ... AF10: =SUM(P10:P13) -> 1815
B11: 07.15 - 07.30 | C11: 50 | D11: 12 | E11: 3 | F11: 42 | G11: 2 | H11: 0 | I11: 2 | J11: 1 | K11: 0 | L11: 0 | M11: 200 | N11: 0 | O11: =SUM(C11:L11,N11) -> 112 | P11: =SUM(C11:N11) -> 312 | R11: 0800-0900 | S11: =SUM(C14:C17) -> 188 | T11: =SUM(D14:D17) -> 33 | U11: =SUM(E14:E17) -> 25 | V11: =SUM(F14:F17) -> 172 | W11: =SUM(G14:G17) -> 7 | X11: =SUM(H14:H17) -> 2 | Y11: =SUM(I14:I17) -> 31 | Z11: =SUM(J14:J17) -> 10 | ... AF11: =SUM(P14:P17) -> 1489
B12: 07.30 - 07.45 | C12: 332 | D12: 13 | E12: 5 | F12: 32 | G12: 0 | H12: 1 | I12: 4 | J12: 5 | K12: 0 | L12: 0 | M12: 255 | N12: 0 | O12: =SUM(C12:L12,N12) -> 392 | P12: =SUM(C12:N12) -> 647 | R12: 0900-1000 | S12: =SUM(C18:C21) -> 212 | T12: =SUM(D18:D21) -> 44 | U12: =SUM(E18:E21) -> 26 | V12: =SUM(F18:F21) -> 205 | W12: =SUM(G18:G21) -> 2 | X12: =SUM(H18:H21) -> 4 | Y12: =SUM(I18:I21) -> 54 | Z12: =SUM(J18:J21) -> 13 | ... AF12: =SUM(P18:P21) -> 1357
B13: 07.45 - 08.00 | C13: 47 | D13: 8 | E13: 6 | F13: 46 | G13: 0 | H13: 0 | I13: 4 | J13: 2 | K13: 0 | L13: 0 | M13: 250 | N13: 0 | O13: =SUM(C13:L13,N13) -> 113 | P13: =SUM(C13:N13) -> 363 | R13: 1000-1100 | S13: =SUM(C22:C25) -> 289 | T13: =SUM(D22:D25) -> 55 | U13: =SUM(E22:E25) -> 22 | V13: =SUM(F22:F25) -> 238 | W13: =SUM(G22:G25) -> 3 | X13: =SUM(H22:H25) -> 1 | Y13: =SUM(I22:I25) -> 40 | Z13: =SUM(J22:J25) -> 34 | ... AF13: =SUM(P22:P25) -> 1690
B14: 08.00 - 08.15 | C14: 30 | D14: 11 | E14: 7 | F14: 40 | G14: 2 | H14: 0 | I14: 5 | J14: 0 | K14: 1 | L14: 0 | M14: 240 | N14: 0 | O14: =SUM(C14:L14,N14) -> 96 | P14: =SUM(C14:N14) -> 336 | R14: 1100-1200 | S14: =SUM(C26:C29) -> 263 | T14: =SUM(D26:D29) -> 34 | U14: =SUM(E26:E29) -> 28 | V14: =SUM(F26:F29) -> 260 | W14: =SUM(G26:G29) -> 1 | X14: =SUM(H26:H29) -> 1 | Y14: =SUM(I26:I29) -> 25 | Z14: =SUM(J26:J29) -> 15 | ... AF14: =SUM(P26:P29) -> 1320
B15: 08.15 - 08.30 | C15: 50 | D15: 6 | E15: 4 | F15: 32 | G15: 1 | H15: 1 | I15: 11 | J15: 4 | K15: 3 | L15: 0 | M15: 225 | N15: 0 | O15: =SUM(C15:L15,N15) -> 112 | P15: =SUM(C15:N15) -> 337 | R15: 1200-1300 | S15: =SUM(C30:C33) -> 367 | T15: =SUM(D30:D33) -> 61 | U15: =SUM(E30:E33) -> 38 | V15: =SUM(F30:F33) -> 261 | W15: =SUM(G30:G33) -> 1 | X15: =SUM(H30:H33) -> 3 | Y15: =SUM(I30:I33) -> 39 | Z15: =SUM(J30:J33) -> 44 | ... AF15: =SUM(P30:P33) -> 1325
B16: 08.30 - 08.45 | C16: 59 | D16: 7 | E16: 5 | F16: 47 | G16: 2 | H16: 0 | I16: 9 | J16: 3 | K16: 0 | L16: 0 | M16: 295 | N16: 0 | O16: =SUM(C16:L16,N16) -> 132 | P16: =SUM(C16:N16) -> 427 | R16: 1300-1400 | S16: =SUM(C34:C37) -> 178 | T16: =SUM(D34:D37) -> 45 | U16: =SUM(E34:E37) -> 20 | V16: =SUM(F34:F37) -> 162 | W16: =SUM(G34:G37) -> 3 | X16: =SUM(H34:H37) -> 2 | Y16: =SUM(I34:I37) -> 38 | Z16: =SUM(J34:J37) -> 23 | ... AF16: =SUM(P34:P37) -> 899
B17: 08.45 - 9.00 | C17: 49 | D17: 9 | E17: 9 | F17: 53 | G17: 2 | H17: 1 | I17: 6 | J17: 3 | K17: 1 | L17: 1 | M17: 255 | N17: 0 | O17: =SUM(C17:L17,N17) -> 134 | P17: =SUM(C17:N17) -> 389 | R17: 1400-1500 | S17: =SUM(C38:C41) -> 148 | T17: =SUM(D38:D41) -> 45 | U17: =SUM(E38:E41) -> 32 | V17: =SUM(F38:F41) -> 133 | W17: =SUM(G38:G41) -> 4 | X17: =SUM(H38:H41) -> 0 | Y17: =SUM(I38:I41) -> 32 | Z17: =SUM(J38:J41) -> 35 | ... AF17: =SUM(P38:P41) -> 734
B18: 09.00 - 09.15 | C18: 47 | D18: 12 | E18: 11 | F18: 60 | G18: 2 | H18: 1 | I18: 11 | J18: 2 | K18: 0 | L18: 0 | M18: 150 | N18: 0 | O18: =SUM(C18:L18,N18) -> 146 | P18: =SUM(C18:N18) -> 296 | R18: 1500-1600 | S18: =SUM(C42:C45) -> 185 | T18: =SUM(D42:D45) -> 57 | U18: =SUM(E42:E45) -> 28 | V18: =SUM(F42:F45) -> 166 | W18: =SUM(G42:G45) -> 1 | X18: =SUM(H42:H45) -> 2 | Y18: =SUM(I42:I45) -> 56 | Z18: =SUM(J42:J45) -> 39 | ... AF18: =SUM(P42:P45) -> 1110
B19: 09.15 - 09.30 | C19: 54 | D19: 14 | E19: 6 | F19: 36 | G19: 0 | H19: 2 | I19: 13 | J19: 6 | K19: 1 | L19: 0 | M19: 235 | N19: 0 | O19: =SUM(C19:L19,N19) -> 132 | P19: =SUM(C19:N19) -> 367 | R19: 1600-1700 | S19: =SUM(C46:C49) -> 253 | T19: =SUM(D46:D49) -> 44 | U19: =SUM(E46:E49) -> 26 | V19: =SUM(F46:F49) -> 245 | W19: =SUM(G46:G49) -> 1 | X19: =SUM(H46:H49) -> 3 | Y19: =SUM(I46:I49) -> 48 | Z19: =SUM(J46:J49) -> 34 | ... AF19: =SUM(P46:P49) -> 1213
B20: 09.30 - 09.45 | C20: 50 | D20: 6 | E20: 5 | F20: 53 | G20: 0 | H20: 0 | I20: 11 | J20: 3 | K20: 0 | L20: 0 | M20: 140 | N20: 0 | O20: =SUM(C20:L20,N20) -> 128 | P20: =SUM(C20:N20) -> 268 | R20: 1700-1800 | S20: =SUM(C50:C53) -> 119 | T20: =SUM(D50:D53) -> 30 | U20: =SUM(E50:E53) -> 17 | V20: =SUM(F50:F53) -> 167 | W20: =SUM(G50:G53) -> 4 | X20: =SUM(H50:H53) -> 3 | Y20: =SUM(I50:I53) -> 34 | Z20: =SUM(J50:J53) -> 30 | ... AF20: =SUM(P50:P53) -> 1147
B21: 09.45 - 10.00 | C21: 61 | D21: 12 | E21: 4 | F21: 56 | G21: 0 | H21: 1 | I21: 19 | J21: 2 | K21: 3 | L21: 1 | M21: 267 | N21: 0 | O21: =SUM(C21:L21,N21) -> 159 | P21: =SUM(C21:N21) -> 426 | R21: 1800-1900 | S21: =SUM(C54:C57) -> 282 | T21: =SUM(D54:D57) -> 36 | U21: =SUM(E54:E57) -> 27 | V21: =SUM(F54:F57) -> 505 | W21: =SUM(G54:G57) -> 3 | X21: =SUM(H54:H57) -> 9 | Y21: =SUM(I54:I57) -> 46 | Z21: =SUM(J54:J57) -> 24 | ... AF21: =SUM(P54:P57) -> 1906
B22: 10.00 - 10.15 | C22: 83 | D22: 15 | E22: 6 | F22: 55 | G22: 0 | H22: 0 | I22: 10 | J22: 8 | K22: 1 | L22: 0 | M22: 160 | N22: 0 | O22: =SUM(C22:L22,N22) -> 178 | P22: =SUM(C22:N22) -> 338 | R22: AM Peak Hr | S22: =MAX(S10:S12) -> 499 | T22: =MAX(T10:T12) -> 44 | U22: =MAX(U10:U12) -> 26 | V22: =MAX(V10:V12) -> 205 | W22: =MAX(W10:W12) -> 7 | X22: =MAX(X10:X12) -> 4 | Y22: =MAX(Y10:Y12) -> 54 | Z22: =MAX(Z10:Z12) -> 13 | ... AF22: =MAX(AF10:AF12) -> 1815
B23: 10.15 - 10.30 | C23: 61 | D23: 17 | E23: 4 | F23: 61 | G23: 2 | H23: 1 | I23: 3 | J23: 6 | K23: 6 | L23: 0 | M23: 288 | N23: 0 | O23: =SUM(C23:L23,N23) -> 161 | P23: =SUM(C23:N23) -> 449 | R23: IP Peak Hr | S23: =MAX(S13:S18) -> 367 | T23: =MAX(T13:T18) -> 61 | U23: =MAX(U13:U18) -> 38 | V23: =MAX(V13:V18) -> 261 | W23: =MAX(W13:W18) -> 4 | X23: =MAX(X13:X18) -> 3 | Y23: =MAX(Y13:Y18) -> 56 | Z23: =MAX(Z13:Z18) -> 44 | ... AF23: =MAX(AF13:AF18) -> 1690
B24: 10.30 - 10.45 | C24: 85 | D24: 9 | E24: 6 | F24: 68 | G24: 0 | H24: 0 | I24: 13 | J24: 6 | K24: 5 | L24: 1 | M24: 340 | N24: 0 | O24: =SUM(C24:L24,N24) -> 193 | P24: =SUM(C24:N24) -> 533 | R24: PM Peak Hr | S24: =MAX(S19:S21) -> 282 | T24: =MAX(T19:T21) -> 44 | U24: =MAX(U19:U21) -> 27 | V24: =MAX(V19:V21) -> 505 | W24: =MAX(W19:W21) -> 4 | X24: =MAX(X19:X21) -> 9 | Y24: =MAX(Y19:Y21) -> 48 | Z24: =MAX(Z19:Z21) -> 34 | ... AF24: =MAX(AF19:AF21) -> 1906
B25: 10.45 - 11.00 | C25: 60 | D25: 14 | E25: 6 | F25: 54 | G25: 1 | H25: 0 | I25: 14 | J25: 14 | K25: 6 | L25: 1 | M25: 200 | N25: 0 | O25: =SUM(C25:L25,N25) -> 170 | P25: =SUM(C25:N25) -> 370 | R25: AM Period | S25: =SUM(S10:S12) -> 899 | T25: =SUM(T10:T12) -> 121 | U25: =SUM(U10:U12) -> 73 | V25: =SUM(V10:V12) -> 555 | W25: =SUM(W10:W12) -> 12 | X25: =SUM(X10:X12) -> 9 | Y25: =SUM(Y10:Y12) -> 102 | Z25: =SUM(Z10:Z12) -> 32 | ... AF25: =SUM(AF10:AF12) -> 4661
B26: 11.00 - 11.15 | C26: 44 | D26: 12 | E26: 8 | F26: 43 | G26: 0 | H26: 1 | I26: 8 | J26: 7 | K26: 3 | L26: 1 | M26: 185 | N26: 0 | O26: =SUM(C26:L26,N26) -> 127 | P26: =SUM(C26:N26) -> 312 | R26: IP Period | S26: =SUM(S13:S18) -> 1430 | T26: =SUM(T13:T18) -> 297 | U26: =SUM(U13:U18) -> 168 | V26: =SUM(V13:V18) -> 1220 | W26: =SUM(W13:W18) -> 13 | X26: =SUM(X13:X18) -> 9 | Y26: =SUM(Y13:Y18) -> 230 | Z26: =SUM(Z13:Z18) -> 190 | ... AF26: =SUM(AF13:AF18) -> 7078
B27: 11.15 - 11.30 | C27: 64 | D27: 9 | E27: 8 | F27: 75 | G27: 0 | H27: 0 | I27: 5 | J27: 3 | K27: 3 | L27: 0 | M27: 159 | N27: 0 | O27: =SUM(C27:L27,N27) -> 167 | P27: =SUM(C27:N27) -> 326 | R27: PM Period | S27: =SUM(S19:S21) -> 654 | T27: =SUM(T19:T21) -> 110 | U27: =SUM(U19:U21) -> 70 | V27: =SUM(V19:V21) -> 917 | W27: =SUM(W19:W21) -> 8 | X27: =SUM(X19:X21) -> 15 | Y27: =SUM(Y19:Y21) -> 128 | Z27: =SUM(Z19:Z21) -> 88 | ... AF27: =SUM(AF19:AF21) -> 4266
B28: 11.30 - 11.45 | C28: 65 | D28: 6 | E28: 4 | F28: 57 | G28: 1 | H28: 0 | I28: 6 | J28: 2 | K28: 3 | L28: 2 | M28: 165 | N28: 0 | O28: =SUM(C28:L28,N28) -> 146 | P28: =SUM(C28:N28) -> 311 | R28: 12 Hours | S28: =SUM(S10:S21) -> 2983 | T28: =SUM(T10:T21) -> 528 | U28: =SUM(U10:U21) -> 311 | V28: =SUM(V10:V21) -> 2692 | W28: =SUM(W10:W21) -> 33 | X28: =SUM(X10:X21) -> 33 | Y28: =SUM(Y10:Y21) -> 460 | Z28: =SUM(Z10:Z21) -> 310 | ... AF28: =SUM(AF10:AF21) -> 16005
B29: 11.45 - 12.00 | C29: 90 | D29: 7 | E29: 8 | F29: 85 | G29: 0 | H29: 0 | I29: 6 | J29: 3 | K29: 2 | L29: 0 | M29: 170 | N29: 0 | O29: =SUM(C29:L29,N29) -> 201 | P29: =SUM(C29:N29) -> 371
B30: 12.00 - 12.15 | C30: 100 | D30: 21 | E30: 15 | F30: 80 | G30: 1 | H30: 1 | I30: 12 | J30: 17 | K30: 6 | L30: 0 | M30: 156 | N30: 0 | O30: =SUM(C30:L30,N30) -> 253 | P30: =SUM(C30:N30) -> 409
B31: 12.15 - 12.30 | C31: 116 | D31: 18 | E31: 10 | F31: 76 | G31: 0 | H31: 0 | I31: 11 | J31: 12 | K31: 5 | L31: 0 | M31: 140 | N31: 0 | O31: =SUM(C31:L31,N31) -> 248 | P31: =SUM(C31:N31) -> 388
B32: 12.30 - 12.45 | C32: 81 | D32: 7 | E32: 5 | F32: 30 | G32: 0 | H32: 1 | I32: 8 | J32: 10 | K32: 5 | L32: 1 | M32: 45 | N32: 0 | O32: =SUM(C32:L32,N32) -> 148 | P32: =SUM(C32:N32) -> 193
B33: 12.45 - 13.00 | C33: 70 | D33: 15 | E33: 8 | F33: 75 | G33: 0 | H33: 1 | I33: 8 | J33: 5 | K33: 3 | L33: 0 | M33: 150 | N33: 0 | O33: =SUM(C33:L33,N33) -> 185 | P33: =SUM(C33:N33) -> 335
B34: 13.00 - 13.15 | C34: 75 | D34: 9 | E34: 3 | F34: 34 | G34: 3 | H34: 0 | I34: 5 | J34: 0 | K34: 3 | L34: 2 | M34: 118 | N34: 0 | O34: =SUM(C34:L34,N34) -> 134 | P34: =SUM(C34:N34) -> 252
B35: 13.15 - 13.30 | C35: 33 | D35: 10 | E35: 8 | F35: 45 | G35: 0 | H35: 0 | I35: 9 | J35: 9 | K35: 2 | L35: 0 | M35: 85 | N35: 0 | O35: =SUM(C35:L35,N35) -> 116 | P35: =SUM(C35:N35) -> 201
B36: 13.30 - 13.45 | C36: 38 | D36: 11 | E36: 4 | F36: 47 | G36: 0 | H36: 1 | I36: 10 | J36: 6 | K36: 1 | L36: 2 | M36: 100 | N36: 0 | O36: =SUM(C36:L36,N36) -> 120 | P36: =SUM(C36:N36) -> 220
B37: 13.45 - 14.00 | C37: 32 | D37: 15 | E37: 5 | F37: 36 | G37: 0 | H37: 1 | I37: 14 | J37: 8 | K37: 5 | L37: 0 | M37: 110 | N37: 0 | O37: =SUM(C37:L37,N37) -> 116 | P37: =SUM(C37:N37) -> 226
B38: 14.00 - 14.15 | C38: 38 | D38: 14 | E38: 12 | F38: 38 | G38: 3 | H38: 0 | I38: 8 | J38: 6 | K38: 3 | L38: 0 | M38: 80 | N38: 0 | O38: =SUM(C38:L38,N38) -> 122 | P38: =SUM(C38:N38) -> 202
B39: 14.15 - 14.30 | C39: 34 | D39: 14 | E39: 4 | F39: 43 | G39: 0 | H39: 0 | I39: 7 | J39: 12 | K39: 5 | L39: 0 | M39: 96 | N39: 0 | O39: =SUM(C39:L39,N39) -> 119 | P39: =SUM(C39:N39) -> 215
B40: 14.30 - 14.45 | C40: 39 | D40: 14 | E40: 9 | F40: 28 | G40: 1 | H40: 0 | I40: 9 | J40: 11 | K40: 10 | L40: 1 | M40: 61 | N40: 0 | O40: =SUM(C40:L40,N40) -> 122 | P40: =SUM(C40:N40) -> 183
... B57: 18.45 - 19.00 | C57: 49 | D57: 10 | E57: 6 | F57: 135 | G57: 0 | H57: 0 | I57: 8 | J57: 8 | K57: 1 | L57: 0 | M57: 193 | N57: 0 | O57: =SUM(C57:L57,N57) -> 217 | P57: =SUM(C57:N57) -> 410
B58: Totals | C58: =SUM(C10:C57) -> 2983 | D58: =SUM(D10:D57) -> 528 | E58: =SUM(E10:E57) -> 311 | F58: =SUM(F10:F57) -> 2692 | G58: =SUM(G10:G57) -> 33 | H58: =SUM(H10:H57) -> 33 | I58: =SUM(I10:I57) -> 460 | J58: =SUM(J10:J57) -> 310 | ... P58: =SUM(P10:P57) -> 16005
...

Sheet 24.07 KALERWE-GAYAZA
B1: Consultancy services for Preparation of Expressway Development Master Plan (EDMP) for Uganda
B2: MANUAL CLASSIFIED COUNT (MCC)
B3: ROAD NAME: | C3: ='22.07 KALERWE-GAYAZA'!C3:G3 -> MCC - C1 - STN26 - Gayaza Road Kanyanya
C5: Date | D5: 24.07.19 | F5: Location | G5: ='22.07 KALERWE-GAYAZA'!G5:H5 -> DELTA KYEBANDO | J5: Surveyor | K5: NALUBEGA JOSEPHINE AND NANDUTU SANDRAH
C6: Dir. From | D6: ='22.07 KALERWE-GAYAZA'!D6:E6 -> KALERWE | F6: Dir. To | G6: ='22.07 KALERWE-GAYAZA'!G6:H6 -> GAYAZA | J6: Supervisor | K6: ='22.07 KALERWE-GAYAZA'!K6:L6 -> WALAKIRA
B8: Time / Veh Type | R8: SUMMARY TRAFFIC VOLUMES
C9: 1. Car | D9: 2. Station Wagon | E9: 3. Pickups | F9: 4. Minibus, matatu | G9: 5. Medium bus | H9: 6. Large Bus | I9: 7. Light Truck | J9: 8. Medium Truck | K9: 9. Heavy truck | L9: 10. Truck Trailer | M9: 11. Motor cycles | N9: 12. Tractors | O9: Total Excl M/Cycles | P9: Total All | R9: Time | S9: 1. Car | T9: 2. Station Wagon | U9: 3. Pickups | V9: 4. Minibus, matatu | W9: 5. Medium bus | X9: 6. Large Bus | Y9: 7. Light Truck | Z9: 8. Medium Truck | AA9: 9. Heavy truck | AB9: 10. Truck Trailer | AC9: 11. Motorcycles | AD9: 12. Tractors, Graders | AE9: Total Excl M/ Cycles | AF9: Total All
B10: 07.00 - 07.15 | C10: 21 | D10: 6 | E10: 4 | F10: 60 | G10: 2 | H10: 1 | I10: 8 | J10: 3 | K10: 0 | L10: 0 | M10: 385 | N10: 0 | O10: =SUM(C10:L10,N10) -> 105 | P10: =SUM(C10:N10) -> 490 | R10: 0700-0800 | S10: =SUM(C10:C13) -> 76 | T10: =SUM(D10:D13) -> 17 | U10: =SUM(E10:E13) -> 18 | V10: =SUM(F10:F13) -> 196 | W10: =SUM(G10:G13) -> 8 | X10: =SUM(H10:H13) -> 3 | Y10: =SUM(I10:I13) -> 34 | Z10: =SUM(J10:J13) -> 10 | ... AF10: =SUM(P10:P13) -> 1882
B11: 07.15 - 07.30 | C11: 16 | D11: 8 | E11: 1 | F11: 47 | G11: 2 | H11: 0 | I11: 8 | J11: 1 | K11: 0 | L11: 1 | M11: 400 | N11: 0 | O11: =SUM(C11:L11,N11) -> 84 | P11: =SUM(C11:N11) -> 484 | R11: 0800-0900 | S11: =SUM(C14:C17) -> 89 | T11: =SUM(D14:D17) -> 25 | U11: =SUM(E14:E17) -> 25 | V11: =SUM(F14:F17) -> 234 | W11: =SUM(G14:G17) -> 2 | X11: =SUM(H14:H17) -> 1 | Y11: =SUM(I14:I17) -> 21 | Z11: =SUM(J14:J17) -> 7 | ... AF11: =SUM(P14:P17) -> 1851
B12: 07.30 - 07.45 | C12: 18 | D12: 1 | E12: 9 | F12: 49 | G12: 1 | H12: 2 | I12: 10 | J12: 6 | K12: 0 | L12: 1 | M12: 325 | N12: 0 | O12: =SUM(C12:L12,N12) -> 97 | P12: =SUM(C12:N12) -> 422 | R12: 0900-1000 | S12: =SUM(C18:C21) -> 149 | T12: =SUM(D18:D21) -> 32 | U12: =SUM(E18:E21) -> 34 | V12: =SUM(F18:F21) -> 216 | W12: =SUM(G18:G21) -> 1 | X12: =SUM(H18:H21) -> 1 | Y12: =SUM(I18:I21) -> 31 | Z12: =SUM(J18:J21) -> 8 | ... AF12: =SUM(P18:P21) -> 1780
B13: 07.45 - 08.00 | C13: 21 | D13: 2 | E13: 4 | F13: 40 | G13: 3 | H13: 0 | I13: 8 | J13: 0 | K13: 0 | L13: 3 | M13: 405 | N13: 0 | O13: =SUM(C13:L13,N13) -> 81 | P13: =SUM(C13:N13) -> 486 | R13: 1000-1100 | S13: =SUM(C22:C25) -> 169 | T13: =SUM(D22:D25) -> 40 | U13: =SUM(E22:E25) -> 29 | V13: =SUM(F22:F25) -> 175 | W13: =SUM(G22:G25) -> 1 | X13: =SUM(H22:H25) -> 2 | Y13: =SUM(I22:I25) -> 49 | Z13: =SUM(J22:J25) -> 15 | ... AF13: =SUM(P22:P25) -> 1514
B14: 08.00 - 08.15 | C14: 19 | D14: 7 | E14: 6 | F14: 60 | G14: 1 | H14: 0 | I14: 8 | J14: 3 | K14: 0 | L14: 0 | M14: 394 | N14: 0 | O14: =SUM(C14:L14,N14) -> 104 | P14: =SUM(C14:N14) -> 498 | R14: 1100-1200 | S14: =SUM(C26:C29) -> 146 | T14: =SUM(D26:D29) -> 42 | U14: =SUM(E26:E29) -> 32 | V14: =SUM(F26:F29) -> 186 | W14: =SUM(G26:G29) -> 0 | X14: =SUM(H26:H29) -> 1 | Y14: =SUM(I26:I29) -> 63 | Z14: =SUM(J26:J29) -> 7 | ... AF14: =SUM(P26:P29) -> 1437
B15: 08.15 - 08.30 | C15: 19 | D15: 4 | E15: 6 | F15: 45 | G15: 0 | H15: 1 | I15: 5 | J15: 1 | K15: 0 | L15: 0 | M15: 280 | N15: 0 | O15: =SUM(C15:L15,N15) -> 81 | P15: =SUM(C15:N15) -> 361 | R15: 1200-1300 | S15: =SUM(C30:C33) -> 164 | T15: =SUM(D30:D33) -> 23 | U15: =SUM(E30:E33) -> 45 | V15: =SUM(F30:F33) -> 171 | W15: =SUM(G30:G33) -> 8 | X15: =SUM(H30:H33) -> 1 | Y15: =SUM(I30:I33) -> 48 | Z15: =SUM(J30:J33) -> 14 | ... AF15: =SUM(P30:P33) -> 1208
B16: 08.30 - 08.45 | C16: 24 | D16: 7 | E16: 5 | F16: 76 | G16: 1 | H16: 0 | I16: 1 | J16: 1 | K16: 0 | L16: 2 | M16: 335 | N16: 0 | O16: =SUM(C16:L16,N16) -> 117 | P16: =SUM(C16:N16) -> 452 | R16: 1300-1400 | S16: =SUM(C34:C37) -> 160 | T16: =SUM(D34:D37) -> 33 | U16: =SUM(E34:E37) -> 39 | V16: =SUM(F34:F37) -> 156 | W16: =SUM(G34:G37) -> 0 | X16: =SUM(H34:H37) -> 4 | Y16: =SUM(I34:I37) -> 44 | Z16: =SUM(J34:J37) -> 16 | ... AF16: =SUM(P34:P37) -> 1245
B17: 08.45 - 9.00 | C17: 27 | D17: 7 | E17: 8 | F17: 53 | G17: 0 | H17: 0 | I17: 7 | J17: 2 | K17: 0 | L17: 1 | M17: 435 | N17: 0 | O17: =SUM(C17:L17,N17) -> 105 | P17: =SUM(C17:N17) -> 540 | R17: 1400-1500 | S17: =SUM(C38:C41) -> 187 | T17: =SUM(D38:D41) -> 36 | U17: =SUM(E38:E41) -> 34 | V17: =SUM(F38:F41) -> 179 | W17: =SUM(G38:G41) -> 1 | X17: =SUM(H38:H41) -> 3 | Y17: =SUM(I38:I41) -> 48 | Z17: =SUM(J38:J41) -> 18 | ... AF17: =SUM(P38:P41) -> 1696
B18: 09.00 - 09.15 | C18: 21 | D18: 7 | E18: 8 | F18: 58 | G18: 0 | H18: 0 | I18: 5 | J18: 1 | K18: 0 | L18: 0 | M18: 331 | N18: 0 | O18: =SUM(C18:L18,N18) -> 100 | P18: =SUM(C18:N18) -> 431 | R18: 1500-1600 | S18: =SUM(C42:C45) -> 242 | T18: =SUM(D42:D45) -> 54 | U18: =SUM(E42:E45) -> 52 | V18: =SUM(F42:F45) -> 215 | W18: =SUM(G42:G45) -> 0 | X18: =SUM(H42:H45) -> 3 | Y18: =SUM(I42:I45) -> 45 | Z18: =SUM(J42:J45) -> 13 | ... AF18: =SUM(P42:P45) -> 1750
B19: 09.15 - 09.30 | C19: 32 | D19: 9 | E19: 7 | F19: 53 | G19: 1 | H19: 0 | I19: 8 | J19: 1 | K19: 0 | L19: 1 | M19: 336 | N19: 0 | O19: =SUM(C19:L19,N19) -> 112 | P19: =SUM(C19:N19) -> 448 | R19: 1600-1700 | S19: =SUM(C46:C49) -> 230 | T19: =SUM(D46:D49) -> 78 | U19: =SUM(E46:E49) -> 37 | V19: =SUM(F46:F49) -> 185 | W19: =SUM(G46:G49) -> 3 | X19: =SUM(H46:H49) -> 8 | Y19: =SUM(I46:I49) -> 44 | Z19: =SUM(J46:J49) -> 13 | ... AF19: =SUM(P46:P49) -> 1747
B20: 09.30 - 09.45 | C20: 39 | D20: 7 | E20: 8 | F20: 58 | G20: 0 | H20: 1 | I20: 10 | J20: 6 | K20: 0 | L20: 1 | M20: 327 | N20: 0 | O20: =SUM(C20:L20,N20) -> 130 | P20: =SUM(C20:N20) -> 457 | R20: 1700-1800 | S20: =SUM(C50:C53) -> 285 | T20: =SUM(D50:D53) -> 79 | U20: =SUM(E50:E53) -> 50 | V20: =SUM(F50:F53) -> 171 | W20: =SUM(G50:G53) -> 8 | X20: =SUM(H50:H53) -> 2 | Y20: =SUM(I50:I53) -> 37 | Z20: =SUM(J50:J53) -> 10 | ... AF20: =SUM(P50:P53) -> 1794
B21: 09.45 - 10.00 | C21: 57 | D21: 9 | E21: 11 | F21: 47 | G21: 0 | H21: 0 | I21: 8 | J21: 0 | K21: 0 | L21: 3 | M21: 309 | N21: 0 | O21: =SUM(C21:L21,N21) -> 135 | P21: =SUM(C21:N21) -> 444 | R21: 1800-1900 | S21: =SUM(C54:C57) -> 264 | T21: =SUM(D54:D57) -> 78 | U21: =SUM(E54:E57) -> 51 | V21: =SUM(F54:F57) -> 177 | W21: =SUM(G54:G57) -> 4 | X21: =SUM(H54:H57) -> 7 | Y21: =SUM(I54:I57) -> 17 | Z21: =SUM(J54:J57) -> 9 | ... AF21: =SUM(P54:P57) -> 1892
B22: 10.00 - 10.15 | C22: 41 | D22: 19 | E22: 5 | F22: 42 | G22: 0 | H22: 0 | I22: 5 | J22: 1 | K22: 0 | L22: 4 | M22: 250 | N22: 0 | O22: =SUM(C22:L22,N22) -> 117 | P22: =SUM(C22:N22) -> 367 | R22: AM Peak Hr | S22: =MAX(S10:S12) -> 149 | T22: =MAX(T10:T12) -> 32 | U22: =MAX(U10:U12) -> 34 | V22: =MAX(V10:V12) -> 234 | W22: =MAX(W10:W12) -> 8 | X22: =MAX(X10:X12) -> 3 | Y22: =MAX(Y10:Y12) -> 34 | Z22: =MAX(Z10:Z12) -> 10 | ... AF22: =MAX(AF10:AF12) -> 1882
B23: 10.15 - 10.30 | C23: 32 | D23: 4 | E23: 4 | F23: 36 | G23: 0 | H23: 1 | I23: 9 | J23: 9 | K23: 0 | L23: 2 | M23: 265 | N23: 0 | O23: =SUM(C23:L23,N23) -> 97 | P23: =SUM(C23:N23) -> 362 | R23: IP Peak Hr | S23: =MAX(S13:S18) -> 242 | T23: =MAX(T13:T18) -> 54 | U23: =MAX(U13:U18) -> 52 | V23: =MAX(V13:V18) -> 215 | W23: =MAX(W13:W18) -> 8 | X23: =MAX(X13:X18) -> 4 | Y23: =MAX(Y13:Y18) -> 63 | Z23: =MAX(Z13:Z18) -> 18 | ... AF23: =MAX(AF13:AF18) -> 1750
B24: 10.30 - 10.45 | C24: 50 | D24: 8 | E24: 15 | F24: 47 | G24: 1 | H24: 0 | I24: 18 | J24: 2 | K24: 0 | L24: 1 | M24: 260 | N24: 0 | O24: =SUM(C24:L24,N24) -> 142 | P24: =SUM(C24:N24) -> 402 | R24: PM Peak Hr | S24: =MAX(S19:S21) -> 285 | T24: =MAX(T19:T21) -> 79 | U24: =MAX(U19:U21) -> 51 | V24: =MAX(V19:V21) -> 185 | W24: =MAX(W19:W21) -> 8 | X24: =MAX(X19:X21) -> 8 | Y24: =MAX(Y19:Y21) -> 44 | Z24: =MAX(Z19:Z21) -> 13 | ... AF24: =MAX(AF19:AF21) -> 1892
B25: 10.45 - 11.00 | C25: 46 | D25: 9 | E25: 5 | F25: 50 | G25: 0 | H25: 1 | I25: 17 | J25: 3 | K25: 0 | L25: 1 | M25: 251 | N25: 0 | O25: =SUM(C25:L25,N25) -> 132 | P25: =SUM(C25:N25) -> 383 | R25: AM Period | S25: =SUM(S10:S12) -> 314 | T25: =SUM(T10:T12) -> 74 | U25: =SUM(U10:U12) -> 77 | V25: =SUM(V10:V12) -> 646 | W25: =SUM(W10:W12) -> 11 | X25: =SUM(X10:X12) -> 5 | Y25: =SUM(Y10:Y12) -> 86 | Z25: =SUM(Z10:Z12) -> 25 | ... AF25: =SUM(AF10:AF12) -> 5513
B26: 11.00 - 11.15 | C26: 42 | D26: 6 | E26: 9 | F26: 49 | G26: 0 | H26: 1 | I26: 17 | J26: 4 | K26: 0 | L26: 4 | M26: 230 | N26: 0 | O26: =SUM(C26:L26,N26) -> 132 | P26: =SUM(C26:N26) -> 362 | R26: IP Period | S26: =SUM(S13:S18) -> 1068 | T26: =SUM(T13:T18) -> 228 | U26: =SUM(U13:U18) -> 231 | V26: =SUM(V13:V18) -> 1082 | W26: =SUM(W13:W18) -> 10 | X26: =SUM(X13:X18) -> 14 | Y26: =SUM(Y13:Y18) -> 297 | Z26: =SUM(Z13:Z18) -> 83 | ... AF26: =SUM(AF13:AF18) -> 8850
