Workbook

Sheet 29.07 Kyebando-Mulago
B1: Consultancy services for Preparation of Expressway Development Master Plan (EDMP) for Uganda
B2: MANUAL CLASSIFIED COUNT (MCC)
B3: ROAD NAME: | C3: ='02.08 Kyebando-Mulago'!C3:G3 -> MCC - C1 - STN28 - KISINGIRI ROAD
C5: Date | D5: 29.07.19 | F5: Location | G5: ='02.08 Kyebando-Mulago'!G5:H5 -> Kisingiri Street | J5: Surveyor | K5: Rashida
C6: Dir. From | D6: ='02.08 Kyebando-Mulago'!D6:E6 -> Kyebando | F6: Dir. To | G6: ='02.08 Kyebando-Mulago'!G6:H6 -> Mulago | J6: Supervisor | K6: Steven
B8: Time / Veh Type | R8: SUMMARY TRAFFIC VOLUMES
C9: 1. Car | D9: 2. Station Wagon | E9: 3. Pickups | F9: 4. Minibus, matatu | G9: 5. Medium bus | H9: 6. Large Bus | I9: 7. Light Truck | J9: 8. Medium Truck | K9: 9. Heavy truck | L9: 10. Truck Trailer | M9: 11. Motor cycles | N9: 12. Tractors | O9: Total Excl M/Cycles | P9: Total All | R9: Time | S9: 1. Car | T9: 2. Station Wagon | U9: 3. Pickups | V9: 4. Minibus, matatu | W9: 5. Medium bus | X9: 6. Large Bus | Y9: 7. Light Truck | Z9: 8. Medium Truck | AA9: 9. Heavy truck | AB9: 10. Truck Trailer | AC9: 11. Motorcycles | AD9: 12. Tractors, Graders | AE9: Total Excl M/ Cycles | AF9: Total All
B10: 07.00 - 07.15 | C10: 0 | D10: 0 | E10: 0 | F10: 0 | G10: 0 | H10: 0 | I10: 0 | J10: 0 | K10: 0 | L10: 0 | M10: 0 | N10: 0 | O10: =SUM(C10:L10,N10) -> 0 | P10: =SUM(C10:N10) -> 0 | R10: 0700-0800 | S10: =SUM(C10:C13) -> 0 | T10: =SUM(D10:D13) -> 0 | U10: =SUM(E10:E13) -> 0 | V10: =SUM(F10:F13) -> 0 | W10: =SUM(G10:G13) -> 0 | X10: =SUM(H10:H13) -> 0 | Y10: =SUM(I10:I13) -> 0 | Z10: =SUM(J10:J13) -> 0 | ... AF10: =SUM(P10:P13) -> 0
B11: 07.15 - 07.30 | C11: 0 | D11: 0 | E11: 0 | F11: 0 | G11: 0 | H11: 0 | I11: 0 | J11: 0 | K11: 0 | L11: 0 | M11: 0 | N11: 0 | O11: =SUM(C11:L11,N11) -> 0 | P11: =SUM(C11:N11) -> 0 | R11: 0800-0900 | S11: =SUM(C14:C17) -> 292 | T11: =SUM(D14:D17) -> 45 | U11: =SUM(E14:E17) -> 32 | V11: =SUM(F14:F17) -> 108 | W11: =SUM(G14:G17) -> 2 | X11: =SUM(H14:H17) -> 1 | Y11: =SUM(I14:I17) -> 11 | Z11: =SUM(J14:J17) -> 3 | ... AF11: =SUM(P14:P17) -> 970
B12: 07.30 - 07.45 | C12: 0 | D12: 0 | E12: 0 | F12: 0 | G12: 0 | H12: 0 | I12: 0 | J12: 0 | K12: 0 | L12: 0 | M12: 0 | N12: 0 | O12: =SUM(C12:L12,N12) -> 0 | P12: =SUM(C12:N12) -> 0 | R12: 0900-1000 | S12: =SUM(C18:C21) -> 376 | T12: =SUM(D18:D21) -> 56 | U12: =SUM(E18:E21) -> 40 | V12: =SUM(F18:F21) -> 100 | W12: =SUM(G18:G21) -> 2 | X12: =SUM(H18:H21) -> 0 | Y12: =SUM(I18:I21) -> 8 | Z12: =SUM(J18:J21) -> 3 | ... AF12: =SUM(P18:P21) -> 1113
B13: 07.45 - 08.00 | C13: 0 | D13: 0 | E13: 0 | F13: 0 | G13: 0 | H13: 0 | I13: 0 | J13: 0 | K13: 0 | L13: 0 | M13: 0 | N13: 0 | O13: =SUM(C13:L13,N13) -> 0 | P13: =SUM(C13:N13) -> 0 | R13: 1000-1100 | S13: =SUM(C22:C25) -> 288 | T13: =SUM(D22:D25) -> 48 | U13: =SUM(E22:E25) -> 28 | V13: =SUM(F22:F25) -> 62 | W13: =SUM(G22:G25) -> 0 | X13: =SUM(H22:H25) -> 0 | Y13: =SUM(I22:I25) -> 19 | Z13: =SUM(J22:J25) -> 1 | ... AF13: =SUM(P22:P25) -> 765
B14: 08.00 - 08.15 | C14: 25 | D14: 8 | E14: 0 | F14: 7 | G14: 0 | H14: 0 | I14: 0 | J14: 0 | K14: 0 | L14: 0 | M14: 25 | N14: 0 | O14: =SUM(C14:L14,N14) -> 40 | P14: =SUM(C14:N14) -> 65 | R14: 1100-1200 | S14: =SUM(C26:C29) -> 256 | T14: =SUM(D26:D29) -> 59 | U14: =SUM(E26:E29) -> 28 | V14: =SUM(F26:F29) -> 41 | W14: =SUM(G26:G29) -> 0 | X14: =SUM(H26:H29) -> 2 | Y14: =SUM(I26:I29) -> 23 | Z14: =SUM(J26:J29) -> 1 | ... AF14: =SUM(P26:P29) -> 737
B15: 08.15 - 08.30 | C15: 95 | D15: 19 | E15: 17 | F15: 40 | G15: 0 | H15: 0 | I15: 1 | J15: 1 | K15: 0 | L15: 0 | M15: 105 | N15: 0 | O15: =SUM(C15:L15,N15) -> 173 | P15: =SUM(C15:N15) -> 278 | R15: 1200-1300 | S15: =SUM(C30:C33) -> 195 | T15: =SUM(D30:D33) -> 36 | U15: =SUM(E30:E33) -> 24 | V15: =SUM(F30:F33) -> 44 | W15: =SUM(G30:G33) -> 0 | X15: =SUM(H30:H33) -> 0 | Y15: =SUM(I30:I33) -> 20 | Z15: =SUM(J30:J33) -> 6 | ... AF15: =SUM(P30:P33) -> 652
B16: 08.30 - 08.45 | C16: 92 | D16: 6 | E16: 5 | F16: 36 | G16: 0 | H16: 1 | I16: 5 | J16: 2 | K16: 0 | L16: 0 | M16: 166 | N16: 0 | O16: =SUM(C16:L16,N16) -> 147 | P16: =SUM(C16:N16) -> 313 | R16: 1300-1400 | S16: =SUM(C34:C37) -> 171 | T16: =SUM(D34:D37) -> 32 | U16: =SUM(E34:E37) -> 16 | V16: =SUM(F34:F37) -> 43 | W16: =SUM(G34:G37) -> 0 | X16: =SUM(H34:H37) -> 0 | Y16: =SUM(I34:I37) -> 17 | Z16: =SUM(J34:J37) -> 5 | ... AF16: =SUM(P34:P37) -> 554
B17: 08.45 - 9.00 | C17: 80 | D17: 12 | E17: 10 | F17: 25 | G17: 2 | H17: 0 | I17: 5 | J17: 0 | K17: 0 | L17: 0 | M17: 180 | N17: 0 | O17: =SUM(C17:L17,N17) -> 134 | P17: =SUM(C17:N17) -> 314 | R17: 1400-1500 | S17: =SUM(C38:C41) -> 151 | T17: =SUM(D38:D41) -> 30 | U17: =SUM(E38:E41) -> 20 | V17: =SUM(F38:F41) -> 28 | W17: =SUM(G38:G41) -> 0 | X17: =SUM(H38:H41) -> 0 | Y17: =SUM(I38:I41) -> 10 | Z17: =SUM(J38:J41) -> 7 | ... AF17: =SUM(P38:P41) -> 566
B18: 09.00 - 09.15 | C18: 78 | D18: 15 | E18: 9 | F18: 23 | G18: 1 | H18: 0 | I18: 0 | J18: 2 | K18: 0 | L18: 0 | M18: 117 | N18: 0 | O18: =SUM(C18:L18,N18) -> 128 | P18: =SUM(C18:N18) -> 245 | R18: 1500-1600 | S18: =SUM(C42:C45) -> 177 | T18: =SUM(D42:D45) -> 25 | U18: =SUM(E42:E45) -> 18 | V18: =SUM(F42:F45) -> 44 | W18: =SUM(G42:G45) -> 2 | X18: =SUM(H42:H45) -> 1 | Y18: =SUM(I42:I45) -> 22 | Z18: =SUM(J42:J45) -> 0 | ... AF18: =SUM(P42:P45) -> 605
B19: 09.15 - 09.30 | C19: 105 | D19: 17 | E19: 7 | F19: 25 | G19: 0 | H19: 0 | I19: 1 | J19: 1 | K19: 0 | L19: 0 | M19: 146 | N19: 0 | O19: =SUM(C19:L19,N19) -> 156 | P19: =SUM(C19:N19) -> 302 | R19: 1600-1700 | S19: =SUM(C46:C49) -> 163 | T19: =SUM(D46:D49) -> 38 | U19: =SUM(E46:E49) -> 25 | V19: =SUM(F46:F49) -> 47 | W19: =SUM(G46:G49) -> 0 | X19: =SUM(H46:H49) -> 1 | Y19: =SUM(I46:I49) -> 8 | Z19: =SUM(J46:J49) -> 5 | ... AF19: =SUM(P46:P49) -> 685
B20: 09.30 - 09.45 | C20: 111 | D20: 11 | E20: 8 | F20: 30 | G20: 1 | H20: 0 | I20: 5 | J20: 0 | K20: 0 | L20: 0 | M20: 145 | N20: 0 | O20: =SUM(C20:L20,N20) -> 166 | P20: =SUM(C20:N20) -> 311 | R20: 1700-1800 | S20: =SUM(C50:C53) -> 174 | T20: =SUM(D50:D53) -> 38 | U20: =SUM(E50:E53) -> 32 | V20: =SUM(F50:F53) -> 45 | W20: =SUM(G50:G53) -> 2 | X20: =SUM(H50:H53) -> 0 | Y20: =SUM(I50:I53) -> 12 | Z20: =SUM(J50:J53) -> 4 | ... AF20: =SUM(P50:P53) -> 912
B21: 09.45 - 10.00 | C21: 82 | D21: 13 | E21: 16 | F21: 22 | G21: 0 | H21: 0 | I21: 2 | J21: 0 | K21: 0 | L21: 0 | M21: 120 | N21: 0 | O21: =SUM(C21:L21,N21) -> 135 | P21: =SUM(C21:N21) -> 255 | R21: 1800-1900 | S21: =SUM(C54:C57) -> 120 | T21: =SUM(D54:D57) -> 29 | U21: =SUM(E54:E57) -> 16 | V21: =SUM(F54:F57) -> 27 | W21: =SUM(G54:G57) -> 0 | X21: =SUM(H54:H57) -> 1 | Y21: =SUM(I54:I57) -> 8 | Z21: =SUM(J54:J57) -> 1 | ... AF21: =SUM(P54:P57) -> 662
B22: 10.00 - 10.15 | C22: 77 | D22: 21 | E22: 5 | F22: 24 | G22: 0 | H22: 0 | I22: 2 | J22: 0 | K22: 0 | L22: 0 | M22: 103 | N22: 0 | O22: =SUM(C22:L22,N22) -> 129 | P22: =SUM(C22:N22) -> 232 | R22: AM Peak Hr | S22: =MAX(S10:S12) -> 376 | T22: =MAX(T10:T12) -> 56 | U22: =MAX(U10:U12) -> 40 | V22: =MAX(V10:V12) -> 108 | W22: =MAX(W10:W12) -> 2 | X22: =MAX(X10:X12) -> 1 | Y22: =MAX(Y10:Y12) -> 11 | Z22: =MAX(Z10:Z12) -> 3 | ... AF22: =MAX(AF10:AF12) -> 1113
B23: 10.15 - 10.30 | C23: 59 | D23: 9 | E23: 8 | F23: 9 | G23: 0 | H23: 0 | I23: 8 | J23: 0 | K23: 0 | L23: 0 | M23: 72 | N23: 0 | O23: =SUM(C23:L23,N23) -> 93 | P23: =SUM(C23:N23) -> 165 | R23: IP Peak Hr | S23: =MAX(S13:S18) -> 288 | T23: =MAX(T13:T18) -> 59 | U23: =MAX(U13:U18) -> 28 | V23: =MAX(V13:V18) -> 62 | W23: =MAX(W13:W18) -> 2 | X23: =MAX(X13:X18) -> 2 | Y23: =MAX(Y13:Y18) -> 23 | Z23: =MAX(Z13:Z18) -> 7 | ... AF23: =MAX(AF13:AF18) -> 765
B24: 10.30 - 10.45 | C24: 72 | D24: 13 | E24: 11 | F24: 17 | G24: 0 | H24: 0 | I24: 3 | J24: 1 | K24: 0 | L24: 0 | M24: 55 | N24: 0 | O24: =SUM(C24:L24,N24) -> 117 | P24: =SUM(C24:N24) -> 172 | R24: PM Peak Hr | S24: =MAX(S19:S21) -> 174 | T24: =MAX(T19:T21) -> 38 | U24: =MAX(U19:U21) -> 32 | V24: =MAX(V19:V21) -> 47 | W24: =MAX(W19:W21) -> 2 | X24: =MAX(X19:X21) -> 1 | Y24: =MAX(Y19:Y21) -> 12 | Z24: =MAX(Z19:Z21) -> 5 | ... AF24: =MAX(AF19:AF21) -> 912
B25: 10.45 - 11.00 | C25: 80 | D25: 5 | E25: 4 | F25: 12 | G25: 0 | H25: 0 | I25: 6 | J25: 0 | K25: 0 | L25: 0 | M25: 89 | N25: 0 | O25: =SUM(C25:L25,N25) -> 107 | P25: =SUM(C25:N25) -> 196 | R25: AM Period | S25: =SUM(S10:S12) -> 668 | T25: =SUM(T10:T12) -> 101 | U25: =SUM(U10:U12) -> 72 | V25: =SUM(V10:V12) -> 208 | W25: =SUM(W10:W12) -> 4 | X25: =SUM(X10:X12) -> 1 | Y25: =SUM(Y10:Y12) -> 19 | Z25: =SUM(Z10:Z12) -> 6 | ... AF25: =SUM(AF10:AF12) -> 2083
B26: 11.00 - 11.15 | C26: 75 | D26: 20 | E26: 9 | F26: 13 | G26: 0 | H26: 1 | I26: 7 | J26: 0 | K26: 0 | L26: 0 | M26: 97 | N26: 0 | O26: =SUM(C26:L26,N26) -> 125 | P26: =SUM(C26:N26) -> 222 | R26: IP Period | S26: =SUM(S13:S18) -> 1238 | T26: =SUM(T13:T18) -> 230 | U26: =SUM(U13:U18) -> 134 | V26: =SUM(V13:V18) -> 262 | W26: =SUM(W13:W18) -> 2 | X26: =SUM(X13:X18) -> 3 | Y26: =SUM(Y13:Y18) -> 111 | Z26: =SUM(Z13:Z18) -> 20 | ... AF26: =SUM(AF13:AF18) -> 3879
B27: 11.15 - 11.30 | C27: 77 | D27: 14 | E27: 9 | F27: 7 | G27: 0 | H27: 1 | I27: 5 | J27: 1 | K27: 0 | L27: 0 | M27: 95 | N27: 0 | O27: =SUM(C27:L27,N27) -> 114 | P27: =SUM(C27:N27) -> 209 | R27: PM Period | S27: =SUM(S19:S21) -> 457 | T27: =SUM(T19:T21) -> 105 | U27: =SUM(U19:U21) -> 73 | V27: =SUM(V19:V21) -> 119 | W27: =SUM(W19:W21) -> 2 | X27: =SUM(X19:X21) -> 2 | Y27: =SUM(Y19:Y21) -> 28 | Z27: =SUM(Z19:Z21) -> 10 | ... AF27: =SUM(AF19:AF21) -> 2259
B28: 11.30 - 11.45 | C28: 63 | D28: 13 | E28: 7 | F28: 12 | G28: 0 | H28: 0 | I28: 5 | J28: 0 | K28: 0 | L28: 0 | M28: 81 | N28: 0 | O28: =SUM(C28:L28,N28) -> 100 | P28: =SUM(C28:N28) -> 181 | R28: 12 Hours | S28: =SUM(S10:S21) -> 2363 | T28: =SUM(T10:T21) -> 436 | U28: =SUM(U10:U21) -> 279 | V28: =SUM(V10:V21) -> 589 | W28: =SUM(W10:W21) -> 8 | X28: =SUM(X10:X21) -> 6 | Y28: =SUM(Y10:Y21) -> 158 | Z28: =SUM(Z10:Z21) -> 36 | ... AF28: =SUM(AF10:AF21) -> 8221
B29: 11.45 - 12.00 | C29: 41 | D29: 12 | E29: 3 | F29: 9 | G29: 0 | H29: 0 | I29: 6 | J29: 0 | K29: 0 | L29: 0 | M29: 54 | N29: 0 | O29: =SUM(C29:L29,N29) -> 71 | P29: =SUM(C29:N29) -> 125
B30: 12.00 - 12.15 | C30: 66 | D30: 11 | E30: 5 | F30: 12 | G30: 0 | H30: 0 | I30: 8 | J30: 3 | K30: 0 | L30: 0 | M30: 87 | N30: 0 | O30: =SUM(C30:L30,N30) -> 105 | P30: =SUM(C30:N30) -> 192
B31: 12.15 - 12.30 | C31: 49 | D31: 9 | E31: 4 | F31: 10 | G31: 0 | H31: 0 | I31: 5 | J31: 0 | K31: 0 | L31: 0 | M31: 74 | N31: 0 | O31: =SUM(C31:L31,N31) -> 77 | P31: =SUM(C31:N31) -> 151
B32: 12.30 - 12.45 | C32: 37 | D32: 6 | E32: 10 | F32: 15 | G32: 0 | H32: 0 | I32: 5 | J32: 2 | K32: 0 | L32: 0 | M32: 100 | N32: 0 | O32: =SUM(C32:L32,N32) -> 75 | P32: =SUM(C32:N32) -> 175
B33: 12.45 - 13.00 | C33: 43 | D33: 10 | E33: 5 | F33: 7 | G33: 0 | H33: 0 | I33: 2 | J33: 1 | K33: 0 | L33: 0 | M33: 66 | N33: 0 | O33: =SUM(C33:L33,N33) -> 68 | P33: =SUM(C33:N33) -> 134
B34: 13.00 - 13.15 | C34: 48 | D34: 8 | E34: 6 | F34: 7 | G34: 0 | H34: 0 | I34: 5 | J34: 2 | K34: 0 | L34: 0 | M34: 72 | N34: 0 | O34: =SUM(C34:L34,N34) -> 76 | P34: =SUM(C34:N34) -> 148
B35: 13.15 - 13.30 | C35: 41 | D35: 11 | E35: 5 | F35: 7 | G35: 0 | H35: 0 | I35: 3 | J35: 0 | K35: 0 | L35: 0 | M35: 65 | N35: 0 | O35: =SUM(C35:L35,N35) -> 67 | P35: =SUM(C35:N35) -> 132
B36: 13.30 - 13.45 | C36: 42 | D36: 8 | E36: 3 | F36: 14 | G36: 0 | H36: 0 | I36: 5 | J36: 2 | K36: 0 | L36: 0 | M36: 63 | N36: 0 | O36: =SUM(C36:L36,N36) -> 74 | P36: =SUM(C36:N36) -> 137
B37: 13.45 - 14.00 | C37: 40 | D37: 5 | E37: 2 | F37: 15 | G37: 0 | H37: 0 | I37: 4 | J37: 1 | K37: 0 | L37: 0 | M37: 70 | N37: 0 | O37: =SUM(C37:L37,N37) -> 67 | P37: =SUM(C37:N37) -> 137
B38: 14.00 - 14.15 | C38: 32 | D38: 6 | E38: 3 | F38: 6 | G38: 0 | H38: 0 | I38: 1 | J38: 1 | K38: 0 | L38: 0 | M38: 75 | N38: 0 | O38: =SUM(C38:L38,N38) -> 49 | P38: =SUM(C38:N38) -> 124
B39: 14.15 - 14.30 | C39: 41 | D39: 6 | E39: 3 | F39: 8 | G39: 0 | H39: 0 | I39: 3 | J39: 3 | K39: 0 | L39: 0 | M39: 79 | N39: 0 | O39: =SUM(C39:L39,N39) -> 64 | P39: =SUM(C39:N39) -> 143
B40: 14.30 - 14.45 | C40: 40 | D40: 8 | E40: 4 | F40: 7 | G40: 0 | H40: 0 | I40: 4 | J40: 3 | K40: 0 | L40: 0 | M40: 86 | N40: 0 | O40: =SUM(C40:L40,N40) -> 66 | P40: =SUM(C40:N40) -> 152
... B57: 18.45 - 19.00 | C57: 22 | D57: 5 | E57: 7 | F57: 5 | G57: 0 | H57: 0 | I57: 2 | J57: 0 | K57: 0 | L57: 0 | M57: 175 | N57: 0 | O57: =SUM(C57:L57,N57) -> 41 | P57: =SUM(C57:N57) -> 216
B58: Totals | C58: =SUM(C10:C57) -> 2363 | D58: =SUM(D10:D57) -> 436 | E58: =SUM(E10:E57) -> 279 | F58: =SUM(F10:F57) -> 589 | G58: =SUM(G10:G57) -> 8 | H58: =SUM(H10:H57) -> 6 | I58: =SUM(I10:I57) -> 158 | J58: =SUM(J10:J57) -> 36 | ... P58: =SUM(P10:P57) -> 8221
...

Sheet 29.07 Mulago-Kyebando
B1: Consultancy services for Preparation of Expressway Development Master Plan (EDMP) for Uganda
B2: MANUAL CLASSIFIED COUNT (MCC)
B3: ROAD NAME: | C3: ='02.08 Mulago-Kyebando'!C3:G3 -> MCC - C1 - STN28 - KISINGIRI ROAD
C5: Date | D5: ='29.07 Kyebando-Mulago'!D5 -> 29.07.19 | F5: Location | G5: ='02.08 Kyebando-Mulago'!G5:H5 -> Kisingiri Street | J5: Surveyor | K5: Frank
C6: Dir. From | D6: ='02.08 Mulago-Kyebando'!D6:E6 -> Mulago | F6: Dir. To | G6: ='02.08 Mulago-Kyebando'!G6:H6 -> Kyebando | J6: Supervisor | K6: Steven
B8: Time / Veh Type | R8: SUMMARY TRAFFIC VOLUMES
C9: 1. Car | D9: 2. Station Wagon | E9: 3. Pickups | F9: 4. Minibus, matatu | G9: 5. Medium bus | H9: 6. Large Bus | I9: 7. Light Truck | J9: 8. Medium Truck | K9: 9. Heavy truck | L9: 10. Truck Trailer | M9: 11. Motor cycles | N9: 12. Tractors | O9: Total Excl M/Cycles | P9: Total All | R9: Time | S9: 1. Car | T9: 2. Station Wagon | U9: 3. Pickups | V9: 4. Minibus, matatu | W9: 5. Medium bus | X9: 6. Large Bus | Y9: 7. Light Truck | Z9: 8. Medium Truck | AA9: 9. Heavy truck | AB9: 10. Truck Trailer | AC9: 11. Motorcycles | AD9: 12. Tractors, Graders | AE9: Total Excl M/ Cycles | AF9: Total All
B10: 07.00 - 07.15 | C10: 0 | D10: 0 | E10: 0 | F10: 0 | G10: 0 | H10: 0 | I10: 0 | J10: 0 | K10: 0 | L10: 0 | M10: 0 | N10: 0 | O10: =SUM(C10:L10,N10) -> 0 | P10: =SUM(C10:N10) -> 0 | R10: 0700-0800 | S10: =SUM(C10:C13) -> 0 | T10: =SUM(D10:D13) -> 0 | U10: =SUM(E10:E13) -> 0 | V10: =SUM(F10:F13) -> 0 | W10: =SUM(G10:G13) -> 0 | X10: =SUM(H10:H13) -> 0 | Y10: =SUM(I10:I13) -> 0 | Z10: =SUM(J10:J13) -> 0 | ... AF10: =SUM(P10:P13) -> 0
B11: 07.15 - 07.30 | C11: 0 | D11: 0 | E11: 0 | F11: 0 | G11: 0 | H11: 0 | I11: 0 | J11: 0 | K11: 0 | L11: 0 | M11: 0 | N11: 0 | O11: =SUM(C11:L11,N11) -> 0 | P11: =SUM(C11:N11) -> 0 | R11: 0800-0900 | S11: =SUM(C14:C17) -> 93 | T11: =SUM(D14:D17) -> 16 | U11: =SUM(E14:E17) -> 7 | V11: =SUM(F14:F17) -> 31 | W11: =SUM(G14:G17) -> 0 | X11: =SUM(H14:H17) -> 0 | Y11: =SUM(I14:I17) -> 12 | Z11: =SUM(J14:J17) -> 0 | ... AF11: =SUM(P14:P17) -> 1054
B12: 07.30 - 07.45 | C12: 0 | D12: 0 | E12: 0 | F12: 0 | G12: 0 | H12: 0 | I12: 0 | J12: 0 | K12: 0 | L12: 0 | M12: 0 | N12: 0 | O12: =SUM(C12:L12,N12) -> 0 | P12: =SUM(C12:N12) -> 0 | R12: 0900-1000 | S12: =SUM(C18:C21) -> 116 | T12: =SUM(D18:D21) -> 15 | U12: =SUM(E18:E21) -> 18 | V12: =SUM(F18:F21) -> 64 | W12: =SUM(G18:G21) -> 2 | X12: =SUM(H18:H21) -> 0 | Y12: =SUM(I18:I21) -> 31 | Z12: =SUM(J18:J21) -> 0 | ... AF12: =SUM(P18:P21) -> 1126
B13: 07.45 - 08.00 | C13: 0 | D13: 0 | E13: 0 | F13: 0 | G13: 0 | H13: 0 | I13: 0 | J13: 0 | K13: 0 | L13: 0 | M13: 0 | N13: 0 | O13: =SUM(C13:L13,N13) -> 0 | P13: =SUM(C13:N13) -> 0 | R13: 1000-1100 | S13: =SUM(C22:C25) -> 151 | T13: =SUM(D22:D25) -> 27 | U13: =SUM(E22:E25) -> 30 | V13: =SUM(F22:F25) -> 69 | W13: =SUM(G22:G25) -> 1 | X13: =SUM(H22:H25) -> 0 | Y13: =SUM(I22:I25) -> 19 | Z13: =SUM(J22:J25) -> 3 | ... AF13: =SUM(P22:P25) -> 914
B14: 08.00 - 08.15 | C14: 15 | D14: 2 | E14: 0 | F14: 1 | G14: 0 | H14: 0 | I14: 1 | J14: 0 | K14: 0 | L14: 0 | M14: 30 | N14: 0 | O14: =SUM(C14:L14,N14) -> 19 | P14: =SUM(C14:N14) -> 49 | R14: 1100-1200 | S14: =SUM(C26:C29) -> 178 | T14: =SUM(D26:D29) -> 22 | U14: =SUM(E26:E29) -> 45 | V14: =SUM(F26:F29) -> 50 | W14: =SUM(G26:G29) -> 1 | X14: =SUM(H26:H29) -> 0 | Y14: =SUM(I26:I29) -> 24 | Z14: =SUM(J26:J29) -> 3 | ... AF14: =SUM(P26:P29) -> 815
B15: 08.15 - 08.30 | C15: 18 | D15: 4 | E15: 1 | F15: 8 | G15: 0 | H15: 0 | I15: 1 | J15: 0 | K15: 0 | L15: 0 | M15: 350 | N15: 0 | O15: =SUM(C15:L15,N15) -> 32 | P15: =SUM(C15:N15) -> 382 | R15: 1200-1300 | S15: =SUM(C30:C33) -> 180 | T15: =SUM(D30:D33) -> 35 | U15: =SUM(E30:E33) -> 31 | V15: =SUM(F30:F33) -> 55 | W15: =SUM(G30:G33) -> 1 | X15: =SUM(H30:H33) -> 0 | Y15: =SUM(I30:I33) -> 14 | Z15: =SUM(J30:J33) -> 8 | ... AF15: =SUM(P30:P33) -> 668
B16: 08.30 - 08.45 | C16: 28 | D16: 3 | E16: 4 | F16: 11 | G16: 0 | H16: 0 | I16: 3 | J16: 0 | K16: 0 | L16: 0 | M16: 345 | N16: 0 | O16: =SUM(C16:L16,N16) -> 49 | P16: =SUM(C16:N16) -> 394 | R16: 1300-1400 | S16: =SUM(C34:C37) -> 237 | T16: =SUM(D34:D37) -> 24 | U16: =SUM(E34:E37) -> 33 | V16: =SUM(F34:F37) -> 53 | W16: =SUM(G34:G37) -> 2 | X16: =SUM(H34:H37) -> 0 | Y16: =SUM(I34:I37) -> 26 | Z16: =SUM(J34:J37) -> 1 | ... AF16: =SUM(P34:P37) -> 760
B17: 08.45 - 9.00 | C17: 32 | D17: 7 | E17: 2 | F17: 11 | G17: 0 | H17: 0 | I17: 7 | J17: 0 | K17: 0 | L17: 0 | M17: 170 | N17: 0 | O17: =SUM(C17:L17,N17) -> 59 | P17: =SUM(C17:N17) -> 229 | R17: 1400-1500 | S17: =SUM(C38:C41) -> 230 | T17: =SUM(D38:D41) -> 20 | U17: =SUM(E38:E41) -> 40 | V17: =SUM(F38:F41) -> 37 | W17: =SUM(G38:G41) -> 4 | X17: =SUM(H38:H41) -> 0 | Y17: =SUM(I38:I41) -> 21 | Z17: =SUM(J38:J41) -> 2 | ... AF17: =SUM(P38:P41) -> 771
B18: 09.00 - 09.15 | C18: 16 | D18: 3 | E18: 2 | F18: 12 | G18: 0 | H18: 0 | I18: 5 | J18: 0 | K18: 0 | L18: 0 | M18: 195 | N18: 0 | O18: =SUM(C18:L18,N18) -> 38 | P18: =SUM(C18:N18) -> 233 | R18: 1500-1600 | S18: =SUM(C42:C45) -> 286 | T18: =SUM(D42:D45) -> 45 | U18: =SUM(E42:E45) -> 57 | V18: =SUM(F42:F45) -> 60 | W18: =SUM(G42:G45) -> 1 | X18: =SUM(H42:H45) -> 1 | Y18: =SUM(I42:I45) -> 22 | Z18: =SUM(J42:J45) -> 3 | ... AF18: =SUM(P42:P45) -> 964
B19: 09.15 - 09.30 | C19: 30 | D19: 3 | E19: 2 | F19: 12 | G19: 1 | H19: 0 | I19: 7 | J19: 0 | K19: 0 | L19: 0 | M19: 270 | N19: 0 | O19: =SUM(C19:L19,N19) -> 55 | P19: =SUM(C19:N19) -> 325 | R19: 1600-1700 | S19: =SUM(C46:C49) -> 494 | T19: =SUM(D46:D49) -> 64 | U19: =SUM(E46:E49) -> 62 | V19: =SUM(F46:F49) -> 87 | W19: =SUM(G46:G49) -> 3 | X19: =SUM(H46:H49) -> 0 | Y19: =SUM(I46:I49) -> 17 | Z19: =SUM(J46:J49) -> 8 | ... AF19: =SUM(P46:P49) -> 1275
B20: 09.30 - 09.45 | C20: 34 | D20: 3 | E20: 4 | F20: 18 | G20: 1 | H20: 0 | I20: 8 | J20: 0 | K20: 0 | L20: 0 | M20: 260 | N20: 0 | O20: =SUM(C20:L20,N20) -> 68 | P20: =SUM(C20:N20) -> 328 | R20: 1700-1800 | S20: =SUM(C50:C53) -> 638 | T20: =SUM(D50:D53) -> 67 | U20: =SUM(E50:E53) -> 50 | V20: =SUM(F50:F53) -> 78 | W20: =SUM(G50:G53) -> 1 | X20: =SUM(H50:H53) -> 1 | Y20: =SUM(I50:I53) -> 16 | Z20: =SUM(J50:J53) -> 4 | ... AF20: =SUM(P50:P53) -> 1495
B21: 09.45 - 10.00 | C21: 36 | D21: 6 | E21: 10 | F21: 22 | G21: 0 | H21: 0 | I21: 11 | J21: 0 | K21: 0 | L21: 0 | M21: 155 | N21: 0 | O21: =SUM(C21:L21,N21) -> 85 | P21: =SUM(C21:N21) -> 240 | R21: 1800-1900 | S21: =SUM(C54:C57) -> 314 | T21: =SUM(D54:D57) -> 34 | U21: =SUM(E54:E57) -> 25 | V21: =SUM(F54:F57) -> 55 | W21: =SUM(G54:G57) -> 4 | X21: =SUM(H54:H57) -> 0 | Y21: =SUM(I54:I57) -> 5 | Z21: =SUM(J54:J57) -> 0 | ... AF21: =SUM(P54:P57) -> 1122
B22: 10.00 - 10.15 | C22: 30 | D22: 7 | E22: 2 | F22: 14 | G22: 0 | H22: 0 | I22: 7 | J22: 0 | K22: 0 | L22: 0 | M22: 145 | N22: 0 | O22: =SUM(C22:L22,N22) -> 60 | P22: =SUM(C22:N22) -> 205 | R22: AM Peak Hr | S22: =MAX(S10:S12) -> 116 | T22: =MAX(T10:T12) -> 16 | U22: =MAX(U10:U12) -> 18 | V22: =MAX(V10:V12) -> 64 | W22: =MAX(W10:W12) -> 2 | X22: =MAX(X10:X12) -> 0 | Y22: =MAX(Y10:Y12) -> 31 | Z22: =MAX(Z10:Z12) -> 0 | ... AF22: =MAX(AF10:AF12) -> 1126
B23: 10.15 - 10.30 | C23: 38 | D23: 5 | E23: 8 | F23: 15 | G23: 1 | H23: 0 | I23: 7 | J23: 2 | K23: 0 | L23: 0 | M23: 132 | N23: 0 | O23: =SUM(C23:L23,N23) -> 76 | P23: =SUM(C23:N23) -> 208 | R23: IP Peak Hr | S23: =MAX(S13:S18) -> 286 | T23: =MAX(T13:T18) -> 45 | U23: =MAX(U13:U18) -> 57 | V23: =MAX(V13:V18) -> 69 | W23: =MAX(W13:W18) -> 4 | X23: =MAX(X13:X18) -> 1 | Y23: =MAX(Y13:Y18) -> 26 | Z23: =MAX(Z13:Z18) -> 8 | ... AF23: =MAX(AF13:AF18) -> 964
B24: 10.30 - 10.45 | C24: 41 | D24: 12 | E24: 14 | F24: 26 | G24: 0 | H24: 0 | I24: 4 | J24: 1 | K24: 0 | L24: 0 | M24: 215 | N24: 0 | O24: =SUM(C24:L24,N24) -> 98 | P24: =SUM(C24:N24) -> 313 | R24: PM Peak Hr | S24: =MAX(S19:S21) -> 638 | T24: =MAX(T19:T21) -> 67 | U24: =MAX(U19:U21) -> 62 | V24: =MAX(V19:V21) -> 87 | W24: =MAX(W19:W21) -> 4 | X24: =MAX(X19:X21) -> 1 | Y24: =MAX(Y19:Y21) -> 17 | Z24: =MAX(Z19:Z21) -> 8 | ... AF24: =MAX(AF19:AF21) -> 1495
B25: 10.45 - 11.00 | C25: 42 | D25: 3 | E25: 6 | F25: 14 | G25: 0 | H25: 0 | I25: 1 | J25: 0 | K25: 0 | L25: 0 | M25: 122 | N25: 0 | O25: =SUM(C25:L25,N25) -> 66 | P25: =SUM(C25:N25) -> 188 | R25: AM Period | S25: =SUM(S10:S12) -> 209 | T25: =SUM(T10:T12) -> 31 | U25: =SUM(U10:U12) -> 25 | V25: =SUM(V10:V12) -> 95 | W25: =SUM(W10:W12) -> 2 | X25: =SUM(X10:X12) -> 0 | Y25: =SUM(Y10:Y12) -> 43 | Z25: =SUM(Z10:Z12) -> 0 | ... AF25: =SUM(AF10:AF12) -> 2180
B26: 11.00 - 11.15 | C26: 40 | D26: 4 | E26: 11 | F26: 14 | G26: 0 | H26: 0 | I26: 5 | J26: 1 | K26: 0 | L26: 0 | M26: 141 | N26: 0 | O26: =SUM(C26:L26,N26) -> 75 | P26: =SUM(C26:N26) -> 216 | R26: IP Period | S26: =SUM(S13:S18) -> 1262 | T26: =SUM(T13:T18) -> 173 | U26: =SUM(U13:U18) -> 236 | V26: =SUM(V13:V18) -> 324 | W26: =SUM(W13:W18) -> 10 | X26: =SUM(X13:X18) -> 1 | Y26: =SUM(Y13:Y18) -> 126 | Z26: =SUM(Z13:Z18) -> 20 | ... AF26: =SUM(AF13:AF18) -> 4892
B27: 11.15 - 11.30 | C27: 53 | D27: 9 | E27: 10 | F27: 18 | G27: 0 | H27: 0 | I27: 12 | J27: 1 | K27: 0 | L27: 0 | M27: 120 | N27: 0 | O27: =SUM(C27:L27,N27) -> 103 | P27: =SUM(C27:N27) -> 223 | R27: PM Period | S27: =SUM(S19:S21) -> 1446 | T27: =SUM(T19:T21) -> 165 | U27: =SUM(U19:U21) -> 137 | V27: =SUM(V19:V21) -> 220 | W27: =SUM(W19:W21) -> 8 | X27: =SUM(X19:X21) -> 1 | Y27: =SUM(Y19:Y21) -> 38 | Z27: =SUM(Z19:Z21) -> 12 | ... AF27: =SUM(AF19:AF21) -> 3892
B28: 11.30 - 11.45 | C28: 47 | D28: 2 | E28: 12 | F28: 12 | G28: 1 | H28: 0 | I28: 4 | J28: 0 | K28: 0 | L28: 0 | M28: 100 | N28: 0 | O28: =SUM(C28:L28,N28) -> 78 | P28: =SUM(C28:N28) -> 178 | R28: 12 Hours | S28: =SUM(S10:S21) -> 2917 | T28: =SUM(T10:T21) -> 369 | U28: =SUM(U10:U21) -> 398 | V28: =SUM(V10:V21) -> 639 | W28: =SUM(W10:W21) -> 20 | X28: =SUM(X10:X21) -> 2 | Y28: =SUM(Y10:Y21) -> 207 | Z28: =SUM(Z10:Z21) -> 32 | ... AF28: =SUM(AF10:AF21) -> 10964
B29: 11.45 - 12.00 | C29: 38 | D29: 7 | E29: 12 | F29: 6 | G29: 0 | H29: 0 | I29: 3 | J29: 1 | K29: 0 | L29: 0 | M29: 131 | N29: 0 | O29: =SUM(C29:L29,N29) -> 67 | P29: =SUM(C29:N29) -> 198
B30: 12.00 - 12.15 | C30: 29 | D30: 6 | E30: 3 | F30: 10 | G30: 0 | H30: 0 | I30: 8 | J30: 3 | K30: 0 | L30: 0 | M30: 65 | N30: 0 | O30: =SUM(C30:L30,N30) -> 59 | P30: =SUM(C30:N30) -> 124
B31: 12.15 - 12.30 | C31: 47 | D31: 5 | E31: 12 | F31: 17 | G31: 0 | H31: 0 | I31: 0 | J31: 1 | K31: 0 | L31: 0 | M31: 70 | N31: 0 | O31: =SUM(C31:L31,N31) -> 82 | P31: =SUM(C31:N31) -> 152
B32: 12.30 - 12.45 | C32: 48 | D32: 11 | E32: 9 | F32: 12 | G32: 1 | H32: 0 | I32: 3 | J32: 1 | K32: 0 | L32: 0 | M32: 115 | N32: 0 | O32: =SUM(C32:L32,N32) -> 85 | P32: =SUM(C32:N32) -> 200
B33: 12.45 - 13.00 | C33: 56 | D33: 13 | E33: 7 | F33: 16 | G33: 0 | H33: 0 | I33: 3 | J33: 3 | K33: 0 | L33: 0 | M33: 94 | N33: 0 | O33: =SUM(C33:L33,N33) -> 98 | P33: =SUM(C33:N33) -> 192
B34: 13.00 - 13.15 | C34: 57 | D34: 7 | E34: 3 | F34: 9 | G34: 2 | H34: 0 | I34: 3 | J34: 0 | K34: 0 | L34: 0 | M34: 97 | N34: 0 | O34: =SUM(C34:L34,N34) -> 81 | P34: =SUM(C34:N34) -> 178
B35: 13.15 - 13.30 | C35: 64 | D35: 6 | E35: 11 | F35: 20 | G35: 0 | H35: 0 | I35: 6 | J35: 1 | K35: 0 | L35: 0 | M35: 122 | N35: 0 | O35: =SUM(C35:L35,N35) -> 108 | P35: =SUM(C35:N35) -> 230
B36: 13.30 - 13.45 | C36: 75 | D36: 6 | E36: 13 | F36: 10 | G36: 0 | H36: 0 | I36: 14 | J36: 0 | K36: 0 | L36: 0 | M36: 90 | N36: 0 | O36: =SUM(C36:L36,N36) -> 118 | P36: =SUM(C36:N36) -> 208
B37: 13.45 - 14.00 | C37: 41 | D37: 5 | E37: 6 | F37: 14 | G37: 0 | H37: 0 | I37: 3 | J37: 0 | K37: 0 | L37: 0 | M37: 75 | N37: 0 | O37: =SUM(C37:L37,N37) -> 69 | P37: =SUM(C37:N37) -> 144
B38: 14.00 - 14.15 | C38: 60 | D38: 8 | E38: 13 | F38: 7 | G38: 1 | H38: 0 | I38: 7 | J38: 1 | K38: 1 | L38: 0 | M38: 120 | N38: 0 | O38: =SUM(C38:L38,N38) -> 98 | P38: =SUM(C38:N38) -> 218
B39: 14.15 - 14.30 | C39: 41 | D39: 4 | E39: 6 | F39: 12 | G39: 2 | H39: 0 | I39: 2 | J39: 0 | K39: 0 | L39: 0 | M39: 110 | N39: 0 | O39: =SUM(C39:L39,N39) -> 67 | P39: =SUM(C39:N39) -> 177
B40: 14.30 - 14.45 | C40: 76 | D40: 5 | E40: 14 | F40: 7 | G40: 1 | H40: 0 | I40: 10 | J40: 1 | K40: 1 | L40: 0 | M40: 115 | N40: 0 | O40: =SUM(C40:L40,N40) -> 115 | P40: =SUM(C40:N40) -> 230
... B57: 18.45 - 19.00 | C57: 65 | D57: 4 | E57: 0 | F57: 8 | G57: 1 | H57: 0 | I57: 0 | J57: 0 | K57: 0 | L57: 0 | M57: 125 | N57: 0 | O57: =SUM(C57:L57,N57) -> 78 | P57: =SUM(C57:N57) -> 203
B58: Totals | C58: =SUM(C10:C57) -> 2917 | D58: =SUM(D10:D57) -> 369 | E58: =SUM(E10:E57) -> 398 | F58: =SUM(F10:F57) -> 639 | G58: =SUM(G10:G57) -> 20 | H58: =SUM(H10:H57) -> 2 | I58: =SUM(I10:I57) -> 207 | J58: =SUM(J10:J57) -> 32 | ... P58: =SUM(P10:P57) -> 10964
...

Sheet 30.07 -Kyebando-Mulago
B1: Consultancy services for Preparation of Expressway Development Master Plan (EDMP) for Uganda
B2: MANUAL CLASSIFIED COUNT (MCC)
B3: ROAD NAME: | C3: ='02.08 Kyebando-Mulago'!C3:G3 -> MCC - C1 - STN28 - KISINGIRI ROAD
C5: Date | D5: 30.07.19 | F5: Location | G5: ='02.08 Kyebando-Mulago'!G5:H5 -> Kisingiri Street | J5: Surveyor | K5: ='02.08 Kyebando-Mulago'!K5:L5 -> Nabayunga Rashida
C6: Dir. From | D6: ='02.08 Kyebando-Mulago'!D6:E6 -> Kyebando | F6: Dir. To | G6: ='02.08 Kyebando-Mulago'!G6:H6 -> Mulago | J6: Supervisor | K6: Steven
B8: Time / Veh Type | R8: SUMMARY TRAFFIC VOLUMES
C9: 1. Car | D9: 2. Station Wagon | E9: 3. Pickups | F9: 4. Minibus, matatu | G9: 5. Medium bus | H9: 6. Large Bus | I9: 7. Light Truck | J9: 8. Medium Truck | K9: 9. Heavy truck | L9: 10. Truck Trailer | M9: 11. Motor cycles | N9: 12. Tractors | O9: Total Excl M/Cycles | P9: Total All | R9: Time | S9: 1. Car | T9: 2. Station Wagon | U9: 3. Pickups | V9: 4. Minibus, matatu | W9: 5. Medium bus | X9: 6. Large Bus | Y9: 7. Light Truck | Z9: 8. Medium Truck | AA9: 9. Heavy truck | AB9: 10. Truck Trailer | AC9: 11. Motorcycles | AD9: 12. Tractors, Graders | AE9: Total Excl M/ Cycles | AF9: Total All
B10: 07.00 - 07.15 | C10: 215 | D10: 26 | E10: 21 | F10: 69 | G10: 0 | H10: 0 | I10: 4 | J10: 1 | K10: 0 | L10: 0 | M10: 100 | N10: 0 | O10: =SUM(C10:L10,N10) -> 336 | P10: =SUM(C10:N10) -> 436 | R10: 0700-0800 | S10: =SUM(C10:C13) -> 831 | T10: =SUM(D10:D13) -> 81 | U10: =SUM(E10:E13) -> 59 | V10: =SUM(F10:F13) -> 249 | W10: =SUM(G10:G13) -> 1 | X10: =SUM(H10:H13) -> 0 | Y10: =SUM(I10:I13) -> 7 | Z10: =SUM(J10:J13) -> 1 | ... AF10: =SUM(P10:P13) -> 1868
B11: 07.15 - 07.30 | C11: 235 | D11: 18 | E11: 11 | F11: 66 | G11: 1 | H11: 0 | I11: 1 | J11: 0 | K11: 0 | L11: 0 | M11: 115 | N11: 0 | O11: =SUM(C11:L11,N11) -> 332 | P11: =SUM(C11:N11) -> 447 | R11: 0800-0900 | S11: =SUM(C14:C17) -> 516 | T11: =SUM(D14:D17) -> 74 | U11: =SUM(E14:E17) -> 50 | V11: =SUM(F14:F17) -> 198 | W11: =SUM(G14:G17) -> 0 | X11: =SUM(H14:H17) -> 0 | Y11: =SUM(I14:I17) -> 15 | Z11: =SUM(J14:J17) -> 4 | ... AF11: =SUM(P14:P17) -> 1684
B12: 07.30 - 07.45 | C12: 251 | D12: 22 | E12: 17 | F12: 81 | G12: 0 | H12: 0 | I12: 0 | J12: 0 | K12: 0 | L12: 0 | M12: 285 | N12: 0 | O12: =SUM(C12:L12,N12) -> 371 | P12: =SUM(C12:N12) -> 656 | R12: 0900-1000 | S12: =SUM(C18:C21) -> 378 | T12: =SUM(D18:D21) -> 70 | U12: =SUM(E18:E21) -> 46 | V12: =SUM(F18:F21) -> 92 | W12: =SUM(G18:G21) -> 0 | X12: =SUM(H18:H21) -> 0 | Y12: =SUM(I18:I21) -> 22 | Z12: =SUM(J18:J21) -> 3 | ... AF12: =SUM(P18:P21) -> 1272
B13: 07.45 - 08.00 | C13: 130 | D13: 15 | E13: 10 | F13: 33 | G13: 0 | H13: 0 | I13: 2 | J13: 0 | K13: 0 | L13: 0 | M13: 139 | N13: 0 | O13: =SUM(C13:L13,N13) -> 190 | P13: =SUM(C13:N13) -> 329 | R13: 1000-1100 | S13: =SUM(C22:C25) -> 316 | T13: =SUM(D22:D25) -> 73 | U13: =SUM(E22:E25) -> 44 | V13: =SUM(F22:F25) -> 61 | W13: =SUM(G22:G25) -> 1 | X13: =SUM(H22:H25) -> 0 | Y13: =SUM(I22:I25) -> 14 | Z13: =SUM(J22:J25) -> 5 | ... AF13: =SUM(P22:P25) -> 1010
B14: 08.00 - 08.15 | C14: 172 | D14: 30 | E14: 21 | F14: 58 | G14: 0 | H14: 0 | I14: 4 | J14: 0 | K14: 0 | L14: 0 | M14: 170 | N14: 0 | O14: =SUM(C14:L14,N14) -> 285 | P14: =SUM(C14:N14) -> 455 | R14: 1100-1200 | S14: =SUM(C26:C29) -> 215 | T14: =SUM(D26:D29) -> 47 | U14: =SUM(E26:E29) -> 15 | V14: =SUM(F26:F29) -> 44 | W14: =SUM(G26:G29) -> 0 | X14: =SUM(H26:H29) -> 0 | Y14: =SUM(I26:I29) -> 17 | Z14: =SUM(J26:J29) -> 3 | ... AF14: =SUM(P26:P29) -> 706
B15: 08.15 - 08.30 | C15: 111 | D15: 21 | E15: 4 | F15: 61 | G15: 0 | H15: 0 | I15: 2 | J15: 1 | K15: 0 | L15: 0 | M15: 240 | N15: 0 | O15: =SUM(C15:L15,N15) -> 200 | P15: =SUM(C15:N15) -> 440 | R15: 1200-1300 | S15: =SUM(C30:C33) -> 203 | T15: =SUM(D30:D33) -> 42 | U15: =SUM(E30:E33) -> 33 | V15: =SUM(F30:F33) -> 32 | W15: =SUM(G30:G33) -> 0 | X15: =SUM(H30:H33) -> 0 | Y15: =SUM(I30:I33) -> 11 | Z15: =SUM(J30:J33) -> 7 | ... AF15: =SUM(P30:P33) -> 651
B16: 08.30 - 08.45 | C16: 130 | D16: 5 | E16: 9 | F16: 52 | G16: 0 | H16: 0 | I16: 6 | J16: 1 | K16: 0 | L16: 0 | M16: 242 | N16: 0 | O16: =SUM(C16:L16,N16) -> 203 | P16: =SUM(C16:N16) -> 445 | R16: 1300-1400 | S16: =SUM(C34:C37) -> 188 | T16: =SUM(D34:D37) -> 32 | U16: =SUM(E34:E37) -> 25 | V16: =SUM(F34:F37) -> 38 | W16: =SUM(G34:G37) -> 0 | X16: =SUM(H34:H37) -> 0 | Y16: =SUM(I34:I37) -> 14 | Z16: =SUM(J34:J37) -> 6 | ... AF16: =SUM(P34:P37) -> 555
B17: 08.45 - 9.00 | C17: 103 | D17: 18 | E17: 16 | F17: 27 | G17: 0 | H17: 0 | I17: 3 | J17: 2 | K17: 0 | L17: 0 | M17: 175 | N17: 0 | O17: =SUM(C17:L17,N17) -> 169 | P17: =SUM(C17:N17) -> 344 | R17: 1400-1500 | S17: =SUM(C38:C41) -> 137 | T17: =SUM(D38:D41) -> 22 | U17: =SUM(E38:E41) -> 17 | V17: =SUM(F38:F41) -> 38 | W17: =SUM(G38:G41) -> 1 | X17: =SUM(H38:H41) -> 0 | Y17: =SUM(I38:I41) -> 10 | Z17: =SUM(J38:J41) -> 3 | ... AF17: =SUM(P38:P41) -> 559
B18: 09.00 - 09.15 | C18: 121 | D18: 19 | E18: 11 | F18: 32 | G18: 0 | H18: 0 | I18: 4 | J18: 2 | K18: 0 | L18: 0 | M18: 205 | N18: 0 | O18: =SUM(C18:L18,N18) -> 189 | P18: =SUM(C18:N18) -> 394 | R18: 1500-1600 | S18: =SUM(C42:C45) -> 157 | T18: =SUM(D42:D45) -> 31 | U18: =SUM(E42:E45) -> 30 | V18: =SUM(F42:F45) -> 41 | W18: =SUM(G42:G45) -> 1 | X18: =SUM(H42:H45) -> 0 | Y18: =SUM(I42:I45) -> 13 | Z18: =SUM(J42:J45) -> 1 | ... AF18: =SUM(P42:P45) -> 598
B19: 09.15 - 09.30 | C19: 74 | D19: 25 | E19: 12 | F19: 21 | G19: 0 | H19: 0 | I19: 7 | J19: 0 | K19: 0 | L19: 0 | M19: 126 | N19: 0 | O19: =SUM(C19:L19,N19) -> 139 | P19: =SUM(C19:N19) -> 265 | R19: 1600-1700 | S19: =SUM(C46:C49) -> 182 | T19: =SUM(D46:D49) -> 43 | U19: =SUM(E46:E49) -> 26 | V19: =SUM(F46:F49) -> 33 | W19: =SUM(G46:G49) -> 1 | X19: =SUM(H46:H49) -> 0 | Y19: =SUM(I46:I49) -> 10 | Z19: =SUM(J46:J49) -> 0 | ... AF19: =SUM(P46:P49) -> 640
B20: 09.30 - 09.45 | C20: 108 | D20: 19 | E20: 11 | F20: 21 | G20: 0 | H20: 0 | I20: 5 | J20: 1 | K20: 0 | L20: 0 | M20: 175 | N20: 0 | O20: =SUM(C20:L20,N20) -> 165 | P20: =SUM(C20:N20) -> 340 | R20: 1700-1800 | S20: =SUM(C50:C53) -> 156 | T20: =SUM(D50:D53) -> 29 | U20: =SUM(E50:E53) -> 26 | V20: =SUM(F50:F53) -> 37 | W20: =SUM(G50:G53) -> 2 | X20: =SUM(H50:H53) -> 0 | Y20: =SUM(I50:I53) -> 17 | Z20: =SUM(J50:J53) -> 1 | ... AF20: =SUM(P50:P53) -> 747
B21: 09.45 - 10.00 | C21: 75 | D21: 7 | E21: 12 | F21: 18 | G21: 0 | H21: 0 | I21: 6 | J21: 0 | K21: 0 | L21: 0 | M21: 155 | N21: 0 | O21: =SUM(C21:L21,N21) -> 118 | P21: =SUM(C21:N21) -> 273 | R21: 1800-1900 | S21: =SUM(C54:C57) -> 151 | T21: =SUM(D54:D57) -> 32 | U21: =SUM(E54:E57) -> 27 | V21: =SUM(F54:F57) -> 29 | W21: =SUM(G54:G57) -> 1 | X21: =SUM(H54:H57) -> 0 | Y21: =SUM(I54:I57) -> 9 | Z21: =SUM(J54:J57) -> 0 | ... AF21: =SUM(P54:P57) -> 644
B22: 10.00 - 10.15 | C22: 93 | D22: 21 | E22: 8 | F22: 22 | G22: 1 | H22: 0 | I22: 3 | J22: 2 | K22: 0 | L22: 0 | M22: 147 | N22: 0 | O22: =SUM(C22:L22,N22) -> 150 | P22: =SUM(C22:N22) -> 297 | R22: AM Peak Hr | S22: =MAX(S10:S12) -> 831 | T22: =MAX(T10:T12) -> 81 | U22: =MAX(U10:U12) -> 59 | V22: =MAX(V10:V12) -> 249 | W22: =MAX(W10:W12) -> 1 | X22: =MAX(X10:X12) -> 0 | Y22: =MAX(Y10:Y12) -> 22 | Z22: =MAX(Z10:Z12) -> 4 | ... AF22: =MAX(AF10:AF12) -> 1868
B23: 10.15 - 10.30 | C23: 75 | D23: 20 | E23: 10 | F23: 15 | G23: 0 | H23: 0 | I23: 1 | J23: 2 | K23: 0 | L23: 0 | M23: 111 | N23: 0 | O23: =SUM(C23:L23,N23) -> 123 | P23: =SUM(C23:N23) -> 234 | R23: IP Peak Hr | S23: =MAX(S13:S18) -> 316 | T23: =MAX(T13:T18) -> 73 | U23: =MAX(U13:U18) -> 44 | V23: =MAX(V13:V18) -> 61 | W23: =MAX(W13:W18) -> 1 | X23: =MAX(X13:X18) -> 0 | Y23: =MAX(Y13:Y18) -> 17 | Z23: =MAX(Z13:Z18) -> 7 | ... AF23: =MAX(AF13:AF18) -> 1010
B24: 10.30 - 10.45 | C24: 83 | D24: 17 | E24: 11 | F24: 15 | G24: 0 | H24: 0 | I24: 9 | J24: 1 | K24: 0 | L24: 0 | M24: 137 | N24: 0 | O24: =SUM(C24:L24,N24) -> 136 | P24: =SUM(C24:N24) -> 273 | R24: PM Peak Hr | S24: =MAX(S19:S21) -> 182 | T24: =MAX(T19:T21) -> 43 | U24: =MAX(U19:U21) -> 27 | V24: =MAX(V19:V21) -> 37 | W24: =MAX(W19:W21) -> 2 | X24: =MAX(X19:X21) -> 0 | Y24: =MAX(Y19:Y21) -> 17 | Z24: =MAX(Z19:Z21) -> 1 | ... AF24: =MAX(AF19:AF21) -> 747
B25: 10.45 - 11.00 | C25: 65 | D25: 15 | E25: 15 | F25: 9 | G25: 0 | H25: 0 | I25: 1 | J25: 0 | K25: 0 | L25: 0 | M25: 101 | N25: 0 | O25: =SUM(C25:L25,N25) -> 105 | P25: =SUM(C25:N25) -> 206 | R25: AM Period | S25: =SUM(S10:S12) -> 1725 | T25: =SUM(T10:T12) -> 225 | U25: =SUM(U10:U12) -> 155 | V25: =SUM(V10:V12) -> 539 | W25: =SUM(W10:W12) -> 1 | X25: =SUM(X10:X12) -> 0 | Y25: =SUM(Y10:Y12) -> 44 | Z25: =SUM(Z10:Z12) -> 8 | ... AF25: =SUM(AF10:AF12) -> 4824
B26: 11.00 - 11.15 | C26: 69 | D26: 13 | E26: 4 | F26: 12 | G26: 0 | H26: 0 | I26: 4 | J26: 1 | K26: 0 | L26: 0 | M26: 97 | N26: 0 | O26: =SUM(C26:L26,N26) -> 103 | P26: =SUM(C26:N26) -> 200 | R26: IP Period | S26: =SUM(S13:S18) -> 1216 | T26: =SUM(T13:T18) -> 247 | U26: =SUM(U13:U18) -> 164 | V26: =SUM(V13:V18) -> 254 | W26: =SUM(W13:W18) -> 3 | X26: =SUM(X13:X18) -> 0 | Y26: =SUM(Y13:Y18) -> 79 | Z26: =SUM(Z13:Z18) -> 25 | ... AF26: =SUM(AF13:AF18) -> 4079
B27: 11.15 - 11.30 | C27: 52 | D27: 14 | E27: 1 | F27: 14 | G27: 0 | H27: 0 | I27: 8 | J27: 2 | K27: 0 | L27: 0 | M27: 115 | N27: 0 | O27: =SUM(C27:L27,N27) -> 91 | P27: =SUM(C27:N27) -> 206 | R27: PM Period | S27: =SUM(S19:S21) -> 489 | T27: =SUM(T19:T21) -> 104 | U27: =SUM(U19:U21) -> 79 | V27: =SUM(V19:V21) -> 99 | W27: =SUM(W19:W21) -> 4 | X27: =SUM(X19:X21) -> 0 | Y27: =SUM(Y19:Y21) -> 36 | Z27: =SUM(Z19:Z21) -> 1 | ... AF27: =SUM(AF19:AF21) -> 2031
B28: 11.30 - 11.45 | C28: 59 | D28: 11 | E28: 7 | F28: 12 | G28: 0 | H28: 0 | I28: 3 | J28: 0 | K28: 0 | L28: 0 | M28: 98 | N28: 0 | O28: =SUM(C28:L28,N28) -> 92 | P28: =SUM(C28:N28) -> 190 | R28: 12 Hours | S28: =SUM(S10:S21) -> 3430 | T28: =SUM(T10:T21) -> 576 | U28: =SUM(U10:U21) -> 398 | V28: =SUM(V10:V21) -> 892 | W28: =SUM(W10:W21) -> 8 | X28: =SUM(X10:X21) -> 0 | Y28: =SUM(Y10:Y21) -> 159 | Z28: =SUM(Z10:Z21) -> 34 | ... AF28: =SUM(AF10:AF21) -> 10934
B29: 11.45 - 12.00 | C29: 35 | D29: 9 | E29: 3 | F29: 6 | G29: 0 | H29: 0 | I29: 2 | J29: 0 | K29: 0 | L29: 0 | M29: 55 | N29: 0 | O29: =SUM(C29:L29,N29) -> 55 | P29: =SUM(C29:N29) -> 110
B30: 12.00 - 12.15 | C30: 55 | D30: 13 | E30: 13 | F30: 6 | G30: 0 | H30: 0 | I30: 6 | J30: 2 | K30: 0 | L30: 0 | M30: 72 | N30: 0 | O30: =SUM(C30:L30,N30) -> 95 | P30: =SUM(C30:N30) -> 167
B31: 12.15 - 12.30 | C31: 56 | D31: 12 | E31: 6 | F31: 8 | G31: 0 | H31: 0 | I31: 1 | J31: 0 | K31: 0 | L31: 0 | M31: 79 | N31: 0 | O31: =SUM(C31:L31,N31) -> 83 | P31: =SUM(C31:N31) -> 162
B32: 12.30 - 12.45 | C32: 37 | D32: 10 | E32: 10 | F32: 10 | G32: 0 | H32: 0 | I32: 2 | J32: 2 | K32: 0 | L32: 0 | M32: 70 | N32: 0 | O32: =SUM(C32:L32,N32) -> 71 | P32: =SUM(C32:N32) -> 141
B33: 12.45 - 13.00 | C33: 55 | D33: 7 | E33: 4 | F33: 8 | G33: 0 | H33: 0 | I33: 2 | J33: 3 | K33: 0 | L33: 0 | M33: 102 | N33: 0 | O33: =SUM(C33:L33,N33) -> 79 | P33: =SUM(C33:N33) -> 181
B34: 13.00 - 13.15 | C34: 47 | D34: 10 | E34: 6 | F34: 10 | G34: 0 | H34: 0 | I34: 7 | J34: 1 | K34: 0 | L34: 0 | M34: 65 | N34: 0 | O34: =SUM(C34:L34,N34) -> 81 | P34: =SUM(C34:N34) -> 146
B35: 13.15 - 13.30 | C35: 51 | D35: 6 | E35: 6 | F35: 13 | G35: 0 | H35: 0 | I35: 1 | J35: 2 | K35: 0 | L35: 0 | M35: 56 | N35: 0 | O35: =SUM(C35:L35,N35) -> 79 | P35: =SUM(C35:N35) -> 135
B36: 13.30 - 13.45 | C36: 33 | D36: 10 | E36: 6 | F36: 8 | G36: 0 | H36: 0 | I36: 2 | J36: 3 | K36: 1 | L36: 0 | M36: 80 | N36: 0 | O36: =SUM(C36:L36,N36) -> 63 | P36: =SUM(C36:N36) -> 143
B37: 13.45 - 14.00 | C37: 57 | D37: 6 | E37: 7 | F37: 7 | G37: 0 | H37: 0 | I37: 4 | J37: 0 | K37: 0 | L37: 0 | M37: 50 | N37: 0 | O37: =SUM(C37:L37,N37) -> 81 | P37: =SUM(C37:N37) -> 131
B38: 14.00 - 14.15 | C38: 22 | D38: 6 | E38: 3 | F38: 8 | G38: 0 | H38: 0 | I38: 4 | J38: 2 | K38: 0 | L38: 0 | M38: 80 | N38: 0 | O38: =SUM(C38:L38,N38) -> 45 | P38: =SUM(C38:N38) -> 125
B39: 14.15 - 14.30 | C39: 40 | D39: 6 | E39: 5 | F39: 11 | G39: 0 | H39: 0 | I39: 1 | J39: 1 | K39: 0 | L39: 0 | M39: 90 | N39: 0 | O39: =SUM(C39:L39,N39) -> 64 | P39: =SUM(C39:N39) -> 154
B40: 14.30 - 14.45 | C40: 40 | D40: 3 | E40: 4 | F40: 9 | G40: 0 | H40: 0 | I40: 2 | J40: 0 | K40: 0 | L40: 0 | M40: 91 | N40: 0 | O40: =SUM(C40:L40,N40) -> 58 | P40: =SUM(C40:N40) -> 149
... B57: 18.45 - 19.00 | C57: 41 | D57: 6 | E57: 8 | F57: 10 | G57: 0 | H57: 0 | I57: 5 | J57: 0 | K57: 0 | L57: 0 | M57: 60 | N57: 0 | O57: =SUM(C57:L57,N57) -> 70 | P57: =SUM(C57:N57) -> 130
B58: Totals | C58: =SUM(C10:C57) -> 3430 | D58: =SUM(D10:D57) -> 576 | E58: =SUM(E10:E57) -> 398 | F58: =SUM(F10:F57) -> 892 | G58: =SUM(G10:G57) -> 8 | H58: =SUM(H10:H57) -> 0 | I58: =SUM(I10:I57) -> 159 | J58: =SUM(J10:J57) -> 34 | ... P58: =SUM(P10:P57) -> 10934
...

Sheet 30.07 Mulago-Kyebando
B1: Consultancy services for Preparation of Expressway Development Master Plan (EDMP) for Uganda
B2: MANUAL CLASSIFIED COUNT (MCC)
B3: ROAD NAME: | C3: ='02.08 Mulago-Kyebando'!C3:G3 -> MCC - C1 - STN28 - KISINGIRI ROAD
C5: Date | D5: ='30.07 -Kyebando-Mulago'!D5 -> 30.07.19 | F5: Location | G5: ='02.08 Kyebando-Mulago'!G5:H5 -> Kisingiri Street | J5: Surveyor | K5: Frank
C6: Dir. From | D6: ='02.08 Mulago-Kyebando'!D6:E6 -> Mulago | F6: Dir. To | G6: ='02.08 Mulago-Kyebando'!G6:H6 -> Kyebando | J6: Supervisor | K6: Steven
B8: Time / Veh Type | R8: SUMMARY TRAFFIC VOLUMES
C9: 1. Car | D9: 2. Station Wagon | E9: 3. Pickups | F9: 4. Minibus, matatu | G9: 5. Medium bus | H9: 6. Large Bus | I9: 7. Light Truck | J9: 8. Medium Truck | K9: 9. Heavy truck | L9: 10. Truck Trailer | M9: 11. Motor cycles | N9: 12. Tractors | O9: Total Excl M/Cycles | P9: Total All | R9: Time | S9: 1. Car | T9: 2. Station Wagon | U9: 3. Pickups | V9: 4. Minibus, matatu | W9: 5. Medium bus | X9: 6. Large Bus | Y9: 7. Light Truck | Z9: 8. Medium Truck | AA9: 9. Heavy truck | AB9: 10. Truck Trailer | AC9: 11. Motorcycles | AD9: 12. Tractors, Graders | AE9: Total Excl M/ Cycles | AF9: Total All
B10: 07.00 - 07.15 | C10: 31 | D10: 4 | E10: 3 | F10: 12 | G10: 1 | H10: 0 | I10: 5 | J10: 0 | K10: 0 | L10: 0 | M10: 135 | N10: 0 | O10: =SUM(C10:L10,N10) -> 56 | P10: =SUM(C10:N10) -> 191 | R10: 0700-0800 | S10: =SUM(C10:C13) -> 102 | T10: =SUM(D10:D13) -> 10 | U10: =SUM(E10:E13) -> 15 | V10: =SUM(F10:F13) -> 50 | W10: =SUM(G10:G13) -> 4 | X10: =SUM(H10:H13) -> 0 | Y10: =SUM(I10:I13) -> 7 | Z10: =SUM(J10:J13) -> 0 | ... AF10: =SUM(P10:P13) -> 843
B11: 07.15 - 07.30 | C11: 22 | D11: 3 | E11: 5 | F11: 14 | G11: 2 | H11: 0 | I11: 0 | J11: 0 | K11: 0 | L11: 0 | M11: 125 | N11: 0 | O11: =SUM(C11:L11,N11) -> 46 | P11: =SUM(C11:N11) -> 171 | R11: 0800-0900 | S11: =SUM(C14:C17) -> 113 | T11: =SUM(D14:D17) -> 14 | U11: =SUM(E14:E17) -> 8 | V11: =SUM(F14:F17) -> 39 | W11: =SUM(G14:G17) -> 1 | X11: =SUM(H14:H17) -> 0 | Y11: =SUM(I14:I17) -> 8 | Z11: =SUM(J14:J17) -> 2 | ... AF11: =SUM(P14:P17) -> 912
B12: 07.30 - 07.45 | C12: 34 | D12: 2 | E12: 6 | F12: 19 | G12: 1 | H12: 0 | I12: 2 | J12: 0 | K12: 0 | L12: 0 | M12: 260 | N12: 0 | O12: =SUM(C12:L12,N12) -> 64 | P12: =SUM(C12:N12) -> 324 | R12: 0900-1000 | S12: =SUM(C18:C21) -> 131 | T12: =SUM(D18:D21) -> 12 | U12: =SUM(E18:E21) -> 23 | V12: =SUM(F18:F21) -> 57 | W12: =SUM(G18:G21) -> 2 | X12: =SUM(H18:H21) -> 0 | Y12: =SUM(I18:I21) -> 11 | Z12: =SUM(J18:J21) -> 4 | ... AF12: =SUM(P18:P21) -> 941
B13: 07.45 - 08.00 | C13: 15 | D13: 1 | E13: 1 | F13: 5 | G13: 0 | H13: 0 | I13: 0 | J13: 0 | K13: 0 | L13: 0 | M13: 135 | N13: 0 | O13: =SUM(C13:L13,N13) -> 22 | P13: =SUM(C13:N13) -> 157 | R13: 1000-1100 | S13: =SUM(C22:C25) -> 137 | T13: =SUM(D22:D25) -> 29 | U13: =SUM(E22:E25) -> 29 | V13: =SUM(F22:F25) -> 49 | W13: =SUM(G22:G25) -> 1 | X13: =SUM(H22:H25) -> 0 | Y13: =SUM(I22:I25) -> 16 | Z13: =SUM(J22:J25) -> 0 | ... AF13: =SUM(P22:P25) -> 859
B14: 08.00 - 08.15 | C14: 32 | D14: 2 | E14: 0 | F14: 3 | G14: 1 | H14: 0 | I14: 2 | J14: 0 | K14: 0 | L14: 0 | M14: 181 | N14: 0 | O14: =SUM(C14:L14,N14) -> 40 | P14: =SUM(C14:N14) -> 221 | R14: 1100-1200 | S14: =SUM(C26:C29) -> 133 | T14: =SUM(D26:D29) -> 21 | U14: =SUM(E26:E29) -> 29 | V14: =SUM(F26:F29) -> 48 | W14: =SUM(G26:G29) -> 1 | X14: =SUM(H26:H29) -> 0 | Y14: =SUM(I26:I29) -> 26 | Z14: =SUM(J26:J29) -> 3 | ... AF14: =SUM(P26:P29) -> 590
B15: 08.15 - 08.30 | C15: 29 | D15: 4 | E15: 3 | F15: 15 | G15: 0 | H15: 0 | I15: 2 | J15: 1 | K15: 0 | L15: 0 | M15: 160 | N15: 0 | O15: =SUM(C15:L15,N15) -> 54 | P15: =SUM(C15:N15) -> 214 | R15: 1200-1300 | S15: =SUM(C30:C33) -> 148 | T15: =SUM(D30:D33) -> 11 | U15: =SUM(E30:E33) -> 31 | V15: =SUM(F30:F33) -> 36 | W15: =SUM(G30:G33) -> 1 | X15: =SUM(H30:H33) -> 1 | Y15: =SUM(I30:I33) -> 28 | Z15: =SUM(J30:J33) -> 5 | ... AF15: =SUM(P30:P33) -> 578
B16: 08.30 - 08.45 | C16: 29 | D16: 3 | E16: 3 | F16: 11 | G16: 0 | H16: 0 | I16: 2 | J16: 1 | K16: 0 | L16: 0 | M16: 215 | N16: 0 | O16: =SUM(C16:L16,N16) -> 49 | P16: =SUM(C16:N16) -> 264 | R16: 1300-1400 | S16: =SUM(C34:C37) -> 169 | T16: =SUM(D34:D37) -> 23 | U16: =SUM(E34:E37) -> 31 | V16: =SUM(F34:F37) -> 46 | W16: =SUM(G34:G37) -> 1 | X16: =SUM(H34:H37) -> 0 | Y16: =SUM(I34:I37) -> 19 | Z16: =SUM(J34:J37) -> 4 | ... AF16: =SUM(P34:P37) -> 594
B17: 08.45 - 9.00 | C17: 23 | D17: 5 | E17: 2 | F17: 10 | G17: 0 | H17: 0 | I17: 2 | J17: 0 | K17: 0 | L17: 0 | M17: 171 | N17: 0 | O17: =SUM(C17:L17,N17) -> 42 | P17: =SUM(C17:N17) -> 213 | R17: 1400-1500 | S17: =SUM(C38:C41) -> 184 | T17: =SUM(D38:D41) -> 27 | U17: =SUM(E38:E41) -> 21 | V17: =SUM(F38:F41) -> 29 | W17: =SUM(G38:G41) -> 1 | X17: =SUM(H38:H41) -> 1 | Y17: =SUM(I38:I41) -> 18 | Z17: =SUM(J38:J41) -> 4 | ... AF17: =SUM(P38:P41) -> 601
B18: 09.00 - 09.15 | C18: 36 | D18: 4 | E18: 3 | F18: 2 | G18: 0 | H18: 0 | I18: 2 | J18: 0 | K18: 0 | L18: 0 | M18: 235 | N18: 0 | O18: =SUM(C18:L18,N18) -> 47 | P18: =SUM(C18:N18) -> 282 | R18: 1500-1600 | S18: =SUM(C42:C45) -> 233 | T18: =SUM(D42:D45) -> 32 | U18: =SUM(E42:E45) -> 45 | V18: =SUM(F42:F45) -> 41 | W18: =SUM(G42:G45) -> 0 | X18: =SUM(H42:H45) -> 1 | Y18: =SUM(I42:I45) -> 18 | Z18: =SUM(J42:J45) -> 4 | ... AF18: =SUM(P42:P45) -> 692
B19: 09.15 - 09.30 | C19: 34 | D19: 1 | E19: 4 | F19: 16 | G19: 1 | H19: 0 | I19: 5 | J19: 0 | K19: 0 | L19: 0 | M19: 175 | N19: 0 | O19: =SUM(C19:L19,N19) -> 61 | P19: =SUM(C19:N19) -> 236 | R19: 1600-1700 | S19: =SUM(C46:C49) -> 371 | T19: =SUM(D46:D49) -> 47 | U19: =SUM(E46:E49) -> 32 | V19: =SUM(F46:F49) -> 47 | W19: =SUM(G46:G49) -> 2 | X19: =SUM(H46:H49) -> 0 | Y19: =SUM(I46:I49) -> 16 | Z19: =SUM(J46:J49) -> 2 | ... AF19: =SUM(P46:P49) -> 852
B20: 09.30 - 09.45 | C20: 38 | D20: 3 | E20: 5 | F20: 31 | G20: 1 | H20: 0 | I20: 2 | J20: 3 | K20: 0 | L20: 0 | M20: 180 | N20: 0 | O20: =SUM(C20:L20,N20) -> 83 | P20: =SUM(C20:N20) -> 263 | R20: 1700-1800 | S20: =SUM(C50:C53) -> 635 | T20: =SUM(D50:D53) -> 57 | U20: =SUM(E50:E53) -> 43 | V20: =SUM(F50:F53) -> 53 | W20: =SUM(G50:G53) -> 2 | X20: =SUM(H50:H53) -> 1 | Y20: =SUM(I50:I53) -> 19 | Z20: =SUM(J50:J53) -> 3 | ... AF20: =SUM(P50:P53) -> 1200
B21: 09.45 - 10.00 | C21: 23 | D21: 4 | E21: 11 | F21: 8 | G21: 0 | H21: 0 | I21: 2 | J21: 1 | K21: 0 | L21: 0 | M21: 111 | N21: 0 | O21: =SUM(C21:L21,N21) -> 49 | P21: =SUM(C21:N21) -> 160 | R21: 1800-1900 | S21: =SUM(C54:C57) -> 535 | T21: =SUM(D54:D57) -> 23 | U21: =SUM(E54:E57) -> 25 | V21: =SUM(F54:F57) -> 70 | W21: =SUM(G54:G57) -> 2 | X21: =SUM(H54:H57) -> 0 | Y21: =SUM(I54:I57) -> 14 | Z21: =SUM(J54:J57) -> 0 | ... AF21: =SUM(P54:P57) -> 949
B22: 10.00 - 10.15 | C22: 20 | D22: 6 | E22: 5 | F22: 6 | G22: 0 | H22: 0 | I22: 3 | J22: 0 | K22: 0 | L22: 0 | M22: 137 | N22: 0 | O22: =SUM(C22:L22,N22) -> 40 | P22: =SUM(C22:N22) -> 177 | R22: AM Peak Hr | S22: =MAX(S10:S12) -> 131 | T22: =MAX(T10:T12) -> 14 | U22: =MAX(U10:U12) -> 23 | V22: =MAX(V10:V12) -> 57 | W22: =MAX(W10:W12) -> 4 | X22: =MAX(X10:X12) -> 0 | Y22: =MAX(Y10:Y12) -> 11 | Z22: =MAX(Z10:Z12) -> 4 | ... AF22: =MAX(AF10:AF12) -> 941
B23: 10.15 - 10.30 | C23: 46 | D23: 10 | E23: 7 | F23: 17 | G23: 0 | H23: 0 | I23: 3 | J23: 0 | K23: 0 | L23: 0 | M23: 160 | N23: 0 | O23: =SUM(C23:L23,N23) -> 83 | P23: =SUM(C23:N23) -> 243 | R23: IP Peak Hr | S23: =MAX(S13:S18) -> 233 | T23: =MAX(T13:T18) -> 32 | U23: =MAX(U13:U18) -> 45 | V23: =MAX(V13:V18) -> 49 | W23: =MAX(W13:W18) -> 1 | X23: =MAX(X13:X18) -> 1 | Y23: =MAX(Y13:Y18) -> 28 | Z23: =MAX(Z13:Z18) -> 5 | ... AF23: =MAX(AF13:AF18) -> 859
B24: 10.30 - 10.45 | C24: 25 | D24: 7 | E24: 9 | F24: 12 | G24: 0 | H24: 0 | I24: 3 | J24: 0 | K24: 1 | L24: 0 | M24: 140 | N24: 0 | O24: =SUM(C24:L24,N24) -> 57 | P24: =SUM(C24:N24) -> 197 | R24: PM Peak Hr | S24: =MAX(S19:S21) -> 635 | T24: =MAX(T19:T21) -> 57 | U24: =MAX(U19:U21) -> 43 | V24: =MAX(V19:V21) -> 70 | W24: =MAX(W19:W21) -> 2 | X24: =MAX(X19:X21) -> 1 | Y24: =MAX(Y19:Y21) -> 19 | Z24: =MAX(Z19:Z21) -> 3 | ... AF24: =MAX(AF19:AF21) -> 1200
B25: 10.45 - 11.00 | C25: 46 | D25: 6 | E25: 8 | F25: 14 | G25: 1 | H25: 0 | I25: 7 | J25: 0 | K25: 0 | L25: 0 | M25: 160 | N25: 0 | O25: =SUM(C25:L25,N25) -> 82 | P25: =SUM(C25:N25) -> 242 | R25: AM Period | S25: =SUM(S10:S12) -> 346 | T25: =SUM(T10:T12) -> 36 | U25: =SUM(U10:U12) -> 46 | V25: =SUM(V10:V12) -> 146 | W25: =SUM(W10:W12) -> 7 | X25: =SUM(X10:X12) -> 0 | Y25: =SUM(Y10:Y12) -> 26 | Z25: =SUM(Z10:Z12) -> 6 | ... AF25: =SUM(AF10:AF12) -> 2696
B26: 11.00 - 11.15 | C26: 50 | D26: 8 | E26: 9 | F26: 16 | G26: 1 | H26: 0 | I26: 12 | J26: 0 | K26: 0 | L26: 0 | M26: 120 | N26: 0 | O26: =SUM(C26:L26,N26) -> 96 | P26: =SUM(C26:N26) -> 216 | R26: IP Period | S26: =SUM(S13:S18) -> 1004 | T26: =SUM(T13:T18) -> 143 | U26: =SUM(U13:U18) -> 186 | V26: =SUM(V13:V18) -> 249 | W26: =SUM(W13:W18) -> 5 | X26: =SUM(X13:X18) -> 3 | Y26: =SUM(Y13:Y18) -> 125 | Z26: =SUM(Z13:Z18) -> 20 | ... AF26: =SUM(AF13:AF18) -> 3914
B27: 11.15 - 11.30 | C27: 22 | D27: 2 | E27: 11 | F27: 13 | G27: 0 | H27: 0 | I27: 4 | J27: 1 | K27: 0 | L27: 0 | M27: 90 | N27: 0 | O27: =SUM(C27:L27,N27) -> 53 | P27: =SUM(C27:N27) -> 143 | R27: PM Period | S27: =SUM(S19:S21) -> 1541 | T27: =SUM(T19:T21) -> 127 | U27: =SUM(U19:U21) -> 100 | V27: =SUM(V19:V21) -> 170 | W27: =SUM(W19:W21) -> 6 | X27: =SUM(X19:X21) -> 1 | Y27: =SUM(Y19:Y21) -> 49 | Z27: =SUM(Z19:Z21) -> 5 | ... AF27: =SUM(AF19:AF21) -> 3001
B28: 11.30 - 11.45 | C28: 27 | D28: 5 | E28: 2 | F28: 7 | G28: 0 | H28: 0 | I28: 2 | J28: 1 | K28: 0 | L28: 0 | M28: 69 | N28: 0 | O28: =SUM(C28:L28,N28) -> 44 | P28: =SUM(C28:N28) -> 113 | R28: 12 Hours | S28: =SUM(S10:S21) -> 2891 | T28: =SUM(T10:T21) -> 306 | U28: =SUM(U10:U21) -> 332 | V28: =SUM(V10:V21) -> 565 | W28: =SUM(W10:W21) -> 18 | X28: =SUM(X10:X21) -> 4 | Y28: =SUM(Y10:Y21) -> 200 | Z28: =SUM(Z10:Z21) -> 31 | ... AF28: =SUM(AF10:AF21) -> 9611
B29: 11.45 - 12.00 | C29: 34 | D29: 6 | E29: 7 | F29: 12 | G29: 0 | H29: 0 | I29: 8 | J29: 1 | K29: 0 | L29: 0 | M29: 50 | N29: 0 | O29: =SUM(C29:L29,N29) -> 68 | P29: =SUM(C29:N29) -> 118
B30: 12.00 - 12.15 | C30: 36 | D30: 3 | E30: 4 | F30: 11 | G30: 0 | H30: 0 | I30: 9 | J30: 0 | K30: 0 | L30: 0 | M30: 71 | N30: 0 | O30: =SUM(C30:L30,N30) -> 63 | P30: =SUM(C30:N30) -> 134
B31: 12.15 - 12.30 | C31: 37 | D31: 6 | E31: 8 | F31: 10 | G31: 0 | H31: 0 | I31: 9 | J31: 1 | K31: 1 | L31: 0 | M31: 70 | N31: 0 | O31: =SUM(C31:L31,N31) -> 72 | P31: =SUM(C31:N31) -> 142
B32: 12.30 - 12.45 | C32: 35 | D32: 0 | E32: 8 | F32: 8 | G32: 0 | H32: 0 | I32: 7 | J32: 1 | K32: 0 | L32: 0 | M32: 95 | N32: 0 | O32: =SUM(C32:L32,N32) -> 59 | P32: =SUM(C32:N32) -> 154
B33: 12.45 - 13.00 | C33: 40 | D33: 2 | E33: 11 | F33: 7 | G33: 1 | H33: 1 | I33: 3 | J33: 3 | K33: 0 | L33: 0 | M33: 80 | N33: 0 | O33: =SUM(C33:L33,N33) -> 68 | P33: =SUM(C33:N33) -> 148
B34: 13.00 - 13.15 | C34: 65 | D34: 7 | E34: 9 | F34: 24 | G34: 0 | H34: 0 | I34: 9 | J34: 1 | K34: 0 | L34: 0 | M34: 95 | N34: 0 | O34: =SUM(C34:L34,N34) -> 115 | P34: =SUM(C34:N34) -> 210
B35: 13.15 - 13.30 | C35: 45 | D35: 5 | E35: 8 | F35: 13 | G35: 1 | H35: 0 | I35: 4 | J35: 0 | K35: 0 | L35: 0 | M35: 90 | N35: 0 | O35: =SUM(C35:L35,N35) -> 76 | P35: =SUM(C35:N35) -> 166
B36: 13.30 - 13.45 | C36: 32 | D36: 3 | E36: 7 | F36: 3 | G36: 0 | H36: 0 | I36: 1 | J36: 1 | K36: 0 | L36: 0 | M36: 65 | N36: 0 | O36: =SUM(C36:L36,N36) -> 47 | P36: =SUM(C36:N36) -> 112
B37: 13.45 - 14.00 | C37: 27 | D37: 8 | E37: 7 | F37: 6 | G37: 0 | H37: 0 | I37: 5 | J37: 2 | K37: 0 | L37: 0 | M37: 51 | N37: 0 | O37: =SUM(C37:L37,N37) -> 55 | P37: =SUM(C37:N37) -> 106
B38: 14.00 - 14.15 | C38: 43 | D38: 9 | E38: 7 | F38: 10 | G38: 1 | H38: 0 | I38: 4 | J38: 1 | K38: 0 | L38: 0 | M38: 105 | N38: 0 | O38: =SUM(C38:L38,N38) -> 75 | P38: =SUM(C38:N38) -> 180
B39: 14.15 - 14.30 | C39: 59 | D39: 6 | E39: 7 | F39: 10 | G39: 0 | H39: 1 | I39: 2 | J39: 1 | K39: 1 | L39: 0 | M39: 65 | N39: 0 | O39: =SUM(C39:L39,N39) -> 87 | P39: =SUM(C39:N39) -> 152
B40: 14.30 - 14.45 | C40: 46 | D40: 2 | E40: 4 | F40: 2 | G40: 0 | H40: 0 | I40: 3 | J40: 0 | K40: 0 | L40: 0 | M40: 80 | N40: 0 | O40: =SUM(C40:L40,N40) -> 57 | P40: =SUM(C40:N40) -> 137
... B57: 18.45 - 19.00 | C57: 130 | D57: 4 | E57: 5 | F57: 10 | G57: 0 | H57: 0 | I57: 3 | J57: 0 | K57: 0 | L57: 0 | M57: 75 | N57: 0 | O57: =SUM(C57:L57,N57) -> 152 | P57: =SUM(C57:N57) -> 227
B58: Totals | C58: =SUM(C10:C57) -> 2891 | D58: =SUM(D10:D57) -> 306 | E58: =SUM(E10:E57) -> 332 | F58: =SUM(F10:F57) -> 565 | G58: =SUM(G10:G57) -> 18 | H58: =SUM(H10:H57) -> 4 | I58: =SUM(I10:I57) -> 200 | J58: =SUM(J10:J57) -> 31 | ... P58: =SUM(P10:P57) -> 9611
...

Sheet 31.07 Kyebando-Mulago
B1: Consultancy services for Preparation of Expressway Development Master Plan (EDMP) for Uganda
B2: MANUAL CLASSIFIED COUNT (MCC)
B3: ROAD NAME: | C3: ='02.08 Kyebando-Mulago'!C3:G3 -> MCC - C1 - STN28 - KISINGIRI ROAD
C5: Date | D5: 31.07.19 | F5: Location | G5: ='30.07 Mulago-Kyebando'!G5:H5 -> Kisingiri Street | J5: Surveyor | K5: Rashida
C6: Dir. From | D6: ='02.08 Kyebando-Mulago'!D6:E6 -> Kyebando | F6: Dir. To | G6: ='02.08 Kyebando-Mulago'!G6:H6 -> Mulago | J6: Supervisor | K6: Steven
B8: Time / Veh Type | R8: SUMMARY TRAFFIC VOLUMES
C9: 1. Car | D9: 2. Station Wagon | E9: 3. Pickups | F9: 4. Minibus, matatu | G9: 5. Medium bus | H9: 6. Large Bus | I9: 7. Light Truck | J9: 8. Medium Truck | K9: 9. Heavy truck | L9: 10. Truck Trailer | M9: 11. Motor cycles | N9: 12. Tractors | O9: Total Excl M/Cycles | P9: Total All | R9: Time | S9: 1. Car | T9: 2. Station Wagon | U9: 3. Pickups | V9: 4. Minibus, matatu | W9: 5. Medium bus | X9: 6. Large Bus | Y9: 7. Light Truck | Z9: 8. Medium Truck | AA9: 9. Heavy truck | AB9: 10. Truck Trailer | AC9: 11. Motorcycles | AD9: 12. Tractors, Graders | AE9: Total Excl M/ Cycles | AF9: Total All
B10: 07.00 - 07.15 | C10: 258 | D10: 33 | E10: 12 | F10: 75 | G10: 0 | H10: 0 | I10: 4 | J10: 0 | K10: 0 | L10: 0 | M10: 93 | N10: 0 | O10: =SUM(C10:L10,N10) -> 382 | P10: =SUM(C10:N10) -> 475 | R10: 0700-0800 | S10: =SUM(C10:C13) -> 868 | T10: =SUM(D10:D13) -> 124 | U10: =SUM(E10:E13) -> 49 | V10: =SUM(F10:F13) -> 318 | W10: =SUM(G10:G13) -> 3 | X10: =SUM(H10:H13) -> 0 | Y10: =SUM(I10:I13) -> 14 | Z10: =SUM(J10:J13) -> 4 | ... AF10: =SUM(P10:P13) -> 2088
B11: 07.15 - 07.30 | C11: 220 | D11: 30 | E11: 14 | F11: 80 | G11: 1 | H11: 0 | I11: 3 | J11: 1 | K11: 0 | L11: 0 | M11: 160 | N11: 0 | O11: =SUM(C11:L11,N11) -> 349 | P11: =SUM(C11:N11) -> 509 | R11: 0800-0900 | S11: =SUM(C14:C17) -> 550 | T11: =SUM(D14:D17) -> 79 | U11: =SUM(E14:E17) -> 50 | V11: =SUM(F14:F17) -> 218 | W11: =SUM(G14:G17) -> 0 | X11: =SUM(H14:H17) -> 2 | Y11: =SUM(I14:I17) -> 12 | Z11: =SUM(J14:J17) -> 11 | ... AF11: =SUM(P14:P17) -> 1797
B12: 07.30 - 07.45 | C12: 245 | D12: 25 | E12: 10 | F12: 93 | G12: 1 | H12: 0 | I12: 3 | J12: 0 | K12: 0 | L12: 0 | M12: 270 | N12: 0 | O12: =SUM(C12:L12,N12) -> 377 | P12: =SUM(C12:N12) -> 647 | R12: 0900-1000 | S12: =SUM(C18:C21) -> 298 | T12: =SUM(D18:D21) -> 49 | U12: =SUM(E18:E21) -> 31 | V12: =SUM(F18:F21) -> 89 | W12: =SUM(G18:G21) -> 0 | X12: =SUM(H18:H21) -> 0 | Y12: =SUM(I18:I21) -> 9 | Z12: =SUM(J18:J21) -> 0 | ... AF12: =SUM(P18:P21) -> 998
B13: 07.45 - 08.00 | C13: 145 | D13: 36 | E13: 13 | F13: 70 | G13: 1 | H13: 0 | I13: 4 | J13: 3 | K13: 0 | L13: 0 | M13: 185 | N13: 0 | O13: =SUM(C13:L13,N13) -> 272 | P13: =SUM(C13:N13) -> 457 | R13: 1000-1100 | S13: =SUM(C22:C25) -> 283 | T13: =SUM(D22:D25) -> 51 | U13: =SUM(E22:E25) -> 29 | V13: =SUM(F22:F25) -> 62 | W13: =SUM(G22:G25) -> 1 | X13: =SUM(H22:H25) -> 0 | Y13: =SUM(I22:I25) -> 17 | Z13: =SUM(J22:J25) -> 1 | ... AF13: =SUM(P22:P25) -> 860
B14: 08.00 - 08.15 | C14: 155 | D14: 31 | E14: 16 | F14: 81 | G14: 0 | H14: 0 | I14: 4 | J14: 0 | K14: 0 | L14: 0 | M14: 225 | N14: 0 | O14: =SUM(C14:L14,N14) -> 287 | P14: =SUM(C14:N14) -> 512 | R14: 1100-1200 | S14: =SUM(C26:C29) -> 203 | T14: =SUM(D26:D29) -> 38 | U14: =SUM(E26:E29) -> 35 | V14: =SUM(F26:F29) -> 37 | W14: =SUM(G26:G29) -> 0 | X14: =SUM(H26:H29) -> 0 | Y14: =SUM(I26:I29) -> 18 | Z14: =SUM(J26:J29) -> 1 | ... AF14: =SUM(P26:P29) -> 664
B15: 08.15 - 08.30 | C15: 139 | D15: 8 | E15: 13 | F15: 55 | G15: 0 | H15: 0 | I15: 1 | J15: 0 | K15: 0 | L15: 0 | M15: 242 | N15: 0 | O15: =SUM(C15:L15,N15) -> 216 | P15: =SUM(C15:N15) -> 458 | R15: 1200-1300 | S15: =SUM(C30:C33) -> 148 | T15: =SUM(D30:D33) -> 45 | U15: =SUM(E30:E33) -> 19 | V15: =SUM(F30:F33) -> 44 | W15: =SUM(G30:G33) -> 1 | X15: =SUM(H30:H33) -> 0 | Y15: =SUM(I30:I33) -> 12 | Z15: =SUM(J30:J33) -> 3 | ... AF15: =SUM(P30:P33) -> 575
B16: 08.30 - 08.45 | C16: 136 | D16: 18 | E16: 10 | F16: 50 | G16: 0 | H16: 2 | I16: 5 | J16: 0 | K16: 0 | L16: 0 | M16: 220 | N16: 0 | O16: =SUM(C16:L16,N16) -> 221 | P16: =SUM(C16:N16) -> 441 | R16: 1300-1400 | S16: =SUM(C34:C37) -> 136 | T16: =SUM(D34:D37) -> 23 | U16: =SUM(E34:E37) -> 28 | V16: =SUM(F34:F37) -> 40 | W16: =SUM(G34:G37) -> 1 | X16: =SUM(H34:H37) -> 0 | Y16: =SUM(I34:I37) -> 13 | Z16: =SUM(J34:J37) -> 2 | ... AF16: =SUM(P34:P37) -> 540
B17: 08.45 - 9.00 | C17: 120 | D17: 22 | E17: 11 | F17: 32 | G17: 0 | H17: 0 | I17: 2 | J17: 11 | K17: 0 | L17: 0 | M17: 188 | N17: 0 | O17: =SUM(C17:L17,N17) -> 198 | P17: =SUM(C17:N17) -> 386 | R17: 1400-1500 | S17: =SUM(C38:C41) -> 222 | T17: =SUM(D38:D41) -> 33 | U17: =SUM(E38:E41) -> 35 | V17: =SUM(F38:F41) -> 25 | W17: =SUM(G38:G41) -> 1 | X17: =SUM(H38:H41) -> 0 | Y17: =SUM(I38:I41) -> 8 | Z17: =SUM(J38:J41) -> 2 | ... AF17: =SUM(P38:P41) -> 606
B18: 09.00 - 09.15 | C18: 61 | D18: 13 | E18: 11 | F18: 29 | G18: 0 | H18: 0 | I18: 0 | J18: 0 | K18: 0 | L18: 0 | M18: 117 | N18: 0 | O18: =SUM(C18:L18,N18) -> 114 | P18: =SUM(C18:N18) -> 231 | R18: 1500-1600 | S18: =SUM(C42:C45) -> 144 | T18: =SUM(D42:D45) -> 37 | U18: =SUM(E42:E45) -> 22 | V18: =SUM(F42:F45) -> 34 | W18: =SUM(G42:G45) -> 1 | X18: =SUM(H42:H45) -> 0 | Y18: =SUM(I42:I45) -> 17 | Z18: =SUM(J42:J45) -> 0 | ... AF18: =SUM(P42:P45) -> 549
B19: 09.15 - 09.30 | C19: 50 | D19: 10 | E19: 5 | F19: 21 | G19: 0 | H19: 0 | I19: 3 | J19: 0 | K19: 0 | L19: 0 | M19: 120 | N19: 0 | O19: =SUM(C19:L19,N19) -> 89 | P19: =SUM(C19:N19) -> 209 | R19: 1600-1700 | S19: =SUM(C46:C49) -> 175 | T19: =SUM(D46:D49) -> 32 | U19: =SUM(E46:E49) -> 20 | V19: =SUM(F46:F49) -> 50 | W19: =SUM(G46:G49) -> 1 | X19: =SUM(H46:H49) -> 0 | Y19: =SUM(I46:I49) -> 14 | Z19: =SUM(J46:J49) -> 6 | ... AF19: =SUM(P46:P49) -> 702
B20: 09.30 - 09.45 | C20: 70 | D20: 14 | E20: 7 | F20: 26 | G20: 0 | H20: 0 | I20: 3 | J20: 0 | K20: 0 | L20: 0 | M20: 120 | N20: 0 | O20: =SUM(C20:L20,N20) -> 120 | P20: =SUM(C20:N20) -> 240 | R20: 1700-1800 | S20: =SUM(C50:C53) -> 197 | T20: =SUM(D50:D53) -> 41 | U20: =SUM(E50:E53) -> 22 | V20: =SUM(F50:F53) -> 26 | W20: =SUM(G50:G53) -> 1 | X20: =SUM(H50:H53) -> 0 | Y20: =SUM(I50:I53) -> 19 | Z20: =SUM(J50:J53) -> 1 | ... AF20: =SUM(P50:P53) -> 722
B21: 09.45 - 10.00 | C21: 117 | D21: 12 | E21: 8 | F21: 13 | G21: 0 | H21: 0 | I21: 3 | J21: 0 | K21: 0 | L21: 0 | M21: 165 | N21: 0 | O21: =SUM(C21:L21,N21) -> 153 | P21: =SUM(C21:N21) -> 318 | R21: 1800-1900 | S21: =SUM(C54:C57) -> 130 | T21: =SUM(D54:D57) -> 34 | U21: =SUM(E54:E57) -> 11 | V21: =SUM(F54:F57) -> 31 | W21: =SUM(G54:G57) -> 1 | X21: =SUM(H54:H57) -> 0 | Y21: =SUM(I54:I57) -> 14 | Z21: =SUM(J54:J57) -> 3 | ... AF21: =SUM(P54:P57) -> 535
B22: 10.00 - 10.15 | C22: 68 | D22: 17 | E22: 9 | F22: 13 | G22: 0 | H22: 0 | I22: 2 | J22: 0 | K22: 0 | L22: 0 | M22: 115 | N22: 0 | O22: =SUM(C22:L22,N22) -> 109 | P22: =SUM(C22:N22) -> 224 | R22: AM Peak Hr | S22: =MAX(S10:S12) -> 868 | T22: =MAX(T10:T12) -> 124 | U22: =MAX(U10:U12) -> 50 | V22: =MAX(V10:V12) -> 318 | W22: =MAX(W10:W12) -> 3 | X22: =MAX(X10:X12) -> 2 | Y22: =MAX(Y10:Y12) -> 14 | Z22: =MAX(Z10:Z12) -> 11 | ... AF22: =MAX(AF10:AF12) -> 2088
B23: 10.15 - 10.30 | C23: 63 | D23: 11 | E23: 7 | F23: 7 | G23: 1 | H23: 0 | I23: 5 | J23: 0 | K23: 0 | L23: 0 | M23: 96 | N23: 0 | O23: =SUM(C23:L23,N23) -> 94 | P23: =SUM(C23:N23) -> 190 | R23: IP Peak Hr | S23: =MAX(S13:S18) -> 283 | T23: =MAX(T13:T18) -> 51 | U23: =MAX(U13:U18) -> 35 | V23: =MAX(V13:V18) -> 62 | W23: =MAX(W13:W18) -> 1 | X23: =MAX(X13:X18) -> 0 | Y23: =MAX(Y13:Y18) -> 18 | Z23: =MAX(Z13:Z18) -> 3 | ... AF23: =MAX(AF13:AF18) -> 860
B24: 10.30 - 10.45 | C24: 84 | D24: 15 | E24: 6 | F24: 25 | G24: 0 | H24: 0 | I24: 6 | J24: 1 | K24: 0 | L24: 0 | M24: 110 | N24: 0 | O24: =SUM(C24:L24,N24) -> 137 | P24: =SUM(C24:N24) -> 247 | R24: PM Peak Hr | S24: =MAX(S19:S21) -> 197 | T24: =MAX(T19:T21) -> 41 | U24: =MAX(U19:U21) -> 22 | V24: =MAX(V19:V21) -> 50 | W24: =MAX(W19:W21) -> 1 | X24: =MAX(X19:X21) -> 0 | Y24: =MAX(Y19:Y21) -> 19 | Z24: =MAX(Z19:Z21) -> 6 | ... AF24: =MAX(AF19:AF21) -> 722
B25: 10.45 - 11.00 | C25: 68 | D25: 8 | E25: 7 | F25: 17 | G25: 0 | H25: 0 | I25: 4 | J25: 0 | K25: 0 | L25: 0 | M25: 95 | N25: 0 | O25: =SUM(C25:L25,N25) -> 104 | P25: =SUM(C25:N25) -> 199 | R25: AM Period | S25: =SUM(S10:S12) -> 1716 | T25: =SUM(T10:T12) -> 252 | U25: =SUM(U10:U12) -> 130 | V25: =SUM(V10:V12) -> 625 | W25: =SUM(W10:W12) -> 3 | X25: =SUM(X10:X12) -> 2 | Y25: =SUM(Y10:Y12) -> 35 | Z25: =SUM(Z10:Z12) -> 15 | ... AF25: =SUM(AF10:AF12) -> 4883
B26: 11.00 - 11.15 | C26: 76 | D26: 15 | E26: 11 | F26: 9 | G26: 0 | H26: 0 | I26: 5 | J26: 0 | K26: 0 | L26: 0 | M26: 100 | N26: 0 | O26: =SUM(C26:L26,N26) -> 116 | P26: =SUM(C26:N26) -> 216 | R26: IP Period | S26: =SUM(S13:S18) -> 1136 | T26: =SUM(T13:T18) -> 227 | U26: =SUM(U13:U18) -> 168 | V26: =SUM(V13:V18) -> 242 | W26: =SUM(W13:W18) -> 5 | X26: =SUM(X13:X18) -> 0 | Y26: =SUM(Y13:Y18) -> 85 | Z26: =SUM(Z13:Z18) -> 9 | ... AF26: =SUM(AF13:AF18) -> 3794
B27: 11.15 - 11.30 | C27: 35 | D27: 6 | E27: 9 | F27: 12 | G27: 0 | H27: 0 | I27: 4 | J27: 0 | K27: 0 | L27: 0 | M27: 61 | N27: 0 | O27: =SUM(C27:L27,N27) -> 66 | P27: =SUM(C27:N27) -> 127 | R27: PM Period | S27: =SUM(S19:S21) -> 502 | T27: =SUM(T19:T21) -> 107 | U27: =SUM(U19:U21) -> 53 | V27: =SUM(V19:V21) -> 107 | W27: =SUM(W19:W21) -> 3 | X27: =SUM(X19:X21) -> 0 | Y27: =SUM(Y19:Y21) -> 47 | Z27: =SUM(Z19:Z21) -> 10 | ... AF27: =SUM(AF19:AF21) -> 1959
