Workbook

Sheet 23.09.19 Gaba -Munyonyo
B1: Consultancy services for Preparation of Expressway Development Master Plan (EDMP) for Uganda
B2: MANUAL CLASSIFIED COUNT (MCC)
B3: ROAD NAME: | C3: MCC-C2-STNO 52-Wavamuno RD
C5: Date | D5: 23.09.19 | F5: Location | G5: Wavamuno | J5: Surveyor | K5: Andrew
C6: Dir. From | D6: GABA | F6: Dir. To | G6: MUNYONYO | J6: Supervisor | K6: Steven
B8: Time / Veh Type | R8: SUMMARY TRAFFIC VOLUMES
C9: 1. Car | D9: 2. Station Wagon | E9: 3. Pickups | F9: 4. Minibus, matatu | G9: 5. Medium bus | H9: 6. Large Bus | I9: 7. Light Truck | J9: 8. Medium Truck | K9: 9. Heavy truck | L9: 10. Truck Trailer | M9: 11. Motor cycles | N9: 12. Tractors | O9: Total Excl M/Cycles | P9: Total All | R9: Time | S9: 1. Car | T9: 2. Station Wagon | U9: 3. Pickups | V9: 4. Minibus, matatu | W9: 5. Medium bus | X9: 6. Large Bus | Y9: 7. Light Truck | Z9: 8. Medium Truck | AA9: 9. Heavy truck | AB9: 10. Truck Trailer | AC9: 11. Motorcycles | AD9: 12. Tractors, Graders | AE9: Total Excl M/ Cycles | AF9: Total All
B10: 07.00 - 07.15 | C10: 15 | D10: 1 | E10: 0 | F10: 10 | G10: 0 | H10: 0 | I10: 0 | J10: 0 | K10: 0 | L10: 0 | M10: 28 | N10: 0 | O10: =SUM(C10:L10,N10) -> 26 | P10: =SUM(C10:N10) -> 54 | R10: 0700-0800 | S10: =SUM(C10:C13) -> 126 | T10: =SUM(D10:D13) -> 36 | U10: =SUM(E10:E13) -> 14 | V10: =SUM(F10:F13) -> 57 | W10: =SUM(G10:G13) -> 2 | X10: =SUM(H10:H13) -> 0 | Y10: =SUM(I10:I13) -> 4 | Z10: =SUM(J10:J13) -> 5 | ... AF10: =SUM(P10:P13) -> 410
B11: 07.15 - 07.30 | C11: 35 | D11: 8 | E11: 1 | F11: 15 | G11: 1 | H11: 0 | I11: 1 | J11: 3 | K11: 1 | L11: 0 | M11: 36 | N11: 0 | O11: =SUM(C11:L11,N11) -> 65 | P11: =SUM(C11:N11) -> 101 | R11: 0800-0900 | S11: =SUM(C14:C17) -> 125 | T11: =SUM(D14:D17) -> 59 | U11: =SUM(E14:E17) -> 31 | V11: =SUM(F14:F17) -> 91 | W11: =SUM(G14:G17) -> 6 | X11: =SUM(H14:H17) -> 1 | Y11: =SUM(I14:I17) -> 8 | Z11: =SUM(J14:J17) -> 6 | ... AF11: =SUM(P14:P17) -> 501
B12: 07.30 - 07.45 | C12: 35 | D12: 16 | E12: 4 | F12: 19 | G12: 1 | H12: 0 | I12: 1 | J12: 0 | K12: 0 | L12: 0 | M12: 45 | N12: 0 | O12: =SUM(C12:L12,N12) -> 76 | P12: =SUM(C12:N12) -> 121 | R12: 0900-1000 | S12: =SUM(C18:C21) -> 94 | T12: =SUM(D18:D21) -> 38 | U12: =SUM(E18:E21) -> 30 | V12: =SUM(F18:F21) -> 42 | W12: =SUM(G18:G21) -> 2 | X12: =SUM(H18:H21) -> 0 | Y12: =SUM(I18:I21) -> 12 | Z12: =SUM(J18:J21) -> 11 | ... AF12: =SUM(P18:P21) -> 383
B13: 07.45 - 08.00 | C13: 41 | D13: 11 | E13: 9 | F13: 13 | G13: 0 | H13: 0 | I13: 2 | J13: 2 | K13: 0 | L13: 0 | M13: 56 | N13: 0 | O13: =SUM(C13:L13,N13) -> 78 | P13: =SUM(C13:N13) -> 134 | R13: 1000-1100 | S13: =SUM(C22:C25) -> 101 | T13: =SUM(D22:D25) -> 33 | U13: =SUM(E22:E25) -> 22 | V13: =SUM(F22:F25) -> 44 | W13: =SUM(G22:G25) -> 5 | X13: =SUM(H22:H25) -> 0 | Y13: =SUM(I22:I25) -> 15 | Z13: =SUM(J22:J25) -> 9 | ... AF13: =SUM(P22:P25) -> 428
B14: 08.00 - 08.15 | C14: 34 | D14: 10 | E14: 6 | F14: 23 | G14: 1 | H14: 0 | I14: 2 | J14: 0 | K14: 0 | L14: 0 | M14: 30 | N14: 0 | O14: =SUM(C14:L14,N14) -> 76 | P14: =SUM(C14:N14) -> 106 | R14: 1100-1200 | S14: =SUM(C26:C29) -> 111 | T14: =SUM(D26:D29) -> 42 | U14: =SUM(E26:E29) -> 26 | V14: =SUM(F26:F29) -> 38 | W14: =SUM(G26:G29) -> 4 | X14: =SUM(H26:H29) -> 0 | Y14: =SUM(I26:I29) -> 9 | Z14: =SUM(J26:J29) -> 4 | ... AF14: =SUM(P26:P29) -> 439
B15: 08.15 - 08.30 | C15: 25 | D15: 20 | E15: 7 | F15: 16 | G15: 1 | H15: 0 | I15: 2 | J15: 1 | K15: 0 | L15: 0 | M15: 40 | N15: 0 | O15: =SUM(C15:L15,N15) -> 72 | P15: =SUM(C15:N15) -> 112 | R15: 1200-1300 | S15: =SUM(C30:C33) -> 132 | T15: =SUM(D30:D33) -> 42 | U15: =SUM(E30:E33) -> 33 | V15: =SUM(F30:F33) -> 40 | W15: =SUM(G30:G33) -> 1 | X15: =SUM(H30:H33) -> 0 | Y15: =SUM(I30:I33) -> 10 | Z15: =SUM(J30:J33) -> 6 | ... AF15: =SUM(P30:P33) -> 436
B16: 08.30 - 08.45 | C16: 30 | D16: 12 | E16: 6 | F16: 19 | G16: 0 | H16: 0 | I16: 3 | J16: 3 | K16: 1 | L16: 0 | M16: 55 | N16: 0 | O16: =SUM(C16:L16,N16) -> 74 | P16: =SUM(C16:N16) -> 129 | R16: 1300-1400 | S16: =SUM(C34:C37) -> 145 | T16: =SUM(D34:D37) -> 42 | U16: =SUM(E34:E37) -> 24 | V16: =SUM(F34:F37) -> 46 | W16: =SUM(G34:G37) -> 5 | X16: =SUM(H34:H37) -> 0 | Y16: =SUM(I34:I37) -> 12 | Z16: =SUM(J34:J37) -> 12 | ... AF16: =SUM(P34:P37) -> 475
B17: 08.45 - 9.00 | C17: 36 | D17: 17 | E17: 12 | F17: 33 | G17: 4 | H17: 1 | I17: 1 | J17: 2 | K17: 0 | L17: 0 | M17: 48 | N17: 0 | O17: =SUM(C17:L17,N17) -> 106 | P17: =SUM(C17:N17) -> 154 | R17: 1400-1500 | S17: =SUM(C38:C41) -> 114 | T17: =SUM(D38:D41) -> 40 | U17: =SUM(E38:E41) -> 19 | V17: =SUM(F38:F41) -> 43 | W17: =SUM(G38:G41) -> 1 | X17: =SUM(H38:H41) -> 0 | Y17: =SUM(I38:I41) -> 5 | Z17: =SUM(J38:J41) -> 3 | ... AF17: =SUM(P38:P41) -> 388
B18: 09.00 - 09.15 | C18: 23 | D18: 6 | E18: 5 | F18: 15 | G18: 0 | H18: 0 | I18: 1 | J18: 5 | K18: 0 | L18: 0 | M18: 36 | N18: 0 | O18: =SUM(C18:L18,N18) -> 55 | P18: =SUM(C18:N18) -> 91 | R18: 1500-1600 | S18: =SUM(C42:C45) -> 145 | T18: =SUM(D42:D45) -> 46 | U18: =SUM(E42:E45) -> 23 | V18: =SUM(F42:F45) -> 42 | W18: =SUM(G42:G45) -> 1 | X18: =SUM(H42:H45) -> 0 | Y18: =SUM(I42:I45) -> 11 | Z18: =SUM(J42:J45) -> 4 | ... AF18: =SUM(P42:P45) -> 387
B19: 09.15 - 09.30 | C19: 26 | D19: 10 | E19: 6 | F19: 6 | G19: 0 | H19: 0 | I19: 3 | J19: 5 | K19: 0 | L19: 0 | M19: 39 | N19: 0 | O19: =SUM(C19:L19,N19) -> 56 | P19: =SUM(C19:N19) -> 95 | R19: 1600-1700 | S19: =SUM(C46:C49) -> 152 | T19: =SUM(D46:D49) -> 38 | U19: =SUM(E46:E49) -> 20 | V19: =SUM(F46:F49) -> 82 | W19: =SUM(G46:G49) -> 2 | X19: =SUM(H46:H49) -> 0 | Y19: =SUM(I46:I49) -> 12 | Z19: =SUM(J46:J49) -> 10 | ... AF19: =SUM(P46:P49) -> 455
B20: 09.30 - 09.45 | C20: 24 | D20: 13 | E20: 6 | F20: 13 | G20: 0 | H20: 0 | I20: 5 | J20: 0 | K20: 1 | L20: 0 | M20: 45 | N20: 0 | O20: =SUM(C20:L20,N20) -> 62 | P20: =SUM(C20:N20) -> 107 | R20: 1700-1800 | S20: =SUM(C50:C53) -> 179 | T20: =SUM(D50:D53) -> 59 | U20: =SUM(E50:E53) -> 18 | V20: =SUM(F50:F53) -> 44 | W20: =SUM(G50:G53) -> 1 | X20: =SUM(H50:H53) -> 0 | Y20: =SUM(I50:I53) -> 9 | Z20: =SUM(J50:J53) -> 8 | ... AF20: =SUM(P50:P53) -> 479
B21: 09.45 - 10.00 | C21: 21 | D21: 9 | E21: 13 | F21: 8 | G21: 2 | H21: 0 | I21: 3 | J21: 1 | K21: 0 | L21: 0 | M21: 33 | N21: 0 | O21: =SUM(C21:L21,N21) -> 57 | P21: =SUM(C21:N21) -> 90 | R21: 1800-1900 | S21: =SUM(C54:C57) -> 191 | T21: =SUM(D54:D57) -> 39 | U21: =SUM(E54:E57) -> 21 | V21: =SUM(F54:F57) -> 53 | W21: =SUM(G54:G57) -> 3 | X21: =SUM(H54:H57) -> 0 | Y21: =SUM(I54:I57) -> 4 | Z21: =SUM(J54:J57) -> 11 | ... AF21: =SUM(P54:P57) -> 502
B22: 10.00 - 10.15 | C22: 23 | D22: 4 | E22: 5 | F22: 10 | G22: 0 | H22: 0 | I22: 3 | J22: 2 | K22: 1 | L22: 0 | M22: 43 | N22: 0 | O22: =SUM(C22:L22,N22) -> 48 | P22: =SUM(C22:N22) -> 91 | R22: AM Peak Hr | S22: =MAX(S10:S12) -> 126 | T22: =MAX(T10:T12) -> 59 | U22: =MAX(U10:U12) -> 31 | V22: =MAX(V10:V12) -> 91 | W22: =MAX(W10:W12) -> 6 | X22: =MAX(X10:X12) -> 1 | Y22: =MAX(Y10:Y12) -> 12 | Z22: =MAX(Z10:Z12) -> 11 | ... AF22: =MAX(AF10:AF12) -> 501
B23: 10.15 - 10.30 | C23: 20 | D23: 10 | E23: 6 | F23: 13 | G23: 0 | H23: 0 | I23: 5 | J23: 2 | K23: 0 | L23: 0 | M23: 50 | N23: 0 | O23: =SUM(C23:L23,N23) -> 56 | P23: =SUM(C23:N23) -> 106 | R23: IP Peak Hr | S23: =MAX(S13:S18) -> 145 | T23: =MAX(T13:T18) -> 46 | U23: =MAX(U13:U18) -> 33 | V23: =MAX(V13:V18) -> 46 | W23: =MAX(W13:W18) -> 5 | X23: =MAX(X13:X18) -> 0 | Y23: =MAX(Y13:Y18) -> 15 | Z23: =MAX(Z13:Z18) -> 12 | ... AF23: =MAX(AF13:AF18) -> 475
B24: 10.30 - 10.45 | C24: 25 | D24: 9 | E24: 4 | F24: 10 | G24: 2 | H24: 0 | I24: 5 | J24: 3 | K24: 0 | L24: 0 | M24: 48 | N24: 0 | O24: =SUM(C24:L24,N24) -> 58 | P24: =SUM(C24:N24) -> 106 | R24: PM Peak Hr | S24: =MAX(S19:S21) -> 191 | T24: =MAX(T19:T21) -> 59 | U24: =MAX(U19:U21) -> 21 | V24: =MAX(V19:V21) -> 82 | W24: =MAX(W19:W21) -> 3 | X24: =MAX(X19:X21) -> 0 | Y24: =MAX(Y19:Y21) -> 12 | Z24: =MAX(Z19:Z21) -> 11 | ... AF24: =MAX(AF19:AF21) -> 502
B25: 10.45 - 11.00 | C25: 33 | D25: 10 | E25: 7 | F25: 11 | G25: 3 | H25: 0 | I25: 2 | J25: 2 | K25: 0 | L25: 0 | M25: 57 | N25: 0 | O25: =SUM(C25:L25,N25) -> 68 | P25: =SUM(C25:N25) -> 125 | R25: AM Period | S25: =SUM(S10:S12) -> 345 | T25: =SUM(T10:T12) -> 133 | U25: =SUM(U10:U12) -> 75 | V25: =SUM(V10:V12) -> 190 | W25: =SUM(W10:W12) -> 10 | X25: =SUM(X10:X12) -> 1 | Y25: =SUM(Y10:Y12) -> 24 | Z25: =SUM(Z10:Z12) -> 22 | ... AF25: =SUM(AF10:AF12) -> 1294
B26: 11.00 - 11.15 | C26: 31 | D26: 8 | E26: 8 | F26: 11 | G26: 0 | H26: 0 | I26: 4 | J26: 0 | K26: 1 | L26: 0 | M26: 47 | N26: 0 | O26: =SUM(C26:L26,N26) -> 63 | P26: =SUM(C26:N26) -> 110 | R26: IP Period | S26: =SUM(S13:S18) -> 748 | T26: =SUM(T13:T18) -> 245 | U26: =SUM(U13:U18) -> 147 | V26: =SUM(V13:V18) -> 253 | W26: =SUM(W13:W18) -> 17 | X26: =SUM(X13:X18) -> 0 | Y26: =SUM(Y13:Y18) -> 62 | Z26: =SUM(Z13:Z18) -> 38 | ... AF26: =SUM(AF13:AF18) -> 2553
B27: 11.15 - 11.30 | C27: 24 | D27: 14 | E27: 6 | F27: 12 | G27: 0 | H27: 0 | I27: 2 | J27: 2 | K27: 1 | L27: 0 | M27: 40 | N27: 0 | O27: =SUM(C27:L27,N27) -> 61 | P27: =SUM(C27:N27) -> 101 | R27: PM Period | S27: =SUM(S19:S21) -> 522 | T27: =SUM(T19:T21) -> 136 | U27: =SUM(U19:U21) -> 59 | V27: =SUM(V19:V21) -> 179 | W27: =SUM(W19:W21) -> 6 | X27: =SUM(X19:X21) -> 0 | Y27: =SUM(Y19:Y21) -> 25 | Z27: =SUM(Z19:Z21) -> 29 | ... AF27: =SUM(AF19:AF21) -> 1436
B28: 11.30 - 11.45 | C28: 26 | D28: 10 | E28: 7 | F28: 2 | G28: 1 | H28: 0 | I28: 1 | J28: 2 | K28: 0 | L28: 0 | M28: 51 | N28: 0 | O28: =SUM(C28:L28,N28) -> 49 | P28: =SUM(C28:N28) -> 100 | R28: 12 Hours | S28: =SUM(S10:S21) -> 1615 | T28: =SUM(T10:T21) -> 514 | U28: =SUM(U10:U21) -> 281 | V28: =SUM(V10:V21) -> 622 | W28: =SUM(W10:W21) -> 33 | X28: =SUM(X10:X21) -> 1 | Y28: =SUM(Y10:Y21) -> 111 | Z28: =SUM(Z10:Z21) -> 89 | ... AF28: =SUM(AF10:AF21) -> 5283
B29: 11.45 - 12.00 | C29: 30 | D29: 10 | E29: 5 | F29: 13 | G29: 3 | H29: 0 | I29: 2 | J29: 0 | K29: 1 | L29: 0 | M29: 64 | N29: 0 | O29: =SUM(C29:L29,N29) -> 64 | P29: =SUM(C29:N29) -> 128
B30: 12.00 - 12.15 | C30: 29 | D30: 10 | E30: 11 | F30: 7 | G30: 0 | H30: 0 | I30: 3 | J30: 1 | K30: 0 | L30: 0 | M30: 40 | N30: 0 | O30: =SUM(C30:L30,N30) -> 61 | P30: =SUM(C30:N30) -> 101
B31: 12.15 - 12.30 | C31: 45 | D31: 16 | E31: 9 | F31: 10 | G31: 0 | H31: 0 | I31: 1 | J31: 2 | K31: 1 | L31: 0 | M31: 49 | N31: 0 | O31: =SUM(C31:L31,N31) -> 84 | P31: =SUM(C31:N31) -> 133
B32: 12.30 - 12.45 | C32: 33 | D32: 6 | E32: 8 | F32: 12 | G32: 1 | H32: 0 | I32: 5 | J32: 2 | K32: 0 | L32: 0 | M32: 41 | N32: 0 | O32: =SUM(C32:L32,N32) -> 67 | P32: =SUM(C32:N32) -> 108
B33: 12.45 - 13.00 | C33: 25 | D33: 10 | E33: 5 | F33: 11 | G33: 0 | H33: 0 | I33: 1 | J33: 1 | K33: 1 | L33: 0 | M33: 40 | N33: 0 | O33: =SUM(C33:L33,N33) -> 54 | P33: =SUM(C33:N33) -> 94
B34: 13.00 - 13.15 | C34: 42 | D34: 20 | E34: 4 | F34: 10 | G34: 1 | H34: 0 | I34: 3 | J34: 3 | K34: 0 | L34: 0 | M34: 39 | N34: 0 | O34: =SUM(C34:L34,N34) -> 83 | P34: =SUM(C34:N34) -> 122
B35: 13.15 - 13.30 | C35: 40 | D35: 11 | E35: 5 | F35: 8 | G35: 3 | H35: 0 | I35: 5 | J35: 3 | K35: 0 | L35: 0 | M35: 40 | N35: 0 | O35: =SUM(C35:L35,N35) -> 75 | P35: =SUM(C35:N35) -> 115
B36: 13.30 - 13.45 | C36: 33 | D36: 5 | E36: 8 | F36: 13 | G36: 1 | H36: 0 | I36: 1 | J36: 1 | K36: 0 | L36: 0 | M36: 38 | N36: 0 | O36: =SUM(C36:L36,N36) -> 62 | P36: =SUM(C36:N36) -> 100
B37: 13.45 - 14.00 | C37: 30 | D37: 6 | E37: 7 | F37: 15 | G37: 0 | H37: 0 | I37: 3 | J37: 5 | K37: 0 | L37: 0 | M37: 72 | N37: 0 | O37: =SUM(C37:L37,N37) -> 66 | P37: =SUM(C37:N37) -> 138
B38: 14.00 - 14.15 | C38: 32 | D38: 4 | E38: 6 | F38: 7 | G38: 1 | H38: 0 | I38: 1 | J38: 2 | K38: 0 | L38: 0 | M38: 44 | N38: 0 | O38: =SUM(C38:L38,N38) -> 53 | P38: =SUM(C38:N38) -> 97
B39: 14.15 - 14.30 | C39: 23 | D39: 18 | E39: 6 | F39: 10 | G39: 0 | H39: 0 | I39: 0 | J39: 1 | K39: 1 | L39: 0 | M39: 37 | N39: 3 | O39: =SUM(C39:L39,N39) -> 62 | P39: =SUM(C39:N39) -> 99
B40: 14.30 - 14.45 | C40: 39 | D40: 11 | E40: 3 | F40: 12 | G40: 0 | H40: 0 | I40: 2 | J40: 0 | K40: 0 | L40: 0 | M40: 45 | N40: 0 | O40: =SUM(C40:L40,N40) -> 67 | P40: =SUM(C40:N40) -> 112
... B57: 18.45 - 19.00 | C57: 40 | D57: 5 | E57: 4 | F57: 11 | G57: 0 | H57: 0 | I57: 1 | J57: 1 | K57: 0 | L57: 0 | M57: 41 | N57: 0 | O57: =SUM(C57:L57,N57) -> 62 | P57: =SUM(C57:N57) -> 103
B58: Totals | C58: =SUM(C10:C57) -> 1615 | D58: =SUM(D10:D57) -> 514 | E58: =SUM(E10:E57) -> 281 | F58: =SUM(F10:F57) -> 622 | G58: =SUM(G10:G57) -> 33 | H58: =SUM(H10:H57) -> 1 | I58: =SUM(I10:I57) -> 111 | J58: =SUM(J10:J57) -> 89 | ... P58: =SUM(P10:P57) -> 5283
...

Sheet 23.09.19 Munyonyo -Gaba
B1: Consultancy services for Preparation of Expressway Development Master Plan (EDMP) for Uganda
B2: MANUAL CLASSIFIED COUNT (MCC)
B3: ROAD NAME: | C3: ='23.09.19 Gaba -Munyonyo'!C3:G3 -> MCC-C2-STNO 52-Wavamuno RD
C5: Date | D5: ='23.09.19 Gaba -Munyonyo'!D5 -> 23.09.19 | F5: Location | G5: ='23.09.19 Gaba -Munyonyo'!G5:H5 -> Wavamuno | J5: Surveyor | K5: Amanda Emmanuel
C6: Dir. From | D6: MUNYONYO | F6: Dir. To | G6: GABA | J6: Supervisor | K6: ='23.09.19 Gaba -Munyonyo'!K6:L6 -> Steven
B8: Time / Veh Type | R8: SUMMARY TRAFFIC VOLUMES
C9: 1. Car | D9: 2. Station Wagon | E9: 3. Pickups | F9: 4. Minibus, matatu | G9: 5. Medium bus | H9: 6. Large Bus | I9: 7. Light Truck | J9: 8. Medium Truck | K9: 9. Heavy truck | L9: 10. Truck Trailer | M9: 11. Motor cycles | N9: 12. Tractors | O9: Total Excl M/Cycles | P9: Total All | R9: Time | S9: 1. Car | T9: 2. Station Wagon | U9: 3. Pickups | V9: 4. Minibus, matatu | W9: 5. Medium bus | X9: 6. Large Bus | Y9: 7. Light Truck | Z9: 8. Medium Truck | AA9: 9. Heavy truck | AB9: 10. Truck Trailer | AC9: 11. Motorcycles | AD9: 12. Tractors, Graders | AE9: Total Excl M/ Cycles | AF9: Total All
B10: 07.00 - 07.15 | C10: 13 | D10: 10 | E10: 16 | F10: 28 | G10: 0 | H10: 0 | I10: 3 | J10: 0 | K10: 0 | L10: 0 | M10: 21 | N10: 0 | O10: =SUM(C10:L10,N10) -> 70 | P10: =SUM(C10:N10) -> 91 | R10: 0700-0800 | S10: =SUM(C10:C13) -> 47 | T10: =SUM(D10:D13) -> 75 | U10: =SUM(E10:E13) -> 36 | V10: =SUM(F10:F13) -> 75 | W10: =SUM(G10:G13) -> 2 | X10: =SUM(H10:H13) -> 0 | Y10: =SUM(I10:I13) -> 5 | Z10: =SUM(J10:J13) -> 3 | ... AF10: =SUM(P10:P13) -> 370
B11: 07.15 - 07.30 | C11: 11 | D11: 18 | E11: 10 | F11: 23 | G11: 1 | H11: 0 | I11: 1 | J11: 2 | K11: 0 | L11: 0 | M11: 31 | N11: 0 | O11: =SUM(C11:L11,N11) -> 66 | P11: =SUM(C11:N11) -> 97 | R11: 0800-0900 | S11: =SUM(C14:C17) -> 91 | T11: =SUM(D14:D17) -> 78 | U11: =SUM(E14:E17) -> 18 | V11: =SUM(F14:F17) -> 49 | W11: =SUM(G14:G17) -> 1 | X11: =SUM(H14:H17) -> 0 | Y11: =SUM(I14:I17) -> 14 | Z11: =SUM(J14:J17) -> 3 | ... AF11: =SUM(P14:P17) -> 371
B12: 07.30 - 07.45 | C12: 10 | D12: 26 | E12: 7 | F12: 10 | G12: 1 | H12: 0 | I12: 1 | J12: 1 | K12: 0 | L12: 0 | M12: 42 | N12: 0 | O12: =SUM(C12:L12,N12) -> 56 | P12: =SUM(C12:N12) -> 98 | R12: 0900-1000 | S12: =SUM(C18:C21) -> 113 | T12: =SUM(D18:D21) -> 74 | U12: =SUM(E18:E21) -> 31 | V12: =SUM(F18:F21) -> 49 | W12: =SUM(G18:G21) -> 1 | X12: =SUM(H18:H21) -> 0 | Y12: =SUM(I18:I21) -> 11 | Z12: =SUM(J18:J21) -> 4 | ... AF12: =SUM(P18:P21) -> 408
B13: 07.45 - 08.00 | C13: 13 | D13: 21 | E13: 3 | F13: 14 | G13: 0 | H13: 0 | I13: 0 | J13: 0 | K13: 0 | L13: 0 | M13: 33 | N13: 0 | O13: =SUM(C13:L13,N13) -> 51 | P13: =SUM(C13:N13) -> 84 | R13: 1000-1100 | S13: =SUM(C22:C25) -> 84 | T13: =SUM(D22:D25) -> 96 | U13: =SUM(E22:E25) -> 37 | V13: =SUM(F22:F25) -> 72 | W13: =SUM(G22:G25) -> 0 | X13: =SUM(H22:H25) -> 0 | Y13: =SUM(I22:I25) -> 7 | Z13: =SUM(J22:J25) -> 2 | ... AF13: =SUM(P22:P25) -> 442
B14: 08.00 - 08.15 | C14: 21 | D14: 15 | E14: 3 | F14: 11 | G14: 0 | H14: 0 | I14: 2 | J14: 1 | K14: 0 | L14: 0 | M14: 24 | N14: 0 | O14: =SUM(C14:L14,N14) -> 53 | P14: =SUM(C14:N14) -> 77 | R14: 1100-1200 | S14: =SUM(C26:C29) -> 81 | T14: =SUM(D26:D29) -> 88 | U14: =SUM(E26:E29) -> 38 | V14: =SUM(F26:F29) -> 82 | W14: =SUM(G26:G29) -> 0 | X14: =SUM(H26:H29) -> 0 | Y14: =SUM(I26:I29) -> 6 | Z14: =SUM(J26:J29) -> 3 | ... AF14: =SUM(P26:P29) -> 444
B15: 08.15 - 08.30 | C15: 22 | D15: 27 | E15: 11 | F15: 11 | G15: 0 | H15: 0 | I15: 5 | J15: 1 | K15: 0 | L15: 0 | M15: 26 | N15: 0 | O15: =SUM(C15:L15,N15) -> 77 | P15: =SUM(C15:N15) -> 103 | R15: 1200-1300 | S15: =SUM(C30:C33) -> 70 | T15: =SUM(D30:D33) -> 54 | U15: =SUM(E30:E33) -> 15 | V15: =SUM(F30:F33) -> 77 | W15: =SUM(G30:G33) -> 7 | X15: =SUM(H30:H33) -> 0 | Y15: =SUM(I30:I33) -> 10 | Z15: =SUM(J30:J33) -> 4 | ... AF15: =SUM(P30:P33) -> 425
B16: 08.30 - 08.45 | C16: 26 | D16: 19 | E16: 2 | F16: 15 | G16: 0 | H16: 0 | I16: 3 | J16: 0 | K16: 0 | L16: 0 | M16: 32 | N16: 0 | O16: =SUM(C16:L16,N16) -> 65 | P16: =SUM(C16:N16) -> 97 | R16: 1300-1400 | S16: =SUM(C34:C37) -> 43 | T16: =SUM(D34:D37) -> 54 | U16: =SUM(E34:E37) -> 35 | V16: =SUM(F34:F37) -> 119 | W16: =SUM(G34:G37) -> 2 | X16: =SUM(H34:H37) -> 0 | Y16: =SUM(I34:I37) -> 5 | Z16: =SUM(J34:J37) -> 5 | ... AF16: =SUM(P34:P37) -> 375
B17: 08.45 - 9.00 | C17: 22 | D17: 17 | E17: 2 | F17: 12 | G17: 1 | H17: 0 | I17: 4 | J17: 1 | K17: 0 | L17: 0 | M17: 35 | N17: 0 | O17: =SUM(C17:L17,N17) -> 59 | P17: =SUM(C17:N17) -> 94 | R17: 1400-1500 | S17: =SUM(C38:C41) -> 64 | T17: =SUM(D38:D41) -> 45 | U17: =SUM(E38:E41) -> 17 | V17: =SUM(F38:F41) -> 60 | W17: =SUM(G38:G41) -> 0 | X17: =SUM(H38:H41) -> 0 | Y17: =SUM(I38:I41) -> 8 | Z17: =SUM(J38:J41) -> 3 | ... AF17: =SUM(P38:P41) -> 306
B18: 09.00 - 09.15 | C18: 22 | D18: 18 | E18: 3 | F18: 8 | G18: 1 | H18: 0 | I18: 2 | J18: 0 | K18: 0 | L18: 0 | M18: 28 | N18: 0 | O18: =SUM(C18:L18,N18) -> 54 | P18: =SUM(C18:N18) -> 82 | R18: 1500-1600 | S18: =SUM(C42:C45) -> 71 | T18: =SUM(D42:D45) -> 41 | U18: =SUM(E42:E45) -> 25 | V18: =SUM(F42:F45) -> 69 | W18: =SUM(G42:G45) -> 0 | X18: =SUM(H42:H45) -> 1 | Y18: =SUM(I42:I45) -> 12 | Z18: =SUM(J42:J45) -> 8 | ... AF18: =SUM(P42:P45) -> 331
B19: 09.15 - 09.30 | C19: 33 | D19: 18 | E19: 0 | F19: 12 | G19: 0 | H19: 0 | I19: 1 | J19: 0 | K19: 0 | L19: 0 | M19: 30 | N19: 0 | O19: =SUM(C19:L19,N19) -> 64 | P19: =SUM(C19:N19) -> 94 | R19: 1600-1700 | S19: =SUM(C46:C49) -> 49 | T19: =SUM(D46:D49) -> 67 | U19: =SUM(E46:E49) -> 24 | V19: =SUM(F46:F49) -> 69 | W19: =SUM(G46:G49) -> 0 | X19: =SUM(H46:H49) -> 0 | Y19: =SUM(I46:I49) -> 12 | Z19: =SUM(J46:J49) -> 4 | ... AF19: =SUM(P46:P49) -> 340
B20: 09.30 - 09.45 | C20: 36 | D20: 22 | E20: 6 | F20: 10 | G20: 0 | H20: 0 | I20: 2 | J20: 1 | K20: 0 | L20: 0 | M20: 42 | N20: 0 | O20: =SUM(C20:L20,N20) -> 77 | P20: =SUM(C20:N20) -> 119 | R20: 1700-1800 | S20: =SUM(C50:C53) -> 47 | T20: =SUM(D50:D53) -> 61 | U20: =SUM(E50:E53) -> 41 | V20: =SUM(F50:F53) -> 71 | W20: =SUM(G50:G53) -> 0 | X20: =SUM(H50:H53) -> 0 | Y20: =SUM(I50:I53) -> 8 | Z20: =SUM(J50:J53) -> 2 | ... AF20: =SUM(P50:P53) -> 332
B21: 09.45 - 10.00 | C21: 22 | D21: 16 | E21: 22 | F21: 19 | G21: 0 | H21: 0 | I21: 6 | J21: 3 | K21: 0 | L21: 0 | M21: 25 | N21: 0 | O21: =SUM(C21:L21,N21) -> 88 | P21: =SUM(C21:N21) -> 113 | R21: 1800-1900 | S21: =SUM(C54:C57) -> 43 | T21: =SUM(D54:D57) -> 49 | U21: =SUM(E54:E57) -> 16 | V21: =SUM(F54:F57) -> 66 | W21: =SUM(G54:G57) -> 4 | X21: =SUM(H54:H57) -> 2 | Y21: =SUM(I54:I57) -> 10 | Z21: =SUM(J54:J57) -> 3 | ... AF21: =SUM(P54:P57) -> 284
B22: 10.00 - 10.15 | C22: 23 | D22: 23 | E22: 7 | F22: 20 | G22: 0 | H22: 0 | I22: 2 | J22: 0 | K22: 0 | L22: 0 | M22: 27 | N22: 0 | O22: =SUM(C22:L22,N22) -> 75 | P22: =SUM(C22:N22) -> 102 | R22: AM Peak Hr | S22: =MAX(S10:S12) -> 113 | T22: =MAX(T10:T12) -> 78 | U22: =MAX(U10:U12) -> 36 | V22: =MAX(V10:V12) -> 75 | W22: =MAX(W10:W12) -> 2 | X22: =MAX(X10:X12) -> 0 | Y22: =MAX(Y10:Y12) -> 14 | Z22: =MAX(Z10:Z12) -> 4 | ... AF22: =MAX(AF10:AF12) -> 408
B23: 10.15 - 10.30 | C23: 16 | D23: 17 | E23: 11 | F23: 11 | G23: 0 | H23: 0 | I23: 2 | J23: 0 | K23: 0 | L23: 0 | M23: 31 | N23: 0 | O23: =SUM(C23:L23,N23) -> 57 | P23: =SUM(C23:N23) -> 88 | R23: IP Peak Hr | S23: =MAX(S13:S18) -> 84 | T23: =MAX(T13:T18) -> 96 | U23: =MAX(U13:U18) -> 38 | V23: =MAX(V13:V18) -> 119 | W23: =MAX(W13:W18) -> 7 | X23: =MAX(X13:X18) -> 1 | Y23: =MAX(Y13:Y18) -> 12 | Z23: =MAX(Z13:Z18) -> 8 | ... AF23: =MAX(AF13:AF18) -> 444
B24: 10.30 - 10.45 | C24: 21 | D24: 27 | E24: 9 | F24: 16 | G24: 0 | H24: 0 | I24: 1 | J24: 1 | K24: 1 | L24: 0 | M24: 34 | N24: 0 | O24: =SUM(C24:L24,N24) -> 76 | P24: =SUM(C24:N24) -> 110 | R24: PM Peak Hr | S24: =MAX(S19:S21) -> 49 | T24: =MAX(T19:T21) -> 67 | U24: =MAX(U19:U21) -> 41 | V24: =MAX(V19:V21) -> 71 | W24: =MAX(W19:W21) -> 4 | X24: =MAX(X19:X21) -> 2 | Y24: =MAX(Y19:Y21) -> 12 | Z24: =MAX(Z19:Z21) -> 4 | ... AF24: =MAX(AF19:AF21) -> 340
B25: 10.45 - 11.00 | C25: 24 | D25: 29 | E25: 10 | F25: 25 | G25: 0 | H25: 0 | I25: 2 | J25: 1 | K25: 0 | L25: 0 | M25: 51 | N25: 0 | O25: =SUM(C25:L25,N25) -> 91 | P25: =SUM(C25:N25) -> 142 | R25: AM Period | S25: =SUM(S10:S12) -> 251 | T25: =SUM(T10:T12) -> 227 | U25: =SUM(U10:U12) -> 85 | V25: =SUM(V10:V12) -> 173 | W25: =SUM(W10:W12) -> 4 | X25: =SUM(X10:X12) -> 0 | Y25: =SUM(Y10:Y12) -> 30 | Z25: =SUM(Z10:Z12) -> 10 | ... AF25: =SUM(AF10:AF12) -> 1149
B26: 11.00 - 11.15 | C26: 16 | D26: 27 | E26: 8 | F26: 21 | G26: 0 | H26: 0 | I26: 0 | J26: 0 | K26: 0 | L26: 0 | M26: 25 | N26: 0 | O26: =SUM(C26:L26,N26) -> 72 | P26: =SUM(C26:N26) -> 97 | R26: IP Period | S26: =SUM(S13:S18) -> 413 | T26: =SUM(T13:T18) -> 378 | U26: =SUM(U13:U18) -> 167 | V26: =SUM(V13:V18) -> 479 | W26: =SUM(W13:W18) -> 9 | X26: =SUM(X13:X18) -> 1 | Y26: =SUM(Y13:Y18) -> 48 | Z26: =SUM(Z13:Z18) -> 25 | ... AF26: =SUM(AF13:AF18) -> 2323
B27: 11.15 - 11.30 | C27: 19 | D27: 14 | E27: 11 | F27: 22 | G27: 0 | H27: 0 | I27: 2 | J27: 1 | K27: 0 | L27: 0 | M27: 41 | N27: 0 | O27: =SUM(C27:L27,N27) -> 69 | P27: =SUM(C27:N27) -> 110 | R27: PM Period | S27: =SUM(S19:S21) -> 139 | T27: =SUM(T19:T21) -> 177 | U27: =SUM(U19:U21) -> 81 | V27: =SUM(V19:V21) -> 206 | W27: =SUM(W19:W21) -> 4 | X27: =SUM(X19:X21) -> 2 | Y27: =SUM(Y19:Y21) -> 30 | Z27: =SUM(Z19:Z21) -> 9 | ... AF27: =SUM(AF19:AF21) -> 956
B28: 11.30 - 11.45 | C28: 25 | D28: 27 | E28: 7 | F28: 16 | G28: 0 | H28: 0 | I28: 1 | J28: 1 | K28: 0 | L28: 1 | M28: 36 | N28: 0 | O28: =SUM(C28:L28,N28) -> 78 | P28: =SUM(C28:N28) -> 114 | R28: 12 Hours | S28: =SUM(S10:S21) -> 803 | T28: =SUM(T10:T21) -> 782 | U28: =SUM(U10:U21) -> 333 | V28: =SUM(V10:V21) -> 858 | W28: =SUM(W10:W21) -> 17 | X28: =SUM(X10:X21) -> 3 | Y28: =SUM(Y10:Y21) -> 108 | Z28: =SUM(Z10:Z21) -> 44 | ... AF28: =SUM(AF10:AF21) -> 4428
B29: 11.45 - 12.00 | C29: 21 | D29: 20 | E29: 12 | F29: 23 | G29: 0 | H29: 0 | I29: 3 | J29: 1 | K29: 0 | L29: 0 | M29: 43 | N29: 0 | O29: =SUM(C29:L29,N29) -> 80 | P29: =SUM(C29:N29) -> 123
B30: 12.00 - 12.15 | C30: 18 | D30: 18 | E30: 5 | F30: 31 | G30: 7 | H30: 0 | I30: 6 | J30: 0 | K30: 0 | L30: 0 | M30: 49 | N30: 0 | O30: =SUM(C30:L30,N30) -> 85 | P30: =SUM(C30:N30) -> 134
B31: 12.15 - 12.30 | C31: 21 | D31: 11 | E31: 3 | F31: 15 | G31: 0 | H31: 0 | I31: 1 | J31: 0 | K31: 0 | L31: 0 | M31: 58 | N31: 0 | O31: =SUM(C31:L31,N31) -> 51 | P31: =SUM(C31:N31) -> 109
B32: 12.30 - 12.45 | C32: 17 | D32: 15 | E32: 2 | F32: 9 | G32: 0 | H32: 0 | I32: 2 | J32: 1 | K32: 0 | L32: 0 | M32: 52 | N32: 0 | O32: =SUM(C32:L32,N32) -> 46 | P32: =SUM(C32:N32) -> 98
B33: 12.45 - 13.00 | C33: 14 | D33: 10 | E33: 5 | F33: 22 | G33: 0 | H33: 0 | I33: 1 | J33: 3 | K33: 0 | L33: 0 | M33: 29 | N33: 0 | O33: =SUM(C33:L33,N33) -> 55 | P33: =SUM(C33:N33) -> 84
B34: 13.00 - 13.15 | C34: 8 | D34: 12 | E34: 7 | F34: 23 | G34: 2 | H34: 0 | I34: 0 | J34: 1 | K34: 0 | L34: 0 | M34: 24 | N34: 0 | O34: =SUM(C34:L34,N34) -> 53 | P34: =SUM(C34:N34) -> 77
B35: 13.15 - 13.30 | C35: 9 | D35: 11 | E35: 10 | F35: 26 | G35: 0 | H35: 0 | I35: 2 | J35: 0 | K35: 2 | L35: 0 | M35: 32 | N35: 0 | O35: =SUM(C35:L35,N35) -> 60 | P35: =SUM(C35:N35) -> 92
B36: 13.30 - 13.45 | C36: 16 | D36: 16 | E36: 8 | F36: 37 | G36: 0 | H36: 0 | I36: 2 | J36: 4 | K36: 0 | L36: 0 | M36: 21 | N36: 0 | O36: =SUM(C36:L36,N36) -> 83 | P36: =SUM(C36:N36) -> 104
B37: 13.45 - 14.00 | C37: 10 | D37: 15 | E37: 10 | F37: 33 | G37: 0 | H37: 0 | I37: 1 | J37: 0 | K37: 0 | L37: 0 | M37: 33 | N37: 0 | O37: =SUM(C37:L37,N37) -> 69 | P37: =SUM(C37:N37) -> 102
B38: 14.00 - 14.15 | C38: 24 | D38: 11 | E38: 8 | F38: 14 | G38: 0 | H38: 0 | I38: 2 | J38: 2 | K38: 0 | L38: 0 | M38: 31 | N38: 0 | O38: =SUM(C38:L38,N38) -> 61 | P38: =SUM(C38:N38) -> 92
B39: 14.15 - 14.30 | C39: 16 | D39: 18 | E39: 3 | F39: 10 | G39: 0 | H39: 0 | I39: 5 | J39: 0 | K39: 0 | L39: 0 | M39: 37 | N39: 0 | O39: =SUM(C39:L39,N39) -> 52 | P39: =SUM(C39:N39) -> 89
B40: 14.30 - 14.45 | C40: 14 | D40: 10 | E40: 6 | F40: 21 | G40: 0 | H40: 0 | I40: 0 | J40: 0 | K40: 0 | L40: 0 | M40: 24 | N40: 0 | O40: =SUM(C40:L40,N40) -> 51 | P40: =SUM(C40:N40) -> 75
... B57: 18.45 - 19.00 | C57: 10 | D57: 10 | E57: 7 | F57: 11 | G57: 0 | H57: 2 | I57: 2 | J57: 1 | K57: 0 | L57: 0 | M57: 19 | N57: 0 | O57: =SUM(C57:L57,N57) -> 43 | P57: =SUM(C57:N57) -> 62
B58: Totals | C58: =SUM(C10:C57) -> 803 | D58: =SUM(D10:D57) -> 782 | E58: =SUM(E10:E57) -> 333 | F58: =SUM(F10:F57) -> 858 | G58: =SUM(G10:G57) -> 17 | H58: =SUM(H10:H57) -> 3 | I58: =SUM(I10:I57) -> 108 | J58: =SUM(J10:J57) -> 44 | ... P58: =SUM(P10:P57) -> 4428
...

Sheet 24.09 Gaba-Munyonyo
B1: Consultancy services for Preparation of Expressway Development Master Plan (EDMP) for Uganda
B2: MANUAL CLASSIFIED COUNT (MCC)
B3: ROAD NAME: | C3: MCC-C2-STN52-WAVAMUNNO
C5: Date | D5: 24.09.19 | F5: Location | G5: FUSION AUTO SPA | J5: Surveyor | K5: ANDREW
C6: Dir. From | D6: GGABA ROAD | F6: Dir. To | G6: MUNYONYO | J6: Supervisor | K6: STEVEN
B8: Time / Veh Type | R8: SUMMARY TRAFFIC VOLUMES
C9: 1. Car | D9: 2. Station Wagon | E9: 3. Pickups | F9: 4. Minibus, matatu | G9: 5. Medium bus | H9: 6. Large Bus | I9: 7. Light Truck | J9: 8. Medium Truck | K9: 9. Heavy truck | L9: 10. Truck Trailer | M9: 11. Motor cycles | N9: 12. Tractors | O9: Total Excl M/Cycles | P9: Total All | R9: Time | S9: 1. Car | T9: 2. Station Wagon | U9: 3. Pickups | V9: 4. Minibus, matatu | W9: 5. Medium bus | X9: 6. Large Bus | Y9: 7. Light Truck | Z9: 8. Medium Truck | AA9: 9. Heavy truck | AB9: 10. Truck Trailer | AC9: 11. Motorcycles | AD9: 12. Tractors, Graders | AE9: Total Excl M/ Cycles | AF9: Total All
B10: 07.00 - 07.15 | C10: 35 | D10: 6 | E10: 3 | F10: 14 | G10: 1 | H10: 0 | I10: 1 | J10: 1 | K10: 0 | L10: 0 | M10: 28 | N10: 0 | O10: =SUM(C10:L10,N10) -> 61 | P10: =SUM(C10:N10) -> 89 | R10: 0700-0800 | S10: =SUM(C10:C13) -> 135 | T10: =SUM(D10:D13) -> 44 | U10: =SUM(E10:E13) -> 14 | V10: =SUM(F10:F13) -> 59 | W10: =SUM(G10:G13) -> 3 | X10: =SUM(H10:H13) -> 1 | Y10: =SUM(I10:I13) -> 5 | Z10: =SUM(J10:J13) -> 7 | ... AF10: =SUM(P10:P13) -> 394
B11: 07.15 - 07.30 | C11: 21 | D11: 8 | E11: 5 | F11: 15 | G11: 0 | H11: 0 | I11: 2 | J11: 2 | K11: 0 | L11: 0 | M11: 31 | N11: 0 | O11: =SUM(C11:L11,N11) -> 53 | P11: =SUM(C11:N11) -> 84 | R11: 0800-0900 | S11: =SUM(C14:C17) -> 132 | T11: =SUM(D14:D17) -> 46 | U11: =SUM(E14:E17) -> 25 | V11: =SUM(F14:F17) -> 71 | W11: =SUM(G14:G17) -> 5 | X11: =SUM(H14:H17) -> 0 | Y11: =SUM(I14:I17) -> 5 | Z11: =SUM(J14:J17) -> 6 | ... AF11: =SUM(P14:P17) -> 479
B12: 07.30 - 07.45 | C12: 38 | D12: 18 | E12: 2 | F12: 19 | G12: 1 | H12: 0 | I12: 0 | J12: 3 | K12: 0 | L12: 0 | M12: 20 | N12: 0 | O12: =SUM(C12:L12,N12) -> 81 | P12: =SUM(C12:N12) -> 101 | R12: 0900-1000 | S12: =SUM(C18:C21) -> 106 | T12: =SUM(D18:D21) -> 35 | U12: =SUM(E18:E21) -> 26 | V12: =SUM(F18:F21) -> 51 | W12: =SUM(G18:G21) -> 7 | X12: =SUM(H18:H21) -> 0 | Y12: =SUM(I18:I21) -> 16 | Z12: =SUM(J18:J21) -> 4 | ... AF12: =SUM(P18:P21) -> 422
B13: 07.45 - 08.00 | C13: 41 | D13: 12 | E13: 4 | F13: 11 | G13: 1 | H13: 1 | I13: 2 | J13: 1 | K13: 0 | L13: 0 | M13: 47 | N13: 0 | O13: =SUM(C13:L13,N13) -> 73 | P13: =SUM(C13:N13) -> 120 | R13: 1000-1100 | S13: =SUM(C22:C25) -> 133 | T13: =SUM(D22:D25) -> 32 | U13: =SUM(E22:E25) -> 26 | V13: =SUM(F22:F25) -> 46 | W13: =SUM(G22:G25) -> 5 | X13: =SUM(H22:H25) -> 0 | Y13: =SUM(I22:I25) -> 12 | Z13: =SUM(J22:J25) -> 4 | ... AF13: =SUM(P22:P25) -> 424
B14: 08.00 - 08.15 | C14: 43 | D14: 11 | E14: 7 | F14: 21 | G14: 1 | H14: 0 | I14: 0 | J14: 1 | K14: 0 | L14: 0 | M14: 52 | N14: 0 | O14: =SUM(C14:L14,N14) -> 84 | P14: =SUM(C14:N14) -> 136 | R14: 1100-1200 | S14: =SUM(C26:C29) -> 110 | T14: =SUM(D26:D29) -> 44 | U14: =SUM(E26:E29) -> 26 | V14: =SUM(F26:F29) -> 43 | W14: =SUM(G26:G29) -> 1 | X14: =SUM(H26:H29) -> 0 | Y14: =SUM(I26:I29) -> 9 | Z14: =SUM(J26:J29) -> 9 | ... AF14: =SUM(P26:P29) -> 412
B15: 08.15 - 08.30 | C15: 28 | D15: 9 | E15: 5 | F15: 20 | G15: 1 | H15: 0 | I15: 2 | J15: 1 | K15: 0 | L15: 0 | M15: 46 | N15: 0 | O15: =SUM(C15:L15,N15) -> 66 | P15: =SUM(C15:N15) -> 112 | R15: 1200-1300 | S15: =SUM(C30:C33) -> 134 | T15: =SUM(D30:D33) -> 36 | U15: =SUM(E30:E33) -> 20 | V15: =SUM(F30:F33) -> 38 | W15: =SUM(G30:G33) -> 2 | X15: =SUM(H30:H33) -> 1 | Y15: =SUM(I30:I33) -> 12 | Z15: =SUM(J30:J33) -> 5 | ... AF15: =SUM(P30:P33) -> 422
B16: 08.30 - 08.45 | C16: 31 | D16: 15 | E16: 10 | F16: 12 | G16: 2 | H16: 0 | I16: 2 | J16: 1 | K16: 0 | L16: 0 | M16: 48 | N16: 0 | O16: =SUM(C16:L16,N16) -> 73 | P16: =SUM(C16:N16) -> 121 | R16: 1300-1400 | S16: =SUM(C34:C37) -> 140 | T16: =SUM(D34:D37) -> 43 | U16: =SUM(E34:E37) -> 21 | V16: =SUM(F34:F37) -> 33 | W16: =SUM(G34:G37) -> 1 | X16: =SUM(H34:H37) -> 2 | Y16: =SUM(I34:I37) -> 7 | Z16: =SUM(J34:J37) -> 8 | ... AF16: =SUM(P34:P37) -> 409
B17: 08.45 - 9.00 | C17: 30 | D17: 11 | E17: 3 | F17: 18 | G17: 1 | H17: 0 | I17: 1 | J17: 3 | K17: 0 | L17: 0 | M17: 43 | N17: 0 | O17: =SUM(C17:L17,N17) -> 67 | P17: =SUM(C17:N17) -> 110 | R17: 1400-1500 | S17: =SUM(C38:C41) -> 120 | T17: =SUM(D38:D41) -> 34 | U17: =SUM(E38:E41) -> 25 | V17: =SUM(F38:F41) -> 33 | W17: =SUM(G38:G41) -> 2 | X17: =SUM(H38:H41) -> 0 | Y17: =SUM(I38:I41) -> 8 | Z17: =SUM(J38:J41) -> 8 | ... AF17: =SUM(P38:P41) -> 367
B18: 09.00 - 09.15 | C18: 25 | D18: 13 | E18: 5 | F18: 23 | G18: 1 | H18: 0 | I18: 5 | J18: 1 | K18: 0 | L18: 0 | M18: 53 | N18: 0 | O18: =SUM(C18:L18,N18) -> 73 | P18: =SUM(C18:N18) -> 126 | R18: 1500-1600 | S18: =SUM(C42:C45) -> 159 | T18: =SUM(D42:D45) -> 43 | U18: =SUM(E42:E45) -> 17 | V18: =SUM(F42:F45) -> 60 | W18: =SUM(G42:G45) -> 2 | X18: =SUM(H42:H45) -> 0 | Y18: =SUM(I42:I45) -> 10 | Z18: =SUM(J42:J45) -> 8 | ... AF18: =SUM(P42:P45) -> 436
B19: 09.15 - 09.30 | C19: 28 | D19: 12 | E19: 12 | F19: 12 | G19: 2 | H19: 0 | I19: 3 | J19: 1 | K19: 0 | L19: 0 | M19: 48 | N19: 0 | O19: =SUM(C19:L19,N19) -> 70 | P19: =SUM(C19:N19) -> 118 | R19: 1600-1700 | S19: =SUM(C46:C49) -> 143 | T19: =SUM(D46:D49) -> 39 | U19: =SUM(E46:E49) -> 15 | V19: =SUM(F46:F49) -> 53 | W19: =SUM(G46:G49) -> 2 | X19: =SUM(H46:H49) -> 1 | Y19: =SUM(I46:I49) -> 9 | Z19: =SUM(J46:J49) -> 10 | ... AF19: =SUM(P46:P49) -> 428
B20: 09.30 - 09.45 | C20: 30 | D20: 5 | E20: 5 | F20: 8 | G20: 2 | H20: 0 | I20: 5 | J20: 2 | K20: 0 | L20: 1 | M20: 40 | N20: 0 | O20: =SUM(C20:L20,N20) -> 58 | P20: =SUM(C20:N20) -> 98 | R20: 1700-1800 | S20: =SUM(C50:C53) -> 208 | T20: =SUM(D50:D53) -> 65 | U20: =SUM(E50:E53) -> 19 | V20: =SUM(F50:F53) -> 39 | W20: =SUM(G50:G53) -> 3 | X20: =SUM(H50:H53) -> 0 | Y20: =SUM(I50:I53) -> 8 | Z20: =SUM(J50:J53) -> 4 | ... AF20: =SUM(P50:P53) -> 518
B21: 09.45 - 10.00 | C21: 23 | D21: 5 | E21: 4 | F21: 8 | G21: 2 | H21: 0 | I21: 3 | J21: 0 | K21: 0 | L21: 0 | M21: 35 | N21: 0 | O21: =SUM(C21:L21,N21) -> 45 | P21: =SUM(C21:N21) -> 80 | R21: 1800-1900 | S21: =SUM(C54:C57) -> 190 | T21: =SUM(D54:D57) -> 50 | U21: =SUM(E54:E57) -> 30 | V21: =SUM(F54:F57) -> 45 | W21: =SUM(G54:G57) -> 1 | X21: =SUM(H54:H57) -> 0 | Y21: =SUM(I54:I57) -> 10 | Z21: =SUM(J54:J57) -> 4 | ... AF21: =SUM(P54:P57) -> 565
B22: 10.00 - 10.15 | C22: 22 | D22: 9 | E22: 10 | F22: 18 | G22: 2 | H22: 0 | I22: 4 | J22: 1 | K22: 0 | L22: 0 | M22: 40 | N22: 0 | O22: =SUM(C22:L22,N22) -> 66 | P22: =SUM(C22:N22) -> 106 | R22: AM Peak Hr | S22: =MAX(S10:S12) -> 135 | T22: =MAX(T10:T12) -> 46 | U22: =MAX(U10:U12) -> 26 | V22: =MAX(V10:V12) -> 71 | W22: =MAX(W10:W12) -> 7 | X22: =MAX(X10:X12) -> 1 | Y22: =MAX(Y10:Y12) -> 16 | Z22: =MAX(Z10:Z12) -> 7 | ... AF22: =MAX(AF10:AF12) -> 479
B23: 10.15 - 10.30 | C23: 36 | D23: 5 | E23: 6 | F23: 13 | G23: 1 | H23: 0 | I23: 3 | J23: 0 | K23: 0 | L23: 0 | M23: 51 | N23: 0 | O23: =SUM(C23:L23,N23) -> 64 | P23: =SUM(C23:N23) -> 115 | R23: IP Peak Hr | S23: =MAX(S13:S18) -> 159 | T23: =MAX(T13:T18) -> 44 | U23: =MAX(U13:U18) -> 26 | V23: =MAX(V13:V18) -> 60 | W23: =MAX(W13:W18) -> 5 | X23: =MAX(X13:X18) -> 2 | Y23: =MAX(Y13:Y18) -> 12 | Z23: =MAX(Z13:Z18) -> 9 | ... AF23: =MAX(AF13:AF18) -> 436
B24: 10.30 - 10.45 | C24: 36 | D24: 7 | E24: 4 | F24: 6 | G24: 2 | H24: 0 | I24: 1 | J24: 1 | K24: 0 | L24: 0 | M24: 28 | N24: 0 | O24: =SUM(C24:L24,N24) -> 57 | P24: =SUM(C24:N24) -> 85 | R24: PM Peak Hr | S24: =MAX(S19:S21) -> 208 | T24: =MAX(T19:T21) -> 65 | U24: =MAX(U19:U21) -> 30 | V24: =MAX(V19:V21) -> 53 | W24: =MAX(W19:W21) -> 3 | X24: =MAX(X19:X21) -> 1 | Y24: =MAX(Y19:Y21) -> 10 | Z24: =MAX(Z19:Z21) -> 10 | ... AF24: =MAX(AF19:AF21) -> 565
B25: 10.45 - 11.00 | C25: 39 | D25: 11 | E25: 6 | F25: 9 | G25: 0 | H25: 0 | I25: 4 | J25: 2 | K25: 0 | L25: 0 | M25: 47 | N25: 0 | O25: =SUM(C25:L25,N25) -> 71 | P25: =SUM(C25:N25) -> 118 | R25: AM Period | S25: =SUM(S10:S12) -> 373 | T25: =SUM(T10:T12) -> 125 | U25: =SUM(U10:U12) -> 65 | V25: =SUM(V10:V12) -> 181 | W25: =SUM(W10:W12) -> 15 | X25: =SUM(X10:X12) -> 1 | Y25: =SUM(Y10:Y12) -> 26 | Z25: =SUM(Z10:Z12) -> 17 | ... AF25: =SUM(AF10:AF12) -> 1295
B26: 11.00 - 11.15 | C26: 26 | D26: 13 | E26: 3 | F26: 12 | G26: 1 | H26: 0 | I26: 2 | J26: 4 | K26: 0 | L26: 0 | M26: 42 | N26: 0 | O26: =SUM(C26:L26,N26) -> 61 | P26: =SUM(C26:N26) -> 103 | R26: IP Period | S26: =SUM(S13:S18) -> 796 | T26: =SUM(T13:T18) -> 232 | U26: =SUM(U13:U18) -> 135 | V26: =SUM(V13:V18) -> 253 | W26: =SUM(W13:W18) -> 13 | X26: =SUM(X13:X18) -> 3 | Y26: =SUM(Y13:Y18) -> 58 | Z26: =SUM(Z13:Z18) -> 42 | ... AF26: =SUM(AF13:AF18) -> 2470
B27: 11.15 - 11.30 | C27: 21 | D27: 12 | E27: 8 | F27: 7 | G27: 0 | H27: 0 | I27: 1 | J27: 2 | K27: 0 | L27: 0 | M27: 35 | N27: 0 | O27: =SUM(C27:L27,N27) -> 51 | P27: =SUM(C27:N27) -> 86 | R27: PM Period | S27: =SUM(S19:S21) -> 541 | T27: =SUM(T19:T21) -> 154 | U27: =SUM(U19:U21) -> 64 | V27: =SUM(V19:V21) -> 137 | W27: =SUM(W19:W21) -> 6 | X27: =SUM(X19:X21) -> 1 | Y27: =SUM(Y19:Y21) -> 27 | Z27: =SUM(Z19:Z21) -> 18 | ... AF27: =SUM(AF19:AF21) -> 1511
B28: 11.30 - 11.45 | C28: 23 | D28: 8 | E28: 8 | F28: 15 | G28: 0 | H28: 0 | I28: 4 | J28: 0 | K28: 0 | L28: 0 | M28: 35 | N28: 0 | O28: =SUM(C28:L28,N28) -> 58 | P28: =SUM(C28:N28) -> 93 | R28: 12 Hours | S28: =SUM(S10:S21) -> 1710 | T28: =SUM(T10:T21) -> 511 | U28: =SUM(U10:U21) -> 264 | V28: =SUM(V10:V21) -> 571 | W28: =SUM(W10:W21) -> 34 | X28: =SUM(X10:X21) -> 5 | Y28: =SUM(Y10:Y21) -> 111 | Z28: =SUM(Z10:Z21) -> 77 | ... AF28: =SUM(AF10:AF21) -> 5276
B29: 11.45 - 12.00 | C29: 40 | D29: 11 | E29: 7 | F29: 9 | G29: 0 | H29: 0 | I29: 2 | J29: 3 | K29: 0 | L29: 0 | M29: 58 | N29: 0 | O29: =SUM(C29:L29,N29) -> 72 | P29: =SUM(C29:N29) -> 130
B30: 12.00 - 12.15 | C30: 38 | D30: 10 | E30: 8 | F30: 14 | G30: 0 | H30: 0 | I30: 6 | J30: 2 | K30: 0 | L30: 0 | M30: 52 | N30: 0 | O30: =SUM(C30:L30,N30) -> 78 | P30: =SUM(C30:N30) -> 130
B31: 12.15 - 12.30 | C31: 36 | D31: 5 | E31: 5 | F31: 12 | G31: 0 | H31: 0 | I31: 2 | J31: 3 | K31: 0 | L31: 0 | M31: 46 | N31: 0 | O31: =SUM(C31:L31,N31) -> 63 | P31: =SUM(C31:N31) -> 109
B32: 12.30 - 12.45 | C32: 31 | D32: 10 | E32: 3 | F32: 6 | G32: 0 | H32: 0 | I32: 3 | J32: 0 | K32: 1 | L32: 0 | M32: 40 | N32: 0 | O32: =SUM(C32:L32,N32) -> 54 | P32: =SUM(C32:N32) -> 94
B33: 12.45 - 13.00 | C33: 29 | D33: 11 | E33: 4 | F33: 6 | G33: 2 | H33: 1 | I33: 1 | J33: 0 | K33: 0 | L33: 0 | M33: 35 | N33: 0 | O33: =SUM(C33:L33,N33) -> 54 | P33: =SUM(C33:N33) -> 89
B34: 13.00 - 13.15 | C34: 46 | D34: 9 | E34: 2 | F34: 12 | G34: 1 | H34: 0 | I34: 2 | J34: 4 | K34: 1 | L34: 0 | M34: 30 | N34: 0 | O34: =SUM(C34:L34,N34) -> 77 | P34: =SUM(C34:N34) -> 107
B35: 13.15 - 13.30 | C35: 34 | D35: 11 | E35: 5 | F35: 10 | G35: 0 | H35: 1 | I35: 2 | J35: 3 | K35: 0 | L35: 0 | M35: 54 | O35: =SUM(C35:L35,N35) -> 66 | P35: =SUM(C35:N35) -> 120
B36: 13.30 - 13.45 | C36: 35 | D36: 10 | E36: 9 | F36: 7 | G36: 0 | H36: 1 | I36: 2 | J36: 0 | K36: 0 | L36: 0 | M36: 43 | N36: 0 | O36: =SUM(C36:L36,N36) -> 64 | P36: =SUM(C36:N36) -> 107
B37: 13.45 - 14.00 | C37: 25 | D37: 13 | E37: 5 | F37: 4 | G37: 0 | H37: 0 | I37: 1 | J37: 1 | K37: 0 | L37: 0 | M37: 26 | N37: 0 | O37: =SUM(C37:L37,N37) -> 49 | P37: =SUM(C37:N37) -> 75
B38: 14.00 - 14.15 | C38: 27 | D38: 6 | E38: 7 | F38: 9 | G38: 0 | H38: 0 | I38: 1 | J38: 2 | K38: 0 | L38: 1 | M38: 30 | N38: 0 | O38: =SUM(C38:L38,N38) -> 53 | P38: =SUM(C38:N38) -> 83
B39: 14.15 - 14.30 | C39: 28 | D39: 5 | E39: 3 | F39: 5 | G39: 1 | H39: 0 | I39: 3 | J39: 1 | K39: 1 | L39: 0 | M39: 35 | N39: 0 | O39: =SUM(C39:L39,N39) -> 47 | P39: =SUM(C39:N39) -> 82
B40: 14.30 - 14.45 | C40: 33 | D40: 12 | E40: 6 | F40: 10 | G40: 1 | H40: 0 | I40: 1 | J40: 3 | K40: 0 | L40: 0 | M40: 30 | N40: 0 | O40: =SUM(C40:L40,N40) -> 66 | P40: =SUM(C40:N40) -> 96
B41: 14.45 - 15.00 | C41: 32 | D41: 11 | E41: 9 | F41: 9 | G41: 0 | H41: 0 | I41: 3 | J41: 2 | K41: 0 | L41: 0 | M41: 40 | N41: 0 | O41: =SUM(C41:L41,N41) -> 66 | P41: =SUM(C41:N41) -> 106
B42: 15.00 - 15.15 | C42: 35 | D42: 8 | E42: 5 | F42: 13 | G42: 0 | H42: 0 | I42: 2 | J42: 2 | K42: 0 | L42: 0 | M42: 40 | N42: 0 | O42: =SUM(C42:L42,N42) -> 65 | P42: =SUM(C42:N42) -> 105
...

Sheet 24.09 Munyonyo-Gaba
B1: Consultancy services for Preparation of Expressway Development Master Plan (EDMP) for Uganda
B2: MANUAL CLASSIFIED COUNT (MCC)
B3: ROAD NAME: | C3: ='[1]24.09.2019 GGABA RD-MUNYONYO '!C3:G3 -> MCC-C2-STN52-WAVAMUNNO
C5: Date | D5: ='[1]24.09.2019 GGABA RD-MUNYONYO '!D5 -> 24.09.19 | F5: Location | G5: ='[1]24.09.2019 GGABA RD-MUNYONYO '!G5:H5 -> FUSION AUTO SPA | J5: Surveyor | K5: AMANDU EMMANUEL
C6: Dir. From | D6: MUNYONYO | F6: Dir. To | G6: GGABA ROAD | J6: Supervisor | K6: ='[1]24.09.2019 GGABA RD-MUNYONYO '!K6:L6 -> STEVEN
B8: Time / Veh Type | R8: SUMMARY TRAFFIC VOLUMES
C9: 1. Car | D9: 2. Station Wagon | E9: 3. Pickups | F9: 4. Minibus, matatu | G9: 5. Medium bus | H9: 6. Large Bus | I9: 7. Light Truck | J9: 8. Medium Truck | K9: 9. Heavy truck | L9: 10. Truck Trailer | M9: 11. Motor cycles | N9: 12. Tractors | O9: Total Excl M/Cycles | P9: Total All | R9: Time | S9: 1. Car | T9: 2. Station Wagon | U9: 3. Pickups | V9: 4. Minibus, matatu | W9: 5. Medium bus | X9: 6. Large Bus | Y9: 7. Light Truck | Z9: 8. Medium Truck | AA9: 9. Heavy truck | AB9: 10. Truck Trailer | AC9: 11. Motorcycles | AD9: 12. Tractors, Graders | AE9: Total Excl M/ Cycles | AF9: Total All
B10: 07.00 - 07.15 | C10: 37 | D10: 18 | E10: 3 | F10: 11 | G10: 0 | H10: 0 | I10: 0 | J10: 1 | K10: 0 | L10: 0 | M10: 31 | N10: 0 | O10: =SUM(C10:L10,N10) -> 70 | P10: =SUM(C10:N10) -> 101 | R10: 0700-0800 | S10: =SUM(C10:C13) -> 100 | T10: =SUM(D10:D13) -> 71 | U10: =SUM(E10:E13) -> 10 | V10: =SUM(F10:F13) -> 45 | W10: =SUM(G10:G13) -> 1 | X10: =SUM(H10:H13) -> 0 | Y10: =SUM(I10:I13) -> 3 | Z10: =SUM(J10:J13) -> 2 | ... AF10: =SUM(P10:P13) -> 327
B11: 07.15 - 07.30 | C11: 25 | D11: 22 | E11: 6 | F11: 21 | G11: 1 | H11: 0 | I11: 1 | J11: 0 | K11: 0 | L11: 0 | M11: 28 | N11: 0 | O11: =SUM(C11:L11,N11) -> 76 | P11: =SUM(C11:N11) -> 104 | R11: 0800-0900 | S11: =SUM(C14:C17) -> 52 | T11: =SUM(D14:D17) -> 58 | U11: =SUM(E14:E17) -> 18 | V11: =SUM(F14:F17) -> 52 | W11: =SUM(G14:G17) -> 1 | X11: =SUM(H14:H17) -> 0 | Y11: =SUM(I14:I17) -> 6 | Z11: =SUM(J14:J17) -> 2 | ... AF11: =SUM(P14:P17) -> 292
B12: 07.30 - 07.45 | C12: 20 | D12: 20 | E12: 1 | F12: 11 | G12: 0 | H12: 0 | I12: 2 | J12: 0 | K12: 0 | L12: 0 | M12: 12 | N12: 0 | O12: =SUM(C12:L12,N12) -> 54 | P12: =SUM(C12:N12) -> 66 | R12: 0900-1000 | S12: =SUM(C18:C21) -> 39 | T12: =SUM(D18:D21) -> 53 | U12: =SUM(E18:E21) -> 17 | V12: =SUM(F18:F21) -> 57 | W12: =SUM(G18:G21) -> 0 | X12: =SUM(H18:H21) -> 0 | Y12: =SUM(I18:I21) -> 7 | Z12: =SUM(J18:J21) -> 5 | ... AF12: =SUM(P18:P21) -> 268
B13: 07.45 - 08.00 | C13: 18 | D13: 11 | E13: 0 | F13: 2 | G13: 0 | H13: 0 | I13: 0 | J13: 1 | K13: 0 | L13: 0 | M13: 24 | N13: 0 | O13: =SUM(C13:L13,N13) -> 32 | P13: =SUM(C13:N13) -> 56 | R13: 1000-1100 | S13: =SUM(C22:C25) -> 53 | T13: =SUM(D22:D25) -> 57 | U13: =SUM(E22:E25) -> 4 | V13: =SUM(F22:F25) -> 42 | W13: =SUM(G22:G25) -> 2 | X13: =SUM(H22:H25) -> 1 | Y13: =SUM(I22:I25) -> 5 | Z13: =SUM(J22:J25) -> 4 | ... AF13: =SUM(P22:P25) -> 236
B14: 08.00 - 08.15 | C14: 11 | D14: 26 | E14: 3 | F14: 10 | G14: 1 | H14: 0 | I14: 2 | J14: 0 | K14: 0 | L14: 0 | M14: 28 | N14: 0 | O14: =SUM(C14:L14,N14) -> 53 | P14: =SUM(C14:N14) -> 81 | R14: 1100-1200 | S14: =SUM(C26:C29) -> 48 | T14: =SUM(D26:D29) -> 67 | U14: =SUM(E26:E29) -> 4 | V14: =SUM(F26:F29) -> 33 | W14: =SUM(G26:G29) -> 1 | X14: =SUM(H26:H29) -> 0 | Y14: =SUM(I26:I29) -> 8 | Z14: =SUM(J26:J29) -> 1 | ... AF14: =SUM(P26:P29) -> 255
B15: 08.15 - 08.30 | C15: 18 | D15: 11 | E15: 8 | F15: 12 | G15: 0 | H15: 0 | I15: 0 | J15: 2 | K15: 1 | L15: 0 | M15: 25 | N15: 0 | O15: =SUM(C15:L15,N15) -> 52 | P15: =SUM(C15:N15) -> 77 | R15: 1200-1300 | S15: =SUM(C30:C33) -> 44 | T15: =SUM(D30:D33) -> 55 | U15: =SUM(E30:E33) -> 19 | V15: =SUM(F30:F33) -> 52 | W15: =SUM(G30:G33) -> 2 | X15: =SUM(H30:H33) -> 0 | Y15: =SUM(I30:I33) -> 6 | Z15: =SUM(J30:J33) -> 6 | ... AF15: =SUM(P30:P33) -> 276
B16: 08.30 - 08.45 | C16: 13 | D16: 13 | E16: 3 | F16: 10 | G16: 0 | H16: 0 | I16: 3 | J16: 0 | K16: 0 | L16: 0 | M16: 21 | N16: 0 | O16: =SUM(C16:L16,N16) -> 42 | P16: =SUM(C16:N16) -> 63 | R16: 1300-1400 | S16: =SUM(C34:C38) -> 52 | T16: =SUM(D34:D38) -> 49 | U16: =SUM(E34:E38) -> 16 | V16: =SUM(F34:F38) -> 45 | W16: =SUM(G34:G38) -> 3 | X16: =SUM(H34:H38) -> 0 | Y16: =SUM(I34:I38) -> 6 | Z16: =SUM(J34:J38) -> 1 | ... AC16: =SUM(M34:M38) -> 131 | AD16: =SUM(N34:N37) -> 0 | AE16: =SUM(O34:O37) -> 136 | AF16: =SUM(P34:P37) -> 245
B17: 08.45 - 9.00 | C17: 10 | D17: 8 | E17: 4 | F17: 20 | G17: 0 | H17: 0 | I17: 1 | J17: 0 | K17: 0 | L17: 0 | M17: 28 | N17: 0 | O17: =SUM(C17:L17,N17) -> 43 | P17: =SUM(C17:N17) -> 71 | R17: 1400-1500 | S17: =SUM(C39:C42) -> 57 | T17: =SUM(D39:D42) -> 50 | U17: =SUM(E39:E42) -> 11 | V17: =SUM(F39:F42) -> 29 | W17: =SUM(G39:G42) -> 3 | X17: =SUM(H39:H42) -> 0 | Y17: =SUM(I39:I42) -> 11 | Z17: =SUM(J39:J42) -> 4 | ... AC17: =SUM(M39:M42) -> 112 | AD17: =SUM(N38:N41) -> 0 | AE17: =SUM(O38:O41) -> 141 | AF17: =SUM(P38:P41) -> 244
B18: 09.00 - 09.15 | C18: 12 | D18: 17 | E18: 6 | F18: 11 | G18: 0 | H18: 0 | I18: 1 | J18: 0 | K18: 0 | L18: 0 | M18: 31 | N18: 0 | O18: =SUM(C18:L18,N18) -> 47 | P18: =SUM(C18:N18) -> 78 | R18: 1500-1600 | S18: =SUM(C43:C46) -> 42 | T18: =SUM(D43:D46) -> 56 | U18: =SUM(E43:E46) -> 6 | V18: =SUM(F43:F46) -> 49 | W18: =SUM(G43:G46) -> 0 | X18: =SUM(H43:H46) -> 0 | Y18: =SUM(I43:I46) -> 10 | Z18: =SUM(J43:J46) -> 2 | ... AC18: =SUM(M43:M46) -> 98 | AD18: =SUM(N42:N45) -> 0 | AE18: =SUM(O42:O45) -> 175 | AF18: =SUM(P42:P45) -> 280
B19: 09.15 - 09.30 | C19: 9 | D19: 14 | E19: 9 | F19: 22 | G19: 0 | H19: 0 | I19: 4 | J19: 3 | K19: 1 | L19: 0 | M19: 24 | N19: 0 | O19: =SUM(C19:L19,N19) -> 62 | P19: =SUM(C19:N19) -> 86 | R19: 1600-1700 | S19: =SUM(C47:C50) -> 44 | T19: =SUM(D47:D50) -> 57 | U19: =SUM(E47:E50) -> 16 | V19: =SUM(F47:F50) -> 53 | W19: =SUM(G47:G50) -> 0 | X19: =SUM(H47:H50) -> 0 | Y19: =SUM(I47:I50) -> 2 | Z19: =SUM(J47:J50) -> 0 | ... AC19: =SUM(M47:M50) -> 101 | AD19: =SUM(N46:N49) -> 0 | AE19: =SUM(O46:O49) -> 193 | AF19: =SUM(P46:P49) -> 303
B20: 09.30 - 09.45 | C20: 9 | D20: 11 | E20: 2 | F20: 8 | G20: 0 | H20: 0 | I20: 1 | J20: 1 | K20: 0 | L20: 0 | M20: 18 | N20: 0 | O20: =SUM(C20:L20,N20) -> 32 | P20: =SUM(C20:N20) -> 50 | R20: 1700-1800 | S20: =SUM(C51:C53) -> 26 | T20: =SUM(D51:D53) -> 45 | U20: =SUM(E51:E53) -> 4 | V20: =SUM(F51:F53) -> 23 | W20: =SUM(G51:G53) -> 2 | X20: =SUM(H51:H53) -> 0 | Y20: =SUM(I51:I53) -> 4 | Z20: =SUM(J51:J53) -> 2 | ... AC20: =SUM(M51:M53) -> 70 | AD20: =SUM(N50:N53) -> 0 | AE20: =SUM(O50:O53) -> 138 | AF20: =SUM(P50:P53) -> 223
B21: 09.45 - 10.00 | C21: 9 | D21: 11 | E21: 0 | F21: 16 | G21: 0 | H21: 0 | I21: 1 | J21: 1 | K21: 0 | L21: 0 | M21: 16 | N21: 0 | O21: =SUM(C21:L21,N21) -> 38 | P21: =SUM(C21:N21) -> 54 | R21: 1800-1900 | S21: =SUM(C54:C57) -> 44 | T21: =SUM(D54:D57) -> 51 | U21: =SUM(E54:E57) -> 35 | V21: =SUM(F54:F57) -> 73 | W21: =SUM(G54:G57) -> 1 | X21: =SUM(H54:H57) -> 1 | Y21: =SUM(I54:I57) -> 6 | Z21: =SUM(J54:J57) -> 2 | ... AF21: =SUM(P54:P57) -> 343
B22: 10.00 - 10.15 | C22: 11 | D22: 5 | E22: 1 | F22: 16 | G22: 0 | H22: 0 | I22: 1 | J22: 2 | K22: 0 | L22: 0 | M22: 17 | N22: 0 | O22: =SUM(C22:L22,N22) -> 36 | P22: =SUM(C22:N22) -> 53 | R22: AM Peak Hr | S22: =MAX(S10:S12) -> 100 | T22: =MAX(T10:T12) -> 71 | U22: =MAX(U10:U12) -> 18 | V22: =MAX(V10:V12) -> 57 | W22: =MAX(W10:W12) -> 1 | X22: =MAX(X10:X12) -> 0 | Y22: =MAX(Y10:Y12) -> 7 | Z22: =MAX(Z10:Z12) -> 5 | ... AF22: =MAX(AF10:AF12) -> 327
B23: 10.15 - 10.30 | C23: 14 | D23: 15 | E23: 0 | F23: 5 | G23: 2 | H23: 1 | I23: 3 | J23: 1 | K23: 0 | L23: 0 | M23: 14 | N23: 0 | O23: =SUM(C23:L23,N23) -> 41 | P23: =SUM(C23:N23) -> 55 | R23: IP Peak Hr | S23: =MAX(S13:S18) -> 57 | T23: =MAX(T13:T18) -> 67 | U23: =MAX(U13:U18) -> 19 | V23: =MAX(V13:V18) -> 52 | W23: =MAX(W13:W18) -> 3 | X23: =MAX(X13:X18) -> 1 | Y23: =MAX(Y13:Y18) -> 11 | Z23: =MAX(Z13:Z18) -> 6 | ... AF23: =MAX(AF13:AF18) -> 280
B24: 10.30 - 10.45 | C24: 11 | D24: 21 | E24: 3 | F24: 5 | G24: 0 | H24: 0 | I24: 1 | J24: 0 | K24: 0 | L24: 0 | M24: 25 | N24: 0 | O24: =SUM(C24:L24,N24) -> 41 | P24: =SUM(C24:N24) -> 66 | R24: PM Peak Hr | S24: =MAX(S19:S21) -> 44 | T24: =MAX(T19:T21) -> 57 | U24: =MAX(U19:U21) -> 35 | V24: =MAX(V19:V21) -> 73 | W24: =MAX(W19:W21) -> 2 | X24: =MAX(X19:X21) -> 1 | Y24: =MAX(Y19:Y21) -> 6 | Z24: =MAX(Z19:Z21) -> 2 | ... AF24: =MAX(AF19:AF21) -> 343
B25: 10.45 - 11.00 | C25: 17 | D25: 16 | E25: 0 | F25: 16 | G25: 0 | H25: 0 | I25: 0 | J25: 1 | K25: 0 | L25: 0 | M25: 12 | N25: 0 | O25: =SUM(C25:L25,N25) -> 50 | P25: =SUM(C25:N25) -> 62 | R25: AM Period | S25: =SUM(S10:S12) -> 191 | T25: =SUM(T10:T12) -> 182 | U25: =SUM(U10:U12) -> 45 | V25: =SUM(V10:V12) -> 154 | W25: =SUM(W10:W12) -> 2 | X25: =SUM(X10:X12) -> 0 | Y25: =SUM(Y10:Y12) -> 16 | Z25: =SUM(Z10:Z12) -> 9 | ... AF25: =SUM(AF10:AF12) -> 887
B26: 11.00 - 11.15 | C26: 8 | D26: 18 | E26: 1 | F26: 10 | G26: 0 | H26: 0 | I26: 0 | J26: 0 | K26: 0 | L26: 0 | M26: 16 | N26: 0 | O26: =SUM(C26:L26,N26) -> 37 | P26: =SUM(C26:N26) -> 53 | R26: IP Period | S26: =SUM(S13:S18) -> 296 | T26: =SUM(T13:T18) -> 334 | U26: =SUM(U13:U18) -> 60 | V26: =SUM(V13:V18) -> 250 | W26: =SUM(W13:W18) -> 11 | X26: =SUM(X13:X18) -> 1 | Y26: =SUM(Y13:Y18) -> 46 | Z26: =SUM(Z13:Z18) -> 18 | ... AF26: =SUM(AF13:AF18) -> 1536
B27: 11.15 - 11.30 | C27: 14 | D27: 19 | E27: 1 | F27: 7 | G27: 1 | H27: 0 | I27: 2 | J27: 0 | K27: 0 | L27: 1 | M27: 34 | N27: 0 | O27: =SUM(C27:L27,N27) -> 45 | P27: =SUM(C27:N27) -> 79 | R27: PM Period | S27: =SUM(S19:S21) -> 114 | T27: =SUM(T19:T21) -> 153 | U27: =SUM(U19:U21) -> 55 | V27: =SUM(V19:V21) -> 149 | W27: =SUM(W19:W21) -> 3 | X27: =SUM(X19:X21) -> 1 | Y27: =SUM(Y19:Y21) -> 12 | Z27: =SUM(Z19:Z21) -> 4 | ... AF27: =SUM(AF19:AF21) -> 869
B28: 11.30 - 11.45 | C28: 9 | D28: 12 | E28: 2 | F28: 7 | G28: 0 | H28: 0 | I28: 5 | J28: 1 | K28: 0 | L28: 0 | M28: 22 | N28: 0 | O28: =SUM(C28:L28,N28) -> 36 | P28: =SUM(C28:N28) -> 58 | R28: 12 Hours | S28: =SUM(S10:S21) -> 601 | T28: =SUM(T10:T21) -> 669 | U28: =SUM(U10:U21) -> 160 | V28: =SUM(V10:V21) -> 553 | W28: =SUM(W10:W21) -> 16 | X28: =SUM(X10:X21) -> 2 | Y28: =SUM(Y10:Y21) -> 74 | Z28: =SUM(Z10:Z21) -> 31 | ... AF28: =SUM(AF10:AF21) -> 3292
B29: 11.45 - 12.00 | C29: 17 | D29: 18 | E29: 0 | F29: 9 | G29: 0 | H29: 0 | I29: 1 | J29: 0 | K29: 0 | L29: 0 | M29: 20 | N29: 0 | O29: =SUM(C29:L29,N29) -> 45 | P29: =SUM(C29:N29) -> 65
B30: 12.00 - 12.15 | C30: 13 | D30: 16 | E30: 3 | F30: 8 | G30: 0 | H30: 0 | I30: 2 | J30: 2 | K30: 0 | L30: 0 | M30: 28 | N30: 0 | O30: =SUM(C30:L30,N30) -> 44 | P30: =SUM(C30:N30) -> 72
B31: 12.15 - 12.30 | C31: 13 | D31: 21 | E31: 6 | F31: 12 | G31: 0 | H31: 0 | I31: 1 | J31: 2 | K31: 0 | L31: 0 | M31: 27 | N31: 0 | O31: =SUM(C31:L31,N31) -> 55 | P31: =SUM(C31:N31) -> 82
B32: 12.30 - 12.45 | C32: 8 | D32: 7 | E32: 6 | F32: 16 | G32: 2 | H32: 0 | I32: 0 | J32: 0 | K32: 0 | L32: 0 | M32: 21 | N32: 0 | O32: =SUM(C32:L32,N32) -> 39 | P32: =SUM(C32:N32) -> 60
B33: 12.45 - 13.00 | C33: 10 | D33: 11 | E33: 4 | F33: 16 | G33: 0 | H33: 0 | I33: 3 | J33: 2 | K33: 0 | L33: 0 | M33: 16 | N33: 0 | O33: =SUM(C33:L33,N33) -> 46 | P33: =SUM(C33:N33) -> 62
B34: 13.00 - 13.15 | C34: 13 | D34: 6 | E34: 1 | F34: 11 | G34: 3 | H34: 0 | I34: 0 | J34: 0 | K34: 0 | L34: 0 | M34: 16 | N34: 0 | O34: =SUM(C34:L34,N34) -> 34 | P34: =SUM(C34:N34) -> 50
B35: 13.15 - 13.30 | C35: 8 | D35: 13 | E35: 3 | F35: 18 | G35: 0 | H35: 0 | I35: 1 | J35: 1 | K35: 0 | L35: 0 | M35: 28 | N35: 0 | O35: =SUM(C35:L35,N35) -> 44 | P35: =SUM(C35:N35) -> 72
B36: 13.30 - 13.45 | C36: 11 | D36: 8 | E36: 5 | F36: 1 | G36: 0 | H36: 0 | I36: 2 | J36: 0 | K36: 0 | L36: 0 | M36: 36 | N36: 0 | O36: =SUM(C36:L36,N36) -> 27 | P36: =SUM(C36:N36) -> 63
B37: 13.45 - 14.00 | C37: 7 | D37: 13 | E37: 4 | F37: 5 | G37: 0 | H37: 0 | I37: 2 | J37: 0 | K37: 0 | L37: 0 | M37: 29 | N37: 0 | O37: =SUM(C37:L37,N37) -> 31 | P37: =SUM(C37:N37) -> 60
B38: 14.00 - 14.15 | C38: 13 | D38: 9 | E38: 3 | F38: 10 | G38: 0 | H38: 0 | I38: 1 | J38: 0 | K38: 0 | L38: 0 | M38: 22 | N38: 0 | O38: =SUM(C38:L38,N38) -> 36 | P38: =SUM(C38:N38) -> 58
B39: 14.15 - 14.30 | C39: 15 | D39: 9 | E39: 3 | F39: 4 | G39: 2 | H39: 0 | I39: 3 | J39: 2 | K39: 0 | L39: 0 | M39: 26 | N39: 0 | O39: =SUM(C39:L39,N39) -> 38 | P39: =SUM(C39:N39) -> 64
B40: 14.30 - 14.45 | C40: 7 | D40: 14 | E40: 1 | F40: 7 | G40: 0 | H40: 0 | I40: 3 | J40: 0 | K40: 0 | L40: 0 | M40: 23 | N40: 0 | O40: =SUM(C40:L40,N40) -> 32 | P40: =SUM(C40:N40) -> 55
... B57: 18.45 - 19.00 | C57: 11 | D57: 11 | E57: 10 | F57: 13 | G57: 0 | H57: 0 | I57: 2 | J57: 0 | K57: 0 | L57: 0 | M57: 34 | N57: 0 | O57: =SUM(C57:L57,N57) -> 47 | P57: =SUM(C57:N57) -> 81
B58: Totals | C58: =SUM(C10:C57) -> 601 | D58: =SUM(D10:D57) -> 669 | E58: =SUM(E10:E57) -> 160 | F58: =SUM(F10:F57) -> 553 | G58: =SUM(G10:G57) -> 16 | H58: =SUM(H10:H57) -> 2 | I58: =SUM(I10:I57) -> 74 | J58: =SUM(J10:J57) -> 31 | ... N58: =SUM(N10:N57) -> 0 | O58: =SUM(C58:L58,N58) -> 2114 | P58: =SUM(P10:P57) -> 3292
...

Sheet 25.09 Gaba-Munyonyo
B1: Consultancy services for Preparation of Expressway Development Master Plan (EDMP) for Uganda
B2: MANUAL CLASSIFIED COUNT (MCC)
B3: ROAD NAME: | C3: ='23.09.19 Gaba -Munyonyo'!C3:G3 -> MCC-C2-STNO 52-Wavamuno RD
C5: Date | D5: 25.09.19 | F5: Location | G5: ='23.09.19 Gaba -Munyonyo'!G5:H5 -> Wavamuno | J5: Surveyor | K5: ='23.09.19 Gaba -Munyonyo'!K5:L5 -> Andrew
C6: Dir. From | D6: ='23.09.19 Gaba -Munyonyo'!D6:E6 -> GABA | F6: Dir. To | G6: ='23.09.19 Gaba -Munyonyo'!G6:H6 -> MUNYONYO | J6: Supervisor | K6: ='23.09.19 Gaba -Munyonyo'!K6:L6 -> Steven
B8: Time / Veh Type | R8: SUMMARY TRAFFIC VOLUMES
C9: 1. Car | D9: 2. Station Wagon | E9: 3. Pickups | F9: 4. Minibus, matatu | G9: 5. Medium bus | H9: 6. Large Bus | I9: 7. Light Truck | J9: 8. Medium Truck | K9: 9. Heavy truck | L9: 10. Truck Trailer | M9: 11. Motor cycles | N9: 12. Tractors | O9: Total Excl M/Cycles | P9: Total All | R9: Time | S9: 1. Car | T9: 2. Station Wagon | U9: 3. Pickups | V9: 4. Minibus, matatu | W9: 5. Medium bus | X9: 6. Large Bus | Y9: 7. Light Truck | Z9: 8. Medium Truck | AA9: 9. Heavy truck | AB9: 10. Truck Trailer | AC9: 11. Motorcycles | AD9: 12. Tractors, Graders | AE9: Total Excl M/ Cycles | AF9: Total All
B10: 07.00 - 07.15 | C10: 29 | D10: 7 | E10: 7 | F10: 11 | G10: 0 | H10: 0 | I10: 1 | J10: 0 | K10: 0 | L10: 0 | M10: 22 | N10: 0 | O10: =SUM(C10:L10,N10) -> 55 | P10: =SUM(C10:N10) -> 77 | R10: 0700-0800 | S10: =SUM(C10:C13) -> 136 | T10: =SUM(D10:D13) -> 36 | U10: =SUM(E10:E13) -> 16 | V10: =SUM(F10:F13) -> 63 | W10: =SUM(G10:G13) -> 2 | X10: =SUM(H10:H13) -> 0 | Y10: =SUM(I10:I13) -> 7 | Z10: =SUM(J10:J13) -> 7 | ... AF10: =SUM(P10:P13) -> 403
B11: 07.15 - 07.30 | C11: 40 | D11: 12 | E11: 1 | F11: 15 | G11: 2 | H11: 0 | I11: 1 | J11: 2 | K11: 0 | L11: 0 | M11: 28 | N11: 0 | O11: =SUM(C11:L11,N11) -> 73 | P11: =SUM(C11:N11) -> 101 | R11: 0800-0900 | S11: =SUM(C14:C17) -> 99 | T11: =SUM(D14:D17) -> 34 | U11: =SUM(E14:E17) -> 21 | V11: =SUM(F14:F17) -> 62 | W11: =SUM(G14:G17) -> 3 | X11: =SUM(H14:H17) -> 0 | Y11: =SUM(I14:I17) -> 4 | Z11: =SUM(J14:J17) -> 9 | ... AF11: =SUM(P14:P17) -> 335
B12: 07.30 - 07.45 | C12: 31 | D12: 6 | E12: 3 | F12: 14 | G12: 0 | H12: 0 | I12: 0 | J12: 2 | K12: 0 | L12: 0 | M12: 36 | N12: 0 | O12: =SUM(C12:L12,N12) -> 56 | P12: =SUM(C12:N12) -> 92 | R12: 0900-1000 | S12: =SUM(C18:C21) -> 101 | T12: =SUM(D18:D21) -> 29 | U12: =SUM(E18:E21) -> 21 | V12: =SUM(F18:F21) -> 43 | W12: =SUM(G18:G21) -> 2 | X12: =SUM(H18:H21) -> 1 | Y12: =SUM(I18:I21) -> 9 | Z12: =SUM(J18:J21) -> 8 | ... AF12: =SUM(P18:P21) -> 397
B13: 07.45 - 08.00 | C13: 36 | D13: 11 | E13: 5 | F13: 23 | G13: 0 | H13: 0 | I13: 5 | J13: 3 | K13: 0 | L13: 0 | M13: 50 | N13: 0 | O13: =SUM(C13:L13,N13) -> 83 | P13: =SUM(C13:N13) -> 133 | R13: 1000-1100 | S13: =SUM(C22:C25) -> 102 | T13: =SUM(D22:D25) -> 28 | U13: =SUM(E22:E25) -> 22 | V13: =SUM(F22:F25) -> 40 | W13: =SUM(G22:G25) -> 7 | X13: =SUM(H22:H25) -> 0 | Y13: =SUM(I22:I25) -> 10 | Z13: =SUM(J22:J25) -> 7 | ... AF13: =SUM(P22:P25) -> 379
B14: 08.00 - 08.15 | C14: 37 | D14: 9 | E14: 8 | F14: 15 | G14: 0 | H14: 0 | I14: 1 | J14: 2 | K14: 0 | L14: 0 | M14: 23 | N14: 0 | O14: =SUM(C14:L14,N14) -> 72 | P14: =SUM(C14:N14) -> 95 | R14: 1100-1200 | S14: =SUM(C26:C29) -> 120 | T14: =SUM(D26:D29) -> 29 | U14: =SUM(E26:E29) -> 15 | V14: =SUM(F26:F29) -> 38 | W14: =SUM(G26:G29) -> 1 | X14: =SUM(H26:H29) -> 0 | Y14: =SUM(I26:I29) -> 14 | Z14: =SUM(J26:J29) -> 6 | ... AF14: =SUM(P26:P29) -> 408
B15: 08.15 - 08.30 | C15: 20 | D15: 8 | E15: 5 | F15: 17 | G15: 2 | H15: 0 | I15: 1 | J15: 3 | K15: 0 | L15: 0 | M15: 27 | N15: 0 | O15: =SUM(C15:L15,N15) -> 56 | P15: =SUM(C15:N15) -> 83 | R15: 1200-1300 | S15: =SUM(C30:C33) -> 129 | T15: =SUM(D30:D33) -> 35 | U15: =SUM(E30:E33) -> 21 | V15: =SUM(F30:F33) -> 44 | W15: =SUM(G30:G33) -> 1 | X15: =SUM(H30:H33) -> 0 | Y15: =SUM(I30:I33) -> 16 | Z15: =SUM(J30:J33) -> 11 | ... AF15: =SUM(P30:P33) -> 459
B16: 08.30 - 08.45 | C16: 23 | D16: 8 | E16: 2 | F16: 13 | G16: 1 | H16: 0 | I16: 1 | J16: 4 | K16: 0 | L16: 0 | M16: 19 | N16: 0 | O16: =SUM(C16:L16,N16) -> 52 | P16: =SUM(C16:N16) -> 71 | R16: 1300-1400 | S16: =SUM(C34:C37) -> 143 | T16: =SUM(D34:D37) -> 38 | U16: =SUM(E34:E37) -> 16 | V16: =SUM(F34:F37) -> 40 | W16: =SUM(G34:G37) -> 0 | X16: =SUM(H34:H37) -> 0 | Y16: =SUM(I34:I37) -> 9 | Z16: =SUM(J34:J37) -> 12 | ... AF16: =SUM(P34:P37) -> 451
B17: 08.45 - 9.00 | C17: 19 | D17: 9 | E17: 6 | F17: 17 | G17: 0 | H17: 0 | I17: 1 | J17: 0 | K17: 0 | L17: 0 | M17: 34 | N17: 0 | O17: =SUM(C17:L17,N17) -> 52 | P17: =SUM(C17:N17) -> 86 | R17: 1400-1500 | S17: =SUM(C38:C41) -> 146 | T17: =SUM(D38:D41) -> 42 | U17: =SUM(E38:E41) -> 20 | V17: =SUM(F38:F41) -> 30 | W17: =SUM(G38:G41) -> 1 | X17: =SUM(H38:H41) -> 0 | Y17: =SUM(I38:I41) -> 7 | Z17: =SUM(J38:J41) -> 11 | ... AF17: =SUM(P38:P41) -> 451
B18: 09.00 - 09.15 | C18: 22 | D18: 8 | E18: 9 | F18: 9 | G18: 1 | H18: 0 | I18: 2 | J18: 5 | K18: 0 | L18: 0 | M18: 45 | N18: 0 | O18: =SUM(C18:L18,N18) -> 56 | P18: =SUM(C18:N18) -> 101 | R18: 1500-1600 | S18: =SUM(C42:C45) -> 183 | T18: =SUM(D42:D45) -> 46 | U18: =SUM(E42:E45) -> 16 | V18: =SUM(F42:F45) -> 39 | W18: =SUM(G42:G45) -> 1 | X18: =SUM(H42:H45) -> 0 | Y18: =SUM(I42:I45) -> 11 | Z18: =SUM(J42:J45) -> 9 | ... AF18: =SUM(P42:P45) -> 492
B19: 09.15 - 09.30 | C19: 27 | D19: 6 | E19: 6 | F19: 21 | G19: 0 | H19: 0 | I19: 4 | J19: 2 | K19: 0 | L19: 0 | M19: 47 | N19: 0 | O19: =SUM(C19:L19,N19) -> 66 | P19: =SUM(C19:N19) -> 113 | R19: 1600-1700 | S19: =SUM(C46:C49) -> 188 | T19: =SUM(D46:D49) -> 55 | U19: =SUM(E46:E49) -> 21 | V19: =SUM(F46:F49) -> 54 | W19: =SUM(G46:G49) -> 2 | X19: =SUM(H46:H49) -> 0 | Y19: =SUM(I46:I49) -> 7 | Z19: =SUM(J46:J49) -> 6 | ... AF19: =SUM(P46:P49) -> 556
B20: 09.30 - 09.45 | C20: 34 | D20: 11 | E20: 2 | F20: 6 | G20: 1 | H20: 1 | I20: 2 | J20: 0 | K20: 0 | L20: 0 | M20: 52 | N20: 0 | O20: =SUM(C20:L20,N20) -> 57 | P20: =SUM(C20:N20) -> 109 | R20: 1700-1800 | S20: =SUM(C50:C53) -> 226 | T20: =SUM(D50:D53) -> 66 | U20: =SUM(E50:E53) -> 11 | V20: =SUM(F50:F53) -> 65 | W20: =SUM(G50:G53) -> 1 | X20: =SUM(H50:H53) -> 0 | Y20: =SUM(I50:I53) -> 12 | Z20: =SUM(J50:J53) -> 10 | ... AF20: =SUM(P50:P53) -> 654
B21: 09.45 - 10.00 | C21: 18 | D21: 4 | E21: 4 | F21: 7 | G21: 0 | H21: 0 | I21: 1 | J21: 1 | K21: 0 | L21: 0 | M21: 39 | N21: 0 | O21: =SUM(C21:L21,N21) -> 35 | P21: =SUM(C21:N21) -> 74 | R21: 1800-1900 | S21: =SUM(C54:C57) -> 204 | T21: =SUM(D54:D57) -> 60 | U21: =SUM(E54:E57) -> 24 | V21: =SUM(F54:F57) -> 38 | W21: =SUM(G54:G57) -> 3 | X21: =SUM(H54:H57) -> 0 | Y21: =SUM(I54:I57) -> 10 | Z21: =SUM(J54:J57) -> 9 | ... AF21: =SUM(P54:P57) -> 598
B22: 10.00 - 10.15 | C22: 26 | D22: 8 | E22: 11 | F22: 13 | G22: 3 | H22: 0 | I22: 1 | J22: 2 | K22: 0 | L22: 1 | M22: 31 | N22: 0 | O22: =SUM(C22:L22,N22) -> 65 | P22: =SUM(C22:N22) -> 96 | R22: AM Peak Hr | S22: =MAX(S10:S12) -> 136 | T22: =MAX(T10:T12) -> 36 | U22: =MAX(U10:U12) -> 21 | V22: =MAX(V10:V12) -> 63 | W22: =MAX(W10:W12) -> 3 | X22: =MAX(X10:X12) -> 1 | Y22: =MAX(Y10:Y12) -> 9 | Z22: =MAX(Z10:Z12) -> 9 | ... AF22: =MAX(AF10:AF12) -> 403
B23: 10.15 - 10.30 | C23: 23 | D23: 7 | E23: 4 | F23: 8 | G23: 1 | H23: 0 | I23: 4 | J23: 3 | K23: 0 | L23: 0 | M23: 40 | N23: 0 | O23: =SUM(C23:L23,N23) -> 50 | P23: =SUM(C23:N23) -> 90 | R23: IP Peak Hr | S23: =MAX(S13:S18) -> 183 | T23: =MAX(T13:T18) -> 46 | U23: =MAX(U13:U18) -> 22 | V23: =MAX(V13:V18) -> 44 | W23: =MAX(W13:W18) -> 7 | X23: =MAX(X13:X18) -> 0 | Y23: =MAX(Y13:Y18) -> 16 | Z23: =MAX(Z13:Z18) -> 12 | ... AF23: =MAX(AF13:AF18) -> 492
B24: 10.30 - 10.45 | C24: 28 | D24: 5 | E24: 1 | F24: 9 | G24: 0 | H24: 0 | I24: 3 | J24: 0 | K24: 0 | L24: 0 | M24: 39 | N24: 0 | O24: =SUM(C24:L24,N24) -> 46 | P24: =SUM(C24:N24) -> 85 | R24: PM Peak Hr | S24: =MAX(S19:S21) -> 226 | T24: =MAX(T19:T21) -> 66 | U24: =MAX(U19:U21) -> 24 | V24: =MAX(V19:V21) -> 65 | W24: =MAX(W19:W21) -> 3 | X24: =MAX(X19:X21) -> 0 | Y24: =MAX(Y19:Y21) -> 12 | Z24: =MAX(Z19:Z21) -> 10 | ... AF24: =MAX(AF19:AF21) -> 654
B25: 10.45 - 11.00 | C25: 25 | D25: 8 | E25: 6 | F25: 10 | G25: 3 | H25: 0 | I25: 2 | J25: 2 | K25: 0 | L25: 0 | M25: 52 | N25: 0 | O25: =SUM(C25:L25,N25) -> 56 | P25: =SUM(C25:N25) -> 108 | R25: AM Period | S25: =SUM(S10:S12) -> 336 | T25: =SUM(T10:T12) -> 99 | U25: =SUM(U10:U12) -> 58 | V25: =SUM(V10:V12) -> 168 | W25: =SUM(W10:W12) -> 7 | X25: =SUM(X10:X12) -> 1 | Y25: =SUM(Y10:Y12) -> 20 | Z25: =SUM(Z10:Z12) -> 24 | ... AF25: =SUM(AF10:AF12) -> 1135
B26: 11.00 - 11.15 | C26: 30 | D26: 5 | E26: 3 | F26: 6 | G26: 0 | H26: 0 | I26: 5 | J26: 4 | K26: 0 | L26: 0 | M26: 41 | N26: 0 | O26: =SUM(C26:L26,N26) -> 53 | P26: =SUM(C26:N26) -> 94 | R26: IP Period | S26: =SUM(S13:S18) -> 823 | T26: =SUM(T13:T18) -> 218 | U26: =SUM(U13:U18) -> 110 | V26: =SUM(V13:V18) -> 231 | W26: =SUM(W13:W18) -> 11 | X26: =SUM(X13:X18) -> 0 | Y26: =SUM(Y13:Y18) -> 67 | Z26: =SUM(Z13:Z18) -> 56 | ... AF26: =SUM(AF13:AF18) -> 2640
B27: 11.15 - 11.30 | C27: 31 | D27: 8 | E27: 2 | F27: 7 | G27: 0 | H27: 0 | I27: 1 | J27: 1 | K27: 0 | L27: 0 | M27: 58 | N27: 0 | O27: =SUM(C27:L27,N27) -> 50 | P27: =SUM(C27:N27) -> 108 | R27: PM Period | S27: =SUM(S19:S21) -> 618 | T27: =SUM(T19:T21) -> 181 | U27: =SUM(U19:U21) -> 56 | V27: =SUM(V19:V21) -> 157 | W27: =SUM(W19:W21) -> 6 | X27: =SUM(X19:X21) -> 0 | Y27: =SUM(Y19:Y21) -> 29 | Z27: =SUM(Z19:Z21) -> 25 | ... AF27: =SUM(AF19:AF21) -> 1808
