Workbook

Sheet 17.10 SSEMBABULE-KANONI
B1: Consultancy services for Preparation of Expressway Development Master Plan (EDMP) for Uganda
B2: MANUAL CLASSIFIED COUNT (MCC)
B3: ROAD NAME: | C3: SSEMBABULE-KABULASOKE ROAD
C5: Date | D5: 17.10.2019 | F5: Location | G5: KYABI | J5: Surveyor | K5: SUSAN
C6: Dir. From | D6: SSEMBABULE | F6: Dir. To | G6: KANONI | J6: Supervisor | K6: ONYUTI BETTY
B8: Time / Veh Type | R8: SUMMARY TRAFFIC VOLUMES
C9: 1. Car | D9: 2. Station Wagon | E9: 3. Pickups | F9: 4. Minibus, matatu | G9: 5. Medium bus | H9: 6. Large Bus | I9: 7. Light Truck | J9: 8. Medium Truck | K9: 9. Heavy truck | L9: 10. Truck Trailer | M9: 11. Motor cycles | N9: 12. Tractors | O9: Total Excl M/Cycles | P9: Total All | R9: Time | S9: 1. Car | T9: 2. Station Wagon | U9: 3. Pickups | V9: 4. Minibus, matatu | W9: 5. Medium bus | X9: 6. Large Bus | Y9: 7. Light Truck | Z9: 8. Medium Truck | AA9: 9. Heavy truck | AB9: 10. Truck Trailer | AC9: 11. Motorcycles | AD9: 12. Tractors, Graders | AE9: Total Excl M/ Cycles | AF9: Total All
B10: 07.00 - 07.15 | C10: 1 | D10: 0 | E10: 0 | F10: 1 | G10: 0 | H10: 0 | I10: 0 | J10: 0 | K10: 0 | L10: 0 | M10: 5 | N10: 0 | O10: =SUM(C10:L10,N10) -> 2 | P10: =SUM(C10:N10) -> 7 | R10: 0700-0800 | S10: =SUM(C10:C13) -> 8 | T10: =SUM(D10:D13) -> 2 | U10: =SUM(E10:E13) -> 1 | V10: =SUM(F10:F13) -> 1 | W10: =SUM(G10:G13) -> 0 | X10: =SUM(H10:H13) -> 0 | Y10: =SUM(I10:I13) -> 3 | Z10: =SUM(J10:J13) -> 0 | ... AF10: =SUM(P10:P13) -> 38
B11: 07.15 - 07.30 | C11: 6 | D11: 1 | E11: 1 | F11: 0 | G11: 0 | H11: 0 | I11: 1 | J11: 0 | K11: 1 | L11: 0 | M11: 2 | N11: 0 | O11: =SUM(C11:L11,N11) -> 10 | P11: =SUM(C11:N11) -> 12 | R11: 0800-0900 | S11: =SUM(C14:C17) -> 3 | T11: =SUM(D14:D17) -> 1 | U11: =SUM(E14:E17) -> 3 | V11: =SUM(F14:F17) -> 1 | W11: =SUM(G14:G17) -> 0 | X11: =SUM(H14:H17) -> 0 | Y11: =SUM(I14:I17) -> 4 | Z11: =SUM(J14:J17) -> 2 | ... AF11: =SUM(P14:P17) -> 40
B12: 07.30 - 07.45 | C12: 0 | D12: 1 | E12: 0 | F12: 0 | G12: 0 | H12: 0 | I12: 2 | J12: 0 | K12: 0 | L12: 0 | M12: 5 | N12: 0 | O12: =SUM(C12:L12,N12) -> 3 | P12: =SUM(C12:N12) -> 8 | R12: 0900-1000 | S12: =SUM(C18:C21) -> 4 | T12: =SUM(D18:D21) -> 3 | U12: =SUM(E18:E21) -> 2 | V12: =SUM(F18:F21) -> 2 | W12: =SUM(G18:G21) -> 0 | X12: =SUM(H18:H21) -> 0 | Y12: =SUM(I18:I21) -> 3 | Z12: =SUM(J18:J21) -> 2 | ... AF12: =SUM(P18:P21) -> 48
B13: 07.45 - 08.00 | C13: 1 | D13: 0 | E13: 0 | F13: 0 | G13: 0 | H13: 0 | I13: 0 | J13: 0 | K13: 1 | L13: 0 | M13: 9 | N13: 0 | O13: =SUM(C13:L13,N13) -> 2 | P13: =SUM(C13:N13) -> 11 | R13: 1000-1100 | S13: =SUM(C22:C25) -> 4 | T13: =SUM(D22:D25) -> 1 | U13: =SUM(E22:E25) -> 5 | V13: =SUM(F22:F25) -> 1 | W13: =SUM(G22:G25) -> 0 | X13: =SUM(H22:H25) -> 0 | Y13: =SUM(I22:I25) -> 3 | Z13: =SUM(J22:J25) -> 1 | ... AF13: =SUM(P22:P25) -> 44
B14: 08.00 - 08.15 | C14: 1 | D14: 1 | E14: 0 | F14: 0 | G14: 0 | H14: 0 | I14: 2 | J14: 1 | K14: 2 | L14: 0 | M14: 5 | N14: 0 | O14: =SUM(C14:L14,N14) -> 7 | P14: =SUM(C14:N14) -> 12 | R14: 1100-1200 | S14: =SUM(C26:C29) -> 4 | T14: =SUM(D26:D29) -> 1 | U14: =SUM(E26:E29) -> 2 | V14: =SUM(F26:F29) -> 1 | W14: =SUM(G26:G29) -> 0 | X14: =SUM(H26:H29) -> 0 | Y14: =SUM(I26:I29) -> 4 | Z14: =SUM(J26:J29) -> 0 | ... AF14: =SUM(P26:P29) -> 46
B15: 08.15 - 08.30 | C15: 1 | D15: 0 | E15: 2 | F15: 0 | G15: 0 | H15: 0 | I15: 0 | J15: 0 | K15: 1 | L15: 0 | M15: 8 | N15: 0 | O15: =SUM(C15:L15,N15) -> 4 | P15: =SUM(C15:N15) -> 12 | R15: 1200-1300 | S15: =SUM(C30:C33) -> 10 | T15: =SUM(D30:D33) -> 0 | U15: =SUM(E30:E33) -> 2 | V15: =SUM(F30:F33) -> 1 | W15: =SUM(G30:G33) -> 0 | X15: =SUM(H30:H33) -> 0 | Y15: =SUM(I30:I33) -> 0 | Z15: =SUM(J30:J33) -> 0 | ... AF15: =SUM(P30:P33) -> 45
B16: 08.30 - 08.45 | C16: 0 | D16: 0 | E16: 0 | F16: 0 | G16: 0 | H16: 0 | I16: 1 | J16: 0 | K16: 0 | L16: 0 | M16: 3 | N16: 0 | O16: =SUM(C16:L16,N16) -> 1 | P16: =SUM(C16:N16) -> 4 | R16: 1300-1400 | S16: =SUM(C34:C37) -> 10 | T16: =SUM(D34:D37) -> 0 | U16: =SUM(E34:E37) -> 1 | V16: =SUM(F34:F37) -> 0 | W16: =SUM(G34:G37) -> 0 | X16: =SUM(H34:H37) -> 0 | Y16: =SUM(I34:I37) -> 0 | Z16: =SUM(J34:J37) -> 1 | ... AF16: =SUM(P34:P37) -> 48
B17: 08.45 - 9.00 | C17: 1 | D17: 0 | E17: 1 | F17: 1 | G17: 0 | H17: 0 | I17: 1 | J17: 1 | K17: 1 | L17: 0 | M17: 6 | N17: 0 | O17: =SUM(C17:L17,N17) -> 6 | P17: =SUM(C17:N17) -> 12 | R17: 1400-1500 | S17: =SUM(C38:C41) -> 3 | T17: =SUM(D38:D41) -> 1 | U17: =SUM(E38:E41) -> 0 | V17: =SUM(F38:F41) -> 4 | W17: =SUM(G38:G41) -> 0 | X17: =SUM(H38:H41) -> 0 | Y17: =SUM(I38:I41) -> 2 | Z17: =SUM(J38:J41) -> 0 | ... AF17: =SUM(P38:P41) -> 50
B18: 09.00 - 09.15 | C18: 2 | D18: 0 | E18: 1 | F18: 1 | G18: 0 | H18: 0 | I18: 0 | J18: 1 | K18: 1 | L18: 0 | M18: 11 | N18: 0 | O18: =SUM(C18:L18,N18) -> 6 | P18: =SUM(C18:N18) -> 17 | R18: 1500-1600 | S18: =SUM(C42:C45) -> 3 | T18: =SUM(D42:D45) -> 0 | U18: =SUM(E42:E45) -> 1 | V18: =SUM(F42:F45) -> 3 | W18: =SUM(G42:G45) -> 0 | X18: =SUM(H42:H45) -> 0 | Y18: =SUM(I42:I45) -> 1 | Z18: =SUM(J42:J45) -> 0 | ... AF18: =SUM(P42:P45) -> 38
B19: 09.15 - 09.30 | C19: 1 | D19: 1 | E19: 1 | F19: 1 | G19: 0 | H19: 0 | I19: 2 | J19: 0 | K19: 1 | L19: 0 | M19: 6 | N19: 0 | O19: =SUM(C19:L19,N19) -> 7 | P19: =SUM(C19:N19) -> 13 | R19: 1600-1700 | S19: =SUM(C46:C49) -> 5 | T19: =SUM(D46:D49) -> 0 | U19: =SUM(E46:E49) -> 1 | V19: =SUM(F46:F49) -> 1 | W19: =SUM(G46:G49) -> 0 | X19: =SUM(H46:H49) -> 0 | Y19: =SUM(I46:I49) -> 2 | Z19: =SUM(J46:J49) -> 0 | ... AF19: =SUM(P46:P49) -> 43
B20: 09.30 - 09.45 | C20: 1 | D20: 0 | E20: 0 | F20: 0 | G20: 0 | H20: 0 | I20: 0 | J20: 0 | K20: 0 | L20: 0 | M20: 5 | N20: 0 | O20: =SUM(C20:L20,N20) -> 1 | P20: =SUM(C20:N20) -> 6 | R20: 1700-1800 | S20: =SUM(C50:C53) -> 13 | T20: =SUM(D50:D53) -> 2 | U20: =SUM(E50:E53) -> 2 | V20: =SUM(F50:F53) -> 9 | W20: =SUM(G50:G53) -> 1 | X20: =SUM(H50:H53) -> 0 | Y20: =SUM(I50:I53) -> 3 | Z20: =SUM(J50:J53) -> 2 | ... AF20: =SUM(P50:P53) -> 78
B21: 09.45 - 10.00 | C21: 0 | D21: 2 | E21: 0 | F21: 0 | G21: 0 | H21: 0 | I21: 1 | J21: 1 | K21: 0 | L21: 0 | M21: 8 | N21: 0 | O21: =SUM(C21:L21,N21) -> 4 | P21: =SUM(C21:N21) -> 12 | R21: 1800-1900 | S21: =SUM(C54:C57) -> 4 | T21: =SUM(D54:D57) -> 7 | U21: =SUM(E54:E57) -> 0 | V21: =SUM(F54:F57) -> 6 | W21: =SUM(G54:G57) -> 1 | X21: =SUM(H54:H57) -> 0 | Y21: =SUM(I54:I57) -> 6 | Z21: =SUM(J54:J57) -> 1 | ... AF21: =SUM(P54:P57) -> 74
B22: 10.00 - 10.15 | C22: 2 | D22: 0 | E22: 1 | F22: 0 | G22: 0 | H22: 0 | I22: 0 | J22: 0 | K22: 0 | L22: 0 | M22: 8 | N22: 0 | O22: =SUM(C22:L22,N22) -> 3 | P22: =SUM(C22:N22) -> 11 | R22: AM Peak Hr | S22: =MAX(S10:S12) -> 8 | T22: =MAX(T10:T12) -> 3 | U22: =MAX(U10:U12) -> 3 | V22: =MAX(V10:V12) -> 2 | W22: =MAX(W10:W12) -> 0 | X22: =MAX(X10:X12) -> 0 | Y22: =MAX(Y10:Y12) -> 4 | Z22: =MAX(Z10:Z12) -> 2 | ... AF22: =MAX(AF10:AF12) -> 48
B23: 10.15 - 10.30 | C23: 1 | D23: 0 | E23: 2 | F23: 1 | G23: 0 | H23: 0 | I23: 0 | J23: 1 | K23: 1 | L23: 0 | M23: 10 | N23: 0 | O23: =SUM(C23:L23,N23) -> 6 | P23: =SUM(C23:N23) -> 16 | R23: IP Peak Hr | S23: =MAX(S13:S18) -> 10 | T23: =MAX(T13:T18) -> 1 | U23: =MAX(U13:U18) -> 5 | V23: =MAX(V13:V18) -> 4 | W23: =MAX(W13:W18) -> 0 | X23: =MAX(X13:X18) -> 0 | Y23: =MAX(Y13:Y18) -> 4 | Z23: =MAX(Z13:Z18) -> 1 | ... AF23: =MAX(AF13:AF18) -> 50
B24: 10.30 - 10.45 | C24: 1 | D24: 1 | E24: 0 | F24: 0 | G24: 0 | H24: 0 | I24: 0 | J24: 0 | K24: 0 | L24: 0 | M24: 5 | N24: 0 | O24: =SUM(C24:L24,N24) -> 2 | P24: =SUM(C24:N24) -> 7 | R24: PM Peak Hr | S24: =MAX(S19:S21) -> 13 | T24: =MAX(T19:T21) -> 7 | U24: =MAX(U19:U21) -> 2 | V24: =MAX(V19:V21) -> 9 | W24: =MAX(W19:W21) -> 1 | X24: =MAX(X19:X21) -> 0 | Y24: =MAX(Y19:Y21) -> 6 | Z24: =MAX(Z19:Z21) -> 2 | ... AF24: =MAX(AF19:AF21) -> 78
B25: 10.45 - 11.00 | C25: 0 | D25: 0 | E25: 2 | F25: 0 | G25: 0 | H25: 0 | I25: 3 | J25: 0 | K25: 0 | L25: 0 | M25: 5 | N25: 0 | O25: =SUM(C25:L25,N25) -> 5 | P25: =SUM(C25:N25) -> 10 | R25: AM Period | S25: =SUM(S10:S12) -> 15 | T25: =SUM(T10:T12) -> 6 | U25: =SUM(U10:U12) -> 6 | V25: =SUM(V10:V12) -> 4 | W25: =SUM(W10:W12) -> 0 | X25: =SUM(X10:X12) -> 0 | Y25: =SUM(Y10:Y12) -> 10 | Z25: =SUM(Z10:Z12) -> 4 | ... AF25: =SUM(AF10:AF12) -> 126
B26: 11.00 - 11.15 | C26: 0 | D26: 1 | E26: 0 | F26: 0 | G26: 0 | H26: 0 | I26: 2 | J26: 0 | K26: 1 | L26: 0 | M26: 6 | N26: 0 | O26: =SUM(C26:L26,N26) -> 4 | P26: =SUM(C26:N26) -> 10 | R26: IP Period | S26: =SUM(S13:S18) -> 34 | T26: =SUM(T13:T18) -> 3 | U26: =SUM(U13:U18) -> 11 | V26: =SUM(V13:V18) -> 10 | W26: =SUM(W13:W18) -> 0 | X26: =SUM(X13:X18) -> 0 | Y26: =SUM(Y13:Y18) -> 10 | Z26: =SUM(Z13:Z18) -> 2 | ... AF26: =SUM(AF13:AF18) -> 271
B27: 11.15 - 11.30 | C27: 2 | D27: 0 | E27: 1 | F27: 1 | G27: 0 | H27: 0 | I27: 0 | J27: 0 | K27: 0 | L27: 0 | M27: 10 | N27: 0 | O27: =SUM(C27:L27,N27) -> 4 | P27: =SUM(C27:N27) -> 14 | R27: PM Period | S27: =SUM(S19:S21) -> 22 | T27: =SUM(T19:T21) -> 9 | U27: =SUM(U19:U21) -> 3 | V27: =SUM(V19:V21) -> 16 | W27: =SUM(W19:W21) -> 2 | X27: =SUM(X19:X21) -> 0 | Y27: =SUM(Y19:Y21) -> 11 | Z27: =SUM(Z19:Z21) -> 3 | ... AF27: =SUM(AF19:AF21) -> 195
B28: 11.30 - 11.45 | C28: 0 | D28: 0 | E28: 1 | F28: 0 | G28: 0 | H28: 0 | I28: 2 | J28: 0 | K28: 2 | L28: 0 | M28: 9 | N28: 0 | O28: =SUM(C28:L28,N28) -> 5 | P28: =SUM(C28:N28) -> 14 | R28: 12 Hours | S28: =SUM(S10:S21) -> 71 | T28: =SUM(T10:T21) -> 18 | U28: =SUM(U10:U21) -> 20 | V28: =SUM(V10:V21) -> 30 | W28: =SUM(W10:W21) -> 2 | X28: =SUM(X10:X21) -> 0 | Y28: =SUM(Y10:Y21) -> 31 | Z28: =SUM(Z10:Z21) -> 9 | ... AF28: =SUM(AF10:AF21) -> 592
B29: 11.45 - 12.00 | C29: 2 | D29: 0 | E29: 0 | F29: 0 | G29: 0 | H29: 0 | I29: 0 | J29: 0 | K29: 1 | L29: 0 | M29: 5 | N29: 0 | O29: =SUM(C29:L29,N29) -> 3 | P29: =SUM(C29:N29) -> 8
B30: 12.00 - 12.15 | C30: 2 | D30: 0 | E30: 0 | F30: 1 | G30: 0 | H30: 0 | I30: 0 | J30: 0 | K30: 0 | L30: 0 | M30: 7 | N30: 0 | O30: =SUM(C30:L30,N30) -> 3 | P30: =SUM(C30:N30) -> 10
B31: 12.15 - 12.30 | C31: 5 | D31: 0 | E31: 0 | F31: 0 | G31: 0 | H31: 0 | I31: 0 | J31: 0 | K31: 0 | L31: 0 | M31: 10 | N31: 0 | O31: =SUM(C31:L31,N31) -> 5 | P31: =SUM(C31:N31) -> 15
B32: 12.30 - 12.45 | C32: 1 | D32: 0 | E32: 1 | F32: 0 | G32: 0 | H32: 0 | I32: 0 | J32: 0 | K32: 1 | L32: 0 | M32: 6 | N32: 0 | O32: =SUM(C32:L32,N32) -> 3 | P32: =SUM(C32:N32) -> 9
B33: 12.45 - 13.00 | C33: 2 | D33: 0 | E33: 1 | F33: 0 | G33: 0 | H33: 0 | I33: 0 | J33: 0 | K33: 0 | L33: 0 | M33: 8 | N33: 0 | O33: =SUM(C33:L33,N33) -> 3 | P33: =SUM(C33:N33) -> 11
B34: 13.00 - 13.15 | C34: 3 | D34: 0 | E34: 0 | F34: 0 | G34: 0 | H34: 0 | I34: 0 | J34: 0 | K34: 0 | L34: 0 | M34: 5 | N34: 0 | O34: =SUM(C34:L34,N34) -> 3 | P34: =SUM(C34:N34) -> 8
B35: 13.15 - 13.30 | C35: 2 | D35: 0 | E35: 0 | F35: 0 | G35: 0 | H35: 0 | I35: 0 | J35: 1 | K35: 0 | L35: 0 | M35: 6 | N35: 0 | O35: =SUM(C35:L35,N35) -> 3 | P35: =SUM(C35:N35) -> 9
B36: 13.30 - 13.45 | C36: 4 | D36: 0 | E36: 1 | F36: 0 | G36: 0 | H36: 0 | I36: 0 | J36: 0 | K36: 0 | L36: 0 | M36: 15 | N36: 0 | O36: =SUM(C36:L36,N36) -> 5 | P36: =SUM(C36:N36) -> 20
B37: 13.45 - 14.00 | C37: 1 | D37: 0 | E37: 0 | F37: 0 | G37: 0 | H37: 0 | I37: 0 | J37: 0 | K37: 1 | L37: 0 | M37: 9 | N37: 0 | O37: =SUM(C37:L37,N37) -> 2 | P37: =SUM(C37:N37) -> 11
B38: 14.00 - 14.15 | C38: 0 | D38: 1 | E38: 0 | F38: 2 | G38: 0 | H38: 0 | I38: 1 | J38: 0 | K38: 0 | L38: 1 | M38: 12 | N38: 0 | O38: =SUM(C38:L38,N38) -> 5 | P38: =SUM(C38:N38) -> 17
B39: 14.15 - 14.30 | C39: 1 | D39: 0 | E39: 0 | F39: 0 | G39: 0 | H39: 0 | I39: 0 | J39: 0 | K39: 0 | L39: 0 | M39: 4 | N39: 0 | O39: =SUM(C39:L39,N39) -> 1 | P39: =SUM(C39:N39) -> 5
B40: 14.30 - 14.45 | C40: 1 | D40: 0 | E40: 0 | F40: 1 | G40: 0 | H40: 0 | I40: 0 | J40: 0 | K40: 0 | L40: 0 | M40: 8 | N40: 0 | O40: =SUM(C40:L40,N40) -> 2 | P40: =SUM(C40:N40) -> 10
... B57: 18.45 - 19.00 | C57: 1 | D57: 2 | E57: 0 | F57: 1 | G57: 0 | H57: 0 | I57: 1 | J57: 1 | K57: 0 | L57: 0 | M57: 6 | N57: 0 | O57: =SUM(C57:L57,N57) -> 6 | P57: =SUM(C57:N57) -> 12
B58: Totals | C58: =SUM(C10:C57) -> 71 | D58: =SUM(D10:D57) -> 18 | E58: =SUM(E10:E57) -> 20 | F58: =SUM(F10:F57) -> 30 | G58: =SUM(G10:G57) -> 2 | H58: =SUM(H10:H57) -> 0 | I58: =SUM(I10:I57) -> 31 | J58: =SUM(J10:J57) -> 9 | ... P58: =SUM(P10:P57) -> 592
...

Sheet 17.10 KANONI-SSEMBABULE
B1: Consultancy services for Preparation of Expressway Development Master Plan (EDMP) for Uganda
B2: MANUAL CLASSIFIED COUNT (MCC)
B3: ROAD NAME: | C3: ='17.10 SSEMBABULE-KANONI'!C3:G3 -> SSEMBABULE-KABULASOKE ROAD
C5: Date | D5: ='17.10 SSEMBABULE-KANONI'!D5 -> 17.10.2019 | F5: Location | G5: ='17.10 SSEMBABULE-KANONI'!G5:H5 -> KYABI | J5: Surveyor | K5: NAMUDDU MARIAM
C6: Dir. From | D6: Makindye | F6: Dir. To | G6: Kibuye | J6: Supervisor | K6: ='17.10 SSEMBABULE-KANONI'!K6:L6 -> ONYUTI BETTY
B8: Time / Veh Type | R8: SUMMARY TRAFFIC VOLUMES
C9: 1. Car | D9: 2. Station Wagon | E9: 3. Pickups | F9: 4. Minibus, matatu | G9: 5. Medium bus | H9: 6. Large Bus | I9: 7. Light Truck | J9: 8. Medium Truck | K9: 9. Heavy truck | L9: 10. Truck Trailer | M9: 11. Motor cycles | N9: 12. Tractors | O9: Total Excl M/Cycles | P9: Total All | R9: Time | S9: 1. Car | T9: 2. Station Wagon | U9: 3. Pickups | V9: 4. Minibus, matatu | W9: 5. Medium bus | X9: 6. Large Bus | Y9: 7. Light Truck | Z9: 8. Medium Truck | AA9: 9. Heavy truck | AB9: 10. Truck Trailer | AC9: 11. Motorcycles | AD9: 12. Tractors, Graders | AE9: Total Excl M/ Cycles | AF9: Total All
B10: 07.00 - 07.15 | C10: 0 | D10: 0 | E10: 0 | F10: 0 | G10: 0 | H10: 0 | I10: 1 | J10: 0 | K10: 0 | L10: 0 | M10: 6 | N10: 0 | O10: =SUM(C10:L10,N10) -> 1 | P10: =SUM(C10:N10) -> 7 | R10: 0700-0800 | S10: =SUM(C10:C13) -> 3 | T10: =SUM(D10:D13) -> 1 | U10: =SUM(E10:E13) -> 2 | V10: =SUM(F10:F13) -> 1 | W10: =SUM(G10:G13) -> 0 | X10: =SUM(H10:H13) -> 0 | Y10: =SUM(I10:I13) -> 5 | Z10: =SUM(J10:J13) -> 1 | ... AF10: =SUM(P10:P13) -> 40
B11: 07.15 - 07.30 | C11: 0 | D11: 0 | E11: 0 | F11: 0 | G11: 0 | H11: 0 | I11: 0 | J11: 0 | K11: 0 | L11: 0 | M11: 2 | N11: 0 | O11: =SUM(C11:L11,N11) -> 0 | P11: =SUM(C11:N11) -> 2 | R11: 0800-0900 | S11: =SUM(C14:C17) -> 3 | T11: =SUM(D14:D17) -> 0 | U11: =SUM(E14:E17) -> 0 | V11: =SUM(F14:F17) -> 7 | W11: =SUM(G14:G17) -> 0 | X11: =SUM(H14:H17) -> 0 | Y11: =SUM(I14:I17) -> 0 | Z11: =SUM(J14:J17) -> 0 | ... AF11: =SUM(P14:P17) -> 31
B12: 07.30 - 07.45 | C12: 2 | D12: 0 | E12: 2 | F12: 0 | G12: 0 | H12: 0 | I12: 2 | J12: 1 | K12: 0 | L12: 0 | M12: 10 | N12: 0 | O12: =SUM(C12:L12,N12) -> 7 | P12: =SUM(C12:N12) -> 17 | R12: 0900-1000 | S12: =SUM(C18:C21) -> 3 | T12: =SUM(D18:D21) -> 0 | U12: =SUM(E18:E21) -> 2 | V12: =SUM(F18:F21) -> 2 | W12: =SUM(G18:G21) -> 0 | X12: =SUM(H18:H21) -> 0 | Y12: =SUM(I18:I21) -> 1 | Z12: =SUM(J18:J21) -> 0 | ... AF12: =SUM(P18:P21) -> 41
B13: 07.45 - 08.00 | C13: 1 | D13: 1 | E13: 0 | F13: 1 | G13: 0 | H13: 0 | I13: 2 | J13: 0 | K13: 0 | L13: 0 | M13: 9 | N13: 0 | O13: =SUM(C13:L13,N13) -> 5 | P13: =SUM(C13:N13) -> 14 | R13: 1000-1100 | S13: =SUM(C22:C25) -> 2 | T13: =SUM(D22:D25) -> 2 | U13: =SUM(E22:E25) -> 0 | V13: =SUM(F22:F25) -> 0 | W13: =SUM(G22:G25) -> 0 | X13: =SUM(H22:H25) -> 0 | Y13: =SUM(I22:I25) -> 1 | Z13: =SUM(J22:J25) -> 0 | ... AF13: =SUM(P22:P25) -> 38
B14: 08.00 - 08.15 | C14: 1 | D14: 0 | E14: 0 | F14: 2 | G14: 0 | H14: 0 | I14: 0 | J14: 0 | K14: 0 | L14: 0 | M14: 6 | N14: 0 | O14: =SUM(C14:L14,N14) -> 3 | P14: =SUM(C14:N14) -> 9 | R14: 1100-1200 | S14: =SUM(C26:C29) -> 6 | T14: =SUM(D26:D29) -> 2 | U14: =SUM(E26:E29) -> 1 | V14: =SUM(F26:F29) -> 4 | W14: =SUM(G26:G29) -> 0 | X14: =SUM(H26:H29) -> 0 | Y14: =SUM(I26:I29) -> 1 | Z14: =SUM(J26:J29) -> 0 | ... AF14: =SUM(P26:P29) -> 51
B15: 08.15 - 08.30 | C15: 1 | D15: 0 | E15: 0 | F15: 2 | G15: 0 | H15: 0 | I15: 0 | J15: 0 | K15: 0 | L15: 0 | M15: 5 | N15: 0 | O15: =SUM(C15:L15,N15) -> 3 | P15: =SUM(C15:N15) -> 8 | R15: 1200-1300 | S15: =SUM(C30:C33) -> 13 | T15: =SUM(D30:D33) -> 0 | U15: =SUM(E30:E33) -> 2 | V15: =SUM(F30:F33) -> 3 | W15: =SUM(G30:G33) -> 0 | X15: =SUM(H30:H33) -> 0 | Y15: =SUM(I30:I33) -> 2 | Z15: =SUM(J30:J33) -> 2 | ... AF15: =SUM(P30:P33) -> 65
B16: 08.30 - 08.45 | C16: 0 | D16: 0 | E16: 0 | F16: 1 | G16: 0 | H16: 0 | I16: 0 | J16: 0 | K16: 0 | L16: 0 | M16: 4 | N16: 0 | O16: =SUM(C16:L16,N16) -> 1 | P16: =SUM(C16:N16) -> 5 | R16: 1300-1400 | S16: =SUM(C34:C37) -> 9 | T16: =SUM(D34:D37) -> 0 | U16: =SUM(E34:E37) -> 2 | V16: =SUM(F34:F37) -> 5 | W16: =SUM(G34:G37) -> 1 | X16: =SUM(H34:H37) -> 0 | Y16: =SUM(I34:I37) -> 4 | Z16: =SUM(J34:J37) -> 2 | ... AF16: =SUM(P34:P37) -> 66
B17: 08.45 - 9.00 | C17: 1 | D17: 0 | E17: 0 | F17: 2 | G17: 0 | H17: 0 | I17: 0 | J17: 0 | K17: 0 | L17: 0 | M17: 6 | N17: 0 | O17: =SUM(C17:L17,N17) -> 3 | P17: =SUM(C17:N17) -> 9 | R17: 1400-1500 | S17: =SUM(C38:C41) -> 2 | T17: =SUM(D38:D41) -> 0 | U17: =SUM(E38:E41) -> 1 | V17: =SUM(F38:F41) -> 2 | W17: =SUM(G38:G41) -> 0 | X17: =SUM(H38:H41) -> 0 | Y17: =SUM(I38:I41) -> 3 | Z17: =SUM(J38:J41) -> 0 | ... AF17: =SUM(P38:P41) -> 62
B18: 09.00 - 09.15 | C18: 1 | D18: 0 | E18: 1 | F18: 1 | G18: 0 | H18: 0 | I18: 0 | J18: 0 | K18: 0 | L18: 0 | M18: 6 | N18: 0 | O18: =SUM(C18:L18,N18) -> 3 | P18: =SUM(C18:N18) -> 9 | R18: 1500-1600 | S18: =SUM(C42:C45) -> 6 | T18: =SUM(D42:D45) -> 0 | U18: =SUM(E42:E45) -> 2 | V18: =SUM(F42:F45) -> 1 | W18: =SUM(G42:G45) -> 0 | X18: =SUM(H42:H45) -> 0 | Y18: =SUM(I42:I45) -> 2 | Z18: =SUM(J42:J45) -> 1 | ... AF18: =SUM(P42:P45) -> 56
B19: 09.15 - 09.30 | C19: 1 | D19: 0 | E19: 1 | F19: 0 | G19: 0 | H19: 0 | I19: 1 | J19: 0 | K19: 0 | L19: 0 | M19: 5 | N19: 0 | O19: =SUM(C19:L19,N19) -> 3 | P19: =SUM(C19:N19) -> 8 | R19: 1600-1700 | S19: =SUM(C46:C49) -> 3 | T19: =SUM(D46:D49) -> 2 | U19: =SUM(E46:E49) -> 1 | V19: =SUM(F46:F49) -> 0 | W19: =SUM(G46:G49) -> 1 | X19: =SUM(H46:H49) -> 0 | Y19: =SUM(I46:I49) -> 3 | Z19: =SUM(J46:J49) -> 1 | ... AF19: =SUM(P46:P49) -> 48
B20: 09.30 - 09.45 | C20: 0 | D20: 0 | E20: 0 | F20: 1 | G20: 0 | H20: 0 | I20: 0 | J20: 0 | K20: 3 | L20: 0 | M20: 9 | N20: 0 | O20: =SUM(C20:L20,N20) -> 4 | P20: =SUM(C20:N20) -> 13 | R20: 1700-1800 | S20: =SUM(C50:C53) -> 7 | T20: =SUM(D50:D53) -> 0 | U20: =SUM(E50:E53) -> 0 | V20: =SUM(F50:F53) -> 1 | W20: =SUM(G50:G53) -> 0 | X20: =SUM(H50:H53) -> 0 | Y20: =SUM(I50:I53) -> 6 | Z20: =SUM(J50:J53) -> 5 | ... AF20: =SUM(P50:P53) -> 54
B21: 09.45 - 10.00 | C21: 1 | D21: 0 | E21: 0 | F21: 0 | G21: 0 | H21: 0 | I21: 0 | J21: 0 | K21: 1 | L21: 0 | M21: 9 | N21: 0 | O21: =SUM(C21:L21,N21) -> 2 | P21: =SUM(C21:N21) -> 11 | R21: 1800-1900 | S21: =SUM(C54:C57) -> 2 | T21: =SUM(D54:D57) -> 1 | U21: =SUM(E54:E57) -> 1 | V21: =SUM(F54:F57) -> 4 | W21: =SUM(G54:G57) -> 1 | X21: =SUM(H54:H57) -> 0 | Y21: =SUM(I54:I57) -> 5 | Z21: =SUM(J54:J57) -> 2 | ... AF21: =SUM(P54:P57) -> 72
B22: 10.00 - 10.15 | C22: 0 | D22: 0 | E22: 0 | F22: 0 | G22: 0 | H22: 0 | I22: 0 | J22: 0 | K22: 2 | L22: 0 | M22: 11 | N22: 0 | O22: =SUM(C22:L22,N22) -> 2 | P22: =SUM(C22:N22) -> 13 | R22: AM Peak Hr | S22: =MAX(S10:S12) -> 3 | T22: =MAX(T10:T12) -> 1 | U22: =MAX(U10:U12) -> 2 | V22: =MAX(V10:V12) -> 7 | W22: =MAX(W10:W12) -> 0 | X22: =MAX(X10:X12) -> 0 | Y22: =MAX(Y10:Y12) -> 5 | Z22: =MAX(Z10:Z12) -> 1 | ... AF22: =MAX(AF10:AF12) -> 41
B23: 10.15 - 10.30 | C23: 0 | D23: 1 | E23: 0 | F23: 0 | G23: 0 | H23: 0 | I23: 0 | J23: 0 | K23: 1 | L23: 0 | M23: 6 | N23: 0 | O23: =SUM(C23:L23,N23) -> 2 | P23: =SUM(C23:N23) -> 8 | R23: IP Peak Hr | S23: =MAX(S13:S18) -> 13 | T23: =MAX(T13:T18) -> 2 | U23: =MAX(U13:U18) -> 2 | V23: =MAX(V13:V18) -> 5 | W23: =MAX(W13:W18) -> 1 | X23: =MAX(X13:X18) -> 0 | Y23: =MAX(Y13:Y18) -> 4 | Z23: =MAX(Z13:Z18) -> 2 | ... AF23: =MAX(AF13:AF18) -> 66
B24: 10.30 - 10.45 | C24: 1 | D24: 0 | E24: 0 | F24: 0 | G24: 0 | H24: 0 | I24: 0 | J24: 0 | K24: 1 | L24: 0 | M24: 7 | N24: 0 | O24: =SUM(C24:L24,N24) -> 2 | P24: =SUM(C24:N24) -> 9 | R24: PM Peak Hr | S24: =MAX(S19:S21) -> 7 | T24: =MAX(T19:T21) -> 2 | U24: =MAX(U19:U21) -> 1 | V24: =MAX(V19:V21) -> 4 | W24: =MAX(W19:W21) -> 1 | X24: =MAX(X19:X21) -> 0 | Y24: =MAX(Y19:Y21) -> 6 | Z24: =MAX(Z19:Z21) -> 5 | ... AF24: =MAX(AF19:AF21) -> 72
B25: 10.45 - 11.00 | C25: 1 | D25: 1 | E25: 0 | F25: 0 | G25: 0 | H25: 0 | I25: 1 | J25: 0 | K25: 0 | L25: 0 | M25: 5 | N25: 0 | O25: =SUM(C25:L25,N25) -> 3 | P25: =SUM(C25:N25) -> 8 | R25: AM Period | S25: =SUM(S10:S12) -> 9 | T25: =SUM(T10:T12) -> 1 | U25: =SUM(U10:U12) -> 4 | V25: =SUM(V10:V12) -> 10 | W25: =SUM(W10:W12) -> 0 | X25: =SUM(X10:X12) -> 0 | Y25: =SUM(Y10:Y12) -> 6 | Z25: =SUM(Z10:Z12) -> 1 | ... AF25: =SUM(AF10:AF12) -> 112
B26: 11.00 - 11.15 | C26: 1 | D26: 1 | E26: 0 | F26: 1 | G26: 0 | H26: 0 | I26: 0 | J26: 0 | K26: 0 | L26: 0 | M26: 10 | N26: 0 | O26: =SUM(C26:L26,N26) -> 3 | P26: =SUM(C26:N26) -> 13 | R26: IP Period | S26: =SUM(S13:S18) -> 38 | T26: =SUM(T13:T18) -> 4 | U26: =SUM(U13:U18) -> 8 | V26: =SUM(V13:V18) -> 15 | W26: =SUM(W13:W18) -> 1 | X26: =SUM(X13:X18) -> 0 | Y26: =SUM(Y13:Y18) -> 13 | Z26: =SUM(Z13:Z18) -> 5 | ... AF26: =SUM(AF13:AF18) -> 338
B27: 11.15 - 11.30 | C27: 1 | D27: 1 | E27: 0 | F27: 0 | G27: 0 | H27: 0 | I27: 0 | J27: 0 | K27: 0 | L27: 0 | M27: 13 | N27: 0 | O27: =SUM(C27:L27,N27) -> 2 | P27: =SUM(C27:N27) -> 15 | R27: PM Period | S27: =SUM(S19:S21) -> 12 | T27: =SUM(T19:T21) -> 3 | U27: =SUM(U19:U21) -> 2 | V27: =SUM(V19:V21) -> 5 | W27: =SUM(W19:W21) -> 2 | X27: =SUM(X19:X21) -> 0 | Y27: =SUM(Y19:Y21) -> 14 | Z27: =SUM(Z19:Z21) -> 8 | ... AF27: =SUM(AF19:AF21) -> 174
B28: 11.30 - 11.45 | C28: 3 | D28: 0 | E28: 0 | F28: 0 | G28: 0 | H28: 0 | I28: 0 | J28: 0 | K28: 0 | L28: 0 | M28: 5 | N28: 0 | O28: =SUM(C28:L28,N28) -> 3 | P28: =SUM(C28:N28) -> 8 | R28: 12 Hours | S28: =SUM(S10:S21) -> 59 | T28: =SUM(T10:T21) -> 8 | U28: =SUM(U10:U21) -> 14 | V28: =SUM(V10:V21) -> 30 | W28: =SUM(W10:W21) -> 3 | X28: =SUM(X10:X21) -> 0 | Y28: =SUM(Y10:Y21) -> 33 | Z28: =SUM(Z10:Z21) -> 14 | ... AF28: =SUM(AF10:AF21) -> 624
B29: 11.45 - 12.00 | C29: 1 | D29: 0 | E29: 1 | F29: 3 | G29: 0 | H29: 0 | I29: 1 | J29: 0 | K29: 0 | L29: 0 | M29: 9 | N29: 0 | O29: =SUM(C29:L29,N29) -> 6 | P29: =SUM(C29:N29) -> 15
B30: 12.00 - 12.15 | C30: 2 | D30: 0 | E30: 0 | F30: 2 | G30: 0 | H30: 0 | I30: 0 | J30: 0 | K30: 1 | L30: 0 | M30: 5 | N30: 0 | O30: =SUM(C30:L30,N30) -> 5 | P30: =SUM(C30:N30) -> 10
B31: 12.15 - 12.30 | C31: 5 | D31: 0 | E31: 2 | F31: 0 | G31: 0 | H31: 0 | I31: 0 | J31: 1 | K31: 2 | L31: 0 | M31: 13 | N31: 0 | O31: =SUM(C31:L31,N31) -> 10 | P31: =SUM(C31:N31) -> 23
B32: 12.30 - 12.45 | C32: 2 | D32: 0 | E32: 0 | F32: 1 | G32: 0 | H32: 0 | I32: 0 | J32: 0 | K32: 1 | L32: 0 | M32: 6 | N32: 0 | O32: =SUM(C32:L32,N32) -> 4 | P32: =SUM(C32:N32) -> 10
B33: 12.45 - 13.00 | C33: 4 | D33: 0 | E33: 0 | F33: 0 | G33: 0 | H33: 0 | I33: 2 | J33: 1 | K33: 0 | L33: 0 | M33: 15 | N33: 0 | O33: =SUM(C33:L33,N33) -> 7 | P33: =SUM(C33:N33) -> 22
B34: 13.00 - 13.15 | C34: 1 | D34: 0 | E34: 1 | F34: 0 | G34: 0 | H34: 0 | I34: 0 | J34: 1 | K34: 0 | L34: 0 | M34: 11 | N34: 0 | O34: =SUM(C34:L34,N34) -> 3 | P34: =SUM(C34:N34) -> 14
B35: 13.15 - 13.30 | C35: 3 | D35: 0 | E35: 0 | F35: 0 | G35: 1 | H35: 0 | I35: 0 | J35: 1 | K35: 0 | L35: 0 | M35: 6 | N35: 0 | O35: =SUM(C35:L35,N35) -> 5 | P35: =SUM(C35:N35) -> 11
B36: 13.30 - 13.45 | C36: 4 | D36: 0 | E36: 0 | F36: 2 | G36: 0 | H36: 0 | I36: 2 | J36: 0 | K36: 0 | L36: 1 | M36: 12 | N36: 0 | O36: =SUM(C36:L36,N36) -> 9 | P36: =SUM(C36:N36) -> 21
B37: 13.45 - 14.00 | C37: 1 | D37: 0 | E37: 1 | F37: 3 | G37: 0 | H37: 0 | I37: 2 | J37: 0 | K37: 0 | L37: 0 | M37: 13 | N37: 0 | O37: =SUM(C37:L37,N37) -> 7 | P37: =SUM(C37:N37) -> 20
B38: 14.00 - 14.15 | C38: 1 | D38: 0 | E38: 0 | F38: 1 | G38: 0 | H38: 0 | I38: 1 | J38: 0 | K38: 11 | L38: 1 | M38: 6 | N38: 0 | O38: =SUM(C38:L38,N38) -> 15 | P38: =SUM(C38:N38) -> 21
B39: 14.15 - 14.30 | C39: 1 | D39: 0 | E39: 0 | F39: 1 | G39: 0 | H39: 0 | I39: 0 | J39: 0 | K39: 0 | L39: 0 | M39: 11 | N39: 0 | O39: =SUM(C39:L39,N39) -> 2 | P39: =SUM(C39:N39) -> 13
B40: 14.30 - 14.45 | C40: 0 | D40: 0 | E40: 0 | F40: 0 | G40: 0 | H40: 0 | I40: 0 | J40: 0 | K40: 1 | L40: 0 | M40: 7 | N40: 0 | O40: =SUM(C40:L40,N40) -> 1 | P40: =SUM(C40:N40) -> 8
... B57: 18.45 - 19.00 | C57: 0 | D57: 0 | E57: 0 | F57: 0 | G57: 0 | H57: 0 | I57: 0 | J57: 0 | K57: 0 | L57: 0 | M57: 16 | N57: 0 | O57: =SUM(C57:L57,N57) -> 0 | P57: =SUM(C57:N57) -> 16
B58: Totals | C58: =SUM(C10:C57) -> 59 | D58: =SUM(D10:D57) -> 8 | E58: =SUM(E10:E57) -> 14 | F58: =SUM(F10:F57) -> 30 | G58: =SUM(G10:G57) -> 3 | H58: =SUM(H10:H57) -> 0 | I58: =SUM(I10:I57) -> 33 | J58: =SUM(J10:J57) -> 14 | ... P58: =SUM(P10:P57) -> 624
...

Sheet 18.10 SSEMBABULE-KANONI-24h
B1: Consultancy services for Preparation of Expressway Development Master Plan (EDMP) for Uganda
B2: MANUAL CLASSIFIED COUNT (MCC)
B3: ROAD NAME: | C3: ='17.10 SSEMBABULE-KANONI'!C3:G3 -> SSEMBABULE-KABULASOKE ROAD
C5: Date | D5: 18.10.2019 | F5: Location | G5: ='22.10 KANONI-SSEMBABULE'!G5:H5 -> KYABI | J5: Surveyor | K5: VIOLA
C6: Dir. From | D6: ='17.10 SSEMBABULE-KANONI'!D6:E6 -> SSEMBABULE | F6: Dir. To | G6: ='17.10 SSEMBABULE-KANONI'!G6:H6 -> KANONI | J6: Supervisor | K6: ='22.10 KANONI-SSEMBABULE'!K6:L6 -> ONYUTI BETTY
B8: Time / Veh Type | R8: SUMMARY TRAFFIC VOLUMES
C9: 1. Car | D9: 2. Station Wagon | E9: 3. Pickups | F9: 4. Minibus, matatu | G9: 5. Medium bus | H9: 6. Large Bus | I9: 7. Light Truck | J9: 8. Medium Truck | K9: 9. Heavy truck | L9: 10. Truck Trailer | M9: 11. Motor cycles | N9: 12. Tractors | O9: Total Excl M/Cycles | P9: Total All | R9: Time | S9: 1. Car | T9: 2. Station Wagon | U9: 3. Pickups | V9: 4. Minibus, matatu | W9: 5. Medium bus | X9: 6. Large Bus | Y9: 7. Light Truck | Z9: 8. Medium Truck | AA9: 9. Heavy truck | AB9: 10. Truck Trailer | AC9: 11. Motorcycles | AD9: 12. Tractors, Graders | AE9: Total Excl M/ Cycles | AF9: Total All
B10: 07.00 - 07.15 | C10: 1 | D10: 1 | E10: 0 | F10: 3 | G10: 0 | H10: 0 | I10: 1 | J10: 0 | K10: 0 | L10: 0 | M10: 8 | N10: 0 | O10: =SUM(C10:L10,N10) -> 6 | P10: =SUM(C10:N10) -> 14 | R10: 0700-0800 | S10: =SUM(C10:C13) -> 3 | T10: =SUM(D10:D13) -> 3 | U10: =SUM(E10:E13) -> 1 | V10: =SUM(F10:F13) -> 5 | W10: =SUM(G10:G13) -> 0 | X10: =SUM(H10:H13) -> 0 | Y10: =SUM(I10:I13) -> 2 | Z10: =SUM(J10:J13) -> 0 | ... AF10: =SUM(P10:P13) -> 39
B11: 07.15 - 07.30 | C11: 0 | D11: 0 | E11: 1 | F11: 1 | G11: 0 | H11: 0 | I11: 1 | J11: 0 | K11: 0 | L11: 0 | M11: 8 | N11: 0 | O11: =SUM(C11:L11,N11) -> 3 | P11: =SUM(C11:N11) -> 11 | R11: 0800-0900 | S11: =SUM(C14:C17) -> 4 | T11: =SUM(D14:D17) -> 3 | U11: =SUM(E14:E17) -> 0 | V11: =SUM(F14:F17) -> 2 | W11: =SUM(G14:G17) -> 2 | X11: =SUM(H14:H17) -> 0 | Y11: =SUM(I14:I17) -> 4 | Z11: =SUM(J14:J17) -> 2 | ... AF11: =SUM(P14:P17) -> 36
B12: 07.30 - 07.45 | C12: 0 | D12: 2 | E12: 0 | F12: 1 | G12: 0 | H12: 0 | I12: 0 | J12: 0 | K12: 0 | L12: 0 | M12: 5 | N12: 0 | O12: =SUM(C12:L12,N12) -> 3 | P12: =SUM(C12:N12) -> 8 | R12: 0900-1000 | S12: =SUM(C18:C21) -> 1 | T12: =SUM(D18:D21) -> 2 | U12: =SUM(E18:E21) -> 1 | V12: =SUM(F18:F21) -> 2 | W12: =SUM(G18:G21) -> 2 | X12: =SUM(H18:H21) -> 0 | Y12: =SUM(I18:I21) -> 3 | Z12: =SUM(J18:J21) -> 0 | ... AF12: =SUM(P18:P21) -> 32
B13: 07.45 - 08.00 | C13: 2 | D13: 0 | E13: 0 | F13: 0 | G13: 0 | H13: 0 | I13: 0 | J13: 0 | K13: 0 | L13: 0 | M13: 4 | N13: 0 | O13: =SUM(C13:L13,N13) -> 2 | P13: =SUM(C13:N13) -> 6 | R13: 1000-1100 | S13: =SUM(C22:C25) -> 2 | T13: =SUM(D22:D25) -> 7 | U13: =SUM(E22:E25) -> 1 | V13: =SUM(F22:F25) -> 0 | W13: =SUM(G22:G25) -> 0 | X13: =SUM(H22:H25) -> 0 | Y13: =SUM(I22:I25) -> 4 | Z13: =SUM(J22:J25) -> 1 | ... AF13: =SUM(P22:P25) -> 45
B14: 08.00 - 08.15 | C14: 0 | D14: 0 | E14: 0 | F14: 0 | G14: 0 | H14: 0 | I14: 0 | J14: 0 | K14: 1 | L14: 0 | M14: 4 | N14: 0 | O14: =SUM(C14:L14,N14) -> 1 | P14: =SUM(C14:N14) -> 5 | R14: 1100-1200 | S14: =SUM(C26:C29) -> 5 | T14: =SUM(D26:D29) -> 2 | U14: =SUM(E26:E29) -> 1 | V14: =SUM(F26:F29) -> 0 | W14: =SUM(G26:G29) -> 0 | X14: =SUM(H26:H29) -> 0 | Y14: =SUM(I26:I29) -> 4 | Z14: =SUM(J26:J29) -> 2 | ... AF14: =SUM(P26:P29) -> 34
B15: 08.15 - 08.30 | C15: 2 | D15: 0 | E15: 0 | F15: 1 | G15: 0 | H15: 0 | I15: 2 | J15: 1 | K15: 0 | L15: 0 | M15: 5 | N15: 0 | O15: =SUM(C15:L15,N15) -> 6 | P15: =SUM(C15:N15) -> 11 | R15: 1200-1300 | S15: =SUM(C30:C33) -> 3 | T15: =SUM(D30:D33) -> 1 | U15: =SUM(E30:E33) -> 0 | V15: =SUM(F30:F33) -> 0 | W15: =SUM(G30:G33) -> 0 | X15: =SUM(H30:H33) -> 0 | Y15: =SUM(I30:I33) -> 0 | Z15: =SUM(J30:J33) -> 1 | ... AF15: =SUM(P30:P33) -> 17
B16: 08.30 - 08.45 | C16: 2 | D16: 3 | E16: 0 | F16: 0 | G16: 0 | H16: 0 | I16: 1 | J16: 1 | K16: 0 | L16: 0 | M16: 5 | N16: 0 | O16: =SUM(C16:L16,N16) -> 7 | P16: =SUM(C16:N16) -> 12 | R16: 1300-1400 | S16: =SUM(C34:C37) -> 4 | T16: =SUM(D34:D37) -> 14 | U16: =SUM(E34:E37) -> 1 | V16: =SUM(F34:F37) -> 2 | W16: =SUM(G34:G37) -> 0 | X16: =SUM(H34:H37) -> 0 | Y16: =SUM(I34:I37) -> 5 | Z16: =SUM(J34:J37) -> 0 | ... AF16: =SUM(P34:P37) -> 47
B17: 08.45 - 9.00 | C17: 0 | D17: 0 | E17: 0 | F17: 1 | G17: 2 | H17: 0 | I17: 1 | J17: 0 | K17: 0 | L17: 0 | M17: 4 | N17: 0 | O17: =SUM(C17:L17,N17) -> 4 | P17: =SUM(C17:N17) -> 8 | R17: 1400-1500 | S17: =SUM(C38:C41) -> 6 | T17: =SUM(D38:D41) -> 2 | U17: =SUM(E38:E41) -> 0 | V17: =SUM(F38:F41) -> 1 | W17: =SUM(G38:G41) -> 0 | X17: =SUM(H38:H41) -> 0 | Y17: =SUM(I38:I41) -> 2 | Z17: =SUM(J38:J41) -> 0 | ... AF17: =SUM(P38:P41) -> 36
B18: 09.00 - 09.15 | C18: 0 | D18: 1 | E18: 0 | F18: 0 | G18: 0 | H18: 0 | I18: 1 | J18: 0 | K18: 0 | L18: 0 | M18: 5 | N18: 0 | O18: =SUM(C18:L18,N18) -> 2 | P18: =SUM(C18:N18) -> 7 | R18: 1500-1600 | S18: =SUM(C42:C45) -> 2 | T18: =SUM(D42:D45) -> 5 | U18: =SUM(E42:E45) -> 2 | V18: =SUM(F42:F45) -> 3 | W18: =SUM(G42:G45) -> 0 | X18: =SUM(H42:H45) -> 0 | Y18: =SUM(I42:I45) -> 3 | Z18: =SUM(J42:J45) -> 3 | ... AF18: =SUM(P42:P45) -> 45
B19: 09.15 - 09.30 | C19: 1 | D19: 0 | E19: 0 | F19: 2 | G19: 2 | H19: 0 | I19: 1 | J19: 0 | K19: 0 | L19: 0 | M19: 6 | N19: 0 | O19: =SUM(C19:L19,N19) -> 6 | P19: =SUM(C19:N19) -> 12 | R19: 1600-1700 | S19: =SUM(C46:C49) -> 0 | T19: =SUM(D46:D49) -> 1 | U19: =SUM(E46:E49) -> 0 | V19: =SUM(F46:F49) -> 1 | W19: =SUM(G46:G49) -> 0 | X19: =SUM(H46:H49) -> 2 | Y19: =SUM(I46:I49) -> 1 | Z19: =SUM(J46:J49) -> 1 | ... AF19: =SUM(P46:P49) -> 31
B20: 09.30 - 09.45 | C20: 0 | D20: 0 | E20: 0 | F20: 0 | G20: 0 | H20: 0 | I20: 0 | J20: 0 | K20: 1 | L20: 0 | M20: 6 | N20: 0 | O20: =SUM(C20:L20,N20) -> 1 | P20: =SUM(C20:N20) -> 7 | R20: 1700-1800 | S20: =SUM(C50:C53) -> 3 | T20: =SUM(D50:D53) -> 6 | U20: =SUM(E50:E53) -> 4 | V20: =SUM(F50:F53) -> 0 | W20: =SUM(G50:G53) -> 2 | X20: =SUM(H50:H53) -> 0 | Y20: =SUM(I50:I53) -> 1 | Z20: =SUM(J50:J53) -> 2 | ... AF20: =SUM(P50:P53) -> 40
B21: 09.45 - 10.00 | C21: 0 | D21: 1 | E21: 1 | F21: 0 | G21: 0 | H21: 0 | I21: 1 | J21: 0 | K21: 1 | L21: 1 | M21: 1 | N21: 0 | O21: =SUM(C21:L21,N21) -> 5 | P21: =SUM(C21:N21) -> 6 | R21: 1800-1900 | S21: =SUM(C54:C57) -> 2 | T21: =SUM(D54:D57) -> 6 | U21: =SUM(E54:E57) -> 0 | V21: =SUM(F54:F57) -> 2 | W21: =SUM(G54:G57) -> 1 | X21: =SUM(H54:H57) -> 0 | Y21: =SUM(I54:I57) -> 1 | Z21: =SUM(J54:J57) -> 4 | ... AF21: =SUM(P54:P57) -> 31
B22: 10.00 - 10.15 | C22: 0 | D22: 1 | E22: 0 | F22: 0 | G22: 0 | H22: 0 | I22: 0 | J22: 0 | K22: 0 | L22: 0 | M22: 6 | N22: 0 | O22: =SUM(C22:L22,N22) -> 1 | P22: =SUM(C22:N22) -> 7 | R22: 1900-2000 | S22: =SUM(C58:C61) -> 6 | T22: =SUM(D58:D61) -> 0 | U22: =SUM(E58:E61) -> 2 | V22: =SUM(F58:F61) -> 2 | W22: =SUM(G58:G61) -> 0 | X22: =SUM(H58:H61) -> 0 | Y22: =SUM(I58:I61) -> 3 | Z22: =SUM(J58:J61) -> 2 | ... AF22: =SUM(P58:P61) -> 66
B23: 10.15 - 10.30 | C23: 1 | D23: 1 | E23: 0 | F23: 0 | G23: 0 | H23: 0 | I23: 2 | J23: 0 | K23: 0 | L23: 0 | M23: 9 | N23: 0 | O23: =SUM(C23:L23,N23) -> 4 | P23: =SUM(C23:N23) -> 13 | R23: 2000-2100 | S23: =SUM(C62:C65) -> 4 | T23: =SUM(D62:D65) -> 1 | U23: =SUM(E62:E65) -> 0 | V23: =SUM(F62:F65) -> 0 | W23: =SUM(G62:G65) -> 0 | X23: =SUM(H62:H65) -> 0 | Y23: =SUM(I62:I65) -> 3 | Z23: =SUM(J62:J65) -> 0 | ... AF23: =SUM(P62:P65) -> 29
B24: 10.30 - 10.45 | C24: 0 | D24: 1 | E24: 1 | F24: 0 | G24: 0 | H24: 0 | I24: 1 | J24: 0 | K24: 0 | L24: 0 | M24: 8 | N24: 0 | O24: =SUM(C24:L24,N24) -> 3 | P24: =SUM(C24:N24) -> 11 | R24: 2100-2200 | S24: =SUM(C66:C69) -> 1 | T24: =SUM(D66:D69) -> 0 | U24: =SUM(E66:E69) -> 0 | V24: =SUM(F66:F69) -> 1 | W24: =SUM(G66:G69) -> 0 | X24: =SUM(H66:H69) -> 0 | Y24: =SUM(I66:I69) -> 1 | Z24: =SUM(J66:J69) -> 4 | ... AF24: =SUM(P66:P69) -> 18
B25: 10.45 - 11.00 | C25: 1 | D25: 4 | E25: 0 | F25: 0 | G25: 0 | H25: 0 | I25: 1 | J25: 1 | K25: 0 | L25: 0 | M25: 7 | N25: 0 | O25: =SUM(C25:L25,N25) -> 7 | P25: =SUM(C25:N25) -> 14 | R25: 2200-2300 | S25: =SUM(C70:C73) -> 1 | T25: =SUM(D70:D73) -> 0 | U25: =SUM(E70:E73) -> 2 | V25: =SUM(F70:F73) -> 1 | W25: =SUM(G70:G73) -> 0 | X25: =SUM(H70:H73) -> 0 | Y25: =SUM(I70:I73) -> 1 | Z25: =SUM(J70:J73) -> 3 | ... AF25: =SUM(P70:P73) -> 10
B26: 11.00 - 11.15 | C26: 3 | D26: 1 | E26: 0 | F26: 0 | G26: 0 | H26: 0 | I26: 0 | J26: 1 | K26: 0 | L26: 0 | M26: 7 | N26: 0 | O26: =SUM(C26:L26,N26) -> 5 | P26: =SUM(C26:N26) -> 12 | R26: 2300-0000 | S26: =SUM(C74:C77) -> 1 | T26: =SUM(D74:D77) -> 0 | U26: =SUM(E74:E77) -> 0 | V26: =SUM(F74:F77) -> 1 | W26: =SUM(G74:G77) -> 0 | X26: =SUM(H74:H77) -> 0 | Y26: =SUM(I74:I77) -> 0 | Z26: =SUM(J74:J77) -> 1 | ... AF26: =SUM(P74:P77) -> 3
B27: 11.15 - 11.30 | C27: 0 | D27: 0 | E27: 1 | F27: 0 | G27: 0 | H27: 0 | I27: 0 | J27: 1 | K27: 0 | L27: 0 | M27: 8 | N27: 0 | O27: =SUM(C27:L27,N27) -> 2 | P27: =SUM(C27:N27) -> 10 | R27: 0000-0100 | S27: =SUM(C78:C81) -> 1 | T27: =SUM(D78:D81) -> 0 | U27: =SUM(E78:E81) -> 0 | V27: =SUM(F78:F81) -> 0 | W27: =SUM(G78:G81) -> 0 | X27: =SUM(H78:H81) -> 0 | Y27: =SUM(I78:I81) -> 2 | Z27: =SUM(J78:J81) -> 0 | ... AF27: =SUM(P78:P81) -> 7
B28: 11.30 - 11.45 | C28: 2 | D28: 0 | E28: 0 | F28: 0 | G28: 0 | H28: 0 | I28: 1 | J28: 0 | K28: 0 | L28: 0 | M28: 4 | N28: 0 | O28: =SUM(C28:L28,N28) -> 3 | P28: =SUM(C28:N28) -> 7 | R28: 0100-0200 | S28: =SUM(C82:C85) -> 0 | T28: =SUM(D82:D85) -> 2 | U28: =SUM(E82:E85) -> 1 | V28: =SUM(F82:F85) -> 0 | W28: =SUM(G82:G85) -> 1 | X28: =SUM(H82:H85) -> 0 | Y28: =SUM(I82:I85) -> 3 | Z28: =SUM(J82:J85) -> 4 | ... AF28: =SUM(P82:P85) -> 17
B29: 11.45 - 12.00 | C29: 0 | D29: 1 | E29: 0 | F29: 0 | G29: 0 | H29: 0 | I29: 3 | J29: 0 | K29: 0 | L29: 0 | M29: 1 | N29: 0 | O29: =SUM(C29:L29,N29) -> 4 | P29: =SUM(C29:N29) -> 5 | R29: 0200-0300 | S29: =SUM(C86:C89) -> 0 | T29: =SUM(D86:D89) -> 0 | U29: =SUM(E86:E89) -> 0 | V29: =SUM(F86:F89) -> 0 | W29: =SUM(G86:G89) -> 0 | X29: =SUM(H86:H89) -> 0 | Y29: =SUM(I86:I89) -> 2 | Z29: =SUM(J86:J89) -> 1 | ... AF29: =SUM(P86:P89) -> 5
B30: 12.00 - 12.15 | C30: 1 | D30: 0 | E30: 0 | F30: 0 | G30: 0 | H30: 0 | I30: 0 | J30: 0 | K30: 0 | L30: 0 | M30: 3 | N30: 0 | O30: =SUM(C30:L30,N30) -> 1 | P30: =SUM(C30:N30) -> 4 | R30: 0300-0400 | S30: =SUM(C90:C93) -> 1 | T30: =SUM(D90:D93) -> 1 | U30: =SUM(E90:E93) -> 0 | V30: =SUM(F90:F93) -> 1 | W30: =SUM(G90:G93) -> 2 | X30: =SUM(H90:H93) -> 0 | Y30: =SUM(I90:I93) -> 1 | Z30: =SUM(J90:J93) -> 1 | ... AF30: =SUM(P90:P93) -> 7
B31: 12.15 - 12.30 | C31: 2 | D31: 0 | E31: 0 | F31: 0 | G31: 0 | H31: 0 | I31: 0 | J31: 1 | K31: 1 | L31: 1 | M31: 1 | N31: 0 | O31: =SUM(C31:L31,N31) -> 5 | P31: =SUM(C31:N31) -> 6 | R31: 0400-0500 | S31: =SUM(C94:C97) -> 1 | T31: =SUM(D94:D97) -> 2 | U31: =SUM(E94:E97) -> 0 | V31: =SUM(F94:F97) -> 0 | W31: =SUM(G94:G97) -> 1 | X31: =SUM(H94:H97) -> 0 | Y31: =SUM(I94:I97) -> 2 | Z31: =SUM(J94:J97) -> 0 | ... AF31: =SUM(P94:P97) -> 13
B32: 12.30 - 12.45 | C32: 0 | D32: 0 | E32: 0 | F32: 0 | G32: 0 | H32: 0 | I32: 0 | J32: 0 | K32: 0 | L32: 0 | M32: 3 | N32: 0 | O32: =SUM(C32:L32,N32) -> 0 | P32: =SUM(C32:N32) -> 3 | R32: 0500-0600 | S32: =SUM(C98:C101) -> 1 | T32: =SUM(D98:D101) -> 0 | U32: =SUM(E98:E101) -> 0 | V32: =SUM(F98:F101) -> 0 | W32: =SUM(G98:G101) -> 0 | X32: =SUM(H98:H101) -> 0 | Y32: =SUM(I98:I101) -> 3 | Z32: =SUM(J98:J101) -> 0 | ... AF32: =SUM(P98:P101) -> 5
B33: 12.45 - 13.00 | C33: 0 | D33: 1 | E33: 0 | F33: 0 | G33: 0 | H33: 0 | I33: 0 | J33: 0 | K33: 0 | L33: 0 | M33: 3 | N33: 0 | O33: =SUM(C33:L33,N33) -> 1 | P33: =SUM(C33:N33) -> 4 | R33: 0600-0700 | S33: =SUM(C102:C105) -> 4 | T33: =SUM(D102:D105) -> 1 | U33: =SUM(E102:E105) -> 1 | V33: =SUM(F102:F105) -> 6 | W33: =SUM(G102:G105) -> 1 | X33: =SUM(H102:H105) -> 0 | Y33: =SUM(I102:I105) -> 0 | Z33: =SUM(J102:J105) -> 1 | ... AF33: =SUM(P102:P105) -> 24
B34: 13.00 - 13.15 | C34: 1 | D34: 8 | E34: 0 | F34: 1 | G34: 0 | H34: 0 | I34: 2 | J34: 0 | K34: 0 | L34: 0 | M34: 10 | N34: 0 | O34: =SUM(C34:L34,N34) -> 12 | P34: =SUM(C34:N34) -> 22 | R34: AM Peak Hr | S34: =MAX(S10:S12) -> 4 | T34: =MAX(T10:T12) -> 3 | U34: =MAX(U10:U12) -> 1 | V34: =MAX(V10:V12) -> 5 | W34: =MAX(W10:W12) -> 2 | X34: =MAX(X10:X12) -> 0 | Y34: =MAX(Y10:Y12) -> 4 | Z34: =MAX(Z10:Z12) -> 2 | ... AF34: =MAX(AF10:AF12) -> 39
B35: 13.15 - 13.30 | C35: 2 | D35: 3 | E35: 1 | F35: 1 | G35: 0 | H35: 0 | I35: 0 | J35: 0 | K35: 0 | L35: 0 | M35: 0 | N35: 0 | O35: =SUM(C35:L35,N35) -> 7 | P35: =SUM(C35:N35) -> 7 | R35: IP Peak Hr | S35: =MAX(S13:S18) -> 6 | T35: =MAX(T13:T18) -> 14 | U35: =MAX(U13:U18) -> 2 | V35: =MAX(V13:V18) -> 3 | W35: =MAX(W13:W18) -> 0 | X35: =MAX(X13:X18) -> 0 | Y35: =MAX(Y13:Y18) -> 5 | Z35: =MAX(Z13:Z18) -> 3 | ... AF35: =MAX(AF13:AF18) -> 47
B36: 13.30 - 13.45 | C36: 0 | D36: 1 | E36: 0 | F36: 0 | G36: 0 | H36: 0 | I36: 0 | J36: 0 | K36: 0 | L36: 0 | M36: 3 | N36: 0 | O36: =SUM(C36:L36,N36) -> 1 | P36: =SUM(C36:N36) -> 4 | R36: PM Peak Hr | S36: =MAX(S19:S21) -> 3 | T36: =MAX(T19:T21) -> 6 | U36: =MAX(U19:U21) -> 4 | V36: =MAX(V19:V21) -> 2 | W36: =MAX(W19:W21) -> 2 | X36: =MAX(X19:X21) -> 2 | Y36: =MAX(Y19:Y21) -> 1 | Z36: =MAX(Z19:Z21) -> 4 | ... AF36: =MAX(AF19:AF21) -> 40
B37: 13.45 - 14.00 | C37: 1 | D37: 2 | E37: 0 | F37: 0 | G37: 0 | H37: 0 | I37: 3 | J37: 0 | K37: 0 | L37: 0 | M37: 7 | N37: 1 | O37: =SUM(C37:L37,N37) -> 7 | P37: =SUM(C37:N37) -> 14 | R37: AM Period | S37: =SUM(S10:S12) -> 8 | T37: =SUM(T10:T12) -> 8 | U37: =SUM(U10:U12) -> 2 | V37: =SUM(V10:V12) -> 9 | W37: =SUM(W10:W12) -> 4 | X37: =SUM(X10:X12) -> 0 | Y37: =SUM(Y10:Y12) -> 9 | Z37: =SUM(Z10:Z12) -> 2 | ... AF37: =SUM(AF10:AF12) -> 107
B38: 14.00 - 14.15 | C38: 0 | D38: 1 | E38: 0 | F38: 0 | G38: 0 | H38: 0 | I38: 0 | J38: 0 | K38: 0 | L38: 0 | M38: 12 | N38: 0 | O38: =SUM(C38:L38,N38) -> 1 | P38: =SUM(C38:N38) -> 13 | R38: IP Period | S38: =SUM(S13:S18) -> 22 | T38: =SUM(T13:T18) -> 31 | U38: =SUM(U13:U18) -> 5 | V38: =SUM(V13:V18) -> 6 | W38: =SUM(W13:W18) -> 0 | X38: =SUM(X13:X18) -> 0 | Y38: =SUM(Y13:Y18) -> 18 | Z38: =SUM(Z13:Z18) -> 7 | ... AF38: =SUM(AF13:AF18) -> 224
B39: 14.15 - 14.30 | C39: 1 | D39: 0 | E39: 0 | F39: 1 | G39: 0 | H39: 0 | I39: 1 | J39: 0 | K39: 0 | L39: 0 | M39: 7 | N39: 0 | O39: =SUM(C39:L39,N39) -> 3 | P39: =SUM(C39:N39) -> 10 | R39: PM Period | S39: =SUM(S19:S21) -> 5 | T39: =SUM(T19:T21) -> 13 | U39: =SUM(U19:U21) -> 4 | V39: =SUM(V19:V21) -> 3 | W39: =SUM(W19:W21) -> 3 | X39: =SUM(X19:X21) -> 2 | Y39: =SUM(Y19:Y21) -> 3 | Z39: =SUM(Z19:Z21) -> 7 | ... AF39: =SUM(AF19:AF21) -> 102
B40: 14.30 - 14.45 | C40: 1 | D40: 0 | E40: 0 | F40: 0 | G40: 0 | H40: 0 | I40: 0 | J40: 0 | K40: 0 | L40: 0 | M40: 1 | N40: 0 | O40: =SUM(C40:L40,N40) -> 1 | P40: =SUM(C40:N40) -> 2 | R40: 12 Hours | S40: =SUM(S10:S21) -> 35 | T40: =SUM(T10:T21) -> 52 | U40: =SUM(U10:U21) -> 11 | V40: =SUM(V10:V21) -> 18 | W40: =SUM(W10:W21) -> 7 | X40: =SUM(X10:X21) -> 2 | Y40: =SUM(Y10:Y21) -> 30 | Z40: =SUM(Z10:Z21) -> 16 | ... AF40: =SUM(AF10:AF21) -> 433
B41: 14.45 - 15.00 | C41: 4 | D41: 1 | E41: 0 | F41: 0 | G41: 0 | H41: 0 | I41: 1 | J41: 0 | K41: 0 | L41: 0 | M41: 5 | N41: 0 | O41: =SUM(C41:L41,N41) -> 6 | P41: =SUM(C41:N41) -> 11 | R41: 24 Hrs/ADT | S41: =SUM(S10:S33) -> 56 | T41: =SUM(T10:T33) -> 59 | U41: =SUM(U10:U33) -> 17 | V41: =SUM(V10:V33) -> 30 | W41: =SUM(W10:W33) -> 12 | X41: =SUM(X10:X33) -> 2 | Y41: =SUM(Y10:Y33) -> 51 | Z41: =SUM(Z10:Z33) -> 33 | ... AF41: =SUM(AF10:AF33) -> 637
B42: 15.00 - 15.15 | C42: 1 | D42: 1 | E42: 0 | F42: 1 | G42: 0 | H42: 0 | I42: 1 | J42: 0 | K42: 0 | L42: 0 | M42: 5 | N42: 0 | O42: =SUM(C42:L42,N42) -> 4 | P42: =SUM(C42:N42) -> 9 | R42: NEF | S42: =S41/S40 -> 1.6 | T42: =T41/T40 -> 1.1346154 | U42: =U41/U40 -> 1.5454545 | V42: =V41/V40 -> 1.6666667 | W42: =W41/W40 -> 1.7142857 | X42: =X41/X40 -> 1 | Y42: =Y41/Y40 -> 1.7 | Z42: =Z41/Z40 -> 2.0625 | ... AF42: =AF41/AF40 -> 1.4711316
...

Sheet 18.10 KANONI-SSEMBABULE-24h
B1: Consultancy services for Preparation of Expressway Development Master Plan (EDMP) for Uganda
B2: MANUAL CLASSIFIED COUNT (MCC)
B3: ROAD NAME: | C3: ='17.10 SSEMBABULE-KANONI'!C3:G3 -> SSEMBABULE-KABULASOKE ROAD
C5: Date | D5: ='18.10 SSEMBABULE-KANONI-24h'!D5 -> 18.10.2019 | F5: Location | G5: ='18.10 SSEMBABULE-KANONI-24h'!G5:H5 -> KYABI | J5: Surveyor | K5: KATUMBA SAMUEL
C6: Dir. From | D6: KANONI | F6: Dir. To | G6: SSEMBABULE | J6: Supervisor | K6: ='18.10 SSEMBABULE-KANONI-24h'!K6:L6 -> ONYUTI BETTY
B8: Time / Veh Type | R8: SUMMARY TRAFFIC VOLUMES
C9: 1. Car | D9: 2. Station Wagon | E9: 3. Pickups | F9: 4. Minibus, matatu | G9: 5. Medium bus | H9: 6. Large Bus | I9: 7. Light Truck | J9: 8. Medium Truck | K9: 9. Heavy truck | L9: 10. Truck Trailer | M9: 11. Motor cycles | N9: 12. Tractors | O9: Total Excl M/Cycles | P9: Total All | R9: Time | S9: 1. Car | T9: 2. Station Wagon | U9: 3. Pickups | V9: 4. Minibus, matatu | W9: 5. Medium bus | X9: 6. Large Bus | Y9: 7. Light Truck | Z9: 8. Medium Truck | AA9: 9. Heavy truck | AB9: 10. Truck Trailer | AC9: 11. Motorcycles | AD9: 12. Tractors, Graders | AE9: Total Excl M/ Cycles | AF9: Total All
B10: 07.00 - 07.15 | C10: 0 | D10: 0 | E10: 0 | F10: 2 | G10: 1 | H10: 0 | I10: 2 | J10: 1 | K10: 0 | L10: 0 | M10: 6 | N10: 0 | O10: =SUM(C10:L10,N10) -> 6 | P10: =SUM(C10:N10) -> 12 | R10: 0700-0800 | S10: =SUM(C10:C13) -> 2 | T10: =SUM(D10:D13) -> 1 | U10: =SUM(E10:E13) -> 0 | V10: =SUM(F10:F13) -> 6 | W10: =SUM(G10:G13) -> 1 | X10: =SUM(H10:H13) -> 0 | Y10: =SUM(I10:I13) -> 7 | Z10: =SUM(J10:J13) -> 2 | ... AF10: =SUM(P10:P13) -> 38
B11: 07.15 - 07.30 | C11: 2 | D11: 0 | E11: 0 | F11: 2 | G11: 0 | H11: 0 | I11: 2 | J11: 0 | K11: 0 | L11: 0 | M11: 11 | N11: 0 | O11: =SUM(C11:L11,N11) -> 6 | P11: =SUM(C11:N11) -> 17 | R11: 0800-0900 | S11: =SUM(C14:C17) -> 8 | T11: =SUM(D14:D17) -> 2 | U11: =SUM(E14:E17) -> 0 | V11: =SUM(F14:F17) -> 3 | W11: =SUM(G14:G17) -> 0 | X11: =SUM(H14:H17) -> 0 | Y11: =SUM(I14:I17) -> 1 | Z11: =SUM(J14:J17) -> 1 | ... AF11: =SUM(P14:P17) -> 32
B12: 07.30 - 07.45 | C12: 0 | D12: 1 | E12: 0 | F12: 0 | G12: 0 | H12: 0 | I12: 2 | J12: 1 | K12: 0 | L12: 0 | M12: 1 | N12: 0 | O12: =SUM(C12:L12,N12) -> 4 | P12: =SUM(C12:N12) -> 5 | R12: 0900-1000 | S12: =SUM(C18:C21) -> 6 | T12: =SUM(D18:D21) -> 1 | U12: =SUM(E18:E21) -> 0 | V12: =SUM(F18:F21) -> 1 | W12: =SUM(G18:G21) -> 0 | X12: =SUM(H18:H21) -> 0 | Y12: =SUM(I18:I21) -> 1 | Z12: =SUM(J18:J21) -> 1 | ... AF12: =SUM(P18:P21) -> 31
B13: 07.45 - 08.00 | C13: 0 | D13: 0 | E13: 0 | F13: 2 | G13: 0 | H13: 0 | I13: 1 | J13: 0 | K13: 0 | L13: 0 | M13: 1 | N13: 0 | O13: =SUM(C13:L13,N13) -> 3 | P13: =SUM(C13:N13) -> 4 | R13: 1000-1100 | S13: =SUM(C22:C25) -> 3 | T13: =SUM(D22:D25) -> 2 | U13: =SUM(E22:E25) -> 0 | V13: =SUM(F22:F25) -> 1 | W13: =SUM(G22:G25) -> 0 | X13: =SUM(H22:H25) -> 0 | Y13: =SUM(I22:I25) -> 0 | Z13: =SUM(J22:J25) -> 0 | ... AF13: =SUM(P22:P25) -> 30
B14: 08.00 - 08.15 | C14: 0 | D14: 0 | E14: 0 | F14: 1 | G14: 0 | H14: 0 | I14: 0 | J14: 1 | K14: 0 | L14: 0 | M14: 8 | N14: 0 | O14: =SUM(C14:L14,N14) -> 2 | P14: =SUM(C14:N14) -> 10 | R14: 1100-1200 | S14: =SUM(C26:C29) -> 3 | T14: =SUM(D26:D29) -> 5 | U14: =SUM(E26:E29) -> 0 | V14: =SUM(F26:F29) -> 1 | W14: =SUM(G26:G29) -> 0 | X14: =SUM(H26:H29) -> 0 | Y14: =SUM(I26:I29) -> 2 | Z14: =SUM(J26:J29) -> 0 | ... AF14: =SUM(P26:P29) -> 41
B15: 08.15 - 08.30 | C15: 0 | D15: 1 | E15: 0 | F15: 1 | G15: 0 | H15: 0 | I15: 1 | J15: 0 | K15: 0 | L15: 0 | M15: 3 | N15: 0 | O15: =SUM(C15:L15,N15) -> 3 | P15: =SUM(C15:N15) -> 6 | R15: 1200-1300 | S15: =SUM(C30:C33) -> 6 | T15: =SUM(D30:D33) -> 3 | U15: =SUM(E30:E33) -> 0 | V15: =SUM(F30:F33) -> 1 | W15: =SUM(G30:G33) -> 0 | X15: =SUM(H30:H33) -> 0 | Y15: =SUM(I30:I33) -> 1 | Z15: =SUM(J30:J33) -> 1 | ... AF15: =SUM(P30:P33) -> 40
B16: 08.30 - 08.45 | C16: 5 | D16: 1 | E16: 0 | F16: 1 | G16: 0 | H16: 0 | I16: 0 | J16: 0 | K16: 0 | L16: 0 | M16: 0 | N16: 0 | O16: =SUM(C16:L16,N16) -> 7 | P16: =SUM(C16:N16) -> 7 | R16: 1300-1400 | S16: =SUM(C34:C37) -> 3 | T16: =SUM(D34:D37) -> 0 | U16: =SUM(E34:E37) -> 0 | V16: =SUM(F34:F37) -> 2 | W16: =SUM(G34:G37) -> 0 | X16: =SUM(H34:H37) -> 0 | Y16: =SUM(I34:I37) -> 5 | Z16: =SUM(J34:J37) -> 0 | ... AF16: =SUM(P34:P37) -> 35
B17: 08.45 - 9.00 | C17: 3 | D17: 0 | E17: 0 | F17: 0 | G17: 0 | H17: 0 | I17: 0 | J17: 0 | K17: 0 | L17: 0 | M17: 6 | N17: 0 | O17: =SUM(C17:L17,N17) -> 3 | P17: =SUM(C17:N17) -> 9 | R17: 1400-1500 | S17: =SUM(C38:C41) -> 2 | T17: =SUM(D38:D41) -> 3 | U17: =SUM(E38:E41) -> 0 | V17: =SUM(F38:F41) -> 0 | W17: =SUM(G38:G41) -> 0 | X17: =SUM(H38:H41) -> 0 | Y17: =SUM(I38:I41) -> 2 | Z17: =SUM(J38:J41) -> 2 | ... AF17: =SUM(P38:P41) -> 34
B18: 09.00 - 09.15 | C18: 0 | D18: 1 | E18: 0 | F18: 1 | G18: 0 | H18: 0 | I18: 0 | J18: 0 | K18: 0 | L18: 0 | M18: 2 | N18: 0 | O18: =SUM(C18:L18,N18) -> 2 | P18: =SUM(C18:N18) -> 4 | R18: 1500-1600 | S18: =SUM(C42:C45) -> 1 | T18: =SUM(D42:D45) -> 4 | U18: =SUM(E42:E45) -> 1 | V18: =SUM(F42:F45) -> 0 | W18: =SUM(G42:G45) -> 0 | X18: =SUM(H42:H45) -> 0 | Y18: =SUM(I42:I45) -> 0 | Z18: =SUM(J42:J45) -> 4 | ... AF18: =SUM(P42:P45) -> 37
B19: 09.15 - 09.30 | C19: 1 | D19: 0 | E19: 0 | F19: 0 | G19: 0 | H19: 0 | I19: 0 | J19: 1 | K19: 0 | L19: 0 | M19: 6 | N19: 0 | O19: =SUM(C19:L19,N19) -> 2 | P19: =SUM(C19:N19) -> 8 | R19: 1600-1700 | S19: =SUM(C46:C49) -> 2 | T19: =SUM(D46:D49) -> 4 | U19: =SUM(E46:E49) -> 0 | V19: =SUM(F46:F49) -> 1 | W19: =SUM(G46:G49) -> 0 | X19: =SUM(H46:H49) -> 0 | Y19: =SUM(I46:I49) -> 0 | Z19: =SUM(J46:J49) -> 2 | ... AF19: =SUM(P46:P49) -> 31
B20: 09.30 - 09.45 | C20: 5 | D20: 0 | E20: 0 | F20: 0 | G20: 0 | H20: 0 | I20: 0 | J20: 0 | K20: 2 | L20: 0 | M20: 5 | N20: 0 | O20: =SUM(C20:L20,N20) -> 7 | P20: =SUM(C20:N20) -> 12 | R20: 1700-1800 | S20: =SUM(C50:C53) -> 0 | T20: =SUM(D50:D53) -> 6 | U20: =SUM(E50:E53) -> 1 | V20: =SUM(F50:F53) -> 4 | W20: =SUM(G50:G53) -> 1 | X20: =SUM(H50:H53) -> 0 | Y20: =SUM(I50:I53) -> 2 | Z20: =SUM(J50:J53) -> 2 | ... AF20: =SUM(P50:P53) -> 42
B21: 09.45 - 10.00 | C21: 0 | D21: 0 | E21: 0 | F21: 0 | G21: 0 | H21: 0 | I21: 1 | J21: 0 | K21: 0 | L21: 0 | M21: 6 | N21: 0 | O21: =SUM(C21:L21,N21) -> 1 | P21: =SUM(C21:N21) -> 7 | R21: 1800-1900 | S21: =SUM(C54:C57) -> 4 | T21: =SUM(D54:D57) -> 0 | U21: =SUM(E54:E57) -> 2 | V21: =SUM(F54:F57) -> 0 | W21: =SUM(G54:G57) -> 0 | X21: =SUM(H54:H57) -> 0 | Y21: =SUM(I54:I57) -> 1 | Z21: =SUM(J54:J57) -> 1 | ... AF21: =SUM(P54:P57) -> 35
B22: 10.00 - 10.15 | C22: 2 | D22: 1 | E22: 0 | F22: 0 | G22: 0 | H22: 0 | I22: 0 | J22: 0 | K22: 1 | L22: 0 | M22: 6 | N22: 1 | O22: =SUM(C22:L22,N22) -> 5 | P22: =SUM(C22:N22) -> 11 | R22: 1900-2000 | S22: =SUM(C58:C61) -> 6 | T22: =SUM(D58:D61) -> 7 | U22: =SUM(E58:E61) -> 2 | V22: =SUM(F58:F61) -> 1 | W22: =SUM(G58:G61) -> 1 | X22: =SUM(H58:H61) -> 0 | Y22: =SUM(I58:I61) -> 1 | Z22: =SUM(J58:J61) -> 1 | ... AF22: =SUM(P58:P61) -> 55
B23: 10.15 - 10.30 | C23: 0 | D23: 0 | E23: 0 | F23: 1 | G23: 0 | H23: 0 | I23: 0 | J23: 0 | K23: 0 | L23: 0 | M23: 5 | N23: 0 | O23: =SUM(C23:L23,N23) -> 1 | P23: =SUM(C23:N23) -> 6 | R23: 2000-2100 | S23: =SUM(C62:C65) -> 6 | T23: =SUM(D62:D65) -> 5 | U23: =SUM(E62:E65) -> 0 | V23: =SUM(F62:F65) -> 1 | W23: =SUM(G62:G65) -> 0 | X23: =SUM(H62:H65) -> 0 | Y23: =SUM(I62:I65) -> 3 | Z23: =SUM(J62:J65) -> 4 | ... AF23: =SUM(P62:P65) -> 38
B24: 10.30 - 10.45 | C24: 0 | D24: 0 | E24: 0 | F24: 0 | G24: 0 | H24: 0 | I24: 0 | J24: 0 | K24: 0 | L24: 0 | M24: 6 | N24: 0 | O24: =SUM(C24:L24,N24) -> 0 | P24: =SUM(C24:N24) -> 6 | R24: 2100-2200 | S24: =SUM(C66:C69) -> 4 | T24: =SUM(D66:D69) -> 4 | U24: =SUM(E66:E69) -> 0 | V24: =SUM(F66:F69) -> 1 | W24: =SUM(G66:G69) -> 0 | X24: =SUM(H66:H69) -> 0 | Y24: =SUM(I66:I69) -> 0 | Z24: =SUM(J66:J69) -> 3 | ... AF24: =SUM(P66:P69) -> 23
B25: 10.45 - 11.00 | C25: 1 | D25: 1 | E25: 0 | F25: 0 | G25: 0 | H25: 0 | I25: 0 | J25: 0 | K25: 0 | L25: 0 | M25: 5 | N25: 0 | O25: =SUM(C25:L25,N25) -> 2 | P25: =SUM(C25:N25) -> 7 | R25: 2200-2300 | S25: =SUM(C70:C73) -> 0 | T25: =SUM(D70:D73) -> 0 | U25: =SUM(E70:E73) -> 0 | V25: =SUM(F70:F73) -> 1 | W25: =SUM(G70:G73) -> 0 | X25: =SUM(H70:H73) -> 0 | Y25: =SUM(I70:I73) -> 1 | Z25: =SUM(J70:J73) -> 0 | ... AF25: =SUM(P70:P73) -> 4
B26: 11.00 - 11.15 | C26: 1 | D26: 1 | E26: 0 | F26: 1 | G26: 0 | H26: 0 | I26: 0 | J26: 0 | K26: 0 | L26: 0 | M26: 13 | N26: 0 | O26: =SUM(C26:L26,N26) -> 3 | P26: =SUM(C26:N26) -> 16 | R26: 2300-0000 | S26: =SUM(C74:C77) -> 3 | T26: =SUM(D74:D77) -> 0 | U26: =SUM(E74:E77) -> 0 | V26: =SUM(F74:F77) -> 2 | W26: =SUM(G74:G77) -> 0 | X26: =SUM(H74:H77) -> 0 | Y26: =SUM(I74:I77) -> 0 | Z26: =SUM(J74:J77) -> 0 | ... AF26: =SUM(P74:P77) -> 8
B27: 11.15 - 11.30 | C27: 1 | D27: 1 | E27: 0 | F27: 0 | G27: 0 | H27: 0 | I27: 1 | J27: 0 | K27: 0 | L27: 0 | M27: 6 | N27: 0 | O27: =SUM(C27:L27,N27) -> 3 | P27: =SUM(C27:N27) -> 9 | R27: 0000-0100 | S27: =SUM(C78:C81) -> 2 | T27: =SUM(D78:D81) -> 5 | U27: =SUM(E78:E81) -> 0 | V27: =SUM(F78:F81) -> 1 | W27: =SUM(G78:G81) -> 2 | X27: =SUM(H78:H81) -> 0 | Y27: =SUM(I78:I81) -> 2 | Z27: =SUM(J78:J81) -> 2 | ... AF27: =SUM(P78:P81) -> 18
B28: 11.30 - 11.45 | C28: 0 | D28: 0 | E28: 0 | F28: 0 | G28: 0 | H28: 0 | I28: 0 | J28: 0 | K28: 0 | L28: 0 | M28: 6 | N28: 0 | O28: =SUM(C28:L28,N28) -> 0 | P28: =SUM(C28:N28) -> 6 | R28: 0100-0200 | S28: =SUM(C82:C85) -> 1 | T28: =SUM(D82:D85) -> 0 | U28: =SUM(E82:E85) -> 0 | V28: =SUM(F82:F85) -> 0 | W28: =SUM(G82:G85) -> 1 | X28: =SUM(H82:H85) -> 1 | Y28: =SUM(I82:I85) -> 5 | Z28: =SUM(J82:J85) -> 0 | ... AF28: =SUM(P82:P85) -> 13
B29: 11.45 - 12.00 | C29: 1 | D29: 3 | E29: 0 | F29: 0 | G29: 0 | H29: 0 | I29: 1 | J29: 0 | K29: 0 | L29: 1 | M29: 4 | N29: 0 | O29: =SUM(C29:L29,N29) -> 6 | P29: =SUM(C29:N29) -> 10 | R29: 0200-0300 | S29: =SUM(C86:C89) -> 2 | T29: =SUM(D86:D89) -> 0 | U29: =SUM(E86:E89) -> 0 | V29: =SUM(F86:F89) -> 0 | W29: =SUM(G86:G89) -> 0 | X29: =SUM(H86:H89) -> 1 | Y29: =SUM(I86:I89) -> 1 | Z29: =SUM(J86:J89) -> 4 | ... AF29: =SUM(P86:P89) -> 10
B30: 12.00 - 12.15 | C30: 1 | D30: 1 | E30: 0 | F30: 1 | G30: 0 | H30: 0 | I30: 0 | J30: 0 | K30: 0 | L30: 0 | M30: 4 | N30: 0 | O30: =SUM(C30:L30,N30) -> 3 | P30: =SUM(C30:N30) -> 7 | R30: 0300-0400 | S30: =SUM(C90:C93) -> 0 | T30: =SUM(D90:D93) -> 2 | U30: =SUM(E90:E93) -> 0 | V30: =SUM(F90:F93) -> 0 | W30: =SUM(G90:G93) -> 0 | X30: =SUM(H90:H93) -> 0 | Y30: =SUM(I90:I93) -> 2 | Z30: =SUM(J90:J93) -> 3 | ... AF30: =SUM(P90:P93) -> 9
B31: 12.15 - 12.30 | C31: 0 | D31: 1 | E31: 0 | F31: 0 | G31: 0 | H31: 0 | I31: 1 | J31: 1 | K31: 0 | L31: 0 | M31: 7 | N31: 0 | O31: =SUM(C31:L31,N31) -> 3 | P31: =SUM(C31:N31) -> 10 | R31: 0400-0500 | S31: =SUM(C94:C97) -> 1 | T31: =SUM(D94:D97) -> 3 | U31: =SUM(E94:E97) -> 0 | V31: =SUM(F94:F97) -> 0 | W31: =SUM(G94:G97) -> 3 | X31: =SUM(H94:H97) -> 1 | Y31: =SUM(I94:I97) -> 3 | Z31: =SUM(J94:J97) -> 1 | ... AF31: =SUM(P94:P97) -> 15
B32: 12.30 - 12.45 | C32: 2 | D32: 1 | E32: 0 | F32: 0 | G32: 0 | H32: 0 | I32: 0 | J32: 0 | K32: 0 | L32: 0 | M32: 7 | N32: 0 | O32: =SUM(C32:L32,N32) -> 3 | P32: =SUM(C32:N32) -> 10 | R32: 0500-0600 | S32: =SUM(C98:C101) -> 0 | T32: =SUM(D98:D101) -> 0 | U32: =SUM(E98:E101) -> 0 | V32: =SUM(F98:F101) -> 2 | W32: =SUM(G98:G101) -> 0 | X32: =SUM(H98:H101) -> 0 | Y32: =SUM(I98:I101) -> 1 | Z32: =SUM(J98:J101) -> 2 | ... AF32: =SUM(P98:P101) -> 7
B33: 12.45 - 13.00 | C33: 3 | D33: 0 | E33: 0 | F33: 0 | G33: 0 | H33: 0 | I33: 0 | J33: 0 | K33: 0 | L33: 0 | M33: 10 | N33: 0 | O33: =SUM(C33:L33,N33) -> 3 | P33: =SUM(C33:N33) -> 13 | R33: 0600-0700 | S33: =SUM(C102:C105) -> 0 | T33: =SUM(D102:D105) -> 2 | U33: =SUM(E102:E105) -> 0 | V33: =SUM(F102:F105) -> 2 | W33: =SUM(G102:G105) -> 2 | X33: =SUM(H102:H105) -> 1 | Y33: =SUM(I102:I105) -> 2 | Z33: =SUM(J102:J105) -> 0 | ... AF33: =SUM(P102:P105) -> 17
B34: 13.00 - 13.15 | C34: 2 | D34: 0 | E34: 0 | F34: 0 | G34: 0 | H34: 0 | I34: 1 | J34: 0 | K34: 0 | L34: 0 | M34: 6 | N34: 0 | O34: =SUM(C34:L34,N34) -> 3 | P34: =SUM(C34:N34) -> 9 | R34: AM Peak Hr | S34: =MAX(S10:S12) -> 8 | T34: =MAX(T10:T12) -> 2 | U34: =MAX(U10:U12) -> 0 | V34: =MAX(V10:V12) -> 6 | W34: =MAX(W10:W12) -> 1 | X34: =MAX(X10:X12) -> 0 | Y34: =MAX(Y10:Y12) -> 7 | Z34: =MAX(Z10:Z12) -> 2 | ... AF34: =MAX(AF10:AF12) -> 38
B35: 13.15 - 13.30 | C35: 1 | D35: 0 | E35: 0 | F35: 0 | G35: 0 | H35: 0 | I35: 1 | J35: 0 | K35: 0 | L35: 0 | M35: 5 | N35: 0 | O35: =SUM(C35:L35,N35) -> 2 | P35: =SUM(C35:N35) -> 7 | R35: IP Peak Hr | S35: =MAX(S13:S18) -> 6 | T35: =MAX(T13:T18) -> 5 | U35: =MAX(U13:U18) -> 1 | V35: =MAX(V13:V18) -> 2 | W35: =MAX(W13:W18) -> 0 | X35: =MAX(X13:X18) -> 0 | Y35: =MAX(Y13:Y18) -> 5 | Z35: =MAX(Z13:Z18) -> 4 | ... AF35: =MAX(AF13:AF18) -> 41
B36: 13.30 - 13.45 | C36: 0 | D36: 0 | E36: 0 | F36: 1 | G36: 0 | H36: 0 | I36: 1 | J36: 0 | K36: 0 | L36: 0 | M36: 10 | N36: 0 | O36: =SUM(C36:L36,N36) -> 2 | P36: =SUM(C36:N36) -> 12 | R36: PM Peak Hr | S36: =MAX(S19:S21) -> 4 | T36: =MAX(T19:T21) -> 6 | U36: =MAX(U19:U21) -> 2 | V36: =MAX(V19:V21) -> 4 | W36: =MAX(W19:W21) -> 1 | X36: =MAX(X19:X21) -> 0 | Y36: =MAX(Y19:Y21) -> 2 | Z36: =MAX(Z19:Z21) -> 2 | ... AF36: =MAX(AF19:AF21) -> 42
B37: 13.45 - 14.00 | C37: 0 | D37: 0 | E37: 0 | F37: 1 | G37: 0 | H37: 0 | I37: 2 | J37: 0 | K37: 0 | L37: 0 | M37: 4 | N37: 0 | O37: =SUM(C37:L37,N37) -> 3 | P37: =SUM(C37:N37) -> 7 | R37: AM Period | S37: =SUM(S10:S12) -> 16 | T37: =SUM(T10:T12) -> 4 | U37: =SUM(U10:U12) -> 0 | V37: =SUM(V10:V12) -> 10 | W37: =SUM(W10:W12) -> 1 | X37: =SUM(X10:X12) -> 0 | Y37: =SUM(Y10:Y12) -> 9 | Z37: =SUM(Z10:Z12) -> 4 | ... AF37: =SUM(AF10:AF12) -> 101
B38: 14.00 - 14.15 | C38: 0 | D38: 1 | E38: 0 | F38: 0 | G38: 0 | H38: 0 | I38: 2 | J38: 1 | K38: 0 | L38: 0 | M38: 6 | N38: 0 | O38: =SUM(C38:L38,N38) -> 4 | P38: =SUM(C38:N38) -> 10 | R38: IP Period | S38: =SUM(S13:S18) -> 18 | T38: =SUM(T13:T18) -> 17 | U38: =SUM(U13:U18) -> 1 | V38: =SUM(V13:V18) -> 5 | W38: =SUM(W13:W18) -> 0 | X38: =SUM(X13:X18) -> 0 | Y38: =SUM(Y13:Y18) -> 10 | Z38: =SUM(Z13:Z18) -> 7 | ... AF38: =SUM(AF13:AF18) -> 217
B39: 14.15 - 14.30 | C39: 1 | D39: 1 | E39: 0 | F39: 0 | G39: 0 | H39: 0 | I39: 0 | J39: 1 | K39: 0 | L39: 0 | M39: 10 | N39: 0 | O39: =SUM(C39:L39,N39) -> 3 | P39: =SUM(C39:N39) -> 13 | R39: PM Period | S39: =SUM(S19:S21) -> 6 | T39: =SUM(T19:T21) -> 10 | U39: =SUM(U19:U21) -> 3 | V39: =SUM(V19:V21) -> 5 | W39: =SUM(W19:W21) -> 1 | X39: =SUM(X19:X21) -> 0 | Y39: =SUM(Y19:Y21) -> 3 | Z39: =SUM(Z19:Z21) -> 5 | ... AF39: =SUM(AF19:AF21) -> 108
B40: 14.30 - 14.45 | C40: 1 | D40: 1 | E40: 0 | F40: 0 | G40: 0 | H40: 0 | I40: 0 | J40: 0 | K40: 1 | L40: 0 | M40: 8 | N40: 0 | O40: =SUM(C40:L40,N40) -> 3 | P40: =SUM(C40:N40) -> 11 | R40: 12 Hours | S40: =SUM(S10:S21) -> 40 | T40: =SUM(T10:T21) -> 31 | U40: =SUM(U10:U21) -> 4 | V40: =SUM(V10:V21) -> 20 | W40: =SUM(W10:W21) -> 2 | X40: =SUM(X10:X21) -> 0 | Y40: =SUM(Y10:Y21) -> 22 | Z40: =SUM(Z10:Z21) -> 16 | ... AF40: =SUM(AF10:AF21) -> 426
B41: 14.45 - 15.00 | C41: 0 | D41: 0 | E41: 0 | F41: 0 | G41: 0 | H41: 0 | I41: 0 | J41: 0 | K41: 0 | L41: 0 | M41: 0 | N41: 0 | O41: =SUM(C41:L41,N41) -> 0 | P41: =SUM(C41:N41) -> 0 | R41: 24 Hrs/ADT | S41: =SUM(S10:S33) -> 65 | T41: =SUM(T10:T33) -> 59 | U41: =SUM(U10:U33) -> 6 | V41: =SUM(V10:V33) -> 31 | W41: =SUM(W10:W33) -> 11 | X41: =SUM(X10:X33) -> 4 | Y41: =SUM(Y10:Y33) -> 43 | Z41: =SUM(Z10:Z33) -> 36 | ... AF41: =SUM(AF10:AF33) -> 643
B42: 15.00 - 15.15 | C42: 0 | D42: 0 | E42: 0 | F42: 0 | G42: 0 | H42: 0 | I42: 0 | J42: 0 | K42: 0 | L42: 0 | M42: 3 | N42: 0 | O42: =SUM(C42:L42,N42) -> 0 | P42: =SUM(C42:N42) -> 3 | R42: NEF | S42: =S41/S40 -> 1.625 | T42: =T41/T40 -> 1.9032258 | U42: =U41/U40 -> 1.5 | V42: =V41/V40 -> 1.55 | W42: =W41/W40 -> 5.5 | X42: =X41/X40 -> #DIV/0! | Y42: =Y41/Y40 -> 1.9545455 | Z42: =Z41/Z40 -> 2.25 | ... AF42: =AF41/AF40 -> 1.5093897
...

Sheet 19.10  SSEMBABULE- KANONI-24h
B1: Consultancy services for Preparation of Expressway Development Master Plan (EDMP) for Uganda
B2: MANUAL CLASSIFIED COUNT (MCC)
B3: ROAD NAME: | C3: ='17.10 SSEMBABULE-KANONI'!C3:G3 -> SSEMBABULE-KABULASOKE ROAD
C5: Date | D5: 19.10.2019 | F5: Location | G5: ='18.10 KANONI-SSEMBABULE-24h'!G5:H5 -> KYABI | J5: Surveyor | K5: VIOLA
C6: Dir. From | D6: SSEMBABULE | F6: Dir. To | G6: ='17.10 SSEMBABULE-KANONI'!G6:H6 -> KANONI | J6: Supervisor | K6: ='18.10 KANONI-SSEMBABULE-24h'!K6:L6 -> ONYUTI BETTY
B8: Time / Veh Type | R8: SUMMARY TRAFFIC VOLUMES
C9: 1. Car | D9: 2. Station Wagon | E9: 3. Pickups | F9: 4. Minibus, matatu | G9: 5. Medium bus | H9: 6. Large Bus | I9: 7. Light Truck | J9: 8. Medium Truck | K9: 9. Heavy truck | L9: 10. Truck Trailer | M9: 11. Motor cycles | N9: 12. Tractors | O9: Total Excl M/Cycles | P9: Total All | R9: Time | S9: 1. Car | T9: 2. Station Wagon | U9: 3. Pickups | V9: 4. Minibus, matatu | W9: 5. Medium bus | X9: 6. Large Bus | Y9: 7. Light Truck | Z9: 8. Medium Truck | AA9: 9. Heavy truck | AB9: 10. Truck Trailer | AC9: 11. Motorcycles | AD9: 12. Tractors, Graders | AE9: Total Excl M/ Cycles | AF9: Total All
B10: 07.00 - 07.15 | C10: 2 | D10: 2 | E10: 1 | F10: 3 | G10: 0 | H10: 0 | I10: 1 | J10: 0 | K10: 1 | L10: 0 | M10: 3 | N10: 0 | O10: =SUM(C10:L10,N10) -> 10 | P10: =SUM(C10:N10) -> 13 | R10: 0700-0800 | S10: =SUM(C10:C13) -> 2 | T10: =SUM(D10:D13) -> 2 | U10: =SUM(E10:E13) -> 2 | V10: =SUM(F10:F13) -> 3 | W10: =SUM(G10:G13) -> 0 | X10: =SUM(H10:H13) -> 0 | Y10: =SUM(I10:I13) -> 3 | Z10: =SUM(J10:J13) -> 0 | ... AF10: =SUM(P10:P13) -> 42
B11: 07.15 - 07.30 | C11: 0 | D11: 0 | E11: 0 | F11: 0 | G11: 0 | H11: 0 | I11: 0 | J11: 0 | K11: 0 | L11: 0 | M11: 7 | N11: 0 | O11: =SUM(C11:L11,N11) -> 0 | P11: =SUM(C11:N11) -> 7 | R11: 0800-0900 | S11: =SUM(C14:C17) -> 2 | T11: =SUM(D14:D17) -> 4 | U11: =SUM(E14:E17) -> 1 | V11: =SUM(F14:F17) -> 0 | W11: =SUM(G14:G17) -> 0 | X11: =SUM(H14:H17) -> 0 | Y11: =SUM(I14:I17) -> 1 | Z11: =SUM(J14:J17) -> 1 | ... AF11: =SUM(P14:P17) -> 29
B12: 07.30 - 07.45 | C12: 0 | D12: 0 | E12: 1 | F12: 0 | G12: 0 | H12: 0 | I12: 2 | J12: 0 | K12: 0 | L12: 0 | M12: 1 | N12: 0 | O12: =SUM(C12:L12,N12) -> 3 | P12: =SUM(C12:N12) -> 4 | R12: 0900-1000 | S12: =SUM(C18:C21) -> 1 | T12: =SUM(D18:D21) -> 3 | U12: =SUM(E18:E21) -> 0 | V12: =SUM(F18:F21) -> 3 | W12: =SUM(G18:G21) -> 0 | X12: =SUM(H18:H21) -> 0 | Y12: =SUM(I18:I21) -> 5 | Z12: =SUM(J18:J21) -> 0 | ... AF12: =SUM(P18:P21) -> 38
B13: 07.45 - 08.00 | C13: 0 | D13: 0 | E13: 0 | F13: 0 | G13: 0 | H13: 0 | I13: 0 | J13: 0 | K13: 3 | L13: 0 | M13: 15 | N13: 0 | O13: =SUM(C13:L13,N13) -> 3 | P13: =SUM(C13:N13) -> 18 | R13: 1000-1100 | S13: =SUM(C22:C25) -> 1 | T13: =SUM(D22:D25) -> 0 | U13: =SUM(E22:E25) -> 4 | V13: =SUM(F22:F25) -> 0 | W13: =SUM(G22:G25) -> 0 | X13: =SUM(H22:H25) -> 0 | Y13: =SUM(I22:I25) -> 2 | Z13: =SUM(J22:J25) -> 0 | ... AF13: =SUM(P22:P25) -> 33
B14: 08.00 - 08.15 | C14: 0 | D14: 1 | E14: 1 | F14: 0 | G14: 0 | H14: 0 | I14: 1 | J14: 0 | K14: 2 | L14: 0 | M14: 4 | N14: 0 | O14: =SUM(C14:L14,N14) -> 5 | P14: =SUM(C14:N14) -> 9 | R14: 1100-1200 | S14: =SUM(C26:C29) -> 1 | T14: =SUM(D26:D29) -> 7 | U14: =SUM(E26:E29) -> 0 | V14: =SUM(F26:F29) -> 0 | W14: =SUM(G26:G29) -> 2 | X14: =SUM(H26:H29) -> 0 | Y14: =SUM(I26:I29) -> 4 | Z14: =SUM(J26:J29) -> 0 | ... AF14: =SUM(P26:P29) -> 40
B15: 08.15 - 08.30 | C15: 2 | D15: 2 | E15: 0 | F15: 0 | G15: 0 | H15: 0 | I15: 0 | J15: 0 | K15: 1 | L15: 0 | M15: 6 | N15: 0 | O15: =SUM(C15:L15,N15) -> 5 | P15: =SUM(C15:N15) -> 11 | R15: 1200-1300 | S15: =SUM(C30:C33) -> 1 | T15: =SUM(D30:D33) -> 5 | U15: =SUM(E30:E33) -> 3 | V15: =SUM(F30:F33) -> 2 | W15: =SUM(G30:G33) -> 1 | X15: =SUM(H30:H33) -> 0 | Y15: =SUM(I30:I33) -> 2 | Z15: =SUM(J30:J33) -> 2 | ... AF15: =SUM(P30:P33) -> 41
