Workbook

Sheet 25.10 BULIISA-HOIMA
B1: Consultancy services for Preparation of Expressway Development Master Plan (EDMP) for Uganda
B2: MANUAL CLASSIFIED COUNT (MCC)
B3: ROAD NAME: | C3: MCC - C4 - STN111A- BULIISA HOIMA ROAD
C5: Date | D5: 25.10.19 | F5: Location | G5: KISIABI | J5: Surveyor | K5: CATHY
C6: Dir. From | D6: BULIISA | F6: Dir. To | G6: HOIMA | J6: Supervisor | K6: LAWRENCE
B8: Time / Veh Type | R8: SUMMARY TRAFFIC VOLUMES
C9: 1. Car | D9: 2. Station Wagon | E9: 3. Pickups | F9: 4. Minibus, matatu | G9: 5. Medium bus | H9: 6. Large Bus | I9: 7. Light Truck | J9: 8. Medium Truck | K9: 9. Heavy truck | L9: 10. Truck Trailer | M9: 11. Motor cycles | N9: 12. Tractors | O9: Total Excl M/Cycles | P9: Total All | R9: Time | S9: 1. Car | T9: 2. Station Wagon | U9: 3. Pickups | V9: 4. Minibus, matatu | W9: 5. Medium bus | X9: 6. Large Bus | Y9: 7. Light Truck | Z9: 8. Medium Truck | AA9: 9. Heavy truck | AB9: 10. Truck Trailer | AC9: 11. Motorcycles | AD9: 12. Tractors, Graders | AE9: Total Excl M/ Cycles | AF9: Total All
B10: 07.00 - 07.15 | C10: 0 | D10: 0 | E10: 0 | F10: 1 | G10: 0 | H10: 0 | I10: 0 | J10: 0 | K10: 1 | L10: 0 | M10: 3 | N10: 0 | O10: =SUM(C10:L10,N10) -> 2 | P10: =SUM(C10:N10) -> 5 | R10: 0700-0800 | S10: =SUM(C10:C13) -> 2 | T10: =SUM(D10:D13) -> 1 | U10: =SUM(E10:E13) -> 1 | V10: =SUM(F10:F13) -> 7 | W10: =SUM(G10:G13) -> 0 | X10: =SUM(H10:H13) -> 0 | Y10: =SUM(I10:I13) -> 0 | Z10: =SUM(J10:J13) -> 1 | ... AF10: =SUM(P10:P13) -> 27
B11: 07.15 - 07.30 | C11: 1 | D11: 1 | E11: 0 | F11: 1 | G11: 0 | H11: 0 | I11: 0 | J11: 1 | K11: 0 | L11: 0 | M11: 5 | N11: 0 | O11: =SUM(C11:L11,N11) -> 4 | P11: =SUM(C11:N11) -> 9 | R11: 0800-0900 | S11: =SUM(C14:C17) -> 0 | T11: =SUM(D14:D17) -> 0 | U11: =SUM(E14:E17) -> 2 | V11: =SUM(F14:F17) -> 4 | W11: =SUM(G14:G17) -> 0 | X11: =SUM(H14:H17) -> 0 | Y11: =SUM(I14:I17) -> 0 | Z11: =SUM(J14:J17) -> 1 | ... AF11: =SUM(P14:P17) -> 21
B12: 07.30 - 07.45 | C12: 0 | D12: 0 | E12: 1 | F12: 1 | G12: 0 | H12: 0 | I12: 0 | J12: 0 | K12: 0 | L12: 0 | M12: 3 | N12: 0 | O12: =SUM(C12:L12,N12) -> 2 | P12: =SUM(C12:N12) -> 5 | R12: 0900-1000 | S12: =SUM(C18:C21) -> 1 | T12: =SUM(D18:D21) -> 0 | U12: =SUM(E18:E21) -> 2 | V12: =SUM(F18:F21) -> 5 | W12: =SUM(G18:G21) -> 0 | X12: =SUM(H18:H21) -> 0 | Y12: =SUM(I18:I21) -> 0 | Z12: =SUM(J18:J21) -> 1 | ... AF12: =SUM(P18:P21) -> 31
B13: 07.45 - 08.00 | C13: 1 | D13: 0 | E13: 0 | F13: 4 | G13: 0 | H13: 0 | I13: 0 | J13: 0 | K13: 0 | L13: 0 | M13: 3 | N13: 0 | O13: =SUM(C13:L13,N13) -> 5 | P13: =SUM(C13:N13) -> 8 | R13: 1000-1100 | S13: =SUM(C22:C25) -> 4 | T13: =SUM(D22:D25) -> 0 | U13: =SUM(E22:E25) -> 0 | V13: =SUM(F22:F25) -> 2 | W13: =SUM(G22:G25) -> 0 | X13: =SUM(H22:H25) -> 0 | Y13: =SUM(I22:I25) -> 1 | Z13: =SUM(J22:J25) -> 1 | ... AF13: =SUM(P22:P25) -> 26
B14: 08.00 - 08.15 | C14: 0 | D14: 0 | E14: 0 | F14: 1 | G14: 0 | H14: 0 | I14: 0 | J14: 0 | K14: 0 | L14: 0 | M14: 3 | N14: 0 | O14: =SUM(C14:L14,N14) -> 1 | P14: =SUM(C14:N14) -> 4 | R14: 1100-1200 | S14: =SUM(C26:C29) -> 0 | T14: =SUM(D26:D29) -> 0 | U14: =SUM(E26:E29) -> 2 | V14: =SUM(F26:F29) -> 2 | W14: =SUM(G26:G29) -> 0 | X14: =SUM(H26:H29) -> 0 | Y14: =SUM(I26:I29) -> 0 | Z14: =SUM(J26:J29) -> 0 | ... AF14: =SUM(P26:P29) -> 19
B15: 08.15 - 08.30 | C15: 0 | D15: 0 | E15: 2 | F15: 1 | G15: 0 | H15: 0 | I15: 0 | J15: 1 | K15: 0 | L15: 0 | M15: 6 | N15: 0 | O15: =SUM(C15:L15,N15) -> 4 | P15: =SUM(C15:N15) -> 10 | R15: 1200-1300 | S15: =SUM(C30:C33) -> 1 | T15: =SUM(D30:D33) -> 0 | U15: =SUM(E30:E33) -> 0 | V15: =SUM(F30:F33) -> 1 | W15: =SUM(G30:G33) -> 0 | X15: =SUM(H30:H33) -> 0 | Y15: =SUM(I30:I33) -> 1 | Z15: =SUM(J30:J33) -> 0 | ... AF15: =SUM(P30:P33) -> 18
B16: 08.30 - 08.45 | C16: 0 | D16: 0 | E16: 0 | F16: 1 | G16: 0 | H16: 0 | I16: 0 | J16: 0 | K16: 0 | L16: 0 | M16: 3 | N16: 0 | O16: =SUM(C16:L16,N16) -> 1 | P16: =SUM(C16:N16) -> 4 | R16: 1300-1400 | S16: =SUM(C34:C37) -> 3 | T16: =SUM(D34:D37) -> 1 | U16: =SUM(E34:E37) -> 1 | V16: =SUM(F34:F37) -> 3 | W16: =SUM(G34:G37) -> 0 | X16: =SUM(H34:H37) -> 0 | Y16: =SUM(I34:I37) -> 0 | Z16: =SUM(J34:J37) -> 0 | ... AF16: =SUM(P34:P37) -> 17
B17: 08.45 - 9.00 | C17: 0 | D17: 0 | E17: 0 | F17: 1 | G17: 0 | H17: 0 | I17: 0 | J17: 0 | K17: 0 | L17: 0 | M17: 2 | N17: 0 | O17: =SUM(C17:L17,N17) -> 1 | P17: =SUM(C17:N17) -> 3 | R17: 1400-1500 | S17: =SUM(C38:C41) -> 0 | T17: =SUM(D38:D41) -> 0 | U17: =SUM(E38:E41) -> 0 | V17: =SUM(F38:F41) -> 2 | W17: =SUM(G38:G41) -> 0 | X17: =SUM(H38:H41) -> 0 | Y17: =SUM(I38:I41) -> 0 | Z17: =SUM(J38:J41) -> 1 | ... AF17: =SUM(P38:P41) -> 14
B18: 09.00 - 09.15 | C18: 0 | D18: 0 | E18: 0 | F18: 1 | G18: 0 | H18: 0 | I18: 0 | J18: 0 | K18: 0 | L18: 0 | M18: 7 | N18: 0 | O18: =SUM(C18:L18,N18) -> 1 | P18: =SUM(C18:N18) -> 8 | R18: 1500-1600 | S18: =SUM(C42:C45) -> 1 | T18: =SUM(D42:D45) -> 0 | U18: =SUM(E42:E45) -> 2 | V18: =SUM(F42:F45) -> 1 | W18: =SUM(G42:G45) -> 0 | X18: =SUM(H42:H45) -> 0 | Y18: =SUM(I42:I45) -> 1 | Z18: =SUM(J42:J45) -> 0 | ... AF18: =SUM(P42:P45) -> 15
B19: 09.15 - 09.30 | C19: 0 | D19: 0 | E19: 1 | F19: 2 | G19: 0 | H19: 0 | I19: 0 | J19: 1 | K19: 0 | L19: 0 | M19: 8 | N19: 0 | O19: =SUM(C19:L19,N19) -> 4 | P19: =SUM(C19:N19) -> 12 | R19: 1600-1700 | S19: =SUM(C46:C49) -> 1 | T19: =SUM(D46:D49) -> 0 | U19: =SUM(E46:E49) -> 2 | V19: =SUM(F46:F49) -> 5 | W19: =SUM(G46:G49) -> 0 | X19: =SUM(H46:H49) -> 0 | Y19: =SUM(I46:I49) -> 1 | Z19: =SUM(J46:J49) -> 1 | ... AF19: =SUM(P46:P49) -> 35
B20: 09.30 - 09.45 | C20: 0 | D20: 0 | E20: 1 | F20: 2 | G20: 0 | H20: 0 | I20: 0 | J20: 0 | K20: 0 | L20: 0 | M20: 5 | N20: 0 | O20: =SUM(C20:L20,N20) -> 3 | P20: =SUM(C20:N20) -> 8 | R20: 1700-1800 | S20: =SUM(C50:C53) -> 3 | T20: =SUM(D50:D53) -> 1 | U20: =SUM(E50:E53) -> 6 | V20: =SUM(F50:F53) -> 1 | W20: =SUM(G50:G53) -> 0 | X20: =SUM(H50:H53) -> 0 | Y20: =SUM(I50:I53) -> 1 | Z20: =SUM(J50:J53) -> 0 | ... AF20: =SUM(P50:P53) -> 32
B21: 09.45 - 10.00 | C21: 1 | D21: 0 | E21: 0 | F21: 0 | G21: 0 | H21: 0 | I21: 0 | J21: 0 | K21: 0 | L21: 0 | M21: 2 | N21: 0 | O21: =SUM(C21:L21,N21) -> 1 | P21: =SUM(C21:N21) -> 3 | R21: 1800-1900 | S21: =SUM(C54:C57) -> 0 | T21: =SUM(D54:D57) -> 0 | U21: =SUM(E54:E57) -> 0 | V21: =SUM(F54:F57) -> 3 | W21: =SUM(G54:G57) -> 0 | X21: =SUM(H54:H57) -> 0 | Y21: =SUM(I54:I57) -> 0 | Z21: =SUM(J54:J57) -> 0 | ... AF21: =SUM(P54:P57) -> 21
B22: 10.00 - 10.15 | C22: 2 | D22: 0 | E22: 0 | F22: 0 | G22: 0 | H22: 0 | I22: 0 | J22: 0 | K22: 0 | L22: 0 | M22: 7 | N22: 0 | O22: =SUM(C22:L22,N22) -> 2 | P22: =SUM(C22:N22) -> 9 | R22: AM Peak Hr | S22: =MAX(S10:S12) -> 2 | T22: =MAX(T10:T12) -> 1 | U22: =MAX(U10:U12) -> 2 | V22: =MAX(V10:V12) -> 7 | W22: =MAX(W10:W12) -> 0 | X22: =MAX(X10:X12) -> 0 | Y22: =MAX(Y10:Y12) -> 0 | Z22: =MAX(Z10:Z12) -> 1 | ... AF22: =MAX(AF10:AF12) -> 31
B23: 10.15 - 10.30 | C23: 1 | D23: 0 | E23: 0 | F23: 0 | G23: 0 | H23: 0 | I23: 0 | J23: 0 | K23: 1 | L23: 0 | M23: 5 | N23: 0 | O23: =SUM(C23:L23,N23) -> 2 | P23: =SUM(C23:N23) -> 7 | R23: IP Peak Hr | S23: =MAX(S13:S18) -> 4 | T23: =MAX(T13:T18) -> 1 | U23: =MAX(U13:U18) -> 2 | V23: =MAX(V13:V18) -> 3 | W23: =MAX(W13:W18) -> 0 | X23: =MAX(X13:X18) -> 0 | Y23: =MAX(Y13:Y18) -> 1 | Z23: =MAX(Z13:Z18) -> 1 | ... AF23: =MAX(AF13:AF18) -> 26
B24: 10.30 - 10.45 | C24: 0 | D24: 0 | E24: 0 | F24: 2 | G24: 0 | H24: 0 | I24: 0 | J24: 0 | K24: 0 | L24: 0 | M24: 2 | N24: 0 | O24: =SUM(C24:L24,N24) -> 2 | P24: =SUM(C24:N24) -> 4 | R24: PM Peak Hr | S24: =MAX(S19:S21) -> 3 | T24: =MAX(T19:T21) -> 1 | U24: =MAX(U19:U21) -> 6 | V24: =MAX(V19:V21) -> 5 | W24: =MAX(W19:W21) -> 0 | X24: =MAX(X19:X21) -> 0 | Y24: =MAX(Y19:Y21) -> 1 | Z24: =MAX(Z19:Z21) -> 1 | ... AF24: =MAX(AF19:AF21) -> 35
B25: 10.45 - 11.00 | C25: 1 | D25: 0 | E25: 0 | F25: 0 | G25: 0 | H25: 0 | I25: 1 | J25: 1 | K25: 0 | L25: 0 | M25: 3 | N25: 0 | O25: =SUM(C25:L25,N25) -> 3 | P25: =SUM(C25:N25) -> 6 | R25: AM Period | S25: =SUM(S10:S12) -> 3 | T25: =SUM(T10:T12) -> 1 | U25: =SUM(U10:U12) -> 5 | V25: =SUM(V10:V12) -> 16 | W25: =SUM(W10:W12) -> 0 | X25: =SUM(X10:X12) -> 0 | Y25: =SUM(Y10:Y12) -> 0 | Z25: =SUM(Z10:Z12) -> 3 | ... AF25: =SUM(AF10:AF12) -> 79
B26: 11.00 - 11.15 | C26: 0 | D26: 0 | E26: 1 | F26: 0 | G26: 0 | H26: 0 | I26: 0 | J26: 0 | K26: 0 | L26: 0 | M26: 5 | N26: 0 | O26: =SUM(C26:L26,N26) -> 1 | P26: =SUM(C26:N26) -> 6 | R26: IP Period | S26: =SUM(S13:S18) -> 9 | T26: =SUM(T13:T18) -> 1 | U26: =SUM(U13:U18) -> 5 | V26: =SUM(V13:V18) -> 11 | W26: =SUM(W13:W18) -> 0 | X26: =SUM(X13:X18) -> 0 | Y26: =SUM(Y13:Y18) -> 3 | Z26: =SUM(Z13:Z18) -> 2 | ... AF26: =SUM(AF13:AF18) -> 109
B27: 11.15 - 11.30 | C27: 0 | D27: 0 | E27: 1 | F27: 1 | G27: 0 | H27: 0 | I27: 0 | J27: 0 | K27: 0 | L27: 0 | M27: 2 | N27: 0 | O27: =SUM(C27:L27,N27) -> 2 | P27: =SUM(C27:N27) -> 4 | R27: PM Period | S27: =SUM(S19:S21) -> 4 | T27: =SUM(T19:T21) -> 1 | U27: =SUM(U19:U21) -> 8 | V27: =SUM(V19:V21) -> 9 | W27: =SUM(W19:W21) -> 0 | X27: =SUM(X19:X21) -> 0 | Y27: =SUM(Y19:Y21) -> 2 | Z27: =SUM(Z19:Z21) -> 1 | ... AF27: =SUM(AF19:AF21) -> 88
B28: 11.30 - 11.45 | C28: 0 | D28: 0 | E28: 0 | F28: 0 | G28: 0 | H28: 0 | I28: 0 | J28: 0 | K28: 0 | L28: 0 | M28: 4 | N28: 0 | O28: =SUM(C28:L28,N28) -> 0 | P28: =SUM(C28:N28) -> 4 | R28: 12 Hours | S28: =SUM(S10:S21) -> 16 | T28: =SUM(T10:T21) -> 3 | U28: =SUM(U10:U21) -> 18 | V28: =SUM(V10:V21) -> 36 | W28: =SUM(W10:W21) -> 0 | X28: =SUM(X10:X21) -> 0 | Y28: =SUM(Y10:Y21) -> 5 | Z28: =SUM(Z10:Z21) -> 6 | ... AF28: =SUM(AF10:AF21) -> 276
B29: 11.45 - 12.00 | C29: 0 | D29: 0 | E29: 0 | F29: 1 | G29: 0 | H29: 0 | I29: 0 | J29: 0 | K29: 0 | L29: 0 | M29: 4 | N29: 0 | O29: =SUM(C29:L29,N29) -> 1 | P29: =SUM(C29:N29) -> 5
B30: 12.00 - 12.15 | C30: 0 | D30: 0 | E30: 0 | F30: 0 | G30: 0 | H30: 0 | I30: 0 | J30: 0 | K30: 0 | L30: 0 | M30: 4 | N30: 0 | O30: =SUM(C30:L30,N30) -> 0 | P30: =SUM(C30:N30) -> 4
B31: 12.15 - 12.30 | C31: 1 | D31: 0 | E31: 0 | F31: 1 | G31: 0 | H31: 0 | I31: 0 | J31: 0 | K31: 0 | L31: 0 | M31: 4 | N31: 0 | O31: =SUM(C31:L31,N31) -> 2 | P31: =SUM(C31:N31) -> 6
B32: 12.30 - 12.45 | C32: 0 | D32: 0 | E32: 0 | F32: 0 | G32: 0 | H32: 0 | I32: 0 | J32: 0 | K32: 0 | L32: 0 | M32: 4 | N32: 0 | O32: =SUM(C32:L32,N32) -> 0 | P32: =SUM(C32:N32) -> 4
B33: 12.45 - 13.00 | C33: 0 | D33: 0 | E33: 0 | F33: 0 | G33: 0 | H33: 0 | I33: 1 | J33: 0 | K33: 0 | L33: 0 | M33: 3 | N33: 0 | O33: =SUM(C33:L33,N33) -> 1 | P33: =SUM(C33:N33) -> 4
B34: 13.00 - 13.15 | C34: 1 | D34: 0 | E34: 0 | F34: 2 | G34: 0 | H34: 0 | I34: 0 | J34: 0 | K34: 0 | L34: 0 | M34: 2 | N34: 0 | O34: =SUM(C34:L34,N34) -> 3 | P34: =SUM(C34:N34) -> 5
B35: 13.15 - 13.30 | C35: 0 | D35: 0 | E35: 0 | F35: 0 | G35: 0 | H35: 0 | I35: 0 | J35: 0 | K35: 0 | L35: 0 | M35: 3 | N35: 0 | O35: =SUM(C35:L35,N35) -> 0 | P35: =SUM(C35:N35) -> 3
B36: 13.30 - 13.45 | C36: 1 | D36: 0 | E36: 0 | F36: 1 | G36: 0 | H36: 0 | I36: 0 | J36: 0 | K36: 0 | L36: 0 | M36: 3 | N36: 0 | O36: =SUM(C36:L36,N36) -> 2 | P36: =SUM(C36:N36) -> 5
B37: 13.45 - 14.00 | C37: 1 | D37: 1 | E37: 1 | F37: 0 | G37: 0 | H37: 0 | I37: 0 | J37: 0 | K37: 0 | L37: 0 | M37: 1 | N37: 0 | O37: =SUM(C37:L37,N37) -> 3 | P37: =SUM(C37:N37) -> 4
B38: 14.00 - 14.15 | C38: 0 | D38: 0 | E38: 0 | F38: 1 | G38: 0 | H38: 0 | I38: 0 | J38: 0 | K38: 0 | L38: 0 | M38: 2 | N38: 0 | O38: =SUM(C38:L38,N38) -> 1 | P38: =SUM(C38:N38) -> 3
B39: 14.15 - 14.30 | C39: 0 | D39: 0 | E39: 0 | F39: 0 | G39: 0 | H39: 0 | I39: 0 | J39: 0 | K39: 0 | L39: 0 | M39: 4 | N39: 0 | O39: =SUM(C39:L39,N39) -> 0 | P39: =SUM(C39:N39) -> 4
B40: 14.30 - 14.45 | C40: 0 | D40: 0 | E40: 0 | F40: 0 | G40: 0 | H40: 0 | I40: 0 | J40: 0 | K40: 0 | L40: 0 | M40: 1 | N40: 0 | O40: =SUM(C40:L40,N40) -> 0 | P40: =SUM(C40:N40) -> 1
... B57: 18.45 - 19.00 | C57: 0 | D57: 0 | E57: 0 | F57: 1 | G57: 0 | H57: 0 | I57: 0 | J57: 0 | K57: 0 | L57: 0 | M57: 2 | N57: 0 | O57: =SUM(C57:L57,N57) -> 1 | P57: =SUM(C57:N57) -> 3
B58: Totals | C58: =SUM(C10:C57) -> 16 | D58: =SUM(D10:D57) -> 3 | E58: =SUM(E10:E57) -> 18 | F58: =SUM(F10:F57) -> 36 | G58: =SUM(G10:G57) -> 0 | H58: =SUM(H10:H57) -> 0 | I58: =SUM(I10:I57) -> 5 | J58: =SUM(J10:J57) -> 6 | ... P58: =SUM(P10:P57) -> 276
...

Sheet 25.10 HOIMA-BULIISA
B1: Consultancy services for Preparation of Expressway Development Master Plan (EDMP) for Uganda
B2: MANUAL CLASSIFIED COUNT (MCC)
B3: ROAD NAME: | C3: ='25.10 BULIISA-HOIMA'!C3:G3 -> MCC - C4 - STN111A- BULIISA HOIMA ROAD
C5: Date | D5: ='25.10 BULIISA-HOIMA'!D5 -> 25.10.19 | F5: Location | G5: ='25.10 BULIISA-HOIMA'!G5:H5 -> KISIABI | J5: Surveyor | K5: LAWRENCE
C6: Dir. From | D6: HOIMA | F6: Dir. To | G6: BULIISA | J6: Supervisor | K6: ='25.10 BULIISA-HOIMA'!K6:L6 -> LAWRENCE
B8: Time / Veh Type | R8: SUMMARY TRAFFIC VOLUMES
C9: 1. Car | D9: 2. Station Wagon | E9: 3. Pickups | F9: 4. Minibus, matatu | G9: 5. Medium bus | H9: 6. Large Bus | I9: 7. Light Truck | J9: 8. Medium Truck | K9: 9. Heavy truck | L9: 10. Truck Trailer | M9: 11. Motor cycles | N9: 12. Tractors | O9: Total Excl M/Cycles | P9: Total All | R9: Time | S9: 1. Car | T9: 2. Station Wagon | U9: 3. Pickups | V9: 4. Minibus, matatu | W9: 5. Medium bus | X9: 6. Large Bus | Y9: 7. Light Truck | Z9: 8. Medium Truck | AA9: 9. Heavy truck | AB9: 10. Truck Trailer | AC9: 11. Motorcycles | AD9: 12. Tractors, Graders | AE9: Total Excl M/ Cycles | AF9: Total All
B10: 07.00 - 07.15 | C10: 0 | D10: 0 | E10: 1 | F10: 0 | G10: 0 | H10: 0 | I10: 0 | J10: 0 | K10: 0 | L10: 0 | M10: 4 | N10: 0 | O10: =SUM(C10:L10,N10) -> 1 | P10: =SUM(C10:N10) -> 5 | R10: 0700-0800 | S10: =SUM(C10:C13) -> 0 | T10: =SUM(D10:D13) -> 0 | U10: =SUM(E10:E13) -> 2 | V10: =SUM(F10:F13) -> 4 | W10: =SUM(G10:G13) -> 0 | X10: =SUM(H10:H13) -> 0 | Y10: =SUM(I10:I13) -> 1 | Z10: =SUM(J10:J13) -> 2 | ... AF10: =SUM(P10:P13) -> 23
B11: 07.15 - 07.30 | C11: 0 | D11: 0 | E11: 1 | F11: 0 | G11: 0 | H11: 0 | I11: 1 | J11: 1 | K11: 0 | L11: 0 | M11: 4 | N11: 0 | O11: =SUM(C11:L11,N11) -> 3 | P11: =SUM(C11:N11) -> 7 | R11: 0800-0900 | S11: =SUM(C14:C17) -> 1 | T11: =SUM(D14:D17) -> 0 | U11: =SUM(E14:E17) -> 5 | V11: =SUM(F14:F17) -> 4 | W11: =SUM(G14:G17) -> 0 | X11: =SUM(H14:H17) -> 0 | Y11: =SUM(I14:I17) -> 0 | Z11: =SUM(J14:J17) -> 0 | ... AF11: =SUM(P14:P17) -> 37
B12: 07.30 - 07.45 | C12: 0 | D12: 0 | E12: 0 | F12: 3 | G12: 0 | H12: 0 | I12: 0 | J12: 0 | K12: 0 | L12: 0 | M12: 6 | N12: 0 | O12: =SUM(C12:L12,N12) -> 3 | P12: =SUM(C12:N12) -> 9 | R12: 0900-1000 | S12: =SUM(C18:C21) -> 3 | T12: =SUM(D18:D21) -> 0 | U12: =SUM(E18:E21) -> 0 | V12: =SUM(F18:F21) -> 4 | W12: =SUM(G18:G21) -> 0 | X12: =SUM(H18:H21) -> 0 | Y12: =SUM(I18:I21) -> 2 | Z12: =SUM(J18:J21) -> 0 | ... AF12: =SUM(P18:P21) -> 26
B13: 07.45 - 08.00 | C13: 0 | D13: 0 | E13: 0 | F13: 1 | G13: 0 | H13: 0 | I13: 0 | J13: 1 | K13: 0 | L13: 0 | M13: 0 | N13: 0 | O13: =SUM(C13:L13,N13) -> 2 | P13: =SUM(C13:N13) -> 2 | R13: 1000-1100 | S13: =SUM(C22:C25) -> 3 | T13: =SUM(D22:D25) -> 0 | U13: =SUM(E22:E25) -> 2 | V13: =SUM(F22:F25) -> 0 | W13: =SUM(G22:G25) -> 0 | X13: =SUM(H22:H25) -> 0 | Y13: =SUM(I22:I25) -> 0 | Z13: =SUM(J22:J25) -> 0 | ... AF13: =SUM(P22:P25) -> 22
B14: 08.00 - 08.15 | C14: 0 | D14: 0 | E14: 1 | F14: 0 | G14: 0 | H14: 0 | I14: 0 | J14: 0 | K14: 0 | L14: 0 | M14: 4 | N14: 0 | O14: =SUM(C14:L14,N14) -> 1 | P14: =SUM(C14:N14) -> 5 | R14: 1100-1200 | S14: =SUM(C26:C29) -> 0 | T14: =SUM(D26:D29) -> 0 | U14: =SUM(E26:E29) -> 2 | V14: =SUM(F26:F29) -> 2 | W14: =SUM(G26:G29) -> 0 | X14: =SUM(H26:H29) -> 0 | Y14: =SUM(I26:I29) -> 0 | Z14: =SUM(J26:J29) -> 1 | ... AF14: =SUM(P26:P29) -> 20
B15: 08.15 - 08.30 | C15: 0 | D15: 0 | E15: 0 | F15: 1 | G15: 0 | H15: 0 | I15: 0 | J15: 0 | K15: 0 | L15: 0 | M15: 10 | N15: 0 | O15: =SUM(C15:L15,N15) -> 1 | P15: =SUM(C15:N15) -> 11 | R15: 1200-1300 | S15: =SUM(C30:C33) -> 0 | T15: =SUM(D30:D33) -> 0 | U15: =SUM(E30:E33) -> 0 | V15: =SUM(F30:F33) -> 2 | W15: =SUM(G30:G33) -> 0 | X15: =SUM(H30:H33) -> 0 | Y15: =SUM(I30:I33) -> 0 | Z15: =SUM(J30:J33) -> 0 | ... AF15: =SUM(P30:P33) -> 11
B16: 08.30 - 08.45 | C16: 0 | D16: 0 | E16: 2 | F16: 2 | G16: 0 | H16: 0 | I16: 0 | J16: 0 | K16: 1 | L16: 0 | M16: 8 | N16: 0 | O16: =SUM(C16:L16,N16) -> 5 | P16: =SUM(C16:N16) -> 13 | R16: 1300-1400 | S16: =SUM(C34:C37) -> 1 | T16: =SUM(D34:D37) -> 1 | U16: =SUM(E34:E37) -> 1 | V16: =SUM(F34:F37) -> 3 | W16: =SUM(G34:G37) -> 0 | X16: =SUM(H34:H37) -> 0 | Y16: =SUM(I34:I37) -> 0 | Z16: =SUM(J34:J37) -> 0 | ... AF16: =SUM(P34:P37) -> 22
B17: 08.45 - 9.00 | C17: 1 | D17: 0 | E17: 2 | F17: 1 | G17: 0 | H17: 0 | I17: 0 | J17: 0 | K17: 0 | L17: 0 | M17: 4 | N17: 0 | O17: =SUM(C17:L17,N17) -> 4 | P17: =SUM(C17:N17) -> 8 | R17: 1400-1500 | S17: =SUM(C38:C41) -> 0 | T17: =SUM(D38:D41) -> 0 | U17: =SUM(E38:E41) -> 1 | V17: =SUM(F38:F41) -> 4 | W17: =SUM(G38:G41) -> 0 | X17: =SUM(H38:H41) -> 0 | Y17: =SUM(I38:I41) -> 0 | Z17: =SUM(J38:J41) -> 0 | ... AF17: =SUM(P38:P41) -> 12
B18: 09.00 - 09.15 | C18: 2 | D18: 0 | E18: 0 | F18: 1 | G18: 0 | H18: 0 | I18: 0 | J18: 0 | K18: 0 | L18: 0 | M18: 5 | N18: 0 | O18: =SUM(C18:L18,N18) -> 3 | P18: =SUM(C18:N18) -> 8 | R18: 1500-1600 | S18: =SUM(C42:C45) -> 0 | T18: =SUM(D42:D45) -> 0 | U18: =SUM(E42:E45) -> 1 | V18: =SUM(F42:F45) -> 1 | W18: =SUM(G42:G45) -> 0 | X18: =SUM(H42:H45) -> 0 | Y18: =SUM(I42:I45) -> 0 | Z18: =SUM(J42:J45) -> 0 | ... AF18: =SUM(P42:P45) -> 20
B19: 09.15 - 09.30 | C19: 0 | D19: 0 | E19: 0 | F19: `1 | G19: 0 | H19: 0 | I19: 0 | J19: 0 | K19: 0 | L19: 0 | M19: 6 | N19: 0 | O19: =SUM(C19:L19,N19) -> 0 | P19: =SUM(C19:N19) -> 6 | R19: 1600-1700 | S19: =SUM(C46:C49) -> 1 | T19: =SUM(D46:D49) -> 0 | U19: =SUM(E46:E49) -> 1 | V19: =SUM(F46:F49) -> 1 | W19: =SUM(G46:G49) -> 0 | X19: =SUM(H46:H49) -> 0 | Y19: =SUM(I46:I49) -> 2 | Z19: =SUM(J46:J49) -> 2 | ... AF19: =SUM(P46:P49) -> 17
B20: 09.30 - 09.45 | C20: 0 | D20: 0 | E20: 0 | F20: 1 | G20: 0 | H20: 0 | I20: 2 | J20: 0 | K20: 0 | L20: 0 | M20: 1 | N20: 0 | O20: =SUM(C20:L20,N20) -> 3 | P20: =SUM(C20:N20) -> 4 | R20: 1700-1800 | S20: =SUM(C50:C53) -> 1 | T20: =SUM(D50:D53) -> 0 | U20: =SUM(E50:E53) -> 1 | V20: =SUM(F50:F53) -> 5 | W20: =SUM(G50:G53) -> 0 | X20: =SUM(H50:H53) -> 0 | Y20: =SUM(I50:I53) -> 0 | Z20: =SUM(J50:J53) -> 0 | ... AF20: =SUM(P50:P53) -> 23
B21: 09.45 - 10.00 | C21: 1 | D21: 0 | E21: 0 | F21: 2 | G21: 0 | H21: 0 | I21: 0 | J21: 0 | K21: 1 | L21: 0 | M21: 4 | N21: 0 | O21: =SUM(C21:L21,N21) -> 4 | P21: =SUM(C21:N21) -> 8 | R21: 1800-1900 | S21: =SUM(C54:C57) -> 0 | T21: =SUM(D54:D57) -> 1 | U21: =SUM(E54:E57) -> 1 | V21: =SUM(F54:F57) -> 0 | W21: =SUM(G54:G57) -> 0 | X21: =SUM(H54:H57) -> 0 | Y21: =SUM(I54:I57) -> 1 | Z21: =SUM(J54:J57) -> 0 | ... AF21: =SUM(P54:P57) -> 17
B22: 10.00 - 10.15 | C22: 0 | D22: 0 | E22: 1 | F22: 0 | G22: 0 | H22: 0 | I22: 0 | J22: 0 | K22: 0 | L22: 0 | M22: 9 | N22: 0 | O22: =SUM(C22:L22,N22) -> 1 | P22: =SUM(C22:N22) -> 10 | R22: AM Peak Hr | S22: =MAX(S10:S12) -> 3 | T22: =MAX(T10:T12) -> 0 | U22: =MAX(U10:U12) -> 5 | V22: =MAX(V10:V12) -> 4 | W22: =MAX(W10:W12) -> 0 | X22: =MAX(X10:X12) -> 0 | Y22: =MAX(Y10:Y12) -> 2 | Z22: =MAX(Z10:Z12) -> 2 | ... AF22: =MAX(AF10:AF12) -> 37
B23: 10.15 - 10.30 | C23: 1 | D23: 0 | E23: 0 | F23: 0 | G23: 0 | H23: 0 | I23: 0 | J23: 0 | K23: 0 | L23: 0 | M23: 2 | N23: 0 | O23: =SUM(C23:L23,N23) -> 1 | P23: =SUM(C23:N23) -> 3 | R23: IP Peak Hr | S23: =MAX(S13:S18) -> 3 | T23: =MAX(T13:T18) -> 1 | U23: =MAX(U13:U18) -> 2 | V23: =MAX(V13:V18) -> 4 | W23: =MAX(W13:W18) -> 0 | X23: =MAX(X13:X18) -> 0 | Y23: =MAX(Y13:Y18) -> 0 | Z23: =MAX(Z13:Z18) -> 1 | ... AF23: =MAX(AF13:AF18) -> 22
B24: 10.30 - 10.45 | C24: 0 | D24: 0 | E24: 0 | F24: 0 | G24: 0 | H24: 0 | I24: 0 | J24: 0 | K24: 0 | L24: 0 | M24: 2 | N24: 0 | O24: =SUM(C24:L24,N24) -> 0 | P24: =SUM(C24:N24) -> 2 | R24: PM Peak Hr | S24: =MAX(S19:S21) -> 1 | T24: =MAX(T19:T21) -> 1 | U24: =MAX(U19:U21) -> 1 | V24: =MAX(V19:V21) -> 5 | W24: =MAX(W19:W21) -> 0 | X24: =MAX(X19:X21) -> 0 | Y24: =MAX(Y19:Y21) -> 2 | Z24: =MAX(Z19:Z21) -> 2 | ... AF24: =MAX(AF19:AF21) -> 23
B25: 10.45 - 11.00 | C25: 2 | D25: 0 | E25: 1 | F25: 0 | G25: 0 | H25: 0 | I25: 0 | J25: 0 | K25: 0 | L25: 0 | M25: 4 | N25: 0 | O25: =SUM(C25:L25,N25) -> 3 | P25: =SUM(C25:N25) -> 7 | R25: AM Period | S25: =SUM(S10:S12) -> 4 | T25: =SUM(T10:T12) -> 0 | U25: =SUM(U10:U12) -> 7 | V25: =SUM(V10:V12) -> 12 | W25: =SUM(W10:W12) -> 0 | X25: =SUM(X10:X12) -> 0 | Y25: =SUM(Y10:Y12) -> 3 | Z25: =SUM(Z10:Z12) -> 2 | ... AF25: =SUM(AF10:AF12) -> 86
B26: 11.00 - 11.15 | C26: 0 | D26: 0 | E26: 0 | F26: 1 | G26: 0 | H26: 0 | I26: 0 | J26: 0 | K26: 0 | L26: 0 | M26: 2 | N26: 0 | O26: =SUM(C26:L26,N26) -> 1 | P26: =SUM(C26:N26) -> 3 | R26: IP Period | S26: =SUM(S13:S18) -> 4 | T26: =SUM(T13:T18) -> 1 | U26: =SUM(U13:U18) -> 7 | V26: =SUM(V13:V18) -> 12 | W26: =SUM(W13:W18) -> 0 | X26: =SUM(X13:X18) -> 0 | Y26: =SUM(Y13:Y18) -> 0 | Z26: =SUM(Z13:Z18) -> 1 | ... AF26: =SUM(AF13:AF18) -> 107
B27: 11.15 - 11.30 | C27: 0 | D27: 0 | E27: 0 | F27: 0 | G27: 0 | H27: 0 | I27: 0 | J27: 0 | K27: 0 | L27: 0 | M27: 4 | N27: 0 | O27: =SUM(C27:L27,N27) -> 0 | P27: =SUM(C27:N27) -> 4 | R27: PM Period | S27: =SUM(S19:S21) -> 2 | T27: =SUM(T19:T21) -> 1 | U27: =SUM(U19:U21) -> 3 | V27: =SUM(V19:V21) -> 6 | W27: =SUM(W19:W21) -> 0 | X27: =SUM(X19:X21) -> 0 | Y27: =SUM(Y19:Y21) -> 3 | Z27: =SUM(Z19:Z21) -> 2 | ... AF27: =SUM(AF19:AF21) -> 57
B28: 11.30 - 11.45 | C28: 0 | D28: 0 | E28: 1 | F28: 1 | G28: 0 | H28: 0 | I28: 0 | J28: 0 | K28: 0 | L28: 0 | M28: 3 | N28: 0 | O28: =SUM(C28:L28,N28) -> 2 | P28: =SUM(C28:N28) -> 5 | R28: 12 Hours | S28: =SUM(S10:S21) -> 10 | T28: =SUM(T10:T21) -> 2 | U28: =SUM(U10:U21) -> 17 | V28: =SUM(V10:V21) -> 30 | W28: =SUM(W10:W21) -> 0 | X28: =SUM(X10:X21) -> 0 | Y28: =SUM(Y10:Y21) -> 6 | Z28: =SUM(Z10:Z21) -> 5 | ... AF28: =SUM(AF10:AF21) -> 250
B29: 11.45 - 12.00 | C29: 0 | D29: 0 | E29: 1 | F29: 0 | G29: 0 | H29: 0 | I29: 0 | J29: 1 | K29: 0 | L29: 0 | M29: 6 | N29: 0 | O29: =SUM(C29:L29,N29) -> 2 | P29: =SUM(C29:N29) -> 8
B30: 12.00 - 12.15 | C30: 0 | D30: 0 | E30: 0 | F30: 2 | G30: 0 | H30: 0 | I30: 0 | J30: 0 | K30: 0 | L30: 0 | M30: 5 | N30: 0 | O30: =SUM(C30:L30,N30) -> 2 | P30: =SUM(C30:N30) -> 7
B31: 12.15 - 12.30 | C31: 0 | D31: 0 | E31: 0 | F31: 0 | G31: 0 | H31: 0 | I31: 0 | J31: 0 | K31: 0 | L31: 0 | M31: 1 | N31: 0 | O31: =SUM(C31:L31,N31) -> 0 | P31: =SUM(C31:N31) -> 1
B32: 12.30 - 12.45 | C32: 0 | D32: 0 | E32: 0 | F32: 0 | G32: 0 | H32: 0 | I32: 0 | J32: 0 | K32: 0 | L32: 0 | M32: 2 | N32: 0 | O32: =SUM(C32:L32,N32) -> 0 | P32: =SUM(C32:N32) -> 2
B33: 12.45 - 13.00 | C33: 0 | D33: 0 | E33: 0 | F33: 0 | G33: 0 | H33: 0 | I33: 0 | J33: 0 | K33: 0 | L33: 0 | M33: 1 | N33: 0 | O33: =SUM(C33:L33,N33) -> 0 | P33: =SUM(C33:N33) -> 1
B34: 13.00 - 13.15 | C34: 1 | D34: 0 | E34: 0 | F34: 2 | G34: 0 | H34: 0 | I34: 0 | J34: 0 | K34: 0 | L34: 0 | M34: 3 | N34: 0 | O34: =SUM(C34:L34,N34) -> 3 | P34: =SUM(C34:N34) -> 6
B35: 13.15 - 13.30 | C35: 0 | D35: 0 | E35: 0 | F35: 1 | G35: 0 | H35: 0 | I35: 0 | J35: 0 | K35: 0 | L35: 0 | M35: 4 | N35: 0 | O35: =SUM(C35:L35,N35) -> 1 | P35: =SUM(C35:N35) -> 5
B36: 13.30 - 13.45 | C36: 0 | D36: 1 | E36: 1 | F36: 0 | G36: 0 | H36: 0 | I36: 0 | J36: 0 | K36: 0 | L36: 0 | M36: 5 | N36: 0 | O36: =SUM(C36:L36,N36) -> 2 | P36: =SUM(C36:N36) -> 7
B37: 13.45 - 14.00 | C37: 0 | D37: 0 | E37: 0 | F37: 0 | G37: 0 | H37: 0 | I37: 0 | J37: 0 | K37: 0 | L37: 0 | M37: 4 | N37: 0 | O37: =SUM(C37:L37,N37) -> 0 | P37: =SUM(C37:N37) -> 4
B38: 14.00 - 14.15 | C38: 0 | D38: 0 | E38: 0 | F38: 0 | G38: 0 | H38: 0 | I38: 0 | J38: 0 | K38: 0 | L38: 0 | M38: 3 | N38: 0 | O38: =SUM(C38:L38,N38) -> 0 | P38: =SUM(C38:N38) -> 3
B39: 14.15 - 14.30 | C39: 0 | D39: 0 | E39: 0 | F39: 1 | G39: 0 | H39: 0 | I39: 0 | J39: 0 | K39: 0 | L39: 0 | M39: 2 | N39: 0 | O39: =SUM(C39:L39,N39) -> 1 | P39: =SUM(C39:N39) -> 3
B40: 14.30 - 14.45 | C40: 0 | D40: 0 | E40: 0 | F40: 1 | G40: 0 | H40: 0 | I40: 0 | J40: 0 | K40: 0 | L40: 0 | M40: 1 | N40: 0 | O40: =SUM(C40:L40,N40) -> 1 | P40: =SUM(C40:N40) -> 2
... B57: 18.45 - 19.00 | C57: 0 | D57: 0 | E57: 0 | F57: 0 | G57: 0 | H57: 0 | I57: 0 | J57: 0 | K57: 0 | L57: 0 | M57: 4 | N57: 0 | O57: =SUM(C57:L57,N57) -> 0 | P57: =SUM(C57:N57) -> 4
B58: Totals | C58: =SUM(C10:C57) -> 10 | D58: =SUM(D10:D57) -> 2 | E58: =SUM(E10:E57) -> 17 | F58: =SUM(F10:F57) -> 30 | G58: =SUM(G10:G57) -> 0 | H58: =SUM(H10:H57) -> 0 | I58: =SUM(I10:I57) -> 6 | J58: =SUM(J10:J57) -> 5 | ... P58: =SUM(P10:P57) -> 250
...

Sheet 26.10 BULIISA-HOIMA-24h
B1: Consultancy services for Preparation of Expressway Development Master Plan (EDMP) for Uganda
B2: MANUAL CLASSIFIED COUNT (MCC)
B3: ROAD NAME: | C3: ='25.10 BULIISA-HOIMA'!C3:G3 -> MCC - C4 - STN111A- BULIISA HOIMA ROAD
C5: Date | D5: 26.10.19 | F5: Location | G5: ='30.10 HOIMA-BULIISA'!G5:H5 -> KISIABI | J5: Surveyor | K5: FRANK
C6: Dir. From | D6: ='25.10 BULIISA-HOIMA'!D6:E6 -> BULIISA | F6: Dir. To | G6: ='25.10 BULIISA-HOIMA'!G6:H6 -> HOIMA | J6: Supervisor | K6: ='30.10 HOIMA-BULIISA'!K6:L6 -> LAWRENCE
B8: Time / Veh Type | R8: SUMMARY TRAFFIC VOLUMES
C9: 1. Car | D9: 2. Station Wagon | E9: 3. Pickups | F9: 4. Minibus, matatu | G9: 5. Medium bus | H9: 6. Large Bus | I9: 7. Light Truck | J9: 8. Medium Truck | K9: 9. Heavy truck | L9: 10. Truck Trailer | M9: 11. Motor cycles | N9: 12. Tractors | O9: Total Excl M/Cycles | P9: Total All | R9: Time | S9: 1. Car | T9: 2. Station Wagon | U9: 3. Pickups | V9: 4. Minibus, matatu | W9: 5. Medium bus | X9: 6. Large Bus | Y9: 7. Light Truck | Z9: 8. Medium Truck | AA9: 9. Heavy truck | AB9: 10. Truck Trailer | AC9: 11. Motorcycles | AD9: 12. Tractors, Graders | AE9: Total Excl M/ Cycles | AF9: Total All
B10: 07.00 - 07.15 | C10: 0 | D10: 0 | E10: 0 | F10: 0 | G10: 0 | H10: 0 | I10: 0 | J10: 0 | K10: 1 | L10: 0 | M10: 5 | N10: 0 | O10: =SUM(C10:L10,N10) -> 1 | P10: =SUM(C10:N10) -> 6 | R10: 0700-0800 | S10: =SUM(C10:C13) -> 0 | T10: =SUM(D10:D13) -> 1 | U10: =SUM(E10:E13) -> 2 | V10: =SUM(F10:F13) -> 1 | W10: =SUM(G10:G13) -> 0 | X10: =SUM(H10:H13) -> 0 | Y10: =SUM(I10:I13) -> 0 | Z10: =SUM(J10:J13) -> 0 | ... AF10: =SUM(P10:P13) -> 29
B11: 07.15 - 07.30 | C11: 0 | D11: 1 | E11: 1 | F11: 0 | G11: 0 | H11: 0 | I11: 0 | J11: 0 | K11: 0 | L11: 0 | M11: 7 | N11: 0 | O11: =SUM(C11:L11,N11) -> 2 | P11: =SUM(C11:N11) -> 9 | R11: 0800-0900 | S11: =SUM(C14:C17) -> 1 | T11: =SUM(D14:D17) -> 1 | U11: =SUM(E14:E17) -> 1 | V11: =SUM(F14:F17) -> 5 | W11: =SUM(G14:G17) -> 0 | X11: =SUM(H14:H17) -> 0 | Y11: =SUM(I14:I17) -> 1 | Z11: =SUM(J14:J17) -> 0 | ... AF11: =SUM(P14:P17) -> 23
B12: 07.30 - 07.45 | C12: 0 | D12: 0 | E12: 0 | F12: 0 | G12: 0 | H12: 0 | I12: 0 | J12: 0 | K12: 0 | L12: 0 | M12: 7 | N12: 0 | O12: =SUM(C12:L12,N12) -> 0 | P12: =SUM(C12:N12) -> 7 | R12: 0900-1000 | S12: =SUM(C18:C21) -> 1 | T12: =SUM(D18:D21) -> 3 | U12: =SUM(E18:E21) -> 0 | V12: =SUM(F18:F21) -> 5 | W12: =SUM(G18:G21) -> 0 | X12: =SUM(H18:H21) -> 0 | Y12: =SUM(I18:I21) -> 1 | Z12: =SUM(J18:J21) -> 0 | ... AF12: =SUM(P18:P21) -> 41
B13: 07.45 - 08.00 | C13: 0 | D13: 0 | E13: 1 | F13: 1 | G13: 0 | H13: 0 | I13: 0 | J13: 0 | K13: 0 | L13: 0 | M13: 5 | N13: 0 | O13: =SUM(C13:L13,N13) -> 2 | P13: =SUM(C13:N13) -> 7 | R13: 1000-1100 | S13: =SUM(C22:C25) -> 0 | T13: =SUM(D22:D25) -> 2 | U13: =SUM(E22:E25) -> 1 | V13: =SUM(F22:F25) -> 3 | W13: =SUM(G22:G25) -> 0 | X13: =SUM(H22:H25) -> 0 | Y13: =SUM(I22:I25) -> 1 | Z13: =SUM(J22:J25) -> 0 | ... AF13: =SUM(P22:P25) -> 31
B14: 08.00 - 08.15 | C14: 0 | D14: 0 | E14: 0 | F14: 2 | G14: 0 | H14: 0 | I14: 0 | J14: 0 | K14: 0 | L14: 0 | M14: 2 | N14: 0 | O14: =SUM(C14:L14,N14) -> 2 | P14: =SUM(C14:N14) -> 4 | R14: 1100-1200 | S14: =SUM(C26:C29) -> 0 | T14: =SUM(D26:D29) -> 0 | U14: =SUM(E26:E29) -> 1 | V14: =SUM(F26:F29) -> 2 | W14: =SUM(G26:G29) -> 0 | X14: =SUM(H26:H29) -> 0 | Y14: =SUM(I26:I29) -> 0 | Z14: =SUM(J26:J29) -> 0 | ... AF14: =SUM(P26:P29) -> 21
B15: 08.15 - 08.30 | C15: 1 | D15: 1 | E15: 1 | F15: 1 | G15: 0 | H15: 0 | I15: 0 | J15: 0 | K15: 0 | L15: 0 | M15: 3 | N15: 0 | O15: =SUM(C15:L15,N15) -> 4 | P15: =SUM(C15:N15) -> 7 | R15: 1200-1300 | S15: =SUM(C30:C33) -> 0 | T15: =SUM(D30:D33) -> 0 | U15: =SUM(E30:E33) -> 0 | V15: =SUM(F30:F33) -> 0 | W15: =SUM(G30:G33) -> 0 | X15: =SUM(H30:H33) -> 0 | Y15: =SUM(I30:I33) -> 0 | Z15: =SUM(J30:J33) -> 0 | ... AF15: =SUM(P30:P33) -> 10
B16: 08.30 - 08.45 | C16: 0 | D16: 0 | E16: 0 | F16: 0 | G16: 0 | H16: 0 | I16: 1 | J16: 0 | K16: 0 | L16: 0 | M16: 6 | N16: 0 | O16: =SUM(C16:L16,N16) -> 1 | P16: =SUM(C16:N16) -> 7 | R16: 1300-1400 | S16: =SUM(C34:C37) -> 0 | T16: =SUM(D34:D37) -> 0 | U16: =SUM(E34:E37) -> 2 | V16: =SUM(F34:F37) -> 1 | W16: =SUM(G34:G37) -> 0 | X16: =SUM(H34:H37) -> 0 | Y16: =SUM(I34:I37) -> 0 | Z16: =SUM(J34:J37) -> 0 | ... AF16: =SUM(P34:P37) -> 17
B17: 08.45 - 9.00 | C17: 0 | D17: 0 | E17: 0 | F17: 2 | G17: 0 | H17: 0 | I17: 0 | J17: 0 | K17: 0 | L17: 0 | M17: 3 | N17: 0 | O17: =SUM(C17:L17,N17) -> 2 | P17: =SUM(C17:N17) -> 5 | R17: 1400-1500 | S17: =SUM(C38:C41) -> 1 | T17: =SUM(D38:D41) -> 0 | U17: =SUM(E38:E41) -> 1 | V17: =SUM(F38:F41) -> 2 | W17: =SUM(G38:G41) -> 0 | X17: =SUM(H38:H41) -> 0 | Y17: =SUM(I38:I41) -> 0 | Z17: =SUM(J38:J41) -> 0 | ... AF17: =SUM(P38:P41) -> 20
B18: 09.00 - 09.15 | C18: 0 | D18: 1 | E18: 0 | F18: 1 | G18: 0 | H18: 0 | I18: 0 | J18: 0 | K18: 0 | L18: 0 | M18: 5 | N18: 0 | O18: =SUM(C18:L18,N18) -> 2 | P18: =SUM(C18:N18) -> 7 | R18: 1500-1600 | S18: =SUM(C42:C45) -> 1 | T18: =SUM(D42:D45) -> 0 | U18: =SUM(E42:E45) -> 2 | V18: =SUM(F42:F45) -> 2 | W18: =SUM(G42:G45) -> 0 | X18: =SUM(H42:H45) -> 0 | Y18: =SUM(I42:I45) -> 0 | Z18: =SUM(J42:J45) -> 1 | ... AF18: =SUM(P42:P45) -> 21
B19: 09.15 - 09.30 | C19: 1 | D19: 1 | E19: 0 | F19: 2 | G19: 0 | H19: 0 | I19: 0 | J19: 0 | K19: 0 | L19: 0 | M19: 6 | N19: 0 | O19: =SUM(C19:L19,N19) -> 4 | P19: =SUM(C19:N19) -> 10 | R19: 1600-1700 | S19: =SUM(C46:C49) -> 1 | T19: =SUM(D46:D49) -> 1 | U19: =SUM(E46:E49) -> 0 | V19: =SUM(F46:F49) -> 4 | W19: =SUM(G46:G49) -> 0 | X19: =SUM(H46:H49) -> 0 | Y19: =SUM(I46:I49) -> 0 | Z19: =SUM(J46:J49) -> 0 | ... AF19: =SUM(P46:P49) -> 24
B20: 09.30 - 09.45 | C20: 0 | D20: 1 | E20: 0 | F20: 1 | G20: 0 | H20: 0 | I20: 1 | J20: 0 | K20: 0 | L20: 0 | M20: 9 | N20: 0 | O20: =SUM(C20:L20,N20) -> 3 | P20: =SUM(C20:N20) -> 12 | R20: 1700-1800 | S20: =SUM(C50:C53) -> 1 | T20: =SUM(D50:D53) -> 0 | U20: =SUM(E50:E53) -> 1 | V20: =SUM(F50:F53) -> 5 | W20: =SUM(G50:G53) -> 0 | X20: =SUM(H50:H53) -> 0 | Y20: =SUM(I50:I53) -> 1 | Z20: =SUM(J50:J53) -> 0 | ... AF20: =SUM(P50:P53) -> 42
B21: 09.45 - 10.00 | C21: 0 | D21: 0 | E21: 0 | F21: 1 | G21: 0 | H21: 0 | I21: 0 | J21: 0 | K21: 0 | L21: 0 | M21: 11 | N21: 0 | O21: =SUM(C21:L21,N21) -> 1 | P21: =SUM(C21:N21) -> 12 | R21: 1800-1900 | S21: =SUM(C54:C57) -> 1 | T21: =SUM(D54:D57) -> 0 | U21: =SUM(E54:E57) -> 1 | V21: =SUM(F54:F57) -> 4 | W21: =SUM(G54:G57) -> 0 | X21: =SUM(H54:H57) -> 0 | Y21: =SUM(I54:I57) -> 1 | Z21: =SUM(J54:J57) -> 0 | ... AF21: =SUM(P54:P57) -> 42
B22: 10.00 - 10.15 | C22: 0 | D22: 0 | E22: 0 | F22: 0 | G22: 0 | H22: 0 | I22: 1 | J22: 0 | K22: 0 | L22: 0 | M22: 9 | N22: 0 | O22: =SUM(C22:L22,N22) -> 1 | P22: =SUM(C22:N22) -> 10 | R22: 1900-2000 | S22: =SUM(C58:C61) -> 0 | T22: =SUM(D58:D61) -> 0 | U22: =SUM(E58:E61) -> 2 | V22: =SUM(F58:F61) -> 0 | W22: =SUM(G58:G61) -> 0 | X22: =SUM(H58:H61) -> 0 | Y22: =SUM(I58:I61) -> 0 | Z22: =SUM(J58:J61) -> 0 | ... AF22: =SUM(P58:P61) -> 17
B23: 10.15 - 10.30 | C23: 0 | D23: 2 | E23: 1 | F23: 1 | G23: 0 | H23: 0 | I23: 0 | J23: 0 | K23: 0 | L23: 0 | M23: 3 | N23: 0 | O23: =SUM(C23:L23,N23) -> 4 | P23: =SUM(C23:N23) -> 7 | R23: 2000-2100 | S23: =SUM(C62:C65) -> 0 | T23: =SUM(D62:D65) -> 0 | U23: =SUM(E62:E65) -> 0 | V23: =SUM(F62:F65) -> 1 | W23: =SUM(G62:G65) -> 1 | X23: =SUM(H62:H65) -> 0 | Y23: =SUM(I62:I65) -> 0 | Z23: =SUM(J62:J65) -> 0 | ... AF23: =SUM(P62:P65) -> 16
B24: 10.30 - 10.45 | C24: 0 | D24: 0 | E24: 0 | F24: 2 | G24: 0 | H24: 0 | I24: 0 | J24: 0 | K24: 1 | L24: 0 | M24: 5 | N24: 0 | O24: =SUM(C24:L24,N24) -> 3 | P24: =SUM(C24:N24) -> 8 | R24: 2100-2200 | S24: =SUM(C66:C69) -> 0 | T24: =SUM(D66:D69) -> 0 | U24: =SUM(E66:E69) -> 0 | V24: =SUM(F66:F69) -> 1 | W24: =SUM(G66:G69) -> 0 | X24: =SUM(H66:H69) -> 0 | Y24: =SUM(I66:I69) -> 0 | Z24: =SUM(J66:J69) -> 0 | ... AF24: =SUM(P66:P69) -> 6
B25: 10.45 - 11.00 | C25: 0 | D25: 0 | E25: 0 | F25: 0 | G25: 0 | H25: 0 | I25: 0 | J25: 0 | K25: 0 | L25: 0 | M25: 6 | N25: 0 | O25: =SUM(C25:L25,N25) -> 0 | P25: =SUM(C25:N25) -> 6 | R25: 2200-2300 | S25: =SUM(C70:C73) -> 0 | T25: =SUM(D70:D73) -> 0 | U25: =SUM(E70:E73) -> 0 | V25: =SUM(F70:F73) -> 0 | W25: =SUM(G70:G73) -> 0 | X25: =SUM(H70:H73) -> 0 | Y25: =SUM(I70:I73) -> 0 | Z25: =SUM(J70:J73) -> 0 | ... AF25: =SUM(P70:P73) -> 7
B26: 11.00 - 11.15 | C26: 0 | D26: 0 | E26: 0 | F26: 0 | G26: 0 | H26: 0 | I26: 0 | J26: 0 | K26: 0 | L26: 0 | M26: 8 | N26: 0 | O26: =SUM(C26:L26,N26) -> 0 | P26: =SUM(C26:N26) -> 8 | R26: 2300-0000 | S26: =SUM(C74:C77) -> 0 | T26: =SUM(D74:D77) -> 0 | U26: =SUM(E74:E77) -> 0 | V26: =SUM(F74:F77) -> 0 | W26: =SUM(G74:G77) -> 0 | X26: =SUM(H74:H77) -> 0 | Y26: =SUM(I74:I77) -> 0 | Z26: =SUM(J74:J77) -> 1 | ... AF26: =SUM(P74:P77) -> 2
B27: 11.15 - 11.30 | C27: 0 | D27: 0 | E27: 0 | F27: 1 | G27: 0 | H27: 0 | I27: 0 | J27: 0 | K27: 0 | L27: 0 | M27: 3 | N27: 0 | O27: =SUM(C27:L27,N27) -> 1 | P27: =SUM(C27:N27) -> 4 | R27: 0000-0100 | S27: =SUM(C78:C81) -> 0 | T27: =SUM(D78:D81) -> 0 | U27: =SUM(E78:E81) -> 0 | V27: =SUM(F78:F81) -> 0 | W27: =SUM(G78:G81) -> 0 | X27: =SUM(H78:H81) -> 0 | Y27: =SUM(I78:I81) -> 0 | Z27: =SUM(J78:J81) -> 0 | ... AF27: =SUM(P78:P81) -> 3
B28: 11.30 - 11.45 | C28: 0 | D28: 0 | E28: 1 | F28: 0 | G28: 0 | H28: 0 | I28: 0 | J28: 0 | K28: 1 | L28: 0 | M28: 5 | N28: 0 | O28: =SUM(C28:L28,N28) -> 2 | P28: =SUM(C28:N28) -> 7 | R28: 0100-0200 | S28: =SUM(C82:C85) -> 0 | T28: =SUM(D82:D85) -> 0 | U28: =SUM(E82:E85) -> 0 | V28: =SUM(F82:F85) -> 0 | W28: =SUM(G82:G85) -> 0 | X28: =SUM(H82:H85) -> 0 | Y28: =SUM(I82:I85) -> 0 | Z28: =SUM(J82:J85) -> 0 | ... AF28: =SUM(P82:P85) -> 2
B29: 11.45 - 12.00 | C29: 0 | D29: 0 | E29: 0 | F29: 1 | G29: 0 | H29: 0 | I29: 0 | J29: 0 | K29: 0 | L29: 0 | M29: 1 | N29: 0 | O29: =SUM(C29:L29,N29) -> 1 | P29: =SUM(C29:N29) -> 2 | R29: 0200-0300 | S29: =SUM(C86:C89) -> 0 | T29: =SUM(D86:D89) -> 0 | U29: =SUM(E86:E89) -> 0 | V29: =SUM(F86:F89) -> 0 | W29: =SUM(G86:G89) -> 0 | X29: =SUM(H86:H89) -> 0 | Y29: =SUM(I86:I89) -> 0 | Z29: =SUM(J86:J89) -> 0 | ... AF29: =SUM(P86:P89) -> 2
B30: 12.00 - 12.15 | C30: 0 | D30: 0 | E30: 0 | F30: 0 | G30: 0 | H30: 0 | I30: 0 | J30: 0 | K30: 0 | L30: 1 | M30: 2 | N30: 0 | O30: =SUM(C30:L30,N30) -> 1 | P30: =SUM(C30:N30) -> 3 | R30: 0300-0400 | S30: =SUM(C90:C93) -> 0 | T30: =SUM(D90:D93) -> 0 | U30: =SUM(E90:E93) -> 0 | V30: =SUM(F90:F93) -> 0 | W30: =SUM(G90:G93) -> 0 | X30: =SUM(H90:H93) -> 0 | Y30: =SUM(I90:I93) -> 0 | Z30: =SUM(J90:J93) -> 0 | ... AF30: =SUM(P90:P93) -> 3
B31: 12.15 - 12.30 | C31: 0 | D31: 0 | E31: 0 | F31: 0 | G31: 0 | H31: 0 | I31: 0 | J31: 0 | K31: 0 | L31: 0 | M31: 5 | N31: 0 | O31: =SUM(C31:L31,N31) -> 0 | P31: =SUM(C31:N31) -> 5 | R31: 0400-0500 | S31: =SUM(C94:C97) -> 0 | T31: =SUM(D94:D97) -> 0 | U31: =SUM(E94:E97) -> 0 | V31: =SUM(F94:F97) -> 0 | W31: =SUM(G94:G97) -> 0 | X31: =SUM(H94:H97) -> 0 | Y31: =SUM(I94:I97) -> 0 | Z31: =SUM(J94:J97) -> 0 | ... AF31: =SUM(P94:P97) -> 3
B32: 12.30 - 12.45 | C32: 0 | D32: 0 | E32: 0 | F32: 0 | G32: 0 | H32: 0 | I32: 0 | J32: 0 | K32: 0 | L32: 0 | M32: 0 | N32: 0 | O32: =SUM(C32:L32,N32) -> 0 | P32: =SUM(C32:N32) -> 0 | R32: 0500-0600 | S32: =SUM(C98:C101) -> 0 | T32: =SUM(D98:D101) -> 0 | U32: =SUM(E98:E101) -> 0 | V32: =SUM(F98:F101) -> 1 | W32: =SUM(G98:G101) -> 0 | X32: =SUM(H98:H101) -> 0 | Y32: =SUM(I98:I101) -> 0 | Z32: =SUM(J98:J101) -> 0 | ... AF32: =SUM(P98:P101) -> 1
B33: 12.45 - 13.00 | C33: 0 | D33: 0 | E33: 0 | F33: 0 | G33: 0 | H33: 0 | I33: 0 | J33: 0 | K33: 0 | L33: 0 | M33: 2 | N33: 0 | O33: =SUM(C33:L33,N33) -> 0 | P33: =SUM(C33:N33) -> 2 | R33: 0600-0700 | S33: =SUM(C102:C105) -> 0 | T33: =SUM(D102:D105) -> 0 | U33: =SUM(E102:E105) -> 0 | V33: =SUM(F102:F105) -> 3 | W33: =SUM(G102:G105) -> 0 | X33: =SUM(H102:H105) -> 0 | Y33: =SUM(I102:I105) -> 0 | Z33: =SUM(J102:J105) -> 0 | ... AF33: =SUM(P102:P105) -> 8
B34: 13.00 - 13.15 | C34: 0 | D34: 0 | E34: 0 | F34: 0 | G34: 0 | H34: 0 | I34: 0 | J34: 0 | K34: 0 | L34: 0 | M34: 1 | N34: 0 | O34: =SUM(C34:L34,N34) -> 0 | P34: =SUM(C34:N34) -> 1 | R34: AM Peak Hr | S34: =MAX(S10:S12) -> 1 | T34: =MAX(T10:T12) -> 3 | U34: =MAX(U10:U12) -> 2 | V34: =MAX(V10:V12) -> 5 | W34: =MAX(W10:W12) -> 0 | X34: =MAX(X10:X12) -> 0 | Y34: =MAX(Y10:Y12) -> 1 | Z34: =MAX(Z10:Z12) -> 0 | ... AF34: =MAX(AF10:AF12) -> 41
B35: 13.15 - 13.30 | C35: 0 | D35: 0 | E35: 2 | F35: 0 | G35: 0 | H35: 0 | I35: 0 | J35: 0 | K35: 0 | L35: 0 | M35: 8 | N35: 0 | O35: =SUM(C35:L35,N35) -> 2 | P35: =SUM(C35:N35) -> 10 | R35: IP Peak Hr | S35: =MAX(S13:S18) -> 1 | T35: =MAX(T13:T18) -> 2 | U35: =MAX(U13:U18) -> 2 | V35: =MAX(V13:V18) -> 3 | W35: =MAX(W13:W18) -> 0 | X35: =MAX(X13:X18) -> 0 | Y35: =MAX(Y13:Y18) -> 1 | Z35: =MAX(Z13:Z18) -> 1 | ... AF35: =MAX(AF13:AF18) -> 31
B36: 13.30 - 13.45 | C36: 0 | D36: 0 | E36: 0 | F36: 1 | G36: 0 | H36: 0 | I36: 0 | J36: 0 | K36: 0 | L36: 0 | M36: 4 | N36: 0 | O36: =SUM(C36:L36,N36) -> 1 | P36: =SUM(C36:N36) -> 5 | R36: PM Peak Hr | S36: =MAX(S19:S21) -> 1 | T36: =MAX(T19:T21) -> 1 | U36: =MAX(U19:U21) -> 1 | V36: =MAX(V19:V21) -> 5 | W36: =MAX(W19:W21) -> 0 | X36: =MAX(X19:X21) -> 0 | Y36: =MAX(Y19:Y21) -> 1 | Z36: =MAX(Z19:Z21) -> 0 | ... AF36: =MAX(AF19:AF21) -> 42
B37: 13.45 - 14.00 | C37: 0 | D37: 0 | E37: 0 | F37: 0 | G37: 0 | H37: 0 | I37: 0 | J37: 0 | K37: 0 | L37: 0 | M37: 1 | N37: 0 | O37: =SUM(C37:L37,N37) -> 0 | P37: =SUM(C37:N37) -> 1 | R37: AM Period | S37: =SUM(S10:S12) -> 2 | T37: =SUM(T10:T12) -> 5 | U37: =SUM(U10:U12) -> 3 | V37: =SUM(V10:V12) -> 11 | W37: =SUM(W10:W12) -> 0 | X37: =SUM(X10:X12) -> 0 | Y37: =SUM(Y10:Y12) -> 2 | Z37: =SUM(Z10:Z12) -> 0 | ... AF37: =SUM(AF10:AF12) -> 93
B38: 14.00 - 14.15 | C38: 1 | D38: 0 | E38: 0 | F38: 0 | G38: 0 | H38: 0 | I38: 0 | J38: 0 | K38: 0 | L38: 0 | M38: 4 | N38: 0 | O38: =SUM(C38:L38,N38) -> 1 | P38: =SUM(C38:N38) -> 5 | R38: IP Period | S38: =SUM(S13:S18) -> 2 | T38: =SUM(T13:T18) -> 2 | U38: =SUM(U13:U18) -> 7 | V38: =SUM(V13:V18) -> 10 | W38: =SUM(W13:W18) -> 0 | X38: =SUM(X13:X18) -> 0 | Y38: =SUM(Y13:Y18) -> 1 | Z38: =SUM(Z13:Z18) -> 1 | ... AF38: =SUM(AF13:AF18) -> 120
B39: 14.15 - 14.30 | C39: 0 | D39: 0 | E39: 0 | F39: 0 | G39: 0 | H39: 0 | I39: 0 | J39: 0 | K39: 0 | L39: 0 | M39: 3 | N39: 0 | O39: =SUM(C39:L39,N39) -> 0 | P39: =SUM(C39:N39) -> 3 | R39: PM Period | S39: =SUM(S19:S21) -> 3 | T39: =SUM(T19:T21) -> 1 | U39: =SUM(U19:U21) -> 2 | V39: =SUM(V19:V21) -> 13 | W39: =SUM(W19:W21) -> 0 | X39: =SUM(X19:X21) -> 0 | Y39: =SUM(Y19:Y21) -> 2 | Z39: =SUM(Z19:Z21) -> 0 | ... AF39: =SUM(AF19:AF21) -> 108
B40: 14.30 - 14.45 | C40: 0 | D40: 0 | E40: 1 | F40: 0 | G40: 0 | H40: 0 | I40: 0 | J40: 0 | K40: 0 | L40: 0 | M40: 6 | N40: 0 | O40: =SUM(C40:L40,N40) -> 1 | P40: =SUM(C40:N40) -> 7 | R40: 12 Hours | S40: =SUM(S10:S21) -> 7 | T40: =SUM(T10:T21) -> 8 | U40: =SUM(U10:U21) -> 12 | V40: =SUM(V10:V21) -> 34 | W40: =SUM(W10:W21) -> 0 | X40: =SUM(X10:X21) -> 0 | Y40: =SUM(Y10:Y21) -> 5 | Z40: =SUM(Z10:Z21) -> 1 | ... AF40: =SUM(AF10:AF21) -> 321
B41: 14.45 - 15.00 | C41: 0 | D41: 0 | E41: 0 | F41: 2 | G41: 0 | H41: 0 | I41: 0 | J41: 0 | K41: 0 | L41: 0 | M41: 3 | N41: 0 | O41: =SUM(C41:L41,N41) -> 2 | P41: =SUM(C41:N41) -> 5 | R41: 24 Hrs/ADT | S41: =SUM(S10:S33) -> 7 | T41: =SUM(T10:T33) -> 8 | U41: =SUM(U10:U33) -> 14 | V41: =SUM(V10:V33) -> 40 | W41: =SUM(W10:W33) -> 1 | X41: =SUM(X10:X33) -> 0 | Y41: =SUM(Y10:Y33) -> 5 | Z41: =SUM(Z10:Z33) -> 2 | ... AF41: =SUM(AF10:AF33) -> 391
B42: 15.00 - 15.15 | C42: 0 | D42: 0 | E42: 1 | F42: 1 | G42: 0 | H42: 0 | I42: 0 | J42: 0 | K42: 0 | L42: 0 | M42: 1 | N42: 0 | O42: =SUM(C42:L42,N42) -> 2 | P42: =SUM(C42:N42) -> 3 | R42: NEF | S42: =S41/S40 -> 1 | T42: =T41/T40 -> 1 | U42: =U41/U40 -> 1.1666667 | V42: =V41/V40 -> 1.1764706 | W42: =W41/W40 -> #DIV/0! | X42: =X41/X40 -> #DIV/0! | Y42: =Y41/Y40 -> 1 | Z42: =Z41/Z40 -> 2 | ... AF42: =AF41/AF40 -> 1.2180685
...

Sheet 26.10 HOIMA-BULIISA-24h
B1: Consultancy services for Preparation of Expressway Development Master Plan (EDMP) for Uganda
B2: MANUAL CLASSIFIED COUNT (MCC)
B3: ROAD NAME: | C3: ='25.10 BULIISA-HOIMA'!C3:G3 -> MCC - C4 - STN111A- BULIISA HOIMA ROAD
C5: Date | D5: 26.10.19 | F5: Location | G5: ='28.10 BULIISA-HOIMA-24h'!G5:H5 -> KISIABI | J5: Surveyor | K5: WANDERA
C6: Dir. From | D6: HOIMA | F6: Dir. To | G6: BULIISA | J6: Supervisor | K6: ='28.10 BULIISA-HOIMA-24h'!K6:L6 -> LAWRENCE
B8: Time / Veh Type | R8: SUMMARY TRAFFIC VOLUMES
C9: 1. Car | D9: 2. Station Wagon | E9: 3. Pickups | F9: 4. Minibus, matatu | G9: 5. Medium bus | H9: 6. Large Bus | I9: 7. Light Truck | J9: 8. Medium Truck | K9: 9. Heavy truck | L9: 10. Truck Trailer | M9: 11. Motor cycles | N9: 12. Tractors | O9: Total Excl M/Cycles | P9: Total All | R9: Time | S9: 1. Car | T9: 2. Station Wagon | U9: 3. Pickups | V9: 4. Minibus, matatu | W9: 5. Medium bus | X9: 6. Large Bus | Y9: 7. Light Truck | Z9: 8. Medium Truck | AA9: 9. Heavy truck | AB9: 10. Truck Trailer | AC9: 11. Motorcycles | AD9: 12. Tractors, Graders | AE9: Total Excl M/ Cycles | AF9: Total All
B10: 07.00 - 07.15 | C10: 0 | D10: 1 | E10: 0 | F10: 0 | G10: 0 | H10: 0 | I10: 0 | J10: 0 | K10: 0 | L10: 0 | M10: 5 | N10: 0 | O10: =SUM(C10:L10,N10) -> 1 | P10: =SUM(C10:N10) -> 6 | R10: 0700-0800 | S10: =SUM(C10:C13) -> 0 | T10: =SUM(D10:D13) -> 2 | U10: =SUM(E10:E13) -> 1 | V10: =SUM(F10:F13) -> 0 | W10: =SUM(G10:G13) -> 1 | X10: =SUM(H10:H13) -> 0 | Y10: =SUM(I10:I13) -> 0 | Z10: =SUM(J10:J13) -> 0 | ... AF10: =SUM(P10:P13) -> 22
B11: 07.15 - 07.30 | C11: 0 | D11: 0 | E11: 0 | F11: 0 | G11: 0 | H11: 0 | I11: 0 | J11: 0 | K11: 0 | L11: 0 | M11: 6 | N11: 0 | O11: =SUM(C11:L11,N11) -> 0 | P11: =SUM(C11:N11) -> 6 | R11: 0800-0900 | S11: =SUM(C14:C17) -> 0 | T11: =SUM(D14:D17) -> 0 | U11: =SUM(E14:E17) -> 3 | V11: =SUM(F14:F17) -> 3 | W11: =SUM(G14:G17) -> 0 | X11: =SUM(H14:H17) -> 0 | Y11: =SUM(I14:I17) -> 1 | Z11: =SUM(J14:J17) -> 0 | ... AF11: =SUM(P14:P17) -> 27
B12: 07.30 - 07.45 | C12: 0 | D12: 1 | E12: 1 | F12: 0 | G12: 1 | H12: 0 | I12: 0 | J12: 0 | K12: 0 | L12: 0 | M12: 5 | N12: 0 | O12: =SUM(C12:L12,N12) -> 3 | P12: =SUM(C12:N12) -> 8 | R12: 0900-1000 | S12: =SUM(C18:C21) -> 0 | T12: =SUM(D18:D21) -> 2 | U12: =SUM(E18:E21) -> 1 | V12: =SUM(F18:F21) -> 3 | W12: =SUM(G18:G21) -> 0 | X12: =SUM(H18:H21) -> 0 | Y12: =SUM(I18:I21) -> 1 | Z12: =SUM(J18:J21) -> 0 | ... AF12: =SUM(P18:P21) -> 40
B13: 07.45 - 08.00 | C13: 0 | D13: 0 | E13: 0 | F13: 0 | G13: 0 | H13: 0 | I13: 0 | J13: 0 | K13: 0 | L13: 0 | M13: 2 | N13: 0 | O13: =SUM(C13:L13,N13) -> 0 | P13: =SUM(C13:N13) -> 2 | R13: 1000-1100 | S13: =SUM(C22:C25) -> 0 | T13: =SUM(D22:D25) -> 0 | U13: =SUM(E22:E25) -> 0 | V13: =SUM(F22:F25) -> 1 | W13: =SUM(G22:G25) -> 1 | X13: =SUM(H22:H25) -> 0 | Y13: =SUM(I22:I25) -> 1 | Z13: =SUM(J22:J25) -> 1 | ... AF13: =SUM(P22:P25) -> 35
B14: 08.00 - 08.15 | C14: 0 | D14: 0 | E14: 1 | F14: 0 | G14: 0 | H14: 0 | I14: 0 | J14: 0 | K14: 0 | L14: 0 | M14: 4 | N14: 0 | O14: =SUM(C14:L14,N14) -> 1 | P14: =SUM(C14:N14) -> 5 | R14: 1100-1200 | S14: =SUM(C26:C29) -> 0 | T14: =SUM(D26:D29) -> 2 | U14: =SUM(E26:E29) -> 2 | V14: =SUM(F26:F29) -> 3 | W14: =SUM(G26:G29) -> 0 | X14: =SUM(H26:H29) -> 0 | Y14: =SUM(I26:I29) -> 0 | Z14: =SUM(J26:J29) -> 1 | ... AF14: =SUM(P26:P29) -> 42
B15: 08.15 - 08.30 | C15: 0 | D15: 0 | E15: 0 | F15: 2 | G15: 0 | H15: 0 | I15: 1 | J15: 0 | K15: 0 | L15: 0 | M15: 1 | N15: 0 | O15: =SUM(C15:L15,N15) -> 3 | P15: =SUM(C15:N15) -> 4 | R15: 1200-1300 | S15: =SUM(C30:C33) -> 1 | T15: =SUM(D30:D33) -> 0 | U15: =SUM(E30:E33) -> 2 | V15: =SUM(F30:F33) -> 2 | W15: =SUM(G30:G33) -> 0 | X15: =SUM(H30:H33) -> 0 | Y15: =SUM(I30:I33) -> 0 | Z15: =SUM(J30:J33) -> 1 | ... AF15: =SUM(P30:P33) -> 38
B16: 08.30 - 08.45 | C16: 0 | D16: 0 | E16: 2 | F16: 0 | G16: 0 | H16: 0 | I16: 0 | J16: 0 | K16: 0 | L16: 0 | M16: 7 | N16: 0 | O16: =SUM(C16:L16,N16) -> 2 | P16: =SUM(C16:N16) -> 9 | R16: 1300-1400 | S16: =SUM(C34:C37) -> 2 | T16: =SUM(D34:D37) -> 0 | U16: =SUM(E34:E37) -> 1 | V16: =SUM(F34:F37) -> 5 | W16: =SUM(G34:G37) -> 0 | X16: =SUM(H34:H37) -> 0 | Y16: =SUM(I34:I37) -> 1 | Z16: =SUM(J34:J37) -> 0 | ... AF16: =SUM(P34:P37) -> 28
B17: 08.45 - 9.00 | C17: 0 | D17: 0 | E17: 0 | F17: 1 | G17: 0 | H17: 0 | I17: 0 | J17: 0 | K17: 0 | L17: 0 | M17: 8 | N17: 0 | O17: =SUM(C17:L17,N17) -> 1 | P17: =SUM(C17:N17) -> 9 | R17: 1400-1500 | S17: =SUM(C38:C41) -> 1 | T17: =SUM(D38:D41) -> 0 | U17: =SUM(E38:E41) -> 1 | V17: =SUM(F38:F41) -> 2 | W17: =SUM(G38:G41) -> 0 | X17: =SUM(H38:H41) -> 1 | Y17: =SUM(I38:I41) -> 0 | Z17: =SUM(J38:J41) -> 1 | ... AF17: =SUM(P38:P41) -> 18
B18: 09.00 - 09.15 | C18: 0 | D18: 2 | E18: 1 | F18: 1 | G18: 0 | H18: 0 | I18: 0 | J18: 0 | K18: 0 | L18: 0 | M18: 6 | N18: 0 | O18: =SUM(C18:L18,N18) -> 4 | P18: =SUM(C18:N18) -> 10 | R18: 1500-1600 | S18: =SUM(C42:C45) -> 1 | T18: =SUM(D42:D45) -> 0 | U18: =SUM(E42:E45) -> 1 | V18: =SUM(F42:F45) -> 4 | W18: =SUM(G42:G45) -> 0 | X18: =SUM(H42:H45) -> 0 | Y18: =SUM(I42:I45) -> 1 | Z18: =SUM(J42:J45) -> 0 | ... AF18: =SUM(P42:P45) -> 25
B19: 09.15 - 09.30 | C19: 0 | D19: 0 | E19: 0 | F19: 0 | G19: 0 | H19: 0 | I19: 1 | J19: 0 | K19: 0 | L19: 1 | M19: 8 | N19: 0 | O19: =SUM(C19:L19,N19) -> 2 | P19: =SUM(C19:N19) -> 10 | R19: 1600-1700 | S19: =SUM(C46:C49) -> 0 | T19: =SUM(D46:D49) -> 0 | U19: =SUM(E46:E49) -> 1 | V19: =SUM(F46:F49) -> 4 | W19: =SUM(G46:G49) -> 0 | X19: =SUM(H46:H49) -> 0 | Y19: =SUM(I46:I49) -> 1 | Z19: =SUM(J46:J49) -> 0 | ... AF19: =SUM(P46:P49) -> 23
B20: 09.30 - 09.45 | C20: 0 | D20: 0 | E20: 0 | F20: 1 | G20: 0 | H20: 0 | I20: 0 | J20: 0 | K20: 0 | L20: 0 | M20: 4 | N20: 0 | O20: =SUM(C20:L20,N20) -> 1 | P20: =SUM(C20:N20) -> 5 | R20: 1700-1800 | S20: =SUM(C50:C53) -> 0 | T20: =SUM(D50:D53) -> 0 | U20: =SUM(E50:E53) -> 0 | V20: =SUM(F50:F53) -> 1 | W20: =SUM(G50:G53) -> 0 | X20: =SUM(H50:H53) -> 0 | Y20: =SUM(I50:I53) -> 0 | Z20: =SUM(J50:J53) -> 0 | ... AF20: =SUM(P50:P53) -> 19
B21: 09.45 - 10.00 | C21: 0 | D21: 0 | E21: 0 | F21: 1 | G21: 0 | H21: 0 | I21: 0 | J21: 0 | K21: 0 | L21: 0 | M21: 14 | N21: 0 | O21: =SUM(C21:L21,N21) -> 1 | P21: =SUM(C21:N21) -> 15 | R21: 1800-1900 | S21: =SUM(C54:C57) -> 0 | T21: =SUM(D54:D57) -> 0 | U21: =SUM(E54:E57) -> 1 | V21: =SUM(F54:F57) -> 1 | W21: =SUM(G54:G57) -> 0 | X21: =SUM(H54:H57) -> 0 | Y21: =SUM(I54:I57) -> 0 | Z21: =SUM(J54:J57) -> 0 | ... AF21: =SUM(P54:P57) -> 19
B22: 10.00 - 10.15 | C22: 0 | D22: 0 | E22: 0 | F22: 0 | G22: 1 | H22: 0 | I22: 1 | J22: 1 | K22: 0 | L22: 0 | M22: 10 | N22: 0 | O22: =SUM(C22:L22,N22) -> 3 | P22: =SUM(C22:N22) -> 13 | R22: 1900-2000 | S22: =SUM(C58:C61) -> 0 | T22: =SUM(D58:D61) -> 0 | U22: =SUM(E58:E61) -> 1 | V22: =SUM(F58:F61) -> 1 | W22: =SUM(G58:G61) -> 0 | X22: =SUM(H58:H61) -> 0 | Y22: =SUM(I58:I61) -> 0 | Z22: =SUM(J58:J61) -> 1 | ... AF22: =SUM(P58:P61) -> 20
B23: 10.15 - 10.30 | C23: 0 | D23: 0 | E23: 0 | F23: 0 | G23: 0 | H23: 0 | I23: 0 | J23: 0 | K23: 0 | L23: 0 | M23: 10 | N23: 0 | O23: =SUM(C23:L23,N23) -> 0 | P23: =SUM(C23:N23) -> 10 | R23: 2000-2100 | S23: =SUM(C62:C65) -> 1 | T23: =SUM(D62:D65) -> 1 | U23: =SUM(E62:E65) -> 0 | V23: =SUM(F62:F65) -> 1 | W23: =SUM(G62:G65) -> 0 | X23: =SUM(H62:H65) -> 0 | Y23: =SUM(I62:I65) -> 0 | Z23: =SUM(J62:J65) -> 1 | ... AF23: =SUM(P62:P65) -> 15
B24: 10.30 - 10.45 | C24: 0 | D24: 0 | E24: 0 | F24: 0 | G24: 0 | H24: 0 | I24: 0 | J24: 0 | K24: 0 | L24: 0 | M24: 3 | N24: 0 | O24: =SUM(C24:L24,N24) -> 0 | P24: =SUM(C24:N24) -> 3 | R24: 2100-2200 | S24: =SUM(C66:C69) -> 0 | T24: =SUM(D66:D69) -> 0 | U24: =SUM(E66:E69) -> 0 | V24: =SUM(F66:F69) -> 1 | W24: =SUM(G66:G69) -> 0 | X24: =SUM(H66:H69) -> 0 | Y24: =SUM(I66:I69) -> 0 | Z24: =SUM(J66:J69) -> 0 | ... AF24: =SUM(P66:P69) -> 14
B25: 10.45 - 11.00 | C25: 0 | D25: 0 | E25: 0 | F25: 1 | G25: 0 | H25: 0 | I25: 0 | J25: 0 | K25: 0 | L25: 0 | M25: 8 | N25: 0 | O25: =SUM(C25:L25,N25) -> 1 | P25: =SUM(C25:N25) -> 9 | R25: 2200-2300 | S25: =SUM(C70:C73) -> 0 | T25: =SUM(D70:D73) -> 0 | U25: =SUM(E70:E73) -> 0 | V25: =SUM(F70:F73) -> 1 | W25: =SUM(G70:G73) -> 0 | X25: =SUM(H70:H73) -> 0 | Y25: =SUM(I70:I73) -> 0 | Z25: =SUM(J70:J73) -> 0 | ... AF25: =SUM(P70:P73) -> 3
B26: 11.00 - 11.15 | C26: 0 | D26: 0 | E26: 0 | F26: 0 | G26: 0 | H26: 0 | I26: 0 | J26: 0 | K26: 0 | L26: 0 | M26: 12 | N26: 0 | O26: =SUM(C26:L26,N26) -> 0 | P26: =SUM(C26:N26) -> 12 | R26: 2300-0000 | S26: =SUM(C74:C77) -> 0 | T26: =SUM(D74:D77) -> 0 | U26: =SUM(E74:E77) -> 0 | V26: =SUM(F74:F77) -> 0 | W26: =SUM(G74:G77) -> 0 | X26: =SUM(H74:H77) -> 0 | Y26: =SUM(I74:I77) -> 0 | Z26: =SUM(J74:J77) -> 0 | ... AF26: =SUM(P74:P77) -> 1
B27: 11.15 - 11.30 | C27: 0 | D27: 1 | E27: 0 | F27: 0 | G27: 0 | H27: 0 | I27: 0 | J27: 0 | K27: 0 | L27: 0 | M27: 7 | N27: 0 | O27: =SUM(C27:L27,N27) -> 1 | P27: =SUM(C27:N27) -> 8 | R27: 0000-0100 | S27: =SUM(C78:C81) -> 0 | T27: =SUM(D78:D81) -> 0 | U27: =SUM(E78:E81) -> 0 | V27: =SUM(F78:F81) -> 0 | W27: =SUM(G78:G81) -> 0 | X27: =SUM(H78:H81) -> 0 | Y27: =SUM(I78:I81) -> 0 | Z27: =SUM(J78:J81) -> 0 | ... AF27: =SUM(P78:P81) -> 0
B28: 11.30 - 11.45 | C28: 0 | D28: 0 | E28: 1 | F28: 1 | G28: 0 | H28: 0 | I28: 0 | J28: 0 | K28: 0 | L28: 0 | M28: 8 | N28: 0 | O28: =SUM(C28:L28,N28) -> 2 | P28: =SUM(C28:N28) -> 10 | R28: 0100-0200 | S28: =SUM(C82:C85) -> 0 | T28: =SUM(D82:D85) -> 0 | U28: =SUM(E82:E85) -> 0 | V28: =SUM(F82:F85) -> 0 | W28: =SUM(G82:G85) -> 0 | X28: =SUM(H82:H85) -> 0 | Y28: =SUM(I82:I85) -> 0 | Z28: =SUM(J82:J85) -> 0 | ... AF28: =SUM(P82:P85) -> 0
B29: 11.45 - 12.00 | C29: 0 | D29: 1 | E29: 1 | F29: 2 | G29: 0 | H29: 0 | I29: 0 | J29: 1 | K29: 0 | L29: 0 | M29: 7 | N29: 0 | O29: =SUM(C29:L29,N29) -> 5 | P29: =SUM(C29:N29) -> 12 | R29: 0200-0300 | S29: =SUM(C86:C89) -> 0 | T29: =SUM(D86:D89) -> 0 | U29: =SUM(E86:E89) -> 0 | V29: =SUM(F86:F89) -> 0 | W29: =SUM(G86:G89) -> 0 | X29: =SUM(H86:H89) -> 0 | Y29: =SUM(I86:I89) -> 0 | Z29: =SUM(J86:J89) -> 0 | ... AF29: =SUM(P86:P89) -> 1
B30: 12.00 - 12.15 | C30: 0 | D30: 0 | E30: 0 | F30: 0 | G30: 0 | H30: 0 | I30: 0 | J30: 0 | K30: 0 | L30: 0 | M30: 11 | N30: 0 | O30: =SUM(C30:L30,N30) -> 0 | P30: =SUM(C30:N30) -> 11 | R30: 0300-0400 | S30: =SUM(C90:C93) -> 0 | T30: =SUM(D90:D93) -> 0 | U30: =SUM(E90:E93) -> 0 | V30: =SUM(F90:F93) -> 0 | W30: =SUM(G90:G93) -> 0 | X30: =SUM(H90:H93) -> 0 | Y30: =SUM(I90:I93) -> 0 | Z30: =SUM(J90:J93) -> 0 | ... AF30: =SUM(P90:P93) -> 1
B31: 12.15 - 12.30 | C31: 0 | D31: 0 | E31: 0 | F31: 0 | G31: 0 | H31: 0 | I31: 0 | J31: 0 | K31: 0 | L31: 0 | M31: 2 | N31: 0 | O31: =SUM(C31:L31,N31) -> 0 | P31: =SUM(C31:N31) -> 2 | R31: 0400-0500 | S31: =SUM(C94:C97) -> 0 | T31: =SUM(D94:D97) -> 0 | U31: =SUM(E94:E97) -> 0 | V31: =SUM(F94:F97) -> 0 | W31: =SUM(G94:G97) -> 0 | X31: =SUM(H94:H97) -> 0 | Y31: =SUM(I94:I97) -> 0 | Z31: =SUM(J94:J97) -> 0 | ... AF31: =SUM(P94:P97) -> 1
B32: 12.30 - 12.45 | C32: 1 | D32: 0 | E32: 0 | F32: 0 | G32: 0 | H32: 0 | I32: 0 | J32: 0 | K32: 0 | L32: 0 | M32: 11 | N32: 0 | O32: =SUM(C32:L32,N32) -> 1 | P32: =SUM(C32:N32) -> 12 | R32: 0500-0600 | S32: =SUM(C98:C101) -> 0 | T32: =SUM(D98:D101) -> 0 | U32: =SUM(E98:E101) -> 0 | V32: =SUM(F98:F101) -> 0 | W32: =SUM(G98:G101) -> 0 | X32: =SUM(H98:H101) -> 0 | Y32: =SUM(I98:I101) -> 0 | Z32: =SUM(J98:J101) -> 0 | ... AF32: =SUM(P98:P101) -> 1
B33: 12.45 - 13.00 | C33: 0 | D33: 0 | E33: 2 | F33: 2 | G33: 0 | H33: 0 | I33: 0 | J33: 1 | K33: 0 | L33: 0 | M33: 8 | N33: 0 | O33: =SUM(C33:L33,N33) -> 5 | P33: =SUM(C33:N33) -> 13 | R33: 0600-0700 | S33: =SUM(C102:C105) -> 0 | T33: =SUM(D102:D105) -> 0 | U33: =SUM(E102:E105) -> 0 | V33: =SUM(F102:F105) -> 0 | W33: =SUM(G102:G105) -> 0 | X33: =SUM(H102:H105) -> 0 | Y33: =SUM(I102:I105) -> 0 | Z33: =SUM(J102:J105) -> 1 | ... AF33: =SUM(P102:P105) -> 7
B34: 13.00 - 13.15 | C34: 0 | D34: 0 | E34: 0 | F34: 1 | G34: 0 | H34: 0 | I34: 0 | J34: 0 | K34: 0 | L34: 0 | M34: 4 | N34: 0 | O34: =SUM(C34:L34,N34) -> 1 | P34: =SUM(C34:N34) -> 5 | R34: AM Peak Hr | S34: =MAX(S10:S12) -> 0 | T34: =MAX(T10:T12) -> 2 | U34: =MAX(U10:U12) -> 3 | V34: =MAX(V10:V12) -> 3 | W34: =MAX(W10:W12) -> 1 | X34: =MAX(X10:X12) -> 0 | Y34: =MAX(Y10:Y12) -> 1 | Z34: =MAX(Z10:Z12) -> 0 | ... AF34: =MAX(AF10:AF12) -> 40
B35: 13.15 - 13.30 | C35: 1 | D35: 0 | E35: 1 | F35: 2 | G35: 0 | H35: 0 | I35: 0 | J35: 0 | K35: 0 | L35: 0 | M35: 10 | N35: 0 | O35: =SUM(C35:L35,N35) -> 4 | P35: =SUM(C35:N35) -> 14 | R35: IP Peak Hr | S35: =MAX(S13:S18) -> 2 | T35: =MAX(T13:T18) -> 2 | U35: =MAX(U13:U18) -> 2 | V35: =MAX(V13:V18) -> 5 | W35: =MAX(W13:W18) -> 1 | X35: =MAX(X13:X18) -> 1 | Y35: =MAX(Y13:Y18) -> 1 | Z35: =MAX(Z13:Z18) -> 1 | ... AF35: =MAX(AF13:AF18) -> 42
B36: 13.30 - 13.45 | C36: 1 | D36: 0 | E36: 0 | F36: 1 | G36: 0 | H36: 0 | I36: 0 | J36: 0 | K36: 0 | L36: 0 | M36: 3 | N36: 0 | O36: =SUM(C36:L36,N36) -> 2 | P36: =SUM(C36:N36) -> 5 | R36: PM Peak Hr | S36: =MAX(S19:S21) -> 0 | T36: =MAX(T19:T21) -> 0 | U36: =MAX(U19:U21) -> 1 | V36: =MAX(V19:V21) -> 4 | W36: =MAX(W19:W21) -> 0 | X36: =MAX(X19:X21) -> 0 | Y36: =MAX(Y19:Y21) -> 1 | Z36: =MAX(Z19:Z21) -> 0 | ... AF36: =MAX(AF19:AF21) -> 23
B37: 13.45 - 14.00 | C37: 0 | D37: 0 | E37: 0 | F37: 1 | G37: 0 | H37: 0 | I37: 1 | J37: 0 | K37: 0 | L37: 0 | M37: 2 | N37: 0 | O37: =SUM(C37:L37,N37) -> 2 | P37: =SUM(C37:N37) -> 4 | R37: AM Period | S37: =SUM(S10:S12) -> 0 | T37: =SUM(T10:T12) -> 4 | U37: =SUM(U10:U12) -> 5 | V37: =SUM(V10:V12) -> 6 | W37: =SUM(W10:W12) -> 1 | X37: =SUM(X10:X12) -> 0 | Y37: =SUM(Y10:Y12) -> 2 | Z37: =SUM(Z10:Z12) -> 0 | ... AF37: =SUM(AF10:AF12) -> 89
B38: 14.00 - 14.15 | C38: 0 | D38: 0 | E38: 0 | F38: 1 | G38: 0 | H38: 0 | I38: 0 | J38: 0 | K38: 0 | L38: 0 | M38: 3 | N38: 0 | O38: =SUM(C38:L38,N38) -> 1 | P38: =SUM(C38:N38) -> 4 | R38: IP Period | S38: =SUM(S13:S18) -> 5 | T38: =SUM(T13:T18) -> 2 | U38: =SUM(U13:U18) -> 7 | V38: =SUM(V13:V18) -> 17 | W38: =SUM(W13:W18) -> 1 | X38: =SUM(X13:X18) -> 1 | Y38: =SUM(Y13:Y18) -> 3 | Z38: =SUM(Z13:Z18) -> 4 | ... AF38: =SUM(AF13:AF18) -> 186
B39: 14.15 - 14.30 | C39: 0 | D39: 0 | E39: 0 | F39: 0 | G39: 0 | H39: 0 | I39: 0 | J39: 0 | K39: 0 | L39: 0 | M39: 2 | N39: 0 | O39: =SUM(C39:L39,N39) -> 0 | P39: =SUM(C39:N39) -> 2 | R39: PM Period | S39: =SUM(S19:S21) -> 0 | T39: =SUM(T19:T21) -> 0 | U39: =SUM(U19:U21) -> 2 | V39: =SUM(V19:V21) -> 6 | W39: =SUM(W19:W21) -> 0 | X39: =SUM(X19:X21) -> 0 | Y39: =SUM(Y19:Y21) -> 1 | Z39: =SUM(Z19:Z21) -> 0 | ... AF39: =SUM(AF19:AF21) -> 61
B40: 14.30 - 14.45 | C40: 0 | D40: 0 | E40: 0 | F40: 0 | G40: 0 | H40: 1 | I40: 0 | J40: 0 | K40: 0 | L40: 0 | M40: 4 | N40: 0 | O40: =SUM(C40:L40,N40) -> 1 | P40: =SUM(C40:N40) -> 5 | R40: 12 Hours | S40: =SUM(S10:S21) -> 5 | T40: =SUM(T10:T21) -> 6 | U40: =SUM(U10:U21) -> 14 | V40: =SUM(V10:V21) -> 29 | W40: =SUM(W10:W21) -> 2 | X40: =SUM(X10:X21) -> 1 | Y40: =SUM(Y10:Y21) -> 6 | Z40: =SUM(Z10:Z21) -> 4 | ... AF40: =SUM(AF10:AF21) -> 336
B41: 14.45 - 15.00 | C41: 1 | D41: 0 | E41: 1 | F41: 1 | G41: 0 | H41: 0 | I41: 0 | J41: 1 | K41: 0 | L41: 0 | M41: 3 | N41: 0 | O41: =SUM(C41:L41,N41) -> 4 | P41: =SUM(C41:N41) -> 7 | R41: 24 Hrs/ADT | S41: =SUM(S10:S33) -> 6 | T41: =SUM(T10:T33) -> 7 | U41: =SUM(U10:U33) -> 15 | V41: =SUM(V10:V33) -> 33 | W41: =SUM(W10:W33) -> 2 | X41: =SUM(X10:X33) -> 1 | Y41: =SUM(Y10:Y33) -> 6 | Z41: =SUM(Z10:Z33) -> 7 | ... AF41: =SUM(AF10:AF33) -> 400
B42: 15.00 - 15.15 | C42: 0 | D42: 0 | E42: 1 | F42: 0 | G42: 0 | H42: 0 | I42: 0 | J42: 0 | K42: 0 | L42: 0 | M42: 5 | N42: 0 | O42: =SUM(C42:L42,N42) -> 1 | P42: =SUM(C42:N42) -> 6 | R42: NEF | S42: =S41/S40 -> 1.2 | T42: =T41/T40 -> 1.1666667 | U42: =U41/U40 -> 1.0714286 | V42: =V41/V40 -> 1.137931 | W42: =W41/W40 -> 1 | X42: =X41/X40 -> 1 | Y42: =Y41/Y40 -> 1 | Z42: =Z41/Z40 -> 1.75 | ... AF42: =AF41/AF40 -> 1.1904762
...

Sheet 27.10 BULIISA-HOIMA
B1: Consultancy services for Preparation of Expressway Development Master Plan (EDMP) for Uganda
B2: MANUAL CLASSIFIED COUNT (MCC)
B3: ROAD NAME: | C3: ='25.10 BULIISA-HOIMA'!C3:G3 -> MCC - C4 - STN111A- BULIISA HOIMA ROAD
C5: Date | D5: 27.10.19 | F5: Location | G5: ='25.10 BULIISA-HOIMA'!G5:H5 -> KISIABI | J5: Surveyor | K5: CATHY
C6: Dir. From | D6: ='25.10 BULIISA-HOIMA'!D6:E6 -> BULIISA | F6: Dir. To | G6: ='25.10 BULIISA-HOIMA'!G6:H6 -> HOIMA | J6: Supervisor | K6: ='25.10 BULIISA-HOIMA'!K6:L6 -> LAWRENCE
B8: Time / Veh Type | R8: SUMMARY TRAFFIC VOLUMES
C9: 1. Car | D9: 2. Station Wagon | E9: 3. Pickups | F9: 4. Minibus, matatu | G9: 5. Medium bus | H9: 6. Large Bus | I9: 7. Light Truck | J9: 8. Medium Truck | K9: 9. Heavy truck | L9: 10. Truck Trailer | M9: 11. Motor cycles | N9: 12. Tractors | O9: Total Excl M/Cycles | P9: Total All | R9: Time | S9: 1. Car | T9: 2. Station Wagon | U9: 3. Pickups | V9: 4. Minibus, matatu | W9: 5. Medium bus | X9: 6. Large Bus | Y9: 7. Light Truck | Z9: 8. Medium Truck | AA9: 9. Heavy truck | AB9: 10. Truck Trailer | AC9: 11. Motorcycles | AD9: 12. Tractors, Graders | AE9: Total Excl M/ Cycles | AF9: Total All
B10: 07.00 - 07.15 | C10: 0 | D10: 0 | E10: 0 | F10: 0 | G10: 0 | H10: 0 | I10: 0 | J10: 0 | K10: 1 | L10: 0 | M10: 3 | N10: 0 | O10: =SUM(C10:L10,N10) -> 1 | P10: =SUM(C10:N10) -> 4 | R10: 0700-0800 | S10: =SUM(C10:C13) -> 1 | T10: =SUM(D10:D13) -> 0 | U10: =SUM(E10:E13) -> 1 | V10: =SUM(F10:F13) -> 3 | W10: =SUM(G10:G13) -> 0 | X10: =SUM(H10:H13) -> 0 | Y10: =SUM(I10:I13) -> 1 | Z10: =SUM(J10:J13) -> 0 | ... AF10: =SUM(P10:P13) -> 22
B11: 07.15 - 07.30 | C11: 1 | D11: 0 | E11: 1 | F11: 1 | G11: 0 | H11: 0 | I11: 0 | J11: 0 | K11: 0 | L11: 0 | M11: 5 | N11: 0 | O11: =SUM(C11:L11,N11) -> 3 | P11: =SUM(C11:N11) -> 8 | R11: 0800-0900 | S11: =SUM(C14:C17) -> 3 | T11: =SUM(D14:D17) -> 0 | U11: =SUM(E14:E17) -> 1 | V11: =SUM(F14:F17) -> 2 | W11: =SUM(G14:G17) -> 0 | X11: =SUM(H14:H17) -> 0 | Y11: =SUM(I14:I17) -> 0 | Z11: =SUM(J14:J17) -> 1 | ... AF11: =SUM(P14:P17) -> 20
B12: 07.30 - 07.45 | C12: 0 | D12: 0 | E12: 0 | F12: 2 | G12: 0 | H12: 0 | I12: 0 | J12: 0 | K12: 0 | L12: 0 | M12: 2 | N12: 0 | O12: =SUM(C12:L12,N12) -> 2 | P12: =SUM(C12:N12) -> 4 | R12: 0900-1000 | S12: =SUM(C18:C21) -> 0 | T12: =SUM(D18:D21) -> 0 | U12: =SUM(E18:E21) -> 0 | V12: =SUM(F18:F21) -> 0 | W12: =SUM(G18:G21) -> 0 | X12: =SUM(H18:H21) -> 0 | Y12: =SUM(I18:I21) -> 0 | Z12: =SUM(J18:J21) -> 0 | ... AF12: =SUM(P18:P21) -> 11
B13: 07.45 - 08.00 | C13: 0 | D13: 0 | E13: 0 | F13: 0 | G13: 0 | H13: 0 | I13: 1 | J13: 0 | K13: 0 | L13: 0 | M13: 5 | N13: 0 | O13: =SUM(C13:L13,N13) -> 1 | P13: =SUM(C13:N13) -> 6 | R13: 1000-1100 | S13: =SUM(C22:C25) -> 0 | T13: =SUM(D22:D25) -> 0 | U13: =SUM(E22:E25) -> 2 | V13: =SUM(F22:F25) -> 0 | W13: =SUM(G22:G25) -> 0 | X13: =SUM(H22:H25) -> 0 | Y13: =SUM(I22:I25) -> 0 | Z13: =SUM(J22:J25) -> 0 | ... AF13: =SUM(P22:P25) -> 19
B14: 08.00 - 08.15 | C14: 1 | D14: 0 | E14: 0 | F14: 2 | G14: 0 | H14: 0 | I14: 0 | J14: 0 | K14: 0 | L14: 0 | M14: 3 | N14: 0 | O14: =SUM(C14:L14,N14) -> 3 | P14: =SUM(C14:N14) -> 6 | R14: 1100-1200 | S14: =SUM(C26:C29) -> 0 | T14: =SUM(D26:D29) -> 0 | U14: =SUM(E26:E29) -> 1 | V14: =SUM(F26:F29) -> 4 | W14: =SUM(G26:G29) -> 0 | X14: =SUM(H26:H29) -> 0 | Y14: =SUM(I26:I29) -> 0 | Z14: =SUM(J26:J29) -> 0 | ... AF14: =SUM(P26:P29) -> 23
B15: 08.15 - 08.30 | C15: 1 | D15: 0 | E15: 0 | F15: 0 | G15: 0 | H15: 0 | I15: 0 | J15: 0 | K15: 0 | L15: 0 | M15: 0 | N15: 0 | O15: =SUM(C15:L15,N15) -> 1 | P15: =SUM(C15:N15) -> 1 | R15: 1200-1300 | S15: =SUM(C30:C33) -> 1 | T15: =SUM(D30:D33) -> 0 | U15: =SUM(E30:E33) -> 0 | V15: =SUM(F30:F33) -> 1 | W15: =SUM(G30:G33) -> 0 | X15: =SUM(H30:H33) -> 0 | Y15: =SUM(I30:I33) -> 0 | Z15: =SUM(J30:J33) -> 0 | ... AF15: =SUM(P30:P33) -> 16
