Workbook

Sheet 22.07 Nateete-Ndeeba
B1: Consultancy services for Preparation of Expressway Development Master Plan (EDMP) for Uganda
B2: MANUAL CLASSIFIED COUNT (MCC)
B3: ROAD NAME: | C3: MCC - C1 - STN07 - MASAKA ROAD
C5: Date | D5: 22/7/2019 | F5: Location | G5: Rhino Funeral Services | J5: Surveyor | K5: Ahimbisibwe Faith
C6: Dir. From | D6: Nateete | F6: Dir. To | G6: Ndeeba | J6: Supervisor | K6: Felix
B8: Time / Veh Type | R8: SUMMARY TRAFFIC VOLUMES
C9: 1. Car | D9: 2. Station Wagon | E9: 3. Pickups | F9: 4. Minibus, matatu | G9: 5. Medium bus | H9: 6. Large Bus | I9: 7. Light Truck | J9: 8. Medium Truck | K9: 9. Heavy truck | L9: 10. Truck Trailer | M9: 11. Motor cycles | N9: 12. Tractors | O9: Total Excl M/Cycles | P9: Total All | R9: Time | S9: 1. Car | T9: 2. Station Wagon | U9: 3. Pickups | V9: 4. Minibus, matatu | W9: 5. Medium bus | X9: 6. Large Bus | Y9: 7. Light Truck | Z9: 8. Medium Truck | AA9: 9. Heavy truck | AB9: 10. Truck Trailer | AC9: 11. Motorcycles | AD9: 12. Tractors, Graders | AE9: Total Excl M/ Cycles | AF9: Total All
B10: 07.00 - 07.15 | C10: 10 | D10: 2 | E10: 3 | F10: 10 | G10: 2 | H10: 5 | I10: 4 | J10: 5 | K10: 1 | L10: 0 | M10: 80 | N10: 0 | O10: =SUM(C10:L10,N10) -> 42 | P10: =SUM(C10:N10) -> 122 | R10: 0700-0800 | S10: =SUM(C10:C13) -> 121 | T10: =SUM(D10:D13) -> 9 | U10: =SUM(E10:E13) -> 11 | V10: =SUM(F10:F13) -> 55 | W10: =SUM(G10:G13) -> 4 | X10: =SUM(H10:H13) -> 8 | Y10: =SUM(I10:I13) -> 40 | Z10: =SUM(J10:J13) -> 22 | ... AF10: =SUM(P10:P13) -> 988
B11: 07.15 - 07.30 | C11: 15 | D11: 4 | E11: 2 | F11: 7 | G11: 0 | H11: 2 | I11: 3 | J11: 2 | K11: 0 | L11: 0 | M11: 100 | N11: 0 | O11: =SUM(C11:L11,N11) -> 35 | P11: =SUM(C11:N11) -> 135 | R11: 0800-0900 | S11: =SUM(C14:C17) -> 211 | T11: =SUM(D14:D17) -> 29 | U11: =SUM(E14:E17) -> 15 | V11: =SUM(F14:F17) -> 130 | W11: =SUM(G14:G17) -> 4 | X11: =SUM(H14:H17) -> 0 | Y11: =SUM(I14:I17) -> 49 | Z11: =SUM(J14:J17) -> 30 | ... AF11: =SUM(P14:P17) -> 1763
B12: 07.30 - 07.45 | C12: 35 | D12: 1 | E12: 1 | F12: 7 | G12: 1 | H12: 1 | I12: 16 | J12: 3 | K12: 0 | L12: 0 | M12: 135 | N12: 0 | O12: =SUM(C12:L12,N12) -> 65 | P12: =SUM(C12:N12) -> 200 | R12: 0900-1000 | S12: =SUM(C18:C21) -> 154 | T12: =SUM(D18:D21) -> 28 | U12: =SUM(E18:E21) -> 17 | V12: =SUM(F18:F21) -> 152 | W12: =SUM(G18:G21) -> 1 | X12: =SUM(H18:H21) -> 0 | Y12: =SUM(I18:I21) -> 50 | Z12: =SUM(J18:J21) -> 56 | ... AF12: =SUM(P18:P21) -> 1528
B13: 07.45 - 08.00 | C13: 61 | D13: 2 | E13: 5 | F13: 31 | G13: 1 | H13: 0 | I13: 17 | J13: 12 | K13: 2 | L13: 0 | M13: 400 | N13: 0 | O13: =SUM(C13:L13,N13) -> 131 | P13: =SUM(C13:N13) -> 531 | R13: 1000-1100 | S13: =SUM(C22:C25) -> 199 | T13: =SUM(D22:D25) -> 25 | U13: =SUM(E22:E25) -> 17 | V13: =SUM(F22:F25) -> 136 | W13: =SUM(G22:G25) -> 0 | X13: =SUM(H22:H25) -> 0 | Y13: =SUM(I22:I25) -> 36 | Z13: =SUM(J22:J25) -> 41 | ... AF13: =SUM(P22:P25) -> 1403
B14: 08.00 - 08.15 | C14: 48 | D14: 8 | E14: 3 | F14: 30 | G14: 1 | H14: 0 | I14: 5 | J14: 9 | K14: 1 | L14: 0 | M14: 295 | N14: 0 | O14: =SUM(C14:L14,N14) -> 105 | P14: =SUM(C14:N14) -> 400 | R14: 1100-1200 | S14: =SUM(C26:C29) -> 150 | T14: =SUM(D26:D29) -> 19 | U14: =SUM(E26:E29) -> 18 | V14: =SUM(F26:F29) -> 94 | W14: =SUM(G26:G29) -> 1 | X14: =SUM(H26:H29) -> 0 | Y14: =SUM(I26:I29) -> 26 | Z14: =SUM(J26:J29) -> 52 | ... AF14: =SUM(P26:P29) -> 1536
B15: 08.15 - 08.30 | C15: 52 | D15: 4 | E15: 3 | F15: 37 | G15: 2 | H15: 0 | I15: 13 | J15: 9 | K15: 5 | L15: 0 | M15: 335 | N15: 0 | O15: =SUM(C15:L15,N15) -> 125 | P15: =SUM(C15:N15) -> 460 | R15: 1200-1300 | S15: =SUM(C30:C33) -> 171 | T15: =SUM(D30:D33) -> 28 | U15: =SUM(E30:E33) -> 22 | V15: =SUM(F30:F33) -> 146 | W15: =SUM(G30:G33) -> 4 | X15: =SUM(H30:H33) -> 0 | Y15: =SUM(I30:I33) -> 34 | Z15: =SUM(J30:J33) -> 58 | ... AF15: =SUM(P30:P33) -> 1572
B16: 08.30 - 08.45 | C16: 47 | D16: 11 | E16: 6 | F16: 27 | G16: 0 | H16: 0 | I16: 19 | J16: 7 | K16: 3 | L16: 0 | M16: 330 | N16: 0 | O16: =SUM(C16:L16,N16) -> 120 | P16: =SUM(C16:N16) -> 450 | R16: 1300-1400 | S16: =SUM(C34:C37) -> 176 | T16: =SUM(D34:D37) -> 24 | U16: =SUM(E34:E37) -> 18 | V16: =SUM(F34:F37) -> 152 | W16: =SUM(G34:G37) -> 1 | X16: =SUM(H34:H37) -> 1 | Y16: =SUM(I34:I37) -> 41 | Z16: =SUM(J34:J37) -> 28 | ... AF16: =SUM(P34:P37) -> 1397
B17: 08.45 - 9.00 | C17: 64 | D17: 6 | E17: 3 | F17: 36 | G17: 1 | H17: 0 | I17: 12 | J17: 5 | K17: 4 | L17: 1 | M17: 321 | N17: 0 | O17: =SUM(C17:L17,N17) -> 132 | P17: =SUM(C17:N17) -> 453 | R17: 1400-1500 | S17: =SUM(C38:C41) -> 172 | T17: =SUM(D38:D41) -> 20 | U17: =SUM(E38:E41) -> 15 | V17: =SUM(F38:F41) -> 137 | W17: =SUM(G38:G41) -> 2 | X17: =SUM(H38:H41) -> 1 | Y17: =SUM(I38:I41) -> 31 | Z17: =SUM(J38:J41) -> 53 | ... AF17: =SUM(P38:P41) -> 1239
B18: 09.00 - 09.15 | C18: 35 | D18: 9 | E18: 4 | F18: 26 | G18: 0 | H18: 0 | I18: 7 | J18: 15 | K18: 3 | L18: 1 | M18: 235 | N18: 0 | O18: =SUM(C18:L18,N18) -> 100 | P18: =SUM(C18:N18) -> 335 | R18: 1500-1600 | S18: =SUM(C42:C45) -> 176 | T18: =SUM(D42:D45) -> 32 | U18: =SUM(E42:E45) -> 25 | V18: =SUM(F42:F45) -> 112 | W18: =SUM(G42:G45) -> 7 | X18: =SUM(H42:H45) -> 2 | Y18: =SUM(I42:I45) -> 56 | Z18: =SUM(J42:J45) -> 50 | ... AF18: =SUM(P42:P45) -> 930
B19: 09.15 - 09.30 | C19: 29 | D19: 4 | E19: 5 | F19: 50 | G19: 0 | H19: 0 | I19: 11 | J19: 9 | K19: 0 | L19: 0 | M19: 179 | N19: 0 | O19: =SUM(C19:L19,N19) -> 108 | P19: =SUM(C19:N19) -> 287 | R19: 1600-1700 | S19: =SUM(C46:C49) -> 182 | T19: =SUM(D46:D49) -> 20 | U19: =SUM(E46:E49) -> 14 | V19: =SUM(F46:F49) -> 132 | W19: =SUM(G46:G49) -> 3 | X19: =SUM(H46:H49) -> 0 | Y19: =SUM(I46:I49) -> 17 | Z19: =SUM(J46:J49) -> 41 | ... AF19: =SUM(P46:P49) -> 1220
B20: 09.30 - 09.45 | C20: 42 | D20: 8 | E20: 5 | F20: 35 | G20: 0 | H20: 0 | I20: 16 | J20: 17 | K20: 3 | L20: 0 | M20: 295 | N20: 0 | O20: =SUM(C20:L20,N20) -> 126 | P20: =SUM(C20:N20) -> 421 | R20: 1700-1800 | S20: =SUM(C50:C53) -> 124 | T20: =SUM(D50:D53) -> 8 | U20: =SUM(E50:E53) -> 19 | V20: =SUM(F50:F53) -> 157 | W20: =SUM(G50:G53) -> 0 | X20: =SUM(H50:H53) -> 0 | Y20: =SUM(I50:I53) -> 27 | Z20: =SUM(J50:J53) -> 32 | ... AF20: =SUM(P50:P53) -> 1202
B21: 09.45 - 10.00 | C21: 48 | D21: 7 | E21: 3 | F21: 41 | G21: 1 | H21: 0 | I21: 16 | J21: 15 | K21: 4 | L21: 0 | M21: 350 | N21: 0 | O21: =SUM(C21:L21,N21) -> 135 | P21: =SUM(C21:N21) -> 485 | R21: 1800-1900 | S21: =SUM(C54:C57) -> 84 | T21: =SUM(D54:D57) -> 24 | U21: =SUM(E54:E57) -> 10 | V21: =SUM(F54:F57) -> 123 | W21: =SUM(G54:G57) -> 5 | X21: =SUM(H54:H57) -> 5 | Y21: =SUM(I54:I57) -> 18 | Z21: =SUM(J54:J57) -> 24 | ... AF21: =SUM(P54:P57) -> 1149
B22: 10.00 - 10.15 | C22: 54 | D22: 4 | E22: 6 | F22: 41 | G22: 0 | H22: 0 | I22: 5 | J22: 8 | K22: 0 | L22: 0 | M22: 150 | N22: 1 | O22: =SUM(C22:L22,N22) -> 119 | P22: =SUM(C22:N22) -> 269 | R22: AM Peak Hr | S22: =MAX(S10:S12) -> 211 | T22: =MAX(T10:T12) -> 29 | U22: =MAX(U10:U12) -> 17 | V22: =MAX(V10:V12) -> 152 | W22: =MAX(W10:W12) -> 4 | X22: =MAX(X10:X12) -> 8 | Y22: =MAX(Y10:Y12) -> 50 | Z22: =MAX(Z10:Z12) -> 56 | ... AF22: =MAX(AF10:AF12) -> 1763
B23: 10.15 - 10.30 | C23: 40 | D23: 10 | E23: 4 | F23: 30 | G23: 0 | H23: 0 | I23: 5 | J23: 4 | K23: 3 | L23: 0 | M23: 285 | N23: 0 | O23: =SUM(C23:L23,N23) -> 96 | P23: =SUM(C23:N23) -> 381 | R23: IP Peak Hr | S23: =MAX(S13:S18) -> 199 | T23: =MAX(T13:T18) -> 32 | U23: =MAX(U13:U18) -> 25 | V23: =MAX(V13:V18) -> 152 | W23: =MAX(W13:W18) -> 7 | X23: =MAX(X13:X18) -> 2 | Y23: =MAX(Y13:Y18) -> 56 | Z23: =MAX(Z13:Z18) -> 58 | ... AF23: =MAX(AF13:AF18) -> 1572
B24: 10.30 - 10.45 | C24: 62 | D24: 7 | E24: 3 | F24: 27 | G24: 0 | H24: 0 | I24: 13 | J24: 18 | K24: 6 | L24: 1 | M24: 249 | N24: 0 | O24: =SUM(C24:L24,N24) -> 137 | P24: =SUM(C24:N24) -> 386 | R24: PM Peak Hr | S24: =MAX(S19:S21) -> 182 | T24: =MAX(T19:T21) -> 24 | U24: =MAX(U19:U21) -> 19 | V24: =MAX(V19:V21) -> 157 | W24: =MAX(W19:W21) -> 5 | X24: =MAX(X19:X21) -> 5 | Y24: =MAX(Y19:Y21) -> 27 | Z24: =MAX(Z19:Z21) -> 41 | ... AF24: =MAX(AF19:AF21) -> 1220
B25: 10.45 - 11.00 | C25: 43 | D25: 4 | E25: 4 | F25: 38 | G25: 0 | H25: 0 | I25: 13 | J25: 11 | K25: 4 | L25: 0 | M25: 250 | N25: 0 | O25: =SUM(C25:L25,N25) -> 117 | P25: =SUM(C25:N25) -> 367 | R25: AM Period | S25: =SUM(S10:S12) -> 486 | T25: =SUM(T10:T12) -> 66 | U25: =SUM(U10:U12) -> 43 | V25: =SUM(V10:V12) -> 337 | W25: =SUM(W10:W12) -> 9 | X25: =SUM(X10:X12) -> 8 | Y25: =SUM(Y10:Y12) -> 139 | Z25: =SUM(Z10:Z12) -> 108 | ... AF25: =SUM(AF10:AF12) -> 4279
B26: 11.00 - 11.15 | C26: 31 | D26: 7 | E26: 4 | F26: 32 | G26: 0 | H26: 0 | I26: 1 | J26: 20 | K26: 4 | L26: 0 | M26: 285 | N26: 0 | O26: =SUM(C26:L26,N26) -> 99 | P26: =SUM(C26:N26) -> 384 | R26: IP Period | S26: =SUM(S13:S18) -> 1044 | T26: =SUM(T13:T18) -> 148 | U26: =SUM(U13:U18) -> 115 | V26: =SUM(V13:V18) -> 777 | W26: =SUM(W13:W18) -> 15 | X26: =SUM(X13:X18) -> 4 | Y26: =SUM(Y13:Y18) -> 224 | Z26: =SUM(Z13:Z18) -> 282 | ... AF26: =SUM(AF13:AF18) -> 8077
B27: 11.15 - 11.30 | C27: 36 | D27: 3 | E27: 4 | F27: 1 | G27: 1 | H27: 0 | I27: 10 | J27: 4 | K27: 3 | L27: 0 | M27: 275 | N27: 0 | O27: =SUM(C27:L27,N27) -> 62 | P27: =SUM(C27:N27) -> 337 | R27: PM Period | S27: =SUM(S19:S21) -> 390 | T27: =SUM(T19:T21) -> 52 | U27: =SUM(U19:U21) -> 43 | V27: =SUM(V19:V21) -> 412 | W27: =SUM(W19:W21) -> 8 | X27: =SUM(X19:X21) -> 5 | Y27: =SUM(Y19:Y21) -> 62 | Z27: =SUM(Z19:Z21) -> 97 | ... AF27: =SUM(AF19:AF21) -> 3571
B28: 11.30 - 11.45 | C28: 34 | D28: 4 | E28: 4 | F28: 26 | G28: 0 | H28: 0 | I28: 11 | J28: 14 | K28: 8 | L28: 0 | M28: 305 | N28: 0 | O28: =SUM(C28:L28,N28) -> 101 | P28: =SUM(C28:N28) -> 406 | R28: 12 Hours | S28: =SUM(S10:S21) -> 1920 | T28: =SUM(T10:T21) -> 266 | U28: =SUM(U10:U21) -> 201 | V28: =SUM(V10:V21) -> 1526 | W28: =SUM(W10:W21) -> 32 | X28: =SUM(X10:X21) -> 17 | Y28: =SUM(Y10:Y21) -> 425 | Z28: =SUM(Z10:Z21) -> 487 | ... AF28: =SUM(AF10:AF21) -> 15927
B29: 11.45 - 12.00 | C29: 49 | D29: 5 | E29: 6 | F29: 35 | G29: 0 | H29: 0 | I29: 4 | J29: 14 | K29: 6 | L29: 0 | M29: 290 | N29: 0 | O29: =SUM(C29:L29,N29) -> 119 | P29: =SUM(C29:N29) -> 409
B30: 12.00 - 12.15 | C30: 56 | D30: 6 | E30: 8 | F30: 36 | G30: 2 | H30: 0 | I30: 10 | J30: 14 | K30: 8 | L30: 0 | M30: 275 | N30: 0 | O30: =SUM(C30:L30,N30) -> 140 | P30: =SUM(C30:N30) -> 415
B31: 12.15 - 12.30 | C31: 35 | D31: 6 | E31: 7 | F31: 34 | G31: 0 | H31: 0 | I31: 8 | J31: 16 | K31: 9 | L31: 0 | M31: 225 | N31: 0 | O31: =SUM(C31:L31,N31) -> 115 | P31: =SUM(C31:N31) -> 340
B32: 12.30 - 12.45 | C32: 36 | D32: 7 | E32: 2 | F32: 31 | G32: 1 | H32: 0 | I32: 4 | J32: 18 | K32: 4 | L32: 0 | M32: 255 | N32: 0 | O32: =SUM(C32:L32,N32) -> 103 | P32: =SUM(C32:N32) -> 358
B33: 12.45 - 13.00 | C33: 44 | D33: 9 | E33: 5 | F33: 45 | G33: 1 | H33: 0 | I33: 12 | J33: 10 | K33: 3 | L33: 0 | M33: 330 | N33: 0 | O33: =SUM(C33:L33,N33) -> 129 | P33: =SUM(C33:N33) -> 459
B34: 13.00 - 13.15 | C34: 83 | D34: 8 | E34: 4 | F34: 58 | G34: 0 | H34: 0 | I34: 9 | J34: 16 | K34: 5 | L34: 0 | M34: 315 | N34: 0 | O34: =SUM(C34:L34,N34) -> 183 | P34: =SUM(C34:N34) -> 498
B35: 13.15 - 13.30 | C35: 16 | D35: 5 | E35: 3 | F35: 26 | G35: 0 | H35: 0 | I35: 10 | J35: 0 | K35: 1 | L35: 0 | M35: 200 | N35: 0 | O35: =SUM(C35:L35,N35) -> 61 | P35: =SUM(C35:N35) -> 261
B36: 13.30 - 13.45 | C36: 28 | D36: 4 | E36: 5 | F36: 38 | G36: 1 | H36: 1 | I36: 12 | J36: 7 | K36: 1 | L36: 0 | M36: 225 | N36: 0 | O36: =SUM(C36:L36,N36) -> 97 | P36: =SUM(C36:N36) -> 322
B37: 13.45 - 14.00 | C37: 49 | D37: 7 | E37: 6 | F37: 30 | G37: 0 | H37: 0 | I37: 10 | J37: 5 | K37: 4 | L37: 0 | M37: 205 | N37: 0 | O37: =SUM(C37:L37,N37) -> 111 | P37: =SUM(C37:N37) -> 316
B38: 14.00 - 14.15 | C38: 40 | D38: 1 | E38: 2 | F38: 42 | G38: 2 | H38: 0 | I38: 10 | J38: 16 | K38: 1 | L38: 0 | M38: 240 | N38: 0 | O38: =SUM(C38:L38,N38) -> 114 | P38: =SUM(C38:N38) -> 354
B39: 14.15 - 14.30 | C39: 55 | D39: 7 | E39: 5 | F39: 32 | G39: 0 | H39: 0 | I39: 8 | J39: 12 | K39: 2 | L39: 1 | M39: 200 | N39: 0 | O39: =SUM(C39:L39,N39) -> 122 | P39: =SUM(C39:N39) -> 322
B40: 14.30 - 14.45 | C40: 34 | D40: 6 | E40: 4 | F40: 33 | G40: 0 | H40: 1 | I40: 10 | J40: 14 | K40: 2 | L40: 0 | M40: 190 | N40: 0 | O40: =SUM(C40:L40,N40) -> 104 | P40: =SUM(C40:N40) -> 294
... B57: 18.45 - 19.00 | C57: 20 | D57: 7 | E57: 3 | F57: 40 | G57: 3 | H57: 3 | I57: 6 | J57: 8 | K57: 2 | L57: 0 | M57: 200 | N57: 0 | O57: =SUM(C57:L57,N57) -> 92 | P57: =SUM(C57:N57) -> 292
B58: Totals | C58: =SUM(C10:C57) -> 1920 | D58: =SUM(D10:D57) -> 266 | E58: =SUM(E10:E57) -> 201 | F58: =SUM(F10:F57) -> 1526 | G58: =SUM(G10:G57) -> 32 | H58: =SUM(H10:H57) -> 17 | I58: =SUM(I10:I57) -> 425 | J58: =SUM(J10:J57) -> 487 | ... P58: =SUM(P10:P57) -> 15927
...

Sheet 22.07 Ndeeba-Nateete
B1: Consultancy services for Preparation of Expressway Development Master Plan (EDMP) for Uganda
B2: MANUAL CLASSIFIED COUNT (MCC)
B3: ROAD NAME: | C3: ='22.07 Nateete-Ndeeba'!C3:G3 -> MCC - C1 - STN07 - MASAKA ROAD
C5: Date | D5: ='22.07 Nateete-Ndeeba'!D5 -> 22/7/2019 | F5: Location | G5: ='22.07 Nateete-Ndeeba'!G5:H5 -> Rhino Funeral Services | J5: Surveyor | K5: Asibazuyo Jennifer
C6: Dir. From | D6: Ndeeba | F6: Dir. To | G6: Nateete | J6: Supervisor | K6: ='22.07 Nateete-Ndeeba'!K6:L6 -> Felix
B8: Time / Veh Type | R8: SUMMARY TRAFFIC VOLUMES
C9: 1. Car | D9: 2. Station Wagon | E9: 3. Pickups | F9: 4. Minibus, matatu | G9: 5. Medium bus | H9: 6. Large Bus | I9: 7. Light Truck | J9: 8. Medium Truck | K9: 9. Heavy truck | L9: 10. Truck Trailer | M9: 11. Motor cycles | N9: 12. Tractors | O9: Total Excl M/Cycles | P9: Total All | R9: Time | S9: 1. Car | T9: 2. Station Wagon | U9: 3. Pickups | V9: 4. Minibus, matatu | W9: 5. Medium bus | X9: 6. Large Bus | Y9: 7. Light Truck | Z9: 8. Medium Truck | AA9: 9. Heavy truck | AB9: 10. Truck Trailer | AC9: 11. Motorcycles | AD9: 12. Tractors, Graders | AE9: Total Excl M/ Cycles | AF9: Total All
B10: 07.00 - 07.15 | C10: 23 | D10: 4 | E10: 1 | F10: 8 | G10: 2 | H10: 0 | I10: 14 | J10: 0 | K10: 0 | L10: 0 | M10: 123 | N10: 0 | O10: =SUM(C10:L10,N10) -> 52 | P10: =SUM(C10:N10) -> 175 | R10: 0700-0800 | S10: =SUM(C10:C13) -> 76 | T10: =SUM(D10:D13) -> 7 | U10: =SUM(E10:E13) -> 11 | V10: =SUM(F10:F13) -> 89 | W10: =SUM(G10:G13) -> 3 | X10: =SUM(H10:H13) -> 1 | Y10: =SUM(I10:I13) -> 49 | Z10: =SUM(J10:J13) -> 2 | ... AF10: =SUM(P10:P13) -> 708
B11: 07.15 - 07.30 | C11: 15 | D11: 2 | E11: 5 | F11: 32 | G11: 0 | H11: 0 | I11: 24 | J11: 0 | K11: 2 | L11: 0 | M11: 73 | N11: 0 | O11: =SUM(C11:L11,N11) -> 80 | P11: =SUM(C11:N11) -> 153 | R11: 0800-0900 | S11: =SUM(C14:C17) -> 57 | T11: =SUM(D14:D17) -> 28 | U11: =SUM(E14:E17) -> 2 | V11: =SUM(F14:F17) -> 144 | W11: =SUM(G14:G17) -> 2 | X11: =SUM(H14:H17) -> 0 | Y11: =SUM(I14:I17) -> 28 | Z11: =SUM(J14:J17) -> 9 | ... AF11: =SUM(P14:P17) -> 997
B12: 07.30 - 07.45 | C12: 10 | D12: 1 | E12: 2 | F12: 22 | G12: 0 | H12: 1 | I12: 7 | J12: 0 | K12: 0 | L12: 0 | M12: 105 | N12: 0 | O12: =SUM(C12:L12,N12) -> 43 | P12: =SUM(C12:N12) -> 148 | R12: 0900-1000 | S12: =SUM(C18:C21) -> 123 | T12: =SUM(D18:D21) -> 19 | U12: =SUM(E18:E21) -> 3 | V12: =SUM(F18:F21) -> 221 | W12: =SUM(G18:G21) -> 4 | X12: =SUM(H18:H21) -> 3 | Y12: =SUM(I18:I21) -> 37 | Z12: =SUM(J18:J21) -> 12 | ... AF12: =SUM(P18:P21) -> 1292
B13: 07.45 - 08.00 | C13: 28 | D13: 0 | E13: 3 | F13: 27 | G13: 1 | H13: 0 | I13: 4 | J13: 2 | K13: 0 | L13: 1 | M13: 166 | N13: 0 | O13: =SUM(C13:L13,N13) -> 66 | P13: =SUM(C13:N13) -> 232 | R13: 1000-1100 | S13: =SUM(C22:C25) -> 79 | T13: =SUM(D22:D25) -> 19 | U13: =SUM(E22:E25) -> 7 | V13: =SUM(F22:F25) -> 223 | W13: =SUM(G22:G25) -> 4 | X13: =SUM(H22:H25) -> 0 | Y13: =SUM(I22:I25) -> 52 | Z13: =SUM(J22:J25) -> 11 | ... AF13: =SUM(P22:P25) -> 1079
B14: 08.00 - 08.15 | C14: 8 | D14: 3 | E14: 1 | F14: 32 | G14: 0 | H14: 0 | I14: 2 | J14: 4 | K14: 0 | L14: 0 | M14: 165 | N14: 0 | O14: =SUM(C14:L14,N14) -> 50 | P14: =SUM(C14:N14) -> 215 | R14: 1100-1200 | S14: =SUM(C26:C29) -> 73 | T14: =SUM(D26:D29) -> 15 | U14: =SUM(E26:E29) -> 9 | V14: =SUM(F26:F29) -> 87 | W14: =SUM(G26:G29) -> 1 | X14: =SUM(H26:H29) -> 3 | Y14: =SUM(I26:I29) -> 78 | Z14: =SUM(J26:J29) -> 6 | ... AF14: =SUM(P26:P29) -> 819
B15: 08.15 - 08.30 | C15: 11 | D15: 8 | E15: 0 | F15: 37 | G15: 0 | H15: 0 | I15: 6 | J15: 3 | K15: 0 | L15: 1 | M15: 170 | N15: 0 | O15: =SUM(C15:L15,N15) -> 66 | P15: =SUM(C15:N15) -> 236 | R15: 1200-1300 | S15: =SUM(C30:C33) -> 125 | T15: =SUM(D30:D33) -> 14 | U15: =SUM(E30:E33) -> 8 | V15: =SUM(F30:F33) -> 150 | W15: =SUM(G30:G33) -> 4 | X15: =SUM(H30:H33) -> 1 | Y15: =SUM(I30:I33) -> 69 | Z15: =SUM(J30:J33) -> 14 | ... AF15: =SUM(P30:P33) -> 997
B16: 08.30 - 08.45 | C16: 13 | D16: 13 | E16: 1 | F16: 39 | G16: 1 | H16: 0 | I16: 11 | J16: 0 | K16: 11 | L16: 0 | M16: 180 | N16: 0 | O16: =SUM(C16:L16,N16) -> 89 | P16: =SUM(C16:N16) -> 269 | R16: 1300-1400 | S16: =SUM(C34:C37) -> 148 | T16: =SUM(D34:D37) -> 18 | U16: =SUM(E34:E37) -> 9 | V16: =SUM(F34:F37) -> 154 | W16: =SUM(G34:G37) -> 0 | X16: =SUM(H34:H37) -> 0 | Y16: =SUM(I34:I37) -> 92 | Z16: =SUM(J34:J37) -> 15 | ... AF16: =SUM(P34:P37) -> 1166
B17: 08.45 - 9.00 | C17: 25 | D17: 4 | E17: 0 | F17: 36 | G17: 1 | H17: 0 | I17: 9 | J17: 2 | K17: 0 | L17: 0 | M17: 200 | N17: 0 | O17: =SUM(C17:L17,N17) -> 77 | P17: =SUM(C17:N17) -> 277 | R17: 1400-1500 | S17: =SUM(C38:C41) -> 137 | T17: =SUM(D38:D41) -> 36 | U17: =SUM(E38:E41) -> 16 | V17: =SUM(F38:F41) -> 133 | W17: =SUM(G38:G41) -> 7 | X17: =SUM(H38:H41) -> 0 | Y17: =SUM(I38:I41) -> 44 | Z17: =SUM(J38:J41) -> 45 | ... AF17: =SUM(P38:P41) -> 996
B18: 09.00 - 09.15 | C18: 40 | D18: 0 | E18: 0 | F18: 60 | G18: 0 | H18: 0 | I18: 2 | J18: 1 | K18: 0 | L18: 0 | M18: 215 | N18: 0 | O18: =SUM(C18:L18,N18) -> 103 | P18: =SUM(C18:N18) -> 318 | R18: 1500-1600 | S18: =SUM(C42:C45) -> 107 | T18: =SUM(D42:D45) -> 60 | U18: =SUM(E42:E45) -> 4 | V18: =SUM(F42:F45) -> 74 | W18: =SUM(G42:G45) -> 5 | X18: =SUM(H42:H45) -> 1 | Y18: =SUM(I42:I45) -> 24 | Z18: =SUM(J42:J45) -> 13 | ... AF18: =SUM(P42:P45) -> 634
B19: 09.15 - 09.30 | C19: 26 | D19: 2 | E19: 2 | F19: 60 | G19: 3 | H19: 0 | I19: 11 | J19: 5 | K19: 0 | L19: 0 | M19: 190 | N19: 0 | O19: =SUM(C19:L19,N19) -> 109 | P19: =SUM(C19:N19) -> 299 | R19: 1600-1700 | S19: =SUM(C46:C49) -> 104 | T19: =SUM(D46:D49) -> 33 | U19: =SUM(E46:E49) -> 20 | V19: =SUM(F46:F49) -> 130 | W19: =SUM(G46:G49) -> 0 | X19: =SUM(H46:H49) -> 0 | Y19: =SUM(I46:I49) -> 47 | Z19: =SUM(J46:J49) -> 33 | ... AF19: =SUM(P46:P49) -> 931
B20: 09.30 - 09.45 | C20: 9 | D20: 1 | E20: 0 | F20: 32 | G20: 1 | H20: 0 | I20: 9 | J20: 0 | K20: 2 | L20: 0 | M20: 170 | N20: 0 | O20: =SUM(C20:L20,N20) -> 54 | P20: =SUM(C20:N20) -> 224 | R20: 1700-1800 | S20: =SUM(C50:C53) -> 85 | T20: =SUM(D50:D53) -> 103 | U20: =SUM(E50:E53) -> 41 | V20: =SUM(F50:F53) -> 129 | W20: =SUM(G50:G53) -> 1 | X20: =SUM(H50:H53) -> 9 | Y20: =SUM(I50:I53) -> 44 | Z20: =SUM(J50:J53) -> 36 | ... AF20: =SUM(P50:P53) -> 1036
B21: 09.45 - 10.00 | C21: 48 | D21: 16 | E21: 1 | F21: 69 | G21: 0 | H21: 3 | I21: 15 | J21: 6 | K21: 0 | L21: 0 | M21: 293 | N21: 0 | O21: =SUM(C21:L21,N21) -> 158 | P21: =SUM(C21:N21) -> 451 | R21: 1800-1900 | S21: =SUM(C54:C57) -> 127 | T21: =SUM(D54:D57) -> 26 | U21: =SUM(E54:E57) -> 2 | V21: =SUM(F54:F57) -> 510 | W21: =SUM(G54:G57) -> 0 | X21: =SUM(H54:H57) -> 0 | Y21: =SUM(I54:I57) -> 41 | Z21: =SUM(J54:J57) -> 47 | ... AF21: =SUM(P54:P57) -> 1217
B22: 10.00 - 10.15 | C22: 20 | D22: 9 | E22: 2 | F22: 50 | G22: 2 | H22: 0 | I22: 11 | J22: 2 | K22: 0 | L22: 0 | M22: 180 | N22: 0 | O22: =SUM(C22:L22,N22) -> 96 | P22: =SUM(C22:N22) -> 276 | R22: AM Peak Hr | S22: =MAX(S10:S12) -> 123 | T22: =MAX(T10:T12) -> 28 | U22: =MAX(U10:U12) -> 11 | V22: =MAX(V10:V12) -> 221 | W22: =MAX(W10:W12) -> 4 | X22: =MAX(X10:X12) -> 3 | Y22: =MAX(Y10:Y12) -> 49 | Z22: =MAX(Z10:Z12) -> 12 | ... AF22: =MAX(AF10:AF12) -> 1292
B23: 10.15 - 10.30 | C23: 24 | D23: 0 | E23: 1 | F23: 70 | G23: 1 | H23: 0 | I23: 7 | J23: 0 | K23: 1 | L23: 1 | M23: 210 | N23: 0 | O23: =SUM(C23:L23,N23) -> 105 | P23: =SUM(C23:N23) -> 315 | R23: IP Peak Hr | S23: =MAX(S13:S18) -> 148 | T23: =MAX(T13:T18) -> 60 | U23: =MAX(U13:U18) -> 16 | V23: =MAX(V13:V18) -> 223 | W23: =MAX(W13:W18) -> 7 | X23: =MAX(X13:X18) -> 3 | Y23: =MAX(Y13:Y18) -> 92 | Z23: =MAX(Z13:Z18) -> 45 | ... AF23: =MAX(AF13:AF18) -> 1166
B24: 10.30 - 10.45 | C24: 20 | D24: 5 | E24: 4 | F24: 41 | G24: 0 | H24: 0 | I24: 11 | J24: 6 | K24: 4 | L24: 0 | M24: 147 | N24: 0 | O24: =SUM(C24:L24,N24) -> 91 | P24: =SUM(C24:N24) -> 238 | R24: PM Peak Hr | S24: =MAX(S19:S21) -> 127 | T24: =MAX(T19:T21) -> 103 | U24: =MAX(U19:U21) -> 41 | V24: =MAX(V19:V21) -> 510 | W24: =MAX(W19:W21) -> 1 | X24: =MAX(X19:X21) -> 9 | Y24: =MAX(Y19:Y21) -> 47 | Z24: =MAX(Z19:Z21) -> 47 | ... AF24: =MAX(AF19:AF21) -> 1217
B25: 10.45 - 11.00 | C25: 15 | D25: 5 | E25: 0 | F25: 62 | G25: 1 | H25: 0 | I25: 23 | J25: 3 | K25: 1 | L25: 0 | M25: 140 | N25: 0 | O25: =SUM(C25:L25,N25) -> 110 | P25: =SUM(C25:N25) -> 250 | R25: AM Period | S25: =SUM(S10:S12) -> 256 | T25: =SUM(T10:T12) -> 54 | U25: =SUM(U10:U12) -> 16 | V25: =SUM(V10:V12) -> 454 | W25: =SUM(W10:W12) -> 9 | X25: =SUM(X10:X12) -> 4 | Y25: =SUM(Y10:Y12) -> 114 | Z25: =SUM(Z10:Z12) -> 23 | ... AF25: =SUM(AF10:AF12) -> 2997
B26: 11.00 - 11.15 | C26: 15 | D26: 0 | E26: 0 | F26: 4 | G26: 0 | H26: 1 | I26: 18 | J26: 1 | K26: 0 | L26: 0 | M26: 127 | N26: 0 | O26: =SUM(C26:L26,N26) -> 39 | P26: =SUM(C26:N26) -> 166 | R26: IP Period | S26: =SUM(S13:S18) -> 669 | T26: =SUM(T13:T18) -> 162 | U26: =SUM(U13:U18) -> 53 | V26: =SUM(V13:V18) -> 821 | W26: =SUM(W13:W18) -> 21 | X26: =SUM(X13:X18) -> 5 | Y26: =SUM(Y13:Y18) -> 359 | Z26: =SUM(Z13:Z18) -> 104 | ... AF26: =SUM(AF13:AF18) -> 5691
B27: 11.15 - 11.30 | C27: 18 | D27: 9 | E27: 4 | F27: 20 | G27: 0 | H27: 2 | I27: 20 | J27: 0 | K27: 2 | L27: 0 | M27: 129 | N27: 0 | O27: =SUM(C27:L27,N27) -> 75 | P27: =SUM(C27:N27) -> 204 | R27: PM Period | S27: =SUM(S19:S21) -> 316 | T27: =SUM(T19:T21) -> 162 | U27: =SUM(U19:U21) -> 63 | V27: =SUM(V19:V21) -> 769 | W27: =SUM(W19:W21) -> 1 | X27: =SUM(X19:X21) -> 9 | Y27: =SUM(Y19:Y21) -> 132 | Z27: =SUM(Z19:Z21) -> 116 | ... AF27: =SUM(AF19:AF21) -> 3184
B28: 11.30 - 11.45 | C28: 18 | D28: 3 | E28: 2 | F28: 33 | G28: 1 | H28: 0 | I28: 17 | J28: 5 | K28: 2 | L28: 0 | M28: 167 | N28: 0 | O28: =SUM(C28:L28,N28) -> 81 | P28: =SUM(C28:N28) -> 248 | R28: 12 Hours | S28: =SUM(S10:S21) -> 1241 | T28: =SUM(T10:T21) -> 378 | U28: =SUM(U10:U21) -> 132 | V28: =SUM(V10:V21) -> 2044 | W28: =SUM(W10:W21) -> 31 | X28: =SUM(X10:X21) -> 18 | Y28: =SUM(Y10:Y21) -> 605 | Z28: =SUM(Z10:Z21) -> 243 | ... AF28: =SUM(AF10:AF21) -> 11872
B29: 11.45 - 12.00 | C29: 22 | D29: 3 | E29: 3 | F29: 30 | G29: 0 | H29: 0 | I29: 23 | J29: 0 | K29: 0 | L29: 0 | M29: 120 | N29: 0 | O29: =SUM(C29:L29,N29) -> 81 | P29: =SUM(C29:N29) -> 201
B30: 12.00 - 12.15 | C30: 25 | D30: 4 | E30: 3 | F30: 22 | G30: 0 | H30: 1 | I30: 15 | J30: 1 | K30: 0 | L30: 0 | M30: 140 | N30: 1 | O30: =SUM(C30:L30,N30) -> 72 | P30: =SUM(C30:N30) -> 212
B31: 12.15 - 12.30 | C31: 40 | D31: 4 | E31: 3 | F31: 40 | G31: 2 | H31: 0 | I31: 15 | J31: 5 | K31: 3 | L31: 2 | M31: 150 | N31: 0 | O31: =SUM(C31:L31,N31) -> 114 | P31: =SUM(C31:N31) -> 264
B32: 12.30 - 12.45 | C32: 42 | D32: 0 | E32: 2 | F32: 56 | G32: 0 | H32: 0 | I32: 17 | J32: 2 | K32: 3 | L32: 3 | M32: 145 | N32: 0 | O32: =SUM(C32:L32,N32) -> 125 | P32: =SUM(C32:N32) -> 270
B33: 12.45 - 13.00 | C33: 18 | D33: 6 | E33: 0 | F33: 32 | G33: 2 | H33: 0 | I33: 22 | J33: 6 | K33: 5 | L33: 0 | M33: 160 | N33: 0 | O33: =SUM(C33:L33,N33) -> 91 | P33: =SUM(C33:N33) -> 251
B34: 13.00 - 13.15 | C34: 34 | D34: 2 | E34: 2 | F34: 27 | G34: 0 | H34: 0 | I34: 15 | J34: 8 | K34: 0 | L34: 0 | M34: 160 | N34: 0 | O34: =SUM(C34:L34,N34) -> 88 | P34: =SUM(C34:N34) -> 248
B35: 13.15 - 13.30 | C35: 34 | D35: 0 | E35: 0 | F35: 25 | G35: 0 | H35: 0 | I35: 18 | J35: 5 | K35: 0 | L35: 0 | M35: 179 | N35: 0 | O35: =SUM(C35:L35,N35) -> 82 | P35: =SUM(C35:N35) -> 261
B36: 13.30 - 13.45 | C36: 35 | D36: 4 | E36: 3 | F36: 52 | G36: 0 | H36: 0 | I36: 24 | J36: 2 | K36: 0 | L36: 0 | M36: 156 | N36: 0 | O36: =SUM(C36:L36,N36) -> 120 | P36: =SUM(C36:N36) -> 276
B37: 13.45 - 14.00 | C37: 45 | D37: 12 | E37: 4 | F37: 50 | G37: 0 | H37: 0 | I37: 35 | J37: 0 | K37: 0 | L37: 0 | M37: 235 | N37: 0 | O37: =SUM(C37:L37,N37) -> 146 | P37: =SUM(C37:N37) -> 381
B38: 14.00 - 14.15 | C38: 34 | D38: 17 | E38: 0 | F38: 45 | G38: 1 | H38: 0 | I38: 13 | J38: 3 | K38: 0 | L38: 1 | M38: 160 | N38: 0 | O38: =SUM(C38:L38,N38) -> 114 | P38: =SUM(C38:N38) -> 274
B39: 14.15 - 14.30 | C39: 27 | D39: 5 | E39: 0 | F39: 25 | G39: 1 | H39: 0 | I39: 5 | J39: 8 | K39: 5 | L39: 2 | M39: 125 | N39: 0 | O39: =SUM(C39:L39,N39) -> 78 | P39: =SUM(C39:N39) -> 203
B40: 14.30 - 14.45 | C40: 40 | D40: 4 | E40: 0 | F40: 45 | G40: 5 | H40: 0 | I40: 10 | J40: 34 | K40: 0 | L40: 0 | M40: 180 | N40: 0 | O40: =SUM(C40:L40,N40) -> 138 | P40: =SUM(C40:N40) -> 318
... B57: 18.45 - 19.00 | C57: 28 | D57: 13 | E57: 0 | F57: 0 | G57: 0 | H57: 0 | I57: 13 | J57: 9 | K57: 1 | L57: 0 | M57: 118 | N57: 0 | O57: =SUM(C57:L57,N57) -> 64 | P57: =SUM(C57:N57) -> 182
B58: Totals | C58: =SUM(C10:C57) -> 1241 | D58: =SUM(D10:D57) -> 378 | E58: =SUM(E10:E57) -> 132 | F58: =SUM(F10:F57) -> 2044 | G58: =SUM(G10:G57) -> 31 | H58: =SUM(H10:H57) -> 18 | I58: =SUM(I10:I57) -> 605 | J58: =SUM(J10:J57) -> 243 | ... P58: =SUM(P10:P57) -> 11872
...

Sheet 23.07 Nateete-Ndeeba
B1: Consultancy services for Preparation of Expressway Development Master Plan (EDMP) for Uganda
B2: MANUAL CLASSIFIED COUNT (MCC)
B3: ROAD NAME: | C3: MCC-CI-STNO1-MASAKA
C5: Date | D5: 23.07.19 | F5: Location | G5: ='22.07 Nateete-Ndeeba'!G5:H5 -> Rhino Funeral Services | J5: Surveyor | K5: ='22.07 Nateete-Ndeeba'!K5:L5 -> Ahimbisibwe Faith
C6: Dir. From | D6: ='22.07 Nateete-Ndeeba'!D6:E6 -> Nateete | F6: Dir. To | G6: ='22.07 Nateete-Ndeeba'!G6:H6 -> Ndeeba | J6: Supervisor | K6: ='22.07 Nateete-Ndeeba'!K6:L6 -> Felix
B8: Time / Veh Type | R8: SUMMARY TRAFFIC VOLUMES
C9: 1. Car | D9: 2. Station Wagon | E9: 3. Pickups | F9: 4. Minibus, matatu | G9: 5. Medium bus | H9: 6. Large Bus | I9: 7. Light Truck | J9: 8. Medium Truck | K9: 9. Heavy truck | L9: 10. Truck Trailer | M9: 11. Motor cycles | N9: 12. Tractors | O9: Total Excl M/Cycles | P9: Total All | R9: Time | S9: 1. Car | T9: 2. Station Wagon | U9: 3. Pickups | V9: 4. Minibus, matatu | W9: 5. Medium bus | X9: 6. Large Bus | Y9: 7. Light Truck | Z9: 8. Medium Truck | AA9: 9. Heavy truck | AB9: 10. Truck Trailer | AC9: 11. Motorcycles | AD9: 12. Tractors, Graders | AE9: Total Excl M/ Cycles | AF9: Total All
B10: 07.00 - 07.15 | C10: 10 | D10: 0 | E10: 4 | F10: 9 | G10: 0 | H10: 0 | I10: 5 | J10: 0 | K10: 3 | L10: 2 | M10: 25 | N10: 0 | O10: =SUM(C10:L10,N10) -> 33 | P10: =SUM(C10:N10) -> 58 | R10: 0700-0800 | S10: =SUM(C10:C13) -> 49 | T10: =SUM(D10:D13) -> 15 | U10: =SUM(E10:E13) -> 5 | V10: =SUM(F10:F13) -> 84 | W10: =SUM(G10:G13) -> 1 | X10: =SUM(H10:H13) -> 1 | Y10: =SUM(I10:I13) -> 37 | Z10: =SUM(J10:J13) -> 5 | ... AF10: =SUM(P10:P13) -> 797
B11: 07.15 - 07.30 | C11: 11 | D11: 2 | E11: 1 | F11: 24 | G11: 1 | H11: 0 | I11: 3 | J11: 2 | K11: 0 | L11: 1 | M11: 152 | N11: 0 | O11: =SUM(C11:L11,N11) -> 45 | P11: =SUM(C11:N11) -> 197 | R11: 0800-0900 | S11: =SUM(C14:C17) -> 36 | T11: =SUM(D14:D17) -> 63 | U11: =SUM(E14:E17) -> 13 | V11: =SUM(F14:F17) -> 160 | W11: =SUM(G14:G17) -> 4 | X11: =SUM(H14:H17) -> 3 | Y11: =SUM(I14:I17) -> 28 | Z11: =SUM(J14:J17) -> 6 | ... AF11: =SUM(P14:P17) -> 1127
B12: 07.30 - 07.45 | C12: 13 | D12: 3 | E12: 0 | F12: 27 | G12: 0 | H12: 1 | I12: 16 | J12: 3 | K12: 1 | L12: 1 | M12: 185 | N12: 0 | O12: =SUM(C12:L12,N12) -> 65 | P12: =SUM(C12:N12) -> 250 | R12: 0900-1000 | S12: =SUM(C18:C21) -> 59 | T12: =SUM(D18:D21) -> 36 | U12: =SUM(E18:E21) -> 11 | V12: =SUM(F18:F21) -> 215 | W12: =SUM(G18:G21) -> 1 | X12: =SUM(H18:H21) -> 0 | Y12: =SUM(I18:I21) -> 62 | Z12: =SUM(J18:J21) -> 17 | ... AF12: =SUM(P18:P21) -> 1142
B13: 07.45 - 08.00 | C13: 15 | D13: 10 | E13: 0 | F13: 24 | G13: 0 | H13: 0 | I13: 13 | J13: 0 | K13: 0 | L13: 0 | M13: 230 | N13: 0 | O13: =SUM(C13:L13,N13) -> 62 | P13: =SUM(C13:N13) -> 292 | R13: 1000-1100 | S13: =SUM(C22:C25) -> 45 | T13: =SUM(D22:D25) -> 38 | U13: =SUM(E22:E25) -> 25 | V13: =SUM(F22:F25) -> 130 | W13: =SUM(G22:G25) -> 2 | X13: =SUM(H22:H25) -> 0 | Y13: =SUM(I22:I25) -> 44 | Z13: =SUM(J22:J25) -> 36 | ... AF13: =SUM(P22:P25) -> 1153
B14: 08.00 - 08.15 | C14: 20 | D14: 17 | E14: 2 | F14: 30 | G14: 1 | H14: 1 | I14: 9 | J14: 3 | K14: 0 | L14: 0 | M14: 170 | N14: 0 | O14: =SUM(C14:L14,N14) -> 83 | P14: =SUM(C14:N14) -> 253 | R14: 1100-1200 | S14: =SUM(C26:C29) -> 132 | T14: =SUM(D26:D29) -> 82 | U14: =SUM(E26:E29) -> 19 | V14: =SUM(F26:F29) -> 209 | W14: =SUM(G26:G29) -> 5 | X14: =SUM(H26:H29) -> 0 | Y14: =SUM(I26:I29) -> 81 | Z14: =SUM(J26:J29) -> 32 | ... AF14: =SUM(P26:P29) -> 1400
B15: 08.15 - 08.30 | C15: 11 | D15: 20 | E15: 5 | F15: 40 | G15: 0 | H15: 1 | I15: 9 | J15: 1 | K15: 3 | L15: 2 | M15: 188 | N15: 0 | O15: =SUM(C15:L15,N15) -> 92 | P15: =SUM(C15:N15) -> 280 | R15: 1200-1300 | S15: =SUM(C30:C33) -> 129 | T15: =SUM(D30:D33) -> 24 | U15: =SUM(E30:E33) -> 12 | V15: =SUM(F30:F33) -> 100 | W15: =SUM(G30:G33) -> 0 | X15: =SUM(H30:H33) -> 0 | Y15: =SUM(I30:I33) -> 57 | Z15: =SUM(J30:J33) -> 24 | ... AF15: =SUM(P30:P33) -> 973
B16: 08.30 - 08.45 | C16: 3 | D16: 7 | E16: 0 | F16: 20 | G16: 0 | H16: 1 | I16: 5 | J16: 0 | K16: 0 | L16: 0 | M16: 195 | N16: 0 | O16: =SUM(C16:L16,N16) -> 36 | P16: =SUM(C16:N16) -> 231 | R16: 1300-1400 | S16: =SUM(C34:C37) -> 162 | T16: =SUM(D34:D37) -> 29 | U16: =SUM(E34:E37) -> 17 | V16: =SUM(F34:F37) -> 135 | W16: =SUM(G34:G37) -> 2 | X16: =SUM(H34:H37) -> 0 | Y16: =SUM(I34:I37) -> 97 | Z16: =SUM(J34:J37) -> 25 | ... AF16: =SUM(P34:P37) -> 939
B17: 08.45 - 9.00 | C17: 2 | D17: 19 | E17: 6 | F17: 70 | G17: 3 | H17: 0 | I17: 5 | J17: 2 | K17: 0 | L17: 0 | M17: 256 | N17: 0 | O17: =SUM(C17:L17,N17) -> 107 | P17: =SUM(C17:N17) -> 363 | R17: 1400-1500 | S17: =SUM(C38:C41) -> 85 | T17: =SUM(D38:D41) -> 22 | U17: =SUM(E38:E41) -> 24 | V17: =SUM(F38:F41) -> 112 | W17: =SUM(G38:G41) -> 7 | X17: =SUM(H38:H41) -> 0 | Y17: =SUM(I38:I41) -> 57 | Z17: =SUM(J38:J41) -> 22 | ... AF17: =SUM(P38:P41) -> 939
B18: 09.00 - 09.15 | C18: 3 | D18: 9 | E18: 3 | F18: 32 | G18: 1 | H18: 0 | I18: 9 | J18: 3 | K18: 0 | L18: 0 | M18: 170 | N18: 0 | O18: =SUM(C18:L18,N18) -> 60 | P18: =SUM(C18:N18) -> 230 | R18: 1500-1600 | S18: =SUM(C42:C45) -> 95 | T18: =SUM(D42:D45) -> 27 | U18: =SUM(E42:E45) -> 25 | V18: =SUM(F42:F45) -> 108 | W18: =SUM(G42:G45) -> 1 | X18: =SUM(H42:H45) -> 3 | Y18: =SUM(I42:I45) -> 63 | Z18: =SUM(J42:J45) -> 29 | ... AF18: =SUM(P42:P45) -> 990
B19: 09.15 - 09.30 | C19: 10 | D19: 6 | E19: 4 | F19: 60 | G19: 0 | H19: 0 | I19: 5 | J19: 0 | K19: 2 | L19: 1 | M19: 205 | N19: 0 | O19: =SUM(C19:L19,N19) -> 88 | P19: =SUM(C19:N19) -> 293 | R19: 1600-1700 | S19: =SUM(C46:C49) -> 106 | T19: =SUM(D46:D49) -> 23 | U19: =SUM(E46:E49) -> 31 | V19: =SUM(F46:F49) -> 95 | W19: =SUM(G46:G49) -> 0 | X19: =SUM(H46:H49) -> 0 | Y19: =SUM(I46:I49) -> 55 | Z19: =SUM(J46:J49) -> 59 | ... AF19: =SUM(P46:P49) -> 1126
B20: 09.30 - 09.45 | C20: 43 | D20: 13 | E20: 0 | F20: 90 | G20: 0 | H20: 0 | I20: 41 | J20: 5 | K20: 2 | L20: 1 | M20: 170 | N20: 0 | O20: =SUM(C20:L20,N20) -> 195 | P20: =SUM(C20:N20) -> 365 | R20: 1700-1800 | S20: =SUM(C50:C53) -> 84 | T20: =SUM(D50:D53) -> 21 | U20: =SUM(E50:E53) -> 24 | V20: =SUM(F50:F53) -> 121 | W20: =SUM(G50:G53) -> 0 | X20: =SUM(H50:H53) -> 0 | Y20: =SUM(I50:I53) -> 48 | Z20: =SUM(J50:J53) -> 39 | ... AF20: =SUM(P50:P53) -> 1141
B21: 09.45 - 10.00 | C21: 3 | D21: 8 | E21: 4 | F21: 33 | G21: 0 | H21: 0 | I21: 7 | J21: 9 | K21: 2 | L21: 0 | M21: 188 | N21: 0 | O21: =SUM(C21:L21,N21) -> 66 | P21: =SUM(C21:N21) -> 254 | R21: 1800-1900 | S21: =SUM(C54:C57) -> 135 | T21: =SUM(D54:D57) -> 44 | U21: =SUM(E54:E57) -> 25 | V21: =SUM(F54:F57) -> 144 | W21: =SUM(G54:G57) -> 1 | X21: =SUM(H54:H57) -> 1 | Y21: =SUM(I54:I57) -> 58 | Z21: =SUM(J54:J57) -> 45 | ... AF21: =SUM(P54:P57) -> 1356
B22: 10.00 - 10.15 | C22: 7 | D22: 11 | E22: 8 | F22: 31 | G22: 1 | H22: 0 | I22: 8 | J22: 3 | K22: 0 | L22: 0 | M22: 210 | N22: 1 | O22: =SUM(C22:L22,N22) -> 70 | P22: =SUM(C22:N22) -> 280 | R22: AM Peak Hr | S22: =MAX(S10:S12) -> 59 | T22: =MAX(T10:T12) -> 63 | U22: =MAX(U10:U12) -> 13 | V22: =MAX(V10:V12) -> 215 | W22: =MAX(W10:W12) -> 4 | X22: =MAX(X10:X12) -> 3 | Y22: =MAX(Y10:Y12) -> 62 | Z22: =MAX(Z10:Z12) -> 17 | ... AF22: =MAX(AF10:AF12) -> 1142
B23: 10.15 - 10.30 | C23: 9 | D23: 11 | E23: 12 | F23: 17 | G23: 0 | H23: 0 | I23: 14 | J23: 11 | K23: 1 | L23: 6 | M23: 153 | N23: 0 | O23: =SUM(C23:L23,N23) -> 81 | P23: =SUM(C23:N23) -> 234 | R23: IP Peak Hr | S23: =MAX(S13:S18) -> 162 | T23: =MAX(T13:T18) -> 82 | U23: =MAX(U13:U18) -> 25 | V23: =MAX(V13:V18) -> 209 | W23: =MAX(W13:W18) -> 7 | X23: =MAX(X13:X18) -> 3 | Y23: =MAX(Y13:Y18) -> 97 | Z23: =MAX(Z13:Z18) -> 36 | ... AF23: =MAX(AF13:AF18) -> 1400
B24: 10.30 - 10.45 | C24: 11 | D24: 10 | E24: 2 | F24: 33 | G24: 1 | H24: 0 | I24: 10 | J24: 9 | K24: 1 | L24: 5 | M24: 175 | N24: 1 | O24: =SUM(C24:L24,N24) -> 83 | P24: =SUM(C24:N24) -> 258 | R24: PM Peak Hr | S24: =MAX(S19:S21) -> 135 | T24: =MAX(T19:T21) -> 44 | U24: =MAX(U19:U21) -> 31 | V24: =MAX(V19:V21) -> 144 | W24: =MAX(W19:W21) -> 1 | X24: =MAX(X19:X21) -> 1 | Y24: =MAX(Y19:Y21) -> 58 | Z24: =MAX(Z19:Z21) -> 59 | ... AF24: =MAX(AF19:AF21) -> 1356
B25: 10.45 - 11.00 | C25: 18 | D25: 6 | E25: 3 | F25: 49 | G25: 0 | H25: 0 | I25: 12 | J25: 13 | K25: 4 | L25: 1 | M25: 275 | N25: 0 | O25: =SUM(C25:L25,N25) -> 106 | P25: =SUM(C25:N25) -> 381 | R25: AM Period | S25: =SUM(S10:S12) -> 144 | T25: =SUM(T10:T12) -> 114 | U25: =SUM(U10:U12) -> 29 | V25: =SUM(V10:V12) -> 459 | W25: =SUM(W10:W12) -> 6 | X25: =SUM(X10:X12) -> 4 | Y25: =SUM(Y10:Y12) -> 127 | Z25: =SUM(Z10:Z12) -> 28 | ... AF25: =SUM(AF10:AF12) -> 3066
B26: 11.00 - 11.15 | C26: 30 | D26: 45 | E26: 4 | F26: 70 | G26: 2 | H26: 0 | I26: 22 | J26: 5 | K26: 3 | L26: 3 | M26: 220 | N26: 0 | O26: =SUM(C26:L26,N26) -> 184 | P26: =SUM(C26:N26) -> 404 | R26: IP Period | S26: =SUM(S13:S18) -> 648 | T26: =SUM(T13:T18) -> 222 | U26: =SUM(U13:U18) -> 122 | V26: =SUM(V13:V18) -> 794 | W26: =SUM(W13:W18) -> 17 | X26: =SUM(X13:X18) -> 3 | Y26: =SUM(Y13:Y18) -> 399 | Z26: =SUM(Z13:Z18) -> 168 | ... AF26: =SUM(AF13:AF18) -> 6394
B27: 11.15 - 11.30 | C27: 19 | D27: 8 | E27: 4 | F27: 41 | G27: 1 | H27: 0 | I27: 36 | J27: 12 | K27: 2 | L27: 2 | M27: 190 | N27: 0 | O27: =SUM(C27:L27,N27) -> 125 | P27: =SUM(C27:N27) -> 315 | R27: PM Period | S27: =SUM(S19:S21) -> 325 | T27: =SUM(T19:T21) -> 88 | U27: =SUM(U19:U21) -> 80 | V27: =SUM(V19:V21) -> 360 | W27: =SUM(W19:W21) -> 1 | X27: =SUM(X19:X21) -> 1 | Y27: =SUM(Y19:Y21) -> 161 | Z27: =SUM(Z19:Z21) -> 143 | ... AF27: =SUM(AF19:AF21) -> 3623
B28: 11.30 - 11.45 | C28: 42 | D28: 12 | E28: 2 | F28: 50 | G28: 2 | H28: 0 | I28: 13 | J28: 11 | K28: 1 | L28: 2 | M28: 115 | N28: 0 | O28: =SUM(C28:L28,N28) -> 135 | P28: =SUM(C28:N28) -> 250 | R28: 12 Hours | S28: =SUM(S10:S21) -> 1117 | T28: =SUM(T10:T21) -> 424 | U28: =SUM(U10:U21) -> 231 | V28: =SUM(V10:V21) -> 1613 | W28: =SUM(W10:W21) -> 24 | X28: =SUM(X10:X21) -> 8 | Y28: =SUM(Y10:Y21) -> 687 | Z28: =SUM(Z10:Z21) -> 339 | ... AF28: =SUM(AF10:AF21) -> 13083
B29: 11.45 - 12.00 | C29: 41 | D29: 17 | E29: 9 | F29: 48 | G29: 0 | H29: 0 | I29: 10 | J29: 4 | K29: 2 | L29: 5 | M29: 295 | N29: 0 | O29: =SUM(C29:L29,N29) -> 136 | P29: =SUM(C29:N29) -> 431
B30: 12.00 - 12.15 | C30: 4 | D30: 1 | E30: 0 | F30: 23 | G30: 0 | H30: 0 | I30: 16 | J30: 5 | K30: 2 | L30: 3 | M30: 105 | N30: 0 | O30: =SUM(C30:L30,N30) -> 54 | P30: =SUM(C30:N30) -> 159
B31: 12.15 - 12.30 | C31: 16 | D31: 4 | E31: 0 | F31: 15 | G31: 0 | H31: 0 | I31: 9 | J31: 5 | K31: 3 | L31: 3 | M31: 165 | N31: 0 | O31: =SUM(C31:L31,N31) -> 55 | P31: =SUM(C31:N31) -> 220
B32: 12.30 - 12.45 | C32: 96 | D32: 16 | E32: 5 | F32: 37 | G32: 0 | H32: 0 | I32: 24 | J32: 11 | K32: 1 | L32: 3 | M32: 180 | N32: 0 | O32: =SUM(C32:L32,N32) -> 193 | P32: =SUM(C32:N32) -> 373
B33: 12.45 - 13.00 | C33: 13 | D33: 3 | E33: 7 | F33: 25 | G33: 0 | H33: 0 | I33: 8 | J33: 3 | K33: 7 | L33: 8 | M33: 147 | N33: 0 | O33: =SUM(C33:L33,N33) -> 74 | P33: =SUM(C33:N33) -> 221
B34: 13.00 - 13.15 | C34: 29 | D34: 3 | E34: 5 | F34: 49 | G34: 2 | H34: 0 | I34: 37 | J34: 9 | K34: 5 | L34: 4 | M34: 120 | N34: 0 | O34: =SUM(C34:L34,N34) -> 143 | P34: =SUM(C34:N34) -> 263
B35: 13.15 - 13.30 | C35: 28 | D35: 15 | E35: 1 | F35: 15 | G35: 0 | H35: 0 | I35: 13 | J35: 8 | K35: 0 | L35: 2 | M35: 165 | N35: 0 | O35: =SUM(C35:L35,N35) -> 82 | P35: =SUM(C35:N35) -> 247
B36: 13.30 - 13.45 | C36: 85 | D36: 11 | E36: 5 | F36: 53 | G36: 0 | H36: 0 | I36: 24 | J36: 4 | K36: 0 | L36: 4 | M36: 17 | N36: 0 | O36: =SUM(C36:L36,N36) -> 186 | P36: =SUM(C36:N36) -> 203
B37: 13.45 - 14.00 | C37: 20 | D37: 0 | E37: 6 | F37: 18 | G37: 0 | H37: 0 | I37: 23 | J37: 4 | K37: 0 | L37: 0 | M37: 155 | N37: 0 | O37: =SUM(C37:L37,N37) -> 71 | P37: =SUM(C37:N37) -> 226
B38: 14.00 - 14.15 | C38: 18 | D38: 0 | E38: 4 | F38: 20 | G38: 0 | H38: 0 | I38: 14 | J38: 4 | K38: 3 | L38: 2 | M38: 165 | N38: 0 | O38: =SUM(C38:L38,N38) -> 65 | P38: =SUM(C38:N38) -> 230
B39: 14.15 - 14.30 | C39: 40 | D39: 16 | E39: 6 | F39: 23 | G39: 2 | H39: 0 | I39: 24 | J39: 9 | K39: 0 | L39: 0 | M39: 173 | O39: =SUM(C39:L39,N39) -> 120 | P39: =SUM(C39:N39) -> 293
B40: 14.30 - 14.45 | C40: 19 | D40: 2 | E40: 3 | F40: 29 | G40: 5 | H40: 0 | I40: 10 | J40: 8 | K40: 4 | L40: 2 | M40: 135 | N40: 0 | O40: =SUM(C40:L40,N40) -> 82 | P40: =SUM(C40:N40) -> 217
B41: 14.45-15.00 | C41: 8 | D41: 4 | E41: 11 | F41: 40 | G41: 0 | H41: 0 | I41: 9 | J41: 1 | K41: 4 | L41: 2 | M41: 120 | N41: 0 | O41: =SUM(C41:L41,N41) -> 79 | P41: =SUM(C41:N41) -> 199
B42: 15.00 - 15.15 | C42: 20 | D42: 3 | E42: 7 | F42: 28 | G42: 0 | H42: 2 | I42: 4 | J42: 10 | K42: 1 | L42: 4 | M42: 158 | N42: 0 | O42: =SUM(C42:L42,N42) -> 79 | P42: =SUM(C42:N42) -> 237
...

Sheet 23.07 Ndeeba-Nateete
B1: Consultancy services for Preparation of Expressway Development Master Plan (EDMP) for Uganda
B2: MANUAL CLASSIFIED COUNT (MCC)
B3: ROAD NAME: | C3: MCC-C1-STNO7-MASAKA ROAD
C5: Date | D5: ='23.07 Nateete-Ndeeba'!D5 -> 23.07.19 | F5: Location | G5: Rhino Funeral Services | J5: Surveyor | K5: Asibazuyo Jennifer
C6: Dir. From | D6: Ndeeba | F6: Dir. To | G6: Nateete | J6: Supervisor | K6: ='22.07 Nateete-Ndeeba'!K6:L6 -> Felix
B8: Time / Veh Type | R8: SUMMARY TRAFFIC VOLUMES
C9: 1. Car | D9: 2. Station Wagon | E9: 3. Pickups | F9: 4. Minibus, matatu | G9: 5. Medium bus | H9: 6. Large Bus | I9: 7. Light Truck | J9: 8. Medium Truck | K9: 9. Heavy truck | L9: 10. Truck Trailer | M9: 11. Motor cycles | N9: 12. Tractors | O9: Total Excl M/Cycles | P9: Total All | R9: Time | S9: 1. Car | T9: 2. Station Wagon | U9: 3. Pickups | V9: 4. Minibus, matatu | W9: 5. Medium bus | X9: 6. Large Bus | Y9: 7. Light Truck | Z9: 8. Medium Truck | AA9: 9. Heavy truck | AB9: 10. Truck Trailer | AC9: 11. Motorcycles | AD9: 12. Tractors, Graders | AE9: Total Excl M/ Cycles | AF9: Total All
B10: 07.00 - 07.15 | C10: 35 | D10: 7 | E10: 5 | F10: 22 | G10: 0 | H10: 0 | I10: 8 | J10: 2 | K10: 1 | L10: 1 | M10: 85 | N10: 0 | O10: =SUM(C10:L10,N10) -> 81 | P10: =SUM(C10:N10) -> 166 | R10: 0700-0800 | S10: =SUM(C10:C13) -> 173 | T10: =SUM(D10:D13) -> 25 | U10: =SUM(E10:E13) -> 15 | V10: =SUM(F10:F13) -> 111 | W10: =SUM(G10:G13) -> 0 | X10: =SUM(H10:H13) -> 0 | Y10: =SUM(I10:I13) -> 28 | Z10: =SUM(J10:J13) -> 34 | ... AF10: =SUM(P10:P13) -> 1416
B11: 07.15 - 07.30 | C11: 41 | D11: 7 | E11: 2 | F11: 23 | G11: 0 | H11: 0 | I11: 10 | J11: 9 | K11: 3 | L11: 0 | M11: 305 | N11: 0 | O11: =SUM(C11:L11,N11) -> 95 | P11: =SUM(C11:N11) -> 400 | R11: 0800-0900 | S11: =SUM(C14:C17) -> 164 | T11: =SUM(D14:D17) -> 17 | U11: =SUM(E14:E17) -> 23 | V11: =SUM(F14:F17) -> 160 | W11: =SUM(G14:G17) -> 1 | X11: =SUM(H14:H17) -> 1 | Y11: =SUM(I14:I17) -> 29 | Z11: =SUM(J14:J17) -> 48 | ... AF11: =SUM(P14:P17) -> 1368
B12: 07.30 - 07.45 | C12: 51 | D12: 7 | E12: 3 | F12: 27 | G12: 0 | H12: 0 | I12: 7 | J12: 16 | K12: 2 | L12: 0 | M12: 285 | N12: 0 | O12: =SUM(C12:L12,N12) -> 113 | P12: =SUM(C12:N12) -> 398 | R12: 0900-1000 | S12: =SUM(C18:C21) -> 153 | T12: =SUM(D18:D21) -> 32 | U12: =SUM(E18:E21) -> 15 | V12: =SUM(F18:F21) -> 160 | W12: =SUM(G18:G21) -> 2 | X12: =SUM(H18:H21) -> 0 | Y12: =SUM(I18:I21) -> 24 | Z12: =SUM(J18:J21) -> 39 | ... AF12: =SUM(P18:P21) -> 1427
B13: 07.45 - 08.00 | C13: 46 | D13: 4 | E13: 5 | F13: 39 | G13: 0 | H13: 0 | I13: 3 | J13: 7 | K13: 2 | L13: 1 | M13: 345 | N13: 0 | O13: =SUM(C13:L13,N13) -> 107 | P13: =SUM(C13:N13) -> 452 | R13: 1000-1100 | S13: =SUM(C22:C25) -> 212 | T13: =SUM(D22:D25) -> 19 | U13: =SUM(E22:E25) -> 22 | V13: =SUM(F22:F25) -> 132 | W13: =SUM(G22:G25) -> 1 | X13: =SUM(H22:H25) -> 0 | Y13: =SUM(I22:I25) -> 26 | Z13: =SUM(J22:J25) -> 37 | ... AF13: =SUM(P22:P25) -> 1374
B14: 08.00 - 08.15 | C14: 55 | D14: 4 | E14: 3 | F14: 40 | G14: 0 | H14: 1 | I14: 10 | J14: 17 | K14: 2 | L14: 0 | M14: 295 | N14: 0 | O14: =SUM(C14:L14,N14) -> 132 | P14: =SUM(C14:N14) -> 427 | R14: 1100-1200 | S14: =SUM(C26:C29) -> 156 | T14: =SUM(D26:D29) -> 24 | U14: =SUM(E26:E29) -> 16 | V14: =SUM(F26:F29) -> 133 | W14: =SUM(G26:G29) -> 4 | X14: =SUM(H26:H29) -> 1 | Y14: =SUM(I26:I29) -> 25 | Z14: =SUM(J26:J29) -> 54 | ... AF14: =SUM(P26:P29) -> 1434
B15: 08.15 - 08.30 | C15: 30 | D15: 1 | E15: 1 | F15: 30 | G15: 0 | H15: 0 | I15: 5 | J15: 4 | K15: 0 | L15: 1 | M15: 190 | N15: 0 | O15: =SUM(C15:L15,N15) -> 72 | P15: =SUM(C15:N15) -> 262 | R15: 1200-1300 | S15: =SUM(C30:C33) -> 177 | T15: =SUM(D30:D33) -> 25 | U15: =SUM(E30:E33) -> 16 | V15: =SUM(F30:F33) -> 138 | W15: =SUM(G30:G33) -> 0 | X15: =SUM(H30:H33) -> 0 | Y15: =SUM(I30:I33) -> 27 | Z15: =SUM(J30:J33) -> 51 | ... AF15: =SUM(P30:P33) -> 1231
B16: 08.30 - 08.45 | C16: 34 | D16: 5 | E16: 7 | F16: 50 | G16: 0 | H16: 0 | I16: 6 | J16: 9 | K16: 0 | L16: 0 | M16: 155 | N16: 0 | O16: =SUM(C16:L16,N16) -> 111 | P16: =SUM(C16:N16) -> 266 | R16: 1300-1400 | S16: =SUM(C34:C37) -> 110 | T16: =SUM(D34:D37) -> 25 | U16: =SUM(E34:E37) -> 10 | V16: =SUM(F34:F37) -> 137 | W16: =SUM(G34:G37) -> 1 | X16: =SUM(H34:H37) -> 0 | Y16: =SUM(I34:I37) -> 41 | Z16: =SUM(J34:J37) -> 31 | ... AF16: =SUM(P34:P37) -> 1154
B17: 08.45 - 9.00 | C17: 45 | D17: 7 | E17: 12 | F17: 40 | G17: 1 | H17: 0 | I17: 8 | J17: 18 | K17: 2 | L17: 0 | M17: 280 | N17: 0 | O17: =SUM(C17:L17,N17) -> 133 | P17: =SUM(C17:N17) -> 413 | R17: 1400-1500 | S17: =SUM(C38:C41) -> 173 | T17: =SUM(D38:D41) -> 22 | U17: =SUM(E38:E41) -> 14 | V17: =SUM(F38:F41) -> 124 | W17: =SUM(G38:G41) -> 1 | X17: =SUM(H38:H41) -> 0 | Y17: =SUM(I38:I41) -> 19 | Z17: =SUM(J38:J41) -> 39 | ... AF17: =SUM(P38:P41) -> 1238
B18: 09.00 - 09.15 | C18: 22 | D18: 3 | E18: 2 | F18: 44 | G18: 2 | H18: 0 | I18: 2 | J18: 4 | K18: 1 | L18: 0 | M18: 315 | N18: 0 | O18: =SUM(C18:L18,N18) -> 80 | P18: =SUM(C18:N18) -> 395 | R18: 1500-1600 | S18: =SUM(C42:C45) -> 185 | T18: =SUM(D42:D45) -> 20 | U18: =SUM(E42:E45) -> 15 | V18: =SUM(F42:F45) -> 127 | W18: =SUM(G42:G45) -> 0 | X18: =SUM(H42:H45) -> 0 | Y18: =SUM(I42:I45) -> 27 | Z18: =SUM(J42:J45) -> 50 | ... AF18: =SUM(P42:P45) -> 1241
B19: 09.15 - 09.30 | C19: 47 | D19: 11 | E19: 3 | F19: 44 | G19: 0 | H19: 0 | I19: 9 | J19: 10 | K19: 0 | L19: 0 | M19: 255 | N19: 0 | O19: =SUM(C19:L19,N19) -> 124 | P19: =SUM(C19:N19) -> 379 | R19: 1600-1700 | S19: =SUM(C46:C49) -> 179 | T19: =SUM(D46:D49) -> 24 | U19: =SUM(E46:E49) -> 17 | V19: =SUM(F46:F49) -> 141 | W19: =SUM(G46:G49) -> 5 | X19: =SUM(H46:H49) -> 0 | Y19: =SUM(I46:I49) -> 23 | Z19: =SUM(J46:J49) -> 48 | ... AF19: =SUM(P46:P49) -> 1087
B20: 09.30 - 09.45 | C20: 41 | D20: 8 | E20: 3 | F20: 36 | G20: 0 | H20: 0 | I20: 7 | J20: 11 | K20: 2 | L20: 0 | M20: 225 | N20: 0 | O20: =SUM(C20:L20,N20) -> 108 | P20: =SUM(C20:N20) -> 333 | R20: 1700-1800 | S20: =SUM(C50:C53) -> 165 | T20: =SUM(D50:D53) -> 19 | U20: =SUM(E50:E53) -> 17 | V20: =SUM(F50:F53) -> 138 | W20: =SUM(G50:G53) -> 4 | X20: =SUM(H50:H53) -> 3 | Y20: =SUM(I50:I53) -> 16 | Z20: =SUM(J50:J53) -> 57 | ... AF20: =SUM(P50:P53) -> 1173
B21: 09.45 - 10.00 | C21: 43 | D21: 10 | E21: 7 | F21: 36 | G21: 0 | H21: 0 | I21: 6 | J21: 14 | K21: 2 | L21: 2 | M21: 200 | N21: 0 | O21: =SUM(C21:L21,N21) -> 120 | P21: =SUM(C21:N21) -> 320 | R21: 1800-1900 | S21: =SUM(C54:C57) -> 111 | T21: =SUM(D54:D57) -> 42 | U21: =SUM(E54:E57) -> 19 | V21: =SUM(F54:F57) -> 98 | W21: =SUM(G54:G57) -> 36 | X21: =SUM(H54:H57) -> 3 | Y21: =SUM(I54:I57) -> 16 | Z21: =SUM(J54:J57) -> 41 | ... AF21: =SUM(P54:P57) -> 1329
B22: 10.00 - 10.15 | C22: 49 | D22: 6 | E22: 7 | F22: 34 | G22: 0 | H22: 0 | I22: 6 | J22: 9 | K22: 2 | L22: 0 | M22: 195 | N22: 0 | O22: =SUM(C22:L22,N22) -> 113 | P22: =SUM(C22:N22) -> 308 | R22: AM Peak Hr | S22: =MAX(S10:S12) -> 173 | T22: =MAX(T10:T12) -> 32 | U22: =MAX(U10:U12) -> 23 | V22: =MAX(V10:V12) -> 160 | W22: =MAX(W10:W12) -> 2 | X22: =MAX(X10:X12) -> 1 | Y22: =MAX(Y10:Y12) -> 29 | Z22: =MAX(Z10:Z12) -> 48 | ... AF22: =MAX(AF10:AF12) -> 1427
B23: 10.15 - 10.30 | C23: 41 | D23: 3 | E23: 0 | F23: 34 | G23: 0 | H23: 0 | I23: 7 | J23: 12 | K23: 0 | L23: 0 | M23: 245 | N23: 0 | O23: =SUM(C23:L23,N23) -> 97 | P23: =SUM(C23:N23) -> 342 | R23: IP Peak Hr | S23: =MAX(S13:S18) -> 212 | T23: =MAX(T13:T18) -> 25 | U23: =MAX(U13:U18) -> 22 | V23: =MAX(V13:V18) -> 138 | W23: =MAX(W13:W18) -> 4 | X23: =MAX(X13:X18) -> 1 | Y23: =MAX(Y13:Y18) -> 41 | Z23: =MAX(Z13:Z18) -> 54 | ... AF23: =MAX(AF13:AF18) -> 1434
B24: 10.30 - 10.45 | C24: 68 | D24: 7 | E24: 9 | F24: 27 | G24: 0 | H24: 0 | I24: 4 | J24: 8 | K24: 1 | L24: 0 | M24: 230 | N24: 0 | O24: =SUM(C24:L24,N24) -> 124 | P24: =SUM(C24:N24) -> 354 | R24: PM Peak Hr | S24: =MAX(S19:S21) -> 179 | T24: =MAX(T19:T21) -> 42 | U24: =MAX(U19:U21) -> 19 | V24: =MAX(V19:V21) -> 141 | W24: =MAX(W19:W21) -> 36 | X24: =MAX(X19:X21) -> 3 | Y24: =MAX(Y19:Y21) -> 23 | Z24: =MAX(Z19:Z21) -> 57 | ... AF24: =MAX(AF19:AF21) -> 1329
B25: 10.45 - 11.00 | C25: 54 | D25: 3 | E25: 6 | F25: 37 | G25: 1 | H25: 0 | I25: 9 | J25: 8 | K25: 7 | L25: 0 | M25: 245 | N25: 0 | O25: =SUM(C25:L25,N25) -> 125 | P25: =SUM(C25:N25) -> 370 | R25: AM Period | S25: =SUM(S10:S12) -> 490 | T25: =SUM(T10:T12) -> 74 | U25: =SUM(U10:U12) -> 53 | V25: =SUM(V10:V12) -> 431 | W25: =SUM(W10:W12) -> 3 | X25: =SUM(X10:X12) -> 1 | Y25: =SUM(Y10:Y12) -> 81 | Z25: =SUM(Z10:Z12) -> 121 | ... AF25: =SUM(AF10:AF12) -> 4211
B26: 11.00 - 11.15 | C26: 20 | D26: 4 | E26: 2 | F26: 28 | G26: 2 | H26: 1 | I26: 4 | J26: 8 | K26: 1 | L26: 0 | M26: 195 | N26: 0 | O26: =SUM(C26:L26,N26) -> 70 | P26: =SUM(C26:N26) -> 265 | R26: IP Period | S26: =SUM(S13:S18) -> 1013 | T26: =SUM(T13:T18) -> 135 | U26: =SUM(U13:U18) -> 93 | V26: =SUM(V13:V18) -> 791 | W26: =SUM(W13:W18) -> 7 | X26: =SUM(X13:X18) -> 1 | Y26: =SUM(Y13:Y18) -> 165 | Z26: =SUM(Z13:Z18) -> 262 | ... AF26: =SUM(AF13:AF18) -> 7672
B27: 11.15 - 11.30 | C27: 55 | D27: 5 | E27: 7 | F27: 29 | G27: 1 | H27: 0 | I27: 9 | J27: 25 | K27: 10 | L27: 0 | M27: 310 | N27: 0 | O27: =SUM(C27:L27,N27) -> 141 | P27: =SUM(C27:N27) -> 451 | R27: PM Period | S27: =SUM(S19:S21) -> 455 | T27: =SUM(T19:T21) -> 85 | U27: =SUM(U19:U21) -> 53 | V27: =SUM(V19:V21) -> 377 | W27: =SUM(W19:W21) -> 45 | X27: =SUM(X19:X21) -> 6 | Y27: =SUM(Y19:Y21) -> 55 | Z27: =SUM(Z19:Z21) -> 146 | ... AF27: =SUM(AF19:AF21) -> 3589
B28: 11.30 - 11.45 | C28: 52 | D28: 12 | E28: 5 | F28: 38 | G28: 1 | H28: 0 | I28: 7 | J28: 16 | K28: 0 | L28: 0 | M28: 250 | N28: 0 | O28: =SUM(C28:L28,N28) -> 131 | P28: =SUM(C28:N28) -> 381 | R28: 12 Hours | S28: =SUM(S10:S21) -> 1958 | T28: =SUM(T10:T21) -> 294 | U28: =SUM(U10:U21) -> 199 | V28: =SUM(V10:V21) -> 1599 | W28: =SUM(W10:W21) -> 55 | X28: =SUM(X10:X21) -> 8 | Y28: =SUM(Y10:Y21) -> 301 | Z28: =SUM(Z10:Z21) -> 529 | ... AF28: =SUM(AF10:AF21) -> 15472
B29: 11.45 - 12.00 | C29: 29 | D29: 3 | E29: 2 | F29: 38 | G29: 0 | H29: 0 | I29: 5 | J29: 5 | K29: 0 | L29: 0 | M29: 255 | N29: 0 | O29: =SUM(C29:L29,N29) -> 82 | P29: =SUM(C29:N29) -> 337
B30: 12.00 - 12.15 | C30: 49 | D30: 8 | E30: 3 | F30: 32 | G30: 0 | H30: 0 | I30: 9 | J30: 13 | K30: 3 | L30: 2 | M30: 165 | N30: 0 | O30: =SUM(C30:L30,N30) -> 119 | P30: =SUM(C30:N30) -> 284
B31: 12.15 - 12.30 | C31: 59 | D31: 5 | E31: 4 | F31: 35 | G31: 0 | H31: 0 | I31: 8 | J31: 13 | K31: 2 | L31: 0 | M31: 235 | N31: 0 | O31: =SUM(C31:L31,N31) -> 126 | P31: =SUM(C31:N31) -> 361
B32: 12.30 - 12.45 | C32: 37 | D32: 8 | E32: 3 | F32: 33 | G32: 0 | H32: 0 | I32: 7 | J32: 13 | K32: 3 | L32: 0 | M32: 235 | N32: 0 | O32: =SUM(C32:L32,N32) -> 104 | P32: =SUM(C32:N32) -> 339
B33: 12.45 - 13.00 | C33: 32 | D33: 4 | E33: 6 | F33: 38 | G33: 0 | H33: 0 | I33: 3 | J33: 12 | K33: 1 | L33: 1 | M33: 150 | N33: 0 | O33: =SUM(C33:L33,N33) -> 97 | P33: =SUM(C33:N33) -> 247
B34: 13.00 - 13.15 | C34: 30 | D34: 6 | E34: 1 | F34: 35 | G34: 1 | H34: 0 | I34: 2 | J34: 5 | K34: 7 | L34: 1 | M34: 225 | N34: 0 | O34: =SUM(C34:L34,N34) -> 88 | P34: =SUM(C34:N34) -> 313
B35: 13.15 - 13.30 | C35: 31 | D35: 6 | E35: 4 | F35: 32 | G35: 0 | H35: 0 | I35: 8 | J35: 10 | K35: 2 | L35: 2 | M35: 220 | N35: 0 | O35: =SUM(C35:L35,N35) -> 95 | P35: =SUM(C35:N35) -> 315
B36: 13.30 - 13.45 | C36: 21 | D36: 8 | E36: 2 | F36: 42 | G36: 0 | H36: 0 | I36: 26 | J36: 8 | K36: 0 | L36: 0 | M36: 220 | N36: 0 | O36: =SUM(C36:L36,N36) -> 107 | P36: =SUM(C36:N36) -> 327
B37: 13.45 - 14.00 | C37: 28 | D37: 5 | E37: 3 | F37: 28 | G37: 0 | H37: 0 | I37: 5 | J37: 8 | K37: 2 | L37: 0 | M37: 120 | N37: 0 | O37: =SUM(C37:L37,N37) -> 79 | P37: =SUM(C37:N37) -> 199
B38: 14.00 - 14.15 | C38: 32 | D38: 1 | E38: 2 | F38: 32 | G38: 0 | H38: 0 | I38: 4 | J38: 9 | K38: 3 | L38: 3 | M38: 170 | N38: 0 | O38: =SUM(C38:L38,N38) -> 86 | P38: =SUM(C38:N38) -> 256
B39: 14.15 - 14.30 | C39: 47 | D39: 7 | E39: 2 | F39: 26 | G39: 0 | H39: 0 | I39: 6 | J39: 12 | K39: 4 | L39: 1 | M39: 245 | N39: 0 | O39: =SUM(C39:L39,N39) -> 105 | P39: =SUM(C39:N39) -> 350
B40: 14.30 - 14.45 | C40: 46 | D40: 4 | E40: 5 | F40: 30 | G40: 1 | H40: 0 | I40: 6 | J40: 6 | K40: 7 | L40: 0 | M40: 200 | N40: 0 | O40: =SUM(C40:L40,N40) -> 105 | P40: =SUM(C40:N40) -> 305
... B57: 18.45 - 19.00 | C57: 0 | D57: 28 | E57: 6 | F57: 3 | G57: 33 | H57: 1 | I57: 3 | J57: 7 | K57: 2 | L57: 0 | M57: 225 | N57: 0 | O57: =SUM(C57:L57,N57) -> 83 | P57: =SUM(C57:N57) -> 308
B58: Totals | C58: =SUM(C10:C57) -> 1958 | D58: =SUM(D10:D57) -> 294 | E58: =SUM(E10:E57) -> 199 | F58: =SUM(F10:F57) -> 1599 | G58: =SUM(G10:G57) -> 55 | H58: =SUM(H10:H57) -> 8 | I58: =SUM(I10:I57) -> 301 | J58: =SUM(J10:J57) -> 529 | ... P58: =SUM(P10:P57) -> 15472
...

Sheet 24.07 Nateete-Ndeeba
B1: Consultancy services for Preparation of Expressway Development Master Plan (EDMP) for Uganda
B2: MANUAL CLASSIFIED COUNT (MCC)
B3: ROAD NAME: | C3: ='22.07 Nateete-Ndeeba'!C3:G3 -> MCC - C1 - STN07 - MASAKA ROAD
C5: Date | D5: 24.07.19 | F5: Location | G5: ='22.07 Nateete-Ndeeba'!G5:H5 -> Rhino Funeral Services | J5: Surveyor | K5: Ahimbisibwe Faith
C6: Dir. From | D6: ='22.07 Nateete-Ndeeba'!D6:E6 -> Nateete | F6: Dir. To | G6: ='22.07 Nateete-Ndeeba'!G6:H6 -> Ndeeba | J6: Supervisor | K6: ='22.07 Nateete-Ndeeba'!K6:L6 -> Felix
B8: Time / Veh Type | R8: SUMMARY TRAFFIC VOLUMES
C9: 1. Car | D9: 2. Station Wagon | E9: 3. Pickups | F9: 4. Minibus, matatu | G9: 5. Medium bus | H9: 6. Large Bus | I9: 7. Light Truck | J9: 8. Medium Truck | K9: 9. Heavy truck | L9: 10. Truck Trailer | M9: 11. Motor cycles | N9: 12. Tractors | O9: Total Excl M/Cycles | P9: Total All | R9: Time | S9: 1. Car | T9: 2. Station Wagon | U9: 3. Pickups | V9: 4. Minibus, matatu | W9: 5. Medium bus | X9: 6. Large Bus | Y9: 7. Light Truck | Z9: 8. Medium Truck | AA9: 9. Heavy truck | AB9: 10. Truck Trailer | AC9: 11. Motorcycles | AD9: 12. Tractors, Graders | AE9: Total Excl M/ Cycles | AF9: Total All
B10: 07.00 - 07.15 | C10: 38 | D10: 3 | E10: 2 | F10: 18 | G10: 0 | H10: 0 | I10: 13 | J10: 2 | K10: 1 | L10: 1 | M10: 65 | N10: 0 | O10: =SUM(C10:L10,N10) -> 78 | P10: =SUM(C10:N10) -> 143 | R10: 0700-0800 | S10: =SUM(C10:C13) -> 186 | T10: =SUM(D10:D13) -> 13 | U10: =SUM(E10:E13) -> 15 | V10: =SUM(F10:F13) -> 117 | W10: =SUM(G10:G13) -> 1 | X10: =SUM(H10:H13) -> 1 | Y10: =SUM(I10:I13) -> 34 | Z10: =SUM(J10:J13) -> 45 | ... AF10: =SUM(P10:P13) -> 835
B11: 07.15 - 07.30 | C11: 56 | D11: 3 | E11: 3 | F11: 31 | G11: 1 | H11: 1 | I11: 10 | J11: 15 | K11: 1 | L11: 2 | M11: 110 | N11: 0 | O11: =SUM(C11:L11,N11) -> 123 | P11: =SUM(C11:N11) -> 233 | R11: 0800-0900 | S11: =SUM(C14:C17) -> 238 | T11: =SUM(D14:D17) -> 15 | U11: =SUM(E14:E17) -> 8 | V11: =SUM(F14:F17) -> 227 | W11: =SUM(G14:G17) -> 4 | X11: =SUM(H14:H17) -> 3 | Y11: =SUM(I14:I17) -> 49 | Z11: =SUM(J14:J17) -> 79 | ... AF11: =SUM(P14:P17) -> 1366
B12: 07.30 - 07.45 | C12: 46 | D12: 5 | E12: 5 | F12: 28 | G12: 0 | H12: 0 | I12: 6 | J12: 13 | K12: 1 | L12: 0 | M12: 135 | N12: 0 | O12: =SUM(C12:L12,N12) -> 104 | P12: =SUM(C12:N12) -> 239 | R12: 0900-1000 | S12: =SUM(C18:C21) -> 197 | T12: =SUM(D18:D21) -> 27 | U12: =SUM(E18:E21) -> 21 | V12: =SUM(F18:F21) -> 139 | W12: =SUM(G18:G21) -> 2 | X12: =SUM(H18:H21) -> 1 | Y12: =SUM(I18:I21) -> 27 | Z12: =SUM(J18:J21) -> 68 | ... AF12: =SUM(P18:P21) -> 1209
B13: 07.45 - 08.00 | C13: 46 | D13: 2 | E13: 5 | F13: 40 | G13: 0 | H13: 0 | I13: 5 | J13: 15 | K13: 0 | L13: 2 | M13: 105 | N13: 0 | O13: =SUM(C13:L13,N13) -> 115 | P13: =SUM(C13:N13) -> 220 | R13: 1000-1100 | S13: =SUM(C22:C25) -> 205 | T13: =SUM(D22:D25) -> 19 | U13: =SUM(E22:E25) -> 22 | V13: =SUM(F22:F25) -> 134 | W13: =SUM(G22:G25) -> 2 | X13: =SUM(H22:H25) -> 2 | Y13: =SUM(I22:I25) -> 28 | Z13: =SUM(J22:J25) -> 67 | ... AF13: =SUM(P22:P25) -> 1269
B14: 08.00 - 08.15 | C14: 62 | D14: 4 | E14: 3 | F14: 27 | G14: 1 | H14: 0 | I14: 9 | J14: 17 | K14: 0 | L14: 3 | M14: 150 | N14: 0 | O14: =SUM(C14:L14,N14) -> 126 | P14: =SUM(C14:N14) -> 276 | R14: 1100-1200 | S14: =SUM(C26:C29) -> 204 | T14: =SUM(D26:D29) -> 25 | U14: =SUM(E26:E29) -> 15 | V14: =SUM(F26:F29) -> 127 | W14: =SUM(G26:G29) -> 3 | X14: =SUM(H26:H29) -> 2 | Y14: =SUM(I26:I29) -> 26 | Z14: =SUM(J26:J29) -> 70 | ... AF14: =SUM(P26:P29) -> 1229
B15: 08.15 - 08.30 | C15: 64 | D15: 1 | E15: 2 | F15: 36 | G15: 1 | H15: 2 | I15: 7 | J15: 15 | K15: 5 | L15: 0 | M15: 200 | N15: 0 | O15: =SUM(C15:L15,N15) -> 133 | P15: =SUM(C15:N15) -> 333 | R15: 1200-1300 | S15: =SUM(C30:C33) -> 220 | T15: =SUM(D30:D33) -> 22 | U15: =SUM(E30:E33) -> 14 | V15: =SUM(F30:F33) -> 147 | W15: =SUM(G30:G33) -> 5 | X15: =SUM(H30:H33) -> 0 | Y15: =SUM(I30:I33) -> 29 | Z15: =SUM(J30:J33) -> 82 | ... AF15: =SUM(P30:P33) -> 1359
B16: 08.30 - 08.45 | C16: 50 | D16: 0 | E16: 1 | F16: 120 | G16: 0 | H16: 1 | I16: 16 | J16: 22 | K16: 0 | L16: 0 | M16: 175 | N16: 0 | O16: =SUM(C16:L16,N16) -> 210 | P16: =SUM(C16:N16) -> 385 | R16: 1300-1400 | S16: =SUM(C34:C37) -> 172 | T16: =SUM(D34:D37) -> 22 | U16: =SUM(E34:E37) -> 15 | V16: =SUM(F34:F37) -> 100 | W16: =SUM(G34:G37) -> 0 | X16: =SUM(H34:H37) -> 0 | Y16: =SUM(I34:I37) -> 25 | Z16: =SUM(J34:J37) -> 57 | ... AF16: =SUM(P34:P37) -> 1164
B17: 08.45 - 9.00 | C17: 62 | D17: 10 | E17: 2 | F17: 44 | G17: 2 | H17: 0 | I17: 17 | J17: 25 | K17: 1 | L17: 23 | M17: 185 | N17: 1 | O17: =SUM(C17:L17,N17) -> 187 | P17: =SUM(C17:N17) -> 372 | R17: 1400-1500 | S17: =SUM(C38:C41) -> 171 | T17: =SUM(D38:D41) -> 21 | U17: =SUM(E38:E41) -> 13 | V17: =SUM(F38:F41) -> 108 | W17: =SUM(G38:G41) -> 2 | X17: =SUM(H38:H41) -> 1 | Y17: =SUM(I38:I41) -> 17 | Z17: =SUM(J38:J41) -> 55 | ... AF17: =SUM(P38:P41) -> 1167
B18: 09.00 - 09.15 | C18: 53 | D18: 7 | E18: 3 | F18: 28 | G18: 1 | H18: 1 | I18: 12 | J18: 20 | K18: 1 | L18: 1 | M18: 155 | N18: 0 | O18: =SUM(C18:L18,N18) -> 127 | P18: =SUM(C18:N18) -> 282 | R18: 1500-1600 | S18: =SUM(C42:C45) -> 163 | T18: =SUM(D42:D45) -> 18 | U18: =SUM(E42:E45) -> 13 | V18: =SUM(F42:F45) -> 122 | W18: =SUM(G42:G45) -> 1 | X18: =SUM(H42:H45) -> 0 | Y18: =SUM(I42:I45) -> 17 | Z18: =SUM(J42:J45) -> 41 | ... AF18: =SUM(P42:P45) -> 1166
B19: 09.15 - 09.30 | C19: 41 | D19: 3 | E19: 3 | F19: 41 | G19: 1 | H19: 0 | I19: 6 | J19: 9 | K19: 0 | L19: 0 | M19: 145 | N19: 0 | O19: =SUM(C19:L19,N19) -> 104 | P19: =SUM(C19:N19) -> 249 | R19: 1600-1700 | S19: =SUM(C46:C49) -> 189 | T19: =SUM(D46:D49) -> 22 | U19: =SUM(E46:E49) -> 24 | V19: =SUM(F46:F49) -> 109 | W19: =SUM(G46:G49) -> 2 | X19: =SUM(H46:H49) -> 0 | Y19: =SUM(I46:I49) -> 13 | Z19: =SUM(J46:J49) -> 58 | ... AF19: =SUM(P46:P49) -> 1136
B20: 09.30 - 09.45 | C20: 50 | D20: 11 | E20: 10 | F20: 36 | G20: 0 | H20: 0 | I20: 7 | J20: 14 | K20: 2 | L20: 0 | M20: 195 | N20: 0 | O20: =SUM(C20:L20,N20) -> 130 | P20: =SUM(C20:N20) -> 325 | R20: 1700-1800 | S20: =SUM(C50:C53) -> 170 | T20: =SUM(D50:D53) -> 12 | U20: =SUM(E50:E53) -> 7 | V20: =SUM(F50:F53) -> 132 | W20: =SUM(G50:G53) -> 0 | X20: =SUM(H50:H53) -> 3 | Y20: =SUM(I50:I53) -> 11 | Z20: =SUM(J50:J53) -> 50 | ... AF20: =SUM(P50:P53) -> 1065
B21: 09.45 - 10.00 | C21: 53 | D21: 6 | E21: 5 | F21: 34 | G21: 0 | H21: 0 | I21: 2 | J21: 25 | K21: 2 | L21: 1 | M21: 225 | N21: 0 | O21: =SUM(C21:L21,N21) -> 128 | P21: =SUM(C21:N21) -> 353 | R21: 1800-1900 | S21: =SUM(C54:C57) -> 156 | T21: =SUM(D54:D57) -> 19 | U21: =SUM(E54:E57) -> 11 | V21: =SUM(F54:F57) -> 168 | W21: =SUM(G54:G57) -> 7 | X21: =SUM(H54:H57) -> 4 | Y21: =SUM(I54:I57) -> 20 | Z21: =SUM(J54:J57) -> 50 | ... AF21: =SUM(P54:P57) -> 1080
B22: 10.00 - 10.15 | C22: 50 | D22: 2 | E22: 9 | F22: 31 | G22: 0 | H22: 0 | I22: 12 | J22: 18 | K22: 5 | L22: 0 | M22: 200 | N22: 0 | O22: =SUM(C22:L22,N22) -> 127 | P22: =SUM(C22:N22) -> 327 | R22: AM Peak Hr | S22: =MAX(S10:S12) -> 238 | T22: =MAX(T10:T12) -> 27 | U22: =MAX(U10:U12) -> 21 | V22: =MAX(V10:V12) -> 227 | W22: =MAX(W10:W12) -> 4 | X22: =MAX(X10:X12) -> 3 | Y22: =MAX(Y10:Y12) -> 49 | Z22: =MAX(Z10:Z12) -> 79 | ... AF22: =MAX(AF10:AF12) -> 1366
B23: 10.15 - 10.30 | C23: 57 | D23: 3 | E23: 6 | F23: 40 | G23: 1 | H23: 1 | I23: 10 | J23: 20 | K23: 2 | L23: 0 | M23: 170 | N23: 0 | O23: =SUM(C23:L23,N23) -> 140 | P23: =SUM(C23:N23) -> 310 | R23: IP Peak Hr | S23: =MAX(S13:S18) -> 220 | T23: =MAX(T13:T18) -> 25 | U23: =MAX(U13:U18) -> 22 | V23: =MAX(V13:V18) -> 147 | W23: =MAX(W13:W18) -> 5 | X23: =MAX(X13:X18) -> 2 | Y23: =MAX(Y13:Y18) -> 29 | Z23: =MAX(Z13:Z18) -> 82 | ... AF23: =MAX(AF13:AF18) -> 1359
B24: 10.30 - 10.45 | C24: 51 | D24: 7 | E24: 5 | F24: 31 | G24: 1 | H24: 0 | I24: 4 | J24: 9 | K24: 2 | L24: 2 | M24: 195 | N24: 0 | O24: =SUM(C24:L24,N24) -> 112 | P24: =SUM(C24:N24) -> 307 | R24: PM Peak Hr | S24: =MAX(S19:S21) -> 189 | T24: =MAX(T19:T21) -> 22 | U24: =MAX(U19:U21) -> 24 | V24: =MAX(V19:V21) -> 168 | W24: =MAX(W19:W21) -> 7 | X24: =MAX(X19:X21) -> 4 | Y24: =MAX(Y19:Y21) -> 20 | Z24: =MAX(Z19:Z21) -> 58 | ... AF24: =MAX(AF19:AF21) -> 1136
B25: 10.45 - 11.00 | C25: 47 | D25: 7 | E25: 2 | F25: 32 | G25: 0 | H25: 1 | I25: 2 | J25: 20 | K25: 1 | L25: 3 | M25: 210 | N25: 0 | O25: =SUM(C25:L25,N25) -> 115 | P25: =SUM(C25:N25) -> 325 | R25: AM Period | S25: =SUM(S10:S12) -> 621 | T25: =SUM(T10:T12) -> 55 | U25: =SUM(U10:U12) -> 44 | V25: =SUM(V10:V12) -> 483 | W25: =SUM(W10:W12) -> 7 | X25: =SUM(X10:X12) -> 5 | Y25: =SUM(Y10:Y12) -> 110 | Z25: =SUM(Z10:Z12) -> 192 | ... AF25: =SUM(AF10:AF12) -> 3410
B26: 11.00 - 11.15 | C26: 53 | D26: 4 | E26: 2 | F26: 33 | G26: 0 | H26: 0 | I26: 8 | J26: 20 | K26: 3 | L26: 4 | M26: 160 | N26: 0 | O26: =SUM(C26:L26,N26) -> 127 | P26: =SUM(C26:N26) -> 287 | R26: IP Period | S26: =SUM(S13:S18) -> 1135 | T26: =SUM(T13:T18) -> 127 | U26: =SUM(U13:U18) -> 92 | V26: =SUM(V13:V18) -> 738 | W26: =SUM(W13:W18) -> 13 | X26: =SUM(X13:X18) -> 5 | Y26: =SUM(Y13:Y18) -> 142 | Z26: =SUM(Z13:Z18) -> 372 | ... AF26: =SUM(AF13:AF18) -> 7354
B27: 11.15 - 11.30 | C27: 51 | D27: 3 | E27: 4 | F27: 36 | G27: 0 | H27: 0 | I27: 4 | J27: 15 | K27: 2 | L27: 1 | M27: 190 | N27: 0 | O27: =SUM(C27:L27,N27) -> 116 | P27: =SUM(C27:N27) -> 306 | R27: PM Period | S27: =SUM(S19:S21) -> 515 | T27: =SUM(T19:T21) -> 53 | U27: =SUM(U19:U21) -> 42 | V27: =SUM(V19:V21) -> 409 | W27: =SUM(W19:W21) -> 9 | X27: =SUM(X19:X21) -> 7 | Y27: =SUM(Y19:Y21) -> 44 | Z27: =SUM(Z19:Z21) -> 158 | ... AF27: =SUM(AF19:AF21) -> 3281
