Workbook

Sheet 25.10 Kasese-Fort Portal
B1: Consultancy services for Preparation of Expressway Development Master Plan (EDMP) for Uganda
B2: MANUAL CLASSIFIED COUNT (MCC)
B3: ROAD NAME: | C3: MCC - C4 - STN106
C5: Date | D5: 25.10.19 | F5: Location | G5: Kisanga B | J5: Surveyor | K5: Onyuti Betty
C6: Dir. From | D6: Kasese | F6: Dir. To | G6: Fort Portal | J6: Supervisor | K6: Onyuti Betty
B8: Time / Veh Type | R8: SUMMARY TRAFFIC VOLUMES
C9: 1. Car | D9: 2. Station Wagon | E9: 3. Pickups | F9: 4. Minibus, matatu | G9: 5. Medium bus | H9: 6. Large Bus | I9: 7. Light Truck | J9: 8. Medium Truck | K9: 9. Heavy truck | L9: 10. Truck Trailer | M9: 11. Motor cycles | N9: 12. Tractors | O9: Total Excl M/Cycles | P9: Total All | R9: Time | S9: 1. Car | T9: 2. Station Wagon | U9: 3. Pickups | V9: 4. Minibus, matatu | W9: 5. Medium bus | X9: 6. Large Bus | Y9: 7. Light Truck | Z9: 8. Medium Truck | AA9: 9. Heavy truck | AB9: 10. Truck Trailer | AC9: 11. Motorcycles | AD9: 12. Tractors, Graders | AE9: Total Excl M/ Cycles | AF9: Total All
B10: 07.00 - 07.15 | C10: 5 | D10: 2 | E10: 4 | F10: 6 | G10: 1 | H10: 1 | I10: 4 | J10: 0 | K10: 0 | L10: 0 | M10: 102 | N10: 0 | O10: =SUM(C10:L10,N10) -> 23 | P10: =SUM(C10:N10) -> 125 | R10: 0700-0800 | S10: =SUM(C10:C13) -> 37 | T10: =SUM(D10:D13) -> 4 | U10: =SUM(E10:E13) -> 9 | V10: =SUM(F10:F13) -> 27 | W10: =SUM(G10:G13) -> 2 | X10: =SUM(H10:H13) -> 1 | Y10: =SUM(I10:I13) -> 13 | Z10: =SUM(J10:J13) -> 0 | ... AF10: =SUM(P10:P13) -> 530
B11: 07.15 - 07.30 | C11: 14 | D11: 1 | E11: 3 | F11: 8 | G11: 0 | H11: 0 | I11: 3 | J11: 0 | K11: 0 | L11: 1 | M11: 115 | N11: 0 | O11: =SUM(C11:L11,N11) -> 30 | P11: =SUM(C11:N11) -> 145 | R11: 0800-0900 | S11: =SUM(C14:C17) -> 42 | T11: =SUM(D14:D17) -> 15 | U11: =SUM(E14:E17) -> 20 | V11: =SUM(F14:F17) -> 28 | W11: =SUM(G14:G17) -> 1 | X11: =SUM(H14:H17) -> 2 | Y11: =SUM(I14:I17) -> 23 | Z11: =SUM(J14:J17) -> 3 | ... AF11: =SUM(P14:P17) -> 643
B12: 07.30 - 07.45 | C12: 10 | D12: 1 | E12: 0 | F12: 8 | G12: 0 | H12: 0 | I12: 3 | J12: 0 | K12: 0 | L12: 0 | M12: 115 | N12: 0 | O12: =SUM(C12:L12,N12) -> 22 | P12: =SUM(C12:N12) -> 137 | R12: 0900-1000 | S12: =SUM(C18:C21) -> 53 | T12: =SUM(D18:D21) -> 10 | U12: =SUM(E18:E21) -> 16 | V12: =SUM(F18:F21) -> 23 | W12: =SUM(G18:G21) -> 0 | X12: =SUM(H18:H21) -> 2 | Y12: =SUM(I18:I21) -> 16 | Z12: =SUM(J18:J21) -> 3 | ... AF12: =SUM(P18:P21) -> 791
B13: 07.45 - 08.00 | C13: 8 | D13: 0 | E13: 2 | F13: 5 | G13: 1 | H13: 0 | I13: 3 | J13: 0 | K13: 1 | L13: 0 | M13: 103 | N13: 0 | O13: =SUM(C13:L13,N13) -> 20 | P13: =SUM(C13:N13) -> 123 | R13: 1000-1100 | S13: =SUM(C22:C25) -> 48 | T13: =SUM(D22:D25) -> 9 | U13: =SUM(E22:E25) -> 6 | V13: =SUM(F22:F25) -> 25 | W13: =SUM(G22:G25) -> 0 | X13: =SUM(H22:H25) -> 4 | Y13: =SUM(I22:I25) -> 15 | Z13: =SUM(J22:J25) -> 2 | ... AF13: =SUM(P22:P25) -> 592
B14: 08.00 - 08.15 | C14: 13 | D14: 2 | E14: 5 | F14: 6 | G14: 0 | H14: 0 | I14: 2 | J14: 1 | K14: 3 | L14: 0 | M14: 100 | N14: 0 | O14: =SUM(C14:L14,N14) -> 32 | P14: =SUM(C14:N14) -> 132 | R14: 1100-1200 | S14: =SUM(C26:C29) -> 34 | T14: =SUM(D26:D29) -> 12 | U14: =SUM(E26:E29) -> 21 | V14: =SUM(F26:F29) -> 24 | W14: =SUM(G26:G29) -> 0 | X14: =SUM(H26:H29) -> 1 | Y14: =SUM(I26:I29) -> 29 | Z14: =SUM(J26:J29) -> 3 | ... AF14: =SUM(P26:P29) -> 548
B15: 08.15 - 08.30 | C15: 5 | D15: 5 | E15: 3 | F15: 6 | G15: 0 | H15: 2 | I15: 10 | J15: 0 | K15: 0 | L15: 0 | M15: 120 | N15: 0 | O15: =SUM(C15:L15,N15) -> 31 | P15: =SUM(C15:N15) -> 151 | R15: 1200-1300 | S15: =SUM(C30:C33) -> 42 | T15: =SUM(D30:D33) -> 12 | U15: =SUM(E30:E33) -> 16 | V15: =SUM(F30:F33) -> 27 | W15: =SUM(G30:G33) -> 0 | X15: =SUM(H30:H33) -> 1 | Y15: =SUM(I30:I33) -> 17 | Z15: =SUM(J30:J33) -> 3 | ... AF15: =SUM(P30:P33) -> 535
B16: 08.30 - 08.45 | C16: 11 | D16: 3 | E16: 5 | F16: 7 | G16: 0 | H16: 0 | I16: 3 | J16: 2 | K16: 2 | L16: 0 | M16: 136 | N16: 0 | O16: =SUM(C16:L16,N16) -> 33 | P16: =SUM(C16:N16) -> 169 | R16: 1300-1400 | S16: =SUM(C34:C37) -> 46 | T16: =SUM(D34:D37) -> 7 | U16: =SUM(E34:E37) -> 19 | V16: =SUM(F34:F37) -> 19 | W16: =SUM(G34:G37) -> 2 | X16: =SUM(H34:H37) -> 3 | Y16: =SUM(I34:I37) -> 17 | Z16: =SUM(J34:J37) -> 2 | ... AF16: =SUM(P34:P37) -> 521
B17: 08.45 - 9.00 | C17: 13 | D17: 5 | E17: 7 | F17: 9 | G17: 1 | H17: 0 | I17: 8 | J17: 0 | K17: 0 | L17: 0 | M17: 148 | N17: 0 | O17: =SUM(C17:L17,N17) -> 43 | P17: =SUM(C17:N17) -> 191 | R17: 1400-1500 | S17: =SUM(C38:C41) -> 28 | T17: =SUM(D38:D41) -> 7 | U17: =SUM(E38:E41) -> 26 | V17: =SUM(F38:F41) -> 26 | W17: =SUM(G38:G41) -> 0 | X17: =SUM(H38:H41) -> 1 | Y17: =SUM(I38:I41) -> 22 | Z17: =SUM(J38:J41) -> 4 | ... AF17: =SUM(P38:P41) -> 484
B18: 09.00 - 09.15 | C18: 12 | D18: 3 | E18: 3 | F18: 4 | G18: 0 | H18: 1 | I18: 3 | J18: 0 | K18: 1 | L18: 2 | M18: 170 | N18: 0 | O18: =SUM(C18:L18,N18) -> 29 | P18: =SUM(C18:N18) -> 199 | R18: 1500-1600 | S18: =SUM(C42:C45) -> 43 | T18: =SUM(D42:D45) -> 5 | U18: =SUM(E42:E45) -> 23 | V18: =SUM(F42:F45) -> 23 | W18: =SUM(G42:G45) -> 2 | X18: =SUM(H42:H45) -> 2 | Y18: =SUM(I42:I45) -> 21 | Z18: =SUM(J42:J45) -> 4 | ... AF18: =SUM(P42:P45) -> 396
B19: 09.15 - 09.30 | C19: 14 | D19: 3 | E19: 3 | F19: 6 | G19: 0 | H19: 0 | I19: 5 | J19: 0 | K19: 1 | L19: 3 | M19: 175 | N19: 0 | O19: =SUM(C19:L19,N19) -> 35 | P19: =SUM(C19:N19) -> 210 | R19: 1600-1700 | S19: =SUM(C46:C49) -> 39 | T19: =SUM(D46:D49) -> 3 | U19: =SUM(E46:E49) -> 28 | V19: =SUM(F46:F49) -> 28 | W19: =SUM(G46:G49) -> 2 | X19: =SUM(H46:H49) -> 1 | Y19: =SUM(I46:I49) -> 20 | Z19: =SUM(J46:J49) -> 0 | ... AF19: =SUM(P46:P49) -> 648
B20: 09.30 - 09.45 | C20: 15 | D20: 2 | E20: 7 | F20: 5 | G20: 0 | H20: 1 | I20: 5 | J20: 1 | K20: 1 | L20: 1 | M20: 123 | N20: 0 | O20: =SUM(C20:L20,N20) -> 38 | P20: =SUM(C20:N20) -> 161 | R20: 1700-1800 | S20: =SUM(C50:C53) -> 62 | T20: =SUM(D50:D53) -> 8 | U20: =SUM(E50:E53) -> 19 | V20: =SUM(F50:F53) -> 27 | W20: =SUM(G50:G53) -> 0 | X20: =SUM(H50:H53) -> 0 | Y20: =SUM(I50:I53) -> 5 | Z20: =SUM(J50:J53) -> 0 | ... AF20: =SUM(P50:P53) -> 644
B21: 09.45 - 10.00 | C21: 12 | D21: 2 | E21: 3 | F21: 8 | G21: 0 | H21: 0 | I21: 3 | J21: 2 | K21: 0 | L21: 1 | M21: 190 | N21: 0 | O21: =SUM(C21:L21,N21) -> 31 | P21: =SUM(C21:N21) -> 221 | R21: 1800-1900 | S21: =SUM(C54:C57) -> 49 | T21: =SUM(D54:D57) -> 12 | U21: =SUM(E54:E57) -> 15 | V21: =SUM(F54:F57) -> 25 | W21: =SUM(G54:G57) -> 1 | X21: =SUM(H54:H57) -> 0 | Y21: =SUM(I54:I57) -> 0 | Z21: =SUM(J54:J57) -> 0 | ... AF21: =SUM(P54:P57) -> 547
B22: 10.00 - 10.15 | C22: 8 | D22: 3 | E22: 2 | F22: 1 | G22: 0 | H22: 1 | I22: 4 | J22: 1 | K22: 2 | L22: 0 | M22: 132 | N22: 0 | O22: =SUM(C22:L22,N22) -> 22 | P22: =SUM(C22:N22) -> 154 | R22: AM Peak Hr | S22: =MAX(S10:S12) -> 53 | T22: =MAX(T10:T12) -> 15 | U22: =MAX(U10:U12) -> 20 | V22: =MAX(V10:V12) -> 28 | W22: =MAX(W10:W12) -> 2 | X22: =MAX(X10:X12) -> 2 | Y22: =MAX(Y10:Y12) -> 23 | Z22: =MAX(Z10:Z12) -> 3 | ... AF22: =MAX(AF10:AF12) -> 791
B23: 10.15 - 10.30 | C23: 9 | D23: 2 | E23: 1 | F23: 11 | G23: 0 | H23: 0 | I23: 3 | J23: 0 | K23: 1 | L23: 0 | M23: 108 | N23: 0 | O23: =SUM(C23:L23,N23) -> 27 | P23: =SUM(C23:N23) -> 135 | R23: IP Peak Hr | S23: =MAX(S13:S18) -> 48 | T23: =MAX(T13:T18) -> 12 | U23: =MAX(U13:U18) -> 26 | V23: =MAX(V13:V18) -> 27 | W23: =MAX(W13:W18) -> 2 | X23: =MAX(X13:X18) -> 4 | Y23: =MAX(Y13:Y18) -> 29 | Z23: =MAX(Z13:Z18) -> 4 | ... AF23: =MAX(AF13:AF18) -> 592
B24: 10.30 - 10.45 | C24: 12 | D24: 1 | E24: 3 | F24: 6 | G24: 0 | H24: 3 | I24: 1 | J24: 1 | K24: 0 | L24: 0 | M24: 108 | N24: 0 | O24: =SUM(C24:L24,N24) -> 27 | P24: =SUM(C24:N24) -> 135 | R24: PM Peak Hr | S24: =MAX(S19:S21) -> 62 | T24: =MAX(T19:T21) -> 12 | U24: =MAX(U19:U21) -> 28 | V24: =MAX(V19:V21) -> 28 | W24: =MAX(W19:W21) -> 2 | X24: =MAX(X19:X21) -> 1 | Y24: =MAX(Y19:Y21) -> 20 | Z24: =MAX(Z19:Z21) -> 0 | ... AF24: =MAX(AF19:AF21) -> 648
B25: 10.45 - 11.00 | C25: 19 | D25: 3 | E25: 0 | F25: 7 | G25: 0 | H25: 0 | I25: 7 | J25: 0 | K25: 0 | L25: 0 | M25: 132 | N25: 0 | O25: =SUM(C25:L25,N25) -> 36 | P25: =SUM(C25:N25) -> 168 | R25: AM Period | S25: =SUM(S10:S12) -> 132 | T25: =SUM(T10:T12) -> 29 | U25: =SUM(U10:U12) -> 45 | V25: =SUM(V10:V12) -> 78 | W25: =SUM(W10:W12) -> 3 | X25: =SUM(X10:X12) -> 5 | Y25: =SUM(Y10:Y12) -> 52 | Z25: =SUM(Z10:Z12) -> 6 | ... AF25: =SUM(AF10:AF12) -> 1964
B26: 11.00 - 11.15 | C26: 9 | D26: 0 | E26: 6 | F26: 6 | G26: 0 | H26: 0 | I26: 9 | J26: 0 | K26: 1 | L26: 1 | M26: 94 | N26: 0 | O26: =SUM(C26:L26,N26) -> 32 | P26: =SUM(C26:N26) -> 126 | R26: IP Period | S26: =SUM(S13:S18) -> 241 | T26: =SUM(T13:T18) -> 52 | U26: =SUM(U13:U18) -> 111 | V26: =SUM(V13:V18) -> 144 | W26: =SUM(W13:W18) -> 4 | X26: =SUM(X13:X18) -> 12 | Y26: =SUM(Y13:Y18) -> 121 | Z26: =SUM(Z13:Z18) -> 18 | ... AF26: =SUM(AF13:AF18) -> 3076
B27: 11.15 - 11.30 | C27: 9 | D27: 3 | E27: 4 | F27: 7 | G27: 0 | H27: 1 | I27: 8 | J27: 0 | K27: 0 | L27: 0 | M27: 114 | N27: 0 | O27: =SUM(C27:L27,N27) -> 32 | P27: =SUM(C27:N27) -> 146 | R27: PM Period | S27: =SUM(S19:S21) -> 150 | T27: =SUM(T19:T21) -> 23 | U27: =SUM(U19:U21) -> 62 | V27: =SUM(V19:V21) -> 80 | W27: =SUM(W19:W21) -> 3 | X27: =SUM(X19:X21) -> 1 | Y27: =SUM(Y19:Y21) -> 25 | Z27: =SUM(Z19:Z21) -> 0 | ... AF27: =SUM(AF19:AF21) -> 1839
B28: 11.30 - 11.45 | C28: 7 | D28: 5 | E28: 3 | F28: 7 | G28: 0 | H28: 0 | I28: 6 | J28: 1 | K28: 0 | L28: 5 | M28: 112 | N28: 0 | O28: =SUM(C28:L28,N28) -> 34 | P28: =SUM(C28:N28) -> 146 | R28: 12 Hours | S28: =SUM(S10:S21) -> 523 | T28: =SUM(T10:T21) -> 104 | U28: =SUM(U10:U21) -> 218 | V28: =SUM(V10:V21) -> 302 | W28: =SUM(W10:W21) -> 10 | X28: =SUM(X10:X21) -> 18 | Y28: =SUM(Y10:Y21) -> 198 | Z28: =SUM(Z10:Z21) -> 24 | ... AF28: =SUM(AF10:AF21) -> 6879
B29: 11.45 - 12.00 | C29: 9 | D29: 4 | E29: 8 | F29: 4 | G29: 0 | H29: 0 | I29: 6 | J29: 2 | K29: 0 | L29: 1 | M29: 96 | N29: 0 | O29: =SUM(C29:L29,N29) -> 34 | P29: =SUM(C29:N29) -> 130
B30: 12.00 - 12.15 | C30: 15 | D30: 3 | E30: 5 | F30: 9 | G30: 0 | H30: 0 | I30: 6 | J30: 0 | K30: 1 | L30: 0 | M30: 113 | N30: 0 | O30: =SUM(C30:L30,N30) -> 39 | P30: =SUM(C30:N30) -> 152
B31: 12.15 - 12.30 | C31: 10 | D31: 1 | E31: 3 | F31: 2 | G31: 0 | H31: 1 | I31: 1 | J31: 0 | K31: 0 | L31: 0 | M31: 103 | N31: 0 | O31: =SUM(C31:L31,N31) -> 18 | P31: =SUM(C31:N31) -> 121
B32: 12.30 - 12.45 | C32: 8 | D32: 5 | E32: 4 | F32: 8 | G32: 0 | H32: 0 | I32: 5 | J32: 2 | K32: 1 | L32: 0 | M32: 92 | N32: 0 | O32: =SUM(C32:L32,N32) -> 33 | P32: =SUM(C32:N32) -> 125
B33: 12.45 - 13.00 | C33: 9 | D33: 3 | E33: 4 | F33: 8 | G33: 0 | H33: 0 | I33: 5 | J33: 1 | K33: 1 | L33: 0 | M33: 106 | N33: 0 | O33: =SUM(C33:L33,N33) -> 31 | P33: =SUM(C33:N33) -> 137
B34: 13.00 - 13.15 | C34: 12 | D34: 1 | E34: 3 | F34: 3 | G34: 2 | H34: 2 | I34: 4 | J34: 1 | K34: 0 | L34: 0 | M34: 114 | N34: 0 | O34: =SUM(C34:L34,N34) -> 28 | P34: =SUM(C34:N34) -> 142
B35: 13.15 - 13.30 | C35: 12 | D35: 1 | E35: 9 | F35: 9 | G35: 0 | H35: 0 | I35: 8 | J35: 0 | K35: 2 | L35: 0 | M35: 100 | N35: 0 | O35: =SUM(C35:L35,N35) -> 41 | P35: =SUM(C35:N35) -> 141
B36: 13.30 - 13.45 | C36: 15 | D36: 3 | E36: 5 | F36: 5 | G36: 0 | H36: 0 | I36: 3 | J36: 0 | K36: 0 | L36: 1 | M36: 98 | N36: 0 | O36: =SUM(C36:L36,N36) -> 32 | P36: =SUM(C36:N36) -> 130
B37: 13.45 - 14.00 | C37: 7 | D37: 2 | E37: 2 | F37: 2 | G37: 0 | H37: 1 | I37: 2 | J37: 1 | K37: 0 | L37: 2 | M37: 89 | N37: 0 | O37: =SUM(C37:L37,N37) -> 19 | P37: =SUM(C37:N37) -> 108
B38: 14.00 - 14.15 | C38: 4 | D38: 4 | E38: 7 | F38: 7 | G38: 0 | H38: 1 | I38: 7 | J38: 0 | K38: 0 | L38: 1 | M38: 98 | N38: 0 | O38: =SUM(C38:L38,N38) -> 31 | P38: =SUM(C38:N38) -> 129
B39: 14.15 - 14.30 | C39: 9 | D39: 0 | E39: 11 | F39: 11 | G39: 0 | H39: 0 | I39: 5 | J39: 2 | K39: 1 | L39: 0 | M39: 100 | N39: 0 | O39: =SUM(C39:L39,N39) -> 39 | P39: =SUM(C39:N39) -> 139
B40: 14.30 - 14.45 | C40: 5 | D40: 1 | E40: 4 | F40: 4 | G40: 0 | H40: 0 | I40: 8 | J40: 1 | K40: 0 | L40: 1 | M40: 67 | N40: 0 | O40: =SUM(C40:L40,N40) -> 24 | P40: =SUM(C40:N40) -> 91
... B57: 18.45 - 19.00 | C57: 14 | D57: 1 | E57: 1 | F57: 6 | G57: 0 | H57: 0 | I57: 0 | J57: 0 | K57: 1 | L57: 0 | M57: 112 | N57: 1 | O57: =SUM(C57:L57,N57) -> 24 | P57: =SUM(C57:N57) -> 136
B58: Totals | C58: =SUM(C10:C57) -> 523 | D58: =SUM(D10:D57) -> 104 | E58: =SUM(E10:E57) -> 218 | F58: =SUM(F10:F57) -> 302 | G58: =SUM(G10:G57) -> 10 | H58: =SUM(H10:H57) -> 18 | I58: =SUM(I10:I57) -> 198 | J58: =SUM(J10:J57) -> 24 | ... P58: =SUM(P10:P57) -> 6879
...

Sheet 25.10 Fort Portal-Kasese
B1: Consultancy services for Preparation of Expressway Development Master Plan (EDMP) for Uganda
B2: MANUAL CLASSIFIED COUNT (MCC)
B3: ROAD NAME: | C3: ='25.10 Kasese-Fort Portal'!C3:G3 -> MCC - C4 - STN106
C5: Date | D5: ='25.10 Kasese-Fort Portal'!D5 -> 25.10.19 | F5: Location | G5: ='25.10 Kasese-Fort Portal'!G5:H5 -> Kisanga B | J5: Surveyor | K5: ='25.10 Kasese-Fort Portal'!K5:L5 -> Onyuti Betty
C6: Dir. From | D6: Fort Portal | F6: Dir. To | G6: Kasese | J6: Supervisor | K6: ='25.10 Kasese-Fort Portal'!K6:L6 -> Onyuti Betty
B8: Time / Veh Type | R8: SUMMARY TRAFFIC VOLUMES
C9: 1. Car | D9: 2. Station Wagon | E9: 3. Pickups | F9: 4. Minibus, matatu | G9: 5. Medium bus | H9: 6. Large Bus | I9: 7. Light Truck | J9: 8. Medium Truck | K9: 9. Heavy truck | L9: 10. Truck Trailer | M9: 11. Motor cycles | N9: 12. Tractors | O9: Total Excl M/Cycles | P9: Total All | R9: Time | S9: 1. Car | T9: 2. Station Wagon | U9: 3. Pickups | V9: 4. Minibus, matatu | W9: 5. Medium bus | X9: 6. Large Bus | Y9: 7. Light Truck | Z9: 8. Medium Truck | AA9: 9. Heavy truck | AB9: 10. Truck Trailer | AC9: 11. Motorcycles | AD9: 12. Tractors, Graders | AE9: Total Excl M/ Cycles | AF9: Total All
B10: 07.00 - 07.15 | C10: 8 | D10: 2 | E10: 0 | F10: 5 | G10: 0 | H10: 0 | I10: 1 | J10: 0 | K10: 0 | L10: 2 | M10: 120 | N10: 0 | O10: =SUM(C10:L10,N10) -> 18 | P10: =SUM(C10:N10) -> 138 | R10: 0700-0800 | S10: =SUM(C10:C13) -> 41 | T10: =SUM(D10:D13) -> 4 | U10: =SUM(E10:E13) -> 8 | V10: =SUM(F10:F13) -> 28 | W10: =SUM(G10:G13) -> 3 | X10: =SUM(H10:H13) -> 2 | Y10: =SUM(I10:I13) -> 6 | Z10: =SUM(J10:J13) -> 4 | ... AF10: =SUM(P10:P13) -> 559
B11: 07.15 - 07.30 | C11: 15 | D11: 1 | E11: 2 | F11: 8 | G11: 2 | H11: 1 | I11: 0 | J11: 1 | K11: 0 | L11: 0 | M11: 123 | N11: 0 | O11: =SUM(C11:L11,N11) -> 30 | P11: =SUM(C11:N11) -> 153 | R11: 0800-0900 | S11: =SUM(C14:C17) -> 47 | T11: =SUM(D14:D17) -> 7 | U11: =SUM(E14:E17) -> 14 | V11: =SUM(F14:F17) -> 26 | W11: =SUM(G14:G17) -> 0 | X11: =SUM(H14:H17) -> 0 | Y11: =SUM(I14:I17) -> 22 | Z11: =SUM(J14:J17) -> 9 | ... AF11: =SUM(P14:P17) -> 552
B12: 07.30 - 07.45 | C12: 8 | D12: 1 | E12: 1 | F12: 8 | G12: 0 | H12: 1 | I12: 4 | J12: 1 | K12: 1 | L12: 2 | M12: 109 | N12: 0 | O12: =SUM(C12:L12,N12) -> 27 | P12: =SUM(C12:N12) -> 136 | R12: 0900-1000 | S12: =SUM(C18:C21) -> 37 | T12: =SUM(D18:D21) -> 21 | U12: =SUM(E18:E21) -> 15 | V12: =SUM(F18:F21) -> 18 | W12: =SUM(G18:G21) -> 3 | X12: =SUM(H18:H21) -> 1 | Y12: =SUM(I18:I21) -> 17 | Z12: =SUM(J18:J21) -> 8 | ... AF12: =SUM(P18:P21) -> 591
B13: 07.45 - 08.00 | C13: 10 | D13: 0 | E13: 5 | F13: 7 | G13: 1 | H13: 0 | I13: 1 | J13: 2 | K13: 0 | L13: 0 | M13: 106 | N13: 0 | O13: =SUM(C13:L13,N13) -> 26 | P13: =SUM(C13:N13) -> 132 | R13: 1000-1100 | S13: =SUM(C22:C25) -> 41 | T13: =SUM(D22:D25) -> 13 | U13: =SUM(E22:E25) -> 15 | V13: =SUM(F22:F25) -> 28 | W13: =SUM(G22:G25) -> 1 | X13: =SUM(H22:H25) -> 0 | Y13: =SUM(I22:I25) -> 19 | Z13: =SUM(J22:J25) -> 7 | ... AF13: =SUM(P22:P25) -> 627
B14: 08.00 - 08.15 | C14: 14 | D14: 2 | E14: 4 | F14: 9 | G14: 0 | H14: 0 | I14: 5 | J14: 3 | K14: 0 | L14: 1 | M14: 115 | N14: 0 | O14: =SUM(C14:L14,N14) -> 38 | P14: =SUM(C14:N14) -> 153 | R14: 1100-1200 | S14: =SUM(C26:C29) -> 35 | T14: =SUM(D26:D29) -> 9 | U14: =SUM(E26:E29) -> 15 | V14: =SUM(F26:F29) -> 27 | W14: =SUM(G26:G29) -> 0 | X14: =SUM(H26:H29) -> 0 | Y14: =SUM(I26:I29) -> 24 | Z14: =SUM(J26:J29) -> 2 | ... AF14: =SUM(P26:P29) -> 616
B15: 08.15 - 08.30 | C15: 15 | D15: 2 | E15: 1 | F15: 5 | G15: 0 | H15: 0 | I15: 5 | J15: 2 | K15: 1 | L15: 2 | M15: 93 | N15: 0 | O15: =SUM(C15:L15,N15) -> 33 | P15: =SUM(C15:N15) -> 126 | R15: 1200-1300 | S15: =SUM(C30:C33) -> 50 | T15: =SUM(D30:D33) -> 14 | U15: =SUM(E30:E33) -> 16 | V15: =SUM(F30:F33) -> 35 | W15: =SUM(G30:G33) -> 1 | X15: =SUM(H30:H33) -> 2 | Y15: =SUM(I30:I33) -> 21 | Z15: =SUM(J30:J33) -> 3 | ... AF15: =SUM(P30:P33) -> 728
B16: 08.30 - 08.45 | C16: 5 | D16: 2 | E16: 3 | F16: 7 | G16: 0 | H16: 0 | I16: 7 | J16: 1 | K16: 0 | L16: 1 | M16: 102 | N16: 0 | O16: =SUM(C16:L16,N16) -> 26 | P16: =SUM(C16:N16) -> 128 | R16: 1300-1400 | S16: =SUM(C34:C37) -> 42 | T16: =SUM(D34:D37) -> 13 | U16: =SUM(E34:E37) -> 11 | V16: =SUM(F34:F37) -> 23 | W16: =SUM(G34:G37) -> 0 | X16: =SUM(H34:H37) -> 2 | Y16: =SUM(I34:I37) -> 15 | Z16: =SUM(J34:J37) -> 1 | ... AF16: =SUM(P34:P37) -> 682
B17: 08.45 - 9.00 | C17: 13 | D17: 1 | E17: 6 | F17: 5 | G17: 0 | H17: 0 | I17: 5 | J17: 3 | K17: 1 | L17: 2 | M17: 109 | N17: 0 | O17: =SUM(C17:L17,N17) -> 36 | P17: =SUM(C17:N17) -> 145 | R17: 1400-1500 | S17: =SUM(C38:C41) -> 36 | T17: =SUM(D38:D41) -> 6 | U17: =SUM(E38:E41) -> 16 | V17: =SUM(F38:F41) -> 25 | W17: =SUM(G38:G41) -> 2 | X17: =SUM(H38:H41) -> 2 | Y17: =SUM(I38:I41) -> 20 | Z17: =SUM(J38:J41) -> 4 | ... AF17: =SUM(P38:P41) -> 575
B18: 09.00 - 09.15 | C18: 13 | D18: 6 | E18: 3 | F18: 6 | G18: 1 | H18: 0 | I18: 8 | J18: 0 | K18: 0 | L18: 2 | M18: 115 | N18: 0 | O18: =SUM(C18:L18,N18) -> 39 | P18: =SUM(C18:N18) -> 154 | R18: 1500-1600 | S18: =SUM(C42:C45) -> 46 | T18: =SUM(D42:D45) -> 9 | U18: =SUM(E42:E45) -> 14 | V18: =SUM(F42:F45) -> 26 | W18: =SUM(G42:G45) -> 1 | X18: =SUM(H42:H45) -> 1 | Y18: =SUM(I42:I45) -> 21 | Z18: =SUM(J42:J45) -> 8 | ... AF18: =SUM(P42:P45) -> 687
B19: 09.15 - 09.30 | C19: 13 | D19: 10 | E19: 4 | F19: 8 | G19: 1 | H19: 1 | I19: 5 | J19: 2 | K19: 1 | L19: 1 | M19: 124 | N19: 0 | O19: =SUM(C19:L19,N19) -> 46 | P19: =SUM(C19:N19) -> 170 | R19: 1600-1700 | S19: =SUM(C46:C49) -> 50 | T19: =SUM(D46:D49) -> 11 | U19: =SUM(E46:E49) -> 16 | V19: =SUM(F46:F49) -> 20 | W19: =SUM(G46:G49) -> 0 | X19: =SUM(H46:H49) -> 0 | Y19: =SUM(I46:I49) -> 14 | Z19: =SUM(J46:J49) -> 6 | ... AF19: =SUM(P46:P49) -> 718
B20: 09.30 - 09.45 | C20: 4 | D20: 1 | E20: 1 | F20: 0 | G20: 1 | H20: 0 | I20: 4 | J20: 1 | K20: 1 | L20: 1 | M20: 110 | N20: 0 | O20: =SUM(C20:L20,N20) -> 14 | P20: =SUM(C20:N20) -> 124 | R20: 1700-1800 | S20: =SUM(C50:C53) -> 68 | T20: =SUM(D50:D53) -> 16 | U20: =SUM(E50:E53) -> 27 | V20: =SUM(F50:F53) -> 18 | W20: =SUM(G50:G53) -> 0 | X20: =SUM(H50:H53) -> 1 | Y20: =SUM(I50:I53) -> 15 | Z20: =SUM(J50:J53) -> 8 | ... AF20: =SUM(P50:P53) -> 679
B21: 09.45 - 10.00 | C21: 7 | D21: 4 | E21: 7 | F21: 4 | G21: 0 | H21: 0 | I21: 0 | J21: 5 | K21: 1 | L21: 1 | M21: 114 | N21: 0 | O21: =SUM(C21:L21,N21) -> 29 | P21: =SUM(C21:N21) -> 143 | R21: 1800-1900 | S21: =SUM(C54:C57) -> 69 | T21: =SUM(D54:D57) -> 11 | U21: =SUM(E54:E57) -> 17 | V21: =SUM(F54:F57) -> 25 | W21: =SUM(G54:G57) -> 2 | X21: =SUM(H54:H57) -> 2 | Y21: =SUM(I54:I57) -> 25 | Z21: =SUM(J54:J57) -> 2 | ... AF21: =SUM(P54:P57) -> 526
B22: 10.00 - 10.15 | C22: 12 | D22: 5 | E22: 5 | F22: 7 | G22: 1 | H22: 0 | I22: 6 | J22: 2 | K22: 0 | L22: 1 | M22: 159 | N22: 0 | O22: =SUM(C22:L22,N22) -> 39 | P22: =SUM(C22:N22) -> 198 | R22: AM Peak Hr | S22: =MAX(S10:S12) -> 47 | T22: =MAX(T10:T12) -> 21 | U22: =MAX(U10:U12) -> 15 | V22: =MAX(V10:V12) -> 28 | W22: =MAX(W10:W12) -> 3 | X22: =MAX(X10:X12) -> 2 | Y22: =MAX(Y10:Y12) -> 22 | Z22: =MAX(Z10:Z12) -> 9 | ... AF22: =MAX(AF10:AF12) -> 591
B23: 10.15 - 10.30 | C23: 6 | D23: 2 | E23: 6 | F23: 6 | G23: 0 | H23: 0 | I23: 3 | J23: 0 | K23: 0 | L23: 1 | M23: 77 | N23: 0 | O23: =SUM(C23:L23,N23) -> 24 | P23: =SUM(C23:N23) -> 101 | R23: IP Peak Hr | S23: =MAX(S13:S18) -> 50 | T23: =MAX(T13:T18) -> 14 | U23: =MAX(U13:U18) -> 16 | V23: =MAX(V13:V18) -> 35 | W23: =MAX(W13:W18) -> 2 | X23: =MAX(X13:X18) -> 2 | Y23: =MAX(Y13:Y18) -> 24 | Z23: =MAX(Z13:Z18) -> 8 | ... AF23: =MAX(AF13:AF18) -> 728
B24: 10.30 - 10.45 | C24: 10 | D24: 5 | E24: 2 | F24: 6 | G24: 0 | H24: 0 | I24: 6 | J24: 3 | K24: 1 | L24: 3 | M24: 119 | N24: 0 | O24: =SUM(C24:L24,N24) -> 36 | P24: =SUM(C24:N24) -> 155 | R24: PM Peak Hr | S24: =MAX(S19:S21) -> 69 | T24: =MAX(T19:T21) -> 16 | U24: =MAX(U19:U21) -> 27 | V24: =MAX(V19:V21) -> 25 | W24: =MAX(W19:W21) -> 2 | X24: =MAX(X19:X21) -> 2 | Y24: =MAX(Y19:Y21) -> 25 | Z24: =MAX(Z19:Z21) -> 8 | ... AF24: =MAX(AF19:AF21) -> 718
B25: 10.45 - 11.00 | C25: 13 | D25: 1 | E25: 2 | F25: 9 | G25: 0 | H25: 0 | I25: 4 | J25: 2 | K25: 1 | L25: 2 | M25: 139 | N25: 0 | O25: =SUM(C25:L25,N25) -> 34 | P25: =SUM(C25:N25) -> 173 | R25: AM Period | S25: =SUM(S10:S12) -> 125 | T25: =SUM(T10:T12) -> 32 | U25: =SUM(U10:U12) -> 37 | V25: =SUM(V10:V12) -> 72 | W25: =SUM(W10:W12) -> 6 | X25: =SUM(X10:X12) -> 3 | Y25: =SUM(Y10:Y12) -> 45 | Z25: =SUM(Z10:Z12) -> 21 | ... AF25: =SUM(AF10:AF12) -> 1702
B26: 11.00 - 11.15 | C26: 15 | D26: 1 | E26: 4 | F26: 3 | G26: 0 | H26: 0 | I26: 6 | J26: 1 | K26: 0 | L26: 1 | M26: 120 | N26: 0 | O26: =SUM(C26:L26,N26) -> 31 | P26: =SUM(C26:N26) -> 151 | R26: IP Period | S26: =SUM(S13:S18) -> 250 | T26: =SUM(T13:T18) -> 64 | U26: =SUM(U13:U18) -> 87 | V26: =SUM(V13:V18) -> 164 | W26: =SUM(W13:W18) -> 5 | X26: =SUM(X13:X18) -> 7 | Y26: =SUM(Y13:Y18) -> 120 | Z26: =SUM(Z13:Z18) -> 25 | ... AF26: =SUM(AF13:AF18) -> 3915
B27: 11.15 - 11.30 | C27: 8 | D27: 2 | E27: 4 | F27: 13 | G27: 0 | H27: 0 | I27: 7 | J27: 0 | K27: 0 | L27: 1 | M27: 137 | N27: 0 | O27: =SUM(C27:L27,N27) -> 35 | P27: =SUM(C27:N27) -> 172 | R27: PM Period | S27: =SUM(S19:S21) -> 187 | T27: =SUM(T19:T21) -> 38 | U27: =SUM(U19:U21) -> 60 | V27: =SUM(V19:V21) -> 63 | W27: =SUM(W19:W21) -> 2 | X27: =SUM(X19:X21) -> 3 | Y27: =SUM(Y19:Y21) -> 54 | Z27: =SUM(Z19:Z21) -> 16 | ... AF27: =SUM(AF19:AF21) -> 1923
B28: 11.30 - 11.45 | C28: 11 | D28: 5 | E28: 6 | F28: 10 | G28: 0 | H28: 0 | I28: 4 | J28: 0 | K28: 1 | L28: 0 | M28: 137 | N28: 0 | O28: =SUM(C28:L28,N28) -> 37 | P28: =SUM(C28:N28) -> 174 | R28: 12 Hours | S28: =SUM(S10:S21) -> 562 | T28: =SUM(T10:T21) -> 134 | U28: =SUM(U10:U21) -> 184 | V28: =SUM(V10:V21) -> 299 | W28: =SUM(W10:W21) -> 13 | X28: =SUM(X10:X21) -> 13 | Y28: =SUM(Y10:Y21) -> 219 | Z28: =SUM(Z10:Z21) -> 62 | ... AF28: =SUM(AF10:AF21) -> 7540
B29: 11.45 - 12.00 | C29: 1 | D29: 1 | E29: 1 | F29: 1 | G29: 0 | H29: 0 | I29: 7 | J29: 1 | K29: 0 | L29: 0 | M29: 107 | N29: 0 | O29: =SUM(C29:L29,N29) -> 12 | P29: =SUM(C29:N29) -> 119
B30: 12.00 - 12.15 | C30: 11 | D30: 4 | E30: 6 | F30: 15 | G30: 0 | H30: 0 | I30: 2 | J30: 1 | K30: 0 | L30: 0 | M30: 156 | N30: 0 | O30: =SUM(C30:L30,N30) -> 39 | P30: =SUM(C30:N30) -> 195
B31: 12.15 - 12.30 | C31: 14 | D31: 3 | E31: 5 | F31: 6 | G31: 0 | H31: 0 | I31: 5 | J31: 0 | K31: 0 | L31: 0 | M31: 136 | N31: 0 | O31: =SUM(C31:L31,N31) -> 33 | P31: =SUM(C31:N31) -> 169
B32: 12.30 - 12.45 | C32: 10 | D32: 5 | E32: 2 | F32: 3 | G32: 1 | H32: 0 | I32: 7 | J32: 1 | K32: 0 | L32: 0 | M32: 141 | N32: 0 | O32: =SUM(C32:L32,N32) -> 29 | P32: =SUM(C32:N32) -> 170
B33: 12.45 - 13.00 | C33: 15 | D33: 2 | E33: 3 | F33: 11 | G33: 0 | H33: 2 | I33: 7 | J33: 1 | K33: 0 | L33: 1 | M33: 152 | N33: 0 | O33: =SUM(C33:L33,N33) -> 42 | P33: =SUM(C33:N33) -> 194
B34: 13.00 - 13.15 | C34: 5 | D34: 3 | E34: 3 | F34: 4 | G34: 0 | H34: 2 | I34: 6 | J34: 0 | K34: 1 | L34: 0 | M34: 135 | N34: 0 | O34: =SUM(C34:L34,N34) -> 24 | P34: =SUM(C34:N34) -> 159
B35: 13.15 - 13.30 | C35: 12 | D35: 3 | E35: 4 | F35: 5 | G35: 0 | H35: 0 | I35: 2 | J35: 0 | K35: 1 | L35: 1 | M35: 147 | N35: 0 | O35: =SUM(C35:L35,N35) -> 28 | P35: =SUM(C35:N35) -> 175
B36: 13.30 - 13.45 | C36: 13 | D36: 3 | E36: 2 | F36: 9 | G36: 0 | H36: 0 | I36: 4 | J36: 1 | K36: 0 | L36: 1 | M36: 124 | N36: 0 | O36: =SUM(C36:L36,N36) -> 33 | P36: =SUM(C36:N36) -> 157
B37: 13.45 - 14.00 | C37: 12 | D37: 4 | E37: 2 | F37: 5 | G37: 0 | H37: 0 | I37: 3 | J37: 0 | K37: 0 | L37: 1 | M37: 164 | N37: 0 | O37: =SUM(C37:L37,N37) -> 27 | P37: =SUM(C37:N37) -> 191
B38: 14.00 - 14.15 | C38: 7 | D38: 0 | E38: 4 | F38: 7 | G38: 0 | H38: 1 | I38: 6 | J38: 0 | K38: 0 | L38: 0 | M38: 110 | N38: 0 | O38: =SUM(C38:L38,N38) -> 25 | P38: =SUM(C38:N38) -> 135
B39: 14.15 - 14.30 | C39: 10 | D39: 1 | E39: 5 | F39: 10 | G39: 1 | H39: 0 | I39: 3 | J39: 1 | K39: 0 | L39: 2 | M39: 133 | N39: 0 | O39: =SUM(C39:L39,N39) -> 33 | P39: =SUM(C39:N39) -> 166
B40: 14.30 - 14.45 | C40: 8 | D40: 1 | E40: 3 | F40: 4 | G40: 1 | H40: 0 | I40: 8 | J40: 2 | K40: 0 | L40: 0 | M40: 88 | N40: 0 | O40: =SUM(C40:L40,N40) -> 27 | P40: =SUM(C40:N40) -> 115
... B55: 18.15 - 18.30 | C55: 15 | D55: 4 | E55: 4 | F55: 8 | G55: 0 | H55: 2 | I55: 7 | J55: 0 | K55: 0 | L55: 1 | M55: 95 | N55: 0 | O55: =SUM(C55:L55,N55) -> 41 | P55: =SUM(C55:N55) -> 136
B56: 18.30 - 18.45 | C56: 14 | D56: 3 | E56: 4 | F56: 7 | G56: 1 | H56: 0 | I56: 3 | J56: 0 | M56: 103 | N56: 0 | O56: =SUM(C56:L56,N56) -> 32 | P56: =SUM(C56:N56) -> 135
...

Sheet 26.10 Kasese-Fort Portal-24h
B1: Consultancy services for Preparation of Expressway Development Master Plan (EDMP) for Uganda
B2: MANUAL CLASSIFIED COUNT (MCC)
B3: ROAD NAME: | C3: ='25.10 Kasese-Fort Portal'!C3:G3 -> MCC - C4 - STN106
C5: Date | D5: 26.10.19 | F5: Location | G5: ='30.10 Fort Portal-Kasese'!G5:H5 -> Kisanga B | J5: Surveyor | K5: ='30.10 Fort Portal-Kasese'!K5:L5 -> Onyuti Betty
C6: Dir. From | D6: ='25.10 Kasese-Fort Portal'!D6:E6 -> Kasese | F6: Dir. To | G6: ='25.10 Kasese-Fort Portal'!G6:H6 -> Fort Portal | J6: Supervisor | K6: ='30.10 Fort Portal-Kasese'!K6:L6 -> Onyuti Betty
B8: Time / Veh Type | R8: SUMMARY TRAFFIC VOLUMES
C9: 1. Car | D9: 2. Station Wagon | E9: 3. Pickups | F9: 4. Minibus, matatu | G9: 5. Medium bus | H9: 6. Large Bus | I9: 7. Light Truck | J9: 8. Medium Truck | K9: 9. Heavy truck | L9: 10. Truck Trailer | M9: 11. Motor cycles | N9: 12. Tractors | O9: Total Excl M/Cycles | P9: Total All | R9: Time | S9: 1. Car | T9: 2. Station Wagon | U9: 3. Pickups | V9: 4. Minibus, matatu | W9: 5. Medium bus | X9: 6. Large Bus | Y9: 7. Light Truck | Z9: 8. Medium Truck | AA9: 9. Heavy truck | AB9: 10. Truck Trailer | AC9: 11. Motorcycles | AD9: 12. Tractors, Graders | AE9: Total Excl M/ Cycles | AF9: Total All
B10: 07.00 - 07.15 | C10: 6 | D10: 0 | E10: 0 | F10: 5 | G10: 0 | H10: 1 | I10: 0 | J10: 2 | K10: 0 | L10: 1 | M10: 9 | N10: 0 | O10: =SUM(C10:L10,N10) -> 15 | P10: =SUM(C10:N10) -> 24 | R10: 0700-0800 | S10: =SUM(C10:C13) -> 25 | T10: =SUM(D10:D13) -> 0 | U10: =SUM(E10:E13) -> 6 | V10: =SUM(F10:F13) -> 17 | W10: =SUM(G10:G13) -> 0 | X10: =SUM(H10:H13) -> 1 | Y10: =SUM(I10:I13) -> 0 | Z10: =SUM(J10:J13) -> 2 | ... AF10: =SUM(P10:P13) -> 133
B11: 07.15 - 07.30 | C11: 7 | D11: 0 | E11: 2 | F11: 4 | G11: 0 | H11: 0 | I11: 0 | J11: 0 | K11: 0 | L11: 0 | M11: 17 | N11: 0 | O11: =SUM(C11:L11,N11) -> 13 | P11: =SUM(C11:N11) -> 30 | R11: 0800-0900 | S11: =SUM(C14:C17) -> 17 | T11: =SUM(D14:D17) -> 8 | U11: =SUM(E14:E17) -> 5 | V11: =SUM(F14:F17) -> 16 | W11: =SUM(G14:G17) -> 0 | X11: =SUM(H14:H17) -> 1 | Y11: =SUM(I14:I17) -> 4 | Z11: =SUM(J14:J17) -> 2 | ... AF11: =SUM(P14:P17) -> 112
B12: 07.30 - 07.45 | C12: 5 | D12: 0 | E12: 2 | F12: 4 | G12: 0 | H12: 0 | I12: 0 | J12: 0 | K12: 0 | L12: 0 | M12: 23 | N12: 0 | O12: =SUM(C12:L12,N12) -> 11 | P12: =SUM(C12:N12) -> 34 | R12: 0900-1000 | S12: =SUM(C18:C21) -> 15 | T12: =SUM(D18:D21) -> 4 | U12: =SUM(E18:E21) -> 5 | V12: =SUM(F18:F21) -> 13 | W12: =SUM(G18:G21) -> 2 | X12: =SUM(H18:H21) -> 1 | Y12: =SUM(I18:I21) -> 2 | Z12: =SUM(J18:J21) -> 2 | ... AF12: =SUM(P18:P21) -> 135
B13: 07.45 - 08.00 | C13: 7 | D13: 0 | E13: 2 | F13: 4 | G13: 0 | H13: 0 | I13: 0 | J13: 0 | K13: 0 | L13: 0 | M13: 32 | N13: 0 | O13: =SUM(C13:L13,N13) -> 13 | P13: =SUM(C13:N13) -> 45 | R13: 1000-1100 | S13: =SUM(C22:C25) -> 17 | T13: =SUM(D22:D25) -> 2 | U13: =SUM(E22:E25) -> 4 | V13: =SUM(F22:F25) -> 12 | W13: =SUM(G22:G25) -> 1 | X13: =SUM(H22:H25) -> 3 | Y13: =SUM(I22:I25) -> 5 | Z13: =SUM(J22:J25) -> 3 | ... AF13: =SUM(P22:P25) -> 259
B14: 08.00 - 08.15 | C14: 6 | D14: 1 | E14: 1 | F14: 0 | G14: 0 | H14: 0 | I14: 0 | J14: 1 | K14: 0 | L14: 0 | M14: 28 | N14: 0 | O14: =SUM(C14:L14,N14) -> 9 | P14: =SUM(C14:N14) -> 37 | R14: 1100-1200 | S14: =SUM(C26:C29) -> 42 | T14: =SUM(D26:D29) -> 15 | U14: =SUM(E26:E29) -> 8 | V14: =SUM(F26:F29) -> 22 | W14: =SUM(G26:G29) -> 2 | X14: =SUM(H26:H29) -> 2 | Y14: =SUM(I26:I29) -> 8 | Z14: =SUM(J26:J29) -> 5 | ... AF14: =SUM(P26:P29) -> 626
B15: 08.15 - 08.30 | C15: 7 | D15: 4 | E15: 3 | F15: 8 | G15: 0 | H15: 1 | I15: 1 | J15: 0 | K15: 0 | L15: 1 | M15: 13 | N15: 0 | O15: =SUM(C15:L15,N15) -> 25 | P15: =SUM(C15:N15) -> 38 | R15: 1200-1300 | S15: =SUM(C30:C33) -> 34 | T15: =SUM(D30:D33) -> 10 | U15: =SUM(E30:E33) -> 7 | V15: =SUM(F30:F33) -> 32 | W15: =SUM(G30:G33) -> 3 | X15: =SUM(H30:H33) -> 0 | Y15: =SUM(I30:I33) -> 9 | Z15: =SUM(J30:J33) -> 10 | ... AF15: =SUM(P30:P33) -> 661
B16: 08.30 - 08.45 | C16: 1 | D16: 2 | E16: 1 | F16: 4 | G16: 0 | H16: 0 | I16: 0 | J16: 0 | K16: 0 | L16: 0 | M16: 13 | N16: 0 | O16: =SUM(C16:L16,N16) -> 8 | P16: =SUM(C16:N16) -> 21 | R16: 1300-1400 | S16: =SUM(C34:C37) -> 36 | T16: =SUM(D34:D37) -> 9 | U16: =SUM(E34:E37) -> 15 | V16: =SUM(F34:F37) -> 17 | W16: =SUM(G34:G37) -> 0 | X16: =SUM(H34:H37) -> 1 | Y16: =SUM(I34:I37) -> 8 | Z16: =SUM(J34:J37) -> 6 | ... AF16: =SUM(P34:P37) -> 672
B17: 08.45 - 9.00 | C17: 3 | D17: 1 | E17: 0 | F17: 4 | G17: 0 | H17: 0 | I17: 3 | J17: 1 | K17: 0 | L17: 0 | M17: 4 | N17: 0 | O17: =SUM(C17:L17,N17) -> 12 | P17: =SUM(C17:N17) -> 16 | R17: 1400-1500 | S17: =SUM(C38:C41) -> 37 | T17: =SUM(D38:D41) -> 9 | U17: =SUM(E38:E41) -> 7 | V17: =SUM(F38:F41) -> 10 | W17: =SUM(G38:G41) -> 0 | X17: =SUM(H38:H41) -> 2 | Y17: =SUM(I38:I41) -> 5 | Z17: =SUM(J38:J41) -> 4 | ... AF17: =SUM(P38:P41) -> 670
B18: 09.00 - 09.15 | C18: 5 | D18: 1 | E18: 1 | F18: 4 | G18: 1 | H18: 0 | I18: 1 | J18: 1 | K18: 1 | L18: 2 | M18: 19 | N18: 0 | O18: =SUM(C18:L18,N18) -> 17 | P18: =SUM(C18:N18) -> 36 | R18: 1500-1600 | S18: =SUM(C42:C45) -> 33 | T18: =SUM(D42:D45) -> 6 | U18: =SUM(E42:E45) -> 8 | V18: =SUM(F42:F45) -> 24 | W18: =SUM(G42:G45) -> 1 | X18: =SUM(H42:H45) -> 0 | Y18: =SUM(I42:I45) -> 5 | Z18: =SUM(J42:J45) -> 7 | ... AF18: =SUM(P42:P45) -> 393
B19: 09.15 - 09.30 | C19: 2 | D19: 0 | E19: 1 | F19: 1 | G19: 0 | H19: 0 | I19: 0 | J19: 0 | K19: 0 | L19: 0 | M19: 11 | N19: 0 | O19: =SUM(C19:L19,N19) -> 4 | P19: =SUM(C19:N19) -> 15 | R19: 1600-1700 | S19: =SUM(C46:C49) -> 31 | T19: =SUM(D46:D49) -> 8 | U19: =SUM(E46:E49) -> 15 | V19: =SUM(F46:F49) -> 17 | W19: =SUM(G46:G49) -> 1 | X19: =SUM(H46:H49) -> 3 | Y19: =SUM(I46:I49) -> 11 | Z19: =SUM(J46:J49) -> 0 | ... AF19: =SUM(P46:P49) -> 632
B20: 09.30 - 09.45 | C20: 5 | D20: 1 | E20: 2 | F20: 3 | G20: 1 | H20: 0 | I20: 1 | J20: 0 | K20: 0 | L20: 0 | M20: 13 | N20: 0 | O20: =SUM(C20:L20,N20) -> 13 | P20: =SUM(C20:N20) -> 26 | R20: 1700-1800 | S20: =SUM(C50:C53) -> 36 | T20: =SUM(D50:D53) -> 7 | U20: =SUM(E50:E53) -> 12 | V20: =SUM(F50:F53) -> 25 | W20: =SUM(G50:G53) -> 1 | X20: =SUM(H50:H53) -> 1 | Y20: =SUM(I50:I53) -> 17 | Z20: =SUM(J50:J53) -> 2 | ... AF20: =SUM(P50:P53) -> 644
B21: 09.45 - 10.00 | C21: 3 | D21: 2 | E21: 1 | F21: 5 | G21: 0 | H21: 1 | I21: 0 | J21: 1 | K21: 0 | L21: 0 | M21: 45 | N21: 0 | O21: =SUM(C21:L21,N21) -> 13 | P21: =SUM(C21:N21) -> 58 | R21: 1800-1900 | S21: =SUM(C54:C57) -> 37 | T21: =SUM(D54:D57) -> 8 | U21: =SUM(E54:E57) -> 14 | V21: =SUM(F54:F57) -> 16 | W21: =SUM(G54:G57) -> 1 | X21: =SUM(H54:H57) -> 0 | Y21: =SUM(I54:I57) -> 13 | Z21: =SUM(J54:J57) -> 1 | ... AF21: =SUM(P54:P57) -> 647
B22: 10.00 - 10.15 | C22: 6 | D22: 0 | E22: 0 | F22: 0 | G22: 0 | H22: 0 | I22: 0 | J22: 0 | K22: 0 | L22: 0 | M22: 39 | N22: 0 | O22: =SUM(C22:L22,N22) -> 6 | P22: =SUM(C22:N22) -> 45 | R22: 1900-2000 | S22: =SUM(C58:C61) -> 49 | T22: =SUM(D58:D61) -> 3 | U22: =SUM(E58:E61) -> 8 | V22: =SUM(F58:F61) -> 16 | W22: =SUM(G58:G61) -> 0 | X22: =SUM(H58:H61) -> 2 | Y22: =SUM(I58:I61) -> 10 | Z22: =SUM(J58:J61) -> 1 | ... AF22: =SUM(P58:P61) -> 588
B23: 10.15 - 10.30 | C23: 2 | D23: 1 | E23: 1 | F23: 4 | G23: 0 | H23: 1 | I23: 0 | J23: 0 | K23: 0 | L23: 0 | M23: 39 | N23: 0 | O23: =SUM(C23:L23,N23) -> 9 | P23: =SUM(C23:N23) -> 48 | R23: 2000-2100 | S23: =SUM(C62:C65) -> 50 | T23: =SUM(D62:D65) -> 3 | U23: =SUM(E62:E65) -> 7 | V23: =SUM(F62:F65) -> 16 | W23: =SUM(G62:G65) -> 1 | X23: =SUM(H62:H65) -> 1 | Y23: =SUM(I62:I65) -> 6 | Z23: =SUM(J62:J65) -> 3 | ... AF23: =SUM(P62:P65) -> 373
B24: 10.30 - 10.45 | C24: 2 | D24: 1 | E24: 1 | F24: 6 | G24: 0 | H24: 1 | I24: 3 | J24: 1 | K24: 0 | L24: 0 | M24: 60 | N24: 0 | O24: =SUM(C24:L24,N24) -> 15 | P24: =SUM(C24:N24) -> 75 | R24: 2100-2200 | S24: =SUM(C66:C69) -> 36 | T24: =SUM(D66:D69) -> 1 | U24: =SUM(E66:E69) -> 6 | V24: =SUM(F66:F69) -> 14 | W24: =SUM(G66:G69) -> 0 | X24: =SUM(H66:H69) -> 2 | Y24: =SUM(I66:I69) -> 10 | Z24: =SUM(J66:J69) -> 0 | ... AF24: =SUM(P66:P69) -> 275
B25: 10.45 - 11.00 | C25: 7 | D25: 0 | E25: 2 | F25: 2 | G25: 1 | H25: 1 | I25: 2 | J25: 2 | K25: 0 | L25: 0 | M25: 74 | N25: 0 | O25: =SUM(C25:L25,N25) -> 17 | P25: =SUM(C25:N25) -> 91 | R25: 2200-2300 | S25: =SUM(C70:C73) -> 26 | T25: =SUM(D70:D73) -> 2 | U25: =SUM(E70:E73) -> 3 | V25: =SUM(F70:F73) -> 3 | W25: =SUM(G70:G73) -> 0 | X25: =SUM(H70:H73) -> 2 | Y25: =SUM(I70:I73) -> 5 | Z25: =SUM(J70:J73) -> 2 | ... AF25: =SUM(P70:P73) -> 188
B26: 11.00 - 11.15 | C26: 12 | D26: 2 | E26: 4 | F26: 12 | G26: 0 | H26: 0 | I26: 6 | J26: 1 | K26: 2 | L26: 1 | M26: 106 | N26: 0 | O26: =SUM(C26:L26,N26) -> 40 | P26: =SUM(C26:N26) -> 146 | R26: 2300-0000 | S26: =SUM(C74:C77) -> 17 | T26: =SUM(D74:D77) -> 0 | U26: =SUM(E74:E77) -> 1 | V26: =SUM(F74:F77) -> 3 | W26: =SUM(G74:G77) -> 0 | X26: =SUM(H74:H77) -> 0 | Y26: =SUM(I74:I77) -> 2 | Z26: =SUM(J74:J77) -> 0 | ... AF26: =SUM(P74:P77) -> 109
B27: 11.15 - 11.30 | C27: 10 | D27: 5 | E27: 0 | F27: 2 | G27: 0 | H27: 0 | I27: 0 | J27: 1 | K27: 0 | L27: 0 | M27: 111 | N27: 0 | O27: =SUM(C27:L27,N27) -> 18 | P27: =SUM(C27:N27) -> 129 | R27: 0000-0100 | S27: =SUM(C78:C81) -> 4 | T27: =SUM(D78:D81) -> 1 | U27: =SUM(E78:E81) -> 1 | V27: =SUM(F78:F81) -> 0 | W27: =SUM(G78:G81) -> 0 | X27: =SUM(H78:H81) -> 1 | Y27: =SUM(I78:I81) -> 1 | Z27: =SUM(J78:J81) -> 0 | ... AF27: =SUM(P78:P81) -> 69
B28: 11.30 - 11.45 | C28: 5 | D28: 2 | E28: 4 | F28: 3 | G28: 0 | H28: 1 | I28: 0 | J28: 1 | K28: 0 | L28: 1 | M28: 135 | N28: 0 | O28: =SUM(C28:L28,N28) -> 17 | P28: =SUM(C28:N28) -> 152 | R28: 0100-0200 | S28: =SUM(C82:C85) -> 8 | T28: =SUM(D82:D85) -> 0 | U28: =SUM(E82:E85) -> 0 | V28: =SUM(F82:F85) -> 0 | W28: =SUM(G82:G85) -> 0 | X28: =SUM(H82:H85) -> 0 | Y28: =SUM(I82:I85) -> 0 | Z28: =SUM(J82:J85) -> 1 | ... AF28: =SUM(P82:P85) -> 49
B29: 11.45 - 12.00 | C29: 15 | D29: 6 | E29: 0 | F29: 5 | G29: 2 | H29: 1 | I29: 2 | J29: 2 | K29: 0 | L29: 1 | M29: 165 | N29: 0 | O29: =SUM(C29:L29,N29) -> 34 | P29: =SUM(C29:N29) -> 199 | R29: 0200-0300 | S29: =SUM(C86:C89) -> 3 | T29: =SUM(D86:D89) -> 0 | U29: =SUM(E86:E89) -> 1 | V29: =SUM(F86:F89) -> 0 | W29: =SUM(G86:G89) -> 0 | X29: =SUM(H86:H89) -> 0 | Y29: =SUM(I86:I89) -> 1 | Z29: =SUM(J86:J89) -> 0 | ... AF29: =SUM(P86:P89) -> 40
B30: 12.00 - 12.15 | C30: 9 | D30: 4 | E30: 2 | F30: 7 | G30: 1 | H30: 0 | I30: 2 | J30: 4 | K30: 1 | L30: 0 | M30: 210 | N30: 0 | O30: =SUM(C30:L30,N30) -> 30 | P30: =SUM(C30:N30) -> 240 | R30: 0300-0400 | S30: =SUM(C90:C93) -> 4 | T30: =SUM(D90:D93) -> 0 | U30: =SUM(E90:E93) -> 0 | V30: =SUM(F90:F93) -> 2 | W30: =SUM(G90:G93) -> 0 | X30: =SUM(H90:H93) -> 0 | Y30: =SUM(I90:I93) -> 1 | Z30: =SUM(J90:J93) -> 0 | ... AF30: =SUM(P90:P93) -> 39
B31: 12.15 - 12.30 | C31: 5 | D31: 2 | E31: 1 | F31: 9 | G31: 1 | H31: 0 | I31: 2 | J31: 1 | K31: 0 | L31: 0 | M31: 128 | N31: 0 | O31: =SUM(C31:L31,N31) -> 21 | P31: =SUM(C31:N31) -> 149 | R31: 0400-0500 | S31: =SUM(C94:C97) -> 3 | T31: =SUM(D94:D97) -> 1 | U31: =SUM(E94:E97) -> 0 | V31: =SUM(F94:F97) -> 0 | W31: =SUM(G94:G97) -> 0 | X31: =SUM(H94:H97) -> 0 | Y31: =SUM(I94:I97) -> 0 | Z31: =SUM(J94:J97) -> 0 | ... AF31: =SUM(P94:P97) -> 34
B32: 12.30 - 12.45 | C32: 6 | D32: 2 | E32: 1 | F32: 8 | G32: 1 | H32: 0 | I32: 5 | J32: 4 | K32: 0 | L32: 1 | M32: 104 | N32: 0 | O32: =SUM(C32:L32,N32) -> 28 | P32: =SUM(C32:N32) -> 132 | R32: 0500-0600 | S32: =SUM(C98:C101) -> 7 | T32: =SUM(D98:D101) -> 0 | U32: =SUM(E98:E101) -> 0 | V32: =SUM(F98:F101) -> 1 | W32: =SUM(G98:G101) -> 0 | X32: =SUM(H98:H101) -> 1 | Y32: =SUM(I98:I101) -> 0 | Z32: =SUM(J98:J101) -> 0 | ... AF32: =SUM(P98:P101) -> 52
B33: 12.45 - 13.00 | C33: 14 | D33: 2 | E33: 3 | F33: 8 | G33: 0 | H33: 0 | I33: 0 | J33: 1 | K33: 0 | L33: 0 | M33: 112 | N33: 0 | O33: =SUM(C33:L33,N33) -> 28 | P33: =SUM(C33:N33) -> 140 | R33: 0600-0700 | S33: =SUM(C102:C105) -> 9 | T33: =SUM(D102:D105) -> 1 | U33: =SUM(E102:E105) -> 3 | V33: =SUM(F102:F105) -> 3 | W33: =SUM(G102:G105) -> 0 | X33: =SUM(H102:H105) -> 3 | Y33: =SUM(I102:I105) -> 6 | Z33: =SUM(J102:J105) -> 1 | ... AF33: =SUM(P102:P105) -> 108
B34: 13.00 - 13.15 | C34: 9 | D34: 3 | E34: 3 | F34: 8 | G34: 0 | H34: 1 | I34: 1 | J34: 1 | K34: 0 | L34: 0 | M34: 131 | N34: 0 | O34: =SUM(C34:L34,N34) -> 26 | P34: =SUM(C34:N34) -> 157 | R34: AM Peak Hr | S34: =MAX(S10:S12) -> 25 | T34: =MAX(T10:T12) -> 8 | U34: =MAX(U10:U12) -> 6 | V34: =MAX(V10:V12) -> 17 | W34: =MAX(W10:W12) -> 2 | X34: =MAX(X10:X12) -> 1 | Y34: =MAX(Y10:Y12) -> 4 | Z34: =MAX(Z10:Z12) -> 2 | ... AF34: =MAX(AF10:AF12) -> 135
B35: 13.15 - 13.30 | C35: 5 | D35: 4 | E35: 3 | F35: 2 | G35: 0 | H35: 0 | I35: 5 | J35: 1 | K35: 0 | L35: 0 | M35: 130 | N35: 0 | O35: =SUM(C35:L35,N35) -> 20 | P35: =SUM(C35:N35) -> 150 | R35: IP Peak Hr | S35: =MAX(S13:S18) -> 42 | T35: =MAX(T13:T18) -> 15 | U35: =MAX(U13:U18) -> 15 | V35: =MAX(V13:V18) -> 32 | W35: =MAX(W13:W18) -> 3 | X35: =MAX(X13:X18) -> 3 | Y35: =MAX(Y13:Y18) -> 9 | Z35: =MAX(Z13:Z18) -> 10 | ... AF35: =MAX(AF13:AF18) -> 672
B36: 13.30 - 13.45 | C36: 8 | D36: 1 | E36: 4 | F36: 4 | G36: 0 | H36: 0 | I36: 1 | J36: 1 | K36: 0 | L36: 0 | M36: 148 | N36: 0 | O36: =SUM(C36:L36,N36) -> 19 | P36: =SUM(C36:N36) -> 167 | R36: PM Peak Hr | S36: =MAX(S19:S21) -> 37 | T36: =MAX(T19:T21) -> 8 | U36: =MAX(U19:U21) -> 15 | V36: =MAX(V19:V21) -> 25 | W36: =MAX(W19:W21) -> 1 | X36: =MAX(X19:X21) -> 3 | Y36: =MAX(Y19:Y21) -> 17 | Z36: =MAX(Z19:Z21) -> 2 | ... AF36: =MAX(AF19:AF21) -> 647
B37: 13.45 - 14.00 | C37: 14 | D37: 1 | E37: 5 | F37: 3 | G37: 0 | H37: 0 | I37: 1 | J37: 3 | K37: 0 | L37: 1 | M37: 170 | N37: 0 | O37: =SUM(C37:L37,N37) -> 28 | P37: =SUM(C37:N37) -> 198 | R37: AM Period | S37: =SUM(S10:S12) -> 57 | T37: =SUM(T10:T12) -> 12 | U37: =SUM(U10:U12) -> 16 | V37: =SUM(V10:V12) -> 46 | W37: =SUM(W10:W12) -> 2 | X37: =SUM(X10:X12) -> 3 | Y37: =SUM(Y10:Y12) -> 6 | Z37: =SUM(Z10:Z12) -> 6 | ... AF37: =SUM(AF10:AF12) -> 380
B38: 14.00 - 14.15 | C38: 9 | D38: 2 | E38: 0 | F38: 1 | G38: 0 | H38: 0 | I38: 1 | J38: 0 | K38: 0 | L38: 0 | M38: 170 | N38: 0 | O38: =SUM(C38:L38,N38) -> 13 | P38: =SUM(C38:N38) -> 183 | R38: IP Period | S38: =SUM(S13:S18) -> 199 | T38: =SUM(T13:T18) -> 51 | U38: =SUM(U13:U18) -> 49 | V38: =SUM(V13:V18) -> 117 | W38: =SUM(W13:W18) -> 7 | X38: =SUM(X13:X18) -> 8 | Y38: =SUM(Y13:Y18) -> 40 | Z38: =SUM(Z13:Z18) -> 35 | ... AF38: =SUM(AF13:AF18) -> 3281
B39: 14.15 - 14.30 | C39: 12 | D39: 4 | E39: 5 | F39: 4 | G39: 0 | H39: 1 | I39: 2 | J39: 0 | K39: 1 | L39: 0 | M39: 140 | N39: 0 | O39: =SUM(C39:L39,N39) -> 29 | P39: =SUM(C39:N39) -> 169 | R39: PM Period | S39: =SUM(S19:S21) -> 104 | T39: =SUM(T19:T21) -> 23 | U39: =SUM(U19:U21) -> 41 | V39: =SUM(V19:V21) -> 58 | W39: =SUM(W19:W21) -> 3 | X39: =SUM(X19:X21) -> 4 | Y39: =SUM(Y19:Y21) -> 41 | Z39: =SUM(Z19:Z21) -> 3 | ... AF39: =SUM(AF19:AF21) -> 1923
B40: 14.30 - 14.45 | C40: 1 | D40: 2 | E40: 1 | F40: 4 | G40: 0 | H40: 1 | I40: 1 | J40: 2 | K40: 0 | L40: 0 | M40: 145 | N40: 0 | O40: =SUM(C40:L40,N40) -> 12 | P40: =SUM(C40:N40) -> 157 | R40: 12 Hours | S40: =SUM(S10:S21) -> 360 | T40: =SUM(T10:T21) -> 86 | U40: =SUM(U10:U21) -> 106 | V40: =SUM(V10:V21) -> 221 | W40: =SUM(W10:W21) -> 12 | X40: =SUM(X10:X21) -> 15 | Y40: =SUM(Y10:Y21) -> 87 | Z40: =SUM(Z10:Z21) -> 44 | ... AF40: =SUM(AF10:AF21) -> 5584
B41: 14.45 - 15.00 | C41: 15 | D41: 1 | E41: 1 | F41: 1 | G41: 0 | H41: 0 | I41: 1 | J41: 2 | K41: 0 | L41: 0 | M41: 140 | N41: 0 | O41: =SUM(C41:L41,N41) -> 21 | P41: =SUM(C41:N41) -> 161 | R41: 24 Hrs/ADT | S41: =SUM(S10:S33) -> 576 | T41: =SUM(T10:T33) -> 98 | U41: =SUM(U10:U33) -> 136 | V41: =SUM(V10:V33) -> 279 | W41: =SUM(W10:W33) -> 13 | X41: =SUM(X10:X33) -> 27 | Y41: =SUM(Y10:Y33) -> 129 | Z41: =SUM(Z10:Z33) -> 52 | ... AF41: =SUM(AF10:AF33) -> 7508
B42: 15.00 - 15.15 | C42: 11 | D42: 3 | E42: 0 | F42: 8 | G42: 1 | H42: 0 | I42: 0 | J42: 2 | K42: 0 | L42: 0 | M42: 77 | N42: 0 | O42: =SUM(C42:L42,N42) -> 25 | P42: =SUM(C42:N42) -> 102 | R42: NEF | S42: =S41/S40 -> 1.6 | T42: =T41/T40 -> 1.1395349 | U42: =U41/U40 -> 1.2830189 | V42: =V41/V40 -> 1.2624434 | W42: =W41/W40 -> 1.0833333 | X42: =X41/X40 -> 1.8 | Y42: =Y41/Y40 -> 1.4827586 | Z42: =Z41/Z40 -> 1.1818182 | ... AF42: =AF41/AF40 -> 1.3445559
...

Sheet 26.10 Fort Portal-Kasese-24h
B1: Consultancy services for Preparation of Expressway Development Master Plan (EDMP) for Uganda
B2: MANUAL CLASSIFIED COUNT (MCC)
B3: ROAD NAME: | C3: ='25.10 Kasese-Fort Portal'!C3:G3 -> MCC - C4 - STN106
C5: Date | D5: ='26.10 Kasese-Fort Portal-24h'!D5 -> 26.10.19 | F5: Location | G5: ='26.10 Kasese-Fort Portal-24h'!G5:H5 -> Kisanga B | J5: Surveyor | K5: ='26.10 Kasese-Fort Portal-24h'!K5:L5 -> Onyuti Betty
C6: Dir. From | D6: ='25.10 Fort Portal-Kasese'!D6:E6 -> Fort Portal | F6: Dir. To | G6: ='27.10 Fort Portal-Kasese'!G6:H6 -> Kasese | J6: Supervisor | K6: ='26.10 Kasese-Fort Portal-24h'!K6:L6 -> Onyuti Betty
B8: Time / Veh Type | R8: SUMMARY TRAFFIC VOLUMES
C9: 1. Car | D9: 2. Station Wagon | E9: 3. Pickups | F9: 4. Minibus, matatu | G9: 5. Medium bus | H9: 6. Large Bus | I9: 7. Light Truck | J9: 8. Medium Truck | K9: 9. Heavy truck | L9: 10. Truck Trailer | M9: 11. Motor cycles | N9: 12. Tractors | O9: Total Excl M/Cycles | P9: Total All | R9: Time | S9: 1. Car | T9: 2. Station Wagon | U9: 3. Pickups | V9: 4. Minibus, matatu | W9: 5. Medium bus | X9: 6. Large Bus | Y9: 7. Light Truck | Z9: 8. Medium Truck | AA9: 9. Heavy truck | AB9: 10. Truck Trailer | AC9: 11. Motorcycles | AD9: 12. Tractors, Graders | AE9: Total Excl M/ Cycles | AF9: Total All
B10: 07.00 - 07.15 | C10: 2 | D10: 0 | E10: 0 | F10: 4 | G10: 0 | H10: 0 | I10: 2 | J10: 1 | K10: 0 | L10: 0 | M10: 12 | N10: 0 | O10: =SUM(C10:L10,N10) -> 9 | P10: =SUM(C10:N10) -> 21 | R10: 0700-0800 | S10: =SUM(C10:C13) -> 26 | T10: =SUM(D10:D13) -> 3 | U10: =SUM(E10:E13) -> 4 | V10: =SUM(F10:F13) -> 12 | W10: =SUM(G10:G13) -> 0 | X10: =SUM(H10:H13) -> 0 | Y10: =SUM(I10:I13) -> 12 | Z10: =SUM(J10:J13) -> 3 | ... AF10: =SUM(P10:P13) -> 158
B11: 07.15 - 07.30 | C11: 6 | D11: 0 | E11: 0 | F11: 2 | G11: 0 | H11: 0 | I11: 3 | J11: 2 | K11: 0 | L11: 0 | M11: 24 | N11: 0 | O11: =SUM(C11:L11,N11) -> 13 | P11: =SUM(C11:N11) -> 37 | R11: 0800-0900 | S11: =SUM(C14:C17) -> 29 | T11: =SUM(D14:D17) -> 15 | U11: =SUM(E14:E17) -> 4 | V11: =SUM(F14:F17) -> 19 | W11: =SUM(G14:G17) -> 1 | X11: =SUM(H14:H17) -> 0 | Y11: =SUM(I14:I17) -> 6 | Z11: =SUM(J14:J17) -> 3 | ... AF11: =SUM(P14:P17) -> 143
B12: 07.30 - 07.45 | C12: 7 | D12: 2 | E12: 2 | F12: 3 | G12: 0 | H12: 0 | I12: 4 | J12: 0 | K12: 0 | L12: 1 | M12: 22 | N12: 0 | O12: =SUM(C12:L12,N12) -> 19 | P12: =SUM(C12:N12) -> 41 | R12: 0900-1000 | S12: =SUM(C18:C21) -> 39 | T12: =SUM(D18:D21) -> 16 | U12: =SUM(E18:E21) -> 5 | V12: =SUM(F18:F21) -> 2 | W12: =SUM(G18:G21) -> 1 | X12: =SUM(H18:H21) -> 2 | Y12: =SUM(I18:I21) -> 3 | Z12: =SUM(J18:J21) -> 3 | ... AF12: =SUM(P18:P21) -> 176
B13: 07.45 - 08.00 | C13: 11 | D13: 1 | E13: 2 | F13: 3 | G13: 0 | H13: 0 | I13: 3 | J13: 0 | K13: 0 | L13: 0 | M13: 39 | N13: 0 | O13: =SUM(C13:L13,N13) -> 20 | P13: =SUM(C13:N13) -> 59 | R13: 1000-1100 | S13: =SUM(C22:C25) -> 50 | T13: =SUM(D22:D25) -> 13 | U13: =SUM(E22:E25) -> 10 | V13: =SUM(F22:F25) -> 22 | W13: =SUM(G22:G25) -> 1 | X13: =SUM(H22:H25) -> 0 | Y13: =SUM(I22:I25) -> 10 | Z13: =SUM(J22:J25) -> 0 | ... AF13: =SUM(P22:P25) -> 428
B14: 08.00 - 08.15 | C14: 14 | D14: 4 | E14: 0 | F14: 5 | G14: 1 | H14: 0 | I14: 2 | J14: 2 | K14: 0 | L14: 0 | M14: 31 | N14: 0 | O14: =SUM(C14:L14,N14) -> 28 | P14: =SUM(C14:N14) -> 59 | R14: 1100-1200 | S14: =SUM(C26:C29) -> 57 | T14: =SUM(D26:D29) -> 14 | U14: =SUM(E26:E29) -> 17 | V14: =SUM(F26:F29) -> 27 | W14: =SUM(G26:G29) -> 0 | X14: =SUM(H26:H29) -> 1 | Y14: =SUM(I26:I29) -> 12 | Z14: =SUM(J26:J29) -> 2 | ... AF14: =SUM(P26:P29) -> 708
B15: 08.15 - 08.30 | C15: 7 | D15: 6 | E15: 0 | F15: 2 | G15: 0 | H15: 0 | I15: 1 | J15: 0 | K15: 0 | L15: 0 | M15: 15 | N15: 0 | O15: =SUM(C15:L15,N15) -> 16 | P15: =SUM(C15:N15) -> 31 | R15: 1200-1300 | S15: =SUM(C30:C33) -> 31 | T15: =SUM(D30:D33) -> 17 | U15: =SUM(E30:E33) -> 15 | V15: =SUM(F30:F33) -> 26 | W15: =SUM(G30:G33) -> 1 | X15: =SUM(H30:H33) -> 1 | Y15: =SUM(I30:I33) -> 5 | Z15: =SUM(J30:J33) -> 2 | ... AF15: =SUM(P30:P33) -> 617
B16: 08.30 - 08.45 | C16: 7 | D16: 3 | E16: 2 | F16: 7 | G16: 0 | H16: 0 | I16: 2 | J16: 1 | K16: 0 | L16: 0 | M16: 10 | N16: 0 | O16: =SUM(C16:L16,N16) -> 22 | P16: =SUM(C16:N16) -> 32 | R16: 1300-1400 | S16: =SUM(C34:C37) -> 42 | T16: =SUM(D34:D37) -> 12 | U16: =SUM(E34:E37) -> 10 | V16: =SUM(F34:F37) -> 17 | W16: =SUM(G34:G37) -> 4 | X16: =SUM(H34:H37) -> 1 | Y16: =SUM(I34:I37) -> 11 | Z16: =SUM(J34:J37) -> 3 | ... AF16: =SUM(P34:P37) -> 603
B17: 08.45 - 9.00 | C17: 1 | D17: 2 | E17: 2 | F17: 5 | G17: 0 | H17: 0 | I17: 1 | J17: 0 | K17: 0 | L17: 1 | M17: 9 | N17: 0 | O17: =SUM(C17:L17,N17) -> 12 | P17: =SUM(C17:N17) -> 21 | R17: 1400-1500 | S17: =SUM(C38:C41) -> 26 | T17: =SUM(D38:D41) -> 14 | U17: =SUM(E38:E41) -> 13 | V17: =SUM(F38:F41) -> 9 | W17: =SUM(G38:G41) -> 0 | X17: =SUM(H38:H41) -> 2 | Y17: =SUM(I38:I41) -> 6 | Z17: =SUM(J38:J41) -> 1 | ... AF17: =SUM(P38:P41) -> 575
B18: 09.00 - 09.15 | C18: 7 | D18: 5 | E18: 1 | F18: 1 | G18: 0 | H18: 0 | I18: 1 | J18: 1 | K18: 0 | L18: 1 | M18: 20 | N18: 0 | O18: =SUM(C18:L18,N18) -> 17 | P18: =SUM(C18:N18) -> 37 | R18: 1500-1600 | S18: =SUM(C42:C45) -> 44 | T18: =SUM(D42:D45) -> 7 | U18: =SUM(E42:E45) -> 13 | V18: =SUM(F42:F45) -> 15 | W18: =SUM(G42:G45) -> 1 | X18: =SUM(H42:H45) -> 1 | Y18: =SUM(I42:I45) -> 11 | Z18: =SUM(J42:J45) -> 1 | ... AF18: =SUM(P42:P45) -> 476
B19: 09.15 - 09.30 | C19: 3 | D19: 2 | E19: 0 | F19: 1 | G19: 0 | H19: 0 | I19: 1 | J19: 0 | K19: 0 | L19: 0 | M19: 8 | N19: 0 | O19: =SUM(C19:L19,N19) -> 7 | P19: =SUM(C19:N19) -> 15 | R19: 1600-1700 | S19: =SUM(C46:C49) -> 40 | T19: =SUM(D46:D49) -> 10 | U19: =SUM(E46:E49) -> 15 | V19: =SUM(F46:F49) -> 17 | W19: =SUM(G46:G49) -> 0 | X19: =SUM(H46:H49) -> 1 | Y19: =SUM(I46:I49) -> 10 | Z19: =SUM(J46:J49) -> 2 | ... AF19: =SUM(P46:P49) -> 501
B20: 09.30 - 09.45 | C20: 10 | D20: 7 | E20: 3 | F20: 0 | G20: 1 | H20: 2 | I20: 1 | J20: 1 | K20: 0 | L20: 1 | M20: 29 | N20: 0 | O20: =SUM(C20:L20,N20) -> 26 | P20: =SUM(C20:N20) -> 55 | R20: 1700-1800 | S20: =SUM(C50:C53) -> 50 | T20: =SUM(D50:D53) -> 10 | U20: =SUM(E50:E53) -> 9 | V20: =SUM(F50:F53) -> 21 | W20: =SUM(G50:G53) -> 1 | X20: =SUM(H50:H53) -> 1 | Y20: =SUM(I50:I53) -> 17 | Z20: =SUM(J50:J53) -> 2 | ... AF20: =SUM(P50:P53) -> 617
B21: 09.45 - 10.00 | C21: 19 | D21: 2 | E21: 1 | F21: 0 | G21: 0 | H21: 0 | I21: 0 | J21: 1 | K21: 0 | L21: 0 | M21: 46 | N21: 0 | O21: =SUM(C21:L21,N21) -> 23 | P21: =SUM(C21:N21) -> 69 | R21: 1800-1900 | S21: =SUM(C54:C57) -> 25 | T21: =SUM(D54:D57) -> 10 | U21: =SUM(E54:E57) -> 9 | V21: =SUM(F54:F57) -> 12 | W21: =SUM(G54:G57) -> 3 | X21: =SUM(H54:H57) -> 0 | Y21: =SUM(I54:I57) -> 10 | Z21: =SUM(J54:J57) -> 1 | ... AF21: =SUM(P54:P57) -> 545
B22: 10.00 - 10.15 | C22: 14 | D22: 2 | E22: 2 | F22: 4 | G22: 0 | H22: 0 | I22: 2 | J22: 0 | K22: 1 | L22: 0 | M22: 65 | N22: 0 | O22: =SUM(C22:L22,N22) -> 25 | P22: =SUM(C22:N22) -> 90 | R22: 1900-2000 | S22: =SUM(C58:C61) -> 44 | T22: =SUM(D58:D61) -> 5 | U22: =SUM(E58:E61) -> 11 | V22: =SUM(F58:F61) -> 9 | W22: =SUM(G58:G61) -> 0 | X22: =SUM(H58:H61) -> 0 | Y22: =SUM(I58:I61) -> 9 | Z22: =SUM(J58:J61) -> 1 | ... AF22: =SUM(P58:P61) -> 483
B23: 10.15 - 10.30 | C23: 15 | D23: 4 | E23: 1 | F23: 8 | G23: 0 | H23: 0 | I23: 3 | J23: 0 | K23: 0 | L23: 0 | M23: 50 | N23: 0 | O23: =SUM(C23:L23,N23) -> 31 | P23: =SUM(C23:N23) -> 81 | R23: 2000-2100 | S23: =SUM(C62:C65) -> 34 | T23: =SUM(D62:D65) -> 9 | U23: =SUM(E62:E65) -> 6 | V23: =SUM(F62:F65) -> 11 | W23: =SUM(G62:G65) -> 0 | X23: =SUM(H62:H65) -> 2 | Y23: =SUM(I62:I65) -> 7 | Z23: =SUM(J62:J65) -> 1 | ... AF23: =SUM(P62:P65) -> 317
B24: 10.30 - 10.45 | C24: 8 | D24: 7 | E24: 3 | F24: 4 | G24: 0 | H24: 0 | I24: 2 | J24: 0 | K24: 0 | L24: 2 | M24: 89 | N24: 0 | O24: =SUM(C24:L24,N24) -> 26 | P24: =SUM(C24:N24) -> 115 | R24: 2100-2200 | S24: =SUM(C66:C69) -> 29 | T24: =SUM(D66:D69) -> 1 | U24: =SUM(E66:E69) -> 9 | V24: =SUM(F66:F69) -> 15 | W24: =SUM(G66:G69) -> 0 | X24: =SUM(H66:H69) -> 1 | Y24: =SUM(I66:I69) -> 5 | Z24: =SUM(J66:J69) -> 1 | ... AF24: =SUM(P66:P69) -> 238
B25: 10.45 - 11.00 | C25: 13 | D25: 0 | E25: 4 | F25: 6 | G25: 1 | H25: 0 | I25: 3 | J25: 0 | K25: 1 | L25: 1 | M25: 113 | N25: 0 | O25: =SUM(C25:L25,N25) -> 29 | P25: =SUM(C25:N25) -> 142 | R25: 2200-2300 | S25: =SUM(C70:C73) -> 21 | T25: =SUM(D70:D73) -> 2 | U25: =SUM(E70:E73) -> 5 | V25: =SUM(F70:F73) -> 5 | W25: =SUM(G70:G73) -> 0 | X25: =SUM(H70:H73) -> 2 | Y25: =SUM(I70:I73) -> 3 | Z25: =SUM(J70:J73) -> 1 | ... AF25: =SUM(P70:P73) -> 158
B26: 11.00 - 11.15 | C26: 11 | D26: 5 | E26: 4 | F26: 7 | G26: 0 | H26: 0 | I26: 5 | J26: 1 | K26: 0 | L26: 1 | M26: 145 | N26: 0 | O26: =SUM(C26:L26,N26) -> 34 | P26: =SUM(C26:N26) -> 179 | R26: 2300-0000 | S26: =SUM(C74:C77) -> 15 | T26: =SUM(D74:D77) -> 0 | U26: =SUM(E74:E77) -> 0 | V26: =SUM(F74:F77) -> 2 | W26: =SUM(G74:G77) -> 0 | X26: =SUM(H74:H77) -> 2 | Y26: =SUM(I74:I77) -> 0 | Z26: =SUM(J74:J77) -> 0 | ... AF26: =SUM(P74:P77) -> 88
B27: 11.15 - 11.30 | C27: 18 | D27: 3 | E27: 3 | F27: 5 | G27: 0 | H27: 0 | I27: 4 | J27: 1 | K27: 0 | L27: 0 | M27: 133 | N27: 0 | O27: =SUM(C27:L27,N27) -> 34 | P27: =SUM(C27:N27) -> 167 | R27: 0000-0100 | S27: =SUM(C78:C81) -> 9 | T27: =SUM(D78:D81) -> 1 | U27: =SUM(E78:E81) -> 1 | V27: =SUM(F78:F81) -> 2 | W27: =SUM(G78:G81) -> 0 | X27: =SUM(H78:H81) -> 1 | Y27: =SUM(I78:I81) -> 3 | Z27: =SUM(J78:J81) -> 1 | ... AF27: =SUM(P78:P81) -> 80
B28: 11.30 - 11.45 | C28: 15 | D28: 2 | E28: 4 | F28: 10 | G28: 0 | H28: 1 | I28: 3 | J28: 0 | K28: 0 | L28: 1 | M28: 159 | N28: 0 | O28: =SUM(C28:L28,N28) -> 36 | P28: =SUM(C28:N28) -> 195 | R28: 0100-0200 | S28: =SUM(C82:C85) -> 4 | T28: =SUM(D82:D85) -> 0 | U28: =SUM(E82:E85) -> 0 | V28: =SUM(F82:F85) -> 0 | W28: =SUM(G82:G85) -> 0 | X28: =SUM(H82:H85) -> 0 | Y28: =SUM(I82:I85) -> 0 | Z28: =SUM(J82:J85) -> 0 | ... AF28: =SUM(P82:P85) -> 50
B29: 11.45 - 12.00 | C29: 13 | D29: 4 | E29: 6 | F29: 5 | G29: 0 | H29: 0 | I29: 0 | J29: 0 | K29: 0 | L29: 3 | M29: 136 | N29: 0 | O29: =SUM(C29:L29,N29) -> 31 | P29: =SUM(C29:N29) -> 167 | R29: 0200-0300 | S29: =SUM(C86:C89) -> 2 | T29: =SUM(D86:D89) -> 0 | U29: =SUM(E86:E89) -> 0 | V29: =SUM(F86:F89) -> 2 | W29: =SUM(G86:G89) -> 0 | X29: =SUM(H86:H89) -> 2 | Y29: =SUM(I86:I89) -> 2 | Z29: =SUM(J86:J89) -> 0 | ... AF29: =SUM(P86:P89) -> 40
B30: 12.00 - 12.15 | C30: 5 | D30: 5 | E30: 4 | F30: 6 | G30: 1 | H30: 1 | I30: 0 | J30: 0 | K30: 0 | L30: 1 | M30: 145 | N30: 0 | O30: =SUM(C30:L30,N30) -> 23 | P30: =SUM(C30:N30) -> 168 | R30: 0300-0400 | S30: =SUM(C90:C93) -> 3 | T30: =SUM(D90:D93) -> 0 | U30: =SUM(E90:E93) -> 0 | V30: =SUM(F90:F93) -> 3 | W30: =SUM(G90:G93) -> 0 | X30: =SUM(H90:H93) -> 1 | Y30: =SUM(I90:I93) -> 0 | Z30: =SUM(J90:J93) -> 0 | ... AF30: =SUM(P90:P93) -> 38
B31: 12.15 - 12.30 | C31: 12 | D31: 4 | E31: 4 | F31: 6 | G31: 0 | H31: 0 | I31: 2 | J31: 1 | K31: 0 | L31: 3 | M31: 115 | N31: 0 | O31: =SUM(C31:L31,N31) -> 32 | P31: =SUM(C31:N31) -> 147 | R31: 0400-0500 | S31: =SUM(C94:C97) -> 2 | T31: =SUM(D94:D97) -> 0 | U31: =SUM(E94:E97) -> 0 | V31: =SUM(F94:F97) -> 0 | W31: =SUM(G94:G97) -> 0 | X31: =SUM(H94:H97) -> 1 | Y31: =SUM(I94:I97) -> 1 | Z31: =SUM(J94:J97) -> 0 | ... AF31: =SUM(P94:P97) -> 34
B32: 12.30 - 12.45 | C32: 8 | D32: 4 | E32: 3 | F32: 9 | G32: 0 | H32: 0 | I32: 2 | J32: 1 | K32: 0 | L32: 1 | M32: 141 | N32: 0 | O32: =SUM(C32:L32,N32) -> 28 | P32: =SUM(C32:N32) -> 169 | R32: 0500-0600 | S32: =SUM(C98:C101) -> 5 | T32: =SUM(D98:D101) -> 0 | U32: =SUM(E98:E101) -> 0 | V32: =SUM(F98:F101) -> 1 | W32: =SUM(G98:G101) -> 0 | X32: =SUM(H98:H101) -> 1 | Y32: =SUM(I98:I101) -> 0 | Z32: =SUM(J98:J101) -> 0 | ... AF32: =SUM(P98:P101) -> 52
B33: 12.45 - 13.00 | C33: 6 | D33: 4 | E33: 4 | F33: 5 | G33: 0 | H33: 0 | I33: 1 | J33: 0 | K33: 0 | L33: 3 | M33: 110 | N33: 0 | O33: =SUM(C33:L33,N33) -> 23 | P33: =SUM(C33:N33) -> 133 | R33: 0600-0700 | S33: =SUM(C102:C105) -> 15 | T33: =SUM(D102:D105) -> 0 | U33: =SUM(E102:E105) -> 2 | V33: =SUM(F102:F105) -> 7 | W33: =SUM(G102:G105) -> 0 | X33: =SUM(H102:H105) -> 1 | Y33: =SUM(I102:I105) -> 2 | Z33: =SUM(J102:J105) -> 2 | ... AF33: =SUM(P102:P105) -> 127
B34: 13.00 - 13.15 | C34: 12 | D34: 3 | E34: 4 | F34: 4 | G34: 0 | H34: 0 | I34: 3 | J34: 3 | K34: 0 | L34: 1 | M34: 127 | N34: 0 | O34: =SUM(C34:L34,N34) -> 30 | P34: =SUM(C34:N34) -> 157 | R34: AM Peak Hr | S34: =MAX(S10:S12) -> 39 | T34: =MAX(T10:T12) -> 16 | U34: =MAX(U10:U12) -> 5 | V34: =MAX(V10:V12) -> 19 | W34: =MAX(W10:W12) -> 1 | X34: =MAX(X10:X12) -> 2 | Y34: =MAX(Y10:Y12) -> 12 | Z34: =MAX(Z10:Z12) -> 3 | ... AF34: =MAX(AF10:AF12) -> 176
B35: 13.15 - 13.30 | C35: 9 | D35: 3 | E35: 3 | F35: 8 | G35: 1 | H35: 0 | I35: 1 | J35: 0 | K35: 0 | L35: 3 | M35: 126 | N35: 0 | O35: =SUM(C35:L35,N35) -> 28 | P35: =SUM(C35:N35) -> 154 | R35: IP Peak Hr | S35: =MAX(S13:S18) -> 57 | T35: =MAX(T13:T18) -> 17 | U35: =MAX(U13:U18) -> 17 | V35: =MAX(V13:V18) -> 27 | W35: =MAX(W13:W18) -> 4 | X35: =MAX(X13:X18) -> 2 | Y35: =MAX(Y13:Y18) -> 12 | Z35: =MAX(Z13:Z18) -> 3 | ... AF35: =MAX(AF13:AF18) -> 708
B36: 13.30 - 13.45 | C36: 10 | D36: 1 | E36: 1 | F36: 4 | G36: 1 | H36: 1 | I36: 3 | J36: 0 | K36: 0 | L36: 1 | M36: 119 | N36: 0 | O36: =SUM(C36:L36,N36) -> 22 | P36: =SUM(C36:N36) -> 141 | R36: PM Peak Hr | S36: =MAX(S19:S21) -> 50 | T36: =MAX(T19:T21) -> 10 | U36: =MAX(U19:U21) -> 15 | V36: =MAX(V19:V21) -> 21 | W36: =MAX(W19:W21) -> 3 | X36: =MAX(X19:X21) -> 1 | Y36: =MAX(Y19:Y21) -> 17 | Z36: =MAX(Z19:Z21) -> 2 | ... AF36: =MAX(AF19:AF21) -> 617
B37: 13.45 - 14.00 | C37: 11 | D37: 5 | E37: 2 | F37: 1 | G37: 2 | H37: 0 | I37: 4 | J37: 0 | K37: 0 | L37: 0 | M37: 126 | N37: 0 | O37: =SUM(C37:L37,N37) -> 25 | P37: =SUM(C37:N37) -> 151 | R37: AM Period | S37: =SUM(S10:S12) -> 94 | T37: =SUM(T10:T12) -> 34 | U37: =SUM(U10:U12) -> 13 | V37: =SUM(V10:V12) -> 33 | W37: =SUM(W10:W12) -> 2 | X37: =SUM(X10:X12) -> 2 | Y37: =SUM(Y10:Y12) -> 21 | Z37: =SUM(Z10:Z12) -> 9 | ... AF37: =SUM(AF10:AF12) -> 477
B38: 14.00 - 14.15 | C38: 6 | D38: 4 | E38: 4 | F38: 2 | G38: 0 | H38: 0 | I38: 1 | J38: 0 | K38: 0 | L38: 0 | M38: 98 | N38: 0 | O38: =SUM(C38:L38,N38) -> 17 | P38: =SUM(C38:N38) -> 115 | R38: IP Period | S38: =SUM(S13:S18) -> 250 | T38: =SUM(T13:T18) -> 77 | U38: =SUM(U13:U18) -> 78 | V38: =SUM(V13:V18) -> 116 | W38: =SUM(W13:W18) -> 7 | X38: =SUM(X13:X18) -> 6 | Y38: =SUM(Y13:Y18) -> 55 | Z38: =SUM(Z13:Z18) -> 9 | ... AF38: =SUM(AF13:AF18) -> 3407
B39: 14.15 - 14.30 | C39: 7 | D39: 4 | E39: 2 | F39: 0 | G39: 0 | H39: 0 | I39: 3 | J39: 1 | K39: 0 | L39: 2 | M39: 150 | N39: 0 | O39: =SUM(C39:L39,N39) -> 19 | P39: =SUM(C39:N39) -> 169 | R39: PM Period | S39: =SUM(S19:S21) -> 115 | T39: =SUM(T19:T21) -> 30 | U39: =SUM(U19:U21) -> 33 | V39: =SUM(V19:V21) -> 50 | W39: =SUM(W19:W21) -> 4 | X39: =SUM(X19:X21) -> 2 | Y39: =SUM(Y19:Y21) -> 37 | Z39: =SUM(Z19:Z21) -> 5 | ... AF39: =SUM(AF19:AF21) -> 1663
B40: 14.30 - 14.45 | C40: 6 | D40: 3 | E40: 5 | F40: 4 | G40: 0 | H40: 2 | I40: 1 | J40: 0 | K40: 0 | L40: 0 | M40: 135 | N40: 0 | O40: =SUM(C40:L40,N40) -> 21 | P40: =SUM(C40:N40) -> 156 | R40: 12 Hours | S40: =SUM(S10:S21) -> 459 | T40: =SUM(T10:T21) -> 141 | U40: =SUM(U10:U21) -> 124 | V40: =SUM(V10:V21) -> 199 | W40: =SUM(W10:W21) -> 13 | X40: =SUM(X10:X21) -> 10 | Y40: =SUM(Y10:Y21) -> 113 | Z40: =SUM(Z10:Z21) -> 23 | ... AF40: =SUM(AF10:AF21) -> 5547
B41: 14.45 - 15.00 | C41: 7 | D41: 3 | E41: 2 | F41: 3 | G41: 0 | H41: 0 | I41: 1 | J41: 0 | K41: 0 | L41: 0 | M41: 119 | N41: 0 | O41: =SUM(C41:L41,N41) -> 16 | P41: =SUM(C41:N41) -> 135 | R41: 24 Hrs/ADT | S41: =SUM(S10:S33) -> 642 | T41: =SUM(T10:T33) -> 159 | U41: =SUM(U10:U33) -> 158 | V41: =SUM(V10:V33) -> 256 | W41: =SUM(W10:W33) -> 13 | X41: =SUM(X10:X33) -> 24 | Y41: =SUM(Y10:Y33) -> 145 | Z41: =SUM(Z10:Z33) -> 30 | ... AF41: =SUM(AF10:AF33) -> 7252
B42: 15.00 - 15.15 | C42: 8 | D42: 2 | E42: 5 | F42: 5 | G42: 0 | H42: 0 | I42: 0 | J42: 0 | K42: 0 | L42: 1 | M42: 97 | N42: 0 | O42: =SUM(C42:L42,N42) -> 21 | P42: =SUM(C42:N42) -> 118 | R42: NEF | S42: =S41/S40 -> 1.3986928 | T42: =T41/T40 -> 1.1276596 | U42: =U41/U40 -> 1.2741935 | V42: =V41/V40 -> 1.2864322 | W42: =W41/W40 -> 1 | X42: =X41/X40 -> 2.4 | Y42: =Y41/Y40 -> 1.2831858 | Z42: =Z41/Z40 -> 1.3043478 | ... AF42: =AF41/AF40 -> 1.3073734
...

Sheet 27.10 Kasese-Fort Portal
B1: Consultancy services for Preparation of Expressway Development Master Plan (EDMP) for Uganda
B2: MANUAL CLASSIFIED COUNT (MCC)
B3: ROAD NAME: | C3: ='25.10 Kasese-Fort Portal'!C3:G3 -> MCC - C4 - STN106
C5: Date | D5: 27.10.19 | F5: Location | G5: ='25.10 Kasese-Fort Portal'!G5:H5 -> Kisanga B | J5: Surveyor | K5: ='25.10 Kasese-Fort Portal'!K5:L5 -> Onyuti Betty
C6: Dir. From | D6: ='25.10 Kasese-Fort Portal'!D6:E6 -> Kasese | F6: Dir. To | G6: ='25.10 Kasese-Fort Portal'!G6:H6 -> Fort Portal | J6: Supervisor | K6: ='25.10 Kasese-Fort Portal'!K6:L6 -> Onyuti Betty
B8: Time / Veh Type | R8: SUMMARY TRAFFIC VOLUMES
C9: 1. Car | D9: 2. Station Wagon | E9: 3. Pickups | F9: 4. Minibus, matatu | G9: 5. Medium bus | H9: 6. Large Bus | I9: 7. Light Truck | J9: 8. Medium Truck | K9: 9. Heavy truck | L9: 10. Truck Trailer | M9: 11. Motor cycles | N9: 12. Tractors | O9: Total Excl M/Cycles | P9: Total All | R9: Time | S9: 1. Car | T9: 2. Station Wagon | U9: 3. Pickups | V9: 4. Minibus, matatu | W9: 5. Medium bus | X9: 6. Large Bus | Y9: 7. Light Truck | Z9: 8. Medium Truck | AA9: 9. Heavy truck | AB9: 10. Truck Trailer | AC9: 11. Motorcycles | AD9: 12. Tractors, Graders | AE9: Total Excl M/ Cycles | AF9: Total All
B10: 07.00 - 07.15 | C10: 9 | D10: 0 | E10: 0 | F10: 4 | G10: 0 | H10: 1 | I10: 2 | J10: 0 | K10: 0 | L10: 0 | M10: 55 | N10: 0 | O10: =SUM(C10:L10,N10) -> 16 | P10: =SUM(C10:N10) -> 71 | R10: 0700-0800 | S10: =SUM(C10:C13) -> 29 | T10: =SUM(D10:D13) -> 1 | U10: =SUM(E10:E13) -> 3 | V10: =SUM(F10:F13) -> 18 | W10: =SUM(G10:G13) -> 0 | X10: =SUM(H10:H13) -> 2 | Y10: =SUM(I10:I13) -> 8 | Z10: =SUM(J10:J13) -> 3 | ... AF10: =SUM(P10:P13) -> 382
B11: 07.15 - 07.30 | C11: 8 | D11: 0 | E11: 1 | F11: 5 | G11: 0 | H11: 0 | I11: 2 | J11: 2 | K11: 0 | L11: 1 | M11: 85 | N11: 0 | O11: =SUM(C11:L11,N11) -> 19 | P11: =SUM(C11:N11) -> 104 | R11: 0800-0900 | S11: =SUM(C14:C17) -> 19 | T11: =SUM(D14:D17) -> 4 | U11: =SUM(E14:E17) -> 5 | V11: =SUM(F14:F17) -> 24 | W11: =SUM(G14:G17) -> 1 | X11: =SUM(H14:H17) -> 1 | Y11: =SUM(I14:I17) -> 9 | Z11: =SUM(J14:J17) -> 2 | ... AF11: =SUM(P14:P17) -> 361
B12: 07.30 - 07.45 | C12: 9 | D12: 1 | E12: 0 | F12: 7 | G12: 0 | H12: 0 | I12: 2 | J12: 0 | K12: 0 | L12: 1 | M12: 80 | N12: 0 | O12: =SUM(C12:L12,N12) -> 20 | P12: =SUM(C12:N12) -> 100 | R12: 0900-1000 | S12: =SUM(C18:C21) -> 34 | T12: =SUM(D18:D21) -> 7 | U12: =SUM(E18:E21) -> 16 | V12: =SUM(F18:F21) -> 30 | W12: =SUM(G18:G21) -> 0 | X12: =SUM(H18:H21) -> 1 | Y12: =SUM(I18:I21) -> 11 | Z12: =SUM(J18:J21) -> 4 | ... AF12: =SUM(P18:P21) -> 467
