Workbook

Sheet 29.07 Kisasi-Bukoto
B1: Consultancy services for Preparation of Expressway Development Master Plan (EDMP) for Uganda
B2: MANUAL CLASSIFIED COUNT (MCC)
B3: ROAD NAME: | C3: MCC - C1 - STN32 - BUKOTO KISASI ROAD
C5: Date | D5: 29.07.19 | F5: Location | G5: KISASI | J5: Surveyor | K5: RWAMBITITO J./NICHOL A./GEORGE W.
C6: Dir. From | D6: KISASI | F6: Dir. To | G6: BUKOTO | J6: Supervisor | K6: SALIMA L.
B8: Time / Veh Type | R8: SUMMARY TRAFFIC VOLUMES
C9: 1. Car | D9: 2. Station Wagon | E9: 3. Pickups | F9: 4. Minibus, matatu | G9: 5. Medium bus | H9: 6. Large Bus | I9: 7. Light Truck | J9: 8. Medium Truck | K9: 9. Heavy truck | L9: 10. Truck Trailer | M9: 11. Motor cycles | N9: 12. Tractors | O9: Total Excl M/Cycles | P9: Total All | R9: Time | S9: 1. Car | T9: 2. Station Wagon | U9: 3. Pickups | V9: 4. Minibus, matatu | W9: 5. Medium bus | X9: 6. Large Bus | Y9: 7. Light Truck | Z9: 8. Medium Truck | AA9: 9. Heavy truck | AB9: 10. Truck Trailer | AC9: 11. Motorcycles | AD9: 12. Tractors, Graders | AE9: Total Excl M/ Cycles | AF9: Total All
B10: 07.00 - 07.15 | C10: 23 | D10: 8 | E10: 0 | F10: 3 | G10: 0 | H10: 0 | I10: 1 | J10: 0 | K10: 0 | L10: 0 | M10: 15 | N10: 0 | O10: =SUM(C10:L10,N10) -> 35 | P10: =SUM(C10:N10) -> 50 | R10: 0700-0800 | S10: =SUM(C10:C13) -> 188 | T10: =SUM(D10:D13) -> 89 | U10: =SUM(E10:E13) -> 0 | V10: =SUM(F10:F13) -> 29 | W10: =SUM(G10:G13) -> 0 | X10: =SUM(H10:H13) -> 0 | Y10: =SUM(I10:I13) -> 10 | Z10: =SUM(J10:J13) -> 0 | ... AF10: =SUM(P10:P13) -> 465
B11: 07.15 - 07.30 | C11: 40 | D11: 4 | E11: 0 | F11: 6 | G11: 0 | H11: 0 | I11: 3 | J11: 0 | K11: 0 | L11: 0 | M11: 13 | N11: 0 | O11: =SUM(C11:L11,N11) -> 53 | P11: =SUM(C11:N11) -> 66 | R11: 0800-0900 | S11: =SUM(C14:C17) -> 238 | T11: =SUM(D14:D17) -> 144 | U11: =SUM(E14:E17) -> 0 | V11: =SUM(F14:F17) -> 53 | W11: =SUM(G14:G17) -> 1 | X11: =SUM(H14:H17) -> 0 | Y11: =SUM(I14:I17) -> 11 | Z11: =SUM(J14:J17) -> 2 | ... AF11: =SUM(P14:P17) -> 768
B12: 07.30 - 07.45 | C12: 45 | D12: 31 | E12: 0 | F12: 5 | G12: 0 | H12: 0 | I12: 2 | J12: 0 | K12: 0 | L12: 0 | M12: 38 | N12: 0 | O12: =SUM(C12:L12,N12) -> 83 | P12: =SUM(C12:N12) -> 121 | R12: 0900-1000 | S12: =SUM(C18:C21) -> 183 | T12: =SUM(D18:D21) -> 97 | U12: =SUM(E18:E21) -> 0 | V12: =SUM(F18:F21) -> 37 | W12: =SUM(G18:G21) -> 0 | X12: =SUM(H18:H21) -> 1 | Y12: =SUM(I18:I21) -> 13 | Z12: =SUM(J18:J21) -> 1 | ... AF12: =SUM(P18:P21) -> 564
B13: 07.45 - 08.00 | C13: 80 | D13: 46 | E13: 0 | F13: 15 | G13: 0 | H13: 0 | I13: 4 | J13: 0 | K13: 0 | L13: 0 | M13: 83 | N13: 0 | O13: =SUM(C13:L13,N13) -> 145 | P13: =SUM(C13:N13) -> 228 | R13: 1000-1100 | S13: =SUM(C22:C25) -> 146 | T13: =SUM(D22:D25) -> 72 | U13: =SUM(E22:E25) -> 2 | V13: =SUM(F22:F25) -> 40 | W13: =SUM(G22:G25) -> 2 | X13: =SUM(H22:H25) -> 0 | Y13: =SUM(I22:I25) -> 8 | Z13: =SUM(J22:J25) -> 1 | ... AF13: =SUM(P22:P25) -> 496
B14: 08.00 - 08.15 | C14: 85 | D14: 46 | E14: 0 | F14: 14 | G14: 0 | H14: 0 | I14: 5 | J14: 0 | K14: 0 | L14: 0 | M14: 98 | N14: 0 | O14: =SUM(C14:L14,N14) -> 150 | P14: =SUM(C14:N14) -> 248 | R14: 1100-1200 | S14: =SUM(C26:C29) -> 107 | T14: =SUM(D26:D29) -> 68 | U14: =SUM(E26:E29) -> 5 | V14: =SUM(F26:F29) -> 41 | W14: =SUM(G26:G29) -> 0 | X14: =SUM(H26:H29) -> 0 | Y14: =SUM(I26:I29) -> 6 | Z14: =SUM(J26:J29) -> 1 | ... AF14: =SUM(P26:P29) -> 461
B15: 08.15 - 08.30 | C15: 67 | D15: 38 | E15: 0 | F15: 10 | G15: 0 | H15: 0 | I15: 3 | J15: 0 | K15: 0 | L15: 0 | M15: 76 | N15: 0 | O15: =SUM(C15:L15,N15) -> 118 | P15: =SUM(C15:N15) -> 194 | R15: 1200-1300 | S15: =SUM(C30:C33) -> 104 | T15: =SUM(D30:D33) -> 53 | U15: =SUM(E30:E33) -> 12 | V15: =SUM(F30:F33) -> 36 | W15: =SUM(G30:G33) -> 0 | X15: =SUM(H30:H33) -> 0 | Y15: =SUM(I30:I33) -> 11 | Z15: =SUM(J30:J33) -> 0 | ... AF15: =SUM(P30:P33) -> 418
B16: 08.30 - 08.45 | C16: 41 | D16: 26 | E16: 0 | F16: 15 | G16: 1 | H16: 0 | I16: 0 | J16: 0 | K16: 0 | L16: 0 | M16: 63 | N16: 0 | O16: =SUM(C16:L16,N16) -> 83 | P16: =SUM(C16:N16) -> 146 | R16: 1300-1400 | S16: =SUM(C34:C37) -> 79 | T16: =SUM(D34:D37) -> 34 | U16: =SUM(E34:E37) -> 5 | V16: =SUM(F34:F37) -> 34 | W16: =SUM(G34:G37) -> 0 | X16: =SUM(H34:H37) -> 0 | Y16: =SUM(I34:I37) -> 3 | Z16: =SUM(J34:J37) -> 4 | ... AF16: =SUM(P34:P37) -> 387
B17: 08.45 - 9.00 | C17: 45 | D17: 34 | E17: 0 | F17: 14 | G17: 0 | H17: 0 | I17: 3 | J17: 2 | K17: 0 | L17: 0 | M17: 82 | N17: 0 | O17: =SUM(C17:L17,N17) -> 98 | P17: =SUM(C17:N17) -> 180 | R17: 1400-1500 | S17: =SUM(C38:C41) -> 104 | T17: =SUM(D38:D41) -> 41 | U17: =SUM(E38:E41) -> 6 | V17: =SUM(F38:F41) -> 36 | W17: =SUM(G38:G41) -> 0 | X17: =SUM(H38:H41) -> 0 | Y17: =SUM(I38:I41) -> 7 | Z17: =SUM(J38:J41) -> 0 | ... AF17: =SUM(P38:P41) -> 480
B18: 09.00 - 09.15 | C18: 53 | D18: 31 | E18: 0 | F18: 2 | G18: 0 | H18: 0 | I18: 5 | J18: 0 | K18: 0 | L18: 0 | M18: 70 | N18: 0 | O18: =SUM(C18:L18,N18) -> 91 | P18: =SUM(C18:N18) -> 161 | R18: 1500-1600 | S18: =SUM(C42:C45) -> 80 | T18: =SUM(D42:D45) -> 45 | U18: =SUM(E42:E45) -> 8 | V18: =SUM(F42:F45) -> 27 | W18: =SUM(G42:G45) -> 0 | X18: =SUM(H42:H45) -> 0 | Y18: =SUM(I42:I45) -> 5 | Z18: =SUM(J42:J45) -> 2 | ... AF18: =SUM(P42:P45) -> 384
B19: 09.15 - 09.30 | C19: 54 | D19: 27 | E19: 0 | F19: 12 | G19: 0 | H19: 1 | I19: 2 | J19: 0 | K19: 0 | L19: 0 | M19: 54 | N19: 0 | O19: =SUM(C19:L19,N19) -> 96 | P19: =SUM(C19:N19) -> 150 | R19: 1600-1700 | S19: =SUM(C46:C49) -> 115 | T19: =SUM(D46:D49) -> 57 | U19: =SUM(E46:E49) -> 11 | V19: =SUM(F46:F49) -> 42 | W19: =SUM(G46:G49) -> 1 | X19: =SUM(H46:H49) -> 0 | Y19: =SUM(I46:I49) -> 11 | Z19: =SUM(J46:J49) -> 1 | ... AF19: =SUM(P46:P49) -> 512
B20: 09.30 - 09.45 | C20: 33 | D20: 16 | E20: 0 | F20: 10 | G20: 0 | H20: 0 | I20: 2 | J20: 0 | K20: 0 | L20: 0 | M20: 43 | N20: 0 | O20: =SUM(C20:L20,N20) -> 61 | P20: =SUM(C20:N20) -> 104 | R20: 1700-1800 | S20: =SUM(C50:C53) -> 114 | T20: =SUM(D50:D53) -> 42 | U20: =SUM(E50:E53) -> 14 | V20: =SUM(F50:F53) -> 33 | W20: =SUM(G50:G53) -> 0 | X20: =SUM(H50:H53) -> 0 | Y20: =SUM(I50:I53) -> 7 | Z20: =SUM(J50:J53) -> 1 | ... AF20: =SUM(P50:P53) -> 520
B21: 09.45 - 10.00 | C21: 43 | D21: 23 | E21: 0 | F21: 13 | G21: 0 | H21: 0 | I21: 4 | J21: 1 | K21: 0 | L21: 0 | M21: 65 | N21: 0 | O21: =SUM(C21:L21,N21) -> 84 | P21: =SUM(C21:N21) -> 149 | R21: 1800-1900 | S21: =SUM(C54:C57) -> 87 | T21: =SUM(D54:D57) -> 34 | U21: =SUM(E54:E57) -> 12 | V21: =SUM(F54:F57) -> 31 | W21: =SUM(G54:G57) -> 3 | X21: =SUM(H54:H57) -> 0 | Y21: =SUM(I54:I57) -> 12 | Z21: =SUM(J54:J57) -> 7 | ... AF21: =SUM(P54:P57) -> 524
B22: 10.00 - 10.15 | C22: 35 | D22: 14 | E22: 1 | F22: 9 | G22: 0 | H22: 0 | I22: 2 | J22: 0 | K22: 0 | L22: 0 | M22: 61 | N22: 0 | O22: =SUM(C22:L22,N22) -> 61 | P22: =SUM(C22:N22) -> 122 | R22: AM Peak Hr | S22: =MAX(S10:S12) -> 238 | T22: =MAX(T10:T12) -> 144 | U22: =MAX(U10:U12) -> 0 | V22: =MAX(V10:V12) -> 53 | W22: =MAX(W10:W12) -> 1 | X22: =MAX(X10:X12) -> 1 | Y22: =MAX(Y10:Y12) -> 13 | Z22: =MAX(Z10:Z12) -> 2 | ... AF22: =MAX(AF10:AF12) -> 768
B23: 10.15 - 10.30 | C23: 39 | D23: 22 | E23: 0 | F23: 10 | G23: 1 | H23: 0 | I23: 0 | J23: 1 | K23: 0 | L23: 0 | M23: 43 | N23: 0 | O23: =SUM(C23:L23,N23) -> 73 | P23: =SUM(C23:N23) -> 116 | R23: IP Peak Hr | S23: =MAX(S13:S18) -> 146 | T23: =MAX(T13:T18) -> 72 | U23: =MAX(U13:U18) -> 12 | V23: =MAX(V13:V18) -> 41 | W23: =MAX(W13:W18) -> 2 | X23: =MAX(X13:X18) -> 0 | Y23: =MAX(Y13:Y18) -> 11 | Z23: =MAX(Z13:Z18) -> 4 | ... AF23: =MAX(AF13:AF18) -> 496
B24: 10.30 - 10.45 | C24: 33 | D24: 19 | E24: 0 | F24: 8 | G24: 0 | H24: 0 | I24: 4 | J24: 0 | K24: 0 | L24: 0 | M24: 68 | N24: 0 | O24: =SUM(C24:L24,N24) -> 64 | P24: =SUM(C24:N24) -> 132 | R24: PM Peak Hr | S24: =MAX(S19:S21) -> 115 | T24: =MAX(T19:T21) -> 57 | U24: =MAX(U19:U21) -> 14 | V24: =MAX(V19:V21) -> 42 | W24: =MAX(W19:W21) -> 3 | X24: =MAX(X19:X21) -> 0 | Y24: =MAX(Y19:Y21) -> 12 | Z24: =MAX(Z19:Z21) -> 7 | ... AF24: =MAX(AF19:AF21) -> 524
B25: 10.45 - 11.00 | C25: 39 | D25: 17 | E25: 1 | F25: 13 | G25: 1 | H25: 0 | I25: 2 | J25: 0 | K25: 0 | L25: 0 | M25: 53 | N25: 0 | O25: =SUM(C25:L25,N25) -> 73 | P25: =SUM(C25:N25) -> 126 | R25: AM Period | S25: =SUM(S10:S12) -> 609 | T25: =SUM(T10:T12) -> 330 | U25: =SUM(U10:U12) -> 0 | V25: =SUM(V10:V12) -> 119 | W25: =SUM(W10:W12) -> 1 | X25: =SUM(X10:X12) -> 1 | Y25: =SUM(Y10:Y12) -> 34 | Z25: =SUM(Z10:Z12) -> 3 | ... AF25: =SUM(AF10:AF12) -> 1797
B26: 11.00 - 11.15 | C26: 31 | D26: 21 | E26: 3 | F26: 15 | G26: 0 | H26: 0 | I26: 0 | J26: 1 | K26: 1 | L26: 0 | M26: 43 | N26: 0 | O26: =SUM(C26:L26,N26) -> 72 | P26: =SUM(C26:N26) -> 115 | R26: IP Period | S26: =SUM(S13:S18) -> 620 | T26: =SUM(T13:T18) -> 313 | U26: =SUM(U13:U18) -> 38 | V26: =SUM(V13:V18) -> 214 | W26: =SUM(W13:W18) -> 2 | X26: =SUM(X13:X18) -> 0 | Y26: =SUM(Y13:Y18) -> 40 | Z26: =SUM(Z13:Z18) -> 8 | ... AF26: =SUM(AF13:AF18) -> 2626
B27: 11.15 - 11.30 | C27: 29 | D27: 18 | E27: 1 | F27: 9 | G27: 0 | H27: 0 | I27: 3 | J27: 0 | K27: 0 | L27: 0 | M27: 53 | N27: 0 | O27: =SUM(C27:L27,N27) -> 60 | P27: =SUM(C27:N27) -> 113 | R27: PM Period | S27: =SUM(S19:S21) -> 316 | T27: =SUM(T19:T21) -> 133 | U27: =SUM(U19:U21) -> 37 | V27: =SUM(V19:V21) -> 106 | W27: =SUM(W19:W21) -> 4 | X27: =SUM(X19:X21) -> 0 | Y27: =SUM(Y19:Y21) -> 30 | Z27: =SUM(Z19:Z21) -> 9 | ... AF27: =SUM(AF19:AF21) -> 1556
B28: 11.30 - 11.45 | C28: 26 | D28: 19 | E28: 1 | F28: 9 | G28: 0 | H28: 0 | I28: 2 | J28: 0 | K28: 0 | L28: 0 | M28: 63 | N28: 0 | O28: =SUM(C28:L28,N28) -> 57 | P28: =SUM(C28:N28) -> 120 | R28: 12 Hours | S28: =SUM(S10:S21) -> 1545 | T28: =SUM(T10:T21) -> 776 | U28: =SUM(U10:U21) -> 75 | V28: =SUM(V10:V21) -> 439 | W28: =SUM(W10:W21) -> 7 | X28: =SUM(X10:X21) -> 1 | Y28: =SUM(Y10:Y21) -> 104 | Z28: =SUM(Z10:Z21) -> 20 | ... AF28: =SUM(AF10:AF21) -> 5979
B29: 11.45 - 12.00 | C29: 21 | D29: 10 | E29: 0 | F29: 8 | G29: 0 | H29: 0 | I29: 1 | J29: 0 | K29: 1 | L29: 0 | M29: 72 | N29: 0 | O29: =SUM(C29:L29,N29) -> 41 | P29: =SUM(C29:N29) -> 113
B30: 12.00 - 12.15 | C30: 11 | D30: 14 | E30: 7 | F30: 9 | G30: 0 | H30: 0 | I30: 1 | J30: 0 | K30: 0 | L30: 0 | M30: 53 | N30: 0 | O30: =SUM(C30:L30,N30) -> 42 | P30: =SUM(C30:N30) -> 95
B31: 12.15 - 12.30 | C31: 41 | D31: 16 | E31: 4 | F31: 7 | G31: 0 | H31: 0 | I31: 5 | J31: 0 | K31: 0 | L31: 0 | M31: 48 | N31: 0 | O31: =SUM(C31:L31,N31) -> 73 | P31: =SUM(C31:N31) -> 121
B32: 12.30 - 12.45 | C32: 27 | D32: 10 | E32: 1 | F32: 13 | G32: 0 | H32: 0 | I32: 2 | J32: 0 | K32: 0 | L32: 0 | M32: 47 | N32: 0 | O32: =SUM(C32:L32,N32) -> 53 | P32: =SUM(C32:N32) -> 100
B33: 12.45 - 13.00 | C33: 25 | D33: 13 | E33: 0 | F33: 7 | G33: 0 | H33: 0 | I33: 3 | J33: 0 | K33: 0 | L33: 0 | M33: 54 | N33: 0 | O33: =SUM(C33:L33,N33) -> 48 | P33: =SUM(C33:N33) -> 102
B34: 13.00 - 13.15 | C34: 23 | D34: 6 | E34: 1 | F34: 3 | G34: 0 | H34: 0 | I34: 0 | J34: 3 | K34: 0 | L34: 0 | M34: 60 | N34: 0 | O34: =SUM(C34:L34,N34) -> 36 | P34: =SUM(C34:N34) -> 96
B35: 13.15 - 13.30 | C35: 14 | D35: 11 | E35: 1 | F35: 11 | G35: 0 | H35: 0 | I35: 2 | J35: 1 | K35: 0 | L35: 0 | M35: 61 | N35: 0 | O35: =SUM(C35:L35,N35) -> 40 | P35: =SUM(C35:N35) -> 101
B36: 13.30 - 13.45 | C36: 18 | D36: 11 | E36: 2 | F36: 8 | G36: 0 | H36: 0 | I36: 0 | J36: 0 | K36: 1 | L36: 0 | M36: 53 | N36: 0 | O36: =SUM(C36:L36,N36) -> 40 | P36: =SUM(C36:N36) -> 93
B37: 13.45 - 14.00 | C37: 24 | D37: 6 | E37: 1 | F37: 12 | G37: 0 | H37: 0 | I37: 1 | J37: 0 | K37: 0 | L37: 0 | M37: 53 | N37: 0 | O37: =SUM(C37:L37,N37) -> 44 | P37: =SUM(C37:N37) -> 97
B38: 14.00 - 14.15 | C38: 21 | D38: 11 | E38: 0 | F38: 11 | G38: 0 | H38: 0 | I38: 1 | J38: 0 | K38: 0 | L38: 0 | M38: 67 | N38: 0 | O38: =SUM(C38:L38,N38) -> 44 | P38: =SUM(C38:N38) -> 111
B39: 14.15 - 14.30 | C39: 26 | D39: 16 | E39: 3 | F39: 9 | G39: 0 | H39: 0 | I39: 2 | J39: 0 | K39: 0 | L39: 0 | M39: 69 | N39: 0 | O39: =SUM(C39:L39,N39) -> 56 | P39: =SUM(C39:N39) -> 125
B40: 14.30 - 14.45 | C40: 27 | D40: 7 | E40: 1 | F40: 6 | G40: 0 | H40: 0 | I40: 0 | J40: 0 | K40: 0 | L40: 0 | M40: 70 | N40: 0 | O40: =SUM(C40:L40,N40) -> 41 | P40: =SUM(C40:N40) -> 111
... B57: 18.45 - 19.00 | C57: 19 | D57: 6 | E57: 4 | F57: 4 | G57: 0 | H57: 0 | I57: 3 | J57: 6 | K57: 0 | L57: 0 | M57: 105 | N57: 0 | O57: =SUM(C57:L57,N57) -> 42 | P57: =SUM(C57:N57) -> 147
B58: Totals | C58: =SUM(C10:C57) -> 1545 | D58: =SUM(D10:D57) -> 776 | E58: =SUM(E10:E57) -> 75 | F58: =SUM(F10:F57) -> 439 | G58: =SUM(G10:G57) -> 7 | H58: =SUM(H10:H57) -> 1 | I58: =SUM(I10:I57) -> 104 | J58: =SUM(J10:J57) -> 20 | ... P58: =SUM(P10:P57) -> 5979
...

Sheet 29.07 Bukoto-Kisasi
B1: Consultancy services for Preparation of Expressway Development Master Plan (EDMP) for Uganda
B2: MANUAL CLASSIFIED COUNT (MCC)
B3: ROAD NAME: | C3: ='29.07 Kisasi-Bukoto'!C3:G3 -> MCC - C1 - STN32 - BUKOTO KISASI ROAD
C5: Date | D5: ='29.07 Kisasi-Bukoto'!D5 -> 29.07.19 | F5: Location | G5: ='29.07 Kisasi-Bukoto'!G5:H5 -> KISASI | J5: Surveyor | K5: ='29.07 Kisasi-Bukoto'!K5:L5 -> RWAMBITITO J./NICHOL A./GEORGE W.
C6: Dir. From | D6: BUKOTO | F6: Dir. To | G6: KISASI | J6: Supervisor | K6: ='29.07 Kisasi-Bukoto'!K6:L6 -> SALIMA L.
B8: Time / Veh Type | R8: SUMMARY TRAFFIC VOLUMES
C9: 1. Car | D9: 2. Station Wagon | E9: 3. Pickups | F9: 4. Minibus, matatu | G9: 5. Medium bus | H9: 6. Large Bus | I9: 7. Light Truck | J9: 8. Medium Truck | K9: 9. Heavy truck | L9: 10. Truck Trailer | M9: 11. Motor cycles | N9: 12. Tractors | O9: Total Excl M/Cycles | P9: Total All | R9: Time | S9: 1. Car | T9: 2. Station Wagon | U9: 3. Pickups | V9: 4. Minibus, matatu | W9: 5. Medium bus | X9: 6. Large Bus | Y9: 7. Light Truck | Z9: 8. Medium Truck | AA9: 9. Heavy truck | AB9: 10. Truck Trailer | AC9: 11. Motorcycles | AD9: 12. Tractors, Graders | AE9: Total Excl M/ Cycles | AF9: Total All
B10: 07.00 - 07.15 | C10: 5 | D10: 7 | E10: 2 | F10: 3 | G10: 0 | H10: 0 | I10: 0 | J10: 0 | K10: 0 | L10: 0 | M10: 37 | N10: 0 | O10: =SUM(C10:L10,N10) -> 17 | P10: =SUM(C10:N10) -> 54 | R10: 0700-0800 | S10: =SUM(C10:C13) -> 55 | T10: =SUM(D10:D13) -> 55 | U10: =SUM(E10:E13) -> 19 | V10: =SUM(F10:F13) -> 29 | W10: =SUM(G10:G13) -> 0 | X10: =SUM(H10:H13) -> 0 | Y10: =SUM(I10:I13) -> 7 | Z10: =SUM(J10:J13) -> 0 | ... AF10: =SUM(P10:P13) -> 403
B11: 07.15 - 07.30 | C11: 12 | D11: 19 | E11: 6 | F11: 11 | G11: 0 | H11: 0 | I11: 1 | J11: 0 | K11: 0 | L11: 0 | M11: 41 | N11: 0 | O11: =SUM(C11:L11,N11) -> 49 | P11: =SUM(C11:N11) -> 90 | R11: 0800-0900 | S11: =SUM(C14:C17) -> 91 | T11: =SUM(D14:D17) -> 32 | U11: =SUM(E14:E17) -> 34 | V11: =SUM(F14:F17) -> 40 | W11: =SUM(G14:G17) -> 1 | X11: =SUM(H14:H17) -> 0 | Y11: =SUM(I14:I17) -> 4 | Z11: =SUM(J14:J17) -> 0 | ... AF11: =SUM(P14:P17) -> 575
B12: 07.30 - 07.45 | C12: 18 | D12: 16 | E12: 4 | F12: 8 | G12: 0 | H12: 0 | I12: 4 | J12: 0 | K12: 0 | L12: 0 | M12: 73 | N12: 0 | O12: =SUM(C12:L12,N12) -> 50 | P12: =SUM(C12:N12) -> 123 | R12: 0900-1000 | S12: =SUM(C18:C21) -> 69 | T12: =SUM(D18:D21) -> 25 | U12: =SUM(E18:E21) -> 24 | V12: =SUM(F18:F21) -> 16 | W12: =SUM(G18:G21) -> 0 | X12: =SUM(H18:H21) -> 0 | Y12: =SUM(I18:I21) -> 12 | Z12: =SUM(J18:J21) -> 3 | ... AF12: =SUM(P18:P21) -> 478
B13: 07.45 - 08.00 | C13: 20 | D13: 13 | E13: 7 | F13: 7 | G13: 0 | H13: 0 | I13: 2 | J13: 0 | K13: 0 | L13: 0 | M13: 87 | N13: 0 | O13: =SUM(C13:L13,N13) -> 49 | P13: =SUM(C13:N13) -> 136 | R13: 1000-1100 | S13: =SUM(C22:C25) -> 51 | T13: =SUM(D22:D25) -> 33 | U13: =SUM(E22:E25) -> 17 | V13: =SUM(F22:F25) -> 24 | W13: =SUM(G22:G25) -> 0 | X13: =SUM(H22:H25) -> 0 | Y13: =SUM(I22:I25) -> 5 | Z13: =SUM(J22:J25) -> 5 | ... AF13: =SUM(P22:P25) -> 382
B14: 08.00 - 08.15 | C14: 23 | D14: 8 | E14: 6 | F14: 12 | G14: 0 | H14: 0 | I14: 0 | J14: 0 | K14: 0 | L14: 0 | M14: 92 | N14: 0 | O14: =SUM(C14:L14,N14) -> 49 | P14: =SUM(C14:N14) -> 141 | R14: 1100-1200 | S14: =SUM(C26:C29) -> 55 | T14: =SUM(D26:D29) -> 22 | U14: =SUM(E26:E29) -> 21 | V14: =SUM(F26:F29) -> 23 | W14: =SUM(G26:G29) -> 0 | X14: =SUM(H26:H29) -> 0 | Y14: =SUM(I26:I29) -> 9 | Z14: =SUM(J26:J29) -> 4 | ... AF14: =SUM(P26:P29) -> 337
B15: 08.15 - 08.30 | C15: 18 | D15: 6 | E15: 8 | F15: 9 | G15: 0 | H15: 0 | I15: 3 | J15: 0 | K15: 0 | L15: 0 | M15: 89 | N15: 0 | O15: =SUM(C15:L15,N15) -> 44 | P15: =SUM(C15:N15) -> 133 | R15: 1200-1300 | S15: =SUM(C30:C33) -> 52 | T15: =SUM(D30:D33) -> 25 | U15: =SUM(E30:E33) -> 16 | V15: =SUM(F30:F33) -> 25 | W15: =SUM(G30:G33) -> 0 | X15: =SUM(H30:H33) -> 0 | Y15: =SUM(I30:I33) -> 10 | Z15: =SUM(J30:J33) -> 1 | ... AF15: =SUM(P30:P33) -> 264
B16: 08.30 - 08.45 | C16: 26 | D16: 10 | E16: 9 | F16: 11 | G16: 0 | H16: 0 | I16: 1 | J16: 0 | K16: 0 | L16: 0 | M16: 94 | N16: 0 | O16: =SUM(C16:L16,N16) -> 57 | P16: =SUM(C16:N16) -> 151 | R16: 1300-1400 | S16: =SUM(C34:C37) -> 39 | T16: =SUM(D34:D37) -> 33 | U16: =SUM(E34:E37) -> 15 | V16: =SUM(F34:F37) -> 21 | W16: =SUM(G34:G37) -> 0 | X16: =SUM(H34:H37) -> 0 | Y16: =SUM(I34:I37) -> 6 | Z16: =SUM(J34:J37) -> 0 | ... AF16: =SUM(P34:P37) -> 239
B17: 08.45 - 9.00 | C17: 24 | D17: 8 | E17: 11 | F17: 8 | G17: 1 | H17: 0 | I17: 0 | J17: 0 | K17: 0 | L17: 0 | M17: 98 | N17: 0 | O17: =SUM(C17:L17,N17) -> 52 | P17: =SUM(C17:N17) -> 150 | R17: 1400-1500 | S17: =SUM(C38:C41) -> 47 | T17: =SUM(D38:D41) -> 22 | U17: =SUM(E38:E41) -> 14 | V17: =SUM(F38:F41) -> 22 | W17: =SUM(G38:G41) -> 0 | X17: =SUM(H38:H41) -> 0 | Y17: =SUM(I38:I41) -> 6 | Z17: =SUM(J38:J41) -> 1 | ... AF17: =SUM(P38:P41) -> 248
B18: 09.00 - 09.15 | C18: 21 | D18: 6 | E18: 9 | F18: 5 | G18: 0 | H18: 0 | I18: 2 | J18: 0 | K18: 0 | L18: 0 | M18: 98 | N18: 0 | O18: =SUM(C18:L18,N18) -> 43 | P18: =SUM(C18:N18) -> 141 | R18: 1500-1600 | S18: =SUM(C42:C45) -> 76 | T18: =SUM(D42:D45) -> 29 | U18: =SUM(E42:E45) -> 25 | V18: =SUM(F42:F45) -> 20 | W18: =SUM(G42:G45) -> 0 | X18: =SUM(H42:H45) -> 0 | Y18: =SUM(I42:I45) -> 10 | Z18: =SUM(J42:J45) -> 3 | ... AF18: =SUM(P42:P45) -> 299
B19: 09.15 - 09.30 | C19: 18 | D19: 8 | E19: 6 | F19: 3 | G19: 0 | H19: 0 | I19: 3 | J19: 1 | K19: 0 | L19: 0 | M19: 82 | N19: 0 | O19: =SUM(C19:L19,N19) -> 39 | P19: =SUM(C19:N19) -> 121 | R19: 1600-1700 | S19: =SUM(C46:C49) -> 231 | T19: =SUM(D46:D49) -> 109 | U19: =SUM(E46:E49) -> 53 | V19: =SUM(F46:F49) -> 48 | W19: =SUM(G46:G49) -> 2 | X19: =SUM(H46:H49) -> 1 | Y19: =SUM(I46:I49) -> 11 | Z19: =SUM(J46:J49) -> 6 | ... AF19: =SUM(P46:P49) -> 641
B20: 09.30 - 09.45 | C20: 16 | D20: 6 | E20: 4 | F20: 5 | G20: 0 | H20: 0 | I20: 2 | J20: 1 | K20: 0 | L20: 0 | M20: 77 | N20: 0 | O20: =SUM(C20:L20,N20) -> 34 | P20: =SUM(C20:N20) -> 111 | R20: 1700-1800 | S20: =SUM(C50:C53) -> 390 | T20: =SUM(D50:D53) -> 173 | U20: =SUM(E50:E53) -> 65 | V20: =SUM(F50:F53) -> 43 | W20: =SUM(G50:G53) -> 2 | X20: =SUM(H50:H53) -> 0 | Y20: =SUM(I50:I53) -> 14 | Z20: =SUM(J50:J53) -> 2 | ... AF20: =SUM(P50:P53) -> 865
B21: 09.45 - 10.00 | C21: 14 | D21: 5 | E21: 5 | F21: 3 | G21: 0 | H21: 0 | I21: 5 | J21: 1 | K21: 0 | L21: 0 | M21: 72 | N21: 0 | O21: =SUM(C21:L21,N21) -> 33 | P21: =SUM(C21:N21) -> 105 | R21: 1800-1900 | S21: =SUM(C54:C57) -> 368 | T21: =SUM(D54:D57) -> 146 | U21: =SUM(E54:E57) -> 49 | V21: =SUM(F54:F57) -> 51 | W21: =SUM(G54:G57) -> 0 | X21: =SUM(H54:H57) -> 0 | Y21: =SUM(I54:I57) -> 7 | Z21: =SUM(J54:J57) -> 0 | ... AF21: =SUM(P54:P57) -> 831
B22: 10.00 - 10.15 | C22: 13 | D22: 6 | E22: 3 | F22: 5 | G22: 0 | H22: 0 | I22: 2 | J22: 1 | K22: 0 | L22: 0 | M22: 68 | N22: 0 | O22: =SUM(C22:L22,N22) -> 30 | P22: =SUM(C22:N22) -> 98 | R22: AM Peak Hr | S22: =MAX(S10:S12) -> 91 | T22: =MAX(T10:T12) -> 55 | U22: =MAX(U10:U12) -> 34 | V22: =MAX(V10:V12) -> 40 | W22: =MAX(W10:W12) -> 1 | X22: =MAX(X10:X12) -> 0 | Y22: =MAX(Y10:Y12) -> 12 | Z22: =MAX(Z10:Z12) -> 3 | ... AF22: =MAX(AF10:AF12) -> 575
B23: 10.15 - 10.30 | C23: 10 | D23: 13 | E23: 2 | F23: 4 | G23: 0 | H23: 0 | I23: 1 | J23: 1 | K23: 0 | L23: 0 | M23: 62 | N23: 0 | O23: =SUM(C23:L23,N23) -> 31 | P23: =SUM(C23:N23) -> 93 | R23: IP Peak Hr | S23: =MAX(S13:S18) -> 76 | T23: =MAX(T13:T18) -> 33 | U23: =MAX(U13:U18) -> 25 | V23: =MAX(V13:V18) -> 25 | W23: =MAX(W13:W18) -> 0 | X23: =MAX(X13:X18) -> 0 | Y23: =MAX(Y13:Y18) -> 10 | Z23: =MAX(Z13:Z18) -> 5 | ... AF23: =MAX(AF13:AF18) -> 382
B24: 10.30 - 10.45 | C24: 12 | D24: 9 | E24: 5 | F24: 8 | G24: 0 | H24: 0 | I24: 2 | J24: 2 | K24: 0 | L24: 0 | M24: 57 | N24: 0 | O24: =SUM(C24:L24,N24) -> 38 | P24: =SUM(C24:N24) -> 95 | R24: PM Peak Hr | S24: =MAX(S19:S21) -> 390 | T24: =MAX(T19:T21) -> 173 | U24: =MAX(U19:U21) -> 65 | V24: =MAX(V19:V21) -> 51 | W24: =MAX(W19:W21) -> 2 | X24: =MAX(X19:X21) -> 1 | Y24: =MAX(Y19:Y21) -> 14 | Z24: =MAX(Z19:Z21) -> 6 | ... AF24: =MAX(AF19:AF21) -> 865
B25: 10.45 - 11.00 | C25: 16 | D25: 5 | E25: 7 | F25: 7 | G25: 0 | H25: 0 | I25: 0 | J25: 1 | K25: 0 | L25: 0 | M25: 60 | N25: 0 | O25: =SUM(C25:L25,N25) -> 36 | P25: =SUM(C25:N25) -> 96 | R25: AM Period | S25: =SUM(S10:S12) -> 215 | T25: =SUM(T10:T12) -> 112 | U25: =SUM(U10:U12) -> 77 | V25: =SUM(V10:V12) -> 85 | W25: =SUM(W10:W12) -> 1 | X25: =SUM(X10:X12) -> 0 | Y25: =SUM(Y10:Y12) -> 23 | Z25: =SUM(Z10:Z12) -> 3 | ... AF25: =SUM(AF10:AF12) -> 1456
B26: 11.00 - 11.15 | C26: 13 | D26: 3 | E26: 6 | F26: 4 | G26: 0 | H26: 0 | I26: 2 | J26: 1 | K26: 0 | L26: 0 | M26: 58 | N26: 0 | O26: =SUM(C26:L26,N26) -> 29 | P26: =SUM(C26:N26) -> 87 | R26: IP Period | S26: =SUM(S13:S18) -> 320 | T26: =SUM(T13:T18) -> 164 | U26: =SUM(U13:U18) -> 108 | V26: =SUM(V13:V18) -> 135 | W26: =SUM(W13:W18) -> 0 | X26: =SUM(X13:X18) -> 0 | Y26: =SUM(Y13:Y18) -> 46 | Z26: =SUM(Z13:Z18) -> 14 | ... AF26: =SUM(AF13:AF18) -> 1769
B27: 11.15 - 11.30 | C27: 16 | D27: 8 | E27: 9 | F27: 6 | G27: 0 | H27: 0 | I27: 1 | J27: 3 | K27: 0 | L27: 0 | M27: 64 | N27: 0 | O27: =SUM(C27:L27,N27) -> 43 | P27: =SUM(C27:N27) -> 107 | R27: PM Period | S27: =SUM(S19:S21) -> 989 | T27: =SUM(T19:T21) -> 428 | U27: =SUM(U19:U21) -> 167 | V27: =SUM(V19:V21) -> 142 | W27: =SUM(W19:W21) -> 4 | X27: =SUM(X19:X21) -> 1 | Y27: =SUM(Y19:Y21) -> 32 | Z27: =SUM(Z19:Z21) -> 8 | ... AF27: =SUM(AF19:AF21) -> 2337
B28: 11.30 - 11.45 | C28: 11 | D28: 6 | E28: 4 | F28: 9 | G28: 0 | H28: 0 | I28: 4 | J28: 0 | K28: 0 | L28: 0 | M28: 48 | N28: 0 | O28: =SUM(C28:L28,N28) -> 34 | P28: =SUM(C28:N28) -> 82 | R28: 12 Hours | S28: =SUM(S10:S21) -> 1524 | T28: =SUM(T10:T21) -> 704 | U28: =SUM(U10:U21) -> 352 | V28: =SUM(V10:V21) -> 362 | W28: =SUM(W10:W21) -> 5 | X28: =SUM(X10:X21) -> 1 | Y28: =SUM(Y10:Y21) -> 101 | Z28: =SUM(Z10:Z21) -> 25 | ... AF28: =SUM(AF10:AF21) -> 5562
B29: 11.45 - 12.00 | C29: 15 | D29: 5 | E29: 2 | F29: 4 | G29: 0 | H29: 0 | I29: 2 | J29: 0 | K29: 0 | L29: 0 | M29: 33 | N29: 0 | O29: =SUM(C29:L29,N29) -> 28 | P29: =SUM(C29:N29) -> 61
B30: 12.00 - 12.15 | C30: 13 | D30: 3 | E30: 4 | F30: 5 | G30: 0 | H30: 0 | I30: 1 | J30: 1 | K30: 0 | L30: 0 | M30: 30 | N30: 0 | O30: =SUM(C30:L30,N30) -> 27 | P30: =SUM(C30:N30) -> 57
B31: 12.15 - 12.30 | C31: 15 | D31: 6 | E31: 3 | F31: 7 | G31: 0 | H31: 0 | I31: 5 | J31: 0 | K31: 0 | L31: 0 | M31: 37 | N31: 0 | O31: =SUM(C31:L31,N31) -> 36 | P31: =SUM(C31:N31) -> 73
B32: 12.30 - 12.45 | C32: 13 | D32: 9 | E32: 5 | F32: 7 | G32: 0 | H32: 0 | I32: 2 | J32: 0 | K32: 0 | L32: 0 | M32: 32 | N32: 0 | O32: =SUM(C32:L32,N32) -> 36 | P32: =SUM(C32:N32) -> 68
B33: 12.45 - 13.00 | C33: 11 | D33: 7 | E33: 4 | F33: 6 | G33: 0 | H33: 0 | I33: 2 | J33: 0 | K33: 0 | L33: 0 | M33: 36 | N33: 0 | O33: =SUM(C33:L33,N33) -> 30 | P33: =SUM(C33:N33) -> 66
B34: 13.00 - 13.15 | C34: 9 | D34: 5 | E34: 3 | F34: 6 | G34: 0 | H34: 0 | I34: 2 | J34: 0 | K34: 1 | L34: 0 | M34: 31 | N34: 0 | O34: =SUM(C34:L34,N34) -> 26 | P34: =SUM(C34:N34) -> 57
B35: 13.15 - 13.30 | C35: 12 | D35: 8 | E35: 4 | F35: 5 | G35: 0 | H35: 0 | I35: 3 | J35: 0 | K35: 0 | L35: 0 | M35: 29 | N35: 0 | O35: =SUM(C35:L35,N35) -> 32 | P35: =SUM(C35:N35) -> 61
B36: 13.30 - 13.45 | C36: 10 | D36: 11 | E36: 5 | F36: 3 | G36: 0 | H36: 0 | I36: 1 | J36: 0 | K36: 0 | L36: 0 | M36: 33 | N36: 0 | O36: =SUM(C36:L36,N36) -> 30 | P36: =SUM(C36:N36) -> 63
B37: 13.45 - 14.00 | C37: 8 | D37: 9 | E37: 3 | F37: 7 | G37: 0 | H37: 0 | I37: 0 | J37: 0 | K37: 0 | L37: 0 | M37: 31 | N37: 0 | O37: =SUM(C37:L37,N37) -> 27 | P37: =SUM(C37:N37) -> 58
B38: 14.00 - 14.15 | C38: 10 | D38: 7 | E38: 4 | F38: 6 | G38: 0 | H38: 0 | I38: 2 | J38: 0 | K38: 1 | L38: 0 | M38: 34 | N38: 0 | O38: =SUM(C38:L38,N38) -> 30 | P38: =SUM(C38:N38) -> 64
B39: 14.15 - 14.30 | C39: 13 | D39: 5 | E39: 3 | F39: 4 | G39: 0 | H39: 0 | I39: 1 | J39: 0 | K39: 0 | L39: 0 | M39: 31 | N39: 0 | O39: =SUM(C39:L39,N39) -> 26 | P39: =SUM(C39:N39) -> 57
B40: 14.30 - 14.45 | C40: 10 | D40: 4 | E40: 5 | F40: 7 | G40: 0 | H40: 0 | I40: 3 | J40: 1 | K40: 0 | L40: 0 | M40: 36 | N40: 0 | O40: =SUM(C40:L40,N40) -> 30 | P40: =SUM(C40:N40) -> 66
... B57: 18.45 - 19.00 | C57: 88 | D57: 33 | E57: 8 | F57: 10 | G57: 0 | H57: 0 | I57: 0 | J57: 0 | K57: 0 | L57: 0 | M57: 48 | N57: 0 | O57: =SUM(C57:L57,N57) -> 139 | P57: =SUM(C57:N57) -> 187
B58: Totals | C58: =SUM(C10:C57) -> 1524 | D58: =SUM(D10:D57) -> 704 | E58: =SUM(E10:E57) -> 352 | F58: =SUM(F10:F57) -> 362 | G58: =SUM(G10:G57) -> 5 | H58: =SUM(H10:H57) -> 1 | I58: =SUM(I10:I57) -> 101 | J58: =SUM(J10:J57) -> 25 | ... P58: =SUM(P10:P57) -> 5562
...

Sheet 30.07 Kisasi-Bukoto
B1: Consultancy services for Preparation of Expressway Development Master Plan (EDMP) for Uganda
B2: MANUAL CLASSIFIED COUNT (MCC)
B3: ROAD NAME: | C3: ='29.07 Kisasi-Bukoto'!C3:G3 -> MCC - C1 - STN32 - BUKOTO KISASI ROAD
C5: Date | D5: 30.07.19 | F5: Location | G5: ='29.07 Kisasi-Bukoto'!G5:H5 -> KISASI | J5: Surveyor | K5: ='29.07 Kisasi-Bukoto'!K5:L5 -> RWAMBITITO J./NICHOL A./GEORGE W.
C6: Dir. From | D6: ='29.07 Kisasi-Bukoto'!D6:E6 -> KISASI | F6: Dir. To | G6: ='29.07 Kisasi-Bukoto'!G6:H6 -> BUKOTO | J6: Supervisor | K6: ='29.07 Kisasi-Bukoto'!K6:L6 -> SALIMA L.
B8: Time / Veh Type | R8: SUMMARY TRAFFIC VOLUMES
C9: 1. Car | D9: 2. Station Wagon | E9: 3. Pickups | F9: 4. Minibus, matatu | G9: 5. Medium bus | H9: 6. Large Bus | I9: 7. Light Truck | J9: 8. Medium Truck | K9: 9. Heavy truck | L9: 10. Truck Trailer | M9: 11. Motor cycles | N9: 12. Tractors | O9: Total Excl M/Cycles | P9: Total All | R9: Time | S9: 1. Car | T9: 2. Station Wagon | U9: 3. Pickups | V9: 4. Minibus, matatu | W9: 5. Medium bus | X9: 6. Large Bus | Y9: 7. Light Truck | Z9: 8. Medium Truck | AA9: 9. Heavy truck | AB9: 10. Truck Trailer | AC9: 11. Motorcycles | AD9: 12. Tractors, Graders | AE9: Total Excl M/ Cycles | AF9: Total All
B10: 07.00 - 07.15 | C10: 70 | D10: 43 | E10: 6 | F10: 18 | G10: 1 | H10: 0 | I10: 2 | J10: 0 | K10: 0 | L10: 0 | M10: 133 | N10: 0 | O10: =SUM(C10:L10,N10) -> 140 | P10: =SUM(C10:N10) -> 273 | R10: 0700-0800 | S10: =SUM(C10:C13) -> 291 | T10: =SUM(D10:D13) -> 143 | U10: =SUM(E10:E13) -> 30 | V10: =SUM(F10:F13) -> 66 | W10: =SUM(G10:G13) -> 1 | X10: =SUM(H10:H13) -> 0 | Y10: =SUM(I10:I13) -> 5 | Z10: =SUM(J10:J13) -> 2 | ... AF10: =SUM(P10:P13) -> 950
B11: 07.15 - 07.30 | C11: 80 | D11: 46 | E11: 13 | F11: 20 | G11: 0 | H11: 0 | I11: 1 | J11: 0 | K11: 0 | L11: 0 | M11: 109 | N11: 0 | O11: =SUM(C11:L11,N11) -> 160 | P11: =SUM(C11:N11) -> 269 | R11: 0800-0900 | S11: =SUM(C14:C17) -> 241 | T11: =SUM(D14:D17) -> 134 | U11: =SUM(E14:E17) -> 24 | V11: =SUM(F14:F17) -> 52 | W11: =SUM(G14:G17) -> 0 | X11: =SUM(H14:H17) -> 0 | Y11: =SUM(I14:I17) -> 7 | Z11: =SUM(J14:J17) -> 0 | ... AF11: =SUM(P14:P17) -> 883
B12: 07.30 - 07.45 | C12: 46 | D12: 13 | E12: 8 | F12: 8 | G12: 0 | H12: 0 | I12: 2 | J12: 1 | K12: 0 | L12: 0 | M12: 72 | N12: 0 | O12: =SUM(C12:L12,N12) -> 78 | P12: =SUM(C12:N12) -> 150 | R12: 0900-1000 | S12: =SUM(C18:C21) -> 187 | T12: =SUM(D18:D21) -> 88 | U12: =SUM(E18:E21) -> 12 | V12: =SUM(F18:F21) -> 46 | W12: =SUM(G18:G21) -> 0 | X12: =SUM(H18:H21) -> 1 | Y12: =SUM(I18:I21) -> 7 | Z12: =SUM(J18:J21) -> 2 | ... AF12: =SUM(P18:P21) -> 628
B13: 07.45 - 08.00 | C13: 95 | D13: 41 | E13: 3 | F13: 20 | G13: 0 | H13: 0 | I13: 0 | J13: 1 | K13: 0 | L13: 0 | M13: 98 | N13: 0 | O13: =SUM(C13:L13,N13) -> 160 | P13: =SUM(C13:N13) -> 258 | R13: 1000-1100 | S13: =SUM(C22:C25) -> 135 | T13: =SUM(D22:D25) -> 69 | U13: =SUM(E22:E25) -> 13 | V13: =SUM(F22:F25) -> 46 | W13: =SUM(G22:G25) -> 0 | X13: =SUM(H22:H25) -> 0 | Y13: =SUM(I22:I25) -> 12 | Z13: =SUM(J22:J25) -> 0 | ... AF13: =SUM(P22:P25) -> 576
B14: 08.00 - 08.15 | C14: 84 | D14: 57 | E14: 7 | F14: 16 | G14: 0 | H14: 0 | I14: 3 | J14: 0 | K14: 0 | L14: 0 | M14: 108 | N14: 0 | O14: =SUM(C14:L14,N14) -> 167 | P14: =SUM(C14:N14) -> 275 | R14: 1100-1200 | S14: =SUM(C26:C29) -> 115 | T14: =SUM(D26:D29) -> 65 | U14: =SUM(E26:E29) -> 3 | V14: =SUM(F26:F29) -> 48 | W14: =SUM(G26:G29) -> 0 | X14: =SUM(H26:H29) -> 0 | Y14: =SUM(I26:I29) -> 5 | Z14: =SUM(J26:J29) -> 1 | ... AF14: =SUM(P26:P29) -> 472
B15: 08.15 - 08.30 | C15: 69 | D15: 30 | E15: 10 | F15: 13 | G15: 0 | H15: 0 | I15: 2 | J15: 0 | K15: 0 | L15: 0 | M15: 84 | N15: 0 | O15: =SUM(C15:L15,N15) -> 124 | P15: =SUM(C15:N15) -> 208 | R15: 1200-1300 | S15: =SUM(C30:C33) -> 98 | T15: =SUM(D30:D33) -> 58 | U15: =SUM(E30:E33) -> 6 | V15: =SUM(F30:F33) -> 37 | W15: =SUM(G30:G33) -> 0 | X15: =SUM(H30:H33) -> 0 | Y15: =SUM(I30:I33) -> 8 | Z15: =SUM(J30:J33) -> 0 | ... AF15: =SUM(P30:P33) -> 379
B16: 08.30 - 08.45 | C16: 54 | D16: 18 | E16: 2 | F16: 12 | G16: 0 | H16: 0 | I16: 1 | J16: 0 | K16: 0 | L16: 0 | M16: 120 | N16: 0 | O16: =SUM(C16:L16,N16) -> 87 | P16: =SUM(C16:N16) -> 207 | R16: 1300-1400 | S16: =SUM(C34:C37) -> 87 | T16: =SUM(D34:D37) -> 48 | U16: =SUM(E34:E37) -> 6 | V16: =SUM(F34:F37) -> 37 | W16: =SUM(G34:G37) -> 0 | X16: =SUM(H34:H37) -> 0 | Y16: =SUM(I34:I37) -> 9 | Z16: =SUM(J34:J37) -> 0 | ... AF16: =SUM(P34:P37) -> 416
B17: 08.45 - 9.00 | C17: 34 | D17: 29 | E17: 5 | F17: 11 | G17: 0 | H17: 0 | I17: 1 | J17: 0 | K17: 0 | L17: 0 | M17: 113 | N17: 0 | O17: =SUM(C17:L17,N17) -> 80 | P17: =SUM(C17:N17) -> 193 | R17: 1400-1500 | S17: =SUM(C38:C41) -> 102 | T17: =SUM(D38:D41) -> 46 | U17: =SUM(E38:E41) -> 5 | V17: =SUM(F38:F41) -> 34 | W17: =SUM(G38:G41) -> 1 | X17: =SUM(H38:H41) -> 0 | Y17: =SUM(I38:I41) -> 11 | Z17: =SUM(J38:J41) -> 5 | ... AF17: =SUM(P38:P41) -> 434
B18: 09.00 - 09.15 | C18: 47 | D18: 33 | E18: 5 | F18: 14 | G18: 0 | H18: 1 | I18: 2 | J18: 0 | K18: 0 | L18: 0 | M18: 75 | N18: 0 | O18: =SUM(C18:L18,N18) -> 102 | P18: =SUM(C18:N18) -> 177 | R18: 1500-1600 | S18: =SUM(C42:C45) -> 101 | T18: =SUM(D42:D45) -> 62 | U18: =SUM(E42:E45) -> 8 | V18: =SUM(F42:F45) -> 30 | W18: =SUM(G42:G45) -> 0 | X18: =SUM(H42:H45) -> 0 | Y18: =SUM(I42:I45) -> 14 | Z18: =SUM(J42:J45) -> 2 | ... AF18: =SUM(P42:P45) -> 487
B19: 09.15 - 09.30 | C19: 47 | D19: 27 | E19: 0 | F19: 10 | G19: 0 | H19: 0 | I19: 1 | J19: 2 | K19: 0 | L19: 0 | M19: 82 | N19: 0 | O19: =SUM(C19:L19,N19) -> 87 | P19: =SUM(C19:N19) -> 169 | R19: 1600-1700 | S19: =SUM(C46:C49) -> 97 | T19: =SUM(D46:D49) -> 63 | U19: =SUM(E46:E49) -> 4 | V19: =SUM(F46:F49) -> 29 | W19: =SUM(G46:G49) -> 1 | X19: =SUM(H46:H49) -> 0 | Y19: =SUM(I46:I49) -> 13 | Z19: =SUM(J46:J49) -> 0 | ... AF19: =SUM(P46:P49) -> 485
B20: 09.30 - 09.45 | C20: 48 | D20: 12 | E20: 3 | F20: 11 | G20: 0 | H20: 0 | I20: 3 | J20: 0 | K20: 0 | L20: 0 | M20: 53 | N20: 0 | O20: =SUM(C20:L20,N20) -> 77 | P20: =SUM(C20:N20) -> 130 | R20: 1700-1800 | S20: =SUM(C50:C53) -> 108 | T20: =SUM(D50:D53) -> 70 | U20: =SUM(E50:E53) -> 9 | V20: =SUM(F50:F53) -> 45 | W20: =SUM(G50:G53) -> 0 | X20: =SUM(H50:H53) -> 0 | Y20: =SUM(I50:I53) -> 9 | Z20: =SUM(J50:J53) -> 4 | ... AF20: =SUM(P50:P53) -> 585
B21: 09.45 - 10.00 | C21: 45 | D21: 16 | E21: 4 | F21: 11 | G21: 0 | H21: 0 | I21: 1 | J21: 0 | K21: 0 | L21: 0 | M21: 75 | N21: 0 | O21: =SUM(C21:L21,N21) -> 77 | P21: =SUM(C21:N21) -> 152 | R21: 1800-1900 | S21: =SUM(C54:C57) -> 66 | T21: =SUM(D54:D57) -> 50 | U21: =SUM(E54:E57) -> 6 | V21: =SUM(F54:F57) -> 38 | W21: =SUM(G54:G57) -> 3 | X21: =SUM(H54:H57) -> 0 | Y21: =SUM(I54:I57) -> 11 | Z21: =SUM(J54:J57) -> 2 | ... AF21: =SUM(P54:P57) -> 475
B22: 10.00 - 10.15 | C22: 48 | D22: 27 | E22: 7 | F22: 16 | G22: 0 | H22: 0 | I22: 4 | J22: 0 | K22: 0 | L22: 0 | M22: 79 | N22: 0 | O22: =SUM(C22:L22,N22) -> 102 | P22: =SUM(C22:N22) -> 181 | R22: AM Peak Hr | S22: =MAX(S10:S12) -> 291 | T22: =MAX(T10:T12) -> 143 | U22: =MAX(U10:U12) -> 30 | V22: =MAX(V10:V12) -> 66 | W22: =MAX(W10:W12) -> 1 | X22: =MAX(X10:X12) -> 1 | Y22: =MAX(Y10:Y12) -> 7 | Z22: =MAX(Z10:Z12) -> 2 | ... AF22: =MAX(AF10:AF12) -> 950
B23: 10.15 - 10.30 | C23: 30 | D23: 13 | E23: 1 | F23: 10 | G23: 0 | H23: 0 | I23: 2 | J23: 0 | K23: 0 | L23: 0 | M23: 80 | N23: 0 | O23: =SUM(C23:L23,N23) -> 56 | P23: =SUM(C23:N23) -> 136 | R23: IP Peak Hr | S23: =MAX(S13:S18) -> 135 | T23: =MAX(T13:T18) -> 69 | U23: =MAX(U13:U18) -> 13 | V23: =MAX(V13:V18) -> 48 | W23: =MAX(W13:W18) -> 1 | X23: =MAX(X13:X18) -> 0 | Y23: =MAX(Y13:Y18) -> 14 | Z23: =MAX(Z13:Z18) -> 5 | ... AF23: =MAX(AF13:AF18) -> 576
B24: 10.30 - 10.45 | C24: 33 | D24: 17 | E24: 3 | F24: 14 | G24: 0 | H24: 0 | I24: 0 | J24: 0 | K24: 0 | L24: 0 | M24: 77 | N24: 0 | O24: =SUM(C24:L24,N24) -> 67 | P24: =SUM(C24:N24) -> 144 | R24: PM Peak Hr | S24: =MAX(S19:S21) -> 108 | T24: =MAX(T19:T21) -> 70 | U24: =MAX(U19:U21) -> 9 | V24: =MAX(V19:V21) -> 45 | W24: =MAX(W19:W21) -> 3 | X24: =MAX(X19:X21) -> 0 | Y24: =MAX(Y19:Y21) -> 13 | Z24: =MAX(Z19:Z21) -> 4 | ... AF24: =MAX(AF19:AF21) -> 585
B25: 10.45 - 11.00 | C25: 24 | D25: 12 | E25: 2 | F25: 6 | G25: 0 | H25: 0 | I25: 6 | J25: 0 | K25: 0 | L25: 0 | M25: 65 | N25: 0 | O25: =SUM(C25:L25,N25) -> 50 | P25: =SUM(C25:N25) -> 115 | R25: AM Period | S25: =SUM(S10:S12) -> 719 | T25: =SUM(T10:T12) -> 365 | U25: =SUM(U10:U12) -> 66 | V25: =SUM(V10:V12) -> 164 | W25: =SUM(W10:W12) -> 1 | X25: =SUM(X10:X12) -> 1 | Y25: =SUM(Y10:Y12) -> 19 | Z25: =SUM(Z10:Z12) -> 4 | ... AF25: =SUM(AF10:AF12) -> 2461
B26: 11.00 - 11.15 | C26: 40 | D26: 14 | E26: 0 | F26: 11 | G26: 0 | H26: 0 | I26: 1 | J26: 0 | K26: 0 | L26: 0 | M26: 63 | N26: 0 | O26: =SUM(C26:L26,N26) -> 66 | P26: =SUM(C26:N26) -> 129 | R26: IP Period | S26: =SUM(S13:S18) -> 638 | T26: =SUM(T13:T18) -> 348 | U26: =SUM(U13:U18) -> 41 | V26: =SUM(V13:V18) -> 232 | W26: =SUM(W13:W18) -> 1 | X26: =SUM(X13:X18) -> 0 | Y26: =SUM(Y13:Y18) -> 59 | Z26: =SUM(Z13:Z18) -> 8 | ... AF26: =SUM(AF13:AF18) -> 2764
B27: 11.15 - 11.30 | C27: 26 | D27: 14 | E27: 1 | F27: 10 | G27: 0 | H27: 0 | I27: 2 | J27: 0 | K27: 0 | L27: 0 | M27: 59 | N27: 0 | O27: =SUM(C27:L27,N27) -> 53 | P27: =SUM(C27:N27) -> 112 | R27: PM Period | S27: =SUM(S19:S21) -> 271 | T27: =SUM(T19:T21) -> 183 | U27: =SUM(U19:U21) -> 19 | V27: =SUM(V19:V21) -> 112 | W27: =SUM(W19:W21) -> 4 | X27: =SUM(X19:X21) -> 0 | Y27: =SUM(Y19:Y21) -> 33 | Z27: =SUM(Z19:Z21) -> 6 | ... AF27: =SUM(AF19:AF21) -> 1545
B28: 11.30 - 11.45 | C28: 28 | D28: 15 | E28: 1 | F28: 13 | G28: 0 | H28: 0 | I28: 1 | J28: 1 | K28: 0 | L28: 0 | M28: 60 | N28: 0 | O28: =SUM(C28:L28,N28) -> 59 | P28: =SUM(C28:N28) -> 119 | R28: 12 Hours | S28: =SUM(S10:S21) -> 1628 | T28: =SUM(T10:T21) -> 896 | U28: =SUM(U10:U21) -> 126 | V28: =SUM(V10:V21) -> 508 | W28: =SUM(W10:W21) -> 6 | X28: =SUM(X10:X21) -> 1 | Y28: =SUM(Y10:Y21) -> 111 | Z28: =SUM(Z10:Z21) -> 18 | ... AF28: =SUM(AF10:AF21) -> 6770
B29: 11.45 - 12.00 | C29: 21 | D29: 22 | E29: 1 | F29: 14 | G29: 0 | H29: 0 | I29: 1 | J29: 0 | K29: 0 | L29: 0 | M29: 53 | N29: 0 | O29: =SUM(C29:L29,N29) -> 59 | P29: =SUM(C29:N29) -> 112
B30: 12.00 - 12.15 | C30: 24 | D30: 16 | E30: 0 | F30: 13 | G30: 0 | H30: 0 | I30: 3 | J30: 0 | K30: 1 | L30: 0 | M30: 34 | N30: 0 | O30: =SUM(C30:L30,N30) -> 57 | P30: =SUM(C30:N30) -> 91
B31: 12.15 - 12.30 | C31: 21 | D31: 10 | E31: 1 | F31: 8 | G31: 0 | H31: 0 | I31: 2 | J31: 0 | K31: 0 | L31: 0 | M31: 35 | N31: 0 | O31: =SUM(C31:L31,N31) -> 42 | P31: =SUM(C31:N31) -> 77
B32: 12.30 - 12.45 | C32: 25 | D32: 12 | E32: 3 | F32: 6 | G32: 0 | H32: 0 | I32: 3 | J32: 0 | K32: 0 | L32: 0 | M32: 55 | N32: 0 | O32: =SUM(C32:L32,N32) -> 49 | P32: =SUM(C32:N32) -> 104
B33: 12.45 - 13.00 | C33: 28 | D33: 20 | E33: 2 | F33: 10 | G33: 0 | H33: 0 | I33: 0 | J33: 0 | K33: 0 | L33: 0 | M33: 47 | N33: 0 | O33: =SUM(C33:L33,N33) -> 60 | P33: =SUM(C33:N33) -> 107
B34: 13.00 - 13.15 | C34: 22 | D34: 15 | E34: 3 | F34: 11 | G34: 0 | H34: 0 | I34: 3 | J34: 0 | K34: 0 | L34: 0 | M34: 57 | N34: 0 | O34: =SUM(C34:L34,N34) -> 54 | P34: =SUM(C34:N34) -> 111
B35: 13.15 - 13.30 | C35: 17 | D35: 7 | E35: 0 | F35: 8 | G35: 0 | H35: 0 | I35: 0 | J35: 0 | K35: 0 | L35: 0 | M35: 62 | N35: 0 | O35: =SUM(C35:L35,N35) -> 32 | P35: =SUM(C35:N35) -> 94
B36: 13.30 - 13.45 | C36: 16 | D36: 10 | E36: 1 | F36: 10 | G36: 0 | H36: 0 | I36: 4 | J36: 0 | K36: 0 | L36: 0 | M36: 63 | N36: 0 | O36: =SUM(C36:L36,N36) -> 41 | P36: =SUM(C36:N36) -> 104
B37: 13.45 - 14.00 | C37: 32 | D37: 16 | E37: 2 | F37: 8 | G37: 0 | H37: 0 | I37: 2 | J37: 0 | K37: 0 | L37: 0 | M37: 47 | N37: 0 | O37: =SUM(C37:L37,N37) -> 60 | P37: =SUM(C37:N37) -> 107
B38: 14.00 - 14.15 | C38: 30 | D38: 11 | E38: 0 | F38: 8 | G38: 1 | H38: 0 | I38: 2 | J38: 0 | K38: 0 | L38: 0 | M38: 75 | N38: 0 | O38: =SUM(C38:L38,N38) -> 52 | P38: =SUM(C38:N38) -> 127
B39: 14.15 - 14.30 | C39: 21 | D39: 15 | E39: 2 | F39: 7 | G39: 0 | H39: 0 | I39: 4 | J39: 0 | K39: 0 | L39: 0 | M39: 52 | N39: 0 | O39: =SUM(C39:L39,N39) -> 49 | P39: =SUM(C39:N39) -> 101
B40: 14.30 - 14.45 | C40: 24 | D40: 11 | E40: 2 | F40: 9 | G40: 0 | H40: 0 | I40: 2 | J40: 2 | K40: 0 | L40: 0 | M40: 53 | N40: 0 | O40: =SUM(C40:L40,N40) -> 50 | P40: =SUM(C40:N40) -> 103
... B57: 18.45 - 19.00 | C57: 14 | D57: 6 | E57: 2 | F57: 9 | G57: 0 | H57: 0 | I57: 3 | J57: 1 | K57: 0 | L57: 0 | M57: 67 | N57: 0 | O57: =SUM(C57:L57,N57) -> 35 | P57: =SUM(C57:N57) -> 102
B58: Totals | C58: =SUM(C10:C57) -> 1628 | D58: =SUM(D10:D57) -> 896 | E58: =SUM(E10:E57) -> 126 | F58: =SUM(F10:F57) -> 508 | G58: =SUM(G10:G57) -> 6 | H58: =SUM(H10:H57) -> 1 | I58: =SUM(I10:I57) -> 111 | J58: =SUM(J10:J57) -> 18 | ... P58: =SUM(P10:P57) -> 6770
...

Sheet 30.07 Bukoto-Kisasi
B1: Consultancy services for Preparation of Expressway Development Master Plan (EDMP) for Uganda
B2: MANUAL CLASSIFIED COUNT (MCC)
B3: ROAD NAME: | C3: ='29.07 Bukoto-Kisasi'!C3:G3 -> MCC - C1 - STN32 - BUKOTO KISASI ROAD
C5: Date | D5: ='30.07 Kisasi-Bukoto'!D5 -> 30.07.19 | F5: Location | G5: ='29.07 Kisasi-Bukoto'!G5:H5 -> KISASI | J5: Surveyor | K5: ='29.07 Kisasi-Bukoto'!K5:L5 -> RWAMBITITO J./NICHOL A./GEORGE W.
C6: Dir. From | D6: ='29.07 Bukoto-Kisasi'!D6:E6 -> BUKOTO | F6: Dir. To | G6: ='29.07 Bukoto-Kisasi'!G6:H6 -> KISASI | J6: Supervisor | K6: ='29.07 Kisasi-Bukoto'!K6:L6 -> SALIMA L.
B8: Time / Veh Type | R8: SUMMARY TRAFFIC VOLUMES
C9: 1. Car | D9: 2. Station Wagon | E9: 3. Pickups | F9: 4. Minibus, matatu | G9: 5. Medium bus | H9: 6. Large Bus | I9: 7. Light Truck | J9: 8. Medium Truck | K9: 9. Heavy truck | L9: 10. Truck Trailer | M9: 11. Motor cycles | N9: 12. Tractors | O9: Total Excl M/Cycles | P9: Total All | R9: Time | S9: 1. Car | T9: 2. Station Wagon | U9: 3. Pickups | V9: 4. Minibus, matatu | W9: 5. Medium bus | X9: 6. Large Bus | Y9: 7. Light Truck | Z9: 8. Medium Truck | AA9: 9. Heavy truck | AB9: 10. Truck Trailer | AC9: 11. Motorcycles | AD9: 12. Tractors, Graders | AE9: Total Excl M/ Cycles | AF9: Total All
B10: 07.00 - 07.15 | C10: 11 | D10: 7 | E10: 1 | F10: 3 | G10: 0 | H10: 0 | I10: 1 | J10: 0 | K10: 0 | L10: 0 | M10: 28 | N10: 0 | O10: =SUM(C10:L10,N10) -> 23 | P10: =SUM(C10:N10) -> 51 | R10: 0700-0800 | S10: =SUM(C10:C13) -> 46 | T10: =SUM(D10:D13) -> 25 | U10: =SUM(E10:E13) -> 11 | V10: =SUM(F10:F13) -> 20 | W10: =SUM(G10:G13) -> 1 | X10: =SUM(H10:H13) -> 0 | Y10: =SUM(I10:I13) -> 4 | Z10: =SUM(J10:J13) -> 1 | ... AF10: =SUM(P10:P13) -> 245
B11: 07.15 - 07.30 | C11: 14 | D11: 6 | E11: 4 | F11: 5 | G11: 0 | H11: 0 | I11: 2 | J11: 0 | K11: 0 | L11: 0 | M11: 36 | N11: 0 | O11: =SUM(C11:L11,N11) -> 31 | P11: =SUM(C11:N11) -> 67 | R11: 0800-0900 | S11: =SUM(C14:C17) -> 54 | T11: =SUM(D14:D17) -> 26 | U11: =SUM(E14:E17) -> 7 | V11: =SUM(F14:F17) -> 22 | W11: =SUM(G14:G17) -> 0 | X11: =SUM(H14:H17) -> 0 | Y11: =SUM(I14:I17) -> 4 | Z11: =SUM(J14:J17) -> 1 | ... AF11: =SUM(P14:P17) -> 252
B12: 07.30 - 07.45 | C12: 12 | D12: 4 | E12: 2 | F12: 7 | G12: 1 | H12: 0 | I12: 1 | J12: 0 | K12: 0 | L12: 0 | M12: 39 | N12: 0 | O12: =SUM(C12:L12,N12) -> 27 | P12: =SUM(C12:N12) -> 66 | R12: 0900-1000 | S12: =SUM(C18:C21) -> 36 | T12: =SUM(D18:D21) -> 21 | U12: =SUM(E18:E21) -> 11 | V12: =SUM(F18:F21) -> 17 | W12: =SUM(G18:G21) -> 0 | X12: =SUM(H18:H21) -> 0 | Y12: =SUM(I18:I21) -> 5 | Z12: =SUM(J18:J21) -> 1 | ... AF12: =SUM(P18:P21) -> 218
B13: 07.45 - 08.00 | C13: 9 | D13: 8 | E13: 4 | F13: 5 | G13: 0 | H13: 0 | I13: 0 | J13: 1 | K13: 0 | L13: 0 | M13: 34 | N13: 0 | O13: =SUM(C13:L13,N13) -> 27 | P13: =SUM(C13:N13) -> 61 | R13: 1000-1100 | S13: =SUM(C22:C25) -> 47 | T13: =SUM(D22:D25) -> 21 | U13: =SUM(E22:E25) -> 10 | V13: =SUM(F22:F25) -> 19 | W13: =SUM(G22:G25) -> 0 | X13: =SUM(H22:H25) -> 0 | Y13: =SUM(I22:I25) -> 13 | Z13: =SUM(J22:J25) -> 2 | ... AF13: =SUM(P22:P25) -> 242
B14: 08.00 - 08.15 | C14: 14 | D14: 6 | E14: 3 | F14: 4 | G14: 0 | H14: 0 | I14: 2 | J14: 0 | K14: 0 | L14: 0 | M14: 32 | N14: 0 | O14: =SUM(C14:L14,N14) -> 29 | P14: =SUM(C14:N14) -> 61 | R14: 1100-1200 | S14: =SUM(C26:C29) -> 35 | T14: =SUM(D26:D29) -> 19 | U14: =SUM(E26:E29) -> 5 | V14: =SUM(F26:F29) -> 15 | W14: =SUM(G26:G29) -> 0 | X14: =SUM(H26:H29) -> 0 | Y14: =SUM(I26:I29) -> 0 | Z14: =SUM(J26:J29) -> 1 | ... AF14: =SUM(P26:P29) -> 226
B15: 08.15 - 08.30 | C15: 18 | D15: 9 | E15: 1 | F15: 8 | G15: 0 | H15: 0 | I15: 1 | J15: 0 | K15: 0 | L15: 0 | M15: 29 | N15: 0 | O15: =SUM(C15:L15,N15) -> 37 | P15: =SUM(C15:N15) -> 66 | R15: 1200-1300 | S15: =SUM(C30:C33) -> 52 | T15: =SUM(D30:D33) -> 25 | U15: =SUM(E30:E33) -> 18 | V15: =SUM(F30:F33) -> 19 | W15: =SUM(G30:G33) -> 0 | X15: =SUM(H30:H33) -> 0 | Y15: =SUM(I30:I33) -> 12 | Z15: =SUM(J30:J33) -> 2 | ... AF15: =SUM(P30:P33) -> 265
B16: 08.30 - 08.45 | C16: 13 | D16: 7 | E16: 2 | F16: 4 | G16: 0 | H16: 0 | I16: 0 | J16: 1 | K16: 0 | L16: 0 | M16: 36 | N16: 0 | O16: =SUM(C16:L16,N16) -> 27 | P16: =SUM(C16:N16) -> 63 | R16: 1300-1400 | S16: =SUM(C34:C37) -> 54 | T16: =SUM(D34:D37) -> 24 | U16: =SUM(E34:E37) -> 18 | V16: =SUM(F34:F37) -> 23 | W16: =SUM(G34:G37) -> 0 | X16: =SUM(H34:H37) -> 0 | Y16: =SUM(I34:I37) -> 9 | Z16: =SUM(J34:J37) -> 1 | ... AF16: =SUM(P34:P37) -> 258
B17: 08.45 - 9.00 | C17: 9 | D17: 4 | E17: 1 | F17: 6 | G17: 0 | H17: 0 | I17: 1 | J17: 0 | K17: 0 | L17: 0 | M17: 41 | N17: 0 | O17: =SUM(C17:L17,N17) -> 21 | P17: =SUM(C17:N17) -> 62 | R17: 1400-1500 | S17: =SUM(C38:C41) -> 53 | T17: =SUM(D38:D41) -> 22 | U17: =SUM(E38:E41) -> 18 | V17: =SUM(F38:F41) -> 22 | W17: =SUM(G38:G41) -> 0 | X17: =SUM(H38:H41) -> 0 | Y17: =SUM(I38:I41) -> 6 | Z17: =SUM(J38:J41) -> 1 | ... AF17: =SUM(P38:P41) -> 259
B18: 09.00 - 09.15 | C18: 8 | D18: 4 | E18: 3 | F18: 5 | G18: 0 | H18: 0 | I18: 0 | J18: 0 | K18: 0 | L18: 0 | M18: 33 | N18: 0 | O18: =SUM(C18:L18,N18) -> 20 | P18: =SUM(C18:N18) -> 53 | R18: 1500-1600 | S18: =SUM(C42:C45) -> 66 | T18: =SUM(D42:D45) -> 34 | U18: =SUM(E42:E45) -> 28 | V18: =SUM(F42:F45) -> 27 | W18: =SUM(G42:G45) -> 0 | X18: =SUM(H42:H45) -> 0 | Y18: =SUM(I42:I45) -> 3 | Z18: =SUM(J42:J45) -> 0 | ... AF18: =SUM(P42:P45) -> 294
B19: 09.15 - 09.30 | C19: 5 | D19: 8 | E19: 2 | F19: 5 | G19: 0 | H19: 0 | I19: 1 | J19: 1 | K19: 0 | L19: 0 | M19: 29 | N19: 0 | O19: =SUM(C19:L19,N19) -> 22 | P19: =SUM(C19:N19) -> 51 | R19: 1600-1700 | S19: =SUM(C46:C49) -> 141 | T19: =SUM(D46:D49) -> 55 | U19: =SUM(E46:E49) -> 44 | V19: =SUM(F46:F49) -> 35 | W19: =SUM(G46:G49) -> 0 | X19: =SUM(H46:H49) -> 1 | Y19: =SUM(I46:I49) -> 8 | Z19: =SUM(J46:J49) -> 3 | ... AF19: =SUM(P46:P49) -> 419
B20: 09.30 - 09.45 | C20: 10 | D20: 3 | E20: 6 | F20: 3 | G20: 0 | H20: 0 | I20: 1 | J20: 0 | K20: 0 | L20: 0 | M20: 27 | N20: 0 | O20: =SUM(C20:L20,N20) -> 23 | P20: =SUM(C20:N20) -> 50 | R20: 1700-1800 | S20: =SUM(C50:C53) -> 322 | T20: =SUM(D50:D53) -> 121 | U20: =SUM(E50:E53) -> 53 | V20: =SUM(F50:F53) -> 50 | W20: =SUM(G50:G53) -> 0 | X20: =SUM(H50:H53) -> 0 | Y20: =SUM(I50:I53) -> 6 | Z20: =SUM(J50:J53) -> 3 | ... AF20: =SUM(P50:P53) -> 697
B21: 09.45 - 10.00 | C21: 13 | D21: 6 | E21: 0 | F21: 4 | G21: 0 | H21: 0 | I21: 3 | J21: 0 | K21: 0 | L21: 0 | M21: 38 | N21: 0 | O21: =SUM(C21:L21,N21) -> 26 | P21: =SUM(C21:N21) -> 64 | R21: 1800-1900 | S21: =SUM(C54:C57) -> 353 | T21: =SUM(D54:D57) -> 140 | U21: =SUM(E54:E57) -> 54 | V21: =SUM(F54:F57) -> 46 | W21: =SUM(G54:G57) -> 0 | X21: =SUM(H54:H57) -> 0 | Y21: =SUM(I54:I57) -> 8 | Z21: =SUM(J54:J57) -> 5 | ... AF21: =SUM(P54:P57) -> 749
B22: 10.00 - 10.15 | C22: 9 | D22: 3 | E22: 2 | F22: 3 | G22: 0 | H22: 0 | I22: 3 | J22: 1 | K22: 0 | L22: 0 | M22: 33 | N22: 0 | O22: =SUM(C22:L22,N22) -> 21 | P22: =SUM(C22:N22) -> 54 | R22: AM Peak Hr | S22: =MAX(S10:S12) -> 54 | T22: =MAX(T10:T12) -> 26 | U22: =MAX(U10:U12) -> 11 | V22: =MAX(V10:V12) -> 22 | W22: =MAX(W10:W12) -> 1 | X22: =MAX(X10:X12) -> 0 | Y22: =MAX(Y10:Y12) -> 5 | Z22: =MAX(Z10:Z12) -> 1 | ... AF22: =MAX(AF10:AF12) -> 252
B23: 10.15 - 10.30 | C23: 12 | D23: 6 | E23: 4 | F23: 7 | G23: 0 | H23: 0 | I23: 0 | J23: 0 | K23: 0 | L23: 0 | M23: 29 | N23: 0 | O23: =SUM(C23:L23,N23) -> 29 | P23: =SUM(C23:N23) -> 58 | R23: IP Peak Hr | S23: =MAX(S13:S18) -> 66 | T23: =MAX(T13:T18) -> 34 | U23: =MAX(U13:U18) -> 28 | V23: =MAX(V13:V18) -> 27 | W23: =MAX(W13:W18) -> 0 | X23: =MAX(X13:X18) -> 0 | Y23: =MAX(Y13:Y18) -> 13 | Z23: =MAX(Z13:Z18) -> 2 | ... AF23: =MAX(AF13:AF18) -> 294
B24: 10.30 - 10.45 | C24: 15 | D24: 9 | E24: 4 | F24: 6 | G24: 0 | H24: 0 | I24: 7 | J24: 1 | K24: 0 | L24: 0 | M24: 36 | N24: 0 | O24: =SUM(C24:L24,N24) -> 42 | P24: =SUM(C24:N24) -> 78 | R24: PM Peak Hr | S24: =MAX(S19:S21) -> 353 | T24: =MAX(T19:T21) -> 140 | U24: =MAX(U19:U21) -> 54 | V24: =MAX(V19:V21) -> 50 | W24: =MAX(W19:W21) -> 0 | X24: =MAX(X19:X21) -> 1 | Y24: =MAX(Y19:Y21) -> 8 | Z24: =MAX(Z19:Z21) -> 5 | ... AF24: =MAX(AF19:AF21) -> 749
B25: 10.45 - 11.00 | C25: 11 | D25: 3 | E25: 0 | F25: 3 | G25: 0 | H25: 0 | I25: 3 | J25: 0 | K25: 0 | L25: 0 | M25: 32 | N25: 0 | O25: =SUM(C25:L25,N25) -> 20 | P25: =SUM(C25:N25) -> 52 | R25: AM Period | S25: =SUM(S10:S12) -> 136 | T25: =SUM(T10:T12) -> 72 | U25: =SUM(U10:U12) -> 29 | V25: =SUM(V10:V12) -> 59 | W25: =SUM(W10:W12) -> 1 | X25: =SUM(X10:X12) -> 0 | Y25: =SUM(Y10:Y12) -> 13 | Z25: =SUM(Z10:Z12) -> 3 | ... AF25: =SUM(AF10:AF12) -> 715
B26: 11.00 - 11.15 | C26: 8 | D26: 4 | E26: 0 | F26: 3 | G26: 0 | H26: 0 | I26: 0 | J26: 1 | K26: 0 | L26: 0 | M26: 38 | N26: 0 | O26: =SUM(C26:L26,N26) -> 16 | P26: =SUM(C26:N26) -> 54 | R26: IP Period | S26: =SUM(S13:S18) -> 307 | T26: =SUM(T13:T18) -> 145 | U26: =SUM(U13:U18) -> 97 | V26: =SUM(V13:V18) -> 125 | W26: =SUM(W13:W18) -> 0 | X26: =SUM(X13:X18) -> 0 | Y26: =SUM(Y13:Y18) -> 43 | Z26: =SUM(Z13:Z18) -> 7 | ... AF26: =SUM(AF13:AF18) -> 1544
B27: 11.15 - 11.30 | C27: 6 | D27: 2 | E27: 2 | F27: 5 | G27: 0 | H27: 0 | I27: 0 | J27: 0 | K27: 0 | L27: 0 | M27: 42 | N27: 0 | O27: =SUM(C27:L27,N27) -> 15 | P27: =SUM(C27:N27) -> 57 | R27: PM Period | S27: =SUM(S19:S21) -> 816 | T27: =SUM(T19:T21) -> 316 | U27: =SUM(U19:U21) -> 151 | V27: =SUM(V19:V21) -> 131 | W27: =SUM(W19:W21) -> 0 | X27: =SUM(X19:X21) -> 1 | Y27: =SUM(Y19:Y21) -> 22 | Z27: =SUM(Z19:Z21) -> 11 | ... AF27: =SUM(AF19:AF21) -> 1865
B28: 11.30 - 11.45 | C28: 12 | D28: 9 | E28: 0 | F28: 3 | G28: 0 | H28: 0 | I28: 0 | J28: 0 | K28: 0 | L28: 0 | M28: 39 | N28: 0 | O28: =SUM(C28:L28,N28) -> 24 | P28: =SUM(C28:N28) -> 63 | R28: 12 Hours | S28: =SUM(S10:S21) -> 1259 | T28: =SUM(T10:T21) -> 533 | U28: =SUM(U10:U21) -> 277 | V28: =SUM(V10:V21) -> 315 | W28: =SUM(W10:W21) -> 1 | X28: =SUM(X10:X21) -> 1 | Y28: =SUM(Y10:Y21) -> 78 | Z28: =SUM(Z10:Z21) -> 21 | ... AF28: =SUM(AF10:AF21) -> 4124
B29: 11.45 - 12.00 | C29: 9 | D29: 4 | E29: 3 | F29: 4 | G29: 0 | H29: 0 | I29: 0 | J29: 0 | K29: 0 | L29: 0 | M29: 32 | N29: 0 | O29: =SUM(C29:L29,N29) -> 20 | P29: =SUM(C29:N29) -> 52
B30: 12.00 - 12.15 | C30: 10 | D30: 4 | E30: 6 | F30: 3 | G30: 0 | H30: 0 | I30: 3 | J30: 0 | K30: 0 | L30: 0 | M30: 28 | N30: 0 | O30: =SUM(C30:L30,N30) -> 26 | P30: =SUM(C30:N30) -> 54
B31: 12.15 - 12.30 | C31: 11 | D31: 8 | E31: 2 | F31: 5 | G31: 0 | H31: 0 | I31: 4 | J31: 0 | K31: 0 | L31: 0 | M31: 33 | N31: 0 | O31: =SUM(C31:L31,N31) -> 30 | P31: =SUM(C31:N31) -> 63
B32: 12.30 - 12.45 | C32: 17 | D32: 11 | E32: 4 | F32: 7 | G32: 0 | H32: 0 | I32: 2 | J32: 1 | K32: 0 | L32: 0 | M32: 37 | N32: 0 | O32: =SUM(C32:L32,N32) -> 42 | P32: =SUM(C32:N32) -> 79
B33: 12.45 - 13.00 | C33: 14 | D33: 2 | E33: 6 | F33: 4 | G33: 0 | H33: 0 | I33: 3 | J33: 1 | K33: 0 | L33: 0 | M33: 39 | N33: 0 | O33: =SUM(C33:L33,N33) -> 30 | P33: =SUM(C33:N33) -> 69
B34: 13.00 - 13.15 | C34: 11 | D34: 6 | E34: 5 | F34: 5 | G34: 0 | H34: 0 | I34: 2 | J34: 0 | K34: 0 | L34: 0 | M34: 34 | N34: 0 | O34: =SUM(C34:L34,N34) -> 29 | P34: =SUM(C34:N34) -> 63
B35: 13.15 - 13.30 | C35: 13 | D35: 4 | E35: 6 | F35: 7 | G35: 0 | H35: 0 | I35: 3 | J35: 0 | K35: 0 | L35: 0 | M35: 31 | N35: 0 | O35: =SUM(C35:L35,N35) -> 33 | P35: =SUM(C35:N35) -> 64
B36: 13.30 - 13.45 | C36: 17 | D36: 6 | E36: 4 | F36: 4 | G36: 0 | H36: 0 | I36: 3 | J36: 1 | K36: 0 | L36: 0 | M36: 36 | N36: 0 | O36: =SUM(C36:L36,N36) -> 35 | P36: =SUM(C36:N36) -> 71
B37: 13.45 - 14.00 | C37: 13 | D37: 8 | E37: 3 | F37: 7 | G37: 0 | H37: 0 | I37: 1 | J37: 0 | K37: 0 | L37: 0 | M37: 28 | N37: 0 | O37: =SUM(C37:L37,N37) -> 32 | P37: =SUM(C37:N37) -> 60
B38: 14.00 - 14.15 | C38: 11 | D38: 3 | E38: 6 | F38: 8 | G38: 0 | H38: 0 | I38: 1 | J38: 0 | K38: 0 | L38: 0 | M38: 33 | N38: 0 | O38: =SUM(C38:L38,N38) -> 29 | P38: =SUM(C38:N38) -> 62
B39: 14.15 - 14.30 | C39: 16 | D39: 6 | E39: 2 | F39: 4 | G39: 0 | H39: 0 | I39: 1 | J39: 0 | K39: 0 | L39: 0 | M39: 29 | N39: 0 | O39: =SUM(C39:L39,N39) -> 29 | P39: =SUM(C39:N39) -> 58
B40: 14.30 - 14.45 | C40: 12 | D40: 4 | E40: 4 | F40: 7 | G40: 0 | H40: 0 | I40: 3 | J40: 0 | K40: 0 | L40: 0 | M40: 39 | N40: 0 | O40: =SUM(C40:L40,N40) -> 30 | P40: =SUM(C40:N40) -> 69
... B57: 18.45 - 19.00 | C57: 89 | D57: 37 | E57: 14 | F57: 12 | G57: 0 | H57: 0 | I57: 3 | J57: 1 | K57: 0 | L57: 0 | M57: 34 | N57: 0 | O57: =SUM(C57:L57,N57) -> 156 | P57: =SUM(C57:N57) -> 190
B58: Totals | C58: =SUM(C10:C57) -> 1259 | D58: =SUM(D10:D57) -> 533 | E58: =SUM(E10:E57) -> 277 | F58: =SUM(F10:F57) -> 315 | G58: =SUM(G10:G57) -> 1 | H58: =SUM(H10:H57) -> 1 | I58: =SUM(I10:I57) -> 78 | J58: =SUM(J10:J57) -> 21 | ... P58: =SUM(P10:P57) -> 4124
...

Sheet 31.07 Kisasi-Bukoto
B1: Consultancy services for Preparation of Expressway Development Master Plan (EDMP) for Uganda
B2: MANUAL CLASSIFIED COUNT (MCC)
B3: ROAD NAME: | C3: ='29.07 Kisasi-Bukoto'!C3:G3 -> MCC - C1 - STN32 - BUKOTO KISASI ROAD
C5: Date | D5: 31.07.19 | F5: Location | G5: ='29.07 Kisasi-Bukoto'!G5:H5 -> KISASI | J5: Surveyor | K5: ='29.07 Kisasi-Bukoto'!K5:L5 -> RWAMBITITO J./NICHOL A./GEORGE W.
C6: Dir. From | D6: ='29.07 Kisasi-Bukoto'!D6:E6 -> KISASI | F6: Dir. To | G6: ='29.07 Kisasi-Bukoto'!G6:H6 -> BUKOTO | J6: Supervisor | K6: ='29.07 Kisasi-Bukoto'!K6:L6 -> SALIMA L.
B8: Time / Veh Type | R8: SUMMARY TRAFFIC VOLUMES
C9: 1. Car | D9: 2. Station Wagon | E9: 3. Pickups | F9: 4. Minibus, matatu | G9: 5. Medium bus | H9: 6. Large Bus | I9: 7. Light Truck | J9: 8. Medium Truck | K9: 9. Heavy truck | L9: 10. Truck Trailer | M9: 11. Motor cycles | N9: 12. Tractors | O9: Total Excl M/Cycles | P9: Total All | R9: Time | S9: 1. Car | T9: 2. Station Wagon | U9: 3. Pickups | V9: 4. Minibus, matatu | W9: 5. Medium bus | X9: 6. Large Bus | Y9: 7. Light Truck | Z9: 8. Medium Truck | AA9: 9. Heavy truck | AB9: 10. Truck Trailer | AC9: 11. Motorcycles | AD9: 12. Tractors, Graders | AE9: Total Excl M/ Cycles | AF9: Total All
B10: 07.00 - 07.15 | C10: 95 | D10: 45 | E10: 3 | F10: 17 | G10: 1 | H10: 0 | I10: 1 | J10: 0 | K10: 0 | L10: 0 | M10: 107 | N10: 0 | O10: =SUM(C10:L10,N10) -> 162 | P10: =SUM(C10:N10) -> 269 | R10: 0700-0800 | S10: =SUM(C10:C13) -> 330 | T10: =SUM(D10:D13) -> 177 | U10: =SUM(E10:E13) -> 11 | V10: =SUM(F10:F13) -> 57 | W10: =SUM(G10:G13) -> 1 | X10: =SUM(H10:H13) -> 0 | Y10: =SUM(I10:I13) -> 10 | Z10: =SUM(J10:J13) -> 0 | ... AF10: =SUM(P10:P13) -> 1034
B11: 07.15 - 07.30 | C11: 70 | D11: 54 | E11: 2 | F11: 10 | G11: 0 | H11: 0 | I11: 4 | J11: 0 | K11: 0 | L11: 0 | M11: 110 | N11: 0 | O11: =SUM(C11:L11,N11) -> 140 | P11: =SUM(C11:N11) -> 250 | R11: 0800-0900 | S11: =SUM(C14:C17) -> 197 | T11: =SUM(D14:D17) -> 97 | U11: =SUM(E14:E17) -> 5 | V11: =SUM(F14:F17) -> 43 | W11: =SUM(G14:G17) -> 0 | X11: =SUM(H14:H17) -> 0 | Y11: =SUM(I14:I17) -> 13 | Z11: =SUM(J14:J17) -> 1 | ... AF11: =SUM(P14:P17) -> 696
B12: 07.30 - 07.45 | C12: 75 | D12: 35 | E12: 2 | F12: 17 | G12: 0 | H12: 0 | I12: 3 | J12: 0 | K12: 0 | L12: 0 | M12: 122 | N12: 0 | O12: =SUM(C12:L12,N12) -> 132 | P12: =SUM(C12:N12) -> 254 | R12: 0900-1000 | S12: =SUM(C18:C21) -> 161 | T12: =SUM(D18:D21) -> 95 | U12: =SUM(E18:E21) -> 2 | V12: =SUM(F18:F21) -> 49 | W12: =SUM(G18:G21) -> 1 | X12: =SUM(H18:H21) -> 1 | Y12: =SUM(I18:I21) -> 16 | Z12: =SUM(J18:J21) -> 1 | ... AF12: =SUM(P18:P21) -> 588
B13: 07.45 - 08.00 | C13: 90 | D13: 43 | E13: 4 | F13: 13 | G13: 0 | H13: 0 | I13: 2 | J13: 0 | K13: 0 | L13: 0 | M13: 109 | N13: 0 | O13: =SUM(C13:L13,N13) -> 152 | P13: =SUM(C13:N13) -> 261 | R13: 1000-1100 | S13: =SUM(C22:C25) -> 137 | T13: =SUM(D22:D25) -> 66 | U13: =SUM(E22:E25) -> 4 | V13: =SUM(F22:F25) -> 45 | W13: =SUM(G22:G25) -> 0 | X13: =SUM(H22:H25) -> 0 | Y13: =SUM(I22:I25) -> 12 | Z13: =SUM(J22:J25) -> 0 | ... AF13: =SUM(P22:P25) -> 601
B14: 08.00 - 08.15 | C14: 89 | D14: 41 | E14: 2 | F14: 16 | G14: 0 | H14: 0 | I14: 2 | J14: 0 | K14: 0 | L14: 0 | M14: 85 | N14: 0 | O14: =SUM(C14:L14,N14) -> 150 | P14: =SUM(C14:N14) -> 235 | R14: 1100-1200 | S14: =SUM(C26:C29) -> 113 | T14: =SUM(D26:D29) -> 52 | U14: =SUM(E26:E29) -> 4 | V14: =SUM(F26:F29) -> 41 | W14: =SUM(G26:G29) -> 0 | X14: =SUM(H26:H29) -> 0 | Y14: =SUM(I26:I29) -> 12 | Z14: =SUM(J26:J29) -> 0 | ... AF14: =SUM(P26:P29) -> 513
B15: 08.15 - 08.30 | C15: 63 | D15: 24 | E15: 2 | F15: 14 | G15: 0 | H15: 0 | I15: 3 | J15: 0 | K15: 0 | L15: 0 | M15: 90 | N15: 0 | O15: =SUM(C15:L15,N15) -> 106 | P15: =SUM(C15:N15) -> 196 | R15: 1200-1300 | S15: =SUM(C30:C33) -> 123 | T15: =SUM(D30:D33) -> 53 | U15: =SUM(E30:E33) -> 3 | V15: =SUM(F30:F33) -> 32 | W15: =SUM(G30:G33) -> 0 | X15: =SUM(H30:H33) -> 0 | Y15: =SUM(I30:I33) -> 7 | Z15: =SUM(J30:J33) -> 0 | ... AF15: =SUM(P30:P33) -> 485
B16: 08.30 - 08.45 | C16: 32 | D16: 19 | E16: 0 | F16: 8 | G16: 0 | H16: 0 | I16: 5 | J16: 0 | K16: 0 | L16: 0 | M16: 80 | N16: 0 | O16: =SUM(C16:L16,N16) -> 64 | P16: =SUM(C16:N16) -> 144 | R16: 1300-1400 | S16: =SUM(C34:C37) -> 77 | T16: =SUM(D34:D37) -> 26 | U16: =SUM(E34:E37) -> 3 | V16: =SUM(F34:F37) -> 23 | W16: =SUM(G34:G37) -> 0 | X16: =SUM(H34:H37) -> 0 | Y16: =SUM(I34:I37) -> 6 | Z16: =SUM(J34:J37) -> 0 | ... AF16: =SUM(P34:P37) -> 372
B17: 08.45 - 9.00 | C17: 13 | D17: 13 | E17: 1 | F17: 5 | G17: 0 | H17: 0 | I17: 3 | J17: 1 | K17: 0 | L17: 0 | M17: 85 | N17: 0 | O17: =SUM(C17:L17,N17) -> 36 | P17: =SUM(C17:N17) -> 121 | R17: 1400-1500 | S17: =SUM(C38:C41) -> 89 | T17: =SUM(D38:D41) -> 49 | U17: =SUM(E38:E41) -> 5 | V17: =SUM(F38:F41) -> 34 | W17: =SUM(G38:G41) -> 0 | X17: =SUM(H38:H41) -> 0 | Y17: =SUM(I38:I41) -> 3 | Z17: =SUM(J38:J41) -> 1 | ... AF17: =SUM(P38:P41) -> 400
B18: 09.00 - 09.15 | C18: 44 | D18: 29 | E18: 2 | F18: 14 | G18: 0 | H18: 1 | I18: 5 | J18: 0 | K18: 0 | L18: 0 | M18: 77 | N18: 0 | O18: =SUM(C18:L18,N18) -> 95 | P18: =SUM(C18:N18) -> 172 | R18: 1500-1600 | S18: =SUM(C42:C45) -> 121 | T18: =SUM(D42:D45) -> 69 | U18: =SUM(E42:E45) -> 2 | V18: =SUM(F42:F45) -> 33 | W18: =SUM(G42:G45) -> 0 | X18: =SUM(H42:H45) -> 0 | Y18: =SUM(I42:I45) -> 9 | Z18: =SUM(J42:J45) -> 0 | ... AF18: =SUM(P42:P45) -> 515
B19: 09.15 - 09.30 | C19: 41 | D19: 20 | E19: 0 | F19: 12 | G19: 1 | H19: 0 | I19: 2 | J19: 0 | K19: 0 | L19: 0 | M19: 70 | N19: 0 | O19: =SUM(C19:L19,N19) -> 76 | P19: =SUM(C19:N19) -> 146 | R19: 1600-1700 | S19: =SUM(C46:C49) -> 107 | T19: =SUM(D46:D49) -> 56 | U19: =SUM(E46:E49) -> 4 | V19: =SUM(F46:F49) -> 32 | W19: =SUM(G46:G49) -> 3 | X19: =SUM(H46:H49) -> 0 | Y19: =SUM(I46:I49) -> 4 | Z19: =SUM(J46:J49) -> 2 | ... AF19: =SUM(P46:P49) -> 475
B20: 09.30 - 09.45 | C20: 46 | D20: 26 | E20: 0 | F20: 18 | G20: 0 | H20: 0 | I20: 5 | J20: 0 | K20: 0 | L20: 0 | M20: 55 | N20: 0 | O20: =SUM(C20:L20,N20) -> 95 | P20: =SUM(C20:N20) -> 150 | R20: 1700-1800 | S20: =SUM(C50:C53) -> 112 | T20: =SUM(D50:D53) -> 66 | U20: =SUM(E50:E53) -> 4 | V20: =SUM(F50:F53) -> 37 | W20: =SUM(G50:G53) -> 0 | X20: =SUM(H50:H53) -> 0 | Y20: =SUM(I50:I53) -> 4 | Z20: =SUM(J50:J53) -> 3 | ... AF20: =SUM(P50:P53) -> 543
B21: 09.45 - 10.00 | C21: 30 | D21: 20 | E21: 0 | F21: 5 | G21: 0 | H21: 0 | I21: 4 | J21: 1 | K21: 0 | L21: 0 | M21: 60 | N21: 0 | O21: =SUM(C21:L21,N21) -> 60 | P21: =SUM(C21:N21) -> 120 | R21: 1800-1900 | S21: =SUM(C54:C57) -> 95 | T21: =SUM(D54:D57) -> 51 | U21: =SUM(E54:E57) -> 5 | V21: =SUM(F54:F57) -> 30 | W21: =SUM(G54:G57) -> 3 | X21: =SUM(H54:H57) -> 0 | Y21: =SUM(I54:I57) -> 2 | Z21: =SUM(J54:J57) -> 2 | ... AF21: =SUM(P54:P57) -> 491
B22: 10.00 - 10.15 | C22: 35 | D22: 23 | E22: 0 | F22: 13 | G22: 0 | H22: 0 | I22: 2 | J22: 0 | K22: 0 | L22: 0 | M22: 85 | N22: 0 | O22: =SUM(C22:L22,N22) -> 73 | P22: =SUM(C22:N22) -> 158 | R22: AM Peak Hr | S22: =MAX(S10:S12) -> 330 | T22: =MAX(T10:T12) -> 177 | U22: =MAX(U10:U12) -> 11 | V22: =MAX(V10:V12) -> 57 | W22: =MAX(W10:W12) -> 1 | X22: =MAX(X10:X12) -> 1 | Y22: =MAX(Y10:Y12) -> 16 | Z22: =MAX(Z10:Z12) -> 1 | ... AF22: =MAX(AF10:AF12) -> 1034
B23: 10.15 - 10.30 | C23: 35 | D23: 14 | E23: 2 | F23: 12 | G23: 0 | H23: 0 | I23: 4 | J23: 0 | K23: 0 | L23: 0 | M23: 87 | N23: 0 | O23: =SUM(C23:L23,N23) -> 67 | P23: =SUM(C23:N23) -> 154 | R23: IP Peak Hr | S23: =MAX(S13:S18) -> 137 | T23: =MAX(T13:T18) -> 69 | U23: =MAX(U13:U18) -> 5 | V23: =MAX(V13:V18) -> 45 | W23: =MAX(W13:W18) -> 0 | X23: =MAX(X13:X18) -> 0 | Y23: =MAX(Y13:Y18) -> 12 | Z23: =MAX(Z13:Z18) -> 1 | ... AF23: =MAX(AF13:AF18) -> 601
B24: 10.30 - 10.45 | C24: 26 | D24: 15 | E24: 1 | F24: 7 | G24: 0 | H24: 0 | I24: 3 | J24: 0 | K24: 0 | L24: 0 | M24: 80 | N24: 0 | O24: =SUM(C24:L24,N24) -> 52 | P24: =SUM(C24:N24) -> 132 | R24: PM Peak Hr | S24: =MAX(S19:S21) -> 112 | T24: =MAX(T19:T21) -> 66 | U24: =MAX(U19:U21) -> 5 | V24: =MAX(V19:V21) -> 37 | W24: =MAX(W19:W21) -> 3 | X24: =MAX(X19:X21) -> 0 | Y24: =MAX(Y19:Y21) -> 4 | Z24: =MAX(Z19:Z21) -> 3 | ... AF24: =MAX(AF19:AF21) -> 543
B25: 10.45 - 11.00 | C25: 41 | D25: 14 | E25: 1 | F25: 13 | G25: 0 | H25: 0 | I25: 3 | J25: 0 | K25: 0 | L25: 0 | M25: 85 | N25: 0 | O25: =SUM(C25:L25,N25) -> 72 | P25: =SUM(C25:N25) -> 157 | R25: AM Period | S25: =SUM(S10:S12) -> 688 | T25: =SUM(T10:T12) -> 369 | U25: =SUM(U10:U12) -> 18 | V25: =SUM(V10:V12) -> 149 | W25: =SUM(W10:W12) -> 2 | X25: =SUM(X10:X12) -> 1 | Y25: =SUM(Y10:Y12) -> 39 | Z25: =SUM(Z10:Z12) -> 2 | ... AF25: =SUM(AF10:AF12) -> 2318
B26: 11.00 - 11.15 | C26: 26 | D26: 14 | E26: 1 | F26: 11 | G26: 0 | H26: 0 | I26: 4 | J26: 0 | K26: 0 | L26: 0 | M26: 82 | N26: 0 | O26: =SUM(C26:L26,N26) -> 56 | P26: =SUM(C26:N26) -> 138 | R26: IP Period | S26: =SUM(S13:S18) -> 660 | T26: =SUM(T13:T18) -> 315 | U26: =SUM(U13:U18) -> 21 | V26: =SUM(V13:V18) -> 208 | W26: =SUM(W13:W18) -> 0 | X26: =SUM(X13:X18) -> 0 | Y26: =SUM(Y13:Y18) -> 49 | Z26: =SUM(Z13:Z18) -> 1 | ... AF26: =SUM(AF13:AF18) -> 2886
B27: 11.15 - 11.30 | C27: 35 | D27: 5 | E27: 2 | F27: 9 | G27: 0 | H27: 0 | I27: 2 | J27: 0 | K27: 0 | L27: 0 | M27: 69 | N27: 0 | O27: =SUM(C27:L27,N27) -> 53 | P27: =SUM(C27:N27) -> 122 | R27: PM Period | S27: =SUM(S19:S21) -> 314 | T27: =SUM(T19:T21) -> 173 | U27: =SUM(U19:U21) -> 13 | V27: =SUM(V19:V21) -> 99 | W27: =SUM(W19:W21) -> 6 | X27: =SUM(X19:X21) -> 0 | Y27: =SUM(Y19:Y21) -> 10 | Z27: =SUM(Z19:Z21) -> 7 | ... AF27: =SUM(AF19:AF21) -> 1509
