Workbook

Sheet 29.07 Kyanja -Kisaasi
B1: Consultancy services for Preparation of Expressway Development Master Plan (EDMP) for Uganda
B2: MANUAL CLASSIFIED COUNT (MCC)
B3: ROAD NAME: | C3: MCC - C1 - STN34- KISAASI-KYANJA ROAD
C5: Date | D5: 29.07.19 | F5: Location | G5: Malcom Health center | J5: Surveyor | K5: Babirye Phiona
C6: Dir. From | D6: Kyanja | F6: Dir. To | G6: Kisaasi | J6: Supervisor | K6: Steven
B8: Time / Veh Type | R8: SUMMARY TRAFFIC VOLUMES
C9: 1. Car | D9: 2. Station Wagon | E9: 3. Pickups | F9: 4. Minibus, matatu | G9: 5. Medium bus | H9: 6. Large Bus | I9: 7. Light Truck | J9: 8. Medium Truck | K9: 9. Heavy truck | L9: 10. Truck Trailer | M9: 11. Motor cycles | N9: 12. Tractors | O9: Total Excl M/Cycles | P9: Total All | R9: Time | S9: 1. Car | T9: 2. Station Wagon | U9: 3. Pickups | V9: 4. Minibus, matatu | W9: 5. Medium bus | X9: 6. Large Bus | Y9: 7. Light Truck | Z9: 8. Medium Truck | AA9: 9. Heavy truck | AB9: 10. Truck Trailer | AC9: 11. Motorcycles | AD9: 12. Tractors, Graders | AE9: Total Excl M/ Cycles | AF9: Total All
B10: 07.00 - 07.15 | C10: 33 | D10: 0 | E10: 2 | F10: 3 | G10: 0 | H10: 1 | I10: 0 | J10: 0 | K10: 4 | L10: 0 | M10: 55 | N10: 0 | O10: =SUM(C10:L10,N10) -> 43 | P10: =SUM(C10:N10) -> 98 | R10: 0700-0800 | S10: =SUM(C10:C13) -> 151 | T10: =SUM(D10:D13) -> 62 | U10: =SUM(E10:E13) -> 24 | V10: =SUM(F10:F13) -> 70 | W10: =SUM(G10:G13) -> 1 | X10: =SUM(H10:H13) -> 1 | Y10: =SUM(I10:I13) -> 5 | Z10: =SUM(J10:J13) -> 2 | ... AF10: =SUM(P10:P13) -> 656
B11: 07.15 - 07.30 | C11: 36 | D11: 32 | E11: 7 | F11: 12 | G11: 0 | H11: 0 | I11: 1 | J11: 0 | K11: 3 | L11: 0 | M11: 90 | N11: 0 | O11: =SUM(C11:L11,N11) -> 91 | P11: =SUM(C11:N11) -> 181 | R11: 0800-0900 | S11: =SUM(C14:C17) -> 158 | T11: =SUM(D14:D17) -> 83 | U11: =SUM(E14:E17) -> 13 | V11: =SUM(F14:F17) -> 230 | W11: =SUM(G14:G17) -> 0 | X11: =SUM(H14:H17) -> 0 | Y11: =SUM(I14:I17) -> 10 | Z11: =SUM(J14:J17) -> 7 | ... AF11: =SUM(P14:P17) -> 579
B12: 07.30 - 07.45 | C12: 40 | D12: 15 | E12: 7 | F12: 26 | G12: 0 | H12: 0 | I12: 3 | J12: 2 | K12: 4 | L12: 0 | M12: 87 | N12: 0 | O12: =SUM(C12:L12,N12) -> 97 | P12: =SUM(C12:N12) -> 184 | R12: 0900-1000 | S12: =SUM(C18:C21) -> 145 | T12: =SUM(D18:D21) -> 56 | U12: =SUM(E18:E21) -> 15 | V12: =SUM(F18:F21) -> 81 | W12: =SUM(G18:G21) -> 0 | X12: =SUM(H18:H21) -> 0 | Y12: =SUM(I18:I21) -> 21 | Z12: =SUM(J18:J21) -> 5 | ... AF12: =SUM(P18:P21) -> 700
B13: 07.45 - 08.00 | C13: 42 | D13: 15 | E13: 8 | F13: 29 | G13: 1 | H13: 0 | I13: 1 | J13: 0 | K13: 7 | L13: 0 | M13: 90 | N13: 0 | O13: =SUM(C13:L13,N13) -> 103 | P13: =SUM(C13:N13) -> 193 | R13: 1000-1100 | S13: =SUM(C22:C25) -> 112 | T13: =SUM(D22:D25) -> 70 | U13: =SUM(E22:E25) -> 34 | V13: =SUM(F22:F25) -> 62 | W13: =SUM(G22:G25) -> 0 | X13: =SUM(H22:H25) -> 0 | Y13: =SUM(I22:I25) -> 13 | Z13: =SUM(J22:J25) -> 6 | ... AF13: =SUM(P22:P25) -> 373
B14: 08.00 - 08.15 | C14: 40 | D14: 9 | E14: 5 | F14: 70 | G14: 0 | H14: 0 | I14: 2 | J14: 0 | K14: 0 | L14: 0 | M14: 18 | N14: 0 | O14: =SUM(C14:L14,N14) -> 126 | P14: =SUM(C14:N14) -> 144 | R14: 1100-1200 | S14: =SUM(C26:C29) -> 126 | T14: =SUM(D26:D29) -> 51 | U14: =SUM(E26:E29) -> 18 | V14: =SUM(F26:F29) -> 63 | W14: =SUM(G26:G29) -> 2 | X14: =SUM(H26:H29) -> 0 | Y14: =SUM(I26:I29) -> 26 | Z14: =SUM(J26:J29) -> 4 | ... AF14: =SUM(P26:P29) -> 378
B15: 08.15 - 08.30 | C15: 48 | D15: 9 | E15: 5 | F15: 70 | G15: 0 | H15: 0 | I15: 4 | J15: 6 | K15: 1 | L15: 0 | M15: 18 | N15: 0 | O15: =SUM(C15:L15,N15) -> 143 | P15: =SUM(C15:N15) -> 161 | R15: 1200-1300 | S15: =SUM(C30:C33) -> 51 | T15: =SUM(D30:D33) -> 49 | U15: =SUM(E30:E33) -> 13 | V15: =SUM(F30:F33) -> 19 | W15: =SUM(G30:G33) -> 1 | X15: =SUM(H30:H33) -> 0 | Y15: =SUM(I30:I33) -> 12 | Z15: =SUM(J30:J33) -> 6 | ... AF15: =SUM(P30:P33) -> 308
B16: 08.30 - 08.45 | C16: 30 | D16: 35 | E16: 0 | F16: 70 | G16: 0 | H16: 0 | I16: 0 | J16: 1 | K16: 2 | L16: 0 | M16: 19 | N16: 0 | O16: =SUM(C16:L16,N16) -> 138 | P16: =SUM(C16:N16) -> 157 | R16: 1300-1400 | S16: =SUM(C34:C37) -> 85 | T16: =SUM(D34:D37) -> 121 | U16: =SUM(E34:E37) -> 37 | V16: =SUM(F34:F37) -> 57 | W16: =SUM(G34:G37) -> 1 | X16: =SUM(H34:H37) -> 0 | Y16: =SUM(I34:I37) -> 13 | Z16: =SUM(J34:J37) -> 16 | ... AF16: =SUM(P34:P37) -> 654
B17: 08.45 - 9.00 | C17: 40 | D17: 30 | E17: 3 | F17: 20 | G17: 0 | H17: 0 | I17: 4 | J17: 0 | K17: 3 | L17: 2 | M17: 15 | N17: 0 | O17: =SUM(C17:L17,N17) -> 102 | P17: =SUM(C17:N17) -> 117 | R17: 1400-1500 | S17: =SUM(C38:C41) -> 94 | T17: =SUM(D38:D41) -> 117 | U17: =SUM(E38:E41) -> 29 | V17: =SUM(F38:F41) -> 53 | W17: =SUM(G38:G41) -> 0 | X17: =SUM(H38:H41) -> 2 | Y17: =SUM(I38:I41) -> 16 | Z17: =SUM(J38:J41) -> 13 | ... AF17: =SUM(P38:P41) -> 655
B18: 09.00 - 09.15 | C18: 34 | D18: 10 | E18: 2 | F18: 22 | G18: 0 | H18: 0 | I18: 7 | J18: 1 | K18: 3 | L18: 3 | M18: 95 | N18: 0 | O18: =SUM(C18:L18,N18) -> 82 | P18: =SUM(C18:N18) -> 177 | R18: 1500-1600 | S18: =SUM(C42:C45) -> 97 | T18: =SUM(D42:D45) -> 142 | U18: =SUM(E42:E45) -> 33 | V18: =SUM(F42:F45) -> 43 | W18: =SUM(G42:G45) -> 1 | X18: =SUM(H42:H45) -> 0 | Y18: =SUM(I42:I45) -> 14 | Z18: =SUM(J42:J45) -> 17 | ... AF18: =SUM(P42:P45) -> 678
B19: 09.15 - 09.30 | C19: 26 | D19: 16 | E19: 3 | F19: 4 | G19: 0 | H19: 0 | I19: 5 | J19: 2 | K19: 6 | L19: 2 | M19: 95 | N19: 0 | O19: =SUM(C19:L19,N19) -> 64 | P19: =SUM(C19:N19) -> 159 | R19: 1600-1700 | S19: =SUM(C46:C49) -> 156 | T19: =SUM(D46:D49) -> 174 | U19: =SUM(E46:E49) -> 38 | V19: =SUM(F46:F49) -> 62 | W19: =SUM(G46:G49) -> 1 | X19: =SUM(H46:H49) -> 0 | Y19: =SUM(I46:I49) -> 11 | Z19: =SUM(J46:J49) -> 8 | ... AF19: =SUM(P46:P49) -> 781
B20: 09.30 - 09.45 | C20: 50 | D20: 10 | E20: 6 | F20: 25 | G20: 0 | H20: 0 | I20: 4 | J20: 1 | K20: 1 | L20: 0 | M20: 75 | N20: 0 | O20: =SUM(C20:L20,N20) -> 97 | P20: =SUM(C20:N20) -> 172 | R20: 1700-1800 | S20: =SUM(C50:C53) -> 185 | T20: =SUM(D50:D53) -> 258 | U20: =SUM(E50:E53) -> 43 | V20: =SUM(F50:F53) -> 109 | W20: =SUM(G50:G53) -> 2 | X20: =SUM(H50:H53) -> 0 | Y20: =SUM(I50:I53) -> 9 | Z20: =SUM(J50:J53) -> 8 | ... AF20: =SUM(P50:P53) -> 1130
B21: 09.45 - 10.00 | C21: 35 | D21: 20 | E21: 4 | F21: 30 | G21: 0 | H21: 0 | I21: 5 | J21: 1 | K21: 2 | L21: 0 | M21: 95 | N21: 0 | O21: =SUM(C21:L21,N21) -> 97 | P21: =SUM(C21:N21) -> 192 | R21: 1800-1900 | S21: =SUM(C54:C57) -> 275 | T21: =SUM(D54:D57) -> 325 | U21: =SUM(E54:E57) -> 29 | V21: =SUM(F54:F57) -> 290 | W21: =SUM(G54:G57) -> 1 | X21: =SUM(H54:H57) -> 0 | Y21: =SUM(I54:I57) -> 5 | Z21: =SUM(J54:J57) -> 4 | ... AF21: =SUM(P54:P57) -> 1493
B22: 10.00 - 10.15 | C22: 30 | D22: 15 | E22: 4 | F22: 23 | G22: 0 | H22: 0 | I22: 2 | J22: 1 | K22: 2 | L22: 2 | M22: 19 | N22: 0 | O22: =SUM(C22:L22,N22) -> 79 | P22: =SUM(C22:N22) -> 98 | R22: AM Peak Hr | S22: =MAX(S10:S12) -> 158 | T22: =MAX(T10:T12) -> 83 | U22: =MAX(U10:U12) -> 24 | V22: =MAX(V10:V12) -> 230 | W22: =MAX(W10:W12) -> 1 | X22: =MAX(X10:X12) -> 1 | Y22: =MAX(Y10:Y12) -> 21 | Z22: =MAX(Z10:Z12) -> 7 | ... AF22: =MAX(AF10:AF12) -> 700
B23: 10.15 - 10.30 | C23: 40 | D23: 20 | E23: 16 | F23: 20 | G23: 0 | H23: 0 | I23: 8 | J23: 3 | K23: 2 | L23: 1 | M23: 15 | N23: 0 | O23: =SUM(C23:L23,N23) -> 110 | P23: =SUM(C23:N23) -> 125 | R23: IP Peak Hr | S23: =MAX(S13:S18) -> 126 | T23: =MAX(T13:T18) -> 142 | U23: =MAX(U13:U18) -> 37 | V23: =MAX(V13:V18) -> 63 | W23: =MAX(W13:W18) -> 2 | X23: =MAX(X13:X18) -> 2 | Y23: =MAX(Y13:Y18) -> 26 | Z23: =MAX(Z13:Z18) -> 17 | ... AF23: =MAX(AF13:AF18) -> 678
B24: 10.30 - 10.45 | C24: 22 | D24: 15 | E24: 9 | F24: 3 | G24: 0 | H24: 0 | I24: 1 | J24: 1 | K24: 2 | L24: 0 | M24: 14 | N24: 0 | O24: =SUM(C24:L24,N24) -> 53 | P24: =SUM(C24:N24) -> 67 | R24: PM Peak Hr | S24: =MAX(S19:S21) -> 275 | T24: =MAX(T19:T21) -> 325 | U24: =MAX(U19:U21) -> 43 | V24: =MAX(V19:V21) -> 290 | W24: =MAX(W19:W21) -> 2 | X24: =MAX(X19:X21) -> 0 | Y24: =MAX(Y19:Y21) -> 11 | Z24: =MAX(Z19:Z21) -> 8 | ... AF24: =MAX(AF19:AF21) -> 1493
B25: 10.45 - 11.00 | C25: 20 | D25: 20 | E25: 5 | F25: 16 | G25: 0 | H25: 0 | I25: 2 | J25: 1 | K25: 2 | L25: 2 | M25: 15 | N25: 0 | O25: =SUM(C25:L25,N25) -> 68 | P25: =SUM(C25:N25) -> 83 | R25: AM Period | S25: =SUM(S10:S12) -> 454 | T25: =SUM(T10:T12) -> 201 | U25: =SUM(U10:U12) -> 52 | V25: =SUM(V10:V12) -> 381 | W25: =SUM(W10:W12) -> 1 | X25: =SUM(X10:X12) -> 1 | Y25: =SUM(Y10:Y12) -> 36 | Z25: =SUM(Z10:Z12) -> 14 | ... AF25: =SUM(AF10:AF12) -> 1935
B26: 11.00 - 11.15 | C26: 30 | D26: 15 | E26: 5 | F26: 15 | G26: 1 | H26: 0 | I26: 5 | J26: 3 | K26: 2 | L26: 1 | M26: 18 | N26: 0 | O26: =SUM(C26:L26,N26) -> 77 | P26: =SUM(C26:N26) -> 95 | R26: IP Period | S26: =SUM(S13:S18) -> 565 | T26: =SUM(T13:T18) -> 550 | U26: =SUM(U13:U18) -> 164 | V26: =SUM(V13:V18) -> 297 | W26: =SUM(W13:W18) -> 5 | X26: =SUM(X13:X18) -> 2 | Y26: =SUM(Y13:Y18) -> 94 | Z26: =SUM(Z13:Z18) -> 62 | ... AF26: =SUM(AF13:AF18) -> 3046
B27: 11.15 - 11.30 | C27: 35 | D27: 4 | E27: 4 | F27: 20 | G27: 0 | H27: 0 | I27: 8 | J27: 0 | K27: 1 | L27: 3 | M27: 16 | N27: 0 | O27: =SUM(C27:L27,N27) -> 75 | P27: =SUM(C27:N27) -> 91 | R27: PM Period | S27: =SUM(S19:S21) -> 616 | T27: =SUM(T19:T21) -> 757 | U27: =SUM(U19:U21) -> 110 | V27: =SUM(V19:V21) -> 461 | W27: =SUM(W19:W21) -> 4 | X27: =SUM(X19:X21) -> 0 | Y27: =SUM(Y19:Y21) -> 25 | Z27: =SUM(Z19:Z21) -> 20 | ... AF27: =SUM(AF19:AF21) -> 3404
B28: 11.30 - 11.45 | C28: 36 | D28: 17 | E28: 2 | F28: 11 | G28: 0 | H28: 0 | I28: 4 | J28: 1 | K28: 3 | L28: 1 | M28: 20 | N28: 0 | O28: =SUM(C28:L28,N28) -> 75 | P28: =SUM(C28:N28) -> 95 | R28: 12 Hours | S28: =SUM(S10:S21) -> 1635 | T28: =SUM(T10:T21) -> 1508 | U28: =SUM(U10:U21) -> 326 | V28: =SUM(V10:V21) -> 1139 | W28: =SUM(W10:W21) -> 10 | X28: =SUM(X10:X21) -> 3 | Y28: =SUM(Y10:Y21) -> 155 | Z28: =SUM(Z10:Z21) -> 96 | ... AF28: =SUM(AF10:AF21) -> 8385
B29: 11.45 - 12.00 | C29: 25 | D29: 15 | E29: 7 | F29: 17 | G29: 1 | H29: 0 | I29: 9 | J29: 0 | K29: 0 | L29: 3 | M29: 20 | N29: 0 | O29: =SUM(C29:L29,N29) -> 77 | P29: =SUM(C29:N29) -> 97
B30: 12.00 - 12.15 | C30: 15 | D30: 15 | E30: 4 | F30: 9 | G30: 1 | H30: 0 | I30: 4 | J30: 1 | K30: 1 | L30: 1 | M30: 20 | N30: 0 | O30: =SUM(C30:L30,N30) -> 51 | P30: =SUM(C30:N30) -> 71
B31: 12.15 - 12.30 | C31: 26 | D31: 24 | E31: 6 | F31: 4 | G31: 0 | H31: 0 | I31: 4 | J31: 3 | K31: 2 | L31: 2 | M31: 16 | N31: 0 | O31: =SUM(C31:L31,N31) -> 71 | P31: =SUM(C31:N31) -> 87
B32: 12.30 - 12.45 | C32: 5 | D32: 5 | E32: 1 | F32: 3 | G32: 0 | H32: 0 | I32: 2 | J32: 1 | K32: 1 | L32: 1 | M32: 18 | N32: 0 | O32: =SUM(C32:L32,N32) -> 19 | P32: =SUM(C32:N32) -> 37
B33: 12.45 - 13.00 | C33: 5 | D33: 5 | E33: 2 | F33: 3 | G33: 0 | H33: 0 | I33: 2 | J33: 1 | K33: 0 | L33: 0 | M33: 95 | N33: 0 | O33: =SUM(C33:L33,N33) -> 18 | P33: =SUM(C33:N33) -> 113
B34: 13.00 - 13.15 | C34: 25 | D34: 30 | E34: 16 | F34: 26 | G34: 1 | H34: 0 | I34: 2 | J34: 7 | K34: 3 | L34: 1 | M34: 90 | N34: 0 | O34: =SUM(C34:L34,N34) -> 111 | P34: =SUM(C34:N34) -> 201
B35: 13.15 - 13.30 | C35: 15 | D35: 31 | E35: 5 | F35: 16 | G35: 0 | H35: 0 | I35: 1 | J35: 1 | K35: 1 | L35: 1 | M35: 80 | N35: 0 | O35: =SUM(C35:L35,N35) -> 71 | P35: =SUM(C35:N35) -> 151
B36: 13.30 - 13.45 | C36: 25 | D36: 30 | E36: 11 | F36: 5 | G36: 0 | H36: 0 | I36: 7 | J36: 6 | K36: 0 | L36: 3 | M36: 82 | N36: 0 | O36: =SUM(C36:L36,N36) -> 87 | P36: =SUM(C36:N36) -> 169
B37: 13.45 - 14.00 | C37: 20 | D37: 30 | E37: 5 | F37: 10 | G37: 0 | H37: 0 | I37: 3 | J37: 2 | K37: 1 | L37: 2 | M37: 60 | N37: 0 | O37: =SUM(C37:L37,N37) -> 73 | P37: =SUM(C37:N37) -> 133
B38: 14.00 - 14.15 | C38: 20 | D38: 25 | E38: 9 | F38: 9 | G38: 0 | H38: 0 | I38: 5 | J38: 2 | K38: 0 | L38: 2 | M38: 80 | N38: 0 | O38: =SUM(C38:L38,N38) -> 72 | P38: =SUM(C38:N38) -> 152
B39: 14.15 - 14.30 | C39: 30 | D39: 27 | E39: 8 | F39: 17 | G39: 0 | H39: 0 | I39: 1 | J39: 3 | K39: 0 | L39: 0 | M39: 85 | N39: 0 | O39: =SUM(C39:L39,N39) -> 86 | P39: =SUM(C39:N39) -> 171
B40: 14.30 - 14.45 | C40: 20 | D40: 30 | E40: 3 | F40: 16 | G40: 0 | H40: 1 | I40: 4 | J40: 3 | K40: 2 | L40: 1 | M40: 75 | N40: 0 | O40: =SUM(C40:L40,N40) -> 80 | P40: =SUM(C40:N40) -> 155
... B57: 18.45 - 19.00 | C57: 75 | D57: 65 | E57: 3 | F57: 70 | G57: 0 | H57: 0 | I57: 0 | J57: 0 | K57: 1 | L57: 0 | M57: 120 | N57: 0 | O57: =SUM(C57:L57,N57) -> 214 | P57: =SUM(C57:N57) -> 334
B58: Totals | C58: =SUM(C10:C57) -> 1635 | D58: =SUM(D10:D57) -> 1508 | E58: =SUM(E10:E57) -> 326 | F58: =SUM(F10:F57) -> 1139 | G58: =SUM(G10:G57) -> 10 | H58: =SUM(H10:H57) -> 3 | I58: =SUM(I10:I57) -> 155 | J58: =SUM(J10:J57) -> 96 | ... P58: =SUM(P10:P57) -> 8385
...

Sheet 29.07 Kisaasi-Kyanja
B1: Consultancy services for Preparation of Expressway Development Master Plan (EDMP) for Uganda
B2: MANUAL CLASSIFIED COUNT (MCC)
B3: ROAD NAME: | C3: ='29.07 Kyanja -Kisaasi'!C3:G3 -> MCC - C1 - STN34- KISAASI-KYANJA ROAD
C5: Date | D5: ='29.07 Kyanja -Kisaasi'!D5 -> 29.07.19 | F5: Location | G5: ='29.07 Kyanja -Kisaasi'!G5:H5 -> Malcom Health center | J5: Surveyor | K5: Nansamba Catherine & Yiga Elly
C6: Dir. From | D6: Kisaasi | F6: Dir. To | G6: Kyanja | J6: Supervisor | K6: Steven
B8: Time / Veh Type | R8: SUMMARY TRAFFIC VOLUMES
C9: 1. Car | D9: 2. Station Wagon | E9: 3. Pickups | F9: 4. Minibus, matatu | G9: 5. Medium bus | H9: 6. Large Bus | I9: 7. Light Truck | J9: 8. Medium Truck | K9: 9. Heavy truck | L9: 10. Truck Trailer | M9: 11. Motor cycles | N9: 12. Tractors | O9: Total Excl M/Cycles | P9: Total All | R9: Time | S9: 1. Car | T9: 2. Station Wagon | U9: 3. Pickups | V9: 4. Minibus, matatu | W9: 5. Medium bus | X9: 6. Large Bus | Y9: 7. Light Truck | Z9: 8. Medium Truck | AA9: 9. Heavy truck | AB9: 10. Truck Trailer | AC9: 11. Motorcycles | AD9: 12. Tractors, Graders | AE9: Total Excl M/ Cycles | AF9: Total All
B10: 07.00 - 07.15 | C10: 82 | D10: 21 | E10: 8 | F10: 12 | G10: 0 | H10: 0 | I10: 0 | J10: 1 | K10: 0 | L10: 0 | M10: 73 | N10: 0 | O10: =SUM(C10:L10,N10) -> 124 | P10: =SUM(C10:N10) -> 197 | R10: 0700-0800 | S10: =SUM(C10:C13) -> 389 | T10: =SUM(D10:D13) -> 139 | U10: =SUM(E10:E13) -> 36 | V10: =SUM(F10:F13) -> 62 | W10: =SUM(G10:G13) -> 0 | X10: =SUM(H10:H13) -> 0 | Y10: =SUM(I10:I13) -> 9 | Z10: =SUM(J10:J13) -> 1 | ... AF10: =SUM(P10:P13) -> 1114
B11: 07.15 - 07.30 | C11: 112 | D11: 50 | E11: 10 | F11: 14 | G11: 0 | H11: 0 | I11: 2 | J11: 0 | K11: 0 | L11: 0 | M11: 84 | N11: 0 | O11: =SUM(C11:L11,N11) -> 188 | P11: =SUM(C11:N11) -> 272 | R11: 0800-0900 | S11: =SUM(C14:C17) -> 454 | T11: =SUM(D14:D17) -> 173 | U11: =SUM(E14:E17) -> 49 | V11: =SUM(F14:F17) -> 64 | W11: =SUM(G14:G17) -> 5 | X11: =SUM(H14:H17) -> 0 | Y11: =SUM(I14:I17) -> 28 | Z11: =SUM(J14:J17) -> 10 | ... AF11: =SUM(P14:P17) -> 1531
B12: 07.30 - 07.45 | C12: 105 | D12: 43 | E12: 7 | F12: 16 | G12: 0 | H12: 0 | I12: 5 | J12: 0 | K12: 0 | L12: 0 | M12: 135 | N12: 0 | O12: =SUM(C12:L12,N12) -> 176 | P12: =SUM(C12:N12) -> 311 | R12: 0900-1000 | S12: =SUM(C18:C21) -> 394 | T12: =SUM(D18:D21) -> 140 | U12: =SUM(E18:E21) -> 50 | V12: =SUM(F18:F21) -> 57 | W12: =SUM(G18:G21) -> 0 | X12: =SUM(H18:H21) -> 0 | Y12: =SUM(I18:I21) -> 32 | Z12: =SUM(J18:J21) -> 4 | ... AF12: =SUM(P18:P21) -> 1430
B13: 07.45 - 08.00 | C13: 90 | D13: 25 | E13: 11 | F13: 20 | G13: 0 | H13: 0 | I13: 2 | J13: 0 | K13: 0 | L13: 0 | M13: 186 | N13: 0 | O13: =SUM(C13:L13,N13) -> 148 | P13: =SUM(C13:N13) -> 334 | R13: 1000-1100 | S13: =SUM(C22:C25) -> 325 | T13: =SUM(D22:D25) -> 123 | U13: =SUM(E22:E25) -> 32 | V13: =SUM(F22:F25) -> 49 | W13: =SUM(G22:G25) -> 0 | X13: =SUM(H22:H25) -> 0 | Y13: =SUM(I22:I25) -> 15 | Z13: =SUM(J22:J25) -> 2 | ... AF13: =SUM(P22:P25) -> 1088
B14: 08.00 - 08.15 | C14: 119 | D14: 41 | E14: 15 | F14: 23 | G14: 0 | H14: 0 | I14: 9 | J14: 1 | K14: 2 | L14: 0 | M14: 134 | N14: 0 | O14: =SUM(C14:L14,N14) -> 210 | P14: =SUM(C14:N14) -> 344 | R14: 1100-1200 | S14: =SUM(C26:C29) -> 265 | T14: =SUM(D26:D29) -> 71 | U14: =SUM(E26:E29) -> 33 | V14: =SUM(F26:F29) -> 53 | W14: =SUM(G26:G29) -> 0 | X14: =SUM(H26:H29) -> 0 | Y14: =SUM(I26:I29) -> 22 | Z14: =SUM(J26:J29) -> 5 | ... AF14: =SUM(P26:P29) -> 1158
B15: 08.15 - 08.30 | C15: 114 | D15: 54 | E15: 12 | F15: 18 | G15: 5 | H15: 0 | I15: 7 | J15: 4 | K15: 2 | L15: 1 | M15: 162 | N15: 0 | O15: =SUM(C15:L15,N15) -> 217 | P15: =SUM(C15:N15) -> 379 | R15: 1200-1300 | S15: =SUM(C30:C33) -> 189 | T15: =SUM(D30:D33) -> 94 | U15: =SUM(E30:E33) -> 22 | V15: =SUM(F30:F33) -> 43 | W15: =SUM(G30:G33) -> 0 | X15: =SUM(H30:H33) -> 0 | Y15: =SUM(I30:I33) -> 10 | Z15: =SUM(J30:J33) -> 4 | ... AF15: =SUM(P30:P33) -> 937
B16: 08.30 - 08.45 | C16: 114 | D16: 36 | E16: 12 | F16: 13 | G16: 0 | H16: 0 | I16: 6 | J16: 2 | K16: 1 | L16: 0 | M16: 190 | N16: 0 | O16: =SUM(C16:L16,N16) -> 184 | P16: =SUM(C16:N16) -> 374 | R16: 1300-1400 | S16: =SUM(C34:C37) -> 171 | T16: =SUM(D34:D37) -> 61 | U16: =SUM(E34:E37) -> 17 | V16: =SUM(F34:F37) -> 44 | W16: =SUM(G34:G37) -> 0 | X16: =SUM(H34:H37) -> 0 | Y16: =SUM(I34:I37) -> 26 | Z16: =SUM(J34:J37) -> 9 | ... AF16: =SUM(P34:P37) -> 919
B17: 08.45 - 9.00 | C17: 107 | D17: 42 | E17: 10 | F17: 10 | G17: 0 | H17: 0 | I17: 6 | J17: 3 | K17: 1 | L17: 0 | M17: 255 | N17: 0 | O17: =SUM(C17:L17,N17) -> 179 | P17: =SUM(C17:N17) -> 434 | R17: 1400-1500 | S17: =SUM(C38:C41) -> 171 | T17: =SUM(D38:D41) -> 73 | U17: =SUM(E38:E41) -> 31 | V17: =SUM(F38:F41) -> 46 | W17: =SUM(G38:G41) -> 3 | X17: =SUM(H38:H41) -> 0 | Y17: =SUM(I38:I41) -> 21 | Z17: =SUM(J38:J41) -> 10 | ... AF17: =SUM(P38:P41) -> 840
B18: 09.00 - 09.15 | C18: 96 | D18: 28 | E18: 12 | F18: 20 | G18: 0 | H18: 0 | I18: 11 | J18: 1 | K18: 2 | L18: 1 | M18: 185 | N18: 0 | O18: =SUM(C18:L18,N18) -> 171 | P18: =SUM(C18:N18) -> 356 | R18: 1500-1600 | S18: =SUM(C42:C45) -> 219 | T18: =SUM(D42:D45) -> 93 | U18: =SUM(E42:E45) -> 43 | V18: =SUM(F42:F45) -> 40 | W18: =SUM(G42:G45) -> 0 | X18: =SUM(H42:H45) -> 0 | Y18: =SUM(I42:I45) -> 32 | Z18: =SUM(J42:J45) -> 8 | ... AF18: =SUM(P42:P45) -> 882
B19: 09.15 - 09.30 | C19: 102 | D19: 37 | E19: 9 | F19: 14 | G19: 0 | H19: 0 | I19: 7 | J19: 1 | K19: 0 | L19: 1 | M19: 178 | N19: 0 | O19: =SUM(C19:L19,N19) -> 171 | P19: =SUM(C19:N19) -> 349 | R19: 1600-1700 | S19: =SUM(C46:C49) -> 272 | T19: =SUM(D46:D49) -> 112 | U19: =SUM(E46:E49) -> 31 | V19: =SUM(F46:F49) -> 47 | W19: =SUM(G46:G49) -> 0 | X19: =SUM(H46:H49) -> 0 | Y19: =SUM(I46:I49) -> 26 | Z19: =SUM(J46:J49) -> 11 | ... AF19: =SUM(P46:P49) -> 1035
B20: 09.30 - 09.45 | C20: 100 | D20: 39 | E20: 16 | F20: 9 | G20: 0 | H20: 0 | I20: 6 | J20: 0 | K20: 4 | L20: 0 | M20: 191 | N20: 0 | O20: =SUM(C20:L20,N20) -> 174 | P20: =SUM(C20:N20) -> 365 | R20: 1700-1800 | S20: =SUM(C50:C53) -> 286 | T20: =SUM(D50:D53) -> 142 | U20: =SUM(E50:E53) -> 40 | V20: =SUM(F50:F53) -> 93 | W20: =SUM(G50:G53) -> 5 | X20: =SUM(H50:H53) -> 0 | Y20: =SUM(I50:I53) -> 9 | Z20: =SUM(J50:J53) -> 1 | ... AF20: =SUM(P50:P53) -> 1326
B21: 09.45 - 10.00 | C21: 96 | D21: 36 | E21: 13 | F21: 14 | G21: 0 | H21: 0 | I21: 8 | J21: 2 | K21: 1 | L21: 0 | M21: 190 | N21: 0 | O21: =SUM(C21:L21,N21) -> 170 | P21: =SUM(C21:N21) -> 360 | R21: 1800-1900 | S21: =SUM(C54:C57) -> 249 | T21: =SUM(D54:D57) -> 145 | U21: =SUM(E54:E57) -> 36 | V21: =SUM(F54:F57) -> 65 | W21: =SUM(G54:G57) -> 2 | X21: =SUM(H54:H57) -> 0 | Y21: =SUM(I54:I57) -> 18 | Z21: =SUM(J54:J57) -> 5 | ... AF21: =SUM(P54:P57) -> 1367
B22: 10.00 - 10.15 | C22: 90 | D22: 43 | E22: 8 | F22: 11 | G22: 0 | H22: 0 | I22: 2 | J22: 0 | K22: 0 | L22: 1 | M22: 134 | N22: 0 | O22: =SUM(C22:L22,N22) -> 155 | P22: =SUM(C22:N22) -> 289 | R22: AM Peak Hr | S22: =MAX(S10:S12) -> 454 | T22: =MAX(T10:T12) -> 173 | U22: =MAX(U10:U12) -> 50 | V22: =MAX(V10:V12) -> 64 | W22: =MAX(W10:W12) -> 5 | X22: =MAX(X10:X12) -> 0 | Y22: =MAX(Y10:Y12) -> 32 | Z22: =MAX(Z10:Z12) -> 10 | ... AF22: =MAX(AF10:AF12) -> 1531
B23: 10.15 - 10.30 | C23: 73 | D23: 26 | E23: 6 | F23: 11 | G23: 0 | H23: 0 | I23: 5 | J23: 0 | K23: 0 | L23: 0 | M23: 129 | N23: 0 | O23: =SUM(C23:L23,N23) -> 121 | P23: =SUM(C23:N23) -> 250 | R23: IP Peak Hr | S23: =MAX(S13:S18) -> 325 | T23: =MAX(T13:T18) -> 123 | U23: =MAX(U13:U18) -> 43 | V23: =MAX(V13:V18) -> 53 | W23: =MAX(W13:W18) -> 3 | X23: =MAX(X13:X18) -> 0 | Y23: =MAX(Y13:Y18) -> 32 | Z23: =MAX(Z13:Z18) -> 10 | ... AF23: =MAX(AF13:AF18) -> 1158
B24: 10.30 - 10.45 | C24: 88 | D24: 39 | E24: 8 | F24: 17 | G24: 0 | H24: 0 | I24: 3 | J24: 1 | K24: 0 | L24: 0 | M24: 142 | N24: 0 | O24: =SUM(C24:L24,N24) -> 156 | P24: =SUM(C24:N24) -> 298 | R24: PM Peak Hr | S24: =MAX(S19:S21) -> 286 | T24: =MAX(T19:T21) -> 145 | U24: =MAX(U19:U21) -> 40 | V24: =MAX(V19:V21) -> 93 | W24: =MAX(W19:W21) -> 5 | X24: =MAX(X19:X21) -> 0 | Y24: =MAX(Y19:Y21) -> 26 | Z24: =MAX(Z19:Z21) -> 11 | ... AF24: =MAX(AF19:AF21) -> 1367
B25: 10.45 - 11.00 | C25: 74 | D25: 15 | E25: 10 | F25: 10 | G25: 0 | H25: 0 | I25: 5 | J25: 1 | K25: 3 | L25: 0 | M25: 133 | N25: 0 | O25: =SUM(C25:L25,N25) -> 118 | P25: =SUM(C25:N25) -> 251 | R25: AM Period | S25: =SUM(S10:S12) -> 1237 | T25: =SUM(T10:T12) -> 452 | U25: =SUM(U10:U12) -> 135 | V25: =SUM(V10:V12) -> 183 | W25: =SUM(W10:W12) -> 5 | X25: =SUM(X10:X12) -> 0 | Y25: =SUM(Y10:Y12) -> 69 | Z25: =SUM(Z10:Z12) -> 15 | ... AF25: =SUM(AF10:AF12) -> 4075
B26: 11.00 - 11.15 | C26: 77 | D26: 3 | E26: 6 | F26: 9 | G26: 0 | H26: 0 | I26: 3 | J26: 0 | K26: 2 | L26: 0 | M26: 166 | N26: 0 | O26: =SUM(C26:L26,N26) -> 100 | P26: =SUM(C26:N26) -> 266 | R26: IP Period | S26: =SUM(S13:S18) -> 1340 | T26: =SUM(T13:T18) -> 515 | U26: =SUM(U13:U18) -> 178 | V26: =SUM(V13:V18) -> 275 | W26: =SUM(W13:W18) -> 3 | X26: =SUM(X13:X18) -> 0 | Y26: =SUM(Y13:Y18) -> 126 | Z26: =SUM(Z13:Z18) -> 38 | ... AF26: =SUM(AF13:AF18) -> 5824
B27: 11.15 - 11.30 | C27: 57 | D27: 22 | E27: 11 | F27: 15 | G27: 0 | H27: 0 | I27: 5 | J27: 3 | K27: 3 | L27: 0 | M27: 191 | N27: 0 | O27: =SUM(C27:L27,N27) -> 116 | P27: =SUM(C27:N27) -> 307 | R27: PM Period | S27: =SUM(S19:S21) -> 807 | T27: =SUM(T19:T21) -> 399 | U27: =SUM(U19:U21) -> 107 | V27: =SUM(V19:V21) -> 205 | W27: =SUM(W19:W21) -> 7 | X27: =SUM(X19:X21) -> 0 | Y27: =SUM(Y19:Y21) -> 53 | Z27: =SUM(Z19:Z21) -> 17 | ... AF27: =SUM(AF19:AF21) -> 3728
B28: 11.30 - 11.45 | C28: 69 | D28: 20 | E28: 8 | F28: 17 | G28: 0 | H28: 0 | I28: 7 | J28: 1 | K28: 1 | L28: 0 | M28: 159 | N28: 0 | O28: =SUM(C28:L28,N28) -> 123 | P28: =SUM(C28:N28) -> 282 | R28: 12 Hours | S28: =SUM(S10:S21) -> 3384 | T28: =SUM(T10:T21) -> 1366 | U28: =SUM(U10:U21) -> 420 | V28: =SUM(V10:V21) -> 663 | W28: =SUM(W10:W21) -> 15 | X28: =SUM(X10:X21) -> 0 | Y28: =SUM(Y10:Y21) -> 248 | Z28: =SUM(Z10:Z21) -> 70 | ... AF28: =SUM(AF10:AF21) -> 13627
B29: 11.45 - 12.00 | C29: 62 | D29: 26 | E29: 8 | F29: 12 | G29: 0 | H29: 0 | I29: 7 | J29: 1 | K29: 0 | L29: 0 | M29: 187 | N29: 0 | O29: =SUM(C29:L29,N29) -> 116 | P29: =SUM(C29:N29) -> 303
B30: 12.00 - 12.15 | C30: 46 | D30: 29 | E30: 4 | F30: 13 | G30: 0 | H30: 0 | I30: 2 | J30: 1 | K30: 1 | L30: 1 | M30: 140 | N30: 1 | O30: =SUM(C30:L30,N30) -> 98 | P30: =SUM(C30:N30) -> 238
B31: 12.15 - 12.30 | C31: 50 | D31: 23 | E31: 6 | F31: 10 | G31: 0 | H31: 0 | I31: 6 | J31: 2 | K31: 2 | L31: 0 | M31: 158 | N31: 0 | O31: =SUM(C31:L31,N31) -> 99 | P31: =SUM(C31:N31) -> 257
B32: 12.30 - 12.45 | C32: 50 | D32: 18 | E32: 7 | F32: 7 | G32: 0 | H32: 0 | I32: 1 | J32: 1 | K32: 1 | L32: 0 | M32: 128 | N32: 0 | O32: =SUM(C32:L32,N32) -> 85 | P32: =SUM(C32:N32) -> 213
B33: 12.45 - 13.00 | C33: 43 | D33: 24 | E33: 5 | F33: 13 | G33: 0 | H33: 0 | I33: 1 | J33: 0 | K33: 1 | L33: 0 | M33: 142 | N33: 0 | O33: =SUM(C33:L33,N33) -> 87 | P33: =SUM(C33:N33) -> 229
B34: 13.00 - 13.15 | C34: 44 | D34: 16 | E34: 3 | F34: 10 | G34: 0 | H34: 0 | I34: 3 | J34: 2 | K34: 0 | L34: 0 | M34: 162 | N34: 0 | O34: =SUM(C34:L34,N34) -> 78 | P34: =SUM(C34:N34) -> 240
B35: 13.15 - 13.30 | C35: 32 | D35: 14 | E35: 7 | F35: 12 | G35: 0 | H35: 0 | I35: 5 | J35: 1 | K35: 0 | L35: 0 | M35: 165 | N35: 0 | O35: =SUM(C35:L35,N35) -> 71 | P35: =SUM(C35:N35) -> 236
B36: 13.30 - 13.45 | C36: 57 | D36: 18 | E36: 3 | F36: 12 | G36: 0 | H36: 0 | I36: 6 | J36: 4 | K36: 2 | L36: 0 | M36: 123 | N36: 0 | O36: =SUM(C36:L36,N36) -> 102 | P36: =SUM(C36:N36) -> 225
B37: 13.45 - 14.00 | C37: 38 | D37: 13 | E37: 4 | F37: 10 | G37: 0 | H37: 0 | I37: 12 | J37: 2 | K37: 1 | L37: 0 | M37: 138 | N37: 0 | O37: =SUM(C37:L37,N37) -> 80 | P37: =SUM(C37:N37) -> 218
B38: 14.00 - 14.15 | C38: 46 | D38: 19 | E38: 6 | F38: 10 | G38: 0 | H38: 0 | I38: 7 | J38: 1 | K38: 2 | L38: 0 | M38: 111 | N38: 0 | O38: =SUM(C38:L38,N38) -> 91 | P38: =SUM(C38:N38) -> 202
B39: 14.15 - 14.30 | C39: 43 | D39: 23 | E39: 13 | F39: 13 | G39: 2 | H39: 0 | I39: 5 | J39: 3 | K39: 1 | L39: 1 | M39: 120 | N39: 0 | O39: =SUM(C39:L39,N39) -> 104 | P39: =SUM(C39:N39) -> 224
B40: 14.30 - 14.45 | C40: 45 | D40: 14 | E40: 7 | F40: 11 | G40: 0 | H40: 0 | I40: 8 | J40: 4 | K40: 5 | L40: 0 | M40: 98 | N40: 0 | O40: =SUM(C40:L40,N40) -> 94 | P40: =SUM(C40:N40) -> 192
... B57: 18.45 - 19.00 | C57: 52 | D57: 36 | E57: 6 | F57: 16 | G57: 1 | H57: 0 | I57: 2 | J57: 2 | K57: 2 | L57: 0 | M57: 218 | N57: 0 | O57: =SUM(C57:L57,N57) -> 117 | P57: =SUM(C57:N57) -> 335
B58: Totals | C58: =SUM(C10:C57) -> 3384 | D58: =SUM(D10:D57) -> 1366 | E58: =SUM(E10:E57) -> 420 | F58: =SUM(F10:F57) -> 663 | G58: =SUM(G10:G57) -> 15 | H58: =SUM(H10:H57) -> 0 | I58: =SUM(I10:I57) -> 248 | J58: =SUM(J10:J57) -> 70 | ... P58: =SUM(P10:P57) -> 13627
...

Sheet 30.07 Kyanja-Kisaasi
B1: Consultancy services for Preparation of Expressway Development Master Plan (EDMP) for Uganda
B2: MANUAL CLASSIFIED COUNT (MCC)
B3: ROAD NAME: | C3: MCC - CI - STN03 - KALINDA ROAD
C5: Date | D5: 30.07.19 | F5: Location | G5: ='29.07 Kyanja -Kisaasi'!G5:H5 -> Malcom Health center | J5: Surveyor | K5: Babirye Phiona
C6: Dir. From | D6: ='29.07 Kyanja -Kisaasi'!D6:E6 -> Kyanja | F6: Dir. To | G6: ='29.07 Kyanja -Kisaasi'!G6:H6 -> Kisaasi | J6: Supervisor | K6: ='29.07 Kyanja -Kisaasi'!K6:L6 -> Steven
B8: Time / Veh Type | R8: SUMMARY TRAFFIC VOLUMES
C9: 1. Car | D9: 2. Station Wagon | E9: 3. Pickups | F9: 4. Minibus, matatu | G9: 5. Medium bus | H9: 6. Large Bus | I9: 7. Light Truck | J9: 8. Medium Truck | K9: 9. Heavy truck | L9: 10. Truck Trailer | M9: 11. Motor cycles | N9: 12. Tractors | O9: Total Excl M/Cycles | P9: Total All | R9: Time | S9: 1. Car | T9: 2. Station Wagon | U9: 3. Pickups | V9: 4. Minibus, matatu | W9: 5. Medium bus | X9: 6. Large Bus | Y9: 7. Light Truck | Z9: 8. Medium Truck | AA9: 9. Heavy truck | AB9: 10. Truck Trailer | AC9: 11. Motorcycles | AD9: 12. Tractors, Graders | AE9: Total Excl M/ Cycles | AF9: Total All
B10: 07.00 - 07.15 | C10: 34 | D10: 36 | E10: 5 | F10: 12 | G10: 0 | H10: 0 | I10: 6 | J10: 3 | K10: 0 | L10: 0 | M10: 115 | N10: 0 | O10: =SUM(C10:L10,N10) -> 96 | P10: =SUM(C10:N10) -> 211 | R10: 0700-0800 | S10: =SUM(C10:C13) -> 157 | T10: =SUM(D10:D13) -> 70 | U10: =SUM(E10:E13) -> 15 | V10: =SUM(F10:F13) -> 61 | W10: =SUM(G10:G13) -> 1 | X10: =SUM(H10:H13) -> 0 | Y10: =SUM(I10:I13) -> 17 | Z10: =SUM(J10:J13) -> 5 | ... AF10: =SUM(P10:P13) -> 812
B11: 07.15 - 07.30 | C11: 34 | D11: 13 | E11: 1 | F11: 7 | G11: 0 | H11: 0 | I11: 2 | J11: 0 | K11: 1 | L11: 0 | M11: 93 | N11: 0 | O11: =SUM(C11:L11,N11) -> 58 | P11: =SUM(C11:N11) -> 151 | R11: 0800-0900 | S11: =SUM(C14:C17) -> 169 | T11: =SUM(D14:D17) -> 27 | U11: =SUM(E14:E17) -> 17 | V11: =SUM(F14:F17) -> 113 | W11: =SUM(G14:G17) -> 0 | X11: =SUM(H14:H17) -> 0 | Y11: =SUM(I14:I17) -> 14 | Z11: =SUM(J14:J17) -> 7 | ... AF11: =SUM(P14:P17) -> 946
B12: 07.30 - 07.45 | C12: 46 | D12: 12 | E12: 4 | F12: 17 | G12: 1 | H12: 0 | I12: 7 | J12: 1 | K12: 1 | L12: 0 | M12: 125 | N12: 0 | O12: =SUM(C12:L12,N12) -> 89 | P12: =SUM(C12:N12) -> 214 | R12: 0900-1000 | S12: =SUM(C18:C21) -> 143 | T12: =SUM(D18:D21) -> 28 | U12: =SUM(E18:E21) -> 20 | V12: =SUM(F18:F21) -> 98 | W12: =SUM(G18:G21) -> 0 | X12: =SUM(H18:H21) -> 0 | Y12: =SUM(I18:I21) -> 27 | Z12: =SUM(J18:J21) -> 9 | ... AF12: =SUM(P18:P21) -> 911
B13: 07.45 - 08.00 | C13: 43 | D13: 9 | E13: 5 | F13: 25 | G13: 0 | H13: 0 | I13: 2 | J13: 1 | K13: 1 | L13: 0 | M13: 150 | N13: 0 | O13: =SUM(C13:L13,N13) -> 86 | P13: =SUM(C13:N13) -> 236 | R13: 1000-1100 | S13: =SUM(C22:C25) -> 149 | T13: =SUM(D22:D25) -> 31 | U13: =SUM(E22:E25) -> 23 | V13: =SUM(F22:F25) -> 66 | W13: =SUM(G22:G25) -> 0 | X13: =SUM(H22:H25) -> 0 | Y13: =SUM(I22:I25) -> 29 | Z13: =SUM(J22:J25) -> 5 | ... AF13: =SUM(P22:P25) -> 859
B14: 08.00 - 08.15 | C14: 52 | D14: 5 | E14: 5 | F14: 31 | G14: 0 | H14: 0 | I14: 1 | J14: 1 | K14: 0 | L14: 0 | M14: 150 | N14: 0 | O14: =SUM(C14:L14,N14) -> 95 | P14: =SUM(C14:N14) -> 245 | R14: 1100-1200 | S14: =SUM(C26:C29) -> 164 | T14: =SUM(D26:D29) -> 18 | U14: =SUM(E26:E29) -> 22 | V14: =SUM(F26:F29) -> 63 | W14: =SUM(G26:G29) -> 0 | X14: =SUM(H26:H29) -> 0 | Y14: =SUM(I26:I29) -> 26 | Z14: =SUM(J26:J29) -> 16 | ... AF14: =SUM(P26:P29) -> 820
B15: 08.15 - 08.30 | C15: 51 | D15: 6 | E15: 6 | F15: 33 | G15: 0 | H15: 0 | I15: 5 | J15: 2 | K15: 2 | L15: 0 | M15: 150 | N15: 0 | O15: =SUM(C15:L15,N15) -> 105 | P15: =SUM(C15:N15) -> 255 | R15: 1200-1300 | S15: =SUM(C30:C33) -> 175 | T15: =SUM(D30:D33) -> 35 | U15: =SUM(E30:E33) -> 20 | V15: =SUM(F30:F33) -> 45 | W15: =SUM(G30:G33) -> 0 | X15: =SUM(H30:H33) -> 0 | Y15: =SUM(I30:I33) -> 23 | Z15: =SUM(J30:J33) -> 15 | ... AF15: =SUM(P30:P33) -> 811
B16: 08.30 - 08.45 | C16: 30 | D16: 4 | E16: 2 | F16: 24 | G16: 0 | H16: 0 | I16: 3 | J16: 0 | K16: 0 | L16: 0 | M16: 150 | N16: 0 | O16: =SUM(C16:L16,N16) -> 63 | P16: =SUM(C16:N16) -> 213 | R16: 1300-1400 | S16: =SUM(C34:C37) -> 194 | T16: =SUM(D34:D37) -> 23 | U16: =SUM(E34:E37) -> 14 | V16: =SUM(F34:F37) -> 55 | W16: =SUM(G34:G37) -> 1 | X16: =SUM(H34:H37) -> 0 | Y16: =SUM(I34:I37) -> 18 | Z16: =SUM(J34:J37) -> 17 | ... AF16: =SUM(P34:P37) -> 844
B17: 08.45 - 9.00 | C17: 36 | D17: 12 | E17: 4 | F17: 25 | G17: 0 | H17: 0 | I17: 5 | J17: 4 | K17: 2 | L17: 0 | M17: 145 | N17: 0 | O17: =SUM(C17:L17,N17) -> 88 | P17: =SUM(C17:N17) -> 233 | R17: 1400-1500 | S17: =SUM(C38:C41) -> 186 | T17: =SUM(D38:D41) -> 35 | U17: =SUM(E38:E41) -> 27 | V17: =SUM(F38:F41) -> 59 | W17: =SUM(G38:G41) -> 1 | X17: =SUM(H38:H41) -> 1 | Y17: =SUM(I38:I41) -> 21 | Z17: =SUM(J38:J41) -> 10 | ... AF17: =SUM(P38:P41) -> 837
B18: 09.00 - 09.15 | C18: 29 | D18: 7 | E18: 4 | F18: 21 | G18: 0 | H18: 0 | I18: 9 | J18: 0 | K18: 5 | L18: 0 | M18: 150 | N18: 0 | O18: =SUM(C18:L18,N18) -> 75 | P18: =SUM(C18:N18) -> 225 | R18: 1500-1600 | S18: =SUM(C42:C45) -> 166 | T18: =SUM(D42:D45) -> 25 | U18: =SUM(E42:E45) -> 30 | V18: =SUM(F42:F45) -> 45 | W18: =SUM(G42:G45) -> 2 | X18: =SUM(H42:H45) -> 0 | Y18: =SUM(I42:I45) -> 17 | Z18: =SUM(J42:J45) -> 10 | ... AF18: =SUM(P42:P45) -> 761
B19: 09.15 - 09.30 | C19: 41 | D19: 6 | E19: 5 | F19: 30 | G19: 0 | H19: 0 | I19: 7 | J19: 4 | K19: 5 | L19: 0 | M19: 150 | N19: 0 | O19: =SUM(C19:L19,N19) -> 98 | P19: =SUM(C19:N19) -> 248 | R19: 1600-1700 | S19: =SUM(C46:C49) -> 336 | T19: =SUM(D46:D49) -> 51 | U19: =SUM(E46:E49) -> 36 | V19: =SUM(F46:F49) -> 55 | W19: =SUM(G46:G49) -> 1 | X19: =SUM(H46:H49) -> 0 | Y19: =SUM(I46:I49) -> 20 | Z19: =SUM(J46:J49) -> 9 | ... AF19: =SUM(P46:P49) -> 1150
B20: 09.30 - 09.45 | C20: 48 | D20: 7 | E20: 6 | F20: 27 | G20: 0 | H20: 0 | I20: 5 | J20: 2 | K20: 3 | L20: 0 | M20: 150 | N20: 0 | O20: =SUM(C20:L20,N20) -> 98 | P20: =SUM(C20:N20) -> 248 | R20: 1700-1800 | S20: =SUM(C50:C53) -> 495 | T20: =SUM(D50:D53) -> 210 | U20: =SUM(E50:E53) -> 45 | V20: =SUM(F50:F53) -> 52 | W20: =SUM(G50:G53) -> 1 | X20: =SUM(H50:H53) -> 0 | Y20: =SUM(I50:I53) -> 6 | Z20: =SUM(J50:J53) -> 4 | ... AF20: =SUM(P50:P53) -> 1463
B21: 09.45 - 10.00 | C21: 25 | D21: 8 | E21: 5 | F21: 20 | G21: 0 | H21: 0 | I21: 6 | J21: 3 | K21: 5 | L21: 0 | M21: 118 | N21: 0 | O21: =SUM(C21:L21,N21) -> 72 | P21: =SUM(C21:N21) -> 190 | R21: 1800-1900 | S21: =SUM(C54:C57) -> 550 | T21: =SUM(D54:D57) -> 300 | U21: =SUM(E54:E57) -> 49 | V21: =SUM(F54:F57) -> 134 | W21: =SUM(G54:G57) -> 1 | X21: =SUM(H54:H57) -> 0 | Y21: =SUM(I54:I57) -> 8 | Z21: =SUM(J54:J57) -> 13 | ... AF21: =SUM(P54:P57) -> 1740
B22: 10.00 - 10.15 | C22: 33 | D22: 3 | E22: 2 | F22: 14 | G22: 0 | H22: 0 | I22: 8 | J22: 1 | K22: 4 | L22: 0 | M22: 145 | N22: 0 | O22: =SUM(C22:L22,N22) -> 65 | P22: =SUM(C22:N22) -> 210 | R22: AM Peak Hr | S22: =MAX(S10:S12) -> 169 | T22: =MAX(T10:T12) -> 70 | U22: =MAX(U10:U12) -> 20 | V22: =MAX(V10:V12) -> 113 | W22: =MAX(W10:W12) -> 1 | X22: =MAX(X10:X12) -> 0 | Y22: =MAX(Y10:Y12) -> 27 | Z22: =MAX(Z10:Z12) -> 9 | ... AF22: =MAX(AF10:AF12) -> 946
B23: 10.15 - 10.30 | C23: 40 | D23: 5 | E23: 10 | F23: 21 | G23: 0 | H23: 0 | I23: 5 | J23: 1 | K23: 4 | L23: 0 | M23: 140 | N23: 0 | O23: =SUM(C23:L23,N23) -> 86 | P23: =SUM(C23:N23) -> 226 | R23: IP Peak Hr | S23: =MAX(S13:S18) -> 194 | T23: =MAX(T13:T18) -> 35 | U23: =MAX(U13:U18) -> 30 | V23: =MAX(V13:V18) -> 66 | W23: =MAX(W13:W18) -> 2 | X23: =MAX(X13:X18) -> 1 | Y23: =MAX(Y13:Y18) -> 29 | Z23: =MAX(Z13:Z18) -> 17 | ... AF23: =MAX(AF13:AF18) -> 859
B24: 10.30 - 10.45 | C24: 30 | D24: 9 | E24: 8 | F24: 17 | G24: 0 | H24: 0 | I24: 10 | J24: 2 | K24: 1 | L24: 0 | M24: 130 | N24: 0 | O24: =SUM(C24:L24,N24) -> 77 | P24: =SUM(C24:N24) -> 207 | R24: PM Peak Hr | S24: =MAX(S19:S21) -> 550 | T24: =MAX(T19:T21) -> 300 | U24: =MAX(U19:U21) -> 49 | V24: =MAX(V19:V21) -> 134 | W24: =MAX(W19:W21) -> 1 | X24: =MAX(X19:X21) -> 0 | Y24: =MAX(Y19:Y21) -> 20 | Z24: =MAX(Z19:Z21) -> 13 | ... AF24: =MAX(AF19:AF21) -> 1740
B25: 10.45 - 11.00 | C25: 46 | D25: 14 | E25: 3 | F25: 14 | G25: 0 | H25: 0 | I25: 6 | J25: 1 | K25: 2 | L25: 0 | M25: 130 | N25: 0 | O25: =SUM(C25:L25,N25) -> 86 | P25: =SUM(C25:N25) -> 216 | R25: AM Period | S25: =SUM(S10:S12) -> 469 | T25: =SUM(T10:T12) -> 125 | U25: =SUM(U10:U12) -> 52 | V25: =SUM(V10:V12) -> 272 | W25: =SUM(W10:W12) -> 1 | X25: =SUM(X10:X12) -> 0 | Y25: =SUM(Y10:Y12) -> 58 | Z25: =SUM(Z10:Z12) -> 21 | ... AF25: =SUM(AF10:AF12) -> 2669
B26: 11.00 - 11.15 | C26: 43 | D26: 10 | E26: 6 | F26: 20 | G26: 0 | H26: 0 | I26: 9 | J26: 7 | K26: 5 | L26: 0 | M26: 140 | N26: 0 | O26: =SUM(C26:L26,N26) -> 100 | P26: =SUM(C26:N26) -> 240 | R26: IP Period | S26: =SUM(S13:S18) -> 1034 | T26: =SUM(T13:T18) -> 167 | U26: =SUM(U13:U18) -> 136 | V26: =SUM(V13:V18) -> 333 | W26: =SUM(W13:W18) -> 4 | X26: =SUM(X13:X18) -> 1 | Y26: =SUM(Y13:Y18) -> 134 | Z26: =SUM(Z13:Z18) -> 73 | ... AF26: =SUM(AF13:AF18) -> 4932
B27: 11.15 - 11.30 | C27: 40 | D27: 3 | E27: 3 | F27: 13 | G27: 0 | H27: 0 | I27: 6 | J27: 1 | K27: 5 | L27: 0 | M27: 105 | N27: 0 | O27: =SUM(C27:L27,N27) -> 71 | P27: =SUM(C27:N27) -> 176 | R27: PM Period | S27: =SUM(S19:S21) -> 1381 | T27: =SUM(T19:T21) -> 561 | U27: =SUM(U19:U21) -> 130 | V27: =SUM(V19:V21) -> 241 | W27: =SUM(W19:W21) -> 3 | X27: =SUM(X19:X21) -> 0 | Y27: =SUM(Y19:Y21) -> 34 | Z27: =SUM(Z19:Z21) -> 26 | ... AF27: =SUM(AF19:AF21) -> 4353
B28: 11.30 - 11.45 | C28: 40 | D28: 3 | E28: 6 | F28: 11 | G28: 0 | H28: 0 | I28: 4 | J28: 3 | K28: 5 | L28: 0 | M28: 145 | N28: 0 | O28: =SUM(C28:L28,N28) -> 72 | P28: =SUM(C28:N28) -> 217 | R28: 12 Hours | S28: =SUM(S10:S21) -> 2884 | T28: =SUM(T10:T21) -> 853 | U28: =SUM(U10:U21) -> 318 | V28: =SUM(V10:V21) -> 846 | W28: =SUM(W10:W21) -> 8 | X28: =SUM(X10:X21) -> 1 | Y28: =SUM(Y10:Y21) -> 226 | Z28: =SUM(Z10:Z21) -> 120 | ... AF28: =SUM(AF10:AF21) -> 11954
B29: 11.45 - 12.00 | C29: 41 | D29: 2 | E29: 7 | F29: 19 | G29: 0 | H29: 0 | I29: 7 | J29: 5 | K29: 6 | L29: 0 | M29: 100 | N29: 0 | O29: =SUM(C29:L29,N29) -> 87 | P29: =SUM(C29:N29) -> 187
B30: 12.00 - 12.15 | C30: 47 | D30: 5 | E30: 3 | F30: 13 | G30: 0 | H30: 0 | I30: 6 | J30: 5 | K30: 6 | L30: 0 | M30: 87 | N30: 0 | O30: =SUM(C30:L30,N30) -> 85 | P30: =SUM(C30:N30) -> 172
B31: 12.15 - 12.30 | C31: 40 | D31: 5 | E31: 7 | F31: 11 | G31: 0 | H31: 0 | I31: 5 | J31: 3 | K31: 1 | L31: 0 | M31: 110 | N31: 0 | O31: =SUM(C31:L31,N31) -> 72 | P31: =SUM(C31:N31) -> 182
B32: 12.30 - 12.45 | C32: 50 | D32: 10 | E32: 6 | F32: 13 | G32: 0 | H32: 0 | I32: 6 | J32: 5 | K32: 9 | L32: 0 | M32: 150 | N32: 0 | O32: =SUM(C32:L32,N32) -> 99 | P32: =SUM(C32:N32) -> 249
B33: 12.45 - 13.00 | C33: 38 | D33: 15 | E33: 4 | F33: 8 | G33: 0 | H33: 0 | I33: 6 | J33: 2 | K33: 5 | L33: 0 | M33: 130 | N33: 0 | O33: =SUM(C33:L33,N33) -> 78 | P33: =SUM(C33:N33) -> 208
B34: 13.00 - 13.15 | C34: 50 | D34: 9 | E34: 4 | F34: 19 | G34: 1 | H34: 0 | I34: 5 | J34: 3 | K34: 4 | L34: 0 | M34: 150 | N34: 0 | O34: =SUM(C34:L34,N34) -> 95 | P34: =SUM(C34:N34) -> 245
B35: 13.15 - 13.30 | C35: 44 | D35: 6 | E35: 4 | F35: 13 | G35: 0 | H35: 0 | I35: 2 | J35: 5 | K35: 3 | L35: 0 | M35: 150 | N35: 0 | O35: =SUM(C35:L35,N35) -> 77 | P35: =SUM(C35:N35) -> 227
B36: 13.30 - 13.45 | C36: 50 | D36: 5 | E36: 1 | F36: 12 | G36: 0 | H36: 0 | I36: 6 | J36: 5 | K36: 2 | L36: 0 | M36: 75 | N36: 0 | O36: =SUM(C36:L36,N36) -> 81 | P36: =SUM(C36:N36) -> 156
B37: 13.45 - 14.00 | C37: 50 | D37: 3 | E37: 5 | F37: 11 | G37: 0 | H37: 0 | I37: 5 | J37: 4 | K37: 3 | L37: 0 | M37: 135 | N37: 0 | O37: =SUM(C37:L37,N37) -> 81 | P37: =SUM(C37:N37) -> 216
B38: 14.00 - 14.15 | C38: 48 | D38: 6 | E38: 3 | F38: 18 | G38: 0 | H38: 0 | I38: 6 | J38: 4 | K38: 2 | L38: 0 | M38: 111 | N38: 0 | O38: =SUM(C38:L38,N38) -> 87 | P38: =SUM(C38:N38) -> 198
B39: 14.15 - 14.30 | C39: 47 | D39: 8 | E39: 8 | F39: 13 | G39: 0 | H39: 0 | I39: 3 | J39: 2 | K39: 1 | L39: 0 | M39: 126 | N39: 0 | O39: =SUM(C39:L39,N39) -> 82 | P39: =SUM(C39:N39) -> 208
B40: 14.30 - 14.45 | C40: 46 | D40: 11 | E40: 6 | F40: 12 | G40: 1 | H40: 1 | I40: 6 | J40: 1 | K40: 4 | L40: 0 | M40: 130 | N40: 0 | O40: =SUM(C40:L40,N40) -> 88 | P40: =SUM(C40:N40) -> 218
... B57: 18.45 - 19.00 | C57: 170 | D57: 55 | E57: 25 | F57: 22 | G57: 0 | H57: 0 | I57: 4 | J57: 3 | K57: 2 | L57: 0 | M57: 170 | N57: 0 | O57: =SUM(C57:L57,N57) -> 281 | P57: =SUM(C57:N57) -> 451
B58: Totals | C58: =SUM(C10:C57) -> 2884 | D58: =SUM(D10:D57) -> 853 | E58: =SUM(E10:E57) -> 318 | F58: =SUM(F10:F57) -> 846 | G58: =SUM(G10:G57) -> 8 | H58: =SUM(H10:H57) -> 1 | I58: =SUM(I10:I57) -> 226 | J58: =SUM(J10:J57) -> 120 | ... P58: =SUM(P10:P57) -> 11954
...

Sheet 30.07 Kisaasi-Kyanja
B1: Consultancy services for Preparation of Expressway Development Master Plan (EDMP) for Uganda
B2: MANUAL CLASSIFIED COUNT (MCC)
B3: ROAD NAME: | C3: ='29.07 Kisaasi-Kyanja'!C3:G3 -> MCC - C1 - STN34- KISAASI-KYANJA ROAD
C5: Date | D5: ='30.07 Kyanja-Kisaasi'!D5 -> 30.07.19 | F5: Location | G5: ='29.07 Kyanja -Kisaasi'!G5:H5 -> Malcom Health center | J5: Surveyor | K5: Kizito Geofrey
C6: Dir. From | D6: Kisaasi | F6: Dir. To | G6: Kyanja | J6: Supervisor | K6: ='29.07 Kyanja -Kisaasi'!K6:L6 -> Steven
B8: Time / Veh Type | R8: SUMMARY TRAFFIC VOLUMES
C9: 1. Car | D9: 2. Station Wagon | E9: 3. Pickups | F9: 4. Minibus, matatu | G9: 5. Medium bus | H9: 6. Large Bus | I9: 7. Light Truck | J9: 8. Medium Truck | K9: 9. Heavy truck | L9: 10. Truck Trailer | M9: 11. Motor cycles | N9: 12. Tractors | O9: Total Excl M/Cycles | P9: Total All | R9: Time | S9: 1. Car | T9: 2. Station Wagon | U9: 3. Pickups | V9: 4. Minibus, matatu | W9: 5. Medium bus | X9: 6. Large Bus | Y9: 7. Light Truck | Z9: 8. Medium Truck | AA9: 9. Heavy truck | AB9: 10. Truck Trailer | AC9: 11. Motorcycles | AD9: 12. Tractors, Graders | AE9: Total Excl M/ Cycles | AF9: Total All
B10: 07.00 - 07.15 | C10: 137 | D10: 51 | E10: 34 | F10: 30 | G10: 0 | H10: 0 | I10: 2 | J10: 0 | K10: 0 | L10: 0 | M10: 204 | N10: 0 | O10: =SUM(C10:L10,N10) -> 254 | P10: =SUM(C10:N10) -> 458 | R10: 0700-0800 | S10: =SUM(C10:C13) -> 498 | T10: =SUM(D10:D13) -> 158 | U10: =SUM(E10:E13) -> 87 | V10: =SUM(F10:F13) -> 86 | W10: =SUM(G10:G13) -> 0 | X10: =SUM(H10:H13) -> 0 | Y10: =SUM(I10:I13) -> 9 | Z10: =SUM(J10:J13) -> 3 | ... AF10: =SUM(P10:P13) -> 1871
B11: 07.15 - 07.30 | C11: 134 | D11: 50 | E11: 21 | F11: 23 | G11: 0 | H11: 0 | I11: 0 | J11: 1 | K11: 1 | L11: 0 | M11: 230 | N11: 0 | O11: =SUM(C11:L11,N11) -> 230 | P11: =SUM(C11:N11) -> 460 | R11: 0800-0900 | S11: =SUM(C14:C17) -> 495 | T11: =SUM(D14:D17) -> 106 | U11: =SUM(E14:E17) -> 56 | V11: =SUM(F14:F17) -> 70 | W11: =SUM(G14:G17) -> 1 | X11: =SUM(H14:H17) -> 0 | Y11: =SUM(I14:I17) -> 20 | Z11: =SUM(J14:J17) -> 6 | ... AF11: =SUM(P14:P17) -> 1851
B12: 07.30 - 07.45 | C12: 128 | D12: 27 | E12: 20 | F12: 19 | G12: 0 | H12: 0 | I12: 3 | J12: 2 | K12: 1 | L12: 0 | M12: 280 | N12: 0 | O12: =SUM(C12:L12,N12) -> 200 | P12: =SUM(C12:N12) -> 480 | R12: 0900-1000 | S12: =SUM(C18:C21) -> 384 | T12: =SUM(D18:D21) -> 95 | U12: =SUM(E18:E21) -> 49 | V12: =SUM(F18:F21) -> 57 | W12: =SUM(G18:G21) -> 0 | X12: =SUM(H18:H21) -> 0 | Y12: =SUM(I18:I21) -> 23 | Z12: =SUM(J18:J21) -> 11 | ... AF12: =SUM(P18:P21) -> 1488
B13: 07.45 - 08.00 | C13: 99 | D13: 30 | E13: 12 | F13: 14 | G13: 0 | H13: 0 | I13: 4 | J13: 0 | K13: 0 | L13: 0 | M13: 314 | N13: 0 | O13: =SUM(C13:L13,N13) -> 159 | P13: =SUM(C13:N13) -> 473 | R13: 1000-1100 | S13: =SUM(C22:C25) -> 286 | T13: =SUM(D22:D25) -> 106 | U13: =SUM(E22:E25) -> 36 | V13: =SUM(F22:F25) -> 48 | W13: =SUM(G22:G25) -> 1 | X13: =SUM(H22:H25) -> 0 | Y13: =SUM(I22:I25) -> 14 | Z13: =SUM(J22:J25) -> 6 | ... AF13: =SUM(P22:P25) -> 1234
B14: 08.00 - 08.15 | C14: 134 | D14: 35 | E14: 16 | F14: 20 | G14: 0 | H14: 0 | I14: 1 | J14: 3 | K14: 1 | L14: 0 | M14: 287 | N14: 0 | O14: =SUM(C14:L14,N14) -> 210 | P14: =SUM(C14:N14) -> 497 | R14: 1100-1200 | S14: =SUM(C26:C29) -> 244 | T14: =SUM(D26:D29) -> 62 | U14: =SUM(E26:E29) -> 32 | V14: =SUM(F26:F29) -> 44 | W14: =SUM(G26:G29) -> 0 | X14: =SUM(H26:H29) -> 0 | Y14: =SUM(I26:I29) -> 17 | Z14: =SUM(J26:J29) -> 15 | ... AF14: =SUM(P26:P29) -> 986
B15: 08.15 - 08.30 | C15: 135 | D15: 32 | E15: 13 | F15: 17 | G15: 1 | H15: 0 | I15: 9 | J15: 0 | K15: 0 | L15: 0 | M15: 284 | N15: 0 | O15: =SUM(C15:L15,N15) -> 207 | P15: =SUM(C15:N15) -> 491 | R15: 1200-1300 | S15: =SUM(C30:C33) -> 231 | T15: =SUM(D30:D33) -> 69 | U15: =SUM(E30:E33) -> 44 | V15: =SUM(F30:F33) -> 36 | W15: =SUM(G30:G33) -> 0 | X15: =SUM(H30:H33) -> 0 | Y15: =SUM(I30:I33) -> 16 | Z15: =SUM(J30:J33) -> 12 | ... AF15: =SUM(P30:P33) -> 906
B16: 08.30 - 08.45 | C16: 117 | D16: 22 | E16: 14 | F16: 20 | G16: 0 | H16: 0 | I16: 2 | J16: 1 | K16: 1 | L16: 0 | M16: 251 | N16: 0 | O16: =SUM(C16:L16,N16) -> 177 | P16: =SUM(C16:N16) -> 428 | R16: 1300-1400 | S16: =SUM(C34:C37) -> 185 | T16: =SUM(D34:D37) -> 47 | U16: =SUM(E34:E37) -> 29 | V16: =SUM(F34:F37) -> 52 | W16: =SUM(G34:G37) -> 1 | X16: =SUM(H34:H37) -> 0 | Y16: =SUM(I34:I37) -> 14 | Z16: =SUM(J34:J37) -> 15 | ... AF16: =SUM(P34:P37) -> 919
B17: 08.45 - 9.00 | C17: 109 | D17: 17 | E17: 13 | F17: 13 | G17: 0 | H17: 0 | I17: 8 | J17: 2 | K17: 3 | L17: 0 | M17: 270 | N17: 0 | O17: =SUM(C17:L17,N17) -> 165 | P17: =SUM(C17:N17) -> 435 | R17: 1400-1500 | S17: =SUM(C38:C41) -> 165 | T17: =SUM(D38:D41) -> 43 | U17: =SUM(E38:E41) -> 31 | V17: =SUM(F38:F41) -> 40 | W17: =SUM(G38:G41) -> 4 | X17: =SUM(H38:H41) -> 0 | Y17: =SUM(I38:I41) -> 23 | Z17: =SUM(J38:J41) -> 11 | ... AF17: =SUM(P38:P41) -> 1009
B18: 09.00 - 09.15 | C18: 105 | D18: 43 | E18: 15 | F18: 18 | G18: 0 | H18: 0 | I18: 5 | J18: 3 | K18: 3 | L18: 0 | M18: 232 | N18: 0 | O18: =SUM(C18:L18,N18) -> 192 | P18: =SUM(C18:N18) -> 424 | R18: 1500-1600 | S18: =SUM(C42:C45) -> 189 | T18: =SUM(D42:D45) -> 55 | U18: =SUM(E42:E45) -> 26 | V18: =SUM(F42:F45) -> 45 | W18: =SUM(G42:G45) -> 1 | X18: =SUM(H42:H45) -> 0 | Y18: =SUM(I42:I45) -> 16 | Z18: =SUM(J42:J45) -> 9 | ... AF18: =SUM(P42:P45) -> 1127
B19: 09.15 - 09.30 | C19: 94 | D19: 14 | E19: 11 | F19: 14 | G19: 0 | H19: 0 | I19: 3 | J19: 6 | K19: 1 | L19: 0 | M19: 215 | N19: 0 | O19: =SUM(C19:L19,N19) -> 143 | P19: =SUM(C19:N19) -> 358 | R19: 1600-1700 | S19: =SUM(C46:C49) -> 209 | T19: =SUM(D46:D49) -> 59 | U19: =SUM(E46:E49) -> 36 | V19: =SUM(F46:F49) -> 48 | W19: =SUM(G46:G49) -> 0 | X19: =SUM(H46:H49) -> 0 | Y19: =SUM(I46:I49) -> 17 | Z19: =SUM(J46:J49) -> 6 | ... AF19: =SUM(P46:P49) -> 1192
B20: 09.30 - 09.45 | C20: 90 | D20: 21 | E20: 12 | F20: 13 | G20: 0 | H20: 0 | I20: 7 | J20: 2 | K20: 3 | L20: 0 | M20: 220 | N20: 0 | O20: =SUM(C20:L20,N20) -> 148 | P20: =SUM(C20:N20) -> 368 | R20: 1700-1800 | S20: =SUM(C50:C53) -> 239 | T20: =SUM(D50:D53) -> 70 | U20: =SUM(E50:E53) -> 35 | V20: =SUM(F50:F53) -> 53 | W20: =SUM(G50:G53) -> 3 | X20: =SUM(H50:H53) -> 0 | Y20: =SUM(I50:I53) -> 16 | Z20: =SUM(J50:J53) -> 17 | ... AF20: =SUM(P50:P53) -> 1175
B21: 09.45 - 10.00 | C21: 95 | D21: 17 | E21: 11 | F21: 12 | G21: 0 | H21: 0 | I21: 8 | J21: 0 | K21: 2 | L21: 0 | M21: 193 | N21: 0 | O21: =SUM(C21:L21,N21) -> 145 | P21: =SUM(C21:N21) -> 338 | R21: 1800-1900 | S21: =SUM(C54:C57) -> 215 | T21: =SUM(D54:D57) -> 57 | U21: =SUM(E54:E57) -> 25 | V21: =SUM(F54:F57) -> 60 | W21: =SUM(G54:G57) -> 1 | X21: =SUM(H54:H57) -> 0 | Y21: =SUM(I54:I57) -> 8 | Z21: =SUM(J54:J57) -> 7 | ... AF21: =SUM(P54:P57) -> 1149
B22: 10.00 - 10.15 | C22: 81 | D22: 26 | E22: 7 | F22: 13 | G22: 0 | H22: 0 | I22: 2 | J22: 1 | K22: 1 | L22: 0 | M22: 202 | N22: 0 | O22: =SUM(C22:L22,N22) -> 131 | P22: =SUM(C22:N22) -> 333 | R22: AM Peak Hr | S22: =MAX(S10:S12) -> 498 | T22: =MAX(T10:T12) -> 158 | U22: =MAX(U10:U12) -> 87 | V22: =MAX(V10:V12) -> 86 | W22: =MAX(W10:W12) -> 1 | X22: =MAX(X10:X12) -> 0 | Y22: =MAX(Y10:Y12) -> 23 | Z22: =MAX(Z10:Z12) -> 11 | ... AF22: =MAX(AF10:AF12) -> 1871
B23: 10.15 - 10.30 | C23: 71 | D23: 28 | E23: 9 | F23: 14 | G23: 1 | H23: 0 | I23: 3 | J23: 1 | K23: 0 | L23: 0 | M23: 168 | N23: 0 | O23: =SUM(C23:L23,N23) -> 127 | P23: =SUM(C23:N23) -> 295 | R23: IP Peak Hr | S23: =MAX(S13:S18) -> 286 | T23: =MAX(T13:T18) -> 106 | U23: =MAX(U13:U18) -> 44 | V23: =MAX(V13:V18) -> 52 | W23: =MAX(W13:W18) -> 4 | X23: =MAX(X13:X18) -> 0 | Y23: =MAX(Y13:Y18) -> 23 | Z23: =MAX(Z13:Z18) -> 15 | ... AF23: =MAX(AF13:AF18) -> 1234
B24: 10.30 - 10.45 | C24: 78 | D24: 21 | E24: 9 | F24: 11 | G24: 0 | H24: 0 | I24: 7 | J24: 2 | K24: 6 | L24: 0 | M24: 191 | N24: 0 | O24: =SUM(C24:L24,N24) -> 134 | P24: =SUM(C24:N24) -> 325 | R24: PM Peak Hr | S24: =MAX(S19:S21) -> 239 | T24: =MAX(T19:T21) -> 70 | U24: =MAX(U19:U21) -> 36 | V24: =MAX(V19:V21) -> 60 | W24: =MAX(W19:W21) -> 3 | X24: =MAX(X19:X21) -> 0 | Y24: =MAX(Y19:Y21) -> 17 | Z24: =MAX(Z19:Z21) -> 17 | ... AF24: =MAX(AF19:AF21) -> 1192
B25: 10.45 - 11.00 | C25: 56 | D25: 31 | E25: 11 | F25: 10 | G25: 0 | H25: 0 | I25: 2 | J25: 2 | K25: 2 | L25: 0 | M25: 167 | N25: 0 | O25: =SUM(C25:L25,N25) -> 114 | P25: =SUM(C25:N25) -> 281 | R25: AM Period | S25: =SUM(S10:S12) -> 1377 | T25: =SUM(T10:T12) -> 359 | U25: =SUM(U10:U12) -> 192 | V25: =SUM(V10:V12) -> 213 | W25: =SUM(W10:W12) -> 1 | X25: =SUM(X10:X12) -> 0 | Y25: =SUM(Y10:Y12) -> 52 | Z25: =SUM(Z10:Z12) -> 20 | ... AF25: =SUM(AF10:AF12) -> 5210
B26: 11.00 - 11.15 | C26: 64 | D26: 23 | E26: 11 | F26: 12 | G26: 0 | H26: 0 | I26: 6 | J26: 5 | K26: 3 | L26: 0 | M26: 183 | N26: 0 | O26: =SUM(C26:L26,N26) -> 124 | P26: =SUM(C26:N26) -> 307 | R26: IP Period | S26: =SUM(S13:S18) -> 1300 | T26: =SUM(T13:T18) -> 382 | U26: =SUM(U13:U18) -> 198 | V26: =SUM(V13:V18) -> 265 | W26: =SUM(W13:W18) -> 7 | X26: =SUM(X13:X18) -> 0 | Y26: =SUM(Y13:Y18) -> 100 | Z26: =SUM(Z13:Z18) -> 68 | ... AF26: =SUM(AF13:AF18) -> 6181
B27: 11.15 - 11.30 | C27: 55 | D27: 18 | E27: 6 | F27: 14 | G27: 0 | H27: 0 | I27: 5 | J27: 2 | K27: 1 | L27: 0 | M27: 125 | N27: 0 | O27: =SUM(C27:L27,N27) -> 101 | P27: =SUM(C27:N27) -> 226 | R27: PM Period | S27: =SUM(S19:S21) -> 663 | T27: =SUM(T19:T21) -> 186 | U27: =SUM(U19:U21) -> 96 | V27: =SUM(V19:V21) -> 161 | W27: =SUM(W19:W21) -> 4 | X27: =SUM(X19:X21) -> 0 | Y27: =SUM(Y19:Y21) -> 41 | Z27: =SUM(Z19:Z21) -> 30 | ... AF27: =SUM(AF19:AF21) -> 3516
B28: 11.30 - 11.45 | C28: 63 | D28: 12 | E28: 8 | F28: 11 | G28: 0 | H28: 0 | I28: 3 | J28: 4 | K28: 2 | L28: 0 | M28: 153 | N28: 0 | O28: =SUM(C28:L28,N28) -> 103 | P28: =SUM(C28:N28) -> 256 | R28: 12 Hours | S28: =SUM(S10:S21) -> 3340 | T28: =SUM(T10:T21) -> 927 | U28: =SUM(U10:U21) -> 486 | V28: =SUM(V10:V21) -> 639 | W28: =SUM(W10:W21) -> 12 | X28: =SUM(X10:X21) -> 0 | Y28: =SUM(Y10:Y21) -> 193 | Z28: =SUM(Z10:Z21) -> 118 | ... AF28: =SUM(AF10:AF21) -> 14907
B29: 11.45 - 12.00 | C29: 62 | D29: 9 | E29: 7 | F29: 7 | G29: 0 | H29: 0 | I29: 3 | J29: 4 | K29: 2 | L29: 0 | M29: 103 | N29: 0 | O29: =SUM(C29:L29,N29) -> 94 | P29: =SUM(C29:N29) -> 197
B30: 12.00 - 12.15 | C30: 66 | D30: 19 | E30: 15 | F30: 11 | G30: 0 | H30: 0 | I30: 4 | J30: 2 | K30: 0 | L30: 2 | M30: 132 | N30: 0 | O30: =SUM(C30:L30,N30) -> 119 | P30: =SUM(C30:N30) -> 251
B31: 12.15 - 12.30 | C31: 67 | D31: 21 | E31: 15 | F31: 8 | G31: 0 | H31: 0 | I31: 2 | J31: 2 | K31: 0 | L31: 0 | M31: 125 | N31: 0 | O31: =SUM(C31:L31,N31) -> 115 | P31: =SUM(C31:N31) -> 240
B32: 12.30 - 12.45 | C32: 42 | D32: 17 | E32: 4 | F32: 9 | G32: 0 | H32: 0 | I32: 7 | J32: 7 | K32: 1 | L32: 0 | M32: 122 | N32: 0 | O32: =SUM(C32:L32,N32) -> 87 | P32: =SUM(C32:N32) -> 209
B33: 12.45 - 13.00 | C33: 56 | D33: 12 | E33: 10 | F33: 8 | G33: 0 | H33: 0 | I33: 3 | J33: 1 | K33: 0 | L33: 0 | M33: 116 | N33: 0 | O33: =SUM(C33:L33,N33) -> 90 | P33: =SUM(C33:N33) -> 206
B34: 13.00 - 13.15 | C34: 55 | D34: 11 | E34: 12 | F34: 14 | G34: 0 | H34: 0 | I34: 5 | J34: 4 | K34: 0 | L34: 2 | M34: 151 | N34: 0 | O34: =SUM(C34:L34,N34) -> 103 | P34: =SUM(C34:N34) -> 254
B35: 13.15 - 13.30 | C35: 41 | D35: 12 | E35: 10 | F35: 8 | G35: 0 | H35: 0 | I35: 4 | J35: 5 | K35: 3 | L35: 1 | M35: 132 | N35: 0 | O35: =SUM(C35:L35,N35) -> 84 | P35: =SUM(C35:N35) -> 216
B36: 13.30 - 13.45 | C36: 46 | D36: 14 | E36: 5 | F36: 19 | G36: 1 | H36: 0 | I36: 5 | J36: 5 | K36: 3 | L36: 1 | M36: 146 | N36: 0 | O36: =SUM(C36:L36,N36) -> 99 | P36: =SUM(C36:N36) -> 245
B37: 13.45 - 14.00 | C37: 43 | D37: 10 | E37: 2 | F37: 11 | G37: 0 | H37: 0 | I37: 0 | J37: 1 | K37: 0 | L37: 0 | M37: 137 | N37: 0 | O37: =SUM(C37:L37,N37) -> 67 | P37: =SUM(C37:N37) -> 204
B38: 14.00 - 14.15 | C38: 44 | D38: 7 | E38: 13 | F38: 10 | G38: 0 | H38: 0 | I38: 8 | J38: 7 | K38: 1 | L38: 1 | M38: 125 | N38: 0 | O38: =SUM(C38:L38,N38) -> 91 | P38: =SUM(C38:N38) -> 216
B39: 14.15 - 14.30 | C39: 44 | D39: 15 | E39: 4 | F39: 10 | G39: 2 | H39: 0 | I39: 5 | J39: 1 | K39: 6 | L39: 0 | M39: 188 | N39: 0 | O39: =SUM(C39:L39,N39) -> 87 | P39: =SUM(C39:N39) -> 275
B40: 14.30 - 14.45 | C40: 21 | D40: 10 | E40: 5 | F40: 7 | G40: 1 | H40: 0 | I40: 0 | J40: 2 | K40: 2 | L40: 0 | M40: 179 | N40: 0 | O40: =SUM(C40:L40,N40) -> 48 | P40: =SUM(C40:N40) -> 227
... B57: 18.45 - 19.00 | C57: 73 | D57: 27 | E57: 7 | F57: 15 | G57: 1 | H57: 0 | I57: 2 | J57: 2 | K57: 2 | L57: 0 | M57: 208 | N57: 0 | O57: =SUM(C57:L57,N57) -> 129 | P57: =SUM(C57:N57) -> 337
B58: Totals | C58: =SUM(C10:C57) -> 3340 | D58: =SUM(D10:D57) -> 927 | E58: =SUM(E10:E57) -> 486 | F58: =SUM(F10:F57) -> 639 | G58: =SUM(G10:G57) -> 12 | H58: =SUM(H10:H57) -> 0 | I58: =SUM(I10:I57) -> 193 | J58: =SUM(J10:J57) -> 118 | ... P58: =SUM(P10:P57) -> 14907
...

Sheet 31.07 Kyanja-Kisaasi
B1: Consultancy services for Preparation of Expressway Development Master Plan (EDMP) for Uganda
B2: MANUAL CLASSIFIED COUNT (MCC)
B3: ROAD NAME: | C3: ='29.07 Kyanja -Kisaasi'!C3:G3 -> MCC - C1 - STN34- KISAASI-KYANJA ROAD
C5: Date | D5: 31.07.19 | F5: Location | G5: ='29.07 Kyanja -Kisaasi'!G5:H5 -> Malcom Health center | J5: Surveyor | K5: Babirye Phiona
C6: Dir. From | D6: ='29.07 Kyanja -Kisaasi'!D6:E6 -> Kyanja | F6: Dir. To | G6: ='29.07 Kyanja -Kisaasi'!G6:H6 -> Kisaasi | J6: Supervisor | K6: ='29.07 Kyanja -Kisaasi'!K6:L6 -> Steven
B8: Time / Veh Type | R8: SUMMARY TRAFFIC VOLUMES
C9: 1. Car | D9: 2. Station Wagon | E9: 3. Pickups | F9: 4. Minibus, matatu | G9: 5. Medium bus | H9: 6. Large Bus | I9: 7. Light Truck | J9: 8. Medium Truck | K9: 9. Heavy truck | L9: 10. Truck Trailer | M9: 11. Motor cycles | N9: 12. Tractors | O9: Total Excl M/Cycles | P9: Total All | R9: Time | S9: 1. Car | T9: 2. Station Wagon | U9: 3. Pickups | V9: 4. Minibus, matatu | W9: 5. Medium bus | X9: 6. Large Bus | Y9: 7. Light Truck | Z9: 8. Medium Truck | AA9: 9. Heavy truck | AB9: 10. Truck Trailer | AC9: 11. Motorcycles | AD9: 12. Tractors, Graders | AE9: Total Excl M/ Cycles | AF9: Total All
B10: 07.00 - 07.15 | C10: 61 | D10: 10 | E10: 9 | F10: 16 | G10: 0 | H10: 0 | I10: 2 | J10: 3 | K10: 6 | L10: 0 | M10: 100 | N10: 0 | O10: =SUM(C10:L10,N10) -> 107 | P10: =SUM(C10:N10) -> 207 | R10: 0700-0800 | S10: =SUM(C10:C13) -> 187 | T10: =SUM(D10:D13) -> 35 | U10: =SUM(E10:E13) -> 22 | V10: =SUM(F10:F13) -> 64 | W10: =SUM(G10:G13) -> 2 | X10: =SUM(H10:H13) -> 0 | Y10: =SUM(I10:I13) -> 4 | Z10: =SUM(J10:J13) -> 6 | ... AF10: =SUM(P10:P13) -> 922
B11: 07.15 - 07.30 | C11: 41 | D11: 10 | E11: 7 | F11: 11 | G11: 2 | H11: 0 | I11: 0 | J11: 0 | K11: 7 | L11: 0 | M11: 152 | N11: 0 | O11: =SUM(C11:L11,N11) -> 78 | P11: =SUM(C11:N11) -> 230 | R11: 0800-0900 | S11: =SUM(C14:C17) -> 164 | T11: =SUM(D14:D17) -> 18 | U11: =SUM(E14:E17) -> 22 | V11: =SUM(F14:F17) -> 128 | W11: =SUM(G14:G17) -> 2 | X11: =SUM(H14:H17) -> 1 | Y11: =SUM(I14:I17) -> 10 | Z11: =SUM(J14:J17) -> 5 | ... AF11: =SUM(P14:P17) -> 1123
B12: 07.30 - 07.45 | C12: 48 | D12: 8 | E12: 3 | F12: 16 | G12: 0 | H12: 0 | I12: 1 | J12: 1 | K12: 2 | L12: 0 | M12: 153 | N12: 0 | O12: =SUM(C12:L12,N12) -> 79 | P12: =SUM(C12:N12) -> 232 | R12: 0900-1000 | S12: =SUM(C18:C21) -> 143 | T12: =SUM(D18:D21) -> 38 | U12: =SUM(E18:E21) -> 28 | V12: =SUM(F18:F21) -> 78 | W12: =SUM(G18:G21) -> 0 | X12: =SUM(H18:H21) -> 0 | Y12: =SUM(I18:I21) -> 21 | Z12: =SUM(J18:J21) -> 11 | ... AF12: =SUM(P18:P21) -> 936
B13: 07.45 - 08.00 | C13: 37 | D13: 7 | E13: 3 | F13: 21 | G13: 0 | H13: 0 | I13: 1 | J13: 2 | K13: 2 | L13: 0 | M13: 180 | N13: 0 | O13: =SUM(C13:L13,N13) -> 73 | P13: =SUM(C13:N13) -> 253 | R13: 1000-1100 | S13: =SUM(C22:C25) -> 168 | T13: =SUM(D22:D25) -> 25 | U13: =SUM(E22:E25) -> 21 | V13: =SUM(F22:F25) -> 72 | W13: =SUM(G22:G25) -> 0 | X13: =SUM(H22:H25) -> 0 | Y13: =SUM(I22:I25) -> 23 | Z13: =SUM(J22:J25) -> 6 | ... AF13: =SUM(P22:P25) -> 930
B14: 08.00 - 08.15 | C14: 41 | D14: 5 | E14: 4 | F14: 29 | G14: 1 | H14: 0 | I14: 3 | J14: 1 | K14: 2 | L14: 0 | M14: 220 | N14: 0 | O14: =SUM(C14:L14,N14) -> 86 | P14: =SUM(C14:N14) -> 306 | R14: 1100-1200 | S14: =SUM(C26:C29) -> 150 | T14: =SUM(D26:D29) -> 69 | U14: =SUM(E26:E29) -> 30 | V14: =SUM(F26:F29) -> 80 | W14: =SUM(G26:G29) -> 1 | X14: =SUM(H26:H29) -> 0 | Y14: =SUM(I26:I29) -> 23 | Z14: =SUM(J26:J29) -> 9 | ... AF14: =SUM(P26:P29) -> 846
B15: 08.15 - 08.30 | C15: 42 | D15: 7 | E15: 9 | F15: 33 | G15: 0 | H15: 0 | I15: 1 | J15: 1 | K15: 5 | L15: 0 | M15: 170 | N15: 0 | O15: =SUM(C15:L15,N15) -> 98 | P15: =SUM(C15:N15) -> 268 | R15: 1200-1300 | S15: =SUM(C30:C33) -> 165 | T15: =SUM(D30:D33) -> 21 | U15: =SUM(E30:E33) -> 15 | V15: =SUM(F30:F33) -> 51 | W15: =SUM(G30:G33) -> 0 | X15: =SUM(H30:H33) -> 0 | Y15: =SUM(I30:I33) -> 31 | Z15: =SUM(J30:J33) -> 8 | ... AF15: =SUM(P30:P33) -> 714
B16: 08.30 - 08.45 | C16: 45 | D16: 1 | E16: 3 | F16: 32 | G16: 1 | H16: 0 | I16: 4 | J16: 3 | K16: 3 | L16: 0 | M16: 185 | N16: 0 | O16: =SUM(C16:L16,N16) -> 92 | P16: =SUM(C16:N16) -> 277 | R16: 1300-1400 | S16: =SUM(C34:C37) -> 82 | T16: =SUM(D34:D37) -> 148 | U16: =SUM(E34:E37) -> 33 | V16: =SUM(F34:F37) -> 90 | W16: =SUM(G34:G37) -> 0 | X16: =SUM(H34:H37) -> 3 | Y16: =SUM(I34:I37) -> 24 | Z16: =SUM(J34:J37) -> 8 | ... AF16: =SUM(P34:P37) -> 711
B17: 08.45 - 9.00 | C17: 36 | D17: 5 | E17: 6 | F17: 34 | G17: 0 | H17: 1 | I17: 2 | J17: 0 | K17: 3 | L17: 0 | M17: 185 | N17: 0 | O17: =SUM(C17:L17,N17) -> 87 | P17: =SUM(C17:N17) -> 272 | R17: 1400-1500 | S17: =SUM(C38:C41) -> 150 | T17: =SUM(D38:D41) -> 132 | U17: =SUM(E38:E41) -> 20 | V17: =SUM(F38:F41) -> 50 | W17: =SUM(G38:G41) -> 0 | X17: =SUM(H38:H41) -> 0 | Y17: =SUM(I38:I41) -> 26 | Z17: =SUM(J38:J41) -> 9 | ... AF17: =SUM(P38:P41) -> 857
B18: 09.00 - 09.15 | C18: 31 | D18: 10 | E18: 7 | F18: 15 | G18: 0 | H18: 0 | I18: 2 | J18: 5 | K18: 6 | L18: 0 | M18: 152 | N18: 0 | O18: =SUM(C18:L18,N18) -> 76 | P18: =SUM(C18:N18) -> 228 | R18: 1500-1600 | S18: =SUM(C42:C45) -> 132 | T18: =SUM(D42:D45) -> 134 | U18: =SUM(E42:E45) -> 23 | V18: =SUM(F42:F45) -> 70 | W18: =SUM(G42:G45) -> 0 | X18: =SUM(H42:H45) -> 0 | Y18: =SUM(I42:I45) -> 23 | Z18: =SUM(J42:J45) -> 12 | ... AF18: =SUM(P42:P45) -> 805
B19: 09.15 - 09.30 | C19: 32 | D19: 13 | E19: 5 | F19: 24 | G19: 0 | H19: 0 | I19: 8 | J19: 3 | K19: 3 | L19: 0 | M19: 175 | N19: 0 | O19: =SUM(C19:L19,N19) -> 88 | P19: =SUM(C19:N19) -> 263 | R19: 1600-1700 | S19: =SUM(C46:C49) -> 226 | T19: =SUM(D46:D49) -> 145 | U19: =SUM(E46:E49) -> 25 | V19: =SUM(F46:F49) -> 60 | W19: =SUM(G46:G49) -> 1 | X19: =SUM(H46:H49) -> 0 | Y19: =SUM(I46:I49) -> 31 | Z19: =SUM(J46:J49) -> 11 | ... AF19: =SUM(P46:P49) -> 907
B20: 09.30 - 09.45 | C20: 43 | D20: 7 | E20: 8 | F20: 19 | G20: 0 | H20: 0 | I20: 5 | J20: 2 | K20: 0 | L20: 0 | M20: 100 | N20: 0 | O20: =SUM(C20:L20,N20) -> 84 | P20: =SUM(C20:N20) -> 184 | R20: 1700-1800 | S20: =SUM(C50:C53) -> 365 | T20: =SUM(D50:D53) -> 201 | U20: =SUM(E50:E53) -> 40 | V20: =SUM(F50:F53) -> 79 | W20: =SUM(G50:G53) -> 1 | X20: =SUM(H50:H53) -> 0 | Y20: =SUM(I50:I53) -> 17 | Z20: =SUM(J50:J53) -> 3 | ... AF20: =SUM(P50:P53) -> 1199
B21: 09.45 - 10.00 | C21: 37 | D21: 8 | E21: 8 | F21: 20 | G21: 0 | H21: 0 | I21: 6 | J21: 1 | K21: 1 | L21: 0 | M21: 180 | N21: 0 | O21: =SUM(C21:L21,N21) -> 81 | P21: =SUM(C21:N21) -> 261 | R21: 1800-1900 | S21: =SUM(C54:C57) -> 295 | T21: =SUM(D54:D57) -> 270 | U21: =SUM(E54:E57) -> 42 | V21: =SUM(F54:F57) -> 88 | W21: =SUM(G54:G57) -> 0 | X21: =SUM(H54:H57) -> 0 | Y21: =SUM(I54:I57) -> 14 | Z21: =SUM(J54:J57) -> 5 | ... AF21: =SUM(P54:P57) -> 1228
B22: 10.00 - 10.15 | C22: 40 | D22: 9 | E22: 6 | F22: 20 | G22: 0 | H22: 0 | I22: 6 | J22: 2 | K22: 4 | L22: 0 | M22: 154 | N22: 0 | O22: =SUM(C22:L22,N22) -> 87 | P22: =SUM(C22:N22) -> 241 | R22: AM Peak Hr | S22: =MAX(S10:S12) -> 187 | T22: =MAX(T10:T12) -> 38 | U22: =MAX(U10:U12) -> 28 | V22: =MAX(V10:V12) -> 128 | W22: =MAX(W10:W12) -> 2 | X22: =MAX(X10:X12) -> 1 | Y22: =MAX(Y10:Y12) -> 21 | Z22: =MAX(Z10:Z12) -> 11 | ... AF22: =MAX(AF10:AF12) -> 1123
B23: 10.15 - 10.30 | C23: 42 | D23: 7 | E23: 6 | F23: 17 | G23: 0 | H23: 0 | I23: 7 | J23: 1 | K23: 2 | L23: 0 | M23: 159 | N23: 0 | O23: =SUM(C23:L23,N23) -> 82 | P23: =SUM(C23:N23) -> 241 | R23: IP Peak Hr | S23: =MAX(S13:S18) -> 168 | T23: =MAX(T13:T18) -> 148 | U23: =MAX(U13:U18) -> 33 | V23: =MAX(V13:V18) -> 90 | W23: =MAX(W13:W18) -> 1 | X23: =MAX(X13:X18) -> 3 | Y23: =MAX(Y13:Y18) -> 31 | Z23: =MAX(Z13:Z18) -> 12 | ... AF23: =MAX(AF13:AF18) -> 930
B24: 10.30 - 10.45 | C24: 45 | D24: 6 | E24: 3 | F24: 19 | G24: 0 | H24: 0 | I24: 5 | J24: 1 | K24: 7 | L24: 0 | M24: 165 | N24: 0 | O24: =SUM(C24:L24,N24) -> 86 | P24: =SUM(C24:N24) -> 251 | R24: PM Peak Hr | S24: =MAX(S19:S21) -> 365 | T24: =MAX(T19:T21) -> 270 | U24: =MAX(U19:U21) -> 42 | V24: =MAX(V19:V21) -> 88 | W24: =MAX(W19:W21) -> 1 | X24: =MAX(X19:X21) -> 0 | Y24: =MAX(Y19:Y21) -> 31 | Z24: =MAX(Z19:Z21) -> 11 | ... AF24: =MAX(AF19:AF21) -> 1228
B25: 10.45 - 11.00 | C25: 41 | D25: 3 | E25: 6 | F25: 16 | G25: 0 | H25: 0 | I25: 5 | J25: 2 | K25: 4 | L25: 0 | M25: 120 | N25: 0 | O25: =SUM(C25:L25,N25) -> 77 | P25: =SUM(C25:N25) -> 197 | R25: AM Period | S25: =SUM(S10:S12) -> 494 | T25: =SUM(T10:T12) -> 91 | U25: =SUM(U10:U12) -> 72 | V25: =SUM(V10:V12) -> 270 | W25: =SUM(W10:W12) -> 4 | X25: =SUM(X10:X12) -> 1 | Y25: =SUM(Y10:Y12) -> 35 | Z25: =SUM(Z10:Z12) -> 22 | ... AF25: =SUM(AF10:AF12) -> 2981
B26: 11.00 - 11.15 | C26: 30 | D26: 13 | E26: 3 | F26: 19 | G26: 0 | H26: 0 | I26: 4 | J26: 1 | K26: 3 | L26: 0 | M26: 121 | N26: 0 | O26: =SUM(C26:L26,N26) -> 73 | P26: =SUM(C26:N26) -> 194 | R26: IP Period | S26: =SUM(S13:S18) -> 847 | T26: =SUM(T13:T18) -> 529 | U26: =SUM(U13:U18) -> 142 | V26: =SUM(V13:V18) -> 413 | W26: =SUM(W13:W18) -> 1 | X26: =SUM(X13:X18) -> 3 | Y26: =SUM(Y13:Y18) -> 150 | Z26: =SUM(Z13:Z18) -> 52 | ... AF26: =SUM(AF13:AF18) -> 4863
B27: 11.15 - 11.30 | C27: 40 | D27: 5 | E27: 2 | F27: 13 | G27: 1 | H27: 0 | I27: 4 | J27: 3 | K27: 6 | L27: 0 | M27: 115 | N27: 0 | O27: =SUM(C27:L27,N27) -> 74 | P27: =SUM(C27:N27) -> 189 | R27: PM Period | S27: =SUM(S19:S21) -> 886 | T27: =SUM(T19:T21) -> 616 | U27: =SUM(U19:U21) -> 107 | V27: =SUM(V19:V21) -> 227 | W27: =SUM(W19:W21) -> 2 | X27: =SUM(X19:X21) -> 0 | Y27: =SUM(Y19:Y21) -> 62 | Z27: =SUM(Z19:Z21) -> 19 | ... AF27: =SUM(AF19:AF21) -> 3334
