Workbook

Sheet 17.10 MASAKA-MBARARA
B1: Consultancy services for Preparation of Expressway Development Master Plan (EDMP) for Uganda
B2: MANUAL CLASSIFIED COUNT (MCC)
B3: ROAD NAME: | C3: MASAKA-MBARARA ROAD
C5: Date | D5: 17.10.19 | F5: Location | G5: KINONI | J5: Surveyor | K5: KETRA
C6: Dir. From | D6: MASAKA | F6: Dir. To | G6: MBARARA | J6: Supervisor | K6: BABIRYE
B8: Time / Veh Type | R8: SUMMARY TRAFFIC VOLUMES
C9: 1. Car | D9: 2. Station Wagon | E9: 3. Pickups | F9: 4. Minibus, matatu | G9: 5. Medium bus | H9: 6. Large Bus | I9: 7. Light Truck | J9: 8. Medium Truck | K9: 9. Heavy truck | L9: 10. Truck Trailer | M9: 11. Motor cycles | N9: 12. Tractors | O9: Total Excl M/Cycles | P9: Total All | R9: Time | S9: 1. Car | T9: 2. Station Wagon | U9: 3. Pickups | V9: 4. Minibus, matatu | W9: 5. Medium bus | X9: 6. Large Bus | Y9: 7. Light Truck | Z9: 8. Medium Truck | AA9: 9. Heavy truck | AB9: 10. Truck Trailer | AC9: 11. Motorcycles | AD9: 12. Tractors, Graders | AE9: Total Excl M/ Cycles | AF9: Total All
B10: 07.00 - 07.15 | C10: 4 | D10: 0 | E10: 0 | F10: 3 | G10: 0 | H10: 1 | I10: 0 | J10: 0 | K10: 3 | L10: 0 | M10: 3 | N10: 0 | O10: =SUM(C10:L10,N10) -> 11 | P10: =SUM(C10:N10) -> 14 | R10: 0700-0800 | S10: =SUM(C10:C13) -> 22 | T10: =SUM(D10:D13) -> 6 | U10: =SUM(E10:E13) -> 3 | V10: =SUM(F10:F13) -> 11 | W10: =SUM(G10:G13) -> 0 | X10: =SUM(H10:H13) -> 1 | Y10: =SUM(I10:I13) -> 9 | Z10: =SUM(J10:J13) -> 1 | ... AF10: =SUM(P10:P13) -> 77
B11: 07.15 - 07.30 | C11: 8 | D11: 0 | E11: 1 | F11: 4 | G11: 0 | H11: 0 | I11: 4 | J11: 0 | K11: 1 | L11: 0 | M11: 5 | N11: 0 | O11: =SUM(C11:L11,N11) -> 18 | P11: =SUM(C11:N11) -> 23 | R11: 0800-0900 | S11: =SUM(C14:C17) -> 25 | T11: =SUM(D14:D17) -> 5 | U11: =SUM(E14:E17) -> 5 | V11: =SUM(F14:F17) -> 10 | W11: =SUM(G14:G17) -> 0 | X11: =SUM(H14:H17) -> 1 | Y11: =SUM(I14:I17) -> 4 | Z11: =SUM(J14:J17) -> 4 | ... AF11: =SUM(P14:P17) -> 84
B12: 07.30 - 07.45 | C12: 6 | D12: 3 | E12: 2 | F12: 1 | G12: 0 | H12: 0 | I12: 1 | J12: 1 | K12: 1 | L12: 0 | M12: 4 | N12: 0 | O12: =SUM(C12:L12,N12) -> 15 | P12: =SUM(C12:N12) -> 19 | R12: 0900-1000 | S12: =SUM(C18:C21) -> 24 | T12: =SUM(D18:D21) -> 10 | U12: =SUM(E18:E21) -> 12 | V12: =SUM(F18:F21) -> 11 | W12: =SUM(G18:G21) -> 0 | X12: =SUM(H18:H21) -> 4 | Y12: =SUM(I18:I21) -> 10 | Z12: =SUM(J18:J21) -> 8 | ... AF12: =SUM(P18:P21) -> 111
B13: 07.45 - 08.00 | C13: 4 | D13: 3 | E13: 0 | F13: 3 | G13: 0 | H13: 0 | I13: 4 | J13: 0 | K13: 1 | L13: 0 | M13: 6 | N13: 0 | O13: =SUM(C13:L13,N13) -> 15 | P13: =SUM(C13:N13) -> 21 | R13: 1000-1100 | S13: =SUM(C22:C25) -> 37 | T13: =SUM(D22:D25) -> 15 | U13: =SUM(E22:E25) -> 12 | V13: =SUM(F22:F25) -> 21 | W13: =SUM(G22:G25) -> 0 | X13: =SUM(H22:H25) -> 6 | Y13: =SUM(I22:I25) -> 4 | Z13: =SUM(J22:J25) -> 6 | ... AF13: =SUM(P22:P25) -> 143
B14: 08.00 - 08.15 | C14: 6 | D14: 1 | E14: 0 | F14: 2 | G14: 0 | H14: 0 | I14: 2 | J14: 1 | K14: 4 | L14: 0 | M14: 9 | N14: 0 | O14: =SUM(C14:L14,N14) -> 16 | P14: =SUM(C14:N14) -> 25 | R14: 1100-1200 | S14: =SUM(C26:C29) -> 25 | T14: =SUM(D26:D29) -> 8 | U14: =SUM(E26:E29) -> 8 | V14: =SUM(F26:F29) -> 19 | W14: =SUM(G26:G29) -> 3 | X14: =SUM(H26:H29) -> 5 | Y14: =SUM(I26:I29) -> 6 | Z14: =SUM(J26:J29) -> 4 | ... AF14: =SUM(P26:P29) -> 103
B15: 08.15 - 08.30 | C15: 6 | D15: 2 | E15: 1 | F15: 1 | G15: 0 | H15: 0 | I15: 1 | J15: 0 | K15: 2 | L15: 0 | M15: 2 | N15: 0 | O15: =SUM(C15:L15,N15) -> 13 | P15: =SUM(C15:N15) -> 15 | R15: 1200-1300 | S15: =SUM(C30:C33) -> 28 | T15: =SUM(D30:D33) -> 14 | U15: =SUM(E30:E33) -> 5 | V15: =SUM(F30:F33) -> 19 | W15: =SUM(G30:G33) -> 1 | X15: =SUM(H30:H33) -> 6 | Y15: =SUM(I30:I33) -> 12 | Z15: =SUM(J30:J33) -> 3 | ... AF15: =SUM(P30:P33) -> 133
B16: 08.30 - 08.45 | C16: 5 | D16: 1 | E16: 1 | F16: 4 | G16: 0 | H16: 1 | I16: 0 | J16: 3 | K16: 1 | L16: 0 | M16: 4 | N16: 0 | O16: =SUM(C16:L16,N16) -> 16 | P16: =SUM(C16:N16) -> 20 | R16: 1300-1400 | S16: =SUM(C34:C37) -> 21 | T16: =SUM(D34:D37) -> 11 | U16: =SUM(E34:E37) -> 7 | V16: =SUM(F34:F37) -> 21 | W16: =SUM(G34:G37) -> 0 | X16: =SUM(H34:H37) -> 3 | Y16: =SUM(I34:I37) -> 6 | Z16: =SUM(J34:J37) -> 4 | ... AF16: =SUM(P34:P37) -> 105
B17: 08.45 - 9.00 | C17: 8 | D17: 1 | E17: 3 | F17: 3 | G17: 0 | H17: 0 | I17: 1 | J17: 0 | K17: 2 | L17: 0 | M17: 6 | N17: 0 | O17: =SUM(C17:L17,N17) -> 18 | P17: =SUM(C17:N17) -> 24 | R17: 1400-1500 | S17: =SUM(C38:C41) -> 24 | T17: =SUM(D38:D41) -> 13 | U17: =SUM(E38:E41) -> 1 | V17: =SUM(F38:F41) -> 10 | W17: =SUM(G38:G41) -> 0 | X17: =SUM(H38:H41) -> 7 | Y17: =SUM(I38:I41) -> 5 | Z17: =SUM(J38:J41) -> 4 | ... AF17: =SUM(P38:P41) -> 91
B18: 09.00 - 09.15 | C18: 9 | D18: 2 | E18: 2 | F18: 2 | G18: 0 | H18: 1 | I18: 4 | J18: 1 | K18: 1 | L18: 0 | M18: 2 | N18: 0 | O18: =SUM(C18:L18,N18) -> 22 | P18: =SUM(C18:N18) -> 24 | R18: 1500-1600 | S18: =SUM(C42:C45) -> 30 | T18: =SUM(D42:D45) -> 11 | U18: =SUM(E42:E45) -> 6 | V18: =SUM(F42:F45) -> 18 | W18: =SUM(G42:G45) -> 0 | X18: =SUM(H42:H45) -> 8 | Y18: =SUM(I42:I45) -> 13 | Z18: =SUM(J42:J45) -> 1 | ... AF18: =SUM(P42:P45) -> 122
B19: 09.15 - 09.30 | C19: 4 | D19: 2 | E19: 4 | F19: 5 | G19: 0 | H19: 0 | I19: 0 | J19: 1 | K19: 4 | L19: 0 | M19: 6 | N19: 0 | O19: =SUM(C19:L19,N19) -> 20 | P19: =SUM(C19:N19) -> 26 | R19: 1600-1700 | S19: =SUM(C46:C49) -> 27 | T19: =SUM(D46:D49) -> 14 | U19: =SUM(E46:E49) -> 10 | V19: =SUM(F46:F49) -> 17 | W19: =SUM(G46:G49) -> 1 | X19: =SUM(H46:H49) -> 9 | Y19: =SUM(I46:I49) -> 7 | Z19: =SUM(J46:J49) -> 5 | ... AF19: =SUM(P46:P49) -> 125
B20: 09.30 - 09.45 | C20: 7 | D20: 2 | E20: 3 | F20: 2 | G20: 0 | H20: 2 | I20: 6 | J20: 3 | K20: 4 | L20: 0 | M20: 5 | N20: 0 | O20: =SUM(C20:L20,N20) -> 29 | P20: =SUM(C20:N20) -> 34 | R20: 1700-1800 | S20: =SUM(C50:C53) -> 34 | T20: =SUM(D50:D53) -> 12 | U20: =SUM(E50:E53) -> 10 | V20: =SUM(F50:F53) -> 16 | W20: =SUM(G50:G53) -> 0 | X20: =SUM(H50:H53) -> 5 | Y20: =SUM(I50:I53) -> 14 | Z20: =SUM(J50:J53) -> 0 | ... AF20: =SUM(P50:P53) -> 136
B21: 09.45 - 10.00 | C21: 4 | D21: 4 | E21: 3 | F21: 2 | G21: 0 | H21: 1 | I21: 0 | J21: 3 | K21: 3 | L21: 0 | M21: 7 | N21: 0 | O21: =SUM(C21:L21,N21) -> 20 | P21: =SUM(C21:N21) -> 27 | R21: 1800-1900 | S21: =SUM(C54:C57) -> 23 | T21: =SUM(D54:D57) -> 7 | U21: =SUM(E54:E57) -> 13 | V21: =SUM(F54:F57) -> 18 | W21: =SUM(G54:G57) -> 1 | X21: =SUM(H54:H57) -> 5 | Y21: =SUM(I54:I57) -> 12 | Z21: =SUM(J54:J57) -> 5 | ... AF21: =SUM(P54:P57) -> 129
B22: 10.00 - 10.15 | C22: 9 | D22: 3 | E22: 7 | F22: 8 | G22: 0 | H22: 1 | I22: 2 | J22: 1 | K22: 2 | L22: 1 | M22: 9 | N22: 0 | O22: =SUM(C22:L22,N22) -> 34 | P22: =SUM(C22:N22) -> 43 | R22: AM Peak Hr | S22: =MAX(S10:S12) -> 25 | T22: =MAX(T10:T12) -> 10 | U22: =MAX(U10:U12) -> 12 | V22: =MAX(V10:V12) -> 11 | W22: =MAX(W10:W12) -> 0 | X22: =MAX(X10:X12) -> 4 | Y22: =MAX(Y10:Y12) -> 10 | Z22: =MAX(Z10:Z12) -> 8 | ... AF22: =MAX(AF10:AF12) -> 111
B23: 10.15 - 10.30 | C23: 11 | D23: 4 | E23: 1 | F23: 2 | G23: 0 | H23: 1 | I23: 0 | J23: 1 | K23: 3 | L23: 0 | M23: 8 | N23: 0 | O23: =SUM(C23:L23,N23) -> 23 | P23: =SUM(C23:N23) -> 31 | R23: IP Peak Hr | S23: =MAX(S13:S18) -> 37 | T23: =MAX(T13:T18) -> 15 | U23: =MAX(U13:U18) -> 12 | V23: =MAX(V13:V18) -> 21 | W23: =MAX(W13:W18) -> 3 | X23: =MAX(X13:X18) -> 8 | Y23: =MAX(Y13:Y18) -> 13 | Z23: =MAX(Z13:Z18) -> 6 | ... AF23: =MAX(AF13:AF18) -> 143
B24: 10.30 - 10.45 | C24: 8 | D24: 2 | E24: 2 | F24: 5 | G24: 0 | H24: 3 | I24: 2 | J24: 2 | K24: 6 | L24: 0 | M24: 1 | N24: 0 | O24: =SUM(C24:L24,N24) -> 30 | P24: =SUM(C24:N24) -> 31 | R24: PM Peak Hr | S24: =MAX(S19:S21) -> 34 | T24: =MAX(T19:T21) -> 14 | U24: =MAX(U19:U21) -> 13 | V24: =MAX(V19:V21) -> 18 | W24: =MAX(W19:W21) -> 1 | X24: =MAX(X19:X21) -> 9 | Y24: =MAX(Y19:Y21) -> 14 | Z24: =MAX(Z19:Z21) -> 5 | ... AF24: =MAX(AF19:AF21) -> 136
B25: 10.45 - 11.00 | C25: 9 | D25: 6 | E25: 2 | F25: 6 | G25: 0 | H25: 1 | I25: 0 | J25: 2 | K25: 3 | L25: 1 | M25: 8 | N25: 0 | O25: =SUM(C25:L25,N25) -> 30 | P25: =SUM(C25:N25) -> 38 | R25: AM Period | S25: =SUM(S10:S12) -> 71 | T25: =SUM(T10:T12) -> 21 | U25: =SUM(U10:U12) -> 20 | V25: =SUM(V10:V12) -> 32 | W25: =SUM(W10:W12) -> 0 | X25: =SUM(X10:X12) -> 6 | Y25: =SUM(Y10:Y12) -> 23 | Z25: =SUM(Z10:Z12) -> 13 | ... AF25: =SUM(AF10:AF12) -> 272
B26: 11.00 - 11.15 | C26: 8 | D26: 4 | E26: 3 | F26: 4 | G26: 2 | H26: 1 | I26: 0 | J26: 1 | K26: 1 | L26: 0 | M26: 4 | N26: 0 | O26: =SUM(C26:L26,N26) -> 24 | P26: =SUM(C26:N26) -> 28 | R26: IP Period | S26: =SUM(S13:S18) -> 165 | T26: =SUM(T13:T18) -> 72 | U26: =SUM(U13:U18) -> 39 | V26: =SUM(V13:V18) -> 108 | W26: =SUM(W13:W18) -> 4 | X26: =SUM(X13:X18) -> 35 | Y26: =SUM(Y13:Y18) -> 46 | Z26: =SUM(Z13:Z18) -> 22 | ... AF26: =SUM(AF13:AF18) -> 697
B27: 11.15 - 11.30 | C27: 3 | D27: 1 | E27: 0 | F27: 2 | G27: 0 | H27: 0 | I27: 1 | J27: 1 | K27: 1 | L27: 0 | M27: 3 | N27: 0 | O27: =SUM(C27:L27,N27) -> 9 | P27: =SUM(C27:N27) -> 12 | R27: PM Period | S27: =SUM(S19:S21) -> 84 | T27: =SUM(T19:T21) -> 33 | U27: =SUM(U19:U21) -> 33 | V27: =SUM(V19:V21) -> 51 | W27: =SUM(W19:W21) -> 2 | X27: =SUM(X19:X21) -> 19 | Y27: =SUM(Y19:Y21) -> 33 | Z27: =SUM(Z19:Z21) -> 10 | ... AF27: =SUM(AF19:AF21) -> 390
B28: 11.30 - 11.45 | C28: 7 | D28: 1 | E28: 2 | F28: 7 | G28: 1 | H28: 2 | I28: 4 | J28: 1 | K28: 2 | L28: 0 | M28: 4 | N28: 0 | O28: =SUM(C28:L28,N28) -> 27 | P28: =SUM(C28:N28) -> 31 | R28: 12 Hours | S28: =SUM(S10:S21) -> 320 | T28: =SUM(T10:T21) -> 126 | U28: =SUM(U10:U21) -> 92 | V28: =SUM(V10:V21) -> 191 | W28: =SUM(W10:W21) -> 6 | X28: =SUM(X10:X21) -> 60 | Y28: =SUM(Y10:Y21) -> 102 | Z28: =SUM(Z10:Z21) -> 45 | ... AF28: =SUM(AF10:AF21) -> 1359
B29: 11.45 - 12.00 | C29: 7 | D29: 2 | E29: 3 | F29: 6 | G29: 0 | H29: 2 | I29: 1 | J29: 1 | K29: 0 | L29: 0 | M29: 10 | N29: 0 | O29: =SUM(C29:L29,N29) -> 22 | P29: =SUM(C29:N29) -> 32
B30: 12.00 - 12.15 | C30: 11 | D30: 4 | E30: 2 | F30: 2 | G30: 0 | H30: 2 | I30: 2 | J30: 0 | K30: 3 | L30: 0 | M30: 10 | N30: 0 | O30: =SUM(C30:L30,N30) -> 26 | P30: =SUM(C30:N30) -> 36
B31: 12.15 - 12.30 | C31: 8 | D31: 3 | E31: 1 | F31: 5 | G31: 1 | H31: 2 | I31: 3 | J31: 0 | K31: 3 | L31: 1 | M31: 7 | N31: 0 | O31: =SUM(C31:L31,N31) -> 27 | P31: =SUM(C31:N31) -> 34
B32: 12.30 - 12.45 | C32: 6 | D32: 4 | E32: 2 | F32: 4 | G32: 0 | H32: 2 | I32: 5 | J32: 2 | K32: 0 | L32: 0 | M32: 10 | N32: 0 | O32: =SUM(C32:L32,N32) -> 25 | P32: =SUM(C32:N32) -> 35
B33: 12.45 - 13.00 | C33: 3 | D33: 3 | E33: 0 | F33: 8 | G33: 0 | H33: 0 | I33: 2 | J33: 1 | K33: 2 | L33: 0 | M33: 9 | N33: 0 | O33: =SUM(C33:L33,N33) -> 19 | P33: =SUM(C33:N33) -> 28
B34: 13.00 - 13.15 | C34: 4 | D34: 2 | E34: 2 | F34: 2 | G34: 0 | H34: 0 | I34: 2 | J34: 1 | K34: 2 | L34: 0 | M34: 4 | N34: 0 | O34: =SUM(C34:L34,N34) -> 15 | P34: =SUM(C34:N34) -> 19
B35: 13.15 - 13.30 | C35: 4 | D35: 1 | E35: 2 | F35: 7 | G35: 0 | H35: 1 | I35: 1 | J35: 1 | K35: 3 | L35: 0 | M35: 3 | N35: 0 | O35: =SUM(C35:L35,N35) -> 20 | P35: =SUM(C35:N35) -> 23
B36: 13.30 - 13.45 | C36: 7 | D36: 6 | E36: 2 | F36: 8 | G36: 0 | H36: 0 | I36: 1 | J36: 1 | K36: 1 | L36: 2 | M36: 7 | N36: 0 | O36: =SUM(C36:L36,N36) -> 28 | P36: =SUM(C36:N36) -> 35
B37: 13.45 - 14.00 | C37: 6 | D37: 2 | E37: 1 | F37: 4 | G37: 0 | H37: 2 | I37: 2 | J37: 1 | K37: 2 | L37: 0 | M37: 8 | N37: 0 | O37: =SUM(C37:L37,N37) -> 20 | P37: =SUM(C37:N37) -> 28
B38: 14.00 - 14.15 | C38: 6 | D38: 1 | E38: 0 | F38: 1 | G38: 0 | H38: 1 | I38: 2 | J38: 1 | K38: 3 | L38: 0 | M38: 5 | N38: 0 | O38: =SUM(C38:L38,N38) -> 15 | P38: =SUM(C38:N38) -> 20
B39: 14.15 - 14.30 | C39: 6 | D39: 3 | E39: 0 | F39: 4 | G39: 0 | H39: 2 | I39: 2 | J39: 0 | K39: 4 | L39: 0 | M39: 4 | N39: 0 | O39: =SUM(C39:L39,N39) -> 21 | P39: =SUM(C39:N39) -> 25
B40: 14.30 - 14.45 | C40: 9 | D40: 3 | E40: 1 | F40: 3 | G40: 0 | H40: 3 | I40: 1 | J40: 1 | K40: 2 | L40: 0 | M40: 1 | N40: 0 | O40: =SUM(C40:L40,N40) -> 23 | P40: =SUM(C40:N40) -> 24
... B57: 18.45 - 19.00 | C57: 5 | D57: 2 | E57: 2 | F57: 3 | G57: 0 | H57: 1 | I57: 4 | J57: 1 | K57: 0 | L57: 0 | M57: 6 | N57: 0 | O57: =SUM(C57:L57,N57) -> 18 | P57: =SUM(C57:N57) -> 24
B58: Totals | C58: =SUM(C10:C57) -> 320 | D58: =SUM(D10:D57) -> 126 | E58: =SUM(E10:E57) -> 92 | F58: =SUM(F10:F57) -> 191 | G58: =SUM(G10:G57) -> 6 | H58: =SUM(H10:H57) -> 60 | I58: =SUM(I10:I57) -> 102 | J58: =SUM(J10:J57) -> 45 | ... P58: =SUM(P10:P57) -> 1359
...

Sheet 17.10 MBARARA-MASAKA
B1: Consultancy services for Preparation of Expressway Development Master Plan (EDMP) for Uganda
B2: MANUAL CLASSIFIED COUNT (MCC)
B3: ROAD NAME: | C3: ='23.10 MASAKA-MBARARA'!C3:G3 -> MASAKA-MBARARA
C5: Date | D5: ='17.10 MASAKA-MBARARA'!D5 -> 17.10.19 | F5: Location | G5: ='17.10 MASAKA-MBARARA'!G5:H5 -> KINONI | J5: Surveyor | K5: SANDRA
C6: Dir. From | D6: MBARARA | F6: Dir. To | G6: MASAKA | J6: Supervisor | K6: SANDRA
B8: Time / Veh Type | R8: SUMMARY TRAFFIC VOLUMES
C9: 1. Car | D9: 2. Station Wagon | E9: 3. Pickups | F9: 4. Minibus, matatu | G9: 5. Medium bus | H9: 6. Large Bus | I9: 7. Light Truck | J9: 8. Medium Truck | K9: 9. Heavy truck | L9: 10. Truck Trailer | M9: 11. Motor cycles | N9: 12. Tractors | O9: Total Excl M/Cycles | P9: Total All | R9: Time | S9: 1. Car | T9: 2. Station Wagon | U9: 3. Pickups | V9: 4. Minibus, matatu | W9: 5. Medium bus | X9: 6. Large Bus | Y9: 7. Light Truck | Z9: 8. Medium Truck | AA9: 9. Heavy truck | AB9: 10. Truck Trailer | AC9: 11. Motorcycles | AD9: 12. Tractors, Graders | AE9: Total Excl M/ Cycles | AF9: Total All
B10: 07.00 - 07.15 | C10: 3 | D10: 1 | E10: 1 | F10: 3 | G10: 0 | H10: 1 | I10: 0 | J10: 0 | K10: 1 | L10: 0 | M10: 4 | N10: 0 | O10: =SUM(C10:L10,N10) -> 10 | P10: =SUM(C10:N10) -> 14 | R10: 0700-0800 | S10: =SUM(C10:C13) -> 19 | T10: =SUM(D10:D13) -> 5 | U10: =SUM(E10:E13) -> 1 | V10: =SUM(F10:F13) -> 13 | W10: =SUM(G10:G13) -> 0 | X10: =SUM(H10:H13) -> 2 | Y10: =SUM(I10:I13) -> 2 | Z10: =SUM(J10:J13) -> 2 | ... AF10: =SUM(P10:P13) -> 82
B11: 07.15 - 07.30 | C11: 5 | D11: 1 | E11: 0 | F11: 3 | G11: 0 | H11: 0 | I11: 1 | J11: 1 | K11: 1 | L11: 0 | M11: 13 | N11: 0 | O11: =SUM(C11:L11,N11) -> 12 | P11: =SUM(C11:N11) -> 25 | R11: 0800-0900 | S11: =SUM(C14:C17) -> 13 | T11: =SUM(D14:D17) -> 6 | U11: =SUM(E14:E17) -> 6 | V11: =SUM(F14:F17) -> 17 | W11: =SUM(G14:G17) -> 0 | X11: =SUM(H14:H17) -> 3 | Y11: =SUM(I14:I17) -> 1 | Z11: =SUM(J14:J17) -> 2 | ... AF11: =SUM(P14:P17) -> 82
B12: 07.30 - 07.45 | C12: 2 | D12: 0 | E12: 0 | F12: 4 | G12: 0 | H12: 1 | I12: 1 | J12: 0 | K12: 1 | L12: 0 | M12: 5 | N12: 0 | O12: =SUM(C12:L12,N12) -> 9 | P12: =SUM(C12:N12) -> 14 | R12: 0900-1000 | S12: =SUM(C18:C21) -> 20 | T12: =SUM(D18:D21) -> 7 | U12: =SUM(E18:E21) -> 6 | V12: =SUM(F18:F21) -> 16 | W12: =SUM(G18:G21) -> 0 | X12: =SUM(H18:H21) -> 1 | Y12: =SUM(I18:I21) -> 3 | Z12: =SUM(J18:J21) -> 4 | ... AF12: =SUM(P18:P21) -> 103
B13: 07.45 - 08.00 | C13: 9 | D13: 3 | E13: 0 | F13: 3 | G13: 0 | H13: 0 | I13: 0 | J13: 1 | K13: 0 | L13: 0 | M13: 13 | N13: 0 | O13: =SUM(C13:L13,N13) -> 16 | P13: =SUM(C13:N13) -> 29 | R13: 1000-1100 | S13: =SUM(C22:C25) -> 29 | T13: =SUM(D22:D25) -> 3 | U13: =SUM(E22:E25) -> 8 | V13: =SUM(F22:F25) -> 16 | W13: =SUM(G22:G25) -> 0 | X13: =SUM(H22:H25) -> 6 | Y13: =SUM(I22:I25) -> 2 | Z13: =SUM(J22:J25) -> 1 | ... AF13: =SUM(P22:P25) -> 108
B14: 08.00 - 08.15 | C14: 4 | D14: 2 | E14: 1 | F14: 5 | G14: 0 | H14: 1 | I14: 0 | J14: 0 | K14: 1 | L14: 0 | M14: 5 | N14: 0 | O14: =SUM(C14:L14,N14) -> 14 | P14: =SUM(C14:N14) -> 19 | R14: 1100-1200 | S14: =SUM(C26:C29) -> 18 | T14: =SUM(D26:D29) -> 13 | U14: =SUM(E26:E29) -> 14 | V14: =SUM(F26:F29) -> 21 | W14: =SUM(G26:G29) -> 0 | X14: =SUM(H26:H29) -> 5 | Y14: =SUM(I26:I29) -> 5 | Z14: =SUM(J26:J29) -> 2 | ... AF14: =SUM(P26:P29) -> 110
B15: 08.15 - 08.30 | C15: 1 | D15: 3 | E15: 2 | F15: 2 | G15: 0 | H15: 1 | I15: 0 | J15: 1 | K15: 1 | L15: 0 | M15: 9 | N15: 0 | O15: =SUM(C15:L15,N15) -> 11 | P15: =SUM(C15:N15) -> 20 | R15: 1200-1300 | S15: =SUM(C30:C33) -> 29 | T15: =SUM(D30:D33) -> 16 | U15: =SUM(E30:E33) -> 10 | V15: =SUM(F30:F33) -> 19 | W15: =SUM(G30:G33) -> 0 | X15: =SUM(H30:H33) -> 7 | Y15: =SUM(I30:I33) -> 7 | Z15: =SUM(J30:J33) -> 0 | ... AF15: =SUM(P30:P33) -> 123
B16: 08.30 - 08.45 | C16: 6 | D16: 0 | E16: 0 | F16: 4 | G16: 0 | H16: 0 | I16: 0 | J16: 1 | K16: 3 | L16: 1 | M16: 5 | N16: 0 | O16: =SUM(C16:L16,N16) -> 15 | P16: =SUM(C16:N16) -> 20 | R16: 1300-1400 | S16: =SUM(C34:C37) -> 29 | T16: =SUM(D34:D37) -> 18 | U16: =SUM(E34:E37) -> 9 | V16: =SUM(F34:F37) -> 13 | W16: =SUM(G34:G37) -> 3 | X16: =SUM(H34:H37) -> 9 | Y16: =SUM(I34:I37) -> 7 | Z16: =SUM(J34:J37) -> 3 | ... AF16: =SUM(P34:P37) -> 127
B17: 08.45 - 9.00 | C17: 2 | D17: 1 | E17: 3 | F17: 6 | G17: 0 | H17: 1 | I17: 1 | J17: 0 | K17: 1 | L17: 0 | M17: 8 | N17: 0 | O17: =SUM(C17:L17,N17) -> 15 | P17: =SUM(C17:N17) -> 23 | R17: 1400-1500 | S17: =SUM(C38:C41) -> 21 | T17: =SUM(D38:D41) -> 7 | U17: =SUM(E38:E41) -> 9 | V17: =SUM(F38:F41) -> 18 | W17: =SUM(G38:G41) -> 0 | X17: =SUM(H38:H41) -> 7 | Y17: =SUM(I38:I41) -> 5 | Z17: =SUM(J38:J41) -> 6 | ... AF17: =SUM(P38:P41) -> 126
B18: 09.00 - 09.15 | C18: 2 | D18: 2 | E18: 2 | F18: 6 | G18: 0 | H18: 0 | I18: 0 | J18: 0 | K18: 1 | L18: 0 | M18: 8 | N18: 0 | O18: =SUM(C18:L18,N18) -> 13 | P18: =SUM(C18:N18) -> 21 | R18: 1500-1600 | S18: =SUM(C42:C45) -> 36 | T18: =SUM(D42:D45) -> 16 | U18: =SUM(E42:E45) -> 11 | V18: =SUM(F42:F45) -> 20 | W18: =SUM(G42:G45) -> 0 | X18: =SUM(H42:H45) -> 6 | Y18: =SUM(I42:I45) -> 1 | Z18: =SUM(J42:J45) -> 6 | ... AF18: =SUM(P42:P45) -> 155
B19: 09.15 - 09.30 | C19: 6 | D19: 3 | E19: 1 | F19: 3 | G19: 0 | H19: 0 | I19: 3 | J19: 1 | K19: 1 | L19: 0 | M19: 4 | N19: 0 | O19: =SUM(C19:L19,N19) -> 18 | P19: =SUM(C19:N19) -> 22 | R19: 1600-1700 | S19: =SUM(C46:C49) -> 42 | T19: =SUM(D46:D49) -> 10 | U19: =SUM(E46:E49) -> 13 | V19: =SUM(F46:F49) -> 17 | W19: =SUM(G46:G49) -> 0 | X19: =SUM(H46:H49) -> 4 | Y19: =SUM(I46:I49) -> 1 | Z19: =SUM(J46:J49) -> 0 | ... AF19: =SUM(P46:P49) -> 145
B20: 09.30 - 09.45 | C20: 6 | D20: 2 | E20: 2 | F20: 4 | G20: 0 | H20: 1 | I20: 0 | J20: 3 | K20: 3 | L20: 0 | M20: 17 | N20: 0 | O20: =SUM(C20:L20,N20) -> 21 | P20: =SUM(C20:N20) -> 38 | R20: 1700-1800 | S20: =SUM(C50:C53) -> 33 | T20: =SUM(D50:D53) -> 14 | U20: =SUM(E50:E53) -> 12 | V20: =SUM(F50:F53) -> 21 | W20: =SUM(G50:G53) -> 0 | X20: =SUM(H50:H53) -> 5 | Y20: =SUM(I50:I53) -> 7 | Z20: =SUM(J50:J53) -> 7 | ... AF20: =SUM(P50:P53) -> 183
B21: 09.45 - 10.00 | C21: 6 | D21: 0 | E21: 1 | F21: 3 | G21: 0 | H21: 0 | I21: 0 | J21: 0 | K21: 3 | L21: 0 | M21: 9 | N21: 0 | O21: =SUM(C21:L21,N21) -> 13 | P21: =SUM(C21:N21) -> 22 | R21: 1800-1900 | S21: =SUM(C54:C57) -> 46 | T21: =SUM(D54:D57) -> 9 | U21: =SUM(E54:E57) -> 11 | V21: =SUM(F54:F57) -> 27 | W21: =SUM(G54:G57) -> 0 | X21: =SUM(H54:H57) -> 6 | Y21: =SUM(I54:I57) -> 10 | Z21: =SUM(J54:J57) -> 12 | ... AF21: =SUM(P54:P57) -> 191
B22: 10.00 - 10.15 | C22: 3 | D22: 0 | E22: 3 | F22: 6 | G22: 0 | H22: 0 | I22: 0 | J22: 1 | K22: 2 | L22: 0 | M22: 9 | N22: 0 | O22: =SUM(C22:L22,N22) -> 15 | P22: =SUM(C22:N22) -> 24 | R22: AM Peak Hr | S22: =MAX(S10:S12) -> 20 | T22: =MAX(T10:T12) -> 7 | U22: =MAX(U10:U12) -> 6 | V22: =MAX(V10:V12) -> 17 | W22: =MAX(W10:W12) -> 0 | X22: =MAX(X10:X12) -> 3 | Y22: =MAX(Y10:Y12) -> 3 | Z22: =MAX(Z10:Z12) -> 4 | ... AF22: =MAX(AF10:AF12) -> 103
B23: 10.15 - 10.30 | C23: 7 | D23: 1 | E23: 1 | F23: 3 | G23: 0 | H23: 1 | I23: 1 | J23: 0 | K23: 0 | L23: 0 | M23: 13 | N23: 0 | O23: =SUM(C23:L23,N23) -> 14 | P23: =SUM(C23:N23) -> 27 | R23: IP Peak Hr | S23: =MAX(S13:S18) -> 36 | T23: =MAX(T13:T18) -> 18 | U23: =MAX(U13:U18) -> 14 | V23: =MAX(V13:V18) -> 21 | W23: =MAX(W13:W18) -> 3 | X23: =MAX(X13:X18) -> 9 | Y23: =MAX(Y13:Y18) -> 7 | Z23: =MAX(Z13:Z18) -> 6 | ... AF23: =MAX(AF13:AF18) -> 155
B24: 10.30 - 10.45 | C24: 5 | D24: 0 | E24: 2 | F24: 3 | G24: 0 | H24: 4 | I24: 0 | J24: 0 | K24: 1 | L24: 1 | M24: 10 | N24: 0 | O24: =SUM(C24:L24,N24) -> 16 | P24: =SUM(C24:N24) -> 26 | R24: PM Peak Hr | S24: =MAX(S19:S21) -> 46 | T24: =MAX(T19:T21) -> 14 | U24: =MAX(U19:U21) -> 13 | V24: =MAX(V19:V21) -> 27 | W24: =MAX(W19:W21) -> 0 | X24: =MAX(X19:X21) -> 6 | Y24: =MAX(Y19:Y21) -> 10 | Z24: =MAX(Z19:Z21) -> 12 | ... AF24: =MAX(AF19:AF21) -> 191
B25: 10.45 - 11.00 | C25: 14 | D25: 2 | E25: 2 | F25: 4 | G25: 0 | H25: 1 | I25: 1 | J25: 0 | K25: 1 | L25: 0 | M25: 6 | N25: 0 | O25: =SUM(C25:L25,N25) -> 25 | P25: =SUM(C25:N25) -> 31 | R25: AM Period | S25: =SUM(S10:S12) -> 52 | T25: =SUM(T10:T12) -> 18 | U25: =SUM(U10:U12) -> 13 | V25: =SUM(V10:V12) -> 46 | W25: =SUM(W10:W12) -> 0 | X25: =SUM(X10:X12) -> 6 | Y25: =SUM(Y10:Y12) -> 6 | Z25: =SUM(Z10:Z12) -> 8 | ... AF25: =SUM(AF10:AF12) -> 267
B26: 11.00 - 11.15 | C26: 1 | D26: 3 | E26: 2 | F26: 4 | G26: 0 | H26: 1 | I26: 2 | J26: 1 | K26: 2 | L26: 1 | M26: 5 | N26: 0 | O26: =SUM(C26:L26,N26) -> 17 | P26: =SUM(C26:N26) -> 22 | R26: IP Period | S26: =SUM(S13:S18) -> 162 | T26: =SUM(T13:T18) -> 73 | U26: =SUM(U13:U18) -> 61 | V26: =SUM(V13:V18) -> 107 | W26: =SUM(W13:W18) -> 3 | X26: =SUM(X13:X18) -> 40 | Y26: =SUM(Y13:Y18) -> 27 | Z26: =SUM(Z13:Z18) -> 18 | ... AF26: =SUM(AF13:AF18) -> 749
B27: 11.15 - 11.30 | C27: 7 | D27: 4 | E27: 1 | F27: 7 | G27: 0 | H27: 1 | I27: 0 | J27: 0 | K27: 2 | L27: 0 | M27: 5 | N27: 0 | O27: =SUM(C27:L27,N27) -> 22 | P27: =SUM(C27:N27) -> 27 | R27: PM Period | S27: =SUM(S19:S21) -> 121 | T27: =SUM(T19:T21) -> 33 | U27: =SUM(U19:U21) -> 36 | V27: =SUM(V19:V21) -> 65 | W27: =SUM(W19:W21) -> 0 | X27: =SUM(X19:X21) -> 15 | Y27: =SUM(Y19:Y21) -> 18 | Z27: =SUM(Z19:Z21) -> 19 | ... AF27: =SUM(AF19:AF21) -> 519
B28: 11.30 - 11.45 | C28: 7 | D28: 2 | E28: 5 | F28: 5 | G28: 0 | H28: 2 | I28: 2 | J28: 1 | K28: 1 | L28: 0 | M28: 6 | N28: 0 | O28: =SUM(C28:L28,N28) -> 25 | P28: =SUM(C28:N28) -> 31 | R28: 12 Hours | S28: =SUM(S10:S21) -> 335 | T28: =SUM(T10:T21) -> 124 | U28: =SUM(U10:U21) -> 110 | V28: =SUM(V10:V21) -> 218 | W28: =SUM(W10:W21) -> 3 | X28: =SUM(X10:X21) -> 61 | Y28: =SUM(Y10:Y21) -> 51 | Z28: =SUM(Z10:Z21) -> 45 | ... AF28: =SUM(AF10:AF21) -> 1535
B29: 11.45 - 12.00 | C29: 3 | D29: 4 | E29: 6 | F29: 5 | G29: 0 | H29: 1 | I29: 1 | J29: 0 | K29: 1 | L29: 0 | M29: 9 | N29: 0 | O29: =SUM(C29:L29,N29) -> 21 | P29: =SUM(C29:N29) -> 30
B30: 12.00 - 12.15 | C30: 8 | D30: 8 | E30: 0 | F30: 4 | G30: 0 | H30: 2 | I30: 0 | J30: 0 | K30: 1 | L30: 0 | M30: 7 | N30: 0 | O30: =SUM(C30:L30,N30) -> 23 | P30: =SUM(C30:N30) -> 30
B31: 12.15 - 12.30 | C31: 9 | D31: 3 | E31: 5 | F31: 6 | G31: 0 | H31: 2 | I31: 2 | J31: 0 | K31: 1 | L31: 0 | M31: 4 | N31: 0 | O31: =SUM(C31:L31,N31) -> 28 | P31: =SUM(C31:N31) -> 32
B32: 12.30 - 12.45 | C32: 7 | D32: 3 | E32: 4 | F32: 5 | G32: 0 | H32: 1 | I32: 3 | J32: 0 | K32: 3 | L32: 0 | M32: 7 | N32: 0 | O32: =SUM(C32:L32,N32) -> 26 | P32: =SUM(C32:N32) -> 33
B33: 12.45 - 13.00 | C33: 5 | D33: 2 | E33: 1 | F33: 4 | G33: 0 | H33: 2 | I33: 2 | J33: 0 | K33: 2 | L33: 0 | M33: 10 | N33: 0 | O33: =SUM(C33:L33,N33) -> 18 | P33: =SUM(C33:N33) -> 28
B34: 13.00 - 13.15 | C34: 6 | D34: 2 | E34: 3 | F34: 4 | G34: 0 | H34: 2 | I34: 2 | J34: 1 | K34: 0 | L34: 0 | M34: 7 | N34: 0 | O34: =SUM(C34:L34,N34) -> 20 | P34: =SUM(C34:N34) -> 27
B35: 13.15 - 13.30 | C35: 12 | D35: 6 | E35: 5 | F35: 5 | G35: 3 | H35: 3 | I35: 4 | J35: 0 | K35: 3 | L35: 0 | M35: 10 | N35: 0 | O35: =SUM(C35:L35,N35) -> 41 | P35: =SUM(C35:N35) -> 51
B36: 13.30 - 13.45 | C36: 3 | D36: 4 | E36: 0 | F36: 2 | G36: 0 | H36: 4 | I36: 1 | J36: 0 | K36: 0 | L36: 0 | M36: 3 | N36: 0 | O36: =SUM(C36:L36,N36) -> 14 | P36: =SUM(C36:N36) -> 17
B37: 13.45 - 14.00 | C37: 8 | D37: 6 | E37: 1 | F37: 2 | G37: 0 | H37: 0 | I37: 0 | J37: 2 | K37: 3 | L37: 0 | M37: 10 | N37: 0 | O37: =SUM(C37:L37,N37) -> 22 | P37: =SUM(C37:N37) -> 32
B38: 14.00 - 14.15 | C38: 6 | D38: 1 | E38: 4 | F38: 8 | G38: 0 | H38: 0 | I38: 1 | J38: 2 | K38: 3 | L38: 0 | M38: 3 | N38: 0 | O38: =SUM(C38:L38,N38) -> 25 | P38: =SUM(C38:N38) -> 28
B39: 14.15 - 14.30 | C39: 6 | D39: 1 | E39: 1 | F39: 4 | G39: 0 | H39: 3 | I39: 1 | J39: 1 | K39: 5 | L39: 1 | M39: 7 | N39: 0 | O39: =SUM(C39:L39,N39) -> 23 | P39: =SUM(C39:N39) -> 30
B40: 14.30 - 14.45 | C40: 5 | D40: 3 | E40: 3 | F40: 3 | G40: 0 | H40: 2 | I40: 1 | J40: 2 | K40: 11 | L40: 0 | M40: 7 | N40: 0 | O40: =SUM(C40:L40,N40) -> 30 | P40: =SUM(C40:N40) -> 37
... B57: 18.45 - 19.00 | C57: 14 | D57: 3 | E57: 0 | F57: 8 | G57: 0 | H57: 0 | I57: 0 | J57: 4 | K57: 1 | L57: 0 | M57: 13 | N57: 0 | O57: =SUM(C57:L57,N57) -> 30 | P57: =SUM(C57:N57) -> 43
B58: Totals | C58: =SUM(C10:C57) -> 335 | D58: =SUM(D10:D57) -> 124 | E58: =SUM(E10:E57) -> 110 | F58: =SUM(F10:F57) -> 218 | G58: =SUM(G10:G57) -> 3 | H58: =SUM(H10:H57) -> 61 | I58: =SUM(I10:I57) -> 51 | J58: =SUM(J10:J57) -> 45 | ... P58: =SUM(P10:P57) -> 1535
...

Sheet 18.10 MASAKA-MBARARA-24H
B1: Consultancy services for Preparation of Expressway Development Master Plan (EDMP) for Uganda
B2: MANUAL CLASSIFIED COUNT (MCC)
B3: ROAD NAME: | C3: MASAKA-MBARARA ROAD
C5: Date | D5: 18.10.19 | F5: Location | G5: ='19.10 MASAKA-MBARARA-24H'!G5:H5 -> KINONI | J5: Surveyor | K5: KETRA
C6: Dir. From | D6: MASAKA | F6: Dir. To | G6: MBARARA | J6: Supervisor | K6: ='19.10 MASAKA-MBARARA-24H'!K6:L6 -> SANDRA
B8: Time / Veh Type | R8: SUMMARY TRAFFIC VOLUMES
C9: 1. Car | D9: 2. Station Wagon | E9: 3. Pickups | F9: 4. Minibus, matatu | G9: 5. Medium bus | H9: 6. Large Bus | I9: 7. Light Truck | J9: 8. Medium Truck | K9: 9. Heavy truck | L9: 10. Truck Trailer | M9: 11. Motor cycles | N9: 12. Tractors | O9: Total Excl M/Cycles | P9: Total All | R9: Time | S9: 1. Car | T9: 2. Station Wagon | U9: 3. Pickups | V9: 4. Minibus, matatu | W9: 5. Medium bus | X9: 6. Large Bus | Y9: 7. Light Truck | Z9: 8. Medium Truck | AA9: 9. Heavy truck | AB9: 10. Truck Trailer | AC9: 11. Motorcycles | AD9: 12. Tractors, Graders | AE9: Total Excl M/ Cycles | AF9: Total All
B10: 07.00 - 07.15 | C10: 6 | D10: 2 | E10: 2 | F10: 5 | G10: 0 | H10: 1 | I10: 2 | J10: 1 | K10: 4 | L10: 0 | M10: 4 | N10: 0 | O10: =SUM(C10:L10,N10) -> 23 | P10: =SUM(C10:N10) -> 27 | R10: 0700-0800 | S10: =SUM(C10:C13) -> 31 | T10: =SUM(D10:D13) -> 14 | U10: =SUM(E10:E13) -> 12 | V10: =SUM(F10:F13) -> 12 | W10: =SUM(G10:G13) -> 0 | X10: =SUM(H10:H13) -> 1 | Y10: =SUM(I10:I13) -> 9 | Z10: =SUM(J10:J13) -> 2 | ... AF10: =SUM(P10:P13) -> 133
B11: 07.15 - 07.30 | C11: 4 | D11: 6 | E11: 0 | F11: 4 | G11: 0 | H11: 0 | I11: 2 | J11: 0 | K11: 4 | L11: 0 | M11: 8 | N11: 0 | O11: =SUM(C11:L11,N11) -> 20 | P11: =SUM(C11:N11) -> 28 | R11: 0800-0900 | S11: =SUM(C14:C17) -> 40 | T11: =SUM(D14:D17) -> 20 | U11: =SUM(E14:E17) -> 9 | V11: =SUM(F14:F17) -> 18 | W11: =SUM(G14:G17) -> 0 | X11: =SUM(H14:H17) -> 3 | Y11: =SUM(I14:I17) -> 2 | Z11: =SUM(J14:J17) -> 4 | ... AF11: =SUM(P14:P17) -> 140
B12: 07.30 - 07.45 | C12: 12 | D12: 2 | E12: 4 | F12: 2 | G12: 0 | H12: 0 | I12: 4 | J12: 1 | K12: 3 | L12: 0 | M12: 15 | N12: 0 | O12: =SUM(C12:L12,N12) -> 28 | P12: =SUM(C12:N12) -> 43 | R12: 0900-1000 | S12: =SUM(C18:C21) -> 38 | T12: =SUM(D18:D21) -> 13 | U12: =SUM(E18:E21) -> 4 | V12: =SUM(F18:F21) -> 19 | W12: =SUM(G18:G21) -> 5 | X12: =SUM(H18:H21) -> 2 | Y12: =SUM(I18:I21) -> 7 | Z12: =SUM(J18:J21) -> 4 | ... AF12: =SUM(P18:P21) -> 155
B13: 07.45 - 08.00 | C13: 9 | D13: 4 | E13: 6 | F13: 1 | G13: 0 | H13: 0 | I13: 1 | J13: 0 | K13: 1 | L13: 1 | M13: 12 | N13: 0 | O13: =SUM(C13:L13,N13) -> 23 | P13: =SUM(C13:N13) -> 35 | R13: 1000-1100 | S13: =SUM(C22:C25) -> 31 | T13: =SUM(D22:D25) -> 18 | U13: =SUM(E22:E25) -> 4 | V13: =SUM(F22:F25) -> 18 | W13: =SUM(G22:G25) -> 0 | X13: =SUM(H22:H25) -> 3 | Y13: =SUM(I22:I25) -> 1 | Z13: =SUM(J22:J25) -> 6 | ... AF13: =SUM(P22:P25) -> 144
B14: 08.00 - 08.15 | C14: 8 | D14: 3 | E14: 1 | F14: 4 | G14: 0 | H14: 1 | I14: 0 | J14: 0 | K14: 4 | L14: 0 | M14: 2 | N14: 0 | O14: =SUM(C14:L14,N14) -> 21 | P14: =SUM(C14:N14) -> 23 | R14: 1100-1200 | S14: =SUM(C26:C29) -> 39 | T14: =SUM(D26:D29) -> 13 | U14: =SUM(E26:E29) -> 2 | V14: =SUM(F26:F29) -> 12 | W14: =SUM(G26:G29) -> 3 | X14: =SUM(H26:H29) -> 3 | Y14: =SUM(I26:I29) -> 0 | Z14: =SUM(J26:J29) -> 7 | ... AF14: =SUM(P26:P29) -> 131
B15: 08.15 - 08.30 | C15: 10 | D15: 3 | E15: 3 | F15: 5 | G15: 0 | H15: 0 | I15: 2 | J15: 2 | K15: 2 | L15: 0 | M15: 13 | N15: 0 | O15: =SUM(C15:L15,N15) -> 27 | P15: =SUM(C15:N15) -> 40 | R15: 1200-1300 | S15: =SUM(C30:C33) -> 39 | T15: =SUM(D30:D33) -> 21 | U15: =SUM(E30:E33) -> 9 | V15: =SUM(F30:F33) -> 21 | W15: =SUM(G30:G33) -> 0 | X15: =SUM(H30:H33) -> 5 | Y15: =SUM(I30:I33) -> 2 | Z15: =SUM(J30:J33) -> 10 | ... AF15: =SUM(P30:P33) -> 161
B16: 08.30 - 08.45 | C16: 7 | D16: 5 | E16: 3 | F16: 6 | G16: 0 | H16: 1 | I16: 0 | J16: 2 | K16: 1 | L16: 1 | M16: 4 | N16: 0 | O16: =SUM(C16:L16,N16) -> 26 | P16: =SUM(C16:N16) -> 30 | R16: 1300-1400 | S16: =SUM(C34:C37) -> 21 | T16: =SUM(D34:D37) -> 9 | U16: =SUM(E34:E37) -> 2 | V16: =SUM(F34:F37) -> 17 | W16: =SUM(G34:G37) -> 2 | X16: =SUM(H34:H37) -> 6 | Y16: =SUM(I34:I37) -> 2 | Z16: =SUM(J34:J37) -> 4 | ... AF16: =SUM(P34:P37) -> 108
B17: 08.45 - 9.00 | C17: 15 | D17: 9 | E17: 2 | F17: 3 | G17: 0 | H17: 1 | I17: 0 | J17: 0 | K17: 1 | L17: 0 | M17: 16 | N17: 0 | O17: =SUM(C17:L17,N17) -> 31 | P17: =SUM(C17:N17) -> 47 | R17: 1400-1500 | S17: =SUM(C38:C41) -> 21 | T17: =SUM(D38:D41) -> 11 | U17: =SUM(E38:E41) -> 2 | V17: =SUM(F38:F41) -> 10 | W17: =SUM(G38:G41) -> 1 | X17: =SUM(H38:H41) -> 4 | Y17: =SUM(I38:I41) -> 2 | Z17: =SUM(J38:J41) -> 9 | ... AF17: =SUM(P38:P41) -> 98
B18: 09.00 - 09.15 | C18: 7 | D18: 1 | E18: 0 | F18: 1 | G18: 0 | H18: 1 | I18: 4 | J18: 2 | K18: 3 | L18: 0 | M18: 11 | N18: 0 | O18: =SUM(C18:L18,N18) -> 19 | P18: =SUM(C18:N18) -> 30 | R18: 1500-1600 | S18: =SUM(C42:C45) -> 45 | T18: =SUM(D42:D45) -> 21 | U18: =SUM(E42:E45) -> 4 | V18: =SUM(F42:F45) -> 21 | W18: =SUM(G42:G45) -> 0 | X18: =SUM(H42:H45) -> 8 | Y18: =SUM(I42:I45) -> 5 | Z18: =SUM(J42:J45) -> 20 | ... AF18: =SUM(P42:P45) -> 173
B19: 09.15 - 09.30 | C19: 6 | D19: 1 | E19: 2 | F19: 9 | G19: 2 | H19: 0 | I19: 0 | J19: 0 | K19: 3 | L19: 0 | M19: 13 | N19: 0 | O19: =SUM(C19:L19,N19) -> 23 | P19: =SUM(C19:N19) -> 36 | R19: 1600-1700 | S19: =SUM(C46:C49) -> 42 | T19: =SUM(D46:D49) -> 29 | U19: =SUM(E46:E49) -> 5 | V19: =SUM(F46:F49) -> 19 | W19: =SUM(G46:G49) -> 3 | X19: =SUM(H46:H49) -> 7 | Y19: =SUM(I46:I49) -> 7 | Z19: =SUM(J46:J49) -> 24 | ... AF19: =SUM(P46:P49) -> 185
B20: 09.30 - 09.45 | C20: 16 | D20: 4 | E20: 1 | F20: 8 | G20: 0 | H20: 1 | I20: 1 | J20: 1 | K20: 9 | L20: 0 | M20: 5 | N20: 0 | O20: =SUM(C20:L20,N20) -> 41 | P20: =SUM(C20:N20) -> 46 | R20: 1700-1800 | S20: =SUM(C50:C53) -> 58 | T20: =SUM(D50:D53) -> 16 | U20: =SUM(E50:E53) -> 9 | V20: =SUM(F50:F53) -> 20 | W20: =SUM(G50:G53) -> 2 | X20: =SUM(H50:H53) -> 8 | Y20: =SUM(I50:I53) -> 10 | Z20: =SUM(J50:J53) -> 22 | ... AF20: =SUM(P50:P53) -> 204
B21: 09.45 - 10.00 | C21: 9 | D21: 7 | E21: 1 | F21: 1 | G21: 3 | H21: 0 | I21: 2 | J21: 1 | K21: 0 | L21: 0 | M21: 19 | N21: 0 | O21: =SUM(C21:L21,N21) -> 24 | P21: =SUM(C21:N21) -> 43 | R21: 1800-1900 | S21: =SUM(C54:C57) -> 33 | T21: =SUM(D54:D57) -> 20 | U21: =SUM(E54:E57) -> 4 | V21: =SUM(F54:F57) -> 18 | W21: =SUM(G54:G57) -> 0 | X21: =SUM(H54:H57) -> 5 | Y21: =SUM(I54:I57) -> 3 | Z21: =SUM(J54:J57) -> 17 | ... AF21: =SUM(P54:P57) -> 146
B22: 10.00 - 10.15 | C22: 6 | D22: 6 | E22: 1 | F22: 4 | G22: 0 | H22: 2 | I22: 0 | J22: 2 | K22: 4 | L22: 0 | M22: 12 | N22: 0 | O22: =SUM(C22:L22,N22) -> 25 | P22: =SUM(C22:N22) -> 37 | R22: 1900-2000 | S22: =SUM(C58:C61) -> 34 | T22: =SUM(D58:D61) -> 13 | U22: =SUM(E58:E61) -> 4 | V22: =SUM(F58:F61) -> 15 | W22: =SUM(G58:G61) -> 1 | X22: =SUM(H58:H61) -> 4 | Y22: =SUM(I58:I61) -> 8 | Z22: =SUM(J58:J61) -> 8 | ... AF22: =SUM(P58:P61) -> 115
B23: 10.15 - 10.30 | C23: 7 | D23: 4 | E23: 0 | F23: 4 | G23: 0 | H23: 0 | I23: 1 | J23: 1 | K23: 1 | L23: 0 | M23: 16 | N23: 0 | O23: =SUM(C23:L23,N23) -> 18 | P23: =SUM(C23:N23) -> 34 | R23: 2000-2100 | S23: =SUM(C62:C65) -> 37 | T23: =SUM(D62:D65) -> 4 | U23: =SUM(E62:E65) -> 4 | V23: =SUM(F62:F65) -> 8 | W23: =SUM(G62:G65) -> 0 | X23: =SUM(H62:H65) -> 5 | Y23: =SUM(I62:I65) -> 19 | Z23: =SUM(J62:J65) -> 0 | ... AF23: =SUM(P62:P65) -> 102
B24: 10.30 - 10.45 | C24: 9 | D24: 2 | E24: 2 | F24: 6 | G24: 0 | H24: 0 | I24: 0 | J24: 1 | K24: 2 | L24: 1 | M24: 9 | N24: 0 | O24: =SUM(C24:L24,N24) -> 23 | P24: =SUM(C24:N24) -> 32 | R24: 2100-2200 | S24: =SUM(C66:C69) -> 30 | T24: =SUM(D66:D69) -> 2 | U24: =SUM(E66:E69) -> 7 | V24: =SUM(F66:F69) -> 10 | W24: =SUM(G66:G69) -> 1 | X24: =SUM(H66:H69) -> 3 | Y24: =SUM(I66:I69) -> 17 | Z24: =SUM(J66:J69) -> 1 | ... AF24: =SUM(P66:P69) -> 94
B25: 10.45 - 11.00 | C25: 9 | D25: 6 | E25: 1 | F25: 4 | G25: 0 | H25: 1 | I25: 0 | J25: 2 | K25: 1 | L25: 0 | M25: 17 | N25: 0 | O25: =SUM(C25:L25,N25) -> 24 | P25: =SUM(C25:N25) -> 41 | R25: 2200-2300 | S25: =SUM(C70:C73) -> 19 | T25: =SUM(D70:D73) -> 6 | U25: =SUM(E70:E73) -> 5 | V25: =SUM(F70:F73) -> 9 | W25: =SUM(G70:G73) -> 0 | X25: =SUM(H70:H73) -> 6 | Y25: =SUM(I70:I73) -> 24 | Z25: =SUM(J70:J73) -> 3 | ... AF25: =SUM(P70:P73) -> 88
B26: 11.00 - 11.15 | C26: 9 | D26: 1 | E26: 0 | F26: 1 | G26: 0 | H26: 0 | I26: 0 | J26: 2 | K26: 0 | L26: 1 | M26: 11 | N26: 0 | O26: =SUM(C26:L26,N26) -> 14 | P26: =SUM(C26:N26) -> 25 | R26: 2300-0000 | S26: =SUM(C74:C77) -> 22 | T26: =SUM(D74:D77) -> 5 | U26: =SUM(E74:E77) -> 4 | V26: =SUM(F74:F77) -> 4 | W26: =SUM(G74:G77) -> 0 | X26: =SUM(H74:H77) -> 4 | Y26: =SUM(I74:I77) -> 11 | Z26: =SUM(J74:J77) -> 5 | ... AF26: =SUM(P74:P77) -> 74
B27: 11.15 - 11.30 | C27: 10 | D27: 3 | E27: 2 | F27: 3 | G27: 1 | H27: 2 | I27: 0 | J27: 2 | K27: 1 | L27: 1 | M27: 12 | N27: 0 | O27: =SUM(C27:L27,N27) -> 25 | P27: =SUM(C27:N27) -> 37 | R27: 0000-0100 | S27: =SUM(C78:C81) -> 13 | T27: =SUM(D78:D81) -> 2 | U27: =SUM(E78:E81) -> 4 | V27: =SUM(F78:F81) -> 6 | W27: =SUM(G78:G81) -> 2 | X27: =SUM(H78:H81) -> 2 | Y27: =SUM(I78:I81) -> 9 | Z27: =SUM(J78:J81) -> 4 | ... AF27: =SUM(P78:P81) -> 54
B28: 11.30 - 11.45 | C28: 13 | D28: 4 | E28: 0 | F28: 4 | G28: 1 | H28: 0 | I28: 0 | J28: 0 | K28: 2 | L28: 0 | M28: 14 | N28: 0 | O28: =SUM(C28:L28,N28) -> 24 | P28: =SUM(C28:N28) -> 38 | R28: 0100-0200 | S28: =SUM(C82:C85) -> 19 | T28: =SUM(D82:D85) -> 3 | U28: =SUM(E82:E85) -> 3 | V28: =SUM(F82:F85) -> 4 | W28: =SUM(G82:G85) -> 0 | X28: =SUM(H82:H85) -> 20 | Y28: =SUM(I82:I85) -> 12 | Z28: =SUM(J82:J85) -> 14 | ... AF28: =SUM(P82:P85) -> 90
B29: 11.45 - 12.00 | C29: 7 | D29: 5 | E29: 0 | F29: 4 | G29: 1 | H29: 1 | I29: 0 | J29: 3 | K29: 1 | L29: 0 | M29: 9 | N29: 0 | O29: =SUM(C29:L29,N29) -> 22 | P29: =SUM(C29:N29) -> 31 | R29: 0200-0300 | S29: =SUM(C86:C89) -> 8 | T29: =SUM(D86:D89) -> 2 | U29: =SUM(E86:E89) -> 0 | V29: =SUM(F86:F89) -> 6 | W29: =SUM(G86:G89) -> 0 | X29: =SUM(H86:H89) -> 10 | Y29: =SUM(I86:I89) -> 6 | Z29: =SUM(J86:J89) -> 10 | ... AF29: =SUM(P86:P89) -> 58
B30: 12.00 - 12.15 | C30: 7 | D30: 4 | E30: 2 | F30: 7 | G30: 0 | H30: 2 | I30: 0 | J30: 3 | K30: 4 | L30: 0 | M30: 15 | N30: 0 | O30: =SUM(C30:L30,N30) -> 29 | P30: =SUM(C30:N30) -> 44 | R30: 0300-0400 | S30: =SUM(C90:C93) -> 10 | T30: =SUM(D90:D93) -> 0 | U30: =SUM(E90:E93) -> 1 | V30: =SUM(F90:F93) -> 4 | W30: =SUM(G90:G93) -> 1 | X30: =SUM(H90:H93) -> 7 | Y30: =SUM(I90:I93) -> 11 | Z30: =SUM(J90:J93) -> 4 | ... AF30: =SUM(P90:P93) -> 56
B31: 12.15 - 12.30 | C31: 12 | D31: 6 | E31: 4 | F31: 5 | G31: 0 | H31: 1 | I31: 1 | J31: 2 | K31: 0 | L31: 0 | M31: 10 | N31: 0 | O31: =SUM(C31:L31,N31) -> 31 | P31: =SUM(C31:N31) -> 41 | R31: 0400-0500 | S31: =SUM(C94:C97) -> 2 | T31: =SUM(D94:D97) -> 1 | U31: =SUM(E94:E97) -> 2 | V31: =SUM(F94:F97) -> 0 | W31: =SUM(G94:G97) -> 1 | X31: =SUM(H94:H97) -> 2 | Y31: =SUM(I94:I97) -> 3 | Z31: =SUM(J94:J97) -> 4 | ... AF31: =SUM(P94:P97) -> 31
B32: 12.30 - 12.45 | C32: 9 | D32: 5 | E32: 1 | F32: 6 | G32: 0 | H32: 1 | I32: 1 | J32: 3 | K32: 6 | L32: 1 | M32: 12 | N32: 0 | O32: =SUM(C32:L32,N32) -> 33 | P32: =SUM(C32:N32) -> 45 | R32: 0500-0600 | S32: =SUM(C98:C101) -> 1 | T32: =SUM(D98:D101) -> 2 | U32: =SUM(E98:E101) -> 2 | V32: =SUM(F98:F101) -> 1 | W32: =SUM(G98:G101) -> 0 | X32: =SUM(H98:H101) -> 1 | Y32: =SUM(I98:I101) -> 1 | Z32: =SUM(J98:J101) -> 4 | ... AF32: =SUM(P98:P101) -> 19
B33: 12.45 - 13.00 | C33: 11 | D33: 6 | E33: 2 | F33: 3 | G33: 0 | H33: 1 | I33: 0 | J33: 2 | K33: 0 | L33: 0 | M33: 6 | N33: 0 | O33: =SUM(C33:L33,N33) -> 25 | P33: =SUM(C33:N33) -> 31 | R33: 0600-0700 | S33: =SUM(C102:C105) -> 15 | T33: =SUM(D102:D105) -> 3 | U33: =SUM(E102:E105) -> 3 | V33: =SUM(F102:F105) -> 5 | W33: =SUM(G102:G105) -> 0 | X33: =SUM(H102:H105) -> 1 | Y33: =SUM(I102:I105) -> 6 | Z33: =SUM(J102:J105) -> 3 | ... AF33: =SUM(P102:P105) -> 55
B34: 13.00 - 13.15 | C34: 9 | D34: 4 | E34: 0 | F34: 4 | G34: 0 | H34: 1 | I34: 0 | J34: 2 | K34: 3 | L34: 0 | M34: 6 | N34: 0 | O34: =SUM(C34:L34,N34) -> 23 | P34: =SUM(C34:N34) -> 29 | R34: AM Peak Hr | S34: =MAX(S10:S12) -> 40 | T34: =MAX(T10:T12) -> 20 | U34: =MAX(U10:U12) -> 12 | V34: =MAX(V10:V12) -> 19 | W34: =MAX(W10:W12) -> 5 | X34: =MAX(X10:X12) -> 3 | Y34: =MAX(Y10:Y12) -> 9 | Z34: =MAX(Z10:Z12) -> 4 | ... AF34: =MAX(AF10:AF12) -> 155
B35: 13.15 - 13.30 | C35: 7 | D35: 1 | E35: 1 | F35: 8 | G35: 1 | H35: 1 | I35: 1 | J35: 0 | K35: 2 | L35: 0 | M35: 14 | N35: 0 | O35: =SUM(C35:L35,N35) -> 22 | P35: =SUM(C35:N35) -> 36 | R35: IP Peak Hr | S35: =MAX(S13:S18) -> 45 | T35: =MAX(T13:T18) -> 21 | U35: =MAX(U13:U18) -> 9 | V35: =MAX(V13:V18) -> 21 | W35: =MAX(W13:W18) -> 3 | X35: =MAX(X13:X18) -> 8 | Y35: =MAX(Y13:Y18) -> 5 | Z35: =MAX(Z13:Z18) -> 20 | ... AF35: =MAX(AF13:AF18) -> 173
B36: 13.30 - 13.45 | C36: 0 | D36: 0 | E36: 0 | F36: 0 | G36: 0 | H36: 0 | I36: 0 | J36: 0 | K36: 0 | L36: 0 | M36: 9 | N36: 0 | O36: =SUM(C36:L36,N36) -> 0 | P36: =SUM(C36:N36) -> 9 | R36: PM Peak Hr | S36: =MAX(S19:S21) -> 58 | T36: =MAX(T19:T21) -> 29 | U36: =MAX(U19:U21) -> 9 | V36: =MAX(V19:V21) -> 20 | W36: =MAX(W19:W21) -> 3 | X36: =MAX(X19:X21) -> 8 | Y36: =MAX(Y19:Y21) -> 10 | Z36: =MAX(Z19:Z21) -> 24 | ... AF36: =MAX(AF19:AF21) -> 204
B37: 13.45 - 14.00 | C37: 5 | D37: 4 | E37: 1 | F37: 5 | G37: 1 | H37: 4 | I37: 1 | J37: 2 | K37: 3 | L37: 0 | M37: 8 | N37: 0 | O37: =SUM(C37:L37,N37) -> 26 | P37: =SUM(C37:N37) -> 34 | R37: AM Period | S37: =SUM(S10:S12) -> 109 | T37: =SUM(T10:T12) -> 47 | U37: =SUM(U10:U12) -> 25 | V37: =SUM(V10:V12) -> 49 | W37: =SUM(W10:W12) -> 5 | X37: =SUM(X10:X12) -> 6 | Y37: =SUM(Y10:Y12) -> 18 | Z37: =SUM(Z10:Z12) -> 10 | ... AF37: =SUM(AF10:AF12) -> 428
B38: 14.00 - 14.15 | C38: 0 | D38: 0 | E38: 0 | F38: 0 | G38: 0 | H38: 0 | I38: 0 | J38: 0 | K38: 0 | L38: 0 | M38: 0 | N38: 0 | O38: =SUM(C38:L38,N38) -> 0 | P38: =SUM(C38:N38) -> 0 | R38: IP Period | S38: =SUM(S13:S18) -> 196 | T38: =SUM(T13:T18) -> 93 | U38: =SUM(U13:U18) -> 23 | V38: =SUM(V13:V18) -> 99 | W38: =SUM(W13:W18) -> 6 | X38: =SUM(X13:X18) -> 29 | Y38: =SUM(Y13:Y18) -> 12 | Z38: =SUM(Z13:Z18) -> 56 | ... AF38: =SUM(AF13:AF18) -> 815
B39: 14.15 - 14.30 | C39: 7 | D39: 2 | E39: 0 | F39: 4 | G39: 1 | H39: 0 | I39: 2 | J39: 2 | K39: 2 | L39: 0 | M39: 9 | N39: 0 | O39: =SUM(C39:L39,N39) -> 20 | P39: =SUM(C39:N39) -> 29 | R39: PM Period | S39: =SUM(S19:S21) -> 133 | T39: =SUM(T19:T21) -> 65 | U39: =SUM(U19:U21) -> 18 | V39: =SUM(V19:V21) -> 57 | W39: =SUM(W19:W21) -> 5 | X39: =SUM(X19:X21) -> 20 | Y39: =SUM(Y19:Y21) -> 20 | Z39: =SUM(Z19:Z21) -> 63 | ... AF39: =SUM(AF19:AF21) -> 535
B40: 14.30 - 14.45 | C40: 5 | D40: 4 | E40: 2 | F40: 2 | G40: 0 | H40: 3 | I40: 0 | J40: 3 | K40: 0 | L40: 1 | M40: 15 | N40: 0 | O40: =SUM(C40:L40,N40) -> 20 | P40: =SUM(C40:N40) -> 35 | R40: 12 Hours | S40: =SUM(S10:S21) -> 438 | T40: =SUM(T10:T21) -> 205 | U40: =SUM(U10:U21) -> 66 | V40: =SUM(V10:V21) -> 205 | W40: =SUM(W10:W21) -> 16 | X40: =SUM(X10:X21) -> 55 | Y40: =SUM(Y10:Y21) -> 50 | Z40: =SUM(Z10:Z21) -> 129 | ... AF40: =SUM(AF10:AF21) -> 1778
B41: 14.45 - 15.00 | C41: 9 | D41: 5 | E41: 0 | F41: 4 | G41: 0 | H41: 1 | I41: 0 | J41: 4 | K41: 0 | L41: 0 | M41: 11 | N41: 0 | O41: =SUM(C41:L41,N41) -> 23 | P41: =SUM(C41:N41) -> 34 | R41: 24 Hrs/ADT | S41: =SUM(S10:S33) -> 648 | T41: =SUM(T10:T33) -> 248 | U41: =SUM(U10:U33) -> 105 | V41: =SUM(V10:V33) -> 277 | W41: =SUM(W10:W33) -> 22 | X41: =SUM(X10:X33) -> 120 | Y41: =SUM(Y10:Y33) -> 177 | Z41: =SUM(Z10:Z33) -> 189 | ... AF41: =SUM(AF10:AF33) -> 2614
B42: 15.00 - 15.15 | C42: 8 | D42: 5 | E42: 0 | F42: 6 | G42: 0 | H42: 1 | I42: 3 | J42: 5 | K42: 0 | L42: 0 | M42: 15 | N42: 0 | O42: =SUM(C42:L42,N42) -> 28 | P42: =SUM(C42:N42) -> 43 | R42: NEF | S42: =S41/S40 -> 1.4794521 | T42: =T41/T40 -> 1.2097561 | U42: =U41/U40 -> 1.5909091 | V42: =V41/V40 -> 1.3512195 | W42: =W41/W40 -> 1.375 | X42: =X41/X40 -> 2.1818182 | Y42: =Y41/Y40 -> 3.54 | Z42: =Z41/Z40 -> 1.4651163 | ... AF42: =AF41/AF40 -> 1.4701912
...

Sheet 18.10 MBARARA-MASAKA-24H
B1: Consultancy services for Preparation of Expressway Development Master Plan (EDMP) for Uganda
B2: MANUAL CLASSIFIED COUNT (MCC)
B3: ROAD NAME: | C3: MASAKA- MBARARA ROAD
C5: Date | D5: ='18.10 MASAKA-MBARARA-24H'!D5 -> 18.10.19 | F5: Location | G5: ='18.10 MASAKA-MBARARA-24H'!G5:H5 -> KINONI | J5: Surveyor | K5: SANDRA
C6: Dir. From | D6: MBARARA | F6: Dir. To | G6: MASAKA | J6: Supervisor | K6: ='18.10 MASAKA-MBARARA-24H'!K6:L6 -> SANDRA
B8: Time / Veh Type | R8: SUMMARY TRAFFIC VOLUMES
C9: 1. Car | D9: 2. Station Wagon | E9: 3. Pickups | F9: 4. Minibus, matatu | G9: 5. Medium bus | H9: 6. Large Bus | I9: 7. Light Truck | J9: 8. Medium Truck | K9: 9. Heavy truck | L9: 10. Truck Trailer | M9: 11. Motor cycles | N9: 12. Tractors | O9: Total Excl M/Cycles | P9: Total All | R9: Time | S9: 1. Car | T9: 2. Station Wagon | U9: 3. Pickups | V9: 4. Minibus, matatu | W9: 5. Medium bus | X9: 6. Large Bus | Y9: 7. Light Truck | Z9: 8. Medium Truck | AA9: 9. Heavy truck | AB9: 10. Truck Trailer | AC9: 11. Motorcycles | AD9: 12. Tractors, Graders | AE9: Total Excl M/ Cycles | AF9: Total All
B10: 07.00 - 07.15 | C10: 5 | D10: 0 | E10: 0 | F10: 3 | G10: 0 | H10: 0 | I10: 0 | J10: 0 | K10: 1 | L10: 0 | M10: 7 | N10: 0 | O10: =SUM(C10:L10,N10) -> 9 | P10: =SUM(C10:N10) -> 16 | R10: 0700-0800 | S10: =SUM(C10:C13) -> 14 | T10: =SUM(D10:D13) -> 5 | U10: =SUM(E10:E13) -> 3 | V10: =SUM(F10:F13) -> 6 | W10: =SUM(G10:G13) -> 0 | X10: =SUM(H10:H13) -> 1 | Y10: =SUM(I10:I13) -> 1 | Z10: =SUM(J10:J13) -> 5 | ... AF10: =SUM(P10:P13) -> 92
B11: 07.15 - 07.30 | C11: 2 | D11: 0 | E11: 1 | F11: 0 | G11: 0 | H11: 1 | I11: 0 | J11: 3 | K11: 6 | L11: 0 | M11: 6 | N11: 0 | O11: =SUM(C11:L11,N11) -> 13 | P11: =SUM(C11:N11) -> 19 | R11: 0800-0900 | S11: =SUM(C14:C17) -> 14 | T11: =SUM(D14:D17) -> 8 | U11: =SUM(E14:E17) -> 0 | V11: =SUM(F14:F17) -> 17 | W11: =SUM(G14:G17) -> 0 | X11: =SUM(H14:H17) -> 1 | Y11: =SUM(I14:I17) -> 2 | Z11: =SUM(J14:J17) -> 1 | ... AF11: =SUM(P14:P17) -> 124
B12: 07.30 - 07.45 | C12: 2 | D12: 3 | E12: 0 | F12: 1 | G12: 0 | H12: 0 | I12: 0 | J12: 2 | K12: 2 | L12: 0 | M12: 20 | N12: 0 | O12: =SUM(C12:L12,N12) -> 10 | P12: =SUM(C12:N12) -> 30 | R12: 0900-1000 | S12: =SUM(C18:C21) -> 6 | T12: =SUM(D18:D21) -> 8 | U12: =SUM(E18:E21) -> 1 | V12: =SUM(F18:F21) -> 17 | W12: =SUM(G18:G21) -> 0 | X12: =SUM(H18:H21) -> 1 | Y12: =SUM(I18:I21) -> 4 | Z12: =SUM(J18:J21) -> 3 | ... AF12: =SUM(P18:P21) -> 87
B13: 07.45 - 08.00 | C13: 5 | D13: 2 | E13: 2 | F13: 2 | G13: 0 | H13: 0 | I13: 1 | J13: 0 | K13: 3 | L13: 0 | M13: 12 | N13: 0 | O13: =SUM(C13:L13,N13) -> 15 | P13: =SUM(C13:N13) -> 27 | R13: 1000-1100 | S13: =SUM(C22:C25) -> 22 | T13: =SUM(D22:D25) -> 5 | U13: =SUM(E22:E25) -> 5 | V13: =SUM(F22:F25) -> 20 | W13: =SUM(G22:G25) -> 1 | X13: =SUM(H22:H25) -> 4 | Y13: =SUM(I22:I25) -> 3 | Z13: =SUM(J22:J25) -> 2 | ... AF13: =SUM(P22:P25) -> 92
B14: 08.00 - 08.15 | C14: 3 | D14: 2 | E14: 0 | F14: 6 | G14: 0 | H14: 0 | I14: 0 | J14: 0 | K14: 0 | L14: 0 | M14: 19 | N14: 0 | O14: =SUM(C14:L14,N14) -> 11 | P14: =SUM(C14:N14) -> 30 | R14: 1100-1200 | S14: =SUM(C26:C29) -> 21 | T14: =SUM(D26:D29) -> 10 | U14: =SUM(E26:E29) -> 8 | V14: =SUM(F26:F29) -> 14 | W14: =SUM(G26:G29) -> 1 | X14: =SUM(H26:H29) -> 4 | Y14: =SUM(I26:I29) -> 2 | Z14: =SUM(J26:J29) -> 8 | ... AF14: =SUM(P26:P29) -> 116
B15: 08.15 - 08.30 | C15: 4 | D15: 3 | E15: 0 | F15: 2 | G15: 0 | H15: 0 | I15: 1 | J15: 0 | K15: 3 | L15: 0 | M15: 23 | N15: 0 | O15: =SUM(C15:L15,N15) -> 13 | P15: =SUM(C15:N15) -> 36 | R15: 1200-1300 | S15: =SUM(C30:C33) -> 33 | T15: =SUM(D30:D33) -> 13 | U15: =SUM(E30:E33) -> 4 | V15: =SUM(F30:F33) -> 17 | W15: =SUM(G30:G33) -> 0 | X15: =SUM(H30:H33) -> 3 | Y15: =SUM(I30:I33) -> 2 | Z15: =SUM(J30:J33) -> 10 | ... AF15: =SUM(P30:P33) -> 114
B16: 08.30 - 08.45 | C16: 4 | D16: 2 | E16: 0 | F16: 4 | G16: 0 | H16: 1 | I16: 0 | J16: 0 | K16: 0 | L16: 0 | M16: 23 | N16: 0 | O16: =SUM(C16:L16,N16) -> 11 | P16: =SUM(C16:N16) -> 34 | R16: 1300-1400 | S16: =SUM(C34:C37) -> 35 | T16: =SUM(D34:D37) -> 16 | U16: =SUM(E34:E37) -> 7 | V16: =SUM(F34:F37) -> 13 | W16: =SUM(G34:G37) -> 0 | X16: =SUM(H34:H37) -> 8 | Y16: =SUM(I34:I37) -> 8 | Z16: =SUM(J34:J37) -> 9 | ... AF16: =SUM(P34:P37) -> 130
B17: 08.45 - 9.00 | C17: 3 | D17: 1 | E17: 0 | F17: 5 | G17: 0 | H17: 0 | I17: 1 | J17: 1 | K17: 1 | L17: 0 | M17: 12 | N17: 0 | O17: =SUM(C17:L17,N17) -> 12 | P17: =SUM(C17:N17) -> 24 | R17: 1400-1500 | S17: =SUM(C38:C41) -> 28 | T17: =SUM(D38:D41) -> 17 | U17: =SUM(E38:E41) -> 10 | V17: =SUM(F38:F41) -> 21 | W17: =SUM(G38:G41) -> 0 | X17: =SUM(H38:H41) -> 7 | Y17: =SUM(I38:I41) -> 3 | Z17: =SUM(J38:J41) -> 6 | ... AF17: =SUM(P38:P41) -> 144
B18: 09.00 - 09.15 | C18: 3 | D18: 1 | E18: 0 | F18: 3 | G18: 0 | H18: 1 | I18: 0 | J18: 0 | K18: 1 | L18: 0 | M18: 12 | N18: 0 | O18: =SUM(C18:L18,N18) -> 9 | P18: =SUM(C18:N18) -> 21 | R18: 1500-1600 | S18: =SUM(C42:C45) -> 39 | T18: =SUM(D42:D45) -> 18 | U18: =SUM(E42:E45) -> 6 | V18: =SUM(F42:F45) -> 23 | W18: =SUM(G42:G45) -> 3 | X18: =SUM(H42:H45) -> 7 | Y18: =SUM(I42:I45) -> 4 | Z18: =SUM(J42:J45) -> 11 | ... AF18: =SUM(P42:P45) -> 165
B19: 09.15 - 09.30 | C19: 1 | D19: 3 | E19: 1 | F19: 5 | G19: 0 | H19: 0 | I19: 2 | J19: 0 | K19: 0 | L19: 0 | M19: 9 | N19: 0 | O19: =SUM(C19:L19,N19) -> 12 | P19: =SUM(C19:N19) -> 21 | R19: 1600-1700 | S19: =SUM(C46:C49) -> 42 | T19: =SUM(D46:D49) -> 13 | U19: =SUM(E46:E49) -> 7 | V19: =SUM(F46:F49) -> 23 | W19: =SUM(G46:G49) -> 1 | X19: =SUM(H46:H49) -> 9 | Y19: =SUM(I46:I49) -> 6 | Z19: =SUM(J46:J49) -> 14 | ... AF19: =SUM(P46:P49) -> 161
B20: 09.30 - 09.45 | C20: 2 | D20: 1 | E20: 0 | F20: 3 | G20: 0 | H20: 0 | I20: 0 | J20: 1 | K20: 0 | L20: 0 | M20: 15 | N20: 0 | O20: =SUM(C20:L20,N20) -> 7 | P20: =SUM(C20:N20) -> 22 | R20: 1700-1800 | S20: =SUM(C50:C53) -> 47 | T20: =SUM(D50:D53) -> 19 | U20: =SUM(E50:E53) -> 14 | V20: =SUM(F50:F53) -> 26 | W20: =SUM(G50:G53) -> 1 | X20: =SUM(H50:H53) -> 4 | Y20: =SUM(I50:I53) -> 9 | Z20: =SUM(J50:J53) -> 11 | ... AF20: =SUM(P50:P53) -> 200
B21: 09.45 - 10.00 | C21: 0 | D21: 3 | E21: 0 | F21: 6 | G21: 0 | H21: 0 | I21: 2 | J21: 2 | K21: 3 | L21: 0 | M21: 7 | N21: 0 | O21: =SUM(C21:L21,N21) -> 16 | P21: =SUM(C21:N21) -> 23 | R21: 1800-1900 | S21: =SUM(C54:C57) -> 39 | T21: =SUM(D54:D57) -> 16 | U21: =SUM(E54:E57) -> 12 | V21: =SUM(F54:F57) -> 20 | W21: =SUM(G54:G57) -> 0 | X21: =SUM(H54:H57) -> 5 | Y21: =SUM(I54:I57) -> 14 | Z21: =SUM(J54:J57) -> 16 | ... AF21: =SUM(P54:P57) -> 163
B22: 10.00 - 10.15 | C22: 5 | D22: 2 | E22: 0 | F22: 3 | G22: 0 | H22: 0 | I22: 0 | J22: 1 | K22: 1 | L22: 0 | M22: 11 | N22: 0 | O22: =SUM(C22:L22,N22) -> 12 | P22: =SUM(C22:N22) -> 23 | R22: 1900-2000 | S22: =SUM(C58:C61) -> 27 | T22: =SUM(D58:D61) -> 8 | U22: =SUM(E58:E61) -> 9 | V22: =SUM(F58:F61) -> 16 | W22: =SUM(G58:G61) -> 0 | X22: =SUM(H58:H61) -> 5 | Y22: =SUM(I58:I61) -> 21 | Z22: =SUM(J58:J61) -> 7 | ... AF22: =SUM(P58:P61) -> 141
B23: 10.15 - 10.30 | C23: 9 | D23: 0 | E23: 3 | F23: 4 | G23: 0 | H23: 1 | I23: 1 | J23: 0 | K23: 0 | L23: 0 | M23: 6 | N23: 0 | O23: =SUM(C23:L23,N23) -> 18 | P23: =SUM(C23:N23) -> 24 | R23: 2000-2100 | S23: =SUM(C62:C65) -> 38 | T23: =SUM(D62:D65) -> 8 | U23: =SUM(E62:E65) -> 6 | V23: =SUM(F62:F65) -> 16 | W23: =SUM(G62:G65) -> 1 | X23: =SUM(H62:H65) -> 4 | Y23: =SUM(I62:I65) -> 17 | Z23: =SUM(J62:J65) -> 7 | ... AF23: =SUM(P62:P65) -> 128
B24: 10.30 - 10.45 | C24: 4 | D24: 2 | E24: 1 | F24: 3 | G24: 1 | H24: 1 | I24: 1 | J24: 1 | K24: 0 | L24: 0 | M24: 3 | N24: 0 | O24: =SUM(C24:L24,N24) -> 14 | P24: =SUM(C24:N24) -> 17 | R24: 2100-2200 | S24: =SUM(C66:C69) -> 33 | T24: =SUM(D66:D69) -> 7 | U24: =SUM(E66:E69) -> 8 | V24: =SUM(F66:F69) -> 8 | W24: =SUM(G66:G69) -> 1 | X24: =SUM(H66:H69) -> 3 | Y24: =SUM(I66:I69) -> 9 | Z24: =SUM(J66:J69) -> 32 | ... AF24: =SUM(P66:P69) -> 130
B25: 10.45 - 11.00 | C25: 4 | D25: 1 | E25: 1 | F25: 10 | G25: 0 | H25: 2 | I25: 1 | J25: 0 | K25: 0 | L25: 0 | M25: 9 | N25: 0 | O25: =SUM(C25:L25,N25) -> 19 | P25: =SUM(C25:N25) -> 28 | R25: 2200-2300 | S25: =SUM(C70:C73) -> 19 | T25: =SUM(D70:D73) -> 8 | U25: =SUM(E70:E73) -> 7 | V25: =SUM(F70:F73) -> 4 | W25: =SUM(G70:G73) -> 2 | X25: =SUM(H70:H73) -> 3 | Y25: =SUM(I70:I73) -> 2 | Z25: =SUM(J70:J73) -> 21 | ... AF25: =SUM(P70:P73) -> 86
B26: 11.00 - 11.15 | C26: 6 | D26: 5 | E26: 3 | F26: 3 | G26: 0 | H26: 1 | I26: 0 | J26: 2 | K26: 2 | L26: 1 | M26: 11 | N26: 0 | O26: =SUM(C26:L26,N26) -> 23 | P26: =SUM(C26:N26) -> 34 | R26: 2300-0000 | S26: =SUM(C74:C77) -> 14 | T26: =SUM(D74:D77) -> 6 | U26: =SUM(E74:E77) -> 0 | V26: =SUM(F74:F77) -> 1 | W26: =SUM(G74:G77) -> 0 | X26: =SUM(H74:H77) -> 3 | Y26: =SUM(I74:I77) -> 3 | Z26: =SUM(J74:J77) -> 27 | ... AF26: =SUM(P74:P77) -> 86
B27: 11.15 - 11.30 | C27: 4 | D27: 3 | E27: 2 | F27: 1 | G27: 0 | H27: 1 | I27: 1 | J27: 3 | K27: 4 | L27: 0 | M27: 13 | N27: 0 | O27: =SUM(C27:L27,N27) -> 19 | P27: =SUM(C27:N27) -> 32 | R27: 0000-0100 | S27: =SUM(C78:C81) -> 3 | T27: =SUM(D78:D81) -> 3 | U27: =SUM(E78:E81) -> 2 | V27: =SUM(F78:F81) -> 2 | W27: =SUM(G78:G81) -> 0 | X27: =SUM(H78:H81) -> 4 | Y27: =SUM(I78:I81) -> 1 | Z27: =SUM(J78:J81) -> 40 | ... AF27: =SUM(P78:P81) -> 66
B28: 11.30 - 11.45 | C28: 8 | D28: 0 | E28: 2 | F28: 7 | G28: 1 | H28: 2 | I28: 1 | J28: 1 | K28: 2 | L28: 0 | M28: 4 | N28: 0 | O28: =SUM(C28:L28,N28) -> 24 | P28: =SUM(C28:N28) -> 28 | R28: 0100-0200 | S28: =SUM(C82:C85) -> 1 | T28: =SUM(D82:D85) -> 0 | U28: =SUM(E82:E85) -> 2 | V28: =SUM(F82:F85) -> 2 | W28: =SUM(G82:G85) -> 0 | X28: =SUM(H82:H85) -> 9 | Y28: =SUM(I82:I85) -> 3 | Z28: =SUM(J82:J85) -> 22 | ... AF28: =SUM(P82:P85) -> 44
B29: 11.45 - 12.00 | C29: 3 | D29: 2 | E29: 1 | F29: 3 | G29: 0 | H29: 0 | I29: 0 | J29: 2 | K29: 0 | L29: 0 | M29: 11 | N29: 0 | O29: =SUM(C29:L29,N29) -> 11 | P29: =SUM(C29:N29) -> 22 | R29: 0200-0300 | S29: =SUM(C86:C89) -> 2 | T29: =SUM(D86:D89) -> 0 | U29: =SUM(E86:E89) -> 1 | V29: =SUM(F86:F89) -> 2 | W29: =SUM(G86:G89) -> 0 | X29: =SUM(H86:H89) -> 10 | Y29: =SUM(I86:I89) -> 1 | Z29: =SUM(J86:J89) -> 26 | ... AF29: =SUM(P86:P89) -> 45
B30: 12.00 - 12.15 | C30: 3 | D30: 2 | E30: 0 | F30: 5 | G30: 0 | H30: 1 | I30: 0 | J30: 4 | K30: 0 | L30: 0 | M30: 3 | N30: 0 | O30: =SUM(C30:L30,N30) -> 15 | P30: =SUM(C30:N30) -> 18 | R30: 0300-0400 | S30: =SUM(C90:C93) -> 1 | T30: =SUM(D90:D93) -> 0 | U30: =SUM(E90:E93) -> 0 | V30: =SUM(F90:F93) -> 1 | W30: =SUM(G90:G93) -> 1 | X30: =SUM(H90:H93) -> 6 | Y30: =SUM(I90:I93) -> 1 | Z30: =SUM(J90:J93) -> 7 | ... AF30: =SUM(P90:P93) -> 22
B31: 12.15 - 12.30 | C31: 10 | D31: 2 | E31: 1 | F31: 4 | G31: 0 | H31: 1 | I31: 1 | J31: 0 | K31: 2 | L31: 0 | M31: 10 | N31: 0 | O31: =SUM(C31:L31,N31) -> 21 | P31: =SUM(C31:N31) -> 31 | R31: 0400-0500 | S31: =SUM(C94:C97) -> 1 | T31: =SUM(D94:D97) -> 0 | U31: =SUM(E94:E97) -> 0 | V31: =SUM(F94:F97) -> 0 | W31: =SUM(G94:G97) -> 0 | X31: =SUM(H94:H97) -> 9 | Y31: =SUM(I94:I97) -> 3 | Z31: =SUM(J94:J97) -> 7 | ... AF31: =SUM(P94:P97) -> 25
B32: 12.30 - 12.45 | C32: 11 | D32: 5 | E32: 3 | F32: 5 | G32: 0 | H32: 0 | I32: 1 | J32: 3 | K32: 0 | L32: 0 | M32: 7 | N32: 0 | O32: =SUM(C32:L32,N32) -> 28 | P32: =SUM(C32:N32) -> 35 | R32: 0500-0600 | S32: =SUM(C98:C101) -> 4 | T32: =SUM(D98:D101) -> 1 | U32: =SUM(E98:E101) -> 1 | V32: =SUM(F98:F101) -> 4 | W32: =SUM(G98:G101) -> 1 | X32: =SUM(H98:H101) -> 3 | Y32: =SUM(I98:I101) -> 1 | Z32: =SUM(J98:J101) -> 2 | ... AF32: =SUM(P98:P101) -> 27
B33: 12.45 - 13.00 | C33: 9 | D33: 4 | E33: 0 | F33: 3 | G33: 0 | H33: 1 | I33: 0 | J33: 3 | K33: 4 | L33: 0 | M33: 6 | N33: 0 | O33: =SUM(C33:L33,N33) -> 24 | P33: =SUM(C33:N33) -> 30 | R33: 0600-0700 | S33: =SUM(C102:C105) -> 8 | T33: =SUM(D102:D105) -> 3 | U33: =SUM(E102:E105) -> 5 | V33: =SUM(F102:F105) -> 10 | W33: =SUM(G102:G105) -> 0 | X33: =SUM(H102:H105) -> 1 | Y33: =SUM(I102:I105) -> 2 | Z33: =SUM(J102:J105) -> 1 | ... AF33: =SUM(P102:P105) -> 47
B34: 13.00 - 13.15 | C34: 10 | D34: 7 | E34: 3 | F34: 2 | G34: 0 | H34: 3 | I34: 0 | J34: 2 | K34: 0 | L34: 1 | M34: 3 | N34: 0 | O34: =SUM(C34:L34,N34) -> 28 | P34: =SUM(C34:N34) -> 31 | R34: AM Peak Hr | S34: =MAX(S10:S12) -> 14 | T34: =MAX(T10:T12) -> 8 | U34: =MAX(U10:U12) -> 3 | V34: =MAX(V10:V12) -> 17 | W34: =MAX(W10:W12) -> 0 | X34: =MAX(X10:X12) -> 1 | Y34: =MAX(Y10:Y12) -> 4 | Z34: =MAX(Z10:Z12) -> 5 | ... AF34: =MAX(AF10:AF12) -> 124
B35: 13.15 - 13.30 | C35: 9 | D35: 3 | E35: 1 | F35: 4 | G35: 0 | H35: 1 | I35: 1 | J35: 1 | K35: 0 | L35: 0 | M35: 3 | N35: 0 | O35: =SUM(C35:L35,N35) -> 20 | P35: =SUM(C35:N35) -> 23 | R35: IP Peak Hr | S35: =MAX(S13:S18) -> 39 | T35: =MAX(T13:T18) -> 18 | U35: =MAX(U13:U18) -> 10 | V35: =MAX(V13:V18) -> 23 | W35: =MAX(W13:W18) -> 3 | X35: =MAX(X13:X18) -> 8 | Y35: =MAX(Y13:Y18) -> 8 | Z35: =MAX(Z13:Z18) -> 11 | ... AF35: =MAX(AF13:AF18) -> 165
B36: 13.30 - 13.45 | C36: 8 | D36: 6 | E36: 2 | F36: 4 | G36: 0 | H36: 3 | I36: 3 | J36: 4 | K36: 4 | L36: 0 | M36: 9 | N36: 0 | O36: =SUM(C36:L36,N36) -> 34 | P36: =SUM(C36:N36) -> 43 | R36: PM Peak Hr | S36: =MAX(S19:S21) -> 47 | T36: =MAX(T19:T21) -> 19 | U36: =MAX(U19:U21) -> 14 | V36: =MAX(V19:V21) -> 26 | W36: =MAX(W19:W21) -> 1 | X36: =MAX(X19:X21) -> 9 | Y36: =MAX(Y19:Y21) -> 14 | Z36: =MAX(Z19:Z21) -> 16 | ... AF36: =MAX(AF19:AF21) -> 200
B37: 13.45 - 14.00 | C37: 8 | D37: 0 | E37: 1 | F37: 3 | G37: 0 | H37: 1 | I37: 4 | J37: 2 | K37: 2 | L37: 0 | M37: 12 | N37: 0 | O37: =SUM(C37:L37,N37) -> 21 | P37: =SUM(C37:N37) -> 33 | R37: AM Period | S37: =SUM(S10:S12) -> 34 | T37: =SUM(T10:T12) -> 21 | U37: =SUM(U10:U12) -> 4 | V37: =SUM(V10:V12) -> 40 | W37: =SUM(W10:W12) -> 0 | X37: =SUM(X10:X12) -> 3 | Y37: =SUM(Y10:Y12) -> 7 | Z37: =SUM(Z10:Z12) -> 9 | ... AF37: =SUM(AF10:AF12) -> 303
B38: 14.00 - 14.15 | C38: 7 | D38: 6 | E38: 3 | F38: 6 | G38: 0 | H38: 0 | I38: 0 | J38: 0 | K38: 4 | L38: 0 | M38: 11 | N38: 0 | O38: =SUM(C38:L38,N38) -> 26 | P38: =SUM(C38:N38) -> 37 | R38: IP Period | S38: =SUM(S13:S18) -> 178 | T38: =SUM(T13:T18) -> 79 | U38: =SUM(U13:U18) -> 40 | V38: =SUM(V13:V18) -> 108 | W38: =SUM(W13:W18) -> 5 | X38: =SUM(X13:X18) -> 33 | Y38: =SUM(Y13:Y18) -> 22 | Z38: =SUM(Z13:Z18) -> 46 | ... AF38: =SUM(AF13:AF18) -> 761
B39: 14.15 - 14.30 | C39: 2 | D39: 4 | E39: 1 | F39: 3 | G39: 0 | H39: 2 | I39: 1 | J39: 1 | K39: 0 | L39: 0 | M39: 7 | N39: 0 | O39: =SUM(C39:L39,N39) -> 14 | P39: =SUM(C39:N39) -> 21 | R39: PM Period | S39: =SUM(S19:S21) -> 128 | T39: =SUM(T19:T21) -> 48 | U39: =SUM(U19:U21) -> 33 | V39: =SUM(V19:V21) -> 69 | W39: =SUM(W19:W21) -> 2 | X39: =SUM(X19:X21) -> 18 | Y39: =SUM(Y19:Y21) -> 29 | Z39: =SUM(Z19:Z21) -> 41 | ... AF39: =SUM(AF19:AF21) -> 524
B40: 14.30 - 14.45 | C40: 10 | D40: 4 | E40: 3 | F40: 4 | G40: 0 | H40: 1 | I40: 1 | J40: 3 | K40: 4 | L40: 0 | M40: 8 | N40: 0 | O40: =SUM(C40:L40,N40) -> 30 | P40: =SUM(C40:N40) -> 38 | R40: 12 Hours | S40: =SUM(S10:S21) -> 340 | T40: =SUM(T10:T21) -> 148 | U40: =SUM(U10:U21) -> 77 | V40: =SUM(V10:V21) -> 217 | W40: =SUM(W10:W21) -> 7 | X40: =SUM(X10:X21) -> 54 | Y40: =SUM(Y10:Y21) -> 58 | Z40: =SUM(Z10:Z21) -> 96 | ... AF40: =SUM(AF10:AF21) -> 1588
B41: 14.45 - 15.00 | C41: 9 | D41: 3 | E41: 3 | F41: 8 | G41: 0 | H41: 4 | I41: 1 | J41: 2 | K41: 4 | L41: 0 | M41: 14 | N41: 0 | O41: =SUM(C41:L41,N41) -> 34 | P41: =SUM(C41:N41) -> 48 | R41: 24 Hrs/ADT | S41: =SUM(S10:S33) -> 491 | T41: =SUM(T10:T33) -> 192 | U41: =SUM(U10:U33) -> 118 | V41: =SUM(V10:V33) -> 283 | W41: =SUM(W10:W33) -> 13 | X41: =SUM(X10:X33) -> 114 | Y41: =SUM(Y10:Y33) -> 122 | Z41: =SUM(Z10:Z33) -> 295 | ... AF41: =SUM(AF10:AF33) -> 2435
B42: 15.00 - 15.15 | C42: 6 | D42: 2 | E42: 1 | F42: 2 | G42: 0 | H42: 3 | I42: 0 | J42: 2 | K42: 0 | L42: 0 | M42: 11 | N42: 0 | O42: =SUM(C42:L42,N42) -> 16 | P42: =SUM(C42:N42) -> 27 | R42: NEF | S42: =S41/S40 -> 1.4441176 | T42: =T41/T40 -> 1.2972973 | U42: =U41/U40 -> 1.5324675 | V42: =V41/V40 -> 1.3041475 | W42: =W41/W40 -> 1.8571429 | X42: =X41/X40 -> 2.1111111 | Y42: =Y41/Y40 -> 2.1034483 | Z42: =Z41/Z40 -> 3.0729167 | ... AF42: =AF41/AF40 -> 1.5333753
...

Sheet 19.10 MASAKA-MBARARA-24H
B1: Consultancy services for Preparation of Expressway Development Master Plan (EDMP) for Uganda
B2: MANUAL CLASSIFIED COUNT (MCC)
B3: ROAD NAME: | C3: MASAKA- MBARARA ROAD
C5: Date | D5: ='19.10 MBARARA-MASAKA-24H'!D5 -> 19.10.19 | F5: Location | G5: KINONI | J5: Surveyor | K5: KETRA
C6: Dir. From | D6: MASAKA | F6: Dir. To | G6: MBARARA | J6: Supervisor | K6: SANDRA
B8: Time / Veh Type | R8: SUMMARY TRAFFIC VOLUMES
C9: 1. Car | D9: 2. Station Wagon | E9: 3. Pickups | F9: 4. Minibus, matatu | G9: 5. Medium bus | H9: 6. Large Bus | I9: 7. Light Truck | J9: 8. Medium Truck | K9: 9. Heavy truck | L9: 10. Truck Trailer | M9: 11. Motor cycles | N9: 12. Tractors | O9: Total Excl M/Cycles | P9: Total All | R9: Time | S9: 1. Car | T9: 2. Station Wagon | U9: 3. Pickups | V9: 4. Minibus, matatu | W9: 5. Medium bus | X9: 6. Large Bus | Y9: 7. Light Truck | Z9: 8. Medium Truck | AA9: 9. Heavy truck | AB9: 10. Truck Trailer | AC9: 11. Motorcycles | AD9: 12. Tractors, Graders | AE9: Total Excl M/ Cycles | AF9: Total All
B10: 07.00 - 07.15 | C10: 5 | D10: 5 | E10: 0 | F10: 3 | G10: 0 | H10: 0 | I10: 1 | J10: 0 | K10: 2 | L10: 0 | M10: 6 | N10: 0 | O10: =SUM(C10:L10,N10) -> 16 | P10: =SUM(C10:N10) -> 22 | R10: 0700-0800 | S10: =SUM(C10:C13) -> 21 | T10: =SUM(D10:D13) -> 15 | U10: =SUM(E10:E13) -> 2 | V10: =SUM(F10:F13) -> 9 | W10: =SUM(G10:G13) -> 1 | X10: =SUM(H10:H13) -> 0 | Y10: =SUM(I10:I13) -> 4 | Z10: =SUM(J10:J13) -> 0 | ... AF10: =SUM(P10:P13) -> 81
B11: 07.15 - 07.30 | C11: 4 | D11: 2 | E11: 0 | F11: 3 | G11: 0 | H11: 0 | I11: 2 | J11: 0 | K11: 2 | L11: 0 | M11: 7 | N11: 0 | O11: =SUM(C11:L11,N11) -> 13 | P11: =SUM(C11:N11) -> 20 | R11: 0800-0900 | S11: =SUM(C14:C17) -> 56 | T11: =SUM(D14:D17) -> 25 | U11: =SUM(E14:E17) -> 18 | V11: =SUM(F14:F17) -> 18 | W11: =SUM(G14:G17) -> 0 | X11: =SUM(H14:H17) -> 4 | Y11: =SUM(I14:I17) -> 10 | Z11: =SUM(J14:J17) -> 5 | ... AF11: =SUM(P14:P17) -> 159
B12: 07.30 - 07.45 | C12: 7 | D12: 5 | E12: 0 | F12: 0 | G12: 0 | H12: 0 | I12: 0 | J12: 0 | K12: 2 | L12: 1 | M12: 5 | N12: 0 | O12: =SUM(C12:L12,N12) -> 15 | P12: =SUM(C12:N12) -> 20 | R12: 0900-1000 | S12: =SUM(C18:C21) -> 47 | T12: =SUM(D18:D21) -> 19 | U12: =SUM(E18:E21) -> 13 | V12: =SUM(F18:F21) -> 18 | W12: =SUM(G18:G21) -> 2 | X12: =SUM(H18:H21) -> 6 | Y12: =SUM(I18:I21) -> 7 | Z12: =SUM(J18:J21) -> 2 | ... AF12: =SUM(P18:P21) -> 170
B13: 07.45 - 08.00 | C13: 5 | D13: 3 | E13: 2 | F13: 3 | G13: 1 | H13: 0 | I13: 1 | J13: 0 | K13: 1 | L13: 0 | M13: 3 | N13: 0 | O13: =SUM(C13:L13,N13) -> 16 | P13: =SUM(C13:N13) -> 19 | R13: 1000-1100 | S13: =SUM(C22:C25) -> 48 | T13: =SUM(D22:D25) -> 27 | U13: =SUM(E22:E25) -> 17 | V13: =SUM(F22:F25) -> 31 | W13: =SUM(G22:G25) -> 2 | X13: =SUM(H22:H25) -> 3 | Y13: =SUM(I22:I25) -> 17 | Z13: =SUM(J22:J25) -> 2 | ... AF13: =SUM(P22:P25) -> 196
B14: 08.00 - 08.15 | C14: 17 | D14: 6 | E14: 4 | F14: 3 | G14: 0 | H14: 2 | I14: 3 | J14: 1 | K14: 1 | L14: 0 | M14: 4 | N14: 0 | O14: =SUM(C14:L14,N14) -> 37 | P14: =SUM(C14:N14) -> 41 | R14: 1100-1200 | S14: =SUM(C26:C29) -> 43 | T14: =SUM(D26:D29) -> 16 | U14: =SUM(E26:E29) -> 19 | V14: =SUM(F26:F29) -> 23 | W14: =SUM(G26:G29) -> 2 | X14: =SUM(H26:H29) -> 4 | Y14: =SUM(I26:I29) -> 2 | Z14: =SUM(J26:J29) -> 1 | ... AF14: =SUM(P26:P29) -> 158
