Workbook
Name Dist: '[1]ALL DATA'!$S:$S
Name Dist: '[2]ALL DATA'!$S:$S
Name Dist: '[3]ALL DATA'!$S:$S
Name Dist: '[4]ALL DATA'!$S:$S
Name Dist: '[5]ALL DATA'!$S:$S
Name Dist: '[6]ALL DATA'!$S:$S
Name Dist: '[7]ALL DATA'!$S:$S
Name Dist: '[8]ALL DATA'!$S:$S
Name Dist: '[9]ALL DATA'!$S:$S
Name Dist: '[10]ALL DATA'!$S:$S
Name Dist: '[11]ALL DATA'!$S:$S
Name Dist: '[12]ALL DATA'!$S:$S
Name Dist: '[13]ALL DATA'!$S:$S
Name Dist: '[14]ALL DATA'!$S:$S
Name Jtime: '[1]ALL DATA'!$T:$T
Name Jtime: '[2]ALL DATA'!$T:$T
Name Jtime: '[3]ALL DATA'!$T:$T
Name Jtime: '[4]ALL DATA'!$T:$T
Name Jtime: '[5]ALL DATA'!$T:$T
Name Jtime: '[6]ALL DATA'!$T:$T
Name Jtime: '[7]ALL DATA'!$T:$T
Name Jtime: '[8]ALL DATA'!$T:$T
Name Jtime: '[9]ALL DATA'!$T:$T
Name Jtime: '[10]ALL DATA'!$T:$T
Name Jtime: '[11]ALL DATA'!$T:$T
Name Jtime: '[12]ALL DATA'!$T:$T
Name Jtime: '[13]ALL DATA'!$T:$T
Name Jtime: '[14]ALL DATA'!$T:$T
Name Tripfreq: '[1]ALL DATA'!$U:$U
Name Tripfreq: '[2]ALL DATA'!$U:$U
Name Tripfreq: '[3]ALL DATA'!$U:$U
Name Tripfreq: '[4]ALL DATA'!$U:$U
Name Tripfreq: '[5]ALL DATA'!$U:$U
Name Tripfreq: '[6]ALL DATA'!$U:$U
Name Tripfreq: '[7]ALL DATA'!$U:$U
Name Tripfreq: '[8]ALL DATA'!$U:$U
Name Tripfreq: '[9]ALL DATA'!$U:$U
Name Tripfreq: '[10]ALL DATA'!$U:$U
Name Tripfreq: '[11]ALL DATA'!$U:$U
Name Tripfreq: '[12]ALL DATA'!$U:$U
Name Tripfreq: '[13]ALL DATA'!$U:$U
Name Tripfreq: '[14]ALL DATA'!$U:$U
Name Veh: '[2]ALL DATA'!$D:$D
Name Veh: '[3]ALL DATA'!$D:$D
Name Veh: '[5]ALL DATA'!$D:$D
Name Veh: '[6]ALL DATA'!$D:$D
Name Veh: '[7]ALL DATA'!$D:$D
Name Veh: '[8]ALL DATA'!$D:$D
Name Veh: '[9]ALL DATA'!$D:$D
Name Veh: '[10]ALL DATA'!$D:$D
Name Veh: '[11]ALL DATA'!$D:$D
Name Veh: '[12]ALL DATA'!$D:$D
Name Veh: '[13]ALL DATA'!$D:$D
Name Veh: '[14]ALL DATA'!$D:$D
Name zones: #REF!
Name zones: #REF!
Name zones: #REF!
Name zones: #REF!
Name zones: #REF!
Name zones: #REF!

Sheet C5 SUMMARY
B3: Vehicle OD Sample Proportions | N3: Average Journey Time
B4: Vehicle Types | C4: OD Sample | D4: OD Sample, % | N4: Journey Time Range (Hrs) | O4: Cummu-lative | P4: No of Vehicles | Q4: No. of Vehicles, %
B5: Car | C5: 95.142857 | D5: =C5/$C$17 -> 0.1916271 | N5: 0-0.25 | O5: 17 | P5: =O5 -> 17 | Q5: =P5/$O$15 -> 0.05505436
B6: Station Wagon | C6: 73.642857 | D6: =C6/$C$17 -> 0.14832398 | N6: 0.25-0.50 | O6: 47.142857 | P6: =O6-O5 -> 30.142857 | Q6: =P6/$O$15 -> 0.097617395
B7: Pickups | C7: 65 | D7: =C7/$C$17 -> 0.13091641 | N7: 0.50-0.75 | O7: 60.071429 | P7: =O7-O6 -> 12.928571 | Q7: =P7/$O$15 -> 0.041869072
B8: Minibus, matatu | C8: 19.714286 | D8: =C8/$C$17 -> 0.039706517 | N8: 0.75-1.00 | O8: 97.571429 | P8: =O8-O7 -> 37.5 | Q8: =P8/$O$15 -> 0.12144344
B9: Medium bus | C9: 11.785714 | D9: =C9/$C$17 -> 0.023737592 | N9: 1.00-1.50 | O9: 113.5 | P9: =O9-O8 -> 15.928571 | Q9: =P9/$O$15 -> 0.051584548
B10: Large Bus | C10: 27.214286 | D10: =C10/$C$17 -> 0.054812257 | N10: 1.5-2.0 | O10: 156.57143 | P10: =O10-O9 -> 43.071429 | Q10: =P10/$O$15 -> 0.13948647
B11: Light Truck | C11: 43.785714 | D11: =C11/$C$17 -> 0.08818875 | N11: 2.0-3.0 | O11: 192.64286 | P11: =O11-O10 -> 36.071429 | Q11: =P11/$O$15 -> 0.11681703
B12: Medium Truck | C12: 63.928571 | D12: =C12/$C$17 -> 0.12875845 | N12: 3.0-5.0 | O12: 229.14286 | P12: =O12-O11 -> 36.5 | Q12: =P12/$O$15 -> 0.11820495
B13: Heavy truck | C13: 52.428571 | D13: =C13/$C$17 -> 0.10559632 | N13: 5.0-7.5 | O13: 259.92857 | P13: =O13-O12 -> 30.785714 | Q13: =P13/$O$15 -> 0.099699283
B14: Truck Trailer | C14: 7.2857143 | D14: =C14/$C$17 -> 0.014674148 | N14: 7.5-10 | O14: 291.85714 | P14: =O14-O13 -> 31.928571 | Q14: =P14/$O$15 -> 0.10340042
B15: Motor cycles | C15: 30.642857 | D15: =C15/$C$17 -> 0.061717738 | N15: Over 10 | O15: 308.78571 | P15: =O15-O14 -> 16.928571 | Q15: =P15/$O$15 -> 0.05482304
B16: Tractors | C16: 5.9285714 | D16: =C16/$C$17 -> 0.011940728
B17: Average | C17: =SUM(C5:C16) -> 496.5
N21: Trip Frequency
B22: Journey Purpose | N22: Trip Frequency | O22: No of Vehicles | P22: No. of Vehicles, %
B23: Purpose | C23: Respondents | D23: Percent | N23: More than 2 times every day | O23: 80.357143 | P23: =O23/$O$29 -> 0.18391368
B24: Home-Work | C24: 62.071429 | D24: =C24/$C$29 -> 0.12501798 | N24: Daily (Up and Down) | O24: 141 | P24: =O24/$O$29 -> 0.32270721
B25: Home-Study | C25: 1.7142857 | D25: =C25/$C$29 -> 0.0034527406 | N25: 2/3 times a week | O25: 98.285714 | P25: =O25/$O$29 -> 0.22494687
B26: Work-Home | C26: 27.214286 | D26: =C26/$C$29 -> 0.054812257 | N26: Once a week | O26: 69.785714 | P26: =O26/$O$29 -> 0.15971882
B27: Work-Work | C27: 122.57143 | D27: =C27/$C$29 -> 0.24687095 | N27: Once a month | O27: 18.714286 | P27: =O27/$O$29 -> 0.042831453
B28: Others | C28: 282.92857 | D28: =C28/$C$29 -> 0.56984607 | N28: Once in a while | O28: 28.785714 | P28: =O28/$O$29 -> 0.065881968
B29: Average | C29: =C17 -> 496.5 | O29: =SUM(O23:O28) -> 436.92857
B40: Expressway Use
B41: Response | C41: Number | D41: Percent | M41: Vehicle Types | N41: Average Price
B42: Yes | C42: 99 | D42: =C42/$C$44 -> 0.19939577 | M42: Car | N42: 2.9249428
B43: No | C43: 397.5 | D43: =C43/$C$44 -> 0.80060423 | M43: Station Wagon | N43: 3.0792586
B44: Total | C44: =C17 -> 496.5 | M44: Pickups | N44: 3.7728936
M45: Minibus, matatu | N45: 10.403193
M46: Medium bus | N46: 28.750071
M47: Large Bus | N47: 30.735448
M48: Light Truck | N48: 4.039269
M49: Medium Truck | N49: 2.9170693
M50: Heavy truck | N50: 3.3746336
M51: Truck Trailer | N51: 1.9404762
M52: Motor cycles | N52: 1.4582737
M53: Tractors | N53: 1.0357143
B58: Willingness to Pay
B59: Vehicle Types | C59: Average Price
...

Sheet STN114
B1: STN114 OD ANALYSIS
B3: Vehicle OD Sample Proportions | N3: Average Journey Time
B4: Vehicle Types | C4: OD Sample | D4: OD Sample, % | N4: Journey Time Range (Hrs) | O4: Cummu-lative | P4: No of Vehicles | Q4: No. of Vehicles, %
B5: Car | C5: 56 | D5: =C5/$C$17 -> 0.16422287 | N5: 0-0.25 | O5: 0 | P5: =O5 -> 0 | Q5: =P5/$O$15 -> 0
B6: Station Wagon | C6: 57 | D6: =C6/$C$17 -> 0.16715543 | N6: 0.25-0.50 | O6: 0 | P6: =O6-O5 -> 0 | Q6: =P6/$O$15 -> 0
B7: Pickups | C7: 28 | D7: =C7/$C$17 -> 0.082111437 | N7: 0.50-0.75 | O7: 0 | P7: =O7-O6 -> 0 | Q7: =P7/$O$15 -> 0
B8: Minibus, matatu | C8: 27 | D8: =C8/$C$17 -> 0.079178886 | N8: 0.75-1.00 | O8: 69 | P8: =O8-O7 -> 69 | Q8: =P8/$O$15 -> 0.23549488
B9: Medium bus | C9: 3 | D9: =C9/$C$17 -> 0.008797654 | N9: 1.00-1.50 | O9: 69 | P9: =O9-O8 -> 0 | Q9: =P9/$O$15 -> 0
B10: Large Bus | C10: 8 | D10: =C10/$C$17 -> 0.023460411 | N10: 1.5-2.0 | O10: 139 | P10: =O10-O9 -> 70 | Q10: =P10/$O$15 -> 0.23890785
B11: Light Truck | C11: 14 | D11: =C11/$C$17 -> 0.041055718 | N11: 2.0-3.0 | O11: 156 | P11: =O11-O10 -> 17 | Q11: =P11/$O$15 -> 0.058020478
B12: Medium Truck | C12: 41 | D12: =C12/$C$17 -> 0.1202346 | N12: 3.0-5.0 | O12: 180 | P12: =O12-O11 -> 24 | Q12: =P12/$O$15 -> 0.081911263
B13: Heavy truck | C13: 30 | D13: =C13/$C$17 -> 0.08797654 | N13: 5.0-7.5 | O13: 216 | P13: =O13-O12 -> 36 | Q13: =P13/$O$15 -> 0.12286689
B14: Truck Trailer | C14: 28 | D14: =C14/$C$17 -> 0.082111437 | N14: 7.5-10 | O14: 268 | P14: =O14-O13 -> 52 | Q14: =P14/$O$15 -> 0.1774744
B15: Motor cycles | C15: 46 | D15: =C15/$C$17 -> 0.13489736 | N15: Over 10 | O15: 293 | P15: =O15-O14 -> 25 | Q15: =P15/$O$15 -> 0.085324232
B16: Tractors | C16: 3 | D16: =C16/$C$17 -> 0.008797654
C17: =SUM(C5:C16) -> 341
B18: ADT | C18: 2576 | D18: =C17/C18 -> 0.13237578
N21: Trip Frequency
B22: Journey Purpose | N22: Trip Frequency | O22: No of Vehicles | P22: No. of Vehicles, %
B23: Purpose | C23: Respondents | D23: Percent | N23: More than 2 times every day | O23: 25 | P23: =O23/$O$29 -> 0.073746313
B24: Home-Work | C24: 13 | D24: =C24/$C$29 -> 0.038123167 | N24: Daily (Up and Down) | O24: 123 | P24: =O24/$O$29 -> 0.36283186
B25: Home-Study | C25: 0 | D25: =C25/$C$29 -> 0 | N25: 2/3 times a week | O25: 78 | P25: =O25/$O$29 -> 0.2300885
B26: Work-Home | C26: 9 | D26: =C26/$C$29 -> 0.026392962 | N26: Once a week | O26: 44 | P26: =O26/$O$29 -> 0.12979351
B27: Work-Work | C27: 131 | D27: =C27/$C$29 -> 0.38416422 | N27: Once a month | O27: 22 | P27: =O27/$O$29 -> 0.064896755
B28: Others | C28: 188 | D28: =C28/$C$29 -> 0.55131965 | N28: Once in a while | O28: 47 | P28: =O28/$O$29 -> 0.13864307
B29: Total | C29: =C17 -> 341 | O29: =SUM(O23:O28) -> 339
B40: Expressway Use
B41: Response | C41: Number | D41: Percent | M41: Vehicle Types | N41: Average Price
B42: Yes | C42: 341 | D42: =C42/$C$44 -> 1 | M42: Car | N42: 3
B43: No | C43: 0 | D43: =C43/$C$44 -> 0 | M43: Station Wagon | N43: 3
B44: Total | C44: =C29 -> 341 | M44: Pickups | N44: 3
M45: Minibus, matatu | N45: 11
M46: Medium bus | N46: 39
M47: Large Bus | N47: 55
M48: Light Truck | N48: 14
M49: Medium Truck | N49: 3
M50: Heavy truck | N50: 15
M51: Truck Trailer | N51: 2
M52: Motor cycles | N52: 2
M53: Tractors | N53: 1
...

Sheet STN115
B1: STN115 OD ANALYSIS
B3: Vehicle OD Sample Proportions | N3: Average Journey Time
B4: Vehicle Types | C4: OD Sample | D4: OD Sample, % | N4: Journey Time Range (Hrs) | O4: Cummu-lative | P4: No of Vehicles | Q4: No. of Vehicles, %
B5: Car | C5: 101 | D5: =C5/$C$17 -> 0.1616 | N5: 0-0.25 | O5: 3 | P5: =O5 -> 3 | Q5: =P5/$O$15 -> 0.0061983471
B6: Station Wagon | C6: 139 | D6: =C6/$C$17 -> 0.2224 | N6: 0.25-0.50 | O6: 9 | P6: =O6-O5 -> 6 | Q6: =P6/$O$15 -> 0.012396694
B7: Pickups | C7: 104 | D7: =C7/$C$17 -> 0.1664 | N7: 0.50-0.75 | O7: 16 | P7: =O7-O6 -> 7 | Q7: =P7/$O$15 -> 0.01446281
B8: Minibus, matatu | C8: 27 | D8: =C8/$C$17 -> 0.0432 | N8: 0.75-1.00 | O8: 24 | P8: =O8-O7 -> 8 | Q8: =P8/$O$15 -> 0.016528926
B9: Medium bus | C9: 33 | D9: =C9/$C$17 -> 0.0528 | N9: 1.00-1.50 | O9: 27 | P9: =O9-O8 -> 3 | Q9: =P9/$O$15 -> 0.0061983471
B10: Large Bus | C10: 10 | D10: =C10/$C$17 -> 0.016 | N10: 1.5-2.0 | O10: 42 | P10: =O10-O9 -> 15 | Q10: =P10/$O$15 -> 0.030991736
B11: Light Truck | C11: 21 | D11: =C11/$C$17 -> 0.0336 | N11: 2.0-3.0 | O11: 99 | P11: =O11-O10 -> 57 | Q11: =P11/$O$15 -> 0.1177686
B12: Medium Truck | C12: 110 | D12: =C12/$C$17 -> 0.176 | N12: 3.0-5.0 | O12: 187 | P12: =O12-O11 -> 88 | Q12: =P12/$O$15 -> 0.18181818
B13: Heavy truck | C13: 32 | D13: =C13/$C$17 -> 0.0512 | N13: 5.0-7.5 | O13: 278 | P13: =O13-O12 -> 91 | Q13: =P13/$O$15 -> 0.18801653
B14: Truck Trailer | C14: 15 | D14: =C14/$C$17 -> 0.024 | N14: 7.5-10 | O14: 413 | P14: =O14-O13 -> 135 | Q14: =P14/$O$15 -> 0.27892562
B15: Motor cycles | C15: 10 | D15: =C15/$C$17 -> 0.016 | N15: Over 10 | O15: 484 | P15: =O15-O14 -> 71 | Q15: =P15/$O$15 -> 0.14669421
B16: Tractors | C16: 23 | D16: =C16/$C$17 -> 0.0368
C17: =SUM(C5:C16) -> 625
B18: ADT | C18: 1357 | D18: =C17/C18 -> 0.4605748
N21: Trip Frequency
B22: Journey Purpose | N22: Trip Frequency | O22: No of Vehicles | P22: No. of Vehicles, %
B23: Purpose | C23: Respondents | D23: Percent | N23: More than 2 times every day | O23: 26 | P23: =O23/$O$29 -> 0.04290429
B24: Home-Work | C24: 26 | D24: =C24/$C$29 -> 0.0416 | N24: Daily (Up and Down) | O24: 109 | P24: =O24/$O$29 -> 0.17986799
B25: Home-Study | C25: 1 | D25: =C25/$C$29 -> 0.0016 | N25: 2/3 times a week | O25: 189 | P25: =O25/$O$29 -> 0.31188119
B26: Work-Home | C26: 36 | D26: =C26/$C$29 -> 0.0576 | N26: Once a week | O26: 227 | P26: =O26/$O$29 -> 0.37458746
B27: Work-Work | C27: 271 | D27: =C27/$C$29 -> 0.4336 | N27: Once a month | O27: 35 | P27: =O27/$O$29 -> 0.057755776
B28: Others | C28: 291 | D28: =C28/$C$29 -> 0.4656 | N28: Once in a while | O28: 20 | P28: =O28/$O$29 -> 0.0330033
B29: Total | C29: =C17 -> 625 | O29: =SUM(O23:O28) -> 606
B40: Expressway Use
B41: Response | C41: Number | D41: Percent
B42: Yes | C42: 0 | D42: =C42/$C$44 -> 0 | M42: Vehicle Types | N42: Average Occupancy
B43: No | C43: 625 | D43: =C43/$C$44 -> 1 | M43: Car | N43: 2
B44: Total | C44: =C29 -> 625 | M44: Station Wagon | N44: 3
M45: Pickups | N45: 5
M46: Minibus, matatu | N46: 11
M47: Medium bus | N47: 32
M48: Large Bus | N48: 6
M49: Light Truck | N49: 2
M50: Medium Truck | N50: 2
M51: Heavy truck | N51: 2
M52: Truck Trailer | N52: 2
M53: Motor cycles | N53: 2
...

Sheet STN116
B1: STN116 OD ANALYSIS
B3: Vehicle OD Sample Proportions | N3: Average Journey Time
B4: Vehicle Types | C4: OD Sample | D4: OD Sample, % | N4: Journey Time Range (Hrs) | O4: Cummu-lative | P4: No of Vehicles | Q4: No. of Vehicles, %
B5: Car | C5: 162 | D5: =C5/$C$17 -> 0.25755167 | N5: 0-0.25 | O5: 102 | P5: =O5 -> 102 | Q5: =P5/$O$15 -> 0.17770035
B6: Station Wagon | C6: 53 | D6: =C6/$C$17 -> 0.084260731 | N6: 0.25-0.50 | O6: 192 | P6: =O6-O5 -> 90 | Q6: =P6/$O$15 -> 0.15679443
B7: Pickups | C7: 47 | D7: =C7/$C$17 -> 0.074721781 | N7: 0.50-0.75 | O7: 214 | P7: =O7-O6 -> 22 | Q7: =P7/$O$15 -> 0.038327526
B8: Minibus, matatu | C8: 49 | D8: =C8/$C$17 -> 0.077901431 | N8: 0.75-1.00 | O8: 281 | P8: =O8-O7 -> 67 | Q8: =P8/$O$15 -> 0.11672474
B9: Medium bus | C9: 1 | D9: =C9/$C$17 -> 0.0015898251 | N9: 1.00-1.50 | O9: 289 | P9: =O9-O8 -> 8 | Q9: =P9/$O$15 -> 0.013937282
B10: Large Bus | C10: 14 | D10: =C10/$C$17 -> 0.022257552 | N10: 1.5-2.0 | O10: 337 | P10: =O10-O9 -> 48 | Q10: =P10/$O$15 -> 0.083623693
B11: Light Truck | C11: 58 | D11: =C11/$C$17 -> 0.092209857 | N11: 2.0-3.0 | O11: 376 | P11: =O11-O10 -> 39 | Q11: =P11/$O$15 -> 0.067944251
B12: Medium Truck | C12: 88 | D12: =C12/$C$17 -> 0.13990461 | N12: 3.0-5.0 | O12: 426 | P12: =O12-O11 -> 50 | Q12: =P12/$O$15 -> 0.087108014
B13: Heavy truck | C13: 41 | D13: =C13/$C$17 -> 0.06518283 | N13: 5.0-7.5 | O13: 516 | P13: =O13-O12 -> 90 | Q13: =P13/$O$15 -> 0.15679443
B14: Truck Trailer | C14: 34 | D14: =C14/$C$17 -> 0.054054054 | N14: 7.5-10 | O14: 561 | P14: =O14-O13 -> 45 | Q14: =P14/$O$15 -> 0.078397213
B15: Motor cycles | C15: 80 | D15: =C15/$C$17 -> 0.12718601 | N15: Over 10 | O15: 574 | P15: =O15-O14 -> 13 | Q15: =P15/$O$15 -> 0.022648084
B16: Tractors | C16: 2 | D16: =C16/$C$17 -> 0.0031796502
C17: =SUM(C5:C16) -> 629
B18: ADT | C18: 11576 | D18: =C17/C18 -> 0.054336558
N21: Trip Frequency
B22: Journey Purpose | N22: Trip Frequency | O22: No of Vehicles | P22: No. of Vehicles, %
B23: Purpose | C23: Respondents | D23: Percent | N23: More than 2 times every day | O23: 75 | P23: =O23/$O$29 -> 0.11980831
B24: Home-Work | C24: 98 | D24: =C24/$C$29 -> 0.15580286 | N24: Daily (Up and Down) | O24: 242 | P24: =O24/$O$29 -> 0.38658147
B25: Home-Study | C25: 5 | D25: =C25/$C$29 -> 0.0079491256 | N25: 2/3 times a week | O25: 80 | P25: =O25/$O$29 -> 0.12779553
B26: Work-Home | C26: 29 | D26: =C26/$C$29 -> 0.046104928 | N26: Once a week | O26: 103 | P26: =O26/$O$29 -> 0.16453674
B27: Work-Work | C27: 114 | D27: =C27/$C$29 -> 0.18124006 | N27: Once a month | O27: 45 | P27: =O27/$O$29 -> 0.071884984
B28: Others | C28: 383 | D28: =C28/$C$29 -> 0.60890302 | N28: Once in a while | O28: 81 | P28: =O28/$O$29 -> 0.12939297
B29: Total | C29: =C17 -> 629 | O29: =SUM(O23:O28) -> 626
B40: Expressway Use
B41: Response | C41: Number | D41: Percent
B42: Yes | C42: 0 | D42: =C42/$C$44 -> 0 | M42: Vehicle Types | N42: Average Occpancy
B43: No | C43: 629 | D43: =C43/$C$44 -> 1 | M43: Car | N43: 3
B44: Total | C44: =C29 -> 629 | M44: Station Wagon | N44: 3
M45: Pickups | N45: 2
M46: Minibus, matatu | N46: 8
M47: Medium bus | N47: 67
M48: Large Bus | N48: 57
M49: Light Truck | N49: 2
M50: Medium Truck | N50: 3
M51: Heavy truck | N51: 2
M52: Truck Trailer | N52: 2
M53: Motor cycles | N53: 1
...

Sheet STN117
B1: STN117 OD ANALYSIS
B3: Vehicle OD Sample Proportions | N3: Average Journey Time
B4: Vehicle Types | C4: OD Sample | D4: OD Sample, % | N4: Journey Time Range (Hrs) | O4: Cummu-lative | P4: No of Vehicles | Q4: No. of Vehicles, %
B5: Car | C5: 65 | D5: =C5/$C$17 -> 0.19402985 | N5: 0-0.25 | O5: 6 | P5: =O5 -> 6 | Q5: =P5/$O$15 -> 0.018126888
B6: Station Wagon | C6: 21 | D6: =C6/$C$17 -> 0.062686567 | N6: 0.25-0.50 | O6: 50 | P6: =O6-O5 -> 44 | Q6: =P6/$O$15 -> 0.13293051
B7: Pickups | C7: 19 | D7: =C7/$C$17 -> 0.056716418 | N7: 0.50-0.75 | O7: 69 | P7: =O7-O6 -> 19 | Q7: =P7/$O$15 -> 0.057401813
B8: Minibus, matatu | C8: 37 | D8: =C8/$C$17 -> 0.11044776 | N8: 0.75-1.00 | O8: 99 | P8: =O8-O7 -> 30 | Q8: =P8/$O$15 -> 0.090634441
B9: Medium bus | C9: 6 | D9: =C9/$C$17 -> 0.017910448 | N9: 1.00-1.50 | O9: 107 | P9: =O9-O8 -> 8 | Q9: =P9/$O$15 -> 0.024169184
B10: Large Bus | C10: 10 | D10: =C10/$C$17 -> 0.029850746 | N10: 1.5-2.0 | O10: 148 | P10: =O10-O9 -> 41 | Q10: =P10/$O$15 -> 0.12386707
B11: Light Truck | C11: 39 | D11: =C11/$C$17 -> 0.11641791 | N11: 2.0-3.0 | O11: 214 | P11: =O11-O10 -> 66 | Q11: =P11/$O$15 -> 0.19939577
B12: Medium Truck | C12: 49 | D12: =C12/$C$17 -> 0.14626866 | N12: 3.0-5.0 | O12: 270 | P12: =O12-O11 -> 56 | Q12: =P12/$O$15 -> 0.16918429
B13: Heavy truck | C13: 25 | D13: =C13/$C$17 -> 0.074626866 | N13: 5.0-7.5 | O13: 292 | P13: =O13-O12 -> 22 | Q13: =P13/$O$15 -> 0.066465257
B14: Truck Trailer | C14: 5 | D14: =C14/$C$17 -> 0.014925373 | N14: 7.5-10 | O14: 327 | P14: =O14-O13 -> 35 | Q14: =P14/$O$15 -> 0.10574018
B15: Motor cycles | C15: 59 | D15: =C15/$C$17 -> 0.1761194 | N15: Over 10 | O15: 331 | P15: =O15-O14 -> 4 | Q15: =P15/$O$15 -> 0.012084592
B16: Tractors | C16: 0 | D16: =C16/$C$17 -> 0
C17: =SUM(C5:C16) -> 335
B18: ADT | C18: 1415 | D18: =C17/C18 -> 0.23674912
N21: Trip Frequency
B22: Journey Purpose | N22: Trip Frequency | O22: No of Vehicles | P22: No. of Vehicles, %
B23: Purpose | C23: Respondents | D23: Percent | N23: More than 2 times every day | O23: 82 | P23: =O23/$O$29 -> 0.24773414
B24: Home-Work | C24: 73 | D24: =C24/$C$29 -> 0.21791045 | N24: Daily (Up and Down) | O24: 58 | P24: =O24/$O$29 -> 0.17522659
B25: Home-Study | C25: 0 | D25: =C25/$C$29 -> 0 | N25: 2/3 times a week | O25: 24 | P25: =O25/$O$29 -> 0.072507553
B26: Work-Home | C26: 22 | D26: =C26/$C$29 -> 0.065671642 | N26: Once a week | O26: 133 | P26: =O26/$O$29 -> 0.40181269
B27: Work-Work | C27: 136 | D27: =C27/$C$29 -> 0.40597015 | N27: Once a month | O27: 8 | P27: =O27/$O$29 -> 0.024169184
B28: Others | C28: 104 | D28: =C28/$C$29 -> 0.31044776 | N28: Once in a while | O28: 26 | P28: =O28/$O$29 -> 0.078549849
B29: Total | C29: =C17 -> 335 | O29: =SUM(O23:O28) -> 331
B40: Expressway Use
B41: Response | C41: Number | D41: Percent
B42: Yes | C42: 324 | D42: =C42/$C$44 -> 0.96716418 | M42: Vehicle Types | N42: Average Occupancy
B43: No | C43: 11 | D43: =C43/$C$44 -> 0.032835821 | M43: Car | N43: 3
B44: Total | C44: =C29 -> 335 | M44: Station Wagon | N44: 3
M45: Pickups | N45: 3
M46: Minibus, matatu | N46: 11
M47: Medium bus | N47: 28
M48: Large Bus | N48: 45
M49: Light Truck | N49: 4
M50: Medium Truck | N50: 4
M51: Heavy truck | N51: 6
M52: Truck Trailer | N52: 2
M53: Motor cycles | N53: 2
...

Sheet STN118
B1: STN118 OD ANALYSIS
B3: Vehicle OD Sample Proportions | N3: Average Journey Time
B4: Vehicle Types | C4: OD Sample | D4: OD Sample, % | N4: Journey Time Range (Hrs) | O4: Cummu-lative | P4: No of Vehicles | Q4: No. of Vehicles, %
B5: Car | C5: 142 | D5: =C5/$C$17 -> 0.16118048 | N5: 0-0.25 | O5: 20 | P5: =O5 -> 20 | Q5: =P5/$O$15 -> 0.027624309
B6: Station Wagon | C6: 90 | D6: =C6/$C$17 -> 0.10215664 | N6: 0.25-0.50 | O6: 55 | P6: =O6-O5 -> 35 | Q6: =P6/$O$15 -> 0.048342541
B7: Pickups | C7: 158 | D7: =C7/$C$17 -> 0.17934166 | N7: 0.50-0.75 | O7: 87 | P7: =O7-O6 -> 32 | Q7: =P7/$O$15 -> 0.044198895
B8: Minibus, matatu | C8: 19 | D8: =C8/$C$17 -> 0.021566402 | N8: 0.75-1.00 | O8: 162 | P8: =O8-O7 -> 75 | Q8: =P8/$O$15 -> 0.10359116
B9: Medium bus | C9: 44 | D9: =C9/$C$17 -> 0.049943246 | N9: 1.00-1.50 | O9: 192 | P9: =O9-O8 -> 30 | Q9: =P9/$O$15 -> 0.041436464
B10: Large Bus | C10: 78 | D10: =C10/$C$17 -> 0.088535755 | N10: 1.5-2.0 | O10: 318 | P10: =O10-O9 -> 126 | Q10: =P10/$O$15 -> 0.17403315
B11: Light Truck | C11: 47 | D11: =C11/$C$17 -> 0.053348468 | N11: 2.0-3.0 | O11: 393 | P11: =O11-O10 -> 75 | Q11: =P11/$O$15 -> 0.10359116
B12: Medium Truck | C12: 196 | D12: =C12/$C$17 -> 0.22247446 | N12: 3.0-5.0 | O12: 498 | P12: =O12-O11 -> 105 | Q12: =P12/$O$15 -> 0.14502762
B13: Heavy truck | C13: 101 | D13: =C13/$C$17 -> 0.11464245 | N13: 5.0-7.5 | O13: 601 | P13: =O13-O12 -> 103 | Q13: =P13/$O$15 -> 0.14226519
B14: Truck Trailer | C14: 2 | D14: =C14/$C$17 -> 0.0022701476 | N14: 7.5-10 | O14: 690 | P14: =O14-O13 -> 89 | Q14: =P14/$O$15 -> 0.12292818
B15: Motor cycles | C15: 2 | D15: =C15/$C$17 -> 0.0022701476 | N15: Over 10 | O15: 724 | P15: =O15-O14 -> 34 | Q15: =P15/$O$15 -> 0.046961326
B16: Tractors | C16: 2 | D16: =C16/$C$17 -> 0.0022701476
C17: =SUM(C5:C16) -> 881
B18: ADT | C18: 2343 | D18: =C17/C18 -> 0.37601366
N21: Trip Frequency
B22: Journey Purpose | N22: Trip Frequency | O22: No of Vehicles | P22: No. of Vehicles, %
B23: Purpose | C23: Respondents | D23: Percent | N23: More than 2 times every day | O23: 150 | P23: =O23/$O$29 -> 0.17793594
B24: Home-Work | C24: 113 | D24: =C24/$C$29 -> 0.12826334 | N24: Daily (Up and Down) | O24: 218 | P24: =O24/$O$29 -> 0.25860024
B25: Home-Study | C25: 1 | D25: =C25/$C$29 -> 0.0011350738 | N25: 2/3 times a week | O25: 252 | P25: =O25/$O$29 -> 0.29893238
B26: Work-Home | C26: 17 | D26: =C26/$C$29 -> 0.019296254 | N26: Once a week | O26: 140 | P26: =O26/$O$29 -> 0.16607355
B27: Work-Work | C27: 174 | D27: =C27/$C$29 -> 0.19750284 | N27: Once a month | O27: 17 | P27: =O27/$O$29 -> 0.020166074
B28: Others | C28: 576 | D28: =C28/$C$29 -> 0.6538025 | N28: Once in a while | O28: 66 | P28: =O28/$O$29 -> 0.078291815
B29: Total | C29: =C17 -> 881 | O29: =SUM(O23:O28) -> 843
B40: Expressway Use
B41: Response | C41: Number | D41: Percent
B42: Yes | C42: 0 | D42: =C42/$C$44 -> 0 | M42: Vehicle Types | N42: Average Ocupancy
B43: No | C43: 881 | D43: =C43/$C$44 -> 1 | M43: Car | N43: 3
B44: Total | C44: =C29 -> 881 | M44: Station Wagon | N44: 3
M45: Pickups | N45: 3
M46: Minibus, matatu | N46: 9
M47: Medium bus | N47: 23
M48: Large Bus | N48: 4
M49: Light Truck | N49: 2
M50: Medium Truck | N50: 2
M51: Heavy truck | N51: 2
M52: Truck Trailer | N52: 2
M53: Motor cycles | N53: 3
...

Sheet STN119
B1: STN119 OD ANALYSIS
B3: Vehicle OD Sample Proportions | N3: Average Journey Time
B4: Vehicle Types | C4: OD Sample | D4: OD Sample, % | N4: Journey Time Range (Hrs) | O4: Cummu-lative | P4: No of Vehicles | Q4: No. of Vehicles, %
B5: Car | C5: 296 | D5: =C5/$C$17 -> 0.15017757 | N5: 0-0.25 | O5: 0 | P5: =O5 -> 0 | Q5: =P5/$O$15 -> #DIV/0!
B6: Station Wagon | C6: 285 | D6: =C6/$C$17 -> 0.14459665 | N6: 0.25-0.50 | O6: 0 | P6: =O6-O5 -> 0 | Q6: =P6/$O$15 -> #DIV/0!
B7: Pickups | C7: 407 | D7: =C7/$C$17 -> 0.20649417 | N7: 0.50-0.75 | O7: 0 | P7: =O7-O6 -> 0 | Q7: =P7/$O$15 -> #DIV/0!
B8: Minibus, matatu | C8: 17 | D8: =C8/$C$17 -> 0.0086250634 | N8: 0.75-1.00 | O8: 0 | P8: =O8-O7 -> 0 | Q8: =P8/$O$15 -> #DIV/0!
B9: Medium bus | C9: 27 | D9: =C9/$C$17 -> 0.01369863 | N9: 1.00-1.50 | O9: 0 | P9: =O9-O8 -> 0 | Q9: =P9/$O$15 -> #DIV/0!
B10: Large Bus | C10: 88 | D10: =C10/$C$17 -> 0.044647387 | N10: 1.5-2.0 | O10: 0 | P10: =O10-O9 -> 0 | Q10: =P10/$O$15 -> #DIV/0!
B11: Light Truck | C11: 313 | D11: =C11/$C$17 -> 0.15880264 | N11: 2.0-3.0 | O11: 0 | P11: =O11-O10 -> 0 | Q11: =P11/$O$15 -> #DIV/0!
B12: Medium Truck | C12: 208 | D12: =C12/$C$17 -> 0.10553019 | N12: 3.0-5.0 | O12: 0 | P12: =O12-O11 -> 0 | Q12: =P12/$O$15 -> #DIV/0!
B13: Heavy truck | C13: 329 | D13: =C13/$C$17 -> 0.16692035 | N13: 5.0-7.5 | O13: 0 | P13: =O13-O12 -> 0 | Q13: =P13/$O$15 -> #DIV/0!
B14: Truck Trailer | C14: 1 | D14: =C14/$C$17 -> 0.00050735667 | N14: 7.5-10 | O14: 0 | P14: =O14-O13 -> 0 | Q14: =P14/$O$15 -> #DIV/0!
B15: Motor cycles | C15: 0 | D15: =C15/$C$17 -> 0 | N15: Over 10 | O15: 0 | P15: =O15-O14 -> 0 | Q15: =P15/$O$15 -> #DIV/0!
B16: Tractors | C16: 0 | D16: =C16/$C$17 -> 0
C17: =SUM(C5:C16) -> 1971
B18: ADT | C18: 4921 | D18: =C17/C18 -> 0.40052835
N21: Trip Frequency
B22: Journey Purpose | N22: Trip Frequency | O22: No of Vehicles | P22: No. of Vehicles, %
B23: Purpose | C23: Respondents | D23: Percent | N23: More than 2 times every day | O23: 388 | P23: =O23/$O$29 -> 0.30265211
B24: Home-Work | C24: 164 | D24: =C24/$C$29 -> 0.083206494 | N24: Daily (Up and Down) | O24: 391 | P24: =O24/$O$29 -> 0.3049922
B25: Home-Study | C25: 10 | D25: =C25/$C$29 -> 0.0050735667 | N25: 2/3 times a week | O25: 298 | P25: =O25/$O$29 -> 0.2324493
B26: Work-Home | C26: 66 | D26: =C26/$C$29 -> 0.03348554 | N26: Once a week | O26: 88 | P26: =O26/$O$29 -> 0.068642746
B27: Work-Work | C27: 169 | D27: =C27/$C$29 -> 0.085743278 | N27: Once a month | O27: 89 | P27: =O27/$O$29 -> 0.069422777
B28: Others | C28: 1562 | D28: =C28/$C$29 -> 0.79249112 | N28: Once in a while | O28: 28 | P28: =O28/$O$29 -> 0.021840874
B29: Total | C29: =C17 -> 1971 | O29: =SUM(O23:O28) -> 1282
B40: Expressway Use
B41: Response | C41: Number | D41: Percent
B42: Yes | C42: 0 | D42: =C42/$C$44 -> 0 | M42: Vehicle Types | N42: Average Price
B43: No | C43: 1971 | D43: =C43/$C$44 -> 1 | M43: Car | N43: 2.2939189
B44: Total | C44: =C29 -> 1971 | M44: Station Wagon | N44: 2.3929825
M45: Pickups | N45: 11.287469
M46: Minibus, matatu | N46: 9.1176471
M47: Medium bus | N47: 43.076923
M48: Large Bus | N48: 2.2613636
M49: Light Truck | N49: 2.3258786
M50: Medium Truck | N50: 2.0961538
M51: Heavy truck | N51: 1.9393939
M52: Truck Trailer | N52: 1
M53: Motor cycles | N53: 0
...

Sheet STN121
B1: STN121 OD ANALYSIS
B3: Vehicle OD Sample Proportions | N3: Average Journey Time
B4: Vehicle Types | C4: OD Sample | D4: OD Sample, % | N4: Journey Time Range (Hrs) | O4: Cummu-lative | P4: No of Vehicles | Q4: No. of Vehicles, %
B5: Car | C5: 26 | D5: =C5/$C$17 -> 0.17808219 | N5: 0-0.25 | O5: 16 | P5: =O5 -> 16 | Q5: =P5/$O$15 -> 0.128
B6: Station Wagon | C6: 30 | D6: =C6/$C$17 -> 0.20547945 | N6: 0.25-0.50 | O6: 51 | P6: =O6-O5 -> 35 | Q6: =P6/$O$15 -> 0.28
B7: Pickups | C7: 20 | D7: =C7/$C$17 -> 0.1369863 | N7: 0.50-0.75 | O7: 55 | P7: =O7-O6 -> 4 | Q7: =P7/$O$15 -> 0.032
B8: Minibus, matatu | C8: 18 | D8: =C8/$C$17 -> 0.12328767 | N8: 0.75-1.00 | O8: 67 | P8: =O8-O7 -> 12 | Q8: =P8/$O$15 -> 0.096
B9: Medium bus | C9: 1 | D9: =C9/$C$17 -> 0.0068493151 | N9: 1.00-1.50 | O9: 70 | P9: =O9-O8 -> 3 | Q9: =P9/$O$15 -> 0.024
B10: Large Bus | C10: 3 | D10: =C10/$C$17 -> 0.020547945 | N10: 1.5-2.0 | O10: 78 | P10: =O10-O9 -> 8 | Q10: =P10/$O$15 -> 0.064
B11: Light Truck | C11: 9 | D11: =C11/$C$17 -> 0.061643836 | N11: 2.0-3.0 | O11: 102 | P11: =O11-O10 -> 24 | Q11: =P11/$O$15 -> 0.192
B12: Medium Truck | C12: 7 | D12: =C12/$C$17 -> 0.047945205 | N12: 3.0-5.0 | O12: 113 | P12: =O12-O11 -> 11 | Q12: =P12/$O$15 -> 0.088
B13: Heavy truck | C13: 9 | D13: =C13/$C$17 -> 0.061643836 | N13: 5.0-7.5 | O13: 116 | P13: =O13-O12 -> 3 | Q13: =P13/$O$15 -> 0.024
B14: Truck Trailer | C14: 4 | D14: =C14/$C$17 -> 0.02739726 | N14: 7.5-10 | O14: 122 | P14: =O14-O13 -> 6 | Q14: =P14/$O$15 -> 0.048
B15: Motor cycles | C15: 19 | D15: =C15/$C$17 -> 0.13013699 | N15: Over 10 | O15: 125 | P15: =O15-O14 -> 3 | Q15: =P15/$O$15 -> 0.024
B16: Tractors | C16: 0 | D16: =C16/$C$17 -> 0
C17: =SUM(C5:C16) -> 146
B18: ADT | C18: 857 | D18: =C17/C18 -> 0.17036173
N21: Trip Frequency
B22: Journey Purpose | N22: Trip Frequency | O22: No of Vehicles | P22: No. of Vehicles, %
B23: Purpose | C23: Respondents | D23: Percent | N23: More than 2 times every day | O23: 6 | P23: =O23/$O$29 -> 0.044117647
B24: Home-Work | C24: 26 | D24: =C24/$C$29 -> 0.17808219 | N24: Daily (Up and Down) | O24: 82 | P24: =O24/$O$29 -> 0.60294118
B25: Home-Study | C25: 3 | D25: =C25/$C$29 -> 0.020547945 | N25: 2/3 times a week | O25: 18 | P25: =O25/$O$29 -> 0.13235294
B26: Work-Home | C26: 9 | D26: =C26/$C$29 -> 0.061643836 | N26: Once a week | O26: 7 | P26: =O26/$O$29 -> 0.051470588
B27: Work-Work | C27: 71 | D27: =C27/$C$29 -> 0.48630137 | N27: Once a month | O27: 8 | P27: =O27/$O$29 -> 0.058823529
B28: Others | C28: 37 | D28: =C28/$C$29 -> 0.25342466 | N28: Once in a while | O28: 15 | P28: =O28/$O$29 -> 0.11029412
B29: Total | C29: =C17 -> 146 | O29: =SUM(O23:O28) -> 136
B40: Expressway Use
B41: Response | C41: Number | D41: Percent
B42: Yes | C42: 106 | D42: =C42/$C$44 -> 0.7260274 | M42: Vehicle Types | N42: Average Occupancy
B43: No | C43: 40 | D43: =C43/$C$44 -> 0.2739726 | M43: Car | N43: 2.44
B44: Total | C44: =C29 -> 146 | M44: Station Wagon | N44: 3.1666667
M45: Pickups | N45: 3
M46: Minibus, matatu | N46: 10.888889
M47: Medium bus | N47: 27
M48: Large Bus | N48: 44.333333
M49: Light Truck | N49: 2.7777778
M50: Medium Truck | N50: 2.5714286
M51: Heavy truck | N51: 2.8888889
M52: Truck Trailer | N52: 3
M53: Motor cycles | N53: 2.1578947
...

Sheet STN122
B1: STN122 OD ANALYSIS
B3: Vehicle OD Sample Proportions | N3: Average Journey Time
B4: Vehicle Types | C4: OD Sample | D4: OD Sample, % | N4: Journey Time Range (Hrs) | O4: Cummu-lative | P4: No of Vehicles | Q4: No. of Vehicles, %
B5: Car | C5: 23 | D5: =C5/$C$17 -> 0.10849057 | N5: 0-0.25 | O5: 22 | P5: =O5 -> 22 | Q5: =P5/$O$15 -> 0.10945274
B6: Station Wagon | C6: 8 | D6: =C6/$C$17 -> 0.037735849 | N6: 0.25-0.50 | O6: 61 | P6: =O6-O5 -> 39 | Q6: =P6/$O$15 -> 0.19402985
B7: Pickups | C7: 20 | D7: =C7/$C$17 -> 0.094339623 | N7: 0.50-0.75 | O7: 69 | P7: =O7-O6 -> 8 | Q7: =P7/$O$15 -> 0.039800995
B8: Minibus, matatu | C8: 18 | D8: =C8/$C$17 -> 0.08490566 | N8: 0.75-1.00 | O8: 101 | P8: =O8-O7 -> 32 | Q8: =P8/$O$15 -> 0.15920398
B9: Medium bus | C9: 0 | D9: =C9/$C$17 -> 0 | N9: 1.00-1.50 | O9: 102 | P9: =O9-O8 -> 1 | Q9: =P9/$O$15 -> 0.0049751244
B10: Large Bus | C10: 5 | D10: =C10/$C$17 -> 0.023584906 | N10: 1.5-2.0 | O10: 120 | P10: =O10-O9 -> 18 | Q10: =P10/$O$15 -> 0.089552239
B11: Light Truck | C11: 29 | D11: =C11/$C$17 -> 0.13679245 | N11: 2.0-3.0 | O11: 141 | P11: =O11-O10 -> 21 | Q11: =P11/$O$15 -> 0.10447761
B12: Medium Truck | C12: 6 | D12: =C12/$C$17 -> 0.028301887 | N12: 3.0-5.0 | O12: 163 | P12: =O12-O11 -> 22 | Q12: =P12/$O$15 -> 0.10945274
B13: Heavy truck | C13: 16 | D13: =C13/$C$17 -> 0.075471698 | N13: 5.0-7.5 | O13: 179 | P13: =O13-O12 -> 16 | Q13: =P13/$O$15 -> 0.07960199
B14: Truck Trailer | C14: 2 | D14: =C14/$C$17 -> 0.0094339623 | N14: 7.5-10 | O14: 190 | P14: =O14-O13 -> 11 | Q14: =P14/$O$15 -> 0.054726368
B15: Motor cycles | C15: 85 | D15: =C15/$C$17 -> 0.4009434 | N15: Over 10 | O15: 201 | P15: =O15-O14 -> 11 | Q15: =P15/$O$15 -> 0.054726368
B16: Tractors | C16: 0 | D16: =C16/$C$17 -> 0
C17: =SUM(C5:C16) -> 212
B18: ADT | C18: 1154 | D18: =C17/C18 -> 0.18370884
N21: Trip Frequency
B22: Journey Purpose | N22: Trip Frequency | O22: No of Vehicles | P22: No. of Vehicles, %
B23: Purpose | C23: Respondents | D23: Percent | N23: More than 2 times every day | O23: 3 | P23: =O23/$O$29 -> 0.014354067
B24: Home-Work | C24: 46 | D24: =C24/$C$29 -> 0.21698113 | N24: Daily (Up and Down) | O24: 107 | P24: =O24/$O$29 -> 0.51196172
B25: Home-Study | C25: 0 | D25: =C25/$C$29 -> 0 | N25: 2/3 times a week | O25: 48 | P25: =O25/$O$29 -> 0.22966507
B26: Work-Home | C26: 22 | D26: =C26/$C$29 -> 0.10377358 | N26: Once a week | O26: 7 | P26: =O26/$O$29 -> 0.033492823
B27: Work-Work | C27: 51 | D27: =C27/$C$29 -> 0.24056604 | N27: Once a month | O27: 4 | P27: =O27/$O$29 -> 0.019138756
B28: Others | C28: 93 | D28: =C28/$C$29 -> 0.43867925 | N28: Once in a while | O28: 40 | P28: =O28/$O$29 -> 0.19138756
B29: Total | C29: =C17 -> 212 | O29: =SUM(O23:O28) -> 209
B40: Expressway Use
B41: Response | C41: Number | D41: Percent
B42: Yes | C42: 212 | D42: =C42/$C$44 -> 1 | M42: Vehicle Types | N42: Average Price
B43: No | C43: 0 | D43: =C43/$C$44 -> 0 | M43: Car | N43: 2.7391304
B44: Total | C44: =C29 -> 212 | M44: Station Wagon | N44: 4.25
M45: Pickups | N45: 3.9
M46: Minibus, matatu | N46: 10.444444
M47: Medium bus | N47: 0
M48: Large Bus | N48: 67
M49: Light Truck | N49: 3.3448276
M50: Medium Truck | N50: 2.5
M51: Heavy truck | N51: 2.875
M52: Truck Trailer | N52: 2
M53: Motor cycles | N53: 1.6190476
...

Sheet STN123
B1: STN123 OD ANALYSIS
B3: Vehicle OD Sample Proportions | N3: Average Journey Time
B4: Vehicle Types | C4: OD Sample | D4: OD Sample, % | N4: Journey Time Range (Hrs) | O4: Cummu-lative | P4: No of Vehicles | Q4: No. of Vehicles, %
B5: Car | C5: 25 | D5: =C5/$C$17 -> 0.32894737 | N5: 0-0.25 | O5: 4 | P5: =O5 -> 4 | Q5: =P5/$O$15 -> 0.06779661
B6: Station Wagon | C6: 15 | D6: =C6/$C$17 -> 0.19736842 | N6: 0.25-0.50 | O6: 4 | P6: =O6-O5 -> 0 | Q6: =P6/$O$15 -> 0
B7: Pickups | C7: 9 | D7: =C7/$C$17 -> 0.11842105 | N7: 0.50-0.75 | O7: 4 | P7: =O7-O6 -> 0 | Q7: =P7/$O$15 -> 0
B8: Minibus, matatu | C8: 7 | D8: =C8/$C$17 -> 0.092105263 | N8: 0.75-1.00 | O8: 11 | P8: =O8-O7 -> 7 | Q8: =P8/$O$15 -> 0.11864407
B9: Medium bus | C9: 1 | D9: =C9/$C$17 -> 0.013157895 | N9: 1.00-1.50 | O9: 11 | P9: =O9-O8 -> 0 | Q9: =P9/$O$15 -> 0
B10: Large Bus | C10: 0 | D10: =C10/$C$17 -> 0 | N10: 1.5-2.0 | O10: 26 | P10: =O10-O9 -> 15 | Q10: =P10/$O$15 -> 0.25423729
B11: Light Truck | C11: 4 | D11: =C11/$C$17 -> 0.052631579 | N11: 2.0-3.0 | O11: 40 | P11: =O11-O10 -> 14 | Q11: =P11/$O$15 -> 0.23728814
B12: Medium Truck | C12: 5 | D12: =C12/$C$17 -> 0.065789474 | N12: 3.0-5.0 | O12: 54 | P12: =O12-O11 -> 14 | Q12: =P12/$O$15 -> 0.23728814
B13: Heavy truck | C13: 5 | D13: =C13/$C$17 -> 0.065789474 | N13: 5.0-7.5 | O13: 54 | P13: =O13-O12 -> 0 | Q13: =P13/$O$15 -> 0
B14: Truck Trailer | C14: 1 | D14: =C14/$C$17 -> 0.013157895 | N14: 7.5-10 | O14: 55 | P14: =O14-O13 -> 1 | Q14: =P14/$O$15 -> 0.016949153
B15: Motor cycles | C15: 4 | D15: =C15/$C$17 -> 0.052631579 | N15: Over 10 | O15: 59 | P15: =O15-O14 -> 4 | Q15: =P15/$O$15 -> 0.06779661
B16: Tractors | C16: 0 | D16: =C16/$C$17 -> 0
C17: =SUM(C5:C16) -> 76
B18: ADT | C18: 348 | D18: =C17/C18 -> 0.2183908
N21: Trip Frequency
B22: Journey Purpose | N22: Trip Frequency | O22: No of Vehicles | P22: No. of Vehicles, %
B23: Purpose | C23: Respondents | D23: Percent | N23: More than 2 times every day | O23: 7 | P23: =O23/$O$29 -> 0.093333333
B24: Home-Work | C24: 5 | D24: =C24/$C$29 -> 0.065789474 | N24: Daily (Up and Down) | O24: 43 | P24: =O24/$O$29 -> 0.57333333
B25: Home-Study | C25: 1 | D25: =C25/$C$29 -> 0.013157895 | N25: 2/3 times a week | O25: 17 | P25: =O25/$O$29 -> 0.22666667
B26: Work-Home | C26: 1 | D26: =C26/$C$29 -> 0.013157895 | N26: Once a week | O26: 2 | P26: =O26/$O$29 -> 0.026666667
B27: Work-Work | C27: 50 | D27: =C27/$C$29 -> 0.65789474 | N27: Once a month | O27: 0 | P27: =O27/$O$29 -> 0
B28: Others | C28: 19 | D28: =C28/$C$29 -> 0.25 | N28: Once in a while | O28: 6 | P28: =O28/$O$29 -> 0.08
B29: Total | C29: =C17 -> 76 | O29: =SUM(O23:O28) -> 75
B40: Expressway Use
B41: Response | C41: Number | D41: Percent
B42: Yes | C42: 76 | D42: =C42/$C$44 -> 1 | M42: Vehicle Types | N42: Average Occupancy
B43: No | C43: 0 | D43: =C43/$C$44 -> 0 | M43: Car | N43: 2.8
B44: Total | C44: =C29 -> 76 | M44: Station Wagon | N44: 2.5333333
M45: Pickups | N45: 2.1111111
M46: Minibus, matatu | N46: 8.4285714
M47: Medium bus | N47: 11
M48: Large Bus | N48: 0
M49: Light Truck | N49: 4.25
M50: Medium Truck | N50: 4.2
M51: Heavy truck | N51: 1.6
M52: Truck Trailer | N52: 3
M53: Motor cycles | N53: 1.75
...

Sheet STN124
B1: STN124 OD ANALYSIS
B3: Vehicle OD Sample Proportions | N3: Average Journey Time
B4: Vehicle Types | C4: OD Sample | D4: OD Sample, % | N4: Journey Time Range (Hrs) | O4: Cummu-lative | P4: No of Vehicles | Q4: No. of Vehicles, %
B5: Car | C5: 12 | D5: =C5/$C$17 -> 0.091603053 | N5: 0-0.25 | O5: 7 | P5: =O5 -> 7 | Q5: =P5/$O$15 -> 0.058823529
B6: Station Wagon | C6: 39 | D6: =C6/$C$17 -> 0.29770992 | N6: 0.25-0.50 | O6: 15 | P6: =O6-O5 -> 8 | Q6: =P6/$O$15 -> 0.067226891
B7: Pickups | C7: 14 | D7: =C7/$C$17 -> 0.10687023 | N7: 0.50-0.75 | O7: 19 | P7: =O7-O6 -> 4 | Q7: =P7/$O$15 -> 0.033613445
B8: Minibus, matatu | C8: 14 | D8: =C8/$C$17 -> 0.10687023 | N8: 0.75-1.00 | O8: 27 | P8: =O8-O7 -> 8 | Q8: =P8/$O$15 -> 0.067226891
B9: Medium bus | C9: 0 | D9: =C9/$C$17 -> 0 | N9: 1.00-1.50 | O9: 37 | P9: =O9-O8 -> 10 | Q9: =P9/$O$15 -> 0.084033613
B10: Large Bus | C10: 4 | D10: =C10/$C$17 -> 0.030534351 | N10: 1.5-2.0 | O10: 49 | P10: =O10-O9 -> 12 | Q10: =P10/$O$15 -> 0.10084034
B11: Light Truck | C11: 8 | D11: =C11/$C$17 -> 0.061068702 | N11: 2.0-3.0 | O11: 74 | P11: =O11-O10 -> 25 | Q11: =P11/$O$15 -> 0.21008403
B12: Medium Truck | C12: 21 | D12: =C12/$C$17 -> 0.16030534 | N12: 3.0-5.0 | O12: 93 | P12: =O12-O11 -> 19 | Q12: =P12/$O$15 -> 0.15966387
B13: Heavy truck | C13: 15 | D13: =C13/$C$17 -> 0.11450382 | N13: 5.0-7.5 | O13: 107 | P13: =O13-O12 -> 14 | Q13: =P13/$O$15 -> 0.11764706
B14: Truck Trailer | C14: 0 | D14: =C14/$C$17 -> 0 | N14: 7.5-10 | O14: 118 | P14: =O14-O13 -> 11 | Q14: =P14/$O$15 -> 0.092436975
B15: Motor cycles | C15: 3 | D15: =C15/$C$17 -> 0.022900763 | N15: Over 10 | O15: 119 | P15: =O15-O14 -> 1 | Q15: =P15/$O$15 -> 0.0084033613
B16: Tractors | C16: 1 | D16: =C16/$C$17 -> 0.0076335878
C17: =SUM(C5:C16) -> 131
B18: ADT | C18: 1181 | D18: =C17/C18 -> 0.11092295
N21: Trip Frequency
B22: Journey Purpose | N22: Trip Frequency | O22: No of Vehicles | P22: No. of Vehicles, %
B23: Purpose | C23: Respondents | D23: Percent | N23: More than 2 times every day | O23: 1 | P23: =O23/$O$29 -> 0.0085470085
B24: Home-Work | C24: 3 | D24: =C24/$C$29 -> 0.022900763 | N24: Daily (Up and Down) | O24: 15 | P24: =O24/$O$29 -> 0.12820513
B25: Home-Study | C25: 0 | D25: =C25/$C$29 -> 0 | N25: 2/3 times a week | O25: 66 | P25: =O25/$O$29 -> 0.56410256
B26: Work-Home | C26: 20 | D26: =C26/$C$29 -> 0.15267176 | N26: Once a week | O26: 13 | P26: =O26/$O$29 -> 0.11111111
B27: Work-Work | C27: 42 | D27: =C27/$C$29 -> 0.32061069 | N27: Once a month | O27: 4 | P27: =O27/$O$29 -> 0.034188034
B28: Others | C28: 66 | D28: =C28/$C$29 -> 0.50381679 | N28: Once in a while | O28: 18 | P28: =O28/$O$29 -> 0.15384615
B29: Total | C29: =C17 -> 131 | O29: =SUM(O23:O28) -> 117
B40: Expressway Use
B41: Response | C41: Number | D41: Percent
B42: Yes | C42: 0 | D42: =C42/$C$44 -> 0 | M42: Vehicle Types | N42: Average Occupancy
B43: No | C43: 131 | D43: =C43/$C$44 -> 1 | M43: Car | N43: 2.5454545
B44: Total | C44: =C29 -> 131 | M44: Station Wagon | N44: 2.9333333
M45: Pickups | N45: 2.75
M46: Minibus, matatu | N46: 13.181818
M47: Medium bus | N47: 0
M48: Large Bus | N48: 58.75
M49: Light Truck | N49: 3
M50: Medium Truck | N50: 4.0769231
M51: Heavy truck | N51: 2.4444444
M52: Truck Trailer | N52: 0
M53: Motor cycles | N53: 1.3333333
...

Sheet STN126
B1: STN126 OD ANALYSIS
B3: Vehicle OD Sample Proportions | N3: Average Journey Time
B4: Vehicle Types | C4: OD Sample | D4: OD Sample, % | N4: Journey Time Range (Hrs) | O4: Cummu-lative | P4: No of Vehicles | Q4: No. of Vehicles, %
B5: Car | C5: 53 | D5: =C5/$C$17 -> 0.13554987 | N5: 0-0.25 | O5: 11 | P5: =O5 -> 11 | Q5: =P5/$O$15 -> 0.029649596
B6: Station Wagon | C6: 20 | D6: =C6/$C$17 -> 0.051150895 | N6: 0.25-0.50 | O6: 81 | P6: =O6-O5 -> 70 | Q6: =P6/$O$15 -> 0.18867925
B7: Pickups | C7: 19 | D7: =C7/$C$17 -> 0.04859335 | N7: 0.50-0.75 | O7: 126 | P7: =O7-O6 -> 45 | Q7: =P7/$O$15 -> 0.1212938
B8: Minibus, matatu | C8: 36 | D8: =C8/$C$17 -> 0.092071611 | N8: 0.75-1.00 | O8: 171 | P8: =O8-O7 -> 45 | Q8: =P8/$O$15 -> 0.1212938
B9: Medium bus | C9: 3 | D9: =C9/$C$17 -> 0.0076726343 | N9: 1.00-1.50 | O9: 183 | P9: =O9-O8 -> 12 | Q9: =P9/$O$15 -> 0.032345013
B10: Large Bus | C10: 12 | D10: =C10/$C$17 -> 0.030690537 | N10: 1.5-2.0 | O10: 210 | P10: =O10-O9 -> 27 | Q10: =P10/$O$15 -> 0.07277628
B11: Light Truck | C11: 52 | D11: =C11/$C$17 -> 0.13299233 | N11: 2.0-3.0 | O11: 262 | P11: =O11-O10 -> 52 | Q11: =P11/$O$15 -> 0.14016173
B12: Medium Truck | C12: 49 | D12: =C12/$C$17 -> 0.12531969 | N12: 3.0-5.0 | O12: 312 | P12: =O12-O11 -> 50 | Q12: =P12/$O$15 -> 0.13477089
B13: Heavy truck | C13: 23 | D13: =C13/$C$17 -> 0.058823529 | N13: 5.0-7.5 | O13: 339 | P13: =O13-O12 -> 27 | Q13: =P13/$O$15 -> 0.07277628
B14: Truck Trailer | C14: 6 | D14: =C14/$C$17 -> 0.015345269 | N14: 7.5-10 | O14: 362 | P14: =O14-O13 -> 23 | Q14: =P14/$O$15 -> 0.061994609
B15: Motor cycles | C15: 117 | D15: =C15/$C$17 -> 0.29923274 | N15: Over 10 | O15: 371 | P15: =O15-O14 -> 9 | Q15: =P15/$O$15 -> 0.02425876
B16: Tractors | C16: 1 | D16: =C16/$C$17 -> 0.0025575448
C17: =SUM(C5:C16) -> 391
B18: ADT | C18: 1415 | D18: =C17/C18 -> 0.27632509
N21: Trip Frequency
B22: Journey Purpose | N22: Trip Frequency | O22: No of Vehicles | P22: No. of Vehicles, %
B23: Purpose | C23: Respondents | D23: Percent | N23: More than 2 times every day | O23: 53 | P23: =O23/$O$29 -> 0.14520548
B24: Home-Work | C24: 73 | D24: =C24/$C$29 -> 0.18670077 | N24: Daily (Up and Down) | O24: 125 | P24: =O24/$O$29 -> 0.34246575
B25: Home-Study | C25: 2 | D25: =C25/$C$29 -> 0.0051150895 | N25: 2/3 times a week | O25: 20 | P25: =O25/$O$29 -> 0.054794521
B26: Work-Home | C26: 34 | D26: =C26/$C$29 -> 0.086956522 | N26: Once a week | O26: 104 | P26: =O26/$O$29 -> 0.28493151
B27: Work-Work | C27: 160 | D27: =C27/$C$29 -> 0.40920716 | N27: Once a month | O27: 15 | P27: =O27/$O$29 -> 0.04109589
B28: Others | C28: 122 | D28: =C28/$C$29 -> 0.31202046 | N28: Once in a while | O28: 48 | P28: =O28/$O$29 -> 0.13150685
B29: Total | C29: =C17 -> 391 | O29: =SUM(O23:O28) -> 365
B40: Expressway Use
B41: Response | C41: Number | D41: Percent
B42: Yes | C42: 327 | D42: =C42/$C$44 -> 0.83631714 | M42: Vehicle Types | N42: Average Price
B43: No | C43: 64 | D43: =C43/$C$44 -> 0.16368286 | M43: Car | N43: 2.8113208
B44: Total | C44: =C29 -> 391 | M44: Station Wagon | N44: 2.7
M45: Pickups | N45: 3.5263158
M46: Minibus, matatu | N46: 11.583333
M47: Medium bus | N47: 27.666667
M48: Large Bus | N48: 53.333333
M49: Light Truck | N49: 3.5769231
M50: Medium Truck | N50: 2.6938776
M51: Heavy truck | N51: 3.8695652
M52: Truck Trailer | N52: 2.1666667
M53: Motor cycles | N53: 1.5555556
...

Sheet STN128
B1: STN128 OD ANALYSIS
B3: Vehicle OD Sample Proportions | N3: Average Journey Time
B4: Vehicle Types | C4: OD Sample | D4: OD Sample, % | N4: Journey Time Range (Hrs) | O4: Cummu-lative | P4: No of Vehicles | Q4: No. of Vehicles, %
B5: Car | C5: 253 | D5: =C5/$C$17 -> 0.31625 | N5: 0-0.25 | O5: 44 | P5: =O5 -> 44 | Q5: =P5/$O$15 -> 0.057667104
B6: Station Wagon | C6: 226 | D6: =C6/$C$17 -> 0.2825 | N6: 0.25-0.50 | O6: 116 | P6: =O6-O5 -> 72 | Q6: =P6/$O$15 -> 0.094364351
B7: Pickups | C7: 62 | D7: =C7/$C$17 -> 0.0775 | N7: 0.50-0.75 | O7: 141 | P7: =O7-O6 -> 25 | Q7: =P7/$O$15 -> 0.0327654
B8: Minibus, matatu | C8: 6 | D8: =C8/$C$17 -> 0.0075 | N8: 0.75-1.00 | O8: 293 | P8: =O8-O7 -> 152 | Q8: =P8/$O$15 -> 0.19921363
B9: Medium bus | C9: 27 | D9: =C9/$C$17 -> 0.03375 | N9: 1.00-1.50 | O9: 389 | P9: =O9-O8 -> 96 | Q9: =P9/$O$15 -> 0.12581913
B10: Large Bus | C10: 121 | D10: =C10/$C$17 -> 0.15125 | N10: 1.5-2.0 | O10: 541 | P10: =O10-O9 -> 152 | Q10: =P10/$O$15 -> 0.19921363
B11: Light Truck | C11: 6 | D11: =C11/$C$17 -> 0.0075 | N11: 2.0-3.0 | O11: 641 | P11: =O11-O10 -> 100 | Q11: =P11/$O$15 -> 0.1310616
B12: Medium Truck | C12: 36 | D12: =C12/$C$17 -> 0.045 | N12: 3.0-5.0 | O12: 702 | P12: =O12-O11 -> 61 | Q12: =P12/$O$15 -> 0.079947575
B13: Heavy truck | C13: 8 | D13: =C13/$C$17 -> 0.01 | N13: 5.0-7.5 | O13: 724 | P13: =O13-O12 -> 22 | Q13: =P13/$O$15 -> 0.028833552
B14: Truck Trailer | C14: 2 | D14: =C14/$C$17 -> 0.0025 | N14: 7.5-10 | O14: 748 | P14: =O14-O13 -> 24 | Q14: =P14/$O$15 -> 0.031454784
B15: Motor cycles | C15: 2 | D15: =C15/$C$17 -> 0.0025 | N15: Over 10 | O15: 763 | P15: =O15-O14 -> 15 | Q15: =P15/$O$15 -> 0.01965924
B16: Tractors | C16: 51 | D16: =C16/$C$17 -> 0.06375
C17: =SUM(C5:C16) -> 800
B18: ADT | C18: 1434 | D18: =C17/C18 -> 0.55788006
N21: Trip Frequency
B22: Journey Purpose | N22: Trip Frequency | O22: No of Vehicles | P22: No. of Vehicles, %
B23: Purpose | C23: Respondents | D23: Percent | N23: More than 2 times every day | O23: 190 | P23: =O23/$O$29 -> 0.24516129
B24: Home-Work | C24: 217 | D24: =C24/$C$29 -> 0.27125 | N24: Daily (Up and Down) | O24: 410 | P24: =O24/$O$29 -> 0.52903226
B25: Home-Study | C25: 1 | D25: =C25/$C$29 -> 0.00125 | N25: 2/3 times a week | O25: 140 | P25: =O25/$O$29 -> 0.18064516
B26: Work-Home | C26: 47 | D26: =C26/$C$29 -> 0.05875 | N26: Once a week | O26: 27 | P26: =O26/$O$29 -> 0.03483871
B27: Work-Work | C27: 168 | D27: =C27/$C$29 -> 0.21 | N27: Once a month | O27: 6 | P27: =O27/$O$29 -> 0.0077419355
B28: Others | C28: 367 | D28: =C28/$C$29 -> 0.45875 | N28: Once in a while | O28: 2 | P28: =O28/$O$29 -> 0.0025806452
B29: Total | C29: =C17 -> 800 | O29: =SUM(O23:O28) -> 775
B40: Expressway Use
B41: Response | C41: Number | D41: Percent
B42: Yes | C42: 0 | D42: =C42/$C$44 -> 0 | M42: Vehicle Types | N42: Average Price
B43: No | C43: 800 | D43: =C43/$C$44 -> 1 | M43: Car | N43: 4.6468085
B44: Total | C44: =C29 -> 800 | M44: Station Wagon | N44: 4.1105769
M45: Pickups | N45: 8.245614
M46: Minibus, matatu | N46: 22
M47: Medium bus | N47: 58.407407
M48: Large Bus | N48: 1.5825243
M49: Light Truck | N49: 8.8
M50: Medium Truck | N50: 4.7142857
M51: Heavy truck | N51: 1.375
M52: Truck Trailer | N52: 4
M53: Motor cycles | N53: 2
...

Sheet STN129
B1: STN129 OD ANALYSIS
B3: Vehicle OD Sample Proportions | N3: Average Journey Time
B4: Vehicle Types | C4: OD Sample | D4: OD Sample, % | N4: Journey Time Range (Hrs) | O4: Cummu-lative | P4: No of Vehicles | Q4: No. of Vehicles, %
B5: Car | C5: 115 | D5: =C5/$C$17 -> 0.29336735 | N5: 0-0.25 | O5: 3 | P5: =O5 -> 3 | Q5: =P5/$O$15 -> 0.011583012
B6: Station Wagon | C6: 45 | D6: =C6/$C$17 -> 0.11479592 | N6: 0.25-0.50 | O6: 25 | P6: =O6-O5 -> 22 | Q6: =P6/$O$15 -> 0.084942085
B7: Pickups | C7: 3 | D7: =C7/$C$17 -> 0.0076530612 | N7: 0.50-0.75 | O7: 38 | P7: =O7-O6 -> 13 | Q7: =P7/$O$15 -> 0.05019305
B8: Minibus, matatu | C8: 1 | D8: =C8/$C$17 -> 0.0025510204 | N8: 0.75-1.00 | O8: 58 | P8: =O8-O7 -> 20 | Q8: =P8/$O$15 -> 0.077220077
B9: Medium bus | C9: 15 | D9: =C9/$C$17 -> 0.038265306 | N9: 1.00-1.50 | O9: 104 | P9: =O9-O8 -> 46 | Q9: =P9/$O$15 -> 0.17760618
B10: Large Bus | C10: 28 | D10: =C10/$C$17 -> 0.071428571 | N10: 1.5-2.0 | O10: 175 | P10: =O10-O9 -> 71 | Q10: =P10/$O$15 -> 0.27413127
B11: Light Truck | C11: 13 | D11: =C11/$C$17 -> 0.033163265 | N11: 2.0-3.0 | O11: 189 | P11: =O11-O10 -> 14 | Q11: =P11/$O$15 -> 0.054054054
B12: Medium Truck | C12: 73 | D12: =C12/$C$17 -> 0.18622449 | N12: 3.0-5.0 | O12: 197 | P12: =O12-O11 -> 8 | Q12: =P12/$O$15 -> 0.030888031
B13: Heavy truck | C13: 99 | D13: =C13/$C$17 -> 0.25255102 | N13: 5.0-7.5 | O13: 202 | P13: =O13-O12 -> 5 | Q13: =P13/$O$15 -> 0.019305019
B14: Truck Trailer | C14: 0 | D14: =C14/$C$17 -> 0 | N14: 7.5-10 | O14: 214 | P14: =O14-O13 -> 12 | Q14: =P14/$O$15 -> 0.046332046
B15: Motor cycles | C15: 0 | D15: =C15/$C$17 -> 0 | N15: Over 10 | O15: 259 | P15: =O15-O14 -> 45 | Q15: =P15/$O$15 -> 0.17374517
B16: Tractors | C16: 0 | D16: =C16/$C$17 -> 0
C17: =SUM(C5:C16) -> 392
B18: ADT | C18: 746 | D18: =C17/C18 -> 0.52546917
N21: Trip Frequency
B22: Journey Purpose | N22: Trip Frequency | O22: No of Vehicles | P22: No. of Vehicles, %
B23: Purpose | C23: Respondents | D23: Percent | N23: More than 2 times every day | O23: 117 | P23: =O23/$O$29 -> 0.29846939
B24: Home-Work | C24: 12 | D24: =C24/$C$29 -> 0.030612245 | N24: Daily (Up and Down) | O24: 46 | P24: =O24/$O$29 -> 0.11734694
B25: Home-Study | C25: 0 | D25: =C25/$C$29 -> 0 | N25: 2/3 times a week | O25: 136 | P25: =O25/$O$29 -> 0.34693878
B26: Work-Home | C26: 68 | D26: =C26/$C$29 -> 0.17346939 | N26: Once a week | O26: 80 | P26: =O26/$O$29 -> 0.20408163
B27: Work-Work | C27: 176 | D27: =C27/$C$29 -> 0.44897959 | N27: Once a month | O27: 8 | P27: =O27/$O$29 -> 0.020408163
B28: Others | C28: 136 | D28: =C28/$C$29 -> 0.34693878 | N28: Once in a while | O28: 5 | P28: =O28/$O$29 -> 0.012755102
B29: Total | C29: =C17 -> 392 | O29: =SUM(O23:O28) -> 392
B40: Expressway Use
B41: Response | C41: Number | D41: Percent
B42: Yes | C42: 0 | D42: =C42/$C$44 -> 0 | M42: Vehicle Types | N42: Average Occupancy
B43: No | C43: 392 | D43: =C43/$C$44 -> 1 | M43: Car | N43: 3.6725664
B44: Total | C44: =C29 -> 392 | M44: Station Wagon | N44: 3.0227273
M45: Pickups | N45: 2
M46: Minibus, matatu | N46: 10
M47: Medium bus | N47: 24.6
M48: Large Bus | N48: 36.035714
M49: Light Truck | N49: 2.3076923
M50: Medium Truck | N50: 1.9863014
M51: Heavy truck | N51: 1.7525773
M52: Truck Trailer | N52: 0
M53: Motor cycles | N53: 0
...

Sheet STN130
B1: STN130 OD ANALYSIS
B3: Vehicle OD Sample Proportions | N3: Average Journey Time
B4: Vehicle Types | C4: OD Sample | D4: OD Sample, % | N4: Journey Time Range (Hrs) | O4: Cummu-lative | P4: No of Vehicles | Q4: No. of Vehicles, %
B5: Car | C5: 3 | D5: =C5/$C$17 -> 0.14285714 | N5: 0-0.25 | O5: 0 | P5: =O5 -> 0 | Q5: =P5/$O$15 -> 0
B6: Station Wagon | C6: 3 | D6: =C6/$C$17 -> 0.14285714 | N6: 0.25-0.50 | O6: 1 | P6: =O6-O5 -> 1 | Q6: =P6/$O$15 -> 0.05
B7: Pickups | C7: 0 | D7: =C7/$C$17 -> 0 | N7: 0.50-0.75 | O7: 3 | P7: =O7-O6 -> 2 | Q7: =P7/$O$15 -> 0.1
B8: Minibus, matatu | C8: 0 | D8: =C8/$C$17 -> 0 | N8: 0.75-1.00 | O8: 3 | P8: =O8-O7 -> 0 | Q8: =P8/$O$15 -> 0
B9: Medium bus | C9: 4 | D9: =C9/$C$17 -> 0.19047619 | N9: 1.00-1.50 | O9: 9 | P9: =O9-O8 -> 6 | Q9: =P9/$O$15 -> 0.3
B10: Large Bus | C10: 0 | D10: =C10/$C$17 -> 0 | N10: 1.5-2.0 | O10: 9 | P10: =O10-O9 -> 0 | Q10: =P10/$O$15 -> 0
B11: Light Truck | C11: 0 | D11: =C11/$C$17 -> 0 | N11: 2.0-3.0 | O11: 10 | P11: =O11-O10 -> 1 | Q11: =P11/$O$15 -> 0.05
B12: Medium Truck | C12: 6 | D12: =C12/$C$17 -> 0.28571429 | N12: 3.0-5.0 | O12: 13 | P12: =O12-O11 -> 3 | Q12: =P12/$O$15 -> 0.15
B13: Heavy truck | C13: 1 | D13: =C13/$C$17 -> 0.047619048 | N13: 5.0-7.5 | O13: 15 | P13: =O13-O12 -> 2 | Q13: =P13/$O$15 -> 0.1
B14: Truck Trailer | C14: 2 | D14: =C14/$C$17 -> 0.095238095 | N14: 7.5-10 | O14: 18 | P14: =O14-O13 -> 3 | Q14: =P14/$O$15 -> 0.15
B15: Motor cycles | C15: 2 | D15: =C15/$C$17 -> 0.095238095 | N15: Over 10 | O15: 20 | P15: =O15-O14 -> 2 | Q15: =P15/$O$15 -> 0.1
B16: Tractors | C16: 0 | D16: =C16/$C$17 -> 0
C17: =SUM(C5:C16) -> 21
B18: ADT | C18: 602 | D18: =C17/C18 -> 0.034883721
N21: Trip Frequency
B22: Journey Purpose | N22: Trip Frequency | O22: No of Vehicles | P22: No. of Vehicles, %
B23: Purpose | C23: Respondents | D23: Percent | N23: More than 2 times every day | O23: 2 | P23: =O23/$O$29 -> 0.095238095
B24: Home-Work | C24: 0 | D24: =C24/$C$29 -> 0 | N24: Daily (Up and Down) | O24: 5 | P24: =O24/$O$29 -> 0.23809524
B25: Home-Study | C25: 0 | D25: =C25/$C$29 -> 0 | N25: 2/3 times a week | O25: 10 | P25: =O25/$O$29 -> 0.47619048
B26: Work-Home | C26: 1 | D26: =C26/$C$29 -> 0.047619048 | N26: Once a week | O26: 2 | P26: =O26/$O$29 -> 0.095238095
B27: Work-Work | C27: 3 | D27: =C27/$C$29 -> 0.14285714 | N27: Once a month | O27: 1 | P27: =O27/$O$29 -> 0.047619048
B28: Others | C28: 17 | D28: =C28/$C$29 -> 0.80952381 | N28: Once in a while | O28: 1 | P28: =O28/$O$29 -> 0.047619048
B29: Total | C29: =C17 -> 21 | O29: =SUM(O23:O28) -> 21
B40: Expressway Use
B41: Response | C41: Number | D41: Percent
B42: Yes | C42: 0 | D42: =C42/$C$44 -> 0 | N42: Vehicle Types | O42: Average Occupancy
B43: No | C43: 21 | D43: =C43/$C$44 -> 1 | N43: Car | O43: 3
B44: Total | C44: =C29 -> 21 | N44: Station Wagon | O44: 3
N45: Pickups | O45: 0
N46: Minibus, matatu | O46: 0
N47: Medium bus | O47: 21.75
N48: Large Bus | O48: 0
N49: Light Truck | O49: 2.1666667
N50: Medium Truck | O50: 2
N51: Heavy truck | O51: 1.5
N52: Truck Trailer | O52: 2
N53: Motor cycles | O53: 0
...
