Workbook
Name Dist: '[1]ALL DATA'!$S:$S
Name Dist: '[2]ALL DATA'!$S:$S
Name Dist: '[3]ALL DATA'!$S:$S
Name Dist: '[4]ALL DATA'!$R:$R
Name Dist: '[5]ALL DATA'!$S:$S
Name Dist: '[6]ALL DATA'!$S:$S
Name Dist: '[1]ALL DATA'!$S:$S
Name Dist: '[7]ALL DATA'!$S:$S
Name Dist: '[8]ALL DATA'!$S:$S
Name Dist: '[9]ALL DATA'!$S:$S
Name Dist: '[10]ALL DATA'!$S:$S
Name Dist: '[11]ALL DATA'!$S:$S
Name Dist: '[12]ALL DATA'!$S:$S
Name Dist: '[13]ALL DATA'!$S:$S
Name Dist: '[14]ALL DATA'!$S:$S
Name Dist: '[1]ALL DATA'!$S:$S
Name Dist: '[15]ALL DATA'!$S:$S
Name Jtime: '[1]ALL DATA'!$T:$T
Name Jtime: '[2]ALL DATA'!$T:$T
Name Jtime: '[3]ALL DATA'!$T:$T
Name Jtime: '[4]ALL DATA'!$S:$S
Name Jtime: '[5]ALL DATA'!$T:$T
Name Jtime: '[6]ALL DATA'!$T:$T
Name Jtime: '[1]ALL DATA'!$T:$T
Name Jtime: '[7]ALL DATA'!$T:$T
Name Jtime: '[8]ALL DATA'!$T:$T
Name Jtime: '[9]ALL DATA'!$T:$T
Name Jtime: '[10]ALL DATA'!$T:$T
Name Jtime: '[11]ALL DATA'!$T:$T
Name Jtime: '[12]ALL DATA'!$T:$T
Name Jtime: '[13]ALL DATA'!$T:$T
Name Jtime: '[14]ALL DATA'!$T:$T
Name Jtime: '[1]ALL DATA'!$T:$T
Name Jtime: '[15]ALL DATA'!$T:$T
Name occ: '[16]ALL DATA'!$E:$E
Name Tripfreq: '[1]ALL DATA'!$U:$U
Name Tripfreq: '[2]ALL DATA'!$U:$U
Name Tripfreq: '[3]ALL DATA'!$U:$U
Name Tripfreq: '[4]ALL DATA'!$T:$T
Name Tripfreq: '[5]ALL DATA'!$U:$U
Name Tripfreq: '[6]ALL DATA'!$U:$U
Name Tripfreq: '[1]ALL DATA'!$U:$U
Name Tripfreq: '[7]ALL DATA'!$U:$U
Name Tripfreq: '[8]ALL DATA'!$U:$U
Name Tripfreq: '[9]ALL DATA'!$U:$U
Name Tripfreq: '[10]ALL DATA'!$U:$U
Name Tripfreq: '[11]ALL DATA'!$U:$U
Name Tripfreq: '[12]ALL DATA'!$U:$U
Name Tripfreq: '[13]ALL DATA'!$U:$U
Name Tripfreq: '[14]ALL DATA'!$U:$U
Name Tripfreq: '[1]ALL DATA'!$U:$U
Name Tripfreq: '[15]ALL DATA'!$U:$U
Name veh: '[1]ALL DATA'!$D:$D
Name Veh: '[4]ALL DATA'!$C:$C
Name Veh: '[6]ALL DATA'!$D:$D
Name veh: '[1]ALL DATA'!$D:$D
Name Veh: '[8]ALL DATA'!$D:$D
Name Veh: '[11]ALL DATA'!$D:$D
Name veh: '[1]ALL DATA'!$D:$D
Name Veh: '[2]ALL DATA'!$D:$D

Sheet AVERAGE C4
B3: Vehicle OD Sample Proportions | N3: Average Journey Time
B4: Vehicle Types | C4: OD Sample | D4: OD Sample, % | N4: Journey Time Range (Hrs) | O4: Cummu-lative | P4: No of Vehicles | Q4: No. of Vehicles, %
B5: Car | C5: =AVERAGE('STN 99'!C5,'STN 100A'!C5,'STN 100'!C5,'STN 101'!C5,'STN 102'!C5,'STN 103'!C5,'STN 104'!C5,'STN 105'!C5,'STN 106'!C5,'STN 107'!C5,'STN 108'!C5,'STN 111A'!C5,'STN 111'!C5,'STN 112'!C5,'STN 113'!C5,'STN 120'!C5) -> 127.125 | D5: =C5/$C$17 -> 0.27650897 | N5: 0-0.25 | O5: =AVERAGE('STN 99'!O5,'STN 100A'!O5,'STN 100'!O5,'STN 101'!O5,'STN 102'!O5,'STN 103'!O5,'STN 104'!O5,'STN 105'!O5,'STN 106'!O5,'STN 107'!O5,'STN 108'!O5,'STN 111A'!O5,'STN 111'!O5,'STN 112'!O5,'STN 113'!O5,'STN 120'!O5) -> 73.5 | P5: =O5 -> 73.5 | Q5: =P5/$O$15 -> 0.1382066
B6: Station Wagon | C6: =AVERAGE('STN 99'!C6,'STN 100A'!C6,'STN 100'!C6,'STN 101'!C6,'STN 102'!C6,'STN 103'!C6,'STN 104'!C6,'STN 105'!C6,'STN 106'!C6,'STN 107'!C6,'STN 108'!C6,'STN 111A'!C6,'STN 111'!C6,'STN 112'!C6,'STN 113'!C6,'STN 120'!C6) -> 60.8125 | D6: =C6/$C$17 -> 0.13227297 | N6: 0.25-0.50 | O6: =AVERAGE('STN 99'!O6,'STN 100A'!O6,'STN 100'!O6,'STN 101'!O6,'STN 102'!O6,'STN 103'!O6,'STN 104'!O6,'STN 105'!O6,'STN 106'!O6,'STN 107'!O6,'STN 108'!O6,'STN 111A'!O6,'STN 111'!O6,'STN 112'!O6,'STN 113'!O6,'STN 120'!O6) -> 178.6875 | P6: =O6-O5 -> 105.1875 | Q6: =P6/$O$15 -> 0.19779057
B7: Pickups | C7: =AVERAGE('STN 99'!C7,'STN 100A'!C7,'STN 100'!C7,'STN 101'!C7,'STN 102'!C7,'STN 103'!C7,'STN 104'!C7,'STN 105'!C7,'STN 106'!C7,'STN 107'!C7,'STN 108'!C7,'STN 111A'!C7,'STN 111'!C7,'STN 112'!C7,'STN 113'!C7,'STN 120'!C7) -> 54.8125 | D7: =C7/$C$17 -> 0.1192224 | N7: 0.50-0.75 | O7: =AVERAGE('STN 99'!O7,'STN 100A'!O7,'STN 100'!O7,'STN 101'!O7,'STN 102'!O7,'STN 103'!O7,'STN 104'!O7,'STN 105'!O7,'STN 106'!O7,'STN 107'!O7,'STN 108'!O7,'STN 111A'!O7,'STN 111'!O7,'STN 112'!O7,'STN 113'!O7,'STN 120'!O7) -> 216.0625 | P7: =O7-O6 -> 37.375 | Q7: =P7/$O$15 -> 0.070278529
B8: Minibus, matatu | C8: =AVERAGE('STN 99'!C8,'STN 100A'!C8,'STN 100'!C8,'STN 101'!C8,'STN 102'!C8,'STN 103'!C8,'STN 104'!C8,'STN 105'!C8,'STN 106'!C8,'STN 107'!C8,'STN 108'!C8,'STN 111A'!C8,'STN 111'!C8,'STN 112'!C8,'STN 113'!C8,'STN 120'!C8) -> 46.6875 | D8: =C8/$C$17 -> 0.10154976 | N8: 0.75-1.00 | O8: =AVERAGE('STN 99'!O8,'STN 100A'!O8,'STN 100'!O8,'STN 101'!O8,'STN 102'!O8,'STN 103'!O8,'STN 104'!O8,'STN 105'!O8,'STN 106'!O8,'STN 107'!O8,'STN 108'!O8,'STN 111A'!O8,'STN 111'!O8,'STN 112'!O8,'STN 113'!O8,'STN 120'!O8) -> 310.125 | P8: =O8-O7 -> 94.0625 | Q8: =P8/$O$15 -> 0.17687155
B9: Medium bus | C9: =AVERAGE('STN 99'!C9,'STN 100A'!C9,'STN 100'!C9,'STN 101'!C9,'STN 102'!C9,'STN 103'!C9,'STN 104'!C9,'STN 105'!C9,'STN 106'!C9,'STN 107'!C9,'STN 108'!C9,'STN 111A'!C9,'STN 111'!C9,'STN 112'!C9,'STN 113'!C9,'STN 120'!C9) -> 9.75 | D9: =C9/$C$17 -> 0.021207178 | N9: 1.00-1.50 | O9: =AVERAGE('STN 99'!O9,'STN 100A'!O9,'STN 100'!O9,'STN 101'!O9,'STN 102'!O9,'STN 103'!O9,'STN 104'!O9,'STN 105'!O9,'STN 106'!O9,'STN 107'!O9,'STN 108'!O9,'STN 111A'!O9,'STN 111'!O9,'STN 112'!O9,'STN 113'!O9,'STN 120'!O9) -> 333.6875 | P9: =O9-O8 -> 23.5625 | Q9: =P9/$O$15 -> 0.044306029
B10: Large Bus | C10: =AVERAGE('STN 99'!C10,'STN 100A'!C10,'STN 100'!C10,'STN 101'!C10,'STN 102'!C10,'STN 103'!C10,'STN 104'!C10,'STN 105'!C10,'STN 106'!C10,'STN 107'!C10,'STN 108'!C10,'STN 111A'!C10,'STN 111'!C10,'STN 112'!C10,'STN 113'!C10,'STN 120'!C10) -> 14.5625 | D10: =C10/$C$17 -> 0.031674823 | N10: 1.5-2.0 | O10: =AVERAGE('STN 99'!O10,'STN 100A'!O10,'STN 100'!O10,'STN 101'!O10,'STN 102'!O10,'STN 103'!O10,'STN 104'!O10,'STN 105'!O10,'STN 106'!O10,'STN 107'!O10,'STN 108'!O10,'STN 111A'!O10,'STN 111'!O10,'STN 112'!O10,'STN 113'!O10,'STN 120'!O10) -> 377.875 | P10: =O10-O9 -> 44.1875 | Q10: =P10/$O$15 -> 0.083088495
B11: Light Truck | C11: =AVERAGE('STN 99'!C11,'STN 100A'!C11,'STN 100'!C11,'STN 101'!C11,'STN 102'!C11,'STN 103'!C11,'STN 104'!C11,'STN 105'!C11,'STN 106'!C11,'STN 107'!C11,'STN 108'!C11,'STN 111A'!C11,'STN 111'!C11,'STN 112'!C11,'STN 113'!C11,'STN 120'!C11) -> 35.625 | D11: =C11/$C$17 -> 0.077487765 | N11: 2.0-3.0 | O11: =AVERAGE('STN 99'!O11,'STN 100A'!O11,'STN 100'!O11,'STN 101'!O11,'STN 102'!O11,'STN 103'!O11,'STN 104'!O11,'STN 105'!O11,'STN 106'!O11,'STN 107'!O11,'STN 108'!O11,'STN 111A'!O11,'STN 111'!O11,'STN 112'!O11,'STN 113'!O11,'STN 120'!O11) -> 422.125 | P11: =O11-O10 -> 44.25 | Q11: =P11/$O$15 -> 0.083206017
B12: Medium Truck | C12: =AVERAGE('STN 99'!C12,'STN 100A'!C12,'STN 100'!C12,'STN 101'!C12,'STN 102'!C12,'STN 103'!C12,'STN 104'!C12,'STN 105'!C12,'STN 106'!C12,'STN 107'!C12,'STN 108'!C12,'STN 111A'!C12,'STN 111'!C12,'STN 112'!C12,'STN 113'!C12,'STN 120'!C12) -> 52.6875 | D12: =C12/$C$17 -> 0.11460033 | N12: 3.0-5.0 | O12: =AVERAGE('STN 99'!O12,'STN 100A'!O12,'STN 100'!O12,'STN 101'!O12,'STN 102'!O12,'STN 103'!O12,'STN 104'!O12,'STN 105'!O12,'STN 106'!O12,'STN 107'!O12,'STN 108'!O12,'STN 111A'!O12,'STN 111'!O12,'STN 112'!O12,'STN 113'!O12,'STN 120'!O12) -> 471.625 | P12: =O12-O11 -> 49.5 | Q12: =P12/$O$15 -> 0.093077917
B13: Heavy truck | C13: =AVERAGE('STN 99'!C13,'STN 100A'!C13,'STN 100'!C13,'STN 101'!C13,'STN 102'!C13,'STN 103'!C13,'STN 104'!C13,'STN 105'!C13,'STN 106'!C13,'STN 107'!C13,'STN 108'!C13,'STN 111A'!C13,'STN 111'!C13,'STN 112'!C13,'STN 113'!C13,'STN 120'!C13) -> 26.875 | D13: =C13/$C$17 -> 0.058455682 | N13: 5.0-7.5 | O13: =AVERAGE('STN 99'!O13,'STN 100A'!O13,'STN 100'!O13,'STN 101'!O13,'STN 102'!O13,'STN 103'!O13,'STN 104'!O13,'STN 105'!O13,'STN 106'!O13,'STN 107'!O13,'STN 108'!O13,'STN 111A'!O13,'STN 111'!O13,'STN 112'!O13,'STN 113'!O13,'STN 120'!O13) -> 504.4375 | P13: =O13-O12 -> 32.8125 | Q13: =P13/$O$15 -> 0.061699377
B14: Truck Trailer | C14: =AVERAGE('STN 99'!C14,'STN 100A'!C14,'STN 100'!C14,'STN 101'!C14,'STN 102'!C14,'STN 103'!C14,'STN 104'!C14,'STN 105'!C14,'STN 106'!C14,'STN 107'!C14,'STN 108'!C14,'STN 111A'!C14,'STN 111'!C14,'STN 112'!C14,'STN 113'!C14,'STN 120'!C14) -> 6.875 | D14: =C14/$C$17 -> 0.014953779 | N14: 7.5-10 | O14: =AVERAGE('STN 99'!O14,'STN 100A'!O14,'STN 100'!O14,'STN 101'!O14,'STN 102'!O14,'STN 103'!O14,'STN 104'!O14,'STN 105'!O14,'STN 106'!O14,'STN 107'!O14,'STN 108'!O14,'STN 111A'!O14,'STN 111'!O14,'STN 112'!O14,'STN 113'!O14,'STN 120'!O14) -> 523.875 | P14: =O14-O13 -> 19.4375 | Q14: =P14/$O$15 -> 0.036549536
B15: Motor cycles | C15: =AVERAGE('STN 99'!C15,'STN 100A'!C15,'STN 100'!C15,'STN 101'!C15,'STN 102'!C15,'STN 103'!C15,'STN 104'!C15,'STN 105'!C15,'STN 106'!C15,'STN 107'!C15,'STN 108'!C15,'STN 111A'!C15,'STN 111'!C15,'STN 112'!C15,'STN 113'!C15,'STN 120'!C15) -> 17.625 | D15: =C15/$C$17 -> 0.038336052 | N15: Over 10 | O15: =AVERAGE('STN 99'!O15,'STN 100A'!O15,'STN 100'!O15,'STN 101'!O15,'STN 102'!O15,'STN 103'!O15,'STN 104'!O15,'STN 105'!O15,'STN 106'!O15,'STN 107'!O15,'STN 108'!O15,'STN 111A'!O15,'STN 111'!O15,'STN 112'!O15,'STN 113'!O15,'STN 120'!O15) -> 531.8125 | P15: =O15-O14 -> 7.9375 | Q15: =P15/$O$15 -> 0.014925373
B16: Tractors | C16: =AVERAGE('STN 99'!C16,'STN 100A'!C16,'STN 100'!C16,'STN 101'!C16,'STN 102'!C16,'STN 103'!C16,'STN 104'!C16,'STN 105'!C16,'STN 106'!C16,'STN 107'!C16,'STN 108'!C16,'STN 111A'!C16,'STN 111'!C16,'STN 112'!C16,'STN 113'!C16,'STN 120'!C16) -> 6.3125 | D16: =C16/$C$17 -> 0.013730288
B17: Average | C17: =SUM(C5:C16) -> 459.75
N21: Trip Frequency
B22: Journey Purpose | N22: Trip Frequency | O22: No of Vehicles | P22: No. of Vehicles, %
B23: Purpose | C23: Respondents | D23: Percent | N23: More than 2 times every day | O23: =AVERAGE('STN 99'!O23,'STN 100A'!O23,'STN 100'!O23,'STN 101'!O23,'STN 102'!O23,'STN 103'!O23,'STN 104'!O23,'STN 105'!O23,'STN 106'!O23,'STN 107'!O23,'STN 108'!O23,'STN 111A'!O23,'STN 111'!O23,'STN 112'!O23,'STN 113'!O23,'STN 120'!O23) -> 151.5 | P23: =O23/$O$29 -> 0.26339237
B24: Home-Work | C24: =AVERAGE('STN 99'!C24,'STN 100A'!C24,'STN 100'!C24,'STN 101'!C24,'STN 102'!C24,'STN 103'!C24,'STN 104'!C24,'STN 105'!C24,'STN 106'!C24,'STN 107'!C24,'STN 108'!C24,'STN 111A'!C24,'STN 111'!C24,'STN 112'!C24,'STN 113'!C24,'STN 120'!C24) -> 68.875 | D24: =C24/$C$29 -> 0.14980968 | N24: Daily (Up and Down) | O24: =AVERAGE('STN 99'!O24,'STN 100A'!O24,'STN 100'!O24,'STN 101'!O24,'STN 102'!O24,'STN 103'!O24,'STN 104'!O24,'STN 105'!O24,'STN 106'!O24,'STN 107'!O24,'STN 108'!O24,'STN 111A'!O24,'STN 111'!O24,'STN 112'!O24,'STN 113'!O24,'STN 120'!O24) -> 195.375 | P24: =O24/$O$29 -> 0.33967185
B25: Home-Study | C25: =AVERAGE('STN 99'!C25,'STN 100A'!C25,'STN 100'!C25,'STN 101'!C25,'STN 102'!C25,'STN 103'!C25,'STN 104'!C25,'STN 105'!C25,'STN 106'!C25,'STN 107'!C25,'STN 108'!C25,'STN 111A'!C25,'STN 111'!C25,'STN 112'!C25,'STN 113'!C25,'STN 120'!C25) -> 4 | D25: =C25/$C$29 -> 0.0087003806 | N25: 2/3 times a week | O25: =AVERAGE('STN 99'!O25,'STN 100A'!O25,'STN 100'!O25,'STN 101'!O25,'STN 102'!O25,'STN 103'!O25,'STN 104'!O25,'STN 105'!O25,'STN 106'!O25,'STN 107'!O25,'STN 108'!O25,'STN 111A'!O25,'STN 111'!O25,'STN 112'!O25,'STN 113'!O25,'STN 120'!O25) -> 103.875 | P25: =O25/$O$29 -> 0.18059328
B26: Work-Home | C26: =AVERAGE('STN 99'!C26,'STN 100A'!C26,'STN 100'!C26,'STN 101'!C26,'STN 102'!C26,'STN 103'!C26,'STN 104'!C26,'STN 105'!C26,'STN 106'!C26,'STN 107'!C26,'STN 108'!C26,'STN 111A'!C26,'STN 111'!C26,'STN 112'!C26,'STN 113'!C26,'STN 120'!C26) -> 31.0625 | D26: =C26/$C$29 -> 0.067563893 | N26: Once a week | O26: =AVERAGE('STN 99'!O26,'STN 100A'!O26,'STN 100'!O26,'STN 101'!O26,'STN 102'!O26,'STN 103'!O26,'STN 104'!O26,'STN 105'!O26,'STN 106'!O26,'STN 107'!O26,'STN 108'!O26,'STN 111A'!O26,'STN 111'!O26,'STN 112'!O26,'STN 113'!O26,'STN 120'!O26) -> 70.0625 | P26: =O26/$O$29 -> 0.12180811
B27: Work-Work | C27: =AVERAGE('STN 99'!C27,'STN 100A'!C27,'STN 100'!C27,'STN 101'!C27,'STN 102'!C27,'STN 103'!C27,'STN 104'!C27,'STN 105'!C27,'STN 106'!C27,'STN 107'!C27,'STN 108'!C27,'STN 111A'!C27,'STN 111'!C27,'STN 112'!C27,'STN 113'!C27,'STN 120'!C27) -> 111.8125 | D27: =C27/$C$29 -> 0.24320283 | N27: Once a month | O27: =AVERAGE('STN 99'!O27,'STN 100A'!O27,'STN 100'!O27,'STN 101'!O27,'STN 102'!O27,'STN 103'!O27,'STN 104'!O27,'STN 105'!O27,'STN 106'!O27,'STN 107'!O27,'STN 108'!O27,'STN 111A'!O27,'STN 111'!O27,'STN 112'!O27,'STN 113'!O27,'STN 120'!O27) -> 20.3125 | P27: =O27/$O$29 -> 0.035314571
B28: Others | C28: =AVERAGE('STN 99'!C28,'STN 100A'!C28,'STN 100'!C28,'STN 101'!C28,'STN 102'!C28,'STN 103'!C28,'STN 104'!C28,'STN 105'!C28,'STN 106'!C28,'STN 107'!C28,'STN 108'!C28,'STN 111A'!C28,'STN 111'!C28,'STN 112'!C28,'STN 113'!C28,'STN 120'!C28) -> 244 | D28: =C28/$C$29 -> 0.53072322 | N28: Once in a while | O28: =AVERAGE('STN 99'!O28,'STN 100A'!O28,'STN 100'!O28,'STN 101'!O28,'STN 102'!O28,'STN 103'!O28,'STN 104'!O28,'STN 105'!O28,'STN 106'!O28,'STN 107'!O28,'STN 108'!O28,'STN 111A'!O28,'STN 111'!O28,'STN 112'!O28,'STN 113'!O28,'STN 120'!O28) -> 34.0625 | P28: =O28/$O$29 -> 0.05921982
B29: Average | C29: =C17 -> 459.75 | O29: =SUM(O23:O28) -> 575.1875
B40: Expressway Use
B41: Response | C41: Number | D41: Percent
B42: Yes | C42: =AVERAGE('STN 99'!C42,'STN 100A'!C42,'STN 100'!C42,'STN 101'!C42,'STN 102'!C42,'STN 103'!C42,'STN 104'!C42,'STN 105'!C42,'STN 106'!C42,'STN 107'!C42,'STN 108'!C42,'STN 111A'!C42,'STN 111'!C42,'STN 112'!C42,'STN 113'!C42,'STN 120'!C42) -> 102.5 | D42: =C42/$C$44 -> 0.22294725 | N42: Vehicle Types | O42: Average Occupancy
B43: No | C43: =AVERAGE('STN 99'!C43,'STN 100A'!C43,'STN 100'!C43,'STN 101'!C43,'STN 102'!C43,'STN 103'!C43,'STN 104'!C43,'STN 105'!C43,'STN 106'!C43,'STN 107'!C43,'STN 108'!C43,'STN 111A'!C43,'STN 111'!C43,'STN 112'!C43,'STN 113'!C43,'STN 120'!C43) -> 357.375 | D43: =C43/$C$44 -> 0.77732463 | N43: Car | O43: 2.7058824
B44: Total | C44: =C29 -> 459.75 | N44: Station Wagon | O44: 2.3529412
N45: Pickups | O45: 3.3529412
N46: Minibus, matatu | O46: 8.6470588
N47: Medium bus | O47: 19.411765
N48: Large Bus | O48: 20.705882
N49: Light Truck | O49: 2.7058824
N50: Medium Truck | O50: 2.8235294
N51: Heavy truck | O51: 2.2352941
N52: Truck Trailer | O52: 1.4705882
N53: Motor cycles | O53: 1.3529412
N54: Tractors | O54: 1
B58: Willingness to Pay
...

Sheet STN 99
B1: STN99 OD ANALYSIS
B3: Vehicle OD Sample Proportions | N3: Average Journey Time
B4: Vehicle Types | C4: OD Sample | D4: OD Sample, % | N4: Journey Time Range (Hrs) | O4: Cummu-lative | P4: No of Vehicles | Q4: No. of Vehicles, %
B5: Car | C5: 132 | D5: =C5/$C$17 -> 0.26774848 | N5: 0-0.25 | O5: 42 | P5: =O5 -> 42 | Q5: =P5/$O$15 -> 0.099526066
B6: Station Wagon | C6: 9 | D6: =C6/$C$17 -> 0.018255578 | N6: 0.25-0.50 | O6: 97 | P6: =O6-O5 -> 55 | Q6: =P6/$O$15 -> 0.13033175
B7: Pickups | C7: 11 | D7: =C7/$C$17 -> 0.022312373 | N7: 0.50-0.75 | O7: 115 | P7: =O7-O6 -> 18 | Q7: =P7/$O$15 -> 0.042654028
B8: Minibus, matatu | C8: 89 | D8: =C8/$C$17 -> 0.18052738 | N8: 0.75-1.00 | O8: 184 | P8: =O8-O7 -> 69 | Q8: =P8/$O$15 -> 0.16350711
B9: Medium bus | C9: 2 | D9: =C9/$C$17 -> 0.0040567951 | N9: 1.00-1.50 | O9: 206 | P9: =O9-O8 -> 22 | Q9: =P9/$O$15 -> 0.052132701
B10: Large Bus | C10: 4 | D10: =C10/$C$17 -> 0.0081135903 | N10: 1.5-2.0 | O10: 240 | P10: =O10-O9 -> 34 | Q10: =P10/$O$15 -> 0.08056872
B11: Light Truck | C11: 37 | D11: =C11/$C$17 -> 0.07505071 | N11: 2.0-3.0 | O11: 264 | P11: =O11-O10 -> 24 | Q11: =P11/$O$15 -> 0.056872038
B12: Medium Truck | C12: 53 | D12: =C12/$C$17 -> 0.10750507 | N12: 3.0-5.0 | O12: 372 | P12: =O12-O11 -> 108 | Q12: =P12/$O$15 -> 0.25592417
B13: Heavy truck | C13: 86 | D13: =C13/$C$17 -> 0.17444219 | N13: 5.0-7.5 | O13: 399 | P13: =O13-O12 -> 27 | Q13: =P13/$O$15 -> 0.063981043
B14: Truck Trailer | C14: 12 | D14: =C14/$C$17 -> 0.024340771 | N14: 7.5-10 | O14: 411 | P14: =O14-O13 -> 12 | Q14: =P14/$O$15 -> 0.028436019
B15: Motor cycles | C15: 56 | D15: =C15/$C$17 -> 0.11359026 | N15: Over 10 | O15: 422 | P15: =O15-O14 -> 11 | Q15: =P15/$O$15 -> 0.026066351
B16: Tractors | C16: 2 | D16: =C16/$C$17 -> 0.0040567951
B17: Total | C17: =SUM(C5:C16) -> 493
B18: ADT | C18: 2335.0952 | D18: =C17/C18 -> 0.21112629
N21: Trip Frequency
B22: Journey Purpose | N22: Trip Frequency | O22: No of Vehicles | P22: No. of Vehicles, %
B23: Purpose | C23: Respondents | D23: Percent | N23: More than 2 times every day | O23: 74 | P23: =O23/$O$29 -> 0.14919355
B24: Home-Work | C24: 32 | D24: =C24/$C$29 -> 0.064908722 | N24: Daily (Up and Down) | O24: 203 | P24: =O24/$O$29 -> 0.40927419
B25: Home-Study | C25: 0 | D25: =C25/$C$29 -> 0 | N25: 2/3 times a week | O25: 83 | P25: =O25/$O$29 -> 0.16733871
B26: Work-Home | C26: 30 | D26: =C26/$C$29 -> 0.060851927 | N26: Once a week | O26: 87 | P26: =O26/$O$29 -> 0.17540323
B27: Work-Work | C27: 161 | D27: =C27/$C$29 -> 0.32657201 | N27: Once a month | O27: 25 | P27: =O27/$O$29 -> 0.050403226
B28: Others | C28: 270 | D28: =C28/$C$29 -> 0.54766734 | N28: Once in a while | O28: 24 | P28: =O28/$O$29 -> 0.048387097
B29: Total | C29: =C17 -> 493 | N29: Total | O29: =SUM(O23:O28) -> 496
B40: Expressway Use
B41: Response | C41: Number | D41: Percent
B42: Yes | C42: 100 | D42: =C42/$C$44 -> 0.20283976 | N42: Vehicle Types | O42: Average Occupancy
B43: No | C43: 393 | D43: =C43/$C$44 -> 0.79716024 | N43: Car | O43: 3
B44: Total | C44: =C29 -> 493 | N44: Station Wagon | O44: 2
N45: Pickups | O45: 2
N46: Minibus, matatu | O46: 9
N47: Medium bus | O47: 35
N48: Large Bus | O48: 32
N49: Light Truck | O49: 2
N50: Medium Truck | O50: 2
N51: Heavy truck | O51: 2
N52: Truck Trailer | O52: 2
N53: Motor cycles | O53: 1
...

Sheet STN 100A
B1: STN100A OD ANALYSIS
B3: Vehicle OD Sample Proportions | N3: Average Journey Time
B4: Vehicle Types | C4: OD Sample | D4: OD Sample, % | N4: Journey Time Range (Hrs) | O4: Cummu-lative | P4: No of Vehicles | Q4: No. of Vehicles, %
B5: Car | C5: 152 | D5: =C5/$C$17 -> 0.42105263 | N5: 0-0.25 | O5: 89 | P5: =O5 -> 89 | Q5: =P5/$O$15 -> 0.26176471
B6: Station Wagon | C6: 34 | D6: =C6/$C$17 -> 0.094182825 | N6: 0.25-0.50 | O6: 209 | P6: =O6-O5 -> 120 | Q6: =P6/$O$15 -> 0.35294118
B7: Pickups | C7: 23 | D7: =C7/$C$17 -> 0.063711911 | N7: 0.50-0.75 | O7: 221 | P7: =O7-O6 -> 12 | Q7: =P7/$O$15 -> 0.035294118
B8: Minibus, matatu | C8: 13 | D8: =C8/$C$17 -> 0.03601108 | N8: 0.75-1.00 | O8: 273 | P8: =O8-O7 -> 52 | Q8: =P8/$O$15 -> 0.15294118
B9: Medium bus | C9: 1 | D9: =C9/$C$17 -> 0.0027700831 | N9: 1.00-1.50 | O9: 293 | P9: =O9-O8 -> 20 | Q9: =P9/$O$15 -> 0.058823529
B10: Large Bus | C10: 0 | D10: =C10/$C$17 -> 0 | N10: 1.5-2.0 | O10: 319 | P10: =O10-O9 -> 26 | Q10: =P10/$O$15 -> 0.076470588
B11: Light Truck | C11: 36 | D11: =C11/$C$17 -> 0.099722992 | N11: 2.0-3.0 | O11: 325 | P11: =O11-O10 -> 6 | Q11: =P11/$O$15 -> 0.017647059
B12: Medium Truck | C12: 35 | D12: =C12/$C$17 -> 0.096952909 | N12: 3.0-5.0 | O12: 335 | P12: =O12-O11 -> 10 | Q12: =P12/$O$15 -> 0.029411765
B13: Heavy truck | C13: 2 | D13: =C13/$C$17 -> 0.0055401662 | N13: 5.0-7.5 | O13: 339 | P13: =O13-O12 -> 4 | Q13: =P13/$O$15 -> 0.011764706
B14: Truck Trailer | C14: 1 | D14: =C14/$C$17 -> 0.0027700831 | N14: 7.5-10 | O14: 339 | P14: =O14-O13 -> 0 | Q14: =P14/$O$15 -> 0
B15: Motor cycles | C15: 64 | D15: =C15/$C$17 -> 0.17728532 | N15: Over 10 | O15: 340 | P15: =O15-O14 -> 1 | Q15: =P15/$O$15 -> 0.0029411765
B16: Tractors | C16: 0 | D16: =C16/$C$17 -> 0
B17: Total | C17: =SUM(C5:C16) -> 361
B18: ADT | C18: 6994.4286 | D18: =C17/C18 -> 0.051612508
N21: Trip Frequency
B22: Journey Purpose | N22: Trip Frequency | O22: No of Vehicles | P22: No. of Vehicles, %
B23: Purpose | C23: Respondents | D23: Percent | N23: More than 2 times every day | O23: 74 | P23: =O23/$O$29 -> 0.2084507
B24: Home-Work | C24: 52 | D24: =C24/$C$29 -> 0.14404432 | N24: Daily (Up and Down) | O24: 129 | P24: =O24/$O$29 -> 0.36338028
B25: Home-Study | C25: 18 | D25: =C25/$C$29 -> 0.049861496 | N25: 2/3 times a week | O25: 84 | P25: =O25/$O$29 -> 0.23661972
B26: Work-Home | C26: 69 | D26: =C26/$C$29 -> 0.19113573 | N26: Once a week | O26: 44 | P26: =O26/$O$29 -> 0.12394366
B27: Work-Work | C27: 47 | D27: =C27/$C$29 -> 0.13019391 | N27: Once a month | O27: 9 | P27: =O27/$O$29 -> 0.025352113
B28: Others | C28: 175 | D28: =C28/$C$29 -> 0.48476454 | N28: Once in a while | O28: 15 | P28: =O28/$O$29 -> 0.042253521
B29: Total | C29: =C17 -> 361 | N29: Total | O29: =SUM(O23:O28) -> 355
B40: Expressway Use
B41: Response | C41: Number | D41: Percent
B42: Yes | C42: 361 | D42: =C42/$C$44 -> 1 | N42: Vehicle Types | O42: Average Occupancy
B43: No | C43: 0 | D43: =C43/$C$44 -> 0 | N43: Car | O43: 1
B44: Total | C44: =C29 -> 361 | N44: Station Wagon | O44: 2
N45: Pickups | O45: 2
N46: Minibus, matatu | O46: 7
N47: Medium bus | O47: 6
N48: Large Bus | O48: 2
N49: Light Truck | O49: 2
N50: Medium Truck | O50: 2
N51: Heavy truck | O51: 3
N52: Truck Trailer | O52: 0
N53: Motor cycles | O53: 0
...

Sheet STN 100
B1: STN100 OD ANALYSIS
B3: Vehicle OD Sample Proportions | N3: Average Journey Time
B4: Vehicle Types | C4: OD Sample | D4: OD Sample, % | N4: Journey Time Range (Hrs) | O4: Cummu-lative | P4: No of Vehicles | Q4: No. of Vehicles, %
B5: Car | C5: 71 | D5: =C5/$C$17 -> 0.22327044 | N5: 0-0.25 | O5: 5 | P5: =O5 -> 5 | Q5: =P5/$O$15 -> 0.017985612
B6: Station Wagon | C6: 34 | D6: =C6/$C$17 -> 0.10691824 | N6: 0.25-0.50 | O6: 21 | P6: =O6-O5 -> 16 | Q6: =P6/$O$15 -> 0.057553957
B7: Pickups | C7: 11 | D7: =C7/$C$17 -> 0.034591195 | N7: 0.50-0.75 | O7: 31 | P7: =O7-O6 -> 10 | Q7: =P7/$O$15 -> 0.035971223
B8: Minibus, matatu | C8: 72 | D8: =C8/$C$17 -> 0.22641509 | N8: 0.75-1.00 | O8: 58 | P8: =O8-O7 -> 27 | Q8: =P8/$O$15 -> 0.097122302
B9: Medium bus | C9: 4 | D9: =C9/$C$17 -> 0.012578616 | N9: 1.00-1.50 | O9: 78 | P9: =O9-O8 -> 20 | Q9: =P9/$O$15 -> 0.071942446
B10: Large Bus | C10: 14 | D10: =C10/$C$17 -> 0.044025157 | N10: 1.5-2.0 | O10: 129 | P10: =O10-O9 -> 51 | Q10: =P10/$O$15 -> 0.18345324
B11: Light Truck | C11: 31 | D11: =C11/$C$17 -> 0.097484277 | N11: 2.0-3.0 | O11: 188 | P11: =O11-O10 -> 59 | Q11: =P11/$O$15 -> 0.21223022
B12: Medium Truck | C12: 24 | D12: =C12/$C$17 -> 0.075471698 | N12: 3.0-5.0 | O12: 225 | P12: =O12-O11 -> 37 | Q12: =P12/$O$15 -> 0.13309353
B13: Heavy truck | C13: 37 | D13: =C13/$C$17 -> 0.1163522 | N13: 5.0-7.5 | O13: 244 | P13: =O13-O12 -> 19 | Q13: =P13/$O$15 -> 0.068345324
B14: Truck Trailer | C14: 15 | D14: =C14/$C$17 -> 0.047169811 | N14: 7.5-10 | O14: 273 | P14: =O14-O13 -> 29 | Q14: =P14/$O$15 -> 0.10431655
B15: Motor cycles | C15: 5 | D15: =C15/$C$17 -> 0.01572327 | N15: Over 10 | O15: 278 | P15: =O15-O14 -> 5 | Q15: =P15/$O$15 -> 0.017985612
B16: Tractors | C16: 0 | D16: =C16/$C$17 -> 0
B17: Total | C17: =SUM(C5:C16) -> 318
B18: ADT | C18: 4916.9524 | D18: =C17/C18 -> 0.064674208
N21: Trip Frequency
B22: Journey Purpose | N22: Trip Frequency | O22: No of Vehicles | P22: No. of Vehicles, %
B23: Purpose | C23: Respondents | D23: Percent | N23: More than 2 times every day | O23: 41 | P23: =O23/$O$29 -> 0.13311688
B24: Home-Work | C24: 32 | D24: =C24/$C$29 -> 0.10062893 | N24: Daily (Up and Down) | O24: 139 | P24: =O24/$O$29 -> 0.4512987
B25: Home-Study | C25: 4 | D25: =C25/$C$29 -> 0.012578616 | N25: 2/3 times a week | O25: 56 | P25: =O25/$O$29 -> 0.18181818
B26: Work-Home | C26: 35 | D26: =C26/$C$29 -> 0.11006289 | N26: Once a week | O26: 44 | P26: =O26/$O$29 -> 0.14285714
B27: Work-Work | C27: 70 | D27: =C27/$C$29 -> 0.22012579 | N27: Once a month | O27: 10 | P27: =O27/$O$29 -> 0.032467532
B28: Others | C28: 177 | D28: =C28/$C$29 -> 0.55660377 | N28: Once in a while | O28: 18 | P28: =O28/$O$29 -> 0.058441558
B29: Total | C29: =C17 -> 318 | N29: Total | O29: =SUM(O23:O28) -> 308
B40: Expressway Use
B41: Response | C41: Number | D41: Percent
B42: Yes | C42: 145 | D42: =C42/$C$44 -> 0.45597484
B43: No | C43: 173 | D43: =C43/$C$44 -> 0.54402516 | N43: Vehicle Types | O43: Average Occupancy
B44: Total | C44: =C29 -> 318 | N44: Car | O44: 2
N45: Station Wagon | O45: 3
N46: Pickups | O46: 5
N47: Minibus, matatu | O47: 14
N48: Medium bus | O48: 25
N49: Large Bus | O49: 60
N50: Light Truck | O50: 2
N51: Medium Truck | O51: 2
N52: Heavy truck | O52: 2
N53: Truck Trailer | O53: 2
...

Sheet STN 101
B1: STN101 OD ANALYSIS
B3: Vehicle OD Sample Proportions | N3: Average Journey Time
B4: Vehicle Types | C4: OD Sample | D4: OD Sample, % | N4: Journey Time Range (Hrs) | O4: Cummu-lative | P4: No of Vehicles | Q4: No. of Vehicles, %
B5: Car | C5: 82 | D5: =C5/$C$17 -> 0.21025641 | N5: 0-0.25 | O5: 31 | P5: =O5 -> 31 | Q5: =P5/$O$15 -> 0.072261072
B6: Station Wagon | C6: 103 | D6: =C6/$C$17 -> 0.26410256 | N6: 0.25-0.50 | O6: 79 | P6: =O6-O5 -> 48 | Q6: =P6/$O$15 -> 0.11188811
B7: Pickups | C7: 54 | D7: =C7/$C$17 -> 0.13846154 | N7: 0.50-0.75 | O7: 84 | P7: =O7-O6 -> 5 | Q7: =P7/$O$15 -> 0.011655012
B8: Minibus, matatu | C8: 40 | D8: =C8/$C$17 -> 0.1025641 | N8: 0.75-1.00 | O8: 228 | P8: =O8-O7 -> 144 | Q8: =P8/$O$15 -> 0.33566434
B9: Medium bus | C9: 7 | D9: =C9/$C$17 -> 0.017948718 | N9: 1.00-1.50 | O9: 271 | P9: =O9-O8 -> 43 | Q9: =P9/$O$15 -> 0.1002331
B10: Large Bus | C10: 59 | D10: =C10/$C$17 -> 0.15128205 | N10: 1.5-2.0 | O10: 302 | P10: =O10-O9 -> 31 | Q10: =P10/$O$15 -> 0.072261072
B11: Light Truck | C11: 23 | D11: =C11/$C$17 -> 0.058974359 | N11: 2.0-3.0 | O11: 346 | P11: =O11-O10 -> 44 | Q11: =P11/$O$15 -> 0.1025641
B12: Medium Truck | C12: 9 | D12: =C12/$C$17 -> 0.023076923 | N12: 3.0-5.0 | O12: 391 | P12: =O12-O11 -> 45 | Q12: =P12/$O$15 -> 0.1048951
B13: Heavy truck | C13: 5 | D13: =C13/$C$17 -> 0.012820513 | N13: 5.0-7.5 | O13: 418 | P13: =O13-O12 -> 27 | Q13: =P13/$O$15 -> 0.062937063
B14: Truck Trailer | C14: 2 | D14: =C14/$C$17 -> 0.0051282051 | N14: 7.5-10 | O14: 426 | P14: =O14-O13 -> 8 | Q14: =P14/$O$15 -> 0.018648019
B15: Motor cycles | C15: 0 | D15: =C15/$C$17 -> 0 | N15: Over 10 | O15: 429 | P15: =O15-O14 -> 3 | Q15: =P15/$O$15 -> 0.006993007
B16: Tractors | C16: 6 | D16: =C16/$C$17 -> 0.015384615
B17: Total | C17: =SUM(C5:C16) -> 390
B18: ADT | C18: 9674.7143 | D18: =C17/C18 -> 0.040311268
N21: Trip Frequency
B22: Journey Purpose | N22: Trip Frequency | O22: No of Vehicles | P22: No. of Vehicles, %
B23: Purpose | C23: Respondents | D23: Percent | N23: More than 2 times every day | O23: 174 | P23: =O23/$O$29 -> 0.38580931
B24: Home-Work | C24: 0 | D24: =C24/$C$29 -> 0 | N24: Daily (Up and Down) | O24: 122 | P24: =O24/$O$29 -> 0.27050998
B25: Home-Study | C25: 0 | D25: =C25/$C$29 -> 0 | N25: 2/3 times a week | O25: 55 | P25: =O25/$O$29 -> 0.12195122
B26: Work-Home | C26: 0 | D26: =C26/$C$29 -> 0 | N26: Once a week | O26: 43 | P26: =O26/$O$29 -> 0.095343681
B27: Work-Work | C27: 0 | D27: =C27/$C$29 -> 0 | N27: Once a month | O27: 16 | P27: =O27/$O$29 -> 0.035476718
B28: Others | C28: 390 | D28: =C28/$C$29 -> 1 | N28: Once in a while | O28: 41 | P28: =O28/$O$29 -> 0.090909091
B29: Total | C29: =C17 -> 390 | N29: Total | O29: =SUM(O23:O28) -> 451
B40: Expressway Use
B41: Response | C41: Number | D41: Percent
B42: Yes | C42: 43 | D42: =C42/$C$44 -> 0.11025641
B43: No | C43: 347 | D43: =C43/$C$44 -> 0.88974359
B44: Total | C44: =C29 -> 390 | N44: Vehicle Types | O44: Average Occupancy
N45: Car | O45: 4
N46: Station Wagon | O46: 2
N47: Pickups | O47: 2
N48: Minibus, matatu | O48: 12
N49: Medium bus | O49: 14
N50: Large Bus | O50: 15
N51: Light Truck | O51: 3
N52: Medium Truck | O52: 2
N53: Heavy truck | O53: 3
...

Sheet STN 102
B1: STN102 OD ANALYSIS
B3: Vehicle OD Sample Proportions | N3: Average Journey Time
B4: Vehicle Types | C4: OD Sample | D4: OD Sample, % | N4: Journey Time Range (Hrs) | O4: Cummu-lative | P4: No of Vehicles | Q4: No. of Vehicles, %
B5: Car | C5: 149 | D5: =C5/$C$17 -> 0.43695015 | N5: 0-0.25 | O5: 5 | P5: =O5 -> 5 | Q5: =P5/$O$15 -> 0.014705882
B6: Station Wagon | C6: 30 | D6: =C6/$C$17 -> 0.08797654 | N6: 0.25-0.50 | O6: 15 | P6: =O6-O5 -> 10 | Q6: =P6/$O$15 -> 0.029411765
B7: Pickups | C7: 13 | D7: =C7/$C$17 -> 0.038123167 | N7: 0.50-0.75 | O7: 32 | P7: =O7-O6 -> 17 | Q7: =P7/$O$15 -> 0.05
B8: Minibus, matatu | C8: 56 | D8: =C8/$C$17 -> 0.16422287 | N8: 0.75-1.00 | O8: 162 | P8: =O8-O7 -> 130 | Q8: =P8/$O$15 -> 0.38235294
B9: Medium bus | C9: 6 | D9: =C9/$C$17 -> 0.017595308 | N9: 1.00-1.50 | O9: 172 | P9: =O9-O8 -> 10 | Q9: =P9/$O$15 -> 0.029411765
B10: Large Bus | C10: 7 | D10: =C10/$C$17 -> 0.020527859 | N10: 1.5-2.0 | O10: 244 | P10: =O10-O9 -> 72 | Q10: =P10/$O$15 -> 0.21176471
B11: Light Truck | C11: 22 | D11: =C11/$C$17 -> 0.064516129 | N11: 2.0-3.0 | O11: 281 | P11: =O11-O10 -> 37 | Q11: =P11/$O$15 -> 0.10882353
B12: Medium Truck | C12: 25 | D12: =C12/$C$17 -> 0.073313783 | N12: 3.0-5.0 | O12: 319 | P12: =O12-O11 -> 38 | Q12: =P12/$O$15 -> 0.11176471
B13: Heavy truck | C13: 14 | D13: =C13/$C$17 -> 0.041055718 | N13: 5.0-7.5 | O13: 328 | P13: =O13-O12 -> 9 | Q13: =P13/$O$15 -> 0.026470588
B14: Truck Trailer | C14: 5 | D14: =C14/$C$17 -> 0.014662757 | N14: 7.5-10 | O14: 339 | P14: =O14-O13 -> 11 | Q14: =P14/$O$15 -> 0.032352941
B15: Motor cycles | C15: 14 | D15: =C15/$C$17 -> 0.041055718 | N15: Over 10 | O15: 340 | P15: =O15-O14 -> 1 | Q15: =P15/$O$15 -> 0.0029411765
B16: Tractors | C16: 0 | D16: =C16/$C$17 -> 0
B17: Total | C17: =SUM(C5:C16) -> 341
B18: ADT | C18: 2565.0714 | D18: =C17/C18 -> 0.13293977
N21: Trip Frequency
B22: Journey Purpose | N22: Trip Frequency | O22: No of Vehicles | P22: No. of Vehicles, %
B23: Purpose | C23: Respondents | D23: Percent | N23: More than 2 times every day | O23: 37 | P23: =O23/$O$29 -> 0.11044776
B24: Home-Work | C24: 67 | D24: =C24/$C$29 -> 0.19648094 | N24: Daily (Up and Down) | O24: 155 | P24: =O24/$O$29 -> 0.46268657
B25: Home-Study | C25: 6 | D25: =C25/$C$29 -> 0.017595308 | N25: 2/3 times a week | O25: 73 | P25: =O25/$O$29 -> 0.21791045
B26: Work-Home | C26: 34 | D26: =C26/$C$29 -> 0.099706745 | N26: Once a week | O26: 24 | P26: =O26/$O$29 -> 0.071641791
B27: Work-Work | C27: 137 | D27: =C27/$C$29 -> 0.40175953 | N27: Once a month | O27: 17 | P27: =O27/$O$29 -> 0.050746269
B28: Others | C28: 97 | D28: =C28/$C$29 -> 0.28445748 | N28: Once in a while | O28: 29 | P28: =O28/$O$29 -> 0.086567164
B29: Total | C29: =C17 -> 341 | N29: Total | O29: =SUM(O23:O28) -> 335
B40: Expressway Use
B41: Response | C41: Number | D41: Percent
B42: Yes | C42: 57 | D42: =C42/$C$44 -> 0.16715543 | N42: Vehicle Types | O42: Average Occupancy
B43: No | C43: 284 | D43: =C43/$C$44 -> 0.83284457 | N43: Car | O43: 4
B44: Total | C44: =C29 -> 341 | N44: Station Wagon | O44: 2
N45: Pickups | O45: 2
N46: Minibus, matatu | O46: 12
N47: Medium bus | O47: 27
N48: Large Bus | O48: 26
N49: Light Truck | O49: 4
N50: Medium Truck | O50: 2
N51: Heavy truck | O51: 2
N52: Truck Trailer | O52: 2
N53: Motor cycles | O53: 1
...

Sheet STN 103
B1: STN103 OD ANALYSIS
B3: Vehicle OD Sample Proportions | N3: Average Journey Time
B4: Vehicle Types | C4: OD Sample | D4: OD Sample, % | N4: Journey Time Range (Hrs) | O4: Cummu-lative | P4: No of Vehicles | Q4: No. of Vehicles, %
B5: Car | C5: 120 | D5: =C5/$C$17 -> 0.44117647 | N5: 0-0.25 | O5: 14 | P5: =O5 -> 14 | Q5: =P5/$O$15 -> 0.054474708
B6: Station Wagon | C6: 37 | D6: =C6/$C$17 -> 0.13602941 | N6: 0.25-0.50 | O6: 53 | P6: =O6-O5 -> 39 | Q6: =P6/$O$15 -> 0.15175097
B7: Pickups | C7: 22 | D7: =C7/$C$17 -> 0.080882353 | N7: 0.50-0.75 | O7: 67 | P7: =O7-O6 -> 14 | Q7: =P7/$O$15 -> 0.054474708
B8: Minibus, matatu | C8: 10 | D8: =C8/$C$17 -> 0.036764706 | N8: 0.75-1.00 | O8: 140 | P8: =O8-O7 -> 73 | Q8: =P8/$O$15 -> 0.28404669
B9: Medium bus | C9: 2 | D9: =C9/$C$17 -> 0.0073529412 | N9: 1.00-1.50 | O9: 151 | P9: =O9-O8 -> 11 | Q9: =P9/$O$15 -> 0.042801556
B10: Large Bus | C10: 2 | D10: =C10/$C$17 -> 0.0073529412 | N10: 1.5-2.0 | O10: 191 | P10: =O10-O9 -> 40 | Q10: =P10/$O$15 -> 0.15564202
B11: Light Truck | C11: 15 | D11: =C11/$C$17 -> 0.055147059 | N11: 2.0-3.0 | O11: 215 | P11: =O11-O10 -> 24 | Q11: =P11/$O$15 -> 0.093385214
B12: Medium Truck | C12: 45 | D12: =C12/$C$17 -> 0.16544118 | N12: 3.0-5.0 | O12: 240 | P12: =O12-O11 -> 25 | Q12: =P12/$O$15 -> 0.097276265
B13: Heavy truck | C13: 9 | D13: =C13/$C$17 -> 0.033088235 | N13: 5.0-7.5 | O13: 256 | P13: =O13-O12 -> 16 | Q13: =P13/$O$15 -> 0.062256809
B14: Truck Trailer | C14: 6 | D14: =C14/$C$17 -> 0.022058824 | N14: 7.5-10 | O14: 257 | P14: =O14-O13 -> 1 | Q14: =P14/$O$15 -> 0.0038910506
B15: Motor cycles | C15: 3 | D15: =C15/$C$17 -> 0.011029412 | N15: Over 10 | O15: 257 | P15: =O15-O14 -> 0 | Q15: =P15/$O$15 -> 0
B16: Tractors | C16: 1 | D16: =C16/$C$17 -> 0.0036764706
B17: Total | C17: =SUM(C5:C16) -> 272
B18: ADT | C18: 2143.5 | D18: =C17/C18 -> 0.12689526
N21: Trip Frequency
B22: Journey Purpose | N22: Trip Frequency | O22: No of Vehicles | P22: No. of Vehicles, %
B23: Purpose | C23: Respondents | D23: Percent | N23: More than 2 times every day | O23: 48 | P23: =O23/$O$29 -> 0.18461538
B24: Home-Work | C24: 89 | D24: =C24/$C$29 -> 0.32720588 | N24: Daily (Up and Down) | O24: 67 | P24: =O24/$O$29 -> 0.25769231
B25: Home-Study | C25: 1 | D25: =C25/$C$29 -> 0.0036764706 | N25: 2/3 times a week | O25: 35 | P25: =O25/$O$29 -> 0.13461538
B26: Work-Home | C26: 30 | D26: =C26/$C$29 -> 0.11029412 | N26: Once a week | O26: 56 | P26: =O26/$O$29 -> 0.21538462
B27: Work-Work | C27: 45 | D27: =C27/$C$29 -> 0.16544118 | N27: Once a month | O27: 10 | P27: =O27/$O$29 -> 0.038461538
B28: Others | C28: 107 | D28: =C28/$C$29 -> 0.39338235 | N28: Once in a while | O28: 44 | P28: =O28/$O$29 -> 0.16923077
B29: Total | C29: =C17 -> 272 | N29: Total | O29: =SUM(O23:O28) -> 260
B40: Expressway Use
B41: Response | C41: Number | D41: Percent
B42: Yes | C42: 184 | D42: =C42/$C$44 -> 0.67647059 | N42: Vehicle Types | O42: Average Occupancy
B43: No | C43: 88 | D43: =C43/$C$44 -> 0.32352941 | N43: Car | O43: 3
B44: Total | C44: =C29 -> 272 | N44: Station Wagon | O44: 3
N45: Pickups | O45: 2
N46: Minibus, matatu | O46: 12
N47: Medium bus | O47: 19
N48: Large Bus | O48: 62
N49: Light Truck | O49: 2
N50: Medium Truck | O50: 2
N51: Heavy truck | O51: 2
N52: Truck Trailer | O52: 2
N53: Motor cycles | O53: 2
...

Sheet STN 104
B1: STN104 OD ANALYSIS
B3: Vehicle OD Sample Proportions | N3: Average Journey Time
B4: Vehicle Types | C4: OD Sample | D4: OD Sample, % | N4: Journey Time Range (Hrs) | O4: Cummu-lative | P4: No of Vehicles | Q4: No. of Vehicles, %
B5: Car | C5: 182 | D5: =C5/$C$17 -> 0.26883309 | N5: 0-0.25 | O5: 308 | P5: =O5 -> 308 | Q5: =P5/$O$15 -> 0.21038251
B6: Station Wagon | C6: 109 | D6: =C6/$C$17 -> 0.16100443 | N6: 0.25-0.50 | O6: 827 | P6: =O6-O5 -> 519 | Q6: =P6/$O$15 -> 0.3545082
B7: Pickups | C7: 127 | D7: =C7/$C$17 -> 0.18759232 | N7: 0.50-0.75 | O7: 1019 | P7: =O7-O6 -> 192 | Q7: =P7/$O$15 -> 0.13114754
B8: Minibus, matatu | C8: 4 | D8: =C8/$C$17 -> 0.0059084195 | N8: 0.75-1.00 | O8: 1305 | P8: =O8-O7 -> 286 | Q8: =P8/$O$15 -> 0.19535519
B9: Medium bus | C9: 8 | D9: =C9/$C$17 -> 0.011816839 | N9: 1.00-1.50 | O9: 1347 | P9: =O9-O8 -> 42 | Q9: =P9/$O$15 -> 0.028688525
B10: Large Bus | C10: 51 | D10: =C10/$C$17 -> 0.075332349 | N10: 1.5-2.0 | O10: 1407 | P10: =O10-O9 -> 60 | Q10: =P10/$O$15 -> 0.040983607
B11: Light Truck | C11: 70 | D11: =C11/$C$17 -> 0.10339734 | N11: 2.0-3.0 | O11: 1436 | P11: =O11-O10 -> 29 | Q11: =P11/$O$15 -> 0.019808743
B12: Medium Truck | C12: 45 | D12: =C12/$C$17 -> 0.066469719 | N12: 3.0-5.0 | O12: 1454 | P12: =O12-O11 -> 18 | Q12: =P12/$O$15 -> 0.012295082
B13: Heavy truck | C13: 81 | D13: =C13/$C$17 -> 0.11964549 | N13: 5.0-7.5 | O13: 1461 | P13: =O13-O12 -> 7 | Q13: =P13/$O$15 -> 0.0047814208
B14: Truck Trailer | C14: 0 | D14: =C14/$C$17 -> 0 | N14: 7.5-10 | O14: 1463 | P14: =O14-O13 -> 2 | Q14: =P14/$O$15 -> 0.0013661202
B15: Motor cycles | C15: 0 | D15: =C15/$C$17 -> 0 | N15: Over 10 | O15: 1464 | P15: =O15-O14 -> 1 | Q15: =P15/$O$15 -> 0.00068306011
B16: Tractors | C16: 0 | D16: =C16/$C$17 -> 0
B17: Total | C17: =SUM(C5:C16) -> 677
B18: ADT | C18: 7357.4286 | D18: =C17/C18 -> 0.092015844
N21: Trip Frequency
B22: Journey Purpose | N22: Trip Frequency | O22: No of Vehicles | P22: No. of Vehicles, %
B23: Purpose | C23: Respondents | D23: Percent | N23: More than 2 times every day | O23: 593 | P23: =O23/$O$29 -> 0.37915601
B24: Home-Work | C24: 155 | D24: =C24/$C$29 -> 0.22895126 | N24: Daily (Up and Down) | O24: 543 | P24: =O24/$O$29 -> 0.3471867
B25: Home-Study | C25: 1 | D25: =C25/$C$29 -> 0.0014771049 | N25: 2/3 times a week | O25: 179 | P25: =O25/$O$29 -> 0.11445013
B26: Work-Home | C26: 20 | D26: =C26/$C$29 -> 0.029542097 | N26: Once a week | O26: 104 | P26: =O26/$O$29 -> 0.066496164
B27: Work-Work | C27: 216 | D27: =C27/$C$29 -> 0.31905465 | N27: Once a month | O27: 35 | P27: =O27/$O$29 -> 0.022378517
B28: Others | C28: 285 | D28: =C28/$C$29 -> 0.42097489 | N28: Once in a while | O28: 110 | P28: =O28/$O$29 -> 0.070332481
B29: Total | C29: =C17 -> 677 | N29: Total | O29: =SUM(O23:O28) -> 1564
B40: Expressway Use
B41: Response | C41: Number | D41: Percent
B42: Yes | C42: 0 | D42: =C42/$C$44 -> 0 | N42: Vehicle Types | O42: Average Occupancy
B43: No | C43: 677 | D43: =C43/$C$44 -> 1 | N43: Car | O43: 3
B44: Total | C44: =C29 -> 677 | N44: Station Wagon | O44: 2
N45: Pickups | O45: 9
N46: Minibus, matatu | O46: 2
N47: Medium bus | O47: 29
N48: Large Bus | O48: 3
N49: Light Truck | O49: 3
N50: Medium Truck | O50: 2
N51: Heavy truck | O51: 2
N52: Truck Trailer | O52: 0
N53: Motor cycles | O53: 0
...

Sheet STN 105
B1: STN105 OD ANALYSIS
B3: Vehicle OD Sample Proportions | N3: Average Journey Time
B4: Vehicle Types | C4: OD Sample | D4: OD Sample, % | N4: Journey Time Range (Hrs) | O4: Cummu-lative | P4: No of Vehicles | Q4: No. of Vehicles, %
B5: Car | C5: 81 | D5: =C5/$C$17 -> 0.20199501 | N5: 0-0.25 | O5: 159 | P5: =O5 -> 159 | Q5: =P5/$O$15 -> 0.39949749
B6: Station Wagon | C6: 77 | D6: =C6/$C$17 -> 0.19201995 | N6: 0.25-0.50 | O6: 163 | P6: =O6-O5 -> 4 | Q6: =P6/$O$15 -> 0.010050251
B7: Pickups | C7: 122 | D7: =C7/$C$17 -> 0.3042394 | N7: 0.50-0.75 | O7: 167 | P7: =O7-O6 -> 4 | Q7: =P7/$O$15 -> 0.010050251
B8: Minibus, matatu | C8: 16 | D8: =C8/$C$17 -> 0.039900249 | N8: 0.75-1.00 | O8: 247 | P8: =O8-O7 -> 80 | Q8: =P8/$O$15 -> 0.20100503
B9: Medium bus | C9: 15 | D9: =C9/$C$17 -> 0.037406484 | N9: 1.00-1.50 | O9: 250 | P9: =O9-O8 -> 3 | Q9: =P9/$O$15 -> 0.0075376884
B10: Large Bus | C10: 1 | D10: =C10/$C$17 -> 0.0024937656 | N10: 1.5-2.0 | O10: 291 | P10: =O10-O9 -> 41 | Q10: =P10/$O$15 -> 0.10301508
B11: Light Truck | C11: 0 | D11: =C11/$C$17 -> 0 | N11: 2.0-3.0 | O11: 356 | P11: =O11-O10 -> 65 | Q11: =P11/$O$15 -> 0.16331658
B12: Medium Truck | C12: 38 | D12: =C12/$C$17 -> 0.094763092 | N12: 3.0-5.0 | O12: 386 | P12: =O12-O11 -> 30 | Q12: =P12/$O$15 -> 0.075376884
B13: Heavy truck | C13: 6 | D13: =C13/$C$17 -> 0.014962594 | N13: 5.0-7.5 | O13: 393 | P13: =O13-O12 -> 7 | Q13: =P13/$O$15 -> 0.01758794
B14: Truck Trailer | C14: 0 | D14: =C14/$C$17 -> 0 | N14: 7.5-10 | O14: 398 | P14: =O14-O13 -> 5 | Q14: =P14/$O$15 -> 0.012562814
B15: Motor cycles | C15: 0 | D15: =C15/$C$17 -> 0 | N15: Over 10 | O15: 398 | P15: =O15-O14 -> 0 | Q15: =P15/$O$15 -> 0
B16: Tractors | C16: 45 | D16: =C16/$C$17 -> 0.11221945
B17: Total | C17: =SUM(C5:C16) -> 401
B18: ADT | C18: 1918.4094 | D18: =C17/C18 -> 0.20902733
N21: Trip Frequency
B22: Journey Purpose | N22: Trip Frequency | O22: No of Vehicles | P22: No. of Vehicles, %
B23: Purpose | C23: Respondents | D23: Percent | N23: More than 2 times every day | O23: 46 | P23: =O23/$O$29 -> 0.10823529
B24: Home-Work | C24: 48 | D24: =C24/$C$29 -> 0.11970075 | N24: Daily (Up and Down) | O24: 137 | P24: =O24/$O$29 -> 0.32235294
B25: Home-Study | C25: 22 | D25: =C25/$C$29 -> 0.054862843 | N25: 2/3 times a week | O25: 138 | P25: =O25/$O$29 -> 0.32470588
B26: Work-Home | C26: 47 | D26: =C26/$C$29 -> 0.11720698 | N26: Once a week | O26: 83 | P26: =O26/$O$29 -> 0.19529412
B27: Work-Work | C27: 28 | D27: =C27/$C$29 -> 0.069825436 | N27: Once a month | O27: 14 | P27: =O27/$O$29 -> 0.032941176
B28: Others | C28: 256 | D28: =C28/$C$29 -> 0.63840399 | N28: Once in a while | O28: 7 | P28: =O28/$O$29 -> 0.016470588
B29: Total | C29: =C17 -> 401 | O29: =SUM(O23:O28) -> 425
B40: Expressway Use
B41: Response | C41: Number | D41: Percent
B42: Yes | C42: 0 | D42: =C42/$C$44 -> 0 | N42: Vehicle Types | O42: Average Occupancy
B43: No | C43: 401 | D43: =C43/$C$44 -> 1 | N43: Car | O43: 1
B44: Total | C44: =C29 -> 401 | N44: Station Wagon | O44: 2
N45: Pickups | O45: 2
N46: Minibus, matatu | O46: 3
N47: Medium bus | O47: 2
N48: Large Bus | O48: 1
N49: Light Truck | O49: 0
N50: Medium Truck | O50: 2
N51: Heavy truck | O51: 2
N52: Truck Trailer | O52: 0
N53: Motor cycles | O53: 2
...

Sheet STN 106
B1: STN106 OD ANALYSIS
B3: Vehicle OD Sample Proportions | N3: Average Journey Time
B4: Vehicle Types | C4: OD Sample | D4: OD Sample, % | N4: Journey Time Range (Hrs) | O4: Cummu-lative | P4: No of Vehicles | Q4: No. of Vehicles, %
B5: Car | C5: 176 | D5: =C5/$C$17 -> 0.28805237 | N5: 0-0.25 | O5: 94 | P5: =O5 -> 94 | Q5: =P5/$O$15 -> 0.15771812
B6: Station Wagon | C6: 47 | D6: =C6/$C$17 -> 0.076923077 | N6: 0.25-0.50 | O6: 222 | P6: =O6-O5 -> 128 | Q6: =P6/$O$15 -> 0.2147651
B7: Pickups | C7: 41 | D7: =C7/$C$17 -> 0.06710311 | N7: 0.50-0.75 | O7: 257 | P7: =O7-O6 -> 35 | Q7: =P7/$O$15 -> 0.058724832
B8: Minibus, matatu | C8: 141 | D8: =C8/$C$17 -> 0.23076923 | N8: 0.75-1.00 | O8: 339 | P8: =O8-O7 -> 82 | Q8: =P8/$O$15 -> 0.13758389
B9: Medium bus | C9: 13 | D9: =C9/$C$17 -> 0.021276596 | N9: 1.00-1.50 | O9: 376 | P9: =O9-O8 -> 37 | Q9: =P9/$O$15 -> 0.062080537
B10: Large Bus | C10: 16 | D10: =C10/$C$17 -> 0.026186579 | N10: 1.5-2.0 | O10: 435 | P10: =O10-O9 -> 59 | Q10: =P10/$O$15 -> 0.098993289
B11: Light Truck | C11: 103 | D11: =C11/$C$17 -> 0.1685761 | N11: 2.0-3.0 | O11: 505 | P11: =O11-O10 -> 70 | Q11: =P11/$O$15 -> 0.11744966
B12: Medium Truck | C12: 32 | D12: =C12/$C$17 -> 0.052373159 | N12: 3.0-5.0 | O12: 540 | P12: =O12-O11 -> 35 | Q12: =P12/$O$15 -> 0.058724832
B13: Heavy truck | C13: 9 | D13: =C13/$C$17 -> 0.014729951 | N13: 5.0-7.5 | O13: 565 | P13: =O13-O12 -> 25 | Q13: =P13/$O$15 -> 0.041946309
B14: Truck Trailer | C14: 14 | D14: =C14/$C$17 -> 0.022913257 | N14: 7.5-10 | O14: 587 | P14: =O14-O13 -> 22 | Q14: =P14/$O$15 -> 0.036912752
B15: Motor cycles | C15: 18 | D15: =C15/$C$17 -> 0.029459902 | N15: Over 10 | O15: 596 | P15: =O15-O14 -> 9 | Q15: =P15/$O$15 -> 0.015100671
B16: Tractors | C16: 1 | D16: =C16/$C$17 -> 0.0016366612
B17: Total | C17: =SUM(C5:C16) -> 611
B18: ADT | C18: 15651.333 | D18: =C17/C18 -> 0.039038208
N21: Trip Frequency
B22: Journey Purpose | N22: Trip Frequency | O22: No of Vehicles | P22: No. of Vehicles, %
B23: Purpose | C23: Respondents | D23: Percent | N23: More than 2 times every day | O23: 319 | P23: =O23/$O$29 -> 0.53255426
B24: Home-Work | C24: 87 | D24: =C24/$C$29 -> 0.14238953 | N24: Daily (Up and Down) | O24: 142 | P24: =O24/$O$29 -> 0.23706177
B25: Home-Study | C25: 1 | D25: =C25/$C$29 -> 0.0016366612 | N25: 2/3 times a week | O25: 72 | P25: =O25/$O$29 -> 0.12020033
B26: Work-Home | C26: 35 | D26: =C26/$C$29 -> 0.057283142 | N26: Once a week | O26: 34 | P26: =O26/$O$29 -> 0.056761269
B27: Work-Work | C27: 182 | D27: =C27/$C$29 -> 0.29787234 | N27: Once a month | O27: 13 | P27: =O27/$O$29 -> 0.021702838
B28: Others | C28: 306 | D28: =C28/$C$29 -> 0.50081833 | N28: Once in a while | O28: 19 | P28: =O28/$O$29 -> 0.031719533
B29: Total | C29: =C17 -> 611 | O29: =SUM(O23:O28) -> 599
B40: Expressway Use
B41: Response | C41: Number | D41: Percent | N41: Vehicle Types | O41: Average Occupancy
B42: Yes | C42: 10 | D42: =C42/$C$44 -> 0.016366612 | N42: Car | O42: 2
B43: No | C43: 601 | D43: =C43/$C$44 -> 0.98363339 | N43: Station Wagon | O43: 2
B44: Total | C44: =C29 -> 611 | N44: Pickups | O44: 2
N45: Minibus, matatu | O45: 10
N46: Medium bus | O46: 15
N47: Large Bus | O47: 45
N48: Light Truck | O48: 2
N49: Medium Truck | O49: 5
N50: Heavy truck | O50: 2
N51: Truck Trailer | O51: 1
N52: Motor cycles | O52: 2
N53: Tractors | O53: 2
...

Sheet STN 107
B1: STN107 OD ANALYSIS
B3: Vehicle OD Sample Proportions | N3: Average Journey Time
B4: Vehicle Types | C4: OD Sample | D4: OD Sample, % | N4: Journey Time Range (Hrs) | O4: Cummu-lative | P4: No of Vehicles | Q4: No. of Vehicles, %
B5: Car | C5: 41 | D5: =C5/$C$17 -> 0.11714286 | N5: 0-0.25 | O5: 3 | P5: =O5 -> 3 | Q5: =P5/$O$15 -> 0.012931034
B6: Station Wagon | C6: 20 | D6: =C6/$C$17 -> 0.057142857 | N6: 0.25-0.50 | O6: 3 | P6: =O6-O5 -> 0 | Q6: =P6/$O$15 -> 0
B7: Pickups | C7: 83 | D7: =C7/$C$17 -> 0.23714286 | N7: 0.50-0.75 | O7: 3 | P7: =O7-O6 -> 0 | Q7: =P7/$O$15 -> 0
B8: Minibus, matatu | C8: 4 | D8: =C8/$C$17 -> 0.011428571 | N8: 0.75-1.00 | O8: 19 | P8: =O8-O7 -> 16 | Q8: =P8/$O$15 -> 0.068965517
B9: Medium bus | C9: 41 | D9: =C9/$C$17 -> 0.11714286 | N9: 1.00-1.50 | O9: 23 | P9: =O9-O8 -> 4 | Q9: =P9/$O$15 -> 0.017241379
B10: Large Bus | C10: 18 | D10: =C10/$C$17 -> 0.051428571 | N10: 1.5-2.0 | O10: 47 | P10: =O10-O9 -> 24 | Q10: =P10/$O$15 -> 0.10344828
B11: Light Truck | C11: 38 | D11: =C11/$C$17 -> 0.10857143 | N11: 2.0-3.0 | O11: 63 | P11: =O11-O10 -> 16 | Q11: =P11/$O$15 -> 0.068965517
B12: Medium Truck | C12: 69 | D12: =C12/$C$17 -> 0.19714286 | N12: 3.0-5.0 | O12: 118 | P12: =O12-O11 -> 55 | Q12: =P12/$O$15 -> 0.23706897
B13: Heavy truck | C13: 4 | D13: =C13/$C$17 -> 0.011428571 | N13: 5.0-7.5 | O13: 172 | P13: =O13-O12 -> 54 | Q13: =P13/$O$15 -> 0.23275862
B14: Truck Trailer | C14: 3 | D14: =C14/$C$17 -> 0.0085714286 | N14: 7.5-10 | O14: 217 | P14: =O14-O13 -> 45 | Q14: =P14/$O$15 -> 0.19396552
B15: Motor cycles | C15: 1 | D15: =C15/$C$17 -> 0.0028571429 | N15: Over 10 | O15: 232 | P15: =O15-O14 -> 15 | Q15: =P15/$O$15 -> 0.064655172
B16: Tractors | C16: 28 | D16: =C16/$C$17 -> 0.08
B17: Total | C17: =SUM(C5:C16) -> 350
B18: ADT | C18: 1208.5714 | D18: =C17/C18 -> 0.28959811
N21: Trip Frequency
B22: Journey Purpose | N22: Trip Frequency | O22: No of Vehicles | P22: No. of Vehicles, %
B23: Purpose | C23: Respondents | D23: Percent | N23: More than 2 times every day | O23: 58 | P23: =O23/$O$29 -> 0.16618911
B24: Home-Work | C24: 52 | D24: =C24/$C$29 -> 0.14857143 | N24: Daily (Up and Down) | O24: 71 | P24: =O24/$O$29 -> 0.2034384
B25: Home-Study | C25: 2 | D25: =C25/$C$29 -> 0.0057142857 | N25: 2/3 times a week | O25: 115 | P25: =O25/$O$29 -> 0.32951289
B26: Work-Home | C26: 43 | D26: =C26/$C$29 -> 0.12285714 | N26: Once a week | O26: 78 | P26: =O26/$O$29 -> 0.2234957
B27: Work-Work | C27: 33 | D27: =C27/$C$29 -> 0.094285714 | N27: Once a month | O27: 17 | P27: =O27/$O$29 -> 0.048710602
B28: Others | C28: 220 | D28: =C28/$C$29 -> 0.62857143 | N28: Once in a while | O28: 10 | P28: =O28/$O$29 -> 0.028653295
B29: Total | C29: =C17 -> 350 | O29: =SUM(O23:O28) -> 349
B40: Expressway Use
B41: Response | C41: Number | D41: Percent
B42: Yes | C42: 0 | D42: =C42/$C$44 -> 0 | N42: Vehicle Types | O42: Average Occupancy
B43: No | C43: 350 | D43: =C43/$C$44 -> 1 | N43: Car | O43: 3
B44: Total | C44: =C29 -> 350 | N44: Station Wagon | O44: 4
N45: Pickups | O45: 4
N46: Minibus, matatu | O46: 5
N47: Medium bus | O47: 10
N48: Large Bus | O48: 2
N49: Light Truck | O49: 3
N50: Medium Truck | O50: 3
N51: Heavy truck | O51: 2
N52: Truck Trailer | O52: 2
N53: Motor cycles | O53: 2
...

Sheet STN 108
B1: STN108 OD ANALYSIS
B3: Vehicle OD Sample Proportions | N3: Average Journey Time
B4: Vehicle Types | C4: OD Sample | D4: OD Sample, % | N4: Journey Time Range (Hrs) | O4: Cummu-lative | P4: No of Vehicles | Q4: No. of Vehicles, %
B5: Car | C5: 124 | D5: =C5/$C$17 -> 0.40924092 | N5: 0-0.25 | O5: 38 | P5: =O5 -> 38 | Q5: =P5/$O$15 -> 0.16593886
B6: Station Wagon | C6: 17 | D6: =C6/$C$17 -> 0.056105611 | N6: 0.25-0.50 | O6: 81 | P6: =O6-O5 -> 43 | Q6: =P6/$O$15 -> 0.18777293
B7: Pickups | C7: 17 | D7: =C7/$C$17 -> 0.056105611 | N7: 0.50-0.75 | O7: 91 | P7: =O7-O6 -> 10 | Q7: =P7/$O$15 -> 0.043668122
B8: Minibus, matatu | C8: 40 | D8: =C8/$C$17 -> 0.1320132 | N8: 0.75-1.00 | O8: 133 | P8: =O8-O7 -> 42 | Q8: =P8/$O$15 -> 0.18340611
B9: Medium bus | C9: 3 | D9: =C9/$C$17 -> 0.0099009901 | N9: 1.00-1.50 | O9: 154 | P9: =O9-O8 -> 21 | Q9: =P9/$O$15 -> 0.091703057
B10: Large Bus | C10: 1 | D10: =C10/$C$17 -> 0.00330033 | N10: 1.5-2.0 | O10: 184 | P10: =O10-O9 -> 30 | Q10: =P10/$O$15 -> 0.13100437
B11: Light Truck | C11: 36 | D11: =C11/$C$17 -> 0.11881188 | N11: 2.0-3.0 | O11: 204 | P11: =O11-O10 -> 20 | Q11: =P11/$O$15 -> 0.087336245
B12: Medium Truck | C12: 35 | D12: =C12/$C$17 -> 0.11551155 | N12: 3.0-5.0 | O12: 221 | P12: =O12-O11 -> 17 | Q12: =P12/$O$15 -> 0.074235808
B13: Heavy truck | C13: 13 | D13: =C13/$C$17 -> 0.04290429 | N13: 5.0-7.5 | O13: 227 | P13: =O13-O12 -> 6 | Q13: =P13/$O$15 -> 0.026200873
B14: Truck Trailer | C14: 2 | D14: =C14/$C$17 -> 0.0066006601 | N14: 7.5-10 | O14: 227 | P14: =O14-O13 -> 0 | Q14: =P14/$O$15 -> 0
B15: Motor cycles | C15: 15 | D15: =C15/$C$17 -> 0.04950495 | N15: Over 10 | O15: 229 | P15: =O15-O14 -> 2 | Q15: =P15/$O$15 -> 0.0087336245
B16: Tractors | C16: 0 | D16: =C16/$C$17 -> 0
B17: Total | C17: =SUM(C5:C16) -> 303
B18: ADT | C18: 5069.7143 | D18: =C17/C18 -> 0.059766682
N21: Trip Frequency
B22: Journey Purpose | N22: Trip Frequency | O22: No of Vehicles | P22: No. of Vehicles, %
B23: Purpose | C23: Respondents | D23: Percent | N23: More than 2 times every day | O23: 112 | P23: =O23/$O$29 -> 0.36963696
B24: Home-Work | C24: 63 | D24: =C24/$C$29 -> 0.20792079 | N24: Daily (Up and Down) | O24: 126 | P24: =O24/$O$29 -> 0.41584158
B25: Home-Study | C25: 0 | D25: =C25/$C$29 -> 0 | N25: 2/3 times a week | O25: 22 | P25: =O25/$O$29 -> 0.072607261
B26: Work-Home | C26: 19 | D26: =C26/$C$29 -> 0.062706271 | N26: Once a week | O26: 20 | P26: =O26/$O$29 -> 0.066006601
B27: Work-Work | C27: 56 | D27: =C27/$C$29 -> 0.18481848 | N27: Once a month | O27: 7 | P27: =O27/$O$29 -> 0.02310231
B28: Others | C28: 165 | D28: =C28/$C$29 -> 0.54455446 | N28: Once in a while | O28: 16 | P28: =O28/$O$29 -> 0.052805281
B29: Total | C29: =C17 -> 303 | O29: =SUM(O23:O28) -> 303
B40: Expressway Use
B41: Response | C41: Number | D41: Percent
B42: Yes | C42: 89 | D42: =C42/$C$44 -> 0.29372937 | N42: Vehicle Types | O42: Average Occupacy
B43: No | C43: 214 | D43: =C43/$C$44 -> 0.70627063 | N43: Car | O43: 3
B44: Total | C44: =C29 -> 303 | N44: Station Wagon | O44: 2
N45: Pickups | O45: 2
N46: Minibus, matatu | O46: 9
N47: Medium bus | O47: 16
N48: Large Bus | O48: 2
N49: Light Truck | O49: 2
N50: Medium Truck | O50: 3
N51: Heavy truck | O51: 2
N52: Truck Trailer | O52: 2
N53: Motor cycles | O53: 1
...

Sheet STN 111A
B1: STN111A OD ANALYSIS
B3: Vehicle OD Sample Proportions | N3: Average Journey Time
B4: Vehicle Types | C4: OD Sample | D4: OD Sample, % | N4: Journey Time Range (Hrs) | O4: Cummu-lative | P4: No of Vehicles | Q4: No. of Vehicles, %
B5: Car | C5: 40 | D5: =C5/$C$17 -> 0.13605442 | N5: 0-0.25 | O5: 39 | P5: =O5 -> 39 | Q5: =P5/$O$15 -> 0.13448276
B6: Station Wagon | C6: 11 | D6: =C6/$C$17 -> 0.037414966 | N6: 0.25-0.50 | O6: 52 | P6: =O6-O5 -> 13 | Q6: =P6/$O$15 -> 0.044827586
B7: Pickups | C7: 24 | D7: =C7/$C$17 -> 0.081632653 | N7: 0.50-0.75 | O7: 64 | P7: =O7-O6 -> 12 | Q7: =P7/$O$15 -> 0.04137931
B8: Minibus, matatu | C8: 103 | D8: =C8/$C$17 -> 0.35034014 | N8: 0.75-1.00 | O8: 94 | P8: =O8-O7 -> 30 | Q8: =P8/$O$15 -> 0.10344828
B9: Medium bus | C9: 2 | D9: =C9/$C$17 -> 0.0068027211 | N9: 1.00-1.50 | O9: 111 | P9: =O9-O8 -> 17 | Q9: =P9/$O$15 -> 0.05862069
B10: Large Bus | C10: 0 | D10: =C10/$C$17 -> 0 | N10: 1.5-2.0 | O10: 179 | P10: =O10-O9 -> 68 | Q10: =P10/$O$15 -> 0.23448276
B11: Light Truck | C11: 14 | D11: =C11/$C$17 -> 0.047619048 | N11: 2.0-3.0 | O11: 250 | P11: =O11-O10 -> 71 | Q11: =P11/$O$15 -> 0.24482759
B12: Medium Truck | C12: 8 | D12: =C12/$C$17 -> 0.027210884 | N12: 3.0-5.0 | O12: 275 | P12: =O12-O11 -> 25 | Q12: =P12/$O$15 -> 0.086206897
B13: Heavy truck | C13: 11 | D13: =C13/$C$17 -> 0.037414966 | N13: 5.0-7.5 | O13: 284 | P13: =O13-O12 -> 9 | Q13: =P13/$O$15 -> 0.031034483
B14: Truck Trailer | C14: 2 | D14: =C14/$C$17 -> 0.0068027211 | N14: 7.5-10 | O14: 289 | P14: =O14-O13 -> 5 | Q14: =P14/$O$15 -> 0.017241379
B15: Motor cycles | C15: 79 | D15: =C15/$C$17 -> 0.26870748 | N15: Over 10 | O15: 290 | P15: =O15-O14 -> 1 | Q15: =P15/$O$15 -> 0.0034482759
B16: Tractors | C16: 0 | D16: =C16/$C$17 -> 0
B17: Total | C17: =SUM(C5:C16) -> 294
B18: ADT | C18: 720.54762 | D18: =C17/C18 -> 0.408023
N21: Trip Frequency
B22: Journey Purpose | N22: Trip Frequency | O22: No of Vehicles | P22: No. of Vehicles, %
B23: Purpose | C23: Respondents | D23: Percent | N23: More than 2 times every day | O23: 25 | P23: =O23/$O$29 -> 0.087719298
B24: Home-Work | C24: 24 | D24: =C24/$C$29 -> 0.081632653 | N24: Daily (Up and Down) | O24: 137 | P24: =O24/$O$29 -> 0.48070175
B25: Home-Study | C25: 1 | D25: =C25/$C$29 -> 0.0034013605 | N25: 2/3 times a week | O25: 52 | P25: =O25/$O$29 -> 0.18245614
B26: Work-Home | C26: 15 | D26: =C26/$C$29 -> 0.051020408 | N26: Once a week | O26: 30 | P26: =O26/$O$29 -> 0.10526316
B27: Work-Work | C27: 171 | D27: =C27/$C$29 -> 0.58163265 | N27: Once a month | O27: 11 | P27: =O27/$O$29 -> 0.038596491
B28: Others | C28: 83 | D28: =C28/$C$29 -> 0.28231293 | N28: Once in a while | O28: 30 | P28: =O28/$O$29 -> 0.10526316
B29: Total | C29: =C17 -> 294 | O29: =SUM(O23:O28) -> 285
B40: Expressway Use
B41: Response | C41: Number | D41: Percent | N41: Vehicle Types | O41: Average Occupancy
B42: Yes | C42: 0 | D42: =C42/$C$44 -> 0 | N42: Car | O42: 4
B43: No | C43: 294 | D43: =C43/$C$44 -> 1 | N43: Station Wagon | O43: 2
B44: Total | C44: =C29 -> 294 | N44: Pickups | O44: 5
N45: Minibus, matatu | O45: 14
N46: Medium bus | O46: 17
N47: Large Bus | O47: 0
N48: Light Truck | O48: 11
N49: Medium Truck | O49: 3
N50: Heavy truck | O50: 6
N51: Truck Trailer | O51: 3
N52: Motor cycles | O52: 2
N53: Tractors | O53: 0
...

Sheet STN 111
B1: STN111 OD ANALYSIS
B3: Vehicle OD Sample Proportions | N3: Average Journey Time
B4: Vehicle Types | C4: OD Sample | D4: OD Sample, % | N4: Journey Time Range (Hrs) | O4: Cummu-lative | P4: No of Vehicles | Q4: No. of Vehicles, %
B5: Car | C5: 118 | D5: =C5/$C$17 -> 0.39864865 | N5: 0-0.25 | O5: 2 | P5: =O5 -> 2 | Q5: =P5/$O$15 -> 0.0088888889
B6: Station Wagon | C6: 53 | D6: =C6/$C$17 -> 0.17905405 | N6: 0.25-0.50 | O6: 77 | P6: =O6-O5 -> 75 | Q6: =P6/$O$15 -> 0.33333333
B7: Pickups | C7: 19 | D7: =C7/$C$17 -> 0.064189189 | N7: 0.50-0.75 | O7: 95 | P7: =O7-O6 -> 18 | Q7: =P7/$O$15 -> 0.08
B8: Minibus, matatu | C8: 8 | D8: =C8/$C$17 -> 0.027027027 | N8: 0.75-1.00 | O8: 132 | P8: =O8-O7 -> 37 | Q8: =P8/$O$15 -> 0.16444444
B9: Medium bus | C9: 5 | D9: =C9/$C$17 -> 0.016891892 | N9: 1.00-1.50 | O9: 172 | P9: =O9-O8 -> 40 | Q9: =P9/$O$15 -> 0.17777778
B10: Large Bus | C10: 8 | D10: =C10/$C$17 -> 0.027027027 | N10: 1.5-2.0 | O10: 183 | P10: =O10-O9 -> 11 | Q10: =P10/$O$15 -> 0.048888889
B11: Light Truck | C11: 9 | D11: =C11/$C$17 -> 0.030405405 | N11: 2.0-3.0 | O11: 201 | P11: =O11-O10 -> 18 | Q11: =P11/$O$15 -> 0.08
B12: Medium Truck | C12: 37 | D12: =C12/$C$17 -> 0.125 | N12: 3.0-5.0 | O12: 216 | P12: =O12-O11 -> 15 | Q12: =P12/$O$15 -> 0.066666667
B13: Heavy truck | C13: 12 | D13: =C13/$C$17 -> 0.040540541 | N13: 5.0-7.5 | O13: 223 | P13: =O13-O12 -> 7 | Q13: =P13/$O$15 -> 0.031111111
B14: Truck Trailer | C14: 20 | D14: =C14/$C$17 -> 0.067567568 | N14: 7.5-10 | O14: 225 | P14: =O14-O13 -> 2 | Q14: =P14/$O$15 -> 0.0088888889
B15: Motor cycles | C15: 4 | D15: =C15/$C$17 -> 0.013513514 | N15: Over 10 | O15: 225 | P15: =O15-O14 -> 0 | Q15: =P15/$O$15 -> 0
B16: Tractors | C16: 3 | D16: =C16/$C$17 -> 0.010135135
B17: Total | C17: =SUM(C5:C16) -> 296
B18: ADT | C18: 4726.4286 | D18: =C17/C18 -> 0.062626568
N21: Trip Frequency
B22: Journey Purpose | N22: Trip Frequency | O22: No of Vehicles | P22: No. of Vehicles, %
B23: Purpose | C23: Respondents | D23: Percent | N23: More than 2 times every day | O23: 30 | P23: =O23/$O$29 -> 0.098039216
B24: Home-Work | C24: 121 | D24: =C24/$C$29 -> 0.40878378 | N24: Daily (Up and Down) | O24: 109 | P24: =O24/$O$29 -> 0.35620915
B25: Home-Study | C25: 5 | D25: =C25/$C$29 -> 0.016891892 | N25: 2/3 times a week | O25: 61 | P25: =O25/$O$29 -> 0.19934641
B26: Work-Home | C26: 14 | D26: =C26/$C$29 -> 0.047297297 | N26: Once a week | O26: 81 | P26: =O26/$O$29 -> 0.26470588
B27: Work-Work | C27: 111 | D27: =C27/$C$29 -> 0.375 | N27: Once a month | O27: 21 | P27: =O27/$O$29 -> 0.068627451
B28: Others | C28: 45 | D28: =C28/$C$29 -> 0.15202703 | N28: Once in a while | O28: 4 | P28: =O28/$O$29 -> 0.013071895
B29: Total | C29: =C17 -> 296 | O29: =SUM(O23:O28) -> 306
B40: Expressway Use
B41: Response | C41: Number | D41: Percent
B42: Yes | C42: 0 | D42: =C42/$C$44 -> 0 | N42: Vehicle Types | O42: Average Occupancy
B43: No | C43: 296 | D43: =C43/$C$44 -> 1 | N43: Car | O43: 4
B44: Total | C44: =C29 -> 296 | N44: Station Wagon | O44: 4
N45: Pickups | O45: 7
N46: Minibus, matatu | O46: 5
N47: Medium bus | O47: 52
N48: Large Bus | O48: 3
N49: Light Truck | O49: 3
N50: Medium Truck | O50: 11
N51: Heavy truck | O51: 2
N52: Truck Trailer | O52: 4
N53: Motor cycles | O53: 2
...

Sheet STN 112
B1: STN112 OD ANALYSIS
B3: Vehicle OD Sample Proportions | N3: Average Journey Time
B4: Vehicle Types | C4: OD Sample | D4: OD Sample, % | N4: Journey Time Range (Hrs) | O4: Cummu-lative | P4: No of Vehicles | Q4: No. of Vehicles, %
B5: Car | C5: 188 | D5: =C5/$C$17 -> 0.28967643 | N5: 0-0.25 | O5: 34 | P5: =O5 -> 34 | Q5: =P5/$O$15 -> 0.052877138
B6: Station Wagon | C6: 45 | D6: =C6/$C$17 -> 0.069337442 | N6: 0.25-0.50 | O6: 108 | P6: =O6-O5 -> 74 | Q6: =P6/$O$15 -> 0.11508554
B7: Pickups | C7: 68 | D7: =C7/$C$17 -> 0.10477658 | N7: 0.50-0.75 | O7: 157 | P7: =O7-O6 -> 49 | Q7: =P7/$O$15 -> 0.076205288
B8: Minibus, matatu | C8: 90 | D8: =C8/$C$17 -> 0.13867488 | N8: 0.75-1.00 | O8: 272 | P8: =O8-O7 -> 115 | Q8: =P8/$O$15 -> 0.17884914
B9: Medium bus | C9: 5 | D9: =C9/$C$17 -> 0.0077041602 | N9: 1.00-1.50 | O9: 308 | P9: =O9-O8 -> 36 | Q9: =P9/$O$15 -> 0.055987558
B10: Large Bus | C10: 17 | D10: =C10/$C$17 -> 0.026194145 | N10: 1.5-2.0 | O10: 341 | P10: =O10-O9 -> 33 | Q10: =P10/$O$15 -> 0.051321928
B11: Light Truck | C11: 68 | D11: =C11/$C$17 -> 0.10477658 | N11: 2.0-3.0 | O11: 458 | P11: =O11-O10 -> 117 | Q11: =P11/$O$15 -> 0.18195956
B12: Medium Truck | C12: 77 | D12: =C12/$C$17 -> 0.11864407 | N12: 3.0-5.0 | O12: 590 | P12: =O12-O11 -> 132 | Q12: =P12/$O$15 -> 0.20528771
B13: Heavy truck | C13: 39 | D13: =C13/$C$17 -> 0.06009245 | N13: 5.0-7.5 | O13: 620 | P13: =O13-O12 -> 30 | Q13: =P13/$O$15 -> 0.046656299
B14: Truck Trailer | C14: 22 | D14: =C14/$C$17 -> 0.033898305 | N14: 7.5-10 | O14: 632 | P14: =O14-O13 -> 12 | Q14: =P14/$O$15 -> 0.018662519
B15: Motor cycles | C15: 22 | D15: =C15/$C$17 -> 0.033898305 | N15: Over 10 | O15: 643 | P15: =O15-O14 -> 11 | Q15: =P15/$O$15 -> 0.017107309
B16: Tractors | C16: 8 | D16: =C16/$C$17 -> 0.012326656
B17: Total | C17: =SUM(C5:C16) -> 649
B18: ADT | C18: 2339.9286 | D18: =C17/C18 -> 0.27735889
N21: Trip Frequency
B22: Journey Purpose | N22: Trip Frequency | O22: No of Vehicles | P22: No. of Vehicles, %
B23: Purpose | C23: Respondents | D23: Percent | N23: More than 2 times every day | O23: 109 | P23: =O23/$O$29 -> 0.16820988
B24: Home-Work | C24: 93 | D24: =C24/$C$29 -> 0.14329738 | N24: Daily (Up and Down) | O24: 197 | P24: =O24/$O$29 -> 0.30401235
B25: Home-Study | C25: 1 | D25: =C25/$C$29 -> 0.001540832 | N25: 2/3 times a week | O25: 135 | P25: =O25/$O$29 -> 0.20833333
B26: Work-Home | C26: 35 | D26: =C26/$C$29 -> 0.053929122 | N26: Once a week | O26: 107 | P26: =O26/$O$29 -> 0.16512346
B27: Work-Work | C27: 116 | D27: =C27/$C$29 -> 0.17873652 | N27: Once a month | O27: 41 | P27: =O27/$O$29 -> 0.063271605
B28: Others | C28: 404 | D28: =C28/$C$29 -> 0.62249615 | N28: Once in a while | O28: 59 | P28: =O28/$O$29 -> 0.091049383
B29: Total | C29: =C17 -> 649 | O29: =SUM(O23:O28) -> 648
B40: Expressway Use
B41: Response | C41: Number | D41: Percent
B42: Yes | C42: 651 | D42: =C42/$C$44 -> 1.0030817 | N42: Vehicle Types | O42: Average Occupancy
B43: No | C43: 0 | D43: =C43/$C$44 -> 0 | N43: Car | O43: 4
B44: Total | C44: =C29 -> 649 | N44: Station Wagon | O44: 3
N45: Pickups | O45: 3
N46: Minibus, matatu | O46: 12
N47: Medium bus | O47: 20
N48: Large Bus | O48: 56
N49: Light Truck | O49: 2
N50: Medium Truck | O50: 3
N51: Heavy truck | O51: 2
N52: Truck Trailer | O52: 1
N53: Motor cycles | O53: 2
...

Sheet STN 113
