Workbook
Name Dist: '[1]ALL DATA'!$S:$S
Name dist: '[2]ALL DATA'!$S:$S
Name Dist: '[3]ALL DATA'!$S:$S
Name Dist: '[4]ALL DATA'!$S:$S
Name Dist: '[5]ALL DATA'!$S:$S
Name Dist: '[6]all data'!$S:$S
Name Dist: '[7]ALL DATA'!$S:$S
Name Dist: '[8]ALL DATA'!$S:$S
Name Dist: '[1]ALL DATA'!$S:$S
Name Dist: '[9]ALL DATA'!$S:$S
Name Dist: '[10]ALL DATA'!$S:$S
Name Dist: '[11]ALL DATA'!$S:$S
Name Dist: '[12]ALL DATA'!$S:$S
Name Dist: '[13]ALL DATA'!$S:$S
Name Dist: '[14]ALL DATA'!$S:$S
Name Dist: '[15]ALL DATA'!$S:$S
Name Dist: '[16]ALL DATA'!$S:$S
Name Dist: '[17]ALL DATA'!$S:$S
Name DIst: '[18]ALL DATA'!$S:$S
Name Dist: '[19]ALL DATA'!$S:$S
Name Dist: '[20]ALL DATA'!$S:$S
Name Dist: '[21]ALL DATA'!$S:$S
Name Dist: '[22]ALL DATA'!$S:$S
Name Dist: '[23]ALL DATA'!$S:$S
Name Dist: '[24]ALL DATA'!$S:$S
Name Dist: '[25]ALL DATA'!$S:$S
Name Dist: '[26]ALL DATA'!$S:$S
Name Dist: '[27]ALL DATA'!$S:$S
Name Dist: '[28]ALL DATA'!$S:$S
Name Dist: '[29]ALL DATA'!$S:$S
Name Dist: '[30]ALL DATA'!$S:$S
Name Dist: '[31]ALL DATA'!$S:$S
Name Dist: '[32]ALL DATA'!$S:$S
Name Dist: '[33]ALL DATA'!$S:$S
Name Dist: '[34]ALL DATA'!$S:$S
Name Dist: '[35]ALL DATA'!$S:$S
Name Dist: '[36]ALL DATA'!$S:$S
Name Dist: '[37]ALL DATA'!$S:$S
Name Dist: '[38]ALL DATA'!$S:$S
Name Dist: '[39]ALL DATA'!$S:$S
Name Dist: '[40]ALL DATA'!$S:$S
Name Dist: '[41]ALL DATA'!$S:$S
Name Dist: '[42]ALL DATA'!$S:$S
Name Dist: '[43]ALL DATA'!$S:$S
Name Dist: '[44]ALL DATA'!$S:$S
Name Dist: '[45]ALL DATA'!$S:$S
Name Dist: '[46]ALL DATA'!$S:$S
Name Dist: '[47]ALL DATA'!$S:$S
Name Jtime: '[1]ALL DATA'!$T:$T
Name Jtime: '[2]ALL DATA'!$T:$T
Name Jtime: '[3]ALL DATA'!$T:$T
Name Jtime: '[4]ALL DATA'!$T:$T
Name Jtime: '[5]ALL DATA'!$T:$T
Name Jtime: '[6]all data'!$T:$T
Name Jtime: '[7]ALL DATA'!$T:$T
Name Jtime: '[8]ALL DATA'!$T:$T
Name Jtime: '[1]ALL DATA'!$T:$T
Name Jtime: '[9]ALL DATA'!$T:$T
Name Jtime: '[10]ALL DATA'!$T:$T
Name Jtime: '[11]ALL DATA'!$T:$T

Sheet Average C1
B4: Vehicle OD Sample Proportions | N4: Average Journey Time
B5: Vehicle Types | C5: OD Sample | D5: OD Sample, % | N5: Journey Time Range (Hrs) | O5: Cummu-lative | P5: No of Vehicles | Q5: No. of Vehicles, %
B6: Car | C6: =AVERAGE(STN01A!C6,'Stn 01'!C6,'STN02'!C6,'STN03'!C6,'STN04'!C6,'STN05'!C6,'STN06'!C6,'STN07'!C6,'STN08'!C6,'STN09'!C6,'STN10'!C6,'STN11'!C6,'STN12'!C6,'STN13'!C6,'STN14'!C6,'STN15'!C6,'STN17'!C6,'STN18'!C6,'STN20'!C6,'STN21'!C6,'STN22'!C6,'STN23'!C6,'STN24'!C6,'STN25'!C6,'STN26'!C6,'STN28'!C6,'STN29'!C6,'STN30'!C6,'STN32'!C6,'STN33'!C6,'STN34'!C6,'STN36'!C6,'STN37'!C6,'STN38'!C6,'STN39'!C6,'STN40'!C6,'STN42'!C6,'STN43'!C6,STN44A!C6,'STN44'!C6,'STN45'!C6,'STN46'!C6,'STN47'!C6,'STN48'!C6,STN48A!C6,'STN49'!C6,'STN50'!C6) -> 326.40426 | D6: =C6/$C$18 -> 0.37837904 | N6: 0-0.25 | O6: =AVERAGE(STN01A!O6,'Stn 01'!O6,'STN02'!O6,'STN03'!O6,'STN04'!O6,'STN05'!O6,'STN06'!O6,'STN07'!O6,'STN08'!O6,'STN09'!O6,'STN10'!O6,'STN11'!O6,'STN12'!O6,'STN13'!O6,'STN14'!O6,'STN15'!O6,'STN17'!O6,'STN18'!O6,'STN20'!O6,'STN21'!O6,'STN22'!O6,'STN23'!O6,'STN24'!O6,'STN25'!O6,'STN26'!O6,'STN28'!O6,'STN29'!O6,'STN30'!O6,'STN32'!O6,'STN33'!O6,'STN34'!O6,'STN36'!O6,'STN37'!O6,'STN38'!O6,'STN39'!O6,'STN40'!O6,'STN42'!O6,'STN43'!O6,STN44A!O6,'STN44'!O6,'STN45'!O6,'STN46'!O6,'STN47'!O6,'STN48'!O6,STN48A!O6,'STN49'!O6,'STN50'!O6) -> 129.10638 | P6: =O6 -> 129.10638 | Q6: =P6/$O$16 -> 0.16878999
B7: Station Wagon | C7: =AVERAGE(STN01A!C7,'Stn 01'!C7,'STN02'!C7,'STN03'!C7,'STN04'!C7,'STN05'!C7,'STN06'!C7,'STN07'!C7,'STN08'!C7,'STN09'!C7,'STN10'!C7,'STN11'!C7,'STN12'!C7,'STN13'!C7,'STN14'!C7,'STN15'!C7,'STN17'!C7,'STN18'!C7,'STN20'!C7,'STN21'!C7,'STN22'!C7,'STN23'!C7,'STN24'!C7,'STN25'!C7,'STN26'!C7,'STN28'!C7,'STN29'!C7,'STN30'!C7,'STN32'!C7,'STN33'!C7,'STN34'!C7,'STN36'!C7,'STN37'!C7,'STN38'!C7,'STN39'!C7,'STN40'!C7,'STN42'!C7,'STN43'!C7,STN44A!C7,'STN44'!C7,'STN45'!C7,'STN46'!C7,'STN47'!C7,'STN48'!C7,STN48A!C7,'STN49'!C7,'STN50'!C7) -> 84.680851 | D7: =C7/$C$18 -> 0.098164957 | N7: 0.25-0.50 | O7: =AVERAGE(STN01A!O7,'Stn 01'!O7,'STN02'!O7,'STN03'!O7,'STN04'!O7,'STN05'!O7,'STN06'!O7,'STN07'!O7,'STN08'!O7,'STN09'!O7,'STN10'!O7,'STN11'!O7,'STN12'!O7,'STN13'!O7,'STN14'!O7,'STN15'!O7,'STN17'!O7,'STN18'!O7,'STN20'!O7,'STN21'!O7,'STN22'!O7,'STN23'!O7,'STN24'!O7,'STN25'!O7,'STN26'!O7,'STN28'!O7,'STN29'!O7,'STN30'!O7,'STN32'!O7,'STN33'!O7,'STN34'!O7,'STN36'!O7,'STN37'!O7,'STN38'!O7,'STN39'!O7,'STN40'!O7,'STN42'!O7,'STN43'!O7,STN44A!O7,'STN44'!O7,'STN45'!O7,'STN46'!O7,'STN47'!O7,'STN48'!O7,STN48A!O7,'STN49'!O7,'STN50'!O7) -> 337.38298 | P7: =O7-O6 -> 208.2766 | Q7: =P7/$O$16 -> 0.27229485
B8: Pickups | C8: =AVERAGE(STN01A!C8,'Stn 01'!C8,'STN02'!C8,'STN03'!C8,'STN04'!C8,'STN05'!C8,'STN06'!C8,'STN07'!C8,'STN08'!C8,'STN09'!C8,'STN10'!C8,'STN11'!C8,'STN12'!C8,'STN13'!C8,'STN14'!C8,'STN15'!C8,'STN17'!C8,'STN18'!C8,'STN20'!C8,'STN21'!C8,'STN22'!C8,'STN23'!C8,'STN24'!C8,'STN25'!C8,'STN26'!C8,'STN28'!C8,'STN29'!C8,'STN30'!C8,'STN32'!C8,'STN33'!C8,'STN34'!C8,'STN36'!C8,'STN37'!C8,'STN38'!C8,'STN39'!C8,'STN40'!C8,'STN42'!C8,'STN43'!C8,STN44A!C8,'STN44'!C8,'STN45'!C8,'STN46'!C8,'STN47'!C8,'STN48'!C8,STN48A!C8,'STN49'!C8,'STN50'!C8) -> 45.446809 | D8: =C8/$C$18 -> 0.052683504 | N8: 0.50-0.75 | O8: =AVERAGE(STN01A!O8,'Stn 01'!O8,'STN02'!O8,'STN03'!O8,'STN04'!O8,'STN05'!O8,'STN06'!O8,'STN07'!O8,'STN08'!O8,'STN09'!O8,'STN10'!O8,'STN11'!O8,'STN12'!O8,'STN13'!O8,'STN14'!O8,'STN15'!O8,'STN17'!O8,'STN18'!O8,'STN20'!O8,'STN21'!O8,'STN22'!O8,'STN23'!O8,'STN24'!O8,'STN25'!O8,'STN26'!O8,'STN28'!O8,'STN29'!O8,'STN30'!O8,'STN32'!O8,'STN33'!O8,'STN34'!O8,'STN36'!O8,'STN37'!O8,'STN38'!O8,'STN39'!O8,'STN40'!O8,'STN42'!O8,'STN43'!O8,STN44A!O8,'STN44'!O8,'STN45'!O8,'STN46'!O8,'STN47'!O8,'STN48'!O8,STN48A!O8,'STN49'!O8,'STN50'!O8) -> 418.46809 | P8: =O8-O7 -> 81.085106 | Q8: =P8/$O$16 -> 0.10600834
B9: Minibus, matatu | C9: =AVERAGE(STN01A!C9,'Stn 01'!C9,'STN02'!C9,'STN03'!C9,'STN04'!C9,'STN05'!C9,'STN06'!C9,'STN07'!C9,'STN08'!C9,'STN09'!C9,'STN10'!C9,'STN11'!C9,'STN12'!C9,'STN13'!C9,'STN14'!C9,'STN15'!C9,'STN17'!C9,'STN18'!C9,'STN20'!C9,'STN21'!C9,'STN22'!C9,'STN23'!C9,'STN24'!C9,'STN25'!C9,'STN26'!C9,'STN28'!C9,'STN29'!C9,'STN30'!C9,'STN32'!C9,'STN33'!C9,'STN34'!C9,'STN36'!C9,'STN37'!C9,'STN38'!C9,'STN39'!C9,'STN40'!C9,'STN42'!C9,'STN43'!C9,STN44A!C9,'STN44'!C9,'STN45'!C9,'STN46'!C9,'STN47'!C9,'STN48'!C9,STN48A!C9,'STN49'!C9,'STN50'!C9) -> 140.80851 | D9: =C9/$C$18 -> 0.16323007 | N9: 0.75-1.00 | O9: =AVERAGE(STN01A!O9,'Stn 01'!O9,'STN02'!O9,'STN03'!O9,'STN04'!O9,'STN05'!O9,'STN06'!O9,'STN07'!O9,'STN08'!O9,'STN09'!O9,'STN10'!O9,'STN11'!O9,'STN12'!O9,'STN13'!O9,'STN14'!O9,'STN15'!O9,'STN17'!O9,'STN18'!O9,'STN20'!O9,'STN21'!O9,'STN22'!O9,'STN23'!O9,'STN24'!O9,'STN25'!O9,'STN26'!O9,'STN28'!O9,'STN29'!O9,'STN30'!O9,'STN32'!O9,'STN33'!O9,'STN34'!O9,'STN36'!O9,'STN37'!O9,'STN38'!O9,'STN39'!O9,'STN40'!O9,'STN42'!O9,'STN43'!O9,STN44A!O9,'STN44'!O9,'STN45'!O9,'STN46'!O9,'STN47'!O9,'STN48'!O9,STN48A!O9,'STN49'!O9,'STN50'!O9) -> 591.78723 | P9: =O9-O8 -> 173.31915 | Q9: =P9/$O$16 -> 0.22659249
B10: Medium bus | C10: =AVERAGE(STN01A!C10,'Stn 01'!C10,'STN02'!C10,'STN03'!C10,'STN04'!C10,'STN05'!C10,'STN06'!C10,'STN07'!C10,'STN08'!C10,'STN09'!C10,'STN10'!C10,'STN11'!C10,'STN12'!C10,'STN13'!C10,'STN14'!C10,'STN15'!C10,'STN17'!C10,'STN18'!C10,'STN20'!C10,'STN21'!C10,'STN22'!C10,'STN23'!C10,'STN24'!C10,'STN25'!C10,'STN26'!C10,'STN28'!C10,'STN29'!C10,'STN30'!C10,'STN32'!C10,'STN33'!C10,'STN34'!C10,'STN36'!C10,'STN37'!C10,'STN38'!C10,'STN39'!C10,'STN40'!C10,'STN42'!C10,'STN43'!C10,STN44A!C10,'STN44'!C10,'STN45'!C10,'STN46'!C10,'STN47'!C10,'STN48'!C10,STN48A!C10,'STN49'!C10,'STN50'!C10) -> 10.765957 | D10: =C10/$C$18 -> 0.012480268 | N10: 1.00-1.50 | O10: =AVERAGE(STN01A!O10,'Stn 01'!O10,'STN02'!O10,'STN03'!O10,'STN04'!O10,'STN05'!O10,'STN06'!O10,'STN07'!O10,'STN08'!O10,'STN09'!O10,'STN10'!O10,'STN11'!O10,'STN12'!O10,'STN13'!O10,'STN14'!O10,'STN15'!O10,'STN17'!O10,'STN18'!O10,'STN20'!O10,'STN21'!O10,'STN22'!O10,'STN23'!O10,'STN24'!O10,'STN25'!O10,'STN26'!O10,'STN28'!O10,'STN29'!O10,'STN30'!O10,'STN32'!O10,'STN33'!O10,'STN34'!O10,'STN36'!O10,'STN37'!O10,'STN38'!O10,'STN39'!O10,'STN40'!O10,'STN42'!O10,'STN43'!O10,STN44A!O10,'STN44'!O10,'STN45'!O10,'STN46'!O10,'STN47'!O10,'STN48'!O10,STN48A!O10,'STN49'!O10,'STN50'!O10) -> 629.29787 | P10: =O10-O9 -> 37.510638 | Q10: =P10/$O$16 -> 0.049040334
B11: Large Bus | C11: =AVERAGE(STN01A!C11,'Stn 01'!C11,'STN02'!C11,'STN03'!C11,'STN04'!C11,'STN05'!C11,'STN06'!C11,'STN07'!C11,'STN08'!C11,'STN09'!C11,'STN10'!C11,'STN11'!C11,'STN12'!C11,'STN13'!C11,'STN14'!C11,'STN15'!C11,'STN17'!C11,'STN18'!C11,'STN20'!C11,'STN21'!C11,'STN22'!C11,'STN23'!C11,'STN24'!C11,'STN25'!C11,'STN26'!C11,'STN28'!C11,'STN29'!C11,'STN30'!C11,'STN32'!C11,'STN33'!C11,'STN34'!C11,'STN36'!C11,'STN37'!C11,'STN38'!C11,'STN39'!C11,'STN40'!C11,'STN42'!C11,'STN43'!C11,STN44A!C11,'STN44'!C11,'STN45'!C11,'STN46'!C11,'STN47'!C11,'STN48'!C11,STN48A!C11,'STN49'!C11,'STN50'!C11) -> 4.2765957 | D11: =C11/$C$18 -> 0.004957577 | N11: 1.5-2.0 | O11: =AVERAGE(STN01A!O11,'Stn 01'!O11,'STN02'!O11,'STN03'!O11,'STN04'!O11,'STN05'!O11,'STN06'!O11,'STN07'!O11,'STN08'!O11,'STN09'!O11,'STN10'!O11,'STN11'!O11,'STN12'!O11,'STN13'!O11,'STN14'!O11,'STN15'!O11,'STN17'!O11,'STN18'!O11,'STN20'!O11,'STN21'!O11,'STN22'!O11,'STN23'!O11,'STN24'!O11,'STN25'!O11,'STN26'!O11,'STN28'!O11,'STN29'!O11,'STN30'!O11,'STN32'!O11,'STN33'!O11,'STN34'!O11,'STN36'!O11,'STN37'!O11,'STN38'!O11,'STN39'!O11,'STN40'!O11,'STN42'!O11,'STN43'!O11,STN44A!O11,'STN44'!O11,'STN45'!O11,'STN46'!O11,'STN47'!O11,'STN48'!O11,STN48A!O11,'STN49'!O11,'STN50'!O11) -> 690.82979 | P11: =O11-O10 -> 61.531915 | Q11: =P11/$O$16 -> 0.080445063
B12: Light Truck | C12: =AVERAGE(STN01A!C12,'Stn 01'!C12,'STN02'!C12,'STN03'!C12,'STN04'!C12,'STN05'!C12,'STN06'!C12,'STN07'!C12,'STN08'!C12,'STN09'!C12,'STN10'!C12,'STN11'!C12,'STN12'!C12,'STN13'!C12,'STN14'!C12,'STN15'!C12,'STN17'!C12,'STN18'!C12,'STN20'!C12,'STN21'!C12,'STN22'!C12,'STN23'!C12,'STN24'!C12,'STN25'!C12,'STN26'!C12,'STN28'!C12,'STN29'!C12,'STN30'!C12,'STN32'!C12,'STN33'!C12,'STN34'!C12,'STN36'!C12,'STN37'!C12,'STN38'!C12,'STN39'!C12,'STN40'!C12,'STN42'!C12,'STN43'!C12,STN44A!C12,'STN44'!C12,'STN45'!C12,'STN46'!C12,'STN47'!C12,'STN48'!C12,STN48A!C12,'STN49'!C12,'STN50'!C12) -> 78.085106 | D12: =C12/$C$18 -> 0.090518942 | N12: 2.0-3.0 | O12: =AVERAGE(STN01A!O12,'Stn 01'!O12,'STN02'!O12,'STN03'!O12,'STN04'!O12,'STN05'!O12,'STN06'!O12,'STN07'!O12,'STN08'!O12,'STN09'!O12,'STN10'!O12,'STN11'!O12,'STN12'!O12,'STN13'!O12,'STN14'!O12,'STN15'!O12,'STN17'!O12,'STN18'!O12,'STN20'!O12,'STN21'!O12,'STN22'!O12,'STN23'!O12,'STN24'!O12,'STN25'!O12,'STN26'!O12,'STN28'!O12,'STN29'!O12,'STN30'!O12,'STN32'!O12,'STN33'!O12,'STN34'!O12,'STN36'!O12,'STN37'!O12,'STN38'!O12,'STN39'!O12,'STN40'!O12,'STN42'!O12,'STN43'!O12,STN44A!O12,'STN44'!O12,'STN45'!O12,'STN46'!O12,'STN47'!O12,'STN48'!O12,STN48A!O12,'STN49'!O12,'STN50'!O12) -> 724 | P12: =O12-O11 -> 33.170213 | Q12: =P12/$O$16 -> 0.043365786
B13: Medium Truck | C13: =AVERAGE(STN01A!C13,'Stn 01'!C13,'STN02'!C13,'STN03'!C13,'STN04'!C13,'STN05'!C13,'STN06'!C13,'STN07'!C13,'STN08'!C13,'STN09'!C13,'STN10'!C13,'STN11'!C13,'STN12'!C13,'STN13'!C13,'STN14'!C13,'STN15'!C13,'STN17'!C13,'STN18'!C13,'STN20'!C13,'STN21'!C13,'STN22'!C13,'STN23'!C13,'STN24'!C13,'STN25'!C13,'STN26'!C13,'STN28'!C13,'STN29'!C13,'STN30'!C13,'STN32'!C13,'STN33'!C13,'STN34'!C13,'STN36'!C13,'STN37'!C13,'STN38'!C13,'STN39'!C13,'STN40'!C13,'STN42'!C13,'STN43'!C13,STN44A!C13,'STN44'!C13,'STN45'!C13,'STN46'!C13,'STN47'!C13,'STN48'!C13,STN48A!C13,'STN49'!C13,'STN50'!C13) -> 53.382979 | D13: =C13/$C$18 -> 0.061883386 | N13: 3.0-5.0 | O13: =AVERAGE(STN01A!O13,'Stn 01'!O13,'STN02'!O13,'STN03'!O13,'STN04'!O13,'STN05'!O13,'STN06'!O13,'STN07'!O13,'STN08'!O13,'STN09'!O13,'STN10'!O13,'STN11'!O13,'STN12'!O13,'STN13'!O13,'STN14'!O13,'STN15'!O13,'STN17'!O13,'STN18'!O13,'STN20'!O13,'STN21'!O13,'STN22'!O13,'STN23'!O13,'STN24'!O13,'STN25'!O13,'STN26'!O13,'STN28'!O13,'STN29'!O13,'STN30'!O13,'STN32'!O13,'STN33'!O13,'STN34'!O13,'STN36'!O13,'STN37'!O13,'STN38'!O13,'STN39'!O13,'STN40'!O13,'STN42'!O13,'STN43'!O13,STN44A!O13,'STN44'!O13,'STN45'!O13,'STN46'!O13,'STN47'!O13,'STN48'!O13,STN48A!O13,'STN49'!O13,'STN50'!O13) -> 747.19149 | P13: =O13-O12 -> 23.191489 | Q13: =P13/$O$16 -> 0.030319889
B14: Heavy truck | C14: =AVERAGE(STN01A!C14,'Stn 01'!C14,'STN02'!C14,'STN03'!C14,'STN04'!C14,'STN05'!C14,'STN06'!C14,'STN07'!C14,'STN08'!C14,'STN09'!C14,'STN10'!C14,'STN11'!C14,'STN12'!C14,'STN13'!C14,'STN14'!C14,'STN15'!C14,'STN17'!C14,'STN18'!C14,'STN20'!C14,'STN21'!C14,'STN22'!C14,'STN23'!C14,'STN24'!C14,'STN25'!C14,'STN26'!C14,'STN28'!C14,'STN29'!C14,'STN30'!C14,'STN32'!C14,'STN33'!C14,'STN34'!C14,'STN36'!C14,'STN37'!C14,'STN38'!C14,'STN39'!C14,'STN40'!C14,'STN42'!C14,'STN43'!C14,STN44A!C14,'STN44'!C14,'STN45'!C14,'STN46'!C14,'STN47'!C14,'STN48'!C14,STN48A!C14,'STN49'!C14,'STN50'!C14) -> 17.468085 | D14: =C14/$C$18 -> 0.020249605 | N14: 5.0-7.5 | O14: =AVERAGE(STN01A!O14,'Stn 01'!O14,'STN02'!O14,'STN03'!O14,'STN04'!O14,'STN05'!O14,'STN06'!O14,'STN07'!O14,'STN08'!O14,'STN09'!O14,'STN10'!O14,'STN11'!O14,'STN12'!O14,'STN13'!O14,'STN14'!O14,'STN15'!O14,'STN17'!O14,'STN18'!O14,'STN20'!O14,'STN21'!O14,'STN22'!O14,'STN23'!O14,'STN24'!O14,'STN25'!O14,'STN26'!O14,'STN28'!O14,'STN29'!O14,'STN30'!O14,'STN32'!O14,'STN33'!O14,'STN34'!O14,'STN36'!O14,'STN37'!O14,'STN38'!O14,'STN39'!O14,'STN40'!O14,'STN42'!O14,'STN43'!O14,STN44A!O14,'STN44'!O14,'STN45'!O14,'STN46'!O14,'STN47'!O14,'STN48'!O14,STN48A!O14,'STN49'!O14,'STN50'!O14) -> 756.93617 | P14: =O14-O13 -> 9.7446809 | Q14: =P14/$O$16 -> 0.012739917
B15: Truck Trailer | C15: =AVERAGE(STN01A!C15,'Stn 01'!C15,'STN02'!C15,'STN03'!C15,'STN04'!C15,'STN05'!C15,'STN06'!C15,'STN07'!C15,'STN08'!C15,'STN09'!C15,'STN10'!C15,'STN11'!C15,'STN12'!C15,'STN13'!C15,'STN14'!C15,'STN15'!C15,'STN17'!C15,'STN18'!C15,'STN20'!C15,'STN21'!C15,'STN22'!C15,'STN23'!C15,'STN24'!C15,'STN25'!C15,'STN26'!C15,'STN28'!C15,'STN29'!C15,'STN30'!C15,'STN32'!C15,'STN33'!C15,'STN34'!C15,'STN36'!C15,'STN37'!C15,'STN38'!C15,'STN39'!C15,'STN40'!C15,'STN42'!C15,'STN43'!C15,STN44A!C15,'STN44'!C15,'STN45'!C15,'STN46'!C15,'STN47'!C15,'STN48'!C15,STN48A!C15,'STN49'!C15,'STN50'!C15) -> 7.6170213 | D15: =C15/$C$18 -> 0.0088299132 | N15: 7.5-10 | O15: =AVERAGE(STN01A!O15,'Stn 01'!O15,'STN02'!O15,'STN03'!O15,'STN04'!O15,'STN05'!O15,'STN06'!O15,'STN07'!O15,'STN08'!O15,'STN09'!O15,'STN10'!O15,'STN11'!O15,'STN12'!O15,'STN13'!O15,'STN14'!O15,'STN15'!O15,'STN17'!O15,'STN18'!O15,'STN20'!O15,'STN21'!O15,'STN22'!O15,'STN23'!O15,'STN24'!O15,'STN25'!O15,'STN26'!O15,'STN28'!O15,'STN29'!O15,'STN30'!O15,'STN32'!O15,'STN33'!O15,'STN34'!O15,'STN36'!O15,'STN37'!O15,'STN38'!O15,'STN39'!O15,'STN40'!O15,'STN42'!O15,'STN43'!O15,STN44A!O15,'STN44'!O15,'STN45'!O15,'STN46'!O15,'STN47'!O15,'STN48'!O15,STN48A!O15,'STN49'!O15,'STN50'!O15) -> 762.51064 | P15: =O15-O14 -> 5.5744681 | Q15: =P15/$O$16 -> 0.0072878999
B16: Motor cycles | C16: =AVERAGE(STN01A!C16,'Stn 01'!C16,'STN02'!C16,'STN03'!C16,'STN04'!C16,'STN05'!C16,'STN06'!C16,'STN07'!C16,'STN08'!C16,'STN09'!C16,'STN10'!C16,'STN11'!C16,'STN12'!C16,'STN13'!C16,'STN14'!C16,'STN15'!C16,'STN17'!C16,'STN18'!C16,'STN20'!C16,'STN21'!C16,'STN22'!C16,'STN23'!C16,'STN24'!C16,'STN25'!C16,'STN26'!C16,'STN28'!C16,'STN29'!C16,'STN30'!C16,'STN32'!C16,'STN33'!C16,'STN34'!C16,'STN36'!C16,'STN37'!C16,'STN38'!C16,'STN39'!C16,'STN40'!C16,'STN42'!C16,'STN43'!C16,STN44A!C16,'STN44'!C16,'STN45'!C16,'STN46'!C16,'STN47'!C16,'STN48'!C16,STN48A!C16,'STN49'!C16,'STN50'!C16) -> 92.787234 | D16: =C16/$C$18 -> 0.10756215 | N16: Over 10 | O16: =AVERAGE(STN01A!O16,'Stn 01'!O16,'STN02'!O16,'STN03'!O16,'STN04'!O16,'STN05'!O16,'STN06'!O16,'STN07'!O16,'STN08'!O16,'STN09'!O16,'STN10'!O16,'STN11'!O16,'STN12'!O16,'STN13'!O16,'STN14'!O16,'STN15'!O16,'STN17'!O16,'STN18'!O16,'STN20'!O16,'STN21'!O16,'STN22'!O16,'STN23'!O16,'STN24'!O16,'STN25'!O16,'STN26'!O16,'STN28'!O16,'STN29'!O16,'STN30'!O16,'STN32'!O16,'STN33'!O16,'STN34'!O16,'STN36'!O16,'STN37'!O16,'STN38'!O16,'STN39'!O16,'STN40'!O16,'STN42'!O16,'STN43'!O16,STN44A!O16,'STN44'!O16,'STN45'!O16,'STN46'!O16,'STN47'!O16,'STN48'!O16,STN48A!O16,'STN49'!O16,'STN50'!O16) -> 764.89362 | P16: =O16-O15 -> 2.3829787 | Q16: =P16/$O$16 -> 0.0031154381
B17: Tractors | C17: =AVERAGE(STN01A!C17,'Stn 01'!C17,'STN02'!C17,'STN03'!C17,'STN04'!C17,'STN05'!C17,'STN06'!C17,'STN07'!C17,'STN08'!C17,'STN09'!C17,'STN10'!C17,'STN11'!C17,'STN12'!C17,'STN13'!C17,'STN14'!C17,'STN15'!C17,'STN17'!C17,'STN18'!C17,'STN20'!C17,'STN21'!C17,'STN22'!C17,'STN23'!C17,'STN24'!C17,'STN25'!C17,'STN26'!C17,'STN28'!C17,'STN29'!C17,'STN30'!C17,'STN32'!C17,'STN33'!C17,'STN34'!C17,'STN36'!C17,'STN37'!C17,'STN38'!C17,'STN39'!C17,'STN40'!C17,'STN42'!C17,'STN43'!C17,STN44A!C17,'STN44'!C17,'STN45'!C17,'STN46'!C17,'STN47'!C17,'STN48'!C17,STN48A!C17,'STN49'!C17,'STN50'!C17) -> 0.91489362 | D17: =C17/$C$18 -> 0.0010605762
B18: Average | C18: =SUM(C6:C17) -> 862.6383
N22: Trip Frequency
B23: Journey Purpose | N23: Trip Frequency | O23: No of Vehicles | P23: No. of Vehicles, %
B24: Purpose | C24: Respondents | D24: Percent | N24: More than 2 times every day | O24: =AVERAGE(STN01A!O24,'Stn 01'!O24,'STN02'!O24,'STN03'!O24,'STN04'!O24,'STN05'!O24,'STN06'!O24,'STN07'!O24,'STN08'!O24,'STN09'!O24,'STN10'!O24,'STN11'!O24,'STN12'!O24,'STN13'!O24,'STN14'!O24,'STN15'!O24,'STN17'!O24,'STN18'!O24,'STN20'!O24,'STN21'!O24,'STN22'!O24,'STN23'!O24,'STN24'!O24,'STN25'!O24,'STN26'!O24,'STN28'!O24,'STN29'!O24,'STN30'!O24,'STN32'!O24,'STN33'!O24,'STN34'!O24,'STN36'!O24,'STN37'!O24,'STN38'!O24,'STN39'!O24,'STN40'!O24,'STN42'!O24,'STN43'!O24,STN44A!O24,'STN44'!O24,'STN45'!O24,'STN46'!O24,'STN47'!O24,'STN48'!O24,STN48A!O24,'STN49'!O24,'STN50'!O24) -> 231.29787 | P24: =O24/$O$30 -> 0.27060463
B25: Home-Work | C25: 139.29167 | D25: =C25/$C$30 -> 0.16147169 | N25: Daily (Up and Down) | O25: =AVERAGE(STN01A!O25,'Stn 01'!O25,'STN02'!O25,'STN03'!O25,'STN04'!O25,'STN05'!O25,'STN06'!O25,'STN07'!O25,'STN08'!O25,'STN09'!O25,'STN10'!O25,'STN11'!O25,'STN12'!O25,'STN13'!O25,'STN14'!O25,'STN15'!O25,'STN17'!O25,'STN18'!O25,'STN20'!O25,'STN21'!O25,'STN22'!O25,'STN23'!O25,'STN24'!O25,'STN25'!O25,'STN26'!O25,'STN28'!O25,'STN29'!O25,'STN30'!O25,'STN32'!O25,'STN33'!O25,'STN34'!O25,'STN36'!O25,'STN37'!O25,'STN38'!O25,'STN39'!O25,'STN40'!O25,'STN42'!O25,'STN43'!O25,STN44A!O25,'STN44'!O25,'STN45'!O25,'STN46'!O25,'STN47'!O25,'STN48'!O25,STN48A!O25,'STN49'!O25,'STN50'!O25) -> 366.25532 | P25: =O25/$O$30 -> 0.42849675
B26: Home-Study | C26: 6.1041667 | D26: =C26/$C$30 -> 0.0070761601 | N26: 2/3 times a week | O26: =AVERAGE(STN01A!O26,'Stn 01'!O26,'STN02'!O26,'STN03'!O26,'STN04'!O26,'STN05'!O26,'STN06'!O26,'STN07'!O26,'STN08'!O26,'STN09'!O26,'STN10'!O26,'STN11'!O26,'STN12'!O26,'STN13'!O26,'STN14'!O26,'STN15'!O26,'STN17'!O26,'STN18'!O26,'STN20'!O26,'STN21'!O26,'STN22'!O26,'STN23'!O26,'STN24'!O26,'STN25'!O26,'STN26'!O26,'STN28'!O26,'STN29'!O26,'STN30'!O26,'STN32'!O26,'STN33'!O26,'STN34'!O26,'STN36'!O26,'STN37'!O26,'STN38'!O26,'STN39'!O26,'STN40'!O26,'STN42'!O26,'STN43'!O26,STN44A!O26,'STN44'!O26,'STN45'!O26,'STN46'!O26,'STN47'!O26,'STN48'!O26,STN48A!O26,'STN49'!O26,'STN50'!O26) -> 94.340426 | P26: =O26/$O$30 -> 0.11037264
B27: Work-Home | C27: 74.833333 | D27: =C27/$C$30 -> 0.086749375 | N27: Once a week | O27: =AVERAGE(STN01A!O27,'Stn 01'!O27,'STN02'!O27,'STN03'!O27,'STN04'!O27,'STN05'!O27,'STN06'!O27,'STN07'!O27,'STN08'!O27,'STN09'!O27,'STN10'!O27,'STN11'!O27,'STN12'!O27,'STN13'!O27,'STN14'!O27,'STN15'!O27,'STN17'!O27,'STN18'!O27,'STN20'!O27,'STN21'!O27,'STN22'!O27,'STN23'!O27,'STN24'!O27,'STN25'!O27,'STN26'!O27,'STN28'!O27,'STN29'!O27,'STN30'!O27,'STN32'!O27,'STN33'!O27,'STN34'!O27,'STN36'!O27,'STN37'!O27,'STN38'!O27,'STN39'!O27,'STN40'!O27,'STN42'!O27,'STN43'!O27,STN44A!O27,'STN44'!O27,'STN45'!O27,'STN46'!O27,'STN47'!O27,'STN48'!O27,STN48A!O27,'STN49'!O27,'STN50'!O27) -> 60.106383 | P27: =O27/$O$30 -> 0.070320862
B28: Work-Work | C28: 69.6875 | D28: =C28/$C$30 -> 0.080784148 | N28: Once a month | O28: =AVERAGE(STN01A!O28,'Stn 01'!O28,'STN02'!O28,'STN03'!O28,'STN04'!O28,'STN05'!O28,'STN06'!O28,'STN07'!O28,'STN08'!O28,'STN09'!O28,'STN10'!O28,'STN11'!O28,'STN12'!O28,'STN13'!O28,'STN14'!O28,'STN15'!O28,'STN17'!O28,'STN18'!O28,'STN20'!O28,'STN21'!O28,'STN22'!O28,'STN23'!O28,'STN24'!O28,'STN25'!O28,'STN26'!O28,'STN28'!O28,'STN29'!O28,'STN30'!O28,'STN32'!O28,'STN33'!O28,'STN34'!O28,'STN36'!O28,'STN37'!O28,'STN38'!O28,'STN39'!O28,'STN40'!O28,'STN42'!O28,'STN43'!O28,STN44A!O28,'STN44'!O28,'STN45'!O28,'STN46'!O28,'STN47'!O28,'STN48'!O28,STN48A!O28,'STN49'!O28,'STN50'!O28) -> 27.851064 | P28: =O28/$O$30 -> 0.032584074
B29: Others | C29: 573.60417 | D29: =C29/$C$30 -> 0.66494169 | N29: Once in a while | O29: =AVERAGE(STN01A!O29,'Stn 01'!O29,'STN02'!O29,'STN03'!O29,'STN04'!O29,'STN05'!O29,'STN06'!O29,'STN07'!O29,'STN08'!O29,'STN09'!O29,'STN10'!O29,'STN11'!O29,'STN12'!O29,'STN13'!O29,'STN14'!O29,'STN15'!O29,'STN17'!O29,'STN18'!O29,'STN20'!O29,'STN21'!O29,'STN22'!O29,'STN23'!O29,'STN24'!O29,'STN25'!O29,'STN26'!O29,'STN28'!O29,'STN29'!O29,'STN30'!O29,'STN32'!O29,'STN33'!O29,'STN34'!O29,'STN36'!O29,'STN37'!O29,'STN38'!O29,'STN39'!O29,'STN40'!O29,'STN42'!O29,'STN43'!O29,STN44A!O29,'STN44'!O29,'STN45'!O29,'STN46'!O29,'STN47'!O29,'STN48'!O29,STN48A!O29,'STN49'!O29,'STN50'!O29) -> 74.893617 | P29: =O29/$O$30 -> 0.087621039
B30: Average | C30: =C18 -> 862.6383 | N30: Total | O30: =SUM(O24:O29) -> 854.74468
B41: Expressway Use
B42: Response | C42: Number | D42: Percent
B43: Yes | C43: =AVERAGE(STN01A!C43,'Stn 01'!C43,'STN02'!C43,'STN03'!C43,'STN04'!C43,'STN05'!C43,'STN06'!C43,'STN07'!C43,'STN08'!C43,'STN09'!C43,'STN10'!C43,'STN11'!C43,'STN12'!C43,'STN13'!C43,'STN14'!C43,'STN15'!C43,'STN17'!C43,'STN18'!C43,'STN20'!C43,'STN21'!C43,'STN22'!C43,'STN23'!C43,'STN24'!C43,'STN25'!C43,'STN26'!C43,'STN28'!C43,'STN29'!C43,'STN30'!C43,'STN32'!C43,'STN33'!C43,'STN34'!C43,'STN36'!C43,'STN37'!C43,'STN38'!C43,'STN39'!C43,'STN40'!C43,'STN42'!C43,'STN43'!C43,STN44A!C43,'STN44'!C43,'STN45'!C43,'STN46'!C43,'STN47'!C43,'STN48'!C43,STN48A!C43,'STN49'!C43,'STN50'!C43) -> 749.68085 | D43: =C43/$C$45 -> 0.86905584 | N43: Vehicle Types | O43: Average Occupancy
B44: No | C44: =AVERAGE(STN01A!C44,'Stn 01'!C44,'STN02'!C44,'STN03'!C44,'STN04'!C44,'STN05'!C44,'STN06'!C44,'STN07'!C44,'STN08'!C44,'STN09'!C44,'STN10'!C44,'STN11'!C44,'STN12'!C44,'STN13'!C44,'STN14'!C44,'STN15'!C44,'STN17'!C44,'STN18'!C44,'STN20'!C44,'STN21'!C44,'STN22'!C44,'STN23'!C44,'STN24'!C44,'STN25'!C44,'STN26'!C44,'STN28'!C44,'STN29'!C44,'STN30'!C44,'STN32'!C44,'STN33'!C44,'STN34'!C44,'STN36'!C44,'STN37'!C44,'STN38'!C44,'STN39'!C44,'STN40'!C44,'STN42'!C44,'STN43'!C44,STN44A!C44,'STN44'!C44,'STN45'!C44,'STN46'!C44,'STN47'!C44,'STN48'!C44,STN48A!C44,'STN49'!C44,'STN50'!C44) -> 112.95745 | D44: =C44/$C$45 -> 0.13094416 | N44: Car | O44: =AVERAGE('STN50'!N44,'STN49'!N44,STN48A!N44,'STN47'!N44,'STN46'!N44,'STN45'!O44,'STN44'!N44,STN44A!N44,'STN43'!N44,'STN42'!N44,'STN40'!N44,'STN39'!N44,'STN38'!N44,'STN37'!N44,'STN36'!O44,'STN34'!O44,'STN33'!O44,'STN32'!O44,'STN30'!O44,'STN29'!O44,'STN28'!O44,'STN26'!O44,'STN25'!O44,'STN24'!O44,'STN23'!O44,'STN22'!O44,'STN21'!O44,'STN20'!O44,'STN18'!O46,'STN17'!O44,'STN15'!O44,'STN14'!O44,'STN13'!O44,'STN12'!O44,'STN11'!O44,'STN10'!O44,'STN09'!O44,'STN08'!O44,'STN07'!O44,'STN06'!O44,'STN05'!O45,'STN04'!O44,'STN03'!O46,'STN02'!O46,'Stn 01'!O46,STN01A!N44) -> 2.0593263
B45: Total | C45: =C30 -> 862.6383 | N45: Station Wagon | O45: =AVERAGE('STN50'!N45,'STN49'!N45,STN48A!N45,'STN47'!N45,'STN46'!N45,'STN45'!O45,'STN44'!N45,STN44A!N45,'STN43'!N45,'STN42'!N45,'STN40'!N45,'STN39'!N45,'STN38'!N45,'STN37'!N45,'STN36'!O45,'STN34'!O45,'STN33'!O45,'STN32'!O45,'STN30'!O45,'STN29'!O45,'STN28'!O45,'STN26'!O45,'STN25'!O45,'STN24'!O45,'STN23'!O45,'STN22'!O45,'STN21'!O45,'STN20'!O45,'STN18'!O47,'STN17'!O45,'STN15'!O45,'STN14'!O45,'STN13'!O45,'STN12'!O45,'STN11'!O45,'STN10'!O45,'STN09'!O45,'STN08'!O45,'STN07'!O45,'STN06'!O45,'STN05'!O46,'STN04'!O45,'STN03'!O47,'STN02'!O47,'Stn 01'!O47,STN01A!N45) -> 2.2665146
N46: Pickups | O46: =AVERAGE('STN50'!N46,'STN49'!N46,STN48A!N46,'STN47'!N46,'STN46'!N46,'STN45'!O46,'STN44'!N46,STN44A!N46,'STN43'!N46,'STN42'!N46,'STN40'!N46,'STN39'!N46,'STN38'!N46,'STN37'!N46,'STN36'!O46,'STN34'!O46,'STN33'!O46,'STN32'!O46,'STN30'!O46,'STN29'!O46,'STN28'!O46,'STN26'!O46,'STN25'!O46,'STN24'!O46,'STN23'!O46,'STN22'!O46,'STN21'!O46,'STN20'!O46,'STN18'!O48,'STN17'!O46,'STN15'!O46,'STN14'!O46,'STN13'!O46,'STN12'!O46,'STN11'!O46,'STN10'!O46,'STN09'!O46,'STN08'!O46,'STN07'!O46,'STN06'!O46,'STN05'!O47,'STN04'!O46,'STN03'!O48,'STN02'!O48,'Stn 01'!O48,STN01A!N46) -> 2.085929
N47: Minibus, matatu | O47: =AVERAGE('STN50'!N47,'STN49'!N47,STN48A!N47,'STN47'!N47,'STN46'!N47,'STN45'!O47,'STN44'!N47,STN44A!N47,'STN43'!N47,'STN42'!N47,'STN40'!N47,'STN39'!N47,'STN38'!N47,'STN37'!N47,'STN36'!O47,'STN34'!O47,'STN33'!O47,'STN32'!O47,'STN30'!O47,'STN29'!O47,'STN28'!O47,'STN26'!O47,'STN25'!O47,'STN24'!O47,'STN23'!O47,'STN22'!O47,'STN21'!O47,'STN20'!O47,'STN18'!O49,'STN17'!O47,'STN15'!O47,'STN14'!O47,'STN13'!O47,'STN12'!O47,'STN11'!O47,'STN10'!O47,'STN09'!O47,'STN08'!O47,'STN07'!O47,'STN06'!O47,'STN05'!O48,'STN04'!O47,'STN03'!O49,'STN02'!O49,'Stn 01'!O49,STN01A!N47) -> 9.1210091
N48: Medium bus | O48: =AVERAGE('STN50'!N48,'STN49'!N48,STN48A!N48,'STN47'!N48,'STN46'!N48,'STN45'!O48,'STN44'!N48,STN44A!N48,'STN43'!N48,'STN42'!N48,'STN40'!N48,'STN39'!N48,'STN38'!N48,'STN37'!N48,'STN36'!O48,'STN34'!O48,'STN33'!O48,'STN32'!O48,'STN30'!O48,'STN29'!O48,'STN28'!O48,'STN26'!O48,'STN25'!O48,'STN24'!O48,'STN23'!O48,'STN22'!O48,'STN21'!O48,'STN20'!O48,'STN18'!O50,'STN17'!O48,'STN15'!O48,'STN14'!O48,'STN13'!O48,'STN12'!O48,'STN11'!O48,'STN10'!O48,'STN09'!O48,'STN08'!O48,'STN07'!O48,'STN06'!O48,'STN05'!O49,'STN04'!O48,'STN03'!O50,'STN02'!O50,'Stn 01'!O50,STN01A!N48) -> 18.113527
N49: Large Bus | O49: =AVERAGE('STN50'!N49,'STN49'!N49,STN48A!N49,'STN47'!N49,'STN46'!N49,'STN45'!O49,'STN44'!N49,STN44A!N49,'STN43'!N49,'STN42'!N49,'STN40'!N49,'STN39'!N49,'STN38'!N49,'STN37'!N49,'STN36'!O49,'STN34'!O49,'STN33'!O49,'STN32'!O49,'STN30'!O49,'STN29'!O49,'STN28'!O49,'STN26'!O49,'STN25'!O49,'STN24'!O49,'STN23'!O49,'STN22'!O49,'STN21'!O49,'STN20'!O49,'STN18'!O51,'STN17'!O49,'STN15'!O49,'STN14'!O49,'STN13'!O49,'STN12'!O49,'STN11'!O49,'STN10'!O49,'STN09'!O49,'STN08'!O49,'STN07'!O49,'STN06'!O49,'STN05'!O50,'STN04'!O49,'STN03'!O51,'STN02'!O51,'Stn 01'!O51,STN01A!N49) -> 21.740448
N50: Light Truck | O50: =AVERAGE('STN50'!N50,'STN49'!N50,STN48A!N50,'STN47'!N50,'STN46'!N50,'STN45'!O50,'STN44'!N50,STN44A!N50,'STN43'!N50,'STN42'!N50,'STN40'!N50,'STN39'!N50,'STN38'!N50,'STN37'!N50,'STN36'!O50,'STN34'!O50,'STN33'!O50,'STN32'!O50,'STN30'!O50,'STN29'!O50,'STN28'!O50,'STN26'!O50,'STN25'!O50,'STN24'!O50,'STN23'!O50,'STN22'!O50,'STN21'!O50,'STN20'!O50,'STN18'!O52,'STN17'!O50,'STN15'!O50,'STN14'!O50,'STN13'!O50,'STN12'!O50,'STN11'!O50,'STN10'!O50,'STN09'!O50,'STN08'!O50,'STN07'!O50,'STN06'!O50,'STN05'!O51,'STN04'!O50,'STN03'!O52,'STN02'!O52,'Stn 01'!O52,STN01A!N50) -> 2.1589214
N51: Medium Truck | O51: =AVERAGE('STN50'!N51,'STN49'!N51,STN48A!N51,'STN47'!N51,'STN46'!N51,'STN45'!O51,'STN44'!N51,STN44A!N51,'STN43'!N51,'STN42'!N51,'STN40'!N51,'STN39'!N51,'STN38'!N51,'STN37'!N51,'STN36'!O51,'STN34'!O51,'STN33'!O51,'STN32'!O51,'STN30'!O51,'STN29'!O51,'STN28'!O51,'STN26'!O51,'STN25'!O51,'STN24'!O51,'STN23'!O51,'STN22'!O51,'STN21'!O51,'STN20'!O51,'STN18'!O53,'STN17'!O51,'STN15'!O51,'STN14'!O51,'STN13'!O51,'STN12'!O51,'STN11'!O51,'STN10'!O51,'STN09'!O51,'STN08'!O51,'STN07'!O51,'STN06'!O51,'STN05'!O52,'STN04'!O51,'STN03'!O53,'STN02'!O53,'Stn 01'!O53,STN01A!N51) -> 2.3210391
N52: Heavy truck | O52: =AVERAGE('STN50'!N52,'STN49'!N52,STN48A!N52,'STN47'!N52,'STN46'!N52,'STN45'!O52,'STN44'!N52,STN44A!N52,'STN43'!N52,'STN42'!N52,'STN40'!N52,'STN39'!N52,'STN38'!N52,'STN37'!N52,'STN36'!O52,'STN34'!O52,'STN33'!O52,'STN32'!O52,'STN30'!O52,'STN29'!O52,'STN28'!O52,'STN26'!O52,'STN25'!O52,'STN24'!O52,'STN23'!O52,'STN22'!O52,'STN21'!O52,'STN20'!O52,'STN18'!O54,'STN17'!O52,'STN15'!O52,'STN14'!O52,'STN13'!O52,'STN12'!O52,'STN11'!O52,'STN10'!O52,'STN09'!O52,'STN08'!O52,'STN07'!O52,'STN06'!O52,'STN05'!O53,'STN04'!O52,'STN03'!O54,'STN02'!O54,'Stn 01'!O54,STN01A!N52) -> 2.4219846
N53: Truck Trailer | O53: =AVERAGE('STN50'!N53,'STN49'!N53,STN48A!N53,'STN47'!N53,'STN46'!N53,'STN45'!O53,'STN44'!N53,STN44A!N53,'STN43'!N53,'STN42'!N53,'STN40'!N53,'STN39'!N53,'STN38'!N53,'STN37'!N53,'STN36'!O53,'STN34'!O53,'STN33'!O53,'STN32'!O53,'STN30'!O53,'STN29'!O53,'STN28'!O53,'STN26'!O53,'STN25'!O53,'STN24'!O53,'STN23'!O53,'STN22'!O53,'STN21'!O53,'STN20'!O53,'STN18'!O55,'STN17'!O53,'STN15'!O53,'STN14'!O53,'STN13'!O53,'STN12'!O53,'STN11'!O53,'STN10'!O53,'STN09'!O53,'STN08'!O53,'STN07'!O53,'STN06'!O53,'STN05'!O54,'STN04'!O53,'STN03'!O55,'STN02'!O55,'Stn 01'!O55,STN01A!N53) -> 1.6883554
N54: Motor cycles | O54: =AVERAGE('STN50'!N54,'STN49'!N54,STN48A!N54,'STN47'!N54,'STN46'!N54,'STN45'!O54,'STN44'!N54,STN44A!N54,'STN43'!N54,'STN42'!N54,'STN40'!N54,'STN39'!N54,'STN38'!N54,'STN37'!N54,'STN36'!O54,'STN34'!O54,'STN33'!O54,'STN32'!O54,'STN30'!O54,'STN29'!O54,'STN28'!O54,'STN26'!O54,'STN25'!O54,'STN24'!O54,'STN23'!O54,'STN22'!O54,'STN21'!O54,'STN20'!O54,'STN18'!O56,'STN17'!O54,'STN15'!O54,'STN14'!O54,'STN13'!O54,'STN12'!O54,'STN11'!O54,'STN10'!O54,'STN09'!O54,'STN08'!O54,'STN07'!O54,'STN06'!O54,'STN05'!O55,'STN04'!O54,'STN03'!O56,'STN02'!O56,'Stn 01'!O56,STN01A!N54) -> 1.3382586
N55: Tractors | O55: =AVERAGE('STN50'!N55,'STN49'!N55,STN48A!N55,'STN47'!N55,'STN46'!N55,'STN45'!O55,'STN44'!N55,STN44A!N55,'STN43'!N55,'STN42'!N55,'STN40'!N55,'STN39'!N55,'STN38'!N55,'STN37'!N55,'STN36'!O55,'STN34'!O55,'STN33'!O55,'STN32'!O55,'STN30'!O55,'STN29'!O55,'STN28'!O55,'STN26'!O55,'STN25'!O55,'STN24'!O55,'STN23'!O55,'STN22'!O55,'STN21'!O55,'STN20'!O55,'STN18'!O57,'STN17'!O55,'STN15'!O55,'STN14'!O55,'STN13'!O55,'STN12'!O55,'STN11'!O55,'STN10'!O55,'STN09'!O55,'STN08'!O55,'STN07'!O55,'STN06'!O55,'STN05'!O56,'STN04'!O55,'STN03'!O57,'STN02'!O57,'Stn 01'!O57,STN01A!N55) -> 0.87272727
N56: Total | O56: =SUM(O44:O55) -> 66.188041
...

Sheet STN01A
B2: STN01A OD ANALYSIS
B4: Vehicle OD Sample Proportions | N4: Average Journey Time
B5: Vehicle Types | C5: OD Sample | D5: OD Sample, % | N5: Journey Time Range (Hrs) | O5: Cummu-lative | P5: No of Vehicles | Q5: No. of Vehicles, %
B6: Car | C6: 728 | D6: =C6/$C$18 -> 0.44309191 | N6: 0-0.25 | O6: 308 | P6: =O6 -> 308 | Q6: =P6/$O$16 -> 0.21038251
B7: Station Wagon | C7: 100 | D7: =C7/$C$18 -> 0.060864273 | N7: 0.25-0.50 | O7: 827 | P7: =O7-O6 -> 519 | Q7: =P7/$O$16 -> 0.3545082
B8: Pickups | C8: 60 | D8: =C8/$C$18 -> 0.036518564 | N8: 0.50-0.75 | O8: 1019 | P8: =O8-O7 -> 192 | Q8: =P8/$O$16 -> 0.13114754
B9: Minibus, matatu | C9: 306 | D9: =C9/$C$18 -> 0.18624467 | N9: 0.75-1.00 | O9: 1305 | P9: =O9-O8 -> 286 | Q9: =P9/$O$16 -> 0.19535519
B10: Medium bus | C10: 11 | D10: =C10/$C$18 -> 0.00669507 | N10: 1.00-1.50 | O10: 1347 | P10: =O10-O9 -> 42 | Q10: =P10/$O$16 -> 0.028688525
B11: Large Bus | C11: 2 | D11: =C11/$C$18 -> 0.0012172855 | N11: 1.5-2.0 | O11: 1407 | P11: =O11-O10 -> 60 | Q11: =P11/$O$16 -> 0.040983607
B12: Light Truck | C12: 123 | D12: =C12/$C$18 -> 0.074863055 | N12: 2.0-3.0 | O12: 1436 | P12: =O12-O11 -> 29 | Q12: =P12/$O$16 -> 0.019808743
B13: Medium Truck | C13: 50 | D13: =C13/$C$18 -> 0.030432136 | N13: 3.0-5.0 | O13: 1454 | P13: =O13-O12 -> 18 | Q13: =P13/$O$16 -> 0.012295082
B14: Heavy truck | C14: 14 | D14: =C14/$C$18 -> 0.0085209982 | N14: 5.0-7.5 | O14: 1461 | P14: =O14-O13 -> 7 | Q14: =P14/$O$16 -> 0.0047814208
B15: Truck Trailer | C15: 3 | D15: =C15/$C$18 -> 0.0018259282 | N15: 7.5-10 | O15: 1463 | P15: =O15-O14 -> 2 | Q15: =P15/$O$16 -> 0.0013661202
B16: Motor cycles | C16: 245 | D16: =C16/$C$18 -> 0.14911747 | N16: Over 10 | O16: 1464 | P16: =O16-O15 -> 1 | Q16: =P16/$O$16 -> 0.00068306011
B17: Tractors | C17: 1 | D17: =C17/$C$18 -> 0.00060864273
B18: Total | C18: =SUM(C6:C17) -> 1643
B19: ADT | C19: 35950 | D19: =C18/C19 -> 0.045702364
N22: Trip Frequency
B23: Journey Purpose | N23: Trip Frequency | O23: No of Vehicles | P23: No. of Vehicles, %
B24: Purpose | C24: Respondents | D24: Percent | N24: More than 2 times every day | O24: 593 | P24: =O24/$O$30 -> 5.7019231
B25: Home-Work | C25: 301 | D25: =C25/$C$30 -> 0.18320146 | N25: Daily (Up and Down) | O25: 543 | P25: =O25/$O$30 -> 5.2211538
B26: Home-Study | C26: 2 | D26: =C26/$C$30 -> 0.0012172855 | N26: 2/3 times a week | O26: 179 | P26: =O26/$O$30 -> 1.7211538
B27: Work-Home | C27: 43 | D27: =C27/$C$30 -> 0.026171637 | N27: Once a week | O27: 593 | P27: =O27/$O$30 -> 5.7019231
B28: Work-Work | C28: 68 | D28: =C28/$C$30 -> 0.041387705 | N28: Once a month | O28: 543 | P28: =O28/$O$30 -> 5.2211538
B29: Others | C29: 1229 | D29: =C29/$C$30 -> 0.74802191 | N29: Once in a while | O29: 179 | P29: =O29/$O$30 -> 1.7211538
B30: Total | C30: =C18 -> 1643 | N30: Total | O30: 104
O31: 35
O32: 110
B41: Expressway Use
B42: Response | C42: Number | D42: Percent
B43: Yes | C43: 1612 | D43: =C43/$C$45 -> 0.98113208 | M43: Vehicle Types | N43: Average Occupancy
B44: No | C44: 31 | D44: =C44/$C$45 -> 0.018867925 | M44: Car | N44: =AVERAGE('[47]ALL DATA'!$E$9:$E$736) -> 2.3791209
B45: Total | C45: =C30 -> 1643 | M45: Station Wagon | N45: =AVERAGE('[47]ALL DATA'!$E$737:$E$836) -> 2.53
M46: Pickups | N46: =AVERAGE('[47]ALL DATA'!$E$837:$E$896) -> 2.5
M47: Minibus, matatu | N47: =AVERAGE('[47]ALL DATA'!$E$897:$E$1202) -> 8.6960784
M48: Medium bus | N48: =AVERAGE('[47]ALL DATA'!$E$1203:$E$1215) -> 12.076923
M49: Large Bus | N49: =AVERAGE('[47]ALL DATA'!$E$1214:$E$1215) -> 6
M50: Light Truck | N50: =AVERAGE('[47]ALL DATA'!$E$1216:$E$1338) -> 1.9268293
M51: Medium Truck | N51: =AVERAGE('[47]ALL DATA'!$E$1339:$E$1388) -> 2.46
M52: Heavy truck | N52: =AVERAGE('[47]ALL DATA'!$E$1389:$E$1401) -> 2.2307692
...

Sheet Stn 01
B2: STN01 OD ANALYSIS
B4: Vehicle OD Sample Proportions | N4: Average Journey Time
B5: Vehicle Types | C5: OD Sample | D5: OD Sample, % | N5: Journey Time Range (Hrs) | O5: Cummu-lative | P5: No of Vehicles | Q5: No. of Vehicles, %
B6: Car | C6: 479 | D6: =C6/$C$18 -> 0.34263233 | N6: 0-0.25 | O6: 363 | P6: =O6 -> 363 | Q6: =P6/$O$16 -> 0.31842105
B7: Station Wagon | C7: 104 | D7: =C7/$C$18 -> 0.074391989 | N7: 0.25-0.50 | O7: 737 | P7: =O7-O6 -> 374 | Q7: =P7/$O$16 -> 0.32807018
B8: Pickups | C8: 57 | D8: =C8/$C$18 -> 0.040772532 | N8: 0.50-0.75 | O8: 855 | P8: =O8-O7 -> 118 | Q8: =P8/$O$16 -> 0.10350877
B9: Minibus, matatu | C9: 114 | D9: =C9/$C$18 -> 0.081545064 | N9: 0.75-1.00 | O9: 1008 | P9: =O9-O8 -> 153 | Q9: =P9/$O$16 -> 0.13421053
B10: Medium bus | C10: 7 | D10: =C10/$C$18 -> 0.0050071531 | N10: 1.00-1.50 | O10: 1041 | P10: =O10-O9 -> 33 | Q10: =P10/$O$16 -> 0.028947368
B11: Large Bus | C11: 0 | D11: =C11/$C$18 -> 0 | N11: 1.5-2.0 | O11: 1101 | P11: =O11-O10 -> 60 | Q11: =P11/$O$16 -> 0.052631579
B12: Light Truck | C12: 84 | D12: =C12/$C$18 -> 0.060085837 | N12: 2.0-3.0 | O12: 1124 | P12: =O12-O11 -> 23 | Q12: =P12/$O$16 -> 0.020175439
B13: Medium Truck | C13: 38 | D13: =C13/$C$18 -> 0.027181688 | N13: 3.0-5.0 | O13: 1139 | P13: =O13-O12 -> 15 | Q13: =P13/$O$16 -> 0.013157895
B14: Heavy truck | C14: 6 | D14: =C14/$C$18 -> 0.0042918455 | N14: 5.0-7.5 | O14: 1140 | P14: =O14-O13 -> 1 | Q14: =P14/$O$16 -> 0.00087719298
B15: Truck Trailer | C15: 3 | D15: =C15/$C$18 -> 0.0021459227 | N15: 7.5-10 | O15: 1140 | P15: =O15-O14 -> 0 | Q15: =P15/$O$16 -> 0
B16: Motor cycles | C16: 506 | D16: =C16/$C$18 -> 0.36194564 | N16: Over 10 | O16: 1140 | P16: =O16-O15 -> 0 | Q16: =P16/$O$16 -> 0
B17: Tractors | C17: 0 | D17: =C17/$C$18 -> 0
B18: Total | C18: =SUM(C6:C17) -> 1398
B19: ADT | C19: 38339 | D19: =C18/C19 -> 0.036464175
N22: Trip Frequency
B23: Journey Purpose | N23: Trip Frequency | O23: No of Vehicles | P23: No. of Vehicles, %
B24: Purpose | C24: Respondents | D24: Percent | N24: More than 2 times every day | O24: 489 | P24: =O24/$O$30 -> 0.36222222
B25: Home-Work | C25: 226 | D25: =C25/$C$30 -> 0.16165951 | N25: Daily (Up and Down) | O25: 599 | P25: =O25/$O$30 -> 0.4437037
B26: Home-Study | C26: 6 | D26: =C26/$C$30 -> 0.0042918455 | N26: 2/3 times a week | O26: 85 | P26: =O26/$O$30 -> 0.062962963
B27: Work-Home | C27: 115 | D27: =C27/$C$30 -> 0.082260372 | N27: Once a week | O27: 70 | P27: =O27/$O$30 -> 0.051851852
B28: Work-Work | C28: 59 | D28: =C28/$C$30 -> 0.042203147 | N28: Once a month | O28: 14 | P28: =O28/$O$30 -> 0.01037037
B29: Others | C29: 992 | D29: =C29/$C$30 -> 0.70958512 | N29: Once in a while | O29: 93 | P29: =O29/$O$30 -> 0.068888889
B30: Total | C30: =C18 -> 1398 | N30: Total | O30: =SUM(O24:O29) -> 1350
B41: Expressway Use
B42: Response | C42: Number | D42: Percent
B43: Yes | C43: 1114 | D43: =C43/$C$45 -> 0.79685265
B44: No | C44: 284 | D44: =C44/$C$45 -> 0.20314735
B45: Total | C45: =C30 -> 1398 | N45: Vehicle Types | O45: Average Occupancy
N46: Car | O46: 1.7505285
N47: Station Wagon | O47: 1.9705882
N48: Pickups | O48: 1.7894737
N49: Minibus, matatu | O49: 6.8672566
N50: Medium bus | O50: 4
N51: Large Bus | O51: 0
N52: Light Truck | O52: 1.8095238
N53: Medium Truck | O53: 2.0789474
N54: Heavy truck | O54: 2.1666667
...

Sheet STN02
B2: STN02 OD ANALYSIS
B4: Vehicle OD Sample Proportions | N4: Average Journey Time
B5: Vehicle Types | C5: OD Sample | D5: OD Sample, % | N5: Journey Time Range (Hrs) | O5: Cummu-lative | P5: No of Vehicles | Q5: No. of Vehicles, %
B6: Car | C6: 504 | D6: =C6/$C$18 -> 0.34169492 | N6: 0-0.25 | O6: 73 | P6: =O6 -> 73 | Q6: =P6/$O$16 -> 0.063368056
B7: Station Wagon | C7: 95 | D7: =C7/$C$18 -> 0.06440678 | N7: 0.25-0.50 | O7: 462 | P7: =O7-O6 -> 389 | Q7: =P7/$O$16 -> 0.33767361
B8: Pickups | C8: 79 | D8: =C8/$C$18 -> 0.053559322 | N8: 0.50-0.75 | O8: 607 | P8: =O8-O7 -> 145 | Q8: =P8/$O$16 -> 0.12586806
B9: Minibus, matatu | C9: 321 | D9: =C9/$C$18 -> 0.21762712 | N9: 0.75-1.00 | O9: 886 | P9: =O9-O8 -> 279 | Q9: =P9/$O$16 -> 0.2421875
B10: Medium bus | C10: 42 | D10: =C10/$C$18 -> 0.028474576 | N10: 1.00-1.50 | O10: 997 | P10: =O10-O9 -> 111 | Q10: =P10/$O$16 -> 0.096354167
B11: Large Bus | C11: 9 | D11: =C11/$C$18 -> 0.0061016949 | N11: 1.5-2.0 | O11: 1089 | P11: =O11-O10 -> 92 | Q11: =P11/$O$16 -> 0.079861111
B12: Light Truck | C12: 141 | D12: =C12/$C$18 -> 0.09559322 | N12: 2.0-3.0 | O12: 1117 | P12: =O12-O11 -> 28 | Q12: =P12/$O$16 -> 0.024305556
B13: Medium Truck | C13: 86 | D13: =C13/$C$18 -> 0.058305085 | N13: 3.0-5.0 | O13: 1138 | P13: =O13-O12 -> 21 | Q13: =P13/$O$16 -> 0.018229167
B14: Heavy truck | C14: 21 | D14: =C14/$C$18 -> 0.014237288 | N14: 5.0-7.5 | O14: 1148 | P14: =O14-O13 -> 10 | Q14: =P14/$O$16 -> 0.0086805556
B15: Truck Trailer | C15: 10 | D15: =C15/$C$18 -> 0.006779661 | N15: 7.5-10 | O15: 1148 | P15: =O15-O14 -> 0 | Q15: =P15/$O$16 -> 0
B16: Motor cycles | C16: 166 | D16: =C16/$C$18 -> 0.11254237 | N16: Over 10 | O16: 1152 | P16: =O16-O15 -> 4 | Q16: =P16/$O$16 -> 0.0034722222
B17: Tractors | C17: 1 | D17: =C17/$C$18 -> 0.0006779661
B18: Total | C18: =SUM(C6:C17) -> 1475
B19: ADT | C19: 71610 | D19: =C18/C19 -> 0.020597682
N22: Trip Frequency
B23: Journey Purpose | N23: Trip Frequency | O23: No of Vehicles | P23: No. of Vehicles, %
B24: Purpose | C24: Respondents | D24: Percent | N24: More than 2 times every day | O24: 419 | P24: =O24/$O$30 -> 0.29716312
B25: Home-Work | C25: 172 | D25: =C25/$C$30 -> 0.11661017 | N25: Daily (Up and Down) | O25: 595 | P25: =O25/$O$30 -> 0.42198582
B26: Home-Study | C26: 10 | D26: =C26/$C$30 -> 0.006779661 | N26: 2/3 times a week | O26: 203 | P26: =O26/$O$30 -> 0.14397163
B27: Work-Home | C27: 76 | D27: =C27/$C$30 -> 0.051525424 | N27: Once a week | O27: 69 | P27: =O27/$O$30 -> 0.04893617
B28: Work-Work | C28: 58 | D28: =C28/$C$30 -> 0.039322034 | N28: Once a month | O28: 32 | P28: =O28/$O$30 -> 0.022695035
B29: Others | C29: 1159 | D29: =C29/$C$30 -> 0.78576271 | N29: Once in a while | O29: 92 | P29: =O29/$O$30 -> 0.065248227
B30: Total | C30: =C18 -> 1475 | N30: Total | O30: =SUM(O24:O29) -> 1410
B41: Expressway Use
B42: Response | C42: Number | D42: Percent
B43: Yes | C43: 1185 | D43: =C43/$C$45 -> 0.80338983
B44: No | C44: 290 | D44: =C44/$C$45 -> 0.19661017
B45: Total | C45: =C30 -> 1475 | N45: Vehicle Types | O45: Average Occupancy
N46: Car | O46: 1.9114688
N47: Station Wagon | O47: 1.7659574
N48: Pickups | O48: 2.2179487
N49: Minibus, matatu | O49: 12.388715
N50: Medium bus | O50: 26.02381
N51: Large Bus | O51: 38.875
N52: Light Truck | O52: 2.141844
N53: Medium Truck | O53: 2.3176471
N54: Heavy truck | O54: 2.4285714
...

Sheet STN03
B2: STN03 OD ANALYSIS
B4: Vehicle OD Sample Proportions | N4: Average Journey Time
B5: Vehicle Types | C5: OD Sample | D5: OD Sample, % | N5: Journey Time Range (Hrs) | O5: Cummu-lative | P5: No of Vehicles | Q5: No. of Vehicles, %
B6: Car | C6: 266 | D6: =C6/$C$18 -> 0.39820359 | N6: 0-0.25 | O6: 134 | P6: =O6 -> 134 | Q6: =P6/$O$16 -> 0.22750424
B7: Station Wagon | C7: 81 | D7: =C7/$C$18 -> 0.12125749 | N7: 0.25-0.50 | O7: 293 | P7: =O7-O6 -> 159 | Q7: =P7/$O$16 -> 0.26994907
B8: Pickups | C8: 37 | D8: =C8/$C$18 -> 0.055389222 | N8: 0.50-0.75 | O8: 348 | P8: =O8-O7 -> 55 | Q8: =P8/$O$16 -> 0.093378608
B9: Minibus, matatu | C9: 74 | D9: =C9/$C$18 -> 0.11077844 | N9: 0.75-1.00 | O9: 490 | P9: =O9-O8 -> 142 | Q9: =P9/$O$16 -> 0.24108659
B10: Medium bus | C10: 3 | D10: =C10/$C$18 -> 0.004491018 | N10: 1.00-1.50 | O10: 519 | P10: =O10-O9 -> 29 | Q10: =P10/$O$16 -> 0.049235993
B11: Large Bus | C11: 1 | D11: =C11/$C$18 -> 0.001497006 | N11: 1.5-2.0 | O11: 556 | P11: =O11-O10 -> 37 | Q11: =P11/$O$16 -> 0.062818336
B12: Light Truck | C12: 80 | D12: =C12/$C$18 -> 0.11976048 | N12: 2.0-3.0 | O12: 570 | P12: =O12-O11 -> 14 | Q12: =P12/$O$16 -> 0.0237691
B13: Medium Truck | C13: 23 | D13: =C13/$C$18 -> 0.034431138 | N13: 3.0-5.0 | O13: 585 | P13: =O13-O12 -> 15 | Q13: =P13/$O$16 -> 0.025466893
B14: Heavy truck | C14: 7 | D14: =C14/$C$18 -> 0.010479042 | N14: 5.0-7.5 | O14: 587 | P14: =O14-O13 -> 2 | Q14: =P14/$O$16 -> 0.0033955857
B15: Truck Trailer | C15: 1 | D15: =C15/$C$18 -> 0.001497006 | N15: 7.5-10 | O15: 588 | P15: =O15-O14 -> 1 | Q15: =P15/$O$16 -> 0.0016977929
B16: Motor cycles | C16: 95 | D16: =C16/$C$18 -> 0.14221557 | N16: Over 10 | O16: 589 | P16: =O16-O15 -> 1 | Q16: =P16/$O$16 -> 0.0016977929
B17: Tractors | C17: 0 | D17: =C17/$C$18 -> 0
B18: Total | C18: =SUM(C6:C17) -> 668
B19: ADT | C19: 38500 | D19: =C18/C19 -> 0.017350649
N22: Trip Frequency
B23: Journey Purpose | N23: Trip Frequency | O23: No of Vehicles | P23: No. of Vehicles, %
B24: Purpose | C24: Respondents | D24: Percent | N24: More than 2 times every day | O24: 98 | P24: =O24/$O$30 -> 0.14984709
B25: Home-Work | C25: 225 | D25: =C25/$C$30 -> 0.33682635 | N25: Daily (Up and Down) | O25: 390 | P25: =O25/$O$30 -> 0.59633028
B26: Home-Study | C26: 8 | D26: =C26/$C$30 -> 0.011976048 | N26: 2/3 times a week | O26: 57 | P26: =O26/$O$30 -> 0.087155963
B27: Work-Home | C27: 92 | D27: =C27/$C$30 -> 0.13772455 | N27: Once a week | O27: 43 | P27: =O27/$O$30 -> 0.065749235
B28: Work-Work | C28: 15 | D28: =C28/$C$30 -> 0.02245509 | N28: Once a month | O28: 11 | P28: =O28/$O$30 -> 0.016819572
B29: Others | C29: 328 | D29: =C29/$C$30 -> 0.49101796 | N29: Once in a while | O29: 55 | P29: =O29/$O$30 -> 0.084097859
B30: Total | C30: =C18 -> 668 | N30: Total | O30: =SUM(O24:O29) -> 654
B41: Expressway Use
B42: Response | C42: Number | D42: Percent
B43: Yes | C43: 637 | D43: =C43/$C$45 -> 0.95359281
B44: No | C44: 31 | D44: =C44/$C$45 -> 0.046407186
B45: Total | C45: =C30 -> 668 | N45: Vehicle Types | O45: Average Occupancy
N46: Car | O46: 1.948
N47: Station Wagon | O47: 2.1333333
N48: Pickups | O48: 2
N49: Minibus, matatu | O49: 7.3918919
N50: Medium bus | O50: 15.333333
N51: Large Bus | O51: 1
N52: Light Truck | O52: 1.9125
N53: Medium Truck | O53: 2.0869565
N54: Heavy truck | O54: 2
...

Sheet STN04
B2: STN04 OD ANALYSIS
B4: Vehicle OD Sample Proportions | N4: Average Journey Time
B5: Vehicle Types | C5: OD Sample | D5: OD Sample, % | N5: Journey Time Range (Hrs) | O5: Cummu-lative | P5: No of Vehicles | Q5: No. of Vehicles, %
B6: Car | C6: 284 | D6: =C6/$C$18 -> 0.56573705 | N6: 0-0.25 | O6: 88 | P6: =O6 -> 88 | Q6: =P6/$O$16 -> 0.20276498
B7: Station Wagon | C7: 37 | D7: =C7/$C$18 -> 0.073705179 | N7: 0.25-0.50 | O7: 242 | P7: =O7-O6 -> 154 | Q7: =P7/$O$16 -> 0.35483871
B8: Pickups | C8: 35 | D8: =C8/$C$18 -> 0.069721116 | N8: 0.50-0.75 | O8: 277 | P8: =O8-O7 -> 35 | Q8: =P8/$O$16 -> 0.080645161
B9: Minibus, matatu | C9: 54 | D9: =C9/$C$18 -> 0.10756972 | N9: 0.75-1.00 | O9: 375 | P9: =O9-O8 -> 98 | Q9: =P9/$O$16 -> 0.22580645
B10: Medium bus | C10: 2 | D10: =C10/$C$18 -> 0.0039840637 | N10: 1.00-1.50 | O10: 388 | P10: =O10-O9 -> 13 | Q10: =P10/$O$16 -> 0.029953917
B11: Large Bus | C11: 0 | D11: =C11/$C$18 -> 0 | N11: 1.5-2.0 | O11: 413 | P11: =O11-O10 -> 25 | Q11: =P11/$O$16 -> 0.057603687
B12: Light Truck | C12: 39 | D12: =C12/$C$18 -> 0.077689243 | N12: 2.0-3.0 | O12: 422 | P12: =O12-O11 -> 9 | Q12: =P12/$O$16 -> 0.020737327
B13: Medium Truck | C13: 13 | D13: =C13/$C$18 -> 0.025896414 | N13: 3.0-5.0 | O13: 430 | P13: =O13-O12 -> 8 | Q13: =P13/$O$16 -> 0.01843318
B14: Heavy truck | C14: 3 | D14: =C14/$C$18 -> 0.0059760956 | N14: 5.0-7.5 | O14: 431 | P14: =O14-O13 -> 1 | Q14: =P14/$O$16 -> 0.0023041475
B15: Truck Trailer | C15: 0 | D15: =C15/$C$18 -> 0 | N15: 7.5-10 | O15: 434 | P15: =O15-O14 -> 3 | Q15: =P15/$O$16 -> 0.0069124424
B16: Motor cycles | C16: 35 | D16: =C16/$C$18 -> 0.069721116 | N16: Over 10 | O16: 434 | P16: =O16-O15 -> 0 | Q16: =P16/$O$16 -> 0
B17: Tractors | C17: 0 | D17: =C17/$C$18 -> 0
B18: Total | C18: =SUM(C6:C17) -> 502
B19: ADT | C19: 22710 | D19: =C18/C19 -> 0.0221048
N22: Trip Frequency
B23: Journey Purpose | N23: Trip Frequency | O23: No of Vehicles | P23: No. of Vehicles, %
B24: Purpose | C24: Respondents | D24: Percent | N24: More than 2 times every day | O24: 75 | P24: =O24/$O$30 -> 0.15368852
B25: Home-Work | C25: 46 | D25: =C25/$C$30 -> 0.091633466 | N25: Daily (Up and Down) | O25: 266 | P25: =O25/$O$30 -> 0.54508197
B26: Home-Study | C26: 1 | D26: =C26/$C$30 -> 0.0019920319 | N26: 2/3 times a week | O26: 42 | P26: =O26/$O$30 -> 0.086065574
B27: Work-Home | C27: 137 | D27: =C27/$C$30 -> 0.27290837 | N27: Once a week | O27: 15 | P27: =O27/$O$30 -> 0.030737705
B28: Work-Work | C28: 35 | D28: =C28/$C$30 -> 0.069721116 | N28: Once a month | O28: 13 | P28: =O28/$O$30 -> 0.026639344
B29: Others | C29: 283 | D29: =C29/$C$30 -> 0.56374502 | N29: Once in a while | O29: 77 | P29: =O29/$O$30 -> 0.15778689
B30: Total | C30: =C18 -> 502 | O30: =SUM(O24:O29) -> 488
B41: Expressway Use
B42: Response | C42: Number | D42: Percent
B43: Yes | C43: 457 | D43: =C43/$C$45 -> 0.91035857 | N43: Vehicle Types | O43: Average Occupancy
B44: No | C44: 45 | D44: =C44/$C$45 -> 0.089641434 | N44: Car | O44: 1.9741697
B45: Total | C45: =C30 -> 502 | N45: Station Wagon | O45: 2
N46: Pickups | O46: 2.2647059
N47: Minibus, matatu | O47: 7.0185185
N48: Medium bus | O48: 1
N49: Large Bus | O49: 0
N50: Light Truck | O50: 2.1282051
N51: Medium Truck | O51: 2
N52: Heavy truck | O52: 2.6666667
N53: Truck Trailer
N54: Motor cycles | O54: 1.2058824
...

Sheet STN05
B2: STN05 OD ANALYSIS
B4: Vehicle OD Sample Proportions | N4: Average Journey Time
B5: Vehicle Types | C5: OD Sample | D5: OD Sample, % | N5: Journey Time Range (Hrs) | O5: Cummu-lative | P5: No of Vehicles | Q5: No. of Vehicles, %
B6: Car | C6: 390 | D6: =C6/$C$18 -> 0.45348837 | N6: 0-0.25 | O6: 266 | P6: =O6 -> 266 | Q6: =P6/$O$16 -> 0.3388535
B7: Station Wagon | C7: 66 | D7: =C7/$C$18 -> 0.076744186 | N7: 0.25-0.50 | O7: 508 | P7: =O7-O6 -> 242 | Q7: =P7/$O$16 -> 0.30828025
B8: Pickups | C8: 35 | D8: =C8/$C$18 -> 0.040697674 | N8: 0.50-0.75 | O8: 555 | P8: =O8-O7 -> 47 | Q8: =P8/$O$16 -> 0.059872611
B9: Minibus, matatu | C9: 158 | D9: =C9/$C$18 -> 0.18372093 | N9: 0.75-1.00 | O9: 703 | P9: =O9-O8 -> 148 | Q9: =P9/$O$16 -> 0.18853503
B10: Medium bus | C10: 7 | D10: =C10/$C$18 -> 0.0081395349 | N10: 1.00-1.50 | O10: 719 | P10: =O10-O9 -> 16 | Q10: =P10/$O$16 -> 0.020382166
B11: Large Bus | C11: 2 | D11: =C11/$C$18 -> 0.0023255814 | N11: 1.5-2.0 | O11: 751 | P11: =O11-O10 -> 32 | Q11: =P11/$O$16 -> 0.040764331
B12: Light Truck | C12: 52 | D12: =C12/$C$18 -> 0.060465116 | N12: 2.0-3.0 | O12: 765 | P12: =O12-O11 -> 14 | Q12: =P12/$O$16 -> 0.017834395
B13: Medium Truck | C13: 18 | D13: =C13/$C$18 -> 0.020930233 | N13: 3.0-5.0 | O13: 776 | P13: =O13-O12 -> 11 | Q13: =P13/$O$16 -> 0.014012739
B14: Heavy truck | C14: 4 | D14: =C14/$C$18 -> 0.0046511628 | N14: 5.0-7.5 | O14: 780 | P14: =O14-O13 -> 4 | Q14: =P14/$O$16 -> 0.0050955414
B15: Truck Trailer | C15: 0 | D15: =C15/$C$18 -> 0 | N15: 7.5-10 | O15: 784 | P15: =O15-O14 -> 4 | Q15: =P15/$O$16 -> 0.0050955414
B16: Motor cycles | C16: 128 | D16: =C16/$C$18 -> 0.14883721 | N16: Over 10 | O16: 785 | P16: =O16-O15 -> 1 | Q16: =P16/$O$16 -> 0.0012738854
B17: Tractors | C17: 0 | D17: =C17/$C$18 -> 0
B18: Total | C18: =SUM(C6:C17) -> 860
B19: ADT | C19: 30133 | D19: =C18/C19 -> 0.028540139
N22: Trip Frequency
B23: Journey Purpose | N23: Trip Frequency | O23: No of Vehicles | P23: No. of Vehicles, %
B24: Purpose | C24: Respondents | D24: Percent | N24: More than 2 times every day | O24: 253 | P24: =O24/$O$30 -> 0.30263158
B25: Home-Work | C25: 106 | D25: =C25/$C$30 -> 0.12325581 | N25: Daily (Up and Down) | O25: 378 | P25: =O25/$O$30 -> 0.45215311
B26: Home-Study | C26: 5 | D26: =C26/$C$30 -> 0.0058139535 | N26: 2/3 times a week | O26: 82 | P26: =O26/$O$30 -> 0.098086124
B27: Work-Home | C27: 111 | D27: =C27/$C$30 -> 0.12906977 | N27: Once a week | O27: 50 | P27: =O27/$O$30 -> 0.059808612
B28: Work-Work | C28: 33 | D28: =C28/$C$30 -> 0.038372093 | N28: Once a month | O28: 14 | P28: =O28/$O$30 -> 0.016746411
B29: Others | C29: 605 | D29: =C29/$C$30 -> 0.70348837 | N29: Once in a while | O29: 59 | P29: =O29/$O$30 -> 0.070574163
B30: Total | C30: =C18 -> 860 | N30: Total | O30: =SUM(O24:O29) -> 836
B41: Expressway Use
B42: Response | C42: Number | D42: Percent
B43: Yes | C43: 798 | D43: =C43/$C$45 -> 0.92790698
B44: No | C44: 62 | D44: =C44/$C$45 -> 0.072093023 | N44: Vehicle Types | O44: Average Occupancy
B45: Total | C45: =C30 -> 860 | N45: Car | O45: 1.9641026
N46: Station Wagon | O46: 2.2272727
N47: Pickups | O47: 1.9428571
N48: Minibus, matatu | O48: 7.7911392
N49: Medium bus | O49: 17.142857
N50: Large Bus | O50: 5.5
N51: Light Truck | O51: 1.9230769
N52: Medium Truck | O52: 2.5833333
N53: Heavy truck | O53: 7.25
N54: Truck Trailer | O54: 0
...

Sheet STN06
B2: STN06 OD ANALYSIS
B4: Vehicle OD Sample Proportions | N4: Average Journey Time
B5: Vehicle Types | C5: OD Sample | D5: OD Sample, % | N5: Journey Time Range (Hrs) | O5: Cummu-lative | P5: No of Vehicles | Q5: No. of Vehicles, %
B6: Car | C6: 113 | D6: =C6/$C$18 -> 0.39788732 | N6: 0-0.25 | O6: 43 | P6: =O6 -> 43 | Q6: =P6/$O$16 -> 0.15750916
B7: Station Wagon | C7: 18 | D7: =C7/$C$18 -> 0.063380282 | N7: 0.25-0.50 | O7: 114 | P7: =O7-O6 -> 71 | Q7: =P7/$O$16 -> 0.26007326
B8: Pickups | C8: 18 | D8: =C8/$C$18 -> 0.063380282 | N8: 0.50-0.75 | O8: 161 | P8: =O8-O7 -> 47 | Q8: =P8/$O$16 -> 0.17216117
B9: Minibus, matatu | C9: 48 | D9: =C9/$C$18 -> 0.16901408 | N9: 0.75-1.00 | O9: 216 | P9: =O9-O8 -> 55 | Q9: =P9/$O$16 -> 0.2014652
B10: Medium bus | C10: 2 | D10: =C10/$C$18 -> 0.0070422535 | N10: 1.00-1.50 | O10: 226 | P10: =O10-O9 -> 10 | Q10: =P10/$O$16 -> 0.036630037
B11: Large Bus | C11: 0 | D11: =C11/$C$18 -> 0 | N11: 1.5-2.0 | O11: 249 | P11: =O11-O10 -> 23 | Q11: =P11/$O$16 -> 0.084249084
B12: Light Truck | C12: 52 | D12: =C12/$C$18 -> 0.18309859 | N12: 2.0-3.0 | O12: 258 | P12: =O12-O11 -> 9 | Q12: =P12/$O$16 -> 0.032967033
B13: Medium Truck | C13: 19 | D13: =C13/$C$18 -> 0.066901408 | N13: 3.0-5.0 | O13: 267 | P13: =O13-O12 -> 9 | Q13: =P13/$O$16 -> 0.032967033
B14: Heavy truck | C14: 3 | D14: =C14/$C$18 -> 0.01056338 | N14: 5.0-7.5 | O14: 270 | P14: =O14-O13 -> 3 | Q14: =P14/$O$16 -> 0.010989011
B15: Truck Trailer | C15: 6 | D15: =C15/$C$18 -> 0.021126761 | N15: 7.5-10 | O15: 272 | P15: =O15-O14 -> 2 | Q15: =P15/$O$16 -> 0.0073260073
B16: Motor cycles | C16: 5 | D16: =C16/$C$18 -> 0.017605634 | N16: Over 10 | O16: 273 | P16: =O16-O15 -> 1 | Q16: =P16/$O$16 -> 0.0036630037
B17: Tractors | C17: 0 | D17: =C17/$C$18 -> 0
B18: Total | C18: =SUM(C6:C17) -> 284
B19: ADT | C19: 36621 | D19: =C18/C19 -> 0.0077551132
N22: Trip Frequency
B23: Journey Purpose | N23: Trip Frequency | O23: No of Vehicles | P23: No. of Vehicles, %
B24: Purpose | C24: Respondents | D24: Percent | N24: More than 2 times every day | O24: 97 | P24: =O24/$O$30 -> 0.35144928
B25: Home-Work | C25: 59 | D25: =C25/$C$30 -> 0.20774648 | N25: Daily (Up and Down) | O25: 99 | P25: =O25/$O$30 -> 0.35869565
B26: Home-Study | C26: 1 | D26: =C26/$C$30 -> 0.0035211268 | N26: 2/3 times a week | O26: 28 | P26: =O26/$O$30 -> 0.10144928
B27: Work-Home | C27: 11 | D27: =C27/$C$30 -> 0.038732394 | N27: Once a week | O27: 24 | P27: =O27/$O$30 -> 0.086956522
B28: Work-Work | C28: 91 | D28: =C28/$C$30 -> 0.32042254 | N28: Once a month | O28: 5 | P28: =O28/$O$30 -> 0.018115942
B29: Others | C29: 122 | D29: =C29/$C$30 -> 0.42957746 | N29: Once in a while | O29: 23 | P29: =O29/$O$30 -> 0.083333333
B30: Total | C30: =C18 -> 284 | N30: Total | O30: =SUM(O24:O29) -> 276
B41: Expressway Use
B42: Response | C42: Number | D42: Percent
B43: Yes | C43: 265 | D43: =C43/$C$45 -> 0.93309859 | N43: Vehicle Types | O43: Average Occupancy
B44: No | C44: 19 | D44: =C44/$C$45 -> 0.066901408 | N44: Car | O44: 1.7699115
B45: Total | C45: =C30 -> 284 | N45: Station Wagon | O45: 2.3333333
N46: Pickups | O46: 2.0555556
N47: Minibus, matatu | O47: 5.5
N48: Medium bus | O48: 27
N49: Large Bus | O49: 0
N50: Light Truck | O50: 2.2745098
N51: Medium Truck | O51: 2
N52: Heavy truck | O52: 6
N53: Truck Trailer | O53: 1.8333333
N54: Motor cycles | O54: 1
...

Sheet STN07
B2: STN07 OD ANALYSIS
B4: Vehicle OD Sample Proportions | N4: Average Journey Time
B5: Vehicle Types | C5: OD Sample | D5: OD Sample, % | N5: Journey Time Range (Hrs) | O5: Cummu-lative | P5: No of Vehicles | Q5: No. of Vehicles, %
B6: Car | C6: 437 | D6: =C6/$C$18 -> 0.33460949 | N6: 0-0.25 | O6: 214 | P6: =O6 -> 214 | Q6: =P6/$O$16 -> 0.18074324
B7: Station Wagon | C7: 120 | D7: =C7/$C$18 -> 0.091883614 | N7: 0.25-0.50 | O7: 508 | P7: =O7-O6 -> 294 | Q7: =P7/$O$16 -> 0.24831081
B8: Pickups | C8: 68 | D8: =C8/$C$18 -> 0.052067381 | N8: 0.50-0.75 | O8: 567 | P8: =O8-O7 -> 59 | Q8: =P8/$O$16 -> 0.049831081
B9: Minibus, matatu | C9: 138 | D9: =C9/$C$18 -> 0.10566616 | N9: 0.75-1.00 | O9: 795 | P9: =O9-O8 -> 228 | Q9: =P9/$O$16 -> 0.19256757
B10: Medium bus | C10: 18 | D10: =C10/$C$18 -> 0.013782542 | N10: 1.00-1.50 | O10: 869 | P10: =O10-O9 -> 74 | Q10: =P10/$O$16 -> 0.0625
B11: Large Bus | C11: 13 | D11: =C11/$C$18 -> 0.0099540582 | N11: 1.5-2.0 | O11: 975 | P11: =O11-O10 -> 106 | Q11: =P11/$O$16 -> 0.089527027
B12: Light Truck | C12: 150 | D12: =C12/$C$18 -> 0.11485452 | N12: 2.0-3.0 | O12: 1048 | P12: =O12-O11 -> 73 | Q12: =P12/$O$16 -> 0.061655405
B13: Medium Truck | C13: 157 | D13: =C13/$C$18 -> 0.1202144 | N13: 3.0-5.0 | O13: 1110 | P13: =O13-O12 -> 62 | Q13: =P13/$O$16 -> 0.052364865
B14: Heavy truck | C14: 77 | D14: =C14/$C$18 -> 0.058958652 | N14: 5.0-7.5 | O14: 1149 | P14: =O14-O13 -> 39 | Q14: =P14/$O$16 -> 0.032939189
B15: Truck Trailer | C15: 39 | D15: =C15/$C$18 -> 0.029862175 | N15: 7.5-10 | O15: 1168 | P15: =O15-O14 -> 19 | Q15: =P15/$O$16 -> 0.016047297
B16: Motor cycles | C16: 87 | D16: =C16/$C$18 -> 0.06661562 | N16: Over 10 | O16: 1184 | P16: =O16-O15 -> 16 | Q16: =P16/$O$16 -> 0.013513514
B17: Tractors | C17: 2 | D17: =C17/$C$18 -> 0.0015313936
B18: Total | C18: =SUM(C6:C17) -> 1306
B19: ADT | C19: 44712 | D19: =C18/C19 -> 0.029209161
N22: Trip Frequency
B23: Journey Purpose | N23: Trip Frequency | O23: No of Vehicles | P23: No. of Vehicles, %
B24: Purpose | C24: Respondents | D24: Percent | N24: More than 2 times every day | O24: 403 | P24: =O24/$O$30 -> 0.32034976
B25: Home-Work | C25: 236 | D25: =C25/$C$30 -> 0.18070444 | N25: Daily (Up and Down) | O25: 445 | P25: =O25/$O$30 -> 0.35373609
B26: Home-Study | C26: 4 | D26: =C26/$C$30 -> 0.0030627871 | N26: 2/3 times a week | O26: 156 | P26: =O26/$O$30 -> 0.12400636
B27: Work-Home | C27: 76 | D27: =C27/$C$30 -> 0.058192956 | N27: Once a week | O27: 106 | P27: =O27/$O$30 -> 0.084260731
B28: Work-Work | C28: 39 | D28: =C28/$C$30 -> 0.029862175 | N28: Once a month | O28: 43 | P28: =O28/$O$30 -> 0.03418124
B29: Others | C29: 951 | D29: =C29/$C$30 -> 0.72817764 | N29: Once in a while | O29: 105 | P29: =O29/$O$30 -> 0.083465819
B30: Total | C30: =C18 -> 1306 | N30: Total | O30: =SUM(O24:O29) -> 1258
B41: Expressway Use
B42: Response | C42: Number | D42: Percent
B43: Yes | C43: 1132 | D43: =C43/$C$45 -> 0.86676876 | N43: Vehicle Types | O43: Average Occupancy
B44: No | C44: 174 | D44: =C44/$C$45 -> 0.13323124 | N44: Car | O44: 2.1655172
B45: Total | C45: =C30 -> 1306 | N45: Station Wagon | O45: 2.1
N46: Pickups | O46: 2.0735294
N47: Minibus, matatu | O47: 11.272059
N48: Medium bus | O48: 22.5
N49: Large Bus | O49: 44.230769
N50: Light Truck | O50: 2.0347222
N51: Medium Truck | O51: 2.4551282
N52: Heavy truck | O52: 2.025974
N53: Truck Trailer | O53: 1.8974359
N54: Motor cycles | O54: 1.1976744
...

Sheet STN08
B2: STN08 OD ANALYSIS
B4: Vehicle OD Sample Proportions | N4: Average Journey Time
B5: Vehicle Types | C5: OD Sample | D5: OD Sample, % | N5: Journey Time Range (Hrs) | O5: Cummu-lative | P5: No of Vehicles | Q5: No. of Vehicles, %
B6: Car | C6: 86 | D6: =C6/$C$18 -> 0.25595238 | N6: 0-0.25 | O6: 28 | P6: =O6 -> 28 | Q6: =P6/$O$16 -> 0.086687307
B7: Station Wagon | C7: 32 | D7: =C7/$C$18 -> 0.095238095 | N7: 0.25-0.50 | O7: 91 | P7: =O7-O6 -> 63 | Q7: =P7/$O$16 -> 0.19504644
B8: Pickups | C8: 21 | D8: =C8/$C$18 -> 0.0625 | N8: 0.50-0.75 | O8: 127 | P8: =O8-O7 -> 36 | Q8: =P8/$O$16 -> 0.11145511
B9: Minibus, matatu | C9: 112 | D9: =C9/$C$18 -> 0.33333333 | N9: 0.75-1.00 | O9: 205 | P9: =O9-O8 -> 78 | Q9: =P9/$O$16 -> 0.24148607
B10: Medium bus | C10: 5 | D10: =C10/$C$18 -> 0.014880952 | N10: 1.00-1.50 | O10: 249 | P10: =O10-O9 -> 44 | Q10: =P10/$O$16 -> 0.13622291
B11: Large Bus | C11: 6 | D11: =C11/$C$18 -> 0.017857143 | N11: 1.5-2.0 | O11: 284 | P11: =O11-O10 -> 35 | Q11: =P11/$O$16 -> 0.10835913
B12: Light Truck | C12: 24 | D12: =C12/$C$18 -> 0.071428571 | N12: 2.0-3.0 | O12: 309 | P12: =O12-O11 -> 25 | Q12: =P12/$O$16 -> 0.077399381
B13: Medium Truck | C13: 13 | D13: =C13/$C$18 -> 0.038690476 | N13: 3.0-5.0 | O13: 319 | P13: =O13-O12 -> 10 | Q13: =P13/$O$16 -> 0.030959752
B14: Heavy truck | C14: 16 | D14: =C14/$C$18 -> 0.047619048 | N14: 5.0-7.5 | O14: 321 | P14: =O14-O13 -> 2 | Q14: =P14/$O$16 -> 0.0061919505
B15: Truck Trailer | C15: 2 | D15: =C15/$C$18 -> 0.005952381 | N15: 7.5-10 | O15: 323 | P15: =O15-O14 -> 2 | Q15: =P15/$O$16 -> 0.0061919505
B16: Motor cycles | C16: 19 | D16: =C16/$C$18 -> 0.056547619 | N16: Over 10 | O16: 323 | P16: =O16-O15 -> 0 | Q16: =P16/$O$16 -> 0
B17: Tractors | C17: 0 | D17: =C17/$C$18 -> 0
B18: Total | C18: =SUM(C6:C17) -> 336
B19: ADT | C19: 58668 | D19: =C18/C19 -> 0.0057271426
N22: Trip Frequency
B23: Journey Purpose | N23: Trip Frequency | O23: No of Vehicles | P23: No. of Vehicles, %
B24: Purpose | C24: Respondents | D24: Percent | N24: More than 2 times every day | O24: 135 | P24: =O24/$O$30 -> 0.42056075
B25: Home-Work | C25: 23 | D25: =C25/$C$30 -> 0.068452381 | N25: Daily (Up and Down) | O25: 84 | P25: =O25/$O$30 -> 0.26168224
B26: Home-Study | C26: 3 | D26: =C26/$C$30 -> 0.0089285714 | N26: 2/3 times a week | O26: 27 | P26: =O26/$O$30 -> 0.08411215
B27: Work-Home | C27: 44 | D27: =C27/$C$30 -> 0.13095238 | N27: Once a week | O27: 22 | P27: =O27/$O$30 -> 0.068535826
B28: Work-Work | C28: 175 | D28: =C28/$C$30 -> 0.52083333 | N28: Once a month | O28: 8 | P28: =O28/$O$30 -> 0.024922118
B29: Others | C29: 91 | D29: =C29/$C$30 -> 0.27083333 | N29: Once in a while | O29: 45 | P29: =O29/$O$30 -> 0.14018692
B30: Total | C30: =C18 -> 336 | N30: Total | O30: =SUM(O24:O29) -> 321
B41: Expressway Use
B42: Response | C42: Number | D42: Percent
