Workbook

Sheet 29.07 Karuma-Kigumba
B1: Consultancy services for Preparation of Expressway Development Master Plan (EDMP) for Uganda
B2: MANUAL CLASSIFIED COUNT (MCC)
B3: ROAD NAME: | C3: MCC - C5 - STN113 - KIGUMBA-KARUMA ROAD
C5: Date | D5: 29.07.19 | F5: Location | G5: nanda | J5: Surveyor | K5: xxx
C6: Dir. From | D6: karuma | F6: Dir. To | G6: kigumba | J6: Supervisor | K6: xxx
B8: Time / Veh Type | R8: SUMMARY TRAFFIC VOLUMES
C9: 1. Car | D9: 2. Station Wagon | E9: 3. Pickups | F9: 4. Minibus, matatu | G9: 5. Medium bus | H9: 6. Large Bus | I9: 7. Light Truck | J9: 8. Medium Truck | K9: 9. Heavy truck | L9: 10. Truck Trailer | M9: 11. Motor cycles | N9: 12. Tractors | O9: Total Excl M/Cycles | P9: Total All | R9: Time | S9: 1. Car | T9: 2. Station Wagon | U9: 3. Pickups | V9: 4. Minibus, matatu | W9: 5. Medium bus | X9: 6. Large Bus | Y9: 7. Light Truck | Z9: 8. Medium Truck | AA9: 9. Heavy truck | AB9: 10. Truck Trailer | AC9: 11. Motorcycles | AD9: 12. Tractors, Graders | AE9: Total Excl M/ Cycles | AF9: Total All
B10: 07.00 - 07.15 | C10: 2 | D10: 3 | E10: 3 | F10: 0 | G10: 0 | H10: 0 | I10: 0 | J10: 1 | K10: 0 | L10: 0 | M10: 1 | N10: 0 | O10: =SUM(C10:L10,N10) -> 9 | P10: =SUM(C10:N10) -> 10 | R10: 0700-0800 | S10: =SUM(C10:C13) -> 2 | T10: =SUM(D10:D13) -> 8 | U10: =SUM(E10:E13) -> 10 | V10: =SUM(F10:F13) -> 2 | W10: =SUM(G10:G13) -> 0 | X10: =SUM(H10:H13) -> 0 | Y10: =SUM(I10:I13) -> 1 | Z10: =SUM(J10:J13) -> 4 | ... AF10: =SUM(P10:P13) -> 43
B11: 07.15 - 07.30 | C11: 0 | D11: 1 | E11: 1 | F11: 1 | G11: 0 | H11: 0 | I11: 0 | J11: 0 | K11: 0 | L11: 1 | M11: 3 | N11: 0 | O11: =SUM(C11:L11,N11) -> 4 | P11: =SUM(C11:N11) -> 7 | R11: 0800-0900 | S11: =SUM(C14:C17) -> 2 | T11: =SUM(D14:D17) -> 6 | U11: =SUM(E14:E17) -> 7 | V11: =SUM(F14:F17) -> 2 | W11: =SUM(G14:G17) -> 0 | X11: =SUM(H14:H17) -> 1 | Y11: =SUM(I14:I17) -> 0 | Z11: =SUM(J14:J17) -> 1 | ... AF11: =SUM(P14:P17) -> 32
B12: 07.30 - 07.45 | C12: 0 | D12: 1 | E12: 2 | F12: 0 | G12: 0 | H12: 0 | I12: 1 | J12: 0 | K12: 0 | L12: 0 | M12: 4 | N12: 0 | O12: =SUM(C12:L12,N12) -> 4 | P12: =SUM(C12:N12) -> 8 | R12: 0900-1000 | S12: =SUM(C18:C21) -> 4 | T12: =SUM(D18:D21) -> 6 | U12: =SUM(E18:E21) -> 7 | V12: =SUM(F18:F21) -> 1 | W12: =SUM(G18:G21) -> 0 | X12: =SUM(H18:H21) -> 5 | Y12: =SUM(I18:I21) -> 1 | Z12: =SUM(J18:J21) -> 0 | ... AF12: =SUM(P18:P21) -> 43
B13: 07.45 - 08.00 | C13: 0 | D13: 3 | E13: 4 | F13: 1 | G13: 0 | H13: 0 | I13: 0 | J13: 3 | K13: 0 | L13: 2 | M13: 5 | N13: 0 | O13: =SUM(C13:L13,N13) -> 13 | P13: =SUM(C13:N13) -> 18 | R13: 1000-1100 | S13: =SUM(C22:C25) -> 8 | T13: =SUM(D22:D25) -> 7 | U13: =SUM(E22:E25) -> 9 | V13: =SUM(F22:F25) -> 8 | W13: =SUM(G22:G25) -> 0 | X13: =SUM(H22:H25) -> 2 | Y13: =SUM(I22:I25) -> 2 | Z13: =SUM(J22:J25) -> 0 | ... AF13: =SUM(P22:P25) -> 48
B14: 08.00 - 08.15 | C14: 1 | D14: 1 | E14: 1 | F14: 1 | G14: 0 | H14: 0 | I14: 0 | J14: 0 | K14: 0 | L14: 1 | M14: 4 | N14: 0 | O14: =SUM(C14:L14,N14) -> 5 | P14: =SUM(C14:N14) -> 9 | R14: 1100-1200 | S14: =SUM(C26:C29) -> 7 | T14: =SUM(D26:D29) -> 8 | U14: =SUM(E26:E29) -> 11 | V14: =SUM(F26:F29) -> 4 | W14: =SUM(G26:G29) -> 0 | X14: =SUM(H26:H29) -> 3 | Y14: =SUM(I26:I29) -> 1 | Z14: =SUM(J26:J29) -> 3 | ... AF14: =SUM(P26:P29) -> 53
B15: 08.15 - 08.30 | C15: 0 | D15: 2 | E15: 2 | F15: 0 | G15: 0 | H15: 0 | I15: 0 | J15: 0 | K15: 0 | L15: 0 | M15: 4 | N15: 0 | O15: =SUM(C15:L15,N15) -> 4 | P15: =SUM(C15:N15) -> 8 | R15: 1200-1300 | S15: =SUM(C30:C33) -> 4 | T15: =SUM(D30:D33) -> 13 | U15: =SUM(E30:E33) -> 15 | V15: =SUM(F30:F33) -> 10 | W15: =SUM(G30:G33) -> 0 | X15: =SUM(H30:H33) -> 11 | Y15: =SUM(I30:I33) -> 6 | Z15: =SUM(J30:J33) -> 0 | ... AF15: =SUM(P30:P33) -> 74
B16: 08.30 - 08.45 | C16: 1 | D16: 2 | E16: 2 | F16: 1 | G16: 0 | H16: 0 | I16: 0 | J16: 1 | K16: 1 | L16: 0 | M16: 0 | N16: 0 | O16: =SUM(C16:L16,N16) -> 8 | P16: =SUM(C16:N16) -> 8 | R16: 1300-1400 | S16: =SUM(C34:C37) -> 6 | T16: =SUM(D34:D37) -> 9 | U16: =SUM(E34:E37) -> 11 | V16: =SUM(F34:F37) -> 3 | W16: =SUM(G34:G37) -> 0 | X16: =SUM(H34:H37) -> 5 | Y16: =SUM(I34:I37) -> 6 | Z16: =SUM(J34:J37) -> 4 | ... AF16: =SUM(P34:P37) -> 59
B17: 08.45 - 9.00 | C17: 0 | D17: 1 | E17: 2 | F17: 0 | G17: 0 | H17: 1 | I17: 0 | J17: 0 | K17: 0 | L17: 1 | M17: 2 | N17: 0 | O17: =SUM(C17:L17,N17) -> 5 | P17: =SUM(C17:N17) -> 7 | R17: 1400-1500 | S17: =SUM(C38:C41) -> 10 | T17: =SUM(D38:D41) -> 8 | U17: =SUM(E38:E41) -> 8 | V17: =SUM(F38:F41) -> 9 | W17: =SUM(G38:G41) -> 0 | X17: =SUM(H38:H41) -> 5 | Y17: =SUM(I38:I41) -> 8 | Z17: =SUM(J38:J41) -> 0 | ... AF17: =SUM(P38:P41) -> 73
B18: 09.00 - 09.15 | C18: 1 | D18: 2 | E18: 2 | F18: 1 | G18: 0 | H18: 2 | I18: 0 | J18: 0 | K18: 0 | L18: 1 | M18: 6 | N18: 0 | O18: =SUM(C18:L18,N18) -> 9 | P18: =SUM(C18:N18) -> 15 | R18: 1500-1600 | S18: =SUM(C42:C45) -> 9 | T18: =SUM(D42:D45) -> 5 | U18: =SUM(E42:E45) -> 6 | V18: =SUM(F42:F45) -> 7 | W18: =SUM(G42:G45) -> 0 | X18: =SUM(H42:H45) -> 5 | Y18: =SUM(I42:I45) -> 9 | Z18: =SUM(J42:J45) -> 1 | ... AF18: =SUM(P42:P45) -> 64
B19: 09.15 - 09.30 | C19: 0 | D19: 1 | E19: 1 | F19: 0 | G19: 0 | H19: 1 | I19: 1 | J19: 0 | K19: 0 | L19: 0 | M19: 1 | N19: 0 | O19: =SUM(C19:L19,N19) -> 4 | P19: =SUM(C19:N19) -> 5 | R19: 1600-1700 | S19: =SUM(C46:C49) -> 5 | T19: =SUM(D46:D49) -> 7 | U19: =SUM(E46:E49) -> 10 | V19: =SUM(F46:F49) -> 5 | W19: =SUM(G46:G49) -> 1 | X19: =SUM(H46:H49) -> 3 | Y19: =SUM(I46:I49) -> 10 | Z19: =SUM(J46:J49) -> 0 | ... AF19: =SUM(P46:P49) -> 59
B20: 09.30 - 09.45 | C20: 1 | D20: 2 | E20: 2 | F20: 0 | G20: 0 | H20: 0 | I20: 0 | J20: 0 | K20: 0 | L20: 2 | M20: 1 | N20: 0 | O20: =SUM(C20:L20,N20) -> 7 | P20: =SUM(C20:N20) -> 8 | R20: 1700-1800 | S20: =SUM(C50:C53) -> 5 | T20: =SUM(D50:D53) -> 6 | U20: =SUM(E50:E53) -> 8 | V20: =SUM(F50:F53) -> 4 | W20: =SUM(G50:G53) -> 0 | X20: =SUM(H50:H53) -> 6 | Y20: =SUM(I50:I53) -> 14 | Z20: =SUM(J50:J53) -> 0 | ... AF20: =SUM(P50:P53) -> 69
B21: 09.45 - 10.00 | C21: 2 | D21: 1 | E21: 2 | F21: 0 | G21: 0 | H21: 2 | I21: 0 | J21: 0 | K21: 0 | L21: 0 | M21: 7 | N21: 1 | O21: =SUM(C21:L21,N21) -> 8 | P21: =SUM(C21:N21) -> 15 | R21: 1800-1900 | S21: =SUM(C54:C57) -> 4 | T21: =SUM(D54:D57) -> 5 | U21: =SUM(E54:E57) -> 7 | V21: =SUM(F54:F57) -> 5 | W21: =SUM(G54:G57) -> 0 | X21: =SUM(H54:H57) -> 2 | Y21: =SUM(I54:I57) -> 14 | Z21: =SUM(J54:J57) -> 8 | ... AF21: =SUM(P54:P57) -> 74
B22: 10.00 - 10.15 | C22: 1 | D22: 1 | E22: 2 | F22: 2 | G22: 0 | H22: 1 | I22: 1 | J22: 0 | K22: 0 | L22: 1 | M22: 2 | N22: 0 | O22: =SUM(C22:L22,N22) -> 9 | P22: =SUM(C22:N22) -> 11 | R22: AM Peak Hr | S22: =MAX(S10:S12) -> 4 | T22: =MAX(T10:T12) -> 8 | U22: =MAX(U10:U12) -> 10 | V22: =MAX(V10:V12) -> 2 | W22: =MAX(W10:W12) -> 0 | X22: =MAX(X10:X12) -> 5 | Y22: =MAX(Y10:Y12) -> 1 | Z22: =MAX(Z10:Z12) -> 4 | ... AF22: =MAX(AF10:AF12) -> 43
B23: 10.15 - 10.30 | C23: 1 | D23: 2 | E23: 2 | F23: 2 | G23: 0 | H23: 0 | I23: 1 | J23: 0 | K23: 0 | L23: 0 | M23: 1 | N23: 0 | O23: =SUM(C23:L23,N23) -> 8 | P23: =SUM(C23:N23) -> 9 | R23: IP Peak Hr | S23: =MAX(S13:S18) -> 10 | T23: =MAX(T13:T18) -> 13 | U23: =MAX(U13:U18) -> 15 | V23: =MAX(V13:V18) -> 10 | W23: =MAX(W13:W18) -> 0 | X23: =MAX(X13:X18) -> 11 | Y23: =MAX(Y13:Y18) -> 9 | Z23: =MAX(Z13:Z18) -> 4 | ... AF23: =MAX(AF13:AF18) -> 74
B24: 10.30 - 10.45 | C24: 2 | D24: 1 | E24: 1 | F24: 1 | G24: 0 | H24: 0 | I24: 0 | J24: 0 | K24: 0 | L24: 0 | M24: 2 | N24: 1 | O24: =SUM(C24:L24,N24) -> 6 | P24: =SUM(C24:N24) -> 8 | R24: PM Peak Hr | S24: =MAX(S19:S21) -> 5 | T24: =MAX(T19:T21) -> 7 | U24: =MAX(U19:U21) -> 10 | V24: =MAX(V19:V21) -> 5 | W24: =MAX(W19:W21) -> 1 | X24: =MAX(X19:X21) -> 6 | Y24: =MAX(Y19:Y21) -> 14 | Z24: =MAX(Z19:Z21) -> 8 | ... AF24: =MAX(AF19:AF21) -> 74
B25: 10.45 - 11.00 | C25: 4 | D25: 3 | E25: 4 | F25: 3 | G25: 0 | H25: 1 | I25: 0 | J25: 0 | K25: 0 | L25: 2 | M25: 3 | N25: 0 | O25: =SUM(C25:L25,N25) -> 17 | P25: =SUM(C25:N25) -> 20 | R25: AM Period | S25: =SUM(S10:S12) -> 8 | T25: =SUM(T10:T12) -> 20 | U25: =SUM(U10:U12) -> 24 | V25: =SUM(V10:V12) -> 5 | W25: =SUM(W10:W12) -> 0 | X25: =SUM(X10:X12) -> 6 | Y25: =SUM(Y10:Y12) -> 2 | Z25: =SUM(Z10:Z12) -> 5 | ... AF25: =SUM(AF10:AF12) -> 118
B26: 11.00 - 11.15 | C26: 0 | D26: 2 | E26: 3 | F26: 2 | G26: 0 | H26: 2 | I26: 0 | J26: 1 | K26: 0 | L26: 2 | M26: 2 | N26: 1 | O26: =SUM(C26:L26,N26) -> 13 | P26: =SUM(C26:N26) -> 15 | R26: IP Period | S26: =SUM(S13:S18) -> 44 | T26: =SUM(T13:T18) -> 50 | U26: =SUM(U13:U18) -> 60 | V26: =SUM(V13:V18) -> 41 | W26: =SUM(W13:W18) -> 0 | X26: =SUM(X13:X18) -> 31 | Y26: =SUM(Y13:Y18) -> 32 | Z26: =SUM(Z13:Z18) -> 8 | ... AF26: =SUM(AF13:AF18) -> 371
B27: 11.15 - 11.30 | C27: 4 | D27: 3 | E27: 3 | F27: 0 | G27: 0 | H27: 0 | I27: 1 | J27: 0 | K27: 0 | L27: 0 | M27: 4 | N27: 1 | O27: =SUM(C27:L27,N27) -> 12 | P27: =SUM(C27:N27) -> 16 | R27: PM Period | S27: =SUM(S19:S21) -> 14 | T27: =SUM(T19:T21) -> 18 | U27: =SUM(U19:U21) -> 25 | V27: =SUM(V19:V21) -> 14 | W27: =SUM(W19:W21) -> 1 | X27: =SUM(X19:X21) -> 11 | Y27: =SUM(Y19:Y21) -> 38 | Z27: =SUM(Z19:Z21) -> 8 | ... AF27: =SUM(AF19:AF21) -> 202
B28: 11.30 - 11.45 | C28: 1 | D28: 3 | E28: 4 | F28: 1 | G28: 0 | H28: 1 | I28: 0 | J28: 0 | K28: 0 | L28: 0 | M28: 2 | N28: 0 | O28: =SUM(C28:L28,N28) -> 10 | P28: =SUM(C28:N28) -> 12 | R28: 12 Hours | S28: =SUM(S10:S21) -> 66 | T28: =SUM(T10:T21) -> 88 | U28: =SUM(U10:U21) -> 109 | V28: =SUM(V10:V21) -> 60 | W28: =SUM(W10:W21) -> 1 | X28: =SUM(X10:X21) -> 48 | Y28: =SUM(Y10:Y21) -> 72 | Z28: =SUM(Z10:Z21) -> 21 | ... AF28: =SUM(AF10:AF21) -> 691
B29: 11.45 - 12.00 | C29: 2 | D29: 0 | E29: 1 | F29: 1 | G29: 0 | H29: 0 | I29: 0 | J29: 2 | K29: 0 | L29: 0 | M29: 4 | N29: 0 | O29: =SUM(C29:L29,N29) -> 6 | P29: =SUM(C29:N29) -> 10
B30: 12.00 - 12.15 | C30: 1 | D30: 2 | E30: 2 | F30: 2 | G30: 0 | H30: 2 | I30: 3 | J30: 0 | K30: 0 | L30: 1 | M30: 2 | N30: 0 | O30: =SUM(C30:L30,N30) -> 13 | P30: =SUM(C30:N30) -> 15
B31: 12.15 - 12.30 | C31: 1 | D31: 4 | E31: 5 | F31: 0 | G31: 0 | H31: 7 | I31: 1 | J31: 0 | K31: 0 | L31: 1 | M31: 5 | N31: 0 | O31: =SUM(C31:L31,N31) -> 19 | P31: =SUM(C31:N31) -> 24
B32: 12.30 - 12.45 | C32: 2 | D32: 2 | E32: 3 | F32: 3 | G32: 0 | H32: 0 | I32: 1 | J32: 0 | K32: 0 | L32: 0 | M32: 3 | N32: 0 | O32: =SUM(C32:L32,N32) -> 11 | P32: =SUM(C32:N32) -> 14
B33: 12.45 - 13.00 | C33: 0 | D33: 5 | E33: 5 | F33: 5 | G33: 0 | H33: 2 | I33: 1 | J33: 0 | K33: 0 | L33: 0 | M33: 3 | N33: 0 | O33: =SUM(C33:L33,N33) -> 18 | P33: =SUM(C33:N33) -> 21
B34: 13.00 - 13.15 | C34: 1 | D34: 1 | E34: 2 | F34: 0 | G34: 0 | H34: 1 | I34: 0 | J34: 1 | K34: 0 | L34: 1 | M34: 4 | N34: 0 | O34: =SUM(C34:L34,N34) -> 7 | P34: =SUM(C34:N34) -> 11
B35: 13.15 - 13.30 | C35: 1 | D35: 3 | E35: 3 | F35: 1 | G35: 0 | H35: 2 | I35: 1 | J35: 1 | K35: 0 | L35: 1 | M35: 2 | N35: 0 | O35: =SUM(C35:L35,N35) -> 13 | P35: =SUM(C35:N35) -> 15
B36: 13.30 - 13.45 | C36: 2 | D36: 2 | E36: 2 | F36: 2 | G36: 0 | H36: 1 | I36: 3 | J36: 1 | K36: 0 | L36: 1 | M36: 1 | N36: 0 | O36: =SUM(C36:L36,N36) -> 14 | P36: =SUM(C36:N36) -> 15
B37: 13.45 - 14.00 | C37: 2 | D37: 3 | E37: 4 | F37: 0 | G37: 0 | H37: 1 | I37: 2 | J37: 1 | K37: 1 | L37: 0 | M37: 4 | N37: 0 | O37: =SUM(C37:L37,N37) -> 14 | P37: =SUM(C37:N37) -> 18
B38: 14.00 - 14.15 | C38: 2 | D38: 1 | E38: 1 | F38: 7 | G38: 0 | H38: 2 | I38: 2 | J38: 0 | K38: 0 | L38: 0 | M38: 4 | N38: 0 | O38: =SUM(C38:L38,N38) -> 15 | P38: =SUM(C38:N38) -> 19
B39: 14.15 - 14.30 | C39: 2 | D39: 1 | E39: 1 | F39: 0 | G39: 0 | H39: 0 | I39: 1 | J39: 0 | K39: 0 | L39: 1 | M39: 4 | N39: 0 | O39: =SUM(C39:L39,N39) -> 6 | P39: =SUM(C39:N39) -> 10
B40: 14.30 - 14.45 | C40: 4 | D40: 4 | E40: 4 | F40: 0 | G40: 0 | H40: 2 | I40: 3 | J40: 0 | K40: 0 | L40: 2 | M40: 6 | N40: 0 | O40: =SUM(C40:L40,N40) -> 19 | P40: =SUM(C40:N40) -> 25
... B57: 18.45 - 19.00 | C57: 1 | D57: 1 | E57: 2 | F57: 0 | G57: 0 | H57: 0 | I57: 3 | J57: 4 | K57: 0 | L57: 2 | M57: 6 | N57: 0 | O57: =SUM(C57:L57,N57) -> 13 | P57: =SUM(C57:N57) -> 19
B58: Totals | C58: =SUM(C10:C57) -> 66 | D58: =SUM(D10:D57) -> 88 | E58: =SUM(E10:E57) -> 109 | F58: =SUM(F10:F57) -> 60 | G58: =SUM(G10:G57) -> 1 | H58: =SUM(H10:H57) -> 48 | I58: =SUM(I10:I57) -> 72 | J58: =SUM(J10:J57) -> 21 | ... P58: =SUM(P10:P57) -> 691
...

Sheet 29.07 Kigumba-Karuma
B1: Consultancy services for Preparation of Expressway Development Master Plan (EDMP) for Uganda
B2: MANUAL CLASSIFIED COUNT (MCC)
B3: ROAD NAME: | C3: ='29.07 Karuma-Kigumba'!C3:G3 -> MCC - C5 - STN113 - KIGUMBA-KARUMA ROAD
C5: Date | D5: ='29.07 Karuma-Kigumba'!D5 -> 29.07.19 | F5: Location | G5: ='29.07 Karuma-Kigumba'!G5:H5 -> nanda | J5: Surveyor | K5: ='29.07 Karuma-Kigumba'!K5:L5 -> xxx
C6: Dir. From | D6: Kigumba | F6: Dir. To | G6: Karuma | J6: Supervisor | K6: ='29.07 Karuma-Kigumba'!K6:L6 -> xxx
B8: Time / Veh Type | R8: SUMMARY TRAFFIC VOLUMES
C9: 1. Car | D9: 2. Station Wagon | E9: 3. Pickups | F9: 4. Minibus, matatu | G9: 5. Medium bus | H9: 6. Large Bus | I9: 7. Light Truck | J9: 8. Medium Truck | K9: 9. Heavy truck | L9: 10. Truck Trailer | M9: 11. Motor cycles | N9: 12. Tractors | O9: Total Excl M/Cycles | P9: Total All | R9: Time | S9: 1. Car | T9: 2. Station Wagon | U9: 3. Pickups | V9: 4. Minibus, matatu | W9: 5. Medium bus | X9: 6. Large Bus | Y9: 7. Light Truck | Z9: 8. Medium Truck | AA9: 9. Heavy truck | AB9: 10. Truck Trailer | AC9: 11. Motorcycles | AD9: 12. Tractors, Graders | AE9: Total Excl M/ Cycles | AF9: Total All
B10: 07.00 - 07.15 | C10: 0 | D10: 1 | E10: 1 | F10: 0 | G10: 0 | H10: 0 | I10: 2 | J10: 0 | K10: 0 | L10: 2 | M10: 1 | N10: 0 | O10: =SUM(C10:L10,N10) -> 6 | P10: =SUM(C10:N10) -> 7 | R10: 0700-0800 | S10: =SUM(C10:C13) -> 5 | T10: =SUM(D10:D13) -> 4 | U10: =SUM(E10:E13) -> 7 | V10: =SUM(F10:F13) -> 3 | W10: =SUM(G10:G13) -> 0 | X10: =SUM(H10:H13) -> 0 | Y10: =SUM(I10:I13) -> 5 | Z10: =SUM(J10:J13) -> 0 | ... AF10: =SUM(P10:P13) -> 43
B11: 07.15 - 07.30 | C11: 2 | D11: 0 | E11: 1 | F11: 0 | G11: 0 | H11: 0 | I11: 0 | J11: 0 | K11: 0 | L11: 0 | M11: 2 | N11: 0 | O11: =SUM(C11:L11,N11) -> 3 | P11: =SUM(C11:N11) -> 5 | R11: 0800-0900 | S11: =SUM(C14:C17) -> 4 | T11: =SUM(D14:D17) -> 7 | U11: =SUM(E14:E17) -> 10 | V11: =SUM(F14:F17) -> 2 | W11: =SUM(G14:G17) -> 0 | X11: =SUM(H14:H17) -> 0 | Y11: =SUM(I14:I17) -> 7 | Z11: =SUM(J14:J17) -> 1 | ... AF11: =SUM(P14:P17) -> 41
B12: 07.30 - 07.45 | C12: 2 | D12: 1 | E12: 2 | F12: 1 | G12: 0 | H12: 0 | I12: 1 | J12: 0 | K12: 0 | L12: 0 | M12: 5 | N12: 0 | O12: =SUM(C12:L12,N12) -> 7 | P12: =SUM(C12:N12) -> 12 | R12: 0900-1000 | S12: =SUM(C18:C21) -> 7 | T12: =SUM(D18:D21) -> 10 | U12: =SUM(E18:E21) -> 12 | V12: =SUM(F18:F21) -> 4 | W12: =SUM(G18:G21) -> 0 | X12: =SUM(H18:H21) -> 0 | Y12: =SUM(I18:I21) -> 5 | Z12: =SUM(J18:J21) -> 0 | ... AF12: =SUM(P18:P21) -> 47
B13: 07.45 - 08.00 | C13: 1 | D13: 2 | E13: 3 | F13: 2 | G13: 0 | H13: 0 | I13: 2 | J13: 0 | K13: 0 | L13: 1 | M13: 8 | N13: 0 | O13: =SUM(C13:L13,N13) -> 11 | P13: =SUM(C13:N13) -> 19 | R13: 1000-1100 | S13: =SUM(C22:C25) -> 3 | T13: =SUM(D22:D25) -> 9 | U13: =SUM(E22:E25) -> 10 | V13: =SUM(F22:F25) -> 9 | W13: =SUM(G22:G25) -> 0 | X13: =SUM(H22:H25) -> 2 | Y13: =SUM(I22:I25) -> 6 | Z13: =SUM(J22:J25) -> 0 | ... AF13: =SUM(P22:P25) -> 46
B14: 08.00 - 08.15 | C14: 0 | D14: 1 | E14: 1 | F14: 0 | G14: 0 | H14: 0 | I14: 0 | J14: 1 | K14: 0 | L14: 0 | M14: 1 | N14: 0 | O14: =SUM(C14:L14,N14) -> 3 | P14: =SUM(C14:N14) -> 4 | R14: 1100-1200 | S14: =SUM(C26:C29) -> 5 | T14: =SUM(D26:D29) -> 7 | U14: =SUM(E26:E29) -> 11 | V14: =SUM(F26:F29) -> 7 | W14: =SUM(G26:G29) -> 0 | X14: =SUM(H26:H29) -> 3 | Y14: =SUM(I26:I29) -> 3 | Z14: =SUM(J26:J29) -> 0 | ... AF14: =SUM(P26:P29) -> 48
B15: 08.15 - 08.30 | C15: 0 | D15: 1 | E15: 2 | F15: 0 | G15: 0 | H15: 0 | I15: 2 | J15: 0 | K15: 0 | L15: 0 | M15: 2 | N15: 0 | O15: =SUM(C15:L15,N15) -> 5 | P15: =SUM(C15:N15) -> 7 | R15: 1200-1300 | S15: =SUM(C30:C33) -> 7 | T15: =SUM(D30:D33) -> 7 | U15: =SUM(E30:E33) -> 11 | V15: =SUM(F30:F33) -> 7 | W15: =SUM(G30:G33) -> 0 | X15: =SUM(H30:H33) -> 1 | Y15: =SUM(I30:I33) -> 3 | Z15: =SUM(J30:J33) -> 0 | ... AF15: =SUM(P30:P33) -> 42
B16: 08.30 - 08.45 | C16: 3 | D16: 2 | E16: 3 | F16: 1 | G16: 0 | H16: 0 | I16: 4 | J16: 0 | K16: 0 | L16: 1 | M16: 4 | N16: 0 | O16: =SUM(C16:L16,N16) -> 14 | P16: =SUM(C16:N16) -> 18 | R16: 1300-1400 | S16: =SUM(C34:C37) -> 5 | T16: =SUM(D34:D37) -> 17 | U16: =SUM(E34:E37) -> 18 | V16: =SUM(F34:F37) -> 12 | W16: =SUM(G34:G37) -> 0 | X16: =SUM(H34:H37) -> 6 | Y16: =SUM(I34:I37) -> 8 | Z16: =SUM(J34:J37) -> 0 | ... AF16: =SUM(P34:P37) -> 86
B17: 08.45 - 9.00 | C17: 1 | D17: 3 | E17: 4 | F17: 1 | G17: 0 | H17: 0 | I17: 1 | J17: 0 | K17: 0 | L17: 1 | M17: 1 | N17: 0 | O17: =SUM(C17:L17,N17) -> 11 | P17: =SUM(C17:N17) -> 12 | R17: 1400-1500 | S17: =SUM(C38:C41) -> 2 | T17: =SUM(D38:D41) -> 14 | U17: =SUM(E38:E41) -> 15 | V17: =SUM(F38:F41) -> 8 | W17: =SUM(G38:G41) -> 0 | X17: =SUM(H38:H41) -> 4 | Y17: =SUM(I38:I41) -> 2 | Z17: =SUM(J38:J41) -> 0 | ... AF17: =SUM(P38:P41) -> 62
B18: 09.00 - 09.15 | C18: 0 | D18: 1 | E18: 2 | F18: 0 | G18: 0 | H18: 0 | I18: 0 | J18: 0 | K18: 0 | L18: 1 | M18: 1 | N18: 0 | O18: =SUM(C18:L18,N18) -> 4 | P18: =SUM(C18:N18) -> 5 | R18: 1500-1600 | S18: =SUM(C42:C45) -> 8 | T18: =SUM(D42:D45) -> 16 | U18: =SUM(E42:E45) -> 17 | V18: =SUM(F42:F45) -> 9 | W18: =SUM(G42:G45) -> 0 | X18: =SUM(H42:H45) -> 4 | Y18: =SUM(I42:I45) -> 6 | Z18: =SUM(J42:J45) -> 3 | ... AF18: =SUM(P42:P45) -> 88
B19: 09.15 - 09.30 | C19: 3 | D19: 2 | E19: 2 | F19: 1 | G19: 0 | H19: 0 | I19: 2 | J19: 0 | K19: 0 | L19: 1 | M19: 5 | N19: 0 | O19: =SUM(C19:L19,N19) -> 11 | P19: =SUM(C19:N19) -> 16 | R19: 1600-1700 | S19: =SUM(C46:C49) -> 13 | T19: =SUM(D46:D49) -> 13 | U19: =SUM(E46:E49) -> 16 | V19: =SUM(F46:F49) -> 9 | W19: =SUM(G46:G49) -> 1 | X19: =SUM(H46:H49) -> 8 | Y19: =SUM(I46:I49) -> 9 | Z19: =SUM(J46:J49) -> 0 | ... AF19: =SUM(P46:P49) -> 87
B20: 09.30 - 09.45 | C20: 1 | D20: 3 | E20: 4 | F20: 1 | G20: 0 | H20: 0 | I20: 0 | J20: 0 | K20: 0 | L20: 0 | M20: 1 | N20: 0 | O20: =SUM(C20:L20,N20) -> 9 | P20: =SUM(C20:N20) -> 10 | R20: 1700-1800 | S20: =SUM(C50:C53) -> 4 | T20: =SUM(D50:D53) -> 9 | U20: =SUM(E50:E53) -> 10 | V20: =SUM(F50:F53) -> 6 | W20: =SUM(G50:G53) -> 0 | X20: =SUM(H50:H53) -> 4 | Y20: =SUM(I50:I53) -> 6 | Z20: =SUM(J50:J53) -> 2 | ... AF20: =SUM(P50:P53) -> 57
B21: 09.45 - 10.00 | C21: 3 | D21: 4 | E21: 4 | F21: 2 | G21: 0 | H21: 0 | I21: 3 | J21: 0 | K21: 0 | L21: 0 | M21: 0 | N21: 0 | O21: =SUM(C21:L21,N21) -> 16 | P21: =SUM(C21:N21) -> 16 | R21: 1800-1900 | S21: =SUM(C54:C57) -> 12 | T21: =SUM(D54:D57) -> 14 | U21: =SUM(E54:E57) -> 16 | V21: =SUM(F54:F57) -> 4 | W21: =SUM(G54:G57) -> 1 | X21: =SUM(H54:H57) -> 5 | Y21: =SUM(I54:I57) -> 9 | Z21: =SUM(J54:J57) -> 0 | ... AF21: =SUM(P54:P57) -> 82
B22: 10.00 - 10.15 | C22: 1 | D22: 3 | E22: 4 | F22: 0 | G22: 0 | H22: 0 | I22: 2 | J22: 0 | K22: 0 | L22: 0 | M22: 1 | N22: 0 | O22: =SUM(C22:L22,N22) -> 10 | P22: =SUM(C22:N22) -> 11 | R22: AM Peak Hr | S22: =MAX(S10:S12) -> 7 | T22: =MAX(T10:T12) -> 10 | U22: =MAX(U10:U12) -> 12 | V22: =MAX(V10:V12) -> 4 | W22: =MAX(W10:W12) -> 0 | X22: =MAX(X10:X12) -> 0 | Y22: =MAX(Y10:Y12) -> 7 | Z22: =MAX(Z10:Z12) -> 1 | ... AF22: =MAX(AF10:AF12) -> 47
B23: 10.15 - 10.30 | C23: 0 | D23: 1 | E23: 1 | F23: 5 | G23: 0 | H23: 1 | I23: 2 | J23: 0 | K23: 0 | L23: 1 | M23: 2 | N23: 0 | O23: =SUM(C23:L23,N23) -> 11 | P23: =SUM(C23:N23) -> 13 | R23: IP Peak Hr | S23: =MAX(S13:S18) -> 8 | T23: =MAX(T13:T18) -> 17 | U23: =MAX(U13:U18) -> 18 | V23: =MAX(V13:V18) -> 12 | W23: =MAX(W13:W18) -> 0 | X23: =MAX(X13:X18) -> 6 | Y23: =MAX(Y13:Y18) -> 8 | Z23: =MAX(Z13:Z18) -> 3 | ... AF23: =MAX(AF13:AF18) -> 88
B24: 10.30 - 10.45 | C24: 0 | D24: 3 | E24: 3 | F24: 0 | G24: 0 | H24: 1 | I24: 2 | J24: 0 | K24: 0 | L24: 0 | M24: 3 | N24: 0 | O24: =SUM(C24:L24,N24) -> 9 | P24: =SUM(C24:N24) -> 12 | R24: PM Peak Hr | S24: =MAX(S19:S21) -> 13 | T24: =MAX(T19:T21) -> 14 | U24: =MAX(U19:U21) -> 16 | V24: =MAX(V19:V21) -> 9 | W24: =MAX(W19:W21) -> 1 | X24: =MAX(X19:X21) -> 8 | Y24: =MAX(Y19:Y21) -> 9 | Z24: =MAX(Z19:Z21) -> 2 | ... AF24: =MAX(AF19:AF21) -> 87
B25: 10.45 - 11.00 | C25: 2 | D25: 2 | E25: 2 | F25: 4 | G25: 0 | H25: 0 | I25: 0 | J25: 0 | K25: 0 | L25: 0 | M25: 0 | N25: 0 | O25: =SUM(C25:L25,N25) -> 10 | P25: =SUM(C25:N25) -> 10 | R25: AM Period | S25: =SUM(S10:S12) -> 16 | T25: =SUM(T10:T12) -> 21 | U25: =SUM(U10:U12) -> 29 | V25: =SUM(V10:V12) -> 9 | W25: =SUM(W10:W12) -> 0 | X25: =SUM(X10:X12) -> 0 | Y25: =SUM(Y10:Y12) -> 17 | Z25: =SUM(Z10:Z12) -> 1 | ... AF25: =SUM(AF10:AF12) -> 131
B26: 11.00 - 11.15 | C26: 1 | D26: 2 | E26: 3 | F26: 2 | G26: 0 | H26: 2 | I26: 0 | J26: 0 | K26: 1 | L26: 0 | M26: 5 | N26: 0 | O26: =SUM(C26:L26,N26) -> 11 | P26: =SUM(C26:N26) -> 16 | R26: IP Period | S26: =SUM(S13:S18) -> 30 | T26: =SUM(T13:T18) -> 70 | U26: =SUM(U13:U18) -> 82 | V26: =SUM(V13:V18) -> 52 | W26: =SUM(W13:W18) -> 0 | X26: =SUM(X13:X18) -> 20 | Y26: =SUM(Y13:Y18) -> 28 | Z26: =SUM(Z13:Z18) -> 3 | ... AF26: =SUM(AF13:AF18) -> 372
B27: 11.15 - 11.30 | C27: 2 | D27: 1 | E27: 2 | F27: 0 | G27: 0 | H27: 0 | I27: 1 | J27: 0 | K27: 0 | L27: 0 | M27: 0 | N27: 0 | O27: =SUM(C27:L27,N27) -> 6 | P27: =SUM(C27:N27) -> 6 | R27: PM Period | S27: =SUM(S19:S21) -> 29 | T27: =SUM(T19:T21) -> 36 | U27: =SUM(U19:U21) -> 42 | V27: =SUM(V19:V21) -> 19 | W27: =SUM(W19:W21) -> 2 | X27: =SUM(X19:X21) -> 17 | Y27: =SUM(Y19:Y21) -> 24 | Z27: =SUM(Z19:Z21) -> 2 | ... AF27: =SUM(AF19:AF21) -> 226
B28: 11.30 - 11.45 | C28: 0 | D28: 2 | E28: 3 | F28: 3 | G28: 0 | H28: 0 | I28: 1 | J28: 0 | K28: 0 | L28: 0 | M28: 3 | N28: 0 | O28: =SUM(C28:L28,N28) -> 9 | P28: =SUM(C28:N28) -> 12 | R28: 12 Hours | S28: =SUM(S10:S21) -> 75 | T28: =SUM(T10:T21) -> 127 | U28: =SUM(U10:U21) -> 153 | V28: =SUM(V10:V21) -> 80 | W28: =SUM(W10:W21) -> 2 | X28: =SUM(X10:X21) -> 37 | Y28: =SUM(Y10:Y21) -> 69 | Z28: =SUM(Z10:Z21) -> 6 | ... AF28: =SUM(AF10:AF21) -> 729
B29: 11.45 - 12.00 | C29: 2 | D29: 2 | E29: 3 | F29: 2 | G29: 0 | H29: 1 | I29: 1 | J29: 0 | K29: 0 | L29: 1 | M29: 2 | N29: 0 | O29: =SUM(C29:L29,N29) -> 12 | P29: =SUM(C29:N29) -> 14
B30: 12.00 - 12.15 | C30: 2 | D30: 1 | E30: 2 | F30: 6 | G30: 0 | H30: 1 | I30: 1 | J30: 0 | K30: 1 | L30: 0 | M30: 1 | N30: 0 | O30: =SUM(C30:L30,N30) -> 14 | P30: =SUM(C30:N30) -> 15
B31: 12.15 - 12.30 | C31: 2 | D31: 4 | E31: 5 | F31: 0 | G31: 0 | H31: 0 | I31: 0 | J31: 0 | K31: 0 | L31: 0 | M31: 2 | N31: 0 | O31: =SUM(C31:L31,N31) -> 11 | P31: =SUM(C31:N31) -> 13
B32: 12.30 - 12.45 | C32: 0 | D32: 0 | E32: 1 | F32: 0 | G32: 0 | H32: 0 | I32: 0 | J32: 0 | K32: 0 | L32: 0 | M32: 1 | N32: 0 | O32: =SUM(C32:L32,N32) -> 1 | P32: =SUM(C32:N32) -> 2
B33: 12.45 - 13.00 | C33: 3 | D33: 2 | E33: 3 | F33: 1 | G33: 0 | H33: 0 | I33: 2 | J33: 0 | K33: 0 | L33: 0 | M33: 1 | N33: 0 | O33: =SUM(C33:L33,N33) -> 11 | P33: =SUM(C33:N33) -> 12
B34: 13.00 - 13.15 | C34: 0 | D34: 4 | E34: 5 | F34: 1 | G34: 0 | H34: 1 | I34: 2 | J34: 0 | K34: 0 | L34: 0 | M34: 4 | N34: 0 | O34: =SUM(C34:L34,N34) -> 13 | P34: =SUM(C34:N34) -> 17
B35: 13.15 - 13.30 | C35: 3 | D35: 4 | E35: 4 | F35: 7 | G35: 0 | H35: 3 | I35: 3 | J35: 0 | K35: 0 | L35: 0 | M35: 6 | N35: 0 | O35: =SUM(C35:L35,N35) -> 24 | P35: =SUM(C35:N35) -> 30
B36: 13.30 - 13.45 | C36: 1 | D36: 5 | E36: 5 | F36: 0 | G36: 0 | H36: 2 | I36: 2 | J36: 0 | K36: 0 | L36: 0 | M36: 3 | N36: 0 | O36: =SUM(C36:L36,N36) -> 15 | P36: =SUM(C36:N36) -> 18
B37: 13.45 - 14.00 | C37: 1 | D37: 4 | E37: 4 | F37: 4 | G37: 0 | H37: 0 | I37: 1 | J37: 0 | K37: 0 | L37: 0 | M37: 7 | N37: 0 | O37: =SUM(C37:L37,N37) -> 14 | P37: =SUM(C37:N37) -> 21
B38: 14.00 - 14.15 | C38: 1 | D38: 3 | E38: 4 | F38: 2 | G38: 0 | H38: 1 | I38: 0 | J38: 0 | K38: 0 | L38: 0 | M38: 3 | N38: 0 | O38: =SUM(C38:L38,N38) -> 11 | P38: =SUM(C38:N38) -> 14
B39: 14.15 - 14.30 | C39: 1 | D39: 3 | E39: 3 | F39: 0 | G39: 0 | H39: 1 | I39: 1 | J39: 0 | K39: 2 | L39: 1 | M39: 3 | N39: 0 | O39: =SUM(C39:L39,N39) -> 12 | P39: =SUM(C39:N39) -> 15
B40: 14.30 - 14.45 | C40: 0 | D40: 4 | E40: 4 | F40: 3 | G40: 0 | H40: 1 | I40: 0 | J40: 0 | K40: 0 | L40: 0 | M40: 5 | N40: 0 | O40: =SUM(C40:L40,N40) -> 12 | P40: =SUM(C40:N40) -> 17
... B57: 18.45 - 19.00 | C57: 3 | D57: 3 | E57: 3 | F57: 2 | G57: 0 | H57: 1 | I57: 3 | J57: 0 | K57: 1 | L57: 0 | M57: 5 | N57: 0 | O57: =SUM(C57:L57,N57) -> 16 | P57: =SUM(C57:N57) -> 21
B58: Totals | C58: =SUM(C10:C57) -> 75 | D58: =SUM(D10:D57) -> 127 | E58: =SUM(E10:E57) -> 153 | F58: =SUM(F10:F57) -> 80 | G58: =SUM(G10:G57) -> 2 | H58: =SUM(H10:H57) -> 37 | I58: =SUM(I10:I57) -> 69 | J58: =SUM(J10:J57) -> 6 | ... P58: =SUM(P10:P57) -> 729
...

Sheet 30.07 Karuma-Kigumba
B1: Consultancy services for Preparation of Expressway Development Master Plan (EDMP) for Uganda
B2: MANUAL CLASSIFIED COUNT (MCC)
B3: ROAD NAME: | C3: ='29.07 Karuma-Kigumba'!C3:G3 -> MCC - C5 - STN113 - KIGUMBA-KARUMA ROAD
C5: Date | D5: 30.07.19 | F5: Location | G5: ='29.07 Karuma-Kigumba'!G5:H5 -> nanda | J5: Surveyor | K5: ='29.07 Karuma-Kigumba'!K5:L5 -> xxx
C6: Dir. From | D6: ='29.07 Karuma-Kigumba'!D6:E6 -> karuma | F6: Dir. To | G6: ='29.07 Karuma-Kigumba'!G6:H6 -> kigumba | J6: Supervisor | K6: ='29.07 Karuma-Kigumba'!K6:L6 -> xxx
B8: Time / Veh Type | R8: SUMMARY TRAFFIC VOLUMES
C9: 1. Car | D9: 2. Station Wagon | E9: 3. Pickups | F9: 4. Minibus, matatu | G9: 5. Medium bus | H9: 6. Large Bus | I9: 7. Light Truck | J9: 8. Medium Truck | K9: 9. Heavy truck | L9: 10. Truck Trailer | M9: 11. Motor cycles | N9: 12. Tractors | O9: Total Excl M/Cycles | P9: Total All | R9: Time | S9: 1. Car | T9: 2. Station Wagon | U9: 3. Pickups | V9: 4. Minibus, matatu | W9: 5. Medium bus | X9: 6. Large Bus | Y9: 7. Light Truck | Z9: 8. Medium Truck | AA9: 9. Heavy truck | AB9: 10. Truck Trailer | AC9: 11. Motorcycles | AD9: 12. Tractors, Graders | AE9: Total Excl M/ Cycles | AF9: Total All
B10: 07.00 - 07.15 | C10: 1 | D10: 0 | E10: 1 | F10: 0 | G10: 0 | H10: 0 | I10: 2 | J10: 1 | K10: 0 | L10: 1 | M10: 2 | N10: 0 | O10: =SUM(C10:L10,N10) -> 6 | P10: =SUM(C10:N10) -> 8 | R10: 0700-0800 | S10: =SUM(C10:C13) -> 4 | T10: =SUM(D10:D13) -> 0 | U10: =SUM(E10:E13) -> 6 | V10: =SUM(F10:F13) -> 2 | W10: =SUM(G10:G13) -> 0 | X10: =SUM(H10:H13) -> 0 | Y10: =SUM(I10:I13) -> 4 | Z10: =SUM(J10:J13) -> 2 | ... AF10: =SUM(P10:P13) -> 32
B11: 07.15 - 07.30 | C11: 0 | D11: 0 | E11: 3 | F11: 2 | G11: 0 | H11: 0 | I11: 1 | J11: 1 | K11: 0 | L11: 0 | M11: 2 | N11: 0 | O11: =SUM(C11:L11,N11) -> 7 | P11: =SUM(C11:N11) -> 9 | R11: 0800-0900 | S11: =SUM(C14:C17) -> 1 | T11: =SUM(D14:D17) -> 2 | U11: =SUM(E14:E17) -> 10 | V11: =SUM(F14:F17) -> 4 | W11: =SUM(G14:G17) -> 0 | X11: =SUM(H14:H17) -> 2 | Y11: =SUM(I14:I17) -> 5 | Z11: =SUM(J14:J17) -> 0 | ... AF11: =SUM(P14:P17) -> 42
B12: 07.30 - 07.45 | C12: 2 | D12: 0 | E12: 2 | F12: 0 | G12: 0 | H12: 0 | I12: 1 | J12: 0 | K12: 0 | L12: 2 | M12: 5 | N12: 0 | O12: =SUM(C12:L12,N12) -> 7 | P12: =SUM(C12:N12) -> 12 | R12: 0900-1000 | S12: =SUM(C18:C21) -> 4 | T12: =SUM(D18:D21) -> 1 | U12: =SUM(E18:E21) -> 10 | V12: =SUM(F18:F21) -> 1 | W12: =SUM(G18:G21) -> 0 | X12: =SUM(H18:H21) -> 3 | Y12: =SUM(I18:I21) -> 5 | Z12: =SUM(J18:J21) -> 0 | ... AF12: =SUM(P18:P21) -> 41
B13: 07.45 - 08.00 | C13: 1 | D13: 0 | E13: 0 | F13: 0 | G13: 0 | H13: 0 | I13: 0 | J13: 0 | K13: 0 | L13: 1 | M13: 1 | N13: 0 | O13: =SUM(C13:L13,N13) -> 2 | P13: =SUM(C13:N13) -> 3 | R13: 1000-1100 | S13: =SUM(C22:C25) -> 5 | T13: =SUM(D22:D25) -> 3 | U13: =SUM(E22:E25) -> 10 | V13: =SUM(F22:F25) -> 6 | W13: =SUM(G22:G25) -> 1 | X13: =SUM(H22:H25) -> 1 | Y13: =SUM(I22:I25) -> 4 | Z13: =SUM(J22:J25) -> 1 | ... AF13: =SUM(P22:P25) -> 47
B14: 08.00 - 08.15 | C14: 1 | D14: 0 | E14: 3 | F14: 0 | G14: 0 | H14: 0 | I14: 1 | J14: 0 | K14: 0 | L14: 0 | M14: 1 | N14: 0 | O14: =SUM(C14:L14,N14) -> 5 | P14: =SUM(C14:N14) -> 6 | R14: 1100-1200 | S14: =SUM(C26:C29) -> 2 | T14: =SUM(D26:D29) -> 2 | U14: =SUM(E26:E29) -> 14 | V14: =SUM(F26:F29) -> 3 | W14: =SUM(G26:G29) -> 0 | X14: =SUM(H26:H29) -> 5 | Y14: =SUM(I26:I29) -> 11 | Z14: =SUM(J26:J29) -> 1 | ... AF14: =SUM(P26:P29) -> 60
B15: 08.15 - 08.30 | C15: 0 | D15: 1 | E15: 3 | F15: 1 | G15: 0 | H15: 0 | I15: 1 | J15: 0 | K15: 0 | L15: 0 | M15: 4 | N15: 0 | O15: =SUM(C15:L15,N15) -> 6 | P15: =SUM(C15:N15) -> 10 | R15: 1200-1300 | S15: =SUM(C30:C33) -> 7 | T15: =SUM(D30:D33) -> 4 | U15: =SUM(E30:E33) -> 16 | V15: =SUM(F30:F33) -> 2 | W15: =SUM(G30:G33) -> 0 | X15: =SUM(H30:H33) -> 9 | Y15: =SUM(I30:I33) -> 9 | Z15: =SUM(J30:J33) -> 0 | ... AF15: =SUM(P30:P33) -> 55
B16: 08.30 - 08.45 | C16: 0 | D16: 0 | E16: 1 | F16: 2 | G16: 0 | H16: 0 | I16: 1 | J16: 0 | K16: 0 | L16: 0 | M16: 6 | N16: 0 | O16: =SUM(C16:L16,N16) -> 4 | P16: =SUM(C16:N16) -> 10 | R16: 1300-1400 | S16: =SUM(C34:C37) -> 7 | T16: =SUM(D34:D37) -> 4 | U16: =SUM(E34:E37) -> 17 | V16: =SUM(F34:F37) -> 6 | W16: =SUM(G34:G37) -> 0 | X16: =SUM(H34:H37) -> 0 | Y16: =SUM(I34:I37) -> 6 | Z16: =SUM(J34:J37) -> 3 | ... AF16: =SUM(P34:P37) -> 56
B17: 08.45 - 9.00 | C17: 0 | D17: 1 | E17: 3 | F17: 1 | G17: 0 | H17: 2 | I17: 2 | J17: 0 | K17: 1 | L17: 1 | M17: 4 | N17: 1 | O17: =SUM(C17:L17,N17) -> 12 | P17: =SUM(C17:N17) -> 16 | R17: 1400-1500 | S17: =SUM(C38:C41) -> 10 | T17: =SUM(D38:D41) -> 3 | U17: =SUM(E38:E41) -> 15 | V17: =SUM(F38:F41) -> 8 | W17: =SUM(G38:G41) -> 0 | X17: =SUM(H38:H41) -> 5 | Y17: =SUM(I38:I41) -> 10 | Z17: =SUM(J38:J41) -> 4 | ... AF17: =SUM(P38:P41) -> 76
B18: 09.00 - 09.15 | C18: 1 | D18: 0 | E18: 3 | F18: 0 | G18: 0 | H18: 0 | I18: 1 | J18: 0 | K18: 0 | L18: 0 | M18: 6 | N18: 0 | O18: =SUM(C18:L18,N18) -> 5 | P18: =SUM(C18:N18) -> 11 | R18: 1500-1600 | S18: =SUM(C42:C45) -> 5 | T18: =SUM(D42:D45) -> 3 | U18: =SUM(E42:E45) -> 13 | V18: =SUM(F42:F45) -> 4 | W18: =SUM(G42:G45) -> 0 | X18: =SUM(H42:H45) -> 7 | Y18: =SUM(I42:I45) -> 12 | Z18: =SUM(J42:J45) -> 0 | ... AF18: =SUM(P42:P45) -> 64
B19: 09.15 - 09.30 | C19: 2 | D19: 1 | E19: 4 | F19: 1 | G19: 0 | H19: 0 | I19: 2 | J19: 0 | K19: 0 | L19: 0 | M19: 5 | N19: 0 | O19: =SUM(C19:L19,N19) -> 10 | P19: =SUM(C19:N19) -> 15 | R19: 1600-1700 | S19: =SUM(C46:C49) -> 10 | T19: =SUM(D46:D49) -> 5 | U19: =SUM(E46:E49) -> 17 | V19: =SUM(F46:F49) -> 6 | W19: =SUM(G46:G49) -> 0 | X19: =SUM(H46:H49) -> 3 | Y19: =SUM(I46:I49) -> 6 | Z19: =SUM(J46:J49) -> 4 | ... AF19: =SUM(P46:P49) -> 72
B20: 09.30 - 09.45 | C20: 0 | D20: 0 | E20: 1 | F20: 0 | G20: 0 | H20: 0 | I20: 0 | J20: 0 | K20: 0 | L20: 0 | M20: 5 | N20: 0 | O20: =SUM(C20:L20,N20) -> 1 | P20: =SUM(C20:N20) -> 6 | R20: 1700-1800 | S20: =SUM(C50:C53) -> 9 | T20: =SUM(D50:D53) -> 6 | U20: =SUM(E50:E53) -> 20 | V20: =SUM(F50:F53) -> 6 | W20: =SUM(G50:G53) -> 0 | X20: =SUM(H50:H53) -> 2 | Y20: =SUM(I50:I53) -> 17 | Z20: =SUM(J50:J53) -> 2 | ... AF20: =SUM(P50:P53) -> 80
B21: 09.45 - 10.00 | C21: 1 | D21: 0 | E21: 2 | F21: 0 | G21: 0 | H21: 3 | I21: 2 | J21: 0 | K21: 0 | L21: 0 | M21: 1 | N21: 0 | O21: =SUM(C21:L21,N21) -> 8 | P21: =SUM(C21:N21) -> 9 | R21: 1800-1900 | S21: =SUM(C54:C57) -> 3 | T21: =SUM(D54:D57) -> 1 | U21: =SUM(E54:E57) -> 14 | V21: =SUM(F54:F57) -> 11 | W21: =SUM(G54:G57) -> 0 | X21: =SUM(H54:H57) -> 3 | Y21: =SUM(I54:I57) -> 12 | Z21: =SUM(J54:J57) -> 0 | ... AF21: =SUM(P54:P57) -> 65
B22: 10.00 - 10.15 | C22: 1 | D22: 1 | E22: 3 | F22: 1 | G22: 0 | H22: 0 | I22: 2 | J22: 0 | K22: 0 | L22: 0 | M22: 5 | N22: 0 | O22: =SUM(C22:L22,N22) -> 8 | P22: =SUM(C22:N22) -> 13 | R22: AM Peak Hr | S22: =MAX(S10:S12) -> 4 | T22: =MAX(T10:T12) -> 2 | U22: =MAX(U10:U12) -> 10 | V22: =MAX(V10:V12) -> 4 | W22: =MAX(W10:W12) -> 0 | X22: =MAX(X10:X12) -> 3 | Y22: =MAX(Y10:Y12) -> 5 | Z22: =MAX(Z10:Z12) -> 2 | ... AF22: =MAX(AF10:AF12) -> 42
B23: 10.15 - 10.30 | C23: 0 | D23: 0 | E23: 1 | F23: 0 | G23: 0 | H23: 1 | I23: 2 | J23: 0 | K23: 0 | L23: 2 | M23: 5 | N23: 0 | O23: =SUM(C23:L23,N23) -> 6 | P23: =SUM(C23:N23) -> 11 | R23: IP Peak Hr | S23: =MAX(S13:S18) -> 10 | T23: =MAX(T13:T18) -> 4 | U23: =MAX(U13:U18) -> 17 | V23: =MAX(V13:V18) -> 8 | W23: =MAX(W13:W18) -> 1 | X23: =MAX(X13:X18) -> 9 | Y23: =MAX(Y13:Y18) -> 12 | Z23: =MAX(Z13:Z18) -> 4 | ... AF23: =MAX(AF13:AF18) -> 76
B24: 10.30 - 10.45 | C24: 2 | D24: 2 | E24: 5 | F24: 3 | G24: 0 | H24: 0 | I24: 0 | J24: 0 | K24: 0 | L24: 0 | M24: 1 | N24: 0 | O24: =SUM(C24:L24,N24) -> 12 | P24: =SUM(C24:N24) -> 13 | R24: PM Peak Hr | S24: =MAX(S19:S21) -> 10 | T24: =MAX(T19:T21) -> 6 | U24: =MAX(U19:U21) -> 20 | V24: =MAX(V19:V21) -> 11 | W24: =MAX(W19:W21) -> 0 | X24: =MAX(X19:X21) -> 3 | Y24: =MAX(Y19:Y21) -> 17 | Z24: =MAX(Z19:Z21) -> 4 | ... AF24: =MAX(AF19:AF21) -> 80
B25: 10.45 - 11.00 | C25: 2 | D25: 0 | E25: 1 | F25: 2 | G25: 1 | H25: 0 | I25: 0 | J25: 1 | K25: 0 | L25: 0 | M25: 3 | N25: 0 | O25: =SUM(C25:L25,N25) -> 7 | P25: =SUM(C25:N25) -> 10 | R25: AM Period | S25: =SUM(S10:S12) -> 9 | T25: =SUM(T10:T12) -> 3 | U25: =SUM(U10:U12) -> 26 | V25: =SUM(V10:V12) -> 7 | W25: =SUM(W10:W12) -> 0 | X25: =SUM(X10:X12) -> 5 | Y25: =SUM(Y10:Y12) -> 14 | Z25: =SUM(Z10:Z12) -> 2 | ... AF25: =SUM(AF10:AF12) -> 115
B26: 11.00 - 11.15 | C26: 1 | D26: 0 | E26: 3 | F26: 0 | G26: 0 | H26: 2 | I26: 2 | J26: 0 | K26: 0 | L26: 0 | M26: 8 | N26: 0 | O26: =SUM(C26:L26,N26) -> 8 | P26: =SUM(C26:N26) -> 16 | R26: IP Period | S26: =SUM(S13:S18) -> 36 | T26: =SUM(T13:T18) -> 19 | U26: =SUM(U13:U18) -> 85 | V26: =SUM(V13:V18) -> 29 | W26: =SUM(W13:W18) -> 1 | X26: =SUM(X13:X18) -> 27 | Y26: =SUM(Y13:Y18) -> 52 | Z26: =SUM(Z13:Z18) -> 9 | ... AF26: =SUM(AF13:AF18) -> 358
B27: 11.15 - 11.30 | C27: 1 | D27: 1 | E27: 4 | F27: 2 | G27: 0 | H27: 1 | I27: 2 | J27: 0 | K27: 1 | L27: 1 | M27: 5 | N27: 0 | O27: =SUM(C27:L27,N27) -> 13 | P27: =SUM(C27:N27) -> 18 | R27: PM Period | S27: =SUM(S19:S21) -> 22 | T27: =SUM(T19:T21) -> 12 | U27: =SUM(U19:U21) -> 51 | V27: =SUM(V19:V21) -> 23 | W27: =SUM(W19:W21) -> 0 | X27: =SUM(X19:X21) -> 8 | Y27: =SUM(Y19:Y21) -> 35 | Z27: =SUM(Z19:Z21) -> 6 | ... AF27: =SUM(AF19:AF21) -> 217
B28: 11.30 - 11.45 | C28: 0 | D28: 1 | E28: 4 | F28: 0 | G28: 0 | H28: 1 | I28: 2 | J28: 1 | K28: 0 | L28: 0 | M28: 3 | N28: 0 | O28: =SUM(C28:L28,N28) -> 9 | P28: =SUM(C28:N28) -> 12 | R28: 12 Hours | S28: =SUM(S10:S21) -> 67 | T28: =SUM(T10:T21) -> 34 | U28: =SUM(U10:U21) -> 162 | V28: =SUM(V10:V21) -> 59 | W28: =SUM(W10:W21) -> 1 | X28: =SUM(X10:X21) -> 40 | Y28: =SUM(Y10:Y21) -> 101 | Z28: =SUM(Z10:Z21) -> 17 | ... AF28: =SUM(AF10:AF21) -> 690
B29: 11.45 - 12.00 | C29: 0 | D29: 0 | E29: 3 | F29: 1 | G29: 0 | H29: 1 | I29: 5 | J29: 0 | K29: 0 | L29: 1 | M29: 3 | N29: 0 | O29: =SUM(C29:L29,N29) -> 11 | P29: =SUM(C29:N29) -> 14
B30: 12.00 - 12.15 | C30: 2 | D30: 1 | E30: 3 | F30: 1 | G30: 0 | H30: 2 | I30: 3 | J30: 0 | K30: 0 | L30: 1 | M30: 2 | N30: 0 | O30: =SUM(C30:L30,N30) -> 13 | P30: =SUM(C30:N30) -> 15
B31: 12.15 - 12.30 | C31: 2 | D31: 0 | E31: 3 | F31: 0 | G31: 0 | H31: 3 | I31: 1 | J31: 0 | K31: 0 | L31: 2 | M31: 1 | N31: 0 | O31: =SUM(C31:L31,N31) -> 11 | P31: =SUM(C31:N31) -> 12
B32: 12.30 - 12.45 | C32: 2 | D32: 1 | E32: 5 | F32: 0 | G32: 0 | H32: 0 | I32: 1 | J32: 0 | K32: 0 | L32: 1 | M32: 0 | N32: 0 | O32: =SUM(C32:L32,N32) -> 10 | P32: =SUM(C32:N32) -> 10
B33: 12.45 - 13.00 | C33: 1 | D33: 2 | E33: 5 | F33: 1 | G33: 0 | H33: 4 | I33: 4 | J33: 0 | K33: 0 | L33: 1 | M33: 0 | N33: 0 | O33: =SUM(C33:L33,N33) -> 18 | P33: =SUM(C33:N33) -> 18
B34: 13.00 - 13.15 | C34: 2 | D34: 1 | E34: 3 | F34: 2 | G34: 0 | H34: 0 | I34: 0 | J34: 1 | K34: 0 | L34: 3 | M34: 4 | N34: 0 | O34: =SUM(C34:L34,N34) -> 12 | P34: =SUM(C34:N34) -> 16
B35: 13.15 - 13.30 | C35: 0 | D35: 0 | E35: 3 | F35: 3 | G35: 0 | H35: 0 | I35: 1 | J35: 1 | K35: 0 | L35: 0 | M35: 2 | N35: 0 | O35: =SUM(C35:L35,N35) -> 8 | P35: =SUM(C35:N35) -> 10
B36: 13.30 - 13.45 | C36: 2 | D36: 1 | E36: 5 | F36: 0 | G36: 0 | H36: 0 | I36: 5 | J36: 0 | K36: 0 | L36: 0 | M36: 1 | N36: 0 | O36: =SUM(C36:L36,N36) -> 13 | P36: =SUM(C36:N36) -> 14
B37: 13.45 - 14.00 | C37: 3 | D37: 2 | E37: 6 | F37: 1 | G37: 0 | H37: 0 | I37: 0 | J37: 1 | K37: 0 | L37: 2 | M37: 1 | N37: 0 | O37: =SUM(C37:L37,N37) -> 15 | P37: =SUM(C37:N37) -> 16
B38: 14.00 - 14.15 | C38: 1 | D38: 1 | E38: 5 | F38: 2 | G38: 0 | H38: 2 | I38: 3 | J38: 0 | K38: 1 | L38: 0 | M38: 2 | N38: 0 | O38: =SUM(C38:L38,N38) -> 15 | P38: =SUM(C38:N38) -> 17
B39: 14.15 - 14.30 | C39: 3 | D39: 1 | E39: 3 | F39: 2 | G39: 0 | H39: 0 | I39: 2 | J39: 1 | K39: 0 | L39: 2 | M39: 3 | N39: 0 | O39: =SUM(C39:L39,N39) -> 14 | P39: =SUM(C39:N39) -> 17
B40: 14.30 - 14.45 | C40: 3 | D40: 0 | E40: 2 | F40: 2 | G40: 0 | H40: 0 | I40: 4 | J40: 2 | K40: 0 | L40: 7 | M40: 4 | N40: 0 | O40: =SUM(C40:L40,N40) -> 20 | P40: =SUM(C40:N40) -> 24
... B57: 18.45 - 19.00 | C57: 0 | D57: 0 | E57: 3 | F57: 1 | G57: 0 | H57: 0 | I57: 1 | J57: 0 | K57: 0 | L57: 1 | M57: 1 | N57: 0 | O57: =SUM(C57:L57,N57) -> 6 | P57: =SUM(C57:N57) -> 7
B58: Totals | C58: =SUM(C10:C57) -> 67 | D58: =SUM(D10:D57) -> 34 | E58: =SUM(E10:E57) -> 162 | F58: =SUM(F10:F57) -> 59 | G58: =SUM(G10:G57) -> 1 | H58: =SUM(H10:H57) -> 40 | I58: =SUM(I10:I57) -> 101 | J58: =SUM(J10:J57) -> 17 | ... P58: =SUM(P10:P57) -> 690
...

Sheet 30.07 Kigumba-Karuma
B1: Consultancy services for Preparation of Expressway Development Master Plan (EDMP) for Uganda
B2: MANUAL CLASSIFIED COUNT (MCC)
B3: ROAD NAME: | C3: ='29.07 Kigumba-Karuma'!C3:G3 -> MCC - C5 - STN113 - KIGUMBA-KARUMA ROAD
C5: Date | D5: ='30.07 Karuma-Kigumba'!D5 -> 30.07.19 | F5: Location | G5: ='29.07 Karuma-Kigumba'!G5:H5 -> nanda | J5: Surveyor | K5: ='29.07 Karuma-Kigumba'!K5:L5 -> xxx
C6: Dir. From | D6: ='29.07 Kigumba-Karuma'!D6:E6 -> Kigumba | F6: Dir. To | G6: ='29.07 Kigumba-Karuma'!G6:H6 -> Karuma | J6: Supervisor | K6: ='29.07 Karuma-Kigumba'!K6:L6 -> xxx
B8: Time / Veh Type | R8: SUMMARY TRAFFIC VOLUMES
C9: 1. Car | D9: 2. Station Wagon | E9: 3. Pickups | F9: 4. Minibus, matatu | G9: 5. Medium bus | H9: 6. Large Bus | I9: 7. Light Truck | J9: 8. Medium Truck | K9: 9. Heavy truck | L9: 10. Truck Trailer | M9: 11. Motor cycles | N9: 12. Tractors | O9: Total Excl M/Cycles | P9: Total All | R9: Time | S9: 1. Car | T9: 2. Station Wagon | U9: 3. Pickups | V9: 4. Minibus, matatu | W9: 5. Medium bus | X9: 6. Large Bus | Y9: 7. Light Truck | Z9: 8. Medium Truck | AA9: 9. Heavy truck | AB9: 10. Truck Trailer | AC9: 11. Motorcycles | AD9: 12. Tractors, Graders | AE9: Total Excl M/ Cycles | AF9: Total All
B10: 07.00 - 07.15 | C10: 1 | D10: 0 | E10: 0 | F10: 1 | G10: 0 | H10: 0 | I10: 1 | J10: 0 | K10: 0 | L10: 3 | M10: 4 | N10: 0 | O10: =SUM(C10:L10,N10) -> 6 | P10: =SUM(C10:N10) -> 10 | R10: 0700-0800 | S10: =SUM(C10:C13) -> 2 | T10: =SUM(D10:D13) -> 4 | U10: =SUM(E10:E13) -> 6 | V10: =SUM(F10:F13) -> 4 | W10: =SUM(G10:G13) -> 0 | X10: =SUM(H10:H13) -> 0 | Y10: =SUM(I10:I13) -> 5 | Z10: =SUM(J10:J13) -> 0 | ... AF10: =SUM(P10:P13) -> 43
B11: 07.15 - 07.30 | C11: 1 | D11: 2 | E11: 2 | F11: 1 | G11: 0 | H11: 0 | I11: 2 | J11: 0 | K11: 0 | L11: 0 | M11: 0 | N11: 0 | O11: =SUM(C11:L11,N11) -> 8 | P11: =SUM(C11:N11) -> 8 | R11: 0800-0900 | S11: =SUM(C14:C17) -> 6 | T11: =SUM(D14:D17) -> 8 | U11: =SUM(E14:E17) -> 10 | V11: =SUM(F14:F17) -> 5 | W11: =SUM(G14:G17) -> 0 | X11: =SUM(H14:H17) -> 0 | Y11: =SUM(I14:I17) -> 6 | Z11: =SUM(J14:J17) -> 2 | ... AF11: =SUM(P14:P17) -> 52
B12: 07.30 - 07.45 | C12: 0 | D12: 1 | E12: 2 | F12: 2 | G12: 0 | H12: 0 | I12: 1 | J12: 0 | K12: 0 | L12: 4 | M12: 3 | N12: 0 | O12: =SUM(C12:L12,N12) -> 10 | P12: =SUM(C12:N12) -> 13 | R12: 0900-1000 | S12: =SUM(C18:C21) -> 6 | T12: =SUM(D18:D21) -> 6 | U12: =SUM(E18:E21) -> 8 | V12: =SUM(F18:F21) -> 7 | W12: =SUM(G18:G21) -> 0 | X12: =SUM(H18:H21) -> 0 | Y12: =SUM(I18:I21) -> 7 | Z12: =SUM(J18:J21) -> 0 | ... AF12: =SUM(P18:P21) -> 53
B13: 07.45 - 08.00 | C13: 0 | D13: 1 | E13: 2 | F13: 0 | G13: 0 | H13: 0 | I13: 1 | J13: 0 | K13: 0 | L13: 6 | M13: 2 | N13: 0 | O13: =SUM(C13:L13,N13) -> 10 | P13: =SUM(C13:N13) -> 12 | R13: 1000-1100 | S13: =SUM(C22:C25) -> 9 | T13: =SUM(D22:D25) -> 7 | U13: =SUM(E22:E25) -> 9 | V13: =SUM(F22:F25) -> 8 | W13: =SUM(G22:G25) -> 0 | X13: =SUM(H22:H25) -> 3 | Y13: =SUM(I22:I25) -> 8 | Z13: =SUM(J22:J25) -> 1 | ... AF13: =SUM(P22:P25) -> 61
B14: 08.00 - 08.15 | C14: 1 | D14: 2 | E14: 2 | F14: 1 | G14: 0 | H14: 0 | I14: 2 | J14: 0 | K14: 1 | L14: 0 | M14: 2 | N14: 0 | O14: =SUM(C14:L14,N14) -> 9 | P14: =SUM(C14:N14) -> 11 | R14: 1100-1200 | S14: =SUM(C26:C29) -> 7 | T14: =SUM(D26:D29) -> 6 | U14: =SUM(E26:E29) -> 9 | V14: =SUM(F26:F29) -> 5 | W14: =SUM(G26:G29) -> 1 | X14: =SUM(H26:H29) -> 4 | Y14: =SUM(I26:I29) -> 7 | Z14: =SUM(J26:J29) -> 0 | ... AF14: =SUM(P26:P29) -> 57
B15: 08.15 - 08.30 | C15: 2 | D15: 1 | E15: 2 | F15: 2 | G15: 0 | H15: 0 | I15: 3 | J15: 1 | K15: 1 | L15: 1 | M15: 0 | N15: 0 | O15: =SUM(C15:L15,N15) -> 13 | P15: =SUM(C15:N15) -> 13 | R15: 1200-1300 | S15: =SUM(C30:C33) -> 12 | T15: =SUM(D30:D33) -> 5 | U15: =SUM(E30:E33) -> 8 | V15: =SUM(F30:F33) -> 8 | W15: =SUM(G30:G33) -> 0 | X15: =SUM(H30:H33) -> 3 | Y15: =SUM(I30:I33) -> 7 | Z15: =SUM(J30:J33) -> 0 | ... AF15: =SUM(P30:P33) -> 57
B16: 08.30 - 08.45 | C16: 1 | D16: 2 | E16: 3 | F16: 0 | G16: 0 | H16: 0 | I16: 1 | J16: 1 | K16: 0 | L16: 1 | M16: 4 | N16: 0 | O16: =SUM(C16:L16,N16) -> 9 | P16: =SUM(C16:N16) -> 13 | R16: 1300-1400 | S16: =SUM(C34:C37) -> 3 | T16: =SUM(D34:D37) -> 12 | U16: =SUM(E34:E37) -> 13 | V16: =SUM(F34:F37) -> 8 | W16: =SUM(G34:G37) -> 0 | X16: =SUM(H34:H37) -> 4 | Y16: =SUM(I34:I37) -> 10 | Z16: =SUM(J34:J37) -> 0 | ... AF16: =SUM(P34:P37) -> 66
B17: 08.45 - 9.00 | C17: 2 | D17: 3 | E17: 3 | F17: 2 | G17: 0 | H17: 0 | I17: 0 | J17: 0 | K17: 0 | L17: 1 | M17: 3 | N17: 1 | O17: =SUM(C17:L17,N17) -> 12 | P17: =SUM(C17:N17) -> 15 | R17: 1400-1500 | S17: =SUM(C38:C41) -> 12 | T17: =SUM(D38:D41) -> 10 | U17: =SUM(E38:E41) -> 13 | V17: =SUM(F38:F41) -> 5 | W17: =SUM(G38:G41) -> 0 | X17: =SUM(H38:H41) -> 2 | Y17: =SUM(I38:I41) -> 6 | Z17: =SUM(J38:J41) -> 1 | ... AF17: =SUM(P38:P41) -> 67
B18: 09.00 - 09.15 | C18: 2 | D18: 1 | E18: 1 | F18: 2 | G18: 0 | H18: 0 | I18: 2 | J18: 0 | K18: 0 | L18: 6 | M18: 3 | N18: 0 | O18: =SUM(C18:L18,N18) -> 14 | P18: =SUM(C18:N18) -> 17 | R18: 1500-1600 | S18: =SUM(C42:C45) -> 10 | T18: =SUM(D42:D45) -> 15 | U18: =SUM(E42:E45) -> 17 | V18: =SUM(F42:F45) -> 2 | W18: =SUM(G42:G45) -> 0 | X18: =SUM(H42:H45) -> 6 | Y18: =SUM(I42:I45) -> 6 | Z18: =SUM(J42:J45) -> 0 | ... AF18: =SUM(P42:P45) -> 71
B19: 09.15 - 09.30 | C19: 1 | D19: 2 | E19: 3 | F19: 1 | G19: 0 | H19: 0 | I19: 1 | J19: 0 | K19: 0 | L19: 1 | M19: 3 | N19: 0 | O19: =SUM(C19:L19,N19) -> 9 | P19: =SUM(C19:N19) -> 12 | R19: 1600-1700 | S19: =SUM(C46:C49) -> 11 | T19: =SUM(D46:D49) -> 14 | U19: =SUM(E46:E49) -> 16 | V19: =SUM(F46:F49) -> 14 | W19: =SUM(G46:G49) -> 0 | X19: =SUM(H46:H49) -> 7 | Y19: =SUM(I46:I49) -> 7 | Z19: =SUM(J46:J49) -> 0 | ... AF19: =SUM(P46:P49) -> 94
B20: 09.30 - 09.45 | C20: 1 | D20: 2 | E20: 2 | F20: 2 | G20: 0 | H20: 0 | I20: 3 | J20: 0 | K20: 0 | L20: 0 | M20: 0 | N20: 0 | O20: =SUM(C20:L20,N20) -> 10 | P20: =SUM(C20:N20) -> 10 | R20: 1700-1800 | S20: =SUM(C50:C53) -> 7 | T20: =SUM(D50:D53) -> 19 | U20: =SUM(E50:E53) -> 21 | V20: =SUM(F50:F53) -> 9 | W20: =SUM(G50:G53) -> 1 | X20: =SUM(H50:H53) -> 7 | Y20: =SUM(I50:I53) -> 8 | Z20: =SUM(J50:J53) -> 2 | ... AF20: =SUM(P50:P53) -> 94
B21: 09.45 - 10.00 | C21: 2 | D21: 1 | E21: 2 | F21: 2 | G21: 0 | H21: 0 | I21: 1 | J21: 0 | K21: 0 | L21: 0 | M21: 6 | N21: 0 | O21: =SUM(C21:L21,N21) -> 8 | P21: =SUM(C21:N21) -> 14 | R21: 1800-1900 | S21: =SUM(C54:C57) -> 4 | T21: =SUM(D54:D57) -> 9 | U21: =SUM(E54:E57) -> 13 | V21: =SUM(F54:F57) -> 9 | W21: =SUM(G54:G57) -> 0 | X21: =SUM(H54:H57) -> 0 | Y21: =SUM(I54:I57) -> 0 | Z21: =SUM(J54:J57) -> 1 | ... AF21: =SUM(P54:P57) -> 61
B22: 10.00 - 10.15 | C22: 0 | D22: 1 | E22: 2 | F22: 2 | G22: 0 | H22: 0 | I22: 0 | J22: 0 | K22: 0 | L22: 0 | M22: 5 | N22: 0 | O22: =SUM(C22:L22,N22) -> 5 | P22: =SUM(C22:N22) -> 10 | R22: AM Peak Hr | S22: =MAX(S10:S12) -> 6 | T22: =MAX(T10:T12) -> 8 | U22: =MAX(U10:U12) -> 10 | V22: =MAX(V10:V12) -> 7 | W22: =MAX(W10:W12) -> 0 | X22: =MAX(X10:X12) -> 0 | Y22: =MAX(Y10:Y12) -> 7 | Z22: =MAX(Z10:Z12) -> 2 | ... AF22: =MAX(AF10:AF12) -> 53
B23: 10.15 - 10.30 | C23: 3 | D23: 2 | E23: 2 | F23: 0 | G23: 0 | H23: 1 | I23: 3 | J23: 0 | K23: 0 | L23: 0 | M23: 3 | N23: 0 | O23: =SUM(C23:L23,N23) -> 11 | P23: =SUM(C23:N23) -> 14 | R23: IP Peak Hr | S23: =MAX(S13:S18) -> 12 | T23: =MAX(T13:T18) -> 15 | U23: =MAX(U13:U18) -> 17 | V23: =MAX(V13:V18) -> 8 | W23: =MAX(W13:W18) -> 1 | X23: =MAX(X13:X18) -> 6 | Y23: =MAX(Y13:Y18) -> 10 | Z23: =MAX(Z13:Z18) -> 1 | ... AF23: =MAX(AF13:AF18) -> 71
B24: 10.30 - 10.45 | C24: 4 | D24: 1 | E24: 1 | F24: 2 | G24: 0 | H24: 1 | I24: 2 | J24: 1 | K24: 0 | L24: 4 | M24: 1 | N24: 0 | O24: =SUM(C24:L24,N24) -> 16 | P24: =SUM(C24:N24) -> 17 | R24: PM Peak Hr | S24: =MAX(S19:S21) -> 11 | T24: =MAX(T19:T21) -> 19 | U24: =MAX(U19:U21) -> 21 | V24: =MAX(V19:V21) -> 14 | W24: =MAX(W19:W21) -> 1 | X24: =MAX(X19:X21) -> 7 | Y24: =MAX(Y19:Y21) -> 8 | Z24: =MAX(Z19:Z21) -> 2 | ... AF24: =MAX(AF19:AF21) -> 94
B25: 10.45 - 11.00 | C25: 2 | D25: 3 | E25: 4 | F25: 4 | G25: 0 | H25: 1 | I25: 3 | J25: 0 | K25: 0 | L25: 0 | M25: 3 | N25: 0 | O25: =SUM(C25:L25,N25) -> 17 | P25: =SUM(C25:N25) -> 20 | R25: AM Period | S25: =SUM(S10:S12) -> 14 | T25: =SUM(T10:T12) -> 18 | U25: =SUM(U10:U12) -> 24 | V25: =SUM(V10:V12) -> 16 | W25: =SUM(W10:W12) -> 0 | X25: =SUM(X10:X12) -> 0 | Y25: =SUM(Y10:Y12) -> 18 | Z25: =SUM(Z10:Z12) -> 2 | ... AF25: =SUM(AF10:AF12) -> 148
B26: 11.00 - 11.15 | C26: 3 | D26: 2 | E26: 3 | F26: 0 | G26: 0 | H26: 1 | I26: 3 | J26: 0 | K26: 0 | L26: 2 | M26: 5 | N26: 0 | O26: =SUM(C26:L26,N26) -> 14 | P26: =SUM(C26:N26) -> 19 | R26: IP Period | S26: =SUM(S13:S18) -> 53 | T26: =SUM(T13:T18) -> 55 | U26: =SUM(U13:U18) -> 69 | V26: =SUM(V13:V18) -> 36 | W26: =SUM(W13:W18) -> 1 | X26: =SUM(X13:X18) -> 22 | Y26: =SUM(Y13:Y18) -> 44 | Z26: =SUM(Z13:Z18) -> 2 | ... AF26: =SUM(AF13:AF18) -> 379
B27: 11.15 - 11.30 | C27: 2 | D27: 1 | E27: 1 | F27: 1 | G27: 0 | H27: 1 | I27: 0 | J27: 0 | K27: 0 | L27: 0 | M27: 2 | N27: 0 | O27: =SUM(C27:L27,N27) -> 6 | P27: =SUM(C27:N27) -> 8 | R27: PM Period | S27: =SUM(S19:S21) -> 22 | T27: =SUM(T19:T21) -> 42 | U27: =SUM(U19:U21) -> 50 | V27: =SUM(V19:V21) -> 32 | W27: =SUM(W19:W21) -> 1 | X27: =SUM(X19:X21) -> 14 | Y27: =SUM(Y19:Y21) -> 15 | Z27: =SUM(Z19:Z21) -> 3 | ... AF27: =SUM(AF19:AF21) -> 249
B28: 11.30 - 11.45 | C28: 1 | D28: 2 | E28: 3 | F28: 2 | G28: 0 | H28: 2 | I28: 3 | J28: 0 | K28: 0 | L28: 1 | M28: 4 | N28: 0 | O28: =SUM(C28:L28,N28) -> 14 | P28: =SUM(C28:N28) -> 18 | R28: 12 Hours | S28: =SUM(S10:S21) -> 89 | T28: =SUM(T10:T21) -> 115 | U28: =SUM(U10:U21) -> 143 | V28: =SUM(V10:V21) -> 84 | W28: =SUM(W10:W21) -> 2 | X28: =SUM(X10:X21) -> 36 | Y28: =SUM(Y10:Y21) -> 77 | Z28: =SUM(Z10:Z21) -> 7 | ... AF28: =SUM(AF10:AF21) -> 776
B29: 11.45 - 12.00 | C29: 1 | D29: 1 | E29: 2 | F29: 2 | G29: 1 | H29: 0 | I29: 1 | J29: 0 | K29: 0 | L29: 0 | M29: 4 | N29: 0 | O29: =SUM(C29:L29,N29) -> 8 | P29: =SUM(C29:N29) -> 12
B30: 12.00 - 12.15 | C30: 3 | D30: 1 | E30: 2 | F30: 3 | G30: 0 | H30: 0 | I30: 2 | J30: 0 | K30: 0 | L30: 1 | M30: 4 | N30: 0 | O30: =SUM(C30:L30,N30) -> 12 | P30: =SUM(C30:N30) -> 16
B31: 12.15 - 12.30 | C31: 6 | D31: 2 | E31: 2 | F31: 2 | G31: 0 | H31: 0 | I31: 2 | J31: 0 | K31: 0 | L31: 0 | M31: 3 | N31: 0 | O31: =SUM(C31:L31,N31) -> 14 | P31: =SUM(C31:N31) -> 17
B32: 12.30 - 12.45 | C32: 0 | D32: 2 | E32: 3 | F32: 1 | G32: 0 | H32: 2 | I32: 2 | J32: 0 | K32: 0 | L32: 0 | M32: 3 | N32: 0 | O32: =SUM(C32:L32,N32) -> 10 | P32: =SUM(C32:N32) -> 13
B33: 12.45 - 13.00 | C33: 3 | D33: 0 | E33: 1 | F33: 2 | G33: 0 | H33: 1 | I33: 1 | J33: 0 | K33: 0 | L33: 1 | M33: 2 | N33: 0 | O33: =SUM(C33:L33,N33) -> 9 | P33: =SUM(C33:N33) -> 11
B34: 13.00 - 13.15 | C34: 3 | D34: 2 | E34: 2 | F34: 4 | G34: 0 | H34: 0 | I34: 2 | J34: 0 | K34: 0 | L34: 0 | M34: 7 | N34: 0 | O34: =SUM(C34:L34,N34) -> 13 | P34: =SUM(C34:N34) -> 20
B35: 13.15 - 13.30 | C35: 0 | D35: 4 | E35: 4 | F35: 3 | G35: 0 | H35: 0 | I35: 3 | J35: 0 | K35: 0 | L35: 3 | M35: 1 | N35: 0 | O35: =SUM(C35:L35,N35) -> 17 | P35: =SUM(C35:N35) -> 18
B36: 13.30 - 13.45 | C36: 0 | D36: 4 | E36: 4 | F36: 1 | G36: 0 | H36: 2 | I36: 2 | J36: 0 | K36: 0 | L36: 1 | M36: 0 | N36: 0 | O36: =SUM(C36:L36,N36) -> 14 | P36: =SUM(C36:N36) -> 14
B37: 13.45 - 14.00 | C37: 0 | D37: 2 | E37: 3 | F37: 0 | G37: 0 | H37: 2 | I37: 3 | J37: 0 | K37: 0 | L37: 1 | M37: 3 | N37: 0 | O37: =SUM(C37:L37,N37) -> 11 | P37: =SUM(C37:N37) -> 14
B38: 14.00 - 14.15 | C38: 3 | D38: 2 | E38: 2 | F38: 2 | G38: 0 | H38: 1 | I38: 1 | J38: 0 | K38: 0 | L38: 1 | M38: 4 | N38: 0 | O38: =SUM(C38:L38,N38) -> 12 | P38: =SUM(C38:N38) -> 16
B39: 14.15 - 14.30 | C39: 3 | D39: 3 | E39: 3 | F39: 0 | G39: 0 | H39: 1 | I39: 2 | J39: 0 | K39: 0 | L39: 0 | M39: 6 | N39: 0 | O39: =SUM(C39:L39,N39) -> 12 | P39: =SUM(C39:N39) -> 18
B40: 14.30 - 14.45 | C40: 4 | D40: 3 | E40: 4 | F40: 2 | G40: 0 | H40: 0 | I40: 1 | J40: 0 | K40: 0 | L40: 0 | M40: 1 | N40: 0 | O40: =SUM(C40:L40,N40) -> 14 | P40: =SUM(C40:N40) -> 15
... B57: 18.45 - 19.00 | C57: 1 | D57: 3 | E57: 4 | F57: 1 | G57: 0 | H57: 0 | I57: 0 | J57: 0 | K57: 0 | L57: 2 | M57: 10 | N57: 0 | O57: =SUM(C57:L57,N57) -> 11 | P57: =SUM(C57:N57) -> 21
B58: Totals | C58: =SUM(C10:C57) -> 89 | D58: =SUM(D10:D57) -> 115 | E58: =SUM(E10:E57) -> 143 | F58: =SUM(F10:F57) -> 84 | G58: =SUM(G10:G57) -> 2 | H58: =SUM(H10:H57) -> 36 | I58: =SUM(I10:I57) -> 77 | J58: =SUM(J10:J57) -> 7 | ... P58: =SUM(P10:P57) -> 776
...

Sheet 31.07 Karuma-Kigumba
B1: Consultancy services for Preparation of Expressway Development Master Plan (EDMP) for Uganda
B2: MANUAL CLASSIFIED COUNT (MCC)
B3: ROAD NAME: | C3: ='29.07 Karuma-Kigumba'!C3:G3 -> MCC - C5 - STN113 - KIGUMBA-KARUMA ROAD
C5: Date | D5: 31.07.19 | F5: Location | G5: ='29.07 Karuma-Kigumba'!G5:H5 -> nanda | J5: Surveyor | K5: ='29.07 Karuma-Kigumba'!K5:L5 -> xxx
C6: Dir. From | D6: ='29.07 Karuma-Kigumba'!D6:E6 -> karuma | F6: Dir. To | G6: ='29.07 Karuma-Kigumba'!G6:H6 -> kigumba | J6: Supervisor | K6: ='29.07 Karuma-Kigumba'!K6:L6 -> xxx
B8: Time / Veh Type | R8: SUMMARY TRAFFIC VOLUMES
C9: 1. Car | D9: 2. Station Wagon | E9: 3. Pickups | F9: 4. Minibus, matatu | G9: 5. Medium bus | H9: 6. Large Bus | I9: 7. Light Truck | J9: 8. Medium Truck | K9: 9. Heavy truck | L9: 10. Truck Trailer | M9: 11. Motor cycles | N9: 12. Tractors | O9: Total Excl M/Cycles | P9: Total All | R9: Time | S9: 1. Car | T9: 2. Station Wagon | U9: 3. Pickups | V9: 4. Minibus, matatu | W9: 5. Medium bus | X9: 6. Large Bus | Y9: 7. Light Truck | Z9: 8. Medium Truck | AA9: 9. Heavy truck | AB9: 10. Truck Trailer | AC9: 11. Motorcycles | AD9: 12. Tractors, Graders | AE9: Total Excl M/ Cycles | AF9: Total All
B10: 07.00 - 07.15 | C10: 0 | D10: 0 | E10: 1 | F10: 1 | G10: 0 | H10: 0 | I10: 1 | J10: 0 | K10: 1 | L10: 2 | M10: 2 | N10: 0 | O10: =SUM(C10:L10,N10) -> 6 | P10: =SUM(C10:N10) -> 8 | R10: 0700-0800 | S10: =SUM(C10:C13) -> 3 | T10: =SUM(D10:D13) -> 0 | U10: =SUM(E10:E13) -> 5 | V10: =SUM(F10:F13) -> 3 | W10: =SUM(G10:G13) -> 0 | X10: =SUM(H10:H13) -> 0 | Y10: =SUM(I10:I13) -> 5 | Z10: =SUM(J10:J13) -> 0 | ... AF10: =SUM(P10:P13) -> 26
B11: 07.15 - 07.30 | C11: 2 | D11: 0 | E11: 0 | F11: 0 | G11: 0 | H11: 0 | I11: 1 | J11: 0 | K11: 0 | L11: 1 | M11: 0 | N11: 0 | O11: =SUM(C11:L11,N11) -> 4 | P11: =SUM(C11:N11) -> 4 | R11: 0800-0900 | S11: =SUM(C14:C17) -> 2 | T11: =SUM(D14:D17) -> 2 | U11: =SUM(E14:E17) -> 13 | V11: =SUM(F14:F17) -> 3 | W11: =SUM(G14:G17) -> 0 | X11: =SUM(H14:H17) -> 1 | Y11: =SUM(I14:I17) -> 4 | Z11: =SUM(J14:J17) -> 0 | ... AF11: =SUM(P14:P17) -> 36
B12: 07.30 - 07.45 | C12: 1 | D12: 0 | E12: 2 | F12: 2 | G12: 0 | H12: 0 | I12: 0 | J12: 0 | K12: 0 | L12: 0 | M12: 1 | N12: 0 | O12: =SUM(C12:L12,N12) -> 5 | P12: =SUM(C12:N12) -> 6 | R12: 0900-1000 | S12: =SUM(C18:C21) -> 4 | T12: =SUM(D18:D21) -> 3 | U12: =SUM(E18:E21) -> 11 | V12: =SUM(F18:F21) -> 6 | W12: =SUM(G18:G21) -> 0 | X12: =SUM(H18:H21) -> 2 | Y12: =SUM(I18:I21) -> 3 | Z12: =SUM(J18:J21) -> 1 | ... AF12: =SUM(P18:P21) -> 46
B13: 07.45 - 08.00 | C13: 0 | D13: 0 | E13: 2 | F13: 0 | G13: 0 | H13: 0 | I13: 3 | J13: 0 | K13: 0 | L13: 1 | M13: 2 | N13: 0 | O13: =SUM(C13:L13,N13) -> 6 | P13: =SUM(C13:N13) -> 8 | R13: 1000-1100 | S13: =SUM(C22:C25) -> 8 | T13: =SUM(D22:D25) -> 2 | U13: =SUM(E22:E25) -> 10 | V13: =SUM(F22:F25) -> 6 | W13: =SUM(G22:G25) -> 0 | X13: =SUM(H22:H25) -> 2 | Y13: =SUM(I22:I25) -> 3 | Z13: =SUM(J22:J25) -> 3 | ... AF13: =SUM(P22:P25) -> 45
B14: 08.00 - 08.15 | C14: 0 | D14: 0 | E14: 3 | F14: 0 | G14: 0 | H14: 0 | I14: 0 | J14: 0 | K14: 0 | L14: 1 | M14: 1 | N14: 0 | O14: =SUM(C14:L14,N14) -> 4 | P14: =SUM(C14:N14) -> 5 | R14: 1100-1200 | S14: =SUM(C26:C29) -> 12 | T14: =SUM(D26:D29) -> 5 | U14: =SUM(E26:E29) -> 17 | V14: =SUM(F26:F29) -> 3 | W14: =SUM(G26:G29) -> 0 | X14: =SUM(H26:H29) -> 4 | Y14: =SUM(I26:I29) -> 2 | Z14: =SUM(J26:J29) -> 0 | ... AF14: =SUM(P26:P29) -> 59
B15: 08.15 - 08.30 | C15: 1 | D15: 0 | E15: 2 | F15: 1 | G15: 0 | H15: 0 | I15: 0 | J15: 0 | K15: 0 | L15: 0 | M15: 4 | N15: 0 | O15: =SUM(C15:L15,N15) -> 4 | P15: =SUM(C15:N15) -> 8 | R15: 1200-1300 | S15: =SUM(C30:C33) -> 7 | T15: =SUM(D30:D33) -> 5 | U15: =SUM(E30:E33) -> 18 | V15: =SUM(F30:F33) -> 6 | W15: =SUM(G30:G33) -> 1 | X15: =SUM(H30:H33) -> 8 | Y15: =SUM(I30:I33) -> 6 | Z15: =SUM(J30:J33) -> 1 | ... AF15: =SUM(P30:P33) -> 64
B16: 08.30 - 08.45 | C16: 0 | D16: 2 | E16: 5 | F16: 1 | G16: 0 | H16: 1 | I16: 2 | J16: 0 | K16: 0 | L16: 0 | M16: 4 | N16: 0 | O16: =SUM(C16:L16,N16) -> 11 | P16: =SUM(C16:N16) -> 15 | R16: 1300-1400 | S16: =SUM(C34:C37) -> 13 | T16: =SUM(D34:D37) -> 5 | U16: =SUM(E34:E37) -> 20 | V16: =SUM(F34:F37) -> 8 | W16: =SUM(G34:G37) -> 0 | X16: =SUM(H34:H37) -> 4 | Y16: =SUM(I34:I37) -> 11 | Z16: =SUM(J34:J37) -> 1 | ... AF16: =SUM(P34:P37) -> 94
B17: 08.45 - 9.00 | C17: 1 | D17: 0 | E17: 3 | F17: 1 | G17: 0 | H17: 0 | I17: 2 | J17: 0 | K17: 0 | L17: 0 | M17: 1 | N17: 0 | O17: =SUM(C17:L17,N17) -> 7 | P17: =SUM(C17:N17) -> 8 | R17: 1400-1500 | S17: =SUM(C38:C41) -> 5 | T17: =SUM(D38:D41) -> 5 | U17: =SUM(E38:E41) -> 18 | V17: =SUM(F38:F41) -> 10 | W17: =SUM(G38:G41) -> 0 | X17: =SUM(H38:H41) -> 5 | Y17: =SUM(I38:I41) -> 8 | Z17: =SUM(J38:J41) -> 0 | ... AF17: =SUM(P38:P41) -> 69
B18: 09.00 - 09.15 | C18: 0 | D18: 1 | E18: 4 | F18: 3 | G18: 0 | H18: 1 | I18: 1 | J18: 1 | K18: 0 | L18: 0 | M18: 1 | N18: 0 | O18: =SUM(C18:L18,N18) -> 11 | P18: =SUM(C18:N18) -> 12 | R18: 1500-1600 | S18: =SUM(C42:C45) -> 5 | T18: =SUM(D42:D45) -> 5 | U18: =SUM(E42:E45) -> 17 | V18: =SUM(F42:F45) -> 4 | W18: =SUM(G42:G45) -> 1 | X18: =SUM(H42:H45) -> 4 | Y18: =SUM(I42:I45) -> 15 | Z18: =SUM(J42:J45) -> 1 | ... AF18: =SUM(P42:P45) -> 79
B19: 09.15 - 09.30 | C19: 1 | D19: 1 | E19: 3 | F19: 2 | G19: 0 | H19: 0 | I19: 1 | J19: 0 | K19: 0 | L19: 1 | M19: 6 | N19: 1 | O19: =SUM(C19:L19,N19) -> 10 | P19: =SUM(C19:N19) -> 16 | R19: 1600-1700 | S19: =SUM(C46:C49) -> 3 | T19: =SUM(D46:D49) -> 5 | U19: =SUM(E46:E49) -> 19 | V19: =SUM(F46:F49) -> 5 | W19: =SUM(G46:G49) -> 0 | X19: =SUM(H46:H49) -> 6 | Y19: =SUM(I46:I49) -> 15 | Z19: =SUM(J46:J49) -> 3 | ... AF19: =SUM(P46:P49) -> 80
B20: 09.30 - 09.45 | C20: 2 | D20: 1 | E20: 3 | F20: 0 | G20: 0 | H20: 0 | I20: 0 | J20: 0 | K20: 0 | L20: 1 | M20: 2 | N20: 0 | O20: =SUM(C20:L20,N20) -> 7 | P20: =SUM(C20:N20) -> 9 | R20: 1700-1800 | S20: =SUM(C50:C53) -> 5 | T20: =SUM(D50:D53) -> 3 | U20: =SUM(E50:E53) -> 17 | V20: =SUM(F50:F53) -> 8 | W20: =SUM(G50:G53) -> 0 | X20: =SUM(H50:H53) -> 4 | Y20: =SUM(I50:I53) -> 5 | Z20: =SUM(J50:J53) -> 0 | ... AF20: =SUM(P50:P53) -> 70
B21: 09.45 - 10.00 | C21: 1 | D21: 0 | E21: 1 | F21: 1 | G21: 0 | H21: 1 | I21: 1 | J21: 0 | K21: 0 | L21: 0 | M21: 4 | N21: 0 | O21: =SUM(C21:L21,N21) -> 5 | P21: =SUM(C21:N21) -> 9 | R21: 1800-1900 | S21: =SUM(C54:C57) -> 8 | T21: =SUM(D54:D57) -> 3 | U21: =SUM(E54:E57) -> 13 | V21: =SUM(F54:F57) -> 11 | W21: =SUM(G54:G57) -> 0 | X21: =SUM(H54:H57) -> 2 | Y21: =SUM(I54:I57) -> 17 | Z21: =SUM(J54:J57) -> 2 | ... AF21: =SUM(P54:P57) -> 78
B22: 10.00 - 10.15 | C22: 2 | D22: 1 | E22: 4 | F22: 1 | G22: 0 | H22: 2 | I22: 0 | J22: 1 | K22: 0 | L22: 0 | M22: 3 | N22: 0 | O22: =SUM(C22:L22,N22) -> 11 | P22: =SUM(C22:N22) -> 14 | R22: AM Peak Hr | S22: =MAX(S10:S12) -> 4 | T22: =MAX(T10:T12) -> 3 | U22: =MAX(U10:U12) -> 13 | V22: =MAX(V10:V12) -> 6 | W22: =MAX(W10:W12) -> 0 | X22: =MAX(X10:X12) -> 2 | Y22: =MAX(Y10:Y12) -> 5 | Z22: =MAX(Z10:Z12) -> 1 | ... AF22: =MAX(AF10:AF12) -> 46
B23: 10.15 - 10.30 | C23: 4 | D23: 0 | E23: 2 | F23: 0 | G23: 0 | H23: 0 | I23: 2 | J23: 1 | K23: 0 | L23: 0 | M23: 2 | N23: 0 | O23: =SUM(C23:L23,N23) -> 9 | P23: =SUM(C23:N23) -> 11 | R23: IP Peak Hr | S23: =MAX(S13:S18) -> 13 | T23: =MAX(T13:T18) -> 5 | U23: =MAX(U13:U18) -> 20 | V23: =MAX(V13:V18) -> 10 | W23: =MAX(W13:W18) -> 1 | X23: =MAX(X13:X18) -> 8 | Y23: =MAX(Y13:Y18) -> 15 | Z23: =MAX(Z13:Z18) -> 3 | ... AF23: =MAX(AF13:AF18) -> 94
B24: 10.30 - 10.45 | C24: 0 | D24: 1 | E24: 4 | F24: 3 | G24: 0 | H24: 0 | I24: 1 | J24: 1 | K24: 1 | L24: 1 | M24: 2 | N24: 0 | O24: =SUM(C24:L24,N24) -> 12 | P24: =SUM(C24:N24) -> 14 | R24: PM Peak Hr | S24: =MAX(S19:S21) -> 8 | T24: =MAX(T19:T21) -> 5 | U24: =MAX(U19:U21) -> 19 | V24: =MAX(V19:V21) -> 11 | W24: =MAX(W19:W21) -> 0 | X24: =MAX(X19:X21) -> 6 | Y24: =MAX(Y19:Y21) -> 17 | Z24: =MAX(Z19:Z21) -> 3 | ... AF24: =MAX(AF19:AF21) -> 80
B25: 10.45 - 11.00 | C25: 2 | D25: 0 | E25: 0 | F25: 2 | G25: 0 | H25: 0 | I25: 0 | J25: 0 | K25: 0 | L25: 0 | M25: 2 | N25: 0 | O25: =SUM(C25:L25,N25) -> 4 | P25: =SUM(C25:N25) -> 6 | R25: AM Period | S25: =SUM(S10:S12) -> 9 | T25: =SUM(T10:T12) -> 5 | U25: =SUM(U10:U12) -> 29 | V25: =SUM(V10:V12) -> 12 | W25: =SUM(W10:W12) -> 0 | X25: =SUM(X10:X12) -> 3 | Y25: =SUM(Y10:Y12) -> 12 | Z25: =SUM(Z10:Z12) -> 1 | ... AF25: =SUM(AF10:AF12) -> 108
B26: 11.00 - 11.15 | C26: 3 | D26: 1 | E26: 4 | F26: 2 | G26: 0 | H26: 1 | I26: 0 | J26: 0 | K26: 0 | L26: 3 | M26: 7 | N26: 0 | O26: =SUM(C26:L26,N26) -> 14 | P26: =SUM(C26:N26) -> 21 | R26: IP Period | S26: =SUM(S13:S18) -> 50 | T26: =SUM(T13:T18) -> 27 | U26: =SUM(U13:U18) -> 100 | V26: =SUM(V13:V18) -> 37 | W26: =SUM(W13:W18) -> 2 | X26: =SUM(X13:X18) -> 27 | Y26: =SUM(Y13:Y18) -> 45 | Z26: =SUM(Z13:Z18) -> 6 | ... AF26: =SUM(AF13:AF18) -> 410
B27: 11.15 - 11.30 | C27: 2 | D27: 1 | E27: 4 | F27: 0 | G27: 0 | H27: 0 | I27: 0 | J27: 0 | K27: 0 | L27: 0 | M27: 0 | N27: 0 | O27: =SUM(C27:L27,N27) -> 7 | P27: =SUM(C27:N27) -> 7 | R27: PM Period | S27: =SUM(S19:S21) -> 16 | T27: =SUM(T19:T21) -> 11 | U27: =SUM(U19:U21) -> 49 | V27: =SUM(V19:V21) -> 24 | W27: =SUM(W19:W21) -> 0 | X27: =SUM(X19:X21) -> 12 | Y27: =SUM(Y19:Y21) -> 37 | Z27: =SUM(Z19:Z21) -> 5 | ... AF27: =SUM(AF19:AF21) -> 228
B28: 11.30 - 11.45 | C28: 3 | D28: 1 | E28: 4 | F28: 1 | G28: 0 | H28: 2 | I28: 0 | J28: 0 | K28: 0 | L28: 2 | M28: 1 | N28: 0 | O28: =SUM(C28:L28,N28) -> 13 | P28: =SUM(C28:N28) -> 14 | R28: 12 Hours | S28: =SUM(S10:S21) -> 75 | T28: =SUM(T10:T21) -> 43 | U28: =SUM(U10:U21) -> 178 | V28: =SUM(V10:V21) -> 73 | W28: =SUM(W10:W21) -> 2 | X28: =SUM(X10:X21) -> 42 | Y28: =SUM(Y10:Y21) -> 94 | Z28: =SUM(Z10:Z21) -> 12 | ... AF28: =SUM(AF10:AF21) -> 746
B29: 11.45 - 12.00 | C29: 4 | D29: 2 | E29: 5 | F29: 0 | G29: 0 | H29: 1 | I29: 2 | J29: 0 | K29: 0 | L29: 0 | M29: 3 | N29: 0 | O29: =SUM(C29:L29,N29) -> 14 | P29: =SUM(C29:N29) -> 17
B30: 12.00 - 12.15 | C30: 0 | D30: 1 | E30: 5 | F30: 2 | G30: 0 | H30: 1 | I30: 0 | J30: 1 | K30: 0 | L30: 1 | M30: 2 | N30: 0 | O30: =SUM(C30:L30,N30) -> 11 | P30: =SUM(C30:N30) -> 13
B31: 12.15 - 12.30 | C31: 4 | D31: 2 | E31: 6 | F31: 1 | G31: 1 | H31: 4 | I31: 4 | J31: 0 | K31: 0 | L31: 1 | M31: 1 | N31: 0 | O31: =SUM(C31:L31,N31) -> 23 | P31: =SUM(C31:N31) -> 24
B32: 12.30 - 12.45 | C32: 1 | D32: 1 | E32: 3 | F32: 2 | G32: 0 | H32: 0 | I32: 2 | J32: 0 | K32: 0 | L32: 0 | M32: 1 | N32: 0 | O32: =SUM(C32:L32,N32) -> 9 | P32: =SUM(C32:N32) -> 10
B33: 12.45 - 13.00 | C33: 2 | D33: 1 | E33: 4 | F33: 1 | G33: 0 | H33: 3 | I33: 0 | J33: 0 | K33: 0 | L33: 2 | M33: 4 | N33: 0 | O33: =SUM(C33:L33,N33) -> 13 | P33: =SUM(C33:N33) -> 17
B34: 13.00 - 13.15 | C34: 3 | D34: 2 | E34: 7 | F34: 2 | G34: 0 | H34: 2 | I34: 2 | J34: 1 | K34: 0 | L34: 0 | M34: 5 | N34: 0 | O34: =SUM(C34:L34,N34) -> 19 | P34: =SUM(C34:N34) -> 24
