Workbook
Name Dist: 'ALL DATA'!$S:$S
Name Jtime: 'ALL DATA'!$T:$T
Name Tripfreq: 'ALL DATA'!$U:$U
Name Veh: 'ALL DATA'!$D:$D
Name Veh_Type: '11.10 KITEMU-BUDDO'!$D$9:$D$37
Name Veh_Type: '12.10 KITEMU-BUDDO'!$D$9:$D$37
Name Veh_Type: '[1]25.07 BUSEGA-NATEETE'!$D:$D
Name Veh_Type: 'ALL DATA'!$D$9:$D$37
Name zones: #REF!
Name zones: #REF!
Name Zones_Ndeke: #REF!
Name Zones_Ndeke: #REF!

Sheet Analysis
B3: Vehicle OD Sample Proportions | N3: Average Journey Time
B4: Vehicle Types | C4: OD Sample | D4: OD Sample, % | N4: Journey Time Range (Hrs) | O4: Cummu-lative | P4: No of Vehicles | Q4: No. of Vehicles, %
B5: Car | C5: =COUNTIF('ALL DATA'!$D$9:$D$5000,"1") -> 299 | D5: =C5/$C$17 -> 0.53971119 | N5: 0-0.25 | O5: =COUNTIF(Jtime,"<=0.25") -> 116 | P5: =O5 -> 116 | Q5: =P5/$O$15 -> 0.21129326
B6: Station Wagon | C6: =COUNTIF('ALL DATA'!$D$9:$D$5000,"2") -> 59 | D6: =C6/$C$17 -> 0.10649819 | N6: 0.25-0.50 | O6: =COUNTIF(Jtime,"<=0.5") -> 253 | P6: =O6-O5 -> 137 | Q6: =P6/$O$15 -> 0.24954463
B7: Pickups | C7: =COUNTIF('ALL DATA'!$D$9:$D$5000,"3") -> 37 | D7: =C7/$C$17 -> 0.066787004 | N7: 0.50-0.75 | O7: =COUNTIF(Jtime,"<=0.75") -> 291 | P7: =O7-O6 -> 38 | Q7: =P7/$O$15 -> 0.069216758
B8: Minibus, matatu | C8: =COUNTIF('ALL DATA'!$D$9:$D$5000,"4") -> 60 | D8: =C8/$C$17 -> 0.10830325 | N8: 0.75-1.00 | O8: =COUNTIF(Jtime,"<=1.0") -> 398 | P8: =O8-O7 -> 107 | Q8: =P8/$O$15 -> 0.19489982
B9: Medium bus | C9: =COUNTIF('ALL DATA'!$D$9:$D$5000,"5") -> 0 | D9: =C9/$C$17 -> 0 | N9: 1.00-1.50 | O9: =COUNTIF(Jtime,"<=1.5") -> 434 | P9: =O9-O8 -> 36 | Q9: =P9/$O$15 -> 0.06557377
B10: Large Bus | C10: =COUNTIF('ALL DATA'!$D$9:$D$5000,"6") -> 4 | D10: =C10/$C$17 -> 0.0072202166 | N10: 1.5-2.0 | O10: =COUNTIF(Jtime,"<=2") -> 499 | P10: =O10-O9 -> 65 | Q10: =P10/$O$15 -> 0.11839709
B11: Light Truck | C11: =COUNTIF('ALL DATA'!$D$9:$D$5000,"7") -> 42 | D11: =C11/$C$17 -> 0.075812274 | N11: 2.0-3.0 | O11: =COUNTIF(Jtime,"<=3") -> 536 | P11: =O11-O10 -> 37 | Q11: =P11/$O$15 -> 0.067395264
B12: Medium Truck | C12: =COUNTIF('ALL DATA'!$D$9:$D$5000,"8") -> 11 | D12: =C12/$C$17 -> 0.019855596 | N12: 3.0-5.0 | O12: =COUNTIF(Jtime,"<=5") -> 546 | P12: =O12-O11 -> 10 | Q12: =P12/$O$15 -> 0.018214936
B13: Heavy truck | C13: =COUNTIF('ALL DATA'!$D$9:$D$5000,"9") -> 8 | D13: =C13/$C$17 -> 0.014440433 | N13: 5.0-7.5 | O13: =COUNTIF(Jtime,"<=7.5") -> 548 | P13: =O13-O12 -> 2 | Q13: =P13/$O$15 -> 0.0036429872
B14: Truck Trailer | C14: =COUNTIF('ALL DATA'!$D$9:$D$5000,"10") -> 0 | D14: =C14/$C$17 -> 0 | N14: 7.5-10 | O14: =COUNTIF(Jtime,"<=10") -> 549 | P14: =O14-O13 -> 1 | Q14: =P14/$O$15 -> 0.0018214936
B15: Motor cycles | C15: =COUNTIF('ALL DATA'!$D$9:$D$5000,"11") -> 34 | D15: =C15/$C$17 -> 0.061371841 | N15: Over 10 | O15: =COUNTIF(Jtime,"<=15") -> 549 | P15: =O15-O14 -> 0 | Q15: =P15/$O$15 -> 0
B16: Tractors | C16: =COUNTIF('ALL DATA'!$D$9:$D$5000,"12") -> 0 | D16: =C16/$C$17 -> 0
C17: =SUM(C5:C16) -> 554
N21: Trip Frequency
B22: Journey Purpose | N22: Trip Frequency | O22: No of Vehicles | P22: No. of Vehicles, %
B23: Purpose | C23: Respondents | D23: Percent | N23: More than 2 times every day | O23: =COUNTIF(Tripfreq,"=1") -> 177 | P23: =O23/$O$29 -> 0.33022388
B24: Home-Work | C24: =COUNTIF('ALL DATA'!$R$9:$R$5000,"Home-Work") -> 135 | D24: =C24/$C$29 -> 0.24368231 | N24: Daily (Up and Down) | O24: =COUNTIF(Tripfreq,"=2") -> 236 | P24: =O24/$O$29 -> 0.44029851
B25: Home-Study | C25: =COUNTIF('ALL DATA'!$R$9:$R$369,"Home-Study") -> 0 | D25: =C25/$C$29 -> 0 | N25: 2/3 times a week | O25: =COUNTIF(Tripfreq,"=3") -> 39 | P25: =O25/$O$29 -> 0.072761194
B26: Work-Home | C26: =COUNTIF('ALL DATA'!$R$9:$R$369,"Work-Home") -> 134 | D26: =C26/$C$29 -> 0.24187726 | N26: Once a week | O26: =COUNTIF(Tripfreq,"=4") -> 32 | P26: =O26/$O$29 -> 0.059701493
B27: Work-Work | C27: =COUNTIF('ALL DATA'!$R$9:$R$369,"Work-Work") -> 62 | D27: =C27/$C$29 -> 0.11191336 | N27: Once a month | O27: =COUNTIF(Tripfreq,"=5") -> 11 | P27: =O27/$O$29 -> 0.020522388
B28: Others | C28: =C29-SUM(C24:C27) -> 223 | D28: =C28/$C$29 -> 0.40252708 | N28: Once in a while | O28: =COUNTIF(Tripfreq,"=6") -> 41 | P28: =O28/$O$29 -> 0.076492537
B29: Total | C29: =C17 -> 554 | O29: =SUM(O23:O28) -> 536
B40: Expressway Use
B41: Response | C41: Number | D41: Percent
B42: Yes | C42: =COUNTIF('ALL DATA'!$Y$9:$Y$5000,"Y") -> 547 | D42: =C42/$C$44 -> 0.98736462
B43: No | C43: =C44-C42 -> 7 | D43: =C43/$C$44 -> 0.012635379
B44: Total | C44: =C29 -> 554
R47: Home | S47: Work | T47: Study | U47: Commercial | V47: Tourism | W47: Leisure/Social | X47: Hospital | Y47: Others
P48: 1 | Q48: Home | R48: =R59/SUM($R$59:$Y$66) -> 0.048736462 | S48: =S59/SUM($R$59:$Y$66) -> 0.24368231 | T48: =T59/SUM($R$59:$Y$66) -> 0.0036101083 | U48: =U59/SUM($R$59:$Y$66) -> 0.018050542 | V48: =V59/SUM($R$59:$Y$66) -> 0 | W48: =W59/SUM($R$59:$Y$66) -> 0.016245487 | X48: =X59/SUM($R$59:$Y$66) -> 0.0072202166 | Y48: =Y59/SUM($R$59:$Y$66) -> 0.010830325
P49: 2 | Q49: Work | R49: =R60/SUM($R$59:$Y$66) -> 0.33935018 | S49: =S60/SUM($R$59:$Y$66) -> 0.16064982 | T49: =T60/SUM($R$59:$Y$66) -> 0 | U49: =U60/SUM($R$59:$Y$66) -> 0.016245487 | V49: =V60/SUM($R$59:$Y$66) -> 0 | W49: =W60/SUM($R$59:$Y$66) -> 0.0036101083 | X49: =X60/SUM($R$59:$Y$66) -> 0 | Y49: =Y60/SUM($R$59:$Y$66) -> 0.0018050542
P50: 3 | Q50: Study | R50: =R61/SUM($R$59:$Y$66) -> 0.0018050542 | S50: =S61/SUM($R$59:$Y$66) -> 0 | T50: =T61/SUM($R$59:$Y$66) -> 0 | U50: =U61/SUM($R$59:$Y$66) -> 0 | V50: =V61/SUM($R$59:$Y$66) -> 0 | W50: =W61/SUM($R$59:$Y$66) -> 0 | X50: =X61/SUM($R$59:$Y$66) -> 0 | Y50: =Y61/SUM($R$59:$Y$66) -> 0
P51: 4 | Q51: Commercial | R51: =R62/SUM($R$59:$Y$66) -> 0.018050542 | S51: =S62/SUM($R$59:$Y$66) -> 0.0054151625 | T51: =T62/SUM($R$59:$Y$66) -> 0 | U51: =U62/SUM($R$59:$Y$66) -> 0.070397112 | V51: =V62/SUM($R$59:$Y$66) -> 0 | W51: =W62/SUM($R$59:$Y$66) -> 0.0036101083 | X51: =X62/SUM($R$59:$Y$66) -> 0 | Y51: =Y62/SUM($R$59:$Y$66) -> 0
P52: 5 | Q52: Tourism | R52: =R63/SUM($R$59:$Y$66) -> 0 | S52: =S63/SUM($R$59:$Y$66) -> 0 | T52: =T63/SUM($R$59:$Y$66) -> 0 | U52: =U63/SUM($R$59:$Y$66) -> 0 | V52: =V63/SUM($R$59:$Y$66) -> 0 | W52: =W63/SUM($R$59:$Y$66) -> 0 | X52: =X63/SUM($R$59:$Y$66) -> 0 | Y52: =Y63/SUM($R$59:$Y$66) -> 0
P53: 6 | Q53: Leisure/Social | R53: =R64/SUM($R$59:$Y$66) -> 0.012635379 | S53: =S64/SUM($R$59:$Y$66) -> 0 | T53: =T64/SUM($R$59:$Y$66) -> 0 | U53: =U64/SUM($R$59:$Y$66) -> 0 | V53: =V64/SUM($R$59:$Y$66) -> 0 | W53: =W64/SUM($R$59:$Y$66) -> 0.0036101083 | X53: =X64/SUM($R$59:$Y$66) -> 0 | Y53: =Y64/SUM($R$59:$Y$66) -> 0
P54: 7 | Q54: Hospital | R54: =R65/SUM($R$59:$Y$66) -> 0.0054151625 | S54: =S65/SUM($R$59:$Y$66) -> 0 | T54: =T65/SUM($R$59:$Y$66) -> 0 | U54: =U65/SUM($R$59:$Y$66) -> 0 | V54: =V65/SUM($R$59:$Y$66) -> 0 | W54: =W65/SUM($R$59:$Y$66) -> 0 | X54: =X65/SUM($R$59:$Y$66) -> 0 | Y54: =Y65/SUM($R$59:$Y$66) -> 0
P55: 8 | Q55: Others | R55: =R66/SUM($R$59:$Y$66) -> 0.0072202166 | S55: =S66/SUM($R$59:$Y$66) -> 0.0018050542 | T55: =T66/SUM($R$59:$Y$66) -> 0 | U55: =U66/SUM($R$59:$Y$66) -> 0 | V55: =V66/SUM($R$59:$Y$66) -> 0 | W55: =W66/SUM($R$59:$Y$66) -> 0 | X55: =X66/SUM($R$59:$Y$66) -> 0 | Y55: =Y66/SUM($R$59:$Y$66) -> 0
R57: 1 | S57: 2 | T57: 3 | U57: 4 | V57: 5 | W57: 6 | X57: 7 | Y57: 8
B58: Willingness to Pay | R58: Home | S58: Work | T58: Study | U58: Commercial | V58: Tourism | W58: Leisure/Social | X58: Hospital | Y58: Others
...

Sheet ALL DATA
B1: Consultancy services for Preparation of Expressway Development Master Plan (EDMP) for Uganda
B2: Roadside OD Interview Survey
B4: Date: | C4: 11.10.19 | E4: Road Name: | F4: BUDO ROAD | I4: Direction From: | L4: BUDO | N4: Interviewers: | O4: MASINDE DENIS | V4: Supervisor: | W4: FLORENCE | Y4: Coded By: | Z4: DAVID | AA4: Chkd By: | AB4: Bakole Deo
I5: Direction To: | L5: KITEMU
B7: Time | C7: Veh_Reg_No. | D7: Veh_Type | E7: No. Occupants | F7: Origin_Address | I7: Origin_Establish | J7: Origin_Purpose | K7: Origin-Purpose Desc | L7: Destination_Address | O7: Destination_Establish | P7: Destination_Purpose | Q7: Destination_Purpose Desc | R7: Journey_Purpose | S7: Approx_Distance (Km) | T7: Approx_Journey Time (Hrs) | U7: Trip_Frequency | V7: GOODS VEHICLES ONLY | Y7: Would You Use Xpressways? | Z7: Pay How Much? (UGX) | AA7: Origin_Zone | AB7: Dest_Zone
F8: Village or Town | G8: District | H8: Country | L8: Village or Town | M8: District | N8: Country | V8: Goods_Type | W8: Goods_Quantity (Ton) | X8: Goods_Value (UGXm)
B9: 0.67361111 | C9: UAR 569K | D9: 1 | E9: 4 | F9: KIVU | G9: WAKISO | H9: UGA | I9: 2 | J9: 2 | K9: =VLOOKUP(J9,Key!$E$2:$F$9,2,FALSE) -> Work | L9: KITEMU | M9: WAKISO | N9: UGA | O9: 1 | P9: 1 | Q9: =VLOOKUP(P9,Key!$E$2:$F$9,2,FALSE) -> Home | R9: =K9&"-"&Q9 -> Work-Home | S9: 2 | T9: 0.2 | U9: 2 | Y9: Y | Z9: 1000 | AA9: =VLOOKUP(F9,'Zones '!$A$2:$F$2056,6,FALSE) -> 1397 | AB9: =VLOOKUP(L9,'Zones '!$A$2:$F$2056,6,FALSE) -> 1397
B10: 0.675 | C10: UAN 230V | D10: 3 | E10: 4 | F10: KISOZI | G10: WAKISO | H10: UGA | I10: 2 | J10: 2 | K10: =VLOOKUP(J10,Key!$E$2:$F$9,2,FALSE) -> Work | L10: KITEMU | M10: WAKISO | N10: UGA | O10: 1 | P10: 1 | Q10: =VLOOKUP(P10,Key!$E$2:$F$9,2,FALSE) -> Home | R10: =K10&"-"&Q10 -> Work-Home | S10: 2 | T10: 0.5 | U10: 2 | Y10: Y | Z10: 1000 | AA10: =VLOOKUP(F10,'Zones '!$A$2:$F$2056,6,FALSE) -> 589 | AB10: =VLOOKUP(L10,'Zones '!$A$2:$F$2056,6,FALSE) -> 1397
B11: 0.67708333 | C11: UAV 413Y | D11: 1 | E11: 5 | F11: KIVU | G11: WAKISO | H11: UGA | I11: 1 | J11: 1 | K11: =VLOOKUP(J11,Key!$E$2:$F$9,2,FALSE) -> Home | L11: NSANGI | M11: WAKISO | N11: UGA | O11: 2 | P11: 2 | Q11: =VLOOKUP(P11,Key!$E$2:$F$9,2,FALSE) -> Work | R11: =K11&"-"&Q11 -> Home-Work | S11: 4 | T11: 0.3 | U11: 2 | Y11: Y | Z11: 500 | AA11: =VLOOKUP(F11,'Zones '!$A$2:$F$2056,6,FALSE) -> 1397 | AB11: =VLOOKUP(L11,'Zones '!$A$2:$F$2056,6,FALSE) -> 1397
B12: 0.67986111 | C12: UAZ 102R | D12: 2 | E12: 5 | F12: KIVU | G12: WAKISO | H12: UGA | I12: 2 | J12: 2 | K12: =VLOOKUP(J12,Key!$E$2:$F$9,2,FALSE) -> Work | L12: KYENGERA | M12: WAKISO | N12: UGA | O12: 1 | P12: 1 | Q12: =VLOOKUP(P12,Key!$E$2:$F$9,2,FALSE) -> Home | R12: =K12&"-"&Q12 -> Work-Home | S12: 5 | T12: 0.5 | U12: 2 | Y12: Y | Z12: 1000 | AA12: =VLOOKUP(F12,'Zones '!$A$2:$F$2056,6,FALSE) -> 1397 | AB12: =VLOOKUP(L12,'Zones '!$A$2:$F$2056,6,FALSE) -> 1397
B13: 0.68194444 | C13: UAK 278H | D13: 4 | E13: 12 | F13: KISOZI | G13: WAKISO | H13: UGA | I13: 1 | J13: 1 | K13: =VLOOKUP(J13,Key!$E$2:$F$9,2,FALSE) -> Home | L13: MAYA | M13: WAKISO | N13: UGA | O13: 3 | P13: 2 | Q13: =VLOOKUP(P13,Key!$E$2:$F$9,2,FALSE) -> Work | R13: =K13&"-"&Q13 -> Home-Work | S13: 9 | T13: 2 | U13: 2 | Y13: Y | Z13: 1000 | AA13: =VLOOKUP(F13,'Zones '!$A$2:$F$2056,6,FALSE) -> 589 | AB13: =VLOOKUP(L13,'Zones '!$A$2:$F$2056,6,FALSE) -> 1397
B14: 0.68611111 | C14: UAM 951M | D14: 1 | E14: 4 | F14: KIVU | G14: WAKISO | H14: UGA | I14: 1 | J14: 1 | K14: =VLOOKUP(J14,Key!$E$2:$F$9,2,FALSE) -> Home | L14: KITEMU | M14: WAKISO | N14: UGA | O14: 2 | P14: 2 | Q14: =VLOOKUP(P14,Key!$E$2:$F$9,2,FALSE) -> Work | R14: =K14&"-"&Q14 -> Home-Work | S14: 2 | T14: 0.5 | U14: 2 | Y14: Y | Z14: 5000 | AA14: =VLOOKUP(F14,'Zones '!$A$2:$F$2056,6,FALSE) -> 1397 | AB14: =VLOOKUP(L14,'Zones '!$A$2:$F$2056,6,FALSE) -> 1397
B15: 0.6875 | C15: UAH 181W | D15: 1 | E15: 2 | F15: KISOZI | G15: WAKISO | H15: UGA | I15: 1 | J15: 1 | K15: =VLOOKUP(J15,Key!$E$2:$F$9,2,FALSE) -> Home | L15: KYENGERA | M15: WAKISO | N15: UGA | O15: 2 | P15: 2 | Q15: =VLOOKUP(P15,Key!$E$2:$F$9,2,FALSE) -> Work | R15: =K15&"-"&Q15 -> Home-Work | S15: 8 | T15: 1 | U15: 2 | Y15: Y | Z15: 1000 | AA15: =VLOOKUP(F15,'Zones '!$A$2:$F$2056,6,FALSE) -> 589 | AB15: =VLOOKUP(L15,'Zones '!$A$2:$F$2056,6,FALSE) -> 1397
B16: 0.69097222 | C16: UAW 890Y | D16: 9 | E16: 3 | F16: KISOZI | G16: WAKISO | H16: UGA | I16: 3 | J16: 2 | K16: =VLOOKUP(J16,Key!$E$2:$F$9,2,FALSE) -> Work | L16: KYENGERA | M16: WAKISO | N16: UGA | O16: 1 | P16: 1 | Q16: =VLOOKUP(P16,Key!$E$2:$F$9,2,FALSE) -> Home | R16: =K16&"-"&Q16 -> Work-Home | S16: 8 | T16: 0.6 | U16: 6 | Y16: Y | Z16: 5000 | AA16: =VLOOKUP(F16,'Zones '!$A$2:$F$2056,6,FALSE) -> 589 | AB16: =VLOOKUP(L16,'Zones '!$A$2:$F$2056,6,FALSE) -> 1397
B17: 0.69375 | C17: UAV 367A | D17: 1 | E17: 2 | F17: MAKINDYE | G17: WAKISO | H17: UGA | I17: 2 | J17: 2 | K17: =VLOOKUP(J17,Key!$E$2:$F$9,2,FALSE) -> Work | L17: KITEMU | M17: WAKISO | N17: UGA | O17: 1 | P17: 1 | Q17: =VLOOKUP(P17,Key!$E$2:$F$9,2,FALSE) -> Home | R17: =K17&"-"&Q17 -> Work-Home | S17: 3 | T17: 0.5 | U17: 3 | Y17: Y | Z17: 2000 | AA17: =VLOOKUP(F17,'Zones '!$A$2:$F$2056,6,FALSE) -> 556 | AB17: =VLOOKUP(L17,'Zones '!$A$2:$F$2056,6,FALSE) -> 1397
B18: 0.69583333 | C18: UAR 403A | D18: 1 | E18: 2 | F18: KIVU | G18: WAKISO | H18: UGA | I18: 2 | J18: 2 | K18: =VLOOKUP(J18,Key!$E$2:$F$9,2,FALSE) -> Work | L18: KITEMU | M18: WAKISO | N18: UGA | O18: 1 | P18: 1 | Q18: =VLOOKUP(P18,Key!$E$2:$F$9,2,FALSE) -> Home | R18: =K18&"-"&Q18 -> Work-Home | S18: 2 | T18: 0.2 | U18: 2 | Y18: Y | Z18: 1000 | AA18: =VLOOKUP(F18,'Zones '!$A$2:$F$2056,6,FALSE) -> 1397 | AB18: =VLOOKUP(L18,'Zones '!$A$2:$F$2056,6,FALSE) -> 1397
B19: 0.69930556 | C19: UAP 133Q | D19: 1 | E19: 2 | F19: KIVU | G19: WAKISO | H19: UGA | I19: 1 | J19: 1 | K19: =VLOOKUP(J19,Key!$E$2:$F$9,2,FALSE) -> Home | L19: KITEMU | M19: WAKISO | N19: UGA | O19: 2 | P19: 2 | Q19: =VLOOKUP(P19,Key!$E$2:$F$9,2,FALSE) -> Work | R19: =K19&"-"&Q19 -> Home-Work | S19: 2 | T19: 0.2 | U19: 2 | Y19: Y | Z19: 2000 | AA19: =VLOOKUP(F19,'Zones '!$A$2:$F$2056,6,FALSE) -> 1397 | AB19: =VLOOKUP(L19,'Zones '!$A$2:$F$2056,6,FALSE) -> 1397
B20: 0.70069444 | C20: UAS 790P | D20: 1 | E20: 3 | F20: KISOZI | G20: WAKISO | H20: UGA | I20: 1 | J20: 1 | K20: =VLOOKUP(J20,Key!$E$2:$F$9,2,FALSE) -> Home | L20: KITEMU | M20: WAKISO | N20: UGA | O20: 2 | P20: 2 | Q20: =VLOOKUP(P20,Key!$E$2:$F$9,2,FALSE) -> Work | R20: =K20&"-"&Q20 -> Home-Work | S20: 2 | T20: 0.2 | U20: 2 | Y20: Y | Z20: 2000 | AA20: =VLOOKUP(F20,'Zones '!$A$2:$F$2056,6,FALSE) -> 589 | AB20: =VLOOKUP(L20,'Zones '!$A$2:$F$2056,6,FALSE) -> 1397
... B26: 0.72222222 | C26: UAP 203R | D26: 3 | E26: 2 | F26: KYENGERA | G26: WAKISO | H26: UGA | I26: 3 | J26: 2 | K26: =VLOOKUP(J26,Key!$E$2:$F$9,2,FALSE) -> Work | L26: KITEMU | M26: WAKISO | N26: UGA | O26: 1 | P26: 1 | Q26: =VLOOKUP(P26,Key!$E$2:$F$9,2,FALSE) -> Home | R26: =K26&"-"&Q26 -> Work-Home | S26: 5 | T26: 1 | U26: 2 | Y26: Y | Z26: 500 | AA26: =VLOOKUP(F26,'Zones '!$A$2:$F$2056,6,FALSE) -> 1397 | AB26: =VLOOKUP(L26,'Zones '!$A$2:$F$2056,6,FALSE) -> 1397
B27: 0.72569444 | C27: UAJ 208H | D27: 1 | E27: 2 | F27: KIVU | G27: WAKISO | H27: UGA | I27: 1 | J27: 1 | K27: =VLOOKUP(J27,Key!$E$2:$F$9,2,FALSE) -> Home | L27: NSANGI | M27: WAKISO | N27: UGA | O27: 3 | P27: 2 | Q27: =VLOOKUP(P27,Key!$E$2:$F$9,2,FALSE) -> Work | R27: =K27&"-"&Q27 -> Home-Work | S27: 5 | T27: 1 | U27: 2 | Y27: Y | AA27: =VLOOKUP(F27,'Zones '!$A$2:$F$2056,6,FALSE) -> 1397 | AB27: =VLOOKUP(L27,'Zones '!$A$2:$F$2056,6,FALSE) -> 1397
B28: 0.72847222 | C28: UAB 906V | D28: 3 | E28: 3 | F28: KIVU | G28: WAKISO | H28: UGA | I28: 2 | J28: 2 | K28: =VLOOKUP(J28,Key!$E$2:$F$9,2,FALSE) -> Work | L28: KITEMU | M28: WAKISO | N28: UGA | O28: 1 | P28: 1 | Q28: =VLOOKUP(P28,Key!$E$2:$F$9,2,FALSE) -> Home | R28: =K28&"-"&Q28 -> Work-Home | S28: 2 | T28: 0.2 | U28: 2 | Y28: Y | Z28: 500 | AA28: =VLOOKUP(F28,'Zones '!$A$2:$F$2056,6,FALSE) -> 1397 | AB28: =VLOOKUP(L28,'Zones '!$A$2:$F$2056,6,FALSE) -> 1397
B29: 0.73055556 | C29: UAS 941F | D29: 1 | E29: 4 | F29: KIVU | G29: WAKISO | H29: UGA | I29: 1 | J29: 1 | K29: =VLOOKUP(J29,Key!$E$2:$F$9,2,FALSE) -> Home | L29: NSANGI | M29: WAKISO | N29: UGA | O29: 2 | P29: 2 | Q29: =VLOOKUP(P29,Key!$E$2:$F$9,2,FALSE) -> Work | R29: =K29&"-"&Q29 -> Home-Work | S29: 4 | T29: 0.1 | U29: 3 | Y29: Y | Z29: 1000 | AA29: =VLOOKUP(F29,'Zones '!$A$2:$F$2056,6,FALSE) -> 1397 | AB29: =VLOOKUP(L29,'Zones '!$A$2:$F$2056,6,FALSE) -> 1397
B30: 0.73541667 | C30: UBE 579X | D30: 1 | E30: 2 | F30: GAYAZA ROAD | G30: KAMPALA | H30: UGA | I30: 1 | J30: 1 | K30: =VLOOKUP(J30,Key!$E$2:$F$9,2,FALSE) -> Home | L30: GAYAZA | M30: WAKISO | N30: UGA | O30: 2 | P30: 2 | Q30: =VLOOKUP(P30,Key!$E$2:$F$9,2,FALSE) -> Work | R30: =K30&"-"&Q30 -> Home-Work | S30: 10 | T30: 1 | U30: 2 | Y30: Y | Z30: 5000 | AA30: =VLOOKUP(F30,'Zones '!$A$2:$F$2056,6,FALSE) -> 811 | AB30: =VLOOKUP(L30,'Zones '!$A$2:$F$2056,6,FALSE) -> 811
B31: 0.74305556 | C31: UAU 398L | D31: 1 | E31: 4 | F31: KIVU | G31: WAKISO | H31: UGA | I31: 3 | J31: 2 | K31: =VLOOKUP(J31,Key!$E$2:$F$9,2,FALSE) -> Work | L31: KITEMU | M31: WAKISO | N31: UGA | O31: 3 | P31: 2 | Q31: =VLOOKUP(P31,Key!$E$2:$F$9,2,FALSE) -> Work | R31: =K31&"-"&Q31 -> Work-Work | S31: 3 | T31: 0.1 | U31: 2 | Y31: Y | Z31: 1000 | AA31: =VLOOKUP(F31,'Zones '!$A$2:$F$2056,6,FALSE) -> 1397 | AB31: =VLOOKUP(L31,'Zones '!$A$2:$F$2056,6,FALSE) -> 1397
B32: 0.73958333 | C32: UBF 172F | D32: 1 | E32: 2 | F32: KISOZI | G32: WAKISO | H32: UGA | I32: 1 | J32: 1 | K32: =VLOOKUP(J32,Key!$E$2:$F$9,2,FALSE) -> Home | L32: KITEMU | M32: WAKISO | N32: UGA | O32: 2 | P32: 2 | Q32: =VLOOKUP(P32,Key!$E$2:$F$9,2,FALSE) -> Work | R32: =K32&"-"&Q32 -> Home-Work | S32: 4 | T32: 0.1 | U32: 2 | Y32: Y | Z32: 1000 | AA32: =VLOOKUP(F32,'Zones '!$A$2:$F$2056,6,FALSE) -> 589 | AB32: =VLOOKUP(L32,'Zones '!$A$2:$F$2056,6,FALSE) -> 1397
B33: 0.74930556 | C33: UAR 926A | D33: 1 | E33: 1 | F33: KIVU | G33: WAKISO | H33: UGA | I33: 1 | J33: 1 | K33: =VLOOKUP(J33,Key!$E$2:$F$9,2,FALSE) -> Home | L33: NSANGI | M33: WAKISO | N33: UGA | O33: 3 | P33: 2 | Q33: =VLOOKUP(P33,Key!$E$2:$F$9,2,FALSE) -> Work | R33: =K33&"-"&Q33 -> Home-Work | T33: 0.1 | U33: 2 | Y33: Y | Z33: 1000 | AA33: =VLOOKUP(F33,'Zones '!$A$2:$F$2056,6,FALSE) -> 1397 | AB33: =VLOOKUP(L33,'Zones '!$A$2:$F$2056,6,FALSE) -> 1397
B34: 0.75 | C34: UAZ 181N | D34: 1 | E34: 2 | F34: KISOZI | G34: WAKISO | H34: UGA | I34: 2 | J34: 2 | K34: =VLOOKUP(J34,Key!$E$2:$F$9,2,FALSE) -> Work | L34: KITEMU | M34: WAKISO | N34: UGA | O34: 1 | P34: 1 | Q34: =VLOOKUP(P34,Key!$E$2:$F$9,2,FALSE) -> Home | R34: =K34&"-"&Q34 -> Work-Home | S34: 4 | T34: 0.1 | U34: 2 | Y34: Y | Z34: 1000 | AA34: =VLOOKUP(F34,'Zones '!$A$2:$F$2056,6,FALSE) -> 589 | AB34: =VLOOKUP(L34,'Zones '!$A$2:$F$2056,6,FALSE) -> 1397
B35: 0.75347222 | C35: UAW 609Q | D35: 1 | E35: 1 | F35: KISOZI | G35: WAKISO | H35: UGA | I35: 1 | J35: 1 | K35: =VLOOKUP(J35,Key!$E$2:$F$9,2,FALSE) -> Home | L35: NABBINGO | M35: WAKISO | N35: UGA | O35: 2 | P35: 2 | Q35: =VLOOKUP(P35,Key!$E$2:$F$9,2,FALSE) -> Work | R35: =K35&"-"&Q35 -> Home-Work | S35: 8 | T35: 0.1 | U35: 2 | Y35: Y | Z35: 1000 | AA35: =VLOOKUP(F35,'Zones '!$A$2:$F$2056,6,FALSE) -> 589 | AB35: =VLOOKUP(L35,'Zones '!$A$2:$F$2056,6,FALSE) -> 1397
B36: 0.75625 | C36: UAV193V | D36: 1 | E36: 4 | F36: NDEJJE | G36: WAKISO | H36: UGA | I36: 1 | J36: 1 | K36: =VLOOKUP(J36,Key!$E$2:$F$9,2,FALSE) -> Home | L36: MASAKA | M36: MASAKA | N36: UGA | O36: 2 | P36: 2 | Q36: =VLOOKUP(P36,Key!$E$2:$F$9,2,FALSE) -> Work | R36: =K36&"-"&Q36 -> Home-Work | S36: 164 | T36: 2.5 | U36: 2 | Y36: Y | Z36: 0 | AA36: =VLOOKUP(F36,'Zones '!$A$2:$F$2056,6,FALSE) -> 1407 | AB36: =VLOOKUP(L36,'Zones '!$A$2:$F$2056,6,FALSE) -> 937
B37: 0.75833333 | C37: UBE 808F | D37: 1 | E37: 3 | F37: KIVU | G37: WAKISO | H37: UGA | I37: 1 | J37: 1 | K37: =VLOOKUP(J37,Key!$E$2:$F$9,2,FALSE) -> Home | L37: NABBINGO | M37: WAKISO | N37: UGA | O37: 3 | P37: 2 | Q37: =VLOOKUP(P37,Key!$E$2:$F$9,2,FALSE) -> Work | R37: =K37&"-"&Q37 -> Home-Work | S37: 2 | T37: 0.5 | U37: 2 | Y37: Y | Z37: 1000 | AA37: =VLOOKUP(F37,'Zones '!$A$2:$F$2056,6,FALSE) -> 1397 | AB37: =VLOOKUP(L37,'Zones '!$A$2:$F$2056,6,FALSE) -> 1397
B38: 0.76041667 | C38: UAM 048J | D38: 1 | E38: 2 | F38: KIVU | G38: WAKISO | H38: UGA | I38: 1 | J38: 1 | K38: =VLOOKUP(J38,Key!$E$2:$F$9,2,FALSE) -> Home | L38: BULENGA | M38: WAKISO | N38: UGA | O38: 2 | P38: 2 | Q38: =VLOOKUP(P38,Key!$E$2:$F$9,2,FALSE) -> Work | R38: =K38&"-"&Q38 -> Home-Work | S38: 10 | T38: 0.2 | U38: 2 | Y38: Y | Z38: 500 | AA38: =VLOOKUP(F38,'Zones '!$A$2:$F$2056,6,FALSE) -> 1397 | AB38: =VLOOKUP(L38,'Zones '!$A$2:$F$2056,6,FALSE) -> 1408
B39: 0.7625 | C39: UAV 770X | D39: 7 | E39: 2 | F39: NSANGI | G39: WAKISO | H39: UGA | I39: 3 | J39: 2 | K39: =VLOOKUP(J39,Key!$E$2:$F$9,2,FALSE) -> Work | L39: GOMBA | M39: GOMBA | N39: UGA | O39: 3 | P39: 2 | Q39: =VLOOKUP(P39,Key!$E$2:$F$9,2,FALSE) -> Work | R39: =K39&"-"&Q39 -> Work-Work | S39: 200 | T39: 3 | U39: 2 | Y39: Y | Z39: 1000 | AA39: =VLOOKUP(F39,'Zones '!$A$2:$F$2056,6,FALSE) -> 1397 | AB39: =VLOOKUP(L39,'Zones '!$A$2:$F$2056,6,FALSE) -> 328
B40: 0.76527778 | C40: UAN 462Z | D40: 1 | E40: 1 | F40: KIVU | G40: WAKISO | H40: UGA | I40: 1 | J40: 1 | K40: =VLOOKUP(J40,Key!$E$2:$F$9,2,FALSE) -> Home | L40: KITEMU | M40: WAKISO | N40: UGA | O40: 2 | P40: 2 | Q40: =VLOOKUP(P40,Key!$E$2:$F$9,2,FALSE) -> Work | R40: =K40&"-"&Q40 -> Home-Work | S40: 3 | T40: 0.1 | U40: 2 | Y40: Y | Z40: 500 | AA40: =VLOOKUP(F40,'Zones '!$A$2:$F$2056,6,FALSE) -> 1397 | AB40: =VLOOKUP(L40,'Zones '!$A$2:$F$2056,6,FALSE) -> 1397
B41: 0.76875 | C41: UBB 410B | D41: 3 | E41: 1 | F41: KAJJANSI | G41: WAKISO | H41: UGA | I41: 2 | J41: 2 | K41: =VLOOKUP(J41,Key!$E$2:$F$9,2,FALSE) -> Work | L41: MAYA | M41: WAKISO | N41: UGA | O41: 1 | P41: 1 | Q41: =VLOOKUP(P41,Key!$E$2:$F$9,2,FALSE) -> Home | R41: =K41&"-"&Q41 -> Work-Home | S41: 14 | T41: 1 | U41: 6 | Y41: Y | Z41: 1000 | AA41: =VLOOKUP(F41,'Zones '!$A$2:$F$2056,6,FALSE) -> 1390 | AB41: =VLOOKUP(L41,'Zones '!$A$2:$F$2056,6,FALSE) -> 1397
B42: 0.77083333 | C42: UAT 389L | D42: 1 | E42: 3 | F42: KISOZI | G42: WAKISO | H42: UGA | I42: 1 | J42: 1 | K42: =VLOOKUP(J42,Key!$E$2:$F$9,2,FALSE) -> Home | L42: KITEMU | M42: WAKISO | N42: UGA | O42: 2 | P42: 2 | Q42: =VLOOKUP(P42,Key!$E$2:$F$9,2,FALSE) -> Work | R42: =K42&"-"&Q42 -> Home-Work | S42: 5 | T42: 0.3 | U42: 2 | Y42: Y | Z42: 0 | AA42: =VLOOKUP(F42,'Zones '!$A$2:$F$2056,6,FALSE) -> 589 | AB42: =VLOOKUP(L42,'Zones '!$A$2:$F$2056,6,FALSE) -> 1397
B43: 0.77430556 | C43: UAR 842A | D43: 1 | E43: 1 | F43: BUDDO | G43: WAKISO | H43: UGA | I43: 1 | J43: 1 | K43: =VLOOKUP(J43,Key!$E$2:$F$9,2,FALSE) -> Home | L43: MASAKA | M43: MASAKA | N43: UGA | O43: 2 | P43: 2 | Q43: =VLOOKUP(P43,Key!$E$2:$F$9,2,FALSE) -> Work | R43: =K43&"-"&Q43 -> Home-Work | S43: 110 | T43: 2.5 | U43: 2 | Y43: Y | Z43: 500 | AA43: =VLOOKUP(F43,'Zones '!$A$2:$F$2056,6,FALSE) -> 1397 | AB43: =VLOOKUP(L43,'Zones '!$A$2:$F$2056,6,FALSE) -> 937
B44: 0.77638889 | C44: UAV 205M | D44: 1 | E44: 4 | F44: KIVU | G44: WAKISO | H44: UGA | I44: 1 | J44: 1 | K44: =VLOOKUP(J44,Key!$E$2:$F$9,2,FALSE) -> Home | L44: WAKISO | M44: WAKISO | N44: UGA | O44: 2 | P44: 2 | Q44: =VLOOKUP(P44,Key!$E$2:$F$9,2,FALSE) -> Work | R44: =K44&"-"&Q44 -> Home-Work | S44: 2 | T44: 0.2 | U44: 2 | Y44: Y | Z44: 10000 | AA44: =VLOOKUP(F44,'Zones '!$A$2:$F$2056,6,FALSE) -> 1397 | AB44: =VLOOKUP(L44,'Zones '!$A$2:$F$2056,6,FALSE) -> 1408
B45: 0.77777778 | C45: UAS 953S | D45: 1 | E45: 1 | F45: KIVU | G45: WAKISO | H45: UGA | I45: 1 | J45: 1 | K45: =VLOOKUP(J45,Key!$E$2:$F$9,2,FALSE) -> Home | L45: KITEMU | M45: WAKISO | N45: UGA | O45: 2 | P45: 2 | Q45: =VLOOKUP(P45,Key!$E$2:$F$9,2,FALSE) -> Work | R45: =K45&"-"&Q45 -> Home-Work | S45: 0.5 | T45: 0.1 | U45: 2 | Y45: Y | Z45: 2000 | AA45: =VLOOKUP(F45,'Zones '!$A$2:$F$2056,6,FALSE) -> 1397 | AB45: =VLOOKUP(L45,'Zones '!$A$2:$F$2056,6,FALSE) -> 1397
B46: 0.77986111 | C46: UBB 641K | D46: 7 | E46: 5 | F46: KIVU | G46: WAKISO | H46: UGA | I46: 3 | J46: 2 | K46: =VLOOKUP(J46,Key!$E$2:$F$9,2,FALSE) -> Work | L46: NABBINGO | M46: WAKISO | N46: UGA | O46: 3 | P46: 2 | Q46: =VLOOKUP(P46,Key!$E$2:$F$9,2,FALSE) -> Work | R46: =K46&"-"&Q46 -> Work-Work | S46: 5 | T46: 0.3 | Y46: Y | Z46: 500 | AA46: =VLOOKUP(F46,'Zones '!$A$2:$F$2056,6,FALSE) -> 1397 | AB46: =VLOOKUP(L46,'Zones '!$A$2:$F$2056,6,FALSE) -> 1397
B47: 0.78263889 | C47: UAP 372A | D47: 1 | E47: 3 | F47: KIVU | G47: WAKISO | H47: UGA | I47: 2 | J47: 2 | K47: =VLOOKUP(J47,Key!$E$2:$F$9,2,FALSE) -> Work | L47: KITEMU | M47: WAKISO | N47: UGA | O47: 1 | P47: 1 | Q47: =VLOOKUP(P47,Key!$E$2:$F$9,2,FALSE) -> Home | R47: =K47&"-"&Q47 -> Work-Home | S47: 1 | T47: 0.1 | U47: 2 | Y47: Y | Z47: 1000 | AA47: =VLOOKUP(F47,'Zones '!$A$2:$F$2056,6,FALSE) -> 1397 | AB47: =VLOOKUP(L47,'Zones '!$A$2:$F$2056,6,FALSE) -> 1397
...

Sheet RSI FORM
B1: Feasibility Study and Detailed Design of Kampala - Jinja Highway
B2: Roadside OD Interview Survey
B4: Date: | C4: 40465 | D4: Interviewer: | G4: Survey Station: | H4: Bweyogerere | J4: Direction: | K4: Bweyogerere-Kireka | L4: Coded By: | N4: Chkd By:
B7: Time Period | C7: Veh_Type | D7: Veh_Other | E7: Occupancy | F7: Origin_Address | H7: Origin_Purpose | I7: Origin_other | J7: Destination_Address | L7: Destination_Purpose | M7: Destination_Other | N7: Origin_Zone | O7: Dest_Zone | P7: WTP
F8: Village/Town | G8: City/Country | J8: Village/Town | K8: City/Country
B9: AM | C9: 3 | E9: 2 | F9: Entebbe | G9: Kla, Ug | H9: 1 | J9: Kla | K9: Kla, Ug | L9: 2 | N9: Blank | O9: Blank | P9: Yes | Q9: 3000
B10: AM | C10: 1 | E10: 1 | F10: Kiwanga | G10: Kla, Ug | H10: 1 | J10: Kla | K10: Kla, Ug | L10: 2 | N10: Blank | O10: Blank | P10: Yes | Q10: 2000
B11: AM | E11: 1 | F11: Bukoto | G11: Kla, Ug | H11: 3 | J11: Kla | K11: Kla, Ug | L11: 1 | N11: Blank | O11: Blank
B12: AM
B13: AM
B14: AM
B15: AM
B16: AM
B17: AM
B18: AM
B19: AM
B20: AM
B21: AM
B22: AM
B23: AM
... B53: AM

Sheet Zones 
A1: ZONE NAME | B1: DISTRICT | C1: COUNTY | D1: SUBCOUNTY | E1: Parish | F1: ZONE No.
A2: Abim | B2: Abim | C2: Labwor | D2: =A2 -> Abim | F2: 1
A3: Abim Town Council | B3: Abim | C3: Labwor | D3: =A3 -> Abim Town Council | F3: 2
A4: Alerek | B4: Abim | C4: Labwor | D4: =A4 -> Alerek | F4: 3
A5: Lotukei | B5: Abim | C5: Labwor | D5: =A5 -> Lotukei | F5: 4
A6: Morulem | B6: Abim | C6: Labwor | D6: =A6 -> Morulem | F6: 5
A7: Nyakwae | B7: Abim | C7: Labwor | D7: =A7 -> Nyakwae | F7: 6
A8: Adjumani Town Council | B8: Adjumani | C8: East Moyo | D8: =A8 -> Adjumani Town Council | F8: 7
A9: ADJUMANI | D9: =A9 -> ADJUMANI | F9: 7
A10: Adropi | B10: Adjumani | C10: East Moyo | D10: =A10 -> Adropi | F10: 8
A11: Arinyapi | B11: Adjumani | C11: East Moyo | D11: =A11 -> Arinyapi | F11: 9
A12: Ciforo | B12: Adjumani | C12: East Moyo | D12: =A12 -> Ciforo | F12: 10
A13: Dzaipi | B13: Adjumani | C13: East Moyo | D13: =A13 -> Dzaipi | F13: 11
A14: Itirikwa | B14: Adjumani | C14: East Moyo | D14: =A14 -> Itirikwa | F14: 12
A15: Ofua | B15: Adjumani | C15: East Moyo | D15: =A15 -> Ofua | F15: 13
A16: Pacara | B16: Adjumani | C16: East Moyo | D16: =A16 -> Pacara | F16: 14
A17: Pakele | B17: Adjumani | C17: East Moyo | D17: =A17 -> Pakele | F17: 15
A18: Ukusijoni | B18: Adjumani | C18: East Moyo | D18: =A18 -> Ukusijoni | F18: 16
A19: Adilang | B19: Agago | C19: Agago | D19: =A19 -> Adilang | F19: 17
A20: Agago Town Council | B20: Agago | C20: Agago | D20: =A20 -> Agago Town Council | F20: 18
A21: Arum | B21: Agago | C21: Agago | D21: =A21 -> Arum | F21: 19
... A26: Lira Palwo | B26: Agago | C26: Agago | D26: =A26 -> Lira Palwo | F26: 24
A27: LIIRA | D27: =A27 -> LIIRA | F27: 24
A28: Lokole | B28: Agago | C28: Agago | D28: =A28 -> Lokole | F28: 25
A29: Omiya Pacwa | B29: Agago | C29: Agago | D29: =A29 -> Omiya Pacwa | F29: 26
A30: Omot | B30: Agago | C30: Agago | D30: =A30 -> Omot | F30: 27
A31: Paimol | B31: Agago | C31: Agago | D31: =A31 -> Paimol | F31: 28
A32: Parabongo | B32: Agago | C32: Agago | D32: =A32 -> Parabongo | F32: 29
A33: Patongo | B33: Agago | C33: Agago | D33: =A33 -> Patongo | F33: 30
A34: Patongo Town Council | B34: Agago | C34: Agago | D34: =A34 -> Patongo Town Council | F34: 31
A35: Wol | B35: Agago | C35: Agago | D35: =A35 -> Wol | F35: 32
A36: Abako | B36: Alebtong | C36: Moroto | D36: =A36 -> Abako | F36: 33
A37: Abia | B37: Alebtong | C37: Moroto | D37: =A37 -> Abia | F37: 34
A38: Akura | B38: Alebtong | C38: Moroto | D38: =A38 -> Akura | F38: 35
A39: Alebtong Town Council | B39: Alebtong | C39: Moroto | D39: =A39 -> Alebtong Town Council | F39: 36
... A85: Apac Muicipality | B85: Apac | C85: Apac Municipality | D85: =A85 -> Apac Muicipality | F85: 82
A86: APAC | D86: =A86 -> APAC | F86: 82
A87: Chawente | B87: Apac | C87: Kwania | D87: =A87 -> Chawente | F87: 83
A88: Chegere | B88: Apac | C88: Maruzi | D88: =A88 -> Chegere | F88: 84
A89: Ibuje | B89: Apac | C89: Maruzi | D89: =A89 -> Ibuje | F89: 85
...

Sheet 11.10 KITEMU-BUDDO
B1: Consultancy services for Preparation of Expressway Development Master Plan (EDMP) for Uganda
B2: Roadside OD Interview Survey
B4: Date: | C4: ='ALL DATA'!C4 -> 11.10.19 | E4: Road Name: | F4: ='ALL DATA'!F4:G4 -> BUDO ROAD | I4: Direction From: | L4: KITEMU | N4: Interviewers: | O4: NDAHURA JOHN, CLAIRE | V4: Supervisor: | W4: ='ALL DATA'!W4 -> FLORENCE | Y4: Coded By: | Z4: ='ALL DATA'!Z4 -> DAVID | AA4: Chkd By: | AB4: ='ALL DATA'!AB4 -> Bakole Deo
I5: Direction To: | L5: BUDDO
B7: Time | C7: Veh_Reg_No. | D7: Veh_Type | E7: No. Occupants | F7: Origin_Address | I7: Origin_Establish | J7: Origin_Purpose | K7: Origin-Purpose Desc | L7: Destination_Address | O7: Destination_Establish | P7: Destination_Purpose | Q7: Destination_Purpose Desc | R7: Journey_Purpose | S7: Approx_Distance (Km) | T7: Approx_Journey Time (Hrs) | U7: Trip_Frequency | V7: GOODS VEHICLES ONLY | Y7: Would You Use Xpressways? | Z7: Pay How Much? (UGX) | AA7: Origin_Zone | AB7: Dest_Zone
F8: Village or Town | G8: District | H8: Country | L8: Village or Town | M8: District | N8: Country | V8: Goods_Type | W8: Goods_Quantity (Ton) | X8: Goods_Value (UGXm)
B9: 0.33333333 | C9: UAK 328W | D9: 1 | E9: 1 | F9: KITEMU | G9: WAKISO | H9: UGA | I9: 11 | J9: 6 | K9: =VLOOKUP(J9,Key!$E$2:$F$9,2,FALSE) -> Leisure/Social | L9: KIVU | M9: WAKISO | N9: UGA | O9: 1 | P9: 1 | Q9: =VLOOKUP(P9,Key!$E$2:$F$9,2,FALSE) -> Home | R9: =K9&"-"&Q9 -> Leisure/Social-Home | S9: 0.5 | T9: 0.1 | U9: 2 | Y9: Y | Z9: 0
B10: 0.35416667 | C10: UAX 109X | D10: 1 | E10: 1 | F10: KITEMU | G10: WAKISO | H10: UGA | I10: 11 | J10: 6 | K10: =VLOOKUP(J10,Key!$E$2:$F$9,2,FALSE) -> Leisure/Social | L10: KIVU | M10: WAKISO | N10: UGA | O10: 1 | P10: 1 | Q10: =VLOOKUP(P10,Key!$E$2:$F$9,2,FALSE) -> Home | R10: =K10&"-"&Q10 -> Leisure/Social-Home | S10: 1 | T10: 0.1 | U10: 2 | Y10: Y | Z10: 0
B11: 0.375 | C11: UAP 700B | D11: 1 | E11: 1 | F11: NSANGI | G11: WAKISO | H11: UGA | I11: 2 | J11: 2 | K11: =VLOOKUP(J11,Key!$E$2:$F$9,2,FALSE) -> Work | L11: KAJJANSI | M11: WAKISO | N11: UGA | O11: 2 | P11: 2 | Q11: =VLOOKUP(P11,Key!$E$2:$F$9,2,FALSE) -> Work | R11: =K11&"-"&Q11 -> Work-Work | S11: 8 | T11: 0.3 | U11: 2 | Y11: Y | Z11: 1000
B12: 0.38541667 | C12: UAM 780X | D12: 2 | E12: 2 | F12: KYENGERA | G12: WAKISO | H12: UGA | I12: 2 | J12: 2 | K12: =VLOOKUP(J12,Key!$E$2:$F$9,2,FALSE) -> Work | L12: KIMBEJJA | M12: WAKISO | N12: UGA | O12: 1 | P12: 1 | Q12: =VLOOKUP(P12,Key!$E$2:$F$9,2,FALSE) -> Home | R12: =K12&"-"&Q12 -> Work-Home | S12: 6 | T12: 0.6 | U12: 2 | Y12: Y | Z12: 1000
B13: 0.38888889 | C13: UAH 648U | D13: 1 | E13: 1 | F13: KITEMU | G13: WAKISO | H13: UGA | I13: 1 | J13: 1 | K13: =VLOOKUP(J13,Key!$E$2:$F$9,2,FALSE) -> Home | L13: KIVU | M13: WAKISO | N13: UGA | O13: 2 | P13: 2 | Q13: =VLOOKUP(P13,Key!$E$2:$F$9,2,FALSE) -> Work | R13: =K13&"-"&Q13 -> Home-Work | S13: 3 | T13: 0.5 | U13: 2 | Y13: Y | Z13: 1000
B14: 0.41597222 | C14: UAS 954T | D14: 7 | E14: 2 | F14: NATEETE | G14: KAMPALA | H14: UGA | I14: 2 | J14: 2 | K14: =VLOOKUP(J14,Key!$E$2:$F$9,2,FALSE) -> Work | L14: KITEMU | M14: WAKISO | N14: UGA | O14: 12 | P14: 4 | Q14: =VLOOKUP(P14,Key!$E$2:$F$9,2,FALSE) -> Commercial | R14: =K14&"-"&Q14 -> Work-Commercial | S14: 8 | T14: 1 | U14: 4 | V14: 11 | Y14: Y | Z14: 1000
B15: 0.42708333 | C15: UAW 283W | D15: 4 | E15: 2 | F15: MUTUKULA | G15: MASAKA | H15: UGA | I15: 2 | J15: 2 | K15: =VLOOKUP(J15,Key!$E$2:$F$9,2,FALSE) -> Work | L15: KAMPALA | M15: WAKISO | N15: UGA | O15: 2 | P15: 2 | Q15: =VLOOKUP(P15,Key!$E$2:$F$9,2,FALSE) -> Work | R15: =K15&"-"&Q15 -> Work-Work | S15: 120 | T15: 2 | U15: 2 | Y15: Y | Z15: 0
B16: 0.4375 | C16: UAQ 301U | D16: 2 | E16: 1 | F16: BUSEGA | G16: KAMPALA | H16: UGA | I16: 1 | J16: 1 | K16: =VLOOKUP(J16,Key!$E$2:$F$9,2,FALSE) -> Home | L16: KITEMU | M16: WAKISO | N16: UGA | O16: 1 | P16: 1 | Q16: =VLOOKUP(P16,Key!$E$2:$F$9,2,FALSE) -> Home | R16: =K16&"-"&Q16 -> Home-Home | S16: 10 | T16: 0.5 | U16: 2 | Y16: Y | Z16: 0
B17: 0.44097222 | C17: UBF 278K | D17: 7 | E17: 6 | F17: KITEMU | G17: WAKISO | H17: UGA | I17: 2 | J17: 2 | K17: =VLOOKUP(J17,Key!$E$2:$F$9,2,FALSE) -> Work | L17: KIVU | M17: WAKISO | N17: UGA | O17: 16 | P17: 2 | Q17: =VLOOKUP(P17,Key!$E$2:$F$9,2,FALSE) -> Work | R17: =K17&"-"&Q17 -> Work-Work | S17: 1 | T17: 0.2 | U17: 1 | V17: 12 | W17: 0.5 | X17: 6 | Y17: Y | Z17: 0
B18: 0.45694444 | C18: UAT 423T | D18: 7 | E18: 2 | F18: MAKINDYE | G18: KAMPALA | H18: UGA | I18: 16 | J18: 2 | K18: =VLOOKUP(J18,Key!$E$2:$F$9,2,FALSE) -> Work | L18: MAYA | M18: WAKISO | N18: UGA | O18: 16 | P18: 2 | Q18: =VLOOKUP(P18,Key!$E$2:$F$9,2,FALSE) -> Work | R18: =K18&"-"&Q18 -> Work-Work | S18: 6 | T18: 5 | U18: 3 | V18: 12 | W18: 0.5 | X18: 5 | Y18: Y | Z18: 500
B19: 0.45833333 | C19: UAW 517B | D19: 7 | E19: 2 | F19: KAMENGO | G19: KALUNGU | H19: UGA | I19: 2 | J19: 2 | K19: =VLOOKUP(J19,Key!$E$2:$F$9,2,FALSE) -> Work | L19: KITEMU | M19: WAKISO | N19: UGA | O19: 2 | P19: 2 | Q19: =VLOOKUP(P19,Key!$E$2:$F$9,2,FALSE) -> Work | R19: =K19&"-"&Q19 -> Work-Work | S19: 28 | T19: 1 | U19: 1 | V19: 4 | W19: 1 | X19: 0.45 | Y19: Y | Z19: 1000
B20: 0.46180556 | C20: UAT 585A | D20: 1 | E20: 2 | F20: KITEMU | G20: WAKISO | H20: UGA | I20: 11 | J20: 4 | K20: =VLOOKUP(J20,Key!$E$2:$F$9,2,FALSE) -> Commercial | L20: BUDDO | M20: WAKISO | N20: UGA | O20: 1 | P20: 1 | Q20: =VLOOKUP(P20,Key!$E$2:$F$9,2,FALSE) -> Home | R20: =K20&"-"&Q20 -> Commercial-Home | S20: 1.5 | T20: 0.5 | U20: 1 | Y20: Y | Z20: 1000
B21: 0.47569444 | C21: UAX 575R | D21: 7 | E21: 2 | F21: KITEMU | G21: WAKISO | H21: UGA | I21: 2 | J21: 2 | K21: =VLOOKUP(J21,Key!$E$2:$F$9,2,FALSE) -> Work | L21: KIVU | M21: WAKISO | N21: UGA | O21: 16 | P21: 2 | Q21: =VLOOKUP(P21,Key!$E$2:$F$9,2,FALSE) -> Work | R21: =K21&"-"&Q21 -> Work-Work | S21: 1 | T21: 0.1 | U21: 1 | V21: 6 | W21: 0.5 | X21: 3 | Y21: Y | Z21: 0
B22: 0.48958333 | C22: UBE 390R | D22: 1 | E22: 1 | F22: MPIGI | G22: MPIGI | H22: UGA | I22: 2 | J22: 2 | K22: =VLOOKUP(J22,Key!$E$2:$F$9,2,FALSE) -> Work | L22: KIVU | M22: WAKISO | N22: UGA | O22: 1 | P22: 1 | Q22: =VLOOKUP(P22,Key!$E$2:$F$9,2,FALSE) -> Home | R22: =K22&"-"&Q22 -> Work-Home | S22: 2 | T22: 1 | U22: 1 | Y22: Y | Z22: 1000
B23: 0.49652778 | C23: UBE 277E | D23: 7 | E23: 3 | F23: HOIMA | G23: HOIMA | H23: UGA | I23: 16 | J23: 2 | K23: =VLOOKUP(J23,Key!$E$2:$F$9,2,FALSE) -> Work | L23: KISOZI | M23: WAKISO | N23: UGA | O23: 16 | P23: 2 | Q23: =VLOOKUP(P23,Key!$E$2:$F$9,2,FALSE) -> Work | R23: =K23&"-"&Q23 -> Work-Work | S23: 175 | T23: 6 | U23: 4 | V23: 6 | W23: 1.5 | X23: 0.8 | Y23: Y | Z23: 2000
B24: 0.50347222 | C24: UBB 161D | D24: 4 | E24: 14 | F24: NABBINGO | G24: WAKISO | H24: UGA | I24: 4 | J24: 2 | K24: =VLOOKUP(J24,Key!$E$2:$F$9,2,FALSE) -> Work | L24: BUDDO | M24: WAKISO | N24: UGA | O24: 4 | P24: 2 | Q24: =VLOOKUP(P24,Key!$E$2:$F$9,2,FALSE) -> Work | R24: =K24&"-"&Q24 -> Work-Work | S24: 10 | T24: 0.7 | U24: 1 | Y24: Y | Z24: 0
B25: 0.51388889 | C25: UBD 947P | D25: 2 | E25: 2 | F25: KAMPALA | G25: KAMPALA | H25: UGA | I25: 2 | J25: 2 | K25: =VLOOKUP(J25,Key!$E$2:$F$9,2,FALSE) -> Work | L25: KIVU | M25: WAKISO | N25: UGA | O25: 1 | P25: 1 | Q25: =VLOOKUP(P25,Key!$E$2:$F$9,2,FALSE) -> Home | R25: =K25&"-"&Q25 -> Work-Home | S25: 10 | T25: 0.2 | U25: 1 | Y25: Y | Z25: 0
B26: 0.51527778 | C26: UBB 023P | D26: 4 | E26: 2 | F26: NSANGI | G26: WAKISO | H26: UGA | I26: 16 | J26: 2 | K26: =VLOOKUP(J26,Key!$E$2:$F$9,2,FALSE) -> Work | L26: BUDDO | M26: WAKISO | N26: UGA | O26: 6 | P26: 2 | Q26: =VLOOKUP(P26,Key!$E$2:$F$9,2,FALSE) -> Work | R26: =K26&"-"&Q26 -> Work-Work | S26: 2 | T26: 0.5 | U26: 1 | Y26: Y | Z26: 0
B27: 0.52777778 | C27: UAT 015P | D27: 1 | E27: 1 | F27: KITEMU | G27: WAKISO | H27: UGA | I27: 11 | J27: 4 | K27: =VLOOKUP(J27,Key!$E$2:$F$9,2,FALSE) -> Commercial | L27: KIVU | M27: WAKISO | N27: UGA | O27: 1 | P27: 1 | Q27: =VLOOKUP(P27,Key!$E$2:$F$9,2,FALSE) -> Home | R27: =K27&"-"&Q27 -> Commercial-Home | S27: 0.5 | T27: 0.1 | U27: 1 | Y27: Y | Z27: 0
B28: 0.53125 | C28: UBB 925R | D28: 2 | E28: 4 | F28: BUSEGA | G28: KAMPALA | H28: UGA | I28: 12 | J28: 4 | K28: =VLOOKUP(J28,Key!$E$2:$F$9,2,FALSE) -> Commercial | L28: KIVU | M28: WAKISO | N28: UGA | O28: 1 | P28: 1 | Q28: =VLOOKUP(P28,Key!$E$2:$F$9,2,FALSE) -> Home | R28: =K28&"-"&Q28 -> Commercial-Home | S28: 2 | T28: 0.7 | U28: 1 | Y28: Y | Z28: 1000
B29: 0.53263889 | C29: UAL 552Y | D29: 2 | E29: 2 | F29: BUSEGA | G29: KAMPALA | H29: UGA | I29: 7 | J29: 4 | K29: =VLOOKUP(J29,Key!$E$2:$F$9,2,FALSE) -> Commercial | L29: KITEMU | M29: WAKISO | N29: UGA | O29: 1 | P29: 1 | Q29: =VLOOKUP(P29,Key!$E$2:$F$9,2,FALSE) -> Home | R29: =K29&"-"&Q29 -> Commercial-Home | S29: 10 | T29: 0.7 | U29: 1 | Y29: Y | Z29: 1000
B30: 0.53472222 | C30: UAR 672B | D30: 1 | E30: 1 | F30: NATEETE | G30: KAMPALA | H30: UGA | I30: 7 | J30: 4 | K30: =VLOOKUP(J30,Key!$E$2:$F$9,2,FALSE) -> Commercial | L30: KITEMU | M30: WAKISO | N30: UGA | O30: 1 | P30: 1 | Q30: =VLOOKUP(P30,Key!$E$2:$F$9,2,FALSE) -> Home | R30: =K30&"-"&Q30 -> Commercial-Home | S30: 20 | T30: 1 | U30: 1 | Y30: Y | Z30: 0
B31: 0.54166667 | C31: UAG 225H | D31: 2 | E31: 4 | F31: KITEMU | G31: WAKISO | H31: UGA | I31: 1 | J31: 1 | K31: =VLOOKUP(J31,Key!$E$2:$F$9,2,FALSE) -> Home | L31: BUDDO | M31: WAKISO | N31: UGA | O31: 2 | P31: 2 | Q31: =VLOOKUP(P31,Key!$E$2:$F$9,2,FALSE) -> Work | R31: =K31&"-"&Q31 -> Home-Work | S31: 10 | T31: 0.5 | U31: 1 | Y31: Y | Z31: 1000
B32: 0.53819444 | C32: UAJ 522M | D32: 1 | E32: 2 | F32: KAMPALA | G32: KAMPALA | H32: UGA | I32: 2 | J32: 2 | K32: =VLOOKUP(J32,Key!$E$2:$F$9,2,FALSE) -> Work | L32: KISOZI | M32: WAKISO | N32: UGA | O32: 2 | P32: 2 | Q32: =VLOOKUP(P32,Key!$E$2:$F$9,2,FALSE) -> Work | R32: =K32&"-"&Q32 -> Work-Work | S32: 10 | T32: 0.1 | U32: 3 | Y32: Y | Z32: 0
B33: 0.54513889 | C33: UAY 469H | D33: 7 | E33: 3 | F33: KITEMU | G33: WAKISO | H33: UGA | I33: 12 | J33: 2 | K33: =VLOOKUP(J33,Key!$E$2:$F$9,2,FALSE) -> Work | L33: KIVU | M33: WAKISO | N33: UGA | O33: 10 | P33: 4 | Q33: =VLOOKUP(P33,Key!$E$2:$F$9,2,FALSE) -> Commercial | R33: =K33&"-"&Q33 -> Work-Commercial | S33: 0.5 | T33: 0.1 | U33: 3 | V33: 4 | W33: 1 | X33: 8 | Y33: Y | Z33: 1000
B34: 0.54861111 | C34: UAH 732F | D34: 2 | E34: 2 | F34: NSANGI | G34: WAKISO | H34: UGA | I34: 2 | J34: 2 | K34: =VLOOKUP(J34,Key!$E$2:$F$9,2,FALSE) -> Work | L34: KISOZI | M34: WAKISO | N34: UGA | O34: 2 | P34: 2 | Q34: =VLOOKUP(P34,Key!$E$2:$F$9,2,FALSE) -> Work | R34: =K34&"-"&Q34 -> Work-Work | S34: 4 | T34: 0.5 | U34: 1 | Y34: Y | Z34: 0
B35: 0.55208333 | C35: UAZ 476B | D35: 1 | E35: 1 | F35: NSANGI | G35: WAKISO | H35: UGA | I35: 1 | J35: 1 | K35: =VLOOKUP(J35,Key!$E$2:$F$9,2,FALSE) -> Home | L35: NAKAWUKA | M35: WAKISO | N35: UGA | O35: 2 | P35: 2 | Q35: =VLOOKUP(P35,Key!$E$2:$F$9,2,FALSE) -> Work | R35: =K35&"-"&Q35 -> Home-Work | S35: 10 | T35: 1 | U35: 3 | Y35: Y | Z35: 3000
B36: 0.55 | C36: UAZ 331T | D36: 4 | E36: 2 | F36: KITEMU | G36: WAKISO | H36: UGA | I36: 16 | J36: 2 | K36: =VLOOKUP(J36,Key!$E$2:$F$9,2,FALSE) -> Work | L36: BUDDO | M36: WAKISO | N36: UGA | O36: 6 | P36: 4 | Q36: =VLOOKUP(P36,Key!$E$2:$F$9,2,FALSE) -> Commercial | R36: =K36&"-"&Q36 -> Work-Commercial | S36: 6 | T36: 0.3 | U36: 1 | Y36: Y | Z36: 0
B37: 0.55486111 | C37: UAT 908V | D37: 4 | E37: 3 | F37: KITEMU | G37: WAKISO | H37: UGA | I37: 16 | J37: 2 | K37: =VLOOKUP(J37,Key!$E$2:$F$9,2,FALSE) -> Work | L37: BUDDO | M37: WAKISO | N37: UGA | O37: 6 | P37: 2 | Q37: =VLOOKUP(P37,Key!$E$2:$F$9,2,FALSE) -> Work | R37: =K37&"-"&Q37 -> Work-Work | S37: 6 | T37: 0.2 | U37: 1 | Y37: Y | Z37: 0
B38: 0.55763889 | C38: UAW 446Z | D38: 1 | E38: 2 | F38: BUSEGA | G38: KAMPALA | H38: UGA | I38: 2 | J38: 2 | K38: =VLOOKUP(J38,Key!$E$2:$F$9,2,FALSE) -> Work | L38: KIVU | M38: WAKISO | N38: UGA | O38: 2 | P38: 2 | Q38: =VLOOKUP(P38,Key!$E$2:$F$9,2,FALSE) -> Work | R38: =K38&"-"&Q38 -> Work-Work | S38: 10 | T38: 0.7 | U38: 3 | Y38: Y | Z38: 2000
B39: 0.55902778 | C39: UAM 589H | D39: 1 | E39: 1 | F39: NSANGI | G39: WAKISO | H39: UGA | I39: 2 | J39: 2 | K39: =VLOOKUP(J39,Key!$E$2:$F$9,2,FALSE) -> Work | L39: KISOZI | M39: WAKISO | N39: UGA | O39: 4 | P39: 4 | Q39: =VLOOKUP(P39,Key!$E$2:$F$9,2,FALSE) -> Commercial | R39: =K39&"-"&Q39 -> Work-Commercial | S39: 3 | T39: 1 | U39: 1 | Y39: Y | Z39: 0
B40: 0.5625 | C40: UBC 438R | D40: 2 | E40: 1 | F40: NSANGI | G40: WAKISO | H40: UGA | I40: 2 | J40: 2 | K40: =VLOOKUP(J40,Key!$E$2:$F$9,2,FALSE) -> Work | L40: KISOZI | M40: WAKISO | N40: UGA | O40: 2 | P40: 2 | Q40: =VLOOKUP(P40,Key!$E$2:$F$9,2,FALSE) -> Work | R40: =K40&"-"&Q40 -> Work-Work | S40: 4 | T40: 1 | U40: 1 | Y40: Y | Z40: 2000
B41: 0.56944444 | C41: UAH 862K | D41: 7 | E41: 1 | F41: NABBINGO | G41: WAKISO | H41: UGA | I41: 2 | J41: 2 | K41: =VLOOKUP(J41,Key!$E$2:$F$9,2,FALSE) -> Work | L41: KITEMU | M41: WAKISO | N41: UGA | O41: 16 | P41: 6 | Q41: =VLOOKUP(P41,Key!$E$2:$F$9,2,FALSE) -> Leisure/Social | R41: =K41&"-"&Q41 -> Work-Leisure/Social | S41: 3 | T41: 0.1 | U41: 1 | V41: 11 | Y41: Y | Z41: 0
B42: 0.57291667 | C42: UAY 754K | D42: 1 | E42: 2 | F42: KITEMU | G42: WAKISO | H42: UGA | I42: 6 | J42: 2 | K42: =VLOOKUP(J42,Key!$E$2:$F$9,2,FALSE) -> Work | L42: KITEMU | M42: WAKISO | N42: UGA | O42: 1 | P42: 1 | Q42: =VLOOKUP(P42,Key!$E$2:$F$9,2,FALSE) -> Home | R42: =K42&"-"&Q42 -> Work-Home | S42: 0.5 | T42: 0.1 | Y42: Y | Z42: 0
...

Sheet 12.10 BUDDO-KITEMU
B1: Consultancy services for Preparation of Expressway Development Master Plan (EDMP) for Uganda
B2: Roadside OD Interview Survey
B4: Date: | C4: 12.10.19 | E4: Road Name: | F4: ='ALL DATA'!F4:G4 -> BUDO ROAD | I4: Direction From: | L4: BUDDO | N4: Interviewers: | O4: MASINDE DENIS | V4: Supervisor: | W4: ='ALL DATA'!W4 -> FLORENCE | Y4: Coded By: | Z4: ='ALL DATA'!Z4 -> DAVID | AA4: Chkd By: | AB4: ='ALL DATA'!AB4 -> Bakole Deo
I5: Direction To: | L5: KITEMU
B7: Time | C7: Veh_Reg_No. | D7: Veh_Type | E7: No. Occupants | F7: Origin_Address | I7: Origin_Establish | J7: Origin_Purpose | K7: Origin-Purpose Desc | L7: Destination_Address | O7: Destination_Establish | P7: Destination_Purpose | Q7: Destination_Purpose Desc | R7: Journey_Purpose | S7: Approx_Distance (Km) | T7: Approx_Journey Time (Hrs) | U7: Trip_Frequency | V7: GOODS VEHICLES ONLY | Y7: Would You Use Xpressways? | Z7: Pay How Much? (UGX) | AA7: Origin_Zone | AB7: Dest_Zone
F8: Village or Town | G8: District | H8: Country | L8: Village or Town | M8: District | N8: Country | V8: Goods_Type | W8: Goods_Quantity (Ton) | X8: Goods_Value (UGXm)
B9: 0.72847222 | C9: UBE 106R | D9: 4 | E9: 14 | F9: KIBEJJA | G9: WAKISO | H9: UGA | I9: 6 | J9: 2 | K9: =VLOOKUP(J9,Key!$E$2:$F$9,2,FALSE) -> Work | L9: KAMPALA | M9: KAMPALA | N9: UGA | O9: 6 | P9: 2 | Q9: =VLOOKUP(P9,Key!$E$2:$F$9,2,FALSE) -> Work | R9: =K9&"-"&Q9 -> Work-Work | S9: 20 | T9: 2.5 | U9: 2 | Y9: Y | Z9: 2000
B10: 0.73263889 | C10: UAJ 318K | D10: 1 | E10: 2 | F10: KISOZI | G10: WAKISO | H10: UGA | I10: 1 | J10: 1 | K10: =VLOOKUP(J10,Key!$E$2:$F$9,2,FALSE) -> Home | L10: BUSEGA | M10: KAMPALA | N10: UGA | O10: 2 | P10: 2 | Q10: =VLOOKUP(P10,Key!$E$2:$F$9,2,FALSE) -> Work | R10: =K10&"-"&Q10 -> Home-Work | S10: 10 | T10: 2 | U10: 2 | Y10: Y | Z10: 2000
B11: 0.29166667 | C11: UBE 856N | D11: 1 | E11: 3 | F11: KISOZI | G11: WAKISO | H11: UGA | I11: 3 | J11: 2 | K11: =VLOOKUP(J11,Key!$E$2:$F$9,2,FALSE) -> Work | L11: KITEMU | M11: WAKISO | N11: UGA | O11: 1 | P11: 1 | Q11: =VLOOKUP(P11,Key!$E$2:$F$9,2,FALSE) -> Home | R11: =K11&"-"&Q11 -> Work-Home | S11: 1.5 | T11: 0.4 | U11: 2 | Y11: Y | Z11: 5000
B12: 0.79097222 | C12: UAR 141V | D12: 1 | E12: 1 | F12: KIVU | G12: WAKISO | H12: UGA | I12: 2 | J12: 2 | K12: =VLOOKUP(J12,Key!$E$2:$F$9,2,FALSE) -> Work | L12: KYENGERA | M12: WAKISO | N12: UGA | O12: 1 | P12: 1 | Q12: =VLOOKUP(P12,Key!$E$2:$F$9,2,FALSE) -> Home | R12: =K12&"-"&Q12 -> Work-Home | S12: 5 | T12: 0.6 | U12: 2 | Y12: Y | Z12: 1000
B13: 0.78472222 | C13: UAZ 786B | D13: 1 | E13: 1 | F13: KISOZI | G13: WAKISO | H13: UGA | I13: 2 | J13: 2 | K13: =VLOOKUP(J13,Key!$E$2:$F$9,2,FALSE) -> Work | L13: KITEMU | M13: WAKISO | N13: UGA | O13: 1 | P13: 1 | Q13: =VLOOKUP(P13,Key!$E$2:$F$9,2,FALSE) -> Home | R13: =K13&"-"&Q13 -> Work-Home | S13: 0.5 | T13: 0.1 | U13: 2 | Y13: Y | Z13: 500
B14: 0.78125 | C14: UAU 683U | D14: 1 | E14: 4 | F14: KIBEJJA | G14: WAKISO | H14: UGA | I14: 2 | J14: 2 | K14: =VLOOKUP(J14,Key!$E$2:$F$9,2,FALSE) -> Work | L14: NSANGI | M14: KAMPALA | N14: UGA | O14: 1 | P14: 1 | Q14: =VLOOKUP(P14,Key!$E$2:$F$9,2,FALSE) -> Home | R14: =K14&"-"&Q14 -> Work-Home | S14: 5 | T14: 1 | U14: 2 | Y14: Y | Z14: 1000
B15: 0.77083333 | C15: UG 4266M | D15: 3 | E15: 1 | F15: KIVU | G15: WAKISO | H15: UGA | I15: 2 | J15: 2 | K15: =VLOOKUP(J15,Key!$E$2:$F$9,2,FALSE) -> Work | L15: KITEMU | M15: WAKISO | N15: UGA | O15: 1 | P15: 1 | Q15: =VLOOKUP(P15,Key!$E$2:$F$9,2,FALSE) -> Home | R15: =K15&"-"&Q15 -> Work-Home | S15: 0.5 | T15: 0.1 | U15: 2 | Y15: Y | Z15: 500
B16: 0.76736111 | C16: UAG 522A | D16: 1 | E16: 1 | F16: KISOZI | G16: WAKISO | H16: UGA | I16: 2 | J16: 2 | K16: =VLOOKUP(J16,Key!$E$2:$F$9,2,FALSE) -> Work | L16: KYENGERA | M16: WAKISO | N16: UGA | O16: 1 | P16: 1 | Q16: =VLOOKUP(P16,Key!$E$2:$F$9,2,FALSE) -> Home | R16: =K16&"-"&Q16 -> Work-Home | S16: 3 | T16: 1 | U16: 2 | Y16: Y | Z16: 1000
B17: 0.75694444 | C17: UAB 612H | D17: 1 | E17: 2 | F17: KISOZI | G17: WAKISO | H17: UGA | I17: 2 | J17: 2 | K17: =VLOOKUP(J17,Key!$E$2:$F$9,2,FALSE) -> Work | L17: NSANGI | M17: WAKISO | N17: UGA | O17: 1 | P17: 1 | Q17: =VLOOKUP(P17,Key!$E$2:$F$9,2,FALSE) -> Home | R17: =K17&"-"&Q17 -> Work-Home | S17: 5 | T17: 1 | U17: 2 | Y17: Y | Z17: 5000
B18: 0.74930556 | C18: UAR 753R | D18: 7 | E18: 4 | F18: KIVU | G18: WAKISO | H18: UGA | I18: 3 | J18: 2 | K18: =VLOOKUP(J18,Key!$E$2:$F$9,2,FALSE) -> Work | L18: KAMPALA | M18: KAMPALA | N18: UGA | O18: 7 | P18: 4 | Q18: =VLOOKUP(P18,Key!$E$2:$F$9,2,FALSE) -> Commercial | R18: =K18&"-"&Q18 -> Work-Commercial | S18: 20 | T18: 2 | U18: 3 | Y18: Y | Z18: 1000
B19: 0.73958333 | C19: UAW 146J | D19: 1 | E19: 3 | F19: KISOZI | G19: WAKISO | H19: UGA | I19: 2 | J19: 2 | K19: =VLOOKUP(J19,Key!$E$2:$F$9,2,FALSE) -> Work | L19: NATEETE | M19: KAMPALA | N19: UGA | O19: 1 | P19: 1 | Q19: =VLOOKUP(P19,Key!$E$2:$F$9,2,FALSE) -> Home | R19: =K19&"-"&Q19 -> Work-Home | S19: 15 | T19: 1.5 | U19: 2 | Y19: Y | Z19: 0
B20: 0.73541667 | C20: UBE 745B | D20: 4 | E20: 14 | F20: KIBEJJA | G20: WAKISO | H20: UGA | I20: 6 | J20: 2 | K20: =VLOOKUP(J20,Key!$E$2:$F$9,2,FALSE) -> Work | L20: NABINGO | M20: WAKISO | N20: UGA | O20: 6 | P20: 1 | Q20: =VLOOKUP(P20,Key!$E$2:$F$9,2,FALSE) -> Home | R20: =K20&"-"&Q20 -> Work-Home | S20: 10 | T20: 1 | U20: 2 | Y20: Y | Z20: 500
... B51: 0.99652778 | C51: UBA 363J | D51: 2 | E51: 2 | F51: KISOZI | G51: WAKISO | H51: UGA | I51: 1 | J51: 1 | K51: =VLOOKUP(J51,Key!$E$2:$F$9,2,FALSE) -> Home | L51: KAMPALA | M51: KAMPALA | N51: UGA | O51: 5 | P51: 7 | Q51: =VLOOKUP(P51,Key!$E$2:$F$9,2,FALSE) -> Hospital | R51: =K51&"-"&Q51 -> Home-Hospital | S51: 30 | T51: 2 | U51: 6 | Y51: Y | Z51: 3000
B52: 0.5 | C52: UBE 002S | D52: 7 | E52: 5 | F52: KISOZI | G52: WAKISO | H52: UGA | I52: 11 | J52: 2 | K52: =VLOOKUP(J52,Key!$E$2:$F$9,2,FALSE) -> Work | L52: KITEMU | M52: WAKISO | N52: UGA | O52: 11 | P52: 2 | Q52: =VLOOKUP(P52,Key!$E$2:$F$9,2,FALSE) -> Work | R52: =K52&"-"&Q52 -> Work-Work | S52: 10 | T52: 0.4 | U52: 3 | V52: 6 | W52: 5 | X52: 0.08 | Y52: Y | Z52: 500
B53: 0.99513889 | C53: UBA 363S | D53: 2 | E53: 2 | F53: KISOZI | G53: WAKISO | H53: UGA | I53: 1 | J53: 1 | K53: =VLOOKUP(J53,Key!$E$2:$F$9,2,FALSE) -> Home | L53: KAMPALA | M53: KAMPALA | N53: UGA | O53: 5 | P53: 7 | Q53: =VLOOKUP(P53,Key!$E$2:$F$9,2,FALSE) -> Hospital | R53: =K53&"-"&Q53 -> Home-Hospital | S53: 30 | T53: 2 | U53: 6 | Y53: Y | Z53: 3000
B54: 0.51388889 | C54: UAW 030M | D54: 1 | E54: 1 | F54: KISOZI | G54: WAKISO | H54: UGA | I54: 1 | J54: 1 | K54: =VLOOKUP(J54,Key!$E$2:$F$9,2,FALSE) -> Home | L54: KITEMU | M54: WAKISO | N54: UGA | O54: 6 | P54: 2 | Q54: =VLOOKUP(P54,Key!$E$2:$F$9,2,FALSE) -> Work | R54: =K54&"-"&Q54 -> Home-Work | S54: 4 | T54: 0.2 | U54: 1 | Y54: Y | Z54: 5000
B55: 0.50694444 | C55: UBA 077N | D55: 2 | E55: 1 | F55: BUDDO | G55: WAKISO | H55: UGA | I55: 1 | J55: 1 | K55: =VLOOKUP(J55,Key!$E$2:$F$9,2,FALSE) -> Home | L55: NSANGI | M55: WAKISO | N55: UGA | O55: 16 | P55: 8 | Q55: =VLOOKUP(P55,Key!$E$2:$F$9,2,FALSE) -> Others | R55: =K55&"-"&Q55 -> Home-Others | S55: 3 | T55: 0.3 | U55: 6 | Y55: Y | Z55: 10000
B56: 0.98611111 | C56: UBA 989Y | D56: 1 | E56: 3 | F56: KISOZI | G56: WAKISO | H56: UGA | I56: 1 | J56: 1 | K56: =VLOOKUP(J56,Key!$E$2:$F$9,2,FALSE) -> Home | L56: NSANGI | M56: WAKISO | N56: UGA | O56: 16 | P56: 6 | Q56: =VLOOKUP(P56,Key!$E$2:$F$9,2,FALSE) -> Leisure/Social | R56: =K56&"-"&Q56 -> Home-Leisure/Social | S56: 25 | T56: 1 | U56: 6 | Y56: Y | Z56: 2000
B57: 0.99236111 | C57: UBD 390F | D57: 4 | E57: 10 | F57: NATEETE | G57: KAMPALA | H57: UGA | I57: 6 | J57: 2 | K57: =VLOOKUP(J57,Key!$E$2:$F$9,2,FALSE) -> Work | L57: MAYA | M57: WAKISO | N57: UGA | O57: 6 | P57: 2 | Q57: =VLOOKUP(P57,Key!$E$2:$F$9,2,FALSE) -> Work | R57: =K57&"-"&Q57 -> Work-Work | S57: 20 | T57: 0.5 | U57: 1 | Y57: Y | Z57: 1000
B58: 0.98402778 | C58: UAR 505D | D58: 1 | E58: 2 | F58: KATWE | G58: KAMPALA | H58: UGA | I58: 2 | J58: 2 | K58: =VLOOKUP(J58,Key!$E$2:$F$9,2,FALSE) -> Work | L58: KITEMU | M58: WAKISO | N58: UGA | O58: 1 | P58: 1 | Q58: =VLOOKUP(P58,Key!$E$2:$F$9,2,FALSE) -> Home | R58: =K58&"-"&Q58 -> Work-Home | S58: 27 | T58: 0.2 | Y58: N
B59: 0.97916667 | C59: UAK 712Y | D59: 1 | E59: 2 | F59: MASAKA | G59: WAKISO | H59: UGA | I59: 2 | J59: 2 | K59: =VLOOKUP(J59,Key!$E$2:$F$9,2,FALSE) -> Work | L59: KITEMU | M59: WAKISO | N59: UGA | O59: 2 | P59: 2 | Q59: =VLOOKUP(P59,Key!$E$2:$F$9,2,FALSE) -> Work | R59: =K59&"-"&Q59 -> Work-Work | S59: 78 | T59: 1.5 | U59: 1 | Y59: Y | Z59: 10000
B60: 0.97083333 | C60: UAT 125S | D60: 8 | E60: 4 | F60: KAJJANSI | G60: WAKISO | H60: UGA | I60: 11 | J60: 2 | K60: =VLOOKUP(J60,Key!$E$2:$F$9,2,FALSE) -> Work | L60: KITEMU | M60: WAKISO | N60: UGA | O60: 11 | P60: 2 | Q60: =VLOOKUP(P60,Key!$E$2:$F$9,2,FALSE) -> Work | R60: =K60&"-"&Q60 -> Work-Work | V60: 6 | W60: 1 | X60: 6 | Y60: Y | Z60: 2000
B61: 0.975 | C61: UAR 403A | D61: 1 | E61: 2 | F61: MUKIKAJJO | G61: WAKISO | H61: UGA | I61: 1 | J61: 1 | K61: =VLOOKUP(J61,Key!$E$2:$F$9,2,FALSE) -> Home | L61: MPIGI | M61: MPIGI | N61: UGA | O61: 16 | P61: 8 | Q61: =VLOOKUP(P61,Key!$E$2:$F$9,2,FALSE) -> Others | R61: =K61&"-"&Q61 -> Home-Others | S61: 10 | T61: 1.5 | U61: 6 | Y61: Y | Z61: 3000
B62: 0.95833333 | C62: UEJ 642J | D62: 11 | E62: 3 | F62: KITEMU | G62: WAKISO | H62: UGA | I62: 9 | J62: 2 | K62: =VLOOKUP(J62,Key!$E$2:$F$9,2,FALSE) -> Work | L62: KIVU | M62: WAKISO | N62: UGA | O62: 11 | P62: 2 | Q62: =VLOOKUP(P62,Key!$E$2:$F$9,2,FALSE) -> Work | R62: =K62&"-"&Q62 -> Work-Work | S62: 3 | T62: 0.1 | U62: 1 | V62: 12 | W62: 2 | X62: 0.2 | Y62: Y | Z62: 1000
B63: 0.96666667 | C63: UBE 802B | D63: 1 | E63: 1 | F63: ENTEBBE | G63: WAKISO | H63: UGA | I63: 1 | J63: 1 | K63: =VLOOKUP(J63,Key!$E$2:$F$9,2,FALSE) -> Home | L63: KAMPALA | M63: KAMPALA | N63: UGA | O63: 11 | P63: 2 | Q63: =VLOOKUP(P63,Key!$E$2:$F$9,2,FALSE) -> Work | R63: =K63&"-"&Q63 -> Home-Work | S63: 45 | T63: 3 | U63: 2 | Y63: Y | Z63: 10000
B64: 0.59305556 | C64: UEV 208Q | D64: 11 | E64: 2 | F64: KIVU | G64: WAKISO | H64: UGA | I64: 8 | J64: 2 | K64: =VLOOKUP(J64,Key!$E$2:$F$9,2,FALSE) -> Work | L64: MAYA | M64: WAKISO | N64: UGA | O64: 8 | P64: 2 | Q64: =VLOOKUP(P64,Key!$E$2:$F$9,2,FALSE) -> Work | R64: =K64&"-"&Q64 -> Work-Work | S64: 10 | T64: 0.4 | U64: 1 | Y64: Y | Z64: 1000
B65: 0.59861111 | C65: UAP 432G | D65: 1 | E65: 1 | F65: KIBUYE | G65: WAKISO | H65: UGA | I65: 1 | J65: 1 | K65: =VLOOKUP(J65,Key!$E$2:$F$9,2,FALSE) -> Home | L65: NSANGI | M65: WAKISO | N65: UGA | O65: 1 | P65: 1 | Q65: =VLOOKUP(P65,Key!$E$2:$F$9,2,FALSE) -> Home | R65: =K65&"-"&Q65 -> Home-Home | S65: 25 | T65: 1 | U65: 6 | Y65: Y | Z65: 10000
B66: 0.55555556 | C66: UAY 272S | D66: 2 | E66: 3 | F66: ENTEBBE | G66: WAKISO | H66: UGA | I66: 2 | J66: 2 | K66: =VLOOKUP(J66,Key!$E$2:$F$9,2,FALSE) -> Work | L66: KAMPALA | M66: KAMPALA | N66: UGA | O66: 2 | P66: 2 | Q66: =VLOOKUP(P66,Key!$E$2:$F$9,2,FALSE) -> Work | R66: =K66&"-"&Q66 -> Work-Work | S66: 35 | T66: 3 | U66: 1 | Y66: Y | Z66: 10000
B67: 0.56180556 | C67: UDY 375Y | D67: 11 | E67: 1 | F67: KIVU | G67: WAKISO | H67: UGA | I67: 8 | J67: 2 | K67: =VLOOKUP(J67,Key!$E$2:$F$9,2,FALSE) -> Work | L67: KITEMU | M67: WAKISO | N67: UGA | O67: 8 | P67: 2 | Q67: =VLOOKUP(P67,Key!$E$2:$F$9,2,FALSE) -> Work | R67: =K67&"-"&Q67 -> Work-Work | S67: 3 | T67: 0.1 | U67: 1 | Y67: Y | Z67: 5000
B68: 0.58472222 | C68: UEA 675L | D68: 11 | E68: 1 | F68: KISOZI | G68: WAKISO | H68: UGA | I68: 8 | J68: 2 | K68: =VLOOKUP(J68,Key!$E$2:$F$9,2,FALSE) -> Work | L68: KITEMU | M68: WAKISO | N68: UGA | O68: 8 | P68: 2 | Q68: =VLOOKUP(P68,Key!$E$2:$F$9,2,FALSE) -> Work | R68: =K68&"-"&Q68 -> Work-Work | S68: 10 | T68: 0.2 | U68: 1 | Y68: Y | Z68: 1000
B69: 0.58888889 | C69: UEE 166B | D69: 11 | E69: 1 | F69: BUDDO | G69: WAKISO | H69: UGA | I69: 8 | J69: 2 | K69: =VLOOKUP(J69,Key!$E$2:$F$9,2,FALSE) -> Work | L69: KITEMU | M69: WAKISO | N69: UGA | O69: 8 | P69: 2 | Q69: =VLOOKUP(P69,Key!$E$2:$F$9,2,FALSE) -> Work | R69: =K69&"-"&Q69 -> Work-Work | S69: 6 | T69: 0.1 | U69: 1 | Y69: Y | Z69: 2000
B70: 0.40069444 | C70: UAY 836W | D70: 2 | E70: 1 | F70: KIVU | G70: WAKISO | H70: UGA | I70: 1 | J70: 1 | K70: =VLOOKUP(J70,Key!$E$2:$F$9,2,FALSE) -> Home | L70: NALUKOLONGO | M70: KAMPALA | N70: UGA | O70: 11 | P70: 2 | Q70: =VLOOKUP(P70,Key!$E$2:$F$9,2,FALSE) -> Work | R70: =K70&"-"&Q70 -> Home-Work | S70: 7 | T70: 2 | U70: 2 | Y70: Y | Z70: 10000
B71: 0.40277778 | C71: UAM 048J | D71: 1 | E71: 2 | F71: KIVU | G71: WAKISO | H71: UGA | I71: 1 | J71: 1 | K71: =VLOOKUP(J71,Key!$E$2:$F$9,2,FALSE) -> Home | L71: KAMPALA | M71: KAMPALA | N71: UGA | O71: 2 | P71: 2 | Q71: =VLOOKUP(P71,Key!$E$2:$F$9,2,FALSE) -> Work | R71: =K71&"-"&Q71 -> Home-Work | S71: 30 | T71: 2 | U71: 2 | Y71: Y | Z71: 2000
B72: 0.42986111 | C72: UEF 409Y | D72: 11 | E72: 2 | F72: BUDDO | G72: WAKISO | H72: UGA | I72: 8 | J72: 2 | K72: =VLOOKUP(J72,Key!$E$2:$F$9,2,FALSE) -> Work | L72: KITEMU | M72: WAKISO | N72: UGA | O72: 8 | P72: 2 | Q72: =VLOOKUP(P72,Key!$E$2:$F$9,2,FALSE) -> Work | R72: =K72&"-"&Q72 -> Work-Work | S72: 5 | T72: 0.2 | U72: 1 | Y72: Y | Z72: 1000
...

Sheet 12.10 KITEMU-BUDDO
B1: Consultancy services for Preparation of Expressway Development Master Plan (EDMP) for Uganda
B2: Roadside OD Interview Survey
B4: Date: | C4: ='12.10 BUDDO-KITEMU'!C4 -> 12.10.19 | E4: Road Name: | F4: ='12.10 BUDDO-KITEMU'!F4:G4 -> BUDO ROAD | I4: Direction From: | L4: KITEMU | N4: Interviewers: | O4: CLAIR, JOHN | V4: Supervisor: | W4: ='12.10 BUDDO-KITEMU'!W4 -> FLORENCE | Y4: Coded By: | Z4: ='12.10 BUDDO-KITEMU'!Z4 -> DAVID | AA4: Chkd By: | AB4: ='12.10 BUDDO-KITEMU'!AB4 -> Bakole Deo
I5: Direction To: | L5: BUDDO
B7: Time | C7: Veh_Reg_No. | D7: Veh_Type | E7: No. Occupants | F7: Origin_Address | I7: Origin_Establish | J7: Origin_Purpose | K7: Origin-Purpose Desc | L7: Destination_Address | O7: Destination_Establish | P7: Destination_Purpose | Q7: Destination_Purpose Desc | R7: Journey_Purpose | S7: Approx_Distance (Km) | T7: Approx_Journey Time (Hrs) | U7: Trip_Frequency | V7: GOODS VEHICLES ONLY | Y7: Would You Use Xpressways? | Z7: Pay How Much? (UGX) | AA7: Origin_Zone | AB7: Dest_Zone
F8: Village or Town | G8: District | H8: Country | L8: Village or Town | M8: District | N8: Country | V8: Goods_Type | W8: Goods_Quantity (Ton) | X8: Goods_Value (UGXm)
B9: 0.20902778 | C9: UAZ 475Y | D9: 1 | E9: 1 | F9: KITEMU | G9: WAKISO | H9: UGA | I9: 1 | J9: 1 | K9: =VLOOKUP(J9,Key!$E$2:$F$9,2,FALSE) -> Home | L9: BUDDO | M9: WAKISO | N9: UGA | O9: 11 | P9: 2 | Q9: =VLOOKUP(P9,Key!$E$2:$F$9,2,FALSE) -> Work | R9: =K9&"-"&Q9 -> Home-Work | S9: 20 | T9: 1 | U9: 2 | Y9: Y | Z9: 1000
B10: 0.225 | C10: UAY 343P | D10: 3 | E10: 2 | F10: KAMPALA | G10: KAMPALA | H10: UGA | I10: 2 | J10: 2 | K10: =VLOOKUP(J10,Key!$E$2:$F$9,2,FALSE) -> Work | L10: BUDDO | M10: WAKISO | N10: UGA | O10: 1 | P10: 1 | Q10: =VLOOKUP(P10,Key!$E$2:$F$9,2,FALSE) -> Home | R10: =K10&"-"&Q10 -> Work-Home | S10: 20 | T10: 2 | U10: 3 | Y10: Y | Z10: 0
B11: 0.96388889 | C11: UAX 518G | D11: 1 | E11: 1 | F11: BUDDO | G11: WAKISO | H11: UGA | I11: 2 | J11: 2 | K11: =VLOOKUP(J11,Key!$E$2:$F$9,2,FALSE) -> Work | L11: KISOZI | M11: WAKISO | N11: UGA | O11: 1 | P11: 1 | Q11: =VLOOKUP(P11,Key!$E$2:$F$9,2,FALSE) -> Home | R11: =K11&"-"&Q11 -> Work-Home | S11: 15 | T11: 1 | Y11: Y | Z11: 2000
B12: 0.8125 | C12: UAW 040E | D12: 1 | E12: 1 | F12: NSANGI | G12: WAKISO | H12: UGA | I12: 2 | J12: 2 | K12: =VLOOKUP(J12,Key!$E$2:$F$9,2,FALSE) -> Work | L12: KIVU | M12: WAKISO | N12: UGA | O12: 1 | P12: 1 | Q12: =VLOOKUP(P12,Key!$E$2:$F$9,2,FALSE) -> Home | R12: =K12&"-"&Q12 -> Work-Home | S12: 8 | T12: 1 | U12: 1 | Y12: Y | Z12: 1000
B13: 0.79444444 | C13: UAV 918W | D13: 1 | E13: 2 | F13: BUSEGA | G13: KAMPALA | H13: UGA | I13: 2 | J13: 2 | K13: =VLOOKUP(J13,Key!$E$2:$F$9,2,FALSE) -> Work | L13: KISOZI | M13: WAKISO | N13: UGA | O13: 1 | P13: 1 | Q13: =VLOOKUP(P13,Key!$E$2:$F$9,2,FALSE) -> Home | R13: =K13&"-"&Q13 -> Work-Home | S13: 8 | T13: 1 | U13: 1 | Y13: Y | Z13: 2000
B14: 0.81666667 | C14: UBA 448W | D14: 1 | E14: 2 | F14: KAYABWE | G14: KALUNGU | H14: UGA | I14: 11 | J14: 2 | K14: =VLOOKUP(J14,Key!$E$2:$F$9,2,FALSE) -> Work | L14: KIVU | M14: WAKISO | N14: UGA | O14: 1 | P14: 1 | Q14: =VLOOKUP(P14,Key!$E$2:$F$9,2,FALSE) -> Home | R14: =K14&"-"&Q14 -> Work-Home | S14: 25 | T14: 1.5 | Y14: Y | Z14: 0
B15: 0.81388889 | C15: UBF 731F | D15: 8 | E15: 2 | F15: MASAKA | G15: MASAKA | H15: UGA | I15: 7 | J15: 4 | K15: =VLOOKUP(J15,Key!$E$2:$F$9,2,FALSE) -> Commercial | L15: KITEMU | M15: WAKISO | N15: UGA | O15: 10 | P15: 4 | Q15: =VLOOKUP(P15,Key!$E$2:$F$9,2,FALSE) -> Commercial | R15: =K15&"-"&Q15 -> Commercial-Commercial | S15: 138 | T15: 3 | U15: 1 | V15: 4 | W15: 2 | X15: 7 | Y15: Y | Z15: 0
B16: 0.82291667 | C16: UBB 273F | D16: 1 | E16: 2 | F16: BUSEGA | G16: KAMPALA | H16: UGA | I16: 2 | J16: 2 | K16: =VLOOKUP(J16,Key!$E$2:$F$9,2,FALSE) -> Work | L16: KITEMU | M16: WAKISO | N16: UGA | O16: 1 | P16: 1 | Q16: =VLOOKUP(P16,Key!$E$2:$F$9,2,FALSE) -> Home | R16: =K16&"-"&Q16 -> Work-Home | S16: 8 | T16: 1 | U16: 1 | Y16: N | Z16: 0
B17: 0.82638889 | C17: UBB 266R | D17: 1 | E17: 3 | F17: NATEETE | G17: KAMPALA | H17: UGA | I17: 2 | J17: 2 | K17: =VLOOKUP(J17,Key!$E$2:$F$9,2,FALSE) -> Work | L17: BUDDO | M17: KAMPALA | N17: UGA | O17: 1 | P17: 1 | Q17: =VLOOKUP(P17,Key!$E$2:$F$9,2,FALSE) -> Home | R17: =K17&"-"&Q17 -> Work-Home | S17: 10 | T17: 1 | U17: 1 | Y17: Y | Z17: 0
B18: 0.84166667 | C18: UBE 856N | D18: 2 | E18: 1 | F18: MPIGI | G18: MPIGI | H18: UGA | I18: 2 | J18: 2 | K18: =VLOOKUP(J18,Key!$E$2:$F$9,2,FALSE) -> Work | L18: KIKAJJO | M18: WAKISO | N18: UGA | O18: 1 | P18: 1 | Q18: =VLOOKUP(P18,Key!$E$2:$F$9,2,FALSE) -> Home | R18: =K18&"-"&Q18 -> Work-Home | S18: 40 | T18: 1 | U18: 1 | Y18: Y | Z18: 3000
B19: 0.84305556 | C19: UBE 302Q | D19: 2 | E19: 2 | F19: MASAKA | G19: MASAKA | H19: UGA | I19: 2 | J19: 2 | K19: =VLOOKUP(J19,Key!$E$2:$F$9,2,FALSE) -> Work | L19: BUDDO | M19: WAKISO | N19: UGA | O19: 1 | P19: 1 | Q19: =VLOOKUP(P19,Key!$E$2:$F$9,2,FALSE) -> Home | R19: =K19&"-"&Q19 -> Work-Home | S19: 138 | T19: 2 | U19: 1 | Y19: Y | Z19: 0
