Workbook

Sheet 23.9.19 SALAMA - MUNYONYO
B1: Consultancy services for Preparation of Expressway Development Master Plan (EDMP) for Uganda
B2: MANUAL CLASSIFIED COUNT (MCC)
B3: ROAD NAME: | C3: MCC - C2 - STN-51 - SALAMA ROAD
C5: Date | D5: 23.07.19 | F5: Location | G5: MUNYONYO P/S | J5: Surveyor | K5: KENNETH
C6: Dir. From | D6: SALAMA | F6: Dir. To | G6: MUNYONYO | J6: Supervisor | K6: STEVEN
B8: Time / Veh Type | R8: SUMMARY TRAFFIC VOLUMES
C9: 1. Car | D9: 2. Station Wagon | E9: 3. Pickups | F9: 4. Minibus, matatu | G9: 5. Medium bus | H9: 6. Large Bus | I9: 7. Light Truck | J9: 8. Medium Truck | K9: 9. Heavy truck | L9: 10. Truck Trailer | M9: 11. Motor cycles | N9: 12. Tractors | O9: Total Excl M/Cycles | P9: Total All | R9: Time | S9: 1. Car | T9: 2. Station Wagon | U9: 3. Pickups | V9: 4. Minibus, matatu | W9: 5. Medium bus | X9: 6. Large Bus | Y9: 7. Light Truck | Z9: 8. Medium Truck | AA9: 9. Heavy truck | AB9: 10. Truck Trailer | AC9: 11. Motorcycles | AD9: 12. Tractors, Graders | AE9: Total Excl M/ Cycles | AF9: Total All
B10: 07.00 - 07.15 | C10: 17 | D10: 3 | E10: 1 | F10: 8 | G10: 0 | H10: 0 | I10: 1 | J10: 0 | K10: 0 | L10: 0 | M10: 15 | N10: 0 | O10: =SUM(C10:L10,N10) -> 30 | P10: =SUM(C10:N10) -> 45 | R10: 0700-0800 | S10: =SUM(C10:C13) -> 61 | T10: =SUM(D10:D13) -> 14 | U10: =SUM(E10:E13) -> 6 | V10: =SUM(F10:F13) -> 66 | W10: =SUM(G10:G13) -> 1 | X10: =SUM(H10:H13) -> 0 | Y10: =SUM(I10:I13) -> 8 | Z10: =SUM(J10:J13) -> 2 | ... AF10: =SUM(P10:P13) -> 228
B11: 07.15 - 07.30 | C11: 16 | D11: 5 | E11: 1 | F11: 19 | G11: 0 | H11: 0 | I11: 1 | J11: 0 | K11: 0 | L11: 0 | M11: 15 | N11: 0 | O11: =SUM(C11:L11,N11) -> 42 | P11: =SUM(C11:N11) -> 57 | R11: 0800-0900 | S11: =SUM(C14:C17) -> 58 | T11: =SUM(D14:D17) -> 10 | U11: =SUM(E14:E17) -> 6 | V11: =SUM(F14:F17) -> 87 | W11: =SUM(G14:G17) -> 0 | X11: =SUM(H14:H17) -> 1 | Y11: =SUM(I14:I17) -> 3 | Z11: =SUM(J14:J17) -> 6 | ... AF11: =SUM(P14:P17) -> 256
B12: 07.30 - 07.45 | C12: 14 | D12: 4 | E12: 1 | F12: 18 | G12: 0 | H12: 0 | I12: 2 | J12: 0 | K12: 0 | L12: 0 | M12: 22 | N12: 0 | O12: =SUM(C12:L12,N12) -> 39 | P12: =SUM(C12:N12) -> 61 | R12: 0900-1000 | S12: =SUM(C18:C21) -> 44 | T12: =SUM(D18:D21) -> 12 | U12: =SUM(E18:E21) -> 6 | V12: =SUM(F18:F21) -> 84 | W12: =SUM(G18:G21) -> 2 | X12: =SUM(H18:H21) -> 0 | Y12: =SUM(I18:I21) -> 5 | Z12: =SUM(J18:J21) -> 0 | ... AF12: =SUM(P18:P21) -> 222
B13: 07.45 - 08.00 | C13: 14 | D13: 2 | E13: 3 | F13: 21 | G13: 1 | H13: 0 | I13: 4 | J13: 2 | K13: 0 | L13: 0 | M13: 18 | N13: 0 | O13: =SUM(C13:L13,N13) -> 47 | P13: =SUM(C13:N13) -> 65 | R13: 1000-1100 | S13: =SUM(C22:C25) -> 40 | T13: =SUM(D22:D25) -> 2 | U13: =SUM(E22:E25) -> 2 | V13: =SUM(F22:F25) -> 69 | W13: =SUM(G22:G25) -> 0 | X13: =SUM(H22:H25) -> 0 | Y13: =SUM(I22:I25) -> 11 | Z13: =SUM(J22:J25) -> 1 | ... AF13: =SUM(P22:P25) -> 196
B14: 08.00 - 08.15 | C14: 13 | D14: 3 | E14: 0 | F14: 18 | G14: 0 | H14: 1 | I14: 1 | J14: 3 | K14: 0 | L14: 0 | M14: 28 | N14: 0 | O14: =SUM(C14:L14,N14) -> 39 | P14: =SUM(C14:N14) -> 67 | R14: 1100-1200 | S14: =SUM(C26:C29) -> 33 | T14: =SUM(D26:D29) -> 6 | U14: =SUM(E26:E29) -> 12 | V14: =SUM(F26:F29) -> 49 | W14: =SUM(G26:G29) -> 2 | X14: =SUM(H26:H29) -> 0 | Y14: =SUM(I26:I29) -> 15 | Z14: =SUM(J26:J29) -> 2 | ... AF14: =SUM(P26:P29) -> 221
B15: 08.15 - 08.30 | C15: 11 | D15: 0 | E15: 0 | F15: 24 | G15: 0 | H15: 0 | I15: 0 | J15: 1 | K15: 0 | L15: 0 | M15: 27 | N15: 0 | O15: =SUM(C15:L15,N15) -> 36 | P15: =SUM(C15:N15) -> 63 | R15: 1200-1300 | S15: =SUM(C30:C33) -> 67 | T15: =SUM(D30:D33) -> 21 | U15: =SUM(E30:E33) -> 10 | V15: =SUM(F30:F33) -> 41 | W15: =SUM(G30:G33) -> 3 | X15: =SUM(H30:H33) -> 0 | Y15: =SUM(I30:I33) -> 5 | Z15: =SUM(J30:J33) -> 7 | ... AF15: =SUM(P30:P33) -> 252
B16: 08.30 - 08.45 | C16: 12 | D16: 3 | E16: 2 | F16: 18 | G16: 0 | H16: 0 | I16: 0 | J16: 0 | K16: 0 | L16: 0 | M16: 10 | N16: 0 | O16: =SUM(C16:L16,N16) -> 35 | P16: =SUM(C16:N16) -> 45 | R16: 1300-1400 | S16: =SUM(C34:C37) -> 65 | T16: =SUM(D34:D37) -> 4 | U16: =SUM(E34:E37) -> 12 | V16: =SUM(F34:F37) -> 34 | W16: =SUM(G34:G37) -> 1 | X16: =SUM(H34:H37) -> 0 | Y16: =SUM(I34:I37) -> 10 | Z16: =SUM(J34:J37) -> 0 | ... AF16: =SUM(P34:P37) -> 183
B17: 08.45 - 9.00 | C17: 22 | D17: 4 | E17: 4 | F17: 27 | G17: 0 | H17: 0 | I17: 2 | J17: 2 | K17: 0 | L17: 0 | M17: 20 | N17: 0 | O17: =SUM(C17:L17,N17) -> 61 | P17: =SUM(C17:N17) -> 81 | R17: 1400-1500 | S17: =SUM(C38:C41) -> 47 | T17: =SUM(D38:D41) -> 6 | U17: =SUM(E38:E41) -> 3 | V17: =SUM(F38:F41) -> 33 | W17: =SUM(G38:G41) -> 1 | X17: =SUM(H38:H41) -> 0 | Y17: =SUM(I38:I41) -> 13 | Z17: =SUM(J38:J41) -> 2 | ... AF17: =SUM(P38:P41) -> 140
B18: 09.00 - 09.15 | C18: 11 | D18: 8 | E18: 4 | F18: 34 | G18: 0 | H18: 0 | I18: 0 | J18: 0 | K18: 0 | L18: 0 | M18: 22 | N18: 0 | O18: =SUM(C18:L18,N18) -> 57 | P18: =SUM(C18:N18) -> 79 | R18: 1500-1600 | S18: =SUM(C42:C45) -> 66 | T18: =SUM(D42:D45) -> 13 | U18: =SUM(E42:E45) -> 14 | V18: =SUM(F42:F45) -> 54 | W18: =SUM(G42:G45) -> 0 | X18: =SUM(H42:H45) -> 0 | Y18: =SUM(I42:I45) -> 9 | Z18: =SUM(J42:J45) -> 1 | ... AF18: =SUM(P42:P45) -> 217
B19: 09.15 - 09.30 | C19: 7 | D19: 0 | E19: 0 | F19: 13 | G19: 0 | H19: 0 | I19: 1 | J19: 0 | K19: 0 | L19: 0 | M19: 10 | N19: 0 | O19: =SUM(C19:L19,N19) -> 21 | P19: =SUM(C19:N19) -> 31 | R19: 1600-1700 | S19: =SUM(C46:C49) -> 122 | T19: =SUM(D46:D49) -> 12 | U19: =SUM(E46:E49) -> 10 | V19: =SUM(F46:F49) -> 72 | W19: =SUM(G46:G49) -> 0 | X19: =SUM(H46:H49) -> 0 | Y19: =SUM(I46:I49) -> 14 | Z19: =SUM(J46:J49) -> 0 | ... AF19: =SUM(P46:P49) -> 287
B20: 09.30 - 09.45 | C20: 12 | D20: 4 | E20: 2 | F20: 15 | G20: 2 | H20: 0 | I20: 2 | J20: 0 | K20: 0 | L20: 0 | M20: 19 | N20: 0 | O20: =SUM(C20:L20,N20) -> 37 | P20: =SUM(C20:N20) -> 56 | R20: 1700-1800 | S20: =SUM(C50:C53) -> 101 | T20: =SUM(D50:D53) -> 7 | U20: =SUM(E50:E53) -> 11 | V20: =SUM(F50:F53) -> 62 | W20: =SUM(G50:G53) -> 1 | X20: =SUM(H50:H53) -> 0 | Y20: =SUM(I50:I53) -> 10 | Z20: =SUM(J50:J53) -> 0 | ... AF20: =SUM(P50:P53) -> 244
B21: 09.45 - 10.00 | C21: 14 | D21: 0 | E21: 0 | F21: 22 | G21: 0 | H21: 0 | I21: 2 | J21: 0 | K21: 0 | L21: 0 | M21: 18 | N21: 0 | O21: =SUM(C21:L21,N21) -> 38 | P21: =SUM(C21:N21) -> 56 | R21: 1800-1900 | S21: =SUM(C54:C57) -> 88 | T21: =SUM(D54:D57) -> 5 | U21: =SUM(E54:E57) -> 10 | V21: =SUM(F54:F57) -> 85 | W21: =SUM(G54:G57) -> 0 | X21: =SUM(H54:H57) -> 0 | Y21: =SUM(I54:I57) -> 0 | Z21: =SUM(J54:J57) -> 0 | ... AF21: =SUM(P54:P57) -> 245
B22: 10.00 - 10.15 | C22: 10 | D22: 0 | E22: 0 | F22: 15 | G22: 0 | H22: 0 | I22: 10 | J22: 0 | K22: 0 | L22: 0 | M22: 22 | N22: 0 | O22: =SUM(C22:L22,N22) -> 35 | P22: =SUM(C22:N22) -> 57 | R22: AM Peak Hr | S22: =MAX(S10:S12) -> 61 | T22: =MAX(T10:T12) -> 14 | U22: =MAX(U10:U12) -> 6 | V22: =MAX(V10:V12) -> 87 | W22: =MAX(W10:W12) -> 2 | X22: =MAX(X10:X12) -> 1 | Y22: =MAX(Y10:Y12) -> 8 | Z22: =MAX(Z10:Z12) -> 6 | ... AF22: =MAX(AF10:AF12) -> 256
B23: 10.15 - 10.30 | C23: 12 | D23: 2 | E23: 0 | F23: 14 | G23: 0 | H23: 0 | I23: 0 | J23: 1 | K23: 0 | L23: 0 | M23: 32 | N23: 0 | O23: =SUM(C23:L23,N23) -> 29 | P23: =SUM(C23:N23) -> 61 | R23: IP Peak Hr | S23: =MAX(S13:S18) -> 67 | T23: =MAX(T13:T18) -> 21 | U23: =MAX(U13:U18) -> 14 | V23: =MAX(V13:V18) -> 69 | W23: =MAX(W13:W18) -> 3 | X23: =MAX(X13:X18) -> 0 | Y23: =MAX(Y13:Y18) -> 15 | Z23: =MAX(Z13:Z18) -> 7 | ... AF23: =MAX(AF13:AF18) -> 252
B24: 10.30 - 10.45 | C24: 5 | D24: 0 | E24: 1 | F24: 10 | G24: 0 | H24: 0 | I24: 0 | J24: 0 | K24: 0 | L24: 0 | M24: 8 | N24: 0 | O24: =SUM(C24:L24,N24) -> 16 | P24: =SUM(C24:N24) -> 24 | R24: PM Peak Hr | S24: =MAX(S19:S21) -> 122 | T24: =MAX(T19:T21) -> 12 | U24: =MAX(U19:U21) -> 11 | V24: =MAX(V19:V21) -> 85 | W24: =MAX(W19:W21) -> 1 | X24: =MAX(X19:X21) -> 0 | Y24: =MAX(Y19:Y21) -> 14 | Z24: =MAX(Z19:Z21) -> 0 | ... AF24: =MAX(AF19:AF21) -> 287
B25: 10.45 - 11.00 | C25: 13 | D25: 0 | E25: 1 | F25: 30 | G25: 0 | H25: 0 | I25: 1 | J25: 0 | K25: 0 | L25: 0 | M25: 9 | N25: 0 | O25: =SUM(C25:L25,N25) -> 45 | P25: =SUM(C25:N25) -> 54 | R25: AM Period | S25: =SUM(S10:S12) -> 163 | T25: =SUM(T10:T12) -> 36 | U25: =SUM(U10:U12) -> 18 | V25: =SUM(V10:V12) -> 237 | W25: =SUM(W10:W12) -> 3 | X25: =SUM(X10:X12) -> 1 | Y25: =SUM(Y10:Y12) -> 16 | Z25: =SUM(Z10:Z12) -> 8 | ... AF25: =SUM(AF10:AF12) -> 706
B26: 11.00 - 11.15 | C26: 14 | D26: 2 | E26: 4 | F26: 19 | G26: 0 | H26: 0 | I26: 1 | J26: 1 | K26: 0 | L26: 0 | M26: 23 | N26: 0 | O26: =SUM(C26:L26,N26) -> 41 | P26: =SUM(C26:N26) -> 64 | R26: IP Period | S26: =SUM(S13:S18) -> 318 | T26: =SUM(T13:T18) -> 52 | U26: =SUM(U13:U18) -> 53 | V26: =SUM(V13:V18) -> 280 | W26: =SUM(W13:W18) -> 7 | X26: =SUM(X13:X18) -> 0 | Y26: =SUM(Y13:Y18) -> 63 | Z26: =SUM(Z13:Z18) -> 13 | ... AF26: =SUM(AF13:AF18) -> 1209
B27: 11.15 - 11.30 | C27: 11 | D27: 3 | E27: 4 | F27: 7 | G27: 2 | H27: 0 | I27: 5 | J27: 1 | K27: 0 | L27: 1 | M27: 30 | N27: 0 | O27: =SUM(C27:L27,N27) -> 34 | P27: =SUM(C27:N27) -> 64 | R27: PM Period | S27: =SUM(S19:S21) -> 311 | T27: =SUM(T19:T21) -> 24 | U27: =SUM(U19:U21) -> 31 | V27: =SUM(V19:V21) -> 219 | W27: =SUM(W19:W21) -> 1 | X27: =SUM(X19:X21) -> 0 | Y27: =SUM(Y19:Y21) -> 24 | Z27: =SUM(Z19:Z21) -> 0 | ... AF27: =SUM(AF19:AF21) -> 776
B28: 11.30 - 11.45 | C28: 4 | D28: 1 | E28: 4 | F28: 9 | G28: 0 | H28: 0 | I28: 3 | J28: 0 | K28: 0 | L28: 0 | M28: 35 | N28: 0 | O28: =SUM(C28:L28,N28) -> 21 | P28: =SUM(C28:N28) -> 56 | R28: 12 Hours | S28: =SUM(S10:S21) -> 792 | T28: =SUM(T10:T21) -> 112 | U28: =SUM(U10:U21) -> 102 | V28: =SUM(V10:V21) -> 736 | W28: =SUM(W10:W21) -> 11 | X28: =SUM(X10:X21) -> 1 | Y28: =SUM(Y10:Y21) -> 103 | Z28: =SUM(Z10:Z21) -> 21 | ... AF28: =SUM(AF10:AF21) -> 2691
B29: 11.45 - 12.00 | C29: 4 | D29: 0 | E29: 0 | F29: 14 | G29: 0 | H29: 0 | I29: 6 | J29: 0 | K29: 0 | L29: 0 | M29: 13 | N29: 0 | O29: =SUM(C29:L29,N29) -> 24 | P29: =SUM(C29:N29) -> 37
B30: 12.00 - 12.15 | C30: 15 | D30: 8 | E30: 5 | F30: 13 | G30: 3 | H30: 0 | I30: 0 | J30: 4 | K30: 0 | L30: 0 | M30: 18 | N30: 0 | O30: =SUM(C30:L30,N30) -> 48 | P30: =SUM(C30:N30) -> 66
B31: 12.15 - 12.30 | C31: 33 | D31: 4 | E31: 0 | F31: 7 | G31: 0 | H31: 0 | I31: 3 | J31: 0 | K31: 0 | L31: 0 | M31: 34 | N31: 0 | O31: =SUM(C31:L31,N31) -> 47 | P31: =SUM(C31:N31) -> 81
B32: 12.30 - 12.45 | C32: 9 | D32: 5 | E32: 1 | F32: 9 | G32: 0 | H32: 0 | I32: 1 | J32: 3 | K32: 0 | L32: 1 | M32: 24 | N32: 0 | O32: =SUM(C32:L32,N32) -> 29 | P32: =SUM(C32:N32) -> 53
B33: 12.45 - 13.00 | C33: 10 | D33: 4 | E33: 4 | F33: 12 | G33: 0 | H33: 0 | I33: 1 | J33: 0 | K33: 0 | L33: 0 | M33: 21 | N33: 0 | O33: =SUM(C33:L33,N33) -> 31 | P33: =SUM(C33:N33) -> 52
B34: 13.00 - 13.15 | C34: 22 | D34: 1 | E34: 5 | F34: 18 | G34: 1 | H34: 0 | I34: 1 | J34: 0 | K34: 0 | L34: 0 | M34: 13 | N34: 0 | O34: =SUM(C34:L34,N34) -> 48 | P34: =SUM(C34:N34) -> 61
B35: 13.15 - 13.30 | C35: 10 | D35: 0 | E35: 2 | F35: 0 | G35: 0 | H35: 0 | I35: 0 | J35: 0 | K35: 0 | L35: 0 | M35: 19 | N35: 0 | O35: =SUM(C35:L35,N35) -> 12 | P35: =SUM(C35:N35) -> 31
B36: 13.30 - 13.45 | C36: 10 | D36: 0 | E36: 1 | F36: 3 | G36: 0 | H36: 0 | I36: 0 | J36: 0 | K36: 0 | L36: 0 | M36: 16 | N36: 0 | O36: =SUM(C36:L36,N36) -> 14 | P36: =SUM(C36:N36) -> 30
B37: 13.45 - 14.00 | C37: 23 | D37: 3 | E37: 4 | F37: 13 | G37: 0 | H37: 0 | I37: 9 | J37: 0 | K37: 0 | L37: 0 | M37: 9 | N37: 0 | O37: =SUM(C37:L37,N37) -> 52 | P37: =SUM(C37:N37) -> 61
B38: 14.00 - 14.15 | C38: 8 | D38: 3 | E38: 1 | F38: 8 | G38: 0 | H38: 0 | I38: 5 | J38: 0 | K38: 0 | L38: 0 | M38: 12 | N38: 0 | O38: =SUM(C38:L38,N38) -> 25 | P38: =SUM(C38:N38) -> 37
B39: 14.15 - 14.30 | C39: 15 | D39: 0 | E39: 1 | F39: 0 | G39: 1 | H39: 0 | I39: 1 | J39: 0 | K39: 0 | L39: 0 | M39: 10 | N39: 0 | O39: =SUM(C39:L39,N39) -> 18 | P39: =SUM(C39:N39) -> 28
B40: 14.30 - 14.45 | C40: 9 | D40: 2 | E40: 1 | F40: 12 | G40: 0 | H40: 0 | I40: 7 | J40: 2 | K40: 0 | L40: 0 | M40: 11 | N40: 0 | O40: =SUM(C40:L40,N40) -> 33 | P40: =SUM(C40:N40) -> 44
... B56: 18.30 - 18.45 | C56: 24 | D56: 3 | E56: 2 | F56: 32 | G56: 0 | H56: 0 | I56: 0 | J56: 0 | K56: 0 | L56: 0 | M56: 18 | N56: 0 | O56: =SUM(C56:L56,N56) -> 61 | P56: =SUM(C56:N56) -> 79
B57: 18.45 - 19.00 | C57: 19 | D57: 0 | E57: 5 | F57: 9 | H57: 0 | I57: 0 | J57: 0 | K57: 0 | L57: 0 | M57: 9 | N57: 0 | O57: =SUM(C57:L57,N57) -> 33 | P57: =SUM(C57:N57) -> 42
...

Sheet 23.9.19-MUNYONYO-SALAMA
B1: Consultancy services for Preparation of Expressway Development Master Plan (EDMP) for Uganda
B2: MANUAL CLASSIFIED COUNT (MCC)
B3: ROAD NAME: | C3: ='23.9.19 SALAMA - MUNYONYO'!C3:G3 -> MCC - C2 - STN-51 - SALAMA ROAD
C5: Date | D5: ='23.9.19 SALAMA - MUNYONYO'!D5 -> 23.07.19 | F5: Location | G5: ='23.9.19 SALAMA - MUNYONYO'!G5:H5 -> MUNYONYO P/S | J5: Surveyor | K5: OLOYA
C6: Dir. From | D6: MUNYONYO | F6: Dir. To | G6: SALAMA | J6: Supervisor | K6: ='23.9.19 SALAMA - MUNYONYO'!K6:L6 -> STEVEN
B8: Time / Veh Type | R8: SUMMARY TRAFFIC VOLUMES
C9: 1. Car | D9: 2. Station Wagon | E9: 3. Pickups | F9: 4. Minibus, matatu | G9: 5. Medium bus | H9: 6. Large Bus | I9: 7. Light Truck | J9: 8. Medium Truck | K9: 9. Heavy truck | L9: 10. Truck Trailer | M9: 11. Motor cycles | N9: 12. Tractors | O9: Total Excl M/Cycles | P9: Total All | R9: Time | S9: 1. Car | T9: 2. Station Wagon | U9: 3. Pickups | V9: 4. Minibus, matatu | W9: 5. Medium bus | X9: 6. Large Bus | Y9: 7. Light Truck | Z9: 8. Medium Truck | AA9: 9. Heavy truck | AB9: 10. Truck Trailer | AC9: 11. Motorcycles | AD9: 12. Tractors, Graders | AE9: Total Excl M/ Cycles | AF9: Total All
B10: 07.00 - 07.15 | C10: 26 | D10: 7 | E10: 6 | F10: 8 | G10: 1 | H10: 0 | I10: 1 | J10: 1 | K10: 1 | L10: 0 | M10: 22 | N10: 0 | O10: =SUM(C10:L10,N10) -> 51 | P10: =SUM(C10:N10) -> 73 | R10: 0700-0800 | S10: =SUM(C10:C13) -> 126 | T10: =SUM(D10:D13) -> 34 | U10: =SUM(E10:E13) -> 14 | V10: =SUM(F10:F13) -> 76 | W10: =SUM(G10:G13) -> 2 | X10: =SUM(H10:H13) -> 0 | Y10: =SUM(I10:I13) -> 7 | Z10: =SUM(J10:J13) -> 3 | ... AF10: =SUM(P10:P13) -> 368
B11: 07.15 - 07.30 | C11: 34 | D11: 11 | E11: 0 | F11: 15 | G11: 0 | H11: 0 | I11: 1 | J11: 1 | K11: 0 | L11: 0 | M11: 21 | N11: 0 | O11: =SUM(C11:L11,N11) -> 62 | P11: =SUM(C11:N11) -> 83 | R11: 0800-0900 | S11: =SUM(C14:C17) -> 100 | T11: =SUM(D14:D17) -> 14 | U11: =SUM(E14:E17) -> 26 | V11: =SUM(F14:F17) -> 76 | W11: =SUM(G14:G17) -> 3 | X11: =SUM(H14:H17) -> 4 | Y11: =SUM(I14:I17) -> 9 | Z11: =SUM(J14:J17) -> 0 | ... AF11: =SUM(P14:P17) -> 366
B12: 07.30 - 07.45 | C12: 46 | D12: 13 | E12: 5 | F12: 13 | G12: 1 | H12: 0 | I12: 2 | J12: 0 | K12: 0 | L12: 0 | M12: 30 | N12: 0 | O12: =SUM(C12:L12,N12) -> 80 | P12: =SUM(C12:N12) -> 110 | R12: 0900-1000 | S12: =SUM(C18:C21) -> 106 | T12: =SUM(D18:D21) -> 30 | U12: =SUM(E18:E21) -> 8 | V12: =SUM(F18:F21) -> 89 | W12: =SUM(G18:G21) -> 0 | X12: =SUM(H18:H21) -> 2 | Y12: =SUM(I18:I21) -> 7 | Z12: =SUM(J18:J21) -> 2 | ... AF12: =SUM(P18:P21) -> 439
B13: 07.45 - 08.00 | C13: 20 | D13: 3 | E13: 3 | F13: 40 | G13: 0 | H13: 0 | I13: 3 | J13: 1 | K13: 0 | L13: 0 | M13: 32 | N13: 0 | O13: =SUM(C13:L13,N13) -> 70 | P13: =SUM(C13:N13) -> 102 | R13: 1000-1100 | S13: =SUM(C22:C25) -> 80 | T13: =SUM(D22:D25) -> 16 | U13: =SUM(E22:E25) -> 4 | V13: =SUM(F22:F25) -> 55 | W13: =SUM(G22:G25) -> 2 | X13: =SUM(H22:H25) -> 0 | Y13: =SUM(I22:I25) -> 9 | Z13: =SUM(J22:J25) -> 3 | ... AF13: =SUM(P22:P25) -> 334
B14: 08.00 - 08.15 | C14: 16 | D14: 0 | E14: 0 | F14: 27 | G14: 2 | H14: 0 | I14: 3 | J14: 0 | K14: 0 | L14: 0 | M14: 14 | N14: 0 | O14: =SUM(C14:L14,N14) -> 48 | P14: =SUM(C14:N14) -> 62 | R14: 1100-1200 | S14: =SUM(C26:C29) -> 55 | T14: =SUM(D26:D29) -> 16 | U14: =SUM(E26:E29) -> 10 | V14: =SUM(F26:F29) -> 53 | W14: =SUM(G26:G29) -> 0 | X14: =SUM(H26:H29) -> 2 | Y14: =SUM(I26:I29) -> 16 | Z14: =SUM(J26:J29) -> 0 | ... AF14: =SUM(P26:P29) -> 291
B15: 08.15 - 08.30 | C15: 34 | D15: 1 | E15: 3 | F15: 34 | G15: 1 | H15: 1 | I15: 2 | J15: 0 | K15: 0 | L15: 0 | M15: 52 | N15: 0 | O15: =SUM(C15:L15,N15) -> 76 | P15: =SUM(C15:N15) -> 128 | R15: 1200-1300 | S15: =SUM(C30:C33) -> 65 | T15: =SUM(D30:D33) -> 13 | U15: =SUM(E30:E33) -> 12 | V15: =SUM(F30:F33) -> 38 | W15: =SUM(G30:G33) -> 12 | X15: =SUM(H30:H33) -> 2 | Y15: =SUM(I30:I33) -> 6 | Z15: =SUM(J30:J33) -> 3 | ... AF15: =SUM(P30:P33) -> 307
B16: 08.30 - 08.45 | C16: 12 | D16: 6 | E16: 0 | F16: 15 | G16: 0 | H16: 0 | I16: 4 | J16: 0 | K16: 0 | L16: 0 | M16: 30 | N16: 0 | O16: =SUM(C16:L16,N16) -> 37 | P16: =SUM(C16:N16) -> 67 | R16: 1300-1400 | S16: =SUM(C34:C37) -> 67 | T16: =SUM(D34:D37) -> 14 | U16: =SUM(E34:E37) -> 12 | V16: =SUM(F34:F37) -> 56 | W16: =SUM(G34:G37) -> 0 | X16: =SUM(H34:H37) -> 0 | Y16: =SUM(I34:I37) -> 17 | Z16: =SUM(J34:J37) -> 1 | ... AF16: =SUM(P34:P37) -> 344
B17: 08.45 - 9.00 | C17: 38 | D17: 7 | E17: 23 | F17: 0 | G17: 0 | H17: 3 | I17: 0 | J17: 0 | K17: 0 | L17: 0 | M17: 38 | N17: 0 | O17: =SUM(C17:L17,N17) -> 71 | P17: =SUM(C17:N17) -> 109 | R17: 1400-1500 | S17: =SUM(C38:C41) -> 94 | T17: =SUM(D38:D41) -> 20 | U17: =SUM(E38:E41) -> 11 | V17: =SUM(F38:F41) -> 51 | W17: =SUM(G38:G41) -> 0 | X17: =SUM(H38:H41) -> 0 | Y17: =SUM(I38:I41) -> 13 | Z17: =SUM(J38:J41) -> 2 | ... AF17: =SUM(P38:P41) -> 335
B18: 09.00 - 09.15 | C18: 29 | D18: 5 | E18: 1 | F18: 29 | G18: 0 | H18: 2 | I18: 1 | J18: 0 | K18: 0 | L18: 0 | M18: 40 | N18: 0 | O18: =SUM(C18:L18,N18) -> 67 | P18: =SUM(C18:N18) -> 107 | R18: 1500-1600 | S18: =SUM(C42:C45) -> 87 | T18: =SUM(D42:D45) -> 16 | U18: =SUM(E42:E45) -> 8 | V18: =SUM(F42:F45) -> 62 | W18: =SUM(G42:G45) -> 1 | X18: =SUM(H42:H45) -> 0 | Y18: =SUM(I42:I45) -> 11 | Z18: =SUM(J42:J45) -> 2 | ... AF18: =SUM(P42:P45) -> 344
B19: 09.15 - 09.30 | C19: 32 | D19: 10 | E19: 0 | F19: 26 | G19: 0 | H19: 0 | I19: 2 | J19: 0 | K19: 1 | L19: 0 | M19: 60 | N19: 0 | O19: =SUM(C19:L19,N19) -> 71 | P19: =SUM(C19:N19) -> 131 | R19: 1600-1700 | S19: =SUM(C46:C49) -> 107 | T19: =SUM(D46:D49) -> 32 | U19: =SUM(E46:E49) -> 16 | V19: =SUM(F46:F49) -> 75 | W19: =SUM(G46:G49) -> 3 | X19: =SUM(H46:H49) -> 1 | Y19: =SUM(I46:I49) -> 14 | Z19: =SUM(J46:J49) -> 3 | ... AF19: =SUM(P46:P49) -> 389
B20: 09.30 - 09.45 | C20: 11 | D20: 4 | E20: 1 | F20: 17 | G20: 0 | H20: 0 | I20: 1 | J20: 2 | K20: 0 | L20: 0 | M20: 34 | N20: 0 | O20: =SUM(C20:L20,N20) -> 36 | P20: =SUM(C20:N20) -> 70 | R20: 1700-1800 | S20: =SUM(C50:C53) -> 112 | T20: =SUM(D50:D53) -> 28 | U20: =SUM(E50:E53) -> 13 | V20: =SUM(F50:F53) -> 52 | W20: =SUM(G50:G53) -> 5 | X20: =SUM(H50:H53) -> 0 | Y20: =SUM(I50:I53) -> 12 | Z20: =SUM(J50:J53) -> 3 | ... AF20: =SUM(P50:P53) -> 390
B21: 09.45 - 10.00 | C21: 34 | D21: 11 | E21: 6 | F21: 17 | G21: 0 | H21: 0 | I21: 3 | J21: 0 | K21: 0 | L21: 0 | M21: 60 | N21: 0 | O21: =SUM(C21:L21,N21) -> 71 | P21: =SUM(C21:N21) -> 131 | R21: 1800-1900 | S21: =SUM(C54:C57) -> 98 | T21: =SUM(D54:D57) -> 32 | U21: =SUM(E54:E57) -> 24 | V21: =SUM(F54:F57) -> 84 | W21: =SUM(G54:G57) -> 2 | X21: =SUM(H54:H57) -> 0 | Y21: =SUM(I54:I57) -> 9 | Z21: =SUM(J54:J57) -> 0 | ... AF21: =SUM(P54:P57) -> 400
B22: 10.00 - 10.15 | C22: 18 | D22: 6 | E22: 0 | F22: 13 | G22: 1 | H22: 0 | I22: 1 | J22: 2 | K22: 1 | L22: 0 | M22: 36 | N22: 0 | O22: =SUM(C22:L22,N22) -> 42 | P22: =SUM(C22:N22) -> 78 | R22: AM Peak Hr | S22: =MAX(S10:S12) -> 126 | T22: =MAX(T10:T12) -> 34 | U22: =MAX(U10:U12) -> 26 | V22: =MAX(V10:V12) -> 89 | W22: =MAX(W10:W12) -> 3 | X22: =MAX(X10:X12) -> 4 | Y22: =MAX(Y10:Y12) -> 9 | Z22: =MAX(Z10:Z12) -> 3 | ... AF22: =MAX(AF10:AF12) -> 439
B23: 10.15 - 10.30 | C23: 32 | D23: 2 | E23: 1 | F23: 14 | G23: 0 | H23: 0 | I23: 1 | J23: 0 | K23: 0 | L23: 0 | M23: 52 | N23: 0 | O23: =SUM(C23:L23,N23) -> 50 | P23: =SUM(C23:N23) -> 102 | R23: IP Peak Hr | S23: =MAX(S13:S18) -> 94 | T23: =MAX(T13:T18) -> 20 | U23: =MAX(U13:U18) -> 12 | V23: =MAX(V13:V18) -> 62 | W23: =MAX(W13:W18) -> 12 | X23: =MAX(X13:X18) -> 2 | Y23: =MAX(Y13:Y18) -> 17 | Z23: =MAX(Z13:Z18) -> 3 | ... AF23: =MAX(AF13:AF18) -> 344
B24: 10.30 - 10.45 | C24: 13 | D24: 3 | E24: 1 | F24: 12 | G24: 0 | H24: 0 | I24: 1 | J24: 0 | K24: 0 | L24: 0 | M24: 44 | N24: 0 | O24: =SUM(C24:L24,N24) -> 30 | P24: =SUM(C24:N24) -> 74 | R24: PM Peak Hr | S24: =MAX(S19:S21) -> 112 | T24: =MAX(T19:T21) -> 32 | U24: =MAX(U19:U21) -> 24 | V24: =MAX(V19:V21) -> 84 | W24: =MAX(W19:W21) -> 5 | X24: =MAX(X19:X21) -> 1 | Y24: =MAX(Y19:Y21) -> 14 | Z24: =MAX(Z19:Z21) -> 3 | ... AF24: =MAX(AF19:AF21) -> 400
B25: 10.45 - 11.00 | C25: 17 | D25: 5 | E25: 2 | F25: 16 | G25: 1 | H25: 0 | I25: 6 | J25: 1 | K25: 0 | L25: 0 | M25: 32 | N25: 0 | O25: =SUM(C25:L25,N25) -> 48 | P25: =SUM(C25:N25) -> 80 | R25: AM Period | S25: =SUM(S10:S12) -> 332 | T25: =SUM(T10:T12) -> 78 | U25: =SUM(U10:U12) -> 48 | V25: =SUM(V10:V12) -> 241 | W25: =SUM(W10:W12) -> 5 | X25: =SUM(X10:X12) -> 6 | Y25: =SUM(Y10:Y12) -> 23 | Z25: =SUM(Z10:Z12) -> 5 | ... AF25: =SUM(AF10:AF12) -> 1173
B26: 11.00 - 11.15 | C26: 16 | D26: 5 | E26: 2 | F26: 13 | G26: 0 | H26: 0 | I26: 5 | J26: 0 | K26: 0 | L26: 0 | M26: 34 | N26: 0 | O26: =SUM(C26:L26,N26) -> 41 | P26: =SUM(C26:N26) -> 75 | R26: IP Period | S26: =SUM(S13:S18) -> 448 | T26: =SUM(T13:T18) -> 95 | U26: =SUM(U13:U18) -> 57 | V26: =SUM(V13:V18) -> 315 | W26: =SUM(W13:W18) -> 15 | X26: =SUM(X13:X18) -> 4 | Y26: =SUM(Y13:Y18) -> 72 | Z26: =SUM(Z13:Z18) -> 11 | ... AF26: =SUM(AF13:AF18) -> 1955
B27: 11.15 - 11.30 | C27: 13 | D27: 3 | E27: 3 | F27: 14 | G27: 0 | H27: 2 | I27: 1 | J27: 0 | K27: 0 | L27: 0 | M27: 36 | N27: 0 | O27: =SUM(C27:L27,N27) -> 36 | P27: =SUM(C27:N27) -> 72 | R27: PM Period | S27: =SUM(S19:S21) -> 317 | T27: =SUM(T19:T21) -> 92 | U27: =SUM(U19:U21) -> 53 | V27: =SUM(V19:V21) -> 211 | W27: =SUM(W19:W21) -> 10 | X27: =SUM(X19:X21) -> 1 | Y27: =SUM(Y19:Y21) -> 35 | Z27: =SUM(Z19:Z21) -> 6 | ... AF27: =SUM(AF19:AF21) -> 1179
B28: 11.30 - 11.45 | C28: 17 | D28: 2 | E28: 4 | F28: 16 | G28: 0 | H28: 0 | I28: 5 | J28: 0 | K28: 0 | L28: 0 | M28: 35 | N28: 0 | O28: =SUM(C28:L28,N28) -> 44 | P28: =SUM(C28:N28) -> 79 | R28: 12 Hours | S28: =SUM(S10:S21) -> 1097 | T28: =SUM(T10:T21) -> 265 | U28: =SUM(U10:U21) -> 158 | V28: =SUM(V10:V21) -> 767 | W28: =SUM(W10:W21) -> 30 | X28: =SUM(X10:X21) -> 11 | Y28: =SUM(Y10:Y21) -> 130 | Z28: =SUM(Z10:Z21) -> 22 | ... AF28: =SUM(AF10:AF21) -> 4307
B29: 11.45 - 12.00 | C29: 9 | D29: 6 | E29: 1 | F29: 10 | G29: 0 | H29: 0 | I29: 5 | J29: 0 | K29: 0 | L29: 0 | M29: 34 | N29: 0 | O29: =SUM(C29:L29,N29) -> 31 | P29: =SUM(C29:N29) -> 65
B30: 12.00 - 12.15 | C30: 13 | D30: 3 | E30: 5 | F30: 12 | G30: 1 | H30: 0 | I30: 0 | J30: 0 | K30: 0 | L30: 0 | M30: 28 | N30: 0 | O30: =SUM(C30:L30,N30) -> 34 | P30: =SUM(C30:N30) -> 62
B31: 12.15 - 12.30 | C31: 14 | D31: 7 | E31: 0 | F31: 11 | G31: 0 | H31: 0 | I31: 5 | J31: 0 | K31: 0 | L31: 0 | M31: 41 | N31: 0 | O31: =SUM(C31:L31,N31) -> 37 | P31: =SUM(C31:N31) -> 78
B32: 12.30 - 12.45 | C32: 23 | D32: 0 | E32: 3 | F32: 0 | G32: 11 | H32: 2 | I32: 0 | J32: 3 | K32: 1 | L32: 0 | M32: 31 | N32: 0 | O32: =SUM(C32:L32,N32) -> 43 | P32: =SUM(C32:N32) -> 74
B33: 12.45 - 13.00 | C33: 15 | D33: 3 | E33: 4 | F33: 15 | G33: 0 | H33: 0 | I33: 1 | J33: 0 | K33: 0 | L33: 0 | M33: 55 | N33: 0 | O33: =SUM(C33:L33,N33) -> 38 | P33: =SUM(C33:N33) -> 93
B34: 13.00 - 13.15 | C34: 18 | D34: 3 | E34: 3 | F34: 13 | G34: 0 | H34: 0 | I34: 7 | J34: 0 | K34: 0 | L34: 0 | M34: 41 | N34: 0 | O34: =SUM(C34:L34,N34) -> 44 | P34: =SUM(C34:N34) -> 85
B35: 13.15 - 13.30 | C35: 13 | D35: 4 | E35: 2 | F35: 16 | G35: 0 | H35: 0 | I35: 1 | J35: 0 | K35: 0 | L35: 0 | M35: 46 | N35: 0 | O35: =SUM(C35:L35,N35) -> 36 | P35: =SUM(C35:N35) -> 82
B36: 13.30 - 13.45 | C36: 17 | D36: 1 | E36: 5 | F36: 12 | G36: 0 | H36: 0 | I36: 6 | J36: 1 | K36: 0 | L36: 0 | M36: 61 | N36: 0 | O36: =SUM(C36:L36,N36) -> 42 | P36: =SUM(C36:N36) -> 103
B37: 13.45 - 14.00 | C37: 19 | D37: 6 | E37: 2 | F37: 15 | G37: 0 | H37: 0 | I37: 3 | J37: 0 | K37: 1 | L37: 0 | M37: 28 | N37: 0 | O37: =SUM(C37:L37,N37) -> 46 | P37: =SUM(C37:N37) -> 74
B38: 14.00 - 14.15 | C38: 26 | D38: 4 | E38: 6 | F38: 16 | G38: 0 | H38: 0 | I38: 5 | J38: 1 | K38: 0 | L38: 0 | M38: 35 | N38: 0 | O38: =SUM(C38:L38,N38) -> 58 | P38: =SUM(C38:N38) -> 93
B39: 14.15 - 14.30 | C39: 34 | D39: 8 | E39: 3 | F39: 14 | G39: 0 | H39: 0 | I39: 4 | J39: 0 | K39: 2 | L39: 0 | M39: 65 | N39: 0 | O39: =SUM(C39:L39,N39) -> 65 | P39: =SUM(C39:N39) -> 130
B40: 14.30 - 14.45 | C40: 12 | D40: 4 | E40: 0 | F40: 9 | G40: 0 | H40: 0 | I40: 1 | J40: 1 | K40: 0 | L40: 0 | M40: 18 | N40: 0 | O40: =SUM(C40:L40,N40) -> 27 | P40: =SUM(C40:N40) -> 45
... B57: 18.45 - 19.00 | C57: 23 | D57: 3 | E57: 6 | F57: 21 | G57: 1 | H57: 0 | I57: 2 | J57: 0 | K57: 0 | L57: 0 | M57: 25 | N57: 0 | O57: =SUM(C57:L57,N57) -> 56 | P57: =SUM(C57:N57) -> 81
B58: Totals | C58: =SUM(C10:C57) -> 1097 | D58: =SUM(D10:D57) -> 265 | E58: =SUM(E10:E57) -> 158 | F58: =SUM(F10:F57) -> 767 | G58: =SUM(G10:G57) -> 30 | H58: =SUM(H10:H57) -> 11 | I58: =SUM(I10:I57) -> 130 | J58: =SUM(J10:J57) -> 22 | ... P58: =SUM(P10:P57) -> 4307
...

Sheet 24.09 SALAMA-MUNYONYO
B1: Consultancy services for Preparation of Expressway Development Master Plan (EDMP) for Uganda
B2: MANUAL CLASSIFIED COUNT (MCC)
B3: ROAD NAME: | C3: MCC-C2-STN51-SALAMA ROAD
C5: Date | D5: 24.09.19 | F5: Location | G5: MUNYONYO PS | J5: Surveyor | K5: KENNETH
C6: Dir. From | D6: SALAAMA | F6: Dir. To | G6: MUNYONYO | J6: Supervisor | K6: STEVEN
B8: Time / Veh Type | R8: SUMMARY TRAFFIC VOLUMES
C9: 1. Car | D9: 2. Station Wagon | E9: 3. Pickups | F9: 4. Minibus, matatu | G9: 5. Medium bus | H9: 6. Large Bus | I9: 7. Light Truck | J9: 8. Medium Truck | K9: 9. Heavy truck | L9: 10. Truck Trailer | M9: 11. Motor cycles | N9: 12. Tractors | O9: Total Excl M/Cycles | P9: Total All | R9: Time | S9: 1. Car | T9: 2. Station Wagon | U9: 3. Pickups | V9: 4. Minibus, matatu | W9: 5. Medium bus | X9: 6. Large Bus | Y9: 7. Light Truck | Z9: 8. Medium Truck | AA9: 9. Heavy truck | AB9: 10. Truck Trailer | AC9: 11. Motorcycles | AD9: 12. Tractors, Graders | AE9: Total Excl M/ Cycles | AF9: Total All
B10: 07.00 - 07.15 | C10: 18 | D10: 2 | E10: 1 | F10: 29 | G10: 0 | H10: 0 | I10: 0 | J10: 0 | K10: 0 | L10: 0 | M10: 29 | N10: 0 | O10: =SUM(C10:L10,N10) -> 50 | P10: =SUM(C10:N10) -> 79 | R10: 0700-0800 | S10: =SUM(C10:C13) -> 87 | T10: =SUM(D10:D13) -> 10 | U10: =SUM(E10:E13) -> 5 | V10: =SUM(F10:F13) -> 72 | W10: =SUM(G10:G13) -> 0 | X10: =SUM(H10:H13) -> 0 | Y10: =SUM(I10:I13) -> 7 | Z10: =SUM(J10:J13) -> 1 | ... AF10: =SUM(P10:P13) -> 278
B11: 07.15 - 07.30 | C11: 25 | D11: 5 | E11: 1 | F11: 20 | G11: 0 | H11: 0 | I11: 4 | J11: 0 | K11: 0 | L11: 0 | M11: 23 | N11: 0 | O11: =SUM(C11:L11,N11) -> 55 | P11: =SUM(C11:N11) -> 78 | R11: 0800-0900 | S11: =SUM(C14:C17) -> 64 | T11: =SUM(D14:D17) -> 5 | U11: =SUM(E14:E17) -> 13 | V11: =SUM(F14:F17) -> 93 | W11: =SUM(G14:G17) -> 0 | X11: =SUM(H14:H17) -> 0 | Y11: =SUM(I14:I17) -> 11 | Z11: =SUM(J14:J17) -> 3 | ... AF11: =SUM(P14:P17) -> 315
B12: 07.30 - 07.45 | C12: 10 | D12: 3 | E12: 1 | F12: 14 | G12: 0 | H12: 0 | I12: 1 | J12: 0 | K12: 0 | L12: 0 | M12: 10 | N12: 0 | O12: =SUM(C12:L12,N12) -> 29 | P12: =SUM(C12:N12) -> 39 | R12: 0900-1000 | S12: =SUM(C18:C23) -> 80 | T12: =SUM(D18:D23) -> 2 | U12: =SUM(E18:E23) -> 8 | V12: =SUM(F18:F23) -> 89 | W12: =SUM(G18:G23) -> 0 | X12: =SUM(H18:H23) -> 0 | Y12: =SUM(I18:I23) -> 6 | Z12: =SUM(J18:J23) -> 17 | ... AD12: =SUM(N18:N23) -> 0 | AE12: =SUM(O18:O21) -> 134 | AF12: =SUM(P18:P21) -> 229
B13: 07.45 - 08.00 | C13: 34 | D13: 0 | E13: 2 | F13: 9 | G13: 0 | H13: 0 | I13: 2 | J13: 1 | K13: 0 | L13: 0 | M13: 34 | N13: 0 | O13: =SUM(C13:L13,N13) -> 48 | P13: =SUM(C13:N13) -> 82 | R13: 1000-1100 | S13: =SUM(C24:C27) -> 58 | T13: =SUM(D24:D27) -> 11 | U13: =SUM(E24:E27) -> 5 | V13: =SUM(F24:F27) -> 60 | W13: =SUM(G24:G27) -> 0 | X13: =SUM(H24:H27) -> 0 | Y13: =SUM(I24:I27) -> 7 | Z13: =SUM(J24:J27) -> 0 | ... AD13: =SUM(N24:N27) -> 0 | AE13: =SUM(O22:O25) -> 130 | AF13: =SUM(P22:P25) -> 207
B14: 08.00 - 08.15 | C14: 22 | D14: 0 | E14: 5 | F14: 29 | G14: 0 | H14: 0 | I14: 5 | J14: 0 | K14: 0 | L14: 0 | M14: 35 | N14: 0 | O14: =SUM(C14:L14,N14) -> 61 | P14: =SUM(C14:N14) -> 96 | R14: 1100-1200 | S14: =SUM(C28:C31) -> 40 | T14: =SUM(D28:D31) -> 7 | U14: =SUM(E28:E31) -> 12 | V14: =SUM(F28:F31) -> 38 | W14: =SUM(G28:G31) -> 0 | X14: =SUM(H28:H31) -> 0 | Y14: =SUM(I28:I31) -> 8 | Z14: =SUM(J28:J31) -> 0 | ... AD14: =SUM(N28:N31) -> 0 | AE14: =SUM(O26:O29) -> 118 | AF14: =SUM(P26:P29) -> 201
B15: 08.15 - 08.30 | C15: 10 | D15: 3 | E15: 1 | F15: 25 | G15: 0 | H15: 0 | I15: 2 | J15: 0 | K15: 0 | L15: 0 | M15: 18 | N15: 0 | O15: =SUM(C15:L15,N15) -> 41 | P15: =SUM(C15:N15) -> 59 | R15: 1200-1300 | S15: =SUM(C32:C35) -> 70 | T15: =SUM(D32:D35) -> 16 | U15: =SUM(E32:E35) -> 10 | V15: =SUM(F32:F35) -> 54 | W15: =SUM(G32:G35) -> 3 | X15: =SUM(H32:H35) -> 1 | Y15: =SUM(I32:I35) -> 14 | Z15: =SUM(J32:J35) -> 0 | ... AD15: =SUM(N32:N35) -> 0 | AE15: =SUM(O30:O33) -> 143 | AF15: =SUM(P30:P33) -> 236
B16: 08.30 - 08.45 | C16: 19 | D16: 1 | E16: 6 | F16: 11 | G16: 0 | H16: 0 | I16: 4 | J16: 0 | K16: 0 | L16: 0 | M16: 35 | N16: 0 | O16: =SUM(C16:L16,N16) -> 41 | P16: =SUM(C16:N16) -> 76 | R16: 1300-1400 | S16: =SUM(C36:C39) -> 55 | T16: =SUM(D36:D39) -> 7 | U16: =SUM(E36:E39) -> 2 | V16: =SUM(F36:F39) -> 37 | W16: =SUM(G36:G39) -> 0 | X16: =SUM(H36:H39) -> 0 | Y16: =SUM(I36:I39) -> 11 | Z16: =SUM(J36:J39) -> 0 | ... AD16: =SUM(N36:N39) -> 0 | AE16: =SUM(O34:O37) -> 150 | AF16: =SUM(P34:P37) -> 265
B17: 08.45 - 9.00 | C17: 13 | D17: 1 | E17: 1 | F17: 28 | G17: 0 | H17: 0 | I17: 0 | J17: 3 | K17: 0 | L17: 0 | M17: 38 | N17: 0 | O17: =SUM(C17:L17,N17) -> 46 | P17: =SUM(C17:N17) -> 84 | R17: 1400-1500 | S17: =SUM(C40:C43) -> 84 | T17: =SUM(D40:D43) -> 28 | U17: =SUM(E40:E43) -> 10 | V17: =SUM(F40:F43) -> 64 | W17: =SUM(G40:G43) -> 0 | X17: =SUM(H40:H43) -> 0 | Y17: =SUM(I40:I43) -> 4 | Z17: =SUM(J40:J43) -> 6 | ... AD17: =SUM(N40:N43) -> 0 | AE17: =SUM(O38:O41) -> 152 | AF17: =SUM(P38:P41) -> 276
B18: 09.00 - 09.15 | C18: 13 | D18: 0 | E18: 1 | F18: 18 | G18: 0 | H18: 0 | I18: 0 | J18: 3 | K18: 0 | L18: 0 | M18: 32 | N18: 0 | O18: =SUM(C18:L18,N18) -> 35 | P18: =SUM(C18:N18) -> 67 | R18: 1500-1600 | S18: =SUM(C44:C47) -> 74 | T18: =SUM(D44:D47) -> 9 | U18: =SUM(E44:E47) -> 2 | V18: =SUM(F44:F47) -> 78 | W18: =SUM(G44:G47) -> 0 | X18: =SUM(H44:H47) -> 0 | Y18: =SUM(I44:I47) -> 6 | Z18: =SUM(J44:J47) -> 2 | ... AD18: =SUM(N44:N47) -> 0 | AE18: =SUM(O42:O45) -> 193 | AF18: =SUM(P42:P45) -> 316
B19: 09.15 - 09.30 | C19: 12 | D19: 1 | E19: 1 | F19: 12 | G19: 0 | H19: 0 | I19: 1 | J19: 4 | K19: 0 | L19: 0 | M19: 21 | N19: 0 | O19: =SUM(C19:L19,N19) -> 31 | P19: =SUM(C19:N19) -> 52 | R19: 1600-1700 | S19: =SUM(C48:C51) -> 113 | T19: =SUM(D48:D51) -> 12 | U19: =SUM(E48:E51) -> 9 | V19: =SUM(F48:F51) -> 61 | W19: =SUM(G48:G51) -> 0 | X19: =SUM(H48:H51) -> 0 | Y19: =SUM(I48:I51) -> 2 | Z19: =SUM(J48:J51) -> 3 | ... AD19: =SUM(N48:N51) -> 0 | AE19: =SUM(O46:O49) -> 172 | AF19: =SUM(P46:P49) -> 237
B20: 09.30 - 09.45 | C20: 14 | D20: 0 | E20: 1 | F20: 16 | G20: 0 | H20: 0 | I20: 1 | J20: 1 | K20: 0 | L20: 0 | M20: 19 | N20: 0 | O20: =SUM(C20:L20,N20) -> 33 | P20: =SUM(C20:N20) -> 52 | R20: 1700-1800 | S20: =SUM(C52:C53) -> 68 | T20: =SUM(D52:D53) -> 5 | U20: =SUM(E52:E53) -> 8 | V20: =SUM(F52:F53) -> 51 | W20: =SUM(G52:G53) -> 1 | X20: =SUM(H52:H53) -> 0 | Y20: =SUM(I52:I53) -> 4 | Z20: =SUM(J52:J53) -> 1 | ... AD20: =SUM(N52:N53) -> 0 | AE20: =SUM(O50:O53) -> 244 | AF20: =SUM(P50:P53) -> 328
B21: 09.45 - 10.00 | C21: 9 | D21: 1 | E21: 2 | F21: 17 | G21: 0 | H21: 0 | I21: 1 | J21: 5 | K21: 0 | L21: 0 | M21: 23 | N21: 0 | O21: =SUM(C21:L21,N21) -> 35 | P21: =SUM(C21:N21) -> 58 | R21: 1800-1900 | S21: =SUM(C54:C57) -> 158 | T21: =SUM(D54:D57) -> 20 | U21: =SUM(E54:E57) -> 24 | V21: =SUM(F54:F57) -> 78 | W21: =SUM(G54:G57) -> 2 | X21: =SUM(H54:H57) -> 0 | Y21: =SUM(I54:I57) -> 11 | Z21: =SUM(J54:J57) -> 1 | ... AF21: =SUM(P54:P57) -> 433
B22: 10.00 - 10.15 | C22: 17 | D22: 0 | E22: 0 | F22: 15 | G22: 0 | H22: 0 | I22: 2 | J22: 4 | K22: 0 | L22: 0 | M22: 14 | N22: 0 | O22: =SUM(C22:L22,N22) -> 38 | P22: =SUM(C22:N22) -> 52 | R22: AM Peak Hr | S22: =MAX(S10:S12) -> 87 | T22: =MAX(T10:T12) -> 10 | U22: =MAX(U10:U12) -> 13 | V22: =MAX(V10:V12) -> 93 | W22: =MAX(W10:W12) -> 0 | X22: =MAX(X10:X12) -> 0 | Y22: =MAX(Y10:Y12) -> 11 | Z22: =MAX(Z10:Z12) -> 17 | ... AF22: =MAX(AF10:AF12) -> 315
B23: 10.15 - 10.30 | C23: 15 | D23: 0 | E23: 3 | F23: 11 | G23: 0 | H23: 0 | I23: 1 | J23: 0 | K23: 0 | L23: 0 | M23: 22 | N23: 0 | O23: =SUM(C23:L23,N23) -> 30 | P23: =SUM(C23:N23) -> 52 | R23: IP Peak Hr | S23: =MAX(S13:S18) -> 84 | T23: =MAX(T13:T18) -> 28 | U23: =MAX(U13:U18) -> 12 | V23: =MAX(V13:V18) -> 78 | W23: =MAX(W13:W18) -> 3 | X23: =MAX(X13:X18) -> 1 | Y23: =MAX(Y13:Y18) -> 14 | Z23: =MAX(Z13:Z18) -> 6 | ... AF23: =MAX(AF13:AF18) -> 316
B24: 10.30 - 10.45 | C24: 5 | D24: 3 | E24: 0 | F24: 11 | G24: 0 | H24: 0 | I24: 2 | J24: 0 | K24: 0 | L24: 0 | M24: 22 | N24: 0 | O24: =SUM(C24:L24,N24) -> 21 | P24: =SUM(C24:N24) -> 43 | R24: PM Peak Hr | S24: =MAX(S19:S21) -> 158 | T24: =MAX(T19:T21) -> 20 | U24: =MAX(U19:U21) -> 24 | V24: =MAX(V19:V21) -> 78 | W24: =MAX(W19:W21) -> 2 | X24: =MAX(X19:X21) -> 0 | Y24: =MAX(Y19:Y21) -> 11 | Z24: =MAX(Z19:Z21) -> 3 | ... AF24: =MAX(AF19:AF21) -> 433
B25: 10.45 - 11.00 | C25: 19 | D25: 1 | E25: 2 | F25: 15 | G25: 0 | H25: 0 | I25: 4 | J25: 0 | K25: 0 | L25: 0 | M25: 19 | N25: 0 | O25: =SUM(C25:L25,N25) -> 41 | P25: =SUM(C25:N25) -> 60 | R25: AM Period | S25: =SUM(S10:S12) -> 231 | T25: =SUM(T10:T12) -> 17 | U25: =SUM(U10:U12) -> 26 | V25: =SUM(V10:V12) -> 254 | W25: =SUM(W10:W12) -> 0 | X25: =SUM(X10:X12) -> 0 | Y25: =SUM(Y10:Y12) -> 24 | Z25: =SUM(Z10:Z12) -> 21 | ... AF25: =SUM(AF10:AF12) -> 822
B26: 11.00 - 11.15 | C26: 10 | D26: 3 | E26: 0 | F26: 10 | G26: 0 | H26: 0 | I26: 0 | J26: 0 | K26: 0 | L26: 0 | M26: 20 | N26: 0 | O26: =SUM(C26:L26,N26) -> 23 | P26: =SUM(C26:N26) -> 43 | R26: IP Period | S26: =SUM(S13:S18) -> 381 | T26: =SUM(T13:T18) -> 78 | U26: =SUM(U13:U18) -> 41 | V26: =SUM(V13:V18) -> 331 | W26: =SUM(W13:W18) -> 3 | X26: =SUM(X13:X18) -> 1 | Y26: =SUM(Y13:Y18) -> 50 | Z26: =SUM(Z13:Z18) -> 8 | ... AF26: =SUM(AF13:AF18) -> 1501
B27: 11.15 - 11.30 | C27: 24 | D27: 4 | E27: 3 | F27: 24 | G27: 0 | H27: 0 | I27: 1 | J27: 0 | K27: 0 | L27: 0 | M27: 40 | N27: 0 | O27: =SUM(C27:L27,N27) -> 56 | P27: =SUM(C27:N27) -> 96 | R27: PM Period | S27: =SUM(S19:S21) -> 339 | T27: =SUM(T19:T21) -> 37 | U27: =SUM(U19:U21) -> 41 | V27: =SUM(V19:V21) -> 190 | W27: =SUM(W19:W21) -> 3 | X27: =SUM(X19:X21) -> 0 | Y27: =SUM(Y19:Y21) -> 17 | Z27: =SUM(Z19:Z21) -> 5 | ... AF27: =SUM(AF19:AF21) -> 998
B28: 11.30 - 11.45 | C28: 15 | D28: 1 | E28: 5 | F28: 12 | G28: 0 | H28: 0 | I28: 1 | J28: 0 | K28: 0 | L28: 0 | M28: 19 | N28: 0 | O28: =SUM(C28:L28,N28) -> 34 | P28: =SUM(C28:N28) -> 53 | R28: 12 Hours | S28: =SUM(S10:S21) -> 951 | T28: =SUM(T10:T21) -> 132 | U28: =SUM(U10:U21) -> 108 | V28: =SUM(V10:V21) -> 775 | W28: =SUM(W10:W21) -> 6 | X28: =SUM(X10:X21) -> 1 | Y28: =SUM(Y10:Y21) -> 91 | Z28: =SUM(Z10:Z21) -> 34 | ... AF28: =SUM(AF10:AF21) -> 3321
B29: 11.45 - 12.00 | C29: 2 | D29: 0 | E29: 0 | F29: 3 | G29: 0 | H29: 0 | I29: 0 | J29: 0 | K29: 0 | L29: 0 | M29: 4 | N29: 0 | O29: =SUM(C29:L29,N29) -> 5 | P29: =SUM(C29:N29) -> 9
B30: 12.00 - 12.15 | C30: 10 | D30: 1 | E30: 2 | F30: 14 | G30: 0 | H30: 0 | I30: 3 | J30: 0 | K30: 0 | L30: 0 | M30: 13 | N30: 0 | O30: =SUM(C30:L30,N30) -> 30 | P30: =SUM(C30:N30) -> 43
B31: 12.15 - 12.30 | C31: 13 | D31: 5 | E31: 5 | F31: 9 | G31: 0 | H31: 0 | I31: 4 | J31: 0 | K31: 0 | L31: 0 | M31: 23 | N31: 0 | O31: =SUM(C31:L31,N31) -> 36 | P31: =SUM(C31:N31) -> 59
B32: 12.30 - 12.45 | C32: 24 | D32: 6 | E32: 3 | F32: 14 | G32: 1 | H32: 0 | I32: 0 | J32: 0 | K32: 0 | L32: 0 | M32: 33 | N32: 0 | O32: =SUM(C32:L32,N32) -> 48 | P32: =SUM(C32:N32) -> 81
B33: 12.45 - 13.00 | C33: 14 | D33: 2 | E33: 1 | F33: 8 | G33: 1 | H33: 0 | I33: 3 | J33: 0 | K33: 0 | L33: 0 | M33: 24 | N33: 0 | O33: =SUM(C33:L33,N33) -> 29 | P33: =SUM(C33:N33) -> 53
B34: 13.00 - 13.15 | C34: 19 | D34: 6 | E34: 2 | F34: 22 | G34: 1 | H34: 1 | I34: 9 | J34: 0 | K34: 0 | L34: 0 | M34: 23 | N34: 0 | O34: =SUM(C34:L34,N34) -> 60 | P34: =SUM(C34:N34) -> 83
B35: 13.15 - 13.30 | C35: 13 | D35: 2 | E35: 4 | F35: 10 | G35: 0 | H35: 0 | I35: 2 | J35: 0 | K35: 0 | L35: 0 | M35: 39 | N35: 0 | O35: =SUM(C35:L35,N35) -> 31 | P35: =SUM(C35:N35) -> 70
B36: 13.30 - 13.45 | C36: 10 | D36: 5 | E36: 0 | F36: 14 | G36: 0 | H36: 0 | I36: 3 | J36: 0 | K36: 0 | L36: 0 | M36: 18 | N36: 0 | O36: =SUM(C36:L36,N36) -> 32 | P36: =SUM(C36:N36) -> 50
B37: 13.45 - 14.00 | C37: 16 | D37: 1 | E37: 0 | F37: 6 | G37: 0 | H37: 0 | I37: 4 | J37: 0 | K37: 0 | L37: 0 | M37: 35 | N37: 0 | O37: =SUM(C37:L37,N37) -> 27 | P37: =SUM(C37:N37) -> 62
B38: 14.00 - 14.15 | C38: 13 | D38: 1 | E38: 1 | F38: 10 | G38: 0 | H38: 0 | I38: 3 | J38: 0 | K38: 0 | L38: 0 | M38: 26 | N38: 0 | O38: =SUM(C38:L38,N38) -> 28 | P38: =SUM(C38:N38) -> 54
B39: 14.15 - 14.30 | C39: 16 | D39: 0 | E39: 1 | F39: 7 | G39: 0 | H39: 0 | I39: 1 | J39: 0 | K39: 0 | L39: 0 | M39: 13 | N39: 0 | O39: =SUM(C39:L39,N39) -> 25 | P39: =SUM(C39:N39) -> 38
B40: 14.30 - 14.45 | C40: 13 | D40: 2 | E40: 3 | F40: 22 | G40: 0 | H40: 0 | I40: 0 | J40: 0 | K40: 0 | L40: 0 | M40: 47 | N40: 0 | O40: =SUM(C40:L40,N40) -> 40 | P40: =SUM(C40:N40) -> 87
... B43: 15.15 - 15.30 | C43: 27 | D43: 14 | E43: 0 | F43: 13 | G43: 0 | H43: 0 | I43: 1 | J43: 2 | K43: 0 | L43: 0 | M43: 39 | N43: 0 | O43: =SUM(C43:L43,N43) -> 57 | P43: =SUM(C43:N43) -> 96
B44: 15.30 - 15.45 | C44: P | D44: 6 | E44: 2 | F44: 29 | G44: 0 | H44: 0 | I44: 3 | J44: 0 | K44: 0 | L44: 0 | M44: 39 | N44: 0 | O44: =SUM(C44:L44,N44) -> 40 | P44: =SUM(C44:N44) -> 79
...

Sheet 24.09 MUNYONYO-SALAMA
B1: Consultancy services for Preparation of Expressway Development Master Plan (EDMP) for Uganda
B2: MANUAL CLASSIFIED COUNT (MCC)
B3: ROAD NAME: | C3: ='24.09 SALAMA-MUNYONYO'!C3:G3 -> MCC-C2-STN51-SALAMA ROAD
C5: Date | D5: ='[1]24.09.2019 SALAAMA-MUNYONYO'!D5 -> 24.09.19 | F5: Location | G5: ='[1]24.09.2019 SALAAMA-MUNYONYO'!G5:H5 -> MUNYONYO PS | J5: Surveyor | K5: OLOYA FELIX
C6: Dir. From | D6: MUNYONYO | F6: Dir. To | G6: SALAAMA | J6: Supervisor | K6: ='[1]24.09.2019 SALAAMA-MUNYONYO'!K6:L6 -> STEVEN
B8: Time / Veh Type | R8: SUMMARY TRAFFIC VOLUMES
C9: 1. Car | D9: 2. Station Wagon | E9: 3. Pickups | F9: 4. Minibus, matatu | G9: 5. Medium bus | H9: 6. Large Bus | I9: 7. Light Truck | J9: 8. Medium Truck | K9: 9. Heavy truck | L9: 10. Truck Trailer | M9: 11. Motor cycles | N9: 12. Tractors | O9: Total Excl M/Cycles | P9: Total All | R9: Time | S9: 1. Car | T9: 2. Station Wagon | U9: 3. Pickups | V9: 4. Minibus, matatu | W9: 5. Medium bus | X9: 6. Large Bus | Y9: 7. Light Truck | Z9: 8. Medium Truck | AA9: 9. Heavy truck | AB9: 10. Truck Trailer | AC9: 11. Motorcycles | AD9: 12. Tractors, Graders | AE9: Total Excl M/ Cycles | AF9: Total All
B10: 07.00 - 07.15 | C10: 43 | D10: 3 | E10: 4 | F10: 0 | G10: 2 | H10: 0 | I10: 2 | J10: 0 | K10: 0 | L10: 0 | M10: 59 | N10: 0 | O10: =SUM(C10:L10,N10) -> 54 | P10: =SUM(C10:N10) -> 113 | R10: 0700-0800 | S10: =SUM(C10:C13) -> 184 | T10: =SUM(D10:D13) -> 41 | U10: =SUM(E10:E13) -> 16 | V10: =SUM(F10:F13) -> 63 | W10: =SUM(G10:G13) -> 2 | X10: =SUM(H10:H13) -> 1 | Y10: =SUM(I10:I13) -> 12 | Z10: =SUM(J10:J13) -> 1 | ... AF10: =SUM(P10:P13) -> 530
B11: 07.15 - 07.30 | C11: 55 | D11: 17 | E11: 6 | F11: 24 | G11: 0 | H11: 0 | I11: 1 | J11: 0 | K11: 0 | L11: 0 | M11: 56 | N11: 0 | O11: =SUM(C11:L11,N11) -> 103 | P11: =SUM(C11:N11) -> 159 | R11: 0800-0900 | S11: =SUM(C14:C17) -> 130 | T11: =SUM(D14:D17) -> 35 | U11: =SUM(E14:E17) -> 14 | V11: =SUM(F14:F17) -> 95 | W11: =SUM(G14:G17) -> 2 | X11: =SUM(H14:H17) -> 0 | Y11: =SUM(I14:I17) -> 15 | Z11: =SUM(J14:J17) -> 0 | ... AF11: =SUM(P14:P17) -> 543
B12: 07.30 - 07.45 | C12: 44 | D12: 11 | E12: 4 | F12: 14 | G12: 0 | H12: 1 | I12: 2 | J12: 1 | K12: 0 | L12: 1 | M12: 45 | N12: 0 | O12: =SUM(C12:L12,N12) -> 78 | P12: =SUM(C12:N12) -> 123 | R12: 0900-1000 | S12: =SUM(C18:C21) -> 83 | T12: =SUM(D18:D21) -> 18 | U12: =SUM(E18:E21) -> 12 | V12: =SUM(F18:F21) -> 65 | W12: =SUM(G18:G21) -> 0 | X12: =SUM(H18:H21) -> 0 | Y12: =SUM(I18:I21) -> 6 | Z12: =SUM(J18:J21) -> 0 | ... AF12: =SUM(P18:P21) -> 363
B13: 07.45 - 08.00 | C13: 42 | D13: 10 | E13: 2 | F13: 25 | G13: 0 | H13: 0 | I13: 7 | J13: 0 | K13: 0 | L13: 0 | M13: 49 | N13: 0 | O13: =SUM(C13:L13,N13) -> 86 | P13: =SUM(C13:N13) -> 135 | R13: 1000-1100 | S13: =SUM(C22:C25) -> 82 | T13: =SUM(D22:D25) -> 22 | U13: =SUM(E22:E25) -> 8 | V13: =SUM(F22:F25) -> 54 | W13: =SUM(G22:G25) -> 2 | X13: =SUM(H22:H25) -> 0 | Y13: =SUM(I22:I25) -> 14 | Z13: =SUM(J22:J25) -> 1 | ... AF13: =SUM(P22:P25) -> 369
B14: 08.00 - 08.15 | C14: 24 | D14: 13 | E14: 3 | F14: 35 | G14: 0 | H14: 0 | I14: 3 | J14: 0 | K14: 1 | L14: 0 | M14: 65 | N14: 0 | O14: =SUM(C14:L14,N14) -> 79 | P14: =SUM(C14:N14) -> 144 | R14: 1100-1200 | S14: =SUM(C26:C29) -> 62 | T14: =SUM(D26:D29) -> 26 | U14: =SUM(E26:E29) -> 18 | V14: =SUM(F26:F29) -> 40 | W14: =SUM(G26:G29) -> 0 | X14: =SUM(H26:H29) -> 0 | Y14: =SUM(I26:I29) -> 16 | Z14: =SUM(J26:J29) -> 0 | ... AF14: =SUM(P26:P29) -> 337
B15: 08.15 - 08.30 | C15: 38 | D15: 8 | E15: 3 | F15: 20 | G15: 0 | H15: 0 | I15: 5 | J15: 0 | K15: 0 | L15: 0 | M15: 62 | N15: 0 | O15: =SUM(C15:L15,N15) -> 74 | P15: =SUM(C15:N15) -> 136 | R15: 1200-1300 | S15: =SUM(C30:C33) -> 67 | T15: =SUM(D30:D33) -> 21 | U15: =SUM(E30:E33) -> 10 | V15: =SUM(F30:F33) -> 46 | W15: =SUM(G30:G33) -> 0 | X15: =SUM(H30:H33) -> 0 | Y15: =SUM(I30:I33) -> 13 | Z15: =SUM(J30:J33) -> 1 | ... AF15: =SUM(P30:P33) -> 310
B16: 08.30 - 08.45 | C16: 39 | D16: 6 | E16: 4 | F16: 15 | G16: 2 | H16: 0 | I16: 4 | J16: 0 | K16: 0 | L16: 0 | M16: 63 | N16: 0 | O16: =SUM(C16:L16,N16) -> 70 | P16: =SUM(C16:N16) -> 133 | R16: 1300-1400 | S16: =SUM(C34:C37) -> 69 | T16: =SUM(D34:D37) -> 25 | U16: =SUM(E34:E37) -> 11 | V16: =SUM(F34:F37) -> 48 | W16: =SUM(G34:G37) -> 1 | X16: =SUM(H34:H37) -> 0 | Y16: =SUM(I34:I37) -> 14 | Z16: =SUM(J34:J37) -> 3 | ... AF16: =SUM(P34:P37) -> 325
B17: 08.45 - 9.00 | C17: 29 | D17: 8 | E17: 4 | F17: 25 | G17: 0 | H17: 0 | I17: 3 | J17: 0 | K17: 0 | L17: 0 | M17: 61 | N17: 0 | O17: =SUM(C17:L17,N17) -> 69 | P17: =SUM(C17:N17) -> 130 | R17: 1400-1500 | S17: =SUM(C38:C41) -> 65 | T17: =SUM(D38:D41) -> 24 | U17: =SUM(E38:E41) -> 16 | V17: =SUM(F38:F41) -> 46 | W17: =SUM(G38:G41) -> 0 | X17: =SUM(H38:H41) -> 0 | Y17: =SUM(I38:I41) -> 13 | Z17: =SUM(J38:J41) -> 1 | ... AF17: =SUM(P38:P41) -> 303
B18: 09.00 - 09.15 | C18: 21 | D18: 5 | E18: 2 | F18: 11 | G18: 0 | H18: 0 | I18: 3 | J18: 0 | K18: 0 | L18: 0 | M18: 36 | N18: 0 | O18: =SUM(C18:L18,N18) -> 42 | P18: =SUM(C18:N18) -> 78 | R18: 1500-1600 | S18: =SUM(C42:C45) -> 64 | T18: =SUM(D42:D45) -> 22 | U18: =SUM(E42:E45) -> 5 | V18: =SUM(F42:F45) -> 57 | W18: =SUM(G42:G45) -> 0 | X18: =SUM(H42:H45) -> 0 | Y18: =SUM(I42:I45) -> 5 | Z18: =SUM(J42:J45) -> 4 | ... AF18: =SUM(P42:P45) -> 286
B19: 09.15 - 09.30 | C19: 25 | D19: 2 | E19: 2 | F19: 19 | G19: 0 | H19: 0 | I19: 1 | J19: 0 | K19: 0 | L19: 0 | M19: 50 | N19: 0 | O19: =SUM(C19:L19,N19) -> 49 | P19: =SUM(C19:N19) -> 99 | R19: 1600-1700 | S19: =SUM(C46:C49) -> 105 | T19: =SUM(D46:D49) -> 25 | U19: =SUM(E46:E49) -> 13 | V19: =SUM(F46:F49) -> 64 | W19: =SUM(G46:G49) -> 0 | X19: =SUM(H46:H49) -> 0 | Y19: =SUM(I46:I49) -> 14 | Z19: =SUM(J46:J49) -> 0 | ... AF19: =SUM(P46:P49) -> 350
B20: 09.30 - 09.45 | C20: 15 | D20: 5 | E20: 3 | F20: 20 | G20: 0 | H20: 0 | I20: 1 | J20: 0 | K20: 0 | L20: 0 | M20: 47 | N20: 0 | O20: =SUM(C20:L20,N20) -> 44 | P20: =SUM(C20:N20) -> 91 | R20: 1700-1800 | S20: =SUM(C50:C53) -> 99 | T20: =SUM(D50:D53) -> 37 | U20: =SUM(E50:E53) -> 14 | V20: =SUM(F50:F53) -> 73 | W20: =SUM(G50:G53) -> 3 | X20: =SUM(H50:H53) -> 1 | Y20: =SUM(I50:I53) -> 16 | Z20: =SUM(J50:J53) -> 1 | ... AF20: =SUM(P50:P53) -> 404
B21: 09.45 - 10.00 | C21: 22 | D21: 6 | E21: 5 | F21: 15 | G21: 0 | H21: 0 | I21: 1 | J21: 0 | K21: 0 | L21: 0 | M21: 46 | N21: 0 | O21: =SUM(C21:L21,N21) -> 49 | P21: =SUM(C21:N21) -> 95 | R21: 1800-1900 | S21: =SUM(C54:C57) -> 108 | T21: =SUM(D54:D57) -> 30 | U21: =SUM(E54:E57) -> 16 | V21: =SUM(F54:F57) -> 83 | W21: =SUM(G54:G57) -> 2 | X21: =SUM(H54:H57) -> 0 | Y21: =SUM(I54:I57) -> 12 | Z21: =SUM(J54:J57) -> 0 | ... AF21: =SUM(P54:P57) -> 422
B22: 10.00 - 10.15 | C22: 26 | D22: 8 | E22: 4 | F22: 18 | G22: 0 | H22: 0 | I22: 1 | J22: 0 | K22: 0 | L22: 0 | M22: 57 | N22: 0 | O22: =SUM(C22:L22,N22) -> 57 | P22: =SUM(C22:N22) -> 114 | R22: AM Peak Hr | S22: =MAX(S10:S12) -> 184 | T22: =MAX(T10:T12) -> 41 | U22: =MAX(U10:U12) -> 16 | V22: =MAX(V10:V12) -> 95 | W22: =MAX(W10:W12) -> 2 | X22: =MAX(X10:X12) -> 1 | Y22: =MAX(Y10:Y12) -> 15 | Z22: =MAX(Z10:Z12) -> 1 | ... AF22: =MAX(AF10:AF12) -> 543
B23: 10.15 - 10.30 | C23: 18 | D23: 3 | E23: 3 | F23: 16 | G23: 1 | H23: 0 | I23: 3 | J23: 0 | K23: 0 | L23: 0 | M23: 36 | N23: 0 | O23: =SUM(C23:L23,N23) -> 44 | P23: =SUM(C23:N23) -> 80 | R23: IP Peak Hr | S23: =MAX(S13:S18) -> 82 | T23: =MAX(T13:T18) -> 26 | U23: =MAX(U13:U18) -> 18 | V23: =MAX(V13:V18) -> 57 | W23: =MAX(W13:W18) -> 2 | X23: =MAX(X13:X18) -> 0 | Y23: =MAX(Y13:Y18) -> 16 | Z23: =MAX(Z13:Z18) -> 4 | ... AF23: =MAX(AF13:AF18) -> 369
B24: 10.30 - 10.45 | C24: 20 | D24: 6 | E24: 0 | F24: 6 | G24: 0 | H24: 0 | I24: 5 | J24: 1 | K24: 0 | L24: 0 | M24: 46 | N24: 0 | O24: =SUM(C24:L24,N24) -> 38 | P24: =SUM(C24:N24) -> 84 | R24: PM Peak Hr | S24: =MAX(S19:S21) -> 108 | T24: =MAX(T19:T21) -> 37 | U24: =MAX(U19:U21) -> 16 | V24: =MAX(V19:V21) -> 83 | W24: =MAX(W19:W21) -> 3 | X24: =MAX(X19:X21) -> 1 | Y24: =MAX(Y19:Y21) -> 16 | Z24: =MAX(Z19:Z21) -> 1 | ... AF24: =MAX(AF19:AF21) -> 422
B25: 10.45 - 11.00 | C25: 18 | D25: 5 | E25: 1 | F25: 14 | G25: 1 | H25: 0 | I25: 5 | J25: 0 | K25: 1 | L25: 0 | M25: 46 | N25: 0 | O25: =SUM(C25:L25,N25) -> 45 | P25: =SUM(C25:N25) -> 91 | R25: AM Period | S25: =SUM(S10:S12) -> 397 | T25: =SUM(T10:T12) -> 94 | U25: =SUM(U10:U12) -> 42 | V25: =SUM(V10:V12) -> 223 | W25: =SUM(W10:W12) -> 4 | X25: =SUM(X10:X12) -> 1 | Y25: =SUM(Y10:Y12) -> 33 | Z25: =SUM(Z10:Z12) -> 1 | ... AF25: =SUM(AF10:AF12) -> 1436
B26: 11.00 - 11.15 | C26: 13 | D26: 8 | E26: 7 | F26: 9 | G26: 0 | H26: 0 | I26: 6 | J26: 0 | K26: 0 | L26: 0 | M26: 51 | N26: 0 | O26: =SUM(C26:L26,N26) -> 43 | P26: =SUM(C26:N26) -> 94 | R26: IP Period | S26: =SUM(S13:S18) -> 409 | T26: =SUM(T13:T18) -> 140 | U26: =SUM(U13:U18) -> 68 | V26: =SUM(V13:V18) -> 291 | W26: =SUM(W13:W18) -> 3 | X26: =SUM(X13:X18) -> 0 | Y26: =SUM(Y13:Y18) -> 75 | Z26: =SUM(Z13:Z18) -> 10 | ... AF26: =SUM(AF13:AF18) -> 1930
B27: 11.15 - 11.30 | C27: 22 | D27: 7 | E27: 4 | F27: 11 | G27: 0 | H27: 0 | I27: 5 | J27: 0 | K27: 0 | L27: 0 | M27: 32 | N27: 0 | O27: =SUM(C27:L27,N27) -> 49 | P27: =SUM(C27:N27) -> 81 | R27: PM Period | S27: =SUM(S19:S21) -> 312 | T27: =SUM(T19:T21) -> 92 | U27: =SUM(U19:U21) -> 43 | V27: =SUM(V19:V21) -> 220 | W27: =SUM(W19:W21) -> 5 | X27: =SUM(X19:X21) -> 1 | Y27: =SUM(Y19:Y21) -> 42 | Z27: =SUM(Z19:Z21) -> 1 | ... AF27: =SUM(AF19:AF21) -> 1176
B28: 11.30 - 11.45 | C28: 8 | D28: 7 | E28: 2 | F28: 12 | G28: 0 | H28: 0 | I28: 2 | J28: 0 | K28: 0 | L28: 0 | M28: 46 | N28: 0 | O28: =SUM(C28:L28,N28) -> 31 | P28: =SUM(C28:N28) -> 77 | R28: 12 Hours | S28: =SUM(S10:S21) -> 1118 | T28: =SUM(T10:T21) -> 326 | U28: =SUM(U10:U21) -> 153 | V28: =SUM(V10:V21) -> 734 | W28: =SUM(W10:W21) -> 12 | X28: =SUM(X10:X21) -> 2 | Y28: =SUM(Y10:Y21) -> 150 | Z28: =SUM(Z10:Z21) -> 12 | ... AF28: =SUM(AF10:AF21) -> 4542
B29: 11.45 - 12.00 | C29: 19 | D29: 4 | E29: 5 | F29: 8 | G29: 0 | H29: 0 | I29: 3 | J29: 0 | K29: 0 | L29: 0 | M29: 46 | N29: 0 | O29: =SUM(C29:L29,N29) -> 39 | P29: =SUM(C29:N29) -> 85
B30: 12.00 - 12.15 | C30: 12 | D30: 2 | E30: 2 | F30: 16 | G30: 0 | H30: 0 | I30: 3 | J30: 0 | K30: 0 | L30: 0 | M30: 22 | N30: 0 | O30: =SUM(C30:L30,N30) -> 35 | P30: =SUM(C30:N30) -> 57
B31: 12.15 - 12.30 | C31: 13 | D31: 4 | E31: 1 | F31: 13 | G31: 0 | H31: 0 | I31: 4 | J31: 1 | K31: 0 | L31: 0 | M31: 42 | N31: 0 | O31: =SUM(C31:L31,N31) -> 36 | P31: =SUM(C31:N31) -> 78
B32: 12.30 - 12.45 | C32: 29 | D32: 10 | E32: 3 | F32: 11 | G32: 0 | H32: 0 | I32: 2 | J32: 0 | K32: 1 | L32: 0 | M32: 43 | N32: 0 | O32: =SUM(C32:L32,N32) -> 56 | P32: =SUM(C32:N32) -> 99
B33: 12.45 - 13.00 | C33: 13 | D33: 5 | E33: 4 | F33: 6 | G33: 0 | H33: 0 | I33: 4 | J33: 0 | K33: 0 | L33: 0 | M33: 44 | N33: 0 | O33: =SUM(C33:L33,N33) -> 32 | P33: =SUM(C33:N33) -> 76
B34: 13.00 - 13.15 | C34: 19 | D34: 5 | E34: 2 | F34: 14 | G34: 1 | H34: 0 | I34: 3 | J34: 1 | K34: 0 | L34: 0 | M34: 38 | N34: 0 | O34: =SUM(C34:L34,N34) -> 45 | P34: =SUM(C34:N34) -> 83
B35: 13.15 - 13.30 | C35: 16 | D35: 9 | E35: 3 | F35: 12 | G35: 0 | H35: 0 | I35: 4 | J35: 2 | K35: 0 | L35: 1 | M35: 41 | N35: 0 | O35: =SUM(C35:L35,N35) -> 47 | P35: =SUM(C35:N35) -> 88
B36: 13.30 - 13.45 | C36: 12 | D36: 4 | E36: 2 | F36: 12 | G36: 0 | H36: 0 | I36: 3 | J36: 0 | K36: 0 | L36: 0 | M36: 32 | N36: 0 | O36: =SUM(C36:L36,N36) -> 33 | P36: =SUM(C36:N36) -> 65
B37: 13.45 - 14.00 | C37: 22 | D37: 7 | E37: 4 | F37: 10 | G37: 0 | H37: 0 | I37: 4 | J37: 0 | K37: 0 | L37: 0 | M37: 42 | N37: 0 | O37: =SUM(C37:L37,N37) -> 47 | P37: =SUM(C37:N37) -> 89
B38: 14.00 - 14.15 | C38: 16 | D38: 2 | E38: 0 | F38: 15 | G38: 0 | H38: 0 | I38: 3 | J38: 0 | K38: 0 | L38: 0 | M38: 36 | N38: 0 | O38: =SUM(C38:L38,N38) -> 36 | P38: =SUM(C38:N38) -> 72
B39: 14.15 - 14.30 | C39: 15 | D39: 3 | E39: 6 | F39: 8 | G39: 0 | H39: 0 | I39: 5 | J39: 1 | K39: 0 | L39: 0 | M39: 27 | N39: 0 | O39: =SUM(C39:L39,N39) -> 38 | P39: =SUM(C39:N39) -> 65
B40: 14.30 - 14.45 | C40: 13 | D40: 8 | E40: 2 | F40: 10 | G40: 0 | H40: 0 | I40: 4 | J40: 0 | K40: 0 | L40: 0 | M40: 44 | N40: 0 | O40: =SUM(C40:L40,N40) -> 37 | P40: =SUM(C40:N40) -> 81
... B57: 18.45 - 19.00 | C57: 20 | D57: 6 | E57: 8 | F57: 18 | G57: 0 | H57: 0 | I57: 2 | J57: 0 | K57: 1 | L57: 0 | M57: 43 | N57: 0 | O57: =SUM(C57:L57,N57) -> 55 | P57: =SUM(C57:N57) -> 98
B58: Totals | C58: =SUM(C10:C57) -> 1118 | D58: =SUM(D10:D57) -> 326 | E58: =SUM(E10:E57) -> 153 | F58: =SUM(F10:F57) -> 734 | G58: =SUM(G10:G57) -> 12 | H58: =SUM(H10:H57) -> 2 | I58: =SUM(I10:I57) -> 150 | J58: =SUM(J10:J57) -> 12 | ... P58: =SUM(P10:P57) -> 4542
...

Sheet 25.09 SALAMA-MUNYONYO
B1: Consultancy services for Preparation of Expressway Development Master Plan (EDMP) for Uganda
B2: MANUAL CLASSIFIED COUNT (MCC)
B3: ROAD NAME: | C3: ='23.9.19 SALAMA - MUNYONYO'!C3:G3 -> MCC - C2 - STN-51 - SALAMA ROAD
C5: Date | D5: 25.09.19 | F5: Location | G5: ='23.9.19 SALAMA - MUNYONYO'!G5:H5 -> MUNYONYO P/S | J5: Surveyor | K5: ='23.9.19 SALAMA - MUNYONYO'!K5:L5 -> KENNETH
C6: Dir. From | D6: ='23.9.19 SALAMA - MUNYONYO'!D6:E6 -> SALAMA | F6: Dir. To | G6: ='23.9.19 SALAMA - MUNYONYO'!G6:H6 -> MUNYONYO | J6: Supervisor | K6: ='23.9.19 SALAMA - MUNYONYO'!K6:L6 -> STEVEN
B8: Time / Veh Type | R8: SUMMARY TRAFFIC VOLUMES
C9: 1. Car | D9: 2. Station Wagon | E9: 3. Pickups | F9: 4. Minibus, matatu | G9: 5. Medium bus | H9: 6. Large Bus | I9: 7. Light Truck | J9: 8. Medium Truck | K9: 9. Heavy truck | L9: 10. Truck Trailer | M9: 11. Motor cycles | N9: 12. Tractors | O9: Total Excl M/Cycles | P9: Total All | R9: Time | S9: 1. Car | T9: 2. Station Wagon | U9: 3. Pickups | V9: 4. Minibus, matatu | W9: 5. Medium bus | X9: 6. Large Bus | Y9: 7. Light Truck | Z9: 8. Medium Truck | AA9: 9. Heavy truck | AB9: 10. Truck Trailer | AC9: 11. Motorcycles | AD9: 12. Tractors, Graders | AE9: Total Excl M/ Cycles | AF9: Total All
B10: 07.00 - 07.15 | C10: 25 | D10: 4 | E10: 5 | F10: 19 | G10: 0 | H10: 0 | I10: 1 | J10: 0 | K10: 0 | L10: 0 | M10: 29 | N10: 0 | O10: =SUM(C10:L10,N10) -> 54 | P10: =SUM(C10:N10) -> 83 | R10: 0700-0800 | S10: =SUM(C10:C13) -> 73 | T10: =SUM(D10:D13) -> 8 | U10: =SUM(E10:E13) -> 7 | V10: =SUM(F10:F13) -> 69 | W10: =SUM(G10:G13) -> 0 | X10: =SUM(H10:H13) -> 0 | Y10: =SUM(I10:I13) -> 15 | Z10: =SUM(J10:J13) -> 0 | ... AF10: =SUM(P10:P13) -> 269
B11: 07.15 - 07.30 | C11: 13 | D11: 2 | E11: 0 | F11: 17 | G11: 0 | H11: 0 | I11: 7 | J11: 0 | K11: 0 | L11: 0 | M11: 23 | N11: 0 | O11: =SUM(C11:L11,N11) -> 39 | P11: =SUM(C11:N11) -> 62 | R11: 0800-0900 | S11: =SUM(C14:C17) -> 88 | T11: =SUM(D14:D17) -> 14 | U11: =SUM(E14:E17) -> 8 | V11: =SUM(F14:F17) -> 59 | W11: =SUM(G14:G17) -> 1 | X11: =SUM(H14:H17) -> 0 | Y11: =SUM(I14:I17) -> 12 | Z11: =SUM(J14:J17) -> 2 | ... AF11: =SUM(P14:P17) -> 319
B12: 07.30 - 07.45 | C12: 19 | D12: 1 | E12: 1 | F12: 23 | G12: 0 | H12: 0 | I12: 2 | J12: 0 | K12: 0 | L12: 0 | M12: 27 | N12: 0 | O12: =SUM(C12:L12,N12) -> 46 | P12: =SUM(C12:N12) -> 73 | R12: 0900-1000 | S12: =SUM(C18:C21) -> 63 | T12: =SUM(D18:D21) -> 9 | U12: =SUM(E18:E21) -> 8 | V12: =SUM(F18:F21) -> 73 | W12: =SUM(G18:G21) -> 0 | X12: =SUM(H18:H21) -> 0 | Y12: =SUM(I18:I21) -> 4 | Z12: =SUM(J18:J21) -> 6 | ... AF12: =SUM(P18:P21) -> 291
B13: 07.45 - 08.00 | C13: 16 | D13: 1 | E13: 1 | F13: 10 | G13: 0 | H13: 0 | I13: 5 | J13: 0 | K13: 0 | L13: 0 | M13: 18 | N13: 0 | O13: =SUM(C13:L13,N13) -> 33 | P13: =SUM(C13:N13) -> 51 | R13: 1000-1100 | S13: =SUM(C22:C25) -> 77 | T13: =SUM(D22:D25) -> 7 | U13: =SUM(E22:E25) -> 8 | V13: =SUM(F22:F25) -> 59 | W13: =SUM(G22:G25) -> 0 | X13: =SUM(H22:H25) -> 0 | Y13: =SUM(I22:I25) -> 6 | Z13: =SUM(J22:J25) -> 0 | ... AF13: =SUM(P22:P25) -> 282
B14: 08.00 - 08.15 | C14: 30 | D14: 3 | E14: 1 | F14: 6 | G14: 0 | H14: 0 | I14: 6 | J14: 1 | K14: 0 | L14: 0 | M14: 37 | N14: 0 | O14: =SUM(C14:L14,N14) -> 47 | P14: =SUM(C14:N14) -> 84 | R14: 1100-1200 | S14: =SUM(C26:C29) -> 47 | T14: =SUM(D26:D29) -> 5 | U14: =SUM(E26:E29) -> 8 | V14: =SUM(F26:F29) -> 53 | W14: =SUM(G26:G29) -> 0 | X14: =SUM(H26:H29) -> 0 | Y14: =SUM(I26:I29) -> 13 | Z14: =SUM(J26:J29) -> 5 | ... AF14: =SUM(P26:P29) -> 272
B15: 08.15 - 08.30 | C15: 21 | D15: 5 | E15: 1 | F15: 9 | G15: 1 | H15: 0 | I15: 1 | J15: 1 | K15: 0 | L15: 0 | M15: 35 | N15: 0 | O15: =SUM(C15:L15,N15) -> 39 | P15: =SUM(C15:N15) -> 74 | R15: 1200-1300 | S15: =SUM(C30:C33) -> 80 | T15: =SUM(D30:D33) -> 6 | U15: =SUM(E30:E33) -> 5 | V15: =SUM(F30:F33) -> 66 | W15: =SUM(G30:G33) -> 3 | X15: =SUM(H30:H33) -> 0 | Y15: =SUM(I30:I33) -> 10 | Z15: =SUM(J30:J33) -> 3 | ... AF15: =SUM(P30:P33) -> 296
B16: 08.30 - 08.45 | C16: 17 | D16: 3 | E16: 4 | F16: 21 | G16: 0 | H16: 0 | I16: 3 | J16: 0 | K16: 0 | L16: 0 | M16: 34 | N16: 0 | O16: =SUM(C16:L16,N16) -> 48 | P16: =SUM(C16:N16) -> 82 | R16: 1300-1400 | S16: =SUM(C34:C37) -> 70 | T16: =SUM(D34:D37) -> 8 | U16: =SUM(E34:E37) -> 12 | V16: =SUM(F34:F37) -> 66 | W16: =SUM(G34:G37) -> 2 | X16: =SUM(H34:H37) -> 0 | Y16: =SUM(I34:I37) -> 14 | Z16: =SUM(J34:J37) -> 2 | ... AF16: =SUM(P34:P37) -> 304
B17: 08.45 - 9.00 | C17: 20 | D17: 3 | E17: 2 | F17: 23 | G17: 0 | H17: 0 | I17: 2 | J17: 0 | K17: 0 | L17: 0 | M17: 29 | N17: 0 | O17: =SUM(C17:L17,N17) -> 50 | P17: =SUM(C17:N17) -> 79 | R17: 1400-1500 | S17: =SUM(C38:C41) -> 81 | T17: =SUM(D38:D41) -> 17 | U17: =SUM(E38:E41) -> 3 | V17: =SUM(F38:F41) -> 48 | W17: =SUM(G38:G41) -> 0 | X17: =SUM(H38:H41) -> 0 | Y17: =SUM(I38:I41) -> 13 | Z17: =SUM(J38:J41) -> 4 | ... AF17: =SUM(P38:P41) -> 296
B18: 09.00 - 09.15 | C18: 13 | D18: 3 | E18: 2 | F18: 21 | G18: 0 | H18: 0 | I18: 0 | J18: 1 | K18: 0 | L18: 0 | M18: 39 | N18: 0 | O18: =SUM(C18:L18,N18) -> 40 | P18: =SUM(C18:N18) -> 79 | R18: 1500-1600 | S18: =SUM(C42:C45) -> 90 | T18: =SUM(D42:D45) -> 10 | U18: =SUM(E42:E45) -> 6 | V18: =SUM(F42:F45) -> 57 | W18: =SUM(G42:G45) -> 0 | X18: =SUM(H42:H45) -> 0 | Y18: =SUM(I42:I45) -> 16 | Z18: =SUM(J42:J45) -> 0 | ... AF18: =SUM(P42:P45) -> 376
B19: 09.15 - 09.30 | C19: 18 | D19: 6 | E19: 2 | F19: 24 | G19: 0 | H19: 0 | I19: 1 | J19: 1 | K19: 0 | L19: 0 | M19: 43 | N19: 0 | O19: =SUM(C19:L19,N19) -> 52 | P19: =SUM(C19:N19) -> 95 | R19: 1600-1700 | S19: =SUM(C46:C49) -> 163 | T19: =SUM(D46:D49) -> 16 | U19: =SUM(E46:E49) -> 9 | V19: =SUM(F46:F49) -> 75 | W19: =SUM(G46:G49) -> 2 | X19: =SUM(H46:H49) -> 3 | Y19: =SUM(I46:I49) -> 12 | Z19: =SUM(J46:J49) -> 0 | ... AF19: =SUM(P46:P49) -> 472
B20: 09.30 - 09.45 | C20: 15 | D20: 0 | E20: 2 | F20: 15 | G20: 0 | H20: 0 | I20: 1 | J20: 1 | K20: 0 | L20: 0 | M20: 30 | N20: 0 | O20: =SUM(C20:L20,N20) -> 34 | P20: =SUM(C20:N20) -> 64 | R20: 1700-1800 | S20: =SUM(C50:C53) -> 118 | T20: =SUM(D50:D53) -> 25 | U20: =SUM(E50:E53) -> 9 | V20: =SUM(F50:F53) -> 83 | W20: =SUM(G50:G53) -> 2 | X20: =SUM(H50:H53) -> 0 | Y20: =SUM(I50:I53) -> 13 | Z20: =SUM(J50:J53) -> 7 | ... AF20: =SUM(P50:P53) -> 392
B21: 09.45 - 10.00 | C21: 17 | D21: 0 | E21: 2 | F21: 13 | G21: 0 | H21: 0 | I21: 2 | J21: 3 | K21: 0 | L21: 0 | M21: 16 | N21: 0 | O21: =SUM(C21:L21,N21) -> 37 | P21: =SUM(C21:N21) -> 53 | R21: 1800-1900 | S21: =SUM(C54:C57) -> 160 | T21: =SUM(D54:D57) -> 29 | U21: =SUM(E54:E57) -> 18 | V21: =SUM(F54:F57) -> 73 | W21: =SUM(G54:G57) -> 1 | X21: =SUM(H54:H57) -> 0 | Y21: =SUM(I54:I57) -> 10 | Z21: =SUM(J54:J57) -> 6 | ... AF21: =SUM(P54:P57) -> 421
B22: 10.00 - 10.15 | C22: 17 | D22: 1 | E22: 4 | F22: 17 | G22: 0 | H22: 0 | I22: 3 | J22: 0 | K22: 0 | L22: 0 | M22: 35 | N22: 0 | O22: =SUM(C22:L22,N22) -> 42 | P22: =SUM(C22:N22) -> 77 | R22: AM Peak Hr | S22: =MAX(S10:S12) -> 88 | T22: =MAX(T10:T12) -> 14 | U22: =MAX(U10:U12) -> 8 | V22: =MAX(V10:V12) -> 73 | W22: =MAX(W10:W12) -> 1 | X22: =MAX(X10:X12) -> 0 | Y22: =MAX(Y10:Y12) -> 15 | Z22: =MAX(Z10:Z12) -> 6 | ... AF22: =MAX(AF10:AF12) -> 319
B23: 10.15 - 10.30 | C23: 23 | D23: 2 | E23: 1 | F23: 20 | G23: 0 | H23: 0 | I23: 0 | J23: 0 | K23: 0 | L23: 0 | M23: 21 | N23: 0 | O23: =SUM(C23:L23,N23) -> 46 | P23: =SUM(C23:N23) -> 67 | R23: IP Peak Hr | S23: =MAX(S13:S18) -> 90 | T23: =MAX(T13:T18) -> 17 | U23: =MAX(U13:U18) -> 12 | V23: =MAX(V13:V18) -> 66 | W23: =MAX(W13:W18) -> 3 | X23: =MAX(X13:X18) -> 0 | Y23: =MAX(Y13:Y18) -> 16 | Z23: =MAX(Z13:Z18) -> 5 | ... AF23: =MAX(AF13:AF18) -> 376
B24: 10.30 - 10.45 | C24: 21 | D24: 1 | E24: 1 | F24: 14 | G24: 0 | H24: 0 | I24: 1 | J24: 0 | K24: 1 | L24: 0 | M24: 26 | N24: 0 | O24: =SUM(C24:L24,N24) -> 39 | P24: =SUM(C24:N24) -> 65 | R24: PM Peak Hr | S24: =MAX(S19:S21) -> 163 | T24: =MAX(T19:T21) -> 29 | U24: =MAX(U19:U21) -> 18 | V24: =MAX(V19:V21) -> 83 | W24: =MAX(W19:W21) -> 2 | X24: =MAX(X19:X21) -> 3 | Y24: =MAX(Y19:Y21) -> 13 | Z24: =MAX(Z19:Z21) -> 7 | ... AF24: =MAX(AF19:AF21) -> 472
B25: 10.45 - 11.00 | C25: 16 | D25: 3 | E25: 2 | F25: 8 | G25: 0 | H25: 0 | I25: 2 | J25: 0 | K25: 0 | L25: 0 | M25: 42 | N25: 0 | O25: =SUM(C25:L25,N25) -> 31 | P25: =SUM(C25:N25) -> 73 | R25: AM Period | S25: =SUM(S10:S12) -> 224 | T25: =SUM(T10:T12) -> 31 | U25: =SUM(U10:U12) -> 23 | V25: =SUM(V10:V12) -> 201 | W25: =SUM(W10:W12) -> 1 | X25: =SUM(X10:X12) -> 0 | Y25: =SUM(Y10:Y12) -> 31 | Z25: =SUM(Z10:Z12) -> 8 | ... AF25: =SUM(AF10:AF12) -> 879
B26: 11.00 - 11.15 | C26: 10 | D26: 1 | E26: 3 | F26: 15 | G26: 0 | H26: 0 | I26: 3 | J26: 0 | K26: 0 | L26: 0 | M26: 36 | N26: 0 | O26: =SUM(C26:L26,N26) -> 32 | P26: =SUM(C26:N26) -> 68 | R26: IP Period | S26: =SUM(S13:S18) -> 445 | T26: =SUM(T13:T18) -> 53 | U26: =SUM(U13:U18) -> 42 | V26: =SUM(V13:V18) -> 349 | W26: =SUM(W13:W18) -> 5 | X26: =SUM(X13:X18) -> 0 | Y26: =SUM(Y13:Y18) -> 72 | Z26: =SUM(Z13:Z18) -> 14 | ... AF26: =SUM(AF13:AF18) -> 1826
B27: 11.15 - 11.30 | C27: 13 | D27: 0 | E27: 2 | F27: 14 | G27: 0 | H27: 0 | I27: 2 | J27: 4 | K27: 0 | L27: 0 | M27: 44 | N27: 0 | O27: =SUM(C27:L27,N27) -> 35 | P27: =SUM(C27:N27) -> 79 | R27: PM Period | S27: =SUM(S19:S21) -> 441 | T27: =SUM(T19:T21) -> 70 | U27: =SUM(U19:U21) -> 36 | V27: =SUM(V19:V21) -> 231 | W27: =SUM(W19:W21) -> 5 | X27: =SUM(X19:X21) -> 3 | Y27: =SUM(Y19:Y21) -> 35 | Z27: =SUM(Z19:Z21) -> 13 | ... AF27: =SUM(AF19:AF21) -> 1285
B28: 11.30 - 11.45 | C28: 10 | D28: 4 | E28: 1 | F28: 9 | G28: 0 | H28: 0 | I28: 5 | J28: 1 | K28: 0 | L28: 0 | M28: 32 | N28: 0 | O28: =SUM(C28:L28,N28) -> 30 | P28: =SUM(C28:N28) -> 62 | R28: 12 Hours | S28: =SUM(S10:S21) -> 1110 | T28: =SUM(T10:T21) -> 154 | U28: =SUM(U10:U21) -> 101 | V28: =SUM(V10:V21) -> 781 | W28: =SUM(W10:W21) -> 11 | X28: =SUM(X10:X21) -> 3 | Y28: =SUM(Y10:Y21) -> 138 | Z28: =SUM(Z10:Z21) -> 35 | ... AF28: =SUM(AF10:AF21) -> 3990
