Workbook

Sheet 05.08 KABONG-KOTIDO
B1: Consultancy services for Preparation of Expressway Development Master Plan (EDMP) for Uganda
B2: MANUAL CLASSIFIED COUNT (MCC)
B3: ROAD NAME: | C3: MCC - C5 - STN0125 - KAABONG-KOTIDO ROAD
C5: Date | D5: 5.08.19 | F5: Location | G5: xxx | J5: Surveyor | K5: NALUBEGA JOSEPHINE
C6: Dir. From | D6: KABONG | F6: Dir. To | G6: KOTIDO | J6: Supervisor | K6: CRANIMER
B8: Time / Veh Type | R8: SUMMARY TRAFFIC VOLUMES
C9: 1. Car | D9: 2. Station Wagon | E9: 3. Pickups | F9: 4. Minibus, matatu | G9: 5. Medium bus | H9: 6. Large Bus | I9: 7. Light Truck | J9: 8. Medium Truck | K9: 9. Heavy truck | L9: 10. Truck Trailer | M9: 11. Motor cycles | N9: 12. Tractors | O9: Total Excl M/Cycles | P9: Total All | R9: Time | S9: 1. Car | T9: 2. Station Wagon | U9: 3. Pickups | V9: 4. Minibus, matatu | W9: 5. Medium bus | X9: 6. Large Bus | Y9: 7. Light Truck | Z9: 8. Medium Truck | AA9: 9. Heavy truck | AB9: 10. Truck Trailer | AC9: 11. Motorcycles | AD9: 12. Tractors, Graders | AE9: Total Excl M/ Cycles | AF9: Total All
B10: 07.00 - 07.15 | C10: 0 | D10: 0 | E10: 1 | F10: 0 | G10: 0 | H10: 0 | I10: 0 | J10: 1 | K10: 0 | L10: 0 | M10: 0 | N10: 0 | O10: =SUM(C10:L10,N10) -> 2 | P10: =SUM(C10:N10) -> 2 | R10: 0700-0800 | S10: =SUM(C10:C13) -> 0 | T10: =SUM(D10:D13) -> 2 | U10: =SUM(E10:E13) -> 1 | V10: =SUM(F10:F13) -> 0 | W10: =SUM(G10:G13) -> 0 | X10: =SUM(H10:H13) -> 0 | Y10: =SUM(I10:I13) -> 0 | Z10: =SUM(J10:J13) -> 2 | ... AF10: =SUM(P10:P13) -> 8
B11: 07.15 - 07.30 | C11: 0 | D11: 0 | E11: 0 | F11: 0 | G11: 0 | H11: 0 | I11: 0 | J11: 0 | K11: 2 | L11: 0 | M11: 0 | N11: 0 | O11: =SUM(C11:L11,N11) -> 2 | P11: =SUM(C11:N11) -> 2 | R11: 0800-0900 | S11: =SUM(C14:C17) -> 0 | T11: =SUM(D14:D17) -> 0 | U11: =SUM(E14:E17) -> 1 | V11: =SUM(F14:F17) -> 0 | W11: =SUM(G14:G17) -> 0 | X11: =SUM(H14:H17) -> 1 | Y11: =SUM(I14:I17) -> 1 | Z11: =SUM(J14:J17) -> 1 | ... AF11: =SUM(P14:P17) -> 7
B12: 07.30 - 07.45 | C12: 0 | D12: 1 | E12: 0 | F12: 0 | G12: 0 | H12: 0 | I12: 0 | J12: 0 | K12: 0 | L12: 0 | M12: 0 | N12: 0 | O12: =SUM(C12:L12,N12) -> 1 | P12: =SUM(C12:N12) -> 1 | R12: 0900-1000 | S12: =SUM(C18:C21) -> 2 | T12: =SUM(D18:D21) -> 2 | U12: =SUM(E18:E21) -> 0 | V12: =SUM(F18:F21) -> 1 | W12: =SUM(G18:G21) -> 0 | X12: =SUM(H18:H21) -> 0 | Y12: =SUM(I18:I21) -> 0 | Z12: =SUM(J18:J21) -> 2 | ... AF12: =SUM(P18:P21) -> 13
B13: 07.45 - 08.00 | C13: 0 | D13: 1 | E13: 0 | F13: 0 | G13: 0 | H13: 0 | I13: 0 | J13: 1 | K13: 0 | L13: 0 | M13: 0 | N13: 1 | O13: =SUM(C13:L13,N13) -> 3 | P13: =SUM(C13:N13) -> 3 | R13: 1000-1100 | S13: =SUM(C22:C25) -> 1 | T13: =SUM(D22:D25) -> 2 | U13: =SUM(E22:E25) -> 1 | V13: =SUM(F22:F25) -> 0 | W13: =SUM(G22:G25) -> 0 | X13: =SUM(H22:H25) -> 0 | Y13: =SUM(I22:I25) -> 2 | Z13: =SUM(J22:J25) -> 0 | ... AF13: =SUM(P22:P25) -> 8
B14: 08.00 - 08.15 | C14: 0 | D14: 0 | E14: 0 | F14: 0 | G14: 0 | H14: 1 | I14: 1 | J14: 0 | K14: 1 | L14: 0 | M14: 0 | N14: 0 | O14: =SUM(C14:L14,N14) -> 3 | P14: =SUM(C14:N14) -> 3 | R14: 1100-1200 | S14: =SUM(C26:C29) -> 0 | T14: =SUM(D26:D29) -> 1 | U14: =SUM(E26:E29) -> 0 | V14: =SUM(F26:F29) -> 0 | W14: =SUM(G26:G29) -> 0 | X14: =SUM(H26:H29) -> 0 | Y14: =SUM(I26:I29) -> 0 | Z14: =SUM(J26:J29) -> 2 | ... AF14: =SUM(P26:P29) -> 3
B15: 08.15 - 08.30 | C15: 0 | D15: 0 | E15: 0 | F15: 0 | G15: 0 | H15: 0 | I15: 0 | J15: 1 | K15: 0 | L15: 0 | M15: 2 | N15: 0 | O15: =SUM(C15:L15,N15) -> 1 | P15: =SUM(C15:N15) -> 3 | R15: 1200-1300 | S15: =SUM(C30:C33) -> 0 | T15: =SUM(D30:D33) -> 0 | U15: =SUM(E30:E33) -> 1 | V15: =SUM(F30:F33) -> 0 | W15: =SUM(G30:G33) -> 0 | X15: =SUM(H30:H33) -> 0 | Y15: =SUM(I30:I33) -> 0 | Z15: =SUM(J30:J33) -> 0 | ... AF15: =SUM(P30:P33) -> 2
B16: 08.30 - 08.45 | C16: 0 | D16: 0 | E16: 0 | F16: 0 | G16: 0 | H16: 0 | I16: 0 | J16: 0 | K16: 0 | L16: 0 | M16: 0 | N16: 0 | O16: =SUM(C16:L16,N16) -> 0 | P16: =SUM(C16:N16) -> 0 | R16: 1300-1400 | S16: =SUM(C34:C37) -> 1 | T16: =SUM(D34:D37) -> 1 | U16: =SUM(E34:E37) -> 0 | V16: =SUM(F34:F37) -> 0 | W16: =SUM(G34:G37) -> 0 | X16: =SUM(H34:H37) -> 0 | Y16: =SUM(I34:I37) -> 1 | Z16: =SUM(J34:J37) -> 2 | ... AF16: =SUM(P34:P37) -> 8
B17: 08.45 - 9.00 | C17: 0 | D17: 0 | E17: 1 | F17: 0 | G17: 0 | H17: 0 | I17: 0 | J17: 0 | K17: 0 | L17: 0 | M17: 0 | N17: 0 | O17: =SUM(C17:L17,N17) -> 1 | P17: =SUM(C17:N17) -> 1 | R17: 1400-1500 | S17: =SUM(C38:C41) -> 0 | T17: =SUM(D38:D41) -> 0 | U17: =SUM(E38:E41) -> 0 | V17: =SUM(F38:F41) -> 1 | W17: =SUM(G38:G41) -> 0 | X17: =SUM(H38:H41) -> 0 | Y17: =SUM(I38:I41) -> 3 | Z17: =SUM(J38:J41) -> 0 | ... AF17: =SUM(P38:P41) -> 4
B18: 09.00 - 09.15 | C18: 0 | D18: 0 | E18: 0 | F18: 0 | G18: 0 | H18: 0 | I18: 0 | J18: 1 | K18: 0 | L18: 0 | M18: 2 | N18: 0 | O18: =SUM(C18:L18,N18) -> 1 | P18: =SUM(C18:N18) -> 3 | R18: 1500-1600 | S18: =SUM(C42:C45) -> 0 | T18: =SUM(D42:D45) -> 2 | U18: =SUM(E42:E45) -> 2 | V18: =SUM(F42:F45) -> 0 | W18: =SUM(G42:G45) -> 0 | X18: =SUM(H42:H45) -> 0 | Y18: =SUM(I42:I45) -> 4 | Z18: =SUM(J42:J45) -> 2 | ... AF18: =SUM(P42:P45) -> 14
B19: 09.15 - 09.30 | C19: 2 | D19: 2 | E19: 0 | F19: 0 | G19: 0 | H19: 0 | I19: 0 | J19: 1 | K19: 0 | L19: 0 | M19: 1 | N19: 0 | O19: =SUM(C19:L19,N19) -> 5 | P19: =SUM(C19:N19) -> 6 | R19: 1600-1700 | S19: =SUM(C46:C49) -> 0 | T19: =SUM(D46:D49) -> 1 | U19: =SUM(E46:E49) -> 2 | V19: =SUM(F46:F49) -> 0 | W19: =SUM(G46:G49) -> 0 | X19: =SUM(H46:H49) -> 0 | Y19: =SUM(I46:I49) -> 1 | Z19: =SUM(J46:J49) -> 1 | ... AF19: =SUM(P46:P49) -> 7
B20: 09.30 - 09.45 | C20: 0 | D20: 0 | E20: 0 | F20: 1 | G20: 0 | H20: 0 | I20: 0 | J20: 0 | K20: 0 | L20: 0 | M20: 3 | N20: 0 | O20: =SUM(C20:L20,N20) -> 1 | P20: =SUM(C20:N20) -> 4 | R20: 1700-1800 | S20: =SUM(C50:C53) -> 0 | T20: =SUM(D50:D53) -> 0 | U20: =SUM(E50:E53) -> 3 | V20: =SUM(F50:F53) -> 0 | W20: =SUM(G50:G53) -> 0 | X20: =SUM(H50:H53) -> 0 | Y20: =SUM(I50:I53) -> 0 | Z20: =SUM(J50:J53) -> 0 | ... AF20: =SUM(P50:P53) -> 6
B21: 09.45 - 10.00 | C21: 0 | D21: 0 | E21: 0 | F21: 0 | G21: 0 | H21: 0 | I21: 0 | J21: 0 | K21: 0 | L21: 0 | M21: 0 | N21: 0 | O21: =SUM(C21:L21,N21) -> 0 | P21: =SUM(C21:N21) -> 0 | R21: 1800-1900 | S21: =SUM(C54:C57) -> 1 | T21: =SUM(D54:D57) -> 0 | U21: =SUM(E54:E57) -> 0 | V21: =SUM(F54:F57) -> 0 | W21: =SUM(G54:G57) -> 0 | X21: =SUM(H54:H57) -> 0 | Y21: =SUM(I54:I57) -> 0 | Z21: =SUM(J54:J57) -> 0 | ... AF21: =SUM(P54:P57) -> 2
B22: 10.00 - 10.15 | C22: 0 | D22: 1 | E22: 1 | F22: 0 | G22: 0 | H22: 0 | I22: 1 | J22: 0 | K22: 0 | L22: 0 | M22: 1 | N22: 0 | O22: =SUM(C22:L22,N22) -> 3 | P22: =SUM(C22:N22) -> 4 | R22: AM Peak Hr | S22: =MAX(S10:S12) -> 2 | T22: =MAX(T10:T12) -> 2 | U22: =MAX(U10:U12) -> 1 | V22: =MAX(V10:V12) -> 1 | W22: =MAX(W10:W12) -> 0 | X22: =MAX(X10:X12) -> 1 | Y22: =MAX(Y10:Y12) -> 1 | Z22: =MAX(Z10:Z12) -> 2 | ... AF22: =MAX(AF10:AF12) -> 13
B23: 10.15 - 10.30 | C23: 0 | D23: 0 | E23: 0 | F23: 0 | G23: 0 | H23: 0 | I23: 0 | J23: 0 | K23: 0 | L23: 0 | M23: 0 | N23: 0 | O23: =SUM(C23:L23,N23) -> 0 | P23: =SUM(C23:N23) -> 0 | R23: IP Peak Hr | S23: =MAX(S13:S18) -> 1 | T23: =MAX(T13:T18) -> 2 | U23: =MAX(U13:U18) -> 2 | V23: =MAX(V13:V18) -> 1 | W23: =MAX(W13:W18) -> 0 | X23: =MAX(X13:X18) -> 0 | Y23: =MAX(Y13:Y18) -> 4 | Z23: =MAX(Z13:Z18) -> 2 | ... AF23: =MAX(AF13:AF18) -> 14
B24: 10.30 - 10.45 | C24: 1 | D24: 0 | E24: 0 | F24: 0 | G24: 0 | H24: 0 | I24: 1 | J24: 0 | K24: 0 | L24: 0 | M24: 1 | N24: 0 | O24: =SUM(C24:L24,N24) -> 2 | P24: =SUM(C24:N24) -> 3 | R24: PM Peak Hr | S24: =MAX(S19:S21) -> 1 | T24: =MAX(T19:T21) -> 1 | U24: =MAX(U19:U21) -> 3 | V24: =MAX(V19:V21) -> 0 | W24: =MAX(W19:W21) -> 0 | X24: =MAX(X19:X21) -> 0 | Y24: =MAX(Y19:Y21) -> 1 | Z24: =MAX(Z19:Z21) -> 1 | ... AF24: =MAX(AF19:AF21) -> 7
B25: 10.45 - 11.00 | C25: 0 | D25: 1 | E25: 0 | F25: 0 | G25: 0 | H25: 0 | I25: 0 | J25: 0 | K25: 0 | L25: 0 | M25: 0 | N25: 0 | O25: =SUM(C25:L25,N25) -> 1 | P25: =SUM(C25:N25) -> 1 | R25: AM Period | S25: =SUM(S10:S12) -> 2 | T25: =SUM(T10:T12) -> 4 | U25: =SUM(U10:U12) -> 2 | V25: =SUM(V10:V12) -> 1 | W25: =SUM(W10:W12) -> 0 | X25: =SUM(X10:X12) -> 1 | Y25: =SUM(Y10:Y12) -> 1 | Z25: =SUM(Z10:Z12) -> 5 | ... AF25: =SUM(AF10:AF12) -> 28
B26: 11.00 - 11.15 | C26: 0 | D26: 0 | E26: 0 | F26: 0 | G26: 0 | H26: 0 | I26: 0 | J26: 1 | K26: 0 | L26: 0 | M26: 0 | N26: 0 | O26: =SUM(C26:L26,N26) -> 1 | P26: =SUM(C26:N26) -> 1 | R26: IP Period | S26: =SUM(S13:S18) -> 2 | T26: =SUM(T13:T18) -> 6 | U26: =SUM(U13:U18) -> 4 | V26: =SUM(V13:V18) -> 1 | W26: =SUM(W13:W18) -> 0 | X26: =SUM(X13:X18) -> 0 | Y26: =SUM(Y13:Y18) -> 10 | Z26: =SUM(Z13:Z18) -> 6 | ... AF26: =SUM(AF13:AF18) -> 39
B27: 11.15 - 11.30 | C27: 0 | D27: 0 | E27: 0 | F27: 0 | G27: 0 | H27: 0 | I27: 0 | J27: 0 | K27: 0 | L27: 0 | M27: 0 | N27: 0 | O27: =SUM(C27:L27,N27) -> 0 | P27: =SUM(C27:N27) -> 0 | R27: PM Period | S27: =SUM(S19:S21) -> 1 | T27: =SUM(T19:T21) -> 1 | U27: =SUM(U19:U21) -> 5 | V27: =SUM(V19:V21) -> 0 | W27: =SUM(W19:W21) -> 0 | X27: =SUM(X19:X21) -> 0 | Y27: =SUM(Y19:Y21) -> 1 | Z27: =SUM(Z19:Z21) -> 1 | ... AF27: =SUM(AF19:AF21) -> 15
B28: 11.30 - 11.45 | C28: 0 | D28: 0 | E28: 0 | F28: 0 | G28: 0 | H28: 0 | I28: 0 | J28: 0 | K28: 0 | L28: 0 | M28: 0 | N28: 0 | O28: =SUM(C28:L28,N28) -> 0 | P28: =SUM(C28:N28) -> 0 | R28: 12 Hours | S28: =SUM(S10:S21) -> 5 | T28: =SUM(T10:T21) -> 11 | U28: =SUM(U10:U21) -> 11 | V28: =SUM(V10:V21) -> 2 | W28: =SUM(W10:W21) -> 0 | X28: =SUM(X10:X21) -> 1 | Y28: =SUM(Y10:Y21) -> 12 | Z28: =SUM(Z10:Z21) -> 12 | ... AF28: =SUM(AF10:AF21) -> 82
B29: 11.45 - 12.00 | C29: 0 | D29: 1 | E29: 0 | F29: 0 | G29: 0 | H29: 0 | I29: 0 | J29: 1 | K29: 0 | L29: 0 | M29: 0 | N29: 0 | O29: =SUM(C29:L29,N29) -> 2 | P29: =SUM(C29:N29) -> 2
B30: 12.00 - 12.15 | C30: 0 | D30: 0 | E30: 0 | F30: 0 | G30: 0 | H30: 0 | I30: 0 | J30: 0 | K30: 0 | L30: 0 | M30: 0 | N30: 0 | O30: =SUM(C30:L30,N30) -> 0 | P30: =SUM(C30:N30) -> 0
B31: 12.15 - 12.30 | C31: 0 | D31: 0 | E31: 1 | F31: 0 | G31: 0 | H31: 0 | I31: 0 | J31: 0 | K31: 0 | L31: 0 | M31: 0 | N31: 0 | O31: =SUM(C31:L31,N31) -> 1 | P31: =SUM(C31:N31) -> 1
B32: 12.30 - 12.45 | C32: 0 | D32: 0 | E32: 0 | F32: 0 | G32: 0 | H32: 0 | I32: 0 | J32: 0 | K32: 0 | L32: 0 | M32: 1 | N32: 0 | O32: =SUM(C32:L32,N32) -> 0 | P32: =SUM(C32:N32) -> 1
B33: 12.45 - 13.00 | C33: 0 | D33: 0 | E33: 0 | F33: 0 | G33: 0 | H33: 0 | I33: 0 | J33: 0 | K33: 0 | L33: 0 | M33: 0 | N33: 0 | O33: =SUM(C33:L33,N33) -> 0 | P33: =SUM(C33:N33) -> 0
B34: 13.00 - 13.15 | C34: 1 | D34: 1 | E34: 0 | F34: 0 | G34: 0 | H34: 0 | I34: 1 | J34: 1 | K34: 0 | L34: 0 | M34: 2 | N34: 0 | O34: =SUM(C34:L34,N34) -> 4 | P34: =SUM(C34:N34) -> 6
B35: 13.15 - 13.30 | C35: 0 | D35: 0 | E35: 0 | F35: 0 | G35: 0 | H35: 0 | I35: 0 | J35: 1 | K35: 0 | L35: 0 | M35: 1 | N35: 0 | O35: =SUM(C35:L35,N35) -> 1 | P35: =SUM(C35:N35) -> 2
B36: 13.30 - 13.45 | C36: 0 | D36: 0 | E36: 0 | F36: 0 | G36: 0 | H36: 0 | I36: 0 | J36: 0 | K36: 0 | L36: 0 | M36: 0 | N36: 0 | O36: =SUM(C36:L36,N36) -> 0 | P36: =SUM(C36:N36) -> 0
B37: 13.45 - 14.00 | C37: 0 | D37: 0 | E37: 0 | F37: 0 | G37: 0 | H37: 0 | I37: 0 | J37: 0 | K37: 0 | L37: 0 | M37: 0 | N37: 0 | O37: =SUM(C37:L37,N37) -> 0 | P37: =SUM(C37:N37) -> 0
B38: 14.00 - 14.15 | C38: 0 | D38: 0 | E38: 0 | F38: 0 | G38: 0 | H38: 0 | I38: 0 | J38: 0 | K38: 0 | L38: 0 | M38: 0 | N38: 0 | O38: =SUM(C38:L38,N38) -> 0 | P38: =SUM(C38:N38) -> 0
B39: 14.15 - 14.30 | C39: 0 | D39: 0 | E39: 0 | F39: 0 | G39: 0 | H39: 0 | I39: 0 | J39: 0 | K39: 0 | L39: 0 | M39: 0 | N39: 0 | O39: =SUM(C39:L39,N39) -> 0 | P39: =SUM(C39:N39) -> 0
B40: 14.30 - 14.45 | C40: 0 | D40: 0 | E40: 0 | F40: 0 | G40: 0 | H40: 0 | I40: 2 | J40: 0 | K40: 0 | L40: 0 | M40: 0 | N40: 0 | O40: =SUM(C40:L40,N40) -> 2 | P40: =SUM(C40:N40) -> 2
... B57: 18.45 - 19.00 | C57: 0 | D57: 0 | E57: 0 | F57: 0 | G57: 0 | H57: 0 | I57: 0 | J57: 0 | K57: 0 | L57: 0 | M57: 0 | N57: 0 | O57: =SUM(C57:L57,N57) -> 0 | P57: =SUM(C57:N57) -> 0
B58: Totals | C58: =SUM(C10:C57) -> 5 | D58: =SUM(D10:D57) -> 11 | E58: =SUM(E10:E57) -> 11 | F58: =SUM(F10:F57) -> 2 | G58: =SUM(G10:G57) -> 0 | H58: =SUM(H10:H57) -> 1 | I58: =SUM(I10:I57) -> 12 | J58: =SUM(J10:J57) -> 12 | ... P58: =SUM(P10:P57) -> 82
...

Sheet 05.08 KOTIDO-KABONG
B1: Consultancy services for Preparation of Expressway Development Master Plan (EDMP) for Uganda
B2: MANUAL CLASSIFIED COUNT (MCC)
B3: ROAD NAME: | C3: ='05.08 KABONG-KOTIDO'!C3:G3 -> MCC - C5 - STN0125 - KAABONG-KOTIDO ROAD
C5: Date | D5: ='05.08 KABONG-KOTIDO'!D5 -> 5.08.19 | F5: Location | G5: ='05.08 KABONG-KOTIDO'!G5:H5 -> xxx | J5: Surveyor | K5: ='05.08 KABONG-KOTIDO'!K5:L5 -> NALUBEGA JOSEPHINE
C6: Dir. From | D6: KITIDO | F6: Dir. To | G6: KABONG | J6: Supervisor | K6: ='05.08 KABONG-KOTIDO'!K6:L6 -> CRANIMER
B8: Time / Veh Type | R8: SUMMARY TRAFFIC VOLUMES
C9: 1. Car | D9: 2. Station Wagon | E9: 3. Pickups | F9: 4. Minibus, matatu | G9: 5. Medium bus | H9: 6. Large Bus | I9: 7. Light Truck | J9: 8. Medium Truck | K9: 9. Heavy truck | L9: 10. Truck Trailer | M9: 11. Motor cycles | N9: 12. Tractors | O9: Total Excl M/Cycles | P9: Total All | R9: Time | S9: 1. Car | T9: 2. Station Wagon | U9: 3. Pickups | V9: 4. Minibus, matatu | W9: 5. Medium bus | X9: 6. Large Bus | Y9: 7. Light Truck | Z9: 8. Medium Truck | AA9: 9. Heavy truck | AB9: 10. Truck Trailer | AC9: 11. Motorcycles | AD9: 12. Tractors, Graders | AE9: Total Excl M/ Cycles | AF9: Total All
B10: 07.00 - 07.15 | C10: 0 | D10: 0 | E10: 2 | F10: 0 | G10: 0 | H10: 0 | I10: 0 | J10: 1 | K10: 0 | L10: 0 | M10: 1 | N10: 0 | O10: =SUM(C10:L10,N10) -> 3 | P10: =SUM(C10:N10) -> 4 | R10: 0700-0800 | S10: =SUM(C10:C13) -> 1 | T10: =SUM(D10:D13) -> 1 | U10: =SUM(E10:E13) -> 2 | V10: =SUM(F10:F13) -> 0 | W10: =SUM(G10:G13) -> 0 | X10: =SUM(H10:H13) -> 0 | Y10: =SUM(I10:I13) -> 0 | Z10: =SUM(J10:J13) -> 1 | ... AF10: =SUM(P10:P13) -> 7
B11: 07.15 - 07.30 | C11: 0 | D11: 0 | E11: 0 | F11: 0 | G11: 0 | H11: 0 | I11: 0 | J11: 0 | K11: 0 | L11: 0 | M11: 0 | N11: 0 | O11: =SUM(C11:L11,N11) -> 0 | P11: =SUM(C11:N11) -> 0 | R11: 0800-0900 | S11: =SUM(C14:C17) -> 1 | T11: =SUM(D14:D17) -> 3 | U11: =SUM(E14:E17) -> 1 | V11: =SUM(F14:F17) -> 0 | W11: =SUM(G14:G17) -> 0 | X11: =SUM(H14:H17) -> 0 | Y11: =SUM(I14:I17) -> 1 | Z11: =SUM(J14:J17) -> 8 | ... AF11: =SUM(P14:P17) -> 21
B12: 07.30 - 07.45 | C12: 0 | D12: 0 | E12: 0 | F12: 0 | G12: 0 | H12: 0 | I12: 0 | J12: 0 | K12: 0 | L12: 0 | M12: 0 | N12: 0 | O12: =SUM(C12:L12,N12) -> 0 | P12: =SUM(C12:N12) -> 0 | R12: 0900-1000 | S12: =SUM(C18:C21) -> 2 | T12: =SUM(D18:D21) -> 4 | U12: =SUM(E18:E21) -> 1 | V12: =SUM(F18:F21) -> 0 | W12: =SUM(G18:G21) -> 0 | X12: =SUM(H18:H21) -> 2 | Y12: =SUM(I18:I21) -> 2 | Z12: =SUM(J18:J21) -> 0 | ... AF12: =SUM(P18:P21) -> 19
B13: 07.45 - 08.00 | C13: 1 | D13: 1 | E13: 0 | F13: 0 | G13: 0 | H13: 0 | I13: 0 | J13: 0 | K13: 0 | L13: 0 | M13: 1 | N13: 0 | O13: =SUM(C13:L13,N13) -> 2 | P13: =SUM(C13:N13) -> 3 | R13: 1000-1100 | S13: =SUM(C22:C25) -> 0 | T13: =SUM(D22:D25) -> 2 | U13: =SUM(E22:E25) -> 1 | V13: =SUM(F22:F25) -> 0 | W13: =SUM(G22:G25) -> 0 | X13: =SUM(H22:H25) -> 0 | Y13: =SUM(I22:I25) -> 1 | Z13: =SUM(J22:J25) -> 2 | ... AF13: =SUM(P22:P25) -> 9
B14: 08.00 - 08.15 | C14: 0 | D14: 0 | E14: 0 | F14: 0 | G14: 0 | H14: 0 | I14: 1 | J14: 0 | K14: 0 | L14: 0 | M14: 3 | N14: 0 | O14: =SUM(C14:L14,N14) -> 1 | P14: =SUM(C14:N14) -> 4 | R14: 1100-1200 | S14: =SUM(C26:C29) -> 1 | T14: =SUM(D26:D29) -> 0 | U14: =SUM(E26:E29) -> 0 | V14: =SUM(F26:F29) -> 0 | W14: =SUM(G26:G29) -> 0 | X14: =SUM(H26:H29) -> 0 | Y14: =SUM(I26:I29) -> 1 | Z14: =SUM(J26:J29) -> 0 | ... AF14: =SUM(P26:P29) -> 2
B15: 08.15 - 08.30 | C15: 0 | D15: 0 | E15: 0 | F15: 0 | G15: 0 | H15: 0 | I15: 0 | J15: 0 | K15: 0 | L15: 0 | M15: 2 | N15: 0 | O15: =SUM(C15:L15,N15) -> 0 | P15: =SUM(C15:N15) -> 2 | R15: 1200-1300 | S15: =SUM(C30:C33) -> 2 | T15: =SUM(D30:D33) -> 1 | U15: =SUM(E30:E33) -> 2 | V15: =SUM(F30:F33) -> 0 | W15: =SUM(G30:G33) -> 0 | X15: =SUM(H30:H33) -> 0 | Y15: =SUM(I30:I33) -> 0 | Z15: =SUM(J30:J33) -> 2 | ... AF15: =SUM(P30:P33) -> 8
B16: 08.30 - 08.45 | C16: 1 | D16: 1 | E16: 0 | F16: 0 | G16: 0 | H16: 0 | I16: 0 | J16: 0 | K16: 0 | L16: 0 | M16: 2 | N16: 0 | O16: =SUM(C16:L16,N16) -> 2 | P16: =SUM(C16:N16) -> 4 | R16: 1300-1400 | S16: =SUM(C34:C37) -> 0 | T16: =SUM(D34:D37) -> 0 | U16: =SUM(E34:E37) -> 1 | V16: =SUM(F34:F37) -> 0 | W16: =SUM(G34:G37) -> 0 | X16: =SUM(H34:H37) -> 0 | Y16: =SUM(I34:I37) -> 0 | Z16: =SUM(J34:J37) -> 3 | ... AF16: =SUM(P34:P37) -> 6
B17: 08.45 - 9.00 | C17: 0 | D17: 2 | E17: 1 | F17: 0 | G17: 0 | H17: 0 | I17: 0 | J17: 8 | K17: 0 | L17: 0 | M17: 0 | N17: 0 | O17: =SUM(C17:L17,N17) -> 11 | P17: =SUM(C17:N17) -> 11 | R17: 1400-1500 | S17: =SUM(C38:C41) -> 0 | T17: =SUM(D38:D41) -> 2 | U17: =SUM(E38:E41) -> 1 | V17: =SUM(F38:F41) -> 0 | W17: =SUM(G38:G41) -> 0 | X17: =SUM(H38:H41) -> 0 | Y17: =SUM(I38:I41) -> 0 | Z17: =SUM(J38:J41) -> 0 | ... AF17: =SUM(P38:P41) -> 5
B18: 09.00 - 09.15 | C18: 0 | D18: 0 | E18: 0 | F18: 0 | G18: 0 | H18: 0 | I18: 0 | J18: 0 | K18: 0 | L18: 0 | M18: 3 | N18: 0 | O18: =SUM(C18:L18,N18) -> 0 | P18: =SUM(C18:N18) -> 3 | R18: 1500-1600 | S18: =SUM(C42:C45) -> 0 | T18: =SUM(D42:D45) -> 0 | U18: =SUM(E42:E45) -> 1 | V18: =SUM(F42:F45) -> 0 | W18: =SUM(G42:G45) -> 0 | X18: =SUM(H42:H45) -> 0 | Y18: =SUM(I42:I45) -> 0 | Z18: =SUM(J42:J45) -> 0 | ... AF18: =SUM(P42:P45) -> 2
B19: 09.15 - 09.30 | C19: 0 | D19: 2 | E19: 1 | F19: 0 | G19: 0 | H19: 0 | I19: 2 | J19: 0 | K19: 0 | L19: 0 | M19: 3 | N19: 0 | O19: =SUM(C19:L19,N19) -> 5 | P19: =SUM(C19:N19) -> 8 | R19: 1600-1700 | S19: =SUM(C46:C49) -> 0 | T19: =SUM(D46:D49) -> 0 | U19: =SUM(E46:E49) -> 0 | V19: =SUM(F46:F49) -> 0 | W19: =SUM(G46:G49) -> 1 | X19: =SUM(H46:H49) -> 0 | Y19: =SUM(I46:I49) -> 0 | Z19: =SUM(J46:J49) -> 0 | ... AF19: =SUM(P46:P49) -> 4
B20: 09.30 - 09.45 | C20: 2 | D20: 0 | E20: 0 | F20: 0 | G20: 0 | H20: 2 | I20: 0 | J20: 0 | K20: 0 | L20: 0 | M20: 1 | N20: 0 | O20: =SUM(C20:L20,N20) -> 4 | P20: =SUM(C20:N20) -> 5 | R20: 1700-1800 | S20: =SUM(C50:C53) -> 0 | T20: =SUM(D50:D53) -> 1 | U20: =SUM(E50:E53) -> 0 | V20: =SUM(F50:F53) -> 0 | W20: =SUM(G50:G53) -> 0 | X20: =SUM(H50:H53) -> 0 | Y20: =SUM(I50:I53) -> 0 | Z20: =SUM(J50:J53) -> 2 | ... AF20: =SUM(P50:P53) -> 4
B21: 09.45 - 10.00 | C21: 0 | D21: 2 | E21: 0 | F21: 0 | G21: 0 | H21: 0 | I21: 0 | J21: 0 | K21: 0 | L21: 0 | M21: 1 | N21: 0 | O21: =SUM(C21:L21,N21) -> 2 | P21: =SUM(C21:N21) -> 3 | R21: 1800-1900 | S21: =SUM(C54:C57) -> 0 | T21: =SUM(D54:D57) -> 1 | U21: =SUM(E54:E57) -> 0 | V21: =SUM(F54:F57) -> 0 | W21: =SUM(G54:G57) -> 0 | X21: =SUM(H54:H57) -> 0 | Y21: =SUM(I54:I57) -> 0 | Z21: =SUM(J54:J57) -> 0 | ... AF21: =SUM(P54:P57) -> 2
B22: 10.00 - 10.15 | C22: 0 | D22: 1 | E22: 0 | F22: 0 | G22: 0 | H22: 0 | I22: 1 | J22: 2 | K22: 0 | L22: 0 | M22: 2 | N22: 0 | O22: =SUM(C22:L22,N22) -> 4 | P22: =SUM(C22:N22) -> 6 | R22: AM Peak Hr | S22: =MAX(S10:S12) -> 2 | T22: =MAX(T10:T12) -> 4 | U22: =MAX(U10:U12) -> 2 | V22: =MAX(V10:V12) -> 0 | W22: =MAX(W10:W12) -> 0 | X22: =MAX(X10:X12) -> 2 | Y22: =MAX(Y10:Y12) -> 2 | Z22: =MAX(Z10:Z12) -> 8 | ... AF22: =MAX(AF10:AF12) -> 21
B23: 10.15 - 10.30 | C23: 0 | D23: 1 | E23: 0 | F23: 0 | G23: 0 | H23: 0 | I23: 0 | J23: 0 | K23: 0 | L23: 0 | M23: 0 | N23: 0 | O23: =SUM(C23:L23,N23) -> 1 | P23: =SUM(C23:N23) -> 1 | R23: IP Peak Hr | S23: =MAX(S13:S18) -> 2 | T23: =MAX(T13:T18) -> 2 | U23: =MAX(U13:U18) -> 2 | V23: =MAX(V13:V18) -> 0 | W23: =MAX(W13:W18) -> 0 | X23: =MAX(X13:X18) -> 0 | Y23: =MAX(Y13:Y18) -> 1 | Z23: =MAX(Z13:Z18) -> 3 | ... AF23: =MAX(AF13:AF18) -> 9
B24: 10.30 - 10.45 | C24: 0 | D24: 0 | E24: 1 | F24: 0 | G24: 0 | H24: 0 | I24: 0 | J24: 0 | K24: 0 | L24: 0 | M24: 0 | N24: 0 | O24: =SUM(C24:L24,N24) -> 1 | P24: =SUM(C24:N24) -> 1 | R24: PM Peak Hr | S24: =MAX(S19:S21) -> 0 | T24: =MAX(T19:T21) -> 1 | U24: =MAX(U19:U21) -> 0 | V24: =MAX(V19:V21) -> 0 | W24: =MAX(W19:W21) -> 1 | X24: =MAX(X19:X21) -> 0 | Y24: =MAX(Y19:Y21) -> 0 | Z24: =MAX(Z19:Z21) -> 2 | ... AF24: =MAX(AF19:AF21) -> 4
B25: 10.45 - 11.00 | C25: 0 | D25: 0 | E25: 0 | F25: 0 | G25: 0 | H25: 0 | I25: 0 | J25: 0 | K25: 1 | L25: 0 | M25: 0 | N25: 0 | O25: =SUM(C25:L25,N25) -> 1 | P25: =SUM(C25:N25) -> 1 | R25: AM Period | S25: =SUM(S10:S12) -> 4 | T25: =SUM(T10:T12) -> 8 | U25: =SUM(U10:U12) -> 4 | V25: =SUM(V10:V12) -> 0 | W25: =SUM(W10:W12) -> 0 | X25: =SUM(X10:X12) -> 2 | Y25: =SUM(Y10:Y12) -> 3 | Z25: =SUM(Z10:Z12) -> 9 | ... AF25: =SUM(AF10:AF12) -> 47
B26: 11.00 - 11.15 | C26: 0 | D26: 0 | E26: 0 | F26: 0 | G26: 0 | H26: 0 | I26: 1 | J26: 0 | K26: 0 | L26: 0 | M26: 0 | N26: 0 | O26: =SUM(C26:L26,N26) -> 1 | P26: =SUM(C26:N26) -> 1 | R26: IP Period | S26: =SUM(S13:S18) -> 3 | T26: =SUM(T13:T18) -> 5 | U26: =SUM(U13:U18) -> 6 | V26: =SUM(V13:V18) -> 0 | W26: =SUM(W13:W18) -> 0 | X26: =SUM(X13:X18) -> 0 | Y26: =SUM(Y13:Y18) -> 2 | Z26: =SUM(Z13:Z18) -> 7 | ... AF26: =SUM(AF13:AF18) -> 32
B27: 11.15 - 11.30 | C27: 0 | D27: 0 | E27: 0 | F27: 0 | G27: 0 | H27: 0 | I27: 0 | J27: 0 | K27: 0 | L27: 0 | M27: 0 | N27: 0 | O27: =SUM(C27:L27,N27) -> 0 | P27: =SUM(C27:N27) -> 0 | R27: PM Period | S27: =SUM(S19:S21) -> 0 | T27: =SUM(T19:T21) -> 2 | U27: =SUM(U19:U21) -> 0 | V27: =SUM(V19:V21) -> 0 | W27: =SUM(W19:W21) -> 1 | X27: =SUM(X19:X21) -> 0 | Y27: =SUM(Y19:Y21) -> 0 | Z27: =SUM(Z19:Z21) -> 2 | ... AF27: =SUM(AF19:AF21) -> 10
B28: 11.30 - 11.45 | C28: 0 | D28: 0 | E28: 0 | F28: 0 | G28: 0 | H28: 0 | I28: 0 | J28: 0 | K28: 0 | L28: 0 | M28: 0 | N28: 0 | O28: =SUM(C28:L28,N28) -> 0 | P28: =SUM(C28:N28) -> 0 | R28: 12 Hours | S28: =SUM(S10:S21) -> 7 | T28: =SUM(T10:T21) -> 15 | U28: =SUM(U10:U21) -> 10 | V28: =SUM(V10:V21) -> 0 | W28: =SUM(W10:W21) -> 1 | X28: =SUM(X10:X21) -> 2 | Y28: =SUM(Y10:Y21) -> 5 | Z28: =SUM(Z10:Z21) -> 18 | ... AF28: =SUM(AF10:AF21) -> 89
B29: 11.45 - 12.00 | C29: 1 | D29: 0 | E29: 0 | F29: 0 | G29: 0 | H29: 0 | I29: 0 | J29: 0 | K29: 0 | L29: 0 | M29: 0 | N29: 0 | O29: =SUM(C29:L29,N29) -> 1 | P29: =SUM(C29:N29) -> 1
B30: 12.00 - 12.15 | C30: 0 | D30: 0 | E30: 0 | F30: 0 | G30: 0 | H30: 0 | I30: 0 | J30: 0 | K30: 0 | L30: 0 | M30: 0 | N30: 0 | O30: =SUM(C30:L30,N30) -> 0 | P30: =SUM(C30:N30) -> 0
B31: 12.15 - 12.30 | C31: 0 | D31: 0 | E31: 2 | F31: 0 | G31: 0 | H31: 0 | I31: 0 | J31: 1 | K31: 0 | L31: 0 | M31: 0 | N31: 0 | O31: =SUM(C31:L31,N31) -> 3 | P31: =SUM(C31:N31) -> 3
B32: 12.30 - 12.45 | C32: 0 | D32: 0 | E32: 0 | F32: 0 | G32: 0 | H32: 0 | I32: 0 | J32: 0 | K32: 0 | L32: 0 | M32: 1 | N32: 0 | O32: =SUM(C32:L32,N32) -> 0 | P32: =SUM(C32:N32) -> 1
B33: 12.45 - 13.00 | C33: 2 | D33: 1 | E33: 0 | F33: 0 | G33: 0 | H33: 0 | I33: 0 | J33: 1 | K33: 0 | L33: 0 | M33: 0 | N33: 0 | O33: =SUM(C33:L33,N33) -> 4 | P33: =SUM(C33:N33) -> 4
B34: 13.00 - 13.15 | C34: 0 | D34: 0 | E34: 1 | F34: 0 | G34: 0 | H34: 0 | I34: 0 | J34: 0 | K34: 0 | L34: 0 | M34: 0 | N34: 0 | O34: =SUM(C34:L34,N34) -> 1 | P34: =SUM(C34:N34) -> 1
B35: 13.15 - 13.30 | C35: 0 | D35: 0 | E35: 0 | F35: 0 | G35: 0 | H35: 0 | I35: 0 | J35: 0 | K35: 0 | L35: 0 | M35: 2 | N35: 0 | O35: =SUM(C35:L35,N35) -> 0 | P35: =SUM(C35:N35) -> 2
B36: 13.30 - 13.45 | C36: 0 | D36: 0 | E36: 0 | F36: 0 | G36: 0 | H36: 0 | I36: 0 | J36: 2 | K36: 0 | L36: 0 | M36: 0 | N36: 0 | O36: =SUM(C36:L36,N36) -> 2 | P36: =SUM(C36:N36) -> 2
B37: 13.45 - 14.00 | C37: 0 | D37: 0 | E37: 0 | F37: 0 | G37: 0 | H37: 0 | I37: 0 | J37: 1 | K37: 0 | L37: 0 | M37: 0 | N37: 0 | O37: =SUM(C37:L37,N37) -> 1 | P37: =SUM(C37:N37) -> 1
B38: 14.00 - 14.15 | C38: 0 | D38: 2 | E38: 0 | F38: 0 | G38: 0 | H38: 0 | I38: 0 | J38: 0 | K38: 0 | L38: 0 | M38: 0 | N38: 0 | O38: =SUM(C38:L38,N38) -> 2 | P38: =SUM(C38:N38) -> 2
B39: 14.15 - 14.30 | C39: 0 | D39: 0 | E39: 0 | F39: 0 | G39: 0 | H39: 0 | I39: 0 | J39: 0 | K39: 0 | L39: 0 | M39: 1 | N39: 0 | O39: =SUM(C39:L39,N39) -> 0 | P39: =SUM(C39:N39) -> 1
B40: 14.30 - 14.45 | C40: 0 | D40: 0 | E40: 0 | F40: 0 | G40: 0 | H40: 0 | I40: 0 | J40: 0 | K40: 0 | L40: 0 | M40: 0 | N40: 0 | O40: =SUM(C40:L40,N40) -> 0 | P40: =SUM(C40:N40) -> 0
... B57: 18.45 - 19.00 | C57: 0 | D57: 0 | E57: 0 | F57: 0 | G57: 0 | H57: 0 | I57: 0 | J57: 0 | K57: 0 | L57: 0 | M57: 0 | N57: 0 | O57: =SUM(C57:L57,N57) -> 0 | P57: =SUM(C57:N57) -> 0
B58: Totals | C58: =SUM(C10:C57) -> 7 | D58: =SUM(D10:D57) -> 15 | E58: =SUM(E10:E57) -> 10 | F58: =SUM(F10:F57) -> 0 | G58: =SUM(G10:G57) -> 1 | H58: =SUM(H10:H57) -> 2 | I58: =SUM(I10:I57) -> 5 | J58: =SUM(J10:J57) -> 18 | ... P58: =SUM(P10:P57) -> 89
...

Sheet 06.07 KABONG-KOTIDO
B1: Consultancy services for Preparation of Expressway Development Master Plan (EDMP) for Uganda
B2: MANUAL CLASSIFIED COUNT (MCC)
B3: ROAD NAME: | C3: ='05.08 KABONG-KOTIDO'!C3:G3 -> MCC - C5 - STN0125 - KAABONG-KOTIDO ROAD
C5: Date | D5: 06.08.19 | F5: Location | G5: ='05.08 KABONG-KOTIDO'!G5:H5 -> xxx | J5: Surveyor | K5: ='05.08 KABONG-KOTIDO'!K5:L5 -> NALUBEGA JOSEPHINE
C6: Dir. From | D6: ='05.08 KABONG-KOTIDO'!D6:E6 -> KABONG | F6: Dir. To | G6: ='05.08 KABONG-KOTIDO'!G6:H6 -> KOTIDO | J6: Supervisor | K6: ='05.08 KABONG-KOTIDO'!K6:L6 -> CRANIMER
B8: Time / Veh Type | R8: SUMMARY TRAFFIC VOLUMES
C9: 1. Car | D9: 2. Station Wagon | E9: 3. Pickups | F9: 4. Minibus, matatu | G9: 5. Medium bus | H9: 6. Large Bus | I9: 7. Light Truck | J9: 8. Medium Truck | K9: 9. Heavy truck | L9: 10. Truck Trailer | M9: 11. Motor cycles | N9: 12. Tractors | O9: Total Excl M/Cycles | P9: Total All | R9: Time | S9: 1. Car | T9: 2. Station Wagon | U9: 3. Pickups | V9: 4. Minibus, matatu | W9: 5. Medium bus | X9: 6. Large Bus | Y9: 7. Light Truck | Z9: 8. Medium Truck | AA9: 9. Heavy truck | AB9: 10. Truck Trailer | AC9: 11. Motorcycles | AD9: 12. Tractors, Graders | AE9: Total Excl M/ Cycles | AF9: Total All
B10: 07.00 - 07.15 | C10: 0 | D10: 0 | E10: 1 | F10: 0 | G10: 0 | H10: 0 | I10: 2 | J10: 0 | K10: 0 | L10: 0 | M10: 1 | N10: 0 | O10: =SUM(C10:L10,N10) -> 3 | P10: =SUM(C10:N10) -> 4 | R10: 0700-0800 | S10: =SUM(C10:C13) -> 3 | T10: =SUM(D10:D13) -> 0 | U10: =SUM(E10:E13) -> 3 | V10: =SUM(F10:F13) -> 0 | W10: =SUM(G10:G13) -> 0 | X10: =SUM(H10:H13) -> 0 | Y10: =SUM(I10:I13) -> 3 | Z10: =SUM(J10:J13) -> 1 | ... AF10: =SUM(P10:P13) -> 13
B11: 07.15 - 07.30 | C11: 2 | D11: 0 | E11: 0 | F11: 0 | G11: 0 | H11: 0 | I11: 0 | J11: 0 | K11: 0 | L11: 0 | M11: 0 | N11: 0 | O11: =SUM(C11:L11,N11) -> 2 | P11: =SUM(C11:N11) -> 2 | R11: 0800-0900 | S11: =SUM(C14:C17) -> 0 | T11: =SUM(D14:D17) -> 1 | U11: =SUM(E14:E17) -> 0 | V11: =SUM(F14:F17) -> 0 | W11: =SUM(G14:G17) -> 0 | X11: =SUM(H14:H17) -> 0 | Y11: =SUM(I14:I17) -> 1 | Z11: =SUM(J14:J17) -> 2 | ... AF11: =SUM(P14:P17) -> 6
B12: 07.30 - 07.45 | C12: 0 | D12: 0 | E12: 0 | F12: 0 | G12: 0 | H12: 0 | I12: 0 | J12: 0 | K12: 0 | L12: 0 | M12: 2 | N12: 0 | O12: =SUM(C12:L12,N12) -> 0 | P12: =SUM(C12:N12) -> 2 | R12: 0900-1000 | S12: =SUM(C18:C21) -> 0 | T12: =SUM(D18:D21) -> 0 | U12: =SUM(E18:E21) -> 2 | V12: =SUM(F18:F21) -> 0 | W12: =SUM(G18:G21) -> 0 | X12: =SUM(H18:H21) -> 0 | Y12: =SUM(I18:I21) -> 2 | Z12: =SUM(J18:J21) -> 0 | ... AF12: =SUM(P18:P21) -> 7
B13: 07.45 - 08.00 | C13: 1 | D13: 0 | E13: 2 | F13: 0 | G13: 0 | H13: 0 | I13: 1 | J13: 1 | K13: 0 | L13: 0 | M13: 0 | N13: 0 | O13: =SUM(C13:L13,N13) -> 5 | P13: =SUM(C13:N13) -> 5 | R13: 1000-1100 | S13: =SUM(C22:C25) -> 0 | T13: =SUM(D22:D25) -> 3 | U13: =SUM(E22:E25) -> 0 | V13: =SUM(F22:F25) -> 0 | W13: =SUM(G22:G25) -> 0 | X13: =SUM(H22:H25) -> 0 | Y13: =SUM(I22:I25) -> 2 | Z13: =SUM(J22:J25) -> 1 | ... AF13: =SUM(P22:P25) -> 7
B14: 08.00 - 08.15 | C14: 0 | D14: 0 | E14: 0 | F14: 0 | G14: 0 | H14: 0 | I14: 0 | J14: 0 | K14: 0 | L14: 0 | M14: 0 | N14: 0 | O14: =SUM(C14:L14,N14) -> 0 | P14: =SUM(C14:N14) -> 0 | R14: 1100-1200 | S14: =SUM(C26:C29) -> 0 | T14: =SUM(D26:D29) -> 0 | U14: =SUM(E26:E29) -> 0 | V14: =SUM(F26:F29) -> 0 | W14: =SUM(G26:G29) -> 0 | X14: =SUM(H26:H29) -> 0 | Y14: =SUM(I26:I29) -> 0 | Z14: =SUM(J26:J29) -> 0 | ... AF14: =SUM(P26:P29) -> 1
B15: 08.15 - 08.30 | C15: 0 | D15: 0 | E15: 0 | F15: 0 | G15: 0 | H15: 0 | I15: 1 | J15: 2 | K15: 0 | L15: 0 | M15: 0 | N15: 0 | O15: =SUM(C15:L15,N15) -> 3 | P15: =SUM(C15:N15) -> 3 | R15: 1200-1300 | S15: =SUM(C30:C33) -> 0 | T15: =SUM(D30:D33) -> 0 | U15: =SUM(E30:E33) -> 0 | V15: =SUM(F30:F33) -> 0 | W15: =SUM(G30:G33) -> 0 | X15: =SUM(H30:H33) -> 0 | Y15: =SUM(I30:I33) -> 0 | Z15: =SUM(J30:J33) -> 0 | ... AF15: =SUM(P30:P33) -> 1
B16: 08.30 - 08.45 | C16: 0 | D16: 0 | E16: 0 | F16: 0 | G16: 0 | H16: 0 | I16: 0 | J16: 0 | K16: 0 | L16: 0 | M16: 0 | N16: 0 | O16: =SUM(C16:L16,N16) -> 0 | P16: =SUM(C16:N16) -> 0 | R16: 1300-1400 | S16: =SUM(C34:C37) -> 0 | T16: =SUM(D34:D37) -> 2 | U16: =SUM(E34:E37) -> 0 | V16: =SUM(F34:F37) -> 0 | W16: =SUM(G34:G37) -> 0 | X16: =SUM(H34:H37) -> 0 | Y16: =SUM(I34:I37) -> 1 | Z16: =SUM(J34:J37) -> 2 | ... AF16: =SUM(P34:P37) -> 6
B17: 08.45 - 9.00 | C17: 0 | D17: 1 | E17: 0 | F17: 0 | G17: 0 | H17: 0 | I17: 0 | J17: 0 | K17: 0 | L17: 0 | M17: 2 | N17: 0 | O17: =SUM(C17:L17,N17) -> 1 | P17: =SUM(C17:N17) -> 3 | R17: 1400-1500 | S17: =SUM(C38:C41) -> 0 | T17: =SUM(D38:D41) -> 1 | U17: =SUM(E38:E41) -> 2 | V17: =SUM(F38:F41) -> 0 | W17: =SUM(G38:G41) -> 0 | X17: =SUM(H38:H41) -> 0 | Y17: =SUM(I38:I41) -> 1 | Z17: =SUM(J38:J41) -> 0 | ... AF17: =SUM(P38:P41) -> 5
B18: 09.00 - 09.15 | C18: 0 | D18: 0 | E18: 0 | F18: 0 | G18: 0 | H18: 0 | I18: 1 | J18: 0 | K18: 0 | L18: 0 | M18: 1 | N18: 0 | O18: =SUM(C18:L18,N18) -> 1 | P18: =SUM(C18:N18) -> 2 | R18: 1500-1600 | S18: =SUM(C42:C45) -> 0 | T18: =SUM(D42:D45) -> 1 | U18: =SUM(E42:E45) -> 0 | V18: =SUM(F42:F45) -> 0 | W18: =SUM(G42:G45) -> 0 | X18: =SUM(H42:H45) -> 0 | Y18: =SUM(I42:I45) -> 1 | Z18: =SUM(J42:J45) -> 0 | ... AF18: =SUM(P42:P45) -> 3
B19: 09.15 - 09.30 | C19: 0 | D19: 0 | E19: 1 | F19: 0 | G19: 0 | H19: 0 | I19: 1 | J19: 0 | K19: 0 | L19: 0 | M19: 0 | N19: 0 | O19: =SUM(C19:L19,N19) -> 2 | P19: =SUM(C19:N19) -> 2 | R19: 1600-1700 | S19: =SUM(C46:C49) -> 0 | T19: =SUM(D46:D49) -> 1 | U19: =SUM(E46:E49) -> 0 | V19: =SUM(F46:F49) -> 0 | W19: =SUM(G46:G49) -> 0 | X19: =SUM(H46:H49) -> 0 | Y19: =SUM(I46:I49) -> 1 | Z19: =SUM(J46:J49) -> 0 | ... AF19: =SUM(P46:P49) -> 4
B20: 09.30 - 09.45 | C20: 0 | D20: 0 | E20: 1 | F20: 0 | G20: 0 | H20: 0 | I20: 0 | J20: 0 | K20: 0 | L20: 0 | M20: 2 | N20: 0 | O20: =SUM(C20:L20,N20) -> 1 | P20: =SUM(C20:N20) -> 3 | R20: 1700-1800 | S20: =SUM(C50:C53) -> 0 | T20: =SUM(D50:D53) -> 0 | U20: =SUM(E50:E53) -> 4 | V20: =SUM(F50:F53) -> 0 | W20: =SUM(G50:G53) -> 0 | X20: =SUM(H50:H53) -> 0 | Y20: =SUM(I50:I53) -> 1 | Z20: =SUM(J50:J53) -> 1 | ... AF20: =SUM(P50:P53) -> 10
B21: 09.45 - 10.00 | C21: 0 | D21: 0 | E21: 0 | F21: 0 | G21: 0 | H21: 0 | I21: 0 | J21: 0 | K21: 0 | L21: 0 | M21: 0 | N21: 0 | O21: =SUM(C21:L21,N21) -> 0 | P21: =SUM(C21:N21) -> 0 | R21: 1800-1900 | S21: =SUM(C54:C57) -> 1 | T21: =SUM(D54:D57) -> 2 | U21: =SUM(E54:E57) -> 1 | V21: =SUM(F54:F57) -> 0 | W21: =SUM(G54:G57) -> 0 | X21: =SUM(H54:H57) -> 0 | Y21: =SUM(I54:I57) -> 0 | Z21: =SUM(J54:J57) -> 2 | ... AF21: =SUM(P54:P57) -> 9
B22: 10.00 - 10.15 | C22: 0 | D22: 1 | E22: 0 | F22: 0 | G22: 0 | H22: 0 | I22: 0 | J22: 0 | K22: 0 | L22: 0 | M22: 1 | N22: 0 | O22: =SUM(C22:L22,N22) -> 1 | P22: =SUM(C22:N22) -> 2 | R22: AM Peak Hr | S22: =MAX(S10:S12) -> 3 | T22: =MAX(T10:T12) -> 1 | U22: =MAX(U10:U12) -> 3 | V22: =MAX(V10:V12) -> 0 | W22: =MAX(W10:W12) -> 0 | X22: =MAX(X10:X12) -> 0 | Y22: =MAX(Y10:Y12) -> 3 | Z22: =MAX(Z10:Z12) -> 2 | ... AF22: =MAX(AF10:AF12) -> 13
B23: 10.15 - 10.30 | C23: 0 | D23: 0 | E23: 0 | F23: 0 | G23: 0 | H23: 0 | I23: 2 | J23: 0 | K23: 0 | L23: 0 | M23: 0 | N23: 0 | O23: =SUM(C23:L23,N23) -> 2 | P23: =SUM(C23:N23) -> 2 | R23: IP Peak Hr | S23: =MAX(S13:S18) -> 0 | T23: =MAX(T13:T18) -> 3 | U23: =MAX(U13:U18) -> 2 | V23: =MAX(V13:V18) -> 0 | W23: =MAX(W13:W18) -> 0 | X23: =MAX(X13:X18) -> 0 | Y23: =MAX(Y13:Y18) -> 2 | Z23: =MAX(Z13:Z18) -> 2 | ... AF23: =MAX(AF13:AF18) -> 7
B24: 10.30 - 10.45 | C24: 0 | D24: 1 | E24: 0 | F24: 0 | G24: 0 | H24: 0 | I24: 0 | J24: 1 | K24: 0 | L24: 0 | M24: 0 | N24: 0 | O24: =SUM(C24:L24,N24) -> 2 | P24: =SUM(C24:N24) -> 2 | R24: PM Peak Hr | S24: =MAX(S19:S21) -> 1 | T24: =MAX(T19:T21) -> 2 | U24: =MAX(U19:U21) -> 4 | V24: =MAX(V19:V21) -> 0 | W24: =MAX(W19:W21) -> 0 | X24: =MAX(X19:X21) -> 0 | Y24: =MAX(Y19:Y21) -> 1 | Z24: =MAX(Z19:Z21) -> 2 | ... AF24: =MAX(AF19:AF21) -> 10
B25: 10.45 - 11.00 | C25: 0 | D25: 1 | E25: 0 | F25: 0 | G25: 0 | H25: 0 | I25: 0 | J25: 0 | K25: 0 | L25: 0 | M25: 0 | N25: 0 | O25: =SUM(C25:L25,N25) -> 1 | P25: =SUM(C25:N25) -> 1 | R25: AM Period | S25: =SUM(S10:S12) -> 3 | T25: =SUM(T10:T12) -> 1 | U25: =SUM(U10:U12) -> 5 | V25: =SUM(V10:V12) -> 0 | W25: =SUM(W10:W12) -> 0 | X25: =SUM(X10:X12) -> 0 | Y25: =SUM(Y10:Y12) -> 6 | Z25: =SUM(Z10:Z12) -> 3 | ... AF25: =SUM(AF10:AF12) -> 26
B26: 11.00 - 11.15 | C26: 0 | D26: 0 | E26: 0 | F26: 0 | G26: 0 | H26: 0 | I26: 0 | J26: 0 | K26: 0 | L26: 0 | M26: 0 | N26: 0 | O26: =SUM(C26:L26,N26) -> 0 | P26: =SUM(C26:N26) -> 0 | R26: IP Period | S26: =SUM(S13:S18) -> 0 | T26: =SUM(T13:T18) -> 7 | U26: =SUM(U13:U18) -> 2 | V26: =SUM(V13:V18) -> 0 | W26: =SUM(W13:W18) -> 0 | X26: =SUM(X13:X18) -> 0 | Y26: =SUM(Y13:Y18) -> 5 | Z26: =SUM(Z13:Z18) -> 3 | ... AF26: =SUM(AF13:AF18) -> 23
B27: 11.15 - 11.30 | C27: 0 | D27: 0 | E27: 0 | F27: 0 | G27: 0 | H27: 0 | I27: 0 | J27: 0 | K27: 0 | L27: 0 | M27: 0 | N27: 0 | O27: =SUM(C27:L27,N27) -> 0 | P27: =SUM(C27:N27) -> 0 | R27: PM Period | S27: =SUM(S19:S21) -> 1 | T27: =SUM(T19:T21) -> 3 | U27: =SUM(U19:U21) -> 5 | V27: =SUM(V19:V21) -> 0 | W27: =SUM(W19:W21) -> 0 | X27: =SUM(X19:X21) -> 0 | Y27: =SUM(Y19:Y21) -> 2 | Z27: =SUM(Z19:Z21) -> 3 | ... AF27: =SUM(AF19:AF21) -> 23
B28: 11.30 - 11.45 | C28: 0 | D28: 0 | E28: 0 | F28: 0 | G28: 0 | H28: 0 | I28: 0 | J28: 0 | K28: 0 | L28: 0 | M28: 0 | N28: 0 | O28: =SUM(C28:L28,N28) -> 0 | P28: =SUM(C28:N28) -> 0 | R28: 12 Hours | S28: =SUM(S10:S21) -> 4 | T28: =SUM(T10:T21) -> 11 | U28: =SUM(U10:U21) -> 12 | V28: =SUM(V10:V21) -> 0 | W28: =SUM(W10:W21) -> 0 | X28: =SUM(X10:X21) -> 0 | Y28: =SUM(Y10:Y21) -> 13 | Z28: =SUM(Z10:Z21) -> 9 | ... AF28: =SUM(AF10:AF21) -> 72
B29: 11.45 - 12.00 | C29: 0 | D29: 0 | E29: 0 | F29: 0 | G29: 0 | H29: 0 | I29: 0 | J29: 0 | K29: 0 | L29: 0 | M29: 1 | N29: 0 | O29: =SUM(C29:L29,N29) -> 0 | P29: =SUM(C29:N29) -> 1
B30: 12.00 - 12.15 | C30: 0 | D30: 0 | E30: 0 | F30: 0 | G30: 0 | H30: 0 | I30: 0 | J30: 0 | K30: 0 | L30: 0 | M30: 1 | N30: 0 | O30: =SUM(C30:L30,N30) -> 0 | P30: =SUM(C30:N30) -> 1
B31: 12.15 - 12.30 | C31: 0 | D31: 0 | E31: 0 | F31: 0 | G31: 0 | H31: 0 | I31: 0 | J31: 0 | K31: 0 | L31: 0 | M31: 0 | N31: 0 | O31: =SUM(C31:L31,N31) -> 0 | P31: =SUM(C31:N31) -> 0
B32: 12.30 - 12.45 | C32: 0 | D32: 0 | E32: 0 | F32: 0 | G32: 0 | H32: 0 | I32: 0 | J32: 0 | K32: 0 | L32: 0 | M32: 0 | N32: 0 | O32: =SUM(C32:L32,N32) -> 0 | P32: =SUM(C32:N32) -> 0
B33: 12.45 - 13.00 | C33: 0 | D33: 0 | E33: 0 | F33: 0 | G33: 0 | H33: 0 | I33: 0 | J33: 0 | K33: 0 | L33: 0 | M33: 0 | N33: 0 | O33: =SUM(C33:L33,N33) -> 0 | P33: =SUM(C33:N33) -> 0
B34: 13.00 - 13.15 | C34: 0 | D34: 0 | E34: 0 | F34: 0 | G34: 0 | H34: 0 | I34: 1 | J34: 0 | K34: 0 | L34: 0 | M34: 0 | N34: 0 | O34: =SUM(C34:L34,N34) -> 1 | P34: =SUM(C34:N34) -> 1
B35: 13.15 - 13.30 | C35: 0 | D35: 2 | E35: 0 | F35: 0 | G35: 0 | H35: 0 | I35: 0 | J35: 0 | K35: 0 | L35: 0 | M35: 1 | N35: 0 | O35: =SUM(C35:L35,N35) -> 2 | P35: =SUM(C35:N35) -> 3
B36: 13.30 - 13.45 | C36: 0 | D36: 0 | E36: 0 | F36: 0 | G36: 0 | H36: 0 | I36: 0 | J36: 1 | K36: 0 | L36: 0 | M36: 0 | N36: 0 | O36: =SUM(C36:L36,N36) -> 1 | P36: =SUM(C36:N36) -> 1
B37: 13.45 - 14.00 | C37: 0 | D37: 0 | E37: 0 | F37: 0 | G37: 0 | H37: 0 | I37: 0 | J37: 1 | K37: 0 | L37: 0 | M37: 0 | N37: 0 | O37: =SUM(C37:L37,N37) -> 1 | P37: =SUM(C37:N37) -> 1
B38: 14.00 - 14.15 | C38: 0 | D38: 0 | E38: 0 | F38: 0 | G38: 0 | H38: 0 | I38: 1 | J38: 0 | K38: 0 | L38: 0 | M38: 1 | N38: 0 | O38: =SUM(C38:L38,N38) -> 1 | P38: =SUM(C38:N38) -> 2
B39: 14.15 - 14.30 | C39: 0 | D39: 0 | E39: 1 | F39: 0 | G39: 0 | H39: 0 | I39: 0 | J39: 0 | K39: 0 | L39: 0 | M39: 0 | N39: 0 | O39: =SUM(C39:L39,N39) -> 1 | P39: =SUM(C39:N39) -> 1
B40: 14.30 - 14.45 | C40: 0 | D40: 1 | E40: 0 | F40: 0 | G40: 0 | H40: 0 | I40: 0 | J40: 0 | K40: 0 | L40: 0 | M40: 0 | N40: 0 | O40: =SUM(C40:L40,N40) -> 1 | P40: =SUM(C40:N40) -> 1
... B57: 18.45 - 19.00 | C57: 0 | D57: 1 | E57: 0 | F57: 0 | G57: 0 | H57: 0 | I57: 0 | J57: 0 | K57: 0 | L57: 0 | M57: 2 | N57: 0 | O57: =SUM(C57:L57,N57) -> 1 | P57: =SUM(C57:N57) -> 3
B58: Totals | C58: =SUM(C10:C57) -> 4 | D58: =SUM(D10:D57) -> 11 | E58: =SUM(E10:E57) -> 12 | F58: =SUM(F10:F57) -> 0 | G58: =SUM(G10:G57) -> 0 | H58: =SUM(H10:H57) -> 0 | I58: =SUM(I10:I57) -> 13 | J58: =SUM(J10:J57) -> 9 | ... P58: =SUM(P10:P57) -> 72
...

Sheet 06.08 KOTIDO-KABONG
B1: Consultancy services for Preparation of Expressway Development Master Plan (EDMP) for Uganda
B2: MANUAL CLASSIFIED COUNT (MCC)
B3: ROAD NAME: | C3: ='05.08 KOTIDO-KABONG'!C3:G3 -> MCC - C5 - STN0125 - KAABONG-KOTIDO ROAD
C5: Date | D5: ='06.07 KABONG-KOTIDO'!D5 -> 06.08.19 | F5: Location | G5: ='05.08 KABONG-KOTIDO'!G5:H5 -> xxx | J5: Surveyor | K5: ='05.08 KABONG-KOTIDO'!K5:L5 -> NALUBEGA JOSEPHINE
C6: Dir. From | D6: ='05.08 KOTIDO-KABONG'!D6:E6 -> KITIDO | F6: Dir. To | G6: ='05.08 KOTIDO-KABONG'!G6:H6 -> KABONG | J6: Supervisor | K6: ='05.08 KABONG-KOTIDO'!K6:L6 -> CRANIMER
B8: Time / Veh Type | R8: SUMMARY TRAFFIC VOLUMES
C9: 1. Car | D9: 2. Station Wagon | E9: 3. Pickups | F9: 4. Minibus, matatu | G9: 5. Medium bus | H9: 6. Large Bus | I9: 7. Light Truck | J9: 8. Medium Truck | K9: 9. Heavy truck | L9: 10. Truck Trailer | M9: 11. Motor cycles | N9: 12. Tractors | O9: Total Excl M/Cycles | P9: Total All | R9: Time | S9: 1. Car | T9: 2. Station Wagon | U9: 3. Pickups | V9: 4. Minibus, matatu | W9: 5. Medium bus | X9: 6. Large Bus | Y9: 7. Light Truck | Z9: 8. Medium Truck | AA9: 9. Heavy truck | AB9: 10. Truck Trailer | AC9: 11. Motorcycles | AD9: 12. Tractors, Graders | AE9: Total Excl M/ Cycles | AF9: Total All
B10: 07.00 - 07.15 | C10: 1 | D10: 0 | E10: 0 | F10: 0 | G10: 0 | H10: 0 | I10: 0 | J10: 0 | K10: 0 | L10: 0 | M10: 3 | N10: 0 | O10: =SUM(C10:L10,N10) -> 1 | P10: =SUM(C10:N10) -> 4 | R10: 0700-0800 | S10: =SUM(C10:C13) -> 1 | T10: =SUM(D10:D13) -> 1 | U10: =SUM(E10:E13) -> 1 | V10: =SUM(F10:F13) -> 0 | W10: =SUM(G10:G13) -> 0 | X10: =SUM(H10:H13) -> 0 | Y10: =SUM(I10:I13) -> 0 | Z10: =SUM(J10:J13) -> 2 | ... AF10: =SUM(P10:P13) -> 9
B11: 07.15 - 07.30 | C11: 0 | D11: 1 | E11: 0 | F11: 0 | G11: 0 | H11: 0 | I11: 0 | J11: 1 | K11: 0 | L11: 0 | M11: 1 | N11: 0 | O11: =SUM(C11:L11,N11) -> 2 | P11: =SUM(C11:N11) -> 3 | R11: 0800-0900 | S11: =SUM(C14:C17) -> 1 | T11: =SUM(D14:D17) -> 1 | U11: =SUM(E14:E17) -> 3 | V11: =SUM(F14:F17) -> 0 | W11: =SUM(G14:G17) -> 0 | X11: =SUM(H14:H17) -> 0 | Y11: =SUM(I14:I17) -> 3 | Z11: =SUM(J14:J17) -> 1 | ... AF11: =SUM(P14:P17) -> 11
B12: 07.30 - 07.45 | C12: 0 | D12: 0 | E12: 1 | F12: 0 | G12: 0 | H12: 0 | I12: 0 | J12: 1 | K12: 0 | L12: 0 | M12: 0 | N12: 0 | O12: =SUM(C12:L12,N12) -> 2 | P12: =SUM(C12:N12) -> 2 | R12: 0900-1000 | S12: =SUM(C18:C21) -> 0 | T12: =SUM(D18:D21) -> 3 | U12: =SUM(E18:E21) -> 1 | V12: =SUM(F18:F21) -> 0 | W12: =SUM(G18:G21) -> 0 | X12: =SUM(H18:H21) -> 0 | Y12: =SUM(I18:I21) -> 0 | Z12: =SUM(J18:J21) -> 0 | ... AF12: =SUM(P18:P21) -> 7
B13: 07.45 - 08.00 | C13: 0 | D13: 0 | E13: 0 | F13: 0 | G13: 0 | H13: 0 | I13: 0 | J13: 0 | K13: 0 | L13: 0 | M13: 0 | N13: 0 | O13: =SUM(C13:L13,N13) -> 0 | P13: =SUM(C13:N13) -> 0 | R13: 1000-1100 | S13: =SUM(C22:C25) -> 0 | T13: =SUM(D22:D25) -> 1 | U13: =SUM(E22:E25) -> 2 | V13: =SUM(F22:F25) -> 0 | W13: =SUM(G22:G25) -> 0 | X13: =SUM(H22:H25) -> 0 | Y13: =SUM(I22:I25) -> 1 | Z13: =SUM(J22:J25) -> 0 | ... AF13: =SUM(P22:P25) -> 5
B14: 08.00 - 08.15 | C14: 0 | D14: 0 | E14: 2 | F14: 0 | G14: 0 | H14: 0 | I14: 2 | J14: 0 | K14: 0 | L14: 0 | M14: 0 | N14: 0 | O14: =SUM(C14:L14,N14) -> 4 | P14: =SUM(C14:N14) -> 4 | R14: 1100-1200 | S14: =SUM(C26:C29) -> 1 | T14: =SUM(D26:D29) -> 3 | U14: =SUM(E26:E29) -> 0 | V14: =SUM(F26:F29) -> 0 | W14: =SUM(G26:G29) -> 0 | X14: =SUM(H26:H29) -> 0 | Y14: =SUM(I26:I29) -> 0 | Z14: =SUM(J26:J29) -> 2 | ... AF14: =SUM(P26:P29) -> 6
B15: 08.15 - 08.30 | C15: 1 | D15: 0 | E15: 0 | F15: 0 | G15: 0 | H15: 0 | I15: 0 | J15: 0 | K15: 0 | L15: 0 | M15: 2 | N15: 0 | O15: =SUM(C15:L15,N15) -> 1 | P15: =SUM(C15:N15) -> 3 | R15: 1200-1300 | S15: =SUM(C30:C33) -> 0 | T15: =SUM(D30:D33) -> 1 | U15: =SUM(E30:E33) -> 0 | V15: =SUM(F30:F33) -> 0 | W15: =SUM(G30:G33) -> 0 | X15: =SUM(H30:H33) -> 1 | Y15: =SUM(I30:I33) -> 1 | Z15: =SUM(J30:J33) -> 0 | ... AF15: =SUM(P30:P33) -> 6
B16: 08.30 - 08.45 | C16: 0 | D16: 0 | E16: 0 | F16: 0 | G16: 0 | H16: 0 | I16: 1 | J16: 1 | K16: 0 | L16: 0 | M16: 0 | N16: 0 | O16: =SUM(C16:L16,N16) -> 2 | P16: =SUM(C16:N16) -> 2 | R16: 1300-1400 | S16: =SUM(C34:C37) -> 0 | T16: =SUM(D34:D37) -> 0 | U16: =SUM(E34:E37) -> 1 | V16: =SUM(F34:F37) -> 0 | W16: =SUM(G34:G37) -> 0 | X16: =SUM(H34:H37) -> 0 | Y16: =SUM(I34:I37) -> 0 | Z16: =SUM(J34:J37) -> 0 | ... AF16: =SUM(P34:P37) -> 3
B17: 08.45 - 9.00 | C17: 0 | D17: 1 | E17: 1 | F17: 0 | G17: 0 | H17: 0 | I17: 0 | J17: 0 | K17: 0 | L17: 0 | M17: 0 | N17: 0 | O17: =SUM(C17:L17,N17) -> 2 | P17: =SUM(C17:N17) -> 2 | R17: 1400-1500 | S17: =SUM(C38:C41) -> 0 | T17: =SUM(D38:D41) -> 1 | U17: =SUM(E38:E41) -> 0 | V17: =SUM(F38:F41) -> 0 | W17: =SUM(G38:G41) -> 0 | X17: =SUM(H38:H41) -> 0 | Y17: =SUM(I38:I41) -> 0 | Z17: =SUM(J38:J41) -> 1 | ... AF17: =SUM(P38:P41) -> 5
B18: 09.00 - 09.15 | C18: 0 | D18: 1 | E18: 0 | F18: 0 | G18: 0 | H18: 0 | I18: 0 | J18: 0 | K18: 0 | L18: 0 | M18: 1 | N18: 0 | O18: =SUM(C18:L18,N18) -> 1 | P18: =SUM(C18:N18) -> 2 | R18: 1500-1600 | S18: =SUM(C42:C45) -> 0 | T18: =SUM(D42:D45) -> 0 | U18: =SUM(E42:E45) -> 0 | V18: =SUM(F42:F45) -> 0 | W18: =SUM(G42:G45) -> 0 | X18: =SUM(H42:H45) -> 1 | Y18: =SUM(I42:I45) -> 0 | Z18: =SUM(J42:J45) -> 0 | ... AF18: =SUM(P42:P45) -> 16
B19: 09.15 - 09.30 | C19: 0 | D19: 1 | E19: 0 | F19: 0 | G19: 0 | H19: 0 | I19: 0 | J19: 0 | K19: 0 | L19: 0 | M19: 1 | N19: 0 | O19: =SUM(C19:L19,N19) -> 1 | P19: =SUM(C19:N19) -> 2 | R19: 1600-1700 | S19: =SUM(C46:C49) -> 0 | T19: =SUM(D46:D49) -> 3 | U19: =SUM(E46:E49) -> 0 | V19: =SUM(F46:F49) -> 0 | W19: =SUM(G46:G49) -> 0 | X19: =SUM(H46:H49) -> 0 | Y19: =SUM(I46:I49) -> 0 | Z19: =SUM(J46:J49) -> 1 | ... AF19: =SUM(P46:P49) -> 5
B20: 09.30 - 09.45 | C20: 0 | D20: 1 | E20: 0 | F20: 0 | G20: 0 | H20: 0 | I20: 0 | J20: 0 | K20: 0 | L20: 0 | M20: 0 | N20: 0 | O20: =SUM(C20:L20,N20) -> 1 | P20: =SUM(C20:N20) -> 1 | R20: 1700-1800 | S20: =SUM(C50:C53) -> 1 | T20: =SUM(D50:D53) -> 0 | U20: =SUM(E50:E53) -> 0 | V20: =SUM(F50:F53) -> 0 | W20: =SUM(G50:G53) -> 0 | X20: =SUM(H50:H53) -> 1 | Y20: =SUM(I50:I53) -> 0 | Z20: =SUM(J50:J53) -> 0 | ... AF20: =SUM(P50:P53) -> 2
B21: 09.45 - 10.00 | C21: 0 | D21: 0 | E21: 1 | F21: 0 | G21: 0 | H21: 0 | I21: 0 | J21: 0 | K21: 0 | L21: 0 | M21: 1 | N21: 0 | O21: =SUM(C21:L21,N21) -> 1 | P21: =SUM(C21:N21) -> 2 | R21: 1800-1900 | S21: =SUM(C54:C57) -> 1 | T21: =SUM(D54:D57) -> 1 | U21: =SUM(E54:E57) -> 0 | V21: =SUM(F54:F57) -> 0 | W21: =SUM(G54:G57) -> 0 | X21: =SUM(H54:H57) -> 0 | Y21: =SUM(I54:I57) -> 1 | Z21: =SUM(J54:J57) -> 2 | ... AF21: =SUM(P54:P57) -> 7
B22: 10.00 - 10.15 | C22: 0 | D22: 0 | E22: 0 | F22: 0 | G22: 0 | H22: 0 | I22: 0 | J22: 0 | K22: 0 | L22: 0 | M22: 0 | N22: 0 | O22: =SUM(C22:L22,N22) -> 0 | P22: =SUM(C22:N22) -> 0 | R22: AM Peak Hr | S22: =MAX(S10:S12) -> 1 | T22: =MAX(T10:T12) -> 3 | U22: =MAX(U10:U12) -> 3 | V22: =MAX(V10:V12) -> 0 | W22: =MAX(W10:W12) -> 0 | X22: =MAX(X10:X12) -> 0 | Y22: =MAX(Y10:Y12) -> 3 | Z22: =MAX(Z10:Z12) -> 2 | ... AF22: =MAX(AF10:AF12) -> 11
B23: 10.15 - 10.30 | C23: 0 | D23: 1 | E23: 0 | F23: 0 | G23: 0 | H23: 0 | I23: 0 | J23: 0 | K23: 0 | L23: 0 | M23: 1 | N23: 0 | O23: =SUM(C23:L23,N23) -> 1 | P23: =SUM(C23:N23) -> 2 | R23: IP Peak Hr | S23: =MAX(S13:S18) -> 1 | T23: =MAX(T13:T18) -> 3 | U23: =MAX(U13:U18) -> 2 | V23: =MAX(V13:V18) -> 0 | W23: =MAX(W13:W18) -> 0 | X23: =MAX(X13:X18) -> 1 | Y23: =MAX(Y13:Y18) -> 1 | Z23: =MAX(Z13:Z18) -> 2 | ... AF23: =MAX(AF13:AF18) -> 16
B24: 10.30 - 10.45 | C24: 0 | D24: 0 | E24: 2 | F24: 0 | G24: 0 | H24: 0 | I24: 1 | J24: 0 | K24: 0 | L24: 0 | M24: 0 | N24: 0 | O24: =SUM(C24:L24,N24) -> 3 | P24: =SUM(C24:N24) -> 3 | R24: PM Peak Hr | S24: =MAX(S19:S21) -> 1 | T24: =MAX(T19:T21) -> 3 | U24: =MAX(U19:U21) -> 0 | V24: =MAX(V19:V21) -> 0 | W24: =MAX(W19:W21) -> 0 | X24: =MAX(X19:X21) -> 1 | Y24: =MAX(Y19:Y21) -> 1 | Z24: =MAX(Z19:Z21) -> 2 | ... AF24: =MAX(AF19:AF21) -> 7
B25: 10.45 - 11.00 | C25: 0 | D25: 0 | E25: 0 | F25: 0 | G25: 0 | H25: 0 | I25: 0 | J25: 0 | K25: 0 | L25: 0 | M25: 0 | N25: 0 | O25: =SUM(C25:L25,N25) -> 0 | P25: =SUM(C25:N25) -> 0 | R25: AM Period | S25: =SUM(S10:S12) -> 2 | T25: =SUM(T10:T12) -> 5 | U25: =SUM(U10:U12) -> 5 | V25: =SUM(V10:V12) -> 0 | W25: =SUM(W10:W12) -> 0 | X25: =SUM(X10:X12) -> 0 | Y25: =SUM(Y10:Y12) -> 3 | Z25: =SUM(Z10:Z12) -> 3 | ... AF25: =SUM(AF10:AF12) -> 27
B26: 11.00 - 11.15 | C26: 1 | D26: 0 | E26: 0 | F26: 0 | G26: 0 | H26: 0 | I26: 0 | J26: 2 | K26: 0 | L26: 0 | M26: 0 | N26: 0 | O26: =SUM(C26:L26,N26) -> 3 | P26: =SUM(C26:N26) -> 3 | R26: IP Period | S26: =SUM(S13:S18) -> 1 | T26: =SUM(T13:T18) -> 6 | U26: =SUM(U13:U18) -> 3 | V26: =SUM(V13:V18) -> 0 | W26: =SUM(W13:W18) -> 0 | X26: =SUM(X13:X18) -> 2 | Y26: =SUM(Y13:Y18) -> 2 | Z26: =SUM(Z13:Z18) -> 3 | ... AF26: =SUM(AF13:AF18) -> 41
B27: 11.15 - 11.30 | C27: 0 | D27: 0 | E27: 0 | F27: 0 | G27: 0 | H27: 0 | I27: 0 | J27: 0 | K27: 0 | L27: 0 | M27: 0 | N27: 0 | O27: =SUM(C27:L27,N27) -> 0 | P27: =SUM(C27:N27) -> 0 | R27: PM Period | S27: =SUM(S19:S21) -> 2 | T27: =SUM(T19:T21) -> 4 | U27: =SUM(U19:U21) -> 0 | V27: =SUM(V19:V21) -> 0 | W27: =SUM(W19:W21) -> 0 | X27: =SUM(X19:X21) -> 1 | Y27: =SUM(Y19:Y21) -> 1 | Z27: =SUM(Z19:Z21) -> 3 | ... AF27: =SUM(AF19:AF21) -> 14
B28: 11.30 - 11.45 | C28: 0 | D28: 0 | E28: 0 | F28: 0 | G28: 0 | H28: 0 | I28: 0 | J28: 0 | K28: 0 | L28: 0 | M28: 0 | N28: 0 | O28: =SUM(C28:L28,N28) -> 0 | P28: =SUM(C28:N28) -> 0 | R28: 12 Hours | S28: =SUM(S10:S21) -> 5 | T28: =SUM(T10:T21) -> 15 | U28: =SUM(U10:U21) -> 8 | V28: =SUM(V10:V21) -> 0 | W28: =SUM(W10:W21) -> 0 | X28: =SUM(X10:X21) -> 3 | Y28: =SUM(Y10:Y21) -> 6 | Z28: =SUM(Z10:Z21) -> 9 | ... AF28: =SUM(AF10:AF21) -> 82
B29: 11.45 - 12.00 | C29: 0 | D29: 3 | E29: 0 | F29: 0 | G29: 0 | H29: 0 | I29: 0 | J29: 0 | K29: 0 | L29: 0 | M29: 0 | N29: 0 | O29: =SUM(C29:L29,N29) -> 3 | P29: =SUM(C29:N29) -> 3
B30: 12.00 - 12.15 | C30: 0 | D30: 0 | E30: 0 | F30: 0 | G30: 0 | H30: 0 | I30: 1 | J30: 0 | K30: 0 | L30: 0 | M30: 2 | N30: 0 | O30: =SUM(C30:L30,N30) -> 1 | P30: =SUM(C30:N30) -> 3
B31: 12.15 - 12.30 | C31: 0 | D31: 0 | E31: 0 | F31: 0 | G31: 0 | H31: 1 | I31: 0 | J31: 0 | K31: 0 | L31: 0 | M31: 0 | N31: 0 | O31: =SUM(C31:L31,N31) -> 1 | P31: =SUM(C31:N31) -> 1
B32: 12.30 - 12.45 | C32: 0 | D32: 0 | E32: 0 | F32: 0 | G32: 0 | H32: 0 | I32: 0 | J32: 0 | K32: 0 | L32: 0 | M32: 1 | N32: 0 | O32: =SUM(C32:L32,N32) -> 0 | P32: =SUM(C32:N32) -> 1
B33: 12.45 - 13.00 | C33: 0 | D33: 1 | E33: 0 | F33: 0 | G33: 0 | H33: 0 | I33: 0 | J33: 0 | K33: 0 | L33: 0 | M33: 0 | N33: 0 | O33: =SUM(C33:L33,N33) -> 1 | P33: =SUM(C33:N33) -> 1
B34: 13.00 - 13.15 | C34: 0 | D34: 0 | E34: 0 | F34: 0 | G34: 0 | H34: 0 | I34: 0 | J34: 0 | K34: 0 | L34: 0 | M34: 0 | N34: 0 | O34: =SUM(C34:L34,N34) -> 0 | P34: =SUM(C34:N34) -> 0
B35: 13.15 - 13.30 | C35: 0 | D35: 0 | E35: 0 | F35: 0 | G35: 0 | H35: 0 | I35: 0 | J35: 0 | K35: 0 | L35: 0 | M35: 2 | N35: 0 | O35: =SUM(C35:L35,N35) -> 0 | P35: =SUM(C35:N35) -> 2
B36: 13.30 - 13.45 | C36: 0 | D36: 0 | E36: 0 | F36: 0 | G36: 0 | H36: 0 | I36: 0 | J36: 0 | K36: 0 | L36: 0 | M36: 0 | N36: 0 | O36: =SUM(C36:L36,N36) -> 0 | P36: =SUM(C36:N36) -> 0
B37: 13.45 - 14.00 | C37: 0 | D37: 0 | E37: 1 | F37: 0 | G37: 0 | H37: 0 | I37: 0 | J37: 0 | K37: 0 | L37: 0 | M37: 0 | N37: 0 | O37: =SUM(C37:L37,N37) -> 1 | P37: =SUM(C37:N37) -> 1
B38: 14.00 - 14.15 | C38: 0 | D38: 1 | E38: 0 | F38: 0 | G38: 0 | H38: 0 | I38: 0 | J38: 0 | K38: 0 | L38: 0 | M38: 1 | N38: 0 | O38: =SUM(C38:L38,N38) -> 1 | P38: =SUM(C38:N38) -> 2
B39: 14.15 - 14.30 | C39: 0 | D39: 0 | E39: 0 | F39: 0 | G39: 0 | H39: 0 | I39: 0 | J39: 0 | K39: 0 | L39: 0 | M39: 0 | N39: 0 | O39: =SUM(C39:L39,N39) -> 0 | P39: =SUM(C39:N39) -> 0
B40: 14.30 - 14.45 | C40: 0 | D40: 0 | E40: 0 | F40: 0 | G40: 0 | H40: 0 | I40: 0 | J40: 1 | K40: 0 | L40: 0 | M40: 2 | N40: 0 | O40: =SUM(C40:L40,N40) -> 1 | P40: =SUM(C40:N40) -> 3
... B57: 18.45 - 19.00 | C57: 0 | D57: 0 | E57: 0 | F57: 0 | G57: 0 | H57: 0 | I57: 0 | J57: 0 | K57: 0 | L57: 0 | M57: 0 | N57: 0 | O57: =SUM(C57:L57,N57) -> 0 | P57: =SUM(C57:N57) -> 0
B58: Totals | C58: =SUM(C10:C57) -> 5 | D58: =SUM(D10:D57) -> 15 | E58: =SUM(E10:E57) -> 8 | F58: =SUM(F10:F57) -> 0 | G58: =SUM(G10:G57) -> 0 | H58: =SUM(H10:H57) -> 3 | I58: =SUM(I10:I57) -> 6 | J58: =SUM(J10:J57) -> 9 | ... P58: =SUM(P10:P57) -> 82
...

Sheet 07.08 KABONG-KOTIDO
B1: Consultancy services for Preparation of Expressway Development Master Plan (EDMP) for Uganda
B2: MANUAL CLASSIFIED COUNT (MCC)
B3: ROAD NAME: | C3: ='05.08 KABONG-KOTIDO'!C3:G3 -> MCC - C5 - STN0125 - KAABONG-KOTIDO ROAD
C5: Date | D5: 07.08.19 | F5: Location | G5: ='05.08 KABONG-KOTIDO'!G5:H5 -> xxx | J5: Surveyor | K5: ='05.08 KABONG-KOTIDO'!K5:L5 -> NALUBEGA JOSEPHINE
C6: Dir. From | D6: ='05.08 KABONG-KOTIDO'!D6:E6 -> KABONG | F6: Dir. To | G6: ='05.08 KABONG-KOTIDO'!G6:H6 -> KOTIDO | J6: Supervisor | K6: ='05.08 KABONG-KOTIDO'!K6:L6 -> CRANIMER
B8: Time / Veh Type | R8: SUMMARY TRAFFIC VOLUMES
C9: 1. Car | D9: 2. Station Wagon | E9: 3. Pickups | F9: 4. Minibus, matatu | G9: 5. Medium bus | H9: 6. Large Bus | I9: 7. Light Truck | J9: 8. Medium Truck | K9: 9. Heavy truck | L9: 10. Truck Trailer | M9: 11. Motor cycles | N9: 12. Tractors | O9: Total Excl M/Cycles | P9: Total All | R9: Time | S9: 1. Car | T9: 2. Station Wagon | U9: 3. Pickups | V9: 4. Minibus, matatu | W9: 5. Medium bus | X9: 6. Large Bus | Y9: 7. Light Truck | Z9: 8. Medium Truck | AA9: 9. Heavy truck | AB9: 10. Truck Trailer | AC9: 11. Motorcycles | AD9: 12. Tractors, Graders | AE9: Total Excl M/ Cycles | AF9: Total All
B10: 07.00 - 07.15 | C10: 0 | D10: 0 | E10: 0 | F10: 0 | G10: 0 | H10: 0 | I10: 2 | J10: 0 | K10: 0 | L10: 0 | M10: 1 | N10: 0 | O10: =SUM(C10:L10,N10) -> 2 | P10: =SUM(C10:N10) -> 3 | R10: 0700-0800 | S10: =SUM(C10:C13) -> 0 | T10: =SUM(D10:D13) -> 1 | U10: =SUM(E10:E13) -> 1 | V10: =SUM(F10:F13) -> 0 | W10: =SUM(G10:G13) -> 0 | X10: =SUM(H10:H13) -> 0 | Y10: =SUM(I10:I13) -> 2 | Z10: =SUM(J10:J13) -> 0 | ... AF10: =SUM(P10:P13) -> 8
B11: 07.15 - 07.30 | C11: 0 | D11: 0 | E11: 0 | F11: 0 | G11: 0 | H11: 0 | I11: 0 | J11: 0 | K11: 0 | L11: 0 | M11: 3 | N11: 0 | O11: =SUM(C11:L11,N11) -> 0 | P11: =SUM(C11:N11) -> 3 | R11: 0800-0900 | S11: =SUM(C14:C17) -> 0 | T11: =SUM(D14:D17) -> 1 | U11: =SUM(E14:E17) -> 1 | V11: =SUM(F14:F17) -> 0 | W11: =SUM(G14:G17) -> 0 | X11: =SUM(H14:H17) -> 0 | Y11: =SUM(I14:I17) -> 3 | Z11: =SUM(J14:J17) -> 0 | ... AF11: =SUM(P14:P17) -> 9
B12: 07.30 - 07.45 | C12: 0 | D12: 1 | E12: 1 | F12: 0 | G12: 0 | H12: 0 | I12: 0 | J12: 0 | K12: 0 | L12: 0 | M12: 0 | N12: 0 | O12: =SUM(C12:L12,N12) -> 2 | P12: =SUM(C12:N12) -> 2 | R12: 0900-1000 | S12: =SUM(C18:C21) -> 0 | T12: =SUM(D18:D21) -> 0 | U12: =SUM(E18:E21) -> 0 | V12: =SUM(F18:F21) -> 0 | W12: =SUM(G18:G21) -> 0 | X12: =SUM(H18:H21) -> 0 | Y12: =SUM(I18:I21) -> 0 | Z12: =SUM(J18:J21) -> 0 | ... AF12: =SUM(P18:P21) -> 2
B13: 07.45 - 08.00 | C13: 0 | D13: 0 | E13: 0 | F13: 0 | G13: 0 | H13: 0 | I13: 0 | J13: 0 | K13: 0 | L13: 0 | M13: 0 | N13: 0 | O13: =SUM(C13:L13,N13) -> 0 | P13: =SUM(C13:N13) -> 0 | R13: 1000-1100 | S13: =SUM(C22:C25) -> 0 | T13: =SUM(D22:D25) -> 1 | U13: =SUM(E22:E25) -> 0 | V13: =SUM(F22:F25) -> 0 | W13: =SUM(G22:G25) -> 0 | X13: =SUM(H22:H25) -> 0 | Y13: =SUM(I22:I25) -> 0 | Z13: =SUM(J22:J25) -> 0 | ... AF13: =SUM(P22:P25) -> 2
B14: 08.00 - 08.15 | C14: 0 | D14: 1 | E14: 0 | F14: 0 | G14: 0 | H14: 0 | I14: 1 | J14: 0 | K14: 0 | L14: 0 | M14: 2 | N14: 0 | O14: =SUM(C14:L14,N14) -> 2 | P14: =SUM(C14:N14) -> 4 | R14: 1100-1200 | S14: =SUM(C26:C29) -> 0 | T14: =SUM(D26:D29) -> 0 | U14: =SUM(E26:E29) -> 0 | V14: =SUM(F26:F29) -> 0 | W14: =SUM(G26:G29) -> 0 | X14: =SUM(H26:H29) -> 0 | Y14: =SUM(I26:I29) -> 0 | Z14: =SUM(J26:J29) -> 0 | ... AF14: =SUM(P26:P29) -> 1
B15: 08.15 - 08.30 | C15: 0 | D15: 0 | E15: 0 | F15: 0 | G15: 0 | H15: 0 | I15: 0 | J15: 0 | K15: 0 | L15: 0 | M15: 0 | N15: 0 | O15: =SUM(C15:L15,N15) -> 0 | P15: =SUM(C15:N15) -> 0 | R15: 1200-1300 | S15: =SUM(C30:C33) -> 0 | T15: =SUM(D30:D33) -> 0 | U15: =SUM(E30:E33) -> 0 | V15: =SUM(F30:F33) -> 0 | W15: =SUM(G30:G33) -> 0 | X15: =SUM(H30:H33) -> 0 | Y15: =SUM(I30:I33) -> 0 | Z15: =SUM(J30:J33) -> 0 | ... AF15: =SUM(P30:P33) -> 2
B16: 08.30 - 08.45 | C16: 0 | D16: 0 | E16: 1 | F16: 0 | G16: 0 | H16: 0 | I16: 2 | J16: 0 | K16: 0 | L16: 0 | M16: 0 | N16: 0 | O16: =SUM(C16:L16,N16) -> 3 | P16: =SUM(C16:N16) -> 3 | R16: 1300-1400 | S16: =SUM(C34:C37) -> 0 | T16: =SUM(D34:D37) -> 0 | U16: =SUM(E34:E37) -> 0 | V16: =SUM(F34:F37) -> 0 | W16: =SUM(G34:G37) -> 0 | X16: =SUM(H34:H37) -> 0 | Y16: =SUM(I34:I37) -> 0 | Z16: =SUM(J34:J37) -> 0 | ... AF16: =SUM(P34:P37) -> 3
B17: 08.45 - 9.00 | C17: 0 | D17: 0 | E17: 0 | F17: 0 | G17: 0 | H17: 0 | I17: 0 | J17: 0 | K17: 0 | L17: 0 | M17: 2 | N17: 0 | O17: =SUM(C17:L17,N17) -> 0 | P17: =SUM(C17:N17) -> 2 | R17: 1400-1500 | S17: =SUM(C38:C41) -> 0 | T17: =SUM(D38:D41) -> 0 | U17: =SUM(E38:E41) -> 3 | V17: =SUM(F38:F41) -> 0 | W17: =SUM(G38:G41) -> 0 | X17: =SUM(H38:H41) -> 0 | Y17: =SUM(I38:I41) -> 0 | Z17: =SUM(J38:J41) -> 0 | ... AF17: =SUM(P38:P41) -> 3
B18: 09.00 - 09.15 | C18: 0 | D18: 0 | E18: 0 | F18: 0 | G18: 0 | H18: 0 | I18: 0 | J18: 0 | K18: 0 | L18: 0 | M18: 0 | N18: 0 | O18: =SUM(C18:L18,N18) -> 0 | P18: =SUM(C18:N18) -> 0 | R18: 1500-1600 | S18: =SUM(C42:C45) -> 0 | T18: =SUM(D42:D45) -> 1 | U18: =SUM(E42:E45) -> 2 | V18: =SUM(F42:F45) -> 0 | W18: =SUM(G42:G45) -> 0 | X18: =SUM(H42:H45) -> 0 | Y18: =SUM(I42:I45) -> 0 | Z18: =SUM(J42:J45) -> 0 | ... AF18: =SUM(P42:P45) -> 4
B19: 09.15 - 09.30 | C19: 0 | D19: 0 | E19: 0 | F19: 0 | G19: 0 | H19: 0 | I19: 0 | J19: 0 | K19: 0 | L19: 0 | M19: 1 | N19: 0 | O19: =SUM(C19:L19,N19) -> 0 | P19: =SUM(C19:N19) -> 1 | R19: 1600-1700 | S19: =SUM(C46:C49) -> 0 | T19: =SUM(D46:D49) -> 1 | U19: =SUM(E46:E49) -> 2 | V19: =SUM(F46:F49) -> 0 | W19: =SUM(G46:G49) -> 0 | X19: =SUM(H46:H49) -> 0 | Y19: =SUM(I46:I49) -> 0 | Z19: =SUM(J46:J49) -> 0 | ... AF19: =SUM(P46:P49) -> 7
B20: 09.30 - 09.45 | C20: 0 | D20: 0 | E20: 0 | F20: 0 | G20: 0 | H20: 0 | I20: 0 | J20: 0 | K20: 0 | L20: 0 | M20: 1 | N20: 0 | O20: =SUM(C20:L20,N20) -> 0 | P20: =SUM(C20:N20) -> 1 | R20: 1700-1800 | S20: =SUM(C50:C53) -> 1 | T20: =SUM(D50:D53) -> 2 | U20: =SUM(E50:E53) -> 2 | V20: =SUM(F50:F53) -> 0 | W20: =SUM(G50:G53) -> 0 | X20: =SUM(H50:H53) -> 1 | Y20: =SUM(I50:I53) -> 0 | Z20: =SUM(J50:J53) -> 0 | ... AF20: =SUM(P50:P53) -> 8
B21: 09.45 - 10.00 | C21: 0 | D21: 0 | E21: 0 | F21: 0 | G21: 0 | H21: 0 | I21: 0 | J21: 0 | K21: 0 | L21: 0 | M21: 0 | N21: 0 | O21: =SUM(C21:L21,N21) -> 0 | P21: =SUM(C21:N21) -> 0 | R21: 1800-1900 | S21: =SUM(C54:C57) -> 1 | T21: =SUM(D54:D57) -> 4 | U21: =SUM(E54:E57) -> 2 | V21: =SUM(F54:F57) -> 0 | W21: =SUM(G54:G57) -> 0 | X21: =SUM(H54:H57) -> 2 | Y21: =SUM(I54:I57) -> 1 | Z21: =SUM(J54:J57) -> 0 | ... AF21: =SUM(P54:P57) -> 10
B22: 10.00 - 10.15 | C22: 0 | D22: 0 | E22: 0 | F22: 0 | G22: 0 | H22: 0 | I22: 0 | J22: 0 | K22: 0 | L22: 0 | M22: 0 | N22: 0 | O22: =SUM(C22:L22,N22) -> 0 | P22: =SUM(C22:N22) -> 0 | R22: AM Peak Hr | S22: =MAX(S10:S12) -> 0 | T22: =MAX(T10:T12) -> 1 | U22: =MAX(U10:U12) -> 1 | V22: =MAX(V10:V12) -> 0 | W22: =MAX(W10:W12) -> 0 | X22: =MAX(X10:X12) -> 0 | Y22: =MAX(Y10:Y12) -> 3 | Z22: =MAX(Z10:Z12) -> 0 | ... AF22: =MAX(AF10:AF12) -> 9
B23: 10.15 - 10.30 | C23: 0 | D23: 1 | E23: 0 | F23: 0 | G23: 0 | H23: 0 | I23: 0 | J23: 0 | K23: 0 | L23: 0 | M23: 0 | N23: 0 | O23: =SUM(C23:L23,N23) -> 1 | P23: =SUM(C23:N23) -> 1 | R23: IP Peak Hr | S23: =MAX(S13:S18) -> 0 | T23: =MAX(T13:T18) -> 1 | U23: =MAX(U13:U18) -> 3 | V23: =MAX(V13:V18) -> 0 | W23: =MAX(W13:W18) -> 0 | X23: =MAX(X13:X18) -> 0 | Y23: =MAX(Y13:Y18) -> 0 | Z23: =MAX(Z13:Z18) -> 0 | ... AF23: =MAX(AF13:AF18) -> 4
B24: 10.30 - 10.45 | C24: 0 | D24: 0 | E24: 0 | F24: 0 | G24: 0 | H24: 0 | I24: 0 | J24: 0 | K24: 0 | L24: 0 | M24: 1 | N24: 0 | O24: =SUM(C24:L24,N24) -> 0 | P24: =SUM(C24:N24) -> 1 | R24: PM Peak Hr | S24: =MAX(S19:S21) -> 1 | T24: =MAX(T19:T21) -> 4 | U24: =MAX(U19:U21) -> 2 | V24: =MAX(V19:V21) -> 0 | W24: =MAX(W19:W21) -> 0 | X24: =MAX(X19:X21) -> 2 | Y24: =MAX(Y19:Y21) -> 1 | Z24: =MAX(Z19:Z21) -> 0 | ... AF24: =MAX(AF19:AF21) -> 10
B25: 10.45 - 11.00 | C25: 0 | D25: 0 | E25: 0 | F25: 0 | G25: 0 | H25: 0 | I25: 0 | J25: 0 | K25: 0 | L25: 0 | M25: 0 | N25: 0 | O25: =SUM(C25:L25,N25) -> 0 | P25: =SUM(C25:N25) -> 0 | R25: AM Period | S25: =SUM(S10:S12) -> 0 | T25: =SUM(T10:T12) -> 2 | U25: =SUM(U10:U12) -> 2 | V25: =SUM(V10:V12) -> 0 | W25: =SUM(W10:W12) -> 0 | X25: =SUM(X10:X12) -> 0 | Y25: =SUM(Y10:Y12) -> 5 | Z25: =SUM(Z10:Z12) -> 0 | ... AF25: =SUM(AF10:AF12) -> 19
B26: 11.00 - 11.15 | C26: 0 | D26: 0 | E26: 0 | F26: 0 | G26: 0 | H26: 0 | I26: 0 | J26: 0 | K26: 0 | L26: 0 | M26: 0 | N26: 0 | O26: =SUM(C26:L26,N26) -> 0 | P26: =SUM(C26:N26) -> 0 | R26: IP Period | S26: =SUM(S13:S18) -> 0 | T26: =SUM(T13:T18) -> 2 | U26: =SUM(U13:U18) -> 5 | V26: =SUM(V13:V18) -> 0 | W26: =SUM(W13:W18) -> 0 | X26: =SUM(X13:X18) -> 0 | Y26: =SUM(Y13:Y18) -> 0 | Z26: =SUM(Z13:Z18) -> 0 | ... AF26: =SUM(AF13:AF18) -> 15
B27: 11.15 - 11.30 | C27: 0 | D27: 0 | E27: 0 | F27: 0 | G27: 0 | H27: 0 | I27: 0 | J27: 0 | K27: 0 | L27: 0 | M27: 1 | N27: 0 | O27: =SUM(C27:L27,N27) -> 0 | P27: =SUM(C27:N27) -> 1 | R27: PM Period | S27: =SUM(S19:S21) -> 2 | T27: =SUM(T19:T21) -> 7 | U27: =SUM(U19:U21) -> 6 | V27: =SUM(V19:V21) -> 0 | W27: =SUM(W19:W21) -> 0 | X27: =SUM(X19:X21) -> 3 | Y27: =SUM(Y19:Y21) -> 1 | Z27: =SUM(Z19:Z21) -> 0 | ... AF27: =SUM(AF19:AF21) -> 25
B28: 11.30 - 11.45 | C28: 0 | D28: 0 | E28: 0 | F28: 0 | G28: 0 | H28: 0 | I28: 0 | J28: 0 | K28: 0 | L28: 0 | M28: 0 | N28: 0 | O28: =SUM(C28:L28,N28) -> 0 | P28: =SUM(C28:N28) -> 0 | R28: 12 Hours | S28: =SUM(S10:S21) -> 2 | T28: =SUM(T10:T21) -> 11 | U28: =SUM(U10:U21) -> 13 | V28: =SUM(V10:V21) -> 0 | W28: =SUM(W10:W21) -> 0 | X28: =SUM(X10:X21) -> 3 | Y28: =SUM(Y10:Y21) -> 6 | Z28: =SUM(Z10:Z21) -> 0 | ... AF28: =SUM(AF10:AF21) -> 59
B29: 11.45 - 12.00 | C29: 0 | D29: 0 | E29: 0 | F29: 0 | G29: 0 | H29: 0 | I29: 0 | J29: 0 | K29: 0 | L29: 0 | M29: 0 | N29: 0 | O29: =SUM(C29:L29,N29) -> 0 | P29: =SUM(C29:N29) -> 0
B30: 12.00 - 12.15 | C30: 0 | D30: 0 | E30: 0 | F30: 0 | G30: 0 | H30: 0 | I30: 0 | J30: 0 | K30: 0 | L30: 0 | M30: 1 | N30: 0 | O30: =SUM(C30:L30,N30) -> 0 | P30: =SUM(C30:N30) -> 1
B31: 12.15 - 12.30 | C31: 0 | D31: 0 | E31: 0 | F31: 0 | G31: 0 | H31: 0 | I31: 0 | J31: 0 | K31: 0 | L31: 0 | M31: 0 | N31: 0 | O31: =SUM(C31:L31,N31) -> 0 | P31: =SUM(C31:N31) -> 0
B32: 12.30 - 12.45 | C32: 0 | D32: 0 | E32: 0 | F32: 0 | G32: 0 | H32: 0 | I32: 0 | J32: 0 | K32: 0 | L32: 0 | M32: 1 | N32: 0 | O32: =SUM(C32:L32,N32) -> 0 | P32: =SUM(C32:N32) -> 1
B33: 12.45 - 13.00 | C33: 0 | D33: 0 | E33: 0 | F33: 0 | G33: 0 | H33: 0 | I33: 0 | J33: 0 | K33: 0 | L33: 0 | M33: 0 | N33: 0 | O33: =SUM(C33:L33,N33) -> 0 | P33: =SUM(C33:N33) -> 0
B34: 13.00 - 13.15 | C34: 0 | D34: 0 | E34: 0 | F34: 0 | G34: 0 | H34: 0 | I34: 0 | J34: 0 | K34: 0 | L34: 0 | M34: 1 | N34: 0 | O34: =SUM(C34:L34,N34) -> 0 | P34: =SUM(C34:N34) -> 1
B35: 13.15 - 13.30 | C35: 0 | D35: 0 | E35: 0 | F35: 0 | G35: 0 | H35: 0 | I35: 0 | J35: 0 | K35: 0 | L35: 0 | M35: 1 | N35: 0 | O35: =SUM(C35:L35,N35) -> 0 | P35: =SUM(C35:N35) -> 1
B36: 13.30 - 13.45 | C36: 0 | D36: 0 | E36: 0 | F36: 0 | G36: 0 | H36: 0 | I36: 0 | J36: 0 | K36: 0 | L36: 0 | M36: 1 | N36: 0 | O36: =SUM(C36:L36,N36) -> 0 | P36: =SUM(C36:N36) -> 1
