Workbook
Name Veh_Type: 'PT-04'!$C$10:$C$38
Name zones: #REF!
Name Zones_Ndeke: #REF!

Sheet PT-04
B1: Consultancy services for Preparation of Expressway Development Master Plan (EDMP) for Uganda
B2: Public Transport/Bus Surveys
B4: Date: | D4: 01.08.19 | G4: Location | J4: Coded By: | N4: Chkd By: | O4: Bakole. D.M
B5: Enumerator: | G5: Supervisor:
B7: Time | C7: Veh_Type | D7: Type of Veh. | E7: Veh_Reg_No. | F7: IN / OUT | G7: Origin_Address | J7: Destination_Address | M7: No. Passengers | N7: Cost of Trip (UGX) | O7: Approx_Journey Time (Hrs)
G8: Town | H8: District | I8: Country | J8: Town | K8: District | L8: Journey_Desc
B9: 43692 | L9: =H9&"-"&K9 -> -
B10: 0.33333333 | C10: 4 | D10: =IF(C10="", "",VLOOKUP(C10,Key!$A$5:$B$7,2,FALSE)) -> Minibus, matatu | F10: OUT | G10: TORORO | H10: TORORO | J10: KAMPALA | K10: KAMPALA | L10: =H10&"-"&K10 -> TORORO-KAMPALA | M10: 14 | N10: 18000 | O10: 4.8
B11: 0.34375 | C11: 4 | D11: =IF(C11="", "",VLOOKUP(C11,Key!$A$5:$B$7,2,FALSE)) -> Minibus, matatu | F11: IN | G11: MBALE | H11: MBALE | J11: TORORO | K11: TORORO | L11: =H11&"-"&K11 -> MBALE-TORORO | M11: 14 | N11: 5000 | O11: 1.89
B12: 0.35486111 | C12: 4 | D12: =IF(C12="", "",VLOOKUP(C12,Key!$A$5:$B$7,2,FALSE)) -> Minibus, matatu | F12: IN | G12: TORORO | H12: TORORO | J12: KAMPALA | K12: KAMPALA | L12: =H12&"-"&K12 -> TORORO-KAMPALA | M12: 14 | N12: 18000 | O12: 4.8
B13: 0.375 | C13: 4 | D13: =IF(C13="", "",VLOOKUP(C13,Key!$A$5:$B$7,2,FALSE)) -> Minibus, matatu | F13: IN | G13: TORORO | H13: TORORO | J13: JINJA | K13: JINJA | L13: =H13&"-"&K13 -> TORORO-JINJA | M13: 14 | N13: 13000 | O13: 2.25
B14: 0.38263889 | C14: 4 | D14: =IF(C14="", "",VLOOKUP(C14,Key!$A$5:$B$7,2,FALSE)) -> Minibus, matatu | F14: IN | G14: JINJA | H14: JINJA | J14: TORORO | K14: TORORO | L14: =H14&"-"&K14 -> JINJA-TORORO | M14: 14 | N14: 13000 | O14: 2.25
B15: 0.38402778 | C15: 4 | D15: =IF(C15="", "",VLOOKUP(C15,Key!$A$5:$B$7,2,FALSE)) -> Minibus, matatu | F15: IN | G15: MBALE | H15: MBALE | J15: TORORO | K15: TORORO | L15: =H15&"-"&K15 -> MBALE-TORORO | M15: 14 | N15: 5000 | O15: 1.89
B16: 0.38680556 | C16: 4 | D16: =IF(C16="", "",VLOOKUP(C16,Key!$A$5:$B$7,2,FALSE)) -> Minibus, matatu | F16: IN | G16: JINJA | H16: JINJA | J16: TORORO | K16: TORORO | L16: =H16&"-"&K16 -> JINJA-TORORO | M16: 14 | N16: 13000 | O16: 2.25
B17: 0.39305556 | C17: 4 | D17: =IF(C17="", "",VLOOKUP(C17,Key!$A$5:$B$7,2,FALSE)) -> Minibus, matatu | F17: OUT | G17: TORORO | H17: TORORO | J17: MBALE | K17: MBALE | L17: =H17&"-"&K17 -> TORORO-MBALE | M17: 14 | N17: 5000 | O17: 1.9
B18: 0.39652778 | C18: 4 | D18: =IF(C18="", "",VLOOKUP(C18,Key!$A$5:$B$7,2,FALSE)) -> Minibus, matatu | F18: IN | G18: JINJA | H18: JINJA | J18: TORORO | K18: TORORO | L18: =H18&"-"&K18 -> JINJA-TORORO | M18: 14 | N18: 13000 | O18: 2.25
B19: 0.40069444 | C19: 4 | D19: =IF(C19="", "",VLOOKUP(C19,Key!$A$5:$B$7,2,FALSE)) -> Minibus, matatu | F19: IN | G19: JINJA | H19: JINJA | J19: TORORO | K19: TORORO | L19: =H19&"-"&K19 -> JINJA-TORORO | M19: 14 | N19: 13000 | O19: 2.25
B20: 0.40277778 | C20: 4 | D20: =IF(C20="", "",VLOOKUP(C20,Key!$A$5:$B$7,2,FALSE)) -> Minibus, matatu | F20: IN | G20: JINJA | H20: JINJA | J20: TORORO | K20: TORORO | L20: =H20&"-"&K20 -> JINJA-TORORO | M20: 14 | N20: 13000 | O20: 2.25
B21: 0.40625 | C21: 4 | D21: =IF(C21="", "",VLOOKUP(C21,Key!$A$5:$B$7,2,FALSE)) -> Minibus, matatu | F21: IN | G21: KAMPALA | H21: KAMPALA | J21: TORORO | K21: TORORO | L21: =H21&"-"&K21 -> KAMPALA-TORORO | M21: 14 | N21: 18000 | O21: 4.8
... B89: 0.59722222 | C89: 4 | D89: =IF(C89="", "",VLOOKUP(C89,Key!$A$5:$B$7,2,FALSE)) -> Minibus, matatu | F89: IN | G89: MBALE | H89: MBALE | J89: TORORO | K89: TORORO | L89: =H89&"-"&K89 -> MBALE-TORORO | M89: 14 | N89: 5000 | O89: 1.89
B90: 43693 | L90: =H90&"-"&K90 -> -
B91: 0.32291667 | C91: 4 | D91: =IF(C91="", "",VLOOKUP(C91,Key!$A$5:$B$7,2,FALSE)) -> Minibus, matatu | F91: IN | G91: IGANGA | H91: IGANGA | J91: TORORO | K91: TORORO | L91: =H91&"-"&K91 -> IGANGA-TORORO | M91: 14 | N91: 10000 | O91: 1.8
B92: 0.33333333 | C92: 4 | D92: =IF(C92="", "",VLOOKUP(C92,Key!$A$5:$B$7,2,FALSE)) -> Minibus, matatu | F92: IN | G92: MBALE | H92: MBALE | J92: TORORO | K92: TORORO | L92: =H92&"-"&K92 -> MBALE-TORORO | M92: 14 | N92: 5000 | O92: 1.89
B93: 0.38333333 | C93: 4 | D93: =IF(C93="", "",VLOOKUP(C93,Key!$A$5:$B$7,2,FALSE)) -> Minibus, matatu | F93: IN | G93: MBALE | H93: MBALE | J93: TORORO | K93: TORORO | L93: =H93&"-"&K93 -> MBALE-TORORO | M93: 14 | N93: 5000 | O93: 1.89
B94: 0.38402778 | C94: 4 | D94: =IF(C94="", "",VLOOKUP(C94,Key!$A$5:$B$7,2,FALSE)) -> Minibus, matatu | F94: IN | G94: JINJA | H94: JINJA | J94: TORORO | K94: TORORO | L94: =H94&"-"&K94 -> JINJA-TORORO | M94: 14 | N94: 13000 | O94: 2.25
B95: 0.38472222 | C95: 4 | D95: =IF(C95="", "",VLOOKUP(C95,Key!$A$5:$B$7,2,FALSE)) -> Minibus, matatu | F95: OUT | G95: TORORO | H95: TORORO | J95: JINJA | K95: JINJA | L95: =H95&"-"&K95 -> TORORO-JINJA | M95: 14 | N95: 13000 | O95: 2.25
B96: 0.39583333 | C96: 4 | D96: =IF(C96="", "",VLOOKUP(C96,Key!$A$5:$B$7,2,FALSE)) -> Minibus, matatu | F96: IN | G96: BUSIA | H96: BUSIA | J96: TORORO | K96: TORORO | L96: =H96&"-"&K96 -> BUSIA-TORORO | M96: 14 | N96: 5000 | O96: 1.25
B97: 0.39652778 | C97: 4 | D97: =IF(C97="", "",VLOOKUP(C97,Key!$A$5:$B$7,2,FALSE)) -> Minibus, matatu | F97: IN | G97: BUSIA | H97: BUSIA | J97: TORORO | K97: TORORO | L97: =H97&"-"&K97 -> BUSIA-TORORO | M97: 14 | N97: 5000 | O97: 1.25
B98: 0.40416667 | C98: 4 | D98: =IF(C98="", "",VLOOKUP(C98,Key!$A$5:$B$7,2,FALSE)) -> Minibus, matatu | F98: IN | G98: BUSIA | H98: BUSIA | J98: TORORO | K98: TORORO | L98: =H98&"-"&K98 -> BUSIA-TORORO | M98: 14 | N98: 5000 | O98: 1.25
B99: 0.40972222 | C99: 4 | D99: =IF(C99="", "",VLOOKUP(C99,Key!$A$5:$B$7,2,FALSE)) -> Minibus, matatu | F99: IN | G99: BUSIA | H99: BUSIA | J99: TORORO | K99: TORORO | L99: =H99&"-"&K99 -> BUSIA-TORORO | M99: 14 | N99: 5000 | O99: 1.25
B100: 0.41666667 | C100: 4 | D100: =IF(C100="", "",VLOOKUP(C100,Key!$A$5:$B$7,2,FALSE)) -> Minibus, matatu | F100: IN | G100: BUSIA | H100: BUSIA | J100: TORORO | K100: TORORO | L100: =H100&"-"&K100 -> BUSIA-TORORO | M100: 14 | N100: 5000 | O100: 1.25
B101: 0.41736111 | C101: 4 | D101: =IF(C101="", "",VLOOKUP(C101,Key!$A$5:$B$7,2,FALSE)) -> Minibus, matatu | F101: IN | G101: BUSIA | H101: BUSIA | J101: TORORO | K101: TORORO | L101: =H101&"-"&K101 -> BUSIA-TORORO | M101: 14 | N101: 5000 | O101: 1.25
B102: 0.42013889 | C102: 4 | D102: =IF(C102="", "",VLOOKUP(C102,Key!$A$5:$B$7,2,FALSE)) -> Minibus, matatu | F102: IN | G102: JINJA | H102: JINJA | J102: TORORO | K102: TORORO | L102: =H102&"-"&K102 -> JINJA-TORORO | M102: 14 | N102: 13000 | O102: 2.25
... B172: 0.8625 | C172: 6 | D172: =IF(C172="", "",VLOOKUP(C172,Key!$A$5:$B$7,2,FALSE)) -> Large Bus | F172: OUT | G172: LIRA | H172: LIRA | J172: BUSIA | K172: BUSIA | L172: =H172&"-"&K172 -> LIRA-BUSIA | M172: 53 | N172: 25000 | O172: 5.25
B173: 43694 | L173: =H173&"-"&K173 -> -
B174: 0.31666667 | C174: 4 | D174: =IF(C174="", "",VLOOKUP(C174,Key!$A$5:$B$7,2,FALSE)) -> Minibus, matatu | F174: OUT | G174: TORORO | H174: TORORO | J174: KAMPALA | K174: KAMPALA | L174: =H174&"-"&K174 -> TORORO-KAMPALA | M174: 14 | N174: 18000 | O174: 4.8
B175: 0.32569444 | C175: 4 | D175: =IF(C175="", "",VLOOKUP(C175,Key!$A$5:$B$7,2,FALSE)) -> Minibus, matatu | F175: IN | G175: MBALE | H175: MBALE | J175: TORORO | K175: TORORO | L175: =H175&"-"&K175 -> MBALE-TORORO | M175: 14 | N175: 5000 | O175: 1.89
B176: 0.33333333 | C176: 4 | D176: =IF(C176="", "",VLOOKUP(C176,Key!$A$5:$B$7,2,FALSE)) -> Minibus, matatu | F176: IN | G176: MBALE | H176: MBALE | J176: TORORO | K176: TORORO | L176: =H176&"-"&K176 -> MBALE-TORORO | M176: 14 | N176: 5000 | O176: 1.89
B177: 0.35069444 | C177: 4 | D177: =IF(C177="", "",VLOOKUP(C177,Key!$A$5:$B$7,2,FALSE)) -> Minibus, matatu | F177: IN | G177: JINJA | H177: JINJA | J177: TORORO | K177: TORORO | L177: =H177&"-"&K177 -> JINJA-TORORO | M177: 14 | N177: 13000 | O177: 2.25
B178: 0.35416667 | C178: 4 | D178: =IF(C178="", "",VLOOKUP(C178,Key!$A$5:$B$7,2,FALSE)) -> Minibus, matatu | F178: IN | G178: KAMPALA | H178: KAMPALA | J178: TORORO | K178: TORORO | L178: =H178&"-"&K178 -> KAMPALA-TORORO | M178: 14 | N178: 18000 | O178: 4.8
...

Sheet RSI FORM
B1: Feasibility Study and Detailed Design of Kampala - Jinja Highway
B2: Roadside OD Interview Survey
B4: Date: | C4: 40465 | D4: Interviewer: | G4: Survey Station: | H4: Bweyogerere | J4: Direction: | K4: Bweyogerere-Kireka | L4: Coded By: | N4: Chkd By:
B7: Time Period | C7: Veh_Type | D7: Veh_Other | E7: Occupancy | F7: Origin_Address | H7: Origin_Purpose | I7: Origin_other | J7: Destination_Address | L7: Destination_Purpose | M7: Destination_Other | N7: Origin_Zone | O7: Dest_Zone | P7: WTP
F8: Village/Town | G8: City/Country | J8: Village/Town | K8: City/Country
B9: AM | C9: 3 | E9: 2 | F9: Entebbe | G9: Kla, Ug | H9: 1 | J9: Kla | K9: Kla, Ug | L9: 2 | N9: Blank | O9: Blank | P9: Yes | Q9: 3000
B10: AM | C10: 1 | E10: 1 | F10: Kiwanga | G10: Kla, Ug | H10: 1 | J10: Kla | K10: Kla, Ug | L10: 2 | N10: Blank | O10: Blank | P10: Yes | Q10: 2000
B11: AM | E11: 1 | F11: Bukoto | G11: Kla, Ug | H11: 3 | J11: Kla | K11: Kla, Ug | L11: 1 | N11: Blank | O11: Blank
B12: AM
B13: AM
B14: AM
B15: AM
B16: AM
B17: AM
B18: AM
B19: AM
B20: AM
B21: AM
B22: AM
B23: AM
... B53: AM

Sheet Summary
B2: BUS OPERATIONS AT TORORO
D4: BUS JOURNEY | J4: PASSENGER DETAILS
B5: STATION | C5: DIRECTION | D5: ORIGIN | E5: DESTINATION | F5: ROUTE ID | G5: BUS TRIPS / DAY | H5: JOURNEY DISTANCE (KM) | I5: JOURNEY TIME/ TRIP (HRS) | J5: EST. PAX/ BUS | K5: AVERAGE PAX FARE (UGX)
B6: TORORO | C6: FROM KAMPALA | D6: KAMPALA | E6: TORORO | F6: =D6&"-"&E6 -> KAMPALA-TORORO | G6: =ROUNDUP(COUNTIF('PT-04'!$L$9:$L$3233,Summary!F6)/5,0) -> 12 | H6: 210 | I6: =AVERAGEIF('PT-04'!$L$9:$L$3233,Summary!F6,'PT-04'!$O$9:$O$3233) -> 4.8 | J6: =AVERAGEIF('PT-04'!$L$9:$L$3233,Summary!F6,'PT-04'!$M$9:$M$3233) -> 14 | K6: =AVERAGEIF('PT-04'!$L$9:$L$3233,Summary!F6,'PT-04'!$N$9:$N$3233) -> 17551.724
B7: TORORO | C7: TO KAMPALA | D7: TORORO | E7: KAMPALA | F7: =D7&"-"&E7 -> TORORO-KAMPALA | G7: =ROUNDUP(COUNTIF('PT-04'!$L$9:$L$3233,Summary!F7)/5,0) -> 2 | H7: 210 | I7: =AVERAGEIF('PT-04'!$L$9:$L$3233,Summary!F7,'PT-04'!$O$9:$O$3233) -> 4.8 | J7: =AVERAGEIF('PT-04'!$L$9:$L$3233,Summary!F7,'PT-04'!$M$9:$M$3233) -> 14 | K7: =AVERAGEIF('PT-04'!$L$9:$L$3233,Summary!F7,'PT-04'!$N$9:$N$3233) -> 18000
B8: TORORO | C8: TO KAMPALA | D8: BUSIA | E8: KAMPALA | F8: =D8&"-"&E8 -> BUSIA-KAMPALA | G8: =ROUNDUP(COUNTIF('PT-04'!$L$9:$L$3233,Summary!F8)/5,0) -> 1 | H8: 194 | I8: =AVERAGEIF('PT-04'!$L$9:$L$3233,Summary!F8,'PT-04'!$O$9:$O$3233) -> 4.25 | J8: =AVERAGEIF('PT-04'!$L$9:$L$3233,Summary!F8,'PT-04'!$M$9:$M$3233) -> 14 | K8: =AVERAGEIF('PT-04'!$L$9:$L$3233,Summary!F8,'PT-04'!$N$9:$N$3233) -> 20000
B9: TORORO | C9: TO KAMPALA | D9: LIRA | E9: KAMPALA | F9: =D9&"-"&E9 -> LIRA-KAMPALA | G9: =ROUNDUP(COUNTIF('PT-04'!$L$9:$L$3233,Summary!F9)/5,0) -> 1 | H9: 337 | I9: =AVERAGEIF('PT-04'!$L$9:$L$3233,Summary!F9,'PT-04'!$O$9:$O$3233) -> 5.25 | J9: =AVERAGEIF('PT-04'!$L$9:$L$3233,Summary!F9,'PT-04'!$M$9:$M$3233) -> 46 | K9: =AVERAGEIF('PT-04'!$L$9:$L$3233,Summary!F9,'PT-04'!$N$9:$N$3233) -> 25000
B10: TORORO | C10: TO TORORO | D10: BUGIRI | E10: TORORO | F10: =D10&"-"&E10 -> BUGIRI-TORORO | G10: =ROUNDUP(COUNTIF('PT-04'!$L$9:$L$3233,Summary!F10)/5,0) -> 1 | H10: 59 | I10: =AVERAGEIF('PT-04'!$L$9:$L$3233,Summary!F10,'PT-04'!$O$9:$O$3233) -> 1.25 | J10: =AVERAGEIF('PT-04'!$L$9:$L$3233,Summary!F10,'PT-04'!$M$9:$M$3233) -> 14 | K10: =AVERAGEIF('PT-04'!$L$9:$L$3233,Summary!F10,'PT-04'!$N$9:$N$3233) -> 6000
B11: TORORO | C11: TO TORORO | D11: BUSIA | E11: TORORO | F11: =D11&"-"&E11 -> BUSIA-TORORO | G11: =ROUNDUP(COUNTIF('PT-04'!$L$9:$L$3233,Summary!F11)/5,0) -> 6 | H11: 52 | I11: =AVERAGEIF('PT-04'!$L$9:$L$3233,Summary!F11,'PT-04'!$O$9:$O$3233) -> 1.25 | J11: =AVERAGEIF('PT-04'!$L$9:$L$3233,Summary!F11,'PT-04'!$M$9:$M$3233) -> 14 | K11: =AVERAGEIF('PT-04'!$L$9:$L$3233,Summary!F11,'PT-04'!$N$9:$N$3233) -> 5035.7143
B12: TORORO | C12: TO TORORO | D12: BUTALEJA | E12: TORORO | F12: =D12&"-"&E12 -> BUTALEJA-TORORO | G12: =ROUNDUP(COUNTIF('PT-04'!$L$9:$L$3233,Summary!F12)/5,0) -> 1 | H12: 52 | I12: =AVERAGEIF('PT-04'!$L$9:$L$3233,Summary!F12,'PT-04'!$O$9:$O$3233) -> 1.25 | J12: =AVERAGEIF('PT-04'!$L$9:$L$3233,Summary!F12,'PT-04'!$M$9:$M$3233) -> 14 | K12: =AVERAGEIF('PT-04'!$L$9:$L$3233,Summary!F12,'PT-04'!$N$9:$N$3233) -> 5000
B13: TORORO | C13: TO TORORO | D13: IGANGA | E13: TORORO | F13: =D13&"-"&E13 -> IGANGA-TORORO | G13: =ROUNDUP(COUNTIF('PT-04'!$L$9:$L$3233,Summary!F13)/5,0) -> 2 | H13: 93 | I13: =AVERAGEIF('PT-04'!$L$9:$L$3233,Summary!F13,'PT-04'!$O$9:$O$3233) -> 1.8 | J13: =AVERAGEIF('PT-04'!$L$9:$L$3233,Summary!F13,'PT-04'!$M$9:$M$3233) -> 14 | K13: =AVERAGEIF('PT-04'!$L$9:$L$3233,Summary!F13,'PT-04'!$N$9:$N$3233) -> 10000
B14: TORORO | C14: TO TORORO | D14: JINJA | E14: TORORO | F14: =D14&"-"&E14 -> JINJA-TORORO | G14: =ROUNDUP(COUNTIF('PT-04'!$L$9:$L$3233,Summary!F14)/5,0) -> 11 | H14: 131 | I14: =AVERAGEIF('PT-04'!$L$9:$L$3233,Summary!F14,'PT-04'!$O$9:$O$3233) -> 2.25 | J14: =AVERAGEIF('PT-04'!$L$9:$L$3233,Summary!F14,'PT-04'!$M$9:$M$3233) -> 14 | K14: =AVERAGEIF('PT-04'!$L$9:$L$3233,Summary!F14,'PT-04'!$N$9:$N$3233) -> 13000
B15: TORORO | C15: TO TORORO | D15: MBALE | E15: TORORO | F15: =D15&"-"&E15 -> MBALE-TORORO | G15: =ROUNDUP(COUNTIF('PT-04'!$L$9:$L$3233,Summary!F15)/5,0) -> 18 | H15: 51 | I15: =AVERAGEIF('PT-04'!$L$9:$L$3233,Summary!F15,'PT-04'!$O$9:$O$3233) -> 1.901236 | J15: =AVERAGEIF('PT-04'!$L$9:$L$3233,Summary!F15,'PT-04'!$M$9:$M$3233) -> 14 | K15: =AVERAGEIF('PT-04'!$L$9:$L$3233,Summary!F15,'PT-04'!$N$9:$N$3233) -> 5112.3596
B16: TORORO | C16: FROM TORORO | D16: TORORO | E16: BUSIA | F16: =D16&"-"&E16 -> TORORO-BUSIA | G16: =ROUNDUP(COUNTIF('PT-04'!$L$9:$L$3233,Summary!F16)/5,0) -> 1 | H16: 52 | I16: =AVERAGEIF('PT-04'!$L$9:$L$3233,Summary!F16,'PT-04'!$O$9:$O$3233) -> 0.5 | J16: =AVERAGEIF('PT-04'!$L$9:$L$3233,Summary!F16,'PT-04'!$M$9:$M$3233) -> 14 | K16: =AVERAGEIF('PT-04'!$L$9:$L$3233,Summary!F16,'PT-04'!$N$9:$N$3233) -> 6000
B17: TORORO | C17: FROM TORORO | D17: TORORO | E17: JINJA | F17: =D17&"-"&E17 -> TORORO-JINJA | G17: =ROUNDUP(COUNTIF('PT-04'!$L$9:$L$3233,Summary!F17)/5,0) -> 3 | H17: 131 | I17: =AVERAGEIF('PT-04'!$L$9:$L$3233,Summary!F17,'PT-04'!$O$9:$O$3233) -> 2.25 | J17: =AVERAGEIF('PT-04'!$L$9:$L$3233,Summary!F17,'PT-04'!$M$9:$M$3233) -> 14 | K17: =AVERAGEIF('PT-04'!$L$9:$L$3233,Summary!F17,'PT-04'!$N$9:$N$3233) -> 13000
... B21: TORORO | C21: FROM LIRA | D21: LIRA | E21: BUSIA | F21: =D21&"-"&E21 -> LIRA-BUSIA | G21: =ROUNDUP(COUNTIF('PT-04'!$L$9:$L$3233,Summary!F21)/5,0) -> 1 | H21: 324 | I21: =AVERAGEIF('PT-04'!$L$9:$L$3233,Summary!F21,'PT-04'!$O$9:$O$3233) -> 5.25 | J21: =AVERAGEIF('PT-04'!$L$9:$L$3233,Summary!F21,'PT-04'!$M$9:$M$3233) -> 56.5 | K21: =AVERAGEIF('PT-04'!$L$9:$L$3233,Summary!F21,'PT-04'!$N$9:$N$3233) -> 25000

Sheet Key
B1: Vehicle Type
A2: 1 | B2: Car
A3: 2 | B3: Station Wagon
A4: 3 | B4: Pickups
A5: 4 | B5: Minibus, matatu
A6: 5 | B6: Medium bus
A7: 6 | B7: Large Bus
A8: 7 | B8: Light Truck
A9: 8 | B9: Medium Truck
A10: 9 | B10: Heavy truck
A11: 10 | B11: Truck Trailer
A12: 11 | B12: Motor cycles
A13: 12 | B13: Tractors
