Workbook

Sheet 23.09 Kira-Kyaliwalla
B1: Consultancy services for Preparation of Expressway Development Master Plan (EDMP) for Uganda
B2: MANUAL CLASSIFIED COUNT (MCC)
B3: ROAD NAME: | C3: MCC-C2-STNO72-KIRA KYALIWAJALLA
C5: Date | D5: 23.09.19 | F5: Location | G5: Kira Police Division | J5: Surveyor | K5: Nairuba Apothio
C6: Dir. From | D6: Kira | F6: Dir. To | G6: Kyaliwajara | J6: Supervisor | K6: ='[1]23.09.19-Namugongo-Ssonde'!K6:L6 -> Tracy
B8: Time / Veh Type | R8: SUMMARY TRAFFIC VOLUMES
C9: 1. Car | D9: 2. Station Wagon | E9: 3. Pickups | F9: 4. Minibus, matatu | G9: 5. Medium bus | H9: 6. Large Bus | I9: 7. Light Truck | J9: 8. Medium Truck | K9: 9. Heavy truck | L9: 10. Truck Trailer | M9: 11. Motor cycles | N9: 12. Tractors | O9: Total Excl M/Cycles | P9: Total All | R9: Time | S9: 1. Car | T9: 2. Station Wagon | U9: 3. Pickups | V9: 4. Minibus, matatu | W9: 5. Medium bus | X9: 6. Large Bus | Y9: 7. Light Truck | Z9: 8. Medium Truck | AA9: 9. Heavy truck | AB9: 10. Truck Trailer | AC9: 11. Motorcycles | AD9: 12. Tractors, Graders | AE9: Total Excl M/ Cycles | AF9: Total All
B10: 07.00 - 07.15 | C10: 0 | D10: 0 | E10: 0 | F10: 0 | G10: 0 | H10: 0 | I10: 0 | J10: 0 | K10: 0 | L10: 0 | M10: 0 | N10: 0 | O10: =SUM(C10:L10,N10) -> 0 | P10: =SUM(C10:N10) -> 0 | R10: 0700-0800 | S10: =SUM(C10:C13) -> 0 | T10: =SUM(D10:D13) -> 0 | U10: =SUM(E10:E13) -> 0 | V10: =SUM(F10:F13) -> 0 | W10: =SUM(G10:G13) -> 0 | X10: =SUM(H10:H13) -> 0 | Y10: =SUM(I10:I13) -> 0 | Z10: =SUM(J10:J13) -> 0 | ... AF10: =SUM(P10:P13) -> 0
B11: 07.15 - 07.30 | C11: 0 | D11: 0 | E11: 0 | F11: 0 | G11: 0 | H11: 0 | I11: 0 | J11: 0 | K11: 0 | L11: 0 | M11: 0 | N11: 0 | O11: =SUM(C11:L11,N11) -> 0 | P11: =SUM(C11:N11) -> 0 | R11: 0800-0900 | S11: =SUM(C14:C17) -> 168 | T11: =SUM(D14:D17) -> 103 | U11: =SUM(E14:E17) -> 49 | V11: =SUM(F14:F17) -> 72 | W11: =SUM(G14:G17) -> 0 | X11: =SUM(H14:H17) -> 0 | Y11: =SUM(I14:I17) -> 16 | Z11: =SUM(J14:J17) -> 12 | ... AF11: =SUM(P14:P17) -> 745
B12: 07.30 - 07.45 | C12: 0 | D12: 0 | E12: 0 | F12: 0 | G12: 0 | H12: 0 | I12: 0 | J12: 0 | K12: 0 | L12: 0 | M12: 0 | N12: 0 | O12: =SUM(C12:L12,N12) -> 0 | P12: =SUM(C12:N12) -> 0 | R12: 0900-1000 | S12: =SUM(C18:C21) -> 136 | T12: =SUM(D18:D21) -> 80 | U12: =SUM(E18:E21) -> 22 | V12: =SUM(F18:F21) -> 93 | W12: =SUM(G18:G21) -> 2 | X12: =SUM(H18:H21) -> 1 | Y12: =SUM(I18:I21) -> 19 | Z12: =SUM(J18:J21) -> 11 | ... AF12: =SUM(P18:P21) -> 747
B13: 07.45 - 08.00 | C13: 0 | D13: 0 | E13: 0 | F13: 0 | G13: 0 | H13: 0 | I13: 0 | J13: 0 | K13: 0 | L13: 0 | M13: 0 | N13: 0 | O13: =SUM(C13:L13,N13) -> 0 | P13: =SUM(C13:N13) -> 0 | R13: 1000-1100 | S13: =SUM(C22:C25) -> 156 | T13: =SUM(D22:D25) -> 62 | U13: =SUM(E22:E25) -> 16 | V13: =SUM(F22:F25) -> 71 | W13: =SUM(G22:G25) -> 0 | X13: =SUM(H22:H25) -> 0 | Y13: =SUM(I22:I25) -> 15 | Z13: =SUM(J22:J25) -> 14 | ... AF13: =SUM(P22:P25) -> 709
B14: 08.00 - 08.15 | C14: 23 | D14: 26 | E14: 7 | F14: 20 | G14: 0 | H14: 0 | I14: 3 | J14: 0 | K14: 0 | L14: 0 | M14: 40 | N14: 0 | O14: =SUM(C14:L14,N14) -> 79 | P14: =SUM(C14:N14) -> 119 | R14: 1100-1200 | S14: =SUM(C26:C29) -> 130 | T14: =SUM(D26:D29) -> 68 | U14: =SUM(E26:E29) -> 27 | V14: =SUM(F26:F29) -> 54 | W14: =SUM(G26:G29) -> 0 | X14: =SUM(H26:H29) -> 0 | Y14: =SUM(I26:I29) -> 14 | Z14: =SUM(J26:J29) -> 23 | ... AF14: =SUM(P26:P29) -> 623
B15: 08.15 - 08.30 | C15: 40 | D15: 15 | E15: 15 | F15: 12 | G15: 0 | H15: 0 | I15: 5 | J15: 0 | K15: 0 | L15: 0 | M15: 58 | N15: 0 | O15: =SUM(C15:L15,N15) -> 87 | P15: =SUM(C15:N15) -> 145 | R15: 1200-1300 | S15: =SUM(C30:C33) -> 108 | T15: =SUM(D30:D33) -> 45 | U15: =SUM(E30:E33) -> 29 | V15: =SUM(F30:F33) -> 60 | W15: =SUM(G30:G33) -> 0 | X15: =SUM(H30:H33) -> 0 | Y15: =SUM(I30:I33) -> 11 | Z15: =SUM(J30:J33) -> 20 | ... AF15: =SUM(P30:P33) -> 547
B16: 08.30 - 08.45 | C16: 59 | D16: 39 | E16: 16 | F16: 22 | G16: 0 | H16: 0 | I16: 4 | J16: 9 | K16: 0 | L16: 0 | M16: 121 | N16: 0 | O16: =SUM(C16:L16,N16) -> 149 | P16: =SUM(C16:N16) -> 270 | R16: 1300-1400 | S16: =SUM(C34:C37) -> 105 | T16: =SUM(D34:D37) -> 57 | U16: =SUM(E34:E37) -> 31 | V16: =SUM(F34:F37) -> 71 | W16: =SUM(G34:G37) -> 0 | X16: =SUM(H34:H37) -> 0 | Y16: =SUM(I34:I37) -> 14 | Z16: =SUM(J34:J37) -> 16 | ... AF16: =SUM(P34:P37) -> 546
B17: 08.45 - 9.00 | C17: 46 | D17: 23 | E17: 11 | F17: 18 | G17: 0 | H17: 0 | I17: 4 | J17: 3 | K17: 2 | L17: 0 | M17: 104 | N17: 0 | O17: =SUM(C17:L17,N17) -> 107 | P17: =SUM(C17:N17) -> 211 | R17: 1400-1500 | S17: =SUM(C38:C41) -> 93 | T17: =SUM(D38:D41) -> 35 | U17: =SUM(E38:E41) -> 22 | V17: =SUM(F38:F41) -> 71 | W17: =SUM(G38:G41) -> 0 | X17: =SUM(H38:H41) -> 0 | Y17: =SUM(I38:I41) -> 12 | Z17: =SUM(J38:J41) -> 26 | ... AF17: =SUM(P38:P41) -> 424
B18: 09.00 - 09.15 | C18: 36 | D18: 23 | E18: 7 | F18: 23 | G18: 0 | H18: 0 | I18: 3 | J18: 0 | K18: 0 | L18: 0 | M18: 95 | N18: 0 | O18: =SUM(C18:L18,N18) -> 92 | P18: =SUM(C18:N18) -> 187 | R18: 1500-1600 | S18: =SUM(C42:C45) -> 91 | T18: =SUM(D42:D45) -> 64 | U18: =SUM(E42:E45) -> 11 | V18: =SUM(F42:F45) -> 61 | W18: =SUM(G42:G45) -> 1 | X18: =SUM(H42:H45) -> 1 | Y18: =SUM(I42:I45) -> 16 | Z18: =SUM(J42:J45) -> 20 | ... AF18: =SUM(P42:P45) -> 393
B19: 09.15 - 09.30 | C19: 35 | D19: 22 | E19: 1 | F19: 28 | G19: 0 | H19: 0 | I19: 4 | J19: 3 | K19: 0 | L19: 2 | M19: 96 | N19: 0 | O19: =SUM(C19:L19,N19) -> 95 | P19: =SUM(C19:N19) -> 191 | R19: 1600-1700 | S19: =SUM(C46:C49) -> 100 | T19: =SUM(D46:D49) -> 100 | U19: =SUM(E46:E49) -> 32 | V19: =SUM(F46:F49) -> 59 | W19: =SUM(G46:G49) -> 2 | X19: =SUM(H46:H49) -> 0 | Y19: =SUM(I46:I49) -> 24 | Z19: =SUM(J46:J49) -> 11 | ... AF19: =SUM(P46:P49) -> 555
B20: 09.30 - 09.45 | C20: 26 | D20: 20 | E20: 10 | F20: 23 | G20: 1 | H20: 0 | I20: 8 | J20: 7 | K20: 0 | L20: 0 | M20: 99 | N20: 0 | O20: =SUM(C20:L20,N20) -> 95 | P20: =SUM(C20:N20) -> 194 | R20: 1700-1800 | S20: =SUM(C50:C53) -> 96 | T20: =SUM(D50:D53) -> 158 | U20: =SUM(E50:E53) -> 27 | V20: =SUM(F50:F53) -> 79 | W20: =SUM(G50:G53) -> 4 | X20: =SUM(H50:H53) -> 0 | Y20: =SUM(I50:I53) -> 33 | Z20: =SUM(J50:J53) -> 6 | ... AF20: =SUM(P50:P53) -> 676
B21: 09.45 - 10.00 | C21: 39 | D21: 15 | E21: 4 | F21: 19 | G21: 1 | H21: 1 | I21: 4 | J21: 1 | K21: 1 | L21: 0 | M21: 90 | N21: 0 | O21: =SUM(C21:L21,N21) -> 85 | P21: =SUM(C21:N21) -> 175 | R21: 1800-1900 | S21: =SUM(C54:C57) -> 56 | T21: =SUM(D54:D57) -> 158 | U21: =SUM(E54:E57) -> 17 | V21: =SUM(F54:F57) -> 66 | W21: =SUM(G54:G57) -> 1 | X21: =SUM(H54:H57) -> 0 | Y21: =SUM(I54:I57) -> 22 | Z21: =SUM(J54:J57) -> 3 | ... AF21: =SUM(P54:P57) -> 573
B22: 10.00 - 10.15 | C22: 43 | D22: 27 | E22: 5 | F22: 22 | G22: 0 | H22: 0 | I22: 3 | J22: 3 | K22: 0 | L22: 0 | M22: 103 | N22: 0 | O22: =SUM(C22:L22,N22) -> 103 | P22: =SUM(C22:N22) -> 206 | R22: AM Peak Hr | S22: =MAX(S10:S12) -> 168 | T22: =MAX(T10:T12) -> 103 | U22: =MAX(U10:U12) -> 49 | V22: =MAX(V10:V12) -> 93 | W22: =MAX(W10:W12) -> 2 | X22: =MAX(X10:X12) -> 1 | Y22: =MAX(Y10:Y12) -> 19 | Z22: =MAX(Z10:Z12) -> 12 | ... AF22: =MAX(AF10:AF12) -> 747
B23: 10.15 - 10.30 | C23: 36 | D23: 15 | E23: 7 | F23: 15 | G23: 0 | H23: 0 | I23: 6 | J23: 6 | K23: 1 | L23: 0 | M23: 96 | N23: 0 | O23: =SUM(C23:L23,N23) -> 86 | P23: =SUM(C23:N23) -> 182 | R23: IP Peak Hr | S23: =MAX(S13:S18) -> 156 | T23: =MAX(T13:T18) -> 68 | U23: =MAX(U13:U18) -> 31 | V23: =MAX(V13:V18) -> 71 | W23: =MAX(W13:W18) -> 1 | X23: =MAX(X13:X18) -> 1 | Y23: =MAX(Y13:Y18) -> 16 | Z23: =MAX(Z13:Z18) -> 26 | ... AF23: =MAX(AF13:AF18) -> 709
B24: 10.30 - 10.45 | C24: 45 | D24: 13 | E24: 1 | F24: 16 | G24: 0 | H24: 0 | I24: 3 | J24: 4 | K24: 1 | L24: 0 | M24: 90 | N24: 0 | O24: =SUM(C24:L24,N24) -> 83 | P24: =SUM(C24:N24) -> 173 | R24: PM Peak Hr | S24: =MAX(S19:S21) -> 100 | T24: =MAX(T19:T21) -> 158 | U24: =MAX(U19:U21) -> 32 | V24: =MAX(V19:V21) -> 79 | W24: =MAX(W19:W21) -> 4 | X24: =MAX(X19:X21) -> 0 | Y24: =MAX(Y19:Y21) -> 33 | Z24: =MAX(Z19:Z21) -> 11 | ... AF24: =MAX(AF19:AF21) -> 676
B25: 10.45 - 11.00 | C25: 32 | D25: 7 | E25: 3 | F25: 18 | G25: 0 | H25: 0 | I25: 3 | J25: 1 | K25: 2 | L25: 0 | M25: 82 | N25: 0 | O25: =SUM(C25:L25,N25) -> 66 | P25: =SUM(C25:N25) -> 148 | R25: AM Period | S25: =SUM(S10:S12) -> 304 | T25: =SUM(T10:T12) -> 183 | U25: =SUM(U10:U12) -> 71 | V25: =SUM(V10:V12) -> 165 | W25: =SUM(W10:W12) -> 2 | X25: =SUM(X10:X12) -> 1 | Y25: =SUM(Y10:Y12) -> 35 | Z25: =SUM(Z10:Z12) -> 23 | ... AF25: =SUM(AF10:AF12) -> 1492
B26: 11.00 - 11.15 | C26: 41 | D26: 30 | E26: 5 | F26: 21 | G26: 0 | H26: 0 | I26: 6 | J26: 6 | K26: 0 | L26: 0 | M26: 85 | N26: 0 | O26: =SUM(C26:L26,N26) -> 109 | P26: =SUM(C26:N26) -> 194 | R26: IP Period | S26: =SUM(S13:S18) -> 683 | T26: =SUM(T13:T18) -> 331 | U26: =SUM(U13:U18) -> 136 | V26: =SUM(V13:V18) -> 388 | W26: =SUM(W13:W18) -> 1 | X26: =SUM(X13:X18) -> 1 | Y26: =SUM(Y13:Y18) -> 82 | Z26: =SUM(Z13:Z18) -> 119 | ... AF26: =SUM(AF13:AF18) -> 3242
B27: 11.15 - 11.30 | C27: 28 | D27: 18 | E27: 3 | F27: 12 | G27: 0 | H27: 0 | I27: 1 | J27: 7 | K27: 0 | L27: 0 | M27: 68 | N27: 0 | O27: =SUM(C27:L27,N27) -> 69 | P27: =SUM(C27:N27) -> 137 | R27: PM Period | S27: =SUM(S19:S21) -> 252 | T27: =SUM(T19:T21) -> 416 | U27: =SUM(U19:U21) -> 76 | V27: =SUM(V19:V21) -> 204 | W27: =SUM(W19:W21) -> 7 | X27: =SUM(X19:X21) -> 0 | Y27: =SUM(Y19:Y21) -> 79 | Z27: =SUM(Z19:Z21) -> 20 | ... AF27: =SUM(AF19:AF21) -> 1804
B28: 11.30 - 11.45 | C28: 30 | D28: 10 | E28: 11 | F28: 13 | G28: 0 | H28: 0 | I28: 2 | J28: 8 | K28: 0 | L28: 0 | M28: 76 | N28: 0 | O28: =SUM(C28:L28,N28) -> 74 | P28: =SUM(C28:N28) -> 150 | R28: 12 Hours | S28: =SUM(S10:S21) -> 1239 | T28: =SUM(T10:T21) -> 930 | U28: =SUM(U10:U21) -> 283 | V28: =SUM(V10:V21) -> 757 | W28: =SUM(W10:W21) -> 10 | X28: =SUM(X10:X21) -> 2 | Y28: =SUM(Y10:Y21) -> 196 | Z28: =SUM(Z10:Z21) -> 162 | ... AF28: =SUM(AF10:AF21) -> 6538
B29: 11.45 - 12.00 | C29: 31 | D29: 10 | E29: 8 | F29: 8 | G29: 0 | H29: 0 | I29: 5 | J29: 2 | K29: 3 | L29: 0 | M29: 75 | N29: 0 | O29: =SUM(C29:L29,N29) -> 67 | P29: =SUM(C29:N29) -> 142
B30: 12.00 - 12.15 | C30: 48 | D30: 14 | E30: 3 | F30: 26 | G30: 0 | H30: 0 | I30: 5 | J30: 7 | K30: 0 | L30: 0 | M30: 87 | N30: 0 | O30: =SUM(C30:L30,N30) -> 103 | P30: =SUM(C30:N30) -> 190
B31: 12.15 - 12.30 | C31: 17 | D31: 10 | E31: 4 | F31: 10 | G31: 0 | H31: 0 | I31: 3 | J31: 5 | K31: 0 | L31: 0 | M31: 72 | N31: 0 | O31: =SUM(C31:L31,N31) -> 49 | P31: =SUM(C31:N31) -> 121
B32: 12.30 - 12.45 | C32: 20 | D32: 12 | E32: 17 | F32: 14 | G32: 0 | H32: 0 | I32: 1 | J32: 3 | K32: 0 | L32: 0 | M32: 55 | N32: 0 | O32: =SUM(C32:L32,N32) -> 67 | P32: =SUM(C32:N32) -> 122
B33: 12.45 - 13.00 | C33: 23 | D33: 9 | E33: 5 | F33: 10 | G33: 0 | H33: 0 | I33: 2 | J33: 5 | K33: 0 | L33: 1 | M33: 59 | N33: 0 | O33: =SUM(C33:L33,N33) -> 55 | P33: =SUM(C33:N33) -> 114
B34: 13.00 - 13.15 | C34: 25 | D34: 12 | E34: 9 | F34: 16 | G34: 0 | H34: 0 | I34: 6 | J34: 3 | K34: 1 | L34: 0 | M34: 66 | N34: 0 | O34: =SUM(C34:L34,N34) -> 72 | P34: =SUM(C34:N34) -> 138
B35: 13.15 - 13.30 | C35: 30 | D35: 22 | E35: 7 | F35: 20 | G35: 0 | H35: 0 | I35: 3 | J35: 5 | K35: 2 | L35: 0 | M35: 62 | N35: 0 | O35: =SUM(C35:L35,N35) -> 89 | P35: =SUM(C35:N35) -> 151
B36: 13.30 - 13.45 | C36: 27 | D36: 12 | E36: 7 | F36: 18 | G36: 0 | H36: 0 | I36: 2 | J36: 6 | K36: 0 | L36: 0 | M36: 71 | N36: 0 | O36: =SUM(C36:L36,N36) -> 72 | P36: =SUM(C36:N36) -> 143
B37: 13.45 - 14.00 | C37: 23 | D37: 11 | E37: 8 | F37: 17 | G37: 0 | H37: 0 | I37: 3 | J37: 2 | K37: 2 | L37: 0 | M37: 48 | N37: 0 | O37: =SUM(C37:L37,N37) -> 66 | P37: =SUM(C37:N37) -> 114
B38: 14.00 - 14.15 | C38: 30 | D38: 10 | E38: 12 | F38: 22 | G38: 0 | H38: 0 | I38: 9 | J38: 9 | K38: 0 | L38: 0 | M38: 60 | N38: 0 | O38: =SUM(C38:L38,N38) -> 92 | P38: =SUM(C38:N38) -> 152
B39: 14.15 - 14.30 | C39: 25 | D39: 7 | E39: 4 | F39: 15 | G39: 0 | H39: 0 | I39: 1 | J39: 8 | K39: 0 | L39: 0 | M39: 50 | N39: 0 | O39: =SUM(C39:L39,N39) -> 60 | P39: =SUM(C39:N39) -> 110
B40: 14.30 - 14.45 | C40: 26 | D40: 12 | E40: 3 | F40: 22 | G40: 0 | H40: 0 | I40: 1 | J40: 5 | K40: 0 | L40: 0 | M40: 28 | N40: 0 | O40: =SUM(C40:L40,N40) -> 69 | P40: =SUM(C40:N40) -> 97
... B57: 18.45 - 19.00 | C57: 11 | D57: 28 | E57: 3 | F57: 14 | G57: 0 | H57: 0 | I57: 6 | J57: 0 | K57: 0 | L57: 0 | M57: 58 | N57: 0 | O57: =SUM(C57:L57,N57) -> 62 | P57: =SUM(C57:N57) -> 120
B58: Totals | C58: =SUM(C10:C57) -> 1239 | D58: =SUM(D10:D57) -> 930 | E58: =SUM(E10:E57) -> 283 | F58: =SUM(F10:F57) -> 757 | G58: =SUM(G10:G57) -> 10 | H58: =SUM(H10:H57) -> 2 | I58: =SUM(I10:I57) -> 196 | J58: =SUM(J10:J57) -> 162 | ... P58: =SUM(P10:P57) -> 6538
...

Sheet 23.09 Kyaliwajalla-Kira
B1: Consultancy services for Preparation of Expressway Development Master Plan (EDMP) for Uganda
B2: MANUAL CLASSIFIED COUNT (MCC)
B3: ROAD NAME: | C3: ='[3]23.09.19 Wakiso-Bukasa'!C3:G3 -> MCC - C2- STN0 64-Bukasa RD
C5: Date | D5: ='[2]23.09.19 -Kira-Kyaliwajara'!D5 -> 23.09.19 | F5: Location | G5: ='[2]23.09.19 -Kira-Kyaliwajara'!G5:H5 -> Kira Police Division | J5: Surveyor | K5: ='[2]23.09.19 -Kira-Kyaliwajara'!K5:L5 -> Nairuba Apothio
C6: Dir. From | D6: ='[3]23.09.19 Wakiso-Bukasa'!D6:E6 -> Wakiso | F6: Dir. To | G6: ='[3]23.09.19 Wakiso-Bukasa'!G6:H6 -> Bukasa | J6: Supervisor | K6: ='[2]23.09.19 -Kira-Kyaliwajara'!K6:L6 -> Tracy
B8: Time / Veh Type | R8: SUMMARY TRAFFIC VOLUMES
C9: 1. Car | D9: 2. Station Wagon | E9: 3. Pickups | F9: 4. Minibus, matatu | G9: 5. Medium bus | H9: 6. Large Bus | I9: 7. Light Truck | J9: 8. Medium Truck | K9: 9. Heavy truck | L9: 10. Truck Trailer | M9: 11. Motor cycles | N9: 12. Tractors | O9: Total Excl M/Cycles | P9: Total All | R9: Time | S9: 1. Car | T9: 2. Station Wagon | U9: 3. Pickups | V9: 4. Minibus, matatu | W9: 5. Medium bus | X9: 6. Large Bus | Y9: 7. Light Truck | Z9: 8. Medium Truck | AA9: 9. Heavy truck | AB9: 10. Truck Trailer | AC9: 11. Motorcycles | AD9: 12. Tractors, Graders | AE9: Total Excl M/ Cycles | AF9: Total All
B10: 07.00 - 07.15 | C10: 13 | D10: 18 | E10: 10 | F10: 3 | G10: 0 | H10: 0 | I10: 0 | J10: 0 | K10: 0 | L10: 0 | M10: 61 | N10: 0 | O10: =SUM(C10:L10,N10) -> 44 | P10: =SUM(C10:N10) -> 105 | R10: 0700-0800 | S10: =SUM(C10:C13) -> 40 | T10: =SUM(D10:D13) -> 95 | U10: =SUM(E10:E13) -> 28 | V10: =SUM(F10:F13) -> 29 | W10: =SUM(G10:G13) -> 0 | X10: =SUM(H10:H13) -> 0 | Y10: =SUM(I10:I13) -> 3 | Z10: =SUM(J10:J13) -> 0 | ... AF10: =SUM(P10:P13) -> 409
B11: 07.15 - 07.30 | C11: 15 | D11: 39 | E11: 7 | F11: 9 | G11: 0 | H11: 0 | I11: 2 | J11: 0 | K11: 1 | L11: 0 | M11: 50 | N11: 0 | O11: =SUM(C11:L11,N11) -> 73 | P11: =SUM(C11:N11) -> 123 | R11: 0800-0900 | S11: =SUM(C14:C17) -> 69 | T11: =SUM(D14:D17) -> 132 | U11: =SUM(E14:E17) -> 11 | V11: =SUM(F14:F17) -> 29 | W11: =SUM(G14:G17) -> 0 | X11: =SUM(H14:H17) -> 0 | Y11: =SUM(I14:I17) -> 13 | Z11: =SUM(J14:J17) -> 2 | ... AF11: =SUM(P14:P17) -> 530
B12: 07.30 - 07.45 | C12: 9 | D12: 26 | E12: 9 | F12: 4 | G12: 0 | H12: 0 | I12: 1 | J12: 0 | K12: 2 | L12: 0 | M12: 45 | N12: 0 | O12: =SUM(C12:L12,N12) -> 51 | P12: =SUM(C12:N12) -> 96 | R12: 0900-1000 | S12: =SUM(C18:C21) -> 51 | T12: =SUM(D18:D21) -> 116 | U12: =SUM(E18:E21) -> 17 | V12: =SUM(F18:F21) -> 64 | W12: =SUM(G18:G21) -> 1 | X12: =SUM(H18:H21) -> 1 | Y12: =SUM(I18:I21) -> 15 | Z12: =SUM(J18:J21) -> 7 | ... AF12: =SUM(P18:P21) -> 646
B13: 07.45 - 08.00 | C13: 3 | D13: 12 | E13: 2 | F13: 13 | G13: 0 | H13: 0 | I13: 0 | J13: 0 | K13: 0 | L13: 0 | M13: 55 | N13: 0 | O13: =SUM(C13:L13,N13) -> 30 | P13: =SUM(C13:N13) -> 85 | R13: 1000-1100 | S13: =SUM(C22:C25) -> 56 | T13: =SUM(D22:D25) -> 115 | U13: =SUM(E22:E25) -> 19 | V13: =SUM(F22:F25) -> 36 | W13: =SUM(G22:G25) -> 11 | X13: =SUM(H22:H25) -> 0 | Y13: =SUM(I22:I25) -> 11 | Z13: =SUM(J22:J25) -> 16 | ... AF13: =SUM(P22:P25) -> 588
B14: 08.00 - 08.15 | C14: 12 | D14: 7 | E14: 2 | F14: 3 | G14: 0 | H14: 0 | I14: 3 | J14: 0 | K14: 0 | L14: 0 | M14: 58 | N14: 0 | O14: =SUM(C14:L14,N14) -> 27 | P14: =SUM(C14:N14) -> 85 | R14: 1100-1200 | S14: =SUM(C26:C29) -> 70 | T14: =SUM(D26:D29) -> 125 | U14: =SUM(E26:E29) -> 23 | V14: =SUM(F26:F29) -> 18 | W14: =SUM(G26:G29) -> 1 | X14: =SUM(H26:H29) -> 0 | Y14: =SUM(I26:I29) -> 41 | Z14: =SUM(J26:J29) -> 11 | ... AF14: =SUM(P26:P29) -> 574
B15: 08.15 - 08.30 | C15: 16 | D15: 34 | E15: 1 | F15: 4 | G15: 0 | H15: 0 | I15: 1 | J15: 1 | K15: 2 | L15: 0 | M15: 55 | N15: 0 | O15: =SUM(C15:L15,N15) -> 59 | P15: =SUM(C15:N15) -> 114 | R15: 1200-1300 | S15: =SUM(C30:C33) -> 63 | T15: =SUM(D30:D33) -> 89 | U15: =SUM(E30:E33) -> 35 | V15: =SUM(F30:F33) -> 25 | W15: =SUM(G30:G33) -> 7 | X15: =SUM(H30:H33) -> 0 | Y15: =SUM(I30:I33) -> 27 | Z15: =SUM(J30:J33) -> 6 | ... AF15: =SUM(P30:P33) -> 513
B16: 08.30 - 08.45 | C16: 21 | D16: 47 | E16: 3 | F16: 12 | G16: 0 | H16: 0 | I16: 4 | J16: 1 | K16: 5 | L16: 1 | M16: 87 | N16: 0 | O16: =SUM(C16:L16,N16) -> 94 | P16: =SUM(C16:N16) -> 181 | R16: 1300-1400 | S16: =SUM(C34:C37) -> 53 | T16: =SUM(D34:D37) -> 101 | U16: =SUM(E34:E37) -> 18 | V16: =SUM(F34:F37) -> 24 | W16: =SUM(G34:G37) -> 0 | X16: =SUM(H34:H37) -> 0 | Y16: =SUM(I34:I37) -> 16 | Z16: =SUM(J34:J37) -> 0 | ... AF16: =SUM(P34:P37) -> 432
B17: 08.45 - 9.00 | C17: 20 | D17: 44 | E17: 5 | F17: 10 | G17: 0 | H17: 0 | I17: 5 | J17: 0 | K17: 2 | L17: 0 | M17: 64 | N17: 0 | O17: =SUM(C17:L17,N17) -> 86 | P17: =SUM(C17:N17) -> 150 | R17: 1400-1500 | S17: =SUM(C38:C41) -> 76 | T17: =SUM(D38:D41) -> 121 | U17: =SUM(E38:E41) -> 21 | V17: =SUM(F38:F41) -> 23 | W17: =SUM(G38:G41) -> 0 | X17: =SUM(H38:H41) -> 0 | Y17: =SUM(I38:I41) -> 49 | Z17: =SUM(J38:J41) -> 17 | ... AF17: =SUM(P38:P41) -> 459
B18: 09.00 - 09.15 | C18: 23 | D18: 21 | E18: 6 | F18: 14 | G18: 0 | H18: 0 | I18: 1 | J18: 1 | K18: 1 | L18: 1 | M18: 95 | N18: 0 | O18: =SUM(C18:L18,N18) -> 68 | P18: =SUM(C18:N18) -> 163 | R18: 1500-1600 | S18: =SUM(C42:C45) -> 80 | T18: =SUM(D42:D45) -> 118 | U18: =SUM(E42:E45) -> 26 | V18: =SUM(F42:F45) -> 33 | W18: =SUM(G42:G45) -> 0 | X18: =SUM(H42:H45) -> 0 | Y18: =SUM(I42:I45) -> 15 | Z18: =SUM(J42:J45) -> 4 | ... AF18: =SUM(P42:P45) -> 414
B19: 09.15 - 09.30 | C19: 8 | D19: 13 | E19: 0 | F19: 10 | G19: 1 | H19: 0 | I19: 3 | J19: 2 | K19: 0 | L19: 0 | M19: 73 | N19: 0 | O19: =SUM(C19:L19,N19) -> 37 | P19: =SUM(C19:N19) -> 110 | R19: 1600-1700 | S19: =SUM(C46:C49) -> 137 | T19: =SUM(D46:D49) -> 204 | U19: =SUM(E46:E49) -> 22 | V19: =SUM(F46:F49) -> 73 | W19: =SUM(G46:G49) -> 0 | X19: =SUM(H46:H49) -> 0 | Y19: =SUM(I46:I49) -> 16 | Z19: =SUM(J46:J49) -> 13 | ... AF19: =SUM(P46:P49) -> 687
B20: 09.30 - 09.45 | C20: 8 | D20: 32 | E20: 3 | F20: 10 | G20: 0 | H20: 0 | I20: 4 | J20: 0 | K20: 2 | L20: 0 | M20: 105 | N20: 0 | O20: =SUM(C20:L20,N20) -> 59 | P20: =SUM(C20:N20) -> 164 | R20: 1700-1800 | S20: =SUM(C50:C53) -> 88 | T20: =SUM(D50:D53) -> 171 | U20: =SUM(E50:E53) -> 17 | V20: =SUM(F50:F53) -> 63 | W20: =SUM(G50:G53) -> 1 | X20: =SUM(H50:H53) -> 1 | Y20: =SUM(I50:I53) -> 12 | Z20: =SUM(J50:J53) -> 6 | ... AF20: =SUM(P50:P53) -> 573
B21: 09.45 - 10.00 | C21: 12 | D21: 50 | E21: 8 | F21: 30 | G21: 0 | H21: 1 | I21: 7 | J21: 4 | K21: 2 | L21: 0 | M21: 95 | N21: 0 | O21: =SUM(C21:L21,N21) -> 114 | P21: =SUM(C21:N21) -> 209 | R21: 1800-1900 | S21: =SUM(C54:C57) -> 107 | T21: =SUM(D54:D57) -> 129 | U21: =SUM(E54:E57) -> 31 | V21: =SUM(F54:F57) -> 38 | W21: =SUM(G54:G57) -> 0 | X21: =SUM(H54:H57) -> 0 | Y21: =SUM(I54:I57) -> 7 | Z21: =SUM(J54:J57) -> 3 | ... AF21: =SUM(P54:P57) -> 523
B22: 10.00 - 10.15 | C22: 13 | D22: 35 | E22: 5 | F22: 14 | G22: 0 | H22: 0 | I22: 2 | J22: 2 | K22: 0 | L22: 0 | M22: 66 | N22: 0 | O22: =SUM(C22:L22,N22) -> 71 | P22: =SUM(C22:N22) -> 137 | R22: AM Peak Hr | S22: =MAX(S10:S12) -> 69 | T22: =MAX(T10:T12) -> 132 | U22: =MAX(U10:U12) -> 28 | V22: =MAX(V10:V12) -> 64 | W22: =MAX(W10:W12) -> 1 | X22: =MAX(X10:X12) -> 1 | Y22: =MAX(Y10:Y12) -> 15 | Z22: =MAX(Z10:Z12) -> 7 | ... AF22: =MAX(AF10:AF12) -> 646
B23: 10.15 - 10.30 | C23: 21 | D23: 31 | E23: 0 | F23: 0 | G23: 10 | H23: 0 | I23: 0 | J23: 9 | K23: 2 | L23: 1 | M23: 108 | N23: 0 | O23: =SUM(C23:L23,N23) -> 74 | P23: =SUM(C23:N23) -> 182 | R23: IP Peak Hr | S23: =MAX(S13:S18) -> 80 | T23: =MAX(T13:T18) -> 125 | U23: =MAX(U13:U18) -> 35 | V23: =MAX(V13:V18) -> 36 | W23: =MAX(W13:W18) -> 11 | X23: =MAX(X13:X18) -> 0 | Y23: =MAX(Y13:Y18) -> 49 | Z23: =MAX(Z13:Z18) -> 17 | ... AF23: =MAX(AF13:AF18) -> 588
B24: 10.30 - 10.45 | C24: 8 | D24: 21 | E24: 8 | F24: 12 | G24: 0 | H24: 0 | I24: 5 | J24: 3 | K24: 2 | L24: 0 | M24: 74 | N24: 0 | O24: =SUM(C24:L24,N24) -> 59 | P24: =SUM(C24:N24) -> 133 | R24: PM Peak Hr | S24: =MAX(S19:S21) -> 137 | T24: =MAX(T19:T21) -> 204 | U24: =MAX(U19:U21) -> 31 | V24: =MAX(V19:V21) -> 73 | W24: =MAX(W19:W21) -> 1 | X24: =MAX(X19:X21) -> 1 | Y24: =MAX(Y19:Y21) -> 16 | Z24: =MAX(Z19:Z21) -> 13 | ... AF24: =MAX(AF19:AF21) -> 687
B25: 10.45 - 11.00 | C25: 14 | D25: 28 | E25: 6 | F25: 10 | G25: 1 | H25: 0 | I25: 4 | J25: 2 | K25: 0 | L25: 0 | M25: 71 | N25: 0 | O25: =SUM(C25:L25,N25) -> 65 | P25: =SUM(C25:N25) -> 136 | R25: AM Period | S25: =SUM(S10:S12) -> 160 | T25: =SUM(T10:T12) -> 343 | U25: =SUM(U10:U12) -> 56 | V25: =SUM(V10:V12) -> 122 | W25: =SUM(W10:W12) -> 1 | X25: =SUM(X10:X12) -> 1 | Y25: =SUM(Y10:Y12) -> 31 | Z25: =SUM(Z10:Z12) -> 9 | ... AF25: =SUM(AF10:AF12) -> 1585
B26: 11.00 - 11.15 | C26: 8 | D26: 16 | E26: 8 | F26: 2 | G26: 0 | H26: 0 | I26: 13 | J26: 4 | K26: 0 | L26: 0 | M26: 93 | N26: 0 | O26: =SUM(C26:L26,N26) -> 51 | P26: =SUM(C26:N26) -> 144 | R26: IP Period | S26: =SUM(S13:S18) -> 398 | T26: =SUM(T13:T18) -> 669 | U26: =SUM(U13:U18) -> 142 | V26: =SUM(V13:V18) -> 159 | W26: =SUM(W13:W18) -> 19 | X26: =SUM(X13:X18) -> 0 | Y26: =SUM(Y13:Y18) -> 159 | Z26: =SUM(Z13:Z18) -> 54 | ... AF26: =SUM(AF13:AF18) -> 2980
B27: 11.15 - 11.30 | C27: 15 | D27: 25 | E27: 4 | F27: 3 | G27: 0 | H27: 0 | I27: 10 | J27: 2 | K27: 1 | L27: 0 | M27: 60 | N27: 0 | O27: =SUM(C27:L27,N27) -> 60 | P27: =SUM(C27:N27) -> 120 | R27: PM Period | S27: =SUM(S19:S21) -> 332 | T27: =SUM(T19:T21) -> 504 | U27: =SUM(U19:U21) -> 70 | V27: =SUM(V19:V21) -> 174 | W27: =SUM(W19:W21) -> 1 | X27: =SUM(X19:X21) -> 1 | Y27: =SUM(Y19:Y21) -> 35 | Z27: =SUM(Z19:Z21) -> 22 | ... AF27: =SUM(AF19:AF21) -> 1783
B28: 11.30 - 11.45 | C28: 33 | D28: 59 | E28: 6 | F28: 3 | G28: 1 | H28: 0 | I28: 10 | J28: 2 | K28: 1 | L28: 0 | M28: 66 | N28: 0 | O28: =SUM(C28:L28,N28) -> 115 | P28: =SUM(C28:N28) -> 181 | R28: 12 Hours | S28: =SUM(S10:S21) -> 890 | T28: =SUM(T10:T21) -> 1516 | U28: =SUM(U10:U21) -> 268 | V28: =SUM(V10:V21) -> 455 | W28: =SUM(W10:W21) -> 21 | X28: =SUM(X10:X21) -> 2 | Y28: =SUM(Y10:Y21) -> 225 | Z28: =SUM(Z10:Z21) -> 85 | ... AF28: =SUM(AF10:AF21) -> 6348
B29: 11.45 - 12.00 | C29: 14 | D29: 25 | E29: 5 | F29: 10 | G29: 0 | H29: 0 | I29: 8 | J29: 3 | K29: 6 | L29: 0 | M29: 58 | N29: 0 | O29: =SUM(C29:L29,N29) -> 71 | P29: =SUM(C29:N29) -> 129
B30: 12.00 - 12.15 | C30: 15 | D30: 18 | E30: 15 | F30: 4 | G30: 4 | H30: 0 | I30: 4 | J30: 1 | K30: 0 | L30: 0 | M30: 63 | N30: 0 | O30: =SUM(C30:L30,N30) -> 61 | P30: =SUM(C30:N30) -> 124
B31: 12.15 - 12.30 | C31: 20 | D31: 29 | E31: 8 | F31: 5 | G31: 3 | H31: 0 | I31: 8 | J31: 4 | K31: 3 | L31: 0 | M31: 95 | N31: 0 | O31: =SUM(C31:L31,N31) -> 80 | P31: =SUM(C31:N31) -> 175
B32: 12.30 - 12.45 | C32: 19 | D32: 30 | E32: 6 | F32: 6 | G32: 0 | H32: 0 | I32: 11 | J32: 1 | K32: 0 | L32: 0 | M32: 40 | N32: 0 | O32: =SUM(C32:L32,N32) -> 73 | P32: =SUM(C32:N32) -> 113
B33: 12.45 - 13.00 | C33: 9 | D33: 12 | E33: 6 | F33: 10 | G33: 0 | H33: 0 | I33: 4 | J33: 0 | K33: 0 | L33: 0 | M33: 60 | N33: 0 | O33: =SUM(C33:L33,N33) -> 41 | P33: =SUM(C33:N33) -> 101
B34: 13.00 - 13.15 | C34: 9 | D34: 35 | E34: 6 | F34: 3 | G34: 0 | H34: 0 | I34: 4 | J34: 0 | K34: 0 | L34: 0 | M34: 60 | N34: 0 | O34: =SUM(C34:L34,N34) -> 57 | P34: =SUM(C34:N34) -> 117
B35: 13.15 - 13.30 | C35: 16 | D35: 20 | E35: 4 | F35: 6 | G35: 0 | H35: 0 | I35: 7 | J35: 0 | K35: 0 | L35: 0 | M35: 56 | N35: 0 | O35: =SUM(C35:L35,N35) -> 53 | P35: =SUM(C35:N35) -> 109
B36: 13.30 - 13.45 | C36: 12 | D36: 28 | E36: 4 | F36: 5 | G36: 0 | H36: 0 | I36: 5 | J36: 0 | K36: 2 | L36: 0 | M36: 54 | N36: 0 | O36: =SUM(C36:L36,N36) -> 56 | P36: =SUM(C36:N36) -> 110
B37: 13.45 - 14.00 | C37: 16 | D37: 18 | E37: 4 | F37: 10 | G37: 0 | H37: 0 | I37: 0 | J37: 0 | K37: 0 | L37: 0 | M37: 48 | N37: 0 | O37: =SUM(C37:L37,N37) -> 48 | P37: =SUM(C37:N37) -> 96
B38: 14.00 - 14.15 | C38: 11 | D38: 20 | E38: 2 | F38: 4 | G38: 0 | H38: 0 | I38: 4 | J38: 9 | K38: 0 | L38: 0 | M38: 29 | N38: 0 | O38: =SUM(C38:L38,N38) -> 50 | P38: =SUM(C38:N38) -> 79
B39: 14.15 - 14.30 | C39: 30 | D39: 38 | E39: 3 | F39: 6 | G39: 0 | H39: 0 | I39: 19 | J39: 5 | K39: 4 | L39: 0 | M39: 60 | N39: 0 | O39: =SUM(C39:L39,N39) -> 105 | P39: =SUM(C39:N39) -> 165
B40: 14.30 - 14.45 | C40: 10 | D40: 45 | E40: 9 | F40: 7 | G40: 0 | H40: 0 | I40: 5 | J40: 3 | K40: 0 | L40: 0 | M40: 25 | N40: 0 | O40: =SUM(C40:L40,N40) -> 79 | P40: =SUM(C40:N40) -> 104
... B57: 18.45 - 19.00 | C57: 44 | D57: 30 | E57: 3 | F57: 13 | G57: 0 | H57: 0 | I57: 1 | J57: 0 | K57: 0 | L57: 0 | M57: 63 | N57: 0 | O57: =SUM(C57:L57,N57) -> 91 | P57: =SUM(C57:N57) -> 154
B58: Totals | C58: =SUM(C10:C57) -> 890 | D58: =SUM(D10:D57) -> 1516 | E58: =SUM(E10:E57) -> 268 | F58: =SUM(F10:F57) -> 455 | G58: =SUM(G10:G57) -> 21 | H58: =SUM(H10:H57) -> 2 | I58: =SUM(I10:I57) -> 225 | J58: =SUM(J10:J57) -> 85 | ... P58: =SUM(P10:P57) -> 6348
...

Sheet 24.09 Kira-Kyaliwajalla
B1: Consultancy services for Preparation of Expressway Development Master Plan (EDMP) for Uganda
B2: MANUAL CLASSIFIED COUNT (MCC)
B3: ROAD NAME: | C3: ='[4]24.09.19 Kyaliwajala-Kira'!C3:G3 -> MCC - C2- STN072 - KIRA POLICE STATION RD
C5: Date | D5: ='[4]24.09.19 Kyaliwajala-Kira'!D5 -> 24.09.19 | F5: Location | G5: ='[4]24.09.19 Kyaliwajala-Kira'!G5:H5 -> KIRA POLICE STATION | J5: Surveyor | K5: Nairuba
C6: Dir. From | D6: KIRA | F6: Dir. To | G6: KYALIWAJALA | J6: Supervisor | K6: ='[4]24.09.19 Kyaliwajala-Kira'!K6:L6 -> Tracy
B8: Time / Veh Type | R8: SUMMARY TRAFFIC VOLUMES
C9: 1. Car | D9: 2. Station Wagon | E9: 3. Pickups | F9: 4. Minibus, matatu | G9: 5. Medium bus | H9: 6. Large Bus | I9: 7. Light Truck | J9: 8. Medium Truck | K9: 9. Heavy truck | L9: 10. Truck Trailer | M9: 11. Motor cycles | N9: 12. Tractors | O9: Total Excl M/Cycles | P9: Total All | R9: Time | S9: 1. Car | T9: 2. Station Wagon | U9: 3. Pickups | V9: 4. Minibus, matatu | W9: 5. Medium bus | X9: 6. Large Bus | Y9: 7. Light Truck | Z9: 8. Medium Truck | AA9: 9. Heavy truck | AB9: 10. Truck Trailer | AC9: 11. Motorcycles | AD9: 12. Tractors, Graders | AE9: Total Excl M/ Cycles | AF9: Total All
B10: 07.00 - 07.15 | C10: 40 | D10: 80 | E10: 15 | F10: 20 | G10: 1 | H10: 0 | I10: 5 | J10: 0 | K10: 2 | L10: 0 | M10: 86 | N10: 0 | O10: =SUM(C10:L10,N10) -> 163 | P10: =SUM(C10:N10) -> 249 | R10: 0700-0800 | S10: =SUM(C10:C13) -> 169 | T10: =SUM(D10:D13) -> 268 | U10: =SUM(E10:E13) -> 43 | V10: =SUM(F10:F13) -> 108 | W10: =SUM(G10:G13) -> 2 | X10: =SUM(H10:H13) -> 0 | Y10: =SUM(I10:I13) -> 27 | Z10: =SUM(J10:J13) -> 0 | ... AF10: =SUM(P10:P13) -> 1057
B11: 07.15 - 07.30 | C11: 46 | D11: 73 | E11: 12 | F11: 26 | G11: 1 | H11: 0 | I11: 7 | J11: 0 | K11: 2 | L11: 0 | M11: 88 | N11: 0 | O11: =SUM(C11:L11,N11) -> 167 | P11: =SUM(C11:N11) -> 255 | R11: 0800-0900 | S11: =SUM(C14:C17) -> 122 | T11: =SUM(D14:D17) -> 216 | U11: =SUM(E14:E17) -> 53 | V11: =SUM(F14:F17) -> 88 | W11: =SUM(G14:G17) -> 0 | X11: =SUM(H14:H17) -> 0 | Y11: =SUM(I14:I17) -> 17 | Z11: =SUM(J14:J17) -> 1 | ... AF11: =SUM(P14:P17) -> 932
B12: 07.30 - 07.45 | C12: 51 | D12: 54 | E12: 9 | F12: 29 | G12: 0 | H12: 0 | I12: 4 | J12: 0 | K12: 2 | L12: 0 | M12: 116 | N12: 0 | O12: =SUM(C12:L12,N12) -> 149 | P12: =SUM(C12:N12) -> 265 | R12: 0900-1000 | S12: =SUM(C18:C21) -> 108 | T12: =SUM(D18:D21) -> 155 | U12: =SUM(E18:E21) -> 25 | V12: =SUM(F18:F21) -> 69 | W12: =SUM(G18:G21) -> 0 | X12: =SUM(H18:H21) -> 0 | Y12: =SUM(I18:I21) -> 32 | Z12: =SUM(J18:J21) -> 6 | ... AF12: =SUM(P18:P21) -> 766
B13: 07.45 - 08.00 | C13: 32 | D13: 61 | E13: 7 | F13: 33 | G13: 0 | H13: 0 | I13: 11 | J13: 0 | K13: 0 | L13: 0 | M13: 144 | N13: 0 | O13: =SUM(C13:L13,N13) -> 144 | P13: =SUM(C13:N13) -> 288 | R13: 1000-1100 | S13: =SUM(C22:C25) -> 153 | T13: =SUM(D22:D25) -> 103 | U13: =SUM(E22:E25) -> 15 | V13: =SUM(F22:F25) -> 50 | W13: =SUM(G22:G25) -> 0 | X13: =SUM(H22:H25) -> 1 | Y13: =SUM(I22:I25) -> 28 | Z13: =SUM(J22:J25) -> 5 | ... AF13: =SUM(P22:P25) -> 646
B14: 08.00 - 08.15 | C14: 33 | D14: 60 | E14: 15 | F14: 22 | G14: 0 | H14: 0 | I14: 1 | J14: 1 | K14: 0 | L14: 0 | M14: 100 | N14: 0 | O14: =SUM(C14:L14,N14) -> 132 | P14: =SUM(C14:N14) -> 232 | R14: 1100-1200 | S14: =SUM(C26:C29) -> 101 | T14: =SUM(D26:D29) -> 95 | U14: =SUM(E26:E29) -> 21 | V14: =SUM(F26:F29) -> 36 | W14: =SUM(G26:G29) -> 0 | X14: =SUM(H26:H29) -> 0 | Y14: =SUM(I26:I29) -> 20 | Z14: =SUM(J26:J29) -> 2 | ... AF14: =SUM(P26:P29) -> 546
B15: 08.15 - 08.30 | C15: 32 | D15: 69 | E15: 5 | F15: 23 | G15: 0 | H15: 0 | I15: 5 | J15: 0 | K15: 0 | L15: 0 | M15: 114 | N15: 0 | O15: =SUM(C15:L15,N15) -> 134 | P15: =SUM(C15:N15) -> 248 | R15: 1200-1300 | S15: =SUM(C30:C33) -> 79 | T15: =SUM(D30:D33) -> 95 | U15: =SUM(E30:E33) -> 5 | V15: =SUM(F30:F33) -> 51 | W15: =SUM(G30:G33) -> 0 | X15: =SUM(H30:H33) -> 0 | Y15: =SUM(I30:I33) -> 30 | Z15: =SUM(J30:J33) -> 5 | ... AF15: =SUM(P30:P33) -> 568
B16: 08.30 - 08.45 | C16: 27 | D16: 50 | E16: 20 | F16: 17 | G16: 0 | H16: 0 | I16: 4 | J16: 0 | K16: 0 | L16: 0 | M16: 102 | N16: 0 | O16: =SUM(C16:L16,N16) -> 118 | P16: =SUM(C16:N16) -> 220 | R16: 1300-1400 | S16: =SUM(C34:C37) -> 78 | T16: =SUM(D34:D37) -> 85 | U16: =SUM(E34:E37) -> 24 | V16: =SUM(F34:F37) -> 45 | W16: =SUM(G34:G37) -> 1 | X16: =SUM(H34:H37) -> 0 | Y16: =SUM(I34:I37) -> 34 | Z16: =SUM(J34:J37) -> 14 | ... AF16: =SUM(P34:P37) -> 504
B17: 08.45 - 9.00 | C17: 30 | D17: 37 | E17: 13 | F17: 26 | G17: 0 | H17: 0 | I17: 7 | J17: 0 | K17: 0 | L17: 0 | M17: 119 | N17: 0 | O17: =SUM(C17:L17,N17) -> 113 | P17: =SUM(C17:N17) -> 232 | R17: 1400-1500 | S17: =SUM(C38:C41) -> 83 | T17: =SUM(D38:D41) -> 79 | U17: =SUM(E38:E41) -> 18 | V17: =SUM(F38:F41) -> 53 | W17: =SUM(G38:G41) -> 2 | X17: =SUM(H38:H41) -> 0 | Y17: =SUM(I38:I41) -> 26 | Z17: =SUM(J38:J41) -> 6 | ... AF17: =SUM(P38:P41) -> 479
B18: 09.00 - 09.15 | C18: 28 | D18: 30 | E18: 5 | F18: 19 | G18: 0 | H18: 0 | I18: 6 | J18: 1 | K18: 1 | L18: 0 | M18: 93 | N18: 0 | O18: =SUM(C18:L18,N18) -> 90 | P18: =SUM(C18:N18) -> 183 | R18: 1500-1600 | S18: =SUM(C42:C45) -> 84 | T18: =SUM(D42:D45) -> 79 | U18: =SUM(E42:E45) -> 18 | V18: =SUM(F42:F45) -> 42 | W18: =SUM(G42:G45) -> 0 | X18: =SUM(H42:H45) -> 0 | Y18: =SUM(I42:I45) -> 18 | Z18: =SUM(J42:J45) -> 13 | ... AF18: =SUM(P42:P45) -> 424
B19: 09.15 - 09.30 | C19: 23 | D19: 45 | E19: 6 | F19: 21 | G19: 0 | H19: 0 | I19: 13 | J19: 1 | K19: 0 | L19: 0 | M19: 80 | N19: 0 | O19: =SUM(C19:L19,N19) -> 109 | P19: =SUM(C19:N19) -> 189 | R19: 1600-1700 | S19: =SUM(C46:C49) -> 121 | T19: =SUM(D46:D49) -> 157 | U19: =SUM(E46:E49) -> 23 | V19: =SUM(F46:F49) -> 52 | W19: =SUM(G46:G49) -> 2 | X19: =SUM(H46:H49) -> 0 | Y19: =SUM(I46:I49) -> 36 | Z19: =SUM(J46:J49) -> 2 | ... AF19: =SUM(P46:P49) -> 685
B20: 09.30 - 09.45 | C20: 35 | D20: 44 | E20: 5 | F20: 14 | G20: 0 | H20: 0 | I20: 8 | J20: 2 | K20: 0 | L20: 0 | M20: 111 | N20: 0 | O20: =SUM(C20:L20,N20) -> 108 | P20: =SUM(C20:N20) -> 219 | R20: 1700-1800 | S20: =SUM(C50:C53) -> 118 | T20: =SUM(D50:D53) -> 160 | U20: =SUM(E50:E53) -> 25 | V20: =SUM(F50:F53) -> 66 | W20: =SUM(G50:G53) -> 4 | X20: =SUM(H50:H53) -> 0 | Y20: =SUM(I50:I53) -> 31 | Z20: =SUM(J50:J53) -> 3 | ... AF20: =SUM(P50:P53) -> 766
B21: 09.45 - 10.00 | C21: 22 | D21: 36 | E21: 9 | F21: 15 | G21: 0 | H21: 0 | I21: 5 | J21: 2 | K21: 0 | L21: 0 | M21: 86 | N21: 0 | O21: =SUM(C21:L21,N21) -> 89 | P21: =SUM(C21:N21) -> 175 | R21: 1800-1900 | S21: =SUM(C54:C57) -> 108 | T21: =SUM(D54:D57) -> 174 | U21: =SUM(E54:E57) -> 17 | V21: =SUM(F54:F57) -> 35 | W21: =SUM(G54:G57) -> 4 | X21: =SUM(H54:H57) -> 0 | Y21: =SUM(I54:I57) -> 26 | Z21: =SUM(J54:J57) -> 4 | ... AF21: =SUM(P54:P57) -> 790
B22: 10.00 - 10.15 | C22: 37 | D22: 30 | E22: 5 | F22: 14 | G22: 0 | H22: 0 | I22: 6 | J22: 1 | K22: 0 | L22: 0 | M22: 61 | N22: 0 | O22: =SUM(C22:L22,N22) -> 93 | P22: =SUM(C22:N22) -> 154 | R22: AM Peak Hr | S22: =MAX(S10:S12) -> 169 | T22: =MAX(T10:T12) -> 268 | U22: =MAX(U10:U12) -> 53 | V22: =MAX(V10:V12) -> 108 | W22: =MAX(W10:W12) -> 2 | X22: =MAX(X10:X12) -> 0 | Y22: =MAX(Y10:Y12) -> 32 | Z22: =MAX(Z10:Z12) -> 6 | ... AF22: =MAX(AF10:AF12) -> 1057
B23: 10.15 - 10.30 | C23: 55 | D23: 30 | E23: 4 | F23: 10 | G23: 0 | H23: 0 | I23: 5 | J23: 1 | K23: 0 | L23: 0 | M23: 92 | N23: 0 | O23: =SUM(C23:L23,N23) -> 105 | P23: =SUM(C23:N23) -> 197 | R23: IP Peak Hr | S23: =MAX(S13:S18) -> 153 | T23: =MAX(T13:T18) -> 103 | U23: =MAX(U13:U18) -> 24 | V23: =MAX(V13:V18) -> 53 | W23: =MAX(W13:W18) -> 2 | X23: =MAX(X13:X18) -> 1 | Y23: =MAX(Y13:Y18) -> 34 | Z23: =MAX(Z13:Z18) -> 14 | ... AF23: =MAX(AF13:AF18) -> 646
B24: 10.30 - 10.45 | C24: 36 | D24: 30 | E24: 4 | F24: 10 | G24: 0 | H24: 0 | I24: 5 | J24: 2 | K24: 1 | L24: 0 | M24: 73 | N24: 0 | O24: =SUM(C24:L24,N24) -> 88 | P24: =SUM(C24:N24) -> 161 | R24: PM Peak Hr | S24: =MAX(S19:S21) -> 121 | T24: =MAX(T19:T21) -> 174 | U24: =MAX(U19:U21) -> 25 | V24: =MAX(V19:V21) -> 66 | W24: =MAX(W19:W21) -> 4 | X24: =MAX(X19:X21) -> 0 | Y24: =MAX(Y19:Y21) -> 36 | Z24: =MAX(Z19:Z21) -> 4 | ... AF24: =MAX(AF19:AF21) -> 790
B25: 10.45 - 11.00 | C25: 25 | D25: 13 | E25: 2 | F25: 16 | G25: 0 | H25: 1 | I25: 12 | J25: 1 | K25: 2 | L25: 0 | M25: 62 | N25: 0 | O25: =SUM(C25:L25,N25) -> 72 | P25: =SUM(C25:N25) -> 134 | R25: AM Period | S25: =SUM(S10:S12) -> 399 | T25: =SUM(T10:T12) -> 639 | U25: =SUM(U10:U12) -> 121 | V25: =SUM(V10:V12) -> 265 | W25: =SUM(W10:W12) -> 2 | X25: =SUM(X10:X12) -> 0 | Y25: =SUM(Y10:Y12) -> 76 | Z25: =SUM(Z10:Z12) -> 7 | ... AF25: =SUM(AF10:AF12) -> 2755
B26: 11.00 - 11.15 | C26: 23 | D26: 26 | E26: 7 | F26: 5 | G26: 0 | H26: 0 | I26: 8 | J26: 2 | K26: 1 | L26: 0 | M26: 66 | N26: 0 | O26: =SUM(C26:L26,N26) -> 72 | P26: =SUM(C26:N26) -> 138 | R26: IP Period | S26: =SUM(S13:S18) -> 578 | T26: =SUM(T13:T18) -> 536 | U26: =SUM(U13:U18) -> 101 | V26: =SUM(V13:V18) -> 277 | W26: =SUM(W13:W18) -> 3 | X26: =SUM(X13:X18) -> 1 | Y26: =SUM(Y13:Y18) -> 156 | Z26: =SUM(Z13:Z18) -> 45 | ... AF26: =SUM(AF13:AF18) -> 3167
B27: 11.15 - 11.30 | C27: 20 | D27: 22 | E27: 2 | F27: 10 | G27: 0 | H27: 0 | I27: 4 | J27: 0 | K27: 1 | L27: 0 | M27: 63 | N27: 0 | O27: =SUM(C27:L27,N27) -> 59 | P27: =SUM(C27:N27) -> 122 | R27: PM Period | S27: =SUM(S19:S21) -> 347 | T27: =SUM(T19:T21) -> 491 | U27: =SUM(U19:U21) -> 65 | V27: =SUM(V19:V21) -> 153 | W27: =SUM(W19:W21) -> 10 | X27: =SUM(X19:X21) -> 0 | Y27: =SUM(Y19:Y21) -> 93 | Z27: =SUM(Z19:Z21) -> 9 | ... AF27: =SUM(AF19:AF21) -> 2241
B28: 11.30 - 11.45 | C28: 21 | D28: 21 | E28: 4 | F28: 7 | G28: 0 | H28: 0 | I28: 5 | J28: 0 | K28: 1 | L28: 0 | M28: 64 | N28: 0 | O28: =SUM(C28:L28,N28) -> 59 | P28: =SUM(C28:N28) -> 123 | R28: 12 Hours | S28: =SUM(S10:S21) -> 1324 | T28: =SUM(T10:T21) -> 1666 | U28: =SUM(U10:U21) -> 287 | V28: =SUM(V10:V21) -> 695 | W28: =SUM(W10:W21) -> 15 | X28: =SUM(X10:X21) -> 1 | Y28: =SUM(Y10:Y21) -> 325 | Z28: =SUM(Z10:Z21) -> 61 | ... AF28: =SUM(AF10:AF21) -> 8163
B29: 11.45 - 12.00 | C29: 37 | D29: 26 | E29: 8 | F29: 14 | G29: 0 | H29: 0 | I29: 3 | J29: 0 | K29: 9 | L29: 1 | M29: 65 | N29: 0 | O29: =SUM(C29:L29,N29) -> 98 | P29: =SUM(C29:N29) -> 163
B30: 12.00 - 12.15 | C30: 25 | D30: 9 | E30: 1 | F30: 11 | G30: 0 | H30: 0 | I30: 7 | J30: 2 | K30: 0 | L30: 0 | M30: 64 | N30: 0 | O30: =SUM(C30:L30,N30) -> 55 | P30: =SUM(C30:N30) -> 119
B31: 12.15 - 12.30 | C31: 22 | D31: 29 | E31: 0 | F31: 15 | G31: 0 | H31: 0 | I31: 11 | J31: 2 | K31: 1 | L31: 1 | M31: 97 | N31: 0 | O31: =SUM(C31:L31,N31) -> 81 | P31: =SUM(C31:N31) -> 178
B32: 12.30 - 12.45 | C32: 10 | D32: 19 | E32: 2 | F32: 16 | G32: 0 | H32: 0 | I32: 7 | J32: 0 | K32: 5 | L32: 0 | M32: 61 | N32: 0 | O32: =SUM(C32:L32,N32) -> 59 | P32: =SUM(C32:N32) -> 120
B33: 12.45 - 13.00 | C33: 22 | D33: 38 | E33: 2 | F33: 9 | G33: 0 | H33: 0 | I33: 5 | J33: 1 | K33: 1 | L33: 0 | M33: 73 | N33: 0 | O33: =SUM(C33:L33,N33) -> 78 | P33: =SUM(C33:N33) -> 151
B34: 13.00 - 13.15 | C34: 21 | D34: 22 | E34: 12 | F34: 12 | G34: 0 | H34: 0 | I34: 13 | J34: 0 | K34: 2 | L34: 0 | M34: 59 | N34: 0 | O34: =SUM(C34:L34,N34) -> 82 | P34: =SUM(C34:N34) -> 141
B35: 13.15 - 13.30 | C35: 8 | D35: 29 | E35: 6 | F35: 13 | G35: 1 | H35: 0 | I35: 7 | J35: 2 | K35: 0 | L35: 0 | M35: 45 | N35: 0 | O35: =SUM(C35:L35,N35) -> 66 | P35: =SUM(C35:N35) -> 111
B36: 13.30 - 13.45 | C36: 21 | D36: 18 | E36: 3 | F36: 12 | G36: 0 | H36: 0 | I36: 6 | J36: 6 | K36: 4 | L36: 0 | M36: 80 | N36: 0 | O36: =SUM(C36:L36,N36) -> 70 | P36: =SUM(C36:N36) -> 150
B37: 13.45 - 14.00 | C37: 28 | D37: 16 | E37: 3 | F37: 8 | G37: 0 | H37: 0 | I37: 8 | J37: 6 | K37: 2 | L37: 0 | M37: 31 | N37: 0 | O37: =SUM(C37:L37,N37) -> 71 | P37: =SUM(C37:N37) -> 102
B38: 14.00 - 14.15 | C38: 23 | D38: 19 | E38: 8 | F38: 20 | G38: 1 | H38: 0 | I38: 8 | J38: 2 | K38: 5 | L38: 0 | M38: 43 | N38: 0 | O38: =SUM(C38:L38,N38) -> 86 | P38: =SUM(C38:N38) -> 129
B39: 14.15 - 14.30 | C39: 24 | D39: 18 | E39: 1 | F39: 11 | G39: 0 | H39: 0 | I39: 5 | J39: 1 | K39: 2 | L39: 1 | M39: 46 | N39: 0 | O39: =SUM(C39:L39,N39) -> 63 | P39: =SUM(C39:N39) -> 109
B40: 14.30 - 14.45 | C40: 21 | D40: 24 | E40: 5 | F40: 10 | G40: 1 | H40: 0 | I40: 5 | J40: 3 | K40: 1 | L40: 0 | M40: 55 | N40: 0 | O40: =SUM(C40:L40,N40) -> 70 | P40: =SUM(C40:N40) -> 125
... B57: 18.45 - 19.00 | C57: 16 | D57: 18 | E57: 3 | F57: 6 | G57: 2 | H57: 0 | I57: 4 | J57: 2 | K57: 1 | L57: 0 | M57: 100 | N57: 0 | O57: =SUM(C57:L57,N57) -> 52 | P57: =SUM(C57:N57) -> 152
B58: Totals | C58: =SUM(C10:C57) -> 1324 | D58: =SUM(D10:D57) -> 1666 | E58: =SUM(E10:E57) -> 287 | F58: =SUM(F10:F57) -> 695 | G58: =SUM(G10:G57) -> 15 | H58: =SUM(H10:H57) -> 1 | I58: =SUM(I10:I57) -> 325 | J58: =SUM(J10:J57) -> 61 | ... P58: =SUM(P10:P57) -> 8163
...

Sheet 24.09 Kyaliwajalla-Kira
B1: Consultancy services for Preparation of Expressway Development Master Plan (EDMP) for Uganda
B2: MANUAL CLASSIFIED COUNT (MCC)
B3: ROAD NAME: | C3: MCC - C2- STN072 - KIRA POLICE STATION RD
C5: Date | D5: 24.09.19 | F5: Location | G5: KIRA POLICE STATION | J5: Surveyor | K5: Isaac
C6: Dir. From | D6: KYALIWAJALA | F6: Dir. To | G6: KIRA | J6: Supervisor | K6: Tracy
B8: Time / Veh Type | R8: SUMMARY TRAFFIC VOLUMES
C9: 1. Car | D9: 2. Station Wagon | E9: 3. Pickups | F9: 4. Minibus, matatu | G9: 5. Medium bus | H9: 6. Large Bus | I9: 7. Light Truck | J9: 8. Medium Truck | K9: 9. Heavy truck | L9: 10. Truck Trailer | M9: 11. Motor cycles | N9: 12. Tractors | O9: Total Excl M/Cycles | P9: Total All | R9: Time | S9: 1. Car | T9: 2. Station Wagon | U9: 3. Pickups | V9: 4. Minibus, matatu | W9: 5. Medium bus | X9: 6. Large Bus | Y9: 7. Light Truck | Z9: 8. Medium Truck | AA9: 9. Heavy truck | AB9: 10. Truck Trailer | AC9: 11. Motorcycles | AD9: 12. Tractors, Graders | AE9: Total Excl M/ Cycles | AF9: Total All
B10: 07.00 - 07.15 | C10: 49 | D10: 11 | E10: 7 | F10: 6 | G10: 0 | H10: 0 | I10: 3 | J10: 0 | K10: 0 | L10: 0 | M10: 63 | N10: 0 | O10: =SUM(C10:L10,N10) -> 76 | P10: =SUM(C10:N10) -> 139 | R10: 0700-0800 | S10: =SUM(C10:C13) -> 168 | T10: =SUM(D10:D13) -> 52 | U10: =SUM(E10:E13) -> 19 | V10: =SUM(F10:F13) -> 23 | W10: =SUM(G10:G13) -> 0 | X10: =SUM(H10:H13) -> 0 | Y10: =SUM(I10:I13) -> 13 | Z10: =SUM(J10:J13) -> 2 | ... AF10: =SUM(P10:P13) -> 516
B11: 07.15 - 07.30 | C11: 45 | D11: 17 | E11: 7 | F11: 9 | G11: 0 | H11: 0 | I11: 3 | J11: 0 | K11: 1 | L11: 0 | M11: 70 | N11: 0 | O11: =SUM(C11:L11,N11) -> 82 | P11: =SUM(C11:N11) -> 152 | R11: 0800-0900 | S11: =SUM(C14:C17) -> 218 | T11: =SUM(D14:D17) -> 68 | U11: =SUM(E14:E17) -> 21 | V11: =SUM(F14:F17) -> 19 | W11: =SUM(G14:G17) -> 0 | X11: =SUM(H14:H17) -> 0 | Y11: =SUM(I14:I17) -> 28 | Z11: =SUM(J14:J17) -> 7 | ... AF11: =SUM(P14:P17) -> 757
B12: 07.30 - 07.45 | C12: 37 | D12: 12 | E12: 2 | F12: 5 | G12: 0 | H12: 0 | I12: 4 | J12: 1 | K12: 0 | L12: 0 | M12: 10 | N12: 0 | O12: =SUM(C12:L12,N12) -> 61 | P12: =SUM(C12:N12) -> 71 | R12: 0900-1000 | S12: =SUM(C18:C21) -> 117 | T12: =SUM(D18:D21) -> 28 | U12: =SUM(E18:E21) -> 24 | V12: =SUM(F18:F21) -> 9 | W12: =SUM(G18:G21) -> 0 | X12: =SUM(H18:H21) -> 1 | Y12: =SUM(I18:I21) -> 11 | Z12: =SUM(J18:J21) -> 4 | ... AF12: =SUM(P18:P21) -> 586
B13: 07.45 - 08.00 | C13: 37 | D13: 12 | E13: 3 | F13: 3 | G13: 0 | H13: 0 | I13: 3 | J13: 1 | K13: 0 | L13: 0 | M13: 95 | N13: 0 | O13: =SUM(C13:L13,N13) -> 59 | P13: =SUM(C13:N13) -> 154 | R13: 1000-1100 | S13: =SUM(C22:C25) -> 133 | T13: =SUM(D22:D25) -> 84 | U13: =SUM(E22:E25) -> 31 | V13: =SUM(F22:F25) -> 14 | W13: =SUM(G22:G25) -> 0 | X13: =SUM(H22:H25) -> 0 | Y13: =SUM(I22:I25) -> 24 | Z13: =SUM(J22:J25) -> 8 | ... AF13: =SUM(P22:P25) -> 658
B14: 08.00 - 08.15 | C14: 68 | D14: 17 | E14: 4 | F14: 6 | G14: 0 | H14: 0 | I14: 6 | J14: 1 | K14: 1 | L14: 0 | M14: 118 | N14: 0 | O14: =SUM(C14:L14,N14) -> 103 | P14: =SUM(C14:N14) -> 221 | R14: 1100-1200 | S14: =SUM(C26:C29) -> 92 | T14: =SUM(D26:D29) -> 50 | U14: =SUM(E26:E29) -> 21 | V14: =SUM(F26:F29) -> 18 | W14: =SUM(G26:G29) -> 0 | X14: =SUM(H26:H29) -> 0 | Y14: =SUM(I26:I29) -> 30 | Z14: =SUM(J26:J29) -> 4 | ... AF14: =SUM(P26:P29) -> 493
B15: 08.15 - 08.30 | C15: 46 | D15: 19 | E15: 8 | F15: 6 | G15: 0 | H15: 0 | I15: 4 | J15: 0 | K15: 0 | L15: 0 | M15: 73 | N15: 0 | O15: =SUM(C15:L15,N15) -> 83 | P15: =SUM(C15:N15) -> 156 | R15: 1200-1300 | S15: =SUM(C30:C33) -> 104 | T15: =SUM(D30:D33) -> 57 | U15: =SUM(E30:E33) -> 46 | V15: =SUM(F30:F33) -> 18 | W15: =SUM(G30:G33) -> 0 | X15: =SUM(H30:H33) -> 0 | Y15: =SUM(I30:I33) -> 20 | Z15: =SUM(J30:J33) -> 7 | ... AF15: =SUM(P30:P33) -> 513
B16: 08.30 - 08.45 | C16: 58 | D16: 19 | E16: 4 | F16: 4 | G16: 0 | H16: 0 | I16: 5 | J16: 1 | K16: 3 | L16: 0 | M16: 76 | N16: 0 | O16: =SUM(C16:L16,N16) -> 94 | P16: =SUM(C16:N16) -> 170 | R16: 1300-1400 | S16: =SUM(C34:C37) -> 102 | T16: =SUM(D34:D37) -> 51 | U16: =SUM(E34:E37) -> 25 | V16: =SUM(F34:F37) -> 15 | W16: =SUM(G34:G37) -> 0 | X16: =SUM(H34:H37) -> 0 | Y16: =SUM(I34:I37) -> 24 | Z16: =SUM(J34:J37) -> 10 | ... AF16: =SUM(P34:P37) -> 486
B17: 08.45 - 9.00 | C17: 46 | D17: 13 | E17: 5 | F17: 3 | G17: 0 | H17: 0 | I17: 13 | J17: 5 | K17: 2 | L17: 0 | M17: 123 | N17: 0 | O17: =SUM(C17:L17,N17) -> 87 | P17: =SUM(C17:N17) -> 210 | R17: 1400-1500 | S17: =SUM(C38:C41) -> 79 | T17: =SUM(D38:D41) -> 46 | U17: =SUM(E38:E41) -> 53 | V17: =SUM(F38:F41) -> 14 | W17: =SUM(G38:G41) -> 2 | X17: =SUM(H38:H41) -> 0 | Y17: =SUM(I38:I41) -> 16 | Z17: =SUM(J38:J41) -> 6 | ... AF17: =SUM(P38:P41) -> 502
B18: 09.00 - 09.15 | C18: 23 | D18: 4 | E18: 9 | F18: 2 | G18: 0 | H18: 1 | I18: 3 | J18: 2 | K18: 0 | L18: 0 | M18: 102 | N18: 0 | O18: =SUM(C18:L18,N18) -> 44 | P18: =SUM(C18:N18) -> 146 | R18: 1500-1600 | S18: =SUM(C42:C45) -> 99 | T18: =SUM(D42:D45) -> 44 | U18: =SUM(E42:E45) -> 37 | V18: =SUM(F42:F45) -> 29 | W18: =SUM(G42:G45) -> 0 | X18: =SUM(H42:H45) -> 0 | Y18: =SUM(I42:I45) -> 9 | Z18: =SUM(J42:J45) -> 4 | ... AF18: =SUM(P42:P45) -> 480
B19: 09.15 - 09.30 | C19: 38 | D19: 5 | E19: 2 | F19: 1 | G19: 0 | H19: 0 | I19: 3 | J19: 0 | K19: 1 | L19: 0 | M19: 76 | N19: 0 | O19: =SUM(C19:L19,N19) -> 50 | P19: =SUM(C19:N19) -> 126 | R19: 1600-1700 | S19: =SUM(C46:C49) -> 165 | T19: =SUM(D46:D49) -> 140 | U19: =SUM(E46:E49) -> 20 | V19: =SUM(F46:F49) -> 36 | W19: =SUM(G46:G49) -> 1 | X19: =SUM(H46:H49) -> 0 | Y19: =SUM(I46:I49) -> 17 | Z19: =SUM(J46:J49) -> 8 | ... AF19: =SUM(P46:P49) -> 715
B20: 09.30 - 09.45 | C20: 28 | D20: 11 | E20: 7 | F20: 3 | G20: 0 | H20: 0 | I20: 3 | J20: 2 | K20: 0 | L20: 0 | M20: 110 | N20: 0 | O20: =SUM(C20:L20,N20) -> 54 | P20: =SUM(C20:N20) -> 164 | R20: 1700-1800 | S20: =SUM(C50:C53) -> 199 | T20: =SUM(D50:D53) -> 149 | U20: =SUM(E50:E53) -> 34 | V20: =SUM(F50:F53) -> 31 | W20: =SUM(G50:G53) -> 3 | X20: =SUM(H50:H53) -> 0 | Y20: =SUM(I50:I53) -> 10 | Z20: =SUM(J50:J53) -> 3 | ... AF20: =SUM(P50:P53) -> 761
B21: 09.45 - 10.00 | C21: 28 | D21: 8 | E21: 6 | F21: 3 | G21: 0 | H21: 0 | I21: 2 | J21: 0 | K21: 2 | L21: 0 | M21: 101 | N21: 0 | O21: =SUM(C21:L21,N21) -> 49 | P21: =SUM(C21:N21) -> 150 | R21: 1800-1900 | S21: =SUM(C54:C57) -> 189 | T21: =SUM(D54:D57) -> 140 | U21: =SUM(E54:E57) -> 47 | V21: =SUM(F54:F57) -> 21 | W21: =SUM(G54:G57) -> 0 | X21: =SUM(H54:H57) -> 0 | Y21: =SUM(I54:I57) -> 12 | Z21: =SUM(J54:J57) -> 2 | ... AF21: =SUM(P54:P57) -> 775
B22: 10.00 - 10.15 | C22: 38 | D22: 15 | E22: 7 | F22: 2 | G22: 0 | H22: 0 | I22: 4 | J22: 1 | K22: 0 | L22: 0 | M22: 98 | N22: 0 | O22: =SUM(C22:L22,N22) -> 67 | P22: =SUM(C22:N22) -> 165 | R22: AM Peak Hr | S22: =MAX(S10:S12) -> 218 | T22: =MAX(T10:T12) -> 68 | U22: =MAX(U10:U12) -> 24 | V22: =MAX(V10:V12) -> 23 | W22: =MAX(W10:W12) -> 0 | X22: =MAX(X10:X12) -> 1 | Y22: =MAX(Y10:Y12) -> 28 | Z22: =MAX(Z10:Z12) -> 7 | ... AF22: =MAX(AF10:AF12) -> 757
B23: 10.15 - 10.30 | C23: 33 | D23: 22 | E23: 5 | F23: 5 | G23: 0 | H23: 0 | I23: 6 | J23: 2 | K23: 2 | L23: 0 | M23: 95 | N23: 0 | O23: =SUM(C23:L23,N23) -> 75 | P23: =SUM(C23:N23) -> 170 | R23: IP Peak Hr | S23: =MAX(S13:S18) -> 133 | T23: =MAX(T13:T18) -> 84 | U23: =MAX(U13:U18) -> 53 | V23: =MAX(V13:V18) -> 29 | W23: =MAX(W13:W18) -> 2 | X23: =MAX(X13:X18) -> 0 | Y23: =MAX(Y13:Y18) -> 30 | Z23: =MAX(Z13:Z18) -> 10 | ... AF23: =MAX(AF13:AF18) -> 658
B24: 10.30 - 10.45 | C24: 26 | D24: 18 | E24: 10 | F24: 7 | G24: 0 | H24: 0 | I24: 5 | J24: 1 | K24: 4 | L24: 0 | M24: 81 | N24: 0 | O24: =SUM(C24:L24,N24) -> 71 | P24: =SUM(C24:N24) -> 152 | R24: PM Peak Hr | S24: =MAX(S19:S21) -> 199 | T24: =MAX(T19:T21) -> 149 | U24: =MAX(U19:U21) -> 47 | V24: =MAX(V19:V21) -> 36 | W24: =MAX(W19:W21) -> 3 | X24: =MAX(X19:X21) -> 0 | Y24: =MAX(Y19:Y21) -> 17 | Z24: =MAX(Z19:Z21) -> 8 | ... AF24: =MAX(AF19:AF21) -> 775
B25: 10.45 - 11.00 | C25: 36 | D25: 29 | E25: 9 | F25: 0 | G25: 0 | H25: 0 | I25: 9 | J25: 4 | K25: 1 | L25: 0 | M25: 82 | N25: 1 | O25: =SUM(C25:L25,N25) -> 89 | P25: =SUM(C25:N25) -> 171 | R25: AM Period | S25: =SUM(S10:S12) -> 503 | T25: =SUM(T10:T12) -> 148 | U25: =SUM(U10:U12) -> 64 | V25: =SUM(V10:V12) -> 51 | W25: =SUM(W10:W12) -> 0 | X25: =SUM(X10:X12) -> 1 | Y25: =SUM(Y10:Y12) -> 52 | Z25: =SUM(Z10:Z12) -> 13 | ... AF25: =SUM(AF10:AF12) -> 1859
B26: 11.00 - 11.15 | C26: 21 | D26: 9 | E26: 3 | F26: 4 | G26: 0 | H26: 0 | I26: 6 | J26: 3 | K26: 3 | L26: 0 | M26: 72 | N26: 0 | O26: =SUM(C26:L26,N26) -> 49 | P26: =SUM(C26:N26) -> 121 | R26: IP Period | S26: =SUM(S13:S18) -> 609 | T26: =SUM(T13:T18) -> 332 | U26: =SUM(U13:U18) -> 213 | V26: =SUM(V13:V18) -> 108 | W26: =SUM(W13:W18) -> 2 | X26: =SUM(X13:X18) -> 0 | Y26: =SUM(Y13:Y18) -> 123 | Z26: =SUM(Z13:Z18) -> 39 | ... AF26: =SUM(AF13:AF18) -> 3132
B27: 11.15 - 11.30 | C27: 31 | D27: 12 | E27: 7 | F27: 6 | G27: 0 | H27: 0 | I27: 7 | J27: 1 | K27: 0 | L27: 0 | M27: 70 | N27: 0 | O27: =SUM(C27:L27,N27) -> 64 | P27: =SUM(C27:N27) -> 134 | R27: PM Period | S27: =SUM(S19:S21) -> 553 | T27: =SUM(T19:T21) -> 429 | U27: =SUM(U19:U21) -> 101 | V27: =SUM(V19:V21) -> 88 | W27: =SUM(W19:W21) -> 4 | X27: =SUM(X19:X21) -> 0 | Y27: =SUM(Y19:Y21) -> 39 | Z27: =SUM(Z19:Z21) -> 13 | ... AF27: =SUM(AF19:AF21) -> 2251
B28: 11.30 - 11.45 | C28: 22 | D28: 16 | E28: 5 | F28: 2 | G28: 0 | H28: 0 | I28: 8 | J28: 0 | K28: 1 | L28: 0 | M28: 69 | N28: 0 | O28: =SUM(C28:L28,N28) -> 54 | P28: =SUM(C28:N28) -> 123 | R28: 12 Hours | S28: =SUM(S10:S21) -> 1665 | T28: =SUM(T10:T21) -> 909 | U28: =SUM(U10:U21) -> 378 | V28: =SUM(V10:V21) -> 247 | W28: =SUM(W10:W21) -> 6 | X28: =SUM(X10:X21) -> 1 | Y28: =SUM(Y10:Y21) -> 214 | Z28: =SUM(Z10:Z21) -> 65 | ... AF28: =SUM(AF10:AF21) -> 7242
B29: 11.45 - 12.00 | C29: 18 | D29: 13 | E29: 6 | F29: 6 | G29: 0 | H29: 0 | I29: 9 | J29: 0 | K29: 0 | L29: 0 | M29: 63 | N29: 0 | O29: =SUM(C29:L29,N29) -> 52 | P29: =SUM(C29:N29) -> 115
B30: 12.00 - 12.15 | C30: 23 | D30: 16 | E30: 11 | F30: 4 | G30: 0 | H30: 0 | I30: 3 | J30: 1 | K30: 2 | L30: 0 | M30: 63 | N30: 0 | O30: =SUM(C30:L30,N30) -> 60 | P30: =SUM(C30:N30) -> 123
B31: 12.15 - 12.30 | C31: 36 | D31: 21 | E31: 14 | F31: 2 | G31: 0 | H31: 0 | I31: 6 | J31: 0 | K31: 0 | L31: 0 | M31: 67 | N31: 0 | O31: =SUM(C31:L31,N31) -> 79 | P31: =SUM(C31:N31) -> 146
B32: 12.30 - 12.45 | C32: 26 | D32: 14 | E32: 16 | F32: 6 | G32: 0 | H32: 0 | I32: 4 | J32: 4 | K32: 1 | L32: 0 | M32: 59 | N32: 0 | O32: =SUM(C32:L32,N32) -> 71 | P32: =SUM(C32:N32) -> 130
B33: 12.45 - 13.00 | C33: 19 | D33: 6 | E33: 5 | F33: 6 | G33: 0 | H33: 0 | I33: 7 | J33: 2 | K33: 3 | L33: 0 | M33: 66 | N33: 0 | O33: =SUM(C33:L33,N33) -> 48 | P33: =SUM(C33:N33) -> 114
B34: 13.00 - 13.15 | C34: 21 | D34: 7 | E34: 4 | F34: 2 | G34: 0 | H34: 0 | I34: 7 | J34: 2 | K34: 1 | L34: 0 | M34: 68 | N34: 0 | O34: =SUM(C34:L34,N34) -> 44 | P34: =SUM(C34:N34) -> 112
B35: 13.15 - 13.30 | C35: 24 | D35: 16 | E35: 7 | F35: 4 | G35: 0 | H35: 0 | I35: 6 | J35: 3 | K35: 3 | L35: 0 | M35: 66 | N35: 0 | O35: =SUM(C35:L35,N35) -> 63 | P35: =SUM(C35:N35) -> 129
B36: 13.30 - 13.45 | C36: 30 | D36: 13 | E36: 6 | F36: 6 | G36: 0 | H36: 0 | I36: 7 | J36: 3 | K36: 3 | L36: 0 | M36: 58 | N36: 0 | O36: =SUM(C36:L36,N36) -> 68 | P36: =SUM(C36:N36) -> 126
B37: 13.45 - 14.00 | C37: 27 | D37: 15 | E37: 8 | F37: 3 | G37: 0 | H37: 0 | I37: 4 | J37: 2 | K37: 3 | L37: 0 | M37: 57 | N37: 0 | O37: =SUM(C37:L37,N37) -> 62 | P37: =SUM(C37:N37) -> 119
B38: 14.00 - 14.15 | C38: 18 | D38: 7 | E38: 9 | F38: 3 | G38: 0 | H38: 0 | I38: 6 | J38: 3 | K38: 3 | L38: 0 | M38: 68 | N38: 0 | O38: =SUM(C38:L38,N38) -> 49 | P38: =SUM(C38:N38) -> 117
B39: 14.15 - 14.30 | C39: 24 | D39: 16 | E39: 18 | F39: 3 | G39: 0 | H39: 0 | I39: 3 | J39: 1 | K39: 4 | L39: 0 | M39: 66 | N39: 0 | O39: =SUM(C39:L39,N39) -> 69 | P39: =SUM(C39:N39) -> 135
B40: 14.30 - 14.45 | C40: 19 | D40: 11 | E40: 11 | F40: 5 | G40: 0 | H40: 0 | I40: 3 | J40: 2 | K40: 3 | L40: 0 | M40: 72 | N40: 0 | O40: =SUM(C40:L40,N40) -> 54 | P40: =SUM(C40:N40) -> 126
... B57: 18.45 - 19.00 | C57: 49 | D57: 35 | E57: 13 | F57: 3 | G57: 0 | H57: 0 | I57: 4 | J57: 0 | K57: 0 | L57: 0 | M57: 90 | N57: 0 | O57: =SUM(C57:L57,N57) -> 104 | P57: =SUM(C57:N57) -> 194
B58: Totals | C58: =SUM(C10:C57) -> 1665 | D58: =SUM(D10:D57) -> 909 | E58: =SUM(E10:E57) -> 378 | F58: =SUM(F10:F57) -> 247 | G58: =SUM(G10:G57) -> 6 | H58: =SUM(H10:H57) -> 1 | I58: =SUM(I10:I57) -> 214 | J58: =SUM(J10:J57) -> 65 | ... P58: =SUM(P10:P57) -> 7242
...

Sheet 25.09 Kira-Kyaliwajalla
B1: Consultancy services for Preparation of Expressway Development Master Plan (EDMP) for Uganda
B2: MANUAL CLASSIFIED COUNT (MCC)
B3: ROAD NAME: | C3: ='23.09 Kira-Kyaliwalla'!C3:G3 -> MCC-C2-STNO72-KIRA KYALIWAJALLA
C5: Date | D5: 25.07.19 | F5: Location | G5: ='23.09 Kira-Kyaliwalla'!G5:H5 -> Kira Police Division | J5: Surveyor | K5: ='23.09 Kira-Kyaliwalla'!K5:L5 -> Nairuba Apothio
C6: Dir. From | D6: ='23.09 Kira-Kyaliwalla'!D6:E6 -> Kira | F6: Dir. To | G6: ='23.09 Kira-Kyaliwalla'!G6:H6 -> Kyaliwajara | J6: Supervisor | K6: ='23.09 Kira-Kyaliwalla'!K6:L6 -> Tracy
B8: Time / Veh Type | R8: SUMMARY TRAFFIC VOLUMES
C9: 1. Car | D9: 2. Station Wagon | E9: 3. Pickups | F9: 4. Minibus, matatu | G9: 5. Medium bus | H9: 6. Large Bus | I9: 7. Light Truck | J9: 8. Medium Truck | K9: 9. Heavy truck | L9: 10. Truck Trailer | M9: 11. Motor cycles | N9: 12. Tractors | O9: Total Excl M/Cycles | P9: Total All | R9: Time | S9: 1. Car | T9: 2. Station Wagon | U9: 3. Pickups | V9: 4. Minibus, matatu | W9: 5. Medium bus | X9: 6. Large Bus | Y9: 7. Light Truck | Z9: 8. Medium Truck | AA9: 9. Heavy truck | AB9: 10. Truck Trailer | AC9: 11. Motorcycles | AD9: 12. Tractors, Graders | AE9: Total Excl M/ Cycles | AF9: Total All
B10: 07.00 - 07.15 | C10: 70 | D10: 60 | E10: 8 | F10: 14 | G10: 2 | H10: 0 | I10: 4 | J10: 0 | K10: 1 | L10: 0 | M10: 105 | N10: 0 | O10: =SUM(C10:L10,N10) -> 159 | P10: =SUM(C10:N10) -> 264 | R10: 0700-0800 | S10: =SUM(C10:C13) -> 249 | T10: =SUM(D10:D13) -> 219 | U10: =SUM(E10:E13) -> 48 | V10: =SUM(F10:F13) -> 64 | W10: =SUM(G10:G13) -> 2 | X10: =SUM(H10:H13) -> 0 | Y10: =SUM(I10:I13) -> 17 | Z10: =SUM(J10:J13) -> 3 | ... AF10: =SUM(P10:P13) -> 1064
B11: 07.15 - 07.30 | C11: 69 | D11: 54 | E11: 18 | F11: 18 | G11: 0 | H11: 0 | I11: 5 | J11: 0 | K11: 1 | L11: 0 | M11: 133 | N11: 0 | O11: =SUM(C11:L11,N11) -> 165 | P11: =SUM(C11:N11) -> 298 | R11: 0800-0900 | S11: =SUM(C14:C17) -> 183 | T11: =SUM(D14:D17) -> 160 | U11: =SUM(E14:E17) -> 32 | V11: =SUM(F14:F17) -> 46 | W11: =SUM(G14:G17) -> 0 | X11: =SUM(H14:H17) -> 0 | Y11: =SUM(I14:I17) -> 29 | Z11: =SUM(J14:J17) -> 3 | ... AF11: =SUM(P14:P17) -> 876
B12: 07.30 - 07.45 | C12: 56 | D12: 49 | E12: 12 | F12: 20 | G12: 0 | H12: 0 | I12: 4 | J12: 0 | K12: 2 | L12: 1 | M12: 114 | N12: 0 | O12: =SUM(C12:L12,N12) -> 144 | P12: =SUM(C12:N12) -> 258 | R12: 0900-1000 | S12: =SUM(C18:C21) -> 152 | T12: =SUM(D18:D21) -> 100 | U12: =SUM(E18:E21) -> 32 | V12: =SUM(F18:F21) -> 40 | W12: =SUM(G18:G21) -> 0 | X12: =SUM(H18:H21) -> 3 | Y12: =SUM(I18:I21) -> 27 | Z12: =SUM(J18:J21) -> 2 | ... AF12: =SUM(P18:P21) -> 724
B13: 07.45 - 08.00 | C13: 54 | D13: 56 | E13: 10 | F13: 12 | G13: 0 | H13: 0 | I13: 4 | J13: 3 | K13: 0 | L13: 0 | M13: 105 | N13: 0 | O13: =SUM(C13:L13,N13) -> 139 | P13: =SUM(C13:N13) -> 244 | R13: 1000-1100 | S13: =SUM(C22:C25) -> 129 | T13: =SUM(D22:D25) -> 96 | U13: =SUM(E22:E25) -> 26 | V13: =SUM(F22:F25) -> 49 | W13: =SUM(G22:G25) -> 1 | X13: =SUM(H22:H25) -> 0 | Y13: =SUM(I22:I25) -> 34 | Z13: =SUM(J22:J25) -> 8 | ... AF13: =SUM(P22:P25) -> 695
B14: 08.00 - 08.15 | C14: 53 | D14: 38 | E14: 11 | F14: 11 | G14: 0 | H14: 0 | I14: 7 | J14: 3 | K14: 1 | L14: 0 | M14: 115 | N14: 1 | O14: =SUM(C14:L14,N14) -> 125 | P14: =SUM(C14:N14) -> 240 | R14: 1100-1200 | S14: =SUM(C26:C29) -> 122 | T14: =SUM(D26:D29) -> 88 | U14: =SUM(E26:E29) -> 26 | V14: =SUM(F26:F29) -> 48 | W14: =SUM(G26:G29) -> 2 | X14: =SUM(H26:H29) -> 1 | Y14: =SUM(I26:I29) -> 37 | Z14: =SUM(J26:J29) -> 6 | ... AF14: =SUM(P26:P29) -> 658
B15: 08.15 - 08.30 | C15: 49 | D15: 48 | E15: 6 | F15: 10 | G15: 0 | H15: 0 | I15: 10 | J15: 0 | K15: 1 | L15: 0 | M15: 121 | N15: 0 | O15: =SUM(C15:L15,N15) -> 124 | P15: =SUM(C15:N15) -> 245 | R15: 1200-1300 | S15: =SUM(C30:C33) -> 113 | T15: =SUM(D30:D33) -> 74 | U15: =SUM(E30:E33) -> 18 | V15: =SUM(F30:F33) -> 40 | W15: =SUM(G30:G33) -> 1 | X15: =SUM(H30:H33) -> 0 | Y15: =SUM(I30:I33) -> 33 | Z15: =SUM(J30:J33) -> 7 | ... AF15: =SUM(P30:P33) -> 553
B16: 08.30 - 08.45 | C16: 43 | D16: 45 | E16: 7 | F16: 12 | G16: 0 | H16: 0 | I16: 5 | J16: 0 | K16: 2 | L16: 0 | M16: 89 | N16: 0 | O16: =SUM(C16:L16,N16) -> 114 | P16: =SUM(C16:N16) -> 203 | R16: 1300-1400 | S16: =SUM(C34:C37) -> 129 | T16: =SUM(D34:D37) -> 80 | U16: =SUM(E34:E37) -> 19 | V16: =SUM(F34:F37) -> 35 | W16: =SUM(G34:G37) -> 0 | X16: =SUM(H34:H37) -> 0 | Y16: =SUM(I34:I37) -> 31 | Z16: =SUM(J34:J37) -> 5 | ... AF16: =SUM(P34:P37) -> 590
B17: 08.45 - 9.00 | C17: 38 | D17: 29 | E17: 8 | F17: 13 | G17: 0 | H17: 0 | I17: 7 | J17: 0 | K17: 0 | L17: 0 | M17: 92 | N17: 1 | O17: =SUM(C17:L17,N17) -> 96 | P17: =SUM(C17:N17) -> 188 | R17: 1400-1500 | S17: =SUM(C38:C41) -> 119 | T17: =SUM(D38:D41) -> 60 | U17: =SUM(E38:E41) -> 22 | V17: =SUM(F38:F41) -> 43 | W17: =SUM(G38:G41) -> 3 | X17: =SUM(H38:H41) -> 0 | Y17: =SUM(I38:I41) -> 26 | Z17: =SUM(J38:J41) -> 4 | ... AF17: =SUM(P38:P41) -> 570
B18: 09.00 - 09.15 | C18: 55 | D18: 26 | E18: 9 | F18: 11 | G18: 0 | H18: 0 | I18: 11 | J18: 0 | K18: 0 | L18: 0 | M18: 80 | N18: 0 | O18: =SUM(C18:L18,N18) -> 112 | P18: =SUM(C18:N18) -> 192 | R18: 1500-1600 | S18: =SUM(C42:C45) -> 93 | T18: =SUM(D42:D45) -> 77 | U18: =SUM(E42:E45) -> 14 | V18: =SUM(F42:F45) -> 39 | W18: =SUM(G42:G45) -> 1 | X18: =SUM(H42:H45) -> 0 | Y18: =SUM(I42:I45) -> 31 | Z18: =SUM(J42:J45) -> 4 | ... AF18: =SUM(P42:P45) -> 579
B19: 09.15 - 09.30 | C19: 31 | D19: 7 | E19: 13 | F19: 0 | G19: 0 | H19: 3 | I19: 1 | J19: 0 | K19: 0 | L19: 0 | M19: 85 | N19: 0 | O19: =SUM(C19:L19,N19) -> 55 | P19: =SUM(C19:N19) -> 140 | R19: 1600-1700 | S19: =SUM(C46:C49) -> 109 | T19: =SUM(D46:D49) -> 129 | U19: =SUM(E46:E49) -> 17 | V19: =SUM(F46:F49) -> 49 | W19: =SUM(G46:G49) -> 2 | X19: =SUM(H46:H49) -> 0 | Y19: =SUM(I46:I49) -> 38 | Z19: =SUM(J46:J49) -> 6 | ... AF19: =SUM(P46:P49) -> 669
B20: 09.30 - 09.45 | C20: 34 | D20: 36 | E20: 7 | F20: 20 | G20: 0 | H20: 0 | I20: 13 | J20: 1 | K20: 0 | L20: 0 | M20: 116 | N20: 0 | O20: =SUM(C20:L20,N20) -> 111 | P20: =SUM(C20:N20) -> 227 | R20: 1700-1800 | S20: =SUM(C50:C53) -> 172 | T20: =SUM(D50:D53) -> 123 | U20: =SUM(E50:E53) -> 24 | V20: =SUM(F50:F53) -> 58 | W20: =SUM(G50:G53) -> 3 | X20: =SUM(H50:H53) -> 0 | Y20: =SUM(I50:I53) -> 39 | Z20: =SUM(J50:J53) -> 2 | ... AF20: =SUM(P50:P53) -> 732
B21: 09.45 - 10.00 | C21: 32 | D21: 31 | E21: 3 | F21: 9 | G21: 0 | H21: 0 | I21: 2 | J21: 1 | K21: 1 | L21: 0 | M21: 86 | N21: 0 | O21: =SUM(C21:L21,N21) -> 79 | P21: =SUM(C21:N21) -> 165 | R21: 1800-1900 | S21: =SUM(C54:C57) -> 183 | T21: =SUM(D54:D57) -> 150 | U21: =SUM(E54:E57) -> 26 | V21: =SUM(F54:F57) -> 44 | W21: =SUM(G54:G57) -> 1 | X21: =SUM(H54:H57) -> 0 | Y21: =SUM(I54:I57) -> 29 | Z21: =SUM(J54:J57) -> 3 | ... AF21: =SUM(P54:P57) -> 834
B22: 10.00 - 10.15 | C22: 38 | D22: 19 | E22: 13 | F22: 16 | G22: 0 | H22: 0 | I22: 11 | J22: 1 | K22: 4 | L22: 0 | M22: 92 | N22: 0 | O22: =SUM(C22:L22,N22) -> 102 | P22: =SUM(C22:N22) -> 194 | R22: AM Peak Hr | S22: =MAX(S10:S12) -> 249 | T22: =MAX(T10:T12) -> 219 | U22: =MAX(U10:U12) -> 48 | V22: =MAX(V10:V12) -> 64 | W22: =MAX(W10:W12) -> 2 | X22: =MAX(X10:X12) -> 3 | Y22: =MAX(Y10:Y12) -> 29 | Z22: =MAX(Z10:Z12) -> 3 | ... AF22: =MAX(AF10:AF12) -> 1064
B23: 10.15 - 10.30 | C23: 35 | D23: 33 | E23: 2 | F23: 12 | G23: 1 | H23: 0 | I23: 9 | J23: 1 | K23: 1 | L23: 0 | M23: 101 | N23: 0 | O23: =SUM(C23:L23,N23) -> 94 | P23: =SUM(C23:N23) -> 195 | R23: IP Peak Hr | S23: =MAX(S13:S18) -> 129 | T23: =MAX(T13:T18) -> 96 | U23: =MAX(U13:U18) -> 26 | V23: =MAX(V13:V18) -> 49 | W23: =MAX(W13:W18) -> 3 | X23: =MAX(X13:X18) -> 1 | Y23: =MAX(Y13:Y18) -> 37 | Z23: =MAX(Z13:Z18) -> 8 | ... AF23: =MAX(AF13:AF18) -> 695
B24: 10.30 - 10.45 | C24: 16 | D24: 21 | E24: 5 | F24: 10 | G24: 0 | H24: 0 | I24: 4 | J24: 2 | K24: 1 | L24: 0 | M24: 55 | N24: 0 | O24: =SUM(C24:L24,N24) -> 59 | P24: =SUM(C24:N24) -> 114 | R24: PM Peak Hr | S24: =MAX(S19:S21) -> 183 | T24: =MAX(T19:T21) -> 150 | U24: =MAX(U19:U21) -> 26 | V24: =MAX(V19:V21) -> 58 | W24: =MAX(W19:W21) -> 3 | X24: =MAX(X19:X21) -> 0 | Y24: =MAX(Y19:Y21) -> 39 | Z24: =MAX(Z19:Z21) -> 6 | ... AF24: =MAX(AF19:AF21) -> 834
B25: 10.45 - 11.00 | C25: 40 | D25: 23 | E25: 6 | F25: 11 | G25: 0 | H25: 0 | I25: 10 | J25: 4 | K25: 0 | L25: 0 | M25: 98 | N25: 0 | O25: =SUM(C25:L25,N25) -> 94 | P25: =SUM(C25:N25) -> 192 | R25: AM Period | S25: =SUM(S10:S12) -> 584 | T25: =SUM(T10:T12) -> 479 | U25: =SUM(U10:U12) -> 112 | V25: =SUM(V10:V12) -> 150 | W25: =SUM(W10:W12) -> 2 | X25: =SUM(X10:X12) -> 3 | Y25: =SUM(Y10:Y12) -> 73 | Z25: =SUM(Z10:Z12) -> 8 | ... AF25: =SUM(AF10:AF12) -> 2664
B26: 11.00 - 11.15 | C26: 34 | D26: 18 | E26: 9 | F26: 17 | G26: 1 | H26: 0 | I26: 15 | J26: 0 | K26: 0 | L26: 0 | M26: 103 | N26: 0 | O26: =SUM(C26:L26,N26) -> 94 | P26: =SUM(C26:N26) -> 197 | R26: IP Period | S26: =SUM(S13:S18) -> 705 | T26: =SUM(T13:T18) -> 475 | U26: =SUM(U13:U18) -> 125 | V26: =SUM(V13:V18) -> 254 | W26: =SUM(W13:W18) -> 8 | X26: =SUM(X13:X18) -> 1 | Y26: =SUM(Y13:Y18) -> 192 | Z26: =SUM(Z13:Z18) -> 34 | ... AF26: =SUM(AF13:AF18) -> 3645
B27: 11.15 - 11.30 | C27: 24 | D27: 27 | E27: 4 | F27: 10 | G27: 1 | H27: 0 | I27: 8 | J27: 3 | K27: 0 | L27: 0 | M27: 92 | N27: 0 | O27: =SUM(C27:L27,N27) -> 77 | P27: =SUM(C27:N27) -> 169 | R27: PM Period | S27: =SUM(S19:S21) -> 464 | T27: =SUM(T19:T21) -> 402 | U27: =SUM(U19:U21) -> 67 | V27: =SUM(V19:V21) -> 151 | W27: =SUM(W19:W21) -> 6 | X27: =SUM(X19:X21) -> 0 | Y27: =SUM(Y19:Y21) -> 106 | Z27: =SUM(Z19:Z21) -> 11 | ... AF27: =SUM(AF19:AF21) -> 2235
