Workbook

Sheet 25.10.19 CYANIKA-KISORO-24h
B1: Consultancy services for Preparation of Expressway Development Master Plan (EDMP) for Uganda
B2: MANUAL CLASSIFIED COUNT (MCC)
B3: ROAD NAME: | C3: KISOORO ROAD
C5: Date | D5: 25.10.19 | F5: Location | G5: ='25.10.19 KISORO-CYANIKA-24h'!G5:H5 -> #REF! | J5: Surveyor | K5: COMFORT AHEBWA
C6: Dir. From | D6: CYANIKA | F6: Dir. To | G6: KISORO | J6: Supervisor | K6: ='25.10.19 KISORO-CYANIKA-24h'!K6:L6 -> #REF!
B8: Time / Veh Type | R8: SUMMARY TRAFFIC VOLUMES
C9: 1. Car | D9: 2. Station Wagon | E9: 3. Pickups | F9: 4. Minibus, matatu | G9: 5. Medium bus | H9: 6. Large Bus | I9: 7. Light Truck | J9: 8. Medium Truck | K9: 9. Heavy truck | L9: 10. Truck Trailer | M9: 11. Motor cycles | N9: 12. Tractors | O9: Total Excl M/Cycles | P9: Total All | R9: Time | S9: 1. Car | T9: 2. Station Wagon | U9: 3. Pickups | V9: 4. Minibus, matatu | W9: 5. Medium bus | X9: 6. Large Bus | Y9: 7. Light Truck | Z9: 8. Medium Truck | AA9: 9. Heavy truck | AB9: 10. Truck Trailer | AC9: 11. Motorcycles | AD9: 12. Tractors, Graders | AE9: Total Excl M/ Cycles | AF9: Total All
B10: 07.00 - 07.15 | C10: 1 | D10: 0 | E10: 0 | F10: 0 | G10: 0 | H10: 0 | I10: 0 | J10: 0 | K10: 0 | L10: 0 | M10: 13 | N10: 0 | O10: =SUM(C10:L10,N10) -> 1 | P10: =SUM(C10:N10) -> 14 | R10: 0700-0800 | S10: =SUM(C10:C13) -> 4 | T10: =SUM(D10:D13) -> 5 | U10: =SUM(E10:E13) -> 1 | V10: =SUM(F10:F13) -> 0 | W10: =SUM(G10:G13) -> 0 | X10: =SUM(H10:H13) -> 0 | Y10: =SUM(I10:I13) -> 2 | Z10: =SUM(J10:J13) -> 0 | ... AF10: =SUM(P10:P13) -> 55
B11: 07.15 - 07.30 | C11: 2 | D11: 1 | E11: 1 | F11: 0 | G11: 0 | H11: 0 | I11: 0 | J11: 0 | K11: 0 | L11: 0 | M11: 10 | N11: 0 | O11: =SUM(C11:L11,N11) -> 4 | P11: =SUM(C11:N11) -> 14 | R11: 0800-0900 | S11: =SUM(C14:C17) -> 4 | T11: =SUM(D14:D17) -> 1 | U11: =SUM(E14:E17) -> 3 | V11: =SUM(F14:F17) -> 0 | W11: =SUM(G14:G17) -> 0 | X11: =SUM(H14:H17) -> 0 | Y11: =SUM(I14:I17) -> 0 | Z11: =SUM(J14:J17) -> 0 | ... AF11: =SUM(P14:P17) -> 58
B12: 07.30 - 07.45 | C12: 1 | D12: 3 | E12: 0 | F12: 0 | G12: 0 | H12: 0 | I12: 0 | J12: 0 | K12: 0 | L12: 0 | M12: 8 | N12: 0 | O12: =SUM(C12:L12,N12) -> 4 | P12: =SUM(C12:N12) -> 12 | R12: 0900-1000 | S12: =SUM(C18:C21) -> 10 | T12: =SUM(D18:D21) -> 5 | U12: =SUM(E18:E21) -> 2 | V12: =SUM(F18:F21) -> 0 | W12: =SUM(G18:G21) -> 0 | X12: =SUM(H18:H21) -> 0 | Y12: =SUM(I18:I21) -> 2 | Z12: =SUM(J18:J21) -> 0 | ... AF12: =SUM(P18:P21) -> 112
B13: 07.45 - 08.00 | C13: 0 | D13: 1 | E13: 0 | F13: 0 | G13: 0 | H13: 0 | I13: 2 | J13: 0 | K13: 0 | L13: 0 | M13: 12 | N13: 0 | O13: =SUM(C13:L13,N13) -> 3 | P13: =SUM(C13:N13) -> 15 | R13: 1000-1100 | S13: =SUM(C22:C25) -> 3 | T13: =SUM(D22:D25) -> 7 | U13: =SUM(E22:E25) -> 6 | V13: =SUM(F22:F25) -> 1 | W13: =SUM(G22:G25) -> 0 | X13: =SUM(H22:H25) -> 0 | Y13: =SUM(I22:I25) -> 2 | Z13: =SUM(J22:J25) -> 4 | ... AF13: =SUM(P22:P25) -> 134
B14: 08.00 - 08.15 | C14: 1 | D14: 0 | E14: 0 | F14: 0 | G14: 0 | H14: 0 | I14: 0 | J14: 0 | K14: 0 | L14: 0 | M14: 13 | N14: 0 | O14: =SUM(C14:L14,N14) -> 1 | P14: =SUM(C14:N14) -> 14 | R14: 1100-1200 | S14: =SUM(C26:C29) -> 7 | T14: =SUM(D26:D29) -> 3 | U14: =SUM(E26:E29) -> 4 | V14: =SUM(F26:F29) -> 0 | W14: =SUM(G26:G29) -> 0 | X14: =SUM(H26:H29) -> 0 | Y14: =SUM(I26:I29) -> 0 | Z14: =SUM(J26:J29) -> 1 | ... AF14: =SUM(P26:P29) -> 151
B15: 08.15 - 08.30 | C15: 0 | D15: 0 | E15: 2 | F15: 0 | G15: 0 | H15: 0 | I15: 0 | J15: 0 | K15: 0 | L15: 0 | M15: 12 | N15: 0 | O15: =SUM(C15:L15,N15) -> 2 | P15: =SUM(C15:N15) -> 14 | R15: 1200-1300 | S15: =SUM(C30:C33) -> 8 | T15: =SUM(D30:D33) -> 0 | U15: =SUM(E30:E33) -> 4 | V15: =SUM(F30:F33) -> 1 | W15: =SUM(G30:G33) -> 0 | X15: =SUM(H30:H33) -> 0 | Y15: =SUM(I30:I33) -> 1 | Z15: =SUM(J30:J33) -> 1 | ... AF15: =SUM(P30:P33) -> 155
B16: 08.30 - 08.45 | C16: 2 | D16: 1 | E16: 0 | F16: 0 | G16: 0 | H16: 0 | I16: 0 | J16: 0 | K16: 0 | L16: 0 | M16: 9 | N16: 0 | O16: =SUM(C16:L16,N16) -> 3 | P16: =SUM(C16:N16) -> 12 | R16: 1300-1400 | S16: =SUM(C34:C37) -> 5 | T16: =SUM(D34:D37) -> 7 | U16: =SUM(E34:E37) -> 4 | V16: =SUM(F34:F37) -> 1 | W16: =SUM(G34:G37) -> 0 | X16: =SUM(H34:H37) -> 0 | Y16: =SUM(I34:I37) -> 1 | Z16: =SUM(J34:J37) -> 2 | ... AF16: =SUM(P34:P37) -> 129
B17: 08.45 - 9.00 | C17: 1 | D17: 0 | E17: 1 | F17: 0 | G17: 0 | H17: 0 | I17: 0 | J17: 0 | K17: 0 | L17: 0 | M17: 16 | N17: 0 | O17: =SUM(C17:L17,N17) -> 2 | P17: =SUM(C17:N17) -> 18 | R17: 1400-1500 | S17: =SUM(C38:C41) -> 5 | T17: =SUM(D38:D41) -> 2 | U17: =SUM(E38:E41) -> 4 | V17: =SUM(F38:F41) -> 0 | W17: =SUM(G38:G41) -> 0 | X17: =SUM(H38:H41) -> 0 | Y17: =SUM(I38:I41) -> 2 | Z17: =SUM(J38:J41) -> 2 | ... AF17: =SUM(P38:P41) -> 123
B18: 09.00 - 09.15 | C18: 3 | D18: 3 | E18: 0 | F18: 0 | G18: 0 | H18: 0 | I18: 0 | J18: 0 | K18: 1 | L18: 0 | M18: 19 | N18: 0 | O18: =SUM(C18:L18,N18) -> 7 | P18: =SUM(C18:N18) -> 26 | R18: 1500-1600 | S18: =SUM(C42:C45) -> 5 | T18: =SUM(D42:D45) -> 4 | U18: =SUM(E42:E45) -> 2 | V18: =SUM(F42:F45) -> 0 | W18: =SUM(G42:G45) -> 0 | X18: =SUM(H42:H45) -> 0 | Y18: =SUM(I42:I45) -> 0 | Z18: =SUM(J42:J45) -> 4 | ... AF18: =SUM(P42:P45) -> 125
B19: 09.15 - 09.30 | C19: 1 | D19: 1 | E19: 1 | F19: 0 | G19: 0 | H19: 0 | I19: 2 | J19: 0 | K19: 0 | L19: 0 | M19: 21 | N19: 0 | O19: =SUM(C19:L19,N19) -> 5 | P19: =SUM(C19:N19) -> 26 | R19: 1600-1700 | S19: =SUM(C46:C49) -> 13 | T19: =SUM(D46:D49) -> 7 | U19: =SUM(E46:E49) -> 4 | V19: =SUM(F46:F49) -> 0 | W19: =SUM(G46:G49) -> 0 | X19: =SUM(H46:H49) -> 1 | Y19: =SUM(I46:I49) -> 1 | Z19: =SUM(J46:J49) -> 4 | ... AF19: =SUM(P46:P49) -> 154
B20: 09.30 - 09.45 | C20: 4 | D20: 0 | E20: 1 | F20: 0 | G20: 0 | H20: 0 | I20: 0 | J20: 0 | K20: 2 | L20: 0 | M20: 26 | N20: 0 | O20: =SUM(C20:L20,N20) -> 7 | P20: =SUM(C20:N20) -> 33 | R20: 1700-1800 | S20: =SUM(C50:C53) -> 8 | T20: =SUM(D50:D53) -> 6 | U20: =SUM(E50:E53) -> 5 | V20: =SUM(F50:F53) -> 1 | W20: =SUM(G50:G53) -> 0 | X20: =SUM(H50:H53) -> 0 | Y20: =SUM(I50:I53) -> 1 | Z20: =SUM(J50:J53) -> 4 | ... AF20: =SUM(P50:P53) -> 166
B21: 09.45 - 10.00 | C21: 2 | D21: 1 | E21: 0 | F21: 0 | G21: 0 | H21: 0 | I21: 0 | J21: 0 | K21: 1 | L21: 0 | M21: 23 | N21: 0 | O21: =SUM(C21:L21,N21) -> 4 | P21: =SUM(C21:N21) -> 27 | R21: 1800-1900 | S21: =SUM(C54:C57) -> 8 | T21: =SUM(D54:D57) -> 3 | U21: =SUM(E54:E57) -> 4 | V21: =SUM(F54:F57) -> 0 | W21: =SUM(G54:G57) -> 0 | X21: =SUM(H54:H57) -> 0 | Y21: =SUM(I54:I57) -> 3 | Z21: =SUM(J54:J57) -> 7 | ... AF21: =SUM(P54:P57) -> 139
B22: 10.00 - 10.15 | C22: 0 | D22: 2 | E22: 0 | F22: 0 | G22: 0 | H22: 0 | I22: 1 | J22: 1 | K22: 0 | L22: 0 | M22: 15 | N22: 0 | O22: =SUM(C22:L22,N22) -> 4 | P22: =SUM(C22:N22) -> 19 | R22: 1900-2000 | S22: =SUM(C58:C61) -> 4 | T22: =SUM(D58:D61) -> 1 | U22: =SUM(E58:E61) -> 3 | V22: =SUM(F58:F61) -> 0 | W22: =SUM(G58:G61) -> 0 | X22: =SUM(H58:H61) -> 0 | Y22: =SUM(I58:I61) -> 1 | Z22: =SUM(J58:J61) -> 6 | ... AF22: =SUM(P58:P61) -> 152
B23: 10.15 - 10.30 | C23: 1 | D23: 3 | E23: 4 | F23: 1 | G23: 0 | H23: 0 | I23: 0 | J23: 0 | K23: 0 | L23: 0 | M23: 27 | N23: 0 | O23: =SUM(C23:L23,N23) -> 9 | P23: =SUM(C23:N23) -> 36 | R23: 2000-2100 | S23: =SUM(C62:C65) -> 3 | T23: =SUM(D62:D65) -> 2 | U23: =SUM(E62:E65) -> 1 | V23: =SUM(F62:F65) -> 0 | W23: =SUM(G62:G65) -> 0 | X23: =SUM(H62:H65) -> 0 | Y23: =SUM(I62:I65) -> 0 | Z23: =SUM(J62:J65) -> 0 | ... AF23: =SUM(P62:P65) -> 66
B24: 10.30 - 10.45 | C24: 1 | D24: 0 | E24: 2 | F24: 0 | G24: 0 | H24: 0 | I24: 1 | J24: 1 | K24: 0 | L24: 0 | M24: 34 | N24: 0 | O24: =SUM(C24:L24,N24) -> 5 | P24: =SUM(C24:N24) -> 39 | R24: 2100-2200 | S24: =SUM(C66:C69) -> 4 | T24: =SUM(D66:D69) -> 1 | U24: =SUM(E66:E69) -> 1 | V24: =SUM(F66:F69) -> 1 | W24: =SUM(G66:G69) -> 0 | X24: =SUM(H66:H69) -> 0 | Y24: =SUM(I66:I69) -> 0 | Z24: =SUM(J66:J69) -> 1 | ... AF24: =SUM(P66:P69) -> 34
B25: 10.45 - 11.00 | C25: 1 | D25: 2 | E25: 0 | F25: 0 | G25: 0 | H25: 0 | I25: 0 | J25: 2 | K25: 0 | L25: 0 | M25: 35 | N25: 0 | O25: =SUM(C25:L25,N25) -> 5 | P25: =SUM(C25:N25) -> 40 | R25: 2200-2300 | S25: =SUM(C70:C73) -> 2 | T25: =SUM(D70:D73) -> 0 | U25: =SUM(E70:E73) -> 1 | V25: =SUM(F70:F73) -> 0 | W25: =SUM(G70:G73) -> 0 | X25: =SUM(H70:H73) -> 0 | Y25: =SUM(I70:I73) -> 1 | Z25: =SUM(J70:J73) -> 0 | ... AF25: =SUM(P70:P73) -> 13
B26: 11.00 - 11.15 | C26: 1 | D26: 1 | E26: 1 | F26: 0 | G26: 0 | H26: 0 | I26: 0 | J26: 1 | K26: 0 | L26: 0 | M26: 29 | N26: 0 | O26: =SUM(C26:L26,N26) -> 4 | P26: =SUM(C26:N26) -> 33 | R26: 2300-0000 | S26: =SUM(C74:C77) -> 0 | T26: =SUM(D74:D77) -> 0 | U26: =SUM(E74:E77) -> 0 | V26: =SUM(F74:F77) -> 0 | W26: =SUM(G74:G77) -> 0 | X26: =SUM(H74:H77) -> 0 | Y26: =SUM(I74:I77) -> 0 | Z26: =SUM(J74:J77) -> 1 | ... AF26: =SUM(P74:P77) -> 2
B27: 11.15 - 11.30 | C27: 2 | D27: 0 | E27: 1 | F27: 0 | G27: 0 | H27: 0 | I27: 0 | J27: 0 | K27: 0 | L27: 0 | M27: 33 | N27: 0 | O27: =SUM(C27:L27,N27) -> 3 | P27: =SUM(C27:N27) -> 36 | R27: 0000-0100 | S27: =SUM(C78:C81) -> 2 | T27: =SUM(D78:D81) -> 1 | U27: =SUM(E78:E81) -> 0 | V27: =SUM(F78:F81) -> 0 | W27: =SUM(G78:G81) -> 0 | X27: =SUM(H78:H81) -> 0 | Y27: =SUM(I78:I81) -> 0 | Z27: =SUM(J78:J81) -> 1 | ... AF27: =SUM(P78:P81) -> 4
B28: 11.30 - 11.45 | C28: 1 | D28: 1 | E28: 0 | F28: 0 | G28: 0 | H28: 0 | I28: 0 | J28: 0 | K28: 0 | L28: 0 | M28: 30 | N28: 0 | O28: =SUM(C28:L28,N28) -> 2 | P28: =SUM(C28:N28) -> 32 | R28: 0100-0200 | S28: =SUM(C82:C85) -> 0 | T28: =SUM(D82:D85) -> 0 | U28: =SUM(E82:E85) -> 1 | V28: =SUM(F82:F85) -> 1 | W28: =SUM(G82:G85) -> 0 | X28: =SUM(H82:H85) -> 0 | Y28: =SUM(I82:I85) -> 0 | Z28: =SUM(J82:J85) -> 0 | ... AF28: =SUM(P82:P85) -> 2
B29: 11.45 - 12.00 | C29: 3 | D29: 1 | E29: 2 | F29: 0 | G29: 0 | H29: 0 | I29: 0 | J29: 0 | K29: 0 | L29: 0 | M29: 44 | N29: 0 | O29: =SUM(C29:L29,N29) -> 6 | P29: =SUM(C29:N29) -> 50 | R29: 0200-0300 | S29: =SUM(C86:C89) -> 0 | T29: =SUM(D86:D89) -> 0 | U29: =SUM(E86:E89) -> 0 | V29: =SUM(F86:F89) -> 0 | W29: =SUM(G86:G89) -> 0 | X29: =SUM(H86:H89) -> 0 | Y29: =SUM(I86:I89) -> 0 | Z29: =SUM(J86:J89) -> 0 | ... AF29: =SUM(P86:P89) -> 0
B30: 12.00 - 12.15 | C30: 5 | D30: 0 | E30: 0 | F30: 1 | G30: 0 | H30: 0 | I30: 0 | J30: 1 | K30: 0 | L30: 0 | M30: 37 | N30: 0 | O30: =SUM(C30:L30,N30) -> 7 | P30: =SUM(C30:N30) -> 44 | R30: 0300-0400 | S30: =SUM(C90:C93) -> 0 | T30: =SUM(D90:D93) -> 0 | U30: =SUM(E90:E93) -> 0 | V30: =SUM(F90:F93) -> 0 | W30: =SUM(G90:G93) -> 0 | X30: =SUM(H90:H93) -> 0 | Y30: =SUM(I90:I93) -> 1 | Z30: =SUM(J90:J93) -> 0 | ... AF30: =SUM(P90:P93) -> 1
B31: 12.15 - 12.30 | C31: 0 | D31: 0 | E31: 2 | F31: 0 | G31: 0 | H31: 0 | I31: 0 | J31: 0 | K31: 0 | L31: 0 | M31: 38 | N31: 0 | O31: =SUM(C31:L31,N31) -> 2 | P31: =SUM(C31:N31) -> 40 | R31: 0400-0500 | S31: =SUM(C94:C97) -> 2 | T31: =SUM(D94:D97) -> 1 | U31: =SUM(E94:E97) -> 1 | V31: =SUM(F94:F97) -> 0 | W31: =SUM(G94:G97) -> 0 | X31: =SUM(H94:H97) -> 0 | Y31: =SUM(I94:I97) -> 0 | Z31: =SUM(J94:J97) -> 1 | ... AF31: =SUM(P94:P97) -> 8
B32: 12.30 - 12.45 | C32: 2 | D32: 0 | E32: 1 | F32: 0 | G32: 0 | H32: 0 | I32: 1 | J32: 0 | K32: 0 | L32: 0 | M32: 31 | N32: 0 | O32: =SUM(C32:L32,N32) -> 4 | P32: =SUM(C32:N32) -> 35 | R32: 0500-0600 | S32: =SUM(C98:C101) -> 1 | T32: =SUM(D98:D101) -> 5 | U32: =SUM(E98:E101) -> 0 | V32: =SUM(F98:F101) -> 0 | W32: =SUM(G98:G101) -> 0 | X32: =SUM(H98:H101) -> 0 | Y32: =SUM(I98:I101) -> 1 | Z32: =SUM(J98:J101) -> 3 | ... AF32: =SUM(P98:P101) -> 26
B33: 12.45 - 13.00 | C33: 1 | D33: 0 | E33: 1 | F33: 0 | G33: 0 | H33: 0 | I33: 0 | J33: 0 | K33: 0 | L33: 0 | M33: 34 | N33: 0 | O33: =SUM(C33:L33,N33) -> 2 | P33: =SUM(C33:N33) -> 36 | R33: 0600-0700 | S33: =SUM(C102:C105) -> 3 | T33: =SUM(D102:D105) -> 1 | U33: =SUM(E102:E105) -> 1 | V33: =SUM(F102:F105) -> 0 | W33: =SUM(G102:G105) -> 0 | X33: =SUM(H102:H105) -> 0 | Y33: =SUM(I102:I105) -> 2 | Z33: =SUM(J102:J105) -> 0 | ... AF33: =SUM(P102:P105) -> 34
B34: 13.00 - 13.15 | C34: 2 | D34: 0 | E34: 2 | F34: 0 | G34: 0 | H34: 0 | I34: 0 | J34: 0 | K34: 0 | L34: 0 | M34: 24 | N34: 0 | O34: =SUM(C34:L34,N34) -> 4 | P34: =SUM(C34:N34) -> 28 | R34: AM Peak Hr | S34: =MAX(S10:S12) -> 10 | T34: =MAX(T10:T12) -> 5 | U34: =MAX(U10:U12) -> 3 | V34: =MAX(V10:V12) -> 0 | W34: =MAX(W10:W12) -> 0 | X34: =MAX(X10:X12) -> 0 | Y34: =MAX(Y10:Y12) -> 2 | Z34: =MAX(Z10:Z12) -> 0 | ... AF34: =MAX(AF10:AF12) -> 112
B35: 13.15 - 13.30 | C35: 0 | D35: 2 | E35: 0 | F35: 1 | G35: 0 | H35: 0 | I35: 0 | J35: 0 | K35: 0 | L35: 0 | M35: 32 | N35: 0 | O35: =SUM(C35:L35,N35) -> 3 | P35: =SUM(C35:N35) -> 35 | R35: IP Peak Hr | S35: =MAX(S13:S18) -> 8 | T35: =MAX(T13:T18) -> 7 | U35: =MAX(U13:U18) -> 6 | V35: =MAX(V13:V18) -> 1 | W35: =MAX(W13:W18) -> 0 | X35: =MAX(X13:X18) -> 0 | Y35: =MAX(Y13:Y18) -> 2 | Z35: =MAX(Z13:Z18) -> 4 | ... AF35: =MAX(AF13:AF18) -> 155
B36: 13.30 - 13.45 | C36: 2 | D36: 2 | E36: 2 | F36: 0 | G36: 0 | H36: 0 | I36: 0 | J36: 0 | K36: 0 | L36: 0 | M36: 27 | N36: 0 | O36: =SUM(C36:L36,N36) -> 6 | P36: =SUM(C36:N36) -> 33 | R36: PM Peak Hr | S36: =MAX(S19:S21) -> 13 | T36: =MAX(T19:T21) -> 7 | U36: =MAX(U19:U21) -> 5 | V36: =MAX(V19:V21) -> 1 | W36: =MAX(W19:W21) -> 0 | X36: =MAX(X19:X21) -> 1 | Y36: =MAX(Y19:Y21) -> 3 | Z36: =MAX(Z19:Z21) -> 7 | ... AF36: =MAX(AF19:AF21) -> 166
B37: 13.45 - 14.00 | C37: 1 | D37: 3 | E37: 0 | F37: 0 | G37: 0 | H37: 0 | I37: 1 | J37: 2 | K37: 0 | L37: 0 | M37: 26 | N37: 0 | O37: =SUM(C37:L37,N37) -> 7 | P37: =SUM(C37:N37) -> 33 | R37: AM Period | S37: =SUM(S10:S12) -> 18 | T37: =SUM(T10:T12) -> 11 | U37: =SUM(U10:U12) -> 6 | V37: =SUM(V10:V12) -> 0 | W37: =SUM(W10:W12) -> 0 | X37: =SUM(X10:X12) -> 0 | Y37: =SUM(Y10:Y12) -> 4 | Z37: =SUM(Z10:Z12) -> 0 | ... AF37: =SUM(AF10:AF12) -> 225
B38: 14.00 - 14.15 | C38: 2 | D38: 0 | E38: 2 | F38: 0 | G38: 0 | H38: 0 | I38: 1 | J38: 1 | K38: 0 | L38: 0 | M38: 28 | N38: 0 | O38: =SUM(C38:L38,N38) -> 6 | P38: =SUM(C38:N38) -> 34 | R38: IP Period | S38: =SUM(S13:S18) -> 33 | T38: =SUM(T13:T18) -> 23 | U38: =SUM(U13:U18) -> 24 | V38: =SUM(V13:V18) -> 3 | W38: =SUM(W13:W18) -> 0 | X38: =SUM(X13:X18) -> 0 | Y38: =SUM(Y13:Y18) -> 6 | Z38: =SUM(Z13:Z18) -> 14 | ... AF38: =SUM(AF13:AF18) -> 817
B39: 14.15 - 14.30 | C39: 2 | D39: 0 | E39: 0 | F39: 0 | G39: 0 | H39: 0 | I39: 0 | J39: 0 | K39: 0 | L39: 0 | M39: 23 | N39: 0 | O39: =SUM(C39:L39,N39) -> 2 | P39: =SUM(C39:N39) -> 25 | R39: PM Period | S39: =SUM(S19:S21) -> 29 | T39: =SUM(T19:T21) -> 16 | U39: =SUM(U19:U21) -> 13 | V39: =SUM(V19:V21) -> 1 | W39: =SUM(W19:W21) -> 0 | X39: =SUM(X19:X21) -> 1 | Y39: =SUM(Y19:Y21) -> 5 | Z39: =SUM(Z19:Z21) -> 15 | ... AF39: =SUM(AF19:AF21) -> 459
B40: 14.30 - 14.45 | C40: 0 | D40: 1 | E40: 2 | F40: 0 | G40: 0 | H40: 0 | I40: 0 | J40: 0 | K40: 0 | L40: 0 | M40: 33 | N40: 0 | O40: =SUM(C40:L40,N40) -> 3 | P40: =SUM(C40:N40) -> 36 | R40: 12 Hours | S40: =SUM(S10:S21) -> 80 | T40: =SUM(T10:T21) -> 50 | U40: =SUM(U10:U21) -> 43 | V40: =SUM(V10:V21) -> 4 | W40: =SUM(W10:W21) -> 0 | X40: =SUM(X10:X21) -> 1 | Y40: =SUM(Y10:Y21) -> 15 | Z40: =SUM(Z10:Z21) -> 29 | ... AF40: =SUM(AF10:AF21) -> 1501
B41: 14.45 - 15.00 | C41: 1 | D41: 1 | E41: 0 | F41: 0 | G41: 0 | H41: 0 | I41: 1 | J41: 1 | K41: 0 | L41: 0 | M41: 24 | N41: 0 | O41: =SUM(C41:L41,N41) -> 4 | P41: =SUM(C41:N41) -> 28 | R41: 24 Hrs/ADT | S41: =SUM(S10:S33) -> 101 | T41: =SUM(T10:T33) -> 62 | U41: =SUM(U10:U33) -> 52 | V41: =SUM(V10:V33) -> 6 | W41: =SUM(W10:W33) -> 0 | X41: =SUM(X10:X33) -> 1 | Y41: =SUM(Y10:Y33) -> 21 | Z41: =SUM(Z10:Z33) -> 42 | ... AF41: =SUM(AF10:AF33) -> 1843
B42: 15.00 - 15.15 | C42: 0 | D42: 0 | E42: 1 | F42: 0 | G42: 0 | H42: 0 | I42: 0 | J42: 1 | K42: 0 | L42: 0 | M42: 37 | N42: 0 | O42: =SUM(C42:L42,N42) -> 2 | P42: =SUM(C42:N42) -> 39 | R42: NEF | S42: =S41/S40 -> 1.2625 | T42: =T41/T40 -> 1.24 | U42: =U41/U40 -> 1.2093023 | V42: =V41/V40 -> 1.5 | W42: 0 | X42: =X41/X40 -> 1 | Y42: =Y41/Y40 -> 1.4 | Z42: =Z41/Z40 -> 1.4482759 | AA42: =AA41/AA40 -> 1 | AB42: 0 | AC42: =AC41/AC40 -> 1.2188235 | AD42: 0 | AE42: =AE41/AE40 -> 1.2787611 | AF42: =AF41/AF40 -> 1.2278481
...

Sheet 25.10.19 KISORO-CYANIKA-24h
B1: Consultancy services for Preparation of Expressway Development Master Plan (EDMP) for Uganda
B2: MANUAL CLASSIFIED COUNT (MCC)
B3: ROAD NAME: | C3: KISORO ROAD
C5: Date | D5: 25.10.19 | F5: Location | G5: =#REF! -> #REF! | J5: Surveyor | K5: JOVANA BELLA
C6: Dir. From | D6: KISORO | F6: Dir. To | G6: CYANIKA | J6: Supervisor | K6: =#REF! -> #REF!
B8: Time / Veh Type | R8: SUMMARY TRAFFIC VOLUMES
C9: 1. Car | D9: 2. Station Wagon | E9: 3. Pickups | F9: 4. Minibus, matatu | G9: 5. Medium bus | H9: 6. Large Bus | I9: 7. Light Truck | J9: 8. Medium Truck | K9: 9. Heavy truck | L9: 10. Truck Trailer | M9: 11. Motor cycles | N9: 12. Tractors | O9: Total Excl M/Cycles | P9: Total All | R9: Time | S9: 1. Car | T9: 2. Station Wagon | U9: 3. Pickups | V9: 4. Minibus, matatu | W9: 5. Medium bus | X9: 6. Large Bus | Y9: 7. Light Truck | Z9: 8. Medium Truck | AA9: 9. Heavy truck | AB9: 10. Truck Trailer | AC9: 11. Motorcycles | AD9: 12. Tractors, Graders | AE9: Total Excl M/ Cycles | AF9: Total All
B10: 07.00 - 07.15 | C10: 2 | D10: 0 | E10: 1 | F10: 0 | G10: 0 | H10: 0 | I10: 0 | J10: 0 | K10: 0 | L10: 0 | M10: 15 | N10: 0 | O10: =SUM(C10:L10,N10) -> 3 | P10: =SUM(C10:N10) -> 18 | R10: 0700-0800 | S10: =SUM(C10:C13) -> 4 | T10: =SUM(D10:D13) -> 2 | U10: =SUM(E10:E13) -> 1 | V10: =SUM(F10:F13) -> 0 | W10: =SUM(G10:G13) -> 0 | X10: =SUM(H10:H13) -> 0 | Y10: =SUM(I10:I13) -> 0 | Z10: =SUM(J10:J13) -> 0 | ... AF10: =SUM(P10:P13) -> 63
B11: 07.15 - 07.30 | C11: 1 | D11: 1 | E11: 0 | F11: 0 | G11: 0 | H11: 0 | I11: 0 | J11: 0 | K11: 0 | L11: 0 | M11: 14 | N11: 0 | O11: =SUM(C11:L11,N11) -> 2 | P11: =SUM(C11:N11) -> 16 | R11: 0800-0900 | S11: =SUM(C14:C17) -> 0 | T11: =SUM(D14:D17) -> 2 | U11: =SUM(E14:E17) -> 2 | V11: =SUM(F14:F17) -> 0 | W11: =SUM(G14:G17) -> 0 | X11: =SUM(H14:H17) -> 0 | Y11: =SUM(I14:I17) -> 0 | Z11: =SUM(J14:J17) -> 1 | ... AF11: =SUM(P14:P17) -> 89
B12: 07.30 - 07.45 | C12: 0 | D12: 0 | E12: 0 | F12: 0 | G12: 0 | H12: 0 | I12: 0 | J12: 0 | K12: 0 | L12: 0 | M12: 11 | N12: 0 | O12: =SUM(C12:L12,N12) -> 0 | P12: =SUM(C12:N12) -> 11 | R12: 0900-1000 | S12: =SUM(C18:C21) -> 1 | T12: =SUM(D18:D21) -> 2 | U12: =SUM(E18:E21) -> 2 | V12: =SUM(F18:F21) -> 1 | W12: =SUM(G18:G21) -> 0 | X12: =SUM(H18:H21) -> 0 | Y12: =SUM(I18:I21) -> 1 | Z12: =SUM(J18:J21) -> 4 | ... AF12: =SUM(P18:P21) -> 133
B13: 07.45 - 08.00 | C13: 1 | D13: 1 | E13: 0 | F13: 0 | G13: 0 | H13: 0 | I13: 0 | J13: 0 | K13: 0 | L13: 0 | M13: 16 | N13: 0 | O13: =SUM(C13:L13,N13) -> 2 | P13: =SUM(C13:N13) -> 18 | R13: 1000-1100 | S13: =SUM(C22:C25) -> 9 | T13: =SUM(D22:D25) -> 2 | U13: =SUM(E22:E25) -> 4 | V13: =SUM(F22:F25) -> 0 | W13: =SUM(G22:G25) -> 0 | X13: =SUM(H22:H25) -> 0 | Y13: =SUM(I22:I25) -> 3 | Z13: =SUM(J22:J25) -> 3 | ... AF13: =SUM(P22:P25) -> 139
B14: 08.00 - 08.15 | C14: 0 | D14: 1 | E14: 2 | F14: 0 | G14: 0 | H14: 0 | I14: 0 | J14: 0 | K14: 0 | L14: 0 | M14: 18 | N14: 0 | O14: =SUM(C14:L14,N14) -> 3 | P14: =SUM(C14:N14) -> 21 | R14: 1100-1200 | S14: =SUM(C26:C29) -> 15 | T14: =SUM(D26:D29) -> 3 | U14: =SUM(E26:E29) -> 2 | V14: =SUM(F26:F29) -> 0 | W14: =SUM(G26:G29) -> 0 | X14: =SUM(H26:H29) -> 0 | Y14: =SUM(I26:I29) -> 1 | Z14: =SUM(J26:J29) -> 1 | ... AF14: =SUM(P26:P29) -> 179
B15: 08.15 - 08.30 | C15: 0 | D15: 0 | E15: 0 | F15: 0 | G15: 0 | H15: 0 | I15: 0 | J15: 1 | K15: 0 | L15: 0 | M15: 20 | N15: 0 | O15: =SUM(C15:L15,N15) -> 1 | P15: =SUM(C15:N15) -> 21 | R15: 1200-1300 | S15: =SUM(C30:C33) -> 9 | T15: =SUM(D30:D33) -> 3 | U15: =SUM(E30:E33) -> 8 | V15: =SUM(F30:F33) -> 0 | W15: =SUM(G30:G33) -> 0 | X15: =SUM(H30:H33) -> 0 | Y15: =SUM(I30:I33) -> 4 | Z15: =SUM(J30:J33) -> 1 | ... AF15: =SUM(P30:P33) -> 178
B16: 08.30 - 08.45 | C16: 0 | D16: 1 | E16: 0 | F16: 0 | G16: 0 | H16: 0 | I16: 0 | J16: 0 | K16: 0 | L16: 0 | M16: 21 | N16: 0 | O16: =SUM(C16:L16,N16) -> 1 | P16: =SUM(C16:N16) -> 22 | R16: 1300-1400 | S16: =SUM(C34:C37) -> 12 | T16: =SUM(D34:D37) -> 6 | U16: =SUM(E34:E37) -> 2 | V16: =SUM(F34:F37) -> 0 | W16: =SUM(G34:G37) -> 0 | X16: =SUM(H34:H37) -> 0 | Y16: =SUM(I34:I37) -> 3 | Z16: =SUM(J34:J37) -> 0 | ... AF16: =SUM(P34:P37) -> 150
B17: 08.45 - 9.00 | C17: 0 | D17: 0 | E17: 0 | F17: 0 | G17: 0 | H17: 0 | I17: 0 | J17: 0 | K17: 0 | L17: 0 | M17: 25 | N17: 0 | O17: =SUM(C17:L17,N17) -> 0 | P17: =SUM(C17:N17) -> 25 | R17: 1400-1500 | S17: =SUM(C38:C41) -> 6 | T17: =SUM(D38:D41) -> 2 | U17: =SUM(E38:E41) -> 3 | V17: =SUM(F38:F41) -> 0 | W17: =SUM(G38:G41) -> 0 | X17: =SUM(H38:H41) -> 1 | Y17: =SUM(I38:I41) -> 1 | Z17: =SUM(J38:J41) -> 0 | ... AF17: =SUM(P38:P41) -> 140
B18: 09.00 - 09.15 | C18: 1 | D18: 0 | E18: 1 | F18: 0 | G18: 0 | H18: 0 | I18: 0 | J18: 1 | K18: 0 | L18: 0 | M18: 29 | N18: 0 | O18: =SUM(C18:L18,N18) -> 3 | P18: =SUM(C18:N18) -> 32 | R18: 1500-1600 | S18: =SUM(C42:C45) -> 22 | T18: =SUM(D42:D45) -> 4 | U18: =SUM(E42:E45) -> 6 | V18: =SUM(F42:F45) -> 0 | W18: =SUM(G42:G45) -> 0 | X18: =SUM(H42:H45) -> 0 | Y18: =SUM(I42:I45) -> 1 | Z18: =SUM(J42:J45) -> 1 | ... AF18: =SUM(P42:P45) -> 178
B19: 09.15 - 09.30 | C19: 0 | D19: 1 | E19: 1 | F19: 1 | G19: 0 | H19: 0 | I19: 1 | J19: 0 | K19: 0 | L19: 0 | M19: 25 | N19: 0 | O19: =SUM(C19:L19,N19) -> 4 | P19: =SUM(C19:N19) -> 29 | R19: 1600-1700 | S19: =SUM(C46:C49) -> 17 | T19: =SUM(D46:D49) -> 6 | U19: =SUM(E46:E49) -> 4 | V19: =SUM(F46:F49) -> 0 | W19: =SUM(G46:G49) -> 0 | X19: =SUM(H46:H49) -> 0 | Y19: =SUM(I46:I49) -> 3 | Z19: =SUM(J46:J49) -> 1 | ... AF19: =SUM(P46:P49) -> 190
B20: 09.30 - 09.45 | C20: 0 | D20: 1 | E20: 0 | F20: 0 | G20: 0 | H20: 0 | I20: 0 | J20: 2 | K20: 0 | L20: 0 | M20: 30 | N20: 0 | O20: =SUM(C20:L20,N20) -> 3 | P20: =SUM(C20:N20) -> 33 | R20: 1700-1800 | S20: =SUM(C50:C53) -> 8 | T20: =SUM(D50:D53) -> 7 | U20: =SUM(E50:E53) -> 4 | V20: =SUM(F50:F53) -> 1 | W20: =SUM(G50:G53) -> 0 | X20: =SUM(H50:H53) -> 0 | Y20: =SUM(I50:I53) -> 1 | Z20: =SUM(J50:J53) -> 1 | ... AF20: =SUM(P50:P53) -> 206
B21: 09.45 - 10.00 | C21: 0 | D21: 0 | E21: 0 | F21: 0 | G21: 0 | H21: 0 | I21: 0 | J21: 1 | K21: 0 | L21: 0 | M21: 38 | N21: 0 | O21: =SUM(C21:L21,N21) -> 1 | P21: =SUM(C21:N21) -> 39 | R21: 1800-1900 | S21: =SUM(C54:C57) -> 8 | T21: =SUM(D54:D57) -> 8 | U21: =SUM(E54:E57) -> 7 | V21: =SUM(F54:F57) -> 0 | W21: =SUM(G54:G57) -> 0 | X21: =SUM(H54:H57) -> 0 | Y21: =SUM(I54:I57) -> 1 | Z21: =SUM(J54:J57) -> 2 | ... AF21: =SUM(P54:P57) -> 195
B22: 10.00 - 10.15 | C22: 0 | D22: 0 | E22: 3 | F22: 0 | G22: 0 | H22: 0 | I22: 1 | J22: 0 | K22: 0 | L22: 0 | M22: 29 | N22: 0 | O22: =SUM(C22:L22,N22) -> 4 | P22: =SUM(C22:N22) -> 33 | R22: 1900-2000 | S22: =SUM(C58:C61) -> 16 | T22: =SUM(D58:D61) -> 3 | U22: =SUM(E58:E61) -> 5 | V22: =SUM(F58:F61) -> 1 | W22: =SUM(G58:G61) -> 0 | X22: =SUM(H58:H61) -> 0 | Y22: =SUM(I58:I61) -> 4 | Z22: =SUM(J58:J61) -> 2 | ... AF22: =SUM(P58:P61) -> 243
B23: 10.15 - 10.30 | C23: 3 | D23: 0 | E23: 0 | F23: 0 | G23: 0 | H23: 0 | I23: 0 | J23: 1 | K23: 0 | L23: 0 | M23: 37 | N23: 0 | O23: =SUM(C23:L23,N23) -> 4 | P23: =SUM(C23:N23) -> 41 | R23: 2000-2100 | S23: =SUM(C62:C65) -> 13 | T23: =SUM(D62:D65) -> 1 | U23: =SUM(E62:E65) -> 3 | V23: =SUM(F62:F65) -> 1 | W23: =SUM(G62:G65) -> 0 | X23: =SUM(H62:H65) -> 0 | Y23: =SUM(I62:I65) -> 0 | Z23: =SUM(J62:J65) -> 0 | ... AF23: =SUM(P62:P65) -> 116
B24: 10.30 - 10.45 | C24: 3 | D24: 1 | E24: 1 | F24: 0 | G24: 0 | H24: 0 | I24: 1 | J24: 0 | K24: 0 | L24: 0 | M24: 31 | N24: 0 | O24: =SUM(C24:L24,N24) -> 6 | P24: =SUM(C24:N24) -> 37 | R24: 2100-2200 | S24: =SUM(C66:C69) -> 20 | T24: =SUM(D66:D69) -> 6 | U24: =SUM(E66:E69) -> 1 | V24: =SUM(F66:F69) -> 1 | W24: =SUM(G66:G69) -> 0 | X24: =SUM(H66:H69) -> 0 | Y24: =SUM(I66:I69) -> 0 | Z24: =SUM(J66:J69) -> 0 | ... AF24: =SUM(P66:P69) -> 79
B25: 10.45 - 11.00 | C25: 3 | D25: 1 | E25: 0 | F25: 0 | G25: 0 | H25: 0 | I25: 1 | J25: 2 | K25: 0 | L25: 0 | M25: 21 | N25: 0 | O25: =SUM(C25:L25,N25) -> 7 | P25: =SUM(C25:N25) -> 28 | R25: 2200-2300 | S25: =SUM(C70:C73) -> 18 | T25: =SUM(D70:D73) -> 2 | U25: =SUM(E70:E73) -> 2 | V25: =SUM(F70:F73) -> 0 | W25: =SUM(G70:G73) -> 0 | X25: =SUM(H70:H73) -> 0 | Y25: =SUM(I70:I73) -> 0 | Z25: =SUM(J70:J73) -> 0 | ... AF25: =SUM(P70:P73) -> 50
B26: 11.00 - 11.15 | C26: 3 | D26: 1 | E26: 1 | F26: 0 | G26: 0 | H26: 0 | I26: 0 | J26: 0 | K26: 0 | L26: 0 | M26: 44 | N26: 0 | O26: =SUM(C26:L26,N26) -> 5 | P26: =SUM(C26:N26) -> 49 | R26: 2300-0000 | S26: =SUM(C74:C77) -> 3 | T26: =SUM(D74:D77) -> 1 | U26: =SUM(E74:E77) -> 0 | V26: =SUM(F74:F77) -> 0 | W26: =SUM(G74:G77) -> 0 | X26: =SUM(H74:H77) -> 0 | Y26: =SUM(I74:I77) -> 0 | Z26: =SUM(J74:J77) -> 0 | ... AF26: =SUM(P74:P77) -> 15
B27: 11.15 - 11.30 | C27: 1 | D27: 1 | E27: 0 | F27: 0 | G27: 0 | H27: 0 | I27: 1 | J27: 1 | K27: 0 | L27: 0 | M27: 44 | N27: 0 | O27: =SUM(C27:L27,N27) -> 4 | P27: =SUM(C27:N27) -> 48 | R27: 0000-0100 | S27: =SUM(C78:C81) -> 2 | T27: =SUM(D78:D81) -> 0 | U27: =SUM(E78:E81) -> 0 | V27: =SUM(F78:F81) -> 0 | W27: =SUM(G78:G81) -> 0 | X27: =SUM(H78:H81) -> 0 | Y27: =SUM(I78:I81) -> 0 | Z27: =SUM(J78:J81) -> 0 | ... AF27: =SUM(P78:P81) -> 4
B28: 11.30 - 11.45 | C28: 3 | D28: 1 | E28: 1 | F28: 0 | G28: 0 | H28: 0 | I28: 0 | J28: 0 | K28: 0 | L28: 0 | M28: 28 | N28: 0 | O28: =SUM(C28:L28,N28) -> 5 | P28: =SUM(C28:N28) -> 33 | R28: 0100-0200 | S28: =SUM(C82:C85) -> 0 | T28: =SUM(D82:D85) -> 1 | U28: =SUM(E82:E85) -> 0 | V28: =SUM(F82:F85) -> 0 | W28: =SUM(G82:G85) -> 0 | X28: =SUM(H82:H85) -> 0 | Y28: =SUM(I82:I85) -> 0 | Z28: =SUM(J82:J85) -> 0 | ... AF28: =SUM(P82:P85) -> 2
B29: 11.45 - 12.00 | C29: 8 | D29: 0 | E29: 0 | F29: 0 | G29: 0 | H29: 0 | I29: 0 | J29: 0 | K29: 0 | L29: 0 | M29: 41 | N29: 0 | O29: =SUM(C29:L29,N29) -> 8 | P29: =SUM(C29:N29) -> 49 | R29: 0200-0300 | S29: =SUM(C86:C89) -> 0 | T29: =SUM(D86:D89) -> 0 | U29: =SUM(E86:E89) -> 0 | V29: =SUM(F86:F89) -> 0 | W29: =SUM(G86:G89) -> 0 | X29: =SUM(H86:H89) -> 0 | Y29: =SUM(I86:I89) -> 0 | Z29: =SUM(J86:J89) -> 1 | ... AF29: =SUM(P86:P89) -> 1
B30: 12.00 - 12.15 | C30: 0 | D30: 1 | E30: 3 | F30: 0 | G30: 0 | H30: 0 | I30: 1 | J30: 0 | K30: 0 | L30: 0 | M30: 41 | N30: 0 | O30: =SUM(C30:L30,N30) -> 5 | P30: =SUM(C30:N30) -> 46 | R30: 0300-0400 | S30: =SUM(C90:C93) -> 0 | T30: =SUM(D90:D93) -> 0 | U30: =SUM(E90:E93) -> 0 | V30: =SUM(F90:F93) -> 0 | W30: =SUM(G90:G93) -> 0 | X30: =SUM(H90:H93) -> 0 | Y30: =SUM(I90:I93) -> 0 | Z30: =SUM(J90:J93) -> 0 | ... AF30: =SUM(P90:P93) -> 0
B31: 12.15 - 12.30 | C31: 5 | D31: 0 | E31: 2 | F31: 0 | G31: 0 | H31: 0 | I31: 2 | J31: 0 | K31: 0 | L31: 0 | M31: 39 | N31: 0 | O31: =SUM(C31:L31,N31) -> 9 | P31: =SUM(C31:N31) -> 48 | R31: 0400-0500 | S31: =SUM(C94:C97) -> 2 | T31: =SUM(D94:D97) -> 0 | U31: =SUM(E94:E97) -> 0 | V31: =SUM(F94:F97) -> 0 | W31: =SUM(G94:G97) -> 0 | X31: =SUM(H94:H97) -> 0 | Y31: =SUM(I94:I97) -> 0 | Z31: =SUM(J94:J97) -> 0 | ... AF31: =SUM(P94:P97) -> 2
B32: 12.30 - 12.45 | C32: 1 | D32: 0 | E32: 1 | F32: 0 | G32: 0 | H32: 0 | I32: 0 | J32: 0 | K32: 0 | L32: 0 | M32: 33 | N32: 0 | O32: =SUM(C32:L32,N32) -> 2 | P32: =SUM(C32:N32) -> 35 | R32: 0500-0600 | S32: =SUM(C98:C101) -> 3 | T32: =SUM(D98:D101) -> 0 | U32: =SUM(E98:E101) -> 1 | V32: =SUM(F98:F101) -> 0 | W32: =SUM(G98:G101) -> 0 | X32: =SUM(H98:H101) -> 0 | Y32: =SUM(I98:I101) -> 0 | Z32: =SUM(J98:J101) -> 0 | ... AF32: =SUM(P98:P101) -> 8
B33: 12.45 - 13.00 | C33: 3 | D33: 2 | E33: 2 | F33: 0 | G33: 0 | H33: 0 | I33: 1 | J33: 1 | K33: 0 | L33: 0 | M33: 40 | N33: 0 | O33: =SUM(C33:L33,N33) -> 9 | P33: =SUM(C33:N33) -> 49 | R33: 0600-0700 | S33: =SUM(C102:C105) -> 1 | T33: =SUM(D102:D105) -> 1 | U33: =SUM(E102:E105) -> 0 | V33: =SUM(F102:F105) -> 1 | W33: =SUM(G102:G105) -> 0 | X33: =SUM(H102:H105) -> 0 | Y33: =SUM(I102:I105) -> 1 | Z33: =SUM(J102:J105) -> 0 | ... AF33: =SUM(P102:P105) -> 18
B34: 13.00 - 13.15 | C34: 2 | D34: 0 | E34: 0 | F34: 0 | G34: 0 | H34: 0 | I34: 1 | J34: 0 | K34: 0 | L34: 0 | M34: 29 | N34: 0 | O34: =SUM(C34:L34,N34) -> 3 | P34: =SUM(C34:N34) -> 32 | R34: AM Peak Hr | S34: =MAX(S10:S12) -> 4 | T34: =MAX(T10:T12) -> 2 | U34: =MAX(U10:U12) -> 2 | V34: =MAX(V10:V12) -> 1 | W34: =MAX(W10:W12) -> 0 | X34: =MAX(X10:X12) -> 0 | Y34: =MAX(Y10:Y12) -> 1 | Z34: =MAX(Z10:Z12) -> 4 | ... AF34: =MAX(AF10:AF12) -> 133
B35: 13.15 - 13.30 | C35: 4 | D35: 2 | E35: 1 | F35: 0 | G35: 0 | H35: 0 | I35: 0 | J35: 0 | K35: 0 | L35: 0 | M35: 30 | N35: 0 | O35: =SUM(C35:L35,N35) -> 7 | P35: =SUM(C35:N35) -> 37 | R35: IP Peak Hr | S35: =MAX(S13:S18) -> 22 | T35: =MAX(T13:T18) -> 6 | U35: =MAX(U13:U18) -> 8 | V35: =MAX(V13:V18) -> 0 | W35: =MAX(W13:W18) -> 0 | X35: =MAX(X13:X18) -> 1 | Y35: =MAX(Y13:Y18) -> 4 | Z35: =MAX(Z13:Z18) -> 3 | ... AF35: =MAX(AF13:AF18) -> 179
B36: 13.30 - 13.45 | C36: 4 | D36: 3 | E36: 1 | F36: 0 | G36: 0 | H36: 0 | I36: 1 | J36: 0 | K36: 0 | L36: 0 | M36: 35 | N36: 0 | O36: =SUM(C36:L36,N36) -> 9 | P36: =SUM(C36:N36) -> 44 | R36: PM Peak Hr | S36: =MAX(S19:S21) -> 17 | T36: =MAX(T19:T21) -> 8 | U36: =MAX(U19:U21) -> 7 | V36: =MAX(V19:V21) -> 1 | W36: =MAX(W19:W21) -> 0 | X36: =MAX(X19:X21) -> 0 | Y36: =MAX(Y19:Y21) -> 3 | Z36: =MAX(Z19:Z21) -> 2 | ... AF36: =MAX(AF19:AF21) -> 206
B37: 13.45 - 14.00 | C37: 2 | D37: 1 | E37: 0 | F37: 0 | G37: 0 | H37: 0 | I37: 1 | J37: 0 | K37: 0 | L37: 0 | M37: 33 | N37: 0 | O37: =SUM(C37:L37,N37) -> 4 | P37: =SUM(C37:N37) -> 37 | R37: AM Period | S37: =SUM(S10:S12) -> 5 | T37: =SUM(T10:T12) -> 6 | U37: =SUM(U10:U12) -> 5 | V37: =SUM(V10:V12) -> 1 | W37: =SUM(W10:W12) -> 0 | X37: =SUM(X10:X12) -> 0 | Y37: =SUM(Y10:Y12) -> 1 | Z37: =SUM(Z10:Z12) -> 5 | ... AF37: =SUM(AF10:AF12) -> 285
B38: 14.00 - 14.15 | C38: 3 | D38: 0 | E38: 1 | F38: 0 | G38: 0 | H38: 0 | I38: 0 | J38: 0 | K38: 0 | L38: 0 | M38: 31 | N38: 0 | O38: =SUM(C38:L38,N38) -> 4 | P38: =SUM(C38:N38) -> 35 | R38: IP Period | S38: =SUM(S13:S18) -> 73 | T38: =SUM(T13:T18) -> 20 | U38: =SUM(U13:U18) -> 25 | V38: =SUM(V13:V18) -> 0 | W38: =SUM(W13:W18) -> 0 | X38: =SUM(X13:X18) -> 1 | Y38: =SUM(Y13:Y18) -> 13 | Z38: =SUM(Z13:Z18) -> 6 | ... AF38: =SUM(AF13:AF18) -> 964
B39: 14.15 - 14.30 | C39: 2 | D39: 1 | E39: 0 | F39: 0 | G39: 0 | H39: 0 | I39: 0 | J39: 0 | K39: 0 | L39: 0 | M39: 24 | N39: 0 | O39: =SUM(C39:L39,N39) -> 3 | P39: =SUM(C39:N39) -> 27 | R39: PM Period | S39: =SUM(S19:S21) -> 33 | T39: =SUM(T19:T21) -> 21 | U39: =SUM(U19:U21) -> 15 | V39: =SUM(V19:V21) -> 1 | W39: =SUM(W19:W21) -> 0 | X39: =SUM(X19:X21) -> 0 | Y39: =SUM(Y19:Y21) -> 5 | Z39: =SUM(Z19:Z21) -> 4 | ... AF39: =SUM(AF19:AF21) -> 591
B40: 14.30 - 14.45 | C40: 0 | D40: 1 | E40: 2 | F40: 0 | G40: 0 | H40: 1 | I40: 0 | J40: 0 | K40: 0 | L40: 0 | M40: 43 | N40: 0 | O40: =SUM(C40:L40,N40) -> 4 | P40: =SUM(C40:N40) -> 47 | R40: 12 Hours | S40: =SUM(S10:S21) -> 111 | T40: =SUM(T10:T21) -> 47 | U40: =SUM(U10:U21) -> 45 | V40: =SUM(V10:V21) -> 2 | W40: =SUM(W10:W21) -> 0 | X40: =SUM(X10:X21) -> 1 | Y40: =SUM(Y10:Y21) -> 19 | Z40: =SUM(Z10:Z21) -> 15 | ... AF40: =SUM(AF10:AF21) -> 1840
B41: 14.45 - 15.00 | C41: 1 | D41: 0 | E41: 0 | F41: 0 | G41: 0 | H41: 0 | I41: 1 | J41: 0 | K41: 0 | L41: 0 | M41: 29 | N41: 0 | O41: =SUM(C41:L41,N41) -> 2 | P41: =SUM(C41:N41) -> 31 | R41: 24 Hrs/ADT | S41: =SUM(S10:S33) -> 189 | T41: =SUM(T10:T33) -> 62 | U41: =SUM(U10:U33) -> 57 | V41: =SUM(V10:V33) -> 6 | W41: =SUM(W10:W33) -> 0 | X41: =SUM(X10:X33) -> 1 | Y41: =SUM(Y10:Y33) -> 24 | Z41: =SUM(Z10:Z33) -> 18 | ... AF41: =SUM(AF10:AF33) -> 2378
B42: 15.00 - 15.15 | C42: 10 | D42: 3 | E42: 0 | F42: 0 | G42: 0 | H42: 0 | I42: 1 | J42: 0 | K42: 0 | L42: 0 | M42: 44 | N42: 0 | O42: =SUM(C42:L42,N42) -> 14 | P42: =SUM(C42:N42) -> 58 | R42: NEF | S42: =S41/S40 -> 1.7027027 | T42: =T41/T40 -> 1.3191489 | U42: =U41/U40 -> 1.2666667 | V42: =V41/V40 -> 3 | W42: =W41/W40 -> #DIV/0! | X42: =X41/X40 -> 1 | Y42: =Y41/Y40 -> 1.2631579 | Z42: =Z41/Z40 -> 1.2 | ... AF42: =AF41/AF40 -> 1.2923913
...

Sheet 26.10 CYANIKA-KISORO
B1: Consultancy services for Preparation of Expressway Development Master Plan (EDMP) for Uganda
B2: MANUAL CLASSIFIED COUNT (MCC)
B3: ROAD NAME: | C3: ='27.10 KISORO-CYANIKA'!C3:G3 -> MCC - C4 - STN135 - KISORO ROAD
C5: Date | D5: 26.10.19 | F5: Location | G5: ='27.10 CYANIKA-KISORO'!G5:H5 -> STATION 135 | J5: Surveyor | K5: ='27.10 CYANIKA-KISORO'!K5:L5 -> COMFORT AHEBWA
C6: Dir. From | D6: ='27.10 CYANIKA-KISORO'!D6:E6 -> CYANIKA | F6: Dir. To | G6: ='27.10 CYANIKA-KISORO'!G6:H6 -> KISORO | J6: Supervisor | K6: ='27.10 CYANIKA-KISORO'!K6:L6 -> BELLA
B8: Time / Veh Type | R8: SUMMARY TRAFFIC VOLUMES
C9: 1. Car | D9: 2. Station Wagon | E9: 3. Pickups | F9: 4. Minibus, matatu | G9: 5. Medium bus | H9: 6. Large Bus | I9: 7. Light Truck | J9: 8. Medium Truck | K9: 9. Heavy truck | L9: 10. Truck Trailer | M9: 11. Motor cycles | N9: 12. Tractors | O9: Total Excl M/Cycles | P9: Total All | R9: Time | S9: 1. Car | T9: 2. Station Wagon | U9: 3. Pickups | V9: 4. Minibus, matatu | W9: 5. Medium bus | X9: 6. Large Bus | Y9: 7. Light Truck | Z9: 8. Medium Truck | AA9: 9. Heavy truck | AB9: 10. Truck Trailer | AC9: 11. Motorcycles | AD9: 12. Tractors, Graders | AE9: Total Excl M/ Cycles | AF9: Total All
B10: 07.00 - 07.15 | C10: 0 | D10: 1 | E10: 0 | F10: 0 | G10: 0 | H10: 0 | I10: 0 | J10: 0 | K10: 0 | L10: 0 | M10: 12 | N10: 0 | O10: =SUM(C10:L10,N10) -> 1 | P10: =SUM(C10:N10) -> 13 | R10: 0700-0800 | S10: =SUM(C10:C13) -> 8 | T10: =SUM(D10:D13) -> 3 | U10: =SUM(E10:E13) -> 0 | V10: =SUM(F10:F13) -> 0 | W10: =SUM(G10:G13) -> 0 | X10: =SUM(H10:H13) -> 0 | Y10: =SUM(I10:I13) -> 0 | Z10: =SUM(J10:J13) -> 1 | ... AF10: =SUM(P10:P13) -> 53
B11: 07.15 - 07.30 | C11: 3 | D11: 0 | E11: 0 | F11: 0 | G11: 0 | H11: 0 | I11: 0 | J11: 0 | K11: 0 | L11: 0 | M11: 12 | N11: 0 | O11: =SUM(C11:L11,N11) -> 3 | P11: =SUM(C11:N11) -> 15 | R11: 0800-0900 | S11: =SUM(C14:C17) -> 4 | T11: =SUM(D14:D17) -> 1 | U11: =SUM(E14:E17) -> 4 | V11: =SUM(F14:F17) -> 0 | W11: =SUM(G14:G17) -> 0 | X11: =SUM(H14:H17) -> 0 | Y11: =SUM(I14:I17) -> 2 | Z11: =SUM(J14:J17) -> 0 | ... AF11: =SUM(P14:P17) -> 51
B12: 07.30 - 07.45 | C12: 1 | D12: 1 | E12: 0 | F12: 0 | G12: 0 | H12: 0 | I12: 0 | J12: 0 | K12: 0 | L12: 0 | M12: 6 | N12: 0 | O12: =SUM(C12:L12,N12) -> 2 | P12: =SUM(C12:N12) -> 8 | R12: 0900-1000 | S12: =SUM(C18:C21) -> 10 | T12: =SUM(D18:D21) -> 4 | U12: =SUM(E18:E21) -> 0 | V12: =SUM(F18:F21) -> 1 | W12: =SUM(G18:G21) -> 0 | X12: =SUM(H18:H21) -> 0 | Y12: =SUM(I18:I21) -> 0 | Z12: =SUM(J18:J21) -> 4 | ... AF12: =SUM(P18:P21) -> 92
B13: 07.45 - 08.00 | C13: 4 | D13: 1 | E13: 0 | F13: 0 | G13: 0 | H13: 0 | I13: 0 | J13: 1 | K13: 0 | L13: 0 | M13: 11 | N13: 0 | O13: =SUM(C13:L13,N13) -> 6 | P13: =SUM(C13:N13) -> 17 | R13: 1000-1100 | S13: =SUM(C22:C25) -> 8 | T13: =SUM(D22:D25) -> 3 | U13: =SUM(E22:E25) -> 4 | V13: =SUM(F22:F25) -> 1 | W13: =SUM(G22:G25) -> 0 | X13: =SUM(H22:H25) -> 0 | Y13: =SUM(I22:I25) -> 1 | Z13: =SUM(J22:J25) -> 1 | ... AF13: =SUM(P22:P25) -> 134
B14: 08.00 - 08.15 | C14: 2 | D14: 0 | E14: 2 | F14: 0 | G14: 0 | H14: 0 | I14: 0 | J14: 0 | K14: 0 | L14: 0 | M14: 9 | N14: 0 | O14: =SUM(C14:L14,N14) -> 4 | P14: =SUM(C14:N14) -> 13 | R14: 1100-1200 | S14: =SUM(C26:C29) -> 14 | T14: =SUM(D26:D29) -> 5 | U14: =SUM(E26:E29) -> 1 | V14: =SUM(F26:F29) -> 1 | W14: =SUM(G26:G29) -> 0 | X14: =SUM(H26:H29) -> 0 | Y14: =SUM(I26:I29) -> 1 | Z14: =SUM(J26:J29) -> 2 | ... AF14: =SUM(P26:P29) -> 152
B15: 08.15 - 08.30 | C15: 0 | D15: 0 | E15: 0 | F15: 0 | G15: 0 | H15: 0 | I15: 1 | J15: 0 | K15: 0 | L15: 0 | M15: 4 | N15: 0 | O15: =SUM(C15:L15,N15) -> 1 | P15: =SUM(C15:N15) -> 5 | R15: 1200-1300 | S15: =SUM(C30:C33) -> 6 | T15: =SUM(D30:D33) -> 3 | U15: =SUM(E30:E33) -> 5 | V15: =SUM(F30:F33) -> 0 | W15: =SUM(G30:G33) -> 0 | X15: =SUM(H30:H33) -> 0 | Y15: =SUM(I30:I33) -> 0 | Z15: =SUM(J30:J33) -> 3 | ... AF15: =SUM(P30:P33) -> 128
B16: 08.30 - 08.45 | C16: 0 | D16: 0 | E16: 1 | F16: 0 | G16: 0 | H16: 0 | I16: 1 | J16: 0 | K16: 0 | L16: 0 | M16: 12 | N16: 0 | O16: =SUM(C16:L16,N16) -> 2 | P16: =SUM(C16:N16) -> 14 | R16: 1300-1400 | S16: =SUM(C34:C37) -> 10 | T16: =SUM(D34:D37) -> 2 | U16: =SUM(E34:E37) -> 3 | V16: =SUM(F34:F37) -> 0 | W16: =SUM(G34:G37) -> 0 | X16: =SUM(H34:H37) -> 0 | Y16: =SUM(I34:I37) -> 1 | Z16: =SUM(J34:J37) -> 3 | ... AF16: =SUM(P34:P37) -> 138
B17: 08.45 - 9.00 | C17: 2 | D17: 1 | E17: 1 | F17: 0 | G17: 0 | H17: 0 | I17: 0 | J17: 0 | K17: 0 | L17: 0 | M17: 15 | N17: 0 | O17: =SUM(C17:L17,N17) -> 4 | P17: =SUM(C17:N17) -> 19 | R17: 1400-1500 | S17: =SUM(C38:C41) -> 6 | T17: =SUM(D38:D41) -> 6 | U17: =SUM(E38:E41) -> 2 | V17: =SUM(F38:F41) -> 1 | W17: =SUM(G38:G41) -> 0 | X17: =SUM(H38:H41) -> 0 | Y17: =SUM(I38:I41) -> 1 | Z17: =SUM(J38:J41) -> 2 | ... AF17: =SUM(P38:P41) -> 111
B18: 09.00 - 09.15 | C18: 1 | D18: 0 | E18: 0 | F18: 0 | G18: 0 | H18: 0 | I18: 0 | J18: 1 | K18: 0 | L18: 0 | M18: 14 | N18: 0 | O18: =SUM(C18:L18,N18) -> 2 | P18: =SUM(C18:N18) -> 16 | R18: 1500-1600 | S18: =SUM(C42:C45) -> 5 | T18: =SUM(D42:D45) -> 3 | U18: =SUM(E42:E45) -> 2 | V18: =SUM(F42:F45) -> 0 | W18: =SUM(G42:G45) -> 0 | X18: =SUM(H42:H45) -> 0 | Y18: =SUM(I42:I45) -> 0 | Z18: =SUM(J42:J45) -> 3 | ... AF18: =SUM(P42:P45) -> 130
B19: 09.15 - 09.30 | C19: 3 | D19: 0 | E19: 0 | F19: 1 | G19: 0 | H19: 0 | I19: 0 | J19: 0 | K19: 0 | L19: 0 | M19: 12 | N19: 0 | O19: =SUM(C19:L19,N19) -> 4 | P19: =SUM(C19:N19) -> 16 | R19: 1600-1700 | S19: =SUM(C46:C49) -> 5 | T19: =SUM(D46:D49) -> 0 | U19: =SUM(E46:E49) -> 2 | V19: =SUM(F46:F49) -> 0 | W19: =SUM(G46:G49) -> 0 | X19: =SUM(H46:H49) -> 0 | Y19: =SUM(I46:I49) -> 0 | Z19: =SUM(J46:J49) -> 4 | ... AF19: =SUM(P46:P49) -> 132
B20: 09.30 - 09.45 | C20: 2 | D20: 4 | E20: 0 | F20: 0 | G20: 0 | H20: 0 | I20: 0 | J20: 3 | K20: 0 | L20: 0 | M20: 26 | N20: 0 | O20: =SUM(C20:L20,N20) -> 9 | P20: =SUM(C20:N20) -> 35 | R20: 1700-1800 | S20: =SUM(C50:C53) -> 5 | T20: =SUM(D50:D53) -> 3 | U20: =SUM(E50:E53) -> 2 | V20: =SUM(F50:F53) -> 0 | W20: =SUM(G50:G53) -> 0 | X20: =SUM(H50:H53) -> 0 | Y20: =SUM(I50:I53) -> 0 | Z20: =SUM(J50:J53) -> 6 | ... AF20: =SUM(P50:P53) -> 138
B21: 09.45 - 10.00 | C21: 4 | D21: 0 | E21: 0 | F21: 0 | G21: 0 | H21: 0 | I21: 0 | J21: 0 | K21: 0 | L21: 0 | M21: 21 | N21: 0 | O21: =SUM(C21:L21,N21) -> 4 | P21: =SUM(C21:N21) -> 25 | R21: 1800-1900 | S21: =SUM(C54:C57) -> 9 | T21: =SUM(D54:D57) -> 1 | U21: =SUM(E54:E57) -> 2 | V21: =SUM(F54:F57) -> 0 | W21: =SUM(G54:G57) -> 0 | X21: =SUM(H54:H57) -> 0 | Y21: =SUM(I54:I57) -> 0 | Z21: =SUM(J54:J57) -> 6 | ... AF21: =SUM(P54:P57) -> 151
B22: 10.00 - 10.15 | C22: 0 | D22: 1 | E22: 2 | F22: 0 | G22: 0 | H22: 0 | I22: 0 | J22: 0 | K22: 0 | L22: 0 | M22: 22 | N22: 0 | O22: =SUM(C22:L22,N22) -> 3 | P22: =SUM(C22:N22) -> 25 | R22: AM Peak Hr | S22: =MAX(S10:S12) -> 10 | T22: =MAX(T10:T12) -> 4 | U22: =MAX(U10:U12) -> 4 | V22: =MAX(V10:V12) -> 1 | W22: =MAX(W10:W12) -> 0 | X22: =MAX(X10:X12) -> 0 | Y22: =MAX(Y10:Y12) -> 2 | Z22: =MAX(Z10:Z12) -> 4 | ... AF22: =MAX(AF10:AF12) -> 92
B23: 10.15 - 10.30 | C23: 4 | D23: 1 | E23: 0 | F23: 1 | G23: 0 | H23: 0 | I23: 0 | J23: 1 | K23: 0 | L23: 0 | M23: 31 | N23: 0 | O23: =SUM(C23:L23,N23) -> 7 | P23: =SUM(C23:N23) -> 38 | R23: IP Peak Hr | S23: =MAX(S13:S18) -> 14 | T23: =MAX(T13:T18) -> 6 | U23: =MAX(U13:U18) -> 5 | V23: =MAX(V13:V18) -> 1 | W23: =MAX(W13:W18) -> 0 | X23: =MAX(X13:X18) -> 0 | Y23: =MAX(Y13:Y18) -> 1 | Z23: =MAX(Z13:Z18) -> 3 | ... AF23: =MAX(AF13:AF18) -> 152
B24: 10.30 - 10.45 | C24: 0 | D24: 1 | E24: 1 | F24: 0 | G24: 0 | H24: 0 | I24: 1 | J24: 0 | K24: 0 | L24: 0 | M24: 36 | N24: 0 | O24: =SUM(C24:L24,N24) -> 3 | P24: =SUM(C24:N24) -> 39 | R24: PM Peak Hr | S24: =MAX(S19:S21) -> 9 | T24: =MAX(T19:T21) -> 3 | U24: =MAX(U19:U21) -> 2 | V24: =MAX(V19:V21) -> 0 | W24: =MAX(W19:W21) -> 0 | X24: =MAX(X19:X21) -> 0 | Y24: =MAX(Y19:Y21) -> 0 | Z24: =MAX(Z19:Z21) -> 6 | ... AF24: =MAX(AF19:AF21) -> 151
B25: 10.45 - 11.00 | C25: 4 | D25: 0 | E25: 1 | F25: 0 | G25: 0 | H25: 0 | I25: 0 | J25: 0 | K25: 0 | L25: 0 | M25: 27 | N25: 0 | O25: =SUM(C25:L25,N25) -> 5 | P25: =SUM(C25:N25) -> 32 | R25: AM Period | S25: =SUM(S10:S12) -> 22 | T25: =SUM(T10:T12) -> 8 | U25: =SUM(U10:U12) -> 4 | V25: =SUM(V10:V12) -> 1 | W25: =SUM(W10:W12) -> 0 | X25: =SUM(X10:X12) -> 0 | Y25: =SUM(Y10:Y12) -> 2 | Z25: =SUM(Z10:Z12) -> 5 | ... AF25: =SUM(AF10:AF12) -> 196
B26: 11.00 - 11.15 | C26: 5 | D26: 1 | E26: 0 | F26: 0 | G26: 0 | H26: 0 | I26: 1 | J26: 1 | K26: 0 | L26: 0 | M26: 29 | N26: 0 | O26: =SUM(C26:L26,N26) -> 8 | P26: =SUM(C26:N26) -> 37 | R26: IP Period | S26: =SUM(S13:S18) -> 49 | T26: =SUM(T13:T18) -> 22 | U26: =SUM(U13:U18) -> 17 | V26: =SUM(V13:V18) -> 3 | W26: =SUM(W13:W18) -> 0 | X26: =SUM(X13:X18) -> 0 | Y26: =SUM(Y13:Y18) -> 4 | Z26: =SUM(Z13:Z18) -> 14 | ... AF26: =SUM(AF13:AF18) -> 793
B27: 11.15 - 11.30 | C27: 4 | D27: 2 | E27: 1 | F27: 0 | G27: 0 | H27: 0 | I27: 0 | J27: 0 | K27: 0 | L27: 0 | M27: 30 | N27: 0 | O27: =SUM(C27:L27,N27) -> 7 | P27: =SUM(C27:N27) -> 37 | R27: PM Period | S27: =SUM(S19:S21) -> 19 | T27: =SUM(T19:T21) -> 4 | U27: =SUM(U19:U21) -> 6 | V27: =SUM(V19:V21) -> 0 | W27: =SUM(W19:W21) -> 0 | X27: =SUM(X19:X21) -> 0 | Y27: =SUM(Y19:Y21) -> 0 | Z27: =SUM(Z19:Z21) -> 16 | ... AF27: =SUM(AF19:AF21) -> 421
B28: 11.30 - 11.45 | C28: 2 | D28: 0 | E28: 0 | F28: 0 | G28: 0 | H28: 0 | I28: 0 | J28: 1 | K28: 0 | L28: 0 | M28: 38 | N28: 0 | O28: =SUM(C28:L28,N28) -> 3 | P28: =SUM(C28:N28) -> 41 | R28: 12 Hours | S28: =SUM(S10:S21) -> 90 | T28: =SUM(T10:T21) -> 34 | U28: =SUM(U10:U21) -> 27 | V28: =SUM(V10:V21) -> 4 | W28: =SUM(W10:W21) -> 0 | X28: =SUM(X10:X21) -> 0 | Y28: =SUM(Y10:Y21) -> 6 | Z28: =SUM(Z10:Z21) -> 35 | ... AF28: =SUM(AF10:AF21) -> 1410
B29: 11.45 - 12.00 | C29: 3 | D29: 2 | E29: 0 | F29: 1 | G29: 0 | H29: 0 | I29: 0 | J29: 0 | K29: 0 | L29: 0 | M29: 31 | N29: 0 | O29: =SUM(C29:L29,N29) -> 6 | P29: =SUM(C29:N29) -> 37
B30: 12.00 - 12.15 | C30: 2 | D30: 0 | E30: 1 | F30: 0 | G30: 0 | H30: 0 | I30: 0 | J30: 0 | K30: 0 | L30: 0 | M30: 23 | N30: 0 | O30: =SUM(C30:L30,N30) -> 3 | P30: =SUM(C30:N30) -> 26
B31: 12.15 - 12.30 | C31: 1 | D31: 1 | E31: 2 | F31: 0 | G31: 0 | H31: 0 | I31: 0 | J31: 1 | K31: 0 | L31: 0 | M31: 29 | N31: 0 | O31: =SUM(C31:L31,N31) -> 5 | P31: =SUM(C31:N31) -> 34
B32: 12.30 - 12.45 | C32: 2 | D32: 1 | E32: 1 | F32: 0 | G32: 0 | H32: 0 | I32: 0 | J32: 1 | K32: 0 | L32: 0 | M32: 21 | N32: 0 | O32: =SUM(C32:L32,N32) -> 5 | P32: =SUM(C32:N32) -> 26
B33: 12.45 - 13.00 | C33: 1 | D33: 1 | E33: 1 | F33: 0 | G33: 0 | H33: 0 | I33: 0 | J33: 1 | K33: 0 | L33: 0 | M33: 38 | N33: 0 | O33: =SUM(C33:L33,N33) -> 4 | P33: =SUM(C33:N33) -> 42
B34: 13.00 - 13.15 | C34: 3 | D34: 1 | E34: 0 | F34: 0 | G34: 0 | H34: 0 | I34: 1 | J34: 0 | K34: 0 | L34: 0 | M34: 25 | N34: 0 | O34: =SUM(C34:L34,N34) -> 5 | P34: =SUM(C34:N34) -> 30
B35: 13.15 - 13.30 | C35: 3 | D35: 0 | E35: 1 | F35: 0 | G35: 0 | H35: 0 | I35: 0 | J35: 1 | K35: 0 | L35: 0 | M35: 39 | N35: 0 | O35: =SUM(C35:L35,N35) -> 5 | P35: =SUM(C35:N35) -> 44
B36: 13.30 - 13.45 | C36: 3 | D36: 1 | E36: 2 | F36: 0 | G36: 0 | H36: 0 | I36: 0 | J36: 1 | K36: 0 | L36: 0 | M36: 22 | N36: 0 | O36: =SUM(C36:L36,N36) -> 7 | P36: =SUM(C36:N36) -> 29
B37: 13.45 - 14.00 | C37: 1 | D37: 0 | E37: 0 | F37: 0 | G37: 0 | H37: 0 | I37: 0 | J37: 1 | K37: 0 | L37: 0 | M37: 33 | N37: 0 | O37: =SUM(C37:L37,N37) -> 2 | P37: =SUM(C37:N37) -> 35
B38: 14.00 - 14.15 | C38: 1 | D38: 2 | E38: 2 | F38: 0 | G38: 0 | H38: 0 | I38: 1 | J38: 0 | K38: 0 | L38: 0 | M38: 24 | N38: 0 | O38: =SUM(C38:L38,N38) -> 6 | P38: =SUM(C38:N38) -> 30
B39: 14.15 - 14.30 | C39: 1 | D39: 1 | E39: 0 | F39: 1 | G39: 0 | H39: 0 | I39: 0 | J39: 0 | K39: 0 | L39: 0 | M39: 19 | N39: 0 | O39: =SUM(C39:L39,N39) -> 3 | P39: =SUM(C39:N39) -> 22
B40: 14.30 - 14.45 | C40: 3 | D40: 2 | E40: 0 | F40: 0 | G40: 0 | H40: 0 | I40: 0 | J40: 2 | K40: 0 | L40: 0 | M40: 22 | N40: 0 | O40: =SUM(C40:L40,N40) -> 7 | P40: =SUM(C40:N40) -> 29
... B57: 18.45 - 19.00 | C57: 3 | D57: 1 | E57: 1 | F57: 0 | G57: 0 | H57: 0 | I57: 0 | J57: 1 | K57: 0 | L57: 0 | M57: 39 | N57: 0 | O57: =SUM(C57:L57,N57) -> 6 | P57: =SUM(C57:N57) -> 45
B58: Totals | C58: =SUM(C10:C57) -> 90 | D58: =SUM(D10:D57) -> 34 | E58: =SUM(E10:E57) -> 27 | F58: =SUM(F10:F57) -> 4 | G58: =SUM(G10:G57) -> 0 | H58: =SUM(H10:H57) -> 0 | I58: =SUM(I10:I57) -> 6 | J58: =SUM(J10:J57) -> 35 | ... P58: =SUM(P10:P57) -> 1410
...

Sheet 26.10 KISORO-CYANIKA
B1: Consultancy services for Preparation of Expressway Development Master Plan (EDMP) for Uganda
B2: MANUAL CLASSIFIED COUNT (MCC)
B3: ROAD NAME: | C3: ='27.10 KISORO-CYANIKA'!C3:G3 -> MCC - C4 - STN135 - KISORO ROAD
C5: Date | D5: ='26.10 CYANIKA-KISORO'!D5 -> 26.10.19 | F5: Location | G5: ='27.10 CYANIKA-KISORO'!G5:H5 -> STATION 135 | J5: Surveyor | K5: JOVANA BELLA
C6: Dir. From | D6: ='27.10 KISORO-CYANIKA'!D6:E6 -> KISORO | F6: Dir. To | G6: ='27.10 KISORO-CYANIKA'!G6:H6 -> CYANIKA | J6: Supervisor | K6: ='27.10 CYANIKA-KISORO'!K6:L6 -> BELLA
B8: Time / Veh Type | R8: SUMMARY TRAFFIC VOLUMES
C9: 1. Car | D9: 2. Station Wagon | E9: 3. Pickups | F9: 4. Minibus, matatu | G9: 5. Medium bus | H9: 6. Large Bus | I9: 7. Light Truck | J9: 8. Medium Truck | K9: 9. Heavy truck | L9: 10. Truck Trailer | M9: 11. Motor cycles | N9: 12. Tractors | O9: Total Excl M/Cycles | P9: Total All | R9: Time | S9: 1. Car | T9: 2. Station Wagon | U9: 3. Pickups | V9: 4. Minibus, matatu | W9: 5. Medium bus | X9: 6. Large Bus | Y9: 7. Light Truck | Z9: 8. Medium Truck | AA9: 9. Heavy truck | AB9: 10. Truck Trailer | AC9: 11. Motorcycles | AD9: 12. Tractors, Graders | AE9: Total Excl M/ Cycles | AF9: Total All
B10: 07.00 - 07.15 | C10: 4 | D10: 0 | E10: 0 | F10: 0 | G10: 0 | H10: 0 | I10: 0 | J10: 0 | K10: 0 | L10: 0 | M10: 1 | N10: 0 | O10: =SUM(C10:L10,N10) -> 4 | P10: =SUM(C10:N10) -> 5 | R10: 0700-0800 | S10: =SUM(C10:C13) -> 7 | T10: =SUM(D10:D13) -> 0 | U10: =SUM(E10:E13) -> 1 | V10: =SUM(F10:F13) -> 0 | W10: =SUM(G10:G13) -> 0 | X10: =SUM(H10:H13) -> 0 | Y10: =SUM(I10:I13) -> 0 | Z10: =SUM(J10:J13) -> 3 | ... AF10: =SUM(P10:P13) -> 40
B11: 07.15 - 07.30 | C11: 1 | D11: 0 | E11: 1 | F11: 0 | G11: 0 | H11: 0 | I11: 0 | J11: 2 | K11: 0 | L11: 0 | M11: 6 | N11: 0 | O11: =SUM(C11:L11,N11) -> 4 | P11: =SUM(C11:N11) -> 10 | R11: 0800-0900 | S11: =SUM(C14:C17) -> 7 | T11: =SUM(D14:D17) -> 2 | U11: =SUM(E14:E17) -> 1 | V11: =SUM(F14:F17) -> 1 | W11: =SUM(G14:G17) -> 0 | X11: =SUM(H14:H17) -> 0 | Y11: =SUM(I14:I17) -> 0 | Z11: =SUM(J14:J17) -> 3 | ... AF11: =SUM(P14:P17) -> 48
B12: 07.30 - 07.45 | C12: 1 | D12: 0 | E12: 0 | F12: 0 | G12: 0 | H12: 0 | I12: 0 | J12: 0 | K12: 0 | L12: 0 | M12: 11 | N12: 0 | O12: =SUM(C12:L12,N12) -> 1 | P12: =SUM(C12:N12) -> 12 | R12: 0900-1000 | S12: =SUM(C18:C21) -> 2 | T12: =SUM(D18:D21) -> 5 | U12: =SUM(E18:E21) -> 1 | V12: =SUM(F18:F21) -> 0 | W12: =SUM(G18:G21) -> 0 | X12: =SUM(H18:H21) -> 0 | Y12: =SUM(I18:I21) -> 1 | Z12: =SUM(J18:J21) -> 4 | ... AF12: =SUM(P18:P21) -> 86
B13: 07.45 - 08.00 | C13: 1 | D13: 0 | E13: 0 | F13: 0 | G13: 0 | H13: 0 | I13: 0 | J13: 1 | K13: 0 | L13: 0 | M13: 11 | N13: 0 | O13: =SUM(C13:L13,N13) -> 2 | P13: =SUM(C13:N13) -> 13 | R13: 1000-1100 | S13: =SUM(C22:C25) -> 7 | T13: =SUM(D22:D25) -> 0 | U13: =SUM(E22:E25) -> 4 | V13: =SUM(F22:F25) -> 2 | W13: =SUM(G22:G25) -> 0 | X13: =SUM(H22:H25) -> 0 | Y13: =SUM(I22:I25) -> 3 | Z13: =SUM(J22:J25) -> 5 | ... AF13: =SUM(P22:P25) -> 134
B14: 08.00 - 08.15 | C14: 2 | D14: 2 | E14: 1 | F14: 0 | G14: 0 | H14: 0 | I14: 0 | J14: 0 | K14: 0 | L14: 0 | M14: 6 | N14: 0 | O14: =SUM(C14:L14,N14) -> 5 | P14: =SUM(C14:N14) -> 11 | R14: 1100-1200 | S14: =SUM(C26:C29) -> 5 | T14: =SUM(D26:D29) -> 6 | U14: =SUM(E26:E29) -> 2 | V14: =SUM(F26:F29) -> 1 | W14: =SUM(G26:G29) -> 0 | X14: =SUM(H26:H29) -> 0 | Y14: =SUM(I26:I29) -> 3 | Z14: =SUM(J26:J29) -> 1 | ... AF14: =SUM(P26:P29) -> 169
B15: 08.15 - 08.30 | C15: 3 | D15: 0 | E15: 0 | F15: 1 | G15: 0 | H15: 0 | I15: 0 | J15: 1 | K15: 0 | L15: 0 | M15: 4 | N15: 0 | O15: =SUM(C15:L15,N15) -> 5 | P15: =SUM(C15:N15) -> 9 | R15: 1200-1300 | S15: =SUM(C30:C33) -> 6 | T15: =SUM(D30:D33) -> 3 | U15: =SUM(E30:E33) -> 4 | V15: =SUM(F30:F33) -> 0 | W15: =SUM(G30:G33) -> 0 | X15: =SUM(H30:H33) -> 0 | Y15: =SUM(I30:I33) -> 1 | Z15: =SUM(J30:J33) -> 5 | ... AF15: =SUM(P30:P33) -> 172
B16: 08.30 - 08.45 | C16: 1 | D16: 0 | E16: 0 | F16: 0 | G16: 0 | H16: 0 | I16: 0 | J16: 1 | K16: 0 | L16: 0 | M16: 12 | N16: 0 | O16: =SUM(C16:L16,N16) -> 2 | P16: =SUM(C16:N16) -> 14 | R16: 1300-1400 | S16: =SUM(C34:C37) -> 10 | T16: =SUM(D34:D37) -> 6 | U16: =SUM(E34:E37) -> 4 | V16: =SUM(F34:F37) -> 1 | W16: =SUM(G34:G37) -> 0 | X16: =SUM(H34:H37) -> 0 | Y16: =SUM(I34:I37) -> 5 | Z16: =SUM(J34:J37) -> 2 | ... AF16: =SUM(P34:P37) -> 174
B17: 08.45 - 9.00 | C17: 1 | D17: 0 | E17: 0 | F17: 0 | G17: 0 | H17: 0 | I17: 0 | J17: 1 | K17: 0 | L17: 0 | M17: 12 | N17: 0 | O17: =SUM(C17:L17,N17) -> 2 | P17: =SUM(C17:N17) -> 14 | R17: 1400-1500 | S17: =SUM(C38:C41) -> 9 | T17: =SUM(D38:D41) -> 4 | U17: =SUM(E38:E41) -> 4 | V17: =SUM(F38:F41) -> 0 | W17: =SUM(G38:G41) -> 0 | X17: =SUM(H38:H41) -> 1 | Y17: =SUM(I38:I41) -> 1 | Z17: =SUM(J38:J41) -> 3 | ... AF17: =SUM(P38:P41) -> 179
B18: 09.00 - 09.15 | C18: 1 | D18: 2 | E18: 0 | F18: 0 | G18: 0 | H18: 0 | I18: 0 | J18: 1 | K18: 0 | L18: 0 | M18: 12 | N18: 0 | O18: =SUM(C18:L18,N18) -> 4 | P18: =SUM(C18:N18) -> 16 | R18: 1500-1600 | S18: =SUM(C42:C45) -> 7 | T18: =SUM(D42:D45) -> 4 | U18: =SUM(E42:E45) -> 1 | V18: =SUM(F42:F45) -> 0 | W18: =SUM(G42:G45) -> 0 | X18: =SUM(H42:H45) -> 0 | Y18: =SUM(I42:I45) -> 3 | Z18: =SUM(J42:J45) -> 1 | ... AF18: =SUM(P42:P45) -> 160
B19: 09.15 - 09.30 | C19: 0 | D19: 1 | E19: 0 | F19: 0 | G19: 0 | H19: 0 | I19: 0 | J19: 0 | K19: 0 | L19: 0 | M19: 14 | N19: 0 | O19: =SUM(C19:L19,N19) -> 1 | P19: =SUM(C19:N19) -> 15 | R19: 1600-1700 | S19: =SUM(C46:C49) -> 9 | T19: =SUM(D46:D49) -> 11 | U19: =SUM(E46:E49) -> 3 | V19: =SUM(F46:F49) -> 1 | W19: =SUM(G46:G49) -> 0 | X19: =SUM(H46:H49) -> 0 | Y19: =SUM(I46:I49) -> 1 | Z19: =SUM(J46:J49) -> 1 | ... AF19: =SUM(P46:P49) -> 168
B20: 09.30 - 09.45 | C20: 1 | D20: 1 | E20: 0 | F20: 0 | G20: 0 | H20: 0 | I20: 0 | J20: 1 | K20: 0 | L20: 0 | M20: 19 | N20: 0 | O20: =SUM(C20:L20,N20) -> 3 | P20: =SUM(C20:N20) -> 22 | R20: 1700-1800 | S20: =SUM(C50:C53) -> 7 | T20: =SUM(D50:D53) -> 4 | U20: =SUM(E50:E53) -> 4 | V20: =SUM(F50:F53) -> 0 | W20: =SUM(G50:G53) -> 0 | X20: =SUM(H50:H53) -> 0 | Y20: =SUM(I50:I53) -> 2 | Z20: =SUM(J50:J53) -> 2 | ... AF20: =SUM(P50:P53) -> 177
B21: 09.45 - 10.00 | C21: 0 | D21: 1 | E21: 1 | F21: 0 | G21: 0 | H21: 0 | I21: 1 | J21: 2 | K21: 0 | L21: 0 | M21: 28 | N21: 0 | O21: =SUM(C21:L21,N21) -> 5 | P21: =SUM(C21:N21) -> 33 | R21: 1800-1900 | S21: =SUM(C54:C57) -> 9 | T21: =SUM(D54:D57) -> 3 | U21: =SUM(E54:E57) -> 1 | V21: =SUM(F54:F57) -> 1 | W21: =SUM(G54:G57) -> 0 | X21: =SUM(H54:H57) -> 0 | Y21: =SUM(I54:I57) -> 2 | Z21: =SUM(J54:J57) -> 2 | ... AF21: =SUM(P54:P57) -> 188
B22: 10.00 - 10.15 | C22: 3 | D22: 0 | E22: 0 | F22: 0 | G22: 0 | H22: 0 | I22: 1 | J22: 0 | K22: 0 | L22: 0 | M22: 21 | N22: 0 | O22: =SUM(C22:L22,N22) -> 4 | P22: =SUM(C22:N22) -> 25 | R22: AM Peak Hr | S22: =MAX(S10:S12) -> 7 | T22: =MAX(T10:T12) -> 5 | U22: =MAX(U10:U12) -> 1 | V22: =MAX(V10:V12) -> 1 | W22: =MAX(W10:W12) -> 0 | X22: =MAX(X10:X12) -> 0 | Y22: =MAX(Y10:Y12) -> 1 | Z22: =MAX(Z10:Z12) -> 4 | ... AF22: =MAX(AF10:AF12) -> 86
B23: 10.15 - 10.30 | C23: 2 | D23: 0 | E23: 0 | F23: 0 | G23: 0 | H23: 0 | I23: 0 | J23: 1 | K23: 0 | L23: 0 | M23: 27 | N23: 0 | O23: =SUM(C23:L23,N23) -> 3 | P23: =SUM(C23:N23) -> 30 | R23: IP Peak Hr | S23: =MAX(S13:S18) -> 10 | T23: =MAX(T13:T18) -> 6 | U23: =MAX(U13:U18) -> 4 | V23: =MAX(V13:V18) -> 2 | W23: =MAX(W13:W18) -> 0 | X23: =MAX(X13:X18) -> 1 | Y23: =MAX(Y13:Y18) -> 5 | Z23: =MAX(Z13:Z18) -> 5 | ... AF23: =MAX(AF13:AF18) -> 179
B24: 10.30 - 10.45 | C24: 0 | D24: 0 | E24: 2 | F24: 1 | G24: 0 | H24: 0 | I24: 1 | J24: 3 | K24: 0 | L24: 0 | M24: 30 | N24: 0 | O24: =SUM(C24:L24,N24) -> 7 | P24: =SUM(C24:N24) -> 37 | R24: PM Peak Hr | S24: =MAX(S19:S21) -> 9 | T24: =MAX(T19:T21) -> 11 | U24: =MAX(U19:U21) -> 4 | V24: =MAX(V19:V21) -> 1 | W24: =MAX(W19:W21) -> 0 | X24: =MAX(X19:X21) -> 0 | Y24: =MAX(Y19:Y21) -> 2 | Z24: =MAX(Z19:Z21) -> 2 | ... AF24: =MAX(AF19:AF21) -> 188
B25: 10.45 - 11.00 | C25: 2 | D25: 0 | E25: 2 | F25: 1 | G25: 0 | H25: 0 | I25: 1 | J25: 1 | K25: 0 | L25: 0 | M25: 35 | N25: 0 | O25: =SUM(C25:L25,N25) -> 7 | P25: =SUM(C25:N25) -> 42 | R25: AM Period | S25: =SUM(S10:S12) -> 16 | T25: =SUM(T10:T12) -> 7 | U25: =SUM(U10:U12) -> 3 | V25: =SUM(V10:V12) -> 1 | W25: =SUM(W10:W12) -> 0 | X25: =SUM(X10:X12) -> 0 | Y25: =SUM(Y10:Y12) -> 1 | Z25: =SUM(Z10:Z12) -> 10 | ... AF25: =SUM(AF10:AF12) -> 174
B26: 11.00 - 11.15 | C26: 3 | D26: 1 | E26: 0 | F26: 0 | G26: 0 | H26: 0 | I26: 0 | J26: 0 | K26: 0 | L26: 0 | M26: 31 | N26: 0 | O26: =SUM(C26:L26,N26) -> 4 | P26: =SUM(C26:N26) -> 35 | R26: IP Period | S26: =SUM(S13:S18) -> 44 | T26: =SUM(T13:T18) -> 23 | U26: =SUM(U13:U18) -> 19 | V26: =SUM(V13:V18) -> 4 | W26: =SUM(W13:W18) -> 0 | X26: =SUM(X13:X18) -> 1 | Y26: =SUM(Y13:Y18) -> 16 | Z26: =SUM(Z13:Z18) -> 17 | ... AF26: =SUM(AF13:AF18) -> 988
B27: 11.15 - 11.30 | C27: 1 | D27: 1 | E27: 0 | F27: 0 | G27: 0 | H27: 0 | I27: 1 | J27: 0 | K27: 0 | L27: 0 | M27: 39 | N27: 0 | O27: =SUM(C27:L27,N27) -> 3 | P27: =SUM(C27:N27) -> 42 | R27: PM Period | S27: =SUM(S19:S21) -> 25 | T27: =SUM(T19:T21) -> 18 | U27: =SUM(U19:U21) -> 8 | V27: =SUM(V19:V21) -> 2 | W27: =SUM(W19:W21) -> 0 | X27: =SUM(X19:X21) -> 0 | Y27: =SUM(Y19:Y21) -> 5 | Z27: =SUM(Z19:Z21) -> 5 | ... AF27: =SUM(AF19:AF21) -> 533
B28: 11.30 - 11.45 | C28: 0 | D28: 2 | E28: 1 | F28: 1 | G28: 0 | H28: 0 | I28: 0 | J28: 0 | K28: 0 | L28: 0 | M28: 44 | N28: 0 | O28: =SUM(C28:L28,N28) -> 4 | P28: =SUM(C28:N28) -> 48 | R28: 12 Hours | S28: =SUM(S10:S21) -> 85 | T28: =SUM(T10:T21) -> 48 | U28: =SUM(U10:U21) -> 30 | V28: =SUM(V10:V21) -> 7 | W28: =SUM(W10:W21) -> 0 | X28: =SUM(X10:X21) -> 1 | Y28: =SUM(Y10:Y21) -> 22 | Z28: =SUM(Z10:Z21) -> 32 | ... AF28: =SUM(AF10:AF21) -> 1695
B29: 11.45 - 12.00 | C29: 1 | D29: 2 | E29: 1 | F29: 0 | G29: 0 | H29: 0 | I29: 2 | J29: 1 | K29: 0 | L29: 0 | M29: 37 | N29: 0 | O29: =SUM(C29:L29,N29) -> 7 | P29: =SUM(C29:N29) -> 44
B30: 12.00 - 12.15 | C30: 1 | D30: 1 | E30: 2 | F30: 0 | G30: 0 | H30: 0 | I30: 1 | J30: 1 | K30: 0 | L30: 0 | M30: 42 | N30: 0 | O30: =SUM(C30:L30,N30) -> 6 | P30: =SUM(C30:N30) -> 48
B31: 12.15 - 12.30 | C31: 3 | D31: 1 | E31: 1 | F31: 0 | G31: 0 | H31: 0 | I31: 0 | J31: 1 | K31: 0 | L31: 0 | M31: 31 | N31: 0 | O31: =SUM(C31:L31,N31) -> 6 | P31: =SUM(C31:N31) -> 37
B32: 12.30 - 12.45 | C32: 1 | D32: 1 | E32: 1 | F32: 0 | G32: 0 | H32: 0 | I32: 0 | J32: 0 | K32: 0 | L32: 0 | M32: 31 | N32: 0 | O32: =SUM(C32:L32,N32) -> 3 | P32: =SUM(C32:N32) -> 34
B33: 12.45 - 13.00 | C33: 1 | D33: 0 | E33: 0 | F33: 0 | G33: 0 | H33: 0 | I33: 0 | J33: 3 | K33: 0 | L33: 0 | M33: 49 | N33: 0 | O33: =SUM(C33:L33,N33) -> 4 | P33: =SUM(C33:N33) -> 53
B34: 13.00 - 13.15 | C34: 3 | D34: 0 | E34: 0 | F34: 1 | G34: 0 | H34: 0 | I34: 1 | J34: 2 | K34: 0 | L34: 0 | M34: 30 | N34: 0 | O34: =SUM(C34:L34,N34) -> 7 | P34: =SUM(C34:N34) -> 37
B35: 13.15 - 13.30 | C35: 3 | D35: 3 | E35: 2 | F35: 0 | G35: 0 | H35: 0 | I35: 1 | J35: 0 | K35: 0 | L35: 0 | M35: 29 | N35: 0 | O35: =SUM(C35:L35,N35) -> 9 | P35: =SUM(C35:N35) -> 38
B36: 13.30 - 13.45 | C36: 3 | D36: 1 | E36: 0 | F36: 0 | G36: 0 | H36: 0 | I36: 1 | J36: 0 | K36: 0 | L36: 0 | M36: 46 | N36: 0 | O36: =SUM(C36:L36,N36) -> 5 | P36: =SUM(C36:N36) -> 51
B37: 13.45 - 14.00 | C37: 1 | D37: 2 | E37: 2 | F37: 0 | G37: 0 | H37: 0 | I37: 2 | J37: 0 | K37: 0 | L37: 0 | M37: 41 | N37: 0 | O37: =SUM(C37:L37,N37) -> 7 | P37: =SUM(C37:N37) -> 48
B38: 14.00 - 14.15 | C38: 5 | D38: 2 | E38: 1 | F38: 0 | G38: 0 | H38: 1 | I38: 0 | J38: 1 | K38: 0 | L38: 0 | M38: 37 | N38: 0 | O38: =SUM(C38:L38,N38) -> 10 | P38: =SUM(C38:N38) -> 47
B39: 14.15 - 14.30 | C39: 1 | D39: 2 | E39: 0 | F39: 0 | G39: 0 | H39: 0 | I39: 0 | J39: 2 | K39: 0 | L39: 0 | M39: 42 | N39: 0 | O39: =SUM(C39:L39,N39) -> 5 | P39: =SUM(C39:N39) -> 47
B40: 14.30 - 14.45 | C40: 2 | D40: 0 | E40: 1 | F40: 0 | G40: 0 | H40: 0 | I40: 1 | J40: 0 | K40: 0 | L40: 0 | M40: 40 | N40: 0 | O40: =SUM(C40:L40,N40) -> 4 | P40: =SUM(C40:N40) -> 44
... B57: 18.45 - 19.00 | C57: 5 | D57: 0 | E57: 0 | F57: 0 | G57: 0 | H57: 0 | I57: 0 | J57: 1 | K57: 0 | L57: 0 | M57: 60 | N57: 0 | O57: =SUM(C57:L57,N57) -> 6 | P57: =SUM(C57:N57) -> 66
B58: Totals | C58: =SUM(C10:C57) -> 85 | D58: =SUM(D10:D57) -> 48 | E58: =SUM(E10:E57) -> 30 | F58: =SUM(F10:F57) -> 7 | G58: =SUM(G10:G57) -> 0 | H58: =SUM(H10:H57) -> 1 | I58: =SUM(I10:I57) -> 22 | J58: =SUM(J10:J57) -> 32 | ... P58: =SUM(P10:P57) -> 1695
...

Sheet 27.10 CYANIKA-KISORO
B1: Consultancy services for Preparation of Expressway Development Master Plan (EDMP) for Uganda
B2: MANUAL CLASSIFIED COUNT (MCC)
B3: ROAD NAME: | C3: MCC - C4 - STN135 - KISORO ROAD
C5: Date | D5: 27.10.2019 | F5: Location | G5: STATION 135 | J5: Surveyor | K5: COMFORT AHEBWA
C6: Dir. From | D6: CYANIKA | F6: Dir. To | G6: KISORO | J6: Supervisor | K6: BELLA
B8: Time / Veh Type | R8: SUMMARY TRAFFIC VOLUMES
C9: 1. Car | D9: 2. Station Wagon | E9: 3. Pickups | F9: 4. Minibus, matatu | G9: 5. Medium bus | H9: 6. Large Bus | I9: 7. Light Truck | J9: 8. Medium Truck | K9: 9. Heavy truck | L9: 10. Truck Trailer | M9: 11. Motor cycles | N9: 12. Tractors | O9: Total Excl M/Cycles | P9: Total All | R9: Time | S9: 1. Car | T9: 2. Station Wagon | U9: 3. Pickups | V9: 4. Minibus, matatu | W9: 5. Medium bus | X9: 6. Large Bus | Y9: 7. Light Truck | Z9: 8. Medium Truck | AA9: 9. Heavy truck | AB9: 10. Truck Trailer | AC9: 11. Motorcycles | AD9: 12. Tractors, Graders | AE9: Total Excl M/ Cycles | AF9: Total All
B10: 07.00 - 07.15 | C10: 1 | D10: 1 | E10: 0 | F10: 0 | G10: 0 | H10: 0 | I10: 0 | J10: 0 | K10: 0 | L10: 0 | M10: 9 | N10: 0 | O10: =SUM(C10:L10,N10) -> 2 | P10: =SUM(C10:N10) -> 11 | R10: 0700-0800 | S10: =SUM(C10:C13) -> 4 | T10: =SUM(D10:D13) -> 3 | U10: =SUM(E10:E13) -> 3 | V10: =SUM(F10:F13) -> 1 | W10: =SUM(G10:G13) -> 0 | X10: =SUM(H10:H13) -> 0 | Y10: =SUM(I10:I13) -> 0 | Z10: =SUM(J10:J13) -> 0 | ... AF10: =SUM(P10:P13) -> 45
B11: 07.15 - 07.30 | C11: 0 | D11: 0 | E11: 0 | F11: 1 | G11: 0 | H11: 0 | I11: 0 | J11: 0 | K11: 0 | L11: 0 | M11: 13 | N11: 0 | O11: =SUM(C11:L11,N11) -> 1 | P11: =SUM(C11:N11) -> 14 | R11: 0800-0900 | S11: =SUM(C14:C17) -> 4 | T11: =SUM(D14:D17) -> 2 | U11: =SUM(E14:E17) -> 4 | V11: =SUM(F14:F17) -> 0 | W11: =SUM(G14:G17) -> 0 | X11: =SUM(H14:H17) -> 0 | Y11: =SUM(I14:I17) -> 0 | Z11: =SUM(J14:J17) -> 0 | ... AF11: =SUM(P14:P17) -> 62
B12: 07.30 - 07.45 | C12: 1 | D12: 0 | E12: 1 | F12: 0 | G12: 0 | H12: 0 | I12: 0 | J12: 0 | K12: 0 | L12: 0 | M12: 8 | N12: 0 | O12: =SUM(C12:L12,N12) -> 2 | P12: =SUM(C12:N12) -> 10 | R12: 0900-1000 | S12: =SUM(C18:C21) -> 6 | T12: =SUM(D18:D21) -> 2 | U12: =SUM(E18:E21) -> 4 | V12: =SUM(F18:F21) -> 0 | W12: =SUM(G18:G21) -> 0 | X12: =SUM(H18:H21) -> 0 | Y12: =SUM(I18:I21) -> 0 | Z12: =SUM(J18:J21) -> 0 | ... AF12: =SUM(P18:P21) -> 110
B13: 07.45 - 08.00 | C13: 2 | D13: 2 | E13: 2 | F13: 0 | G13: 0 | H13: 0 | I13: 0 | J13: 0 | K13: 0 | L13: 0 | M13: 4 | N13: 0 | O13: =SUM(C13:L13,N13) -> 6 | P13: =SUM(C13:N13) -> 10 | R13: 1000-1100 | S13: =SUM(C22:C25) -> 9 | T13: =SUM(D22:D25) -> 3 | U13: =SUM(E22:E25) -> 3 | V13: =SUM(F22:F25) -> 0 | W13: =SUM(G22:G25) -> 0 | X13: =SUM(H22:H25) -> 0 | Y13: =SUM(I22:I25) -> 0 | Z13: =SUM(J22:J25) -> 0 | ... AF13: =SUM(P22:P25) -> 140
B14: 08.00 - 08.15 | C14: 1 | D14: 0 | E14: 1 | F14: 0 | G14: 0 | H14: 0 | I14: 0 | J14: 0 | K14: 0 | L14: 0 | M14: 7 | N14: 0 | O14: =SUM(C14:L14,N14) -> 2 | P14: =SUM(C14:N14) -> 9 | R14: 1100-1200 | S14: =SUM(C26:C29) -> 9 | T14: =SUM(D26:D29) -> 6 | U14: =SUM(E26:E29) -> 0 | V14: =SUM(F26:F29) -> 0 | W14: =SUM(G26:G29) -> 0 | X14: =SUM(H26:H29) -> 0 | Y14: =SUM(I26:I29) -> 1 | Z14: =SUM(J26:J29) -> 1 | ... AF14: =SUM(P26:P29) -> 145
B15: 08.15 - 08.30 | C15: 1 | D15: 0 | E15: 0 | F15: 0 | G15: 0 | H15: 0 | I15: 0 | J15: 0 | K15: 0 | L15: 0 | M15: 17 | N15: 0 | O15: =SUM(C15:L15,N15) -> 1 | P15: =SUM(C15:N15) -> 18 | R15: 1200-1300 | S15: =SUM(C30:C33) -> 4 | T15: =SUM(D30:D33) -> 4 | U15: =SUM(E30:E33) -> 2 | V15: =SUM(F30:F33) -> 0 | W15: =SUM(G30:G33) -> 0 | X15: =SUM(H30:H33) -> 0 | Y15: =SUM(I30:I33) -> 2 | Z15: =SUM(J30:J33) -> 2 | ... AF15: =SUM(P30:P33) -> 113
