Workbook

Sheet 29.07 Pakwach-Karuma
B1: Consultancy services for Preparation of Expressway Development Master Plan (EDMP) for Uganda
B2: MANUAL CLASSIFIED COUNT (MCC)
B3: ROAD NAME: | C3: MCC - C5 - STN115 - KARUMA-PAKWACH ROAD
C5: Date | D5: 29.07.19 | F5: Location | G5: xxx | J5: Surveyor | K5: xxx
C6: Dir. From | D6: pakwach | F6: Dir. To | G6: karuma | J6: Supervisor | K6: xxx
B8: Time / Veh Type | R8: SUMMARY TRAFFIC VOLUMES
C9: 1. Car | D9: 2. Station Wagon | E9: 3. Pickups | F9: 4. Minibus, matatu | G9: 5. Medium bus | H9: 6. Large Bus | I9: 7. Light Truck | J9: 8. Medium Truck | K9: 9. Heavy truck | L9: 10. Truck Trailer | M9: 11. Motor cycles | N9: 12. Tractors | O9: Total Excl M/Cycles | P9: Total All | R9: Time | S9: 1. Car | T9: 2. Station Wagon | U9: 3. Pickups | V9: 4. Minibus, matatu | W9: 5. Medium bus | X9: 6. Large Bus | Y9: 7. Light Truck | Z9: 8. Medium Truck | AA9: 9. Heavy truck | AB9: 10. Truck Trailer | AC9: 11. Motorcycles | AD9: 12. Tractors, Graders | AE9: Total Excl M/ Cycles | AF9: Total All
B10: 07.00 - 07.15 | C10: 0 | D10: 0 | E10: 1 | F10: 0 | G10: 0 | H10: 0 | I10: 0 | J10: 0 | K10: 0 | L10: 0 | M10: 2 | N10: 0 | O10: =SUM(C10:L10,N10) -> 1 | P10: =SUM(C10:N10) -> 3 | R10: 0700-0800 | S10: =SUM(C10:C13) -> 0 | T10: =SUM(D10:D13) -> 1 | U10: =SUM(E10:E13) -> 4 | V10: =SUM(F10:F13) -> 0 | W10: =SUM(G10:G13) -> 0 | X10: =SUM(H10:H13) -> 0 | Y10: =SUM(I10:I13) -> 0 | Z10: =SUM(J10:J13) -> 0 | ... AF10: =SUM(P10:P13) -> 17
B11: 07.15 - 07.30 | C11: 0 | D11: 1 | E11: 2 | F11: 0 | G11: 0 | H11: 0 | I11: 0 | J11: 0 | K11: 1 | L11: 1 | M11: 3 | N11: 0 | O11: =SUM(C11:L11,N11) -> 5 | P11: =SUM(C11:N11) -> 8 | R11: 0800-0900 | S11: =SUM(C14:C17) -> 1 | T11: =SUM(D14:D17) -> 1 | U11: =SUM(E14:E17) -> 4 | V11: =SUM(F14:F17) -> 0 | W11: =SUM(G14:G17) -> 3 | X11: =SUM(H14:H17) -> 0 | Y11: =SUM(I14:I17) -> 4 | Z11: =SUM(J14:J17) -> 2 | ... AF11: =SUM(P14:P17) -> 53
B12: 07.30 - 07.45 | C12: 0 | D12: 0 | E12: 1 | F12: 0 | G12: 0 | H12: 0 | I12: 0 | J12: 0 | K12: 0 | L12: 0 | M12: 2 | N12: 0 | O12: =SUM(C12:L12,N12) -> 1 | P12: =SUM(C12:N12) -> 3 | R12: 0900-1000 | S12: =SUM(C18:C21) -> 6 | T12: =SUM(D18:D21) -> 0 | U12: =SUM(E18:E21) -> 5 | V12: =SUM(F18:F21) -> 0 | W12: =SUM(G18:G21) -> 5 | X12: =SUM(H18:H21) -> 0 | Y12: =SUM(I18:I21) -> 3 | Z12: =SUM(J18:J21) -> 1 | ... AF12: =SUM(P18:P21) -> 58
B13: 07.45 - 08.00 | C13: 0 | D13: 0 | E13: 0 | F13: 0 | G13: 0 | H13: 0 | I13: 0 | J13: 0 | K13: 1 | L13: 0 | M13: 2 | N13: 0 | O13: =SUM(C13:L13,N13) -> 1 | P13: =SUM(C13:N13) -> 3 | R13: 1000-1100 | S13: =SUM(C22:C25) -> 3 | T13: =SUM(D22:D25) -> 1 | U13: =SUM(E22:E25) -> 6 | V13: =SUM(F22:F25) -> 0 | W13: =SUM(G22:G25) -> 5 | X13: =SUM(H22:H25) -> 0 | Y13: =SUM(I22:I25) -> 3 | Z13: =SUM(J22:J25) -> 2 | ... AF13: =SUM(P22:P25) -> 37
B14: 08.00 - 08.15 | C14: 0 | D14: 0 | E14: 0 | F14: 0 | G14: 0 | H14: 0 | I14: 1 | J14: 0 | K14: 1 | L14: 3 | M14: 4 | N14: 0 | O14: =SUM(C14:L14,N14) -> 5 | P14: =SUM(C14:N14) -> 9 | R14: 1100-1200 | S14: =SUM(C26:C29) -> 4 | T14: =SUM(D26:D29) -> 5 | U14: =SUM(E26:E29) -> 13 | V14: =SUM(F26:F29) -> 1 | W14: =SUM(G26:G29) -> 12 | X14: =SUM(H26:H29) -> 1 | Y14: =SUM(I26:I29) -> 2 | Z14: =SUM(J26:J29) -> 3 | ... AF14: =SUM(P26:P29) -> 74
B15: 08.15 - 08.30 | C15: 0 | D15: 0 | E15: 1 | F15: 0 | G15: 1 | H15: 0 | I15: 2 | J15: 0 | K15: 1 | L15: 1 | M15: 7 | N15: 1 | O15: =SUM(C15:L15,N15) -> 7 | P15: =SUM(C15:N15) -> 14 | R15: 1200-1300 | S15: =SUM(C30:C33) -> 3 | T15: =SUM(D30:D33) -> 1 | U15: =SUM(E30:E33) -> 8 | V15: =SUM(F30:F33) -> 1 | W15: =SUM(G30:G33) -> 4 | X15: =SUM(H30:H33) -> 0 | Y15: =SUM(I30:I33) -> 0 | Z15: =SUM(J30:J33) -> 1 | ... AF15: =SUM(P30:P33) -> 31
B16: 08.30 - 08.45 | C16: 0 | D16: 0 | E16: 1 | F16: 0 | G16: 0 | H16: 0 | I16: 0 | J16: 0 | K16: 1 | L16: 5 | M16: 3 | N16: 3 | O16: =SUM(C16:L16,N16) -> 10 | P16: =SUM(C16:N16) -> 13 | R16: 1300-1400 | S16: =SUM(C34:C37) -> 0 | T16: =SUM(D34:D37) -> 1 | U16: =SUM(E34:E37) -> 5 | V16: =SUM(F34:F37) -> 0 | W16: =SUM(G34:G37) -> 2 | X16: =SUM(H34:H37) -> 0 | Y16: =SUM(I34:I37) -> 1 | Z16: =SUM(J34:J37) -> 0 | ... AF16: =SUM(P34:P37) -> 19
B17: 08.45 - 9.00 | C17: 1 | D17: 1 | E17: 2 | F17: 0 | G17: 2 | H17: 0 | I17: 1 | J17: 2 | K17: 0 | L17: 1 | M17: 7 | N17: 0 | O17: =SUM(C17:L17,N17) -> 10 | P17: =SUM(C17:N17) -> 17 | R17: 1400-1500 | S17: =SUM(C38:C41) -> 2 | T17: =SUM(D38:D41) -> 2 | U17: =SUM(E38:E41) -> 10 | V17: =SUM(F38:F41) -> 0 | W17: =SUM(G38:G41) -> 5 | X17: =SUM(H38:H41) -> 3 | Y17: =SUM(I38:I41) -> 3 | Z17: =SUM(J38:J41) -> 0 | ... AF17: =SUM(P38:P41) -> 44
B18: 09.00 - 09.15 | C18: 2 | D18: 0 | E18: 0 | F18: 0 | G18: 1 | H18: 0 | I18: 0 | J18: 0 | K18: 0 | L18: 3 | M18: 8 | N18: 2 | O18: =SUM(C18:L18,N18) -> 8 | P18: =SUM(C18:N18) -> 16 | R18: 1500-1600 | S18: =SUM(C42:C45) -> 1 | T18: =SUM(D42:D45) -> 1 | U18: =SUM(E42:E45) -> 8 | V18: =SUM(F42:F45) -> 1 | W18: =SUM(G42:G45) -> 4 | X18: =SUM(H42:H45) -> 1 | Y18: =SUM(I42:I45) -> 1 | Z18: =SUM(J42:J45) -> 2 | ... AF18: =SUM(P42:P45) -> 43
B19: 09.15 - 09.30 | C19: 0 | D19: 0 | E19: 2 | F19: 0 | G19: 2 | H19: 0 | I19: 0 | J19: 0 | K19: 0 | L19: 1 | M19: 11 | N19: 0 | O19: =SUM(C19:L19,N19) -> 5 | P19: =SUM(C19:N19) -> 16 | R19: 1600-1700 | S19: =SUM(C46:C49) -> 5 | T19: =SUM(D46:D49) -> 6 | U19: =SUM(E46:E49) -> 13 | V19: =SUM(F46:F49) -> 0 | W19: =SUM(G46:G49) -> 7 | X19: =SUM(H46:H49) -> 1 | Y19: =SUM(I46:I49) -> 2 | Z19: =SUM(J46:J49) -> 1 | ... AF19: =SUM(P46:P49) -> 51
B20: 09.30 - 09.45 | C20: 1 | D20: 0 | E20: 2 | F20: 0 | G20: 0 | H20: 0 | I20: 2 | J20: 1 | K20: 0 | L20: 0 | M20: 9 | N20: 0 | O20: =SUM(C20:L20,N20) -> 6 | P20: =SUM(C20:N20) -> 15 | R20: 1700-1800 | S20: =SUM(C50:C53) -> 2 | T20: =SUM(D50:D53) -> 6 | U20: =SUM(E50:E53) -> 16 | V20: =SUM(F50:F53) -> 2 | W20: =SUM(G50:G53) -> 6 | X20: =SUM(H50:H53) -> 4 | Y20: =SUM(I50:I53) -> 2 | Z20: =SUM(J50:J53) -> 4 | ... AF20: =SUM(P50:P53) -> 72
B21: 09.45 - 10.00 | C21: 3 | D21: 0 | E21: 1 | F21: 0 | G21: 2 | H21: 0 | I21: 1 | J21: 0 | K21: 0 | L21: 1 | M21: 3 | N21: 0 | O21: =SUM(C21:L21,N21) -> 8 | P21: =SUM(C21:N21) -> 11 | R21: 1800-1900 | S21: =SUM(C54:C57) -> 0 | T21: =SUM(D54:D57) -> 0 | U21: =SUM(E54:E57) -> 8 | V21: =SUM(F54:F57) -> 0 | W21: =SUM(G54:G57) -> 8 | X21: =SUM(H54:H57) -> 2 | Y21: =SUM(I54:I57) -> 2 | Z21: =SUM(J54:J57) -> 1 | ... AF21: =SUM(P54:P57) -> 45
B22: 10.00 - 10.15 | C22: 1 | D22: 1 | E22: 3 | F22: 0 | G22: 0 | H22: 0 | I22: 1 | J22: 0 | K22: 0 | L22: 0 | M22: 2 | N22: 0 | O22: =SUM(C22:L22,N22) -> 6 | P22: =SUM(C22:N22) -> 8 | R22: AM Peak Hr | S22: =MAX(S10:S12) -> 6 | T22: =MAX(T10:T12) -> 1 | U22: =MAX(U10:U12) -> 5 | V22: =MAX(V10:V12) -> 0 | W22: =MAX(W10:W12) -> 5 | X22: =MAX(X10:X12) -> 0 | Y22: =MAX(Y10:Y12) -> 4 | Z22: =MAX(Z10:Z12) -> 2 | ... AF22: =MAX(AF10:AF12) -> 58
B23: 10.15 - 10.30 | C23: 2 | D23: 0 | E23: 2 | F23: 0 | G23: 2 | H23: 0 | I23: 0 | J23: 0 | K23: 0 | L23: 0 | M23: 3 | N23: 0 | O23: =SUM(C23:L23,N23) -> 6 | P23: =SUM(C23:N23) -> 9 | R23: IP Peak Hr | S23: =MAX(S13:S18) -> 4 | T23: =MAX(T13:T18) -> 5 | U23: =MAX(U13:U18) -> 13 | V23: =MAX(V13:V18) -> 1 | W23: =MAX(W13:W18) -> 12 | X23: =MAX(X13:X18) -> 3 | Y23: =MAX(Y13:Y18) -> 3 | Z23: =MAX(Z13:Z18) -> 3 | ... AF23: =MAX(AF13:AF18) -> 74
B24: 10.30 - 10.45 | C24: 0 | D24: 0 | E24: 1 | F24: 0 | G24: 0 | H24: 0 | I24: 0 | J24: 0 | K24: 0 | L24: 0 | M24: 4 | N24: 0 | O24: =SUM(C24:L24,N24) -> 1 | P24: =SUM(C24:N24) -> 5 | R24: PM Peak Hr | S24: =MAX(S19:S21) -> 5 | T24: =MAX(T19:T21) -> 6 | U24: =MAX(U19:U21) -> 16 | V24: =MAX(V19:V21) -> 2 | W24: =MAX(W19:W21) -> 8 | X24: =MAX(X19:X21) -> 4 | Y24: =MAX(Y19:Y21) -> 2 | Z24: =MAX(Z19:Z21) -> 4 | ... AF24: =MAX(AF19:AF21) -> 72
B25: 10.45 - 11.00 | C25: 0 | D25: 0 | E25: 0 | F25: 0 | G25: 3 | H25: 0 | I25: 2 | J25: 2 | K25: 0 | L25: 2 | M25: 6 | N25: 0 | O25: =SUM(C25:L25,N25) -> 9 | P25: =SUM(C25:N25) -> 15 | R25: AM Period | S25: =SUM(S10:S12) -> 7 | T25: =SUM(T10:T12) -> 2 | U25: =SUM(U10:U12) -> 13 | V25: =SUM(V10:V12) -> 0 | W25: =SUM(W10:W12) -> 8 | X25: =SUM(X10:X12) -> 0 | Y25: =SUM(Y10:Y12) -> 7 | Z25: =SUM(Z10:Z12) -> 3 | ... AF25: =SUM(AF10:AF12) -> 128
B26: 11.00 - 11.15 | C26: 2 | D26: 1 | E26: 2 | F26: 0 | G26: 2 | H26: 0 | I26: 1 | J26: 0 | K26: 1 | L26: 0 | M26: 12 | N26: 1 | O26: =SUM(C26:L26,N26) -> 10 | P26: =SUM(C26:N26) -> 22 | R26: IP Period | S26: =SUM(S13:S18) -> 13 | T26: =SUM(T13:T18) -> 11 | U26: =SUM(U13:U18) -> 50 | V26: =SUM(V13:V18) -> 3 | W26: =SUM(W13:W18) -> 32 | X26: =SUM(X13:X18) -> 5 | Y26: =SUM(Y13:Y18) -> 10 | Z26: =SUM(Z13:Z18) -> 8 | ... AF26: =SUM(AF13:AF18) -> 248
B27: 11.15 - 11.30 | C27: 2 | D27: 2 | E27: 4 | F27: 1 | G27: 2 | H27: 0 | I27: 1 | J27: 0 | K27: 0 | L27: 1 | M27: 9 | N27: 0 | O27: =SUM(C27:L27,N27) -> 13 | P27: =SUM(C27:N27) -> 22 | R27: PM Period | S27: =SUM(S19:S21) -> 7 | T27: =SUM(T19:T21) -> 12 | U27: =SUM(U19:U21) -> 37 | V27: =SUM(V19:V21) -> 2 | W27: =SUM(W19:W21) -> 21 | X27: =SUM(X19:X21) -> 7 | Y27: =SUM(Y19:Y21) -> 6 | Z27: =SUM(Z19:Z21) -> 6 | ... AF27: =SUM(AF19:AF21) -> 168
B28: 11.30 - 11.45 | C28: 0 | D28: 1 | E28: 4 | F28: 0 | G28: 3 | H28: 0 | I28: 0 | J28: 0 | K28: 0 | L28: 1 | M28: 3 | N28: 0 | O28: =SUM(C28:L28,N28) -> 9 | P28: =SUM(C28:N28) -> 12 | R28: 12 Hours | S28: =SUM(S10:S21) -> 27 | T28: =SUM(T10:T21) -> 25 | U28: =SUM(U10:U21) -> 100 | V28: =SUM(V10:V21) -> 5 | W28: =SUM(W10:W21) -> 61 | X28: =SUM(X10:X21) -> 12 | Y28: =SUM(Y10:Y21) -> 23 | Z28: =SUM(Z10:Z21) -> 17 | ... AF28: =SUM(AF10:AF21) -> 544
B29: 11.45 - 12.00 | C29: 0 | D29: 1 | E29: 3 | F29: 0 | G29: 5 | H29: 1 | I29: 0 | J29: 3 | K29: 0 | L29: 0 | M29: 5 | N29: 0 | O29: =SUM(C29:L29,N29) -> 13 | P29: =SUM(C29:N29) -> 18
B30: 12.00 - 12.15 | C30: 0 | D30: 0 | E30: 2 | F30: 0 | G30: 0 | H30: 0 | I30: 0 | J30: 0 | K30: 0 | L30: 0 | M30: 4 | N30: 0 | O30: =SUM(C30:L30,N30) -> 2 | P30: =SUM(C30:N30) -> 6
B31: 12.15 - 12.30 | C31: 1 | D31: 0 | E31: 2 | F31: 1 | G31: 0 | H31: 0 | I31: 0 | J31: 0 | K31: 0 | L31: 0 | M31: 3 | N31: 0 | O31: =SUM(C31:L31,N31) -> 4 | P31: =SUM(C31:N31) -> 7
B32: 12.30 - 12.45 | C32: 1 | D32: 0 | E32: 2 | F32: 0 | G32: 1 | H32: 0 | I32: 0 | J32: 0 | K32: 0 | L32: 0 | M32: 2 | N32: 0 | O32: =SUM(C32:L32,N32) -> 4 | P32: =SUM(C32:N32) -> 6
B33: 12.45 - 13.00 | C33: 1 | D33: 1 | E33: 2 | F33: 0 | G33: 3 | H33: 0 | I33: 0 | J33: 1 | K33: 0 | L33: 0 | M33: 3 | N33: 1 | O33: =SUM(C33:L33,N33) -> 9 | P33: =SUM(C33:N33) -> 12
B34: 13.00 - 13.15 | C34: 0 | D34: 0 | E34: 1 | F34: 0 | G34: 1 | H34: 0 | I34: 0 | J34: 0 | K34: 0 | L34: 0 | M34: 5 | N34: 0 | O34: =SUM(C34:L34,N34) -> 2 | P34: =SUM(C34:N34) -> 7
B35: 13.15 - 13.30 | C35: 0 | D35: 0 | E35: 1 | F35: 0 | G35: 0 | H35: 0 | I35: 0 | J35: 0 | K35: 0 | L35: 0 | M35: 3 | N35: 0 | O35: =SUM(C35:L35,N35) -> 1 | P35: =SUM(C35:N35) -> 4
B36: 13.30 - 13.45 | C36: 0 | D36: 0 | E36: 1 | F36: 0 | G36: 0 | H36: 0 | I36: 0 | J36: 0 | K36: 0 | L36: 0 | M36: 0 | N36: 0 | O36: =SUM(C36:L36,N36) -> 1 | P36: =SUM(C36:N36) -> 1
B37: 13.45 - 14.00 | C37: 0 | D37: 1 | E37: 2 | F37: 0 | G37: 1 | H37: 0 | I37: 1 | J37: 0 | K37: 0 | L37: 0 | M37: 2 | N37: 0 | O37: =SUM(C37:L37,N37) -> 5 | P37: =SUM(C37:N37) -> 7
B38: 14.00 - 14.15 | C38: 1 | D38: 1 | E38: 3 | F38: 0 | G38: 1 | H38: 0 | I38: 0 | J38: 0 | K38: 0 | L38: 5 | M38: 4 | N38: 1 | O38: =SUM(C38:L38,N38) -> 12 | P38: =SUM(C38:N38) -> 16
B39: 14.15 - 14.30 | C39: 0 | D39: 0 | E39: 2 | F39: 0 | G39: 1 | H39: 1 | I39: 1 | J39: 0 | K39: 0 | L39: 1 | M39: 3 | N39: 0 | O39: =SUM(C39:L39,N39) -> 6 | P39: =SUM(C39:N39) -> 9
B40: 14.30 - 14.45 | C40: 0 | D40: 0 | E40: 2 | F40: 0 | G40: 0 | H40: 2 | I40: 1 | J40: 0 | K40: 0 | L40: 0 | M40: 2 | N40: 0 | O40: =SUM(C40:L40,N40) -> 5 | P40: =SUM(C40:N40) -> 7
... B57: 18.45 - 19.00 | C57: 0 | D57: 0 | E57: 2 | F57: 0 | G57: 1 | H57: 0 | I57: 0 | J57: 0 | K57: 0 | L57: 2 | M57: 3 | N57: 0 | O57: =SUM(C57:L57,N57) -> 5 | P57: =SUM(C57:N57) -> 8
B58: Totals | C58: =SUM(C10:C57) -> 27 | D58: =SUM(D10:D57) -> 25 | E58: =SUM(E10:E57) -> 100 | F58: =SUM(F10:F57) -> 5 | G58: =SUM(G10:G57) -> 61 | H58: =SUM(H10:H57) -> 12 | I58: =SUM(I10:I57) -> 23 | J58: =SUM(J10:J57) -> 17 | ... P58: =SUM(P10:P57) -> 544
...

Sheet 29.07 karuma-pakwach
B1: Consultancy services for Preparation of Expressway Development Master Plan (EDMP) for Uganda
B2: MANUAL CLASSIFIED COUNT (MCC)
B3: ROAD NAME: | C3: ='29.07 Pakwach-Karuma'!C3:G3 -> MCC - C5 - STN115 - KARUMA-PAKWACH ROAD
C5: Date | D5: 29.07.19 | F5: Location | G5: ='29.07 Pakwach-Karuma'!G5:H5 -> xxx | J5: Surveyor | K5: ='29.07 Pakwach-Karuma'!K5:L5 -> xxx
C6: Dir. From | D6: karuma | F6: Dir. To | G6: pakwach | J6: Supervisor | K6: ='29.07 Pakwach-Karuma'!K6:L6 -> xxx
B8: Time / Veh Type | R8: SUMMARY TRAFFIC VOLUMES
C9: 1. Car | D9: 2. Station Wagon | E9: 3. Pickups | F9: 4. Minibus, matatu | G9: 5. Medium bus | H9: 6. Large Bus | I9: 7. Light Truck | J9: 8. Medium Truck | K9: 9. Heavy truck | L9: 10. Truck Trailer | M9: 11. Motor cycles | N9: 12. Tractors | O9: Total Excl M/Cycles | P9: Total All | R9: Time | S9: 1. Car | T9: 2. Station Wagon | U9: 3. Pickups | V9: 4. Minibus, matatu | W9: 5. Medium bus | X9: 6. Large Bus | Y9: 7. Light Truck | Z9: 8. Medium Truck | AA9: 9. Heavy truck | AB9: 10. Truck Trailer | AC9: 11. Motorcycles | AD9: 12. Tractors, Graders | AE9: Total Excl M/ Cycles | AF9: Total All
B10: 07.00 - 07.15 | C10: 1 | D10: 0 | E10: 1 | F10: ='[1]RD115 MCC'!$J$48 -> 2 | G10: 0 | H10: 0 | I10: 0 | J10: 0 | K10: 0 | L10: 2 | M10: 1 | N10: 0 | O10: =SUM(C10:L10,N10) -> 6 | P10: =SUM(C10:N10) -> 7 | R10: 0700-0800 | S10: =SUM(C10:C13) -> 2 | T10: =SUM(D10:D13) -> 0 | U10: =SUM(E10:E13) -> 2 | V10: =SUM(F10:F13) -> 2 | W10: =SUM(G10:G13) -> 0 | X10: =SUM(H10:H13) -> 0 | Y10: =SUM(I10:I13) -> 0 | Z10: =SUM(J10:J13) -> 0 | ... AF10: =SUM(P10:P13) -> 15
B11: 07.15 - 07.30 | C11: 0 | D11: 0 | E11: 0 | F11: 0 | G11: 0 | H11: 0 | I11: 0 | J11: 0 | K11: 0 | L11: 0 | M11: 3 | N11: 0 | O11: =SUM(C11:L11,N11) -> 0 | P11: =SUM(C11:N11) -> 3 | R11: 0800-0900 | S11: =SUM(C14:C17) -> 2 | T11: =SUM(D14:D17) -> 0 | U11: =SUM(E14:E17) -> 5 | V11: =SUM(F14:F17) -> 0 | W11: =SUM(G14:G17) -> 5 | X11: =SUM(H14:H17) -> 1 | Y11: =SUM(I14:I17) -> 1 | Z11: =SUM(J14:J17) -> 0 | ... AF11: =SUM(P14:P17) -> 34
B12: 07.30 - 07.45 | C12: 1 | D12: 0 | E12: 0 | F12: 0 | G12: 0 | H12: 0 | I12: 0 | J12: 0 | K12: 0 | L12: 0 | M12: 2 | N12: 0 | O12: =SUM(C12:L12,N12) -> 1 | P12: =SUM(C12:N12) -> 3 | R12: 0900-1000 | S12: =SUM(C18:C21) -> 1 | T12: =SUM(D18:D21) -> 0 | U12: =SUM(E18:E21) -> 3 | V12: =SUM(F18:F21) -> 0 | W12: =SUM(G18:G21) -> 5 | X12: =SUM(H18:H21) -> 2 | Y12: =SUM(I18:I21) -> 0 | Z12: =SUM(J18:J21) -> 0 | ... AF12: =SUM(P18:P21) -> 24
B13: 07.45 - 08.00 | C13: 0 | D13: 0 | E13: 1 | F13: 0 | G13: 0 | H13: 0 | I13: 0 | J13: 0 | K13: 0 | L13: 0 | M13: 1 | N13: 0 | O13: =SUM(C13:L13,N13) -> 1 | P13: =SUM(C13:N13) -> 2 | R13: 1000-1100 | S13: =SUM(C22:C25) -> 3 | T13: =SUM(D22:D25) -> 1 | U13: =SUM(E22:E25) -> 7 | V13: =SUM(F22:F25) -> 0 | W13: =SUM(G22:G25) -> 11 | X13: =SUM(H22:H25) -> 4 | Y13: =SUM(I22:I25) -> 2 | Z13: =SUM(J22:J25) -> 2 | ... AF13: =SUM(P22:P25) -> 40
B14: 08.00 - 08.15 | C14: 0 | D14: 0 | E14: 2 | F14: 0 | G14: 0 | H14: 0 | I14: 0 | J14: 0 | K14: 0 | L14: 2 | M14: 2 | N14: 0 | O14: =SUM(C14:L14,N14) -> 4 | P14: =SUM(C14:N14) -> 6 | R14: 1100-1200 | S14: =SUM(C26:C29) -> 2 | T14: =SUM(D26:D29) -> 0 | U14: =SUM(E26:E29) -> 7 | V14: =SUM(F26:F29) -> 0 | W14: =SUM(G26:G29) -> 8 | X14: =SUM(H26:H29) -> 0 | Y14: =SUM(I26:I29) -> 7 | Z14: =SUM(J26:J29) -> 2 | ... AF14: =SUM(P26:P29) -> 51
B15: 08.15 - 08.30 | C15: 2 | D15: 0 | E15: 0 | F15: 0 | G15: 0 | H15: 0 | I15: 0 | J15: 0 | K15: 0 | L15: 0 | M15: 4 | N15: 0 | O15: =SUM(C15:L15,N15) -> 2 | P15: =SUM(C15:N15) -> 6 | R15: 1200-1300 | S15: =SUM(C30:C33) -> 2 | T15: =SUM(D30:D33) -> 0 | U15: =SUM(E30:E33) -> 4 | V15: =SUM(F30:F33) -> 0 | W15: =SUM(G30:G33) -> 3 | X15: =SUM(H30:H33) -> 4 | Y15: =SUM(I30:I33) -> 0 | Z15: =SUM(J30:J33) -> 1 | ... AF15: =SUM(P30:P33) -> 19
B16: 08.30 - 08.45 | C16: 0 | D16: 0 | E16: 1 | F16: 0 | G16: 0 | H16: 0 | I16: 1 | J16: 0 | K16: 0 | L16: 0 | M16: 4 | N16: 1 | O16: =SUM(C16:L16,N16) -> 3 | P16: =SUM(C16:N16) -> 7 | R16: 1300-1400 | S16: =SUM(C34:C37) -> 5 | T16: =SUM(D34:D37) -> 0 | U16: =SUM(E34:E37) -> 2 | V16: =SUM(F34:F37) -> 0 | W16: =SUM(G34:G37) -> 1 | X16: =SUM(H34:H37) -> 0 | Y16: =SUM(I34:I37) -> 0 | Z16: =SUM(J34:J37) -> 0 | ... AF16: =SUM(P34:P37) -> 23
B17: 08.45 - 9.00 | C17: 0 | D17: 0 | E17: 2 | F17: 0 | G17: 5 | H17: 1 | I17: 0 | J17: 0 | K17: 0 | L17: 1 | M17: 6 | N17: 0 | O17: =SUM(C17:L17,N17) -> 9 | P17: =SUM(C17:N17) -> 15 | R17: 1400-1500 | S17: =SUM(C38:C41) -> 2 | T17: =SUM(D38:D41) -> 1 | U17: =SUM(E38:E41) -> 8 | V17: =SUM(F38:F41) -> 0 | W17: =SUM(G38:G41) -> 2 | X17: =SUM(H38:H41) -> 2 | Y17: =SUM(I38:I41) -> 2 | Z17: =SUM(J38:J41) -> 0 | ... AF17: =SUM(P38:P41) -> 39
B18: 09.00 - 09.15 | C18: 0 | D18: 0 | E18: 0 | F18: 0 | G18: 0 | H18: 0 | I18: 0 | J18: 0 | K18: 0 | L18: 1 | M18: 0 | N18: 0 | O18: =SUM(C18:L18,N18) -> 1 | P18: =SUM(C18:N18) -> 1 | R18: 1500-1600 | S18: =SUM(C42:C45) -> 1 | T18: =SUM(D42:D45) -> 0 | U18: =SUM(E42:E45) -> 4 | V18: =SUM(F42:F45) -> 0 | W18: =SUM(G42:G45) -> 3 | X18: =SUM(H42:H45) -> 3 | Y18: =SUM(I42:I45) -> 2 | Z18: =SUM(J42:J45) -> 3 | ... AF18: =SUM(P42:P45) -> 48
B19: 09.15 - 09.30 | C19: 1 | D19: 0 | E19: 0 | F19: 0 | G19: 0 | H19: 0 | I19: 0 | J19: 0 | K19: 0 | L19: 2 | M19: 2 | N19: 0 | O19: =SUM(C19:L19,N19) -> 3 | P19: =SUM(C19:N19) -> 5 | R19: 1600-1700 | S19: =SUM(C46:C49) -> 0 | T19: =SUM(D46:D49) -> 0 | U19: =SUM(E46:E49) -> 2 | V19: =SUM(F46:F49) -> 0 | W19: =SUM(G46:G49) -> 4 | X19: =SUM(H46:H49) -> 0 | Y19: =SUM(I46:I49) -> 1 | Z19: =SUM(J46:J49) -> 2 | ... AF19: =SUM(P46:P49) -> 26
B20: 09.30 - 09.45 | C20: 0 | D20: 0 | E20: 1 | F20: 0 | G20: 0 | H20: 1 | I20: 0 | J20: 0 | K20: 0 | L20: 0 | M20: 4 | N20: 0 | O20: =SUM(C20:L20,N20) -> 2 | P20: =SUM(C20:N20) -> 6 | R20: 1700-1800 | S20: =SUM(C50:C53) -> 2 | T20: =SUM(D50:D53) -> 0 | U20: =SUM(E50:E53) -> 5 | V20: =SUM(F50:F53) -> 0 | W20: =SUM(G50:G53) -> 4 | X20: =SUM(H50:H53) -> 0 | Y20: =SUM(I50:I53) -> 0 | Z20: =SUM(J50:J53) -> 1 | ... AF20: =SUM(P50:P53) -> 23
B21: 09.45 - 10.00 | C21: 0 | D21: 0 | E21: 2 | F21: 0 | G21: 5 | H21: 1 | I21: 0 | J21: 0 | K21: 0 | L21: 0 | M21: 4 | N21: 0 | O21: =SUM(C21:L21,N21) -> 8 | P21: =SUM(C21:N21) -> 12 | R21: 1800-1900 | S21: =SUM(C54:C57) -> 2 | T21: =SUM(D54:D57) -> 0 | U21: =SUM(E54:E57) -> 3 | V21: =SUM(F54:F57) -> 0 | W21: =SUM(G54:G57) -> 1 | X21: =SUM(H54:H57) -> 0 | Y21: =SUM(I54:I57) -> 3 | Z21: =SUM(J54:J57) -> 0 | ... AF21: =SUM(P54:P57) -> 27
B22: 10.00 - 10.15 | C22: 1 | D22: 0 | E22: 2 | F22: 0 | G22: 2 | H22: 0 | I22: 0 | J22: 0 | K22: 0 | L22: 0 | M22: 2 | N22: 0 | O22: =SUM(C22:L22,N22) -> 5 | P22: =SUM(C22:N22) -> 7 | R22: AM Peak Hr | S22: =MAX(S10:S12) -> 2 | T22: =MAX(T10:T12) -> 0 | U22: =MAX(U10:U12) -> 5 | V22: =MAX(V10:V12) -> 2 | W22: =MAX(W10:W12) -> 5 | X22: =MAX(X10:X12) -> 2 | Y22: =MAX(Y10:Y12) -> 1 | Z22: =MAX(Z10:Z12) -> 0 | ... AF22: =MAX(AF10:AF12) -> 34
B23: 10.15 - 10.30 | C23: 2 | D23: 1 | E23: 4 | F23: 0 | G23: 3 | H23: 1 | I23: 0 | J23: 0 | K23: 1 | L23: 0 | M23: 3 | N23: 0 | O23: =SUM(C23:L23,N23) -> 12 | P23: =SUM(C23:N23) -> 15 | R23: IP Peak Hr | S23: =MAX(S13:S18) -> 5 | T23: =MAX(T13:T18) -> 1 | U23: =MAX(U13:U18) -> 8 | V23: =MAX(V13:V18) -> 0 | W23: =MAX(W13:W18) -> 11 | X23: =MAX(X13:X18) -> 4 | Y23: =MAX(Y13:Y18) -> 7 | Z23: =MAX(Z13:Z18) -> 3 | ... AF23: =MAX(AF13:AF18) -> 51
B24: 10.30 - 10.45 | C24: 0 | D24: 0 | E24: 1 | F24: 0 | G24: 5 | H24: 3 | I24: 2 | J24: 2 | K24: 1 | L24: 1 | M24: 2 | N24: 0 | O24: =SUM(C24:L24,N24) -> 15 | P24: =SUM(C24:N24) -> 17 | R24: PM Peak Hr | S24: =MAX(S19:S21) -> 2 | T24: =MAX(T19:T21) -> 0 | U24: =MAX(U19:U21) -> 5 | V24: =MAX(V19:V21) -> 0 | W24: =MAX(W19:W21) -> 4 | X24: =MAX(X19:X21) -> 0 | Y24: =MAX(Y19:Y21) -> 3 | Z24: =MAX(Z19:Z21) -> 2 | ... AF24: =MAX(AF19:AF21) -> 27
B25: 10.45 - 11.00 | C25: 0 | D25: 0 | E25: 0 | F25: 0 | G25: 1 | H25: 0 | I25: 0 | J25: 0 | K25: 0 | L25: 0 | M25: 0 | N25: 0 | O25: =SUM(C25:L25,N25) -> 1 | P25: =SUM(C25:N25) -> 1 | R25: AM Period | S25: =SUM(S10:S12) -> 5 | T25: =SUM(T10:T12) -> 0 | U25: =SUM(U10:U12) -> 10 | V25: =SUM(V10:V12) -> 2 | W25: =SUM(W10:W12) -> 10 | X25: =SUM(X10:X12) -> 3 | Y25: =SUM(Y10:Y12) -> 1 | Z25: =SUM(Z10:Z12) -> 0 | ... AF25: =SUM(AF10:AF12) -> 73
B26: 11.00 - 11.15 | C26: 0 | D26: 0 | E26: 2 | F26: 0 | G26: 4 | H26: 0 | I26: 1 | J26: 0 | K26: 0 | L26: 2 | M26: 2 | N26: 0 | O26: =SUM(C26:L26,N26) -> 9 | P26: =SUM(C26:N26) -> 11 | R26: IP Period | S26: =SUM(S13:S18) -> 15 | T26: =SUM(T13:T18) -> 2 | U26: =SUM(U13:U18) -> 32 | V26: =SUM(V13:V18) -> 0 | W26: =SUM(W13:W18) -> 28 | X26: =SUM(X13:X18) -> 13 | Y26: =SUM(Y13:Y18) -> 13 | Z26: =SUM(Z13:Z18) -> 8 | ... AF26: =SUM(AF13:AF18) -> 220
B27: 11.15 - 11.30 | C27: 0 | D27: 0 | E27: 1 | F27: 0 | G27: 3 | H27: 0 | I27: 3 | J27: 1 | K27: 0 | L27: 1 | M27: 3 | N27: 1 | O27: =SUM(C27:L27,N27) -> 10 | P27: =SUM(C27:N27) -> 13 | R27: PM Period | S27: =SUM(S19:S21) -> 4 | T27: =SUM(T19:T21) -> 0 | U27: =SUM(U19:U21) -> 10 | V27: =SUM(V19:V21) -> 0 | W27: =SUM(W19:W21) -> 9 | X27: =SUM(X19:X21) -> 0 | Y27: =SUM(Y19:Y21) -> 4 | Z27: =SUM(Z19:Z21) -> 3 | ... AF27: =SUM(AF19:AF21) -> 76
B28: 11.30 - 11.45 | C28: 2 | D28: 0 | E28: 2 | F28: 0 | G28: 1 | H28: 0 | I28: 0 | J28: 0 | K28: 0 | L28: 1 | M28: 5 | N28: 0 | O28: =SUM(C28:L28,N28) -> 6 | P28: =SUM(C28:N28) -> 11 | R28: 12 Hours | S28: =SUM(S10:S21) -> 24 | T28: =SUM(T10:T21) -> 2 | U28: =SUM(U10:U21) -> 52 | V28: =SUM(V10:V21) -> 2 | W28: =SUM(W10:W21) -> 47 | X28: =SUM(X10:X21) -> 16 | Y28: =SUM(Y10:Y21) -> 18 | Z28: =SUM(Z10:Z21) -> 11 | ... AF28: =SUM(AF10:AF21) -> 369
B29: 11.45 - 12.00 | C29: 0 | D29: 0 | E29: 2 | F29: 0 | G29: 0 | H29: 0 | I29: 3 | J29: 1 | K29: 0 | L29: 0 | M29: 10 | N29: 0 | O29: =SUM(C29:L29,N29) -> 6 | P29: =SUM(C29:N29) -> 16
B30: 12.00 - 12.15 | C30: 1 | D30: 0 | E30: 0 | F30: 0 | G30: 0 | H30: 0 | I30: 0 | J30: 0 | K30: 0 | L30: 0 | M30: 0 | N30: 0 | O30: =SUM(C30:L30,N30) -> 1 | P30: =SUM(C30:N30) -> 1
B31: 12.15 - 12.30 | C31: 0 | D31: 0 | E31: 1 | F31: 0 | G31: 0 | H31: 2 | I31: 0 | J31: 0 | K31: 0 | L31: 0 | M31: 0 | N31: 0 | O31: =SUM(C31:L31,N31) -> 3 | P31: =SUM(C31:N31) -> 3
B32: 12.30 - 12.45 | C32: 1 | D32: 0 | E32: 1 | F32: 0 | G32: 2 | H32: 0 | I32: 0 | J32: 0 | K32: 0 | L32: 0 | M32: 2 | N32: 0 | O32: =SUM(C32:L32,N32) -> 4 | P32: =SUM(C32:N32) -> 6
B33: 12.45 - 13.00 | C33: 0 | D33: 0 | E33: 2 | F33: 0 | G33: 1 | H33: 2 | I33: 0 | J33: 1 | K33: 0 | L33: 1 | M33: 2 | N33: 0 | O33: =SUM(C33:L33,N33) -> 7 | P33: =SUM(C33:N33) -> 9
B34: 13.00 - 13.15 | C34: 2 | D34: 0 | E34: 0 | F34: 0 | G34: 0 | H34: 0 | I34: 0 | J34: 0 | K34: 0 | L34: 0 | M34: 9 | N34: 0 | O34: =SUM(C34:L34,N34) -> 2 | P34: =SUM(C34:N34) -> 11
B35: 13.15 - 13.30 | C35: 1 | D35: 0 | E35: 0 | F35: 0 | G35: 0 | H35: 0 | I35: 0 | J35: 0 | K35: 0 | L35: 0 | M35: 1 | N35: 0 | O35: =SUM(C35:L35,N35) -> 1 | P35: =SUM(C35:N35) -> 2
B36: 13.30 - 13.45 | C36: 2 | D36: 0 | E36: 0 | F36: 0 | G36: 0 | H36: 0 | I36: 0 | J36: 0 | K36: 0 | L36: 0 | M36: 3 | N36: 0 | O36: =SUM(C36:L36,N36) -> 2 | P36: =SUM(C36:N36) -> 5
B37: 13.45 - 14.00 | C37: 0 | D37: 0 | E37: 2 | F37: 0 | G37: 1 | H37: 0 | I37: 0 | J37: 0 | K37: 0 | L37: 0 | M37: 2 | N37: 0 | O37: =SUM(C37:L37,N37) -> 3 | P37: =SUM(C37:N37) -> 5
B38: 14.00 - 14.15 | C38: 1 | D38: 1 | E38: 4 | F38: 0 | G38: 0 | H38: 1 | I38: 0 | J38: 0 | K38: 0 | L38: 2 | M38: 7 | N38: 1 | O38: =SUM(C38:L38,N38) -> 10 | P38: =SUM(C38:N38) -> 17
B39: 14.15 - 14.30 | C39: 0 | D39: 0 | E39: 1 | F39: 0 | G39: 0 | H39: 1 | I39: 0 | J39: 0 | K39: 2 | L39: 0 | M39: 4 | N39: 0 | O39: =SUM(C39:L39,N39) -> 4 | P39: =SUM(C39:N39) -> 8
B40: 14.30 - 14.45 | C40: 1 | D40: 0 | E40: 2 | F40: 0 | G40: 1 | H40: 0 | I40: 1 | J40: 0 | K40: 0 | L40: 0 | M40: 3 | N40: 0 | O40: =SUM(C40:L40,N40) -> 5 | P40: =SUM(C40:N40) -> 8
... B57: 18.45 - 19.00 | C57: 1 | D57: 0 | E57: 2 | F57: 0 | G57: 1 | H57: 0 | I57: 0 | J57: 0 | K57: 0 | L57: 1 | M57: 6 | N57: 0 | O57: =SUM(C57:L57,N57) -> 5 | P57: =SUM(C57:N57) -> 11
B58: Totals | C58: 0 | D58: =SUM(D10:D57) -> 2 | E58: 0 | F58: =SUM(F10:F57) -> 2 | G58: 0 | H58: 0 | I58: 0 | J58: 0 | K58: 0 | L58: =SUM(L10:L57) -> 37 | M58: 0 | N58: 0 | O58: =SUM(O10:O57) -> 234 | P58: =SUM(P10:P57) -> 369
...

Sheet 30.07.19 pakwach-karuma
B1: Consultancy services for Preparation of Expressway Development Master Plan (EDMP) for Uganda
B2: MANUAL CLASSIFIED COUNT (MCC)
B3: ROAD NAME: | C3: ='29.07 Pakwach-Karuma'!C3:G3 -> MCC - C5 - STN115 - KARUMA-PAKWACH ROAD
C5: Date | D5: 30.07.19 | F5: Location | G5: ='29.07 Pakwach-Karuma'!G5:H5 -> xxx | J5: Surveyor | K5: ='29.07 Pakwach-Karuma'!K5:L5 -> xxx
C6: Dir. From | D6: pakwach | F6: Dir. To | G6: karuma | J6: Supervisor | K6: ='29.07 Pakwach-Karuma'!K6:L6 -> xxx
B8: Time / Veh Type | R8: SUMMARY TRAFFIC VOLUMES
C9: 1. Car | D9: 2. Station Wagon | E9: 3. Pickups | F9: 4. Minibus, matatu | G9: 5. Medium bus | H9: 6. Large Bus | I9: 7. Light Truck | J9: 8. Medium Truck | K9: 9. Heavy truck | L9: 10. Truck Trailer | M9: 11. Motor cycles | N9: 12. Tractors | O9: Total Excl M/Cycles | P9: Total All | R9: Time | S9: 1. Car | T9: 2. Station Wagon | U9: 3. Pickups | V9: 4. Minibus, matatu | W9: 5. Medium bus | X9: 6. Large Bus | Y9: 7. Light Truck | Z9: 8. Medium Truck | AA9: 9. Heavy truck | AB9: 10. Truck Trailer | AC9: 11. Motorcycles | AD9: 12. Tractors, Graders | AE9: Total Excl M/ Cycles | AF9: Total All
B10: 07.00 - 07.15 | C10: 3 | D10: 1 | E10: 4 | F10: 0 | G10: 0 | H10: 0 | I10: 2 | J10: 0 | K10: 0 | L10: 2 | M10: 6 | N10: 1 | O10: =SUM(C10:L10,N10) -> 13 | P10: =SUM(C10:N10) -> 19 | R10: 0700-0800 | S10: =SUM(C10:C13) -> 4 | T10: =SUM(D10:D13) -> 3 | U10: =SUM(E10:E13) -> 12 | V10: =SUM(F10:F13) -> 3 | W10: =SUM(G10:G13) -> 0 | X10: =SUM(H10:H13) -> 0 | Y10: =SUM(I10:I13) -> 2 | Z10: =SUM(J10:J13) -> 6 | ... AF10: =SUM(P10:P13) -> 62
B11: 07.15 - 07.30 | C11: 1 | D11: 0 | E11: 0 | F11: 0 | G11: 0 | H11: 0 | I11: 0 | J11: 1 | K11: 2 | L11: 3 | M11: 7 | N11: 0 | O11: =SUM(C11:L11,N11) -> 7 | P11: =SUM(C11:N11) -> 14 | R11: 0800-0900 | S11: =SUM(C14:C17) -> 1 | T11: =SUM(D14:D17) -> 2 | U11: =SUM(E14:E17) -> 8 | V11: =SUM(F14:F17) -> 4 | W11: =SUM(G14:G17) -> 0 | X11: =SUM(H14:H17) -> 0 | Y11: =SUM(I14:I17) -> 3 | Z11: =SUM(J14:J17) -> 6 | ... AF11: =SUM(P14:P17) -> 40
B12: 07.30 - 07.45 | C12: 0 | D12: 0 | E12: 2 | F12: 3 | G12: 0 | H12: 0 | I12: 0 | J12: 3 | K12: 0 | L12: 3 | M12: 3 | N12: 2 | O12: =SUM(C12:L12,N12) -> 13 | P12: =SUM(C12:N12) -> 16 | R12: 0900-1000 | S12: =SUM(C18:C21) -> 1 | T12: =SUM(D18:D21) -> 0 | U12: =SUM(E18:E21) -> 3 | V12: =SUM(F18:F21) -> 4 | W12: =SUM(G18:G21) -> 0 | X12: =SUM(H18:H21) -> 1 | Y12: =SUM(I18:I21) -> 0 | Z12: =SUM(J18:J21) -> 2 | ... AF12: =SUM(P18:P21) -> 30
B13: 07.45 - 08.00 | C13: 0 | D13: 2 | E13: 6 | F13: 0 | G13: 0 | H13: 0 | I13: 0 | J13: 2 | K13: 0 | L13: 0 | M13: 3 | N13: 0 | O13: =SUM(C13:L13,N13) -> 10 | P13: =SUM(C13:N13) -> 13 | R13: 1000-1100 | S13: =SUM(C22:C25) -> 2 | T13: =SUM(D22:D25) -> 0 | U13: =SUM(E22:E25) -> 6 | V13: =SUM(F22:F25) -> 7 | W13: =SUM(G22:G25) -> 0 | X13: =SUM(H22:H25) -> 0 | Y13: =SUM(I22:I25) -> 0 | Z13: =SUM(J22:J25) -> 4 | ... AF13: =SUM(P22:P25) -> 44
B14: 08.00 - 08.15 | C14: 0 | D14: 0 | E14: 0 | F14: 0 | G14: 0 | H14: 0 | I14: 1 | J14: 3 | K14: 1 | L14: 1 | M14: 0 | N14: 1 | O14: =SUM(C14:L14,N14) -> 7 | P14: =SUM(C14:N14) -> 7 | R14: 1100-1200 | S14: =SUM(C26:C29) -> 0 | T14: =SUM(D26:D29) -> 1 | U14: =SUM(E26:E29) -> 7 | V14: =SUM(F26:F29) -> 7 | W14: =SUM(G26:G29) -> 0 | X14: =SUM(H26:H29) -> 0 | Y14: =SUM(I26:I29) -> 3 | Z14: =SUM(J26:J29) -> 1 | ... AF14: =SUM(P26:P29) -> 46
B15: 08.15 - 08.30 | C15: 0 | D15: 1 | E15: 3 | F15: 2 | G15: 0 | H15: 0 | I15: 2 | J15: 2 | K15: 0 | L15: 0 | M15: 3 | N15: 0 | O15: =SUM(C15:L15,N15) -> 10 | P15: =SUM(C15:N15) -> 13 | R15: 1200-1300 | S15: =SUM(C30:C33) -> 1 | T15: =SUM(D30:D33) -> 1 | U15: =SUM(E30:E33) -> 11 | V15: =SUM(F30:F33) -> 6 | W15: =SUM(G30:G33) -> 0 | X15: =SUM(H30:H33) -> 2 | Y15: =SUM(I30:I33) -> 0 | Z15: =SUM(J30:J33) -> 1 | ... AF15: =SUM(P30:P33) -> 43
B16: 08.30 - 08.45 | C16: 1 | D16: 1 | E16: 3 | F16: 2 | G16: 0 | H16: 0 | I16: 0 | J16: 0 | K16: 0 | L16: 2 | M16: 2 | N16: 1 | O16: =SUM(C16:L16,N16) -> 10 | P16: =SUM(C16:N16) -> 12 | R16: 1300-1400 | S16: =SUM(C34:C37) -> 5 | T16: =SUM(D34:D37) -> 0 | U16: =SUM(E34:E37) -> 4 | V16: =SUM(F34:F37) -> 6 | W16: =SUM(G34:G37) -> 0 | X16: =SUM(H34:H37) -> 0 | Y16: =SUM(I34:I37) -> 2 | Z16: =SUM(J34:J37) -> 0 | ... AF16: =SUM(P34:P37) -> 37
B17: 08.45 - 9.00 | C17: 0 | D17: 0 | E17: 2 | F17: 0 | G17: 0 | H17: 0 | I17: 0 | J17: 1 | K17: 0 | L17: 0 | M17: 4 | N17: 1 | O17: =SUM(C17:L17,N17) -> 4 | P17: =SUM(C17:N17) -> 8 | R17: 1400-1500 | S17: =SUM(C38:C41) -> 3 | T17: =SUM(D38:D41) -> 1 | U17: =SUM(E38:E41) -> 7 | V17: =SUM(F38:F41) -> 5 | W17: =SUM(G38:G41) -> 1 | X17: =SUM(H38:H41) -> 4 | Y17: =SUM(I38:I41) -> 0 | Z17: =SUM(J38:J41) -> 2 | ... AF17: =SUM(P38:P41) -> 42
B18: 09.00 - 09.15 | C18: 1 | D18: 0 | E18: 1 | F18: 0 | G18: 0 | H18: 0 | I18: 0 | J18: 0 | K18: 0 | L18: 0 | M18: 1 | N18: 0 | O18: =SUM(C18:L18,N18) -> 2 | P18: =SUM(C18:N18) -> 3 | R18: 1500-1600 | S18: =SUM(C42:C45) -> 4 | T18: =SUM(D42:D45) -> 0 | U18: =SUM(E42:E45) -> 6 | V18: =SUM(F42:F45) -> 2 | W18: =SUM(G42:G45) -> 0 | X18: =SUM(H42:H45) -> 1 | Y18: =SUM(I42:I45) -> 1 | Z18: =SUM(J42:J45) -> 0 | ... AF18: =SUM(P42:P45) -> 31
B19: 09.15 - 09.30 | C19: 0 | D19: 0 | E19: 2 | F19: 0 | G19: 0 | H19: 1 | I19: 0 | J19: 0 | K19: 0 | L19: 0 | M19: 9 | N19: 0 | O19: =SUM(C19:L19,N19) -> 3 | P19: =SUM(C19:N19) -> 12 | R19: 1600-1700 | S19: =SUM(C46:C49) -> 0 | T19: =SUM(D46:D49) -> 1 | U19: =SUM(E46:E49) -> 7 | V19: =SUM(F46:F49) -> 10 | W19: =SUM(G46:G49) -> 0 | X19: =SUM(H46:H49) -> 2 | Y19: =SUM(I46:I49) -> 3 | Z19: =SUM(J46:J49) -> 1 | ... AF19: =SUM(P46:P49) -> 50
B20: 09.30 - 09.45 | C20: 0 | D20: 0 | E20: 0 | F20: 2 | G20: 0 | H20: 0 | I20: 0 | J20: 1 | K20: 0 | L20: 1 | M20: 2 | N20: 0 | O20: =SUM(C20:L20,N20) -> 4 | P20: =SUM(C20:N20) -> 6 | R20: 1700-1800 | S20: =SUM(C50:C53) -> 6 | T20: =SUM(D50:D53) -> 2 | U20: =SUM(E50:E53) -> 9 | V20: =SUM(F50:F53) -> 5 | W20: =SUM(G50:G53) -> 0 | X20: =SUM(H50:H53) -> 3 | Y20: =SUM(I50:I53) -> 2 | Z20: =SUM(J50:J53) -> 3 | ... AF20: =SUM(P50:P53) -> 41
B21: 09.45 - 10.00 | C21: 0 | D21: 0 | E21: 0 | F21: 2 | G21: 0 | H21: 0 | I21: 0 | J21: 1 | K21: 0 | L21: 0 | M21: 6 | N21: 0 | O21: =SUM(C21:L21,N21) -> 3 | P21: =SUM(C21:N21) -> 9 | R21: 1800-1900 | S21: =SUM(C54:C57) -> 1 | T21: =SUM(D54:D57) -> 3 | U21: =SUM(E54:E57) -> 13 | V21: =SUM(F54:F57) -> 3 | W21: =SUM(G54:G57) -> 0 | X21: =SUM(H54:H57) -> 2 | Y21: =SUM(I54:I57) -> 2 | Z21: =SUM(J54:J57) -> 1 | ... AF21: =SUM(P54:P57) -> 44
B22: 10.00 - 10.15 | C22: 1 | D22: 0 | E22: 2 | F22: 1 | G22: 0 | H22: 0 | I22: 0 | J22: 0 | K22: 1 | L22: 2 | M22: 6 | N22: 0 | O22: =SUM(C22:L22,N22) -> 7 | P22: =SUM(C22:N22) -> 13 | R22: AM Peak Hr | S22: =MAX(S10:S12) -> 4 | T22: =MAX(T10:T12) -> 3 | U22: =MAX(U10:U12) -> 12 | V22: =MAX(V10:V12) -> 4 | W22: =MAX(W10:W12) -> 0 | X22: =MAX(X10:X12) -> 1 | Y22: =MAX(Y10:Y12) -> 3 | Z22: =MAX(Z10:Z12) -> 6 | ... AF22: =MAX(AF10:AF12) -> 62
B23: 10.15 - 10.30 | C23: 0 | D23: 0 | E23: 2 | F23: 2 | G23: 0 | H23: 0 | I23: 0 | J23: 0 | K23: 0 | L23: 2 | M23: 2 | N23: 0 | O23: =SUM(C23:L23,N23) -> 6 | P23: =SUM(C23:N23) -> 8 | R23: IP Peak Hr | S23: =MAX(S13:S18) -> 5 | T23: =MAX(T13:T18) -> 1 | U23: =MAX(U13:U18) -> 11 | V23: =MAX(V13:V18) -> 7 | W23: =MAX(W13:W18) -> 1 | X23: =MAX(X13:X18) -> 4 | Y23: =MAX(Y13:Y18) -> 3 | Z23: =MAX(Z13:Z18) -> 4 | ... AF23: =MAX(AF13:AF18) -> 46
B24: 10.30 - 10.45 | C24: 1 | D24: 0 | E24: 2 | F24: 2 | G24: 0 | H24: 0 | I24: 0 | J24: 4 | K24: 0 | L24: 0 | M24: 9 | N24: 0 | O24: =SUM(C24:L24,N24) -> 9 | P24: =SUM(C24:N24) -> 18 | R24: PM Peak Hr | S24: =MAX(S19:S21) -> 6 | T24: =MAX(T19:T21) -> 3 | U24: =MAX(U19:U21) -> 13 | V24: =MAX(V19:V21) -> 10 | W24: =MAX(W19:W21) -> 0 | X24: =MAX(X19:X21) -> 3 | Y24: =MAX(Y19:Y21) -> 3 | Z24: =MAX(Z19:Z21) -> 3 | ... AF24: =MAX(AF19:AF21) -> 50
B25: 10.45 - 11.00 | C25: 0 | D25: 0 | E25: 0 | F25: 2 | G25: 0 | H25: 0 | I25: 0 | J25: 0 | K25: 0 | L25: 0 | M25: 3 | N25: 0 | O25: =SUM(C25:L25,N25) -> 2 | P25: =SUM(C25:N25) -> 5 | R25: AM Period | S25: =SUM(S10:S12) -> 6 | T25: =SUM(T10:T12) -> 5 | U25: =SUM(U10:U12) -> 23 | V25: =SUM(V10:V12) -> 11 | W25: =SUM(W10:W12) -> 0 | X25: =SUM(X10:X12) -> 1 | Y25: =SUM(Y10:Y12) -> 5 | Z25: =SUM(Z10:Z12) -> 14 | ... AF25: =SUM(AF10:AF12) -> 132
B26: 11.00 - 11.15 | C26: 0 | D26: 0 | E26: 0 | F26: 3 | G26: 0 | H26: 0 | I26: 1 | J26: 0 | K26: 0 | L26: 1 | M26: 6 | N26: 0 | O26: =SUM(C26:L26,N26) -> 5 | P26: =SUM(C26:N26) -> 11 | R26: IP Period | S26: =SUM(S13:S18) -> 15 | T26: =SUM(T13:T18) -> 3 | U26: =SUM(U13:U18) -> 41 | V26: =SUM(V13:V18) -> 33 | W26: =SUM(W13:W18) -> 1 | X26: =SUM(X13:X18) -> 7 | Y26: =SUM(Y13:Y18) -> 6 | Z26: =SUM(Z13:Z18) -> 8 | ... AF26: =SUM(AF13:AF18) -> 243
B27: 11.15 - 11.30 | C27: 0 | D27: 0 | E27: 1 | F27: 2 | G27: 0 | H27: 0 | I27: 0 | J27: 0 | K27: 0 | L27: 1 | M27: 6 | N27: 1 | O27: =SUM(C27:L27,N27) -> 5 | P27: =SUM(C27:N27) -> 11 | R27: PM Period | S27: =SUM(S19:S21) -> 7 | T27: =SUM(T19:T21) -> 6 | U27: =SUM(U19:U21) -> 29 | V27: =SUM(V19:V21) -> 18 | W27: =SUM(W19:W21) -> 0 | X27: =SUM(X19:X21) -> 7 | Y27: =SUM(Y19:Y21) -> 7 | Z27: =SUM(Z19:Z21) -> 5 | ... AF27: =SUM(AF19:AF21) -> 135
B28: 11.30 - 11.45 | C28: 0 | D28: 0 | E28: 2 | F28: 1 | G28: 0 | H28: 0 | I28: 0 | J28: 0 | K28: 0 | L28: 0 | M28: 4 | N28: 0 | O28: =SUM(C28:L28,N28) -> 3 | P28: =SUM(C28:N28) -> 7 | R28: 12 Hours | S28: =SUM(S10:S21) -> 28 | T28: =SUM(T10:T21) -> 14 | U28: =SUM(U10:U21) -> 93 | V28: =SUM(V10:V21) -> 62 | W28: =SUM(W10:W21) -> 1 | X28: =SUM(X10:X21) -> 15 | Y28: =SUM(Y10:Y21) -> 18 | Z28: =SUM(Z10:Z21) -> 27 | ... AF28: =SUM(AF10:AF21) -> 510
B29: 11.45 - 12.00 | C29: 0 | D29: 1 | E29: 4 | F29: 1 | G29: 0 | H29: 0 | I29: 2 | J29: 1 | K29: 0 | L29: 0 | M29: 8 | N29: 0 | O29: =SUM(C29:L29,N29) -> 9 | P29: =SUM(C29:N29) -> 17
B30: 12.00 - 12.15 | C30: 0 | D30: 0 | E30: 2 | F30: 2 | G30: 0 | H30: 0 | I30: 0 | J30: 0 | K30: 0 | L30: 0 | M30: 5 | N30: 0 | O30: =SUM(C30:L30,N30) -> 4 | P30: =SUM(C30:N30) -> 9
B31: 12.15 - 12.30 | C31: 1 | D31: 0 | E31: 2 | F31: 0 | G31: 0 | H31: 0 | I31: 0 | J31: 1 | K31: 0 | L31: 0 | M31: 7 | N31: 0 | O31: =SUM(C31:L31,N31) -> 4 | P31: =SUM(C31:N31) -> 11
B32: 12.30 - 12.45 | C32: 0 | D32: 1 | E32: 5 | F32: 2 | G32: 0 | H32: 1 | I32: 0 | J32: 0 | K32: 0 | L32: 1 | M32: 6 | N32: 0 | O32: =SUM(C32:L32,N32) -> 10 | P32: =SUM(C32:N32) -> 16
B33: 12.45 - 13.00 | C33: 0 | D33: 0 | E33: 2 | F33: 2 | G33: 0 | H33: 1 | I33: 0 | J33: 0 | K33: 0 | L33: 0 | M33: 2 | N33: 0 | O33: =SUM(C33:L33,N33) -> 5 | P33: =SUM(C33:N33) -> 7
B34: 13.00 - 13.15 | C34: 3 | D34: 0 | E34: 2 | F34: 1 | G34: 0 | H34: 0 | I34: 2 | J34: 0 | K34: 0 | L34: 2 | M34: 5 | N34: 0 | O34: =SUM(C34:L34,N34) -> 10 | P34: =SUM(C34:N34) -> 15
B35: 13.15 - 13.30 | C35: 1 | D35: 0 | E35: 0 | F35: 1 | G35: 0 | H35: 0 | I35: 0 | J35: 0 | K35: 0 | L35: 0 | M35: 5 | N35: 0 | O35: =SUM(C35:L35,N35) -> 2 | P35: =SUM(C35:N35) -> 7
B36: 13.30 - 13.45 | C36: 1 | D36: 0 | E36: 1 | F36: 2 | G36: 0 | H36: 0 | I36: 0 | J36: 0 | K36: 0 | L36: 0 | M36: 4 | N36: 0 | O36: =SUM(C36:L36,N36) -> 4 | P36: =SUM(C36:N36) -> 8
B37: 13.45 - 14.00 | C37: 0 | D37: 0 | E37: 1 | F37: 2 | G37: 0 | H37: 0 | I37: 0 | J37: 0 | K37: 1 | L37: 0 | M37: 3 | N37: 0 | O37: =SUM(C37:L37,N37) -> 4 | P37: =SUM(C37:N37) -> 7
B38: 14.00 - 14.15 | C38: 0 | D38: 0 | E38: 1 | F38: 0 | G38: 0 | H38: 0 | I38: 0 | J38: 0 | K38: 1 | L38: 0 | M38: 2 | N38: 0 | O38: =SUM(C38:L38,N38) -> 2 | P38: =SUM(C38:N38) -> 4
B39: 14.15 - 14.30 | C39: 0 | D39: 1 | E39: 3 | F39: 2 | G39: 0 | H39: 0 | I39: 0 | J39: 0 | K39: 0 | L39: 0 | M39: 1 | N39: 0 | O39: =SUM(C39:L39,N39) -> 6 | P39: =SUM(C39:N39) -> 7
B40: 14.30 - 14.45 | C40: 2 | D40: 0 | E40: 2 | F40: 1 | G40: 1 | H40: 4 | I40: 0 | J40: 1 | K40: 0 | L40: 1 | M40: 8 | N40: 0 | O40: =SUM(C40:L40,N40) -> 12 | P40: =SUM(C40:N40) -> 20
... B57: 18.45 - 19.00 | C57: 0 | D57: 2 | E57: 6 | F57: 1 | G57: 0 | H57: 0 | I57: 1 | J57: 0 | K57: 1 | L57: 0 | M57: 2 | N57: 0 | O57: =SUM(C57:L57,N57) -> 11 | P57: =SUM(C57:N57) -> 13
B58: Totals | C58: 0 | D58: =SUM(D10:D57) -> 14 | E58: 0 | F58: 0 | G58: 0 | H58: 0 | I58: 0 | J58: 0 | K58: 0 | L58: =SUM(L10:L57) -> 31 | M58: 0 | N58: 0 | O58: =SUM(O10:O57) -> 309 | P58: =SUM(P10:P57) -> 510
...

Sheet 30.07 karuma-pakwach
B1: Consultancy services for Preparation of Expressway Development Master Plan (EDMP) for Uganda
B2: MANUAL CLASSIFIED COUNT (MCC)
B3: ROAD NAME: | C3: ='29.07 karuma-pakwach'!C3:G3 -> MCC - C5 - STN115 - KARUMA-PAKWACH ROAD
C5: Date | D5: 30.07.19 | F5: Location | G5: ='29.07 Pakwach-Karuma'!G5:H5 -> xxx | J5: Surveyor | K5: ='29.07 Pakwach-Karuma'!K5:L5 -> xxx
C6: Dir. From | D6: karuma | F6: Dir. To | G6: pakwach | J6: Supervisor | K6: ='29.07 Pakwach-Karuma'!K6:L6 -> xxx
B8: Time / Veh Type | R8: SUMMARY TRAFFIC VOLUMES
C9: 1. Car | D9: 2. Station Wagon | E9: 3. Pickups | F9: 4. Minibus, matatu | G9: 5. Medium bus | H9: 6. Large Bus | I9: 7. Light Truck | J9: 8. Medium Truck | K9: 9. Heavy truck | L9: 10. Truck Trailer | M9: 11. Motor cycles | N9: 12. Tractors | O9: Total Excl M/Cycles | P9: Total All | R9: Time | S9: 1. Car | T9: 2. Station Wagon | U9: 3. Pickups | V9: 4. Minibus, matatu | W9: 5. Medium bus | X9: 6. Large Bus | Y9: 7. Light Truck | Z9: 8. Medium Truck | AA9: 9. Heavy truck | AB9: 10. Truck Trailer | AC9: 11. Motorcycles | AD9: 12. Tractors, Graders | AE9: Total Excl M/ Cycles | AF9: Total All
B10: 07.00 - 07.15 | C10: 2 | D10: 0 | E10: 0 | F10: 0 | G10: 0 | H10: 0 | I10: 0 | J10: 0 | K10: 0 | L10: 1 | M10: 3 | N10: 0 | O10: =SUM(C10:L10,N10) -> 3 | P10: =SUM(C10:N10) -> 6 | R10: 0700-0800 | S10: =SUM(C10:C13) -> 3 | T10: =SUM(D10:D13) -> 0 | U10: =SUM(E10:E13) -> 0 | V10: =SUM(F10:F13) -> 1 | W10: =SUM(G10:G13) -> 0 | X10: =SUM(H10:H13) -> 1 | Y10: =SUM(I10:I13) -> 3 | Z10: =SUM(J10:J13) -> 0 | ... AF10: =SUM(P10:P13) -> 22
B11: 07.15 - 07.30 | C11: 0 | D11: 0 | E11: 0 | F11: 0 | G11: 0 | H11: 1 | I11: 2 | J11: 0 | K11: 0 | L11: 1 | M11: 1 | N11: 0 | O11: =SUM(C11:L11,N11) -> 4 | P11: =SUM(C11:N11) -> 5 | R11: 0800-0900 | S11: =SUM(C14:C17) -> 0 | T11: =SUM(D14:D17) -> 0 | U11: =SUM(E14:E17) -> 3 | V11: =SUM(F14:F17) -> 1 | W11: =SUM(G14:G17) -> 0 | X11: =SUM(H14:H17) -> 0 | Y11: =SUM(I14:I17) -> 0 | Z11: =SUM(J14:J17) -> 1 | ... AF11: =SUM(P14:P17) -> 22
B12: 07.30 - 07.45 | C12: 0 | D12: 0 | E12: 0 | F12: 0 | G12: 0 | H12: 0 | I12: 0 | J12: 0 | K12: 0 | L12: 3 | M12: 1 | N12: 1 | O12: =SUM(C12:L12,N12) -> 4 | P12: =SUM(C12:N12) -> 5 | R12: 0900-1000 | S12: =SUM(C18:C21) -> 0 | T12: =SUM(D18:D21) -> 0 | U12: =SUM(E18:E21) -> 2 | V12: =SUM(F18:F21) -> 3 | W12: =SUM(G18:G21) -> 0 | X12: =SUM(H18:H21) -> 1 | Y12: =SUM(I18:I21) -> 1 | Z12: =SUM(J18:J21) -> 0 | ... AF12: =SUM(P18:P21) -> 21
B13: 07.45 - 08.00 | C13: 1 | D13: 0 | E13: 0 | F13: 1 | G13: 0 | H13: 0 | I13: 1 | J13: 0 | K13: 0 | L13: 0 | M13: 3 | N13: 0 | O13: =SUM(C13:L13,N13) -> 3 | P13: =SUM(C13:N13) -> 6 | R13: 1000-1100 | S13: =SUM(C22:C25) -> 2 | T13: =SUM(D22:D25) -> 0 | U13: =SUM(E22:E25) -> 4 | V13: =SUM(F22:F25) -> 2 | W13: =SUM(G22:G25) -> 0 | X13: =SUM(H22:H25) -> 3 | Y13: =SUM(I22:I25) -> 5 | Z13: =SUM(J22:J25) -> 0 | ... AF13: =SUM(P22:P25) -> 26
B14: 08.00 - 08.15 | C14: 0 | D14: 0 | E14: 0 | F14: 0 | G14: 0 | H14: 0 | I14: 0 | J14: 1 | K14: 0 | L14: 2 | M14: 2 | N14: 0 | O14: =SUM(C14:L14,N14) -> 3 | P14: =SUM(C14:N14) -> 5 | R14: 1100-1200 | S14: =SUM(C26:C29) -> 3 | T14: =SUM(D26:D29) -> 0 | U14: =SUM(E26:E29) -> 1 | V14: =SUM(F26:F29) -> 2 | W14: =SUM(G26:G29) -> 1 | X14: =SUM(H26:H29) -> 3 | Y14: =SUM(I26:I29) -> 1 | Z14: =SUM(J26:J29) -> 3 | ... AF14: =SUM(P26:P29) -> 31
B15: 08.15 - 08.30 | C15: 0 | D15: 0 | E15: 2 | F15: 0 | G15: 0 | H15: 0 | I15: 0 | J15: 0 | K15: 0 | L15: 3 | M15: 2 | N15: 1 | O15: =SUM(C15:L15,N15) -> 6 | P15: =SUM(C15:N15) -> 8 | R15: 1200-1300 | S15: =SUM(C30:C33) -> 3 | T15: =SUM(D30:D33) -> 0 | U15: =SUM(E30:E33) -> 4 | V15: =SUM(F30:F33) -> 4 | W15: =SUM(G30:G33) -> 2 | X15: =SUM(H30:H33) -> 0 | Y15: =SUM(I30:I33) -> 3 | Z15: =SUM(J30:J33) -> 1 | ... AF15: =SUM(P30:P33) -> 39
B16: 08.30 - 08.45 | C16: 0 | D16: 0 | E16: 1 | F16: 1 | G16: 0 | H16: 0 | I16: 0 | J16: 0 | K16: 0 | L16: 1 | M16: 4 | N16: 0 | O16: =SUM(C16:L16,N16) -> 3 | P16: =SUM(C16:N16) -> 7 | R16: 1300-1400 | S16: =SUM(C34:C37) -> 4 | T16: =SUM(D34:D37) -> 1 | U16: =SUM(E34:E37) -> 5 | V16: =SUM(F34:F37) -> 2 | W16: =SUM(G34:G37) -> 0 | X16: =SUM(H34:H37) -> 2 | Y16: =SUM(I34:I37) -> 4 | Z16: =SUM(J34:J37) -> 0 | ... AF16: =SUM(P34:P37) -> 30
B17: 08.45 - 9.00 | C17: 0 | D17: 0 | E17: 0 | F17: 0 | G17: 0 | H17: 0 | I17: 0 | J17: 0 | K17: 0 | L17: 1 | M17: 1 | N17: 0 | O17: =SUM(C17:L17,N17) -> 1 | P17: =SUM(C17:N17) -> 2 | R17: 1400-1500 | S17: =SUM(C38:C41) -> 3 | T17: =SUM(D38:D41) -> 0 | U17: =SUM(E38:E41) -> 3 | V17: =SUM(F38:F41) -> 1 | W17: =SUM(G38:G41) -> 0 | X17: =SUM(H38:H41) -> 1 | Y17: =SUM(I38:I41) -> 1 | Z17: =SUM(J38:J41) -> 1 | ... AF17: =SUM(P38:P41) -> 15
B18: 09.00 - 09.15 | C18: 0 | D18: 0 | E18: 1 | F18: 1 | G18: 0 | H18: 0 | I18: 0 | J18: 0 | K18: 0 | L18: 0 | M18: 3 | N18: 0 | O18: =SUM(C18:L18,N18) -> 2 | P18: =SUM(C18:N18) -> 5 | R18: 1500-1600 | S18: =SUM(C42:C45) -> 5 | T18: =SUM(D42:D45) -> 1 | U18: =SUM(E42:E45) -> 5 | V18: =SUM(F42:F45) -> 3 | W18: =SUM(G42:G45) -> 0 | X18: =SUM(H42:H45) -> 2 | Y18: =SUM(I42:I45) -> 7 | Z18: =SUM(J42:J45) -> 1 | ... AF18: =SUM(P42:P45) -> 46
B19: 09.15 - 09.30 | C19: 0 | D19: 0 | E19: 1 | F19: 1 | G19: 0 | H19: 1 | I19: 1 | J19: 0 | K19: 0 | L19: 0 | M19: 2 | N19: 0 | O19: =SUM(C19:L19,N19) -> 4 | P19: =SUM(C19:N19) -> 6 | R19: 1600-1700 | S19: =SUM(C46:C49) -> 2 | T19: =SUM(D46:D49) -> 0 | U19: =SUM(E46:E49) -> 3 | V19: =SUM(F46:F49) -> 2 | W19: =SUM(G46:G49) -> 0 | X19: =SUM(H46:H49) -> 1 | Y19: =SUM(I46:I49) -> 4 | Z19: =SUM(J46:J49) -> 0 | ... AF19: =SUM(P46:P49) -> 26
B20: 09.30 - 09.45 | C20: 0 | D20: 0 | E20: 0 | F20: 1 | G20: 0 | H20: 0 | I20: 0 | J20: 0 | K20: 0 | L20: 0 | M20: 2 | N20: 0 | O20: =SUM(C20:L20,N20) -> 1 | P20: =SUM(C20:N20) -> 3 | R20: 1700-1800 | S20: =SUM(C50:C53) -> 7 | T20: =SUM(D50:D53) -> 1 | U20: =SUM(E50:E53) -> 4 | V20: =SUM(F50:F53) -> 4 | W20: =SUM(G50:G53) -> 1 | X20: =SUM(H50:H53) -> 0 | Y20: =SUM(I50:I53) -> 0 | Z20: =SUM(J50:J53) -> 1 | ... AF20: =SUM(P50:P53) -> 31
B21: 09.45 - 10.00 | C21: 0 | D21: 0 | E21: 0 | F21: 0 | G21: 0 | H21: 0 | I21: 0 | J21: 0 | K21: 0 | L21: 0 | M21: 7 | N21: 0 | O21: =SUM(C21:L21,N21) -> 0 | P21: =SUM(C21:N21) -> 7 | R21: 1800-1900 | S21: =SUM(C54:C57) -> 1 | T21: =SUM(D54:D57) -> 1 | U21: =SUM(E54:E57) -> 2 | V21: =SUM(F54:F57) -> 0 | W21: =SUM(G54:G57) -> 0 | X21: =SUM(H54:H57) -> 0 | Y21: =SUM(I54:I57) -> 3 | Z21: =SUM(J54:J57) -> 0 | ... AF21: =SUM(P54:P57) -> 19
B22: 10.00 - 10.15 | C22: 0 | D22: 0 | E22: 0 | F22: 1 | G22: 0 | H22: 1 | I22: 1 | J22: 0 | K22: 0 | L22: 1 | M22: 4 | N22: 0 | O22: =SUM(C22:L22,N22) -> 4 | P22: =SUM(C22:N22) -> 8 | R22: AM Peak Hr | S22: =MAX(S10:S12) -> 3 | T22: =MAX(T10:T12) -> 0 | U22: =MAX(U10:U12) -> 3 | V22: =MAX(V10:V12) -> 3 | W22: =MAX(W10:W12) -> 0 | X22: =MAX(X10:X12) -> 1 | Y22: =MAX(Y10:Y12) -> 3 | Z22: =MAX(Z10:Z12) -> 1 | ... AF22: =MAX(AF10:AF12) -> 22
B23: 10.15 - 10.30 | C23: 2 | D23: 0 | E23: 2 | F23: 1 | G23: 0 | H23: 1 | I23: 2 | J23: 0 | K23: 0 | L23: 0 | M23: 0 | N23: 0 | O23: =SUM(C23:L23,N23) -> 8 | P23: =SUM(C23:N23) -> 8 | R23: IP Peak Hr | S23: =MAX(S13:S18) -> 5 | T23: =MAX(T13:T18) -> 1 | U23: =MAX(U13:U18) -> 5 | V23: =MAX(V13:V18) -> 4 | W23: =MAX(W13:W18) -> 2 | X23: =MAX(X13:X18) -> 3 | Y23: =MAX(Y13:Y18) -> 7 | Z23: =MAX(Z13:Z18) -> 3 | ... AF23: =MAX(AF13:AF18) -> 46
B24: 10.30 - 10.45 | C24: 0 | D24: 0 | E24: 0 | F24: 0 | G24: 0 | H24: 0 | I24: 0 | J24: 0 | K24: 0 | L24: 0 | M24: 1 | N24: 0 | O24: =SUM(C24:L24,N24) -> 0 | P24: =SUM(C24:N24) -> 1 | R24: PM Peak Hr | S24: =MAX(S19:S21) -> 7 | T24: =MAX(T19:T21) -> 1 | U24: =MAX(U19:U21) -> 4 | V24: =MAX(V19:V21) -> 4 | W24: =MAX(W19:W21) -> 1 | X24: =MAX(X19:X21) -> 1 | Y24: =MAX(Y19:Y21) -> 4 | Z24: =MAX(Z19:Z21) -> 1 | ... AF24: =MAX(AF19:AF21) -> 31
B25: 10.45 - 11.00 | C25: 0 | D25: 0 | E25: 2 | F25: 0 | G25: 0 | H25: 1 | I25: 2 | J25: 0 | K25: 0 | L25: 1 | M25: 3 | N25: 0 | O25: =SUM(C25:L25,N25) -> 6 | P25: =SUM(C25:N25) -> 9 | R25: AM Period | S25: =SUM(S10:S12) -> 3 | T25: =SUM(T10:T12) -> 0 | U25: =SUM(U10:U12) -> 5 | V25: =SUM(V10:V12) -> 5 | W25: =SUM(W10:W12) -> 0 | X25: =SUM(X10:X12) -> 2 | Y25: =SUM(Y10:Y12) -> 4 | Z25: =SUM(Z10:Z12) -> 1 | ... AF25: =SUM(AF10:AF12) -> 65
B26: 11.00 - 11.15 | C26: 0 | D26: 0 | E26: 0 | F26: 0 | G26: 0 | H26: 1 | I26: 0 | J26: 1 | K26: 0 | L26: 2 | M26: 6 | N26: 0 | O26: =SUM(C26:L26,N26) -> 4 | P26: =SUM(C26:N26) -> 10 | R26: IP Period | S26: =SUM(S13:S18) -> 20 | T26: =SUM(T13:T18) -> 2 | U26: =SUM(U13:U18) -> 22 | V26: =SUM(V13:V18) -> 14 | W26: =SUM(W13:W18) -> 3 | X26: =SUM(X13:X18) -> 11 | Y26: =SUM(Y13:Y18) -> 21 | Z26: =SUM(Z13:Z18) -> 6 | ... AF26: =SUM(AF13:AF18) -> 187
B27: 11.15 - 11.30 | C27: 0 | D27: 0 | E27: 1 | F27: 0 | G27: 0 | H27: 2 | I27: 0 | J27: 0 | K27: 0 | L27: 1 | M27: 2 | N27: 0 | O27: =SUM(C27:L27,N27) -> 4 | P27: =SUM(C27:N27) -> 6 | R27: PM Period | S27: =SUM(S19:S21) -> 10 | T27: =SUM(T19:T21) -> 2 | U27: =SUM(U19:U21) -> 9 | V27: =SUM(V19:V21) -> 6 | W27: =SUM(W19:W21) -> 1 | X27: =SUM(X19:X21) -> 1 | Y27: =SUM(Y19:Y21) -> 7 | Z27: =SUM(Z19:Z21) -> 1 | ... AF27: =SUM(AF19:AF21) -> 76
B28: 11.30 - 11.45 | C28: 1 | D28: 0 | E28: 0 | F28: 0 | G28: 0 | H28: 0 | I28: 0 | J28: 1 | K28: 0 | L28: 0 | M28: 3 | N28: 0 | O28: =SUM(C28:L28,N28) -> 2 | P28: =SUM(C28:N28) -> 5 | R28: 12 Hours | S28: =SUM(S10:S21) -> 33 | T28: =SUM(T10:T21) -> 4 | U28: =SUM(U10:U21) -> 36 | V28: =SUM(V10:V21) -> 25 | W28: =SUM(W10:W21) -> 4 | X28: =SUM(X10:X21) -> 14 | Y28: =SUM(Y10:Y21) -> 32 | Z28: =SUM(Z10:Z21) -> 8 | ... AF28: =SUM(AF10:AF21) -> 328
B29: 11.45 - 12.00 | C29: 2 | D29: 0 | E29: 0 | F29: 2 | G29: 1 | H29: 0 | I29: 1 | J29: 1 | K29: 0 | L29: 0 | M29: 3 | N29: 0 | O29: =SUM(C29:L29,N29) -> 7 | P29: =SUM(C29:N29) -> 10
B30: 12.00 - 12.15 | C30: 1 | D30: 0 | E30: 0 | F30: 1 | G30: 0 | H30: 0 | I30: 0 | J30: 0 | K30: 0 | L30: 2 | M30: 3 | N30: 0 | O30: =SUM(C30:L30,N30) -> 4 | P30: =SUM(C30:N30) -> 7
B31: 12.15 - 12.30 | C31: 0 | D31: 0 | E31: 1 | F31: 0 | G31: 0 | H31: 0 | I31: 0 | J31: 1 | K31: 0 | L31: 0 | M31: 1 | N31: 0 | O31: =SUM(C31:L31,N31) -> 2 | P31: =SUM(C31:N31) -> 3
B32: 12.30 - 12.45 | C32: 1 | D32: 0 | E32: 2 | F32: 2 | G32: 1 | H32: 0 | I32: 2 | J32: 0 | K32: 0 | L32: 0 | M32: 8 | N32: 1 | O32: =SUM(C32:L32,N32) -> 9 | P32: =SUM(C32:N32) -> 17
B33: 12.45 - 13.00 | C33: 1 | D33: 0 | E33: 1 | F33: 1 | G33: 1 | H33: 0 | I33: 1 | J33: 0 | K33: 0 | L33: 2 | M33: 4 | N33: 1 | O33: =SUM(C33:L33,N33) -> 8 | P33: =SUM(C33:N33) -> 12
B34: 13.00 - 13.15 | C34: 0 | D34: 0 | E34: 0 | F34: 0 | G34: 0 | H34: 0 | I34: 1 | J34: 0 | K34: 0 | L34: 0 | M34: 2 | N34: 0 | O34: =SUM(C34:L34,N34) -> 1 | P34: =SUM(C34:N34) -> 3
B35: 13.15 - 13.30 | C35: 4 | D35: 0 | E35: 1 | F35: 2 | G35: 0 | H35: 1 | I35: 2 | J35: 0 | K35: 0 | L35: 2 | M35: 1 | N35: 0 | O35: =SUM(C35:L35,N35) -> 12 | P35: =SUM(C35:N35) -> 13
B36: 13.30 - 13.45 | C36: 0 | D36: 0 | E36: 2 | F36: 0 | G36: 0 | H36: 1 | I36: 0 | J36: 0 | K36: 0 | L36: 2 | M36: 2 | N36: 0 | O36: =SUM(C36:L36,N36) -> 5 | P36: =SUM(C36:N36) -> 7
B37: 13.45 - 14.00 | C37: 0 | D37: 1 | E37: 2 | F37: 0 | G37: 0 | H37: 0 | I37: 1 | J37: 0 | K37: 0 | L37: 1 | M37: 1 | N37: 1 | O37: =SUM(C37:L37,N37) -> 6 | P37: =SUM(C37:N37) -> 7
B38: 14.00 - 14.15 | C38: 1 | D38: 0 | E38: 2 | F38: 0 | G38: 0 | H38: 0 | I38: 0 | J38: 1 | K38: 0 | L38: 0 | M38: 1 | N38: 0 | O38: =SUM(C38:L38,N38) -> 4 | P38: =SUM(C38:N38) -> 5
B39: 14.15 - 14.30 | C39: 0 | D39: 0 | E39: 0 | F39: 0 | G39: 0 | H39: 0 | I39: 1 | J39: 0 | K39: 0 | L39: 1 | M39: 1 | N39: 0 | O39: =SUM(C39:L39,N39) -> 2 | P39: =SUM(C39:N39) -> 3
B40: 14.30 - 14.45 | C40: 0 | D40: 0 | E40: 0 | F40: 1 | G40: 0 | H40: 0 | I40: 0 | J40: 0 | K40: 0 | L40: 0 | M40: 0 | N40: 0 | O40: =SUM(C40:L40,N40) -> 1 | P40: =SUM(C40:N40) -> 1
... B57: 18.45 - 19.00 | C57: 0 | D57: 0 | E57: 0 | F57: 0 | G57: 0 | H57: 0 | I57: 0 | J57: 0 | K57: 0 | L57: 0 | M57: 0 | N57: 0 | O57: =SUM(C57:L57,N57) -> 0 | P57: =SUM(C57:N57) -> 0
B58: Totals | C58: 0 | D58: =SUM(D10:D57) -> 4 | E58: 0 | F58: 0 | G58: 0 | H58: 0 | I58: 0 | J58: 0 | K58: 0 | L58: =SUM(L10:L57) -> 36 | M58: 0 | N58: 0 | O58: =SUM(O10:O57) -> 207 | P58: =SUM(P10:P57) -> 328
...

Sheet 31.07 pakwach-karuma
B1: Consultancy services for Preparation of Expressway Development Master Plan (EDMP) for Uganda
B2: MANUAL CLASSIFIED COUNT (MCC)
B3: ROAD NAME: | C3: ='29.07 Pakwach-Karuma'!C3:G3 -> MCC - C5 - STN115 - KARUMA-PAKWACH ROAD
C5: Date | D5: 31.07.19 | F5: Location | G5: ='29.07 Pakwach-Karuma'!G5:H5 -> xxx | J5: Surveyor | K5: ='29.07 Pakwach-Karuma'!K5:L5 -> xxx
C6: Dir. From | D6: pakwach | F6: Dir. To | G6: karuma | J6: Supervisor | K6: ='29.07 Pakwach-Karuma'!K6:L6 -> xxx
B8: Time / Veh Type | R8: SUMMARY TRAFFIC VOLUMES
C9: 1. Car | D9: 2. Station Wagon | E9: 3. Pickups | F9: 4. Minibus, matatu | G9: 5. Medium bus | H9: 6. Large Bus | I9: 7. Light Truck | J9: 8. Medium Truck | K9: 9. Heavy truck | L9: 10. Truck Trailer | M9: 11. Motor cycles | N9: 12. Tractors | O9: Total Excl M/Cycles | P9: Total All | R9: Time | S9: 1. Car | T9: 2. Station Wagon | U9: 3. Pickups | V9: 4. Minibus, matatu | W9: 5. Medium bus | X9: 6. Large Bus | Y9: 7. Light Truck | Z9: 8. Medium Truck | AA9: 9. Heavy truck | AB9: 10. Truck Trailer | AC9: 11. Motorcycles | AD9: 12. Tractors, Graders | AE9: Total Excl M/ Cycles | AF9: Total All
B10: 07.00 - 07.15 | C10: 1 | D10: 0 | E10: 2 | F10: 0 | G10: 0 | H10: 0 | I10: 0 | J10: 0 | K10: 0 | L10: 0 | M10: 3 | N10: 0 | O10: =SUM(C10:L10,N10) -> 3 | P10: =SUM(C10:N10) -> 6 | R10: 0700-0800 | S10: =SUM(C10:C13) -> 2 | T10: =SUM(D10:D13) -> 0 | U10: =SUM(E10:E13) -> 7 | V10: =SUM(F10:F13) -> 2 | W10: =SUM(G10:G13) -> 1 | X10: =SUM(H10:H13) -> 0 | Y10: =SUM(I10:I13) -> 0 | Z10: =SUM(J10:J13) -> 1 | ... AF10: =SUM(P10:P13) -> 26
B11: 07.15 - 07.30 | C11: 1 | D11: 0 | E11: 2 | F11: 2 | G11: 0 | H11: 0 | I11: 0 | J11: 0 | K11: 0 | L11: 0 | M11: 1 | N11: 0 | O11: =SUM(C11:L11,N11) -> 5 | P11: =SUM(C11:N11) -> 6 | R11: 0800-0900 | S11: =SUM(C14:C17) -> 11 | T11: =SUM(D14:D17) -> 1 | U11: =SUM(E14:E17) -> 5 | V11: =SUM(F14:F17) -> 0 | W11: =SUM(G14:G17) -> 0 | X11: =SUM(H14:H17) -> 0 | Y11: =SUM(I14:I17) -> 3 | Z11: =SUM(J14:J17) -> 3 | ... AF11: =SUM(P14:P17) -> 43
B12: 07.30 - 07.45 | C12: 0 | D12: 0 | E12: 2 | F12: 0 | G12: 1 | H12: 0 | I12: 0 | J12: 1 | K12: 1 | L12: 1 | M12: 3 | N12: 0 | O12: =SUM(C12:L12,N12) -> 6 | P12: =SUM(C12:N12) -> 9 | R12: 0900-1000 | S12: =SUM(C18:C21) -> 3 | T12: =SUM(D18:D21) -> 2 | U12: =SUM(E18:E21) -> 5 | V12: =SUM(F18:F21) -> 2 | W12: =SUM(G18:G21) -> 0 | X12: =SUM(H18:H21) -> 0 | Y12: =SUM(I18:I21) -> 2 | Z12: =SUM(J18:J21) -> 2 | ... AF12: =SUM(P18:P21) -> 35
B13: 07.45 - 08.00 | C13: 0 | D13: 0 | E13: 1 | F13: 0 | G13: 0 | H13: 0 | I13: 0 | J13: 0 | K13: 0 | L13: 2 | M13: 2 | N13: 0 | O13: =SUM(C13:L13,N13) -> 3 | P13: =SUM(C13:N13) -> 5 | R13: 1000-1100 | S13: =SUM(C22:C25) -> 1 | T13: =SUM(D22:D25) -> 1 | U13: =SUM(E22:E25) -> 6 | V13: =SUM(F22:F25) -> 4 | W13: =SUM(G22:G25) -> 1 | X13: =SUM(H22:H25) -> 0 | Y13: =SUM(I22:I25) -> 2 | Z13: =SUM(J22:J25) -> 4 | ... AF13: =SUM(P22:P25) -> 41
B14: 08.00 - 08.15 | C14: 3 | D14: 0 | E14: 1 | F14: 0 | G14: 0 | H14: 0 | I14: 0 | J14: 1 | K14: 0 | L14: 1 | M14: 2 | N14: 0 | O14: =SUM(C14:L14,N14) -> 6 | P14: =SUM(C14:N14) -> 8 | R14: 1100-1200 | S14: =SUM(C26:C29) -> 3 | T14: =SUM(D26:D29) -> 1 | U14: =SUM(E26:E29) -> 6 | V14: =SUM(F26:F29) -> 7 | W14: =SUM(G26:G29) -> 0 | X14: =SUM(H26:H29) -> 0 | Y14: =SUM(I26:I29) -> 0 | Z14: =SUM(J26:J29) -> 1 | ... AF14: =SUM(P26:P29) -> 33
B15: 08.15 - 08.30 | C15: 3 | D15: 0 | E15: 0 | F15: 0 | G15: 0 | H15: 0 | I15: 2 | J15: 0 | K15: 2 | L15: 0 | M15: 3 | N15: 0 | O15: =SUM(C15:L15,N15) -> 7 | P15: =SUM(C15:N15) -> 10 | R15: 1200-1300 | S15: =SUM(C30:C33) -> 1 | T15: =SUM(D30:D33) -> 1 | U15: =SUM(E30:E33) -> 4 | V15: =SUM(F30:F33) -> 6 | W15: =SUM(G30:G33) -> 0 | X15: =SUM(H30:H33) -> 1 | Y15: =SUM(I30:I33) -> 0 | Z15: =SUM(J30:J33) -> 0 | ... AF15: =SUM(P30:P33) -> 40
B16: 08.30 - 08.45 | C16: 4 | D16: 1 | E16: 2 | F16: 0 | G16: 0 | H16: 0 | I16: 0 | J16: 0 | K16: 2 | L16: 0 | M16: 4 | N16: 0 | O16: =SUM(C16:L16,N16) -> 9 | P16: =SUM(C16:N16) -> 13 | R16: 1300-1400 | S16: =SUM(C34:C37) -> 1 | T16: =SUM(D34:D37) -> 2 | U16: =SUM(E34:E37) -> 9 | V16: =SUM(F34:F37) -> 3 | W16: =SUM(G34:G37) -> 1 | X16: =SUM(H34:H37) -> 1 | Y16: =SUM(I34:I37) -> 4 | Z16: =SUM(J34:J37) -> 0 | ... AF16: =SUM(P34:P37) -> 40
B17: 08.45 - 9.00 | C17: 1 | D17: 0 | E17: 2 | F17: 0 | G17: 0 | H17: 0 | I17: 1 | J17: 2 | K17: 0 | L17: 2 | M17: 4 | N17: 0 | O17: =SUM(C17:L17,N17) -> 8 | P17: =SUM(C17:N17) -> 12 | R17: 1400-1500 | S17: =SUM(C38:C41) -> 0 | T17: =SUM(D38:D41) -> 2 | U17: =SUM(E38:E41) -> 4 | V17: =SUM(F38:F41) -> 4 | W17: =SUM(G38:G41) -> 1 | X17: =SUM(H38:H41) -> 2 | Y17: =SUM(I38:I41) -> 0 | Z17: =SUM(J38:J41) -> 1 | ... AF17: =SUM(P38:P41) -> 33
B18: 09.00 - 09.15 | C18: 0 | D18: 0 | E18: 1 | F18: 0 | G18: 0 | H18: 0 | I18: 0 | J18: 0 | K18: 0 | L18: 0 | M18: 3 | N18: 1 | O18: =SUM(C18:L18,N18) -> 2 | P18: =SUM(C18:N18) -> 5 | R18: 1500-1600 | S18: =SUM(C42:C45) -> 1 | T18: =SUM(D42:D45) -> 2 | U18: =SUM(E42:E45) -> 6 | V18: =SUM(F42:F45) -> 5 | W18: =SUM(G42:G45) -> 0 | X18: =SUM(H42:H45) -> 1 | Y18: =SUM(I42:I45) -> 3 | Z18: =SUM(J42:J45) -> 0 | ... AF18: =SUM(P42:P45) -> 41
B19: 09.15 - 09.30 | C19: 1 | D19: 0 | E19: 0 | F19: 0 | G19: 0 | H19: 0 | I19: 0 | J19: 0 | K19: 0 | L19: 0 | M19: 1 | N19: 0 | O19: =SUM(C19:L19,N19) -> 1 | P19: =SUM(C19:N19) -> 2 | R19: 1600-1700 | S19: =SUM(C46:C49) -> 3 | T19: =SUM(D46:D49) -> 1 | U19: =SUM(E46:E49) -> 3 | V19: =SUM(F46:F49) -> 4 | W19: =SUM(G46:G49) -> 0 | X19: =SUM(H46:H49) -> 3 | Y19: =SUM(I46:I49) -> 0 | Z19: =SUM(J46:J49) -> 1 | ... AF19: =SUM(P46:P49) -> 46
B20: 09.30 - 09.45 | C20: 2 | D20: 1 | E20: 2 | F20: 1 | G20: 0 | H20: 0 | I20: 0 | J20: 2 | K20: 0 | L20: 2 | M20: 6 | N20: 0 | O20: =SUM(C20:L20,N20) -> 10 | P20: =SUM(C20:N20) -> 16 | R20: 1700-1800 | S20: =SUM(C50:C53) -> 3 | T20: =SUM(D50:D53) -> 0 | U20: =SUM(E50:E53) -> 6 | V20: =SUM(F50:F53) -> 3 | W20: =SUM(G50:G53) -> 0 | X20: =SUM(H50:H53) -> 3 | Y20: =SUM(I50:I53) -> 1 | Z20: =SUM(J50:J53) -> 3 | ... AF20: =SUM(P50:P53) -> 41
B21: 09.45 - 10.00 | C21: 0 | D21: 1 | E21: 2 | F21: 1 | G21: 0 | H21: 0 | I21: 2 | J21: 0 | K21: 1 | L21: 0 | M21: 5 | N21: 0 | O21: =SUM(C21:L21,N21) -> 7 | P21: =SUM(C21:N21) -> 12 | R21: 1800-1900 | S21: =SUM(C54:C57) -> 1 | T21: =SUM(D54:D57) -> 0 | U21: =SUM(E54:E57) -> 2 | V21: =SUM(F54:F57) -> 4 | W21: =SUM(G54:G57) -> 3 | X21: =SUM(H54:H57) -> 2 | Y21: =SUM(I54:I57) -> 0 | Z21: =SUM(J54:J57) -> 0 | ... AF21: =SUM(P54:P57) -> 40
B22: 10.00 - 10.15 | C22: 0 | D22: 0 | E22: 1 | F22: 2 | G22: 0 | H22: 0 | I22: 1 | J22: 2 | K22: 0 | L22: 2 | M22: 4 | N22: 0 | O22: =SUM(C22:L22,N22) -> 8 | P22: =SUM(C22:N22) -> 12 | R22: AM Peak Hr | S22: =MAX(S10:S12) -> 11 | T22: =MAX(T10:T12) -> 2 | U22: =MAX(U10:U12) -> 7 | V22: =MAX(V10:V12) -> 2 | W22: =MAX(W10:W12) -> 1 | X22: =MAX(X10:X12) -> 0 | Y22: =MAX(Y10:Y12) -> 3 | Z22: =MAX(Z10:Z12) -> 3 | ... AF22: =MAX(AF10:AF12) -> 43
B23: 10.15 - 10.30 | C23: 0 | D23: 0 | E23: 2 | F23: 1 | G23: 1 | H23: 0 | I23: 0 | J23: 1 | K23: 0 | L23: 2 | M23: 4 | N23: 1 | O23: =SUM(C23:L23,N23) -> 8 | P23: =SUM(C23:N23) -> 12 | R23: IP Peak Hr | S23: =MAX(S13:S18) -> 3 | T23: =MAX(T13:T18) -> 2 | U23: =MAX(U13:U18) -> 9 | V23: =MAX(V13:V18) -> 7 | W23: =MAX(W13:W18) -> 1 | X23: =MAX(X13:X18) -> 2 | Y23: =MAX(Y13:Y18) -> 4 | Z23: =MAX(Z13:Z18) -> 4 | ... AF23: =MAX(AF13:AF18) -> 41
B24: 10.30 - 10.45 | C24: 0 | D24: 1 | E24: 2 | F24: 0 | G24: 0 | H24: 0 | I24: 1 | J24: 1 | K24: 0 | L24: 1 | M24: 5 | N24: 0 | O24: =SUM(C24:L24,N24) -> 6 | P24: =SUM(C24:N24) -> 11 | R24: PM Peak Hr | S24: =MAX(S19:S21) -> 3 | T24: =MAX(T19:T21) -> 1 | U24: =MAX(U19:U21) -> 6 | V24: =MAX(V19:V21) -> 4 | W24: =MAX(W19:W21) -> 3 | X24: =MAX(X19:X21) -> 3 | Y24: =MAX(Y19:Y21) -> 1 | Z24: =MAX(Z19:Z21) -> 3 | ... AF24: =MAX(AF19:AF21) -> 46
B25: 10.45 - 11.00 | C25: 1 | D25: 0 | E25: 1 | F25: 1 | G25: 0 | H25: 0 | I25: 0 | J25: 0 | K25: 1 | L25: 0 | M25: 2 | N25: 0 | O25: =SUM(C25:L25,N25) -> 4 | P25: =SUM(C25:N25) -> 6 | R25: AM Period | S25: =SUM(S10:S12) -> 16 | T25: =SUM(T10:T12) -> 3 | U25: =SUM(U10:U12) -> 17 | V25: =SUM(V10:V12) -> 4 | W25: =SUM(W10:W12) -> 1 | X25: =SUM(X10:X12) -> 0 | Y25: =SUM(Y10:Y12) -> 5 | Z25: =SUM(Z10:Z12) -> 6 | ... AF25: =SUM(AF10:AF12) -> 104
B26: 11.00 - 11.15 | C26: 1 | D26: 0 | E26: 2 | F26: 4 | G26: 0 | H26: 0 | I26: 0 | J26: 0 | K26: 1 | L26: 1 | M26: 1 | N26: 0 | O26: =SUM(C26:L26,N26) -> 9 | P26: =SUM(C26:N26) -> 10 | R26: IP Period | S26: =SUM(S13:S18) -> 7 | T26: =SUM(T13:T18) -> 9 | U26: =SUM(U13:U18) -> 35 | V26: =SUM(V13:V18) -> 29 | W26: =SUM(W13:W18) -> 3 | X26: =SUM(X13:X18) -> 5 | Y26: =SUM(Y13:Y18) -> 9 | Z26: =SUM(Z13:Z18) -> 6 | ... AF26: =SUM(AF13:AF18) -> 228
B27: 11.15 - 11.30 | C27: 1 | D27: 0 | E27: 1 | F27: 1 | G27: 0 | H27: 0 | I27: 0 | J27: 1 | K27: 0 | L27: 0 | M27: 5 | N27: 0 | O27: =SUM(C27:L27,N27) -> 4 | P27: =SUM(C27:N27) -> 9 | R27: PM Period | S27: =SUM(S19:S21) -> 7 | T27: =SUM(T19:T21) -> 1 | U27: =SUM(U19:U21) -> 11 | V27: =SUM(V19:V21) -> 11 | W27: =SUM(W19:W21) -> 3 | X27: =SUM(X19:X21) -> 8 | Y27: =SUM(Y19:Y21) -> 1 | Z27: =SUM(Z19:Z21) -> 4 | ... AF27: =SUM(AF19:AF21) -> 127
B28: 11.30 - 11.45 | C28: 0 | D28: 0 | E28: 1 | F28: 0 | G28: 0 | H28: 0 | I28: 0 | J28: 0 | K28: 0 | L28: 0 | M28: 4 | N28: 0 | O28: =SUM(C28:L28,N28) -> 1 | P28: =SUM(C28:N28) -> 5 | R28: 12 Hours | S28: =SUM(S10:S21) -> 30 | T28: =SUM(T10:T21) -> 13 | U28: =SUM(U10:U21) -> 63 | V28: =SUM(V10:V21) -> 44 | W28: =SUM(W10:W21) -> 7 | X28: =SUM(X10:X21) -> 13 | Y28: =SUM(Y10:Y21) -> 15 | Z28: =SUM(Z10:Z21) -> 16 | ... AF28: =SUM(AF10:AF21) -> 459
B29: 11.45 - 12.00 | C29: 1 | D29: 1 | E29: 2 | F29: 2 | G29: 0 | H29: 0 | I29: 0 | J29: 0 | K29: 0 | L29: 0 | M29: 3 | N29: 0 | O29: =SUM(C29:L29,N29) -> 6 | P29: =SUM(C29:N29) -> 9
B30: 12.00 - 12.15 | C30: 0 | D30: 0 | E30: 1 | F30: 2 | G30: 0 | H30: 0 | I30: 0 | J30: 0 | K30: 0 | L30: 0 | M30: 9 | N30: 0 | O30: =SUM(C30:L30,N30) -> 3 | P30: =SUM(C30:N30) -> 12
B31: 12.15 - 12.30 | C31: 1 | D31: 0 | E31: 1 | F31: 1 | G31: 0 | H31: 0 | I31: 0 | J31: 0 | K31: 1 | L31: 1 | M31: 4 | N31: 0 | O31: =SUM(C31:L31,N31) -> 5 | P31: =SUM(C31:N31) -> 9
B32: 12.30 - 12.45 | C32: 0 | D32: 0 | E32: 0 | F32: 1 | G32: 0 | H32: 0 | I32: 0 | J32: 0 | K32: 1 | L32: 0 | M32: 5 | N32: 0 | O32: =SUM(C32:L32,N32) -> 2 | P32: =SUM(C32:N32) -> 7
B33: 12.45 - 13.00 | C33: 0 | D33: 1 | E33: 2 | F33: 2 | G33: 0 | H33: 1 | I33: 0 | J33: 0 | K33: 0 | L33: 0 | M33: 6 | N33: 0 | O33: =SUM(C33:L33,N33) -> 6 | P33: =SUM(C33:N33) -> 12
B34: 13.00 - 13.15 | C34: 0 | D34: 0 | E34: 2 | F34: 2 | G34: 0 | H34: 0 | I34: 1 | J34: 0 | K34: 0 | L34: 2 | M34: 6 | N34: 0 | O34: =SUM(C34:L34,N34) -> 7 | P34: =SUM(C34:N34) -> 13
B35: 13.15 - 13.30 | C35: 1 | D35: 0 | E35: 2 | F35: 1 | G35: 0 | H35: 0 | I35: 2 | J35: 0 | K35: 0 | L35: 1 | M35: 2 | N35: 0 | O35: =SUM(C35:L35,N35) -> 7 | P35: =SUM(C35:N35) -> 9
B36: 13.30 - 13.45 | C36: 0 | D36: 2 | E36: 3 | F36: 0 | G36: 1 | H36: 0 | I36: 1 | J36: 0 | K36: 0 | L36: 0 | M36: 3 | N36: 0 | O36: =SUM(C36:L36,N36) -> 7 | P36: =SUM(C36:N36) -> 10
B37: 13.45 - 14.00 | C37: 0 | D37: 0 | E37: 2 | F37: 0 | G37: 0 | H37: 1 | I37: 0 | J37: 0 | K37: 0 | L37: 2 | M37: 3 | N37: 0 | O37: =SUM(C37:L37,N37) -> 5 | P37: =SUM(C37:N37) -> 8
