Workbook

Sheet 07.09. Ishaka-Katungulu-24h
B1: Consultancy services for Preparation of Expressway Development Master Plan (EDMP) for Uganda
B2: MANUAL CLASSIFIED COUNT (MCC)
B3: ROAD NAME: | C3: ='09.09 Ishaka-Katungulu'!C3:G3 -> MCC - C4 - STN104 - ISHAKA KATUNGULU ROAD
C5: Date | D5: 07.09.19 | F5: Location | G5: ='12.09 Katungulu-Ishaka'!G5:H5 -> Rubirizi | J5: Surveyor | K5: ='12.09 Katungulu-Ishaka'!K5:L5 -> xxx
C6: Dir. From | D6: ='09.09 Ishaka-Katungulu'!D6:E6 -> Ishaka | F6: Dir. To | G6: ='09.09 Ishaka-Katungulu'!G6:H6 -> Katungulu | J6: Supervisor | K6: ='12.09 Katungulu-Ishaka'!K6:L6 -> xxx
B8: Time / Veh Type | R8: SUMMARY TRAFFIC VOLUMES
C9: 1. Car | D9: 2. Station Wagon | E9: 3. Pickups | F9: 4. Minibus, matatu | G9: 5. Medium bus | H9: 6. Large Bus | I9: 7. Light Truck | J9: 8. Medium Truck | K9: 9. Heavy truck | L9: 10. Truck Trailer | M9: 11. Motor cycles | N9: 12. Tractors | O9: Total Excl M/Cycles | P9: Total All | R9: Time | S9: 1. Car | T9: 2. Station Wagon | U9: 3. Pickups | V9: 4. Minibus, matatu | W9: 5. Medium bus | X9: 6. Large Bus | Y9: 7. Light Truck | Z9: 8. Medium Truck | AA9: 9. Heavy truck | AB9: 10. Truck Trailer | AC9: 11. Motorcycles | AD9: 12. Tractors, Graders | AE9: Total Excl M/ Cycles | AF9: Total All
B10: 07.00 - 07.15 | C10: 2 | D10: 0 | E10: 0 | F10: 2 | G10: 0 | H10: 0 | I10: 0 | J10: 1 | K10: 0 | L10: 2 | M10: 5 | N10: 0 | O10: =SUM(C10:L10,N10) -> 7 | P10: =SUM(C10:N10) -> 12 | R10: 0700-0800 | S10: =SUM(C10:C13) -> 13 | T10: =SUM(D10:D13) -> 0 | U10: =SUM(E10:E13) -> 0 | V10: =SUM(F10:F13) -> 5 | W10: =SUM(G10:G13) -> 2 | X10: =SUM(H10:H13) -> 0 | Y10: =SUM(I10:I13) -> 0 | Z10: =SUM(J10:J13) -> 6 | ... AF10: =SUM(P10:P13) -> 78
B11: 07.15 - 07.30 | C11: 3 | D11: 0 | E11: 0 | F11: 3 | G11: 1 | H11: 0 | I11: 0 | J11: 2 | K11: 1 | L11: 3 | M11: 8 | N11: 0 | O11: =SUM(C11:L11,N11) -> 13 | P11: =SUM(C11:N11) -> 21 | R11: 0800-0900 | S11: =SUM(C14:C17) -> 8 | T11: =SUM(D14:D17) -> 4 | U11: =SUM(E14:E17) -> 7 | V11: =SUM(F14:F17) -> 16 | W11: =SUM(G14:G17) -> 0 | X11: =SUM(H14:H17) -> 1 | Y11: =SUM(I14:I17) -> 3 | Z11: =SUM(J14:J17) -> 16 | ... AF11: =SUM(P14:P17) -> 221
B12: 07.30 - 07.45 | C12: 3 | D12: 0 | E12: 0 | F12: 0 | G12: 0 | H12: 0 | I12: 0 | J12: 1 | K12: 0 | L12: 0 | M12: 12 | N12: 0 | O12: =SUM(C12:L12,N12) -> 4 | P12: =SUM(C12:N12) -> 16 | R12: 0900-1000 | S12: =SUM(C18:C21) -> 19 | T12: =SUM(D18:D21) -> 6 | U12: =SUM(E18:E21) -> 11 | V12: =SUM(F18:F21) -> 13 | W12: =SUM(G18:G21) -> 0 | X12: =SUM(H18:H21) -> 0 | Y12: =SUM(I18:I21) -> 1 | Z12: =SUM(J18:J21) -> 6 | ... AF12: =SUM(P18:P21) -> 224
B13: 07.45 - 08.00 | C13: 5 | D13: 0 | E13: 0 | F13: 0 | G13: 1 | H13: 0 | I13: 0 | J13: 2 | K13: 0 | L13: 1 | M13: 20 | N13: 0 | O13: =SUM(C13:L13,N13) -> 9 | P13: =SUM(C13:N13) -> 29 | R13: 1000-1100 | S13: =SUM(C22:C25) -> 16 | T13: =SUM(D22:D25) -> 8 | U13: =SUM(E22:E25) -> 9 | V13: =SUM(F22:F25) -> 10 | W13: =SUM(G22:G25) -> 1 | X13: =SUM(H22:H25) -> 0 | Y13: =SUM(I22:I25) -> 1 | Z13: =SUM(J22:J25) -> 4 | ... AF13: =SUM(P22:P25) -> 243
B14: 08.00 - 08.15 | C14: 3 | D14: 1 | E14: 2 | F14: 4 | G14: 0 | H14: 0 | I14: 1 | J14: 2 | K14: 3 | L14: 4 | M14: 23 | N14: 0 | O14: =SUM(C14:L14,N14) -> 20 | P14: =SUM(C14:N14) -> 43 | R14: 1100-1200 | S14: =SUM(C26:C29) -> 37 | T14: =SUM(D26:D29) -> 8 | U14: =SUM(E26:E29) -> 12 | V14: =SUM(F26:F29) -> 17 | W14: =SUM(G26:G29) -> 1 | X14: =SUM(H26:H29) -> 0 | Y14: =SUM(I26:I29) -> 6 | Z14: =SUM(J26:J29) -> 0 | ... AF14: =SUM(P26:P29) -> 267
B15: 08.15 - 08.30 | C15: 5 | D15: 2 | E15: 3 | F15: 6 | G15: 0 | H15: 1 | I15: 2 | J15: 3 | K15: 5 | L15: 5 | M15: 39 | N15: 1 | O15: =SUM(C15:L15,N15) -> 33 | P15: =SUM(C15:N15) -> 72 | R15: 1200-1300 | S15: =SUM(C30:C33) -> 32 | T15: =SUM(D30:D33) -> 11 | U15: =SUM(E30:E33) -> 16 | V15: =SUM(F30:F33) -> 9 | W15: =SUM(G30:G33) -> 0 | X15: =SUM(H30:H33) -> 0 | Y15: =SUM(I30:I33) -> 4 | Z15: =SUM(J30:J33) -> 6 | ... AF15: =SUM(P30:P33) -> 260
B16: 08.30 - 08.45 | C16: 0 | D16: 0 | E16: 1 | F16: 2 | G16: 0 | H16: 0 | I16: 0 | J16: 4 | K16: 2 | L16: 2 | M16: 28 | N16: 0 | O16: =SUM(C16:L16,N16) -> 11 | P16: =SUM(C16:N16) -> 39 | R16: 1300-1400 | S16: =SUM(C34:C37) -> 27 | T16: =SUM(D34:D37) -> 6 | U16: =SUM(E34:E37) -> 8 | V16: =SUM(F34:F37) -> 20 | W16: =SUM(G34:G37) -> 0 | X16: =SUM(H34:H37) -> 0 | Y16: =SUM(I34:I37) -> 3 | Z16: =SUM(J34:J37) -> 8 | ... AF16: =SUM(P34:P37) -> 261
B17: 08.45 - 9.00 | C17: 0 | D17: 1 | E17: 1 | F17: 4 | G17: 0 | H17: 0 | I17: 0 | J17: 7 | K17: 3 | L17: 4 | M17: 47 | N17: 0 | O17: =SUM(C17:L17,N17) -> 20 | P17: =SUM(C17:N17) -> 67 | R17: 1400-1500 | S17: =SUM(C38:C41) -> 32 | T17: =SUM(D38:D41) -> 9 | U17: =SUM(E38:E41) -> 14 | V17: =SUM(F38:F41) -> 16 | W17: =SUM(G38:G41) -> 0 | X17: =SUM(H38:H41) -> 0 | Y17: =SUM(I38:I41) -> 14 | Z17: =SUM(J38:J41) -> 1 | ... AF17: =SUM(P38:P41) -> 285
B18: 09.00 - 09.15 | C18: 4 | D18: 0 | E18: 0 | F18: 1 | G18: 0 | H18: 0 | I18: 0 | J18: 2 | K18: 0 | L18: 0 | M18: 27 | N18: 0 | O18: =SUM(C18:L18,N18) -> 7 | P18: =SUM(C18:N18) -> 34 | R18: 1500-1600 | S18: =SUM(C42:C45) -> 16 | T18: =SUM(D42:D45) -> 7 | U18: =SUM(E42:E45) -> 10 | V18: =SUM(F42:F45) -> 14 | W18: =SUM(G42:G45) -> 0 | X18: =SUM(H42:H45) -> 0 | Y18: =SUM(I42:I45) -> 6 | Z18: =SUM(J42:J45) -> 9 | ... AF18: =SUM(P42:P45) -> 243
B19: 09.15 - 09.30 | C19: 7 | D19: 0 | E19: 1 | F19: 2 | G19: 0 | H19: 0 | I19: 1 | J19: 3 | K19: 1 | L19: 0 | M19: 45 | N19: 0 | O19: =SUM(C19:L19,N19) -> 15 | P19: =SUM(C19:N19) -> 60 | R19: 1600-1700 | S19: =SUM(C46:C49) -> 26 | T19: =SUM(D46:D49) -> 6 | U19: =SUM(E46:E49) -> 10 | V19: =SUM(F46:F49) -> 11 | W19: =SUM(G46:G49) -> 0 | X19: =SUM(H46:H49) -> 0 | Y19: =SUM(I46:I49) -> 5 | Z19: =SUM(J46:J49) -> 3 | ... AF19: =SUM(P46:P49) -> 163
B20: 09.30 - 09.45 | C20: 3 | D20: 2 | E20: 4 | F20: 4 | G20: 0 | H20: 0 | I20: 0 | J20: 0 | K20: 4 | L20: 0 | M20: 31 | N20: 0 | O20: =SUM(C20:L20,N20) -> 17 | P20: =SUM(C20:N20) -> 48 | R20: 1700-1800 | S20: =SUM(C50:C53) -> 45 | T20: =SUM(D50:D53) -> 10 | U20: =SUM(E50:E53) -> 15 | V20: =SUM(F50:F53) -> 15 | W20: =SUM(G50:G53) -> 0 | X20: =SUM(H50:H53) -> 1 | Y20: =SUM(I50:I53) -> 9 | Z20: =SUM(J50:J53) -> 4 | ... AF20: =SUM(P50:P53) -> 306
B21: 09.45 - 10.00 | C21: 5 | D21: 4 | E21: 6 | F21: 6 | G21: 0 | H21: 0 | I21: 0 | J21: 1 | K21: 7 | L21: 1 | M21: 52 | N21: 0 | O21: =SUM(C21:L21,N21) -> 30 | P21: =SUM(C21:N21) -> 82 | R21: 1800-1900 | S21: =SUM(C54:C57) -> 34 | T21: =SUM(D54:D57) -> 12 | U21: =SUM(E54:E57) -> 17 | V21: =SUM(F54:F57) -> 16 | W21: =SUM(G54:G57) -> 0 | X21: =SUM(H54:H57) -> 0 | Y21: =SUM(I54:I57) -> 3 | Z21: =SUM(J54:J57) -> 5 | ... AF21: =SUM(P54:P57) -> 254
B22: 10.00 - 10.15 | C22: 3 | D22: 1 | E22: 1 | F22: 2 | G22: 0 | H22: 0 | I22: 0 | J22: 1 | K22: 4 | L22: 2 | M22: 28 | N22: 0 | O22: =SUM(C22:L22,N22) -> 14 | P22: =SUM(C22:N22) -> 42 | R22: 1900-2000 | S22: =SUM(C58:C61) -> 32 | T22: =SUM(D58:D61) -> 11 | U22: =SUM(E58:E61) -> 18 | V22: =SUM(F58:F61) -> 13 | W22: =SUM(G58:G61) -> 0 | X22: =SUM(H58:H61) -> 2 | Y22: =SUM(I58:I61) -> 1 | Z22: =SUM(J58:J61) -> 0 | ... AF22: =SUM(P58:P61) -> 260
B23: 10.15 - 10.30 | C23: 5 | D23: 2 | E23: 2 | F23: 3 | G23: 1 | H23: 0 | I23: 1 | J23: 2 | K23: 6 | L23: 4 | M23: 46 | N23: 0 | O23: =SUM(C23:L23,N23) -> 26 | P23: =SUM(C23:N23) -> 72 | R23: 2000-2100 | S23: =SUM(C62:C65) -> 9 | T23: =SUM(D62:D65) -> 10 | U23: =SUM(E62:E65) -> 14 | V23: =SUM(F62:F65) -> 8 | W23: =SUM(G62:G65) -> 0 | X23: =SUM(H62:H65) -> 1 | Y23: =SUM(I62:I65) -> 5 | Z23: =SUM(J62:J65) -> 0 | ... AF23: =SUM(P62:P65) -> 113
B24: 10.30 - 10.45 | C24: 3 | D24: 2 | E24: 2 | F24: 2 | G24: 0 | H24: 0 | I24: 0 | J24: 0 | K24: 1 | L24: 0 | M24: 38 | N24: 0 | O24: =SUM(C24:L24,N24) -> 10 | P24: =SUM(C24:N24) -> 48 | R24: 2100-2200 | S24: =SUM(C66:C69) -> 11 | T24: =SUM(D66:D69) -> 2 | U24: =SUM(E66:E69) -> 4 | V24: =SUM(F66:F69) -> 12 | W24: =SUM(G66:G69) -> 0 | X24: =SUM(H66:H69) -> 0 | Y24: =SUM(I66:I69) -> 6 | Z24: =SUM(J66:J69) -> 0 | ... AF24: =SUM(P66:P69) -> 77
B25: 10.45 - 11.00 | C25: 5 | D25: 3 | E25: 4 | F25: 3 | G25: 0 | H25: 0 | I25: 0 | J25: 1 | K25: 2 | L25: 0 | M25: 63 | N25: 0 | O25: =SUM(C25:L25,N25) -> 18 | P25: =SUM(C25:N25) -> 81 | R25: 2200-2300 | S25: =SUM(C70:C73) -> 15 | T25: =SUM(D70:D73) -> 3 | U25: =SUM(E70:E73) -> 4 | V25: =SUM(F70:F73) -> 3 | W25: =SUM(G70:G73) -> 0 | X25: =SUM(H70:H73) -> 0 | Y25: =SUM(I70:I73) -> 1 | Z25: =SUM(J70:J73) -> 11 | ... AF25: =SUM(P70:P73) -> 65
B26: 11.00 - 11.15 | C26: 7 | D26: 2 | E26: 2 | F26: 4 | G26: 0 | H26: 0 | I26: 2 | J26: 0 | K26: 0 | L26: 0 | M26: 29 | N26: 0 | O26: =SUM(C26:L26,N26) -> 17 | P26: =SUM(C26:N26) -> 46 | R26: 2300-0000 | S26: =SUM(C74:C77) -> 9 | T26: =SUM(D74:D77) -> 3 | U26: =SUM(E74:E77) -> 5 | V26: =SUM(F74:F77) -> 13 | W26: =SUM(G74:G77) -> 0 | X26: =SUM(H74:H77) -> 1 | Y26: =SUM(I74:I77) -> 9 | Z26: =SUM(J74:J77) -> 5 | ... AF26: =SUM(P74:P77) -> 78
B27: 11.15 - 11.30 | C27: 11 | D27: 2 | E27: 4 | F27: 7 | G27: 1 | H27: 0 | I27: 3 | J27: 0 | K27: 1 | L27: 1 | M27: 48 | N27: 0 | O27: =SUM(C27:L27,N27) -> 30 | P27: =SUM(C27:N27) -> 78 | R27: 0000-0100 | S27: =SUM(C78:C81) -> 4 | T27: =SUM(D78:D81) -> 0 | U27: =SUM(E78:E81) -> 1 | V27: =SUM(F78:F81) -> 1 | W27: =SUM(G78:G81) -> 1 | X27: =SUM(H78:H81) -> 3 | Y27: =SUM(I78:I81) -> 1 | Z27: =SUM(J78:J81) -> 0 | ... AF27: =SUM(P78:P81) -> 28
B28: 11.30 - 11.45 | C28: 7 | D28: 2 | E28: 2 | F28: 2 | G28: 0 | H28: 0 | I28: 0 | J28: 0 | K28: 1 | L28: 1 | M28: 38 | N28: 0 | O28: =SUM(C28:L28,N28) -> 15 | P28: =SUM(C28:N28) -> 53 | R28: 0100-0200 | S28: =SUM(C82:C85) -> 1 | T28: =SUM(D82:D85) -> 0 | U28: =SUM(E82:E85) -> 1 | V28: =SUM(F82:F85) -> 0 | W28: =SUM(G82:G85) -> 0 | X28: =SUM(H82:H85) -> 0 | Y28: =SUM(I82:I85) -> 0 | Z28: =SUM(J82:J85) -> 1 | ... AF28: =SUM(P82:P85) -> 11
B29: 11.45 - 12.00 | C29: 12 | D29: 2 | E29: 4 | F29: 4 | G29: 0 | H29: 0 | I29: 1 | J29: 0 | K29: 2 | L29: 2 | M29: 63 | N29: 0 | O29: =SUM(C29:L29,N29) -> 27 | P29: =SUM(C29:N29) -> 90 | R29: 0200-0300 | S29: =SUM(C86:C89) -> 3 | T29: =SUM(D86:D89) -> 0 | U29: =SUM(E86:E89) -> 1 | V29: =SUM(F86:F89) -> 0 | W29: =SUM(G86:G89) -> 0 | X29: =SUM(H86:H89) -> 0 | Y29: =SUM(I86:I89) -> 0 | Z29: =SUM(J86:J89) -> 2 | ... AF29: =SUM(P86:P89) -> 7
B30: 12.00 - 12.15 | C30: 7 | D30: 2 | E30: 3 | F30: 2 | G30: 0 | H30: 0 | I30: 0 | J30: 0 | K30: 0 | L30: 0 | M30: 40 | N30: 0 | O30: =SUM(C30:L30,N30) -> 14 | P30: =SUM(C30:N30) -> 54 | R30: 0300-0400 | S30: =SUM(C90:C93) -> 0 | T30: =SUM(D90:D93) -> 0 | U30: =SUM(E90:E93) -> 1 | V30: =SUM(F90:F93) -> 0 | W30: =SUM(G90:G93) -> 0 | X30: =SUM(H90:H93) -> 0 | Y30: =SUM(I90:I93) -> 0 | Z30: =SUM(J90:J93) -> 0 | ... AF30: =SUM(P90:P93) -> 1
B31: 12.15 - 12.30 | C31: 11 | D31: 4 | E31: 5 | F31: 4 | G31: 0 | H31: 0 | I31: 1 | J31: 1 | K31: 0 | L31: 1 | M31: 67 | N31: 0 | O31: =SUM(C31:L31,N31) -> 27 | P31: =SUM(C31:N31) -> 94 | R31: 0400-0500 | S31: =SUM(C94:C97) -> 0 | T31: =SUM(D94:D97) -> 0 | U31: =SUM(E94:E97) -> 1 | V31: =SUM(F94:F97) -> 0 | W31: =SUM(G94:G97) -> 0 | X31: =SUM(H94:H97) -> 0 | Y31: =SUM(I94:I97) -> 0 | Z31: =SUM(J94:J97) -> 1 | ... AF31: =SUM(P94:P97) -> 4
B32: 12.30 - 12.45 | C32: 5 | D32: 2 | E32: 3 | F32: 1 | G32: 0 | H32: 0 | I32: 1 | J32: 2 | K32: 0 | L32: 0 | M32: 27 | N32: 0 | O32: =SUM(C32:L32,N32) -> 14 | P32: =SUM(C32:N32) -> 41 | R32: 0500-0600 | S32: =SUM(C98:C101) -> 1 | T32: =SUM(D98:D101) -> 1 | U32: =SUM(E98:E101) -> 2 | V32: =SUM(F98:F101) -> 2 | W32: =SUM(G98:G101) -> 0 | X32: =SUM(H98:H101) -> 0 | Y32: =SUM(I98:I101) -> 0 | Z32: =SUM(J98:J101) -> 0 | ... AF32: =SUM(P98:P101) -> 14
B33: 12.45 - 13.00 | C33: 9 | D33: 3 | E33: 5 | F33: 2 | G33: 0 | H33: 0 | I33: 2 | J33: 3 | K33: 1 | L33: 1 | M33: 45 | N33: 0 | O33: =SUM(C33:L33,N33) -> 26 | P33: =SUM(C33:N33) -> 71 | R33: 0600-0700 | S33: =SUM(C102:C105) -> 9 | T33: =SUM(D102:D105) -> 3 | U33: =SUM(E102:E105) -> 5 | V33: =SUM(F102:F105) -> 4 | W33: =SUM(G102:G105) -> 0 | X33: =SUM(H102:H105) -> 0 | Y33: =SUM(I102:I105) -> 0 | Z33: =SUM(J102:J105) -> 0 | ... AF33: =SUM(P102:P105) -> 36
B34: 13.00 - 13.15 | C34: 6 | D34: 1 | E34: 1 | F34: 4 | G34: 0 | H34: 0 | I34: 0 | J34: 2 | K34: 0 | L34: 0 | M34: 28 | N34: 0 | O34: =SUM(C34:L34,N34) -> 14 | P34: =SUM(C34:N34) -> 42 | R34: AM Peak Hr | S34: =MAX(S10:S12) -> 19 | T34: =MAX(T10:T12) -> 6 | U34: =MAX(U10:U12) -> 11 | V34: =MAX(V10:V12) -> 16 | W34: =MAX(W10:W12) -> 2 | X34: =MAX(X10:X12) -> 1 | Y34: =MAX(Y10:Y12) -> 3 | Z34: =MAX(Z10:Z12) -> 16 | ... AF34: =MAX(AF10:AF12) -> 224
B35: 13.15 - 13.30 | C35: 10 | D35: 2 | E35: 2 | F35: 6 | G35: 0 | H35: 0 | I35: 0 | J35: 3 | K35: 1 | L35: 0 | M35: 47 | N35: 0 | O35: =SUM(C35:L35,N35) -> 24 | P35: =SUM(C35:N35) -> 71 | R35: IP Peak Hr | S35: =MAX(S13:S18) -> 37 | T35: =MAX(T13:T18) -> 11 | U35: =MAX(U13:U18) -> 16 | V35: =MAX(V13:V18) -> 20 | W35: =MAX(W13:W18) -> 1 | X35: =MAX(X13:X18) -> 0 | Y35: =MAX(Y13:Y18) -> 14 | Z35: =MAX(Z13:Z18) -> 9 | ... AF35: =MAX(AF13:AF18) -> 285
B36: 13.30 - 13.45 | C36: 4 | D36: 1 | E36: 2 | F36: 4 | G36: 0 | H36: 0 | I36: 1 | J36: 1 | K36: 1 | L36: 0 | M36: 41 | N36: 0 | O36: =SUM(C36:L36,N36) -> 14 | P36: =SUM(C36:N36) -> 55 | R36: PM Peak Hr | S36: =MAX(S19:S21) -> 45 | T36: =MAX(T19:T21) -> 12 | U36: =MAX(U19:U21) -> 17 | V36: =MAX(V19:V21) -> 16 | W36: =MAX(W19:W21) -> 0 | X36: =MAX(X19:X21) -> 1 | Y36: =MAX(Y19:Y21) -> 9 | Z36: =MAX(Z19:Z21) -> 5 | ... AF36: =MAX(AF19:AF21) -> 306
B37: 13.45 - 14.00 | C37: 7 | D37: 2 | E37: 3 | F37: 6 | G37: 0 | H37: 0 | I37: 2 | J37: 2 | K37: 2 | L37: 1 | M37: 68 | N37: 0 | O37: =SUM(C37:L37,N37) -> 25 | P37: =SUM(C37:N37) -> 93 | R37: AM Period | S37: =SUM(S10:S12) -> 40 | T37: =SUM(T10:T12) -> 10 | U37: =SUM(U10:U12) -> 18 | V37: =SUM(V10:V12) -> 34 | W37: =SUM(W10:W12) -> 2 | X37: =SUM(X10:X12) -> 1 | Y37: =SUM(Y10:Y12) -> 4 | Z37: =SUM(Z10:Z12) -> 28 | ... AF37: =SUM(AF10:AF12) -> 523
B38: 14.00 - 14.15 | C38: 10 | D38: 2 | E38: 2 | F38: 4 | G38: 0 | H38: 0 | I38: 3 | J38: 0 | K38: 3 | L38: 0 | M38: 38 | N38: 0 | O38: =SUM(C38:L38,N38) -> 24 | P38: =SUM(C38:N38) -> 62 | R38: IP Period | S38: =SUM(S13:S18) -> 160 | T38: =SUM(T13:T18) -> 49 | U38: =SUM(U13:U18) -> 69 | V38: =SUM(V13:V18) -> 86 | W38: =SUM(W13:W18) -> 2 | X38: =SUM(X13:X18) -> 0 | Y38: =SUM(Y13:Y18) -> 34 | Z38: =SUM(Z13:Z18) -> 28 | ... AF38: =SUM(AF13:AF18) -> 1559
B39: 14.15 - 14.30 | C39: 16 | D39: 2 | E39: 4 | F39: 6 | G39: 0 | H39: 0 | I39: 5 | J39: 1 | K39: 5 | L39: 1 | M39: 64 | N39: 0 | O39: =SUM(C39:L39,N39) -> 40 | P39: =SUM(C39:N39) -> 104 | R39: PM Period | S39: =SUM(S19:S21) -> 105 | T39: =SUM(T19:T21) -> 28 | U39: =SUM(U19:U21) -> 42 | V39: =SUM(V19:V21) -> 42 | W39: =SUM(W19:W21) -> 0 | X39: =SUM(X19:X21) -> 1 | Y39: =SUM(Y19:Y21) -> 17 | Z39: =SUM(Z19:Z21) -> 12 | ... AF39: =SUM(AF19:AF21) -> 723
B40: 14.30 - 14.45 | C40: 2 | D40: 2 | E40: 3 | F40: 2 | G40: 0 | H40: 0 | I40: 2 | J40: 0 | K40: 2 | L40: 0 | M40: 31 | N40: 0 | O40: =SUM(C40:L40,N40) -> 13 | P40: =SUM(C40:N40) -> 44 | R40: 12 Hours | S40: =SUM(S10:S21) -> 305 | T40: =SUM(T10:T21) -> 87 | U40: =SUM(U10:U21) -> 129 | V40: =SUM(V10:V21) -> 162 | W40: =SUM(W10:W21) -> 4 | X40: =SUM(X10:X21) -> 2 | Y40: =SUM(Y10:Y21) -> 55 | Z40: =SUM(Z10:Z21) -> 68 | ... AF40: =SUM(AF10:AF21) -> 2805
B41: 14.45 - 15.00 | C41: 4 | D41: 3 | E41: 5 | F41: 4 | G41: 0 | H41: 0 | I41: 4 | J41: 0 | K41: 3 | L41: 1 | M41: 51 | N41: 0 | O41: =SUM(C41:L41,N41) -> 24 | P41: =SUM(C41:N41) -> 75 | R41: 24 Hrs/ADT | S41: =SUM(S10:S33) -> 399 | T41: =SUM(T10:T33) -> 120 | U41: =SUM(U10:U33) -> 186 | V41: =SUM(V10:V33) -> 218 | W41: =SUM(W10:W33) -> 5 | X41: =SUM(X10:X33) -> 9 | Y41: =SUM(Y10:Y33) -> 78 | Z41: =SUM(Z10:Z33) -> 88 | ... AF41: =SUM(AF10:AF33) -> 3499
B42: 15.00 - 15.15 | C42: 2 | D42: 0 | E42: 1 | F42: 2 | G42: 0 | H42: 0 | I42: 2 | J42: 2 | K42: 2 | L42: 2 | M42: 29 | N42: 0 | O42: =SUM(C42:L42,N42) -> 13 | P42: =SUM(C42:N42) -> 42 | R42: NEF | S42: =S41/S40 -> 1.3081967 | T42: =T41/T40 -> 1.3793103 | U42: =U41/U40 -> 1.4418605 | V42: =V41/V40 -> 1.345679 | W42: =W41/W40 -> 1.25 | X42: =X41/X40 -> 4.5 | Y42: =Y41/Y40 -> 1.4181818 | Z42: =Z41/Z40 -> 1.2941176 | ... AF42: =AF41/AF40 -> 1.2474153
...

Sheet 07.09. Katungulu-Ishaka-24h
B1: Consultancy services for Preparation of Expressway Development Master Plan (EDMP) for Uganda
B2: MANUAL CLASSIFIED COUNT (MCC)
B3: ROAD NAME: | C3: ='09.09 Ishaka-Katungulu'!C3:G3 -> MCC - C4 - STN104 - ISHAKA KATUNGULU ROAD
C5: Date | D5: ='07.09. Ishaka-Katungulu-24h'!D5 -> 07.09.19 | F5: Location | G5: ='07.09. Ishaka-Katungulu-24h'!G5:H5 -> Rubirizi | J5: Surveyor | K5: ='07.09. Ishaka-Katungulu-24h'!K5:L5 -> xxx
C6: Dir. From | D6: ='09.09 Katungulu-Ishaka'!D6:E6 -> Katungulu | F6: Dir. To | G6: ='10.09 Katungulu-Ishaka'!G6:H6 -> Ishaka | J6: Supervisor | K6: ='07.09. Ishaka-Katungulu-24h'!K6:L6 -> xxx
B8: Time / Veh Type | R8: SUMMARY TRAFFIC VOLUMES
C9: 1. Car | D9: 2. Station Wagon | E9: 3. Pickups | F9: 4. Minibus, matatu | G9: 5. Medium bus | H9: 6. Large Bus | I9: 7. Light Truck | J9: 8. Medium Truck | K9: 9. Heavy truck | L9: 10. Truck Trailer | M9: 11. Motor cycles | N9: 12. Tractors | O9: Total Excl M/Cycles | P9: Total All | R9: Time | S9: 1. Car | T9: 2. Station Wagon | U9: 3. Pickups | V9: 4. Minibus, matatu | W9: 5. Medium bus | X9: 6. Large Bus | Y9: 7. Light Truck | Z9: 8. Medium Truck | AA9: 9. Heavy truck | AB9: 10. Truck Trailer | AC9: 11. Motorcycles | AD9: 12. Tractors, Graders | AE9: Total Excl M/ Cycles | AF9: Total All
B10: 07.00 - 07.15 | C10: 1 | D10: 0 | E10: 0 | F10: 2 | G10: 0 | H10: 0 | I10: 0 | J10: 2 | K10: 0 | L10: 0 | M10: 2 | N10: 0 | O10: =SUM(C10:L10,N10) -> 5 | P10: =SUM(C10:N10) -> 7 | R10: 0700-0800 | S10: =SUM(C10:C13) -> 3 | T10: =SUM(D10:D13) -> 0 | U10: =SUM(E10:E13) -> 0 | V10: =SUM(F10:F13) -> 6 | W10: =SUM(G10:G13) -> 0 | X10: =SUM(H10:H13) -> 0 | Y10: =SUM(I10:I13) -> 0 | Z10: =SUM(J10:J13) -> 5 | ... AF10: =SUM(P10:P13) -> 43
B11: 07.15 - 07.30 | C11: 2 | D11: 0 | E11: 0 | F11: 3 | G11: 0 | H11: 0 | I11: 0 | J11: 3 | K11: 0 | L11: 1 | M11: 3 | N11: 0 | O11: =SUM(C11:L11,N11) -> 9 | P11: =SUM(C11:N11) -> 12 | R11: 0800-0900 | S11: =SUM(C14:C17) -> 11 | T11: =SUM(D14:D17) -> 1 | U11: =SUM(E14:E17) -> 3 | V11: =SUM(F14:F17) -> 11 | W11: =SUM(G14:G17) -> 0 | X11: =SUM(H14:H17) -> 0 | Y11: =SUM(I14:I17) -> 6 | Z11: =SUM(J14:J17) -> 1 | ... AF11: =SUM(P14:P17) -> 168
B12: 07.30 - 07.45 | C12: 0 | D12: 0 | E12: 0 | F12: 0 | G12: 0 | H12: 0 | I12: 0 | J12: 0 | K12: 0 | L12: 1 | M12: 7 | N12: 0 | O12: =SUM(C12:L12,N12) -> 1 | P12: =SUM(C12:N12) -> 8 | R12: 0900-1000 | S12: =SUM(C18:C21) -> 22 | T12: =SUM(D18:D21) -> 4 | U12: =SUM(E18:E21) -> 7 | V12: =SUM(F18:F21) -> 13 | W12: =SUM(G18:G21) -> 6 | X12: =SUM(H18:H21) -> 2 | Y12: =SUM(I18:I21) -> 1 | Z12: =SUM(J18:J21) -> 1 | ... AF12: =SUM(P18:P21) -> 264
B13: 07.45 - 08.00 | C13: 0 | D13: 0 | E13: 0 | F13: 1 | G13: 0 | H13: 0 | I13: 0 | J13: 0 | K13: 1 | L13: 2 | M13: 12 | N13: 0 | O13: =SUM(C13:L13,N13) -> 4 | P13: =SUM(C13:N13) -> 16 | R13: 1000-1100 | S13: =SUM(C22:C25) -> 17 | T13: =SUM(D22:D25) -> 7 | U13: =SUM(E22:E25) -> 11 | V13: =SUM(F22:F25) -> 18 | W13: =SUM(G22:G25) -> 0 | X13: =SUM(H22:H25) -> 0 | Y13: =SUM(I22:I25) -> 8 | Z13: =SUM(J22:J25) -> 0 | ... AF13: =SUM(P22:P25) -> 236
B14: 08.00 - 08.15 | C14: 1 | D14: 0 | E14: 1 | F14: 2 | G14: 0 | H14: 0 | I14: 1 | J14: 0 | K14: 0 | L14: 0 | M14: 23 | N14: 0 | O14: =SUM(C14:L14,N14) -> 5 | P14: =SUM(C14:N14) -> 28 | R14: 1100-1200 | S14: =SUM(C26:C29) -> 19 | T14: =SUM(D26:D29) -> 6 | U14: =SUM(E26:E29) -> 9 | V14: =SUM(F26:F29) -> 22 | W14: =SUM(G26:G29) -> 0 | X14: =SUM(H26:H29) -> 1 | Y14: =SUM(I26:I29) -> 1 | Z14: =SUM(J26:J29) -> 1 | ... AF14: =SUM(P26:P29) -> 251
B15: 08.15 - 08.30 | C15: 2 | D15: 1 | E15: 1 | F15: 4 | G15: 0 | H15: 0 | I15: 2 | J15: 0 | K15: 0 | L15: 0 | M15: 39 | N15: 0 | O15: =SUM(C15:L15,N15) -> 10 | P15: =SUM(C15:N15) -> 49 | R15: 1200-1300 | S15: =SUM(C30:C33) -> 16 | T15: =SUM(D30:D33) -> 9 | U15: =SUM(E30:E33) -> 13 | V15: =SUM(F30:F33) -> 11 | W15: =SUM(G30:G33) -> 0 | X15: =SUM(H30:H33) -> 0 | Y15: =SUM(I30:I33) -> 3 | Z15: =SUM(J30:J33) -> 14 | ... AF15: =SUM(P30:P33) -> 266
B16: 08.30 - 08.45 | C16: 3 | D16: 0 | E16: 0 | F16: 2 | G16: 0 | H16: 0 | I16: 1 | J16: 0 | K16: 0 | L16: 0 | M16: 27 | N16: 0 | O16: =SUM(C16:L16,N16) -> 6 | P16: =SUM(C16:N16) -> 33 | R16: 1300-1400 | S16: =SUM(C34:C37) -> 23 | T16: =SUM(D34:D37) -> 6 | U16: =SUM(E34:E37) -> 10 | V16: =SUM(F34:F37) -> 13 | W16: =SUM(G34:G37) -> 0 | X16: =SUM(H34:H37) -> 0 | Y16: =SUM(I34:I37) -> 8 | Z16: =SUM(J34:J37) -> 3 | ... AF16: =SUM(P34:P37) -> 195
B17: 08.45 - 9.00 | C17: 5 | D17: 0 | E17: 1 | F17: 3 | G17: 0 | H17: 0 | I17: 2 | J17: 1 | K17: 1 | L17: 0 | M17: 45 | N17: 0 | O17: =SUM(C17:L17,N17) -> 13 | P17: =SUM(C17:N17) -> 58 | R17: 1400-1500 | S17: =SUM(C38:C41) -> 29 | T17: =SUM(D38:D41) -> 8 | U17: =SUM(E38:E41) -> 9 | V17: =SUM(F38:F41) -> 16 | W17: =SUM(G38:G41) -> 0 | X17: =SUM(H38:H41) -> 0 | Y17: =SUM(I38:I41) -> 6 | Z17: =SUM(J38:J41) -> 6 | ... AF17: =SUM(P38:P41) -> 281
B18: 09.00 - 09.15 | C18: 4 | D18: 0 | E18: 1 | F18: 3 | G18: 0 | H18: 0 | I18: 0 | J18: 0 | K18: 0 | L18: 1 | M18: 36 | N18: 0 | O18: =SUM(C18:L18,N18) -> 9 | P18: =SUM(C18:N18) -> 45 | R18: 1500-1600 | S18: =SUM(C42:C45) -> 23 | T18: =SUM(D42:D45) -> 6 | U18: =SUM(E42:E45) -> 9 | V18: =SUM(F42:F45) -> 15 | W18: =SUM(G42:G45) -> 0 | X18: =SUM(H42:H45) -> 0 | Y18: =SUM(I42:I45) -> 4 | Z18: =SUM(J42:J45) -> 1 | ... AF18: =SUM(P42:P45) -> 240
B19: 09.15 - 09.30 | C19: 7 | D19: 1 | E19: 1 | F19: 5 | G19: 0 | H19: 1 | I19: 0 | J19: 0 | K19: 0 | L19: 2 | M19: 60 | N19: 0 | O19: =SUM(C19:L19,N19) -> 17 | P19: =SUM(C19:N19) -> 77 | R19: 1600-1700 | S19: =SUM(C46:C49) -> 35 | T19: =SUM(D46:D49) -> 9 | U19: =SUM(E46:E49) -> 15 | V19: =SUM(F46:F49) -> 16 | W19: =SUM(G46:G49) -> 1 | X19: =SUM(H46:H49) -> 0 | Y19: =SUM(I46:I49) -> 10 | Z19: =SUM(J46:J49) -> 13 | ... AF19: =SUM(P46:P49) -> 239
B20: 09.30 - 09.45 | C20: 4 | D20: 1 | E20: 2 | F20: 2 | G20: 2 | H20: 0 | I20: 0 | J20: 0 | K20: 0 | L20: 1 | M20: 40 | N20: 0 | O20: =SUM(C20:L20,N20) -> 12 | P20: =SUM(C20:N20) -> 52 | R20: 1700-1800 | S20: =SUM(C50:C53) -> 49 | T20: =SUM(D50:D53) -> 16 | U20: =SUM(E50:E53) -> 23 | V20: =SUM(F50:F53) -> 12 | W20: =SUM(G50:G53) -> 0 | X20: =SUM(H50:H53) -> 0 | Y20: =SUM(I50:I53) -> 12 | Z20: =SUM(J50:J53) -> 9 | ... AF20: =SUM(P50:P53) -> 384
B21: 09.45 - 10.00 | C21: 7 | D21: 2 | E21: 3 | F21: 3 | G21: 4 | H21: 1 | I21: 1 | J21: 1 | K21: 0 | L21: 2 | M21: 66 | N21: 0 | O21: =SUM(C21:L21,N21) -> 24 | P21: =SUM(C21:N21) -> 90 | R21: 1800-1900 | S21: =SUM(C54:C57) -> 35 | T21: =SUM(D54:D57) -> 12 | U21: =SUM(E54:E57) -> 17 | V21: =SUM(F54:F57) -> 16 | W21: =SUM(G54:G57) -> 0 | X21: =SUM(H54:H57) -> 0 | Y21: =SUM(I54:I57) -> 6 | Z21: =SUM(J54:J57) -> 8 | ... AF21: =SUM(P54:P57) -> 291
B22: 10.00 - 10.15 | C22: 4 | D22: 2 | E22: 2 | F22: 2 | G22: 0 | H22: 0 | I22: 1 | J22: 0 | K22: 4 | L22: 0 | M22: 29 | N22: 0 | O22: =SUM(C22:L22,N22) -> 15 | P22: =SUM(C22:N22) -> 44 | R22: 1900-2000 | S22: =SUM(C58:C61) -> 38 | T22: =SUM(D58:D61) -> 9 | U22: =SUM(E58:E61) -> 14 | V22: =SUM(F58:F61) -> 21 | W22: =SUM(G58:G61) -> 3 | X22: =SUM(H58:H61) -> 0 | Y22: =SUM(I58:I61) -> 1 | Z22: =SUM(J58:J61) -> 7 | ... AF22: =SUM(P58:P61) -> 266
B23: 10.15 - 10.30 | C23: 7 | D23: 2 | E23: 4 | F23: 3 | G23: 0 | H23: 0 | I23: 2 | J23: 0 | K23: 6 | L23: 1 | M23: 48 | N23: 0 | O23: =SUM(C23:L23,N23) -> 25 | P23: =SUM(C23:N23) -> 73 | R23: 2000-2100 | S23: =SUM(C62:C65) -> 11 | T23: =SUM(D62:D65) -> 9 | U23: =SUM(E62:E65) -> 15 | V23: =SUM(F62:F65) -> 14 | W23: =SUM(G62:G65) -> 1 | X23: =SUM(H62:H65) -> 6 | Y23: =SUM(I62:I65) -> 1 | Z23: =SUM(J62:J65) -> 6 | ... AF23: =SUM(P62:P65) -> 168
B24: 10.30 - 10.45 | C24: 2 | D24: 1 | E24: 2 | F24: 5 | G24: 0 | H24: 0 | I24: 2 | J24: 0 | K24: 2 | L24: 2 | M24: 28 | N24: 0 | O24: =SUM(C24:L24,N24) -> 16 | P24: =SUM(C24:N24) -> 44 | R24: 2100-2200 | S24: =SUM(C66:C69) -> 11 | T24: =SUM(D66:D69) -> 4 | U24: =SUM(E66:E69) -> 5 | V24: =SUM(F66:F69) -> 9 | W24: =SUM(G66:G69) -> 3 | X24: =SUM(H66:H69) -> 1 | Y24: =SUM(I66:I69) -> 0 | Z24: =SUM(J66:J69) -> 1 | ... AF24: =SUM(P66:P69) -> 104
B25: 10.45 - 11.00 | C25: 4 | D25: 2 | E25: 3 | F25: 8 | G25: 0 | H25: 0 | I25: 3 | J25: 0 | K25: 4 | L25: 4 | M25: 47 | N25: 0 | O25: =SUM(C25:L25,N25) -> 28 | P25: =SUM(C25:N25) -> 75 | R25: 2200-2300 | S25: =SUM(C70:C73) -> 4 | T25: =SUM(D70:D73) -> 5 | U25: =SUM(E70:E73) -> 6 | V25: =SUM(F70:F73) -> 5 | W25: =SUM(G70:G73) -> 0 | X25: =SUM(H70:H73) -> 1 | Y25: =SUM(I70:I73) -> 3 | Z25: =SUM(J70:J73) -> 8 | ... AF25: =SUM(P70:P73) -> 78
B26: 11.00 - 11.15 | C26: 2 | D26: 1 | E26: 1 | F26: 4 | G26: 0 | H26: 0 | I26: 0 | J26: 0 | K26: 2 | L26: 0 | M26: 38 | N26: 0 | O26: =SUM(C26:L26,N26) -> 10 | P26: =SUM(C26:N26) -> 48 | R26: 2300-0000 | S26: =SUM(C74:C77) -> 5 | T26: =SUM(D74:D77) -> 4 | U26: =SUM(E74:E77) -> 5 | V26: =SUM(F74:F77) -> 1 | W26: =SUM(G74:G77) -> 2 | X26: =SUM(H74:H77) -> 1 | Y26: =SUM(I74:I77) -> 1 | Z26: =SUM(J74:J77) -> 6 | ... AF26: =SUM(P74:P77) -> 53
B27: 11.15 - 11.30 | C27: 4 | D27: 1 | E27: 2 | F27: 7 | G27: 0 | H27: 0 | I27: 1 | J27: 0 | K27: 3 | L27: 1 | M27: 64 | N27: 0 | O27: =SUM(C27:L27,N27) -> 19 | P27: =SUM(C27:N27) -> 83 | R27: 0000-0100 | S27: =SUM(C78:C81) -> 4 | T27: =SUM(D78:D81) -> 0 | U27: =SUM(E78:E81) -> 1 | V27: =SUM(F78:F81) -> 4 | W27: =SUM(G78:G81) -> 0 | X27: =SUM(H78:H81) -> 3 | Y27: =SUM(I78:I81) -> 0 | Z27: =SUM(J78:J81) -> 8 | ... AF27: =SUM(P78:P81) -> 36
B28: 11.30 - 11.45 | C28: 5 | D28: 2 | E28: 2 | F28: 4 | G28: 0 | H28: 0 | I28: 0 | J28: 0 | K28: 2 | L28: 1 | M28: 28 | N28: 0 | O28: =SUM(C28:L28,N28) -> 16 | P28: =SUM(C28:N28) -> 44 | R28: 0100-0200 | S28: =SUM(C82:C85) -> 0 | T28: =SUM(D82:D85) -> 0 | U28: =SUM(E82:E85) -> 0 | V28: =SUM(F82:F85) -> 0 | W28: =SUM(G82:G85) -> 0 | X28: =SUM(H82:H85) -> 1 | Y28: =SUM(I82:I85) -> 0 | Z28: =SUM(J82:J85) -> 0 | ... AF28: =SUM(P82:P85) -> 14
B29: 11.45 - 12.00 | C29: 8 | D29: 2 | E29: 4 | F29: 7 | G29: 0 | H29: 1 | I29: 0 | J29: 1 | K29: 3 | L29: 3 | M29: 47 | N29: 0 | O29: =SUM(C29:L29,N29) -> 29 | P29: =SUM(C29:N29) -> 76 | R29: 0200-0300 | S29: =SUM(C86:C89) -> 0 | T29: =SUM(D86:D89) -> 0 | U29: =SUM(E86:E89) -> 0 | V29: =SUM(F86:F89) -> 1 | W29: =SUM(G86:G89) -> 0 | X29: =SUM(H86:H89) -> 0 | Y29: =SUM(I86:I89) -> 0 | Z29: =SUM(J86:J89) -> 0 | ... AF29: =SUM(P86:P89) -> 3
B30: 12.00 - 12.15 | C30: 4 | D30: 2 | E30: 3 | F30: 2 | G30: 0 | H30: 0 | I30: 0 | J30: 3 | K30: 4 | L30: 0 | M30: 41 | N30: 0 | O30: =SUM(C30:L30,N30) -> 18 | P30: =SUM(C30:N30) -> 59 | R30: 0300-0400 | S30: =SUM(C90:C93) -> 0 | T30: =SUM(D90:D93) -> 0 | U30: =SUM(E90:E93) -> 0 | V30: =SUM(F90:F93) -> 1 | W30: =SUM(G90:G93) -> 0 | X30: =SUM(H90:H93) -> 0 | Y30: =SUM(I90:I93) -> 0 | Z30: =SUM(J90:J93) -> 1 | ... AF30: =SUM(P90:P93) -> 2
B31: 12.15 - 12.30 | C31: 7 | D31: 4 | E31: 5 | F31: 4 | G31: 0 | H31: 0 | I31: 0 | J31: 5 | K31: 6 | L31: 1 | M31: 68 | N31: 0 | O31: =SUM(C31:L31,N31) -> 32 | P31: =SUM(C31:N31) -> 100 | R31: 0400-0500 | S31: =SUM(C94:C97) -> 0 | T31: =SUM(D94:D97) -> 0 | U31: =SUM(E94:E97) -> 0 | V31: =SUM(F94:F97) -> 0 | W31: =SUM(G94:G97) -> 0 | X31: =SUM(H94:H97) -> 0 | Y31: =SUM(I94:I97) -> 0 | Z31: =SUM(J94:J97) -> 0 | ... AF31: =SUM(P94:P97) -> 1
B32: 12.30 - 12.45 | C32: 2 | D32: 1 | E32: 2 | F32: 2 | G32: 0 | H32: 0 | I32: 1 | J32: 2 | K32: 2 | L32: 2 | M32: 26 | N32: 0 | O32: =SUM(C32:L32,N32) -> 14 | P32: =SUM(C32:N32) -> 40 | R32: 0500-0600 | S32: =SUM(C98:C101) -> 4 | T32: =SUM(D98:D101) -> 0 | U32: =SUM(E98:E101) -> 2 | V32: =SUM(F98:F101) -> 6 | W32: =SUM(G98:G101) -> 0 | X32: =SUM(H98:H101) -> 0 | Y32: =SUM(I98:I101) -> 0 | Z32: =SUM(J98:J101) -> 0 | ... AF32: =SUM(P98:P101) -> 24
B33: 12.45 - 13.00 | C33: 3 | D33: 2 | E33: 3 | F33: 3 | G33: 0 | H33: 0 | I33: 2 | J33: 4 | K33: 3 | L33: 3 | M33: 44 | N33: 0 | O33: =SUM(C33:L33,N33) -> 23 | P33: =SUM(C33:N33) -> 67 | R33: 0600-0700 | S33: =SUM(C102:C105) -> 11 | T33: =SUM(D102:D105) -> 1 | U33: =SUM(E102:E105) -> 3 | V33: =SUM(F102:F105) -> 6 | W33: =SUM(G102:G105) -> 0 | X33: =SUM(H102:H105) -> 0 | Y33: =SUM(I102:I105) -> 0 | Z33: =SUM(J102:J105) -> 0 | ... AF33: =SUM(P102:P105) -> 37
B34: 13.00 - 13.15 | C34: 2 | D34: 1 | E34: 2 | F34: 2 | G34: 0 | H34: 0 | I34: 2 | J34: 0 | K34: 3 | L34: 2 | M34: 4 | N34: 0 | O34: =SUM(C34:L34,N34) -> 14 | P34: =SUM(C34:N34) -> 18 | R34: AM Peak Hr | S34: =MAX(S10:S12) -> 22 | T34: =MAX(T10:T12) -> 4 | U34: =MAX(U10:U12) -> 7 | V34: =MAX(V10:V12) -> 13 | W34: =MAX(W10:W12) -> 6 | X34: =MAX(X10:X12) -> 2 | Y34: =MAX(Y10:Y12) -> 6 | Z34: =MAX(Z10:Z12) -> 5 | ... AF34: =MAX(AF10:AF12) -> 264
B35: 13.15 - 13.30 | C35: 4 | D35: 2 | E35: 3 | F35: 3 | G35: 0 | H35: 0 | I35: 3 | J35: 0 | K35: 5 | L35: 4 | M35: 6 | N35: 0 | O35: =SUM(C35:L35,N35) -> 24 | P35: =SUM(C35:N35) -> 30 | R35: IP Peak Hr | S35: =MAX(S13:S18) -> 29 | T35: =MAX(T13:T18) -> 9 | U35: =MAX(U13:U18) -> 13 | V35: =MAX(V13:V18) -> 22 | W35: =MAX(W13:W18) -> 0 | X35: =MAX(X13:X18) -> 1 | Y35: =MAX(Y13:Y18) -> 8 | Z35: =MAX(Z13:Z18) -> 14 | ... AF35: =MAX(AF13:AF18) -> 281
B36: 13.30 - 13.45 | C36: 6 | D36: 1 | E36: 2 | F36: 3 | G36: 0 | H36: 0 | I36: 1 | J36: 1 | K36: 0 | L36: 1 | M36: 39 | N36: 0 | O36: =SUM(C36:L36,N36) -> 15 | P36: =SUM(C36:N36) -> 54 | R36: PM Peak Hr | S36: =MAX(S19:S21) -> 49 | T36: =MAX(T19:T21) -> 16 | U36: =MAX(U19:U21) -> 23 | V36: =MAX(V19:V21) -> 16 | W36: =MAX(W19:W21) -> 1 | X36: =MAX(X19:X21) -> 0 | Y36: =MAX(Y19:Y21) -> 12 | Z36: =MAX(Z19:Z21) -> 13 | ... AF36: =MAX(AF19:AF21) -> 384
B37: 13.45 - 14.00 | C37: 11 | D37: 2 | E37: 3 | F37: 5 | G37: 0 | H37: 0 | I37: 2 | J37: 2 | K37: 1 | L37: 2 | M37: 65 | N37: 0 | O37: =SUM(C37:L37,N37) -> 28 | P37: =SUM(C37:N37) -> 93 | R37: AM Period | S37: =SUM(S10:S12) -> 36 | T37: =SUM(T10:T12) -> 5 | U37: =SUM(U10:U12) -> 10 | V37: =SUM(V10:V12) -> 30 | W37: =SUM(W10:W12) -> 6 | X37: =SUM(X10:X12) -> 2 | Y37: =SUM(Y10:Y12) -> 7 | Z37: =SUM(Z10:Z12) -> 7 | ... AF37: =SUM(AF10:AF12) -> 475
B38: 14.00 - 14.15 | C38: 5 | D38: 1 | E38: 1 | F38: 2 | G38: 0 | H38: 0 | I38: 1 | J38: 0 | K38: 0 | L38: 0 | M38: 37 | N38: 0 | O38: =SUM(C38:L38,N38) -> 10 | P38: =SUM(C38:N38) -> 47 | R38: IP Period | S38: =SUM(S13:S18) -> 127 | T38: =SUM(T13:T18) -> 42 | U38: =SUM(U13:U18) -> 61 | V38: =SUM(V13:V18) -> 95 | W38: =SUM(W13:W18) -> 0 | X38: =SUM(X13:X18) -> 1 | Y38: =SUM(Y13:Y18) -> 30 | Z38: =SUM(Z13:Z18) -> 25 | ... AF38: =SUM(AF13:AF18) -> 1469
B39: 14.15 - 14.30 | C39: 8 | D39: 2 | E39: 2 | F39: 4 | G39: 0 | H39: 0 | I39: 2 | J39: 0 | K39: 1 | L39: 1 | M39: 62 | N39: 0 | O39: =SUM(C39:L39,N39) -> 20 | P39: =SUM(C39:N39) -> 82 | R39: PM Period | S39: =SUM(S19:S21) -> 119 | T39: =SUM(T19:T21) -> 37 | U39: =SUM(U19:U21) -> 55 | V39: =SUM(V19:V21) -> 44 | W39: =SUM(W19:W21) -> 1 | X39: =SUM(X19:X21) -> 0 | Y39: =SUM(Y19:Y21) -> 28 | Z39: =SUM(Z19:Z21) -> 30 | ... AF39: =SUM(AF19:AF21) -> 914
B40: 14.30 - 14.45 | C40: 6 | D40: 2 | E40: 2 | F40: 4 | G40: 0 | H40: 0 | I40: 1 | J40: 2 | K40: 4 | L40: 1 | M40: 26 | N40: 0 | O40: =SUM(C40:L40,N40) -> 22 | P40: =SUM(C40:N40) -> 48 | R40: 12 Hours | S40: =SUM(S10:S21) -> 282 | T40: =SUM(T10:T21) -> 84 | U40: =SUM(U10:U21) -> 126 | V40: =SUM(V10:V21) -> 169 | W40: =SUM(W10:W21) -> 7 | X40: =SUM(X10:X21) -> 3 | Y40: =SUM(Y10:Y21) -> 65 | Z40: =SUM(Z10:Z21) -> 62 | ... AF40: =SUM(AF10:AF21) -> 2858
B41: 14.45 - 15.00 | C41: 10 | D41: 3 | E41: 4 | F41: 6 | G41: 0 | H41: 0 | I41: 2 | J41: 4 | K41: 7 | L41: 2 | M41: 66 | N41: 0 | O41: =SUM(C41:L41,N41) -> 38 | P41: =SUM(C41:N41) -> 104 | R41: 24 Hrs/ADT | S41: =SUM(S10:S33) -> 370 | T41: =SUM(T10:T33) -> 116 | U41: =SUM(U10:U33) -> 177 | V41: =SUM(V10:V33) -> 237 | W41: =SUM(W10:W33) -> 16 | X41: =SUM(X10:X33) -> 16 | Y41: =SUM(Y10:Y33) -> 71 | Z41: =SUM(Z10:Z33) -> 99 | ... AF41: =SUM(AF10:AF33) -> 3644
B42: 15.00 - 15.15 | C42: 4 | D42: 1 | E42: 1 | F42: 4 | G42: 0 | H42: 0 | I42: 1 | J42: 0 | K42: 4 | L42: 0 | M42: 34 | N42: 0 | O42: =SUM(C42:L42,N42) -> 15 | P42: =SUM(C42:N42) -> 49 | R42: NEF | S42: =S41/S40 -> 1.3120567 | T42: =T41/T40 -> 1.3809524 | U42: =U41/U40 -> 1.4047619 | V42: =V41/V40 -> 1.4023669 | W42: =W41/W40 -> 2.2857143 | X42: =X41/X40 -> 5.3333333 | Y42: =Y41/Y40 -> 1.0923077 | Z42: =Z41/Z40 -> 1.5967742 | ... AF42: =AF41/AF40 -> 1.2750175
...

Sheet 08.09 Ishaka-Katungulu-24h
B1: Consultancy services for Preparation of Expressway Development Master Plan (EDMP) for Uganda
B2: MANUAL CLASSIFIED COUNT (MCC)
B3: ROAD NAME: | C3: ='09.09 Ishaka-Katungulu'!C3:G3 -> MCC - C4 - STN104 - ISHAKA KATUNGULU ROAD
C5: Date | D5: 08.09.19 | F5: Location | G5: ='07.09. Katungulu-Ishaka-24h'!G5:H5 -> Rubirizi | J5: Surveyor | K5: ='07.09. Katungulu-Ishaka-24h'!K5:L5 -> xxx
C6: Dir. From | D6: ='09.09 Ishaka-Katungulu'!D6:E6 -> Ishaka | F6: Dir. To | G6: ='09.09 Ishaka-Katungulu'!G6:H6 -> Katungulu | J6: Supervisor | K6: ='07.09. Katungulu-Ishaka-24h'!K6:L6 -> xxx
B8: Time / Veh Type | R8: SUMMARY TRAFFIC VOLUMES
C9: 1. Car | D9: 2. Station Wagon | E9: 3. Pickups | F9: 4. Minibus, matatu | G9: 5. Medium bus | H9: 6. Large Bus | I9: 7. Light Truck | J9: 8. Medium Truck | K9: 9. Heavy truck | L9: 10. Truck Trailer | M9: 11. Motor cycles | N9: 12. Tractors | O9: Total Excl M/Cycles | P9: Total All | R9: Time | S9: 1. Car | T9: 2. Station Wagon | U9: 3. Pickups | V9: 4. Minibus, matatu | W9: 5. Medium bus | X9: 6. Large Bus | Y9: 7. Light Truck | Z9: 8. Medium Truck | AA9: 9. Heavy truck | AB9: 10. Truck Trailer | AC9: 11. Motorcycles | AD9: 12. Tractors, Graders | AE9: Total Excl M/ Cycles | AF9: Total All
B10: 07.00 - 07.15 | C10: 2 | D10: =ROUND((0.4*E10),0) -> 0 | E10: 1 | F10: 0 | G10: 0 | H10: 0 | I10: 0 | J10: 0 | K10: 0 | L10: 0 | M10: 8 | N10: 0 | O10: =SUM(C10:L10,N10) -> 3 | P10: =SUM(C10:N10) -> 11 | R10: 0700-0800 | S10: =SUM(C10:C13) -> 8 | T10: =SUM(D10:D13) -> 1 | U10: =SUM(E10:E13) -> 5 | V10: =SUM(F10:F13) -> 6 | W10: =SUM(G10:G13) -> 0 | X10: =SUM(H10:H13) -> 0 | Y10: =SUM(I10:I13) -> 0 | Z10: =SUM(J10:J13) -> 3 | ... AF10: =SUM(P10:P13) -> 149
B11: 07.15 - 07.30 | C11: 6 | D11: =ROUND((0.4*E11),0) -> 1 | E11: 3 | F11: 0 | G11: 0 | H11: 0 | I11: 0 | J11: 0 | K11: 0 | L11: 1 | M11: 21 | N11: 0 | O11: =SUM(C11:L11,N11) -> 11 | P11: =SUM(C11:N11) -> 32 | R11: 0800-0900 | S11: =SUM(C14:C17) -> 14 | T11: =SUM(D14:D17) -> 3 | U11: =SUM(E14:E17) -> 8 | V11: =SUM(F14:F17) -> 11 | W11: =SUM(G14:G17) -> 0 | X11: =SUM(H14:H17) -> 0 | Y11: =SUM(I14:I17) -> 1 | Z11: =SUM(J14:J17) -> 7 | ... AF11: =SUM(P14:P17) -> 369
B12: 07.30 - 07.45 | C12: 0 | D12: =ROUND((0.4*E12),0) -> 0 | E12: 0 | F12: 2 | G12: 0 | H12: 0 | I12: 0 | J12: 1 | K12: 0 | L12: 0 | M12: 27 | N12: 0 | O12: =SUM(C12:L12,N12) -> 3 | P12: =SUM(C12:N12) -> 30 | R12: 0900-1000 | S12: =SUM(C18:C21) -> 23 | T12: =SUM(D18:D21) -> 2 | U12: =SUM(E18:E21) -> 7 | V12: =SUM(F18:F21) -> 7 | W12: =SUM(G18:G21) -> 0 | X12: =SUM(H18:H21) -> 3 | Y12: =SUM(I18:I21) -> 2 | Z12: =SUM(J18:J21) -> 6 | ... AF12: =SUM(P18:P21) -> 311
B13: 07.45 - 08.00 | C13: 0 | D13: =ROUND((0.4*E13),0) -> 0 | E13: 1 | F13: 4 | G13: 0 | H13: 0 | I13: 0 | J13: 2 | K13: 1 | L13: 1 | M13: 67 | N13: 0 | O13: =SUM(C13:L13,N13) -> 9 | P13: =SUM(C13:N13) -> 76 | R13: 1000-1100 | S13: =SUM(C22:C25) -> 22 | T13: =SUM(D22:D25) -> 10 | U13: =SUM(E22:E25) -> 25 | V13: =SUM(F22:F25) -> 11 | W13: =SUM(G22:G25) -> 0 | X13: =SUM(H22:H25) -> 0 | Y13: =SUM(I22:I25) -> 0 | Z13: =SUM(J22:J25) -> 8 | ... AF13: =SUM(P22:P25) -> 321
B14: 08.00 - 08.15 | C14: 2 | D14: =ROUND((0.4*E14),0) -> 0 | E14: 0 | F14: 2 | G14: 0 | H14: 0 | I14: 0 | J14: 2 | K14: 4 | L14: 1 | M14: 41 | N14: 0 | O14: =SUM(C14:L14,N14) -> 11 | P14: =SUM(C14:N14) -> 52 | R14: 1100-1200 | S14: =SUM(C26:C29) -> 19 | T14: =SUM(D26:D29) -> 7 | U14: =SUM(E26:E29) -> 18 | V14: =SUM(F26:F29) -> 8 | W14: =SUM(G26:G29) -> 0 | X14: =SUM(H26:H29) -> 0 | Y14: =SUM(I26:I29) -> 2 | Z14: =SUM(J26:J29) -> 2 | ... AF14: =SUM(P26:P29) -> 290
B15: 08.15 - 08.30 | C15: 6 | D15: =ROUND((0.4*E15),0) -> 0 | E15: 1 | F15: 5 | G15: 0 | H15: 0 | I15: 0 | J15: 4 | K15: 9 | L15: 2 | M15: 103 | N15: 0 | O15: =SUM(C15:L15,N15) -> 27 | P15: =SUM(C15:N15) -> 130 | R15: 1200-1300 | S15: =SUM(C30:C33) -> 27 | T15: =SUM(D30:D33) -> 7 | U15: =SUM(E30:E33) -> 19 | V15: =SUM(F30:F33) -> 17 | W15: =SUM(G30:G33) -> 0 | X15: =SUM(H30:H33) -> 0 | Y15: =SUM(I30:I33) -> 4 | Z15: =SUM(J30:J33) -> 2 | ... AF15: =SUM(P30:P33) -> 351
B16: 08.30 - 08.45 | C16: 2 | D16: =ROUND((0.4*E16),0) -> 1 | E16: 2 | F16: 1 | G16: 0 | H16: 0 | I16: 0 | J16: 0 | K16: 2 | L16: 1 | M16: 44 | N16: 0 | O16: =SUM(C16:L16,N16) -> 9 | P16: =SUM(C16:N16) -> 53 | R16: 1300-1400 | S16: =SUM(C34:C37) -> 38 | T16: =SUM(D34:D37) -> 3 | U16: =SUM(E34:E37) -> 9 | V16: =SUM(F34:F37) -> 12 | W16: =SUM(G34:G37) -> 0 | X16: =SUM(H34:H37) -> 1 | Y16: =SUM(I34:I37) -> 1 | Z16: =SUM(J34:J37) -> 11 | ... AF16: =SUM(P34:P37) -> 410
B17: 08.45 - 9.00 | C17: 4 | D17: =ROUND((0.4*E17),0) -> 2 | E17: 5 | F17: 3 | G17: 0 | H17: 0 | I17: 1 | J17: 1 | K17: 5 | L17: 3 | M17: 110 | N17: 0 | O17: =SUM(C17:L17,N17) -> 24 | P17: =SUM(C17:N17) -> 134 | R17: 1400-1500 | S17: =SUM(C38:C41) -> 11 | T17: =SUM(D38:D41) -> 2 | U17: =SUM(E38:E41) -> 7 | V17: =SUM(F38:F41) -> 14 | W17: =SUM(G38:G41) -> 0 | X17: =SUM(H38:H41) -> 0 | Y17: =SUM(I38:I41) -> 4 | Z17: =SUM(J38:J41) -> 2 | ... AF17: =SUM(P38:P41) -> 253
B18: 09.00 - 09.15 | C18: 4 | D18: =ROUND((0.4*E18),0) -> 0 | E18: 1 | F18: 2 | G18: 0 | H18: 1 | I18: 0 | J18: 1 | K18: 1 | L18: 0 | M18: 38 | N18: 0 | O18: =SUM(C18:L18,N18) -> 10 | P18: =SUM(C18:N18) -> 48 | R18: 1500-1600 | S18: =SUM(C42:C45) -> 21 | T18: =SUM(D42:D45) -> 6 | U18: =SUM(E42:E45) -> 13 | V18: =SUM(F42:F45) -> 13 | W18: =SUM(G42:G45) -> 0 | X18: =SUM(H42:H45) -> 0 | Y18: =SUM(I42:I45) -> 3 | Z18: =SUM(J42:J45) -> 7 | ... AF18: =SUM(P42:P45) -> 316
B19: 09.15 - 09.30 | C19: 11 | D19: =ROUND((0.4*E19),0) -> 1 | E19: 2 | F19: 4 | G19: 0 | H19: 2 | I19: 1 | J19: 2 | K19: 3 | L19: 0 | M19: 94 | N19: 0 | O19: =SUM(C19:L19,N19) -> 26 | P19: =SUM(C19:N19) -> 120 | R19: 1600-1700 | S19: =SUM(C46:C49) -> 14 | T19: =SUM(D46:D49) -> 6 | U19: =SUM(E46:E49) -> 15 | V19: =SUM(F46:F49) -> 10 | W19: =SUM(G46:G49) -> 0 | X19: =SUM(H46:H49) -> 0 | Y19: =SUM(I46:I49) -> 1 | Z19: =SUM(J46:J49) -> 1 | ... AF19: =SUM(P46:P49) -> 263
B20: 09.30 - 09.45 | C20: 2 | D20: =ROUND((0.4*E20),0) -> 0 | E20: 1 | F20: 0 | G20: 0 | H20: 0 | I20: 0 | J20: 1 | K20: 2 | L20: 0 | M20: 34 | N20: 0 | O20: =SUM(C20:L20,N20) -> 6 | P20: =SUM(C20:N20) -> 40 | R20: 1700-1800 | S20: =SUM(C50:C53) -> 24 | T20: =SUM(D50:D53) -> 0 | U20: =SUM(E50:E53) -> 2 | V20: =SUM(F50:F53) -> 10 | W20: =SUM(G50:G53) -> 0 | X20: =SUM(H50:H53) -> 0 | Y20: =SUM(I50:I53) -> 4 | Z20: =SUM(J50:J53) -> 5 | ... AF20: =SUM(P50:P53) -> 344
B21: 09.45 - 10.00 | C21: 6 | D21: =ROUND((0.4*E21),0) -> 1 | E21: 3 | F21: 1 | G21: 0 | H21: 0 | I21: 1 | J21: 2 | K21: 4 | L21: 1 | M21: 84 | N21: 0 | O21: =SUM(C21:L21,N21) -> 19 | P21: =SUM(C21:N21) -> 103 | R21: 1800-1900 | S21: =SUM(C54:C57) -> 20 | T21: =SUM(D54:D57) -> 6 | U21: =SUM(E54:E57) -> 13 | V21: =SUM(F54:F57) -> 14 | W21: =SUM(G54:G57) -> 0 | X21: =SUM(H54:H57) -> 1 | Y21: =SUM(I54:I57) -> 3 | Z21: =SUM(J54:J57) -> 4 | ... AF21: =SUM(P54:P57) -> 302
B22: 10.00 - 10.15 | C22: 2 | D22: =ROUND((0.4*E22),0) -> 1 | E22: 3 | F22: 1 | G22: 0 | H22: 0 | I22: 0 | J22: 0 | K22: 2 | L22: 1 | M22: 32 | N22: 0 | O22: =SUM(C22:L22,N22) -> 10 | P22: =SUM(C22:N22) -> 42 | R22: 1900-2000 | S22: =SUM(C58:C61) -> 16 | T22: =SUM(D58:D61) -> 14 | U22: =SUM(E58:E61) -> 36 | V22: =SUM(F58:F61) -> 6 | W22: =SUM(G58:G61) -> 0 | X22: =SUM(H58:H61) -> 0 | Y22: =SUM(I58:I61) -> 2 | Z22: =SUM(J58:J61) -> 0 | ... AF22: =SUM(P58:P61) -> 309
B23: 10.15 - 10.30 | C23: 6 | D23: =ROUND((0.4*E23),0) -> 3 | E23: 8 | F23: 2 | G23: 0 | H23: 0 | I23: 0 | J23: 1 | K23: 4 | L23: 2 | M23: 81 | N23: 0 | O23: =SUM(C23:L23,N23) -> 26 | P23: =SUM(C23:N23) -> 107 | R23: 2000-2100 | S23: =SUM(C62:C65) -> 18 | T23: =SUM(D62:D65) -> 4 | U23: =SUM(E62:E65) -> 11 | V23: =SUM(F62:F65) -> 9 | W23: =SUM(G62:G65) -> 1 | X23: =SUM(H62:H65) -> 0 | Y23: =SUM(I62:I65) -> 3 | Z23: =SUM(J62:J65) -> 4 | ... AF23: =SUM(P62:P65) -> 185
B24: 10.30 - 10.45 | C24: 4 | D24: =ROUND((0.4*E24),0) -> 2 | E24: 4 | F24: 2 | G24: 0 | H24: 0 | I24: 0 | J24: 2 | K24: 1 | L24: 0 | M24: 34 | N24: 0 | O24: =SUM(C24:L24,N24) -> 15 | P24: =SUM(C24:N24) -> 49 | R24: 2100-2200 | S24: =SUM(C66:C69) -> 12 | T24: =SUM(D66:D69) -> 7 | U24: =SUM(E66:E69) -> 17 | V24: =SUM(F66:F69) -> 9 | W24: =SUM(G66:G69) -> 0 | X24: =SUM(H66:H69) -> 0 | Y24: =SUM(I66:I69) -> 1 | Z24: =SUM(J66:J69) -> 0 | ... AF24: =SUM(P66:P69) -> 97
B25: 10.45 - 11.00 | C25: 10 | D25: =ROUND((0.4*E25),0) -> 4 | E25: 10 | F25: 6 | G25: 0 | H25: 0 | I25: 0 | J25: 5 | K25: 2 | L25: 0 | M25: 86 | N25: 0 | O25: =SUM(C25:L25,N25) -> 37 | P25: =SUM(C25:N25) -> 123 | R25: 2200-2300 | S25: =SUM(C70:C73) -> 8 | T25: =SUM(D70:D73) -> 7 | U25: =SUM(E70:E73) -> 16 | V25: =SUM(F70:F73) -> 7 | W25: =SUM(G70:G73) -> 1 | X25: =SUM(H70:H73) -> 1 | Y25: =SUM(I70:I73) -> 1 | Z25: =SUM(J70:J73) -> 3 | ... AF25: =SUM(P70:P73) -> 74
B26: 11.00 - 11.15 | C26: 2 | D26: =ROUND((0.4*E26),0) -> 1 | E26: 3 | F26: 1 | G26: 0 | H26: 0 | I26: 0 | J26: 0 | K26: 0 | L26: 1 | M26: 32 | N26: 0 | O26: =SUM(C26:L26,N26) -> 8 | P26: =SUM(C26:N26) -> 40 | R26: 2300-0000 | S26: =SUM(C74:C77) -> 4 | T26: =SUM(D74:D77) -> 1 | U26: =SUM(E74:E77) -> 4 | V26: =SUM(F74:F77) -> 5 | W26: =SUM(G74:G77) -> 0 | X26: =SUM(H74:H77) -> 0 | Y26: =SUM(I74:I77) -> 0 | Z26: =SUM(J74:J77) -> 0 | ... AF26: =SUM(P74:P77) -> 35
B27: 11.15 - 11.30 | C27: 6 | D27: =ROUND((0.4*E27),0) -> 3 | E27: 8 | F27: 3 | G27: 0 | H27: 0 | I27: 1 | J27: 1 | K27: 0 | L27: 3 | M27: 81 | N27: 0 | O27: =SUM(C27:L27,N27) -> 25 | P27: =SUM(C27:N27) -> 106 | R27: 0000-0100 | S27: =SUM(C78:C81) -> 1 | T27: =SUM(D78:D81) -> 1 | U27: =SUM(E78:E81) -> 4 | V27: =SUM(F78:F81) -> 4 | W27: =SUM(G78:G81) -> 0 | X27: =SUM(H78:H81) -> 0 | Y27: =SUM(I78:I81) -> 3 | Z27: =SUM(J78:J81) -> 3 | ... AF27: =SUM(P78:P81) -> 25
B28: 11.30 - 11.45 | C28: 3 | D28: =ROUND((0.4*E28),0) -> 1 | E28: 2 | F28: 1 | G28: 0 | H28: 0 | I28: 0 | J28: 0 | K28: 0 | L28: 0 | M28: 33 | N28: 0 | O28: =SUM(C28:L28,N28) -> 7 | P28: =SUM(C28:N28) -> 40 | R28: 0100-0200 | S28: =SUM(C82:C85) -> 2 | T28: =SUM(D82:D85) -> 1 | U28: =SUM(E82:E85) -> 4 | V28: =SUM(F82:F85) -> 0 | W28: =SUM(G82:G85) -> 0 | X28: =SUM(H82:H85) -> 0 | Y28: =SUM(I82:I85) -> 0 | Z28: =SUM(J82:J85) -> 1 | ... AF28: =SUM(P82:P85) -> 15
B29: 11.45 - 12.00 | C29: 8 | D29: =ROUND((0.4*E29),0) -> 2 | E29: 5 | F29: 3 | G29: 0 | H29: 0 | I29: 1 | J29: 1 | K29: 0 | L29: 1 | M29: 83 | N29: 0 | O29: =SUM(C29:L29,N29) -> 21 | P29: =SUM(C29:N29) -> 104 | R29: 0200-0300 | S29: =SUM(C86:C89) -> 0 | T29: =SUM(D86:D89) -> 0 | U29: =SUM(E86:E89) -> 1 | V29: =SUM(F86:F89) -> 0 | W29: =SUM(G86:G89) -> 0 | X29: =SUM(H86:H89) -> 0 | Y29: =SUM(I86:I89) -> 0 | Z29: =SUM(J86:J89) -> 0 | ... AF29: =SUM(P86:P89) -> 3
B30: 12.00 - 12.15 | C30: 4 | D30: =ROUND((0.4*E30),0) -> 1 | E30: 2 | F30: 3 | G30: 0 | H30: 0 | I30: 1 | J30: 0 | K30: 0 | L30: 1 | M30: 42 | N30: 0 | O30: =SUM(C30:L30,N30) -> 12 | P30: =SUM(C30:N30) -> 54 | R30: 0300-0400 | S30: =SUM(C90:C93) -> 0 | T30: =SUM(D90:D93) -> 0 | U30: =SUM(E90:E93) -> 0 | V30: =SUM(F90:F93) -> 0 | W30: =SUM(G90:G93) -> 0 | X30: =SUM(H90:H93) -> 0 | Y30: =SUM(I90:I93) -> 0 | Z30: =SUM(J90:J93) -> 0 | ... AF30: =SUM(P90:P93) -> 3
B31: 12.15 - 12.30 | C31: 10 | D31: =ROUND((0.4*E31),0) -> 2 | E31: 6 | F31: 7 | G31: 0 | H31: 0 | I31: 2 | J31: 1 | K31: 0 | L31: 2 | M31: 104 | N31: 0 | O31: =SUM(C31:L31,N31) -> 30 | P31: =SUM(C31:N31) -> 134 | R31: 0400-0500 | S31: =SUM(C94:C97) -> 0 | T31: =SUM(D94:D97) -> 0 | U31: =SUM(E94:E97) -> 1 | V31: =SUM(F94:F97) -> 0 | W31: =SUM(G94:G97) -> 0 | X31: =SUM(H94:H97) -> 0 | Y31: =SUM(I94:I97) -> 0 | Z31: =SUM(J94:J97) -> 0 | ... AF31: =SUM(P94:P97) -> 4
B32: 12.30 - 12.45 | C32: 4 | D32: =ROUND((0.4*E32),0) -> 1 | E32: 3 | F32: 2 | G32: 0 | H32: 0 | I32: 0 | J32: 0 | K32: 0 | L32: 1 | M32: 35 | N32: 0 | O32: =SUM(C32:L32,N32) -> 11 | P32: =SUM(C32:N32) -> 46 | R32: 0500-0600 | S32: =SUM(C98:C101) -> 1 | T32: =SUM(D98:D101) -> 0 | U32: =SUM(E98:E101) -> 0 | V32: =SUM(F98:F101) -> 3 | W32: =SUM(G98:G101) -> 0 | X32: =SUM(H98:H101) -> 0 | Y32: =SUM(I98:I101) -> 0 | Z32: =SUM(J98:J101) -> 0 | ... AF32: =SUM(P98:P101) -> 10
B33: 12.45 - 13.00 | C33: 9 | D33: =ROUND((0.4*E33),0) -> 3 | E33: 8 | F33: 5 | G33: 0 | H33: 0 | I33: 1 | J33: 1 | K33: 1 | L33: 2 | M33: 87 | N33: 0 | O33: =SUM(C33:L33,N33) -> 30 | P33: =SUM(C33:N33) -> 117 | R33: 0600-0700 | S33: =SUM(C102:C105) -> 10 | T33: =SUM(D102:D105) -> 2 | U33: =SUM(E102:E105) -> 6 | V33: =SUM(F102:F105) -> 4 | W33: =SUM(G102:G105) -> 0 | X33: =SUM(H102:H105) -> 0 | Y33: =SUM(I102:I105) -> 0 | Z33: =SUM(J102:J105) -> 0 | ... AF33: =SUM(P102:P105) -> 37
B34: 13.00 - 13.15 | C34: 5 | D34: =ROUND((0.4*E34),0) -> 0 | E34: 0 | F34: 2 | G34: 0 | H34: 0 | I34: 0 | J34: 1 | K34: 1 | L34: 0 | M34: 46 | N34: 0 | O34: =SUM(C34:L34,N34) -> 9 | P34: =SUM(C34:N34) -> 55 | R34: AM Peak Hr | S34: =MAX(S10:S12) -> 23 | T34: =MAX(T10:T12) -> 3 | U34: =MAX(U10:U12) -> 8 | V34: =MAX(V10:V12) -> 11 | W34: =MAX(W10:W12) -> 0 | X34: =MAX(X10:X12) -> 3 | Y34: =MAX(Y10:Y12) -> 2 | Z34: =MAX(Z10:Z12) -> 7 | ... AF34: =MAX(AF10:AF12) -> 369
B35: 13.15 - 13.30 | C35: 12 | D35: =ROUND((0.4*E35),0) -> 0 | E35: 1 | F35: 4 | G35: 0 | H35: 0 | I35: 0 | J35: 3 | K35: 2 | L35: 1 | M35: 114 | N35: 0 | O35: =SUM(C35:L35,N35) -> 23 | P35: =SUM(C35:N35) -> 137 | R35: IP Peak Hr | S35: =MAX(S13:S18) -> 38 | T35: =MAX(T13:T18) -> 10 | U35: =MAX(U13:U18) -> 25 | V35: =MAX(V13:V18) -> 17 | W35: =MAX(W13:W18) -> 0 | X35: =MAX(X13:X18) -> 1 | Y35: =MAX(Y13:Y18) -> 4 | Z35: =MAX(Z13:Z18) -> 11 | ... AF35: =MAX(AF13:AF18) -> 410
B36: 13.30 - 13.45 | C36: 6 | D36: =ROUND((0.4*E36),0) -> 1 | E36: 2 | F36: 2 | G36: 0 | H36: 0 | I36: 0 | J36: 2 | K36: 1 | L36: 0 | M36: 48 | N36: 0 | O36: =SUM(C36:L36,N36) -> 14 | P36: =SUM(C36:N36) -> 62 | R36: PM Peak Hr | S36: =MAX(S19:S21) -> 24 | T36: =MAX(T19:T21) -> 6 | U36: =MAX(U19:U21) -> 15 | V36: =MAX(V19:V21) -> 14 | W36: =MAX(W19:W21) -> 0 | X36: =MAX(X19:X21) -> 1 | Y36: =MAX(Y19:Y21) -> 4 | Z36: =MAX(Z19:Z21) -> 5 | ... AF36: =MAX(AF19:AF21) -> 344
B37: 13.45 - 14.00 | C37: 15 | D37: =ROUND((0.4*E37),0) -> 2 | E37: 6 | F37: 4 | G37: 0 | H37: 1 | I37: 1 | J37: 5 | K37: 2 | L37: 1 | M37: 119 | N37: 0 | O37: =SUM(C37:L37,N37) -> 37 | P37: =SUM(C37:N37) -> 156 | R37: AM Period | S37: =SUM(S10:S12) -> 45 | T37: =SUM(T10:T12) -> 6 | U37: =SUM(U10:U12) -> 20 | V37: =SUM(V10:V12) -> 24 | W37: =SUM(W10:W12) -> 0 | X37: =SUM(X10:X12) -> 3 | Y37: =SUM(Y10:Y12) -> 3 | Z37: =SUM(Z10:Z12) -> 16 | ... AF37: =SUM(AF10:AF12) -> 829
B38: 14.00 - 14.15 | C38: 0 | D38: =ROUND((0.4*E38),0) -> 0 | E38: 1 | F38: 3 | G38: 0 | H38: 0 | I38: 0 | J38: 0 | K38: 1 | L38: 1 | M38: 29 | N38: 0 | O38: =SUM(C38:L38,N38) -> 6 | P38: =SUM(C38:N38) -> 35 | R38: IP Period | S38: =SUM(S13:S18) -> 138 | T38: =SUM(T13:T18) -> 35 | U38: =SUM(U13:U18) -> 91 | V38: =SUM(V13:V18) -> 75 | W38: =SUM(W13:W18) -> 0 | X38: =SUM(X13:X18) -> 1 | Y38: =SUM(Y13:Y18) -> 14 | Z38: =SUM(Z13:Z18) -> 32 | ... AF38: =SUM(AF13:AF18) -> 1941
B39: 14.15 - 14.30 | C39: 1 | D39: =ROUND((0.4*E39),0) -> 1 | E39: 2 | F39: 7 | G39: 0 | H39: 0 | I39: 1 | J39: 1 | K39: 2 | L39: 3 | M39: 72 | N39: 0 | O39: =SUM(C39:L39,N39) -> 18 | P39: =SUM(C39:N39) -> 90 | R39: PM Period | S39: =SUM(S19:S21) -> 58 | T39: =SUM(T19:T21) -> 12 | U39: =SUM(U19:U21) -> 30 | V39: =SUM(V19:V21) -> 34 | W39: =SUM(W19:W21) -> 0 | X39: =SUM(X19:X21) -> 1 | Y39: =SUM(Y19:Y21) -> 8 | Z39: =SUM(Z19:Z21) -> 10 | ... AF39: =SUM(AF19:AF21) -> 909
B40: 14.30 - 14.45 | C40: 3 | D40: =ROUND((0.4*E40),0) -> 0 | E40: 1 | F40: 1 | G40: 0 | H40: 0 | I40: 1 | J40: 0 | K40: 0 | L40: 1 | M40: 29 | N40: 0 | O40: =SUM(C40:L40,N40) -> 7 | P40: =SUM(C40:N40) -> 36 | R40: 12 Hours | S40: =SUM(S10:S21) -> 241 | T40: =SUM(T10:T21) -> 53 | U40: =SUM(U10:U21) -> 141 | V40: =SUM(V10:V21) -> 133 | W40: =SUM(W10:W21) -> 0 | X40: =SUM(X10:X21) -> 5 | Y40: =SUM(Y10:Y21) -> 25 | Z40: =SUM(Z10:Z21) -> 58 | ... AF40: =SUM(AF10:AF21) -> 3679
B41: 14.45 - 15.00 | C41: 7 | D41: =ROUND((0.4*E41),0) -> 1 | E41: 3 | F41: 3 | G41: 0 | H41: 0 | I41: 2 | J41: 1 | K41: 1 | L41: 2 | M41: 72 | N41: 0 | O41: =SUM(C41:L41,N41) -> 20 | P41: =SUM(C41:N41) -> 92 | R41: 24 Hrs/ADT | S41: =SUM(S10:S33) -> 313 | T41: =SUM(T10:T33) -> 90 | U41: =SUM(U10:U33) -> 241 | V41: =SUM(V10:V33) -> 180 | W41: =SUM(W10:W33) -> 2 | X41: =SUM(X10:X33) -> 6 | Y41: =SUM(Y10:Y33) -> 35 | Z41: =SUM(Z10:Z33) -> 69 | ... AF41: =SUM(AF10:AF33) -> 4476
B42: 15.00 - 15.15 | C42: 4 | D42: =ROUND((0.4*E42),0) -> 1 | E42: 2 | F42: 2 | G42: 0 | H42: 0 | I42: 1 | J42: 1 | K42: 2 | L42: 0 | M42: 34 | N42: 0 | O42: =SUM(C42:L42,N42) -> 13 | P42: =SUM(C42:N42) -> 47 | R42: NEF | S42: =S41/S40 -> 1.2987552 | T42: =T41/T40 -> 1.6981132 | U42: =U41/U40 -> 1.7092199 | V42: =V41/V40 -> 1.3533835 | W42: =W41/W40 -> #DIV/0! | X42: =X41/X40 -> 1.2 | Y42: =Y41/Y40 -> 1.4 | Z42: =Z41/Z40 -> 1.1896552 | ... AF42: =AF41/AF40 -> 1.216635
...

Sheet 08.09 Katungulu-Ishaka-24h
B1: Consultancy services for Preparation of Expressway Development Master Plan (EDMP) for Uganda
B2: MANUAL CLASSIFIED COUNT (MCC)
B3: ROAD NAME: | C3: ='09.09 Ishaka-Katungulu'!C3:G3 -> MCC - C4 - STN104 - ISHAKA KATUNGULU ROAD
C5: Date | D5: ='08.09 Ishaka-Katungulu-24h'!D5 -> 08.09.19 | F5: Location | G5: ='08.09 Ishaka-Katungulu-24h'!G5:H5 -> Rubirizi | J5: Surveyor | K5: ='08.09 Ishaka-Katungulu-24h'!K5:L5 -> xxx
C6: Dir. From | D6: ='09.09 Katungulu-Ishaka'!D6:E6 -> Katungulu | F6: Dir. To | G6: ='09.09 Katungulu-Ishaka'!G6:H6 -> Ishaka | J6: Supervisor | K6: ='08.09 Ishaka-Katungulu-24h'!K6:L6 -> xxx
B8: Time / Veh Type | R8: SUMMARY TRAFFIC VOLUMES
C9: 1. Car | D9: 2. Station Wagon | E9: 3. Pickups | F9: 4. Minibus, matatu | G9: 5. Medium bus | H9: 6. Large Bus | I9: 7. Light Truck | J9: 8. Medium Truck | K9: 9. Heavy truck | L9: 10. Truck Trailer | M9: 11. Motor cycles | N9: 12. Tractors | O9: Total Excl M/Cycles | P9: Total All | R9: Time | S9: 1. Car | T9: 2. Station Wagon | U9: 3. Pickups | V9: 4. Minibus, matatu | W9: 5. Medium bus | X9: 6. Large Bus | Y9: 7. Light Truck | Z9: 8. Medium Truck | AA9: 9. Heavy truck | AB9: 10. Truck Trailer | AC9: 11. Motorcycles | AD9: 12. Tractors, Graders | AE9: Total Excl M/ Cycles | AF9: Total All
B10: 07.00 - 07.15 | C10: 2 | D10: =ROUND((0.4*E10),0) -> 0 | E10: 0 | F10: 0 | G10: 0 | H10: 0 | I10: 0 | J10: 0 | K10: 0 | L10: 0 | M10: 8 | N10: 0 | O10: =SUM(C10:L10,N10) -> 2 | P10: =SUM(C10:N10) -> 10 | R10: 0700-0800 | S10: =SUM(C10:C13) -> 7 | T10: =SUM(D10:D13) -> 1 | U10: =SUM(E10:E13) -> 3 | V10: =SUM(F10:F13) -> 5 | W10: =SUM(G10:G13) -> 0 | X10: =SUM(H10:H13) -> 0 | Y10: =SUM(I10:I13) -> 0 | Z10: =SUM(J10:J13) -> 0 | ... AF10: =SUM(P10:P13) -> 120
B11: 07.15 - 07.30 | C11: 4 | D11: =ROUND((0.4*E11),0) -> 0 | E11: 0 | F11: 1 | G11: 0 | H11: 0 | I11: 0 | J11: 0 | K11: 0 | L11: 0 | M11: 20 | N11: 0 | O11: =SUM(C11:L11,N11) -> 5 | P11: =SUM(C11:N11) -> 25 | R11: 0800-0900 | S11: =SUM(C14:C17) -> 9 | T11: =SUM(D14:D17) -> 1 | U11: =SUM(E14:E17) -> 5 | V11: =SUM(F14:F17) -> 7 | W11: =SUM(G14:G17) -> 1 | X11: =SUM(H14:H17) -> 0 | Y11: =SUM(I14:I17) -> 5 | Z11: =SUM(J14:J17) -> 7 | ... AF11: =SUM(P14:P17) -> 317
B12: 07.30 - 07.45 | C12: 0 | D12: =ROUND((0.4*E12),0) -> 0 | E12: 1 | F12: 1 | G12: 0 | H12: 0 | I12: 0 | J12: 0 | K12: 0 | L12: 0 | M12: 22 | N12: 0 | O12: =SUM(C12:L12,N12) -> 2 | P12: =SUM(C12:N12) -> 24 | R12: 0900-1000 | S12: =SUM(C18:C21) -> 14 | T12: =SUM(D18:D21) -> 4 | U12: =SUM(E18:E21) -> 11 | V12: =SUM(F18:F21) -> 11 | W12: =SUM(G18:G21) -> 0 | X12: =SUM(H18:H21) -> 2 | Y12: =SUM(I18:I21) -> 6 | Z12: =SUM(J18:J21) -> 1 | ... AF12: =SUM(P18:P21) -> 354
B13: 07.45 - 08.00 | C13: 1 | D13: =ROUND((0.4*E13),0) -> 1 | E13: 2 | F13: 3 | G13: 0 | H13: 0 | I13: 0 | J13: 0 | K13: 0 | L13: 0 | M13: 54 | N13: 0 | O13: =SUM(C13:L13,N13) -> 7 | P13: =SUM(C13:N13) -> 61 | R13: 1000-1100 | S13: =SUM(C22:C25) -> 17 | T13: =SUM(D22:D25) -> 3 | U13: =SUM(E22:E25) -> 7 | V13: =SUM(F22:F25) -> 12 | W13: =SUM(G22:G25) -> 0 | X13: =SUM(H22:H25) -> 1 | Y13: =SUM(I22:I25) -> 0 | Z13: =SUM(J22:J25) -> 4 | ... AF13: =SUM(P22:P25) -> 323
B14: 08.00 - 08.15 | C14: 2 | D14: =ROUND((0.4*E14),0) -> 0 | E14: 1 | F14: 1 | G14: 0 | H14: 0 | I14: 0 | J14: 0 | K14: 0 | L14: 0 | M14: 37 | N14: 0 | O14: =SUM(C14:L14,N14) -> 4 | P14: =SUM(C14:N14) -> 41 | R14: 1100-1200 | S14: =SUM(C26:C29) -> 23 | T14: =SUM(D26:D29) -> 4 | U14: =SUM(E26:E29) -> 11 | V14: =SUM(F26:F29) -> 11 | W14: =SUM(G26:G29) -> 0 | X14: =SUM(H26:H29) -> 0 | Y14: =SUM(I26:I29) -> 1 | Z14: =SUM(J26:J29) -> 4 | ... AF14: =SUM(P26:P29) -> 284
B15: 08.15 - 08.30 | C15: 4 | D15: =ROUND((0.4*E15),0) -> 1 | E15: 3 | F15: 3 | G15: 1 | H15: 0 | I15: 1 | J15: 0 | K15: 0 | L15: 0 | M15: 92 | N15: 0 | O15: =SUM(C15:L15,N15) -> 13 | P15: =SUM(C15:N15) -> 105 | R15: 1200-1300 | S15: =SUM(C30:C33) -> 18 | T15: =SUM(D30:D33) -> 7 | U15: =SUM(E30:E33) -> 17 | V15: =SUM(F30:F33) -> 9 | W15: =SUM(G30:G33) -> 1 | X15: =SUM(H30:H33) -> 0 | Y15: =SUM(I30:I33) -> 2 | Z15: =SUM(J30:J33) -> 4 | ... AF15: =SUM(P30:P33) -> 294
B16: 08.30 - 08.45 | C16: 1 | D16: =ROUND((0.4*E16),0) -> 0 | E16: 0 | F16: 1 | G16: 0 | H16: 0 | I16: 1 | J16: 2 | K16: 0 | L16: 1 | M16: 43 | N16: 0 | O16: =SUM(C16:L16,N16) -> 6 | P16: =SUM(C16:N16) -> 49 | R16: 1300-1400 | S16: =SUM(C34:C37) -> 27 | T16: =SUM(D34:D37) -> 6 | U16: =SUM(E34:E37) -> 14 | V16: =SUM(F34:F37) -> 14 | W16: =SUM(G34:G37) -> 0 | X16: =SUM(H34:H37) -> 0 | Y16: =SUM(I34:I37) -> 4 | Z16: =SUM(J34:J37) -> 2 | ... AF16: =SUM(P34:P37) -> 340
B17: 08.45 - 9.00 | C17: 2 | D17: =ROUND((0.4*E17),0) -> 0 | E17: 1 | F17: 2 | G17: 0 | H17: 0 | I17: 3 | J17: 5 | K17: 0 | L17: 2 | M17: 107 | N17: 0 | O17: =SUM(C17:L17,N17) -> 15 | P17: =SUM(C17:N17) -> 122 | R17: 1400-1500 | S17: =SUM(C38:C41) -> 28 | T17: =SUM(D38:D41) -> 7 | U17: =SUM(E38:E41) -> 16 | V17: =SUM(F38:F41) -> 10 | W17: =SUM(G38:G41) -> 1 | X17: =SUM(H38:H41) -> 0 | Y17: =SUM(I38:I41) -> 2 | Z17: =SUM(J38:J41) -> 4 | ... AF17: =SUM(P38:P41) -> 314
B18: 09.00 - 09.15 | C18: 2 | D18: =ROUND((0.4*E18),0) -> 0 | E18: 1 | F18: 2 | G18: 0 | H18: 0 | I18: 1 | J18: 0 | K18: 0 | L18: 1 | M18: 43 | N18: 0 | O18: =SUM(C18:L18,N18) -> 7 | P18: =SUM(C18:N18) -> 50 | R18: 1500-1600 | S18: =SUM(C42:C45) -> 26 | T18: =SUM(D42:D45) -> 7 | U18: =SUM(E42:E45) -> 16 | V18: =SUM(F42:F45) -> 10 | W18: =SUM(G42:G45) -> 1 | X18: =SUM(H42:H45) -> 3 | Y18: =SUM(I42:I45) -> 6 | Z18: =SUM(J42:J45) -> 3 | ... AF18: =SUM(P42:P45) -> 361
B19: 09.15 - 09.30 | C19: 4 | D19: =ROUND((0.4*E19),0) -> 1 | E19: 2 | F19: 5 | G19: 0 | H19: 1 | I19: 2 | J19: 0 | K19: 1 | L19: 2 | M19: 108 | N19: 0 | O19: =SUM(C19:L19,N19) -> 18 | P19: =SUM(C19:N19) -> 126 | R19: 1600-1700 | S19: =SUM(C46:C49) -> 18 | T19: =SUM(D46:D49) -> 9 | U19: =SUM(E46:E49) -> 22 | V19: =SUM(F46:F49) -> 14 | W19: =SUM(G46:G49) -> 1 | X19: =SUM(H46:H49) -> 3 | Y19: =SUM(I46:I49) -> 4 | Z19: =SUM(J46:J49) -> 1 | ... AF19: =SUM(P46:P49) -> 369
B20: 09.30 - 09.45 | C20: 2 | D20: =ROUND((0.4*E20),0) -> 1 | E20: 2 | F20: 1 | G20: 0 | H20: 0 | I20: 1 | J20: 0 | K20: 1 | L20: 1 | M20: 41 | N20: 0 | O20: =SUM(C20:L20,N20) -> 9 | P20: =SUM(C20:N20) -> 50 | R20: 1700-1800 | S20: =SUM(C50:C53) -> 33 | T20: =SUM(D50:D53) -> 9 | U20: =SUM(E50:E53) -> 21 | V20: =SUM(F50:F53) -> 13 | W20: =SUM(G50:G53) -> 0 | X20: =SUM(H50:H53) -> 0 | Y20: =SUM(I50:I53) -> 9 | Z20: =SUM(J50:J53) -> 3 | ... AF20: =SUM(P50:P53) -> 410
B21: 09.45 - 10.00 | C21: 6 | D21: =ROUND((0.4*E21),0) -> 2 | E21: 6 | F21: 3 | G21: 0 | H21: 1 | I21: 2 | J21: 1 | K21: 2 | L21: 2 | M21: 103 | N21: 0 | O21: =SUM(C21:L21,N21) -> 25 | P21: =SUM(C21:N21) -> 128 | R21: 1800-1900 | S21: =SUM(C54:C57) -> 28 | T21: =SUM(D54:D57) -> 2 | U21: =SUM(E54:E57) -> 7 | V21: =SUM(F54:F57) -> 15 | W21: =SUM(G54:G57) -> 0 | X21: =SUM(H54:H57) -> 0 | Y21: =SUM(I54:I57) -> 7 | Z21: =SUM(J54:J57) -> 4 | ... AF21: =SUM(P54:P57) -> 332
B22: 10.00 - 10.15 | C22: 3 | D22: =ROUND((0.4*E22),0) -> 1 | E22: 2 | F22: 1 | G22: 0 | H22: 0 | I22: 0 | J22: 1 | K22: 2 | L22: 1 | M22: 38 | N22: 0 | O22: =SUM(C22:L22,N22) -> 11 | P22: =SUM(C22:N22) -> 49 | R22: 1900-2000 | S22: =SUM(C58:C61) -> 37 | T22: =SUM(D58:D61) -> 7 | U22: =SUM(E58:E61) -> 18 | V22: =SUM(F58:F61) -> 4 | W22: =SUM(G58:G61) -> 3 | X22: =SUM(H58:H61) -> 0 | Y22: =SUM(I58:I61) -> 5 | Z22: =SUM(J58:J61) -> 3 | ... AF22: =SUM(P58:P61) -> 431
B23: 10.15 - 10.30 | C23: 7 | D23: =ROUND((0.4*E23),0) -> 2 | E23: 4 | F23: 3 | G23: 0 | H23: 1 | I23: 0 | J23: 3 | K23: 4 | L23: 2 | M23: 96 | N23: 0 | O23: =SUM(C23:L23,N23) -> 26 | P23: =SUM(C23:N23) -> 122 | R23: 2000-2100 | S23: =SUM(C62:C65) -> 13 | T23: =SUM(D62:D65) -> 6 | U23: =SUM(E62:E65) -> 15 | V23: =SUM(F62:F65) -> 8 | W23: =SUM(G62:G65) -> 0 | X23: =SUM(H62:H65) -> 0 | Y23: =SUM(I62:I65) -> 3 | Z23: =SUM(J62:J65) -> 13 | ... AF23: =SUM(P62:P65) -> 315
B24: 10.30 - 10.45 | C24: 2 | D24: =ROUND((0.4*E24),0) -> 0 | E24: 0 | F24: 2 | G24: 0 | H24: 0 | I24: 0 | J24: 0 | K24: 1 | L24: 2 | M24: 36 | N24: 0 | O24: =SUM(C24:L24,N24) -> 7 | P24: =SUM(C24:N24) -> 43 | R24: 2100-2200 | S24: =SUM(C66:C69) -> 14 | T24: =SUM(D66:D69) -> 9 | U24: =SUM(E66:E69) -> 20 | V24: =SUM(F66:F69) -> 2 | W24: =SUM(G66:G69) -> 0 | X24: =SUM(H66:H69) -> 0 | Y24: =SUM(I66:I69) -> 0 | Z24: =SUM(J66:J69) -> 1 | ... AF24: =SUM(P66:P69) -> 123
B25: 10.45 - 11.00 | C25: 5 | D25: =ROUND((0.4*E25),0) -> 0 | E25: 1 | F25: 6 | G25: 0 | H25: 0 | I25: 0 | J25: 0 | K25: 3 | L25: 3 | M25: 90 | N25: 1 | O25: =SUM(C25:L25,N25) -> 19 | P25: =SUM(C25:N25) -> 109 | R25: 2200-2300 | S25: =SUM(C70:C73) -> 13 | T25: =SUM(D70:D73) -> 9 | U25: =SUM(E70:E73) -> 20 | V25: =SUM(F70:F73) -> 1 | W25: =SUM(G70:G73) -> 0 | X25: =SUM(H70:H73) -> 0 | Y25: =SUM(I70:I73) -> 0 | Z25: =SUM(J70:J73) -> 4 | ... AF25: =SUM(P70:P73) -> 83
B26: 11.00 - 11.15 | C26: 4 | D26: =ROUND((0.4*E26),0) -> 0 | E26: 1 | F26: 1 | G26: 0 | H26: 0 | I26: 0 | J26: 1 | K26: 3 | L26: 0 | M26: 34 | N26: 0 | O26: =SUM(C26:L26,N26) -> 10 | P26: =SUM(C26:N26) -> 44 | R26: 2300-0000 | S26: =SUM(C74:C77) -> 2 | T26: =SUM(D74:D77) -> 0 | U26: =SUM(E74:E77) -> 1 | V26: =SUM(F74:F77) -> 4 | W26: =SUM(G74:G77) -> 0 | X26: =SUM(H74:H77) -> 1 | Y26: =SUM(I74:I77) -> 1 | Z26: =SUM(J74:J77) -> 0 | ... AF26: =SUM(P74:P77) -> 30
B27: 11.15 - 11.30 | C27: 9 | D27: =ROUND((0.4*E27),0) -> 1 | E27: 2 | F27: 2 | G27: 0 | H27: 0 | I27: 1 | J27: 2 | K27: 7 | L27: 1 | M27: 86 | N27: 0 | O27: =SUM(C27:L27,N27) -> 25 | P27: =SUM(C27:N27) -> 111 | R27: 0000-0100 | S27: =SUM(C78:C81) -> 1 | T27: =SUM(D78:D81) -> 3 | U27: =SUM(E78:E81) -> 6 | V27: =SUM(F78:F81) -> 8 | W27: =SUM(G78:G81) -> 0 | X27: =SUM(H78:H81) -> 1 | Y27: =SUM(I78:I81) -> 0 | Z27: =SUM(J78:J81) -> 2 | ... AF27: =SUM(P78:P81) -> 26
B28: 11.30 - 11.45 | C28: 3 | D28: =ROUND((0.4*E28),0) -> 1 | E28: 2 | F28: 2 | G28: 0 | H28: 0 | I28: 0 | J28: 0 | K28: 1 | L28: 2 | M28: 26 | N28: 0 | O28: =SUM(C28:L28,N28) -> 11 | P28: =SUM(C28:N28) -> 37 | R28: 0100-0200 | S28: =SUM(C82:C85) -> 2 | T28: =SUM(D82:D85) -> 1 | U28: =SUM(E82:E85) -> 4 | V28: =SUM(F82:F85) -> 4 | W28: =SUM(G82:G85) -> 0 | X28: =SUM(H82:H85) -> 0 | Y28: =SUM(I82:I85) -> 0 | Z28: =SUM(J82:J85) -> 3 | ... AF28: =SUM(P82:P85) -> 26
B29: 11.45 - 12.00 | C29: 7 | D29: =ROUND((0.4*E29),0) -> 2 | E29: 6 | F29: 6 | G29: 0 | H29: 0 | I29: 0 | J29: 1 | K29: 2 | L29: 4 | M29: 64 | N29: 0 | O29: =SUM(C29:L29,N29) -> 28 | P29: =SUM(C29:N29) -> 92 | R29: 0200-0300 | S29: =SUM(C86:C89) -> 0 | T29: =SUM(D86:D89) -> 0 | U29: =SUM(E86:E89) -> 1 | V29: =SUM(F86:F89) -> 0 | W29: =SUM(G86:G89) -> 0 | X29: =SUM(H86:H89) -> 0 | Y29: =SUM(I86:I89) -> 0 | Z29: =SUM(J86:J89) -> 0 | ... AF29: =SUM(P86:P89) -> 8
