Workbook

Sheet 17.10 KAPEEKA-NGOMA
B1: Consultancy services for Preparation of Expressway Development Master Plan (EDMP) for Uganda
B2: MANUAL CLASSIFIED COUNT (MCC)
B3: ROAD NAME: | C3: KAPEEKA -NGOMA ROAD
C5: Date | D5: 17.10.2019 | F5: Location | G5: BUTALANGU | J5: Surveyor | K5: MIREMBE RUTH
C6: Dir. From | D6: KAPEEKA | F6: Dir. To | G6: NGOMA | J6: Supervisor | K6: MIREMBE RUTH
B8: Time / Veh Type | R8: SUMMARY TRAFFIC VOLUMES
C9: 1. Car | D9: 2. Station Wagon | E9: 3. Pickups | F9: 4. Minibus, matatu | G9: 5. Medium bus | H9: 6. Large Bus | I9: 7. Light Truck | J9: 8. Medium Truck | K9: 9. Heavy truck | L9: 10. Truck Trailer | M9: 11. Motor cycles | N9: 12. Tractors | O9: Total Excl M/Cycles | P9: Total All | R9: Time | S9: 1. Car | T9: 2. Station Wagon | U9: 3. Pickups | V9: 4. Minibus, matatu | W9: 5. Medium bus | X9: 6. Large Bus | Y9: 7. Light Truck | Z9: 8. Medium Truck | AA9: 9. Heavy truck | AB9: 10. Truck Trailer | AC9: 11. Motorcycles | AD9: 12. Tractors, Graders | AE9: Total Excl M/ Cycles | AF9: Total All
B10: 07.00 - 07.15 | C10: 0 | D10: 0 | E10: 0 | F10: 0 | G10: 0 | H10: 0 | I10: 0 | J10: 0 | K10: 0 | L10: 0 | M10: 0 | N10: 0 | O10: =SUM(C10:L10,N10) -> 0 | P10: =SUM(C10:N10) -> 0 | R10: 0700-0800 | S10: =SUM(C10:C13) -> 0 | T10: =SUM(D10:D13) -> 0 | U10: =SUM(E10:E13) -> 0 | V10: =SUM(F10:F13) -> 0 | W10: =SUM(G10:G13) -> 0 | X10: =SUM(H10:H13) -> 0 | Y10: =SUM(I10:I13) -> 2 | Z10: =SUM(J10:J13) -> 0 | ... AF10: =SUM(P10:P13) -> 8
B11: 07.15 - 07.30 | C11: 0 | D11: 0 | E11: 0 | F11: 0 | G11: 0 | H11: 0 | I11: 2 | J11: 0 | K11: 0 | L11: 0 | M11: 0 | N11: 0 | O11: =SUM(C11:L11,N11) -> 2 | P11: =SUM(C11:N11) -> 2 | R11: 0800-0900 | S11: =SUM(C14:C17) -> 0 | T11: =SUM(D14:D17) -> 1 | U11: =SUM(E14:E17) -> 2 | V11: =SUM(F14:F17) -> 0 | W11: =SUM(G14:G17) -> 0 | X11: =SUM(H14:H17) -> 0 | Y11: =SUM(I14:I17) -> 3 | Z11: =SUM(J14:J17) -> 1 | ... AF11: =SUM(P14:P17) -> 16
B12: 07.30 - 07.45 | C12: 0 | D12: 0 | E12: 0 | F12: 0 | G12: 0 | H12: 0 | I12: 0 | J12: 0 | K12: 0 | L12: 0 | M12: 4 | N12: 0 | O12: =SUM(C12:L12,N12) -> 0 | P12: =SUM(C12:N12) -> 4 | R12: 0900-1000 | S12: =SUM(C18:C21) -> 4 | T12: =SUM(D18:D21) -> 1 | U12: =SUM(E18:E21) -> 3 | V12: =SUM(F18:F21) -> 0 | W12: =SUM(G18:G21) -> 0 | X12: =SUM(H18:H21) -> 0 | Y12: =SUM(I18:I21) -> 4 | Z12: =SUM(J18:J21) -> 0 | ... AF12: =SUM(P18:P21) -> 32
B13: 07.45 - 08.00 | C13: 0 | D13: 0 | E13: 0 | F13: 0 | G13: 0 | H13: 0 | I13: 0 | J13: 0 | K13: 0 | L13: 0 | M13: 2 | N13: 0 | O13: =SUM(C13:L13,N13) -> 0 | P13: =SUM(C13:N13) -> 2 | R13: 1000-1100 | S13: =SUM(C22:C25) -> 3 | T13: =SUM(D22:D25) -> 0 | U13: =SUM(E22:E25) -> 1 | V13: =SUM(F22:F25) -> 0 | W13: =SUM(G22:G25) -> 0 | X13: =SUM(H22:H25) -> 0 | Y13: =SUM(I22:I25) -> 3 | Z13: =SUM(J22:J25) -> 0 | ... AF13: =SUM(P22:P25) -> 24
B14: 08.00 - 08.15 | C14: 0 | D14: 0 | E14: 1 | F14: 0 | G14: 0 | H14: 0 | I14: 0 | J14: 0 | K14: 0 | L14: 0 | M14: 1 | N14: 1 | O14: =SUM(C14:L14,N14) -> 2 | P14: =SUM(C14:N14) -> 3 | R14: 1100-1200 | S14: =SUM(C26:C29) -> 3 | T14: =SUM(D26:D29) -> 0 | U14: =SUM(E26:E29) -> 2 | V14: =SUM(F26:F29) -> 0 | W14: =SUM(G26:G29) -> 0 | X14: =SUM(H26:H29) -> 0 | Y14: =SUM(I26:I29) -> 4 | Z14: =SUM(J26:J29) -> 1 | ... AF14: =SUM(P26:P29) -> 26
B15: 08.15 - 08.30 | C15: 0 | D15: 0 | E15: 0 | F15: 0 | G15: 0 | H15: 0 | I15: 1 | J15: 0 | K15: 0 | L15: 0 | M15: 2 | N15: 0 | O15: =SUM(C15:L15,N15) -> 1 | P15: =SUM(C15:N15) -> 3 | R15: 1200-1300 | S15: =SUM(C30:C33) -> 2 | T15: =SUM(D30:D33) -> 0 | U15: =SUM(E30:E33) -> 4 | V15: =SUM(F30:F33) -> 2 | W15: =SUM(G30:G33) -> 0 | X15: =SUM(H30:H33) -> 0 | Y15: =SUM(I30:I33) -> 2 | Z15: =SUM(J30:J33) -> 4 | ... AF15: =SUM(P30:P33) -> 31
B16: 08.30 - 08.45 | C16: 0 | D16: 0 | E16: 1 | F16: 0 | G16: 0 | H16: 0 | I16: 2 | J16: 1 | K16: 0 | L16: 0 | M16: 0 | N16: 0 | O16: =SUM(C16:L16,N16) -> 4 | P16: =SUM(C16:N16) -> 4 | R16: 1300-1400 | S16: =SUM(C34:C37) -> 5 | T16: =SUM(D34:D37) -> 0 | U16: =SUM(E34:E37) -> 2 | V16: =SUM(F34:F37) -> 2 | W16: =SUM(G34:G37) -> 0 | X16: =SUM(H34:H37) -> 0 | Y16: =SUM(I34:I37) -> 1 | Z16: =SUM(J34:J37) -> 0 | ... AF16: =SUM(P34:P37) -> 27
B17: 08.45 - 9.00 | C17: 0 | D17: 1 | E17: 0 | F17: 0 | G17: 0 | H17: 0 | I17: 0 | J17: 0 | K17: 0 | L17: 0 | M17: 5 | N17: 0 | O17: =SUM(C17:L17,N17) -> 1 | P17: =SUM(C17:N17) -> 6 | R17: 1400-1500 | S17: =SUM(C38:C41) -> 0 | T17: =SUM(D38:D41) -> 0 | U17: =SUM(E38:E41) -> 2 | V17: =SUM(F38:F41) -> 2 | W17: =SUM(G38:G41) -> 0 | X17: =SUM(H38:H41) -> 0 | Y17: =SUM(I38:I41) -> 3 | Z17: =SUM(J38:J41) -> 0 | ... AF17: =SUM(P38:P41) -> 25
B18: 09.00 - 09.15 | C18: 4 | D18: 1 | E18: 2 | F18: 0 | G18: 0 | H18: 0 | I18: 1 | J18: 0 | K18: 0 | L18: 0 | M18: 5 | N18: 0 | O18: =SUM(C18:L18,N18) -> 8 | P18: =SUM(C18:N18) -> 13 | R18: 1500-1600 | S18: =SUM(C42:C45) -> 1 | T18: =SUM(D42:D45) -> 0 | U18: =SUM(E42:E45) -> 2 | V18: =SUM(F42:F45) -> 3 | W18: =SUM(G42:G45) -> 0 | X18: =SUM(H42:H45) -> 0 | Y18: =SUM(I42:I45) -> 3 | Z18: =SUM(J42:J45) -> 0 | ... AF18: =SUM(P42:P45) -> 29
B19: 09.15 - 09.30 | C19: 0 | D19: 0 | E19: 0 | F19: 0 | G19: 0 | H19: 0 | I19: 2 | J19: 0 | K19: 0 | L19: 0 | M19: 2 | N19: 0 | O19: =SUM(C19:L19,N19) -> 2 | P19: =SUM(C19:N19) -> 4 | R19: 1600-1700 | S19: =SUM(C46:C49) -> 1 | T19: =SUM(D46:D49) -> 0 | U19: =SUM(E46:E49) -> 3 | V19: =SUM(F46:F49) -> 1 | W19: =SUM(G46:G49) -> 0 | X19: =SUM(H46:H49) -> 0 | Y19: =SUM(I46:I49) -> 1 | Z19: =SUM(J46:J49) -> 1 | ... AF19: =SUM(P46:P49) -> 28
B20: 09.30 - 09.45 | C20: 0 | D20: 0 | E20: 1 | F20: 0 | G20: 0 | H20: 0 | I20: 0 | J20: 0 | K20: 0 | L20: 0 | M20: 7 | N20: 0 | O20: =SUM(C20:L20,N20) -> 1 | P20: =SUM(C20:N20) -> 8 | R20: 1700-1800 | S20: =SUM(C50:C53) -> 3 | T20: =SUM(D50:D53) -> 0 | U20: =SUM(E50:E53) -> 2 | V20: =SUM(F50:F53) -> 3 | W20: =SUM(G50:G53) -> 0 | X20: =SUM(H50:H53) -> 0 | Y20: =SUM(I50:I53) -> 2 | Z20: =SUM(J50:J53) -> 1 | ... AF20: =SUM(P50:P53) -> 27
B21: 09.45 - 10.00 | C21: 0 | D21: 0 | E21: 0 | F21: 0 | G21: 0 | H21: 0 | I21: 1 | J21: 0 | K21: 0 | L21: 0 | M21: 6 | N21: 0 | O21: =SUM(C21:L21,N21) -> 1 | P21: =SUM(C21:N21) -> 7 | R21: 1800-1900 | S21: =SUM(C54:C57) -> 1 | T21: =SUM(D54:D57) -> 0 | U21: =SUM(E54:E57) -> 1 | V21: =SUM(F54:F57) -> 3 | W21: =SUM(G54:G57) -> 0 | X21: =SUM(H54:H57) -> 0 | Y21: =SUM(I54:I57) -> 3 | Z21: =SUM(J54:J57) -> 0 | ... AF21: =SUM(P54:P57) -> 26
B22: 10.00 - 10.15 | C22: 0 | D22: 0 | E22: 0 | F22: 0 | G22: 0 | H22: 0 | I22: 2 | J22: 0 | K22: 0 | L22: 0 | M22: 3 | N22: 1 | O22: =SUM(C22:L22,N22) -> 3 | P22: =SUM(C22:N22) -> 6 | R22: AM Peak Hr | S22: =MAX(S10:S12) -> 4 | T22: =MAX(T10:T12) -> 1 | U22: =MAX(U10:U12) -> 3 | V22: =MAX(V10:V12) -> 0 | W22: =MAX(W10:W12) -> 0 | X22: =MAX(X10:X12) -> 0 | Y22: =MAX(Y10:Y12) -> 4 | Z22: =MAX(Z10:Z12) -> 1 | ... AF22: =MAX(AF10:AF12) -> 32
B23: 10.15 - 10.30 | C23: 0 | D23: 0 | E23: 1 | F23: 0 | G23: 0 | H23: 0 | I23: 1 | J23: 0 | K23: 0 | L23: 0 | M23: 0 | N23: 0 | O23: =SUM(C23:L23,N23) -> 2 | P23: =SUM(C23:N23) -> 2 | R23: IP Peak Hr | S23: =MAX(S13:S18) -> 5 | T23: =MAX(T13:T18) -> 0 | U23: =MAX(U13:U18) -> 4 | V23: =MAX(V13:V18) -> 3 | W23: =MAX(W13:W18) -> 0 | X23: =MAX(X13:X18) -> 0 | Y23: =MAX(Y13:Y18) -> 4 | Z23: =MAX(Z13:Z18) -> 4 | ... AF23: =MAX(AF13:AF18) -> 31
B24: 10.30 - 10.45 | C24: 1 | D24: 0 | E24: 0 | F24: 0 | G24: 0 | H24: 0 | I24: 0 | J24: 0 | K24: 0 | L24: 0 | M24: 6 | N24: 0 | O24: =SUM(C24:L24,N24) -> 1 | P24: =SUM(C24:N24) -> 7 | R24: PM Peak Hr | S24: =MAX(S19:S21) -> 3 | T24: =MAX(T19:T21) -> 0 | U24: =MAX(U19:U21) -> 3 | V24: =MAX(V19:V21) -> 3 | W24: =MAX(W19:W21) -> 0 | X24: =MAX(X19:X21) -> 0 | Y24: =MAX(Y19:Y21) -> 3 | Z24: =MAX(Z19:Z21) -> 1 | ... AF24: =MAX(AF19:AF21) -> 28
B25: 10.45 - 11.00 | C25: 2 | D25: 0 | E25: 0 | F25: 0 | G25: 0 | H25: 0 | I25: 0 | J25: 0 | K25: 0 | L25: 0 | M25: 6 | N25: 1 | O25: =SUM(C25:L25,N25) -> 3 | P25: =SUM(C25:N25) -> 9 | R25: AM Period | S25: =SUM(S10:S12) -> 4 | T25: =SUM(T10:T12) -> 2 | U25: =SUM(U10:U12) -> 5 | V25: =SUM(V10:V12) -> 0 | W25: =SUM(W10:W12) -> 0 | X25: =SUM(X10:X12) -> 0 | Y25: =SUM(Y10:Y12) -> 9 | Z25: =SUM(Z10:Z12) -> 1 | ... AF25: =SUM(AF10:AF12) -> 56
B26: 11.00 - 11.15 | C26: 0 | D26: 0 | E26: 2 | F26: 0 | G26: 0 | H26: 0 | I26: 2 | J26: 1 | K26: 0 | L26: 0 | M26: 6 | N26: 0 | O26: =SUM(C26:L26,N26) -> 5 | P26: =SUM(C26:N26) -> 11 | R26: IP Period | S26: =SUM(S13:S18) -> 14 | T26: =SUM(T13:T18) -> 0 | U26: =SUM(U13:U18) -> 13 | V26: =SUM(V13:V18) -> 9 | W26: =SUM(W13:W18) -> 0 | X26: =SUM(X13:X18) -> 0 | Y26: =SUM(Y13:Y18) -> 16 | Z26: =SUM(Z13:Z18) -> 5 | ... AF26: =SUM(AF13:AF18) -> 162
B27: 11.15 - 11.30 | C27: 1 | D27: 0 | E27: 0 | F27: 0 | G27: 0 | H27: 0 | I27: 0 | J27: 0 | K27: 0 | L27: 0 | M27: 1 | N27: 0 | O27: =SUM(C27:L27,N27) -> 1 | P27: =SUM(C27:N27) -> 2 | R27: PM Period | S27: =SUM(S19:S21) -> 5 | T27: =SUM(T19:T21) -> 0 | U27: =SUM(U19:U21) -> 6 | V27: =SUM(V19:V21) -> 7 | W27: =SUM(W19:W21) -> 0 | X27: =SUM(X19:X21) -> 0 | Y27: =SUM(Y19:Y21) -> 6 | Z27: =SUM(Z19:Z21) -> 2 | ... AF27: =SUM(AF19:AF21) -> 81
B28: 11.30 - 11.45 | C28: 0 | D28: 0 | E28: 0 | F28: 0 | G28: 0 | H28: 0 | I28: 2 | J28: 0 | K28: 0 | L28: 0 | M28: 5 | N28: 0 | O28: =SUM(C28:L28,N28) -> 2 | P28: =SUM(C28:N28) -> 7 | R28: 12 Hours | S28: =SUM(S10:S21) -> 23 | T28: =SUM(T10:T21) -> 2 | U28: =SUM(U10:U21) -> 24 | V28: =SUM(V10:V21) -> 16 | W28: =SUM(W10:W21) -> 0 | X28: =SUM(X10:X21) -> 0 | Y28: =SUM(Y10:Y21) -> 31 | Z28: =SUM(Z10:Z21) -> 8 | ... AF28: =SUM(AF10:AF21) -> 299
B29: 11.45 - 12.00 | C29: 2 | D29: 0 | E29: 0 | F29: 0 | G29: 0 | H29: 0 | I29: 0 | J29: 0 | K29: 0 | L29: 0 | M29: 4 | N29: 0 | O29: =SUM(C29:L29,N29) -> 2 | P29: =SUM(C29:N29) -> 6
B30: 12.00 - 12.15 | C30: 0 | D30: 0 | E30: 1 | F30: 0 | G30: 0 | H30: 0 | I30: 0 | J30: 3 | K30: 0 | L30: 0 | M30: 5 | N30: 0 | O30: =SUM(C30:L30,N30) -> 4 | P30: =SUM(C30:N30) -> 9
B31: 12.15 - 12.30 | C31: 1 | D31: 0 | E31: 1 | F31: 1 | G31: 0 | H31: 0 | I31: 0 | J31: 0 | K31: 0 | L31: 0 | M31: 4 | N31: 0 | O31: =SUM(C31:L31,N31) -> 3 | P31: =SUM(C31:N31) -> 7
B32: 12.30 - 12.45 | C32: 1 | D32: 0 | E32: 1 | F32: 0 | G32: 0 | H32: 0 | I32: 0 | J32: 1 | K32: 0 | L32: 0 | M32: 2 | N32: 0 | O32: =SUM(C32:L32,N32) -> 3 | P32: =SUM(C32:N32) -> 5
B33: 12.45 - 13.00 | C33: 0 | D33: 0 | E33: 1 | F33: 1 | G33: 0 | H33: 0 | I33: 2 | J33: 0 | K33: 0 | L33: 0 | M33: 6 | N33: 0 | O33: =SUM(C33:L33,N33) -> 4 | P33: =SUM(C33:N33) -> 10
B34: 13.00 - 13.15 | C34: 2 | D34: 0 | E34: 0 | F34: 1 | G34: 0 | H34: 0 | I34: 0 | J34: 0 | K34: 0 | L34: 0 | M34: 5 | N34: 0 | O34: =SUM(C34:L34,N34) -> 3 | P34: =SUM(C34:N34) -> 8
B35: 13.15 - 13.30 | C35: 1 | D35: 0 | E35: 2 | F35: 0 | G35: 0 | H35: 0 | I35: 1 | J35: 0 | K35: 0 | L35: 0 | M35: 4 | N35: 0 | O35: =SUM(C35:L35,N35) -> 4 | P35: =SUM(C35:N35) -> 8
B36: 13.30 - 13.45 | C36: 1 | D36: 0 | E36: 0 | F36: 1 | G36: 0 | H36: 0 | I36: 0 | J36: 0 | K36: 0 | L36: 0 | M36: 3 | N36: 0 | O36: =SUM(C36:L36,N36) -> 2 | P36: =SUM(C36:N36) -> 5
B37: 13.45 - 14.00 | C37: 1 | D37: 0 | E37: 0 | F37: 0 | G37: 0 | H37: 0 | I37: 0 | J37: 0 | K37: 0 | L37: 0 | M37: 5 | N37: 0 | O37: =SUM(C37:L37,N37) -> 1 | P37: =SUM(C37:N37) -> 6
B38: 14.00 - 14.15 | C38: 0 | D38: 0 | E38: 0 | F38: 1 | G38: 0 | H38: 0 | I38: 0 | J38: 0 | K38: 0 | L38: 0 | M38: 1 | N38: 1 | O38: =SUM(C38:L38,N38) -> 2 | P38: =SUM(C38:N38) -> 3
B39: 14.15 - 14.30 | C39: 0 | D39: 0 | E39: 1 | F39: 0 | G39: 0 | H39: 0 | I39: 1 | J39: 0 | K39: 0 | L39: 0 | M39: 3 | N39: 0 | O39: =SUM(C39:L39,N39) -> 2 | P39: =SUM(C39:N39) -> 5
B40: 14.30 - 14.45 | C40: 0 | D40: 0 | E40: 1 | F40: 0 | G40: 0 | H40: 0 | I40: 1 | J40: 0 | K40: 0 | L40: 0 | M40: 9 | N40: 0 | O40: =SUM(C40:L40,N40) -> 2 | P40: =SUM(C40:N40) -> 11
... B57: 18.45 - 19.00 | C57: 0 | D57: 0 | E57: 0 | F57: 1 | G57: 0 | H57: 0 | I57: 0 | J57: 0 | K57: 0 | L57: 0 | M57: 1 | N57: 0 | O57: =SUM(C57:L57,N57) -> 1 | P57: =SUM(C57:N57) -> 2
B58: Totals | C58: =SUM(C10:C57) -> 23 | D58: =SUM(D10:D57) -> 2 | E58: =SUM(E10:E57) -> 24 | F58: =SUM(F10:F57) -> 16 | G58: =SUM(G10:G57) -> 0 | H58: =SUM(H10:H57) -> 0 | I58: =SUM(I10:I57) -> 31 | J58: =SUM(J10:J57) -> 8 | ... P58: =SUM(P10:P57) -> 299
...

Sheet 17.10 NGOMA-KAPEEKA
B1: Consultancy services for Preparation of Expressway Development Master Plan (EDMP) for Uganda
B2: MANUAL CLASSIFIED COUNT (MCC)
B3: ROAD NAME: | C3: ='17.10 KAPEEKA-NGOMA'!C3:G3 -> KAPEEKA -NGOMA ROAD
C5: Date | D5: ='17.10 KAPEEKA-NGOMA'!D5 -> 17.10.2019 | F5: Location | G5: BUTALANGU | J5: Surveyor | K5: AMOS A
C6: Dir. From | D6: NGOMA | F6: Dir. To | G6: KAPEEKA | J6: Supervisor | K6: ='17.10 KAPEEKA-NGOMA'!K6:L6 -> MIREMBE RUTH
B8: Time / Veh Type | R8: SUMMARY TRAFFIC VOLUMES
C9: 1. Car | D9: 2. Station Wagon | E9: 3. Pickups | F9: 4. Minibus, matatu | G9: 5. Medium bus | H9: 6. Large Bus | I9: 7. Light Truck | J9: 8. Medium Truck | K9: 9. Heavy truck | L9: 10. Truck Trailer | M9: 11. Motor cycles | N9: 12. Tractors | O9: Total Excl M/Cycles | P9: Total All | R9: Time | S9: 1. Car | T9: 2. Station Wagon | U9: 3. Pickups | V9: 4. Minibus, matatu | W9: 5. Medium bus | X9: 6. Large Bus | Y9: 7. Light Truck | Z9: 8. Medium Truck | AA9: 9. Heavy truck | AB9: 10. Truck Trailer | AC9: 11. Motorcycles | AD9: 12. Tractors, Graders | AE9: Total Excl M/ Cycles | AF9: Total All
B10: 07.00 - 07.15 | C10: 0 | D10: 0 | E10: 0 | F10: 0 | G10: 0 | H10: 0 | I10: 0 | J10: 0 | K10: 0 | L10: 0 | M10: 1 | N10: 0 | O10: =SUM(C10:L10,N10) -> 0 | P10: =SUM(C10:N10) -> 1 | R10: 0700-0800 | S10: =SUM(C10:C13) -> 2 | T10: =SUM(D10:D13) -> 0 | U10: =SUM(E10:E13) -> 1 | V10: =SUM(F10:F13) -> 2 | W10: =SUM(G10:G13) -> 0 | X10: =SUM(H10:H13) -> 0 | Y10: =SUM(I10:I13) -> 0 | Z10: =SUM(J10:J13) -> 0 | ... AF10: =SUM(P10:P13) -> 14
B11: 07.15 - 07.30 | C11: 1 | D11: 0 | E11: 0 | F11: 1 | G11: 0 | H11: 0 | I11: 0 | J11: 0 | K11: 0 | L11: 0 | M11: 1 | N11: 0 | O11: =SUM(C11:L11,N11) -> 2 | P11: =SUM(C11:N11) -> 3 | R11: 0800-0900 | S11: =SUM(C14:C17) -> 0 | T11: =SUM(D14:D17) -> 0 | U11: =SUM(E14:E17) -> 0 | V11: =SUM(F14:F17) -> 1 | W11: =SUM(G14:G17) -> 0 | X11: =SUM(H14:H17) -> 0 | Y11: =SUM(I14:I17) -> 1 | Z11: =SUM(J14:J17) -> 0 | ... AF11: =SUM(P14:P17) -> 27
B12: 07.30 - 07.45 | C12: 0 | D12: 0 | E12: 0 | F12: 0 | G12: 0 | H12: 0 | I12: 0 | J12: 0 | K12: 0 | L12: 0 | M12: 4 | N12: 0 | O12: =SUM(C12:L12,N12) -> 0 | P12: =SUM(C12:N12) -> 4 | R12: 0900-1000 | S12: =SUM(C18:C21) -> 1 | T12: =SUM(D18:D21) -> 1 | U12: =SUM(E18:E21) -> 1 | V12: =SUM(F18:F21) -> 2 | W12: =SUM(G18:G21) -> 0 | X12: =SUM(H18:H21) -> 0 | Y12: =SUM(I18:I21) -> 1 | Z12: =SUM(J18:J21) -> 2 | ... AF12: =SUM(P18:P21) -> 24
B13: 07.45 - 08.00 | C13: 1 | D13: 0 | E13: 1 | F13: 1 | G13: 0 | H13: 0 | I13: 0 | J13: 0 | K13: 0 | L13: 0 | M13: 3 | N13: 0 | O13: =SUM(C13:L13,N13) -> 3 | P13: =SUM(C13:N13) -> 6 | R13: 1000-1100 | S13: =SUM(C22:C25) -> 4 | T13: =SUM(D22:D25) -> 0 | U13: =SUM(E22:E25) -> 0 | V13: =SUM(F22:F25) -> 1 | W13: =SUM(G22:G25) -> 0 | X13: =SUM(H22:H25) -> 0 | Y13: =SUM(I22:I25) -> 1 | Z13: =SUM(J22:J25) -> 0 | ... AF13: =SUM(P22:P25) -> 25
B14: 08.00 - 08.15 | C14: 0 | D14: 0 | E14: 0 | F14: 0 | G14: 0 | H14: 0 | I14: 0 | J14: 0 | K14: 0 | L14: 0 | M14: 8 | N14: 0 | O14: =SUM(C14:L14,N14) -> 0 | P14: =SUM(C14:N14) -> 8 | R14: 1100-1200 | S14: =SUM(C26:C29) -> 2 | T14: =SUM(D26:D29) -> 0 | U14: =SUM(E26:E29) -> 2 | V14: =SUM(F26:F29) -> 4 | W14: =SUM(G26:G29) -> 0 | X14: =SUM(H26:H29) -> 0 | Y14: =SUM(I26:I29) -> 1 | Z14: =SUM(J26:J29) -> 1 | ... AF14: =SUM(P26:P29) -> 35
B15: 08.15 - 08.30 | C15: 0 | D15: 0 | E15: 0 | F15: 0 | G15: 0 | H15: 0 | I15: 0 | J15: 0 | K15: 0 | L15: 0 | M15: 6 | N15: 0 | O15: =SUM(C15:L15,N15) -> 0 | P15: =SUM(C15:N15) -> 6 | R15: 1200-1300 | S15: =SUM(C30:C33) -> 2 | T15: =SUM(D30:D33) -> 0 | U15: =SUM(E30:E33) -> 1 | V15: =SUM(F30:F33) -> 3 | W15: =SUM(G30:G33) -> 0 | X15: =SUM(H30:H33) -> 0 | Y15: =SUM(I30:I33) -> 1 | Z15: =SUM(J30:J33) -> 2 | ... AF15: =SUM(P30:P33) -> 39
B16: 08.30 - 08.45 | C16: 0 | D16: 0 | E16: 0 | F16: 1 | G16: 0 | H16: 0 | I16: 1 | J16: 0 | K16: 0 | L16: 0 | M16: 7 | N16: 0 | O16: =SUM(C16:L16,N16) -> 2 | P16: =SUM(C16:N16) -> 9 | R16: 1300-1400 | S16: =SUM(C34:C37) -> 0 | T16: =SUM(D34:D37) -> 0 | U16: =SUM(E34:E37) -> 0 | V16: =SUM(F34:F37) -> 1 | W16: =SUM(G34:G37) -> 0 | X16: =SUM(H34:H37) -> 0 | Y16: =SUM(I34:I37) -> 0 | Z16: =SUM(J34:J37) -> 2 | ... AF16: =SUM(P34:P37) -> 27
B17: 08.45 - 9.00 | C17: 0 | D17: 0 | E17: 0 | F17: 0 | G17: 0 | H17: 0 | I17: 0 | J17: 0 | K17: 0 | L17: 0 | M17: 4 | N17: 0 | O17: =SUM(C17:L17,N17) -> 0 | P17: =SUM(C17:N17) -> 4 | R17: 1400-1500 | S17: =SUM(C38:C41) -> 2 | T17: =SUM(D38:D41) -> 0 | U17: =SUM(E38:E41) -> 4 | V17: =SUM(F38:F41) -> 2 | W17: =SUM(G38:G41) -> 0 | X17: =SUM(H38:H41) -> 0 | Y17: =SUM(I38:I41) -> 0 | Z17: =SUM(J38:J41) -> 0 | ... AF17: =SUM(P38:P41) -> 42
B18: 09.00 - 09.15 | C18: 1 | D18: 1 | E18: 0 | F18: 0 | G18: 0 | H18: 0 | I18: 0 | J18: 0 | K18: 0 | L18: 0 | M18: 3 | N18: 0 | O18: =SUM(C18:L18,N18) -> 2 | P18: =SUM(C18:N18) -> 5 | R18: 1500-1600 | S18: =SUM(C42:C45) -> 1 | T18: =SUM(D42:D45) -> 1 | U18: =SUM(E42:E45) -> 0 | V18: =SUM(F42:F45) -> 1 | W18: =SUM(G42:G45) -> 0 | X18: =SUM(H42:H45) -> 0 | Y18: =SUM(I42:I45) -> 8 | Z18: =SUM(J42:J45) -> 2 | ... AF18: =SUM(P42:P45) -> 37
B19: 09.15 - 09.30 | C19: 0 | D19: 0 | E19: 1 | F19: 1 | G19: 0 | H19: 0 | I19: 0 | J19: 0 | K19: 0 | L19: 0 | M19: 4 | N19: 0 | O19: =SUM(C19:L19,N19) -> 2 | P19: =SUM(C19:N19) -> 6 | R19: 1600-1700 | S19: =SUM(C46:C49) -> 13 | T19: =SUM(D46:D49) -> 0 | U19: =SUM(E46:E49) -> 2 | V19: =SUM(F46:F49) -> 2 | W19: =SUM(G46:G49) -> 0 | X19: =SUM(H46:H49) -> 0 | Y19: =SUM(I46:I49) -> 0 | Z19: =SUM(J46:J49) -> 1 | ... AF19: =SUM(P46:P49) -> 41
B20: 09.30 - 09.45 | C20: 0 | D20: 0 | E20: 0 | F20: 1 | G20: 0 | H20: 0 | I20: 1 | J20: 2 | K20: 0 | L20: 0 | M20: 8 | N20: 0 | O20: =SUM(C20:L20,N20) -> 4 | P20: =SUM(C20:N20) -> 12 | R20: 1700-1800 | S20: =SUM(C50:C53) -> 1 | T20: =SUM(D50:D53) -> 4 | U20: =SUM(E50:E53) -> 1 | V20: =SUM(F50:F53) -> 2 | W20: =SUM(G50:G53) -> 0 | X20: =SUM(H50:H53) -> 0 | Y20: =SUM(I50:I53) -> 5 | Z20: =SUM(J50:J53) -> 1 | ... AF20: =SUM(P50:P53) -> 42
B21: 09.45 - 10.00 | C21: 0 | D21: 0 | E21: 0 | F21: 0 | G21: 0 | H21: 0 | I21: 0 | J21: 0 | K21: 0 | L21: 0 | M21: 1 | N21: 0 | O21: =SUM(C21:L21,N21) -> 0 | P21: =SUM(C21:N21) -> 1 | R21: 1800-1900 | S21: =SUM(C54:C57) -> 2 | T21: =SUM(D54:D57) -> 0 | U21: =SUM(E54:E57) -> 0 | V21: =SUM(F54:F57) -> 1 | W21: =SUM(G54:G57) -> 0 | X21: =SUM(H54:H57) -> 0 | Y21: =SUM(I54:I57) -> 1 | Z21: =SUM(J54:J57) -> 2 | ... AF21: =SUM(P54:P57) -> 18
B22: 10.00 - 10.15 | C22: 2 | D22: 0 | E22: 0 | F22: 1 | G22: 0 | H22: 0 | I22: 0 | J22: 0 | K22: 0 | L22: 0 | M22: 2 | N22: 0 | O22: =SUM(C22:L22,N22) -> 3 | P22: =SUM(C22:N22) -> 5 | R22: AM Peak Hr | S22: =MAX(S10:S12) -> 2 | T22: =MAX(T10:T12) -> 1 | U22: =MAX(U10:U12) -> 1 | V22: =MAX(V10:V12) -> 2 | W22: =MAX(W10:W12) -> 0 | X22: =MAX(X10:X12) -> 0 | Y22: =MAX(Y10:Y12) -> 1 | Z22: =MAX(Z10:Z12) -> 2 | ... AF22: =MAX(AF10:AF12) -> 27
B23: 10.15 - 10.30 | C23: 0 | D23: 0 | E23: 0 | F23: 0 | G23: 0 | H23: 0 | I23: 1 | J23: 0 | K23: 0 | L23: 0 | M23: 8 | N23: 0 | O23: =SUM(C23:L23,N23) -> 1 | P23: =SUM(C23:N23) -> 9 | R23: IP Peak Hr | S23: =MAX(S13:S18) -> 4 | T23: =MAX(T13:T18) -> 1 | U23: =MAX(U13:U18) -> 4 | V23: =MAX(V13:V18) -> 4 | W23: =MAX(W13:W18) -> 0 | X23: =MAX(X13:X18) -> 0 | Y23: =MAX(Y13:Y18) -> 8 | Z23: =MAX(Z13:Z18) -> 2 | ... AF23: =MAX(AF13:AF18) -> 42
B24: 10.30 - 10.45 | C24: 2 | D24: 0 | E24: 0 | F24: 0 | G24: 0 | H24: 0 | I24: 0 | J24: 0 | K24: 0 | L24: 0 | M24: 3 | N24: 1 | O24: =SUM(C24:L24,N24) -> 3 | P24: =SUM(C24:N24) -> 6 | R24: PM Peak Hr | S24: =MAX(S19:S21) -> 13 | T24: =MAX(T19:T21) -> 4 | U24: =MAX(U19:U21) -> 2 | V24: =MAX(V19:V21) -> 2 | W24: =MAX(W19:W21) -> 0 | X24: =MAX(X19:X21) -> 0 | Y24: =MAX(Y19:Y21) -> 5 | Z24: =MAX(Z19:Z21) -> 2 | ... AF24: =MAX(AF19:AF21) -> 42
B25: 10.45 - 11.00 | C25: 0 | D25: 0 | E25: 0 | F25: 0 | G25: 0 | H25: 0 | I25: 0 | J25: 0 | K25: 0 | L25: 0 | M25: 5 | N25: 0 | O25: =SUM(C25:L25,N25) -> 0 | P25: =SUM(C25:N25) -> 5 | R25: AM Period | S25: =SUM(S10:S12) -> 3 | T25: =SUM(T10:T12) -> 1 | U25: =SUM(U10:U12) -> 2 | V25: =SUM(V10:V12) -> 5 | W25: =SUM(W10:W12) -> 0 | X25: =SUM(X10:X12) -> 0 | Y25: =SUM(Y10:Y12) -> 2 | Z25: =SUM(Z10:Z12) -> 2 | ... AF25: =SUM(AF10:AF12) -> 65
B26: 11.00 - 11.15 | C26: 2 | D26: 0 | E26: 0 | F26: 2 | G26: 0 | H26: 0 | I26: 0 | J26: 0 | K26: 0 | L26: 0 | M26: 4 | N26: 0 | O26: =SUM(C26:L26,N26) -> 4 | P26: =SUM(C26:N26) -> 8 | R26: IP Period | S26: =SUM(S13:S18) -> 11 | T26: =SUM(T13:T18) -> 1 | U26: =SUM(U13:U18) -> 7 | V26: =SUM(V13:V18) -> 12 | W26: =SUM(W13:W18) -> 0 | X26: =SUM(X13:X18) -> 0 | Y26: =SUM(Y13:Y18) -> 11 | Z26: =SUM(Z13:Z18) -> 7 | ... AF26: =SUM(AF13:AF18) -> 205
B27: 11.15 - 11.30 | C27: 0 | D27: 0 | E27: 0 | F27: 0 | G27: 0 | H27: 0 | I27: 0 | J27: 0 | K27: 0 | L27: 0 | M27: 6 | N27: 0 | O27: =SUM(C27:L27,N27) -> 0 | P27: =SUM(C27:N27) -> 6 | R27: PM Period | S27: =SUM(S19:S21) -> 16 | T27: =SUM(T19:T21) -> 4 | U27: =SUM(U19:U21) -> 3 | V27: =SUM(V19:V21) -> 5 | W27: =SUM(W19:W21) -> 0 | X27: =SUM(X19:X21) -> 0 | Y27: =SUM(Y19:Y21) -> 6 | Z27: =SUM(Z19:Z21) -> 4 | ... AF27: =SUM(AF19:AF21) -> 101
B28: 11.30 - 11.45 | C28: 0 | D28: 0 | E28: 2 | F28: 1 | G28: 0 | H28: 0 | I28: 1 | J28: 1 | K28: 0 | L28: 0 | M28: 6 | N28: 0 | O28: =SUM(C28:L28,N28) -> 5 | P28: =SUM(C28:N28) -> 11 | R28: 12 Hours | S28: =SUM(S10:S21) -> 30 | T28: =SUM(T10:T21) -> 6 | U28: =SUM(U10:U21) -> 12 | V28: =SUM(V10:V21) -> 22 | W28: =SUM(W10:W21) -> 0 | X28: =SUM(X10:X21) -> 0 | Y28: =SUM(Y10:Y21) -> 19 | Z28: =SUM(Z10:Z21) -> 13 | ... AF28: =SUM(AF10:AF21) -> 371
B29: 11.45 - 12.00 | C29: 0 | D29: 0 | E29: 0 | F29: 1 | G29: 0 | H29: 0 | I29: 0 | J29: 0 | K29: 0 | L29: 0 | M29: 9 | N29: 0 | O29: =SUM(C29:L29,N29) -> 1 | P29: =SUM(C29:N29) -> 10
B30: 12.00 - 12.15 | C30: 0 | D30: 0 | E30: 0 | F30: 0 | G30: 0 | H30: 0 | I30: 0 | J30: 0 | K30: 0 | L30: 0 | M30: 12 | N30: 0 | O30: =SUM(C30:L30,N30) -> 0 | P30: =SUM(C30:N30) -> 12
B31: 12.15 - 12.30 | C31: 0 | D31: 0 | E31: 0 | F31: 0 | G31: 0 | H31: 0 | I31: 0 | J31: 0 | K31: 0 | L31: 0 | M31: 3 | N31: 1 | O31: =SUM(C31:L31,N31) -> 1 | P31: =SUM(C31:N31) -> 4
B32: 12.30 - 12.45 | C32: 1 | D32: 0 | E32: 0 | F32: 1 | G32: 0 | H32: 0 | I32: 1 | J32: 1 | K32: 0 | L32: 0 | M32: 7 | N32: 1 | O32: =SUM(C32:L32,N32) -> 5 | P32: =SUM(C32:N32) -> 12
B33: 12.45 - 13.00 | C33: 1 | D33: 0 | E33: 1 | F33: 2 | G33: 0 | H33: 0 | I33: 0 | J33: 1 | K33: 0 | L33: 0 | M33: 6 | N33: 0 | O33: =SUM(C33:L33,N33) -> 5 | P33: =SUM(C33:N33) -> 11
B34: 13.00 - 13.15 | C34: 0 | D34: 0 | E34: 0 | F34: 0 | G34: 0 | H34: 0 | I34: 0 | J34: 2 | K34: 0 | L34: 0 | M34: 3 | N34: 0 | O34: =SUM(C34:L34,N34) -> 2 | P34: =SUM(C34:N34) -> 5
B35: 13.15 - 13.30 | C35: 0 | D35: 0 | E35: 0 | F35: 0 | G35: 0 | H35: 0 | I35: 0 | J35: 0 | K35: 0 | L35: 0 | M35: 4 | N35: 0 | O35: =SUM(C35:L35,N35) -> 0 | P35: =SUM(C35:N35) -> 4
B36: 13.30 - 13.45 | C36: 0 | D36: 0 | E36: 0 | F36: 1 | G36: 0 | H36: 0 | I36: 0 | J36: 0 | K36: 0 | L36: 0 | M36: 8 | N36: 0 | O36: =SUM(C36:L36,N36) -> 1 | P36: =SUM(C36:N36) -> 9
B37: 13.45 - 14.00 | C37: 0 | D37: 0 | E37: 0 | F37: 0 | G37: 0 | H37: 0 | I37: 0 | J37: 0 | K37: 0 | L37: 0 | M37: 9 | N37: 0 | O37: =SUM(C37:L37,N37) -> 0 | P37: =SUM(C37:N37) -> 9
B38: 14.00 - 14.15 | C38: 1 | D38: 0 | E38: 0 | F38: 0 | G38: 0 | H38: 0 | I38: 0 | J38: 0 | K38: 0 | L38: 0 | M38: 7 | N38: 0 | O38: =SUM(C38:L38,N38) -> 1 | P38: =SUM(C38:N38) -> 8
B39: 14.15 - 14.30 | C39: 0 | D39: 0 | E39: 2 | F39: 1 | G39: 0 | H39: 0 | I39: 0 | J39: 0 | K39: 0 | L39: 0 | M39: 9 | N39: 0 | O39: =SUM(C39:L39,N39) -> 3 | P39: =SUM(C39:N39) -> 12
B40: 14.30 - 14.45 | C40: 0 | D40: 0 | E40: 2 | F40: 1 | G40: 0 | H40: 0 | I40: 0 | J40: 0 | K40: 0 | L40: 0 | M40: 9 | N40: 0 | O40: =SUM(C40:L40,N40) -> 3 | P40: =SUM(C40:N40) -> 12
... B56: 18.30 - 18.45 | C56: 0 | D56: 0 | E56: 0 | F56: 1 | G56: 0 | H56: 0 | I56: 0 | J56: 0 | K56: 0 | L56: 0 | M56: 5 | N56: 0 | O56: =SUM(C56:L56,N56) -> 1 | P56: =SUM(C56:N56) -> 6
B57: 18.45 - 19.00 | C57: 1 | D57: 0 | E57: 0 | F57: 0 | G57: 0 | H57: 0 | I57: 0 | J57: 1 | K57: 0 | L57: 0 | M57: S | N57: 0 | O57: =SUM(C57:L57,N57) -> 2 | P57: =SUM(C57:N57) -> 2
...

Sheet 18.10 KAPEEKA-NGOMA
B1: Consultancy services for Preparation of Expressway Development Master Plan (EDMP) for Uganda
B2: MANUAL CLASSIFIED COUNT (MCC)
B3: ROAD NAME: | C3: ='17.10 KAPEEKA-NGOMA'!C3:G3 -> KAPEEKA -NGOMA ROAD
C5: Date | D5: 18.10.2019 | F5: Location | G5: ='17.10 KAPEEKA-NGOMA'!G5:H5 -> BUTALANGU | J5: Surveyor | K5: ='17.10 KAPEEKA-NGOMA'!K5:L5 -> MIREMBE RUTH
C6: Dir. From | D6: ='17.10 KAPEEKA-NGOMA'!D6:E6 -> KAPEEKA | F6: Dir. To | G6: ='17.10 KAPEEKA-NGOMA'!G6:H6 -> NGOMA | J6: Supervisor | K6: ='17.10 KAPEEKA-NGOMA'!K6:L6 -> MIREMBE RUTH
B8: Time / Veh Type | R8: SUMMARY TRAFFIC VOLUMES
C9: 1. Car | D9: 2. Station Wagon | E9: 3. Pickups | F9: 4. Minibus, matatu | G9: 5. Medium bus | H9: 6. Large Bus | I9: 7. Light Truck | J9: 8. Medium Truck | K9: 9. Heavy truck | L9: 10. Truck Trailer | M9: 11. Motor cycles | N9: 12. Tractors | O9: Total Excl M/Cycles | P9: Total All | R9: Time | S9: 1. Car | T9: 2. Station Wagon | U9: 3. Pickups | V9: 4. Minibus, matatu | W9: 5. Medium bus | X9: 6. Large Bus | Y9: 7. Light Truck | Z9: 8. Medium Truck | AA9: 9. Heavy truck | AB9: 10. Truck Trailer | AC9: 11. Motorcycles | AD9: 12. Tractors, Graders | AE9: Total Excl M/ Cycles | AF9: Total All
B10: 07.00 - 07.15 | C10: 0 | D10: 0 | E10: 0 | F10: 0 | G10: 0 | H10: 0 | I10: 2 | J10: 0 | K10: 0 | L10: 0 | M10: 5 | N10: 0 | O10: =SUM(C10:L10,N10) -> 2 | P10: =SUM(C10:N10) -> 7 | R10: 0700-0800 | S10: =SUM(C10:C13) -> 1 | T10: =SUM(D10:D13) -> 0 | U10: =SUM(E10:E13) -> 0 | V10: =SUM(F10:F13) -> 0 | W10: =SUM(G10:G13) -> 0 | X10: =SUM(H10:H13) -> 0 | Y10: =SUM(I10:I13) -> 6 | Z10: =SUM(J10:J13) -> 0 | ... AF10: =SUM(P10:P13) -> 32
B11: 07.15 - 07.30 | C11: 0 | D11: 0 | E11: 0 | F11: 0 | G11: 0 | H11: 0 | I11: 3 | J11: 0 | K11: 0 | L11: 0 | M11: 5 | N11: 0 | O11: =SUM(C11:L11,N11) -> 3 | P11: =SUM(C11:N11) -> 8 | R11: 0800-0900 | S11: =SUM(C14:C17) -> 0 | T11: =SUM(D14:D17) -> 0 | U11: =SUM(E14:E17) -> 1 | V11: =SUM(F14:F17) -> 0 | W11: =SUM(G14:G17) -> 0 | X11: =SUM(H14:H17) -> 0 | Y11: =SUM(I14:I17) -> 2 | Z11: =SUM(J14:J17) -> 1 | ... AF11: =SUM(P14:P17) -> 21
B12: 07.30 - 07.45 | C12: 0 | D12: 0 | E12: 0 | F12: 0 | G12: 0 | H12: 0 | I12: 1 | J12: 0 | K12: 0 | L12: 0 | M12: 7 | N12: 0 | O12: =SUM(C12:L12,N12) -> 1 | P12: =SUM(C12:N12) -> 8 | R12: 0900-1000 | S12: =SUM(C18:C21) -> 1 | T12: =SUM(D18:D21) -> 0 | U12: =SUM(E18:E21) -> 1 | V12: =SUM(F18:F21) -> 0 | W12: =SUM(G18:G21) -> 0 | X12: =SUM(H18:H21) -> 0 | Y12: =SUM(I18:I21) -> 3 | Z12: =SUM(J18:J21) -> 0 | ... AF12: =SUM(P18:P21) -> 21
B13: 07.45 - 08.00 | C13: 1 | D13: 0 | E13: 0 | F13: 0 | G13: 0 | H13: 0 | I13: 0 | J13: 0 | K13: 0 | L13: 4 | M13: 4 | N13: 0 | O13: =SUM(C13:L13,N13) -> 5 | P13: =SUM(C13:N13) -> 9 | R13: 1000-1100 | S13: =SUM(C22:C25) -> 1 | T13: =SUM(D22:D25) -> 2 | U13: =SUM(E22:E25) -> 1 | V13: =SUM(F22:F25) -> 1 | W13: =SUM(G22:G25) -> 0 | X13: =SUM(H22:H25) -> 0 | Y13: =SUM(I22:I25) -> 2 | Z13: =SUM(J22:J25) -> 0 | ... AF13: =SUM(P22:P25) -> 27
B14: 08.00 - 08.15 | C14: 0 | D14: 0 | E14: 0 | F14: 0 | G14: 0 | H14: 0 | I14: 1 | J14: 0 | K14: 1 | L14: 0 | M14: 6 | N14: 0 | O14: =SUM(C14:L14,N14) -> 2 | P14: =SUM(C14:N14) -> 8 | R14: 1100-1200 | S14: =SUM(C26:C29) -> 2 | T14: =SUM(D26:D29) -> 0 | U14: =SUM(E26:E29) -> 0 | V14: =SUM(F26:F29) -> 2 | W14: =SUM(G26:G29) -> 0 | X14: =SUM(H26:H29) -> 0 | Y14: =SUM(I26:I29) -> 1 | Z14: =SUM(J26:J29) -> 0 | ... AF14: =SUM(P26:P29) -> 32
B15: 08.15 - 08.30 | C15: 0 | D15: 0 | E15: 1 | F15: 0 | G15: 0 | H15: 0 | I15: 0 | J15: 0 | K15: 0 | L15: 0 | M15: 3 | N15: 0 | O15: =SUM(C15:L15,N15) -> 1 | P15: =SUM(C15:N15) -> 4 | R15: 1200-1300 | S15: =SUM(C30:C33) -> 2 | T15: =SUM(D30:D33) -> 0 | U15: =SUM(E30:E33) -> 0 | V15: =SUM(F30:F33) -> 2 | W15: =SUM(G30:G33) -> 0 | X15: =SUM(H30:H33) -> 0 | Y15: =SUM(I30:I33) -> 3 | Z15: =SUM(J30:J33) -> 1 | ... AF15: =SUM(P30:P33) -> 27
B16: 08.30 - 08.45 | C16: 0 | D16: 0 | E16: 0 | F16: 0 | G16: 0 | H16: 0 | I16: 0 | J16: 1 | K16: 0 | L16: 0 | M16: 5 | N16: 0 | O16: =SUM(C16:L16,N16) -> 1 | P16: =SUM(C16:N16) -> 6 | R16: 1300-1400 | S16: =SUM(C34:C37) -> 1 | T16: =SUM(D34:D37) -> 0 | U16: =SUM(E34:E37) -> 2 | V16: =SUM(F34:F37) -> 2 | W16: =SUM(G34:G37) -> 0 | X16: =SUM(H34:H37) -> 0 | Y16: =SUM(I34:I37) -> 4 | Z16: =SUM(J34:J37) -> 1 | ... AF16: =SUM(P34:P37) -> 36
B17: 08.45 - 9.00 | C17: 0 | D17: 0 | E17: 0 | F17: 0 | G17: 0 | H17: 0 | I17: 1 | J17: 0 | K17: 0 | L17: 0 | M17: 2 | N17: 0 | O17: =SUM(C17:L17,N17) -> 1 | P17: =SUM(C17:N17) -> 3 | R17: 1400-1500 | S17: =SUM(C38:C41) -> 11 | T17: =SUM(D38:D41) -> 1 | U17: =SUM(E38:E41) -> 1 | V17: =SUM(F38:F41) -> 1 | W17: =SUM(G38:G41) -> 0 | X17: =SUM(H38:H41) -> 0 | Y17: =SUM(I38:I41) -> 4 | Z17: =SUM(J38:J41) -> 0 | ... AF17: =SUM(P38:P41) -> 36
B18: 09.00 - 09.15 | C18: 0 | D18: 0 | E18: 1 | F18: 0 | G18: 0 | H18: 0 | I18: 1 | J18: 0 | K18: 0 | L18: 0 | M18: 4 | N18: 0 | O18: =SUM(C18:L18,N18) -> 2 | P18: =SUM(C18:N18) -> 6 | R18: 1500-1600 | S18: =SUM(C42:C45) -> 1 | T18: =SUM(D42:D45) -> 0 | U18: =SUM(E42:E45) -> 2 | V18: =SUM(F42:F45) -> 1 | W18: =SUM(G42:G45) -> 0 | X18: =SUM(H42:H45) -> 0 | Y18: =SUM(I42:I45) -> 2 | Z18: =SUM(J42:J45) -> 0 | ... AF18: =SUM(P42:P45) -> 33
B19: 09.15 - 09.30 | C19: 1 | D19: 0 | E19: 0 | F19: 0 | G19: 0 | H19: 0 | I19: 1 | J19: 0 | K19: 0 | L19: 0 | M19: 5 | N19: 0 | O19: =SUM(C19:L19,N19) -> 2 | P19: =SUM(C19:N19) -> 7 | R19: 1600-1700 | S19: =SUM(C46:C49) -> 0 | T19: =SUM(D46:D49) -> 1 | U19: =SUM(E46:E49) -> 1 | V19: =SUM(F46:F49) -> 3 | W19: =SUM(G46:G49) -> 0 | X19: =SUM(H46:H49) -> 0 | Y19: =SUM(I46:I49) -> 1 | Z19: =SUM(J46:J49) -> 0 | ... AF19: =SUM(P46:P49) -> 31
B20: 09.30 - 09.45 | C20: 0 | D20: 0 | E20: 0 | F20: 0 | G20: 0 | H20: 0 | I20: 0 | J20: 0 | K20: 0 | L20: 0 | M20: 2 | N20: 0 | O20: =SUM(C20:L20,N20) -> 0 | P20: =SUM(C20:N20) -> 2 | R20: 1700-1800 | S20: =SUM(C50:C53) -> 2 | T20: =SUM(D50:D53) -> 1 | U20: =SUM(E50:E53) -> 0 | V20: =SUM(F50:F53) -> 0 | W20: =SUM(G50:G53) -> 0 | X20: =SUM(H50:H53) -> 0 | Y20: =SUM(I50:I53) -> 1 | Z20: =SUM(J50:J53) -> 0 | ... AF20: =SUM(P50:P53) -> 28
B21: 09.45 - 10.00 | C21: 0 | D21: 0 | E21: 0 | F21: 0 | G21: 0 | H21: 0 | I21: 1 | J21: 0 | K21: 0 | L21: 0 | M21: 5 | N21: 0 | O21: =SUM(C21:L21,N21) -> 1 | P21: =SUM(C21:N21) -> 6 | R21: 1800-1900 | S21: =SUM(C54:C57) -> 4 | T21: =SUM(D54:D57) -> 1 | U21: =SUM(E54:E57) -> 0 | V21: =SUM(F54:F57) -> 4 | W21: =SUM(G54:G57) -> 0 | X21: =SUM(H54:H57) -> 0 | Y21: =SUM(I54:I57) -> 1 | Z21: =SUM(J54:J57) -> 0 | ... AF21: =SUM(P54:P57) -> 27
B22: 10.00 - 10.15 | C22: 1 | D22: 1 | E22: 0 | F22: 0 | G22: 0 | H22: 0 | I22: 0 | J22: 0 | K22: 0 | L22: 0 | M22: 6 | N22: 0 | O22: =SUM(C22:L22,N22) -> 2 | P22: =SUM(C22:N22) -> 8 | R22: AM Peak Hr | S22: =MAX(S10:S12) -> 1 | T22: =MAX(T10:T12) -> 0 | U22: =MAX(U10:U12) -> 1 | V22: =MAX(V10:V12) -> 0 | W22: =MAX(W10:W12) -> 0 | X22: =MAX(X10:X12) -> 0 | Y22: =MAX(Y10:Y12) -> 6 | Z22: =MAX(Z10:Z12) -> 1 | ... AF22: =MAX(AF10:AF12) -> 32
B23: 10.15 - 10.30 | C23: 0 | D23: 0 | E23: 0 | F23: 0 | G23: 0 | H23: 0 | I23: 1 | J23: 0 | K23: 0 | L23: 0 | M23: 3 | N23: 0 | O23: =SUM(C23:L23,N23) -> 1 | P23: =SUM(C23:N23) -> 4 | R23: IP Peak Hr | S23: =MAX(S13:S18) -> 11 | T23: =MAX(T13:T18) -> 2 | U23: =MAX(U13:U18) -> 2 | V23: =MAX(V13:V18) -> 2 | W23: =MAX(W13:W18) -> 0 | X23: =MAX(X13:X18) -> 0 | Y23: =MAX(Y13:Y18) -> 4 | Z23: =MAX(Z13:Z18) -> 1 | ... AF23: =MAX(AF13:AF18) -> 36
B24: 10.30 - 10.45 | C24: 0 | D24: 1 | E24: 1 | F24: 1 | G24: 0 | H24: 0 | I24: 0 | J24: 0 | K24: 0 | L24: 0 | M24: 4 | N24: 0 | O24: =SUM(C24:L24,N24) -> 3 | P24: =SUM(C24:N24) -> 7 | R24: PM Peak Hr | S24: =MAX(S19:S21) -> 4 | T24: =MAX(T19:T21) -> 1 | U24: =MAX(U19:U21) -> 1 | V24: =MAX(V19:V21) -> 4 | W24: =MAX(W19:W21) -> 0 | X24: =MAX(X19:X21) -> 0 | Y24: =MAX(Y19:Y21) -> 1 | Z24: =MAX(Z19:Z21) -> 0 | ... AF24: =MAX(AF19:AF21) -> 31
B25: 10.45 - 11.00 | C25: 0 | D25: 0 | E25: 0 | F25: 0 | G25: 0 | H25: 0 | I25: 1 | J25: 0 | K25: 0 | L25: 0 | M25: 7 | N25: 0 | O25: =SUM(C25:L25,N25) -> 1 | P25: =SUM(C25:N25) -> 8 | R25: AM Period | S25: =SUM(S10:S12) -> 2 | T25: =SUM(T10:T12) -> 0 | U25: =SUM(U10:U12) -> 2 | V25: =SUM(V10:V12) -> 0 | W25: =SUM(W10:W12) -> 0 | X25: =SUM(X10:X12) -> 0 | Y25: =SUM(Y10:Y12) -> 11 | Z25: =SUM(Z10:Z12) -> 1 | ... AF25: =SUM(AF10:AF12) -> 74
B26: 11.00 - 11.15 | C26: 0 | D26: 0 | E26: 0 | F26: 1 | G26: 0 | H26: 0 | I26: 0 | J26: 0 | K26: 0 | L26: 1 | M26: 9 | N26: 0 | O26: =SUM(C26:L26,N26) -> 2 | P26: =SUM(C26:N26) -> 11 | R26: IP Period | S26: =SUM(S13:S18) -> 18 | T26: =SUM(T13:T18) -> 3 | U26: =SUM(U13:U18) -> 6 | V26: =SUM(V13:V18) -> 9 | W26: =SUM(W13:W18) -> 0 | X26: =SUM(X13:X18) -> 0 | Y26: =SUM(Y13:Y18) -> 16 | Z26: =SUM(Z13:Z18) -> 2 | ... AF26: =SUM(AF13:AF18) -> 191
B27: 11.15 - 11.30 | C27: 0 | D27: 0 | E27: 0 | F27: 0 | G27: 0 | H27: 0 | I27: 0 | J27: 0 | K27: 0 | L27: 0 | M27: 6 | N27: 0 | O27: =SUM(C27:L27,N27) -> 0 | P27: =SUM(C27:N27) -> 6 | R27: PM Period | S27: =SUM(S19:S21) -> 6 | T27: =SUM(T19:T21) -> 3 | U27: =SUM(U19:U21) -> 1 | V27: =SUM(V19:V21) -> 7 | W27: =SUM(W19:W21) -> 0 | X27: =SUM(X19:X21) -> 0 | Y27: =SUM(Y19:Y21) -> 3 | Z27: =SUM(Z19:Z21) -> 0 | ... AF27: =SUM(AF19:AF21) -> 86
B28: 11.30 - 11.45 | C28: 0 | D28: 0 | E28: 0 | F28: 0 | G28: 0 | H28: 0 | I28: 1 | J28: 0 | K28: 0 | L28: 0 | M28: 4 | N28: 0 | O28: =SUM(C28:L28,N28) -> 1 | P28: =SUM(C28:N28) -> 5 | R28: 12 Hours | S28: =SUM(S10:S21) -> 26 | T28: =SUM(T10:T21) -> 6 | U28: =SUM(U10:U21) -> 9 | V28: =SUM(V10:V21) -> 16 | W28: =SUM(W10:W21) -> 0 | X28: =SUM(X10:X21) -> 0 | Y28: =SUM(Y10:Y21) -> 30 | Z28: =SUM(Z10:Z21) -> 3 | ... AF28: =SUM(AF10:AF21) -> 351
B29: 11.45 - 12.00 | C29: 2 | D29: 0 | E29: 0 | F29: 1 | G29: 0 | H29: 0 | I29: 0 | J29: 0 | K29: 0 | L29: 0 | M29: 7 | N29: 0 | O29: =SUM(C29:L29,N29) -> 3 | P29: =SUM(C29:N29) -> 10
B30: 12.00 - 12.15 | C30: 0 | D30: 0 | E30: 0 | F30: 0 | G30: 0 | H30: 0 | I30: 1 | J30: 0 | K30: 0 | L30: 0 | M30: 5 | N30: 0 | O30: =SUM(C30:L30,N30) -> 1 | P30: =SUM(C30:N30) -> 6
B31: 12.15 - 12.30 | C31: 0 | D31: 0 | E31: 0 | F31: 1 | G31: 0 | H31: 0 | I31: 1 | J31: 0 | K31: 0 | L31: 0 | M31: 3 | N31: 0 | O31: =SUM(C31:L31,N31) -> 2 | P31: =SUM(C31:N31) -> 5
B32: 12.30 - 12.45 | C32: 1 | D32: 0 | E32: 0 | F32: 1 | G32: 0 | H32: 0 | I32: 0 | J32: 0 | K32: 0 | L32: 0 | M32: 5 | N32: 0 | O32: =SUM(C32:L32,N32) -> 2 | P32: =SUM(C32:N32) -> 7
B33: 12.45 - 13.00 | C33: 1 | D33: 0 | E33: 0 | F33: 0 | G33: 0 | H33: 0 | I33: 1 | J33: 1 | K33: 0 | L33: 0 | M33: 6 | N33: 0 | O33: =SUM(C33:L33,N33) -> 3 | P33: =SUM(C33:N33) -> 9
B34: 13.00 - 13.15 | C34: 0 | D34: 0 | E34: 1 | F34: 0 | G34: 0 | H34: 0 | I34: 1 | J34: 1 | K34: 0 | L34: 0 | M34: 10 | N34: 0 | O34: =SUM(C34:L34,N34) -> 3 | P34: =SUM(C34:N34) -> 13
B35: 13.15 - 13.30 | C35: 1 | D35: 0 | E35: 0 | F35: 0 | G35: 0 | H35: 0 | I35: 0 | J35: 0 | K35: 0 | L35: 0 | M35: 9 | N35: 0 | O35: =SUM(C35:L35,N35) -> 1 | P35: =SUM(C35:N35) -> 10
B36: 13.30 - 13.45 | C36: 0 | D36: 0 | E36: 1 | F36: 1 | G36: 0 | H36: 0 | I36: 2 | J36: 0 | K36: 0 | L36: 0 | M36: 2 | N36: 0 | O36: =SUM(C36:L36,N36) -> 4 | P36: =SUM(C36:N36) -> 6
B37: 13.45 - 14.00 | C37: 0 | D37: 0 | E37: 0 | F37: 1 | G37: 0 | H37: 0 | I37: 1 | J37: 0 | K37: 0 | L37: 0 | M37: 5 | N37: 0 | O37: =SUM(C37:L37,N37) -> 2 | P37: =SUM(C37:N37) -> 7
B38: 14.00 - 14.15 | C38: 0 | D38: 0 | E38: 0 | F38: 1 | G38: 0 | H38: 0 | I38: 1 | J38: 0 | K38: 0 | L38: 0 | M38: 1 | N38: 0 | O38: =SUM(C38:L38,N38) -> 2 | P38: =SUM(C38:N38) -> 3
B39: 14.15 - 14.30 | C39: 1 | D39: 0 | E39: 0 | F39: 0 | G39: 0 | H39: 0 | I39: 2 | J39: 0 | K39: 0 | L39: 0 | M39: 4 | N39: 0 | O39: =SUM(C39:L39,N39) -> 3 | P39: =SUM(C39:N39) -> 7
B40: 14.30 - 14.45 | C40: 0 | D40: 1 | E40: 0 | F40: 0 | G40: 0 | H40: 0 | I40: 1 | J40: 0 | K40: 0 | L40: 0 | M40: 7 | N40: 1 | O40: =SUM(C40:L40,N40) -> 3 | P40: =SUM(C40:N40) -> 10
... B57: 18.45 - 19.00 | C57: 0 | D57: 1 | E57: 0 | F57: 0 | G57: 0 | H57: 0 | I57: 1 | J57: 0 | K57: 0 | L57: 0 | M57: 3 | N57: 0 | O57: =SUM(C57:L57,N57) -> 2 | P57: =SUM(C57:N57) -> 5
B58: Totals | C58: =SUM(C10:C57) -> 26 | D58: =SUM(D10:D57) -> 6 | E58: =SUM(E10:E57) -> 9 | F58: =SUM(F10:F57) -> 16 | G58: =SUM(G10:G57) -> 0 | H58: =SUM(H10:H57) -> 0 | I58: =SUM(I10:I57) -> 30 | J58: =SUM(J10:J57) -> 3 | ... P58: =SUM(P10:P57) -> 351
...

Sheet 18.10 NGOMA KAPEEKA
B1: Consultancy services for Preparation of Expressway Development Master Plan (EDMP) for Uganda
B2: MANUAL CLASSIFIED COUNT (MCC)
B3: ROAD NAME: | C3: ='17.10 NGOMA-KAPEEKA'!C3:G3 -> KAPEEKA -NGOMA ROAD
C5: Date | D5: ='18.10 KAPEEKA-NGOMA'!D5 -> 18.10.2019 | F5: Location | G5: ='17.10 KAPEEKA-NGOMA'!G5:H5 -> BUTALANGU | J5: Surveyor | K5: AMOS A
C6: Dir. From | D6: ='17.10 NGOMA-KAPEEKA'!D6:E6 -> NGOMA | F6: Dir. To | G6: ='17.10 NGOMA-KAPEEKA'!G6:H6 -> KAPEEKA | J6: Supervisor | K6: ='17.10 KAPEEKA-NGOMA'!K6:L6 -> MIREMBE RUTH
B8: Time / Veh Type | R8: SUMMARY TRAFFIC VOLUMES
C9: 1. Car | D9: 2. Station Wagon | E9: 3. Pickups | F9: 4. Minibus, matatu | G9: 5. Medium bus | H9: 6. Large Bus | I9: 7. Light Truck | J9: 8. Medium Truck | K9: 9. Heavy truck | L9: 10. Truck Trailer | M9: 11. Motor cycles | N9: 12. Tractors | O9: Total Excl M/Cycles | P9: Total All | R9: Time | S9: 1. Car | T9: 2. Station Wagon | U9: 3. Pickups | V9: 4. Minibus, matatu | W9: 5. Medium bus | X9: 6. Large Bus | Y9: 7. Light Truck | Z9: 8. Medium Truck | AA9: 9. Heavy truck | AB9: 10. Truck Trailer | AC9: 11. Motorcycles | AD9: 12. Tractors, Graders | AE9: Total Excl M/ Cycles | AF9: Total All
B10: 07.00 - 07.15 | C10: 0 | D10: 0 | E10: 0 | F10: 1 | G10: 0 | H10: 0 | I10: 0 | J10: 0 | K10: 0 | L10: 0 | M10: 0 | N10: 0 | O10: =SUM(C10:L10,N10) -> 1 | P10: =SUM(C10:N10) -> 1 | R10: 0700-0800 | S10: =SUM(C10:C13) -> 1 | T10: =SUM(D10:D13) -> 0 | U10: =SUM(E10:E13) -> 0 | V10: =SUM(F10:F13) -> 2 | W10: =SUM(G10:G13) -> 0 | X10: =SUM(H10:H13) -> 0 | Y10: =SUM(I10:I13) -> 0 | Z10: =SUM(J10:J13) -> 0 | ... AF10: =SUM(P10:P13) -> 16
B11: 07.15 - 07.30 | C11: 0 | D11: 0 | E11: 0 | F11: 0 | G11: 0 | H11: 0 | I11: 0 | J11: 0 | K11: 0 | L11: 0 | M11: 3 | N11: 0 | O11: =SUM(C11:L11,N11) -> 0 | P11: =SUM(C11:N11) -> 3 | R11: 0800-0900 | S11: =SUM(C14:C17) -> 0 | T11: =SUM(D14:D17) -> 0 | U11: =SUM(E14:E17) -> 0 | V11: =SUM(F14:F17) -> 1 | W11: =SUM(G14:G17) -> 0 | X11: =SUM(H14:H17) -> 0 | Y11: =SUM(I14:I17) -> 2 | Z11: =SUM(J14:J17) -> 1 | ... AF11: =SUM(P14:P17) -> 25
B12: 07.30 - 07.45 | C12: 1 | D12: 0 | E12: 0 | F12: 1 | G12: 0 | H12: 0 | I12: 0 | J12: 0 | K12: 0 | L12: 0 | M12: 7 | N12: 0 | O12: =SUM(C12:L12,N12) -> 2 | P12: =SUM(C12:N12) -> 9 | R12: 0900-1000 | S12: =SUM(C18:C21) -> 2 | T12: =SUM(D18:D21) -> 0 | U12: =SUM(E18:E21) -> 1 | V12: =SUM(F18:F21) -> 3 | W12: =SUM(G18:G21) -> 0 | X12: =SUM(H18:H21) -> 0 | Y12: =SUM(I18:I21) -> 1 | Z12: =SUM(J18:J21) -> 0 | ... AF12: =SUM(P18:P21) -> 21
B13: 07.45 - 08.00 | C13: 0 | D13: 0 | E13: 0 | F13: 0 | G13: 0 | H13: 0 | I13: 0 | J13: 0 | K13: 0 | L13: 0 | M13: 3 | N13: 0 | O13: =SUM(C13:L13,N13) -> 0 | P13: =SUM(C13:N13) -> 3 | R13: 1000-1100 | S13: =SUM(C22:C25) -> 4 | T13: =SUM(D22:D25) -> 0 | U13: =SUM(E22:E25) -> 0 | V13: =SUM(F22:F25) -> 1 | W13: =SUM(G22:G25) -> 0 | X13: =SUM(H22:H25) -> 0 | Y13: =SUM(I22:I25) -> 1 | Z13: =SUM(J22:J25) -> 0 | ... AF13: =SUM(P22:P25) -> 32
B14: 08.00 - 08.15 | C14: 0 | D14: 0 | E14: 0 | F14: 0 | G14: 0 | H14: 0 | I14: 0 | J14: 0 | K14: 0 | L14: 0 | M14: 3 | N14: 0 | O14: =SUM(C14:L14,N14) -> 0 | P14: =SUM(C14:N14) -> 3 | R14: 1100-1200 | S14: =SUM(C26:C29) -> 1 | T14: =SUM(D26:D29) -> 2 | U14: =SUM(E26:E29) -> 1 | V14: =SUM(F26:F29) -> 1 | W14: =SUM(G26:G29) -> 0 | X14: =SUM(H26:H29) -> 0 | Y14: =SUM(I26:I29) -> 2 | Z14: =SUM(J26:J29) -> 0 | ... AF14: =SUM(P26:P29) -> 29
B15: 08.15 - 08.30 | C15: 0 | D15: 0 | E15: 0 | F15: 0 | G15: 0 | H15: 0 | I15: 1 | J15: 0 | K15: 0 | L15: 0 | M15: 8 | N15: 0 | O15: =SUM(C15:L15,N15) -> 1 | P15: =SUM(C15:N15) -> 9 | R15: 1200-1300 | S15: =SUM(C30:C33) -> 4 | T15: =SUM(D30:D33) -> 1 | U15: =SUM(E30:E33) -> 2 | V15: =SUM(F30:F33) -> 2 | W15: =SUM(G30:G33) -> 0 | X15: =SUM(H30:H33) -> 0 | Y15: =SUM(I30:I33) -> 2 | Z15: =SUM(J30:J33) -> 0 | ... AF15: =SUM(P30:P33) -> 29
B16: 08.30 - 08.45 | C16: 0 | D16: 0 | E16: 0 | F16: 0 | G16: 0 | H16: 0 | I16: 0 | J16: 0 | K16: 0 | L16: 0 | M16: 7 | N16: 0 | O16: =SUM(C16:L16,N16) -> 0 | P16: =SUM(C16:N16) -> 7 | R16: 1300-1400 | S16: =SUM(C34:C37) -> 2 | T16: =SUM(D34:D37) -> 1 | U16: =SUM(E34:E37) -> 0 | V16: =SUM(F34:F37) -> 3 | W16: =SUM(G34:G37) -> 0 | X16: =SUM(H34:H37) -> 0 | Y16: =SUM(I34:I37) -> 5 | Z16: =SUM(J34:J37) -> 0 | ... AF16: =SUM(P34:P37) -> 38
B17: 08.45 - 9.00 | C17: 0 | D17: 0 | E17: 0 | F17: 1 | G17: 0 | H17: 0 | I17: 1 | J17: 1 | K17: 0 | L17: 0 | M17: 3 | N17: 0 | O17: =SUM(C17:L17,N17) -> 3 | P17: =SUM(C17:N17) -> 6 | R17: 1400-1500 | S17: =SUM(C38:C41) -> 2 | T17: =SUM(D38:D41) -> 0 | U17: =SUM(E38:E41) -> 3 | V17: =SUM(F38:F41) -> 1 | W17: =SUM(G38:G41) -> 0 | X17: =SUM(H38:H41) -> 0 | Y17: =SUM(I38:I41) -> 1 | Z17: =SUM(J38:J41) -> 1 | ... AF17: =SUM(P38:P41) -> 27
B18: 09.00 - 09.15 | C18: 0 | D18: 0 | E18: 0 | F18: 1 | G18: 0 | H18: 0 | I18: 0 | J18: 0 | K18: 0 | L18: 0 | M18: 2 | N18: 0 | O18: =SUM(C18:L18,N18) -> 1 | P18: =SUM(C18:N18) -> 3 | R18: 1500-1600 | S18: =SUM(C42:C45) -> 5 | T18: =SUM(D42:D45) -> 2 | U18: =SUM(E42:E45) -> 2 | V18: =SUM(F42:F45) -> 2 | W18: =SUM(G42:G45) -> 0 | X18: =SUM(H42:H45) -> 0 | Y18: =SUM(I42:I45) -> 4 | Z18: =SUM(J42:J45) -> 0 | ... AF18: =SUM(P42:P45) -> 42
B19: 09.15 - 09.30 | C19: 0 | D19: 0 | E19: 1 | F19: 0 | G19: 0 | H19: 0 | I19: 1 | J19: 0 | K19: 0 | L19: 0 | M19: 4 | N19: 0 | O19: =SUM(C19:L19,N19) -> 2 | P19: =SUM(C19:N19) -> 6 | R19: 1600-1700 | S19: =SUM(C46:C49) -> 0 | T19: =SUM(D46:D49) -> 2 | U19: =SUM(E46:E49) -> 1 | V19: =SUM(F46:F49) -> 2 | W19: =SUM(G46:G49) -> 0 | X19: =SUM(H46:H49) -> 0 | Y19: =SUM(I46:I49) -> 3 | Z19: =SUM(J46:J49) -> 0 | ... AF19: =SUM(P46:P49) -> 34
B20: 09.30 - 09.45 | C20: 0 | D20: 0 | E20: 0 | F20: 0 | G20: 0 | H20: 0 | I20: 0 | J20: 0 | K20: 0 | L20: 0 | M20: 4 | N20: 0 | O20: =SUM(C20:L20,N20) -> 0 | P20: =SUM(C20:N20) -> 4 | R20: 1700-1800 | S20: =SUM(C50:C53) -> 3 | T20: =SUM(D50:D53) -> 0 | U20: =SUM(E50:E53) -> 1 | V20: =SUM(F50:F53) -> 0 | W20: =SUM(G50:G53) -> 0 | X20: =SUM(H50:H53) -> 0 | Y20: =SUM(I50:I53) -> 5 | Z20: =SUM(J50:J53) -> 0 | ... AF20: =SUM(P50:P53) -> 30
B21: 09.45 - 10.00 | C21: 2 | D21: 0 | E21: 0 | F21: 2 | G21: 0 | H21: 0 | I21: 0 | J21: 0 | K21: 0 | L21: 0 | M21: 4 | N21: 0 | O21: =SUM(C21:L21,N21) -> 4 | P21: =SUM(C21:N21) -> 8 | R21: 1800-1900 | S21: =SUM(C54:C57) -> 2 | T21: =SUM(D54:D57) -> 0 | U21: =SUM(E54:E57) -> 1 | V21: =SUM(F54:F57) -> 2 | W21: =SUM(G54:G57) -> 0 | X21: =SUM(H54:H57) -> 0 | Y21: =SUM(I54:I57) -> 2 | Z21: =SUM(J54:J57) -> 0 | ... AF21: =SUM(P54:P57) -> 39
B22: 10.00 - 10.15 | C22: 2 | D22: 0 | E22: 0 | F22: 0 | G22: 0 | H22: 0 | I22: 0 | J22: 0 | K22: 0 | L22: 0 | M22: 6 | N22: 0 | O22: =SUM(C22:L22,N22) -> 2 | P22: =SUM(C22:N22) -> 8 | R22: AM Peak Hr | S22: =MAX(S10:S12) -> 2 | T22: =MAX(T10:T12) -> 0 | U22: =MAX(U10:U12) -> 1 | V22: =MAX(V10:V12) -> 3 | W22: =MAX(W10:W12) -> 0 | X22: =MAX(X10:X12) -> 0 | Y22: =MAX(Y10:Y12) -> 2 | Z22: =MAX(Z10:Z12) -> 1 | ... AF22: =MAX(AF10:AF12) -> 25
B23: 10.15 - 10.30 | C23: 1 | D23: 0 | E23: 0 | F23: 0 | G23: 0 | H23: 0 | I23: 0 | J23: 0 | K23: 0 | L23: 0 | M23: 9 | N23: 0 | O23: =SUM(C23:L23,N23) -> 1 | P23: =SUM(C23:N23) -> 10 | R23: IP Peak Hr | S23: =MAX(S13:S18) -> 5 | T23: =MAX(T13:T18) -> 2 | U23: =MAX(U13:U18) -> 3 | V23: =MAX(V13:V18) -> 3 | W23: =MAX(W13:W18) -> 0 | X23: =MAX(X13:X18) -> 0 | Y23: =MAX(Y13:Y18) -> 5 | Z23: =MAX(Z13:Z18) -> 1 | ... AF23: =MAX(AF13:AF18) -> 42
B24: 10.30 - 10.45 | C24: 0 | D24: 0 | E24: 0 | F24: 0 | G24: 0 | H24: 0 | I24: 0 | J24: 0 | K24: 0 | L24: 0 | M24: 8 | N24: 0 | O24: =SUM(C24:L24,N24) -> 0 | P24: =SUM(C24:N24) -> 8 | R24: PM Peak Hr | S24: =MAX(S19:S21) -> 3 | T24: =MAX(T19:T21) -> 2 | U24: =MAX(U19:U21) -> 1 | V24: =MAX(V19:V21) -> 2 | W24: =MAX(W19:W21) -> 0 | X24: =MAX(X19:X21) -> 0 | Y24: =MAX(Y19:Y21) -> 5 | Z24: =MAX(Z19:Z21) -> 0 | ... AF24: =MAX(AF19:AF21) -> 39
B25: 10.45 - 11.00 | C25: 1 | D25: 0 | E25: 0 | F25: 1 | G25: 0 | H25: 0 | I25: 1 | J25: 0 | K25: 0 | L25: 0 | M25: 3 | N25: 0 | O25: =SUM(C25:L25,N25) -> 3 | P25: =SUM(C25:N25) -> 6 | R25: AM Period | S25: =SUM(S10:S12) -> 3 | T25: =SUM(T10:T12) -> 0 | U25: =SUM(U10:U12) -> 1 | V25: =SUM(V10:V12) -> 6 | W25: =SUM(W10:W12) -> 0 | X25: =SUM(X10:X12) -> 0 | Y25: =SUM(Y10:Y12) -> 3 | Z25: =SUM(Z10:Z12) -> 1 | ... AF25: =SUM(AF10:AF12) -> 62
B26: 11.00 - 11.15 | C26: 0 | D26: 0 | E26: 0 | F26: 0 | G26: 0 | H26: 0 | I26: 0 | J26: 0 | K26: 0 | L26: 0 | M26: 4 | N26: 0 | O26: =SUM(C26:L26,N26) -> 0 | P26: =SUM(C26:N26) -> 4 | R26: IP Period | S26: =SUM(S13:S18) -> 18 | T26: =SUM(T13:T18) -> 6 | U26: =SUM(U13:U18) -> 8 | V26: =SUM(V13:V18) -> 10 | W26: =SUM(W13:W18) -> 0 | X26: =SUM(X13:X18) -> 0 | Y26: =SUM(Y13:Y18) -> 15 | Z26: =SUM(Z13:Z18) -> 1 | ... AF26: =SUM(AF13:AF18) -> 197
B27: 11.15 - 11.30 | C27: 1 | D27: 1 | E27: 0 | F27: 0 | G27: 0 | H27: 0 | I27: 0 | J27: 0 | K27: 0 | L27: 0 | M27: 6 | N27: 0 | O27: =SUM(C27:L27,N27) -> 2 | P27: =SUM(C27:N27) -> 8 | R27: PM Period | S27: =SUM(S19:S21) -> 5 | T27: =SUM(T19:T21) -> 2 | U27: =SUM(U19:U21) -> 3 | V27: =SUM(V19:V21) -> 4 | W27: =SUM(W19:W21) -> 0 | X27: =SUM(X19:X21) -> 0 | Y27: =SUM(Y19:Y21) -> 10 | Z27: =SUM(Z19:Z21) -> 0 | ... AF27: =SUM(AF19:AF21) -> 103
B28: 11.30 - 11.45 | C28: 0 | D28: 1 | E28: 1 | F28: 1 | G28: 0 | H28: 0 | I28: 1 | J28: 0 | K28: 0 | L28: 0 | M28: 8 | N28: 0 | O28: =SUM(C28:L28,N28) -> 4 | P28: =SUM(C28:N28) -> 12 | R28: 12 Hours | S28: =SUM(S10:S21) -> 26 | T28: =SUM(T10:T21) -> 8 | U28: =SUM(U10:U21) -> 12 | V28: =SUM(V10:V21) -> 20 | W28: =SUM(W10:W21) -> 0 | X28: =SUM(X10:X21) -> 0 | Y28: =SUM(Y10:Y21) -> 28 | Z28: =SUM(Z10:Z21) -> 2 | ... AF28: =SUM(AF10:AF21) -> 362
B29: 11.45 - 12.00 | C29: 0 | D29: 0 | E29: 0 | F29: 0 | G29: 0 | H29: 0 | I29: 1 | J29: 0 | K29: 0 | L29: 0 | M29: 4 | N29: 0 | O29: =SUM(C29:L29,N29) -> 1 | P29: =SUM(C29:N29) -> 5
B30: 12.00 - 12.15 | C30: 0 | D30: 0 | E30: 0 | F30: 2 | G30: 0 | H30: 0 | I30: 1 | J30: 0 | K30: 0 | L30: 0 | M30: 6 | N30: 0 | O30: =SUM(C30:L30,N30) -> 3 | P30: =SUM(C30:N30) -> 9
B31: 12.15 - 12.30 | C31: 2 | D31: 0 | E31: 0 | F31: 0 | G31: 0 | H31: 0 | I31: 1 | J31: 0 | K31: 0 | L31: 0 | M31: 4 | N31: 0 | O31: =SUM(C31:L31,N31) -> 3 | P31: =SUM(C31:N31) -> 7
B32: 12.30 - 12.45 | C32: 1 | D32: 1 | E32: 1 | F32: 0 | G32: 0 | H32: 0 | I32: 0 | J32: 0 | K32: 0 | L32: 0 | M32: 3 | N32: 0 | O32: =SUM(C32:L32,N32) -> 3 | P32: =SUM(C32:N32) -> 6
B33: 12.45 - 13.00 | C33: 1 | D33: 0 | E33: 1 | F33: 0 | G33: 0 | H33: 0 | I33: 0 | J33: 0 | K33: 0 | L33: 0 | M33: 4 | N33: 1 | O33: =SUM(C33:L33,N33) -> 3 | P33: =SUM(C33:N33) -> 7
B34: 13.00 - 13.15 | C34: 0 | D34: 0 | E34: 0 | F34: 1 | G34: 0 | H34: 0 | I34: 3 | J34: 0 | K34: 0 | L34: 0 | M34: 8 | N34: 0 | O34: =SUM(C34:L34,N34) -> 4 | P34: =SUM(C34:N34) -> 12
B35: 13.15 - 13.30 | C35: 1 | D35: 1 | E35: 0 | F35: 1 | G35: 0 | H35: 0 | I35: 1 | J35: 0 | K35: 1 | L35: 0 | M35: 10 | N35: 0 | O35: =SUM(C35:L35,N35) -> 5 | P35: =SUM(C35:N35) -> 15
B36: 13.30 - 13.45 | C36: 1 | D36: 0 | E36: 0 | F36: 0 | G36: 0 | H36: 0 | I36: 1 | J36: 0 | K36: 0 | L36: 0 | M36: 3 | N36: 0 | O36: =SUM(C36:L36,N36) -> 2 | P36: =SUM(C36:N36) -> 5
B37: 13.45 - 14.00 | C37: 0 | D37: 0 | E37: 0 | F37: 1 | G37: 0 | H37: 0 | I37: 0 | J37: 0 | K37: 0 | L37: 0 | M37: 5 | N37: 0 | O37: =SUM(C37:L37,N37) -> 1 | P37: =SUM(C37:N37) -> 6
B38: 14.00 - 14.15 | C38: 1 | D38: 0 | E38: 2 | F38: 0 | G38: 0 | H38: 0 | I38: 0 | J38: 0 | K38: 0 | L38: 0 | M38: 6 | N38: 0 | O38: =SUM(C38:L38,N38) -> 3 | P38: =SUM(C38:N38) -> 9
B39: 14.15 - 14.30 | C39: 0 | D39: 0 | E39: 0 | F39: 0 | G39: 0 | H39: 0 | I39: 1 | J39: 0 | K39: 0 | L39: 0 | M39: 3 | N39: 0 | O39: =SUM(C39:L39,N39) -> 1 | P39: =SUM(C39:N39) -> 4
B40: 14.30 - 14.45 | C40: 1 | D40: 0 | E40: 0 | F40: 0 | G40: 0 | H40: 0 | I40: 0 | J40: 1 | K40: 0 | L40: 0 | M40: 6 | N40: 0 | O40: =SUM(C40:L40,N40) -> 2 | P40: =SUM(C40:N40) -> 8
... B57: 18.45 - 19.00 | C57: 0 | D57: 0 | E57: 0 | F57: 0 | G57: 0 | H57: 0 | I57: 0 | J57: 0 | K57: 0 | L57: 0 | M57: 8 | N57: 0 | O57: =SUM(C57:L57,N57) -> 0 | P57: =SUM(C57:N57) -> 8
B58: Totals | C58: =SUM(C10:C57) -> 26 | D58: =SUM(D10:D57) -> 8 | E58: =SUM(E10:E57) -> 12 | F58: =SUM(F10:F57) -> 20 | G58: =SUM(G10:G57) -> 0 | H58: =SUM(H10:H57) -> 0 | I58: =SUM(I10:I57) -> 28 | J58: =SUM(J10:J57) -> 2 | ... P58: =SUM(P10:P57) -> 362
...

Sheet 19.10 KAPEEKA-NGOMA 24h
B1: Consultancy services for Preparation of Expressway Development Master Plan (EDMP) for Uganda
B2: MANUAL CLASSIFIED COUNT (MCC)
B3: ROAD NAME: | C3: ='17.10 KAPEEKA-NGOMA'!C3:G3 -> KAPEEKA -NGOMA ROAD
C5: Date | D5: 19.10.2019 | F5: Location | G5: ='22.10 NGOMA-KAPEERA'!G5:H5 -> BUTALANGU | J5: Surveyor | K5: ='22.10 NGOMA-KAPEERA'!K5:L5 -> AMOS A
C6: Dir. From | D6: ='17.10 KAPEEKA-NGOMA'!D6:E6 -> KAPEEKA | F6: Dir. To | G6: ='17.10 KAPEEKA-NGOMA'!G6:H6 -> NGOMA | J6: Supervisor | K6: ='22.10 NGOMA-KAPEERA'!K6:L6 -> MIREMBE RUTH
B8: Time / Veh Type | R8: SUMMARY TRAFFIC VOLUMES
C9: 1. Car | D9: 2. Station Wagon | E9: 3. Pickups | F9: 4. Minibus, matatu | G9: 5. Medium bus | H9: 6. Large Bus | I9: 7. Light Truck | J9: 8. Medium Truck | K9: 9. Heavy truck | L9: 10. Truck Trailer | M9: 11. Motor cycles | N9: 12. Tractors | O9: Total Excl M/Cycles | P9: Total All | R9: Time | S9: 1. Car | T9: 2. Station Wagon | U9: 3. Pickups | V9: 4. Minibus, matatu | W9: 5. Medium bus | X9: 6. Large Bus | Y9: 7. Light Truck | Z9: 8. Medium Truck | AA9: 9. Heavy truck | AB9: 10. Truck Trailer | AC9: 11. Motorcycles | AD9: 12. Tractors, Graders | AE9: Total Excl M/ Cycles | AF9: Total All
B10: 07.00 - 07.15 | C10: 0 | D10: 0 | E10: 0 | F10: 0 | G10: 0 | H10: 0 | I10: 0 | J10: 0 | K10: 0 | L10: 0 | M10: 5 | N10: 0 | O10: =SUM(C10:L10,N10) -> 0 | P10: =SUM(C10:N10) -> 5 | R10: 0700-0800 | S10: =SUM(C10:C13) -> 4 | T10: =SUM(D10:D13) -> 2 | U10: =SUM(E10:E13) -> 3 | V10: =SUM(F10:F13) -> 0 | W10: =SUM(G10:G13) -> 0 | X10: =SUM(H10:H13) -> 0 | Y10: =SUM(I10:I13) -> 2 | Z10: =SUM(J10:J13) -> 0 | ... AF10: =SUM(P10:P13) -> 24
B11: 07.15 - 07.30 | C11: 2 | D11: 0 | E11: 3 | F11: 0 | G11: 0 | H11: 0 | I11: 0 | J11: 0 | K11: 0 | L11: 0 | M11: 2 | N11: 0 | O11: =SUM(C11:L11,N11) -> 5 | P11: =SUM(C11:N11) -> 7 | R11: 0800-0900 | S11: =SUM(C14:C17) -> 2 | T11: =SUM(D14:D17) -> 2 | U11: =SUM(E14:E17) -> 2 | V11: =SUM(F14:F17) -> 0 | W11: =SUM(G14:G17) -> 0 | X11: =SUM(H14:H17) -> 0 | Y11: =SUM(I14:I17) -> 3 | Z11: =SUM(J14:J17) -> 0 | ... AF11: =SUM(P14:P17) -> 25
B12: 07.30 - 07.45 | C12: 1 | D12: 1 | E12: 0 | F12: 0 | G12: 0 | H12: 0 | I12: 1 | J12: 0 | K12: 0 | L12: 0 | M12: 3 | N12: 0 | O12: =SUM(C12:L12,N12) -> 3 | P12: =SUM(C12:N12) -> 6 | R12: 0900-1000 | S12: =SUM(C18:C21) -> 5 | T12: =SUM(D18:D21) -> 1 | U12: =SUM(E18:E21) -> 1 | V12: =SUM(F18:F21) -> 0 | W12: =SUM(G18:G21) -> 0 | X12: =SUM(H18:H21) -> 0 | Y12: =SUM(I18:I21) -> 2 | Z12: =SUM(J18:J21) -> 0 | ... AF12: =SUM(P18:P21) -> 28
B13: 07.45 - 08.00 | C13: 1 | D13: 1 | E13: 0 | F13: 0 | G13: 0 | H13: 0 | I13: 1 | J13: 0 | K13: 0 | L13: 0 | M13: 3 | N13: 0 | O13: =SUM(C13:L13,N13) -> 3 | P13: =SUM(C13:N13) -> 6 | R13: 1000-1100 | S13: =SUM(C22:C25) -> 4 | T13: =SUM(D22:D25) -> 0 | U13: =SUM(E22:E25) -> 1 | V13: =SUM(F22:F25) -> 1 | W13: =SUM(G22:G25) -> 0 | X13: =SUM(H22:H25) -> 0 | Y13: =SUM(I22:I25) -> 1 | Z13: =SUM(J22:J25) -> 1 | ... AF13: =SUM(P22:P25) -> 26
B14: 08.00 - 08.15 | C14: 2 | D14: 1 | E14: 0 | F14: 0 | G14: 0 | H14: 0 | I14: 1 | J14: 0 | K14: 0 | L14: 0 | M14: 1 | N14: 0 | O14: =SUM(C14:L14,N14) -> 4 | P14: =SUM(C14:N14) -> 5 | R14: 1100-1200 | S14: =SUM(C26:C29) -> 4 | T14: =SUM(D26:D29) -> 2 | U14: =SUM(E26:E29) -> 4 | V14: =SUM(F26:F29) -> 3 | W14: =SUM(G26:G29) -> 0 | X14: =SUM(H26:H29) -> 0 | Y14: =SUM(I26:I29) -> 3 | Z14: =SUM(J26:J29) -> 0 | ... AF14: =SUM(P26:P29) -> 34
B15: 08.15 - 08.30 | C15: 0 | D15: 1 | E15: 1 | F15: 0 | G15: 0 | H15: 0 | I15: 1 | J15: 0 | K15: 0 | L15: 0 | M15: 6 | N15: 0 | O15: =SUM(C15:L15,N15) -> 3 | P15: =SUM(C15:N15) -> 9 | R15: 1200-1300 | S15: =SUM(C30:C33) -> 1 | T15: =SUM(D30:D33) -> 0 | U15: =SUM(E30:E33) -> 4 | V15: =SUM(F30:F33) -> 1 | W15: =SUM(G30:G33) -> 0 | X15: =SUM(H30:H33) -> 0 | Y15: =SUM(I30:I33) -> 3 | Z15: =SUM(J30:J33) -> 0 | ... AF15: =SUM(P30:P33) -> 24
B16: 08.30 - 08.45 | C16: 0 | D16: 0 | E16: 0 | F16: 0 | G16: 0 | H16: 0 | I16: 0 | J16: 0 | K16: 0 | L16: 0 | M16: 6 | N16: 0 | O16: =SUM(C16:L16,N16) -> 0 | P16: =SUM(C16:N16) -> 6 | R16: 1300-1400 | S16: =SUM(C34:C37) -> 2 | T16: =SUM(D34:D37) -> 0 | U16: =SUM(E34:E37) -> 0 | V16: =SUM(F34:F37) -> 2 | W16: =SUM(G34:G37) -> 0 | X16: =SUM(H34:H37) -> 0 | Y16: =SUM(I34:I37) -> 2 | Z16: =SUM(J34:J37) -> 0 | ... AF16: =SUM(P34:P37) -> 22
B17: 08.45 - 9.00 | C17: 0 | D17: 0 | E17: 1 | F17: 0 | G17: 0 | H17: 0 | I17: 1 | J17: 0 | K17: 0 | L17: 0 | M17: 3 | N17: 0 | O17: =SUM(C17:L17,N17) -> 2 | P17: =SUM(C17:N17) -> 5 | R17: 1400-1500 | S17: =SUM(C38:C41) -> 1 | T17: =SUM(D38:D41) -> 0 | U17: =SUM(E38:E41) -> 0 | V17: =SUM(F38:F41) -> 2 | W17: =SUM(G38:G41) -> 0 | X17: =SUM(H38:H41) -> 0 | Y17: =SUM(I38:I41) -> 3 | Z17: =SUM(J38:J41) -> 0 | ... AF17: =SUM(P38:P41) -> 30
B18: 09.00 - 09.15 | C18: 0 | D18: 1 | E18: 1 | F18: 0 | G18: 0 | H18: 0 | I18: 0 | J18: 0 | K18: 0 | L18: 0 | M18: 7 | N18: 0 | O18: =SUM(C18:L18,N18) -> 2 | P18: =SUM(C18:N18) -> 9 | R18: 1500-1600 | S18: =SUM(C42:C45) -> 2 | T18: =SUM(D42:D45) -> 0 | U18: =SUM(E42:E45) -> 2 | V18: =SUM(F42:F45) -> 4 | W18: =SUM(G42:G45) -> 0 | X18: =SUM(H42:H45) -> 0 | Y18: =SUM(I42:I45) -> 2 | Z18: =SUM(J42:J45) -> 0 | ... AF18: =SUM(P42:P45) -> 18
B19: 09.15 - 09.30 | C19: 1 | D19: 0 | E19: 0 | F19: 0 | G19: 0 | H19: 0 | I19: 1 | J19: 0 | K19: 0 | L19: 0 | M19: 6 | N19: 0 | O19: =SUM(C19:L19,N19) -> 2 | P19: =SUM(C19:N19) -> 8 | R19: 1600-1700 | S19: =SUM(C46:C49) -> 3 | T19: =SUM(D46:D49) -> 0 | U19: =SUM(E46:E49) -> 0 | V19: =SUM(F46:F49) -> 1 | W19: =SUM(G46:G49) -> 0 | X19: =SUM(H46:H49) -> 0 | Y19: =SUM(I46:I49) -> 4 | Z19: =SUM(J46:J49) -> 0 | ... AF19: =SUM(P46:P49) -> 18
B20: 09.30 - 09.45 | C20: 3 | D20: 0 | E20: 0 | F20: 0 | G20: 0 | H20: 0 | I20: 1 | J20: 0 | K20: 0 | L20: 0 | M20: 4 | N20: 0 | O20: =SUM(C20:L20,N20) -> 4 | P20: =SUM(C20:N20) -> 8 | R20: 1700-1800 | S20: =SUM(C50:C53) -> 1 | T20: =SUM(D50:D53) -> 3 | U20: =SUM(E50:E53) -> 3 | V20: =SUM(F50:F53) -> 3 | W20: =SUM(G50:G53) -> 0 | X20: =SUM(H50:H53) -> 0 | Y20: =SUM(I50:I53) -> 2 | Z20: =SUM(J50:J53) -> 0 | ... AF20: =SUM(P50:P53) -> 26
B21: 09.45 - 10.00 | C21: 1 | D21: 0 | E21: 0 | F21: 0 | G21: 0 | H21: 0 | I21: 0 | J21: 0 | K21: 0 | L21: 0 | M21: 2 | N21: 0 | O21: =SUM(C21:L21,N21) -> 1 | P21: =SUM(C21:N21) -> 3 | R21: 1800-1900 | S21: =SUM(C54:C57) -> 3 | T21: =SUM(D54:D57) -> 0 | U21: =SUM(E54:E57) -> 6 | V21: =SUM(F54:F57) -> 1 | W21: =SUM(G54:G57) -> 0 | X21: =SUM(H54:H57) -> 0 | Y21: =SUM(I54:I57) -> 2 | Z21: =SUM(J54:J57) -> 1 | ... AF21: =SUM(P54:P57) -> 27
B22: 10.00 - 10.15 | C22: 0 | D22: 0 | E22: 1 | F22: 0 | G22: 0 | H22: 0 | I22: 0 | J22: 0 | K22: 0 | L22: 0 | M22: 6 | N22: 0 | O22: =SUM(C22:L22,N22) -> 1 | P22: =SUM(C22:N22) -> 7 | R22: 1900-2000 | S22: =SUM(C58:C61) -> 2 | T22: =SUM(D58:D61) -> 1 | U22: =SUM(E58:E61) -> 1 | V22: =SUM(F58:F61) -> 0 | W22: =SUM(G58:G61) -> 0 | X22: =SUM(H58:H61) -> 0 | Y22: =SUM(I58:I61) -> 4 | Z22: =SUM(J58:J61) -> 2 | ... AF22: =SUM(P58:P61) -> 28
B23: 10.15 - 10.30 | C23: 0 | D23: 0 | E23: 0 | F23: 0 | G23: 0 | H23: 0 | I23: 1 | J23: 1 | K23: 0 | L23: 0 | M23: 2 | N23: 0 | O23: =SUM(C23:L23,N23) -> 2 | P23: =SUM(C23:N23) -> 4 | R23: 2000-2100 | S23: =SUM(C62:C65) -> 0 | T23: =SUM(D62:D65) -> 1 | U23: =SUM(E62:E65) -> 0 | V23: =SUM(F62:F65) -> 2 | W23: =SUM(G62:G65) -> 0 | X23: =SUM(H62:H65) -> 0 | Y23: =SUM(I62:I65) -> 1 | Z23: =SUM(J62:J65) -> 1 | ... AF23: =SUM(P62:P65) -> 14
B24: 10.30 - 10.45 | C24: 1 | D24: 0 | E24: 0 | F24: 1 | G24: 0 | H24: 0 | I24: 0 | J24: 0 | K24: 0 | L24: 0 | M24: 6 | N24: 0 | O24: =SUM(C24:L24,N24) -> 2 | P24: =SUM(C24:N24) -> 8 | R24: 2100-2200 | S24: =SUM(C66:C69) -> 1 | T24: =SUM(D66:D69) -> 1 | U24: =SUM(E66:E69) -> 1 | V24: =SUM(F66:F69) -> 3 | W24: =SUM(G66:G69) -> 0 | X24: =SUM(H66:H69) -> 0 | Y24: =SUM(I66:I69) -> 2 | Z24: =SUM(J66:J69) -> 3 | ... AF24: =SUM(P66:P69) -> 20
B25: 10.45 - 11.00 | C25: 3 | D25: 0 | E25: 0 | F25: 0 | G25: 0 | H25: 0 | I25: 0 | J25: 0 | K25: 0 | L25: 0 | M25: 4 | N25: 0 | O25: =SUM(C25:L25,N25) -> 3 | P25: =SUM(C25:N25) -> 7 | R25: 2200-2300 | S25: =SUM(C70:C73) -> 1 | T25: =SUM(D70:D73) -> 0 | U25: =SUM(E70:E73) -> 0 | V25: =SUM(F70:F73) -> 0 | W25: =SUM(G70:G73) -> 0 | X25: =SUM(H70:H73) -> 0 | Y25: =SUM(I70:I73) -> 1 | Z25: =SUM(J70:J73) -> 0 | ... AF25: =SUM(P70:P73) -> 8
B26: 11.00 - 11.15 | C26: 0 | D26: 0 | E26: 2 | F26: 1 | G26: 0 | H26: 0 | I26: 0 | J26: 0 | K26: 0 | L26: 0 | M26: 7 | N26: 0 | O26: =SUM(C26:L26,N26) -> 3 | P26: =SUM(C26:N26) -> 10 | R26: 2300-0000 | S26: =SUM(C74:C77) -> 1 | T26: =SUM(D74:D77) -> 0 | U26: =SUM(E74:E77) -> 0 | V26: =SUM(F74:F77) -> 0 | W26: =SUM(G74:G77) -> 0 | X26: =SUM(H74:H77) -> 0 | Y26: =SUM(I74:I77) -> 0 | Z26: =SUM(J74:J77) -> 0 | ... AF26: =SUM(P74:P77) -> 2
B27: 11.15 - 11.30 | C27: 0 | D27: 0 | E27: 1 | F27: 1 | G27: 0 | H27: 0 | I27: 1 | J27: 0 | K27: 0 | L27: 0 | M27: 5 | N27: 0 | O27: =SUM(C27:L27,N27) -> 3 | P27: =SUM(C27:N27) -> 8 | R27: 0000-0100 | S27: =SUM(C78:C81) -> 1 | T27: =SUM(D78:D81) -> 0 | U27: =SUM(E78:E81) -> 0 | V27: =SUM(F78:F81) -> 0 | W27: =SUM(G78:G81) -> 0 | X27: =SUM(H78:H81) -> 0 | Y27: =SUM(I78:I81) -> 0 | Z27: =SUM(J78:J81) -> 0 | ... AF27: =SUM(P78:P81) -> 2
B28: 11.30 - 11.45 | C28: 2 | D28: 0 | E28: 1 | F28: 0 | G28: 0 | H28: 0 | I28: 1 | J28: 0 | K28: 0 | L28: 0 | M28: 3 | N28: 0 | O28: =SUM(C28:L28,N28) -> 4 | P28: =SUM(C28:N28) -> 7 | R28: 0100-0200 | S28: =SUM(C82:C85) -> 0 | T28: =SUM(D82:D85) -> 0 | U28: =SUM(E82:E85) -> 0 | V28: =SUM(F82:F85) -> 0 | W28: =SUM(G82:G85) -> 0 | X28: =SUM(H82:H85) -> 0 | Y28: =SUM(I82:I85) -> 0 | Z28: =SUM(J82:J85) -> 3 | ... AF28: =SUM(P82:P85) -> 3
B29: 11.45 - 12.00 | C29: 2 | D29: 2 | E29: 0 | F29: 1 | G29: 0 | H29: 0 | I29: 1 | J29: 0 | K29: 0 | L29: 0 | M29: 3 | N29: 0 | O29: =SUM(C29:L29,N29) -> 6 | P29: =SUM(C29:N29) -> 9 | R29: 0200-0300 | S29: =SUM(C86:C89) -> 1 | T29: =SUM(D86:D89) -> 0 | U29: =SUM(E86:E89) -> 0 | V29: =SUM(F86:F89) -> 0 | W29: =SUM(G86:G89) -> 0 | X29: =SUM(H86:H89) -> 0 | Y29: =SUM(I86:I89) -> 0 | Z29: =SUM(J86:J89) -> 0 | ... AF29: =SUM(P86:P89) -> 1
B30: 12.00 - 12.15 | C30: 0 | D30: 0 | E30: 2 | F30: 0 | G30: 0 | H30: 0 | I30: 0 | J30: 0 | K30: 0 | L30: 0 | M30: 3 | N30: 0 | O30: =SUM(C30:L30,N30) -> 2 | P30: =SUM(C30:N30) -> 5 | R30: 0300-0400 | S30: =SUM(C90:C93) -> 0 | T30: =SUM(D90:D93) -> 0 | U30: =SUM(E90:E93) -> 0 | V30: =SUM(F90:F93) -> 0 | W30: =SUM(G90:G93) -> 0 | X30: =SUM(H90:H93) -> 0 | Y30: =SUM(I90:I93) -> 1 | Z30: =SUM(J90:J93) -> 1 | ... AF30: =SUM(P90:P93) -> 2
B31: 12.15 - 12.30 | C31: 1 | D31: 0 | E31: 0 | F31: 1 | G31: 0 | H31: 0 | I31: 2 | J31: 0 | K31: 0 | L31: 0 | M31: 7 | N31: 0 | O31: =SUM(C31:L31,N31) -> 4 | P31: =SUM(C31:N31) -> 11 | R31: 0400-0500 | S31: =SUM(C94:C97) -> 0 | T31: =SUM(D94:D97) -> 0 | U31: =SUM(E94:E97) -> 0 | V31: =SUM(F94:F97) -> 0 | W31: =SUM(G94:G97) -> 0 | X31: =SUM(H94:H97) -> 0 | Y31: =SUM(I94:I97) -> 0 | Z31: =SUM(J94:J97) -> 0 | ... AF31: =SUM(P94:P97) -> 2
