Workbook

Sheet 25.10 KYENJOJO-HOIMA
B1: Consultancy services for Preparation of Expressway Development Master Plan (EDMP) for Uganda
B2: MANUAL CLASSIFIED COUNT (MCC)
B3: ROAD NAME: | C3: MCC - C4 - STN108 - HOIMA ROAD
C5: Date | D5: 25.10.19 | F5: Location | G5: KYENJOJO | J5: Surveyor | K5: OLOYA FELIX
C6: Dir. From | D6: KYENJOJO | F6: Dir. To | G6: HOIMA | J6: Supervisor | K6: FELIX
B8: Time / Veh Type | R8: SUMMARY TRAFFIC VOLUMES
C9: 1. Car | D9: 2. Station Wagon | E9: 3. Pickups | F9: 4. Minibus, matatu | G9: 5. Medium bus | H9: 6. Large Bus | I9: 7. Light Truck | J9: 8. Medium Truck | K9: 9. Heavy truck | L9: 10. Truck Trailer | M9: 11. Motor cycles | N9: 12. Tractors | O9: Total Excl M/Cycles | P9: Total All | R9: Time | S9: 1. Car | T9: 2. Station Wagon | U9: 3. Pickups | V9: 4. Minibus, matatu | W9: 5. Medium bus | X9: 6. Large Bus | Y9: 7. Light Truck | Z9: 8. Medium Truck | AA9: 9. Heavy truck | AB9: 10. Truck Trailer | AC9: 11. Motorcycles | AD9: 12. Tractors, Graders | AE9: Total Excl M/ Cycles | AF9: Total All
B10: 07.00 - 07.15 | C10: 0 | D10: 1 | E10: 1 | F10: 0 | G10: 0 | H10: 0 | I10: 0 | J10: 2 | K10: 1 | L10: 0 | M10: 8 | N10: 0 | O10: =SUM(C10:L10,N10) -> 5 | P10: =SUM(C10:N10) -> 13 | R10: 0700-0800 | S10: =SUM(C10:C13) -> 11 | T10: =SUM(D10:D13) -> 3 | U10: =SUM(E10:E13) -> 2 | V10: =SUM(F10:F13) -> 3 | W10: =SUM(G10:G13) -> 0 | X10: =SUM(H10:H13) -> 0 | Y10: =SUM(I10:I13) -> 1 | Z10: =SUM(J10:J13) -> 2 | ... AF10: =SUM(P10:P13) -> 103
B11: 07.15 - 07.30 | C11: 3 | D11: 1 | E11: 0 | F11: 2 | G11: 0 | H11: 0 | I11: 0 | J11: 0 | K11: 0 | L11: 0 | M11: 32 | N11: 0 | O11: =SUM(C11:L11,N11) -> 6 | P11: =SUM(C11:N11) -> 38 | R11: 0800-0900 | S11: =SUM(C14:C17) -> 28 | T11: =SUM(D14:D17) -> 0 | U11: =SUM(E14:E17) -> 4 | V11: =SUM(F14:F17) -> 2 | W11: =SUM(G14:G17) -> 0 | X11: =SUM(H14:H17) -> 0 | Y11: =SUM(I14:I17) -> 4 | Z11: =SUM(J14:J17) -> 3 | ... AF11: =SUM(P14:P17) -> 143
B12: 07.30 - 07.45 | C12: 1 | D12: 0 | E12: 0 | F12: 0 | G12: 0 | H12: 0 | I12: 0 | J12: 0 | K12: 0 | L12: 0 | M12: 16 | N12: 0 | O12: =SUM(C12:L12,N12) -> 1 | P12: =SUM(C12:N12) -> 17 | R12: 0900-1000 | S12: =SUM(C18:C21) -> 16 | T12: =SUM(D18:D21) -> 2 | U12: =SUM(E18:E21) -> 9 | V12: =SUM(F18:F21) -> 3 | W12: =SUM(G18:G21) -> 0 | X12: =SUM(H18:H21) -> 0 | Y12: =SUM(I18:I21) -> 5 | Z12: =SUM(J18:J21) -> 3 | ... AF12: =SUM(P18:P21) -> 150
B13: 07.45 - 08.00 | C13: 7 | D13: 1 | E13: 1 | F13: 1 | G13: 0 | H13: 0 | I13: 1 | J13: 0 | K13: 0 | L13: 0 | M13: 24 | N13: 0 | O13: =SUM(C13:L13,N13) -> 11 | P13: =SUM(C13:N13) -> 35 | R13: 1000-1100 | S13: =SUM(C22:C25) -> 56 | T13: =SUM(D22:D25) -> 2 | U13: =SUM(E22:E25) -> 13 | V13: =SUM(F22:F25) -> 8 | W13: =SUM(G22:G25) -> 0 | X13: =SUM(H22:H25) -> 0 | Y13: =SUM(I22:I25) -> 2 | Z13: =SUM(J22:J25) -> 2 | ... AF13: =SUM(P22:P25) -> 247
B14: 08.00 - 08.15 | C14: 5 | D14: 0 | E14: 1 | F14: 0 | G14: 0 | H14: 0 | I14: 2 | J14: 1 | K14: 0 | L14: 0 | M14: 25 | N14: 0 | O14: =SUM(C14:L14,N14) -> 9 | P14: =SUM(C14:N14) -> 34 | R14: 1100-1200 | S14: =SUM(C26:C29) -> 18 | T14: =SUM(D26:D29) -> 1 | U14: =SUM(E26:E29) -> 4 | V14: =SUM(F26:F29) -> 1 | W14: =SUM(G26:G29) -> 0 | X14: =SUM(H26:H29) -> 0 | Y14: =SUM(I26:I29) -> 0 | Z14: =SUM(J26:J29) -> 1 | ... AF14: =SUM(P26:P29) -> 160
B15: 08.15 - 08.30 | C15: 8 | D15: 0 | E15: 3 | F15: 0 | G15: 0 | H15: 0 | I15: 0 | J15: 0 | K15: 0 | L15: 0 | M15: 27 | N15: 0 | O15: =SUM(C15:L15,N15) -> 11 | P15: =SUM(C15:N15) -> 38 | R15: 1200-1300 | S15: =SUM(C30:C33) -> 24 | T15: =SUM(D30:D33) -> 4 | U15: =SUM(E30:E33) -> 4 | V15: =SUM(F30:F33) -> 4 | W15: =SUM(G30:G33) -> 0 | X15: =SUM(H30:H33) -> 0 | Y15: =SUM(I30:I33) -> 4 | Z15: =SUM(J30:J33) -> 2 | ... AF15: =SUM(P30:P33) -> 203
B16: 08.30 - 08.45 | C16: 9 | D16: 0 | E16: 0 | F16: 2 | G16: 0 | H16: 0 | I16: 2 | J16: 0 | K16: 0 | L16: 0 | M16: 33 | N16: 0 | O16: =SUM(C16:L16,N16) -> 13 | P16: =SUM(C16:N16) -> 46 | R16: 1300-1400 | S16: =SUM(C34:C37) -> 28 | T16: =SUM(D34:D37) -> 3 | U16: =SUM(E34:E37) -> 4 | V16: =SUM(F34:F37) -> 4 | W16: =SUM(G34:G37) -> 0 | X16: =SUM(H34:H37) -> 0 | Y16: =SUM(I34:I37) -> 2 | Z16: =SUM(J34:J37) -> 2 | ... AF16: =SUM(P34:P37) -> 223
B17: 08.45 - 9.00 | C17: 6 | D17: 0 | E17: 0 | F17: 0 | G17: 0 | H17: 0 | I17: 0 | J17: 2 | K17: 0 | L17: 0 | M17: 17 | N17: 0 | O17: =SUM(C17:L17,N17) -> 8 | P17: =SUM(C17:N17) -> 25 | R17: 1400-1500 | S17: =SUM(C38:C41) -> 18 | T17: =SUM(D38:D41) -> 2 | U17: =SUM(E38:E41) -> 5 | V17: =SUM(F38:F41) -> 0 | W17: =SUM(G38:G41) -> 0 | X17: =SUM(H38:H41) -> 0 | Y17: =SUM(I38:I41) -> 1 | Z17: =SUM(J38:J41) -> 0 | ... AF17: =SUM(P38:P41) -> 156
B18: 09.00 - 09.15 | C18: 2 | D18: 0 | E18: 3 | F18: 0 | G18: 0 | H18: 0 | I18: 1 | J18: 2 | K18: 0 | L18: 0 | M18: 17 | N18: 0 | O18: =SUM(C18:L18,N18) -> 8 | P18: =SUM(C18:N18) -> 25 | R18: 1500-1600 | S18: =SUM(C42:C45) -> 21 | T18: =SUM(D42:D45) -> 0 | U18: =SUM(E42:E45) -> 5 | V18: =SUM(F42:F45) -> 3 | W18: =SUM(G42:G45) -> 0 | X18: =SUM(H42:H45) -> 0 | Y18: =SUM(I42:I45) -> 2 | Z18: =SUM(J42:J45) -> 2 | ... AF18: =SUM(P42:P45) -> 207
B19: 09.15 - 09.30 | C19: 5 | D19: 0 | E19: 0 | F19: 0 | G19: 0 | H19: 0 | I19: 1 | J19: 1 | K19: 0 | L19: 0 | M19: 25 | N19: 0 | O19: =SUM(C19:L19,N19) -> 7 | P19: =SUM(C19:N19) -> 32 | R19: 1600-1700 | S19: =SUM(C46:C49) -> 26 | T19: =SUM(D46:D49) -> 3 | U19: =SUM(E46:E49) -> 2 | V19: =SUM(F46:F49) -> 10 | W19: =SUM(G46:G49) -> 0 | X19: =SUM(H46:H49) -> 0 | Y19: =SUM(I46:I49) -> 5 | Z19: =SUM(J46:J49) -> 3 | ... AF19: =SUM(P46:P49) -> 208
B20: 09.30 - 09.45 | C20: 4 | D20: 0 | E20: 4 | F20: 2 | G20: 0 | H20: 0 | I20: 2 | J20: 0 | K20: 0 | L20: 0 | M20: 42 | N20: 0 | O20: =SUM(C20:L20,N20) -> 12 | P20: =SUM(C20:N20) -> 54 | R20: 1700-1800 | S20: =SUM(C50:C53) -> 27 | T20: =SUM(D50:D53) -> 6 | U20: =SUM(E50:E53) -> 7 | V20: =SUM(F50:F53) -> 2 | W20: =SUM(G50:G53) -> 0 | X20: =SUM(H50:H53) -> 0 | Y20: =SUM(I50:I53) -> 4 | Z20: =SUM(J50:J53) -> 7 | ... AF20: =SUM(P50:P53) -> 189
B21: 09.45 - 10.00 | C21: 5 | D21: 2 | E21: 2 | F21: 1 | G21: 0 | H21: 0 | I21: 1 | J21: 0 | K21: 0 | L21: 0 | M21: 28 | N21: 0 | O21: =SUM(C21:L21,N21) -> 11 | P21: =SUM(C21:N21) -> 39 | R21: 1800-1900 | S21: =SUM(C54:C57) -> 36 | T21: =SUM(D54:D57) -> 1 | U21: =SUM(E54:E57) -> 2 | V21: =SUM(F54:F57) -> 2 | W21: =SUM(G54:G57) -> 0 | X21: =SUM(H54:H57) -> 0 | Y21: =SUM(I54:I57) -> 2 | Z21: =SUM(J54:J57) -> 3 | ... AF21: =SUM(P54:P57) -> 186
B22: 10.00 - 10.15 | C22: 11 | D22: 2 | E22: 1 | F22: 1 | G22: 0 | H22: 0 | I22: 1 | J22: 1 | K22: 0 | L22: 0 | M22: 26 | N22: 0 | O22: =SUM(C22:L22,N22) -> 17 | P22: =SUM(C22:N22) -> 43 | R22: AM Peak Hr | S22: =MAX(S10:S12) -> 28 | T22: =MAX(T10:T12) -> 3 | U22: =MAX(U10:U12) -> 9 | V22: =MAX(V10:V12) -> 3 | W22: =MAX(W10:W12) -> 0 | X22: =MAX(X10:X12) -> 0 | Y22: =MAX(Y10:Y12) -> 5 | Z22: =MAX(Z10:Z12) -> 3 | ... AF22: =MAX(AF10:AF12) -> 150
B23: 10.15 - 10.30 | C23: 18 | D23: 0 | E23: 7 | F23: 3 | G23: 0 | H23: 0 | I23: 0 | J23: 0 | K23: 0 | L23: 0 | M23: 43 | N23: 0 | O23: =SUM(C23:L23,N23) -> 28 | P23: =SUM(C23:N23) -> 71 | R23: IP Peak Hr | S23: =MAX(S13:S18) -> 56 | T23: =MAX(T13:T18) -> 4 | U23: =MAX(U13:U18) -> 13 | V23: =MAX(V13:V18) -> 8 | W23: =MAX(W13:W18) -> 0 | X23: =MAX(X13:X18) -> 0 | Y23: =MAX(Y13:Y18) -> 4 | Z23: =MAX(Z13:Z18) -> 2 | ... AF23: =MAX(AF13:AF18) -> 247
B24: 10.30 - 10.45 | C24: 15 | D24: 0 | E24: 3 | F24: 3 | G24: 0 | H24: 0 | I24: 0 | J24: 1 | K24: 1 | L24: 1 | M24: 47 | N24: 0 | O24: =SUM(C24:L24,N24) -> 24 | P24: =SUM(C24:N24) -> 71 | R24: PM Peak Hr | S24: =MAX(S19:S21) -> 36 | T24: =MAX(T19:T21) -> 6 | U24: =MAX(U19:U21) -> 7 | V24: =MAX(V19:V21) -> 10 | W24: =MAX(W19:W21) -> 0 | X24: =MAX(X19:X21) -> 0 | Y24: =MAX(Y19:Y21) -> 5 | Z24: =MAX(Z19:Z21) -> 7 | ... AF24: =MAX(AF19:AF21) -> 208
B25: 10.45 - 11.00 | C25: 12 | D25: 0 | E25: 2 | F25: 1 | G25: 0 | H25: 0 | I25: 1 | J25: 0 | K25: 0 | L25: 0 | M25: 45 | N25: 1 | O25: =SUM(C25:L25,N25) -> 17 | P25: =SUM(C25:N25) -> 62 | R25: AM Period | S25: =SUM(S10:S12) -> 55 | T25: =SUM(T10:T12) -> 5 | U25: =SUM(U10:U12) -> 15 | V25: =SUM(V10:V12) -> 8 | W25: =SUM(W10:W12) -> 0 | X25: =SUM(X10:X12) -> 0 | Y25: =SUM(Y10:Y12) -> 10 | Z25: =SUM(Z10:Z12) -> 8 | ... AF25: =SUM(AF10:AF12) -> 396
B26: 11.00 - 11.15 | C26: 6 | D26: 0 | E26: 1 | F26: 1 | G26: 0 | H26: 0 | I26: 0 | J26: 0 | K26: 0 | L26: 0 | M26: 25 | N26: 0 | O26: =SUM(C26:L26,N26) -> 8 | P26: =SUM(C26:N26) -> 33 | R26: IP Period | S26: =SUM(S13:S18) -> 165 | T26: =SUM(T13:T18) -> 12 | U26: =SUM(U13:U18) -> 35 | V26: =SUM(V13:V18) -> 20 | W26: =SUM(W13:W18) -> 0 | X26: =SUM(X13:X18) -> 0 | Y26: =SUM(Y13:Y18) -> 11 | Z26: =SUM(Z13:Z18) -> 9 | ... AF26: =SUM(AF13:AF18) -> 1196
B27: 11.15 - 11.30 | C27: 7 | D27: 1 | E27: 0 | F27: 0 | G27: 0 | H27: 0 | I27: 0 | J27: 1 | K27: 0 | L27: 0 | M27: 42 | N27: 0 | O27: =SUM(C27:L27,N27) -> 9 | P27: =SUM(C27:N27) -> 51 | R27: PM Period | S27: =SUM(S19:S21) -> 89 | T27: =SUM(T19:T21) -> 10 | U27: =SUM(U19:U21) -> 11 | V27: =SUM(V19:V21) -> 14 | W27: =SUM(W19:W21) -> 0 | X27: =SUM(X19:X21) -> 0 | Y27: =SUM(Y19:Y21) -> 11 | Z27: =SUM(Z19:Z21) -> 13 | ... AF27: =SUM(AF19:AF21) -> 583
B28: 11.30 - 11.45 | C28: 3 | D28: 0 | E28: 0 | F28: 0 | G28: 0 | H28: 0 | I28: 0 | J28: 0 | K28: 0 | L28: 0 | M28: 29 | N28: 0 | O28: =SUM(C28:L28,N28) -> 3 | P28: =SUM(C28:N28) -> 32 | R28: 12 Hours | S28: =SUM(S10:S21) -> 309 | T28: =SUM(T10:T21) -> 27 | U28: =SUM(U10:U21) -> 61 | V28: =SUM(V10:V21) -> 42 | W28: =SUM(W10:W21) -> 0 | X28: =SUM(X10:X21) -> 0 | Y28: =SUM(Y10:Y21) -> 32 | Z28: =SUM(Z10:Z21) -> 30 | ... AF28: =SUM(AF10:AF21) -> 2175
B29: 11.45 - 12.00 | C29: 2 | D29: 0 | E29: 3 | F29: 0 | G29: 0 | H29: 0 | I29: 0 | J29: 0 | K29: 1 | L29: 1 | M29: 37 | N29: 0 | O29: =SUM(C29:L29,N29) -> 7 | P29: =SUM(C29:N29) -> 44
B30: 12.00 - 12.15 | C30: 5 | D30: 0 | E30: 1 | F30: 1 | G30: 0 | H30: 0 | I30: 1 | J30: 0 | K30: 0 | L30: 0 | M30: 35 | N30: 0 | O30: =SUM(C30:L30,N30) -> 8 | P30: =SUM(C30:N30) -> 43
B31: 12.15 - 12.30 | C31: 8 | D31: 1 | E31: 0 | F31: 3 | G31: 0 | H31: 0 | I31: 0 | J31: 0 | K31: 0 | L31: 0 | M31: 41 | N31: 0 | O31: =SUM(C31:L31,N31) -> 12 | P31: =SUM(C31:N31) -> 53
B32: 12.30 - 12.45 | C32: 4 | D32: 2 | E32: 1 | F32: 0 | G32: 0 | H32: 0 | I32: 2 | J32: 2 | K32: 0 | L32: 0 | M32: 44 | N32: 0 | O32: =SUM(C32:L32,N32) -> 11 | P32: =SUM(C32:N32) -> 55
B33: 12.45 - 13.00 | C33: 7 | D33: 1 | E33: 2 | F33: 0 | G33: 0 | H33: 0 | I33: 1 | J33: 0 | K33: 0 | L33: 0 | M33: 41 | N33: 0 | O33: =SUM(C33:L33,N33) -> 11 | P33: =SUM(C33:N33) -> 52
B34: 13.00 - 13.15 | C34: 6 | D34: 0 | E34: 1 | F34: 0 | G34: 0 | H34: 0 | I34: 0 | J34: 1 | K34: 0 | L34: 0 | M34: 35 | N34: 0 | O34: =SUM(C34:L34,N34) -> 8 | P34: =SUM(C34:N34) -> 43
B35: 13.15 - 13.30 | C35: 3 | D35: 0 | E35: 1 | F35: 2 | G35: 0 | H35: 0 | I35: 1 | J35: 0 | K35: 0 | L35: 0 | M35: 45 | N35: 0 | O35: =SUM(C35:L35,N35) -> 7 | P35: =SUM(C35:N35) -> 52
B36: 13.30 - 13.45 | C36: 7 | D36: 2 | E36: 1 | F36: 1 | G36: 0 | H36: 0 | I36: 0 | J36: 0 | K36: 0 | L36: 1 | M36: 37 | N36: 0 | O36: =SUM(C36:L36,N36) -> 12 | P36: =SUM(C36:N36) -> 49
B37: 13.45 - 14.00 | C37: 12 | D37: 1 | E37: 1 | F37: 1 | G37: 0 | H37: 0 | I37: 1 | J37: 1 | K37: 0 | L37: 1 | M37: 61 | N37: 0 | O37: =SUM(C37:L37,N37) -> 18 | P37: =SUM(C37:N37) -> 79
B38: 14.00 - 14.15 | C38: 5 | D38: 0 | E38: 1 | F38: 0 | G38: 0 | H38: 0 | I38: 1 | J38: 0 | K38: 0 | L38: 0 | M38: 32 | N38: 0 | O38: =SUM(C38:L38,N38) -> 7 | P38: =SUM(C38:N38) -> 39
B39: 14.15 - 14.30 | C39: 8 | D39: 0 | E39: 3 | F39: 0 | G39: 0 | H39: 0 | I39: 0 | J39: 0 | K39: 0 | L39: 1 | M39: 22 | N39: 0 | O39: =SUM(C39:L39,N39) -> 12 | P39: =SUM(C39:N39) -> 34
B40: 14.30 - 14.45 | C40: 0 | D40: 0 | E40: 0 | F40: 0 | G40: 0 | H40: 0 | I40: 0 | J40: 0 | K40: 0 | L40: 0 | M40: 44 | N40: 0 | O40: =SUM(C40:L40,N40) -> 0 | P40: =SUM(C40:N40) -> 44
... B57: 18.45 - 19.00 | C57: 5 | D57: 0 | E57: 0 | F57: 0 | G57: 0 | H57: 0 | I57: 0 | J57: 1 | K57: 0 | L57: 0 | M57: 21 | N57: 0 | O57: =SUM(C57:L57,N57) -> 6 | P57: =SUM(C57:N57) -> 27
B58: Totals | C58: =SUM(C10:C57) -> 309 | D58: =SUM(D10:D57) -> 27 | E58: =SUM(E10:E57) -> 61 | F58: =SUM(F10:F57) -> 42 | G58: =SUM(G10:G57) -> 0 | H58: =SUM(H10:H57) -> 0 | I58: =SUM(I10:I57) -> 32 | J58: =SUM(J10:J57) -> 30 | ... P58: =SUM(P10:P57) -> 2175
...

Sheet 25.10 HOIMA-KYENJOJO
B1: Consultancy services for Preparation of Expressway Development Master Plan (EDMP) for Uganda
B2: MANUAL CLASSIFIED COUNT (MCC)
B3: ROAD NAME: | C3: ='25.10 KYENJOJO-HOIMA'!C3:G3 -> MCC - C4 - STN108 - HOIMA ROAD
C5: Date | D5: ='25.10 KYENJOJO-HOIMA'!D5 -> 25.10.19 | F5: Location | G5: ='25.10 KYENJOJO-HOIMA'!G5:H5 -> KYENJOJO | J5: Surveyor | K5: BABIRYE PHIONA
C6: Dir. From | D6: HOIMA | F6: Dir. To | G6: KYENJOJO | J6: Supervisor | K6: FELIX
B8: Time / Veh Type | R8: SUMMARY TRAFFIC VOLUMES
C9: 1. Car | D9: 2. Station Wagon | E9: 3. Pickups | F9: 4. Minibus, matatu | G9: 5. Medium bus | H9: 6. Large Bus | I9: 7. Light Truck | J9: 8. Medium Truck | K9: 9. Heavy truck | L9: 10. Truck Trailer | M9: 11. Motor cycles | N9: 12. Tractors | O9: Total Excl M/Cycles | P9: Total All | R9: Time | S9: 1. Car | T9: 2. Station Wagon | U9: 3. Pickups | V9: 4. Minibus, matatu | W9: 5. Medium bus | X9: 6. Large Bus | Y9: 7. Light Truck | Z9: 8. Medium Truck | AA9: 9. Heavy truck | AB9: 10. Truck Trailer | AC9: 11. Motorcycles | AD9: 12. Tractors, Graders | AE9: Total Excl M/ Cycles | AF9: Total All
B10: 07.00 - 07.15 | C10: 2 | D10: 0 | E10: 0 | F10: 0 | G10: 0 | H10: 0 | I10: 0 | J10: 0 | K10: 0 | L10: 0 | M10: 15 | N10: 0 | O10: =SUM(C10:L10,N10) -> 2 | P10: =SUM(C10:N10) -> 17 | R10: 0700-0800 | S10: =SUM(C10:C13) -> 15 | T10: =SUM(D10:D13) -> 3 | U10: =SUM(E10:E13) -> 4 | V10: =SUM(F10:F13) -> 6 | W10: =SUM(G10:G13) -> 0 | X10: =SUM(H10:H13) -> 0 | Y10: =SUM(I10:I13) -> 4 | Z10: =SUM(J10:J13) -> 1 | ... AF10: =SUM(P10:P13) -> 163
B11: 07.15 - 07.30 | C11: 6 | D11: 1 | E11: 2 | F11: 0 | G11: 0 | H11: 0 | I11: 1 | J11: 1 | K11: 1 | L11: 0 | M11: 40 | N11: 0 | O11: =SUM(C11:L11,N11) -> 12 | P11: =SUM(C11:N11) -> 52 | R11: 0800-0900 | S11: =SUM(C14:C17) -> 23 | T11: =SUM(D14:D17) -> 7 | U11: =SUM(E14:E17) -> 4 | V11: =SUM(F14:F17) -> 4 | W11: =SUM(G14:G17) -> 0 | X11: =SUM(H14:H17) -> 1 | Y11: =SUM(I14:I17) -> 5 | Z11: =SUM(J14:J17) -> 1 | ... AF11: =SUM(P14:P17) -> 199
B12: 07.30 - 07.45 | C12: 4 | D12: 2 | E12: 1 | F12: 3 | G12: 0 | H12: 0 | I12: 2 | J12: 0 | K12: 0 | L12: 0 | M12: 41 | N12: 0 | O12: =SUM(C12:L12,N12) -> 12 | P12: =SUM(C12:N12) -> 53 | R12: 0900-1000 | S12: =SUM(C18:C21) -> 16 | T12: =SUM(D18:D21) -> 8 | U12: =SUM(E18:E21) -> 5 | V12: =SUM(F18:F21) -> 5 | W12: =SUM(G18:G21) -> 0 | X12: =SUM(H18:H21) -> 0 | Y12: =SUM(I18:I21) -> 3 | Z12: =SUM(J18:J21) -> 4 | ... AF12: =SUM(P18:P21) -> 210
B13: 07.45 - 08.00 | C13: 3 | D13: 0 | E13: 1 | F13: 3 | G13: 0 | H13: 0 | I13: 1 | J13: 0 | K13: 0 | L13: 0 | M13: 33 | N13: 0 | O13: =SUM(C13:L13,N13) -> 8 | P13: =SUM(C13:N13) -> 41 | R13: 1000-1100 | S13: =SUM(C22:C25) -> 15 | T13: =SUM(D22:D25) -> 5 | U13: =SUM(E22:E25) -> 6 | V13: =SUM(F22:F25) -> 2 | W13: =SUM(G22:G25) -> 0 | X13: =SUM(H22:H25) -> 0 | Y13: =SUM(I22:I25) -> 5 | Z13: =SUM(J22:J25) -> 2 | ... AF13: =SUM(P22:P25) -> 130
B14: 08.00 - 08.15 | C14: 2 | D14: 0 | E14: 1 | F14: 0 | G14: 0 | H14: 1 | I14: 1 | J14: 1 | K14: 0 | L14: 0 | M14: 34 | N14: 0 | O14: =SUM(C14:L14,N14) -> 6 | P14: =SUM(C14:N14) -> 40 | R14: 1100-1200 | S14: =SUM(C26:C29) -> 18 | T14: =SUM(D26:D29) -> 6 | U14: =SUM(E26:E29) -> 8 | V14: =SUM(F26:F29) -> 3 | W14: =SUM(G26:G29) -> 0 | X14: =SUM(H26:H29) -> 0 | Y14: =SUM(I26:I29) -> 2 | Z14: =SUM(J26:J29) -> 0 | ... AF14: =SUM(P26:P29) -> 173
B15: 08.15 - 08.30 | C15: 3 | D15: 3 | E15: 1 | F15: 2 | G15: 0 | H15: 0 | I15: 2 | J15: 0 | K15: 0 | L15: 0 | M15: 35 | N15: 0 | O15: =SUM(C15:L15,N15) -> 11 | P15: =SUM(C15:N15) -> 46 | R15: 1200-1300 | S15: =SUM(C30:C33) -> 22 | T15: =SUM(D30:D33) -> 6 | U15: =SUM(E30:E33) -> 7 | V15: =SUM(F30:F33) -> 2 | W15: =SUM(G30:G33) -> 0 | X15: =SUM(H30:H33) -> 1 | Y15: =SUM(I30:I33) -> 2 | Z15: =SUM(J30:J33) -> 1 | ... AF15: =SUM(P30:P33) -> 216
B16: 08.30 - 08.45 | C16: 10 | D16: 1 | E16: 1 | F16: 2 | G16: 0 | H16: 0 | I16: 1 | J16: 0 | K16: 0 | L16: 0 | M16: 48 | N16: 0 | O16: =SUM(C16:L16,N16) -> 15 | P16: =SUM(C16:N16) -> 63 | R16: 1300-1400 | S16: =SUM(C34:C37) -> 30 | T16: =SUM(D34:D37) -> 4 | U16: =SUM(E34:E37) -> 5 | V16: =SUM(F34:F37) -> 3 | W16: =SUM(G34:G37) -> 0 | X16: =SUM(H34:H37) -> 0 | Y16: =SUM(I34:I37) -> 1 | Z16: =SUM(J34:J37) -> 2 | ... AF16: =SUM(P34:P37) -> 195
B17: 08.45 - 9.00 | C17: 8 | D17: 3 | E17: 1 | F17: 0 | G17: 0 | H17: 0 | I17: 1 | J17: 0 | K17: 0 | L17: 0 | M17: 37 | N17: 0 | O17: =SUM(C17:L17,N17) -> 13 | P17: =SUM(C17:N17) -> 50 | R17: 1400-1500 | S17: =SUM(C38:C41) -> 47 | T17: =SUM(D38:D41) -> 10 | U17: =SUM(E38:E41) -> 6 | V17: =SUM(F38:F41) -> 9 | W17: =SUM(G38:G41) -> 0 | X17: =SUM(H38:H41) -> 0 | Y17: =SUM(I38:I41) -> 9 | Z17: =SUM(J38:J41) -> 1 | ... AF17: =SUM(P38:P41) -> 230
B18: 09.00 - 09.15 | C18: 7 | D18: 2 | E18: 1 | F18: 1 | G18: 0 | H18: 0 | I18: 1 | J18: 1 | K18: 0 | L18: 0 | M18: 31 | N18: 0 | O18: =SUM(C18:L18,N18) -> 13 | P18: =SUM(C18:N18) -> 44 | R18: 1500-1600 | S18: =SUM(C42:C45) -> 10 | T18: =SUM(D42:D45) -> 8 | U18: =SUM(E42:E45) -> 1 | V18: =SUM(F42:F45) -> 11 | W18: =SUM(G42:G45) -> 0 | X18: =SUM(H42:H45) -> 0 | Y18: =SUM(I42:I45) -> 4 | Z18: =SUM(J42:J45) -> 3 | ... AF18: =SUM(P42:P45) -> 213
B19: 09.15 - 09.30 | C19: 5 | D19: 2 | E19: 2 | F19: 0 | G19: 0 | H19: 0 | I19: 2 | J19: 2 | K19: 0 | L19: 0 | M19: 35 | N19: 0 | O19: =SUM(C19:L19,N19) -> 13 | P19: =SUM(C19:N19) -> 48 | R19: 1600-1700 | S19: =SUM(C46:C49) -> 21 | T19: =SUM(D46:D49) -> 2 | U19: =SUM(E46:E49) -> 1 | V19: =SUM(F46:F49) -> 5 | W19: =SUM(G46:G49) -> 0 | X19: =SUM(H46:H49) -> 0 | Y19: =SUM(I46:I49) -> 4 | Z19: =SUM(J46:J49) -> 2 | ... AF19: =SUM(P46:P49) -> 220
B20: 09.30 - 09.45 | C20: 2 | D20: 1 | E20: 2 | F20: 2 | G20: 0 | H20: 0 | I20: 0 | J20: 1 | K20: 0 | L20: 0 | M20: 55 | N20: 0 | O20: =SUM(C20:L20,N20) -> 8 | P20: =SUM(C20:N20) -> 63 | R20: 1700-1800 | S20: =SUM(C50:C53) -> 20 | T20: =SUM(D50:D53) -> 1 | U20: =SUM(E50:E53) -> 3 | V20: =SUM(F50:F53) -> 2 | W20: =SUM(G50:G53) -> 1 | X20: =SUM(H50:H53) -> 2 | Y20: =SUM(I50:I53) -> 3 | Z20: =SUM(J50:J53) -> 5 | ... AF20: =SUM(P50:P53) -> 164
B21: 09.45 - 10.00 | C21: 2 | D21: 3 | E21: 0 | F21: 2 | G21: 0 | H21: 0 | I21: 0 | J21: 0 | K21: 2 | L21: 0 | M21: 46 | N21: 0 | O21: =SUM(C21:L21,N21) -> 9 | P21: =SUM(C21:N21) -> 55 | R21: 1800-1900 | S21: =SUM(C54:C57) -> 23 | T21: =SUM(D54:D57) -> 1 | U21: =SUM(E54:E57) -> 5 | V21: =SUM(F54:F57) -> 4 | W21: =SUM(G54:G57) -> 0 | X21: =SUM(H54:H57) -> 0 | Y21: =SUM(I54:I57) -> 2 | Z21: =SUM(J54:J57) -> 2 | ... AF21: =SUM(P54:P57) -> 161
B22: 10.00 - 10.15 | C22: 3 | D22: 0 | E22: 3 | F22: 2 | G22: 0 | H22: 0 | I22: 0 | J22: 0 | K22: 0 | L22: 0 | M22: 26 | N22: 0 | O22: =SUM(C22:L22,N22) -> 8 | P22: =SUM(C22:N22) -> 34 | R22: AM Peak Hr | S22: =MAX(S10:S12) -> 23 | T22: =MAX(T10:T12) -> 8 | U22: =MAX(U10:U12) -> 5 | V22: =MAX(V10:V12) -> 6 | W22: =MAX(W10:W12) -> 0 | X22: =MAX(X10:X12) -> 1 | Y22: =MAX(Y10:Y12) -> 5 | Z22: =MAX(Z10:Z12) -> 4 | ... AF22: =MAX(AF10:AF12) -> 210
B23: 10.15 - 10.30 | C23: 6 | D23: 2 | E23: 0 | F23: 0 | G23: 0 | H23: 0 | I23: 1 | J23: 1 | K23: 0 | L23: 0 | M23: 20 | N23: 0 | O23: =SUM(C23:L23,N23) -> 10 | P23: =SUM(C23:N23) -> 30 | R23: IP Peak Hr | S23: =MAX(S13:S18) -> 47 | T23: =MAX(T13:T18) -> 10 | U23: =MAX(U13:U18) -> 8 | V23: =MAX(V13:V18) -> 11 | W23: =MAX(W13:W18) -> 0 | X23: =MAX(X13:X18) -> 1 | Y23: =MAX(Y13:Y18) -> 9 | Z23: =MAX(Z13:Z18) -> 3 | ... AF23: =MAX(AF13:AF18) -> 230
B24: 10.30 - 10.45 | C24: 4 | D24: 2 | E24: 0 | F24: 0 | G24: 0 | H24: 0 | I24: 2 | J24: 1 | K24: 0 | L24: 0 | M24: 35 | N24: 0 | O24: =SUM(C24:L24,N24) -> 9 | P24: =SUM(C24:N24) -> 44 | R24: PM Peak Hr | S24: =MAX(S19:S21) -> 23 | T24: =MAX(T19:T21) -> 2 | U24: =MAX(U19:U21) -> 5 | V24: =MAX(V19:V21) -> 5 | W24: =MAX(W19:W21) -> 1 | X24: =MAX(X19:X21) -> 2 | Y24: =MAX(Y19:Y21) -> 4 | Z24: =MAX(Z19:Z21) -> 5 | ... AF24: =MAX(AF19:AF21) -> 220
B25: 10.45 - 11.00 | C25: 2 | D25: 1 | E25: 3 | F25: 0 | G25: 0 | H25: 0 | I25: 2 | J25: 0 | K25: 0 | L25: 0 | M25: 14 | N25: 0 | O25: =SUM(C25:L25,N25) -> 8 | P25: =SUM(C25:N25) -> 22 | R25: AM Period | S25: =SUM(S10:S12) -> 54 | T25: =SUM(T10:T12) -> 18 | U25: =SUM(U10:U12) -> 13 | V25: =SUM(V10:V12) -> 15 | W25: =SUM(W10:W12) -> 0 | X25: =SUM(X10:X12) -> 1 | Y25: =SUM(Y10:Y12) -> 12 | Z25: =SUM(Z10:Z12) -> 6 | ... AF25: =SUM(AF10:AF12) -> 572
B26: 11.00 - 11.15 | C26: 8 | D26: 5 | E26: 3 | F26: 1 | G26: 0 | H26: 0 | I26: 0 | J26: 0 | K26: 0 | L26: 0 | M26: 44 | N26: 0 | O26: =SUM(C26:L26,N26) -> 17 | P26: =SUM(C26:N26) -> 61 | R26: IP Period | S26: =SUM(S13:S18) -> 142 | T26: =SUM(T13:T18) -> 39 | U26: =SUM(U13:U18) -> 33 | V26: =SUM(V13:V18) -> 30 | W26: =SUM(W13:W18) -> 0 | X26: =SUM(X13:X18) -> 1 | Y26: =SUM(Y13:Y18) -> 23 | Z26: =SUM(Z13:Z18) -> 9 | ... AF26: =SUM(AF13:AF18) -> 1157
B27: 11.15 - 11.30 | C27: 6 | D27: 1 | E27: 1 | F27: 1 | G27: 0 | H27: 0 | I27: 0 | J27: 0 | K27: 0 | L27: 0 | M27: 30 | N27: 0 | O27: =SUM(C27:L27,N27) -> 9 | P27: =SUM(C27:N27) -> 39 | R27: PM Period | S27: =SUM(S19:S21) -> 64 | T27: =SUM(T19:T21) -> 4 | U27: =SUM(U19:U21) -> 9 | V27: =SUM(V19:V21) -> 11 | W27: =SUM(W19:W21) -> 1 | X27: =SUM(X19:X21) -> 2 | Y27: =SUM(Y19:Y21) -> 9 | Z27: =SUM(Z19:Z21) -> 9 | ... AF27: =SUM(AF19:AF21) -> 545
B28: 11.30 - 11.45 | C28: 2 | D28: 0 | E28: 3 | F28: 1 | G28: 0 | H28: 0 | I28: 2 | J28: 0 | K28: 0 | L28: 0 | M28: 31 | N28: 1 | O28: =SUM(C28:L28,N28) -> 9 | P28: =SUM(C28:N28) -> 40 | R28: 12 Hours | S28: =SUM(S10:S21) -> 260 | T28: =SUM(T10:T21) -> 61 | U28: =SUM(U10:U21) -> 55 | V28: =SUM(V10:V21) -> 56 | W28: =SUM(W10:W21) -> 1 | X28: =SUM(X10:X21) -> 4 | Y28: =SUM(Y10:Y21) -> 44 | Z28: =SUM(Z10:Z21) -> 24 | ... AF28: =SUM(AF10:AF21) -> 2274
B29: 11.45 - 12.00 | C29: 2 | D29: 0 | E29: 1 | F29: 0 | G29: 0 | H29: 0 | I29: 0 | J29: 0 | K29: 0 | L29: 0 | M29: 30 | N29: 0 | O29: =SUM(C29:L29,N29) -> 3 | P29: =SUM(C29:N29) -> 33
B30: 12.00 - 12.15 | C30: 4 | D30: 2 | E30: 3 | F30: 0 | G30: 0 | H30: 0 | I30: 0 | J30: 0 | K30: 0 | L30: 0 | M30: 34 | N30: 0 | O30: =SUM(C30:L30,N30) -> 9 | P30: =SUM(C30:N30) -> 43
B31: 12.15 - 12.30 | C31: 7 | D31: 0 | E31: 0 | F31: 0 | G31: 0 | H31: 0 | I31: 0 | J31: 0 | K31: 0 | L31: 0 | M31: 53 | N31: 0 | O31: =SUM(C31:L31,N31) -> 7 | P31: =SUM(C31:N31) -> 60
B32: 12.30 - 12.45 | C32: 6 | D32: 1 | E32: 2 | F32: 1 | G32: 0 | H32: 1 | I32: 0 | J32: 1 | K32: 0 | L32: 0 | M32: 43 | N32: 0 | O32: =SUM(C32:L32,N32) -> 12 | P32: =SUM(C32:N32) -> 55
B33: 12.45 - 13.00 | C33: 5 | D33: 3 | E33: 2 | F33: 1 | G33: 0 | H33: 0 | I33: 2 | J33: 0 | K33: 0 | L33: 0 | M33: 45 | N33: 0 | O33: =SUM(C33:L33,N33) -> 13 | P33: =SUM(C33:N33) -> 58
B34: 13.00 - 13.15 | C34: 6 | D34: 1 | E34: 2 | F34: 3 | G34: 0 | H34: 0 | I34: 1 | J34: 0 | K34: 1 | L34: 0 | M34: 27 | N34: 0 | O34: =SUM(C34:L34,N34) -> 14 | P34: =SUM(C34:N34) -> 41
B35: 13.15 - 13.30 | C35: 4 | D35: 2 | E35: 1 | F35: 0 | G35: 0 | H35: 0 | I35: 0 | J35: 0 | K35: 0 | L35: 0 | M35: 50 | N35: 0 | O35: =SUM(C35:L35,N35) -> 7 | P35: =SUM(C35:N35) -> 57
B36: 13.30 - 13.45 | C36: 7 | D36: 0 | E36: 2 | F36: 0 | G36: 0 | H36: 0 | I36: 0 | J36: 1 | K36: 1 | L36: 0 | M36: 31 | N36: 0 | O36: =SUM(C36:L36,N36) -> 11 | P36: =SUM(C36:N36) -> 42
B37: 13.45 - 14.00 | C37: 13 | D37: 1 | E37: 0 | F37: 0 | G37: 0 | H37: 0 | I37: 0 | J37: 1 | K37: 1 | L37: 0 | M37: 39 | N37: 0 | O37: =SUM(C37:L37,N37) -> 16 | P37: =SUM(C37:N37) -> 55
B38: 14.00 - 14.15 | C38: 31 | D38: 2 | E38: 3 | F38: 3 | G38: 0 | H38: 0 | I38: 2 | J38: 0 | K38: 0 | L38: 0 | M38: 50 | N38: 0 | O38: =SUM(C38:L38,N38) -> 41 | P38: =SUM(C38:N38) -> 91
B39: 14.15 - 14.30 | C39: 8 | D39: 4 | E39: 0 | F39: 1 | G39: 0 | H39: 0 | I39: 3 | J39: 0 | K39: 0 | L39: 0 | M39: 29 | N39: 0 | O39: =SUM(C39:L39,N39) -> 16 | P39: =SUM(C39:N39) -> 45
B40: 14.30 - 14.45 | C40: 6 | D40: 2 | E40: 1 | F40: 2 | G40: 0 | H40: 0 | I40: 2 | J40: 0 | K40: 0 | L40: 0 | M40: 38 | N40: 0 | O40: =SUM(C40:L40,N40) -> 13 | P40: =SUM(C40:N40) -> 51
... B57: 18.45 - 19.00 | C57: 4 | D57: 1 | E57: 1 | F57: 3 | G57: 0 | H57: 0 | I57: 0 | J57: 0 | K57: 0 | L57: 0 | M57: 23 | N57: 0 | O57: =SUM(C57:L57,N57) -> 9 | P57: =SUM(C57:N57) -> 32
B58: Totals | C58: =SUM(C10:C57) -> 260 | D58: =SUM(D10:D57) -> 61 | E58: =SUM(E10:E57) -> 55 | F58: =SUM(F10:F57) -> 56 | G58: =SUM(G10:G57) -> 1 | H58: =SUM(H10:H57) -> 4 | I58: =SUM(I10:I57) -> 44 | J58: =SUM(J10:J57) -> 24 | ... P58: =SUM(P10:P57) -> 2274
...

Sheet 26.10 KYENJOJO-HOIMA-24h
B1: Consultancy services for Preparation of Expressway Development Master Plan (EDMP) for Uganda
B2: MANUAL CLASSIFIED COUNT (MCC)
B3: ROAD NAME: | C3: ='25.10 KYENJOJO-HOIMA'!C3:G3 -> MCC - C4 - STN108 - HOIMA ROAD
C5: Date | D5: 26.07.19 | F5: Location | G5: ='30.10 HOIMA-KYENJOJO'!G5:H5 -> KYENJOJO | J5: Surveyor | K5: MOSES
C6: Dir. From | D6: ='25.10 KYENJOJO-HOIMA'!D6:E6 -> KYENJOJO | F6: Dir. To | G6: ='25.10 KYENJOJO-HOIMA'!G6:H6 -> HOIMA | J6: Supervisor | K6: ='30.10 HOIMA-KYENJOJO'!K6:L6 -> FELIX
B8: Time / Veh Type | R8: SUMMARY TRAFFIC VOLUMES
C9: 1. Car | D9: 2. Station Wagon | E9: 3. Pickups | F9: 4. Minibus, matatu | G9: 5. Medium bus | H9: 6. Large Bus | I9: 7. Light Truck | J9: 8. Medium Truck | K9: 9. Heavy truck | L9: 10. Truck Trailer | M9: 11. Motor cycles | N9: 12. Tractors | O9: Total Excl M/Cycles | P9: Total All | R9: Time | S9: 1. Car | T9: 2. Station Wagon | U9: 3. Pickups | V9: 4. Minibus, matatu | W9: 5. Medium bus | X9: 6. Large Bus | Y9: 7. Light Truck | Z9: 8. Medium Truck | AA9: 9. Heavy truck | AB9: 10. Truck Trailer | AC9: 11. Motorcycles | AD9: 12. Tractors, Graders | AE9: Total Excl M/ Cycles | AF9: Total All
B10: 07.00 - 07.15 | C10: 0 | D10: 0 | E10: 0 | F10: 0 | G10: 0 | H10: 0 | I10: 0 | J10: 0 | K10: 0 | L10: 0 | M10: 0 | N10: 0 | O10: =SUM(C10:L10,N10) -> 0 | P10: =SUM(C10:N10) -> 0 | R10: 0700-0800 | S10: =SUM(C10:C13) -> 2 | T10: =SUM(D10:D13) -> 2 | U10: =SUM(E10:E13) -> 1 | V10: =SUM(F10:F13) -> 4 | W10: =SUM(G10:G13) -> 0 | X10: =SUM(H10:H13) -> 0 | Y10: =SUM(I10:I13) -> 0 | Z10: =SUM(J10:J13) -> 0 | ... AF10: =SUM(P10:P13) -> 12
B11: 07.15 - 07.30 | C11: 2 | D11: 0 | E11: 1 | F11: 3 | G11: 0 | H11: 0 | I11: 0 | J11: 0 | K11: 0 | L11: 2 | M11: 0 | N11: 0 | O11: =SUM(C11:L11,N11) -> 8 | P11: =SUM(C11:N11) -> 8 | R11: 0800-0900 | S11: =SUM(C14:C17) -> 3 | T11: =SUM(D14:D17) -> 0 | U11: =SUM(E14:E17) -> 1 | V11: =SUM(F14:F17) -> 3 | W11: =SUM(G14:G17) -> 0 | X11: =SUM(H14:H17) -> 0 | Y11: =SUM(I14:I17) -> 0 | Z11: =SUM(J14:J17) -> 0 | ... AF11: =SUM(P14:P17) -> 16
B12: 07.30 - 07.45 | C12: 0 | D12: 2 | E12: 0 | F12: 1 | G12: 0 | H12: 0 | I12: 0 | J12: 0 | K12: 0 | L12: 0 | M12: 0 | N12: 0 | O12: =SUM(C12:L12,N12) -> 3 | P12: =SUM(C12:N12) -> 3 | R12: 0900-1000 | S12: =SUM(C18:C21) -> 15 | T12: =SUM(D18:D21) -> 1 | U12: =SUM(E18:E21) -> 1 | V12: =SUM(F18:F21) -> 3 | W12: =SUM(G18:G21) -> 0 | X12: =SUM(H18:H21) -> 0 | Y12: =SUM(I18:I21) -> 0 | Z12: =SUM(J18:J21) -> 1 | ... AF12: =SUM(P18:P21) -> 66
B13: 07.45 - 08.00 | C13: 0 | D13: 0 | E13: 0 | F13: 0 | G13: 0 | H13: 0 | I13: 0 | J13: 0 | K13: 0 | L13: 0 | M13: 1 | N13: 0 | O13: =SUM(C13:L13,N13) -> 0 | P13: =SUM(C13:N13) -> 1 | R13: 1000-1100 | S13: =SUM(C22:C25) -> 24 | T13: =SUM(D22:D25) -> 4 | U13: =SUM(E22:E25) -> 7 | V13: =SUM(F22:F25) -> 8 | W13: =SUM(G22:G25) -> 0 | X13: =SUM(H22:H25) -> 0 | Y13: =SUM(I22:I25) -> 3 | Z13: =SUM(J22:J25) -> 3 | ... AF13: =SUM(P22:P25) -> 126
B14: 08.00 - 08.15 | C14: 0 | D14: 0 | E14: 1 | F14: 0 | G14: 0 | H14: 0 | I14: 0 | J14: 0 | K14: 0 | L14: 0 | M14: 2 | N14: 0 | O14: =SUM(C14:L14,N14) -> 1 | P14: =SUM(C14:N14) -> 3 | R14: 1100-1200 | S14: =SUM(C26:C29) -> 17 | T14: =SUM(D26:D29) -> 4 | U14: =SUM(E26:E29) -> 5 | V14: =SUM(F26:F29) -> 4 | W14: =SUM(G26:G29) -> 0 | X14: =SUM(H26:H29) -> 0 | Y14: =SUM(I26:I29) -> 3 | Z14: =SUM(J26:J29) -> 1 | ... AF14: =SUM(P26:P29) -> 162
B15: 08.15 - 08.30 | C15: 1 | D15: 0 | E15: 0 | F15: 1 | G15: 0 | H15: 0 | I15: 0 | J15: 0 | K15: 0 | L15: 0 | M15: 2 | N15: 0 | O15: =SUM(C15:L15,N15) -> 2 | P15: =SUM(C15:N15) -> 4 | R15: 1200-1300 | S15: =SUM(C30:C33) -> 20 | T15: =SUM(D30:D33) -> 5 | U15: =SUM(E30:E33) -> 5 | V15: =SUM(F30:F33) -> 1 | W15: =SUM(G30:G33) -> 0 | X15: =SUM(H30:H33) -> 0 | Y15: =SUM(I30:I33) -> 2 | Z15: =SUM(J30:J33) -> 0 | ... AF15: =SUM(P30:P33) -> 163
B16: 08.30 - 08.45 | C16: 1 | D16: 0 | E16: 0 | F16: 2 | G16: 0 | H16: 0 | I16: 0 | J16: 0 | K16: 0 | L16: 0 | M16: 3 | N16: 0 | O16: =SUM(C16:L16,N16) -> 3 | P16: =SUM(C16:N16) -> 6 | R16: 1300-1400 | S16: =SUM(C34:C37) -> 21 | T16: =SUM(D34:D37) -> 1 | U16: =SUM(E34:E37) -> 5 | V16: =SUM(F34:F37) -> 3 | W16: =SUM(G34:G37) -> 1 | X16: =SUM(H34:H37) -> 0 | Y16: =SUM(I34:I37) -> 6 | Z16: =SUM(J34:J37) -> 1 | ... AF16: =SUM(P34:P37) -> 228
B17: 08.45 - 9.00 | C17: 1 | D17: 0 | E17: 0 | F17: 0 | G17: 0 | H17: 0 | I17: 0 | J17: 0 | K17: 0 | L17: 1 | M17: 1 | N17: 0 | O17: =SUM(C17:L17,N17) -> 2 | P17: =SUM(C17:N17) -> 3 | R17: 1400-1500 | S17: =SUM(C38:C41) -> 17 | T17: =SUM(D38:D41) -> 1 | U17: =SUM(E38:E41) -> 1 | V17: =SUM(F38:F41) -> 4 | W17: =SUM(G38:G41) -> 0 | X17: =SUM(H38:H41) -> 0 | Y17: =SUM(I38:I41) -> 7 | Z17: =SUM(J38:J41) -> 4 | ... AF17: =SUM(P38:P41) -> 224
B18: 09.00 - 09.15 | C18: 5 | D18: 1 | E18: 0 | F18: 1 | G18: 0 | H18: 0 | I18: 0 | J18: 0 | K18: 0 | L18: 0 | M18: 6 | N18: 0 | O18: =SUM(C18:L18,N18) -> 7 | P18: =SUM(C18:N18) -> 13 | R18: 1500-1600 | S18: =SUM(C42:C45) -> 22 | T18: =SUM(D42:D45) -> 2 | U18: =SUM(E42:E45) -> 3 | V18: =SUM(F42:F45) -> 2 | W18: =SUM(G42:G45) -> 1 | X18: =SUM(H42:H45) -> 0 | Y18: =SUM(I42:I45) -> 4 | Z18: =SUM(J42:J45) -> 2 | ... AF18: =SUM(P42:P45) -> 114
B19: 09.15 - 09.30 | C19: 4 | D19: 0 | E19: 1 | F19: 0 | G19: 0 | H19: 0 | I19: 0 | J19: 0 | K19: 0 | L19: 0 | M19: 8 | N19: 0 | O19: =SUM(C19:L19,N19) -> 5 | P19: =SUM(C19:N19) -> 13 | R19: 1600-1700 | S19: =SUM(C46:C49) -> 38 | T19: =SUM(D46:D49) -> 0 | U19: =SUM(E46:E49) -> 9 | V19: =SUM(F46:F49) -> 7 | W19: =SUM(G46:G49) -> 0 | X19: =SUM(H46:H49) -> 0 | Y19: =SUM(I46:I49) -> 1 | Z19: =SUM(J46:J49) -> 2 | ... AF19: =SUM(P46:P49) -> 141
B20: 09.30 - 09.45 | C20: 4 | D20: 0 | E20: 0 | F20: 2 | G20: 0 | H20: 0 | I20: 0 | J20: 0 | K20: 0 | L20: 0 | M20: 16 | N20: 0 | O20: =SUM(C20:L20,N20) -> 6 | P20: =SUM(C20:N20) -> 22 | R20: 1700-1800 | S20: =SUM(C50:C53) -> 28 | T20: =SUM(D50:D53) -> 2 | U20: =SUM(E50:E53) -> 3 | V20: =SUM(F50:F53) -> 0 | W20: =SUM(G50:G53) -> 0 | X20: =SUM(H50:H53) -> 0 | Y20: =SUM(I50:I53) -> 2 | Z20: =SUM(J50:J53) -> 0 | ... AF20: =SUM(P50:P53) -> 171
B21: 09.45 - 10.00 | C21: 2 | D21: 0 | E21: 0 | F21: 0 | G21: 0 | H21: 0 | I21: 0 | J21: 1 | K21: 0 | L21: 0 | M21: 15 | N21: 0 | O21: =SUM(C21:L21,N21) -> 3 | P21: =SUM(C21:N21) -> 18 | R21: 1800-1900 | S21: =SUM(C54:C57) -> 22 | T21: =SUM(D54:D57) -> 2 | U21: =SUM(E54:E57) -> 2 | V21: =SUM(F54:F57) -> 4 | W21: =SUM(G54:G57) -> 0 | X21: =SUM(H54:H57) -> 0 | Y21: =SUM(I54:I57) -> 1 | Z21: =SUM(J54:J57) -> 0 | ... AF21: =SUM(P54:P57) -> 165
B22: 10.00 - 10.15 | C22: 7 | D22: 1 | E22: 3 | F22: 2 | G22: 0 | H22: 0 | I22: 0 | J22: 1 | K22: 1 | L22: 0 | M22: 21 | N22: 0 | O22: =SUM(C22:L22,N22) -> 15 | P22: =SUM(C22:N22) -> 36 | R22: 1900-2000 | S22: =SUM(C58:C61) -> 37 | T22: =SUM(D58:D61) -> 1 | U22: =SUM(E58:E61) -> 2 | V22: =SUM(F58:F61) -> 0 | W22: =SUM(G58:G61) -> 0 | X22: =SUM(H58:H61) -> 0 | Y22: =SUM(I58:I61) -> 10 | Z22: =SUM(J58:J61) -> 1 | ... AF22: =SUM(P58:P61) -> 144
B23: 10.15 - 10.30 | C23: 8 | D23: 0 | E23: 0 | F23: 2 | G23: 0 | H23: 0 | I23: 0 | J23: 0 | K23: 0 | L23: 0 | M23: 20 | N23: 0 | O23: =SUM(C23:L23,N23) -> 10 | P23: =SUM(C23:N23) -> 30 | R23: 2000-2100 | S23: =SUM(C62:C65) -> 20 | T23: =SUM(D62:D65) -> 0 | U23: =SUM(E62:E65) -> 4 | V23: =SUM(F62:F65) -> 0 | W23: =SUM(G62:G65) -> 0 | X23: =SUM(H62:H65) -> 0 | Y23: =SUM(I62:I65) -> 2 | Z23: =SUM(J62:J65) -> 1 | ... AF23: =SUM(P62:P65) -> 82
B24: 10.30 - 10.45 | C24: 5 | D24: 2 | E24: 1 | F24: 0 | G24: 0 | H24: 0 | I24: 2 | J24: 1 | K24: 0 | L24: 0 | M24: 16 | N24: 0 | O24: =SUM(C24:L24,N24) -> 11 | P24: =SUM(C24:N24) -> 27 | R24: 2100-2200 | S24: =SUM(C66:C69) -> 13 | T24: =SUM(D66:D69) -> 5 | U24: =SUM(E66:E69) -> 3 | V24: =SUM(F66:F69) -> 0 | W24: =SUM(G66:G69) -> 0 | X24: =SUM(H66:H69) -> 0 | Y24: =SUM(I66:I69) -> 2 | Z24: =SUM(J66:J69) -> 1 | ... AF24: =SUM(P66:P69) -> 97
B25: 10.45 - 11.00 | C25: 4 | D25: 1 | E25: 3 | F25: 4 | G25: 0 | H25: 0 | I25: 1 | J25: 1 | K25: 0 | L25: 0 | M25: 19 | N25: 0 | O25: =SUM(C25:L25,N25) -> 14 | P25: =SUM(C25:N25) -> 33 | R25: 2200-2300 | S25: =SUM(C70:C73) -> 10 | T25: =SUM(D70:D73) -> 0 | U25: =SUM(E70:E73) -> 3 | V25: =SUM(F70:F73) -> 1 | W25: =SUM(G70:G73) -> 0 | X25: =SUM(H70:H73) -> 0 | Y25: =SUM(I70:I73) -> 2 | Z25: =SUM(J70:J73) -> 1 | ... AF25: =SUM(P70:P73) -> 53
B26: 11.00 - 11.15 | C26: 6 | D26: 0 | E26: 1 | F26: 2 | G26: 0 | H26: 0 | I26: 2 | J26: 1 | K26: 0 | L26: 0 | M26: 21 | N26: 0 | O26: =SUM(C26:L26,N26) -> 12 | P26: =SUM(C26:N26) -> 33 | R26: 2300-0000 | S26: =SUM(C74:C77) -> 9 | T26: =SUM(D74:D77) -> 0 | U26: =SUM(E74:E77) -> 1 | V26: =SUM(F74:F77) -> 1 | W26: =SUM(G74:G77) -> 0 | X26: =SUM(H74:H77) -> 0 | Y26: =SUM(I74:I77) -> 0 | Z26: =SUM(J74:J77) -> 0 | ... AF26: =SUM(P74:P77) -> 29
B27: 11.15 - 11.30 | C27: 2 | D27: 0 | E27: 0 | F27: 1 | G27: 0 | H27: 0 | I27: 0 | J27: 0 | K27: 0 | L27: 0 | M27: 31 | N27: 0 | O27: =SUM(C27:L27,N27) -> 3 | P27: =SUM(C27:N27) -> 34 | R27: 0000-0100 | S27: =SUM(C78:C81) -> 2 | T27: =SUM(D78:D81) -> 0 | U27: =SUM(E78:E81) -> 0 | V27: =SUM(F78:F81) -> 1 | W27: =SUM(G78:G81) -> 0 | X27: =SUM(H78:H81) -> 0 | Y27: =SUM(I78:I81) -> 0 | Z27: =SUM(J78:J81) -> 0 | ... AF27: =SUM(P78:P81) -> 16
B28: 11.30 - 11.45 | C28: 7 | D28: 3 | E28: 1 | F28: 0 | G28: 0 | H28: 0 | I28: 1 | J28: 0 | K28: 0 | L28: 0 | M28: 39 | N28: 0 | O28: =SUM(C28:L28,N28) -> 12 | P28: =SUM(C28:N28) -> 51 | R28: 0100-0200 | S28: =SUM(C82:C85) -> 1 | T28: =SUM(D82:D85) -> 0 | U28: =SUM(E82:E85) -> 0 | V28: =SUM(F82:F85) -> 1 | W28: =SUM(G82:G85) -> 0 | X28: =SUM(H82:H85) -> 0 | Y28: =SUM(I82:I85) -> 0 | Z28: =SUM(J82:J85) -> 1 | ... AF28: =SUM(P82:P85) -> 7
B29: 11.45 - 12.00 | C29: 2 | D29: 1 | E29: 3 | F29: 1 | G29: 0 | H29: 0 | I29: 0 | J29: 0 | K29: 0 | L29: 0 | M29: 37 | N29: 0 | O29: =SUM(C29:L29,N29) -> 7 | P29: =SUM(C29:N29) -> 44 | R29: 0200-0300 | S29: =SUM(C86:C89) -> 2 | T29: =SUM(D86:D89) -> 0 | U29: =SUM(E86:E89) -> 0 | V29: =SUM(F86:F89) -> 0 | W29: =SUM(G86:G89) -> 0 | X29: =SUM(H86:H89) -> 0 | Y29: =SUM(I86:I89) -> 0 | Z29: =SUM(J86:J89) -> 2 | ... AF29: =SUM(P86:P89) -> 5
B30: 12.00 - 12.15 | C30: 4 | D30: 2 | E30: 1 | F30: 0 | G30: 0 | H30: 0 | I30: 0 | J30: 0 | K30: 0 | L30: 0 | M30: 44 | N30: 0 | O30: =SUM(C30:L30,N30) -> 7 | P30: =SUM(C30:N30) -> 51 | R30: 0300-0400 | S30: =SUM(C90:C93) -> 0 | T30: =SUM(D90:D93) -> 0 | U30: =SUM(E90:E93) -> 1 | V30: =SUM(F90:F93) -> 0 | W30: =SUM(G90:G93) -> 1 | X30: =SUM(H90:H93) -> 0 | Y30: =SUM(I90:I93) -> 0 | Z30: =SUM(J90:J93) -> 0 | ... AF30: =SUM(P90:P93) -> 5
B31: 12.15 - 12.30 | C31: 4 | D31: 3 | E31: 0 | F31: 1 | G31: 0 | H31: 0 | I31: 0 | J31: 0 | K31: 0 | L31: 0 | M31: 23 | N31: 0 | O31: =SUM(C31:L31,N31) -> 8 | P31: =SUM(C31:N31) -> 31 | R31: 0400-0500 | S31: =SUM(C94:C97) -> 4 | T31: =SUM(D94:D97) -> 0 | U31: =SUM(E94:E97) -> 0 | V31: =SUM(F94:F97) -> 0 | W31: =SUM(G94:G97) -> 0 | X31: =SUM(H94:H97) -> 0 | Y31: =SUM(I94:I97) -> 1 | Z31: =SUM(J94:J97) -> 0 | ... AF31: =SUM(P94:P97) -> 14
B32: 12.30 - 12.45 | C32: 8 | D32: 0 | E32: 3 | F32: 0 | G32: 0 | H32: 0 | I32: 2 | J32: 0 | K32: 0 | L32: 0 | M32: 52 | N32: 0 | O32: =SUM(C32:L32,N32) -> 13 | P32: =SUM(C32:N32) -> 65 | R32: 0500-0600 | S32: =SUM(C98:C101) -> 1 | T32: =SUM(D98:D101) -> 0 | U32: =SUM(E98:E101) -> 0 | V32: =SUM(F98:F101) -> 0 | W32: =SUM(G98:G101) -> 0 | X32: =SUM(H98:H101) -> 0 | Y32: =SUM(I98:I101) -> 1 | Z32: =SUM(J98:J101) -> 0 | ... AF32: =SUM(P98:P101) -> 6
B33: 12.45 - 13.00 | C33: 4 | D33: 0 | E33: 1 | F33: 0 | G33: 0 | H33: 0 | I33: 0 | J33: 0 | K33: 0 | L33: 0 | M33: 11 | N33: 0 | O33: =SUM(C33:L33,N33) -> 5 | P33: =SUM(C33:N33) -> 16 | R33: 0600-0700 | S33: =SUM(C102:C105) -> 4 | T33: =SUM(D102:D105) -> 0 | U33: =SUM(E102:E105) -> 0 | V33: =SUM(F102:F105) -> 2 | W33: =SUM(G102:G105) -> 0 | X33: =SUM(H102:H105) -> 0 | Y33: =SUM(I102:I105) -> 0 | Z33: =SUM(J102:J105) -> 1 | ... AF33: =SUM(P102:P105) -> 18
B34: 13.00 - 13.15 | C34: 3 | D34: 0 | E34: 2 | F34: 0 | G34: 1 | H34: 0 | I34: 0 | J34: 0 | K34: 1 | L34: 0 | M34: 26 | N34: 0 | O34: =SUM(C34:L34,N34) -> 7 | P34: =SUM(C34:N34) -> 33 | R34: AM Peak Hr | S34: =MAX(S10:S12) -> 15 | T34: =MAX(T10:T12) -> 2 | U34: =MAX(U10:U12) -> 1 | V34: =MAX(V10:V12) -> 4 | W34: =MAX(W10:W12) -> 0 | X34: =MAX(X10:X12) -> 0 | Y34: =MAX(Y10:Y12) -> 0 | Z34: =MAX(Z10:Z12) -> 1 | ... AF34: =MAX(AF10:AF12) -> 66
B35: 13.15 - 13.30 | C35: 4 | D35: 1 | E35: 1 | F35: 1 | G35: 0 | H35: 0 | I35: 0 | J35: 1 | K35: 2 | L35: 0 | M35: 58 | N35: 0 | O35: =SUM(C35:L35,N35) -> 10 | P35: =SUM(C35:N35) -> 68 | R35: IP Peak Hr | S35: =MAX(S13:S18) -> 24 | T35: =MAX(T13:T18) -> 5 | U35: =MAX(U13:U18) -> 7 | V35: =MAX(V13:V18) -> 8 | W35: =MAX(W13:W18) -> 1 | X35: =MAX(X13:X18) -> 0 | Y35: =MAX(Y13:Y18) -> 7 | Z35: =MAX(Z13:Z18) -> 4 | ... AF35: =MAX(AF13:AF18) -> 228
B36: 13.30 - 13.45 | C36: 9 | D36: 0 | E36: 2 | F36: 1 | G36: 0 | H36: 0 | I36: 3 | J36: 0 | K36: 0 | L36: 0 | M36: 52 | N36: 0 | O36: =SUM(C36:L36,N36) -> 15 | P36: =SUM(C36:N36) -> 67 | R36: PM Peak Hr | S36: =MAX(S19:S21) -> 38 | T36: =MAX(T19:T21) -> 2 | U36: =MAX(U19:U21) -> 9 | V36: =MAX(V19:V21) -> 7 | W36: =MAX(W19:W21) -> 0 | X36: =MAX(X19:X21) -> 0 | Y36: =MAX(Y19:Y21) -> 2 | Z36: =MAX(Z19:Z21) -> 2 | ... AF36: =MAX(AF19:AF21) -> 171
B37: 13.45 - 14.00 | C37: 5 | D37: 0 | E37: 0 | F37: 1 | G37: 0 | H37: 0 | I37: 3 | J37: 0 | K37: 0 | L37: 0 | M37: 51 | N37: 0 | O37: =SUM(C37:L37,N37) -> 9 | P37: =SUM(C37:N37) -> 60 | R37: AM Period | S37: =SUM(S10:S12) -> 20 | T37: =SUM(T10:T12) -> 3 | U37: =SUM(U10:U12) -> 3 | V37: =SUM(V10:V12) -> 10 | W37: =SUM(W10:W12) -> 0 | X37: =SUM(X10:X12) -> 0 | Y37: =SUM(Y10:Y12) -> 0 | Z37: =SUM(Z10:Z12) -> 1 | ... AF37: =SUM(AF10:AF12) -> 94
B38: 14.00 - 14.15 | C38: 7 | D38: 0 | E38: 0 | F38: 0 | G38: 0 | H38: 0 | I38: 2 | J38: 0 | K38: 0 | L38: 0 | M38: 46 | N38: 0 | O38: =SUM(C38:L38,N38) -> 9 | P38: =SUM(C38:N38) -> 55 | R38: IP Period | S38: =SUM(S13:S18) -> 121 | T38: =SUM(T13:T18) -> 17 | U38: =SUM(U13:U18) -> 26 | V38: =SUM(V13:V18) -> 22 | W38: =SUM(W13:W18) -> 2 | X38: =SUM(X13:X18) -> 0 | Y38: =SUM(Y13:Y18) -> 25 | Z38: =SUM(Z13:Z18) -> 11 | ... AF38: =SUM(AF13:AF18) -> 1017
B39: 14.15 - 14.30 | C39: 5 | D39: 1 | E39: 0 | F39: 1 | G39: 0 | H39: 0 | I39: 3 | J39: 1 | K39: 0 | L39: 0 | M39: 60 | N39: 0 | O39: =SUM(C39:L39,N39) -> 11 | P39: =SUM(C39:N39) -> 71 | R39: PM Period | S39: =SUM(S19:S21) -> 88 | T39: =SUM(T19:T21) -> 4 | U39: =SUM(U19:U21) -> 14 | V39: =SUM(V19:V21) -> 11 | W39: =SUM(W19:W21) -> 0 | X39: =SUM(X19:X21) -> 0 | Y39: =SUM(Y19:Y21) -> 4 | Z39: =SUM(Z19:Z21) -> 2 | ... AF39: =SUM(AF19:AF21) -> 477
B40: 14.30 - 14.45 | C40: 1 | D40: 0 | E40: 0 | F40: 1 | G40: 0 | H40: 0 | I40: 0 | J40: 1 | K40: 0 | L40: 0 | M40: 47 | N40: 0 | O40: =SUM(C40:L40,N40) -> 3 | P40: =SUM(C40:N40) -> 50 | R40: 12 Hours | S40: =SUM(S10:S21) -> 229 | T40: =SUM(T10:T21) -> 24 | U40: =SUM(U10:U21) -> 43 | V40: =SUM(V10:V21) -> 43 | W40: =SUM(W10:W21) -> 2 | X40: =SUM(X10:X21) -> 0 | Y40: =SUM(Y10:Y21) -> 29 | Z40: =SUM(Z10:Z21) -> 14 | ... AF40: =SUM(AF10:AF21) -> 1588
B41: 14.45 - 15.00 | C41: 4 | D41: 0 | E41: 1 | F41: 2 | G41: 0 | H41: 0 | I41: 2 | J41: 2 | K41: 0 | L41: 0 | M41: 37 | N41: 0 | O41: =SUM(C41:L41,N41) -> 11 | P41: =SUM(C41:N41) -> 48 | R41: 24 Hrs/ADT | S41: =SUM(S10:S33) -> 332 | T41: =SUM(T10:T33) -> 30 | U41: =SUM(U10:U33) -> 57 | V41: =SUM(V10:V33) -> 49 | W41: =SUM(W10:W33) -> 3 | X41: =SUM(X10:X33) -> 0 | Y41: =SUM(Y10:Y33) -> 47 | Z41: =SUM(Z10:Z33) -> 22 | ... AF41: =SUM(AF10:AF33) -> 2064
B42: 15.00 - 15.15 | C42: 6 | D42: 0 | E42: 0 | F42: 0 | G42: 0 | H42: 0 | I42: 1 | J42: 1 | K42: 0 | L42: 0 | M42: 34 | N42: 0 | O42: =SUM(C42:L42,N42) -> 8 | P42: =SUM(C42:N42) -> 42 | R42: NEF | S42: =S41/S40 -> 1.4497817 | T42: =T41/T40 -> 1.25 | U42: =U41/U40 -> 1.3255814 | V42: =V41/V40 -> 1.1395349 | W42: =W41/W40 -> 1.5 | X42: =X41/X40 -> #DIV/0! | Y42: =Y41/Y40 -> 1.6206897 | Z42: =Z41/Z40 -> 1.5714286 | ... AF42: =AF41/AF40 -> 1.2997481
...

Sheet 26.10 HOIMA-KYENJOJO-24h
B1: Consultancy services for Preparation of Expressway Development Master Plan (EDMP) for Uganda
B2: MANUAL CLASSIFIED COUNT (MCC)
B3: ROAD NAME: | C3: ='25.10 KYENJOJO-HOIMA'!C3:G3 -> MCC - C4 - STN108 - HOIMA ROAD
C5: Date | D5: ='26.10 KYENJOJO-HOIMA-24h'!D5 -> 26.07.19 | F5: Location | G5: ='26.10 KYENJOJO-HOIMA-24h'!G5:H5 -> KYENJOJO | J5: Surveyor | K5: STEVEN
C6: Dir. From | D6: ='25.10 HOIMA-KYENJOJO'!D6:E6 -> HOIMA | F6: Dir. To | G6: ='27.10 HOIMA-KYENJOJO'!G6:H6 -> KYENJOJO | J6: Supervisor | K6: FELIX
B8: Time / Veh Type | R8: SUMMARY TRAFFIC VOLUMES
C9: 1. Car | D9: 2. Station Wagon | E9: 3. Pickups | F9: 4. Minibus, matatu | G9: 5. Medium bus | H9: 6. Large Bus | I9: 7. Light Truck | J9: 8. Medium Truck | K9: 9. Heavy truck | L9: 10. Truck Trailer | M9: 11. Motor cycles | N9: 12. Tractors | O9: Total Excl M/Cycles | P9: Total All | R9: Time | S9: 1. Car | T9: 2. Station Wagon | U9: 3. Pickups | V9: 4. Minibus, matatu | W9: 5. Medium bus | X9: 6. Large Bus | Y9: 7. Light Truck | Z9: 8. Medium Truck | AA9: 9. Heavy truck | AB9: 10. Truck Trailer | AC9: 11. Motorcycles | AD9: 12. Tractors, Graders | AE9: Total Excl M/ Cycles | AF9: Total All
B10: 07.00 - 07.15 | C10: 0 | D10: 0 | E10: 0 | F10: 0 | G10: 0 | H10: 0 | I10: 0 | J10: 0 | K10: 0 | L10: 0 | M10: 0 | N10: 0 | O10: =SUM(C10:L10,N10) -> 0 | P10: =SUM(C10:N10) -> 0 | R10: 0700-0800 | S10: =SUM(C10:C13) -> 3 | T10: =SUM(D10:D13) -> 1 | U10: =SUM(E10:E13) -> 0 | V10: =SUM(F10:F13) -> 2 | W10: =SUM(G10:G13) -> 0 | X10: =SUM(H10:H13) -> 0 | Y10: =SUM(I10:I13) -> 0 | Z10: =SUM(J10:J13) -> 0 | ... AF10: =SUM(P10:P13) -> 8
B11: 07.15 - 07.30 | C11: 1 | D11: 0 | E11: 0 | F11: 2 | G11: 0 | H11: 0 | I11: 0 | J11: 0 | K11: 0 | L11: 0 | M11: 0 | N11: 0 | O11: =SUM(C11:L11,N11) -> 3 | P11: =SUM(C11:N11) -> 3 | R11: 0800-0900 | S11: =SUM(C14:C17) -> 4 | T11: =SUM(D14:D17) -> 0 | U11: =SUM(E14:E17) -> 1 | V11: =SUM(F14:F17) -> 2 | W11: =SUM(G14:G17) -> 0 | X11: =SUM(H14:H17) -> 0 | Y11: =SUM(I14:I17) -> 0 | Z11: =SUM(J14:J17) -> 1 | ... AF11: =SUM(P14:P17) -> 13
B12: 07.30 - 07.45 | C12: 2 | D12: 1 | E12: 0 | F12: 0 | G12: 0 | H12: 0 | I12: 0 | J12: 0 | K12: 0 | L12: 0 | M12: 0 | N12: 0 | O12: =SUM(C12:L12,N12) -> 3 | P12: =SUM(C12:N12) -> 3 | R12: 0900-1000 | S12: =SUM(C18:C21) -> 17 | T12: =SUM(D18:D21) -> 2 | U12: =SUM(E18:E21) -> 1 | V12: =SUM(F18:F21) -> 2 | W12: =SUM(G18:G21) -> 0 | X12: =SUM(H18:H21) -> 0 | Y12: =SUM(I18:I21) -> 4 | Z12: =SUM(J18:J21) -> 0 | ... AF12: =SUM(P18:P21) -> 94
B13: 07.45 - 08.00 | C13: 0 | D13: 0 | E13: 0 | F13: 0 | G13: 0 | H13: 0 | I13: 0 | J13: 0 | K13: 0 | L13: 0 | M13: 2 | N13: 0 | O13: =SUM(C13:L13,N13) -> 0 | P13: =SUM(C13:N13) -> 2 | R13: 1000-1100 | S13: =SUM(C22:C25) -> 22 | T13: =SUM(D22:D25) -> 1 | U13: =SUM(E22:E25) -> 1 | V13: =SUM(F22:F25) -> 3 | W13: =SUM(G22:G25) -> 0 | X13: =SUM(H22:H25) -> 1 | Y13: =SUM(I22:I25) -> 2 | Z13: =SUM(J22:J25) -> 2 | ... AF13: =SUM(P22:P25) -> 121
B14: 08.00 - 08.15 | C14: 2 | D14: 0 | E14: 0 | F14: 0 | G14: 0 | H14: 0 | I14: 0 | J14: 0 | K14: 0 | L14: 0 | M14: 1 | N14: 0 | O14: =SUM(C14:L14,N14) -> 2 | P14: =SUM(C14:N14) -> 3 | R14: 1100-1200 | S14: =SUM(C26:C29) -> 15 | T14: =SUM(D26:D29) -> 5 | U14: =SUM(E26:E29) -> 3 | V14: =SUM(F26:F29) -> 7 | W14: =SUM(G26:G29) -> 0 | X14: =SUM(H26:H29) -> 0 | Y14: =SUM(I26:I29) -> 6 | Z14: =SUM(J26:J29) -> 3 | ... AF14: =SUM(P26:P29) -> 130
B15: 08.15 - 08.30 | C15: 1 | D15: 0 | E15: 1 | F15: 1 | G15: 0 | H15: 0 | I15: 0 | J15: 0 | K15: 0 | L15: 0 | M15: 1 | N15: 0 | O15: =SUM(C15:L15,N15) -> 3 | P15: =SUM(C15:N15) -> 4 | R15: 1200-1300 | S15: =SUM(C30:C33) -> 39 | T15: =SUM(D30:D33) -> 4 | U15: =SUM(E30:E33) -> 5 | V15: =SUM(F30:F33) -> 5 | W15: =SUM(G30:G33) -> 0 | X15: =SUM(H30:H33) -> 0 | Y15: =SUM(I30:I33) -> 3 | Z15: =SUM(J30:J33) -> 1 | ... AF15: =SUM(P30:P33) -> 153
B16: 08.30 - 08.45 | C16: 1 | D16: 0 | E16: 0 | F16: 1 | G16: 0 | H16: 0 | I16: 0 | J16: 1 | K16: 0 | L16: 0 | M16: 3 | N16: 0 | O16: =SUM(C16:L16,N16) -> 3 | P16: =SUM(C16:N16) -> 6 | R16: 1300-1400 | S16: =SUM(C34:C37) -> 16 | T16: =SUM(D34:D37) -> 0 | U16: =SUM(E34:E37) -> 3 | V16: =SUM(F34:F37) -> 7 | W16: =SUM(G34:G37) -> 0 | X16: =SUM(H34:H37) -> 0 | Y16: =SUM(I34:I37) -> 1 | Z16: =SUM(J34:J37) -> 2 | ... AF16: =SUM(P34:P37) -> 116
B17: 08.45 - 9.00 | C17: 0 | D17: 0 | E17: 0 | F17: 0 | G17: 0 | H17: 0 | I17: 0 | J17: 0 | K17: 0 | L17: 0 | M17: 0 | N17: 0 | O17: =SUM(C17:L17,N17) -> 0 | P17: =SUM(C17:N17) -> 0 | R17: 1400-1500 | S17: =SUM(C38:C41) -> 17 | T17: =SUM(D38:D41) -> 2 | U17: =SUM(E38:E41) -> 2 | V17: =SUM(F38:F41) -> 0 | W17: =SUM(G38:G41) -> 0 | X17: =SUM(H38:H41) -> 0 | Y17: =SUM(I38:I41) -> 7 | Z17: =SUM(J38:J41) -> 1 | ... AF17: =SUM(P38:P41) -> 145
B18: 09.00 - 09.15 | C18: 1 | D18: 2 | E18: 0 | F18: 0 | G18: 0 | H18: 0 | I18: 1 | J18: 0 | K18: 0 | L18: 0 | M18: 4 | N18: 0 | O18: =SUM(C18:L18,N18) -> 4 | P18: =SUM(C18:N18) -> 8 | R18: 1500-1600 | S18: =SUM(C42:C45) -> 18 | T18: =SUM(D42:D45) -> 0 | U18: =SUM(E42:E45) -> 3 | V18: =SUM(F42:F45) -> 0 | W18: =SUM(G42:G45) -> 0 | X18: =SUM(H42:H45) -> 0 | Y18: =SUM(I42:I45) -> 4 | Z18: =SUM(J42:J45) -> 2 | ... AF18: =SUM(P42:P45) -> 59
B19: 09.15 - 09.30 | C19: 5 | D19: 0 | E19: 1 | F19: 2 | G19: 0 | H19: 0 | I19: 1 | J19: 0 | K19: 0 | L19: 0 | M19: 16 | N19: 0 | O19: =SUM(C19:L19,N19) -> 9 | P19: =SUM(C19:N19) -> 25 | R19: 1600-1700 | S19: =SUM(C46:C49) -> 30 | T19: =SUM(D46:D49) -> 4 | U19: =SUM(E46:E49) -> 5 | V19: =SUM(F46:F49) -> 4 | W19: =SUM(G46:G49) -> 2 | X19: =SUM(H46:H49) -> 0 | Y19: =SUM(I46:I49) -> 3 | Z19: =SUM(J46:J49) -> 2 | ... AF19: =SUM(P46:P49) -> 89
B20: 09.30 - 09.45 | C20: 6 | D20: 0 | E20: 0 | F20: 0 | G20: 0 | H20: 0 | I20: 1 | J20: 0 | K20: 0 | L20: 0 | M20: 26 | N20: 0 | O20: =SUM(C20:L20,N20) -> 7 | P20: =SUM(C20:N20) -> 33 | R20: 1700-1800 | S20: =SUM(C50:C53) -> 16 | T20: =SUM(D50:D53) -> 1 | U20: =SUM(E50:E53) -> 1 | V20: =SUM(F50:F53) -> 3 | W20: =SUM(G50:G53) -> 0 | X20: =SUM(H50:H53) -> 0 | Y20: =SUM(I50:I53) -> 0 | Z20: =SUM(J50:J53) -> 1 | ... AF20: =SUM(P50:P53) -> 65
B21: 09.45 - 10.00 | C21: 5 | D21: 0 | E21: 0 | F21: 0 | G21: 0 | H21: 0 | I21: 1 | J21: 0 | K21: 0 | L21: 0 | M21: 22 | N21: 0 | O21: =SUM(C21:L21,N21) -> 6 | P21: =SUM(C21:N21) -> 28 | R21: 1800-1900 | S21: =SUM(C54:C57) -> 33 | T21: =SUM(D54:D57) -> 2 | U21: =SUM(E54:E57) -> 4 | V21: =SUM(F54:F57) -> 1 | W21: =SUM(G54:G57) -> 0 | X21: =SUM(H54:H57) -> 0 | Y21: =SUM(I54:I57) -> 7 | Z21: =SUM(J54:J57) -> 0 | ... AF21: =SUM(P54:P57) -> 158
B22: 10.00 - 10.15 | C22: 10 | D22: 0 | E22: 1 | F22: 0 | G22: 0 | H22: 1 | I22: 0 | J22: 0 | K22: 0 | L22: 0 | M22: 21 | N22: 0 | O22: =SUM(C22:L22,N22) -> 12 | P22: =SUM(C22:N22) -> 33 | R22: 1900-2000 | S22: =SUM(C58:C61) -> 34 | T22: =SUM(D58:D61) -> 3 | U22: =SUM(E58:E61) -> 4 | V22: =SUM(F58:F61) -> 3 | W22: =SUM(G58:G61) -> 0 | X22: =SUM(H58:H61) -> 0 | Y22: =SUM(I58:I61) -> 1 | Z22: =SUM(J58:J61) -> 1 | ... AF22: =SUM(P58:P61) -> 156
B23: 10.15 - 10.30 | C23: 4 | D23: 1 | E23: 0 | F23: 2 | G23: 0 | H23: 0 | I23: 1 | J23: 0 | K23: 1 | L23: 0 | M23: 20 | N23: 0 | O23: =SUM(C23:L23,N23) -> 9 | P23: =SUM(C23:N23) -> 29 | R23: 2000-2100 | S23: =SUM(C62:C65) -> 15 | T23: =SUM(D62:D65) -> 2 | U23: =SUM(E62:E65) -> 4 | V23: =SUM(F62:F65) -> 1 | W23: =SUM(G62:G65) -> 0 | X23: =SUM(H62:H65) -> 0 | Y23: =SUM(I62:I65) -> 1 | Z23: =SUM(J62:J65) -> 1 | ... AF23: =SUM(P62:P65) -> 74
B24: 10.30 - 10.45 | C24: 4 | D24: 0 | E24: 0 | F24: 0 | G24: 0 | H24: 0 | I24: 0 | J24: 2 | K24: 0 | L24: 0 | M24: 21 | N24: 0 | O24: =SUM(C24:L24,N24) -> 6 | P24: =SUM(C24:N24) -> 27 | R24: 2100-2200 | S24: =SUM(C66:C69) -> 10 | T24: =SUM(D66:D69) -> 1 | U24: =SUM(E66:E69) -> 2 | V24: =SUM(F66:F69) -> 1 | W24: =SUM(G66:G69) -> 0 | X24: =SUM(H66:H69) -> 0 | Y24: =SUM(I66:I69) -> 0 | Z24: =SUM(J66:J69) -> 0 | ... AF24: =SUM(P66:P69) -> 60
B25: 10.45 - 11.00 | C25: 4 | D25: 0 | E25: 0 | F25: 1 | G25: 0 | H25: 0 | I25: 1 | J25: 0 | K25: 0 | L25: 0 | M25: 26 | N25: 0 | O25: =SUM(C25:L25,N25) -> 6 | P25: =SUM(C25:N25) -> 32 | R25: 2200-2300 | S25: =SUM(C70:C73) -> 6 | T25: =SUM(D70:D73) -> 1 | U25: =SUM(E70:E73) -> 2 | V25: =SUM(F70:F73) -> 1 | W25: =SUM(G70:G73) -> 0 | X25: =SUM(H70:H73) -> 0 | Y25: =SUM(I70:I73) -> 4 | Z25: =SUM(J70:J73) -> 1 | ... AF25: =SUM(P70:P73) -> 52
B26: 11.00 - 11.15 | C26: 5 | D26: 3 | E26: 1 | F26: 0 | G26: 0 | H26: 0 | I26: 2 | J26: 0 | K26: 1 | L26: 0 | M26: 14 | N26: 0 | O26: =SUM(C26:L26,N26) -> 12 | P26: =SUM(C26:N26) -> 26 | R26: 2300-0000 | S26: =SUM(C74:C77) -> 7 | T26: =SUM(D74:D77) -> 1 | U26: =SUM(E74:E77) -> 1 | V26: =SUM(F74:F77) -> 0 | W26: =SUM(G74:G77) -> 0 | X26: =SUM(H74:H77) -> 0 | Y26: =SUM(I74:I77) -> 0 | Z26: =SUM(J74:J77) -> 0 | ... AF26: =SUM(P74:P77) -> 28
B27: 11.15 - 11.30 | C27: 4 | D27: 0 | E27: 0 | F27: 2 | G27: 0 | H27: 0 | I27: 1 | J27: 2 | K27: 0 | L27: 0 | M27: 23 | N27: 0 | O27: =SUM(C27:L27,N27) -> 9 | P27: =SUM(C27:N27) -> 32 | R27: 0000-0100 | S27: =SUM(C78:C81) -> 3 | T27: =SUM(D78:D81) -> 0 | U27: =SUM(E78:E81) -> 0 | V27: =SUM(F78:F81) -> 0 | W27: =SUM(G78:G81) -> 0 | X27: =SUM(H78:H81) -> 0 | Y27: =SUM(I78:I81) -> 1 | Z27: =SUM(J78:J81) -> 0 | ... AF27: =SUM(P78:P81) -> 17
B28: 11.30 - 11.45 | C28: 5 | D28: 1 | E28: 0 | F28: 2 | G28: 0 | H28: 0 | I28: 2 | J28: 1 | K28: 0 | L28: 0 | M28: 28 | N28: 0 | O28: =SUM(C28:L28,N28) -> 11 | P28: =SUM(C28:N28) -> 39 | R28: 0100-0200 | S28: =SUM(C82:C85) -> 0 | T28: =SUM(D82:D85) -> 0 | U28: =SUM(E82:E85) -> 0 | V28: =SUM(F82:F85) -> 0 | W28: =SUM(G82:G85) -> 0 | X28: =SUM(H82:H85) -> 0 | Y28: =SUM(I82:I85) -> 0 | Z28: =SUM(J82:J85) -> 0 | ... AF28: =SUM(P82:P85) -> 8
B29: 11.45 - 12.00 | C29: 1 | D29: 1 | E29: 2 | F29: 3 | G29: 0 | H29: 0 | I29: 1 | J29: 0 | K29: 0 | L29: 0 | M29: 25 | N29: 0 | O29: =SUM(C29:L29,N29) -> 8 | P29: =SUM(C29:N29) -> 33 | R29: 0200-0300 | S29: =SUM(C86:C89) -> 0 | T29: =SUM(D86:D89) -> 0 | U29: =SUM(E86:E89) -> 0 | V29: =SUM(F86:F89) -> 0 | W29: =SUM(G86:G89) -> 0 | X29: =SUM(H86:H89) -> 0 | Y29: =SUM(I86:I89) -> 0 | Z29: =SUM(J86:J89) -> 0 | ... AF29: =SUM(P86:P89) -> 5
B30: 12.00 - 12.15 | C30: 11 | D30: 2 | E30: 2 | F30: 2 | G30: 0 | H30: 0 | I30: 1 | J30: 1 | K30: 0 | L30: 0 | M30: 38 | N30: 0 | O30: =SUM(C30:L30,N30) -> 19 | P30: =SUM(C30:N30) -> 57 | R30: 0300-0400 | S30: =SUM(C90:C93) -> 0 | T30: =SUM(D90:D93) -> 0 | U30: =SUM(E90:E93) -> 0 | V30: =SUM(F90:F93) -> 1 | W30: =SUM(G90:G93) -> 0 | X30: =SUM(H90:H93) -> 0 | Y30: =SUM(I90:I93) -> 0 | Z30: =SUM(J90:J93) -> 0 | ... AF30: =SUM(P90:P93) -> 3
B31: 12.15 - 12.30 | C31: 10 | D31: 1 | E31: 1 | F31: 0 | G31: 0 | H31: 0 | I31: 0 | J31: 0 | K31: 0 | L31: 0 | M31: 7 | N31: 0 | O31: =SUM(C31:L31,N31) -> 12 | P31: =SUM(C31:N31) -> 19 | R31: 0400-0500 | S31: =SUM(C94:C97) -> 2 | T31: =SUM(D94:D97) -> 1 | U31: =SUM(E94:E97) -> 0 | V31: =SUM(F94:F97) -> 0 | W31: =SUM(G94:G97) -> 0 | X31: =SUM(H94:H97) -> 0 | Y31: =SUM(I94:I97) -> 1 | Z31: =SUM(J94:J97) -> 0 | ... AF31: =SUM(P94:P97) -> 5
B32: 12.30 - 12.45 | C32: 12 | D32: 0 | E32: 2 | F32: 1 | G32: 0 | H32: 0 | I32: 2 | J32: 0 | K32: 0 | L32: 0 | M32: 28 | N32: 0 | O32: =SUM(C32:L32,N32) -> 17 | P32: =SUM(C32:N32) -> 45 | R32: 0500-0600 | S32: =SUM(C98:C101) -> 1 | T32: =SUM(D98:D101) -> 1 | U32: =SUM(E98:E101) -> 0 | V32: =SUM(F98:F101) -> 1 | W32: =SUM(G98:G101) -> 0 | X32: =SUM(H98:H101) -> 0 | Y32: =SUM(I98:I101) -> 0 | Z32: =SUM(J98:J101) -> 0 | ... AF32: =SUM(P98:P101) -> 4
B33: 12.45 - 13.00 | C33: 6 | D33: 1 | E33: 0 | F33: 2 | G33: 0 | H33: 0 | I33: 0 | J33: 0 | K33: 0 | L33: 0 | M33: 23 | N33: 0 | O33: =SUM(C33:L33,N33) -> 9 | P33: =SUM(C33:N33) -> 32 | R33: 0600-0700 | S33: =SUM(C102:C105) -> 8 | T33: =SUM(D102:D105) -> 1 | U33: =SUM(E102:E105) -> 0 | V33: =SUM(F102:F105) -> 0 | W33: =SUM(G102:G105) -> 0 | X33: =SUM(H102:H105) -> 0 | Y33: =SUM(I102:I105) -> 0 | Z33: =SUM(J102:J105) -> 0 | ... AF33: =SUM(P102:P105) -> 27
B34: 13.00 - 13.15 | C34: 4 | D34: 0 | E34: 0 | F34: 3 | G34: 0 | H34: 0 | I34: 0 | J34: 0 | K34: 0 | L34: 0 | M34: 22 | N34: 0 | O34: =SUM(C34:L34,N34) -> 7 | P34: =SUM(C34:N34) -> 29 | R34: AM Peak Hr | S34: =MAX(S10:S12) -> 17 | T34: =MAX(T10:T12) -> 2 | U34: =MAX(U10:U12) -> 1 | V34: =MAX(V10:V12) -> 2 | W34: =MAX(W10:W12) -> 0 | X34: =MAX(X10:X12) -> 0 | Y34: =MAX(Y10:Y12) -> 4 | Z34: =MAX(Z10:Z12) -> 1 | ... AF34: =MAX(AF10:AF12) -> 94
B35: 13.15 - 13.30 | C35: 2 | D35: 0 | E35: 1 | F35: 0 | G35: 0 | H35: 0 | I35: 1 | J35: 0 | K35: 0 | L35: 0 | M35: 18 | N35: 0 | O35: =SUM(C35:L35,N35) -> 4 | P35: =SUM(C35:N35) -> 22 | R35: IP Peak Hr | S35: =MAX(S13:S18) -> 39 | T35: =MAX(T13:T18) -> 5 | U35: =MAX(U13:U18) -> 5 | V35: =MAX(V13:V18) -> 7 | W35: =MAX(W13:W18) -> 0 | X35: =MAX(X13:X18) -> 1 | Y35: =MAX(Y13:Y18) -> 7 | Z35: =MAX(Z13:Z18) -> 3 | ... AF35: =MAX(AF13:AF18) -> 153
B36: 13.30 - 13.45 | C36: 7 | D36: 0 | E36: 1 | F36: 2 | G36: 0 | H36: 0 | I36: 0 | J36: 1 | K36: 1 | L36: 0 | M36: 32 | N36: 0 | O36: =SUM(C36:L36,N36) -> 12 | P36: =SUM(C36:N36) -> 44 | R36: PM Peak Hr | S36: =MAX(S19:S21) -> 33 | T36: =MAX(T19:T21) -> 4 | U36: =MAX(U19:U21) -> 5 | V36: =MAX(V19:V21) -> 4 | W36: =MAX(W19:W21) -> 2 | X36: =MAX(X19:X21) -> 0 | Y36: =MAX(Y19:Y21) -> 7 | Z36: =MAX(Z19:Z21) -> 2 | ... AF36: =MAX(AF19:AF21) -> 158
B37: 13.45 - 14.00 | C37: 3 | D37: 0 | E37: 1 | F37: 2 | G37: 0 | H37: 0 | I37: 0 | J37: 1 | K37: 1 | L37: 0 | M37: 13 | N37: 0 | O37: =SUM(C37:L37,N37) -> 8 | P37: =SUM(C37:N37) -> 21 | R37: AM Period | S37: =SUM(S10:S12) -> 24 | T37: =SUM(T10:T12) -> 3 | U37: =SUM(U10:U12) -> 2 | V37: =SUM(V10:V12) -> 6 | W37: =SUM(W10:W12) -> 0 | X37: =SUM(X10:X12) -> 0 | Y37: =SUM(Y10:Y12) -> 4 | Z37: =SUM(Z10:Z12) -> 1 | ... AF37: =SUM(AF10:AF12) -> 115
B38: 14.00 - 14.15 | C38: 8 | D38: 2 | E38: 0 | F38: 0 | G38: 0 | H38: 0 | I38: 1 | J38: 0 | K38: 0 | L38: 0 | M38: 45 | N38: 0 | O38: =SUM(C38:L38,N38) -> 11 | P38: =SUM(C38:N38) -> 56 | R38: IP Period | S38: =SUM(S13:S18) -> 127 | T38: =SUM(T13:T18) -> 12 | U38: =SUM(U13:U18) -> 17 | V38: =SUM(V13:V18) -> 22 | W38: =SUM(W13:W18) -> 0 | X38: =SUM(X13:X18) -> 1 | Y38: =SUM(Y13:Y18) -> 23 | Z38: =SUM(Z13:Z18) -> 11 | ... AF38: =SUM(AF13:AF18) -> 724
B39: 14.15 - 14.30 | C39: 1 | D39: 0 | E39: 1 | F39: 0 | G39: 0 | H39: 0 | I39: 1 | J39: 0 | K39: 0 | L39: 0 | M39: 33 | N39: 0 | O39: =SUM(C39:L39,N39) -> 3 | P39: =SUM(C39:N39) -> 36 | R39: PM Period | S39: =SUM(S19:S21) -> 79 | T39: =SUM(T19:T21) -> 7 | U39: =SUM(U19:U21) -> 10 | V39: =SUM(V19:V21) -> 8 | W39: =SUM(W19:W21) -> 2 | X39: =SUM(X19:X21) -> 0 | Y39: =SUM(Y19:Y21) -> 10 | Z39: =SUM(Z19:Z21) -> 3 | ... AF39: =SUM(AF19:AF21) -> 312
B40: 14.30 - 14.45 | C40: 4 | D40: 0 | E40: 1 | F40: 0 | G40: 0 | H40: 0 | I40: 4 | J40: 0 | K40: 0 | L40: 0 | M40: 18 | N40: 0 | O40: =SUM(C40:L40,N40) -> 9 | P40: =SUM(C40:N40) -> 27 | R40: 12 Hours | S40: =SUM(S10:S21) -> 230 | T40: =SUM(T10:T21) -> 22 | U40: =SUM(U10:U21) -> 29 | V40: =SUM(V10:V21) -> 36 | W40: =SUM(W10:W21) -> 2 | X40: =SUM(X10:X21) -> 1 | Y40: =SUM(Y10:Y21) -> 37 | Z40: =SUM(Z10:Z21) -> 15 | ... AF40: =SUM(AF10:AF21) -> 1151
B41: 14.45 - 15.00 | C41: 4 | D41: 0 | E41: 0 | F41: 0 | G41: 0 | H41: 0 | I41: 1 | J41: 1 | K41: 0 | L41: 0 | M41: 20 | N41: 0 | O41: =SUM(C41:L41,N41) -> 6 | P41: =SUM(C41:N41) -> 26 | R41: 24 Hrs/ADT | S41: =SUM(S10:S33) -> 316 | T41: =SUM(T10:T33) -> 33 | U41: =SUM(U10:U33) -> 42 | V41: =SUM(V10:V33) -> 44 | W41: =SUM(W10:W33) -> 2 | X41: =SUM(X10:X33) -> 1 | Y41: =SUM(Y10:Y33) -> 45 | Z41: =SUM(Z10:Z33) -> 18 | ... AF41: =SUM(AF10:AF33) -> 1590
B42: 15.00 - 15.15 | C42: 2 | D42: 0 | E42: 0 | F42: 0 | G42: 0 | H42: 0 | I42: 1 | J42: 0 | K42: 0 | L42: 0 | M42: 15 | N42: 0 | O42: =SUM(C42:L42,N42) -> 3 | P42: =SUM(C42:N42) -> 18 | R42: NEF | S42: =S41/S40 -> 1.373913 | T42: =T41/T40 -> 1.5 | U42: =U41/U40 -> 1.4482759 | V42: =V41/V40 -> 1.2222222 | W42: =W41/W40 -> 1 | X42: =X41/X40 -> 1 | Y42: =Y41/Y40 -> 1.2162162 | Z42: =Z41/Z40 -> 1.2 | ... AF42: =AF41/AF40 -> 1.3814075
...

Sheet 27.10 KYENJOJO-HOIMA
B1: Consultancy services for Preparation of Expressway Development Master Plan (EDMP) for Uganda
B2: MANUAL CLASSIFIED COUNT (MCC)
B3: ROAD NAME: | C3: ='25.10 KYENJOJO-HOIMA'!C3:G3 -> MCC - C4 - STN108 - HOIMA ROAD
C5: Date | D5: 27.10.19 | F5: Location | G5: ='25.10 KYENJOJO-HOIMA'!G5:H5 -> KYENJOJO | J5: Surveyor | K5: ='25.10 KYENJOJO-HOIMA'!K5:L5 -> OLOYA FELIX
C6: Dir. From | D6: ='25.10 KYENJOJO-HOIMA'!D6:E6 -> KYENJOJO | F6: Dir. To | G6: ='25.10 KYENJOJO-HOIMA'!G6:H6 -> HOIMA | J6: Supervisor | K6: ='25.10 KYENJOJO-HOIMA'!K6:L6 -> FELIX
B8: Time / Veh Type | R8: SUMMARY TRAFFIC VOLUMES
C9: 1. Car | D9: 2. Station Wagon | E9: 3. Pickups | F9: 4. Minibus, matatu | G9: 5. Medium bus | H9: 6. Large Bus | I9: 7. Light Truck | J9: 8. Medium Truck | K9: 9. Heavy truck | L9: 10. Truck Trailer | M9: 11. Motor cycles | N9: 12. Tractors | O9: Total Excl M/Cycles | P9: Total All | R9: Time | S9: 1. Car | T9: 2. Station Wagon | U9: 3. Pickups | V9: 4. Minibus, matatu | W9: 5. Medium bus | X9: 6. Large Bus | Y9: 7. Light Truck | Z9: 8. Medium Truck | AA9: 9. Heavy truck | AB9: 10. Truck Trailer | AC9: 11. Motorcycles | AD9: 12. Tractors, Graders | AE9: Total Excl M/ Cycles | AF9: Total All
B10: 07.00 - 07.15 | C10: 1 | D10: 0 | E10: 0 | F10: 0 | G10: 0 | H10: 0 | I10: 1 | J10: 1 | K10: 1 | L10: 1 | M10: 4 | N10: 0 | O10: =SUM(C10:L10,N10) -> 5 | P10: =SUM(C10:N10) -> 9 | R10: 0700-0800 | S10: =SUM(C10:C13) -> 5 | T10: =SUM(D10:D13) -> 0 | U10: =SUM(E10:E13) -> 0 | V10: =SUM(F10:F13) -> 1 | W10: =SUM(G10:G13) -> 0 | X10: =SUM(H10:H13) -> 0 | Y10: =SUM(I10:I13) -> 1 | Z10: =SUM(J10:J13) -> 1 | ... AF10: =SUM(P10:P13) -> 55
B11: 07.15 - 07.30 | C11: 3 | D11: 0 | E11: 0 | F11: 0 | G11: 0 | H11: 0 | I11: 0 | J11: 0 | K11: 0 | L11: 0 | M11: 12 | N11: 0 | O11: =SUM(C11:L11,N11) -> 3 | P11: =SUM(C11:N11) -> 15 | R11: 0800-0900 | S11: =SUM(C14:C17) -> 13 | T11: =SUM(D14:D17) -> 0 | U11: =SUM(E14:E17) -> 2 | V11: =SUM(F14:F17) -> 2 | W11: =SUM(G14:G17) -> 0 | X11: =SUM(H14:H17) -> 0 | Y11: =SUM(I14:I17) -> 2 | Z11: =SUM(J14:J17) -> 5 | ... AF11: =SUM(P14:P17) -> 133
B12: 07.30 - 07.45 | C12: 0 | D12: 0 | E12: 0 | F12: 0 | G12: 0 | H12: 0 | I12: 0 | J12: 0 | K12: 0 | L12: 0 | M12: 9 | N12: 0 | O12: =SUM(C12:L12,N12) -> 0 | P12: =SUM(C12:N12) -> 9 | R12: 0900-1000 | S12: =SUM(C18:C21) -> 18 | T12: =SUM(D18:D21) -> 1 | U12: =SUM(E18:E21) -> 2 | V12: =SUM(F18:F21) -> 0 | W12: =SUM(G18:G21) -> 0 | X12: =SUM(H18:H21) -> 0 | Y12: =SUM(I18:I21) -> 3 | Z12: =SUM(J18:J21) -> 3 | ... AF12: =SUM(P18:P21) -> 175
B13: 07.45 - 08.00 | C13: 1 | D13: 0 | E13: 0 | F13: 1 | G13: 0 | H13: 0 | I13: 0 | J13: 0 | K13: 0 | L13: 0 | M13: 20 | N13: 0 | O13: =SUM(C13:L13,N13) -> 2 | P13: =SUM(C13:N13) -> 22 | R13: 1000-1100 | S13: =SUM(C22:C25) -> 17 | T13: =SUM(D22:D25) -> 2 | U13: =SUM(E22:E25) -> 4 | V13: =SUM(F22:F25) -> 2 | W13: =SUM(G22:G25) -> 0 | X13: =SUM(H22:H25) -> 0 | Y13: =SUM(I22:I25) -> 4 | Z13: =SUM(J22:J25) -> 2 | ... AF13: =SUM(P22:P25) -> 207
B14: 08.00 - 08.15 | C14: 0 | D14: 0 | E14: 0 | F14: 1 | G14: 0 | H14: 0 | I14: 0 | J14: 0 | K14: 0 | L14: 1 | M14: 27 | N14: 0 | O14: =SUM(C14:L14,N14) -> 2 | P14: =SUM(C14:N14) -> 29 | R14: 1100-1200 | S14: =SUM(C26:C29) -> 36 | T14: =SUM(D26:D29) -> 0 | U14: =SUM(E26:E29) -> 4 | V14: =SUM(F26:F29) -> 0 | W14: =SUM(G26:G29) -> 0 | X14: =SUM(H26:H29) -> 0 | Y14: =SUM(I26:I29) -> 4 | Z14: =SUM(J26:J29) -> 3 | ... AF14: =SUM(P26:P29) -> 248
