Workbook

Sheet 22.07 Ndeeba-Nyanama
B1: Consultancy services for Preparation of Expressway Development Master Plan (EDMP) for Uganda
B2: MANUAL CLASSIFIED COUNT (MCC)
B3: ROAD NAME: | C3: MCC - C1 - STN04 - WERAGA ROAD
C5: Date | D5: 22.07.19 | F5: Location | G5: Golden Mille Hotel | J5: Surveyor | K5: Steven Dan
C6: Dir. From | D6: Ndeeba | F6: Dir. To | G6: Nyanama | J6: Supervisor | K6: Denis
B8: Time / Veh Type | R8: SUMMARY TRAFFIC VOLUMES
C9: 1. Car | D9: 2. Station Wagon | E9: 3. Pickups | F9: 4. Minibus, matatu | G9: 5. Medium bus | H9: 6. Large Bus | I9: 7. Light Truck | J9: 8. Medium Truck | K9: 9. Heavy truck | L9: 10. Truck Trailer | M9: 11. Motor cycles | N9: 12. Tractors | O9: Total Excl M/Cycles | P9: Total All | R9: Time | S9: 1. Car | T9: 2. Station Wagon | U9: 3. Pickups | V9: 4. Minibus, matatu | W9: 5. Medium bus | X9: 6. Large Bus | Y9: 7. Light Truck | Z9: 8. Medium Truck | AA9: 9. Heavy truck | AB9: 10. Truck Trailer | AC9: 11. Motorcycles | AD9: 12. Tractors, Graders | AE9: Total Excl M/ Cycles | AF9: Total All
B10: 07.00 - 07.15 | C10: 11 | D10: 2 | E10: 1 | F10: 3 | G10: 0 | H10: 0 | I10: 0 | J10: 0 | K10: 0 | L10: 0 | M10: 20 | N10: 0 | O10: =SUM(C10:L10,N10) -> 17 | P10: =SUM(C10:N10) -> 37 | R10: 0700-0800 | S10: =SUM(C10:C13) -> 52 | T10: =SUM(D10:D13) -> 6 | U10: =SUM(E10:E13) -> 3 | V10: =SUM(F10:F13) -> 13 | W10: =SUM(G10:G13) -> 0 | X10: =SUM(H10:H13) -> 0 | Y10: =SUM(I10:I13) -> 3 | Z10: =SUM(J10:J13) -> 0 | ... AF10: =SUM(P10:P13) -> 393
B11: 07.15 - 07.30 | C11: 17 | D11: 2 | E11: 0 | F11: 4 | G11: 0 | H11: 0 | I11: 0 | J11: 0 | K11: 0 | L11: 0 | M11: 107 | N11: 0 | O11: =SUM(C11:L11,N11) -> 23 | P11: =SUM(C11:N11) -> 130 | R11: 0800-0900 | S11: =SUM(C14:C17) -> 66 | T11: =SUM(D14:D17) -> 5 | U11: =SUM(E14:E17) -> 15 | V11: =SUM(F14:F17) -> 51 | W11: =SUM(G14:G17) -> 0 | X11: =SUM(H14:H17) -> 0 | Y11: =SUM(I14:I17) -> 1 | Z11: =SUM(J14:J17) -> 1 | ... AF11: =SUM(P14:P17) -> 760
B12: 07.30 - 07.45 | C12: 13 | D12: 0 | E12: 1 | F12: 3 | G12: 0 | H12: 0 | I12: 0 | J12: 0 | K12: 0 | L12: 0 | M12: 65 | N12: 0 | O12: =SUM(C12:L12,N12) -> 17 | P12: =SUM(C12:N12) -> 82 | R12: 0900-1000 | S12: =SUM(C18:C21) -> 65 | T12: =SUM(D18:D21) -> 0 | U12: =SUM(E18:E21) -> 2 | V12: =SUM(F18:F21) -> 34 | W12: =SUM(G18:G21) -> 1 | X12: =SUM(H18:H21) -> 0 | Y12: =SUM(I18:I21) -> 18 | Z12: =SUM(J18:J21) -> 3 | ... AF12: =SUM(P18:P21) -> 636
B13: 07.45 - 08.00 | C13: 11 | D13: 2 | E13: 1 | F13: 3 | G13: 0 | H13: 0 | I13: 3 | J13: 0 | K13: 0 | L13: 0 | M13: 124 | N13: 0 | O13: =SUM(C13:L13,N13) -> 20 | P13: =SUM(C13:N13) -> 144 | R13: 1000-1100 | S13: =SUM(C22:C25) -> 94 | T13: =SUM(D22:D25) -> 9 | U13: =SUM(E22:E25) -> 6 | V13: =SUM(F22:F25) -> 31 | W13: =SUM(G22:G25) -> 1 | X13: =SUM(H22:H25) -> 0 | Y13: =SUM(I22:I25) -> 12 | Z13: =SUM(J22:J25) -> 5 | ... AF13: =SUM(P22:P25) -> 652
B14: 08.00 - 08.15 | C14: 15 | D14: 2 | E14: 6 | F14: 21 | G14: 0 | H14: 0 | I14: 0 | J14: 0 | K14: 0 | L14: 0 | M14: 140 | N14: 0 | O14: =SUM(C14:L14,N14) -> 44 | P14: =SUM(C14:N14) -> 184 | R14: 1100-1200 | S14: =SUM(C26:C29) -> 97 | T14: =SUM(D26:D29) -> 2 | U14: =SUM(E26:E29) -> 8 | V14: =SUM(F26:F29) -> 25 | W14: =SUM(G26:G29) -> 1 | X14: =SUM(H26:H29) -> 1 | Y14: =SUM(I26:I29) -> 11 | Z14: =SUM(J26:J29) -> 2 | ... AF14: =SUM(P26:P29) -> 552
B15: 08.15 - 08.30 | C15: 20 | D15: 1 | E15: 1 | F15: 10 | G15: 0 | H15: 0 | I15: 0 | J15: 1 | K15: 0 | L15: 0 | M15: 140 | N15: 0 | O15: =SUM(C15:L15,N15) -> 33 | P15: =SUM(C15:N15) -> 173 | R15: 1200-1300 | S15: =SUM(C30:C33) -> 123 | T15: =SUM(D30:D33) -> 9 | U15: =SUM(E30:E33) -> 11 | V15: =SUM(F30:F33) -> 21 | W15: =SUM(G30:G33) -> 0 | X15: =SUM(H30:H33) -> 0 | Y15: =SUM(I30:I33) -> 10 | Z15: =SUM(J30:J33) -> 6 | ... AF15: =SUM(P30:P33) -> 672
B16: 08.30 - 08.45 | C16: 18 | D16: 2 | E16: 6 | F16: 7 | G16: 0 | H16: 0 | I16: 0 | J16: 0 | K16: 0 | L16: 0 | M16: 155 | N16: 0 | O16: =SUM(C16:L16,N16) -> 33 | P16: =SUM(C16:N16) -> 188 | R16: 1300-1400 | S16: =SUM(C34:C37) -> 110 | T16: =SUM(D34:D37) -> 8 | U16: =SUM(E34:E37) -> 14 | V16: =SUM(F34:F37) -> 33 | W16: =SUM(G34:G37) -> 1 | X16: =SUM(H34:H37) -> 0 | Y16: =SUM(I34:I37) -> 4 | Z16: =SUM(J34:J37) -> 2 | ... AF16: =SUM(P34:P37) -> 633
B17: 08.45 - 9.00 | C17: 13 | D17: 0 | E17: 2 | F17: 13 | G17: 0 | H17: 0 | I17: 1 | J17: 0 | K17: 1 | L17: 0 | M17: 185 | N17: 0 | O17: =SUM(C17:L17,N17) -> 30 | P17: =SUM(C17:N17) -> 215 | R17: 1400-1500 | S17: =SUM(C38:C41) -> 124 | T17: =SUM(D38:D41) -> 4 | U17: =SUM(E38:E41) -> 13 | V17: =SUM(F38:F41) -> 18 | W17: =SUM(G38:G41) -> 1 | X17: =SUM(H38:H41) -> 0 | Y17: =SUM(I38:I41) -> 13 | Z17: =SUM(J38:J41) -> 2 | ... AF17: =SUM(P38:P41) -> 464
B18: 09.00 - 09.15 | C18: 19 | D18: 0 | E18: 2 | F18: 7 | G18: 0 | H18: 0 | I18: 3 | J18: 0 | K18: 1 | L18: 0 | M18: 141 | N18: 0 | O18: =SUM(C18:L18,N18) -> 32 | P18: =SUM(C18:N18) -> 173 | R18: 1500-1600 | S18: =SUM(C42:C45) -> 136 | T18: =SUM(D42:D45) -> 7 | U18: =SUM(E42:E45) -> 8 | V18: =SUM(F42:F45) -> 26 | W18: =SUM(G42:G45) -> 1 | X18: =SUM(H42:H45) -> 1 | Y18: =SUM(I42:I45) -> 21 | Z18: =SUM(J42:J45) -> 2 | ... AF18: =SUM(P42:P45) -> 353
B19: 09.15 - 09.30 | C19: 12 | D19: 0 | E19: 0 | F19: 9 | G19: 1 | H19: 0 | I19: 4 | J19: 0 | K19: 2 | L19: 1 | M19: 125 | N19: 0 | O19: =SUM(C19:L19,N19) -> 29 | P19: =SUM(C19:N19) -> 154 | R19: 1600-1700 | S19: =SUM(C46:C49) -> 225 | T19: =SUM(D46:D49) -> 9 | U19: =SUM(E46:E49) -> 8 | V19: =SUM(F46:F49) -> 36 | W19: =SUM(G46:G49) -> 5 | X19: =SUM(H46:H49) -> 0 | Y19: =SUM(I46:I49) -> 15 | Z19: =SUM(J46:J49) -> 3 | ... AF19: =SUM(P46:P49) -> 672
B20: 09.30 - 09.45 | C20: 21 | D20: 0 | E20: 0 | F20: 7 | G20: 0 | H20: 0 | I20: 5 | J20: 2 | K20: 0 | L20: 1 | M20: 130 | N20: 0 | O20: =SUM(C20:L20,N20) -> 36 | P20: =SUM(C20:N20) -> 166 | R20: 1700-1800 | S20: =SUM(C50:C53) -> 228 | T20: =SUM(D50:D53) -> 4 | U20: =SUM(E50:E53) -> 7 | V20: =SUM(F50:F53) -> 59 | W20: =SUM(G50:G53) -> 0 | X20: =SUM(H50:H53) -> 0 | Y20: =SUM(I50:I53) -> 8 | Z20: =SUM(J50:J53) -> 1 | ... AF20: =SUM(P50:P53) -> 682
B21: 09.45 - 10.00 | C21: 13 | D21: 0 | E21: 0 | F21: 11 | G21: 0 | H21: 0 | I21: 6 | J21: 1 | K21: 0 | L21: 0 | M21: 112 | N21: 0 | O21: =SUM(C21:L21,N21) -> 31 | P21: =SUM(C21:N21) -> 143 | R21: 1800-1900 | S21: =SUM(C54:C57) -> 424 | T21: =SUM(D54:D57) -> 43 | U21: =SUM(E54:E57) -> 22 | V21: =SUM(F54:F57) -> 129 | W21: =SUM(G54:G57) -> 1 | X21: =SUM(H54:H57) -> 0 | Y21: =SUM(I54:I57) -> 18 | Z21: =SUM(J54:J57) -> 4 | ... AF21: =SUM(P54:P57) -> 1236
B22: 10.00 - 10.15 | C22: 18 | D22: 3 | E22: 1 | F22: 6 | G22: 1 | H22: 0 | I22: 5 | J22: 2 | K22: 0 | L22: 0 | M22: 138 | N22: 0 | O22: =SUM(C22:L22,N22) -> 36 | P22: =SUM(C22:N22) -> 174 | R22: AM Peak Hr | S22: =MAX(S10:S12) -> 66 | T22: =MAX(T10:T12) -> 6 | U22: =MAX(U10:U12) -> 15 | V22: =MAX(V10:V12) -> 51 | W22: =MAX(W10:W12) -> 1 | X22: =MAX(X10:X12) -> 0 | Y22: =MAX(Y10:Y12) -> 18 | Z22: =MAX(Z10:Z12) -> 3 | ... AF22: =MAX(AF10:AF12) -> 760
B23: 10.15 - 10.30 | C23: 28 | D23: 4 | E23: 2 | F23: 7 | G23: 0 | H23: 0 | I23: 1 | J23: 3 | K23: 1 | L23: 1 | M23: 120 | N23: 0 | O23: =SUM(C23:L23,N23) -> 47 | P23: =SUM(C23:N23) -> 167 | R23: IP Peak Hr | S23: =MAX(S13:S18) -> 136 | T23: =MAX(T13:T18) -> 9 | U23: =MAX(U13:U18) -> 14 | V23: =MAX(V13:V18) -> 33 | W23: =MAX(W13:W18) -> 1 | X23: =MAX(X13:X18) -> 1 | Y23: =MAX(Y13:Y18) -> 21 | Z23: =MAX(Z13:Z18) -> 6 | ... AF23: =MAX(AF13:AF18) -> 672
B24: 10.30 - 10.45 | C24: 25 | D24: 0 | E24: 3 | F24: 8 | G24: 0 | H24: 0 | I24: 2 | J24: 0 | K24: 0 | L24: 0 | M24: 138 | N24: 0 | O24: =SUM(C24:L24,N24) -> 38 | P24: =SUM(C24:N24) -> 176 | R24: PM Peak Hr | S24: =MAX(S19:S21) -> 424 | T24: =MAX(T19:T21) -> 43 | U24: =MAX(U19:U21) -> 22 | V24: =MAX(V19:V21) -> 129 | W24: =MAX(W19:W21) -> 5 | X24: =MAX(X19:X21) -> 0 | Y24: =MAX(Y19:Y21) -> 18 | Z24: =MAX(Z19:Z21) -> 4 | ... AF24: =MAX(AF19:AF21) -> 1236
B25: 10.45 - 11.00 | C25: 23 | D25: 2 | E25: 0 | F25: 10 | G25: 0 | H25: 0 | I25: 4 | J25: 0 | K25: 1 | L25: 0 | M25: 95 | N25: 0 | O25: =SUM(C25:L25,N25) -> 40 | P25: =SUM(C25:N25) -> 135 | R25: AM Period | S25: =SUM(S10:S12) -> 183 | T25: =SUM(T10:T12) -> 11 | U25: =SUM(U10:U12) -> 20 | V25: =SUM(V10:V12) -> 98 | W25: =SUM(W10:W12) -> 1 | X25: =SUM(X10:X12) -> 0 | Y25: =SUM(Y10:Y12) -> 22 | Z25: =SUM(Z10:Z12) -> 4 | ... AF25: =SUM(AF10:AF12) -> 1789
B26: 11.00 - 11.15 | C26: 31 | D26: 0 | E26: 3 | F26: 6 | G26: 0 | H26: 0 | I26: 3 | J26: 1 | K26: 0 | L26: 0 | M26: 100 | N26: 0 | O26: =SUM(C26:L26,N26) -> 44 | P26: =SUM(C26:N26) -> 144 | R26: IP Period | S26: =SUM(S13:S18) -> 684 | T26: =SUM(T13:T18) -> 39 | U26: =SUM(U13:U18) -> 60 | V26: =SUM(V13:V18) -> 154 | W26: =SUM(W13:W18) -> 5 | X26: =SUM(X13:X18) -> 2 | Y26: =SUM(Y13:Y18) -> 71 | Z26: =SUM(Z13:Z18) -> 19 | ... AF26: =SUM(AF13:AF18) -> 3326
B27: 11.15 - 11.30 | C27: 20 | D27: 0 | E27: 2 | F27: 5 | G27: 1 | H27: 1 | I27: 4 | J27: 1 | K27: 0 | L27: 0 | M27: 105 | N27: 0 | O27: =SUM(C27:L27,N27) -> 34 | P27: =SUM(C27:N27) -> 139 | R27: PM Period | S27: =SUM(S19:S21) -> 877 | T27: =SUM(T19:T21) -> 56 | U27: =SUM(U19:U21) -> 37 | V27: =SUM(V19:V21) -> 224 | W27: =SUM(W19:W21) -> 6 | X27: =SUM(X19:X21) -> 0 | Y27: =SUM(Y19:Y21) -> 41 | Z27: =SUM(Z19:Z21) -> 8 | ... AF27: =SUM(AF19:AF21) -> 2590
B28: 11.30 - 11.45 | C28: 22 | D28: 2 | E28: 2 | F28: 9 | G28: 0 | H28: 0 | I28: 3 | J28: 0 | K28: 1 | L28: 0 | M28: 93 | N28: 0 | O28: =SUM(C28:L28,N28) -> 39 | P28: =SUM(C28:N28) -> 132 | R28: 12 Hours | S28: =SUM(S10:S21) -> 1744 | T28: =SUM(T10:T21) -> 106 | U28: =SUM(U10:U21) -> 117 | V28: =SUM(V10:V21) -> 476 | W28: =SUM(W10:W21) -> 12 | X28: =SUM(X10:X21) -> 2 | Y28: =SUM(Y10:Y21) -> 134 | Z28: =SUM(Z10:Z21) -> 31 | ... AF28: =SUM(AF10:AF21) -> 7705
B29: 11.45 - 12.00 | C29: 24 | D29: 0 | E29: 1 | F29: 5 | G29: 0 | H29: 0 | I29: 1 | J29: 0 | K29: 1 | L29: 0 | M29: 105 | N29: 0 | O29: =SUM(C29:L29,N29) -> 32 | P29: =SUM(C29:N29) -> 137
B30: 12.00 - 12.15 | C30: 33 | D30: 2 | E30: 4 | F30: 8 | G30: 0 | H30: 0 | I30: 4 | J30: 4 | K30: 1 | L30: 0 | M30: 125 | N30: 0 | O30: =SUM(C30:L30,N30) -> 56 | P30: =SUM(C30:N30) -> 181
B31: 12.15 - 12.30 | C31: 33 | D31: 2 | E31: 2 | F31: 3 | G31: 0 | H31: 0 | I31: 4 | J31: 0 | K31: 1 | L31: 1 | M31: 118 | N31: 0 | O31: =SUM(C31:L31,N31) -> 46 | P31: =SUM(C31:N31) -> 164
B32: 12.30 - 12.45 | C32: 37 | D32: 1 | E32: 1 | F32: 6 | G32: 0 | H32: 0 | I32: 1 | J32: 1 | K32: 0 | L32: 0 | M32: 131 | N32: 0 | O32: =SUM(C32:L32,N32) -> 47 | P32: =SUM(C32:N32) -> 178
B33: 12.45 - 13.00 | C33: 20 | D33: 4 | E33: 4 | F33: 4 | G33: 0 | H33: 0 | I33: 1 | J33: 1 | K33: 0 | L33: 0 | M33: 115 | N33: 0 | O33: =SUM(C33:L33,N33) -> 34 | P33: =SUM(C33:N33) -> 149
B34: 13.00 - 13.15 | C34: 17 | D34: 0 | E34: 2 | F34: 6 | G34: 0 | H34: 0 | I34: 1 | J34: 1 | K34: 0 | L34: 0 | M34: 105 | N34: 0 | O34: =SUM(C34:L34,N34) -> 27 | P34: =SUM(C34:N34) -> 132
B35: 13.15 - 13.30 | C35: 32 | D35: 4 | E35: 7 | F35: 8 | G35: 0 | H35: 0 | I35: 2 | J35: 1 | K35: 0 | L35: 0 | M35: 110 | N35: 0 | O35: =SUM(C35:L35,N35) -> 54 | P35: =SUM(C35:N35) -> 164
B36: 13.30 - 13.45 | C36: 28 | D36: 2 | E36: 0 | F36: 7 | G36: 0 | H36: 0 | I36: 1 | J36: 0 | K36: 0 | L36: 1 | M36: 140 | N36: 0 | O36: =SUM(C36:L36,N36) -> 39 | P36: =SUM(C36:N36) -> 179
B37: 13.45 - 14.00 | C37: 33 | D37: 2 | E37: 5 | F37: 12 | G37: 1 | H37: 0 | I37: 0 | J37: 0 | K37: 0 | L37: 0 | M37: 105 | N37: 0 | O37: =SUM(C37:L37,N37) -> 53 | P37: =SUM(C37:N37) -> 158
B38: 14.00 - 14.15 | C38: 26 | D38: 0 | E38: 3 | F38: 2 | G38: 0 | H38: 0 | I38: 1 | J38: 0 | K38: 1 | L38: 0 | M38: 80 | N38: 0 | O38: =SUM(C38:L38,N38) -> 33 | P38: =SUM(C38:N38) -> 113
B39: 14.15 - 14.30 | C39: 46 | D39: 1 | E39: 4 | F39: 3 | G39: 0 | H39: 0 | I39: 2 | J39: 0 | K39: 1 | L39: 0 | M39: 75 | N39: 0 | O39: =SUM(C39:L39,N39) -> 57 | P39: =SUM(C39:N39) -> 132
B40: 14.30 - 14.45 | C40: 16 | D40: 2 | E40: 3 | F40: 5 | G40: 1 | H40: 0 | I40: 4 | J40: 2 | K40: 3 | L40: 0 | M40: 79 | N40: 0 | O40: =SUM(C40:L40,N40) -> 36 | P40: =SUM(C40:N40) -> 115
... B57: 18.45 - 19.00 | C57: 125 | D57: 2 | E57: 1 | F57: 27 | G57: 0 | H57: 0 | I57: 4 | J57: 1 | K57: 0 | L57: 0 | M57: 185 | N57: 0 | O57: =SUM(C57:L57,N57) -> 160 | P57: =SUM(C57:N57) -> 345
B58: Totals | C58: =SUM(C10:C57) -> 1744 | D58: =SUM(D10:D57) -> 106 | E58: =SUM(E10:E57) -> 117 | F58: =SUM(F10:F57) -> 476 | G58: =SUM(G10:G57) -> 12 | H58: =SUM(H10:H57) -> 2 | I58: =SUM(I10:I57) -> 134 | J58: =SUM(J10:J57) -> 31 | ... P58: =SUM(P10:P57) -> 7705
...

Sheet 22.07 Nyanama-Ndeeba
B1: Consultancy services for Preparation of Expressway Development Master Plan (EDMP) for Uganda
B2: MANUAL CLASSIFIED COUNT (MCC)
B3: ROAD NAME: | C3: ='22.07 Ndeeba-Nyanama'!C3:G3 -> MCC - C1 - STN04 - WERAGA ROAD
C5: Date | D5: ='22.07 Ndeeba-Nyanama'!D5 -> 22.07.19 | F5: Location | G5: ='22.07 Ndeeba-Nyanama'!G5:H5 -> Golden Mille Hotel | J5: Surveyor | K5: Walter
C6: Dir. From | D6: Nyanama | F6: Dir. To | G6: Ndeeba | J6: Supervisor | K6: ='22.07 Ndeeba-Nyanama'!K6:L6 -> Denis
B8: Time / Veh Type | R8: SUMMARY TRAFFIC VOLUMES
C9: 1. Car | D9: 2. Station Wagon | E9: 3. Pickups | F9: 4. Minibus, matatu | G9: 5. Medium bus | H9: 6. Large Bus | I9: 7. Light Truck | J9: 8. Medium Truck | K9: 9. Heavy truck | L9: 10. Truck Trailer | M9: 11. Motor cycles | N9: 12. Tractors | O9: Total Excl M/Cycles | P9: Total All | R9: Time | S9: 1. Car | T9: 2. Station Wagon | U9: 3. Pickups | V9: 4. Minibus, matatu | W9: 5. Medium bus | X9: 6. Large Bus | Y9: 7. Light Truck | Z9: 8. Medium Truck | AA9: 9. Heavy truck | AB9: 10. Truck Trailer | AC9: 11. Motorcycles | AD9: 12. Tractors, Graders | AE9: Total Excl M/ Cycles | AF9: Total All
B10: 07.00 - 07.15 | C10: 24 | D10: 2 | E10: 1 | F10: 10 | G10: 0 | H10: 0 | I10: 0 | J10: 0 | K10: 0 | L10: 0 | M10: 20 | N10: 0 | O10: =SUM(C10:L10,N10) -> 37 | P10: =SUM(C10:N10) -> 57 | R10: 0700-0800 | S10: =SUM(C10:C13) -> 160 | T10: =SUM(D10:D13) -> 15 | U10: =SUM(E10:E13) -> 13 | V10: =SUM(F10:F13) -> 75 | W10: =SUM(G10:G13) -> 0 | X10: =SUM(H10:H13) -> 0 | Y10: =SUM(I10:I13) -> 2 | Z10: =SUM(J10:J13) -> 4 | ... AF10: =SUM(P10:P13) -> 469
B11: 07.15 - 07.30 | C11: 38 | D11: 3 | E11: 3 | F11: 13 | G11: 0 | H11: 0 | I11: 0 | J11: 1 | K11: 1 | L11: 0 | M11: 35 | N11: 0 | O11: =SUM(C11:L11,N11) -> 59 | P11: =SUM(C11:N11) -> 94 | R11: 0800-0900 | S11: =SUM(C14:C17) -> 279 | T11: =SUM(D14:D17) -> 24 | U11: =SUM(E14:E17) -> 18 | V11: =SUM(F14:F17) -> 146 | W11: =SUM(G14:G17) -> 1 | X11: =SUM(H14:H17) -> 0 | Y11: =SUM(I14:I17) -> 7 | Z11: =SUM(J14:J17) -> 9 | ... AF11: =SUM(P14:P17) -> 984
B12: 07.30 - 07.45 | C12: 37 | D12: 6 | E12: 3 | F12: 16 | G12: 0 | H12: 0 | I12: 1 | J12: 2 | K12: 1 | L12: 0 | M12: 36 | N12: 0 | O12: =SUM(C12:L12,N12) -> 66 | P12: =SUM(C12:N12) -> 102 | R12: 0900-1000 | S12: =SUM(C18:C21) -> 200 | T12: =SUM(D18:D21) -> 31 | U12: =SUM(E18:E21) -> 18 | V12: =SUM(F18:F21) -> 63 | W12: =SUM(G18:G21) -> 2 | X12: =SUM(H18:H21) -> 0 | Y12: =SUM(I18:I21) -> 12 | Z12: =SUM(J18:J21) -> 5 | ... AF12: =SUM(P18:P21) -> 770
B13: 07.45 - 08.00 | C13: 61 | D13: 4 | E13: 6 | F13: 36 | G13: 0 | H13: 0 | I13: 1 | J13: 1 | K13: 1 | L13: 0 | M13: 106 | N13: 0 | O13: =SUM(C13:L13,N13) -> 110 | P13: =SUM(C13:N13) -> 216 | R13: 1000-1100 | S13: =SUM(C22:C25) -> 160 | T13: =SUM(D22:D25) -> 16 | U13: =SUM(E22:E25) -> 17 | V13: =SUM(F22:F25) -> 37 | W13: =SUM(G22:G25) -> 0 | X13: =SUM(H22:H25) -> 0 | Y13: =SUM(I22:I25) -> 14 | Z13: =SUM(J22:J25) -> 6 | ... AF13: =SUM(P22:P25) -> 667
B14: 08.00 - 08.15 | C14: 80 | D14: 7 | E14: 6 | F14: 37 | G14: 0 | H14: 0 | I14: 3 | J14: 2 | K14: 2 | L14: 0 | M14: 103 | N14: 0 | O14: =SUM(C14:L14,N14) -> 137 | P14: =SUM(C14:N14) -> 240 | R14: 1100-1200 | S14: =SUM(C26:C29) -> 143 | T14: =SUM(D26:D29) -> 24 | U14: =SUM(E26:E29) -> 17 | V14: =SUM(F26:F29) -> 35 | W14: =SUM(G26:G29) -> 3 | X14: =SUM(H26:H29) -> 0 | Y14: =SUM(I26:I29) -> 19 | Z14: =SUM(J26:J29) -> 4 | ... AF14: =SUM(P26:P29) -> 548
B15: 08.15 - 08.30 | C15: 70 | D15: 6 | E15: 4 | F15: 51 | G15: 1 | H15: 0 | I15: 0 | J15: 5 | K15: 0 | L15: 0 | M15: 143 | N15: 0 | O15: =SUM(C15:L15,N15) -> 137 | P15: =SUM(C15:N15) -> 280 | R15: 1200-1300 | S15: =SUM(C30:C33) -> 152 | T15: =SUM(D30:D33) -> 11 | U15: =SUM(E30:E33) -> 12 | V15: =SUM(F30:F33) -> 26 | W15: =SUM(G30:G33) -> 1 | X15: =SUM(H30:H33) -> 0 | Y15: =SUM(I30:I33) -> 15 | Z15: =SUM(J30:J33) -> 8 | ... AF15: =SUM(P30:P33) -> 540
B16: 08.30 - 08.45 | C16: 68 | D16: 7 | E16: 3 | F16: 38 | G16: 0 | H16: 0 | I16: 2 | J16: 2 | K16: 0 | L16: 0 | M16: 148 | N16: 0 | O16: =SUM(C16:L16,N16) -> 120 | P16: =SUM(C16:N16) -> 268 | R16: 1300-1400 | S16: =SUM(C34:C37) -> 143 | T16: =SUM(D34:D37) -> 9 | U16: =SUM(E34:E37) -> 10 | V16: =SUM(F34:F37) -> 34 | W16: =SUM(G34:G37) -> 1 | X16: =SUM(H34:H37) -> 0 | Y16: =SUM(I34:I37) -> 10 | Z16: =SUM(J34:J37) -> 4 | ... AF16: =SUM(P34:P37) -> 504
B17: 08.45 - 9.00 | C17: 61 | D17: 4 | E17: 5 | F17: 20 | G17: 0 | H17: 0 | I17: 2 | J17: 0 | K17: 1 | L17: 0 | M17: 103 | N17: 0 | O17: =SUM(C17:L17,N17) -> 93 | P17: =SUM(C17:N17) -> 196 | R17: 1400-1500 | S17: =SUM(C38:C41) -> 120 | T17: =SUM(D38:D41) -> 18 | U17: =SUM(E38:E41) -> 18 | V17: =SUM(F38:F41) -> 34 | W17: =SUM(G38:G41) -> 0 | X17: =SUM(H38:H41) -> 0 | Y17: =SUM(I38:I41) -> 11 | Z17: =SUM(J38:J41) -> 3 | ... AF17: =SUM(P38:P41) -> 461
B18: 09.00 - 09.15 | C18: 48 | D18: 10 | E18: 4 | F18: 13 | G18: 2 | H18: 0 | I18: 2 | J18: 2 | K18: 0 | L18: 0 | M18: 126 | N18: 0 | O18: =SUM(C18:L18,N18) -> 81 | P18: =SUM(C18:N18) -> 207 | R18: 1500-1600 | S18: =SUM(C42:C45) -> 109 | T18: =SUM(D42:D45) -> 8 | U18: =SUM(E42:E45) -> 14 | V18: =SUM(F42:F45) -> 19 | W18: =SUM(G42:G45) -> 0 | X18: =SUM(H42:H45) -> 0 | Y18: =SUM(I42:I45) -> 7 | Z18: =SUM(J42:J45) -> 1 | ... AF18: =SUM(P42:P45) -> 339
B19: 09.15 - 09.30 | C19: 43 | D19: 8 | E19: 4 | F19: 17 | G19: 0 | H19: 0 | I19: 3 | J19: 0 | K19: 0 | L19: 0 | M19: 90 | N19: 0 | O19: =SUM(C19:L19,N19) -> 75 | P19: =SUM(C19:N19) -> 165 | R19: 1600-1700 | S19: =SUM(C46:C49) -> 128 | T19: =SUM(D46:D49) -> 22 | U19: =SUM(E46:E49) -> 14 | V19: =SUM(F46:F49) -> 23 | W19: =SUM(G46:G49) -> 0 | X19: =SUM(H46:H49) -> 0 | Y19: =SUM(I46:I49) -> 13 | Z19: =SUM(J46:J49) -> 2 | ... AF19: =SUM(P46:P49) -> 475
B20: 09.30 - 09.45 | C20: 55 | D20: 8 | E20: 3 | F20: 13 | G20: 0 | H20: 0 | I20: 2 | J20: 3 | K20: 0 | L20: 0 | M20: 115 | N20: 0 | O20: =SUM(C20:L20,N20) -> 84 | P20: =SUM(C20:N20) -> 199 | R20: 1700-1800 | S20: =SUM(C50:C53) -> 104 | T20: =SUM(D50:D53) -> 14 | U20: =SUM(E50:E53) -> 15 | V20: =SUM(F50:F53) -> 25 | W20: =SUM(G50:G53) -> 1 | X20: =SUM(H50:H53) -> 0 | Y20: =SUM(I50:I53) -> 8 | Z20: =SUM(J50:J53) -> 1 | ... AF20: =SUM(P50:P53) -> 404
B21: 09.45 - 10.00 | C21: 54 | D21: 5 | E21: 7 | F21: 20 | G21: 0 | H21: 0 | I21: 5 | J21: 0 | K21: 0 | L21: 0 | M21: 108 | N21: 0 | O21: =SUM(C21:L21,N21) -> 91 | P21: =SUM(C21:N21) -> 199 | R21: 1800-1900 | S21: =SUM(C54:C57) -> 97 | T21: =SUM(D54:D57) -> 11 | U21: =SUM(E54:E57) -> 12 | V21: =SUM(F54:F57) -> 28 | W21: =SUM(G54:G57) -> 3 | X21: =SUM(H54:H57) -> 2 | Y21: =SUM(I54:I57) -> 7 | Z21: =SUM(J54:J57) -> 4 | ... AF21: =SUM(P54:P57) -> 504
B22: 10.00 - 10.15 | C22: 37 | D22: 4 | E22: 2 | F22: 6 | G22: 0 | H22: 0 | I22: 5 | J22: 1 | K22: 1 | L22: 0 | M22: 93 | N22: 0 | O22: =SUM(C22:L22,N22) -> 56 | P22: =SUM(C22:N22) -> 149 | R22: AM Peak Hr | S22: =MAX(S10:S12) -> 279 | T22: =MAX(T10:T12) -> 31 | U22: =MAX(U10:U12) -> 18 | V22: =MAX(V10:V12) -> 146 | W22: =MAX(W10:W12) -> 2 | X22: =MAX(X10:X12) -> 0 | Y22: =MAX(Y10:Y12) -> 12 | Z22: =MAX(Z10:Z12) -> 9 | ... AF22: =MAX(AF10:AF12) -> 984
B23: 10.15 - 10.30 | C23: 47 | D23: 5 | E23: 5 | F23: 8 | G23: 0 | H23: 0 | I23: 2 | J23: 2 | K23: 0 | L23: 0 | M23: 112 | N23: 0 | O23: =SUM(C23:L23,N23) -> 69 | P23: =SUM(C23:N23) -> 181 | R23: IP Peak Hr | S23: =MAX(S13:S18) -> 160 | T23: =MAX(T13:T18) -> 24 | U23: =MAX(U13:U18) -> 18 | V23: =MAX(V13:V18) -> 37 | W23: =MAX(W13:W18) -> 3 | X23: =MAX(X13:X18) -> 0 | Y23: =MAX(Y13:Y18) -> 19 | Z23: =MAX(Z13:Z18) -> 8 | ... AF23: =MAX(AF13:AF18) -> 667
B24: 10.30 - 10.45 | C24: 41 | D24: 4 | E24: 6 | F24: 13 | G24: 0 | H24: 0 | I24: 1 | J24: 2 | K24: 0 | L24: 0 | M24: 109 | N24: 0 | O24: =SUM(C24:L24,N24) -> 67 | P24: =SUM(C24:N24) -> 176 | R24: PM Peak Hr | S24: =MAX(S19:S21) -> 128 | T24: =MAX(T19:T21) -> 22 | U24: =MAX(U19:U21) -> 15 | V24: =MAX(V19:V21) -> 28 | W24: =MAX(W19:W21) -> 3 | X24: =MAX(X19:X21) -> 2 | Y24: =MAX(Y19:Y21) -> 13 | Z24: =MAX(Z19:Z21) -> 4 | ... AF24: =MAX(AF19:AF21) -> 504
B25: 10.45 - 11.00 | C25: 35 | D25: 3 | E25: 4 | F25: 10 | G25: 0 | H25: 0 | I25: 6 | J25: 1 | K25: 0 | L25: 0 | M25: 102 | N25: 0 | O25: =SUM(C25:L25,N25) -> 59 | P25: =SUM(C25:N25) -> 161 | R25: AM Period | S25: =SUM(S10:S12) -> 639 | T25: =SUM(T10:T12) -> 70 | U25: =SUM(U10:U12) -> 49 | V25: =SUM(V10:V12) -> 284 | W25: =SUM(W10:W12) -> 3 | X25: =SUM(X10:X12) -> 0 | Y25: =SUM(Y10:Y12) -> 21 | Z25: =SUM(Z10:Z12) -> 18 | ... AF25: =SUM(AF10:AF12) -> 2223
B26: 11.00 - 11.15 | C26: 43 | D26: 4 | E26: 5 | F26: 8 | G26: 1 | H26: 0 | I26: 5 | J26: 0 | K26: 0 | L26: 0 | M26: 85 | N26: 0 | O26: =SUM(C26:L26,N26) -> 66 | P26: =SUM(C26:N26) -> 151 | R26: IP Period | S26: =SUM(S13:S18) -> 827 | T26: =SUM(T13:T18) -> 86 | U26: =SUM(U13:U18) -> 88 | V26: =SUM(V13:V18) -> 185 | W26: =SUM(W13:W18) -> 5 | X26: =SUM(X13:X18) -> 0 | Y26: =SUM(Y13:Y18) -> 76 | Z26: =SUM(Z13:Z18) -> 26 | ... AF26: =SUM(AF13:AF18) -> 3059
B27: 11.15 - 11.30 | C27: 34 | D27: 6 | E27: 3 | F27: 7 | G27: 0 | H27: 0 | I27: 6 | J27: 2 | K27: 1 | L27: 0 | M27: 59 | N27: 0 | O27: =SUM(C27:L27,N27) -> 59 | P27: =SUM(C27:N27) -> 118 | R27: PM Period | S27: =SUM(S19:S21) -> 329 | T27: =SUM(T19:T21) -> 47 | U27: =SUM(U19:U21) -> 41 | V27: =SUM(V19:V21) -> 76 | W27: =SUM(W19:W21) -> 4 | X27: =SUM(X19:X21) -> 2 | Y27: =SUM(Y19:Y21) -> 28 | Z27: =SUM(Z19:Z21) -> 7 | ... AF27: =SUM(AF19:AF21) -> 1383
B28: 11.30 - 11.45 | C28: 38 | D28: 6 | E28: 3 | F28: 12 | G28: 1 | H28: 0 | I28: 7 | J28: 2 | K28: 1 | L28: 1 | M28: 75 | N28: 0 | O28: =SUM(C28:L28,N28) -> 71 | P28: =SUM(C28:N28) -> 146 | R28: 12 Hours | S28: =SUM(S10:S21) -> 1795 | T28: =SUM(T10:T21) -> 203 | U28: =SUM(U10:U21) -> 178 | V28: =SUM(V10:V21) -> 545 | W28: =SUM(W10:W21) -> 12 | X28: =SUM(X10:X21) -> 2 | Y28: =SUM(Y10:Y21) -> 125 | Z28: =SUM(Z10:Z21) -> 51 | ... AF28: =SUM(AF10:AF21) -> 6665
B29: 11.45 - 12.00 | C29: 28 | D29: 8 | E29: 6 | F29: 8 | G29: 1 | H29: 0 | I29: 1 | J29: 0 | K29: 0 | L29: 0 | M29: 81 | N29: 0 | O29: =SUM(C29:L29,N29) -> 52 | P29: =SUM(C29:N29) -> 133
B30: 12.00 - 12.15 | C30: 33 | D30: 5 | E30: 4 | F30: 5 | G30: 0 | H30: 0 | I30: 5 | J30: 3 | K30: 0 | L30: 0 | M30: 63 | N30: 0 | O30: =SUM(C30:L30,N30) -> 55 | P30: =SUM(C30:N30) -> 118
B31: 12.15 - 12.30 | C31: 46 | D31: 2 | E31: 2 | F31: 5 | G31: 0 | H31: 0 | I31: 4 | J31: 1 | K31: 0 | L31: 0 | M31: 87 | N31: 0 | O31: =SUM(C31:L31,N31) -> 60 | P31: =SUM(C31:N31) -> 147
B32: 12.30 - 12.45 | C32: 28 | D32: 1 | E32: 2 | F32: 5 | G32: 1 | H32: 0 | I32: 3 | J32: 3 | K32: 0 | L32: 0 | M32: 60 | N32: 0 | O32: =SUM(C32:L32,N32) -> 43 | P32: =SUM(C32:N32) -> 103
B33: 12.45 - 13.00 | C33: 45 | D33: 3 | E33: 4 | F33: 11 | G33: 0 | H33: 0 | I33: 3 | J33: 1 | K33: 0 | L33: 0 | M33: 105 | N33: 0 | O33: =SUM(C33:L33,N33) -> 67 | P33: =SUM(C33:N33) -> 172
B34: 13.00 - 13.15 | C34: 27 | D34: 1 | E34: 3 | F34: 9 | G34: 0 | H34: 0 | I34: 3 | J34: 0 | K34: 0 | L34: 0 | M34: 68 | N34: 0 | O34: =SUM(C34:L34,N34) -> 43 | P34: =SUM(C34:N34) -> 111
B35: 13.15 - 13.30 | C35: 27 | D35: 5 | E35: 1 | F35: 8 | G35: 0 | H35: 0 | I35: 2 | J35: 2 | K35: 0 | L35: 0 | M35: 65 | N35: 0 | O35: =SUM(C35:L35,N35) -> 45 | P35: =SUM(C35:N35) -> 110
B36: 13.30 - 13.45 | C36: 42 | D36: 1 | E36: 1 | F36: 10 | G36: 1 | H36: 0 | I36: 2 | J36: 1 | K36: 0 | L36: 0 | M36: 87 | N36: 0 | O36: =SUM(C36:L36,N36) -> 58 | P36: =SUM(C36:N36) -> 145
B37: 13.45 - 14.00 | C37: 47 | D37: 2 | E37: 5 | F37: 7 | G37: 0 | H37: 0 | I37: 3 | J37: 1 | K37: 1 | L37: 0 | M37: 72 | N37: 0 | O37: =SUM(C37:L37,N37) -> 66 | P37: =SUM(C37:N37) -> 138
B38: 14.00 - 14.15 | C38: 26 | D38: 7 | E38: 0 | F38: 10 | G38: 0 | H38: 0 | I38: 2 | J38: 1 | K38: 0 | L38: 0 | M38: 87 | N38: 0 | O38: =SUM(C38:L38,N38) -> 46 | P38: =SUM(C38:N38) -> 133
B39: 14.15 - 14.30 | C39: 30 | D39: 2 | E39: 6 | F39: 6 | G39: 0 | H39: 0 | I39: 1 | J39: 2 | K39: 0 | L39: 0 | M39: 80 | N39: 0 | O39: =SUM(C39:L39,N39) -> 47 | P39: =SUM(C39:N39) -> 127
B40: 14.30 - 14.45 | C40: 27 | D40: 2 | E40: 5 | F40: 9 | G40: 0 | H40: 0 | I40: 3 | J40: 0 | K40: 0 | L40: 0 | M40: 60 | N40: 0 | O40: =SUM(C40:L40,N40) -> 46 | P40: =SUM(C40:N40) -> 106
... B57: 18.45 - 19.00 | C57: 28 | D57: 2 | E57: 1 | F57: 8 | G57: 2 | H57: 0 | I57: 3 | J57: 0 | K57: 1 | L57: 0 | M57: 90 | N57: 0 | O57: =SUM(C57:L57,N57) -> 45 | P57: =SUM(C57:N57) -> 135
B58: Totals | C58: =SUM(C10:C57) -> 1795 | D58: =SUM(D10:D57) -> 203 | E58: =SUM(E10:E57) -> 178 | F58: =SUM(F10:F57) -> 545 | G58: =SUM(G10:G57) -> 12 | H58: =SUM(H10:H57) -> 2 | I58: =SUM(I10:I57) -> 125 | J58: =SUM(J10:J57) -> 51 | ... P58: =SUM(P10:P57) -> 6665
...

Sheet 23.07 Ndeeba-Nyanama
B1: Consultancy services for Preparation of Expressway Development Master Plan (EDMP) for Uganda
B2: MANUAL CLASSIFIED COUNT (MCC)
B3: ROAD NAME: | C3: ='22.07 Ndeeba-Nyanama'!C3:G3 -> MCC - C1 - STN04 - WERAGA ROAD
C5: Date | D5: 23.07.19 | F5: Location | G5: ='22.07 Ndeeba-Nyanama'!G5:H5 -> Golden Mille Hotel | J5: Surveyor | K5: Steven Dan
C6: Dir. From | D6: ='22.07 Ndeeba-Nyanama'!D6:E6 -> Ndeeba | F6: Dir. To | G6: ='22.07 Ndeeba-Nyanama'!G6:H6 -> Nyanama | J6: Supervisor | K6: ='22.07 Ndeeba-Nyanama'!K6:L6 -> Denis
B8: Time / Veh Type | R8: SUMMARY TRAFFIC VOLUMES
C9: 1. Car | D9: 2. Station Wagon | E9: 3. Pickups | F9: 4. Minibus, matatu | G9: 5. Medium bus | H9: 6. Large Bus | I9: 7. Light Truck | J9: 8. Medium Truck | K9: 9. Heavy truck | L9: 10. Truck Trailer | M9: 11. Motor cycles | N9: 12. Tractors | O9: Total Excl M/Cycles | P9: Total All | R9: Time | S9: 1. Car | T9: 2. Station Wagon | U9: 3. Pickups | V9: 4. Minibus, matatu | W9: 5. Medium bus | X9: 6. Large Bus | Y9: 7. Light Truck | Z9: 8. Medium Truck | AA9: 9. Heavy truck | AB9: 10. Truck Trailer | AC9: 11. Motorcycles | AD9: 12. Tractors, Graders | AE9: Total Excl M/ Cycles | AF9: Total All
B10: 07.00 - 07.15 | C10: 65 | D10: 3 | E10: 8 | F10: 39 | G10: 0 | H10: 0 | I10: 0 | J10: 0 | K10: 0 | L10: 0 | M10: 130 | N10: 0 | O10: =SUM(C10:L10,N10) -> 115 | P10: =SUM(C10:N10) -> 245 | R10: 0700-0800 | S10: =SUM(C10:C13) -> 220 | T10: =SUM(D10:D13) -> 5 | U10: =SUM(E10:E13) -> 20 | V10: =SUM(F10:F13) -> 102 | W10: =SUM(G10:G13) -> 1 | X10: =SUM(H10:H13) -> 0 | Y10: =SUM(I10:I13) -> 3 | Z10: =SUM(J10:J13) -> 3 | ... AF10: =SUM(P10:P13) -> 942
B11: 07.15 - 07.30 | C11: 70 | D11: 0 | E11: 6 | F11: 49 | G11: 0 | H11: 0 | I11: 1 | J11: 0 | K11: 0 | L11: 0 | M11: 140 | N11: 0 | O11: =SUM(C11:L11,N11) -> 126 | P11: =SUM(C11:N11) -> 266 | R11: 0800-0900 | S11: =SUM(C14:C17) -> 208 | T11: =SUM(D14:D17) -> 4 | U11: =SUM(E14:E17) -> 5 | V11: =SUM(F14:F17) -> 28 | W11: =SUM(G14:G17) -> 0 | X11: =SUM(H14:H17) -> 0 | Y11: =SUM(I14:I17) -> 6 | Z11: =SUM(J14:J17) -> 2 | ... AF11: =SUM(P14:P17) -> 762
B12: 07.30 - 07.45 | C12: 50 | D12: 2 | E12: 4 | F12: 5 | G12: 0 | H12: 0 | I12: 2 | J12: 1 | K12: 0 | L12: 0 | M12: 168 | N12: 0 | O12: =SUM(C12:L12,N12) -> 64 | P12: =SUM(C12:N12) -> 232 | R12: 0900-1000 | S12: =SUM(C18:C21) -> 194 | T12: =SUM(D18:D21) -> 5 | U12: =SUM(E18:E21) -> 18 | V12: =SUM(F18:F21) -> 33 | W12: =SUM(G18:G21) -> 3 | X12: =SUM(H18:H21) -> 1 | Y12: =SUM(I18:I21) -> 8 | Z12: =SUM(J18:J21) -> 4 | ... AF12: =SUM(P18:P21) -> 679
B13: 07.45 - 08.00 | C13: 35 | D13: 0 | E13: 2 | F13: 9 | G13: 1 | H13: 0 | I13: 0 | J13: 2 | K13: 0 | L13: 0 | M13: 150 | N13: 0 | O13: =SUM(C13:L13,N13) -> 49 | P13: =SUM(C13:N13) -> 199 | R13: 1000-1100 | S13: =SUM(C22:C25) -> 182 | T13: =SUM(D22:D25) -> 7 | U13: =SUM(E22:E25) -> 12 | V13: =SUM(F22:F25) -> 30 | W13: =SUM(G22:G25) -> 0 | X13: =SUM(H22:H25) -> 0 | Y13: =SUM(I22:I25) -> 9 | Z13: =SUM(J22:J25) -> 3 | ... AF13: =SUM(P22:P25) -> 800
B14: 08.00 - 08.15 | C14: 55 | D14: 1 | E14: 2 | F14: 7 | G14: 0 | H14: 0 | I14: 1 | J14: 0 | K14: 0 | L14: 0 | M14: 155 | N14: 0 | O14: =SUM(C14:L14,N14) -> 66 | P14: =SUM(C14:N14) -> 221 | R14: 1100-1200 | S14: =SUM(C26:C29) -> 186 | T14: =SUM(D26:D29) -> 8 | U14: =SUM(E26:E29) -> 11 | V14: =SUM(F26:F29) -> 18 | W14: =SUM(G26:G29) -> 0 | X14: =SUM(H26:H29) -> 1 | Y14: =SUM(I26:I29) -> 12 | Z14: =SUM(J26:J29) -> 8 | ... AF14: =SUM(P26:P29) -> 637
B15: 08.15 - 08.30 | C15: 61 | D15: 0 | E15: 1 | F15: 8 | G15: 0 | H15: 0 | I15: 4 | J15: 0 | K15: 0 | L15: 0 | M15: 133 | N15: 0 | O15: =SUM(C15:L15,N15) -> 74 | P15: =SUM(C15:N15) -> 207 | R15: 1200-1300 | S15: =SUM(C30:C33) -> 260 | T15: =SUM(D30:D33) -> 4 | U15: =SUM(E30:E33) -> 20 | V15: =SUM(F30:F33) -> 34 | W15: =SUM(G30:G33) -> 3 | X15: =SUM(H30:H33) -> 0 | Y15: =SUM(I30:I33) -> 15 | Z15: =SUM(J30:J33) -> 6 | ... AF15: =SUM(P30:P33) -> 779
B16: 08.30 - 08.45 | C16: 42 | D16: 3 | E16: 2 | F16: 4 | G16: 0 | H16: 0 | I16: 1 | J16: 0 | K16: 1 | L16: 0 | M16: 105 | N16: 0 | O16: =SUM(C16:L16,N16) -> 53 | P16: =SUM(C16:N16) -> 158 | R16: 1300-1400 | S16: =SUM(C34:C37) -> 329 | T16: =SUM(D34:D37) -> 8 | U16: =SUM(E34:E37) -> 15 | V16: =SUM(F34:F37) -> 21 | W16: =SUM(G34:G37) -> 0 | X16: =SUM(H34:H37) -> 0 | Y16: =SUM(I34:I37) -> 9 | Z16: =SUM(J34:J37) -> 7 | ... AF16: =SUM(P34:P37) -> 770
B17: 08.45 - 9.00 | C17: 50 | D17: 0 | E17: 0 | F17: 9 | G17: 0 | H17: 0 | I17: 0 | J17: 2 | K17: 0 | L17: 0 | M17: 115 | N17: 0 | O17: =SUM(C17:L17,N17) -> 61 | P17: =SUM(C17:N17) -> 176 | R17: 1400-1500 | S17: =SUM(C38:C41) -> 260 | T17: =SUM(D38:D41) -> 5 | U17: =SUM(E38:E41) -> 13 | V17: =SUM(F38:F41) -> 19 | W17: =SUM(G38:G41) -> 0 | X17: =SUM(H38:H41) -> 0 | Y17: =SUM(I38:I41) -> 5 | Z17: =SUM(J38:J41) -> 3 | ... AF17: =SUM(P38:P41) -> 811
B18: 09.00 - 09.15 | C18: 34 | D18: 0 | E18: 4 | F18: 6 | G18: 2 | H18: 0 | I18: 2 | J18: 1 | K18: 0 | L18: 0 | M18: 75 | N18: 0 | O18: =SUM(C18:L18,N18) -> 49 | P18: =SUM(C18:N18) -> 124 | R18: 1500-1600 | S18: =SUM(C42:C45) -> 220 | T18: =SUM(D42:D45) -> 0 | U18: =SUM(E42:E45) -> 9 | V18: =SUM(F42:F45) -> 12 | W18: =SUM(G42:G45) -> 0 | X18: =SUM(H42:H45) -> 0 | Y18: =SUM(I42:I45) -> 14 | Z18: =SUM(J42:J45) -> 5 | ... AF18: =SUM(P42:P45) -> 612
B19: 09.15 - 09.30 | C19: 31 | D19: 2 | E19: 2 | F19: 7 | G19: 0 | H19: 1 | I19: 2 | J19: 0 | K19: 0 | L19: 0 | M19: 87 | N19: 0 | O19: =SUM(C19:L19,N19) -> 45 | P19: =SUM(C19:N19) -> 132 | R19: 1600-1700 | S19: =SUM(C46:C49) -> 251 | T19: =SUM(D46:D49) -> 7 | U19: =SUM(E46:E49) -> 14 | V19: =SUM(F46:F49) -> 24 | W19: =SUM(G46:G49) -> 4 | X19: =SUM(H46:H49) -> 0 | Y19: =SUM(I46:I49) -> 8 | Z19: =SUM(J46:J49) -> 5 | ... AF19: =SUM(P46:P49) -> 696
B20: 09.30 - 09.45 | C20: 60 | D20: 0 | E20: 1 | F20: 7 | G20: 1 | H20: 0 | I20: 3 | J20: 0 | K20: 0 | L20: 0 | M20: 101 | N20: 0 | O20: =SUM(C20:L20,N20) -> 72 | P20: =SUM(C20:N20) -> 173 | R20: 1700-1800 | S20: =SUM(C50:C53) -> 440 | T20: =SUM(D50:D53) -> 23 | U20: =SUM(E50:E53) -> 17 | V20: =SUM(F50:F53) -> 53 | W20: =SUM(G50:G53) -> 0 | X20: =SUM(H50:H53) -> 0 | Y20: =SUM(I50:I53) -> 22 | Z20: =SUM(J50:J53) -> 6 | ... AF20: =SUM(P50:P53) -> 1102
B21: 09.45 - 10.00 | C21: 69 | D21: 3 | E21: 11 | F21: 13 | G21: 0 | H21: 0 | I21: 1 | J21: 3 | K21: 0 | L21: 0 | M21: 150 | N21: 0 | O21: =SUM(C21:L21,N21) -> 100 | P21: =SUM(C21:N21) -> 250 | R21: 1800-1900 | S21: =SUM(C54:C57) -> 354 | T21: =SUM(D54:D57) -> 8 | U21: =SUM(E54:E57) -> 15 | V21: =SUM(F54:F57) -> 123 | W21: =SUM(G54:G57) -> 1 | X21: =SUM(H54:H57) -> 0 | Y21: =SUM(I54:I57) -> 18 | Z21: =SUM(J54:J57) -> 4 | ... AF21: =SUM(P54:P57) -> 1073
B22: 10.00 - 10.15 | C22: 79 | D22: 1 | E22: 4 | F22: 13 | G22: 0 | H22: 0 | I22: 1 | J22: 0 | K22: 0 | L22: 0 | M22: 169 | N22: 0 | O22: =SUM(C22:L22,N22) -> 98 | P22: =SUM(C22:N22) -> 267 | R22: AM Peak Hr | S22: =MAX(S10:S12) -> 220 | T22: =MAX(T10:T12) -> 5 | U22: =MAX(U10:U12) -> 20 | V22: =MAX(V10:V12) -> 102 | W22: =MAX(W10:W12) -> 3 | X22: =MAX(X10:X12) -> 1 | Y22: =MAX(Y10:Y12) -> 8 | Z22: =MAX(Z10:Z12) -> 4 | ... AF22: =MAX(AF10:AF12) -> 942
B23: 10.15 - 10.30 | C23: 47 | D23: 4 | E23: 4 | F23: 7 | G23: 0 | H23: 0 | I23: 3 | J23: 0 | K23: 0 | L23: 0 | M23: 140 | N23: 0 | O23: =SUM(C23:L23,N23) -> 65 | P23: =SUM(C23:N23) -> 205 | R23: IP Peak Hr | S23: =MAX(S13:S18) -> 329 | T23: =MAX(T13:T18) -> 8 | U23: =MAX(U13:U18) -> 20 | V23: =MAX(V13:V18) -> 34 | W23: =MAX(W13:W18) -> 3 | X23: =MAX(X13:X18) -> 1 | Y23: =MAX(Y13:Y18) -> 15 | Z23: =MAX(Z13:Z18) -> 8 | ... AF23: =MAX(AF13:AF18) -> 811
B24: 10.30 - 10.45 | C24: 30 | D24: 1 | E24: 2 | F24: 6 | G24: 0 | H24: 0 | I24: 4 | J24: 1 | K24: 0 | L24: 0 | M24: 138 | N24: 0 | O24: =SUM(C24:L24,N24) -> 44 | P24: =SUM(C24:N24) -> 182 | R24: PM Peak Hr | S24: =MAX(S19:S21) -> 440 | T24: =MAX(T19:T21) -> 23 | U24: =MAX(U19:U21) -> 17 | V24: =MAX(V19:V21) -> 123 | W24: =MAX(W19:W21) -> 4 | X24: =MAX(X19:X21) -> 0 | Y24: =MAX(Y19:Y21) -> 22 | Z24: =MAX(Z19:Z21) -> 6 | ... AF24: =MAX(AF19:AF21) -> 1102
B25: 10.45 - 11.00 | C25: 26 | D25: 1 | E25: 2 | F25: 4 | G25: 0 | H25: 0 | I25: 1 | J25: 2 | K25: 0 | L25: 0 | M25: 110 | N25: 0 | O25: =SUM(C25:L25,N25) -> 36 | P25: =SUM(C25:N25) -> 146 | R25: AM Period | S25: =SUM(S10:S12) -> 622 | T25: =SUM(T10:T12) -> 14 | U25: =SUM(U10:U12) -> 43 | V25: =SUM(V10:V12) -> 163 | W25: =SUM(W10:W12) -> 4 | X25: =SUM(X10:X12) -> 1 | Y25: =SUM(Y10:Y12) -> 17 | Z25: =SUM(Z10:Z12) -> 9 | ... AF25: =SUM(AF10:AF12) -> 2383
B26: 11.00 - 11.15 | C26: 32 | D26: 0 | E26: 3 | F26: 3 | G26: 0 | H26: 0 | I26: 2 | J26: 1 | K26: 1 | L26: 0 | M26: 125 | N26: 0 | O26: =SUM(C26:L26,N26) -> 42 | P26: =SUM(C26:N26) -> 167 | R26: IP Period | S26: =SUM(S13:S18) -> 1437 | T26: =SUM(T13:T18) -> 32 | U26: =SUM(U13:U18) -> 80 | V26: =SUM(V13:V18) -> 134 | W26: =SUM(W13:W18) -> 3 | X26: =SUM(X13:X18) -> 1 | Y26: =SUM(Y13:Y18) -> 64 | Z26: =SUM(Z13:Z18) -> 32 | ... AF26: =SUM(AF13:AF18) -> 4409
B27: 11.15 - 11.30 | C27: 56 | D27: 6 | E27: 2 | F27: 8 | G27: 0 | H27: 0 | I27: 6 | J27: 3 | K27: 0 | L27: 0 | M27: 95 | N27: 0 | O27: =SUM(C27:L27,N27) -> 81 | P27: =SUM(C27:N27) -> 176 | R27: PM Period | S27: =SUM(S19:S21) -> 1045 | T27: =SUM(T19:T21) -> 38 | U27: =SUM(U19:U21) -> 46 | V27: =SUM(V19:V21) -> 200 | W27: =SUM(W19:W21) -> 5 | X27: =SUM(X19:X21) -> 0 | Y27: =SUM(Y19:Y21) -> 48 | Z27: =SUM(Z19:Z21) -> 15 | ... AF27: =SUM(AF19:AF21) -> 2871
B28: 11.30 - 11.45 | C28: 45 | D28: 1 | E28: 3 | F28: 3 | G28: 0 | H28: 0 | I28: 2 | J28: 4 | K28: 2 | L28: 0 | M28: 80 | N28: 0 | O28: =SUM(C28:L28,N28) -> 60 | P28: =SUM(C28:N28) -> 140 | R28: 12 Hours | S28: =SUM(S10:S21) -> 3104 | T28: =SUM(T10:T21) -> 84 | U28: =SUM(U10:U21) -> 169 | V28: =SUM(V10:V21) -> 497 | W28: =SUM(W10:W21) -> 12 | X28: =SUM(X10:X21) -> 2 | Y28: =SUM(Y10:Y21) -> 129 | Z28: =SUM(Z10:Z21) -> 56 | ... AF28: =SUM(AF10:AF21) -> 9663
B29: 11.45 - 12.00 | C29: 53 | D29: 1 | E29: 3 | F29: 4 | G29: 0 | H29: 1 | I29: 2 | J29: 0 | K29: 0 | L29: 0 | M29: 90 | N29: 0 | O29: =SUM(C29:L29,N29) -> 64 | P29: =SUM(C29:N29) -> 154
B30: 12.00 - 12.15 | C30: 75 | D30: 0 | E30: 8 | F30: 11 | G30: 0 | H30: 0 | I30: 6 | J30: 3 | K30: 0 | L30: 0 | M30: 156 | N30: 0 | O30: =SUM(C30:L30,N30) -> 103 | P30: =SUM(C30:N30) -> 259
B31: 12.15 - 12.30 | C31: 45 | D31: 3 | E31: 6 | F31: 3 | G31: 0 | H31: 0 | I31: 7 | J31: 2 | K31: 0 | L31: 0 | M31: 100 | N31: 0 | O31: =SUM(C31:L31,N31) -> 66 | P31: =SUM(C31:N31) -> 166
B32: 12.30 - 12.45 | C32: 60 | D32: 0 | E32: 1 | F32: 6 | G32: 3 | H32: 0 | I32: 2 | J32: 1 | K32: 0 | L32: 0 | M32: 105 | N32: 0 | O32: =SUM(C32:L32,N32) -> 73 | P32: =SUM(C32:N32) -> 178
B33: 12.45 - 13.00 | C33: 80 | D33: 1 | E33: 5 | F33: 14 | G33: 0 | H33: 0 | I33: 0 | J33: 0 | K33: 1 | L33: 0 | M33: 75 | N33: 0 | O33: =SUM(C33:L33,N33) -> 101 | P33: =SUM(C33:N33) -> 176
B34: 13.00 - 13.15 | C34: 79 | D34: 3 | E34: 8 | F34: 3 | G34: 0 | H34: 0 | I34: 0 | J34: 4 | K34: 2 | L34: 1 | M34: 85 | N34: 0 | O34: =SUM(C34:L34,N34) -> 100 | P34: =SUM(C34:N34) -> 185
B35: 13.15 - 13.30 | C35: 75 | D35: 2 | E35: 1 | F35: 9 | G35: 0 | H35: 0 | I35: 0 | J35: 3 | K35: 0 | L35: 1 | M35: 110 | N35: 0 | O35: =SUM(C35:L35,N35) -> 91 | P35: =SUM(C35:N35) -> 201
B36: 13.30 - 13.45 | C36: 80 | D36: 2 | E36: 0 | F36: 1 | G36: 0 | H36: 0 | I36: 3 | J36: 0 | K36: 1 | L36: 0 | M36: 65 | N36: 0 | O36: =SUM(C36:L36,N36) -> 87 | P36: =SUM(C36:N36) -> 152
B37: 13.45 - 14.00 | C37: 95 | D37: 1 | E37: 6 | F37: 8 | G37: 0 | H37: 0 | I37: 6 | J37: 0 | K37: 0 | L37: 1 | M37: 115 | N37: 0 | O37: =SUM(C37:L37,N37) -> 117 | P37: =SUM(C37:N37) -> 232
B38: 14.00 - 14.15 | C38: 75 | D38: 1 | E38: 2 | F38: 5 | G38: 0 | H38: 0 | I38: 4 | J38: 0 | K38: 0 | L38: 0 | M38: 154 | N38: 0 | O38: =SUM(C38:L38,N38) -> 87 | P38: =SUM(C38:N38) -> 241
B39: 14.15 - 14.30 | C39: 80 | D39: 3 | E39: 4 | F39: 3 | G39: 0 | H39: 0 | I39: 1 | J39: 0 | K39: 1 | L39: 0 | M39: 150 | N39: 0 | O39: =SUM(C39:L39,N39) -> 92 | P39: =SUM(C39:N39) -> 242
B40: 14.30 - 14.45 | C40: 50 | D40: 1 | E40: 7 | F40: 4 | G40: 0 | H40: 0 | I40: 0 | J40: 1 | K40: 0 | L40: 1 | M40: 105 | N40: 0 | O40: =SUM(C40:L40,N40) -> 64 | P40: =SUM(C40:N40) -> 169
... B57: 18.45 - 19.00 | C57: 78 | D57: 0 | E57: 3 | F57: 53 | G57: 0 | H57: 0 | I57: 3 | J57: 2 | K57: 0 | L57: 0 | M57: 125 | N57: 0 | O57: =SUM(C57:L57,N57) -> 139 | P57: =SUM(C57:N57) -> 264
B58: Totals | C58: =SUM(C10:C57) -> 3104 | D58: =SUM(D10:D57) -> 84 | E58: =SUM(E10:E57) -> 169 | F58: =SUM(F10:F57) -> 497 | G58: =SUM(G10:G57) -> 12 | H58: =SUM(H10:H57) -> 2 | I58: =SUM(I10:I57) -> 129 | J58: =SUM(J10:J57) -> 56 | ... P58: =SUM(P10:P57) -> 9663
...

Sheet 23.07 Nyanama-Ndeeba
B1: Consultancy services for Preparation of Expressway Development Master Plan (EDMP) for Uganda
B2: MANUAL CLASSIFIED COUNT (MCC)
B3: ROAD NAME: | C3: ='22.07 Nyanama-Ndeeba'!C3:G3 -> MCC - C1 - STN04 - WERAGA ROAD
C5: Date | D5: ='23.07 Ndeeba-Nyanama'!D5 -> 23.07.19 | F5: Location | G5: ='22.07 Ndeeba-Nyanama'!G5:H5 -> Golden Mille Hotel | J5: Surveyor | K5: Walter
C6: Dir. From | D6: ='22.07 Nyanama-Ndeeba'!D6:E6 -> Nyanama | F6: Dir. To | G6: ='22.07 Nyanama-Ndeeba'!G6:H6 -> Ndeeba | J6: Supervisor | K6: ='22.07 Ndeeba-Nyanama'!K6:L6 -> Denis
B8: Time / Veh Type | R8: SUMMARY TRAFFIC VOLUMES
C9: 1. Car | D9: 2. Station Wagon | E9: 3. Pickups | F9: 4. Minibus, matatu | G9: 5. Medium bus | H9: 6. Large Bus | I9: 7. Light Truck | J9: 8. Medium Truck | K9: 9. Heavy truck | L9: 10. Truck Trailer | M9: 11. Motor cycles | N9: 12. Tractors | O9: Total Excl M/Cycles | P9: Total All | R9: Time | S9: 1. Car | T9: 2. Station Wagon | U9: 3. Pickups | V9: 4. Minibus, matatu | W9: 5. Medium bus | X9: 6. Large Bus | Y9: 7. Light Truck | Z9: 8. Medium Truck | AA9: 9. Heavy truck | AB9: 10. Truck Trailer | AC9: 11. Motorcycles | AD9: 12. Tractors, Graders | AE9: Total Excl M/ Cycles | AF9: Total All
B10: 07.00 - 07.15 | C10: 21 | D10: 5 | E10: 6 | F10: 12 | G10: 0 | H10: 0 | I10: 3 | J10: 2 | K10: 3 | L10: 0 | M10: 17 | N10: 0 | O10: =SUM(C10:L10,N10) -> 52 | P10: =SUM(C10:N10) -> 69 | R10: 0700-0800 | S10: =SUM(C10:C13) -> 222 | T10: =SUM(D10:D13) -> 29 | U10: =SUM(E10:E13) -> 26 | V10: =SUM(F10:F13) -> 121 | W10: =SUM(G10:G13) -> 1 | X10: =SUM(H10:H13) -> 0 | Y10: =SUM(I10:I13) -> 16 | Z10: =SUM(J10:J13) -> 4 | ... AF10: =SUM(P10:P13) -> 827
B11: 07.15 - 07.30 | C11: 60 | D11: 7 | E11: 6 | F11: 31 | G11: 1 | H11: 0 | I11: 3 | J11: 1 | K11: 0 | L11: 0 | M11: 112 | N11: 0 | O11: =SUM(C11:L11,N11) -> 109 | P11: =SUM(C11:N11) -> 221 | R11: 0800-0900 | S11: =SUM(C14:C17) -> 207 | T11: =SUM(D14:D17) -> 24 | U11: =SUM(E14:E17) -> 14 | V11: =SUM(F14:F17) -> 99 | W11: =SUM(G14:G17) -> 0 | X11: =SUM(H14:H17) -> 0 | Y11: =SUM(I14:I17) -> 11 | Z11: =SUM(J14:J17) -> 2 | ... AF11: =SUM(P14:P17) -> 783
B12: 07.30 - 07.45 | C12: 78 | D12: 9 | E12: 7 | F12: 44 | G12: 0 | H12: 0 | I12: 3 | J12: 1 | K12: 4 | L12: 0 | M12: 153 | N12: 0 | O12: =SUM(C12:L12,N12) -> 146 | P12: =SUM(C12:N12) -> 299 | R12: 0900-1000 | S12: =SUM(C18:C21) -> 182 | T12: =SUM(D18:D21) -> 27 | U12: =SUM(E18:E21) -> 22 | V12: =SUM(F18:F21) -> 49 | W12: =SUM(G18:G21) -> 1 | X12: =SUM(H18:H21) -> 1 | Y12: =SUM(I18:I21) -> 15 | Z12: =SUM(J18:J21) -> 2 | ... AF12: =SUM(P18:P21) -> 689
B13: 07.45 - 08.00 | C13: 63 | D13: 8 | E13: 7 | F13: 34 | G13: 0 | H13: 0 | I13: 7 | J13: 0 | K13: 2 | L13: 0 | M13: 117 | N13: 0 | O13: =SUM(C13:L13,N13) -> 121 | P13: =SUM(C13:N13) -> 238 | R13: 1000-1100 | S13: =SUM(C22:C25) -> 153 | T13: =SUM(D22:D25) -> 21 | U13: =SUM(E22:E25) -> 19 | V13: =SUM(F22:F25) -> 27 | W13: =SUM(G22:G25) -> 1 | X13: =SUM(H22:H25) -> 0 | Y13: =SUM(I22:I25) -> 10 | Z13: =SUM(J22:J25) -> 0 | ... AF13: =SUM(P22:P25) -> 566
B14: 08.00 - 08.15 | C14: 60 | D14: 5 | E14: 3 | F14: 35 | G14: 0 | H14: 0 | I14: 3 | J14: 0 | K14: 0 | L14: 0 | M14: 113 | N14: 0 | O14: =SUM(C14:L14,N14) -> 106 | P14: =SUM(C14:N14) -> 219 | R14: 1100-1200 | S14: =SUM(C26:C29) -> 132 | T14: =SUM(D26:D29) -> 10 | U14: =SUM(E26:E29) -> 18 | V14: =SUM(F26:F29) -> 28 | W14: =SUM(G26:G29) -> 2 | X14: =SUM(H26:H29) -> 0 | Y14: =SUM(I26:I29) -> 7 | Z14: =SUM(J26:J29) -> 9 | ... AF14: =SUM(P26:P29) -> 532
B15: 08.15 - 08.30 | C15: 58 | D15: 6 | E15: 2 | F15: 28 | G15: 0 | H15: 0 | I15: 4 | J15: 0 | K15: 0 | L15: 0 | M15: 103 | N15: 0 | O15: =SUM(C15:L15,N15) -> 98 | P15: =SUM(C15:N15) -> 201 | R15: 1200-1300 | S15: =SUM(C30:C33) -> 133 | T15: =SUM(D30:D33) -> 13 | U15: =SUM(E30:E33) -> 22 | V15: =SUM(F30:F33) -> 27 | W15: =SUM(G30:G33) -> 0 | X15: =SUM(H30:H33) -> 0 | Y15: =SUM(I30:I33) -> 13 | Z15: =SUM(J30:J33) -> 2 | ... AF15: =SUM(P30:P33) -> 549
B16: 08.30 - 08.45 | C16: 54 | D16: 5 | E16: 5 | F16: 23 | G16: 0 | H16: 0 | I16: 3 | J16: 1 | K16: 0 | L16: 0 | M16: 100 | N16: 0 | O16: =SUM(C16:L16,N16) -> 91 | P16: =SUM(C16:N16) -> 191 | R16: 1300-1400 | S16: =SUM(C34:C37) -> 109 | T16: =SUM(D34:D37) -> 20 | U16: =SUM(E34:E37) -> 13 | V16: =SUM(F34:F37) -> 22 | W16: =SUM(G34:G37) -> 0 | X16: =SUM(H34:H37) -> 0 | Y16: =SUM(I34:I37) -> 9 | Z16: =SUM(J34:J37) -> 2 | ... AF16: =SUM(P34:P37) -> 435
B17: 08.45 - 9.00 | C17: 35 | D17: 8 | E17: 4 | F17: 13 | G17: 0 | H17: 0 | I17: 1 | J17: 1 | K17: 0 | L17: 1 | M17: 109 | N17: 0 | O17: =SUM(C17:L17,N17) -> 63 | P17: =SUM(C17:N17) -> 172 | R17: 1400-1500 | S17: =SUM(C38:C41) -> 99 | T17: =SUM(D38:D41) -> 20 | U17: =SUM(E38:E41) -> 14 | V17: =SUM(F38:F41) -> 26 | W17: =SUM(G38:G41) -> 2 | X17: =SUM(H38:H41) -> 0 | Y17: =SUM(I38:I41) -> 6 | Z17: =SUM(J38:J41) -> 1 | ... AF17: =SUM(P38:P41) -> 416
B18: 09.00 - 09.15 | C18: 49 | D18: 7 | E18: 6 | F18: 16 | G18: 0 | H18: 1 | I18: 4 | J18: 0 | K18: 0 | L18: 0 | M18: 118 | N18: 0 | O18: =SUM(C18:L18,N18) -> 83 | P18: =SUM(C18:N18) -> 201 | R18: 1500-1600 | S18: =SUM(C42:C45) -> 113 | T18: =SUM(D42:D45) -> 15 | U18: =SUM(E42:E45) -> 9 | V18: =SUM(F42:F45) -> 17 | W18: =SUM(G42:G45) -> 0 | X18: =SUM(H42:H45) -> 0 | Y18: =SUM(I42:I45) -> 9 | Z18: =SUM(J42:J45) -> 6 | ... AF18: =SUM(P42:P45) -> 401
B19: 09.15 - 09.30 | C19: 47 | D19: 10 | E19: 7 | F19: 8 | G19: 1 | H19: 0 | I19: 2 | J19: 0 | K19: 0 | L19: 0 | M19: 87 | N19: 0 | O19: =SUM(C19:L19,N19) -> 75 | P19: =SUM(C19:N19) -> 162 | R19: 1600-1700 | S19: =SUM(C46:C49) -> 89 | T19: =SUM(D46:D49) -> 17 | U19: =SUM(E46:E49) -> 17 | V19: =SUM(F46:F49) -> 17 | W19: =SUM(G46:G49) -> 0 | X19: =SUM(H46:H49) -> 0 | Y19: =SUM(I46:I49) -> 5 | Z19: =SUM(J46:J49) -> 2 | ... AF19: =SUM(P46:P49) -> 399
B20: 09.30 - 09.45 | C20: 51 | D20: 5 | E20: 5 | F20: 6 | G20: 0 | H20: 0 | I20: 5 | J20: 1 | K20: 0 | L20: 0 | M20: 105 | N20: 0 | O20: =SUM(C20:L20,N20) -> 73 | P20: =SUM(C20:N20) -> 178 | R20: 1700-1800 | S20: =SUM(C50:C53) -> 133 | T20: =SUM(D50:D53) -> 28 | U20: =SUM(E50:E53) -> 15 | V20: =SUM(F50:F53) -> 35 | W20: =SUM(G50:G53) -> 1 | X20: =SUM(H50:H53) -> 0 | Y20: =SUM(I50:I53) -> 10 | Z20: =SUM(J50:J53) -> 2 | ... AF20: =SUM(P50:P53) -> 531
B21: 09.45 - 10.00 | C21: 35 | D21: 5 | E21: 4 | F21: 19 | G21: 0 | H21: 0 | I21: 4 | J21: 1 | K21: 0 | L21: 1 | M21: 79 | N21: 0 | O21: =SUM(C21:L21,N21) -> 69 | P21: =SUM(C21:N21) -> 148 | R21: 1800-1900 | S21: =SUM(C54:C57) -> 105 | T21: =SUM(D54:D57) -> 12 | U21: =SUM(E54:E57) -> 10 | V21: =SUM(F54:F57) -> 37 | W21: =SUM(G54:G57) -> 2 | X21: =SUM(H54:H57) -> 1 | Y21: =SUM(I54:I57) -> 6 | Z21: =SUM(J54:J57) -> 3 | ... AF21: =SUM(P54:P57) -> 497
B22: 10.00 - 10.15 | C22: 54 | D22: 3 | E22: 5 | F22: 9 | G22: 0 | H22: 0 | I22: 3 | J22: 0 | K22: 0 | L22: 0 | M22: 90 | N22: 0 | O22: =SUM(C22:L22,N22) -> 74 | P22: =SUM(C22:N22) -> 164 | R22: AM Peak Hr | S22: =MAX(S10:S12) -> 222 | T22: =MAX(T10:T12) -> 29 | U22: =MAX(U10:U12) -> 26 | V22: =MAX(V10:V12) -> 121 | W22: =MAX(W10:W12) -> 1 | X22: =MAX(X10:X12) -> 1 | Y22: =MAX(Y10:Y12) -> 16 | Z22: =MAX(Z10:Z12) -> 4 | ... AF22: =MAX(AF10:AF12) -> 827
B23: 10.15 - 10.30 | C23: 45 | D23: 10 | E23: 6 | F23: 7 | G23: 1 | H23: 0 | I23: 3 | J23: 0 | K23: 2 | L23: 0 | M23: 82 | N23: 0 | O23: =SUM(C23:L23,N23) -> 74 | P23: =SUM(C23:N23) -> 156 | R23: IP Peak Hr | S23: =MAX(S13:S18) -> 153 | T23: =MAX(T13:T18) -> 21 | U23: =MAX(U13:U18) -> 22 | V23: =MAX(V13:V18) -> 28 | W23: =MAX(W13:W18) -> 2 | X23: =MAX(X13:X18) -> 0 | Y23: =MAX(Y13:Y18) -> 13 | Z23: =MAX(Z13:Z18) -> 9 | ... AF23: =MAX(AF13:AF18) -> 566
B24: 10.30 - 10.45 | C24: 33 | D24: 2 | E24: 4 | F24: 4 | G24: 0 | H24: 0 | I24: 2 | J24: 0 | K24: 0 | L24: 0 | M24: 86 | N24: 0 | O24: =SUM(C24:L24,N24) -> 45 | P24: =SUM(C24:N24) -> 131 | R24: PM Peak Hr | S24: =MAX(S19:S21) -> 133 | T24: =MAX(T19:T21) -> 28 | U24: =MAX(U19:U21) -> 17 | V24: =MAX(V19:V21) -> 37 | W24: =MAX(W19:W21) -> 2 | X24: =MAX(X19:X21) -> 1 | Y24: =MAX(Y19:Y21) -> 10 | Z24: =MAX(Z19:Z21) -> 3 | ... AF24: =MAX(AF19:AF21) -> 531
B25: 10.45 - 11.00 | C25: 21 | D25: 6 | E25: 4 | F25: 7 | G25: 0 | H25: 0 | I25: 2 | J25: 0 | K25: 0 | L25: 0 | M25: 75 | N25: 0 | O25: =SUM(C25:L25,N25) -> 40 | P25: =SUM(C25:N25) -> 115 | R25: AM Period | S25: =SUM(S10:S12) -> 611 | T25: =SUM(T10:T12) -> 80 | U25: =SUM(U10:U12) -> 62 | V25: =SUM(V10:V12) -> 269 | W25: =SUM(W10:W12) -> 2 | X25: =SUM(X10:X12) -> 1 | Y25: =SUM(Y10:Y12) -> 42 | Z25: =SUM(Z10:Z12) -> 8 | ... AF25: =SUM(AF10:AF12) -> 2299
B26: 11.00 - 11.15 | C26: 26 | D26: 1 | E26: 7 | F26: 5 | G26: 1 | H26: 0 | I26: 3 | J26: 3 | K26: 0 | L26: 0 | M26: 74 | N26: 0 | O26: =SUM(C26:L26,N26) -> 46 | P26: =SUM(C26:N26) -> 120 | R26: IP Period | S26: =SUM(S13:S18) -> 739 | T26: =SUM(T13:T18) -> 99 | U26: =SUM(U13:U18) -> 95 | V26: =SUM(V13:V18) -> 147 | W26: =SUM(W13:W18) -> 5 | X26: =SUM(X13:X18) -> 0 | Y26: =SUM(Y13:Y18) -> 54 | Z26: =SUM(Z13:Z18) -> 20 | ... AF26: =SUM(AF13:AF18) -> 2899
B27: 11.15 - 11.30 | C27: 34 | D27: 5 | E27: 3 | F27: 8 | G27: 0 | H27: 0 | I27: 3 | J27: 1 | K27: 0 | L27: 0 | M27: 104 | N27: 0 | O27: =SUM(C27:L27,N27) -> 54 | P27: =SUM(C27:N27) -> 158 | R27: PM Period | S27: =SUM(S19:S21) -> 327 | T27: =SUM(T19:T21) -> 57 | U27: =SUM(U19:U21) -> 42 | V27: =SUM(V19:V21) -> 89 | W27: =SUM(W19:W21) -> 3 | X27: =SUM(X19:X21) -> 1 | Y27: =SUM(Y19:Y21) -> 21 | Z27: =SUM(Z19:Z21) -> 7 | ... AF27: =SUM(AF19:AF21) -> 1427
B28: 11.30 - 11.45 | C28: 31 | D28: 0 | E28: 5 | F28: 9 | G28: 0 | H28: 0 | I28: 1 | J28: 2 | K28: 0 | L28: 0 | M28: 78 | N28: 0 | O28: =SUM(C28:L28,N28) -> 48 | P28: =SUM(C28:N28) -> 126 | R28: 12 Hours | S28: =SUM(S10:S21) -> 1677 | T28: =SUM(T10:T21) -> 236 | U28: =SUM(U10:U21) -> 199 | V28: =SUM(V10:V21) -> 505 | W28: =SUM(W10:W21) -> 10 | X28: =SUM(X10:X21) -> 2 | Y28: =SUM(Y10:Y21) -> 117 | Z28: =SUM(Z10:Z21) -> 35 | ... AF28: =SUM(AF10:AF21) -> 6625
B29: 11.45 - 12.00 | C29: 41 | D29: 4 | E29: 3 | F29: 6 | G29: 1 | H29: 0 | I29: 0 | J29: 3 | K29: 1 | L29: 0 | M29: 69 | N29: 0 | O29: =SUM(C29:L29,N29) -> 59 | P29: =SUM(C29:N29) -> 128
B30: 12.00 - 12.15 | C30: 31 | D30: 4 | E30: 5 | F30: 5 | G30: 0 | H30: 0 | I30: 1 | J30: 0 | K30: 0 | L30: 0 | M30: 78 | N30: 0 | O30: =SUM(C30:L30,N30) -> 46 | P30: =SUM(C30:N30) -> 124
B31: 12.15 - 12.30 | C31: 39 | D31: 1 | E31: 9 | F31: 6 | G31: 0 | H31: 0 | I31: 5 | J31: 2 | K31: 0 | L31: 0 | M31: 82 | N31: 0 | O31: =SUM(C31:L31,N31) -> 62 | P31: =SUM(C31:N31) -> 144
B32: 12.30 - 12.45 | C32: 29 | D32: 5 | E32: 3 | F32: 9 | G32: 0 | H32: 0 | I32: 3 | J32: 0 | K32: 0 | L32: 0 | M32: 72 | N32: 0 | O32: =SUM(C32:L32,N32) -> 49 | P32: =SUM(C32:N32) -> 121
B33: 12.45 - 13.00 | C33: 34 | D33: 3 | E33: 5 | F33: 7 | G33: 0 | H33: 0 | I33: 4 | J33: 0 | K33: 1 | L33: 1 | M33: 105 | N33: 0 | O33: =SUM(C33:L33,N33) -> 55 | P33: =SUM(C33:N33) -> 160
B34: 13.00 - 13.15 | C34: 28 | D34: 5 | E34: 2 | F34: 4 | G34: 0 | H34: 0 | I34: 2 | J34: 1 | K34: 1 | L34: 0 | M34: 67 | N34: 0 | O34: =SUM(C34:L34,N34) -> 43 | P34: =SUM(C34:N34) -> 110
B35: 13.15 - 13.30 | C35: 26 | D35: 5 | E35: 4 | F35: 6 | G35: 0 | H35: 0 | I35: 2 | J35: 1 | K35: 0 | L35: 0 | M35: 72 | N35: 0 | O35: =SUM(C35:L35,N35) -> 44 | P35: =SUM(C35:N35) -> 116
B36: 13.30 - 13.45 | C36: 27 | D36: 6 | E36: 3 | F36: 7 | G36: 0 | H36: 0 | I36: 3 | J36: 0 | K36: 0 | L36: 0 | M36: 56 | N36: 0 | O36: =SUM(C36:L36,N36) -> 46 | P36: =SUM(C36:N36) -> 102
B37: 13.45 - 14.00 | C37: 28 | D37: 4 | E37: 4 | F37: 5 | G37: 0 | H37: 0 | I37: 2 | J37: 0 | K37: 0 | L37: 0 | M37: 64 | N37: 0 | O37: =SUM(C37:L37,N37) -> 43 | P37: =SUM(C37:N37) -> 107
B38: 14.00 - 14.15 | C38: 23 | D38: 5 | E38: 1 | F38: 6 | G38: 0 | H38: 0 | I38: 2 | J38: 0 | K38: 1 | L38: 0 | M38: 55 | N38: 0 | O38: =SUM(C38:L38,N38) -> 38 | P38: =SUM(C38:N38) -> 93
B39: 14.15 - 14.30 | C39: 26 | D39: 6 | E39: 4 | F39: 6 | G39: 2 | H39: 0 | I39: 1 | J39: 1 | K39: 0 | L39: 0 | M39: 68 | N39: 0 | O39: =SUM(C39:L39,N39) -> 46 | P39: =SUM(C39:N39) -> 114
B40: 14.30 - 14.45 | C40: 28 | D40: 5 | E40: 3 | F40: 8 | G40: 0 | H40: 0 | I40: 2 | J40: 0 | K40: 0 | L40: 0 | M40: 69 | N40: 0 | O40: =SUM(C40:L40,N40) -> 46 | P40: =SUM(C40:N40) -> 115
... B57: 18.45 - 19.00 | C57: 22 | D57: 2 | E57: 6 | F57: 10 | G57: 0 | H57: 0 | I57: 1 | J57: 1 | K57: 2 | L57: 0 | M57: 102 | N57: 0 | O57: =SUM(C57:L57,N57) -> 44 | P57: =SUM(C57:N57) -> 146
B58: Totals | C58: =SUM(C10:C57) -> 1677 | D58: =SUM(D10:D57) -> 236 | E58: =SUM(E10:E57) -> 199 | F58: =SUM(F10:F57) -> 505 | G58: =SUM(G10:G57) -> 10 | H58: =SUM(H10:H57) -> 2 | I58: =SUM(I10:I57) -> 117 | J58: =SUM(J10:J57) -> 35 | ... P58: =SUM(P10:P57) -> 6625
...

Sheet 24.07 Ndeeba-Nyanama
B1: Consultancy services for Preparation of Expressway Development Master Plan (EDMP) for Uganda
B2: MANUAL CLASSIFIED COUNT (MCC)
B3: ROAD NAME: | C3: ='22.07 Ndeeba-Nyanama'!C3:G3 -> MCC - C1 - STN04 - WERAGA ROAD
C5: Date | D5: 24.07.19 | F5: Location | G5: ='22.07 Ndeeba-Nyanama'!G5:H5 -> Golden Mille Hotel | J5: Surveyor | K5: ='22.07 Ndeeba-Nyanama'!K5:L5 -> Steven Dan
C6: Dir. From | D6: ='22.07 Ndeeba-Nyanama'!D6:E6 -> Ndeeba | F6: Dir. To | G6: ='22.07 Ndeeba-Nyanama'!G6:H6 -> Nyanama | J6: Supervisor | K6: ='22.07 Ndeeba-Nyanama'!K6:L6 -> Denis
B8: Time / Veh Type | R8: SUMMARY TRAFFIC VOLUMES
C9: 1. Car | D9: 2. Station Wagon | E9: 3. Pickups | F9: 4. Minibus, matatu | G9: 5. Medium bus | H9: 6. Large Bus | I9: 7. Light Truck | J9: 8. Medium Truck | K9: 9. Heavy truck | L9: 10. Truck Trailer | M9: 11. Motor cycles | N9: 12. Tractors | O9: Total Excl M/Cycles | P9: Total All | R9: Time | S9: 1. Car | T9: 2. Station Wagon | U9: 3. Pickups | V9: 4. Minibus, matatu | W9: 5. Medium bus | X9: 6. Large Bus | Y9: 7. Light Truck | Z9: 8. Medium Truck | AA9: 9. Heavy truck | AB9: 10. Truck Trailer | AC9: 11. Motorcycles | AD9: 12. Tractors, Graders | AE9: Total Excl M/ Cycles | AF9: Total All
B10: 07.00 - 07.15 | C10: 50 | D10: 0 | E10: 1 | F10: 52 | G10: 0 | H10: 0 | I10: 1 | J10: 0 | K10: 0 | L10: 0 | M10: 134 | N10: 0 | O10: =SUM(C10:L10,N10) -> 104 | P10: =SUM(C10:N10) -> 238 | R10: 0700-0800 | S10: =SUM(C10:C13) -> 201 | T10: =SUM(D10:D13) -> 4 | U10: =SUM(E10:E13) -> 13 | V10: =SUM(F10:F13) -> 99 | W10: =SUM(G10:G13) -> 0 | X10: =SUM(H10:H13) -> 0 | Y10: =SUM(I10:I13) -> 8 | Z10: =SUM(J10:J13) -> 0 | ... AF10: =SUM(P10:P13) -> 849
B11: 07.15 - 07.30 | C11: 75 | D11: 1 | E11: 0 | F11: 28 | G11: 0 | H11: 0 | I11: 1 | J11: 0 | K11: 1 | L11: 0 | M11: 138 | N11: 0 | O11: =SUM(C11:L11,N11) -> 106 | P11: =SUM(C11:N11) -> 244 | R11: 0800-0900 | S11: =SUM(C14:C17) -> 137 | T11: =SUM(D14:D17) -> 8 | U11: =SUM(E14:E17) -> 17 | V11: =SUM(F14:F17) -> 55 | W11: =SUM(G14:G17) -> 1 | X11: =SUM(H14:H17) -> 0 | Y11: =SUM(I14:I17) -> 5 | Z11: =SUM(J14:J17) -> 1 | ... AF11: =SUM(P14:P17) -> 672
B12: 07.30 - 07.45 | C12: 34 | D12: 2 | E12: 4 | F12: 10 | G12: 0 | H12: 0 | I12: 3 | J12: 0 | K12: 0 | L12: 0 | M12: 130 | N12: 0 | O12: =SUM(C12:L12,N12) -> 53 | P12: =SUM(C12:N12) -> 183 | R12: 0900-1000 | S12: =SUM(C18:C21) -> 220 | T12: =SUM(D18:D21) -> 2 | U12: =SUM(E18:E21) -> 2 | V12: =SUM(F18:F21) -> 38 | W12: =SUM(G18:G21) -> 0 | X12: =SUM(H18:H21) -> 0 | Y12: =SUM(I18:I21) -> 7 | Z12: =SUM(J18:J21) -> 4 | ... AF12: =SUM(P18:P21) -> 580
B13: 07.45 - 08.00 | C13: 42 | D13: 1 | E13: 8 | F13: 9 | G13: 0 | H13: 0 | I13: 3 | J13: 0 | K13: 0 | L13: 1 | M13: 120 | N13: 0 | O13: =SUM(C13:L13,N13) -> 64 | P13: =SUM(C13:N13) -> 184 | R13: 1000-1100 | S13: =SUM(C22:C25) -> 168 | T13: =SUM(D22:D25) -> 1 | U13: =SUM(E22:E25) -> 10 | V13: =SUM(F22:F25) -> 46 | W13: =SUM(G22:G25) -> 1 | X13: =SUM(H22:H25) -> 0 | Y13: =SUM(I22:I25) -> 9 | Z13: =SUM(J22:J25) -> 0 | ... AF13: =SUM(P22:P25) -> 561
B14: 08.00 - 08.15 | C14: 37 | D14: 2 | E14: 7 | F14: 7 | G14: 0 | H14: 0 | I14: 1 | J14: 0 | K14: 0 | L14: 0 | M14: 160 | N14: 0 | O14: =SUM(C14:L14,N14) -> 54 | P14: =SUM(C14:N14) -> 214 | R14: 1100-1200 | S14: =SUM(C26:C29) -> 203 | T14: =SUM(D26:D29) -> 15 | U14: =SUM(E26:E29) -> 7 | V14: =SUM(F26:F29) -> 39 | W14: =SUM(G26:G29) -> 1 | X14: =SUM(H26:H29) -> 0 | Y14: =SUM(I26:I29) -> 8 | Z14: =SUM(J26:J29) -> 4 | ... AF14: =SUM(P26:P29) -> 605
B15: 08.15 - 08.30 | C15: 40 | D15: 3 | E15: 5 | F15: 28 | G15: 1 | H15: 0 | I15: 2 | J15: 1 | K15: 0 | L15: 0 | M15: 100 | N15: 0 | O15: =SUM(C15:L15,N15) -> 80 | P15: =SUM(C15:N15) -> 180 | R15: 1200-1300 | S15: =SUM(C30:C33) -> 212 | T15: =SUM(D30:D33) -> 5 | U15: =SUM(E30:E33) -> 9 | V15: =SUM(F30:F33) -> 18 | W15: =SUM(G30:G33) -> 1 | X15: =SUM(H30:H33) -> 0 | Y15: =SUM(I30:I33) -> 8 | Z15: =SUM(J30:J33) -> 7 | ... AF15: =SUM(P30:P33) -> 658
B16: 08.30 - 08.45 | C16: 33 | D16: 1 | E16: 0 | F16: 0 | G16: 0 | H16: 0 | I16: 0 | J16: 0 | K16: 0 | L16: 0 | M16: 115 | N16: 0 | O16: =SUM(C16:L16,N16) -> 34 | P16: =SUM(C16:N16) -> 149 | R16: 1300-1400 | S16: =SUM(C34:C37) -> 148 | T16: =SUM(D34:D37) -> 1 | U16: =SUM(E34:E37) -> 10 | V16: =SUM(F34:F37) -> 23 | W16: =SUM(G34:G37) -> 1 | X16: =SUM(H34:H37) -> 0 | Y16: =SUM(I34:I37) -> 7 | Z16: =SUM(J34:J37) -> 8 | ... AF16: =SUM(P34:P37) -> 589
B17: 08.45 - 9.00 | C17: 27 | D17: 2 | E17: 5 | F17: 20 | G17: 0 | H17: 0 | I17: 2 | J17: 0 | K17: 0 | L17: 0 | M17: 73 | N17: 0 | O17: =SUM(C17:L17,N17) -> 56 | P17: =SUM(C17:N17) -> 129 | R17: 1400-1500 | S17: =SUM(C38:C41) -> 122 | T17: =SUM(D38:D41) -> 4 | U17: =SUM(E38:E41) -> 4 | V17: =SUM(F38:F41) -> 21 | W17: =SUM(G38:G41) -> 0 | X17: =SUM(H38:H41) -> 0 | Y17: =SUM(I38:I41) -> 4 | Z17: =SUM(J38:J41) -> 3 | ... AF17: =SUM(P38:P41) -> 383
B18: 09.00 - 09.15 | C18: 33 | D18: 0 | E18: 1 | F18: 2 | G18: 0 | H18: 0 | I18: 4 | J18: 1 | K18: 0 | L18: 0 | M18: 110 | N18: 0 | O18: =SUM(C18:L18,N18) -> 41 | P18: =SUM(C18:N18) -> 151 | R18: 1500-1600 | S18: =SUM(C42:C45) -> 283 | T18: =SUM(D42:D45) -> 3 | U18: =SUM(E42:E45) -> 11 | V18: =SUM(F42:F45) -> 16 | W18: =SUM(G42:G45) -> 2 | X18: =SUM(H42:H45) -> 1 | Y18: =SUM(I42:I45) -> 4 | Z18: =SUM(J42:J45) -> 8 | ... AF18: =SUM(P42:P45) -> 745
B19: 09.15 - 09.30 | C19: 55 | D19: 2 | E19: 1 | F19: 25 | G19: 0 | H19: 0 | I19: 1 | J19: 0 | K19: 0 | L19: 1 | M19: 90 | N19: 0 | O19: =SUM(C19:L19,N19) -> 85 | P19: =SUM(C19:N19) -> 175 | R19: 1600-1700 | S19: =SUM(C46:C49) -> 244 | T19: =SUM(D46:D49) -> 9 | U19: =SUM(E46:E49) -> 19 | V19: =SUM(F46:F49) -> 21 | W19: =SUM(G46:G49) -> 2 | X19: =SUM(H46:H49) -> 0 | Y19: =SUM(I46:I49) -> 5 | Z19: =SUM(J46:J49) -> 2 | ... AF19: =SUM(P46:P49) -> 676
B20: 09.30 - 09.45 | C20: 60 | D20: 0 | E20: 0 | F20: 1 | G20: 0 | H20: 0 | I20: 0 | J20: 0 | K20: 0 | L20: 0 | M20: 60 | N20: 0 | O20: =SUM(C20:L20,N20) -> 61 | P20: =SUM(C20:N20) -> 121 | R20: 1700-1800 | S20: =SUM(C50:C53) -> 366 | T20: =SUM(D50:D53) -> 8 | U20: =SUM(E50:E53) -> 18 | V20: =SUM(F50:F53) -> 119 | W20: =SUM(G50:G53) -> 0 | X20: =SUM(H50:H53) -> 0 | Y20: =SUM(I50:I53) -> 28 | Z20: =SUM(J50:J53) -> 3 | ... AF20: =SUM(P50:P53) -> 964
B21: 09.45 - 10.00 | C21: 72 | D21: 0 | E21: 0 | F21: 10 | G21: 0 | H21: 0 | I21: 2 | J21: 3 | K21: 1 | L21: 0 | M21: 45 | N21: 0 | O21: =SUM(C21:L21,N21) -> 88 | P21: =SUM(C21:N21) -> 133 | R21: 1800-1900 | S21: =SUM(C54:C57) -> 344 | T21: =SUM(D54:D57) -> 23 | U21: =SUM(E54:E57) -> 14 | V21: =SUM(F54:F57) -> 119 | W21: =SUM(G54:G57) -> 1 | X21: =SUM(H54:H57) -> 0 | Y21: =SUM(I54:I57) -> 24 | Z21: =SUM(J54:J57) -> 4 | ... AF21: =SUM(P54:P57) -> 1008
B22: 10.00 - 10.15 | C22: 26 | D22: 0 | E22: 0 | F22: 7 | G22: 0 | H22: 0 | I22: 1 | J22: 0 | K22: 1 | L22: 0 | M22: 70 | N22: 0 | O22: =SUM(C22:L22,N22) -> 35 | P22: =SUM(C22:N22) -> 105 | R22: AM Peak Hr | S22: =MAX(S10:S12) -> 220 | T22: =MAX(T10:T12) -> 8 | U22: =MAX(U10:U12) -> 17 | V22: =MAX(V10:V12) -> 99 | W22: =MAX(W10:W12) -> 1 | X22: =MAX(X10:X12) -> 0 | Y22: =MAX(Y10:Y12) -> 8 | Z22: =MAX(Z10:Z12) -> 4 | ... AF22: =MAX(AF10:AF12) -> 849
B23: 10.15 - 10.30 | C23: 40 | D23: 0 | E23: 4 | F23: 11 | G23: 1 | H23: 0 | I23: 3 | J23: 0 | K23: 0 | L23: 0 | M23: 100 | N23: 0 | O23: =SUM(C23:L23,N23) -> 59 | P23: =SUM(C23:N23) -> 159 | R23: IP Peak Hr | S23: =MAX(S13:S18) -> 283 | T23: =MAX(T13:T18) -> 15 | U23: =MAX(U13:U18) -> 11 | V23: =MAX(V13:V18) -> 46 | W23: =MAX(W13:W18) -> 2 | X23: =MAX(X13:X18) -> 1 | Y23: =MAX(Y13:Y18) -> 9 | Z23: =MAX(Z13:Z18) -> 8 | ... AF23: =MAX(AF13:AF18) -> 745
B24: 10.30 - 10.45 | C24: 32 | D24: 1 | E24: 2 | F24: 3 | G24: 0 | H24: 0 | I24: 2 | J24: 0 | K24: 0 | L24: 3 | M24: 70 | N24: 0 | O24: =SUM(C24:L24,N24) -> 43 | P24: =SUM(C24:N24) -> 113 | R24: PM Peak Hr | S24: =MAX(S19:S21) -> 366 | T24: =MAX(T19:T21) -> 23 | U24: =MAX(U19:U21) -> 19 | V24: =MAX(V19:V21) -> 119 | W24: =MAX(W19:W21) -> 2 | X24: =MAX(X19:X21) -> 0 | Y24: =MAX(Y19:Y21) -> 28 | Z24: =MAX(Z19:Z21) -> 4 | ... AF24: =MAX(AF19:AF21) -> 1008
B25: 10.45 - 11.00 | C25: 70 | D25: 0 | E25: 4 | F25: 25 | G25: 0 | H25: 0 | I25: 3 | J25: 0 | K25: 0 | L25: 0 | M25: 82 | N25: 0 | O25: =SUM(C25:L25,N25) -> 102 | P25: =SUM(C25:N25) -> 184 | R25: AM Period | S25: =SUM(S10:S12) -> 558 | T25: =SUM(T10:T12) -> 14 | U25: =SUM(U10:U12) -> 32 | V25: =SUM(V10:V12) -> 192 | W25: =SUM(W10:W12) -> 1 | X25: =SUM(X10:X12) -> 0 | Y25: =SUM(Y10:Y12) -> 20 | Z25: =SUM(Z10:Z12) -> 5 | ... AF25: =SUM(AF10:AF12) -> 2101
B26: 11.00 - 11.15 | C26: 60 | D26: 3 | E26: 1 | F26: 26 | G26: 0 | H26: 0 | I26: 2 | J26: 1 | K26: 0 | L26: 1 | M26: 90 | N26: 0 | O26: =SUM(C26:L26,N26) -> 94 | P26: =SUM(C26:N26) -> 184 | R26: IP Period | S26: =SUM(S13:S18) -> 1136 | T26: =SUM(T13:T18) -> 29 | U26: =SUM(U13:U18) -> 51 | V26: =SUM(V13:V18) -> 163 | W26: =SUM(W13:W18) -> 6 | X26: =SUM(X13:X18) -> 1 | Y26: =SUM(Y13:Y18) -> 40 | Z26: =SUM(Z13:Z18) -> 30 | ... AF26: =SUM(AF13:AF18) -> 3541
B27: 11.15 - 11.30 | C27: 30 | D27: 0 | E27: 2 | F27: 7 | G27: 0 | H27: 0 | I27: 2 | J27: 1 | K27: 0 | L27: 0 | M27: 60 | N27: 0 | O27: =SUM(C27:L27,N27) -> 42 | P27: =SUM(C27:N27) -> 102 | R27: PM Period | S27: =SUM(S19:S21) -> 954 | T27: =SUM(T19:T21) -> 40 | U27: =SUM(U19:U21) -> 51 | V27: =SUM(V19:V21) -> 259 | W27: =SUM(W19:W21) -> 3 | X27: =SUM(X19:X21) -> 0 | Y27: =SUM(Y19:Y21) -> 57 | Z27: =SUM(Z19:Z21) -> 9 | ... AF27: =SUM(AF19:AF21) -> 2648
B28: 11.30 - 11.45 | C28: 73 | D28: 1 | E28: 1 | F28: 6 | G28: 1 | H28: 0 | I28: 3 | J28: 2 | K28: 2 | L28: 0 | M28: 80 | N28: 0 | O28: =SUM(C28:L28,N28) -> 89 | P28: =SUM(C28:N28) -> 169 | R28: 12 Hours | S28: =SUM(S10:S21) -> 2648 | T28: =SUM(T10:T21) -> 83 | U28: =SUM(U10:U21) -> 134 | V28: =SUM(V10:V21) -> 614 | W28: =SUM(W10:W21) -> 10 | X28: =SUM(X10:X21) -> 1 | Y28: =SUM(Y10:Y21) -> 117 | Z28: =SUM(Z10:Z21) -> 44 | ... AF28: =SUM(AF10:AF21) -> 8290
