Workbook

Sheet 23.09 Bombo-Matugga 
B1: Consultancy services for Preparation of Expressway Development Master Plan (EDMP) for Uganda
B2: MANUAL CLASSIFIED COUNT (MCC)
B3: ROAD NAME: | C3: MCC - C2 - STN067- BOMBO ROAD
C5: Date | D5: 23.09.19 | F5: Location | G5: Matugga Gaz | J5: Surveyor | K5: Babirye
C6: Dir. From | D6: Bombo | F6: Dir. To | G6: Matugga | J6: Supervisor | K6: Nusura
B8: Time / Veh Type | R8: SUMMARY TRAFFIC VOLUMES
C9: 1. Car | D9: 2. Station Wagon | E9: 3. Pickups | F9: 4. Minibus, matatu | G9: 5. Medium bus | H9: 6. Large Bus | I9: 7. Light Truck | J9: 8. Medium Truck | K9: 9. Heavy truck | L9: 10. Truck Trailer | M9: 11. Motor cycles | N9: 12. Tractors | O9: Total Excl M/Cycles | P9: Total All | R9: Time | S9: 1. Car | T9: 2. Station Wagon | U9: 3. Pickups | V9: 4. Minibus, matatu | W9: 5. Medium bus | X9: 6. Large Bus | Y9: 7. Light Truck | Z9: 8. Medium Truck | AA9: 9. Heavy truck | AB9: 10. Truck Trailer | AC9: 11. Motorcycles | AD9: 12. Tractors, Graders | AE9: Total Excl M/ Cycles | AF9: Total All
B10: 07.00 - 07.15 | C10: 17 | D10: 0 | E10: 2 | F10: 5 | G10: 1 | H10: 0 | I10: 7 | J10: 0 | K10: 1 | L10: 0 | M10: 105 | N10: 0 | O10: =SUM(C10:L10,N10) -> 33 | P10: =SUM(C10:N10) -> 138 | R10: 0700-0800 | S10: =SUM(C10:C13) -> 105 | T10: =SUM(D10:D13) -> 19 | U10: =SUM(E10:E13) -> 16 | V10: =SUM(F10:F13) -> 123 | W10: =SUM(G10:G13) -> 2 | X10: =SUM(H10:H13) -> 3 | Y10: =SUM(I10:I13) -> 25 | Z10: =SUM(J10:J13) -> 4 | ... AF10: =SUM(P10:P13) -> 669
B11: 07.15 - 07.30 | C11: 38 | D11: 11 | E11: 5 | F11: 33 | G11: 1 | H11: 0 | I11: 5 | J11: 0 | K11: 0 | L11: 0 | M11: 90 | N11: 0 | O11: =SUM(C11:L11,N11) -> 93 | P11: =SUM(C11:N11) -> 183 | R11: 0800-0900 | S11: =SUM(C14:C17) -> 109 | T11: =SUM(D14:D17) -> 28 | U11: =SUM(E14:E17) -> 29 | V11: =SUM(F14:F17) -> 152 | W11: =SUM(G14:G17) -> 6 | X11: =SUM(H14:H17) -> 2 | Y11: =SUM(I14:I17) -> 35 | Z11: =SUM(J14:J17) -> 7 | ... AF11: =SUM(P14:P17) -> 787
B12: 07.30 - 07.45 | C12: 31 | D12: 6 | E12: 6 | F12: 50 | G12: 0 | H12: 1 | I12: 3 | J12: 2 | K12: 0 | L12: 0 | M12: 93 | N12: 0 | O12: =SUM(C12:L12,N12) -> 99 | P12: =SUM(C12:N12) -> 192 | R12: 0900-1000 | S12: =SUM(C18:C21) -> 102 | T12: =SUM(D18:D21) -> 16 | U12: =SUM(E18:E21) -> 18 | V12: =SUM(F18:F21) -> 179 | W12: =SUM(G18:G21) -> 0 | X12: =SUM(H18:H21) -> 1 | Y12: =SUM(I18:I21) -> 40 | Z12: =SUM(J18:J21) -> 9 | ... AF12: =SUM(P18:P21) -> 707
B13: 07.45 - 08.00 | C13: 19 | D13: 2 | E13: 3 | F13: 35 | G13: 0 | H13: 2 | I13: 10 | J13: 2 | K13: 0 | L13: 1 | M13: 82 | N13: 0 | O13: =SUM(C13:L13,N13) -> 74 | P13: =SUM(C13:N13) -> 156 | R13: 1000-1100 | S13: =SUM(C22:C25) -> 112 | T13: =SUM(D22:D25) -> 17 | U13: =SUM(E22:E25) -> 16 | V13: =SUM(F22:F25) -> 149 | W13: =SUM(G22:G25) -> 0 | X13: =SUM(H22:H25) -> 1 | Y13: =SUM(I22:I25) -> 52 | Z13: =SUM(J22:J25) -> 8 | ... AF13: =SUM(P22:P25) -> 644
B14: 08.00 - 08.15 | C14: 30 | D14: 9 | E14: 10 | F14: 65 | G14: 1 | H14: 2 | I14: 13 | J14: 3 | K14: 0 | L14: 2 | M14: 91 | N14: 0 | O14: =SUM(C14:L14,N14) -> 135 | P14: =SUM(C14:N14) -> 226 | R14: 1100-1200 | S14: =SUM(C26:C29) -> 96 | T14: =SUM(D26:D29) -> 30 | U14: =SUM(E26:E29) -> 12 | V14: =SUM(F26:F29) -> 146 | W14: =SUM(G26:G29) -> 3 | X14: =SUM(H26:H29) -> 0 | Y14: =SUM(I26:I29) -> 70 | Z14: =SUM(J26:J29) -> 4 | ... AF14: =SUM(P26:P29) -> 612
B15: 08.15 - 08.30 | C15: 21 | D15: 9 | E15: 5 | F15: 26 | G15: 1 | H15: 0 | I15: 3 | J15: 3 | K15: 1 | L15: 2 | M15: 92 | N15: 0 | O15: =SUM(C15:L15,N15) -> 71 | P15: =SUM(C15:N15) -> 163 | R15: 1200-1300 | S15: =SUM(C30:C33) -> 95 | T15: =SUM(D30:D33) -> 16 | U15: =SUM(E30:E33) -> 19 | V15: =SUM(F30:F33) -> 112 | W15: =SUM(G30:G33) -> 3 | X15: =SUM(H30:H33) -> 3 | Y15: =SUM(I30:I33) -> 34 | Z15: =SUM(J30:J33) -> 4 | ... AF15: =SUM(P30:P33) -> 547
B16: 08.30 - 08.45 | C16: 27 | D16: 3 | E16: 6 | F16: 36 | G16: 2 | H16: 0 | I16: 9 | J16: 0 | K16: 3 | L16: 2 | M16: 125 | N16: 0 | O16: =SUM(C16:L16,N16) -> 88 | P16: =SUM(C16:N16) -> 213 | R16: 1300-1400 | S16: =SUM(C34:C37) -> 101 | T16: =SUM(D34:D37) -> 49 | U16: =SUM(E34:E37) -> 9 | V16: =SUM(F34:F37) -> 141 | W16: =SUM(G34:G37) -> 0 | X16: =SUM(H34:H37) -> 1 | Y16: =SUM(I34:I37) -> 41 | Z16: =SUM(J34:J37) -> 1 | ... AF16: =SUM(P34:P37) -> 502
B17: 08.45 - 9.00 | C17: 31 | D17: 7 | E17: 8 | F17: 25 | G17: 2 | H17: 0 | I17: 10 | J17: 1 | K17: 8 | L17: 3 | M17: 90 | N17: 0 | O17: =SUM(C17:L17,N17) -> 95 | P17: =SUM(C17:N17) -> 185 | R17: 1400-1500 | S17: =SUM(C38:C41) -> 89 | T17: =SUM(D38:D41) -> 30 | U17: =SUM(E38:E41) -> 13 | V17: =SUM(F38:F41) -> 110 | W17: =SUM(G38:G41) -> 0 | X17: =SUM(H38:H41) -> 0 | Y17: =SUM(I38:I41) -> 31 | Z17: =SUM(J38:J41) -> 8 | ... AF17: =SUM(P38:P41) -> 488
B18: 09.00 - 09.15 | C18: 29 | D18: 10 | E18: 7 | F18: 54 | G18: 0 | H18: 0 | I18: 19 | J18: 2 | K18: 1 | L18: 3 | M18: 95 | N18: 0 | O18: =SUM(C18:L18,N18) -> 125 | P18: =SUM(C18:N18) -> 220 | R18: 1500-1600 | S18: =SUM(C42:C45) -> 129 | T18: =SUM(D42:D45) -> 26 | U18: =SUM(E42:E45) -> 32 | V18: =SUM(F42:F45) -> 127 | W18: =SUM(G42:G45) -> 1 | X18: =SUM(H42:H45) -> 7 | Y18: =SUM(I42:I45) -> 43 | Z18: =SUM(J42:J45) -> 4 | ... AF18: =SUM(P42:P45) -> 548
B19: 09.15 - 09.30 | C19: 20 | D19: 2 | E19: 5 | F19: 45 | G19: 0 | H19: 1 | I19: 9 | J19: 1 | K19: 2 | L19: 2 | M19: 73 | N19: 0 | O19: =SUM(C19:L19,N19) -> 87 | P19: =SUM(C19:N19) -> 160 | R19: 1600-1700 | S19: =SUM(C46:C49) -> 149 | T19: =SUM(D46:D49) -> 27 | U19: =SUM(E46:E49) -> 31 | V19: =SUM(F46:F49) -> 109 | W19: =SUM(G46:G49) -> 3 | X19: =SUM(H46:H49) -> 4 | Y19: =SUM(I46:I49) -> 27 | Z19: =SUM(J46:J49) -> 7 | ... AF19: =SUM(P46:P49) -> 500
B20: 09.30 - 09.45 | C20: 26 | D20: 3 | E20: 4 | F20: 47 | G20: 0 | H20: 0 | I20: 7 | J20: 3 | K20: 0 | L20: 1 | M20: 77 | N20: 0 | O20: =SUM(C20:L20,N20) -> 91 | P20: =SUM(C20:N20) -> 168 | R20: 1700-1800 | S20: =SUM(C50:C53) -> 189 | T20: =SUM(D50:D53) -> 45 | U20: =SUM(E50:E53) -> 30 | V20: =SUM(F50:F53) -> 159 | W20: =SUM(G50:G53) -> 17 | X20: =SUM(H50:H53) -> 1 | Y20: =SUM(I50:I53) -> 33 | Z20: =SUM(J50:J53) -> 24 | ... AF20: =SUM(P50:P53) -> 708
B21: 09.45 - 10.00 | C21: 27 | D21: 1 | E21: 2 | F21: 33 | G21: 0 | H21: 0 | I21: 5 | J21: 3 | K21: 0 | L21: 1 | M21: 87 | N21: 0 | O21: =SUM(C21:L21,N21) -> 72 | P21: =SUM(C21:N21) -> 159 | R21: 1800-1900 | S21: =SUM(C54:C57) -> 194 | T21: =SUM(D54:D57) -> 45 | U21: =SUM(E54:E57) -> 40 | V21: =SUM(F54:F57) -> 221 | W21: =SUM(G54:G57) -> 18 | X21: =SUM(H54:H57) -> 6 | Y21: =SUM(I54:I57) -> 44 | Z21: =SUM(J54:J57) -> 26 | ... AF21: =SUM(P54:P57) -> 861
B22: 10.00 - 10.15 | C22: 25 | D22: 2 | E22: 2 | F22: 41 | G22: 0 | H22: 0 | I22: 7 | J22: 1 | K22: 0 | L22: 1 | M22: 63 | N22: 0 | O22: =SUM(C22:L22,N22) -> 79 | P22: =SUM(C22:N22) -> 142 | R22: AM Peak Hr | S22: =MAX(S10:S12) -> 109 | T22: =MAX(T10:T12) -> 28 | U22: =MAX(U10:U12) -> 29 | V22: =MAX(V10:V12) -> 179 | W22: =MAX(W10:W12) -> 6 | X22: =MAX(X10:X12) -> 3 | Y22: =MAX(Y10:Y12) -> 40 | Z22: =MAX(Z10:Z12) -> 9 | ... AF22: =MAX(AF10:AF12) -> 787
B23: 10.15 - 10.30 | C23: 36 | D23: 5 | E23: 6 | F23: 37 | G23: 0 | H23: 1 | I23: 9 | J23: 4 | K23: 2 | L23: 1 | M23: 80 | N23: 0 | O23: =SUM(C23:L23,N23) -> 101 | P23: =SUM(C23:N23) -> 181 | R23: IP Peak Hr | S23: =MAX(S13:S18) -> 129 | T23: =MAX(T13:T18) -> 49 | U23: =MAX(U13:U18) -> 32 | V23: =MAX(V13:V18) -> 149 | W23: =MAX(W13:W18) -> 3 | X23: =MAX(X13:X18) -> 7 | Y23: =MAX(Y13:Y18) -> 70 | Z23: =MAX(Z13:Z18) -> 8 | ... AF23: =MAX(AF13:AF18) -> 644
B24: 10.30 - 10.45 | C24: 28 | D24: 4 | E24: 5 | F24: 37 | G24: 0 | H24: 0 | I24: 11 | J24: 0 | K24: 2 | L24: 1 | M24: 68 | N24: 0 | O24: =SUM(C24:L24,N24) -> 88 | P24: =SUM(C24:N24) -> 156 | R24: PM Peak Hr | S24: =MAX(S19:S21) -> 194 | T24: =MAX(T19:T21) -> 45 | U24: =MAX(U19:U21) -> 40 | V24: =MAX(V19:V21) -> 221 | W24: =MAX(W19:W21) -> 18 | X24: =MAX(X19:X21) -> 6 | Y24: =MAX(Y19:Y21) -> 44 | Z24: =MAX(Z19:Z21) -> 26 | ... AF24: =MAX(AF19:AF21) -> 861
B25: 10.45 - 11.00 | C25: 23 | D25: 6 | E25: 3 | F25: 34 | G25: 0 | H25: 0 | I25: 25 | J25: 3 | K25: 1 | L25: 5 | M25: 65 | N25: 0 | O25: =SUM(C25:L25,N25) -> 100 | P25: =SUM(C25:N25) -> 165 | R25: AM Period | S25: =SUM(S10:S12) -> 316 | T25: =SUM(T10:T12) -> 63 | U25: =SUM(U10:U12) -> 63 | V25: =SUM(V10:V12) -> 454 | W25: =SUM(W10:W12) -> 8 | X25: =SUM(X10:X12) -> 6 | Y25: =SUM(Y10:Y12) -> 100 | Z25: =SUM(Z10:Z12) -> 20 | ... AF25: =SUM(AF10:AF12) -> 2163
B26: 11.00 - 11.15 | C26: 27 | D26: 8 | E26: 3 | F26: 41 | G26: 1 | H26: 0 | I26: 2 | J26: 0 | K26: 1 | L26: 0 | M26: 50 | N26: 0 | O26: =SUM(C26:L26,N26) -> 83 | P26: =SUM(C26:N26) -> 133 | R26: IP Period | S26: =SUM(S13:S18) -> 622 | T26: =SUM(T13:T18) -> 168 | U26: =SUM(U13:U18) -> 101 | V26: =SUM(V13:V18) -> 785 | W26: =SUM(W13:W18) -> 7 | X26: =SUM(X13:X18) -> 12 | Y26: =SUM(Y13:Y18) -> 271 | Z26: =SUM(Z13:Z18) -> 29 | ... AF26: =SUM(AF13:AF18) -> 3341
B27: 11.15 - 11.30 | C27: 13 | D27: 5 | E27: 2 | F27: 45 | G27: 1 | H27: 0 | I27: 40 | J27: 2 | K27: 1 | L27: 1 | M27: 65 | N27: 0 | O27: =SUM(C27:L27,N27) -> 110 | P27: =SUM(C27:N27) -> 175 | R27: PM Period | S27: =SUM(S19:S21) -> 532 | T27: =SUM(T19:T21) -> 117 | U27: =SUM(U19:U21) -> 101 | V27: =SUM(V19:V21) -> 489 | W27: =SUM(W19:W21) -> 38 | X27: =SUM(X19:X21) -> 11 | Y27: =SUM(Y19:Y21) -> 104 | Z27: =SUM(Z19:Z21) -> 57 | ... AF27: =SUM(AF19:AF21) -> 2069
B28: 11.30 - 11.45 | C28: 30 | D28: 2 | E28: 0 | F28: 23 | G28: 1 | H28: 0 | I28: 17 | J28: 0 | K28: 1 | L28: 2 | M28: 75 | N28: 0 | O28: =SUM(C28:L28,N28) -> 76 | P28: =SUM(C28:N28) -> 151 | R28: 12 Hours | S28: =SUM(S10:S21) -> 1470 | T28: =SUM(T10:T21) -> 348 | U28: =SUM(U10:U21) -> 265 | V28: =SUM(V10:V21) -> 1728 | W28: =SUM(W10:W21) -> 53 | X28: =SUM(X10:X21) -> 29 | Y28: =SUM(Y10:Y21) -> 475 | Z28: =SUM(Z10:Z21) -> 106 | ... AF28: =SUM(AF10:AF21) -> 7573
B29: 11.45 - 12.00 | C29: 26 | D29: 15 | E29: 7 | F29: 37 | G29: 0 | H29: 0 | I29: 11 | J29: 2 | K29: 2 | L29: 3 | M29: 50 | N29: 0 | O29: =SUM(C29:L29,N29) -> 103 | P29: =SUM(C29:N29) -> 153
B30: 12.00 - 12.15 | C30: 19 | D30: 7 | E30: 5 | F30: 31 | G30: 1 | H30: 1 | I30: 12 | J30: 2 | K30: 1 | L30: 5 | M30: 54 | N30: 0 | O30: =SUM(C30:L30,N30) -> 84 | P30: =SUM(C30:N30) -> 138
B31: 12.15 - 12.30 | C31: 23 | D31: 3 | E31: 2 | F31: 35 | G31: 1 | H31: 0 | I31: 15 | J31: 1 | K31: 2 | L31: 2 | M31: 60 | N31: 0 | O31: =SUM(C31:L31,N31) -> 84 | P31: =SUM(C31:N31) -> 144
B32: 12.30 - 12.45 | C32: 20 | D32: 3 | E32: 5 | F32: 18 | G32: 0 | H32: 0 | I32: 3 | J32: 1 | K32: 0 | L32: 3 | M32: 63 | N32: 0 | O32: =SUM(C32:L32,N32) -> 53 | P32: =SUM(C32:N32) -> 116
B33: 12.45 - 13.00 | C33: 33 | D33: 3 | E33: 7 | F33: 28 | G33: 1 | H33: 2 | I33: 4 | J33: 0 | K33: 0 | L33: 0 | M33: 71 | N33: 0 | O33: =SUM(C33:L33,N33) -> 78 | P33: =SUM(C33:N33) -> 149
B34: 13.00 - 13.15 | C34: 18 | D34: 9 | E34: 4 | F34: 25 | G34: 0 | H34: 1 | I34: 8 | J34: 0 | K34: 1 | L34: 1 | M34: 35 | N34: 0 | O34: =SUM(C34:L34,N34) -> 67 | P34: =SUM(C34:N34) -> 102
B35: 13.15 - 13.30 | C35: 26 | D35: 3 | E35: 4 | F35: 39 | G35: 0 | H35: 0 | I35: 8 | J35: 1 | K35: 0 | L35: 3 | M35: 33 | N35: 0 | O35: =SUM(C35:L35,N35) -> 84 | P35: =SUM(C35:N35) -> 117
B36: 13.30 - 13.45 | C36: 27 | D36: 12 | E36: 1 | F36: 40 | G36: 0 | H36: 0 | I36: 11 | J36: 0 | K36: 0 | L36: 1 | M36: 41 | N36: 0 | O36: =SUM(C36:L36,N36) -> 92 | P36: =SUM(C36:N36) -> 133
B37: 13.45 - 14.00 | C37: 30 | D37: 25 | E37: 0 | F37: 37 | G37: 0 | H37: 0 | I37: 14 | J37: 0 | K37: 0 | L37: 3 | M37: 40 | N37: 1 | O37: =SUM(C37:L37,N37) -> 110 | P37: =SUM(C37:N37) -> 150
B38: 14.00 - 14.15 | C38: 24 | D38: 3 | E38: 1 | F38: 32 | G38: 0 | H38: 0 | I38: 5 | J38: 2 | K38: 0 | L38: 1 | M38: 52 | N38: 0 | O38: =SUM(C38:L38,N38) -> 68 | P38: =SUM(C38:N38) -> 120
B39: 14.15 - 14.30 | C39: 16 | D39: 8 | E39: 6 | F39: 19 | G39: 0 | H39: 0 | I39: 14 | J39: 3 | K39: 0 | L39: 2 | M39: 45 | N39: 0 | O39: =SUM(C39:L39,N39) -> 68 | P39: =SUM(C39:N39) -> 113
B40: 14.30 - 14.45 | C40: 25 | D40: 6 | E40: 2 | F40: 34 | G40: 0 | H40: 0 | I40: 8 | J40: 3 | K40: 0 | L40: 1 | M40: 53 | N40: 0 | O40: =SUM(C40:L40,N40) -> 79 | P40: =SUM(C40:N40) -> 132
... B57: 18.45 - 19.00 | C57: 51 | D57: 15 | E57: 12 | F57: 42 | G57: 1 | H57: 2 | I57: 14 | J57: 7 | K57: 3 | L57: 1 | M57: 85 | N57: 0 | O57: =SUM(C57:L57,N57) -> 148 | P57: =SUM(C57:N57) -> 233
B58: Totals | C58: =SUM(C10:C57) -> 1470 | D58: =SUM(D10:D57) -> 348 | E58: =SUM(E10:E57) -> 265 | F58: =SUM(F10:F57) -> 1728 | G58: =SUM(G10:G57) -> 53 | H58: =SUM(H10:H57) -> 29 | I58: =SUM(I10:I57) -> 475 | J58: =SUM(J10:J57) -> 106 | ... P58: =SUM(P10:P57) -> 7573
...

Sheet 23.09 Matugga-Bombo
B1: Consultancy services for Preparation of Expressway Development Master Plan (EDMP) for Uganda
B2: MANUAL CLASSIFIED COUNT (MCC)
B3: ROAD NAME: | C3: ='23.09 Bombo-Matugga '!C3:G3 -> MCC - C2 - STN067- BOMBO ROAD
C5: Date | D5: ='23.09 Bombo-Matugga '!D5 -> 23.09.19 | F5: Location | G5: ='23.09 Bombo-Matugga '!G5:H5 -> Matugga Gaz | J5: Surveyor | K5: Omeje Brian
C6: Dir. From | D6: Matugga | F6: Dir. To | G6: Bombo | J6: Supervisor | K6: Nusura
B8: Time / Veh Type | R8: SUMMARY TRAFFIC VOLUMES
C9: 1. Car | D9: 2. Station Wagon | E9: 3. Pickups | F9: 4. Minibus, matatu | G9: 5. Medium bus | H9: 6. Large Bus | I9: 7. Light Truck | J9: 8. Medium Truck | K9: 9. Heavy truck | L9: 10. Truck Trailer | M9: 11. Motor cycles | N9: 12. Tractors | O9: Total Excl M/Cycles | P9: Total All | R9: Time | S9: 1. Car | T9: 2. Station Wagon | U9: 3. Pickups | V9: 4. Minibus, matatu | W9: 5. Medium bus | X9: 6. Large Bus | Y9: 7. Light Truck | Z9: 8. Medium Truck | AA9: 9. Heavy truck | AB9: 10. Truck Trailer | AC9: 11. Motorcycles | AD9: 12. Tractors, Graders | AE9: Total Excl M/ Cycles | AF9: Total All
B10: 07.00 - 07.15 | C10: 33 | D10: 0 | E10: 0 | F10: 1 | G10: 0 | H10: 0 | I10: 3 | J10: 4 | K10: 1 | L10: 0 | M10: 50 | N10: 0 | O10: =SUM(C10:L10,N10) -> 42 | P10: =SUM(C10:N10) -> 92 | R10: 0700-0800 | S10: =SUM(C10:C13) -> 135 | T10: =SUM(D10:D13) -> 35 | U10: =SUM(E10:E13) -> 14 | V10: =SUM(F10:F13) -> 63 | W10: =SUM(G10:G13) -> 29 | X10: =SUM(H10:H13) -> 2 | Y10: =SUM(I10:I13) -> 38 | Z10: =SUM(J10:J13) -> 14 | ... AF10: =SUM(P10:P13) -> 603
B11: 07.15 - 07.30 | C11: 26 | D11: 11 | E11: 4 | F11: 28 | G11: 0 | H11: 1 | I11: 10 | J11: 4 | K11: 1 | L11: 0 | M11: 61 | N11: 0 | O11: =SUM(C11:L11,N11) -> 85 | P11: =SUM(C11:N11) -> 146 | R11: 0800-0900 | S11: =SUM(C14:C17) -> 160 | T11: =SUM(D14:D17) -> 48 | U11: =SUM(E14:E17) -> 25 | V11: =SUM(F14:F17) -> 123 | W11: =SUM(G14:G17) -> 3 | X11: =SUM(H14:H17) -> 1 | Y11: =SUM(I14:I17) -> 43 | Z11: =SUM(J14:J17) -> 11 | ... AF11: =SUM(P14:P17) -> 791
B12: 07.30 - 07.45 | C12: 48 | D12: 12 | E12: 9 | F12: 34 | G12: 0 | H12: 1 | I12: 15 | J12: 4 | K12: 2 | L12: 0 | M12: 90 | N12: 0 | O12: =SUM(C12:L12,N12) -> 125 | P12: =SUM(C12:N12) -> 215 | R12: 0900-1000 | S12: =SUM(C18:C21) -> 151 | T12: =SUM(D18:D21) -> 49 | U12: =SUM(E18:E21) -> 21 | V12: =SUM(F18:F21) -> 165 | W12: =SUM(G18:G21) -> 3 | X12: =SUM(H18:H21) -> 3 | Y12: =SUM(I18:I21) -> 52 | Z12: =SUM(J18:J21) -> 16 | ... AF12: =SUM(P18:P21) -> 819
B13: 07.45 - 08.00 | C13: 28 | D13: 12 | E13: 1 | F13: 0 | G13: 29 | H13: 0 | I13: 10 | J13: 2 | K13: 3 | L13: 0 | M13: 65 | N13: 0 | O13: =SUM(C13:L13,N13) -> 85 | P13: =SUM(C13:N13) -> 150 | R13: 1000-1100 | S13: =SUM(C22:C25) -> 125 | T13: =SUM(D22:D25) -> 36 | U13: =SUM(E22:E25) -> 27 | V13: =SUM(F22:F25) -> 160 | W13: =SUM(G22:G25) -> 6 | X13: =SUM(H22:H25) -> 0 | Y13: =SUM(I22:I25) -> 76 | Z13: =SUM(J22:J25) -> 13 | ... AF13: =SUM(P22:P25) -> 752
B14: 08.00 - 08.15 | C14: 48 | D14: 13 | E14: 7 | F14: 43 | G14: 0 | H14: 1 | I14: 13 | J14: 6 | K14: 7 | L14: 2 | M14: 100 | N14: 1 | O14: =SUM(C14:L14,N14) -> 141 | P14: =SUM(C14:N14) -> 241 | R14: 1100-1200 | S14: =SUM(C26:C29) -> 119 | T14: =SUM(D26:D29) -> 43 | U14: =SUM(E26:E29) -> 35 | V14: =SUM(F26:F29) -> 168 | W14: =SUM(G26:G29) -> 6 | X14: =SUM(H26:H29) -> 7 | Y14: =SUM(I26:I29) -> 61 | Z14: =SUM(J26:J29) -> 11 | ... AF14: =SUM(P26:P29) -> 768
B15: 08.15 - 08.30 | C15: 36 | D15: 10 | E15: 6 | F15: 32 | G15: 1 | H15: 0 | I15: 9 | J15: 0 | K15: 3 | L15: 0 | M15: 82 | N15: 0 | O15: =SUM(C15:L15,N15) -> 97 | P15: =SUM(C15:N15) -> 179 | R15: 1200-1300 | S15: =SUM(C30:C33) -> 138 | T15: =SUM(D30:D33) -> 25 | U15: =SUM(E30:E33) -> 23 | V15: =SUM(F30:F33) -> 119 | W15: =SUM(G30:G33) -> 8 | X15: =SUM(H30:H33) -> 3 | Y15: =SUM(I30:I33) -> 75 | Z15: =SUM(J30:J33) -> 19 | ... AF15: =SUM(P30:P33) -> 720
B16: 08.30 - 08.45 | C16: 49 | D16: 11 | E16: 4 | F16: 30 | G16: 2 | H16: 0 | I16: 9 | J16: 3 | K16: 2 | L16: 0 | M16: 83 | N16: 1 | O16: =SUM(C16:L16,N16) -> 111 | P16: =SUM(C16:N16) -> 194 | R16: 1300-1400 | S16: =SUM(C34:C37) -> 110 | T16: =SUM(D34:D37) -> 50 | U16: =SUM(E34:E37) -> 28 | V16: =SUM(F34:F37) -> 146 | W16: =SUM(G34:G37) -> 8 | X16: =SUM(H34:H37) -> 6 | Y16: =SUM(I34:I37) -> 42 | Z16: =SUM(J34:J37) -> 24 | ... AF16: =SUM(P34:P37) -> 653
B17: 08.45 - 9.00 | C17: 27 | D17: 14 | E17: 8 | F17: 18 | G17: 0 | H17: 0 | I17: 12 | J17: 2 | K17: 1 | L17: 0 | M17: 95 | N17: 0 | O17: =SUM(C17:L17,N17) -> 82 | P17: =SUM(C17:N17) -> 177 | R17: 1400-1500 | S17: =SUM(C38:C41) -> 109 | T17: =SUM(D38:D41) -> 18 | U17: =SUM(E38:E41) -> 20 | V17: =SUM(F38:F41) -> 151 | W17: =SUM(G38:G41) -> 7 | X17: =SUM(H38:H41) -> 8 | Y17: =SUM(I38:I41) -> 93 | Z17: =SUM(J38:J41) -> 27 | ... AF17: =SUM(P38:P41) -> 699
B18: 09.00 - 09.15 | C18: 40 | D18: 8 | E18: 4 | F18: 32 | G18: 1 | H18: 1 | I18: 17 | J18: 4 | K18: 2 | L18: 1 | M18: 91 | N18: 0 | O18: =SUM(C18:L18,N18) -> 110 | P18: =SUM(C18:N18) -> 201 | R18: 1500-1600 | S18: =SUM(C42:C45) -> 102 | T18: =SUM(D42:D45) -> 15 | U18: =SUM(E42:E45) -> 35 | V18: =SUM(F42:F45) -> 124 | W18: =SUM(G42:G45) -> 4 | X18: =SUM(H42:H45) -> 5 | Y18: =SUM(I42:I45) -> 65 | Z18: =SUM(J42:J45) -> 27 | ... AF18: =SUM(P42:P45) -> 557
B19: 09.15 - 09.30 | C19: 42 | D19: 11 | E19: 5 | F19: 50 | G19: 0 | H19: 1 | I19: 6 | J19: 1 | K19: 0 | L19: 1 | M19: 80 | N19: 0 | O19: =SUM(C19:L19,N19) -> 117 | P19: =SUM(C19:N19) -> 197 | R19: 1600-1700 | S19: =SUM(C46:C49) -> 58 | T19: =SUM(D46:D49) -> 9 | U19: =SUM(E46:E49) -> 5 | V19: =SUM(F46:F49) -> 54 | W19: =SUM(G46:G49) -> 0 | X19: =SUM(H46:H49) -> 10 | Y19: =SUM(I46:I49) -> 42 | Z19: =SUM(J46:J49) -> 21 | ... AF19: =SUM(P46:P49) -> 345
B20: 09.30 - 09.45 | C20: 39 | D20: 18 | E20: 3 | F20: 50 | G20: 2 | H20: 1 | I20: 18 | J20: 8 | K20: 4 | L20: 0 | M20: 95 | N20: 0 | O20: =SUM(C20:L20,N20) -> 143 | P20: =SUM(C20:N20) -> 238 | R20: 1700-1800 | S20: =SUM(C50:C53) -> 137 | T20: =SUM(D50:D53) -> 17 | U20: =SUM(E50:E53) -> 20 | V20: =SUM(F50:F53) -> 174 | W20: =SUM(G50:G53) -> 5 | X20: =SUM(H50:H53) -> 4 | Y20: =SUM(I50:I53) -> 46 | Z20: =SUM(J50:J53) -> 15 | ... AF20: =SUM(P50:P53) -> 621
B21: 09.45 - 10.00 | C21: 30 | D21: 12 | E21: 9 | F21: 33 | G21: 0 | H21: 0 | I21: 11 | J21: 3 | K21: 1 | L21: 3 | M21: 81 | N21: 0 | O21: =SUM(C21:L21,N21) -> 102 | P21: =SUM(C21:N21) -> 183 | R21: 1800-1900 | S21: =SUM(C54:C57) -> 99 | T21: =SUM(D54:D57) -> 22 | U21: =SUM(E54:E57) -> 20 | V21: =SUM(F54:F57) -> 163 | W21: =SUM(G54:G57) -> 3 | X21: =SUM(H54:H57) -> 1 | Y21: =SUM(I54:I57) -> 61 | Z21: =SUM(J54:J57) -> 13 | ... AF21: =SUM(P54:P57) -> 604
B22: 10.00 - 10.15 | C22: 27 | D22: 6 | E22: 4 | F22: 43 | G22: 0 | H22: 0 | I22: 8 | J22: 0 | K22: 1 | L22: 1 | M22: 75 | N22: 0 | O22: =SUM(C22:L22,N22) -> 90 | P22: =SUM(C22:N22) -> 165 | R22: AM Peak Hr | S22: =MAX(S10:S12) -> 160 | T22: =MAX(T10:T12) -> 49 | U22: =MAX(U10:U12) -> 25 | V22: =MAX(V10:V12) -> 165 | W22: =MAX(W10:W12) -> 29 | X22: =MAX(X10:X12) -> 3 | Y22: =MAX(Y10:Y12) -> 52 | Z22: =MAX(Z10:Z12) -> 16 | ... AF22: =MAX(AF10:AF12) -> 819
B23: 10.15 - 10.30 | C23: 28 | D23: 8 | E23: 8 | F23: 35 | G23: 0 | H23: 0 | I23: 20 | J23: 6 | K23: 3 | L23: 2 | M23: 70 | N23: 0 | O23: =SUM(C23:L23,N23) -> 110 | P23: =SUM(C23:N23) -> 180 | R23: IP Peak Hr | S23: =MAX(S13:S18) -> 138 | T23: =MAX(T13:T18) -> 50 | U23: =MAX(U13:U18) -> 35 | V23: =MAX(V13:V18) -> 168 | W23: =MAX(W13:W18) -> 8 | X23: =MAX(X13:X18) -> 8 | Y23: =MAX(Y13:Y18) -> 93 | Z23: =MAX(Z13:Z18) -> 27 | ... AF23: =MAX(AF13:AF18) -> 768
B24: 10.30 - 10.45 | C24: 40 | D24: 11 | E24: 10 | F24: 48 | G24: 2 | H24: 0 | I24: 18 | J24: 4 | K24: 3 | L24: 0 | M24: 76 | N24: 0 | O24: =SUM(C24:L24,N24) -> 136 | P24: =SUM(C24:N24) -> 212 | R24: PM Peak Hr | S24: =MAX(S19:S21) -> 137 | T24: =MAX(T19:T21) -> 22 | U24: =MAX(U19:U21) -> 20 | V24: =MAX(V19:V21) -> 174 | W24: =MAX(W19:W21) -> 5 | X24: =MAX(X19:X21) -> 10 | Y24: =MAX(Y19:Y21) -> 61 | Z24: =MAX(Z19:Z21) -> 21 | ... AF24: =MAX(AF19:AF21) -> 621
B25: 10.45 - 11.00 | C25: 30 | D25: 11 | E25: 5 | F25: 34 | G25: 4 | H25: 0 | I25: 30 | J25: 3 | K25: 1 | L25: 2 | M25: 75 | N25: 0 | O25: =SUM(C25:L25,N25) -> 120 | P25: =SUM(C25:N25) -> 195 | R25: AM Period | S25: =SUM(S10:S12) -> 446 | T25: =SUM(T10:T12) -> 132 | U25: =SUM(U10:U12) -> 60 | V25: =SUM(V10:V12) -> 351 | W25: =SUM(W10:W12) -> 35 | X25: =SUM(X10:X12) -> 6 | Y25: =SUM(Y10:Y12) -> 133 | Z25: =SUM(Z10:Z12) -> 41 | ... AF25: =SUM(AF10:AF12) -> 2213
B26: 11.00 - 11.15 | C26: 26 | D26: 9 | E26: 7 | F26: 39 | G26: 0 | H26: 3 | I26: 19 | J26: 2 | K26: 1 | L26: 1 | M26: 75 | N26: 0 | O26: =SUM(C26:L26,N26) -> 107 | P26: =SUM(C26:N26) -> 182 | R26: IP Period | S26: =SUM(S13:S18) -> 703 | T26: =SUM(T13:T18) -> 187 | U26: =SUM(U13:U18) -> 168 | V26: =SUM(V13:V18) -> 868 | W26: =SUM(W13:W18) -> 39 | X26: =SUM(X13:X18) -> 29 | Y26: =SUM(Y13:Y18) -> 412 | Z26: =SUM(Z13:Z18) -> 121 | ... AF26: =SUM(AF13:AF18) -> 4149
B27: 11.15 - 11.30 | C27: 35 | D27: 15 | E27: 10 | F27: 40 | G27: 1 | H27: 1 | I27: 16 | J27: 7 | K27: 3 | L27: 0 | M27: 77 | N27: 0 | O27: =SUM(C27:L27,N27) -> 128 | P27: =SUM(C27:N27) -> 205 | R27: PM Period | S27: =SUM(S19:S21) -> 294 | T27: =SUM(T19:T21) -> 48 | U27: =SUM(U19:U21) -> 45 | V27: =SUM(V19:V21) -> 391 | W27: =SUM(W19:W21) -> 8 | X27: =SUM(X19:X21) -> 15 | Y27: =SUM(Y19:Y21) -> 149 | Z27: =SUM(Z19:Z21) -> 49 | ... AF27: =SUM(AF19:AF21) -> 1570
B28: 11.30 - 11.45 | C28: 30 | D28: 9 | E28: 11 | F28: 38 | G28: 3 | H28: 2 | I28: 12 | J28: 0 | K28: 5 | L28: 3 | M28: 71 | N28: 0 | O28: =SUM(C28:L28,N28) -> 113 | P28: =SUM(C28:N28) -> 184 | R28: 12 Hours | S28: =SUM(S10:S21) -> 1443 | T28: =SUM(T10:T21) -> 367 | U28: =SUM(U10:U21) -> 273 | V28: =SUM(V10:V21) -> 1610 | W28: =SUM(W10:W21) -> 82 | X28: =SUM(X10:X21) -> 50 | Y28: =SUM(Y10:Y21) -> 694 | Z28: =SUM(Z10:Z21) -> 211 | ... AF28: =SUM(AF10:AF21) -> 7932
B29: 11.45 - 12.00 | C29: 28 | D29: 10 | E29: 7 | F29: 51 | G29: 2 | H29: 1 | I29: 14 | J29: 2 | K29: 1 | L29: 0 | M29: 81 | N29: 0 | O29: =SUM(C29:L29,N29) -> 116 | P29: =SUM(C29:N29) -> 197
B30: 12.00 - 12.15 | C30: 32 | D30: 9 | E30: 3 | F30: 34 | G30: 2 | H30: 1 | I30: 24 | J30: 6 | K30: 3 | L30: 2 | M30: 78 | N30: 0 | O30: =SUM(C30:L30,N30) -> 116 | P30: =SUM(C30:N30) -> 194
B31: 12.15 - 12.30 | C31: 39 | D31: 10 | E31: 6 | F31: 41 | G31: 2 | H31: 2 | I31: 20 | J31: 5 | K31: 2 | L31: 2 | M31: 92 | N31: 1 | O31: =SUM(C31:L31,N31) -> 130 | P31: =SUM(C31:N31) -> 222
B32: 12.30 - 12.45 | C32: 33 | D32: 3 | E32: 5 | F32: 23 | G32: 1 | H32: 0 | I32: 10 | J32: 4 | K32: 1 | L32: 0 | M32: 40 | N32: 0 | O32: =SUM(C32:L32,N32) -> 80 | P32: =SUM(C32:N32) -> 120
B33: 12.45 - 13.00 | C33: 34 | D33: 3 | E33: 9 | F33: 21 | G33: 3 | H33: 0 | I33: 21 | J33: 4 | K33: 3 | L33: 2 | M33: 84 | N33: 0 | O33: =SUM(C33:L33,N33) -> 100 | P33: =SUM(C33:N33) -> 184
B34: 13.00 - 13.15 | C34: 18 | D34: 12 | E34: 3 | F34: 26 | G34: 2 | H34: 3 | I34: 8 | J34: 7 | K34: 4 | L34: 1 | M34: 70 | N34: 0 | O34: =SUM(C34:L34,N34) -> 84 | P34: =SUM(C34:N34) -> 154
B35: 13.15 - 13.30 | C35: 21 | D35: 11 | E35: 7 | F35: 31 | G35: 3 | H35: 1 | I35: 9 | J35: 7 | K35: 3 | L35: 1 | M35: 42 | N35: 0 | O35: =SUM(C35:L35,N35) -> 94 | P35: =SUM(C35:N35) -> 136
B36: 13.30 - 13.45 | C36: 28 | D36: 11 | E36: 11 | F36: 44 | G36: 1 | H36: 2 | I36: 12 | J36: 6 | K36: 3 | L36: 3 | M36: 49 | N36: 0 | O36: =SUM(C36:L36,N36) -> 121 | P36: =SUM(C36:N36) -> 170
B37: 13.45 - 14.00 | C37: 43 | D37: 16 | E37: 7 | F37: 45 | G37: 2 | H37: 0 | I37: 13 | J37: 4 | K37: 2 | L37: 1 | M37: 60 | N37: 0 | O37: =SUM(C37:L37,N37) -> 133 | P37: =SUM(C37:N37) -> 193
B38: 14.00 - 14.15 | C38: 35 | D38: 6 | E38: 6 | F38: 50 | G38: 4 | H38: 3 | I38: 24 | J38: 7 | K38: 3 | L38: 0 | M38: 55 | N38: 0 | O38: =SUM(C38:L38,N38) -> 138 | P38: =SUM(C38:N38) -> 193
B39: 14.15 - 14.30 | C39: 23 | D39: 8 | E39: 6 | F39: 32 | G39: 0 | H39: 0 | I39: 19 | J39: 9 | K39: 2 | L39: 2 | M39: 60 | N39: 0 | O39: =SUM(C39:L39,N39) -> 101 | P39: =SUM(C39:N39) -> 161
B40: 14.30 - 14.45 | C40: 36 | D40: 2 | E40: 5 | F40: 51 | G40: 1 | H40: 3 | I40: 37 | J40: 8 | K40: 2 | L40: 4 | M40: 64 | N40: 0 | O40: =SUM(C40:L40,N40) -> 149 | P40: =SUM(C40:N40) -> 213
... B57: 18.45 - 19.00 | C57: 27 | D57: 5 | E57: 6 | F57: 32 | G57: 0 | H57: 0 | I57: 18 | J57: 4 | K57: 0 | L57: 0 | M57: 45 | N57: 0 | O57: =SUM(C57:L57,N57) -> 92 | P57: =SUM(C57:N57) -> 137
B58: Totals | C58: =SUM(C10:C57) -> 1443 | D58: =SUM(D10:D57) -> 367 | E58: =SUM(E10:E57) -> 273 | F58: =SUM(F10:F57) -> 1610 | G58: =SUM(G10:G57) -> 82 | H58: =SUM(H10:H57) -> 50 | I58: =SUM(I10:I57) -> 694 | J58: =SUM(J10:J57) -> 211 | ... P58: =SUM(P10:P57) -> 7932
...

Sheet 24.09 Bombo-Matugga
B1: Consultancy services for Preparation of Expressway Development Master Plan (EDMP) for Uganda
B2: MANUAL CLASSIFIED COUNT (MCC)
B3: ROAD NAME: | C3: MCC-C2-STN67-MATUGGA GAZ
C5: Date | D5: 24.09.19 | F5: Location | G5: GAZ | J5: Surveyor | K5: BABIRYE ROSE
C6: Dir. From | D6: BOMBO | F6: Dir. To | G6: MATUGGA | J6: Supervisor | K6: NUSURAH
B8: Time / Veh Type | R8: SUMMARY TRAFFIC VOLUMES
C9: 1. Car | D9: 2. Station Wagon | E9: 3. Pickups | F9: 4. Minibus, matatu | G9: 5. Medium bus | H9: 6. Large Bus | I9: 7. Light Truck | J9: 8. Medium Truck | K9: 9. Heavy truck | L9: 10. Truck Trailer | M9: 11. Motor cycles | N9: 12. Tractors | O9: Total Excl M/Cycles | P9: Total All | R9: Time | S9: 1. Car | T9: 2. Station Wagon | U9: 3. Pickups | V9: 4. Minibus, matatu | W9: 5. Medium bus | X9: 6. Large Bus | Y9: 7. Light Truck | Z9: 8. Medium Truck | AA9: 9. Heavy truck | AB9: 10. Truck Trailer | AC9: 11. Motorcycles | AD9: 12. Tractors, Graders | AE9: Total Excl M/ Cycles | AF9: Total All
B10: 07.00 - 07.15 | C10: 30 | D10: 5 | E10: 5 | F10: 20 | G10: 0 | H10: 0 | I10: 8 | J10: 4 | K10: 2 | L10: 0 | M10: 92 | N10: 0 | O10: =SUM(C10:L10,N10) -> 74 | P10: =SUM(C10:N10) -> 166 | R10: 0700-0800 | S10: =SUM(C10:C13) -> 110 | T10: =SUM(D10:D13) -> 14 | U10: =SUM(E10:E13) -> 19 | V10: =SUM(F10:F13) -> 106 | W10: =SUM(G10:G13) -> 2 | X10: =SUM(H10:H13) -> 1 | Y10: =SUM(I10:I13) -> 43 | Z10: =SUM(J10:J13) -> 6 | ... AF10: =SUM(P10:P13) -> 720
B11: 07.15 - 07.30 | C11: 21 | D11: 3 | E11: 2 | F11: 27 | G11: 1 | H11: 0 | I11: 12 | J11: 1 | K11: 0 | L11: 0 | M11: 96 | N11: 0 | O11: =SUM(C11:L11,N11) -> 67 | P11: =SUM(C11:N11) -> 163 | R11: 0800-0900 | S11: =SUM(C14:C17) -> 87 | T11: =SUM(D14:D17) -> 16 | U11: =SUM(E14:E17) -> 20 | V11: =SUM(F14:F17) -> 126 | W11: =SUM(G14:G17) -> 2 | X11: =SUM(H14:H17) -> 0 | Y11: =SUM(I14:I17) -> 46 | Z11: =SUM(J14:J17) -> 4 | ... AF11: =SUM(P14:P17) -> 674
B12: 07.30 - 07.45 | C12: 33 | D12: 0 | E12: 7 | F12: 36 | G12: 1 | H12: 0 | I12: 15 | J12: 0 | K12: 0 | L12: 5 | M12: 121 | N12: 0 | O12: =SUM(C12:L12,N12) -> 97 | P12: =SUM(C12:N12) -> 218 | R12: 0900-1000 | S12: =SUM(C18:C21) -> 89 | T12: =SUM(D18:D21) -> 20 | U12: =SUM(E18:E21) -> 15 | V12: =SUM(F18:F21) -> 137 | W12: =SUM(G18:G21) -> 1 | X12: =SUM(H18:H21) -> 1 | Y12: =SUM(I18:I21) -> 55 | Z12: =SUM(J18:J21) -> 4 | ... AF12: =SUM(P18:P21) -> 683
B13: 07.45 - 08.00 | C13: 26 | D13: 6 | E13: 5 | F13: 23 | G13: 0 | H13: 1 | I13: 8 | J13: 1 | K13: 0 | L13: 3 | M13: 100 | N13: 0 | O13: =SUM(C13:L13,N13) -> 73 | P13: =SUM(C13:N13) -> 173 | R13: 1000-1100 | S13: =SUM(C22:C25) -> 91 | T13: =SUM(D22:D25) -> 24 | U13: =SUM(E22:E25) -> 11 | V13: =SUM(F22:F25) -> 128 | W13: =SUM(G22:G25) -> 3 | X13: =SUM(H22:H25) -> 1 | Y13: =SUM(I22:I25) -> 78 | Z13: =SUM(J22:J25) -> 11 | ... AF13: =SUM(P22:P25) -> 689
B14: 08.00 - 08.15 | C14: 28 | D14: 5 | E14: 2 | F14: 35 | G14: 1 | H14: 0 | I14: 16 | J14: 0 | K14: 1 | L14: 2 | M14: 85 | N14: 0 | O14: =SUM(C14:L14,N14) -> 90 | P14: =SUM(C14:N14) -> 175 | R14: 1100-1200 | S14: =SUM(C26:C29) -> 90 | T14: =SUM(D26:D29) -> 21 | U14: =SUM(E26:E29) -> 15 | V14: =SUM(F26:F29) -> 86 | W14: =SUM(G26:G29) -> 2 | X14: =SUM(H26:H29) -> 2 | Y14: =SUM(I26:I29) -> 77 | Z14: =SUM(J26:J29) -> 4 | ... AF14: =SUM(P26:P29) -> 559
B15: 08.15 - 08.30 | C15: 20 | D15: 9 | E15: 9 | F15: 29 | G15: 0 | H15: 0 | I15: 10 | J15: 0 | K15: 0 | L15: 6 | M15: 108 | N15: 0 | O15: =SUM(C15:L15,N15) -> 83 | P15: =SUM(C15:N15) -> 191 | R15: 1200-1300 | S15: =SUM(C30:C33) -> 106 | T15: =SUM(D30:D33) -> 23 | U15: =SUM(E30:E33) -> 29 | V15: =SUM(F30:F33) -> 109 | W15: =SUM(G30:G33) -> 2 | X15: =SUM(H30:H33) -> 1 | Y15: =SUM(I30:I33) -> 78 | Z15: =SUM(J30:J33) -> 6 | ... AF15: =SUM(P30:P33) -> 647
B16: 08.30 - 08.45 | C16: 16 | D16: 1 | E16: 6 | F16: 34 | G16: 1 | H16: 0 | I16: 10 | J16: 2 | K16: 0 | L16: 2 | M16: 85 | N16: 0 | O16: =SUM(C16:L16,N16) -> 72 | P16: =SUM(C16:N16) -> 157 | R16: 1300-1400 | S16: =SUM(C34:C37) -> 114 | T16: =SUM(D34:D37) -> 46 | U16: =SUM(E34:E37) -> 17 | V16: =SUM(F34:F37) -> 120 | W16: =SUM(G34:G37) -> 0 | X16: =SUM(H34:H37) -> 6 | Y16: =SUM(I34:I37) -> 92 | Z16: =SUM(J34:J37) -> 7 | ... AF16: =SUM(P34:P37) -> 700
B17: 08.45 - 9.00 | C17: 23 | D17: 1 | E17: 3 | F17: 28 | G17: 0 | H17: 0 | I17: 10 | J17: 2 | K17: 2 | L17: 2 | M17: 80 | N17: 0 | O17: =SUM(C17:L17,N17) -> 71 | P17: =SUM(C17:N17) -> 151 | R17: 1400-1500 | S17: =SUM(C38:C41) -> 132 | T17: =SUM(D38:D41) -> 32 | U17: =SUM(E38:E41) -> 24 | V17: =SUM(F38:F41) -> 128 | W17: =SUM(G38:G41) -> 1 | X17: =SUM(H38:H41) -> 5 | Y17: =SUM(I38:I41) -> 91 | Z17: =SUM(J38:J41) -> 11 | ... AF17: =SUM(P38:P41) -> 660
B18: 09.00 - 09.15 | C18: 22 | D18: 4 | E18: 5 | F18: 32 | G18: 0 | H18: 0 | I18: 10 | J18: 0 | K18: 0 | L18: 0 | M18: 83 | N18: 0 | O18: =SUM(C18:L18,N18) -> 73 | P18: =SUM(C18:N18) -> 156 | R18: 1500-1600 | S18: =SUM(C42:C45) -> 148 | T18: =SUM(D42:D45) -> 36 | U18: =SUM(E42:E45) -> 30 | V18: =SUM(F42:F45) -> 125 | W18: =SUM(G42:G45) -> 1 | X18: =SUM(H42:H45) -> 6 | Y18: =SUM(I42:I45) -> 90 | Z18: =SUM(J42:J45) -> 27 | ... AF18: =SUM(P42:P45) -> 671
B19: 09.15 - 09.30 | C19: 20 | D19: 6 | E19: 5 | F19: 37 | G19: 0 | H19: 1 | I19: 17 | J19: 2 | K19: 0 | L19: 1 | M19: 111 | N19: 0 | O19: =SUM(C19:L19,N19) -> 89 | P19: =SUM(C19:N19) -> 200 | R19: 1600-1700 | S19: =SUM(C46:C49) -> 160 | T19: =SUM(D46:D49) -> 30 | U19: =SUM(E46:E49) -> 32 | V19: =SUM(F46:F49) -> 141 | W19: =SUM(G46:G49) -> 2 | X19: =SUM(H46:H49) -> 4 | Y19: =SUM(I46:I49) -> 122 | Z19: =SUM(J46:J49) -> 4 | ... AF19: =SUM(P46:P49) -> 708
B20: 09.30 - 09.45 | C20: 23 | D20: 6 | E20: 4 | F20: 32 | G20: 1 | H20: 0 | I20: 12 | J20: 1 | K20: 0 | L20: 2 | M20: 92 | N20: 0 | O20: =SUM(C20:L20,N20) -> 81 | P20: =SUM(C20:N20) -> 173 | R20: 1700-1800 | S20: =SUM(C50:C53) -> 173 | T20: =SUM(D50:D53) -> 35 | U20: =SUM(E50:E53) -> 43 | V20: =SUM(F50:F53) -> 136 | W20: =SUM(G50:G53) -> 3 | X20: =SUM(H50:H53) -> 2 | Y20: =SUM(I50:I53) -> 118 | Z20: =SUM(J50:J53) -> 4 | ... AF20: =SUM(P50:P53) -> 795
B21: 09.45 - 10.00 | C21: 24 | D21: 4 | E21: 1 | F21: 36 | G21: 0 | H21: 0 | I21: 16 | J21: 1 | K21: 0 | L21: 2 | M21: 70 | N21: 0 | O21: =SUM(C21:L21,N21) -> 84 | P21: =SUM(C21:N21) -> 154 | R21: 1800-1900 | S21: =SUM(C54:C57) -> 188 | T21: =SUM(D54:D57) -> 29 | U21: =SUM(E54:E57) -> 32 | V21: =SUM(F54:F57) -> 209 | W21: =SUM(G54:G57) -> 7 | X21: =SUM(H54:H57) -> 5 | Y21: =SUM(I54:I57) -> 70 | Z21: =SUM(J54:J57) -> 8 | ... AF21: =SUM(P54:P57) -> 830
B22: 10.00 - 10.15 | C22: 20 | D22: 2 | E22: 0 | F22: 34 | G22: 1 | H22: 0 | I22: 24 | J22: 5 | K22: 1 | L22: 1 | M22: 77 | N22: 0 | O22: =SUM(C22:L22,N22) -> 88 | P22: =SUM(C22:N22) -> 165 | R22: AM Peak Hr | S22: =MAX(S10:S12) -> 110 | T22: =MAX(T10:T12) -> 20 | U22: =MAX(U10:U12) -> 20 | V22: =MAX(V10:V12) -> 137 | W22: =MAX(W10:W12) -> 2 | X22: =MAX(X10:X12) -> 1 | Y22: =MAX(Y10:Y12) -> 55 | Z22: =MAX(Z10:Z12) -> 6 | ... AF22: =MAX(AF10:AF12) -> 720
B23: 10.15 - 10.30 | C23: 17 | D23: 7 | E23: 2 | F23: 35 | G23: 0 | H23: 1 | I23: 18 | J23: 1 | K23: 0 | L23: 2 | M23: 90 | N23: 0 | O23: =SUM(C23:L23,N23) -> 83 | P23: =SUM(C23:N23) -> 173 | R23: IP Peak Hr | S23: =MAX(S13:S18) -> 148 | T23: =MAX(T13:T18) -> 46 | U23: =MAX(U13:U18) -> 30 | V23: =MAX(V13:V18) -> 128 | W23: =MAX(W13:W18) -> 3 | X23: =MAX(X13:X18) -> 6 | Y23: =MAX(Y13:Y18) -> 92 | Z23: =MAX(Z13:Z18) -> 27 | ... AF23: =MAX(AF13:AF18) -> 700
B24: 10.30 - 10.45 | C24: 31 | D24: 10 | E24: 3 | F24: 36 | G24: 2 | H24: 0 | I24: 29 | J24: 4 | K24: 0 | L24: 1 | M24: 87 | N24: 0 | O24: =SUM(C24:L24,N24) -> 116 | P24: =SUM(C24:N24) -> 203 | R24: PM Peak Hr | S24: =MAX(S19:S21) -> 188 | T24: =MAX(T19:T21) -> 35 | U24: =MAX(U19:U21) -> 43 | V24: =MAX(V19:V21) -> 209 | W24: =MAX(W19:W21) -> 7 | X24: =MAX(X19:X21) -> 5 | Y24: =MAX(Y19:Y21) -> 122 | Z24: =MAX(Z19:Z21) -> 8 | ... AF24: =MAX(AF19:AF21) -> 830
B25: 10.45 - 11.00 | C25: 23 | D25: 5 | E25: 6 | F25: 23 | G25: 0 | H25: 0 | I25: 7 | J25: 1 | K25: 3 | L25: 2 | M25: 78 | N25: 0 | O25: =SUM(C25:L25,N25) -> 70 | P25: =SUM(C25:N25) -> 148 | R25: AM Period | S25: =SUM(S10:S12) -> 286 | T25: =SUM(T10:T12) -> 50 | U25: =SUM(U10:U12) -> 54 | V25: =SUM(V10:V12) -> 369 | W25: =SUM(W10:W12) -> 5 | X25: =SUM(X10:X12) -> 2 | Y25: =SUM(Y10:Y12) -> 144 | Z25: =SUM(Z10:Z12) -> 14 | ... AF25: =SUM(AF10:AF12) -> 2077
B26: 11.00 - 11.15 | C26: 19 | D26: 9 | E26: 2 | F26: 32 | G26: 0 | H26: 1 | I26: 21 | J26: 1 | K26: 1 | L26: 1 | M26: 60 | N26: 0 | O26: =SUM(C26:L26,N26) -> 87 | P26: =SUM(C26:N26) -> 147 | R26: IP Period | S26: =SUM(S13:S18) -> 681 | T26: =SUM(T13:T18) -> 182 | U26: =SUM(U13:U18) -> 126 | V26: =SUM(V13:V18) -> 696 | W26: =SUM(W13:W18) -> 9 | X26: =SUM(X13:X18) -> 21 | Y26: =SUM(Y13:Y18) -> 506 | Z26: =SUM(Z13:Z18) -> 66 | ... AF26: =SUM(AF13:AF18) -> 3926
B27: 11.15 - 11.30 | C27: 15 | D27: 4 | E27: 3 | F27: 3 | G27: 1 | H27: 0 | I27: 24 | J27: 3 | K27: 2 | L27: 1 | M27: 70 | N27: 0 | O27: =SUM(C27:L27,N27) -> 56 | P27: =SUM(C27:N27) -> 126 | R27: PM Period | S27: =SUM(S19:S21) -> 521 | T27: =SUM(T19:T21) -> 94 | U27: =SUM(U19:U21) -> 107 | V27: =SUM(V19:V21) -> 486 | W27: =SUM(W19:W21) -> 12 | X27: =SUM(X19:X21) -> 11 | Y27: =SUM(Y19:Y21) -> 310 | Z27: =SUM(Z19:Z21) -> 16 | ... AF27: =SUM(AF19:AF21) -> 2333
B28: 11.30 - 11.45 | C28: 27 | D28: 3 | E28: 5 | F28: 22 | G28: 0 | H28: 0 | I28: 13 | J28: 0 | K28: 0 | L28: 0 | M28: 63 | N28: 0 | O28: =SUM(C28:L28,N28) -> 70 | P28: =SUM(C28:N28) -> 133 | R28: 12 Hours | S28: =SUM(S10:S21) -> 1488 | T28: =SUM(T10:T21) -> 326 | U28: =SUM(U10:U21) -> 287 | V28: =SUM(V10:V21) -> 1551 | W28: =SUM(W10:W21) -> 26 | X28: =SUM(X10:X21) -> 34 | Y28: =SUM(Y10:Y21) -> 960 | Z28: =SUM(Z10:Z21) -> 96 | ... AF28: =SUM(AF10:AF21) -> 8336
B29: 11.45 - 12.00 | C29: 29 | D29: 5 | E29: 5 | F29: 29 | G29: 1 | H29: 1 | I29: 19 | J29: 0 | K29: 0 | L29: 2 | M29: 62 | N29: 0 | O29: =SUM(C29:L29,N29) -> 91 | P29: =SUM(C29:N29) -> 153
B30: 12.00 - 12.15 | C30: 25 | D30: 4 | E30: 10 | F30: 29 | G30: 0 | H30: 0 | I30: 26 | J30: 1 | K30: 0 | L30: 1 | M30: 80 | N30: 0 | O30: =SUM(C30:L30,N30) -> 96 | P30: =SUM(C30:N30) -> 176
B31: 12.15 - 12.30 | C31: 24 | D31: 7 | E31: 7 | F31: 21 | G31: 0 | H31: 0 | I31: 11 | J31: 0 | K31: 1 | L31: 1 | M31: 56 | N31: 0 | O31: =SUM(C31:L31,N31) -> 72 | P31: =SUM(C31:N31) -> 128
B32: 12.30 - 12.45 | C32: 21 | D32: 7 | E32: 6 | F32: 29 | G32: 0 | H32: 1 | I32: 19 | J32: 3 | K32: 0 | L32: 2 | M32: 74 | N32: 0 | O32: =SUM(C32:L32,N32) -> 88 | P32: =SUM(C32:N32) -> 162
B33: 12.45 - 13.00 | C33: 36 | D33: 5 | E33: 6 | F33: 30 | G33: 2 | H33: 0 | I33: 22 | J33: 2 | K33: 0 | L33: 0 | M33: 78 | N33: 0 | O33: =SUM(C33:L33,N33) -> 103 | P33: =SUM(C33:N33) -> 181
B34: 13.00 - 13.15 | C34: 22 | D34: 9 | E34: 4 | F34: 25 | G34: 0 | H34: 0 | I34: 19 | J34: 1 | K34: 0 | L34: 0 | M34: 78 | N34: 0 | O34: =SUM(C34:L34,N34) -> 80 | P34: =SUM(C34:N34) -> 158
B35: 13.15 - 13.30 | C35: 26 | D35: 6 | E35: 5 | F35: 25 | G35: 0 | H35: 0 | I35: 24 | J35: 1 | K35: 0 | L35: 1 | M35: 84 | N35: 0 | O35: =SUM(C35:L35,N35) -> 88 | P35: =SUM(C35:N35) -> 172
B36: 13.30 - 13.45 | C36: 45 | D36: 15 | E36: 6 | F36: 40 | G36: 0 | H36: 3 | I36: 27 | J36: 2 | K36: 2 | L36: 3 | M36: 65 | N36: 1 | O36: =SUM(C36:L36,N36) -> 144 | P36: =SUM(C36:N36) -> 209
B37: 13.45 - 14.00 | C37: 21 | D37: 16 | E37: 2 | F37: 30 | G37: 0 | H37: 3 | I37: 22 | J37: 3 | K37: 2 | L37: 2 | M37: 60 | N37: 0 | O37: =SUM(C37:L37,N37) -> 101 | P37: =SUM(C37:N37) -> 161
B38: 14.00 - 14.15 | C38: 27 | D38: 11 | E38: 10 | F38: 34 | G38: 0 | H38: 0 | I38: 17 | J38: 3 | K38: 0 | L38: 3 | M38: 55 | N38: 0 | O38: =SUM(C38:L38,N38) -> 105 | P38: =SUM(C38:N38) -> 160
B39: 14.15 - 14.30 | C39: 30 | D39: 7 | E39: 4 | F39: 35 | G39: 0 | H39: 1 | I39: 34 | J39: 0 | K39: 2 | L39: 0 | M39: 60 | N39: 0 | O39: =SUM(C39:L39,N39) -> 113 | P39: =SUM(C39:N39) -> 173
B40: 14.30 - 14.45 | C40: 31 | D40: 8 | E40: 8 | F40: 29 | G40: 1 | H40: 3 | I40: 25 | J40: 4 | K40: 0 | L40: 4 | M40: 55 | N40: 2 | O40: =SUM(C40:L40,N40) -> 115 | P40: =SUM(C40:N40) -> 170
... B57: 18.45 - 19.00 | C57: 50 | D57: 5 | E57: 10 | F57: 60 | G57: 2 | H57: 0 | I57: 23 | J57: 2 | K57: 1 | L57: 1 | M57: 80 | N57: 0 | O57: =SUM(C57:L57,N57) -> 154 | P57: =SUM(C57:N57) -> 234
B58: Totals | C58: =SUM(C10:C57) -> 1488 | D58: =SUM(D10:D57) -> 326 | E58: =SUM(E10:E57) -> 287 | F58: =SUM(F10:F57) -> 1551 | G58: =SUM(G10:G57) -> 26 | H58: =SUM(H10:H57) -> 34 | I58: =SUM(I10:I57) -> 960 | J58: =SUM(J10:J57) -> 96 | ... P58: =SUM(P10:P57) -> 8336
...

Sheet 24.09 Matugga-Bombo
B1: Consultancy services for Preparation of Expressway Development Master Plan (EDMP) for Uganda
B2: MANUAL CLASSIFIED COUNT (MCC)
B3: ROAD NAME: | C3: ='[1]24.09.2019 BOMBO-MATUGGA'!C3:G3 -> MCC-C2-STN67-MATUGGA GAZ
C5: Date | D5: ='[1]24.09.2019 BOMBO-MATUGGA'!D5 -> 24.09.19 | F5: Location | G5: GAZ | J5: Surveyor | K5: SANDRA MUKISA
C6: Dir. From | D6: MATUGGA | F6: Dir. To | G6: BOMBO | J6: Supervisor | K6: NUSURAH
B8: Time / Veh Type | R8: SUMMARY TRAFFIC VOLUMES
C9: 1. Car | D9: 2. Station Wagon | E9: 3. Pickups | F9: 4. Minibus, matatu | G9: 5. Medium bus | H9: 6. Large Bus | I9: 7. Light Truck | J9: 8. Medium Truck | K9: 9. Heavy truck | L9: 10. Truck Trailer | M9: 11. Motor cycles | N9: 12. Tractors | O9: Total Excl M/Cycles | P9: Total All | R9: Time | S9: 1. Car | T9: 2. Station Wagon | U9: 3. Pickups | V9: 4. Minibus, matatu | W9: 5. Medium bus | X9: 6. Large Bus | Y9: 7. Light Truck | Z9: 8. Medium Truck | AA9: 9. Heavy truck | AB9: 10. Truck Trailer | AC9: 11. Motorcycles | AD9: 12. Tractors, Graders | AE9: Total Excl M/ Cycles | AF9: Total All
B10: 07.00 - 07.15 | C10: 19 | D10: 7 | E10: 1 | F10: 9 | G10: 0 | H10: 0 | I10: 6 | J10: 1 | K10: 2 | L10: 0 | M10: 90 | N10: 0 | O10: =SUM(C10:L10,N10) -> 45 | P10: =SUM(C10:N10) -> 135 | R10: 0700-0800 | S10: =SUM(C10:C13) -> 130 | T10: =SUM(D10:D13) -> 31 | U10: =SUM(E10:E13) -> 34 | V10: =SUM(F10:F13) -> 106 | W10: =SUM(G10:G13) -> 2 | X10: =SUM(H10:H13) -> 1 | Y10: =SUM(I10:I13) -> 46 | Z10: =SUM(J10:J13) -> 16 | ... AF10: =SUM(P10:P13) -> 790
B11: 07.15 - 07.30 | C11: 38 | D11: 7 | E11: 8 | F11: 32 | G11: 1 | H11: 0 | I11: 15 | J11: 3 | K11: 4 | L11: 3 | M11: 123 | N11: 0 | O11: =SUM(C11:L11,N11) -> 111 | P11: =SUM(C11:N11) -> 234 | R11: 0800-0900 | S11: =SUM(C14:C17) -> 142 | T11: =SUM(D14:D17) -> 39 | U11: =SUM(E14:E17) -> 34 | V11: =SUM(F14:F17) -> 142 | W11: =SUM(G14:G17) -> 3 | X11: =SUM(H14:H17) -> 4 | Y11: =SUM(I14:I17) -> 54 | Z11: =SUM(J14:J17) -> 16 | ... AF11: =SUM(P14:P17) -> 841
B12: 07.30 - 07.45 | C12: 34 | D12: 5 | E12: 10 | F12: 29 | G12: 0 | H12: 1 | I12: 12 | J12: 2 | K12: 1 | L12: 1 | M12: 80 | N12: 0 | O12: =SUM(C12:L12,N12) -> 95 | P12: =SUM(C12:N12) -> 175 | R12: 0900-1000 | S12: =SUM(C18:C21) -> 145 | T12: =SUM(D18:D21) -> 52 | U12: =SUM(E18:E21) -> 33 | V12: =SUM(F18:F21) -> 168 | W12: =SUM(G18:G21) -> 1 | X12: =SUM(H18:H21) -> 2 | Y12: =SUM(I18:I21) -> 88 | Z12: =SUM(J18:J21) -> 23 | ... AF12: =SUM(P18:P21) -> 875
B13: 07.45 - 08.00 | C13: 39 | D13: 12 | E13: 15 | F13: 36 | G13: 1 | H13: 0 | I13: 13 | J13: 10 | K13: 4 | L13: 1 | M13: 115 | N13: 0 | O13: =SUM(C13:L13,N13) -> 131 | P13: =SUM(C13:N13) -> 246 | R13: 1000-1100 | S13: =SUM(C22:C25) -> 108 | T13: =SUM(D22:D25) -> 64 | U13: =SUM(E22:E25) -> 27 | V13: =SUM(F22:F25) -> 139 | W13: =SUM(G22:G25) -> 0 | X13: =SUM(H22:H25) -> 6 | Y13: =SUM(I22:I25) -> 72 | Z13: =SUM(J22:J25) -> 26 | ... AF13: =SUM(P22:P25) -> 796
B14: 08.00 - 08.15 | C14: 56 | D14: 5 | E14: 8 | F14: 39 | G14: 1 | H14: 2 | I14: 21 | J14: 3 | K14: 2 | L14: 1 | M14: 113 | N14: 0 | O14: =SUM(C14:L14,N14) -> 138 | P14: =SUM(C14:N14) -> 251 | R14: 1100-1200 | S14: =SUM(C26:C29) -> 78 | T14: =SUM(D26:D29) -> 29 | U14: =SUM(E26:E29) -> 24 | V14: =SUM(F26:F29) -> 92 | W14: =SUM(G26:G29) -> 0 | X14: =SUM(H26:H29) -> 1 | Y14: =SUM(I26:I29) -> 71 | Z14: =SUM(J26:J29) -> 27 | ... AF14: =SUM(P26:P29) -> 603
B15: 08.15 - 08.30 | C15: 31 | D15: 12 | E15: 10 | F15: 36 | G15: 1 | H15: 1 | I15: 15 | J15: 4 | K15: 1 | L15: 3 | M15: 108 | N15: 0 | O15: =SUM(C15:L15,N15) -> 114 | P15: =SUM(C15:N15) -> 222 | R15: 1200-1300 | S15: =SUM(C30:C33) -> 132 | T15: =SUM(D30:D33) -> 52 | U15: =SUM(E30:E33) -> 37 | V15: =SUM(F30:F33) -> 134 | W15: =SUM(G30:G33) -> 2 | X15: =SUM(H30:H33) -> 10 | Y15: =SUM(I30:I33) -> 81 | Z15: =SUM(J30:J33) -> 34 | ... AF15: =SUM(P30:P33) -> 773
B16: 08.30 - 08.45 | C16: 24 | D16: 10 | E16: 7 | F16: 31 | G16: 1 | H16: 0 | I16: 8 | J16: 5 | K16: 3 | L16: 0 | M16: 65 | N16: 0 | O16: =SUM(C16:L16,N16) -> 89 | P16: =SUM(C16:N16) -> 154 | R16: 1300-1400 | S16: =SUM(C34:C38) -> 134 | T16: =SUM(D34:D38) -> 44 | U16: =SUM(E34:E38) -> 58 | V16: =SUM(F34:F38) -> 199 | W16: =SUM(G34:G38) -> 1 | X16: =SUM(H34:H38) -> 10 | Y16: =SUM(I34:I38) -> 110 | Z16: =SUM(J34:J38) -> 30 | ... AC16: =SUM(M34:M38) -> 357 | AD16: =SUM(N34:N37) -> 1 | AE16: =SUM(O34:O37) -> 501 | AF16: =SUM(P34:P37) -> 787
B17: 08.45 - 9.00 | C17: 31 | D17: 12 | E17: 9 | F17: 36 | G17: 0 | H17: 1 | I17: 10 | J17: 4 | K17: 3 | L17: 3 | M17: 105 | N17: 0 | O17: =SUM(C17:L17,N17) -> 109 | P17: =SUM(C17:N17) -> 214 | R17: 1400-1500 | S17: =SUM(C39:C42) -> 123 | T17: =SUM(D39:D42) -> 31 | U17: =SUM(E39:E42) -> 32 | V17: =SUM(F39:F42) -> 147 | W17: =SUM(G39:G42) -> 2 | X17: =SUM(H39:H42) -> 2 | Y17: =SUM(I39:I42) -> 72 | Z17: =SUM(J39:J42) -> 42 | ... AC17: =SUM(M39:M42) -> 245 | AD17: =SUM(N38:N41) -> 2 | AE17: =SUM(O38:O41) -> 473 | AF17: =SUM(P38:P41) -> 744
B18: 09.00 - 09.15 | C18: 34 | D18: 14 | E18: 9 | F18: 30 | G18: 0 | H18: 1 | I18: 18 | J18: 4 | K18: 5 | L18: 3 | M18: 99 | N18: 0 | O18: =SUM(C18:L18,N18) -> 118 | P18: =SUM(C18:N18) -> 217 | R18: 1500-1600 | S18: =SUM(C43:C46) -> 104 | T18: =SUM(D43:D46) -> 45 | U18: =SUM(E43:E46) -> 35 | V18: =SUM(F43:F46) -> 124 | W18: =SUM(G43:G46) -> 0 | X18: =SUM(H43:H46) -> 2 | Y18: =SUM(I43:I46) -> 75 | Z18: =SUM(J43:J46) -> 25 | ... AC18: =SUM(M43:M46) -> 242 | AD18: =SUM(N42:N45) -> 0 | AE18: =SUM(O42:O45) -> 453 | AF18: =SUM(P42:P45) -> 680
B19: 09.15 - 09.30 | C19: 35 | D19: 15 | E19: 6 | F19: 41 | G19: 1 | H19: 0 | I19: 29 | J19: 7 | K19: 4 | L19: 0 | M19: 85 | N19: 0 | O19: =SUM(C19:L19,N19) -> 138 | P19: =SUM(C19:N19) -> 223 | R19: 1600-1700 | S19: =SUM(C47:C50) -> 122 | T19: =SUM(D47:D50) -> 25 | U19: =SUM(E47:E50) -> 19 | V19: =SUM(F47:F50) -> 147 | W19: =SUM(G47:G50) -> 1 | X19: =SUM(H47:H50) -> 5 | Y19: =SUM(I47:I50) -> 89 | Z19: =SUM(J47:J50) -> 40 | ... AC19: =SUM(M47:M50) -> 263 | AD19: =SUM(N46:N49) -> 0 | AE19: =SUM(O46:O49) -> 456 | AF19: =SUM(P46:P49) -> 704
B20: 09.30 - 09.45 | C20: 40 | D20: 14 | E20: 9 | F20: 61 | G20: 0 | H20: 1 | I20: 17 | J20: 6 | K20: 2 | L20: 1 | M20: 80 | N20: 0 | O20: =SUM(C20:L20,N20) -> 151 | P20: =SUM(C20:N20) -> 231 | R20: 1700-1800 | S20: =SUM(C51:C53) -> 88 | T20: =SUM(D51:D53) -> 26 | U20: =SUM(E51:E53) -> 17 | V20: =SUM(F51:F53) -> 129 | W20: =SUM(G51:G53) -> 0 | X20: =SUM(H51:H53) -> 2 | Y20: =SUM(I51:I53) -> 45 | Z20: =SUM(J51:J53) -> 20 | ... AC20: =SUM(M51:M53) -> 229 | AD20: =SUM(N50:N53) -> 0 | AE20: =SUM(O50:O53) -> 460 | AF20: =SUM(P50:P53) -> 764
B21: 09.45 - 10.00 | C21: 36 | D21: 9 | E21: 9 | F21: 36 | G21: 0 | H21: 0 | I21: 24 | J21: 6 | K21: 3 | L21: 0 | M21: 81 | N21: 0 | O21: =SUM(C21:L21,N21) -> 123 | P21: =SUM(C21:N21) -> 204 | R21: 1800-1900 | S21: =SUM(C54:C57) -> 134 | T21: =SUM(D54:D57) -> 30 | U21: =SUM(E54:E57) -> 20 | V21: =SUM(F54:F57) -> 183 | W21: =SUM(G54:G57) -> 4 | X21: =SUM(H54:H57) -> 2 | Y21: =SUM(I54:I57) -> 38 | Z21: =SUM(J54:J57) -> 22 | ... AF21: =SUM(P54:P57) -> 702
B22: 10.00 - 10.15 | C22: 40 | D22: 16 | E22: 10 | F22: 41 | G22: 0 | H22: 0 | I22: 13 | J22: 3 | K22: 2 | L22: 1 | M22: 90 | N22: 0 | O22: =SUM(C22:L22,N22) -> 126 | P22: =SUM(C22:N22) -> 216 | R22: AM Peak Hr | S22: =MAX(S10:S12) -> 145 | T22: =MAX(T10:T12) -> 52 | U22: =MAX(U10:U12) -> 34 | V22: =MAX(V10:V12) -> 168 | W22: =MAX(W10:W12) -> 3 | X22: =MAX(X10:X12) -> 4 | Y22: =MAX(Y10:Y12) -> 88 | Z22: =MAX(Z10:Z12) -> 23 | ... AF22: =MAX(AF10:AF12) -> 875
B23: 10.15 - 10.30 | C23: 18 | D23: 20 | E23: 4 | F23: 28 | G23: 0 | H23: 3 | I23: 15 | J23: 10 | K23: 6 | L23: 4 | M23: 75 | N23: 0 | O23: =SUM(C23:L23,N23) -> 108 | P23: =SUM(C23:N23) -> 183 | R23: IP Peak Hr | S23: =MAX(S13:S18) -> 134 | T23: =MAX(T13:T18) -> 64 | U23: =MAX(U13:U18) -> 58 | V23: =MAX(V13:V18) -> 199 | W23: =MAX(W13:W18) -> 2 | X23: =MAX(X13:X18) -> 10 | Y23: =MAX(Y13:Y18) -> 110 | Z23: =MAX(Z13:Z18) -> 42 | ... AF23: =MAX(AF13:AF18) -> 796
B24: 10.30 - 10.45 | C24: 23 | D24: 13 | E24: 3 | F24: 26 | G24: 0 | H24: 3 | I24: 24 | J24: 5 | K24: 3 | L24: 4 | M24: 92 | N24: 0 | O24: =SUM(C24:L24,N24) -> 104 | P24: =SUM(C24:N24) -> 196 | R24: PM Peak Hr | S24: =MAX(S19:S21) -> 134 | T24: =MAX(T19:T21) -> 30 | U24: =MAX(U19:U21) -> 20 | V24: =MAX(V19:V21) -> 183 | W24: =MAX(W19:W21) -> 4 | X24: =MAX(X19:X21) -> 5 | Y24: =MAX(Y19:Y21) -> 89 | Z24: =MAX(Z19:Z21) -> 40 | ... AF24: =MAX(AF19:AF21) -> 764
B25: 10.45 - 11.00 | C25: 27 | D25: 15 | E25: 10 | F25: 44 | G25: 0 | H25: 0 | I25: 20 | J25: 8 | K25: 1 | L25: 1 | M25: 74 | N25: 1 | O25: =SUM(C25:L25,N25) -> 127 | P25: =SUM(C25:N25) -> 201 | R25: AM Period | S25: =SUM(S10:S12) -> 417 | T25: =SUM(T10:T12) -> 122 | U25: =SUM(U10:U12) -> 101 | V25: =SUM(V10:V12) -> 416 | W25: =SUM(W10:W12) -> 6 | X25: =SUM(X10:X12) -> 7 | Y25: =SUM(Y10:Y12) -> 188 | Z25: =SUM(Z10:Z12) -> 55 | ... AF25: =SUM(AF10:AF12) -> 2506
B26: 11.00 - 11.15 | C26: 12 | D26: 5 | E26: 1 | F26: 18 | G26: 0 | H26: 0 | I26: 15 | J26: 7 | K26: 2 | L26: 1 | M26: 80 | N26: 0 | O26: =SUM(C26:L26,N26) -> 61 | P26: =SUM(C26:N26) -> 141 | R26: IP Period | S26: =SUM(S13:S18) -> 679 | T26: =SUM(T13:T18) -> 265 | U26: =SUM(U13:U18) -> 213 | V26: =SUM(V13:V18) -> 835 | W26: =SUM(W13:W18) -> 5 | X26: =SUM(X13:X18) -> 31 | Y26: =SUM(Y13:Y18) -> 481 | Z26: =SUM(Z13:Z18) -> 184 | ... AF26: =SUM(AF13:AF18) -> 4383
B27: 11.15 - 11.30 | C27: 15 | D27: 4 | E27: 10 | F27: 17 | G27: 0 | H27: 0 | I27: 17 | J27: 3 | K27: 5 | L27: 1 | M27: 61 | N27: 0 | O27: =SUM(C27:L27,N27) -> 72 | P27: =SUM(C27:N27) -> 133 | R27: PM Period | S27: =SUM(S19:S21) -> 344 | T27: =SUM(T19:T21) -> 81 | U27: =SUM(U19:U21) -> 56 | V27: =SUM(V19:V21) -> 459 | W27: =SUM(W19:W21) -> 5 | X27: =SUM(X19:X21) -> 9 | Y27: =SUM(Y19:Y21) -> 172 | Z27: =SUM(Z19:Z21) -> 82 | ... AF27: =SUM(AF19:AF21) -> 2170
B28: 11.30 - 11.45 | C28: 24 | D28: 11 | E28: 5 | F28: 24 | G28: 0 | H28: 1 | I28: 18 | J28: 9 | K28: 2 | L28: 1 | M28: 45 | N28: 0 | O28: =SUM(C28:L28,N28) -> 95 | P28: =SUM(C28:N28) -> 140 | R28: 12 Hours | S28: =SUM(S10:S21) -> 1440 | T28: =SUM(T10:T21) -> 468 | U28: =SUM(U10:U21) -> 370 | V28: =SUM(V10:V21) -> 1710 | W28: =SUM(W10:W21) -> 16 | X28: =SUM(X10:X21) -> 47 | Y28: =SUM(Y10:Y21) -> 841 | Z28: =SUM(Z10:Z21) -> 321 | ... AF28: =SUM(AF10:AF21) -> 9059
B29: 11.45 - 12.00 | C29: 27 | D29: 9 | E29: 8 | F29: 33 | G29: 0 | H29: 0 | I29: 21 | J29: 8 | K29: 0 | L29: 1 | M29: 82 | N29: 0 | O29: =SUM(C29:L29,N29) -> 107 | P29: =SUM(C29:N29) -> 189
B30: 12.00 - 12.15 | C30: 38 | D30: 13 | E30: 14 | F30: 33 | G30: 1 | H30: 3 | I30: 21 | J30: 11 | K30: 1 | L30: 1 | M30: 54 | N30: 0 | O30: =SUM(C30:L30,N30) -> 136 | P30: =SUM(C30:N30) -> 190
B31: 12.15 - 12.30 | C31: 34 | D31: 12 | E31: 5 | F31: 42 | G31: 0 | H31: 1 | I31: 17 | J31: 7 | K31: 4 | L31: 0 | M31: 65 | N31: 0 | O31: =SUM(C31:L31,N31) -> 122 | P31: =SUM(C31:N31) -> 187
B32: 12.30 - 12.45 | C32: 35 | D32: 13 | E32: 9 | F32: 29 | G32: 0 | H32: 4 | I32: 24 | J32: 8 | K32: 4 | L32: 3 | M32: 72 | N32: 0 | O32: =SUM(C32:L32,N32) -> 129 | P32: =SUM(C32:N32) -> 201
B33: 12.45 - 13.00 | C33: 25 | D33: 14 | E33: 9 | F33: 30 | G33: 1 | H33: 2 | I33: 19 | J33: 8 | K33: 5 | L33: 2 | M33: 80 | N33: 0 | O33: =SUM(C33:L33,N33) -> 115 | P33: =SUM(C33:N33) -> 195
B34: 13.00 - 13.15 | C34: 24 | D34: 5 | E34: 6 | F34: 51 | G34: 0 | H34: 3 | I34: 26 | J34: 8 | K34: 1 | L34: 3 | M34: 73 | N34: 0 | O34: =SUM(C34:L34,N34) -> 127 | P34: =SUM(C34:N34) -> 200
B35: 13.15 - 13.30 | C35: 32 | D35: 7 | E35: 14 | F35: 26 | G35: 0 | H35: 1 | I35: 17 | J35: 2 | K35: 1 | L35: 2 | M35: 69 | N35: 0 | O35: =SUM(C35:L35,N35) -> 102 | P35: =SUM(C35:N35) -> 171
B36: 13.30 - 13.45 | C36: 34 | D36: 6 | E36: 14 | F36: 44 | G36: 1 | H36: 2 | I36: 21 | J36: 5 | K36: 2 | L36: 4 | M36: 85 | N36: 1 | O36: =SUM(C36:L36,N36) -> 134 | P36: =SUM(C36:N36) -> 219
B37: 13.45 - 14.00 | C37: 23 | D37: 14 | E37: 17 | F37: 45 | G37: 0 | H37: 4 | I37: 20 | J37: 7 | K37: 1 | L37: 7 | M37: 59 | N37: 0 | O37: =SUM(C37:L37,N37) -> 138 | P37: =SUM(C37:N37) -> 197
B38: 14.00 - 14.15 | C38: 21 | D38: 12 | E38: 7 | F38: 33 | G38: 0 | H38: 0 | I38: 26 | J38: 8 | K38: 3 | L38: 5 | M38: 71 | N38: 2 | O38: =SUM(C38:L38,N38) -> 117 | P38: =SUM(C38:N38) -> 188
B39: 14.15 - 14.30 | C39: 38 | D39: 10 | E39: 6 | F39: 40 | G39: 2 | H39: 0 | I39: 16 | J39: 10 | K39: 5 | L39: 3 | M39: 80 | N39: 0 | O39: =SUM(C39:L39,N39) -> 130 | P39: =SUM(C39:N39) -> 210
B40: 14.30 - 14.45 | C40: 23 | D40: 4 | E40: 5 | F40: 30 | G40: 0 | H40: 1 | I40: 21 | J40: 6 | K40: 3 | L40: 3 | M40: 50 | N40: 0 | O40: =SUM(C40:L40,N40) -> 96 | P40: =SUM(C40:N40) -> 146
... B57: 18.45 - 19.00 | C57: 33 | D57: 11 | E57: 5 | F57: 52 | G57: 0 | H57: 0 | I57: 8 | J57: 7 | K57: 1 | L57: 2 | M57: 60 | N57: 0 | O57: =SUM(C57:L57,N57) -> 119 | P57: =SUM(C57:N57) -> 179
B58: Totals | C58: =SUM(C10:C57) -> 1440 | D58: =SUM(D10:D57) -> 468 | E58: =SUM(E10:E57) -> 370 | F58: =SUM(F10:F57) -> 1710 | G58: =SUM(G10:G57) -> 16 | H58: =SUM(H10:H57) -> 47 | I58: =SUM(I10:I57) -> 841 | J58: =SUM(J10:J57) -> 321 | ... N58: =SUM(N10:N57) -> 4 | O58: =SUM(C58:L58,N58) -> 5466 | P58: =SUM(P10:P57) -> 9059
...

Sheet 25.09 Bombo-Matugga
B1: Consultancy services for Preparation of Expressway Development Master Plan (EDMP) for Uganda
B2: MANUAL CLASSIFIED COUNT (MCC)
B3: ROAD NAME: | C3: MCC-C2-STN67-BOMBO ROAD
C5: Date | D5: 25.09.19 | F5: Location | G5: MATUGGA GAZ | J5: Surveyor | K5: BABIRYE. R
C6: Dir. From | D6: BOMBO | F6: Dir. To | G6: MATUGGA | J6: Supervisor | K6: NUSURAH
B8: Time / Veh Type | R8: SUMMARY TRAFFIC VOLUMES
C9: 1. Car | D9: 2. Station Wagon | E9: 3. Pickups | F9: 4. Minibus, matatu | G9: 5. Medium bus | H9: 6. Large Bus | I9: 7. Light Truck | J9: 8. Medium Truck | K9: 9. Heavy truck | L9: 10. Truck Trailer | M9: 11. Motor cycles | N9: 12. Tractors | O9: Total Excl M/Cycles | P9: Total All | R9: Time | S9: 1. Car | T9: 2. Station Wagon | U9: 3. Pickups | V9: 4. Minibus, matatu | W9: 5. Medium bus | X9: 6. Large Bus | Y9: 7. Light Truck | Z9: 8. Medium Truck | AA9: 9. Heavy truck | AB9: 10. Truck Trailer | AC9: 11. Motorcycles | AD9: 12. Tractors, Graders | AE9: Total Excl M/ Cycles | AF9: Total All
B10: 07.00 - 07.15 | C10: 22 | D10: 2 | E10: 0 | F10: 28 | G10: 0 | H10: 1 | I10: 7 | J10: 1 | K10: 0 | L10: 2 | M10: 75 | N10: 0 | O10: =SUM(C10:L10,N10) -> 63 | P10: =SUM(C10:N10) -> 138 | R10: 0700-0800 | S10: =SUM(C10:C13) -> 102 | T10: =SUM(D10:D13) -> 12 | U10: =SUM(E10:E13) -> 11 | V10: =SUM(F10:F13) -> 153 | W10: =SUM(G10:G13) -> 1 | X10: =SUM(H10:H13) -> 2 | Y10: =SUM(I10:I13) -> 39 | Z10: =SUM(J10:J13) -> 3 | ... AF10: =SUM(P10:P13) -> 634
B11: 07.15 - 07.30 | C11: 39 | D11: 5 | E11: 3 | F11: 40 | G11: 1 | H11: 0 | I11: 9 | J11: 0 | K11: 2 | L11: 1 | M11: 88 | N11: 0 | O11: =SUM(C11:L11,N11) -> 100 | P11: =SUM(C11:N11) -> 188 | R11: 0800-0900 | S11: =SUM(C14:C17) -> 97 | T11: =SUM(D14:D17) -> 17 | U11: =SUM(E14:E17) -> 11 | V11: =SUM(F14:F17) -> 140 | W11: =SUM(G14:G17) -> 0 | X11: =SUM(H14:H17) -> 1 | Y11: =SUM(I14:I17) -> 44 | Z11: =SUM(J14:J17) -> 4 | ... AF11: =SUM(P14:P17) -> 602
B12: 07.30 - 07.45 | C12: 18 | D12: 4 | E12: 4 | F12: 45 | G12: 0 | H12: 0 | I12: 13 | J12: 2 | K12: 0 | L12: 0 | M12: 85 | N12: 0 | O12: =SUM(C12:L12,N12) -> 86 | P12: =SUM(C12:N12) -> 171 | R12: 0900-1000 | S12: =SUM(C18:C21) -> 52 | T12: =SUM(D18:D21) -> 8 | U12: =SUM(E18:E21) -> 10 | V12: =SUM(F18:F21) -> 107 | W12: =SUM(G18:G21) -> 1 | X12: =SUM(H18:H21) -> 1 | Y12: =SUM(I18:I21) -> 69 | Z12: =SUM(J18:J21) -> 3 | ... AF12: =SUM(P18:P21) -> 531
B13: 07.45 - 08.00 | C13: 23 | D13: 1 | E13: 4 | F13: 40 | G13: 0 | H13: 1 | I13: 10 | J13: 0 | K13: 0 | L13: 0 | M13: 58 | N13: 0 | O13: =SUM(C13:L13,N13) -> 79 | P13: =SUM(C13:N13) -> 137 | R13: 1000-1100 | S13: =SUM(C22:C25) -> 111 | T13: =SUM(D22:D25) -> 21 | U13: =SUM(E22:E25) -> 18 | V13: =SUM(F22:F25) -> 125 | W13: =SUM(G22:G25) -> 0 | X13: =SUM(H22:H25) -> 1 | Y13: =SUM(I22:I25) -> 70 | Z13: =SUM(J22:J25) -> 4 | ... AF13: =SUM(P22:P25) -> 704
B14: 08.00 - 08.15 | C14: 25 | D14: 5 | E14: 5 | F14: 39 | G14: 0 | H14: 0 | I14: 7 | J14: 1 | K14: 0 | L14: 1 | M14: 78 | N14: 0 | O14: =SUM(C14:L14,N14) -> 83 | P14: =SUM(C14:N14) -> 161 | R14: 1100-1200 | S14: =SUM(C26:C29) -> 78 | T14: =SUM(D26:D29) -> 31 | U14: =SUM(E26:E29) -> 14 | V14: =SUM(F26:F29) -> 99 | W14: =SUM(G26:G29) -> 3 | X14: =SUM(H26:H29) -> 0 | Y14: =SUM(I26:I29) -> 61 | Z14: =SUM(J26:J29) -> 10 | ... AF14: =SUM(P26:P29) -> 599
B15: 08.15 - 08.30 | C15: 25 | D15: 5 | E15: 2 | F15: 33 | G15: 0 | H15: 0 | I15: 12 | J15: 1 | K15: 0 | L15: 2 | M15: 61 | N15: 0 | O15: =SUM(C15:L15,N15) -> 80 | P15: =SUM(C15:N15) -> 141 | R15: 1200-1300 | S15: =SUM(C30:C33) -> 92 | T15: =SUM(D30:D33) -> 24 | U15: =SUM(E30:E33) -> 19 | V15: =SUM(F30:F33) -> 90 | W15: =SUM(G30:G33) -> 0 | X15: =SUM(H30:H33) -> 3 | Y15: =SUM(I30:I33) -> 60 | Z15: =SUM(J30:J33) -> 19 | ... AF15: =SUM(P30:P33) -> 497
B16: 08.30 - 08.45 | C16: 27 | D16: 4 | E16: 3 | F16: 40 | G16: 0 | H16: 0 | I16: 12 | J16: 2 | K16: 1 | L16: 1 | M16: 68 | N16: 0 | O16: =SUM(C16:L16,N16) -> 90 | P16: =SUM(C16:N16) -> 158 | R16: 1300-1400 | S16: =SUM(C34:C37) -> 100 | T16: =SUM(D34:D37) -> 21 | U16: =SUM(E34:E37) -> 12 | V16: =SUM(F34:F37) -> 132 | W16: =SUM(G34:G37) -> 3 | X16: =SUM(H34:H37) -> 4 | Y16: =SUM(I34:I37) -> 129 | Z16: =SUM(J34:J37) -> 12 | ... AF16: =SUM(P34:P37) -> 693
B17: 08.45 - 9.00 | C17: 20 | D17: 3 | E17: 1 | F17: 28 | G17: 0 | H17: 1 | I17: 13 | J17: 0 | K17: 2 | L17: 2 | M17: 72 | N17: 0 | O17: =SUM(C17:L17,N17) -> 70 | P17: =SUM(C17:N17) -> 142 | R17: 1400-1500 | S17: =SUM(C38:C41) -> 129 | T17: =SUM(D38:D41) -> 33 | U17: =SUM(E38:E41) -> 21 | V17: =SUM(F38:F41) -> 111 | W17: =SUM(G38:G41) -> 0 | X17: =SUM(H38:H41) -> 4 | Y17: =SUM(I38:I41) -> 105 | Z17: =SUM(J38:J41) -> 0 | ... AF17: =SUM(P38:P41) -> 631
B18: 09.00 - 09.15 | C18: 11 | D18: 2 | E18: 4 | F18: 30 | G18: 0 | H18: 1 | I18: 11 | J18: 1 | K18: 0 | L18: 3 | M18: 50 | N18: 0 | O18: =SUM(C18:L18,N18) -> 63 | P18: =SUM(C18:N18) -> 113 | R18: 1500-1600 | S18: =SUM(C42:C45) -> 137 | T18: =SUM(D42:D45) -> 53 | U18: =SUM(E42:E45) -> 24 | V18: =SUM(F42:F45) -> 107 | W18: =SUM(G42:G45) -> 1 | X18: =SUM(H42:H45) -> 2 | Y18: =SUM(I42:I45) -> 87 | Z18: =SUM(J42:J45) -> 7 | ... AF18: =SUM(P42:P45) -> 621
B19: 09.15 - 09.30 | C19: 4 | D19: 1 | E19: 1 | F19: 28 | G19: 0 | H19: 0 | I19: 20 | J19: 0 | K19: 1 | L19: 0 | M19: 62 | N19: 0 | O19: =SUM(C19:L19,N19) -> 55 | P19: =SUM(C19:N19) -> 117 | R19: 1600-1700 | S19: =SUM(C46:C49) -> 158 | T19: =SUM(D46:D49) -> 50 | U19: =SUM(E46:E49) -> 38 | V19: =SUM(F46:F49) -> 131 | W19: =SUM(G46:G49) -> 2 | X19: =SUM(H46:H49) -> 5 | Y19: =SUM(I46:I49) -> 101 | Z19: =SUM(J46:J49) -> 9 | ... AF19: =SUM(P46:P49) -> 717
B20: 09.30 - 09.45 | C20: 14 | D20: 0 | E20: 1 | F20: 19 | G20: 1 | H20: 0 | I20: 22 | J20: 1 | K20: 1 | L20: 3 | M20: 78 | N20: 0 | O20: =SUM(C20:L20,N20) -> 62 | P20: =SUM(C20:N20) -> 140 | R20: 1700-1800 | S20: =SUM(C50:C53) -> 198 | T20: =SUM(D50:D53) -> 51 | U20: =SUM(E50:E53) -> 39 | V20: =SUM(F50:F53) -> 117 | W20: =SUM(G50:G53) -> 5 | X20: =SUM(H50:H53) -> 3 | Y20: =SUM(I50:I53) -> 101 | Z20: =SUM(J50:J53) -> 5 | ... AF20: =SUM(P50:P53) -> 825
B21: 09.45 - 10.00 | C21: 23 | D21: 5 | E21: 4 | F21: 30 | G21: 0 | H21: 0 | I21: 16 | J21: 1 | K21: 2 | L21: 2 | M21: 78 | N21: 0 | O21: =SUM(C21:L21,N21) -> 83 | P21: =SUM(C21:N21) -> 161 | R21: 1800-1900 | S21: =SUM(C54:C57) -> 189 | T21: =SUM(D54:D57) -> 50 | U21: =SUM(E54:E57) -> 44 | V21: =SUM(F54:F57) -> 183 | W21: =SUM(G54:G57) -> 7 | X21: =SUM(H54:H57) -> 7 | Y21: =SUM(I54:I57) -> 70 | Z21: =SUM(J54:J57) -> 21 | ... AF21: =SUM(P54:P57) -> 767
B22: 10.00 - 10.15 | C22: 34 | D22: 7 | E22: 5 | F22: 36 | G22: 0 | H22: 0 | I22: 17 | J22: 1 | K22: 0 | L22: 3 | M22: 89 | N22: 0 | O22: =SUM(C22:L22,N22) -> 103 | P22: =SUM(C22:N22) -> 192 | R22: AM Peak Hr | S22: =MAX(S10:S12) -> 102 | T22: =MAX(T10:T12) -> 17 | U22: =MAX(U10:U12) -> 11 | V22: =MAX(V10:V12) -> 153 | W22: =MAX(W10:W12) -> 1 | X22: =MAX(X10:X12) -> 2 | Y22: =MAX(Y10:Y12) -> 69 | Z22: =MAX(Z10:Z12) -> 4 | ... AF22: =MAX(AF10:AF12) -> 634
B23: 10.15 - 10.30 | C23: 25 | D23: 3 | E23: 7 | F23: 27 | G23: 0 | H23: 0 | I23: 21 | J23: 1 | K23: 0 | L23: 2 | M23: 69 | N23: 0 | O23: =SUM(C23:L23,N23) -> 86 | P23: =SUM(C23:N23) -> 155 | R23: IP Peak Hr | S23: =MAX(S13:S18) -> 137 | T23: =MAX(T13:T18) -> 53 | U23: =MAX(U13:U18) -> 24 | V23: =MAX(V13:V18) -> 132 | W23: =MAX(W13:W18) -> 3 | X23: =MAX(X13:X18) -> 4 | Y23: =MAX(Y13:Y18) -> 129 | Z23: =MAX(Z13:Z18) -> 19 | ... AF23: =MAX(AF13:AF18) -> 704
B24: 10.30 - 10.45 | C24: 22 | D24: 4 | E24: 3 | F24: 29 | G24: 0 | H24: 0 | I24: 13 | J24: 1 | K24: 3 | L24: 2 | M24: 93 | N24: 0 | O24: =SUM(C24:L24,N24) -> 77 | P24: =SUM(C24:N24) -> 170 | R24: PM Peak Hr | S24: =MAX(S19:S21) -> 198 | T24: =MAX(T19:T21) -> 51 | U24: =MAX(U19:U21) -> 44 | V24: =MAX(V19:V21) -> 183 | W24: =MAX(W19:W21) -> 7 | X24: =MAX(X19:X21) -> 7 | Y24: =MAX(Y19:Y21) -> 101 | Z24: =MAX(Z19:Z21) -> 21 | ... AF24: =MAX(AF19:AF21) -> 825
B25: 10.45 - 11.00 | C25: 30 | D25: 7 | E25: 3 | F25: 33 | G25: 0 | H25: 1 | I25: 19 | J25: 1 | K25: 0 | L25: 2 | M25: 91 | N25: 0 | O25: =SUM(C25:L25,N25) -> 96 | P25: =SUM(C25:N25) -> 187 | R25: AM Period | S25: =SUM(S10:S12) -> 251 | T25: =SUM(T10:T12) -> 37 | U25: =SUM(U10:U12) -> 32 | V25: =SUM(V10:V12) -> 400 | W25: =SUM(W10:W12) -> 2 | X25: =SUM(X10:X12) -> 4 | Y25: =SUM(Y10:Y12) -> 152 | Z25: =SUM(Z10:Z12) -> 10 | ... AF25: =SUM(AF10:AF12) -> 1767
B26: 11.00 - 11.15 | C26: 17 | D26: 10 | E26: 3 | F26: 25 | G26: 1 | H26: 0 | I26: 15 | J26: 1 | K26: 0 | L26: 0 | M26: 90 | N26: 0 | O26: =SUM(C26:L26,N26) -> 72 | P26: =SUM(C26:N26) -> 162 | R26: IP Period | S26: =SUM(S13:S18) -> 647 | T26: =SUM(T13:T18) -> 183 | U26: =SUM(U13:U18) -> 108 | V26: =SUM(V13:V18) -> 664 | W26: =SUM(W13:W18) -> 7 | X26: =SUM(X13:X18) -> 14 | Y26: =SUM(Y13:Y18) -> 512 | Z26: =SUM(Z13:Z18) -> 52 | ... AF26: =SUM(AF13:AF18) -> 3745
B27: 11.15 - 11.30 | C27: 18 | D27: 6 | E27: 3 | F27: 24 | G27: 0 | H27: 0 | I27: 15 | J27: 2 | K27: 0 | L27: 2 | M27: 74 | N27: 0 | O27: =SUM(C27:L27,N27) -> 70 | P27: =SUM(C27:N27) -> 144 | R27: PM Period | S27: =SUM(S19:S21) -> 545 | T27: =SUM(T19:T21) -> 151 | U27: =SUM(U19:U21) -> 121 | V27: =SUM(V19:V21) -> 431 | W27: =SUM(W19:W21) -> 14 | X27: =SUM(X19:X21) -> 15 | Y27: =SUM(Y19:Y21) -> 272 | Z27: =SUM(Z19:Z21) -> 35 | ... AF27: =SUM(AF19:AF21) -> 2309
