Workbook

Sheet DAY1
A1: Consultancy services for Preparation of Expressway Development Master Plan (EDMP) for Uganda
A2: AXLE LOAD SURVEY FORM
A3: Date: | D3: Station: | E3: ABELOKODI
A4: 43675 | H4: GULU - NIMULE
A5: S/No. | B5: Time | C5: Reg. Number | D5: Vehicle Type | E5: Number of Axles | F5: Axle Configuration | G5: Front | H5: TONNES | N5: Total (Tonnes) | O5: Total (ESA's) | P5: COMMENTS
G6: Axle 1 | H6: Axle 2 | I6: Axle 3 | J6: Axle 4 | K6: Axle 5 | L6: Axle 6 | M6: Axle 7
A7: 1 | B7: 0.32638889 | C7: UAT 749G | D7: 11 | F7: 11*222 | G7: 8.36 | H7: 7.26 | I7: 15.84 | J7: 12.1 | K7: 0.88 | P7: Building mat./H. ware
A8: 2 | B8: 0.34236111 | C8: UAW 693R | D8: 8 | F8: 1*2 | G8: 6.16 | H8: 7.92 | P8: Agric Produce
A9: 3 | B9: 0.34444444 | C9: KBU 718F | D9: 12 | F9: 1*12*222 | G9: 4.62 | H9: 5.5 | I9: 9.02 | J9: 7.26 | K9: 8.8 | L9: 7.7 | P9: Fertilizer & Chemicals
A10: 4 | B10: 0.35416667 | C10: KCH 738B | D10: 12 | F10: 1*22-222 | G10: 6.616 | H10: 5.06 | I10: 5.5 | J10: 8.58 | K10: 6.6 | L10: 6.38 | P10: Agric Produce
A11: 5 | B11: 0.35694444 | C11: KBJ 767X | D11: 12 | F11: 1:22-222 | G11: 5.06 | H11: 3.74 | I11: 3.3 | J11: 4.4 | K11: 4.18 | L11: 2.42
A12: 6 | B12: 0.35902778 | C12: KBM 575D | D12: 12 | F12: 1*22-222 | G12: 6.16 | H12: 6.6 | I12: 6.82 | J12: 7.48 | K12: 7.7 | L12: 7.48 | P12: Agric Produce
A13: 7 | B13: 0.36319444 | C13: UAH 486T | D13: 11 | F13: 11*221 | G13: 5.94 | H13: 7.48 | I13: 9.02 | J13: 5.28 | K13: 3.74 | L13: 3.3 | P13: Agric Produce
A14: 8 | B14: 0.37152778 | C14: KAZ 983E | D14: 12 | F14: 1*22-222 | G14: 6.38 | H14: 6.82 | I14: 7.04 | J14: 3.74 | K14: 3.3 | L14: 3.52 | P14: Others
A15: 9 | B15: 0.375 | C15: UAH 697H | D15: 11 | F15: 11*222 | G15: 5.06 | H15: 11.22 | I15: 13.2 | J15: 7.04 | K15: 2.64 | P15: Agric Produce
A16: 10 | B16: 0.37847222 | C16: UBB 053Q | D16: 10 | F16: 11*222 | G16: 8.3 | H16: 7.7 | I16: 11.88 | J16: 11.66 | K16: 3.74 | P16: Agric Produce
A17: 11 | B17: 0.38194444 | C17: UAP 643U | D17: 8 | F17: 1*2 | G17: 5.28 | H17: 6.6 | P17: Agric Produce
A18: 12 | B18: 0.38333333 | C18: KBV 984C | D18: 10 | F18: 1*22-222 | G18: 5.72 | H18: 7.04 | I18: 7.26 | J18: 9.9 | K18: 7.92 | L18: 5.5 | P18: Building mat./H. ware
A19: 13 | B19: 0.39236111 | C19: KBP 596R | D19: 10 | F19: 1*12-222 | G19: 5.28 | H19: 2.86 | I19: 7.04 | J19: 6.38 | K19: 5.5 | L19: 4.18 | P19: Agric Produce
A20: 14 | B20: 0.40138889 | C20: KBA 665H | D20: 10 | F20: 1*12-222 | G20: 6.38 | H20: 4.62 | I20: 6.38 | J20: 7.04 | K20: 7.04 | L20: 7.48 | P20: Fuels(gas & Liquid)
A21: 15 | B21: 0.40416667 | C21: UAT 364P | D21: 10 | F21: 1*22-222 | G21: 8.4 | H21: 6.6 | I21: 6.38 | J21: 4.62 | K21: 5.28 | L21: 6.6 | P21: Agric Produce
A22: 16 | B22: 0.40625 | C22: UAX 096C | D22: 8 | F22: 1*2 | G22: 6.16 | H22: 8.92 | P22: Building mat./H. ware
A23: 17 | B23: 0.43611111 | C23: UAP 050X | D23: 10 | F23: 11*222 | G23: 6.6 | H23: 6.6 | I23: 10.56 | J23: 9.9 | K23: 0.88 | P23: Agric Produce
A24: 18 | B24: 0.45 | C24: UAW 964F | D24: 10 | F24: 1*22-222 | G24: 5.06 | H24: 5.06 | I24: 6.82 | J24: 5.28 | K24: 5.28 | L24: 6.6 | P24: Agric Produce
A25: 19 | B25: 0.45347222 | C25: UBB 645R | D25: 9 | F25: 1*22 | G25: 6.38 | H25: 12.54 | I25: 7.04 | P25: Agric Produce
A26: 20 | B26: 0.45694444 | C26: SSD 468B | D26: 10 | F26: 1*22-222 | G26: 4.18 | H26: 5.5 | I26: 1.32 | J26: 2.86 | K26: 3.52 | L26: 5.5 | P26: Others
A27: 21 | B27: 0.45972222 | C27: KBQ 327U | D27: 10 | F27: 1*22-222 | G27: 7.04 | H27: 1.76 | I27: 8.14 | J27: 9.9 | K27: 7.04 | L27: 8.36 | P27: Agric Produce
A28: 22 | B28: 0.46180556 | C28: KCQ 013V | D28: 10 | F28: 1*22-222 | G28: 4.18 | H28: 7.26 | I28: 7.04 | J28: 9.02 | K28: 7.04 | L28: 5.94 | P28: Processed foods and beverages
A29: 23 | B29: 0.46388889 | C29: XCL 357E | D29: 10 | F29: 1*22-222 | G29: 5.72 | H29: 10.12 | I29: 8.36 | J29: 8.8 | K29: 6.38 | L29: 8.58 | P29: Building mat./H. ware
A30: 24 | B30: 0.48055556 | C30: SSD 104G | D30: 10 | F30: 1*22-222 | G30: 5.5 | H30: 5.28 | I30: 4.84 | J30: 4.62 | K30: 4.4 | L30: 5.72 | P30: Shop items
A31: 25 | B31: 0.49791667 | C31: UAH 249V | D31: 10 | F31: 1*22-222 | G31: 6.16 | H31: 6.6 | I31: 7.92 | J31: 7.92 | K31: 7.7 | L31: 7.7 | P31: Processed foods and beverages
A32: 26 | B32: 0.51041667 | C32: UAR 767L | D32: 10 | F32: 1*22-222 | G32: 6.6 | H32: 6.82 | I32: 5.28 | J32: 6.16 | K32: 5.94 | L32: 7.26 | P32: Processed foods and beverages
A33: 27 | B33: 0.51388889 | C33: UAY 864S | D33: 10 | F33: 1*22-222 | G33: 5.94 | H33: 8.36 | I33: 8.36 | J33: 10.78 | K33: 7.7 | L33: 7.7 | P33: Processed foods and beverages
A34: 28 | B34: 0.081944444 | C34: UAR 978C | D34: 10 | F34: 1*22-222 | G34: 5.28 | H34: 4.84 | I34: 4.62 | J34: 6.38 | K34: 6.82 | L34: 9.02 | P34: Equipment
A35: 29 | B35: 0.12013889 | C35: KBR 624T | D35: 10 | F35: 1*22-222 | G35: 5.28 | H35: 6.82 | I35: 6.16 | J35: 5.94 | K35: 7.04 | L35: 4.62 | P35: Others
A36: 30 | B36: 0.15763889 | C36: KAL 773R | D36: 10 | F36: 1*22-222 | G36: 5.72 | H36: 5.06 | I36: 6.16 | J36: 5.28 | K36: 5.72 | L36: 4.62 | P36: Fuels(gas & Liquid)
A37: 31 | B37: 0.22013889 | C37: UAT 168D | D37: 10 | F37: 1*22-222 | G37: 4.18 | H37: 5.94 | I37: 3.96 | J37: 1.1 | K37: 3.74 | L37: 4.18
H38: NIMULE - GULU
A39: 1 | B39: 0.2625 | C39: KCF 124T | D39: 10 | F39: 1*22-222 | G39: 4.4 | H39: 1.98 | I39: 2.64 | J39: 2.64 | K39: 2.42 | L39: 3.08 | P39: Empty
A40: 2 | B40: 0.26736111 | C40: KCK 234G | D40: 10 | F40: 1*22-222 | G40: 5.06 | H40: 2.2 | I40: 2.86 | J40: 2.86 | K40: 2.64 | L40: 2.42 | P40: Empty
...

Sheet DAY2
A1: Consultancy services for Preparation of Expressway Development Master Plan (EDMP) for Uganda
A2: AXLE LOAD SURVEY FORM
A3: Date: | D3: Station Name: | E3: ABELOKODI
A4: 43676 | H4: GULU - NIMULE
A5: S/No. | B5: Time | C5: Reg. Number | D5: Vehicle Type | E5: Number of Axles | F5: Axle Configuration | G5: Front | H5: TONNES | N5: Total (Tonnes) | O5: Total (ESA's) | P5: COMMENTS
G6: Axle 1 | H6: Axle 2 | I6: Axle 3 | J6: Axle 4 | K6: Axle 5 | L6: Axle 6 | M6: Axle 7
A7: 1 | B7: 0.29861111 | C7: UAR 579R | D7: 8 | F7: 1*2 | G7: 5.72 | H7: 11.88 | P7: Agric Produce
A8: 2 | B8: 0.30902778 | C8: SSD 519C | D8: 8 | F8: 1*2 | G8: 3.96 | H8: 12.1 | P8: Processed foods and beverages
A9: 3 | B9: 0.31041667 | C9: UAT 422U | D9: 9 | F9: 1*22 | G9: 7.26 | H9: 8.36 | I9: 3.52 | P9: Shop items
A10: 4 | B10: 0.31597222 | C10: UAY 948S | D10: 10 | F10: 1*22-222 | G10: 5.72 | H10: 3.74 | I10: 3.74 | J10: 2.64 | K10: 2.64 | L10: 3.74 | P10: Building mat./H. ware
A11: 5 | B11: 0.31805556 | C11: KBC 770M | D11: 10 | F11: 1*22-222 | G11: 6.38 | H11: 5.5 | I11: 6.82 | J11: 7.04 | K11: 5.5 | L11: 5.72 | P11: Fuels(gas & Liquid)
A12: 6 | B12: 0.33680556 | C12: UEC 853 | D12: 10 | F12: 1*22-22-22 | G12: 7.26 | H12: 5.94 | I12: 5.28 | J12: 6.16 | K12: 5.28 | L12: 8.8 | M12: 5.06 | P12: Fuels(gas & Liquid)
A13: 7 | B13: 0.34930556 | C13: UAP 768U | D13: 10 | F13: 1*22-22-22 | G13: 8.14 | H13: 8.58 | I13: 5.06 | J13: 8.58 | K13: 7.92 | L13: 9.24 | M13: 6.38 | P13: Shop items
A14: 8 | B14: 0.35277778 | C14: UBE 556J | D14: 8 | F14: 1*2 | G14: 3.74 | H14: 13.2 | P14: Agric Produce
A15: 9 | B15: 0.35416667 | C15: UAX 958X | D15: 9 | F15: 1*22 | G15: 8.36 | H15: 7.92 | I15: 6.16 | P15: Processed foods and beverages
A16: 10 | B16: 0.35833333 | C16: UAR 965C | D16: 8 | F16: 1*2 | G16: 5.72 | H16: 6.82 | P16: Shop items
A17: 11 | B17: 0.36666667 | C17: UBE 174Q | D17: 10 | F17: 1*1-22 | G17: 5.5 | H17: 6.38 | I17: 12.32 | J17: 11.22 | K17: 0.66 | P17: Processed foods and beverages
A18: 12 | B18: 0.36944444 | C18: UBB 116P | D18: 10 | F18: 1*22-222 | G18: 5.72 | H18: 7.92 | I18: 6.6 | J18: 10.12 | K18: 6.38 | L18: 7.04 | P18: Processed foods and beverages
A19: 13 | B19: 0.37152778 | C19: UBF 376L | D19: 10 | F19: 1*22-222 | G19: 2.64 | H19: 3.74 | I19: 2.2 | J19: 2.64 | K19: 2.2 | L19: 5.28 | P19: Processed foods and beverages
A20: 14 | B20: 0.40625 | C20: UAY 917N | D20: 10 | F20: 1*22-222 | G20: 6.16 | H20: 7.7 | I20: 6.16 | J20: 7.7 | K20: 8.36 | L20: 5.72 | P20: Processed foods and beverages
A21: 15 | B21: 0.47430556 | C21: UAQ 390T | D21: 10 | F21: 11*221 | G21: 6.38 | H21: 7.7 | I21: 11 | J21: 5.06 | K21: 3.52 | P21: Agric Produce
A22: 16 | B22: 0.49305556 | C22: UAP 963U | D22: 10 | F22: 11*222 | G22: 6.38 | H22: 3.52 | I22: 12.76 | J22: 7.92 | K22: 2.86 | P22: Agric Produce
A23: 17 | B23: 0.49722222 | C23: UAT 660U | D23: 10 | F23: 11*22 | G23: 9.68 | H23: 3.74 | I23: 14.3 | J23: 8.36 | P23: Agric Produce
A24: 18 | B24: 0.50347222 | C24: KBR 976G | D24: 10 | F24: 1*12-222 | G24: 7.04 | H24: 0.44 | I24: 7.48 | J24: 3.08 | K24: 6.6 | L24: 5.5 | P24: Fuels(gas & Liquid)
A25: 19 | B25: 0.51041667 | C25: KBC 501M | D25: 10 | F25: 1*22-222 | G25: 6.16 | H25: 8.36 | I25: 7.92 | J25: 7.26 | K25: 7.04 | L25: 7.04 | P25: Others
A26: 20 | B26: 0.52083333 | C26: UAR 805R | D26: 10 | F26: 1*22-22-22 | G26: 7.26 | H26: 6.38 | I26: 4.18 | J26: 4.4 | K26: 4.62 | L26: 2.64 | M26: 6.38 | P26: Processed foods and beverages
A27: 21 | B27: 0.10138889 | C27: UAQ 235T | D27: 10 | F27: 1*22-222 | G27: 5.72 | H27: 10.12 | I27: 11.66 | J27: 9.46 | K27: 6.38 | L27: 8.58 | P27: Building mat./H. ware
A28: 22 | B28: 0.11597222 | C28: UAZ 965D | D28: 10 | F28: 1:22-22-22 | G28: 8.58 | H28: 6.38 | I28: 5.5 | J28: 9.24 | K28: 5.72 | L28: 7.7 | M28: 6.6 | P28: Building mat./H. ware
A29: 23 | B29: 0.20138889 | C29: UAW 416E | D29: 8 | F29: 1*2 | G29: 3.52 | H29: 6.6 | P29: Agric Produce
A30: 24 | B30: 0.22916667 | C30: KBQ 516V | D30: 10 | F30: 1*12-222 | G30: 6.16 | H30: 5.28 | I30: 5.94 | J30: 5.28 | K30: 6.38 | L30: 3.96 | P30: Building mat./H. ware
A31: 25 | B31: 0.27083333 | C31: KBB 037D | D31: 10 | F31: 1*22-222 | G31: 7.04 | H31: 7.92 | I31: 6.16 | J31: 6.38 | K31: 7.04 | L31: 6.82 | P31: Others
H32: NIMULE - GULU
A33: 1 | B33: 0.36597222 | C33: UBB 462A | D33: 8 | F33: 1*2 | G33: 2.86 | H33: 1.98 | P33: Livestock
A34: 2 | B34: 0.38541667 | C34: UBA 098Q | D34: 10 | F34: 1*12-222 | G34: 6.16 | H34: 8.58 | I34: 5.94 | J34: 7.7 | K34: 7.04 | L34: 6.16 | P34: Empty
A35: 3 | B35: 0.3875 | C35: UAU 780F | D35: 10 | F35: 11*222 | G35: 2.86 | H35: 2.86 | I35: 3.3 | J35: 2.42 | K35: 2.2 | P35: Empty
A36: 4 | B36: 0.47777778 | C36: KBL 644P | D36: 10 | F36: 1*12-222 | G36: 6.16 | H36: 7.7 | I36: 6.16 | J36: 8.36 | K36: 7.26 | L36: 7.26 | P36: Empty
A37: 5 | B37: 0.48263889 | C37: SSD 714D | D37: 10 | F37: 1*22-222 | G37: 5.28 | H37: 2.64 | I37: 2.64 | J37: 2.86 | K37: 3.08 | L37: 3.08 | P37: Empty
A38: 6 | B38: 0.48819444 | C38: KBU 836F | D38: 10 | F38: 1*22-222 | G38: 4.4 | H38: 2.64 | I38: 2.42 | J38: 3.3 | K38: 2.64 | L38: 2.86 | P38: Empty
A39: 7 | B39: 0.50555556 | C39: UAG 765T | D39: 10 | F39: 1*22-22-22 | G39: 4.62 | H39: 3.52 | I39: 2.64 | J39: 1.54 | K39: 2.64 | L39: 1.54 | M39: 2.42 | P39: Empty
A40: 8 | B40: 0.043055556 | C40: UAW 408F | D40: 10 | F40: 1*22-222 | G40: 5.06 | H40: 2.2 | I40: 1.98 | J40: 2.64 | K40: 2.86 | L40: 2.2 | P40: Empty
...

Sheet DAY3
A1: AXLE LOAD SURVEY FORM
A2: Date: | D2: Station Name: | E2: ABELOKODI
A3: 43677 | H3: GULU - NIMULE
A4: S/No. | B4: Time | C4: Reg. Number | D4: Vehicle Type | E4: Number of Axles | F4: Axle Configuration | G4: Front | N4: Total (Tonnes) | O4: Total (ESA's) | P4: COMMENTS
G5: Axle 1 | H5: Axle 2 | I5: Axle 3 | J5: Axle 4 | K5: Axle 5 | L5: Axle 6 | M5: Axle 7
A6: 1 | B6: 0.29861111 | C6: KAW 505M | D6: 10 | F6: 1*22-222 | G6: 6.82 | H6: 0.44 | I6: 7.92 | J6: 4.18 | K6: 2.86 | L6: 4.4 | P6: Fertilizer & Chemicals
A7: 2 | B7: 0.30208333 | C7: UAU 003N | D7: 10 | F7: 1*12-222 | G7: 5.5 | H7: 4.84 | I7: 5.28 | J7: 10.56 | K7: 8.8 | L7: 6.38 | P7: Agric Produce
A8: 3 | B8: 0.31597222 | C8: UAW 589E | D8: 10 | F8: 1*22-222 | G8: 6.6 | H8: 6.82 | I8: 5.72 | J8: 4.62 | K8: 4.62 | L8: 6.38 | P8: Processed foods and beverages
A9: 4 | B9: 0.325 | C9: SSD 483C | D9: 8 | F9: 1*2 | G9: 5.28 | H9: 7.04 | P9: Others
A10: 5 | B10: 0.34444444 | C10: UAU 639Y | D10: 10 | F10: 11*222 | G10: 8.8 | H10: 8.36 | I10: 12.54 | J10: 6.6 | K10: 2.64 | P10: Agric Produce
A11: 6 | B11: 0.35069444 | C11: SSD 780A | D11: 10 | F11: 1*12-222 | G11: 1.65 | H11: 5.28 | I11: 6.6 | J11: 5.28 | K11: 5.94 | L11: 5.72 | P11: Building mat./H. ware
A12: 7 | B12: 0.35416667 | C12: T 124CTH | D12: 10 | F12: 1*12-111 | G12: 5.94 | H12: 5.72 | I12: 4.62 | J12: 11 | K12: 8.36 | L12: 7.04 | P12: Building mat./H. ware
A13: 8 | B13: 0.38611111 | C13: UAS 836Q | D13: 10 | F13: 11*221 | G13: 7.92 | H13: 5.2 | I13: 14.96 | J13: 9.9 | K13: 1.32 | P13: Agric Produce
A14: 9 | B14: 0.38888889 | C14: UAG 923T | D14: 8 | F14: 1*2 | G14: 4.18 | H14: 13.2 | P14: Agric Produce
A15: 10 | B15: 0.42222222 | C15: UBB 118P | D15: 10 | F15: 1*22-222 | G15: 5.5 | H15: 6.16 | I15: 5.94 | J15: 9.68 | K15: 6.6 | L15: 6.16 | P15: Processed foods and beverages
A16: 11 | B16: 0.425 | C16: KCG 184V | D16: 10 | F16: 1*22-222 | G16: 5.94 | H16: 5.5 | I16: 4.4 | J16: 5.28 | K16: 3.96 | L16: 3.96 | P16: Processed foods and beverages
A17: 12 | B17: 0.43472222 | C17: KBQ 844M | D17: 10 | F17: 1*22-222 | G17: 4.62 | H17: 5.06 | I17: 1.98 | J17: 6.38 | K17: 5.5 | L17: 3.96 | P17: Others
A18: 13 | B18: 0.44236111 | C18: UAY 028C | D18: 10 | F18: 1*22-222 | G18: 4.62 | H18: 7.26 | I18: 6.16 | J18: 7.92 | K18: 7.26 | L18: 10.12 | P18: Agric Produce
A19: 14 | B19: 0.46875 | C19: KBS 198X | D19: 10 | F19: 1*1-222 | G19: 6.38 | H19: 8.58 | I19: 3.96 | J19: 4.84 | K19: 4.62 | P19: Others
A20: 15 | B20: 0.48055556 | C20: UAX 918S | D20: 10 | F20: 11*222 | G20: 6.6 | H20: 6.82 | I20: 13.42 | J20: 12.32 | K20: 1.1 | P20: Building mat./H. ware
A21: 16 | B21: 0.49861111 | C21: UAT 903H | D21: 8 | F21: 1*2 | G21: 3.52 | H21: 5.94 | P21: Shop items
A22: 17 | B22: 0.51597222 | C22: SSD 555C | D22: 5 | F22: 1*2 | G22: 6.6 | H22: 9.02 | P22: Others
A23: 18 | B23: 0.52291667 | C23: UBE 088C | D23: 9 | F23: 1*22 | G23: 5.72 | H23: 11.66 | I23: 6.82 | P23: Agric Produce
A24: 19 | B24: 0.53055556 | C24: KBY 743Q | D24: 10 | F24: 1*22-222 | G24: 6.6 | H24: 5.06 | I24: 3.96 | J24: 6.82 | K24: 3.52 | L24: 4.18 | P24: Equipment
A25: 20 | B25: 0.068055556 | C25: UBD 383G | D25: 10 | F25: 11*222 | G25: 4.18 | H25: 8.36 | I25: 12.1 | J25: 9.9 | K25: 6.6 | P25: Processed foods and beverages
A26: 21 | B26: 0.070833333 | C26: K27A 432 | D26: 10 | F26: 1*22-222 | G26: 6.82 | H26: 6.38 | I26: 3.3 | J26: 4.62 | K26: 4.4 | L26: 3.96 | P26: Agric Produce
A27: 22 | B27: 0.073611111 | C27: KX27 A433 | D27: 10 | F27: 1*22-222 | G27: 5.72 | H27: 7.7 | I27: 7.04 | J27: 6.16 | K27: 6.16 | L27: 5.28 | P27: Agric Produce
A28: 23 | B28: 0.12430556 | C28: SSD 639A | D28: 10 | F28: 1*22-222 | G28: 6.16 | H28: 9.24 | I28: 10.78 | J28: 5.06 | K28: 5.28 | L28: 10.78 | P28: Agric Produce
A29: 24 | B29: 0.17013889 | C29: KCC 562J | D29: 10 | F29: 1*22-222 | G29: 6.38 | H29: 2.42 | I29: 10.12 | J29: 5.72 | K29: 4.62 | L29: 6.38 | P29: Others
A30: 25 | B30: 0.17361111 | C30: SSD 599F | D30: 10 | F30: 1*22-222 | G30: 4.62 | H30: 8.14 | I30: 2.42 | J30: 5.28 | K30: 2.64 | L30: 4.18 | P30: Fuels(gas & Liquid)
A31: 26 | B31: 0.17847222 | C31: UAY 310H | D31: 10 | F31: 11*222 | G31: 7.04 | H31: 7.7 | I31: 9.9 | J31: 10.12 | K31: 2.64 | L31: 2.86 | P31: Shop items
A32: 27 | B32: 0.21597222 | C32: UAY 389W | D32: 8 | F32: 1*2 | G32: 5.28 | H32: 9.02 | P32: Building mat./H. ware
H33: NIMULE - GULU
A34: 1 | B34: 0.41527778 | C34: UBD 150Q | D34: 10 | F34: 1*22-222 | G34: 5.72 | H34: 5.53 | I34: 2.86 | J34: 2.42 | K34: 2.86 | L34: 2.42 | P34: Empty
A35: 2 | B35: 0.42708333 | C35: KBZ 433A | D35: 10 | F35: 1*22-222 | G35: 4.62 | H35: 5.06 | I35: 1.98 | J35: 6.38 | K35: 5.5 | L35: 3.96 | P35: Empty
A36: 3 | B36: 0.43958333 | C36: KCC 702X | D36: 10 | F36: 1*22-222 | G36: 5.5 | H36: 2.42 | I36: 2.42 | J36: 2.2 | K36: 2.2 | L36: 2.2 | P36: Empty
A37: 4 | B37: 0.45138889 | C37: UBB 947S | D37: 5 | F37: 1*2 | G37: 6.6 | H37: 6.6 | P37: Empty
A38: 5 | B38: 0.49305556 | C38: UAR 533M | D38: 10 | F38: 11*22 | G38: 3.3 | H38: 2.64 | I38: 4.84 | J38: 3.08 | P38: Empty
A39: 6 | B39: 0.53333333 | C39: KAX 604C | D39: 10 | F39: 1*22-222 | G39: 6.16 | H39: 3.16 | I39: 3.16 | J39: 2.64 | K39: 1.98 | L39: 1.76 | P39: Empty
A40: 7 | B40: 0.045138889 | C40: KBX 376Q | D40: 8 | F40: 1*2 | G40: 2.42 | H40: 2.2 | P40: Empty
...

Sheet Gulu-Nimule
A1: Consultancy services for Preparation of Expressway Development Master Plan (EDMP) for Uganda
A2: AXLE LOAD SURVEY FORM
A3: Date: | D3: Station: | E3: ABELOKODI
A4: 43675 | H4: GULU - NIMULE
A5: S/No. | B5: Time | C5: Reg. Number | D5: Vehicle Type | E5: Number of Axles | F5: Axle Configuration | G5: Front | H5: TONNES | N5: Total (Tonnes) | O5: Total (ESA's) | P5: Load limit (Tonnes) | W5: OVERLOADED? | X5: Overloaded by? | Y5: Overload Bands | Z5: COMMENTS
G6: Axle 1 | H6: Axle 2 | I6: Axle 3 | J6: Axle 4 | K6: Axle 5 | L6: Axle 6 | M6: Axle 7 | P6: Axle 1 | Q6: Axle 2 | R6: Axle 3 | S6: Axle 4 | T6: Axle 5 | U6: Axle 6 | V6: Axle 7
A7: 2 | B7: 0.34236111 | C7: UAW 693R | D7: =IF(COUNT(G7:M7)>3,10,IF(COUNT(G7:M7)>2,9,7)) -> 7 | F7: 1*2 | G7: 6.16 | H7: 7.92 | N7: =SUM(G7:M7) -> 14.08 | O7: =(N7/8.16)^4.5 -> 11.644108 | P7: 8 | Q7: 10 | R7: 9 | S7: 9 | T7: 9 | U7: 9 | V7: 9 | W7: =IF(G7>P7,"Y",IF(H7>Q7,"Y",IF(I7>R7,"Y",IF(J7>S7,"Y",IF(K7>T7,"Y",IF(L7>U7,"Y",IF(M7>V7,"Y","N"))))))) -> N | X7: =IF(W7="Y",MAX((G7-P7),(H7-Q7),(I7-R7),(J7-S7),(K7-T7),(L7-U7),(M7-V7))/10,0) -> 0 | Y7: =IF(X7<5%,"0-4.9%",IF(X7<25%,"5-25%",IF(X7<50%,"25-50%","Over 50%"))) -> 0-4.9% | Z7: Agricultural produce
A8: 11 | B8: 0.38194444 | C8: UAP 643U | D8: =IF(COUNT(G8:M8)>3,10,IF(COUNT(G8:M8)>2,9,7)) -> 7 | F8: 1*2 | G8: 5.28 | H8: 6.6 | N8: =SUM(G8:M8) -> 11.88 | O8: =(N8/8.16)^4.5 -> 5.420861 | P8: 8 | Q8: 10 | R8: 9 | S8: 9 | T8: 9 | U8: 9 | V8: 9 | W8: =IF(G8>P8,"Y",IF(H8>Q8,"Y",IF(I8>R8,"Y",IF(J8>S8,"Y",IF(K8>T8,"Y",IF(L8>U8,"Y",IF(M8>V8,"Y","N"))))))) -> N | X8: =IF(W8="Y",MAX((G8-P8),(H8-Q8),(I8-R8),(J8-S8),(K8-T8),(L8-U8),(M8-V8))/10,0) -> 0 | Y8: =IF(X8<5%,"0-4.9%",IF(X8<25%,"5-25%",IF(X8<50%,"25-50%","Over 50%"))) -> 0-4.9% | Z8: Agricultural produce
A9: 16 | B9: 0.40625 | C9: UAX 096C | D9: =IF(COUNT(G9:M9)>3,10,IF(COUNT(G9:M9)>2,9,7)) -> 7 | F9: 1*2 | G9: 6.16 | H9: 8.92 | N9: =SUM(G9:M9) -> 15.08 | O9: =(N9/8.16)^4.5 -> 15.856244 | P9: 8 | Q9: 10 | R9: 9 | S9: 9 | T9: 9 | U9: 9 | V9: 9 | W9: =IF(G9>P9,"Y",IF(H9>Q9,"Y",IF(I9>R9,"Y",IF(J9>S9,"Y",IF(K9>T9,"Y",IF(L9>U9,"Y",IF(M9>V9,"Y","N"))))))) -> N | X9: =IF(W9="Y",MAX((G9-P9),(H9-Q9),(I9-R9),(J9-S9),(K9-T9),(L9-U9),(M9-V9))/10,0) -> 0 | Y9: =IF(X9<5%,"0-4.9%",IF(X9<25%,"5-25%",IF(X9<50%,"25-50%","Over 50%"))) -> 0-4.9% | Z9: Construction Material
A10: 1 | B10: 0.29861111 | C10: UAR 579R | D10: =IF(COUNT(G10:M10)>3,10,IF(COUNT(G10:M10)>2,9,7)) -> 7 | F10: 1*2 | G10: 5.72 | H10: 11.88 | N10: =SUM(G10:M10) -> 17.6 | O10: =(N10/8.16)^4.5 -> 31.783469 | P10: 8 | Q10: 10 | R10: 9 | S10: 9 | T10: 9 | U10: 9 | V10: 9 | W10: =IF(G10>P10,"Y",IF(H10>Q10,"Y",IF(I10>R10,"Y",IF(J10>S10,"Y",IF(K10>T10,"Y",IF(L10>U10,"Y",IF(M10>V10,"Y","N"))))))) -> Y | X10: =IF(W10="Y",MAX((G10-P10),(H10-Q10),(I10-R10),(J10-S10),(K10-T10),(L10-U10),(M10-V10))/10,0) -> 0.188 | Y10: =IF(X10<5%,"0-4.9%",IF(X10<25%,"5-25%",IF(X10<50%,"25-50%","Over 50%"))) -> 5-25% | Z10: Agricultural produce
A11: 2 | B11: 0.30902778 | C11: SSD 519C | D11: =IF(COUNT(G11:M11)>3,10,IF(COUNT(G11:M11)>2,9,7)) -> 7 | F11: 1*2 | G11: 3.96 | H11: 12.1 | N11: =SUM(G11:M11) -> 16.06 | O11: =(N11/8.16)^4.5 -> 21.04986 | P11: 8 | Q11: 10 | R11: 9 | S11: 9 | T11: 9 | U11: 9 | V11: 9 | W11: =IF(G11>P11,"Y",IF(H11>Q11,"Y",IF(I11>R11,"Y",IF(J11>S11,"Y",IF(K11>T11,"Y",IF(L11>U11,"Y",IF(M11>V11,"Y","N"))))))) -> Y | X11: =IF(W11="Y",MAX((G11-P11),(H11-Q11),(I11-R11),(J11-S11),(K11-T11),(L11-U11),(M11-V11))/10,0) -> 0.21 | Y11: =IF(X11<5%,"0-4.9%",IF(X11<25%,"5-25%",IF(X11<50%,"25-50%","Over 50%"))) -> 5-25% | Z11: Household retail products
A12: 8 | B12: 0.35277778 | C12: UBE 556J | D12: =IF(COUNT(G12:M12)>3,10,IF(COUNT(G12:M12)>2,9,7)) -> 7 | F12: 1*2 | G12: 3.74 | H12: 13.2 | N12: =SUM(G12:M12) -> 16.94 | O12: =(N12/8.16)^4.5 -> 26.76114 | P12: 8 | Q12: 10 | R12: 9 | S12: 9 | T12: 9 | U12: 9 | V12: 9 | W12: =IF(G12>P12,"Y",IF(H12>Q12,"Y",IF(I12>R12,"Y",IF(J12>S12,"Y",IF(K12>T12,"Y",IF(L12>U12,"Y",IF(M12>V12,"Y","N"))))))) -> Y | X12: =IF(W12="Y",MAX((G12-P12),(H12-Q12),(I12-R12),(J12-S12),(K12-T12),(L12-U12),(M12-V12))/10,0) -> 0.32 | Y12: =IF(X12<5%,"0-4.9%",IF(X12<25%,"5-25%",IF(X12<50%,"25-50%","Over 50%"))) -> 25-50% | Z12: Agricultural produce
A13: 10 | B13: 0.35833333 | C13: UAR 965C | D13: =IF(COUNT(G13:M13)>3,10,IF(COUNT(G13:M13)>2,9,7)) -> 7 | F13: 1*2 | G13: 5.72 | H13: 6.82 | N13: =SUM(G13:M13) -> 12.54 | O13: =(N13/8.16)^4.5 -> 6.9140609 | P13: 8 | Q13: 10 | R13: 9 | S13: 9 | T13: 9 | U13: 9 | V13: 9 | W13: =IF(G13>P13,"Y",IF(H13>Q13,"Y",IF(I13>R13,"Y",IF(J13>S13,"Y",IF(K13>T13,"Y",IF(L13>U13,"Y",IF(M13>V13,"Y","N"))))))) -> N | X13: =IF(W13="Y",MAX((G13-P13),(H13-Q13),(I13-R13),(J13-S13),(K13-T13),(L13-U13),(M13-V13))/10,0) -> 0 | Y13: =IF(X13<5%,"0-4.9%",IF(X13<25%,"5-25%",IF(X13<50%,"25-50%","Over 50%"))) -> 0-4.9% | Z13: Household retail products
A14: 23 | B14: 0.20138889 | C14: UAW 416E | D14: =IF(COUNT(G14:M14)>3,10,IF(COUNT(G14:M14)>2,9,7)) -> 7 | F14: 1*2 | G14: 3.52 | H14: 6.6 | N14: =SUM(G14:M14) -> 10.12 | O14: =(N14/8.16)^4.5 -> 2.6345509 | P14: 8 | Q14: 10 | R14: 9 | S14: 9 | T14: 9 | U14: 9 | V14: 9 | W14: =IF(G14>P14,"Y",IF(H14>Q14,"Y",IF(I14>R14,"Y",IF(J14>S14,"Y",IF(K14>T14,"Y",IF(L14>U14,"Y",IF(M14>V14,"Y","N"))))))) -> N | X14: =IF(W14="Y",MAX((G14-P14),(H14-Q14),(I14-R14),(J14-S14),(K14-T14),(L14-U14),(M14-V14))/10,0) -> 0 | Y14: =IF(X14<5%,"0-4.9%",IF(X14<25%,"5-25%",IF(X14<50%,"25-50%","Over 50%"))) -> 0-4.9% | Z14: Agricultural produce
A15: 4 | B15: 0.325 | C15: SSD 483C | D15: =IF(COUNT(G15:M15)>3,10,IF(COUNT(G15:M15)>2,9,7)) -> 7 | F15: 1*2 | G15: 5.28 | H15: 7.04 | N15: =SUM(G15:M15) -> 12.32 | O15: =(N15/8.16)^4.5 -> 6.384729 | P15: 8 | Q15: 10 | R15: 9 | S15: 9 | T15: 9 | U15: 9 | V15: 9 | W15: =IF(G15>P15,"Y",IF(H15>Q15,"Y",IF(I15>R15,"Y",IF(J15>S15,"Y",IF(K15>T15,"Y",IF(L15>U15,"Y",IF(M15>V15,"Y","N"))))))) -> N | X15: =IF(W15="Y",MAX((G15-P15),(H15-Q15),(I15-R15),(J15-S15),(K15-T15),(L15-U15),(M15-V15))/10,0) -> 0 | Y15: =IF(X15<5%,"0-4.9%",IF(X15<25%,"5-25%",IF(X15<50%,"25-50%","Over 50%"))) -> 0-4.9% | Z15: Others
A16: 9 | B16: 0.38888889 | C16: UAG 923T | D16: =IF(COUNT(G16:M16)>3,10,IF(COUNT(G16:M16)>2,9,7)) -> 7 | F16: 1*2 | G16: 4.18 | H16: 13.2 | N16: =SUM(G16:M16) -> 17.38 | O16: =(N16/8.16)^4.5 -> 30.034352 | P16: 8 | Q16: 10 | R16: 9 | S16: 9 | T16: 9 | U16: 9 | V16: 9 | W16: =IF(G16>P16,"Y",IF(H16>Q16,"Y",IF(I16>R16,"Y",IF(J16>S16,"Y",IF(K16>T16,"Y",IF(L16>U16,"Y",IF(M16>V16,"Y","N"))))))) -> Y | X16: =IF(W16="Y",MAX((G16-P16),(H16-Q16),(I16-R16),(J16-S16),(K16-T16),(L16-U16),(M16-V16))/10,0) -> 0.32 | Y16: =IF(X16<5%,"0-4.9%",IF(X16<25%,"5-25%",IF(X16<50%,"25-50%","Over 50%"))) -> 25-50% | Z16: Agricultural produce
A17: 16 | B17: 0.49861111 | C17: UAT 903H | D17: =IF(COUNT(G17:M17)>3,10,IF(COUNT(G17:M17)>2,9,7)) -> 7 | F17: 1*2 | G17: 3.52 | H17: 5.94 | N17: =SUM(G17:M17) -> 9.46 | O17: =(N17/8.16)^4.5 -> 1.9449319 | P17: 8 | Q17: 10 | R17: 9 | S17: 9 | T17: 9 | U17: 9 | V17: 9 | W17: =IF(G17>P17,"Y",IF(H17>Q17,"Y",IF(I17>R17,"Y",IF(J17>S17,"Y",IF(K17>T17,"Y",IF(L17>U17,"Y",IF(M17>V17,"Y","N"))))))) -> N | X17: =IF(W17="Y",MAX((G17-P17),(H17-Q17),(I17-R17),(J17-S17),(K17-T17),(L17-U17),(M17-V17))/10,0) -> 0 | Y17: =IF(X17<5%,"0-4.9%",IF(X17<25%,"5-25%",IF(X17<50%,"25-50%","Over 50%"))) -> 0-4.9% | Z17: Household retail products
A18: 17 | B18: 0.51597222 | C18: SSD 555C | D18: =IF(COUNT(G18:M18)>3,10,IF(COUNT(G18:M18)>2,9,7)) -> 7 | F18: 1*2 | G18: 6.6 | H18: 9.02 | N18: =SUM(G18:M18) -> 15.62 | O18: =(N18/8.16)^4.5 -> 18.576287 | P18: 8 | Q18: 10 | R18: 9 | S18: 9 | T18: 9 | U18: 9 | V18: 9 | W18: =IF(G18>P18,"Y",IF(H18>Q18,"Y",IF(I18>R18,"Y",IF(J18>S18,"Y",IF(K18>T18,"Y",IF(L18>U18,"Y",IF(M18>V18,"Y","N"))))))) -> N | X18: =IF(W18="Y",MAX((G18-P18),(H18-Q18),(I18-R18),(J18-S18),(K18-T18),(L18-U18),(M18-V18))/10,0) -> 0 | Y18: =IF(X18<5%,"0-4.9%",IF(X18<25%,"5-25%",IF(X18<50%,"25-50%","Over 50%"))) -> 0-4.9% | Z18: Others
A19: 27 | B19: 0.21597222 | C19: UAY 389W | D19: =IF(COUNT(G19:M19)>3,10,IF(COUNT(G19:M19)>2,9,7)) -> 7 | F19: 1*2 | G19: 5.28 | H19: 9.02 | N19: =SUM(G19:M19) -> 14.3 | O19: =(N19/8.16)^4.5 -> 12.485515 | P19: 8 | Q19: 10 | R19: 9 | S19: 9 | T19: 9 | U19: 9 | V19: 9 | W19: =IF(G19>P19,"Y",IF(H19>Q19,"Y",IF(I19>R19,"Y",IF(J19>S19,"Y",IF(K19>T19,"Y",IF(L19>U19,"Y",IF(M19>V19,"Y","N"))))))) -> N | X19: =IF(W19="Y",MAX((G19-P19),(H19-Q19),(I19-R19),(J19-S19),(K19-T19),(L19-U19),(M19-V19))/10,0) -> 0 | Y19: =IF(X19<5%,"0-4.9%",IF(X19<25%,"5-25%",IF(X19<50%,"25-50%","Over 50%"))) -> 0-4.9% | Z19: Construction Material
A20: 19 | B20: 0.45347222 | C20: UBB 645R | D20: =IF(COUNT(G20:M20)>3,10,IF(COUNT(G20:M20)>2,9,7)) -> 9 | F20: 1*22 | G20: 6.38 | H20: 12.54 | I20: 7.04 | N20: =SUM(G20:M20) -> 25.96 | O20: =(N20/8.16)^4.5 -> 182.71129 | P20: 8 | Q20: 10 | R20: 9 | S20: 9 | T20: 9 | U20: 9 | V20: 9 | W20: =IF(G20>P20,"Y",IF(H20>Q20,"Y",IF(I20>R20,"Y",IF(J20>S20,"Y",IF(K20>T20,"Y",IF(L20>U20,"Y",IF(M20>V20,"Y","N"))))))) -> Y | X20: =IF(W20="Y",MAX((G20-P20),(H20-Q20),(I20-R20),(J20-S20),(K20-T20),(L20-U20),(M20-V20))/10,0) -> 0.254 | Y20: =IF(X20<5%,"0-4.9%",IF(X20<25%,"5-25%",IF(X20<50%,"25-50%","Over 50%"))) -> 25-50% | Z20: Agricultural produce
A21: 3 | B21: 0.31041667 | C21: UAT 422U | D21: =IF(COUNT(G21:M21)>3,10,IF(COUNT(G21:M21)>2,9,7)) -> 9 | F21: 1*22 | G21: 7.26 | H21: 8.36 | I21: 3.52 | N21: =SUM(G21:M21) -> 19.14 | O21: =(N21/8.16)^4.5 -> 46.358885 | P21: 8 | Q21: 10 | R21: 9 | S21: 9 | T21: 9 | U21: 9 | V21: 9 | W21: =IF(G21>P21,"Y",IF(H21>Q21,"Y",IF(I21>R21,"Y",IF(J21>S21,"Y",IF(K21>T21,"Y",IF(L21>U21,"Y",IF(M21>V21,"Y","N"))))))) -> N | X21: =IF(W21="Y",MAX((G21-P21),(H21-Q21),(I21-R21),(J21-S21),(K21-T21),(L21-U21),(M21-V21))/10,0) -> 0 | Y21: =IF(X21<5%,"0-4.9%",IF(X21<25%,"5-25%",IF(X21<50%,"25-50%","Over 50%"))) -> 0-4.9% | Z21: Household retail products
A22: 9 | B22: 0.35416667 | C22: UAX 958X | D22: =IF(COUNT(G22:M22)>3,10,IF(COUNT(G22:M22)>2,9,7)) -> 9 | F22: 1*22 | G22: 8.36 | H22: 7.92 | I22: 6.16 | N22: =SUM(G22:M22) -> 22.44 | O22: =(N22/8.16)^4.5 -> 94.841218 | P22: 8 | Q22: 10 | R22: 9 | S22: 9 | T22: 9 | U22: 9 | V22: 9 | W22: =IF(G22>P22,"Y",IF(H22>Q22,"Y",IF(I22>R22,"Y",IF(J22>S22,"Y",IF(K22>T22,"Y",IF(L22>U22,"Y",IF(M22>V22,"Y","N"))))))) -> Y | X22: =IF(W22="Y",MAX((G22-P22),(H22-Q22),(I22-R22),(J22-S22),(K22-T22),(L22-U22),(M22-V22))/10,0) -> 0.036 | Y22: =IF(X22<5%,"0-4.9%",IF(X22<25%,"5-25%",IF(X22<50%,"25-50%","Over 50%"))) -> 0-4.9% | Z22: Household retail products
A23: 18 | B23: 0.52291667 | C23: UBE 088C | D23: =IF(COUNT(G23:M23)>3,10,IF(COUNT(G23:M23)>2,9,7)) -> 9 | F23: 1*22 | G23: 5.72 | H23: 11.66 | I23: 6.82 | N23: =SUM(G23:M23) -> 24.2 | O23: =(N23/8.16)^4.5 -> 133.21816 | P23: 8 | Q23: 10 | R23: 9 | S23: 9 | T23: 9 | U23: 9 | V23: 9 | W23: =IF(G23>P23,"Y",IF(H23>Q23,"Y",IF(I23>R23,"Y",IF(J23>S23,"Y",IF(K23>T23,"Y",IF(L23>U23,"Y",IF(M23>V23,"Y","N"))))))) -> Y | X23: =IF(W23="Y",MAX((G23-P23),(H23-Q23),(I23-R23),(J23-S23),(K23-T23),(L23-U23),(M23-V23))/10,0) -> 0.166 | Y23: =IF(X23<5%,"0-4.9%",IF(X23<25%,"5-25%",IF(X23<50%,"25-50%","Over 50%"))) -> 5-25% | Z23: Agricultural produce
A24: 1 | B24: 0.32638889 | C24: UAT 749G | D24: =IF(COUNT(G24:M24)>3,10,IF(COUNT(G24:M24)>2,9,7)) -> 10 | F24: 11*222 | G24: 8.36 | H24: 7.26 | I24: 15.84 | J24: 12.1 | K24: 0.88 | N24: =SUM(G24:M24) -> 44.44 | O24: =(N24/8.16)^4.5 -> 2052.9459 | P24: 8 | Q24: 10 | R24: 9 | S24: 9 | T24: 9 | U24: 9 | V24: 9 | W24: =IF(G24>P24,"Y",IF(H24>Q24,"Y",IF(I24>R24,"Y",IF(J24>S24,"Y",IF(K24>T24,"Y",IF(L24>U24,"Y",IF(M24>V24,"Y","N"))))))) -> Y | X24: =IF(W24="Y",MAX((G24-P24),(H24-Q24),(I24-R24),(J24-S24),(K24-T24),(L24-U24),(M24-V24))/10,0) -> 0.684 | Y24: =IF(X24<5%,"0-4.9%",IF(X24<25%,"5-25%",IF(X24<50%,"25-50%","Over 50%"))) -> Over 50% | Z24: Construction Material
A25: 3 | B25: 0.34444444 | C25: KBU 718F | D25: =IF(COUNT(G25:M25)>3,10,IF(COUNT(G25:M25)>2,9,7)) -> 10 | F25: 1*12*222 | G25: 4.62 | H25: 5.5 | I25: 9.02 | J25: 7.26 | K25: 8.8 | L25: 7.7 | N25: =SUM(G25:M25) -> 42.9 | O25: =(N25/8.16)^4.5 -> 1751.6692 | P25: 8 | Q25: 10 | R25: 9 | S25: 9 | T25: 9 | U25: 9 | V25: 9 | W25: =IF(G25>P25,"Y",IF(H25>Q25,"Y",IF(I25>R25,"Y",IF(J25>S25,"Y",IF(K25>T25,"Y",IF(L25>U25,"Y",IF(M25>V25,"Y","N"))))))) -> Y | X25: =IF(W25="Y",MAX((G25-P25),(H25-Q25),(I25-R25),(J25-S25),(K25-T25),(L25-U25),(M25-V25))/10,0) -> 0.002 | Y25: =IF(X25<5%,"0-4.9%",IF(X25<25%,"5-25%",IF(X25<50%,"25-50%","Over 50%"))) -> 0-4.9% | Z25: Chemical Products
A26: 4 | B26: 0.35416667 | C26: KCH 738B | D26: =IF(COUNT(G26:M26)>3,10,IF(COUNT(G26:M26)>2,9,7)) -> 10 | F26: 1*22-222 | G26: 6.616 | H26: 5.06 | I26: 5.5 | J26: 8.58 | K26: 6.6 | L26: 6.38 | N26: =SUM(G26:M26) -> 38.736 | O26: =(N26/8.16)^4.5 -> 1106.3964 | P26: 8 | Q26: 10 | R26: 9 | S26: 9 | T26: 9 | U26: 9 | V26: 9 | W26: =IF(G26>P26,"Y",IF(H26>Q26,"Y",IF(I26>R26,"Y",IF(J26>S26,"Y",IF(K26>T26,"Y",IF(L26>U26,"Y",IF(M26>V26,"Y","N"))))))) -> N | X26: =IF(W26="Y",MAX((G26-P26),(H26-Q26),(I26-R26),(J26-S26),(K26-T26),(L26-U26),(M26-V26))/10,0) -> 0 | Y26: =IF(X26<5%,"0-4.9%",IF(X26<25%,"5-25%",IF(X26<50%,"25-50%","Over 50%"))) -> 0-4.9% | Z26: Agricultural produce
A27: 5 | B27: 0.35694444 | C27: KBJ 767X | D27: =IF(COUNT(G27:M27)>3,10,IF(COUNT(G27:M27)>2,9,7)) -> 10 | F27: 1:22-222 | G27: 5.06 | H27: 3.74 | I27: 3.3 | J27: 4.4 | K27: 4.18 | L27: 2.42 | N27: =SUM(G27:M27) -> 23.1 | O27: =(N27/8.16)^4.5 -> 108.05583 | P27: 8 | Q27: 10 | R27: 9 | S27: 9 | T27: 9 | U27: 9 | V27: 9 | W27: =IF(G27>P27,"Y",IF(H27>Q27,"Y",IF(I27>R27,"Y",IF(J27>S27,"Y",IF(K27>T27,"Y",IF(L27>U27,"Y",IF(M27>V27,"Y","N"))))))) -> N | X27: =IF(W27="Y",MAX((G27-P27),(H27-Q27),(I27-R27),(J27-S27),(K27-T27),(L27-U27),(M27-V27))/10,0) -> 0 | Y27: =IF(X27<5%,"0-4.9%",IF(X27<25%,"5-25%",IF(X27<50%,"25-50%","Over 50%"))) -> 0-4.9% | Z27: Empty
A28: 6 | B28: 0.35902778 | C28: KBM 575D | D28: =IF(COUNT(G28:M28)>3,10,IF(COUNT(G28:M28)>2,9,7)) -> 10 | F28: 1*22-222 | G28: 6.16 | H28: 6.6 | I28: 6.82 | J28: 7.48 | K28: 7.7 | L28: 7.48 | N28: =SUM(G28:M28) -> 42.24 | O28: =(N28/8.16)^4.5 -> 1633.6231 | P28: 8 | Q28: 10 | R28: 9 | S28: 9 | T28: 9 | U28: 9 | V28: 9 | W28: =IF(G28>P28,"Y",IF(H28>Q28,"Y",IF(I28>R28,"Y",IF(J28>S28,"Y",IF(K28>T28,"Y",IF(L28>U28,"Y",IF(M28>V28,"Y","N"))))))) -> N | X28: =IF(W28="Y",MAX((G28-P28),(H28-Q28),(I28-R28),(J28-S28),(K28-T28),(L28-U28),(M28-V28))/10,0) -> 0 | Y28: =IF(X28<5%,"0-4.9%",IF(X28<25%,"5-25%",IF(X28<50%,"25-50%","Over 50%"))) -> 0-4.9% | Z28: Agricultural produce
A29: 7 | B29: 0.36319444 | C29: UAH 486T | D29: =IF(COUNT(G29:M29)>3,10,IF(COUNT(G29:M29)>2,9,7)) -> 10 | F29: 11*221 | G29: 5.94 | H29: 7.48 | I29: 9.02 | J29: 5.28 | K29: 3.74 | L29: 3.3 | N29: =SUM(G29:M29) -> 34.76 | O29: =(N29/8.16)^4.5 -> 679.5998 | P29: 8 | Q29: 10 | R29: 9 | S29: 9 | T29: 9 | U29: 9 | V29: 9 | W29: =IF(G29>P29,"Y",IF(H29>Q29,"Y",IF(I29>R29,"Y",IF(J29>S29,"Y",IF(K29>T29,"Y",IF(L29>U29,"Y",IF(M29>V29,"Y","N"))))))) -> Y | X29: =IF(W29="Y",MAX((G29-P29),(H29-Q29),(I29-R29),(J29-S29),(K29-T29),(L29-U29),(M29-V29))/10,0) -> 0.002 | Y29: =IF(X29<5%,"0-4.9%",IF(X29<25%,"5-25%",IF(X29<50%,"25-50%","Over 50%"))) -> 0-4.9% | Z29: Agricultural produce
A30: 8 | B30: 0.37152778 | C30: KAZ 983E | D30: =IF(COUNT(G30:M30)>3,10,IF(COUNT(G30:M30)>2,9,7)) -> 10 | F30: 1*22-222 | G30: 6.38 | H30: 6.82 | I30: 7.04 | J30: 3.74 | K30: 3.3 | L30: 3.52 | N30: =SUM(G30:M30) -> 30.8 | O30: =(N30/8.16)^4.5 -> 394.34152 | P30: 8 | Q30: 10 | R30: 9 | S30: 9 | T30: 9 | U30: 9 | V30: 9 | W30: =IF(G30>P30,"Y",IF(H30>Q30,"Y",IF(I30>R30,"Y",IF(J30>S30,"Y",IF(K30>T30,"Y",IF(L30>U30,"Y",IF(M30>V30,"Y","N"))))))) -> N | X30: =IF(W30="Y",MAX((G30-P30),(H30-Q30),(I30-R30),(J30-S30),(K30-T30),(L30-U30),(M30-V30))/10,0) -> 0 | Y30: =IF(X30<5%,"0-4.9%",IF(X30<25%,"5-25%",IF(X30<50%,"25-50%","Over 50%"))) -> 0-4.9% | Z30: Others
A31: 9 | B31: 0.375 | C31: UAH 697H | D31: =IF(COUNT(G31:M31)>3,10,IF(COUNT(G31:M31)>2,9,7)) -> 10 | F31: 11*222 | G31: 5.06 | H31: 11.22 | I31: 13.2 | J31: 7.04 | K31: 2.64 | N31: =SUM(G31:M31) -> 39.16 | O31: =(N31/8.16)^4.5 -> 1161.9471 | P31: 8 | Q31: 10 | R31: 9 | S31: 9 | T31: 9 | U31: 9 | V31: 9 | W31: =IF(G31>P31,"Y",IF(H31>Q31,"Y",IF(I31>R31,"Y",IF(J31>S31,"Y",IF(K31>T31,"Y",IF(L31>U31,"Y",IF(M31>V31,"Y","N"))))))) -> Y | X31: =IF(W31="Y",MAX((G31-P31),(H31-Q31),(I31-R31),(J31-S31),(K31-T31),(L31-U31),(M31-V31))/10,0) -> 0.42 | Y31: =IF(X31<5%,"0-4.9%",IF(X31<25%,"5-25%",IF(X31<50%,"25-50%","Over 50%"))) -> 25-50% | Z31: Agricultural produce
A32: 10 | B32: 0.37847222 | C32: UBB 053Q | D32: =IF(COUNT(G32:M32)>3,10,IF(COUNT(G32:M32)>2,9,7)) -> 10 | F32: 11*222 | G32: 8.3 | H32: 7.7 | I32: 11.88 | J32: 11.66 | K32: 3.74 | N32: =SUM(G32:M32) -> 43.28 | O32: =(N32/8.16)^4.5 -> 1822.5813 | P32: 8 | Q32: 10 | R32: 9 | S32: 9 | T32: 9 | U32: 9 | V32: 9 | W32: =IF(G32>P32,"Y",IF(H32>Q32,"Y",IF(I32>R32,"Y",IF(J32>S32,"Y",IF(K32>T32,"Y",IF(L32>U32,"Y",IF(M32>V32,"Y","N"))))))) -> Y | X32: =IF(W32="Y",MAX((G32-P32),(H32-Q32),(I32-R32),(J32-S32),(K32-T32),(L32-U32),(M32-V32))/10,0) -> 0.288 | Y32: =IF(X32<5%,"0-4.9%",IF(X32<25%,"5-25%",IF(X32<50%,"25-50%","Over 50%"))) -> 25-50% | Z32: Agricultural produce
A33: 12 | B33: 0.38333333 | C33: KBV 984C | D33: =IF(COUNT(G33:M33)>3,10,IF(COUNT(G33:M33)>2,9,7)) -> 10 | F33: 1*22-222 | G33: 5.72 | H33: 7.04 | I33: 7.26 | J33: 9.9 | K33: 7.92 | L33: 5.5 | N33: =SUM(G33:M33) -> 43.34 | O33: =(N33/8.16)^4.5 -> 1833.979 | P33: 8 | Q33: 10 | R33: 9 | S33: 9 | T33: 9 | U33: 9 | V33: 9 | W33: =IF(G33>P33,"Y",IF(H33>Q33,"Y",IF(I33>R33,"Y",IF(J33>S33,"Y",IF(K33>T33,"Y",IF(L33>U33,"Y",IF(M33>V33,"Y","N"))))))) -> Y | X33: =IF(W33="Y",MAX((G33-P33),(H33-Q33),(I33-R33),(J33-S33),(K33-T33),(L33-U33),(M33-V33))/10,0) -> 0.09 | Y33: =IF(X33<5%,"0-4.9%",IF(X33<25%,"5-25%",IF(X33<50%,"25-50%","Over 50%"))) -> 5-25% | Z33: Construction Material
A34: 13 | B34: 0.39236111 | C34: KBP 596R | D34: =IF(COUNT(G34:M34)>3,10,IF(COUNT(G34:M34)>2,9,7)) -> 10 | F34: 1*12-222 | G34: 5.28 | H34: 2.86 | I34: 7.04 | J34: 6.38 | K34: 5.5 | L34: 4.18 | N34: =SUM(G34:M34) -> 31.24 | O34: =(N34/8.16)^4.5 -> 420.3334 | P34: 8 | Q34: 10 | R34: 9 | S34: 9 | T34: 9 | U34: 9 | V34: 9 | W34: =IF(G34>P34,"Y",IF(H34>Q34,"Y",IF(I34>R34,"Y",IF(J34>S34,"Y",IF(K34>T34,"Y",IF(L34>U34,"Y",IF(M34>V34,"Y","N"))))))) -> N | X34: =IF(W34="Y",MAX((G34-P34),(H34-Q34),(I34-R34),(J34-S34),(K34-T34),(L34-U34),(M34-V34))/10,0) -> 0 | Y34: =IF(X34<5%,"0-4.9%",IF(X34<25%,"5-25%",IF(X34<50%,"25-50%","Over 50%"))) -> 0-4.9% | Z34: Agricultural produce
A35: 14 | B35: 0.40138889 | C35: KBA 665H | D35: =IF(COUNT(G35:M35)>3,10,IF(COUNT(G35:M35)>2,9,7)) -> 10 | F35: 1*12-222 | G35: 6.38 | H35: 4.62 | I35: 6.38 | J35: 7.04 | K35: 7.04 | L35: 7.48 | N35: =SUM(G35:M35) -> 38.94 | O35: =(N35/8.16)^4.5 -> 1132.8595 | P35: 8 | Q35: 10 | R35: 9 | S35: 9 | T35: 9 | U35: 9 | V35: 9 | W35: =IF(G35>P35,"Y",IF(H35>Q35,"Y",IF(I35>R35,"Y",IF(J35>S35,"Y",IF(K35>T35,"Y",IF(L35>U35,"Y",IF(M35>V35,"Y","N"))))))) -> N | X35: =IF(W35="Y",MAX((G35-P35),(H35-Q35),(I35-R35),(J35-S35),(K35-T35),(L35-U35),(M35-V35))/10,0) -> 0 | Y35: =IF(X35<5%,"0-4.9%",IF(X35<25%,"5-25%",IF(X35<50%,"25-50%","Over 50%"))) -> 0-4.9% | Z35: Fuels
A36: 15 | B36: 0.40416667 | C36: UAT 364P | D36: =IF(COUNT(G36:M36)>3,10,IF(COUNT(G36:M36)>2,9,7)) -> 10 | F36: 1*22-222 | G36: 8.4 | H36: 6.6 | I36: 6.38 | J36: 4.62 | K36: 5.28 | L36: 6.6 | N36: =SUM(G36:M36) -> 37.88 | O36: =(N36/8.16)^4.5 -> 1000.5508 | P36: 8 | Q36: 10 | R36: 9 | S36: 9 | T36: 9 | U36: 9 | V36: 9 | W36: =IF(G36>P36,"Y",IF(H36>Q36,"Y",IF(I36>R36,"Y",IF(J36>S36,"Y",IF(K36>T36,"Y",IF(L36>U36,"Y",IF(M36>V36,"Y","N"))))))) -> Y | X36: =IF(W36="Y",MAX((G36-P36),(H36-Q36),(I36-R36),(J36-S36),(K36-T36),(L36-U36),(M36-V36))/10,0) -> 0.04 | Y36: =IF(X36<5%,"0-4.9%",IF(X36<25%,"5-25%",IF(X36<50%,"25-50%","Over 50%"))) -> 0-4.9% | Z36: Agricultural produce
A37: 17 | B37: 0.43611111 | C37: UAP 050X | D37: =IF(COUNT(G37:M37)>3,10,IF(COUNT(G37:M37)>2,9,7)) -> 10 | F37: 11*222 | G37: 6.6 | H37: 6.6 | I37: 10.56 | J37: 9.9 | K37: 0.88 | N37: =SUM(G37:M37) -> 34.54 | O37: =(N37/8.16)^4.5 -> 660.45736 | P37: 8 | Q37: 10 | R37: 9 | S37: 9 | T37: 9 | U37: 9 | V37: 9 | W37: =IF(G37>P37,"Y",IF(H37>Q37,"Y",IF(I37>R37,"Y",IF(J37>S37,"Y",IF(K37>T37,"Y",IF(L37>U37,"Y",IF(M37>V37,"Y","N"))))))) -> Y | X37: =IF(W37="Y",MAX((G37-P37),(H37-Q37),(I37-R37),(J37-S37),(K37-T37),(L37-U37),(M37-V37))/10,0) -> 0.156 | Y37: =IF(X37<5%,"0-4.9%",IF(X37<25%,"5-25%",IF(X37<50%,"25-50%","Over 50%"))) -> 5-25% | Z37: Agricultural produce
A38: 18 | B38: 0.45 | C38: UAW 964F | D38: =IF(COUNT(G38:M38)>3,10,IF(COUNT(G38:M38)>2,9,7)) -> 10 | F38: 1*22-222 | G38: 5.06 | H38: 5.06 | I38: 6.82 | J38: 5.28 | K38: 5.28 | L38: 6.6 | N38: =SUM(G38:M38) -> 34.1 | O38: =(N38/8.16)^4.5 -> 623.43186 | P38: 8 | Q38: 10 | R38: 9 | S38: 9 | T38: 9 | U38: 9 | V38: 9 | W38: =IF(G38>P38,"Y",IF(H38>Q38,"Y",IF(I38>R38,"Y",IF(J38>S38,"Y",IF(K38>T38,"Y",IF(L38>U38,"Y",IF(M38>V38,"Y","N"))))))) -> N | X38: =IF(W38="Y",MAX((G38-P38),(H38-Q38),(I38-R38),(J38-S38),(K38-T38),(L38-U38),(M38-V38))/10,0) -> 0 | Y38: =IF(X38<5%,"0-4.9%",IF(X38<25%,"5-25%",IF(X38<50%,"25-50%","Over 50%"))) -> 0-4.9% | Z38: Agricultural produce
A39: 20 | B39: 0.45694444 | C39: SSD 468B | D39: =IF(COUNT(G39:M39)>3,10,IF(COUNT(G39:M39)>2,9,7)) -> 10 | F39: 1*22-222 | G39: 4.18 | H39: 5.5 | I39: 1.32 | J39: 2.86 | K39: 3.52 | L39: 5.5 | N39: =SUM(G39:M39) -> 22.88 | O39: =(N39/8.16)^4.5 -> 103.50144 | P39: 8 | Q39: 10 | R39: 9 | S39: 9 | T39: 9 | U39: 9 | V39: 9 | W39: =IF(G39>P39,"Y",IF(H39>Q39,"Y",IF(I39>R39,"Y",IF(J39>S39,"Y",IF(K39>T39,"Y",IF(L39>U39,"Y",IF(M39>V39,"Y","N"))))))) -> N | X39: =IF(W39="Y",MAX((G39-P39),(H39-Q39),(I39-R39),(J39-S39),(K39-T39),(L39-U39),(M39-V39))/10,0) -> 0 | Y39: =IF(X39<5%,"0-4.9%",IF(X39<25%,"5-25%",IF(X39<50%,"25-50%","Over 50%"))) -> 0-4.9% | Z39: Others
A40: 21 | B40: 0.45972222 | C40: KBQ 327U | D40: =IF(COUNT(G40:M40)>3,10,IF(COUNT(G40:M40)>2,9,7)) -> 10 | F40: 1*22-222 | G40: 7.04 | H40: 1.76 | I40: 8.14 | J40: 9.9 | K40: 7.04 | L40: 8.36 | N40: =SUM(G40:M40) -> 42.24 | O40: =(N40/8.16)^4.5 -> 1633.6231 | P40: 8 | Q40: 10 | R40: 9 | S40: 9 | T40: 9 | U40: 9 | V40: 9 | W40: =IF(G40>P40,"Y",IF(H40>Q40,"Y",IF(I40>R40,"Y",IF(J40>S40,"Y",IF(K40>T40,"Y",IF(L40>U40,"Y",IF(M40>V40,"Y","N"))))))) -> Y | X40: =IF(W40="Y",MAX((G40-P40),(H40-Q40),(I40-R40),(J40-S40),(K40-T40),(L40-U40),(M40-V40))/10,0) -> 0.09 | Y40: =IF(X40<5%,"0-4.9%",IF(X40<25%,"5-25%",IF(X40<50%,"25-50%","Over 50%"))) -> 5-25% | Z40: Agricultural produce
...

Sheet Nimule-Gulu
A1: Consultancy services for Preparation of Expressway Development Master Plan (EDMP) for Uganda
A2: AXLE LOAD SURVEY FORM
A3: Date: | D3: Station: | E3: ABELOKODI
A4: 43675 | H4: NIMULE-GULU
A5: S/No. | B5: Time | C5: Reg. Number | D5: Vehicle Type | E5: Number of Axles | F5: Axle Configuration | G5: Front | H5: TONNES | N5: Total (Tonnes) | O5: Total (ESA's) | P5: Load limit (Tonnes) | W5: OVERLOADED? | X5: Overloaded by? | Y5: Overload Bands | Z5: COMMENTS
G6: Axle 1 | H6: Axle 2 | I6: Axle 3 | J6: Axle 4 | K6: Axle 5 | L6: Axle 6 | M6: Axle 7 | P6: Axle 1 | Q6: Axle 2 | R6: Axle 3 | S6: Axle 4 | T6: Axle 5 | U6: Axle 6 | V6: Axle 7
A7: 1 | B7: 0.36597222 | C7: UBB 462A | D7: =IF(COUNT(G7:M7)>3,10,IF(COUNT(G7:M7)>2,9,7)) -> 7 | F7: 1*2 | G7: 2.86 | H7: 1.98 | N7: =SUM(G7:M7) -> 4.84 | O7: =(N7/8.16)^4.5 -> 0.095323156 | P7: 8 | Q7: 10 | R7: 9 | S7: 9 | T7: 9 | U7: 9 | V7: 9 | W7: =IF(G7>P7,"Y",IF(H7>Q7,"Y",IF(I7>R7,"Y",IF(J7>S7,"Y",IF(K7>T7,"Y",IF(L7>U7,"Y",IF(M7>V7,"Y","N"))))))) -> N | X7: =IF(W7="Y",MAX((G7-P7),(H7-Q7),(I7-R7),(J7-S7),(K7-T7),(L7-U7),(M7-V7))/10,0) -> 0 | Y7: =IF(X7<5%,"0-4.9%",IF(X7<25%,"5-25%",IF(X7<50%,"25-50%","Over 50%"))) -> 0-4.9% | Z7: Livestock
A8: 9 | B8: 0.054166667 | C8: UBD 490Q | D8: =IF(COUNT(G8:M8)>3,10,IF(COUNT(G8:M8)>2,9,7)) -> 7 | F8: 1*2 | G8: 3.96 | H8: 6.6 | N8: =SUM(G8:M8) -> 10.56 | O8: =(N8/8.16)^4.5 -> 3.1906702 | P8: 8 | Q8: 10 | R8: 9 | S8: 9 | T8: 9 | U8: 9 | V8: 9 | W8: =IF(G8>P8,"Y",IF(H8>Q8,"Y",IF(I8>R8,"Y",IF(J8>S8,"Y",IF(K8>T8,"Y",IF(L8>U8,"Y",IF(M8>V8,"Y","N"))))))) -> N | X8: =IF(W8="Y",MAX((G8-P8),(H8-Q8),(I8-R8),(J8-S8),(K8-T8),(L8-U8),(M8-V8))/10,0) -> 0 | Y8: =IF(X8<5%,"0-4.9%",IF(X8<25%,"5-25%",IF(X8<50%,"25-50%","Over 50%"))) -> 0-4.9% | Z8: Empty
A9: 10 | B9: 0.15694444 | C9: UAS 526Q | D9: =IF(COUNT(G9:M9)>3,10,IF(COUNT(G9:M9)>2,9,7)) -> 7 | F9: 1*2 | G9: 6.38 | H9: 10.56 | N9: =SUM(G9:M9) -> 16.94 | O9: =(N9/8.16)^4.5 -> 26.76114 | P9: 8 | Q9: 10 | R9: 9 | S9: 9 | T9: 9 | U9: 9 | V9: 9 | W9: =IF(G9>P9,"Y",IF(H9>Q9,"Y",IF(I9>R9,"Y",IF(J9>S9,"Y",IF(K9>T9,"Y",IF(L9>U9,"Y",IF(M9>V9,"Y","N"))))))) -> Y | X9: =IF(W9="Y",MAX((G9-P9),(H9-Q9),(I9-R9),(J9-S9),(K9-T9),(L9-U9),(M9-V9))/10,0) -> 0.056 | Y9: =IF(X9<5%,"0-4.9%",IF(X9<25%,"5-25%",IF(X9<50%,"25-50%","Over 50%"))) -> 5-25% | Z9: Others
A10: 12 | B10: 0.1875 | C10: UAS 442B | D10: =IF(COUNT(G10:M10)>3,10,IF(COUNT(G10:M10)>2,9,7)) -> 7 | F10: 1*2 | G10: 7.48 | H10: 6.6 | N10: =SUM(G10:M10) -> 14.08 | O10: =(N10/8.16)^4.5 -> 11.644108 | P10: 8 | Q10: 10 | R10: 9 | S10: 9 | T10: 9 | U10: 9 | V10: 9 | W10: =IF(G10>P10,"Y",IF(H10>Q10,"Y",IF(I10>R10,"Y",IF(J10>S10,"Y",IF(K10>T10,"Y",IF(L10>U10,"Y",IF(M10>V10,"Y","N"))))))) -> N | X10: =IF(W10="Y",MAX((G10-P10),(H10-Q10),(I10-R10),(J10-S10),(K10-T10),(L10-U10),(M10-V10))/10,0) -> 0 | Y10: =IF(X10<5%,"0-4.9%",IF(X10<25%,"5-25%",IF(X10<50%,"25-50%","Over 50%"))) -> 0-4.9% | Z10: Others
A11: 4 | B11: 0.45138889 | C11: UBB 947S | D11: =IF(COUNT(G11:M11)>3,10,IF(COUNT(G11:M11)>2,9,7)) -> 7 | F11: 1*2 | G11: 6.6 | H11: 6.6 | N11: =SUM(G11:M11) -> 13.2 | O11: =(N11/8.16)^4.5 -> 8.7091742 | P11: 8 | Q11: 10 | R11: 9 | S11: 9 | T11: 9 | U11: 9 | V11: 9 | W11: =IF(G11>P11,"Y",IF(H11>Q11,"Y",IF(I11>R11,"Y",IF(J11>S11,"Y",IF(K11>T11,"Y",IF(L11>U11,"Y",IF(M11>V11,"Y","N"))))))) -> N | X11: =IF(W11="Y",MAX((G11-P11),(H11-Q11),(I11-R11),(J11-S11),(K11-T11),(L11-U11),(M11-V11))/10,0) -> 0 | Y11: =IF(X11<5%,"0-4.9%",IF(X11<25%,"5-25%",IF(X11<50%,"25-50%","Over 50%"))) -> 0-4.9% | Z11: Empty
A12: 7 | B12: 0.045138889 | C12: KBX 376Q | D12: =IF(COUNT(G12:M12)>3,10,IF(COUNT(G12:M12)>2,9,7)) -> 7 | F12: 1*2 | G12: 2.42 | H12: 2.2 | N12: =SUM(G12:M12) -> 4.62 | O12: =(N12/8.16)^4.5 -> 0.077318456 | P12: 8 | Q12: 10 | R12: 9 | S12: 9 | T12: 9 | U12: 9 | V12: 9 | W12: =IF(G12>P12,"Y",IF(H12>Q12,"Y",IF(I12>R12,"Y",IF(J12>S12,"Y",IF(K12>T12,"Y",IF(L12>U12,"Y",IF(M12>V12,"Y","N"))))))) -> N | X12: =IF(W12="Y",MAX((G12-P12),(H12-Q12),(I12-R12),(J12-S12),(K12-T12),(L12-U12),(M12-V12))/10,0) -> 0 | Y12: =IF(X12<5%,"0-4.9%",IF(X12<25%,"5-25%",IF(X12<50%,"25-50%","Over 50%"))) -> 0-4.9% | Z12: Empty
A13: 9 | B13: 0.12152778 | C13: UAS 159M | D13: =IF(COUNT(G13:M13)>3,10,IF(COUNT(G13:M13)>2,9,7)) -> 7 | F13: 1*2 | G13: 6.38 | H13: 4.84 | N13: =SUM(G13:M13) -> 11.22 | O13: =(N13/8.16)^4.5 -> 4.1914293 | P13: 8 | Q13: 10 | R13: 9 | S13: 9 | T13: 9 | U13: 9 | V13: 9 | W13: =IF(G13>P13,"Y",IF(H13>Q13,"Y",IF(I13>R13,"Y",IF(J13>S13,"Y",IF(K13>T13,"Y",IF(L13>U13,"Y",IF(M13>V13,"Y","N"))))))) -> N | X13: =IF(W13="Y",MAX((G13-P13),(H13-Q13),(I13-R13),(J13-S13),(K13-T13),(L13-U13),(M13-V13))/10,0) -> 0 | Y13: =IF(X13<5%,"0-4.9%",IF(X13<25%,"5-25%",IF(X13<50%,"25-50%","Over 50%"))) -> 0-4.9% | Z13: Empty
A14: 11 | B14: 0.17708333 | C14: UAN 283Z | D14: =IF(COUNT(G14:M14)>3,10,IF(COUNT(G14:M14)>2,9,7)) -> 7 | F14: 1*2 | G14: 5.28 | H14: 7.48 | N14: =SUM(G14:M14) -> 12.76 | O14: =(N14/8.16)^4.5 -> 7.4769129 | P14: 8 | Q14: 10 | R14: 9 | S14: 9 | T14: 9 | U14: 9 | V14: 9 | W14: =IF(G14>P14,"Y",IF(H14>Q14,"Y",IF(I14>R14,"Y",IF(J14>S14,"Y",IF(K14>T14,"Y",IF(L14>U14,"Y",IF(M14>V14,"Y","N"))))))) -> N | X14: =IF(W14="Y",MAX((G14-P14),(H14-Q14),(I14-R14),(J14-S14),(K14-T14),(L14-U14),(M14-V14))/10,0) -> 0 | Y14: =IF(X14<5%,"0-4.9%",IF(X14<25%,"5-25%",IF(X14<50%,"25-50%","Over 50%"))) -> 0-4.9% | Z14: Empty
A15: 13 | B15: 0.20972222 | C15: UBB 657U | D15: =IF(COUNT(G15:M15)>3,10,IF(COUNT(G15:M15)>2,9,7)) -> 7 | F15: 1*2 | G15: 2.64 | H15: 3.3 | N15: =SUM(G15:M15) -> 5.94 | O15: =(N15/8.16)^4.5 -> 0.23957047 | P15: 8 | Q15: 10 | R15: 9 | S15: 9 | T15: 9 | U15: 9 | V15: 9 | W15: =IF(G15>P15,"Y",IF(H15>Q15,"Y",IF(I15>R15,"Y",IF(J15>S15,"Y",IF(K15>T15,"Y",IF(L15>U15,"Y",IF(M15>V15,"Y","N"))))))) -> N | X15: =IF(W15="Y",MAX((G15-P15),(H15-Q15),(I15-R15),(J15-S15),(K15-T15),(L15-U15),(M15-V15))/10,0) -> 0 | Y15: =IF(X15<5%,"0-4.9%",IF(X15<25%,"5-25%",IF(X15<50%,"25-50%","Over 50%"))) -> 0-4.9% | Z15: Empty
A16: 16 | B16: 0.25347222 | C16: SSD 117A | D16: =IF(COUNT(G16:M16)>3,10,IF(COUNT(G16:M16)>2,9,7)) -> 7 | F16: 1*2 | G16: 5.5 | H16: 8.5 | N16: =SUM(G16:M16) -> 14 | O16: =(N16/8.16)^4.5 -> 11.349336 | P16: 8 | Q16: 10 | R16: 9 | S16: 9 | T16: 9 | U16: 9 | V16: 9 | W16: =IF(G16>P16,"Y",IF(H16>Q16,"Y",IF(I16>R16,"Y",IF(J16>S16,"Y",IF(K16>T16,"Y",IF(L16>U16,"Y",IF(M16>V16,"Y","N"))))))) -> N | X16: =IF(W16="Y",MAX((G16-P16),(H16-Q16),(I16-R16),(J16-S16),(K16-T16),(L16-U16),(M16-V16))/10,0) -> 0 | Y16: =IF(X16<5%,"0-4.9%",IF(X16<25%,"5-25%",IF(X16<50%,"25-50%","Over 50%"))) -> 0-4.9% | Z16: Household retail products
A17: 11 | B17: 0.1625 | C17: RAD 268R | D17: =IF(COUNT(G17:M17)>3,10,IF(COUNT(G17:M17)>2,9,7)) -> 9 | F17: 1*21 | G17: 7.48 | H17: 4.84 | I17: 4.18 | N17: =SUM(G17:M17) -> 16.5 | O17: =(N17/8.16)^4.5 -> 23.772346 | P17: 8 | Q17: 10 | R17: 9 | S17: 9 | T17: 9 | U17: 9 | V17: 9 | W17: =IF(G17>P17,"Y",IF(H17>Q17,"Y",IF(I17>R17,"Y",IF(J17>S17,"Y",IF(K17>T17,"Y",IF(L17>U17,"Y",IF(M17>V17,"Y","N"))))))) -> N | X17: =IF(W17="Y",MAX((G17-P17),(H17-Q17),(I17-R17),(J17-S17),(K17-T17),(L17-U17),(M17-V17))/10,0) -> 0 | Y17: =IF(X17<5%,"0-4.9%",IF(X17<25%,"5-25%",IF(X17<50%,"25-50%","Over 50%"))) -> 0-4.9% | Z17: Others
A18: 12 | B18: 0.20625 | C18: UBD 195D | D18: =IF(COUNT(G18:M18)>3,10,IF(COUNT(G18:M18)>2,9,7)) -> 9 | F18: 1*22 | G18: 2.42 | H18: 2.42 | I18: 0.44 | N18: =SUM(G18:M18) -> 5.28 | O18: =(N18/8.16)^4.5 -> 0.14100903 | P18: 8 | Q18: 10 | R18: 9 | S18: 9 | T18: 9 | U18: 9 | V18: 9 | W18: =IF(G18>P18,"Y",IF(H18>Q18,"Y",IF(I18>R18,"Y",IF(J18>S18,"Y",IF(K18>T18,"Y",IF(L18>U18,"Y",IF(M18>V18,"Y","N"))))))) -> N | X18: =IF(W18="Y",MAX((G18-P18),(H18-Q18),(I18-R18),(J18-S18),(K18-T18),(L18-U18),(M18-V18))/10,0) -> 0 | Y18: =IF(X18<5%,"0-4.9%",IF(X18<25%,"5-25%",IF(X18<50%,"25-50%","Over 50%"))) -> 0-4.9% | Z18: Empty
A19: 1 | B19: 0.2625 | C19: KCF 124T | D19: =IF(COUNT(G19:M19)>3,10,IF(COUNT(G19:M19)>2,9,7)) -> 10 | F19: 1*22-222 | G19: 4.4 | H19: 1.98 | I19: 2.64 | J19: 2.64 | K19: 2.42 | L19: 3.08 | N19: =SUM(G19:M19) -> 17.16 | O19: =(N19/8.16)^4.5 -> 28.361034 | P19: 8 | Q19: 10 | R19: 9 | S19: 9 | T19: 9 | U19: 9 | V19: 9 | W19: =IF(G19>P19,"Y",IF(H19>Q19,"Y",IF(I19>R19,"Y",IF(J19>S19,"Y",IF(K19>T19,"Y",IF(L19>U19,"Y",IF(M19>V19,"Y","N"))))))) -> N | X19: =IF(W19="Y",MAX((G19-P19),(H19-Q19),(I19-R19),(J19-S19),(K19-T19),(L19-U19),(M19-V19))/10,0) -> 0 | Y19: =IF(X19<5%,"0-4.9%",IF(X19<25%,"5-25%",IF(X19<50%,"25-50%","Over 50%"))) -> 0-4.9% | Z19: Empty
A20: 2 | B20: 0.26736111 | C20: KCK 234G | D20: =IF(COUNT(G20:M20)>3,10,IF(COUNT(G20:M20)>2,9,7)) -> 10 | F20: 1*22-222 | G20: 5.06 | H20: 2.2 | I20: 2.86 | J20: 2.86 | K20: 2.64 | L20: 2.42 | N20: =SUM(G20:M20) -> 18.04 | O20: =(N20/8.16)^4.5 -> 35.518833 | P20: 8 | Q20: 10 | R20: 9 | S20: 9 | T20: 9 | U20: 9 | V20: 9 | W20: =IF(G20>P20,"Y",IF(H20>Q20,"Y",IF(I20>R20,"Y",IF(J20>S20,"Y",IF(K20>T20,"Y",IF(L20>U20,"Y",IF(M20>V20,"Y","N"))))))) -> N | X20: =IF(W20="Y",MAX((G20-P20),(H20-Q20),(I20-R20),(J20-S20),(K20-T20),(L20-U20),(M20-V20))/10,0) -> 0 | Y20: =IF(X20<5%,"0-4.9%",IF(X20<25%,"5-25%",IF(X20<50%,"25-50%","Over 50%"))) -> 0-4.9% | Z20: Empty
A21: 3 | B21: 0.26944444 | C21: UAR 674C | D21: =IF(COUNT(G21:M21)>3,10,IF(COUNT(G21:M21)>2,9,7)) -> 10 | F21: 1*1-22 | G21: 6.82 | H21: 5.72 | I21: 11.6 | J21: 6.16 | N21: =SUM(G21:M21) -> 30.3 | O21: =(N21/8.16)^4.5 -> 366.3415 | P21: 8 | Q21: 10 | R21: 9 | S21: 9 | T21: 9 | U21: 9 | V21: 9 | W21: =IF(G21>P21,"Y",IF(H21>Q21,"Y",IF(I21>R21,"Y",IF(J21>S21,"Y",IF(K21>T21,"Y",IF(L21>U21,"Y",IF(M21>V21,"Y","N"))))))) -> Y | X21: =IF(W21="Y",MAX((G21-P21),(H21-Q21),(I21-R21),(J21-S21),(K21-T21),(L21-U21),(M21-V21))/10,0) -> 0.26 | Y21: =IF(X21<5%,"0-4.9%",IF(X21<25%,"5-25%",IF(X21<50%,"25-50%","Over 50%"))) -> 25-50% | Z21: Empty
A22: 2 | B22: 0.38541667 | C22: UBA 098Q | D22: =IF(COUNT(G22:M22)>3,10,IF(COUNT(G22:M22)>2,9,7)) -> 10 | F22: 1*12-222 | G22: 6.16 | H22: 8.58 | I22: 5.94 | J22: 7.7 | K22: 7.04 | L22: 6.16 | N22: =SUM(G22:M22) -> 41.58 | O22: =(N22/8.16)^4.5 -> 1521.8592 | P22: 8 | Q22: 10 | R22: 9 | S22: 9 | T22: 9 | U22: 9 | V22: 9 | W22: =IF(G22>P22,"Y",IF(H22>Q22,"Y",IF(I22>R22,"Y",IF(J22>S22,"Y",IF(K22>T22,"Y",IF(L22>U22,"Y",IF(M22>V22,"Y","N"))))))) -> N | X22: =IF(W22="Y",MAX((G22-P22),(H22-Q22),(I22-R22),(J22-S22),(K22-T22),(L22-U22),(M22-V22))/10,0) -> 0 | Y22: =IF(X22<5%,"0-4.9%",IF(X22<25%,"5-25%",IF(X22<50%,"25-50%","Over 50%"))) -> 0-4.9% | Z22: Empty
A23: 3 | B23: 0.3875 | C23: UAU 780F | D23: =IF(COUNT(G23:M23)>3,10,IF(COUNT(G23:M23)>2,9,7)) -> 10 | F23: 11*222 | G23: 2.86 | H23: 2.86 | I23: 3.3 | J23: 2.42 | K23: 2.2 | N23: =SUM(G23:M23) -> 13.64 | O23: =(N23/8.16)^4.5 -> 10.093899 | P23: 8 | Q23: 10 | R23: 9 | S23: 9 | T23: 9 | U23: 9 | V23: 9 | W23: =IF(G23>P23,"Y",IF(H23>Q23,"Y",IF(I23>R23,"Y",IF(J23>S23,"Y",IF(K23>T23,"Y",IF(L23>U23,"Y",IF(M23>V23,"Y","N"))))))) -> N | X23: =IF(W23="Y",MAX((G23-P23),(H23-Q23),(I23-R23),(J23-S23),(K23-T23),(L23-U23),(M23-V23))/10,0) -> 0 | Y23: =IF(X23<5%,"0-4.9%",IF(X23<25%,"5-25%",IF(X23<50%,"25-50%","Over 50%"))) -> 0-4.9% | Z23: Empty
A24: 4 | B24: 0.47777778 | C24: KBL 644P | D24: =IF(COUNT(G24:M24)>3,10,IF(COUNT(G24:M24)>2,9,7)) -> 10 | F24: 1*12-222 | G24: 6.16 | H24: 7.7 | I24: 6.16 | J24: 8.36 | K24: 7.26 | L24: 7.26 | N24: =SUM(G24:M24) -> 42.9 | O24: =(N24/8.16)^4.5 -> 1751.6692 | P24: 8 | Q24: 10 | R24: 9 | S24: 9 | T24: 9 | U24: 9 | V24: 9 | W24: =IF(G24>P24,"Y",IF(H24>Q24,"Y",IF(I24>R24,"Y",IF(J24>S24,"Y",IF(K24>T24,"Y",IF(L24>U24,"Y",IF(M24>V24,"Y","N"))))))) -> N | X24: =IF(W24="Y",MAX((G24-P24),(H24-Q24),(I24-R24),(J24-S24),(K24-T24),(L24-U24),(M24-V24))/10,0) -> 0 | Y24: =IF(X24<5%,"0-4.9%",IF(X24<25%,"5-25%",IF(X24<50%,"25-50%","Over 50%"))) -> 0-4.9% | Z24: Empty
A25: 5 | B25: 0.48263889 | C25: SSD 714D | D25: =IF(COUNT(G25:M25)>3,10,IF(COUNT(G25:M25)>2,9,7)) -> 10 | F25: 1*22-222 | G25: 5.28 | H25: 2.64 | I25: 2.64 | J25: 2.86 | K25: 3.08 | L25: 3.08 | N25: =SUM(G25:M25) -> 19.58 | O25: =(N25/8.16)^4.5 -> 51.351293 | P25: 8 | Q25: 10 | R25: 9 | S25: 9 | T25: 9 | U25: 9 | V25: 9 | W25: =IF(G25>P25,"Y",IF(H25>Q25,"Y",IF(I25>R25,"Y",IF(J25>S25,"Y",IF(K25>T25,"Y",IF(L25>U25,"Y",IF(M25>V25,"Y","N"))))))) -> N | X25: =IF(W25="Y",MAX((G25-P25),(H25-Q25),(I25-R25),(J25-S25),(K25-T25),(L25-U25),(M25-V25))/10,0) -> 0 | Y25: =IF(X25<5%,"0-4.9%",IF(X25<25%,"5-25%",IF(X25<50%,"25-50%","Over 50%"))) -> 0-4.9% | Z25: Empty
A26: 6 | B26: 0.48819444 | C26: KBU 836F | D26: =IF(COUNT(G26:M26)>3,10,IF(COUNT(G26:M26)>2,9,7)) -> 10 | F26: 1*22-222 | G26: 4.4 | H26: 2.64 | I26: 2.42 | J26: 3.3 | K26: 2.64 | L26: 2.86 | N26: =SUM(G26:M26) -> 18.26 | O26: =(N26/8.16)^4.5 -> 37.510061 | P26: 8 | Q26: 10 | R26: 9 | S26: 9 | T26: 9 | U26: 9 | V26: 9 | W26: =IF(G26>P26,"Y",IF(H26>Q26,"Y",IF(I26>R26,"Y",IF(J26>S26,"Y",IF(K26>T26,"Y",IF(L26>U26,"Y",IF(M26>V26,"Y","N"))))))) -> N | X26: =IF(W26="Y",MAX((G26-P26),(H26-Q26),(I26-R26),(J26-S26),(K26-T26),(L26-U26),(M26-V26))/10,0) -> 0 | Y26: =IF(X26<5%,"0-4.9%",IF(X26<25%,"5-25%",IF(X26<50%,"25-50%","Over 50%"))) -> 0-4.9% | Z26: Empty
A27: 7 | B27: 0.50555556 | C27: UAG 765T | D27: =IF(COUNT(G27:M27)>3,10,IF(COUNT(G27:M27)>2,9,7)) -> 10 | F27: 1*22-22-22 | G27: 4.62 | H27: 3.52 | I27: 2.64 | J27: 1.54 | K27: 2.64 | L27: 1.54 | M27: 2.42 | N27: =SUM(G27:M27) -> 18.92 | O27: =(N27/8.16)^4.5 -> 44.008785 | P27: 8 | Q27: 10 | R27: 9 | S27: 9 | T27: 9 | U27: 9 | V27: 9 | W27: =IF(G27>P27,"Y",IF(H27>Q27,"Y",IF(I27>R27,"Y",IF(J27>S27,"Y",IF(K27>T27,"Y",IF(L27>U27,"Y",IF(M27>V27,"Y","N"))))))) -> N | X27: =IF(W27="Y",MAX((G27-P27),(H27-Q27),(I27-R27),(J27-S27),(K27-T27),(L27-U27),(M27-V27))/10,0) -> 0 | Y27: =IF(X27<5%,"0-4.9%",IF(X27<25%,"5-25%",IF(X27<50%,"25-50%","Over 50%"))) -> 0-4.9% | Z27: Empty
A28: 8 | B28: 0.043055556 | C28: UAW 408F | D28: =IF(COUNT(G28:M28)>3,10,IF(COUNT(G28:M28)>2,9,7)) -> 10 | F28: 1*22-222 | G28: 5.06 | H28: 2.2 | I28: 1.98 | J28: 2.64 | K28: 2.86 | L28: 2.2 | N28: =SUM(G28:M28) -> 16.94 | O28: =(N28/8.16)^4.5 -> 26.76114 | P28: 8 | Q28: 10 | R28: 9 | S28: 9 | T28: 9 | U28: 9 | V28: 9 | W28: =IF(G28>P28,"Y",IF(H28>Q28,"Y",IF(I28>R28,"Y",IF(J28>S28,"Y",IF(K28>T28,"Y",IF(L28>U28,"Y",IF(M28>V28,"Y","N"))))))) -> N | X28: =IF(W28="Y",MAX((G28-P28),(H28-Q28),(I28-R28),(J28-S28),(K28-T28),(L28-U28),(M28-V28))/10,0) -> 0 | Y28: =IF(X28<5%,"0-4.9%",IF(X28<25%,"5-25%",IF(X28<50%,"25-50%","Over 50%"))) -> 0-4.9% | Z28: Empty
A29: 1 | B29: 0.41527778 | C29: UBD 150Q | D29: =IF(COUNT(G29:M29)>3,10,IF(COUNT(G29:M29)>2,9,7)) -> 10 | F29: 1*22-222 | G29: 5.72 | H29: 5.53 | I29: 2.86 | J29: 2.42 | K29: 2.86 | L29: 2.42 | N29: =SUM(G29:M29) -> 21.81 | O29: =(N29/8.16)^4.5 -> 83.43433 | P29: 8 | Q29: 10 | R29: 9 | S29: 9 | T29: 9 | U29: 9 | V29: 9 | W29: =IF(G29>P29,"Y",IF(H29>Q29,"Y",IF(I29>R29,"Y",IF(J29>S29,"Y",IF(K29>T29,"Y",IF(L29>U29,"Y",IF(M29>V29,"Y","N"))))))) -> N | X29: =IF(W29="Y",MAX((G29-P29),(H29-Q29),(I29-R29),(J29-S29),(K29-T29),(L29-U29),(M29-V29))/10,0) -> 0 | Y29: =IF(X29<5%,"0-4.9%",IF(X29<25%,"5-25%",IF(X29<50%,"25-50%","Over 50%"))) -> 0-4.9% | Z29: Empty
A30: 2 | B30: 0.42708333 | C30: KBZ 433A | D30: =IF(COUNT(G30:M30)>3,10,IF(COUNT(G30:M30)>2,9,7)) -> 10 | F30: 1*22-222 | G30: 4.62 | H30: 5.06 | I30: 1.98 | J30: 6.38 | K30: 5.5 | L30: 3.96 | N30: =SUM(G30:M30) -> 27.5 | O30: =(N30/8.16)^4.5 -> 236.80529 | P30: 8 | Q30: 10 | R30: 9 | S30: 9 | T30: 9 | U30: 9 | V30: 9 | W30: =IF(G30>P30,"Y",IF(H30>Q30,"Y",IF(I30>R30,"Y",IF(J30>S30,"Y",IF(K30>T30,"Y",IF(L30>U30,"Y",IF(M30>V30,"Y","N"))))))) -> N | X30: =IF(W30="Y",MAX((G30-P30),(H30-Q30),(I30-R30),(J30-S30),(K30-T30),(L30-U30),(M30-V30))/10,0) -> 0 | Y30: =IF(X30<5%,"0-4.9%",IF(X30<25%,"5-25%",IF(X30<50%,"25-50%","Over 50%"))) -> 0-4.9% | Z30: Empty
A31: 3 | B31: 0.43958333 | C31: KCC 702X | D31: =IF(COUNT(G31:M31)>3,10,IF(COUNT(G31:M31)>2,9,7)) -> 10 | F31: 1*22-222 | G31: 5.5 | H31: 2.42 | I31: 2.42 | J31: 2.2 | K31: 2.2 | L31: 2.2 | N31: =SUM(G31:M31) -> 16.94 | O31: =(N31/8.16)^4.5 -> 26.76114 | P31: 8 | Q31: 10 | R31: 9 | S31: 9 | T31: 9 | U31: 9 | V31: 9 | W31: =IF(G31>P31,"Y",IF(H31>Q31,"Y",IF(I31>R31,"Y",IF(J31>S31,"Y",IF(K31>T31,"Y",IF(L31>U31,"Y",IF(M31>V31,"Y","N"))))))) -> N | X31: =IF(W31="Y",MAX((G31-P31),(H31-Q31),(I31-R31),(J31-S31),(K31-T31),(L31-U31),(M31-V31))/10,0) -> 0 | Y31: =IF(X31<5%,"0-4.9%",IF(X31<25%,"5-25%",IF(X31<50%,"25-50%","Over 50%"))) -> 0-4.9% | Z31: Empty
A32: 5 | B32: 0.49305556 | C32: UAR 533M | D32: =IF(COUNT(G32:M32)>3,10,IF(COUNT(G32:M32)>2,9,7)) -> 10 | F32: 11*22 | G32: 3.3 | H32: 2.64 | I32: 4.84 | J32: 3.08 | N32: =SUM(G32:M32) -> 13.86 | O32: =(N32/8.16)^4.5 -> 10.847479 | P32: 8 | Q32: 10 | R32: 9 | S32: 9 | T32: 9 | U32: 9 | V32: 9 | W32: =IF(G32>P32,"Y",IF(H32>Q32,"Y",IF(I32>R32,"Y",IF(J32>S32,"Y",IF(K32>T32,"Y",IF(L32>U32,"Y",IF(M32>V32,"Y","N"))))))) -> N | X32: =IF(W32="Y",MAX((G32-P32),(H32-Q32),(I32-R32),(J32-S32),(K32-T32),(L32-U32),(M32-V32))/10,0) -> 0 | Y32: =IF(X32<5%,"0-4.9%",IF(X32<25%,"5-25%",IF(X32<50%,"25-50%","Over 50%"))) -> 0-4.9% | Z32: Empty
A33: 6 | B33: 0.53333333 | C33: KAX 604C | D33: =IF(COUNT(G33:M33)>3,10,IF(COUNT(G33:M33)>2,9,7)) -> 10 | F33: 1*22-222 | G33: 6.16 | H33: 3.16 | I33: 3.16 | J33: 2.64 | K33: 1.98 | L33: 1.76 | N33: =SUM(G33:M33) -> 18.86 | O33: =(N33/8.16)^4.5 -> 43.384229 | P33: 8 | Q33: 10 | R33: 9 | S33: 9 | T33: 9 | U33: 9 | V33: 9 | W33: =IF(G33>P33,"Y",IF(H33>Q33,"Y",IF(I33>R33,"Y",IF(J33>S33,"Y",IF(K33>T33,"Y",IF(L33>U33,"Y",IF(M33>V33,"Y","N"))))))) -> N | X33: =IF(W33="Y",MAX((G33-P33),(H33-Q33),(I33-R33),(J33-S33),(K33-T33),(L33-U33),(M33-V33))/10,0) -> 0 | Y33: =IF(X33<5%,"0-4.9%",IF(X33<25%,"5-25%",IF(X33<50%,"25-50%","Over 50%"))) -> 0-4.9% | Z33: Empty
A34: 8 | B34: 0.078472222 | C34: SSD 946F | D34: =IF(COUNT(G34:M34)>3,10,IF(COUNT(G34:M34)>2,9,7)) -> 10 | F34: 1*12-222 | G34: 5.06 | H34: 2.2 | I34: 2.86 | J34: 3.08 | K34: 2.2 | L34: 2.2 | N34: =SUM(G34:M34) -> 17.6 | O34: =(N34/8.16)^4.5 -> 31.783469 | P34: 8 | Q34: 10 | R34: 9 | S34: 9 | T34: 9 | U34: 9 | V34: 9 | W34: =IF(G34>P34,"Y",IF(H34>Q34,"Y",IF(I34>R34,"Y",IF(J34>S34,"Y",IF(K34>T34,"Y",IF(L34>U34,"Y",IF(M34>V34,"Y","N"))))))) -> N | X34: =IF(W34="Y",MAX((G34-P34),(H34-Q34),(I34-R34),(J34-S34),(K34-T34),(L34-U34),(M34-V34))/10,0) -> 0 | Y34: =IF(X34<5%,"0-4.9%",IF(X34<25%,"5-25%",IF(X34<50%,"25-50%","Over 50%"))) -> 0-4.9% | Z34: Empty
A35: 10 | B35: 0.15972222 | C35: UAU 823J | D35: =IF(COUNT(G35:M35)>3,10,IF(COUNT(G35:M35)>2,9,7)) -> 10 | F35: 11*222 | G35: 2.64 | H35: 4.18 | I35: 4.62 | J35: 2.64 | K35: 4.4 | N35: =SUM(G35:M35) -> 18.48 | O35: =(N35/8.16)^4.5 -> 39.58705 | P35: 8 | Q35: 10 | R35: 9 | S35: 9 | T35: 9 | U35: 9 | V35: 9 | W35: =IF(G35>P35,"Y",IF(H35>Q35,"Y",IF(I35>R35,"Y",IF(J35>S35,"Y",IF(K35>T35,"Y",IF(L35>U35,"Y",IF(M35>V35,"Y","N"))))))) -> N | X35: =IF(W35="Y",MAX((G35-P35),(H35-Q35),(I35-R35),(J35-S35),(K35-T35),(L35-U35),(M35-V35))/10,0) -> 0 | Y35: =IF(X35<5%,"0-4.9%",IF(X35<25%,"5-25%",IF(X35<50%,"25-50%","Over 50%"))) -> 0-4.9% | Z35: Empty
A36: 14 | B36: 0.23611111 | C36: UAQ 944Q | D36: =IF(COUNT(G36:M36)>3,10,IF(COUNT(G36:M36)>2,9,7)) -> 10 | F36: 1*22-222 | G36: 4.84 | H36: 2.86 | I36: 2.86 | J36: 1.1 | K36: 1.54 | L36: 1.98 | N36: =SUM(G36:M36) -> 15.18 | O36: =(N36/8.16)^4.5 -> 16.334929 | P36: 8 | Q36: 10 | R36: 9 | S36: 9 | T36: 9 | U36: 9 | V36: 9 | W36: =IF(G36>P36,"Y",IF(H36>Q36,"Y",IF(I36>R36,"Y",IF(J36>S36,"Y",IF(K36>T36,"Y",IF(L36>U36,"Y",IF(M36>V36,"Y","N"))))))) -> N | X36: =IF(W36="Y",MAX((G36-P36),(H36-Q36),(I36-R36),(J36-S36),(K36-T36),(L36-U36),(M36-V36))/10,0) -> 0 | Y36: =IF(X36<5%,"0-4.9%",IF(X36<25%,"5-25%",IF(X36<50%,"25-50%","Over 50%"))) -> 0-4.9% | Z36: Empty
A37: 15 | B37: 0.26527778 | C37: UAR 338X | D37: =IF(COUNT(G37:M37)>3,10,IF(COUNT(G37:M37)>2,9,7)) -> 10 | F37: 1*22-222 | G37: 4.62 | H37: 3.08 | I37: 2.86 | J37: 2.2 | K37: 2.64 | L37: 2.42 | N37: =SUM(G37:M37) -> 17.82 | O37: =(N37/8.16)^4.5 -> 33.610807 | P37: 8 | Q37: 10 | R37: 9 | S37: 9 | T37: 9 | U37: 9 | V37: 9 | W37: =IF(G37>P37,"Y",IF(H37>Q37,"Y",IF(I37>R37,"Y",IF(J37>S37,"Y",IF(K37>T37,"Y",IF(L37>U37,"Y",IF(M37>V37,"Y","N"))))))) -> N | X37: =IF(W37="Y",MAX((G37-P37),(H37-Q37),(I37-R37),(J37-S37),(K37-T37),(L37-U37),(M37-V37))/10,0) -> 0 | Y37: =IF(X37<5%,"0-4.9%",IF(X37<25%,"5-25%",IF(X37<50%,"25-50%","Over 50%"))) -> 0-4.9% | Z37: Empty

Sheet Graphs
B1: AXLE LOAD DATA ANALYSIS (GULU-NIMULE HIGHWAY)
A3: Vehicle Categories | L3: Load Description
B4: Truck Type | C4: Gulu-Nimule | D4: Nimule-Gulu | E4: Both Directions | L4: Category | M4: Gulu-Nimule | N4: Nimule-Gulu
A5: 7 | B5: Light/Medium Trucks | C5: =COUNTIF('Gulu-Nimule'!$D$7:$D$500,A5) -> 13 | D5: =COUNTIF('Nimule-Gulu'!$D$7:$D$500,A5) -> 10 | E5: =SUM(C5:D5) -> 23 | L5: Agricultural produce | M5: =COUNTIF('Gulu-Nimule'!$Z$7:$Z$500,L5)/$M$16 -> 0.3373494 | N5: =COUNTIF('Nimule-Gulu'!$Z$7:$Z$187,L5)/$N$16 -> 0
A6: 9 | B6: Heavy Trucks | C6: =COUNTIF('Gulu-Nimule'!$D$7:$D$500,A6) -> 4 | D6: =COUNTIF('Nimule-Gulu'!$D$7:$D$500,A6) -> 2 | E6: =SUM(C6:D6) -> 6 | L6: Perishable | M6: =COUNTIF('Gulu-Nimule'!$Z$7:$Z$500,L6)/$M$16 -> 0 | N6: =COUNTIF('Nimule-Gulu'!$Z$7:$Z$187,L6)/$N$16 -> 0
A7: 10 | B7: Truck/Trailer | C7: =COUNTIF('Gulu-Nimule'!$D$7:$D$500,A7) -> 66 | D7: =COUNTIF('Nimule-Gulu'!$D$7:$D$500,A7) -> 19 | E7: =SUM(C7:D7) -> 85 | L7: Construction Material | M7: =COUNTIF('Gulu-Nimule'!$Z$7:$Z$500,L7)/$M$16 -> 0.1686747 | N7: =COUNTIF('Nimule-Gulu'!$Z$7:$Z$187,L7)/$N$16 -> 0
