Workbook

Sheet DAY1
A1: Consultancy services for Preparation of Expressway Development Master Plan (EDMP) for Uganda
A2: AXLE LOAD SURVEY FORM
A3: Date: | D3: Station Name: | F3: BUJUUKO
A4: 43704 | H4: KAMPALA-MITYANA
A5: S/No. | B5: Time | C5: Reg. Number | D5: Vehicle Type | E5: Number of Axles | F5: Axle Configuration | G5: Front | H5: KGS | N5: Total (Tonnes) | O5: Total (ESA's) | P5: COMMENTS
G6: Axle 1 | H6: Axle 2 | I6: Axle 3 | J6: Axle 4 | K6: Axle 5 | L6: Axle 6 | M6: Axle 7
A7: 1 | B7: 0.34375 | C7: UGANDA | D7: 5 | F7: 1*2 | G7: 9080 | H7: 11160 | P7: Others
A8: 2 | B8: 0.34722222 | C8: UGANDA | D8: 7 | F8: 1*2 | G8: 1960 | H8: 1720
A9: 3 | B9: 0.34861111 | C9: UGANDA | D9: 10 | F9: 1*22-111 | G9: 7420 | H9: 3960 | I9: 3000 | J9: 4500 | K9: 3000
A10: 4 | B10: 0.35208333 | C10: UGANDA | D10: 8 | F10: 1*2 | G10: 2020 | H10: 3940
A11: 5 | B11: 0.35347222 | C11: UGANDA | D11: 8 | F11: 1*2 | G11: 3980 | H11: 4340
A12: 6 | B12: 0.35625 | C12: UGANDA | D12: 8 | F12: 1*2 | G12: 3200 | H12: 6700
A13: 7 | B13: 0.35763889 | C13: UGANDA | D13: 10 | F13: 1*22-222 | G13: 8120 | H13: 12440 | I13: 11520 | J13: 15560 | K13: 14720 | L13: 18460 | P13: Processed foods and beverages
A14: 8 | B14: 0.35902778 | C14: UGANDA | D14: 8 | F14: 1*2 | G14: 9180 | H14: 16520 | P14: Fertilizer & Chemicals
A15: 9 | B15: 0.35972222 | C15: UGANDA | D15: 8 | F15: 1*2 | G15: 3160 | H15: 3400
A16: 10 | B16: 0.36597222 | C16: UGANDA | D16: 8 | F16: 1*2 | G16: 3360 | H16: 3220
A17: 11 | B17: 0.40833333 | C17: UGANDA | D17: 7 | F17: 1*2 | G17: 2620 | H17: 2860 | P17: Fuels(gas & Liquid)
A18: 12 | B18: 0.41111111 | C18: UGANDA | D18: 8 | F18: 1*2 | G18: 4320 | H18: 4960 | P18: Others
A19: 13 | B19: 0.41319444 | C19: UGANDA | D19: 7 | F19: 1*2 | G19: 3100 | H19: 3560 | P19: Shop items
A20: 14 | B20: 0.41458333 | C20: UGANDA | D20: 10 | F20: 1*22-222 | G20: 8920 | H20: 13580 | I20: 12780 | J20: 17960 | K20: 13940 | L20: 13540 | P20: Building mat./H. ware
A21: 15 | B21: 0.41666667 | C21: UGANDA | D21: 5 | F21: 1*2 | G21: 12140 | H21: 20260 | P21: Others
A22: 16 | B22: 0.42152778 | C22: UGANDA | D22: 8 | F22: 1*2 | G22: 4060 | H22: 4340
A23: 17 | B23: 0.42291667 | C23: UGANDA | D23: 5 | F23: 1*2 | G23: 9320 | H23: 14300 | P23: Others
A24: 18 | B24: 0.42361111 | C24: UGANDA | D24: 8 | F24: 1*2 | G24: 2880 | H24: 4360 | P24: Others
A25: 19 | B25: 0.42430556 | C25: UGANDA | D25: 8 | F25: 1*2 | G25: 3780 | H25: 2860
A26: 20 | B26: 0.43055556 | C26: UGANDA | D26: 10 | F26: 1*12-222 | G26: 6800 | H26: 9200 | I26: 14600 | J26: 15200 | K26: 12700 | L26: 15620 | P26: Building mat./H. ware
A27: 21 | B27: 0.43888889 | C27: UGANDA | D27: 5 | F27: 1*2 | G27: 7780 | H27: 15500 | P27: Others
A28: 22 | B28: 0.44791667 | C28: UGANDA | D28: 10 | F28: 1*2+2*22 | G28: 7080 | H28: 11500 | I28: 8520 | J28: 11880 | K28: 11580 | P28: Shop items
A29: 23 | B29: 0.45416667 | C29: UGANDA | D29: 10 | F29: 1*12-111 | G29: 6200 | H29: 3340 | I29: 5840 | J29: 3440 | K29: 2580 | L29: 5100
A30: 24 | B30: 0.45555556 | C30: UGANDA | D30: 10 | F30: 1*22+22*22 | G30: 4260 | H30: 8020 | I30: 3040 | J30: 2060 | K30: 4020 | L30: 3020 | M30: 4900
A31: 25 | B31: 0.45763889 | C31: UGANDA | D31: 8 | F31: 1*2 | G31: 8140 | H31: 16040 | P31: Agric Produce
A32: 26 | B32: 0.46527778 | C32: UGANDA | D32: 9 | F32: 1*22 | G32: 8640 | H32: 14800 | I32: 8560 | P32: Shop items
A33: 27 | B33: 0.46597222 | C33: UGANDA | D33: 8 | F33: 1*2 | G33: 5880 | H33: 15260 | P33: Fuels(gas & Liquid)
A34: 28 | B34: 0.46666667 | C34: UGANDA | D34: 10 | F34: 1*22-222 | G34: 6720 | H34: 10120 | I34: 6080 | J34: 8060 | K34: 7080 | L34: 8060 | P34: Processed foods and beverages
A35: 29 | B35: 0.46736111 | C35: UGANDA | D35: 10 | F35: 1*22-222 | G35: 7580 | H35: 6080 | I35: 6040 | J35: 7040 | K35: 7050 | L35: 7040 | P35: Processed foods and beverages
A36: 30 | B36: 0.46805556 | C36: UGANDA | D36: 9 | F36: 1*22 | G36: 7560 | H36: 7080 | I36: 6080 | P36: Others
A37: 31 | B37: 0.47013889 | C37: UGANDA | D37: 10 | F37: 1*22-222 | G37: 7780 | H37: 5100 | I37: 4520 | J37: 4500 | K37: 4160 | L37: 4040
A38: 32 | B38: 0.47083333 | C38: UGANDA | D38: 10 | F38: 1*12-222 | G38: 8880 | H38: 3860 | I38: 7080 | J38: 6040 | K38: 6040 | L38: 7040 | P38: Processed foods and beverages
A39: 33 | B39: 0.47222222 | C39: UGANDA | D39: 5 | F39: 1*2 | G39: 10500 | H39: 8060 | P39: Others
A40: 34 | B40: 0.48402778 | C40: UGANDA | D40: 9 | F40: 1*22 | G40: 3140 | H40: 4900 | I40: 760
...

Sheet DAY2
A1: Consultancy services for Preparation of Expressway Development Master Plan (EDMP) for Uganda
A2: AXLE LOAD SURVEY FORM
A3: Date: | D3: Station Name: | E3: BUJUUKO
A4: 43705 | H4: KAMPALA-MITYANA
A5: S/No. | B5: Time | C5: Reg. Number | D5: Vehicle Type | E5: Number of Axles | F5: Axle Configuration | G5: Front | H5: KGS | N5: Total (Tonnes) | O5: Total (ESA's) | P5: COMMENTS
G6: Axle 1 | H6: Axle 2 | I6: Axle 3 | J6: Axle 4 | K6: Axle 5 | L6: Axle 6 | M6: Axle 7
A7: 1 | B7: 0.15902778 | C7: UGANDA | D7: 9 | F7: 1*22 | G7: 7060 | H7: 6020 | I7: 5860
A8: 2 | B8: 0.16388889 | C8: KENYA | D8: 10 | F8: 1*22-222 | G8: 7080 | H8: 4800 | I8: 4700 | J8: 3560 | K8: 3780 | L8: 3440
A9: 3 | B9: 0.16944444 | C9: UGANDA | D9: 10 | F9: 11*222 | G9: 3880 | H9: 6580 | I9: 6220 | J9: 6000 | K9: 5980
A10: 4 | B10: 0.17083333 | C10: KENYA | D10: 10 | F10: 1*22-222 | G10: 6840 | H10: 4860 | I10: 3000 | J10: 3780 | K10: 3120 | L10: 3040
A11: 5 | B11: 0.17430556 | C11: KENYA | D11: 10 | F11: 1*22-222 | G11: 7320 | H11: 4940 | I11: 4860 | J11: 3340 | K11: 4020 | L11: 3860
A12: 6 | B12: 0.19236111 | C12: UGANDA | D12: 10 | F12: 11*222 | G12: 6000 | H12: 4100 | I12: 7980 | J12: 6620 | K12: 7000 | P12: Building mat./H. ware
A13: 7 | B13: 0.19444444 | C13: UGANDA | D13: 8 | F13: 1*2 | G13: 3520 | H13: 4100
A14: 8 | B14: 0.20347222 | C14: UGANDA | D14: 9 | F14: 11*22 | G14: 5660 | H14: 5800 | I14: 11480 | J14: 6820 | P14: Building mat./H. ware
A15: 9 | B15: 0.31111111 | C15: UGANDA | D15: 5 | F15: 1*2 | G15: 10700 | H15: 10580 | P15: Others
A16: 10 | B16: 0.31180556 | C16: UGANDA | D16: 8 | F16: 1*2 | G16: 7680 | H16: 12580 | P16: Shop items
A17: 11 | B17: 0.3125 | C17: UGANDA | D17: 10 | F17: 11*222 | G17: 4740 | H17: 5000 | I17: 5520 | J17: 5720 | K17: 1980
A18: 12 | B18: 0.32916667 | C18: UGANDA | D18: 5 | F18: 1*2 | G18: 10450 | H18: 11500 | P18: Others
A19: 13 | B19: 0.34375 | C19: UGANDA | D19: 8 | F19: 1*2 | G19: 6400 | H19: 8420 | P19: Building mat./H. ware
A20: 14 | B20: 0.34722222 | C20: UGANDA | D20: 8 | F20: 1*2 | G20: 3380 | H20: 5840
A21: 15 | B21: 0.34861111 | C21: UGANDA | D21: 9 | F21: 1*22 | G21: 5400 | H21: 5120 | I21: 4180
A22: 16 | B22: 0.35208333 | C22: UGANDA | D22: 8 | F22: 1*2 | G22: 1780 | H22: 2360
A23: 17 | B23: 0.35347222 | C23: UGANDA | D23: 8 | F23: 1*2 | G23: 3340 | H23: 4680
A24: 18 | B24: 0.35625 | C24: UGANDA | D24: 10 | F24: 11*22 | G24: 8240 | H24: 8380 | I24: 13460 | J24: 10460 | P24: Fuels(gas & Liquid)
A25: 19 | B25: 0.35763889 | C25: UGANDA | D25: 10 | F25: 1*22-222 | G25: 7340 | H25: 4860 | I25: 4340 | J25: 5660 | K25: 3620 | L25: 3600
A26: 20 | B26: 0.35902778 | C26: UGANDA | D26: 8 | F26: 1*2 | G26: 4620 | H26: 4140
A27: 21 | B27: 0.35972222 | C27: UGANDA | D27: 5 | F27: 1*2 | G27: 8200 | H27: 13420 | P27: Others
A28: 22 | B28: 0.36597222 | C28: UGANDA | D28: 8 | F28: 1*2 | G28: 2140 | H28: 2240
A29: 23 | B29: 0.40833333 | C29: UGANDA | D29: 8 | F29: 1*2 | G29: 8080 | H29: 12300 | P29: Building mat./H. ware
A30: 24 | B30: 0.41111111 | C30: UGANDA | D30: 8 | F30: 1*2 | G30: 2980 | H30: 7740 | P30: Fuels(gas & Liquid)
A31: 25 | B31: 0.41319444 | C31: UGANDA | D31: 10 | F31: 1*22-222 | G31: 7980 | H31: 10290 | I31: 10480 | J31: 10920 | K31: 10200 | L31: 10300 | P31: Building mat./H. ware
A32: 26 | B32: 0.41458333 | C32: UGANDA | D32: 10 | F32: 11*22 | G32: 5360 | H32: 4360 | I32: 5180
A33: 27 | B33: 0.41666667 | C33: UGANDA | D33: 8 | F33: 1*2 | G33: 7320 | H33: 11580 | P33: Shop items
A34: 28 | B34: 0.42152778 | C34: KENYA | D34: 10 | F34: 1*12-222 | G34: 6280 | H34: 9060 | I34: 10200 | J34: 7340 | K34: 5360 | L34: 6360 | P34: Fuels(gas & Liquid)
A35: 29 | B35: 0.42291667 | C35: UGANDA | D35: 5 | F35: 1*2 | G35: 8080 | H35: 12740 | P35: Others
A36: 30 | B36: 0.42361111 | C36: UGANDA | D36: 9 | F36: 1*22 | G36: 7160 | H36: 11760 | I36: 12000 | P36: Building mat./H. ware
A37: 31 | B37: 0.42430556 | C37: UGANDA | D37: 9 | F37: 1*22 | G37: 8860 | H37: 5060 | I37: 6400 | P37: Building mat./H. ware
A38: 32 | B38: 0.43055556 | C38: UGANDA | D38: 8 | F38: 1*2 | G38: 4220 | H38: 5660
A39: 33 | B39: 0.43888889 | C39: UGANDA | D39: 8 | F39: 1*2 | G39: 3100 | H39: 4060
A40: 34 | B40: 0.44791667 | C40: UGANDA | D40: 10 | F40: 11*22 | G40: 6920 | H40: 8320 | I40: 1220 | J40: 1220 | P40: Fuels(gas & Liquid)
...

Sheet DAY3
A1: Consultancy services for Preparation of Expressway Development Master Plan (EDMP) for Uganda
A2: AXLE LOAD SURVEY FORM
A3: Date: | D3: Station Name: | E3: BUJUUKO
A4: 43706 | H4: KAMPALA-MITYANA
A5: S/No. | B5: Time | C5: Reg. Number | D5: Vehicle Type | E5: Number of Axles | F5: Axle Configuration | G5: Front | H5: KGS | N5: Total (Tonnes) | O5: Total (ESA's) | P5: COMMENTS
G6: Axle 1 | H6: Axle 2 | I6: Axle 3 | J6: Axle 4 | K6: Axle 5 | L6: Axle 6 | M6: Axle 7
A7: 1 | B7: 0.13472222 | C7: UGANDA | D7: 10 | F7: 1*12-111 | G7: 5660 | H7: 4220 | I7: 8580 | J7: 4440 | K7: 3760 | L7: 3200
A8: 2 | B8: 0.13958333 | C8: UGANDA | D8: 8 | F8: 1*2 | G8: 3460 | H8: 4620 | P8: Others
A9: 3 | B9: 0.14375 | C9: UGANDA | D9: 10 | F9: 1*22-222 | G9: 7760 | H9: 12080 | I9: 10740 | J9: 15240 | K9: 10900 | L9: 10520 | P9: Building mat./H. ware
A10: 4 | B10: 0.14444444 | C10: UGANDA | D10: 10 | F10: 1*22-222 | G10: 7700 | H10: 10720 | I10: 10480 | J10: 15240 | K10: 10720 | L10: 10680
A11: 5 | B11: 0.14583333 | C11: UGANDA | D11: 8 | F11: 1*2 | G11: 3000 | H11: 3520
A12: 6 | B12: 0.14652778 | C12: UGANDA | D12: 8 | F12: 1*2 | G12: 6180 | H12: 11760 | P12: Fuels(gas & Liquid)
A13: 7 | B13: 0.14791667 | C13: UGANDA | D13: 8 | F13: 1*2 | G13: 6280 | H13: 10440 | P13: Shop items
A14: 8 | B14: 0.14930556 | C14: UGANDA | D14: 9 | F14: 1*22 | G14: 3960 | H14: 3520 | I14: 3420
A15: 9 | B15: 0.15 | C15: UGANDA | D15: 8 | F15: 1*2 | G15: 6040 | H15: 12400 | P15: Shop items
A16: 10 | B16: 0.15208333 | C16: UGANDA | D16: 5 | F16: 1*2 | G16: 9060 | H16: 13080 | P16: Others
A17: 11 | B17: 0.15277778 | C17: UGANDA | D17: 9 | F17: 1*21 | G17: 8680 | H17: 11200 | I17: 6300 | P17: Fertilizer & Chemicals
A18: 12 | B18: 0.15347222 | C18: UGANDA | D18: 10 | F18: 11*222 | G18: 6060 | H18: 3020 | I18: 4540 | J18: 4440 | K18: 1220
A19: 13 | B19: 0.15555556 | C19: UGANDA | D19: 10 | F19: 1*22-222 | G19: 6920 | H19: 5600 | I19: 5020 | J19: 3660 | K19: 3040 | L19: 4820
A20: 14 | B20: 0.15902778 | C20: UGANDA | D20: 8 | F20: 1*2 | G20: 7680 | H20: 10480 | P20: Building mat./H. ware
A21: 15 | B21: 0.16388889 | C21: UGANDA | D21: 9 | F21: 1*22 | G21: 5960 | H21: 5940 | I21: 4140 | P21: Others
A22: 16 | B22: 0.16944444 | C22: UGANDA | D22: 8 | F22: 1*2 | G22: 6500 | H22: 10940 | P22: Others
A23: 17 | B23: 0.17083333 | C23: UGANDA | D23: 8 | F23: 1*2 | G23: 5500 | H23: 10720 | P23: Equipment
A24: 18 | B24: 0.17430556 | C24: UGANDA | D24: 10 | F24: 1*12-222 | G24: 8480 | H24: 10120 | I24: 14920 | J24: 9820 | K24: 10240 | L24: 11460 | P24: Building mat./H. ware
A25: 19 | B25: 0.19236111 | C25: UGANDA | D25: 9 | F25: 1*22 | G25: 6260 | H25: 10020 | I25: 9180 | P25: Processed foods and beverages
A26: 20 | B26: 0.19444444 | C26: UGANDA | D26: 8 | F26: 1*2 | G26: 7080 | H26: 10820 | P26: Agric Produce
A27: 21 | B27: 0.20347222 | C27: UGANDA | D27: 10 | F27: 1*12-111 | G27: 9240 | H27: 11420 | I27: 12640 | J27: 10820 | K27: 11220 | L27: 12840 | P27: Building mat./H. ware
A28: 22 | B28: 0.34305556 | C28: UGANDA | D28: 8 | F28: 1*2 | G28: 3620 | H28: 5520 | P28: Others
A29: 23 | B29: 0.34375 | C29: UGANDA | D29: 10 | F29: 1*22-222 | G29: 7220 | H29: 4880 | I29: 4180 | J29: 4780 | K29: 2900 | L29: 4780
A30: 24 | B30: 0.34444444 | C30: UGANDA | D30: 10 | F30: 1*222 | G30: 10520 | H30: 15500 | I30: 16200 | J30: 2120 | P30: Fuels(gas & Liquid)
A31: 25 | B31: 0.34652778 | C31: UGANDA | D31: 8 | F31: 1*2 | G31: 10600 | H31: 11480 | P31: Building mat./H. ware
A32: 26 | B32: 0.34722222 | C32: UGANDA | D32: 10 | F32: 1*2-222 | G32: 8080 | H32: 6660 | I32: 4960 | J32: 4860 | K32: 3760
A33: 27 | B33: 0.34791667 | C33: UGANDA | D33: 5 | F33: 1*2 | G33: 9540 | H33: 5500 | P33: Others
A34: 28 | B34: 0.35069444 | C34: UGANDA | D34: 8 | F34: 1*2 | G34: 9820 | H34: 6500 | I34: 6980 | P34: Fuels(gas & Liquid)
A35: 29 | B35: 0.35277778 | C35: UGANDA | D35: 8 | F35: 1*2 | G35: 1840 | H35: 1860
A36: 30 | B36: 0.35763889 | C36: UGANDA | D36: 10 | F36: 1*22-222 | G36: 6520 | H36: 16400 | I36: 11180 | J36: 19880 | K36: 13480 | L36: 12800 | P36: Building mat./H. ware
A37: 31 | B37: 0.35902778 | C37: UGANDA | D37: 9 | F37: 1*22 | G37: 8360 | H37: 10840 | I37: 10400 | P37: Shop items
A38: 32 | B38: 0.36458333 | C38: UGANDA | D38: 8 | F38: 1*2 | G38: 3400 | H38: 5220
A39: 33 | B39: 0.36597222 | C39: UGANDA | D39: 8 | F39: 1*2 | G39: 3360 | H39: 3460
A40: 34 | B40: 0.37430556 | C40: UGANDA | D40: 10 | F40: 11*22 | G40: 9380 | H40: 9760 | I40: 11480 | J40: 10560 | P40: Shop items
...

Sheet Kla-Mityana
A1: Consultancy services for Preparation of Expressway Development Master Plan (EDMP) for Uganda
A2: AXLE LOAD SURVEY FORM
A3: Date: | D3: Station Name: | F3: BUJUUKO
A4: 43704 | H4: KAMPALA-MITYANA
A5: S/No. | B5: Time | C5: Reg. Number | D5: Vehicle Type | E5: Number of Axles | F5: Axle Configuration | G5: Front | H5: KGS | N5: Total (Tonnes) | O5: Total (ESA's) | P5: Load limit (Tonnes) | W5: OVERLOADED? | X5: Overloaded by? | Y5: Overload Bands | Z5: COMMENTS | AB5: Front | AC5: KGS
G6: Axle 1 | H6: Axle 2 | I6: Axle 3 | J6: Axle 4 | K6: Axle 5 | L6: Axle 6 | M6: Axle 7 | P6: Axle 1 | Q6: Axle 2 | R6: Axle 3 | S6: Axle 4 | T6: Axle 5 | U6: Axle 6 | V6: Axle 7 | AB6: Axle 1 | AC6: Axle 2 | AD6: Axle 3 | AE6: Axle 4 | AF6: Axle 5 | AG6: Axle 6 | AH6: Axle 7
A7: 1 | B7: 0.34375 | C7: UGANDA | D7: =IF(COUNT(G7:M7)>3,10,IF(COUNT(G7:M7)>2,9,7)) -> 7 | F7: 1*2 | G7: =AB7/1000 -> 9.08 | H7: =AC7/1000 -> 11.16 | N7: =SUM(G7:M7) -> 20.24 | O7: =(N7/8.16)^4.5 -> 59.613082 | P7: 8 | Q7: 10 | R7: 9 | S7: 9 | T7: 9 | U7: 9 | V7: 9 | W7: =IF(G7>P7,"Y",IF(H7>Q7,"Y",IF(I7>R7,"Y",IF(J7>S7,"Y",IF(K7>T7,"Y",IF(L7>U7,"Y",IF(M7>V7,"Y","N"))))))) -> Y | X7: =IF(W7="Y",MAX((G7-P7),(H7-Q7),(I7-R7),(J7-S7),(K7-T7),(L7-U7),(M7-V7))/10,0) -> 0.116 | Y7: =IF(X7<5%,"0-4.9%",IF(X7<25%,"5-25%",IF(X7<50%,"25-50%","Over 50%"))) -> 5-25% | Z7: Others | AB7: 9080 | AC7: 11160
A8: 2 | B8: 0.34722222 | C8: UGANDA | D8: =IF(COUNT(G8:M8)>3,10,IF(COUNT(G8:M8)>2,9,7)) -> 7 | F8: 1*2 | G8: =AB8/1000 -> 1.96 | H8: =AC8/1000 -> 1.72 | N8: =SUM(G8:M8) -> 3.68 | O8: =(N8/8.16)^4.5 -> 0.027778543 | P8: 8 | Q8: 10 | R8: 9 | S8: 9 | T8: 9 | U8: 9 | V8: 9 | W8: =IF(G8>P8,"Y",IF(H8>Q8,"Y",IF(I8>R8,"Y",IF(J8>S8,"Y",IF(K8>T8,"Y",IF(L8>U8,"Y",IF(M8>V8,"Y","N"))))))) -> N | X8: =IF(W8="Y",MAX((G8-P8),(H8-Q8),(I8-R8),(J8-S8),(K8-T8),(L8-U8),(M8-V8))/10,0) -> 0 | Y8: =IF(X8<5%,"0-4.9%",IF(X8<25%,"5-25%",IF(X8<50%,"25-50%","Over 50%"))) -> 0-4.9% | Z8: Empty | AB8: 1960 | AC8: 1720
A9: 4 | B9: 0.35208333 | C9: UGANDA | D9: =IF(COUNT(G9:M9)>3,10,IF(COUNT(G9:M9)>2,9,7)) -> 7 | F9: 1*2 | G9: =AB9/1000 -> 2.02 | H9: =AC9/1000 -> 3.94 | N9: =SUM(G9:M9) -> 5.96 | O9: =(N9/8.16)^4.5 -> 0.24322178 | P9: 8 | Q9: 10 | R9: 9 | S9: 9 | T9: 9 | U9: 9 | V9: 9 | W9: =IF(G9>P9,"Y",IF(H9>Q9,"Y",IF(I9>R9,"Y",IF(J9>S9,"Y",IF(K9>T9,"Y",IF(L9>U9,"Y",IF(M9>V9,"Y","N"))))))) -> N | X9: =IF(W9="Y",MAX((G9-P9),(H9-Q9),(I9-R9),(J9-S9),(K9-T9),(L9-U9),(M9-V9))/10,0) -> 0 | Y9: =IF(X9<5%,"0-4.9%",IF(X9<25%,"5-25%",IF(X9<50%,"25-50%","Over 50%"))) -> 0-4.9% | Z9: Empty | AB9: 2020 | AC9: 3940
A10: 5 | B10: 0.35347222 | C10: UGANDA | D10: =IF(COUNT(G10:M10)>3,10,IF(COUNT(G10:M10)>2,9,7)) -> 7 | F10: 1*2 | G10: =AB10/1000 -> 3.98 | H10: =AC10/1000 -> 4.34 | N10: =SUM(G10:M10) -> 8.32 | O10: =(N10/8.16)^4.5 -> 1.0913128 | P10: 8 | Q10: 10 | R10: 9 | S10: 9 | T10: 9 | U10: 9 | V10: 9 | W10: =IF(G10>P10,"Y",IF(H10>Q10,"Y",IF(I10>R10,"Y",IF(J10>S10,"Y",IF(K10>T10,"Y",IF(L10>U10,"Y",IF(M10>V10,"Y","N"))))))) -> N | X10: =IF(W10="Y",MAX((G10-P10),(H10-Q10),(I10-R10),(J10-S10),(K10-T10),(L10-U10),(M10-V10))/10,0) -> 0 | Y10: =IF(X10<5%,"0-4.9%",IF(X10<25%,"5-25%",IF(X10<50%,"25-50%","Over 50%"))) -> 0-4.9% | Z10: Empty | AB10: 3980 | AC10: 4340
A11: 6 | B11: 0.35625 | C11: UGANDA | D11: =IF(COUNT(G11:M11)>3,10,IF(COUNT(G11:M11)>2,9,7)) -> 7 | F11: 1*2 | G11: =AB11/1000 -> 3.2 | H11: =AC11/1000 -> 6.7 | N11: =SUM(G11:M11) -> 9.9 | O11: =(N11/8.16)^4.5 -> 2.3864518 | P11: 8 | Q11: 10 | R11: 9 | S11: 9 | T11: 9 | U11: 9 | V11: 9 | W11: =IF(G11>P11,"Y",IF(H11>Q11,"Y",IF(I11>R11,"Y",IF(J11>S11,"Y",IF(K11>T11,"Y",IF(L11>U11,"Y",IF(M11>V11,"Y","N"))))))) -> N | X11: =IF(W11="Y",MAX((G11-P11),(H11-Q11),(I11-R11),(J11-S11),(K11-T11),(L11-U11),(M11-V11))/10,0) -> 0 | Y11: =IF(X11<5%,"0-4.9%",IF(X11<25%,"5-25%",IF(X11<50%,"25-50%","Over 50%"))) -> 0-4.9% | Z11: Empty | AB11: 3200 | AC11: 6700
A12: 8 | B12: 0.35902778 | C12: UGANDA | D12: =IF(COUNT(G12:M12)>3,10,IF(COUNT(G12:M12)>2,9,7)) -> 7 | F12: 1*2 | G12: =AB12/1000 -> 9.18 | H12: =AC12/1000 -> 16.52 | N12: =SUM(G12:M12) -> 25.7 | O12: =(N12/8.16)^4.5 -> 174.61974 | P12: 8 | Q12: 10 | R12: 9 | S12: 9 | T12: 9 | U12: 9 | V12: 9 | W12: =IF(G12>P12,"Y",IF(H12>Q12,"Y",IF(I12>R12,"Y",IF(J12>S12,"Y",IF(K12>T12,"Y",IF(L12>U12,"Y",IF(M12>V12,"Y","N"))))))) -> Y | X12: =IF(W12="Y",MAX((G12-P12),(H12-Q12),(I12-R12),(J12-S12),(K12-T12),(L12-U12),(M12-V12))/10,0) -> 0.652 | Y12: =IF(X12<5%,"0-4.9%",IF(X12<25%,"5-25%",IF(X12<50%,"25-50%","Over 50%"))) -> Over 50% | Z12: Chemical Products | AB12: 9180 | AC12: 16520
A13: 9 | B13: 0.35972222 | C13: UGANDA | D13: =IF(COUNT(G13:M13)>3,10,IF(COUNT(G13:M13)>2,9,7)) -> 7 | F13: 1*2 | G13: =AB13/1000 -> 3.16 | H13: =AC13/1000 -> 3.4 | N13: =SUM(G13:M13) -> 6.56 | O13: =(N13/8.16)^4.5 -> 0.3745084 | P13: 8 | Q13: 10 | R13: 9 | S13: 9 | T13: 9 | U13: 9 | V13: 9 | W13: =IF(G13>P13,"Y",IF(H13>Q13,"Y",IF(I13>R13,"Y",IF(J13>S13,"Y",IF(K13>T13,"Y",IF(L13>U13,"Y",IF(M13>V13,"Y","N"))))))) -> N | X13: =IF(W13="Y",MAX((G13-P13),(H13-Q13),(I13-R13),(J13-S13),(K13-T13),(L13-U13),(M13-V13))/10,0) -> 0 | Y13: =IF(X13<5%,"0-4.9%",IF(X13<25%,"5-25%",IF(X13<50%,"25-50%","Over 50%"))) -> 0-4.9% | Z13: Empty | AB13: 3160 | AC13: 3400
A14: 10 | B14: 0.36597222 | C14: UGANDA | D14: =IF(COUNT(G14:M14)>3,10,IF(COUNT(G14:M14)>2,9,7)) -> 7 | F14: 1*2 | G14: =AB14/1000 -> 3.36 | H14: =AC14/1000 -> 3.22 | N14: =SUM(G14:M14) -> 6.58 | O14: =(N14/8.16)^4.5 -> 0.37967396 | P14: 8 | Q14: 10 | R14: 9 | S14: 9 | T14: 9 | U14: 9 | V14: 9 | W14: =IF(G14>P14,"Y",IF(H14>Q14,"Y",IF(I14>R14,"Y",IF(J14>S14,"Y",IF(K14>T14,"Y",IF(L14>U14,"Y",IF(M14>V14,"Y","N"))))))) -> N | X14: =IF(W14="Y",MAX((G14-P14),(H14-Q14),(I14-R14),(J14-S14),(K14-T14),(L14-U14),(M14-V14))/10,0) -> 0 | Y14: =IF(X14<5%,"0-4.9%",IF(X14<25%,"5-25%",IF(X14<50%,"25-50%","Over 50%"))) -> 0-4.9% | Z14: Empty | AB14: 3360 | AC14: 3220
A15: 11 | B15: 0.40833333 | C15: UGANDA | D15: =IF(COUNT(G15:M15)>3,10,IF(COUNT(G15:M15)>2,9,7)) -> 7 | F15: 1*2 | G15: =AB15/1000 -> 2.62 | H15: =AC15/1000 -> 2.86 | N15: =SUM(G15:M15) -> 5.48 | O15: =(N15/8.16)^4.5 -> 0.16668895 | P15: 8 | Q15: 10 | R15: 9 | S15: 9 | T15: 9 | U15: 9 | V15: 9 | W15: =IF(G15>P15,"Y",IF(H15>Q15,"Y",IF(I15>R15,"Y",IF(J15>S15,"Y",IF(K15>T15,"Y",IF(L15>U15,"Y",IF(M15>V15,"Y","N"))))))) -> N | X15: =IF(W15="Y",MAX((G15-P15),(H15-Q15),(I15-R15),(J15-S15),(K15-T15),(L15-U15),(M15-V15))/10,0) -> 0 | Y15: =IF(X15<5%,"0-4.9%",IF(X15<25%,"5-25%",IF(X15<50%,"25-50%","Over 50%"))) -> 0-4.9% | Z15: Fuels | AB15: 2620 | AC15: 2860
A16: 12 | B16: 0.41111111 | C16: UGANDA | D16: =IF(COUNT(G16:M16)>3,10,IF(COUNT(G16:M16)>2,9,7)) -> 7 | F16: 1*2 | G16: =AB16/1000 -> 4.32 | H16: =AC16/1000 -> 4.96 | N16: =SUM(G16:M16) -> 9.28 | O16: =(N16/8.16)^4.5 -> 1.7838576 | P16: 8 | Q16: 10 | R16: 9 | S16: 9 | T16: 9 | U16: 9 | V16: 9 | W16: =IF(G16>P16,"Y",IF(H16>Q16,"Y",IF(I16>R16,"Y",IF(J16>S16,"Y",IF(K16>T16,"Y",IF(L16>U16,"Y",IF(M16>V16,"Y","N"))))))) -> N | X16: =IF(W16="Y",MAX((G16-P16),(H16-Q16),(I16-R16),(J16-S16),(K16-T16),(L16-U16),(M16-V16))/10,0) -> 0 | Y16: =IF(X16<5%,"0-4.9%",IF(X16<25%,"5-25%",IF(X16<50%,"25-50%","Over 50%"))) -> 0-4.9% | Z16: Others | AB16: 4320 | AC16: 4960
A17: 13 | B17: 0.41319444 | C17: UGANDA | D17: =IF(COUNT(G17:M17)>3,10,IF(COUNT(G17:M17)>2,9,7)) -> 7 | F17: 1*2 | G17: =AB17/1000 -> 3.1 | H17: =AC17/1000 -> 3.56 | N17: =SUM(G17:M17) -> 6.66 | O17: =(N17/8.16)^4.5 -> 0.40089286 | P17: 8 | Q17: 10 | R17: 9 | S17: 9 | T17: 9 | U17: 9 | V17: 9 | W17: =IF(G17>P17,"Y",IF(H17>Q17,"Y",IF(I17>R17,"Y",IF(J17>S17,"Y",IF(K17>T17,"Y",IF(L17>U17,"Y",IF(M17>V17,"Y","N"))))))) -> N | X17: =IF(W17="Y",MAX((G17-P17),(H17-Q17),(I17-R17),(J17-S17),(K17-T17),(L17-U17),(M17-V17))/10,0) -> 0 | Y17: =IF(X17<5%,"0-4.9%",IF(X17<25%,"5-25%",IF(X17<50%,"25-50%","Over 50%"))) -> 0-4.9% | Z17: Household retail products | AB17: 3100 | AC17: 3560
A18: 15 | B18: 0.41666667 | C18: UGANDA | D18: =IF(COUNT(G18:M18)>3,10,IF(COUNT(G18:M18)>2,9,7)) -> 7 | F18: 1*2 | G18: =AB18/1000 -> 12.14 | H18: =AC18/1000 -> 20.26 | N18: =SUM(G18:M18) -> 32.4 | O18: =(N18/8.16)^4.5 -> 495.27548 | P18: 8 | Q18: 10 | R18: 9 | S18: 9 | T18: 9 | U18: 9 | V18: 9 | W18: =IF(G18>P18,"Y",IF(H18>Q18,"Y",IF(I18>R18,"Y",IF(J18>S18,"Y",IF(K18>T18,"Y",IF(L18>U18,"Y",IF(M18>V18,"Y","N"))))))) -> Y | X18: =IF(W18="Y",MAX((G18-P18),(H18-Q18),(I18-R18),(J18-S18),(K18-T18),(L18-U18),(M18-V18))/10,0) -> 1.026 | Y18: =IF(X18<5%,"0-4.9%",IF(X18<25%,"5-25%",IF(X18<50%,"25-50%","Over 50%"))) -> Over 50% | Z18: Others | AB18: 12140 | AC18: 20260
... A110: 41 | B110: 0.41736111 | C110: UGANDA | D110: =IF(COUNT(G110:M110)>3,10,IF(COUNT(G110:M110)>2,9,7)) -> 7 | F110: 1*2 | G110: =AB110/1000 -> 5.64 | H110: =AC110/1000 -> 11.8 | N110: =SUM(G110:M110) -> 17.44 | O110: =(N110/8.16)^4.5 -> 30.503765 | P110: 8 | Q110: 10 | R110: 9 | S110: 9 | T110: 9 | U110: 9 | V110: 9 | W110: =IF(G110>P110,"Y",IF(H110>Q110,"Y",IF(I110>R110,"Y",IF(J110>S110,"Y",IF(K110>T110,"Y",IF(L110>U110,"Y",IF(M110>V110,"Y","N"))))))) -> Y | X110: =IF(W110="Y",MAX((G110-P110),(H110-Q110),(I110-R110),(J110-S110),(K110-T110),(L110-U110),(M110-V110))/10,0) -> 0.18 | Y110: =IF(X110<5%,"0-4.9%",IF(X110<25%,"5-25%",IF(X110<50%,"25-50%","Over 50%"))) -> 5-25% | Z110: Household retail products | AB110: 5640 | AC110: 11800
A111: 45 | B111: 0.44027778 | C111: UGANDA | D111: =IF(COUNT(G111:M111)>3,10,IF(COUNT(G111:M111)>2,9,7)) -> 9 | F111: 1*22 | G111: =AB111/1000 -> 10.08 | H111: =AC111/1000 -> 5.7 | I111: =AD111/1000 -> 8.56 | N111: =SUM(G111:M111) -> 24.34 | O111: =(N111/8.16)^4.5 -> 136.72152 | P111: 8 | Q111: 10 | R111: 9 | S111: 9 | T111: 9 | U111: 9 | V111: 9 | W111: =IF(G111>P111,"Y",IF(H111>Q111,"Y",IF(I111>R111,"Y",IF(J111>S111,"Y",IF(K111>T111,"Y",IF(L111>U111,"Y",IF(M111>V111,"Y","N"))))))) -> Y | X111: =IF(W111="Y",MAX((G111-P111),(H111-Q111),(I111-R111),(J111-S111),(K111-T111),(L111-U111),(M111-V111))/10,0) -> 0.208 | Y111: =IF(X111<5%,"0-4.9%",IF(X111<25%,"5-25%",IF(X111<50%,"25-50%","Over 50%"))) -> 5-25% | Z111: Others | AB111: 10080 | AC111: 5700 | AD111: 8560
A112: 46 | B112: 0.44166667 | C112: UGANDA | D112: =IF(COUNT(G112:M112)>3,10,IF(COUNT(G112:M112)>2,9,7)) -> 9 | F112: 1*22 | G112: =AB112/1000 -> 6.96 | H112: =AC112/1000 -> 10.96 | I112: =AD112/1000 -> 6.08 | N112: =SUM(G112:M112) -> 24 | O112: =(N112/8.16)^4.5 -> 128.33493 | P112: 8 | Q112: 10 | R112: 9 | S112: 9 | T112: 9 | U112: 9 | V112: 9 | W112: =IF(G112>P112,"Y",IF(H112>Q112,"Y",IF(I112>R112,"Y",IF(J112>S112,"Y",IF(K112>T112,"Y",IF(L112>U112,"Y",IF(M112>V112,"Y","N"))))))) -> Y | X112: =IF(W112="Y",MAX((G112-P112),(H112-Q112),(I112-R112),(J112-S112),(K112-T112),(L112-U112),(M112-V112))/10,0) -> 0.096 | Y112: =IF(X112<5%,"0-4.9%",IF(X112<25%,"5-25%",IF(X112<50%,"25-50%","Over 50%"))) -> 5-25% | Z112: Agricultural produce | AB112: 6960 | AC112: 10960 | AD112: 6080
A113: 49 | B113: 0.44791667 | C113: UGANDA | D113: =IF(COUNT(G113:M113)>3,10,IF(COUNT(G113:M113)>2,9,7)) -> 9 | F113: 1*22 | G113: =AB113/1000 -> 9.2 | H113: =AC113/1000 -> 12.18 | I113: =AD113/1000 -> 0.76 | N113: =SUM(G113:M113) -> 22.14 | O113: =(N113/8.16)^4.5 -> 89.267539 | P113: 8 | Q113: 10 | R113: 9 | S113: 9 | T113: 9 | U113: 9 | V113: 9 | W113: =IF(G113>P113,"Y",IF(H113>Q113,"Y",IF(I113>R113,"Y",IF(J113>S113,"Y",IF(K113>T113,"Y",IF(L113>U113,"Y",IF(M113>V113,"Y","N"))))))) -> Y | X113: =IF(W113="Y",MAX((G113-P113),(H113-Q113),(I113-R113),(J113-S113),(K113-T113),(L113-U113),(M113-V113))/10,0) -> 0.218 | Y113: =IF(X113<5%,"0-4.9%",IF(X113<25%,"5-25%",IF(X113<50%,"25-50%","Over 50%"))) -> 5-25% | Z113: Fuels | AB113: 9200 | AC113: 12180 | AD113: 760
A114: 50 | B114: 0.45 | C114: UGANDA | D114: =IF(COUNT(G114:M114)>3,10,IF(COUNT(G114:M114)>2,9,7)) -> 9 | F114: 1*22 | G114: =AB114/1000 -> 5.98 | H114: =AC114/1000 -> 14.2 | I114: =AD114/1000 -> 5.5 | N114: =SUM(G114:M114) -> 25.68 | O114: =(N114/8.16)^4.5 -> 174.00906 | P114: 8 | Q114: 10 | R114: 9 | S114: 9 | T114: 9 | U114: 9 | V114: 9 | W114: =IF(G114>P114,"Y",IF(H114>Q114,"Y",IF(I114>R114,"Y",IF(J114>S114,"Y",IF(K114>T114,"Y",IF(L114>U114,"Y",IF(M114>V114,"Y","N"))))))) -> Y | X114: =IF(W114="Y",MAX((G114-P114),(H114-Q114),(I114-R114),(J114-S114),(K114-T114),(L114-U114),(M114-V114))/10,0) -> 0.42 | Y114: =IF(X114<5%,"0-4.9%",IF(X114<25%,"5-25%",IF(X114<50%,"25-50%","Over 50%"))) -> 25-50% | Z114: Fuels | AB114: 5980 | AC114: 14200 | AD114: 5500
A115: 51 | B115: 0.45138889 | C115: UGANDA | D115: =IF(COUNT(G115:M115)>3,10,IF(COUNT(G115:M115)>2,9,7)) -> 9 | F115: 1*22 | G115: =AB115/1000 -> 8.02 | H115: =AC115/1000 -> 7.66 | I115: =AD115/1000 -> 10.62 | N115: =SUM(G115:M115) -> 26.3 | O115: =(N115/8.16)^4.5 -> 193.72923 | P115: 8 | Q115: 10 | R115: 9 | S115: 9 | T115: 9 | U115: 9 | V115: 9 | W115: =IF(G115>P115,"Y",IF(H115>Q115,"Y",IF(I115>R115,"Y",IF(J115>S115,"Y",IF(K115>T115,"Y",IF(L115>U115,"Y",IF(M115>V115,"Y","N"))))))) -> Y | X115: =IF(W115="Y",MAX((G115-P115),(H115-Q115),(I115-R115),(J115-S115),(K115-T115),(L115-U115),(M115-V115))/10,0) -> 0.162 | Y115: =IF(X115<5%,"0-4.9%",IF(X115<25%,"5-25%",IF(X115<50%,"25-50%","Over 50%"))) -> 5-25% | Z115: Construction Material | AB115: 8020 | AC115: 7660 | AD115: 10620
A116: 53 | B116: 0.45555556 | C116: UGANDA | D116: =IF(COUNT(G116:M116)>3,10,IF(COUNT(G116:M116)>2,9,7)) -> 9 | F116: 1*22 | G116: =AB116/1000 -> 4.92 | H116: =AC116/1000 -> 5.44 | I116: =AD116/1000 -> 4.6 | N116: =SUM(G116:M116) -> 14.96 | O116: =(N116/8.16)^4.5 -> 15.296302 | P116: 8 | Q116: 10 | R116: 9 | S116: 9 | T116: 9 | U116: 9 | V116: 9 | W116: =IF(G116>P116,"Y",IF(H116>Q116,"Y",IF(I116>R116,"Y",IF(J116>S116,"Y",IF(K116>T116,"Y",IF(L116>U116,"Y",IF(M116>V116,"Y","N"))))))) -> N | X116: =IF(W116="Y",MAX((G116-P116),(H116-Q116),(I116-R116),(J116-S116),(K116-T116),(L116-U116),(M116-V116))/10,0) -> 0 | Y116: =IF(X116<5%,"0-4.9%",IF(X116<25%,"5-25%",IF(X116<50%,"25-50%","Over 50%"))) -> 0-4.9% | Z116: Empty | AB116: 4920 | AC116: 5440 | AD116: 4600
A117: 56 | B117: 0.46388889 | C117: UGANDA | D117: =IF(COUNT(G117:M117)>3,10,IF(COUNT(G117:M117)>2,9,7)) -> 9 | F117: 1*22 | G117: =AB117/1000 -> 10.06 | H117: =AC117/1000 -> 8.68 | I117: =AD117/1000 -> 4.6 | N117: =SUM(G117:M117) -> 23.34 | O117: =(N117/8.16)^4.5 -> 113.20044 | P117: 8 | Q117: 10 | R117: 9 | S117: 9 | T117: 9 | U117: 9 | V117: 9 | W117: =IF(G117>P117,"Y",IF(H117>Q117,"Y",IF(I117>R117,"Y",IF(J117>S117,"Y",IF(K117>T117,"Y",IF(L117>U117,"Y",IF(M117>V117,"Y","N"))))))) -> Y | X117: =IF(W117="Y",MAX((G117-P117),(H117-Q117),(I117-R117),(J117-S117),(K117-T117),(L117-U117),(M117-V117))/10,0) -> 0.206 | Y117: =IF(X117<5%,"0-4.9%",IF(X117<25%,"5-25%",IF(X117<50%,"25-50%","Over 50%"))) -> 5-25% | Z117: Others | AB117: 10060 | AC117: 8680 | AD117: 4600
A118: 57 | B118: 0.46527778 | C118: UGANDA | D118: =IF(COUNT(G118:M118)>3,10,IF(COUNT(G118:M118)>2,9,7)) -> 9 | F118: 1*22 | G118: =AB118/1000 -> 10.66 | H118: =AC118/1000 -> 11.18 | I118: =AD118/1000 -> 4.68 | N118: =SUM(G118:M118) -> 26.52 | O118: =(N118/8.16)^4.5 -> 201.1292 | P118: 8 | Q118: 10 | R118: 9 | S118: 9 | T118: 9 | U118: 9 | V118: 9 | W118: =IF(G118>P118,"Y",IF(H118>Q118,"Y",IF(I118>R118,"Y",IF(J118>S118,"Y",IF(K118>T118,"Y",IF(L118>U118,"Y",IF(M118>V118,"Y","N"))))))) -> Y | X118: =IF(W118="Y",MAX((G118-P118),(H118-Q118),(I118-R118),(J118-S118),(K118-T118),(L118-U118),(M118-V118))/10,0) -> 0.266 | Y118: =IF(X118<5%,"0-4.9%",IF(X118<25%,"5-25%",IF(X118<50%,"25-50%","Over 50%"))) -> 25-50% | Z118: Others | AB118: 10660 | AC118: 11180 | AD118: 4680
A119: 58 | B119: 0.46597222 | C119: UGANDA | D119: =IF(COUNT(G119:M119)>3,10,IF(COUNT(G119:M119)>2,9,7)) -> 9 | F119: 1*22 | G119: =AB119/1000 -> 6.4 | H119: =AC119/1000 -> 10.25 | I119: =AD119/1000 -> 4.52 | N119: =SUM(G119:M119) -> 21.17 | O119: =(N119/8.16)^4.5 -> 72.968958 | P119: 8 | Q119: 10 | R119: 9 | S119: 9 | T119: 9 | U119: 9 | V119: 9 | W119: =IF(G119>P119,"Y",IF(H119>Q119,"Y",IF(I119>R119,"Y",IF(J119>S119,"Y",IF(K119>T119,"Y",IF(L119>U119,"Y",IF(M119>V119,"Y","N"))))))) -> Y | X119: =IF(W119="Y",MAX((G119-P119),(H119-Q119),(I119-R119),(J119-S119),(K119-T119),(L119-U119),(M119-V119))/10,0) -> 0.025 | Y119: =IF(X119<5%,"0-4.9%",IF(X119<25%,"5-25%",IF(X119<50%,"25-50%","Over 50%"))) -> 0-4.9% | Z119: Fuels | AB119: 6400 | AC119: 10250 | AD119: 4520
A120: 59 | B120: 0.46805556 | C120: UGANDA | D120: =IF(COUNT(G120:M120)>3,10,IF(COUNT(G120:M120)>2,9,7)) -> 9 | F120: 1*22 | G120: =AB120/1000 -> 3.18 | H120: =AC120/1000 -> 3.18 | I120: =AD120/1000 -> 3.96 | N120: =SUM(G120:M120) -> 10.32 | O120: =(N120/8.16)^4.5 -> 2.8770865 | P120: 8 | Q120: 10 | R120: 9 | S120: 9 | T120: 9 | U120: 9 | V120: 9 | W120: =IF(G120>P120,"Y",IF(H120>Q120,"Y",IF(I120>R120,"Y",IF(J120>S120,"Y",IF(K120>T120,"Y",IF(L120>U120,"Y",IF(M120>V120,"Y","N"))))))) -> N | X120: =IF(W120="Y",MAX((G120-P120),(H120-Q120),(I120-R120),(J120-S120),(K120-T120),(L120-U120),(M120-V120))/10,0) -> 0 | Y120: =IF(X120<5%,"0-4.9%",IF(X120<25%,"5-25%",IF(X120<50%,"25-50%","Over 50%"))) -> 0-4.9% | Z120: Empty | AB120: 3180 | AC120: 3180 | AD120: 3960
A121: 60 | B121: 0.47152778 | C121: UGANDA | D121: =IF(COUNT(G121:M121)>3,10,IF(COUNT(G121:M121)>2,9,7)) -> 9 | F121: 1*22 | G121: =AB121/1000 -> 2.74 | H121: =AC121/1000 -> 8.66 | I121: =AD121/1000 -> 5.86 | N121: =SUM(G121:M121) -> 17.26 | O121: =(N121/8.16)^4.5 -> 29.112389 | P121: 8 | Q121: 10 | R121: 9 | S121: 9 | T121: 9 | U121: 9 | V121: 9 | W121: =IF(G121>P121,"Y",IF(H121>Q121,"Y",IF(I121>R121,"Y",IF(J121>S121,"Y",IF(K121>T121,"Y",IF(L121>U121,"Y",IF(M121>V121,"Y","N"))))))) -> N | X121: =IF(W121="Y",MAX((G121-P121),(H121-Q121),(I121-R121),(J121-S121),(K121-T121),(L121-U121),(M121-V121))/10,0) -> 0 | Y121: =IF(X121<5%,"0-4.9%",IF(X121<25%,"5-25%",IF(X121<50%,"25-50%","Over 50%"))) -> 0-4.9% | Z121: Construction Material | AB121: 2740 | AC121: 8660 | AD121: 5860
A122: 61 | B122: 0.47361111 | C122: UGANDA | D122: =IF(COUNT(G122:M122)>3,10,IF(COUNT(G122:M122)>2,9,7)) -> 9 | F122: 1*22 | G122: =AB122/1000 -> 5.9 | H122: =AC122/1000 -> 12.08 | I122: =AD122/1000 -> 4.18 | N122: =SUM(G122:M122) -> 22.16 | O122: =(N122/8.16)^4.5 -> 89.630989 | P122: 8 | Q122: 10 | R122: 9 | S122: 9 | T122: 9 | U122: 9 | V122: 9 | W122: =IF(G122>P122,"Y",IF(H122>Q122,"Y",IF(I122>R122,"Y",IF(J122>S122,"Y",IF(K122>T122,"Y",IF(L122>U122,"Y",IF(M122>V122,"Y","N"))))))) -> Y | X122: =IF(W122="Y",MAX((G122-P122),(H122-Q122),(I122-R122),(J122-S122),(K122-T122),(L122-U122),(M122-V122))/10,0) -> 0.208 | Y122: =IF(X122<5%,"0-4.9%",IF(X122<25%,"5-25%",IF(X122<50%,"25-50%","Over 50%"))) -> 5-25% | Z122: Others | AB122: 5900 | AC122: 12080 | AD122: 4180
... A125: 74 | B125: 0.49305556 | C125: UGANDA | D125: =IF(COUNT(G125:M125)>3,10,IF(COUNT(G125:M125)>2,9,7)) -> 9 | F125: 1*22 | G125: =AB125/1000 -> 8.56 | H125: =AC125/1000 -> 10.54 | I125: =AD125/1000 -> 6.4 | N125: =SUM(G125:M125) -> 25.5 | O125: =(N125/8.16)^4.5 -> 168.58739 | P125: 8 | Q125: 10 | R125: 9 | S125: 9 | T125: 9 | U125: 9 | V125: 9 | W125: =IF(G125>P125,"Y",IF(H125>Q125,"Y",IF(I125>R125,"Y",IF(J125>S125,"Y",IF(K125>T125,"Y",IF(L125>U125,"Y",IF(M125>V125,"Y","N"))))))) -> Y | X125: =IF(W125="Y",MAX((G125-P125),(H125-Q125),(I125-R125),(J125-S125),(K125-T125),(L125-U125),(M125-V125))/10,0) -> 0.056 | Y125: =IF(X125<5%,"0-4.9%",IF(X125<25%,"5-25%",IF(X125<50%,"25-50%","Over 50%"))) -> 5-25% | Z125: Others | AB125: 8560 | AC125: 10540 | AD125: 6400
A126: 77 | C126: UGANDA | D126: =IF(COUNT(G126:M126)>3,10,IF(COUNT(G126:M126)>2,9,7)) -> 9 | F126: 1*22 | G126: =AB126/1000 -> 5.18 | H126: =AC126/1000 -> 14.92 | I126: =AD126/1000 -> 7.28 | N126: =SUM(G126:M126) -> 27.38 | O126: =(N126/8.16)^4.5 -> 232.19068 | P126: 8 | Q126: 10 | R126: 9 | S126: 9 | T126: 9 | U126: 9 | V126: 9 | W126: =IF(G126>P126,"Y",IF(H126>Q126,"Y",IF(I126>R126,"Y",IF(J126>S126,"Y",IF(K126>T126,"Y",IF(L126>U126,"Y",IF(M126>V126,"Y","N"))))))) -> Y | X126: =IF(W126="Y",MAX((G126-P126),(H126-Q126),(I126-R126),(J126-S126),(K126-T126),(L126-U126),(M126-V126))/10,0) -> 0.492 | Y126: =IF(X126<5%,"0-4.9%",IF(X126<25%,"5-25%",IF(X126<50%,"25-50%","Over 50%"))) -> 25-50% | Z126: Agricultural produce | AB126: 5180 | AC126: 14920 | AD126: 7280
A127: 79 | B127: 0.50416667 | C127: UGANDA | D127: =IF(COUNT(G127:M127)>3,10,IF(COUNT(G127:M127)>2,9,7)) -> 9 | F127: 1*22 | G127: =AB127/1000 -> 3.62 | H127: =AC127/1000 -> 4 | I127: =AD127/1000 -> 4 | N127: =SUM(G127:M127) -> 11.62 | O127: =(N127/8.16)^4.5 -> 4.9070656 | P127: 8 | Q127: 10 | R127: 9 | S127: 9 | T127: 9 | U127: 9 | V127: 9 | W127: =IF(G127>P127,"Y",IF(H127>Q127,"Y",IF(I127>R127,"Y",IF(J127>S127,"Y",IF(K127>T127,"Y",IF(L127>U127,"Y",IF(M127>V127,"Y","N"))))))) -> N | X127: =IF(W127="Y",MAX((G127-P127),(H127-Q127),(I127-R127),(J127-S127),(K127-T127),(L127-U127),(M127-V127))/10,0) -> 0 | Y127: =IF(X127<5%,"0-4.9%",IF(X127<25%,"5-25%",IF(X127<50%,"25-50%","Over 50%"))) -> 0-4.9% | Z127: Empty | AB127: 3620 | AC127: 4000 | AD127: 4000
A128: 80 | B128: 0.50486111 | C128: UGANDA | D128: =IF(COUNT(G128:M128)>3,10,IF(COUNT(G128:M128)>2,9,7)) -> 9 | F128: 1*22 | G128: =AB128/1000 -> 8.07 | H128: =AC128/1000 -> 12.14 | I128: =AD128/1000 -> 4.64 | N128: =SUM(G128:M128) -> 24.85 | O128: =(N128/8.16)^4.5 -> 150.0939 | P128: 8 | Q128: 10 | R128: 9 | S128: 9 | T128: 9 | U128: 9 | V128: 9 | W128: =IF(G128>P128,"Y",IF(H128>Q128,"Y",IF(I128>R128,"Y",IF(J128>S128,"Y",IF(K128>T128,"Y",IF(L128>U128,"Y",IF(M128>V128,"Y","N"))))))) -> Y | X128: =IF(W128="Y",MAX((G128-P128),(H128-Q128),(I128-R128),(J128-S128),(K128-T128),(L128-U128),(M128-V128))/10,0) -> 0.214 | Y128: =IF(X128<5%,"0-4.9%",IF(X128<25%,"5-25%",IF(X128<50%,"25-50%","Over 50%"))) -> 5-25% | Z128: Others | AB128: 8070 | AC128: 12140 | AD128: 4640
A129: 81 | B129: 0.50763889 | C129: UGANDA | D129: =IF(COUNT(G129:M129)>3,10,IF(COUNT(G129:M129)>2,9,7)) -> 9 | F129: 1*22 | G129: =AB129/1000 -> 9.95 | H129: =AC129/1000 -> 10.74 | I129: =AD129/1000 -> 3.06 | N129: =SUM(G129:M129) -> 23.75 | O129: =(N129/8.16)^4.5 -> 122.42794 | P129: 8 | Q129: 10 | R129: 9 | S129: 9 | T129: 9 | U129: 9 | V129: 9 | W129: =IF(G129>P129,"Y",IF(H129>Q129,"Y",IF(I129>R129,"Y",IF(J129>S129,"Y",IF(K129>T129,"Y",IF(L129>U129,"Y",IF(M129>V129,"Y","N"))))))) -> Y | X129: =IF(W129="Y",MAX((G129-P129),(H129-Q129),(I129-R129),(J129-S129),(K129-T129),(L129-U129),(M129-V129))/10,0) -> 0.195 | Y129: =IF(X129<5%,"0-4.9%",IF(X129<25%,"5-25%",IF(X129<50%,"25-50%","Over 50%"))) -> 5-25% | Z129: Others | AB129: 9950 | AC129: 10740 | AD129: 3060
A130: 26 | B130: 0.46527778 | C130: UGANDA | D130: =IF(COUNT(G130:M130)>3,10,IF(COUNT(G130:M130)>2,9,7)) -> 9 | F130: 1*22 | G130: =AB130/1000 -> 8.64 | H130: =AC130/1000 -> 14.8 | I130: =AD130/1000 -> 7.4 | N130: =SUM(G130:M130) -> 30.84 | O130: =(N130/8.16)^4.5 -> 396.65136 | P130: 8 | Q130: 10 | R130: 9 | S130: 9 | T130: 9 | U130: 9 | V130: 9 | W130: =IF(G130>P130,"Y",IF(H130>Q130,"Y",IF(I130>R130,"Y",IF(J130>S130,"Y",IF(K130>T130,"Y",IF(L130>U130,"Y",IF(M130>V130,"Y","N"))))))) -> Y | X130: =IF(W130="Y",MAX((G130-P130),(H130-Q130),(I130-R130),(J130-S130),(K130-T130),(L130-U130),(M130-V130))/10,0) -> 0.48 | Y130: =IF(X130<5%,"0-4.9%",IF(X130<25%,"5-25%",IF(X130<50%,"25-50%","Over 50%"))) -> 25-50% | Z130: Household retail products | AB130: 8640 | AC130: 14800 | AD130: 7400
A131: 30 | B131: 0.46805556 | C131: UGANDA | D131: =IF(COUNT(G131:M131)>3,10,IF(COUNT(G131:M131)>2,9,7)) -> 9 | F131: 1*22 | G131: =AB131/1000 -> 7.56 | H131: =AC131/1000 -> 7.08 | I131: =AD131/1000 -> 4.02 | N131: =SUM(G131:M131) -> 18.66 | O131: =(N131/8.16)^4.5 -> 41.352014 | P131: 8 | Q131: 10 | R131: 9 | S131: 9 | T131: 9 | U131: 9 | V131: 9 | W131: =IF(G131>P131,"Y",IF(H131>Q131,"Y",IF(I131>R131,"Y",IF(J131>S131,"Y",IF(K131>T131,"Y",IF(L131>U131,"Y",IF(M131>V131,"Y","N"))))))) -> N | X131: =IF(W131="Y",MAX((G131-P131),(H131-Q131),(I131-R131),(J131-S131),(K131-T131),(L131-U131),(M131-V131))/10,0) -> 0 | Y131: =IF(X131<5%,"0-4.9%",IF(X131<25%,"5-25%",IF(X131<50%,"25-50%","Over 50%"))) -> 0-4.9% | Z131: Others | AB131: 7560 | AC131: 7080 | AD131: 4020
A132: 34 | B132: 0.48402778 | C132: UGANDA | D132: =IF(COUNT(G132:M132)>3,10,IF(COUNT(G132:M132)>2,9,7)) -> 9 | F132: 1*22 | G132: =AB132/1000 -> 3.14 | H132: =AC132/1000 -> 4.9 | I132: =AD132/1000 -> 6.16 | N132: =SUM(G132:M132) -> 14.2 | O132: =(N132/8.16)^4.5 -> 12.097394 | P132: 8 | Q132: 10 | R132: 9 | S132: 9 | T132: 9 | U132: 9 | V132: 9 | W132: =IF(G132>P132,"Y",IF(H132>Q132,"Y",IF(I132>R132,"Y",IF(J132>S132,"Y",IF(K132>T132,"Y",IF(L132>U132,"Y",IF(M132>V132,"Y","N"))))))) -> N | X132: =IF(W132="Y",MAX((G132-P132),(H132-Q132),(I132-R132),(J132-S132),(K132-T132),(L132-U132),(M132-V132))/10,0) -> 0 | Y132: =IF(X132<5%,"0-4.9%",IF(X132<25%,"5-25%",IF(X132<50%,"25-50%","Over 50%"))) -> 0-4.9% | Z132: Empty | AB132: 3140 | AC132: 4900 | AD132: 6160
A133: 46 | B133: 0.52847222 | C133: UGANDA | D133: =IF(COUNT(G133:M133)>3,10,IF(COUNT(G133:M133)>2,9,7)) -> 9 | F133: 1*22 | G133: =AB133/1000 -> 9.96 | H133: =AC133/1000 -> 15.08 | I133: =AD133/1000 -> 6.88 | N133: =SUM(G133:M133) -> 31.92 | O133: =(N133/8.16)^4.5 -> 463.10264 | P133: 8 | Q133: 10 | R133: 9 | S133: 9 | T133: 9 | U133: 9 | V133: 9 | W133: =IF(G133>P133,"Y",IF(H133>Q133,"Y",IF(I133>R133,"Y",IF(J133>S133,"Y",IF(K133>T133,"Y",IF(L133>U133,"Y",IF(M133>V133,"Y","N"))))))) -> Y | X133: =IF(W133="Y",MAX((G133-P133),(H133-Q133),(I133-R133),(J133-S133),(K133-T133),(L133-U133),(M133-V133))/10,0) -> 0.508 | Y133: =IF(X133<5%,"0-4.9%",IF(X133<25%,"5-25%",IF(X133<50%,"25-50%","Over 50%"))) -> Over 50% | Z133: Others | AB133: 9960 | AC133: 15080 | AD133: 6880
...

Sheet Mityana-Kla
A1: Consultancy services for Preparation of Expressway Development Master Plan (EDMP) for Uganda
A2: AXLE LOAD SURVEY FORM
A3: Date: | D3: Station Name: | F3: BUJUUKO
A4: 43704 | H4: KAMPALA-MITYANA
A5: S/No. | B5: Time | C5: Reg. Number | D5: Vehicle Type | E5: Number of Axles | F5: Axle Configuration | G5: Front | H5: KGS | N5: Total (Tonnes) | O5: Total (ESA's) | P5: Load limit (Tonnes) | W5: OVERLOADED? | X5: Overloaded by? | Y5: Overload Bands | Z5: COMMENTS | AB5: Front | AC5: KGS
G6: Axle 1 | H6: Axle 2 | I6: Axle 3 | J6: Axle 4 | K6: Axle 5 | L6: Axle 6 | M6: Axle 7 | P6: Axle 1 | Q6: Axle 2 | R6: Axle 3 | S6: Axle 4 | T6: Axle 5 | U6: Axle 6 | V6: Axle 7 | AB6: Axle 1 | AC6: Axle 2 | AD6: Axle 3 | AE6: Axle 4 | AF6: Axle 5 | AG6: Axle 6 | AH6: Axle 7
A7: 1 | B7: 0.33888889 | C7: UGANDA | D7: =IF(COUNT(G7:M7)>3,10,IF(COUNT(G7:M7)>2,9,7)) -> 7 | F7: 1*2 | G7: =AB7/1000 -> 4.12 | H7: =AC7/1000 -> 10.06 | N7: =SUM(G7:M7) -> 14.18 | O7: =(N7/8.16)^4.5 -> 12.020909 | P7: 8 | Q7: 10 | R7: 9 | S7: 9 | T7: 9 | U7: 9 | V7: 9 | W7: =IF(G7>P7,"Y",IF(H7>Q7,"Y",IF(I7>R7,"Y",IF(J7>S7,"Y",IF(K7>T7,"Y",IF(L7>U7,"Y",IF(M7>V7,"Y","N"))))))) -> Y | X7: =IF(W7="Y",MAX((G7-P7),(H7-Q7),(I7-R7),(J7-S7),(K7-T7),(L7-U7),(M7-V7))/10,0) -> 0.006 | Y7: =IF(X7<5%,"0-4.9%",IF(X7<25%,"5-25%",IF(X7<50%,"25-50%","Over 50%"))) -> 0-4.9% | Z7: Construction Material | AB7: 4120 | AC7: 10060
A8: 3 | B8: 0.40277778 | C8: UGANDA | D8: =IF(COUNT(G8:M8)>3,10,IF(COUNT(G8:M8)>2,9,7)) -> 7 | F8: 1*2 | G8: =AB8/1000 -> 3.68 | H8: =AC8/1000 -> 3.7 | N8: =SUM(G8:M8) -> 7.38 | O8: =(N8/8.16)^4.5 -> 0.63627947 | P8: 8 | Q8: 10 | R8: 9 | S8: 9 | T8: 9 | U8: 9 | V8: 9 | W8: =IF(G8>P8,"Y",IF(H8>Q8,"Y",IF(I8>R8,"Y",IF(J8>S8,"Y",IF(K8>T8,"Y",IF(L8>U8,"Y",IF(M8>V8,"Y","N"))))))) -> N | X8: =IF(W8="Y",MAX((G8-P8),(H8-Q8),(I8-R8),(J8-S8),(K8-T8),(L8-U8),(M8-V8))/10,0) -> 0 | Y8: =IF(X8<5%,"0-4.9%",IF(X8<25%,"5-25%",IF(X8<50%,"25-50%","Over 50%"))) -> 0-4.9% | Z8: Empty | AB8: 3680 | AC8: 3700
A9: 4 | B9: 0.40347222 | C9: UGANDA | D9: =IF(COUNT(G9:M9)>3,10,IF(COUNT(G9:M9)>2,9,7)) -> 7 | F9: 1*2 | G9: =AB9/1000 -> 4.86 | H9: =AC9/1000 -> 10.34 | N9: =SUM(G9:M9) -> 15.2 | O9: =(N9/8.16)^4.5 -> 16.432 | P9: 8 | Q9: 10 | R9: 9 | S9: 9 | T9: 9 | U9: 9 | V9: 9 | W9: =IF(G9>P9,"Y",IF(H9>Q9,"Y",IF(I9>R9,"Y",IF(J9>S9,"Y",IF(K9>T9,"Y",IF(L9>U9,"Y",IF(M9>V9,"Y","N"))))))) -> Y | X9: =IF(W9="Y",MAX((G9-P9),(H9-Q9),(I9-R9),(J9-S9),(K9-T9),(L9-U9),(M9-V9))/10,0) -> 0.034 | Y9: =IF(X9<5%,"0-4.9%",IF(X9<25%,"5-25%",IF(X9<50%,"25-50%","Over 50%"))) -> 0-4.9% | Z9: Construction Material | AB9: 4860 | AC9: 10340
A10: 6 | B10: 0.41319444 | C10: UGANDA | D10: =IF(COUNT(G10:M10)>3,10,IF(COUNT(G10:M10)>2,9,7)) -> 7 | F10: 1*2 | G10: =AB10/1000 -> 4.46 | H10: =AC10/1000 -> 10.98 | N10: =SUM(G10:M10) -> 15.44 | O10: =(N10/8.16)^4.5 -> 17.632225 | P10: 8 | Q10: 10 | R10: 9 | S10: 9 | T10: 9 | U10: 9 | V10: 9 | W10: =IF(G10>P10,"Y",IF(H10>Q10,"Y",IF(I10>R10,"Y",IF(J10>S10,"Y",IF(K10>T10,"Y",IF(L10>U10,"Y",IF(M10>V10,"Y","N"))))))) -> Y | X10: =IF(W10="Y",MAX((G10-P10),(H10-Q10),(I10-R10),(J10-S10),(K10-T10),(L10-U10),(M10-V10))/10,0) -> 0.098 | Y10: =IF(X10<5%,"0-4.9%",IF(X10<25%,"5-25%",IF(X10<50%,"25-50%","Over 50%"))) -> 5-25% | Z10: Construction Material | AB10: 4460 | AC10: 10980
A11: 7 | B11: 0.41666667 | C11: UGANDA | D11: =IF(COUNT(G11:M11)>3,10,IF(COUNT(G11:M11)>2,9,7)) -> 7 | F11: 1*2 | G11: =AB11/1000 -> 3.02 | H11: =AC11/1000 -> 4.48 | N11: =SUM(G11:M11) -> 7.5 | O11: =(N11/8.16)^4.5 -> 0.68417936 | P11: 8 | Q11: 10 | R11: 9 | S11: 9 | T11: 9 | U11: 9 | V11: 9 | W11: =IF(G11>P11,"Y",IF(H11>Q11,"Y",IF(I11>R11,"Y",IF(J11>S11,"Y",IF(K11>T11,"Y",IF(L11>U11,"Y",IF(M11>V11,"Y","N"))))))) -> N | X11: =IF(W11="Y",MAX((G11-P11),(H11-Q11),(I11-R11),(J11-S11),(K11-T11),(L11-U11),(M11-V11))/10,0) -> 0 | Y11: =IF(X11<5%,"0-4.9%",IF(X11<25%,"5-25%",IF(X11<50%,"25-50%","Over 50%"))) -> 0-4.9% | Z11: Others | AB11: 3020 | AC11: 4480
A12: 8 | B12: 0.41736111 | C12: UGANDA | D12: =IF(COUNT(G12:M12)>3,10,IF(COUNT(G12:M12)>2,9,7)) -> 7 | F12: 1*2 | G12: =AB12/1000 -> 4.1 | H12: =AC12/1000 -> 11.66 | N12: =SUM(G12:M12) -> 15.76 | O12: =(N12/8.16)^4.5 -> 19.337363 | P12: 8 | Q12: 10 | R12: 9 | S12: 9 | T12: 9 | U12: 9 | V12: 9 | W12: =IF(G12>P12,"Y",IF(H12>Q12,"Y",IF(I12>R12,"Y",IF(J12>S12,"Y",IF(K12>T12,"Y",IF(L12>U12,"Y",IF(M12>V12,"Y","N"))))))) -> Y | X12: =IF(W12="Y",MAX((G12-P12),(H12-Q12),(I12-R12),(J12-S12),(K12-T12),(L12-U12),(M12-V12))/10,0) -> 0.166 | Y12: =IF(X12<5%,"0-4.9%",IF(X12<25%,"5-25%",IF(X12<50%,"25-50%","Over 50%"))) -> 5-25% | Z12: Construction Material | AB12: 4100 | AC12: 11660
A13: 9 | B13: 0.41944444 | C13: UGANDA | D13: =IF(COUNT(G13:M13)>3,10,IF(COUNT(G13:M13)>2,9,7)) -> 7 | F13: 1*2 | G13: =AB13/1000 -> 8.44 | H13: =AC13/1000 -> 19.88 | N13: =SUM(G13:M13) -> 28.32 | O13: =(N13/8.16)^4.5 -> 270.28 | P13: 8 | Q13: 10 | R13: 9 | S13: 9 | T13: 9 | U13: 9 | V13: 9 | W13: =IF(G13>P13,"Y",IF(H13>Q13,"Y",IF(I13>R13,"Y",IF(J13>S13,"Y",IF(K13>T13,"Y",IF(L13>U13,"Y",IF(M13>V13,"Y","N"))))))) -> Y | X13: =IF(W13="Y",MAX((G13-P13),(H13-Q13),(I13-R13),(J13-S13),(K13-T13),(L13-U13),(M13-V13))/10,0) -> 0.988 | Y13: =IF(X13<5%,"0-4.9%",IF(X13<25%,"5-25%",IF(X13<50%,"25-50%","Over 50%"))) -> Over 50% | Z13: Construction Material | AB13: 8440 | AC13: 19880
A14: 10 | B14: 0.42152778 | C14: UGANDA | D14: =IF(COUNT(G14:M14)>3,10,IF(COUNT(G14:M14)>2,9,7)) -> 7 | F14: 1*2 | G14: =AB14/1000 -> 3.4 | H14: =AC14/1000 -> 4.64 | N14: =SUM(G14:M14) -> 8.04 | O14: =(N14/8.16)^4.5 -> 0.93550584 | P14: 8 | Q14: 10 | R14: 9 | S14: 9 | T14: 9 | U14: 9 | V14: 9 | W14: =IF(G14>P14,"Y",IF(H14>Q14,"Y",IF(I14>R14,"Y",IF(J14>S14,"Y",IF(K14>T14,"Y",IF(L14>U14,"Y",IF(M14>V14,"Y","N"))))))) -> N | X14: =IF(W14="Y",MAX((G14-P14),(H14-Q14),(I14-R14),(J14-S14),(K14-T14),(L14-U14),(M14-V14))/10,0) -> 0 | Y14: =IF(X14<5%,"0-4.9%",IF(X14<25%,"5-25%",IF(X14<50%,"25-50%","Over 50%"))) -> 0-4.9% | Z14: Household retail products | AB14: 3400 | AC14: 4640
A15: 11 | B15: 0.42222222 | C15: UGANDA | D15: =IF(COUNT(G15:M15)>3,10,IF(COUNT(G15:M15)>2,9,7)) -> 7 | F15: 1*2 | G15: =AB15/1000 -> 3.6 | H15: =AC15/1000 -> 4.86 | N15: =SUM(G15:M15) -> 8.46 | O15: =(N15/8.16)^4.5 -> 1.176416 | P15: 8 | Q15: 10 | R15: 9 | S15: 9 | T15: 9 | U15: 9 | V15: 9 | W15: =IF(G15>P15,"Y",IF(H15>Q15,"Y",IF(I15>R15,"Y",IF(J15>S15,"Y",IF(K15>T15,"Y",IF(L15>U15,"Y",IF(M15>V15,"Y","N"))))))) -> N | X15: =IF(W15="Y",MAX((G15-P15),(H15-Q15),(I15-R15),(J15-S15),(K15-T15),(L15-U15),(M15-V15))/10,0) -> 0 | Y15: =IF(X15<5%,"0-4.9%",IF(X15<25%,"5-25%",IF(X15<50%,"25-50%","Over 50%"))) -> 0-4.9% | Z15: Empty | AB15: 3600 | AC15: 4860
A16: 12 | B16: 0.425 | C16: UGANDA | D16: =IF(COUNT(G16:M16)>3,10,IF(COUNT(G16:M16)>2,9,7)) -> 7 | F16: 1*2 | G16: =AB16/1000 -> 5.68 | H16: =AC16/1000 -> 16.02 | N16: =SUM(G16:M16) -> 21.7 | O16: =(N16/8.16)^4.5 -> 81.557347 | P16: 8 | Q16: 10 | R16: 9 | S16: 9 | T16: 9 | U16: 9 | V16: 9 | W16: =IF(G16>P16,"Y",IF(H16>Q16,"Y",IF(I16>R16,"Y",IF(J16>S16,"Y",IF(K16>T16,"Y",IF(L16>U16,"Y",IF(M16>V16,"Y","N"))))))) -> Y | X16: =IF(W16="Y",MAX((G16-P16),(H16-Q16),(I16-R16),(J16-S16),(K16-T16),(L16-U16),(M16-V16))/10,0) -> 0.602 | Y16: =IF(X16<5%,"0-4.9%",IF(X16<25%,"5-25%",IF(X16<50%,"25-50%","Over 50%"))) -> Over 50% | Z16: Construction Material | AB16: 5680 | AC16: 16020
A17: 13 | B17: 0.42638889 | C17: UGANDA | D17: =IF(COUNT(G17:M17)>3,10,IF(COUNT(G17:M17)>2,9,7)) -> 7 | F17: 1*2 | G17: =AB17/1000 -> 4.36 | H17: =AC17/1000 -> 5.14 | N17: =SUM(G17:M17) -> 9.5 | O17: =(N17/8.16)^4.5 -> 1.9822139 | P17: 8 | Q17: 10 | R17: 9 | S17: 9 | T17: 9 | U17: 9 | V17: 9 | W17: =IF(G17>P17,"Y",IF(H17>Q17,"Y",IF(I17>R17,"Y",IF(J17>S17,"Y",IF(K17>T17,"Y",IF(L17>U17,"Y",IF(M17>V17,"Y","N"))))))) -> N | X17: =IF(W17="Y",MAX((G17-P17),(H17-Q17),(I17-R17),(J17-S17),(K17-T17),(L17-U17),(M17-V17))/10,0) -> 0 | Y17: =IF(X17<5%,"0-4.9%",IF(X17<25%,"5-25%",IF(X17<50%,"25-50%","Over 50%"))) -> 0-4.9% | Z17: Empty | AB17: 4360 | AC17: 5140
A18: 14 | B18: 0.42638889 | C18: UGANDA | D18: =IF(COUNT(G18:M18)>3,10,IF(COUNT(G18:M18)>2,9,7)) -> 7 | F18: 1*2 | G18: =AB18/1000 -> 10.72 | H18: =AC18/1000 -> 14.66 | N18: =SUM(G18:M18) -> 25.38 | O18: =(N18/8.16)^4.5 -> 165.04659 | P18: 8 | Q18: 10 | R18: 9 | S18: 9 | T18: 9 | U18: 9 | V18: 9 | W18: =IF(G18>P18,"Y",IF(H18>Q18,"Y",IF(I18>R18,"Y",IF(J18>S18,"Y",IF(K18>T18,"Y",IF(L18>U18,"Y",IF(M18>V18,"Y","N"))))))) -> Y | X18: =IF(W18="Y",MAX((G18-P18),(H18-Q18),(I18-R18),(J18-S18),(K18-T18),(L18-U18),(M18-V18))/10,0) -> 0.466 | Y18: =IF(X18<5%,"0-4.9%",IF(X18<25%,"5-25%",IF(X18<50%,"25-50%","Over 50%"))) -> 25-50% | Z18: Agricultural produce | AB18: 10720 | AC18: 14660
... A115: 61 | B115: 0.094444444 | C115: UGANDA | D115: =IF(COUNT(G115:M115)>3,10,IF(COUNT(G115:M115)>2,9,7)) -> 7 | F115: 1*2 | G115: =AB115/1000 -> 4 | H115: =AC115/1000 -> 4.8 | N115: =SUM(G115:M115) -> 8.8 | O115: =(N115/8.16)^4.5 -> 1.4046441 | P115: 8 | Q115: 10 | R115: 9 | S115: 9 | T115: 9 | U115: 9 | V115: 9 | W115: =IF(G115>P115,"Y",IF(H115>Q115,"Y",IF(I115>R115,"Y",IF(J115>S115,"Y",IF(K115>T115,"Y",IF(L115>U115,"Y",IF(M115>V115,"Y","N"))))))) -> N | X115: =IF(W115="Y",MAX((G115-P115),(H115-Q115),(I115-R115),(J115-S115),(K115-T115),(L115-U115),(M115-V115))/10,0) -> 0 | Y115: =IF(X115<5%,"0-4.9%",IF(X115<25%,"5-25%",IF(X115<50%,"25-50%","Over 50%"))) -> 0-4.9% | Z115: Household retail products | AB115: 4000 | AC115: 4800
A116: 2 | B116: 0.33958333 | C116: UGANDA | D116: =IF(COUNT(G116:M116)>3,10,IF(COUNT(G116:M116)>2,9,7)) -> 9 | F116: 1*22 | G116: =AB116/1000 -> 7.76 | H116: =AC116/1000 -> 1.184 | I116: =AD116/1000 -> 11.82 | N116: =SUM(G116:M116) -> 20.764 | O116: =(N116/8.16)^4.5 -> 66.879632 | P116: 8 | Q116: 10 | R116: 9 | S116: 9 | T116: 9 | U116: 9 | V116: 9 | W116: =IF(G116>P116,"Y",IF(H116>Q116,"Y",IF(I116>R116,"Y",IF(J116>S116,"Y",IF(K116>T116,"Y",IF(L116>U116,"Y",IF(M116>V116,"Y","N"))))))) -> Y | X116: =IF(W116="Y",MAX((G116-P116),(H116-Q116),(I116-R116),(J116-S116),(K116-T116),(L116-U116),(M116-V116))/10,0) -> 0.282 | Y116: =IF(X116<5%,"0-4.9%",IF(X116<25%,"5-25%",IF(X116<50%,"25-50%","Over 50%"))) -> 25-50% | Z116: Agricultural produce | AB116: 7760 | AC116: 1184 | AD116: 11820
A117: 17 | B117: 0.42847222 | C117: UGANDA | D117: =IF(COUNT(G117:M117)>3,10,IF(COUNT(G117:M117)>2,9,7)) -> 9 | F117: 11*2 | G117: =AB117/1000 -> 4.88 | H117: =AC117/1000 -> 4.78 | I117: =AD117/1000 -> 3.04 | N117: =SUM(G117:M117) -> 12.7 | O117: =(N117/8.16)^4.5 -> 7.3199991 | P117: 8 | Q117: 10 | R117: 9 | S117: 9 | T117: 9 | U117: 9 | V117: 9 | W117: =IF(G117>P117,"Y",IF(H117>Q117,"Y",IF(I117>R117,"Y",IF(J117>S117,"Y",IF(K117>T117,"Y",IF(L117>U117,"Y",IF(M117>V117,"Y","N"))))))) -> N | X117: =IF(W117="Y",MAX((G117-P117),(H117-Q117),(I117-R117),(J117-S117),(K117-T117),(L117-U117),(M117-V117))/10,0) -> 0 | Y117: =IF(X117<5%,"0-4.9%",IF(X117<25%,"5-25%",IF(X117<50%,"25-50%","Over 50%"))) -> 0-4.9% | Z117: Empty | AB117: 4880 | AC117: 4780 | AD117: 3040
A118: 37 | B118: 0.50069444 | C118: UGANDA | D118: =IF(COUNT(G118:M118)>3,10,IF(COUNT(G118:M118)>2,9,7)) -> 9 | F118: 1*22 | G118: =AB118/1000 -> 4.4 | H118: =AC118/1000 -> 5.6 | I118: =AD118/1000 -> 5.36 | N118: =SUM(G118:M118) -> 15.36 | O118: =(N118/8.16)^4.5 -> 17.224823 | P118: 8 | Q118: 10 | R118: 9 | S118: 9 | T118: 9 | U118: 9 | V118: 9 | W118: =IF(G118>P118,"Y",IF(H118>Q118,"Y",IF(I118>R118,"Y",IF(J118>S118,"Y",IF(K118>T118,"Y",IF(L118>U118,"Y",IF(M118>V118,"Y","N"))))))) -> N | X118: =IF(W118="Y",MAX((G118-P118),(H118-Q118),(I118-R118),(J118-S118),(K118-T118),(L118-U118),(M118-V118))/10,0) -> 0 | Y118: =IF(X118<5%,"0-4.9%",IF(X118<25%,"5-25%",IF(X118<50%,"25-50%","Over 50%"))) -> 0-4.9% | Z118: Empty | AB118: 4400 | AC118: 5600 | AD118: 5360
A119: 48 | B119: 0.11388889 | C119: UGANDA | D119: =IF(COUNT(G119:M119)>3,10,IF(COUNT(G119:M119)>2,9,7)) -> 9 | F119: 1*22 | G119: =AB119/1000 -> 6.64 | H119: =AC119/1000 -> 10.74 | I119: =AD119/1000 -> 10.28 | N119: =SUM(G119:M119) -> 27.66 | O119: =(N119/8.16)^4.5 -> 243.06872 | P119: 8 | Q119: 10 | R119: 9 | S119: 9 | T119: 9 | U119: 9 | V119: 9 | W119: =IF(G119>P119,"Y",IF(H119>Q119,"Y",IF(I119>R119,"Y",IF(J119>S119,"Y",IF(K119>T119,"Y",IF(L119>U119,"Y",IF(M119>V119,"Y","N"))))))) -> Y | X119: =IF(W119="Y",MAX((G119-P119),(H119-Q119),(I119-R119),(J119-S119),(K119-T119),(L119-U119),(M119-V119))/10,0) -> 0.128 | Y119: =IF(X119<5%,"0-4.9%",IF(X119<25%,"5-25%",IF(X119<50%,"25-50%","Over 50%"))) -> 5-25% | Z119: Construction Material | AB119: 6640 | AC119: 10740 | AD119: 10280
A120: 49 | B120: 0.11805556 | C120: UGANDA | D120: =IF(COUNT(G120:M120)>3,10,IF(COUNT(G120:M120)>2,9,7)) -> 9 | F120: 1*22 | G120: =AB120/1000 -> 6.04 | H120: =AC120/1000 -> 10.28 | I120: =AD120/1000 -> 10.24 | N120: =SUM(G120:M120) -> 26.56 | O120: =(N120/8.16)^4.5 -> 202.49794 | P120: 8 | Q120: 10 | R120: 9 | S120: 9 | T120: 9 | U120: 9 | V120: 9 | W120: =IF(G120>P120,"Y",IF(H120>Q120,"Y",IF(I120>R120,"Y",IF(J120>S120,"Y",IF(K120>T120,"Y",IF(L120>U120,"Y",IF(M120>V120,"Y","N"))))))) -> Y | X120: =IF(W120="Y",MAX((G120-P120),(H120-Q120),(I120-R120),(J120-S120),(K120-T120),(L120-U120),(M120-V120))/10,0) -> 0.124 | Y120: =IF(X120<5%,"0-4.9%",IF(X120<25%,"5-25%",IF(X120<50%,"25-50%","Over 50%"))) -> 5-25% | Z120: Construction Material | AB120: 6040 | AC120: 10280 | AD120: 10240
A121: 55 | B121: 0.14583333 | C121: UGANDA | D121: =IF(COUNT(G121:M121)>3,10,IF(COUNT(G121:M121)>2,9,7)) -> 9 | F121: 1*22 | G121: =AB121/1000 -> 5.36 | H121: =AC121/1000 -> 10.1 | I121: =AD121/1000 -> 4.26 | N121: =SUM(G121:M121) -> 19.72 | O121: =(N121/8.16)^4.5 -> 53.024354 | P121: 8 | Q121: 10 | R121: 9 | S121: 9 | T121: 9 | U121: 9 | V121: 9 | W121: =IF(G121>P121,"Y",IF(H121>Q121,"Y",IF(I121>R121,"Y",IF(J121>S121,"Y",IF(K121>T121,"Y",IF(L121>U121,"Y",IF(M121>V121,"Y","N"))))))) -> Y | X121: =IF(W121="Y",MAX((G121-P121),(H121-Q121),(I121-R121),(J121-S121),(K121-T121),(L121-U121),(M121-V121))/10,0) -> 0.01 | Y121: =IF(X121<5%,"0-4.9%",IF(X121<25%,"5-25%",IF(X121<50%,"25-50%","Over 50%"))) -> 0-4.9% | Z121: Agricultural produce | AB121: 5360 | AC121: 10100 | AD121: 4260
A122: 19 | B122: 0.37430556 | C122: UGANDA | D122: =IF(COUNT(G122:M122)>3,10,IF(COUNT(G122:M122)>2,9,7)) -> 9 | F122: 1*22 | G122: =AB122/1000 -> 8.82 | H122: =AC122/1000 -> 12.36 | I122: =AD122/1000 -> 10.82 | N122: =SUM(G122:M122) -> 32 | O122: =(N122/8.16)^4.5 -> 468.34856 | P122: 8 | Q122: 10 | R122: 9 | S122: 9 | T122: 9 | U122: 9 | V122: 9 | W122: =IF(G122>P122,"Y",IF(H122>Q122,"Y",IF(I122>R122,"Y",IF(J122>S122,"Y",IF(K122>T122,"Y",IF(L122>U122,"Y",IF(M122>V122,"Y","N"))))))) -> Y | X122: =IF(W122="Y",MAX((G122-P122),(H122-Q122),(I122-R122),(J122-S122),(K122-T122),(L122-U122),(M122-V122))/10,0) -> 0.236 | Y122: =IF(X122<5%,"0-4.9%",IF(X122<25%,"5-25%",IF(X122<50%,"25-50%","Over 50%"))) -> 5-25% | Z122: Metal/machinery | AB122: 8820 | AC122: 12360 | AD122: 10820
A123: 32 | B123: 0.44652778 | C123: UGANDA | D123: =IF(COUNT(G123:M123)>3,10,IF(COUNT(G123:M123)>2,9,7)) -> 9 | F123: 1*22 | G123: =AB123/1000 -> 10.1 | H123: =AC123/1000 -> 14.24 | I123: =AD123/1000 -> 13.64 | N123: =SUM(G123:M123) -> 37.98 | O123: =(N123/8.16)^4.5 -> 1012.492 | P123: 8 | Q123: 10 | R123: 9 | S123: 9 | T123: 9 | U123: 9 | V123: 9 | W123: =IF(G123>P123,"Y",IF(H123>Q123,"Y",IF(I123>R123,"Y",IF(J123>S123,"Y",IF(K123>T123,"Y",IF(L123>U123,"Y",IF(M123>V123,"Y","N"))))))) -> Y | X123: =IF(W123="Y",MAX((G123-P123),(H123-Q123),(I123-R123),(J123-S123),(K123-T123),(L123-U123),(M123-V123))/10,0) -> 0.464 | Y123: =IF(X123<5%,"0-4.9%",IF(X123<25%,"5-25%",IF(X123<50%,"25-50%","Over 50%"))) -> 25-50% | Z123: Construction Material | AB123: 10100 | AC123: 14240 | AD123: 13640
A124: 54 | B124: 0.48472222 | C124: UGANDA | D124: =IF(COUNT(G124:M124)>3,10,IF(COUNT(G124:M124)>2,9,7)) -> 9 | F124: 1*21 | G124: =AB124/1000 -> 10.34 | H124: =AC124/1000 -> 13.04 | I124: =AD124/1000 -> 6.06 | N124: =SUM(G124:M124) -> 29.44 | O124: =(N124/8.16)^4.5 -> 321.82102 | P124: 8 | Q124: 10 | R124: 9 | S124: 9 | T124: 9 | U124: 9 | V124: 9 | W124: =IF(G124>P124,"Y",IF(H124>Q124,"Y",IF(I124>R124,"Y",IF(J124>S124,"Y",IF(K124>T124,"Y",IF(L124>U124,"Y",IF(M124>V124,"Y","N"))))))) -> Y | X124: =IF(W124="Y",MAX((G124-P124),(H124-Q124),(I124-R124),(J124-S124),(K124-T124),(L124-U124),(M124-V124))/10,0) -> 0.304 | Y124: =IF(X124<5%,"0-4.9%",IF(X124<25%,"5-25%",IF(X124<50%,"25-50%","Over 50%"))) -> 25-50% | Z124: Others | AB124: 10340 | AC124: 13040 | AD124: 6060
A125: 10 | B125: 0.51041667 | C125: UGANDA | D125: =IF(COUNT(G125:M125)>3,10,IF(COUNT(G125:M125)>2,9,7)) -> 9 | F125: 1*22 | G125: =AB125/1000 -> 7.1 | H125: =AC125/1000 -> 7.49 | I125: =AD125/1000 -> 4.29 | N125: =SUM(G125:M125) -> 18.88 | O125: =(N125/8.16)^4.5 -> 43.591643 | P125: 8 | Q125: 10 | R125: 9 | S125: 9 | T125: 9 | U125: 9 | V125: 9 | W125: =IF(G125>P125,"Y",IF(H125>Q125,"Y",IF(I125>R125,"Y",IF(J125>S125,"Y",IF(K125>T125,"Y",IF(L125>U125,"Y",IF(M125>V125,"Y","N"))))))) -> N | X125: =IF(W125="Y",MAX((G125-P125),(H125-Q125),(I125-R125),(J125-S125),(K125-T125),(L125-U125),(M125-V125))/10,0) -> 0 | Y125: =IF(X125<5%,"0-4.9%",IF(X125<25%,"5-25%",IF(X125<50%,"25-50%","Over 50%"))) -> 0-4.9% | Z125: Agricultural produce | AB125: 7100 | AC125: 7490 | AD125: 4290
A126: 11 | B126: 0.5125 | C126: UGANDA | D126: =IF(COUNT(G126:M126)>3,10,IF(COUNT(G126:M126)>2,9,7)) -> 9 | F126: 1*22 | G126: =AB126/1000 -> 0.78 | H126: =AC126/1000 -> 9.84 | I126: =AD126/1000 -> 4.74 | N126: =SUM(G126:M126) -> 15.36 | O126: =(N126/8.16)^4.5 -> 17.224823 | P126: 8 | Q126: 10 | R126: 9 | S126: 9 | T126: 9 | U126: 9 | V126: 9 | W126: =IF(G126>P126,"Y",IF(H126>Q126,"Y",IF(I126>R126,"Y",IF(J126>S126,"Y",IF(K126>T126,"Y",IF(L126>U126,"Y",IF(M126>V126,"Y","N"))))))) -> N | X126: =IF(W126="Y",MAX((G126-P126),(H126-Q126),(I126-R126),(J126-S126),(K126-T126),(L126-U126),(M126-V126))/10,0) -> 0 | Y126: =IF(X126<5%,"0-4.9%",IF(X126<25%,"5-25%",IF(X126<50%,"25-50%","Over 50%"))) -> 0-4.9% | Z126: Empty | AB126: 780 | AC126: 9840 | AD126: 4740
A127: 12 | B127: 0.51319444 | C127: UGANDA | D127: =IF(COUNT(G127:M127)>3,10,IF(COUNT(G127:M127)>2,9,7)) -> 9 | F127: 1*22 | G127: =AB127/1000 -> 9.4 | H127: =AC127/1000 -> 14.9 | I127: =AD127/1000 -> 16.3 | N127: =SUM(G127:M127) -> 40.6 | O127: =(N127/8.16)^4.5 -> 1366.9777 | P127: 8 | Q127: 10 | R127: 9 | S127: 9 | T127: 9 | U127: 9 | V127: 9 | W127: =IF(G127>P127,"Y",IF(H127>Q127,"Y",IF(I127>R127,"Y",IF(J127>S127,"Y",IF(K127>T127,"Y",IF(L127>U127,"Y",IF(M127>V127,"Y","N"))))))) -> Y | X127: =IF(W127="Y",MAX((G127-P127),(H127-Q127),(I127-R127),(J127-S127),(K127-T127),(L127-U127),(M127-V127))/10,0) -> 0.73 | Y127: =IF(X127<5%,"0-4.9%",IF(X127<25%,"5-25%",IF(X127<50%,"25-50%","Over 50%"))) -> Over 50% | Z127: Construction Material | AB127: 9400 | AC127: 14900 | AD127: 16300
... A131: 54 | B131: 0.085416667 | C131: UGANDA | D131: =IF(COUNT(G131:M131)>3,10,IF(COUNT(G131:M131)>2,9,7)) -> 9 | F131: 1*22 | G131: =AB131/1000 -> 8.16 | H131: =AC131/1000 -> 8.04 | I131: =AD131/1000 -> 10.72 | N131: =SUM(G131:M131) -> 26.92 | O131: =(N131/8.16)^4.5 -> 215.14539 | P131: 8 | Q131: 10 | R131: 9 | S131: 9 | T131: 9 | U131: 9 | V131: 9 | W131: =IF(G131>P131,"Y",IF(H131>Q131,"Y",IF(I131>R131,"Y",IF(J131>S131,"Y",IF(K131>T131,"Y",IF(L131>U131,"Y",IF(M131>V131,"Y","N"))))))) -> Y | X131: =IF(W131="Y",MAX((G131-P131),(H131-Q131),(I131-R131),(J131-S131),(K131-T131),(L131-U131),(M131-V131))/10,0) -> 0.172 | Y131: =IF(X131<5%,"0-4.9%",IF(X131<25%,"5-25%",IF(X131<50%,"25-50%","Over 50%"))) -> 5-25% | Z131: Construction Material | AB131: 8160 | AC131: 8040 | AD131: 10720
A132: 5 | B132: 0.40902778 | C132: UGANDA | D132: =IF(COUNT(G132:M132)>3,10,IF(COUNT(G132:M132)>2,9,7)) -> 10 | F132: 11*222 | G132: =AB132/1000 -> 11.84 | H132: =AC132/1000 -> 12.72 | I132: =AD132/1000 -> 21.64 | J132: =AE132/1000 -> 14.14 | K132: =AF132/1000 -> 1.44 | L132: =AG132/1000 -> 0 | M132: =AH132/1000 -> 0 | N132: =SUM(G132:M132) -> 61.78 | O132: =(N132/8.16)^4.5 -> 9040.8623 | P132: 8 | Q132: 10 | R132: 9 | S132: 9 | T132: 9 | U132: 9 | V132: 9 | W132: =IF(G132>P132,"Y",IF(H132>Q132,"Y",IF(I132>R132,"Y",IF(J132>S132,"Y",IF(K132>T132,"Y",IF(L132>U132,"Y",IF(M132>V132,"Y","N"))))))) -> Y | X132: =IF(W132="Y",MAX((G132-P132),(H132-Q132),(I132-R132),(J132-S132),(K132-T132),(L132-U132),(M132-V132))/10,0) -> 1.264 | Y132: =IF(X132<5%,"0-4.9%",IF(X132<25%,"5-25%",IF(X132<50%,"25-50%","Over 50%"))) -> Over 50% | Z132: Agricultural produce | AB132: 11840 | AC132: 12720 | AD132: 21640 | AE132: 14140 | AF132: 1440
