Workbook

Sheet DAY1
A1: Consultancy services for Preparation of Expressway Development Master Plan (EDMP) for Uganda
A2: AXLE LOAD SURVEY FORM
A3: Date: | D3: Station Name: | E3: KAKIRI
A4: 43691 | H4: HOIMA-KAMPALA
A5: S/No. | B5: Time | C5: Reg. Number | D5: Vehicle Type | E5: Number of Axles | F5: Axle Configuration | G5: Front | H5: TONNES | N5: Total (Tonnes) | O5: Total (ESA's) | P5: COMMENTS
G6: Axle 1 | H6: Axle 2 | I6: Axle 3 | J6: Axle 4 | K6: Axle 5 | L6: Axle 6 | M6: Axle 7
A7: 1 | B7: 0.29861111 | C7: UAY048K | D7: 8 | F7: 1*2 | G7: 2.6 | H7: 4 | P7: Agric Produce
A8: 2 | B8: 0.30555556 | C8: UBD203G | D8: 8 | F8: 1*2 | G8: 3.9 | H8: 5.9 | P8: Equipment
A9: 3 | B9: 0.31736111 | C9: UAU133B | D9: 8 | F9: 1*2 | G9: 2.34 | H9: 5 | P9: Agric Produce
A10: 4 | B10: 0.325 | C10: KBT049Z | D10: 10 | F10: 1*22*22 | G10: 4.7 | H10: 8 | I10: 4 | J10: 10.12 | K10: 10.1 | P10: Agric Produce
A11: 5 | B11: 0.32986111 | C11: UBF793B | D11: 8 | F11: 1*2 | G11: 1.74 | H11: 2.024
A12: 6 | B12: 0.33958333 | C12: UBE033R | D12: 8 | F12: 1*2 | G12: 8 | H12: 16 | P12: Agric Produce
A13: 7 | B13: 0.34722222 | C13: UAT260A | D13: 8 | F13: 1*2 | G13: 2.24 | H13: 1.44
A14: 8 | B14: 0.35555556 | C14: UAU932V | D14: 8 | F14: 1*2 | G14: 2.8 | H14: 1.4
A15: 9 | B15: 0.36458333 | C15: UBD295U | D15: 10 | F15: 1*22*222 | G15: 5.74 | H15: 9.52 | I15: 8.28 | J15: 6.04 | K15: 7.4 | L15: 6.98 | P15: Equipment
A16: 10 | B16: 0.36666667 | C16: UBB789J | D16: 8 | F16: 1*2 | G16: 3.04 | H16: 6.98 | P16: Building Mat./Hardware
A17: 11 | B17: 0.36805556 | C17: UBA226K | D17: 8 | F17: 1*2 | G17: 1.6 | H17: 1.98
A18: 12 | B18: 0.37430556 | C18: UBE435L | D18: 8 | F18: 1*2 | G18: 1.4 | H18: 2.16 | P18: Agric Produce
A19: 13 | B19: 0.37708333 | C19: UAU334H | D19: 8 | F19: 1*2 | G19: 3.48 | H19: 12.048 | P19: Agric Produce
A20: 14 | B20: 0.38402778 | C20: KBP786U | D20: 12 | F20: 1*22*222 | G20: 5.8 | H20: 6 | I20: 9.8 | J20: 10 | K20: 11 | L20: 7 | P20: Agric Produce
A21: 15 | B21: 0.41388889 | C21: KBW043H | D21: 12 | F21: 1*22*222 | G21: 5.56 | H21: 12.96 | I21: 13.2 | J21: 8.2 | K21: 4.6 | L21: 4.4 | P21: Agric Produce
A22: 16 | B22: 0.44166667 | C22: UBD487T | D22: 8 | F22: 1*2 | G22: 2.506 | H22: 2.48
A23: 17 | B23: 0.45416667 | D23: 8 | F23: 1*2 | G23: 1.12 | H23: 2.4
A24: 18 | B24: 0.45833333 | C24: UBB073U | D24: 10 | F24: 1*22*222 | G24: 3.82 | H24: 4 | I24: 5.36 | J24: 6 | K24: 5.4 | L24: 5.57 | P24: Agric Produce
A25: 19 | B25: 0.46180556 | C25: UBA059Q | D25: 10 | F25: 1*22*222 | G25: 3.79 | H25: 3.01 | I25: 5.6 | J25: 5.36 | K25: 4.22 | L25: 5.06 | P25: Agric Produce
A26: 20 | B26: 0.46527778 | C26: UAZ199F | D26: 8 | F26: 1*2 | G26: 2.7 | H26: 7.32 | P26: Building Mat./Hardware
A27: 21 | B27: 0.47152778 | C27: UBB688U | D27: 8 | F27: 1*2 | G27: 2.04 | H27: 2.46
A28: 22 | B28: 0.49027778 | C28: UAW552K | D28: 8 | F28: 1*2 | G28: 8.42 | H28: 11.3 | P28: Agric Produce
A29: 23 | B29: 0.5 | C29: UAX247U | D29: 8 | F29: 1*2 | G29: 1.45 | H29: 1.52
A30: 24 | B30: 0.52083333 | C30: UBB472P | D30: 8 | F30: 1*2 | G30: 2.206 | H30: 4.512 | P30: Agric Produce
A31: 25 | B31: 0.047916667 | C31: UAM547L | D31: 8 | F31: 1*2 | G31: 7.56 | H31: 9 | P31: Agric Produce
A32: 26 | B32: 0.053472222 | C32: UAX172J | D32: 10 | F32: 1*22*22 | G32: 5.14 | H32: 3.7 | I32: 7.7 | J32: 8.9 | K32: 9.9 | P32: Agric Produce
A33: 27 | B33: 0.125 | C33: UAN961D | D33: 8 | F33: 1*2 | G33: 1.4 | H33: 2.3
A34: 28 | B34: 0.13888889 | C34: UBF285J | D34: 8 | F34: 1*2 | G34: 2.22 | H34: 1.5
A35: 29 | B35: 0.14722222 | C35: UAP216H | D35: 8 | F35: 1*2 | G35: 6 | H35: 12.8 | P35: Agric Produce
H36: KAMPALA - HOIMA
A37: 1 | B37: 0.30208333 | C37: UAT292G | D37: 8 | F37: 1*2 | G37: 1.64 | H37: 1.05
A38: 2 | B38: 0.33958333 | C38: UAY410B | D38: 10 | F38: 1*22*22 | G38: 7.52 | H38: 9.86 | I38: 2.05 | J38: 11.32 | K38: 5.41 | P38: Agric Produce
A39: 3 | B39: 0.34166667 | C39: UAN393Z | D39: 8 | F39: 1*2* | G39: 5.41 | H39: 13 | P39: Others
A40: 4 | B40: 0.34861111 | C40: UBE378N | D40: 8 | F40: 1*2 | G40: 4.68 | H40: 8.38 | P40: Building Mat./Hardware
...

Sheet DAY2
A1: Consultancy services for Preparation of Expressway Development Master Plan (EDMP) for Uganda
A2: AXLE LOAD SURVEY FORM
A3: Date: | D3: Station Name:
A4: 43692 | H4: HOIMA-KAMPALA
A5: S/No. | B5: Time | C5: Reg. Number | D5: Vehicle Type | E5: Number of Axles | F5: Axle Configuration | G5: Front | H5: TONNES | N5: Total (Tonnes) | O5: Total (ESA's) | P5: COMMENTS
G6: Axle 1 | H6: Axle 2 | I6: Axle 3 | J6: Axle 4 | K6: Axle 5 | L6: Axle 6 | M6: Axle 7
A7: 1 | B7: 0.30833333 | C7: UAZ665H | D7: 8 | F7: 1*2 | G7: 3.4 | H7: 4.9 | P7: Agric Produce
A8: 2 | B8: 0.31180556 | C8: UAB132X | D8: 8 | F8: 1*2 | G8: 2.51 | H8: 4.95 | P8: Processed Foods & Beverages
A9: 3 | B9: 0.3125 | C9: UAZ733Y | D9: 8 | F9: 1*2 | G9: 3.37 | H9: 5.71
A10: 4 | B10: 0.32777778 | C10: UBE722H | D10: 8 | F10: 1*2 | G10: 2.83 | H10: 5.17 | P10: Shop items
A11: 5 | B11: 0.34791667 | C11: UAM939H | D11: 8 | F11: 1*2 | G11: 2.25 | H11: 5.94 | P11: Building Mat./Hardware
A12: 6 | B12: 0.34930556 | C12: UAY622X | D12: 8 | F12: 1*2 | G12: 1 | H12: 1.19
A13: 7 | B13: 0.36875 | C13: UAZ896U | D13: 9 | F13: 1*2*2 | G13: 7.36 | H13: 12.96 | I13: 11.12 | P13: Processed Foods & Beverages
A14: 8 | B14: 0.37847222 | C14: UBE428C | D14: 8 | F14: 1*2 | G14: 3 | H14: 7.4 | P14: Processed Foods & Beverages
A15: 9 | B15: 0.38125 | C15: UBD584Y | D15: 8 | F15: 1*2 | G15: 1.14 | H15: 1.75
A16: 10 | B16: 0.38194444 | C16: UAL518B | D16: 8 | F16: 1*2 | G16: 2.98 | H16: 2
A17: 11 | B17: 0.41666667 | C17: UBD575B | D17: 8 | F17: 1*2 | G17: 2.94 | H17: 1.76
A18: 12 | B18: 0.43402778 | C18: UBD478T | D18: 8 | F18: 1*2 | G18: 4.3 | H18: 9 | P18: Building Mat./Hardware
A19: 13 | B19: 0.46180556 | C19: UBF570D | D19: 8 | F19: 1*2 | G19: 3.2 | H19: 7.9 | P19: Agric Produce
A20: 14 | B20: 0.46527778 | C20: UAA122Y | D20: 8 | F20: 1*2 | G20: 1.96 | H20: 3.1 | P20: Shop items
A21: 15 | B21: 0.46736111 | C21: UAZ431H | D21: 8 | F21: 1*2 | G21: 2.94 | H21: 3.2 | P21: Building Mat./Hardware
A22: 16 | B22: 0.47916667 | C22: UBE268A | D22: 8 | F22: 1*2 | G22: 1.4 | H22: 1.11
A23: 17 | B23: 0.48263889 | C23: UBF189F | D23: 8 | F23: 1*2 | G23: 2.04 | H23: 4.68 | P23: Shop items
A24: 18 | B24: 0.48819444 | C24: UAX333K | D24: 8 | F24: 1*2 | G24: 1.34 | H24: 1.99 | P24: Others
A25: 19 | B25: 0.53125 | C25: UAX174J | D25: 8 | F25: 1*2 | G25: 1.92 | H25: 2.9 | P25: Agric Produce
A26: 20 | B26: 0.052083333 | C26: UBA424L | D26: 8 | F26: 1*2 | G26: 3.8 | H26: 9.9 | P26: Agric Produce
A27: 21 | B27: 0.057638889 | C27: UBA764K | D27: 8 | F27: 1*2 | G27: 2.06 | H27: 2.1
A28: 22 | B28: 0.15902778 | C28: UBA374L | D28: 8 | F28: 1*2 | G28: 3.4 | H28: 8 | P28: Building Mat./Hardware
A29: 23 | B29: 0.22638889 | C29: UAU634M | D29: 8 | F29: 1*2 | G29: 3.02 | H29: 7 | P29: Processed Foods & Beverages
H30: KAMPALA - HOIMA
A31: 1 | B31: 0.32708333 | C31: UBA257G | D31: 8 | F31: 1*2 | G31: 1.07 | H31: 2.55
A32: 2 | B32: 0.35069444 | C32: UBB699M | D32: 8 | F32: 1*2 | G32: 2.2 | H32: 5.85 | P32: Agric Produce
A33: 3 | B33: 0.35416667 | C33: UAY812G | D33: 8 | F33: 1*2 | G33: 2.2 | H33: 5.85 | P33: Agric Produce
A34: 4 | B34: 0.35833333 | C34: UBB817G | D34: 8 | F34: 1*2 | G34: 3.52 | H34: 9.14 | P34: Agric Produce
A35: 5 | B35: 0.36527778 | C35: UAX671J | D35: 8 | F35: 1*2 | G35: 2.42 | H35: 4.52 | P35: Processed Foods & Beverages
A36: 6 | B36: 0.37222222 | C36: UAW744K | D36: 8 | F36: 1*2 | G36: 2.1 | H36: 6.04 | P36: Processed Foods & Beverages
A37: 7 | B37: 0.37916667 | C37: UBA614N | D37: 8 | F37: 1*2 | G37: 4 | H37: 9.36 | P37: Agric Produce
A38: 8 | B38: 0.39444444 | C38: UBA889P | D38: 8 | F38: 1*2 | G38: 3.11 | H38: 8.95 | P38: Agric Produce
A39: 9 | B39: 0.42638889 | C39: UBF856L | D39: 8 | F39: 1*2 | G39: 1.39 | H39: 4.9 | P39: Shop items
A40: 10 | B40: 0.47986111 | C40: UBD575E | D40: 8 | F40: 1*2 | G40: 4 | H40: 8.86 | P40: Building Mat./Hardware
...

Sheet DAY3
A1: Consultancy services for Preparation of Expressway Development Master Plan (EDMP) for Uganda
A2: AXLE LOAD SURVEY FORM
A3: Date: | D3: Station Name:
A4: 43693 | H4: HOIMA-KAMPALA
A5: S/No. | B5: Time | C5: Reg. Number | D5: Vehicle Type | E5: Number of Axles | F5: Axle Configuration | G5: Front | H5: TONNES | N5: Total (Tonnes) | O5: Total (ESA's) | P5: COMMENTS
G6: Axle 1 | H6: Axle 2 | I6: Axle 3 | J6: Axle 4 | K6: Axle 5 | L6: Axle 6 | M6: Axle 7
A7: 1 | B7: 0.30208333 | C7: UAY463W | D7: 8 | F7: 1*2 | G7: 1.56 | H7: 1.8
A8: 2 | B8: 0.3125 | C8: UAX553Y | D8: 8 | F8: 1*2 | G8: 1.6 | H8: 1.81
A9: 3 | B9: 0.31597222 | C9: UAU932Y | D9: 8 | F9: 1*2 | G9: 1.52 | H9: 1.96
A10: 4 | B10: 0.325 | C10: UAA984W | D10: 8 | F10: 1*2 | G10: 6 | H10: 14 | P10: Building Mat./Hardware
A11: 5 | B11: 0.35347222 | C11: UAN567J | D11: 8 | F11: 1*2 | G11: 2.8 | H11: 1.6
A12: 6 | B12: 0.35486111 | C12: UAM328T | D12: 8 | F12: 1*2 | G12: 5 | H12: 9 | P12: Agric Produce
A13: 7 | B13: 0.36736111 | C13: UAT568T | D13: 8 | F13: 1*2 | G13: 3.6 | H13: 7.07 | P13: Agric Produce
A14: 8 | B14: 0.40833333 | C14: UAU585K | D14: 8 | F14: 1*2 | G14: 9 | H14: 17 | P14: Building Mat./Hardware
A15: 9 | B15: 0.41319444 | C15: UAR513M | D15: 8 | F15: 1*2 | G15: 7 | H15: 12 | P15: Agric Produce
A16: 10 | B16: 0.4375 | C16: UAR513M | D16: 8 | F16: 1*2 | G16: 3.24 | H16: 4.26 | P16: Agric Produce
A17: 11 | B17: 0.47916667 | C17: UAP132X | D17: 8 | F17: 1*2 | G17: 1.98 | H17: 3.24 | P17: Building Mat./Hardware
A18: 12 | B18: 0.53125 | C18: UAT285J | D18: 8 | F18: 1*2 | G18: 5.7 | H18: 13 | P18: Agric Produce
A19: 13 | B19: 0.0875 | C19: UAJ112G | D19: 8 | F19: 1*2 | G19: 2 | H19: 2.1
A20: 14 | B20: 0.11527778 | C20: UAW951M | D20: 8 | F20: 1*2 | G20: 2.8 | H20: 3.8 | P20: Processed Foods & Beverages
A21: 15 | B21: 0.14861111 | C21: UBF114N | D21: 8 | F21: 1*2 | G21: 4.6 | H21: 8.24 | P21: Shop items
A22: 16 | B22: 0.18125 | C22: UAP578R | D22: 8 | F22: 1*2 | G22: 3.64 | H22: 9.34 | P22: Fuels (Gas & Liquid)
A23: 17 | B23: 0.19444444 | C23: UAK394E | D23: 9 | F23: 1*2*2 | G23: 3.75 | H23: 4.84 | I23: 4.94 | P23: Agric Produce
H24: KAMPALA - HOIMA
A25: 1 | B25: 0.29166667 | C25: UBE077M | D25: 8 | F25: 1*2 | G25: 5.2 | H25: 12 | P25: Agric Produce
A26: 2 | B26: 0.29583333 | C26: UAZ551A | D26: 8 | F26: 1*2 | G26: 5.2 | H26: 14.38 | P26: Agric Produce
A27: 3 | B27: 0.29861111 | C27: UAU562H | D27: 8 | F27: 1*2 | G27: 4.84 | H27: 13.18 | P27: Agric Produce
A28: 4 | B28: 0.30625 | C28: UB D686N | D28: 8 | F28: 1*2 | G28: 2.06 | H28: 1.52
A29: 5 | B29: 0.30902778 | C29: UBD187S | D29: 8 | F29: 1*2 | G29: 2.08 | H29: 1.52
A30: 6 | B30: 0.31875 | C30: UBA546S | D30: 8 | F30: 1*2 | G30: 2.54 | H30: 1.51
A31: 7 | B31: 0.32291667 | C31: UAY386S | D31: 8 | F31: 1*2 | G31: 5.8 | H31: 15.8 | P31: Agric Produce
A32: 8 | B32: 0.35347222 | C32: UBD500K | D32: 10 | F32: 1*2*22 | G32: 5.14 | H32: 9.58 | I32: 13.38 | J32: 3.02 | P32: Agric Produce
A33: 9 | B33: 0.36111111 | C33: UAU445A | D33: 8 | F33: 1*2 | G33: 2.6 | H33: 1.1
A34: 10 | B34: 0.39652778 | C34: UAU385K | D34: 8 | F34: 1*2 | G34: 3.64 | H34: 8.56 | P34: Processed Foods & Beverages
A35: 11 | B35: 0.40763889 | C35: UAZ284S | D35: 8 | F35: 1*2 | G35: 3.88 | H35: 5 | P35: Building Mat./Hardware
A36: 12 | B36: 0.41388889 | C36: UAY764O | D36: 8 | F36: 1*2 | G36: 1.08 | H36: 1.12
A37: 13 | B37: 0.42777778 | C37: UBD433F | D37: 8 | F37: 1*2 | G37: 4.52 | H37: 12.96 | P37: Agric Produce
A38: 14 | B38: 0.42777778 | C38: UBD017H | D38: 8 | F38: 1*2 | G38: 2.2 | H38: 1.11
A39: 15 | B39: 0.42777778 | C39: UAY224E | D39: 8 | F39: 1*2 | G39: 2.54 | H39: 1.2
A40: 16 | B40: 0.42847222 | C40: UAY188B | D40: 8 | F40: 1*2 | G40: 1.5 | H40: 1.09
...

Sheet Kla-Hoima
A1: Consultancy services for Preparation of Expressway Development Master Plan (EDMP) for Uganda
A2: AXLE LOAD SURVEY FORM
A3: Date: | D3: Station Name: | E3: KAKIRI
A4: 43691 | H4: KAMPALA - HOIMA
A5: S/No. | B5: Time | C5: Reg. Number | D5: Vehicle Type | E5: Number of Axles | F5: Axle Configuration | G5: Front | H5: TONNES | N5: Total (Tonnes) | O5: Total (ESA's) | P5: Load limit (Tonnes) | W5: OVERLOADED? | X5: Overloaded by? | Y5: Overload Bands | Z5: COMMENTS
G6: Axle 1 | H6: Axle 2 | I6: Axle 3 | J6: Axle 4 | K6: Axle 5 | L6: Axle 6 | M6: Axle 7 | P6: Axle 1 | Q6: Axle 2 | R6: Axle 3 | S6: Axle 4 | T6: Axle 5 | U6: Axle 6 | V6: Axle 7
A7: 1 | B7: 0.30208333 | C7: UAT292G | D7: =IF(COUNT(G7:M7)>3,10,IF(COUNT(G7:M7)>2,9,7)) -> 7 | F7: 1*2 | G7: 1.64 | H7: 1.05 | N7: =SUM(G7:M7) -> 2.69 | O7: =(N7/8.16)^4.5 -> 0.0067807783 | P7: 8 | Q7: 10 | R7: 9 | S7: 9 | T7: 9 | U7: 9 | V7: 9 | W7: =IF(G7>P7,"Y",IF(H7>Q7,"Y",IF(I7>R7,"Y",IF(J7>S7,"Y",IF(K7>T7,"Y",IF(L7>U7,"Y",IF(M7>V7,"Y","N"))))))) -> N | X7: =IF(W7="Y",MAX((G7-P7),(H7-Q7),(I7-R7),(J7-S7),(K7-T7),(L7-U7),(M7-V7))/10,0) -> 0 | Y7: =IF(X7<5%,"0-4.9%",IF(X7<25%,"5-25%",IF(X7<50%,"25-50%","Over 50%"))) -> 0-4.9% | Z7: Empty
A8: 3 | B8: 0.34166667 | C8: UAN393Z | D8: =IF(COUNT(G8:M8)>3,10,IF(COUNT(G8:M8)>2,9,7)) -> 7 | F8: 1*2* | G8: 5.41 | H8: 13 | N8: =SUM(G8:M8) -> 18.41 | O8: =(N8/8.16)^4.5 -> 38.916729 | P8: 8 | Q8: 10 | R8: 9 | S8: 9 | T8: 9 | U8: 9 | V8: 9 | W8: =IF(G8>P8,"Y",IF(H8>Q8,"Y",IF(I8>R8,"Y",IF(J8>S8,"Y",IF(K8>T8,"Y",IF(L8>U8,"Y",IF(M8>V8,"Y","N"))))))) -> Y | X8: =IF(W8="Y",MAX((G8-P8),(H8-Q8),(I8-R8),(J8-S8),(K8-T8),(L8-U8),(M8-V8))/10,0) -> 0.3 | Y8: =IF(X8<5%,"0-4.9%",IF(X8<25%,"5-25%",IF(X8<50%,"25-50%","Over 50%"))) -> 25-50% | Z8: Others
A9: 4 | B9: 0.34861111 | C9: UBE378N | D9: =IF(COUNT(G9:M9)>3,10,IF(COUNT(G9:M9)>2,9,7)) -> 7 | F9: 1*2 | G9: 4.68 | H9: 8.38 | N9: =SUM(G9:M9) -> 13.06 | O9: =(N9/8.16)^4.5 -> 8.3011561 | P9: 8 | Q9: 10 | R9: 9 | S9: 9 | T9: 9 | U9: 9 | V9: 9 | W9: =IF(G9>P9,"Y",IF(H9>Q9,"Y",IF(I9>R9,"Y",IF(J9>S9,"Y",IF(K9>T9,"Y",IF(L9>U9,"Y",IF(M9>V9,"Y","N"))))))) -> N | X9: =IF(W9="Y",MAX((G9-P9),(H9-Q9),(I9-R9),(J9-S9),(K9-T9),(L9-U9),(M9-V9))/10,0) -> 0 | Y9: =IF(X9<5%,"0-4.9%",IF(X9<25%,"5-25%",IF(X9<50%,"25-50%","Over 50%"))) -> 0-4.9% | Z9: Construction Material
A10: 5 | B10: 0.35833333 | C10: UAY389K | D10: =IF(COUNT(G10:M10)>3,10,IF(COUNT(G10:M10)>2,9,7)) -> 7 | F10: 1*2 | G10: 2.13 | H10: 1.44 | N10: =SUM(G10:M10) -> 3.57 | O10: =(N10/8.16)^4.5 -> 0.024232669 | P10: 8 | Q10: 10 | R10: 9 | S10: 9 | T10: 9 | U10: 9 | V10: 9 | W10: =IF(G10>P10,"Y",IF(H10>Q10,"Y",IF(I10>R10,"Y",IF(J10>S10,"Y",IF(K10>T10,"Y",IF(L10>U10,"Y",IF(M10>V10,"Y","N"))))))) -> N | X10: =IF(W10="Y",MAX((G10-P10),(H10-Q10),(I10-R10),(J10-S10),(K10-T10),(L10-U10),(M10-V10))/10,0) -> 0 | Y10: =IF(X10<5%,"0-4.9%",IF(X10<25%,"5-25%",IF(X10<50%,"25-50%","Over 50%"))) -> 0-4.9% | Z10: Empty
A11: 6 | B11: 0.42152778 | C11: UAK004J | D11: =IF(COUNT(G11:M11)>3,10,IF(COUNT(G11:M11)>2,9,7)) -> 7 | F11: 1*2 | G11: 6.8 | H11: 19.6 | N11: =SUM(G11:M11) -> 26.4 | O11: =(N11/8.16)^4.5 -> 197.06612 | P11: 8 | Q11: 10 | R11: 9 | S11: 9 | T11: 9 | U11: 9 | V11: 9 | W11: =IF(G11>P11,"Y",IF(H11>Q11,"Y",IF(I11>R11,"Y",IF(J11>S11,"Y",IF(K11>T11,"Y",IF(L11>U11,"Y",IF(M11>V11,"Y","N"))))))) -> Y | X11: =IF(W11="Y",MAX((G11-P11),(H11-Q11),(I11-R11),(J11-S11),(K11-T11),(L11-U11),(M11-V11))/10,0) -> 0.96 | Y11: =IF(X11<5%,"0-4.9%",IF(X11<25%,"5-25%",IF(X11<50%,"25-50%","Over 50%"))) -> Over 50% | Z11: Agricultural produce
A12: 7 | B12: 0.42569444 | C12: UBB345G | D12: =IF(COUNT(G12:M12)>3,10,IF(COUNT(G12:M12)>2,9,7)) -> 7 | F12: 1*2 | G12: 2.98 | H12: 8.4 | N12: =SUM(G12:M12) -> 11.38 | O12: =(N12/8.16)^4.5 -> 4.4671904 | P12: 8 | Q12: 10 | R12: 9 | S12: 9 | T12: 9 | U12: 9 | V12: 9 | W12: =IF(G12>P12,"Y",IF(H12>Q12,"Y",IF(I12>R12,"Y",IF(J12>S12,"Y",IF(K12>T12,"Y",IF(L12>U12,"Y",IF(M12>V12,"Y","N"))))))) -> N | X12: =IF(W12="Y",MAX((G12-P12),(H12-Q12),(I12-R12),(J12-S12),(K12-T12),(L12-U12),(M12-V12))/10,0) -> 0 | Y12: =IF(X12<5%,"0-4.9%",IF(X12<25%,"5-25%",IF(X12<50%,"25-50%","Over 50%"))) -> 0-4.9% | Z12: Household retail products
A13: 8 | B13: 0.42777778 | C13: UBC880B | D13: =IF(COUNT(G13:M13)>3,10,IF(COUNT(G13:M13)>2,9,7)) -> 7 | F13: 1*2 | G13: 2.38 | H13: 1.76 | N13: =SUM(G13:M13) -> 4.14 | O13: =(N13/8.16)^4.5 -> 0.047194982 | P13: 8 | Q13: 10 | R13: 9 | S13: 9 | T13: 9 | U13: 9 | V13: 9 | W13: =IF(G13>P13,"Y",IF(H13>Q13,"Y",IF(I13>R13,"Y",IF(J13>S13,"Y",IF(K13>T13,"Y",IF(L13>U13,"Y",IF(M13>V13,"Y","N"))))))) -> N | X13: =IF(W13="Y",MAX((G13-P13),(H13-Q13),(I13-R13),(J13-S13),(K13-T13),(L13-U13),(M13-V13))/10,0) -> 0 | Y13: =IF(X13<5%,"0-4.9%",IF(X13<25%,"5-25%",IF(X13<50%,"25-50%","Over 50%"))) -> 0-4.9% | Z13: Empty
A14: 9 | B14: 0.4375 | C14: UAP518R | D14: =IF(COUNT(G14:M14)>3,10,IF(COUNT(G14:M14)>2,9,7)) -> 7 | F14: 1*2 | G14: 8.16 | H14: 17.42 | N14: =SUM(G14:M14) -> 25.58 | O14: =(N14/8.16)^4.5 -> 170.98055 | P14: 8 | Q14: 10 | R14: 9 | S14: 9 | T14: 9 | U14: 9 | V14: 9 | W14: =IF(G14>P14,"Y",IF(H14>Q14,"Y",IF(I14>R14,"Y",IF(J14>S14,"Y",IF(K14>T14,"Y",IF(L14>U14,"Y",IF(M14>V14,"Y","N"))))))) -> Y | X14: =IF(W14="Y",MAX((G14-P14),(H14-Q14),(I14-R14),(J14-S14),(K14-T14),(L14-U14),(M14-V14))/10,0) -> 0.742 | Y14: =IF(X14<5%,"0-4.9%",IF(X14<25%,"5-25%",IF(X14<50%,"25-50%","Over 50%"))) -> Over 50% | Z14: Agricultural produce
A15: 11 | B15: 0.46875 | C15: UAZ597L | D15: =IF(COUNT(G15:M15)>3,10,IF(COUNT(G15:M15)>2,9,7)) -> 7 | F15: 1*2 | G15: 2.9 | H15: 2.32 | N15: =SUM(G15:M15) -> 5.22 | O15: =(N15/8.16)^4.5 -> 0.13394039 | P15: 8 | Q15: 10 | R15: 9 | S15: 9 | T15: 9 | U15: 9 | V15: 9 | W15: =IF(G15>P15,"Y",IF(H15>Q15,"Y",IF(I15>R15,"Y",IF(J15>S15,"Y",IF(K15>T15,"Y",IF(L15>U15,"Y",IF(M15>V15,"Y","N"))))))) -> N | X15: =IF(W15="Y",MAX((G15-P15),(H15-Q15),(I15-R15),(J15-S15),(K15-T15),(L15-U15),(M15-V15))/10,0) -> 0 | Y15: =IF(X15<5%,"0-4.9%",IF(X15<25%,"5-25%",IF(X15<50%,"25-50%","Over 50%"))) -> 0-4.9% | Z15: Empty
A16: 12 | B16: 0.47916667 | C16: KCT753J | D16: =IF(COUNT(G16:M16)>3,10,IF(COUNT(G16:M16)>2,9,7)) -> 7 | F16: 1*2 | G16: 5.64 | H16: 10.98 | N16: =SUM(G16:M16) -> 16.62 | O16: =(N16/8.16)^4.5 -> 24.560312 | P16: 8 | Q16: 10 | R16: 9 | S16: 9 | T16: 9 | U16: 9 | V16: 9 | W16: =IF(G16>P16,"Y",IF(H16>Q16,"Y",IF(I16>R16,"Y",IF(J16>S16,"Y",IF(K16>T16,"Y",IF(L16>U16,"Y",IF(M16>V16,"Y","N"))))))) -> Y | X16: =IF(W16="Y",MAX((G16-P16),(H16-Q16),(I16-R16),(J16-S16),(K16-T16),(L16-U16),(M16-V16))/10,0) -> 0.098 | Y16: =IF(X16<5%,"0-4.9%",IF(X16<25%,"5-25%",IF(X16<50%,"25-50%","Over 50%"))) -> 5-25% | Z16: Agricultural produce
A17: 13 | B17: 0.48333333 | C17: UAY685D | D17: =IF(COUNT(G17:M17)>3,10,IF(COUNT(G17:M17)>2,9,7)) -> 7 | F17: 1*2 | G17: 5.38 | H17: 11.28 | N17: =SUM(G17:M17) -> 16.66 | O17: =(N17/8.16)^4.5 -> 24.82743 | P17: 8 | Q17: 10 | R17: 9 | S17: 9 | T17: 9 | U17: 9 | V17: 9 | W17: =IF(G17>P17,"Y",IF(H17>Q17,"Y",IF(I17>R17,"Y",IF(J17>S17,"Y",IF(K17>T17,"Y",IF(L17>U17,"Y",IF(M17>V17,"Y","N"))))))) -> Y | X17: =IF(W17="Y",MAX((G17-P17),(H17-Q17),(I17-R17),(J17-S17),(K17-T17),(L17-U17),(M17-V17))/10,0) -> 0.128 | Y17: =IF(X17<5%,"0-4.9%",IF(X17<25%,"5-25%",IF(X17<50%,"25-50%","Over 50%"))) -> 5-25% | Z17: Agricultural produce
A18: 14 | B18: 0.48541667 | C18: UAZ119V | D18: =IF(COUNT(G18:M18)>3,10,IF(COUNT(G18:M18)>2,9,7)) -> 7 | F18: 1*2 | G18: 3.5 | H18: 6.04 | N18: =SUM(G18:M18) -> 9.54 | O18: =(N18/8.16)^4.5 -> 2.0200493 | P18: 8 | Q18: 10 | R18: 9 | S18: 9 | T18: 9 | U18: 9 | V18: 9 | W18: =IF(G18>P18,"Y",IF(H18>Q18,"Y",IF(I18>R18,"Y",IF(J18>S18,"Y",IF(K18>T18,"Y",IF(L18>U18,"Y",IF(M18>V18,"Y","N"))))))) -> N | X18: =IF(W18="Y",MAX((G18-P18),(H18-Q18),(I18-R18),(J18-S18),(K18-T18),(L18-U18),(M18-V18))/10,0) -> 0 | Y18: =IF(X18<5%,"0-4.9%",IF(X18<25%,"5-25%",IF(X18<50%,"25-50%","Over 50%"))) -> 0-4.9% | Z18: Household retail products
... A122: 43 | B122: 0.28680556 | C122: UAX172M | D122: =IF(COUNT(G122:M122)>3,10,IF(COUNT(G122:M122)>2,9,7)) -> 7 | F122: 1*2 | G122: 2.04 | H122: 6.1 | N122: =SUM(G122:M122) -> 8.14 | O122: =(N122/8.16)^4.5 -> 0.9890178 | P122: 8 | Q122: 10 | R122: 9 | S122: 9 | T122: 9 | U122: 9 | V122: 9 | W122: =IF(G122>P122,"Y",IF(H122>Q122,"Y",IF(I122>R122,"Y",IF(J122>S122,"Y",IF(K122>T122,"Y",IF(L122>U122,"Y",IF(M122>V122,"Y","N"))))))) -> N | X122: =IF(W122="Y",MAX((G122-P122),(H122-Q122),(I122-R122),(J122-S122),(K122-T122),(L122-U122),(M122-V122))/10,0) -> 0 | Y122: =IF(X122<5%,"0-4.9%",IF(X122<25%,"5-25%",IF(X122<50%,"25-50%","Over 50%"))) -> 0-4.9% | Z122: Agricultural produce
A123: 33 | B123: 0.2 | C123: UAU804U | D123: =IF(COUNT(G123:M123)>3,10,IF(COUNT(G123:M123)>2,9,7)) -> 9 | F123: 1*2*2 | G123: 4.06 | H123: 4.48 | I123: 3.92 | N123: =SUM(G123:M123) -> 12.46 | O123: =(N123/8.16)^4.5 -> 6.7177753 | P123: 8 | Q123: 10 | R123: 9 | S123: 9 | T123: 9 | U123: 9 | V123: 9 | W123: =IF(G123>P123,"Y",IF(H123>Q123,"Y",IF(I123>R123,"Y",IF(J123>S123,"Y",IF(K123>T123,"Y",IF(L123>U123,"Y",IF(M123>V123,"Y","N"))))))) -> N | X123: =IF(W123="Y",MAX((G123-P123),(H123-Q123),(I123-R123),(J123-S123),(K123-T123),(L123-U123),(M123-V123))/10,0) -> 0 | Y123: =IF(X123<5%,"0-4.9%",IF(X123<25%,"5-25%",IF(X123<50%,"25-50%","Over 50%"))) -> 0-4.9% | Z123: Fuels
A124: 40 | B124: 0.27291667 | C124: UAQ817A | D124: =IF(COUNT(G124:M124)>3,10,IF(COUNT(G124:M124)>2,9,7)) -> 9 | F124: 1*21 | G124: 1.04 | H124: 2.73 | I124: 0.546 | N124: =SUM(G124:M124) -> 4.316 | O124: =(N124/8.16)^4.5 -> 0.056919457 | P124: 8 | Q124: 10 | R124: 9 | S124: 9 | T124: 9 | U124: 9 | V124: 9 | W124: =IF(G124>P124,"Y",IF(H124>Q124,"Y",IF(I124>R124,"Y",IF(J124>S124,"Y",IF(K124>T124,"Y",IF(L124>U124,"Y",IF(M124>V124,"Y","N"))))))) -> N | X124: =IF(W124="Y",MAX((G124-P124),(H124-Q124),(I124-R124),(J124-S124),(K124-T124),(L124-U124),(M124-V124))/10,0) -> 0 | Y124: =IF(X124<5%,"0-4.9%",IF(X124<25%,"5-25%",IF(X124<50%,"25-50%","Over 50%"))) -> 0-4.9% | Z124: Empty
A125: 41 | B125: 0.27847222 | C125: UBE702M | D125: =IF(COUNT(G125:M125)>3,10,IF(COUNT(G125:M125)>2,9,7)) -> 9 | F125: 1*21 | G125: 2.845 | H125: 2.845 | I125: 0.516 | N125: =SUM(G125:M125) -> 6.206 | O125: =(N125/8.16)^4.5 -> 0.29177445 | P125: 8 | Q125: 10 | R125: 9 | S125: 9 | T125: 9 | U125: 9 | V125: 9 | W125: =IF(G125>P125,"Y",IF(H125>Q125,"Y",IF(I125>R125,"Y",IF(J125>S125,"Y",IF(K125>T125,"Y",IF(L125>U125,"Y",IF(M125>V125,"Y","N"))))))) -> N | X125: =IF(W125="Y",MAX((G125-P125),(H125-Q125),(I125-R125),(J125-S125),(K125-T125),(L125-U125),(M125-V125))/10,0) -> 0 | Y125: =IF(X125<5%,"0-4.9%",IF(X125<25%,"5-25%",IF(X125<50%,"25-50%","Over 50%"))) -> 0-4.9% | Z125: Agricultural produce
A126: 2 | B126: 0.33958333 | C126: UAY410B | D126: =IF(COUNT(G126:M126)>3,10,IF(COUNT(G126:M126)>2,9,7)) -> 10 | F126: 1*22*22 | G126: 7.52 | H126: 9.86 | I126: 2.05 | J126: 11.32 | K126: 5.41 | N126: =SUM(G126:M126) -> 36.16 | O126: =(N126/8.16)^4.5 -> 811.74979 | P126: 8 | Q126: 10 | R126: 9 | S126: 9 | T126: 9 | U126: 9 | V126: 9 | W126: =IF(G126>P126,"Y",IF(H126>Q126,"Y",IF(I126>R126,"Y",IF(J126>S126,"Y",IF(K126>T126,"Y",IF(L126>U126,"Y",IF(M126>V126,"Y","N"))))))) -> Y | X126: =IF(W126="Y",MAX((G126-P126),(H126-Q126),(I126-R126),(J126-S126),(K126-T126),(L126-U126),(M126-V126))/10,0) -> 0.232 | Y126: =IF(X126<5%,"0-4.9%",IF(X126<25%,"5-25%",IF(X126<50%,"25-50%","Over 50%"))) -> 5-25% | Z126: Agricultural produce
A127: 10 | B127: 0.45069444 | C127: UBD582A | D127: =IF(COUNT(G127:M127)>3,10,IF(COUNT(G127:M127)>2,9,7)) -> 10 | F127: 1*22*222 | G127: 5.02 | H127: 6.92 | I127: 7.38 | J127: 11.52 | K127: 11.86 | L127: 1.202 | N127: =SUM(G127:M127) -> 43.902 | O127: =(N127/8.16)^4.5 -> 1943.4513 | P127: 8 | Q127: 10 | R127: 9 | S127: 9 | T127: 9 | U127: 9 | V127: 9 | W127: =IF(G127>P127,"Y",IF(H127>Q127,"Y",IF(I127>R127,"Y",IF(J127>S127,"Y",IF(K127>T127,"Y",IF(L127>U127,"Y",IF(M127>V127,"Y","N"))))))) -> Y | X127: =IF(W127="Y",MAX((G127-P127),(H127-Q127),(I127-R127),(J127-S127),(K127-T127),(L127-U127),(M127-V127))/10,0) -> 0.286 | Y127: =IF(X127<5%,"0-4.9%",IF(X127<25%,"5-25%",IF(X127<50%,"25-50%","Over 50%"))) -> 25-50% | Z127: Household retail products
A128: 42 | B128: 0.26388889 | C128: UAY760P | D128: =IF(COUNT(G128:M128)>3,10,IF(COUNT(G128:M128)>2,9,7)) -> 10 | F128: 1*22-22*22 | G128: 3.05 | H128: 4.96 | I128: 4.44 | J128: 3.37 | K128: 4.47 | L128: 3.66 | M128: 3.96 | N128: =SUM(G128:M128) -> 27.91 | O128: =(N128/8.16)^4.5 -> 253.11247 | P128: 8 | Q128: 10 | R128: 9 | S128: 9 | T128: 9 | U128: 9 | V128: 9 | W128: =IF(G128>P128,"Y",IF(H128>Q128,"Y",IF(I128>R128,"Y",IF(J128>S128,"Y",IF(K128>T128,"Y",IF(L128>U128,"Y",IF(M128>V128,"Y","N"))))))) -> N | X128: =IF(W128="Y",MAX((G128-P128),(H128-Q128),(I128-R128),(J128-S128),(K128-T128),(L128-U128),(M128-V128))/10,0) -> 0 | Y128: =IF(X128<5%,"0-4.9%",IF(X128<25%,"5-25%",IF(X128<50%,"25-50%","Over 50%"))) -> 0-4.9% | Z128: Empty
A129: 46 | B129: 0.28263889 | C129: UAW349F | D129: =IF(COUNT(G129:M129)>3,10,IF(COUNT(G129:M129)>2,9,7)) -> 10 | F129: 1*22*22 | G129: 3.72 | H129: 6.44 | I129: 6.77 | J129: 6.74 | K129: 2.06 | N129: =SUM(G129:M129) -> 25.73 | O129: =(N129/8.16)^4.5 -> 175.53888 | P129: 8 | Q129: 10 | R129: 9 | S129: 9 | T129: 9 | U129: 9 | V129: 9 | W129: =IF(G129>P129,"Y",IF(H129>Q129,"Y",IF(I129>R129,"Y",IF(J129>S129,"Y",IF(K129>T129,"Y",IF(L129>U129,"Y",IF(M129>V129,"Y","N"))))))) -> N | X129: =IF(W129="Y",MAX((G129-P129),(H129-Q129),(I129-R129),(J129-S129),(K129-T129),(L129-U129),(M129-V129))/10,0) -> 0 | Y129: =IF(X129<5%,"0-4.9%",IF(X129<25%,"5-25%",IF(X129<50%,"25-50%","Over 50%"))) -> 0-4.9% | Z129: Fuels
A130: 37 | B130: 0.26111111 | C130: UAY390G | D130: =IF(COUNT(G130:M130)>3,10,IF(COUNT(G130:M130)>2,9,7)) -> 10 | F130: 1*2*22 | G130: 2.465 | H130: 1.47 | I130: 2.15 | J130: 2.66 | N130: =SUM(G130:M130) -> 8.745 | O130: =(N130/8.16)^4.5 -> 1.3655684 | P130: 8 | Q130: 10 | R130: 9 | S130: 9 | T130: 9 | U130: 9 | V130: 9 | W130: =IF(G130>P130,"Y",IF(H130>Q130,"Y",IF(I130>R130,"Y",IF(J130>S130,"Y",IF(K130>T130,"Y",IF(L130>U130,"Y",IF(M130>V130,"Y","N"))))))) -> N | X130: =IF(W130="Y",MAX((G130-P130),(H130-Q130),(I130-R130),(J130-S130),(K130-T130),(L130-U130),(M130-V130))/10,0) -> 0 | Y130: =IF(X130<5%,"0-4.9%",IF(X130<25%,"5-25%",IF(X130<50%,"25-50%","Over 50%"))) -> 0-4.9% | Z130: Empty
A131: 8 | B131: 0.35347222 | C131: UBD500K | D131: =IF(COUNT(G131:M131)>3,10,IF(COUNT(G131:M131)>2,9,7)) -> 10 | F131: 1*2*22 | G131: 5.14 | H131: 9.58 | I131: 13.38 | J131: 3.02 | N131: =SUM(G131:M131) -> 31.12 | O131: =(N131/8.16)^4.5 -> 413.1164 | P131: 8 | Q131: 10 | R131: 9 | S131: 9 | T131: 9 | U131: 9 | V131: 9 | W131: =IF(G131>P131,"Y",IF(H131>Q131,"Y",IF(I131>R131,"Y",IF(J131>S131,"Y",IF(K131>T131,"Y",IF(L131>U131,"Y",IF(M131>V131,"Y","N"))))))) -> Y | X131: =IF(W131="Y",MAX((G131-P131),(H131-Q131),(I131-R131),(J131-S131),(K131-T131),(L131-U131),(M131-V131))/10,0) -> 0.438 | Y131: =IF(X131<5%,"0-4.9%",IF(X131<25%,"5-25%",IF(X131<50%,"25-50%","Over 50%"))) -> 25-50% | Z131: Fuels
A132: 23 | B132: 0.096527778 | C132: UAJ370K | D132: =IF(COUNT(G132:M132)>3,10,IF(COUNT(G132:M132)>2,9,7)) -> 10 | F132: 1*22*22 | G132: 4.5 | H132: 9.32 | I132: 10.72 | J132: 10.65 | K132: 4.43 | N132: =SUM(G132:M132) -> 39.62 | O132: =(N132/8.16)^4.5 -> 1224.6427 | P132: 8 | Q132: 10 | R132: 9 | S132: 9 | T132: 9 | U132: 9 | V132: 9 | W132: =IF(G132>P132,"Y",IF(H132>Q132,"Y",IF(I132>R132,"Y",IF(J132>S132,"Y",IF(K132>T132,"Y",IF(L132>U132,"Y",IF(M132>V132,"Y","N"))))))) -> Y | X132: =IF(W132="Y",MAX((G132-P132),(H132-Q132),(I132-R132),(J132-S132),(K132-T132),(L132-U132),(M132-V132))/10,0) -> 0.172 | Y132: =IF(X132<5%,"0-4.9%",IF(X132<25%,"5-25%",IF(X132<50%,"25-50%","Over 50%"))) -> 5-25% | Z132: Fuels
A133: 37 | B133: 0.26319444 | C133: UAV296N | D133: =IF(COUNT(G133:M133)>3,10,IF(COUNT(G133:M133)>2,9,7)) -> 10 | F133: 1*22*222 | G133: 5.44 | H133: 8.12 | I133: 9.66 | J133: 6.44 | K133: 1.82 | L133: 4.78 | N133: =SUM(G133:M133) -> 36.26 | O133: =(N133/8.16)^4.5 -> 821.90076 | P133: 8 | Q133: 10 | R133: 9 | S133: 9 | T133: 9 | U133: 9 | V133: 9 | W133: =IF(G133>P133,"Y",IF(H133>Q133,"Y",IF(I133>R133,"Y",IF(J133>S133,"Y",IF(K133>T133,"Y",IF(L133>U133,"Y",IF(M133>V133,"Y","N"))))))) -> Y | X133: =IF(W133="Y",MAX((G133-P133),(H133-Q133),(I133-R133),(J133-S133),(K133-T133),(L133-U133),(M133-V133))/10,0) -> 0.066 | Y133: =IF(X133<5%,"0-4.9%",IF(X133<25%,"5-25%",IF(X133<50%,"25-50%","Over 50%"))) -> 5-25% | Z133: Fuels
A134: 42 | B134: 0.28541667 | C134: KAT923H | D134: =IF(COUNT(G134:M134)>3,10,IF(COUNT(G134:M134)>2,9,7)) -> 10 | F134: 1*22*222 | G134: 7.58 | H134: 9.9 | I134: 11.56 | J134: 5.32 | K134: 6.1 | L134: 6.94 | N134: =SUM(G134:M134) -> 47.4 | O134: =(N134/8.16)^4.5 -> 2744.0803 | P134: 8 | Q134: 10 | R134: 9 | S134: 9 | T134: 9 | U134: 9 | V134: 9 | W134: =IF(G134>P134,"Y",IF(H134>Q134,"Y",IF(I134>R134,"Y",IF(J134>S134,"Y",IF(K134>T134,"Y",IF(L134>U134,"Y",IF(M134>V134,"Y","N"))))))) -> Y | X134: =IF(W134="Y",MAX((G134-P134),(H134-Q134),(I134-R134),(J134-S134),(K134-T134),(L134-U134),(M134-V134))/10,0) -> 0.256 | Y134: =IF(X134<5%,"0-4.9%",IF(X134<25%,"5-25%",IF(X134<50%,"25-50%","Over 50%"))) -> 25-50% | Z134: Household retail products

Sheet Hoima-Kla
A1: Consultancy services for Preparation of Expressway Development Master Plan (EDMP) for Uganda
A2: AXLE LOAD SURVEY FORM
A3: Date: | D3: Station Name: | E3: KAKIRI
A4: 43691 | H4: HOIMA-KAMPALA
A5: S/No. | B5: Time | C5: Reg. Number | D5: Vehicle Type | E5: Number of Axles | F5: Axle Configuration | G5: Front | H5: TONNES | N5: Total (Tonnes) | O5: Total (ESA's) | P5: Load limit (Tonnes) | W5: OVERLOADED? | X5: Overloaded by? | Y5: Overload Bands | Z5: COMMENTS
G6: Axle 1 | H6: Axle 2 | I6: Axle 3 | J6: Axle 4 | K6: Axle 5 | L6: Axle 6 | M6: Axle 7 | P6: Axle 1 | Q6: Axle 2 | R6: Axle 3 | S6: Axle 4 | T6: Axle 5 | U6: Axle 6 | V6: Axle 7
A7: 1 | B7: 0.29861111 | C7: UAY048K | D7: =IF(COUNT(G7:M7)>3,10,IF(COUNT(G7:M7)>2,9,7)) -> 7 | F7: 1*2 | G7: 2.6 | H7: 4 | N7: =SUM(G7:M7) -> 6.6 | O7: =(N7/8.16)^4.5 -> 0.38489476 | P7: 8 | Q7: 10 | R7: 9 | S7: 9 | T7: 9 | U7: 9 | V7: 9 | W7: =IF(G7>P7,"Y",IF(H7>Q7,"Y",IF(I7>R7,"Y",IF(J7>S7,"Y",IF(K7>T7,"Y",IF(L7>U7,"Y",IF(M7>V7,"Y","N"))))))) -> N | X7: =IF(W7="Y",MAX((G7-P7),(H7-Q7),(I7-R7),(J7-S7),(K7-T7),(L7-U7),(M7-V7))/10,0) -> 0 | Y7: =IF(X7<5%,"0-4.9%",IF(X7<25%,"5-25%",IF(X7<50%,"25-50%","Over 50%"))) -> 0-4.9% | Z7: Agricultural produce
A8: 2 | B8: 0.30555556 | C8: UBD203G | D8: =IF(COUNT(G8:M8)>3,10,IF(COUNT(G8:M8)>2,9,7)) -> 7 | F8: 1*2 | G8: 3.9 | H8: 5.9 | N8: =SUM(G8:M8) -> 9.8 | O8: =(N8/8.16)^4.5 -> 2.2798781 | P8: 8 | Q8: 10 | R8: 9 | S8: 9 | T8: 9 | U8: 9 | V8: 9 | W8: =IF(G8>P8,"Y",IF(H8>Q8,"Y",IF(I8>R8,"Y",IF(J8>S8,"Y",IF(K8>T8,"Y",IF(L8>U8,"Y",IF(M8>V8,"Y","N"))))))) -> N | X8: =IF(W8="Y",MAX((G8-P8),(H8-Q8),(I8-R8),(J8-S8),(K8-T8),(L8-U8),(M8-V8))/10,0) -> 0 | Y8: =IF(X8<5%,"0-4.9%",IF(X8<25%,"5-25%",IF(X8<50%,"25-50%","Over 50%"))) -> 0-4.9% | Z8: Construction Material
A9: 3 | B9: 0.31736111 | C9: UAU133B | D9: =IF(COUNT(G9:M9)>3,10,IF(COUNT(G9:M9)>2,9,7)) -> 7 | F9: 1*2 | G9: 2.34 | H9: 5 | N9: =SUM(G9:M9) -> 7.34 | O9: =(N9/8.16)^4.5 -> 0.620907 | P9: 8 | Q9: 10 | R9: 9 | S9: 9 | T9: 9 | U9: 9 | V9: 9 | W9: =IF(G9>P9,"Y",IF(H9>Q9,"Y",IF(I9>R9,"Y",IF(J9>S9,"Y",IF(K9>T9,"Y",IF(L9>U9,"Y",IF(M9>V9,"Y","N"))))))) -> N | X9: =IF(W9="Y",MAX((G9-P9),(H9-Q9),(I9-R9),(J9-S9),(K9-T9),(L9-U9),(M9-V9))/10,0) -> 0 | Y9: =IF(X9<5%,"0-4.9%",IF(X9<25%,"5-25%",IF(X9<50%,"25-50%","Over 50%"))) -> 0-4.9% | Z9: Agricultural produce
A10: 5 | B10: 0.32986111 | C10: UBF793B | D10: =IF(COUNT(G10:M10)>3,10,IF(COUNT(G10:M10)>2,9,7)) -> 7 | F10: 1*2 | G10: 1.74 | H10: 2.024 | N10: =SUM(G10:M10) -> 3.764 | O10: =(N10/8.16)^4.5 -> 0.030748048 | P10: 8 | Q10: 10 | R10: 9 | S10: 9 | T10: 9 | U10: 9 | V10: 9 | W10: =IF(G10>P10,"Y",IF(H10>Q10,"Y",IF(I10>R10,"Y",IF(J10>S10,"Y",IF(K10>T10,"Y",IF(L10>U10,"Y",IF(M10>V10,"Y","N"))))))) -> N | X10: =IF(W10="Y",MAX((G10-P10),(H10-Q10),(I10-R10),(J10-S10),(K10-T10),(L10-U10),(M10-V10))/10,0) -> 0 | Y10: =IF(X10<5%,"0-4.9%",IF(X10<25%,"5-25%",IF(X10<50%,"25-50%","Over 50%"))) -> 0-4.9% | Z10: Empty
A11: 6 | B11: 0.33958333 | C11: UBE033R | D11: =IF(COUNT(G11:M11)>3,10,IF(COUNT(G11:M11)>2,9,7)) -> 7 | F11: 1*2 | G11: 8 | H11: 16 | N11: =SUM(G11:M11) -> 24 | O11: =(N11/8.16)^4.5 -> 128.33493 | P11: 8 | Q11: 10 | R11: 9 | S11: 9 | T11: 9 | U11: 9 | V11: 9 | W11: =IF(G11>P11,"Y",IF(H11>Q11,"Y",IF(I11>R11,"Y",IF(J11>S11,"Y",IF(K11>T11,"Y",IF(L11>U11,"Y",IF(M11>V11,"Y","N"))))))) -> Y | X11: =IF(W11="Y",MAX((G11-P11),(H11-Q11),(I11-R11),(J11-S11),(K11-T11),(L11-U11),(M11-V11))/10,0) -> 0.6 | Y11: =IF(X11<5%,"0-4.9%",IF(X11<25%,"5-25%",IF(X11<50%,"25-50%","Over 50%"))) -> Over 50% | Z11: Agricultural produce
A12: 7 | B12: 0.34722222 | C12: UAT260A | D12: =IF(COUNT(G12:M12)>3,10,IF(COUNT(G12:M12)>2,9,7)) -> 7 | F12: 1*2 | G12: 2.24 | H12: 1.44 | N12: =SUM(G12:M12) -> 3.68 | O12: =(N12/8.16)^4.5 -> 0.027778543 | P12: 8 | Q12: 10 | R12: 9 | S12: 9 | T12: 9 | U12: 9 | V12: 9 | W12: =IF(G12>P12,"Y",IF(H12>Q12,"Y",IF(I12>R12,"Y",IF(J12>S12,"Y",IF(K12>T12,"Y",IF(L12>U12,"Y",IF(M12>V12,"Y","N"))))))) -> N | X12: =IF(W12="Y",MAX((G12-P12),(H12-Q12),(I12-R12),(J12-S12),(K12-T12),(L12-U12),(M12-V12))/10,0) -> 0 | Y12: =IF(X12<5%,"0-4.9%",IF(X12<25%,"5-25%",IF(X12<50%,"25-50%","Over 50%"))) -> 0-4.9% | Z12: Empty
A13: 8 | B13: 0.35555556 | C13: UAU932V | D13: =IF(COUNT(G13:M13)>3,10,IF(COUNT(G13:M13)>2,9,7)) -> 7 | F13: 1*2 | G13: 2.8 | H13: 1.4 | N13: =SUM(G13:M13) -> 4.2 | O13: =(N13/8.16)^4.5 -> 0.050351927 | P13: 8 | Q13: 10 | R13: 9 | S13: 9 | T13: 9 | U13: 9 | V13: 9 | W13: =IF(G13>P13,"Y",IF(H13>Q13,"Y",IF(I13>R13,"Y",IF(J13>S13,"Y",IF(K13>T13,"Y",IF(L13>U13,"Y",IF(M13>V13,"Y","N"))))))) -> N | X13: =IF(W13="Y",MAX((G13-P13),(H13-Q13),(I13-R13),(J13-S13),(K13-T13),(L13-U13),(M13-V13))/10,0) -> 0 | Y13: =IF(X13<5%,"0-4.9%",IF(X13<25%,"5-25%",IF(X13<50%,"25-50%","Over 50%"))) -> 0-4.9% | Z13: Empty
A14: 10 | B14: 0.36666667 | C14: UBB789J | D14: =IF(COUNT(G14:M14)>3,10,IF(COUNT(G14:M14)>2,9,7)) -> 7 | F14: 1*2 | G14: 3.04 | H14: 6.98 | N14: =SUM(G14:M14) -> 10.02 | O14: =(N14/8.16)^4.5 -> 2.5194111 | P14: 8 | Q14: 10 | R14: 9 | S14: 9 | T14: 9 | U14: 9 | V14: 9 | W14: =IF(G14>P14,"Y",IF(H14>Q14,"Y",IF(I14>R14,"Y",IF(J14>S14,"Y",IF(K14>T14,"Y",IF(L14>U14,"Y",IF(M14>V14,"Y","N"))))))) -> N | X14: =IF(W14="Y",MAX((G14-P14),(H14-Q14),(I14-R14),(J14-S14),(K14-T14),(L14-U14),(M14-V14))/10,0) -> 0 | Y14: =IF(X14<5%,"0-4.9%",IF(X14<25%,"5-25%",IF(X14<50%,"25-50%","Over 50%"))) -> 0-4.9% | Z14: Metal/machinery
A15: 11 | B15: 0.36805556 | C15: UBA226K | D15: =IF(COUNT(G15:M15)>3,10,IF(COUNT(G15:M15)>2,9,7)) -> 7 | F15: 1*2 | G15: 1.6 | H15: 1.98 | N15: =SUM(G15:M15) -> 3.58 | O15: =(N15/8.16)^4.5 -> 0.024539624 | P15: 8 | Q15: 10 | R15: 9 | S15: 9 | T15: 9 | U15: 9 | V15: 9 | W15: =IF(G15>P15,"Y",IF(H15>Q15,"Y",IF(I15>R15,"Y",IF(J15>S15,"Y",IF(K15>T15,"Y",IF(L15>U15,"Y",IF(M15>V15,"Y","N"))))))) -> N | X15: =IF(W15="Y",MAX((G15-P15),(H15-Q15),(I15-R15),(J15-S15),(K15-T15),(L15-U15),(M15-V15))/10,0) -> 0 | Y15: =IF(X15<5%,"0-4.9%",IF(X15<25%,"5-25%",IF(X15<50%,"25-50%","Over 50%"))) -> 0-4.9% | Z15: Empty
A16: 12 | B16: 0.37430556 | C16: UBE435L | D16: =IF(COUNT(G16:M16)>3,10,IF(COUNT(G16:M16)>2,9,7)) -> 7 | F16: 1*2 | G16: 1.4 | H16: 2.16 | N16: =SUM(G16:M16) -> 3.56 | O16: =(N16/8.16)^4.5 -> 0.023928709 | P16: 8 | Q16: 10 | R16: 9 | S16: 9 | T16: 9 | U16: 9 | V16: 9 | W16: =IF(G16>P16,"Y",IF(H16>Q16,"Y",IF(I16>R16,"Y",IF(J16>S16,"Y",IF(K16>T16,"Y",IF(L16>U16,"Y",IF(M16>V16,"Y","N"))))))) -> N | X16: =IF(W16="Y",MAX((G16-P16),(H16-Q16),(I16-R16),(J16-S16),(K16-T16),(L16-U16),(M16-V16))/10,0) -> 0 | Y16: =IF(X16<5%,"0-4.9%",IF(X16<25%,"5-25%",IF(X16<50%,"25-50%","Over 50%"))) -> 0-4.9% | Z16: Agricultural produce
A17: 13 | B17: 0.37708333 | C17: UAU334H | D17: =IF(COUNT(G17:M17)>3,10,IF(COUNT(G17:M17)>2,9,7)) -> 7 | F17: 1*2 | G17: 3.48 | H17: 12.048 | N17: =SUM(G17:M17) -> 15.528 | O17: =(N17/8.16)^4.5 -> 18.088982 | P17: 8 | Q17: 10 | R17: 9 | S17: 9 | T17: 9 | U17: 9 | V17: 9 | W17: =IF(G17>P17,"Y",IF(H17>Q17,"Y",IF(I17>R17,"Y",IF(J17>S17,"Y",IF(K17>T17,"Y",IF(L17>U17,"Y",IF(M17>V17,"Y","N"))))))) -> Y | X17: =IF(W17="Y",MAX((G17-P17),(H17-Q17),(I17-R17),(J17-S17),(K17-T17),(L17-U17),(M17-V17))/10,0) -> 0.2048 | Y17: =IF(X17<5%,"0-4.9%",IF(X17<25%,"5-25%",IF(X17<50%,"25-50%","Over 50%"))) -> 5-25% | Z17: Agricultural produce
A18: 16 | B18: 0.44166667 | C18: UBD487T | D18: =IF(COUNT(G18:M18)>3,10,IF(COUNT(G18:M18)>2,9,7)) -> 7 | F18: 1*2 | G18: 2.506 | H18: 2.48 | N18: =SUM(G18:M18) -> 4.986 | O18: =(N18/8.16)^4.5 -> 0.10896312 | P18: 8 | Q18: 10 | R18: 9 | S18: 9 | T18: 9 | U18: 9 | V18: 9 | W18: =IF(G18>P18,"Y",IF(H18>Q18,"Y",IF(I18>R18,"Y",IF(J18>S18,"Y",IF(K18>T18,"Y",IF(L18>U18,"Y",IF(M18>V18,"Y","N"))))))) -> N | X18: =IF(W18="Y",MAX((G18-P18),(H18-Q18),(I18-R18),(J18-S18),(K18-T18),(L18-U18),(M18-V18))/10,0) -> 0 | Y18: =IF(X18<5%,"0-4.9%",IF(X18<25%,"5-25%",IF(X18<50%,"25-50%","Over 50%"))) -> 0-4.9% | Z18: Empty
A19: 17 | B19: 0.45416667 | D19: =IF(COUNT(G19:M19)>3,10,IF(COUNT(G19:M19)>2,9,7)) -> 7 | F19: 1*2 | G19: 1.12 | H19: 2.4 | N19: =SUM(G19:M19) -> 3.52 | O19: =(N19/8.16)^4.5 -> 0.022742399 | P19: 8 | Q19: 10 | R19: 9 | S19: 9 | T19: 9 | U19: 9 | V19: 9 | W19: =IF(G19>P19,"Y",IF(H19>Q19,"Y",IF(I19>R19,"Y",IF(J19>S19,"Y",IF(K19>T19,"Y",IF(L19>U19,"Y",IF(M19>V19,"Y","N"))))))) -> N | X19: =IF(W19="Y",MAX((G19-P19),(H19-Q19),(I19-R19),(J19-S19),(K19-T19),(L19-U19),(M19-V19))/10,0) -> 0 | Y19: =IF(X19<5%,"0-4.9%",IF(X19<25%,"5-25%",IF(X19<50%,"25-50%","Over 50%"))) -> 0-4.9% | Z19: Empty
A20: 20 | B20: 0.46527778 | C20: UAZ199F | D20: =IF(COUNT(G20:M20)>3,10,IF(COUNT(G20:M20)>2,9,7)) -> 7 | F20: 1*2 | G20: 2.7 | H20: 7.32 | N20: =SUM(G20:M20) -> 10.02 | O20: =(N20/8.16)^4.5 -> 2.5194111 | P20: 8 | Q20: 10 | R20: 9 | S20: 9 | T20: 9 | U20: 9 | V20: 9 | W20: =IF(G20>P20,"Y",IF(H20>Q20,"Y",IF(I20>R20,"Y",IF(J20>S20,"Y",IF(K20>T20,"Y",IF(L20>U20,"Y",IF(M20>V20,"Y","N"))))))) -> N | X20: =IF(W20="Y",MAX((G20-P20),(H20-Q20),(I20-R20),(J20-S20),(K20-T20),(L20-U20),(M20-V20))/10,0) -> 0 | Y20: =IF(X20<5%,"0-4.9%",IF(X20<25%,"5-25%",IF(X20<50%,"25-50%","Over 50%"))) -> 0-4.9% | Z20: Metal/machinery
A21: 21 | B21: 0.47152778 | C21: UBB688U | D21: =IF(COUNT(G21:M21)>3,10,IF(COUNT(G21:M21)>2,9,7)) -> 7 | F21: 1*2 | G21: 2.04 | H21: 2.46 | N21: =SUM(G21:M21) -> 4.5 | O21: =(N21/8.16)^4.5 -> 0.068683212 | P21: 8 | Q21: 10 | R21: 9 | S21: 9 | T21: 9 | U21: 9 | V21: 9 | W21: =IF(G21>P21,"Y",IF(H21>Q21,"Y",IF(I21>R21,"Y",IF(J21>S21,"Y",IF(K21>T21,"Y",IF(L21>U21,"Y",IF(M21>V21,"Y","N"))))))) -> N | X21: =IF(W21="Y",MAX((G21-P21),(H21-Q21),(I21-R21),(J21-S21),(K21-T21),(L21-U21),(M21-V21))/10,0) -> 0 | Y21: =IF(X21<5%,"0-4.9%",IF(X21<25%,"5-25%",IF(X21<50%,"25-50%","Over 50%"))) -> 0-4.9% | Z21: Empty
A22: 22 | B22: 0.49027778 | C22: UAW552K | D22: =IF(COUNT(G22:M22)>3,10,IF(COUNT(G22:M22)>2,9,7)) -> 7 | F22: 1*2 | G22: 8.42 | H22: 11.3 | N22: =SUM(G22:M22) -> 19.72 | O22: =(N22/8.16)^4.5 -> 53.024354 | P22: 8 | Q22: 10 | R22: 9 | S22: 9 | T22: 9 | U22: 9 | V22: 9 | W22: =IF(G22>P22,"Y",IF(H22>Q22,"Y",IF(I22>R22,"Y",IF(J22>S22,"Y",IF(K22>T22,"Y",IF(L22>U22,"Y",IF(M22>V22,"Y","N"))))))) -> Y | X22: =IF(W22="Y",MAX((G22-P22),(H22-Q22),(I22-R22),(J22-S22),(K22-T22),(L22-U22),(M22-V22))/10,0) -> 0.13 | Y22: =IF(X22<5%,"0-4.9%",IF(X22<25%,"5-25%",IF(X22<50%,"25-50%","Over 50%"))) -> 5-25% | Z22: Agricultural produce
A23: 23 | B23: 0.5 | C23: UAX247U | D23: =IF(COUNT(G23:M23)>3,10,IF(COUNT(G23:M23)>2,9,7)) -> 7 | F23: 1*2 | G23: 1.45 | H23: 1.52 | N23: =SUM(G23:M23) -> 2.97 | O23: =(N23/8.16)^4.5 -> 0.010587619 | P23: 8 | Q23: 10 | R23: 9 | S23: 9 | T23: 9 | U23: 9 | V23: 9 | W23: =IF(G23>P23,"Y",IF(H23>Q23,"Y",IF(I23>R23,"Y",IF(J23>S23,"Y",IF(K23>T23,"Y",IF(L23>U23,"Y",IF(M23>V23,"Y","N"))))))) -> N | X23: =IF(W23="Y",MAX((G23-P23),(H23-Q23),(I23-R23),(J23-S23),(K23-T23),(L23-U23),(M23-V23))/10,0) -> 0 | Y23: =IF(X23<5%,"0-4.9%",IF(X23<25%,"5-25%",IF(X23<50%,"25-50%","Over 50%"))) -> 0-4.9% | Z23: Empty
A24: 24 | B24: 0.52083333 | C24: UBB472P | D24: =IF(COUNT(G24:M24)>3,10,IF(COUNT(G24:M24)>2,9,7)) -> 7 | F24: 1*2 | G24: 2.206 | H24: 4.512 | N24: =SUM(G24:M24) -> 6.718 | O24: =(N24/8.16)^4.5 -> 0.4168447 | P24: 8 | Q24: 10 | R24: 9 | S24: 9 | T24: 9 | U24: 9 | V24: 9 | W24: =IF(G24>P24,"Y",IF(H24>Q24,"Y",IF(I24>R24,"Y",IF(J24>S24,"Y",IF(K24>T24,"Y",IF(L24>U24,"Y",IF(M24>V24,"Y","N"))))))) -> N | X24: =IF(W24="Y",MAX((G24-P24),(H24-Q24),(I24-R24),(J24-S24),(K24-T24),(L24-U24),(M24-V24))/10,0) -> 0 | Y24: =IF(X24<5%,"0-4.9%",IF(X24<25%,"5-25%",IF(X24<50%,"25-50%","Over 50%"))) -> 0-4.9% | Z24: Agricultural produce
A25: 25 | B25: 0.047916667 | C25: UAM547L | D25: =IF(COUNT(G25:M25)>3,10,IF(COUNT(G25:M25)>2,9,7)) -> 7 | F25: 1*2 | G25: 7.56 | H25: 9 | N25: =SUM(G25:M25) -> 16.56 | O25: =(N25/8.16)^4.5 -> 24.163831 | P25: 8 | Q25: 10 | R25: 9 | S25: 9 | T25: 9 | U25: 9 | V25: 9 | W25: =IF(G25>P25,"Y",IF(H25>Q25,"Y",IF(I25>R25,"Y",IF(J25>S25,"Y",IF(K25>T25,"Y",IF(L25>U25,"Y",IF(M25>V25,"Y","N"))))))) -> N | X25: =IF(W25="Y",MAX((G25-P25),(H25-Q25),(I25-R25),(J25-S25),(K25-T25),(L25-U25),(M25-V25))/10,0) -> 0 | Y25: =IF(X25<5%,"0-4.9%",IF(X25<25%,"5-25%",IF(X25<50%,"25-50%","Over 50%"))) -> 0-4.9% | Z25: Agricultural produce
A26: 27 | B26: 0.125 | C26: UAN961D | D26: =IF(COUNT(G26:M26)>3,10,IF(COUNT(G26:M26)>2,9,7)) -> 7 | F26: 1*2 | G26: 1.4 | H26: 2.3 | N26: =SUM(G26:M26) -> 3.7 | O26: =(N26/8.16)^4.5 -> 0.028464401 | P26: 8 | Q26: 10 | R26: 9 | S26: 9 | T26: 9 | U26: 9 | V26: 9 | W26: =IF(G26>P26,"Y",IF(H26>Q26,"Y",IF(I26>R26,"Y",IF(J26>S26,"Y",IF(K26>T26,"Y",IF(L26>U26,"Y",IF(M26>V26,"Y","N"))))))) -> N | X26: =IF(W26="Y",MAX((G26-P26),(H26-Q26),(I26-R26),(J26-S26),(K26-T26),(L26-U26),(M26-V26))/10,0) -> 0 | Y26: =IF(X26<5%,"0-4.9%",IF(X26<25%,"5-25%",IF(X26<50%,"25-50%","Over 50%"))) -> 0-4.9% | Z26: Empty
A27: 28 | B27: 0.13888889 | C27: UBF285J | D27: =IF(COUNT(G27:M27)>3,10,IF(COUNT(G27:M27)>2,9,7)) -> 7 | F27: 1*2 | G27: 2.22 | H27: 1.5 | N27: =SUM(G27:M27) -> 3.72 | O27: =(N27/8.16)^4.5 -> 0.029163357 | P27: 8 | Q27: 10 | R27: 9 | S27: 9 | T27: 9 | U27: 9 | V27: 9 | W27: =IF(G27>P27,"Y",IF(H27>Q27,"Y",IF(I27>R27,"Y",IF(J27>S27,"Y",IF(K27>T27,"Y",IF(L27>U27,"Y",IF(M27>V27,"Y","N"))))))) -> N | X27: =IF(W27="Y",MAX((G27-P27),(H27-Q27),(I27-R27),(J27-S27),(K27-T27),(L27-U27),(M27-V27))/10,0) -> 0 | Y27: =IF(X27<5%,"0-4.9%",IF(X27<25%,"5-25%",IF(X27<50%,"25-50%","Over 50%"))) -> 0-4.9% | Z27: Empty
A28: 29 | B28: 0.14722222 | C28: UAP216H | D28: =IF(COUNT(G28:M28)>3,10,IF(COUNT(G28:M28)>2,9,7)) -> 7 | F28: 1*2 | G28: 6 | H28: 12.8 | N28: =SUM(G28:M28) -> 18.8 | O28: =(N28/8.16)^4.5 -> 42.766588 | P28: 8 | Q28: 10 | R28: 9 | S28: 9 | T28: 9 | U28: 9 | V28: 9 | W28: =IF(G28>P28,"Y",IF(H28>Q28,"Y",IF(I28>R28,"Y",IF(J28>S28,"Y",IF(K28>T28,"Y",IF(L28>U28,"Y",IF(M28>V28,"Y","N"))))))) -> Y | X28: =IF(W28="Y",MAX((G28-P28),(H28-Q28),(I28-R28),(J28-S28),(K28-T28),(L28-U28),(M28-V28))/10,0) -> 0.28 | Y28: =IF(X28<5%,"0-4.9%",IF(X28<25%,"5-25%",IF(X28<50%,"25-50%","Over 50%"))) -> 25-50% | Z28: Agricultural produce
A29: 1 | B29: 0.30833333 | C29: UAZ665H | D29: =IF(COUNT(G29:M29)>3,10,IF(COUNT(G29:M29)>2,9,7)) -> 7 | F29: 1*2 | G29: 3.4 | H29: 4.9 | N29: =SUM(G29:M29) -> 8.3 | O29: =(N29/8.16)^4.5 -> 1.0795573 | P29: 8 | Q29: 10 | R29: 9 | S29: 9 | T29: 9 | U29: 9 | V29: 9 | W29: =IF(G29>P29,"Y",IF(H29>Q29,"Y",IF(I29>R29,"Y",IF(J29>S29,"Y",IF(K29>T29,"Y",IF(L29>U29,"Y",IF(M29>V29,"Y","N"))))))) -> N | X29: =IF(W29="Y",MAX((G29-P29),(H29-Q29),(I29-R29),(J29-S29),(K29-T29),(L29-U29),(M29-V29))/10,0) -> 0 | Y29: =IF(X29<5%,"0-4.9%",IF(X29<25%,"5-25%",IF(X29<50%,"25-50%","Over 50%"))) -> 0-4.9% | Z29: Agricultural produce
A30: 2 | B30: 0.31180556 | C30: UAB132X | D30: =IF(COUNT(G30:M30)>3,10,IF(COUNT(G30:M30)>2,9,7)) -> 7 | F30: 1*2 | G30: 2.51 | H30: 4.95 | N30: =SUM(G30:M30) -> 7.46 | O30: =(N30/8.16)^4.5 -> 0.66791164 | P30: 8 | Q30: 10 | R30: 9 | S30: 9 | T30: 9 | U30: 9 | V30: 9 | W30: =IF(G30>P30,"Y",IF(H30>Q30,"Y",IF(I30>R30,"Y",IF(J30>S30,"Y",IF(K30>T30,"Y",IF(L30>U30,"Y",IF(M30>V30,"Y","N"))))))) -> N | X30: =IF(W30="Y",MAX((G30-P30),(H30-Q30),(I30-R30),(J30-S30),(K30-T30),(L30-U30),(M30-V30))/10,0) -> 0 | Y30: =IF(X30<5%,"0-4.9%",IF(X30<25%,"5-25%",IF(X30<50%,"25-50%","Over 50%"))) -> 0-4.9% | Z30: Household retail products
A31: 3 | B31: 0.3125 | C31: UAZ733Y | D31: =IF(COUNT(G31:M31)>3,10,IF(COUNT(G31:M31)>2,9,7)) -> 7 | F31: 1*2 | G31: 3.37 | H31: 5.71 | N31: =SUM(G31:M31) -> 9.08 | O31: =(N31/8.16)^4.5 -> 1.6172628 | P31: 8 | Q31: 10 | R31: 9 | S31: 9 | T31: 9 | U31: 9 | V31: 9 | W31: =IF(G31>P31,"Y",IF(H31>Q31,"Y",IF(I31>R31,"Y",IF(J31>S31,"Y",IF(K31>T31,"Y",IF(L31>U31,"Y",IF(M31>V31,"Y","N"))))))) -> N | X31: =IF(W31="Y",MAX((G31-P31),(H31-Q31),(I31-R31),(J31-S31),(K31-T31),(L31-U31),(M31-V31))/10,0) -> 0 | Y31: =IF(X31<5%,"0-4.9%",IF(X31<25%,"5-25%",IF(X31<50%,"25-50%","Over 50%"))) -> 0-4.9% | Z31: Empty
... A66: 16 | B66: 0.18125 | C66: UAP578R | D66: =IF(COUNT(G66:M66)>3,10,IF(COUNT(G66:M66)>2,9,7)) -> 7 | F66: 1*2 | G66: 3.64 | H66: 9.34 | N66: =SUM(G66:M66) -> 12.98 | O66: =(N66/8.16)^4.5 -> 8.0747745 | P66: 8 | Q66: 10 | R66: 9 | S66: 9 | T66: 9 | U66: 9 | V66: 9 | W66: =IF(G66>P66,"Y",IF(H66>Q66,"Y",IF(I66>R66,"Y",IF(J66>S66,"Y",IF(K66>T66,"Y",IF(L66>U66,"Y",IF(M66>V66,"Y","N"))))))) -> N | X66: =IF(W66="Y",MAX((G66-P66),(H66-Q66),(I66-R66),(J66-S66),(K66-T66),(L66-U66),(M66-V66))/10,0) -> 0 | Y66: =IF(X66<5%,"0-4.9%",IF(X66<25%,"5-25%",IF(X66<50%,"25-50%","Over 50%"))) -> 0-4.9% | Z66: Fuels
A67: 7 | B67: 0.36875 | C67: UAZ896U | D67: =IF(COUNT(G67:M67)>3,10,IF(COUNT(G67:M67)>2,9,7)) -> 9 | F67: 1*2*2 | G67: 7.36 | H67: 12.96 | I67: 11.12 | N67: =SUM(G67:M67) -> 31.44 | O67: =(N67/8.16)^4.5 -> 432.57927 | P67: 8 | Q67: 10 | R67: 9 | S67: 9 | T67: 9 | U67: 9 | V67: 9 | W67: =IF(G67>P67,"Y",IF(H67>Q67,"Y",IF(I67>R67,"Y",IF(J67>S67,"Y",IF(K67>T67,"Y",IF(L67>U67,"Y",IF(M67>V67,"Y","N"))))))) -> Y | X67: =IF(W67="Y",MAX((G67-P67),(H67-Q67),(I67-R67),(J67-S67),(K67-T67),(L67-U67),(M67-V67))/10,0) -> 0.296 | Y67: =IF(X67<5%,"0-4.9%",IF(X67<25%,"5-25%",IF(X67<50%,"25-50%","Over 50%"))) -> 25-50% | Z67: Household retail products
A68: 17 | B68: 0.19444444 | C68: UAK394E | D68: =IF(COUNT(G68:M68)>3,10,IF(COUNT(G68:M68)>2,9,7)) -> 9 | F68: 1*2*2 | G68: 3.75 | H68: 4.84 | I68: 4.94 | N68: =SUM(G68:M68) -> 13.53 | O68: =(N68/8.16)^4.5 -> 9.7327232 | P68: 8 | Q68: 10 | R68: 9 | S68: 9 | T68: 9 | U68: 9 | V68: 9 | W68: =IF(G68>P68,"Y",IF(H68>Q68,"Y",IF(I68>R68,"Y",IF(J68>S68,"Y",IF(K68>T68,"Y",IF(L68>U68,"Y",IF(M68>V68,"Y","N"))))))) -> N | X68: =IF(W68="Y",MAX((G68-P68),(H68-Q68),(I68-R68),(J68-S68),(K68-T68),(L68-U68),(M68-V68))/10,0) -> 0 | Y68: =IF(X68<5%,"0-4.9%",IF(X68<25%,"5-25%",IF(X68<50%,"25-50%","Over 50%"))) -> 0-4.9% | Z68: Agricultural produce
A69: 4 | B69: 0.325 | C69: KBT049Z | D69: =IF(COUNT(G69:M69)>3,10,IF(COUNT(G69:M69)>2,9,7)) -> 10 | F69: 1*22*22 | G69: 4.7 | H69: 8 | I69: 4 | J69: 10.12 | K69: 10.1 | N69: =SUM(G69:M69) -> 36.92 | O69: =(N69/8.16)^4.5 -> 891.3985 | P69: 8 | Q69: 10 | R69: 9 | S69: 9 | T69: 9 | U69: 9 | V69: 9 | W69: =IF(G69>P69,"Y",IF(H69>Q69,"Y",IF(I69>R69,"Y",IF(J69>S69,"Y",IF(K69>T69,"Y",IF(L69>U69,"Y",IF(M69>V69,"Y","N"))))))) -> Y | X69: =IF(W69="Y",MAX((G69-P69),(H69-Q69),(I69-R69),(J69-S69),(K69-T69),(L69-U69),(M69-V69))/10,0) -> 0.112 | Y69: =IF(X69<5%,"0-4.9%",IF(X69<25%,"5-25%",IF(X69<50%,"25-50%","Over 50%"))) -> 5-25% | Z69: Agricultural produce
A70: 9 | B70: 0.36458333 | C70: UBD295U | D70: =IF(COUNT(G70:M70)>3,10,IF(COUNT(G70:M70)>2,9,7)) -> 10 | F70: 1*22*222 | G70: 5.74 | H70: 9.52 | I70: 8.28 | J70: 6.04 | K70: 7.4 | L70: 6.98 | N70: =SUM(G70:M70) -> 43.96 | O70: =(N70/8.16)^4.5 -> 1955.032 | P70: 8 | Q70: 10 | R70: 9 | S70: 9 | T70: 9 | U70: 9 | V70: 9 | W70: =IF(G70>P70,"Y",IF(H70>Q70,"Y",IF(I70>R70,"Y",IF(J70>S70,"Y",IF(K70>T70,"Y",IF(L70>U70,"Y",IF(M70>V70,"Y","N"))))))) -> N | X70: =IF(W70="Y",MAX((G70-P70),(H70-Q70),(I70-R70),(J70-S70),(K70-T70),(L70-U70),(M70-V70))/10,0) -> 0 | Y70: =IF(X70<5%,"0-4.9%",IF(X70<25%,"5-25%",IF(X70<50%,"25-50%","Over 50%"))) -> 0-4.9% | Z70: Construction Material
A71: 14 | B71: 0.38402778 | C71: KBP786U | D71: =IF(COUNT(G71:M71)>3,10,IF(COUNT(G71:M71)>2,9,7)) -> 10 | F71: 1*22*222 | G71: 5.8 | H71: 6 | I71: 9.8 | J71: 10 | K71: 11 | L71: 7 | N71: =SUM(G71:M71) -> 49.6 | O71: =(N71/8.16)^4.5 -> 3365.5948 | P71: 8 | Q71: 10 | R71: 9 | S71: 9 | T71: 9 | U71: 9 | V71: 9 | W71: =IF(G71>P71,"Y",IF(H71>Q71,"Y",IF(I71>R71,"Y",IF(J71>S71,"Y",IF(K71>T71,"Y",IF(L71>U71,"Y",IF(M71>V71,"Y","N"))))))) -> Y | X71: =IF(W71="Y",MAX((G71-P71),(H71-Q71),(I71-R71),(J71-S71),(K71-T71),(L71-U71),(M71-V71))/10,0) -> 0.2 | Y71: =IF(X71<5%,"0-4.9%",IF(X71<25%,"5-25%",IF(X71<50%,"25-50%","Over 50%"))) -> 5-25% | Z71: Agricultural produce
A72: 15 | B72: 0.41388889 | C72: KBW043H | D72: =IF(COUNT(G72:M72)>3,10,IF(COUNT(G72:M72)>2,9,7)) -> 10 | F72: 1*22*222 | G72: 5.56 | H72: 12.96 | I72: 13.2 | J72: 8.2 | K72: 4.6 | L72: 4.4 | N72: =SUM(G72:M72) -> 48.92 | O72: =(N72/8.16)^4.5 -> 3162.8843 | P72: 8 | Q72: 10 | R72: 9 | S72: 9 | T72: 9 | U72: 9 | V72: 9 | W72: =IF(G72>P72,"Y",IF(H72>Q72,"Y",IF(I72>R72,"Y",IF(J72>S72,"Y",IF(K72>T72,"Y",IF(L72>U72,"Y",IF(M72>V72,"Y","N"))))))) -> Y | X72: =IF(W72="Y",MAX((G72-P72),(H72-Q72),(I72-R72),(J72-S72),(K72-T72),(L72-U72),(M72-V72))/10,0) -> 0.42 | Y72: =IF(X72<5%,"0-4.9%",IF(X72<25%,"5-25%",IF(X72<50%,"25-50%","Over 50%"))) -> 25-50% | Z72: Empty
A73: 18 | B73: 0.45833333 | C73: UBB073U | D73: =IF(COUNT(G73:M73)>3,10,IF(COUNT(G73:M73)>2,9,7)) -> 10 | F73: 1*22*222 | G73: 3.82 | H73: 4 | I73: 5.36 | J73: 6 | K73: 5.4 | L73: 5.57 | N73: =SUM(G73:M73) -> 30.15 | O73: =(N73/8.16)^4.5 -> 358.25083 | P73: 8 | Q73: 10 | R73: 9 | S73: 9 | T73: 9 | U73: 9 | V73: 9 | W73: =IF(G73>P73,"Y",IF(H73>Q73,"Y",IF(I73>R73,"Y",IF(J73>S73,"Y",IF(K73>T73,"Y",IF(L73>U73,"Y",IF(M73>V73,"Y","N"))))))) -> N | X73: =IF(W73="Y",MAX((G73-P73),(H73-Q73),(I73-R73),(J73-S73),(K73-T73),(L73-U73),(M73-V73))/10,0) -> 0 | Y73: =IF(X73<5%,"0-4.9%",IF(X73<25%,"5-25%",IF(X73<50%,"25-50%","Over 50%"))) -> 0-4.9% | Z73: Empty
A74: 19 | B74: 0.46180556 | C74: UBA059Q | D74: =IF(COUNT(G74:M74)>3,10,IF(COUNT(G74:M74)>2,9,7)) -> 10 | F74: 1*22*222 | G74: 3.79 | H74: 3.01 | I74: 5.6 | J74: 5.36 | K74: 4.22 | L74: 5.06 | N74: =SUM(G74:M74) -> 27.04 | O74: =(N74/8.16)^4.5 -> 219.49487 | P74: 8 | Q74: 10 | R74: 9 | S74: 9 | T74: 9 | U74: 9 | V74: 9 | W74: =IF(G74>P74,"Y",IF(H74>Q74,"Y",IF(I74>R74,"Y",IF(J74>S74,"Y",IF(K74>T74,"Y",IF(L74>U74,"Y",IF(M74>V74,"Y","N"))))))) -> N | X74: =IF(W74="Y",MAX((G74-P74),(H74-Q74),(I74-R74),(J74-S74),(K74-T74),(L74-U74),(M74-V74))/10,0) -> 0 | Y74: =IF(X74<5%,"0-4.9%",IF(X74<25%,"5-25%",IF(X74<50%,"25-50%","Over 50%"))) -> 0-4.9% | Z74: Agricultural produce
...

Sheet Graphs
B1: AXLE LOAD DATA ANALYSIS (KAMPALA - HOIMA HIGHWAY)
A3: Vehicle Categories | L3: Load Description
B4: Truck Type | C4: Kampala-Hoima | D4: Hoima-Kampala | E4: Both Directions | L4: Category | M4: Kampala-Hoima | N4: Hoima-Kampala
A5: 7 | B5: Light/Medium Trucks | C5: =COUNTIF('Kla-Hoima'!$D$7:$D$500,7) -> 116 | D5: =COUNTIF('Hoima-Kla'!$D$7:$D$500,7) -> 60 | E5: =SUM(C5:D5) -> 176 | L5: Agricultural produce | M5: =COUNTIF('Kla-Hoima'!$Z$7:$Z$230,L5)/$M$16 -> 0.390625 | N5: =COUNTIF('Hoima-Kla'!$Z$7:$Z$187,L5)/$N$16 -> 0.33333333
A6: 9 | B6: Heavy Trucks | C6: =COUNTIF('Kla-Hoima'!$D$7:$D$500,9) -> 3 | D6: =COUNTIF('Hoima-Kla'!$D$7:$D$500,9) -> 2 | E6: =SUM(C6:D6) -> 5 | L6: Perishable | M6: =COUNTIF('Kla-Hoima'!$Z$7:$Z$230,L6)/$M$16 -> 0 | N6: =COUNTIF('Hoima-Kla'!$Z$7:$Z$187,L6)/$N$16 -> 0
A7: 10 | B7: Truck/Trailer | C7: =COUNTIF('Kla-Hoima'!$D$7:$D$500,10) -> 9 | D7: =COUNTIF('Hoima-Kla'!$D$7:$D$500,10) -> 7 | E7: =SUM(C7:D7) -> 16 | L7: Construction Material | M7: =COUNTIF('Kla-Hoima'!$Z$7:$Z$230,L7)/$M$16 -> 0.0859375 | N7: =COUNTIF('Hoima-Kla'!$Z$7:$Z$187,L7)/$N$16 -> 0.043478261
B8: Totals | C8: =SUM(C5:C7) -> 128 | D8: =SUM(D5:D7) -> 69 | E8: =SUM(E5:E7) -> 197 | L8: Metal/machinery | M8: =COUNTIF('Kla-Hoima'!$Z$7:$Z$230,L8)/$M$16 -> 0 | N8: =COUNTIF('Hoima-Kla'!$Z$7:$Z$187,L8)/$N$16 -> 0.11594203
L9: Forestry products | M9: =COUNTIF('Kla-Hoima'!$Z$7:$Z$230,L9)/$M$16 -> 0 | N9: =COUNTIF('Hoima-Kla'!$Z$7:$Z$187,L9)/$N$16 -> 0
L10: Fuels | M10: =COUNTIF('Kla-Hoima'!$Z$7:$Z$230,L10)/$M$16 -> 0.046875 | N10: =COUNTIF('Hoima-Kla'!$Z$7:$Z$187,L10)/$N$16 -> 0.014492754
L11: Chemical Products | M11: =COUNTIF('Kla-Hoima'!$Z$7:$Z$230,L11)/$M$16 -> 0 | N11: =COUNTIF('Hoima-Kla'!$Z$7:$Z$187,L11)/$N$16 -> 0
L12: Livestock | M12: =COUNTIF('Kla-Hoima'!$Z$7:$Z$230,L12)/$M$16 -> 0.0078125 | N12: =COUNTIF('Hoima-Kla'!$Z$7:$Z$187,L12)/$N$16 -> 0
L13: Household retail products | M13: =COUNTIF('Kla-Hoima'!$Z$7:$Z$230,L13)/$M$16 -> 0.109375 | N13: =COUNTIF('Hoima-Kla'!$Z$7:$Z$187,L13)/$N$16 -> 0.13043478
L14: Empty | M14: =COUNTIF('Kla-Hoima'!$Z$7:$Z$230,L14)/$M$16 -> 0.34375 | N14: =COUNTIF('Hoima-Kla'!$Z$7:$Z$187,L14)/$N$16 -> 0.34782609
L15: Others | M15: =COUNTIF('Kla-Hoima'!$Z$7:$Z$230,L15)/$M$16 -> 0.015625 | N15: =COUNTIF('Hoima-Kla'!$Z$7:$Z$187,L15)/$N$16 -> 0.014492754
L16: Total | M16: =C8 -> 128 | N16: =D8 -> 69
A27: Average Total Loading (Tonnes)
B28: Truck Type | C28: Kampala-Hoima | D28: Hoima-Kampala | E28: Both Directions | F28: Limit
A29: 7 | B29: Light/Medium Trucks | C29: =AVERAGEIF('Kla-Hoima'!$D$7:$D$230,Graphs!A29,'Kla-Hoima'!$N$7:$N$230) -> 10.007767 | D29: =AVERAGEIF('Hoima-Kla'!$D$7:$D$187,Graphs!A29,'Hoima-Kla'!$N$7:$N$187) -> 8.6332667 | E29: =AVERAGE(C29:D29) -> 9.320517 | F29: 18
A30: 9 | B30: Heavy Trucks | C30: =AVERAGEIF('Kla-Hoima'!$D$7:$D$230,Graphs!A30,'Kla-Hoima'!$N$7:$N$230) -> 7.6606667 | D30: =AVERAGEIF('Hoima-Kla'!$D$7:$D$187,Graphs!A30,'Hoima-Kla'!$N$7:$N$187) -> 22.485 | E30: =AVERAGE(C30:D30) -> 15.072833 | F30: 27
A31: 10 | B31: Truck/Trailer | C31: =AVERAGEIF('Kla-Hoima'!$D$7:$D$230,Graphs!A31,'Kla-Hoima'!$N$7:$N$230) -> 32.983 | D31: =AVERAGEIF('Hoima-Kla'!$D$7:$D$187,Graphs!A31,'Hoima-Kla'!$N$7:$N$187) -> 38.847143 | E31: =AVERAGE(C31:D31) -> 35.915071 | F31: 54
B32: Totals
L39: Proportion of Overloaded Trucks
M40: Truck Type | N40: Kampala-Hoima | O40: Hoima-Kampala | P40: Both Directions
M41: 0-4.9% | N41: =COUNTIF('Kla-Hoima'!$Y$7:$Y$230,M41)/$N$45 -> 0.734375 | O41: =COUNTIF('Hoima-Kla'!$Y$7:$Y$187,M41)/$O$45 -> 0.8115942 | P41: =AVERAGE(N41:O41) -> 0.7729846
M42: 5-25% | N42: =COUNTIF('Kla-Hoima'!$Y$7:$Y$230,M42)/$N$45 -> 0.1015625 | O42: =COUNTIF('Hoima-Kla'!$Y$7:$Y$187,M42)/$O$45 -> 0.086956522 | P42: =AVERAGE(N42:O42) -> 0.094259511
M43: 25-50% | N43: =COUNTIF('Kla-Hoima'!$Y$7:$Y$230,M43)/$N$45 -> 0.109375 | O43: =COUNTIF('Hoima-Kla'!$Y$7:$Y$187,M43)/$O$45 -> 0.072463768 | P43: =AVERAGE(N43:O43) -> 0.090919384
M44: Over 50% | N44: =COUNTIF('Kla-Hoima'!$Y$7:$Y$230,M44)/$N$45 -> 0.0546875 | O44: =COUNTIF('Hoima-Kla'!$Y$7:$Y$187,M44)/$O$45 -> 0.028985507 | P44: =AVERAGE(N44:O44) -> 0.041836504
N45: =C8 -> 128 | O45: =D8 -> 69
A55: Proportion of Overloaded Trucks
B56: Truck Type | C56: Kampala-Hoima | D56: Hoima-Kampala | E56: Both Directions
A57: 7 | B57: Light/Medium Trucks | C57: =COUNTIF('Kla-Hoima'!W7:W122,"Y")/C5 -> 0.25 | D57: =COUNTIF('Hoima-Kla'!W7:W66,"Y")/D5 -> 0.13333333 | E57: =AVERAGE(C57:D57) -> 0.19166667
A58: 9 | B58: Heavy Trucks | C58: =COUNTIF('Kla-Hoima'!W123:W125,"Y")/C6 -> 0 | D58: =COUNTIF('Hoima-Kla'!W67:W68,"y")/D6 -> 0.5 | E58: =AVERAGE(C58:D58) -> 0.25
A59: 10 | B59: Truck/Trailer | C59: =COUNTIF('Kla-Hoima'!W126:W230,"Y")/C7 -> 0.66666667 | D59: =COUNTIF('Hoima-Kla'!W69:W75,"Y")/D7 -> 0.57142857 | E59: =AVERAGE(C59:D59) -> 0.61904762
B60: Overall | C60: =COUNTIF('Kla-Hoima'!W7:W230,"Y")/C8 -> 0.2734375 | D60: =COUNTIF('Hoima-Kla'!W7:W75,"Y")/D8 -> 0.1884058

Sheet KEY
I1: Axle Configuration
A2: TRUCK TYPES | I2: 2-Axles | J2: 2-Axles | K2: 3-Axle | L2: 4-Axle | M2: 5-Axle | N2: 6-Axle | O2: 7-Axle
A4: 7 | B4: LIGHT SINGLE UNIT TRUCK-DYNAS AND TRACTORS(2 axles) | I4: 1.1 | J4: 1.2
A5: 8 | B5: LIGHT/MEDIUM SINGLE UNIT TRUCKS (3 axles) | K5: 1.22
A6: 9 | B6: MEDIUM - SINGLE UNIT TRUCKS-LORRIES, FUSOS (4 axles) | L6: 1.1-22
L7: 1.222
A10: 10 | B10: HEAVY TRUCK RIGID (5 axles) | M10: 1.1-222
M11: 1.2-222
M12: 1.22-22
A13: 11 | B13: TRUCK TRAILER AND SEMI TRAILER (6 axles) | N13: 1.12-222
N14: 1.22-222
N15: 1.22+1-22
N16: 1.22+2-22
N17: 1.21-222
N18: 1.22-111
A19: 12 | B19: TRUCK TRAILER TYPE 2 (7 axles) | O19: 1.11+11-11
O20: 1.22+22-22
O21: 1.12+11-22
B29: 7. Light Truck
B30: 8. Medium Truck
B31: 9. Heavy truck
B32: 10. Truck Trailer
B35: 1*1 | C35: Light Truck | D35: 7 | E35: 18
B36: 1*2 | C36: Light Truck | D36: 7 | E36: 18
B37: 1*21 | C37: Medium Truck | D37: 8 | E37: 26
B38: 1*22 | C38: Heavy Truck | D38: 9 | E38: 26
B39: 1*2*2 | C39: Truck Trailer | D39: 10 | E39: 46
B40: 1*2*22 | C40: Truck Trailer | D40: 10 | E40: 46
B41: 1*22-22 | C41: Truck Trailer | D41: 10 | E41: 46
B42: 1*2*2*2 | C42: Truck Trailer | D42: 10 | E42: 46
B43: 1*22*2*22 | C43: Truck Trailer | D43: 10 | E43: 46
B44: 11*22 | C44: Heavy Truck | D44: 9 | E44: 34

Sheet Desc
B1: Category | C1: Comment
A2: 1 | B2: Food crop | C2: (Maize,rice,wheat etc)
A3: 2 | B3: Cash Crops | C3: (coffee,tea etc)
A4: 3 | B4: Perishable | C4: (fish,milk,tea etc)
A5: 4 | B5: Construction Material | C5: (cement, gravel,stones,gravel,pipes)
A6: 5 | B6: Metal/machinery
A7: 6 | B7: Forestry products | C7: (timber & charcoal)
A8: 7 | B8: Fuels | C8: (any petroleum products)
A9: 8 | B9: Chemical Products | C9: (fertilizer,paints)
A10: 9 | B10: Livestock | C10: (cows,goats,camel etc)
A11: 10 | B11: Household retail products | C11: (beverage,oil,sugar,salt,flour)
A12: 11 | B12: Empty
A13: 12 | B13: Others (Pl specify)
A14: 4
