Workbook

Sheet DAY1
A2: AXLE LOAD SURVEY FORM
A3: Date: | C3: 43766 | D3: Station Name: | E3: Rubirizi | G3: Direction: | H3: Mbarara-Kasese
A5: S/No. | B5: Time | C5: Reg. Number | D5: Vehicle Type | E5: Number of Axles | F5: Axle Configuration | G5: TONNES | N5: Total (Tonnes) | O5: Total (ESA's) | P5: COMMENTS
G6: AXLE 1 | H6: AXLE 2 | I6: AXLE 3 | J6: AXLE 4 | K6: AXLE 5 | L6: AXLE 6 | M6: AXLE 7
A7: 1 | B7: 0.40138889 | C7: UAW 983V | D7: 7 | E7: 2 | F7: 1*2 | G7: 4.6 | H7: 12.3 | I7: 0 | J7: 0 | K7: 0 | L7: 0 | M7: 0 | P7: GOODS
A8: =A7+1 -> 2 | B8: 0.40277778 | C8: UBD 480T | D8: 9 | E8: 4 | F8: 11*22 | G8: 5.95 | H8: 5.5 | I8: 9.45 | J8: 6.5 | K8: 0 | L8: 0 | M8: 0 | P8: BEER
A9: =A8+1 -> 3 | B9: 0.40486111 | C9: UBB 322P | D9: 7 | E9: 2 | F9: 1*2 | G9: 5.35 | H9: 9.75 | I9: 0 | J9: 0 | K9: 0 | L9: 0 | M9: 0 | P9: FISH
A10: =A9+1 -> 4 | B10: 0.40555556 | C10: UAV 799U | D10: 7 | E10: 2 | F10: 1*2 | G10: 5.1 | H10: 7.9 | I10: 0 | J10: 0 | K10: 0 | L10: 0 | M10: 0 | P10: FISH
A11: =A10+1 -> 5 | B11: 0.50486111 | C11: UAM 930B | D11: 10 | E11: 5 | F11: 11*222 | G11: 7.15 | H11: 4.95 | I11: 8.3 | J11: 5.5 | K11: 2.3 | L11: 0 | M11: 0 | P11: GOODS
A12: =A11+1 -> 6 | B12: 0.53541667 | C12: UAV 916C | D12: 10 | E12: 5 | F12: 11*222 | G12: 5.1 | H12: 5.3 | I12: 10 | J12: 6 | K12: 4 | L12: 0 | M12: 0 | P12: GOODS
A13: =A12+1 -> 7 | B13: 0.54722222 | C13: UBA 297T | D13: 7 | E13: 2 | F13: 1*2 | G13: 3.65 | H13: 9.5 | I13: 0 | J13: 0 | K13: 0 | L13: 0 | M13: 0 | P13: CATTLE
A14: =A13+1 -> 8 | B14: 0.55555556 | C14: UAQ 162Q | D14: 7 | E14: 2 | F14: 1*2 | G14: 3.9 | H14: 7.45 | I14: 0 | J14: 0 | K14: 0 | L14: 0 | M14: 0 | P14: SODA
A15: =A14+1 -> 9 | B15: 0.55694444 | C15: UBD 881D | D15: 7 | E15: 7 | F15: 1*2 | G15: 2.7 | H15: 5.75 | I15: 0 | J15: 0 | K15: 0 | L15: 0 | M15: 0 | P15: TIMBER
A16: =A15+1 -> 10 | B16: 0.6125 | C16: KCC 805S | D16: 10 | E16: 6 | F16: 1*22-222 | G16: 5.25 | H16: 6.85 | I16: 6.85 | J16: 6.5 | K16: 7.35 | L16: 7.55 | M16: 0 | P16: GOODS
A17: =A16+1 -> 11 | B17: 0.61388889 | C17: KCQ 784Z | D17: 10 | E17: 6 | F17: 1*12-222 | G17: 5.4 | H17: 4.8 | I17: 7.85 | J17: 8.3 | K17: 8.1 | L17: 8.35 | M17: 0 | P17: IRON SHEETS
A18: =A17+1 -> 12 | B18: 0.61736111 | C18: KBS 134K | D18: 10 | E18: 6 | F18: 1*12-222 | G18: 5.6 | H18: 5.95 | I18: 9.1 | J18: 7.45 | K18: 7.45 | L18: 6.3 | M18: 0 | P18: IRON SHEETS
A19: =A18+1 -> 13 | B19: 0.64166667 | C19: UBB 621H | D19: 7 | E19: 2 | F19: 1*2 | G19: 4.7 | H19: 10.9 | I19: 0 | J19: 0 | K19: 0 | L19: 0 | M19: 0 | P19: GOODS
... A22: =A21+1 -> 16 | B22: 0.74444444 | C22: KBK 289K | D22: 10 | E22: 6 | F22: 1*22-222 | G22: 5.15 | H22: 8.6 | I22: 6.55 | J22: 8.6 | K22: 6.65 | L22: 5.6 | M22: 0 | P22: IRON SHEETS
H23: KASESE - MBARARA
A24: =A23+1 -> 1 | B24: 0.38263889 | C24: RAC 404Y | D24: 10 | E24: 6 | F24: 1*12-111 | G24: 5.65 | H24: 6.55 | I24: 9.9 | J24: 6.95 | K24: 8.15 | L24: 8.1 | M24: 0 | P24: CEMENT
A25: =A24+1 -> 2 | B25: 0.38402778 | C25: RAC 890L | D25: 10 | E25: 7 | F25: 1*22+22*22 | G25: 8.25 | H25: 9.05 | I25: 7.7 | J25: 6.95 | K25: 5.9 | L25: 5.75 | M25: 5.95 | P25: CEMENT
A26: =A25+1 -> 3 | B26: 0.38819444 | C26: RAD 019B | D26: 10 | E26: 7 | F26: 1*22+22*22 | G26: 8.85 | H26: 7.1 | I26: 7.25 | J26: 7.3 | K26: 7.35 | L26: 7.2 | M26: 5 | P26: CEMENT
A27: =A26+1 -> 4 | B27: 0.39027778 | C27: RAC 126U | D27: 10 | E27: 6 | F27: 1*22-222 | G27: 5.45 | H27: 7.75 | I27: 7.9 | J27: 8.6 | K27: 7.6 | L27: 6.75 | M27: 0 | P27: CEMENT
A28: =A27+1 -> 5 | B28: 0.40625 | C28: UBA 918B | D28: 10 | E28: 6 | F28: 1*12-222 | G28: 5.1 | H28: 6.45 | I28: 9.75 | J28: 7.95 | K28: 7.45 | L28: 6.4 | M28: 0 | P28: CEMENT
A29: =A28+1 -> 6 | B29: 0.42430556 | C29: RAB 567I | D29: 10 | E29: 6 | F29: 1*22-222 | G29: 4.8 | H29: 9.1 | I29: 8.05 | J29: 7.75 | K29: 6.85 | L29: 6.8 | M29: 0 | P29: CEMENT
A30: =A29+1 -> 7 | B30: 0.44305556 | C30: UAV 753D | D30: 10 | E30: 7 | F30: 1*22+22*22 | G30: 7.35 | H30: 7.45 | I30: 7.25 | J30: 8.1 | K30: 7.65 | L30: 7.3 | M30: 5.9 | P30: CEMENT
A31: =A30+1 -> 8 | B31: 0.47291667 | C31: RAD 209B | D31: 10 | E31: 7 | F31: 1*22+22*22 | G31: 6.7 | H31: 7.45 | I31: 8.05 | J31: 6.2 | K31: 7.25 | L31: 8 | M31: 8.2 | P31: CEMENT
A32: =A31+1 -> 9 | B32: 0.54583333 | C32: UAY 764P | D32: 7 | E32: 2 | F32: 1*2 | G32: 5.05 | H32: 11.3 | I32: 0 | J32: 0 | K32: 0 | L32: 0 | M32: 0 | P32: COTTON SEEDS
A33: =A32+1 -> 10 | B33: 0.57013889 | C33: RAB 182P | D33: 10 | E33: 7 | F33: 1*22+22*22 | G33: 8.15 | H33: 7.15 | I33: 6.8 | J33: 7.1 | K33: 7 | L33: 5.85 | M33: 6.6 | P33: CEMENT
A34: =A33+1 -> 11 | B34: 0.57847222 | C34: RAB 524R | D34: 10 | E34: 7 | F34: 1*22+22*22 | G34: 8.05 | H34: 10.05 | I34: 7.95 | J34: 8 | K34: 8.75 | L34: 5.6 | M34: 5.65 | P34: CEMENT
A35: =A34+1 -> 12 | B35: 0.64444444 | C35: UBB 101A | D35: 10 | E35: 6 | F35: 1822-222 | G35: 6.45 | H35: 7.55 | I35: 7.15 | J35: 6.05 | K35: 7.2 | L35: 7.9 | M35: 0 | P35: CEMENT
... A40: =A39+1 -> 17 | B40: 0.73263889 | C40: UBC 266C | D40: 7 | E40: 2 | F40: 1*2 | G40: 4.7 | H40: 11.55 | I40: 0 | J40: 0 | K40: 0 | L40: 0 | M40: 0 | P40: SALT

Sheet DAY2
A2: AXLE LOAD SURVEY FORM
A3: Date: | C3: 43767 | D3: Station Name: | G3: Direction: | H3: Mbarara-Kasese
D4: Rubirizi
A5: S/No. | B5: Time | C5: Reg. Number | D5: Vehicle Type | E5: Number of Axles | F5: Axle Configuration | G5: TONNES | N5: Total (Tonnes) | O5: Total (ESA's) | P5: COMMENTS
G6: AXLE 1 | H6: AXLE 2 | I6: AXLE 3 | J6: AXLE 4 | K6: AXLE 5 | L6: AXLE 6 | M6: AXLE 7
A7: 1 | B7: 0.30694444 | C7: UAZ 623P | D7: 7 | E7: 2 | F7: 1*2 | G7: 4.6 | H7: 7.3 | I7: 0 | J7: 0 | K7: 0 | L7: 0 | M7: 0 | P7: GOODS
A8: =A7+1 -> 2 | B8: 0.31319444 | C8: UAP 580B | D8: 7 | E8: 2 | F8: 1*2 | G8: 3.5 | H8: 9.85 | I8: 0 | J8: 0 | K8: 0 | L8: 0 | M8: 0 | P8: BEER
A9: =A8+1 -> 3 | B9: 0.33472222 | C9: UBB 212S | D9: 10 | E9: 6 | F9: 1*12-222 | G9: 5.7 | H9: 5.95 | I9: 8.45 | J9: 9.1 | K9: 8.45 | L9: 7.95 | M9: 0 | P9: FISH
A10: =A9+1 -> 4 | B10: 0.3375 | C10: UAS 763G | D10: 10 | E10: 6 | F10: 1*22-222 | G10: 5.7 | H10: 7 | I10: 7 | J10: 9.25 | K10: 7.7 | L10: 6.9 | M10: 0 | P10: FISH
A11: =A10+1 -> 5 | B11: 0.35625 | C11: UAY 971M | D11: 8 | E11: 3 | F11: 1*21 | G11: 5.5 | H11: 15 | I11: 15 | J11: 0 | K11: 0 | L11: 0 | M11: 0 | P11: GOODS
A12: =A11+1 -> 6 | B12: 0.35833333 | C12: UAS 906V | D12: 10 | E12: 6 | F12: 1*22-222 | G12: 6.2 | H12: 9.55 | I12: 7.3 | J12: 8.45 | K12: 7.55 | L12: 7.5 | M12: 0 | P12: GOODS
A13: =A12+1 -> 7 | B13: 0.36805556 | C13: 9460 AB19 | D13: 10 | E13: 6 | F13: 1*22-222 | G13: 5.15 | H13: 7.7 | I13: 5.05 | J13: 9.1 | K13: 7.85 | L13: 8.75 | M13: 0 | P13: CATTLE
A14: =A13+1 -> 8 | B14: 0.37291667 | C14: UBD 898X | D14: 7 | E14: 2 | F14: 1*2 | G14: 4.9 | H14: 10.15 | I14: 0 | J14: 0 | K14: 0 | L14: 0 | M14: 0 | P14: SODA
A15: =A14+1 -> 9 | B15: 0.44166667 | C15: UAN 917J | D15: 9 | E15: 4 | F15: 11*21 | G15: 7 | H15: 5.6 | I15: 10.25 | J15: 7.3 | K15: 0 | L15: 0 | M15: 0 | P15: TIMBER
A16: =A15+1 -> 10 | B16: 0.44444444 | C16: KCJ 660D | D16: 10 | E16: 6 | F16: 1*22-212 | G16: 5.35 | H16: 8.95 | I16: 4.75 | J16: 9.7 | K16: 8.15 | L16: 6.7 | M16: 0 | P16: GOODS
A17: =A16+1 -> 11 | B17: 0.46388889 | C17: UBB 652Z | D17: 10 | E17: 6 | F17: 1*12-111 | G17: 5.85 | H17: 5.9 | I17: 9.6 | J17: 8.15 | K17: 8.1 | L17: 7.7 | M17: 0 | P17: IRON SHEETS
A18: =A17+1 -> 12 | B18: 0.47638889 | C18: KBU 420G | D18: 10 | E18: 6 | F18: 1*12-222 | G18: 5 | H18: 4.1 | I18: 6.1 | J18: 6.35 | K18: 5.5 | L18: 5.7 | M18: 0 | P18: IRON SHEETS
A19: =A18+1 -> 13 | B19: 0.48611111 | C19: KBT 973S | D19: 10 | E19: 6 | F19: 1*22-222 | G19: 5.4 | H19: 6.9 | I19: 6.5 | J19: 5.5 | K19: 5.5 | L19: 5.85 | M19: 0 | P19: GOODS
... A21: =A20+1 -> 15 | B21: 0.53541667 | C21: UAY 583R | D21: 10 | E21: 7 | F21: 1*22+22*22 | G21: 6.75 | H21: 7.8 | I21: 7.9 | J21: 6.55 | K21: 6.45 | L21: 7.4 | M21: 6.95 | P21: GOODS
H22: KASESE - MBARARA
A23: 1 | B23: 0.35486111 | C23: UBB 094A | D23: 10 | E23: 6 | F23: 1*22-222 | G23: 6.5 | H23: 7.75 | I23: 7.15 | J23: 7.75 | K23: 7.3 | L23: 8.15 | M23: 0 | P23: CEMENT
A24: 2 | B24: 0.37430556 | C24: RAD829A | D24: 10 | E24: 6 | F24: 1*22-222 | G24: 4.7 | H24: 9.1 | I24: 8.85 | J24: 7.7 | K24: 6.75 | L24: 9.45 | M24: 0 | P24: CEMENT
A25: 3 | B25: 0.38263889 | C25: UBB 955V | D25: 10 | E25: 7 | F25: 1*22+22*22 | G25: 6.15 | H25: 6.45 | I25: 7.5 | J25: 7.95 | K25: 9.35 | L25: 7 | M25: 5.25 | P25: CEMENT
A26: =A25+1 -> 4 | B26: 0.38541667 | C26: RAC 050Q | D26: 10 | E26: 7 | F26: 1*22+22*22 | G26: 7.95 | H26: 8.3 | I26: 7.85 | J26: 6.35 | K26: 6.75 | L26: 7.15 | M26: 5.85 | P26: CEMENT
A27: =A26+1 -> 5 | B27: 0.40833333 | C27: UAQ 604W | D27: 10 | E27: 6 | F27: 1*22-222 | G27: 5.25 | H27: 9.2 | I27: 7.3 | J27: 7.45 | K27: 6.4 | L27: 7.2 | M27: 0 | P27: CEMENT
A28: =A27+1 -> 6 | B28: 0.44305556 | C28: UAX187X | D28: 10 | E28: 6 | F28: 1*22-222 | G28: 3.8 | H28: 8.45 | I28: 3.25 | J28: 8.3 | K28: 7.65 | L28: 6.45 | M28: 0 | P28: CEMENT
A29: =A28+1 -> 7 | B29: 0.475 | C29: UAT013Y | D29: 10 | E29: 6 | F29: 1*12-222 | G29: 5.5 | H29: 6.5 | I29: 9.909 | J29: 6.95 | K29: 7.2 | L29: 7.7 | M29: 0 | P29: CEMENT
A30: =A29+1 -> 8 | B30: 0.47847222 | C30: UAG 173Y | D30: 10 | E30: 6 | F30: 1*22_222 | G30: 5.95 | H30: 8.45 | I30: 8.95 | J30: 7 | K30: 7.15 | L30: 7.4 | M30: 0 | P30: CEMENT
A31: =A30+1 -> 9 | B31: 0.52291667 | C31: UAW 233U | D31: 10 | E31: 6 | F31: 1*22-222 | G31: 5.7 | H31: 7.5 | I31: 7.65 | J31: 7.45 | K31: 7.65 | L31: 7.4 | M31: 0 | P31: CEMENT
A32: =A31+1 -> 10 | B32: 0.57638889 | C32: UAZ 623P | D32: 7 | E32: 2 | F32: 1*2 | G32: 2.9 | H32: 5.85 | I32: 0 | J32: 0 | K32: 0 | L32: 0 | M32: 0 | P32: CEMENT
A33: =A32+1 -> 11 | B33: 0.6625 | C33: UBA 813R | D33: 7 | E33: 2 | F33: 1*2 | G33: 4 | H33: 12.45 | I33: 0 | J33: 0 | K33: 0 | L33: 0 | M33: 0 | P33: CEMENT
A34: =A33+1 -> 12 | B34: 0.66597222 | C34: UAX 936L | D34: 7 | E34: 2 | F34: 1*2 | G34: 3.8 | H34: 9.9 | I34: 0 | J34: 0 | K34: 0 | L34: 0 | M34: 0 | P34: CEMENT
A35: =A34+1 -> 13 | B35: 0.66666667 | C35: UAV 799U | D35: 7 | E35: 2 | F35: 1*2 | G35: 6.2 | H35: 11.2 | I35: 0 | J35: 0 | K35: 0 | L35: 0 | M35: 0 | P35: CEMENT
A36: =A35+1 -> 14 | B36: 0.67430556 | C36: UAZ 357F | D36: 7 | E36: 2 | F36: 1*2 | G36: 5.8 | H36: 11.6 | I36: 0 | J36: 0 | K36: 0 | L36: 0 | M36: 0 | P36: CEMENT
A37: =A36+1 -> 15 | B37: 0.67708333 | C37: RAB139R | D37: 10 | E37: 7 | F37: 1*22+22*22 | G37: 6.25 | H37: 7.2 | I37: 7.3 | J37: 8.05 | K37: 6.5 | L37: 5.75 | M37: 4.25 | P37: CEMENT
... A41: =A40+1 -> 19 | B41: 0.70138889 | C41: RAB 638D | D41: 10 | E41: 7 | F41: 1*22+22*22 | G41: 7.85 | H41: 8.5 | I41: 8.85 | J41: 5.85 | K41: 6.45 | L41: 6.7 | M41: 0 | P41: EMPTY
A42: =A41+1 -> 20 | B42: 0.70208333 | C42: RAD 129U | D42: 10 | E42: 6 | F42: 1*22-222 | G42: 5.4 | H42: 8 | I42: 7.5 | J42: 8.1 | K42: 5.9 | L42: 7 | M42: 0

Sheet DAY3
A2: AXLE LOAD SURVEY FORM
A3: Date: | C3: 43768 | D3: Station Name: | G3: Direction: | H3: Mbarara-Kasese
D4: Rubirizi
A5: S/No. | B5: Time | C5: Reg. Number | D5: Vehicle Type | E5: Number of Axles | F5: Axle Configuration | G5: TONNES | N5: Total (Tonnes) | O5: Total (ESA's) | P5: COMMENTS
G6: AXLE 1 | H6: AXLE 2 | I6: AXLE 3 | J6: AXLE 4 | K6: AXLE 5 | L6: AXLE 6 | M6: AXLE 7
A7: 1 | B7: 0.325 | C7: UAR 808C | D7: 7 | E7: 2 | F7: 1*2 | G7: 4.7 | H7: 11.1 | I7: 0 | J7: 0 | K7: 0 | L7: 0 | M7: 0 | P7: GOODS
A8: =A7+1 -> 2 | B8: 0.32916667 | C8: UBA 275C | D8: 7 | E8: 2 | F8: 1*2 | G8: 5 | H8: 10.1 | I8: 0 | J8: 0 | K8: 0 | L8: 0 | M8: 0 | P8: BEER
A9: =A8+1 -> 3 | B9: 0.36111111 | C9: UAB 801C | D9: 8 | E9: 3 | F9: 1*22 | G9: 5.3 | H9: 8.75 | I9: 9.35 | J9: 0 | K9: 0 | L9: 0 | M9: 0 | P9: FISH
A10: =A9+1 -> 4 | B10: 0.36666667 | C10: UAU 912Y | D10: 7 | E10: 2 | F10: 1*2 | G10: 4.5 | H10: 10.3 | I10: 0 | J10: 0 | K10: 0 | L10: 0 | M10: 0 | P10: FISH
A11: =A10+1 -> 5 | B11: 0.37569444 | C11: UAX 514A | D11: 10 | E11: 6 | F11: 1*12-111 | G11: 7.05 | H11: 5.8 | I11: 7.25 | J11: 7.35 | K11: 7 | L11: 7.15 | M11: 0 | P11: GOODS
A12: =A11+1 -> 6 | B12: 0.38055556 | C12: KCB 043Z | D12: 10 | E12: 6 | F12: 1*12-222 | G12: 6.25 | H12: 4.55 | I12: 9.15 | J12: 7 | K12: 8.2 | L12: 7.1 | M12: 0 | P12: GOODS
A13: =A12+1 -> 7 | B13: 0.38194444 | C13: KBX 74Q | D13: 10 | E13: 6 | F13: 1*12-222 | G13: 5.2 | H13: 5.2 | I13: 8.4 | J13: 6.05 | K13: 7.75 | L13: 6.2 | M13: 0 | P13: CATTLE
A14: =A13+1 -> 8 | B14: 0.38333333 | C14: KCF 216Y | D14: 10 | E14: 6 | F14: 1*12-222 | G14: 5.35 | H14: 5.4 | I14: 9.95 | J14: 7.65 | K14: 6.8 | L14: 5.4 | M14: 0 | P14: SODA
A15: =A14+1 -> 9 | B15: 0.40555556 | C15: UAL 156L | D15: 7 | E15: 2 | F15: 1*2 | G15: 3.75 | H15: 10.75 | I15: 0 | J15: 0 | K15: 0 | L15: 0 | M15: 0 | P15: TIMBER
A16: =A15+1 -> 10 | B16: 0.42361111 | C16: UAP 910C | D16: 10 | E16: 6 | F16: 1*22-222 | G16: 5.55 | H16: 7.5 | I16: 7.35 | J16: 8.3 | K16: 7.4 | L16: 8.05 | M16: 0 | P16: GOODS
A17: =A16+1 -> 11 | B17: 0.475 | C17: UAQ 162Q | D17: 7 | E17: 2 | F17: 1*2 | G17: 4.1 | H17: 8.7 | I17: 0 | J17: 0 | K17: 0 | L17: 0 | M17: 0 | P17: IRON SHEETS
A18: =A17+1 -> 12 | B18: 0.54861111 | C18: KBS 896Y | D18: 10 | E18: 6 | F18: 1*12-222 | G18: 4.2 | H18: 3.95 | I18: 5.65 | J18: 4.6 | K18: 5 | L18: 5.3 | M18: 0 | P18: IRON SHEETS
A19: =A18+1 -> 13 | B19: 0.56458333 | C19: KCC 605W | D19: 10 | E19: 6 | F19: 1*12-222 | G19: 6 | H19: 6 | I19: 8.55 | J19: 6.85 | K19: 7.55 | L19: 6.95 | M19: 0 | P19: GOODS
... A21: =A20+1 -> 15 | B21: 0.71597222 | C21: UBA 918B | D21: 10 | E21: 6 | F21: 1*12-222 | G21: 5.15 | H21: 5.8 | I21: 9.15 | J21: 7.65 | K21: 7 | L21: 6.55 | M21: 0 | P21: GOODS
A22: =A21+1 -> 16 | B22: 0.71666667 | C22: KCK 156Q | D22: 10 | E22: 6 | F22: 1*22-222 | G22: 6.15 | H22: 7.95 | I22: 8 | J22: 6.75 | K22: 6.25 | L22: 7.35 | M22: 0
A23: =A22+1 -> 17 | B23: 0.71736111 | C23: KBX 838R | D23: 10 | E23: 6 | F23: 1*12-222 | G23: 6.85 | H23: 5.9 | I23: 7.95 | J23: 7.95 | K23: 8.2 | L23: 8.1 | M23: 0
H24: KASESE - MBARARA
A25: =A24+1 -> 1 | B25: 0.32291667 | C25: UBD 990A | D25: 10 | E25: 6 | F25: 1*22-222 | G25: 6 | H25: 8.3 | I25: 7.85 | J25: 8.05 | K25: 7.55 | L25: 7.2 | M25: 0 | P25: CEMENT
A26: =A25+1 -> 2 | B26: 0.34930556 | C26: RAD 858S | D26: 10 | E26: 6 | F26: 1*22-222 | G26: 4.55 | H26: 9.35 | I26: 8.35 | J26: 10.95 | K26: 7.15 | L26: 6.8 | M26: 0 | P26: CEMENT
A27: =A26+1 -> 3 | B27: 0.35208333 | C27: RAD 864B | D27: 10 | E27: 6 | F27: 1*22-222 | G27: 5.8 | H27: 7.95 | I27: 7.2 | J27: 8.55 | K27: 7.2 | L27: 7.35 | M27: 0 | P27: CEMENT
A28: =A27+1 -> 4 | B28: 0.35833333 | C28: RAD 080F | D28: 10 | E28: 6 | F28: 1*22-222 | G28: 5.5 | H28: 8.25 | I28: 8.3 | J28: 8.1 | K28: 7.6 | L28: 8.1 | M28: 0 | P28: CEMENT
A29: =A28+1 -> 5 | B29: 0.3625 | C29: UBC 263D | D29: 10 | E29: 6 | F29: 1*22-222 | G29: 5.5 | H29: 8.8 | I29: 8.95 | J29: 6.85 | K29: 6.9 | L29: 5.9 | M29: 0 | P29: CEMENT
A30: =A29+1 -> 6 | B30: 0.37916667 | C30: RAC 253G | D30: 10 | E30: 7 | F30: 1*22+22*22 | G30: 7.9 | H30: 9.45 | I30: 8.4 | J30: 7.1 | K30: 6.4 | L30: 5.95 | M30: 4.9 | P30: CEMENT
A31: =A30+1 -> 7 | B31: 0.39861111 | C31: UAX 152W | D31: 10 | E31: 6 | F31: 1*22-222 | G31: 5.75 | H31: 8 | I31: 8.35 | J31: 7.35 | K31: 6.9 | L31: 6.7 | M31: 0 | P31: CEMENT
A32: =A31+1 -> 8 | B32: 0.41388889 | C32: UAV 052V | D32: 10 | E32: 6 | F32: 1*12-222 | G32: 5.3 | H32: 6.65 | I32: 6.45 | J32: 7.55 | K32: 6.95 | L32: 6.6 | M32: 0 | P32: CEMENT
A33: =A32+1 -> 9 | B33: 0.41736111 | C33: UBB I04A | D33: 10 | E33: 6 | F33: 1*22-222 | G33: 6.5 | H33: 8.3 | I33: 7.9 | J33: 7.15 | K33: 6.75 | L33: 7.3 | M33: 0 | P33: CEMENT
A34: =A33+1 -> 10 | B34: 0.47291667 | C34: UAN 879A | D34: 10 | E34: 5 | F34: 1*22-22 | G34: 4.75 | H34: 5.6 | I34: 5.35 | J34: 6.8 | K34: 7.4 | L34: 0 | M34: 0 | P34: CEMENT
A35: =A34+1 -> 11 | B35: 0.49027778 | C35: RAD 931D | D35: 10 | E35: 5 | F35: 1*2-111 | G35: 5.6 | H35: 11.9 | I35: 6.75 | J35: 7.2 | K35: 6.95 | L35: 0 | M35: 0 | P35: CEMENT
A36: =A35+1 -> 12 | B36: 0.51388889 | C36: UAW 214U | D36: 10 | E36: 6 | F36: 1*22-222 | G36: 5.8 | H36: 7.8 | I36: 7.45 | J36: 8.05 | K36: 7.75 | L36: 6.9 | M36: 0 | P36: CEMENT
... A39: =A38+1 -> 15 | B39: 0.55555556 | C39: UAQ 662T | D39: 10 | E39: 7 | F39: 1*22+22*22 | G39: 6 | H39: 5.2 | I39: 7.3 | J39: 6.85 | K39: 6.6 | L39: 6.25 | M39: 5.15 | P39: CEMENT

Sheet Mba-Kasese
A2: AXLE LOAD SURVEY FORM
A3: Date: | C3: 43766 | D3: Station Name: | E3: Rubirizi | G3: Direction: | H3: Mbarara-Kasese
A5: S/No. | B5: Time | C5: Reg. Number | D5: Vehicle Type | E5: Number of Axles | F5: Axle Configuration | G5: TONNES | N5: Total (Tonnes) | O5: Total (ESA's) | P5: Load limit (Tonnes) | W5: OVERLOADED? | X5: Overloaded by? | Y5: Overload Bands | Z5: COMMENTS
G6: AXLE 1 | H6: AXLE 2 | I6: AXLE 3 | J6: AXLE 4 | K6: AXLE 5 | L6: AXLE 6 | M6: AXLE 7 | P6: Axle 1 | Q6: Axle 2 | R6: Axle 3 | S6: Axle 4 | T6: Axle 5 | U6: Axle 6 | V6: Axle 7
A7: 1 | B7: 0.40138889 | C7: UAW 983V | D7: =IF(COUNT(G7:M7)>3,10,IF(COUNT(G7:M7)>2,9,7)) -> 7 | E7: 2 | F7: 1*2 | G7: 4.6 | H7: 12.3 | N7: =SUM(G7:M7) -> 16.9 | O7: =(N7/8.16)^4.5 -> 26.477956 | P7: 8 | Q7: 10 | R7: 9 | S7: 9 | T7: 9 | U7: 9 | V7: 9 | W7: =IF(G7>P7,"Y",IF(H7>Q7,"Y",IF(I7>R7,"Y",IF(J7>S7,"Y",IF(K7>T7,"Y",IF(L7>U7,"Y",IF(M7>V7,"Y","N"))))))) -> Y | X7: =IF(W7="Y",MAX((G7-P7),(H7-Q7),(I7-R7),(J7-S7),(K7-T7),(L7-U7),(M7-V7))/10,0) -> 0.23 | Y7: =IF(X7<5%,"0-4.9%",IF(X7<25%,"5-25%",IF(X7<50%,"25-50%","Over 50%"))) -> 5-25% | Z7: Household retail products
A8: =A7+1 -> 2 | B8: 0.40486111 | C8: UBB 322P | D8: =IF(COUNT(G8:M8)>3,10,IF(COUNT(G8:M8)>2,9,7)) -> 7 | E8: 2 | F8: 1*2 | G8: 5.35 | H8: 9.75 | N8: =SUM(G8:M8) -> 15.1 | O8: =(N8/8.16)^4.5 -> 15.951097 | P8: 8 | Q8: 10 | R8: 9 | S8: 9 | T8: 9 | U8: 9 | V8: 9 | W8: =IF(G8>P8,"Y",IF(H8>Q8,"Y",IF(I8>R8,"Y",IF(J8>S8,"Y",IF(K8>T8,"Y",IF(L8>U8,"Y",IF(M8>V8,"Y","N"))))))) -> N | X8: =IF(W8="Y",MAX((G8-P8),(H8-Q8),(I8-R8),(J8-S8),(K8-T8),(L8-U8),(M8-V8))/10,0) -> 0 | Y8: =IF(X8<5%,"0-4.9%",IF(X8<25%,"5-25%",IF(X8<50%,"25-50%","Over 50%"))) -> 0-4.9% | Z8: Perishable
A9: =A8+1 -> 3 | B9: 0.40555556 | C9: UAV 799U | D9: =IF(COUNT(G9:M9)>3,10,IF(COUNT(G9:M9)>2,9,7)) -> 7 | E9: 2 | F9: 1*2 | G9: 5.1 | H9: 7.9 | N9: =SUM(G9:M9) -> 13 | O9: =(N9/8.16)^4.5 -> 8.1309141 | P9: 8 | Q9: 10 | R9: 9 | S9: 9 | T9: 9 | U9: 9 | V9: 9 | W9: =IF(G9>P9,"Y",IF(H9>Q9,"Y",IF(I9>R9,"Y",IF(J9>S9,"Y",IF(K9>T9,"Y",IF(L9>U9,"Y",IF(M9>V9,"Y","N"))))))) -> N | X9: =IF(W9="Y",MAX((G9-P9),(H9-Q9),(I9-R9),(J9-S9),(K9-T9),(L9-U9),(M9-V9))/10,0) -> 0 | Y9: =IF(X9<5%,"0-4.9%",IF(X9<25%,"5-25%",IF(X9<50%,"25-50%","Over 50%"))) -> 0-4.9% | Z9: Perishable
A10: =A9+1 -> 4 | B10: 0.54722222 | C10: UBA 297T | D10: =IF(COUNT(G10:M10)>3,10,IF(COUNT(G10:M10)>2,9,7)) -> 7 | E10: 2 | F10: 1*2 | G10: 3.65 | H10: 9.5 | N10: =SUM(G10:M10) -> 13.15 | O10: =(N10/8.16)^4.5 -> 8.5617033 | P10: 8 | Q10: 10 | R10: 9 | S10: 9 | T10: 9 | U10: 9 | V10: 9 | W10: =IF(G10>P10,"Y",IF(H10>Q10,"Y",IF(I10>R10,"Y",IF(J10>S10,"Y",IF(K10>T10,"Y",IF(L10>U10,"Y",IF(M10>V10,"Y","N"))))))) -> N | X10: =IF(W10="Y",MAX((G10-P10),(H10-Q10),(I10-R10),(J10-S10),(K10-T10),(L10-U10),(M10-V10))/10,0) -> 0 | Y10: =IF(X10<5%,"0-4.9%",IF(X10<25%,"5-25%",IF(X10<50%,"25-50%","Over 50%"))) -> 0-4.9% | Z10: Livestock
A11: =A10+1 -> 5 | B11: 0.55555556 | C11: UAQ 162Q | D11: =IF(COUNT(G11:M11)>3,10,IF(COUNT(G11:M11)>2,9,7)) -> 7 | E11: 2 | F11: 1*2 | G11: 3.9 | H11: 7.45 | N11: =SUM(G11:M11) -> 11.35 | O11: =(N11/8.16)^4.5 -> 4.4144404 | P11: 8 | Q11: 10 | R11: 9 | S11: 9 | T11: 9 | U11: 9 | V11: 9 | W11: =IF(G11>P11,"Y",IF(H11>Q11,"Y",IF(I11>R11,"Y",IF(J11>S11,"Y",IF(K11>T11,"Y",IF(L11>U11,"Y",IF(M11>V11,"Y","N"))))))) -> N | X11: =IF(W11="Y",MAX((G11-P11),(H11-Q11),(I11-R11),(J11-S11),(K11-T11),(L11-U11),(M11-V11))/10,0) -> 0 | Y11: =IF(X11<5%,"0-4.9%",IF(X11<25%,"5-25%",IF(X11<50%,"25-50%","Over 50%"))) -> 0-4.9% | Z11: Household retail products
A12: =A11+1 -> 6 | B12: 0.55694444 | C12: UBD 881D | D12: =IF(COUNT(G12:M12)>3,10,IF(COUNT(G12:M12)>2,9,7)) -> 7 | E12: 7 | F12: 1*2 | G12: 2.7 | H12: 5.75 | N12: =SUM(G12:M12) -> 8.45 | O12: =(N12/8.16)^4.5 -> 1.1701714 | P12: 8 | Q12: 10 | R12: 9 | S12: 9 | T12: 9 | U12: 9 | V12: 9 | W12: =IF(G12>P12,"Y",IF(H12>Q12,"Y",IF(I12>R12,"Y",IF(J12>S12,"Y",IF(K12>T12,"Y",IF(L12>U12,"Y",IF(M12>V12,"Y","N"))))))) -> N | X12: =IF(W12="Y",MAX((G12-P12),(H12-Q12),(I12-R12),(J12-S12),(K12-T12),(L12-U12),(M12-V12))/10,0) -> 0 | Y12: =IF(X12<5%,"0-4.9%",IF(X12<25%,"5-25%",IF(X12<50%,"25-50%","Over 50%"))) -> 0-4.9% | Z12: Forestry products
A13: =A12+1 -> 7 | B13: 0.64166667 | C13: UBB 621H | D13: =IF(COUNT(G13:M13)>3,10,IF(COUNT(G13:M13)>2,9,7)) -> 7 | E13: 2 | F13: 1*2 | G13: 4.7 | H13: 10.9 | N13: =SUM(G13:M13) -> 15.6 | O13: =(N13/8.16)^4.5 -> 18.469493 | P13: 8 | Q13: 10 | R13: 9 | S13: 9 | T13: 9 | U13: 9 | V13: 9 | W13: =IF(G13>P13,"Y",IF(H13>Q13,"Y",IF(I13>R13,"Y",IF(J13>S13,"Y",IF(K13>T13,"Y",IF(L13>U13,"Y",IF(M13>V13,"Y","N"))))))) -> Y | X13: =IF(W13="Y",MAX((G13-P13),(H13-Q13),(I13-R13),(J13-S13),(K13-T13),(L13-U13),(M13-V13))/10,0) -> 0.09 | Y13: =IF(X13<5%,"0-4.9%",IF(X13<25%,"5-25%",IF(X13<50%,"25-50%","Over 50%"))) -> 5-25% | Z13: Household retail products
A14: 1 | B14: 0.30694444 | C14: UAZ 623P | D14: =IF(COUNT(G14:M14)>3,10,IF(COUNT(G14:M14)>2,9,7)) -> 7 | E14: 2 | F14: 1*2 | G14: 4.6 | H14: 7.3 | N14: =SUM(G14:M14) -> 11.9 | O14: =(N14/8.16)^4.5 -> 5.4620493 | P14: 8 | Q14: 10 | R14: 9 | S14: 9 | T14: 9 | U14: 9 | V14: 9 | W14: =IF(G14>P14,"Y",IF(H14>Q14,"Y",IF(I14>R14,"Y",IF(J14>S14,"Y",IF(K14>T14,"Y",IF(L14>U14,"Y",IF(M14>V14,"Y","N"))))))) -> N | X14: =IF(W14="Y",MAX((G14-P14),(H14-Q14),(I14-R14),(J14-S14),(K14-T14),(L14-U14),(M14-V14))/10,0) -> 0 | Y14: =IF(X14<5%,"0-4.9%",IF(X14<25%,"5-25%",IF(X14<50%,"25-50%","Over 50%"))) -> 0-4.9% | Z14: Household retail products
A15: =A14+1 -> 2 | B15: 0.31319444 | C15: UAP 580B | D15: =IF(COUNT(G15:M15)>3,10,IF(COUNT(G15:M15)>2,9,7)) -> 7 | E15: 2 | F15: 1*2 | G15: 3.5 | H15: 9.85 | N15: =SUM(G15:M15) -> 13.35 | O15: =(N15/8.16)^4.5 -> 9.1634704 | P15: 8 | Q15: 10 | R15: 9 | S15: 9 | T15: 9 | U15: 9 | V15: 9 | W15: =IF(G15>P15,"Y",IF(H15>Q15,"Y",IF(I15>R15,"Y",IF(J15>S15,"Y",IF(K15>T15,"Y",IF(L15>U15,"Y",IF(M15>V15,"Y","N"))))))) -> N | X15: =IF(W15="Y",MAX((G15-P15),(H15-Q15),(I15-R15),(J15-S15),(K15-T15),(L15-U15),(M15-V15))/10,0) -> 0 | Y15: =IF(X15<5%,"0-4.9%",IF(X15<25%,"5-25%",IF(X15<50%,"25-50%","Over 50%"))) -> 0-4.9% | Z15: Household retail products
A16: =A15+1 -> 3 | B16: 0.37291667 | C16: UBD 898X | D16: =IF(COUNT(G16:M16)>3,10,IF(COUNT(G16:M16)>2,9,7)) -> 7 | E16: 2 | F16: 1*2 | G16: 4.9 | H16: 10.15 | N16: =SUM(G16:M16) -> 15.05 | O16: =(N16/8.16)^4.5 -> 15.714788 | P16: 8 | Q16: 10 | R16: 9 | S16: 9 | T16: 9 | U16: 9 | V16: 9 | W16: =IF(G16>P16,"Y",IF(H16>Q16,"Y",IF(I16>R16,"Y",IF(J16>S16,"Y",IF(K16>T16,"Y",IF(L16>U16,"Y",IF(M16>V16,"Y","N"))))))) -> Y | X16: =IF(W16="Y",MAX((G16-P16),(H16-Q16),(I16-R16),(J16-S16),(K16-T16),(L16-U16),(M16-V16))/10,0) -> 0.015 | Y16: =IF(X16<5%,"0-4.9%",IF(X16<25%,"5-25%",IF(X16<50%,"25-50%","Over 50%"))) -> 0-4.9% | Z16: Household retail products
A17: 1 | B17: 0.325 | C17: UAR 808C | D17: =IF(COUNT(G17:M17)>3,10,IF(COUNT(G17:M17)>2,9,7)) -> 7 | E17: 2 | F17: 1*2 | G17: 4.7 | H17: 11.1 | N17: =SUM(G17:M17) -> 15.8 | O17: =(N17/8.16)^4.5 -> 19.559204 | P17: 8 | Q17: 10 | R17: 9 | S17: 9 | T17: 9 | U17: 9 | V17: 9 | W17: =IF(G17>P17,"Y",IF(H17>Q17,"Y",IF(I17>R17,"Y",IF(J17>S17,"Y",IF(K17>T17,"Y",IF(L17>U17,"Y",IF(M17>V17,"Y","N"))))))) -> Y | X17: =IF(W17="Y",MAX((G17-P17),(H17-Q17),(I17-R17),(J17-S17),(K17-T17),(L17-U17),(M17-V17))/10,0) -> 0.11 | Y17: =IF(X17<5%,"0-4.9%",IF(X17<25%,"5-25%",IF(X17<50%,"25-50%","Over 50%"))) -> 5-25% | Z17: Household retail products
A18: =A17+1 -> 2 | B18: 0.32916667 | C18: UBA 275C | D18: =IF(COUNT(G18:M18)>3,10,IF(COUNT(G18:M18)>2,9,7)) -> 7 | E18: 2 | F18: 1*2 | G18: 5 | H18: 10.1 | N18: =SUM(G18:M18) -> 15.1 | O18: =(N18/8.16)^4.5 -> 15.951097 | P18: 8 | Q18: 10 | R18: 9 | S18: 9 | T18: 9 | U18: 9 | V18: 9 | W18: =IF(G18>P18,"Y",IF(H18>Q18,"Y",IF(I18>R18,"Y",IF(J18>S18,"Y",IF(K18>T18,"Y",IF(L18>U18,"Y",IF(M18>V18,"Y","N"))))))) -> Y | X18: =IF(W18="Y",MAX((G18-P18),(H18-Q18),(I18-R18),(J18-S18),(K18-T18),(L18-U18),(M18-V18))/10,0) -> 0.01 | Y18: =IF(X18<5%,"0-4.9%",IF(X18<25%,"5-25%",IF(X18<50%,"25-50%","Over 50%"))) -> 0-4.9% | Z18: Household retail products
A19: =A18+1 -> 3 | B19: 0.40555556 | C19: UAL 156L | D19: =IF(COUNT(G19:M19)>3,10,IF(COUNT(G19:M19)>2,9,7)) -> 7 | E19: 2 | F19: 1*2 | G19: 3.75 | H19: 10.75 | N19: =SUM(G19:M19) -> 14.5 | O19: =(N19/8.16)^4.5 -> 13.290775 | P19: 8 | Q19: 10 | R19: 9 | S19: 9 | T19: 9 | U19: 9 | V19: 9 | W19: =IF(G19>P19,"Y",IF(H19>Q19,"Y",IF(I19>R19,"Y",IF(J19>S19,"Y",IF(K19>T19,"Y",IF(L19>U19,"Y",IF(M19>V19,"Y","N"))))))) -> Y | X19: =IF(W19="Y",MAX((G19-P19),(H19-Q19),(I19-R19),(J19-S19),(K19-T19),(L19-U19),(M19-V19))/10,0) -> 0.075 | Y19: =IF(X19<5%,"0-4.9%",IF(X19<25%,"5-25%",IF(X19<50%,"25-50%","Over 50%"))) -> 5-25% | Z19: Forestry products
A20: =A19+1 -> 4 | B20: 0.475 | C20: UAQ 162Q | D20: =IF(COUNT(G20:M20)>3,10,IF(COUNT(G20:M20)>2,9,7)) -> 7 | E20: 2 | F20: 1*2 | G20: 4.1 | H20: 8.7 | N20: =SUM(G20:M20) -> 12.8 | O20: =(N20/8.16)^4.5 -> 7.5829667 | P20: 8 | Q20: 10 | R20: 9 | S20: 9 | T20: 9 | U20: 9 | V20: 9 | W20: =IF(G20>P20,"Y",IF(H20>Q20,"Y",IF(I20>R20,"Y",IF(J20>S20,"Y",IF(K20>T20,"Y",IF(L20>U20,"Y",IF(M20>V20,"Y","N"))))))) -> N | X20: =IF(W20="Y",MAX((G20-P20),(H20-Q20),(I20-R20),(J20-S20),(K20-T20),(L20-U20),(M20-V20))/10,0) -> 0 | Y20: =IF(X20<5%,"0-4.9%",IF(X20<25%,"5-25%",IF(X20<50%,"25-50%","Over 50%"))) -> 0-4.9% | Z20: Construction Material
A21: =A20+1 -> 5 | B21: 0.71527778 | C21: UAV 480K | D21: =IF(COUNT(G21:M21)>3,10,IF(COUNT(G21:M21)>2,9,7)) -> 7 | E21: 2 | F21: 1*2 | G21: 5.55 | H21: 5.65 | N21: =SUM(G21:M21) -> 11.2 | O21: =(N21/8.16)^4.5 -> 4.1579129 | P21: 8 | Q21: 10 | R21: 9 | S21: 9 | T21: 9 | U21: 9 | V21: 9 | W21: =IF(G21>P21,"Y",IF(H21>Q21,"Y",IF(I21>R21,"Y",IF(J21>S21,"Y",IF(K21>T21,"Y",IF(L21>U21,"Y",IF(M21>V21,"Y","N"))))))) -> N | X21: =IF(W21="Y",MAX((G21-P21),(H21-Q21),(I21-R21),(J21-S21),(K21-T21),(L21-U21),(M21-V21))/10,0) -> 0 | Y21: =IF(X21<5%,"0-4.9%",IF(X21<25%,"5-25%",IF(X21<50%,"25-50%","Over 50%"))) -> 0-4.9% | Z21: Fuels
A22: =A21+1 -> 6 | B22: 0.35625 | C22: UAY 971M | D22: =IF(COUNT(G22:M22)>3,10,IF(COUNT(G22:M22)>2,9,7)) -> 9 | E22: 3 | F22: 1*21 | G22: 5.5 | H22: 15 | I22: 15 | N22: =SUM(G22:M22) -> 35.5 | O22: =(N22/8.16)^4.5 -> 747.17421 | P22: 8 | Q22: 10 | R22: 9 | S22: 9 | T22: 9 | U22: 9 | V22: 9 | W22: =IF(G22>P22,"Y",IF(H22>Q22,"Y",IF(I22>R22,"Y",IF(J22>S22,"Y",IF(K22>T22,"Y",IF(L22>U22,"Y",IF(M22>V22,"Y","N"))))))) -> Y | X22: =IF(W22="Y",MAX((G22-P22),(H22-Q22),(I22-R22),(J22-S22),(K22-T22),(L22-U22),(M22-V22))/10,0) -> 0.6 | Y22: =IF(X22<5%,"0-4.9%",IF(X22<25%,"5-25%",IF(X22<50%,"25-50%","Over 50%"))) -> Over 50% | Z22: Household retail products
A23: =A22+1 -> 7 | B23: 0.36111111 | C23: UAB 801C | D23: =IF(COUNT(G23:M23)>3,10,IF(COUNT(G23:M23)>2,9,7)) -> 9 | E23: 3 | F23: 1*22 | G23: 5.3 | H23: 8.75 | I23: 9.35 | N23: =SUM(G23:M23) -> 23.4 | O23: =(N23/8.16)^4.5 -> 114.51586 | P23: 8 | Q23: 10 | R23: 9 | S23: 9 | T23: 9 | U23: 9 | V23: 9 | W23: =IF(G23>P23,"Y",IF(H23>Q23,"Y",IF(I23>R23,"Y",IF(J23>S23,"Y",IF(K23>T23,"Y",IF(L23>U23,"Y",IF(M23>V23,"Y","N"))))))) -> Y | X23: =IF(W23="Y",MAX((G23-P23),(H23-Q23),(I23-R23),(J23-S23),(K23-T23),(L23-U23),(M23-V23))/10,0) -> 0.035 | Y23: =IF(X23<5%,"0-4.9%",IF(X23<25%,"5-25%",IF(X23<50%,"25-50%","Over 50%"))) -> 0-4.9% | Z23: Perishable
A24: =A23+1 -> 8 | B24: 0.36666667 | C24: UAU 912Y | D24: =IF(COUNT(G24:M24)>3,10,IF(COUNT(G24:M24)>2,9,7)) -> 9 | E24: 2 | F24: 1*2 | G24: 4.5 | H24: 10.3 | I24: 0 | N24: =SUM(G24:M24) -> 14.8 | O24: =(N24/8.16)^4.5 -> 14.573773 | P24: 8 | Q24: 10 | R24: 9 | S24: 9 | T24: 9 | U24: 9 | V24: 9 | W24: =IF(G24>P24,"Y",IF(H24>Q24,"Y",IF(I24>R24,"Y",IF(J24>S24,"Y",IF(K24>T24,"Y",IF(L24>U24,"Y",IF(M24>V24,"Y","N"))))))) -> Y | X24: =IF(W24="Y",MAX((G24-P24),(H24-Q24),(I24-R24),(J24-S24),(K24-T24),(L24-U24),(M24-V24))/10,0) -> 0.03 | Y24: =IF(X24<5%,"0-4.9%",IF(X24<25%,"5-25%",IF(X24<50%,"25-50%","Over 50%"))) -> 0-4.9% | Z24: Perishable
A25: =A24+1 -> 9 | B25: 0.40277778 | C25: UBD 480T | D25: =IF(COUNT(G25:M25)>3,10,IF(COUNT(G25:M25)>2,9,7)) -> 10 | E25: 4 | F25: 11*22 | G25: 5.95 | H25: 5.5 | I25: 9.45 | J25: 6.5 | N25: =SUM(G25:M25) -> 27.4 | O25: =(N25/8.16)^4.5 -> 232.95488 | P25: 8 | Q25: 10 | R25: 9 | S25: 9 | T25: 9 | U25: 9 | V25: 9 | W25: =IF(G25>P25,"Y",IF(H25>Q25,"Y",IF(I25>R25,"Y",IF(J25>S25,"Y",IF(K25>T25,"Y",IF(L25>U25,"Y",IF(M25>V25,"Y","N"))))))) -> Y | X25: =IF(W25="Y",MAX((G25-P25),(H25-Q25),(I25-R25),(J25-S25),(K25-T25),(L25-U25),(M25-V25))/10,0) -> 0.045 | Y25: =IF(X25<5%,"0-4.9%",IF(X25<25%,"5-25%",IF(X25<50%,"25-50%","Over 50%"))) -> 0-4.9% | Z25: Household retail products
A26: =A25+1 -> 10 | B26: 0.50486111 | C26: UAM 930B | D26: =IF(COUNT(G26:M26)>3,10,IF(COUNT(G26:M26)>2,9,7)) -> 10 | E26: 5 | F26: 11*222 | G26: 7.15 | H26: 4.95 | I26: 8.3 | J26: 5.5 | K26: 2.3 | N26: =SUM(G26:M26) -> 28.2 | O26: =(N26/8.16)^4.5 -> 265.16443 | P26: 8 | Q26: 10 | R26: 9 | S26: 9 | T26: 9 | U26: 9 | V26: 9 | W26: =IF(G26>P26,"Y",IF(H26>Q26,"Y",IF(I26>R26,"Y",IF(J26>S26,"Y",IF(K26>T26,"Y",IF(L26>U26,"Y",IF(M26>V26,"Y","N"))))))) -> N | X26: =IF(W26="Y",MAX((G26-P26),(H26-Q26),(I26-R26),(J26-S26),(K26-T26),(L26-U26),(M26-V26))/10,0) -> 0 | Y26: =IF(X26<5%,"0-4.9%",IF(X26<25%,"5-25%",IF(X26<50%,"25-50%","Over 50%"))) -> 0-4.9% | Z26: Household retail products
A27: =A26+1 -> 11 | B27: 0.53541667 | C27: UAV 916C | D27: =IF(COUNT(G27:M27)>3,10,IF(COUNT(G27:M27)>2,9,7)) -> 10 | E27: 5 | F27: 11*222 | G27: 5.1 | H27: 5.3 | I27: 10 | J27: 6 | K27: 4 | N27: =SUM(G27:M27) -> 30.4 | O27: =(N27/8.16)^4.5 -> 371.81372 | P27: 8 | Q27: 10 | R27: 9 | S27: 9 | T27: 9 | U27: 9 | V27: 9 | W27: =IF(G27>P27,"Y",IF(H27>Q27,"Y",IF(I27>R27,"Y",IF(J27>S27,"Y",IF(K27>T27,"Y",IF(L27>U27,"Y",IF(M27>V27,"Y","N"))))))) -> Y | X27: =IF(W27="Y",MAX((G27-P27),(H27-Q27),(I27-R27),(J27-S27),(K27-T27),(L27-U27),(M27-V27))/10,0) -> 0.1 | Y27: =IF(X27<5%,"0-4.9%",IF(X27<25%,"5-25%",IF(X27<50%,"25-50%","Over 50%"))) -> 5-25% | Z27: Household retail products
A28: =A27+1 -> 12 | B28: 0.6125 | C28: KCC 805S | D28: =IF(COUNT(G28:M28)>3,10,IF(COUNT(G28:M28)>2,9,7)) -> 10 | E28: 6 | F28: 1*22-222 | G28: 5.25 | H28: 6.85 | I28: 6.85 | J28: 6.5 | K28: 7.35 | L28: 7.55 | N28: =SUM(G28:M28) -> 40.35 | O28: =(N28/8.16)^4.5 -> 1329.5057 | P28: 8 | Q28: 10 | R28: 9 | S28: 9 | T28: 9 | U28: 9 | V28: 9 | W28: =IF(G28>P28,"Y",IF(H28>Q28,"Y",IF(I28>R28,"Y",IF(J28>S28,"Y",IF(K28>T28,"Y",IF(L28>U28,"Y",IF(M28>V28,"Y","N"))))))) -> N | X28: =IF(W28="Y",MAX((G28-P28),(H28-Q28),(I28-R28),(J28-S28),(K28-T28),(L28-U28),(M28-V28))/10,0) -> 0 | Y28: =IF(X28<5%,"0-4.9%",IF(X28<25%,"5-25%",IF(X28<50%,"25-50%","Over 50%"))) -> 0-4.9% | Z28: Household retail products
A29: =A28+1 -> 13 | B29: 0.61388889 | C29: KCQ 784Z | D29: =IF(COUNT(G29:M29)>3,10,IF(COUNT(G29:M29)>2,9,7)) -> 10 | E29: 6 | F29: 1*12-222 | G29: 5.4 | H29: 4.8 | I29: 7.85 | J29: 8.3 | K29: 8.1 | L29: 8.35 | N29: =SUM(G29:M29) -> 42.8 | O29: =(N29/8.16)^4.5 -> 1733.3699 | P29: 8 | Q29: 10 | R29: 9 | S29: 9 | T29: 9 | U29: 9 | V29: 9 | W29: =IF(G29>P29,"Y",IF(H29>Q29,"Y",IF(I29>R29,"Y",IF(J29>S29,"Y",IF(K29>T29,"Y",IF(L29>U29,"Y",IF(M29>V29,"Y","N"))))))) -> N | X29: =IF(W29="Y",MAX((G29-P29),(H29-Q29),(I29-R29),(J29-S29),(K29-T29),(L29-U29),(M29-V29))/10,0) -> 0 | Y29: =IF(X29<5%,"0-4.9%",IF(X29<25%,"5-25%",IF(X29<50%,"25-50%","Over 50%"))) -> 0-4.9% | Z29: Construction Material
A30: =A29+1 -> 14 | B30: 0.61736111 | C30: KBS 134K | D30: =IF(COUNT(G30:M30)>3,10,IF(COUNT(G30:M30)>2,9,7)) -> 10 | E30: 6 | F30: 1*12-222 | G30: 5.6 | H30: 5.95 | I30: 9.1 | J30: 7.45 | K30: 7.45 | L30: 6.3 | N30: =SUM(G30:M30) -> 41.85 | O30: =(N30/8.16)^4.5 -> 1566.8372 | P30: 8 | Q30: 10 | R30: 9 | S30: 9 | T30: 9 | U30: 9 | V30: 9 | W30: =IF(G30>P30,"Y",IF(H30>Q30,"Y",IF(I30>R30,"Y",IF(J30>S30,"Y",IF(K30>T30,"Y",IF(L30>U30,"Y",IF(M30>V30,"Y","N"))))))) -> Y | X30: =IF(W30="Y",MAX((G30-P30),(H30-Q30),(I30-R30),(J30-S30),(K30-T30),(L30-U30),(M30-V30))/10,0) -> 0.01 | Y30: =IF(X30<5%,"0-4.9%",IF(X30<25%,"5-25%",IF(X30<50%,"25-50%","Over 50%"))) -> 0-4.9% | Z30: Construction Material
A31: =A30+1 -> 15 | B31: 0.65 | C31: T595 DNS | D31: =IF(COUNT(G31:M31)>3,10,IF(COUNT(G31:M31)>2,9,7)) -> 10 | E31: 6 | F31: 1*12-111 | G31: 6.65 | H31: 5.95 | I31: 8.3 | J31: 7 | K31: 7.05 | L31: 7.1 | N31: =SUM(G31:M31) -> 42.05 | O31: =(N31/8.16)^4.5 -> 1600.8155 | P31: 8 | Q31: 10 | R31: 9 | S31: 9 | T31: 9 | U31: 9 | V31: 9 | W31: =IF(G31>P31,"Y",IF(H31>Q31,"Y",IF(I31>R31,"Y",IF(J31>S31,"Y",IF(K31>T31,"Y",IF(L31>U31,"Y",IF(M31>V31,"Y","N"))))))) -> N | X31: =IF(W31="Y",MAX((G31-P31),(H31-Q31),(I31-R31),(J31-S31),(K31-T31),(L31-U31),(M31-V31))/10,0) -> 0 | Y31: =IF(X31<5%,"0-4.9%",IF(X31<25%,"5-25%",IF(X31<50%,"25-50%","Over 50%"))) -> 0-4.9% | Z31: Fuels
A32: =A31+1 -> 16 | B32: 0.71458333 | C32: KCG 344H | D32: =IF(COUNT(G32:M32)>3,10,IF(COUNT(G32:M32)>2,9,7)) -> 10 | E32: 6 | F32: 1*22-222 | G32: 5.65 | H32: 7.4 | I32: 7.45 | J32: 7.3 | K32: 7.55 | L32: 7.85 | N32: =SUM(G32:M32) -> 43.2 | O32: =(N32/8.16)^4.5 -> 1807.4702 | P32: 8 | Q32: 10 | R32: 9 | S32: 9 | T32: 9 | U32: 9 | V32: 9 | W32: =IF(G32>P32,"Y",IF(H32>Q32,"Y",IF(I32>R32,"Y",IF(J32>S32,"Y",IF(K32>T32,"Y",IF(L32>U32,"Y",IF(M32>V32,"Y","N"))))))) -> N | X32: =IF(W32="Y",MAX((G32-P32),(H32-Q32),(I32-R32),(J32-S32),(K32-T32),(L32-U32),(M32-V32))/10,0) -> 0 | Y32: =IF(X32<5%,"0-4.9%",IF(X32<25%,"5-25%",IF(X32<50%,"25-50%","Over 50%"))) -> 0-4.9% | Z32: Household retail products
A33: =A32+1 -> 17 | B33: 0.74444444 | C33: KBK 289K | D33: =IF(COUNT(G33:M33)>3,10,IF(COUNT(G33:M33)>2,9,7)) -> 10 | E33: 6 | F33: 1*22-222 | G33: 5.15 | H33: 8.6 | I33: 6.55 | J33: 8.6 | K33: 6.65 | L33: 5.6 | N33: =SUM(G33:M33) -> 41.15 | O33: =(N33/8.16)^4.5 -> 1452.3074 | P33: 8 | Q33: 10 | R33: 9 | S33: 9 | T33: 9 | U33: 9 | V33: 9 | W33: =IF(G33>P33,"Y",IF(H33>Q33,"Y",IF(I33>R33,"Y",IF(J33>S33,"Y",IF(K33>T33,"Y",IF(L33>U33,"Y",IF(M33>V33,"Y","N"))))))) -> N | X33: =IF(W33="Y",MAX((G33-P33),(H33-Q33),(I33-R33),(J33-S33),(K33-T33),(L33-U33),(M33-V33))/10,0) -> 0 | Y33: =IF(X33<5%,"0-4.9%",IF(X33<25%,"5-25%",IF(X33<50%,"25-50%","Over 50%"))) -> 0-4.9% | Z33: Construction Material
A34: =A33+1 -> 18 | B34: 0.33472222 | C34: UBB 212S | D34: =IF(COUNT(G34:M34)>3,10,IF(COUNT(G34:M34)>2,9,7)) -> 10 | E34: 6 | F34: 1*12-222 | G34: 5.7 | H34: 5.95 | I34: 8.45 | J34: 9.1 | K34: 8.45 | L34: 7.95 | N34: =SUM(G34:M34) -> 45.6 | O34: =(N34/8.16)^4.5 -> 2305.3458 | P34: 8 | Q34: 10 | R34: 9 | S34: 9 | T34: 9 | U34: 9 | V34: 9 | W34: =IF(G34>P34,"Y",IF(H34>Q34,"Y",IF(I34>R34,"Y",IF(J34>S34,"Y",IF(K34>T34,"Y",IF(L34>U34,"Y",IF(M34>V34,"Y","N"))))))) -> Y | X34: =IF(W34="Y",MAX((G34-P34),(H34-Q34),(I34-R34),(J34-S34),(K34-T34),(L34-U34),(M34-V34))/10,0) -> 0.01 | Y34: =IF(X34<5%,"0-4.9%",IF(X34<25%,"5-25%",IF(X34<50%,"25-50%","Over 50%"))) -> 0-4.9% | Z34: Perishable
A35: =A34+1 -> 19 | B35: 0.3375 | C35: UAS 763G | D35: =IF(COUNT(G35:M35)>3,10,IF(COUNT(G35:M35)>2,9,7)) -> 10 | E35: 6 | F35: 1*22-222 | G35: 5.7 | H35: 7 | I35: 7 | J35: 9.25 | K35: 7.7 | L35: 6.9 | N35: =SUM(G35:M35) -> 43.55 | O35: =(N35/8.16)^4.5 -> 1874.3082 | P35: 8 | Q35: 10 | R35: 9 | S35: 9 | T35: 9 | U35: 9 | V35: 9 | W35: =IF(G35>P35,"Y",IF(H35>Q35,"Y",IF(I35>R35,"Y",IF(J35>S35,"Y",IF(K35>T35,"Y",IF(L35>U35,"Y",IF(M35>V35,"Y","N"))))))) -> Y | X35: =IF(W35="Y",MAX((G35-P35),(H35-Q35),(I35-R35),(J35-S35),(K35-T35),(L35-U35),(M35-V35))/10,0) -> 0.025 | Y35: =IF(X35<5%,"0-4.9%",IF(X35<25%,"5-25%",IF(X35<50%,"25-50%","Over 50%"))) -> 0-4.9% | Z35: Perishable
A36: =A35+1 -> 20 | B36: 0.35833333 | C36: UAS 906V | D36: =IF(COUNT(G36:M36)>3,10,IF(COUNT(G36:M36)>2,9,7)) -> 10 | E36: 6 | F36: 1*22-222 | G36: 6.2 | H36: 9.55 | I36: 7.3 | J36: 8.45 | K36: 7.55 | L36: 7.5 | N36: =SUM(G36:M36) -> 46.55 | O36: =(N36/8.16)^4.5 -> 2529.4894 | P36: 8 | Q36: 10 | R36: 9 | S36: 9 | T36: 9 | U36: 9 | V36: 9 | W36: =IF(G36>P36,"Y",IF(H36>Q36,"Y",IF(I36>R36,"Y",IF(J36>S36,"Y",IF(K36>T36,"Y",IF(L36>U36,"Y",IF(M36>V36,"Y","N"))))))) -> N | X36: =IF(W36="Y",MAX((G36-P36),(H36-Q36),(I36-R36),(J36-S36),(K36-T36),(L36-U36),(M36-V36))/10,0) -> 0 | Y36: =IF(X36<5%,"0-4.9%",IF(X36<25%,"5-25%",IF(X36<50%,"25-50%","Over 50%"))) -> 0-4.9% | Z36: Household retail products
A37: =A36+1 -> 21 | B37: 0.36805556 | C37: 9460 AB19 | D37: =IF(COUNT(G37:M37)>3,10,IF(COUNT(G37:M37)>2,9,7)) -> 10 | E37: 6 | F37: 1*22-222 | G37: 5.15 | H37: 7.7 | I37: 5.05 | J37: 9.1 | K37: 7.85 | L37: 8.75 | N37: =SUM(G37:M37) -> 43.6 | O37: =(N37/8.16)^4.5 -> 1884.0112 | P37: 8 | Q37: 10 | R37: 9 | S37: 9 | T37: 9 | U37: 9 | V37: 9 | W37: =IF(G37>P37,"Y",IF(H37>Q37,"Y",IF(I37>R37,"Y",IF(J37>S37,"Y",IF(K37>T37,"Y",IF(L37>U37,"Y",IF(M37>V37,"Y","N"))))))) -> Y | X37: =IF(W37="Y",MAX((G37-P37),(H37-Q37),(I37-R37),(J37-S37),(K37-T37),(L37-U37),(M37-V37))/10,0) -> 0.01 | Y37: =IF(X37<5%,"0-4.9%",IF(X37<25%,"5-25%",IF(X37<50%,"25-50%","Over 50%"))) -> 0-4.9% | Z37: Livestock
A38: =A37+1 -> 22 | B38: 0.44166667 | C38: UAN 917J | D38: =IF(COUNT(G38:M38)>3,10,IF(COUNT(G38:M38)>2,9,7)) -> 10 | E38: 4 | F38: 11*21 | G38: 7 | H38: 5.6 | I38: 10.25 | J38: 7.3 | N38: =SUM(G38:M38) -> 30.15 | O38: =(N38/8.16)^4.5 -> 358.25083 | P38: 8 | Q38: 10 | R38: 9 | S38: 9 | T38: 9 | U38: 9 | V38: 9 | W38: =IF(G38>P38,"Y",IF(H38>Q38,"Y",IF(I38>R38,"Y",IF(J38>S38,"Y",IF(K38>T38,"Y",IF(L38>U38,"Y",IF(M38>V38,"Y","N"))))))) -> Y | X38: =IF(W38="Y",MAX((G38-P38),(H38-Q38),(I38-R38),(J38-S38),(K38-T38),(L38-U38),(M38-V38))/10,0) -> 0.125 | Y38: =IF(X38<5%,"0-4.9%",IF(X38<25%,"5-25%",IF(X38<50%,"25-50%","Over 50%"))) -> 5-25% | Z38: Forestry products
A39: =A38+1 -> 23 | B39: 0.44444444 | C39: KCJ 660D | D39: =IF(COUNT(G39:M39)>3,10,IF(COUNT(G39:M39)>2,9,7)) -> 10 | E39: 6 | F39: 1*22-212 | G39: 5.35 | H39: 8.95 | I39: 4.75 | J39: 9.7 | K39: 8.15 | L39: 6.7 | N39: =SUM(G39:M39) -> 43.6 | O39: =(N39/8.16)^4.5 -> 1884.0112 | P39: 8 | Q39: 10 | R39: 9 | S39: 9 | T39: 9 | U39: 9 | V39: 9 | W39: =IF(G39>P39,"Y",IF(H39>Q39,"Y",IF(I39>R39,"Y",IF(J39>S39,"Y",IF(K39>T39,"Y",IF(L39>U39,"Y",IF(M39>V39,"Y","N"))))))) -> Y | X39: =IF(W39="Y",MAX((G39-P39),(H39-Q39),(I39-R39),(J39-S39),(K39-T39),(L39-U39),(M39-V39))/10,0) -> 0.07 | Y39: =IF(X39<5%,"0-4.9%",IF(X39<25%,"5-25%",IF(X39<50%,"25-50%","Over 50%"))) -> 5-25% | Z39: Household retail products
A40: =A39+1 -> 24 | B40: 0.46388889 | C40: UBB 652Z | D40: =IF(COUNT(G40:M40)>3,10,IF(COUNT(G40:M40)>2,9,7)) -> 10 | E40: 6 | F40: 1*12-111 | G40: 5.85 | H40: 5.9 | I40: 9.6 | J40: 8.15 | K40: 8.1 | L40: 7.7 | N40: =SUM(G40:M40) -> 45.3 | O40: =(N40/8.16)^4.5 -> 2237.8769 | P40: 8 | Q40: 10 | R40: 9 | S40: 9 | T40: 9 | U40: 9 | V40: 9 | W40: =IF(G40>P40,"Y",IF(H40>Q40,"Y",IF(I40>R40,"Y",IF(J40>S40,"Y",IF(K40>T40,"Y",IF(L40>U40,"Y",IF(M40>V40,"Y","N"))))))) -> Y | X40: =IF(W40="Y",MAX((G40-P40),(H40-Q40),(I40-R40),(J40-S40),(K40-T40),(L40-U40),(M40-V40))/10,0) -> 0.06 | Y40: =IF(X40<5%,"0-4.9%",IF(X40<25%,"5-25%",IF(X40<50%,"25-50%","Over 50%"))) -> 5-25% | Z40: Construction Material
A41: =A40+1 -> 25 | B41: 0.47638889 | C41: KBU 420G | D41: =IF(COUNT(G41:M41)>3,10,IF(COUNT(G41:M41)>2,9,7)) -> 10 | E41: 6 | F41: 1*12-222 | G41: 5 | H41: 4.1 | I41: 6.1 | J41: 6.35 | K41: 5.5 | L41: 5.7 | N41: =SUM(G41:M41) -> 32.75 | O41: =(N41/8.16)^4.5 -> 519.81063 | P41: 8 | Q41: 10 | R41: 9 | S41: 9 | T41: 9 | U41: 9 | V41: 9 | W41: =IF(G41>P41,"Y",IF(H41>Q41,"Y",IF(I41>R41,"Y",IF(J41>S41,"Y",IF(K41>T41,"Y",IF(L41>U41,"Y",IF(M41>V41,"Y","N"))))))) -> N | X41: =IF(W41="Y",MAX((G41-P41),(H41-Q41),(I41-R41),(J41-S41),(K41-T41),(L41-U41),(M41-V41))/10,0) -> 0 | Y41: =IF(X41<5%,"0-4.9%",IF(X41<25%,"5-25%",IF(X41<50%,"25-50%","Over 50%"))) -> 0-4.9% | Z41: Construction Material
A42: =A41+1 -> 26 | B42: 0.48611111 | C42: KBT 973S | D42: =IF(COUNT(G42:M42)>3,10,IF(COUNT(G42:M42)>2,9,7)) -> 10 | E42: 6 | F42: 1*22-222 | G42: 5.4 | H42: 6.9 | I42: 6.5 | J42: 5.5 | K42: 5.5 | L42: 5.85 | N42: =SUM(G42:M42) -> 35.65 | O42: =(N42/8.16)^4.5 -> 761.48647 | P42: 8 | Q42: 10 | R42: 9 | S42: 9 | T42: 9 | U42: 9 | V42: 9 | W42: =IF(G42>P42,"Y",IF(H42>Q42,"Y",IF(I42>R42,"Y",IF(J42>S42,"Y",IF(K42>T42,"Y",IF(L42>U42,"Y",IF(M42>V42,"Y","N"))))))) -> N | X42: =IF(W42="Y",MAX((G42-P42),(H42-Q42),(I42-R42),(J42-S42),(K42-T42),(L42-U42),(M42-V42))/10,0) -> 0 | Y42: =IF(X42<5%,"0-4.9%",IF(X42<25%,"5-25%",IF(X42<50%,"25-50%","Over 50%"))) -> 0-4.9% | Z42: Household retail products
...

Sheet Kasese-Mba
A2: AXLE LOAD SURVEY FORM
A3: Date: | C3: 43766 | D3: Station Name: | E3: Rubirizi | G3: Direction: | H3: Mbarara-Kasese
A5: S/No. | B5: Time | C5: Reg. Number | D5: Vehicle Type | E5: Number of Axles | F5: Axle Configuration | G5: TONNES | N5: Total (Tonnes) | O5: Total (ESA's) | P5: Load limit (Tonnes) | W5: OVERLOADED? | X5: Overloaded by? | Y5: Overload Bands | Z5: COMMENTS
G6: AXLE 1 | H6: AXLE 2 | I6: AXLE 3 | J6: AXLE 4 | K6: AXLE 5 | L6: AXLE 6 | M6: AXLE 7 | P6: Axle 1 | Q6: Axle 2 | R6: Axle 3 | S6: Axle 4 | T6: Axle 5 | U6: Axle 6 | V6: Axle 7
A7: =A6+1 -> 1 | B7: 0.54583333 | C7: UAY 764P | D7: =IF(COUNT(G7:M7)>3,10,IF(COUNT(G7:M7)>2,9,7)) -> 7 | E7: 2 | F7: 1*2 | G7: 5.05 | H7: 11.3 | N7: =SUM(G7:M7) -> 16.35 | O7: =(N7/8.16)^4.5 -> 22.815195 | P7: 8 | Q7: 10 | R7: 9 | S7: 9 | T7: 9 | U7: 9 | V7: 9 | W7: =IF(G7>P7,"Y",IF(H7>Q7,"Y",IF(I7>R7,"Y",IF(J7>S7,"Y",IF(K7>T7,"Y",IF(L7>U7,"Y",IF(M7>V7,"Y","N"))))))) -> Y | X7: =IF(W7="Y",MAX((G7-P7),(H7-Q7),(I7-R7),(J7-S7),(K7-T7),(L7-U7),(M7-V7))/10,0) -> 0.13 | Y7: =IF(X7<5%,"0-4.9%",IF(X7<25%,"5-25%",IF(X7<50%,"25-50%","Over 50%"))) -> 5-25% | Z7: Agricultural produce
A8: =A7+1 -> 2 | B8: 0.64791667 | C8: RAC 460B | D8: =IF(COUNT(G8:M8)>3,10,IF(COUNT(G8:M8)>2,9,7)) -> 7 | E8: 2 | F8: 1*2 | G8: 5.4 | H8: 11.8 | N8: =SUM(G8:M8) -> 17.2 | O8: =(N8/8.16)^4.5 -> 28.659743 | P8: 8 | Q8: 10 | R8: 9 | S8: 9 | T8: 9 | U8: 9 | V8: 9 | W8: =IF(G8>P8,"Y",IF(H8>Q8,"Y",IF(I8>R8,"Y",IF(J8>S8,"Y",IF(K8>T8,"Y",IF(L8>U8,"Y",IF(M8>V8,"Y","N"))))))) -> Y | X8: =IF(W8="Y",MAX((G8-P8),(H8-Q8),(I8-R8),(J8-S8),(K8-T8),(L8-U8),(M8-V8))/10,0) -> 0.18 | Y8: =IF(X8<5%,"0-4.9%",IF(X8<25%,"5-25%",IF(X8<50%,"25-50%","Over 50%"))) -> 5-25% | Z8: Agricultural produce
A9: =A8+1 -> 3 | B9: 0.65902778 | C9: UAK 689H | D9: =IF(COUNT(G9:M9)>3,10,IF(COUNT(G9:M9)>2,9,7)) -> 7 | E9: 2 | F9: 1*2 | G9: 4.5 | H9: 9.95 | N9: =SUM(G9:M9) -> 14.45 | O9: =(N9/8.16)^4.5 -> 13.085779 | P9: 8 | Q9: 10 | R9: 9 | S9: 9 | T9: 9 | U9: 9 | V9: 9 | W9: =IF(G9>P9,"Y",IF(H9>Q9,"Y",IF(I9>R9,"Y",IF(J9>S9,"Y",IF(K9>T9,"Y",IF(L9>U9,"Y",IF(M9>V9,"Y","N"))))))) -> N | X9: =IF(W9="Y",MAX((G9-P9),(H9-Q9),(I9-R9),(J9-S9),(K9-T9),(L9-U9),(M9-V9))/10,0) -> 0 | Y9: =IF(X9<5%,"0-4.9%",IF(X9<25%,"5-25%",IF(X9<50%,"25-50%","Over 50%"))) -> 0-4.9% | Z9: Agricultural produce
A10: =A9+1 -> 4 | B10: 0.68541667 | C10: UAP 344Q | D10: =IF(COUNT(G10:M10)>3,10,IF(COUNT(G10:M10)>2,9,7)) -> 7 | E10: 2 | F10: 1*2 | G10: 4.75 | H10: 11.3 | N10: =SUM(G10:M10) -> 16.05 | O10: =(N10/8.16)^4.5 -> 20.990943 | P10: 8 | Q10: 10 | R10: 9 | S10: 9 | T10: 9 | U10: 9 | V10: 9 | W10: =IF(G10>P10,"Y",IF(H10>Q10,"Y",IF(I10>R10,"Y",IF(J10>S10,"Y",IF(K10>T10,"Y",IF(L10>U10,"Y",IF(M10>V10,"Y","N"))))))) -> Y | X10: =IF(W10="Y",MAX((G10-P10),(H10-Q10),(I10-R10),(J10-S10),(K10-T10),(L10-U10),(M10-V10))/10,0) -> 0.13 | Y10: =IF(X10<5%,"0-4.9%",IF(X10<25%,"5-25%",IF(X10<50%,"25-50%","Over 50%"))) -> 5-25% | Z10: Agricultural produce
A11: =A10+1 -> 5 | B11: 0.73263889 | C11: UBC 266C | D11: =IF(COUNT(G11:M11)>3,10,IF(COUNT(G11:M11)>2,9,7)) -> 7 | E11: 2 | F11: 1*2 | G11: 4.7 | H11: 11.55 | N11: =SUM(G11:M11) -> 16.25 | O11: =(N11/8.16)^4.5 -> 22.193941 | P11: 8 | Q11: 10 | R11: 9 | S11: 9 | T11: 9 | U11: 9 | V11: 9 | W11: =IF(G11>P11,"Y",IF(H11>Q11,"Y",IF(I11>R11,"Y",IF(J11>S11,"Y",IF(K11>T11,"Y",IF(L11>U11,"Y",IF(M11>V11,"Y","N"))))))) -> Y | X11: =IF(W11="Y",MAX((G11-P11),(H11-Q11),(I11-R11),(J11-S11),(K11-T11),(L11-U11),(M11-V11))/10,0) -> 0.155 | Y11: =IF(X11<5%,"0-4.9%",IF(X11<25%,"5-25%",IF(X11<50%,"25-50%","Over 50%"))) -> 5-25% | Z11: Household retail products
A12: =A11+1 -> 6 | B12: 0.57638889 | C12: UAZ 623P | D12: =IF(COUNT(G12:M12)>3,10,IF(COUNT(G12:M12)>2,9,7)) -> 7 | E12: 2 | F12: 1*2 | G12: 2.9 | H12: 5.85 | N12: =SUM(G12:M12) -> 8.75 | O12: =(N12/8.16)^4.5 -> 1.3690854 | P12: 8 | Q12: 10 | R12: 9 | S12: 9 | T12: 9 | U12: 9 | V12: 9 | W12: =IF(G12>P12,"Y",IF(H12>Q12,"Y",IF(I12>R12,"Y",IF(J12>S12,"Y",IF(K12>T12,"Y",IF(L12>U12,"Y",IF(M12>V12,"Y","N"))))))) -> N | X12: =IF(W12="Y",MAX((G12-P12),(H12-Q12),(I12-R12),(J12-S12),(K12-T12),(L12-U12),(M12-V12))/10,0) -> 0 | Y12: =IF(X12<5%,"0-4.9%",IF(X12<25%,"5-25%",IF(X12<50%,"25-50%","Over 50%"))) -> 0-4.9% | Z12: Construction Material
A13: =A12+1 -> 7 | B13: 0.6625 | C13: UBA 813R | D13: =IF(COUNT(G13:M13)>3,10,IF(COUNT(G13:M13)>2,9,7)) -> 7 | E13: 2 | F13: 1*2 | G13: 4 | H13: 12.45 | N13: =SUM(G13:M13) -> 16.45 | O13: =(N13/8.16)^4.5 -> 23.449892 | P13: 8 | Q13: 10 | R13: 9 | S13: 9 | T13: 9 | U13: 9 | V13: 9 | W13: =IF(G13>P13,"Y",IF(H13>Q13,"Y",IF(I13>R13,"Y",IF(J13>S13,"Y",IF(K13>T13,"Y",IF(L13>U13,"Y",IF(M13>V13,"Y","N"))))))) -> Y | X13: =IF(W13="Y",MAX((G13-P13),(H13-Q13),(I13-R13),(J13-S13),(K13-T13),(L13-U13),(M13-V13))/10,0) -> 0.245 | Y13: =IF(X13<5%,"0-4.9%",IF(X13<25%,"5-25%",IF(X13<50%,"25-50%","Over 50%"))) -> 5-25% | Z13: Construction Material
A14: =A13+1 -> 8 | B14: 0.66597222 | C14: UAX 936L | D14: =IF(COUNT(G14:M14)>3,10,IF(COUNT(G14:M14)>2,9,7)) -> 7 | E14: 2 | F14: 1*2 | G14: 3.8 | H14: 9.9 | N14: =SUM(G14:M14) -> 13.7 | O14: =(N14/8.16)^4.5 -> 10.295249 | P14: 8 | Q14: 10 | R14: 9 | S14: 9 | T14: 9 | U14: 9 | V14: 9 | W14: =IF(G14>P14,"Y",IF(H14>Q14,"Y",IF(I14>R14,"Y",IF(J14>S14,"Y",IF(K14>T14,"Y",IF(L14>U14,"Y",IF(M14>V14,"Y","N"))))))) -> N | X14: =IF(W14="Y",MAX((G14-P14),(H14-Q14),(I14-R14),(J14-S14),(K14-T14),(L14-U14),(M14-V14))/10,0) -> 0 | Y14: =IF(X14<5%,"0-4.9%",IF(X14<25%,"5-25%",IF(X14<50%,"25-50%","Over 50%"))) -> 0-4.9% | Z14: Construction Material
A15: =A14+1 -> 9 | B15: 0.66666667 | C15: UAV 799U | D15: =IF(COUNT(G15:M15)>3,10,IF(COUNT(G15:M15)>2,9,7)) -> 7 | E15: 2 | F15: 1*2 | G15: 6.2 | H15: 11.2 | N15: =SUM(G15:M15) -> 17.4 | O15: =(N15/8.16)^4.5 -> 30.190194 | P15: 8 | Q15: 10 | R15: 9 | S15: 9 | T15: 9 | U15: 9 | V15: 9 | W15: =IF(G15>P15,"Y",IF(H15>Q15,"Y",IF(I15>R15,"Y",IF(J15>S15,"Y",IF(K15>T15,"Y",IF(L15>U15,"Y",IF(M15>V15,"Y","N"))))))) -> Y | X15: =IF(W15="Y",MAX((G15-P15),(H15-Q15),(I15-R15),(J15-S15),(K15-T15),(L15-U15),(M15-V15))/10,0) -> 0.12 | Y15: =IF(X15<5%,"0-4.9%",IF(X15<25%,"5-25%",IF(X15<50%,"25-50%","Over 50%"))) -> 5-25% | Z15: Construction Material
A16: =A15+1 -> 10 | B16: 0.67430556 | C16: UAZ 357F | D16: =IF(COUNT(G16:M16)>3,10,IF(COUNT(G16:M16)>2,9,7)) -> 7 | E16: 2 | F16: 1*2 | G16: 5.8 | H16: 11.6 | N16: =SUM(G16:M16) -> 17.4 | O16: =(N16/8.16)^4.5 -> 30.190194 | P16: 8 | Q16: 10 | R16: 9 | S16: 9 | T16: 9 | U16: 9 | V16: 9 | W16: =IF(G16>P16,"Y",IF(H16>Q16,"Y",IF(I16>R16,"Y",IF(J16>S16,"Y",IF(K16>T16,"Y",IF(L16>U16,"Y",IF(M16>V16,"Y","N"))))))) -> Y | X16: =IF(W16="Y",MAX((G16-P16),(H16-Q16),(I16-R16),(J16-S16),(K16-T16),(L16-U16),(M16-V16))/10,0) -> 0.16 | Y16: =IF(X16<5%,"0-4.9%",IF(X16<25%,"5-25%",IF(X16<50%,"25-50%","Over 50%"))) -> 5-25% | Z16: Construction Material
A17: =A16+1 -> 11 | B17: 0.55208333 | C17: UAY 764P | D17: =IF(COUNT(G17:M17)>3,10,IF(COUNT(G17:M17)>2,9,7)) -> 7 | E17: 2 | F17: 1*2 | G17: 5.1 | H17: 10.95 | N17: =SUM(G17:M17) -> 16.05 | O17: =(N17/8.16)^4.5 -> 20.990943 | P17: 8 | Q17: 10 | R17: 9 | S17: 9 | T17: 9 | U17: 9 | V17: 9 | W17: =IF(G17>P17,"Y",IF(H17>Q17,"Y",IF(I17>R17,"Y",IF(J17>S17,"Y",IF(K17>T17,"Y",IF(L17>U17,"Y",IF(M17>V17,"Y","N"))))))) -> Y | X17: =IF(W17="Y",MAX((G17-P17),(H17-Q17),(I17-R17),(J17-S17),(K17-T17),(L17-U17),(M17-V17))/10,0) -> 0.095 | Y17: =IF(X17<5%,"0-4.9%",IF(X17<25%,"5-25%",IF(X17<50%,"25-50%","Over 50%"))) -> 5-25% | Z17: Construction Material
A18: 1 | B18: 0.38263889 | C18: RAC 404Y | D18: =IF(COUNT(G18:M18)>3,10,IF(COUNT(G18:M18)>2,9,7)) -> 10 | E18: 6 | F18: 1*12-111 | G18: 5.65 | H18: 6.55 | I18: 9.9 | J18: 6.95 | K18: 8.15 | L18: 8.1 | N18: =SUM(G18:M18) -> 45.3 | O18: =(N18/8.16)^4.5 -> 2237.8769 | P18: 8 | Q18: 10 | R18: 9 | S18: 9 | T18: 9 | U18: 9 | V18: 9 | W18: =IF(G18>P18,"Y",IF(H18>Q18,"Y",IF(I18>R18,"Y",IF(J18>S18,"Y",IF(K18>T18,"Y",IF(L18>U18,"Y",IF(M18>V18,"Y","N"))))))) -> Y | X18: =IF(W18="Y",MAX((G18-P18),(H18-Q18),(I18-R18),(J18-S18),(K18-T18),(L18-U18),(M18-V18))/10,0) -> 0.09 | Y18: =IF(X18<5%,"0-4.9%",IF(X18<25%,"5-25%",IF(X18<50%,"25-50%","Over 50%"))) -> 5-25% | Z18: Construction Material
A19: =A18+1 -> 2 | B19: 0.38402778 | C19: RAC 890L | D19: =IF(COUNT(G19:M19)>3,10,IF(COUNT(G19:M19)>2,9,7)) -> 10 | E19: 7 | F19: 1*22+22*22 | G19: 8.25 | H19: 9.05 | I19: 7.7 | J19: 6.95 | K19: 5.9 | L19: 5.75 | M19: 5.95 | N19: =SUM(G19:M19) -> 49.55 | O19: =(N19/8.16)^4.5 -> 3350.3544 | P19: 8 | Q19: 10 | R19: 9 | S19: 9 | T19: 9 | U19: 9 | V19: 9 | W19: =IF(G19>P19,"Y",IF(H19>Q19,"Y",IF(I19>R19,"Y",IF(J19>S19,"Y",IF(K19>T19,"Y",IF(L19>U19,"Y",IF(M19>V19,"Y","N"))))))) -> Y | X19: =IF(W19="Y",MAX((G19-P19),(H19-Q19),(I19-R19),(J19-S19),(K19-T19),(L19-U19),(M19-V19))/10,0) -> 0.025 | Y19: =IF(X19<5%,"0-4.9%",IF(X19<25%,"5-25%",IF(X19<50%,"25-50%","Over 50%"))) -> 0-4.9% | Z19: Construction Material
A20: =A19+1 -> 3 | B20: 0.38819444 | C20: RAD 019B | D20: =IF(COUNT(G20:M20)>3,10,IF(COUNT(G20:M20)>2,9,7)) -> 10 | E20: 7 | F20: 1*22+22*22 | G20: 8.85 | H20: 7.1 | I20: 7.25 | J20: 7.3 | K20: 7.35 | L20: 7.2 | M20: 5 | N20: =SUM(G20:M20) -> 50.05 | O20: =(N20/8.16)^4.5 -> 3505.1988 | P20: 8 | Q20: 10 | R20: 9 | S20: 9 | T20: 9 | U20: 9 | V20: 9 | W20: =IF(G20>P20,"Y",IF(H20>Q20,"Y",IF(I20>R20,"Y",IF(J20>S20,"Y",IF(K20>T20,"Y",IF(L20>U20,"Y",IF(M20>V20,"Y","N"))))))) -> Y | X20: =IF(W20="Y",MAX((G20-P20),(H20-Q20),(I20-R20),(J20-S20),(K20-T20),(L20-U20),(M20-V20))/10,0) -> 0.085 | Y20: =IF(X20<5%,"0-4.9%",IF(X20<25%,"5-25%",IF(X20<50%,"25-50%","Over 50%"))) -> 5-25% | Z20: Construction Material
A21: =A20+1 -> 4 | B21: 0.39027778 | C21: RAC 126U | D21: =IF(COUNT(G21:M21)>3,10,IF(COUNT(G21:M21)>2,9,7)) -> 10 | E21: 6 | F21: 1*22-222 | G21: 5.45 | H21: 7.75 | I21: 7.9 | J21: 8.6 | K21: 7.6 | L21: 6.75 | N21: =SUM(G21:M21) -> 44.05 | O21: =(N21/8.16)^4.5 -> 1973.1082 | P21: 8 | Q21: 10 | R21: 9 | S21: 9 | T21: 9 | U21: 9 | V21: 9 | W21: =IF(G21>P21,"Y",IF(H21>Q21,"Y",IF(I21>R21,"Y",IF(J21>S21,"Y",IF(K21>T21,"Y",IF(L21>U21,"Y",IF(M21>V21,"Y","N"))))))) -> N | X21: =IF(W21="Y",MAX((G21-P21),(H21-Q21),(I21-R21),(J21-S21),(K21-T21),(L21-U21),(M21-V21))/10,0) -> 0 | Y21: =IF(X21<5%,"0-4.9%",IF(X21<25%,"5-25%",IF(X21<50%,"25-50%","Over 50%"))) -> 0-4.9% | Z21: Construction Material
A22: =A21+1 -> 5 | B22: 0.40625 | C22: UBA 918B | D22: =IF(COUNT(G22:M22)>3,10,IF(COUNT(G22:M22)>2,9,7)) -> 10 | E22: 6 | F22: 1*12-222 | G22: 5.1 | H22: 6.45 | I22: 9.75 | J22: 7.95 | K22: 7.45 | L22: 6.4 | N22: =SUM(G22:M22) -> 43.1 | O22: =(N22/8.16)^4.5 -> 1788.7185 | P22: 8 | Q22: 10 | R22: 9 | S22: 9 | T22: 9 | U22: 9 | V22: 9 | W22: =IF(G22>P22,"Y",IF(H22>Q22,"Y",IF(I22>R22,"Y",IF(J22>S22,"Y",IF(K22>T22,"Y",IF(L22>U22,"Y",IF(M22>V22,"Y","N"))))))) -> Y | X22: =IF(W22="Y",MAX((G22-P22),(H22-Q22),(I22-R22),(J22-S22),(K22-T22),(L22-U22),(M22-V22))/10,0) -> 0.075 | Y22: =IF(X22<5%,"0-4.9%",IF(X22<25%,"5-25%",IF(X22<50%,"25-50%","Over 50%"))) -> 5-25% | Z22: Construction Material
A23: =A22+1 -> 6 | B23: 0.42430556 | C23: RAB 567I | D23: =IF(COUNT(G23:M23)>3,10,IF(COUNT(G23:M23)>2,9,7)) -> 10 | E23: 6 | F23: 1*22-222 | G23: 4.8 | H23: 9.1 | I23: 8.05 | J23: 7.75 | K23: 6.85 | L23: 6.8 | N23: =SUM(G23:M23) -> 43.35 | O23: =(N23/8.16)^4.5 -> 1835.884 | P23: 8 | Q23: 10 | R23: 9 | S23: 9 | T23: 9 | U23: 9 | V23: 9 | W23: =IF(G23>P23,"Y",IF(H23>Q23,"Y",IF(I23>R23,"Y",IF(J23>S23,"Y",IF(K23>T23,"Y",IF(L23>U23,"Y",IF(M23>V23,"Y","N"))))))) -> N | X23: =IF(W23="Y",MAX((G23-P23),(H23-Q23),(I23-R23),(J23-S23),(K23-T23),(L23-U23),(M23-V23))/10,0) -> 0 | Y23: =IF(X23<5%,"0-4.9%",IF(X23<25%,"5-25%",IF(X23<50%,"25-50%","Over 50%"))) -> 0-4.9% | Z23: Construction Material
A24: =A23+1 -> 7 | B24: 0.44305556 | C24: UAV 753D | D24: =IF(COUNT(G24:M24)>3,10,IF(COUNT(G24:M24)>2,9,7)) -> 10 | E24: 7 | F24: 1*22+22*22 | G24: 7.35 | H24: 7.45 | I24: 7.25 | J24: 8.1 | K24: 7.65 | L24: 7.3 | M24: 5.9 | N24: =SUM(G24:M24) -> 51 | O24: =(N24/8.16)^4.5 -> 3814.6973 | P24: 8 | Q24: 10 | R24: 9 | S24: 9 | T24: 9 | U24: 9 | V24: 9 | W24: =IF(G24>P24,"Y",IF(H24>Q24,"Y",IF(I24>R24,"Y",IF(J24>S24,"Y",IF(K24>T24,"Y",IF(L24>U24,"Y",IF(M24>V24,"Y","N"))))))) -> N | X24: =IF(W24="Y",MAX((G24-P24),(H24-Q24),(I24-R24),(J24-S24),(K24-T24),(L24-U24),(M24-V24))/10,0) -> 0 | Y24: =IF(X24<5%,"0-4.9%",IF(X24<25%,"5-25%",IF(X24<50%,"25-50%","Over 50%"))) -> 0-4.9% | Z24: Construction Material
A25: =A24+1 -> 8 | B25: 0.47291667 | C25: RAD 209B | D25: =IF(COUNT(G25:M25)>3,10,IF(COUNT(G25:M25)>2,9,7)) -> 10 | E25: 7 | F25: 1*22+22*22 | G25: 6.7 | H25: 7.45 | I25: 8.05 | J25: 6.2 | K25: 7.25 | L25: 8 | M25: 8.2 | N25: =SUM(G25:M25) -> 51.85 | O25: =(N25/8.16)^4.5 -> 4109.2608 | P25: 8 | Q25: 10 | R25: 9 | S25: 9 | T25: 9 | U25: 9 | V25: 9 | W25: =IF(G25>P25,"Y",IF(H25>Q25,"Y",IF(I25>R25,"Y",IF(J25>S25,"Y",IF(K25>T25,"Y",IF(L25>U25,"Y",IF(M25>V25,"Y","N"))))))) -> N | X25: =IF(W25="Y",MAX((G25-P25),(H25-Q25),(I25-R25),(J25-S25),(K25-T25),(L25-U25),(M25-V25))/10,0) -> 0 | Y25: =IF(X25<5%,"0-4.9%",IF(X25<25%,"5-25%",IF(X25<50%,"25-50%","Over 50%"))) -> 0-4.9% | Z25: Construction Material
A26: =A25+1 -> 9 | B26: 0.57013889 | C26: RAB 182P | D26: =IF(COUNT(G26:M26)>3,10,IF(COUNT(G26:M26)>2,9,7)) -> 10 | E26: 7 | F26: 1*22+22*22 | G26: 8.15 | H26: 7.15 | I26: 6.8 | J26: 7.1 | K26: 7 | L26: 5.85 | M26: 6.6 | N26: =SUM(G26:M26) -> 48.65 | O26: =(N26/8.16)^4.5 -> 3085.0847 | P26: 8 | Q26: 10 | R26: 9 | S26: 9 | T26: 9 | U26: 9 | V26: 9 | W26: =IF(G26>P26,"Y",IF(H26>Q26,"Y",IF(I26>R26,"Y",IF(J26>S26,"Y",IF(K26>T26,"Y",IF(L26>U26,"Y",IF(M26>V26,"Y","N"))))))) -> Y | X26: =IF(W26="Y",MAX((G26-P26),(H26-Q26),(I26-R26),(J26-S26),(K26-T26),(L26-U26),(M26-V26))/10,0) -> 0.015 | Y26: =IF(X26<5%,"0-4.9%",IF(X26<25%,"5-25%",IF(X26<50%,"25-50%","Over 50%"))) -> 0-4.9% | Z26: Construction Material
A27: =A26+1 -> 10 | B27: 0.57847222 | C27: RAB 524R | D27: =IF(COUNT(G27:M27)>3,10,IF(COUNT(G27:M27)>2,9,7)) -> 10 | E27: 7 | F27: 1*22+22*22 | G27: 8.05 | H27: 10.05 | I27: 7.95 | J27: 8 | K27: 8.75 | L27: 5.6 | M27: 5.65 | N27: =SUM(G27:M27) -> 54.05 | O27: =(N27/8.16)^4.5 -> 4954.2159 | P27: 8 | Q27: 10 | R27: 9 | S27: 9 | T27: 9 | U27: 9 | V27: 9 | W27: =IF(G27>P27,"Y",IF(H27>Q27,"Y",IF(I27>R27,"Y",IF(J27>S27,"Y",IF(K27>T27,"Y",IF(L27>U27,"Y",IF(M27>V27,"Y","N"))))))) -> Y | X27: =IF(W27="Y",MAX((G27-P27),(H27-Q27),(I27-R27),(J27-S27),(K27-T27),(L27-U27),(M27-V27))/10,0) -> 0.005 | Y27: =IF(X27<5%,"0-4.9%",IF(X27<25%,"5-25%",IF(X27<50%,"25-50%","Over 50%"))) -> 0-4.9% | Z27: Construction Material
A28: =A27+1 -> 11 | B28: 0.64444444 | C28: UBB 101A | D28: =IF(COUNT(G28:M28)>3,10,IF(COUNT(G28:M28)>2,9,7)) -> 10 | E28: 6 | F28: 1822-222 | G28: 6.45 | H28: 7.55 | I28: 7.15 | J28: 6.05 | K28: 7.2 | L28: 7.9 | N28: =SUM(G28:M28) -> 42.3 | O28: =(N28/8.16)^4.5 -> 1644.0913 | P28: 8 | Q28: 10 | R28: 9 | S28: 9 | T28: 9 | U28: 9 | V28: 9 | W28: =IF(G28>P28,"Y",IF(H28>Q28,"Y",IF(I28>R28,"Y",IF(J28>S28,"Y",IF(K28>T28,"Y",IF(L28>U28,"Y",IF(M28>V28,"Y","N"))))))) -> N | X28: =IF(W28="Y",MAX((G28-P28),(H28-Q28),(I28-R28),(J28-S28),(K28-T28),(L28-U28),(M28-V28))/10,0) -> 0 | Y28: =IF(X28<5%,"0-4.9%",IF(X28<25%,"5-25%",IF(X28<50%,"25-50%","Over 50%"))) -> 0-4.9% | Z28: Construction Material
A29: =A28+1 -> 12 | B29: 0.67916667 | C29: RAD 177S | D29: =IF(COUNT(G29:M29)>3,10,IF(COUNT(G29:M29)>2,9,7)) -> 10 | E29: 6 | F29: 1*22-111 | G29: 6.25 | H29: 7.25 | I29: 8 | J29: 8.05 | K29: 7.25 | L29: 7.25 | N29: =SUM(G29:M29) -> 44.05 | O29: =(N29/8.16)^4.5 -> 1973.1082 | P29: 8 | Q29: 10 | R29: 9 | S29: 9 | T29: 9 | U29: 9 | V29: 9 | W29: =IF(G29>P29,"Y",IF(H29>Q29,"Y",IF(I29>R29,"Y",IF(J29>S29,"Y",IF(K29>T29,"Y",IF(L29>U29,"Y",IF(M29>V29,"Y","N"))))))) -> N | X29: =IF(W29="Y",MAX((G29-P29),(H29-Q29),(I29-R29),(J29-S29),(K29-T29),(L29-U29),(M29-V29))/10,0) -> 0 | Y29: =IF(X29<5%,"0-4.9%",IF(X29<25%,"5-25%",IF(X29<50%,"25-50%","Over 50%"))) -> 0-4.9% | Z29: Construction Material
A30: 1 | B30: 0.35486111 | C30: UBB 094A | D30: =IF(COUNT(G30:M30)>3,10,IF(COUNT(G30:M30)>2,9,7)) -> 10 | E30: 6 | F30: 1*22-222 | G30: 6.5 | H30: 7.75 | I30: 7.15 | J30: 7.75 | K30: 7.3 | L30: 8.15 | N30: =SUM(G30:M30) -> 44.6 | O30: =(N30/8.16)^4.5 -> 2086.4172 | P30: 8 | Q30: 10 | R30: 9 | S30: 9 | T30: 9 | U30: 9 | V30: 9 | W30: =IF(G30>P30,"Y",IF(H30>Q30,"Y",IF(I30>R30,"Y",IF(J30>S30,"Y",IF(K30>T30,"Y",IF(L30>U30,"Y",IF(M30>V30,"Y","N"))))))) -> N | X30: =IF(W30="Y",MAX((G30-P30),(H30-Q30),(I30-R30),(J30-S30),(K30-T30),(L30-U30),(M30-V30))/10,0) -> 0 | Y30: =IF(X30<5%,"0-4.9%",IF(X30<25%,"5-25%",IF(X30<50%,"25-50%","Over 50%"))) -> 0-4.9% | Z30: Construction Material
A31: 2 | B31: 0.37430556 | C31: RAD829A | D31: =IF(COUNT(G31:M31)>3,10,IF(COUNT(G31:M31)>2,9,7)) -> 10 | E31: 6 | F31: 1*22-222 | G31: 4.7 | H31: 9.1 | I31: 8.85 | J31: 7.7 | K31: 6.75 | L31: 9.45 | N31: =SUM(G31:M31) -> 46.55 | O31: =(N31/8.16)^4.5 -> 2529.4894 | P31: 8 | Q31: 10 | R31: 9 | S31: 9 | T31: 9 | U31: 9 | V31: 9 | W31: =IF(G31>P31,"Y",IF(H31>Q31,"Y",IF(I31>R31,"Y",IF(J31>S31,"Y",IF(K31>T31,"Y",IF(L31>U31,"Y",IF(M31>V31,"Y","N"))))))) -> Y | X31: =IF(W31="Y",MAX((G31-P31),(H31-Q31),(I31-R31),(J31-S31),(K31-T31),(L31-U31),(M31-V31))/10,0) -> 0.045 | Y31: =IF(X31<5%,"0-4.9%",IF(X31<25%,"5-25%",IF(X31<50%,"25-50%","Over 50%"))) -> 0-4.9% | Z31: Construction Material
A32: 3 | B32: 0.38263889 | C32: UBB 955V | D32: =IF(COUNT(G32:M32)>3,10,IF(COUNT(G32:M32)>2,9,7)) -> 10 | E32: 7 | F32: 1*22+22*22 | G32: 6.15 | H32: 6.45 | I32: 7.5 | J32: 7.95 | K32: 9.35 | L32: 7 | M32: 5.25 | N32: =SUM(G32:M32) -> 49.65 | O32: =(N32/8.16)^4.5 -> 3380.8891 | P32: 8 | Q32: 10 | R32: 9 | S32: 9 | T32: 9 | U32: 9 | V32: 9 | W32: =IF(G32>P32,"Y",IF(H32>Q32,"Y",IF(I32>R32,"Y",IF(J32>S32,"Y",IF(K32>T32,"Y",IF(L32>U32,"Y",IF(M32>V32,"Y","N"))))))) -> Y | X32: =IF(W32="Y",MAX((G32-P32),(H32-Q32),(I32-R32),(J32-S32),(K32-T32),(L32-U32),(M32-V32))/10,0) -> 0.035 | Y32: =IF(X32<5%,"0-4.9%",IF(X32<25%,"5-25%",IF(X32<50%,"25-50%","Over 50%"))) -> 0-4.9% | Z32: Construction Material
A33: =A32+1 -> 4 | B33: 0.38541667 | C33: RAC 050Q | D33: =IF(COUNT(G33:M33)>3,10,IF(COUNT(G33:M33)>2,9,7)) -> 10 | E33: 7 | F33: 1*22+22*22 | G33: 7.95 | H33: 8.3 | I33: 7.85 | J33: 6.35 | K33: 6.75 | L33: 7.15 | M33: 5.85 | N33: =SUM(G33:M33) -> 50.2 | O33: =(N33/8.16)^4.5 -> 3552.7203 | P33: 8 | Q33: 10 | R33: 9 | S33: 9 | T33: 9 | U33: 9 | V33: 9 | W33: =IF(G33>P33,"Y",IF(H33>Q33,"Y",IF(I33>R33,"Y",IF(J33>S33,"Y",IF(K33>T33,"Y",IF(L33>U33,"Y",IF(M33>V33,"Y","N"))))))) -> N | X33: =IF(W33="Y",MAX((G33-P33),(H33-Q33),(I33-R33),(J33-S33),(K33-T33),(L33-U33),(M33-V33))/10,0) -> 0 | Y33: =IF(X33<5%,"0-4.9%",IF(X33<25%,"5-25%",IF(X33<50%,"25-50%","Over 50%"))) -> 0-4.9% | Z33: Construction Material
A34: =A33+1 -> 5 | B34: 0.40833333 | C34: UAQ 604W | D34: =IF(COUNT(G34:M34)>3,10,IF(COUNT(G34:M34)>2,9,7)) -> 10 | E34: 6 | F34: 1*22-222 | G34: 5.25 | H34: 9.2 | I34: 7.3 | J34: 7.45 | K34: 6.4 | L34: 7.2 | N34: =SUM(G34:M34) -> 42.8 | O34: =(N34/8.16)^4.5 -> 1733.3699 | P34: 8 | Q34: 10 | R34: 9 | S34: 9 | T34: 9 | U34: 9 | V34: 9 | W34: =IF(G34>P34,"Y",IF(H34>Q34,"Y",IF(I34>R34,"Y",IF(J34>S34,"Y",IF(K34>T34,"Y",IF(L34>U34,"Y",IF(M34>V34,"Y","N"))))))) -> N | X34: =IF(W34="Y",MAX((G34-P34),(H34-Q34),(I34-R34),(J34-S34),(K34-T34),(L34-U34),(M34-V34))/10,0) -> 0 | Y34: =IF(X34<5%,"0-4.9%",IF(X34<25%,"5-25%",IF(X34<50%,"25-50%","Over 50%"))) -> 0-4.9% | Z34: Construction Material
