Workbook

Sheet DAY1
A1: AXLE LOAD SURVEY FORM
A2: Date: | D2: Station Name: | E2: NAKIBIZZI
A3: 43772 | H3: JINJA-KAMPALA
A4: S/No. | B4: Time | C4: Reg. Number | D4: Vehicle Type | E4: Number of Axles | F4: Axle Configuration | G4: Front | N4: Total (Tonnes) | O4: Total (ESA's) | P4: COMMENTS
G5: Axle 1 | H5: Axle 2 | I5: Axle 3 | J5: Axle 4 | K5: Axle 5 | L5: Axle 6 | M5: Axle 7
A6: 1 | B6: 0.40625 | C6: UBC 648D | D6: 12 | E6: 6 | F6: 1*22-222 | G6: 6.8 | H6: 7.8 | I6: 7.4 | J6: 7.3 | K6: 6.1 | L6: 6.3 | N6: =SUM(G6:M6) -> 41.7 | P6: AGRICULTURAL PRODUCTS
A7: 2 | B7: 0.41875 | C7: KAX 251 U | D7: 12 | E7: 6 | F7: 1*22-222 | G7: 5.55 | H7: 3.8 | I7: 7.6 | J7: 5.45 | K7: 5.1 | L7: 4.75 | N7: =SUM(G7:M7) -> 32.25 | P7: AGRICULTURAL PRODUCTS
A8: 3 | B8: 0.42361111 | C8: KAW 037 R | D8: 12 | E8: 6 | F8: 1*22-222 | G8: 5.1 | H8: 3.35 | I8: 10.2 | J8: 8.1 | K8: 7.9 | L8: 7.3 | N8: =SUM(G8:M8) -> 41.95 | P8: OTHERS
A9: 4 | B9: 0.4375 | C9: KCV 613 F | D9: 12 | E9: 6 | F9: 1*22-222 | G9: 5.7 | H9: 5.95 | I9: 8.9 | J9: 8.2 | K9: 6.6 | L9: 7.45 | N9: =SUM(G9:M9) -> 42.8 | P9: OTHERS
A10: 5 | B10: 0.44097222 | C10: UAY 484 B | D10: 7 | E10: 2 | F10: 1*2 | G10: 3.4 | H10: 8.55 | N10: =SUM(G10:M10) -> 11.95 | P10: OTHERS
A11: 6 | B11: 0.4625 | C11: A 2588A | D11: 13 | E11: 7 | F11: 1*22+22*22 | G11: 5.75 | H11: 5.1 | I11: 3.85 | J11: 5.45 | K11: 4.5 | L11: 5.75 | M11: 5.25 | N11: =SUM(G11:M11) -> 35.65 | P11: MINERAL ROCK
A12: 7 | B12: 0.47152778 | C12: UAX 416B | D12: 8 | E12: 3 | F12: 1*21 | G12: 7.1 | H12: 9.2 | I12: 5.8 | N12: =SUM(G12:M12) -> 22.1 | P12: PROCESSED FOODS
A13: 8 | B13: 0.49305556 | C13: KCN 135 Q | D13: 12 | E13: 6 | F13: 1*22-222 | G13: 4.9 | H13: 6.6 | I13: 6.75 | J13: 8.3 | K13: 8.25 | L13: 8.05 | N13: =SUM(G13:M13) -> 42.85 | P13: EQUIPMENT
A14: 9 | B14: 0.50833333 | C14: UAH 982 V | D14: 8 | E14: 3 | F14: 1*22 | G14: 7.45 | H14: 7.3 | I14: 7.75 | N14: =SUM(G14:M14) -> 22.5 | P14: FUEL
A15: 10 | B15: 0.52083333 | C15: UAN 676X | D15: 7 | E15: 2 | F15: 1*2 | G15: 3.9 | H15: 9.2 | N15: =SUM(G15:M15) -> 13.1 | P15: FERTILIZER
A16: 11 | B16: 0.52430556 | C16: UAG 982 T | D16: 10 | E16: 4 | F16: 1*222 | G16: 6.9 | H16: 10.1 | I16: 7.25 | J16: 2.6 | N16: =SUM(G16:M16) -> 26.85 | P16: PROCESSED FOODS
A17: 12 | B17: 0.52777778 | C17: KCT 248 R | D17: 12 | E17: 6 | F17: 1*22-222 | G17: 6.6 | H17: 5.25 | I17: 8.2 | J17: 7.05 | K17: 5.75 | L17: 6.85 | N17: =SUM(G17:M17) -> 39.7 | P17: MINERAL ROCK
A18: 13 | B18: 0.54652778 | C18: UAZ 536X | D18: 7 | E18: 2 | F18: 1*2 | G18: 3.25 | H18: 12.85 | N18: =SUM(G18:M18) -> 16.1 | P18: AGRICULTURAL PRODUCTS
A19: 14 | B19: 0.54722222 | C19: KBU 781S | D19: 12 | E19: 6 | F19: 1*22-222 | G19: 5.75 | H19: 5.4 | I19: 5.5 | J19: 6.3 | K19: 7.2 | L19: 5.3 | N19: =SUM(G19:M19) -> 35.45 | P19: OTHERS
A20: 15 | B20: 0.55555556 | C20: UAN 583A | D20: 7 | E20: 2 | F20: 1*2 | G20: 3.85 | H20: 9.1 | N20: =SUM(G20:M20) -> 12.95 | P20: PROCESSED FOODS
A21: 16 | B21: 0.60416667 | C21: UAM 548 H | D21: 10 | E21: 4 | F21: 1*222 | G21: 6.85 | H21: 8.6 | I21: 9.6 | J21: 2.75 | N21: =SUM(G21:M21) -> 27.8 | P21: PROCESSED FOODS
A22: 17 | B22: 0.60625 | C22: UBE 620S | D22: 10 | E22: 4 | F22: 11*22 | G22: 6.55 | H22: 8 | I22: 9 | J22: 7.8 | N22: =SUM(G22:M22) -> 31.35 | P22: BUILDING MATERIAL
A23: 18 | B23: 0.61944444 | C23: UAN 272 D | D23: 8 | E23: 3 | F23: 1*22 | G23: 5.3 | H23: 9.6 | I23: 9.3 | N23: =SUM(G23:M23) -> 24.2 | P23: PROCESSED FOODS
A24: 19 | B24: 0.63888889 | C24: UBD 675Y | D24: 7 | E24: 2 | F24: 1*2 | G24: 3.7 | H24: 9.75 | N24: =SUM(G24:M24) -> 13.45 | P24: AGRICULTURAL PRODUCTS
A25: 20 | B25: 0.64236111 | C25: KBV 876S | D25: 12 | E25: 6 | F25: 1*22-222 | G25: 6.6 | H25: 8.7 | I25: 7.4 | J25: 7.5 | K25: 7.6 | L25: 8.4 | N25: =SUM(G25:M25) -> 46.2 | P25: MINERAL ROCK
A26: 21 | B26: 0.66875 | C26: UAK 990A | D26: 13 | E26: 7 | F26: 1*22+22*22 | G26: 7.1 | H26: 7.65 | I26: 6.4 | J26: 6.25 | K26: 8.3 | L26: 5.9 | M26: 5.65 | N26: =SUM(G26:M26) -> 47.25 | P26: PROCESSED FOODS
A27: 22 | B27: 0.67361111 | C27: UAE 744R | D27: 12 | E27: 6 | F27: 1*22-222 | G27: 6.1 | H27: 7.35 | I27: 6.9 | J27: 6.55 | K27: 7.15 | L27: 9.1 | N27: =SUM(G27:M27) -> 43.15 | P27: AGRICULTURAL PRODUCTS
A28: 23 | B28: 0.72916667 | C28: UAD 925D | D28: 12 | E28: 6 | F28: 1*22-222 | G28: 5.2 | H28: 4.95 | I28: 3.45 | J28: 4.05 | K28: 4 | L28: 4.9 | N28: =SUM(G28:M28) -> 26.55 | P28: OTHERS
A29: 24 | B29: 0.75 | C29: UAR 067R | D29: 12 | E29: 6 | F29: 1*22-222 | G29: 6.1 | H29: 4.9 | I29: 7.4 | J29: 5.3 | K29: 7 | L29: 7.5 | N29: =SUM(G29:M29) -> 38.2 | P29: BUILDING MATERIAL

Sheet DAY 2
A1: AXLE LOAD SURVEY FORM
A2: Date: | D2: Station Name: | E2: NAKIBIZZI
A3: 43773 | D3: JINJA-KAMPALA | H3: JINJA-KAMPALA
A4: S/No. | B4: Time | C4: Reg. Number | D4: Vehicle Type | E4: Number of Axles | F4: Axle Configuration | G4: Front | N4: Total (Tonnes) | O4: Total (ESA's) | P4: COMMENTS
G5: Axle 1 | H5: Axle 2 | I5: Axle 3 | J5: Axle 4 | K5: Axle 5 | L5: Axle 6 | M5: Axle 7
A6: 1 | B6: 0.34027778 | C6: UAW 025N | D6: 13 | E6: 7 | F6: 1*22+22*22 | G6: 5.95 | H6: 12.25 | I6: 5 | J6: 8.35 | K6: 6.15 | L6: 8.5 | M6: 7.35 | N6: =SUM(G6:M6) -> 53.55 | P6: BUILDING MATERIAL
A7: 2 | B7: 0.34583333 | C7: KCC 578M | D7: 12 | E7: 6 | F7: 1*22-222 | G7: 6.8 | H7: 8.8 | I7: 7.5 | J7: 8.4 | K7: 8.2 | L7: 6.8 | N7: =SUM(G7:M7) -> 46.5 | P7: BUILDING MATERIAL
A8: 3 | B8: 0.37152778 | C8: UBD 281X | D8: 8 | E8: 3 | F8: 1*22 | G8: 4.65 | H8: 8.6 | I8: 10.25 | N8: =SUM(G8:M8) -> 23.5 | P8: AGRICULTURAL PRODUCT
A9: 4 | B9: 0.37569444 | C9: KCL 960B | D9: 12 | E9: 6 | F9: 1*22-222 | G9: 6.6 | H9: 6.7 | I9: 6.1 | J9: 7 | K9: 6.8 | L9: 8 | N9: =SUM(G9:M9) -> 41.2 | P9: BUILDING MATERIAL
A10: 5 | B10: 0.38611111 | C10: UAP 906F | D10: 7 | E10: 2 | F10: 1*2 | G10: 3.3 | H10: 12.65 | N10: =SUM(G10:M10) -> 15.95 | P10: AGRICULTURAL PRODUCT
A11: 6 | B11: 0.39583333 | C11: KCP 784T | D11: 12 | E11: 6 | F11: 1*22-222 | G11: 5.2 | H11: 2.9 | I11: 4.8 | J11: 5 | K11: 4.5 | L11: 4.5 | N11: =SUM(G11:M11) -> 26.9 | P11: EQUIPMENT
A12: 7 | B12: 0.43055556 | C12: UAD 400J | D12: 12 | E12: 6 | F12: 1*22-222 | G12: 5.4 | H12: 6.95 | I12: 8.45 | J12: 8.15 | K12: 8.1 | L12: 8.1 | N12: =SUM(G12:M12) -> 45.15 | P12: AGRICULTURAL PRODUCT
A13: 8 | B13: 0.43263889 | C13: UAU 152S | D13: 8 | E13: 3 | F13: 1*22 | G13: 6.2 | H13: 14.7 | I13: 4.65 | N13: =SUM(G13:M13) -> 25.55 | P13: PROCESSED FOODS
A14: 9 | B14: 0.44722222 | C14: KBR 933V | D14: 12 | E14: 6 | F14: 1*22-222 | G14: 5.25 | H14: 4.05 | I14: 6.6 | J14: 6.45 | K14: 5.65 | L14: 6.1 | N14: =SUM(G14:M14) -> 34.1 | P14: PROCESSED FOODS
A15: 10 | B15: 0.46180556 | C15: UAV 368E | D15: 8 | E15: 3 | F15: 1*22 | G15: 7 | H15: 12.8 | I15: 4.75 | N15: =SUM(G15:M15) -> 24.55 | P15: PROCESSED FOODS
A16: 11 | B16: 0.50763889 | C16: KBU 739W | D16: 12 | E16: 6 | F16: 1*22-222 | G16: 5.5 | H16: 6.95 | I16: 7.15 | J16: 7.8 | K16: 6.7 | L16: 8.3 | N16: =SUM(G16:M16) -> 42.4 | P16: OTHERS
A17: 12 | B17: 0.51388889 | C17: KCU 353G | D17: 12 | E17: 6 | F17: 1*22-222 | G17: 6.05 | H17: 6.25 | I17: 6.75 | J17: 7.5 | K17: 7.85 | L17: 7.55 | N17: =SUM(G17:M17) -> 41.95 | P17: EQUIPMENT
A18: 13 | B18: 0.55694444 | C18: UBF 028K | D18: 7 | E18: 2 | F18: 1*2 | G18: 3.6 | H18: 12.1 | N18: =SUM(G18:M18) -> 15.7 | P18: AGRICULTURAL PRODUCT
A19: 14 | B19: 0.56944444 | C19: UAW 255B | D19: 7 | E19: 2 | F19: 1*2 | G19: 4.15 | H19: 9.45 | N19: =SUM(G19:M19) -> 13.6 | P19: AGRICULTURAL PRODUCT
A20: 15 | B20: 0.57986111 | C20: UAU 690M | D20: 7 | E20: 2 | F20: 1*2 | G20: 3.5 | H20: 7.15 | N20: =SUM(G20:M20) -> 10.65 | P20: OTHERS
A21: 16 | B21: 0.58402778 | C21: UAQ 159T | D21: 7 | E21: 2 | F21: 1*2 | G21: 5.6 | H21: 10.7 | N21: =SUM(G21:M21) -> 16.3 | P21: PROCESSED FOODS
A22: 17 | B22: 0.58888889 | C22: UBF 018K | D22: 7 | E22: 2 | F22: 1*2 | G22: 3.55 | H22: 10.1 | N22: =SUM(G22:M22) -> 13.65 | P22: AGRICULTURAL PRODUCT
A23: 18 | B23: 0.59236111 | C23: UAU 743H | D23: 7 | E23: 2 | F23: 1*2 | G23: 3.2 | H23: 11 | N23: =SUM(G23:M23) -> 14.2 | P23: AGRICULTURAL PRODUCT
A24: 19 | B24: 0.61111111 | C24: KCH 040P | D24: 12 | E24: 6 | F24: 1*22-222 | G24: 4.3 | H24: 4.95 | I24: 6.6 | J24: 6 | K24: 6.2 | L24: 7.2 | N24: =SUM(G24:M24) -> 35.25 | P24: OTHERS
A25: 20 | B25: 0.63263889 | C25: UAZ 192V | D25: 8 | E25: 3 | F25: 1*22 | G25: 4.35 | H25: 10.2 | I25: 10.85 | N25: =SUM(G25:M25) -> 25.4 | P25: AGRICULTURAL PRODUCT
A26: 21 | B26: 0.6375 | C26: UAS 962 U | D26: 12 | E26: 6 | F26: 1*22-222 | G26: 5.3 | H26: 6.8 | I26: 6.5 | J26: 7.4 | K26: 7.5 | L26: 8.1 | N26: =SUM(G26:M26) -> 41.6 | P26: PROCESSED FOODS
A27: 22 | B27: 0.63541667 | C27: UBA 967D | D27: 12 | E27: 6 | F27: 1*22-222 | G27: 5 | H27: 5.1 | I27: 6.3 | J27: 7.4 | K27: 6.7 | L27: 8 | N27: =SUM(G27:M27) -> 38.5 | P27: AGRICULTURAL PRODUCT
A28: 23 | B28: 0.66666667 | C28: UBA 473L | D28: 12 | E28: 6 | F28: 1*22-222 | G28: 6.5 | H28: 6.1 | I28: 5.6 | J28: 5.65 | K28: 7.9 | L28: 9.55 | N28: =SUM(G28:M28) -> 41.3 | P28: PROCESSED FOODS
A29: 24 | B29: 0.67916667 | C29: UBE 457R | D29: 8 | E29: 3 | F29: 1*22 | G29: 4.95 | H29: 9.05 | I29: 9.45 | N29: =SUM(G29:M29) -> 23.45 | P29: AGRICULTURAL PRODUCT

Sheet DAY 3
A1: AXLE LOAD SURVEY FORM
A2: Date: | D2: Station Name: | E2: NAKIBIZZI
A3: 43774 | D3: JINJA-KAMPALA | H3: JINJA KAMPALA
A4: S/No. | B4: Time | C4: Reg. Number | D4: Vehicle Type | E4: Number of Axles | F4: Axle Configuration | G4: Front | N4: Total (Tonnes) | O4: Total (ESA's) | P4: COMMENTS
G5: Axle 1 | H5: Axle 2 | I5: Axle 3 | J5: Axle 4 | K5: Axle 5 | L5: Axle 6 | M5: Axle 7
A6: 1 | B6: 0.38055556 | C6: KCS 027G | D6: 10 | E6: 6 | F6: 1*22-111 | G6: 5.3 | H6: 5.2 | I6: 9.1 | J6: 6.1 | K6: 7.3 | L6: 8 | N6: =SUM(G6:M6) -> 41 | P6: OTHERS
A7: 2 | B7: 0.38263889 | C7: KBQ 399M | D7: 10 | E7: 6 | F7: 1*22-222 | G7: 6.2 | H7: 8.4 | I7: 8.8 | J7: 7.4 | K7: 7.4 | L7: 8.2 | N7: =SUM(G7:M7) -> 46.4 | P7: OTHERS
A8: 3 | B8: 0.38888889 | C8: UAY 324T | D8: 8 | E8: 3 | F8: 1*22 | G8: 3.75 | H8: 11 | I8: 11.75 | N8: =SUM(G8:M8) -> 26.5 | P8: AGRICULTURAL PRODUCTS
A9: 4 | B9: 0.40902778 | C9: UAV 010F | D9: 8 | E9: 3 | F9: 1*22 | G9: 4.2 | H9: 9.8 | I9: 9.35 | N9: =SUM(G9:M9) -> 23.35 | P9: AGRICULTURAL PRODUCTS
A10: 5 | B10: 0.41944444 | C10: UAH 401Y | D10: 7 | E10: 2 | F10: 1*2 | G10: 3.4 | H10: 10.4 | N10: =SUM(G10:M10) -> 13.8 | P10: PROCESSED FOODS
A11: 6 | B11: 0.42361111 | C11: KCC 959G | D11: 10 | E11: 6 | F11: 1*22-222 | G11: 6.3 | H11: 3.45 | I11: 8.7 | J11: 6.4 | K11: 6.6 | L11: 5.2 | N11: =SUM(G11:M11) -> 36.65 | P11: OTHERS
A12: 7 | B12: 0.44097222 | C12: UAK 241L | D12: 7 | E12: 2 | F12: 1*2 | G12: 3.6 | H12: 8.3 | N12: =SUM(G12:M12) -> 11.9 | P12: PROCESSED FOODS
A13: 8 | B13: 0.45902778 | C13: UAT 527R | D13: 12 | E13: 6 | F13: 1*22-222 | G13: 5.25 | H13: 4.95 | I13: 9.4 | J13: 5.9 | K13: 7.7 | L13: 7.7 | N13: =SUM(G13:M13) -> 40.9 | P13: BUILDING MATERIAL
A14: 9 | B14: 0.46319444 | C14: KCD 213Z | D14: 12 | E14: 6 | F14: 1*22-222 | G14: 6.4 | H14: 7.55 | I14: 7.3 | J14: 7.6 | K14: 6.35 | L14: 10.94 | N14: =SUM(G14:M14) -> 46.14 | P14: PROCESSED FOODS
A15: 10 | B15: 0.47222222 | C15: KBT 780D | D15: 12 | E15: 6 | F15: 1*22-222 | G15: 6.1 | H15: 2.9 | I15: 12.1 | J15: 9.25 | K15: 7.7 | L15: 7.4 | N15: =SUM(G15:M15) -> 45.45 | P15: OTHERS
A16: 11 | B16: 0.47777778 | C16: UAW 961P | D16: 7 | E16: 2 | F16: 1*2 | G16: 3.6 | H16: 8.25 | N16: =SUM(G16:M16) -> 11.85 | P16: OTHERS
A17: 12 | B17: 0.48611111 | C17: UAZ 116X | D17: 12 | E17: 6 | F17: 1*22-222 | G17: 6.3 | H17: 8.25 | I17: 8.45 | J17: 8.95 | K17: 7.9 | L17: 7.7 | N17: =SUM(G17:M17) -> 47.55 | P17: AGRICULTURAL PRODUCTS
A18: 13 | B18: 0.50069444 | C18: KCM 709S | D18: 12 | E18: 6 | F18: 1*22-222 | G18: 6.2 | H18: 2.8 | I18: 12 | J18: 6.6 | K18: 9 | L18: 9 | N18: =SUM(G18:M18) -> 45.6 | P18: PROCESSED FOODS
A19: 14 | B19: 0.50763889 | C19: UAA 949C | D19: 7 | E19: 2 | F19: 1*2 | G19: 3.4 | H19: 12.6 | N19: =SUM(G19:M19) -> 16 | P19: AGRICULTURAL PRODUCTS
A20: 15 | B20: 0.51736111 | C20: UBE 081D | D20: 10 | E20: 4 | F20: 11*22 | G20: 6.25 | H20: 2.35 | I20: 10.2 | J20: 8.3 | N20: =SUM(G20:M20) -> 27.1 | P20: PROCESSED FOODS
A21: 16 | B21: 0.5375 | C21: UAF 433J | D21: 11 | E21: 5 | F21: 1*11-22 | G21: 6.6 | H21: 10.45 | I21: 7.1 | J21: 6.95 | K21: 7.7 | N21: =SUM(G21:M21) -> 38.8 | P21: BUILDING MATERIAL
A22: 17 | B22: 0.54305556 | C22: UAT 861N | D22: 12 | E22: 6 | F22: 1*22-222 | G22: 6 | H22: 2.5 | I22: 8 | J22: 8.4 | K22: 8 | L22: 8.2 | N22: =SUM(G22:M22) -> 41.1 | P22: BUILDING MATERIAL
A23: 18 | B23: 0.54861111 | C23: KCM 864T | D23: 12 | E23: 6 | F23: 1*22-222 | G23: 6.55 | H23: 8.3 | I23: 9.6 | J23: 7.6 | K23: 7.4 | L23: 6.2 | N23: =SUM(G23:M23) -> 45.65 | P23: AGRICULTURAL PRODUCTS
A24: 19 | B24: 0.56597222 | C24: UAY 645M | D24: 12 | E24: 6 | F24: 1*22-222 | G24: 5.7 | H24: 11 | I24: 4.5 | J24: 7.4 | K24: 8.4 | L24: 8.2 | N24: =SUM(G24:M24) -> 45.2 | P24: BUILDING MATERIAL
A25: 20 | B25: 0.59305556 | C25: UAU 183L | D25: 12 | E25: 6 | F25: 1*22-222 | G25: 5.9 | H25: 9.3 | I25: 8.8 | J25: 3.4 | K25: 3.6 | L25: 3.6 | N25: =SUM(G25:M25) -> 34.6 | P25: OTHERS
A26: 21 | B26: 0.59583333 | C26: UAL 914W | D26: 12 | E26: 6 | F26: 1*22-222 | G26: 7.4 | H26: 2.4 | I26: 12.1 | J26: 10.1 | K26: 8 | L26: 7.9 | N26: =SUM(G26:M26) -> 47.9 | P26: BUILDING MATERIAL
A27: 22 | B27: 0.60555556 | C27: UAZ 408W | D27: 12 | E27: 6 | F27: 1*12-111 | G27: 4.65 | H27: 8.55 | I27: 6.35 | J27: 6.4 | K27: 6.7 | L27: 9.4 | N27: =SUM(G27:M27) -> 42.05 | P27: PROCESSED FOODS
A28: 23 | B28: 0.61805556 | C28: KBT 223B | D28: 12 | E28: 6 | F28: 1*22-222 | G28: 4 | H28: 3.4 | I28: 7.2 | J28: 4.3 | K28: 4.2 | L28: 3 | N28: =SUM(G28:M28) -> 26.1 | P28: OTHERS
A29: 24 | B29: 0.62708333 | C29: UAS 576U | D29: 7 | E29: 2 | F29: 1*2 | G29: 4.3 | H29: 11.25 | N29: =SUM(G29:M29) -> 15.55 | P29: PROCESSED FOODS
A30: 25 | B30: 0.63194444 | C30: UAP 910L | D30: 7 | E30: 2 | F30: 1*2 | G30: 4.95 | H30: 9.9 | N30: =SUM(G30:M30) -> 14.85 | P30: PROCESSED FOODS
A31: 26 | B31: 0.6375 | C31: UAZ 192 H | D31: 8 | E31: 3 | F31: 1*22 | G31: 4.65 | H31: 11.35 | I31: 10.7 | N31: =SUM(G31:M31) -> 26.7 | P31: AGRICULTURAL PRODUCTS
A32: 27 | B32: 0.65972222 | C32: UBD 828J | D32: 8 | E32: 3 | F32: 1*22 | G32: 5.7 | H32: 8.7 | I32: 8.15 | N32: =SUM(G32:M32) -> 22.55 | P32: OTHERS
A33: 28 | B33: 0.72222222 | C33: UAZ 225T | D33: 8 | E33: 3 | F33: 1*22 | G33: 3.9 | H33: 9.95 | I33: 9.6 | N33: =SUM(G33:M33) -> 23.45 | P33: AGRICULTURAL PRODUCTS
G36: KAMPALA-JINJA
A37: 1 | B37: 0.64097222 | C37: UAW 415X | D37: 7 | E37: 2 | F37: 1*2 | G37: 2.9 | H37: 4.4 | N37: =SUM(G37:M37) -> 7.3 | P37: OTHERS
A38: 2 | B38: 0.66944444 | C38: UAH 162H | D38: 10 | E38: 4 | F38: 1*222 | G38: 8.6 | H38: 9.1 | I38: 7.2 | J38: 3.6 | N38: =SUM(G38:M38) -> 28.5 | P38: OTHERS
A39: 3 | B39: 0.68194444 | C39: UAJ 045T | D39: 10 | E39: 4 | F39: 1*222 | G39: 8.45 | H39: 11.15 | I39: 7.25 | J39: 2.8 | N39: =SUM(G39:M39) -> 29.65 | P39: OTHERS
A40: 4 | B40: 0.70138889 | C40: UAE 881L | D40: 10 | E40: 4 | F40: 1*222 | G40: 7.2 | H40: 11.2 | I40: 11.2 | J40: 2.4 | N40: =SUM(G40:M40) -> 32 | P40: OTHERS
A41: 5 | B41: 0.7125 | C41: UBD 799H | D41: 7 | E41: 2 | F41: 1*2 | G41: 4.2 | H41: 11.1 | N41: =SUM(G41:M41) -> 15.3 | P41: AGRICULTURAL PRODUCTS

Sheet Kla-Jinja
A1: Feasibility Study and Detailed Design of Kampala-Jinja Highway
A2: Axle Load Survey
A4: Station: Nakibizzi | G4: Direction From: Kampala | J4: Direction To: Jinja | M4: Date: 29/09/2010 | N4: Time: 7:00-19:00
A6: Measure No. | C6: Reg.No | D6: Vehicle Type | E6: Number of Axles | F6: Configuration | G6: Axle Load(T) | N6: Total (Tonnes) | O6: Total (ESA's) | P6: Load limit (Tonnes) | W6: OVERLOADED? | X6: Overloaded by? | Y6: Overload Bands | Z6: Load Type
G7: Axle-1 | H7: Axle -2 | I7: Axle-3 | J7: Axle-4 | K7: Axle-5 | L7: Axle-6 | M7: Axle-7 | P7: Axle 1 | Q7: Axle 2 | R7: Axle 3 | S7: Axle 4 | T7: Axle 5 | U7: Axle 6 | V7: Axle 7
A8: 046 | C8: UAM 785T | D8: =IF(COUNT(G8:M8)>3,10,IF(COUNT(G8:M8)>2,9,7)) -> 7 | F8: S2.S4 | G8: 4.2 | H8: 9.6 | N8: =SUM(G8:M8) -> 13.8 | O8: =(N8/8.16)^4.5 -> 10.63776 | P8: 8 | Q8: 10 | R8: 9 | S8: 9 | T8: 9 | U8: 9 | V8: 9 | W8: =IF(G8>P8,"Y",IF(H8>Q8,"Y",IF(I8>R8,"Y",IF(J8>S8,"Y",IF(K8>T8,"Y",IF(L8>U8,"Y",IF(M8>V8,"Y","N"))))))) -> N | X8: =IF(W8="Y",MAX((G8-P8),(H8-Q8),(I8-R8),(J8-S8),(K8-T8),(L8-U8),(M8-V8))/10,0) -> 0 | Y8: =IF(X8<5%,"0-4.9%",IF(X8<25%,"5-25%",IF(X8<50%,"25-50%","Over 50%"))) -> 0-4.9% | Z8: Agricultural produce
A9: 047 | C9: UAM 814J | D9: =IF(COUNT(G9:M9)>3,10,IF(COUNT(G9:M9)>2,9,7)) -> 7 | F9: S2.S4 | G9: 2.9 | H9: 7.4 | N9: =SUM(G9:M9) -> 10.3 | O9: =(N9/8.16)^4.5 -> 2.8520806 | P9: 8 | Q9: 10 | R9: 9 | S9: 9 | T9: 9 | U9: 9 | V9: 9 | W9: =IF(G9>P9,"Y",IF(H9>Q9,"Y",IF(I9>R9,"Y",IF(J9>S9,"Y",IF(K9>T9,"Y",IF(L9>U9,"Y",IF(M9>V9,"Y","N"))))))) -> N | X9: =IF(W9="Y",MAX((G9-P9),(H9-Q9),(I9-R9),(J9-S9),(K9-T9),(L9-U9),(M9-V9))/10,0) -> 0 | Y9: =IF(X9<5%,"0-4.9%",IF(X9<25%,"5-25%",IF(X9<50%,"25-50%","Over 50%"))) -> 0-4.9% | Z9: Household retail products
A10: 048 | C10: UAN 818A | D10: =IF(COUNT(G10:M10)>3,10,IF(COUNT(G10:M10)>2,9,7)) -> 7 | F10: S2.S4 | G10: 4.85 | H10: 9.25 | N10: =SUM(G10:M10) -> 14.1 | O10: =(N10/8.16)^4.5 -> 11.718723 | P10: 8 | Q10: 10 | R10: 9 | S10: 9 | T10: 9 | U10: 9 | V10: 9 | W10: =IF(G10>P10,"Y",IF(H10>Q10,"Y",IF(I10>R10,"Y",IF(J10>S10,"Y",IF(K10>T10,"Y",IF(L10>U10,"Y",IF(M10>V10,"Y","N"))))))) -> N | X10: =IF(W10="Y",MAX((G10-P10),(H10-Q10),(I10-R10),(J10-S10),(K10-T10),(L10-U10),(M10-V10))/10,0) -> 0 | Y10: =IF(X10<5%,"0-4.9%",IF(X10<25%,"5-25%",IF(X10<50%,"25-50%","Over 50%"))) -> 0-4.9% | Z10: Household retail products
A11: 052 | C11: UAG 504A | D11: =IF(COUNT(G11:M11)>3,10,IF(COUNT(G11:M11)>2,9,7)) -> 7 | F11: S2.S4 | G11: 4.75 | H11: 8.9 | N11: =SUM(G11:M11) -> 13.65 | O11: =(N11/8.16)^4.5 -> 10.127243 | P11: 8 | Q11: 10 | R11: 9 | S11: 9 | T11: 9 | U11: 9 | V11: 9 | W11: =IF(G11>P11,"Y",IF(H11>Q11,"Y",IF(I11>R11,"Y",IF(J11>S11,"Y",IF(K11>T11,"Y",IF(L11>U11,"Y",IF(M11>V11,"Y","N"))))))) -> N | X11: =IF(W11="Y",MAX((G11-P11),(H11-Q11),(I11-R11),(J11-S11),(K11-T11),(L11-U11),(M11-V11))/10,0) -> 0 | Y11: =IF(X11<5%,"0-4.9%",IF(X11<25%,"5-25%",IF(X11<50%,"25-50%","Over 50%"))) -> 0-4.9% | Z11: Household retail products
A12: 056 | C12: UAM 927Q | D12: =IF(COUNT(G12:M12)>3,10,IF(COUNT(G12:M12)>2,9,7)) -> 7 | F12: S2.S4 | G12: 3.95 | H12: 10.7 | N12: =SUM(G12:M12) -> 14.65 | O12: =(N12/8.16)^4.5 -> 13.920781 | P12: 8 | Q12: 10 | R12: 9 | S12: 9 | T12: 9 | U12: 9 | V12: 9 | W12: =IF(G12>P12,"Y",IF(H12>Q12,"Y",IF(I12>R12,"Y",IF(J12>S12,"Y",IF(K12>T12,"Y",IF(L12>U12,"Y",IF(M12>V12,"Y","N"))))))) -> Y | X12: =IF(W12="Y",MAX((G12-P12),(H12-Q12),(I12-R12),(J12-S12),(K12-T12),(L12-U12),(M12-V12))/10,0) -> 0.07 | Y12: =IF(X12<5%,"0-4.9%",IF(X12<25%,"5-25%",IF(X12<50%,"25-50%","Over 50%"))) -> 5-25% | Z12: Chemical Products
A13: 064 | C13: 0959AA107 | D13: =IF(COUNT(G13:M13)>3,10,IF(COUNT(G13:M13)>2,9,7)) -> 7 | F13: S2.S4 | G13: 4.75 | H13: 11.05 | N13: =SUM(G13:M13) -> 15.8 | O13: =(N13/8.16)^4.5 -> 19.559204 | P13: 8 | Q13: 10 | R13: 9 | S13: 9 | T13: 9 | U13: 9 | V13: 9 | W13: =IF(G13>P13,"Y",IF(H13>Q13,"Y",IF(I13>R13,"Y",IF(J13>S13,"Y",IF(K13>T13,"Y",IF(L13>U13,"Y",IF(M13>V13,"Y","N"))))))) -> Y | X13: =IF(W13="Y",MAX((G13-P13),(H13-Q13),(I13-R13),(J13-S13),(K13-T13),(L13-U13),(M13-V13))/10,0) -> 0.105 | Y13: =IF(X13<5%,"0-4.9%",IF(X13<25%,"5-25%",IF(X13<50%,"25-50%","Over 50%"))) -> 5-25% | Z13: Agricultural produce
A14: 067 | C14: UAG 270T | D14: =IF(COUNT(G14:M14)>3,10,IF(COUNT(G14:M14)>2,9,7)) -> 7 | F14: S2.S4 | G14: 4.75 | H14: 11.05 | N14: =SUM(G14:M14) -> 15.8 | O14: =(N14/8.16)^4.5 -> 19.559204 | P14: 8 | Q14: 10 | R14: 9 | S14: 9 | T14: 9 | U14: 9 | V14: 9 | W14: =IF(G14>P14,"Y",IF(H14>Q14,"Y",IF(I14>R14,"Y",IF(J14>S14,"Y",IF(K14>T14,"Y",IF(L14>U14,"Y",IF(M14>V14,"Y","N"))))))) -> Y | X14: =IF(W14="Y",MAX((G14-P14),(H14-Q14),(I14-R14),(J14-S14),(K14-T14),(L14-U14),(M14-V14))/10,0) -> 0.105 | Y14: =IF(X14<5%,"0-4.9%",IF(X14<25%,"5-25%",IF(X14<50%,"25-50%","Over 50%"))) -> 5-25% | Z14: Agricultural produce
A15: 070 | C15: UAH 161T | D15: =IF(COUNT(G15:M15)>3,10,IF(COUNT(G15:M15)>2,9,7)) -> 7 | F15: S2.S4 | G15: 3.35 | H15: 6.05 | N15: =SUM(G15:M15) -> 9.4 | O15: =(N15/8.16)^4.5 -> 1.890034 | P15: 8 | Q15: 10 | R15: 9 | S15: 9 | T15: 9 | U15: 9 | V15: 9 | W15: =IF(G15>P15,"Y",IF(H15>Q15,"Y",IF(I15>R15,"Y",IF(J15>S15,"Y",IF(K15>T15,"Y",IF(L15>U15,"Y",IF(M15>V15,"Y","N"))))))) -> N | X15: =IF(W15="Y",MAX((G15-P15),(H15-Q15),(I15-R15),(J15-S15),(K15-T15),(L15-U15),(M15-V15))/10,0) -> 0 | Y15: =IF(X15<5%,"0-4.9%",IF(X15<25%,"5-25%",IF(X15<50%,"25-50%","Over 50%"))) -> 0-4.9% | Z15: Household retail products
A16: 071 | C16: UAK 969T | D16: =IF(COUNT(G16:M16)>3,10,IF(COUNT(G16:M16)>2,9,7)) -> 7 | F16: S2.S4 | G16: 4.05 | H16: 9.25 | N16: =SUM(G16:M16) -> 13.3 | O16: =(N16/8.16)^4.5 -> 9.010039 | P16: 8 | Q16: 10 | R16: 9 | S16: 9 | T16: 9 | U16: 9 | V16: 9 | W16: =IF(G16>P16,"Y",IF(H16>Q16,"Y",IF(I16>R16,"Y",IF(J16>S16,"Y",IF(K16>T16,"Y",IF(L16>U16,"Y",IF(M16>V16,"Y","N"))))))) -> N | X16: =IF(W16="Y",MAX((G16-P16),(H16-Q16),(I16-R16),(J16-S16),(K16-T16),(L16-U16),(M16-V16))/10,0) -> 0 | Y16: =IF(X16<5%,"0-4.9%",IF(X16<25%,"5-25%",IF(X16<50%,"25-50%","Over 50%"))) -> 0-4.9% | Z16: Agricultural produce
A17: 141 | C17: UAJ 299R | D17: =IF(COUNT(G17:M17)>3,10,IF(COUNT(G17:M17)>2,9,7)) -> 7 | F17: S2.S4 | G17: 3.4 | H17: 7.2 | N17: =SUM(G17:M17) -> 10.6 | O17: =(N17/8.16)^4.5 -> 3.2454183 | P17: 8 | Q17: 10 | R17: 9 | S17: 9 | T17: 9 | U17: 9 | V17: 9 | W17: =IF(G17>P17,"Y",IF(H17>Q17,"Y",IF(I17>R17,"Y",IF(J17>S17,"Y",IF(K17>T17,"Y",IF(L17>U17,"Y",IF(M17>V17,"Y","N"))))))) -> N | X17: =IF(W17="Y",MAX((G17-P17),(H17-Q17),(I17-R17),(J17-S17),(K17-T17),(L17-U17),(M17-V17))/10,0) -> 0 | Y17: =IF(X17<5%,"0-4.9%",IF(X17<25%,"5-25%",IF(X17<50%,"25-50%","Over 50%"))) -> 0-4.9% | Z17: Household retail products
A18: 142 | C18: UAL 910L | D18: =IF(COUNT(G18:M18)>3,10,IF(COUNT(G18:M18)>2,9,7)) -> 7 | F18: S2.S4 | G18: 3.95 | H18: 6.45 | N18: =SUM(G18:M18) -> 10.4 | O18: =(N18/8.16)^4.5 -> 2.9788204 | P18: 8 | Q18: 10 | R18: 9 | S18: 9 | T18: 9 | U18: 9 | V18: 9 | W18: =IF(G18>P18,"Y",IF(H18>Q18,"Y",IF(I18>R18,"Y",IF(J18>S18,"Y",IF(K18>T18,"Y",IF(L18>U18,"Y",IF(M18>V18,"Y","N"))))))) -> N | X18: =IF(W18="Y",MAX((G18-P18),(H18-Q18),(I18-R18),(J18-S18),(K18-T18),(L18-U18),(M18-V18))/10,0) -> 0 | Y18: =IF(X18<5%,"0-4.9%",IF(X18<25%,"5-25%",IF(X18<50%,"25-50%","Over 50%"))) -> 0-4.9% | Z18: Agricultural produce
A19: 144 | C19: UAL 025X | D19: =IF(COUNT(G19:M19)>3,10,IF(COUNT(G19:M19)>2,9,7)) -> 7 | F19: S2.S4 | G19: 3.2 | H19: 10.2 | N19: =SUM(G19:M19) -> 13.4 | O19: =(N19/8.16)^4.5 -> 9.3189263 | P19: 8 | Q19: 10 | R19: 9 | S19: 9 | T19: 9 | U19: 9 | V19: 9 | W19: =IF(G19>P19,"Y",IF(H19>Q19,"Y",IF(I19>R19,"Y",IF(J19>S19,"Y",IF(K19>T19,"Y",IF(L19>U19,"Y",IF(M19>V19,"Y","N"))))))) -> Y | X19: =IF(W19="Y",MAX((G19-P19),(H19-Q19),(I19-R19),(J19-S19),(K19-T19),(L19-U19),(M19-V19))/10,0) -> 0.02 | Y19: =IF(X19<5%,"0-4.9%",IF(X19<25%,"5-25%",IF(X19<50%,"25-50%","Over 50%"))) -> 0-4.9% | Z19: Household retail products
... A154: 165 | C154: UAA 916E | D154: =IF(COUNT(G154:M154)>3,10,IF(COUNT(G154:M154)>2,9,7)) -> 7 | F154: S2.S4 | G154: 4.75 | H154: 4.75 | N154: =SUM(G154:M154) -> 9.5 | O154: =(N154/8.16)^4.5 -> 1.9822139 | P154: 8 | Q154: 10 | R154: 9 | S154: 9 | T154: 9 | U154: 9 | V154: 9 | W154: =IF(G154>P154,"Y",IF(H154>Q154,"Y",IF(I154>R154,"Y",IF(J154>S154,"Y",IF(K154>T154,"Y",IF(L154>U154,"Y",IF(M154>V154,"Y","N"))))))) -> N | X154: =IF(W154="Y",MAX((G154-P154),(H154-Q154),(I154-R154),(J154-S154),(K154-T154),(L154-U154),(M154-V154))/10,0) -> 0 | Y154: =IF(X154<5%,"0-4.9%",IF(X154<25%,"5-25%",IF(X154<50%,"25-50%","Over 50%"))) -> 0-4.9% | Z154: Metal/machinery
A155: 166 | C155: UAK 635E | D155: =IF(COUNT(G155:M155)>3,10,IF(COUNT(G155:M155)>2,9,7)) -> 7 | F155: S2.S4 | G155: 4.05 | H155: 9.35 | N155: =SUM(G155:M155) -> 13.4 | O155: =(N155/8.16)^4.5 -> 9.3189263 | P155: 8 | Q155: 10 | R155: 9 | S155: 9 | T155: 9 | U155: 9 | V155: 9 | W155: =IF(G155>P155,"Y",IF(H155>Q155,"Y",IF(I155>R155,"Y",IF(J155>S155,"Y",IF(K155>T155,"Y",IF(L155>U155,"Y",IF(M155>V155,"Y","N"))))))) -> N | X155: =IF(W155="Y",MAX((G155-P155),(H155-Q155),(I155-R155),(J155-S155),(K155-T155),(L155-U155),(M155-V155))/10,0) -> 0 | Y155: =IF(X155<5%,"0-4.9%",IF(X155<25%,"5-25%",IF(X155<50%,"25-50%","Over 50%"))) -> 0-4.9% | Z155: Agricultural produce
A156: 051 | C156: KAK 157V | D156: =IF(COUNT(G156:M156)>3,10,IF(COUNT(G156:M156)>2,9,7)) -> 9 | F156: S2.T8 | G156: 6.05 | H156: 8 | I156: 8 | N156: =SUM(G156:M156) -> 22.05 | O156: =(N156/8.16)^4.5 -> 87.646173 | P156: 8 | Q156: 10 | R156: 9 | S156: 9 | T156: 9 | U156: 9 | V156: 9 | W156: =IF(G156>P156,"Y",IF(H156>Q156,"Y",IF(I156>R156,"Y",IF(J156>S156,"Y",IF(K156>T156,"Y",IF(L156>U156,"Y",IF(M156>V156,"Y","N"))))))) -> N | X156: =IF(W156="Y",MAX((G156-P156),(H156-Q156),(I156-R156),(J156-S156),(K156-T156),(L156-U156),(M156-V156))/10,0) -> 0 | Y156: =IF(X156<5%,"0-4.9%",IF(X156<25%,"5-25%",IF(X156<50%,"25-50%","Over 50%"))) -> 0-4.9% | Z156: Others
A157: 055 | C157: UAN 859G | D157: =IF(COUNT(G157:M157)>3,10,IF(COUNT(G157:M157)>2,9,7)) -> 9 | F157: S2.T8 | G157: 6.75 | H157: 11.5 | I157: 8.7 | N157: =SUM(G157:M157) -> 26.95 | O157: =(N157/8.16)^4.5 -> 216.22642 | P157: 8 | Q157: 10 | R157: 9 | S157: 9 | T157: 9 | U157: 9 | V157: 9 | W157: =IF(G157>P157,"Y",IF(H157>Q157,"Y",IF(I157>R157,"Y",IF(J157>S157,"Y",IF(K157>T157,"Y",IF(L157>U157,"Y",IF(M157>V157,"Y","N"))))))) -> Y | X157: =IF(W157="Y",MAX((G157-P157),(H157-Q157),(I157-R157),(J157-S157),(K157-T157),(L157-U157),(M157-V157))/10,0) -> 0.15 | Y157: =IF(X157<5%,"0-4.9%",IF(X157<25%,"5-25%",IF(X157<50%,"25-50%","Over 50%"))) -> 5-25% | Z157: Household retail products
A158: 057 | C158: KAT 108B | D158: =IF(COUNT(G158:M158)>3,10,IF(COUNT(G158:M158)>2,9,7)) -> 9 | F158: S2.T8 | G158: 6.95 | H158: 16 | I158: 10 | N158: =SUM(G158:M158) -> 32.95 | O158: =(N158/8.16)^4.5 -> 534.24894 | P158: 8 | Q158: 10 | R158: 9 | S158: 9 | T158: 9 | U158: 9 | V158: 9 | W158: =IF(G158>P158,"Y",IF(H158>Q158,"Y",IF(I158>R158,"Y",IF(J158>S158,"Y",IF(K158>T158,"Y",IF(L158>U158,"Y",IF(M158>V158,"Y","N"))))))) -> Y | X158: =IF(W158="Y",MAX((G158-P158),(H158-Q158),(I158-R158),(J158-S158),(K158-T158),(L158-U158),(M158-V158))/10,0) -> 0.6 | Y158: =IF(X158<5%,"0-4.9%",IF(X158<25%,"5-25%",IF(X158<50%,"25-50%","Over 50%"))) -> Over 50% | Z158: Household retail products
A159: 065 | C159: UAN 627A | D159: =IF(COUNT(G159:M159)>3,10,IF(COUNT(G159:M159)>2,9,7)) -> 9 | F159: S2.T8 | G159: 8.4 | H159: 7.4 | I159: 7.95 | N159: =SUM(G159:M159) -> 23.75 | O159: =(N159/8.16)^4.5 -> 122.42794 | P159: 8 | Q159: 10 | R159: 9 | S159: 9 | T159: 9 | U159: 9 | V159: 9 | W159: =IF(G159>P159,"Y",IF(H159>Q159,"Y",IF(I159>R159,"Y",IF(J159>S159,"Y",IF(K159>T159,"Y",IF(L159>U159,"Y",IF(M159>V159,"Y","N"))))))) -> Y | X159: =IF(W159="Y",MAX((G159-P159),(H159-Q159),(I159-R159),(J159-S159),(K159-T159),(L159-U159),(M159-V159))/10,0) -> 0.04 | Y159: =IF(X159<5%,"0-4.9%",IF(X159<25%,"5-25%",IF(X159<50%,"25-50%","Over 50%"))) -> 0-4.9% | Z159: Agricultural produce
A160: 010 | C160: UAK 394E | D160: =IF(COUNT(G160:M160)>3,10,IF(COUNT(G160:M160)>2,9,7)) -> 9 | F160: S2.T8 | G160: 7.75 | H160: 7.6 | I160: 7.35 | N160: =SUM(G160:M160) -> 22.7 | O160: =(N160/8.16)^4.5 -> 99.887385 | P160: 8 | Q160: 10 | R160: 9 | S160: 9 | T160: 9 | U160: 9 | V160: 9 | W160: =IF(G160>P160,"Y",IF(H160>Q160,"Y",IF(I160>R160,"Y",IF(J160>S160,"Y",IF(K160>T160,"Y",IF(L160>U160,"Y",IF(M160>V160,"Y","N"))))))) -> N | X160: =IF(W160="Y",MAX((G160-P160),(H160-Q160),(I160-R160),(J160-S160),(K160-T160),(L160-U160),(M160-V160))/10,0) -> 0 | Y160: =IF(X160<5%,"0-4.9%",IF(X160<25%,"5-25%",IF(X160<50%,"25-50%","Over 50%"))) -> 0-4.9% | Z160: Household retail products
A161: 014 | C161: UAL 480R | D161: =IF(COUNT(G161:M161)>3,10,IF(COUNT(G161:M161)>2,9,7)) -> 9 | F161: S2.T8 | G161: 3.4 | H161: 2.75 | I161: 2.8 | N161: =SUM(G161:M161) -> 8.95 | O161: =(N161/8.16)^4.5 -> 1.5156466 | P161: 8 | Q161: 10 | R161: 9 | S161: 9 | T161: 9 | U161: 9 | V161: 9 | W161: =IF(G161>P161,"Y",IF(H161>Q161,"Y",IF(I161>R161,"Y",IF(J161>S161,"Y",IF(K161>T161,"Y",IF(L161>U161,"Y",IF(M161>V161,"Y","N"))))))) -> N | X161: =IF(W161="Y",MAX((G161-P161),(H161-Q161),(I161-R161),(J161-S161),(K161-T161),(L161-U161),(M161-V161))/10,0) -> 0 | Y161: =IF(X161<5%,"0-4.9%",IF(X161<25%,"5-25%",IF(X161<50%,"25-50%","Over 50%"))) -> 0-4.9% | Z161: Agricultural produce
A162: 015 | C162: UAN 902J | D162: =IF(COUNT(G162:M162)>3,10,IF(COUNT(G162:M162)>2,9,7)) -> 9 | F162: S2.T8 | G162: 6.5 | H162: 7.3 | I162: 7.3 | N162: =SUM(G162:M162) -> 21.1 | O162: =(N162/8.16)^4.5 -> 71.889479 | P162: 8 | Q162: 10 | R162: 9 | S162: 9 | T162: 9 | U162: 9 | V162: 9 | W162: =IF(G162>P162,"Y",IF(H162>Q162,"Y",IF(I162>R162,"Y",IF(J162>S162,"Y",IF(K162>T162,"Y",IF(L162>U162,"Y",IF(M162>V162,"Y","N"))))))) -> N | X162: =IF(W162="Y",MAX((G162-P162),(H162-Q162),(I162-R162),(J162-S162),(K162-T162),(L162-U162),(M162-V162))/10,0) -> 0 | Y162: =IF(X162<5%,"0-4.9%",IF(X162<25%,"5-25%",IF(X162<50%,"25-50%","Over 50%"))) -> 0-4.9% | Z162: Household retail products
A163: 020 | C163: UAL 626U | D163: =IF(COUNT(G163:M163)>3,10,IF(COUNT(G163:M163)>2,9,7)) -> 9 | F163: S2.T8 | G163: 4.15 | H163: 4.15 | I163: 2.7 | N163: =SUM(G163:M163) -> 11 | O163: =(N163/8.16)^4.5 -> 3.8340818 | P163: 8 | Q163: 10 | R163: 9 | S163: 9 | T163: 9 | U163: 9 | V163: 9 | W163: =IF(G163>P163,"Y",IF(H163>Q163,"Y",IF(I163>R163,"Y",IF(J163>S163,"Y",IF(K163>T163,"Y",IF(L163>U163,"Y",IF(M163>V163,"Y","N"))))))) -> N | X163: =IF(W163="Y",MAX((G163-P163),(H163-Q163),(I163-R163),(J163-S163),(K163-T163),(L163-U163),(M163-V163))/10,0) -> 0 | Y163: =IF(X163<5%,"0-4.9%",IF(X163<25%,"5-25%",IF(X163<50%,"25-50%","Over 50%"))) -> 0-4.9% | Z163: Metal/machinery
A164: 046 | C164: UAL 210N | D164: =IF(COUNT(G164:M164)>3,10,IF(COUNT(G164:M164)>2,9,7)) -> 9 | F164: S2.T8 | G164: 4.8 | H164: 3.7 | I164: 3.4 | N164: =SUM(G164:M164) -> 11.9 | O164: =(N164/8.16)^4.5 -> 5.4620493 | P164: 8 | Q164: 10 | R164: 9 | S164: 9 | T164: 9 | U164: 9 | V164: 9 | W164: =IF(G164>P164,"Y",IF(H164>Q164,"Y",IF(I164>R164,"Y",IF(J164>S164,"Y",IF(K164>T164,"Y",IF(L164>U164,"Y",IF(M164>V164,"Y","N"))))))) -> N | X164: =IF(W164="Y",MAX((G164-P164),(H164-Q164),(I164-R164),(J164-S164),(K164-T164),(L164-U164),(M164-V164))/10,0) -> 0 | Y164: =IF(X164<5%,"0-4.9%",IF(X164<25%,"5-25%",IF(X164<50%,"25-50%","Over 50%"))) -> 0-4.9% | Z164: Household retail products
A165: 052 | C165: UAM 890F | D165: =IF(COUNT(G165:M165)>3,10,IF(COUNT(G165:M165)>2,9,7)) -> 9 | F165: S2.T8 | G165: 4.75 | H165: 3.85 | I165: 3.4 | N165: =SUM(G165:M165) -> 12 | O165: =(N165/8.16)^4.5 -> 5.6716561 | P165: 8 | Q165: 10 | R165: 9 | S165: 9 | T165: 9 | U165: 9 | V165: 9 | W165: =IF(G165>P165,"Y",IF(H165>Q165,"Y",IF(I165>R165,"Y",IF(J165>S165,"Y",IF(K165>T165,"Y",IF(L165>U165,"Y",IF(M165>V165,"Y","N"))))))) -> N | X165: =IF(W165="Y",MAX((G165-P165),(H165-Q165),(I165-R165),(J165-S165),(K165-T165),(L165-U165),(M165-V165))/10,0) -> 0 | Y165: =IF(X165<5%,"0-4.9%",IF(X165<25%,"5-25%",IF(X165<50%,"25-50%","Over 50%"))) -> 0-4.9% | Z165: Household retail products
A166: 057 | C166: UAG 157Y | D166: =IF(COUNT(G166:M166)>3,10,IF(COUNT(G166:M166)>2,9,7)) -> 9 | F166: S2.T8 | G166: 4.55 | H166: 4.3 | I166: 2.9 | N166: =SUM(G166:M166) -> 11.75 | O166: =(N166/8.16)^4.5 -> 5.15899 | P166: 8 | Q166: 10 | R166: 9 | S166: 9 | T166: 9 | U166: 9 | V166: 9 | W166: =IF(G166>P166,"Y",IF(H166>Q166,"Y",IF(I166>R166,"Y",IF(J166>S166,"Y",IF(K166>T166,"Y",IF(L166>U166,"Y",IF(M166>V166,"Y","N"))))))) -> N | X166: =IF(W166="Y",MAX((G166-P166),(H166-Q166),(I166-R166),(J166-S166),(K166-T166),(L166-U166),(M166-V166))/10,0) -> 0 | Y166: =IF(X166<5%,"0-4.9%",IF(X166<25%,"5-25%",IF(X166<50%,"25-50%","Over 50%"))) -> 0-4.9% | Z166: Household retail products
A167: 060 | C167: UAN 616A | D167: =IF(COUNT(G167:M167)>3,10,IF(COUNT(G167:M167)>2,9,7)) -> 9 | F167: S2.T8 | G167: 4.65 | H167: 3 | I167: 2.8 | N167: =SUM(G167:M167) -> 10.45 | O167: =(N167/8.16)^4.5 -> 3.0438104 | P167: 8 | Q167: 10 | R167: 9 | S167: 9 | T167: 9 | U167: 9 | V167: 9 | W167: =IF(G167>P167,"Y",IF(H167>Q167,"Y",IF(I167>R167,"Y",IF(J167>S167,"Y",IF(K167>T167,"Y",IF(L167>U167,"Y",IF(M167>V167,"Y","N"))))))) -> N | X167: =IF(W167="Y",MAX((G167-P167),(H167-Q167),(I167-R167),(J167-S167),(K167-T167),(L167-U167),(M167-V167))/10,0) -> 0 | Y167: =IF(X167<5%,"0-4.9%",IF(X167<25%,"5-25%",IF(X167<50%,"25-50%","Over 50%"))) -> 0-4.9% | Z167: Empty
... A214: 159 | C214: UAG 556T | D214: =IF(COUNT(G214:M214)>3,10,IF(COUNT(G214:M214)>2,9,7)) -> 9 | F214: S2.T8 | G214: 6.45 | H214: 8.3 | I214: 8.05 | N214: =SUM(G214:M214) -> 22.8 | O214: =(N214/8.16)^4.5 -> 101.88285 | P214: 8 | Q214: 10 | R214: 9 | S214: 9 | T214: 9 | U214: 9 | V214: 9 | W214: =IF(G214>P214,"Y",IF(H214>Q214,"Y",IF(I214>R214,"Y",IF(J214>S214,"Y",IF(K214>T214,"Y",IF(L214>U214,"Y",IF(M214>V214,"Y","N"))))))) -> N | X214: =IF(W214="Y",MAX((G214-P214),(H214-Q214),(I214-R214),(J214-S214),(K214-T214),(L214-U214),(M214-V214))/10,0) -> 0 | Y214: =IF(X214<5%,"0-4.9%",IF(X214<25%,"5-25%",IF(X214<50%,"25-50%","Over 50%"))) -> 0-4.9% | Z214: Household retail products
A215: 045 | C215: KBG 46 | D215: =IF(COUNT(G215:M215)>3,10,IF(COUNT(G215:M215)>2,9,7)) -> 10 | F215: =#REF! -> #REF! | G215: 6.05 | H215: 8.25 | I215: 8.3 | J215: 8.3 | K215: 8.45 | L215: 9.8 | N215: =SUM(G215:M215) -> 49.15 | O215: =(N215/8.16)^4.5 -> 3230.3541 | P215: 8 | Q215: 10 | R215: 9 | S215: 9 | T215: 9 | U215: 9 | V215: 9 | W215: =IF(G215>P215,"Y",IF(H215>Q215,"Y",IF(I215>R215,"Y",IF(J215>S215,"Y",IF(K215>T215,"Y",IF(L215>U215,"Y",IF(M215>V215,"Y","N"))))))) -> Y | X215: =IF(W215="Y",MAX((G215-P215),(H215-Q215),(I215-R215),(J215-S215),(K215-T215),(L215-U215),(M215-V215))/10,0) -> 0.08 | Y215: =IF(X215<5%,"0-4.9%",IF(X215<25%,"5-25%",IF(X215<50%,"25-50%","Over 50%"))) -> 5-25% | Z215: Others
A216: 049 | C216: KAW 687K | D216: =IF(COUNT(G216:M216)>3,10,IF(COUNT(G216:M216)>2,9,7)) -> 10 | F216: S2.T8.T12 | G216: 6.25 | H216: 6.1 | I216: 6.65 | J216: 6.9 | K216: 6.8 | L216: 8 | N216: =SUM(G216:M216) -> 40.7 | O216: =(N216/8.16)^4.5 -> 1382.1944 | P216: 8 | Q216: 10 | R216: 9 | S216: 9 | T216: 9 | U216: 9 | V216: 9 | W216: =IF(G216>P216,"Y",IF(H216>Q216,"Y",IF(I216>R216,"Y",IF(J216>S216,"Y",IF(K216>T216,"Y",IF(L216>U216,"Y",IF(M216>V216,"Y","N"))))))) -> N | X216: =IF(W216="Y",MAX((G216-P216),(H216-Q216),(I216-R216),(J216-S216),(K216-T216),(L216-U216),(M216-V216))/10,0) -> 0 | Y216: =IF(X216<5%,"0-4.9%",IF(X216<25%,"5-25%",IF(X216<50%,"25-50%","Over 50%"))) -> 0-4.9% | Z216: Household retail products
A217: 050 | C217: KAP 544F | D217: =IF(COUNT(G217:M217)>3,10,IF(COUNT(G217:M217)>2,9,7)) -> 10 | F217: =F216 -> S2.T8.T12 | G217: 5.85 | H217: 7.5 | I217: 7.15 | J217: 7.2 | K217: 7.75 | L217: 10.4 | N217: =SUM(G217:M217) -> 45.85 | O217: =(N217/8.16)^4.5 -> 2362.7693 | P217: 8 | Q217: 10 | R217: 9 | S217: 9 | T217: 9 | U217: 9 | V217: 9 | W217: =IF(G217>P217,"Y",IF(H217>Q217,"Y",IF(I217>R217,"Y",IF(J217>S217,"Y",IF(K217>T217,"Y",IF(L217>U217,"Y",IF(M217>V217,"Y","N"))))))) -> Y | X217: =IF(W217="Y",MAX((G217-P217),(H217-Q217),(I217-R217),(J217-S217),(K217-T217),(L217-U217),(M217-V217))/10,0) -> 0.14 | Y217: =IF(X217<5%,"0-4.9%",IF(X217<25%,"5-25%",IF(X217<50%,"25-50%","Over 50%"))) -> 5-25% | Z217: Household retail products
A218: 053 | C218: KAU 130U | D218: =IF(COUNT(G218:M218)>3,10,IF(COUNT(G218:M218)>2,9,7)) -> 10 | F218: S2.T8.T12 | G218: 4 | H218: 10.25 | I218: 4.5 | J218: 10.05 | K218: 8.45 | L218: 9.15 | N218: =SUM(G218:M218) -> 46.4 | O218: =(N218/8.16)^4.5 -> 2493.0168 | P218: 8 | Q218: 10 | R218: 9 | S218: 9 | T218: 9 | U218: 9 | V218: 9 | W218: =IF(G218>P218,"Y",IF(H218>Q218,"Y",IF(I218>R218,"Y",IF(J218>S218,"Y",IF(K218>T218,"Y",IF(L218>U218,"Y",IF(M218>V218,"Y","N"))))))) -> Y | X218: =IF(W218="Y",MAX((G218-P218),(H218-Q218),(I218-R218),(J218-S218),(K218-T218),(L218-U218),(M218-V218))/10,0) -> 0.105 | Y218: =IF(X218<5%,"0-4.9%",IF(X218<25%,"5-25%",IF(X218<50%,"25-50%","Over 50%"))) -> 5-25% | Z218: Construction Material
A219: 054 | C219: KBK 554R | D219: =IF(COUNT(G219:M219)>3,10,IF(COUNT(G219:M219)>2,9,7)) -> 10 | F219: S2.T6.T12 | G219: 6.85 | H219: 7.55 | I219: 6.15 | J219: 6.2 | K219: 8.8 | L219: 12.35 | N219: =SUM(G219:M219) -> 47.9 | O219: =(N219/8.16)^4.5 -> 2876.7631 | P219: 8 | Q219: 10 | R219: 9 | S219: 9 | T219: 9 | U219: 9 | V219: 9 | W219: =IF(G219>P219,"Y",IF(H219>Q219,"Y",IF(I219>R219,"Y",IF(J219>S219,"Y",IF(K219>T219,"Y",IF(L219>U219,"Y",IF(M219>V219,"Y","N"))))))) -> Y | X219: =IF(W219="Y",MAX((G219-P219),(H219-Q219),(I219-R219),(J219-S219),(K219-T219),(L219-U219),(M219-V219))/10,0) -> 0.335 | Y219: =IF(X219<5%,"0-4.9%",IF(X219<25%,"5-25%",IF(X219<50%,"25-50%","Over 50%"))) -> 25-50% | Z219: Household retail products
A220: 058 | C220: KBK 200P | D220: =IF(COUNT(G220:M220)>3,10,IF(COUNT(G220:M220)>2,9,7)) -> 10 | F220: S2.T8.T12 | G220: 5.3 | H220: 8.6 | I220: 6.95 | J220: 8.5 | K220: 8.85 | L220: 10.75 | N220: =SUM(G220:M220) -> 48.95 | O220: =(N220/8.16)^4.5 -> 3171.622 | P220: 8 | Q220: 10 | R220: 9 | S220: 9 | T220: 9 | U220: 9 | V220: 9 | W220: =IF(G220>P220,"Y",IF(H220>Q220,"Y",IF(I220>R220,"Y",IF(J220>S220,"Y",IF(K220>T220,"Y",IF(L220>U220,"Y",IF(M220>V220,"Y","N"))))))) -> Y | X220: =IF(W220="Y",MAX((G220-P220),(H220-Q220),(I220-R220),(J220-S220),(K220-T220),(L220-U220),(M220-V220))/10,0) -> 0.175 | Y220: =IF(X220<5%,"0-4.9%",IF(X220<25%,"5-25%",IF(X220<50%,"25-50%","Over 50%"))) -> 5-25% | Z220: Household retail products
A221: 059 | C221: KAK 084B | D221: =IF(COUNT(G221:M221)>3,10,IF(COUNT(G221:M221)>2,9,7)) -> 10 | F221: =F220 -> S2.T8.T12 | G221: 7.2 | H221: 8.55 | I221: 6.55 | J221: 9.95 | K221: 8.45 | L221: 9.9 | N221: =SUM(G221:M221) -> 50.6 | O221: =(N221/8.16)^4.5 -> 3681.8968 | P221: 8 | Q221: 10 | R221: 9 | S221: 9 | T221: 9 | U221: 9 | V221: 9 | W221: =IF(G221>P221,"Y",IF(H221>Q221,"Y",IF(I221>R221,"Y",IF(J221>S221,"Y",IF(K221>T221,"Y",IF(L221>U221,"Y",IF(M221>V221,"Y","N"))))))) -> Y | X221: =IF(W221="Y",MAX((G221-P221),(H221-Q221),(I221-R221),(J221-S221),(K221-T221),(L221-U221),(M221-V221))/10,0) -> 0.095 | Y221: =IF(X221<5%,"0-4.9%",IF(X221<25%,"5-25%",IF(X221<50%,"25-50%","Over 50%"))) -> 5-25% | Z221: Household retail products
A222: 060 | C222: KBF 375H | D222: =IF(COUNT(G222:M222)>3,10,IF(COUNT(G222:M222)>2,9,7)) -> 10 | F222: =F221 -> S2.T8.T12 | G222: 5.9 | H222: 6.5 | I222: 8.15 | J222: 7.6 | K222: 8.9 | L222: 8.55 | N222: =SUM(G222:M222) -> 45.6 | O222: =(N222/8.16)^4.5 -> 2305.3458 | P222: 8 | Q222: 10 | R222: 9 | S222: 9 | T222: 9 | U222: 9 | V222: 9 | W222: =IF(G222>P222,"Y",IF(H222>Q222,"Y",IF(I222>R222,"Y",IF(J222>S222,"Y",IF(K222>T222,"Y",IF(L222>U222,"Y",IF(M222>V222,"Y","N"))))))) -> N | X222: =IF(W222="Y",MAX((G222-P222),(H222-Q222),(I222-R222),(J222-S222),(K222-T222),(L222-U222),(M222-V222))/10,0) -> 0 | Y222: =IF(X222<5%,"0-4.9%",IF(X222<25%,"5-25%",IF(X222<50%,"25-50%","Over 50%"))) -> 0-4.9% | Z222: Others
...

Sheet Jinja-Kla
A1: AXLE LOAD SURVEY FORM
A2: Date: | D2: Station Name: | E2: NAKIBIZZI
A3: 43772 | H3: JINJA-KAMPALA
A4: S/No. | B4: Time | C4: Reg. Number | D4: Vehicle Type | E4: Number of Axles | F4: Axle Configuration | G4: Front | N4: Total (Tonnes) | O4: Total (ESA's) | P4: Load limit (Tonnes) | W4: OVERLOADED? | X4: Overloaded by? | Y4: Overload Bands | Z4: COMMENTS
G5: Axle 1 | H5: Axle 2 | I5: Axle 3 | J5: Axle 4 | K5: Axle 5 | L5: Axle 6 | M5: Axle 7 | P5: Axle 1 | Q5: Axle 2 | R5: Axle 3 | S5: Axle 4 | T5: Axle 5 | U5: Axle 6 | V5: Axle 7
A6: 5 | B6: 0.44097222 | C6: UAY 484 B | D6: =IF(COUNT(G6:M6)>3,10,IF(COUNT(G6:M6)>2,9,7)) -> 7 | E6: 2 | F6: 1*2 | G6: 3.4 | H6: 8.55 | N6: =SUM(G6:M6) -> 11.95 | O6: =(N6/8.16)^4.5 -> 5.5660853 | P6: 8 | Q6: 10 | R6: 9 | S6: 9 | T6: 9 | U6: 9 | V6: 9 | W6: =IF(G6>P6,"Y",IF(H6>Q6,"Y",IF(I6>R6,"Y",IF(J6>S6,"Y",IF(K6>T6,"Y",IF(L6>U6,"Y",IF(M6>V6,"Y","N"))))))) -> N | X6: =IF(W6="Y",MAX((G6-P6),(H6-Q6),(I6-R6),(J6-S6),(K6-T6),(L6-U6),(M6-V6))/10,0) -> 0 | Y6: =IF(X6<5%,"0-4.9%",IF(X6<25%,"5-25%",IF(X6<50%,"25-50%","Over 50%"))) -> 0-4.9% | Z6: Others
A7: 10 | B7: 0.52083333 | C7: UAN 676X | D7: =IF(COUNT(G7:M7)>3,10,IF(COUNT(G7:M7)>2,9,7)) -> 7 | E7: 2 | F7: 1*2 | G7: 3.9 | H7: 9.2 | N7: =SUM(G7:M7) -> 13.1 | O7: =(N7/8.16)^4.5 -> 8.416182 | P7: 8 | Q7: 10 | R7: 9 | S7: 9 | T7: 9 | U7: 9 | V7: 9 | W7: =IF(G7>P7,"Y",IF(H7>Q7,"Y",IF(I7>R7,"Y",IF(J7>S7,"Y",IF(K7>T7,"Y",IF(L7>U7,"Y",IF(M7>V7,"Y","N"))))))) -> N | X7: =IF(W7="Y",MAX((G7-P7),(H7-Q7),(I7-R7),(J7-S7),(K7-T7),(L7-U7),(M7-V7))/10,0) -> 0 | Y7: =IF(X7<5%,"0-4.9%",IF(X7<25%,"5-25%",IF(X7<50%,"25-50%","Over 50%"))) -> 0-4.9% | Z7: Chemical Products
A8: 13 | B8: 0.54652778 | C8: UAZ 536X | D8: =IF(COUNT(G8:M8)>3,10,IF(COUNT(G8:M8)>2,9,7)) -> 7 | E8: 2 | F8: 1*2 | G8: 3.25 | H8: 12.85 | N8: =SUM(G8:M8) -> 16.1 | O8: =(N8/8.16)^4.5 -> 21.286817 | P8: 8 | Q8: 10 | R8: 9 | S8: 9 | T8: 9 | U8: 9 | V8: 9 | W8: =IF(G8>P8,"Y",IF(H8>Q8,"Y",IF(I8>R8,"Y",IF(J8>S8,"Y",IF(K8>T8,"Y",IF(L8>U8,"Y",IF(M8>V8,"Y","N"))))))) -> Y | X8: =IF(W8="Y",MAX((G8-P8),(H8-Q8),(I8-R8),(J8-S8),(K8-T8),(L8-U8),(M8-V8))/10,0) -> 0.285 | Y8: =IF(X8<5%,"0-4.9%",IF(X8<25%,"5-25%",IF(X8<50%,"25-50%","Over 50%"))) -> 25-50% | Z8: Agricultural produce
A9: 15 | B9: 0.55555556 | C9: UAN 583A | D9: =IF(COUNT(G9:M9)>3,10,IF(COUNT(G9:M9)>2,9,7)) -> 7 | E9: 2 | F9: 1*2 | G9: 3.85 | H9: 9.1 | N9: =SUM(G9:M9) -> 12.95 | O9: =(N9/8.16)^4.5 -> 7.9911309 | P9: 8 | Q9: 10 | R9: 9 | S9: 9 | T9: 9 | U9: 9 | V9: 9 | W9: =IF(G9>P9,"Y",IF(H9>Q9,"Y",IF(I9>R9,"Y",IF(J9>S9,"Y",IF(K9>T9,"Y",IF(L9>U9,"Y",IF(M9>V9,"Y","N"))))))) -> N | X9: =IF(W9="Y",MAX((G9-P9),(H9-Q9),(I9-R9),(J9-S9),(K9-T9),(L9-U9),(M9-V9))/10,0) -> 0 | Y9: =IF(X9<5%,"0-4.9%",IF(X9<25%,"5-25%",IF(X9<50%,"25-50%","Over 50%"))) -> 0-4.9% | Z9: Household retail products
A10: 19 | B10: 0.63888889 | C10: UBD 675Y | D10: =IF(COUNT(G10:M10)>3,10,IF(COUNT(G10:M10)>2,9,7)) -> 7 | E10: 2 | F10: 1*2 | G10: 3.7 | H10: 9.75 | N10: =SUM(G10:M10) -> 13.45 | O10: =(N10/8.16)^4.5 -> 9.4764258 | P10: 8 | Q10: 10 | R10: 9 | S10: 9 | T10: 9 | U10: 9 | V10: 9 | W10: =IF(G10>P10,"Y",IF(H10>Q10,"Y",IF(I10>R10,"Y",IF(J10>S10,"Y",IF(K10>T10,"Y",IF(L10>U10,"Y",IF(M10>V10,"Y","N"))))))) -> N | X10: =IF(W10="Y",MAX((G10-P10),(H10-Q10),(I10-R10),(J10-S10),(K10-T10),(L10-U10),(M10-V10))/10,0) -> 0 | Y10: =IF(X10<5%,"0-4.9%",IF(X10<25%,"5-25%",IF(X10<50%,"25-50%","Over 50%"))) -> 0-4.9% | Z10: Agricultural produce
A11: 5 | B11: 0.38611111 | C11: UAP 906F | D11: =IF(COUNT(G11:M11)>3,10,IF(COUNT(G11:M11)>2,9,7)) -> 7 | E11: 2 | F11: 1*2 | G11: 3.3 | H11: 12.65 | N11: =SUM(G11:M11) -> 15.95 | O11: =(N11/8.16)^4.5 -> 20.408796 | P11: 8 | Q11: 10 | R11: 9 | S11: 9 | T11: 9 | U11: 9 | V11: 9 | W11: =IF(G11>P11,"Y",IF(H11>Q11,"Y",IF(I11>R11,"Y",IF(J11>S11,"Y",IF(K11>T11,"Y",IF(L11>U11,"Y",IF(M11>V11,"Y","N"))))))) -> Y | X11: =IF(W11="Y",MAX((G11-P11),(H11-Q11),(I11-R11),(J11-S11),(K11-T11),(L11-U11),(M11-V11))/10,0) -> 0.265 | Y11: =IF(X11<5%,"0-4.9%",IF(X11<25%,"5-25%",IF(X11<50%,"25-50%","Over 50%"))) -> 25-50% | Z11: Agricultural produce
A12: 13 | B12: 0.55694444 | C12: UBF 028K | D12: =IF(COUNT(G12:M12)>3,10,IF(COUNT(G12:M12)>2,9,7)) -> 7 | E12: 2 | F12: 1*2 | G12: 3.6 | H12: 12.1 | N12: =SUM(G12:M12) -> 15.7 | O12: =(N12/8.16)^4.5 -> 19.008276 | P12: 8 | Q12: 10 | R12: 9 | S12: 9 | T12: 9 | U12: 9 | V12: 9 | W12: =IF(G12>P12,"Y",IF(H12>Q12,"Y",IF(I12>R12,"Y",IF(J12>S12,"Y",IF(K12>T12,"Y",IF(L12>U12,"Y",IF(M12>V12,"Y","N"))))))) -> Y | X12: =IF(W12="Y",MAX((G12-P12),(H12-Q12),(I12-R12),(J12-S12),(K12-T12),(L12-U12),(M12-V12))/10,0) -> 0.21 | Y12: =IF(X12<5%,"0-4.9%",IF(X12<25%,"5-25%",IF(X12<50%,"25-50%","Over 50%"))) -> 5-25% | Z12: Agricultural produce
A13: 14 | B13: 0.56944444 | C13: UAW 255B | D13: =IF(COUNT(G13:M13)>3,10,IF(COUNT(G13:M13)>2,9,7)) -> 7 | E13: 2 | F13: 1*2 | G13: 4.15 | H13: 9.45 | N13: =SUM(G13:M13) -> 13.6 | O13: =(N13/8.16)^4.5 -> 9.9613769 | P13: 8 | Q13: 10 | R13: 9 | S13: 9 | T13: 9 | U13: 9 | V13: 9 | W13: =IF(G13>P13,"Y",IF(H13>Q13,"Y",IF(I13>R13,"Y",IF(J13>S13,"Y",IF(K13>T13,"Y",IF(L13>U13,"Y",IF(M13>V13,"Y","N"))))))) -> N | X13: =IF(W13="Y",MAX((G13-P13),(H13-Q13),(I13-R13),(J13-S13),(K13-T13),(L13-U13),(M13-V13))/10,0) -> 0 | Y13: =IF(X13<5%,"0-4.9%",IF(X13<25%,"5-25%",IF(X13<50%,"25-50%","Over 50%"))) -> 0-4.9% | Z13: Agricultural produce
A14: 15 | B14: 0.57986111 | C14: UAU 690M | D14: =IF(COUNT(G14:M14)>3,10,IF(COUNT(G14:M14)>2,9,7)) -> 7 | E14: 2 | F14: 1*2 | G14: 3.5 | H14: 7.15 | N14: =SUM(G14:M14) -> 10.65 | O14: =(N14/8.16)^4.5 -> 3.3148778 | P14: 8 | Q14: 10 | R14: 9 | S14: 9 | T14: 9 | U14: 9 | V14: 9 | W14: =IF(G14>P14,"Y",IF(H14>Q14,"Y",IF(I14>R14,"Y",IF(J14>S14,"Y",IF(K14>T14,"Y",IF(L14>U14,"Y",IF(M14>V14,"Y","N"))))))) -> N | X14: =IF(W14="Y",MAX((G14-P14),(H14-Q14),(I14-R14),(J14-S14),(K14-T14),(L14-U14),(M14-V14))/10,0) -> 0 | Y14: =IF(X14<5%,"0-4.9%",IF(X14<25%,"5-25%",IF(X14<50%,"25-50%","Over 50%"))) -> 0-4.9% | Z14: Others
A15: 16 | B15: 0.58402778 | C15: UAQ 159T | D15: =IF(COUNT(G15:M15)>3,10,IF(COUNT(G15:M15)>2,9,7)) -> 7 | E15: 2 | F15: 1*2 | G15: 5.6 | H15: 10.7 | N15: =SUM(G15:M15) -> 16.3 | O15: =(N15/8.16)^4.5 -> 22.502901 | P15: 8 | Q15: 10 | R15: 9 | S15: 9 | T15: 9 | U15: 9 | V15: 9 | W15: =IF(G15>P15,"Y",IF(H15>Q15,"Y",IF(I15>R15,"Y",IF(J15>S15,"Y",IF(K15>T15,"Y",IF(L15>U15,"Y",IF(M15>V15,"Y","N"))))))) -> Y | X15: =IF(W15="Y",MAX((G15-P15),(H15-Q15),(I15-R15),(J15-S15),(K15-T15),(L15-U15),(M15-V15))/10,0) -> 0.07 | Y15: =IF(X15<5%,"0-4.9%",IF(X15<25%,"5-25%",IF(X15<50%,"25-50%","Over 50%"))) -> 5-25% | Z15: Household retail products
A16: 17 | B16: 0.58888889 | C16: UBF 018K | D16: =IF(COUNT(G16:M16)>3,10,IF(COUNT(G16:M16)>2,9,7)) -> 7 | E16: 2 | F16: 1*2 | G16: 3.55 | H16: 10.1 | N16: =SUM(G16:M16) -> 13.65 | O16: =(N16/8.16)^4.5 -> 10.127243 | P16: 8 | Q16: 10 | R16: 9 | S16: 9 | T16: 9 | U16: 9 | V16: 9 | W16: =IF(G16>P16,"Y",IF(H16>Q16,"Y",IF(I16>R16,"Y",IF(J16>S16,"Y",IF(K16>T16,"Y",IF(L16>U16,"Y",IF(M16>V16,"Y","N"))))))) -> Y | X16: =IF(W16="Y",MAX((G16-P16),(H16-Q16),(I16-R16),(J16-S16),(K16-T16),(L16-U16),(M16-V16))/10,0) -> 0.01 | Y16: =IF(X16<5%,"0-4.9%",IF(X16<25%,"5-25%",IF(X16<50%,"25-50%","Over 50%"))) -> 0-4.9% | Z16: Agricultural produce
A17: 18 | B17: 0.59236111 | C17: UAU 743H | D17: =IF(COUNT(G17:M17)>3,10,IF(COUNT(G17:M17)>2,9,7)) -> 7 | E17: 2 | F17: 1*2 | G17: 3.2 | H17: 11 | N17: =SUM(G17:M17) -> 14.2 | O17: =(N17/8.16)^4.5 -> 12.097394 | P17: 8 | Q17: 10 | R17: 9 | S17: 9 | T17: 9 | U17: 9 | V17: 9 | W17: =IF(G17>P17,"Y",IF(H17>Q17,"Y",IF(I17>R17,"Y",IF(J17>S17,"Y",IF(K17>T17,"Y",IF(L17>U17,"Y",IF(M17>V17,"Y","N"))))))) -> Y | X17: =IF(W17="Y",MAX((G17-P17),(H17-Q17),(I17-R17),(J17-S17),(K17-T17),(L17-U17),(M17-V17))/10,0) -> 0.1 | Y17: =IF(X17<5%,"0-4.9%",IF(X17<25%,"5-25%",IF(X17<50%,"25-50%","Over 50%"))) -> 5-25% | Z17: Agricultural produce
... A23: 25 | B23: 0.63194444 | C23: UAP 910L | D23: =IF(COUNT(G23:M23)>3,10,IF(COUNT(G23:M23)>2,9,7)) -> 7 | E23: 2 | F23: 1*2 | G23: 4.95 | H23: 9.9 | N23: =SUM(G23:M23) -> 14.85 | O23: =(N23/8.16)^4.5 -> 14.796647 | P23: 8 | Q23: 10 | R23: 9 | S23: 9 | T23: 9 | U23: 9 | V23: 9 | W23: =IF(G23>P23,"Y",IF(H23>Q23,"Y",IF(I23>R23,"Y",IF(J23>S23,"Y",IF(K23>T23,"Y",IF(L23>U23,"Y",IF(M23>V23,"Y","N"))))))) -> N | X23: =IF(W23="Y",MAX((G23-P23),(H23-Q23),(I23-R23),(J23-S23),(K23-T23),(L23-U23),(M23-V23))/10,0) -> 0 | Y23: =IF(X23<5%,"0-4.9%",IF(X23<25%,"5-25%",IF(X23<50%,"25-50%","Over 50%"))) -> 0-4.9% | Z23: Household retail products
A24: 7 | B24: 0.47152778 | C24: UAX 416B | D24: =IF(COUNT(G24:M24)>3,10,IF(COUNT(G24:M24)>2,9,7)) -> 9 | E24: 3 | F24: 1*21 | G24: 7.1 | H24: 9.2 | I24: 5.8 | N24: =SUM(G24:M24) -> 22.1 | O24: =(N24/8.16)^4.5 -> 88.544077 | P24: 8 | Q24: 10 | R24: 9 | S24: 9 | T24: 9 | U24: 9 | V24: 9 | W24: =IF(G24>P24,"Y",IF(H24>Q24,"Y",IF(I24>R24,"Y",IF(J24>S24,"Y",IF(K24>T24,"Y",IF(L24>U24,"Y",IF(M24>V24,"Y","N"))))))) -> N | X24: =IF(W24="Y",MAX((G24-P24),(H24-Q24),(I24-R24),(J24-S24),(K24-T24),(L24-U24),(M24-V24))/10,0) -> 0 | Y24: =IF(X24<5%,"0-4.9%",IF(X24<25%,"5-25%",IF(X24<50%,"25-50%","Over 50%"))) -> 0-4.9% | Z24: Household retail products
A25: 9 | B25: 0.50833333 | C25: UAH 982 V | D25: =IF(COUNT(G25:M25)>3,10,IF(COUNT(G25:M25)>2,9,7)) -> 9 | E25: 3 | F25: 1*22 | G25: 7.45 | H25: 7.3 | I25: 7.75 | N25: =SUM(G25:M25) -> 22.5 | O25: =(N25/8.16)^4.5 -> 95.987707 | P25: 8 | Q25: 10 | R25: 9 | S25: 9 | T25: 9 | U25: 9 | V25: 9 | W25: =IF(G25>P25,"Y",IF(H25>Q25,"Y",IF(I25>R25,"Y",IF(J25>S25,"Y",IF(K25>T25,"Y",IF(L25>U25,"Y",IF(M25>V25,"Y","N"))))))) -> N | X25: =IF(W25="Y",MAX((G25-P25),(H25-Q25),(I25-R25),(J25-S25),(K25-T25),(L25-U25),(M25-V25))/10,0) -> 0 | Y25: =IF(X25<5%,"0-4.9%",IF(X25<25%,"5-25%",IF(X25<50%,"25-50%","Over 50%"))) -> 0-4.9% | Z25: Fuels
A26: 18 | B26: 0.61944444 | C26: UAN 272 D | D26: =IF(COUNT(G26:M26)>3,10,IF(COUNT(G26:M26)>2,9,7)) -> 9 | E26: 3 | F26: 1*22 | G26: 5.3 | H26: 9.6 | I26: 9.3 | N26: =SUM(G26:M26) -> 24.2 | O26: =(N26/8.16)^4.5 -> 133.21816 | P26: 8 | Q26: 10 | R26: 9 | S26: 9 | T26: 9 | U26: 9 | V26: 9 | W26: =IF(G26>P26,"Y",IF(H26>Q26,"Y",IF(I26>R26,"Y",IF(J26>S26,"Y",IF(K26>T26,"Y",IF(L26>U26,"Y",IF(M26>V26,"Y","N"))))))) -> Y | X26: =IF(W26="Y",MAX((G26-P26),(H26-Q26),(I26-R26),(J26-S26),(K26-T26),(L26-U26),(M26-V26))/10,0) -> 0.03 | Y26: =IF(X26<5%,"0-4.9%",IF(X26<25%,"5-25%",IF(X26<50%,"25-50%","Over 50%"))) -> 0-4.9% | Z26: Household retail products
A27: 3 | B27: 0.37152778 | C27: UBD 281X | D27: =IF(COUNT(G27:M27)>3,10,IF(COUNT(G27:M27)>2,9,7)) -> 9 | E27: 3 | F27: 1*22 | G27: 4.65 | H27: 8.6 | I27: 10.25 | N27: =SUM(G27:M27) -> 23.5 | O27: =(N27/8.16)^4.5 -> 116.73462 | P27: 8 | Q27: 10 | R27: 9 | S27: 9 | T27: 9 | U27: 9 | V27: 9 | W27: =IF(G27>P27,"Y",IF(H27>Q27,"Y",IF(I27>R27,"Y",IF(J27>S27,"Y",IF(K27>T27,"Y",IF(L27>U27,"Y",IF(M27>V27,"Y","N"))))))) -> Y | X27: =IF(W27="Y",MAX((G27-P27),(H27-Q27),(I27-R27),(J27-S27),(K27-T27),(L27-U27),(M27-V27))/10,0) -> 0.125 | Y27: =IF(X27<5%,"0-4.9%",IF(X27<25%,"5-25%",IF(X27<50%,"25-50%","Over 50%"))) -> 5-25% | Z27: Agricultural produce
A28: 8 | B28: 0.43263889 | C28: UAU 152S | D28: =IF(COUNT(G28:M28)>3,10,IF(COUNT(G28:M28)>2,9,7)) -> 9 | E28: 3 | F28: 1*22 | G28: 6.2 | H28: 14.7 | I28: 4.65 | N28: =SUM(G28:M28) -> 25.55 | O28: =(N28/8.16)^4.5 -> 170.08004 | P28: 8 | Q28: 10 | R28: 9 | S28: 9 | T28: 9 | U28: 9 | V28: 9 | W28: =IF(G28>P28,"Y",IF(H28>Q28,"Y",IF(I28>R28,"Y",IF(J28>S28,"Y",IF(K28>T28,"Y",IF(L28>U28,"Y",IF(M28>V28,"Y","N"))))))) -> Y | X28: =IF(W28="Y",MAX((G28-P28),(H28-Q28),(I28-R28),(J28-S28),(K28-T28),(L28-U28),(M28-V28))/10,0) -> 0.47 | Y28: =IF(X28<5%,"0-4.9%",IF(X28<25%,"5-25%",IF(X28<50%,"25-50%","Over 50%"))) -> 25-50% | Z28: Household retail products
A29: 10 | B29: 0.46180556 | C29: UAV 368E | D29: =IF(COUNT(G29:M29)>3,10,IF(COUNT(G29:M29)>2,9,7)) -> 9 | E29: 3 | F29: 1*22 | G29: 7 | H29: 12.8 | I29: 4.75 | N29: =SUM(G29:M29) -> 24.55 | O29: =(N29/8.16)^4.5 -> 142.11045 | P29: 8 | Q29: 10 | R29: 9 | S29: 9 | T29: 9 | U29: 9 | V29: 9 | W29: =IF(G29>P29,"Y",IF(H29>Q29,"Y",IF(I29>R29,"Y",IF(J29>S29,"Y",IF(K29>T29,"Y",IF(L29>U29,"Y",IF(M29>V29,"Y","N"))))))) -> Y | X29: =IF(W29="Y",MAX((G29-P29),(H29-Q29),(I29-R29),(J29-S29),(K29-T29),(L29-U29),(M29-V29))/10,0) -> 0.28 | Y29: =IF(X29<5%,"0-4.9%",IF(X29<25%,"5-25%",IF(X29<50%,"25-50%","Over 50%"))) -> 25-50% | Z29: Household retail products
A30: 20 | B30: 0.63263889 | C30: UAZ 192V | D30: =IF(COUNT(G30:M30)>3,10,IF(COUNT(G30:M30)>2,9,7)) -> 9 | E30: 3 | F30: 1*22 | G30: 4.35 | H30: 10.2 | I30: 10.85 | N30: =SUM(G30:M30) -> 25.4 | O30: =(N30/8.16)^4.5 -> 165.63267 | P30: 8 | Q30: 10 | R30: 9 | S30: 9 | T30: 9 | U30: 9 | V30: 9 | W30: =IF(G30>P30,"Y",IF(H30>Q30,"Y",IF(I30>R30,"Y",IF(J30>S30,"Y",IF(K30>T30,"Y",IF(L30>U30,"Y",IF(M30>V30,"Y","N"))))))) -> Y | X30: =IF(W30="Y",MAX((G30-P30),(H30-Q30),(I30-R30),(J30-S30),(K30-T30),(L30-U30),(M30-V30))/10,0) -> 0.185 | Y30: =IF(X30<5%,"0-4.9%",IF(X30<25%,"5-25%",IF(X30<50%,"25-50%","Over 50%"))) -> 5-25% | Z30: Fuels
A31: 24 | B31: 0.67916667 | C31: UBE 457R | D31: =IF(COUNT(G31:M31)>3,10,IF(COUNT(G31:M31)>2,9,7)) -> 9 | E31: 3 | F31: 1*22 | G31: 4.95 | H31: 9.05 | I31: 9.45 | N31: =SUM(G31:M31) -> 23.45 | O31: =(N31/8.16)^4.5 -> 115.6211 | P31: 8 | Q31: 10 | R31: 9 | S31: 9 | T31: 9 | U31: 9 | V31: 9 | W31: =IF(G31>P31,"Y",IF(H31>Q31,"Y",IF(I31>R31,"Y",IF(J31>S31,"Y",IF(K31>T31,"Y",IF(L31>U31,"Y",IF(M31>V31,"Y","N"))))))) -> Y | X31: =IF(W31="Y",MAX((G31-P31),(H31-Q31),(I31-R31),(J31-S31),(K31-T31),(L31-U31),(M31-V31))/10,0) -> 0.045 | Y31: =IF(X31<5%,"0-4.9%",IF(X31<25%,"5-25%",IF(X31<50%,"25-50%","Over 50%"))) -> 0-4.9% | Z31: Agricultural produce
A32: 3 | B32: 0.38888889 | C32: UAY 324T | D32: =IF(COUNT(G32:M32)>3,10,IF(COUNT(G32:M32)>2,9,7)) -> 9 | E32: 3 | F32: 1*22 | G32: 3.75 | H32: 11 | I32: 11.75 | N32: =SUM(G32:M32) -> 26.5 | O32: =(N32/8.16)^4.5 -> 200.44753 | P32: 8 | Q32: 10 | R32: 9 | S32: 9 | T32: 9 | U32: 9 | V32: 9 | W32: =IF(G32>P32,"Y",IF(H32>Q32,"Y",IF(I32>R32,"Y",IF(J32>S32,"Y",IF(K32>T32,"Y",IF(L32>U32,"Y",IF(M32>V32,"Y","N"))))))) -> Y | X32: =IF(W32="Y",MAX((G32-P32),(H32-Q32),(I32-R32),(J32-S32),(K32-T32),(L32-U32),(M32-V32))/10,0) -> 0.275 | Y32: =IF(X32<5%,"0-4.9%",IF(X32<25%,"5-25%",IF(X32<50%,"25-50%","Over 50%"))) -> 25-50% | Z32: Agricultural produce
A33: 4 | B33: 0.40902778 | C33: UAV 010F | D33: =IF(COUNT(G33:M33)>3,10,IF(COUNT(G33:M33)>2,9,7)) -> 9 | E33: 3 | F33: 1*22 | G33: 4.2 | H33: 9.8 | I33: 9.35 | N33: =SUM(G33:M33) -> 23.35 | O33: =(N33/8.16)^4.5 -> 113.41886 | P33: 8 | Q33: 10 | R33: 9 | S33: 9 | T33: 9 | U33: 9 | V33: 9 | W33: =IF(G33>P33,"Y",IF(H33>Q33,"Y",IF(I33>R33,"Y",IF(J33>S33,"Y",IF(K33>T33,"Y",IF(L33>U33,"Y",IF(M33>V33,"Y","N"))))))) -> Y | X33: =IF(W33="Y",MAX((G33-P33),(H33-Q33),(I33-R33),(J33-S33),(K33-T33),(L33-U33),(M33-V33))/10,0) -> 0.035 | Y33: =IF(X33<5%,"0-4.9%",IF(X33<25%,"5-25%",IF(X33<50%,"25-50%","Over 50%"))) -> 0-4.9% | Z33: Agricultural produce
A34: 26 | B34: 0.6375 | C34: UAZ 192 H | D34: =IF(COUNT(G34:M34)>3,10,IF(COUNT(G34:M34)>2,9,7)) -> 9 | E34: 3 | F34: 1*22 | G34: 4.65 | H34: 11.35 | I34: 10.7 | N34: =SUM(G34:M34) -> 26.7 | O34: =(N34/8.16)^4.5 -> 207.34567 | P34: 8 | Q34: 10 | R34: 9 | S34: 9 | T34: 9 | U34: 9 | V34: 9 | W34: =IF(G34>P34,"Y",IF(H34>Q34,"Y",IF(I34>R34,"Y",IF(J34>S34,"Y",IF(K34>T34,"Y",IF(L34>U34,"Y",IF(M34>V34,"Y","N"))))))) -> Y | X34: =IF(W34="Y",MAX((G34-P34),(H34-Q34),(I34-R34),(J34-S34),(K34-T34),(L34-U34),(M34-V34))/10,0) -> 0.17 | Y34: =IF(X34<5%,"0-4.9%",IF(X34<25%,"5-25%",IF(X34<50%,"25-50%","Over 50%"))) -> 5-25% | Z34: Agricultural produce
A35: 27 | B35: 0.65972222 | C35: UBD 828J | D35: =IF(COUNT(G35:M35)>3,10,IF(COUNT(G35:M35)>2,9,7)) -> 9 | E35: 3 | F35: 1*22 | G35: 5.7 | H35: 8.7 | I35: 8.15 | N35: =SUM(G35:M35) -> 22.55 | O35: =(N35/8.16)^4.5 -> 96.951324 | P35: 8 | Q35: 10 | R35: 9 | S35: 9 | T35: 9 | U35: 9 | V35: 9 | W35: =IF(G35>P35,"Y",IF(H35>Q35,"Y",IF(I35>R35,"Y",IF(J35>S35,"Y",IF(K35>T35,"Y",IF(L35>U35,"Y",IF(M35>V35,"Y","N"))))))) -> N | X35: =IF(W35="Y",MAX((G35-P35),(H35-Q35),(I35-R35),(J35-S35),(K35-T35),(L35-U35),(M35-V35))/10,0) -> 0 | Y35: =IF(X35<5%,"0-4.9%",IF(X35<25%,"5-25%",IF(X35<50%,"25-50%","Over 50%"))) -> 0-4.9% | Z35: Others
A36: 28 | B36: 0.72222222 | C36: UAZ 225T | D36: =IF(COUNT(G36:M36)>3,10,IF(COUNT(G36:M36)>2,9,7)) -> 9 | E36: 3 | F36: 1*22 | G36: 3.9 | H36: 9.95 | I36: 9.6 | N36: =SUM(G36:M36) -> 23.45 | O36: =(N36/8.16)^4.5 -> 115.6211 | P36: 8 | Q36: 10 | R36: 9 | S36: 9 | T36: 9 | U36: 9 | V36: 9 | W36: =IF(G36>P36,"Y",IF(H36>Q36,"Y",IF(I36>R36,"Y",IF(J36>S36,"Y",IF(K36>T36,"Y",IF(L36>U36,"Y",IF(M36>V36,"Y","N"))))))) -> Y | X36: =IF(W36="Y",MAX((G36-P36),(H36-Q36),(I36-R36),(J36-S36),(K36-T36),(L36-U36),(M36-V36))/10,0) -> 0.06 | Y36: =IF(X36<5%,"0-4.9%",IF(X36<25%,"5-25%",IF(X36<50%,"25-50%","Over 50%"))) -> 5-25% | Z36: Agricultural produce
A37: 1 | B37: 0.40625 | C37: UBC 648D | D37: =IF(COUNT(G37:M37)>3,10,IF(COUNT(G37:M37)>2,9,7)) -> 10 | E37: 6 | F37: 1*22-222 | G37: 6.8 | H37: 7.8 | I37: 7.4 | J37: 7.3 | K37: 6.1 | L37: 6.3 | N37: =SUM(G37:M37) -> 41.7 | O37: =(N37/8.16)^4.5 -> 1541.7236 | P37: 8 | Q37: 10 | R37: 9 | S37: 9 | T37: 9 | U37: 9 | V37: 9 | W37: =IF(G37>P37,"Y",IF(H37>Q37,"Y",IF(I37>R37,"Y",IF(J37>S37,"Y",IF(K37>T37,"Y",IF(L37>U37,"Y",IF(M37>V37,"Y","N"))))))) -> N | X37: =IF(W37="Y",MAX((G37-P37),(H37-Q37),(I37-R37),(J37-S37),(K37-T37),(L37-U37),(M37-V37))/10,0) -> 0 | Y37: =IF(X37<5%,"0-4.9%",IF(X37<25%,"5-25%",IF(X37<50%,"25-50%","Over 50%"))) -> 0-4.9% | Z37: Agricultural produce
A38: 2 | B38: 0.41875 | C38: KAX 251 U | D38: =IF(COUNT(G38:M38)>3,10,IF(COUNT(G38:M38)>2,9,7)) -> 10 | E38: 6 | F38: 1*22-222 | G38: 5.55 | H38: 3.8 | I38: 7.6 | J38: 5.45 | K38: 5.1 | L38: 4.75 | N38: =SUM(G38:M38) -> 32.25 | O38: =(N38/8.16)^4.5 -> 485.04052 | P38: 8 | Q38: 10 | R38: 9 | S38: 9 | T38: 9 | U38: 9 | V38: 9 | W38: =IF(G38>P38,"Y",IF(H38>Q38,"Y",IF(I38>R38,"Y",IF(J38>S38,"Y",IF(K38>T38,"Y",IF(L38>U38,"Y",IF(M38>V38,"Y","N"))))))) -> N | X38: =IF(W38="Y",MAX((G38-P38),(H38-Q38),(I38-R38),(J38-S38),(K38-T38),(L38-U38),(M38-V38))/10,0) -> 0 | Y38: =IF(X38<5%,"0-4.9%",IF(X38<25%,"5-25%",IF(X38<50%,"25-50%","Over 50%"))) -> 0-4.9% | Z38: Agricultural produce
A39: 3 | B39: 0.42361111 | C39: KAW 037 R | D39: =IF(COUNT(G39:M39)>3,10,IF(COUNT(G39:M39)>2,9,7)) -> 10 | E39: 6 | F39: 1*22-222 | G39: 5.1 | H39: 3.35 | I39: 10.2 | J39: 8.1 | K39: 7.9 | L39: 7.3 | N39: =SUM(G39:M39) -> 41.95 | O39: =(N39/8.16)^4.5 -> 1583.7555 | P39: 8 | Q39: 10 | R39: 9 | S39: 9 | T39: 9 | U39: 9 | V39: 9 | W39: =IF(G39>P39,"Y",IF(H39>Q39,"Y",IF(I39>R39,"Y",IF(J39>S39,"Y",IF(K39>T39,"Y",IF(L39>U39,"Y",IF(M39>V39,"Y","N"))))))) -> Y | X39: =IF(W39="Y",MAX((G39-P39),(H39-Q39),(I39-R39),(J39-S39),(K39-T39),(L39-U39),(M39-V39))/10,0) -> 0.12 | Y39: =IF(X39<5%,"0-4.9%",IF(X39<25%,"5-25%",IF(X39<50%,"25-50%","Over 50%"))) -> 5-25% | Z39: Others
A40: 4 | B40: 0.4375 | C40: KCV 613 F | D40: =IF(COUNT(G40:M40)>3,10,IF(COUNT(G40:M40)>2,9,7)) -> 10 | E40: 6 | F40: 1*22-222 | G40: 5.7 | H40: 5.95 | I40: 8.9 | J40: 8.2 | K40: 6.6 | L40: 7.45 | N40: =SUM(G40:M40) -> 42.8 | O40: =(N40/8.16)^4.5 -> 1733.3699 | P40: 8 | Q40: 10 | R40: 9 | S40: 9 | T40: 9 | U40: 9 | V40: 9 | W40: =IF(G40>P40,"Y",IF(H40>Q40,"Y",IF(I40>R40,"Y",IF(J40>S40,"Y",IF(K40>T40,"Y",IF(L40>U40,"Y",IF(M40>V40,"Y","N"))))))) -> N | X40: =IF(W40="Y",MAX((G40-P40),(H40-Q40),(I40-R40),(J40-S40),(K40-T40),(L40-U40),(M40-V40))/10,0) -> 0 | Y40: =IF(X40<5%,"0-4.9%",IF(X40<25%,"5-25%",IF(X40<50%,"25-50%","Over 50%"))) -> 0-4.9% | Z40: Fuels
A41: 6 | B41: 0.4625 | C41: A 2588A | D41: =IF(COUNT(G41:M41)>3,10,IF(COUNT(G41:M41)>2,9,7)) -> 10 | E41: 7 | F41: 1*22+22*22 | G41: 5.75 | H41: 5.1 | I41: 3.85 | J41: 5.45 | K41: 4.5 | L41: 5.75 | M41: 5.25 | N41: =SUM(G41:M41) -> 35.65 | O41: =(N41/8.16)^4.5 -> 761.48647 | P41: 8 | Q41: 10 | R41: 9 | S41: 9 | T41: 9 | U41: 9 | V41: 9 | W41: =IF(G41>P41,"Y",IF(H41>Q41,"Y",IF(I41>R41,"Y",IF(J41>S41,"Y",IF(K41>T41,"Y",IF(L41>U41,"Y",IF(M41>V41,"Y","N"))))))) -> N | X41: =IF(W41="Y",MAX((G41-P41),(H41-Q41),(I41-R41),(J41-S41),(K41-T41),(L41-U41),(M41-V41))/10,0) -> 0 | Y41: =IF(X41<5%,"0-4.9%",IF(X41<25%,"5-25%",IF(X41<50%,"25-50%","Over 50%"))) -> 0-4.9% | Z41: Construction Material
A42: 8 | B42: 0.49305556 | C42: KCN 135 Q | D42: =IF(COUNT(G42:M42)>3,10,IF(COUNT(G42:M42)>2,9,7)) -> 10 | E42: 6 | F42: 1*22-222 | G42: 4.9 | H42: 6.6 | I42: 6.75 | J42: 8.3 | K42: 8.25 | L42: 8.05 | N42: =SUM(G42:M42) -> 42.85 | O42: =(N42/8.16)^4.5 -> 1742.5009 | P42: 8 | Q42: 10 | R42: 9 | S42: 9 | T42: 9 | U42: 9 | V42: 9 | W42: =IF(G42>P42,"Y",IF(H42>Q42,"Y",IF(I42>R42,"Y",IF(J42>S42,"Y",IF(K42>T42,"Y",IF(L42>U42,"Y",IF(M42>V42,"Y","N"))))))) -> N | X42: =IF(W42="Y",MAX((G42-P42),(H42-Q42),(I42-R42),(J42-S42),(K42-T42),(L42-U42),(M42-V42))/10,0) -> 0 | Y42: =IF(X42<5%,"0-4.9%",IF(X42<25%,"5-25%",IF(X42<50%,"25-50%","Over 50%"))) -> 0-4.9% | Z42: Metal/machinery
