Workbook

Sheet 29.07 ClockTower-Nsambya
B1: Consultancy services for Preparation of Expressway Development Master Plan (EDMP) for Uganda
B2: MANUAL CLASSIFIED COUNT (MCC)
B3: ROAD NAME: | C3: MCC - C1 - STN50 - NSAMBYA ROAD
C5: Date | D5: 29.07.19 | F5: Location | G5: Gapco | J5: Surveyor | K5: Adong Agnes
C6: Dir. From | D6: Clock Tower | F6: Dir. To | G6: Nsambya | J6: Supervisor | K6: Felix
B8: Time / Veh Type | R8: SUMMARY TRAFFIC VOLUMES
C9: 1. Car | D9: 2. Station Wagon | E9: 3. Pickups | F9: 4. Minibus, matatu | G9: 5. Medium bus | H9: 6. Large Bus | I9: 7. Light Truck | J9: 8. Medium Truck | K9: 9. Heavy truck | L9: 10. Truck Trailer | M9: 11. Motor cycles | N9: 12. Tractors | O9: Total Excl M/Cycles | P9: Total All | R9: Time | S9: 1. Car | T9: 2. Station Wagon | U9: 3. Pickups | V9: 4. Minibus, matatu | W9: 5. Medium bus | X9: 6. Large Bus | Y9: 7. Light Truck | Z9: 8. Medium Truck | AA9: 9. Heavy truck | AB9: 10. Truck Trailer | AC9: 11. Motorcycles | AD9: 12. Tractors, Graders | AE9: Total Excl M/ Cycles | AF9: Total All
B10: 07.00 - 07.15 | C10: 60 | D10: 11 | E10: 5 | F10: 55 | G10: 7 | H10: 0 | I10: 2 | J10: 2 | K10: 0 | L10: 3 | M10: 633 | N10: 0 | O10: =SUM(C10:L10,N10) -> 145 | P10: =SUM(C10:N10) -> 778 | R10: 0700-0800 | S10: =SUM(C10:C13) -> 209 | T10: =SUM(D10:D13) -> 34 | U10: =SUM(E10:E13) -> 21 | V10: =SUM(F10:F13) -> 248 | W10: =SUM(G10:G13) -> 11 | X10: =SUM(H10:H13) -> 0 | Y10: =SUM(I10:I13) -> 10 | Z10: =SUM(J10:J13) -> 7 | ... AF10: =SUM(P10:P13) -> 3446
B11: 07.15 - 07.30 | C11: 45 | D11: 2 | E11: 2 | F11: 73 | G11: 1 | H11: 0 | I11: 3 | J11: 1 | K11: 4 | L11: 2 | M11: 656 | N11: 1 | O11: =SUM(C11:L11,N11) -> 134 | P11: =SUM(C11:N11) -> 790 | R11: 0800-0900 | S11: =SUM(C14:C17) -> 161 | T11: =SUM(D14:D17) -> 38 | U11: =SUM(E14:E17) -> 7 | V11: =SUM(F14:F17) -> 195 | W11: =SUM(G14:G17) -> 11 | X11: =SUM(H14:H17) -> 1 | Y11: =SUM(I14:I17) -> 17 | Z11: =SUM(J14:J17) -> 18 | ... AF11: =SUM(P14:P17) -> 2475
B12: 07.30 - 07.45 | C12: 74 | D12: 13 | E12: 7 | F12: 62 | G12: 2 | H12: 0 | I12: 2 | J12: 2 | K12: 5 | L12: 1 | M12: 702 | N12: 1 | O12: =SUM(C12:L12,N12) -> 169 | P12: =SUM(C12:N12) -> 871 | R12: 0900-1000 | S12: =SUM(C18:C21) -> 105 | T12: =SUM(D18:D21) -> 20 | U12: =SUM(E18:E21) -> 14 | V12: =SUM(F18:F21) -> 213 | W12: =SUM(G18:G21) -> 8 | X12: =SUM(H18:H21) -> 0 | Y12: =SUM(I18:I21) -> 31 | Z12: =SUM(J18:J21) -> 23 | ... AF12: =SUM(P18:P21) -> 1549
B13: 07.45 - 08.00 | C13: 30 | D13: 8 | E13: 7 | F13: 58 | G13: 1 | H13: 0 | I13: 3 | J13: 2 | K13: 2 | L13: 0 | M13: 896 | N13: 0 | O13: =SUM(C13:L13,N13) -> 111 | P13: =SUM(C13:N13) -> 1007 | R13: 1000-1100 | S13: =SUM(C22:C25) -> 145 | T13: =SUM(D22:D25) -> 18 | U13: =SUM(E22:E25) -> 10 | V13: =SUM(F22:F25) -> 155 | W13: =SUM(G22:G25) -> 6 | X13: =SUM(H22:H25) -> 0 | Y13: =SUM(I22:I25) -> 11 | Z13: =SUM(J22:J25) -> 20 | ... AF13: =SUM(P22:P25) -> 1206
B14: 08.00 - 08.15 | C14: 36 | D14: 6 | E14: 2 | F14: 52 | G14: 4 | H14: 0 | I14: 6 | J14: 5 | K14: 4 | L14: 4 | M14: 842 | N14: 1 | O14: =SUM(C14:L14,N14) -> 120 | P14: =SUM(C14:N14) -> 962 | R14: 1100-1200 | S14: =SUM(C26:C29) -> 150 | T14: =SUM(D26:D29) -> 60 | U14: =SUM(E26:E29) -> 25 | V14: =SUM(F26:F29) -> 144 | W14: =SUM(G26:G29) -> 3 | X14: =SUM(H26:H29) -> 0 | Y14: =SUM(I26:I29) -> 28 | Z14: =SUM(J26:J29) -> 29 | ... AF14: =SUM(P26:P29) -> 1740
B15: 08.15 - 08.30 | C15: 27 | D15: 10 | E15: 1 | F15: 42 | G15: 2 | H15: 0 | I15: 3 | J15: 5 | K15: 1 | L15: 6 | M15: 569 | N15: 0 | O15: =SUM(C15:L15,N15) -> 97 | P15: =SUM(C15:N15) -> 666 | R15: 1200-1300 | S15: =SUM(C30:C33) -> 292 | T15: =SUM(D30:D33) -> 166 | U15: =SUM(E30:E33) -> 104 | V15: =SUM(F30:F33) -> 175 | W15: =SUM(G30:G33) -> 2 | X15: =SUM(H30:H33) -> 1 | Y15: =SUM(I30:I33) -> 35 | Z15: =SUM(J30:J33) -> 13 | ... AF15: =SUM(P30:P33) -> 2596
B16: 08.30 - 08.45 | C16: 72 | D16: 16 | E16: 4 | F16: 57 | G16: 3 | H16: 0 | I16: 3 | J16: 4 | K16: 2 | L16: 1 | M16: 300 | N16: 0 | O16: =SUM(C16:L16,N16) -> 162 | P16: =SUM(C16:N16) -> 462 | R16: 1300-1400 | S16: =SUM(C34:C37) -> 375 | T16: =SUM(D34:D37) -> 287 | U16: =SUM(E34:E37) -> 113 | V16: =SUM(F34:F37) -> 134 | W16: =SUM(G34:G37) -> 3 | X16: =SUM(H34:H37) -> 3 | Y16: =SUM(I34:I37) -> 32 | Z16: =SUM(J34:J37) -> 22 | ... AF16: =SUM(P34:P37) -> 2904
B17: 08.45 - 9.00 | C17: 26 | D17: 6 | E17: 0 | F17: 44 | G17: 2 | H17: 1 | I17: 5 | J17: 4 | K17: 2 | L17: 2 | M17: 293 | N17: 0 | O17: =SUM(C17:L17,N17) -> 92 | P17: =SUM(C17:N17) -> 385 | R17: 1400-1500 | S17: =SUM(C38:C41) -> 494 | T17: =SUM(D38:D41) -> 146 | U17: =SUM(E38:E41) -> 78 | V17: =SUM(F38:F41) -> 158 | W17: =SUM(G38:G41) -> 1 | X17: =SUM(H38:H41) -> 0 | Y17: =SUM(I38:I41) -> 46 | Z17: =SUM(J38:J41) -> 21 | ... AF17: =SUM(P38:P41) -> 2928
B18: 09.00 - 09.15 | C18: 35 | D18: 7 | E18: 5 | F18: 42 | G18: 2 | H18: 0 | I18: 7 | J18: 4 | K18: 2 | L18: 2 | M18: 199 | N18: 0 | O18: =SUM(C18:L18,N18) -> 106 | P18: =SUM(C18:N18) -> 305 | R18: 1500-1600 | S18: =SUM(C42:C45) -> 339 | T18: =SUM(D42:D45) -> 101 | U18: =SUM(E42:E45) -> 49 | V18: =SUM(F42:F45) -> 142 | W18: =SUM(G42:G45) -> 2 | X18: =SUM(H42:H45) -> 1 | Y18: =SUM(I42:I45) -> 20 | Z18: =SUM(J42:J45) -> 29 | ... AF18: =SUM(P42:P45) -> 2233
B19: 09.15 - 09.30 | C19: 17 | D19: 1 | E19: 2 | F19: 80 | G19: 5 | H19: 0 | I19: 2 | J19: 3 | K19: 5 | L19: 2 | M19: 158 | N19: 0 | O19: =SUM(C19:L19,N19) -> 117 | P19: =SUM(C19:N19) -> 275 | R19: 1600-1700 | S19: =SUM(C46:C49) -> 269 | T19: =SUM(D46:D49) -> 181 | U19: =SUM(E46:E49) -> 55 | V19: =SUM(F46:F49) -> 103 | W19: =SUM(G46:G49) -> 4 | X19: =SUM(H46:H49) -> 4 | Y19: =SUM(I46:I49) -> 38 | Z19: =SUM(J46:J49) -> 19 | ... AF19: =SUM(P46:P49) -> 2245
B20: 09.30 - 09.45 | C20: 38 | D20: 8 | E20: 4 | F20: 62 | G20: 1 | H20: 0 | I20: 20 | J20: 8 | K20: 3 | L20: 4 | M20: 408 | N20: 0 | O20: =SUM(C20:L20,N20) -> 148 | P20: =SUM(C20:N20) -> 556 | R20: 1700-1800 | S20: =SUM(C50:C53) -> 449 | T20: =SUM(D50:D53) -> 210 | U20: =SUM(E50:E53) -> 41 | V20: =SUM(F50:F53) -> 165 | W20: =SUM(G50:G53) -> 4 | X20: =SUM(H50:H53) -> 0 | Y20: =SUM(I50:I53) -> 27 | Z20: =SUM(J50:J53) -> 13 | ... AF20: =SUM(P50:P53) -> 2515
B21: 09.45 - 10.00 | C21: 15 | D21: 4 | E21: 3 | F21: 29 | G21: 0 | H21: 0 | I21: 2 | J21: 8 | K21: 1 | L21: 0 | M21: 351 | N21: 0 | O21: =SUM(C21:L21,N21) -> 62 | P21: =SUM(C21:N21) -> 413 | R21: 1800-1900 | S21: =SUM(C54:C57) -> 262 | T21: =SUM(D54:D57) -> 67 | U21: =SUM(E54:E57) -> 41 | V21: =SUM(F54:F57) -> 124 | W21: =SUM(G54:G57) -> 3 | X21: =SUM(H54:H57) -> 0 | Y21: =SUM(I54:I57) -> 32 | Z21: =SUM(J54:J57) -> 22 | ... AF21: =SUM(P54:P57) -> 2574
B22: 10.00 - 10.15 | C22: 21 | D22: 5 | E22: 3 | F22: 19 | G22: 0 | H22: 0 | I22: 0 | J22: 7 | K22: 2 | L22: 1 | M22: 289 | N22: 0 | O22: =SUM(C22:L22,N22) -> 58 | P22: =SUM(C22:N22) -> 347 | R22: AM Peak Hr | S22: =MAX(S10:S12) -> 209 | T22: =MAX(T10:T12) -> 38 | U22: =MAX(U10:U12) -> 21 | V22: =MAX(V10:V12) -> 248 | W22: =MAX(W10:W12) -> 11 | X22: =MAX(X10:X12) -> 1 | Y22: =MAX(Y10:Y12) -> 31 | Z22: =MAX(Z10:Z12) -> 23 | ... AF22: =MAX(AF10:AF12) -> 3446
B23: 10.15 - 10.30 | C23: 37 | D23: 0 | E23: 3 | F23: 41 | G23: 1 | H23: 0 | I23: 6 | J23: 6 | K23: 4 | L23: 4 | M23: 192 | N23: 0 | O23: =SUM(C23:L23,N23) -> 102 | P23: =SUM(C23:N23) -> 294 | R23: IP Peak Hr | S23: =MAX(S13:S18) -> 494 | T23: =MAX(T13:T18) -> 287 | U23: =MAX(U13:U18) -> 113 | V23: =MAX(V13:V18) -> 175 | W23: =MAX(W13:W18) -> 6 | X23: =MAX(X13:X18) -> 3 | Y23: =MAX(Y13:Y18) -> 46 | Z23: =MAX(Z13:Z18) -> 29 | ... AF23: =MAX(AF13:AF18) -> 2928
B24: 10.30 - 10.45 | C24: 52 | D24: 3 | E24: 4 | F24: 73 | G24: 3 | H24: 0 | I24: 4 | J24: 4 | K24: 2 | L24: 3 | M24: 179 | N24: 0 | O24: =SUM(C24:L24,N24) -> 148 | P24: =SUM(C24:N24) -> 327 | R24: PM Peak Hr | S24: =MAX(S19:S21) -> 449 | T24: =MAX(T19:T21) -> 210 | U24: =MAX(U19:U21) -> 55 | V24: =MAX(V19:V21) -> 165 | W24: =MAX(W19:W21) -> 4 | X24: =MAX(X19:X21) -> 4 | Y24: =MAX(Y19:Y21) -> 38 | Z24: =MAX(Z19:Z21) -> 22 | ... AF24: =MAX(AF19:AF21) -> 2574
B25: 10.45 - 11.00 | C25: 35 | D25: 10 | E25: 0 | F25: 22 | G25: 2 | H25: 0 | I25: 1 | J25: 3 | K25: 5 | L25: 4 | M25: 156 | N25: 0 | O25: =SUM(C25:L25,N25) -> 82 | P25: =SUM(C25:N25) -> 238 | R25: AM Period | S25: =SUM(S10:S12) -> 475 | T25: =SUM(T10:T12) -> 92 | U25: =SUM(U10:U12) -> 42 | V25: =SUM(V10:V12) -> 656 | W25: =SUM(W10:W12) -> 30 | X25: =SUM(X10:X12) -> 1 | Y25: =SUM(Y10:Y12) -> 58 | Z25: =SUM(Z10:Z12) -> 48 | ... AF25: =SUM(AF10:AF12) -> 7470
B26: 11.00 - 11.15 | C26: 31 | D26: 10 | E26: 3 | F26: 52 | G26: 1 | H26: 0 | I26: 7 | J26: 4 | K26: 1 | L26: 2 | M26: 250 | N26: 0 | O26: =SUM(C26:L26,N26) -> 111 | P26: =SUM(C26:N26) -> 361 | R26: IP Period | S26: =SUM(S13:S18) -> 1795 | T26: =SUM(T13:T18) -> 778 | U26: =SUM(U13:U18) -> 379 | V26: =SUM(V13:V18) -> 908 | W26: =SUM(W13:W18) -> 17 | X26: =SUM(X13:X18) -> 5 | Y26: =SUM(Y13:Y18) -> 172 | Z26: =SUM(Z13:Z18) -> 134 | ... AF26: =SUM(AF13:AF18) -> 13607
B27: 11.15 - 11.30 | C27: 45 | D27: 15 | E27: 6 | F27: 39 | G27: 0 | H27: 0 | I27: 8 | J27: 9 | K27: 6 | L27: 2 | M27: 250 | N27: 0 | O27: =SUM(C27:L27,N27) -> 130 | P27: =SUM(C27:N27) -> 380 | R27: PM Period | S27: =SUM(S19:S21) -> 980 | T27: =SUM(T19:T21) -> 458 | U27: =SUM(U19:U21) -> 137 | V27: =SUM(V19:V21) -> 392 | W27: =SUM(W19:W21) -> 11 | X27: =SUM(X19:X21) -> 4 | Y27: =SUM(Y19:Y21) -> 97 | Z27: =SUM(Z19:Z21) -> 54 | ... AF27: =SUM(AF19:AF21) -> 7334
B28: 11.30 - 11.45 | C28: 22 | D28: 20 | E28: 6 | F28: 30 | G28: 0 | H28: 0 | I28: 5 | J28: 8 | K28: 1 | L28: 3 | M28: 350 | N28: 0 | O28: =SUM(C28:L28,N28) -> 95 | P28: =SUM(C28:N28) -> 445 | R28: 12 Hours | S28: =SUM(S10:S21) -> 3250 | T28: =SUM(T10:T21) -> 1328 | U28: =SUM(U10:U21) -> 558 | V28: =SUM(V10:V21) -> 1956 | W28: =SUM(W10:W21) -> 58 | X28: =SUM(X10:X21) -> 10 | Y28: =SUM(Y10:Y21) -> 327 | Z28: =SUM(Z10:Z21) -> 236 | ... AF28: =SUM(AF10:AF21) -> 28411
B29: 11.45 - 12.00 | C29: 52 | D29: 15 | E29: 10 | F29: 23 | G29: 2 | H29: 0 | I29: 8 | J29: 8 | K29: 1 | L29: 5 | M29: 430 | N29: 0 | O29: =SUM(C29:L29,N29) -> 124 | P29: =SUM(C29:N29) -> 554
B30: 12.00 - 12.15 | C30: 65 | D30: 45 | E30: 16 | F30: 52 | G30: 2 | H30: 0 | I30: 15 | J30: 3 | K30: 5 | L30: 2 | M30: 245 | N30: 0 | O30: =SUM(C30:L30,N30) -> 205 | P30: =SUM(C30:N30) -> 450
B31: 12.15 - 12.30 | C31: 49 | D31: 51 | E31: 22 | F31: 55 | G31: 0 | H31: 1 | I31: 10 | J31: 1 | K31: 4 | L31: 2 | M31: 665 | N31: 1 | O31: =SUM(C31:L31,N31) -> 196 | P31: =SUM(C31:N31) -> 861
B32: 12.30 - 12.45 | C32: 75 | D32: 46 | E32: 38 | F32: 28 | G32: 0 | H32: 0 | I32: 2 | J32: 2 | K32: 1 | L32: 1 | M32: 425 | N32: 0 | O32: =SUM(C32:L32,N32) -> 193 | P32: =SUM(C32:N32) -> 618
B33: 12.45 - 13.00 | C33: 103 | D33: 24 | E33: 28 | F33: 40 | G33: 0 | H33: 0 | I33: 8 | J33: 7 | K33: 5 | L33: 5 | M33: 447 | N33: 0 | O33: =SUM(C33:L33,N33) -> 220 | P33: =SUM(C33:N33) -> 667
B34: 13.00 - 13.15 | C34: 93 | D34: 57 | E34: 30 | F34: 37 | G34: 1 | H34: 1 | I34: 8 | J34: 7 | K34: 7 | L34: 5 | M34: 595 | N34: 0 | O34: =SUM(C34:L34,N34) -> 246 | P34: =SUM(C34:N34) -> 841
B35: 13.15 - 13.30 | C35: 150 | D35: 100 | E35: 38 | F35: 43 | G35: 0 | H35: 0 | I35: 3 | J35: 4 | K35: 2 | L35: 3 | M35: 382 | N35: 0 | O35: =SUM(C35:L35,N35) -> 343 | P35: =SUM(C35:N35) -> 725
B36: 13.30 - 13.45 | C36: 85 | D36: 95 | E36: 20 | F36: 25 | G36: 1 | H36: 2 | I36: 10 | J36: 3 | K36: 1 | L36: 7 | M36: 402 | N36: 0 | O36: =SUM(C36:L36,N36) -> 249 | P36: =SUM(C36:N36) -> 651
B37: 13.45 - 14.00 | C37: 47 | D37: 35 | E37: 25 | F37: 29 | G37: 1 | H37: 0 | I37: 11 | J37: 8 | K37: 6 | L37: 6 | M37: 519 | N37: 0 | O37: =SUM(C37:L37,N37) -> 168 | P37: =SUM(C37:N37) -> 687
B38: 14.00 - 14.15 | C38: 120 | D38: 55 | E38: 27 | F38: 38 | G38: 1 | H38: 0 | I38: 7 | J38: 4 | K38: 3 | L38: 4 | M38: 612 | N38: 0 | O38: =SUM(C38:L38,N38) -> 259 | P38: =SUM(C38:N38) -> 871
B39: 14.15 - 14.30 | C39: 183 | D39: 45 | E39: 31 | F39: 41 | G39: 0 | H39: 0 | I39: 21 | J39: 6 | K39: 3 | L39: 5 | M39: 481 | N39: 0 | O39: =SUM(C39:L39,N39) -> 335 | P39: =SUM(C39:N39) -> 816
B40: 14.30 - 14.45 | C40: 85 | D40: 30 | E40: 11 | F40: 43 | G40: 0 | H40: 0 | I40: 13 | J40: 7 | K40: 2 | L40: 4 | M40: 547 | N40: 0 | O40: =SUM(C40:L40,N40) -> 195 | P40: =SUM(C40:N40) -> 742
... B57: 18.45 - 19.00 | C57: 38 | D57: 16 | E57: 8 | F57: 52 | G57: 0 | H57: 0 | I57: 7 | J57: 6 | K57: 3 | L57: 0 | M57: 482 | N57: 0 | O57: =SUM(C57:L57,N57) -> 130 | P57: =SUM(C57:N57) -> 612
B58: Totals | C58: =SUM(C10:C57) -> 3250 | D58: =SUM(D10:D57) -> 1328 | E58: =SUM(E10:E57) -> 558 | F58: =SUM(F10:F57) -> 1956 | G58: =SUM(G10:G57) -> 58 | H58: =SUM(H10:H57) -> 10 | I58: =SUM(I10:I57) -> 327 | J58: =SUM(J10:J57) -> 236 | ... P58: =SUM(P10:P57) -> 28411
...

Sheet 29.07 Nsambya-ClockTower
B1: Consultancy services for Preparation of Expressway Development Master Plan (EDMP) for Uganda
B2: MANUAL CLASSIFIED COUNT (MCC)
B3: ROAD NAME: | C3: ='29.07 ClockTower-Nsambya'!C3:G3 -> MCC - C1 - STN50 - NSAMBYA ROAD
C5: Date | D5: ='29.07 ClockTower-Nsambya'!D5 -> 29.07.19 | F5: Location | G5: ='29.07 ClockTower-Nsambya'!G5:H5 -> Gapco | J5: Surveyor | K5: Kizito Godfrey
C6: Dir. From | D6: Nsambya | F6: Dir. To | G6: ClockTower | J6: Supervisor | K6: ='29.07 ClockTower-Nsambya'!K6:L6 -> Felix
B8: Time / Veh Type | R8: SUMMARY TRAFFIC VOLUMES
C9: 1. Car | D9: 2. Station Wagon | E9: 3. Pickups | F9: 4. Minibus, matatu | G9: 5. Medium bus | H9: 6. Large Bus | I9: 7. Light Truck | J9: 8. Medium Truck | K9: 9. Heavy truck | L9: 10. Truck Trailer | M9: 11. Motor cycles | N9: 12. Tractors | O9: Total Excl M/Cycles | P9: Total All | R9: Time | S9: 1. Car | T9: 2. Station Wagon | U9: 3. Pickups | V9: 4. Minibus, matatu | W9: 5. Medium bus | X9: 6. Large Bus | Y9: 7. Light Truck | Z9: 8. Medium Truck | AA9: 9. Heavy truck | AB9: 10. Truck Trailer | AC9: 11. Motorcycles | AD9: 12. Tractors, Graders | AE9: Total Excl M/ Cycles | AF9: Total All
B10: 07.00 - 07.15 | C10: 98 | D10: 10 | E10: 14 | F10: 195 | G10: 1 | H10: 0 | I10: 4 | J10: 1 | K10: 0 | L10: 1 | M10: 260 | N10: 0 | O10: =SUM(C10:L10,N10) -> 324 | P10: =SUM(C10:N10) -> 584 | R10: 0700-0800 | S10: =SUM(C10:C13) -> 321 | T10: =SUM(D10:D13) -> 43 | U10: =SUM(E10:E13) -> 38 | V10: =SUM(F10:F13) -> 886 | W10: =SUM(G10:G13) -> 2 | X10: =SUM(H10:H13) -> 0 | Y10: =SUM(I10:I13) -> 16 | Z10: =SUM(J10:J13) -> 2 | ... AF10: =SUM(P10:P13) -> 2571
B11: 07.15 - 07.30 | C11: 75 | D11: 19 | E11: 8 | F11: 196 | G11: 0 | H11: 0 | I11: 4 | J11: 0 | K11: 0 | L11: 1 | M11: 305 | N11: 0 | O11: =SUM(C11:L11,N11) -> 303 | P11: =SUM(C11:N11) -> 608 | R11: 0800-0900 | S11: =SUM(C14:C17) -> 380 | T11: =SUM(D14:D17) -> 26 | U11: =SUM(E14:E17) -> 32 | V11: =SUM(F14:F17) -> 880 | W11: =SUM(G14:G17) -> 12 | X11: =SUM(H14:H17) -> 4 | Y11: =SUM(I14:I17) -> 17 | Z11: =SUM(J14:J17) -> 6 | ... AF11: =SUM(P14:P17) -> 3083
B12: 07.30 - 07.45 | C12: 107 | D12: 13 | E12: 8 | F12: 250 | G12: 1 | H12: 0 | I12: 6 | J12: 1 | K12: 0 | L12: 0 | M12: 335 | N12: 0 | O12: =SUM(C12:L12,N12) -> 386 | P12: =SUM(C12:N12) -> 721 | R12: 0900-1000 | S12: =SUM(C18:C21) -> 227 | T12: =SUM(D18:D21) -> 43 | U12: =SUM(E18:E21) -> 40 | V12: =SUM(F18:F21) -> 765 | W12: =SUM(G18:G21) -> 3 | X12: =SUM(H18:H21) -> 1 | Y12: =SUM(I18:I21) -> 25 | Z12: =SUM(J18:J21) -> 11 | ... AF12: =SUM(P18:P21) -> 2394
B13: 07.45 - 08.00 | C13: 41 | D13: 1 | E13: 8 | F13: 245 | G13: 0 | H13: 0 | I13: 2 | J13: 0 | K13: 0 | L13: 1 | M13: 360 | N13: 0 | O13: =SUM(C13:L13,N13) -> 298 | P13: =SUM(C13:N13) -> 658 | R13: 1000-1100 | S13: =SUM(C22:C25) -> 266 | T13: =SUM(D22:D25) -> 37 | U13: =SUM(E22:E25) -> 41 | V13: =SUM(F22:F25) -> 945 | W13: =SUM(G22:G25) -> 3 | X13: =SUM(H22:H25) -> 1 | Y13: =SUM(I22:I25) -> 24 | Z13: =SUM(J22:J25) -> 15 | ... AF13: =SUM(P22:P25) -> 2599
B14: 08.00 - 08.15 | C14: 92 | D14: 6 | E14: 12 | F14: 250 | G14: 2 | H14: 1 | I14: 4 | J14: 3 | K14: 0 | L14: 1 | M14: 390 | N14: 0 | O14: =SUM(C14:L14,N14) -> 371 | P14: =SUM(C14:N14) -> 761 | R14: 1100-1200 | S14: =SUM(C26:C29) -> 299 | T14: =SUM(D26:D29) -> 55 | U14: =SUM(E26:E29) -> 30 | V14: =SUM(F26:F29) -> 745 | W14: =SUM(G26:G29) -> 3 | X14: =SUM(H26:H29) -> 1 | Y14: =SUM(I26:I29) -> 39 | Z14: =SUM(J26:J29) -> 25 | ... AF14: =SUM(P26:P29) -> 2592
B15: 08.15 - 08.30 | C15: 104 | D15: 9 | E15: 8 | F15: 220 | G15: 3 | H15: 0 | I15: 2 | J15: 1 | K15: 0 | L15: 3 | M15: 445 | N15: 0 | O15: =SUM(C15:L15,N15) -> 350 | P15: =SUM(C15:N15) -> 795 | R15: 1200-1300 | S15: =SUM(C30:C33) -> 279 | T15: =SUM(D30:D33) -> 80 | U15: =SUM(E30:E33) -> 63 | V15: =SUM(F30:F33) -> 710 | W15: =SUM(G30:G33) -> 5 | X15: =SUM(H30:H33) -> 2 | Y15: =SUM(I30:I33) -> 28 | Z15: =SUM(J30:J33) -> 22 | ... AF15: =SUM(P30:P33) -> 3033
B16: 08.30 - 08.45 | C16: 75 | D16: 6 | E16: 4 | F16: 200 | G16: 5 | H16: 1 | I16: 6 | J16: 2 | K16: 1 | L16: 2 | M16: 375 | N16: 0 | O16: =SUM(C16:L16,N16) -> 302 | P16: =SUM(C16:N16) -> 677 | R16: 1300-1400 | S16: =SUM(C34:C37) -> 260 | T16: =SUM(D34:D37) -> 47 | U16: =SUM(E34:E37) -> 37 | V16: =SUM(F34:F37) -> 710 | W16: =SUM(G34:G37) -> 5 | X16: =SUM(H34:H37) -> 1 | Y16: =SUM(I34:I37) -> 60 | Z16: =SUM(J34:J37) -> 23 | ... AF16: =SUM(P34:P37) -> 2647
B17: 08.45 - 9.00 | C17: 109 | D17: 5 | E17: 8 | F17: 210 | G17: 2 | H17: 2 | I17: 5 | J17: 0 | K17: 2 | L17: 2 | M17: 505 | N17: 0 | O17: =SUM(C17:L17,N17) -> 345 | P17: =SUM(C17:N17) -> 850 | R17: 1400-1500 | S17: =SUM(C38:C41) -> 288 | T17: =SUM(D38:D41) -> 110 | U17: =SUM(E38:E41) -> 42 | V17: =SUM(F38:F41) -> 775 | W17: =SUM(G38:G41) -> 6 | X17: =SUM(H38:H41) -> 0 | Y17: =SUM(I38:I41) -> 32 | Z17: =SUM(J38:J41) -> 17 | ... AF17: =SUM(P38:P41) -> 2750
B18: 09.00 - 09.15 | C18: 47 | D18: 14 | E18: 7 | F18: 190 | G18: 0 | H18: 1 | I18: 6 | J18: 3 | K18: 4 | L18: 1 | M18: 360 | N18: 0 | O18: =SUM(C18:L18,N18) -> 273 | P18: =SUM(C18:N18) -> 633 | R18: 1500-1600 | S18: =SUM(C42:C45) -> 242 | T18: =SUM(D42:D45) -> 47 | U18: =SUM(E42:E45) -> 49 | V18: =SUM(F42:F45) -> 635 | W18: =SUM(G42:G45) -> 4 | X18: =SUM(H42:H45) -> 0 | Y18: =SUM(I42:I45) -> 102 | Z18: =SUM(J42:J45) -> 49 | ... AF18: =SUM(P42:P45) -> 2924
B19: 09.15 - 09.30 | C19: 100 | D19: 13 | E19: 13 | F19: 220 | G19: 0 | H19: 0 | I19: 2 | J19: 1 | K19: 2 | L19: 1 | M19: 315 | N19: 0 | O19: =SUM(C19:L19,N19) -> 352 | P19: =SUM(C19:N19) -> 667 | R19: 1600-1700 | S19: =SUM(C46:C49) -> 209 | T19: =SUM(D46:D49) -> 37 | U19: =SUM(E46:E49) -> 52 | V19: =SUM(F46:F49) -> 690 | W19: =SUM(G46:G49) -> 7 | X19: =SUM(H46:H49) -> 0 | Y19: =SUM(I46:I49) -> 33 | Z19: =SUM(J46:J49) -> 29 | ... AF19: =SUM(P46:P49) -> 2834
B20: 09.30 - 09.45 | C20: 45 | D20: 9 | E20: 10 | F20: 185 | G20: 1 | H20: 0 | I20: 11 | J20: 3 | K20: 1 | L20: 3 | M20: 280 | N20: 0 | O20: =SUM(C20:L20,N20) -> 268 | P20: =SUM(C20:N20) -> 548 | R20: 1700-1800 | S20: =SUM(C50:C53) -> 241 | T20: =SUM(D50:D53) -> 44 | U20: =SUM(E50:E53) -> 32 | V20: =SUM(F50:F53) -> 710 | W20: =SUM(G50:G53) -> 6 | X20: =SUM(H50:H53) -> 0 | Y20: =SUM(I50:I53) -> 29 | Z20: =SUM(J50:J53) -> 22 | ... AF20: =SUM(P50:P53) -> 2775
B21: 09.45 - 10.00 | C21: 35 | D21: 7 | E21: 10 | F21: 170 | G21: 2 | H21: 0 | I21: 6 | J21: 4 | K21: 1 | L21: 6 | M21: 305 | N21: 0 | O21: =SUM(C21:L21,N21) -> 241 | P21: =SUM(C21:N21) -> 546 | R21: 1800-1900 | S21: =SUM(C54:C57) -> 269 | T21: =SUM(D54:D57) -> 19 | U21: =SUM(E54:E57) -> 32 | V21: =SUM(F54:F57) -> 580 | W21: =SUM(G54:G57) -> 36 | X21: =SUM(H54:H57) -> 2 | Y21: =SUM(I54:I57) -> 46 | Z21: =SUM(J54:J57) -> 76 | ... AF21: =SUM(P54:P57) -> 2722
B22: 10.00 - 10.15 | C22: 44 | D22: 12 | E22: 9 | F22: 200 | G22: 3 | H22: 0 | I22: 6 | J22: 3 | K22: 2 | L22: 3 | M22: 300 | N22: 0 | O22: =SUM(C22:L22,N22) -> 282 | P22: =SUM(C22:N22) -> 582 | R22: AM Peak Hr | S22: =MAX(S10:S12) -> 380 | T22: =MAX(T10:T12) -> 43 | U22: =MAX(U10:U12) -> 40 | V22: =MAX(V10:V12) -> 886 | W22: =MAX(W10:W12) -> 12 | X22: =MAX(X10:X12) -> 4 | Y22: =MAX(Y10:Y12) -> 25 | Z22: =MAX(Z10:Z12) -> 11 | ... AF22: =MAX(AF10:AF12) -> 3083
B23: 10.15 - 10.30 | C23: 72 | D23: 7 | E23: 12 | F23: 190 | G23: 0 | H23: 0 | I23: 12 | J23: 7 | K23: 2 | L23: 6 | M23: 310 | N23: 0 | O23: =SUM(C23:L23,N23) -> 308 | P23: =SUM(C23:N23) -> 618 | R23: IP Peak Hr | S23: =MAX(S13:S18) -> 299 | T23: =MAX(T13:T18) -> 110 | U23: =MAX(U13:U18) -> 63 | V23: =MAX(V13:V18) -> 945 | W23: =MAX(W13:W18) -> 6 | X23: =MAX(X13:X18) -> 2 | Y23: =MAX(Y13:Y18) -> 102 | Z23: =MAX(Z13:Z18) -> 49 | ... AF23: =MAX(AF13:AF18) -> 3033
B24: 10.30 - 10.45 | C24: 65 | D24: 8 | E24: 10 | F24: 215 | G24: 0 | H24: 1 | I24: 4 | J24: 4 | K24: 0 | L24: 2 | M24: 330 | N24: 0 | O24: =SUM(C24:L24,N24) -> 309 | P24: =SUM(C24:N24) -> 639 | R24: PM Peak Hr | S24: =MAX(S19:S21) -> 269 | T24: =MAX(T19:T21) -> 44 | U24: =MAX(U19:U21) -> 52 | V24: =MAX(V19:V21) -> 710 | W24: =MAX(W19:W21) -> 36 | X24: =MAX(X19:X21) -> 2 | Y24: =MAX(Y19:Y21) -> 46 | Z24: =MAX(Z19:Z21) -> 76 | ... AF24: =MAX(AF19:AF21) -> 2834
B25: 10.45 - 11.00 | C25: 85 | D25: 10 | E25: 10 | F25: 340 | G25: 0 | H25: 0 | I25: 2 | J25: 1 | K25: 0 | L25: 2 | M25: 310 | N25: 0 | O25: =SUM(C25:L25,N25) -> 450 | P25: =SUM(C25:N25) -> 760 | R25: AM Period | S25: =SUM(S10:S12) -> 928 | T25: =SUM(T10:T12) -> 112 | U25: =SUM(U10:U12) -> 110 | V25: =SUM(V10:V12) -> 2531 | W25: =SUM(W10:W12) -> 17 | X25: =SUM(X10:X12) -> 5 | Y25: =SUM(Y10:Y12) -> 58 | Z25: =SUM(Z10:Z12) -> 19 | ... AF25: =SUM(AF10:AF12) -> 8048
B26: 11.00 - 11.15 | C26: 70 | D26: 12 | E26: 9 | F26: 200 | G26: 1 | H26: 0 | I26: 13 | J26: 5 | K26: 2 | L26: 5 | M26: 355 | N26: 0 | O26: =SUM(C26:L26,N26) -> 317 | P26: =SUM(C26:N26) -> 672 | R26: IP Period | S26: =SUM(S13:S18) -> 1634 | T26: =SUM(T13:T18) -> 376 | U26: =SUM(U13:U18) -> 262 | V26: =SUM(V13:V18) -> 4520 | W26: =SUM(W13:W18) -> 26 | X26: =SUM(X13:X18) -> 5 | Y26: =SUM(Y13:Y18) -> 285 | Z26: =SUM(Z13:Z18) -> 151 | ... AF26: =SUM(AF13:AF18) -> 16545
B27: 11.15 - 11.30 | C27: 46 | D27: 8 | E27: 6 | F27: 170 | G27: 2 | H27: 1 | I27: 15 | J27: 8 | K27: 1 | L27: 2 | M27: 335 | N27: 0 | O27: =SUM(C27:L27,N27) -> 259 | P27: =SUM(C27:N27) -> 594 | R27: PM Period | S27: =SUM(S19:S21) -> 719 | T27: =SUM(T19:T21) -> 100 | U27: =SUM(U19:U21) -> 116 | V27: =SUM(V19:V21) -> 1980 | W27: =SUM(W19:W21) -> 49 | X27: =SUM(X19:X21) -> 2 | Y27: =SUM(Y19:Y21) -> 108 | Z27: =SUM(Z19:Z21) -> 127 | ... AF27: =SUM(AF19:AF21) -> 8331
B28: 11.30 - 11.45 | C28: 58 | D28: 10 | E28: 8 | F28: 220 | G28: 0 | H28: 0 | I28: 4 | J28: 4 | K28: 1 | L28: 1 | M28: 285 | N28: 0 | O28: =SUM(C28:L28,N28) -> 306 | P28: =SUM(C28:N28) -> 591 | R28: 12 Hours | S28: =SUM(S10:S21) -> 3281 | T28: =SUM(T10:T21) -> 588 | U28: =SUM(U10:U21) -> 488 | V28: =SUM(V10:V21) -> 9031 | W28: =SUM(W10:W21) -> 92 | X28: =SUM(X10:X21) -> 12 | Y28: =SUM(Y10:Y21) -> 451 | Z28: =SUM(Z10:Z21) -> 297 | ... AF28: =SUM(AF10:AF21) -> 32924
B29: 11.45 - 12.00 | C29: 125 | D29: 25 | E29: 7 | F29: 155 | G29: 0 | H29: 0 | I29: 7 | J29: 8 | K29: 0 | L29: 2 | M29: 405 | N29: 1 | O29: =SUM(C29:L29,N29) -> 330 | P29: =SUM(C29:N29) -> 735
B30: 12.00 - 12.15 | C30: 105 | D30: 45 | E30: 30 | F30: 200 | G30: 1 | H30: 0 | I30: 7 | J30: 5 | K30: 1 | L30: 6 | M30: 395 | N30: 1 | O30: =SUM(C30:L30,N30) -> 401 | P30: =SUM(C30:N30) -> 796
B31: 12.15 - 12.30 | C31: 35 | D31: 17 | E31: 11 | F31: 170 | G31: 2 | H31: 1 | I31: 5 | J31: 3 | K31: 2 | L31: 5 | M31: 437 | N31: 2 | O31: =SUM(C31:L31,N31) -> 253 | P31: =SUM(C31:N31) -> 690
B32: 12.30 - 12.45 | C32: 70 | D32: 15 | E32: 11 | F32: 190 | G32: 2 | H32: 0 | I32: 6 | J32: 9 | K32: 5 | L32: 2 | M32: 479 | N32: 0 | O32: =SUM(C32:L32,N32) -> 310 | P32: =SUM(C32:N32) -> 789
B33: 12.45 - 13.00 | C33: 69 | D33: 3 | E33: 11 | F33: 150 | G33: 0 | H33: 1 | I33: 10 | J33: 5 | K33: 1 | L33: 2 | M33: 506 | N33: 0 | O33: =SUM(C33:L33,N33) -> 252 | P33: =SUM(C33:N33) -> 758
B34: 13.00 - 13.15 | C34: 75 | D34: 13 | E34: 8 | F34: 190 | G34: 1 | H34: 0 | I34: 15 | J34: 7 | K34: 9 | L34: 5 | M34: 445 | N34: 0 | O34: =SUM(C34:L34,N34) -> 323 | P34: =SUM(C34:N34) -> 768
B35: 13.15 - 13.30 | C35: 84 | D35: 7 | E35: 9 | F35: 165 | G35: 2 | H35: 1 | I35: 8 | J35: 7 | K35: 1 | L35: 8 | M35: 352 | N35: 0 | O35: =SUM(C35:L35,N35) -> 292 | P35: =SUM(C35:N35) -> 644
B36: 13.30 - 13.45 | C36: 55 | D36: 9 | E36: 8 | F36: 145 | G36: 1 | H36: 0 | I36: 11 | J36: 5 | K36: 3 | L36: 4 | M36: 328 | N36: 0 | O36: =SUM(C36:L36,N36) -> 241 | P36: =SUM(C36:N36) -> 569
B37: 13.45 - 14.00 | C37: 46 | D37: 18 | E37: 12 | F37: 210 | G37: 1 | H37: 0 | I37: 26 | J37: 4 | K37: 2 | L37: 3 | M37: 344 | N37: 0 | O37: =SUM(C37:L37,N37) -> 322 | P37: =SUM(C37:N37) -> 666
B38: 14.00 - 14.15 | C38: 65 | D38: 23 | E38: 10 | F38: 170 | G38: 3 | H38: 0 | I38: 6 | J38: 3 | K38: 3 | L38: 5 | M38: 360 | N38: 0 | O38: =SUM(C38:L38,N38) -> 288 | P38: =SUM(C38:N38) -> 648
B39: 14.15 - 14.30 | C39: 90 | D39: 38 | E39: 13 | F39: 165 | G39: 0 | H39: 0 | I39: 7 | J39: 2 | K39: 4 | L39: 6 | M39: 364 | N39: 0 | O39: =SUM(C39:L39,N39) -> 325 | P39: =SUM(C39:N39) -> 689
B40: 14.30 - 14.45 | C40: 60 | D40: 17 | E40: 7 | F40: 190 | G40: 1 | H40: 0 | I40: 11 | J40: 3 | K40: 4 | L40: 7 | M40: 339 | N40: 0 | O40: =SUM(C40:L40,N40) -> 300 | P40: =SUM(C40:N40) -> 639
... B57: 18.45 - 19.00 | C57: 75 | D57: 6 | E57: 8 | F57: 135 | G57: 30 | H57: 1 | I57: 16 | J57: 26 | K57: 50 | L57: 25 | M57: 409 | N57: 0 | O57: =SUM(C57:L57,N57) -> 372 | P57: =SUM(C57:N57) -> 781
B58: Totals | C58: =SUM(C10:C57) -> 3281 | D58: =SUM(D10:D57) -> 588 | E58: =SUM(E10:E57) -> 488 | F58: =SUM(F10:F57) -> 9031 | G58: =SUM(G10:G57) -> 92 | H58: =SUM(H10:H57) -> 12 | I58: =SUM(I10:I57) -> 451 | J58: =SUM(J10:J57) -> 297 | ... P58: =SUM(P10:P57) -> 32924
...

Sheet 30.07 ClockTower-Nsambya
B1: Consultancy services for Preparation of Expressway Development Master Plan (EDMP) for Uganda
B2: MANUAL CLASSIFIED COUNT (MCC)
B3: ROAD NAME: | C3: ='29.07 ClockTower-Nsambya'!C3:G3 -> MCC - C1 - STN50 - NSAMBYA ROAD
C5: Date | D5: 30.07.19 | F5: Location | G5: ='29.07 ClockTower-Nsambya'!G5:H5 -> Gapco | J5: Surveyor | K5: ='29.07 ClockTower-Nsambya'!K5:L5 -> Adong Agnes
C6: Dir. From | D6: ='29.07 ClockTower-Nsambya'!D6:E6 -> Clock Tower | F6: Dir. To | G6: ='29.07 ClockTower-Nsambya'!G6:H6 -> Nsambya | J6: Supervisor | K6: ='29.07 ClockTower-Nsambya'!K6:L6 -> Felix
B8: Time / Veh Type | R8: SUMMARY TRAFFIC VOLUMES
C9: 1. Car | D9: 2. Station Wagon | E9: 3. Pickups | F9: 4. Minibus, matatu | G9: 5. Medium bus | H9: 6. Large Bus | I9: 7. Light Truck | J9: 8. Medium Truck | K9: 9. Heavy truck | L9: 10. Truck Trailer | M9: 11. Motor cycles | N9: 12. Tractors | O9: Total Excl M/Cycles | P9: Total All | R9: Time | S9: 1. Car | T9: 2. Station Wagon | U9: 3. Pickups | V9: 4. Minibus, matatu | W9: 5. Medium bus | X9: 6. Large Bus | Y9: 7. Light Truck | Z9: 8. Medium Truck | AA9: 9. Heavy truck | AB9: 10. Truck Trailer | AC9: 11. Motorcycles | AD9: 12. Tractors, Graders | AE9: Total Excl M/ Cycles | AF9: Total All
B10: 07.00 - 07.15 | C10: 68 | D10: 13 | E10: 4 | F10: 76 | G10: 3 | H10: 1 | I10: 2 | J10: 2 | K10: 3 | L10: 2 | M10: 671 | N10: 0 | O10: =SUM(C10:L10,N10) -> 174 | P10: =SUM(C10:N10) -> 845 | R10: 0700-0800 | S10: =SUM(C10:C13) -> 229 | T10: =SUM(D10:D13) -> 45 | U10: =SUM(E10:E13) -> 23 | V10: =SUM(F10:F13) -> 250 | W10: =SUM(G10:G13) -> 29 | X10: =SUM(H10:H13) -> 5 | Y10: =SUM(I10:I13) -> 12 | Z10: =SUM(J10:J13) -> 8 | ... AF10: =SUM(P10:P13) -> 2985
B11: 07.15 - 07.30 | C11: 64 | D11: 13 | E11: 6 | F11: 44 | G11: 1 | H11: 1 | I11: 1 | J11: 1 | K11: 3 | L11: 3 | M11: 501 | N11: 0 | O11: =SUM(C11:L11,N11) -> 137 | P11: =SUM(C11:N11) -> 638 | R11: 0800-0900 | S11: =SUM(C14:C17) -> 144 | T11: =SUM(D14:D17) -> 40 | U11: =SUM(E14:E17) -> 15 | V11: =SUM(F14:F17) -> 198 | W11: =SUM(G14:G17) -> 3 | X11: =SUM(H14:H17) -> 0 | Y11: =SUM(I14:I17) -> 23 | Z11: =SUM(J14:J17) -> 17 | ... AF11: =SUM(P14:P17) -> 1837
B12: 07.30 - 07.45 | C12: 49 | D12: 6 | E12: 6 | F12: 70 | G12: 22 | H12: 3 | I12: 4 | J12: 3 | K12: 3 | L12: 1 | M12: 613 | N12: 0 | O12: =SUM(C12:L12,N12) -> 167 | P12: =SUM(C12:N12) -> 780 | R12: 0900-1000 | S12: =SUM(C18:C21) -> 112 | T12: =SUM(D18:D21) -> 27 | U12: =SUM(E18:E21) -> 23 | V12: =SUM(F18:F21) -> 159 | W12: =SUM(G18:G21) -> 6 | X12: =SUM(H18:H21) -> 1 | Y12: =SUM(I18:I21) -> 28 | Z12: =SUM(J18:J21) -> 12 | ... AF12: =SUM(P18:P21) -> 1768
B13: 07.45 - 08.00 | C13: 48 | D13: 13 | E13: 7 | F13: 60 | G13: 3 | H13: 0 | I13: 5 | J13: 2 | K13: 0 | L13: 0 | M13: 584 | N13: 0 | O13: =SUM(C13:L13,N13) -> 138 | P13: =SUM(C13:N13) -> 722 | R13: 1000-1100 | S13: =SUM(C22:C25) -> 174 | T13: =SUM(D22:D25) -> 22 | U13: =SUM(E22:E25) -> 16 | V13: =SUM(F22:F25) -> 146 | W13: =SUM(G22:G25) -> 6 | X13: =SUM(H22:H25) -> 0 | Y13: =SUM(I22:I25) -> 73 | Z13: =SUM(J22:J25) -> 14 | ... AF13: =SUM(P22:P25) -> 1371
B14: 08.00 - 08.15 | C14: 57 | D14: 12 | E14: 6 | F14: 46 | G14: 1 | H14: 0 | I14: 5 | J14: 5 | K14: 2 | L14: 1 | M14: 412 | N14: 1 | O14: =SUM(C14:L14,N14) -> 136 | P14: =SUM(C14:N14) -> 548 | R14: 1100-1200 | S14: =SUM(C26:C29) -> 196 | T14: =SUM(D26:D29) -> 28 | U14: =SUM(E26:E29) -> 22 | V14: =SUM(F26:F29) -> 151 | W14: =SUM(G26:G29) -> 2 | X14: =SUM(H26:H29) -> 1 | Y14: =SUM(I26:I29) -> 25 | Z14: =SUM(J26:J29) -> 27 | ... AF14: =SUM(P26:P29) -> 1794
B15: 08.15 - 08.30 | C15: 39 | D15: 8 | E15: 3 | F15: 60 | G15: 0 | H15: 0 | I15: 4 | J15: 4 | K15: 1 | L15: 10 | M15: 406 | N15: 0 | O15: =SUM(C15:L15,N15) -> 129 | P15: =SUM(C15:N15) -> 535 | R15: 1200-1300 | S15: =SUM(C30:C33) -> 188 | T15: =SUM(D30:D33) -> 37 | U15: =SUM(E30:E33) -> 31 | V15: =SUM(F30:F33) -> 146 | W15: =SUM(G30:G33) -> 0 | X15: =SUM(H30:H33) -> 1 | Y15: =SUM(I30:I33) -> 36 | Z15: =SUM(J30:J33) -> 25 | ... AF15: =SUM(P30:P33) -> 1405
B16: 08.30 - 08.45 | C16: 36 | D16: 12 | E16: 4 | F16: 52 | G16: 1 | H16: 0 | I16: 4 | J16: 5 | K16: 2 | L16: 2 | M16: 249 | N16: 1 | O16: =SUM(C16:L16,N16) -> 119 | P16: =SUM(C16:N16) -> 368 | R16: 1300-1400 | S16: =SUM(C34:C37) -> 170 | T16: =SUM(D34:D37) -> 61 | U16: =SUM(E34:E37) -> 28 | V16: =SUM(F34:F37) -> 115 | W16: =SUM(G34:G37) -> 3 | X16: =SUM(H34:H37) -> 1 | Y16: =SUM(I34:I37) -> 9 | Z16: =SUM(J34:J37) -> 26 | ... AF16: =SUM(P34:P37) -> 1137
B17: 08.45 - 9.00 | C17: 12 | D17: 8 | E17: 2 | F17: 40 | G17: 1 | H17: 0 | I17: 10 | J17: 3 | K17: 2 | L17: 1 | M17: 307 | N17: 0 | O17: =SUM(C17:L17,N17) -> 79 | P17: =SUM(C17:N17) -> 386 | R17: 1400-1500 | S17: =SUM(C38:C41) -> 240 | T17: =SUM(D38:D41) -> 47 | U17: =SUM(E38:E41) -> 35 | V17: =SUM(F38:F41) -> 109 | W17: =SUM(G38:G41) -> 4 | X17: =SUM(H38:H41) -> 0 | Y17: =SUM(I38:I41) -> 60 | Z17: =SUM(J38:J41) -> 28 | ... AF17: =SUM(P38:P41) -> 1731
B18: 09.00 - 09.15 | C18: 22 | D18: 10 | E18: 4 | F18: 38 | G18: 2 | H18: 0 | I18: 2 | J18: 2 | K18: 3 | L18: 4 | M18: 496 | N18: 0 | O18: =SUM(C18:L18,N18) -> 87 | P18: =SUM(C18:N18) -> 583 | R18: 1500-1600 | S18: =SUM(C42:C45) -> 242 | T18: =SUM(D42:D45) -> 52 | U18: =SUM(E42:E45) -> 33 | V18: =SUM(F42:F45) -> 129 | W18: =SUM(G42:G45) -> 0 | X18: =SUM(H42:H45) -> 2 | Y18: =SUM(I42:I45) -> 55 | Z18: =SUM(J42:J45) -> 19 | ... AF18: =SUM(P42:P45) -> 2341
B19: 09.15 - 09.30 | C19: 33 | D19: 7 | E19: 8 | F19: 33 | G19: 0 | H19: 0 | I19: 5 | J19: 3 | K19: 1 | L19: 1 | M19: 368 | N19: 0 | O19: =SUM(C19:L19,N19) -> 91 | P19: =SUM(C19:N19) -> 459 | R19: 1600-1700 | S19: =SUM(C46:C49) -> 235 | T19: =SUM(D46:D49) -> 230 | U19: =SUM(E46:E49) -> 103 | V19: =SUM(F46:F49) -> 119 | W19: =SUM(G46:G49) -> 6 | X19: =SUM(H46:H49) -> 0 | Y19: =SUM(I46:I49) -> 120 | Z19: =SUM(J46:J49) -> 16 | ... AF19: =SUM(P46:P49) -> 4157
B20: 09.30 - 09.45 | C20: 27 | D20: 2 | E20: 1 | F20: 37 | G20: 1 | H20: 0 | I20: 6 | J20: 6 | K20: 0 | L20: 5 | M20: 350 | N20: 0 | O20: =SUM(C20:L20,N20) -> 85 | P20: =SUM(C20:N20) -> 435 | R20: 1700-1800 | S20: =SUM(C50:C53) -> 331 | T20: =SUM(D50:D53) -> 140 | U20: =SUM(E50:E53) -> 44 | V20: =SUM(F50:F53) -> 102 | W20: =SUM(G50:G53) -> 10 | X20: =SUM(H50:H53) -> 0 | Y20: =SUM(I50:I53) -> 0 | Z20: =SUM(J50:J53) -> 13 | ... AF20: =SUM(P50:P53) -> 3442
B21: 09.45 - 10.00 | C21: 30 | D21: 8 | E21: 10 | F21: 51 | G21: 3 | H21: 1 | I21: 15 | J21: 1 | K21: 1 | L21: 2 | M21: 168 | N21: 1 | O21: =SUM(C21:L21,N21) -> 123 | P21: =SUM(C21:N21) -> 291 | R21: 1800-1900 | S21: =SUM(C54:C57) -> 175 | T21: =SUM(D54:D57) -> 165 | U21: =SUM(E54:E57) -> 117 | V21: =SUM(F54:F57) -> 69 | W21: =SUM(G54:G57) -> 1 | X21: =SUM(H54:H57) -> 1 | Y21: =SUM(I54:I57) -> 82 | Z21: =SUM(J54:J57) -> 12 | ... AF21: =SUM(P54:P57) -> 3523
B22: 10.00 - 10.15 | C22: 21 | D22: 3 | E22: 2 | F22: 27 | G22: 0 | H22: 0 | I22: 8 | J22: 3 | K22: 1 | L22: 5 | M22: 248 | N22: 0 | O22: =SUM(C22:L22,N22) -> 70 | P22: =SUM(C22:N22) -> 318 | R22: AM Peak Hr | S22: =MAX(S10:S12) -> 229 | T22: =MAX(T10:T12) -> 45 | U22: =MAX(U10:U12) -> 23 | V22: =MAX(V10:V12) -> 250 | W22: =MAX(W10:W12) -> 29 | X22: =MAX(X10:X12) -> 5 | Y22: =MAX(Y10:Y12) -> 28 | Z22: =MAX(Z10:Z12) -> 17 | ... AF22: =MAX(AF10:AF12) -> 2985
B23: 10.15 - 10.30 | C23: 38 | D23: 7 | E23: 3 | F23: 33 | G23: 2 | H23: 0 | I23: 9 | J23: 2 | K23: 0 | L23: 2 | M23: 145 | N23: 0 | O23: =SUM(C23:L23,N23) -> 96 | P23: =SUM(C23:N23) -> 241 | R23: IP Peak Hr | S23: =MAX(S13:S18) -> 242 | T23: =MAX(T13:T18) -> 61 | U23: =MAX(U13:U18) -> 35 | V23: =MAX(V13:V18) -> 151 | W23: =MAX(W13:W18) -> 6 | X23: =MAX(X13:X18) -> 2 | Y23: =MAX(Y13:Y18) -> 73 | Z23: =MAX(Z13:Z18) -> 28 | ... AF23: =MAX(AF13:AF18) -> 2341
B24: 10.30 - 10.45 | C24: 59 | D24: 3 | E24: 2 | F24: 42 | G24: 0 | H24: 0 | I24: 10 | J24: 2 | K24: 3 | L24: 3 | M24: 206 | N24: 0 | O24: =SUM(C24:L24,N24) -> 124 | P24: =SUM(C24:N24) -> 330 | R24: PM Peak Hr | S24: =MAX(S19:S21) -> 331 | T24: =MAX(T19:T21) -> 230 | U24: =MAX(U19:U21) -> 117 | V24: =MAX(V19:V21) -> 119 | W24: =MAX(W19:W21) -> 10 | X24: =MAX(X19:X21) -> 1 | Y24: =MAX(Y19:Y21) -> 120 | Z24: =MAX(Z19:Z21) -> 16 | ... AF24: =MAX(AF19:AF21) -> 4157
B25: 10.45 - 11.00 | C25: 56 | D25: 9 | E25: 9 | F25: 44 | G25: 4 | H25: 0 | I25: 46 | J25: 7 | K25: 2 | L25: 4 | M25: 301 | N25: 0 | O25: =SUM(C25:L25,N25) -> 181 | P25: =SUM(C25:N25) -> 482 | R25: AM Period | S25: =SUM(S10:S12) -> 485 | T25: =SUM(T10:T12) -> 112 | U25: =SUM(U10:U12) -> 61 | V25: =SUM(V10:V12) -> 607 | W25: =SUM(W10:W12) -> 38 | X25: =SUM(X10:X12) -> 6 | Y25: =SUM(Y10:Y12) -> 63 | Z25: =SUM(Z10:Z12) -> 37 | ... AF25: =SUM(AF10:AF12) -> 6590
B26: 11.00 - 11.15 | C26: 59 | D26: 7 | E26: 9 | F26: 46 | G26: 0 | H26: 0 | I26: 14 | J26: 6 | K26: 3 | L26: 11 | M26: 402 | N26: 1 | O26: =SUM(C26:L26,N26) -> 156 | P26: =SUM(C26:N26) -> 558 | R26: IP Period | S26: =SUM(S13:S18) -> 1210 | T26: =SUM(T13:T18) -> 247 | U26: =SUM(U13:U18) -> 165 | V26: =SUM(V13:V18) -> 796 | W26: =SUM(W13:W18) -> 15 | X26: =SUM(X13:X18) -> 5 | Y26: =SUM(Y13:Y18) -> 258 | Z26: =SUM(Z13:Z18) -> 139 | ... AF26: =SUM(AF13:AF18) -> 9779
B27: 11.15 - 11.30 | C27: 47 | D27: 6 | E27: 4 | F27: 24 | G27: 0 | H27: 0 | I27: 2 | J27: 6 | K27: 0 | L27: 2 | M27: 363 | N27: 0 | O27: =SUM(C27:L27,N27) -> 91 | P27: =SUM(C27:N27) -> 454 | R27: PM Period | S27: =SUM(S19:S21) -> 741 | T27: =SUM(T19:T21) -> 535 | U27: =SUM(U19:U21) -> 264 | V27: =SUM(V19:V21) -> 290 | W27: =SUM(W19:W21) -> 17 | X27: =SUM(X19:X21) -> 1 | Y27: =SUM(Y19:Y21) -> 202 | Z27: =SUM(Z19:Z21) -> 41 | ... AF27: =SUM(AF19:AF21) -> 11122
B28: 11.30 - 11.45 | C28: 48 | D28: 8 | E28: 8 | F28: 54 | G28: 1 | H28: 0 | I28: 2 | J28: 9 | K28: 0 | L28: 7 | M28: 299 | N28: 0 | O28: =SUM(C28:L28,N28) -> 137 | P28: =SUM(C28:N28) -> 436 | R28: 12 Hours | S28: =SUM(S10:S21) -> 2436 | T28: =SUM(T10:T21) -> 894 | U28: =SUM(U10:U21) -> 490 | V28: =SUM(V10:V21) -> 1693 | W28: =SUM(W10:W21) -> 70 | X28: =SUM(X10:X21) -> 12 | Y28: =SUM(Y10:Y21) -> 523 | Z28: =SUM(Z10:Z21) -> 217 | ... AF28: =SUM(AF10:AF21) -> 27491
B29: 11.45 - 12.00 | C29: 42 | D29: 7 | E29: 1 | F29: 27 | G29: 1 | H29: 1 | I29: 7 | J29: 6 | K29: 1 | L29: 3 | M29: 250 | N29: 0 | O29: =SUM(C29:L29,N29) -> 96 | P29: =SUM(C29:N29) -> 346
B30: 12.00 - 12.15 | C30: 46 | D30: 7 | E30: 5 | F30: 41 | G30: 0 | H30: 0 | I30: 8 | J30: 5 | K30: 1 | L30: 1 | M30: 252 | N30: 0 | O30: =SUM(C30:L30,N30) -> 114 | P30: =SUM(C30:N30) -> 366
B31: 12.15 - 12.30 | C31: 58 | D31: 8 | E31: 11 | F31: 37 | G31: 0 | H31: 1 | I31: 12 | J31: 8 | K31: 2 | L31: 7 | M31: 266 | N31: 0 | O31: =SUM(C31:L31,N31) -> 144 | P31: =SUM(C31:N31) -> 410
B32: 12.30 - 12.45 | C32: 33 | D32: 13 | E32: 7 | F32: 50 | G32: 0 | H32: 0 | I32: 7 | J32: 7 | K32: 3 | L32: 1 | M32: 137 | N32: 0 | O32: =SUM(C32:L32,N32) -> 121 | P32: =SUM(C32:N32) -> 258
B33: 12.45 - 13.00 | C33: 51 | D33: 9 | E33: 8 | F33: 18 | G33: 0 | H33: 0 | I33: 9 | J33: 5 | K33: 2 | L33: 5 | M33: 264 | N33: 0 | O33: =SUM(C33:L33,N33) -> 107 | P33: =SUM(C33:N33) -> 371
B34: 13.00 - 13.15 | C34: 36 | D34: 22 | E34: 9 | F34: 38 | G34: 0 | H34: 0 | I34: 9 | J34: 3 | K34: 2 | L34: 3 | M34: 244 | N34: 0 | O34: =SUM(C34:L34,N34) -> 122 | P34: =SUM(C34:N34) -> 366
B35: 13.15 - 13.30 | C35: 60 | D35: 17 | E35: 6 | F35: 24 | G35: 0 | H35: 0 | I35: 0 | J35: 3 | K35: 2 | L35: 5 | M35: 121 | N35: 0 | O35: =SUM(C35:L35,N35) -> 117 | P35: =SUM(C35:N35) -> 238
B36: 13.30 - 13.45 | C36: 36 | D36: 6 | E36: 7 | F36: 24 | G36: 0 | H36: 0 | I36: 0 | J36: 9 | K36: 2 | L36: 4 | M36: 215 | N36: 0 | O36: =SUM(C36:L36,N36) -> 88 | P36: =SUM(C36:N36) -> 303
B37: 13.45 - 14.00 | C37: 38 | D37: 16 | E37: 6 | F37: 29 | G37: 3 | H37: 1 | I37: 0 | J37: 11 | K37: 3 | L37: 5 | M37: 118 | N37: 0 | O37: =SUM(C37:L37,N37) -> 112 | P37: =SUM(C37:N37) -> 230
B38: 14.00 - 14.15 | C38: 60 | D38: 8 | E38: 8 | F38: 24 | G38: 1 | H38: 0 | I38: 22 | J38: 4 | K38: 1 | L38: 4 | M38: 152 | N38: 0 | O38: =SUM(C38:L38,N38) -> 132 | P38: =SUM(C38:N38) -> 284
B39: 14.15 - 14.30 | C39: 35 | D39: 16 | E39: 9 | F39: 17 | G39: 0 | H39: 0 | I39: 14 | J39: 9 | K39: 1 | L39: 6 | M39: 407 | N39: 0 | O39: =SUM(C39:L39,N39) -> 107 | P39: =SUM(C39:N39) -> 514
B40: 14.30 - 14.45 | C40: 90 | D40: 12 | E40: 11 | F40: 30 | G40: 1 | H40: 0 | I40: 13 | J40: 6 | K40: 1 | L40: 4 | M40: 305 | N40: 0 | O40: =SUM(C40:L40,N40) -> 168 | P40: =SUM(C40:N40) -> 473
... B57: 18.45 - 19.00 | C57: 35 | D57: 40 | E57: 20 | F57: 5 | G57: 0 | H57: 1 | I57: 15 | J57: 4 | K57: 2 | L57: 2 | M57: 500 | N57: 0 | O57: =SUM(C57:L57,N57) -> 124 | P57: =SUM(C57:N57) -> 624
B58: Totals | C58: =SUM(C10:C57) -> 2436 | D58: =SUM(D10:D57) -> 894 | E58: =SUM(E10:E57) -> 490 | F58: =SUM(F10:F57) -> 1693 | G58: =SUM(G10:G57) -> 70 | H58: =SUM(H10:H57) -> 12 | I58: =SUM(I10:I57) -> 523 | J58: =SUM(J10:J57) -> 217 | ... P58: =SUM(P10:P57) -> 27491
...

Sheet 30.07 Nsambya-ClockTower
B1: Consultancy services for Preparation of Expressway Development Master Plan (EDMP) for Uganda
B2: MANUAL CLASSIFIED COUNT (MCC)
B3: ROAD NAME: | C3: ='29.07 Nsambya-ClockTower'!C3:G3 -> MCC - C1 - STN50 - NSAMBYA ROAD
C5: Date | D5: ='30.07 ClockTower-Nsambya'!D5 -> 30.07.19 | F5: Location | G5: ='29.07 ClockTower-Nsambya'!G5:H5 -> Gapco | J5: Surveyor | K5: ='29.07 Nsambya-ClockTower'!K5:L5 -> Kizito Godfrey
C6: Dir. From | D6: ='29.07 Nsambya-ClockTower'!D6:E6 -> Nsambya | F6: Dir. To | G6: ='29.07 Nsambya-ClockTower'!G6:H6 -> ClockTower | J6: Supervisor | K6: ='29.07 ClockTower-Nsambya'!K6:L6 -> Felix
B8: Time / Veh Type | R8: SUMMARY TRAFFIC VOLUMES
C9: 1. Car | D9: 2. Station Wagon | E9: 3. Pickups | F9: 4. Minibus, matatu | G9: 5. Medium bus | H9: 6. Large Bus | I9: 7. Light Truck | J9: 8. Medium Truck | K9: 9. Heavy truck | L9: 10. Truck Trailer | M9: 11. Motor cycles | N9: 12. Tractors | O9: Total Excl M/Cycles | P9: Total All | R9: Time | S9: 1. Car | T9: 2. Station Wagon | U9: 3. Pickups | V9: 4. Minibus, matatu | W9: 5. Medium bus | X9: 6. Large Bus | Y9: 7. Light Truck | Z9: 8. Medium Truck | AA9: 9. Heavy truck | AB9: 10. Truck Trailer | AC9: 11. Motorcycles | AD9: 12. Tractors, Graders | AE9: Total Excl M/ Cycles | AF9: Total All
B10: 07.00 - 07.15 | C10: 93 | D10: 15 | E10: 7 | F10: 80 | G10: 1 | H10: 2 | I10: 2 | J10: 1 | K10: 2 | L10: 7 | M10: 310 | N10: 1 | O10: =SUM(C10:L10,N10) -> 211 | P10: =SUM(C10:N10) -> 521 | R10: 0700-0800 | S10: =SUM(C10:C13) -> 448 | T10: =SUM(D10:D13) -> 55 | U10: =SUM(E10:E13) -> 24 | V10: =SUM(F10:F13) -> 461 | W10: =SUM(G10:G13) -> 3 | X10: =SUM(H10:H13) -> 2 | Y10: =SUM(I10:I13) -> 10 | Z10: =SUM(J10:J13) -> 5 | ... AF10: =SUM(P10:P13) -> 2515
B11: 07.15 - 07.30 | C11: 70 | D11: 20 | E11: 8 | F11: 130 | G11: 0 | H11: 0 | I11: 2 | J11: 1 | K11: 3 | L11: 0 | M11: 335 | N11: 1 | O11: =SUM(C11:L11,N11) -> 235 | P11: =SUM(C11:N11) -> 570 | R11: 0800-0900 | S11: =SUM(C14:C17) -> 399 | T11: =SUM(D14:D17) -> 52 | U11: =SUM(E14:E17) -> 37 | V11: =SUM(F14:F17) -> 245 | W11: =SUM(G14:G17) -> 7 | X11: =SUM(H14:H17) -> 2 | Y11: =SUM(I14:I17) -> 11 | Z11: =SUM(J14:J17) -> 7 | ... AF11: =SUM(P14:P17) -> 2775
B12: 07.30 - 07.45 | C12: 130 | D12: 7 | E12: 6 | F12: 136 | G12: 0 | H12: 0 | I12: 3 | J12: 0 | K12: 0 | L12: 0 | M12: 375 | N12: 0 | O12: =SUM(C12:L12,N12) -> 282 | P12: =SUM(C12:N12) -> 657 | R12: 0900-1000 | S12: =SUM(C18:C21) -> 410 | T12: =SUM(D18:D21) -> 97 | U12: =SUM(E18:E21) -> 58 | V12: =SUM(F18:F21) -> 322 | W12: =SUM(G18:G21) -> 4 | X12: =SUM(H18:H21) -> 1 | Y12: =SUM(I18:I21) -> 22 | Z12: =SUM(J18:J21) -> 17 | ... AF12: =SUM(P18:P21) -> 2702
B13: 07.45 - 08.00 | C13: 155 | D13: 13 | E13: 3 | F13: 115 | G13: 2 | H13: 0 | I13: 3 | J13: 3 | K13: 2 | L13: 2 | M13: 465 | N13: 4 | O13: =SUM(C13:L13,N13) -> 302 | P13: =SUM(C13:N13) -> 767 | R13: 1000-1100 | S13: =SUM(C22:C25) -> 308 | T13: =SUM(D22:D25) -> 56 | U13: =SUM(E22:E25) -> 41 | V13: =SUM(F22:F25) -> 253 | W13: =SUM(G22:G25) -> 5 | X13: =SUM(H22:H25) -> 0 | Y13: =SUM(I22:I25) -> 31 | Z13: =SUM(J22:J25) -> 21 | ... AF13: =SUM(P22:P25) -> 2610
B14: 08.00 - 08.15 | C14: 100 | D14: 13 | E14: 9 | F14: 95 | G14: 1 | H14: 0 | I14: 3 | J14: 1 | K14: 1 | L14: 2 | M14: 503 | N14: 0 | O14: =SUM(C14:L14,N14) -> 225 | P14: =SUM(C14:N14) -> 728 | R14: 1100-1200 | S14: =SUM(C26:C29) -> 245 | T14: =SUM(D26:D29) -> 81 | U14: =SUM(E26:E29) -> 29 | V14: =SUM(F26:F29) -> 285 | W14: =SUM(G26:G29) -> 7 | X14: =SUM(H26:H29) -> 0 | Y14: =SUM(I26:I29) -> 22 | Z14: =SUM(J26:J29) -> 26 | ... AF14: =SUM(P26:P29) -> 2338
B15: 08.15 - 08.30 | C15: 135 | D15: 8 | E15: 11 | F15: 40 | G15: 1 | H15: 0 | I15: 3 | J15: 1 | K15: 2 | L15: 7 | M15: 468 | N15: 0 | O15: =SUM(C15:L15,N15) -> 208 | P15: =SUM(C15:N15) -> 676 | R15: 1200-1300 | S15: =SUM(C30:C33) -> 275 | T15: =SUM(D30:D33) -> 81 | U15: =SUM(E30:E33) -> 36 | V15: =SUM(F30:F33) -> 372 | W15: =SUM(G30:G33) -> 6 | X15: =SUM(H30:H33) -> 1 | Y15: =SUM(I30:I33) -> 30 | Z15: =SUM(J30:J33) -> 24 | ... AF15: =SUM(P30:P33) -> 2683
B16: 08.30 - 08.45 | C16: 90 | D16: 15 | E16: 8 | F16: 65 | G16: 1 | H16: 1 | I16: 4 | J16: 2 | K16: 2 | L16: 4 | M16: 497 | N16: 1 | O16: =SUM(C16:L16,N16) -> 193 | P16: =SUM(C16:N16) -> 690 | R16: 1300-1400 | S16: =SUM(C34:C37) -> 413 | T16: =SUM(D34:D37) -> 46 | U16: =SUM(E34:E37) -> 41 | V16: =SUM(F34:F37) -> 354 | W16: =SUM(G34:G37) -> 10 | X16: =SUM(H34:H37) -> 0 | Y16: =SUM(I34:I37) -> 46 | Z16: =SUM(J34:J37) -> 16 | ... AF16: =SUM(P34:P37) -> 2656
B17: 08.45 - 9.00 | C17: 74 | D17: 16 | E17: 9 | F17: 45 | G17: 4 | H17: 1 | I17: 1 | J17: 3 | K17: 3 | L17: 0 | M17: 525 | N17: 0 | O17: =SUM(C17:L17,N17) -> 156 | P17: =SUM(C17:N17) -> 681 | R17: 1400-1500 | S17: =SUM(C38:C41) -> 438 | T17: =SUM(D38:D41) -> 70 | U17: =SUM(E38:E41) -> 62 | V17: =SUM(F38:F41) -> 356 | W17: =SUM(G38:G41) -> 5 | X17: =SUM(H38:H41) -> 4 | Y17: =SUM(I38:I41) -> 40 | Z17: =SUM(J38:J41) -> 28 | ... AF17: =SUM(P38:P41) -> 2560
B18: 09.00 - 09.15 | C18: 165 | D18: 39 | E18: 22 | F18: 55 | G18: 0 | H18: 0 | I18: 8 | J18: 3 | K18: 3 | L18: 2 | M18: 402 | N18: 0 | O18: =SUM(C18:L18,N18) -> 297 | P18: =SUM(C18:N18) -> 699 | R18: 1500-1600 | S18: =SUM(C42:C45) -> 390 | T18: =SUM(D42:D45) -> 34 | U18: =SUM(E42:E45) -> 29 | V18: =SUM(F42:F45) -> 380 | W18: =SUM(G42:G45) -> 3 | X18: =SUM(H42:H45) -> 0 | Y18: =SUM(I42:I45) -> 165 | Z18: =SUM(J42:J45) -> 22 | ... AF18: =SUM(P42:P45) -> 2135
B19: 09.15 - 09.30 | C19: 75 | D19: 28 | E19: 17 | F19: 65 | G19: 2 | H19: 0 | I19: 3 | J19: 6 | K19: 4 | L19: 3 | M19: 445 | N19: 0 | O19: =SUM(C19:L19,N19) -> 203 | P19: =SUM(C19:N19) -> 648 | R19: 1600-1700 | S19: =SUM(C46:C49) -> 265 | T19: =SUM(D46:D49) -> 63 | U19: =SUM(E46:E49) -> 32 | V19: =SUM(F46:F49) -> 563 | W19: =SUM(G46:G49) -> 8 | X19: =SUM(H46:H49) -> 0 | Y19: =SUM(I46:I49) -> 45 | Z19: =SUM(J46:J49) -> 34 | ... AF19: =SUM(P46:P49) -> 2489
B20: 09.30 - 09.45 | C20: 75 | D20: 15 | E20: 10 | F20: 120 | G20: 0 | H20: 0 | I20: 4 | J20: 4 | K20: 2 | L20: 3 | M20: 490 | N20: 0 | O20: =SUM(C20:L20,N20) -> 233 | P20: =SUM(C20:N20) -> 723 | R20: 1700-1800 | S20: =SUM(C50:C53) -> 345 | T20: =SUM(D50:D53) -> 30 | U20: =SUM(E50:E53) -> 72 | V20: =SUM(F50:F53) -> 345 | W20: =SUM(G50:G53) -> 5 | X20: =SUM(H50:H53) -> 2 | Y20: =SUM(I50:I53) -> 45 | Z20: =SUM(J50:J53) -> 28 | ... AF20: =SUM(P50:P53) -> 2894
B21: 09.45 - 10.00 | C21: 95 | D21: 15 | E21: 9 | F21: 82 | G21: 2 | H21: 1 | I21: 7 | J21: 4 | K21: 0 | L21: 2 | M21: 415 | N21: 0 | O21: =SUM(C21:L21,N21) -> 217 | P21: =SUM(C21:N21) -> 632 | R21: 1800-1900 | S21: =SUM(C54:C57) -> 288 | T21: =SUM(D54:D57) -> 29 | U21: =SUM(E54:E57) -> 104 | V21: =SUM(F54:F57) -> 211 | W21: =SUM(G54:G57) -> 5 | X21: =SUM(H54:H57) -> 2 | Y21: =SUM(I54:I57) -> 36 | Z21: =SUM(J54:J57) -> 26 | ... AF21: =SUM(P54:P57) -> 2644
B22: 10.00 - 10.15 | C22: 72 | D22: 7 | E22: 12 | F22: 65 | G22: 0 | H22: 0 | I22: 9 | J22: 3 | K22: 1 | L22: 3 | M22: 535 | N22: 0 | O22: =SUM(C22:L22,N22) -> 172 | P22: =SUM(C22:N22) -> 707 | R22: AM Peak Hr | S22: =MAX(S10:S12) -> 448 | T22: =MAX(T10:T12) -> 97 | U22: =MAX(U10:U12) -> 58 | V22: =MAX(V10:V12) -> 461 | W22: =MAX(W10:W12) -> 7 | X22: =MAX(X10:X12) -> 2 | Y22: =MAX(Y10:Y12) -> 22 | Z22: =MAX(Z10:Z12) -> 17 | ... AF22: =MAX(AF10:AF12) -> 2775
B23: 10.15 - 10.30 | C23: 56 | D23: 21 | E23: 9 | F23: 90 | G23: 2 | H23: 0 | I23: 8 | J23: 7 | K23: 3 | L23: 2 | M23: 467 | N23: 1 | O23: =SUM(C23:L23,N23) -> 199 | P23: =SUM(C23:N23) -> 666 | R23: IP Peak Hr | S23: =MAX(S13:S18) -> 438 | T23: =MAX(T13:T18) -> 81 | U23: =MAX(U13:U18) -> 62 | V23: =MAX(V13:V18) -> 380 | W23: =MAX(W13:W18) -> 10 | X23: =MAX(X13:X18) -> 4 | Y23: =MAX(Y13:Y18) -> 165 | Z23: =MAX(Z13:Z18) -> 28 | ... AF23: =MAX(AF13:AF18) -> 2683
B24: 10.30 - 10.45 | C24: 80 | D24: 15 | E24: 12 | F24: 80 | G24: 2 | H24: 0 | I24: 8 | J24: 6 | K24: 1 | L24: 6 | M24: 463 | N24: 1 | O24: =SUM(C24:L24,N24) -> 211 | P24: =SUM(C24:N24) -> 674 | R24: PM Peak Hr | S24: =MAX(S19:S21) -> 345 | T24: =MAX(T19:T21) -> 63 | U24: =MAX(U19:U21) -> 104 | V24: =MAX(V19:V21) -> 563 | W24: =MAX(W19:W21) -> 8 | X24: =MAX(X19:X21) -> 2 | Y24: =MAX(Y19:Y21) -> 45 | Z24: =MAX(Z19:Z21) -> 34 | ... AF24: =MAX(AF19:AF21) -> 2894
B25: 10.45 - 11.00 | C25: 100 | D25: 13 | E25: 8 | F25: 18 | G25: 1 | H25: 0 | I25: 6 | J25: 5 | K25: 0 | L25: 2 | M25: 410 | N25: 0 | O25: =SUM(C25:L25,N25) -> 153 | P25: =SUM(C25:N25) -> 563 | R25: AM Period | S25: =SUM(S10:S12) -> 1257 | T25: =SUM(T10:T12) -> 204 | U25: =SUM(U10:U12) -> 119 | V25: =SUM(V10:V12) -> 1028 | W25: =SUM(W10:W12) -> 14 | X25: =SUM(X10:X12) -> 5 | Y25: =SUM(Y10:Y12) -> 43 | Z25: =SUM(Z10:Z12) -> 29 | ... AF25: =SUM(AF10:AF12) -> 7992
B26: 11.00 - 11.15 | C26: 35 | D26: 12 | E26: 7 | F26: 70 | G26: 3 | H26: 0 | I26: 6 | J26: 5 | K26: 3 | L26: 417 | M26: 0 | N26: 0 | O26: =SUM(C26:L26,N26) -> 558 | P26: =SUM(C26:N26) -> 558 | R26: IP Period | S26: =SUM(S13:S18) -> 2069 | T26: =SUM(T13:T18) -> 368 | U26: =SUM(U13:U18) -> 238 | V26: =SUM(V13:V18) -> 2000 | W26: =SUM(W13:W18) -> 36 | X26: =SUM(X13:X18) -> 5 | Y26: =SUM(Y13:Y18) -> 334 | Z26: =SUM(Z13:Z18) -> 137 | ... AF26: =SUM(AF13:AF18) -> 14982
B27: 11.15 - 11.30 | C27: 45 | D27: 24 | E27: 9 | F27: 85 | G27: 1 | H27: 0 | I27: 4 | J27: 6 | K27: 7 | L27: 6 | M27: 391 | N27: 0 | O27: =SUM(C27:L27,N27) -> 187 | P27: =SUM(C27:N27) -> 578 | R27: PM Period | S27: =SUM(S19:S21) -> 898 | T27: =SUM(T19:T21) -> 122 | U27: =SUM(U19:U21) -> 208 | V27: =SUM(V19:V21) -> 1119 | W27: =SUM(W19:W21) -> 18 | X27: =SUM(X19:X21) -> 4 | Y27: =SUM(Y19:Y21) -> 126 | Z27: =SUM(Z19:Z21) -> 88 | ... AF27: =SUM(AF19:AF21) -> 8027
B28: 11.30 - 11.45 | C28: 60 | D28: 20 | E28: 7 | F28: 80 | G28: 2 | H28: 0 | I28: 7 | J28: 4 | K28: 5 | L28: 4 | M28: 405 | N28: 0 | O28: =SUM(C28:L28,N28) -> 189 | P28: =SUM(C28:N28) -> 594 | R28: 12 Hours | S28: =SUM(S10:S21) -> 4224 | T28: =SUM(T10:T21) -> 694 | U28: =SUM(U10:U21) -> 565 | V28: =SUM(V10:V21) -> 4147 | W28: =SUM(W10:W21) -> 68 | X28: =SUM(X10:X21) -> 14 | Y28: =SUM(Y10:Y21) -> 503 | Z28: =SUM(Z10:Z21) -> 254 | ... AF28: =SUM(AF10:AF21) -> 31001
B29: 11.45 - 12.00 | C29: 105 | D29: 25 | E29: 6 | F29: 50 | G29: 1 | H29: 0 | I29: 5 | J29: 11 | K29: 0 | L29: 4 | M29: 401 | N29: 0 | O29: =SUM(C29:L29,N29) -> 207 | P29: =SUM(C29:N29) -> 608
B30: 12.00 - 12.15 | C30: 46 | D30: 18 | E30: 5 | F30: 90 | G30: 2 | H30: 1 | I30: 3 | J30: 6 | K30: 4 | L30: 9 | M30: 472 | N30: 0 | O30: =SUM(C30:L30,N30) -> 184 | P30: =SUM(C30:N30) -> 656
B31: 12.15 - 12.30 | C31: 93 | D31: 13 | E31: 14 | F31: 95 | G31: 2 | H31: 0 | I31: 12 | J31: 3 | K31: 2 | L31: 7 | M31: 445 | N31: 0 | O31: =SUM(C31:L31,N31) -> 241 | P31: =SUM(C31:N31) -> 686
B32: 12.30 - 12.45 | C32: 75 | D32: 41 | E32: 9 | F32: 97 | G32: 1 | H32: 0 | I32: 7 | J32: 8 | K32: 5 | L32: 11 | M32: 435 | N32: 0 | O32: =SUM(C32:L32,N32) -> 254 | P32: =SUM(C32:N32) -> 689
B33: 12.45 - 13.00 | C33: 61 | D33: 9 | E33: 8 | F33: 90 | G33: 1 | H33: 0 | I33: 8 | J33: 7 | K33: 6 | L33: 8 | M33: 454 | N33: 0 | O33: =SUM(C33:L33,N33) -> 198 | P33: =SUM(C33:N33) -> 652
B34: 13.00 - 13.15 | C34: 121 | D34: 20 | E34: 11 | F34: 59 | G34: 1 | H34: 0 | I34: 8 | J34: 9 | K34: 2 | L34: 5 | M34: 420 | N34: 0 | O34: =SUM(C34:L34,N34) -> 236 | P34: =SUM(C34:N34) -> 656
B35: 13.15 - 13.30 | C35: 50 | D35: 12 | E35: 10 | F35: 105 | G35: 3 | H35: 0 | I35: 10 | J35: 2 | K35: 1 | L35: 5 | M35: 449 | N35: 1 | O35: =SUM(C35:L35,N35) -> 199 | P35: =SUM(C35:N35) -> 648
B36: 13.30 - 13.45 | C36: 90 | D36: 10 | E36: 12 | F36: 110 | G36: 4 | H36: 0 | I36: 16 | J36: 0 | K36: 6 | L36: 7 | M36: 386 | N36: 0 | O36: =SUM(C36:L36,N36) -> 255 | P36: =SUM(C36:N36) -> 641
B37: 13.45 - 14.00 | C37: 152 | D37: 4 | E37: 8 | F37: 80 | G37: 2 | H37: 0 | I37: 12 | J37: 5 | K37: 8 | L37: 5 | M37: 435 | N37: 0 | O37: =SUM(C37:L37,N37) -> 276 | P37: =SUM(C37:N37) -> 711
B38: 14.00 - 14.15 | C38: 175 | D38: 10 | E38: 17 | F38: 71 | G38: 1 | H38: 0 | I38: 6 | J38: 7 | K38: 3 | L38: 9 | M38: 444 | N38: 0 | O38: =SUM(C38:L38,N38) -> 299 | P38: =SUM(C38:N38) -> 743
B39: 14.15 - 14.30 | C39: 75 | D39: 5 | E39: 17 | F39: 110 | G39: 3 | H39: 3 | I39: 16 | J39: 8 | K39: 5 | L39: 4 | M39: 380 | N39: 0 | O39: =SUM(C39:L39,N39) -> 246 | P39: =SUM(C39:N39) -> 626
B40: 14.30 - 14.45 | C40: 83 | D40: 11 | E40: 12 | F40: 95 | G40: 1 | H40: 0 | I40: 10 | J40: 6 | K40: 4 | L40: 8 | M40: 355 | N40: 0 | O40: =SUM(C40:L40,N40) -> 230 | P40: =SUM(C40:N40) -> 585
... B57: 18.45 - 19.00 | C57: 50 | D57: 9 | E57: 8 | F57: 35 | G57: 1 | H57: 2 | I57: 6 | J57: 7 | K57: 9 | L57: 12 | M57: 463 | N57: 0 | O57: =SUM(C57:L57,N57) -> 139 | P57: =SUM(C57:N57) -> 602
B58: Totals | C58: =SUM(C10:C57) -> 4224 | D58: =SUM(D10:D57) -> 694 | E58: =SUM(E10:E57) -> 565 | F58: =SUM(F10:F57) -> 4147 | G58: =SUM(G10:G57) -> 68 | H58: =SUM(H10:H57) -> 14 | I58: =SUM(I10:I57) -> 503 | J58: =SUM(J10:J57) -> 254 | ... P58: =SUM(P10:P57) -> 31001
...

Sheet 31.07 ClockTower-Nsambya
B1: Consultancy services for Preparation of Expressway Development Master Plan (EDMP) for Uganda
B2: MANUAL CLASSIFIED COUNT (MCC)
B3: ROAD NAME: | C3: ='29.07 ClockTower-Nsambya'!C3:G3 -> MCC - C1 - STN50 - NSAMBYA ROAD
C5: Date | D5: 31.07.19 | F5: Location | G5: ='29.07 ClockTower-Nsambya'!G5:H5 -> Gapco | J5: Surveyor | K5: ='29.07 ClockTower-Nsambya'!K5:L5 -> Adong Agnes
C6: Dir. From | D6: ='29.07 ClockTower-Nsambya'!D6:E6 -> Clock Tower | F6: Dir. To | G6: ='29.07 ClockTower-Nsambya'!G6:H6 -> Nsambya | J6: Supervisor | K6: ='29.07 ClockTower-Nsambya'!K6:L6 -> Felix
B8: Time / Veh Type | R8: SUMMARY TRAFFIC VOLUMES
C9: 1. Car | D9: 2. Station Wagon | E9: 3. Pickups | F9: 4. Minibus, matatu | G9: 5. Medium bus | H9: 6. Large Bus | I9: 7. Light Truck | J9: 8. Medium Truck | K9: 9. Heavy truck | L9: 10. Truck Trailer | M9: 11. Motor cycles | N9: 12. Tractors | O9: Total Excl M/Cycles | P9: Total All | R9: Time | S9: 1. Car | T9: 2. Station Wagon | U9: 3. Pickups | V9: 4. Minibus, matatu | W9: 5. Medium bus | X9: 6. Large Bus | Y9: 7. Light Truck | Z9: 8. Medium Truck | AA9: 9. Heavy truck | AB9: 10. Truck Trailer | AC9: 11. Motorcycles | AD9: 12. Tractors, Graders | AE9: Total Excl M/ Cycles | AF9: Total All
B10: 07.00 - 07.15 | C10: 90 | D10: 9 | E10: 8 | F10: 60 | G10: 1 | H10: 1 | I10: 5 | J10: 6 | K10: 3 | L10: 5 | M10: 298 | N10: 0 | O10: =SUM(C10:L10,N10) -> 188 | P10: =SUM(C10:N10) -> 486 | R10: 0700-0800 | S10: =SUM(C10:C13) -> 402 | T10: =SUM(D10:D13) -> 49 | U10: =SUM(E10:E13) -> 42 | V10: =SUM(F10:F13) -> 236 | W10: =SUM(G10:G13) -> 5 | X10: =SUM(H10:H13) -> 2 | Y10: =SUM(I10:I13) -> 31 | Z10: =SUM(J10:J13) -> 14 | ... AF10: =SUM(P10:P13) -> 2223
B11: 07.15 - 07.30 | C11: 75 | D11: 8 | E11: 13 | F11: 55 | G11: 2 | H11: 0 | I11: 9 | J11: 3 | K11: 2 | L11: 6 | M11: 315 | N11: 0 | O11: =SUM(C11:L11,N11) -> 173 | P11: =SUM(C11:N11) -> 488 | R11: 0800-0900 | S11: =SUM(C14:C17) -> 485 | T11: =SUM(D14:D17) -> 62 | U11: =SUM(E14:E17) -> 51 | V11: =SUM(F14:F17) -> 273 | W11: =SUM(G14:G17) -> 2 | X11: =SUM(H14:H17) -> 1 | Y11: =SUM(I14:I17) -> 25 | Z11: =SUM(J14:J17) -> 9 | ... AF11: =SUM(P14:P17) -> 2563
B12: 07.30 - 07.45 | C12: 110 | D12: 15 | E12: 15 | F12: 56 | G12: 2 | H12: 0 | I12: 4 | J12: 3 | K12: 4 | L12: 1 | M12: 388 | N12: 1 | O12: =SUM(C12:L12,N12) -> 211 | P12: =SUM(C12:N12) -> 599 | R12: 0900-1000 | S12: =SUM(C18:C21) -> 450 | T12: =SUM(D18:D21) -> 42 | U12: =SUM(E18:E21) -> 48 | V12: =SUM(F18:F21) -> 396 | W12: =SUM(G18:G21) -> 9 | X12: =SUM(H18:H21) -> 2 | Y12: =SUM(I18:I21) -> 31 | Z12: =SUM(J18:J21) -> 16 | ... AF12: =SUM(P18:P21) -> 3255
B13: 07.45 - 08.00 | C13: 127 | D13: 17 | E13: 6 | F13: 65 | G13: 0 | H13: 1 | I13: 13 | J13: 2 | K13: 1 | L13: 2 | M13: 416 | N13: 0 | O13: =SUM(C13:L13,N13) -> 234 | P13: =SUM(C13:N13) -> 650 | R13: 1000-1100 | S13: =SUM(C22:C25) -> 356 | T13: =SUM(D22:D25) -> 57 | U13: =SUM(E22:E25) -> 47 | V13: =SUM(F22:F25) -> 449 | W13: =SUM(G22:G25) -> 8 | X13: =SUM(H22:H25) -> 2 | Y13: =SUM(I22:I25) -> 36 | Z13: =SUM(J22:J25) -> 23 | ... AF13: =SUM(P22:P25) -> 3027
B14: 08.00 - 08.15 | C14: 140 | D14: 21 | E14: 11 | F14: 70 | G14: 1 | H14: 0 | I14: 8 | J14: 3 | K14: 8 | L14: 1 | M14: 406 | N14: 0 | O14: =SUM(C14:L14,N14) -> 263 | P14: =SUM(C14:N14) -> 669 | R14: 1100-1200 | S14: =SUM(C26:C29) -> 380 | T14: =SUM(D26:D29) -> 62 | U14: =SUM(E26:E29) -> 52 | V14: =SUM(F26:F29) -> 402 | W14: =SUM(G26:G29) -> 7 | X14: =SUM(H26:H29) -> 1 | Y14: =SUM(I26:I29) -> 39 | Z14: =SUM(J26:J29) -> 24 | ... AF14: =SUM(P26:P29) -> 3065
B15: 08.15 - 08.30 | C15: 90 | D15: 7 | E15: 12 | F15: 66 | G15: 0 | H15: 0 | I15: 7 | J15: 2 | K15: 3 | L15: 2 | M15: 387 | N15: 0 | O15: =SUM(C15:L15,N15) -> 189 | P15: =SUM(C15:N15) -> 576 | R15: 1200-1300 | S15: =SUM(C30:C33) -> 414 | T15: =SUM(D30:D33) -> 39 | U15: =SUM(E30:E33) -> 36 | V15: =SUM(F30:F33) -> 435 | W15: =SUM(G30:G33) -> 8 | X15: =SUM(H30:H33) -> 3 | Y15: =SUM(I30:I33) -> 32 | Z15: =SUM(J30:J33) -> 32 | ... AF15: =SUM(P30:P33) -> 3005
B16: 08.30 - 08.45 | C16: 105 | D16: 23 | E16: 16 | F16: 60 | G16: 1 | H16: 0 | I16: 5 | J16: 2 | K16: 4 | L16: 2 | M16: 418 | N16: 1 | O16: =SUM(C16:L16,N16) -> 219 | P16: =SUM(C16:N16) -> 637 | R16: 1300-1400 | S16: =SUM(C34:C37) -> 405 | T16: =SUM(D34:D37) -> 61 | U16: =SUM(E34:E37) -> 69 | V16: =SUM(F34:F37) -> 360 | W16: =SUM(G34:G37) -> 14 | X16: =SUM(H34:H37) -> 3 | Y16: =SUM(I34:I37) -> 47 | Z16: =SUM(J34:J37) -> 39 | ... AF16: =SUM(P34:P37) -> 3132
B17: 08.45 - 9.00 | C17: 150 | D17: 11 | E17: 12 | F17: 77 | G17: 0 | H17: 1 | I17: 5 | J17: 2 | K17: 0 | L17: 1 | M17: 422 | N17: 0 | O17: =SUM(C17:L17,N17) -> 259 | P17: =SUM(C17:N17) -> 681 | R17: 1400-1500 | S17: =SUM(C38:C41) -> 430 | T17: =SUM(D38:D41) -> 62 | U17: =SUM(E38:E41) -> 57 | V17: =SUM(F38:F41) -> 343 | W17: =SUM(G38:G41) -> 13 | X17: =SUM(H38:H41) -> 0 | Y17: =SUM(I38:I41) -> 47 | Z17: =SUM(J38:J41) -> 33 | ... AF17: =SUM(P38:P41) -> 3313
B18: 09.00 - 09.15 | C18: 115 | D18: 12 | E18: 6 | F18: 100 | G18: 3 | H18: 1 | I18: 9 | J18: 8 | K18: 0 | L18: 0 | M18: 685 | N18: 1 | O18: =SUM(C18:L18,N18) -> 255 | P18: =SUM(C18:N18) -> 940 | R18: 1500-1600 | S18: =SUM(C42:C45) -> 378 | T18: =SUM(D42:D45) -> 95 | U18: =SUM(E42:E45) -> 67 | V18: =SUM(F42:F45) -> 424 | W18: =SUM(G42:G45) -> 7 | X18: =SUM(H42:H45) -> 0 | Y18: =SUM(I42:I45) -> 52 | Z18: =SUM(J42:J45) -> 29 | ... AF18: =SUM(P42:P45) -> 3297
B19: 09.15 - 09.30 | C19: 170 | D19: 12 | E19: 23 | F19: 80 | G19: 0 | H19: 0 | I19: 2 | J19: 1 | K19: 0 | L19: 3 | M19: 625 | N19: 0 | O19: =SUM(C19:L19,N19) -> 291 | P19: =SUM(C19:N19) -> 916 | R19: 1600-1700 | S19: =SUM(C46:C49) -> 393 | T19: =SUM(D46:D49) -> 66 | U19: =SUM(E46:E49) -> 59 | V19: =SUM(F46:F49) -> 390 | W19: =SUM(G46:G49) -> 4 | X19: =SUM(H46:H49) -> 0 | Y19: =SUM(I46:I49) -> 30 | Z19: =SUM(J46:J49) -> 31 | ... AF19: =SUM(P46:P49) -> 2777
B20: 09.30 - 09.45 | C20: 105 | D20: 8 | E20: 12 | F20: 106 | G20: 6 | H20: 1 | I20: 17 | J20: 3 | K20: 2 | L20: 1 | M20: 510 | N20: 1 | O20: =SUM(C20:L20,N20) -> 262 | P20: =SUM(C20:N20) -> 772 | R20: 1700-1800 | S20: =SUM(C50:C53) -> 380 | T20: =SUM(D50:D53) -> 47 | U20: =SUM(E50:E53) -> 62 | V20: =SUM(F50:F53) -> 281 | W20: =SUM(G50:G53) -> 4 | X20: =SUM(H50:H53) -> 0 | Y20: =SUM(I50:I53) -> 34 | Z20: =SUM(J50:J53) -> 20 | ... AF20: =SUM(P50:P53) -> 2569
B21: 09.45 - 10.00 | C21: 60 | D21: 10 | E21: 7 | F21: 110 | G21: 0 | H21: 0 | I21: 3 | J21: 4 | K21: 5 | L21: 2 | M21: 425 | N21: 1 | O21: =SUM(C21:L21,N21) -> 202 | P21: =SUM(C21:N21) -> 627 | R21: 1800-1900 | S21: =SUM(C54:C57) -> 248 | T21: =SUM(D54:D57) -> 45 | U21: =SUM(E54:E57) -> 33 | V21: =SUM(F54:F57) -> 172 | W21: =SUM(G54:G57) -> 5 | X21: =SUM(H54:H57) -> 2 | Y21: =SUM(I54:I57) -> 18 | Z21: =SUM(J54:J57) -> 23 | ... AF21: =SUM(P54:P57) -> 2693
B22: 10.00 - 10.15 | C22: 75 | D22: 7 | E22: 8 | F22: 135 | G22: 4 | H22: 1 | I22: 6 | J22: 3 | K22: 1 | L22: 5 | M22: 465 | N22: 0 | O22: =SUM(C22:L22,N22) -> 245 | P22: =SUM(C22:N22) -> 710 | R22: AM Peak Hr | S22: =MAX(S10:S12) -> 485 | T22: =MAX(T10:T12) -> 62 | U22: =MAX(U10:U12) -> 51 | V22: =MAX(V10:V12) -> 396 | W22: =MAX(W10:W12) -> 9 | X22: =MAX(X10:X12) -> 2 | Y22: =MAX(Y10:Y12) -> 31 | Z22: =MAX(Z10:Z12) -> 16 | ... AF22: =MAX(AF10:AF12) -> 3255
B23: 10.15 - 10.30 | C23: 95 | D23: 11 | E23: 12 | F23: 94 | G23: 0 | H23: 1 | I23: 13 | J23: 5 | K23: 5 | L23: 3 | M23: 475 | N23: 0 | O23: =SUM(C23:L23,N23) -> 239 | P23: =SUM(C23:N23) -> 714 | R23: IP Peak Hr | S23: =MAX(S13:S18) -> 430 | T23: =MAX(T13:T18) -> 95 | U23: =MAX(U13:U18) -> 69 | V23: =MAX(V13:V18) -> 449 | W23: =MAX(W13:W18) -> 14 | X23: =MAX(X13:X18) -> 3 | Y23: =MAX(Y13:Y18) -> 52 | Z23: =MAX(Z13:Z18) -> 39 | ... AF23: =MAX(AF13:AF18) -> 3313
B24: 10.30 - 10.45 | C24: 106 | D24: 9 | E24: 13 | F24: 120 | G24: 3 | H24: 0 | I24: 7 | J24: 6 | K24: 3 | L24: 5 | M24: 515 | N24: 0 | O24: =SUM(C24:L24,N24) -> 272 | P24: =SUM(C24:N24) -> 787 | R24: PM Peak Hr | S24: =MAX(S19:S21) -> 393 | T24: =MAX(T19:T21) -> 66 | U24: =MAX(U19:U21) -> 62 | V24: =MAX(V19:V21) -> 390 | W24: =MAX(W19:W21) -> 5 | X24: =MAX(X19:X21) -> 2 | Y24: =MAX(Y19:Y21) -> 34 | Z24: =MAX(Z19:Z21) -> 31 | ... AF24: =MAX(AF19:AF21) -> 2777
B25: 10.45 - 11.00 | C25: 80 | D25: 30 | E25: 14 | F25: 100 | G25: 1 | H25: 0 | I25: 10 | J25: 9 | K25: 1 | L25: 6 | M25: 565 | N25: 0 | O25: =SUM(C25:L25,N25) -> 251 | P25: =SUM(C25:N25) -> 816 | R25: AM Period | S25: =SUM(S10:S12) -> 1337 | T25: =SUM(T10:T12) -> 153 | U25: =SUM(U10:U12) -> 141 | V25: =SUM(V10:V12) -> 905 | W25: =SUM(W10:W12) -> 16 | X25: =SUM(X10:X12) -> 5 | Y25: =SUM(Y10:Y12) -> 87 | Z25: =SUM(Z10:Z12) -> 39 | ... AF25: =SUM(AF10:AF12) -> 8041
