Workbook

Sheet 22.07 Bwaise-Makerere
B1: Consultancy services for Preparation of Expressway Development Master Plan (EDMP) for Uganda
B2: MANUAL CLASSIFIED COUNT (MCC)
B3: ROAD NAME: | C3: MCC - C1 - STN021- SIR APOLLO ROAD
C5: Date | D5: 43668 | F5: Location | G5: SAHSEN PLAZA | J5: Surveyor | K5: RUTH
C6: Dir. From | D6: Bwaise | F6: Dir. To | G6: Makerere | J6: Supervisor | K6: SALIMAH
B8: Time / Veh Type | R8: SUMMARY TRAFFIC VOLUMES
C9: 1. Car | D9: 2. Station Wagon | E9: 3. Pickups | F9: 4. Minibus, matatu | G9: 5. Medium bus | H9: 6. Large Bus | I9: 7. Light Truck | J9: 8. Medium Truck | K9: 9. Heavy truck | L9: 10. Truck Trailer | M9: 11. Motor cycles | N9: 12. Tractors | O9: Total Excl M/Cycles | P9: Total All | R9: Time | S9: 1. Car | T9: 2. Station Wagon | U9: 3. Pickups | V9: 4. Minibus, matatu | W9: 5. Medium bus | X9: 6. Large Bus | Y9: 7. Light Truck | Z9: 8. Medium Truck | AA9: 9. Heavy truck | AB9: 10. Truck Trailer | AC9: 11. Motorcycles | AD9: 12. Tractors, Graders | AE9: Total Excl M/ Cycles | AF9: Total All
B10: 07.00 - 07.15 | C10: 60 | D10: 30 | E10: 10 | F10: 60 | G10: 3 | H10: 0 | I10: 1 | J10: 1 | K10: 0 | L10: 0 | M10: 80 | N10: 0 | O10: =SUM(C10:L10,N10) -> 165 | P10: =SUM(C10:N10) -> 245 | R10: 0700-0800 | S10: =SUM(C10:C13) -> 236 | T10: =SUM(D10:D13) -> 74 | U10: =SUM(E10:E13) -> 30 | V10: =SUM(F10:F13) -> 172 | W10: =SUM(G10:G13) -> 6 | X10: =SUM(H10:H13) -> 2 | Y10: =SUM(I10:I13) -> 9 | Z10: =SUM(J10:J13) -> 3 | ... AF10: =SUM(P10:P13) -> 929
B11: 07.15 - 07.30 | C11: 50 | D11: 25 | E11: 7 | F11: 50 | G11: 2 | H11: 0 | I11: 0 | J11: 0 | K11: 0 | M11: 50 | N11: 0 | O11: =SUM(C11:L11,N11) -> 134 | P11: =SUM(C11:N11) -> 184 | R11: 0800-0900 | S11: =SUM(C14:C17) -> 308 | T11: =SUM(D14:D17) -> 81 | U11: =SUM(E14:E17) -> 37 | V11: =SUM(F14:F17) -> 292 | W11: =SUM(G14:G17) -> 6 | X11: =SUM(H14:H17) -> 6 | Y11: =SUM(I14:I17) -> 72 | Z11: =SUM(J14:J17) -> 6 | ... AF11: =SUM(P14:P17) -> 1610
B12: 07.30 - 07.45 | C12: 66 | D12: 0 | E12: 4 | F12: 9 | G12: 1 | H12: 0 | I12: 2 | J12: 0 | K12: 0 | L12: 0 | M12: 150 | N12: 0 | O12: =SUM(C12:L12,N12) -> 82 | P12: =SUM(C12:N12) -> 232 | R12: 0900-1000 | S12: =SUM(C18:C21) -> 203 | T12: =SUM(D18:D21) -> 56 | U12: =SUM(E18:E21) -> 23 | V12: =SUM(F18:F21) -> 190 | W12: =SUM(G18:G21) -> 2 | X12: =SUM(H18:H21) -> 6 | Y12: =SUM(I18:I21) -> 33 | Z12: =SUM(J18:J21) -> 9 | ... AF12: =SUM(P18:P21) -> 1045
B13: 07.45 - 08.00 | C13: 60 | D13: 19 | E13: 9 | F13: 53 | G13: 0 | H13: 2 | I13: 6 | J13: 2 | K13: 1 | L13: 1 | M13: 115 | N13: 0 | O13: =SUM(C13:L13,N13) -> 153 | P13: =SUM(C13:N13) -> 268 | R13: 1000-1100 | S13: =SUM(C22:C25) -> 276 | T13: =SUM(D22:D25) -> 75 | U13: =SUM(E22:E25) -> 37 | V13: =SUM(F22:F25) -> 231 | W13: =SUM(G22:G25) -> 2 | X13: =SUM(H22:H25) -> 1 | Y13: =SUM(I22:I25) -> 32 | Z13: =SUM(J22:J25) -> 9 | ... AF13: =SUM(P22:P25) -> 1254
B14: 08.00 - 08.15 | C14: 56 | D14: 10 | E14: 4 | F14: 50 | G14: 2 | H14: 1 | I14: 2 | J14: 1 | K14: 0 | L14: 0 | M14: 140 | N14: 0 | O14: =SUM(C14:L14,N14) -> 126 | P14: =SUM(C14:N14) -> 266 | R14: 1100-1200 | S14: =SUM(C26:C29) -> 209 | T14: =SUM(D26:D29) -> 62 | U14: =SUM(E26:E29) -> 44 | V14: =SUM(F26:F29) -> 180 | W14: =SUM(G26:G29) -> 2 | X14: =SUM(H26:H29) -> 1 | Y14: =SUM(I26:I29) -> 31 | Z14: =SUM(J26:J29) -> 4 | ... AF14: =SUM(P26:P29) -> 1023
B15: 08.15 - 08.30 | C15: 89 | D15: 20 | E15: 12 | F15: 105 | G15: 0 | H15: 3 | I15: 58 | J15: 1 | K15: 1 | L15: 2 | M15: 300 | N15: 0 | O15: =SUM(C15:L15,N15) -> 291 | P15: =SUM(C15:N15) -> 591 | R15: 1200-1300 | S15: =SUM(C30:C33) -> 129 | T15: =SUM(D30:D33) -> 50 | U15: =SUM(E30:E33) -> 17 | V15: =SUM(F30:F33) -> 123 | W15: =SUM(G30:G33) -> 4 | X15: =SUM(H30:H33) -> 9 | Y15: =SUM(I30:I33) -> 14 | Z15: =SUM(J30:J33) -> 16 | ... AF15: =SUM(P30:P33) -> 744
B16: 08.30 - 08.45 | C16: 122 | D16: 37 | E16: 17 | F16: 90 | G16: 2 | H16: 1 | I16: 9 | J16: 3 | K16: 1 | L16: 1 | M16: 249 | N16: 0 | O16: =SUM(C16:L16,N16) -> 283 | P16: =SUM(C16:N16) -> 532 | R16: 1300-1400 | S16: =SUM(C34:C37) -> 160 | T16: =SUM(D34:D37) -> 55 | U16: =SUM(E34:E37) -> 27 | V16: =SUM(F34:F37) -> 131 | W16: =SUM(G34:G37) -> 2 | X16: =SUM(H34:H37) -> 13 | Y16: =SUM(I34:I37) -> 25 | Z16: =SUM(J34:J37) -> 16 | ... AF16: =SUM(P34:P37) -> 901
B17: 08.45 - 9.00 | C17: 41 | D17: 14 | E17: 4 | F17: 47 | G17: 2 | H17: 1 | I17: 3 | J17: 1 | K17: 2 | L17: 1 | M17: 105 | N17: 0 | O17: =SUM(C17:L17,N17) -> 116 | P17: =SUM(C17:N17) -> 221 | R17: 1400-1500 | S17: =SUM(C38:C41) -> 157 | T17: =SUM(D38:D41) -> 64 | U17: =SUM(E38:E41) -> 24 | V17: =SUM(F38:F41) -> 156 | W17: =SUM(G38:G41) -> 3 | X17: =SUM(H38:H41) -> 4 | Y17: =SUM(I38:I41) -> 22 | Z17: =SUM(J38:J41) -> 10 | ... AF17: =SUM(P38:P41) -> 794
B18: 09.00 - 09.15 | C18: 62 | D18: 18 | E18: 6 | F18: 58 | G18: 0 | H18: 0 | I18: 4 | J18: 2 | K18: 0 | L18: 0 | M18: 125 | N18: 0 | O18: =SUM(C18:L18,N18) -> 150 | P18: =SUM(C18:N18) -> 275 | R18: 1500-1600 | S18: =SUM(C42:C45) -> 172 | T18: =SUM(D42:D45) -> 54 | U18: =SUM(E42:E45) -> 26 | V18: =SUM(F42:F45) -> 144 | W18: =SUM(G42:G45) -> 1 | X18: =SUM(H42:H45) -> 2 | Y18: =SUM(I42:I45) -> 36 | Z18: =SUM(J42:J45) -> 6 | ... AF18: =SUM(P42:P45) -> 682
B19: 09.15 - 09.30 | C19: 38 | D19: 11 | E19: 2 | F19: 41 | G19: 0 | H19: 1 | I19: 5 | J19: 0 | K19: 0 | L19: 0 | M19: 115 | N19: 0 | O19: =SUM(C19:L19,N19) -> 98 | P19: =SUM(C19:N19) -> 213 | R19: 1600-1700 | S19: =SUM(C46:C49) -> 189 | T19: =SUM(D46:D49) -> 60 | U19: =SUM(E46:E49) -> 34 | V19: =SUM(F46:F49) -> 123 | W19: =SUM(G46:G49) -> 6 | X19: =SUM(H46:H49) -> 3 | Y19: =SUM(I46:I49) -> 35 | Z19: =SUM(J46:J49) -> 9 | ... AF19: =SUM(P46:P49) -> 1025
B20: 09.30 - 09.45 | C20: 28 | D20: 8 | E20: 3 | F20: 35 | G20: 0 | H20: 0 | I20: 5 | J20: 5 | K20: 1 | L20: 0 | M20: 90 | N20: 0 | O20: =SUM(C20:L20,N20) -> 85 | P20: =SUM(C20:N20) -> 175 | R20: 1700-1800 | S20: =SUM(C50:C53) -> 184 | T20: =SUM(D50:D53) -> 67 | U20: =SUM(E50:E53) -> 17 | V20: =SUM(F50:F53) -> 141 | W20: =SUM(G50:G53) -> 6 | X20: =SUM(H50:H53) -> 4 | Y20: =SUM(I50:I53) -> 28 | Z20: =SUM(J50:J53) -> 8 | ... AF20: =SUM(P50:P53) -> 1036
B21: 09.45 - 10.00 | C21: 75 | D21: 19 | E21: 12 | F21: 56 | G21: 2 | H21: 5 | I21: 19 | J21: 2 | K21: 2 | L21: 0 | M21: 190 | N21: 0 | O21: =SUM(C21:L21,N21) -> 192 | P21: =SUM(C21:N21) -> 382 | R21: 1800-1900 | S21: =SUM(C54:C57) -> 142 | T21: =SUM(D54:D57) -> 30 | U21: =SUM(E54:E57) -> 11 | V21: =SUM(F54:F57) -> 106 | W21: =SUM(G54:G57) -> 3 | X21: =SUM(H54:H57) -> 0 | Y21: =SUM(I54:I57) -> 15 | Z21: =SUM(J54:J57) -> 5 | ... AF21: =SUM(P54:P57) -> 870
B22: 10.00 - 10.15 | C22: 93 | D22: 26 | E22: 12 | F22: 79 | G22: 1 | H22: 0 | I22: 9 | J22: 1 | K22: 3 | L22: 1 | M22: 245 | N22: 0 | O22: =SUM(C22:L22,N22) -> 225 | P22: =SUM(C22:N22) -> 470 | R22: AM Peak Hr | S22: =MAX(S10:S12) -> 308 | T22: =MAX(T10:T12) -> 81 | U22: =MAX(U10:U12) -> 37 | V22: =MAX(V10:V12) -> 292 | W22: =MAX(W10:W12) -> 6 | X22: =MAX(X10:X12) -> 6 | Y22: =MAX(Y10:Y12) -> 72 | Z22: =MAX(Z10:Z12) -> 9 | ... AF22: =MAX(AF10:AF12) -> 1610
B23: 10.15 - 10.30 | C23: 75 | D23: 19 | E23: 5 | F23: 46 | G23: 0 | H23: 1 | I23: 10 | J23: 4 | K23: 2 | L23: 0 | M23: 105 | N23: 0 | O23: =SUM(C23:L23,N23) -> 162 | P23: =SUM(C23:N23) -> 267 | R23: IP Peak Hr | S23: =MAX(S13:S18) -> 276 | T23: =MAX(T13:T18) -> 75 | U23: =MAX(U13:U18) -> 44 | V23: =MAX(V13:V18) -> 231 | W23: =MAX(W13:W18) -> 4 | X23: =MAX(X13:X18) -> 13 | Y23: =MAX(Y13:Y18) -> 36 | Z23: =MAX(Z13:Z18) -> 16 | ... AF23: =MAX(AF13:AF18) -> 1254
B24: 10.30 - 10.45 | C24: 53 | D24: 16 | E24: 6 | F24: 59 | G24: 0 | H24: 0 | I24: 4 | J24: 4 | K24: 2 | L24: 0 | M24: 110 | N24: 0 | O24: =SUM(C24:L24,N24) -> 144 | P24: =SUM(C24:N24) -> 254 | R24: PM Peak Hr | S24: =MAX(S19:S21) -> 189 | T24: =MAX(T19:T21) -> 67 | U24: =MAX(U19:U21) -> 34 | V24: =MAX(V19:V21) -> 141 | W24: =MAX(W19:W21) -> 6 | X24: =MAX(X19:X21) -> 4 | Y24: =MAX(Y19:Y21) -> 35 | Z24: =MAX(Z19:Z21) -> 9 | ... AF24: =MAX(AF19:AF21) -> 1036
B25: 10.45 - 11.00 | C25: 55 | D25: 14 | E25: 14 | F25: 47 | G25: 1 | H25: 0 | I25: 9 | J25: 0 | K25: 1 | L25: 2 | M25: 120 | N25: 0 | O25: =SUM(C25:L25,N25) -> 143 | P25: =SUM(C25:N25) -> 263 | R25: AM Period | S25: =SUM(S10:S12) -> 747 | T25: =SUM(T10:T12) -> 211 | U25: =SUM(U10:U12) -> 90 | V25: =SUM(V10:V12) -> 654 | W25: =SUM(W10:W12) -> 14 | X25: =SUM(X10:X12) -> 14 | Y25: =SUM(Y10:Y12) -> 114 | Z25: =SUM(Z10:Z12) -> 18 | ... AF25: =SUM(AF10:AF12) -> 3584
B26: 11.00 - 11.15 | C26: 57 | D26: 21 | E26: 11 | F26: 58 | G26: 0 | H26: 0 | I26: 8 | J26: 1 | K26: 1 | L26: 0 | M26: 117 | N26: 0 | O26: =SUM(C26:L26,N26) -> 157 | P26: =SUM(C26:N26) -> 274 | R26: IP Period | S26: =SUM(S13:S18) -> 1103 | T26: =SUM(T13:T18) -> 360 | U26: =SUM(U13:U18) -> 175 | V26: =SUM(V13:V18) -> 965 | W26: =SUM(W13:W18) -> 14 | X26: =SUM(X13:X18) -> 30 | Y26: =SUM(Y13:Y18) -> 160 | Z26: =SUM(Z13:Z18) -> 61 | ... AF26: =SUM(AF13:AF18) -> 5398
B27: 11.15 - 11.30 | C27: 61 | D27: 14 | E27: 11 | F27: 40 | G27: 1 | H27: 0 | I27: 9 | J27: 0 | K27: 0 | L27: 0 | M27: 119 | N27: 0 | O27: =SUM(C27:L27,N27) -> 136 | P27: =SUM(C27:N27) -> 255 | R27: PM Period | S27: =SUM(S19:S21) -> 515 | T27: =SUM(T19:T21) -> 157 | U27: =SUM(U19:U21) -> 62 | V27: =SUM(V19:V21) -> 370 | W27: =SUM(W19:W21) -> 15 | X27: =SUM(X19:X21) -> 7 | Y27: =SUM(Y19:Y21) -> 78 | Z27: =SUM(Z19:Z21) -> 22 | ... AF27: =SUM(AF19:AF21) -> 2931
B28: 11.30 - 11.45 | C28: 42 | D28: 15 | E28: 12 | F28: 50 | G28: 0 | H28: 0 | I28: 9 | J28: 2 | K28: 2 | L28: 1 | M28: 139 | N28: 0 | O28: =SUM(C28:L28,N28) -> 133 | P28: =SUM(C28:N28) -> 272 | R28: 12 Hours | S28: =SUM(S10:S21) -> 2365 | T28: =SUM(T10:T21) -> 728 | U28: =SUM(U10:U21) -> 327 | V28: =SUM(V10:V21) -> 1989 | W28: =SUM(W10:W21) -> 43 | X28: =SUM(X10:X21) -> 51 | Y28: =SUM(Y10:Y21) -> 352 | Z28: =SUM(Z10:Z21) -> 101 | ... AF28: =SUM(AF10:AF21) -> 11913
B29: 11.45 - 12.00 | C29: 49 | D29: 12 | E29: 10 | F29: 32 | G29: 1 | H29: 1 | I29: 5 | J29: 1 | K29: 1 | L29: 0 | M29: 110 | N29: 0 | O29: =SUM(C29:L29,N29) -> 112 | P29: =SUM(C29:N29) -> 222
B30: 12.00 - 12.15 | C30: 31 | D30: 8 | E30: 7 | F30: 23 | G30: 1 | H30: 4 | I30: 1 | J30: 0 | K30: 2 | L30: 0 | M30: 86 | N30: 0 | O30: =SUM(C30:L30,N30) -> 77 | P30: =SUM(C30:N30) -> 163
B31: 12.15 - 12.30 | C31: 18 | D31: 14 | E31: 1 | F31: 29 | G31: 0 | H31: 0 | I31: 7 | J31: 1 | K31: 0 | L31: 0 | M31: 90 | N31: 0 | O31: =SUM(C31:L31,N31) -> 70 | P31: =SUM(C31:N31) -> 160
B32: 12.30 - 12.45 | C32: 43 | D32: 20 | E32: 5 | F32: 42 | G32: 0 | H32: 4 | I32: 6 | J32: 3 | K32: 1 | L32: 0 | M32: 115 | N32: 0 | O32: =SUM(C32:L32,N32) -> 124 | P32: =SUM(C32:N32) -> 239
B33: 12.45 - 13.00 | C33: 37 | D33: 8 | E33: 4 | F33: 29 | G33: 3 | H33: 1 | I33: 0 | J33: 12 | K33: 1 | L33: 2 | M33: 85 | N33: 0 | O33: =SUM(C33:L33,N33) -> 97 | P33: =SUM(C33:N33) -> 182
B34: 13.00 - 13.15 | C34: 27 | D34: 19 | E34: 4 | F34: 28 | G34: 0 | H34: 1 | I34: 9 | J34: 1 | K34: 0 | L34: 0 | M34: 100 | N34: 0 | O34: =SUM(C34:L34,N34) -> 89 | P34: =SUM(C34:N34) -> 189
B35: 13.15 - 13.30 | C35: 46 | D35: 14 | E35: 8 | F35: 38 | G35: 1 | H35: 9 | I35: 0 | J35: 9 | K35: 1 | L35: 0 | M35: 120 | N35: 0 | O35: =SUM(C35:L35,N35) -> 126 | P35: =SUM(C35:N35) -> 246
B36: 13.30 - 13.45 | C36: 47 | D36: 11 | E36: 9 | F36: 28 | G36: 0 | H36: 0 | I36: 8 | J36: 1 | K36: 0 | L36: 0 | M36: 120 | N36: 0 | O36: =SUM(C36:L36,N36) -> 104 | P36: =SUM(C36:N36) -> 224
B37: 13.45 - 14.00 | C37: 40 | D37: 11 | E37: 6 | F37: 37 | G37: 1 | H37: 3 | I37: 8 | J37: 5 | K37: 5 | L37: 0 | M37: 125 | N37: 1 | O37: =SUM(C37:L37,N37) -> 117 | P37: =SUM(C37:N37) -> 242
B38: 14.00 - 14.15 | C38: 48 | D38: 17 | E38: 5 | F38: 36 | G38: 1 | H38: 1 | I38: 5 | J38: 2 | K38: 0 | L38: 0 | M38: 105 | N38: 0 | O38: =SUM(C38:L38,N38) -> 115 | P38: =SUM(C38:N38) -> 220
B39: 14.15 - 14.30 | C39: 38 | D39: 17 | E39: 12 | F39: 43 | G39: 1 | H39: 2 | I39: 9 | J39: 3 | K39: 1 | L39: 0 | M39: 124 | N39: 0 | O39: =SUM(C39:L39,N39) -> 126 | P39: =SUM(C39:N39) -> 250
B40: 14.30 - 14.45 | C40: 28 | D40: 10 | E40: 1 | F40: 32 | G40: 0 | H40: 0 | I40: 1 | J40: 2 | K40: 0 | L40: 0 | M40: 123 | N40: 0 | O40: =SUM(C40:L40,N40) -> 74 | P40: =SUM(C40:N40) -> 197
... B42: 15.00 - 15.15 | C42: 34 | D42: 11 | E42: 2 | F42: 37 | G42: 0 | H42: 0 | I42: 6 | J42: 2 | K42: 0 | L42: 0 | M42: 91 | N42: 0 | O42: =SUM(C42:L42,N42) -> 92 | P42: =SUM(C42:N42) -> 183
B43: 15.15 - 15.30 | C43: 35 | D43: 14 | E43: 9 | F43: 34 | G43: 1 | H43: 0 | I43: 17 | J43: 1 | K43: 2 | M43: 11 | N43: 0 | O43: =SUM(C43:L43,N43) -> 113 | P43: =SUM(C43:N43) -> 124
...

Sheet 22.07 MAKERERE-BWAISE
B1: Consultancy services for Preparation of Expressway Development Master Plan (EDMP) for Uganda
B2: MANUAL CLASSIFIED COUNT (MCC)
B3: ROAD NAME: | C3: MCC - C1 - STN021- SIR APOLLO ROAD
C5: Date | D5: ='22.07 Bwaise-Makerere'!D5 -> 43668 | F5: Location | G5: PREMIUM DESIGN LTD | J5: Surveyor | K5: OMASET
C6: Dir. From | D6: MAKARERE | F6: Dir. To | G6: BWAISE | J6: Supervisor | K6: ='22.07 Bwaise-Makerere'!K6:L6 -> SALIMAH
B8: Time / Veh Type | R8: SUMMARY TRAFFIC VOLUMES
C9: 1. Car | D9: 2. Station Wagon | E9: 3. Pickups | F9: 4. Minibus, matatu | G9: 5. Medium bus | H9: 6. Large Bus | I9: 7. Light Truck | J9: 8. Medium Truck | K9: 9. Heavy truck | L9: 10. Truck Trailer | M9: 11. Motor cycles | N9: 12. Tractors | O9: Total Excl M/Cycles | P9: Total All | R9: Time | S9: 1. Car | T9: 2. Station Wagon | U9: 3. Pickups | V9: 4. Minibus, matatu | W9: 5. Medium bus | X9: 6. Large Bus | Y9: 7. Light Truck | Z9: 8. Medium Truck | AA9: 9. Heavy truck | AB9: 10. Truck Trailer | AC9: 11. Motorcycles | AD9: 12. Tractors, Graders | AE9: Total Excl M/ Cycles | AF9: Total All
B10: 07.00 - 07.15 | C10: 55 | D10: 10 | E10: 4 | F10: 45 | G10: 0 | H10: 0 | I10: 6 | J10: 3 | K10: 1 | L10: 0 | M10: 115 | N10: 0 | O10: =SUM(C10:L10,N10) -> 124 | P10: =SUM(C10:N10) -> 239 | R10: 0700-0800 | S10: =SUM(C10:C13) -> 128 | T10: =SUM(D10:D13) -> 25 | U10: =SUM(E10:E13) -> 11 | V10: =SUM(F10:F13) -> 142 | W10: =SUM(G10:G13) -> 2 | X10: =SUM(H10:H13) -> 2 | Y10: =SUM(I10:I13) -> 11 | Z10: =SUM(J10:J13) -> 4 | ... AF10: =SUM(P10:P13) -> 1009
B11: 07.15 - 07.30 | C11: 23 | D11: 7 | E11: 4 | F11: 2 | G11: 0 | H11: 1 | I11: 1 | J11: 1 | K11: 1 | L11: 0 | M11: 170 | N11: 0 | O11: =SUM(C11:L11,N11) -> 40 | P11: =SUM(C11:N11) -> 210 | R11: 0800-0900 | S11: =SUM(C14:C17) -> 130 | T11: =SUM(D14:D17) -> 21 | U11: =SUM(E14:E17) -> 7 | V11: =SUM(F14:F17) -> 232 | W11: =SUM(G14:G17) -> 4 | X11: =SUM(H14:H17) -> 2 | Y11: =SUM(I14:I17) -> 15 | Z11: =SUM(J14:J17) -> 6 | ... AF11: =SUM(P14:P17) -> 2188
B12: 07.30 - 07.45 | C12: 25 | D12: 5 | E12: 2 | F12: 55 | G12: 2 | H12: 1 | I12: 1 | J12: 0 | K12: 1 | L12: 0 | M12: 180 | N12: 0 | O12: =SUM(C12:L12,N12) -> 92 | P12: =SUM(C12:N12) -> 272 | R12: 0900-1000 | S12: =SUM(C18:C21) -> 87 | T12: =SUM(D18:D21) -> 27 | U12: =SUM(E18:E21) -> 8 | V12: =SUM(F18:F21) -> 202 | W12: =SUM(G18:G21) -> 5 | X12: =SUM(H18:H21) -> 5 | Y12: =SUM(I18:I21) -> 9 | Z12: =SUM(J18:J21) -> 1 | ... AF12: =SUM(P18:P21) -> 881
B13: 07.45 - 08.00 | C13: 25 | D13: 3 | E13: 1 | F13: 40 | G13: 0 | H13: 0 | I13: 3 | J13: 0 | K13: 1 | L13: 0 | M13: 215 | N13: 0 | O13: =SUM(C13:L13,N13) -> 73 | P13: =SUM(C13:N13) -> 288 | R13: 1000-1100 | S13: =SUM(C22:C25) -> 108 | T13: =SUM(D22:D25) -> 36 | U13: =SUM(E22:E25) -> 13 | V13: =SUM(F22:F25) -> 216 | W13: =SUM(G22:G25) -> 3 | X13: =SUM(H22:H25) -> 7 | Y13: =SUM(I22:I25) -> 14 | Z13: =SUM(J22:J25) -> 14 | ... AF13: =SUM(P22:P25) -> 1240
B14: 08.00 - 08.15 | C14: 24 | D14: 3 | E14: 1 | F14: 45 | G14: 2 | H14: 1 | I14: 0 | J14: 2 | K14: 0 | L14: 1 | M14: 205 | N14: 0 | O14: =SUM(C14:L14,N14) -> 79 | P14: =SUM(C14:N14) -> 284 | R14: 1100-1200 | S14: =SUM(C26:C29) -> 135 | T14: =SUM(D26:D29) -> 22 | U14: =SUM(E26:E29) -> 15 | V14: =SUM(F26:F29) -> 180 | W14: =SUM(G26:G29) -> 2 | X14: =SUM(H26:H29) -> 18 | Y14: =SUM(I26:I29) -> 7 | Z14: =SUM(J26:J29) -> 14 | ... AF14: =SUM(P26:P29) -> 1031
B15: 08.15 - 08.30 | C15: 30 | D15: 8 | E15: 1 | F15: 55 | G15: 1 | H15: 1 | I15: 4 | J15: 0 | K15: 2 | L15: 1 | M15: 200 | N15: 0 | O15: =SUM(C15:L15,N15) -> 103 | P15: =SUM(C15:N15) -> 303 | R15: 1200-1300 | S15: =SUM(C30:C33) -> 122 | T15: =SUM(D30:D33) -> 29 | U15: =SUM(E30:E33) -> 21 | V15: =SUM(F30:F33) -> 124 | W15: =SUM(G30:G33) -> 10 | X15: =SUM(H30:H33) -> 7 | Y15: =SUM(I30:I33) -> 8 | Z15: =SUM(J30:J33) -> 2 | ... AF15: =SUM(P30:P33) -> 784
B16: 08.30 - 08.45 | C16: 40 | D16: 4 | E16: 4 | F16: 65 | G16: 0 | H16: 0 | I16: 8 | J16: 2 | K16: 1 | L16: 0 | M16: 175 | N16: 0 | O16: =SUM(C16:L16,N16) -> 124 | P16: =SUM(C16:N16) -> 299 | R16: 1300-1400 | S16: =SUM(C34:C37) -> 141 | T16: =SUM(D34:D37) -> 29 | U16: =SUM(E34:E37) -> 21 | V16: =SUM(F34:F37) -> 178 | W16: =SUM(G34:G37) -> 1 | X16: =SUM(H34:H37) -> 1 | Y16: =SUM(I34:I37) -> 89 | Z16: =SUM(J34:J37) -> 11 | ... AF16: =SUM(P34:P37) -> 1040
B17: 08.45 - 9.00 | C17: 36 | D17: 6 | E17: 1 | F17: 67 | G17: 1 | H17: 0 | I17: 3 | J17: 2 | K17: 0 | L17: 1 | M17: 1185 | N17: 0 | O17: =SUM(C17:L17,N17) -> 117 | P17: =SUM(C17:N17) -> 1302 | R17: 1400-1500 | S17: =SUM(C38:C41) -> 153 | T17: =SUM(D38:D41) -> 53 | U17: =SUM(E38:E41) -> 51 | V17: =SUM(F38:F41) -> 127 | W17: =SUM(G38:G41) -> 3 | X17: =SUM(H38:H41) -> 10 | Y17: =SUM(I38:I41) -> 13 | Z17: =SUM(J38:J41) -> 5 | ... AF17: =SUM(P38:P41) -> 843
B18: 09.00 - 09.15 | C18: 28 | D18: 9 | E18: 2 | F18: 60 | G18: 1 | H18: 4 | I18: 1 | J18: 0 | K18: 1 | L18: 1 | M18: 175 | N18: 0 | O18: =SUM(C18:L18,N18) -> 107 | P18: =SUM(C18:N18) -> 282 | R18: 1500-1600 | S18: =SUM(C42:C45) -> 180 | T18: =SUM(D42:D45) -> 30 | U18: =SUM(E42:E45) -> 26 | V18: =SUM(F42:F45) -> 108 | W18: =SUM(G42:G45) -> 1 | X18: =SUM(H42:H45) -> 3 | Y18: =SUM(I42:I45) -> 17 | Z18: =SUM(J42:J45) -> 11 | ... AF18: =SUM(P42:P45) -> 614
B19: 09.15 - 09.30 | C19: 23 | D19: 5 | E19: 4 | F19: 40 | G19: 2 | H19: 1 | I19: 3 | J19: 0 | K19: 0 | L19: 0 | M19: 99 | N19: 0 | O19: =SUM(C19:L19,N19) -> 78 | P19: =SUM(C19:N19) -> 177 | R19: 1600-1700 | S19: =SUM(C46:C49) -> 202 | T19: =SUM(D46:D49) -> 56 | U19: =SUM(E46:E49) -> 29 | V19: =SUM(F46:F49) -> 160 | W19: =SUM(G46:G49) -> 2 | X19: =SUM(H46:H49) -> 2 | Y19: =SUM(I46:I49) -> 22 | Z19: =SUM(J46:J49) -> 12 | ... AF19: =SUM(P46:P49) -> 952
B20: 09.30 - 09.45 | C20: 25 | D20: 11 | E20: 2 | F20: 47 | G20: 1 | H20: 0 | I20: 4 | J20: 1 | K20: 0 | L20: 0 | M20: 105 | N20: 0 | O20: =SUM(C20:L20,N20) -> 91 | P20: =SUM(C20:N20) -> 196 | R20: 1700-1800 | S20: =SUM(C50:C53) -> 250 | T20: =SUM(D50:D53) -> 57 | U20: =SUM(E50:E53) -> 29 | V20: =SUM(F50:F53) -> 169 | W20: =SUM(G50:G53) -> 1 | X20: =SUM(H50:H53) -> 0 | Y20: =SUM(I50:I53) -> 29 | Z20: =SUM(J50:J53) -> 9 | ... AF20: =SUM(P50:P53) -> 996
B21: 09.45 - 10.00 | C21: 11 | D21: 2 | E21: 0 | F21: 55 | G21: 1 | H21: 0 | I21: 1 | J21: 0 | K21: 1 | L21: 0 | M21: 155 | N21: 0 | O21: =SUM(C21:L21,N21) -> 71 | P21: =SUM(C21:N21) -> 226 | R21: 1800-1900 | S21: =SUM(C54:C57) -> 221 | T21: =SUM(D54:D57) -> 41 | U21: =SUM(E54:E57) -> 76 | V21: =SUM(F54:F57) -> 138 | W21: =SUM(G54:G57) -> 30 | X21: =SUM(H54:H57) -> 9 | Y21: =SUM(I54:I57) -> 9 | Z21: =SUM(J54:J57) -> 2 | ... AF21: =SUM(P54:P57) -> 940
B22: 10.00 - 10.15 | C22: 22 | D22: 9 | E22: 2 | F22: 63 | G22: 2 | H22: 6 | I22: 0 | J22: 1 | K22: 1 | L22: 0 | M22: 249 | N22: 0 | O22: =SUM(C22:L22,N22) -> 106 | P22: =SUM(C22:N22) -> 355 | R22: AM Peak Hr | S22: =MAX(S10:S12) -> 130 | T22: =MAX(T10:T12) -> 27 | U22: =MAX(U10:U12) -> 11 | V22: =MAX(V10:V12) -> 232 | W22: =MAX(W10:W12) -> 5 | X22: =MAX(X10:X12) -> 5 | Y22: =MAX(Y10:Y12) -> 15 | Z22: =MAX(Z10:Z12) -> 6 | ... AF22: =MAX(AF10:AF12) -> 2188
B23: 10.15 - 10.30 | C23: 28 | D23: 4 | E23: 4 | F23: 51 | G23: 1 | H23: 1 | I23: 1 | J23: 4 | K23: 0 | L23: 3 | M23: 200 | N23: 0 | O23: =SUM(C23:L23,N23) -> 97 | P23: =SUM(C23:N23) -> 297 | R23: IP Peak Hr | S23: =MAX(S13:S18) -> 180 | T23: =MAX(T13:T18) -> 53 | U23: =MAX(U13:U18) -> 51 | V23: =MAX(V13:V18) -> 216 | W23: =MAX(W13:W18) -> 10 | X23: =MAX(X13:X18) -> 18 | Y23: =MAX(Y13:Y18) -> 89 | Z23: =MAX(Z13:Z18) -> 14 | ... AF23: =MAX(AF13:AF18) -> 1240
B24: 10.30 - 10.45 | C24: 27 | D24: 9 | E24: 3 | F24: 49 | G24: 0 | H24: 0 | I24: 9 | J24: 9 | K24: 0 | L24: 1 | M24: 205 | N24: 0 | O24: =SUM(C24:L24,N24) -> 107 | P24: =SUM(C24:N24) -> 312 | R24: PM Peak Hr | S24: =MAX(S19:S21) -> 250 | T24: =MAX(T19:T21) -> 57 | U24: =MAX(U19:U21) -> 76 | V24: =MAX(V19:V21) -> 169 | W24: =MAX(W19:W21) -> 30 | X24: =MAX(X19:X21) -> 9 | Y24: =MAX(Y19:Y21) -> 29 | Z24: =MAX(Z19:Z21) -> 12 | ... AF24: =MAX(AF19:AF21) -> 996
B25: 10.45 - 11.00 | C25: 31 | D25: 14 | E25: 4 | F25: 53 | G25: 0 | H25: 0 | I25: 4 | J25: 0 | K25: 0 | L25: 0 | M25: 170 | N25: 0 | O25: =SUM(C25:L25,N25) -> 106 | P25: =SUM(C25:N25) -> 276 | R25: AM Period | S25: =SUM(S10:S12) -> 345 | T25: =SUM(T10:T12) -> 73 | U25: =SUM(U10:U12) -> 26 | V25: =SUM(V10:V12) -> 576 | W25: =SUM(W10:W12) -> 11 | X25: =SUM(X10:X12) -> 9 | Y25: =SUM(Y10:Y12) -> 35 | Z25: =SUM(Z10:Z12) -> 11 | ... AF25: =SUM(AF10:AF12) -> 4078
B26: 11.00 - 11.15 | C26: 30 | D26: 4 | E26: 5 | F26: 50 | G26: 0 | H26: 9 | I26: 0 | J26: 0 | K26: 0 | L26: 0 | M26: 180 | N26: 0 | O26: =SUM(C26:L26,N26) -> 98 | P26: =SUM(C26:N26) -> 278 | R26: IP Period | S26: =SUM(S13:S18) -> 839 | T26: =SUM(T13:T18) -> 199 | U26: =SUM(U13:U18) -> 147 | V26: =SUM(V13:V18) -> 933 | W26: =SUM(W13:W18) -> 20 | X26: =SUM(X13:X18) -> 46 | Y26: =SUM(Y13:Y18) -> 148 | Z26: =SUM(Z13:Z18) -> 57 | ... AF26: =SUM(AF13:AF18) -> 5552
B27: 11.15 - 11.30 | C27: 25 | D27: 8 | E27: 2 | F27: 44 | G27: 0 | H27: 0 | I27: 1 | J27: 12 | K27: 0 | L27: 0 | M27: 150 | N27: 0 | O27: =SUM(C27:L27,N27) -> 92 | P27: =SUM(C27:N27) -> 242 | R27: PM Period | S27: =SUM(S19:S21) -> 673 | T27: =SUM(T19:T21) -> 154 | U27: =SUM(U19:U21) -> 134 | V27: =SUM(V19:V21) -> 467 | W27: =SUM(W19:W21) -> 33 | X27: =SUM(X19:X21) -> 11 | Y27: =SUM(Y19:Y21) -> 60 | Z27: =SUM(Z19:Z21) -> 23 | ... AF27: =SUM(AF19:AF21) -> 2888
B28: 11.30 - 11.45 | C28: 40 | D28: 6 | E28: 4 | F28: 46 | G28: 2 | H28: 7 | I28: 0 | J28: 2 | K28: 0 | L28: 0 | M28: 153 | N28: 0 | O28: =SUM(C28:L28,N28) -> 107 | P28: =SUM(C28:N28) -> 260 | R28: 12 Hours | S28: =SUM(S10:S21) -> 1857 | T28: =SUM(T10:T21) -> 426 | U28: =SUM(U10:U21) -> 307 | V28: =SUM(V10:V21) -> 1976 | W28: =SUM(W10:W21) -> 64 | X28: =SUM(X10:X21) -> 66 | Y28: =SUM(Y10:Y21) -> 243 | Z28: =SUM(Z10:Z21) -> 91 | ... AF28: =SUM(AF10:AF21) -> 12518
B29: 11.45 - 12.00 | C29: 40 | D29: 4 | E29: 4 | F29: 40 | G29: 0 | H29: 2 | I29: 6 | J29: 0 | K29: 2 | L29: 0 | M29: 153 | N29: 0 | O29: =SUM(C29:L29,N29) -> 98 | P29: =SUM(C29:N29) -> 251
B30: 12.00 - 12.15 | C30: 17 | D30: 2 | E30: 1 | F30: 45 | G30: 1 | H30: 4 | I30: 2 | J30: 0 | K30: 1 | L30: 0 | M30: 95 | N30: 0 | O30: =SUM(C30:L30,N30) -> 73 | P30: =SUM(C30:N30) -> 168
B31: 12.15 - 12.30 | C31: 20 | D31: 10 | E31: 11 | F31: 38 | G31: 0 | H31: 0 | I31: 2 | J31: 2 | K31: 2 | L31: 0 | M31: 91 | N31: 0 | O31: =SUM(C31:L31,N31) -> 85 | P31: =SUM(C31:N31) -> 176
B32: 12.30 - 12.45 | C32: 50 | D32: 10 | E32: 4 | F32: 40 | G32: 1 | H32: 1 | I32: 4 | J32: 0 | K32: 0 | L32: 0 | M32: 145 | N32: 0 | O32: =SUM(C32:L32,N32) -> 110 | P32: =SUM(C32:N32) -> 255
B33: 12.45 - 13.00 | C33: 35 | D33: 7 | E33: 5 | F33: 1 | G33: 8 | H33: 2 | I33: 0 | J33: 0 | K33: 0 | L33: 0 | M33: 127 | N33: 0 | O33: =SUM(C33:L33,N33) -> 58 | P33: =SUM(C33:N33) -> 185
B34: 13.00 - 13.15 | C34: 36 | D34: 9 | E34: 7 | F34: 33 | G34: 0 | H34: 1 | I34: 65 | J34: 1 | K34: 2 | L34: 0 | M34: 160 | N34: 0 | O34: =SUM(C34:L34,N34) -> 154 | P34: =SUM(C34:N34) -> 314
B35: 13.15 - 13.30 | C35: 40 | D35: 9 | E35: 5 | F35: 63 | G35: 0 | H35: 0 | I35: 10 | J35: 2 | K35: 3 | L35: 0 | M35: 130 | N35: 0 | O35: =SUM(C35:L35,N35) -> 132 | P35: =SUM(C35:N35) -> 262
B36: 13.30 - 13.45 | C36: 40 | D36: 4 | E36: 4 | F36: 39 | G36: 0 | H36: 0 | I36: 4 | J36: 4 | K36: 1 | L36: 0 | M36: 116 | N36: 0 | O36: =SUM(C36:L36,N36) -> 96 | P36: =SUM(C36:N36) -> 212
B37: 13.45 - 14.00 | C37: 25 | D37: 7 | E37: 5 | F37: 43 | G37: 1 | H37: 0 | I37: 10 | J37: 4 | K37: 0 | L37: 0 | M37: 157 | N37: 0 | O37: =SUM(C37:L37,N37) -> 95 | P37: =SUM(C37:N37) -> 252
B38: 14.00 - 14.15 | C38: 35 | D38: 10 | E38: 42 | F38: 0 | G38: 0 | H38: 7 | I38: 3 | J38: 0 | K38: 1 | L38: 0 | M38: 133 | N38: 0 | O38: =SUM(C38:L38,N38) -> 98 | P38: =SUM(C38:N38) -> 231
B39: 14.15 - 14.30 | C39: 47 | D39: 20 | E39: 3 | F39: 37 | G39: 0 | H39: 1 | I39: 2 | J39: 1 | K39: 0 | L39: 0 | M39: 153 | N39: 0 | O39: =SUM(C39:L39,N39) -> 111 | P39: =SUM(C39:N39) -> 264
B40: 14.30 - 14.45 | C40: 35 | D40: 9 | E40: 3 | F40: 39 | G40: 1 | H40: 2 | I40: 4 | J40: 4 | K40: 1 | L40: 0 | M40: 122 | N40: 0 | O40: =SUM(C40:L40,N40) -> 98 | P40: =SUM(C40:N40) -> 220
B41: 14.45 - 15.00 | C41: 36 | D41: 14 | E41: 3 | F41: 51 | G41: 2 | H41: 0 | I41: 4 | J41: 0 | K41: 1 | M41: 16 | N41: 1 | O41: =SUM(C41:L41,N41) -> 112 | P41: =SUM(C41:N41) -> 128
B42: 15.00 - 15.15 | C42: 61 | D42: 12 | E42: 8 | F42: 27 | G42: 0 | H42: 1 | I42: 2 | J42: 4 | K42: 2 | L42: 1 | M42: 7 | N42: 0 | O42: =SUM(C42:L42,N42) -> 118 | P42: =SUM(C42:N42) -> 125
...

Sheet 23.07 BWAISE-MAKERERE
B1: Consultancy services for Preparation of Expressway Development Master Plan (EDMP) for Uganda
B2: MANUAL CLASSIFIED COUNT (MCC)
B3: ROAD NAME: | C3: MCC-C1-STNO21 SIR APOLLO ROAD
C5: Date | D5: 23.07.19 | F5: Location | G5: PREMIUM DESIGN LTD | J5: Surveyor | K5: OKELLO PETER
C6: Dir. From | D6: BWAISE | F6: Dir. To | G6: MAKERERE | J6: Supervisor | K6: ='22.07 Bwaise-Makerere'!K6:L6 -> SALIMAH
B8: Time / Veh Type | R8: SUMMARY TRAFFIC VOLUMES
C9: 1. Car | D9: 2. Station Wagon | E9: 3. Pickups | F9: 4. Minibus, matatu | G9: 5. Medium bus | H9: 6. Large Bus | I9: 7. Light Truck | J9: 8. Medium Truck | K9: 9. Heavy truck | L9: 10. Truck Trailer | M9: 11. Motor cycles | N9: 12. Tractors | O9: Total Excl M/Cycles | P9: Total All | R9: Time | S9: 1. Car | T9: 2. Station Wagon | U9: 3. Pickups | V9: 4. Minibus, matatu | W9: 5. Medium bus | X9: 6. Large Bus | Y9: 7. Light Truck | Z9: 8. Medium Truck | AA9: 9. Heavy truck | AB9: 10. Truck Trailer | AC9: 11. Motorcycles | AD9: 12. Tractors, Graders | AE9: Total Excl M/ Cycles | AF9: Total All
B10: 07.00 - 07.15 | C10: 82 | D10: 29 | E10: 4 | F10: 55 | G10: 2 | H10: 0 | I10: 2 | J10: 1 | K10: 1 | L10: 0 | M10: 155 | N10: 0 | O10: =SUM(C10:L10,N10) -> 176 | P10: =SUM(C10:N10) -> 331 | R10: 0700-0800 | S10: =SUM(C10:C13) -> 277 | T10: =SUM(D10:D13) -> 94 | U10: =SUM(E10:E13) -> 20 | V10: =SUM(F10:F13) -> 259 | W10: =SUM(G10:G13) -> 8 | X10: =SUM(H10:H13) -> 0 | Y10: =SUM(I10:I13) -> 10 | Z10: =SUM(J10:J13) -> 4 | ... AF10: =SUM(P10:P13) -> 1663
B11: 07.15 - 07.30 | C11: 78 | D11: 25 | E11: 5 | F11: 79 | G11: 2 | H11: 0 | I11: 3 | J11: 1 | K11: 2 | L11: 3 | M11: 270 | N11: 0 | O11: =SUM(C11:L11,N11) -> 198 | P11: =SUM(C11:N11) -> 468 | R11: 0800-0900 | S11: =SUM(C14:C17) -> 252 | T11: =SUM(D14:D17) -> 71 | U11: =SUM(E14:E17) -> 26 | V11: =SUM(F14:F17) -> 266 | W11: =SUM(G14:G17) -> 9 | X11: =SUM(H14:H17) -> 3 | Y11: =SUM(I14:I17) -> 16 | Z11: =SUM(J14:J17) -> 5 | ... AF11: =SUM(P14:P17) -> 1762
B12: 07.30 - 07.45 | C12: 67 | D12: 23 | E12: 4 | F12: 60 | G12: 3 | H12: 0 | I12: 2 | J12: 1 | K12: 0 | L12: 0 | M12: 265 | N12: 0 | O12: =SUM(C12:L12,N12) -> 160 | P12: =SUM(C12:N12) -> 425 | R12: 0900-1000 | S12: =SUM(C18:C21) -> 262 | T12: =SUM(D18:D21) -> 67 | U12: =SUM(E18:E21) -> 19 | V12: =SUM(F18:F21) -> 202 | W12: =SUM(G18:G21) -> 3 | X12: =SUM(H18:H21) -> 5 | Y12: =SUM(I18:I21) -> 31 | Z12: =SUM(J18:J21) -> 9 | ... AF12: =SUM(P18:P21) -> 1617
B13: 07.45 - 08.00 | C13: 50 | D13: 17 | E13: 7 | F13: 65 | G13: 1 | H13: 0 | I13: 3 | J13: 1 | K13: 0 | L13: 0 | M13: 295 | N13: 0 | O13: =SUM(C13:L13,N13) -> 144 | P13: =SUM(C13:N13) -> 439 | R13: 1000-1100 | S13: =SUM(C22:C25) -> 261 | T13: =SUM(D22:D25) -> 82 | U13: =SUM(E22:E25) -> 28 | V13: =SUM(F22:F25) -> 196 | W13: =SUM(G22:G25) -> 6 | X13: =SUM(H22:H25) -> 2 | Y13: =SUM(I22:I25) -> 30 | Z13: =SUM(J22:J25) -> 18 | ... AF13: =SUM(P22:P25) -> 1434
B14: 08.00 - 08.15 | C14: 56 | D14: 19 | E14: 8 | F14: 61 | G14: 3 | H14: 0 | I14: 3 | J14: 2 | K14: 1 | L14: 0 | M14: 260 | N14: 0 | O14: =SUM(C14:L14,N14) -> 153 | P14: =SUM(C14:N14) -> 413 | R14: 1100-1200 | S14: =SUM(C26:C29) -> 183 | T14: =SUM(D26:D29) -> 74 | U14: =SUM(E26:E29) -> 19 | V14: =SUM(F26:F29) -> 144 | W14: =SUM(G26:G29) -> 4 | X14: =SUM(H26:H29) -> 1 | Y14: =SUM(I26:I29) -> 20 | Z14: =SUM(J26:J29) -> 9 | ... AF14: =SUM(P26:P29) -> 1056
B15: 08.15 - 08.30 | C15: 57 | D15: 19 | E15: 3 | F15: 67 | G15: 1 | H15: 0 | I15: 3 | J15: 1 | K15: 4 | L15: 1 | M15: 260 | N15: 0 | O15: =SUM(C15:L15,N15) -> 156 | P15: =SUM(C15:N15) -> 416 | R15: 1200-1300 | S15: =SUM(C30:C33) -> 223 | T15: =SUM(D30:D33) -> 56 | U15: =SUM(E30:E33) -> 90 | V15: =SUM(F30:F33) -> 160 | W15: =SUM(G30:G33) -> 8 | X15: =SUM(H30:H33) -> 2 | Y15: =SUM(I30:I33) -> 36 | Z15: =SUM(J30:J33) -> 20 | ... AF15: =SUM(P30:P33) -> 1351
B16: 08.30 - 08.45 | C16: 75 | D16: 14 | E16: 9 | F16: 59 | G16: 2 | H16: 2 | I16: 7 | J16: 1 | K16: 2 | L16: 2 | M16: 280 | N16: 0 | O16: =SUM(C16:L16,N16) -> 173 | P16: =SUM(C16:N16) -> 453 | R16: 1300-1400 | S16: =SUM(C34:C37) -> 194 | T16: =SUM(D34:D37) -> 68 | U16: =SUM(E34:E37) -> 20 | V16: =SUM(F34:F37) -> 144 | W16: =SUM(G34:G37) -> 2 | X16: =SUM(H34:H37) -> 9 | Y16: =SUM(I34:I37) -> 54 | Z16: =SUM(J34:J37) -> 14 | ... AF16: =SUM(P34:P37) -> 956
B17: 08.45 - 9.00 | C17: 64 | D17: 19 | E17: 6 | F17: 79 | G17: 3 | H17: 1 | I17: 3 | J17: 1 | K17: 3 | L17: 1 | M17: 300 | N17: 0 | O17: =SUM(C17:L17,N17) -> 180 | P17: =SUM(C17:N17) -> 480 | R17: 1400-1500 | S17: =SUM(C38:C41) -> 144 | T17: =SUM(D38:D41) -> 67 | U17: =SUM(E38:E41) -> 23 | V17: =SUM(F38:F41) -> 127 | W17: =SUM(G38:G41) -> 5 | X17: =SUM(H38:H41) -> 7 | Y17: =SUM(I38:I41) -> 49 | Z17: =SUM(J38:J41) -> 16 | ... AF17: =SUM(P38:P41) -> 945
B18: 09.00 - 09.15 | C18: 85 | D18: 14 | E18: 5 | F18: 65 | G18: 1 | H18: 0 | I18: 12 | J18: 1 | K18: 1 | L18: 0 | M18: 295 | N18: 0 | O18: =SUM(C18:L18,N18) -> 184 | P18: =SUM(C18:N18) -> 479 | R18: 1500-1600 | S18: =SUM(C42:C45) -> 171 | T18: =SUM(D42:D45) -> 58 | U18: =SUM(E42:E45) -> 27 | V18: =SUM(F42:F45) -> 136 | W18: =SUM(G42:G45) -> 0 | X18: =SUM(H42:H45) -> 5 | Y18: =SUM(I42:I45) -> 34 | Z18: =SUM(J42:J45) -> 14 | ... AF18: =SUM(P42:P45) -> 968
B19: 09.15 - 09.30 | C19: 50 | D19: 21 | E19: 4 | F19: 40 | G19: 0 | H19: 2 | I19: 5 | J19: 2 | K19: 0 | L19: 0 | M19: 295 | N19: 0 | O19: =SUM(C19:L19,N19) -> 124 | P19: =SUM(C19:N19) -> 419 | R19: 1600-1700 | S19: =SUM(C46:C49) -> 199 | T19: =SUM(D46:D49) -> 73 | U19: =SUM(E46:E49) -> 29 | V19: =SUM(F46:F49) -> 128 | W19: =SUM(G46:G49) -> 3 | X19: =SUM(H46:H49) -> 2 | Y19: =SUM(I46:I49) -> 37 | Z19: =SUM(J46:J49) -> 15 | ... AF19: =SUM(P46:P49) -> 1006
B20: 09.30 - 09.45 | C20: 70 | D20: 17 | E20: 8 | F20: 60 | G20: 1 | H20: 1 | I20: 7 | J20: 3 | K20: 4 | L20: 3 | M20: 220 | N20: 0 | O20: =SUM(C20:L20,N20) -> 174 | P20: =SUM(C20:N20) -> 394 | R20: 1700-1800 | S20: =SUM(C50:C53) -> 173 | T20: =SUM(D50:D53) -> 58 | U20: =SUM(E50:E53) -> 24 | V20: =SUM(F50:F53) -> 157 | W20: =SUM(G50:G53) -> 3 | X20: =SUM(H50:H53) -> 1 | Y20: =SUM(I50:I53) -> 33 | Z20: =SUM(J50:J53) -> 12 | ... AF20: =SUM(P50:P53) -> 1044
B21: 09.45 - 10.00 | C21: 57 | D21: 15 | E21: 2 | F21: 37 | G21: 1 | H21: 2 | I21: 7 | J21: 3 | K21: 5 | L21: 1 | M21: 195 | N21: 0 | O21: =SUM(C21:L21,N21) -> 130 | P21: =SUM(C21:N21) -> 325 | R21: 1800-1900 | S21: =SUM(C54:C57) -> 101 | T21: =SUM(D54:D57) -> 35 | U21: =SUM(E54:E57) -> 17 | V21: =SUM(F54:F57) -> 99 | W21: =SUM(G54:G57) -> 7 | X21: =SUM(H54:H57) -> 3 | Y21: =SUM(I54:I57) -> 19 | Z21: =SUM(J54:J57) -> 3 | ... AF21: =SUM(P54:P57) -> 790
B22: 10.00 - 10.15 | C22: 64 | D22: 16 | E22: 10 | F22: 46 | G22: 4 | H22: 0 | I22: 6 | J22: 5 | K22: 0 | L22: 0 | M22: 240 | N22: 0 | O22: =SUM(C22:L22,N22) -> 151 | P22: =SUM(C22:N22) -> 391 | R22: AM Peak Hr | S22: =MAX(S10:S12) -> 277 | T22: =MAX(T10:T12) -> 94 | U22: =MAX(U10:U12) -> 26 | V22: =MAX(V10:V12) -> 266 | W22: =MAX(W10:W12) -> 9 | X22: =MAX(X10:X12) -> 5 | Y22: =MAX(Y10:Y12) -> 31 | Z22: =MAX(Z10:Z12) -> 9 | ... AF22: =MAX(AF10:AF12) -> 1762
B23: 10.15 - 10.30 | C23: 64 | D23: 20 | E23: 5 | F23: 49 | G23: 0 | H23: 1 | I23: 5 | J23: 4 | K23: 4 | L23: 1 | M23: 225 | N23: 0 | O23: =SUM(C23:L23,N23) -> 153 | P23: =SUM(C23:N23) -> 378 | R23: IP Peak Hr | S23: =MAX(S13:S18) -> 261 | T23: =MAX(T13:T18) -> 82 | U23: =MAX(U13:U18) -> 90 | V23: =MAX(V13:V18) -> 196 | W23: =MAX(W13:W18) -> 8 | X23: =MAX(X13:X18) -> 9 | Y23: =MAX(Y13:Y18) -> 54 | Z23: =MAX(Z13:Z18) -> 20 | ... AF23: =MAX(AF13:AF18) -> 1434
B24: 10.30 - 10.45 | C24: 78 | D24: 24 | E24: 9 | F24: 56 | G24: 2 | H24: 1 | I24: 11 | J24: 5 | K24: 4 | L24: 1 | M24: 164 | N24: 0 | O24: =SUM(C24:L24,N24) -> 191 | P24: =SUM(C24:N24) -> 355 | R24: PM Peak Hr | S24: =MAX(S19:S21) -> 199 | T24: =MAX(T19:T21) -> 73 | U24: =MAX(U19:U21) -> 29 | V24: =MAX(V19:V21) -> 157 | W24: =MAX(W19:W21) -> 7 | X24: =MAX(X19:X21) -> 3 | Y24: =MAX(Y19:Y21) -> 37 | Z24: =MAX(Z19:Z21) -> 15 | ... AF24: =MAX(AF19:AF21) -> 1044
B25: 10.45 - 11.00 | C25: 55 | D25: 22 | E25: 4 | F25: 45 | G25: 0 | H25: 0 | I25: 8 | J25: 4 | K25: 5 | L25: 0 | M25: 167 | N25: 0 | O25: =SUM(C25:L25,N25) -> 143 | P25: =SUM(C25:N25) -> 310 | R25: AM Period | S25: =SUM(S10:S12) -> 791 | T25: =SUM(T10:T12) -> 232 | U25: =SUM(U10:U12) -> 65 | V25: =SUM(V10:V12) -> 727 | W25: =SUM(W10:W12) -> 20 | X25: =SUM(X10:X12) -> 8 | Y25: =SUM(Y10:Y12) -> 57 | Z25: =SUM(Z10:Z12) -> 18 | ... AF25: =SUM(AF10:AF12) -> 5042
B26: 11.00 - 11.15 | C26: 36 | D26: 18 | E26: 4 | F26: 33 | G26: 3 | H26: 0 | I26: 9 | J26: 5 | K26: 7 | L26: 1 | M26: 128 | N26: 0 | O26: =SUM(C26:L26,N26) -> 116 | P26: =SUM(C26:N26) -> 244 | R26: IP Period | S26: =SUM(S13:S18) -> 1176 | T26: =SUM(T13:T18) -> 405 | U26: =SUM(U13:U18) -> 207 | V26: =SUM(V13:V18) -> 907 | W26: =SUM(W13:W18) -> 25 | X26: =SUM(X13:X18) -> 26 | Y26: =SUM(Y13:Y18) -> 223 | Z26: =SUM(Z13:Z18) -> 91 | ... AF26: =SUM(AF13:AF18) -> 6710
B27: 11.15 - 11.30 | C27: 59 | D27: 21 | E27: 8 | F27: 43 | G27: 1 | H27: 1 | I27: 0 | J27: 1 | K27: 0 | L27: 2 | M27: 183 | N27: 1 | O27: =SUM(C27:L27,N27) -> 137 | P27: =SUM(C27:N27) -> 320 | R27: PM Period | S27: =SUM(S19:S21) -> 473 | T27: =SUM(T19:T21) -> 166 | U27: =SUM(U19:U21) -> 70 | V27: =SUM(V19:V21) -> 384 | W27: =SUM(W19:W21) -> 13 | X27: =SUM(X19:X21) -> 6 | Y27: =SUM(Y19:Y21) -> 89 | Z27: =SUM(Z19:Z21) -> 30 | ... AF27: =SUM(AF19:AF21) -> 2840
B28: 11.30 - 11.45 | C28: 43 | D28: 14 | E28: 4 | F28: 35 | G28: 0 | H28: 0 | I28: 3 | J28: 1 | K28: 0 | L28: 2 | M28: 155 | N28: 0 | O28: =SUM(C28:L28,N28) -> 102 | P28: =SUM(C28:N28) -> 257 | R28: 12 Hours | S28: =SUM(S10:S21) -> 2440 | T28: =SUM(T10:T21) -> 803 | U28: =SUM(U10:U21) -> 342 | V28: =SUM(V10:V21) -> 2018 | W28: =SUM(W10:W21) -> 58 | X28: =SUM(X10:X21) -> 40 | Y28: =SUM(Y10:Y21) -> 369 | Z28: =SUM(Z10:Z21) -> 139 | ... AF28: =SUM(AF10:AF21) -> 14592
B29: 11.45 - 12.00 | C29: 45 | D29: 21 | E29: 3 | F29: 33 | G29: 0 | H29: 0 | I29: 8 | J29: 2 | K29: 0 | L29: 0 | M29: 123 | N29: 0 | O29: =SUM(C29:L29,N29) -> 112 | P29: =SUM(C29:N29) -> 235
B30: 12.00 - 12.15 | C30: 39 | D30: 10 | E30: 14 | F30: 39 | G30: 1 | H30: 1 | I30: 7 | J30: 6 | K30: 1 | L30: 0 | M30: 170 | N30: 0 | O30: =SUM(C30:L30,N30) -> 118 | P30: =SUM(C30:N30) -> 288
B31: 12.15 - 12.30 | C31: 63 | D31: 15 | E31: 11 | F31: 40 | G31: 4 | H31: 0 | I31: 10 | J31: 0 | K31: 3 | L31: 0 | M31: 210 | N31: 0 | O31: =SUM(C31:L31,N31) -> 146 | P31: =SUM(C31:N31) -> 356
B32: 12.30 - 12.45 | C32: 72 | D32: 20 | E32: 60 | F32: 43 | G32: 3 | H32: 0 | I32: 2 | J32: 10 | K32: 4 | L32: 0 | M32: 191 | N32: 0 | O32: =SUM(C32:L32,N32) -> 214 | P32: =SUM(C32:N32) -> 405
B33: 12.45 - 13.00 | C33: 49 | D33: 11 | E33: 5 | F33: 38 | G33: 0 | H33: 1 | I33: 17 | J33: 4 | K33: 4 | L33: 3 | M33: 170 | N33: 0 | O33: =SUM(C33:L33,N33) -> 132 | P33: =SUM(C33:N33) -> 302
B34: 13.00 - 13.15 | C34: 49 | D34: 12 | E34: 2 | F34: 30 | G34: 0 | H34: 4 | I34: 8 | J34: 2 | K34: 5 | L34: 3 | M34: 120 | N34: 0 | O34: =SUM(C34:L34,N34) -> 115 | P34: =SUM(C34:N34) -> 235
B35: 13.15 - 13.30 | C35: 31 | D35: 16 | E35: 9 | F35: 25 | G35: 1 | H35: 2 | I35: 16 | J35: 5 | K35: 1 | L35: 0 | M35: 135 | N35: 0 | O35: =SUM(C35:L35,N35) -> 106 | P35: =SUM(C35:N35) -> 241
B36: 13.30 - 13.45 | C36: 68 | D36: 18 | E36: 5 | F36: 42 | G36: 1 | H36: 2 | I36: 16 | J36: 5 | K36: 1 | L36: 0 | M36: 134 | N36: 0 | O36: =SUM(C36:L36,N36) -> 158 | P36: =SUM(C36:N36) -> 292
B37: 13.45 - 14.00 | C37: 46 | D37: 22 | E37: 4 | F37: 47 | G37: 0 | H37: 1 | I37: 14 | J37: 2 | K37: 3 | L37: 1 | M37: 48 | N37: 0 | O37: =SUM(C37:L37,N37) -> 140 | P37: =SUM(C37:N37) -> 188
B38: 14.00 - 14.15 | C38: 36 | D38: 4 | E38: 9 | F38: 30 | G38: 1 | H38: 1 | I38: 6 | J38: 1 | K38: 1 | L38: 2 | M38: 85 | N38: 0 | O38: =SUM(C38:L38,N38) -> 91 | P38: =SUM(C38:N38) -> 176
B39: 14.15 - 14.30 | C39: 34 | D39: 20 | E39: 0 | F39: 25 | G39: 1 | H39: 1 | I39: 17 | J39: 2 | K39: 1 | L39: 0 | M39: 103 | N39: 0 | O39: =SUM(C39:L39,N39) -> 101 | P39: =SUM(C39:N39) -> 204
B40: 14.30 - 14.45 | C40: 26 | D40: 12 | E40: 4 | F40: 24 | G40: 0 | H40: 2 | I40: 10 | J40: 6 | K40: 0 | L40: 1 | M40: 132 | N40: 0 | O40: =SUM(C40:L40,N40) -> 85 | P40: =SUM(C40:N40) -> 217
... B57: 18.45 - 19.00 | C57: 14 | D57: 3 | E57: 1 | F57: 13 | G57: 0 | H57: 0 | I57: 1 | J57: 1 | K57: 1 | L57: 0 | M57: 135 | N57: 0 | O57: =SUM(C57:L57,N57) -> 34 | P57: =SUM(C57:N57) -> 169
B58: Totals | C58: =SUM(C10:C57) -> 2440 | N58: =SUM(N10:N57) -> 1 | O58: =SUM(O10:O57) -> 6344 | P58: =SUM(P10:P57) -> 14592
...

Sheet 23.07 Makerere-Bwaise
B1: Consultancy services for Preparation of Expressway Development Master Plan (EDMP) for Uganda
B2: MANUAL CLASSIFIED COUNT (MCC)
B3: ROAD NAME: | C3: ='22.07 MAKERERE-BWAISE'!C3:G3 -> MCC - C1 - STN021- SIR APOLLO ROAD
C5: Date | D5: ='23.07 BWAISE-MAKERERE'!D5 -> 23.07.19 | F5: Location | G5: ='22.07 Bwaise-Makerere'!G5:H5 -> SAHSEN PLAZA | J5: Surveyor | K5: ANTHONY
C6: Dir. From | D6: ='22.07 MAKERERE-BWAISE'!D6:E6 -> MAKARERE | F6: Dir. To | G6: ='22.07 MAKERERE-BWAISE'!G6:H6 -> BWAISE | J6: Supervisor | K6: ='22.07 Bwaise-Makerere'!K6:L6 -> SALIMAH
B8: Time / Veh Type | R8: SUMMARY TRAFFIC VOLUMES
C9: 1. Car | D9: 2. Station Wagon | E9: 3. Pickups | F9: 4. Minibus, matatu | G9: 5. Medium bus | H9: 6. Large Bus | I9: 7. Light Truck | J9: 8. Medium Truck | K9: 9. Heavy truck | L9: 10. Truck Trailer | M9: 11. Motor cycles | N9: 12. Tractors | O9: Total Excl M/Cycles | P9: Total All | R9: Time | S9: 1. Car | T9: 2. Station Wagon | U9: 3. Pickups | V9: 4. Minibus, matatu | W9: 5. Medium bus | X9: 6. Large Bus | Y9: 7. Light Truck | Z9: 8. Medium Truck | AA9: 9. Heavy truck | AB9: 10. Truck Trailer | AC9: 11. Motorcycles | AD9: 12. Tractors, Graders | AE9: Total Excl M/ Cycles | AF9: Total All
B10: 07.00 - 07.15 | C10: 27 | D10: 6 | E10: 3 | F10: 37 | G10: 4 | H10: 1 | I10: 2 | J10: 2 | K10: 1 | L10: 0 | M10: 83 | N10: 0 | O10: =SUM(C10:L10,N10) -> 83 | P10: =SUM(C10:N10) -> 166 | R10: 0700-0800 | S10: =SUM(C10:C13) -> 115 | T10: =SUM(D10:D13) -> 20 | U10: =SUM(E10:E13) -> 10 | V10: =SUM(F10:F13) -> 155 | W10: =SUM(G10:G13) -> 8 | X10: =SUM(H10:H13) -> 4 | Y10: =SUM(I10:I13) -> 9 | Z10: =SUM(J10:J13) -> 8 | ... AF10: =SUM(P10:P13) -> 842
B11: 07.15 - 07.30 | C11: 40 | D11: 3 | E11: 2 | F11: 42 | G11: 3 | H11: 3 | I11: 2 | J11: 4 | K11: 0 | L11: 0 | M11: 135 | N11: 0 | O11: =SUM(C11:L11,N11) -> 99 | P11: =SUM(C11:N11) -> 234 | R11: 0800-0900 | S11: =SUM(C14:C17) -> 109 | T11: =SUM(D14:D17) -> 25 | U11: =SUM(E14:E17) -> 9 | V11: =SUM(F14:F17) -> 136 | W11: =SUM(G14:G17) -> 4 | X11: =SUM(H14:H17) -> 59 | Y11: =SUM(I14:I17) -> 5 | Z11: =SUM(J14:J17) -> 6 | ... AF11: =SUM(P14:P17) -> 1117
B12: 07.30 - 07.45 | C12: 29 | D12: 8 | E12: 3 | F12: 51 | G12: 1 | H12: 0 | I12: 3 | J12: 2 | K12: 1 | L12: 1 | M12: 160 | N12: 0 | O12: =SUM(C12:L12,N12) -> 99 | P12: =SUM(C12:N12) -> 259 | R12: 0900-1000 | S12: =SUM(C18:C21) -> 115 | T12: =SUM(D18:D21) -> 20 | U12: =SUM(E18:E21) -> 14 | V12: =SUM(F18:F21) -> 714 | W12: =SUM(G18:G21) -> 36 | X12: =SUM(H18:H21) -> 2 | Y12: =SUM(I18:I21) -> 14 | Z12: =SUM(J18:J21) -> 8 | ... AF12: =SUM(P18:P21) -> 1669
B13: 07.45 - 08.00 | C13: 19 | D13: 3 | E13: 2 | F13: 25 | G13: 0 | H13: 0 | I13: 2 | J13: 0 | K13: 0 | L13: 1 | M13: 131 | N13: 0 | O13: =SUM(C13:L13,N13) -> 52 | P13: =SUM(C13:N13) -> 183 | R13: 1000-1100 | S13: =SUM(C22:C25) -> 105 | T13: =SUM(D22:D25) -> 21 | U13: =SUM(E22:E25) -> 18 | V13: =SUM(F22:F25) -> 165 | W13: =SUM(G22:G25) -> 1 | X13: =SUM(H22:H25) -> 1 | Y13: =SUM(I22:I25) -> 10 | Z13: =SUM(J22:J25) -> 15 | ... AF13: =SUM(P22:P25) -> 1030
B14: 08.00 - 08.15 | C14: 30 | D14: 8 | E14: 3 | F14: 43 | G14: 0 | H14: 1 | I14: 2 | J14: 3 | K14: 0 | L14: 1 | M14: 190 | N14: 0 | O14: =SUM(C14:L14,N14) -> 91 | P14: =SUM(C14:N14) -> 281 | R14: 1100-1200 | S14: =SUM(C26:C29) -> 125 | T14: =SUM(D26:D29) -> 35 | U14: =SUM(E26:E29) -> 17 | V14: =SUM(F26:F29) -> 168 | W14: =SUM(G26:G29) -> 0 | X14: =SUM(H26:H29) -> 5 | Y14: =SUM(I26:I29) -> 17 | Z14: =SUM(J26:J29) -> 14 | ... AF14: =SUM(P26:P29) -> 937
B15: 08.15 - 08.30 | C15: 41 | D15: 6 | E15: 1 | F15: 56 | G15: 2 | H15: 2 | I15: 1 | J15: 1 | K15: 0 | L15: 1 | M15: 163 | N15: 0 | O15: =SUM(C15:L15,N15) -> 111 | P15: =SUM(C15:N15) -> 274 | R15: 1200-1300 | S15: =SUM(C30:C33) -> 145 | T15: =SUM(D30:D33) -> 40 | U15: =SUM(E30:E33) -> 20 | V15: =SUM(F30:F33) -> 162 | W15: =SUM(G30:G33) -> 5 | X15: =SUM(H30:H33) -> 3 | Y15: =SUM(I30:I33) -> 18 | Z15: =SUM(J30:J33) -> 13 | ... AF15: =SUM(P30:P33) -> 973
B16: 08.30 - 08.45 | C16: 23 | D16: 3 | E16: 0 | F16: 3 | G16: 2 | H16: 54 | I16: 1 | J16: 0 | K16: 6 | L16: 3 | M16: 190 | N16: 0 | O16: =SUM(C16:L16,N16) -> 95 | P16: =SUM(C16:N16) -> 285 | R16: 1300-1400 | S16: =SUM(C34:C37) -> 137 | T16: =SUM(D34:D37) -> 33 | U16: =SUM(E34:E37) -> 14 | V16: =SUM(F34:F37) -> 134 | W16: =SUM(G34:G37) -> 1 | X16: =SUM(H34:H37) -> 2 | Y16: =SUM(I34:I37) -> 14 | Z16: =SUM(J34:J37) -> 31 | ... AF16: =SUM(P34:P37) -> 883
B17: 08.45 - 9.00 | C17: 15 | D17: 8 | E17: 5 | F17: 34 | G17: 0 | H17: 2 | I17: 1 | J17: 2 | K17: 0 | L17: 0 | M17: 210 | N17: 0 | O17: =SUM(C17:L17,N17) -> 67 | P17: =SUM(C17:N17) -> 277 | R17: 1400-1500 | S17: =SUM(C38:C41) -> 149 | T17: =SUM(D38:D41) -> 28 | U17: =SUM(E38:E41) -> 21 | V17: =SUM(F38:F41) -> 137 | W17: =SUM(G38:G41) -> 42 | X17: =SUM(H38:H41) -> 3 | Y17: =SUM(I38:I41) -> 11 | Z17: =SUM(J38:J41) -> 31 | ... AF17: =SUM(P38:P41) -> 876
B18: 09.00 - 09.15 | C18: 36 | D18: 7 | E18: 2 | F18: 62 | G18: 0 | H18: 2 | I18: 3 | J18: 2 | K18: 1 | L18: 1 | M18: 182 | N18: 0 | O18: =SUM(C18:L18,N18) -> 116 | P18: =SUM(C18:N18) -> 298 | R18: 1500-1600 | S18: =SUM(C42:C45) -> 185 | T18: =SUM(D42:D45) -> 56 | U18: =SUM(E42:E45) -> 24 | V18: =SUM(F42:F45) -> 152 | W18: =SUM(G42:G45) -> 0 | X18: =SUM(H42:H45) -> 5 | Y18: =SUM(I42:I45) -> 16 | Z18: =SUM(J42:J45) -> 42 | ... AF18: =SUM(P42:P45) -> 940
B19: 09.15 - 09.30 | C19: 26 | D19: 3 | E19: 4 | F19: 602 | G19: 0 | H19: 0 | I19: 6 | J19: 2 | K19: 1 | L19: 1 | M19: 195 | N19: 0 | O19: =SUM(C19:L19,N19) -> 645 | P19: =SUM(C19:N19) -> 840 | R19: 1600-1700 | S19: =SUM(C46:C49) -> 218 | T19: =SUM(D46:D49) -> 57 | U19: =SUM(E46:E49) -> 17 | V19: =SUM(F46:F49) -> 168 | W19: =SUM(G46:G49) -> 6 | X19: =SUM(H46:H49) -> 1 | Y19: =SUM(I46:I49) -> 15 | Z19: =SUM(J46:J49) -> 13 | ... AF19: =SUM(P46:P49) -> 1028
B20: 09.30 - 09.45 | C20: 21 | D20: 10 | E20: 3 | F20: 49 | G20: 0 | H20: 0 | I20: 4 | J20: 2 | K20: 1 | L20: 0 | M20: 200 | N20: 0 | O20: =SUM(C20:L20,N20) -> 90 | P20: =SUM(C20:N20) -> 290 | R20: 1700-1800 | S20: =SUM(C50:C53) -> 281 | T20: =SUM(D50:D53) -> 57 | U20: =SUM(E50:E53) -> 21 | V20: =SUM(F50:F53) -> 142 | W20: =SUM(G50:G53) -> 3 | X20: =SUM(H50:H53) -> 0 | Y20: =SUM(I50:I53) -> 13 | Z20: =SUM(J50:J53) -> 29 | ... AF20: =SUM(P50:P53) -> 1018
B21: 09.45 - 10.00 | C21: 32 | D21: 0 | E21: 5 | F21: 1 | G21: 36 | H21: 0 | I21: 1 | J21: 2 | K21: 1 | L21: 0 | M21: 163 | N21: 0 | O21: =SUM(C21:L21,N21) -> 78 | P21: =SUM(C21:N21) -> 241 | R21: 1800-1900 | S21: =SUM(C54:C57) -> 203 | T21: =SUM(D54:D57) -> 32 | U21: =SUM(E54:E57) -> 17 | V21: =SUM(F54:F57) -> 160 | W21: =SUM(G54:G57) -> 3 | X21: =SUM(H54:H57) -> 2 | Y21: =SUM(I54:I57) -> 4 | Z21: =SUM(J54:J57) -> 15 | ... AF21: =SUM(P54:P57) -> 891
B22: 10.00 - 10.15 | C22: 33 | D22: 1 | E22: 6 | F22: 36 | G22: 0 | H22: 0 | I22: 2 | J22: 4 | K22: 0 | L22: 1 | M22: 195 | N22: 0 | O22: =SUM(C22:L22,N22) -> 83 | P22: =SUM(C22:N22) -> 278 | R22: AM Peak Hr | S22: =MAX(S10:S12) -> 115 | T22: =MAX(T10:T12) -> 25 | U22: =MAX(U10:U12) -> 14 | V22: =MAX(V10:V12) -> 714 | W22: =MAX(W10:W12) -> 36 | X22: =MAX(X10:X12) -> 59 | Y22: =MAX(Y10:Y12) -> 14 | Z22: =MAX(Z10:Z12) -> 8 | ... AF22: =MAX(AF10:AF12) -> 1669
B23: 10.15 - 10.30 | C23: 28 | D23: 6 | E23: 9 | F23: 45 | G23: 1 | H23: 1 | I23: 3 | J23: 4 | K23: 0 | L23: 0 | M23: 190 | N23: 0 | O23: =SUM(C23:L23,N23) -> 97 | P23: =SUM(C23:N23) -> 287 | R23: IP Peak Hr | S23: =MAX(S13:S18) -> 185 | T23: =MAX(T13:T18) -> 56 | U23: =MAX(U13:U18) -> 24 | V23: =MAX(V13:V18) -> 168 | W23: =MAX(W13:W18) -> 42 | X23: =MAX(X13:X18) -> 5 | Y23: =MAX(Y13:Y18) -> 18 | Z23: =MAX(Z13:Z18) -> 42 | ... AF23: =MAX(AF13:AF18) -> 1030
B24: 10.30 - 10.45 | C24: 41 | D24: 3 | E24: 3 | F24: 52 | G24: 0 | H24: 0 | I24: 1 | J24: 3 | K24: 3 | L24: 2 | M24: 174 | N24: 0 | O24: =SUM(C24:L24,N24) -> 108 | P24: =SUM(C24:N24) -> 282 | R24: PM Peak Hr | S24: =MAX(S19:S21) -> 281 | T24: =MAX(T19:T21) -> 57 | U24: =MAX(U19:U21) -> 21 | V24: =MAX(V19:V21) -> 168 | W24: =MAX(W19:W21) -> 6 | X24: =MAX(X19:X21) -> 2 | Y24: =MAX(Y19:Y21) -> 15 | Z24: =MAX(Z19:Z21) -> 29 | ... AF24: =MAX(AF19:AF21) -> 1028
B25: 10.45 - 11.00 | C25: 3 | D25: 11 | E25: 0 | F25: 32 | G25: 0 | H25: 0 | I25: 4 | J25: 4 | K25: 1 | L25: 1 | M25: 127 | N25: 0 | O25: =SUM(C25:L25,N25) -> 56 | P25: =SUM(C25:N25) -> 183 | R25: AM Period | S25: =SUM(S10:S12) -> 339 | T25: =SUM(T10:T12) -> 65 | U25: =SUM(U10:U12) -> 33 | V25: =SUM(V10:V12) -> 1005 | W25: =SUM(W10:W12) -> 48 | X25: =SUM(X10:X12) -> 65 | Y25: =SUM(Y10:Y12) -> 28 | Z25: =SUM(Z10:Z12) -> 22 | ... AF25: =SUM(AF10:AF12) -> 3628
B26: 11.00 - 11.15 | C26: 25 | D26: 19 | E26: 5 | F26: 38 | G26: 0 | H26: 1 | I26: 12 | J26: 2 | K26: 1 | L26: 2 | M26: 182 | N26: 1 | O26: =SUM(C26:L26,N26) -> 106 | P26: =SUM(C26:N26) -> 288 | R26: IP Period | S26: =SUM(S13:S18) -> 846 | T26: =SUM(T13:T18) -> 213 | U26: =SUM(U13:U18) -> 114 | V26: =SUM(V13:V18) -> 918 | W26: =SUM(W13:W18) -> 49 | X26: =SUM(X13:X18) -> 19 | Y26: =SUM(Y13:Y18) -> 86 | Z26: =SUM(Z13:Z18) -> 146 | ... AF26: =SUM(AF13:AF18) -> 5639
B27: 11.15 - 11.30 | C27: 37 | D27: 8 | E27: 6 | F27: 51 | H27: 0 | I27: 0 | J27: 5 | K27: 5 | L27: 1 | M27: 110 | N27: 0 | O27: =SUM(C27:L27,N27) -> 113 | P27: =SUM(C27:N27) -> 223 | R27: PM Period | S27: =SUM(S19:S21) -> 702 | T27: =SUM(T19:T21) -> 146 | U27: =SUM(U19:U21) -> 55 | V27: =SUM(V19:V21) -> 470 | W27: =SUM(W19:W21) -> 12 | X27: =SUM(X19:X21) -> 3 | Y27: =SUM(Y19:Y21) -> 32 | Z27: =SUM(Z19:Z21) -> 57 | ... AF27: =SUM(AF19:AF21) -> 2937
B28: 11.30 - 11.45 | C28: 35 | D28: 6 | E28: 3 | F28: 41 | G28: 0 | H28: 2 | I28: 3 | J28: 6 | K28: 1 | L28: 1 | M28: 140 | N28: 0 | O28: =SUM(C28:L28,N28) -> 98 | P28: =SUM(C28:N28) -> 238 | R28: 12 Hours | S28: =SUM(S10:S21) -> 1887 | T28: =SUM(T10:T21) -> 424 | U28: =SUM(U10:U21) -> 202 | V28: =SUM(V10:V21) -> 2393 | W28: =SUM(W10:W21) -> 109 | X28: =SUM(X10:X21) -> 87 | Y28: =SUM(Y10:Y21) -> 146 | Z28: =SUM(Z10:Z21) -> 225 | ... AF28: =SUM(AF10:AF21) -> 12204
B29: 11.45 - 12.00 | C29: 28 | D29: 2 | E29: 3 | F29: 38 | G29: 0 | H29: 2 | I29: 2 | J29: 1 | K29: 1 | L29: 1 | M29: 110 | N29: 0 | O29: =SUM(C29:L29,N29) -> 78 | P29: =SUM(C29:N29) -> 188
B30: 12.00 - 12.15 | C30: 33 | D30: 19 | E30: 7 | F30: 50 | G30: 1 | H30: 1 | I30: 4 | J30: 3 | K30: 3 | L30: 2 | M30: 160 | N30: 0 | O30: =SUM(C30:L30,N30) -> 123 | P30: =SUM(C30:N30) -> 283
B31: 12.15 - 12.30 | C31: 45 | D31: 7 | E31: 3 | F31: 43 | G31: 0 | H31: 2 | I31: 3 | J31: 1 | K31: 1 | L31: 1 | M31: 140 | N31: 0 | O31: =SUM(C31:L31,N31) -> 106 | P31: =SUM(C31:N31) -> 246
B32: 12.30 - 12.45 | C32: 32 | D32: 6 | E32: 5 | F32: 37 | G32: 4 | H32: 0 | I32: 7 | J32: 6 | K32: 0 | L32: 1 | M32: 142 | N32: 0 | O32: =SUM(C32:L32,N32) -> 98 | P32: =SUM(C32:N32) -> 240
B33: 12.45 - 13.00 | C33: 35 | D33: 8 | E33: 5 | F33: 32 | G33: 0 | H33: 0 | I33: 4 | J33: 3 | K33: 1 | L33: 1 | M33: 115 | N33: 0 | O33: =SUM(C33:L33,N33) -> 89 | P33: =SUM(C33:N33) -> 204
B34: 13.00 - 13.15 | C34: 32 | D34: 7 | E34: 4 | F34: 32 | G34: 0 | H34: 0 | I34: 3 | J34: 6 | K34: 0 | L34: 0 | M34: 142 | N34: 0 | O34: =SUM(C34:L34,N34) -> 84 | P34: =SUM(C34:N34) -> 226
B35: 13.15 - 13.30 | C35: 53 | D35: 2 | E35: 4 | F35: 31 | G35: 1 | H35: 0 | I35: 2 | J35: 3 | K35: 1 | L35: 0 | M35: 137 | N35: 0 | O35: =SUM(C35:L35,N35) -> 97 | P35: =SUM(C35:N35) -> 234
B36: 13.30 - 13.45 | C36: 28 | D36: 16 | E36: 5 | F36: 33 | G36: 0 | H36: 1 | I36: 6 | J36: 11 | K36: 2 | L36: 2 | M36: 150 | N36: 0 | O36: =SUM(C36:L36,N36) -> 104 | P36: =SUM(C36:N36) -> 254
B37: 13.45 - 14.00 | C37: 24 | D37: 8 | E37: 1 | F37: 38 | G37: 0 | H37: 1 | I37: 3 | J37: 11 | K37: 0 | L37: 0 | M37: 83 | N37: 0 | O37: =SUM(C37:L37,N37) -> 86 | P37: =SUM(C37:N37) -> 169
B38: 14.00 - 14.15 | C38: 44 | D38: 7 | E38: 6 | F38: 47 | G38: 1 | H38: 1 | I38: 3 | J38: 5 | K38: 0 | L38: 0 | M38: 132 | N38: 0 | O38: =SUM(C38:L38,N38) -> 114 | P38: =SUM(C38:N38) -> 246
B39: 14.15 - 14.30 | C39: 40 | D39: 4 | E39: 7 | F39: 43 | G39: 0 | H39: 0 | I39: 2 | J39: 8 | K39: 0 | L39: 2 | M39: 107 | N39: 0 | O39: =SUM(C39:L39,N39) -> 106 | P39: =SUM(C39:N39) -> 213
B40: 14.30 - 14.45 | C40: 33 | D40: 10 | E40: 4 | F40: 0 | G40: 41 | H40: 0 | I40: 0 | J40: 6 | K40: 8 | L40: 1 | M40: 88 | N40: 0 | O40: =SUM(C40:L40,N40) -> 103 | P40: =SUM(C40:N40) -> 191
... B47: 16.15 -16.30 | C47: 67 | D47: 15 | E47: 4 | F47: 36 | G47: 2 | H47: 0 | I47: 11 | J47: 0 | K47: 0 | L47: 0 | M47: 126 | N47: 0 | O47: =SUM(C47:L47,N47) -> 135 | P47: =SUM(C47:N47) -> 261
B48: 16.30 -16.45 | C48: 49 | D48: 12 | E48: 6 | F48: 50 | G48: 2 | H48: 0 | I48: 0 | K48: 6 | L48: 1 | M48: 150 | N48: 0 | O48: =SUM(C48:L48,N48) -> 126 | P48: =SUM(C48:N48) -> 276
...

Sheet 24.07 Bwaise-Makerere
B1: Consultancy services for Preparation of Expressway Development Master Plan (EDMP) for Uganda
B2: MANUAL CLASSIFIED COUNT (MCC)
B3: ROAD NAME: | C3: SIR APOLLO KAGGWA ROAD
C5: Date | D5: 24.07.19 | F5: Location | G5: PREMIUM DESIGN | J5: Surveyor | K5: OKELLO PETER
C6: Dir. From | D6: ='22.07 Bwaise-Makerere'!D6:E6 -> Bwaise | F6: Dir. To | G6: ='22.07 Bwaise-Makerere'!G6:H6 -> Makerere | J6: Supervisor | K6: ='22.07 Bwaise-Makerere'!K6:L6 -> SALIMAH
B8: Time / Veh Type | R8: SUMMARY TRAFFIC VOLUMES
C9: 1. Car | D9: 2. Station Wagon | E9: 3. Pickups | F9: 4. Minibus, matatu | G9: 5. Medium bus | H9: 6. Large Bus | I9: 7. Light Truck | J9: 8. Medium Truck | K9: 9. Heavy truck | L9: 10. Truck Trailer | M9: 11. Motor cycles | N9: 12. Tractors | O9: Total Excl M/Cycles | P9: Total All | R9: Time | S9: 1. Car | T9: 2. Station Wagon | U9: 3. Pickups | V9: 4. Minibus, matatu | W9: 5. Medium bus | X9: 6. Large Bus | Y9: 7. Light Truck | Z9: 8. Medium Truck | AA9: 9. Heavy truck | AB9: 10. Truck Trailer | AC9: 11. Motorcycles | AD9: 12. Tractors, Graders | AE9: Total Excl M/ Cycles | AF9: Total All
B10: 07.00 - 07.15 | C10: 160 | D10: 32 | E10: 7 | F10: 94 | G10: 3 | H10: 0 | I10: 3 | J10: 1 | K10: 2 | L10: 0 | M10: 267 | N10: 0 | O10: =SUM(C10:L10,N10) -> 302 | P10: =SUM(C10:N10) -> 569 | R10: 0700-0800 | S10: =SUM(C10:C13) -> 362 | T10: =SUM(D10:D13) -> 83 | U10: =SUM(E10:E13) -> 27 | V10: =SUM(F10:F13) -> 219 | W10: =SUM(G10:G13) -> 12 | X10: =SUM(H10:H13) -> 3 | Y10: =SUM(I10:I13) -> 16 | Z10: =SUM(J10:J13) -> 4 | ... AF10: =SUM(P10:P13) -> 1695
B11: 07.15 - 07.30 | C11: 60 | D11: 18 | E11: 2 | F11: 65 | G11: 4 | H11: 0 | I11: 4 | J11: 2 | K11: 0 | L11: 0 | M11: 200 | N11: 0 | O11: =SUM(C11:L11,N11) -> 155 | P11: =SUM(C11:N11) -> 355 | R11: 0800-0900 | S11: =SUM(C14:C17) -> 303 | T11: =SUM(D14:D17) -> 53 | U11: =SUM(E14:E17) -> 24 | V11: =SUM(F14:F17) -> 245 | W11: =SUM(G14:G17) -> 5 | X11: =SUM(H14:H17) -> 1 | Y11: =SUM(I14:I17) -> 7 | Z11: =SUM(J14:J17) -> 2 | ... AF11: =SUM(P14:P17) -> 1755
B12: 07.30 - 07.45 | C12: 68 | D12: 14 | E12: 8 | F12: 59 | G12: 4 | H12: 0 | I12: 7 | J12: 0 | K12: 2 | L12: 0 | M12: 223 | N12: 0 | O12: =SUM(C12:L12,N12) -> 162 | P12: =SUM(C12:N12) -> 385 | R12: 0900-1000 | S12: =SUM(C18:C21) -> 243 | T12: =SUM(D18:D21) -> 63 | U12: =SUM(E18:E21) -> 28 | V12: =SUM(F18:F21) -> 213 | W12: =SUM(G18:G21) -> 64 | X12: =SUM(H18:H21) -> 2 | Y12: =SUM(I18:I21) -> 14 | Z12: =SUM(J18:J21) -> 8 | ... AF12: =SUM(P18:P21) -> 1696
B13: 07.45 - 08.00 | C13: 74 | D13: 19 | E13: 10 | F13: 1 | G13: 1 | H13: 3 | I13: 2 | J13: 1 | K13: 0 | L13: 0 | M13: 275 | N13: 0 | O13: =SUM(C13:L13,N13) -> 111 | P13: =SUM(C13:N13) -> 386 | R13: 1000-1100 | S13: =SUM(C22:C25) -> 247 | T13: =SUM(D22:D25) -> 70 | U13: =SUM(E22:E25) -> 36 | V13: =SUM(F22:F25) -> 212 | W13: =SUM(G22:G25) -> 6 | X13: =SUM(H22:H25) -> 2 | Y13: =SUM(I22:I25) -> 34 | Z13: =SUM(J22:J25) -> 6 | ... AF13: =SUM(P22:P25) -> 1592
B14: 08.00 - 08.15 | C14: 88 | D14: 15 | E14: 2 | F14: 55 | G14: 1 | H14: 0 | I14: 3 | J14: 1 | K14: 3 | L14: 2 | M14: 250 | N14: 0 | O14: =SUM(C14:L14,N14) -> 170 | P14: =SUM(C14:N14) -> 420 | R14: 1100-1200 | S14: =SUM(C26:C29) -> 212 | T14: =SUM(D26:D29) -> 46 | U14: =SUM(E26:E29) -> 42 | V14: =SUM(F26:F29) -> 144 | W14: =SUM(G26:G29) -> 2 | X14: =SUM(H26:H29) -> 10 | Y14: =SUM(I26:I29) -> 21 | Z14: =SUM(J26:J29) -> 5 | ... AF14: =SUM(P26:P29) -> 1350
B15: 08.15 - 08.30 | C15: 57 | D15: 7 | E15: 3 | F15: 57 | G15: 2 | H15: 0 | I15: 1 | J15: 0 | K15: 1 | L15: 0 | M15: 275 | N15: 0 | O15: =SUM(C15:L15,N15) -> 128 | P15: =SUM(C15:N15) -> 403 | R15: 1200-1300 | S15: =SUM(C30:C33) -> 220 | T15: =SUM(D30:D33) -> 69 | U15: =SUM(E30:E33) -> 39 | V15: =SUM(F30:F33) -> 109 | W15: =SUM(G30:G33) -> 4 | X15: =SUM(H30:H33) -> 18 | Y15: =SUM(I30:I33) -> 21 | Z15: =SUM(J30:J33) -> 16 | ... AF15: =SUM(P30:P33) -> 1207
B16: 08.30 - 08.45 | C16: 75 | D16: 15 | E16: 7 | F16: 63 | G16: 1 | H16: 0 | I16: 0 | J16: 0 | K16: 0 | L16: 0 | M16: 279 | N16: 0 | O16: =SUM(C16:L16,N16) -> 161 | P16: =SUM(C16:N16) -> 440 | R16: 1300-1400 | S16: =SUM(C34:C37) -> 158 | T16: =SUM(D34:D37) -> 50 | U16: =SUM(E34:E37) -> 44 | V16: =SUM(F34:F37) -> 95 | W16: =SUM(G34:G37) -> 47 | X16: =SUM(H34:H37) -> 11 | Y16: =SUM(I34:I37) -> 29 | Z16: =SUM(J34:J37) -> 10 | ... AF16: =SUM(P34:P37) -> 1228
B17: 08.45 - 9.00 | C17: 83 | D17: 16 | E17: 12 | F17: 70 | G17: 1 | H17: 1 | I17: 3 | J17: 1 | K17: 4 | L17: 1 | M17: 300 | N17: 0 | O17: =SUM(C17:L17,N17) -> 192 | P17: =SUM(C17:N17) -> 492 | R17: 1400-1500 | S17: =SUM(C38:C41) -> 183 | T17: =SUM(D38:D41) -> 64 | U17: =SUM(E38:E41) -> 38 | V17: =SUM(F38:F41) -> 134 | W17: =SUM(G38:G41) -> 3 | X17: =SUM(H38:H41) -> 4 | Y17: =SUM(I38:I41) -> 26 | Z17: =SUM(J38:J41) -> 7 | ... AF17: =SUM(P38:P41) -> 1258
B18: 09.00 - 09.15 | C18: 60 | D18: 21 | E18: 8 | F18: 64 | G18: 0 | H18: 0 | I18: 5 | J18: 1 | K18: 2 | L18: 0 | M18: 300 | N18: 0 | O18: =SUM(C18:L18,N18) -> 161 | P18: =SUM(C18:N18) -> 461 | R18: 1500-1600 | S18: =SUM(C42:C45) -> 217 | T18: =SUM(D42:D45) -> 63 | U18: =SUM(E42:E45) -> 30 | V18: =SUM(F42:F45) -> 131 | W18: =SUM(G42:G45) -> 8 | X18: =SUM(H42:H45) -> 2 | Y18: =SUM(I42:I45) -> 43 | Z18: =SUM(J42:J45) -> 5 | ... AF18: =SUM(P42:P45) -> 1173
B19: 09.15 - 09.30 | C19: 67 | D19: 18 | E19: 9 | F19: 66 | G19: 60 | H19: 0 | I19: 1 | J19: 6 | K19: 5 | L19: 0 | M19: 300 | N19: 0 | O19: =SUM(C19:L19,N19) -> 232 | P19: =SUM(C19:N19) -> 532 | R19: 1600-1700 | S19: =SUM(C46:C49) -> 201 | T19: =SUM(D46:D49) -> 77 | U19: =SUM(E46:E49) -> 39 | V19: =SUM(F46:F49) -> 133 | W19: =SUM(G46:G49) -> 8 | X19: =SUM(H46:H49) -> 4 | Y19: =SUM(I46:I49) -> 43 | Z19: =SUM(J46:J49) -> 2 | ... AF19: =SUM(P46:P49) -> 1303
B20: 09.30 - 09.45 | C20: 65 | D20: 12 | E20: 8 | F20: 47 | G20: 0 | H20: 0 | I20: 3 | J20: 1 | K20: 2 | L20: 1 | M20: 250 | N20: 0 | O20: =SUM(C20:L20,N20) -> 139 | P20: =SUM(C20:N20) -> 389 | R20: 1700-1800 | S20: =SUM(C50:C53) -> 174 | T20: =SUM(D50:D53) -> 66 | U20: =SUM(E50:E53) -> 24 | V20: =SUM(F50:F53) -> 135 | W20: =SUM(G50:G53) -> 5 | X20: =SUM(H50:H53) -> 3 | Y20: =SUM(I50:I53) -> 28 | Z20: =SUM(J50:J53) -> 3 | ... AF20: =SUM(P50:P53) -> 1194
B21: 09.45 - 10.00 | C21: 51 | D21: 12 | E21: 3 | F21: 36 | G21: 4 | H21: 2 | I21: 5 | J21: 0 | K21: 1 | L21: 0 | M21: 200 | N21: 0 | O21: =SUM(C21:L21,N21) -> 114 | P21: =SUM(C21:N21) -> 314 | R21: 1800-1900 | S21: =SUM(C54:C57) -> 123 | T21: =SUM(D54:D57) -> 38 | U21: =SUM(E54:E57) -> 17 | V21: =SUM(F54:F57) -> 107 | W21: =SUM(G54:G57) -> 6 | X21: =SUM(H54:H57) -> 5 | Y21: =SUM(I54:I57) -> 22 | Z21: =SUM(J54:J57) -> 1 | ... AF21: =SUM(P54:P57) -> 843
B22: 10.00 - 10.15 | C22: 62 | D22: 13 | E22: 6 | F22: 58 | G22: 2 | H22: 0 | I22: 19 | J22: 2 | K22: 5 | L22: 1 | M22: 250 | N22: 0 | O22: =SUM(C22:L22,N22) -> 168 | P22: =SUM(C22:N22) -> 418 | R22: AM Peak Hr | S22: =MAX(S10:S12) -> 362 | T22: =MAX(T10:T12) -> 83 | U22: =MAX(U10:U12) -> 28 | V22: =MAX(V10:V12) -> 245 | W22: =MAX(W10:W12) -> 64 | X22: =MAX(X10:X12) -> 3 | Y22: =MAX(Y10:Y12) -> 16 | Z22: =MAX(Z10:Z12) -> 8 | ... AF22: =MAX(AF10:AF12) -> 1755
B23: 10.15 - 10.30 | C23: 64 | D23: 23 | E23: 11 | F23: 46 | G23: 2 | H23: 1 | I23: 7 | J23: 1 | K23: 0 | L23: 0 | M23: 253 | N23: 0 | O23: =SUM(C23:L23,N23) -> 155 | P23: =SUM(C23:N23) -> 408 | R23: IP Peak Hr | S23: =MAX(S13:S18) -> 247 | T23: =MAX(T13:T18) -> 70 | U23: =MAX(U13:U18) -> 44 | V23: =MAX(V13:V18) -> 212 | W23: =MAX(W13:W18) -> 47 | X23: =MAX(X13:X18) -> 18 | Y23: =MAX(Y13:Y18) -> 43 | Z23: =MAX(Z13:Z18) -> 16 | ... AF23: =MAX(AF13:AF18) -> 1592
B24: 10.30 - 10.45 | C24: 61 | D24: 15 | E24: 10 | F24: 53 | G24: 2 | H24: 1 | I24: 1 | J24: 2 | K24: 0 | L24: 0 | M24: 260 | N24: 0 | O24: =SUM(C24:L24,N24) -> 145 | P24: =SUM(C24:N24) -> 405 | R24: PM Peak Hr | S24: =MAX(S19:S21) -> 201 | T24: =MAX(T19:T21) -> 77 | U24: =MAX(U19:U21) -> 39 | V24: =MAX(V19:V21) -> 135 | W24: =MAX(W19:W21) -> 8 | X24: =MAX(X19:X21) -> 5 | Y24: =MAX(Y19:Y21) -> 43 | Z24: =MAX(Z19:Z21) -> 3 | ... AF24: =MAX(AF19:AF21) -> 1303
B25: 10.45 - 11.00 | C25: 60 | D25: 19 | E25: 9 | F25: 55 | G25: 0 | H25: 0 | I25: 7 | J25: 1 | K25: 1 | L25: 1 | M25: 208 | N25: 0 | O25: =SUM(C25:L25,N25) -> 153 | P25: =SUM(C25:N25) -> 361 | R25: AM Period | S25: =SUM(S10:S12) -> 908 | T25: =SUM(T10:T12) -> 199 | U25: =SUM(U10:U12) -> 79 | V25: =SUM(V10:V12) -> 677 | W25: =SUM(W10:W12) -> 81 | X25: =SUM(X10:X12) -> 6 | Y25: =SUM(Y10:Y12) -> 37 | Z25: =SUM(Z10:Z12) -> 14 | ... AF25: =SUM(AF10:AF12) -> 5146
B26: 11.00 - 11.15 | C26: 47 | D26: 10 | E26: 15 | F26: 33 | G26: 0 | H26: 1 | I26: 7 | J26: 2 | K26: 3 | L26: 0 | M26: 207 | N26: 0 | O26: =SUM(C26:L26,N26) -> 118 | P26: =SUM(C26:N26) -> 325 | R26: IP Period | S26: =SUM(S13:S18) -> 1237 | T26: =SUM(T13:T18) -> 362 | U26: =SUM(U13:U18) -> 229 | V26: =SUM(V13:V18) -> 825 | W26: =SUM(W13:W18) -> 70 | X26: =SUM(X13:X18) -> 47 | Y26: =SUM(Y13:Y18) -> 174 | Z26: =SUM(Z13:Z18) -> 49 | ... AF26: =SUM(AF13:AF18) -> 7808
B27: 11.15 - 11.30 | C27: 49 | D27: 15 | E27: 9 | F27: 30 | G27: 0 | H27: 0 | I27: 10 | J27: 1 | K27: 3 | L27: 0 | M27: 233 | N27: 0 | O27: =SUM(C27:L27,N27) -> 117 | P27: =SUM(C27:N27) -> 350 | R27: PM Period | S27: =SUM(S19:S21) -> 498 | T27: =SUM(T19:T21) -> 181 | U27: =SUM(U19:U21) -> 80 | V27: =SUM(V19:V21) -> 375 | W27: =SUM(W19:W21) -> 19 | X27: =SUM(X19:X21) -> 12 | Y27: =SUM(Y19:Y21) -> 93 | Z27: =SUM(Z19:Z21) -> 6 | ... AF27: =SUM(AF19:AF21) -> 3340
B28: 11.30 - 11.45 | C28: 53 | D28: 8 | E28: 7 | F28: 46 | G28: 1 | H28: 0 | I28: 3 | J28: 1 | K28: 2 | L28: 32 | M28: 182 | N28: 0 | O28: =SUM(C28:L28,N28) -> 153 | P28: =SUM(C28:N28) -> 335 | R28: 12 Hours | S28: =SUM(S10:S21) -> 2643 | T28: =SUM(T10:T21) -> 742 | U28: =SUM(U10:U21) -> 388 | V28: =SUM(V10:V21) -> 1877 | W28: =SUM(W10:W21) -> 170 | X28: =SUM(X10:X21) -> 65 | Y28: =SUM(Y10:Y21) -> 304 | Z28: =SUM(Z10:Z21) -> 69 | ... AF28: =SUM(AF10:AF21) -> 16294
