Workbook

Sheet 12.08 Malaba-Tororo
B1: Consultancy services for Preparation of Expressway Development Master Plan (EDMP) for Uganda
B2: MANUAL CLASSIFIED COUNT (MCC)
B3: ROAD NAME: | C3: MCC - C3b- STN143 - TORORO-MALABA ROAD
C5: Date | D5: 12.08.19 | F5: Location | G5: xxx | J5: Surveyor | K5: xxx
C6: Dir. From | D6: Malaba | F6: Dir. To | G6: Tororo | J6: Supervisor | K6: xxx
B8: Time / Veh Type | R8: SUMMARY TRAFFIC VOLUMES
C9: 1. Car | D9: 2. Station Wagon | E9: 3. Pickups | F9: 4. Minibus, matatu | G9: 5. Medium bus | H9: 6. Large Bus | I9: 7. Light Truck | J9: 8. Medium Truck | K9: 9. Heavy truck | L9: 10. Truck Trailer | M9: 11. Motor cycles | N9: 12. Tractors | O9: Total Excl M/Cycles | P9: Total All | R9: Time | S9: 1. Car | T9: 2. Station Wagon | U9: 3. Pickups | V9: 4. Minibus, matatu | W9: 5. Medium bus | X9: 6. Large Bus | Y9: 7. Light Truck | Z9: 8. Medium Truck | AA9: 9. Heavy truck | AB9: 10. Truck Trailer | AC9: 11. Motorcycles | AD9: 12. Tractors, Graders | AE9: Total Excl M/ Cycles | AF9: Total All
B10: 07.00 - 07.15 | C10: 0 | D10: 0 | E10: 0 | F10: 2 | G10: 0 | H10: 0 | I10: 0 | J10: 0 | K10: 0 | L10: 0 | M10: 16 | N10: 0 | O10: =SUM(C10:L10,N10) -> 2 | P10: =SUM(C10:N10) -> 18 | R10: 0700-0800 | S10: =SUM(C10:C13) -> 3 | T10: =SUM(D10:D13) -> 0 | U10: =SUM(E10:E13) -> 1 | V10: =SUM(F10:F13) -> 7 | W10: =SUM(G10:G13) -> 0 | X10: =SUM(H10:H13) -> 0 | Y10: =SUM(I10:I13) -> 0 | Z10: =SUM(J10:J13) -> 0 | ... AF10: =SUM(P10:P13) -> 84
B11: 07.15 - 07.30 | C11: 1 | D11: 0 | E11: 0 | F11: 1 | G11: 0 | H11: 0 | I11: 0 | J11: 0 | K11: 0 | L11: 0 | M11: 15 | N11: 0 | O11: =SUM(C11:L11,N11) -> 2 | P11: =SUM(C11:N11) -> 17 | R11: 0800-0900 | S11: =SUM(C14:C17) -> 3 | T11: =SUM(D14:D17) -> 1 | U11: =SUM(E14:E17) -> 10 | V11: =SUM(F14:F17) -> 4 | W11: =SUM(G14:G17) -> 0 | X11: =SUM(H14:H17) -> 1 | Y11: =SUM(I14:I17) -> 1 | Z11: =SUM(J14:J17) -> 0 | ... AF11: =SUM(P14:P17) -> 114
B12: 07.30 - 07.45 | C12: 1 | D12: 0 | E12: 0 | F12: 4 | G12: 0 | H12: 0 | I12: 0 | J12: 0 | K12: 0 | L12: 0 | M12: 17 | N12: 0 | O12: =SUM(C12:L12,N12) -> 5 | P12: =SUM(C12:N12) -> 22 | R12: 0900-1000 | S12: =SUM(C18:C21) -> 5 | T12: =SUM(D18:D21) -> 3 | U12: =SUM(E18:E21) -> 14 | V12: =SUM(F18:F21) -> 7 | W12: =SUM(G18:G21) -> 0 | X12: =SUM(H18:H21) -> 0 | Y12: =SUM(I18:I21) -> 3 | Z12: =SUM(J18:J21) -> 0 | ... AF12: =SUM(P18:P21) -> 118
B13: 07.45 - 08.00 | C13: 1 | D13: 0 | E13: 1 | F13: 0 | G13: 0 | H13: 0 | I13: 0 | J13: 0 | K13: 0 | L13: 0 | M13: 25 | N13: 0 | O13: =SUM(C13:L13,N13) -> 2 | P13: =SUM(C13:N13) -> 27 | R13: 1000-1100 | S13: =SUM(C22:C25) -> 12 | T13: =SUM(D22:D25) -> 0 | U13: =SUM(E22:E25) -> 11 | V13: =SUM(F22:F25) -> 7 | W13: =SUM(G22:G25) -> 0 | X13: =SUM(H22:H25) -> 1 | Y13: =SUM(I22:I25) -> 10 | Z13: =SUM(J22:J25) -> 0 | ... AF13: =SUM(P22:P25) -> 143
B14: 08.00 - 08.15 | C14: 0 | D14: 0 | E14: 2 | F14: 0 | G14: 0 | H14: 0 | I14: 0 | J14: 0 | K14: 0 | L14: 0 | M14: 26 | N14: 0 | O14: =SUM(C14:L14,N14) -> 2 | P14: =SUM(C14:N14) -> 28 | R14: 1100-1200 | S14: =SUM(C26:C29) -> 7 | T14: =SUM(D26:D29) -> 1 | U14: =SUM(E26:E29) -> 11 | V14: =SUM(F26:F29) -> 5 | W14: =SUM(G26:G29) -> 1 | X14: =SUM(H26:H29) -> 0 | Y14: =SUM(I26:I29) -> 4 | Z14: =SUM(J26:J29) -> 1 | ... AF14: =SUM(P26:P29) -> 150
B15: 08.15 - 08.30 | C15: 1 | D15: 1 | E15: 3 | F15: 2 | G15: 0 | H15: 0 | I15: 1 | J15: 0 | K15: 0 | L15: 0 | M15: 14 | N15: 0 | O15: =SUM(C15:L15,N15) -> 8 | P15: =SUM(C15:N15) -> 22 | R15: 1200-1300 | S15: =SUM(C30:C33) -> 4 | T15: =SUM(D30:D33) -> 2 | U15: =SUM(E30:E33) -> 12 | V15: =SUM(F30:F33) -> 8 | W15: =SUM(G30:G33) -> 0 | X15: =SUM(H30:H33) -> 0 | Y15: =SUM(I30:I33) -> 17 | Z15: =SUM(J30:J33) -> 2 | ... AF15: =SUM(P30:P33) -> 149
B16: 08.30 - 08.45 | C16: 0 | D16: 0 | E16: 2 | F16: 1 | G16: 0 | H16: 0 | I16: 0 | J16: 0 | K16: 0 | L16: 0 | M16: 34 | N16: 0 | O16: =SUM(C16:L16,N16) -> 3 | P16: =SUM(C16:N16) -> 37 | R16: 1300-1400 | S16: =SUM(C34:C37) -> 11 | T16: =SUM(D34:D37) -> 0 | U16: =SUM(E34:E37) -> 11 | V16: =SUM(F34:F37) -> 6 | W16: =SUM(G34:G37) -> 0 | X16: =SUM(H34:H37) -> 0 | Y16: =SUM(I34:I37) -> 1 | Z16: =SUM(J34:J37) -> 0 | ... AF16: =SUM(P34:P37) -> 145
B17: 08.45 - 9.00 | C17: 2 | D17: 0 | E17: 3 | F17: 1 | G17: 0 | H17: 1 | I17: 0 | J17: 0 | K17: 0 | L17: 0 | M17: 20 | N17: 0 | O17: =SUM(C17:L17,N17) -> 7 | P17: =SUM(C17:N17) -> 27 | R17: 1400-1500 | S17: =SUM(C38:C41) -> 8 | T17: =SUM(D38:D41) -> 2 | U17: =SUM(E38:E41) -> 11 | V17: =SUM(F38:F41) -> 11 | W17: =SUM(G38:G41) -> 0 | X17: =SUM(H38:H41) -> 0 | Y17: =SUM(I38:I41) -> 9 | Z17: =SUM(J38:J41) -> 3 | ... AF17: =SUM(P38:P41) -> 138
B18: 09.00 - 09.15 | C18: 1 | D18: 0 | E18: 2 | F18: 0 | G18: 0 | H18: 0 | I18: 0 | J18: 0 | K18: 0 | L18: 0 | M18: 20 | N18: 0 | O18: =SUM(C18:L18,N18) -> 3 | P18: =SUM(C18:N18) -> 23 | R18: 1500-1600 | S18: =SUM(C42:C45) -> 7 | T18: =SUM(D42:D45) -> 2 | U18: =SUM(E42:E45) -> 13 | V18: =SUM(F42:F45) -> 10 | W18: =SUM(G42:G45) -> 0 | X18: =SUM(H42:H45) -> 0 | Y18: =SUM(I42:I45) -> 4 | Z18: =SUM(J42:J45) -> 0 | ... AF18: =SUM(P42:P45) -> 136
B19: 09.15 - 09.30 | C19: 1 | D19: 1 | E19: 3 | F19: 3 | G19: 0 | H19: 0 | I19: 0 | J19: 0 | K19: 0 | L19: 0 | M19: 23 | N19: 1 | O19: =SUM(C19:L19,N19) -> 9 | P19: =SUM(C19:N19) -> 32 | R19: 1600-1700 | S19: =SUM(C46:C49) -> 22 | T19: =SUM(D46:D49) -> 3 | U19: =SUM(E46:E49) -> 12 | V19: =SUM(F46:F49) -> 11 | W19: =SUM(G46:G49) -> 3 | X19: =SUM(H46:H49) -> 0 | Y19: =SUM(I46:I49) -> 8 | Z19: =SUM(J46:J49) -> 0 | ... AF19: =SUM(P46:P49) -> 167
B20: 09.30 - 09.45 | C20: 2 | D20: 1 | E20: 4 | F20: 3 | G20: 0 | H20: 0 | I20: 3 | J20: 0 | K20: 0 | L20: 0 | M20: 15 | N20: 0 | O20: =SUM(C20:L20,N20) -> 13 | P20: =SUM(C20:N20) -> 28 | R20: 1700-1800 | S20: =SUM(C50:C53) -> 12 | T20: =SUM(D50:D53) -> 2 | U20: =SUM(E50:E53) -> 12 | V20: =SUM(F50:F53) -> 11 | W20: =SUM(G50:G53) -> 2 | X20: =SUM(H50:H53) -> 0 | Y20: =SUM(I50:I53) -> 7 | Z20: =SUM(J50:J53) -> 3 | ... AF20: =SUM(P50:P53) -> 89
B21: 09.45 - 10.00 | C21: 1 | D21: 1 | E21: 5 | F21: 1 | G21: 0 | H21: 0 | I21: 0 | J21: 0 | K21: 0 | L21: 0 | M21: 27 | N21: 0 | O21: =SUM(C21:L21,N21) -> 8 | P21: =SUM(C21:N21) -> 35 | R21: 1800-1900 | S21: =SUM(C54:C57) -> 19 | T21: =SUM(D54:D57) -> 1 | U21: =SUM(E54:E57) -> 10 | V21: =SUM(F54:F57) -> 12 | W21: =SUM(G54:G57) -> 0 | X21: =SUM(H54:H57) -> 0 | Y21: =SUM(I54:I57) -> 6 | Z21: =SUM(J54:J57) -> 1 | ... AF21: =SUM(P54:P57) -> 125
B22: 10.00 - 10.15 | C22: 2 | D22: 0 | E22: 2 | F22: 1 | G22: 0 | H22: 0 | I22: 2 | J22: 0 | K22: 0 | L22: 0 | M22: 21 | N22: 0 | O22: =SUM(C22:L22,N22) -> 7 | P22: =SUM(C22:N22) -> 28 | R22: AM Peak Hr | S22: =MAX(S10:S12) -> 5 | T22: =MAX(T10:T12) -> 3 | U22: =MAX(U10:U12) -> 14 | V22: =MAX(V10:V12) -> 7 | W22: =MAX(W10:W12) -> 0 | X22: =MAX(X10:X12) -> 1 | Y22: =MAX(Y10:Y12) -> 3 | Z22: =MAX(Z10:Z12) -> 0 | ... AF22: =MAX(AF10:AF12) -> 118
B23: 10.15 - 10.30 | C23: 1 | D23: 0 | E23: 3 | F23: 4 | G23: 0 | H23: 0 | I23: 3 | J23: 0 | K23: 0 | L23: 0 | M23: 22 | N23: 0 | O23: =SUM(C23:L23,N23) -> 11 | P23: =SUM(C23:N23) -> 33 | R23: IP Peak Hr | S23: =MAX(S13:S18) -> 12 | T23: =MAX(T13:T18) -> 2 | U23: =MAX(U13:U18) -> 13 | V23: =MAX(V13:V18) -> 11 | W23: =MAX(W13:W18) -> 1 | X23: =MAX(X13:X18) -> 1 | Y23: =MAX(Y13:Y18) -> 17 | Z23: =MAX(Z13:Z18) -> 3 | ... AF23: =MAX(AF13:AF18) -> 150
B24: 10.30 - 10.45 | C24: 4 | D24: 0 | E24: 3 | F24: 0 | G24: 0 | H24: 1 | I24: 4 | J24: 0 | K24: 0 | L24: 0 | M24: 31 | N24: 0 | O24: =SUM(C24:L24,N24) -> 12 | P24: =SUM(C24:N24) -> 43 | R24: PM Peak Hr | S24: =MAX(S19:S21) -> 22 | T24: =MAX(T19:T21) -> 3 | U24: =MAX(U19:U21) -> 12 | V24: =MAX(V19:V21) -> 12 | W24: =MAX(W19:W21) -> 3 | X24: =MAX(X19:X21) -> 0 | Y24: =MAX(Y19:Y21) -> 8 | Z24: =MAX(Z19:Z21) -> 3 | ... AF24: =MAX(AF19:AF21) -> 167
B25: 10.45 - 11.00 | C25: 5 | D25: 0 | E25: 3 | F25: 2 | G25: 0 | H25: 0 | I25: 1 | J25: 0 | K25: 0 | L25: 0 | M25: 28 | N25: 0 | O25: =SUM(C25:L25,N25) -> 11 | P25: =SUM(C25:N25) -> 39 | R25: AM Period | S25: =SUM(S10:S12) -> 11 | T25: =SUM(T10:T12) -> 4 | U25: =SUM(U10:U12) -> 25 | V25: =SUM(V10:V12) -> 18 | W25: =SUM(W10:W12) -> 0 | X25: =SUM(X10:X12) -> 1 | Y25: =SUM(Y10:Y12) -> 4 | Z25: =SUM(Z10:Z12) -> 0 | ... AF25: =SUM(AF10:AF12) -> 316
B26: 11.00 - 11.15 | C26: 3 | D26: 1 | E26: 3 | F26: 3 | G26: 0 | H26: 0 | I26: 2 | J26: 0 | K26: 0 | L26: 0 | M26: 26 | N26: 0 | O26: =SUM(C26:L26,N26) -> 12 | P26: =SUM(C26:N26) -> 38 | R26: IP Period | S26: =SUM(S13:S18) -> 49 | T26: =SUM(T13:T18) -> 7 | U26: =SUM(U13:U18) -> 69 | V26: =SUM(V13:V18) -> 47 | W26: =SUM(W13:W18) -> 1 | X26: =SUM(X13:X18) -> 1 | Y26: =SUM(Y13:Y18) -> 45 | Z26: =SUM(Z13:Z18) -> 6 | ... AF26: =SUM(AF13:AF18) -> 861
B27: 11.15 - 11.30 | C27: 1 | D27: 0 | E27: 3 | F27: 1 | G27: 1 | H27: 0 | I27: 0 | J27: 0 | K27: 0 | L27: 0 | M27: 32 | N27: 0 | O27: =SUM(C27:L27,N27) -> 6 | P27: =SUM(C27:N27) -> 38 | R27: PM Period | S27: =SUM(S19:S21) -> 53 | T27: =SUM(T19:T21) -> 6 | U27: =SUM(U19:U21) -> 34 | V27: =SUM(V19:V21) -> 34 | W27: =SUM(W19:W21) -> 5 | X27: =SUM(X19:X21) -> 0 | Y27: =SUM(Y19:Y21) -> 21 | Z27: =SUM(Z19:Z21) -> 4 | ... AF27: =SUM(AF19:AF21) -> 381
B28: 11.30 - 11.45 | C28: 3 | D28: 0 | E28: 2 | F28: 1 | G28: 0 | H28: 0 | I28: 2 | J28: 0 | K28: 0 | L28: 0 | M28: 33 | N28: 0 | O28: =SUM(C28:L28,N28) -> 8 | P28: =SUM(C28:N28) -> 41 | R28: 12 Hours | S28: =SUM(S10:S21) -> 113 | T28: =SUM(T10:T21) -> 17 | U28: =SUM(U10:U21) -> 128 | V28: =SUM(V10:V21) -> 99 | W28: =SUM(W10:W21) -> 6 | X28: =SUM(X10:X21) -> 2 | Y28: =SUM(Y10:Y21) -> 70 | Z28: =SUM(Z10:Z21) -> 10 | ... AF28: =SUM(AF10:AF21) -> 1558
B29: 11.45 - 12.00 | C29: 0 | D29: 0 | E29: 3 | F29: 0 | G29: 0 | H29: 0 | I29: 0 | J29: 1 | K29: 0 | L29: 0 | M29: 29 | N29: 0 | O29: =SUM(C29:L29,N29) -> 4 | P29: =SUM(C29:N29) -> 33
B30: 12.00 - 12.15 | C30: 0 | D30: 1 | E30: 4 | F30: 4 | G30: 0 | H30: 0 | I30: 5 | J30: 0 | K30: 0 | L30: 0 | M30: 31 | N30: 0 | O30: =SUM(C30:L30,N30) -> 14 | P30: =SUM(C30:N30) -> 45
B31: 12.15 - 12.30 | C31: 0 | D31: 1 | E31: 4 | F31: 3 | G31: 0 | H31: 0 | I31: 5 | J31: 0 | K31: 0 | L31: 0 | M31: 20 | N31: 0 | O31: =SUM(C31:L31,N31) -> 13 | P31: =SUM(C31:N31) -> 33
B32: 12.30 - 12.45 | C32: 1 | D32: 0 | E32: 3 | F32: 0 | G32: 0 | H32: 0 | I32: 5 | J32: 1 | K32: 0 | L32: 0 | M32: 24 | N32: 2 | O32: =SUM(C32:L32,N32) -> 12 | P32: =SUM(C32:N32) -> 36
B33: 12.45 - 13.00 | C33: 3 | D33: 0 | E33: 1 | F33: 1 | G33: 0 | H33: 0 | I33: 2 | J33: 1 | K33: 0 | L33: 0 | M33: 27 | N33: 0 | O33: =SUM(C33:L33,N33) -> 8 | P33: =SUM(C33:N33) -> 35
B34: 13.00 - 13.15 | C34: 5 | D34: 0 | E34: 3 | F34: 3 | G34: 0 | H34: 0 | I34: 0 | J34: 0 | K34: 0 | L34: 0 | M34: 35 | N34: 0 | O34: =SUM(C34:L34,N34) -> 11 | P34: =SUM(C34:N34) -> 46
B35: 13.15 - 13.30 | C35: 4 | D35: 0 | E35: 2 | F35: 1 | G35: 0 | H35: 0 | I35: 1 | J35: 0 | K35: 0 | L35: 0 | M35: 43 | N35: 0 | O35: =SUM(C35:L35,N35) -> 8 | P35: =SUM(C35:N35) -> 51
B36: 13.30 - 13.45 | C36: 0 | D36: 0 | E36: 3 | F36: 2 | G36: 0 | H36: 0 | I36: 0 | J36: 0 | K36: 0 | L36: 0 | M36: 10 | N36: 0 | O36: =SUM(C36:L36,N36) -> 5 | P36: =SUM(C36:N36) -> 15
B37: 13.45 - 14.00 | C37: 2 | D37: 0 | E37: 3 | F37: 0 | G37: 0 | H37: 0 | I37: 0 | J37: 0 | K37: 1 | L37: 0 | M37: 27 | N37: 0 | O37: =SUM(C37:L37,N37) -> 6 | P37: =SUM(C37:N37) -> 33
B38: 14.00 - 14.15 | C38: 5 | D38: 0 | E38: 0 | F38: 1 | G38: 0 | H38: 0 | I38: 3 | J38: 1 | K38: 0 | L38: 0 | M38: 29 | N38: 0 | O38: =SUM(C38:L38,N38) -> 10 | P38: =SUM(C38:N38) -> 39
B39: 14.15 - 14.30 | C39: 1 | D39: 1 | E39: 4 | F39: 5 | G39: 0 | H39: 0 | I39: 3 | J39: 1 | K39: 0 | L39: 0 | M39: 27 | N39: 0 | O39: =SUM(C39:L39,N39) -> 15 | P39: =SUM(C39:N39) -> 42
B40: 14.30 - 14.45 | C40: 1 | D40: 0 | E40: 3 | F40: 1 | G40: 0 | H40: 0 | I40: 1 | J40: 0 | K40: 0 | L40: 0 | M40: 20 | N40: 0 | O40: =SUM(C40:L40,N40) -> 6 | P40: =SUM(C40:N40) -> 26
... B57: 18.45 - 19.00 | C57: 5 | D57: 1 | E57: 5 | F57: 4 | G57: 0 | H57: 0 | I57: 2 | J57: 0 | K57: 0 | L57: 0 | M57: 28 | N57: 0 | O57: =SUM(C57:L57,N57) -> 17 | P57: =SUM(C57:N57) -> 45
B58: Totals | C58: =SUM(C10:C57) -> 113 | D58: =SUM(D10:D57) -> 17 | E58: =SUM(E10:E57) -> 128 | F58: =SUM(F10:F57) -> 99 | G58: =SUM(G10:G57) -> 6 | H58: =SUM(H10:H57) -> 2 | I58: =SUM(I10:I57) -> 70 | J58: =SUM(J10:J57) -> 10 | ... P58: =SUM(P10:P57) -> 1558
...

Sheet 12.08 Tororo-Malaba
B1: Consultancy services for Preparation of Expressway Development Master Plan (EDMP) for Uganda
B2: MANUAL CLASSIFIED COUNT (MCC)
B3: ROAD NAME: | C3: ='12.08 Malaba-Tororo'!C3:G3 -> MCC - C3b- STN143 - TORORO-MALABA ROAD
C5: Date | D5: ='12.08 Malaba-Tororo'!D5 -> 12.08.19 | F5: Location | G5: ='12.08 Malaba-Tororo'!G5:H5 -> xxx | J5: Surveyor | K5: ='12.08 Malaba-Tororo'!K5:L5 -> xxx
C6: Dir. From | D6: Tororo | F6: Dir. To | G6: Malaba | J6: Supervisor | K6: ='12.08 Malaba-Tororo'!K6:L6 -> xxx
B8: Time / Veh Type | R8: SUMMARY TRAFFIC VOLUMES
C9: 1. Car | D9: 2. Station Wagon | E9: 3. Pickups | F9: 4. Minibus, matatu | G9: 5. Medium bus | H9: 6. Large Bus | I9: 7. Light Truck | J9: 8. Medium Truck | K9: 9. Heavy truck | L9: 10. Truck Trailer | M9: 11. Motor cycles | N9: 12. Tractors | O9: Total Excl M/Cycles | P9: Total All | R9: Time | S9: 1. Car | T9: 2. Station Wagon | U9: 3. Pickups | V9: 4. Minibus, matatu | W9: 5. Medium bus | X9: 6. Large Bus | Y9: 7. Light Truck | Z9: 8. Medium Truck | AA9: 9. Heavy truck | AB9: 10. Truck Trailer | AC9: 11. Motorcycles | AD9: 12. Tractors, Graders | AE9: Total Excl M/ Cycles | AF9: Total All
B10: 07.00 - 07.15 | C10: 1 | D10: 0 | E10: 1 | F10: 0 | G10: 0 | H10: 0 | I10: 0 | J10: 0 | K10: 0 | L10: 0 | M10: 6 | N10: 0 | O10: =SUM(C10:L10,N10) -> 2 | P10: =SUM(C10:N10) -> 8 | R10: 0700-0800 | S10: =SUM(C10:C13) -> 6 | T10: =SUM(D10:D13) -> 0 | U10: =SUM(E10:E13) -> 3 | V10: =SUM(F10:F13) -> 4 | W10: =SUM(G10:G13) -> 1 | X10: =SUM(H10:H13) -> 0 | Y10: =SUM(I10:I13) -> 1 | Z10: =SUM(J10:J13) -> 1 | ... AF10: =SUM(P10:P13) -> 75
B11: 07.15 - 07.30 | C11: 1 | D11: 0 | E11: 0 | F11: 2 | G11: 0 | H11: 0 | I11: 0 | J11: 0 | K11: 0 | L11: 0 | M11: 14 | N11: 0 | O11: =SUM(C11:L11,N11) -> 3 | P11: =SUM(C11:N11) -> 17 | R11: 0800-0900 | S11: =SUM(C14:C17) -> 8 | T11: =SUM(D14:D17) -> 0 | U11: =SUM(E14:E17) -> 2 | V11: =SUM(F14:F17) -> 4 | W11: =SUM(G14:G17) -> 0 | X11: =SUM(H14:H17) -> 0 | Y11: =SUM(I14:I17) -> 0 | Z11: =SUM(J14:J17) -> 1 | ... AF11: =SUM(P14:P17) -> 111
B12: 07.30 - 07.45 | C12: 3 | D12: 0 | E12: 1 | F12: 1 | G12: 0 | H12: 0 | I12: 1 | J12: 1 | K12: 0 | L12: 0 | M12: 15 | N12: 0 | O12: =SUM(C12:L12,N12) -> 7 | P12: =SUM(C12:N12) -> 22 | R12: 0900-1000 | S12: =SUM(C18:C21) -> 4 | T12: =SUM(D18:D21) -> 1 | U12: =SUM(E18:E21) -> 12 | V12: =SUM(F18:F21) -> 10 | W12: =SUM(G18:G21) -> 0 | X12: =SUM(H18:H21) -> 0 | Y12: =SUM(I18:I21) -> 1 | Z12: =SUM(J18:J21) -> 0 | ... AF12: =SUM(P18:P21) -> 121
B13: 07.45 - 08.00 | C13: 1 | D13: 0 | E13: 1 | F13: 1 | G13: 1 | H13: 0 | I13: 0 | J13: 0 | K13: 0 | L13: 0 | M13: 24 | N13: 0 | O13: =SUM(C13:L13,N13) -> 4 | P13: =SUM(C13:N13) -> 28 | R13: 1000-1100 | S13: =SUM(C22:C25) -> 9 | T13: =SUM(D22:D25) -> 1 | U13: =SUM(E22:E25) -> 7 | V13: =SUM(F22:F25) -> 4 | W13: =SUM(G22:G25) -> 0 | X13: =SUM(H22:H25) -> 0 | Y13: =SUM(I22:I25) -> 1 | Z13: =SUM(J22:J25) -> 1 | ... AF13: =SUM(P22:P25) -> 136
B14: 08.00 - 08.15 | C14: 1 | D14: 0 | E14: 0 | F14: 3 | G14: 0 | H14: 0 | I14: 0 | J14: 0 | K14: 0 | L14: 0 | M14: 29 | N14: 0 | O14: =SUM(C14:L14,N14) -> 4 | P14: =SUM(C14:N14) -> 33 | R14: 1100-1200 | S14: =SUM(C26:C29) -> 13 | T14: =SUM(D26:D29) -> 1 | U14: =SUM(E26:E29) -> 12 | V14: =SUM(F26:F29) -> 9 | W14: =SUM(G26:G29) -> 0 | X14: =SUM(H26:H29) -> 0 | Y14: =SUM(I26:I29) -> 4 | Z14: =SUM(J26:J29) -> 0 | ... AF14: =SUM(P26:P29) -> 143
B15: 08.15 - 08.30 | C15: 3 | D15: 0 | E15: 0 | F15: 0 | G15: 0 | H15: 0 | I15: 0 | J15: 0 | K15: 0 | L15: 0 | M15: 28 | N15: 0 | O15: =SUM(C15:L15,N15) -> 3 | P15: =SUM(C15:N15) -> 31 | R15: 1200-1300 | S15: =SUM(C30:C33) -> 10 | T15: =SUM(D30:D33) -> 0 | U15: =SUM(E30:E33) -> 7 | V15: =SUM(F30:F33) -> 11 | W15: =SUM(G30:G33) -> 1 | X15: =SUM(H30:H33) -> 0 | Y15: =SUM(I30:I33) -> 0 | Z15: =SUM(J30:J33) -> 0 | ... AF15: =SUM(P30:P33) -> 139
B16: 08.30 - 08.45 | C16: 2 | D16: 0 | E16: 1 | F16: 0 | G16: 0 | H16: 0 | I16: 0 | J16: 0 | K16: 0 | L16: 0 | M16: 24 | N16: 0 | O16: =SUM(C16:L16,N16) -> 3 | P16: =SUM(C16:N16) -> 27 | R16: 1300-1400 | S16: =SUM(C34:C37) -> 6 | T16: =SUM(D34:D37) -> 0 | U16: =SUM(E34:E37) -> 4 | V16: =SUM(F34:F37) -> 10 | W16: =SUM(G34:G37) -> 0 | X16: =SUM(H34:H37) -> 0 | Y16: =SUM(I34:I37) -> 7 | Z16: =SUM(J34:J37) -> 0 | ... AF16: =SUM(P34:P37) -> 111
B17: 08.45 - 9.00 | C17: 2 | D17: 0 | E17: 1 | F17: 1 | G17: 0 | H17: 0 | I17: 0 | J17: 1 | K17: 0 | L17: 0 | M17: 15 | N17: 0 | O17: =SUM(C17:L17,N17) -> 5 | P17: =SUM(C17:N17) -> 20 | R17: 1400-1500 | S17: =SUM(C38:C41) -> 10 | T17: =SUM(D38:D41) -> 1 | U17: =SUM(E38:E41) -> 9 | V17: =SUM(F38:F41) -> 10 | W17: =SUM(G38:G41) -> 1 | X17: =SUM(H38:H41) -> 0 | Y17: =SUM(I38:I41) -> 3 | Z17: =SUM(J38:J41) -> 0 | ... AF17: =SUM(P38:P41) -> 129
B18: 09.00 - 09.15 | C18: 0 | D18: 0 | E18: 3 | F18: 2 | G18: 0 | H18: 0 | I18: 1 | J18: 0 | K18: 0 | L18: 0 | M18: 20 | N18: 0 | O18: =SUM(C18:L18,N18) -> 6 | P18: =SUM(C18:N18) -> 26 | R18: 1500-1600 | S18: =SUM(C42:C45) -> 8 | T18: =SUM(D42:D45) -> 0 | U18: =SUM(E42:E45) -> 2 | V18: =SUM(F42:F45) -> 8 | W18: =SUM(G42:G45) -> 0 | X18: =SUM(H42:H45) -> 0 | Y18: =SUM(I42:I45) -> 4 | Z18: =SUM(J42:J45) -> 0 | ... AF18: =SUM(P42:P45) -> 113
B19: 09.15 - 09.30 | C19: 2 | D19: 0 | E19: 2 | F19: 2 | G19: 0 | H19: 0 | I19: 0 | J19: 0 | K19: 0 | L19: 0 | M19: 23 | N19: 0 | O19: =SUM(C19:L19,N19) -> 6 | P19: =SUM(C19:N19) -> 29 | R19: 1600-1700 | S19: =SUM(C46:C49) -> 19 | T19: =SUM(D46:D49) -> 1 | U19: =SUM(E46:E49) -> 8 | V19: =SUM(F46:F49) -> 13 | W19: =SUM(G46:G49) -> 0 | X19: =SUM(H46:H49) -> 0 | Y19: =SUM(I46:I49) -> 6 | Z19: =SUM(J46:J49) -> 0 | ... AF19: =SUM(P46:P49) -> 153
B20: 09.30 - 09.45 | C20: 1 | D20: 1 | E20: 4 | F20: 1 | G20: 0 | H20: 0 | I20: 0 | J20: 0 | K20: 0 | L20: 0 | M20: 30 | N20: 0 | O20: =SUM(C20:L20,N20) -> 7 | P20: =SUM(C20:N20) -> 37 | R20: 1700-1800 | S20: =SUM(C50:C53) -> 16 | T20: =SUM(D50:D53) -> 0 | U20: =SUM(E50:E53) -> 7 | V20: =SUM(F50:F53) -> 9 | W20: =SUM(G50:G53) -> 0 | X20: =SUM(H50:H53) -> 0 | Y20: =SUM(I50:I53) -> 5 | Z20: =SUM(J50:J53) -> 0 | ... AF20: =SUM(P50:P53) -> 83
B21: 09.45 - 10.00 | C21: 1 | D21: 0 | E21: 3 | F21: 5 | G21: 0 | H21: 0 | I21: 0 | J21: 0 | K21: 0 | L21: 0 | M21: 20 | N21: 0 | O21: =SUM(C21:L21,N21) -> 9 | P21: =SUM(C21:N21) -> 29 | R21: 1800-1900 | S21: =SUM(C54:C57) -> 17 | T21: =SUM(D54:D57) -> 0 | U21: =SUM(E54:E57) -> 6 | V21: =SUM(F54:F57) -> 13 | W21: =SUM(G54:G57) -> 1 | X21: =SUM(H54:H57) -> 2 | Y21: =SUM(I54:I57) -> 3 | Z21: =SUM(J54:J57) -> 1 | ... AF21: =SUM(P54:P57) -> 120
B22: 10.00 - 10.15 | C22: 1 | D22: 1 | E22: 6 | F22: 0 | G22: 0 | H22: 0 | I22: 0 | J22: 1 | K22: 0 | L22: 0 | M22: 35 | N22: 0 | O22: =SUM(C22:L22,N22) -> 9 | P22: =SUM(C22:N22) -> 44 | R22: AM Peak Hr | S22: =MAX(S10:S12) -> 8 | T22: =MAX(T10:T12) -> 1 | U22: =MAX(U10:U12) -> 12 | V22: =MAX(V10:V12) -> 10 | W22: =MAX(W10:W12) -> 1 | X22: =MAX(X10:X12) -> 0 | Y22: =MAX(Y10:Y12) -> 1 | Z22: =MAX(Z10:Z12) -> 1 | ... AF22: =MAX(AF10:AF12) -> 121
B23: 10.15 - 10.30 | C23: 4 | D23: 0 | E23: 0 | F23: 2 | G23: 0 | H23: 0 | I23: 1 | J23: 0 | K23: 0 | L23: 0 | M23: 24 | N23: 0 | O23: =SUM(C23:L23,N23) -> 7 | P23: =SUM(C23:N23) -> 31 | R23: IP Peak Hr | S23: =MAX(S13:S18) -> 13 | T23: =MAX(T13:T18) -> 1 | U23: =MAX(U13:U18) -> 12 | V23: =MAX(V13:V18) -> 11 | W23: =MAX(W13:W18) -> 1 | X23: =MAX(X13:X18) -> 0 | Y23: =MAX(Y13:Y18) -> 7 | Z23: =MAX(Z13:Z18) -> 1 | ... AF23: =MAX(AF13:AF18) -> 143
B24: 10.30 - 10.45 | C24: 1 | D24: 0 | E24: 1 | F24: 1 | G24: 0 | H24: 0 | I24: 0 | J24: 0 | K24: 0 | L24: 0 | M24: 29 | N24: 0 | O24: =SUM(C24:L24,N24) -> 3 | P24: =SUM(C24:N24) -> 32 | R24: PM Peak Hr | S24: =MAX(S19:S21) -> 19 | T24: =MAX(T19:T21) -> 1 | U24: =MAX(U19:U21) -> 8 | V24: =MAX(V19:V21) -> 13 | W24: =MAX(W19:W21) -> 1 | X24: =MAX(X19:X21) -> 2 | Y24: =MAX(Y19:Y21) -> 6 | Z24: =MAX(Z19:Z21) -> 1 | ... AF24: =MAX(AF19:AF21) -> 153
B25: 10.45 - 11.00 | C25: 3 | D25: 0 | E25: 0 | F25: 1 | G25: 0 | H25: 0 | I25: 0 | J25: 0 | K25: 0 | L25: 0 | M25: 25 | N25: 0 | O25: =SUM(C25:L25,N25) -> 4 | P25: =SUM(C25:N25) -> 29 | R25: AM Period | S25: =SUM(S10:S12) -> 18 | T25: =SUM(T10:T12) -> 1 | U25: =SUM(U10:U12) -> 17 | V25: =SUM(V10:V12) -> 18 | W25: =SUM(W10:W12) -> 1 | X25: =SUM(X10:X12) -> 0 | Y25: =SUM(Y10:Y12) -> 2 | Z25: =SUM(Z10:Z12) -> 2 | ... AF25: =SUM(AF10:AF12) -> 307
B26: 11.00 - 11.15 | C26: 1 | D26: 1 | E26: 4 | F26: 1 | G26: 0 | H26: 0 | I26: 0 | J26: 0 | K26: 0 | L26: 0 | M26: 31 | N26: 0 | O26: =SUM(C26:L26,N26) -> 7 | P26: =SUM(C26:N26) -> 38 | R26: IP Period | S26: =SUM(S13:S18) -> 56 | T26: =SUM(T13:T18) -> 3 | U26: =SUM(U13:U18) -> 41 | V26: =SUM(V13:V18) -> 52 | W26: =SUM(W13:W18) -> 2 | X26: =SUM(X13:X18) -> 0 | Y26: =SUM(Y13:Y18) -> 19 | Z26: =SUM(Z13:Z18) -> 1 | ... AF26: =SUM(AF13:AF18) -> 771
B27: 11.15 - 11.30 | C27: 4 | D27: 0 | E27: 3 | F27: 4 | G27: 0 | H27: 0 | I27: 2 | J27: 0 | K27: 0 | L27: 0 | M27: 24 | N27: 0 | O27: =SUM(C27:L27,N27) -> 13 | P27: =SUM(C27:N27) -> 37 | R27: PM Period | S27: =SUM(S19:S21) -> 52 | T27: =SUM(T19:T21) -> 1 | U27: =SUM(U19:U21) -> 21 | V27: =SUM(V19:V21) -> 35 | W27: =SUM(W19:W21) -> 1 | X27: =SUM(X19:X21) -> 2 | Y27: =SUM(Y19:Y21) -> 14 | Z27: =SUM(Z19:Z21) -> 1 | ... AF27: =SUM(AF19:AF21) -> 356
B28: 11.30 - 11.45 | C28: 4 | D28: 0 | E28: 3 | F28: 2 | G28: 0 | H28: 0 | I28: 1 | J28: 0 | K28: 0 | L28: 0 | M28: 25 | N28: 0 | O28: =SUM(C28:L28,N28) -> 10 | P28: =SUM(C28:N28) -> 35 | R28: 12 Hours | S28: =SUM(S10:S21) -> 126 | T28: =SUM(T10:T21) -> 5 | U28: =SUM(U10:U21) -> 79 | V28: =SUM(V10:V21) -> 105 | W28: =SUM(W10:W21) -> 4 | X28: =SUM(X10:X21) -> 2 | Y28: =SUM(Y10:Y21) -> 35 | Z28: =SUM(Z10:Z21) -> 4 | ... AF28: =SUM(AF10:AF21) -> 1434
B29: 11.45 - 12.00 | C29: 4 | D29: 0 | E29: 2 | F29: 2 | G29: 0 | H29: 0 | I29: 1 | J29: 0 | K29: 0 | L29: 0 | M29: 24 | N29: 0 | O29: =SUM(C29:L29,N29) -> 9 | P29: =SUM(C29:N29) -> 33
B30: 12.00 - 12.15 | C30: 2 | D30: 0 | E30: 1 | F30: 2 | G30: 0 | H30: 0 | I30: 0 | J30: 0 | K30: 0 | L30: 0 | M30: 34 | N30: 0 | O30: =SUM(C30:L30,N30) -> 5 | P30: =SUM(C30:N30) -> 39
B31: 12.15 - 12.30 | C31: 0 | D31: 0 | E31: 2 | F31: 1 | G31: 0 | H31: 0 | I31: 0 | J31: 0 | K31: 0 | L31: 0 | M31: 30 | N31: 0 | O31: =SUM(C31:L31,N31) -> 3 | P31: =SUM(C31:N31) -> 33
B32: 12.30 - 12.45 | C32: 5 | D32: 0 | E32: 2 | F32: 3 | G32: 0 | H32: 0 | I32: 0 | J32: 0 | K32: 0 | L32: 0 | M32: 23 | N32: 0 | O32: =SUM(C32:L32,N32) -> 10 | P32: =SUM(C32:N32) -> 33
B33: 12.45 - 13.00 | C33: 3 | D33: 0 | E33: 2 | F33: 5 | G33: 1 | H33: 0 | I33: 0 | J33: 0 | K33: 0 | L33: 0 | M33: 23 | N33: 0 | O33: =SUM(C33:L33,N33) -> 11 | P33: =SUM(C33:N33) -> 34
B34: 13.00 - 13.15 | C34: 0 | D34: 0 | E34: 1 | F34: 2 | G34: 0 | H34: 0 | I34: 2 | J34: 0 | K34: 0 | L34: 0 | M34: 18 | N34: 0 | O34: =SUM(C34:L34,N34) -> 5 | P34: =SUM(C34:N34) -> 23
B35: 13.15 - 13.30 | C35: 0 | D35: 0 | E35: 0 | F35: 3 | G35: 0 | H35: 0 | I35: 2 | J35: 0 | K35: 0 | L35: 0 | M35: 26 | N35: 0 | O35: =SUM(C35:L35,N35) -> 5 | P35: =SUM(C35:N35) -> 31
B36: 13.30 - 13.45 | C36: 2 | D36: 0 | E36: 1 | F36: 3 | G36: 0 | H36: 0 | I36: 1 | J36: 0 | K36: 0 | L36: 0 | M36: 17 | N36: 0 | O36: =SUM(C36:L36,N36) -> 7 | P36: =SUM(C36:N36) -> 24
B37: 13.45 - 14.00 | C37: 4 | D37: 0 | E37: 2 | F37: 2 | G37: 0 | H37: 0 | I37: 2 | J37: 0 | K37: 0 | L37: 0 | M37: 23 | N37: 0 | O37: =SUM(C37:L37,N37) -> 10 | P37: =SUM(C37:N37) -> 33
B38: 14.00 - 14.15 | C38: 1 | D38: 0 | E38: 1 | F38: 0 | G38: 0 | H38: 0 | I38: 1 | J38: 0 | K38: 0 | L38: 0 | M38: 26 | N38: 0 | O38: =SUM(C38:L38,N38) -> 3 | P38: =SUM(C38:N38) -> 29
B39: 14.15 - 14.30 | C39: 2 | D39: 1 | E39: 4 | F39: 6 | G39: 1 | H39: 0 | I39: 2 | J39: 0 | K39: 0 | L39: 0 | M39: 17 | N39: 0 | O39: =SUM(C39:L39,N39) -> 16 | P39: =SUM(C39:N39) -> 33
B40: 14.30 - 14.45 | C40: 4 | D40: 0 | E40: 2 | F40: 3 | G40: 0 | H40: 0 | I40: 0 | J40: 0 | K40: 0 | L40: 0 | M40: 33 | N40: 0 | O40: =SUM(C40:L40,N40) -> 9 | P40: =SUM(C40:N40) -> 42
... B57: 18.45 - 19.00 | C57: 1 | D57: 0 | E57: 1 | F57: 3 | G57: 1 | H57: 2 | I57: 1 | J57: 0 | K57: 0 | L57: 0 | M57: 16 | N57: 0 | O57: =SUM(C57:L57,N57) -> 9 | P57: =SUM(C57:N57) -> 25
B58: Totals | C58: =SUM(C10:C57) -> 126 | D58: =SUM(D10:D57) -> 5 | E58: =SUM(E10:E57) -> 79 | F58: =SUM(F10:F57) -> 105 | G58: =SUM(G10:G57) -> 4 | H58: =SUM(H10:H57) -> 2 | I58: =SUM(I10:I57) -> 35 | J58: =SUM(J10:J57) -> 4 | ... P58: =SUM(P10:P57) -> 1434
...

Sheet 13.08 Malaba-Tororo
B1: Consultancy services for Preparation of Expressway Development Master Plan (EDMP) for Uganda
B2: MANUAL CLASSIFIED COUNT (MCC)
B3: ROAD NAME: | C3: ='12.08 Malaba-Tororo'!C3:G3 -> MCC - C3b- STN143 - TORORO-MALABA ROAD
C5: Date | D5: 13.08.19 | F5: Location | G5: ='12.08 Malaba-Tororo'!G5:H5 -> xxx | J5: Surveyor | K5: ='12.08 Malaba-Tororo'!K5:L5 -> xxx
C6: Dir. From | D6: ='12.08 Malaba-Tororo'!D6:E6 -> Malaba | F6: Dir. To | G6: ='12.08 Malaba-Tororo'!G6:H6 -> Tororo | J6: Supervisor | K6: ='12.08 Malaba-Tororo'!K6:L6 -> xxx
B8: Time / Veh Type | R8: SUMMARY TRAFFIC VOLUMES
C9: 1. Car | D9: 2. Station Wagon | E9: 3. Pickups | F9: 4. Minibus, matatu | G9: 5. Medium bus | H9: 6. Large Bus | I9: 7. Light Truck | J9: 8. Medium Truck | K9: 9. Heavy truck | L9: 10. Truck Trailer | M9: 11. Motor cycles | N9: 12. Tractors | O9: Total Excl M/Cycles | P9: Total All | R9: Time | S9: 1. Car | T9: 2. Station Wagon | U9: 3. Pickups | V9: 4. Minibus, matatu | W9: 5. Medium bus | X9: 6. Large Bus | Y9: 7. Light Truck | Z9: 8. Medium Truck | AA9: 9. Heavy truck | AB9: 10. Truck Trailer | AC9: 11. Motorcycles | AD9: 12. Tractors, Graders | AE9: Total Excl M/ Cycles | AF9: Total All
B10: 07.00 - 07.15 | C10: 0 | D10: 0 | E10: 1 | F10: 1 | G10: 0 | H10: 1 | I10: 0 | J10: 0 | K10: 0 | L10: 0 | M10: 15 | N10: 0 | O10: =SUM(C10:L10,N10) -> 3 | P10: =SUM(C10:N10) -> 18 | R10: 0700-0800 | S10: =SUM(C10:C13) -> 4 | T10: =SUM(D10:D13) -> 0 | U10: =SUM(E10:E13) -> 2 | V10: =SUM(F10:F13) -> 5 | W10: =SUM(G10:G13) -> 0 | X10: =SUM(H10:H13) -> 2 | Y10: =SUM(I10:I13) -> 3 | Z10: =SUM(J10:J13) -> 0 | ... AF10: =SUM(P10:P13) -> 85
B11: 07.15 - 07.30 | C11: 2 | D11: 0 | E11: 0 | F11: 1 | G11: 0 | H11: 1 | I11: 1 | J11: 0 | K11: 0 | L11: 0 | M11: 20 | N11: 0 | O11: =SUM(C11:L11,N11) -> 5 | P11: =SUM(C11:N11) -> 25 | R11: 0800-0900 | S11: =SUM(C14:C17) -> 7 | T11: =SUM(D14:D17) -> 0 | U11: =SUM(E14:E17) -> 7 | V11: =SUM(F14:F17) -> 7 | W11: =SUM(G14:G17) -> 0 | X11: =SUM(H14:H17) -> 1 | Y11: =SUM(I14:I17) -> 4 | Z11: =SUM(J14:J17) -> 0 | ... AF11: =SUM(P14:P17) -> 120
B12: 07.30 - 07.45 | C12: 1 | D12: 0 | E12: 0 | F12: 2 | G12: 0 | H12: 0 | I12: 2 | J12: 0 | K12: 0 | L12: 0 | M12: 13 | N12: 0 | O12: =SUM(C12:L12,N12) -> 5 | P12: =SUM(C12:N12) -> 18 | R12: 0900-1000 | S12: =SUM(C18:C21) -> 12 | T12: =SUM(D18:D21) -> 0 | U12: =SUM(E18:E21) -> 7 | V12: =SUM(F18:F21) -> 7 | W12: =SUM(G18:G21) -> 0 | X12: =SUM(H18:H21) -> 0 | Y12: =SUM(I18:I21) -> 5 | Z12: =SUM(J18:J21) -> 0 | ... AF12: =SUM(P18:P21) -> 147
B13: 07.45 - 08.00 | C13: 1 | D13: 0 | E13: 1 | F13: 1 | G13: 0 | H13: 0 | I13: 0 | J13: 0 | K13: 0 | L13: 0 | M13: 21 | N13: 0 | O13: =SUM(C13:L13,N13) -> 3 | P13: =SUM(C13:N13) -> 24 | R13: 1000-1100 | S13: =SUM(C22:C25) -> 11 | T13: =SUM(D22:D25) -> 1 | U13: =SUM(E22:E25) -> 11 | V13: =SUM(F22:F25) -> 9 | W13: =SUM(G22:G25) -> 2 | X13: =SUM(H22:H25) -> 0 | Y13: =SUM(I22:I25) -> 4 | Z13: =SUM(J22:J25) -> 17 | ... AF13: =SUM(P22:P25) -> 184
B14: 08.00 - 08.15 | C14: 2 | D14: 0 | E14: 3 | F14: 2 | G14: 0 | H14: 0 | I14: 1 | J14: 0 | K14: 0 | L14: 0 | M14: 20 | N14: 0 | O14: =SUM(C14:L14,N14) -> 8 | P14: =SUM(C14:N14) -> 28 | R14: 1100-1200 | S14: =SUM(C26:C29) -> 8 | T14: =SUM(D26:D29) -> 1 | U14: =SUM(E26:E29) -> 9 | V14: =SUM(F26:F29) -> 8 | W14: =SUM(G26:G29) -> 0 | X14: =SUM(H26:H29) -> 0 | Y14: =SUM(I26:I29) -> 9 | Z14: =SUM(J26:J29) -> 0 | ... AF14: =SUM(P26:P29) -> 134
B15: 08.15 - 08.30 | C15: 3 | D15: 0 | E15: 1 | F15: 2 | G15: 0 | H15: 0 | I15: 1 | J15: 0 | K15: 0 | L15: 0 | M15: 24 | N15: 0 | O15: =SUM(C15:L15,N15) -> 7 | P15: =SUM(C15:N15) -> 31 | R15: 1200-1300 | S15: =SUM(C30:C33) -> 7 | T15: =SUM(D30:D33) -> 0 | U15: =SUM(E30:E33) -> 8 | V15: =SUM(F30:F33) -> 7 | W15: =SUM(G30:G33) -> 0 | X15: =SUM(H30:H33) -> 0 | Y15: =SUM(I30:I33) -> 8 | Z15: =SUM(J30:J33) -> 0 | ... AF15: =SUM(P30:P33) -> 134
B16: 08.30 - 08.45 | C16: 1 | D16: 0 | E16: 2 | F16: 1 | G16: 0 | H16: 1 | I16: 1 | J16: 0 | K16: 0 | L16: 0 | M16: 20 | N16: 0 | O16: =SUM(C16:L16,N16) -> 6 | P16: =SUM(C16:N16) -> 26 | R16: 1300-1400 | S16: =SUM(C34:C37) -> 11 | T16: =SUM(D34:D37) -> 3 | U16: =SUM(E34:E37) -> 17 | V16: =SUM(F34:F37) -> 10 | W16: =SUM(G34:G37) -> 0 | X16: =SUM(H34:H37) -> 0 | Y16: =SUM(I34:I37) -> 7 | Z16: =SUM(J34:J37) -> 3 | ... AF16: =SUM(P34:P37) -> 153
B17: 08.45 - 9.00 | C17: 1 | D17: 0 | E17: 1 | F17: 2 | G17: 0 | H17: 0 | I17: 1 | J17: 0 | K17: 0 | L17: 0 | M17: 30 | N17: 0 | O17: =SUM(C17:L17,N17) -> 5 | P17: =SUM(C17:N17) -> 35 | R17: 1400-1500 | S17: =SUM(C38:C41) -> 5 | T17: =SUM(D38:D41) -> 1 | U17: =SUM(E38:E41) -> 13 | V17: =SUM(F38:F41) -> 9 | W17: =SUM(G38:G41) -> 0 | X17: =SUM(H38:H41) -> 0 | Y17: =SUM(I38:I41) -> 4 | Z17: =SUM(J38:J41) -> 4 | ... AF17: =SUM(P38:P41) -> 132
B18: 09.00 - 09.15 | C18: 6 | D18: 0 | E18: 0 | F18: 2 | G18: 0 | H18: 0 | I18: 0 | J18: 0 | K18: 0 | L18: 0 | M18: 26 | N18: 0 | O18: =SUM(C18:L18,N18) -> 8 | P18: =SUM(C18:N18) -> 34 | R18: 1500-1600 | S18: =SUM(C42:C45) -> 12 | T18: =SUM(D42:D45) -> 1 | U18: =SUM(E42:E45) -> 10 | V18: =SUM(F42:F45) -> 6 | W18: =SUM(G42:G45) -> 0 | X18: =SUM(H42:H45) -> 0 | Y18: =SUM(I42:I45) -> 5 | Z18: =SUM(J42:J45) -> 2 | ... AF18: =SUM(P42:P45) -> 150
B19: 09.15 - 09.30 | C19: 2 | D19: 0 | E19: 3 | F19: 0 | G19: 0 | H19: 0 | I19: 1 | J19: 0 | K19: 0 | L19: 0 | M19: 23 | N19: 0 | O19: =SUM(C19:L19,N19) -> 6 | P19: =SUM(C19:N19) -> 29 | R19: 1600-1700 | S19: =SUM(C46:C49) -> 12 | T19: =SUM(D46:D49) -> 2 | U19: =SUM(E46:E49) -> 15 | V19: =SUM(F46:F49) -> 12 | W19: =SUM(G46:G49) -> 1 | X19: =SUM(H46:H49) -> 0 | Y19: =SUM(I46:I49) -> 6 | Z19: =SUM(J46:J49) -> 0 | ... AF19: =SUM(P46:P49) -> 155
B20: 09.30 - 09.45 | C20: 2 | D20: 0 | E20: 3 | F20: 3 | G20: 0 | H20: 0 | I20: 2 | J20: 0 | K20: 0 | L20: 0 | M20: 41 | N20: 0 | O20: =SUM(C20:L20,N20) -> 10 | P20: =SUM(C20:N20) -> 51 | R20: 1700-1800 | S20: =SUM(C50:C53) -> 11 | T20: =SUM(D50:D53) -> 2 | U20: =SUM(E50:E53) -> 15 | V20: =SUM(F50:F53) -> 14 | W20: =SUM(G50:G53) -> 1 | X20: =SUM(H50:H53) -> 0 | Y20: =SUM(I50:I53) -> 5 | Z20: =SUM(J50:J53) -> 1 | ... AF20: =SUM(P50:P53) -> 139
B21: 09.45 - 10.00 | C21: 2 | D21: 0 | E21: 1 | F21: 2 | G21: 0 | H21: 0 | I21: 2 | J21: 0 | K21: 0 | L21: 0 | M21: 26 | N21: 0 | O21: =SUM(C21:L21,N21) -> 7 | P21: =SUM(C21:N21) -> 33 | R21: 1800-1900 | S21: =SUM(C54:C57) -> 25 | T21: =SUM(D54:D57) -> 3 | U21: =SUM(E54:E57) -> 17 | V21: =SUM(F54:F57) -> 8 | W21: =SUM(G54:G57) -> 0 | X21: =SUM(H54:H57) -> 0 | Y21: =SUM(I54:I57) -> 6 | Z21: =SUM(J54:J57) -> 2 | ... AF21: =SUM(P54:P57) -> 180
B22: 10.00 - 10.15 | C22: 1 | D22: 0 | E22: 2 | F22: 2 | G22: 0 | H22: 0 | I22: 1 | J22: 0 | K22: 0 | L22: 0 | M22: 39 | N22: 0 | O22: =SUM(C22:L22,N22) -> 6 | P22: =SUM(C22:N22) -> 45 | R22: AM Peak Hr | S22: =MAX(S10:S12) -> 12 | T22: =MAX(T10:T12) -> 0 | U22: =MAX(U10:U12) -> 7 | V22: =MAX(V10:V12) -> 7 | W22: =MAX(W10:W12) -> 0 | X22: =MAX(X10:X12) -> 2 | Y22: =MAX(Y10:Y12) -> 5 | Z22: =MAX(Z10:Z12) -> 0 | ... AF22: =MAX(AF10:AF12) -> 147
B23: 10.15 - 10.30 | C23: 5 | D23: 0 | E23: 2 | F23: 4 | G23: 0 | H23: 0 | I23: 1 | J23: 0 | K23: 0 | L23: 0 | M23: 42 | N23: 0 | O23: =SUM(C23:L23,N23) -> 12 | P23: =SUM(C23:N23) -> 54 | R23: IP Peak Hr | S23: =MAX(S13:S18) -> 12 | T23: =MAX(T13:T18) -> 3 | U23: =MAX(U13:U18) -> 17 | V23: =MAX(V13:V18) -> 10 | W23: =MAX(W13:W18) -> 2 | X23: =MAX(X13:X18) -> 0 | Y23: =MAX(Y13:Y18) -> 9 | Z23: =MAX(Z13:Z18) -> 17 | ... AF23: =MAX(AF13:AF18) -> 184
B24: 10.30 - 10.45 | C24: 4 | D24: 0 | E24: 1 | F24: 2 | G24: 1 | H24: 0 | I24: 0 | J24: 17 | K24: 0 | L24: 0 | M24: 26 | N24: 0 | O24: =SUM(C24:L24,N24) -> 25 | P24: =SUM(C24:N24) -> 51 | R24: PM Peak Hr | S24: =MAX(S19:S21) -> 25 | T24: =MAX(T19:T21) -> 3 | U24: =MAX(U19:U21) -> 17 | V24: =MAX(V19:V21) -> 14 | W24: =MAX(W19:W21) -> 1 | X24: =MAX(X19:X21) -> 0 | Y24: =MAX(Y19:Y21) -> 6 | Z24: =MAX(Z19:Z21) -> 2 | ... AF24: =MAX(AF19:AF21) -> 180
B25: 10.45 - 11.00 | C25: 1 | D25: 1 | E25: 6 | F25: 1 | G25: 1 | H25: 0 | I25: 2 | J25: 0 | K25: 0 | L25: 0 | M25: 22 | N25: 0 | O25: =SUM(C25:L25,N25) -> 12 | P25: =SUM(C25:N25) -> 34 | R25: AM Period | S25: =SUM(S10:S12) -> 23 | T25: =SUM(T10:T12) -> 0 | U25: =SUM(U10:U12) -> 16 | V25: =SUM(V10:V12) -> 19 | W25: =SUM(W10:W12) -> 0 | X25: =SUM(X10:X12) -> 3 | Y25: =SUM(Y10:Y12) -> 12 | Z25: =SUM(Z10:Z12) -> 0 | ... AF25: =SUM(AF10:AF12) -> 352
B26: 11.00 - 11.15 | C26: 4 | D26: 0 | E26: 2 | F26: 1 | G26: 0 | H26: 0 | I26: 3 | J26: 0 | K26: 0 | L26: 0 | M26: 30 | N26: 0 | O26: =SUM(C26:L26,N26) -> 10 | P26: =SUM(C26:N26) -> 40 | R26: IP Period | S26: =SUM(S13:S18) -> 54 | T26: =SUM(T13:T18) -> 7 | U26: =SUM(U13:U18) -> 68 | V26: =SUM(V13:V18) -> 49 | W26: =SUM(W13:W18) -> 2 | X26: =SUM(X13:X18) -> 0 | Y26: =SUM(Y13:Y18) -> 37 | Z26: =SUM(Z13:Z18) -> 26 | ... AF26: =SUM(AF13:AF18) -> 887
B27: 11.15 - 11.30 | C27: 1 | D27: 0 | E27: 0 | F27: 4 | G27: 0 | H27: 0 | I27: 1 | J27: 0 | K27: 0 | L27: 0 | M27: 16 | N27: 0 | O27: =SUM(C27:L27,N27) -> 6 | P27: =SUM(C27:N27) -> 22 | R27: PM Period | S27: =SUM(S19:S21) -> 48 | T27: =SUM(T19:T21) -> 7 | U27: =SUM(U19:U21) -> 47 | V27: =SUM(V19:V21) -> 34 | W27: =SUM(W19:W21) -> 2 | X27: =SUM(X19:X21) -> 0 | Y27: =SUM(Y19:Y21) -> 17 | Z27: =SUM(Z19:Z21) -> 3 | ... AF27: =SUM(AF19:AF21) -> 474
B28: 11.30 - 11.45 | C28: 1 | D28: 0 | E28: 3 | F28: 1 | G28: 0 | H28: 0 | I28: 1 | J28: 0 | K28: 0 | L28: 0 | M28: 31 | N28: 0 | O28: =SUM(C28:L28,N28) -> 6 | P28: =SUM(C28:N28) -> 37 | R28: 12 Hours | S28: =SUM(S10:S21) -> 125 | T28: =SUM(T10:T21) -> 14 | U28: =SUM(U10:U21) -> 131 | V28: =SUM(V10:V21) -> 102 | W28: =SUM(W10:W21) -> 4 | X28: =SUM(X10:X21) -> 3 | Y28: =SUM(Y10:Y21) -> 66 | Z28: =SUM(Z10:Z21) -> 29 | ... AF28: =SUM(AF10:AF21) -> 1713
B29: 11.45 - 12.00 | C29: 2 | D29: 1 | E29: 4 | F29: 2 | G29: 0 | H29: 0 | I29: 4 | J29: 0 | K29: 0 | L29: 0 | M29: 22 | N29: 0 | O29: =SUM(C29:L29,N29) -> 13 | P29: =SUM(C29:N29) -> 35
B30: 12.00 - 12.15 | C30: 1 | D30: 0 | E30: 2 | F30: 1 | G30: 0 | H30: 0 | I30: 4 | J30: 0 | K30: 0 | L30: 0 | M30: 18 | N30: 0 | O30: =SUM(C30:L30,N30) -> 8 | P30: =SUM(C30:N30) -> 26
B31: 12.15 - 12.30 | C31: 2 | D31: 0 | E31: 3 | F31: 2 | G31: 0 | H31: 0 | I31: 2 | J31: 0 | K31: 0 | L31: 0 | M31: 23 | N31: 0 | O31: =SUM(C31:L31,N31) -> 9 | P31: =SUM(C31:N31) -> 32
B32: 12.30 - 12.45 | C32: 2 | D32: 0 | E32: 2 | F32: 2 | G32: 0 | H32: 0 | I32: 1 | J32: 0 | K32: 0 | L32: 0 | M32: 34 | N32: 0 | O32: =SUM(C32:L32,N32) -> 7 | P32: =SUM(C32:N32) -> 41
B33: 12.45 - 13.00 | C33: 2 | D33: 0 | E33: 1 | F33: 2 | G33: 0 | H33: 0 | I33: 1 | J33: 0 | K33: 0 | L33: 0 | M33: 29 | N33: 0 | O33: =SUM(C33:L33,N33) -> 6 | P33: =SUM(C33:N33) -> 35
B34: 13.00 - 13.15 | C34: 4 | D34: 1 | E34: 4 | F34: 3 | G34: 0 | H34: 0 | I34: 1 | J34: 1 | K34: 0 | L34: 0 | M34: 16 | N34: 0 | O34: =SUM(C34:L34,N34) -> 14 | P34: =SUM(C34:N34) -> 30
B35: 13.15 - 13.30 | C35: 4 | D35: 0 | E35: 3 | F35: 2 | G35: 0 | H35: 0 | I35: 0 | J35: 0 | K35: 2 | L35: 0 | M35: 30 | N35: 0 | O35: =SUM(C35:L35,N35) -> 11 | P35: =SUM(C35:N35) -> 41
B36: 13.30 - 13.45 | C36: 2 | D36: 2 | E36: 7 | F36: 3 | G36: 0 | H36: 0 | I36: 4 | J36: 0 | K36: 0 | L36: 0 | M36: 17 | N36: 0 | O36: =SUM(C36:L36,N36) -> 18 | P36: =SUM(C36:N36) -> 35
B37: 13.45 - 14.00 | C37: 1 | D37: 0 | E37: 3 | F37: 2 | G37: 0 | H37: 0 | I37: 2 | J37: 2 | K37: 0 | L37: 0 | M37: 37 | N37: 0 | O37: =SUM(C37:L37,N37) -> 10 | P37: =SUM(C37:N37) -> 47
B38: 14.00 - 14.15 | C38: 1 | D38: 0 | E38: 3 | F38: 3 | G38: 0 | H38: 0 | I38: 2 | J38: 1 | K38: 0 | L38: 0 | M38: 25 | N38: 0 | O38: =SUM(C38:L38,N38) -> 10 | P38: =SUM(C38:N38) -> 35
B39: 14.15 - 14.30 | C39: 0 | D39: 0 | E39: 3 | F39: 0 | G39: 0 | H39: 0 | I39: 0 | J39: 1 | K39: 0 | L39: 0 | M39: 18 | N39: 0 | O39: =SUM(C39:L39,N39) -> 4 | P39: =SUM(C39:N39) -> 22
B40: 14.30 - 14.45 | C40: 4 | D40: 1 | E40: 4 | F40: 5 | G40: 0 | H40: 0 | I40: 1 | J40: 0 | K40: 0 | L40: 0 | M40: 23 | N40: 0 | O40: =SUM(C40:L40,N40) -> 15 | P40: =SUM(C40:N40) -> 38
... B57: 18.45 - 19.00 | C57: 9 | D57: 0 | E57: 3 | F57: 0 | G57: 0 | H57: 0 | I57: 2 | J57: 1 | K57: 0 | L57: 0 | M57: 31 | N57: 0 | O57: =SUM(C57:L57,N57) -> 15 | P57: =SUM(C57:N57) -> 46
B58: Totals | C58: =SUM(C10:C57) -> 125 | D58: =SUM(D10:D57) -> 14 | E58: =SUM(E10:E57) -> 131 | F58: =SUM(F10:F57) -> 102 | G58: =SUM(G10:G57) -> 4 | H58: =SUM(H10:H57) -> 3 | I58: =SUM(I10:I57) -> 66 | J58: =SUM(J10:J57) -> 29 | ... P58: =SUM(P10:P57) -> 1713
...

Sheet 13.08 Tororo-Malaba
B1: Consultancy services for Preparation of Expressway Development Master Plan (EDMP) for Uganda
B2: MANUAL CLASSIFIED COUNT (MCC)
B3: ROAD NAME: | C3: ='12.08 Tororo-Malaba'!C3:G3 -> MCC - C3b- STN143 - TORORO-MALABA ROAD
C5: Date | D5: ='13.08 Malaba-Tororo'!D5 -> 13.08.19 | F5: Location | G5: ='12.08 Malaba-Tororo'!G5:H5 -> xxx | J5: Surveyor | K5: ='12.08 Malaba-Tororo'!K5:L5 -> xxx
C6: Dir. From | D6: ='12.08 Tororo-Malaba'!D6:E6 -> Tororo | F6: Dir. To | G6: ='12.08 Tororo-Malaba'!G6:H6 -> Malaba | J6: Supervisor | K6: ='12.08 Malaba-Tororo'!K6:L6 -> xxx
B8: Time / Veh Type | R8: SUMMARY TRAFFIC VOLUMES
C9: 1. Car | D9: 2. Station Wagon | E9: 3. Pickups | F9: 4. Minibus, matatu | G9: 5. Medium bus | H9: 6. Large Bus | I9: 7. Light Truck | J9: 8. Medium Truck | K9: 9. Heavy truck | L9: 10. Truck Trailer | M9: 11. Motor cycles | N9: 12. Tractors | O9: Total Excl M/Cycles | P9: Total All | R9: Time | S9: 1. Car | T9: 2. Station Wagon | U9: 3. Pickups | V9: 4. Minibus, matatu | W9: 5. Medium bus | X9: 6. Large Bus | Y9: 7. Light Truck | Z9: 8. Medium Truck | AA9: 9. Heavy truck | AB9: 10. Truck Trailer | AC9: 11. Motorcycles | AD9: 12. Tractors, Graders | AE9: Total Excl M/ Cycles | AF9: Total All
B10: 07.00 - 07.15 | C10: 0 | D10: 0 | E10: 1 | F10: 0 | G10: 0 | H10: 0 | I10: 1 | J10: 0 | K10: 0 | L10: 0 | M10: 9 | N10: 0 | O10: =SUM(C10:L10,N10) -> 2 | P10: =SUM(C10:N10) -> 11 | R10: 0700-0800 | S10: =SUM(C10:C13) -> 3 | T10: =SUM(D10:D13) -> 0 | U10: =SUM(E10:E13) -> 5 | V10: =SUM(F10:F13) -> 2 | W10: =SUM(G10:G13) -> 1 | X10: =SUM(H10:H13) -> 0 | Y10: =SUM(I10:I13) -> 5 | Z10: =SUM(J10:J13) -> 0 | ... AF10: =SUM(P10:P13) -> 99
B11: 07.15 - 07.30 | C11: 3 | D11: 0 | E11: 2 | F11: 0 | G11: 0 | H11: 0 | I11: 2 | J11: 0 | K11: 0 | L11: 0 | M11: 17 | N11: 0 | O11: =SUM(C11:L11,N11) -> 7 | P11: =SUM(C11:N11) -> 24 | R11: 0800-0900 | S11: =SUM(C14:C17) -> 4 | T11: =SUM(D14:D17) -> 0 | U11: =SUM(E14:E17) -> 6 | V11: =SUM(F14:F17) -> 8 | W11: =SUM(G14:G17) -> 0 | X11: =SUM(H14:H17) -> 0 | Y11: =SUM(I14:I17) -> 5 | Z11: =SUM(J14:J17) -> 0 | ... AF11: =SUM(P14:P17) -> 107
B12: 07.30 - 07.45 | C12: 0 | D12: 0 | E12: 0 | F12: 0 | G12: 1 | H12: 0 | I12: 0 | J12: 0 | K12: 0 | L12: 0 | M12: 20 | N12: 0 | O12: =SUM(C12:L12,N12) -> 1 | P12: =SUM(C12:N12) -> 21 | R12: 0900-1000 | S12: =SUM(C18:C21) -> 11 | T12: =SUM(D18:D21) -> 0 | U12: =SUM(E18:E21) -> 5 | V12: =SUM(F18:F21) -> 6 | W12: =SUM(G18:G21) -> 0 | X12: =SUM(H18:H21) -> 0 | Y12: =SUM(I18:I21) -> 2 | Z12: =SUM(J18:J21) -> 0 | ... AF12: =SUM(P18:P21) -> 148
B13: 07.45 - 08.00 | C13: 0 | D13: 0 | E13: 2 | F13: 2 | G13: 0 | H13: 0 | I13: 2 | J13: 0 | K13: 0 | L13: 0 | M13: 37 | N13: 0 | O13: =SUM(C13:L13,N13) -> 6 | P13: =SUM(C13:N13) -> 43 | R13: 1000-1100 | S13: =SUM(C22:C25) -> 11 | T13: =SUM(D22:D25) -> 1 | U13: =SUM(E22:E25) -> 9 | V13: =SUM(F22:F25) -> 8 | W13: =SUM(G22:G25) -> 0 | X13: =SUM(H22:H25) -> 0 | Y13: =SUM(I22:I25) -> 5 | Z13: =SUM(J22:J25) -> 2 | ... AF13: =SUM(P22:P25) -> 137
B14: 08.00 - 08.15 | C14: 1 | D14: 0 | E14: 1 | F14: 0 | G14: 0 | H14: 0 | I14: 2 | J14: 0 | K14: 0 | L14: 0 | M14: 25 | N14: 0 | O14: =SUM(C14:L14,N14) -> 4 | P14: =SUM(C14:N14) -> 29 | R14: 1100-1200 | S14: =SUM(C26:C29) -> 20 | T14: =SUM(D26:D29) -> 0 | U14: =SUM(E26:E29) -> 9 | V14: =SUM(F26:F29) -> 8 | W14: =SUM(G26:G29) -> 0 | X14: =SUM(H26:H29) -> 0 | Y14: =SUM(I26:I29) -> 3 | Z14: =SUM(J26:J29) -> 0 | ... AF14: =SUM(P26:P29) -> 137
B15: 08.15 - 08.30 | C15: 1 | D15: 0 | E15: 0 | F15: 2 | G15: 0 | H15: 0 | I15: 1 | J15: 0 | K15: 0 | L15: 0 | M15: 19 | N15: 0 | O15: =SUM(C15:L15,N15) -> 4 | P15: =SUM(C15:N15) -> 23 | R15: 1200-1300 | S15: =SUM(C30:C33) -> 11 | T15: =SUM(D30:D33) -> 3 | U15: =SUM(E30:E33) -> 14 | V15: =SUM(F30:F33) -> 7 | W15: =SUM(G30:G33) -> 0 | X15: =SUM(H30:H33) -> 0 | Y15: =SUM(I30:I33) -> 1 | Z15: =SUM(J30:J33) -> 0 | ... AF15: =SUM(P30:P33) -> 160
B16: 08.30 - 08.45 | C16: 1 | D16: 0 | E16: 3 | F16: 2 | G16: 0 | H16: 0 | I16: 1 | J16: 0 | K16: 0 | L16: 0 | M16: 19 | N16: 0 | O16: =SUM(C16:L16,N16) -> 7 | P16: =SUM(C16:N16) -> 26 | R16: 1300-1400 | S16: =SUM(C34:C37) -> 15 | T16: =SUM(D34:D37) -> 3 | U16: =SUM(E34:E37) -> 16 | V16: =SUM(F34:F37) -> 12 | W16: =SUM(G34:G37) -> 0 | X16: =SUM(H34:H37) -> 0 | Y16: =SUM(I34:I37) -> 4 | Z16: =SUM(J34:J37) -> 1 | ... AF16: =SUM(P34:P37) -> 169
B17: 08.45 - 9.00 | C17: 1 | D17: 0 | E17: 2 | F17: 4 | G17: 0 | H17: 0 | I17: 1 | J17: 0 | K17: 0 | L17: 0 | M17: 21 | N17: 0 | O17: =SUM(C17:L17,N17) -> 8 | P17: =SUM(C17:N17) -> 29 | R17: 1400-1500 | S17: =SUM(C38:C41) -> 20 | T17: =SUM(D38:D41) -> 4 | U17: =SUM(E38:E41) -> 20 | V17: =SUM(F38:F41) -> 10 | W17: =SUM(G38:G41) -> 0 | X17: =SUM(H38:H41) -> 0 | Y17: =SUM(I38:I41) -> 3 | Z17: =SUM(J38:J41) -> 0 | ... AF17: =SUM(P38:P41) -> 162
B18: 09.00 - 09.15 | C18: 2 | D18: 0 | E18: 1 | F18: 1 | G18: 0 | H18: 0 | I18: 0 | J18: 0 | K18: 0 | L18: 0 | M18: 33 | N18: 0 | O18: =SUM(C18:L18,N18) -> 4 | P18: =SUM(C18:N18) -> 37 | R18: 1500-1600 | S18: =SUM(C42:C45) -> 12 | T18: =SUM(D42:D45) -> 0 | U18: =SUM(E42:E45) -> 9 | V18: =SUM(F42:F45) -> 15 | W18: =SUM(G42:G45) -> 0 | X18: =SUM(H42:H45) -> 0 | Y18: =SUM(I42:I45) -> 5 | Z18: =SUM(J42:J45) -> 0 | ... AF18: =SUM(P42:P45) -> 143
B19: 09.15 - 09.30 | C19: 5 | D19: 0 | E19: 0 | F19: 1 | G19: 0 | H19: 0 | I19: 0 | J19: 0 | K19: 0 | L19: 0 | M19: 31 | N19: 0 | O19: =SUM(C19:L19,N19) -> 6 | P19: =SUM(C19:N19) -> 37 | R19: 1600-1700 | S19: =SUM(C46:C49) -> 9 | T19: =SUM(D46:D49) -> 0 | U19: =SUM(E46:E49) -> 6 | V19: =SUM(F46:F49) -> 12 | W19: =SUM(G46:G49) -> 1 | X19: =SUM(H46:H49) -> 0 | Y19: =SUM(I46:I49) -> 4 | Z19: =SUM(J46:J49) -> 0 | ... AF19: =SUM(P46:P49) -> 126
B20: 09.30 - 09.45 | C20: 2 | D20: 0 | E20: 3 | F20: 2 | G20: 0 | H20: 0 | I20: 0 | J20: 0 | K20: 0 | L20: 0 | M20: 27 | N20: 0 | O20: =SUM(C20:L20,N20) -> 7 | P20: =SUM(C20:N20) -> 34 | R20: 1700-1800 | S20: =SUM(C50:C53) -> 10 | T20: =SUM(D50:D53) -> 2 | U20: =SUM(E50:E53) -> 11 | V20: =SUM(F50:F53) -> 7 | W20: =SUM(G50:G53) -> 1 | X20: =SUM(H50:H53) -> 0 | Y20: =SUM(I50:I53) -> 3 | Z20: =SUM(J50:J53) -> 2 | ... AF20: =SUM(P50:P53) -> 139
B21: 09.45 - 10.00 | C21: 2 | D21: 0 | E21: 1 | F21: 2 | G21: 0 | H21: 0 | I21: 2 | J21: 0 | K21: 0 | L21: 0 | M21: 32 | N21: 1 | O21: =SUM(C21:L21,N21) -> 8 | P21: =SUM(C21:N21) -> 40 | R21: 1800-1900 | S21: =SUM(C54:C57) -> 9 | T21: =SUM(D54:D57) -> 1 | U21: =SUM(E54:E57) -> 8 | V21: =SUM(F54:F57) -> 9 | W21: =SUM(G54:G57) -> 1 | X21: =SUM(H54:H57) -> 1 | Y21: =SUM(I54:I57) -> 3 | Z21: =SUM(J54:J57) -> 0 | ... AF21: =SUM(P54:P57) -> 133
B22: 10.00 - 10.15 | C22: 3 | D22: 0 | E22: 0 | F22: 2 | G22: 0 | H22: 0 | I22: 2 | J22: 0 | K22: 0 | L22: 0 | M22: 36 | N22: 0 | O22: =SUM(C22:L22,N22) -> 7 | P22: =SUM(C22:N22) -> 43 | R22: AM Peak Hr | S22: =MAX(S10:S12) -> 11 | T22: =MAX(T10:T12) -> 0 | U22: =MAX(U10:U12) -> 6 | V22: =MAX(V10:V12) -> 8 | W22: =MAX(W10:W12) -> 1 | X22: =MAX(X10:X12) -> 0 | Y22: =MAX(Y10:Y12) -> 5 | Z22: =MAX(Z10:Z12) -> 0 | ... AF22: =MAX(AF10:AF12) -> 148
B23: 10.15 - 10.30 | C23: 4 | D23: 1 | E23: 4 | F23: 1 | G23: 0 | H23: 0 | I23: 2 | J23: 2 | K23: 0 | L23: 0 | M23: 24 | N23: 0 | O23: =SUM(C23:L23,N23) -> 14 | P23: =SUM(C23:N23) -> 38 | R23: IP Peak Hr | S23: =MAX(S13:S18) -> 20 | T23: =MAX(T13:T18) -> 4 | U23: =MAX(U13:U18) -> 20 | V23: =MAX(V13:V18) -> 15 | W23: =MAX(W13:W18) -> 0 | X23: =MAX(X13:X18) -> 0 | Y23: =MAX(Y13:Y18) -> 5 | Z23: =MAX(Z13:Z18) -> 2 | ... AF23: =MAX(AF13:AF18) -> 169
B24: 10.30 - 10.45 | C24: 3 | D24: 0 | E24: 3 | F24: 4 | G24: 0 | H24: 0 | I24: 1 | J24: 0 | K24: 0 | L24: 0 | M24: 23 | N24: 0 | O24: =SUM(C24:L24,N24) -> 11 | P24: =SUM(C24:N24) -> 34 | R24: PM Peak Hr | S24: =MAX(S19:S21) -> 10 | T24: =MAX(T19:T21) -> 2 | U24: =MAX(U19:U21) -> 11 | V24: =MAX(V19:V21) -> 12 | W24: =MAX(W19:W21) -> 1 | X24: =MAX(X19:X21) -> 1 | Y24: =MAX(Y19:Y21) -> 4 | Z24: =MAX(Z19:Z21) -> 2 | ... AF24: =MAX(AF19:AF21) -> 139
B25: 10.45 - 11.00 | C25: 1 | D25: 0 | E25: 2 | F25: 1 | G25: 0 | H25: 0 | I25: 0 | J25: 0 | K25: 0 | L25: 0 | M25: 18 | N25: 0 | O25: =SUM(C25:L25,N25) -> 4 | P25: =SUM(C25:N25) -> 22 | R25: AM Period | S25: =SUM(S10:S12) -> 18 | T25: =SUM(T10:T12) -> 0 | U25: =SUM(U10:U12) -> 16 | V25: =SUM(V10:V12) -> 16 | W25: =SUM(W10:W12) -> 1 | X25: =SUM(X10:X12) -> 0 | Y25: =SUM(Y10:Y12) -> 12 | Z25: =SUM(Z10:Z12) -> 0 | ... AF25: =SUM(AF10:AF12) -> 354
B26: 11.00 - 11.15 | C26: 6 | D26: 0 | E26: 3 | F26: 0 | G26: 0 | H26: 0 | I26: 0 | J26: 0 | K26: 0 | L26: 0 | M26: 28 | N26: 0 | O26: =SUM(C26:L26,N26) -> 9 | P26: =SUM(C26:N26) -> 37 | R26: IP Period | S26: =SUM(S13:S18) -> 89 | T26: =SUM(T13:T18) -> 11 | U26: =SUM(U13:U18) -> 77 | V26: =SUM(V13:V18) -> 60 | W26: =SUM(W13:W18) -> 0 | X26: =SUM(X13:X18) -> 0 | Y26: =SUM(Y13:Y18) -> 21 | Z26: =SUM(Z13:Z18) -> 3 | ... AF26: =SUM(AF13:AF18) -> 908
B27: 11.15 - 11.30 | C27: 3 | D27: 0 | E27: 2 | F27: 3 | G27: 0 | H27: 0 | I27: 1 | J27: 0 | K27: 0 | L27: 0 | M27: 24 | N27: 0 | O27: =SUM(C27:L27,N27) -> 9 | P27: =SUM(C27:N27) -> 33 | R27: PM Period | S27: =SUM(S19:S21) -> 28 | T27: =SUM(T19:T21) -> 3 | U27: =SUM(U19:U21) -> 25 | V27: =SUM(V19:V21) -> 28 | W27: =SUM(W19:W21) -> 3 | X27: =SUM(X19:X21) -> 1 | Y27: =SUM(Y19:Y21) -> 10 | Z27: =SUM(Z19:Z21) -> 2 | ... AF27: =SUM(AF19:AF21) -> 398
B28: 11.30 - 11.45 | C28: 5 | D28: 0 | E28: 3 | F28: 3 | G28: 0 | H28: 0 | I28: 1 | J28: 0 | K28: 0 | L28: 0 | M28: 20 | N28: 0 | O28: =SUM(C28:L28,N28) -> 12 | P28: =SUM(C28:N28) -> 32 | R28: 12 Hours | S28: =SUM(S10:S21) -> 135 | T28: =SUM(T10:T21) -> 14 | U28: =SUM(U10:U21) -> 118 | V28: =SUM(V10:V21) -> 104 | W28: =SUM(W10:W21) -> 4 | X28: =SUM(X10:X21) -> 1 | Y28: =SUM(Y10:Y21) -> 43 | Z28: =SUM(Z10:Z21) -> 5 | ... AF28: =SUM(AF10:AF21) -> 1660
B29: 11.45 - 12.00 | C29: 6 | D29: 0 | E29: 1 | F29: 2 | G29: 0 | H29: 0 | I29: 1 | J29: 0 | K29: 0 | L29: 0 | M29: 25 | N29: 0 | O29: =SUM(C29:L29,N29) -> 10 | P29: =SUM(C29:N29) -> 35
B30: 12.00 - 12.15 | C30: 0 | D30: 1 | E30: 4 | F30: 2 | G30: 0 | H30: 0 | I30: 0 | J30: 0 | K30: 0 | L30: 0 | M30: 32 | N30: 0 | O30: =SUM(C30:L30,N30) -> 7 | P30: =SUM(C30:N30) -> 39
B31: 12.15 - 12.30 | C31: 2 | D31: 2 | E31: 7 | F31: 1 | G31: 0 | H31: 0 | I31: 0 | J31: 0 | K31: 0 | L31: 0 | M31: 26 | N31: 0 | O31: =SUM(C31:L31,N31) -> 12 | P31: =SUM(C31:N31) -> 38
B32: 12.30 - 12.45 | C32: 5 | D32: 0 | E32: 1 | F32: 4 | G32: 0 | H32: 0 | I32: 1 | J32: 0 | K32: 0 | L32: 0 | M32: 32 | N32: 0 | O32: =SUM(C32:L32,N32) -> 11 | P32: =SUM(C32:N32) -> 43
B33: 12.45 - 13.00 | C33: 4 | D33: 0 | E33: 2 | F33: 0 | G33: 0 | H33: 0 | I33: 0 | J33: 0 | K33: 0 | L33: 0 | M33: 34 | N33: 0 | O33: =SUM(C33:L33,N33) -> 6 | P33: =SUM(C33:N33) -> 40
B34: 13.00 - 13.15 | C34: 1 | D34: 0 | E34: 1 | F34: 1 | G34: 0 | H34: 0 | I34: 0 | J34: 0 | K34: 0 | L34: 0 | M34: 35 | N34: 0 | O34: =SUM(C34:L34,N34) -> 3 | P34: =SUM(C34:N34) -> 38
B35: 13.15 - 13.30 | C35: 3 | D35: 1 | E35: 6 | F35: 6 | G35: 0 | H35: 0 | I35: 0 | J35: 0 | K35: 0 | L35: 0 | M35: 27 | N35: 0 | O35: =SUM(C35:L35,N35) -> 16 | P35: =SUM(C35:N35) -> 43
B36: 13.30 - 13.45 | C36: 8 | D36: 2 | E36: 8 | F36: 4 | G36: 0 | H36: 0 | I36: 1 | J36: 1 | K36: 0 | L36: 0 | M36: 32 | N36: 0 | O36: =SUM(C36:L36,N36) -> 24 | P36: =SUM(C36:N36) -> 56
B37: 13.45 - 14.00 | C37: 3 | D37: 0 | E37: 1 | F37: 1 | G37: 0 | H37: 0 | I37: 3 | J37: 0 | K37: 0 | L37: 0 | M37: 24 | N37: 0 | O37: =SUM(C37:L37,N37) -> 8 | P37: =SUM(C37:N37) -> 32
B38: 14.00 - 14.15 | C38: 3 | D38: 1 | E38: 6 | F38: 0 | G38: 0 | H38: 0 | I38: 2 | J38: 0 | K38: 0 | L38: 0 | M38: 30 | N38: 0 | O38: =SUM(C38:L38,N38) -> 12 | P38: =SUM(C38:N38) -> 42
B39: 14.15 - 14.30 | C39: 5 | D39: 0 | E39: 3 | F39: 5 | G39: 0 | H39: 0 | I39: 0 | J39: 0 | K39: 0 | L39: 0 | M39: 35 | N39: 0 | O39: =SUM(C39:L39,N39) -> 13 | P39: =SUM(C39:N39) -> 48
B40: 14.30 - 14.45 | C40: 5 | D40: 1 | E40: 4 | F40: 1 | G40: 0 | H40: 0 | I40: 1 | J40: 0 | K40: 0 | L40: 0 | M40: 16 | N40: 0 | O40: =SUM(C40:L40,N40) -> 12 | P40: =SUM(C40:N40) -> 28
... B57: 18.45 - 19.00 | C57: 3 | D57: 1 | E57: 4 | F57: 6 | G57: 0 | H57: 0 | I57: 1 | J57: 0 | K57: 0 | L57: 0 | M57: 21 | N57: 0 | O57: =SUM(C57:L57,N57) -> 15 | P57: =SUM(C57:N57) -> 36
B58: Totals | C58: =SUM(C10:C57) -> 135 | D58: =SUM(D10:D57) -> 14 | E58: =SUM(E10:E57) -> 118 | F58: =SUM(F10:F57) -> 104 | G58: =SUM(G10:G57) -> 4 | H58: =SUM(H10:H57) -> 1 | I58: =SUM(I10:I57) -> 43 | J58: =SUM(J10:J57) -> 5 | ... P58: =SUM(P10:P57) -> 1660
...

Sheet 14.08 Malaba-Tororo
B1: Consultancy services for Preparation of Expressway Development Master Plan (EDMP) for Uganda
B2: MANUAL CLASSIFIED COUNT (MCC)
B3: ROAD NAME: | C3: ='12.08 Malaba-Tororo'!C3:G3 -> MCC - C3b- STN143 - TORORO-MALABA ROAD
C5: Date | D5: 14.08.19 | F5: Location | G5: ='12.08 Malaba-Tororo'!G5:H5 -> xxx | J5: Surveyor | K5: ='12.08 Malaba-Tororo'!K5:L5 -> xxx
C6: Dir. From | D6: ='12.08 Malaba-Tororo'!D6:E6 -> Malaba | F6: Dir. To | G6: ='12.08 Malaba-Tororo'!G6:H6 -> Tororo | J6: Supervisor | K6: ='12.08 Malaba-Tororo'!K6:L6 -> xxx
B8: Time / Veh Type | R8: SUMMARY TRAFFIC VOLUMES
C9: 1. Car | D9: 2. Station Wagon | E9: 3. Pickups | F9: 4. Minibus, matatu | G9: 5. Medium bus | H9: 6. Large Bus | I9: 7. Light Truck | J9: 8. Medium Truck | K9: 9. Heavy truck | L9: 10. Truck Trailer | M9: 11. Motor cycles | N9: 12. Tractors | O9: Total Excl M/Cycles | P9: Total All | R9: Time | S9: 1. Car | T9: 2. Station Wagon | U9: 3. Pickups | V9: 4. Minibus, matatu | W9: 5. Medium bus | X9: 6. Large Bus | Y9: 7. Light Truck | Z9: 8. Medium Truck | AA9: 9. Heavy truck | AB9: 10. Truck Trailer | AC9: 11. Motorcycles | AD9: 12. Tractors, Graders | AE9: Total Excl M/ Cycles | AF9: Total All
B10: 07.00 - 07.15 | C10: 1 | D10: 1 | E10: 6 | F10: 3 | G10: 1 | H10: 0 | I10: 0 | J10: 0 | K10: 0 | L10: 0 | M10: 12 | N10: 0 | O10: =SUM(C10:L10,N10) -> 12 | P10: =SUM(C10:N10) -> 24 | R10: 0700-0800 | S10: =SUM(C10:C13) -> 3 | T10: =SUM(D10:D13) -> 1 | U10: =SUM(E10:E13) -> 9 | V10: =SUM(F10:F13) -> 8 | W10: =SUM(G10:G13) -> 1 | X10: =SUM(H10:H13) -> 1 | Y10: =SUM(I10:I13) -> 2 | Z10: =SUM(J10:J13) -> 0 | ... AF10: =SUM(P10:P13) -> 100
B11: 07.15 - 07.30 | C11: 0 | D11: 0 | E11: 2 | F11: 2 | G11: 0 | H11: 0 | I11: 1 | J11: 0 | K11: 0 | L11: 0 | M11: 22 | N11: 0 | O11: =SUM(C11:L11,N11) -> 5 | P11: =SUM(C11:N11) -> 27 | R11: 0800-0900 | S11: =SUM(C14:C17) -> 6 | T11: =SUM(D14:D17) -> 0 | U11: =SUM(E14:E17) -> 3 | V11: =SUM(F14:F17) -> 8 | W11: =SUM(G14:G17) -> 0 | X11: =SUM(H14:H17) -> 1 | Y11: =SUM(I14:I17) -> 1 | Z11: =SUM(J14:J17) -> 0 | ... AF11: =SUM(P14:P17) -> 132
B12: 07.30 - 07.45 | C12: 0 | D12: 0 | E12: 1 | F12: 2 | G12: 0 | H12: 1 | I12: 0 | J12: 0 | K12: 0 | L12: 0 | M12: 13 | N12: 0 | O12: =SUM(C12:L12,N12) -> 4 | P12: =SUM(C12:N12) -> 17 | R12: 0900-1000 | S12: =SUM(C18:C21) -> 8 | T12: =SUM(D18:D21) -> 1 | U12: =SUM(E18:E21) -> 8 | V12: =SUM(F18:F21) -> 9 | W12: =SUM(G18:G21) -> 0 | X12: =SUM(H18:H21) -> 0 | Y12: =SUM(I18:I21) -> 4 | Z12: =SUM(J18:J21) -> 0 | ... AF12: =SUM(P18:P21) -> 138
B13: 07.45 - 08.00 | C13: 2 | D13: 0 | E13: 0 | F13: 1 | G13: 0 | H13: 0 | I13: 1 | J13: 0 | K13: 0 | L13: 0 | M13: 28 | N13: 0 | O13: =SUM(C13:L13,N13) -> 4 | P13: =SUM(C13:N13) -> 32 | R13: 1000-1100 | S13: =SUM(C22:C25) -> 18 | T13: =SUM(D22:D25) -> 0 | U13: =SUM(E22:E25) -> 9 | V13: =SUM(F22:F25) -> 9 | W13: =SUM(G22:G25) -> 0 | X13: =SUM(H22:H25) -> 0 | Y13: =SUM(I22:I25) -> 4 | Z13: =SUM(J22:J25) -> 3 | ... AF13: =SUM(P22:P25) -> 163
B14: 08.00 - 08.15 | C14: 0 | D14: 0 | E14: 0 | F14: 2 | G14: 0 | H14: 1 | I14: 0 | J14: 0 | K14: 0 | L14: 0 | M14: 23 | N14: 0 | O14: =SUM(C14:L14,N14) -> 3 | P14: =SUM(C14:N14) -> 26 | R14: 1100-1200 | S14: =SUM(C26:C29) -> 9 | T14: =SUM(D26:D29) -> 1 | U14: =SUM(E26:E29) -> 12 | V14: =SUM(F26:F29) -> 12 | W14: =SUM(G26:G29) -> 0 | X14: =SUM(H26:H29) -> 0 | Y14: =SUM(I26:I29) -> 6 | Z14: =SUM(J26:J29) -> 0 | ... AF14: =SUM(P26:P29) -> 177
B15: 08.15 - 08.30 | C15: 0 | D15: 0 | E15: 1 | F15: 1 | G15: 0 | H15: 0 | I15: 0 | J15: 0 | K15: 0 | L15: 0 | M15: 24 | N15: 0 | O15: =SUM(C15:L15,N15) -> 2 | P15: =SUM(C15:N15) -> 26 | R15: 1200-1300 | S15: =SUM(C30:C33) -> 13 | T15: =SUM(D30:D33) -> 2 | U15: =SUM(E30:E33) -> 13 | V15: =SUM(F30:F33) -> 14 | W15: =SUM(G30:G33) -> 0 | X15: =SUM(H30:H33) -> 2 | Y15: =SUM(I30:I33) -> 4 | Z15: =SUM(J30:J33) -> 1 | ... AF15: =SUM(P30:P33) -> 173
B16: 08.30 - 08.45 | C16: 3 | D16: 0 | E16: 1 | F16: 2 | G16: 0 | H16: 0 | I16: 1 | J16: 0 | K16: 0 | L16: 0 | M16: 35 | N16: 0 | O16: =SUM(C16:L16,N16) -> 7 | P16: =SUM(C16:N16) -> 42 | R16: 1300-1400 | S16: =SUM(C34:C37) -> 15 | T16: =SUM(D34:D37) -> 0 | U16: =SUM(E34:E37) -> 8 | V16: =SUM(F34:F37) -> 12 | W16: =SUM(G34:G37) -> 0 | X16: =SUM(H34:H37) -> 0 | Y16: =SUM(I34:I37) -> 4 | Z16: =SUM(J34:J37) -> 0 | ... AF16: =SUM(P34:P37) -> 160
B17: 08.45 - 9.00 | C17: 3 | D17: 0 | E17: 1 | F17: 3 | G17: 0 | H17: 0 | I17: 0 | J17: 0 | K17: 0 | L17: 0 | M17: 31 | N17: 0 | O17: =SUM(C17:L17,N17) -> 7 | P17: =SUM(C17:N17) -> 38 | R17: 1400-1500 | S17: =SUM(C38:C41) -> 11 | T17: =SUM(D38:D41) -> 1 | U17: =SUM(E38:E41) -> 8 | V17: =SUM(F38:F41) -> 5 | W17: =SUM(G38:G41) -> 0 | X17: =SUM(H38:H41) -> 0 | Y17: =SUM(I38:I41) -> 1 | Z17: =SUM(J38:J41) -> 0 | ... AF17: =SUM(P38:P41) -> 123
B18: 09.00 - 09.15 | C18: 4 | D18: 0 | E18: 2 | F18: 2 | G18: 0 | H18: 0 | I18: 0 | J18: 0 | K18: 0 | L18: 0 | M18: 23 | N18: 0 | O18: =SUM(C18:L18,N18) -> 8 | P18: =SUM(C18:N18) -> 31 | R18: 1500-1600 | S18: =SUM(C42:C45) -> 8 | T18: =SUM(D42:D45) -> 2 | U18: =SUM(E42:E45) -> 10 | V18: =SUM(F42:F45) -> 12 | W18: =SUM(G42:G45) -> 1 | X18: =SUM(H42:H45) -> 0 | Y18: =SUM(I42:I45) -> 4 | Z18: =SUM(J42:J45) -> 0 | ... AF18: =SUM(P42:P45) -> 142
B19: 09.15 - 09.30 | C19: 3 | D19: 1 | E19: 4 | F19: 0 | G19: 0 | H19: 0 | I19: 1 | J19: 0 | K19: 0 | L19: 0 | M19: 21 | N19: 0 | O19: =SUM(C19:L19,N19) -> 9 | P19: =SUM(C19:N19) -> 30 | R19: 1600-1700 | S19: =SUM(C46:C49) -> 24 | T19: =SUM(D46:D49) -> 2 | U19: =SUM(E46:E49) -> 10 | V19: =SUM(F46:F49) -> 12 | W19: =SUM(G46:G49) -> 1 | X19: =SUM(H46:H49) -> 0 | Y19: =SUM(I46:I49) -> 7 | Z19: =SUM(J46:J49) -> 3 | ... AF19: =SUM(P46:P49) -> 154
B20: 09.30 - 09.45 | C20: 1 | D20: 0 | E20: 1 | F20: 2 | G20: 0 | H20: 0 | I20: 1 | J20: 0 | K20: 0 | L20: 0 | M20: 31 | N20: 0 | O20: =SUM(C20:L20,N20) -> 5 | P20: =SUM(C20:N20) -> 36 | R20: 1700-1800 | S20: =SUM(C50:C53) -> 7 | T20: =SUM(D50:D53) -> 2 | U20: =SUM(E50:E53) -> 16 | V20: =SUM(F50:F53) -> 14 | W20: =SUM(G50:G53) -> 0 | X20: =SUM(H50:H53) -> 0 | Y20: =SUM(I50:I53) -> 3 | Z20: =SUM(J50:J53) -> 1 | ... AF20: =SUM(P50:P53) -> 136
B21: 09.45 - 10.00 | C21: 0 | D21: 0 | E21: 1 | F21: 5 | G21: 0 | H21: 0 | I21: 2 | J21: 0 | K21: 0 | L21: 0 | M21: 33 | N21: 0 | O21: =SUM(C21:L21,N21) -> 8 | P21: =SUM(C21:N21) -> 41 | R21: 1800-1900 | S21: =SUM(C54:C57) -> 13 | T21: =SUM(D54:D57) -> 1 | U21: =SUM(E54:E57) -> 6 | V21: =SUM(F54:F57) -> 10 | W21: =SUM(G54:G57) -> 0 | X21: =SUM(H54:H57) -> 0 | Y21: =SUM(I54:I57) -> 6 | Z21: =SUM(J54:J57) -> 2 | ... AF21: =SUM(P54:P57) -> 144
B22: 10.00 - 10.15 | C22: 2 | D22: 0 | E22: 1 | F22: 2 | G22: 0 | H22: 0 | I22: 0 | J22: 3 | K22: 0 | L22: 0 | M22: 25 | N22: 0 | O22: =SUM(C22:L22,N22) -> 8 | P22: =SUM(C22:N22) -> 33 | R22: AM Peak Hr | S22: =MAX(S10:S12) -> 8 | T22: =MAX(T10:T12) -> 1 | U22: =MAX(U10:U12) -> 9 | V22: =MAX(V10:V12) -> 9 | W22: =MAX(W10:W12) -> 1 | X22: =MAX(X10:X12) -> 1 | Y22: =MAX(Y10:Y12) -> 4 | Z22: =MAX(Z10:Z12) -> 0 | ... AF22: =MAX(AF10:AF12) -> 138
B23: 10.15 - 10.30 | C23: 4 | D23: 0 | E23: 3 | F23: 2 | G23: 0 | H23: 0 | I23: 1 | J23: 0 | K23: 0 | L23: 0 | M23: 24 | N23: 0 | O23: =SUM(C23:L23,N23) -> 10 | P23: =SUM(C23:N23) -> 34 | R23: IP Peak Hr | S23: =MAX(S13:S18) -> 18 | T23: =MAX(T13:T18) -> 2 | U23: =MAX(U13:U18) -> 13 | V23: =MAX(V13:V18) -> 14 | W23: =MAX(W13:W18) -> 1 | X23: =MAX(X13:X18) -> 2 | Y23: =MAX(Y13:Y18) -> 6 | Z23: =MAX(Z13:Z18) -> 3 | ... AF23: =MAX(AF13:AF18) -> 177
B24: 10.30 - 10.45 | C24: 4 | D24: 0 | E24: 3 | F24: 3 | G24: 0 | H24: 0 | I24: 1 | J24: 0 | K24: 0 | L24: 0 | M24: 26 | N24: 0 | O24: =SUM(C24:L24,N24) -> 11 | P24: =SUM(C24:N24) -> 37 | R24: PM Peak Hr | S24: =MAX(S19:S21) -> 24 | T24: =MAX(T19:T21) -> 2 | U24: =MAX(U19:U21) -> 16 | V24: =MAX(V19:V21) -> 14 | W24: =MAX(W19:W21) -> 1 | X24: =MAX(X19:X21) -> 0 | Y24: =MAX(Y19:Y21) -> 7 | Z24: =MAX(Z19:Z21) -> 3 | ... AF24: =MAX(AF19:AF21) -> 154
B25: 10.45 - 11.00 | C25: 8 | D25: 0 | E25: 2 | F25: 2 | G25: 0 | H25: 0 | I25: 2 | J25: 0 | K25: 0 | L25: 0 | M25: 45 | N25: 0 | O25: =SUM(C25:L25,N25) -> 14 | P25: =SUM(C25:N25) -> 59 | R25: AM Period | S25: =SUM(S10:S12) -> 17 | T25: =SUM(T10:T12) -> 2 | U25: =SUM(U10:U12) -> 20 | V25: =SUM(V10:V12) -> 25 | W25: =SUM(W10:W12) -> 1 | X25: =SUM(X10:X12) -> 2 | Y25: =SUM(Y10:Y12) -> 7 | Z25: =SUM(Z10:Z12) -> 0 | ... AF25: =SUM(AF10:AF12) -> 370
B26: 11.00 - 11.15 | C26: 3 | D26: 0 | E26: 3 | F26: 4 | G26: 0 | H26: 0 | I26: 2 | J26: 0 | K26: 0 | L26: 0 | M26: 35 | N26: 0 | O26: =SUM(C26:L26,N26) -> 12 | P26: =SUM(C26:N26) -> 47 | R26: IP Period | S26: =SUM(S13:S18) -> 74 | T26: =SUM(T13:T18) -> 6 | U26: =SUM(U13:U18) -> 60 | V26: =SUM(V13:V18) -> 64 | W26: =SUM(W13:W18) -> 1 | X26: =SUM(X13:X18) -> 2 | Y26: =SUM(Y13:Y18) -> 23 | Z26: =SUM(Z13:Z18) -> 4 | ... AF26: =SUM(AF13:AF18) -> 938
B27: 11.15 - 11.30 | C27: 0 | D27: 0 | E27: 1 | F27: 4 | G27: 0 | H27: 0 | I27: 0 | J27: 0 | K27: 0 | L27: 0 | M27: 29 | N27: 0 | O27: =SUM(C27:L27,N27) -> 5 | P27: =SUM(C27:N27) -> 34 | R27: PM Period | S27: =SUM(S19:S21) -> 44 | T27: =SUM(T19:T21) -> 5 | U27: =SUM(U19:U21) -> 32 | V27: =SUM(V19:V21) -> 36 | W27: =SUM(W19:W21) -> 1 | X27: =SUM(X19:X21) -> 0 | Y27: =SUM(Y19:Y21) -> 16 | Z27: =SUM(Z19:Z21) -> 6 | ... AF27: =SUM(AF19:AF21) -> 434
B28: 11.30 - 11.45 | C28: 3 | D28: 1 | E28: 6 | F28: 2 | G28: 0 | H28: 0 | I28: 3 | J28: 0 | K28: 0 | L28: 0 | M28: 37 | N28: 0 | O28: =SUM(C28:L28,N28) -> 15 | P28: =SUM(C28:N28) -> 52 | R28: 12 Hours | S28: =SUM(S10:S21) -> 135 | T28: =SUM(T10:T21) -> 13 | U28: =SUM(U10:U21) -> 112 | V28: =SUM(V10:V21) -> 125 | W28: =SUM(W10:W21) -> 3 | X28: =SUM(X10:X21) -> 4 | Y28: =SUM(Y10:Y21) -> 46 | Z28: =SUM(Z10:Z21) -> 10 | ... AF28: =SUM(AF10:AF21) -> 1742
B29: 11.45 - 12.00 | C29: 3 | D29: 0 | E29: 2 | F29: 2 | G29: 0 | H29: 0 | I29: 1 | J29: 0 | K29: 0 | L29: 0 | M29: 36 | N29: 0 | O29: =SUM(C29:L29,N29) -> 8 | P29: =SUM(C29:N29) -> 44
B30: 12.00 - 12.15 | C30: 2 | D30: 1 | E30: 4 | F30: 4 | G30: 0 | H30: 0 | I30: 2 | J30: 1 | K30: 0 | L30: 0 | M30: 35 | N30: 0 | O30: =SUM(C30:L30,N30) -> 14 | P30: =SUM(C30:N30) -> 49
B31: 12.15 - 12.30 | C31: 6 | D31: 0 | E31: 3 | F31: 6 | G31: 0 | H31: 0 | I31: 0 | J31: 0 | K31: 0 | L31: 0 | M31: 29 | N31: 0 | O31: =SUM(C31:L31,N31) -> 15 | P31: =SUM(C31:N31) -> 44
B32: 12.30 - 12.45 | C32: 3 | D32: 1 | E32: 5 | F32: 2 | G32: 0 | H32: 0 | I32: 1 | J32: 0 | K32: 0 | L32: 0 | M32: 23 | N32: 0 | O32: =SUM(C32:L32,N32) -> 12 | P32: =SUM(C32:N32) -> 35
B33: 12.45 - 13.00 | C33: 2 | D33: 0 | E33: 1 | F33: 2 | G33: 0 | H33: 2 | I33: 1 | J33: 0 | K33: 0 | L33: 0 | M33: 37 | N33: 0 | O33: =SUM(C33:L33,N33) -> 8 | P33: =SUM(C33:N33) -> 45
