Workbook
Name Dist: 'ALL DATA'!$S:$S
Name Jtime: 'ALL DATA'!$T:$T
Name Tripfreq: 'ALL DATA'!$U:$U
Name Veh: 'ALL DATA'!$D:$D
Name Veh_Type: '11.10.ENTEBBE-BUSABALA'!$D$9:$D$28
Name Veh_Type: '12.10 BUSABALA-ENTEBBE'!$D$9:$D$37
Name Veh_Type: 'ALL DATA'!$D$9:$D$33
Name Veh_Type: '[1]25.07 BUSEGA-NATEETE'!$D:$D
Name Veh_Type: '[1]25.07 BUSEGA-NATEETE'!$D:$D
Name Veh_Type: '11.10.BUSABALA-ENTEBBE'!$D$9:$D$33
Name zones: #REF!
Name Zones_Ndeke: #REF!

Sheet Analysis
B3: Vehicle OD Sample Proportions | N3: Average Journey Time
B4: Vehicle Types | C4: OD Sample | D4: OD Sample, % | N4: Journey Time Range (Hrs) | O4: Cummu-lative | P4: No of Vehicles | Q4: No. of Vehicles, %
B5: Car | C5: =COUNTIF('ALL DATA'!$D$9:$D$5000,"1") -> 107 | D5: =C5/$C$17 -> 0.44583333 | N5: 0-0.25 | O5: =COUNTIF(Jtime,"<=0.25") -> 34 | P5: =O5 -> 34 | Q5: =P5/$O$15 -> 0.17346939
B6: Station Wagon | C6: =COUNTIF('ALL DATA'!$D$9:$D$5000,"2") -> 17 | D6: =C6/$C$17 -> 0.070833333 | N6: 0.25-0.50 | O6: =COUNTIF(Jtime,"<=0.5") -> 117 | P6: =O6-O5 -> 83 | Q6: =P6/$O$15 -> 0.42346939
B7: Pickups | C7: =COUNTIF('ALL DATA'!$D$9:$D$5000,"3") -> 7 | D7: =C7/$C$17 -> 0.029166667 | N7: 0.50-0.75 | O7: =COUNTIF(Jtime,"<=0.75") -> 128 | P7: =O7-O6 -> 11 | Q7: =P7/$O$15 -> 0.056122449
B8: Minibus, matatu | C8: =COUNTIF('ALL DATA'!$D$9:$D$5000,"4") -> 48 | D8: =C8/$C$17 -> 0.2 | N8: 0.75-1.00 | O8: =COUNTIF(Jtime,"<=1.0") -> 175 | P8: =O8-O7 -> 47 | Q8: =P8/$O$15 -> 0.23979592
B9: Medium bus | C9: =COUNTIF('ALL DATA'!$D$9:$D$5000,"5") -> 2 | D9: =C9/$C$17 -> 0.0083333333 | N9: 1.00-1.50 | O9: =COUNTIF(Jtime,"<=1.5") -> 186 | P9: =O9-O8 -> 11 | Q9: =P9/$O$15 -> 0.056122449
B10: Large Bus | C10: =COUNTIF('ALL DATA'!$D$9:$D$5000,"6") -> 0 | D10: =C10/$C$17 -> 0 | N10: 1.5-2.0 | O10: =COUNTIF(Jtime,"<=2") -> 195 | P10: =O10-O9 -> 9 | Q10: =P10/$O$15 -> 0.045918367
B11: Light Truck | C11: =COUNTIF('ALL DATA'!$D$9:$D$5000,"7") -> 12 | D11: =C11/$C$17 -> 0.05 | N11: 2.0-3.0 | O11: =COUNTIF(Jtime,"<=3") -> 195 | P11: =O11-O10 -> 0 | Q11: =P11/$O$15 -> 0
B12: Medium Truck | C12: =COUNTIF('ALL DATA'!$D$9:$D$5000,"8") -> 3 | D12: =C12/$C$17 -> 0.0125 | N12: 3.0-5.0 | O12: =COUNTIF(Jtime,"<=5") -> 195 | P12: =O12-O11 -> 0 | Q12: =P12/$O$15 -> 0
B13: Heavy truck | C13: =COUNTIF('ALL DATA'!$D$9:$D$5000,"9") -> 0 | D13: =C13/$C$17 -> 0 | N13: 5.0-7.5 | O13: =COUNTIF(Jtime,"<=7.5") -> 195 | P13: =O13-O12 -> 0 | Q13: =P13/$O$15 -> 0
B14: Truck Trailer | C14: =COUNTIF('ALL DATA'!$D$9:$D$5000,"10") -> 1 | D14: =C14/$C$17 -> 0.0041666667 | N14: 7.5-10 | O14: =COUNTIF(Jtime,"<=10") -> 196 | P14: =O14-O13 -> 1 | Q14: =P14/$O$15 -> 0.0051020408
B15: Motor cycles | C15: =COUNTIF('ALL DATA'!$D$9:$D$5000,"11") -> 43 | D15: =C15/$C$17 -> 0.17916667 | N15: Over 10 | O15: =COUNTIF(Jtime,"<=15") -> 196 | P15: =O15-O14 -> 0 | Q15: =P15/$O$15 -> 0
B16: Tractors | C16: =COUNTIF('ALL DATA'!$D$9:$D$5000,"12") -> 0 | D16: =C16/$C$17 -> 0
C17: =SUM(C5:C16) -> 240
N21: Trip Frequency
B22: Journey Purpose | N22: Trip Frequency | O22: No of Vehicles | P22: No. of Vehicles, %
B23: Purpose | C23: Respondents | D23: Percent | N23: More than 2 times every day | O23: =COUNTIF(Tripfreq,"=1") -> 48 | P23: =O23/$O$29 -> 0.2
B24: Home-Work | C24: =COUNTIF('ALL DATA'!$R$9:$R$5000,"Home-Work") -> 31 | D24: =C24/$C$29 -> 0.12916667 | N24: Daily (Up and Down) | O24: =COUNTIF(Tripfreq,"=2") -> 138 | P24: =O24/$O$29 -> 0.575
B25: Home-Study | C25: =COUNTIF('ALL DATA'!$R$9:$R$369,"Home-Study") -> 5 | D25: =C25/$C$29 -> 0.020833333 | N25: 2/3 times a week | O25: =COUNTIF(Tripfreq,"=3") -> 19 | P25: =O25/$O$29 -> 0.079166667
B26: Work-Home | C26: =COUNTIF('ALL DATA'!$R$9:$R$369,"Work-Home") -> 27 | D26: =C26/$C$29 -> 0.1125 | N26: Once a week | O26: =COUNTIF(Tripfreq,"=4") -> 11 | P26: =O26/$O$29 -> 0.045833333
B27: Work-Work | C27: =COUNTIF('ALL DATA'!$R$9:$R$369,"Work-Work") -> 68 | D27: =C27/$C$29 -> 0.28333333 | N27: Once a month | O27: =COUNTIF(Tripfreq,"=5") -> 7 | P27: =O27/$O$29 -> 0.029166667
B28: Others | C28: =C29-SUM(C24:C27) -> 109 | D28: =C28/$C$29 -> 0.45416667 | N28: Once in a while | O28: =COUNTIF(Tripfreq,"=6") -> 17 | P28: =O28/$O$29 -> 0.070833333
B29: Total | C29: =C17 -> 240 | O29: =SUM(O23:O28) -> 240
B40: Expressway Use
B41: Response | C41: Number | D41: Percent
B42: Yes | C42: =COUNTIF('ALL DATA'!$Y$9:$Y$5000,"Y") -> 240 | D42: =C42/$C$44 -> 1
B43: No | C43: =C44-C42 -> 0 | D43: =C43/$C$44 -> 0
B44: Total | C44: =C29 -> 240
R47: Home | S47: Work | T47: Study | U47: Commercial | V47: Tourism | W47: Leisure/Social | X47: Hospital | Y47: Others
P48: 1 | Q48: Home | R48: =R59/SUM($R$59:$Y$66) -> 0.058333333 | S48: =S59/SUM($R$59:$Y$66) -> 0.12916667 | T48: =T59/SUM($R$59:$Y$66) -> 0.020833333 | U48: =U59/SUM($R$59:$Y$66) -> 0.025 | V48: =V59/SUM($R$59:$Y$66) -> 0.0125 | W48: =W59/SUM($R$59:$Y$66) -> 0.058333333 | X48: =X59/SUM($R$59:$Y$66) -> 0.0125 | Y48: =Y59/SUM($R$59:$Y$66) -> 0.058333333
P49: 2 | Q49: Work | R49: =R60/SUM($R$59:$Y$66) -> 0.1125 | S49: =S60/SUM($R$59:$Y$66) -> 0.28333333 | T49: =T60/SUM($R$59:$Y$66) -> 0 | U49: =U60/SUM($R$59:$Y$66) -> 0.0083333333 | V49: =V60/SUM($R$59:$Y$66) -> 0 | W49: =W60/SUM($R$59:$Y$66) -> 0 | X49: =X60/SUM($R$59:$Y$66) -> 0 | Y49: =Y60/SUM($R$59:$Y$66) -> 0.0083333333
P50: 3 | Q50: Study | R50: =R61/SUM($R$59:$Y$66) -> 0.016666667 | S50: =S61/SUM($R$59:$Y$66) -> 0 | T50: =T61/SUM($R$59:$Y$66) -> 0.0041666667 | U50: =U61/SUM($R$59:$Y$66) -> 0 | V50: =V61/SUM($R$59:$Y$66) -> 0 | W50: =W61/SUM($R$59:$Y$66) -> 0 | X50: =X61/SUM($R$59:$Y$66) -> 0 | Y50: =Y61/SUM($R$59:$Y$66) -> 0
P51: 4 | Q51: Commercial | R51: =R62/SUM($R$59:$Y$66) -> 0.016666667 | S51: =S62/SUM($R$59:$Y$66) -> 0.0041666667 | T51: =T62/SUM($R$59:$Y$66) -> 0 | U51: =U62/SUM($R$59:$Y$66) -> 0.0041666667 | V51: =V62/SUM($R$59:$Y$66) -> 0 | W51: =W62/SUM($R$59:$Y$66) -> 0.0041666667 | X51: =X62/SUM($R$59:$Y$66) -> 0 | Y51: =Y62/SUM($R$59:$Y$66) -> 0.0041666667
P52: 5 | Q52: Tourism | R52: =R63/SUM($R$59:$Y$66) -> 0 | S52: =S63/SUM($R$59:$Y$66) -> 0 | T52: =T63/SUM($R$59:$Y$66) -> 0 | U52: =U63/SUM($R$59:$Y$66) -> 0 | V52: =V63/SUM($R$59:$Y$66) -> 0 | W52: =W63/SUM($R$59:$Y$66) -> 0 | X52: =X63/SUM($R$59:$Y$66) -> 0 | Y52: =Y63/SUM($R$59:$Y$66) -> 0
P53: 6 | Q53: Leisure/Social | R53: =R64/SUM($R$59:$Y$66) -> 0.0083333333 | S53: =S64/SUM($R$59:$Y$66) -> 0 | T53: =T64/SUM($R$59:$Y$66) -> 0 | U53: =U64/SUM($R$59:$Y$66) -> 0 | V53: =V64/SUM($R$59:$Y$66) -> 0 | W53: =W64/SUM($R$59:$Y$66) -> 0 | X53: =X64/SUM($R$59:$Y$66) -> 0 | Y53: =Y64/SUM($R$59:$Y$66) -> 0
P54: 7 | Q54: Hospital | R54: =R65/SUM($R$59:$Y$66) -> 0.0041666667 | S54: =S65/SUM($R$59:$Y$66) -> 0 | T54: =T65/SUM($R$59:$Y$66) -> 0 | U54: =U65/SUM($R$59:$Y$66) -> 0 | V54: =V65/SUM($R$59:$Y$66) -> 0 | W54: =W65/SUM($R$59:$Y$66) -> 0 | X54: =X65/SUM($R$59:$Y$66) -> 0 | Y54: =Y65/SUM($R$59:$Y$66) -> 0
P55: 8 | Q55: Others | R55: =R66/SUM($R$59:$Y$66) -> 0.041666667 | S55: =S66/SUM($R$59:$Y$66) -> 0.0125 | T55: =T66/SUM($R$59:$Y$66) -> 0 | U55: =U66/SUM($R$59:$Y$66) -> 0.0083333333 | V55: =V66/SUM($R$59:$Y$66) -> 0 | W55: =W66/SUM($R$59:$Y$66) -> 0.0083333333 | X55: =X66/SUM($R$59:$Y$66) -> 0 | Y55: =Y66/SUM($R$59:$Y$66) -> 0.075
R57: 1 | S57: 2 | T57: 3 | U57: 4 | V57: 5 | W57: 6 | X57: 7 | Y57: 8
B58: Willingness to Pay | R58: Home | S58: Work | T58: Study | U58: Commercial | V58: Tourism | W58: Leisure/Social | X58: Hospital | Y58: Others
...

Sheet ALL DATA
B1: Consultancy services for Preparation of Expressway Development Master Plan (EDMP) for Uganda
B2: Roadside OD Interview Survey
B4: Date: | C4: 11.10.19 | E4: Road Name: | F4: BUSABALA ROAD | I4: Direction From: | L4: BUSABALA | N4: Interviewers: | O4: KYLO | V4: Supervisor: | W4: EMMA | Y4: Coded By: | Z4: AJOK EMILY | AA4: Chkd By: | AB4: Bakole Deo
I5: Direction To: | L5: ENTEBBE
B7: Time | C7: Veh_Reg_No. | D7: Veh_Type | E7: No. Occupants | F7: Origin_Address | I7: Origin_Establish | J7: Origin_Purpose | K7: Origin-Purpose Desc | L7: Destination_Address | O7: Destination_Establish | P7: Destination_Purpose | Q7: Destination_Purpose Desc | R7: Journey_Purpose | S7: Approx_Distance (Km) | T7: Approx_Journey Time (Hrs) | U7: Trip_Frequency | V7: GOODS VEHICLES ONLY | Y7: Would You Use Xpressways? | Z7: Pay How Much? (UGX) | AA7: Origin_Zone | AB7: Dest_Zone
F8: Village or Town | G8: District | H8: Country | L8: Village or Town | M8: District | N8: Country | V8: Goods_Type | W8: Goods_Quantity (Ton) | X8: Goods_Value (UGXm)
B9: 0.85277778 | C9: UBF 609Q | D9: 1 | E9: 1 | F9: TOWN CITY | G9: KAMPALA | H9: UG | I9: 2 | J9: 2 | K9: =VLOOKUP(J9,Key!$E$2:$F$9,2,FALSE) -> Work | L9: NAJANANKUMBI | M9: KAMPALA | N9: UG | O9: 1 | P9: 1 | Q9: =VLOOKUP(P9,Key!$E$2:$F$9,2,FALSE) -> Home | R9: =K9&"-"&Q9 -> Work-Home | U9: 2 | Y9: Y | AA9: =VLOOKUP(F9,Zones!$A$2:$F$15614,6,FALSE) -> 521 | AB9: =VLOOKUP(L9,Zones!$A$2:$F$15614,6,FALSE) -> 565
B10: 0.97222222 | C10: UAV 609X | D10: 1 | E10: 1 | F10: KIBIRI | G10: KAMPALA | H10: UG | I10: 2 | J10: 2 | K10: =VLOOKUP(J10,Key!$E$2:$F$9,2,FALSE) -> Work | L10: TOWN CITY | M10: KAMPALA | N10: UG | O10: 1 | P10: 1 | Q10: =VLOOKUP(P10,Key!$E$2:$F$9,2,FALSE) -> Home | R10: =K10&"-"&Q10 -> Work-Home | U10: 2 | Y10: Y | Z10: 1000 | AA10: =VLOOKUP(F10,Zones!$A$2:$F$15614,6,FALSE) -> 522 | AB10: =VLOOKUP(L10,Zones!$A$2:$F$15614,6,FALSE) -> 521
B11: 0.97569444 | C11: UBF 952P | D11: 1 | E11: 1 | F11: BUSABALA | G11: WAKISO | H11: UG | I11: 2 | J11: 2 | K11: =VLOOKUP(J11,Key!$E$2:$F$9,2,FALSE) -> Work | L11: NDEJJE | M11: KAMPALA | N11: UG | O11: 1 | P11: 1 | Q11: =VLOOKUP(P11,Key!$E$2:$F$9,2,FALSE) -> Home | R11: =K11&"-"&Q11 -> Work-Home | S11: 4 | T11: 1 | U11: 2 | Y11: Y | AA11: =VLOOKUP(F11,Zones!$A$2:$F$15614,6,FALSE) -> 522 | AB11: =VLOOKUP(L11,Zones!$A$2:$F$15614,6,FALSE) -> 1407
B12: 0.84722222 | C12: UBD 938L | D12: 1 | E12: 2 | F12: TOWN CITY | G12: KAMPALA | H12: UG | I12: 2 | J12: 2 | K12: =VLOOKUP(J12,Key!$E$2:$F$9,2,FALSE) -> Work | L12: KIBIRI | M12: KAMPALA | N12: UG | O12: 1 | P12: 1 | Q12: =VLOOKUP(P12,Key!$E$2:$F$9,2,FALSE) -> Home | R12: =K12&"-"&Q12 -> Work-Home | U12: 2 | Y12: Y | Z12: 1000 | AA12: =VLOOKUP(F12,Zones!$A$2:$F$15614,6,FALSE) -> 521 | AB12: =VLOOKUP(L12,Zones!$A$2:$F$15614,6,FALSE) -> 522
B13: 0.91319444 | C13: UDT 211K | D13: 11 | E13: 1 | F13: KIGO | G13: WAKISO | H13: UG | I13: 8 | J13: 8 | K13: =VLOOKUP(J13,Key!$E$2:$F$9,2,FALSE) -> Others | L13: KIBIRI | M13: KAMPALA | N13: UG | O13: 8 | P13: 2 | Q13: =VLOOKUP(P13,Key!$E$2:$F$9,2,FALSE) -> Work | R13: =K13&"-"&Q13 -> Others-Work | S13: 2 | T13: 0.41 | U13: 2 | Y13: Y | Z13: 300 | AA13: =VLOOKUP(F13,Zones!$A$2:$F$15614,6,FALSE) -> 522 | AB13: =VLOOKUP(L13,Zones!$A$2:$F$15614,6,FALSE) -> 522
B14: 0.90833333 | C14: UEP 791H | D14: 11 | E14: 1 | F14: BUSABALA | G14: WAKISO | H14: UG | I14: 8 | J14: 2 | K14: =VLOOKUP(J14,Key!$E$2:$F$9,2,FALSE) -> Work | L14: NDEJJE | M14: KAMPALA | N14: UG | O14: 8 | P14: 2 | Q14: =VLOOKUP(P14,Key!$E$2:$F$9,2,FALSE) -> Work | R14: =K14&"-"&Q14 -> Work-Work | U14: 2 | Y14: Y | AA14: =VLOOKUP(F14,Zones!$A$2:$F$15614,6,FALSE) -> 522 | AB14: =VLOOKUP(L14,Zones!$A$2:$F$15614,6,FALSE) -> 1407
B15: 0.91527778 | C15: UDX 127U | D15: 11 | E15: 2 | F15: TOWN CITY | G15: KAMPALA | H15: UG | I15: 8 | J15: 2 | K15: =VLOOKUP(J15,Key!$E$2:$F$9,2,FALSE) -> Work | L15: KIBIRI | M15: KAMPALA | N15: UG | O15: 8 | P15: 2 | Q15: =VLOOKUP(P15,Key!$E$2:$F$9,2,FALSE) -> Work | R15: =K15&"-"&Q15 -> Work-Work | U15: 2 | Y15: Y | Z15: 2000 | AA15: =VLOOKUP(F15,Zones!$A$2:$F$15614,6,FALSE) -> 521 | AB15: =VLOOKUP(L15,Zones!$A$2:$F$15614,6,FALSE) -> 522
B16: 0.375 | C16: UAU 679S | D16: 4 | E16: 2 | F16: BUSABALA | G16: WAKISO | H16: UG | I16: 6 | J16: 2 | K16: =VLOOKUP(J16,Key!$E$2:$F$9,2,FALSE) -> Work | L16: TOWN CITY | M16: KAMPALA | N16: UG | O16: 6 | P16: 2 | Q16: =VLOOKUP(P16,Key!$E$2:$F$9,2,FALSE) -> Work | R16: =K16&"-"&Q16 -> Work-Work | U16: 2 | Y16: Y | Z16: 500 | AA16: =VLOOKUP(F16,Zones!$A$2:$F$15614,6,FALSE) -> 522 | AB16: =VLOOKUP(L16,Zones!$A$2:$F$15614,6,FALSE) -> 521
B17: 0.89652778 | C17: UDL 240B | D17: 11 | E17: 2 | F17: BUSABALA | G17: WAKISO | H17: UG | I17: 8 | J17: 2 | K17: =VLOOKUP(J17,Key!$E$2:$F$9,2,FALSE) -> Work | L17: KIBIRI | M17: KAMPALA | N17: UG | O17: 1 | P17: 1 | Q17: =VLOOKUP(P17,Key!$E$2:$F$9,2,FALSE) -> Home | R17: =K17&"-"&Q17 -> Work-Home | S17: 2 | T17: 0.5 | U17: 2 | Y17: Y | Z17: 500 | AA17: =VLOOKUP(F17,Zones!$A$2:$F$15614,6,FALSE) -> 522 | AB17: =VLOOKUP(L17,Zones!$A$2:$F$15614,6,FALSE) -> 522
B18: 0.90972222 | C18: UAX 752U | D18: 1 | E18: 1 | F18: TOWN CITY | G18: KAMPALA | H18: UG | I18: 2 | J18: 2 | K18: =VLOOKUP(J18,Key!$E$2:$F$9,2,FALSE) -> Work | L18: KIBIRI | M18: KAMPALA | N18: UG | O18: 1 | P18: 1 | Q18: =VLOOKUP(P18,Key!$E$2:$F$9,2,FALSE) -> Home | R18: =K18&"-"&Q18 -> Work-Home | U18: 2 | Y18: Y | Z18: 500 | AA18: =VLOOKUP(F18,Zones!$A$2:$F$15614,6,FALSE) -> 521 | AB18: =VLOOKUP(L18,Zones!$A$2:$F$15614,6,FALSE) -> 522
B19: 21:45 | C19: UBE 594W | D19: 4 | E19: 8 | F19: BUSABALA | G19: WAKISO | H19: UG | I19: 6 | J19: 2 | K19: =VLOOKUP(J19,Key!$E$2:$F$9,2,FALSE) -> Work | L19: TOWN CITY | M19: KAMPALA | N19: UG | O19: 6 | P19: 2 | Q19: =VLOOKUP(P19,Key!$E$2:$F$9,2,FALSE) -> Work | R19: =K19&"-"&Q19 -> Work-Work | U19: 2 | Y19: Y | Z19: 500 | AA19: =VLOOKUP(F19,Zones!$A$2:$F$15614,6,FALSE) -> 522 | AB19: =VLOOKUP(L19,Zones!$A$2:$F$15614,6,FALSE) -> 521
B20: 0.92013889 | C20: UES 018U | D20: 11 | E20: 4 | F20: KIGO | G20: WAKISO | H20: UG | I20: 8 | J20: 2 | K20: =VLOOKUP(J20,Key!$E$2:$F$9,2,FALSE) -> Work | L20: KIBIRI | M20: KAMPALA | N20: UG | O20: 8 | P20: 2 | Q20: =VLOOKUP(P20,Key!$E$2:$F$9,2,FALSE) -> Work | R20: =K20&"-"&Q20 -> Work-Work | S20: 2 | T20: 0.5 | U20: 2 | Y20: Y | Z20: 100 | AA20: =VLOOKUP(F20,Zones!$A$2:$F$15614,6,FALSE) -> 522 | AB20: =VLOOKUP(L20,Zones!$A$2:$F$15614,6,FALSE) -> 522
B21: 0.91736111 | C21: UAR 033M | D21: 4 | E21: 2 | F21: BUSABALA | G21: WAKISO | H21: UG | I21: 6 | J21: 2 | K21: =VLOOKUP(J21,Key!$E$2:$F$9,2,FALSE) -> Work | L21: TOWN CITY | M21: KAMPALA | N21: UG | O21: 6 | P21: 2 | Q21: =VLOOKUP(P21,Key!$E$2:$F$9,2,FALSE) -> Work | R21: =K21&"-"&Q21 -> Work-Work | U21: 2 | Y21: Y | Z21: 500 | AA21: =VLOOKUP(F21,Zones!$A$2:$F$15614,6,FALSE) -> 522 | AB21: =VLOOKUP(L21,Zones!$A$2:$F$15614,6,FALSE) -> 521
B22: 0.92986111 | C22: UAN 128U | D22: 4 | E22: 4 | F22: BUSABALA | G22: WAKISO | H22: UG | I22: 6 | J22: 2 | K22: =VLOOKUP(J22,Key!$E$2:$F$9,2,FALSE) -> Work | L22: TOWN CITY | M22: KAMPALA | N22: UG | O22: 6 | P22: 2 | Q22: =VLOOKUP(P22,Key!$E$2:$F$9,2,FALSE) -> Work | R22: =K22&"-"&Q22 -> Work-Work | S22: 4 | T22: 1.5 | U22: 2 | Y22: Y | Z22: 500 | AA22: =VLOOKUP(F22,Zones!$A$2:$F$15614,6,FALSE) -> 522 | AB22: =VLOOKUP(L22,Zones!$A$2:$F$15614,6,FALSE) -> 521
B23: 0.92569444 | C23: UDU167M | D23: 11 | E23: 2 | F23: TOWN CITY | G23: KAMPALA | H23: UG | I23: 8 | J23: 2 | K23: =VLOOKUP(J23,Key!$E$2:$F$9,2,FALSE) -> Work | L23: KIBIRI | M23: KAMPALA | N23: UG | O23: 8 | P23: 1 | Q23: =VLOOKUP(P23,Key!$E$2:$F$9,2,FALSE) -> Home | R23: =K23&"-"&Q23 -> Work-Home | U23: 2 | Y23: Y | AA23: =VLOOKUP(F23,Zones!$A$2:$F$15614,6,FALSE) -> 521 | AB23: =VLOOKUP(L23,Zones!$A$2:$F$15614,6,FALSE) -> 522
B24: 0.9375 | C24: UEX 713Z | D24: 11 | E24: 1 | F24: TOWN CITY | G24: KAMPALA | H24: UG | I24: 8 | J24: 2 | K24: =VLOOKUP(J24,Key!$E$2:$F$9,2,FALSE) -> Work | L24: KIBIRI | M24: KAMPALA | N24: UG | O24: 1 | P24: 1 | Q24: =VLOOKUP(P24,Key!$E$2:$F$9,2,FALSE) -> Home | R24: =K24&"-"&Q24 -> Work-Home | S24: 1 | T24: 0.4 | U24: 2 | Y24: Y | Z24: 500 | AA24: =VLOOKUP(F24,Zones!$A$2:$F$15614,6,FALSE) -> 521 | AB24: =VLOOKUP(L24,Zones!$A$2:$F$15614,6,FALSE) -> 522
B25: 0.95138889 | C25: UAJ 409F | D25: 4 | E25: 1 | F25: BUSEGA | G25: WAKISO | H25: UG | I25: 6 | J25: 2 | K25: =VLOOKUP(J25,Key!$E$2:$F$9,2,FALSE) -> Work | L25: KIBIRI | M25: KAMPALA | N25: UG | O25: 1 | P25: 1 | Q25: =VLOOKUP(P25,Key!$E$2:$F$9,2,FALSE) -> Home | R25: =K25&"-"&Q25 -> Work-Home | U25: 2 | Y25: Y | Z25: 500 | AA25: =VLOOKUP(F25,Zones!$A$2:$F$15614,6,FALSE) -> 517 | AB25: =VLOOKUP(L25,Zones!$A$2:$F$15614,6,FALSE) -> 522
B26: 0.98263889 | C26: UAW 940M | D26: 4 | E26: 12 | F26: SALAMA | G26: KAMPALA | H26: UG | I26: 6 | J26: 2 | K26: =VLOOKUP(J26,Key!$E$2:$F$9,2,FALSE) -> Work | L26: BUSABALA | M26: WAKISO | N26: UG | O26: 6 | P26: 2 | Q26: =VLOOKUP(P26,Key!$E$2:$F$9,2,FALSE) -> Work | R26: =K26&"-"&Q26 -> Work-Work | S26: 2 | T26: 1 | U26: 2 | Y26: Y | Z26: 1000 | AA26: =VLOOKUP(F26,Zones!$A$2:$F$15614,6,FALSE) -> 579 | AB26: =VLOOKUP(L26,Zones!$A$2:$F$15614,6,FALSE) -> 522
B27: 0.71805556 | C27: UBB 152W | D27: 1 | E27: 4 | F27: BUSABALA | G27: WAKISO | H27: UG | I27: 1 | J27: 2 | K27: =VLOOKUP(J27,Key!$E$2:$F$9,2,FALSE) -> Work | L27: KIBIRI | M27: KAMPALA | N27: UG | O27: 1 | P27: 1 | Q27: =VLOOKUP(P27,Key!$E$2:$F$9,2,FALSE) -> Home | R27: =K27&"-"&Q27 -> Work-Home | S27: 1 | T27: 0.5 | U27: 2 | Y27: Y | Z27: 500 | AA27: =VLOOKUP(F27,Zones!$A$2:$F$15614,6,FALSE) -> 522 | AB27: =VLOOKUP(L27,Zones!$A$2:$F$15614,6,FALSE) -> 522
B28: 0.15625 | C28: UAT 809Q | D28: 1 | E28: 2 | F28: TOWN CITY | G28: KAMPALA | H28: UG | I28: 2 | J28: 1 | K28: =VLOOKUP(J28,Key!$E$2:$F$9,2,FALSE) -> Home | L28: NDEJJE | M28: KAMPALA | N28: UG | O28: 1 | P28: 1 | Q28: =VLOOKUP(P28,Key!$E$2:$F$9,2,FALSE) -> Home | R28: =K28&"-"&Q28 -> Home-Home | U28: 2 | Y28: Y | Z28: 200 | AA28: =VLOOKUP(F28,Zones!$A$2:$F$15614,6,FALSE) -> 521 | AB28: =VLOOKUP(L28,Zones!$A$2:$F$15614,6,FALSE) -> 1407
B29: 0.24305556 | C29: UBD 747T | D29: 1 | E29: 2 | F29: BUSABALA | G29: WAKISO | H29: UG | I29: 1 | J29: 1 | K29: =VLOOKUP(J29,Key!$E$2:$F$9,2,FALSE) -> Home | L29: NAMASUBA | M29: KAMPALA | N29: UG | O29: 2 | P29: 2 | Q29: =VLOOKUP(P29,Key!$E$2:$F$9,2,FALSE) -> Work | R29: =K29&"-"&Q29 -> Home-Work | S29: 1 | T29: 0.5 | U29: 2 | Y29: Y | AA29: =VLOOKUP(F29,Zones!$A$2:$F$15614,6,FALSE) -> 522 | AB29: =VLOOKUP(L29,Zones!$A$2:$F$15614,6,FALSE) -> 565
B30: 0.97916667 | C30: UAT 486V | D30: 1 | E30: 1 | F30: TOWN CITY | G30: KAMPALA | H30: UG | I30: 1 | J30: 1 | K30: =VLOOKUP(J30,Key!$E$2:$F$9,2,FALSE) -> Home | L30: ZANA | M30: WAKISO | N30: UG | O30: 2 | P30: 2 | Q30: =VLOOKUP(P30,Key!$E$2:$F$9,2,FALSE) -> Work | R30: =K30&"-"&Q30 -> Home-Work | U30: 2 | Y30: Y | Z30: 1000 | AA30: =VLOOKUP(F30,Zones!$A$2:$F$15614,6,FALSE) -> 521 | AB30: =VLOOKUP(L30,Zones!$A$2:$F$15614,6,FALSE) -> 565
B31: 0.84722222 | C31: UAU 718Y | D31: 1 | E31: 2 | F31: BUSABALA | G31: WAKISO | H31: UG | I31: 2 | J31: 2 | K31: =VLOOKUP(J31,Key!$E$2:$F$9,2,FALSE) -> Work | L31: KIBIRI | M31: KAMPALA | N31: UG | O31: 1 | P31: 1 | Q31: =VLOOKUP(P31,Key!$E$2:$F$9,2,FALSE) -> Home | R31: =K31&"-"&Q31 -> Work-Home | S31: 2 | T31: 0.5 | U31: 2 | Y31: Y | AA31: =VLOOKUP(F31,Zones!$A$2:$F$15614,6,FALSE) -> 522 | AB31: =VLOOKUP(L31,Zones!$A$2:$F$15614,6,FALSE) -> 522
B32: 0.96875 | C32: UBA 504Q | D32: 1 | E32: 1 | F32: NDEJJE | G32: WAKISO | H32: UG | I32: 2 | J32: 2 | K32: =VLOOKUP(J32,Key!$E$2:$F$9,2,FALSE) -> Work | L32: TOWN CITY | M32: KAMPALA | N32: UG | O32: 1 | P32: 1 | Q32: =VLOOKUP(P32,Key!$E$2:$F$9,2,FALSE) -> Home | R32: =K32&"-"&Q32 -> Work-Home | U32: 2 | Y32: Y | Z32: 1000 | AA32: =VLOOKUP(F32,Zones!$A$2:$F$15614,6,FALSE) -> 1407 | AB32: =VLOOKUP(L32,Zones!$A$2:$F$15614,6,FALSE) -> 521
B33: 0.85763889 | C33: UAA 487F | D33: 3 | E33: 2 | F33: TOWN CITY | G33: KAMPALA | H33: UG | I33: 2 | J33: 2 | K33: =VLOOKUP(J33,Key!$E$2:$F$9,2,FALSE) -> Work | L33: SALAMA | M33: KAMPALA | N33: UG | O33: 1 | P33: 1 | Q33: Home | R33: Work-Home | S33: 4 | T33: 1.5 | U33: 2 | Y33: Y | Z33: 1000 | AA33: =VLOOKUP(F33,Zones!$A$2:$F$15614,6,FALSE) -> 521 | AB33: =VLOOKUP(L33,Zones!$A$2:$F$15614,6,FALSE) -> 579
B34: 0.80555556 | C34: UEF 219E | D34: 11 | E34: 1 | F34: MIREMBE | G34: WAKISO | H34: UG | I34: 16 | J34: 8 | K34: =VLOOKUP(J34,Key!$E$2:$F$9,2,FALSE) -> Others | L34: KIBIRI | M34: WAKISO | N34: UG | O34: 16 | P34: 8 | Q34: =VLOOKUP(P34,Key!$E$2:$F$9,2,FALSE) -> Others | R34: =K34&"-"&Q34 -> Others-Others | S34: 2 | T34: 0.2 | U34: 2 | Y34: Y | Z34: 1000 | AA34: =VLOOKUP(F34,Zones!$A$2:$F$15614,6,FALSE) -> 551 | AB34: =VLOOKUP(L34,Zones!$A$2:$F$15614,6,FALSE) -> 522
B35: 0.95069444 | C35: UEA 503J | D35: 11 | E35: 1 | F35: BUSABALA | G35: WAKISO | H35: UG | I35: 8 | J35: 2 | K35: =VLOOKUP(J35,Key!$E$2:$F$9,2,FALSE) -> Work | L35: MASAJJA | M35: WAKISO | N35: UG | O35: 1 | P35: 1 | Q35: =VLOOKUP(P35,Key!$E$2:$F$9,2,FALSE) -> Home | R35: =K35&"-"&Q35 -> Work-Home | T35: 0.5 | U35: 1 | Y35: Y | Z35: 1000 | AA35: =VLOOKUP(F35,Zones!$A$2:$F$15614,6,FALSE) -> 522 | AB35: =VLOOKUP(L35,Zones!$A$2:$F$15614,6,FALSE) -> 1398
B36: 0.23125 | C36: UAS 232Z | D36: 1 | E36: 1 | F36: STATION | G36: WAKISO | H36: UG | I36: 16 | J36: 8 | K36: =VLOOKUP(J36,Key!$E$2:$F$9,2,FALSE) -> Others | L36: STELLA | M36: WAKISO | N36: UG | O36: 1 | P36: 8 | Q36: =VLOOKUP(P36,Key!$E$2:$F$9,2,FALSE) -> Others | R36: =K36&"-"&Q36 -> Others-Others | T36: 0.5 | U36: 2 | Y36: Y | Z36: 1000 | AA36: =VLOOKUP(F36,Zones!$A$2:$F$15614,6,FALSE) -> 521 | AB36: =VLOOKUP(L36,Zones!$A$2:$F$15614,6,FALSE) -> 565
B37: 0.22569444 | C37: UBD 182M | D37: 1 | E37: 1 | F37: MUNYONYO | G37: WAKISO | H37: UG | I37: 16 | J37: 8 | K37: =VLOOKUP(J37,Key!$E$2:$F$9,2,FALSE) -> Others | L37: KIBULI | M37: KAMPALA | N37: UG | O37: 16 | P37: 8 | Q37: =VLOOKUP(P37,Key!$E$2:$F$9,2,FALSE) -> Others | R37: =K37&"-"&Q37 -> Others-Others | S37: 10 | T37: 0.5 | U37: 6 | Y37: Y | Z37: 1000 | AA37: =VLOOKUP(F37,Zones!$A$2:$F$15614,6,FALSE) -> 522 | AB37: =VLOOKUP(L37,Zones!$A$2:$F$15614,6,FALSE) -> 535
B38: 0.5 | C38: UEV 536D | D38: 11 | E38: 2 | F38: BUSABALA | G38: WAKISO | H38: UG | I38: 16 | J38: 8 | K38: =VLOOKUP(J38,Key!$E$2:$F$9,2,FALSE) -> Others | L38: MASAJJA | M38: WAKISO | N38: UG | O38: 16 | P38: 1 | Q38: =VLOOKUP(P38,Key!$E$2:$F$9,2,FALSE) -> Home | R38: =K38&"-"&Q38 -> Others-Home | T38: 0.2 | U38: 2 | Y38: Y | Z38: 1000 | AA38: =VLOOKUP(F38,Zones!$A$2:$F$15614,6,FALSE) -> 522 | AB38: =VLOOKUP(L38,Zones!$A$2:$F$15614,6,FALSE) -> 1398
B39: 0.010416667 | C39: UAV 583Y | D39: 1 | E39: 2 | F39: BUSABALA | G39: WAKISO | H39: UG | I39: 16 | J39: 8 | K39: =VLOOKUP(J39,Key!$E$2:$F$9,2,FALSE) -> Others | L39: STELLA | M39: WAKISO | N39: UG | O39: 1 | P39: 1 | Q39: =VLOOKUP(P39,Key!$E$2:$F$9,2,FALSE) -> Home | R39: =K39&"-"&Q39 -> Others-Home | T39: 0.5 | U39: 2 | Y39: Y | Z39: 1000 | AA39: =VLOOKUP(F39,Zones!$A$2:$F$15614,6,FALSE) -> 522 | AB39: =VLOOKUP(L39,Zones!$A$2:$F$15614,6,FALSE) -> 565
B40: 0.22916667 | C40: UAV 055D | D40: 1 | E40: 1 | F40: BUSABALA | G40: WAKISO | H40: UG | I40: 16 | J40: 8 | K40: =VLOOKUP(J40,Key!$E$2:$F$9,2,FALSE) -> Others | L40: NAJJANANKUMBI | M40: WAKISO | N40: UG | O40: 16 | P40: 8 | Q40: =VLOOKUP(P40,Key!$E$2:$F$9,2,FALSE) -> Others | R40: =K40&"-"&Q40 -> Others-Others | U40: 6 | Y40: Y | Z40: 1000 | AA40: =VLOOKUP(F40,Zones!$A$2:$F$15614,6,FALSE) -> 522 | AB40: =VLOOKUP(L40,Zones!$A$2:$F$15614,6,FALSE) -> 565
B41: 0.98541667 | C41: UAK 017J | D41: 4 | E41: 2 | F41: BUSABALA | G41: WAKISO | H41: UG | I41: 16 | J41: 8 | K41: =VLOOKUP(J41,Key!$E$2:$F$9,2,FALSE) -> Others | L41: STELLA | M41: WAKISO | N41: UG | O41: 16 | P41: 8 | Q41: =VLOOKUP(P41,Key!$E$2:$F$9,2,FALSE) -> Others | R41: =K41&"-"&Q41 -> Others-Others | T41: 0.3 | U41: 2 | Y41: Y | Z41: 1000 | AA41: =VLOOKUP(F41,Zones!$A$2:$F$15614,6,FALSE) -> 522 | AB41: =VLOOKUP(L41,Zones!$A$2:$F$15614,6,FALSE) -> 565
B42: 0.25 | C42: UAS 775J | D42: 4 | E42: 4 | F42: KIBIRI | G42: WAKISO | H42: UG | I42: 6 | J42: 2 | K42: =VLOOKUP(J42,Key!$E$2:$F$9,2,FALSE) -> Work | L42: TOWN CITY | M42: KAMPALA | N42: UG | O42: 6 | P42: 2 | Q42: =VLOOKUP(P42,Key!$E$2:$F$9,2,FALSE) -> Work | R42: =K42&"-"&Q42 -> Work-Work | S42: 15 | T42: 0.5 | U42: 2 | Y42: Y | Z42: 1000 | AA42: =VLOOKUP(F42,Zones!$A$2:$F$15614,6,FALSE) -> 522 | AB42: =VLOOKUP(L42,Zones!$A$2:$F$15614,6,FALSE) -> 521
...

Sheet Zones
A1: ZONE NAME | B1: DISTRICT | C1: COUNTY | D1: SUBCOUNTY | E1: Parish | F1: ZONE No.
A2: Abim | B2: Abim | C2: Labwor | D2: =A2 -> Abim | F2: 1
A3: Abim Town Council | B3: Abim | C3: Labwor | D3: =A3 -> Abim Town Council | F3: 2
A4: Alerek | B4: Abim | C4: Labwor | D4: =A4 -> Alerek | F4: 3
A5: Lotukei | B5: Abim | C5: Labwor | D5: =A5 -> Lotukei | F5: 4
A6: Morulem | B6: Abim | C6: Labwor | D6: =A6 -> Morulem | F6: 5
A7: Nyakwae | B7: Abim | C7: Labwor | D7: =A7 -> Nyakwae | F7: 6
A8: Adjumani Town Council | B8: Adjumani | C8: East Moyo | D8: =A8 -> Adjumani Town Council | F8: 7
A9: Adropi | B9: Adjumani | C9: East Moyo | D9: =A9 -> Adropi | F9: 8
A10: Arinyapi | B10: Adjumani | C10: East Moyo | D10: =A10 -> Arinyapi | F10: 9
A11: Ciforo | B11: Adjumani | C11: East Moyo | D11: =A11 -> Ciforo | F11: 10
A12: Dzaipi | B12: Adjumani | C12: East Moyo | D12: =A12 -> Dzaipi | F12: 11
A13: Itirikwa | B13: Adjumani | C13: East Moyo | D13: =A13 -> Itirikwa | F13: 12
... A166: Lugazi Municipality | B166: Buikwe | C166: Lugazi Municipality | D166: =A166 -> Lugazi Municipality | F166: 165
A167: LUGAZI | D167: =A167 -> LUGAZI | F167: 165
A168: Najja | B168: Buikwe | C168: Buikwe | D168: =A168 -> Najja | F168: 166
A169: Ngogwe | B169: Buikwe | C169: Buikwe | D169: =A169 -> Ngogwe | F169: 167
A170: Njeru Municipality | B170: Buikwe | C170: Njeru Municipality | D170: =A170 -> Njeru Municipality | F170: 168
A171: Nkokonjeru Town Council | B171: Buikwe | C171: Buikwe | D171: =A171 -> Nkokonjeru Town Council | F171: 169
A172: Ssi-Bukunja | B172: Buikwe | C172: Buikwe | D172: =A172 -> Ssi-Bukunja | F172: 170
A173: Bukedea | B173: Bukedea | C173: Bukedea | D173: =A173 -> Bukedea | F173: 171
A174: Bukedea Town Council | B174: Bukedea | C174: Bukedea | D174: =A174 -> Bukedea Town Council | F174: 172
A175: Kachumbala | B175: Bukedea | C175: Bukedea | D175: =A175 -> Kachumbala | F175: 173
A176: Kidongole | B176: Bukedea | C176: Bukedea | D176: =A176 -> Kidongole | F176: 174
A177: Kolir | B177: Bukedea | C177: Bukedea | D177: =A177 -> Kolir | F177: 175
A178: Malera | B178: Bukedea | C178: Bukedea | D178: =A178 -> Malera | F178: 176
A179: Bigasa | B179: Bukomansimbi | C179: Bukomansimbi | D179: =A179 -> Bigasa | F179: 177
... A337: Gulu Municipality | B337: Gulu | C337: Gulu Municipality | D337: =A337 -> Gulu Municipality | F337: 335
A338: GULU | D338: =A338 -> GULU | F338: 335
A339: Paicho | B339: Gulu | C339: Aswa | D339: =A339 -> Paicho | F339: 336
A340: Unyama | B340: Gulu | C340: Aswa | D340: =A340 -> Unyama | F340: 337
A341: Bugambe | B341: Hoima | C341: Buhaguzi | D341: =A341 -> Bugambe | F341: 338
A342: Buhanika | B342: Hoima | C342: Bugahya | D342: =A342 -> Buhanika | F342: 339
A343: Buhimba | B343: Hoima | C343: Buhaguzi | D343: =A343 -> Buhimba | F343: 340
A344: Hoima Municipality | B344: Hoima | C344: Hoima Municipality | D344: =A344 -> Hoima Municipality | F344: 341
A345: HOIMA | D345: =A345 -> HOIMA | F345: 341
A346: Hima cement | D346: =A346 -> Hima cement | F346: 341
A347: Kabwoya | B347: Hoima | C347: Buhaguzi | D347: =A347 -> Kabwoya | F347: 342
A348: Kigorobya | B348: Hoima | C348: Bugahya | D348: =A348 -> Kigorobya | F348: 343
A349: Kigorobya Town Council | B349: Hoima | C349: Bugahya | D349: =A349 -> Kigorobya Town Council | F349: 344
...

Sheet Zone analysis
A1: Zone | B1: District | C1: County | D1: Subcounty | E1: Parish | F1: DRAFT FINAL ZONE LIST | G1: DISTRICT | H1: Subcounty
A2: 243 | B2: Alebtong | C2: Moroto | D2: Abako | F2: =D2 -> Abako | G2: =B2 -> Alebtong | H2: Abako
A3: 295 | B3: Zombo | C3: Okoro | D3: Abanga | F3: =D3 -> Abanga | G3: =B3 -> Zombo | H3: Abanga
A4: 886 | B4: Amuria | C4: Amuria | D4: Abarilela | F4: =D4 -> Abarilela | G4: =B4 -> Amuria | H4: Abarilela
A5: 215 | B5: Oyam | C5: Oyam | D5: Aber | F5: =D5 -> Aber | G5: =B5 -> Oyam | H5: Aber
A6: 244 | B6: Alebtong | C6: Moroto | D6: Abia | F6: =D6 -> Abia | G6: =B6 -> Alebtong | H6: Abia
A7: 151 | B7: Abim | C7: Labwor | D7: Abim | F7: =D7 -> Abim | G7: =B7 -> Abim | H7: Abim
A8: 152 | B8: Abim | C8: Labwor | D8: Abim Town Council | F8: =D8 -> Abim Town Council | G8: =B8 -> Abim | H8: Abim Town Council
A9: 107 | B9: Nebbi | C9: Nebbi Municipality | D9: Abindu Division | F9: =VLOOKUP(C9,[2]Municipalities!$C$9:$F$1522,4,FALSE) -> Nebbi Municipality | G9: =B9 -> Nebbi | H9: Abindu Division
A10: 216 | B10: Oyam | C10: Oyam | D10: Abok | F10: =D10 -> Abok | G10: =B10 -> Oyam | H10: Abok
A11: 256 | B11: Kole | C11: Kole | D11: Aboke | F11: =D11 -> Aboke | G11: =B11 -> Kole | H11: Aboke
A12: 11 | B12: Apac | C12: Kwania | D12: Abongomola | F12: =D12 -> Abongomola | G12: =B12 -> Apac | H12: Abongomola
A13: 198 | B13: Koboko | C13: Koboko | D13: Abuku | F13: =D13 -> Abuku | G13: =B13 -> Koboko | H13: Abuku
A14: 217 | B14: Oyam | C14: Oyam | D14: Acaba | F14: =D14 -> Acaba | G14: =B14 -> Oyam | H14: Acaba
A15: 126 | B15: Pader | C15: Aruu | D15: Acholibur | F15: =D15 -> Acholibur | G15: =B15 -> Pader | H15: Acholibur
A16: 897 | B16: Amuria | C16: Kapelebyong | D16: Acowa | F16: =D16 -> Acowa | G16: =B16 -> Amuria | H16: Acowa
A17: 173 | B17: Dokolo | C17: Dokolo | D17: Adeknino | F17: =D17 -> Adeknino | G17: =B17 -> Dokolo | H17: Adeknino
A18: 79 | B18: Lira | C18: Erute | D18: Adekokwok | F18: =D18 -> Adekokwok | G18: =B18 -> Lira | H18: Adekokwok
A19: 227 | B19: Agago | C19: Agago | D19: Adilang | F19: =D19 -> Adilang | G19: =B19 -> Agago | H19: Adilang
A20: 1 | B20: Adjumani | C20: East Moyo | D20: Adjumani Town Council | F20: =D20 -> Adjumani Town Council | G20: =B20 -> Adjumani | H20: Adjumani Town Council
A21: 174 | B21: Dokolo | C21: Dokolo | D21: Adok | F21: =D21 -> Adok | G21: =B21 -> Dokolo | H21: Adok
... A26: 287 | B26: Otuke | C26: Otuke | D26: Adwari | F26: =D26 -> Adwari | G26: =B26 -> Otuke | H26: Adwari
A27: 88 | B27: Lira | C27: Lira Municipality | D27: Adyel Division | F27: =VLOOKUP(C27,[2]Municipalities!$C$9:$F$1522,4,FALSE) -> Lira Municipality | G27: =B27 -> Lira | H27: Adyel Division
A28: 228 | B28: Agago | C28: Agago | D28: Agago Town Council | F28: =D28 -> Agago Town Council | G28: =B28 -> Agago | H28: Agago Town Council
A29: 80 | B29: Lira | C29: Erute | D29: Agali | F29: =D29 -> Agali | G29: =B29 -> Lira | H29: Agali
A30: 157 | B30: Amolatar | C30: Kioga | D30: Agikdak | F30: =D30 -> Agikdak | G30: =B30 -> Amolatar | H30: Agikdak
A31: 263 | B31: Lamwo | C31: Lamwo | D31: Agoro | F31: =D31 -> Agoro | G31: =B31 -> Lamwo | H31: Agoro
A32: 802 | B32: Pallisa | C32: Agule | D32: Agule | F32: =D32 -> Agule | G32: =B32 -> Pallisa | H32: Agule
A33: 175 | B33: Dokolo | C33: Dokolo | D33: Agwata | F33: =D33 -> Agwata | G33: =B33 -> Dokolo | H33: Agwata
A34: 81 | B34: Lira | C34: Erute | D34: Agweng | F34: =D34 -> Agweng | G34: =B34 -> Lira | H34: Agweng
A35: 158 | B35: Amolatar | C35: Kioga | D35: Agwingiri | F35: =D35 -> Agwingiri | G35: =B35 -> Amolatar | H35: Agwingiri
A36: 40 | B36: Arua | C36: Terego | D36: Aii-Vu | F36: =D36 -> Aii-Vu | G36: =B36 -> Arua | H36: Aii-Vu
A37: 46 | B37: Arua | C37: Vurra | D37: Ajia | F37: =D37 -> Ajia | G37: =B37 -> Arua | H37: Ajia
A38: 257 | B38: Kole | C38: Kole | D38: Akalo | F38: =D38 -> Akalo | G38: =B38 -> Kole | H38: Akalo
A39: 887 | B39: Amuria | C39: Amuria | D39: Akeriau | F39: =D39 -> Akeriau | G39: =B39 -> Amuria | H39: Akeriau
... A70: 31 | B70: Arua | C70: Madi Okollo | D70: Anyiribu | F70: =D70 -> Anyiribu | G70: =B70 -> Arua | H70: Anyiribu
A71: 20 | B71: Apac | C71: Apac Municipality | D71: Apac | F71: =VLOOKUP(C71,[2]Municipalities!$C$9:$F$1522,4,FALSE) -> Apac Muicipality | G71: =B71 -> Apac | H71: Apac
A72: 21 | B72: Apac | C72: Apac Municipality | D72: Apac Town Council | F72: =VLOOKUP(C72,[2]Municipalities!$C$9:$F$1522,4,FALSE) -> Apac Muicipality | G72: =B72 -> Apac | H72: Apac Town Council
A73: 249 | B73: Alebtong | C73: Moroto | D73: Apala | F73: =D73 -> Apala | G73: =B73 -> Alebtong | H73: Apala
A74: 846 | B74: Kaberamaido | C74: Kalaki | D74: Apapai | F74: =D74 -> Apapai | G74: =B74 -> Kaberamaido | H74: Apapai
...

Sheet 11.10.BUSABALA-ENTEBBE
B1: Consultancy services for Preparation of Expressway Development Master Plan (EDMP) for Uganda
B2: Roadside OD Interview Survey
B4: Date: | C4: 11.10.19 | E4: Road Name: | F4: BUSABALA ROAD | I4: Direction From: | L4: BUSABALA | N4: Interviewers: | O4: KYLO | V4: Supervisor: | W4: EMMA | Y4: Coded By: | Z4: AJOK EMILY | AA4: Chkd By: | AB4: Bakole Deo
I5: Direction To: | L5: ENTEBBE
B7: Time | C7: Veh_Reg_No. | D7: Veh_Type | E7: No. Occupants | F7: Origin_Address | I7: Origin_Establish | J7: Origin_Purpose | K7: Origin-Purpose Desc | L7: Destination_Address | O7: Destination_Establish | P7: Destination_Purpose | Q7: Destination_Purpose Desc | R7: Journey_Purpose | S7: Approx_Distance (Km) | T7: Approx_Journey Time (Hrs) | U7: Trip_Frequency | V7: GOODS VEHICLES ONLY | Y7: Would You Use Xpressways? | Z7: Pay How Much? (UGX) | AA7: Origin_Zone | AB7: Dest_Zone
F8: Village or Town | G8: District | H8: Country | L8: Village or Town | M8: District | N8: Country | V8: Goods_Type | W8: Goods_Quantity (Ton) | X8: Goods_Value (UGXm)
B9: 0.85277778 | C9: UBF 609Q | D9: 1 | E9: 1 | F9: TOWN CITY | G9: KAMPALA | H9: UG | I9: 2 | J9: 2 | K9: =VLOOKUP(J9,Key!$E$2:$F$9,2,FALSE) -> Work | L9: NAJANAKOBI | M9: KAMPALA | N9: UG | O9: 1 | P9: 1 | Q9: =VLOOKUP(P9,Key!$E$2:$F$9,2,FALSE) -> Home | R9: =K9&"-"&Q9 -> Work-Home | U9: 2 | Y9: Y
B10: 0.97222222 | C10: UAV 609X | D10: 1 | E10: 1 | F10: KIBIRI | G10: KAMPALA | H10: UG | I10: 2 | J10: 2 | K10: =VLOOKUP(J10,Key!$E$2:$F$9,2,FALSE) -> Work | L10: TOWN CITY | M10: KAMPALA | N10: UG | O10: 1 | P10: 1 | Q10: =VLOOKUP(P10,Key!$E$2:$F$9,2,FALSE) -> Home | R10: =K10&"-"&Q10 -> Work-Home | U10: 2 | Y10: Y | Z10: 1000
B11: 0.97569444 | C11: UBF 952P | D11: 1 | E11: 1 | F11: BUSABALA | G11: WAKISO | H11: UG | I11: 2 | J11: 2 | K11: =VLOOKUP(J11,Key!$E$2:$F$9,2,FALSE) -> Work | L11: NDEJJE | M11: KAMPALA | N11: UG | O11: 1 | P11: 1 | Q11: =VLOOKUP(P11,Key!$E$2:$F$9,2,FALSE) -> Home | R11: =K11&"-"&Q11 -> Work-Home | S11: 4 | T11: 1 | U11: 2 | Y11: Y
B12: 0.84722222 | C12: UBD 938L | D12: 1 | E12: 2 | F12: TOWN CITY | G12: KAMPALA | H12: UG | I12: 2 | J12: 2 | K12: =VLOOKUP(J12,Key!$E$2:$F$9,2,FALSE) -> Work | L12: KIBIRI | M12: KAMPALA | N12: UG | O12: 1 | P12: 1 | Q12: =VLOOKUP(P12,Key!$E$2:$F$9,2,FALSE) -> Home | R12: =K12&"-"&Q12 -> Work-Home | U12: 2 | Y12: Y | Z12: 1000
B13: 0.91319444 | C13: UDT 211K | D13: 11 | E13: 1 | F13: KIGO | G13: WAKISO | H13: UG | I13: 8 | J13: 8 | K13: =VLOOKUP(J13,Key!$E$2:$F$9,2,FALSE) -> Others | L13: KIBIRI | M13: KAMPALA | N13: UG | O13: 8 | P13: 2 | Q13: =VLOOKUP(P13,Key!$E$2:$F$9,2,FALSE) -> Work | R13: =K13&"-"&Q13 -> Others-Work | S13: 2 | T13: 0.41 | U13: 2 | Y13: Y | Z13: 300
B14: 0.90833333 | C14: UEP 791H | D14: 11 | E14: 1 | F14: BUSABALA | G14: WAKISO | H14: UG | I14: 8 | J14: 2 | K14: =VLOOKUP(J14,Key!$E$2:$F$9,2,FALSE) -> Work | L14: NDEJJE | M14: KAMPALA | N14: UG | O14: 8 | P14: 2 | Q14: =VLOOKUP(P14,Key!$E$2:$F$9,2,FALSE) -> Work | R14: =K14&"-"&Q14 -> Work-Work | U14: 2 | Y14: Y
B15: 0.91527778 | C15: UDX 127U | D15: 11 | E15: 2 | F15: TOWN CITY | G15: KAMPALA | H15: UG | I15: 8 | J15: 2 | K15: =VLOOKUP(J15,Key!$E$2:$F$9,2,FALSE) -> Work | L15: KIBIRI | M15: KAMPALA | N15: UG | O15: 8 | P15: 2 | Q15: =VLOOKUP(P15,Key!$E$2:$F$9,2,FALSE) -> Work | R15: =K15&"-"&Q15 -> Work-Work | U15: 2 | Y15: Y | Z15: 2000
B16: 0.375 | C16: UAU 679S | D16: 4 | E16: 2 | F16: BUSABALA | G16: WAKISO | H16: UG | I16: 6 | J16: 2 | K16: =VLOOKUP(J16,Key!$E$2:$F$9,2,FALSE) -> Work | L16: TOWN CITY | M16: KAMPALA | N16: UG | O16: 6 | P16: 2 | Q16: =VLOOKUP(P16,Key!$E$2:$F$9,2,FALSE) -> Work | R16: =K16&"-"&Q16 -> Work-Work | U16: 2 | Y16: Y | Z16: 500
B17: 0.89652778 | C17: UDL 240B | D17: 11 | E17: 2 | F17: BUSABALA | G17: WAKISO | H17: UG | I17: 8 | J17: 2 | K17: =VLOOKUP(J17,Key!$E$2:$F$9,2,FALSE) -> Work | L17: KIBIRI | M17: KAMPALA | N17: UG | O17: 1 | P17: 1 | Q17: =VLOOKUP(P17,Key!$E$2:$F$9,2,FALSE) -> Home | R17: =K17&"-"&Q17 -> Work-Home | S17: 2 | T17: 0.5 | U17: 2 | Y17: Y | Z17: 500
B18: 0.90972222 | C18: UAX 752U | D18: 1 | E18: 1 | F18: TOWN CITY | G18: KAMPALA | H18: UG | I18: 2 | J18: 2 | K18: =VLOOKUP(J18,Key!$E$2:$F$9,2,FALSE) -> Work | L18: KIBIRI | M18: KAMPALA | N18: UG | O18: 1 | P18: 1 | Q18: =VLOOKUP(P18,Key!$E$2:$F$9,2,FALSE) -> Home | R18: =K18&"-"&Q18 -> Work-Home | U18: 2 | Y18: Y | Z18: 500
B19: 21:45 | C19: UBE 594W | D19: 4 | E19: 8 | F19: BUSABALA | G19: WAKISO | H19: UG | I19: 6 | J19: 2 | K19: =VLOOKUP(J19,Key!$E$2:$F$9,2,FALSE) -> Work | L19: TOWN CITY | M19: KAMPALA | N19: UG | O19: 6 | P19: 2 | Q19: =VLOOKUP(P19,Key!$E$2:$F$9,2,FALSE) -> Work | R19: =K19&"-"&Q19 -> Work-Work | U19: 2 | Y19: Y | Z19: 500
B20: 0.92013889 | C20: UES 018U | D20: 11 | E20: 4 | F20: KIGO | G20: WAKISO | H20: UG | I20: 8 | J20: 2 | K20: =VLOOKUP(J20,Key!$E$2:$F$9,2,FALSE) -> Work | L20: KIBIRI | M20: KAMPALA | N20: UG | O20: 8 | P20: 2 | Q20: =VLOOKUP(P20,Key!$E$2:$F$9,2,FALSE) -> Work | R20: =K20&"-"&Q20 -> Work-Work | S20: 2 | T20: 0.5 | U20: 2 | Y20: Y | Z20: 100
B21: 0.91736111 | C21: UAR 033M | D21: 4 | E21: 2 | F21: BUSABALA | G21: WAKISO | H21: UG | I21: 6 | J21: 2 | K21: =VLOOKUP(J21,Key!$E$2:$F$9,2,FALSE) -> Work | L21: TOWN CITY | M21: KAMPALA | N21: UG | O21: 6 | P21: 2 | Q21: =VLOOKUP(P21,Key!$E$2:$F$9,2,FALSE) -> Work | R21: =K21&"-"&Q21 -> Work-Work | U21: 2 | Y21: Y | Z21: 500
B22: 0.92986111 | C22: UAN 128U | D22: 4 | E22: 4 | F22: BUSABALA | G22: WAKISO | H22: UG | I22: 6 | J22: 2 | K22: =VLOOKUP(J22,Key!$E$2:$F$9,2,FALSE) -> Work | L22: TOWN CITY | M22: KAMPALA | N22: UG | O22: 6 | P22: 2 | Q22: =VLOOKUP(P22,Key!$E$2:$F$9,2,FALSE) -> Work | R22: =K22&"-"&Q22 -> Work-Work | S22: 4 | T22: 1.5 | U22: 2 | Y22: Y | Z22: 500
B23: 0.92569444 | C23: UDU167M | D23: 11 | E23: 2 | F23: TOWN CITY | G23: KAMPALA | H23: UG | I23: 8 | J23: 2 | K23: =VLOOKUP(J23,Key!$E$2:$F$9,2,FALSE) -> Work | L23: KIBIRI | M23: KAMPALA | N23: UG | O23: 8 | P23: 1 | Q23: =VLOOKUP(P23,Key!$E$2:$F$9,2,FALSE) -> Home | R23: =K23&"-"&Q23 -> Work-Home | U23: 2 | Y23: Y
B24: 0.9375 | C24: UEX 713Z | D24: 11 | E24: 1 | F24: TOWN CITY | G24: KAMPALA | H24: UG | I24: 8 | J24: 2 | K24: =VLOOKUP(J24,Key!$E$2:$F$9,2,FALSE) -> Work | L24: KIBIRI | M24: KAMPALA | N24: UG | O24: 1 | P24: 1 | Q24: =VLOOKUP(P24,Key!$E$2:$F$9,2,FALSE) -> Home | R24: =K24&"-"&Q24 -> Work-Home | S24: 1 | T24: 0.4 | U24: 2 | Y24: Y | Z24: 500
B25: 0.95138889 | C25: UAJ 409F | D25: 4 | E25: 1 | F25: BUSEGA | G25: WAKISO | H25: UG | I25: 6 | J25: 2 | K25: =VLOOKUP(J25,Key!$E$2:$F$9,2,FALSE) -> Work | L25: KIBIRI | M25: KAMPALA | N25: UG | O25: 1 | P25: 1 | Q25: =VLOOKUP(P25,Key!$E$2:$F$9,2,FALSE) -> Home | R25: =K25&"-"&Q25 -> Work-Home | U25: 2 | Y25: Y | Z25: 500
B26: 0.98263889 | C26: UAW 940M | D26: 4 | E26: 12 | F26: SOLOMA | G26: KAMPALA | H26: UG | I26: 6 | J26: 2 | K26: =VLOOKUP(J26,Key!$E$2:$F$9,2,FALSE) -> Work | L26: BUSALABA | M26: WAKISO | N26: UG | O26: 6 | P26: 2 | Q26: =VLOOKUP(P26,Key!$E$2:$F$9,2,FALSE) -> Work | R26: =K26&"-"&Q26 -> Work-Work | S26: 2 | T26: 1 | U26: 2 | Y26: Y | Z26: 1000
B27: 0.71805556 | C27: UBB 152W | D27: 1 | E27: 4 | F27: BUSABALA | G27: WAKISO | H27: UG | I27: 1 | J27: 2 | K27: =VLOOKUP(J27,Key!$E$2:$F$9,2,FALSE) -> Work | L27: KIBIRI | M27: KAMPALA | N27: UG | O27: 1 | P27: 1 | Q27: =VLOOKUP(P27,Key!$E$2:$F$9,2,FALSE) -> Home | R27: =K27&"-"&Q27 -> Work-Home | S27: 1 | T27: 0.5 | U27: 2 | Y27: Y | Z27: 500
B28: 0.15625 | C28: UAT 809Q | D28: 1 | E28: 2 | F28: TOWN CITY | G28: KAMPALA | H28: UG | I28: 2 | J28: 1 | K28: =VLOOKUP(J28,Key!$E$2:$F$9,2,FALSE) -> Home | L28: NDEJJE | M28: KAMPALA | N28: UG | O28: 1 | P28: 1 | Q28: =VLOOKUP(P28,Key!$E$2:$F$9,2,FALSE) -> Home | R28: =K28&"-"&Q28 -> Home-Home | U28: 2 | Y28: Y | Z28: 200
B29: 0.24305556 | C29: UBD 747T | D29: 1 | E29: 2 | F29: BUSABALA | G29: WAKISO | H29: UG | I29: 1 | J29: 1 | K29: =VLOOKUP(J29,Key!$E$2:$F$9,2,FALSE) -> Home | L29: NAMASUBA | M29: KAMPALA | N29: UG | O29: 2 | P29: 2 | Q29: =VLOOKUP(P29,Key!$E$2:$F$9,2,FALSE) -> Work | R29: =K29&"-"&Q29 -> Home-Work | S29: 1 | T29: 0.5 | U29: 2 | Y29: Y
B30: 0.97916667 | C30: UAT 486V | D30: 1 | E30: 1 | F30: TOWN CITY | G30: KAMPALA | H30: UG | I30: 1 | J30: 1 | K30: =VLOOKUP(J30,Key!$E$2:$F$9,2,FALSE) -> Home | L30: ZANA | M30: WAKISO | N30: UG | O30: 2 | P30: 2 | Q30: =VLOOKUP(P30,Key!$E$2:$F$9,2,FALSE) -> Work | R30: =K30&"-"&Q30 -> Home-Work | U30: 2 | Y30: Y | Z30: 1000
B31: 0.84722222 | C31: UAU 718Y | D31: 1 | E31: 2 | F31: BUSABALA | G31: WAKISO | H31: UG | I31: 2 | J31: 2 | K31: =VLOOKUP(J31,Key!$E$2:$F$9,2,FALSE) -> Work | L31: KIBIRI | M31: KAMPALA | N31: UG | O31: 1 | P31: 1 | Q31: =VLOOKUP(P31,Key!$E$2:$F$9,2,FALSE) -> Home | R31: =K31&"-"&Q31 -> Work-Home | S31: 2 | T31: 0.5 | U31: 2 | Y31: Y
B32: 0.96875 | C32: UBA 504Q | D32: 1 | E32: 1 | F32: NDEJJE | G32: WAKISO | H32: UG | I32: 2 | J32: 2 | K32: =VLOOKUP(J32,Key!$E$2:$F$9,2,FALSE) -> Work | L32: TOWN CITY | M32: KAMPALA | N32: UG | O32: 1 | P32: 1 | Q32: =VLOOKUP(P32,Key!$E$2:$F$9,2,FALSE) -> Home | R32: =K32&"-"&Q32 -> Work-Home | U32: 2 | Y32: Y | Z32: 1000
B33: 0.85763889 | C33: UAA 487F | D33: 3 | E33: 2 | F33: TOWN CITY | G33: KAMPALA | H33: UG | I33: 2 | J33: 2 | K33: =VLOOKUP(J33,Key!$E$2:$F$9,2,FALSE) -> Work | L33: SALOMA | M33: KAMPALA | N33: UG | O33: 1 | P33: 1 | Q33: Home | R33: Work-Home | S33: 4 | T33: 1.5 | U33: 2 | Y33: Y | Z33: 1000
B34: 0.80555556 | C34: UEF 219E | D34: 11 | E34: 1 | F34: MIREMBE | G34: WAKISO | H34: UG | I34: 16 | J34: 8 | K34: =VLOOKUP(J34,Key!$E$2:$F$9,2,FALSE) -> Others | L34: KIBIRI | M34: WAKISO | N34: UG | O34: 16 | P34: 8 | Q34: =VLOOKUP(P34,Key!$E$2:$F$9,2,FALSE) -> Others | R34: =K34&"-"&Q34 -> Others-Others | S34: 2 | T34: 0.2 | U34: 2 | Y34: Y | Z34: 1000
B35: 0.95069444 | C35: UEA 503J | D35: 11 | E35: 1 | F35: BUSABALA | G35: WAKISO | H35: UG | I35: 8 | J35: 2 | K35: =VLOOKUP(J35,Key!$E$2:$F$9,2,FALSE) -> Work | L35: MASAJJA | M35: WAKISO | N35: UG | O35: 1 | P35: 1 | Q35: =VLOOKUP(P35,Key!$E$2:$F$9,2,FALSE) -> Home | R35: =K35&"-"&Q35 -> Work-Home | T35: 0.5 | U35: 1 | Y35: Y | Z35: 1000
B36: 0.23125 | C36: UAS 232Z | D36: 1 | E36: 1 | F36: STATION | G36: WAKISO | H36: UG | I36: 16 | J36: 8 | K36: =VLOOKUP(J36,Key!$E$2:$F$9,2,FALSE) -> Others | L36: STELLA | M36: WAKISO | N36: UG | O36: 1 | P36: 8 | Q36: =VLOOKUP(P36,Key!$E$2:$F$9,2,FALSE) -> Others | R36: =K36&"-"&Q36 -> Others-Others | T36: 0.5 | U36: 2 | Y36: Y | Z36: 1000
B37: 0.22569444 | C37: UBD 182M | D37: 1 | E37: 1 | F37: MUNYONYO | G37: WAKISO | H37: UG | I37: 16 | J37: 8 | K37: =VLOOKUP(J37,Key!$E$2:$F$9,2,FALSE) -> Others | L37: KIBULI | M37: KAMPALA | N37: UG | O37: 16 | P37: 8 | Q37: =VLOOKUP(P37,Key!$E$2:$F$9,2,FALSE) -> Others | R37: =K37&"-"&Q37 -> Others-Others | S37: 10 | T37: 0.5 | U37: 6 | Y37: Y | Z37: 1000
B38: 0.5 | C38: UEV 536D | D38: 11 | E38: 2 | F38: BUSABALA | G38: WAKISO | H38: UG | I38: 16 | J38: 8 | K38: =VLOOKUP(J38,Key!$E$2:$F$9,2,FALSE) -> Others | L38: MASAJJA | M38: WAKISO | N38: UG | O38: 16 | P38: 1 | Q38: =VLOOKUP(P38,Key!$E$2:$F$9,2,FALSE) -> Home | R38: =K38&"-"&Q38 -> Others-Home | T38: 0.2 | U38: 2 | Y38: Y | Z38: 1000
B39: 0.010416667 | C39: UAV 583Y | D39: 1 | E39: 2 | F39: BUSABALA | G39: WAKISO | H39: UG | I39: 16 | J39: 8 | K39: =VLOOKUP(J39,Key!$E$2:$F$9,2,FALSE) -> Others | L39: STELLA | M39: WAKISO | N39: UG | O39: 1 | P39: 1 | Q39: =VLOOKUP(P39,Key!$E$2:$F$9,2,FALSE) -> Home | R39: =K39&"-"&Q39 -> Others-Home | T39: 0.5 | U39: 2 | Y39: Y | Z39: 1000
B40: 0.22916667 | C40: UAV 055D | D40: 1 | E40: 1 | F40: BUSABALA | G40: WAKISO | H40: UG | I40: 16 | J40: 8 | K40: =VLOOKUP(J40,Key!$E$2:$F$9,2,FALSE) -> Others | L40: NAJJANANKUMBI | M40: WAKISO | N40: UG | O40: 16 | P40: 8 | Q40: =VLOOKUP(P40,Key!$E$2:$F$9,2,FALSE) -> Others | R40: =K40&"-"&Q40 -> Others-Others | U40: 6 | Y40: Y | Z40: 1000
B41: 0.98541667 | C41: UAK 017J | D41: 4 | E41: 2 | F41: MIVALO | G41: WAKISO | H41: UG | I41: 16 | J41: 8 | K41: =VLOOKUP(J41,Key!$E$2:$F$9,2,FALSE) -> Others | L41: STELLA | M41: WAKISO | N41: UG | O41: 16 | P41: 8 | Q41: =VLOOKUP(P41,Key!$E$2:$F$9,2,FALSE) -> Others | R41: =K41&"-"&Q41 -> Others-Others | T41: 0.3 | U41: 2 | Y41: Y | Z41: 1000
B42: 0.25 | C42: UAS 775J | D42: 4 | E42: 4 | F42: KIBIRI | G42: WAKISO | H42: UG | I42: 6 | J42: 2 | K42: =VLOOKUP(J42,Key!$E$2:$F$9,2,FALSE) -> Work | L42: TOWN CITY | M42: KAMPALA | N42: UG | O42: 6 | P42: 2 | Q42: =VLOOKUP(P42,Key!$E$2:$F$9,2,FALSE) -> Work | R42: =K42&"-"&Q42 -> Work-Work | S42: 15 | T42: 0.5 | U42: 2 | Y42: Y | Z42: 1000
...

Sheet RSI FORM
B1: Feasibility Study and Detailed Design of Kampala - Jinja Highway
B2: Roadside OD Interview Survey
B4: Date: | C4: 40465 | D4: Interviewer: | G4: Survey Station: | H4: Bweyogerere | J4: Direction: | K4: Bweyogerere-Kireka | L4: Coded By: | N4: Chkd By:
B7: Time Period | C7: Veh_Type | D7: Veh_Other | E7: Occupancy | F7: Origin_Address | H7: Origin_Purpose | I7: Origin_other | J7: Destination_Address | L7: Destination_Purpose | M7: Destination_Other | N7: Origin_Zone | O7: Dest_Zone | P7: WTP
F8: Village/Town | G8: City/Country | J8: Village/Town | K8: City/Country
B9: AM | C9: 3 | E9: 2 | F9: Entebbe | G9: Kla, Ug | H9: 1 | J9: Kla | K9: Kla, Ug | L9: 2 | N9: Blank | O9: Blank | P9: Yes | Q9: 3000
B10: AM | C10: 1 | E10: 1 | F10: Kiwanga | G10: Kla, Ug | H10: 1 | J10: Kla | K10: Kla, Ug | L10: 2 | N10: Blank | O10: Blank | P10: Yes | Q10: 2000
B11: AM | E11: 1 | F11: Bukoto | G11: Kla, Ug | H11: 3 | J11: Kla | K11: Kla, Ug | L11: 1 | N11: Blank | O11: Blank
B12: AM
B13: AM
B14: AM
B15: AM
B16: AM
B17: AM
B18: AM
B19: AM
B20: AM
B21: AM
B22: AM
B23: AM
... B53: AM

Sheet 11.10.ENTEBBE-BUSABALA
B1: Consultancy services for Preparation of Expressway Development Master Plan (EDMP) for Uganda
B2: Roadside OD Interview Survey
B4: Date: | C4: 11.09.19 | E4: Road Name: | F4: ='11.10.BUSABALA-ENTEBBE'!F4:G4 -> BUSABALA ROAD | I4: Direction From: | L4: ENTEBBE | N4: Interviewers: | O4: DRAKE | V4: Supervisor: | W4: ='11.10.BUSABALA-ENTEBBE'!W4 -> EMMA | Y4: Coded By: | Z4: ='11.10.BUSABALA-ENTEBBE'!Z4 -> AJOK EMILY | AA4: Chkd By: | AB4: ='11.10.BUSABALA-ENTEBBE'!AB4 -> Bakole Deo
I5: Direction To: | L5: BUSABALA
B7: Time | C7: Veh_Reg_No. | D7: Veh_Type | E7: No. Occupants | F7: Origin_Address | I7: Origin_Establish | J7: Origin_Purpose | K7: Origin-Purpose Desc | L7: Destination_Address | O7: Destination_Establish | P7: Destination_Purpose | Q7: Destination_Purpose Desc | R7: Journey_Purpose | S7: Approx_Distance (Km) | T7: Approx_Journey Time (Hrs) | U7: Trip_Frequency | V7: GOODS VEHICLES ONLY | Y7: Would You Use Xpressways? | Z7: Pay How Much? (UGX) | AA7: Origin_Zone | AB7: Dest_Zone
F8: Village or Town | G8: District | H8: Country | L8: Village or Town | M8: District | N8: Country | V8: Goods_Type | W8: Goods_Quantity (Ton) | X8: Goods_Value (UGXm)
B9: 0.1875 | C9: UAP 896F | D9: 4 | E9: 14 | F9: KIBUYE | G9: KAMPALA | H9: UG | I9: 6 | J9: 2 | K9: =VLOOKUP(J9,Key!$E$2:$F$9,2,FALSE) -> Work | L9: MWALO | M9: KAMPALA | N9: UG | O9: 6 | P9: 2 | Q9: =VLOOKUP(P9,Key!$E$2:$F$9,2,FALSE) -> Work | R9: =K9&"-"&Q9 -> Work-Work | T9: 1 | U9: 1 | Y9: Y | Z9: 1000
B10: 0.20833333 | C10: UAZ 713H | D10: 4 | E10: 6 | F10: NEW PARK | G10: KAMPALA | H10: UG | I10: 6 | J10: 2 | K10: =VLOOKUP(J10,Key!$E$2:$F$9,2,FALSE) -> Work | L10: BUSABALA | M10: WAKISO | N10: UG | O10: 6 | P10: 2 | Q10: =VLOOKUP(P10,Key!$E$2:$F$9,2,FALSE) -> Work | R10: =K10&"-"&Q10 -> Work-Work | S10: 13 | T10: 0.8 | U10: 1 | Y10: Y | Z10: 1500
B11: 0.083333333 | C11: UAE 495U | D11: 4 | E11: 10 | F11: MUWUSA | G11: KAMPALA | H11: UG | I11: 6 | J11: 2 | K11: =VLOOKUP(J11,Key!$E$2:$F$9,2,FALSE) -> Work | L11: BUSABALA | M11: WAKISO | N11: UG | O11: 6 | P11: 2 | Q11: =VLOOKUP(P11,Key!$E$2:$F$9,2,FALSE) -> Work | R11: =K11&"-"&Q11 -> Work-Work | T11: 1 | U11: 1 | Y11: Y | Z11: 500
B12: 0.59930556 | C12: UDX 264J | D12: 11 | E12: 1 | F12: MASAJJA | G12: WAKISO | H12: UG | I12: 8 | J12: 2 | K12: =VLOOKUP(J12,Key!$E$2:$F$9,2,FALSE) -> Work | L12: KIRIDA | M12: WAKISO | N12: UG | O12: 8 | P12: 2 | Q12: =VLOOKUP(P12,Key!$E$2:$F$9,2,FALSE) -> Work | R12: =K12&"-"&Q12 -> Work-Work | S12: 8.04 | T12: 1 | U12: 1 | Y12: Y | Z12: 500
B13: 0.60902778 | C13: UAY 473Y | D13: 4 | E13: 10 | F13: KIBUYE | G13: KAMPALA | H13: UG | I13: 6 | J13: 2 | K13: Work | L13: BUSABALA | M13: WAKISO | N13: UG | O13: 6 | P13: 2 | Q13: =VLOOKUP(P13,Key!$E$2:$F$9,2,FALSE) -> Work | R13: =K13&"-"&Q13 -> Work-Work | T13: 0.5 | U13: 1 | Y13: Y | Z13: 500
B14: 0.12013889 | C14: UBD 434L | D14: 1 | E14: 2 | F14: MASAJJA | G14: WAKISO | H14: UG | I14: 16 | J14: 2 | K14: =VLOOKUP(J14,Key!$E$2:$F$9,2,FALSE) -> Work | L14: MUNYONYO | M14: KAMPALA | N14: UG | O14: 1 | P14: 1 | Q14: =VLOOKUP(P14,Key!$E$2:$F$9,2,FALSE) -> Home | R14: =K14&"-"&Q14 -> Work-Home | T14: 0.2 | U14: 3 | Y14: Y | Z14: 1000
B15: 0.59027778 | C15: UDU 313N | D15: 11 | E15: 1 | F15: GANGU | G15: WAKISO | H15: UG | I15: 8 | J15: 1 | K15: =VLOOKUP(J15,Key!$E$2:$F$9,2,FALSE) -> Home | L15: BUSABALA | M15: WAKISO | N15: UG | O15: 8 | P15: 1 | Q15: =VLOOKUP(P15,Key!$E$2:$F$9,2,FALSE) -> Home | R15: =K15&"-"&Q15 -> Home-Home | S15: 1 | T15: 0.2 | U15: 6 | Y15: Y | Z15: 3000
B16: 0.8875 | C16: UAR 033M | D16: 4 | E16: 7 | F16: KATWE | G16: KAMPALA | H16: UG | I16: 6 | J16: 2 | K16: =VLOOKUP(J16,Key!$E$2:$F$9,2,FALSE) -> Work | L16: STATION CENTRE | M16: WAKISO | N16: UG | O16: 6 | P16: 2 | Q16: =VLOOKUP(P16,Key!$E$2:$F$9,2,FALSE) -> Work | R16: =K16&"-"&Q16 -> Work-Work | T16: 0.8 | U16: 1 | Y16: Y | Z16: 400
B17: 0.89722222 | C17: UAW 453D | D17: 4 | E17: 11 | F17: KIBUYE | G17: KAMPALA | H17: UG | I17: 6 | J17: 2 | K17: =VLOOKUP(J17,Key!$E$2:$F$9,2,FALSE) -> Work | L17: MWALO | M17: WAKISO | N17: UG | O17: 6 | P17: 2 | Q17: =VLOOKUP(P17,Key!$E$2:$F$9,2,FALSE) -> Work | R17: =K17&"-"&Q17 -> Work-Work | T17: 1 | U17: 2 | Y17: Y | Z17: 500
B18: 0.90277778 | C18: UBB 159Y | D18: 1 | E18: 1 | F18: NDEJJE | G18: WAKISO | H18: UG | I18: 4 | J18: 3 | K18: =VLOOKUP(J18,Key!$E$2:$F$9,2,FALSE) -> Study | L18: MUNYONYO | M18: KAMPALA | N18: UG | O18: 1 | P18: 1 | Q18: =VLOOKUP(P18,Key!$E$2:$F$9,2,FALSE) -> Home | R18: =K18&"-"&Q18 -> Study-Home | T18: 0.25 | U18: 2 | Y18: Y
B19: 0.91111111 | C19: UAX 017J | D19: 1 | E19: 2 | F19: KISENYI | G19: KAMPALA | H19: UG | I19: 6 | J19: 2 | K19: =VLOOKUP(J19,Key!$E$2:$F$9,2,FALSE) -> Work | L19: MUNYONYO | M19: KAMPALA | N19: UG | O19: 1 | P19: 1 | Q19: =VLOOKUP(P19,Key!$E$2:$F$9,2,FALSE) -> Home | R19: =K19&"-"&Q19 -> Work-Home | S19: 7 | T19: 1.5 | U19: 4 | Y19: Y | Z19: 500
B20: 0.91666667 | C20: UAU 705A | D20: 4 | E20: 3 | F20: MATEGURA | G20: WAKISO | H20: UG | I20: 6 | J20: 2 | K20: =VLOOKUP(J20,Key!$E$2:$F$9,2,FALSE) -> Work | L20: KUMWALO | M20: WAKISO | N20: UG | O20: 6 | P20: 2 | Q20: =VLOOKUP(P20,Key!$E$2:$F$9,2,FALSE) -> Work | R20: =K20&"-"&Q20 -> Work-Work | S20: 5 | T20: 1 | U20: 2 | Y20: Y | Z20: 500
B21: 0.925 | C21: UAT 800T | D21: 4 | E21: 2 | F21: OLD PARK | G21: KAMPALA | H21: UG | I21: 6 | J21: 2 | K21: =VLOOKUP(J21,Key!$E$2:$F$9,2,FALSE) -> Work | L21: BUSABALA | M21: WAKISO | N21: UG | O21: 6 | P21: 2 | Q21: =VLOOKUP(P21,Key!$E$2:$F$9,2,FALSE) -> Work | R21: =K21&"-"&Q21 -> Work-Work | S21: 10 | T21: 1.5 | U21: 1 | Y21: Y | Z21: 1000
B22: 0.93055556 | C22: UDJ 488K | D22: 11 | E22: 2 | F22: KAYEMBE | G22: WAKISO | H22: UG | I22: 8 | J22: 2 | K22: =VLOOKUP(J22,Key!$E$2:$F$9,2,FALSE) -> Work | L22: STATION CENTRE | M22: WAKISO | N22: UG | O22: 8 | P22: 2 | Q22: =VLOOKUP(P22,Key!$E$2:$F$9,2,FALSE) -> Work | R22: =K22&"-"&Q22 -> Work-Work | S22: 4 | T22: 0.4 | U22: 3 | Y22: Y
B23: 0.94097222 | C23: UET 485P | D23: 11 | E23: 2 | F23: KAYEMBE | G23: WAKISO | H23: UG | I23: 8 | J23: 2 | K23: =VLOOKUP(J23,Key!$E$2:$F$9,2,FALSE) -> Work | L23: STATION CENTRE | M23: WAKISO | N23: UG | O23: 8 | P23: 2 | Q23: =VLOOKUP(P23,Key!$E$2:$F$9,2,FALSE) -> Work | R23: =K23&"-"&Q23 -> Work-Work | T23: 0.6 | U23: 1 | Y23: Y
B24: 0.94583333 | C24: UBE 417T | D24: 1 | E24: 2 | F24: MASAJJA | G24: WAKISO | H24: UG | I24: 1 | J24: 1 | K24: =VLOOKUP(J24,Key!$E$2:$F$9,2,FALSE) -> Home | L24: MUNYONYO | M24: KAMPALA | N24: UG | O24: 16 | P24: 6 | Q24: =VLOOKUP(P24,Key!$E$2:$F$9,2,FALSE) -> Leisure/Social | R24: =K24&"-"&Q24 -> Home-Leisure/Social | T24: 0.3 | U24: 3 | Y24: Y | Z24: 1000
B25: 0.99305556 | C25: UAX 046B | D25: 1 | E25: 1 | F25: NDEJJE | G25: WAKISO | H25: UG | I25: 16 | J25: 8 | K25: =VLOOKUP(J25,Key!$E$2:$F$9,2,FALSE) -> Others | L25: MUNYONYO | M25: KAMPALA | N25: UG | O25: 1 | P25: 1 | Q25: =VLOOKUP(P25,Key!$E$2:$F$9,2,FALSE) -> Home | R25: =K25&"-"&Q25 -> Others-Home | T25: 0.4 | U25: 4 | Y25: Y | Z25: 3000
B26: 0.9875 | C26: UAN 230F | D26: 1 | E26: 1 | F26: MAKINDYE | G26: KAMPALA | H26: UG | I26: 2 | J26: 2 | K26: =VLOOKUP(J26,Key!$E$2:$F$9,2,FALSE) -> Work | L26: MUNYONYO | M26: KAMPALA | N26: UG | O26: 1 | P26: 1 | Q26: =VLOOKUP(P26,Key!$E$2:$F$9,2,FALSE) -> Home | R26: =K26&"-"&Q26 -> Work-Home | T26: 0.8 | U26: 2 | Y26: Y | Z26: 2000
B27: 0.5 | C27: UBB 212P | D27: 1 | E27: 1 | F27: MENGO | G27: KAMPALA | H27: UG | I27: 5 | J27: 7 | K27: =VLOOKUP(J27,Key!$E$2:$F$9,2,FALSE) -> Hospital | L27: BUSABALA | M27: WAKISO | N27: UG | O27: 1 | P27: 1 | Q27: =VLOOKUP(P27,Key!$E$2:$F$9,2,FALSE) -> Home | R27: =K27&"-"&Q27 -> Hospital-Home | T27: 1 | U27: 1 | Y27: Y | Z27: 1000
B28: 0.056944444 | C28: UBA 489V | D28: 1 | E28: 1 | F28: NTINDA | G28: KAMPALA | H28: UG | I28: 16 | J28: 2 | K28: =VLOOKUP(J28,Key!$E$2:$F$9,2,FALSE) -> Work | L28: BUSABALA | M28: WAKISO | N28: UG | O28: 1 | P28: 1 | Q28: =VLOOKUP(P28,Key!$E$2:$F$9,2,FALSE) -> Home | R28: =K28&"-"&Q28 -> Work-Home | T28: 1.5 | U28: 2 | Y28: Y | Z28: 2000

Sheet 12.10 ENTEBBE-BUSABALA
B1: Consultancy services for Preparation of Expressway Development Master Plan (EDMP) for Uganda
B2: Roadside OD Interview Survey
B4: Date: | C4: 12.09.19 | E4: Road Name: | F4: ='11.10.BUSABALA-ENTEBBE'!F4:G4 -> BUSABALA ROAD | I4: Direction From: | L4: ENTEBBE | N4: Interviewers: | O4: DRAKE | V4: Supervisor: | W4: ='11.10.BUSABALA-ENTEBBE'!W4 -> EMMA | Y4: Coded By: | Z4: ='11.10.BUSABALA-ENTEBBE'!Z4 -> AJOK EMILY | AA4: Chkd By: | AB4: ='11.10.BUSABALA-ENTEBBE'!AB4 -> Bakole Deo
I5: Direction To: | L5: BUSABALA
B7: Time | C7: Veh_Reg_No. | D7: Veh_Type | E7: No. Occupants | F7: Origin_Address | I7: Origin_Establish | J7: Origin_Purpose | K7: Origin-Purpose Desc | L7: Destination_Address | O7: Destination_Establish | P7: Destination_Purpose | Q7: Destination_Purpose Desc | R7: Journey_Purpose | S7: Approx_Distance (Km) | T7: Approx_Journey Time (Hrs) | U7: Trip_Frequency | V7: GOODS VEHICLES ONLY | Y7: Would You Use Xpressways? | Z7: Pay How Much? (UGX) | AA7: Origin_Zone | AB7: Dest_Zone
F8: Village or Town | G8: District | H8: Country | L8: Village or Town | M8: District | N8: Country | V8: Goods_Type | W8: Goods_Quantity (Ton) | X8: Goods_Value (UGXm)
B9: 0.71527778 | C9: UBB 566R | D9: 4 | E9: 14 | F9: KIBUYE | G9: KAMPALA | H9: UG | I9: 6 | J9: 2 | K9: =VLOOKUP(J9,Key!$E$2:$F$9,2,FALSE) -> Work | L9: BUSABALA | M9: WAKISO | N9: UG | O9: 6 | P9: 2 | Q9: =VLOOKUP(P9,Key!$E$2:$F$9,2,FALSE) -> Work | R9: =K9&"-"&Q9 -> Work-Work | T9: 1.5 | U9: 1 | Y9: Y | Z9: 1000
B10: 0.68055556 | C10: UEY 068W | D10: 11 | E10: 2 | F10: TOWN CITY | G10: KAMPALA | H10: UG | I10: 8 | J10: 2 | K10: =VLOOKUP(J10,Key!$E$2:$F$9,2,FALSE) -> Work | L10: BUSABALA | M10: WAKISO | N10: UG | O10: 8 | P10: 2 | Q10: =VLOOKUP(P10,Key!$E$2:$F$9,2,FALSE) -> Work | R10: =K10&"-"&Q10 -> Work-Work | T10: 0.8 | U10: 3 | Y10: Y | Z10: 1000
B11: 0.66527778 | C11: UAF 627X | D11: 10 | E11: 2 | F11: GANGO | G11: WAKISO | H11: UG | I11: 10 | J11: 2 | K11: =VLOOKUP(J11,Key!$E$2:$F$9,2,FALSE) -> Work | L11: BUSABALA | M11: WAKISO | N11: UG | O11: 1 | P11: 1 | Q11: =VLOOKUP(P11,Key!$E$2:$F$9,2,FALSE) -> Home | R11: =K11&"-"&Q11 -> Work-Home | T11: 0.8 | U11: 1 | Y11: Y | Z11: 500
B12: 0.65763889 | C12: UDZ 201Z | D12: 11 | E12: 1 | F12: KATWE | G12: KAMPALA | H12: UG | I12: 8 | J12: 2 | K12: =VLOOKUP(J12,Key!$E$2:$F$9,2,FALSE) -> Work | L12: BUSABALA | M12: WAKISO | N12: UG | O12: 1 | P12: 1 | Q12: =VLOOKUP(P12,Key!$E$2:$F$9,2,FALSE) -> Home | R12: =K12&"-"&Q12 -> Work-Home | T12: 0.8 | U12: 1 | Y12: Y | Z12: 1000
B13: 0.64861111 | C13: UBD 507K | D13: 8 | E13: 1 | F13: GANGO | G13: WAKISO | H13: UG | I13: 10 | J13: 2 | K13: =VLOOKUP(J13,Key!$E$2:$F$9,2,FALSE) -> Work | L13: BUSABALA | M13: WAKISO | N13: UG | O13: 15 | P13: 2 | Q13: =VLOOKUP(P13,Key!$E$2:$F$9,2,FALSE) -> Work | R13: =K13&"-"&Q13 -> Work-Work | T13: 1 | U13: 1 | Y13: Y | Z13: 2000
B14: 0.64027778 | C14: UAZ 333E | D14: 1 | E14: 2 | F14: GANGO | G14: WAKISO | H14: UG | I14: 1 | J14: 1 | K14: =VLOOKUP(J14,Key!$E$2:$F$9,2,FALSE) -> Home | L14: ENTEBBE | M14: WAKISO | N14: UG | O14: 16 | P14: 2 | Q14: =VLOOKUP(P14,Key!$E$2:$F$9,2,FALSE) -> Work | R14: =K14&"-"&Q14 -> Home-Work | T14: 0.6 | U14: 2 | Y14: Y | Z14: 1000
B15: 0.625 | C15: UAW 844S | D15: 1 | E15: 2 | F15: NZIVANUGI | G15: WAKISO | H15: UG | I15: 1 | J15: 1 | K15: =VLOOKUP(J15,Key!$E$2:$F$9,2,FALSE) -> Home | L15: KASANGA | M15: KAMPALA | N15: UG | O15: 2 | P15: 2 | Q15: =VLOOKUP(P15,Key!$E$2:$F$9,2,FALSE) -> Work | R15: =K15&"-"&Q15 -> Home-Work | S15: 15 | T15: 0.8 | U15: 2 | Y15: Y | Z15: 1000
B16: 0.61944444 | C16: UAB 005C | D16: 1 | E16: 2 | F16: KANABA | G16: WAKISO | H16: UG | I16: 1 | J16: 1 | K16: =VLOOKUP(J16,Key!$E$2:$F$9,2,FALSE) -> Home | L16: TOWN CITY | M16: KAMPALA | N16: UG | O16: 2 | P16: 1 | Q16: =VLOOKUP(P16,Key!$E$2:$F$9,2,FALSE) -> Home | R16: =K16&"-"&Q16 -> Home-Home | T16: 0.8 | U16: 1 | Y16: Y | Z16: 1000
B17: 0.61041667 | C17: UDQ 1000C | D17: 11 | E17: 2 | F17: KIBIRI | G17: WAKISO | H17: UG | I17: 8 | J17: 2 | K17: =VLOOKUP(J17,Key!$E$2:$F$9,2,FALSE) -> Work | L17: BUSABALA | M17: WAKISO | N17: UG | O17: 8 | P17: 2 | Q17: =VLOOKUP(P17,Key!$E$2:$F$9,2,FALSE) -> Work | R17: =K17&"-"&Q17 -> Work-Work | T17: 0.3 | U17: 1 | Y17: Y | Z17: 1000
B18: 0.59861111 | C18: UBD 060V | D18: 5 | E18: 36 | F18: WAKISO TOWN | G18: WAKISO | H18: UG | I18: 16 | J18: 8 | K18: =VLOOKUP(J18,Key!$E$2:$F$9,2,FALSE) -> Others | L18: BUSABALA | M18: WAKISO | N18: UG | O18: 16 | P18: 6 | Q18: =VLOOKUP(P18,Key!$E$2:$F$9,2,FALSE) -> Leisure/Social | R18: =K18&"-"&Q18 -> Others-Leisure/Social | S18: 30 | T18: 120 | U18: 6 | Y18: Y
B19: 0.58958333 | C19: UBF 039U | D19: 8 | E19: 2 | F19: GANGO | G19: WAKISO | H19: UG | I19: 10 | J19: 1 | K19: =VLOOKUP(J19,Key!$E$2:$F$9,2,FALSE) -> Home | L19: KIGO | M19: WAKISO | N19: UG | O19: 15 | P19: 1 | Q19: =VLOOKUP(P19,Key!$E$2:$F$9,2,FALSE) -> Home | R19: =K19&"-"&Q19 -> Home-Home | S19: 1 | T19: 0.2 | U19: 1 | Y19: Y | Z19: 1500
B20: 0.59305556 | C20: UAS 026T | D20: 1 | E20: 1 | F20: GANGO | G20: WAKISO | H20: UG | I20: 16 | J20: 8 | K20: =VLOOKUP(J20,Key!$E$2:$F$9,2,FALSE) -> Others | L20: ENTEBBE | M20: WAKISO | N20: UG | O20: 16 | P20: 8 | Q20: =VLOOKUP(P20,Key!$E$2:$F$9,2,FALSE) -> Others | R20: =K20&"-"&Q20 -> Others-Others | T20: 0.3 | U20: 1 | Y20: Y
B21: 0.55763889 | C21: UEP 619D | D21: 11 | E21: 1 | F21: KIBIBI | G21: WAKISO | H21: UG | I21: 8 | J21: 2 | K21: =VLOOKUP(J21,Key!$E$2:$F$9,2,FALSE) -> Work | L21: BUSABALA | M21: WAKISO | N21: UG | O21: 8 | P21: 2 | Q21: =VLOOKUP(P21,Key!$E$2:$F$9,2,FALSE) -> Work | R21: =K21&"-"&Q21 -> Work-Work | T21: 0.3 | U21: 1 | Y21: Y
B22: 0.55555556 | C22: UAX 056X | D22: 1 | E22: 2 | F22: GANGO | G22: WAKISO | H22: UG | I22: 1 | J22: 1 | K22: =VLOOKUP(J22,Key!$E$2:$F$9,2,FALSE) -> Home | L22: NAKASERO | M22: KAMPALA | N22: UG | O22: 7 | P22: 8 | Q22: =VLOOKUP(P22,Key!$E$2:$F$9,2,FALSE) -> Others | R22: =K22&"-"&Q22 -> Home-Others | T22: 1 | U22: 2 | Y22: Y | Z22: 1500
B23: 0.54930556 | C23: UAU 112H | D23: 1 | E23: 1 | F23: NDEJJE | G23: WAKISO | H23: UG | I23: 1 | J23: 1 | K23: =VLOOKUP(J23,Key!$E$2:$F$9,2,FALSE) -> Home | L23: MUNYONYO | M23: KAMPALA | N23: UG | O23: 16 | P23: 6 | Q23: =VLOOKUP(P23,Key!$E$2:$F$9,2,FALSE) -> Leisure/Social | R23: =K23&"-"&Q23 -> Home-Leisure/Social | T23: 0.3 | U23: 1 | Y23: Y | Z23: 500
