Workbook

Sheet 29.07 NAMUGONGO-KIREKA
B1: Consultancy services for Preparation of Expressway Development Master Plan (EDMP) for Uganda
B2: MANUAL CLASSIFIED COUNT (MCC)
B3: ROAD NAME: | C3: ='01.08 NAMUGONGO-KIREKA'!C3:G3 -> MCC - C1 - STN039 - NAMUGONGO ROAD
C5: Date | D5: 29.07.19 | F5: Location | G5: ='04.08 KIREKA-NAMUGONGO'!G5:H5 -> AGENDA | J5: Surveyor | K5: ='04.08 KIREKA-NAMUGONGO'!K5:L5 -> STEVEN
C6: Dir. From | D6: ='01.08 NAMUGONGO-KIREKA'!D6:E6 -> NAMUGONGO | F6: Dir. To | G6: ='01.08 NAMUGONGO-KIREKA'!G6:H6 -> KIREKA | J6: Supervisor | K6: ='04.08 KIREKA-NAMUGONGO'!K6:L6 -> NAIDO GRACE BRENDA
B8: Time / Veh Type | R8: SUMMARY TRAFFIC VOLUMES
C9: 1. Car | D9: 2. Station Wagon | E9: 3. Pickups | F9: 4. Minibus, matatu | G9: 5. Medium bus | H9: 6. Large Bus | I9: 7. Light Truck | J9: 8. Medium Truck | K9: 9. Heavy truck | L9: 10. Truck Trailer | M9: 11. Motor cycles | N9: 12. Tractors | O9: Total Excl M/Cycles | P9: Total All | R9: Time | S9: 1. Car | T9: 2. Station Wagon | U9: 3. Pickups | V9: 4. Minibus, matatu | W9: 5. Medium bus | X9: 6. Large Bus | Y9: 7. Light Truck | Z9: 8. Medium Truck | AA9: 9. Heavy truck | AB9: 10. Truck Trailer | AC9: 11. Motorcycles | AD9: 12. Tractors, Graders | AE9: Total Excl M/ Cycles | AF9: Total All
B10: 07.00 - 07.15 | C10: 0 | D10: 0 | E10: 0 | F10: 0 | G10: 0 | H10: 0 | I10: 0 | J10: 0 | K10: 0 | L10: 0 | M10: 0 | N10: 0 | O10: =SUM(C10:L10,N10) -> 0 | P10: =SUM(C10:N10) -> 0 | R10: 0700-0800 | S10: =SUM(C10:C13) -> 0 | T10: =SUM(D10:D13) -> 0 | U10: =SUM(E10:E13) -> 0 | V10: =SUM(F10:F13) -> 0 | W10: =SUM(G10:G13) -> 0 | X10: =SUM(H10:H13) -> 0 | Y10: =SUM(I10:I13) -> 0 | Z10: =SUM(J10:J13) -> 0 | ... AF10: =SUM(P10:P13) -> 0
B11: 07.15 - 07.30 | C11: 0 | D11: 0 | E11: 0 | F11: 0 | G11: 0 | H11: 0 | I11: 0 | J11: 0 | K11: 0 | L11: 0 | M11: 0 | N11: 0 | O11: =SUM(C11:L11,N11) -> 0 | P11: =SUM(C11:N11) -> 0 | R11: 0800-0900 | S11: =SUM(C14:C17) -> 0 | T11: =SUM(D14:D17) -> 0 | U11: =SUM(E14:E17) -> 0 | V11: =SUM(F14:F17) -> 0 | W11: =SUM(G14:G17) -> 0 | X11: =SUM(H14:H17) -> 0 | Y11: =SUM(I14:I17) -> 0 | Z11: =SUM(J14:J17) -> 0 | ... AF11: =SUM(P14:P17) -> 0
B12: 07.30 - 07.45 | C12: 0 | D12: 0 | E12: 0 | F12: 0 | G12: 0 | H12: 0 | I12: 0 | J12: 0 | K12: 0 | L12: 0 | M12: 0 | N12: 0 | O12: =SUM(C12:L12,N12) -> 0 | P12: =SUM(C12:N12) -> 0 | R12: 0900-1000 | S12: =SUM(C18:C21) -> 52 | T12: =SUM(D18:D21) -> 10 | U12: =SUM(E18:E21) -> 4 | V12: =SUM(F18:F21) -> 10 | W12: =SUM(G18:G21) -> 0 | X12: =SUM(H18:H21) -> 0 | Y12: =SUM(I18:I21) -> 4 | Z12: =SUM(J18:J21) -> 2 | ... AF12: =SUM(P18:P21) -> 176
B13: 07.45 - 08.00 | C13: 0 | D13: 0 | E13: 0 | F13: 0 | G13: 0 | H13: 0 | I13: 0 | J13: 0 | K13: 0 | L13: 0 | M13: 0 | N13: 0 | O13: =SUM(C13:L13,N13) -> 0 | P13: =SUM(C13:N13) -> 0 | R13: 1000-1100 | S13: =SUM(C22:C25) -> 291 | T13: =SUM(D22:D25) -> 42 | U13: =SUM(E22:E25) -> 54 | V13: =SUM(F22:F25) -> 78 | W13: =SUM(G22:G25) -> 1 | X13: =SUM(H22:H25) -> 0 | Y13: =SUM(I22:I25) -> 32 | Z13: =SUM(J22:J25) -> 3 | ... AF13: =SUM(P22:P25) -> 990
B14: 08.00 - 08.15 | C14: 0 | D14: 0 | E14: 0 | F14: 0 | G14: 0 | H14: 0 | I14: 0 | J14: 0 | K14: 0 | L14: 0 | M14: 0 | N14: 0 | O14: =SUM(C14:L14,N14) -> 0 | P14: =SUM(C14:N14) -> 0 | R14: 1100-1200 | S14: =SUM(C26:C29) -> 239 | T14: =SUM(D26:D29) -> 32 | U14: =SUM(E26:E29) -> 27 | V14: =SUM(F26:F29) -> 86 | W14: =SUM(G26:G29) -> 0 | X14: =SUM(H26:H29) -> 0 | Y14: =SUM(I26:I29) -> 33 | Z14: =SUM(J26:J29) -> 1 | ... AF14: =SUM(P26:P29) -> 934
B15: 08.15 - 08.30 | C15: 0 | D15: 0 | E15: 0 | F15: 0 | G15: 0 | H15: 0 | I15: 0 | J15: 0 | K15: 0 | L15: 0 | M15: 0 | N15: 0 | O15: =SUM(C15:L15,N15) -> 0 | P15: =SUM(C15:N15) -> 0 | R15: 1200-1300 | S15: =SUM(C30:C33) -> 175 | T15: =SUM(D30:D33) -> 22 | U15: =SUM(E30:E33) -> 40 | V15: =SUM(F30:F33) -> 70 | W15: =SUM(G30:G33) -> 2 | X15: =SUM(H30:H33) -> 0 | Y15: =SUM(I30:I33) -> 33 | Z15: =SUM(J30:J33) -> 2 | ... AF15: =SUM(P30:P33) -> 788
B16: 08.30 - 08.45 | C16: 0 | D16: 0 | E16: 0 | F16: 0 | G16: 0 | H16: 0 | I16: 0 | J16: 0 | K16: 0 | L16: 0 | M16: 0 | N16: 0 | O16: =SUM(C16:L16,N16) -> 0 | P16: =SUM(C16:N16) -> 0 | R16: 1300-1400 | S16: =SUM(C34:C37) -> 174 | T16: =SUM(D34:D37) -> 31 | U16: =SUM(E34:E37) -> 29 | V16: =SUM(F34:F37) -> 75 | W16: =SUM(G34:G37) -> 2 | X16: =SUM(H34:H37) -> 0 | Y16: =SUM(I34:I37) -> 31 | Z16: =SUM(J34:J37) -> 0 | ... AF16: =SUM(P34:P37) -> 770
B17: 08.45 - 9.00 | C17: 0 | D17: 0 | E17: 0 | F17: 0 | G17: 0 | H17: 0 | I17: 0 | J17: 0 | K17: 0 | L17: 0 | M17: 0 | N17: 0 | O17: =SUM(C17:L17,N17) -> 0 | P17: =SUM(C17:N17) -> 0 | R17: 1400-1500 | S17: =SUM(C38:C41) -> 191 | T17: =SUM(D38:D41) -> 23 | U17: =SUM(E38:E41) -> 22 | V17: =SUM(F38:F41) -> 66 | W17: =SUM(G38:G41) -> 2 | X17: =SUM(H38:H41) -> 0 | Y17: =SUM(I38:I41) -> 33 | Z17: =SUM(J38:J41) -> 0 | ... AF17: =SUM(P38:P41) -> 722
B18: 09.00 - 09.15 | C18: 0 | D18: 0 | E18: 0 | F18: 0 | G18: 0 | H18: 0 | I18: 0 | J18: 0 | K18: 0 | L18: 0 | M18: 0 | N18: 0 | O18: =SUM(C18:L18,N18) -> 0 | P18: =SUM(C18:N18) -> 0 | R18: 1500-1600 | S18: =SUM(C42:C45) -> 165 | T18: =SUM(D42:D45) -> 30 | U18: =SUM(E42:E45) -> 31 | V18: =SUM(F42:F45) -> 74 | W18: =SUM(G42:G45) -> 11 | X18: =SUM(H42:H45) -> 1 | Y18: =SUM(I42:I45) -> 44 | Z18: =SUM(J42:J45) -> 0 | ... AF18: =SUM(P42:P45) -> 790
B19: 09.15 - 09.30 | C19: 0 | D19: 0 | E19: 0 | F19: 0 | G19: 0 | H19: 0 | I19: 0 | J19: 0 | K19: 0 | L19: 0 | M19: 0 | N19: 0 | O19: =SUM(C19:L19,N19) -> 0 | P19: =SUM(C19:N19) -> 0 | R19: 1600-1700 | S19: =SUM(C46:C49) -> 200 | T19: =SUM(D46:D49) -> 21 | U19: =SUM(E46:E49) -> 24 | V19: =SUM(F46:F49) -> 68 | W19: =SUM(G46:G49) -> 2 | X19: =SUM(H46:H49) -> 0 | Y19: =SUM(I46:I49) -> 33 | Z19: =SUM(J46:J49) -> 0 | ... AF19: =SUM(P46:P49) -> 866
B20: 09.30 - 09.45 | C20: 0 | D20: 0 | E20: 0 | F20: 0 | G20: 0 | H20: 0 | I20: 0 | J20: 0 | K20: 0 | L20: 0 | M20: 0 | N20: 0 | O20: =SUM(C20:L20,N20) -> 0 | P20: =SUM(C20:N20) -> 0 | R20: 1700-1800 | S20: =SUM(C50:C53) -> 230 | T20: =SUM(D50:D53) -> 17 | U20: =SUM(E50:E53) -> 39 | V20: =SUM(F50:F53) -> 87 | W20: =SUM(G50:G53) -> 4 | X20: =SUM(H50:H53) -> 0 | Y20: =SUM(I50:I53) -> 35 | Z20: =SUM(J50:J53) -> 0 | ... AF20: =SUM(P50:P53) -> 909
B21: 09.45 - 10.00 | C21: 52 | D21: 10 | E21: 4 | F21: 10 | G21: 0 | H21: 0 | I21: 4 | J21: 2 | K21: 0 | L21: 0 | M21: 94 | N21: 0 | O21: =SUM(C21:L21,N21) -> 82 | P21: =SUM(C21:N21) -> 176 | R21: 1800-1900 | S21: =SUM(C54:C57) -> 190 | T21: =SUM(D54:D57) -> 24 | U21: =SUM(E54:E57) -> 32 | V21: =SUM(F54:F57) -> 74 | W21: =SUM(G54:G57) -> 5 | X21: =SUM(H54:H57) -> 0 | Y21: =SUM(I54:I57) -> 21 | Z21: =SUM(J54:J57) -> 5 | ... AF21: =SUM(P54:P57) -> 938
B22: 10.00 - 10.15 | C22: 67 | D22: 13 | E22: 19 | F22: 20 | G22: 0 | H22: 0 | I22: 3 | J22: 0 | K22: 0 | L22: 0 | M22: 101 | N22: 0 | O22: =SUM(C22:L22,N22) -> 122 | P22: =SUM(C22:N22) -> 223 | R22: AM Peak Hr | S22: =MAX(S10:S12) -> 52 | T22: =MAX(T10:T12) -> 10 | U22: =MAX(U10:U12) -> 4 | V22: =MAX(V10:V12) -> 10 | W22: =MAX(W10:W12) -> 0 | X22: =MAX(X10:X12) -> 0 | Y22: =MAX(Y10:Y12) -> 4 | Z22: =MAX(Z10:Z12) -> 2 | ... AF22: =MAX(AF10:AF12) -> 176
B23: 10.15 - 10.30 | C23: 72 | D23: 4 | E23: 15 | F23: 20 | G23: 1 | H23: 0 | I23: 10 | J23: 1 | K23: 0 | L23: 2 | M23: 144 | N23: 0 | O23: =SUM(C23:L23,N23) -> 125 | P23: =SUM(C23:N23) -> 269 | R23: IP Peak Hr | S23: =MAX(S13:S18) -> 291 | T23: =MAX(T13:T18) -> 42 | U23: =MAX(U13:U18) -> 54 | V23: =MAX(V13:V18) -> 86 | W23: =MAX(W13:W18) -> 11 | X23: =MAX(X13:X18) -> 1 | Y23: =MAX(Y13:Y18) -> 44 | Z23: =MAX(Z13:Z18) -> 3 | ... AF23: =MAX(AF13:AF18) -> 990
B24: 10.30 - 10.45 | C24: 75 | D24: 12 | E24: 6 | F24: 15 | G24: 0 | H24: 0 | I24: 8 | J24: 2 | K24: 0 | L24: 0 | M24: 133 | N24: 0 | O24: =SUM(C24:L24,N24) -> 118 | P24: =SUM(C24:N24) -> 251 | R24: PM Peak Hr | S24: =MAX(S19:S21) -> 230 | T24: =MAX(T19:T21) -> 24 | U24: =MAX(U19:U21) -> 39 | V24: =MAX(V19:V21) -> 87 | W24: =MAX(W19:W21) -> 5 | X24: =MAX(X19:X21) -> 0 | Y24: =MAX(Y19:Y21) -> 35 | Z24: =MAX(Z19:Z21) -> 5 | ... AF24: =MAX(AF19:AF21) -> 938
B25: 10.45 - 11.00 | C25: 77 | D25: 13 | E25: 14 | F25: 23 | G25: 0 | H25: 0 | I25: 11 | J25: 0 | K25: 2 | L25: 0 | M25: 107 | N25: 0 | O25: =SUM(C25:L25,N25) -> 140 | P25: =SUM(C25:N25) -> 247 | R25: AM Period | S25: =SUM(S10:S12) -> 52 | T25: =SUM(T10:T12) -> 10 | U25: =SUM(U10:U12) -> 4 | V25: =SUM(V10:V12) -> 10 | W25: =SUM(W10:W12) -> 0 | X25: =SUM(X10:X12) -> 0 | Y25: =SUM(Y10:Y12) -> 4 | Z25: =SUM(Z10:Z12) -> 2 | ... AF25: =SUM(AF10:AF12) -> 176
B26: 11.00 - 11.15 | C26: 69 | D26: 5 | E26: 5 | F26: 24 | G26: 0 | H26: 0 | I26: 13 | J26: 0 | K26: 2 | L26: 0 | M26: 135 | N26: 0 | O26: =SUM(C26:L26,N26) -> 118 | P26: =SUM(C26:N26) -> 253 | R26: IP Period | S26: =SUM(S13:S18) -> 1235 | T26: =SUM(T13:T18) -> 180 | U26: =SUM(U13:U18) -> 203 | V26: =SUM(V13:V18) -> 449 | W26: =SUM(W13:W18) -> 18 | X26: =SUM(X13:X18) -> 1 | Y26: =SUM(Y13:Y18) -> 206 | Z26: =SUM(Z13:Z18) -> 6 | ... AF26: =SUM(AF13:AF18) -> 4994
B27: 11.15 - 11.30 | C27: 72 | D27: 10 | E27: 4 | F27: 20 | G27: 0 | H27: 0 | I27: 4 | J27: 1 | K27: 0 | L27: 0 | M27: 129 | N27: 0 | O27: =SUM(C27:L27,N27) -> 111 | P27: =SUM(C27:N27) -> 240 | R27: PM Period | S27: =SUM(S19:S21) -> 620 | T27: =SUM(T19:T21) -> 62 | U27: =SUM(U19:U21) -> 95 | V27: =SUM(V19:V21) -> 229 | W27: =SUM(W19:W21) -> 11 | X27: =SUM(X19:X21) -> 0 | Y27: =SUM(Y19:Y21) -> 89 | Z27: =SUM(Z19:Z21) -> 5 | ... AF27: =SUM(AF19:AF21) -> 2713
B28: 11.30 - 11.45 | C28: 56 | D28: 10 | E28: 7 | F28: 25 | G28: 0 | H28: 0 | I28: 8 | J28: 0 | K28: 1 | L28: 0 | M28: 133 | N28: 0 | O28: =SUM(C28:L28,N28) -> 107 | P28: =SUM(C28:N28) -> 240 | R28: 12 Hours | S28: =SUM(S10:S21) -> 1907 | T28: =SUM(T10:T21) -> 252 | U28: =SUM(U10:U21) -> 302 | V28: =SUM(V10:V21) -> 688 | W28: =SUM(W10:W21) -> 29 | X28: =SUM(X10:X21) -> 1 | Y28: =SUM(Y10:Y21) -> 299 | Z28: =SUM(Z10:Z21) -> 13 | ... AF28: =SUM(AF10:AF21) -> 7883
B29: 11.45 - 12.00 | C29: 42 | D29: 7 | E29: 11 | F29: 17 | G29: 0 | H29: 0 | I29: 8 | J29: 0 | K29: 2 | L29: 0 | M29: 114 | N29: 0 | O29: =SUM(C29:L29,N29) -> 87 | P29: =SUM(C29:N29) -> 201
B30: 12.00 - 12.15 | C30: 25 | D30: 4 | E30: 9 | F30: 25 | G30: 0 | H30: 0 | I30: 5 | J30: 0 | K30: 1 | L30: 0 | M30: 125 | N30: 0 | O30: =SUM(C30:L30,N30) -> 69 | P30: =SUM(C30:N30) -> 194
B31: 12.15 - 12.30 | C31: 45 | D31: 8 | E31: 5 | F31: 20 | G31: 0 | H31: 0 | I31: 9 | J31: 2 | K31: 0 | L31: 0 | M31: 100 | N31: 0 | O31: =SUM(C31:L31,N31) -> 89 | P31: =SUM(C31:N31) -> 189
B32: 12.30 - 12.45 | C32: 63 | D32: 4 | E32: 11 | F32: 25 | G32: 2 | H32: 0 | I32: 13 | J32: 0 | K32: 1 | L32: 0 | M32: 126 | N32: 0 | O32: =SUM(C32:L32,N32) -> 119 | P32: =SUM(C32:N32) -> 245
B33: 12.45 - 13.00 | C33: 42 | D33: 6 | E33: 15 | F33: 0 | G33: 0 | H33: 0 | I33: 6 | J33: 0 | K33: 1 | L33: 0 | M33: 90 | N33: 0 | O33: =SUM(C33:L33,N33) -> 70 | P33: =SUM(C33:N33) -> 160
B34: 13.00 - 13.15 | C34: 27 | D34: 9 | E34: 8 | F34: 21 | G34: 0 | H34: 0 | I34: 11 | J34: 0 | K34: 0 | L34: 0 | M34: 130 | N34: 0 | O34: =SUM(C34:L34,N34) -> 76 | P34: =SUM(C34:N34) -> 206
B35: 13.15 - 13.30 | C35: 50 | D35: 11 | E35: 9 | F35: 22 | G35: 2 | H35: 0 | I35: 7 | J35: 0 | K35: 0 | L35: 0 | M35: 101 | N35: 0 | O35: =SUM(C35:L35,N35) -> 101 | P35: =SUM(C35:N35) -> 202
B36: 13.30 - 13.45 | C36: 47 | D36: 1 | E36: 6 | F36: 14 | G36: 0 | H36: 0 | I36: 7 | J36: 0 | K36: 0 | L36: 0 | M36: 102 | N36: 0 | O36: =SUM(C36:L36,N36) -> 75 | P36: =SUM(C36:N36) -> 177
B37: 13.45 - 14.00 | C37: 50 | D37: 10 | E37: 6 | F37: 18 | G37: 0 | H37: 0 | I37: 6 | J37: 0 | K37: 0 | L37: 0 | M37: 95 | N37: 0 | O37: =SUM(C37:L37,N37) -> 90 | P37: =SUM(C37:N37) -> 185
B38: 14.00 - 14.15 | C38: 54 | D38: 5 | E38: 7 | F38: 19 | G38: 1 | H38: 0 | I38: 7 | J38: 0 | K38: 0 | L38: 0 | M38: 96 | N38: 0 | O38: =SUM(C38:L38,N38) -> 93 | P38: =SUM(C38:N38) -> 189
B39: 14.15 - 14.30 | C39: 49 | D39: 7 | E39: 9 | F39: 16 | G39: 0 | H39: 0 | I39: 9 | J39: 0 | K39: 2 | L39: 0 | M39: 101 | N39: 0 | O39: =SUM(C39:L39,N39) -> 92 | P39: =SUM(C39:N39) -> 193
B40: 14.30 - 14.45 | C40: 43 | D40: 5 | E40: 2 | F40: 14 | G40: 0 | H40: 0 | I40: 11 | J40: 0 | K40: 0 | L40: 0 | M40: 87 | N40: 0 | O40: =SUM(C40:L40,N40) -> 75 | P40: =SUM(C40:N40) -> 162
... B57: 18.45 - 19.00 | C57: 44 | D57: 7 | E57: 7 | F57: 24 | G57: 1 | H57: 0 | I57: 3 | J57: 1 | K57: 0 | L57: 0 | M57: 150 | N57: 0 | O57: =SUM(C57:L57,N57) -> 87 | P57: =SUM(C57:N57) -> 237
B58: Totals | C58: =SUM(C10:C57) -> 1907 | D58: =SUM(D10:D57) -> 252 | E58: =SUM(E10:E57) -> 302 | F58: =SUM(F10:F57) -> 688 | G58: =SUM(G10:G57) -> 29 | H58: =SUM(H10:H57) -> 1 | I58: =SUM(I10:I57) -> 299 | J58: =SUM(J10:J57) -> 13 | ... P58: =SUM(P10:P57) -> 7883
...

Sheet 29.07 KIREKA-NAMUGONGO
B1: Consultancy services for Preparation of Expressway Development Master Plan (EDMP) for Uganda
B2: MANUAL CLASSIFIED COUNT (MCC)
B3: ROAD NAME: | C3: ='01.08 KIREKA-NAMUGONGO'!C3:G3 -> MCC - C1 - STN039 - NAMUGONGO ROAD
C5: Date | D5: ='29.07 NAMUGONGO-KIREKA'!D5 -> 29.07.19 | F5: Location | G5: ='29.07 NAMUGONGO-KIREKA'!G5:H5 -> AGENDA | J5: Surveyor | K5: ='29.07 NAMUGONGO-KIREKA'!K5:L5 -> STEVEN
C6: Dir. From | D6: ='01.08 KIREKA-NAMUGONGO'!D6:E6 -> KIREKA | F6: Dir. To | G6: ='01.08 KIREKA-NAMUGONGO'!G6:H6 -> NAMUGONGO | J6: Supervisor | K6: ='29.07 NAMUGONGO-KIREKA'!K6:L6 -> NAIDO GRACE BRENDA
B8: Time / Veh Type | R8: SUMMARY TRAFFIC VOLUMES
C9: 1. Car | D9: 2. Station Wagon | E9: 3. Pickups | F9: 4. Minibus, matatu | G9: 5. Medium bus | H9: 6. Large Bus | I9: 7. Light Truck | J9: 8. Medium Truck | K9: 9. Heavy truck | L9: 10. Truck Trailer | M9: 11. Motor cycles | N9: 12. Tractors | O9: Total Excl M/Cycles | P9: Total All | R9: Time | S9: 1. Car | T9: 2. Station Wagon | U9: 3. Pickups | V9: 4. Minibus, matatu | W9: 5. Medium bus | X9: 6. Large Bus | Y9: 7. Light Truck | Z9: 8. Medium Truck | AA9: 9. Heavy truck | AB9: 10. Truck Trailer | AC9: 11. Motorcycles | AD9: 12. Tractors, Graders | AE9: Total Excl M/ Cycles | AF9: Total All
B10: 07.00 - 07.15 | C10: 0 | D10: 0 | E10: 0 | F10: 0 | G10: 0 | H10: 0 | I10: 0 | J10: 0 | K10: 0 | L10: 0 | M10: 0 | N10: 0 | O10: =SUM(C10:L10,N10) -> 0 | P10: =SUM(C10:N10) -> 0 | R10: 0700-0800 | S10: =SUM(C10:C13) -> 0 | T10: =SUM(D10:D13) -> 0 | U10: =SUM(E10:E13) -> 0 | V10: =SUM(F10:F13) -> 0 | W10: =SUM(G10:G13) -> 0 | X10: =SUM(H10:H13) -> 0 | Y10: =SUM(I10:I13) -> 0 | Z10: =SUM(J10:J13) -> 0 | ... AF10: =SUM(P10:P13) -> 0
B11: 07.15 - 07.30 | C11: 0 | D11: 0 | E11: 0 | F11: 0 | G11: 0 | H11: 0 | I11: 0 | J11: 0 | K11: 0 | L11: 0 | M11: 0 | N11: 0 | O11: =SUM(C11:L11,N11) -> 0 | P11: =SUM(C11:N11) -> 0 | R11: 0800-0900 | S11: =SUM(C14:C17) -> 0 | T11: =SUM(D14:D17) -> 0 | U11: =SUM(E14:E17) -> 0 | V11: =SUM(F14:F17) -> 0 | W11: =SUM(G14:G17) -> 0 | X11: =SUM(H14:H17) -> 0 | Y11: =SUM(I14:I17) -> 0 | Z11: =SUM(J14:J17) -> 0 | ... AF11: =SUM(P14:P17) -> 0
B12: 07.30 - 07.45 | C12: 0 | D12: 0 | E12: 0 | F12: 0 | G12: 0 | H12: 0 | I12: 0 | J12: 0 | K12: 0 | L12: 0 | M12: 0 | N12: 0 | O12: =SUM(C12:L12,N12) -> 0 | P12: =SUM(C12:N12) -> 0 | R12: 0900-1000 | S12: =SUM(C18:C21) -> 33 | T12: =SUM(D18:D21) -> 1 | U12: =SUM(E18:E21) -> 6 | V12: =SUM(F18:F21) -> 19 | W12: =SUM(G18:G21) -> 0 | X12: =SUM(H18:H21) -> 0 | Y12: =SUM(I18:I21) -> 3 | Z12: =SUM(J18:J21) -> 4 | ... AF12: =SUM(P18:P21) -> 188
B13: 07.45 - 08.00 | C13: 0 | D13: 0 | E13: 0 | F13: 0 | G13: 0 | H13: 0 | I13: 0 | J13: 0 | K13: 0 | L13: 0 | M13: 0 | N13: 0 | O13: =SUM(C13:L13,N13) -> 0 | P13: =SUM(C13:N13) -> 0 | R13: 1000-1100 | S13: =SUM(C22:C25) -> 124 | T13: =SUM(D22:D25) -> 23 | U13: =SUM(E22:E25) -> 20 | V13: =SUM(F22:F25) -> 46 | W13: =SUM(G22:G25) -> 1 | X13: =SUM(H22:H25) -> 0 | Y13: =SUM(I22:I25) -> 42 | Z13: =SUM(J22:J25) -> 10 | ... AF13: =SUM(P22:P25) -> 747
B14: 08.00 - 08.15 | C14: 0 | D14: 0 | E14: 0 | F14: 0 | G14: 0 | H14: 0 | I14: 0 | J14: 0 | K14: 0 | L14: 0 | M14: 0 | N14: 0 | O14: =SUM(C14:L14,N14) -> 0 | P14: =SUM(C14:N14) -> 0 | R14: 1100-1200 | S14: =SUM(C26:C29) -> 130 | T14: =SUM(D26:D29) -> 20 | U14: =SUM(E26:E29) -> 19 | V14: =SUM(F26:F29) -> 53 | W14: =SUM(G26:G29) -> 1 | X14: =SUM(H26:H29) -> 0 | Y14: =SUM(I26:I29) -> 40 | Z14: =SUM(J26:J29) -> 10 | ... AF14: =SUM(P26:P29) -> 759
B15: 08.15 - 08.30 | C15: 0 | D15: 0 | E15: 0 | F15: 0 | G15: 0 | H15: 0 | I15: 0 | J15: 0 | K15: 0 | L15: 0 | M15: 0 | N15: 0 | O15: =SUM(C15:L15,N15) -> 0 | P15: =SUM(C15:N15) -> 0 | R15: 1200-1300 | S15: =SUM(C30:C33) -> 136 | T15: =SUM(D30:D33) -> 19 | U15: =SUM(E30:E33) -> 15 | V15: =SUM(F30:F33) -> 32 | W15: =SUM(G30:G33) -> 1 | X15: =SUM(H30:H33) -> 0 | Y15: =SUM(I30:I33) -> 30 | Z15: =SUM(J30:J33) -> 16 | ... AF15: =SUM(P30:P33) -> 727
B16: 08.30 - 08.45 | C16: 0 | D16: 0 | E16: 0 | F16: 0 | G16: 0 | H16: 0 | I16: 0 | J16: 0 | K16: 0 | L16: 0 | M16: 0 | N16: 0 | O16: =SUM(C16:L16,N16) -> 0 | P16: =SUM(C16:N16) -> 0 | R16: 1300-1400 | S16: =SUM(C34:C37) -> 139 | T16: =SUM(D34:D37) -> 13 | U16: =SUM(E34:E37) -> 15 | V16: =SUM(F34:F37) -> 33 | W16: =SUM(G34:G37) -> 2 | X16: =SUM(H34:H37) -> 0 | Y16: =SUM(I34:I37) -> 37 | Z16: =SUM(J34:J37) -> 12 | ... AF16: =SUM(P34:P37) -> 719
B17: 08.45 - 9.00 | C17: 0 | D17: 0 | E17: 0 | F17: 0 | G17: 0 | H17: 0 | I17: 0 | J17: 0 | K17: 0 | L17: 0 | M17: 0 | N17: 0 | O17: =SUM(C17:L17,N17) -> 0 | P17: =SUM(C17:N17) -> 0 | R17: 1400-1500 | S17: =SUM(C38:C41) -> 112 | T17: =SUM(D38:D41) -> 17 | U17: =SUM(E38:E41) -> 16 | V17: =SUM(F38:F41) -> 33 | W17: =SUM(G38:G41) -> 2 | X17: =SUM(H38:H41) -> 0 | Y17: =SUM(I38:I41) -> 23 | Z17: =SUM(J38:J41) -> 16 | ... AF17: =SUM(P38:P41) -> 679
B18: 09.00 - 09.15 | C18: 0 | D18: 0 | E18: 0 | F18: 0 | G18: 0 | H18: 0 | I18: 0 | J18: 0 | K18: 0 | L18: 0 | M18: 0 | N18: 0 | O18: =SUM(C18:L18,N18) -> 0 | P18: =SUM(C18:N18) -> 0 | R18: 1500-1600 | S18: =SUM(C42:C45) -> 144 | T18: =SUM(D42:D45) -> 26 | U18: =SUM(E42:E45) -> 18 | V18: =SUM(F42:F45) -> 34 | W18: =SUM(G42:G45) -> 3 | X18: =SUM(H42:H45) -> 1 | Y18: =SUM(I42:I45) -> 37 | Z18: =SUM(J42:J45) -> 12 | ... AF18: =SUM(P42:P45) -> 729
B19: 09.15 - 09.30 | C19: 0 | D19: 0 | E19: 0 | F19: 0 | G19: 0 | H19: 0 | I19: 0 | J19: 0 | K19: 0 | L19: 0 | M19: 0 | N19: 0 | O19: =SUM(C19:L19,N19) -> 0 | P19: =SUM(C19:N19) -> 0 | R19: 1600-1700 | S19: =SUM(C46:C49) -> 283 | T19: =SUM(D46:D49) -> 40 | U19: =SUM(E46:E49) -> 39 | V19: =SUM(F46:F49) -> 35 | W19: =SUM(G46:G49) -> 1 | X19: =SUM(H46:H49) -> 0 | Y19: =SUM(I46:I49) -> 33 | Z19: =SUM(J46:J49) -> 7 | ... AF19: =SUM(P46:P49) -> 940
B20: 09.30 - 09.45 | C20: 25 | D20: 1 | E20: 6 | F20: 17 | G20: 0 | H20: 0 | I20: 2 | J20: 4 | K20: 2 | L20: 0 | M20: 77 | N20: 0 | O20: =SUM(C20:L20,N20) -> 57 | P20: =SUM(C20:N20) -> 134 | R20: 1700-1800 | S20: =SUM(C50:C53) -> 432 | T20: =SUM(D50:D53) -> 51 | U20: =SUM(E50:E53) -> 35 | V20: =SUM(F50:F53) -> 51 | W20: =SUM(G50:G53) -> 3 | X20: =SUM(H50:H53) -> 0 | Y20: =SUM(I50:I53) -> 34 | Z20: =SUM(J50:J53) -> 12 | ... AF20: =SUM(P50:P53) -> 1101
B21: 09.45 - 10.00 | C21: 8 | D21: 0 | E21: 0 | F21: 2 | G21: 0 | H21: 0 | I21: 1 | J21: 0 | K21: 0 | L21: 0 | M21: 43 | N21: 0 | O21: =SUM(C21:L21,N21) -> 11 | P21: =SUM(C21:N21) -> 54 | R21: 1800-1900 | S21: =SUM(C54:C57) -> 418 | T21: =SUM(D54:D57) -> 52 | U21: =SUM(E54:E57) -> 34 | V21: =SUM(F54:F57) -> 70 | W21: =SUM(G54:G57) -> 2 | X21: =SUM(H54:H57) -> 0 | Y21: =SUM(I54:I57) -> 14 | Z21: =SUM(J54:J57) -> 7 | ... AF21: =SUM(P54:P57) -> 1079
B22: 10.00 - 10.15 | C22: 6 | D22: 0 | E22: 1 | F22: 1 | G22: 0 | H22: 0 | I22: 2 | J22: 2 | K22: 2 | L22: 0 | M22: 72 | N22: 0 | O22: =SUM(C22:L22,N22) -> 14 | P22: =SUM(C22:N22) -> 86 | R22: AM Peak Hr | S22: =MAX(S10:S12) -> 33 | T22: =MAX(T10:T12) -> 1 | U22: =MAX(U10:U12) -> 6 | V22: =MAX(V10:V12) -> 19 | W22: =MAX(W10:W12) -> 0 | X22: =MAX(X10:X12) -> 0 | Y22: =MAX(Y10:Y12) -> 3 | Z22: =MAX(Z10:Z12) -> 4 | ... AF22: =MAX(AF10:AF12) -> 188
B23: 10.15 - 10.30 | C23: 45 | D23: 11 | E23: 6 | F23: 19 | G23: 0 | H23: 0 | I23: 13 | J23: 4 | K23: 1 | L23: 1 | M23: 119 | N23: 0 | O23: =SUM(C23:L23,N23) -> 100 | P23: =SUM(C23:N23) -> 219 | R23: IP Peak Hr | S23: =MAX(S13:S18) -> 144 | T23: =MAX(T13:T18) -> 26 | U23: =MAX(U13:U18) -> 20 | V23: =MAX(V13:V18) -> 53 | W23: =MAX(W13:W18) -> 3 | X23: =MAX(X13:X18) -> 1 | Y23: =MAX(Y13:Y18) -> 42 | Z23: =MAX(Z13:Z18) -> 16 | ... AF23: =MAX(AF13:AF18) -> 759
B24: 10.30 - 10.45 | C24: 28 | D24: 8 | E24: 4 | F24: 14 | G24: 0 | H24: 0 | I24: 13 | J24: 4 | K24: 1 | L24: 1 | M24: 140 | N24: 0 | O24: =SUM(C24:L24,N24) -> 73 | P24: =SUM(C24:N24) -> 213 | R24: PM Peak Hr | S24: =MAX(S19:S21) -> 432 | T24: =MAX(T19:T21) -> 52 | U24: =MAX(U19:U21) -> 39 | V24: =MAX(V19:V21) -> 70 | W24: =MAX(W19:W21) -> 3 | X24: =MAX(X19:X21) -> 0 | Y24: =MAX(Y19:Y21) -> 34 | Z24: =MAX(Z19:Z21) -> 12 | ... AF24: =MAX(AF19:AF21) -> 1101
B25: 10.45 - 11.00 | C25: 45 | D25: 4 | E25: 9 | F25: 12 | G25: 1 | H25: 0 | I25: 14 | J25: 0 | K25: 0 | L25: 0 | M25: 144 | N25: 0 | O25: =SUM(C25:L25,N25) -> 85 | P25: =SUM(C25:N25) -> 229 | R25: AM Period | S25: =SUM(S10:S12) -> 33 | T25: =SUM(T10:T12) -> 1 | U25: =SUM(U10:U12) -> 6 | V25: =SUM(V10:V12) -> 19 | W25: =SUM(W10:W12) -> 0 | X25: =SUM(X10:X12) -> 0 | Y25: =SUM(Y10:Y12) -> 3 | Z25: =SUM(Z10:Z12) -> 4 | ... AF25: =SUM(AF10:AF12) -> 188
B26: 11.00 - 11.15 | C26: 29 | D26: 5 | E26: 7 | F26: 7 | G26: 0 | H26: 0 | I26: 8 | J26: 1 | K26: 3 | L26: 0 | M26: 129 | N26: 0 | O26: =SUM(C26:L26,N26) -> 60 | P26: =SUM(C26:N26) -> 189 | R26: IP Period | S26: =SUM(S13:S18) -> 785 | T26: =SUM(T13:T18) -> 118 | U26: =SUM(U13:U18) -> 103 | V26: =SUM(V13:V18) -> 231 | W26: =SUM(W13:W18) -> 10 | X26: =SUM(X13:X18) -> 1 | Y26: =SUM(Y13:Y18) -> 209 | Z26: =SUM(Z13:Z18) -> 76 | ... AF26: =SUM(AF13:AF18) -> 4360
B27: 11.15 - 11.30 | C27: 33 | D27: 7 | E27: 5 | F27: 10 | G27: 1 | H27: 0 | I27: 13 | J27: 2 | K27: 1 | L27: 0 | M27: 113 | N27: 0 | O27: =SUM(C27:L27,N27) -> 72 | P27: =SUM(C27:N27) -> 185 | R27: PM Period | S27: =SUM(S19:S21) -> 1133 | T27: =SUM(T19:T21) -> 143 | U27: =SUM(U19:U21) -> 108 | V27: =SUM(V19:V21) -> 156 | W27: =SUM(W19:W21) -> 6 | X27: =SUM(X19:X21) -> 0 | Y27: =SUM(Y19:Y21) -> 81 | Z27: =SUM(Z19:Z21) -> 26 | ... AF27: =SUM(AF19:AF21) -> 3120
B28: 11.30 - 11.45 | C28: 36 | D28: 5 | E28: 4 | F28: 22 | G28: 0 | H28: 0 | I28: 12 | J28: 2 | K28: 6 | L28: 0 | M28: 115 | N28: 0 | O28: =SUM(C28:L28,N28) -> 87 | P28: =SUM(C28:N28) -> 202 | R28: 12 Hours | S28: =SUM(S10:S21) -> 1951 | T28: =SUM(T10:T21) -> 262 | U28: =SUM(U10:U21) -> 217 | V28: =SUM(V10:V21) -> 406 | W28: =SUM(W10:W21) -> 16 | X28: =SUM(X10:X21) -> 1 | Y28: =SUM(Y10:Y21) -> 293 | Z28: =SUM(Z10:Z21) -> 106 | ... AF28: =SUM(AF10:AF21) -> 7668
B29: 11.45 - 12.00 | C29: 32 | D29: 3 | E29: 3 | F29: 14 | G29: 0 | H29: 0 | I29: 7 | J29: 5 | K29: 3 | L29: 0 | M29: 116 | N29: 0 | O29: =SUM(C29:L29,N29) -> 67 | P29: =SUM(C29:N29) -> 183
B30: 12.00 - 12.15 | C30: 32 | D30: 10 | E30: 4 | F30: 4 | G30: 0 | H30: 0 | I30: 7 | J30: 8 | K30: 3 | L30: 0 | M30: 117 | N30: 0 | O30: =SUM(C30:L30,N30) -> 68 | P30: =SUM(C30:N30) -> 185
B31: 12.15 - 12.30 | C31: 31 | D31: 3 | E31: 3 | F31: 9 | G31: 0 | H31: 0 | I31: 7 | J31: 4 | K31: 6 | L31: 0 | M31: 115 | N31: 0 | O31: =SUM(C31:L31,N31) -> 63 | P31: =SUM(C31:N31) -> 178
B32: 12.30 - 12.45 | C32: 44 | D32: 4 | E32: 5 | F32: 11 | G32: 1 | H32: 0 | I32: 8 | J32: 1 | K32: 3 | L32: 0 | M32: 116 | N32: 0 | O32: =SUM(C32:L32,N32) -> 77 | P32: =SUM(C32:N32) -> 193
B33: 12.45 - 13.00 | C33: 29 | D33: 2 | E33: 3 | F33: 8 | G33: 0 | H33: 0 | I33: 8 | J33: 3 | K33: 2 | L33: 0 | M33: 116 | N33: 0 | O33: =SUM(C33:L33,N33) -> 55 | P33: =SUM(C33:N33) -> 171
B34: 13.00 - 13.15 | C34: 41 | D34: 4 | E34: 5 | F34: 8 | G34: 0 | H34: 0 | I34: 10 | J34: 5 | K34: 0 | L34: 0 | M34: 125 | N34: 0 | O34: =SUM(C34:L34,N34) -> 73 | P34: =SUM(C34:N34) -> 198
B35: 13.15 - 13.30 | C35: 29 | D35: 3 | E35: 2 | F35: 7 | G35: 1 | H35: 0 | I35: 5 | J35: 2 | K35: 2 | L35: 0 | M35: 115 | N35: 0 | O35: =SUM(C35:L35,N35) -> 51 | P35: =SUM(C35:N35) -> 166
B36: 13.30 - 13.45 | C36: 29 | D36: 5 | E36: 4 | F36: 15 | G36: 0 | H36: 0 | I36: 12 | J36: 2 | K36: 3 | L36: 0 | M36: 111 | N36: 0 | O36: =SUM(C36:L36,N36) -> 70 | P36: =SUM(C36:N36) -> 181
B37: 13.45 - 14.00 | C37: 40 | D37: 1 | E37: 4 | F37: 3 | G37: 1 | H37: 0 | I37: 10 | J37: 3 | K37: 0 | L37: 0 | M37: 112 | N37: 0 | O37: =SUM(C37:L37,N37) -> 62 | P37: =SUM(C37:N37) -> 174
B38: 14.00 - 14.15 | C38: 33 | D38: 5 | E38: 6 | F38: 9 | G38: 1 | H38: 0 | I38: 3 | J38: 7 | K38: 0 | L38: 0 | M38: 112 | N38: 0 | O38: =SUM(C38:L38,N38) -> 64 | P38: =SUM(C38:N38) -> 176
B39: 14.15 - 14.30 | C39: 45 | D39: 5 | E39: 6 | F39: 12 | G39: 1 | H39: 0 | I39: 8 | J39: 4 | K39: 1 | L39: 0 | M39: 119 | N39: 0 | O39: =SUM(C39:L39,N39) -> 82 | P39: =SUM(C39:N39) -> 201
B40: 14.30 - 14.45 | C40: 19 | D40: 2 | E40: 2 | F40: 7 | G40: 0 | H40: 0 | I40: 8 | J40: 2 | K40: 2 | L40: 0 | M40: 115 | N40: 0 | O40: =SUM(C40:L40,N40) -> 42 | P40: =SUM(C40:N40) -> 157
... B57: 18.45 - 19.00 | C57: 104 | D57: 15 | E57: 7 | F57: 26 | G57: 0 | H57: 0 | I57: 3 | J57: 3 | K57: 1 | L57: 0 | M57: 120 | N57: 0 | O57: =SUM(C57:L57,N57) -> 159 | P57: =SUM(C57:N57) -> 279
B58: Totals | C58: =SUM(C10:C57) -> 1951 | D58: =SUM(D10:D57) -> 262 | E58: =SUM(E10:E57) -> 217 | F58: =SUM(F10:F57) -> 406 | G58: =SUM(G10:G57) -> 16 | H58: =SUM(H10:H57) -> 1 | I58: =SUM(I10:I57) -> 293 | J58: =SUM(J10:J57) -> 106 | ... P58: =SUM(P10:P57) -> 7668
...

Sheet 30.07 NAMUGONGO-KIREKA
B1: Consultancy services for Preparation of Expressway Development Master Plan (EDMP) for Uganda
B2: MANUAL CLASSIFIED COUNT (MCC)
B3: ROAD NAME: | C3: ='01.08 NAMUGONGO-KIREKA'!C3:G3 -> MCC - C1 - STN039 - NAMUGONGO ROAD
C5: Date | D5: 30.07.19 | F5: Location | G5: ='31.07 KIREKA-NAMUGONGO-24h'!G5:H5 -> AGENDA | J5: Surveyor | K5: ='31.07 KIREKA-NAMUGONGO-24h'!K5:L5 -> STEVEN
C6: Dir. From | D6: ='01.08 NAMUGONGO-KIREKA'!D6:E6 -> NAMUGONGO | F6: Dir. To | G6: ='01.08 NAMUGONGO-KIREKA'!G6:H6 -> KIREKA | J6: Supervisor | K6: ='31.07 KIREKA-NAMUGONGO-24h'!K6:L6 -> NAIDO GRACE BRENDA
B8: Time / Veh Type | R8: SUMMARY TRAFFIC VOLUMES
C9: 1. Car | D9: 2. Station Wagon | E9: 3. Pickups | F9: 4. Minibus, matatu | G9: 5. Medium bus | H9: 6. Large Bus | I9: 7. Light Truck | J9: 8. Medium Truck | K9: 9. Heavy truck | L9: 10. Truck Trailer | M9: 11. Motor cycles | N9: 12. Tractors | O9: Total Excl M/Cycles | P9: Total All | R9: Time | S9: 1. Car | T9: 2. Station Wagon | U9: 3. Pickups | V9: 4. Minibus, matatu | W9: 5. Medium bus | X9: 6. Large Bus | Y9: 7. Light Truck | Z9: 8. Medium Truck | AA9: 9. Heavy truck | AB9: 10. Truck Trailer | AC9: 11. Motorcycles | AD9: 12. Tractors, Graders | AE9: Total Excl M/ Cycles | AF9: Total All
B10: 07.00 - 07.15 | C10: 93 | D10: 11 | E10: 8 | F10: 22 | G10: 0 | H10: 0 | I10: 3 | J10: 0 | K10: 0 | L10: 0 | M10: 90 | N10: 0 | O10: =SUM(C10:L10,N10) -> 137 | P10: =SUM(C10:N10) -> 227 | R10: 0700-0800 | S10: =SUM(C10:C13) -> 420 | T10: =SUM(D10:D13) -> 49 | U10: =SUM(E10:E13) -> 49 | V10: =SUM(F10:F13) -> 111 | W10: =SUM(G10:G13) -> 2 | X10: =SUM(H10:H13) -> 0 | Y10: =SUM(I10:I13) -> 14 | Z10: =SUM(J10:J13) -> 0 | ... AF10: =SUM(P10:P13) -> 1248
B11: 07.15 - 07.30 | C11: 122 | D11: 15 | E11: 8 | F11: 29 | G11: 2 | H11: 0 | I11: 5 | J11: 0 | K11: 0 | L11: 0 | M11: 150 | N11: 0 | O11: =SUM(C11:L11,N11) -> 181 | P11: =SUM(C11:N11) -> 331 | R11: 0800-0900 | S11: =SUM(C14:C17) -> 389 | T11: =SUM(D14:D17) -> 35 | U11: =SUM(E14:E17) -> 55 | V11: =SUM(F14:F17) -> 108 | W11: =SUM(G14:G17) -> 1 | X11: =SUM(H14:H17) -> 0 | Y11: =SUM(I14:I17) -> 25 | Z11: =SUM(J14:J17) -> 2 | ... AF11: =SUM(P14:P17) -> 1221
B12: 07.30 - 07.45 | C12: 105 | D12: 12 | E12: 15 | F12: 29 | G12: 0 | H12: 0 | I12: 3 | J12: 0 | K12: 1 | L12: 1 | M12: 194 | N12: 0 | O12: =SUM(C12:L12,N12) -> 166 | P12: =SUM(C12:N12) -> 360 | R12: 0900-1000 | S12: =SUM(C18:C21) -> 304 | T12: =SUM(D18:D21) -> 35 | U12: =SUM(E18:E21) -> 28 | V12: =SUM(F18:F21) -> 94 | W12: =SUM(G18:G21) -> 0 | X12: =SUM(H18:H21) -> 0 | Y12: =SUM(I18:I21) -> 24 | Z12: =SUM(J18:J21) -> 3 | ... AF12: =SUM(P18:P21) -> 1024
B13: 07.45 - 08.00 | C13: 100 | D13: 11 | E13: 18 | F13: 31 | G13: 0 | H13: 0 | I13: 3 | J13: 0 | K13: 0 | L13: 0 | M13: 167 | N13: 0 | O13: =SUM(C13:L13,N13) -> 163 | P13: =SUM(C13:N13) -> 330 | R13: 1000-1100 | S13: =SUM(C22:C25) -> 246 | T13: =SUM(D22:D25) -> 39 | U13: =SUM(E22:E25) -> 32 | V13: =SUM(F22:F25) -> 96 | W13: =SUM(G22:G25) -> 2 | X13: =SUM(H22:H25) -> 0 | Y13: =SUM(I22:I25) -> 20 | Z13: =SUM(J22:J25) -> 4 | ... AF13: =SUM(P22:P25) -> 928
B14: 08.00 - 08.15 | C14: 92 | D14: 7 | E14: 10 | F14: 33 | G14: 0 | H14: 0 | I14: 4 | J14: 0 | K14: 0 | L14: 0 | M14: 173 | N14: 0 | O14: =SUM(C14:L14,N14) -> 146 | P14: =SUM(C14:N14) -> 319 | R14: 1100-1200 | S14: =SUM(C26:C29) -> 202 | T14: =SUM(D26:D29) -> 31 | U14: =SUM(E26:E29) -> 45 | V14: =SUM(F26:F29) -> 82 | W14: =SUM(G26:G29) -> 0 | X14: =SUM(H26:H29) -> 0 | Y14: =SUM(I26:I29) -> 22 | Z14: =SUM(J26:J29) -> 0 | ... AF14: =SUM(P26:P29) -> 828
B15: 08.15 - 08.30 | C15: 84 | D15: 10 | E15: 13 | F15: 28 | G15: 0 | H15: 0 | I15: 5 | J15: 0 | K15: 1 | L15: 0 | M15: 162 | N15: 0 | O15: =SUM(C15:L15,N15) -> 141 | P15: =SUM(C15:N15) -> 303 | R15: 1200-1300 | S15: =SUM(C30:C33) -> 203 | T15: =SUM(D30:D33) -> 15 | U15: =SUM(E30:E33) -> 36 | V15: =SUM(F30:F33) -> 95 | W15: =SUM(G30:G33) -> 0 | X15: =SUM(H30:H33) -> 0 | Y15: =SUM(I30:I33) -> 33 | Z15: =SUM(J30:J33) -> 6 | ... AF15: =SUM(P30:P33) -> 786
B16: 08.30 - 08.45 | C16: 118 | D16: 6 | E16: 17 | F16: 22 | G16: 1 | H16: 0 | I16: 6 | J16: 1 | K16: 0 | L16: 0 | M16: 125 | N16: 0 | O16: =SUM(C16:L16,N16) -> 171 | P16: =SUM(C16:N16) -> 296 | R16: 1300-1400 | S16: =SUM(C34:C37) -> 173 | T16: =SUM(D34:D37) -> 20 | U16: =SUM(E34:E37) -> 32 | V16: =SUM(F34:F37) -> 85 | W16: =SUM(G34:G37) -> 1 | X16: =SUM(H34:H37) -> 0 | Y16: =SUM(I34:I37) -> 34 | Z16: =SUM(J34:J37) -> 2 | ... AF16: =SUM(P34:P37) -> 708
B17: 08.45 - 9.00 | C17: 95 | D17: 12 | E17: 15 | F17: 25 | G17: 0 | H17: 0 | I17: 10 | J17: 1 | K17: 0 | L17: 0 | M17: 145 | N17: 0 | O17: =SUM(C17:L17,N17) -> 158 | P17: =SUM(C17:N17) -> 303 | R17: 1400-1500 | S17: =SUM(C38:C41) -> 141 | T17: =SUM(D38:D41) -> 21 | U17: =SUM(E38:E41) -> 38 | V17: =SUM(F38:F41) -> 140 | W17: =SUM(G38:G41) -> 2 | X17: =SUM(H38:H41) -> 9 | Y17: =SUM(I38:I41) -> 18 | Z17: =SUM(J38:J41) -> 4 | ... AF17: =SUM(P38:P41) -> 778
B18: 09.00 - 09.15 | C18: 100 | D18: 14 | E18: 8 | F18: 25 | G18: 0 | H18: 0 | I18: 7 | J18: 1 | K18: 6 | L18: 0 | M18: 175 | N18: 0 | O18: =SUM(C18:L18,N18) -> 161 | P18: =SUM(C18:N18) -> 336 | R18: 1500-1600 | S18: =SUM(C42:C45) -> 181 | T18: =SUM(D42:D45) -> 14 | U18: =SUM(E42:E45) -> 19 | V18: =SUM(F42:F45) -> 76 | W18: =SUM(G42:G45) -> 0 | X18: =SUM(H42:H45) -> 0 | Y18: =SUM(I42:I45) -> 34 | Z18: =SUM(J42:J45) -> 3 | ... AF18: =SUM(P42:P45) -> 792
B19: 09.15 - 09.30 | C19: 65 | D19: 7 | E19: 10 | F19: 29 | G19: 0 | H19: 0 | I19: 6 | J19: 0 | K19: 1 | L19: 0 | M19: 126 | N19: 0 | O19: =SUM(C19:L19,N19) -> 118 | P19: =SUM(C19:N19) -> 244 | R19: 1600-1700 | S19: =SUM(C46:C49) -> 178 | T19: =SUM(D46:D49) -> 25 | U19: =SUM(E46:E49) -> 30 | V19: =SUM(F46:F49) -> 71 | W19: =SUM(G46:G49) -> 3 | X19: =SUM(H46:H49) -> 1 | Y19: =SUM(I46:I49) -> 29 | Z19: =SUM(J46:J49) -> 4 | ... AF19: =SUM(P46:P49) -> 816
B20: 09.30 - 09.45 | C20: 60 | D20: 9 | E20: 3 | F20: 19 | G20: 0 | H20: 0 | I20: 6 | J20: 1 | K20: 1 | L20: 0 | M20: 119 | N20: 0 | O20: =SUM(C20:L20,N20) -> 99 | P20: =SUM(C20:N20) -> 218 | R20: 1700-1800 | S20: =SUM(C50:C53) -> 185 | T20: =SUM(D50:D53) -> 18 | U20: =SUM(E50:E53) -> 26 | V20: =SUM(F50:F53) -> 87 | W20: =SUM(G50:G53) -> 5 | X20: =SUM(H50:H53) -> 0 | Y20: =SUM(I50:I53) -> 30 | Z20: =SUM(J50:J53) -> 1 | ... AF20: =SUM(P50:P53) -> 903
B21: 09.45 - 10.00 | C21: 79 | D21: 5 | E21: 7 | F21: 21 | G21: 0 | H21: 0 | I21: 5 | J21: 1 | K21: 0 | L21: 0 | M21: 108 | N21: 0 | O21: =SUM(C21:L21,N21) -> 118 | P21: =SUM(C21:N21) -> 226 | R21: 1800-1900 | S21: =SUM(C54:C57) -> 174 | T21: =SUM(D54:D57) -> 20 | U21: =SUM(E54:E57) -> 47 | V21: =SUM(F54:F57) -> 104 | W21: =SUM(G54:G57) -> 4 | X21: =SUM(H54:H57) -> 0 | Y21: =SUM(I54:I57) -> 25 | Z21: =SUM(J54:J57) -> 5 | ... AF21: =SUM(P54:P57) -> 952
B22: 10.00 - 10.15 | C22: 63 | D22: 14 | E22: 8 | F22: 22 | G22: 0 | H22: 0 | I22: 7 | J22: 1 | K22: 0 | L22: 0 | M22: 115 | N22: 0 | O22: =SUM(C22:L22,N22) -> 115 | P22: =SUM(C22:N22) -> 230 | R22: AM Peak Hr | S22: =MAX(S10:S12) -> 420 | T22: =MAX(T10:T12) -> 49 | U22: =MAX(U10:U12) -> 55 | V22: =MAX(V10:V12) -> 111 | W22: =MAX(W10:W12) -> 2 | X22: =MAX(X10:X12) -> 0 | Y22: =MAX(Y10:Y12) -> 25 | Z22: =MAX(Z10:Z12) -> 3 | ... AF22: =MAX(AF10:AF12) -> 1248
B23: 10.15 - 10.30 | C23: 65 | D23: 8 | E23: 5 | F23: 26 | G23: 1 | H23: 0 | I23: 8 | J23: 2 | K23: 2 | L23: 0 | M23: 164 | N23: 0 | O23: =SUM(C23:L23,N23) -> 117 | P23: =SUM(C23:N23) -> 281 | R23: IP Peak Hr | S23: =MAX(S13:S18) -> 246 | T23: =MAX(T13:T18) -> 39 | U23: =MAX(U13:U18) -> 45 | V23: =MAX(V13:V18) -> 140 | W23: =MAX(W13:W18) -> 2 | X23: =MAX(X13:X18) -> 9 | Y23: =MAX(Y13:Y18) -> 34 | Z23: =MAX(Z13:Z18) -> 6 | ... AF23: =MAX(AF13:AF18) -> 928
B24: 10.30 - 10.45 | C24: 65 | D24: 11 | E24: 9 | F24: 27 | G24: 1 | H24: 0 | I24: 1 | J24: 0 | K24: 2 | L24: 0 | M24: 94 | N24: 0 | O24: =SUM(C24:L24,N24) -> 116 | P24: =SUM(C24:N24) -> 210 | R24: PM Peak Hr | S24: =MAX(S19:S21) -> 185 | T24: =MAX(T19:T21) -> 25 | U24: =MAX(U19:U21) -> 47 | V24: =MAX(V19:V21) -> 104 | W24: =MAX(W19:W21) -> 5 | X24: =MAX(X19:X21) -> 1 | Y24: =MAX(Y19:Y21) -> 30 | Z24: =MAX(Z19:Z21) -> 5 | ... AF24: =MAX(AF19:AF21) -> 952
B25: 10.45 - 11.00 | C25: 53 | D25: 6 | E25: 10 | F25: 21 | G25: 0 | H25: 0 | I25: 4 | J25: 1 | K25: 3 | L25: 1 | M25: 108 | N25: 0 | O25: =SUM(C25:L25,N25) -> 99 | P25: =SUM(C25:N25) -> 207 | R25: AM Period | S25: =SUM(S10:S12) -> 1113 | T25: =SUM(T10:T12) -> 119 | U25: =SUM(U10:U12) -> 132 | V25: =SUM(V10:V12) -> 313 | W25: =SUM(W10:W12) -> 3 | X25: =SUM(X10:X12) -> 0 | Y25: =SUM(Y10:Y12) -> 63 | Z25: =SUM(Z10:Z12) -> 5 | ... AF25: =SUM(AF10:AF12) -> 3493
B26: 11.00 - 11.15 | C26: 59 | D26: 9 | E26: 11 | F26: 21 | G26: 0 | H26: 0 | I26: 1 | J26: 0 | K26: 0 | L26: 0 | M26: 107 | N26: 0 | O26: =SUM(C26:L26,N26) -> 101 | P26: =SUM(C26:N26) -> 208 | R26: IP Period | S26: =SUM(S13:S18) -> 1146 | T26: =SUM(T13:T18) -> 140 | U26: =SUM(U13:U18) -> 202 | V26: =SUM(V13:V18) -> 574 | W26: =SUM(W13:W18) -> 5 | X26: =SUM(X13:X18) -> 9 | Y26: =SUM(Y13:Y18) -> 161 | Z26: =SUM(Z13:Z18) -> 19 | ... AF26: =SUM(AF13:AF18) -> 4820
B27: 11.15 - 11.30 | C27: 61 | D27: 5 | E27: 17 | F27: 24 | G27: 0 | H27: 0 | I27: 12 | J27: 0 | K27: 0 | L27: 0 | M27: 125 | N27: 0 | O27: =SUM(C27:L27,N27) -> 119 | P27: =SUM(C27:N27) -> 244 | R27: PM Period | S27: =SUM(S19:S21) -> 537 | T27: =SUM(T19:T21) -> 63 | U27: =SUM(U19:U21) -> 103 | V27: =SUM(V19:V21) -> 262 | W27: =SUM(W19:W21) -> 12 | X27: =SUM(X19:X21) -> 1 | Y27: =SUM(Y19:Y21) -> 84 | Z27: =SUM(Z19:Z21) -> 10 | ... AF27: =SUM(AF19:AF21) -> 2671
B28: 11.30 - 11.45 | C28: 50 | D28: 9 | E28: 6 | F28: 15 | G28: 0 | H28: 0 | I28: 3 | J28: 0 | K28: 2 | L28: 0 | M28: 110 | N28: 0 | O28: =SUM(C28:L28,N28) -> 85 | P28: =SUM(C28:N28) -> 195 | R28: 12 Hours | S28: =SUM(S10:S21) -> 2796 | T28: =SUM(T10:T21) -> 322 | U28: =SUM(U10:U21) -> 437 | V28: =SUM(V10:V21) -> 1149 | W28: =SUM(W10:W21) -> 20 | X28: =SUM(X10:X21) -> 10 | Y28: =SUM(Y10:Y21) -> 308 | Z28: =SUM(Z10:Z21) -> 34 | ... AF28: =SUM(AF10:AF21) -> 10984
B29: 11.45 - 12.00 | C29: 32 | D29: 8 | E29: 11 | F29: 22 | G29: 0 | H29: 0 | I29: 6 | J29: 0 | K29: 2 | L29: 1 | M29: 99 | N29: 0 | O29: =SUM(C29:L29,N29) -> 82 | P29: =SUM(C29:N29) -> 181
B30: 12.00 - 12.15 | C30: 37 | D30: 4 | E30: 10 | F30: 23 | G30: 0 | H30: 0 | I30: 11 | J30: 3 | K30: 0 | L30: 0 | M30: 108 | N30: 0 | O30: =SUM(C30:L30,N30) -> 88 | P30: =SUM(C30:N30) -> 196
B31: 12.15 - 12.30 | C31: 57 | D31: 3 | E31: 13 | F31: 15 | G31: 0 | H31: 0 | I31: 11 | J31: 3 | K31: 0 | L31: 0 | M31: 92 | N31: 0 | O31: =SUM(C31:L31,N31) -> 102 | P31: =SUM(C31:N31) -> 194
B32: 12.30 - 12.45 | C32: 66 | D32: 6 | E32: 5 | F32: 29 | G32: 0 | H32: 0 | I32: 8 | J32: 0 | K32: 0 | L32: 0 | M32: 101 | N32: 0 | O32: =SUM(C32:L32,N32) -> 114 | P32: =SUM(C32:N32) -> 215
B33: 12.45 - 13.00 | C33: 43 | D33: 2 | E33: 8 | F33: 28 | G33: 0 | H33: 0 | I33: 3 | J33: 0 | K33: 1 | L33: 0 | M33: 96 | N33: 0 | O33: =SUM(C33:L33,N33) -> 85 | P33: =SUM(C33:N33) -> 181
B34: 13.00 - 13.15 | C34: 45 | D34: 7 | E34: 10 | F34: 34 | G34: 0 | H34: 0 | I34: 4 | J34: 1 | K34: 0 | L34: 0 | M34: 93 | N34: 0 | O34: =SUM(C34:L34,N34) -> 101 | P34: =SUM(C34:N34) -> 194
B35: 13.15 - 13.30 | C35: 40 | D35: 5 | E35: 6 | F35: 22 | G35: 0 | H35: 0 | I35: 11 | J35: 1 | K35: 1 | L35: 0 | M35: 90 | N35: 0 | O35: =SUM(C35:L35,N35) -> 86 | P35: =SUM(C35:N35) -> 176
B36: 13.30 - 13.45 | C36: 46 | D36: 4 | E36: 5 | F36: 16 | G36: 0 | H36: 0 | I36: 9 | J36: 0 | K36: 0 | L36: 0 | M36: 94 | N36: 0 | O36: =SUM(C36:L36,N36) -> 80 | P36: =SUM(C36:N36) -> 174
B37: 13.45 - 14.00 | C37: 42 | D37: 4 | E37: 11 | F37: 13 | G37: 1 | H37: 0 | I37: 10 | J37: 0 | K37: 1 | L37: 0 | M37: 82 | N37: 0 | O37: =SUM(C37:L37,N37) -> 82 | P37: =SUM(C37:N37) -> 164
B38: 14.00 - 14.15 | C38: 35 | D38: 9 | E38: 9 | F38: 23 | G38: 0 | H38: 9 | I38: 0 | J38: 0 | K38: 0 | L38: 1 | M38: 102 | N38: 0 | O38: =SUM(C38:L38,N38) -> 86 | P38: =SUM(C38:N38) -> 188
B39: 14.15 - 14.30 | C39: 32 | D39: 5 | E39: 12 | F39: 21 | G39: 1 | H39: 0 | I39: 8 | J39: 2 | K39: 0 | L39: 0 | M39: 102 | N39: 0 | O39: =SUM(C39:L39,N39) -> 81 | P39: =SUM(C39:N39) -> 183
B40: 14.30 - 14.45 | C40: 34 | D40: 2 | E40: 7 | F40: 17 | G40: 0 | H40: 0 | I40: 4 | J40: 0 | K40: 0 | L40: 0 | M40: 95 | N40: 0 | O40: =SUM(C40:L40,N40) -> 64 | P40: =SUM(C40:N40) -> 159
... B57: 18.45 - 19.00 | C57: 34 | D57: 3 | E57: 8 | F57: 28 | G57: 0 | H57: 0 | I57: 7 | J57: 0 | K57: 1 | L57: 0 | M57: 160 | N57: 0 | O57: =SUM(C57:L57,N57) -> 81 | P57: =SUM(C57:N57) -> 241
B58: Totals | C58: =SUM(C10:C57) -> 2796 | D58: =SUM(D10:D57) -> 322 | E58: =SUM(E10:E57) -> 437 | F58: =SUM(F10:F57) -> 1149 | G58: =SUM(G10:G57) -> 20 | H58: =SUM(H10:H57) -> 10 | I58: =SUM(I10:I57) -> 308 | J58: =SUM(J10:J57) -> 34 | ... P58: =SUM(P10:P57) -> 10984
...

Sheet 30.07 KIREKA-NAMUGONGO
B1: Consultancy services for Preparation of Expressway Development Master Plan (EDMP) for Uganda
B2: MANUAL CLASSIFIED COUNT (MCC)
B3: ROAD NAME: | C3: ='01.08 KIREKA-NAMUGONGO'!C3:G3 -> MCC - C1 - STN039 - NAMUGONGO ROAD
C5: Date | D5: ='30.07 NAMUGONGO-KIREKA'!D5 -> 30.07.19 | F5: Location | G5: ='30.07 NAMUGONGO-KIREKA'!G5:H5 -> AGENDA | J5: Surveyor | K5: ='30.07 NAMUGONGO-KIREKA'!K5:L5 -> STEVEN
C6: Dir. From | D6: ='01.08 KIREKA-NAMUGONGO'!D6:E6 -> KIREKA | F6: Dir. To | G6: ='01.08 KIREKA-NAMUGONGO'!G6:H6 -> NAMUGONGO | J6: Supervisor | K6: ='30.07 NAMUGONGO-KIREKA'!K6:L6 -> NAIDO GRACE BRENDA
B8: Time / Veh Type | R8: SUMMARY TRAFFIC VOLUMES
C9: 1. Car | D9: 2. Station Wagon | E9: 3. Pickups | F9: 4. Minibus, matatu | G9: 5. Medium bus | H9: 6. Large Bus | I9: 7. Light Truck | J9: 8. Medium Truck | K9: 9. Heavy truck | L9: 10. Truck Trailer | M9: 11. Motor cycles | N9: 12. Tractors | O9: Total Excl M/Cycles | P9: Total All | R9: Time | S9: 1. Car | T9: 2. Station Wagon | U9: 3. Pickups | V9: 4. Minibus, matatu | W9: 5. Medium bus | X9: 6. Large Bus | Y9: 7. Light Truck | Z9: 8. Medium Truck | AA9: 9. Heavy truck | AB9: 10. Truck Trailer | AC9: 11. Motorcycles | AD9: 12. Tractors, Graders | AE9: Total Excl M/ Cycles | AF9: Total All
B10: 07.00 - 07.15 | C10: 8 | D10: 3 | E10: 5 | F10: 0 | G10: 0 | H10: 0 | I10: 0 | J10: 0 | K10: 0 | L10: 0 | M10: 0 | N10: 0 | O10: =SUM(C10:L10,N10) -> 16 | P10: =SUM(C10:N10) -> 16 | R10: 0700-0800 | S10: =SUM(C10:C13) -> 122 | T10: =SUM(D10:D13) -> 39 | U10: =SUM(E10:E13) -> 14 | V10: =SUM(F10:F13) -> 29 | W10: =SUM(G10:G13) -> 1 | X10: =SUM(H10:H13) -> 1 | Y10: =SUM(I10:I13) -> 0 | Z10: =SUM(J10:J13) -> 0 | ... AF10: =SUM(P10:P13) -> 206
B11: 07.15 - 07.30 | C11: 34 | D11: 13 | E11: 0 | F11: 0 | G11: 0 | H11: 0 | I11: 0 | J11: 0 | K11: 0 | L11: 0 | M11: 0 | N11: 0 | O11: =SUM(C11:L11,N11) -> 47 | P11: =SUM(C11:N11) -> 47 | R11: 0800-0900 | S11: =SUM(C14:C17) -> 136 | T11: =SUM(D14:D17) -> 33 | U11: =SUM(E14:E17) -> 15 | V11: =SUM(F14:F17) -> 62 | W11: =SUM(G14:G17) -> 1 | X11: =SUM(H14:H17) -> 0 | Y11: =SUM(I14:I17) -> 0 | Z11: =SUM(J14:J17) -> 0 | ... AF11: =SUM(P14:P17) -> 247
B12: 07.30 - 07.45 | C12: 35 | D12: 10 | E12: 1 | F12: 16 | G12: 1 | H12: 1 | I12: 0 | J12: 0 | K12: 0 | L12: 0 | M12: 0 | N12: 0 | O12: =SUM(C12:L12,N12) -> 64 | P12: =SUM(C12:N12) -> 64 | R12: 0900-1000 | S12: =SUM(C18:C21) -> 138 | T12: =SUM(D18:D21) -> 30 | U12: =SUM(E18:E21) -> 23 | V12: =SUM(F18:F21) -> 70 | W12: =SUM(G18:G21) -> 0 | X12: =SUM(H18:H21) -> 0 | Y12: =SUM(I18:I21) -> 27 | Z12: =SUM(J18:J21) -> 5 | ... AF12: =SUM(P18:P21) -> 806
B13: 07.45 - 08.00 | C13: 45 | D13: 13 | E13: 8 | F13: 13 | G13: 0 | H13: 0 | I13: 0 | J13: 0 | K13: 0 | L13: 0 | M13: 0 | N13: 0 | O13: =SUM(C13:L13,N13) -> 79 | P13: =SUM(C13:N13) -> 79 | R13: 1000-1100 | S13: =SUM(C22:C25) -> 156 | T13: =SUM(D22:D25) -> 66 | U13: =SUM(E22:E25) -> 18 | V13: =SUM(F22:F25) -> 45 | W13: =SUM(G22:G25) -> 16 | X13: =SUM(H22:H25) -> 0 | Y13: =SUM(I22:I25) -> 9 | Z13: =SUM(J22:J25) -> 18 | ... AF13: =SUM(P22:P25) -> 813
B14: 08.00 - 08.15 | C14: 27 | D14: 8 | E14: 2 | F14: 15 | G14: 1 | H14: 0 | I14: 0 | J14: 0 | K14: 0 | L14: 0 | M14: 0 | N14: 0 | O14: =SUM(C14:L14,N14) -> 53 | P14: =SUM(C14:N14) -> 53 | R14: 1100-1200 | S14: =SUM(C26:C29) -> 122 | T14: =SUM(D26:D29) -> 35 | U14: =SUM(E26:E29) -> 20 | V14: =SUM(F26:F29) -> 40 | W14: =SUM(G26:G29) -> 12 | X14: =SUM(H26:H29) -> 0 | Y14: =SUM(I26:I29) -> 36 | Z14: =SUM(J26:J29) -> 19 | ... AF14: =SUM(P26:P29) -> 687
B15: 08.15 - 08.30 | C15: 34 | D15: 6 | E15: 6 | F15: 18 | G15: 0 | H15: 0 | I15: 0 | J15: 0 | K15: 0 | L15: 0 | M15: 0 | N15: 0 | O15: =SUM(C15:L15,N15) -> 64 | P15: =SUM(C15:N15) -> 64 | R15: 1200-1300 | S15: =SUM(C30:C33) -> 138 | T15: =SUM(D30:D33) -> 42 | U15: =SUM(E30:E33) -> 34 | V15: =SUM(F30:F33) -> 50 | W15: =SUM(G30:G33) -> 4 | X15: =SUM(H30:H33) -> 0 | Y15: =SUM(I30:I33) -> 20 | Z15: =SUM(J30:J33) -> 23 | ... AF15: =SUM(P30:P33) -> 678
B16: 08.30 - 08.45 | C16: 43 | D16: 13 | E16: 5 | F16: 16 | G16: 0 | H16: 0 | I16: 0 | J16: 0 | K16: 0 | L16: 0 | M16: 0 | N16: 0 | O16: =SUM(C16:L16,N16) -> 77 | P16: =SUM(C16:N16) -> 77 | R16: 1300-1400 | S16: =SUM(C34:C37) -> 167 | T16: =SUM(D34:D37) -> 37 | U16: =SUM(E34:E37) -> 27 | V16: =SUM(F34:F37) -> 62 | W16: =SUM(G34:G37) -> 0 | X16: =SUM(H34:H37) -> 0 | Y16: =SUM(I34:I37) -> 28 | Z16: =SUM(J34:J37) -> 21 | ... AF16: =SUM(P34:P37) -> 742
B17: 08.45 - 9.00 | C17: 32 | D17: 6 | E17: 2 | F17: 13 | G17: 0 | H17: 0 | I17: 0 | J17: 0 | K17: 0 | L17: 0 | M17: 0 | N17: 0 | O17: =SUM(C17:L17,N17) -> 53 | P17: =SUM(C17:N17) -> 53 | R17: 1400-1500 | S17: =SUM(C38:C41) -> 157 | T17: =SUM(D38:D41) -> 58 | U17: =SUM(E38:E41) -> 26 | V17: =SUM(F38:F41) -> 71 | W17: =SUM(G38:G41) -> 0 | X17: =SUM(H38:H41) -> 0 | Y17: =SUM(I38:I41) -> 26 | Z17: =SUM(J38:J41) -> 13 | ... AF17: =SUM(P38:P41) -> 691
B18: 09.00 - 09.15 | C18: 27 | D18: 6 | E18: 7 | F18: 20 | G18: 0 | H18: 0 | I18: 5 | J18: 2 | K18: 3 | L18: 0 | M18: 133 | N18: 0 | O18: =SUM(C18:L18,N18) -> 70 | P18: =SUM(C18:N18) -> 203 | R18: 1500-1600 | S18: =SUM(C42:C45) -> 179 | T18: =SUM(D42:D45) -> 44 | U18: =SUM(E42:E45) -> 23 | V18: =SUM(F42:F45) -> 62 | W18: =SUM(G42:G45) -> 3 | X18: =SUM(H42:H45) -> 0 | Y18: =SUM(I42:I45) -> 30 | Z18: =SUM(J42:J45) -> 14 | ... AF18: =SUM(P42:P45) -> 765
B19: 09.15 - 09.30 | C19: 25 | D19: 7 | E19: 6 | F19: 18 | G19: 0 | H19: 0 | I19: 11 | J19: 1 | K19: 0 | L19: 0 | M19: 142 | N19: 0 | O19: =SUM(C19:L19,N19) -> 68 | P19: =SUM(C19:N19) -> 210 | R19: 1600-1700 | S19: =SUM(C46:C49) -> 285 | T19: =SUM(D46:D49) -> 77 | U19: =SUM(E46:E49) -> 47 | V19: =SUM(F46:F49) -> 79 | W19: =SUM(G46:G49) -> 3 | X19: =SUM(H46:H49) -> 0 | Y19: =SUM(I46:I49) -> 32 | Z19: =SUM(J46:J49) -> 7 | ... AF19: =SUM(P46:P49) -> 947
B20: 09.30 - 09.45 | C20: 42 | D20: 9 | E20: 6 | F20: 15 | G20: 0 | H20: 0 | I20: 6 | J20: 0 | K20: 2 | L20: 1 | M20: 113 | N20: 0 | O20: =SUM(C20:L20,N20) -> 81 | P20: =SUM(C20:N20) -> 194 | R20: 1700-1800 | S20: =SUM(C50:C53) -> 409 | T20: =SUM(D50:D53) -> 85 | U20: =SUM(E50:E53) -> 47 | V20: =SUM(F50:F53) -> 96 | W20: =SUM(G50:G53) -> 17 | X20: =SUM(H50:H53) -> 2 | Y20: =SUM(I50:I53) -> 26 | Z20: =SUM(J50:J53) -> 2 | ... AF20: =SUM(P50:P53) -> 1254
B21: 09.45 - 10.00 | C21: 44 | D21: 8 | E21: 4 | F21: 17 | G21: 0 | H21: 0 | I21: 5 | J21: 2 | K21: 4 | L21: 0 | M21: 115 | N21: 0 | O21: =SUM(C21:L21,N21) -> 84 | P21: =SUM(C21:N21) -> 199 | R21: 1800-1900 | S21: =SUM(C54:C57) -> 340 | T21: =SUM(D54:D57) -> 104 | U21: =SUM(E54:E57) -> 45 | V21: =SUM(F54:F57) -> 116 | W21: =SUM(G54:G57) -> 1 | X21: =SUM(H54:H57) -> 1 | Y21: =SUM(I54:I57) -> 17 | Z21: =SUM(J54:J57) -> 11 | ... AF21: =SUM(P54:P57) -> 1356
B22: 10.00 - 10.15 | C22: 49 | D22: 20 | E22: 7 | F22: 10 | G22: 1 | H22: 0 | I22: 0 | J22: 10 | K22: 3 | L22: 0 | M22: 119 | N22: 0 | O22: =SUM(C22:L22,N22) -> 100 | P22: =SUM(C22:N22) -> 219 | R22: AM Peak Hr | S22: =MAX(S10:S12) -> 138 | T22: =MAX(T10:T12) -> 39 | U22: =MAX(U10:U12) -> 23 | V22: =MAX(V10:V12) -> 70 | W22: =MAX(W10:W12) -> 1 | X22: =MAX(X10:X12) -> 1 | Y22: =MAX(Y10:Y12) -> 27 | Z22: =MAX(Z10:Z12) -> 5 | ... AF22: =MAX(AF10:AF12) -> 806
B23: 10.15 - 10.30 | C23: 36 | D23: 18 | E23: 4 | F23: 15 | G23: 0 | H23: 0 | I23: 9 | J23: 1 | K23: 1 | L23: 1 | M23: 169 | N23: 0 | O23: =SUM(C23:L23,N23) -> 85 | P23: =SUM(C23:N23) -> 254 | R23: IP Peak Hr | S23: =MAX(S13:S18) -> 179 | T23: =MAX(T13:T18) -> 66 | U23: =MAX(U13:U18) -> 34 | V23: =MAX(V13:V18) -> 71 | W23: =MAX(W13:W18) -> 16 | X23: =MAX(X13:X18) -> 0 | Y23: =MAX(Y13:Y18) -> 36 | Z23: =MAX(Z13:Z18) -> 23 | ... AF23: =MAX(AF13:AF18) -> 813
B24: 10.30 - 10.45 | C24: 32 | D24: 9 | E24: 0 | F24: 4 | G24: 15 | H24: 0 | I24: 0 | J24: 7 | K24: 3 | L24: 6 | M24: 100 | N24: 0 | O24: =SUM(C24:L24,N24) -> 76 | P24: =SUM(C24:N24) -> 176 | R24: PM Peak Hr | S24: =MAX(S19:S21) -> 409 | T24: =MAX(T19:T21) -> 104 | U24: =MAX(U19:U21) -> 47 | V24: =MAX(V19:V21) -> 116 | W24: =MAX(W19:W21) -> 17 | X24: =MAX(X19:X21) -> 2 | Y24: =MAX(Y19:Y21) -> 32 | Z24: =MAX(Z19:Z21) -> 11 | ... AF24: =MAX(AF19:AF21) -> 1356
B25: 10.45 - 11.00 | C25: 39 | D25: 19 | E25: 7 | F25: 16 | G25: 0 | H25: 0 | I25: 0 | J25: 0 | K25: 0 | L25: 0 | M25: 83 | N25: 0 | O25: =SUM(C25:L25,N25) -> 81 | P25: =SUM(C25:N25) -> 164 | R25: AM Period | S25: =SUM(S10:S12) -> 396 | T25: =SUM(T10:T12) -> 102 | U25: =SUM(U10:U12) -> 52 | V25: =SUM(V10:V12) -> 161 | W25: =SUM(W10:W12) -> 2 | X25: =SUM(X10:X12) -> 1 | Y25: =SUM(Y10:Y12) -> 27 | Z25: =SUM(Z10:Z12) -> 5 | ... AF25: =SUM(AF10:AF12) -> 1259
B26: 11.00 - 11.15 | C26: 27 | D26: 12 | E26: 5 | F26: 0 | G26: 12 | H26: 0 | I26: 0 | J26: 5 | K26: 0 | L26: 3 | M26: 84 | N26: 0 | O26: =SUM(C26:L26,N26) -> 64 | P26: =SUM(C26:N26) -> 148 | R26: IP Period | S26: =SUM(S13:S18) -> 919 | T26: =SUM(T13:T18) -> 282 | U26: =SUM(U13:U18) -> 148 | V26: =SUM(V13:V18) -> 330 | W26: =SUM(W13:W18) -> 35 | X26: =SUM(X13:X18) -> 0 | Y26: =SUM(Y13:Y18) -> 149 | Z26: =SUM(Z13:Z18) -> 108 | ... AF26: =SUM(AF13:AF18) -> 4376
B27: 11.15 - 11.30 | C27: 37 | D27: 4 | E27: 5 | F27: 18 | G27: 0 | H27: 0 | I27: 8 | J27: 3 | K27: 0 | L27: 0 | M27: 71 | N27: 0 | O27: =SUM(C27:L27,N27) -> 75 | P27: =SUM(C27:N27) -> 146 | R27: PM Period | S27: =SUM(S19:S21) -> 1034 | T27: =SUM(T19:T21) -> 266 | U27: =SUM(U19:U21) -> 139 | V27: =SUM(V19:V21) -> 291 | W27: =SUM(W19:W21) -> 21 | X27: =SUM(X19:X21) -> 3 | Y27: =SUM(Y19:Y21) -> 75 | Z27: =SUM(Z19:Z21) -> 20 | ... AF27: =SUM(AF19:AF21) -> 3557
B28: 11.30 - 11.45 | C28: 28 | D28: 13 | E28: 4 | F28: 10 | G28: 0 | H28: 0 | I28: 12 | J28: 5 | K28: 0 | L28: 0 | M28: 132 | N28: 0 | O28: =SUM(C28:L28,N28) -> 72 | P28: =SUM(C28:N28) -> 204 | R28: 12 Hours | S28: =SUM(S10:S21) -> 2349 | T28: =SUM(T10:T21) -> 650 | U28: =SUM(U10:U21) -> 339 | V28: =SUM(V10:V21) -> 782 | W28: =SUM(W10:W21) -> 58 | X28: =SUM(X10:X21) -> 4 | Y28: =SUM(Y10:Y21) -> 251 | Z28: =SUM(Z10:Z21) -> 133 | ... AF28: =SUM(AF10:AF21) -> 9192
B29: 11.45 - 12.00 | C29: 30 | D29: 6 | E29: 6 | F29: 12 | G29: 0 | H29: 0 | I29: 16 | J29: 6 | K29: 0 | L29: 0 | M29: 113 | N29: 0 | O29: =SUM(C29:L29,N29) -> 76 | P29: =SUM(C29:N29) -> 189
B30: 12.00 - 12.15 | C30: 41 | D30: 11 | E30: 4 | F30: 12 | G30: 0 | H30: 0 | I30: 16 | J30: 3 | K30: 1 | L30: 0 | M30: 109 | N30: 0 | O30: =SUM(C30:L30,N30) -> 88 | P30: =SUM(C30:N30) -> 197
B31: 12.15 - 12.30 | C31: 32 | D31: 12 | E31: 5 | F31: 9 | G31: 1 | H31: 0 | I31: 0 | J31: 5 | K31: 3 | L31: 1 | M31: 101 | N31: 0 | O31: =SUM(C31:L31,N31) -> 68 | P31: =SUM(C31:N31) -> 169
B32: 12.30 - 12.45 | C32: 33 | D32: 8 | E32: 4 | F32: 16 | G32: 0 | H32: 0 | I32: 4 | J32: 5 | K32: 0 | L32: 1 | M32: 69 | N32: 0 | O32: =SUM(C32:L32,N32) -> 71 | P32: =SUM(C32:N32) -> 140
B33: 12.45 - 13.00 | C33: 32 | D33: 11 | E33: 21 | F33: 13 | G33: 3 | H33: 0 | I33: 0 | J33: 10 | K33: 5 | L33: 0 | M33: 77 | N33: 0 | O33: =SUM(C33:L33,N33) -> 95 | P33: =SUM(C33:N33) -> 172
B34: 13.00 - 13.15 | C34: 42 | D34: 14 | E34: 7 | F34: 13 | G34: 0 | H34: 0 | I34: 0 | J34: 9 | K34: 5 | L34: 0 | M34: 97 | N34: 0 | O34: =SUM(C34:L34,N34) -> 90 | P34: =SUM(C34:N34) -> 187
B35: 13.15 - 13.30 | C35: 31 | D35: 12 | E35: 5 | F35: 11 | G35: 0 | H35: 0 | I35: 12 | J35: 3 | K35: 0 | L35: 0 | M35: 94 | N35: 0 | O35: =SUM(C35:L35,N35) -> 74 | P35: =SUM(C35:N35) -> 168
B36: 13.30 - 13.45 | C36: 46 | D36: 4 | E36: 8 | F36: 19 | G36: 0 | H36: 0 | I36: 7 | J36: 4 | K36: 0 | L36: 0 | M36: 106 | N36: 0 | O36: =SUM(C36:L36,N36) -> 88 | P36: =SUM(C36:N36) -> 194
B37: 13.45 - 14.00 | C37: 48 | D37: 7 | E37: 7 | F37: 19 | G37: 0 | H37: 0 | I37: 9 | J37: 5 | K37: 0 | L37: 1 | M37: 97 | N37: 0 | O37: =SUM(C37:L37,N37) -> 96 | P37: =SUM(C37:N37) -> 193
B38: 14.00 - 14.15 | C38: 37 | D38: 18 | E38: 9 | F38: 19 | G38: 0 | H38: 0 | I38: 9 | J38: 2 | K38: 1 | L38: 1 | M38: 78 | N38: 0 | O38: =SUM(C38:L38,N38) -> 96 | P38: =SUM(C38:N38) -> 174
B39: 14.15 - 14.30 | C39: 35 | D39: 13 | E39: 6 | F39: 23 | G39: 0 | H39: 0 | I39: 7 | J39: 6 | K39: 1 | L39: 2 | M39: 85 | N39: 0 | O39: =SUM(C39:L39,N39) -> 93 | P39: =SUM(C39:N39) -> 178
B40: 14.30 - 14.45 | C40: 44 | D40: 10 | E40: 5 | F40: 14 | G40: 0 | H40: 0 | I40: 4 | J40: 3 | K40: 2 | L40: 0 | M40: 92 | N40: 0 | O40: =SUM(C40:L40,N40) -> 82 | P40: =SUM(C40:N40) -> 174
... B57: 18.45 - 19.00 | C57: 80 | D57: 35 | E57: 10 | F57: 38 | G57: 0 | H57: 0 | I57: 5 | J57: 1 | K57: 1 | L57: 0 | M57: 170 | N57: 0 | O57: =SUM(C57:L57,N57) -> 170 | P57: =SUM(C57:N57) -> 340
B58: Totals | C58: =SUM(C10:C57) -> 2349 | D58: =SUM(D10:D57) -> 650 | E58: =SUM(E10:E57) -> 339 | F58: =SUM(F10:F57) -> 782 | G58: =SUM(G10:G57) -> 58 | H58: =SUM(H10:H57) -> 4 | I58: =SUM(I10:I57) -> 251 | J58: =SUM(J10:J57) -> 133 | ... P58: =SUM(P10:P57) -> 9192
...

Sheet 31.07 NAMUGONGO-KIREKA-24h
B1: Consultancy services for Preparation of Expressway Development Master Plan (EDMP) for Uganda
B2: MANUAL CLASSIFIED COUNT (MCC)
B3: ROAD NAME: | C3: ='01.08 NAMUGONGO-KIREKA'!C3:G3 -> MCC - C1 - STN039 - NAMUGONGO ROAD
C5: Date | D5: 31.07.19 | F5: Location | G5: ='03.08 KIREKA-NAMUGONGO-24h'!G5:H5 -> AGENDA | J5: Surveyor | K5: ='03.08 KIREKA-NAMUGONGO-24h'!K5:L5 -> STEVEN
C6: Dir. From | D6: ='01.08 NAMUGONGO-KIREKA'!D6:E6 -> NAMUGONGO | F6: Dir. To | G6: ='01.08 NAMUGONGO-KIREKA'!G6:H6 -> KIREKA | J6: Supervisor | K6: ='03.08 KIREKA-NAMUGONGO-24h'!K6:L6 -> NAIDO GRACE BRENDA
B8: Time / Veh Type | R8: SUMMARY TRAFFIC VOLUMES
C9: 1. Car | D9: 2. Station Wagon | E9: 3. Pickups | F9: 4. Minibus, matatu | G9: 5. Medium bus | H9: 6. Large Bus | I9: 7. Light Truck | J9: 8. Medium Truck | K9: 9. Heavy truck | L9: 10. Truck Trailer | M9: 11. Motor cycles | N9: 12. Tractors | O9: Total Excl M/Cycles | P9: Total All | R9: Time | S9: 1. Car | T9: 2. Station Wagon | U9: 3. Pickups | V9: 4. Minibus, matatu | W9: 5. Medium bus | X9: 6. Large Bus | Y9: 7. Light Truck | Z9: 8. Medium Truck | AA9: 9. Heavy truck | AB9: 10. Truck Trailer | AC9: 11. Motorcycles | AD9: 12. Tractors, Graders | AE9: Total Excl M/ Cycles | AF9: Total All
B10: 07.00 - 07.15 | C10: 52 | D10: 4 | E10: 2 | F10: 12 | G10: 1 | H10: 0 | I10: 0 | J10: 0 | K10: 0 | L10: 0 | M10: 0 | N10: 0 | O10: =SUM(C10:L10,N10) -> 71 | P10: =SUM(C10:N10) -> 71 | R10: 0700-0800 | S10: =SUM(C10:C13) -> 407 | T10: =SUM(D10:D13) -> 34 | U10: =SUM(E10:E13) -> 63 | V10: =SUM(F10:F13) -> 133 | W10: =SUM(G10:G13) -> 2 | X10: =SUM(H10:H13) -> 0 | Y10: =SUM(I10:I13) -> 8 | Z10: =SUM(J10:J13) -> 2 | ... AF10: =SUM(P10:P13) -> 1175
B11: 07.15 - 07.30 | C11: 130 | D11: 9 | E11: 15 | F11: 48 | G11: 1 | H11: 0 | I11: 6 | J11: 0 | K11: 0 | L11: 0 | M11: 155 | N11: 0 | O11: =SUM(C11:L11,N11) -> 209 | P11: =SUM(C11:N11) -> 364 | R11: 0800-0900 | S11: =SUM(C14:C17) -> 407 | T11: =SUM(D14:D17) -> 41 | U11: =SUM(E14:E17) -> 40 | V11: =SUM(F14:F17) -> 95 | W11: =SUM(G14:G17) -> 1 | X11: =SUM(H14:H17) -> 0 | Y11: =SUM(I14:I17) -> 46 | Z11: =SUM(J14:J17) -> 1 | ... AF11: =SUM(P14:P17) -> 1700
B12: 07.30 - 07.45 | C12: 105 | D12: 10 | E12: 23 | F12: 33 | G12: 0 | H12: 0 | I12: 1 | J12: 1 | K12: 0 | L12: 0 | M12: 198 | N12: 0 | O12: =SUM(C12:L12,N12) -> 173 | P12: =SUM(C12:N12) -> 371 | R12: 0900-1000 | S12: =SUM(C18:C21) -> 351 | T12: =SUM(D18:D21) -> 38 | U12: =SUM(E18:E21) -> 36 | V12: =SUM(F18:F21) -> 108 | W12: =SUM(G18:G21) -> 0 | X12: =SUM(H18:H21) -> 0 | Y12: =SUM(I18:I21) -> 27 | Z12: =SUM(J18:J21) -> 5 | ... AF12: =SUM(P18:P21) -> 1118
B13: 07.45 - 08.00 | C13: 120 | D13: 11 | E13: 23 | F13: 40 | G13: 0 | H13: 0 | I13: 1 | J13: 1 | K13: 0 | L13: 0 | M13: 173 | N13: 0 | O13: =SUM(C13:L13,N13) -> 196 | P13: =SUM(C13:N13) -> 369 | R13: 1000-1100 | S13: =SUM(C22:C25) -> 236 | T13: =SUM(D22:D25) -> 33 | U13: =SUM(E22:E25) -> 27 | V13: =SUM(F22:F25) -> 88 | W13: =SUM(G22:G25) -> 3 | X13: =SUM(H22:H25) -> 0 | Y13: =SUM(I22:I25) -> 16 | Z13: =SUM(J22:J25) -> 7 | ... AF13: =SUM(P22:P25) -> 862
B14: 08.00 - 08.15 | C14: 104 | D14: 9 | E14: 9 | F14: 24 | G14: 0 | H14: 0 | I14: 10 | J14: 0 | K14: 1 | L14: 0 | M14: 515 | N14: 0 | O14: =SUM(C14:L14,N14) -> 157 | P14: =SUM(C14:N14) -> 672 | R14: 1100-1200 | S14: =SUM(C26:C29) -> 193 | T14: =SUM(D26:D29) -> 32 | U14: =SUM(E26:E29) -> 34 | V14: =SUM(F26:F29) -> 74 | W14: =SUM(G26:G29) -> 2 | X14: =SUM(H26:H29) -> 0 | Y14: =SUM(I26:I29) -> 29 | Z14: =SUM(J26:J29) -> 6 | ... AF14: =SUM(P26:P29) -> 828
B15: 08.15 - 08.30 | C15: 111 | D15: 7 | E15: 10 | F15: 33 | G15: 1 | H15: 0 | I15: 8 | J15: 1 | K15: 0 | L15: 0 | M15: 213 | N15: 0 | O15: =SUM(C15:L15,N15) -> 171 | P15: =SUM(C15:N15) -> 384 | R15: 1200-1300 | S15: =SUM(C30:C33) -> 217 | T15: =SUM(D30:D33) -> 21 | U15: =SUM(E30:E33) -> 43 | V15: =SUM(F30:F33) -> 54 | W15: =SUM(G30:G33) -> 5 | X15: =SUM(H30:H33) -> 0 | Y15: =SUM(I30:I33) -> 25 | Z15: =SUM(J30:J33) -> 7 | ... AF15: =SUM(P30:P33) -> 798
B16: 08.30 - 08.45 | C16: 90 | D16: 11 | E16: 9 | F16: 26 | G16: 0 | H16: 0 | I16: 2 | J16: 0 | K16: 0 | L16: 0 | M16: 164 | N16: 0 | O16: =SUM(C16:L16,N16) -> 138 | P16: =SUM(C16:N16) -> 302 | R16: 1300-1400 | S16: =SUM(C34:C37) -> 184 | T16: =SUM(D34:D37) -> 18 | U16: =SUM(E34:E37) -> 38 | V16: =SUM(F34:F37) -> 72 | W16: =SUM(G34:G37) -> 1 | X16: =SUM(H34:H37) -> 0 | Y16: =SUM(I34:I37) -> 29 | Z16: =SUM(J34:J37) -> 8 | ... AF16: =SUM(P34:P37) -> 772
B17: 08.45 - 9.00 | C17: 102 | D17: 14 | E17: 12 | F17: 12 | G17: 0 | H17: 0 | I17: 26 | J17: 0 | K17: 0 | L17: 0 | M17: 176 | N17: 0 | O17: =SUM(C17:L17,N17) -> 166 | P17: =SUM(C17:N17) -> 342 | R17: 1400-1500 | S17: =SUM(C38:C41) -> 186 | T17: =SUM(D38:D41) -> 21 | U17: =SUM(E38:E41) -> 25 | V17: =SUM(F38:F41) -> 72 | W17: =SUM(G38:G41) -> 0 | X17: =SUM(H38:H41) -> 1 | Y17: =SUM(I38:I41) -> 21 | Z17: =SUM(J38:J41) -> 6 | ... AF17: =SUM(P38:P41) -> 1061
B18: 09.00 - 09.15 | C18: 75 | D18: 14 | E18: 14 | F18: 29 | G18: 0 | H18: 0 | I18: 9 | J18: 0 | K18: 0 | L18: 0 | M18: 133 | N18: 0 | O18: =SUM(C18:L18,N18) -> 141 | P18: =SUM(C18:N18) -> 274 | R18: 1500-1600 | S18: =SUM(C42:C45) -> 149 | T18: =SUM(D42:D45) -> 13 | U18: =SUM(E42:E45) -> 44 | V18: =SUM(F42:F45) -> 60 | W18: =SUM(G42:G45) -> 3 | X18: =SUM(H42:H45) -> 0 | Y18: =SUM(I42:I45) -> 32 | Z18: =SUM(J42:J45) -> 13 | ... AF18: =SUM(P42:P45) -> 723
B19: 09.15 - 09.30 | C19: 96 | D19: 6 | E19: 5 | F19: 27 | G19: 0 | H19: 0 | I19: 4 | J19: 5 | K19: 1 | L19: 1 | M19: 156 | N19: 0 | O19: =SUM(C19:L19,N19) -> 145 | P19: =SUM(C19:N19) -> 301 | R19: 1600-1700 | S19: =SUM(C46:C49) -> 167 | T19: =SUM(D46:D49) -> 15 | U19: =SUM(E46:E49) -> 24 | V19: =SUM(F46:F49) -> 98 | W19: =SUM(G46:G49) -> 4 | X19: =SUM(H46:H49) -> 0 | Y19: =SUM(I46:I49) -> 31 | Z19: =SUM(J46:J49) -> 9 | ... AF19: =SUM(P46:P49) -> 836
B20: 09.30 - 09.45 | C20: 100 | D20: 11 | E20: 9 | F20: 27 | G20: 0 | H20: 0 | I20: 4 | J20: 0 | K20: 0 | L20: 0 | M20: 145 | N20: 0 | O20: =SUM(C20:L20,N20) -> 151 | P20: =SUM(C20:N20) -> 296 | R20: 1700-1800 | S20: =SUM(C50:C53) -> 203 | T20: =SUM(D50:D53) -> 26 | U20: =SUM(E50:E53) -> 34 | V20: =SUM(F50:F53) -> 81 | W20: =SUM(G50:G53) -> 3 | X20: =SUM(H50:H53) -> 0 | Y20: =SUM(I50:I53) -> 17 | Z20: =SUM(J50:J53) -> 12 | ... AF20: =SUM(P50:P53) -> 884
B21: 09.45 - 10.00 | C21: 80 | D21: 7 | E21: 8 | F21: 25 | G21: 0 | H21: 0 | I21: 10 | J21: 0 | K21: 0 | L21: 0 | M21: 117 | N21: 0 | O21: =SUM(C21:L21,N21) -> 130 | P21: =SUM(C21:N21) -> 247 | R21: 1800-1900 | S21: =SUM(C54:C57) -> 204 | T21: =SUM(D54:D57) -> 23 | U21: =SUM(E54:E57) -> 38 | V21: =SUM(F54:F57) -> 64 | W21: =SUM(G54:G57) -> 4 | X21: =SUM(H54:H57) -> 0 | Y21: =SUM(I54:I57) -> 14 | Z21: =SUM(J54:J57) -> 11 | ... AF21: =SUM(P54:P57) -> 937
B22: 10.00 - 10.15 | C22: 78 | D22: 12 | E22: 8 | F22: 23 | G22: 0 | H22: 0 | I22: 5 | J22: 0 | K22: 1 | L22: 0 | M22: 108 | N22: 0 | O22: =SUM(C22:L22,N22) -> 127 | P22: =SUM(C22:N22) -> 235 | R22: 1900-2000 | S22: =SUM(C58:C61) -> 0 | T22: =SUM(D58:D61) -> 0 | U22: =SUM(E58:E61) -> 0 | V22: =SUM(F58:F61) -> 0 | W22: =SUM(G58:G61) -> 0 | X22: =SUM(H58:H61) -> 0 | Y22: =SUM(I58:I61) -> 0 | Z22: =SUM(J58:J61) -> 0 | ... AF22: =SUM(P58:P61) -> 0
B23: 10.15 - 10.30 | C23: 57 | D23: 4 | E23: 9 | F23: 28 | G23: 2 | H23: 0 | I23: 4 | J23: 3 | K23: 1 | L23: 0 | M23: 133 | N23: 0 | O23: =SUM(C23:L23,N23) -> 108 | P23: =SUM(C23:N23) -> 241 | R23: 2000-2100 | S23: =SUM(C62:C65) -> 0 | T23: =SUM(D62:D65) -> 0 | U23: =SUM(E62:E65) -> 0 | V23: =SUM(F62:F65) -> 0 | W23: =SUM(G62:G65) -> 0 | X23: =SUM(H62:H65) -> 0 | Y23: =SUM(I62:I65) -> 0 | Z23: =SUM(J62:J65) -> 0 | ... AF23: =SUM(P62:P65) -> 0
B24: 10.30 - 10.45 | C24: 51 | D24: 10 | E24: 5 | F24: 16 | G24: 0 | H24: 0 | I24: 0 | J24: 4 | K24: 1 | L24: 1 | M24: 106 | N24: 0 | O24: =SUM(C24:L24,N24) -> 88 | P24: =SUM(C24:N24) -> 194 | R24: 2100-2200 | S24: =SUM(C66:C69) -> 0 | T24: =SUM(D66:D69) -> 0 | U24: =SUM(E66:E69) -> 0 | V24: =SUM(F66:F69) -> 0 | W24: =SUM(G66:G69) -> 0 | X24: =SUM(H66:H69) -> 0 | Y24: =SUM(I66:I69) -> 0 | Z24: =SUM(J66:J69) -> 0 | ... AF24: =SUM(P66:P69) -> 0
B25: 10.45 - 11.00 | C25: 50 | D25: 7 | E25: 5 | F25: 21 | G25: 1 | H25: 0 | I25: 7 | J25: 0 | K25: 3 | L25: 0 | M25: 98 | N25: 0 | O25: =SUM(C25:L25,N25) -> 94 | P25: =SUM(C25:N25) -> 192 | R25: 2200-2300 | S25: =SUM(C70:C73) -> 0 | T25: =SUM(D70:D73) -> 0 | U25: =SUM(E70:E73) -> 0 | V25: =SUM(F70:F73) -> 0 | W25: =SUM(G70:G73) -> 0 | X25: =SUM(H70:H73) -> 0 | Y25: =SUM(I70:I73) -> 0 | Z25: =SUM(J70:J73) -> 0 | ... AF25: =SUM(P70:P73) -> 0
B26: 11.00 - 11.15 | C26: 60 | D26: 15 | E26: 8 | F26: 17 | G26: 2 | H26: 0 | I26: 2 | J26: 2 | K26: 2 | L26: 1 | M26: 110 | N26: 0 | O26: =SUM(C26:L26,N26) -> 109 | P26: =SUM(C26:N26) -> 219 | R26: 2300-0000 | S26: =SUM(C74:C77) -> 0 | T26: =SUM(D74:D77) -> 0 | U26: =SUM(E74:E77) -> 0 | V26: =SUM(F74:F77) -> 0 | W26: =SUM(G74:G77) -> 0 | X26: =SUM(H74:H77) -> 0 | Y26: =SUM(I74:I77) -> 0 | Z26: =SUM(J74:J77) -> 0 | ... AF26: =SUM(P74:P77) -> 0
