Workbook

Sheet 17.10 KAYUNGA-GALIRAYA
B1: Consultancy services for Preparation of Expressway Development Master Plan (EDMP) for Uganda
B2: MANUAL CLASSIFIED COUNT (MCC)
B3: ROAD NAME: | C3: MCC - C3 - STN89 - GALIRAYA ROAD
C5: Date | D5: 17.10.19 | F5: Location | G5: KYANYA | J5: Surveyor | K5: NAKIWUGE
C6: Dir. From | D6: KAYUNGA | F6: Dir. To | G6: GALIRAYA | J6: Supervisor | K6: GODFREY
B8: Time / Veh Type | R8: SUMMARY TRAFFIC VOLUMES
C9: 1. Car | D9: 2. Station Wagon | E9: 3. Pickups | F9: 4. Minibus, matatu | G9: 5. Medium bus | H9: 6. Large Bus | I9: 7. Light Truck | J9: 8. Medium Truck | K9: 9. Heavy truck | L9: 10. Truck Trailer | M9: 11. Motor cycles | N9: 12. Tractors | O9: Total Excl M/Cycles | P9: Total All | R9: Time | S9: 1. Car | T9: 2. Station Wagon | U9: 3. Pickups | V9: 4. Minibus, matatu | W9: 5. Medium bus | X9: 6. Large Bus | Y9: 7. Light Truck | Z9: 8. Medium Truck | AA9: 9. Heavy truck | AB9: 10. Truck Trailer | AC9: 11. Motorcycles | AD9: 12. Tractors, Graders | AE9: Total Excl M/ Cycles | AF9: Total All
B10: 07.00 - 07.15 | C10: 1 | D10: 0 | E10: 1 | F10: 1 | G10: 1 | H10: 0 | I10: 2 | J10: 0 | K10: 2 | L10: 0 | M10: 3 | N10: 0 | O10: =SUM(C10:L10,N10) -> 8 | P10: =SUM(C10:N10) -> 11 | R10: 0700-0800 | S10: =SUM(C10:C13) -> 4 | T10: =SUM(D10:D13) -> 0 | U10: =SUM(E10:E13) -> 4 | V10: =SUM(F10:F13) -> 1 | W10: =SUM(G10:G13) -> 1 | X10: =SUM(H10:H13) -> 0 | Y10: =SUM(I10:I13) -> 11 | Z10: =SUM(J10:J13) -> 1 | ... AF10: =SUM(P10:P13) -> 47
B11: 07.15 - 07.30 | C11: 0 | D11: 0 | E11: 1 | F11: 0 | G11: 0 | H11: 0 | I11: 3 | J11: 1 | K11: 2 | L11: 0 | M11: 2 | N11: 0 | O11: =SUM(C11:L11,N11) -> 7 | P11: =SUM(C11:N11) -> 9 | R11: 0800-0900 | S11: =SUM(C14:C17) -> 2 | T11: =SUM(D14:D17) -> 0 | U11: =SUM(E14:E17) -> 2 | V11: =SUM(F14:F17) -> 3 | W11: =SUM(G14:G17) -> 0 | X11: =SUM(H14:H17) -> 1 | Y11: =SUM(I14:I17) -> 6 | Z11: =SUM(J14:J17) -> 0 | ... AF11: =SUM(P14:P17) -> 64
B12: 07.30 - 07.45 | C12: 3 | D12: 0 | E12: 0 | F12: 0 | G12: 0 | H12: 0 | I12: 4 | J12: 0 | K12: 2 | L12: 0 | M12: 5 | N12: 0 | O12: =SUM(C12:L12,N12) -> 9 | P12: =SUM(C12:N12) -> 14 | R12: 0900-1000 | S12: =SUM(C18:C21) -> 4 | T12: =SUM(D18:D21) -> 2 | U12: =SUM(E18:E21) -> 3 | V12: =SUM(F18:F21) -> 6 | W12: =SUM(G18:G21) -> 0 | X12: =SUM(H18:H21) -> 0 | Y12: =SUM(I18:I21) -> 3 | Z12: =SUM(J18:J21) -> 4 | ... AF12: =SUM(P18:P21) -> 54
B13: 07.45 - 08.00 | C13: 0 | D13: 0 | E13: 2 | F13: 0 | G13: 0 | H13: 0 | I13: 2 | J13: 0 | K13: 0 | L13: 0 | M13: 9 | N13: 0 | O13: =SUM(C13:L13,N13) -> 4 | P13: =SUM(C13:N13) -> 13 | R13: 1000-1100 | S13: =SUM(C22:C25) -> 1 | T13: =SUM(D22:D25) -> 2 | U13: =SUM(E22:E25) -> 3 | V13: =SUM(F22:F25) -> 5 | W13: =SUM(G22:G25) -> 0 | X13: =SUM(H22:H25) -> 0 | Y13: =SUM(I22:I25) -> 6 | Z13: =SUM(J22:J25) -> 2 | ... AF13: =SUM(P22:P25) -> 75
B14: 08.00 - 08.15 | C14: 1 | D14: 0 | E14: 0 | F14: 0 | G14: 0 | H14: 0 | I14: 0 | J14: 0 | K14: 0 | L14: 0 | M14: 14 | N14: 0 | O14: =SUM(C14:L14,N14) -> 1 | P14: =SUM(C14:N14) -> 15 | R14: 1100-1200 | S14: =SUM(C26:C29) -> 8 | T14: =SUM(D26:D29) -> 1 | U14: =SUM(E26:E29) -> 1 | V14: =SUM(F26:F29) -> 5 | W14: =SUM(G26:G29) -> 0 | X14: =SUM(H26:H29) -> 0 | Y14: =SUM(I26:I29) -> 2 | Z14: =SUM(J26:J29) -> 0 | ... AF14: =SUM(P26:P29) -> 74
B15: 08.15 - 08.30 | C15: 0 | D15: 0 | E15: 0 | F15: 1 | G15: 0 | H15: 0 | I15: 2 | J15: 0 | K15: 1 | L15: 0 | M15: 8 | N15: 8 | O15: =SUM(C15:L15,N15) -> 12 | P15: =SUM(C15:N15) -> 20 | R15: 1200-1300 | S15: =SUM(C30:C33) -> 3 | T15: =SUM(D30:D33) -> 2 | U15: =SUM(E30:E33) -> 1 | V15: =SUM(F30:F33) -> 8 | W15: =SUM(G30:G33) -> 0 | X15: =SUM(H30:H33) -> 0 | Y15: =SUM(I30:I33) -> 4 | Z15: =SUM(J30:J33) -> 0 | ... AF15: =SUM(P30:P33) -> 77
B16: 08.30 - 08.45 | C16: 0 | D16: 0 | E16: 1 | F16: 2 | G16: 0 | H16: 1 | I16: 2 | J16: 0 | K16: 0 | L16: 0 | M16: 8 | N16: 0 | O16: =SUM(C16:L16,N16) -> 6 | P16: =SUM(C16:N16) -> 14 | R16: 1300-1400 | S16: =SUM(C34:C37) -> 7 | T16: =SUM(D34:D37) -> 0 | U16: =SUM(E34:E37) -> 2 | V16: =SUM(F34:F37) -> 10 | W16: =SUM(G34:G37) -> 2 | X16: =SUM(H34:H37) -> 0 | Y16: =SUM(I34:I37) -> 2 | Z16: =SUM(J34:J37) -> 4 | ... AF16: =SUM(P34:P37) -> 58
B17: 08.45 - 9.00 | C17: 1 | D17: 0 | E17: 1 | F17: 0 | G17: 0 | H17: 0 | I17: 2 | J17: 0 | K17: 0 | L17: 0 | M17: 11 | N17: 0 | O17: =SUM(C17:L17,N17) -> 4 | P17: =SUM(C17:N17) -> 15 | R17: 1400-1500 | S17: =SUM(C38:C41) -> 3 | T17: =SUM(D38:D41) -> 0 | U17: =SUM(E38:E41) -> 0 | V17: =SUM(F38:F41) -> 3 | W17: =SUM(G38:G41) -> 2 | X17: =SUM(H38:H41) -> 1 | Y17: =SUM(I38:I41) -> 3 | Z17: =SUM(J38:J41) -> 2 | ... AF17: =SUM(P38:P41) -> 53
B18: 09.00 - 09.15 | C18: 2 | D18: 1 | E18: 0 | F18: 0 | G18: 0 | H18: 0 | I18: 0 | J18: 1 | K18: 0 | L18: 0 | M18: 8 | N18: 0 | O18: =SUM(C18:L18,N18) -> 4 | P18: =SUM(C18:N18) -> 12 | R18: 1500-1600 | S18: =SUM(C42:C45) -> 7 | T18: =SUM(D42:D45) -> 1 | U18: =SUM(E42:E45) -> 2 | V18: =SUM(F42:F45) -> 4 | W18: =SUM(G42:G45) -> 0 | X18: =SUM(H42:H45) -> 1 | Y18: =SUM(I42:I45) -> 5 | Z18: =SUM(J42:J45) -> 2 | ... AF18: =SUM(P42:P45) -> 59
B19: 09.15 - 09.30 | C19: 1 | D19: 1 | E19: 0 | F19: 3 | G19: 0 | H19: 0 | I19: 2 | J19: 2 | K19: 1 | L19: 0 | M19: 11 | N19: 0 | O19: =SUM(C19:L19,N19) -> 10 | P19: =SUM(C19:N19) -> 21 | R19: 1600-1700 | S19: =SUM(C46:C49) -> 2 | T19: =SUM(D46:D49) -> 0 | U19: =SUM(E46:E49) -> 1 | V19: =SUM(F46:F49) -> 9 | W19: =SUM(G46:G49) -> 1 | X19: =SUM(H46:H49) -> 0 | Y19: =SUM(I46:I49) -> 4 | Z19: =SUM(J46:J49) -> 1 | ... AF19: =SUM(P46:P49) -> 53
B20: 09.30 - 09.45 | C20: 1 | D20: 0 | E20: 0 | F20: 0 | G20: 0 | H20: 0 | I20: 1 | J20: 1 | K20: 0 | L20: 0 | M20: 6 | N20: 0 | O20: =SUM(C20:L20,N20) -> 3 | P20: =SUM(C20:N20) -> 9 | R20: 1700-1800 | S20: =SUM(C50:C53) -> 2 | T20: =SUM(D50:D53) -> 0 | U20: =SUM(E50:E53) -> 1 | V20: =SUM(F50:F53) -> 6 | W20: =SUM(G50:G53) -> 1 | X20: =SUM(H50:H53) -> 0 | Y20: =SUM(I50:I53) -> 2 | Z20: =SUM(J50:J53) -> 1 | ... AF20: =SUM(P50:P53) -> 60
B21: 09.45 - 10.00 | C21: 0 | D21: 0 | E21: 3 | F21: 3 | G21: 0 | H21: 0 | I21: 0 | J21: 0 | K21: 0 | L21: 0 | M21: 6 | N21: 0 | O21: =SUM(C21:L21,N21) -> 6 | P21: =SUM(C21:N21) -> 12 | R21: 1800-1900 | S21: =SUM(C54:C57) -> 3 | T21: =SUM(D54:D57) -> 0 | U21: =SUM(E54:E57) -> 3 | V21: =SUM(F54:F57) -> 5 | W21: =SUM(G54:G57) -> 0 | X21: =SUM(H54:H57) -> 0 | Y21: =SUM(I54:I57) -> 1 | Z21: =SUM(J54:J57) -> 1 | ... AF21: =SUM(P54:P57) -> 82
B22: 10.00 - 10.15 | C22: 0 | D22: 1 | E22: 0 | F22: 0 | G22: 0 | H22: 0 | I22: 3 | J22: 0 | K22: 1 | L22: 0 | M22: 14 | N22: 0 | O22: =SUM(C22:L22,N22) -> 5 | P22: =SUM(C22:N22) -> 19 | R22: AM Peak Hr | S22: =MAX(S10:S12) -> 4 | T22: =MAX(T10:T12) -> 2 | U22: =MAX(U10:U12) -> 4 | V22: =MAX(V10:V12) -> 6 | W22: =MAX(W10:W12) -> 1 | X22: =MAX(X10:X12) -> 1 | Y22: =MAX(Y10:Y12) -> 11 | Z22: =MAX(Z10:Z12) -> 4 | ... AF22: =MAX(AF10:AF12) -> 64
B23: 10.15 - 10.30 | C23: 1 | D23: 0 | E23: 0 | F23: 1 | G23: 0 | H23: 0 | I23: 1 | J23: 0 | K23: 1 | L23: 0 | M23: 16 | N23: 0 | O23: =SUM(C23:L23,N23) -> 4 | P23: =SUM(C23:N23) -> 20 | R23: IP Peak Hr | S23: =MAX(S13:S18) -> 8 | T23: =MAX(T13:T18) -> 2 | U23: =MAX(U13:U18) -> 3 | V23: =MAX(V13:V18) -> 10 | W23: =MAX(W13:W18) -> 2 | X23: =MAX(X13:X18) -> 1 | Y23: =MAX(Y13:Y18) -> 6 | Z23: =MAX(Z13:Z18) -> 4 | ... AF23: =MAX(AF13:AF18) -> 77
B24: 10.30 - 10.45 | C24: 0 | D24: 0 | E24: 1 | F24: 1 | G24: 0 | H24: 0 | I24: 0 | J24: 0 | K24: 0 | L24: 0 | M24: 10 | N24: 0 | O24: =SUM(C24:L24,N24) -> 2 | P24: =SUM(C24:N24) -> 12 | R24: PM Peak Hr | S24: =MAX(S19:S21) -> 3 | T24: =MAX(T19:T21) -> 0 | U24: =MAX(U19:U21) -> 3 | V24: =MAX(V19:V21) -> 9 | W24: =MAX(W19:W21) -> 1 | X24: =MAX(X19:X21) -> 0 | Y24: =MAX(Y19:Y21) -> 4 | Z24: =MAX(Z19:Z21) -> 1 | ... AF24: =MAX(AF19:AF21) -> 82
B25: 10.45 - 11.00 | C25: 0 | D25: 1 | E25: 2 | F25: 3 | G25: 0 | H25: 0 | I25: 2 | J25: 2 | K25: 0 | L25: 0 | M25: 14 | N25: 0 | O25: =SUM(C25:L25,N25) -> 10 | P25: =SUM(C25:N25) -> 24 | R25: AM Period | S25: =SUM(S10:S12) -> 10 | T25: =SUM(T10:T12) -> 2 | U25: =SUM(U10:U12) -> 9 | V25: =SUM(V10:V12) -> 10 | W25: =SUM(W10:W12) -> 1 | X25: =SUM(X10:X12) -> 1 | Y25: =SUM(Y10:Y12) -> 20 | Z25: =SUM(Z10:Z12) -> 5 | ... AF25: =SUM(AF10:AF12) -> 165
B26: 11.00 - 11.15 | C26: 1 | D26: 0 | E26: 1 | F26: 1 | G26: 0 | H26: 0 | I26: 2 | J26: 0 | K26: 0 | L26: 0 | M26: 12 | N26: 0 | O26: =SUM(C26:L26,N26) -> 5 | P26: =SUM(C26:N26) -> 17 | R26: IP Period | S26: =SUM(S13:S18) -> 29 | T26: =SUM(T13:T18) -> 6 | U26: =SUM(U13:U18) -> 9 | V26: =SUM(V13:V18) -> 35 | W26: =SUM(W13:W18) -> 4 | X26: =SUM(X13:X18) -> 2 | Y26: =SUM(Y13:Y18) -> 22 | Z26: =SUM(Z13:Z18) -> 10 | ... AF26: =SUM(AF13:AF18) -> 396
B27: 11.15 - 11.30 | C27: 2 | D27: 0 | E27: 0 | F27: 2 | G27: 0 | H27: 0 | I27: 0 | J27: 0 | K27: 0 | L27: 0 | M27: 21 | N27: 0 | O27: =SUM(C27:L27,N27) -> 4 | P27: =SUM(C27:N27) -> 25 | R27: PM Period | S27: =SUM(S19:S21) -> 7 | T27: =SUM(T19:T21) -> 0 | U27: =SUM(U19:U21) -> 5 | V27: =SUM(V19:V21) -> 20 | W27: =SUM(W19:W21) -> 2 | X27: =SUM(X19:X21) -> 0 | Y27: =SUM(Y19:Y21) -> 7 | Z27: =SUM(Z19:Z21) -> 3 | ... AF27: =SUM(AF19:AF21) -> 195
B28: 11.30 - 11.45 | C28: 4 | D28: 1 | E28: 0 | F28: 2 | G28: 0 | H28: 0 | I28: 0 | J28: 0 | K28: 0 | L28: 0 | M28: 16 | N28: 0 | O28: =SUM(C28:L28,N28) -> 7 | P28: =SUM(C28:N28) -> 23 | R28: 12 Hours | S28: =SUM(S10:S21) -> 46 | T28: =SUM(T10:T21) -> 8 | U28: =SUM(U10:U21) -> 23 | V28: =SUM(V10:V21) -> 65 | W28: =SUM(W10:W21) -> 7 | X28: =SUM(X10:X21) -> 3 | Y28: =SUM(Y10:Y21) -> 49 | Z28: =SUM(Z10:Z21) -> 18 | ... AF28: =SUM(AF10:AF21) -> 756
B29: 11.45 - 12.00 | C29: 1 | D29: 0 | E29: 0 | F29: 0 | G29: 0 | H29: 0 | I29: 0 | J29: 0 | K29: 0 | L29: 0 | M29: 8 | N29: 0 | O29: =SUM(C29:L29,N29) -> 1 | P29: =SUM(C29:N29) -> 9
B30: 12.00 - 12.15 | C30: 0 | D30: 1 | E30: 0 | F30: 3 | G30: 0 | H30: 0 | I30: 0 | J30: 0 | K30: 0 | L30: 0 | M30: 14 | N30: 0 | O30: =SUM(C30:L30,N30) -> 4 | P30: =SUM(C30:N30) -> 18
B31: 12.15 - 12.30 | C31: 0 | D31: 0 | E31: 0 | F31: 0 | G31: 0 | H31: 0 | I31: 2 | J31: 0 | K31: 0 | L31: 0 | M31: 7 | N31: 0 | O31: =SUM(C31:L31,N31) -> 2 | P31: =SUM(C31:N31) -> 9
B32: 12.30 - 12.45 | C32: 0 | D32: 1 | E32: 1 | F32: 2 | G32: 0 | H32: 0 | I32: 1 | J32: 0 | K32: 0 | L32: 0 | M32: 17 | N32: 0 | O32: =SUM(C32:L32,N32) -> 5 | P32: =SUM(C32:N32) -> 22
B33: 12.45 - 13.00 | C33: 3 | D33: 0 | E33: 0 | F33: 3 | G33: 0 | H33: 0 | I33: 1 | J33: 0 | K33: 1 | L33: 0 | M33: 20 | N33: 0 | O33: =SUM(C33:L33,N33) -> 8 | P33: =SUM(C33:N33) -> 28
B34: 13.00 - 13.15 | C34: 0 | D34: 0 | E34: 0 | F34: 1 | G34: 0 | H34: 0 | I34: 0 | J34: 2 | K34: 0 | L34: 0 | M34: 7 | N34: 0 | O34: =SUM(C34:L34,N34) -> 3 | P34: =SUM(C34:N34) -> 10
B35: 13.15 - 13.30 | C35: 0 | D35: 0 | E35: 0 | F35: 3 | G35: 0 | H35: 0 | I35: 0 | J35: 0 | K35: 0 | L35: 0 | M35: 8 | N35: 0 | O35: =SUM(C35:L35,N35) -> 3 | P35: =SUM(C35:N35) -> 11
B36: 13.30 - 13.45 | C36: 6 | D36: 0 | E36: 1 | F36: 3 | G36: 1 | H36: 0 | I36: 1 | J36: 2 | K36: 0 | L36: 0 | M36: 8 | N36: 0 | O36: =SUM(C36:L36,N36) -> 14 | P36: =SUM(C36:N36) -> 22
B37: 13.45 - 14.00 | C37: 1 | D37: 0 | E37: 1 | F37: 3 | G37: 1 | H37: 0 | I37: 1 | J37: 0 | K37: 0 | L37: 0 | M37: 8 | N37: 0 | O37: =SUM(C37:L37,N37) -> 7 | P37: =SUM(C37:N37) -> 15
B38: 14.00 - 14.15 | C38: 1 | D38: 0 | E38: 0 | F38: 2 | G38: 1 | H38: 0 | I38: 1 | J38: 0 | K38: 0 | L38: 0 | M38: 12 | N38: 0 | O38: =SUM(C38:L38,N38) -> 5 | P38: =SUM(C38:N38) -> 17
B39: 14.15 - 14.30 | C39: 0 | D39: 0 | E39: 0 | F39: 0 | G39: 0 | H39: 0 | I39: 0 | J39: 2 | K39: 0 | L39: 0 | M39: 7 | N39: 0 | O39: =SUM(C39:L39,N39) -> 2 | P39: =SUM(C39:N39) -> 9
B40: 14.30 - 14.45 | C40: 0 | D40: 0 | E40: 0 | F40: 0 | G40: 0 | H40: 1 | I40: 0 | J40: 0 | K40: 0 | L40: 0 | M40: 10 | N40: 1 | O40: =SUM(C40:L40,N40) -> 2 | P40: =SUM(C40:N40) -> 12
... B57: 18.45 - 19.00 | C57: 0 | D57: 0 | E57: 0 | F57: 1 | G57: 0 | H57: 0 | I57: 1 | J57: 1 | K57: 0 | L57: 0 | M57: 19 | N57: 0 | O57: =SUM(C57:L57,N57) -> 3 | P57: =SUM(C57:N57) -> 22
B58: Totals | C58: =SUM(C10:C57) -> 46 | D58: =SUM(D10:D57) -> 8 | E58: =SUM(E10:E57) -> 23 | F58: =SUM(F10:F57) -> 65 | G58: =SUM(G10:G57) -> 7 | H58: =SUM(H10:H57) -> 3 | I58: =SUM(I10:I57) -> 49 | J58: =SUM(J10:J57) -> 18 | ... P58: =SUM(P10:P57) -> 756
...

Sheet 17.10 GALIRAYA-KAYUNGA
B1: Consultancy services for Preparation of Expressway Development Master Plan (EDMP) for Uganda
B2: MANUAL CLASSIFIED COUNT (MCC)
B3: ROAD NAME: | C3: ='17.10 KAYUNGA-GALIRAYA'!C3:G3 -> MCC - C3 - STN89 - GALIRAYA ROAD
C5: Date | D5: ='17.10 KAYUNGA-GALIRAYA'!D5 -> 17.10.19 | F5: Location | G5: ='17.10 KAYUNGA-GALIRAYA'!G5:H5 -> KYANYA | J5: Surveyor | K5: SEBULIBA GODFREY
C6: Dir. From | D6: GALIRAYA | F6: Dir. To | G6: KAYUNGA | J6: Supervisor | K6: ='17.10 KAYUNGA-GALIRAYA'!K6:L6 -> GODFREY
B8: Time / Veh Type | R8: SUMMARY TRAFFIC VOLUMES
C9: 1. Car | D9: 2. Station Wagon | E9: 3. Pickups | F9: 4. Minibus, matatu | G9: 5. Medium bus | H9: 6. Large Bus | I9: 7. Light Truck | J9: 8. Medium Truck | K9: 9. Heavy truck | L9: 10. Truck Trailer | M9: 11. Motor cycles | N9: 12. Tractors | O9: Total Excl M/Cycles | P9: Total All | R9: Time | S9: 1. Car | T9: 2. Station Wagon | U9: 3. Pickups | V9: 4. Minibus, matatu | W9: 5. Medium bus | X9: 6. Large Bus | Y9: 7. Light Truck | Z9: 8. Medium Truck | AA9: 9. Heavy truck | AB9: 10. Truck Trailer | AC9: 11. Motorcycles | AD9: 12. Tractors, Graders | AE9: Total Excl M/ Cycles | AF9: Total All
B10: 07.00 - 07.15 | C10: 0 | D10: 0 | E10: 0 | F10: 0 | G10: 0 | H10: 0 | I10: 0 | J10: 1 | K10: 0 | L10: 0 | M10: 0 | N10: 0 | O10: =SUM(C10:L10,N10) -> 1 | P10: =SUM(C10:N10) -> 1 | R10: 0700-0800 | S10: =SUM(C10:C13) -> 1 | T10: =SUM(D10:D13) -> 1 | U10: =SUM(E10:E13) -> 0 | V10: =SUM(F10:F13) -> 4 | W10: =SUM(G10:G13) -> 0 | X10: =SUM(H10:H13) -> 0 | Y10: =SUM(I10:I13) -> 0 | Z10: =SUM(J10:J13) -> 2 | ... AF10: =SUM(P10:P13) -> 15
B11: 07.15 - 07.30 | C11: 1 | D11: 1 | E11: 0 | F11: 0 | G11: 0 | H11: 0 | I11: 0 | J11: 1 | K11: 0 | L11: 0 | M11: 3 | N11: 0 | O11: =SUM(C11:L11,N11) -> 3 | P11: =SUM(C11:N11) -> 6 | R11: 0800-0900 | S11: =SUM(C14:C17) -> 2 | T11: =SUM(D14:D17) -> 0 | U11: =SUM(E14:E17) -> 0 | V11: =SUM(F14:F17) -> 3 | W11: =SUM(G14:G17) -> 1 | X11: =SUM(H14:H17) -> 0 | Y11: =SUM(I14:I17) -> 1 | Z11: =SUM(J14:J17) -> 0 | ... AF11: =SUM(P14:P17) -> 32
B12: 07.30 - 07.45 | C12: 0 | D12: 0 | E12: 0 | F12: 2 | G12: 0 | H12: 0 | I12: 0 | J12: 0 | K12: 0 | L12: 0 | M12: 0 | N12: 0 | O12: =SUM(C12:L12,N12) -> 2 | P12: =SUM(C12:N12) -> 2 | R12: 0900-1000 | S12: =SUM(C18:C21) -> 1 | T12: =SUM(D18:D21) -> 0 | U12: =SUM(E18:E21) -> 0 | V12: =SUM(F18:F21) -> 4 | W12: =SUM(G18:G21) -> 0 | X12: =SUM(H18:H21) -> 1 | Y12: =SUM(I18:I21) -> 2 | Z12: =SUM(J18:J21) -> 0 | ... AF12: =SUM(P18:P21) -> 28
B13: 07.45 - 08.00 | C13: 0 | D13: 0 | E13: 0 | F13: 2 | G13: 0 | H13: 0 | I13: 0 | J13: 0 | K13: 1 | L13: 0 | M13: 3 | N13: 0 | O13: =SUM(C13:L13,N13) -> 3 | P13: =SUM(C13:N13) -> 6 | R13: 1000-1100 | S13: =SUM(C22:C25) -> 4 | T13: =SUM(D22:D25) -> 0 | U13: =SUM(E22:E25) -> 2 | V13: =SUM(F22:F25) -> 1 | W13: =SUM(G22:G25) -> 0 | X13: =SUM(H22:H25) -> 0 | Y13: =SUM(I22:I25) -> 0 | Z13: =SUM(J22:J25) -> 0 | ... AF13: =SUM(P22:P25) -> 36
B14: 08.00 - 08.15 | C14: 1 | D14: 0 | E14: 0 | F14: 0 | G14: 1 | H14: 0 | I14: 1 | J14: 0 | K14: 0 | L14: 0 | M14: 7 | N14: 0 | O14: =SUM(C14:L14,N14) -> 3 | P14: =SUM(C14:N14) -> 10 | R14: 1100-1200 | S14: =SUM(C26:C29) -> 0 | T14: =SUM(D26:D29) -> 0 | U14: =SUM(E26:E29) -> 0 | V14: =SUM(F26:F29) -> 4 | W14: =SUM(G26:G29) -> 0 | X14: =SUM(H26:H29) -> 0 | Y14: =SUM(I26:I29) -> 1 | Z14: =SUM(J26:J29) -> 0 | ... AF14: =SUM(P26:P29) -> 58
B15: 08.15 - 08.30 | C15: 0 | D15: 0 | E15: 0 | F15: 0 | G15: 0 | H15: 0 | I15: 0 | J15: 0 | K15: 0 | L15: 0 | M15: 2 | N15: 0 | O15: =SUM(C15:L15,N15) -> 0 | P15: =SUM(C15:N15) -> 2 | R15: 1200-1300 | S15: =SUM(C30:C33) -> 3 | T15: =SUM(D30:D33) -> 1 | U15: =SUM(E30:E33) -> 0 | V15: =SUM(F30:F33) -> 3 | W15: =SUM(G30:G33) -> 0 | X15: =SUM(H30:H33) -> 1 | Y15: =SUM(I30:I33) -> 2 | Z15: =SUM(J30:J33) -> 1 | ... AF15: =SUM(P30:P33) -> 64
B16: 08.30 - 08.45 | C16: 0 | D16: 0 | E16: 0 | F16: 3 | G16: 0 | H16: 0 | I16: 0 | J16: 0 | K16: 0 | L16: 0 | M16: 4 | N16: 0 | O16: =SUM(C16:L16,N16) -> 3 | P16: =SUM(C16:N16) -> 7 | R16: 1300-1400 | S16: =SUM(C34:C37) -> 1 | T16: =SUM(D34:D37) -> 0 | U16: =SUM(E34:E37) -> 3 | V16: =SUM(F34:F37) -> 4 | W16: =SUM(G34:G37) -> 1 | X16: =SUM(H34:H37) -> 0 | Y16: =SUM(I34:I37) -> 2 | Z16: =SUM(J34:J37) -> 0 | ... AF16: =SUM(P34:P37) -> 49
B17: 08.45 - 9.00 | C17: 1 | D17: 0 | E17: 0 | F17: 0 | G17: 0 | H17: 0 | I17: 0 | J17: 0 | K17: 0 | L17: 0 | M17: 12 | N17: 0 | O17: =SUM(C17:L17,N17) -> 1 | P17: =SUM(C17:N17) -> 13 | R17: 1400-1500 | S17: =SUM(C38:C41) -> 3 | T17: =SUM(D38:D41) -> 2 | U17: =SUM(E38:E41) -> 2 | V17: =SUM(F38:F41) -> 6 | W17: =SUM(G38:G41) -> 0 | X17: =SUM(H38:H41) -> 0 | Y17: =SUM(I38:I41) -> 4 | Z17: =SUM(J38:J41) -> 0 | ... AF17: =SUM(P38:P41) -> 64
B18: 09.00 - 09.15 | C18: 0 | D18: 0 | E18: 0 | F18: 1 | G18: 0 | H18: 1 | I18: 0 | J18: 0 | K18: 0 | L18: 0 | M18: 4 | N18: 0 | O18: =SUM(C18:L18,N18) -> 2 | P18: =SUM(C18:N18) -> 6 | R18: 1500-1600 | S18: =SUM(C42:C45) -> 2 | T18: =SUM(D42:D45) -> 0 | U18: =SUM(E42:E45) -> 2 | V18: =SUM(F42:F45) -> 2 | W18: =SUM(G42:G45) -> 1 | X18: =SUM(H42:H45) -> 0 | Y18: =SUM(I42:I45) -> 6 | Z18: =SUM(J42:J45) -> 2 | ... AF18: =SUM(P42:P45) -> 83
B19: 09.15 - 09.30 | C19: 1 | D19: 0 | E19: 0 | F19: 1 | G19: 0 | H19: 0 | I19: 1 | J19: 0 | K19: 0 | L19: 0 | M19: 5 | N19: 0 | O19: =SUM(C19:L19,N19) -> 3 | P19: =SUM(C19:N19) -> 8 | R19: 1600-1700 | S19: =SUM(C46:C49) -> 4 | T19: =SUM(D46:D49) -> 2 | U19: =SUM(E46:E49) -> 2 | V19: =SUM(F46:F49) -> 12 | W19: =SUM(G46:G49) -> 0 | X19: =SUM(H46:H49) -> 2 | Y19: =SUM(I46:I49) -> 3 | Z19: =SUM(J46:J49) -> 3 | ... AF19: =SUM(P46:P49) -> 95
B20: 09.30 - 09.45 | C20: 0 | D20: 0 | E20: 0 | F20: 1 | G20: 0 | H20: 0 | I20: 1 | J20: 0 | K20: 0 | L20: 0 | M20: 2 | N20: 0 | O20: =SUM(C20:L20,N20) -> 2 | P20: =SUM(C20:N20) -> 4 | R20: 1700-1800 | S20: =SUM(C50:C53) -> 4 | T20: =SUM(D50:D53) -> 0 | U20: =SUM(E50:E53) -> 0 | V20: =SUM(F50:F53) -> 4 | W20: =SUM(G50:G53) -> 1 | X20: =SUM(H50:H53) -> 1 | Y20: =SUM(I50:I53) -> 1 | Z20: =SUM(J50:J53) -> 0 | ... AF20: =SUM(P50:P53) -> 34
B21: 09.45 - 10.00 | C21: 0 | D21: 0 | E21: 0 | F21: 1 | G21: 0 | H21: 0 | I21: 0 | J21: 0 | K21: 0 | L21: 0 | M21: 9 | N21: 0 | O21: =SUM(C21:L21,N21) -> 1 | P21: =SUM(C21:N21) -> 10 | R21: 1800-1900 | S21: =SUM(C54:C57) -> 6 | T21: =SUM(D54:D57) -> 1 | U21: =SUM(E54:E57) -> 2 | V21: =SUM(F54:F57) -> 5 | W21: =SUM(G54:G57) -> 0 | X21: =SUM(H54:H57) -> 0 | Y21: =SUM(I54:I57) -> 4 | Z21: =SUM(J54:J57) -> 0 | ... AF21: =SUM(P54:P57) -> 49
B22: 10.00 - 10.15 | C22: 0 | D22: 0 | E22: 0 | F22: 0 | G22: 0 | H22: 0 | I22: 0 | J22: 0 | K22: 0 | L22: 0 | M22: 11 | N22: 0 | O22: =SUM(C22:L22,N22) -> 0 | P22: =SUM(C22:N22) -> 11 | R22: AM Peak Hr | S22: =MAX(S10:S12) -> 2 | T22: =MAX(T10:T12) -> 1 | U22: =MAX(U10:U12) -> 0 | V22: =MAX(V10:V12) -> 4 | W22: =MAX(W10:W12) -> 1 | X22: =MAX(X10:X12) -> 1 | Y22: =MAX(Y10:Y12) -> 2 | Z22: =MAX(Z10:Z12) -> 2 | ... AF22: =MAX(AF10:AF12) -> 32
B23: 10.15 - 10.30 | C23: 1 | D23: 0 | E23: 2 | F23: 1 | G23: 0 | H23: 0 | I23: 0 | J23: 0 | K23: 0 | L23: 0 | M23: 12 | N23: 0 | O23: =SUM(C23:L23,N23) -> 4 | P23: =SUM(C23:N23) -> 16 | R23: IP Peak Hr | S23: =MAX(S13:S18) -> 4 | T23: =MAX(T13:T18) -> 2 | U23: =MAX(U13:U18) -> 3 | V23: =MAX(V13:V18) -> 6 | W23: =MAX(W13:W18) -> 1 | X23: =MAX(X13:X18) -> 1 | Y23: =MAX(Y13:Y18) -> 6 | Z23: =MAX(Z13:Z18) -> 2 | ... AF23: =MAX(AF13:AF18) -> 83
B24: 10.30 - 10.45 | C24: 2 | D24: 0 | E24: 0 | F24: 0 | G24: 0 | H24: 0 | I24: 0 | J24: 0 | K24: 0 | L24: 0 | M24: 3 | N24: 0 | O24: =SUM(C24:L24,N24) -> 2 | P24: =SUM(C24:N24) -> 5 | R24: PM Peak Hr | S24: =MAX(S19:S21) -> 6 | T24: =MAX(T19:T21) -> 2 | U24: =MAX(U19:U21) -> 2 | V24: =MAX(V19:V21) -> 12 | W24: =MAX(W19:W21) -> 1 | X24: =MAX(X19:X21) -> 2 | Y24: =MAX(Y19:Y21) -> 4 | Z24: =MAX(Z19:Z21) -> 3 | ... AF24: =MAX(AF19:AF21) -> 95
B25: 10.45 - 11.00 | C25: 1 | D25: 0 | E25: 0 | F25: 0 | G25: 0 | H25: 0 | I25: 0 | J25: 0 | K25: 0 | L25: 0 | M25: 3 | N25: 0 | O25: =SUM(C25:L25,N25) -> 1 | P25: =SUM(C25:N25) -> 4 | R25: AM Period | S25: =SUM(S10:S12) -> 4 | T25: =SUM(T10:T12) -> 1 | U25: =SUM(U10:U12) -> 0 | V25: =SUM(V10:V12) -> 11 | W25: =SUM(W10:W12) -> 1 | X25: =SUM(X10:X12) -> 1 | Y25: =SUM(Y10:Y12) -> 3 | Z25: =SUM(Z10:Z12) -> 2 | ... AF25: =SUM(AF10:AF12) -> 75
B26: 11.00 - 11.15 | C26: 0 | D26: 0 | E26: 0 | F26: 2 | G26: 0 | H26: 0 | I26: 0 | J26: 0 | K26: 0 | L26: 0 | M26: 9 | N26: 0 | O26: =SUM(C26:L26,N26) -> 2 | P26: =SUM(C26:N26) -> 11 | R26: IP Period | S26: =SUM(S13:S18) -> 13 | T26: =SUM(T13:T18) -> 3 | U26: =SUM(U13:U18) -> 9 | V26: =SUM(V13:V18) -> 20 | W26: =SUM(W13:W18) -> 2 | X26: =SUM(X13:X18) -> 1 | Y26: =SUM(Y13:Y18) -> 15 | Z26: =SUM(Z13:Z18) -> 3 | ... AF26: =SUM(AF13:AF18) -> 354
B27: 11.15 - 11.30 | C27: 0 | D27: 0 | E27: 0 | F27: 0 | G27: 0 | H27: 0 | I27: 0 | J27: 0 | K27: 0 | L27: 0 | M27: 15 | N27: 0 | O27: =SUM(C27:L27,N27) -> 0 | P27: =SUM(C27:N27) -> 15 | R27: PM Period | S27: =SUM(S19:S21) -> 14 | T27: =SUM(T19:T21) -> 3 | U27: =SUM(U19:U21) -> 4 | V27: =SUM(V19:V21) -> 21 | W27: =SUM(W19:W21) -> 1 | X27: =SUM(X19:X21) -> 3 | Y27: =SUM(Y19:Y21) -> 8 | Z27: =SUM(Z19:Z21) -> 3 | ... AF27: =SUM(AF19:AF21) -> 178
B28: 11.30 - 11.45 | C28: 0 | D28: 0 | E28: 0 | F28: 2 | G28: 0 | H28: 0 | I28: 1 | J28: 0 | K28: 0 | L28: 0 | M28: 10 | N28: 0 | O28: =SUM(C28:L28,N28) -> 3 | P28: =SUM(C28:N28) -> 13 | R28: 12 Hours | S28: =SUM(S10:S21) -> 31 | T28: =SUM(T10:T21) -> 7 | U28: =SUM(U10:U21) -> 13 | V28: =SUM(V10:V21) -> 52 | W28: =SUM(W10:W21) -> 4 | X28: =SUM(X10:X21) -> 5 | Y28: =SUM(Y10:Y21) -> 26 | Z28: =SUM(Z10:Z21) -> 8 | ... AF28: =SUM(AF10:AF21) -> 607
B29: 11.45 - 12.00 | C29: 0 | D29: 0 | E29: 0 | F29: 0 | G29: 0 | H29: 0 | I29: 0 | J29: 0 | K29: 0 | L29: 0 | M29: 19 | N29: 0 | O29: =SUM(C29:L29,N29) -> 0 | P29: =SUM(C29:N29) -> 19
B30: 12.00 - 12.15 | C30: 0 | D30: 0 | E30: 0 | F30: 1 | G30: 0 | H30: 0 | I30: 1 | J30: 1 | K30: 1 | L30: 0 | M30: 14 | N30: 0 | O30: =SUM(C30:L30,N30) -> 4 | P30: =SUM(C30:N30) -> 18
B31: 12.15 - 12.30 | C31: 0 | D31: 0 | E31: 0 | F31: 0 | G31: 0 | H31: 0 | I31: 0 | J31: 0 | K31: 0 | L31: 0 | M31: 13 | N31: 0 | O31: =SUM(C31:L31,N31) -> 0 | P31: =SUM(C31:N31) -> 13
B32: 12.30 - 12.45 | C32: 2 | D32: 1 | E32: 0 | F32: 1 | G32: 0 | H32: 0 | I32: 1 | J32: 0 | K32: 0 | L32: 0 | M32: 13 | N32: 0 | O32: =SUM(C32:L32,N32) -> 5 | P32: =SUM(C32:N32) -> 18
B33: 12.45 - 13.00 | C33: 1 | D33: 0 | E33: 0 | F33: 1 | G33: 0 | H33: 1 | I33: 0 | J33: 0 | K33: 0 | L33: 0 | M33: 12 | N33: 0 | O33: =SUM(C33:L33,N33) -> 3 | P33: =SUM(C33:N33) -> 15
B34: 13.00 - 13.15 | C34: 0 | D34: 0 | E34: 0 | F34: 1 | G34: 0 | H34: 0 | I34: 1 | J34: 0 | K34: 0 | L34: 0 | M34: 6 | N34: 0 | O34: =SUM(C34:L34,N34) -> 2 | P34: =SUM(C34:N34) -> 8
B35: 13.15 - 13.30 | C35: 1 | D35: 0 | E35: 1 | F35: 0 | G35: 0 | H35: 0 | I35: 0 | J35: 0 | K35: 0 | L35: 0 | M35: 11 | N35: 0 | O35: =SUM(C35:L35,N35) -> 2 | P35: =SUM(C35:N35) -> 13
B36: 13.30 - 13.45 | C36: 0 | D36: 0 | E36: 1 | F36: 1 | G36: 1 | H36: 0 | I36: 1 | J36: 0 | K36: 0 | L36: 0 | M36: 11 | N36: 0 | O36: =SUM(C36:L36,N36) -> 4 | P36: =SUM(C36:N36) -> 15
B37: 13.45 - 14.00 | C37: 0 | D37: 0 | E37: 1 | F37: 2 | G37: 0 | H37: 0 | I37: 0 | J37: 0 | K37: 0 | L37: 0 | M37: 10 | N37: 0 | O37: =SUM(C37:L37,N37) -> 3 | P37: =SUM(C37:N37) -> 13
B38: 14.00 - 14.15 | C38: 0 | D38: 0 | E38: 1 | F38: 1 | G38: 0 | H38: 0 | I38: 2 | J38: 0 | K38: 0 | L38: 0 | M38: 15 | N38: 0 | O38: =SUM(C38:L38,N38) -> 4 | P38: =SUM(C38:N38) -> 19
B39: 14.15 - 14.30 | C39: 0 | D39: 1 | E39: 1 | F39: 1 | G39: 0 | H39: 0 | I39: 1 | J39: 0 | K39: 2 | L39: 0 | M39: 7 | N39: 0 | O39: =SUM(C39:L39,N39) -> 6 | P39: =SUM(C39:N39) -> 13
B40: 14.30 - 14.45 | C40: 2 | D40: 1 | E40: 0 | F40: 3 | G40: 0 | H40: 0 | I40: 1 | J40: 0 | K40: 0 | L40: 1 | M40: 11 | N40: 0 | O40: =SUM(C40:L40,N40) -> 8 | P40: =SUM(C40:N40) -> 19
... B57: 18.45 - 19.00 | C57: 2 | D57: 0 | E57: 1 | F57: 1 | G57: 0 | H57: 0 | I57: 1 | J57: 0 | K57: 0 | L57: 0 | M57: 4 | N57: 0 | O57: =SUM(C57:L57,N57) -> 5 | P57: =SUM(C57:N57) -> 9
B58: Totals | C58: =SUM(C10:C57) -> 31 | D58: =SUM(D10:D57) -> 7 | E58: =SUM(E10:E57) -> 13 | F58: =SUM(F10:F57) -> 52 | G58: =SUM(G10:G57) -> 4 | H58: =SUM(H10:H57) -> 5 | I58: =SUM(I10:I57) -> 26 | J58: =SUM(J10:J57) -> 8 | ... P58: =SUM(P10:P57) -> 607
...

Sheet 18.10 KAYUNGA-GALIRAYA
B1: Consultancy services for Preparation of Expressway Development Master Plan (EDMP) for Uganda
B2: MANUAL CLASSIFIED COUNT (MCC)
B3: ROAD NAME: | C3: ='17.10 KAYUNGA-GALIRAYA'!C3:G3 -> MCC - C3 - STN89 - GALIRAYA ROAD
C5: Date | D5: 18.10.19 | F5: Location | G5: ='17.10 KAYUNGA-GALIRAYA'!G5:H5 -> KYANYA | J5: Surveyor | K5: NAKIWUGE ALLEN
C6: Dir. From | D6: ='17.10 KAYUNGA-GALIRAYA'!D6:E6 -> KAYUNGA | F6: Dir. To | G6: ='17.10 KAYUNGA-GALIRAYA'!G6:H6 -> GALIRAYA | J6: Supervisor | K6: ='17.10 KAYUNGA-GALIRAYA'!K6:L6 -> GODFREY
B8: Time / Veh Type | R8: SUMMARY TRAFFIC VOLUMES
C9: 1. Car | D9: 2. Station Wagon | E9: 3. Pickups | F9: 4. Minibus, matatu | G9: 5. Medium bus | H9: 6. Large Bus | I9: 7. Light Truck | J9: 8. Medium Truck | K9: 9. Heavy truck | L9: 10. Truck Trailer | M9: 11. Motor cycles | N9: 12. Tractors | O9: Total Excl M/Cycles | P9: Total All | R9: Time | S9: 1. Car | T9: 2. Station Wagon | U9: 3. Pickups | V9: 4. Minibus, matatu | W9: 5. Medium bus | X9: 6. Large Bus | Y9: 7. Light Truck | Z9: 8. Medium Truck | AA9: 9. Heavy truck | AB9: 10. Truck Trailer | AC9: 11. Motorcycles | AD9: 12. Tractors, Graders | AE9: Total Excl M/ Cycles | AF9: Total All
B10: 07.00 - 07.15 | C10: 0 | D10: 0 | E10: 0 | F10: 1 | G10: 0 | H10: 0 | I10: 1 | J10: 2 | K10: 3 | L10: 0 | M10: 0 | N10: 0 | O10: =SUM(C10:L10,N10) -> 7 | P10: =SUM(C10:N10) -> 7 | R10: 0700-0800 | S10: =SUM(C10:C13) -> 0 | T10: =SUM(D10:D13) -> 0 | U10: =SUM(E10:E13) -> 0 | V10: =SUM(F10:F13) -> 5 | W10: =SUM(G10:G13) -> 0 | X10: =SUM(H10:H13) -> 0 | Y10: =SUM(I10:I13) -> 2 | Z10: =SUM(J10:J13) -> 3 | ... AF10: =SUM(P10:P13) -> 19
B11: 07.15 - 07.30 | C11: 0 | D11: 0 | E11: 0 | F11: 1 | G11: 0 | H11: 0 | I11: 0 | J11: 1 | K11: 1 | L11: 0 | M11: 1 | N11: 0 | O11: =SUM(C11:L11,N11) -> 3 | P11: =SUM(C11:N11) -> 4 | R11: 0800-0900 | S11: =SUM(C14:C17) -> 1 | T11: =SUM(D14:D17) -> 1 | U11: =SUM(E14:E17) -> 0 | V11: =SUM(F14:F17) -> 2 | W11: =SUM(G14:G17) -> 0 | X11: =SUM(H14:H17) -> 2 | Y11: =SUM(I14:I17) -> 4 | Z11: =SUM(J14:J17) -> 2 | ... AF11: =SUM(P14:P17) -> 41
B12: 07.30 - 07.45 | C12: 0 | D12: 0 | E12: 0 | F12: 1 | G12: 0 | H12: 0 | I12: 1 | J12: 0 | K12: 0 | L12: 0 | M12: 1 | N12: 0 | O12: =SUM(C12:L12,N12) -> 2 | P12: =SUM(C12:N12) -> 3 | R12: 0900-1000 | S12: =SUM(C18:C21) -> 3 | T12: =SUM(D18:D21) -> 2 | U12: =SUM(E18:E21) -> 1 | V12: =SUM(F18:F21) -> 6 | W12: =SUM(G18:G21) -> 0 | X12: =SUM(H18:H21) -> 0 | Y12: =SUM(I18:I21) -> 5 | Z12: =SUM(J18:J21) -> 0 | ... AF12: =SUM(P18:P21) -> 58
B13: 07.45 - 08.00 | C13: 0 | D13: 0 | E13: 0 | F13: 2 | G13: 0 | H13: 0 | I13: 0 | J13: 0 | K13: 0 | L13: 0 | M13: 3 | N13: 0 | O13: =SUM(C13:L13,N13) -> 2 | P13: =SUM(C13:N13) -> 5 | R13: 1000-1100 | S13: =SUM(C22:C25) -> 5 | T13: =SUM(D22:D25) -> 1 | U13: =SUM(E22:E25) -> 2 | V13: =SUM(F22:F25) -> 5 | W13: =SUM(G22:G25) -> 1 | X13: =SUM(H22:H25) -> 0 | Y13: =SUM(I22:I25) -> 9 | Z13: =SUM(J22:J25) -> 0 | ... AF13: =SUM(P22:P25) -> 66
B14: 08.00 - 08.15 | C14: 1 | D14: 0 | E14: 0 | F14: 0 | G14: 0 | H14: 0 | I14: 1 | J14: 1 | K14: 0 | L14: 0 | M14: 6 | N14: 0 | O14: =SUM(C14:L14,N14) -> 3 | P14: =SUM(C14:N14) -> 9 | R14: 1100-1200 | S14: =SUM(C26:C29) -> 4 | T14: =SUM(D26:D29) -> 0 | U14: =SUM(E26:E29) -> 4 | V14: =SUM(F26:F29) -> 6 | W14: =SUM(G26:G29) -> 1 | X14: =SUM(H26:H29) -> 0 | Y14: =SUM(I26:I29) -> 5 | Z14: =SUM(J26:J29) -> 2 | ... AF14: =SUM(P26:P29) -> 75
B15: 08.15 - 08.30 | C15: 0 | D15: 0 | E15: 0 | F15: 1 | G15: 0 | H15: 0 | I15: 1 | J15: 0 | K15: 0 | L15: 1 | M15: 7 | N15: 0 | O15: =SUM(C15:L15,N15) -> 3 | P15: =SUM(C15:N15) -> 10 | R15: 1200-1300 | S15: =SUM(C30:C33) -> 6 | T15: =SUM(D30:D33) -> 5 | U15: =SUM(E30:E33) -> 5 | V15: =SUM(F30:F33) -> 7 | W15: =SUM(G30:G33) -> 0 | X15: =SUM(H30:H33) -> 0 | Y15: =SUM(I30:I33) -> 3 | Z15: =SUM(J30:J33) -> 3 | ... AF15: =SUM(P30:P33) -> 90
B16: 08.30 - 08.45 | C16: 0 | D16: 0 | E16: 0 | F16: 1 | G16: 0 | H16: 1 | I16: 1 | J16: 0 | K16: 1 | L16: 1 | M16: 5 | N16: 0 | O16: =SUM(C16:L16,N16) -> 5 | P16: =SUM(C16:N16) -> 10 | R16: 1300-1400 | S16: =SUM(C34:C37) -> 6 | T16: =SUM(D34:D37) -> 0 | U16: =SUM(E34:E37) -> 2 | V16: =SUM(F34:F37) -> 6 | W16: =SUM(G34:G37) -> 0 | X16: =SUM(H34:H37) -> 0 | Y16: =SUM(I34:I37) -> 7 | Z16: =SUM(J34:J37) -> 1 | ... AF16: =SUM(P34:P37) -> 76
B17: 08.45 - 9.00 | C17: 0 | D17: 1 | E17: 0 | F17: 0 | G17: 0 | H17: 1 | I17: 1 | J17: 1 | K17: 0 | L17: 0 | M17: 8 | N17: 0 | O17: =SUM(C17:L17,N17) -> 4 | P17: =SUM(C17:N17) -> 12 | R17: 1400-1500 | S17: =SUM(C38:C41) -> 3 | T17: =SUM(D38:D41) -> 0 | U17: =SUM(E38:E41) -> 1 | V17: =SUM(F38:F41) -> 3 | W17: =SUM(G38:G41) -> 0 | X17: =SUM(H38:H41) -> 1 | Y17: =SUM(I38:I41) -> 3 | Z17: =SUM(J38:J41) -> 2 | ... AF17: =SUM(P38:P41) -> 67
B18: 09.00 - 09.15 | C18: 0 | D18: 1 | E18: 1 | F18: 1 | G18: 0 | H18: 0 | I18: 1 | J18: 0 | K18: 0 | L18: 0 | M18: 15 | N18: 0 | O18: =SUM(C18:L18,N18) -> 4 | P18: =SUM(C18:N18) -> 19 | R18: 1500-1600 | S18: =SUM(C42:C45) -> 4 | T18: =SUM(D42:D45) -> 0 | U18: =SUM(E42:E45) -> 2 | V18: =SUM(F42:F45) -> 5 | W18: =SUM(G42:G45) -> 0 | X18: =SUM(H42:H45) -> 1 | Y18: =SUM(I42:I45) -> 2 | Z18: =SUM(J42:J45) -> 2 | ... AF18: =SUM(P42:P45) -> 47
B19: 09.15 - 09.30 | C19: 1 | D19: 1 | E19: 0 | F19: 0 | G19: 0 | H19: 0 | I19: 1 | J19: 0 | K19: 1 | L19: 0 | M19: 1 | N19: 0 | O19: =SUM(C19:L19,N19) -> 4 | P19: =SUM(C19:N19) -> 5 | R19: 1600-1700 | S19: =SUM(C46:C49) -> 3 | T19: =SUM(D46:D49) -> 0 | U19: =SUM(E46:E49) -> 1 | V19: =SUM(F46:F49) -> 4 | W19: =SUM(G46:G49) -> 2 | X19: =SUM(H46:H49) -> 1 | Y19: =SUM(I46:I49) -> 3 | Z19: =SUM(J46:J49) -> 3 | ... AF19: =SUM(P46:P49) -> 61
B20: 09.30 - 09.45 | C20: 1 | D20: 0 | E20: 0 | F20: 1 | G20: 0 | H20: 0 | I20: 2 | J20: 0 | K20: 1 | L20: 0 | M20: 10 | N20: 0 | O20: =SUM(C20:L20,N20) -> 5 | P20: =SUM(C20:N20) -> 15 | R20: 1700-1800 | S20: =SUM(C50:C53) -> 5 | T20: =SUM(D50:D53) -> 0 | U20: =SUM(E50:E53) -> 0 | V20: =SUM(F50:F53) -> 9 | W20: =SUM(G50:G53) -> 1 | X20: =SUM(H50:H53) -> 0 | Y20: =SUM(I50:I53) -> 2 | Z20: =SUM(J50:J53) -> 0 | ... AF20: =SUM(P50:P53) -> 56
B21: 09.45 - 10.00 | C21: 1 | D21: 0 | E21: 0 | F21: 4 | G21: 0 | H21: 0 | I21: 1 | J21: 0 | K21: 0 | L21: 0 | M21: 13 | N21: 0 | O21: =SUM(C21:L21,N21) -> 6 | P21: =SUM(C21:N21) -> 19 | R21: 1800-1900 | S21: =SUM(C54:C57) -> 4 | T21: =SUM(D54:D57) -> 0 | U21: =SUM(E54:E57) -> 0 | V21: =SUM(F54:F57) -> 5 | W21: =SUM(G54:G57) -> 0 | X21: =SUM(H54:H57) -> 0 | Y21: =SUM(I54:I57) -> 5 | Z21: =SUM(J54:J57) -> 0 | ... AF21: =SUM(P54:P57) -> 58
B22: 10.00 - 10.15 | C22: 0 | D22: 1 | E22: 0 | F22: 0 | G22: 0 | H22: 0 | I22: 1 | J22: 0 | K22: 0 | L22: 0 | M22: 4 | N22: 0 | O22: =SUM(C22:L22,N22) -> 2 | P22: =SUM(C22:N22) -> 6 | R22: AM Peak Hr | S22: =MAX(S10:S12) -> 3 | T22: =MAX(T10:T12) -> 2 | U22: =MAX(U10:U12) -> 1 | V22: =MAX(V10:V12) -> 6 | W22: =MAX(W10:W12) -> 0 | X22: =MAX(X10:X12) -> 2 | Y22: =MAX(Y10:Y12) -> 5 | Z22: =MAX(Z10:Z12) -> 3 | ... AF22: =MAX(AF10:AF12) -> 58
B23: 10.15 - 10.30 | C23: 1 | D23: 0 | E23: 1 | F23: 3 | G23: 0 | H23: 0 | I23: 3 | J23: 0 | K23: 0 | L23: 0 | M23: 15 | N23: 0 | O23: =SUM(C23:L23,N23) -> 8 | P23: =SUM(C23:N23) -> 23 | R23: IP Peak Hr | S23: =MAX(S13:S18) -> 6 | T23: =MAX(T13:T18) -> 5 | U23: =MAX(U13:U18) -> 5 | V23: =MAX(V13:V18) -> 7 | W23: =MAX(W13:W18) -> 1 | X23: =MAX(X13:X18) -> 1 | Y23: =MAX(Y13:Y18) -> 9 | Z23: =MAX(Z13:Z18) -> 3 | ... AF23: =MAX(AF13:AF18) -> 90
B24: 10.30 - 10.45 | C24: 0 | D24: 0 | E24: 1 | F24: 2 | G24: 0 | H24: 0 | I24: 1 | J24: 0 | K24: 0 | L24: 0 | M24: 13 | N24: 0 | O24: =SUM(C24:L24,N24) -> 4 | P24: =SUM(C24:N24) -> 17 | R24: PM Peak Hr | S24: =MAX(S19:S21) -> 5 | T24: =MAX(T19:T21) -> 0 | U24: =MAX(U19:U21) -> 1 | V24: =MAX(V19:V21) -> 9 | W24: =MAX(W19:W21) -> 2 | X24: =MAX(X19:X21) -> 1 | Y24: =MAX(Y19:Y21) -> 5 | Z24: =MAX(Z19:Z21) -> 3 | ... AF24: =MAX(AF19:AF21) -> 61
B25: 10.45 - 11.00 | C25: 4 | D25: 0 | E25: 0 | F25: 0 | G25: 1 | H25: 0 | I25: 4 | J25: 0 | K25: 0 | L25: 0 | M25: 11 | N25: 0 | O25: =SUM(C25:L25,N25) -> 9 | P25: =SUM(C25:N25) -> 20 | R25: AM Period | S25: =SUM(S10:S12) -> 4 | T25: =SUM(T10:T12) -> 3 | U25: =SUM(U10:U12) -> 1 | V25: =SUM(V10:V12) -> 13 | W25: =SUM(W10:W12) -> 0 | X25: =SUM(X10:X12) -> 2 | Y25: =SUM(Y10:Y12) -> 11 | Z25: =SUM(Z10:Z12) -> 5 | ... AF25: =SUM(AF10:AF12) -> 118
B26: 11.00 - 11.15 | C26: 1 | D26: 0 | E26: 1 | F26: 0 | G26: 0 | H26: 0 | I26: 1 | J26: 1 | K26: 0 | L26: 0 | M26: 10 | N26: 0 | O26: =SUM(C26:L26,N26) -> 4 | P26: =SUM(C26:N26) -> 14 | R26: IP Period | S26: =SUM(S13:S18) -> 28 | T26: =SUM(T13:T18) -> 6 | U26: =SUM(U13:U18) -> 16 | V26: =SUM(V13:V18) -> 32 | W26: =SUM(W13:W18) -> 2 | X26: =SUM(X13:X18) -> 2 | Y26: =SUM(Y13:Y18) -> 29 | Z26: =SUM(Z13:Z18) -> 10 | ... AF26: =SUM(AF13:AF18) -> 421
B27: 11.15 - 11.30 | C27: 1 | D27: 0 | E27: 0 | F27: 2 | G27: 0 | H27: 0 | I27: 0 | J27: 0 | K27: 0 | L27: 0 | M27: 11 | N27: 0 | O27: =SUM(C27:L27,N27) -> 3 | P27: =SUM(C27:N27) -> 14 | R27: PM Period | S27: =SUM(S19:S21) -> 12 | T27: =SUM(T19:T21) -> 0 | U27: =SUM(U19:U21) -> 1 | V27: =SUM(V19:V21) -> 18 | W27: =SUM(W19:W21) -> 3 | X27: =SUM(X19:X21) -> 1 | Y27: =SUM(Y19:Y21) -> 10 | Z27: =SUM(Z19:Z21) -> 3 | ... AF27: =SUM(AF19:AF21) -> 175
B28: 11.30 - 11.45 | C28: 0 | D28: 0 | E28: 1 | F28: 0 | G28: 1 | H28: 0 | I28: 2 | J28: 0 | K28: 0 | L28: 0 | M28: 13 | N28: 0 | O28: =SUM(C28:L28,N28) -> 4 | P28: =SUM(C28:N28) -> 17 | R28: 12 Hours | S28: =SUM(S10:S21) -> 44 | T28: =SUM(T10:T21) -> 9 | U28: =SUM(U10:U21) -> 18 | V28: =SUM(V10:V21) -> 63 | W28: =SUM(W10:W21) -> 5 | X28: =SUM(X10:X21) -> 5 | Y28: =SUM(Y10:Y21) -> 50 | Z28: =SUM(Z10:Z21) -> 18 | ... AF28: =SUM(AF10:AF21) -> 714
B29: 11.45 - 12.00 | C29: 2 | D29: 0 | E29: 2 | F29: 4 | G29: 0 | H29: 0 | I29: 2 | J29: 1 | K29: 0 | L29: 0 | M29: 19 | N29: 0 | O29: =SUM(C29:L29,N29) -> 11 | P29: =SUM(C29:N29) -> 30
B30: 12.00 - 12.15 | C30: 1 | D30: 0 | E30: 0 | F30: 2 | G30: 0 | H30: 0 | I30: 0 | J30: 1 | K30: 0 | L30: 0 | M30: 13 | N30: 0 | O30: =SUM(C30:L30,N30) -> 4 | P30: =SUM(C30:N30) -> 17
B31: 12.15 - 12.30 | C31: 0 | D31: 2 | E31: 2 | F31: 2 | G31: 0 | H31: 0 | I31: 0 | J31: 1 | K31: 1 | L31: 0 | M31: 8 | N31: 0 | O31: =SUM(C31:L31,N31) -> 8 | P31: =SUM(C31:N31) -> 16
B32: 12.30 - 12.45 | C32: 5 | D32: 0 | E32: 1 | F32: 0 | G32: 0 | H32: 0 | I32: 1 | J32: 1 | K32: 0 | L32: 0 | M32: 23 | N32: 0 | O32: =SUM(C32:L32,N32) -> 8 | P32: =SUM(C32:N32) -> 31
B33: 12.45 - 13.00 | C33: 0 | D33: 3 | E33: 2 | F33: 3 | G33: 0 | H33: 0 | I33: 2 | J33: 0 | K33: 0 | L33: 2 | M33: 14 | N33: 0 | O33: =SUM(C33:L33,N33) -> 12 | P33: =SUM(C33:N33) -> 26
B34: 13.00 - 13.15 | C34: 1 | D34: 0 | E34: 1 | F34: 3 | G34: 0 | H34: 0 | I34: 2 | J34: 0 | K34: 0 | L34: 0 | M34: 14 | N34: 0 | O34: =SUM(C34:L34,N34) -> 7 | P34: =SUM(C34:N34) -> 21
B35: 13.15 - 13.30 | C35: 3 | D35: 0 | E35: 1 | F35: 1 | G35: 0 | H35: 0 | I35: 1 | J35: 1 | K35: 0 | L35: 0 | M35: 16 | N35: 0 | O35: =SUM(C35:L35,N35) -> 7 | P35: =SUM(C35:N35) -> 23
B36: 13.30 - 13.45 | C36: 2 | D36: 0 | E36: 0 | F36: 1 | G36: 0 | H36: 0 | I36: 0 | J36: 0 | K36: 0 | L36: 0 | M36: 12 | N36: 0 | O36: =SUM(C36:L36,N36) -> 3 | P36: =SUM(C36:N36) -> 15
B37: 13.45 - 14.00 | C37: 0 | D37: 0 | E37: 0 | F37: 1 | G37: 0 | H37: 0 | I37: 4 | J37: 0 | K37: 0 | L37: 1 | M37: 11 | N37: 0 | O37: =SUM(C37:L37,N37) -> 6 | P37: =SUM(C37:N37) -> 17
B38: 14.00 - 14.15 | C38: 0 | D38: 0 | E38: 0 | F38: 1 | G38: 0 | H38: 0 | I38: 0 | J38: 0 | K38: 0 | L38: 0 | M38: 7 | N38: 0 | O38: =SUM(C38:L38,N38) -> 1 | P38: =SUM(C38:N38) -> 8
B39: 14.15 - 14.30 | C39: 0 | D39: 0 | E39: 0 | F39: 1 | G39: 0 | H39: 0 | I39: 1 | J39: 0 | K39: 0 | L39: 0 | M39: 13 | N39: 0 | O39: =SUM(C39:L39,N39) -> 2 | P39: =SUM(C39:N39) -> 15
B40: 14.30 - 14.45 | C40: 2 | D40: 0 | E40: 0 | F40: 0 | G40: 0 | H40: 1 | I40: 1 | J40: 2 | K40: 0 | L40: 1 | M40: 20 | N40: 0 | O40: =SUM(C40:L40,N40) -> 7 | P40: =SUM(C40:N40) -> 27
... B57: 18.45 - 19.00 | C57: 0 | D57: 0 | E57: 0 | F57: 1 | G57: 0 | H57: 0 | I57: 0 | J57: 0 | K57: 0 | L57: 0 | M57: 12 | N57: 0 | O57: =SUM(C57:L57,N57) -> 1 | P57: =SUM(C57:N57) -> 13
B58: Totals | C58: =SUM(C10:C57) -> 44 | D58: =SUM(D10:D57) -> 9 | E58: =SUM(E10:E57) -> 18 | F58: =SUM(F10:F57) -> 63 | G58: =SUM(G10:G57) -> 5 | H58: =SUM(H10:H57) -> 5 | I58: =SUM(I10:I57) -> 50 | J58: =SUM(J10:J57) -> 18 | ... P58: =SUM(P10:P57) -> 714
...

Sheet 18.10 GALIRAYA-KAYUNGA
B1: Consultancy services for Preparation of Expressway Development Master Plan (EDMP) for Uganda
B2: MANUAL CLASSIFIED COUNT (MCC)
B3: ROAD NAME: | C3: ='17.10 GALIRAYA-KAYUNGA'!C3:G3 -> MCC - C3 - STN89 - GALIRAYA ROAD
C5: Date | D5: ='18.10 KAYUNGA-GALIRAYA'!D5 -> 18.10.19 | F5: Location | G5: ='17.10 KAYUNGA-GALIRAYA'!G5:H5 -> KYANYA | J5: Surveyor | K5: GODFREY
C6: Dir. From | D6: ='17.10 GALIRAYA-KAYUNGA'!D6:E6 -> GALIRAYA | F6: Dir. To | G6: ='17.10 GALIRAYA-KAYUNGA'!G6:H6 -> KAYUNGA | J6: Supervisor | K6: ='17.10 KAYUNGA-GALIRAYA'!K6:L6 -> GODFREY
B8: Time / Veh Type | R8: SUMMARY TRAFFIC VOLUMES
C9: 1. Car | D9: 2. Station Wagon | E9: 3. Pickups | F9: 4. Minibus, matatu | G9: 5. Medium bus | H9: 6. Large Bus | I9: 7. Light Truck | J9: 8. Medium Truck | K9: 9. Heavy truck | L9: 10. Truck Trailer | M9: 11. Motor cycles | N9: 12. Tractors | O9: Total Excl M/Cycles | P9: Total All | R9: Time | S9: 1. Car | T9: 2. Station Wagon | U9: 3. Pickups | V9: 4. Minibus, matatu | W9: 5. Medium bus | X9: 6. Large Bus | Y9: 7. Light Truck | Z9: 8. Medium Truck | AA9: 9. Heavy truck | AB9: 10. Truck Trailer | AC9: 11. Motorcycles | AD9: 12. Tractors, Graders | AE9: Total Excl M/ Cycles | AF9: Total All
B10: 07.00 - 07.15 | C10: 0 | D10: 0 | E10: 0 | F10: 2 | G10: 0 | H10: 0 | I10: 0 | J10: 0 | K10: 0 | L10: 0 | M10: 2 | N10: 0 | O10: =SUM(C10:L10,N10) -> 2 | P10: =SUM(C10:N10) -> 4 | R10: 0700-0800 | S10: =SUM(C10:C13) -> 0 | T10: =SUM(D10:D13) -> 0 | U10: =SUM(E10:E13) -> 0 | V10: =SUM(F10:F13) -> 4 | W10: =SUM(G10:G13) -> 1 | X10: =SUM(H10:H13) -> 0 | Y10: =SUM(I10:I13) -> 0 | Z10: =SUM(J10:J13) -> 0 | ... AF10: =SUM(P10:P13) -> 21
B11: 07.15 - 07.30 | C11: 0 | D11: 0 | E11: 0 | F11: 1 | G11: 1 | H11: 0 | I11: 0 | J11: 0 | K11: 1 | L11: 0 | M11: 3 | N11: 0 | O11: =SUM(C11:L11,N11) -> 3 | P11: =SUM(C11:N11) -> 6 | R11: 0800-0900 | S11: =SUM(C14:C17) -> 1 | T11: =SUM(D14:D17) -> 1 | U11: =SUM(E14:E17) -> 1 | V11: =SUM(F14:F17) -> 5 | W11: =SUM(G14:G17) -> 0 | X11: =SUM(H14:H17) -> 0 | Y11: =SUM(I14:I17) -> 2 | Z11: =SUM(J14:J17) -> 1 | ... AF11: =SUM(P14:P17) -> 52
B12: 07.30 - 07.45 | C12: 0 | D12: 0 | E12: 0 | F12: 1 | G12: 0 | H12: 0 | I12: 0 | J12: 0 | K12: 0 | L12: 0 | M12: 5 | N12: 0 | O12: =SUM(C12:L12,N12) -> 1 | P12: =SUM(C12:N12) -> 6 | R12: 0900-1000 | S12: =SUM(C18:C21) -> 0 | T12: =SUM(D18:D21) -> 0 | U12: =SUM(E18:E21) -> 0 | V12: =SUM(F18:F21) -> 5 | W12: =SUM(G18:G21) -> 0 | X12: =SUM(H18:H21) -> 3 | Y12: =SUM(I18:I21) -> 1 | Z12: =SUM(J18:J21) -> 0 | ... AF12: =SUM(P18:P21) -> 44
B13: 07.45 - 08.00 | C13: 0 | D13: 0 | E13: 0 | F13: 0 | G13: 0 | H13: 0 | I13: 0 | J13: 0 | K13: 0 | L13: 0 | M13: 5 | N13: 0 | O13: =SUM(C13:L13,N13) -> 0 | P13: =SUM(C13:N13) -> 5 | R13: 1000-1100 | S13: =SUM(C22:C25) -> 2 | T13: =SUM(D22:D25) -> 0 | U13: =SUM(E22:E25) -> 1 | V13: =SUM(F22:F25) -> 2 | W13: =SUM(G22:G25) -> 0 | X13: =SUM(H22:H25) -> 0 | Y13: =SUM(I22:I25) -> 0 | Z13: =SUM(J22:J25) -> 1 | ... AF13: =SUM(P22:P25) -> 36
B14: 08.00 - 08.15 | C14: 1 | D14: 1 | E14: 0 | F14: 2 | G14: 0 | H14: 0 | I14: 0 | J14: 0 | K14: 0 | L14: 0 | M14: 10 | N14: 0 | O14: =SUM(C14:L14,N14) -> 4 | P14: =SUM(C14:N14) -> 14 | R14: 1100-1200 | S14: =SUM(C26:C29) -> 4 | T14: =SUM(D26:D29) -> 1 | U14: =SUM(E26:E29) -> 2 | V14: =SUM(F26:F29) -> 4 | W14: =SUM(G26:G29) -> 0 | X14: =SUM(H26:H29) -> 0 | Y14: =SUM(I26:I29) -> 1 | Z14: =SUM(J26:J29) -> 0 | ... AF14: =SUM(P26:P29) -> 48
B15: 08.15 - 08.30 | C15: 0 | D15: 0 | E15: 1 | F15: 0 | G15: 0 | H15: 0 | I15: 0 | J15: 0 | K15: 0 | L15: 0 | M15: 7 | N15: 0 | O15: =SUM(C15:L15,N15) -> 1 | P15: =SUM(C15:N15) -> 8 | R15: 1200-1300 | S15: =SUM(C30:C33) -> 2 | T15: =SUM(D30:D33) -> 1 | U15: =SUM(E30:E33) -> 1 | V15: =SUM(F30:F33) -> 4 | W15: =SUM(G30:G33) -> 2 | X15: =SUM(H30:H33) -> 1 | Y15: =SUM(I30:I33) -> 2 | Z15: =SUM(J30:J33) -> 0 | ... AF15: =SUM(P30:P33) -> 50
B16: 08.30 - 08.45 | C16: 0 | D16: 0 | E16: 0 | F16: 3 | G16: 0 | H16: 0 | I16: 0 | J16: 1 | K16: 0 | L16: 0 | M16: 4 | N16: 0 | O16: =SUM(C16:L16,N16) -> 4 | P16: =SUM(C16:N16) -> 8 | R16: 1300-1400 | S16: =SUM(C34:C37) -> 6 | T16: =SUM(D34:D37) -> 0 | U16: =SUM(E34:E37) -> 3 | V16: =SUM(F34:F37) -> 4 | W16: =SUM(G34:G37) -> 0 | X16: =SUM(H34:H37) -> 0 | Y16: =SUM(I34:I37) -> 3 | Z16: =SUM(J34:J37) -> 0 | ... AF16: =SUM(P34:P37) -> 46
B17: 08.45 - 9.00 | C17: 0 | D17: 0 | E17: 0 | F17: 0 | G17: 0 | H17: 0 | I17: 2 | J17: 0 | K17: 0 | L17: 0 | M17: 20 | N17: 0 | O17: =SUM(C17:L17,N17) -> 2 | P17: =SUM(C17:N17) -> 22 | R17: 1400-1500 | S17: =SUM(C38:C41) -> 4 | T17: =SUM(D38:D41) -> 0 | U17: =SUM(E38:E41) -> 0 | V17: =SUM(F38:F41) -> 3 | W17: =SUM(G38:G41) -> 0 | X17: =SUM(H38:H41) -> 0 | Y17: =SUM(I38:I41) -> 1 | Z17: =SUM(J38:J41) -> 0 | ... AF17: =SUM(P38:P41) -> 39
B18: 09.00 - 09.15 | C18: 0 | D18: 0 | E18: 0 | F18: 3 | G18: 0 | H18: 2 | I18: 1 | J18: 0 | K18: 0 | L18: 0 | M18: 12 | N18: 0 | O18: =SUM(C18:L18,N18) -> 6 | P18: =SUM(C18:N18) -> 18 | R18: 1500-1600 | S18: =SUM(C42:C45) -> 2 | T18: =SUM(D42:D45) -> 1 | U18: =SUM(E42:E45) -> 1 | V18: =SUM(F42:F45) -> 5 | W18: =SUM(G42:G45) -> 0 | X18: =SUM(H42:H45) -> 1 | Y18: =SUM(I42:I45) -> 5 | Z18: =SUM(J42:J45) -> 1 | ... AF18: =SUM(P42:P45) -> 61
B19: 09.15 - 09.30 | C19: 0 | D19: 0 | E19: 0 | F19: 0 | G19: 0 | H19: 1 | I19: 0 | J19: 0 | K19: 0 | L19: 0 | M19: 11 | N19: 0 | O19: =SUM(C19:L19,N19) -> 1 | P19: =SUM(C19:N19) -> 12 | R19: 1600-1700 | S19: =SUM(C46:C49) -> 1 | T19: =SUM(D46:D49) -> 0 | U19: =SUM(E46:E49) -> 0 | V19: =SUM(F46:F49) -> 5 | W19: =SUM(G46:G49) -> 1 | X19: =SUM(H46:H49) -> 0 | Y19: =SUM(I46:I49) -> 4 | Z19: =SUM(J46:J49) -> 0 | ... AF19: =SUM(P46:P49) -> 43
B20: 09.30 - 09.45 | C20: 0 | D20: 0 | E20: 0 | F20: 0 | G20: 0 | H20: 0 | I20: 0 | J20: 0 | K20: 0 | L20: 0 | M20: 7 | N20: 0 | O20: =SUM(C20:L20,N20) -> 0 | P20: =SUM(C20:N20) -> 7 | R20: 1700-1800 | S20: =SUM(C50:C53) -> 2 | T20: =SUM(D50:D53) -> 2 | U20: =SUM(E50:E53) -> 3 | V20: =SUM(F50:F53) -> 4 | W20: =SUM(G50:G53) -> 1 | X20: =SUM(H50:H53) -> 0 | Y20: =SUM(I50:I53) -> 4 | Z20: =SUM(J50:J53) -> 3 | ... AF20: =SUM(P50:P53) -> 60
B21: 09.45 - 10.00 | C21: 0 | D21: 0 | E21: 0 | F21: 2 | G21: 0 | H21: 0 | I21: 0 | J21: 0 | K21: 0 | L21: 0 | M21: 5 | N21: 0 | O21: =SUM(C21:L21,N21) -> 2 | P21: =SUM(C21:N21) -> 7 | R21: 1800-1900 | S21: =SUM(C54:C57) -> 3 | T21: =SUM(D54:D57) -> 1 | U21: =SUM(E54:E57) -> 3 | V21: =SUM(F54:F57) -> 7 | W21: =SUM(G54:G57) -> 0 | X21: =SUM(H54:H57) -> 0 | Y21: =SUM(I54:I57) -> 3 | Z21: =SUM(J54:J57) -> 1 | ... AF21: =SUM(P54:P57) -> 55
B22: 10.00 - 10.15 | C22: 0 | D22: 0 | E22: 0 | F22: 0 | G22: 0 | H22: 0 | I22: 0 | J22: 0 | K22: 0 | L22: 0 | M22: 8 | N22: 0 | O22: =SUM(C22:L22,N22) -> 0 | P22: =SUM(C22:N22) -> 8 | R22: AM Peak Hr | S22: =MAX(S10:S12) -> 1 | T22: =MAX(T10:T12) -> 1 | U22: =MAX(U10:U12) -> 1 | V22: =MAX(V10:V12) -> 5 | W22: =MAX(W10:W12) -> 1 | X22: =MAX(X10:X12) -> 3 | Y22: =MAX(Y10:Y12) -> 2 | Z22: =MAX(Z10:Z12) -> 1 | ... AF22: =MAX(AF10:AF12) -> 52
B23: 10.15 - 10.30 | C23: 1 | D23: 0 | E23: 0 | F23: 0 | G23: 0 | H23: 0 | I23: 0 | J23: 0 | K23: 0 | L23: 0 | M23: 7 | N23: 0 | O23: =SUM(C23:L23,N23) -> 1 | P23: =SUM(C23:N23) -> 8 | R23: IP Peak Hr | S23: =MAX(S13:S18) -> 6 | T23: =MAX(T13:T18) -> 1 | U23: =MAX(U13:U18) -> 3 | V23: =MAX(V13:V18) -> 5 | W23: =MAX(W13:W18) -> 2 | X23: =MAX(X13:X18) -> 1 | Y23: =MAX(Y13:Y18) -> 5 | Z23: =MAX(Z13:Z18) -> 1 | ... AF23: =MAX(AF13:AF18) -> 61
B24: 10.30 - 10.45 | C24: 1 | D24: 0 | E24: 0 | F24: 1 | G24: 0 | H24: 0 | I24: 0 | J24: 1 | K24: 0 | L24: 0 | M24: 8 | N24: 0 | O24: =SUM(C24:L24,N24) -> 3 | P24: =SUM(C24:N24) -> 11 | R24: PM Peak Hr | S24: =MAX(S19:S21) -> 3 | T24: =MAX(T19:T21) -> 2 | U24: =MAX(U19:U21) -> 3 | V24: =MAX(V19:V21) -> 7 | W24: =MAX(W19:W21) -> 1 | X24: =MAX(X19:X21) -> 0 | Y24: =MAX(Y19:Y21) -> 4 | Z24: =MAX(Z19:Z21) -> 3 | ... AF24: =MAX(AF19:AF21) -> 60
B25: 10.45 - 11.00 | C25: 0 | D25: 0 | E25: 1 | F25: 1 | G25: 0 | H25: 0 | I25: 0 | J25: 0 | K25: 0 | L25: 0 | M25: 7 | N25: 0 | O25: =SUM(C25:L25,N25) -> 2 | P25: =SUM(C25:N25) -> 9 | R25: AM Period | S25: =SUM(S10:S12) -> 1 | T25: =SUM(T10:T12) -> 1 | U25: =SUM(U10:U12) -> 1 | V25: =SUM(V10:V12) -> 14 | W25: =SUM(W10:W12) -> 1 | X25: =SUM(X10:X12) -> 3 | Y25: =SUM(Y10:Y12) -> 3 | Z25: =SUM(Z10:Z12) -> 1 | ... AF25: =SUM(AF10:AF12) -> 117
B26: 11.00 - 11.15 | C26: 0 | D26: 0 | E26: 0 | F26: 0 | G26: 0 | H26: 0 | I26: 0 | J26: 0 | K26: 0 | L26: 0 | M26: 8 | N26: 0 | O26: =SUM(C26:L26,N26) -> 0 | P26: =SUM(C26:N26) -> 8 | R26: IP Period | S26: =SUM(S13:S18) -> 20 | T26: =SUM(T13:T18) -> 3 | U26: =SUM(U13:U18) -> 8 | V26: =SUM(V13:V18) -> 22 | W26: =SUM(W13:W18) -> 2 | X26: =SUM(X13:X18) -> 2 | Y26: =SUM(Y13:Y18) -> 12 | Z26: =SUM(Z13:Z18) -> 2 | ... AF26: =SUM(AF13:AF18) -> 280
B27: 11.15 - 11.30 | C27: 0 | D27: 0 | E27: 1 | F27: 1 | G27: 0 | H27: 0 | I27: 0 | J27: 0 | K27: 0 | L27: 0 | M27: 9 | N27: 0 | O27: =SUM(C27:L27,N27) -> 2 | P27: =SUM(C27:N27) -> 11 | R27: PM Period | S27: =SUM(S19:S21) -> 6 | T27: =SUM(T19:T21) -> 3 | U27: =SUM(U19:U21) -> 6 | V27: =SUM(V19:V21) -> 16 | W27: =SUM(W19:W21) -> 2 | X27: =SUM(X19:X21) -> 0 | Y27: =SUM(Y19:Y21) -> 11 | Z27: =SUM(Z19:Z21) -> 4 | ... AF27: =SUM(AF19:AF21) -> 158
B28: 11.30 - 11.45 | C28: 2 | D28: 1 | E28: 1 | F28: 2 | G28: 0 | H28: 0 | I28: 0 | J28: 0 | K28: 0 | L28: 0 | M28: 14 | N28: 0 | O28: =SUM(C28:L28,N28) -> 6 | P28: =SUM(C28:N28) -> 20 | R28: 12 Hours | S28: =SUM(S10:S21) -> 27 | T28: =SUM(T10:T21) -> 7 | U28: =SUM(U10:U21) -> 15 | V28: =SUM(V10:V21) -> 52 | W28: =SUM(W10:W21) -> 5 | X28: =SUM(X10:X21) -> 5 | Y28: =SUM(Y10:Y21) -> 26 | Z28: =SUM(Z10:Z21) -> 7 | ... AF28: =SUM(AF10:AF21) -> 555
B29: 11.45 - 12.00 | C29: 2 | D29: 0 | E29: 0 | F29: 1 | G29: 0 | H29: 0 | I29: 1 | J29: 0 | K29: 0 | L29: 0 | M29: 5 | N29: 0 | O29: =SUM(C29:L29,N29) -> 4 | P29: =SUM(C29:N29) -> 9
B30: 12.00 - 12.15 | C30: 0 | D30: 0 | E30: 0 | F30: 1 | G30: 0 | H30: 0 | I30: 1 | J30: 0 | K30: 0 | L30: 0 | M30: 11 | N30: 0 | O30: =SUM(C30:L30,N30) -> 2 | P30: =SUM(C30:N30) -> 13
B31: 12.15 - 12.30 | C31: 0 | D31: 1 | E31: 1 | F31: 1 | G31: 0 | H31: 0 | I31: 0 | J31: 0 | K31: 0 | L31: 0 | M31: 10 | N31: 0 | O31: =SUM(C31:L31,N31) -> 3 | P31: =SUM(C31:N31) -> 13
B32: 12.30 - 12.45 | C32: 1 | D32: 0 | E32: 0 | F32: 1 | G32: 1 | H32: 0 | I32: 1 | J32: 0 | K32: 0 | L32: 1 | M32: 11 | N32: 0 | O32: =SUM(C32:L32,N32) -> 5 | P32: =SUM(C32:N32) -> 16
B33: 12.45 - 13.00 | C33: 1 | D33: 0 | E33: 0 | F33: 1 | G33: 1 | H33: 1 | I33: 0 | J33: 0 | K33: 0 | L33: 0 | M33: 4 | N33: 0 | O33: =SUM(C33:L33,N33) -> 4 | P33: =SUM(C33:N33) -> 8
B34: 13.00 - 13.15 | C34: 2 | D34: 0 | E34: 1 | F34: 2 | G34: 0 | H34: 0 | I34: 1 | J34: 0 | K34: 0 | L34: 1 | M34: 7 | N34: 0 | O34: =SUM(C34:L34,N34) -> 7 | P34: =SUM(C34:N34) -> 14
B35: 13.15 - 13.30 | C35: 1 | D35: 0 | E35: 0 | F35: 1 | G35: 0 | H35: 0 | I35: 0 | J35: 0 | K35: 0 | L35: 0 | M35: 6 | N35: 0 | O35: =SUM(C35:L35,N35) -> 2 | P35: =SUM(C35:N35) -> 8
B36: 13.30 - 13.45 | C36: 3 | D36: 0 | E36: 1 | F36: 0 | G36: 0 | H36: 0 | I36: 1 | J36: 0 | K36: 0 | L36: 0 | M36: 12 | N36: 0 | O36: =SUM(C36:L36,N36) -> 5 | P36: =SUM(C36:N36) -> 17
B37: 13.45 - 14.00 | C37: 0 | D37: 0 | E37: 1 | F37: 1 | G37: 0 | H37: 0 | I37: 1 | J37: 0 | K37: 0 | L37: 0 | M37: 4 | N37: 0 | O37: =SUM(C37:L37,N37) -> 3 | P37: =SUM(C37:N37) -> 7
B38: 14.00 - 14.15 | C38: 2 | D38: 0 | E38: 0 | F38: 2 | G38: 0 | H38: 0 | I38: 0 | J38: 0 | K38: 0 | L38: 0 | M38: 10 | N38: 0 | O38: =SUM(C38:L38,N38) -> 4 | P38: =SUM(C38:N38) -> 14
B39: 14.15 - 14.30 | C39: 1 | D39: 0 | E39: 0 | F39: 1 | G39: 0 | H39: 0 | I39: 0 | J39: 0 | K39: 0 | L39: 0 | M39: 9 | N39: 0 | O39: =SUM(C39:L39,N39) -> 2 | P39: =SUM(C39:N39) -> 11
B40: 14.30 - 14.45 | C40: 0 | D40: 0 | E40: 0 | F40: 0 | G40: 0 | H40: 0 | I40: 1 | J40: 0 | K40: 0 | L40: 0 | M40: 5 | N40: 0 | O40: =SUM(C40:L40,N40) -> 1 | P40: =SUM(C40:N40) -> 6
... B57: 18.45 - 19.00 | C57: 1 | D57: 0 | E57: 1 | F57: 1 | G57: 0 | H57: 0 | I57: 0 | J57: 0 | K57: 0 | L57: 0 | M57: 7 | N57: 0 | O57: =SUM(C57:L57,N57) -> 3 | P57: =SUM(C57:N57) -> 10
B58: Totals | C58: =SUM(C10:C57) -> 27 | D58: =SUM(D10:D57) -> 7 | E58: =SUM(E10:E57) -> 15 | F58: =SUM(F10:F57) -> 52 | G58: =SUM(G10:G57) -> 5 | H58: =SUM(H10:H57) -> 5 | I58: =SUM(I10:I57) -> 26 | J58: =SUM(J10:J57) -> 7 | ... P58: =SUM(P10:P57) -> 555
...

Sheet 19.10 KAYUNGA-GALIRAYA-24h
B1: Consultancy services for Preparation of Expressway Development Master Plan (EDMP) for Uganda
B2: MANUAL CLASSIFIED COUNT (MCC)
B3: ROAD NAME: | C3: ='17.10 KAYUNGA-GALIRAYA'!C3:G3 -> MCC - C3 - STN89 - GALIRAYA ROAD
C5: Date | D5: 19.10.19 | F5: Location | G5: ='22.10 GALIRAYA-KAYUNGA'!G5:H5 -> KYANYA | J5: Surveyor | K5: PAMELA
C6: Dir. From | D6: ='17.10 KAYUNGA-GALIRAYA'!D6:E6 -> KAYUNGA | F6: Dir. To | G6: ='17.10 KAYUNGA-GALIRAYA'!G6:H6 -> GALIRAYA | J6: Supervisor | K6: ='22.10 GALIRAYA-KAYUNGA'!K6:L6 -> GODFREY
B8: Time / Veh Type | R8: SUMMARY TRAFFIC VOLUMES
C9: 1. Car | D9: 2. Station Wagon | E9: 3. Pickups | F9: 4. Minibus, matatu | G9: 5. Medium bus | H9: 6. Large Bus | I9: 7. Light Truck | J9: 8. Medium Truck | K9: 9. Heavy truck | L9: 10. Truck Trailer | M9: 11. Motor cycles | N9: 12. Tractors | O9: Total Excl M/Cycles | P9: Total All | R9: Time | S9: 1. Car | T9: 2. Station Wagon | U9: 3. Pickups | V9: 4. Minibus, matatu | W9: 5. Medium bus | X9: 6. Large Bus | Y9: 7. Light Truck | Z9: 8. Medium Truck | AA9: 9. Heavy truck | AB9: 10. Truck Trailer | AC9: 11. Motorcycles | AD9: 12. Tractors, Graders | AE9: Total Excl M/ Cycles | AF9: Total All
B10: 07.00 - 07.15 | C10: 0 | D10: 0 | E10: 0 | F10: 0 | G10: 0 | H10: 0 | I10: 0 | J10: 0 | K10: 0 | L10: 0 | M10: 6 | N10: 0 | O10: =SUM(C10:L10,N10) -> 0 | P10: =SUM(C10:N10) -> 6 | R10: 0700-0800 | S10: =SUM(C10:C13) -> 3 | T10: =SUM(D10:D13) -> 0 | U10: =SUM(E10:E13) -> 0 | V10: =SUM(F10:F13) -> 4 | W10: =SUM(G10:G13) -> 0 | X10: =SUM(H10:H13) -> 0 | Y10: =SUM(I10:I13) -> 0 | Z10: =SUM(J10:J13) -> 2 | ... AF10: =SUM(P10:P13) -> 19
B11: 07.15 - 07.30 | C11: 2 | D11: 0 | E11: 0 | F11: 1 | G11: 0 | H11: 0 | I11: 0 | J11: 0 | K11: 0 | L11: 0 | M11: 2 | N11: 0 | O11: =SUM(C11:L11,N11) -> 3 | P11: =SUM(C11:N11) -> 5 | R11: 0800-0900 | S11: =SUM(C14:C17) -> 3 | T11: =SUM(D14:D17) -> 0 | U11: =SUM(E14:E17) -> 1 | V11: =SUM(F14:F17) -> 9 | W11: =SUM(G14:G17) -> 0 | X11: =SUM(H14:H17) -> 0 | Y11: =SUM(I14:I17) -> 2 | Z11: =SUM(J14:J17) -> 1 | ... AF11: =SUM(P14:P17) -> 54
B12: 07.30 - 07.45 | C12: 1 | D12: 0 | E12: 0 | F12: 0 | G12: 0 | H12: 0 | I12: 0 | J12: 1 | K12: 0 | L12: 0 | M12: 2 | N12: 0 | O12: =SUM(C12:L12,N12) -> 2 | P12: =SUM(C12:N12) -> 4 | R12: 0900-1000 | S12: =SUM(C18:C21) -> 4 | T12: =SUM(D18:D21) -> 2 | U12: =SUM(E18:E21) -> 2 | V12: =SUM(F18:F21) -> 4 | W12: =SUM(G18:G21) -> 0 | X12: =SUM(H18:H21) -> 2 | Y12: =SUM(I18:I21) -> 2 | Z12: =SUM(J18:J21) -> 2 | ... AF12: =SUM(P18:P21) -> 58
B13: 07.45 - 08.00 | C13: 0 | D13: 0 | E13: 0 | F13: 3 | G13: 0 | H13: 0 | I13: 0 | J13: 1 | K13: 0 | L13: 0 | M13: 0 | N13: 0 | O13: =SUM(C13:L13,N13) -> 4 | P13: =SUM(C13:N13) -> 4 | R13: 1000-1100 | S13: =SUM(C22:C25) -> 0 | T13: =SUM(D22:D25) -> 2 | U13: =SUM(E22:E25) -> 2 | V13: =SUM(F22:F25) -> 4 | W13: =SUM(G22:G25) -> 0 | X13: =SUM(H22:H25) -> 0 | Y13: =SUM(I22:I25) -> 3 | Z13: =SUM(J22:J25) -> 0 | ... AF13: =SUM(P22:P25) -> 71
B14: 08.00 - 08.15 | C14: 1 | D14: 0 | E14: 0 | F14: 3 | G14: 0 | H14: 0 | I14: 1 | J14: 0 | K14: 0 | L14: 0 | M14: 4 | N14: 0 | O14: =SUM(C14:L14,N14) -> 5 | P14: =SUM(C14:N14) -> 9 | R14: 1100-1200 | S14: =SUM(C26:C29) -> 3 | T14: =SUM(D26:D29) -> 1 | U14: =SUM(E26:E29) -> 0 | V14: =SUM(F26:F29) -> 3 | W14: =SUM(G26:G29) -> 0 | X14: =SUM(H26:H29) -> 0 | Y14: =SUM(I26:I29) -> 2 | Z14: =SUM(J26:J29) -> 1 | ... AF14: =SUM(P26:P29) -> 68
B15: 08.15 - 08.30 | C15: 0 | D15: 0 | E15: 0 | F15: 2 | G15: 0 | H15: 0 | I15: 1 | J15: 0 | K15: 0 | L15: 0 | M15: 6 | N15: 0 | O15: =SUM(C15:L15,N15) -> 3 | P15: =SUM(C15:N15) -> 9 | R15: 1200-1300 | S15: =SUM(C30:C33) -> 3 | T15: =SUM(D30:D33) -> 0 | U15: =SUM(E30:E33) -> 3 | V15: =SUM(F30:F33) -> 4 | W15: =SUM(G30:G33) -> 0 | X15: =SUM(H30:H33) -> 1 | Y15: =SUM(I30:I33) -> 1 | Z15: =SUM(J30:J33) -> 3 | ... AF15: =SUM(P30:P33) -> 81
B16: 08.30 - 08.45 | C16: 1 | D16: 0 | E16: 1 | F16: 3 | G16: 0 | H16: 0 | I16: 0 | J16: 1 | K16: 0 | L16: 0 | M16: 16 | N16: 0 | O16: =SUM(C16:L16,N16) -> 6 | P16: =SUM(C16:N16) -> 22 | R16: 1300-1400 | S16: =SUM(C34:C37) -> 3 | T16: =SUM(D34:D37) -> 0 | U16: =SUM(E34:E37) -> 0 | V16: =SUM(F34:F37) -> 5 | W16: =SUM(G34:G37) -> 0 | X16: =SUM(H34:H37) -> 0 | Y16: =SUM(I34:I37) -> 3 | Z16: =SUM(J34:J37) -> 0 | ... AF16: =SUM(P34:P37) -> 66
B17: 08.45 - 9.00 | C17: 1 | D17: 0 | E17: 0 | F17: 1 | G17: 0 | H17: 0 | I17: 0 | J17: 0 | K17: 0 | L17: 0 | M17: 12 | N17: 0 | O17: =SUM(C17:L17,N17) -> 2 | P17: =SUM(C17:N17) -> 14 | R17: 1400-1500 | S17: =SUM(C38:C41) -> 5 | T17: =SUM(D38:D41) -> 5 | U17: =SUM(E38:E41) -> 1 | V17: =SUM(F38:F41) -> 5 | W17: =SUM(G38:G41) -> 0 | X17: =SUM(H38:H41) -> 0 | Y17: =SUM(I38:I41) -> 3 | Z17: =SUM(J38:J41) -> 1 | ... AF17: =SUM(P38:P41) -> 56
B18: 09.00 - 09.15 | C18: 1 | D18: 0 | E18: 0 | F18: 0 | G18: 0 | H18: 0 | I18: 2 | J18: 0 | K18: 1 | L18: 0 | M18: 11 | N18: 0 | O18: =SUM(C18:L18,N18) -> 4 | P18: =SUM(C18:N18) -> 15 | R18: 1500-1600 | S18: =SUM(C42:C45) -> 6 | T18: =SUM(D42:D45) -> 2 | U18: =SUM(E42:E45) -> 0 | V18: =SUM(F42:F45) -> 5 | W18: =SUM(G42:G45) -> 0 | X18: =SUM(H42:H45) -> 0 | Y18: =SUM(I42:I45) -> 3 | Z18: =SUM(J42:J45) -> 0 | ... AF18: =SUM(P42:P45) -> 58
B19: 09.15 - 09.30 | C19: 1 | D19: 1 | E19: 0 | F19: 1 | G19: 0 | H19: 1 | I19: 0 | J19: 0 | K19: 0 | L19: 0 | M19: 6 | N19: 0 | O19: =SUM(C19:L19,N19) -> 4 | P19: =SUM(C19:N19) -> 10 | R19: 1600-1700 | S19: =SUM(C46:C49) -> 6 | T19: =SUM(D46:D49) -> 3 | U19: =SUM(E46:E49) -> 2 | V19: =SUM(F46:F49) -> 4 | W19: =SUM(G46:G49) -> 0 | X19: =SUM(H46:H49) -> 1 | Y19: =SUM(I46:I49) -> 3 | Z19: =SUM(J46:J49) -> 0 | ... AF19: =SUM(P46:P49) -> 69
B20: 09.30 - 09.45 | C20: 1 | D20: 0 | E20: 0 | F20: 1 | G20: 0 | H20: 1 | I20: 0 | J20: 0 | K20: 0 | L20: 0 | M20: 7 | N20: 0 | O20: =SUM(C20:L20,N20) -> 3 | P20: =SUM(C20:N20) -> 10 | R20: 1700-1800 | S20: =SUM(C50:C53) -> 6 | T20: =SUM(D50:D53) -> 3 | U20: =SUM(E50:E53) -> 5 | V20: =SUM(F50:F53) -> 6 | W20: =SUM(G50:G53) -> 0 | X20: =SUM(H50:H53) -> 0 | Y20: =SUM(I50:I53) -> 1 | Z20: =SUM(J50:J53) -> 4 | ... AF20: =SUM(P50:P53) -> 87
B21: 09.45 - 10.00 | C21: 1 | D21: 1 | E21: 2 | F21: 2 | G21: 0 | H21: 0 | I21: 0 | J21: 2 | K21: 1 | L21: 0 | M21: 14 | N21: 0 | O21: =SUM(C21:L21,N21) -> 9 | P21: =SUM(C21:N21) -> 23 | R21: 1800-1900 | S21: =SUM(C54:C57) -> 9 | T21: =SUM(D54:D57) -> 6 | U21: =SUM(E54:E57) -> 1 | V21: =SUM(F54:F57) -> 9 | W21: =SUM(G54:G57) -> 1 | X21: =SUM(H54:H57) -> 0 | Y21: =SUM(I54:I57) -> 2 | Z21: =SUM(J54:J57) -> 0 | ... AF21: =SUM(P54:P57) -> 91
B22: 10.00 - 10.15 | C22: 0 | D22: 1 | E22: 1 | F22: 1 | G22: 0 | H22: 0 | I22: 0 | J22: 0 | K22: 0 | L22: 0 | M22: 20 | N22: 0 | O22: =SUM(C22:L22,N22) -> 3 | P22: =SUM(C22:N22) -> 23 | R22: 1900-2000 | S22: =SUM(C58:C61) -> 4 | T22: =SUM(D58:D61) -> 0 | U22: =SUM(E58:E61) -> 2 | V22: =SUM(F58:F61) -> 4 | W22: =SUM(G58:G61) -> 0 | X22: =SUM(H58:H61) -> 0 | Y22: =SUM(I58:I61) -> 3 | Z22: =SUM(J58:J61) -> 2 | ... AF22: =SUM(P58:P61) -> 78
B23: 10.15 - 10.30 | C23: 0 | D23: 0 | E23: 1 | F23: 1 | G23: 0 | H23: 0 | I23: 0 | J23: 0 | K23: 0 | L23: 0 | M23: 13 | N23: 0 | O23: =SUM(C23:L23,N23) -> 2 | P23: =SUM(C23:N23) -> 15 | R23: 2000-2100 | S23: =SUM(C62:C65) -> 5 | T23: =SUM(D62:D65) -> 0 | U23: =SUM(E62:E65) -> 2 | V23: =SUM(F62:F65) -> 6 | W23: =SUM(G62:G65) -> 1 | X23: =SUM(H62:H65) -> 0 | Y23: =SUM(I62:I65) -> 4 | Z23: =SUM(J62:J65) -> 1 | ... AF23: =SUM(P62:P65) -> 52
B24: 10.30 - 10.45 | C24: 0 | D24: 1 | E24: 0 | F24: 1 | G24: 0 | H24: 0 | I24: 2 | J24: 0 | K24: 0 | L24: 0 | M24: 14 | N24: 0 | O24: =SUM(C24:L24,N24) -> 4 | P24: =SUM(C24:N24) -> 18 | R24: 2100-2200 | S24: =SUM(C66:C69) -> 3 | T24: =SUM(D66:D69) -> 1 | U24: =SUM(E66:E69) -> 1 | V24: =SUM(F66:F69) -> 2 | W24: =SUM(G66:G69) -> 0 | X24: =SUM(H66:H69) -> 0 | Y24: =SUM(I66:I69) -> 3 | Z24: =SUM(J66:J69) -> 1 | ... AF24: =SUM(P66:P69) -> 20
B25: 10.45 - 11.00 | C25: 0 | D25: 0 | E25: 0 | F25: 1 | G25: 0 | H25: 0 | I25: 1 | J25: 0 | K25: 0 | L25: 0 | M25: 13 | N25: 0 | O25: =SUM(C25:L25,N25) -> 2 | P25: =SUM(C25:N25) -> 15 | R25: 2200-2300 | S25: =SUM(C70:C73) -> 1 | T25: =SUM(D70:D73) -> 0 | U25: =SUM(E70:E73) -> 0 | V25: =SUM(F70:F73) -> 1 | W25: =SUM(G70:G73) -> 0 | X25: =SUM(H70:H73) -> 0 | Y25: =SUM(I70:I73) -> 0 | Z25: =SUM(J70:J73) -> 3 | ... AF25: =SUM(P70:P73) -> 11
B26: 11.00 - 11.15 | C26: 2 | D26: 0 | E26: 0 | F26: 1 | G26: 0 | H26: 0 | I26: 1 | J26: 0 | K26: 0 | L26: 0 | M26: 15 | N26: 0 | O26: =SUM(C26:L26,N26) -> 4 | P26: =SUM(C26:N26) -> 19 | R26: 2300-0000 | S26: =SUM(C74:C77) -> 1 | T26: =SUM(D74:D77) -> 0 | U26: =SUM(E74:E77) -> 0 | V26: =SUM(F74:F77) -> 2 | W26: =SUM(G74:G77) -> 0 | X26: =SUM(H74:H77) -> 0 | Y26: =SUM(I74:I77) -> 1 | Z26: =SUM(J74:J77) -> 0 | ... AF26: =SUM(P74:P77) -> 9
B27: 11.15 - 11.30 | C27: 0 | D27: 0 | E27: 0 | F27: 0 | G27: 0 | H27: 0 | I27: 1 | J27: 0 | K27: 0 | L27: 0 | M27: 16 | N27: 0 | O27: =SUM(C27:L27,N27) -> 1 | P27: =SUM(C27:N27) -> 17 | R27: 0000-0100 | S27: =SUM(C78:C81) -> 1 | T27: =SUM(D78:D81) -> 0 | U27: =SUM(E78:E81) -> 0 | V27: =SUM(F78:F81) -> 1 | W27: =SUM(G78:G81) -> 0 | X27: =SUM(H78:H81) -> 0 | Y27: =SUM(I78:I81) -> 0 | Z27: =SUM(J78:J81) -> 0 | ... AF27: =SUM(P78:P81) -> 3
B28: 11.30 - 11.45 | C28: 0 | D28: 0 | E28: 0 | F28: 1 | G28: 0 | H28: 0 | I28: 0 | J28: 0 | K28: 0 | L28: 0 | M28: 12 | N28: 0 | O28: =SUM(C28:L28,N28) -> 1 | P28: =SUM(C28:N28) -> 13 | R28: 0100-0200 | S28: =SUM(C82:C85) -> 0 | T28: =SUM(D82:D85) -> 0 | U28: =SUM(E82:E85) -> 0 | V28: =SUM(F82:F85) -> 1 | W28: =SUM(G82:G85) -> 0 | X28: =SUM(H82:H85) -> 0 | Y28: =SUM(I82:I85) -> 0 | Z28: =SUM(J82:J85) -> 0 | ... AF28: =SUM(P82:P85) -> 3
B29: 11.45 - 12.00 | C29: 1 | D29: 1 | E29: 0 | F29: 1 | G29: 0 | H29: 0 | I29: 0 | J29: 1 | K29: 0 | L29: 0 | M29: 15 | N29: 0 | O29: =SUM(C29:L29,N29) -> 4 | P29: =SUM(C29:N29) -> 19 | R29: 0200-0300 | S29: =SUM(C86:C89) -> 0 | T29: =SUM(D86:D89) -> 2 | U29: =SUM(E86:E89) -> 1 | V29: =SUM(F86:F89) -> 0 | W29: =SUM(G86:G89) -> 0 | X29: =SUM(H86:H89) -> 0 | Y29: =SUM(I86:I89) -> 0 | Z29: =SUM(J86:J89) -> 1 | ... AF29: =SUM(P86:P89) -> 6
B30: 12.00 - 12.15 | C30: 0 | D30: 0 | E30: 0 | F30: 0 | G30: 0 | H30: 0 | I30: 0 | J30: 0 | K30: 0 | L30: 0 | M30: 19 | N30: 0 | O30: =SUM(C30:L30,N30) -> 0 | P30: =SUM(C30:N30) -> 19 | R30: 0300-0400 | S30: =SUM(C90:C93) -> 1 | T30: =SUM(D90:D93) -> 0 | U30: =SUM(E90:E93) -> 0 | V30: =SUM(F90:F93) -> 0 | W30: =SUM(G90:G93) -> 0 | X30: =SUM(H90:H93) -> 0 | Y30: =SUM(I90:I93) -> 0 | Z30: =SUM(J90:J93) -> 0 | ... AF30: =SUM(P90:P93) -> 4
B31: 12.15 - 12.30 | C31: 1 | D31: 0 | E31: 0 | F31: 2 | G31: 0 | H31: 0 | I31: 1 | J31: 2 | K31: 0 | L31: 1 | M31: 9 | N31: 0 | O31: =SUM(C31:L31,N31) -> 7 | P31: =SUM(C31:N31) -> 16 | R31: 0400-0500 | S31: =SUM(C94:C97) -> 0 | T31: =SUM(D94:D97) -> 0 | U31: =SUM(E94:E97) -> 0 | V31: =SUM(F94:F97) -> 0 | W31: =SUM(G94:G97) -> 0 | X31: =SUM(H94:H97) -> 0 | Y31: =SUM(I94:I97) -> 0 | Z31: =SUM(J94:J97) -> 0 | ... AF31: =SUM(P94:P97) -> 0
