Workbook

Sheet 22.08 TORORO-BUSITEMA
B1: Consultancy services for Preparation of Expressway Development Master Plan (EDMP) for Uganda
B2: MANUAL CLASSIFIED COUNT (MCC)
B3: ROAD NAME: | C3: TORORO TO BUSITEMA
C5: Date | D5: 22.08.19 | F5: Location | G5: STATION 98 | J5: Surveyor | K5: RWOTHOMIYO NORMAN
C6: Dir. From | D6: TORORO | F6: Dir. To | G6: BUSITEMA | J6: Supervisor | K6: IVAN
B8: Time / Veh Type | R8: SUMMARY TRAFFIC VOLUMES
C9: 1. Car | D9: 2. Station Wagon | E9: 3. Pickups | F9: 4. Minibus, matatu | G9: 5. Medium bus | H9: 6. Large Bus | I9: 7. Light Truck | J9: 8. Medium Truck | K9: 9. Heavy truck | L9: 10. Truck Trailer | M9: 11. Motor cycles | N9: 12. Tractors | O9: Total Excl M/Cycles | P9: Total All | R9: Time | S9: 1. Car | T9: 2. Station Wagon | U9: 3. Pickups | V9: 4. Minibus, matatu | W9: 5. Medium bus | X9: 6. Large Bus | Y9: 7. Light Truck | Z9: 8. Medium Truck | AA9: 9. Heavy truck | AB9: 10. Truck Trailer | AC9: 11. Motorcycles | AD9: 12. Tractors, Graders | AE9: Total Excl M/ Cycles | AF9: Total All
B10: 07.00 - 07.15 | C10: 1 | D10: 1 | E10: 0 | F10: 1 | G10: 0 | H10: 1 | I10: 3 | J10: 1 | K10: 2 | L10: 16 | M10: 2 | N10: 0 | O10: =SUM(C10:L10,N10) -> 26 | P10: =SUM(C10:N10) -> 28 | R10: 0700-0800 | S10: =SUM(C10:C13) -> 5 | T10: =SUM(D10:D13) -> 2 | U10: =SUM(E10:E13) -> 6 | V10: =SUM(F10:F13) -> 12 | W10: =SUM(G10:G13) -> 0 | X10: =SUM(H10:H13) -> 1 | Y10: =SUM(I10:I13) -> 7 | Z10: =SUM(J10:J13) -> 1 | ... AF10: =SUM(P10:P13) -> 96
B11: 07.15 - 07.30 | C11: 1 | D11: 0 | E11: 1 | F11: 3 | G11: 0 | H11: 0 | I11: 1 | J11: 0 | K11: 0 | L11: 16 | M11: 1 | N11: 0 | O11: =SUM(C11:L11,N11) -> 22 | P11: =SUM(C11:N11) -> 23 | R11: 0800-0900 | S11: =SUM(C14:C17) -> 1 | T11: =SUM(D14:D17) -> 10 | U11: =SUM(E14:E17) -> 2 | V11: =SUM(F14:F17) -> 9 | W11: =SUM(G14:G17) -> 1 | X11: =SUM(H14:H17) -> 0 | Y11: =SUM(I14:I17) -> 1 | Z11: =SUM(J14:J17) -> 0 | ... AF11: =SUM(P14:P17) -> 51
B12: 07.30 - 07.45 | C12: 1 | D12: 1 | E12: 3 | F12: 4 | G12: 0 | H12: 0 | I12: 1 | J12: 0 | K12: 1 | L12: 5 | M12: 4 | N12: 0 | O12: =SUM(C12:L12,N12) -> 16 | P12: =SUM(C12:N12) -> 20 | R12: 0900-1000 | S12: =SUM(C18:C21) -> 4 | T12: =SUM(D18:D21) -> 13 | U12: =SUM(E18:E21) -> 4 | V12: =SUM(F18:F21) -> 19 | W12: =SUM(G18:G21) -> 1 | X12: =SUM(H18:H21) -> 1 | Y12: =SUM(I18:I21) -> 6 | Z12: =SUM(J18:J21) -> 0 | ... AF12: =SUM(P18:P21) -> 106
B13: 07.45 - 08.00 | C13: 2 | D13: 0 | E13: 2 | F13: 4 | G13: 0 | H13: 0 | I13: 2 | J13: 0 | K13: 1 | L13: 8 | M13: 6 | N13: 0 | O13: =SUM(C13:L13,N13) -> 19 | P13: =SUM(C13:N13) -> 25 | R13: 1000-1100 | S13: =SUM(C22:C25) -> 7 | T13: =SUM(D22:D25) -> 26 | U13: =SUM(E22:E25) -> 5 | V13: =SUM(F22:F25) -> 20 | W13: =SUM(G22:G25) -> 0 | X13: =SUM(H22:H25) -> 3 | Y13: =SUM(I22:I25) -> 6 | Z13: =SUM(J22:J25) -> 0 | ... AF13: =SUM(P22:P25) -> 131
B14: 08.00 - 08.15 | C14: 0 | D14: 2 | E14: 0 | F14: 1 | G14: 1 | H14: 0 | I14: 1 | J14: 0 | K14: 0 | L14: 2 | M14: 1 | N14: 0 | O14: =SUM(C14:L14,N14) -> 7 | P14: =SUM(C14:N14) -> 8 | R14: 1100-1200 | S14: =SUM(C26:C29) -> 4 | T14: =SUM(D26:D29) -> 19 | U14: =SUM(E26:E29) -> 5 | V14: =SUM(F26:F29) -> 14 | W14: =SUM(G26:G29) -> 1 | X14: =SUM(H26:H29) -> 1 | Y14: =SUM(I26:I29) -> 4 | Z14: =SUM(J26:J29) -> 1 | ... AF14: =SUM(P26:P29) -> 104
B15: 08.15 - 08.30 | C15: 0 | D15: 6 | E15: 2 | F15: 4 | G15: 0 | H15: 0 | I15: 0 | J15: 0 | K15: 0 | L15: 6 | M15: 2 | N15: 0 | O15: =SUM(C15:L15,N15) -> 18 | P15: =SUM(C15:N15) -> 20 | R15: 1200-1300 | S15: =SUM(C30:C33) -> 3 | T15: =SUM(D30:D33) -> 16 | U15: =SUM(E30:E33) -> 11 | V15: =SUM(F30:F33) -> 18 | W15: =SUM(G30:G33) -> 1 | X15: =SUM(H30:H33) -> 0 | Y15: =SUM(I30:I33) -> 7 | Z15: =SUM(J30:J33) -> 1 | ... AF15: =SUM(P30:P33) -> 131
B16: 08.30 - 08.45 | C16: 1 | D16: 2 | E16: 0 | F16: 3 | G16: 0 | H16: 0 | I16: 0 | J16: 0 | K16: 0 | L16: 3 | M16: 6 | N16: 0 | O16: =SUM(C16:L16,N16) -> 9 | P16: =SUM(C16:N16) -> 15 | R16: 1300-1400 | S16: =SUM(C34:C37) -> 3 | T16: =SUM(D34:D37) -> 11 | U16: =SUM(E34:E37) -> 4 | V16: =SUM(F34:F37) -> 9 | W16: =SUM(G34:G37) -> 0 | X16: =SUM(H34:H37) -> 0 | Y16: =SUM(I34:I37) -> 5 | Z16: =SUM(J34:J37) -> 1 | ... AF16: =SUM(P34:P37) -> 76
B17: 08.45 - 9.00 | C17: 0 | D17: 0 | E17: 0 | F17: 1 | G17: 0 | H17: 0 | I17: 0 | J17: 0 | K17: 0 | L17: 5 | M17: 2 | N17: 0 | O17: =SUM(C17:L17,N17) -> 6 | P17: =SUM(C17:N17) -> 8 | R17: 1400-1500 | S17: =SUM(C38:C41) -> 0 | T17: =SUM(D38:D41) -> 10 | U17: =SUM(E38:E41) -> 3 | V17: =SUM(F38:F41) -> 16 | W17: =SUM(G38:G41) -> 0 | X17: =SUM(H38:H41) -> 0 | Y17: =SUM(I38:I41) -> 2 | Z17: =SUM(J38:J41) -> 0 | ... AF17: =SUM(P38:P41) -> 82
B18: 09.00 - 09.15 | C18: 0 | D18: 3 | E18: 1 | F18: 1 | G18: 1 | H18: 0 | I18: 1 | J18: 0 | K18: 1 | L18: 7 | M18: 4 | N18: 0 | O18: =SUM(C18:L18,N18) -> 15 | P18: =SUM(C18:N18) -> 19 | R18: 1500-1600 | S18: =SUM(C42:C45) -> 8 | T18: =SUM(D42:D45) -> 12 | U18: =SUM(E42:E45) -> 2 | V18: =SUM(F42:F45) -> 16 | W18: =SUM(G42:G45) -> 0 | X18: =SUM(H42:H45) -> 0 | Y18: =SUM(I42:I45) -> 4 | Z18: =SUM(J42:J45) -> 0 | ... AF18: =SUM(P42:P45) -> 105
B19: 09.15 - 09.30 | C19: 2 | D19: 4 | E19: 2 | F19: 6 | G19: 0 | H19: 0 | I19: 2 | J19: 0 | K19: 0 | L19: 7 | M19: 6 | N19: 0 | O19: =SUM(C19:L19,N19) -> 23 | P19: =SUM(C19:N19) -> 29 | R19: 1600-1700 | S19: =SUM(C46:C49) -> 8 | T19: =SUM(D46:D49) -> 13 | U19: =SUM(E46:E49) -> 5 | V19: =SUM(F46:F49) -> 12 | W19: =SUM(G46:G49) -> 0 | X19: =SUM(H46:H49) -> 0 | Y19: =SUM(I46:I49) -> 5 | Z19: =SUM(J46:J49) -> 0 | ... AF19: =SUM(P46:P49) -> 83
B20: 09.30 - 09.45 | C20: 2 | D20: 6 | E20: 1 | F20: 7 | G20: 0 | H20: 1 | I20: 2 | J20: 0 | K20: 2 | L20: 11 | M20: 11 | N20: 0 | O20: =SUM(C20:L20,N20) -> 32 | P20: =SUM(C20:N20) -> 43 | R20: 1700-1800 | S20: =SUM(C50:C53) -> 8 | T20: =SUM(D50:D53) -> 13 | U20: =SUM(E50:E53) -> 4 | V20: =SUM(F50:F53) -> 9 | W20: =SUM(G50:G53) -> 0 | X20: =SUM(H50:H53) -> 0 | Y20: =SUM(I50:I53) -> 7 | Z20: =SUM(J50:J53) -> 0 | ... AF20: =SUM(P50:P53) -> 126
B21: 09.45 - 10.00 | C21: 0 | D21: 0 | E21: 0 | F21: 5 | G21: 0 | H21: 0 | I21: 1 | J21: 0 | K21: 1 | L21: 3 | M21: 5 | N21: 0 | O21: =SUM(C21:L21,N21) -> 10 | P21: =SUM(C21:N21) -> 15 | R21: 1800-1900 | S21: =SUM(C54:C57) -> 2 | T21: =SUM(D54:D57) -> 8 | U21: =SUM(E54:E57) -> 1 | V21: =SUM(F54:F57) -> 12 | W21: =SUM(G54:G57) -> 0 | X21: =SUM(H54:H57) -> 0 | Y21: =SUM(I54:I57) -> 18 | Z21: =SUM(J54:J57) -> 0 | ... AF21: =SUM(P54:P57) -> 91
B22: 10.00 - 10.15 | C22: 0 | D22: 2 | E22: 0 | F22: 3 | G22: 0 | H22: 0 | I22: 1 | J22: 0 | K22: 1 | L22: 6 | M22: 3 | N22: 0 | O22: =SUM(C22:L22,N22) -> 13 | P22: =SUM(C22:N22) -> 16 | R22: AM Peak Hr | S22: =MAX(S10:S12) -> 5 | T22: =MAX(T10:T12) -> 13 | U22: =MAX(U10:U12) -> 6 | V22: =MAX(V10:V12) -> 19 | W22: =MAX(W10:W12) -> 1 | X22: =MAX(X10:X12) -> 1 | Y22: =MAX(Y10:Y12) -> 7 | Z22: =MAX(Z10:Z12) -> 1 | ... AF22: =MAX(AF10:AF12) -> 106
B23: 10.15 - 10.30 | C23: 3 | D23: 4 | E23: 1 | F23: 3 | G23: 0 | H23: 3 | I23: 1 | J23: 0 | K23: 0 | L23: 8 | M23: 9 | N23: 0 | O23: =SUM(C23:L23,N23) -> 23 | P23: =SUM(C23:N23) -> 32 | R23: IP Peak Hr | S23: =MAX(S13:S18) -> 8 | T23: =MAX(T13:T18) -> 26 | U23: =MAX(U13:U18) -> 11 | V23: =MAX(V13:V18) -> 20 | W23: =MAX(W13:W18) -> 1 | X23: =MAX(X13:X18) -> 3 | Y23: =MAX(Y13:Y18) -> 7 | Z23: =MAX(Z13:Z18) -> 1 | ... AF23: =MAX(AF13:AF18) -> 131
B24: 10.30 - 10.45 | C24: 3 | D24: 3 | E24: 2 | F24: 5 | G24: 0 | H24: 0 | I24: 1 | J24: 0 | K24: 0 | L24: 8 | M24: 10 | N24: 0 | O24: =SUM(C24:L24,N24) -> 22 | P24: =SUM(C24:N24) -> 32 | R24: PM Peak Hr | S24: =MAX(S19:S21) -> 8 | T24: =MAX(T19:T21) -> 13 | U24: =MAX(U19:U21) -> 5 | V24: =MAX(V19:V21) -> 12 | W24: =MAX(W19:W21) -> 0 | X24: =MAX(X19:X21) -> 0 | Y24: =MAX(Y19:Y21) -> 18 | Z24: =MAX(Z19:Z21) -> 0 | ... AF24: =MAX(AF19:AF21) -> 126
B25: 10.45 - 11.00 | C25: 1 | D25: 17 | E25: 2 | F25: 9 | G25: 0 | H25: 0 | I25: 3 | J25: 0 | K25: 1 | L25: 5 | M25: 13 | N25: 0 | O25: =SUM(C25:L25,N25) -> 38 | P25: =SUM(C25:N25) -> 51 | R25: AM Period | S25: =SUM(S10:S12) -> 10 | T25: =SUM(T10:T12) -> 25 | U25: =SUM(U10:U12) -> 12 | V25: =SUM(V10:V12) -> 40 | W25: =SUM(W10:W12) -> 2 | X25: =SUM(X10:X12) -> 2 | Y25: =SUM(Y10:Y12) -> 14 | Z25: =SUM(Z10:Z12) -> 1 | ... AF25: =SUM(AF10:AF12) -> 253
B26: 11.00 - 11.15 | C26: 1 | D26: 3 | E26: 0 | F26: 2 | G26: 0 | H26: 0 | I26: 1 | J26: 0 | K26: 0 | L26: 10 | M26: 6 | N26: 0 | O26: =SUM(C26:L26,N26) -> 17 | P26: =SUM(C26:N26) -> 23 | R26: IP Period | S26: =SUM(S13:S18) -> 25 | T26: =SUM(T13:T18) -> 94 | U26: =SUM(U13:U18) -> 30 | V26: =SUM(V13:V18) -> 93 | W26: =SUM(W13:W18) -> 2 | X26: =SUM(X13:X18) -> 4 | Y26: =SUM(Y13:Y18) -> 28 | Z26: =SUM(Z13:Z18) -> 3 | ... AF26: =SUM(AF13:AF18) -> 629
B27: 11.15 - 11.30 | C27: 1 | D27: 8 | E27: 1 | F27: 2 | G27: 0 | H27: 0 | I27: 1 | J27: 0 | K27: 0 | L27: 7 | M27: 5 | N27: 0 | O27: =SUM(C27:L27,N27) -> 20 | P27: =SUM(C27:N27) -> 25 | R27: PM Period | S27: =SUM(S19:S21) -> 18 | T27: =SUM(T19:T21) -> 34 | U27: =SUM(U19:U21) -> 10 | V27: =SUM(V19:V21) -> 33 | W27: =SUM(W19:W21) -> 0 | X27: =SUM(X19:X21) -> 0 | Y27: =SUM(Y19:Y21) -> 30 | Z27: =SUM(Z19:Z21) -> 0 | ... AF27: =SUM(AF19:AF21) -> 300
B28: 11.30 - 11.45 | C28: 1 | D28: 4 | E28: 1 | F28: 4 | G28: 1 | H28: 1 | I28: 1 | J28: 0 | K28: 2 | L28: 6 | M28: 4 | N28: 0 | O28: =SUM(C28:L28,N28) -> 21 | P28: =SUM(C28:N28) -> 25 | R28: 12 Hours | S28: =SUM(S10:S21) -> 53 | T28: =SUM(T10:T21) -> 153 | U28: =SUM(U10:U21) -> 52 | V28: =SUM(V10:V21) -> 166 | W28: =SUM(W10:W21) -> 4 | X28: =SUM(X10:X21) -> 6 | Y28: =SUM(Y10:Y21) -> 72 | Z28: =SUM(Z10:Z21) -> 4 | ... AF28: =SUM(AF10:AF21) -> 1182
B29: 11.45 - 12.00 | C29: 1 | D29: 4 | E29: 3 | F29: 6 | G29: 0 | H29: 0 | I29: 1 | J29: 1 | K29: 0 | L29: 13 | M29: 2 | N29: 0 | O29: =SUM(C29:L29,N29) -> 29 | P29: =SUM(C29:N29) -> 31
B30: 12.00 - 12.15 | C30: 0 | D30: 2 | E30: 0 | F30: 4 | G30: 0 | H30: 0 | I30: 0 | J30: 1 | K30: 0 | L30: 9 | M30: 5 | N30: 0 | O30: =SUM(C30:L30,N30) -> 16 | P30: =SUM(C30:N30) -> 21
B31: 12.15 - 12.30 | C31: 1 | D31: 2 | E31: 3 | F31: 6 | G31: 0 | H31: 0 | I31: 1 | J31: 0 | K31: 1 | L31: 12 | M31: 7 | N31: 0 | O31: =SUM(C31:L31,N31) -> 26 | P31: =SUM(C31:N31) -> 33
B32: 12.30 - 12.45 | C32: 2 | D32: 10 | E32: 5 | F32: 6 | G32: 0 | H32: 0 | I32: 4 | J32: 0 | K32: 0 | L32: 22 | M32: 8 | N32: 0 | O32: =SUM(C32:L32,N32) -> 49 | P32: =SUM(C32:N32) -> 57
B33: 12.45 - 13.00 | C33: 0 | D33: 2 | E33: 3 | F33: 2 | G33: 1 | H33: 0 | I33: 2 | J33: 0 | K33: 0 | L33: 7 | M33: 3 | N33: 0 | O33: =SUM(C33:L33,N33) -> 17 | P33: =SUM(C33:N33) -> 20
B34: 13.00 - 13.15 | C34: 1 | D34: 7 | E34: 1 | F34: 0 | G34: 0 | H34: 0 | I34: 1 | J34: 0 | K34: 0 | L34: 3 | M34: 6 | N34: 0 | O34: =SUM(C34:L34,N34) -> 13 | P34: =SUM(C34:N34) -> 19
B35: 13.15 - 13.30 | C35: 1 | D35: 1 | E35: 0 | F35: 2 | G35: 0 | H35: 0 | I35: 1 | J35: 0 | K35: 0 | L35: 2 | M35: 3 | N35: 0 | O35: =SUM(C35:L35,N35) -> 7 | P35: =SUM(C35:N35) -> 10
B36: 13.30 - 13.45 | C36: 1 | D36: 3 | E36: 1 | F36: 1 | G36: 0 | H36: 0 | I36: 1 | J36: 1 | K36: 2 | L36: 7 | M36: 2 | N36: 0 | O36: =SUM(C36:L36,N36) -> 17 | P36: =SUM(C36:N36) -> 19
B37: 13.45 - 14.00 | C37: 0 | D37: 0 | E37: 2 | F37: 6 | G37: 0 | H37: 0 | I37: 2 | J37: 0 | K37: 1 | L37: 7 | M37: 10 | N37: 0 | O37: =SUM(C37:L37,N37) -> 18 | P37: =SUM(C37:N37) -> 28
B38: 14.00 - 14.15 | C38: 0 | D38: 4 | E38: 1 | F38: 4 | G38: 0 | H38: 0 | I38: 1 | J38: 0 | K38: 1 | L38: 13 | M38: 2 | N38: 0 | O38: =SUM(C38:L38,N38) -> 24 | P38: =SUM(C38:N38) -> 26
B39: 14.15 - 14.30 | C39: 0 | D39: 1 | E39: 0 | F39: 3 | G39: 0 | H39: 0 | I39: 0 | J39: 0 | K39: 1 | L39: 6 | M39: 7 | N39: 0 | O39: =SUM(C39:L39,N39) -> 11 | P39: =SUM(C39:N39) -> 18
B40: 14.30 - 14.45 | C40: 0 | D40: 5 | E40: 2 | F40: 5 | G40: 0 | H40: 0 | I40: 0 | J40: 0 | K40: 0 | L40: 6 | M40: 4 | N40: 0 | O40: =SUM(C40:L40,N40) -> 18 | P40: =SUM(C40:N40) -> 22
... B57: 18.45 - 19.00 | C57: 0 | D57: 0 | E57: 0 | F57: 1 | G57: 0 | H57: 0 | I57: 5 | J57: 0 | K57: 0 | L57: 8 | M57: 7 | N57: 0 | O57: =SUM(C57:L57,N57) -> 14 | P57: =SUM(C57:N57) -> 21
B58: Totals | C58: =SUM(C10:C57) -> 53 | D58: =SUM(D10:D57) -> 153 | E58: =SUM(E10:E57) -> 52 | F58: =SUM(F10:F57) -> 166 | G58: =SUM(G10:G57) -> 4 | H58: =SUM(H10:H57) -> 6 | I58: =SUM(I10:I57) -> 72 | J58: =SUM(J10:J57) -> 4 | ... P58: =SUM(P10:P57) -> 1182
...

Sheet 22.08 BUSITEMA-TORORO
B1: Consultancy services for Preparation of Expressway Development Master Plan (EDMP) for Uganda
B2: MANUAL CLASSIFIED COUNT (MCC)
B3: ROAD NAME: | C3: ='22.08 TORORO-BUSITEMA'!C3:G3 -> TORORO TO BUSITEMA
C5: Date | D5: 22.08.19 | F5: Location | G5: ='22.08 TORORO-BUSITEMA'!G5:H5 -> STATION 98 | J5: Surveyor | K5: ='22.08 TORORO-BUSITEMA'!K5:L5 -> RWOTHOMIYO NORMAN
C6: Dir. From | D6: BUSITEMA | F6: Dir. To | G6: TORORO | J6: Supervisor | K6: ='22.08 TORORO-BUSITEMA'!K6:L6 -> IVAN
B8: Time / Veh Type | R8: SUMMARY TRAFFIC VOLUMES
C9: 1. Car | D9: 2. Station Wagon | E9: 3. Pickups | F9: 4. Minibus, matatu | G9: 5. Medium bus | H9: 6. Large Bus | I9: 7. Light Truck | J9: 8. Medium Truck | K9: 9. Heavy truck | L9: 10. Truck Trailer | M9: 11. Motor cycles | N9: 12. Tractors | O9: Total Excl M/Cycles | P9: Total All | R9: Time | S9: 1. Car | T9: 2. Station Wagon | U9: 3. Pickups | V9: 4. Minibus, matatu | W9: 5. Medium bus | X9: 6. Large Bus | Y9: 7. Light Truck | Z9: 8. Medium Truck | AA9: 9. Heavy truck | AB9: 10. Truck Trailer | AC9: 11. Motorcycles | AD9: 12. Tractors, Graders | AE9: Total Excl M/ Cycles | AF9: Total All
B10: 07.00 - 07.15 | C10: 0 | D10: 0 | E10: 0 | F10: 0 | G10: 0 | H10: 0 | I10: 1 | J10: 2 | K10: 2 | L10: 5 | M10: 0 | N10: 0 | O10: =SUM(C10:L10,N10) -> 10 | P10: =SUM(C10:N10) -> 10 | R10: 0700-0800 | S10: =SUM(C10:C13) -> 2 | T10: =SUM(D10:D13) -> 2 | U10: =SUM(E10:E13) -> 6 | V10: =SUM(F10:F13) -> 2 | W10: =SUM(G10:G13) -> 0 | X10: =SUM(H10:H13) -> 0 | Y10: =SUM(I10:I13) -> 1 | Z10: =SUM(J10:J13) -> 3 | ... AF10: =SUM(P10:P13) -> 56
B11: 07.15 - 07.30 | C11: 0 | D11: 1 | E11: 1 | F11: 0 | G11: 0 | H11: 0 | I11: 0 | J11: 0 | K11: 1 | L11: 7 | M11: 8 | N11: 0 | O11: =SUM(C11:L11,N11) -> 10 | P11: =SUM(C11:N11) -> 18 | R11: 0800-0900 | S11: =SUM(C14:C17) -> 7 | T11: =SUM(D14:D17) -> 6 | U11: =SUM(E14:E17) -> 4 | V11: =SUM(F14:F17) -> 13 | W11: =SUM(G14:G17) -> 1 | X11: =SUM(H14:H17) -> 0 | Y11: =SUM(I14:I17) -> 1 | Z11: =SUM(J14:J17) -> 2 | ... AF11: =SUM(P14:P17) -> 91
B12: 07.30 - 07.45 | C12: 2 | D12: 1 | E12: 4 | F12: 2 | G12: 0 | H12: 0 | I12: 0 | J12: 1 | K12: 2 | L12: 4 | M12: 3 | N12: 0 | O12: =SUM(C12:L12,N12) -> 16 | P12: =SUM(C12:N12) -> 19 | R12: 0900-1000 | S12: =SUM(C18:C21) -> 3 | T12: =SUM(D18:D21) -> 13 | U12: =SUM(E18:E21) -> 1 | V12: =SUM(F18:F21) -> 11 | W12: =SUM(G18:G21) -> 2 | X12: =SUM(H18:H21) -> 0 | Y12: =SUM(I18:I21) -> 7 | Z12: =SUM(J18:J21) -> 0 | ... AF12: =SUM(P18:P21) -> 75
B13: 07.45 - 08.00 | C13: 0 | D13: 0 | E13: 1 | F13: 0 | G13: 0 | H13: 0 | I13: 0 | J13: 0 | K13: 0 | L13: 5 | M13: 3 | N13: 0 | O13: =SUM(C13:L13,N13) -> 6 | P13: =SUM(C13:N13) -> 9 | R13: 1000-1100 | S13: =SUM(C22:C25) -> 3 | T13: =SUM(D22:D25) -> 2 | U13: =SUM(E22:E25) -> 5 | V13: =SUM(F22:F25) -> 8 | W13: =SUM(G22:G25) -> 0 | X13: =SUM(H22:H25) -> 0 | Y13: =SUM(I22:I25) -> 2 | Z13: =SUM(J22:J25) -> 2 | ... AF13: =SUM(P22:P25) -> 51
B14: 08.00 - 08.15 | C14: 2 | D14: 1 | E14: 1 | F14: 3 | G14: 0 | H14: 0 | I14: 0 | J14: 0 | K14: 1 | L14: 6 | M14: 5 | N14: 0 | O14: =SUM(C14:L14,N14) -> 14 | P14: =SUM(C14:N14) -> 19 | R14: 1100-1200 | S14: =SUM(C26:C29) -> 6 | T14: =SUM(D26:D29) -> 8 | U14: =SUM(E26:E29) -> 2 | V14: =SUM(F26:F29) -> 12 | W14: =SUM(G26:G29) -> 4 | X14: =SUM(H26:H29) -> 0 | Y14: =SUM(I26:I29) -> 6 | Z14: =SUM(J26:J29) -> 1 | ... AF14: =SUM(P26:P29) -> 57
B15: 08.15 - 08.30 | C15: 0 | D15: 3 | E15: 0 | F15: 5 | G15: 0 | H15: 0 | I15: 0 | J15: 0 | K15: 0 | L15: 5 | M15: 8 | N15: 0 | O15: =SUM(C15:L15,N15) -> 13 | P15: =SUM(C15:N15) -> 21 | R15: 1200-1300 | S15: =SUM(C30:C33) -> 1 | T15: =SUM(D30:D33) -> 3 | U15: =SUM(E30:E33) -> 6 | V15: =SUM(F30:F33) -> 11 | W15: =SUM(G30:G33) -> 0 | X15: =SUM(H30:H33) -> 2 | Y15: =SUM(I30:I33) -> 4 | Z15: =SUM(J30:J33) -> 1 | ... AF15: =SUM(P30:P33) -> 65
B16: 08.30 - 08.45 | C16: 1 | D16: 1 | E16: 0 | F16: 3 | G16: 1 | H16: 0 | I16: 1 | J16: 2 | K16: 1 | L16: 5 | M16: 4 | N16: 0 | O16: =SUM(C16:L16,N16) -> 15 | P16: =SUM(C16:N16) -> 19 | R16: 1300-1400 | S16: =SUM(C34:C37) -> 10 | T16: =SUM(D34:D37) -> 2 | U16: =SUM(E34:E37) -> 8 | V16: =SUM(F34:F37) -> 18 | W16: =SUM(G34:G37) -> 0 | X16: =SUM(H34:H37) -> 0 | Y16: =SUM(I34:I37) -> 8 | Z16: =SUM(J34:J37) -> 5 | ... AF16: =SUM(P34:P37) -> 75
B17: 08.45 - 9.00 | C17: 4 | D17: 1 | E17: 3 | F17: 2 | G17: 0 | H17: 0 | I17: 0 | J17: 0 | K17: 2 | L17: 8 | M17: 12 | N17: 0 | O17: =SUM(C17:L17,N17) -> 20 | P17: =SUM(C17:N17) -> 32 | R17: 1400-1500 | S17: =SUM(C38:C41) -> 3 | T17: =SUM(D38:D41) -> 5 | U17: =SUM(E38:E41) -> 5 | V17: =SUM(F38:F41) -> 20 | W17: =SUM(G38:G41) -> 0 | X17: =SUM(H38:H41) -> 2 | Y17: =SUM(I38:I41) -> 5 | Z17: =SUM(J38:J41) -> 0 | ... AF17: =SUM(P38:P41) -> 72
B18: 09.00 - 09.15 | C18: 2 | D18: 1 | E18: 1 | F18: 1 | G18: 0 | H18: 0 | I18: 2 | J18: 0 | K18: 0 | L18: 4 | M18: 2 | N18: 0 | O18: =SUM(C18:L18,N18) -> 11 | P18: =SUM(C18:N18) -> 13 | R18: 1500-1600 | S18: =SUM(C42:C45) -> 7 | T18: =SUM(D42:D45) -> 13 | U18: =SUM(E42:E45) -> 2 | V18: =SUM(F42:F45) -> 9 | W18: =SUM(G42:G45) -> 0 | X18: =SUM(H42:H45) -> 0 | Y18: =SUM(I42:I45) -> 4 | Z18: =SUM(J42:J45) -> 1 | ... AF18: =SUM(P42:P45) -> 83
B19: 09.15 - 09.30 | C19: 0 | D19: 6 | E19: 0 | F19: 1 | G19: 0 | H19: 0 | I19: 2 | J19: 0 | K19: 0 | L19: 2 | M19: 2 | N19: 0 | O19: =SUM(C19:L19,N19) -> 11 | P19: =SUM(C19:N19) -> 13 | R19: 1600-1700 | S19: =SUM(C46:C49) -> 2 | T19: =SUM(D46:D49) -> 6 | U19: =SUM(E46:E49) -> 1 | V19: =SUM(F46:F49) -> 11 | W19: =SUM(G46:G49) -> 0 | X19: =SUM(H46:H49) -> 4 | Y19: =SUM(I46:I49) -> 5 | Z19: =SUM(J46:J49) -> 0 | ... AF19: =SUM(P46:P49) -> 100
B20: 09.30 - 09.45 | C20: 1 | D20: 5 | E20: 0 | F20: 6 | G20: 0 | H20: 0 | I20: 3 | J20: 0 | K20: 0 | L20: 13 | M20: 4 | N20: 0 | O20: =SUM(C20:L20,N20) -> 28 | P20: =SUM(C20:N20) -> 32 | R20: 1700-1800 | S20: =SUM(C50:C53) -> 4 | T20: =SUM(D50:D53) -> 3 | U20: =SUM(E50:E53) -> 4 | V20: =SUM(F50:F53) -> 15 | W20: =SUM(G50:G53) -> 0 | X20: =SUM(H50:H53) -> 0 | Y20: =SUM(I50:I53) -> 0 | Z20: =SUM(J50:J53) -> 0 | ... AF20: =SUM(P50:P53) -> 84
B21: 09.45 - 10.00 | C21: 0 | D21: 1 | E21: 0 | F21: 3 | G21: 2 | H21: 0 | I21: 0 | J21: 0 | K21: 0 | L21: 3 | M21: 8 | N21: 0 | O21: =SUM(C21:L21,N21) -> 9 | P21: =SUM(C21:N21) -> 17 | R21: 1800-1900 | S21: =SUM(C54:C57) -> 7 | T21: =SUM(D54:D57) -> 3 | U21: =SUM(E54:E57) -> 13 | V21: =SUM(F54:F57) -> 24 | W21: =SUM(G54:G57) -> 3 | X21: =SUM(H54:H57) -> 0 | Y21: =SUM(I54:I57) -> 10 | Z21: =SUM(J54:J57) -> 9 | ... AF21: =SUM(P54:P57) -> 134
B22: 10.00 - 10.15 | C22: 2 | D22: 0 | E22: 5 | F22: 0 | G22: 0 | H22: 0 | I22: 2 | J22: 0 | K22: 5 | L22: 4 | M22: 1 | N22: 0 | O22: =SUM(C22:L22,N22) -> 18 | P22: =SUM(C22:N22) -> 19 | R22: AM Peak Hr | S22: =MAX(S10:S12) -> 7 | T22: =MAX(T10:T12) -> 13 | U22: =MAX(U10:U12) -> 6 | V22: =MAX(V10:V12) -> 13 | W22: =MAX(W10:W12) -> 2 | X22: =MAX(X10:X12) -> 0 | Y22: =MAX(Y10:Y12) -> 7 | Z22: =MAX(Z10:Z12) -> 3 | ... AF22: =MAX(AF10:AF12) -> 91
B23: 10.15 - 10.30 | C23: 0 | D23: 2 | E23: 0 | F23: 4 | G23: 0 | H23: 0 | I23: 0 | J23: 0 | K23: 0 | L23: 1 | M23: 2 | N23: 0 | O23: =SUM(C23:L23,N23) -> 7 | P23: =SUM(C23:N23) -> 9 | R23: IP Peak Hr | S23: =MAX(S13:S18) -> 10 | T23: =MAX(T13:T18) -> 13 | U23: =MAX(U13:U18) -> 8 | V23: =MAX(V13:V18) -> 20 | W23: =MAX(W13:W18) -> 4 | X23: =MAX(X13:X18) -> 2 | Y23: =MAX(Y13:Y18) -> 8 | Z23: =MAX(Z13:Z18) -> 5 | ... AF23: =MAX(AF13:AF18) -> 83
B24: 10.30 - 10.45 | C24: 0 | D24: 0 | E24: 0 | F24: 2 | G24: 0 | H24: 0 | I24: 0 | J24: 2 | K24: 0 | L24: 5 | M24: 4 | N24: 0 | O24: =SUM(C24:L24,N24) -> 9 | P24: =SUM(C24:N24) -> 13 | R24: PM Peak Hr | S24: =MAX(S19:S21) -> 7 | T24: =MAX(T19:T21) -> 6 | U24: =MAX(U19:U21) -> 13 | V24: =MAX(V19:V21) -> 24 | W24: =MAX(W19:W21) -> 3 | X24: =MAX(X19:X21) -> 4 | Y24: =MAX(Y19:Y21) -> 10 | Z24: =MAX(Z19:Z21) -> 9 | ... AF24: =MAX(AF19:AF21) -> 134
B25: 10.45 - 11.00 | C25: 1 | D25: 0 | E25: 0 | F25: 2 | G25: 0 | H25: 0 | I25: 0 | J25: 0 | K25: 0 | L25: 4 | M25: 3 | N25: 0 | O25: =SUM(C25:L25,N25) -> 7 | P25: =SUM(C25:N25) -> 10 | R25: AM Period | S25: =SUM(S10:S12) -> 12 | T25: =SUM(T10:T12) -> 21 | U25: =SUM(U10:U12) -> 11 | V25: =SUM(V10:V12) -> 26 | W25: =SUM(W10:W12) -> 3 | X25: =SUM(X10:X12) -> 0 | Y25: =SUM(Y10:Y12) -> 9 | Z25: =SUM(Z10:Z12) -> 5 | ... AF25: =SUM(AF10:AF12) -> 222
B26: 11.00 - 11.15 | C26: 0 | D26: 0 | E26: 0 | F26: 0 | G26: 0 | H26: 0 | I26: 1 | J26: 0 | K26: 1 | L26: 1 | M26: 0 | N26: 0 | O26: =SUM(C26:L26,N26) -> 3 | P26: =SUM(C26:N26) -> 3 | R26: IP Period | S26: =SUM(S13:S18) -> 30 | T26: =SUM(T13:T18) -> 33 | U26: =SUM(U13:U18) -> 28 | V26: =SUM(V13:V18) -> 78 | W26: =SUM(W13:W18) -> 4 | X26: =SUM(X13:X18) -> 4 | Y26: =SUM(Y13:Y18) -> 29 | Z26: =SUM(Z13:Z18) -> 10 | ... AF26: =SUM(AF13:AF18) -> 403
B27: 11.15 - 11.30 | C27: 0 | D27: 5 | E27: 0 | F27: 5 | G27: 0 | H27: 0 | I27: 3 | J27: 1 | K27: 0 | L27: 2 | M27: 7 | N27: 0 | O27: =SUM(C27:L27,N27) -> 16 | P27: =SUM(C27:N27) -> 23 | R27: PM Period | S27: =SUM(S19:S21) -> 13 | T27: =SUM(T19:T21) -> 12 | U27: =SUM(U19:U21) -> 18 | V27: =SUM(V19:V21) -> 50 | W27: =SUM(W19:W21) -> 3 | X27: =SUM(X19:X21) -> 4 | Y27: =SUM(Y19:Y21) -> 15 | Z27: =SUM(Z19:Z21) -> 9 | ... AF27: =SUM(AF19:AF21) -> 318
B28: 11.30 - 11.45 | C28: 1 | D28: 1 | E28: 2 | F28: 2 | G28: 0 | H28: 0 | I28: 1 | J28: 0 | K28: 0 | L28: 2 | M28: 2 | N28: 0 | O28: =SUM(C28:L28,N28) -> 9 | P28: =SUM(C28:N28) -> 11 | R28: 12 Hours | S28: =SUM(S10:S21) -> 55 | T28: =SUM(T10:T21) -> 66 | U28: =SUM(U10:U21) -> 57 | V28: =SUM(V10:V21) -> 154 | W28: =SUM(W10:W21) -> 10 | X28: =SUM(X10:X21) -> 8 | Y28: =SUM(Y10:Y21) -> 53 | Z28: =SUM(Z10:Z21) -> 24 | ... AF28: =SUM(AF10:AF21) -> 943
B29: 11.45 - 12.00 | C29: 5 | D29: 2 | E29: 0 | F29: 5 | G29: 4 | H29: 0 | I29: 1 | J29: 0 | K29: 3 | L29: 0 | M29: 0 | N29: 0 | O29: =SUM(C29:L29,N29) -> 20 | P29: =SUM(C29:N29) -> 20
B30: 12.00 - 12.15 | C30: 0 | D30: 0 | E30: 1 | F30: 1 | G30: 0 | H30: 0 | I30: 1 | J30: 1 | K30: 1 | L30: 3 | M30: 0 | N30: 0 | O30: =SUM(C30:L30,N30) -> 8 | P30: =SUM(C30:N30) -> 8
B31: 12.15 - 12.30 | C31: 1 | D31: 1 | E31: 1 | F31: 1 | G31: 0 | H31: 0 | I31: 0 | J31: 0 | K31: 2 | L31: 0 | M31: 1 | N31: 0 | O31: =SUM(C31:L31,N31) -> 6 | P31: =SUM(C31:N31) -> 7
B32: 12.30 - 12.45 | C32: 0 | D32: 1 | E32: 1 | F32: 2 | G32: 0 | H32: 2 | I32: 0 | J32: 0 | K32: 0 | L32: 3 | M32: 2 | N32: 0 | O32: =SUM(C32:L32,N32) -> 9 | P32: =SUM(C32:N32) -> 11
B33: 12.45 - 13.00 | C33: 0 | D33: 1 | E33: 3 | F33: 7 | G33: 0 | H33: 0 | I33: 3 | J33: 0 | K33: 3 | L33: 10 | M33: 12 | N33: 0 | O33: =SUM(C33:L33,N33) -> 27 | P33: =SUM(C33:N33) -> 39
B34: 13.00 - 13.15 | C34: 3 | D34: 1 | E34: 2 | F34: 7 | G34: 0 | H34: 0 | I34: 2 | J34: 1 | K34: 5 | L34: 1 | M34: 2 | N34: 0 | O34: =SUM(C34:L34,N34) -> 22 | P34: =SUM(C34:N34) -> 24
B35: 13.15 - 13.30 | C35: 2 | D35: 0 | E35: 5 | F35: 3 | G35: 0 | H35: 0 | I35: 0 | J35: 1 | K35: 0 | L35: 3 | M35: 5 | N35: 0 | O35: =SUM(C35:L35,N35) -> 14 | P35: =SUM(C35:N35) -> 19
B36: 13.30 - 13.45 | C36: 3 | D36: 0 | E36: 0 | F36: 5 | G36: 0 | H36: 0 | I36: 6 | J36: 3 | K36: 1 | L36: 1 | M36: 0 | N36: 0 | O36: =SUM(C36:L36,N36) -> 19 | P36: =SUM(C36:N36) -> 19
B37: 13.45 - 14.00 | C37: 2 | D37: 1 | E37: 1 | F37: 3 | G37: 0 | H37: 0 | I37: 0 | J37: 0 | K37: 0 | L37: 5 | M37: 1 | N37: 0 | O37: =SUM(C37:L37,N37) -> 12 | P37: =SUM(C37:N37) -> 13
B38: 14.00 - 14.15 | C38: 1 | D38: 1 | E38: 1 | F38: 2 | G38: 0 | H38: 0 | I38: 0 | J38: 0 | K38: 0 | L38: 4 | M38: 8 | N38: 0 | O38: =SUM(C38:L38,N38) -> 9 | P38: =SUM(C38:N38) -> 17
B39: 14.15 - 14.30 | C39: 1 | D39: 3 | E39: 3 | F39: 1 | G39: 0 | H39: 2 | I39: 2 | J39: 0 | K39: 0 | L39: 4 | M39: 6 | N39: 0 | O39: =SUM(C39:L39,N39) -> 16 | P39: =SUM(C39:N39) -> 22
B40: 14.30 - 14.45 | C40: 0 | D40: 1 | E40: 1 | F40: 9 | G40: 0 | H40: 0 | I40: 0 | J40: 0 | K40: 0 | L40: 2 | M40: 6 | N40: 0 | O40: =SUM(C40:L40,N40) -> 13 | P40: =SUM(C40:N40) -> 19
... B57: 18.45 - 19.00 | C57: 3 | D57: 2 | E57: 7 | F57: 13 | G57: 3 | H57: 0 | I57: 2 | J57: 6 | K57: 0 | L57: 7 | M57: 8 | N57: 0 | O57: =SUM(C57:L57,N57) -> 43 | P57: =SUM(C57:N57) -> 51
B58: Totals | C58: =SUM(C10:C57) -> 55 | D58: =SUM(D10:D57) -> 66 | E58: =SUM(E10:E57) -> 57 | F58: =SUM(F10:F57) -> 154 | G58: =SUM(G10:G57) -> 10 | H58: =SUM(H10:H57) -> 8 | I58: =SUM(I10:I57) -> 53 | J58: =SUM(J10:J57) -> 24 | ... P58: =SUM(P10:P57) -> 943
...

Sheet 23.08 BUSITEMA-TORORO
B1: Consultancy services for Preparation of Expressway Development Master Plan (EDMP) for Uganda
B2: MANUAL CLASSIFIED COUNT (MCC)
B3: ROAD NAME: | C3: ='22.08 TORORO-BUSITEMA'!C3:G3 -> TORORO TO BUSITEMA
C5: Date | D5: 23.08.19 | F5: Location | G5: ='22.08 TORORO-BUSITEMA'!G5:H5 -> STATION 98 | J5: Surveyor | K5: ='22.08 TORORO-BUSITEMA'!K5:L5 -> RWOTHOMIYO NORMAN
C6: Dir. From | D6: BUSITEMA | F6: Dir. To | G6: TORORO | J6: Supervisor | K6: ='22.08 TORORO-BUSITEMA'!K6:L6 -> IVAN
B8: Time / Veh Type | R8: SUMMARY TRAFFIC VOLUMES
C9: 1. Car | D9: 2. Station Wagon | E9: 3. Pickups | F9: 4. Minibus, matatu | G9: 5. Medium bus | H9: 6. Large Bus | I9: 7. Light Truck | J9: 8. Medium Truck | K9: 9. Heavy truck | L9: 10. Truck Trailer | M9: 11. Motor cycles | N9: 12. Tractors | O9: Total Excl M/Cycles | P9: Total All | R9: Time | S9: 1. Car | T9: 2. Station Wagon | U9: 3. Pickups | V9: 4. Minibus, matatu | W9: 5. Medium bus | X9: 6. Large Bus | Y9: 7. Light Truck | Z9: 8. Medium Truck | AA9: 9. Heavy truck | AB9: 10. Truck Trailer | AC9: 11. Motorcycles | AD9: 12. Tractors, Graders | AE9: Total Excl M/ Cycles | AF9: Total All
B10: 07.00 - 07.15 | C10: 0 | D10: 0 | E10: 0 | F10: 7 | G10: 0 | H10: 0 | I10: 0 | J10: 0 | K10: 3 | L10: 11 | M10: 3 | N10: 0 | O10: =SUM(C10:L10,N10) -> 21 | P10: =SUM(C10:N10) -> 24 | R10: 0700-0800 | S10: =SUM(C10:C13) -> 3 | T10: =SUM(D10:D13) -> 6 | U10: =SUM(E10:E13) -> 1 | V10: =SUM(F10:F13) -> 14 | W10: =SUM(G10:G13) -> 0 | X10: =SUM(H10:H13) -> 0 | Y10: =SUM(I10:I13) -> 0 | Z10: =SUM(J10:J13) -> 0 | ... AF10: =SUM(P10:P13) -> 87
B11: 07.15 - 07.30 | C11: 3 | D11: 0 | E11: 1 | F11: 0 | G11: 0 | H11: 0 | I11: 0 | J11: 0 | K11: 0 | L11: 9 | M11: 4 | N11: 0 | O11: =SUM(C11:L11,N11) -> 13 | P11: =SUM(C11:N11) -> 17 | R11: 0800-0900 | S11: =SUM(C14:C17) -> 3 | T11: =SUM(D14:D17) -> 10 | U11: =SUM(E14:E17) -> 4 | V11: =SUM(F14:F17) -> 13 | W11: =SUM(G14:G17) -> 0 | X11: =SUM(H14:H17) -> 0 | Y11: =SUM(I14:I17) -> 0 | Z11: =SUM(J14:J17) -> 1 | ... AF11: =SUM(P14:P17) -> 75
B12: 07.30 - 07.45 | C12: 0 | D12: 3 | E12: 0 | F12: 4 | G12: 0 | H12: 0 | I12: 0 | J12: 0 | K12: 0 | L12: 20 | M12: 0 | N12: 0 | O12: =SUM(C12:L12,N12) -> 27 | P12: =SUM(C12:N12) -> 27 | R12: 0900-1000 | S12: =SUM(C18:C21) -> 2 | T12: =SUM(D18:D21) -> 7 | U12: =SUM(E18:E21) -> 2 | V12: =SUM(F18:F21) -> 13 | W12: =SUM(G18:G21) -> 0 | X12: =SUM(H18:H21) -> 0 | Y12: =SUM(I18:I21) -> 5 | Z12: =SUM(J18:J21) -> 0 | ... AF12: =SUM(P18:P21) -> 61
B13: 07.45 - 08.00 | C13: 0 | D13: 3 | E13: 0 | F13: 3 | G13: 0 | H13: 0 | I13: 0 | J13: 0 | K13: 0 | L13: 6 | M13: 7 | N13: 0 | O13: =SUM(C13:L13,N13) -> 12 | P13: =SUM(C13:N13) -> 19 | R13: 1000-1100 | S13: =SUM(C22:C25) -> 5 | T13: =SUM(D22:D25) -> 11 | U13: =SUM(E22:E25) -> 0 | V13: =SUM(F22:F25) -> 16 | W13: =SUM(G22:G25) -> 0 | X13: =SUM(H22:H25) -> 0 | Y13: =SUM(I22:I25) -> 2 | Z13: =SUM(J22:J25) -> 0 | ... AF13: =SUM(P22:P25) -> 58
B14: 08.00 - 08.15 | C14: 0 | D14: 2 | E14: 1 | F14: 3 | G14: 0 | H14: 0 | I14: 0 | J14: 0 | K14: 0 | L14: 4 | M14: 0 | N14: 0 | O14: =SUM(C14:L14,N14) -> 10 | P14: =SUM(C14:N14) -> 10 | R14: 1100-1200 | S14: =SUM(C26:C29) -> 5 | T14: =SUM(D26:D29) -> 8 | U14: =SUM(E26:E29) -> 3 | V14: =SUM(F26:F29) -> 12 | W14: =SUM(G26:G29) -> 0 | X14: =SUM(H26:H29) -> 0 | Y14: =SUM(I26:I29) -> 1 | Z14: =SUM(J26:J29) -> 3 | ... AF14: =SUM(P26:P29) -> 77
B15: 08.15 - 08.30 | C15: 0 | D15: 3 | E15: 0 | F15: 1 | G15: 0 | H15: 0 | I15: 0 | J15: 1 | K15: 0 | L15: 8 | M15: 1 | N15: 0 | O15: =SUM(C15:L15,N15) -> 13 | P15: =SUM(C15:N15) -> 14 | R15: 1200-1300 | S15: =SUM(C30:C33) -> 3 | T15: =SUM(D30:D33) -> 15 | U15: =SUM(E30:E33) -> 0 | V15: =SUM(F30:F33) -> 17 | W15: =SUM(G30:G33) -> 0 | X15: =SUM(H30:H33) -> 0 | Y15: =SUM(I30:I33) -> 2 | Z15: =SUM(J30:J33) -> 0 | ... AF15: =SUM(P30:P33) -> 60
B16: 08.30 - 08.45 | C16: 0 | D16: 0 | E16: 1 | F16: 0 | G16: 0 | H16: 0 | I16: 0 | J16: 0 | K16: 0 | L16: 1 | M16: 0 | N16: 0 | O16: =SUM(C16:L16,N16) -> 2 | P16: =SUM(C16:N16) -> 2 | R16: 1300-1400 | S16: =SUM(C34:C37) -> 7 | T16: =SUM(D34:D37) -> 8 | U16: =SUM(E34:E37) -> 1 | V16: =SUM(F34:F37) -> 15 | W16: =SUM(G34:G37) -> 0 | X16: =SUM(H34:H37) -> 0 | Y16: =SUM(I34:I37) -> 4 | Z16: =SUM(J34:J37) -> 3 | ... AF16: =SUM(P34:P37) -> 82
B17: 08.45 - 9.00 | C17: 3 | D17: 5 | E17: 2 | F17: 9 | G17: 0 | H17: 0 | I17: 0 | J17: 0 | K17: 0 | L17: 23 | M17: 7 | N17: 0 | O17: =SUM(C17:L17,N17) -> 42 | P17: =SUM(C17:N17) -> 49 | R17: 1400-1500 | S17: =SUM(C38:C41) -> 4 | T17: =SUM(D38:D41) -> 7 | U17: =SUM(E38:E41) -> 5 | V17: =SUM(F38:F41) -> 30 | W17: =SUM(G38:G41) -> 2 | X17: =SUM(H38:H41) -> 0 | Y17: =SUM(I38:I41) -> 12 | Z17: =SUM(J38:J41) -> 5 | ... AF17: =SUM(P38:P41) -> 116
B18: 09.00 - 09.15 | C18: 0 | D18: 0 | E18: 0 | F18: 0 | G18: 0 | H18: 0 | I18: 0 | J18: 0 | K18: 0 | L18: 0 | M18: 0 | N18: 0 | O18: =SUM(C18:L18,N18) -> 0 | P18: =SUM(C18:N18) -> 0 | R18: 1500-1600 | S18: =SUM(C42:C45) -> 3 | T18: =SUM(D42:D45) -> 4 | U18: =SUM(E42:E45) -> 5 | V18: =SUM(F42:F45) -> 35 | W18: =SUM(G42:G45) -> 0 | X18: =SUM(H42:H45) -> 0 | Y18: =SUM(I42:I45) -> 13 | Z18: =SUM(J42:J45) -> 8 | ... AF18: =SUM(P42:P45) -> 151
B19: 09.15 - 09.30 | C19: 1 | D19: 3 | E19: 1 | F19: 4 | G19: 0 | H19: 0 | I19: 5 | J19: 0 | K19: 2 | L19: 12 | M19: 2 | N19: 0 | O19: =SUM(C19:L19,N19) -> 28 | P19: =SUM(C19:N19) -> 30 | R19: 1600-1700 | S19: =SUM(C46:C49) -> 10 | T19: =SUM(D46:D49) -> 16 | U19: =SUM(E46:E49) -> 7 | V19: =SUM(F46:F49) -> 13 | W19: =SUM(G46:G49) -> 0 | X19: =SUM(H46:H49) -> 0 | Y19: =SUM(I46:I49) -> 4 | Z19: =SUM(J46:J49) -> 0 | ... AF19: =SUM(P46:P49) -> 129
B20: 09.30 - 09.45 | C20: 0 | D20: 4 | E20: 0 | F20: 6 | G20: 0 | H20: 0 | I20: 0 | J20: 0 | K20: 1 | L20: 4 | M20: 3 | N20: 0 | O20: =SUM(C20:L20,N20) -> 15 | P20: =SUM(C20:N20) -> 18 | R20: 1700-1800 | S20: =SUM(C50:C53) -> 8 | T20: =SUM(D50:D53) -> 16 | U20: =SUM(E50:E53) -> 5 | V20: =SUM(F50:F53) -> 21 | W20: =SUM(G50:G53) -> 0 | X20: =SUM(H50:H53) -> 0 | Y20: =SUM(I50:I53) -> 9 | Z20: =SUM(J50:J53) -> 4 | ... AF20: =SUM(P50:P53) -> 125
B21: 09.45 - 10.00 | C21: 1 | D21: 0 | E21: 1 | F21: 3 | G21: 0 | H21: 0 | I21: 0 | J21: 0 | K21: 2 | L21: 2 | M21: 4 | N21: 0 | O21: =SUM(C21:L21,N21) -> 9 | P21: =SUM(C21:N21) -> 13 | R21: 1800-1900 | S21: =SUM(C54:C57) -> 14 | T21: =SUM(D54:D57) -> 9 | U21: =SUM(E54:E57) -> 10 | V21: =SUM(F54:F57) -> 24 | W21: =SUM(G54:G57) -> 1 | X21: =SUM(H54:H57) -> 5 | Y21: =SUM(I54:I57) -> 14 | Z21: =SUM(J54:J57) -> 4 | ... AF21: =SUM(P54:P57) -> 178
B22: 10.00 - 10.15 | C22: 0 | D22: 2 | E22: 0 | F22: 3 | G22: 0 | H22: 0 | I22: 1 | J22: 0 | K22: 3 | L22: 5 | M22: 0 | N22: 0 | O22: =SUM(C22:L22,N22) -> 14 | P22: =SUM(C22:N22) -> 14 | R22: AM Peak Hr | S22: =MAX(S10:S12) -> 3 | T22: =MAX(T10:T12) -> 10 | U22: =MAX(U10:U12) -> 4 | V22: =MAX(V10:V12) -> 14 | W22: =MAX(W10:W12) -> 0 | X22: =MAX(X10:X12) -> 0 | Y22: =MAX(Y10:Y12) -> 5 | Z22: =MAX(Z10:Z12) -> 1 | ... AF22: =MAX(AF10:AF12) -> 87
B23: 10.15 - 10.30 | C23: 2 | D23: 4 | E23: 0 | F23: 2 | G23: 0 | H23: 0 | I23: 1 | J23: 0 | K23: 0 | L23: 2 | M23: 2 | N23: 0 | O23: =SUM(C23:L23,N23) -> 11 | P23: =SUM(C23:N23) -> 13 | R23: IP Peak Hr | S23: =MAX(S13:S18) -> 7 | T23: =MAX(T13:T18) -> 15 | U23: =MAX(U13:U18) -> 5 | V23: =MAX(V13:V18) -> 35 | W23: =MAX(W13:W18) -> 2 | X23: =MAX(X13:X18) -> 0 | Y23: =MAX(Y13:Y18) -> 13 | Z23: =MAX(Z13:Z18) -> 8 | ... AF23: =MAX(AF13:AF18) -> 151
B24: 10.30 - 10.45 | C24: 0 | D24: 1 | E24: 0 | F24: 5 | G24: 0 | H24: 0 | I24: 0 | J24: 0 | K24: 0 | L24: 1 | M24: 1 | N24: 0 | O24: =SUM(C24:L24,N24) -> 7 | P24: =SUM(C24:N24) -> 8 | R24: PM Peak Hr | S24: =MAX(S19:S21) -> 14 | T24: =MAX(T19:T21) -> 16 | U24: =MAX(U19:U21) -> 10 | V24: =MAX(V19:V21) -> 24 | W24: =MAX(W19:W21) -> 1 | X24: =MAX(X19:X21) -> 5 | Y24: =MAX(Y19:Y21) -> 14 | Z24: =MAX(Z19:Z21) -> 4 | ... AF24: =MAX(AF19:AF21) -> 178
B25: 10.45 - 11.00 | C25: 3 | D25: 4 | E25: 0 | F25: 6 | G25: 0 | H25: 0 | I25: 0 | J25: 0 | K25: 0 | L25: 5 | M25: 5 | N25: 0 | O25: =SUM(C25:L25,N25) -> 18 | P25: =SUM(C25:N25) -> 23 | R25: AM Period | S25: =SUM(S10:S12) -> 8 | T25: =SUM(T10:T12) -> 23 | U25: =SUM(U10:U12) -> 7 | V25: =SUM(V10:V12) -> 40 | W25: =SUM(W10:W12) -> 0 | X25: =SUM(X10:X12) -> 0 | Y25: =SUM(Y10:Y12) -> 5 | Z25: =SUM(Z10:Z12) -> 1 | ... AF25: =SUM(AF10:AF12) -> 223
B26: 11.00 - 11.15 | C26: 3 | D26: 1 | E26: 2 | F26: 2 | G26: 0 | H26: 0 | I26: 0 | J26: 2 | K26: 0 | L26: 6 | M26: 11 | N26: 0 | O26: =SUM(C26:L26,N26) -> 16 | P26: =SUM(C26:N26) -> 27 | R26: IP Period | S26: =SUM(S13:S18) -> 27 | T26: =SUM(T13:T18) -> 53 | U26: =SUM(U13:U18) -> 14 | V26: =SUM(V13:V18) -> 125 | W26: =SUM(W13:W18) -> 2 | X26: =SUM(X13:X18) -> 0 | Y26: =SUM(Y13:Y18) -> 34 | Z26: =SUM(Z13:Z18) -> 19 | ... AF26: =SUM(AF13:AF18) -> 544
B27: 11.15 - 11.30 | C27: 0 | D27: 1 | E27: 1 | F27: 3 | G27: 0 | H27: 0 | I27: 0 | J27: 1 | K27: 3 | L27: 2 | M27: 0 | N27: 0 | O27: =SUM(C27:L27,N27) -> 11 | P27: =SUM(C27:N27) -> 11 | R27: PM Period | S27: =SUM(S19:S21) -> 32 | T27: =SUM(T19:T21) -> 41 | U27: =SUM(U19:U21) -> 22 | V27: =SUM(V19:V21) -> 58 | W27: =SUM(W19:W21) -> 1 | X27: =SUM(X19:X21) -> 5 | Y27: =SUM(Y19:Y21) -> 27 | Z27: =SUM(Z19:Z21) -> 8 | ... AF27: =SUM(AF19:AF21) -> 432
B28: 11.30 - 11.45 | C28: 0 | D28: 6 | E28: 0 | F28: 1 | G28: 0 | H28: 0 | I28: 1 | J28: 0 | K28: 1 | L28: 2 | M28: 9 | N28: 0 | O28: =SUM(C28:L28,N28) -> 11 | P28: =SUM(C28:N28) -> 20 | R28: 12 Hours | S28: =SUM(S10:S21) -> 67 | T28: =SUM(T10:T21) -> 117 | U28: =SUM(U10:U21) -> 43 | V28: =SUM(V10:V21) -> 223 | W28: =SUM(W10:W21) -> 3 | X28: =SUM(X10:X21) -> 5 | Y28: =SUM(Y10:Y21) -> 66 | Z28: =SUM(Z10:Z21) -> 28 | ... AF28: =SUM(AF10:AF21) -> 1199
B29: 11.45 - 12.00 | C29: 2 | D29: 0 | E29: 0 | F29: 6 | G29: 0 | H29: 0 | I29: 0 | J29: 0 | K29: 3 | L29: 3 | M29: 5 | N29: 0 | O29: =SUM(C29:L29,N29) -> 14 | P29: =SUM(C29:N29) -> 19
B30: 12.00 - 12.15 | C30: 1 | D30: 4 | E30: 0 | F30: 4 | G30: 0 | H30: 0 | I30: 1 | J30: 0 | K30: 1 | L30: 2 | M30: 3 | N30: 0 | O30: =SUM(C30:L30,N30) -> 13 | P30: =SUM(C30:N30) -> 16
B31: 12.15 - 12.30 | C31: 1 | D31: 3 | E31: 0 | F31: 4 | G31: 0 | H31: 0 | I31: 0 | J31: 0 | K31: 0 | L31: 6 | M31: 1 | N31: 0 | O31: =SUM(C31:L31,N31) -> 14 | P31: =SUM(C31:N31) -> 15
B32: 12.30 - 12.45 | C32: 0 | D32: 5 | E32: 0 | F32: 5 | G32: 0 | H32: 0 | I32: 1 | J32: 0 | K32: 2 | L32: 1 | M32: 1 | N32: 0 | O32: =SUM(C32:L32,N32) -> 14 | P32: =SUM(C32:N32) -> 15
B33: 12.45 - 13.00 | C33: 1 | D33: 3 | E33: 0 | F33: 4 | G33: 0 | H33: 0 | I33: 0 | J33: 0 | K33: 0 | L33: 0 | M33: 6 | N33: 0 | O33: =SUM(C33:L33,N33) -> 8 | P33: =SUM(C33:N33) -> 14
B34: 13.00 - 13.15 | C34: 3 | D34: 2 | E34: 0 | F34: 3 | G34: 0 | H34: 0 | I34: 1 | J34: 1 | K34: 3 | L34: 2 | M34: 8 | N34: 0 | O34: =SUM(C34:L34,N34) -> 15 | P34: =SUM(C34:N34) -> 23
B35: 13.15 - 13.30 | C35: 2 | D35: 1 | E35: 1 | F35: 4 | G35: 0 | H35: 0 | I35: 2 | J35: 0 | K35: 1 | L35: 3 | M35: 4 | N35: 0 | O35: =SUM(C35:L35,N35) -> 14 | P35: =SUM(C35:N35) -> 18
B36: 13.30 - 13.45 | C36: 0 | D36: 1 | E36: 0 | F36: 4 | G36: 0 | H36: 0 | I36: 0 | J36: 1 | K36: 0 | L36: 4 | M36: 5 | N36: 0 | O36: =SUM(C36:L36,N36) -> 10 | P36: =SUM(C36:N36) -> 15
B37: 13.45 - 14.00 | C37: 2 | D37: 4 | E37: 0 | F37: 4 | G37: 0 | H37: 0 | I37: 1 | J37: 1 | K37: 0 | L37: 4 | M37: 10 | N37: 0 | O37: =SUM(C37:L37,N37) -> 16 | P37: =SUM(C37:N37) -> 26
B38: 14.00 - 14.15 | C38: 0 | D38: 1 | E38: 3 | F38: 11 | G38: 2 | H38: 0 | I38: 7 | J38: 3 | K38: 4 | L38: 8 | M38: 3 | N38: 0 | O38: =SUM(C38:L38,N38) -> 39 | P38: =SUM(C38:N38) -> 42
B39: 14.15 - 14.30 | C39: 4 | D39: 2 | E39: 0 | F39: 10 | G39: 0 | H39: 0 | I39: 3 | J39: 2 | K39: 2 | L39: 9 | M39: 7 | N39: 0 | O39: =SUM(C39:L39,N39) -> 32 | P39: =SUM(C39:N39) -> 39
B40: 14.30 - 14.45 | C40: 0 | D40: 3 | E40: 0 | F40: 7 | G40: 0 | H40: 0 | I40: 2 | J40: 0 | K40: 0 | L40: 2 | M40: 4 | N40: 0 | O40: =SUM(C40:L40,N40) -> 14 | P40: =SUM(C40:N40) -> 18
... B57: 18.45 - 19.00 | C57: 1 | D57: 1 | E57: 0 | F57: 3 | G57: 0 | H57: 0 | I57: 0 | J57: 0 | K57: 0 | L57: 9 | M57: 7 | N57: 0 | O57: =SUM(C57:L57,N57) -> 14 | P57: =SUM(C57:N57) -> 21
B58: Totals | C58: =SUM(C10:C57) -> 67 | D58: =SUM(D10:D57) -> 117 | E58: =SUM(E10:E57) -> 43 | F58: =SUM(F10:F57) -> 223 | G58: =SUM(G10:G57) -> 3 | H58: =SUM(H10:H57) -> 5 | I58: =SUM(I10:I57) -> 66 | J58: =SUM(J10:J57) -> 28 | ... P58: =SUM(P10:P57) -> 1199
...

Sheet 23.08 TORORO-BUSITEMA
B1: Consultancy services for Preparation of Expressway Development Master Plan (EDMP) for Uganda
B2: MANUAL CLASSIFIED COUNT (MCC)
B3: ROAD NAME: | C3: ='22.08 BUSITEMA-TORORO'!C3:G3 -> TORORO TO BUSITEMA
C5: Date | D5: ='23.08 BUSITEMA-TORORO'!D5 -> 23.08.19 | F5: Location | G5: ='22.08 TORORO-BUSITEMA'!G5:H5 -> STATION 98 | J5: Surveyor | K5: AMONY JOVANA BELLA
C6: Dir. From | D6: TORORO | F6: Dir. To | G6: BUSITEMA | J6: Supervisor | K6: ='22.08 TORORO-BUSITEMA'!K6:L6 -> IVAN
B8: Time / Veh Type | R8: SUMMARY TRAFFIC VOLUMES
C9: 1. Car | D9: 2. Station Wagon | E9: 3. Pickups | F9: 4. Minibus, matatu | G9: 5. Medium bus | H9: 6. Large Bus | I9: 7. Light Truck | J9: 8. Medium Truck | K9: 9. Heavy truck | L9: 10. Truck Trailer | M9: 11. Motor cycles | N9: 12. Tractors | O9: Total Excl M/Cycles | P9: Total All | R9: Time | S9: 1. Car | T9: 2. Station Wagon | U9: 3. Pickups | V9: 4. Minibus, matatu | W9: 5. Medium bus | X9: 6. Large Bus | Y9: 7. Light Truck | Z9: 8. Medium Truck | AA9: 9. Heavy truck | AB9: 10. Truck Trailer | AC9: 11. Motorcycles | AD9: 12. Tractors, Graders | AE9: Total Excl M/ Cycles | AF9: Total All
B10: 07.00 - 07.15 | C10: 1 | D10: 2 | E10: 0 | F10: 7 | G10: 0 | H10: 1 | I10: 0 | J10: 0 | K10: 3 | L10: 23 | M10: 2 | N10: 0 | O10: =SUM(C10:L10,N10) -> 37 | P10: =SUM(C10:N10) -> 39 | R10: 0700-0800 | S10: =SUM(C10:C13) -> 1 | T10: =SUM(D10:D13) -> 6 | U10: =SUM(E10:E13) -> 7 | V10: =SUM(F10:F13) -> 15 | W10: =SUM(G10:G13) -> 0 | X10: =SUM(H10:H13) -> 1 | Y10: =SUM(I10:I13) -> 0 | Z10: =SUM(J10:J13) -> 0 | ... AF10: =SUM(P10:P13) -> 101
B11: 07.15 - 07.30 | C11: 0 | D11: 0 | E11: 5 | F11: 0 | G11: 0 | H11: 0 | I11: 0 | J11: 0 | K11: 0 | L11: 17 | M11: 0 | N11: 0 | O11: =SUM(C11:L11,N11) -> 22 | P11: =SUM(C11:N11) -> 22 | R11: 0800-0900 | S11: =SUM(C14:C17) -> 4 | T11: =SUM(D14:D17) -> 6 | U11: =SUM(E14:E17) -> 1 | V11: =SUM(F14:F17) -> 8 | W11: =SUM(G14:G17) -> 1 | X11: =SUM(H14:H17) -> 0 | Y11: =SUM(I14:I17) -> 1 | Z11: =SUM(J14:J17) -> 3 | ... AF11: =SUM(P14:P17) -> 77
B12: 07.30 - 07.45 | C12: 0 | D12: 2 | E12: 1 | F12: 6 | G12: 0 | H12: 0 | I12: 0 | J12: 0 | K12: 2 | L12: 15 | M12: 0 | N12: 0 | O12: =SUM(C12:L12,N12) -> 26 | P12: =SUM(C12:N12) -> 26 | R12: 0900-1000 | S12: =SUM(C18:C21) -> 7 | T12: =SUM(D18:D21) -> 7 | U12: =SUM(E18:E21) -> 2 | V12: =SUM(F18:F21) -> 13 | W12: =SUM(G18:G21) -> 0 | X12: =SUM(H18:H21) -> 1 | Y12: =SUM(I18:I21) -> 1 | Z12: =SUM(J18:J21) -> 8 | ... AF12: =SUM(P18:P21) -> 100
B13: 07.45 - 08.00 | C13: 0 | D13: 2 | E13: 1 | F13: 2 | G13: 0 | H13: 0 | I13: 0 | J13: 0 | K13: 1 | L13: 8 | M13: 0 | N13: 0 | O13: =SUM(C13:L13,N13) -> 14 | P13: =SUM(C13:N13) -> 14 | R13: 1000-1100 | S13: =SUM(C22:C25) -> 16 | T13: =SUM(D22:D25) -> 8 | U13: =SUM(E22:E25) -> 5 | V13: =SUM(F22:F25) -> 19 | W13: =SUM(G22:G25) -> 0 | X13: =SUM(H22:H25) -> 0 | Y13: =SUM(I22:I25) -> 1 | Z13: =SUM(J22:J25) -> 4 | ... AF13: =SUM(P22:P25) -> 101
B14: 08.00 - 08.15 | C14: 1 | D14: 4 | E14: 1 | F14: 4 | G14: 1 | H14: 0 | I14: 0 | J14: 0 | K14: 1 | L14: 9 | M14: 0 | N14: 0 | O14: =SUM(C14:L14,N14) -> 21 | P14: =SUM(C14:N14) -> 21 | R14: 1100-1200 | S14: =SUM(C26:C29) -> 22 | T14: =SUM(D26:D29) -> 20 | U14: =SUM(E26:E29) -> 3 | V14: =SUM(F26:F29) -> 17 | W14: =SUM(G26:G29) -> 0 | X14: =SUM(H26:H29) -> 0 | Y14: =SUM(I26:I29) -> 3 | Z14: =SUM(J26:J29) -> 5 | ... AF14: =SUM(P26:P29) -> 122
B15: 08.15 - 08.30 | C15: 1 | D15: 0 | E15: 0 | F15: 1 | G15: 0 | H15: 0 | I15: 1 | J15: 0 | K15: 0 | L15: 12 | M15: 3 | N15: 0 | O15: =SUM(C15:L15,N15) -> 15 | P15: =SUM(C15:N15) -> 18 | R15: 1200-1300 | S15: =SUM(C30:C33) -> 12 | T15: =SUM(D30:D33) -> 18 | U15: =SUM(E30:E33) -> 3 | V15: =SUM(F30:F33) -> 17 | W15: =SUM(G30:G33) -> 0 | X15: =SUM(H30:H33) -> 0 | Y15: =SUM(I30:I33) -> 2 | Z15: =SUM(J30:J33) -> 7 | ... AF15: =SUM(P30:P33) -> 106
B16: 08.30 - 08.45 | C16: 1 | D16: 1 | E16: 0 | F16: 2 | G16: 0 | H16: 0 | I16: 0 | J16: 1 | K16: 2 | L16: 10 | M16: 3 | N16: 0 | O16: =SUM(C16:L16,N16) -> 17 | P16: =SUM(C16:N16) -> 20 | R16: 1300-1400 | S16: =SUM(C34:C37) -> 14 | T16: =SUM(D34:D37) -> 9 | U16: =SUM(E34:E37) -> 6 | V16: =SUM(F34:F37) -> 17 | W16: =SUM(G34:G37) -> 1 | X16: =SUM(H34:H37) -> 6 | Y16: =SUM(I34:I37) -> 4 | Z16: =SUM(J34:J37) -> 5 | ... AF16: =SUM(P34:P37) -> 115
B17: 08.45 - 9.00 | C17: 1 | D17: 1 | E17: 0 | F17: 1 | G17: 0 | H17: 0 | I17: 0 | J17: 2 | K17: 1 | L17: 8 | M17: 4 | N17: 0 | O17: =SUM(C17:L17,N17) -> 14 | P17: =SUM(C17:N17) -> 18 | R17: 1400-1500 | S17: =SUM(C38:C41) -> 22 | T17: =SUM(D38:D41) -> 9 | U17: =SUM(E38:E41) -> 3 | V17: =SUM(F38:F41) -> 11 | W17: =SUM(G38:G41) -> 0 | X17: =SUM(H38:H41) -> 1 | Y17: =SUM(I38:I41) -> 3 | Z17: =SUM(J38:J41) -> 9 | ... AF17: =SUM(P38:P41) -> 98
B18: 09.00 - 09.15 | C18: 0 | D18: 0 | E18: 0 | F18: 0 | G18: 0 | H18: 0 | I18: 0 | J18: 2 | K18: 0 | L18: 14 | M18: 3 | N18: 0 | O18: =SUM(C18:L18,N18) -> 16 | P18: =SUM(C18:N18) -> 19 | R18: 1500-1600 | S18: =SUM(C42:C45) -> 11 | T18: =SUM(D42:D45) -> 3 | U18: =SUM(E42:E45) -> 0 | V18: =SUM(F42:F45) -> 18 | W18: =SUM(G42:G45) -> 1 | X18: =SUM(H42:H45) -> 0 | Y18: =SUM(I42:I45) -> 3 | Z18: =SUM(J42:J45) -> 9 | ... AF18: =SUM(P42:P45) -> 96
B19: 09.15 - 09.30 | C19: 2 | D19: 2 | E19: 1 | F19: 5 | G19: 0 | H19: 1 | I19: 0 | J19: 3 | K19: 2 | L19: 12 | M19: 3 | N19: 0 | O19: =SUM(C19:L19,N19) -> 28 | P19: =SUM(C19:N19) -> 31 | R19: 1600-1700 | S19: =SUM(C46:C49) -> 12 | T19: =SUM(D46:D49) -> 7 | U19: =SUM(E46:E49) -> 5 | V19: =SUM(F46:F49) -> 25 | W19: =SUM(G46:G49) -> 0 | X19: =SUM(H46:H49) -> 0 | Y19: =SUM(I46:I49) -> 2 | Z19: =SUM(J46:J49) -> 8 | ... AF19: =SUM(P46:P49) -> 114
B20: 09.30 - 09.45 | C20: 4 | D20: 2 | E20: 1 | F20: 7 | G20: 0 | H20: 0 | I20: 1 | J20: 3 | K20: 1 | L20: 12 | M20: 3 | N20: 0 | O20: =SUM(C20:L20,N20) -> 31 | P20: =SUM(C20:N20) -> 34 | R20: 1700-1800 | S20: =SUM(C50:C53) -> 20 | T20: =SUM(D50:D53) -> 18 | U20: =SUM(E50:E53) -> 5 | V20: =SUM(F50:F53) -> 17 | W20: =SUM(G50:G53) -> 0 | X20: =SUM(H50:H53) -> 0 | Y20: =SUM(I50:I53) -> 7 | Z20: =SUM(J50:J53) -> 12 | ... AF20: =SUM(P50:P53) -> 142
B21: 09.45 - 10.00 | C21: 1 | D21: 3 | E21: 0 | F21: 1 | G21: 0 | H21: 0 | I21: 0 | J21: 0 | K21: 0 | L21: 8 | M21: 3 | N21: 0 | O21: =SUM(C21:L21,N21) -> 13 | P21: =SUM(C21:N21) -> 16 | R21: 1800-1900 | S21: =SUM(C54:C57) -> 15 | T21: =SUM(D54:D57) -> 18 | U21: =SUM(E54:E57) -> 11 | V21: =SUM(F54:F57) -> 10 | W21: =SUM(G54:G57) -> 4 | X21: =SUM(H54:H57) -> 3 | Y21: =SUM(I54:I57) -> 4 | Z21: =SUM(J54:J57) -> 5 | ... AF21: =SUM(P54:P57) -> 142
B22: 10.00 - 10.15 | C22: 2 | D22: 3 | E22: 1 | F22: 6 | G22: 0 | H22: 0 | I22: 1 | J22: 1 | K22: 1 | L22: 11 | M22: 2 | N22: 0 | O22: =SUM(C22:L22,N22) -> 26 | P22: =SUM(C22:N22) -> 28 | R22: AM Peak Hr | S22: =MAX(S10:S12) -> 7 | T22: =MAX(T10:T12) -> 7 | U22: =MAX(U10:U12) -> 7 | V22: =MAX(V10:V12) -> 15 | W22: =MAX(W10:W12) -> 1 | X22: =MAX(X10:X12) -> 1 | Y22: =MAX(Y10:Y12) -> 1 | Z22: =MAX(Z10:Z12) -> 8 | ... AF22: =MAX(AF10:AF12) -> 101
B23: 10.15 - 10.30 | C23: 2 | D23: 1 | E23: 1 | F23: 4 | G23: 0 | H23: 0 | I23: 0 | J23: 3 | K23: 0 | L23: 14 | M23: 2 | N23: 0 | O23: =SUM(C23:L23,N23) -> 25 | P23: =SUM(C23:N23) -> 27 | R23: IP Peak Hr | S23: =MAX(S13:S18) -> 22 | T23: =MAX(T13:T18) -> 20 | U23: =MAX(U13:U18) -> 6 | V23: =MAX(V13:V18) -> 19 | W23: =MAX(W13:W18) -> 1 | X23: =MAX(X13:X18) -> 6 | Y23: =MAX(Y13:Y18) -> 4 | Z23: =MAX(Z13:Z18) -> 9 | ... AF23: =MAX(AF13:AF18) -> 122
B24: 10.30 - 10.45 | C24: 5 | D24: 2 | E24: 0 | F24: 3 | G24: 0 | H24: 0 | I24: 0 | J24: 0 | K24: 2 | L24: 6 | M24: 3 | N24: 0 | O24: =SUM(C24:L24,N24) -> 18 | P24: =SUM(C24:N24) -> 21 | R24: PM Peak Hr | S24: =MAX(S19:S21) -> 20 | T24: =MAX(T19:T21) -> 18 | U24: =MAX(U19:U21) -> 11 | V24: =MAX(V19:V21) -> 25 | W24: =MAX(W19:W21) -> 4 | X24: =MAX(X19:X21) -> 3 | Y24: =MAX(Y19:Y21) -> 7 | Z24: =MAX(Z19:Z21) -> 12 | ... AF24: =MAX(AF19:AF21) -> 142
B25: 10.45 - 11.00 | C25: 7 | D25: 2 | E25: 3 | F25: 6 | G25: 0 | H25: 0 | I25: 0 | J25: 0 | K25: 0 | L25: 5 | M25: 2 | N25: 0 | O25: =SUM(C25:L25,N25) -> 23 | P25: =SUM(C25:N25) -> 25 | R25: AM Period | S25: =SUM(S10:S12) -> 12 | T25: =SUM(T10:T12) -> 19 | U25: =SUM(U10:U12) -> 10 | V25: =SUM(V10:V12) -> 36 | W25: =SUM(W10:W12) -> 1 | X25: =SUM(X10:X12) -> 2 | Y25: =SUM(Y10:Y12) -> 2 | Z25: =SUM(Z10:Z12) -> 11 | ... AF25: =SUM(AF10:AF12) -> 278
B26: 11.00 - 11.15 | C26: 5 | D26: 8 | E26: 0 | F26: 5 | G26: 0 | H26: 0 | I26: 3 | J26: 2 | K26: 1 | L26: 10 | M26: 2 | N26: 0 | O26: =SUM(C26:L26,N26) -> 34 | P26: =SUM(C26:N26) -> 36 | R26: IP Period | S26: =SUM(S13:S18) -> 97 | T26: =SUM(T13:T18) -> 67 | U26: =SUM(U13:U18) -> 20 | V26: =SUM(V13:V18) -> 99 | W26: =SUM(W13:W18) -> 2 | X26: =SUM(X13:X18) -> 7 | Y26: =SUM(Y13:Y18) -> 16 | Z26: =SUM(Z13:Z18) -> 39 | ... AF26: =SUM(AF13:AF18) -> 638
B27: 11.15 - 11.30 | C27: 3 | D27: 2 | E27: 2 | F27: 5 | G27: 0 | H27: 0 | I27: 0 | J27: 0 | K27: 0 | L27: 7 | M27: 2 | N27: 0 | O27: =SUM(C27:L27,N27) -> 19 | P27: =SUM(C27:N27) -> 21 | R27: PM Period | S27: =SUM(S19:S21) -> 47 | T27: =SUM(T19:T21) -> 43 | U27: =SUM(U19:U21) -> 21 | V27: =SUM(V19:V21) -> 52 | W27: =SUM(W19:W21) -> 4 | X27: =SUM(X19:X21) -> 3 | Y27: =SUM(Y19:Y21) -> 13 | Z27: =SUM(Z19:Z21) -> 25 | ... AF27: =SUM(AF19:AF21) -> 398
B28: 11.30 - 11.45 | C28: 8 | D28: 5 | E28: 1 | F28: 4 | G28: 0 | H28: 0 | I28: 0 | J28: 3 | K28: 1 | L28: 10 | M28: 5 | N28: 0 | O28: =SUM(C28:L28,N28) -> 32 | P28: =SUM(C28:N28) -> 37 | R28: 12 Hours | S28: =SUM(S10:S21) -> 156 | T28: =SUM(T10:T21) -> 129 | U28: =SUM(U10:U21) -> 51 | V28: =SUM(V10:V21) -> 187 | W28: =SUM(W10:W21) -> 7 | X28: =SUM(X10:X21) -> 12 | Y28: =SUM(Y10:Y21) -> 31 | Z28: =SUM(Z10:Z21) -> 75 | ... AF28: =SUM(AF10:AF21) -> 1314
B29: 11.45 - 12.00 | C29: 6 | D29: 5 | E29: 0 | F29: 3 | G29: 0 | H29: 0 | I29: 0 | J29: 0 | K29: 0 | L29: 7 | M29: 7 | N29: 0 | O29: =SUM(C29:L29,N29) -> 21 | P29: =SUM(C29:N29) -> 28
B30: 12.00 - 12.15 | C30: 2 | D30: 4 | E30: 0 | F30: 5 | G30: 0 | H30: 0 | I30: 0 | J30: 1 | K30: 3 | L30: 3 | M30: 4 | N30: 0 | O30: =SUM(C30:L30,N30) -> 18 | P30: =SUM(C30:N30) -> 22
B31: 12.15 - 12.30 | C31: 3 | D31: 2 | E31: 1 | F31: 4 | G31: 0 | H31: 0 | I31: 2 | J31: 4 | K31: 2 | L31: 4 | M31: 1 | N31: 0 | O31: =SUM(C31:L31,N31) -> 22 | P31: =SUM(C31:N31) -> 23
B32: 12.30 - 12.45 | C32: 4 | D32: 7 | E32: 1 | F32: 5 | G32: 0 | H32: 0 | I32: 0 | J32: 1 | K32: 1 | L32: 11 | M32: 5 | N32: 0 | O32: =SUM(C32:L32,N32) -> 30 | P32: =SUM(C32:N32) -> 35
B33: 12.45 - 13.00 | C33: 3 | D33: 5 | E33: 1 | F33: 3 | G33: 0 | H33: 0 | I33: 0 | J33: 1 | K33: 0 | L33: 10 | M33: 3 | N33: 0 | O33: =SUM(C33:L33,N33) -> 23 | P33: =SUM(C33:N33) -> 26
B34: 13.00 - 13.15 | C34: 1 | D34: 1 | E34: 0 | F34: 4 | G34: 0 | H34: 0 | I34: 0 | J34: 0 | K34: 1 | L34: 9 | M34: 4 | N34: 0 | O34: =SUM(C34:L34,N34) -> 16 | P34: =SUM(C34:N34) -> 20
B35: 13.15 - 13.30 | C35: 2 | D35: 3 | E35: 2 | F35: 3 | G35: 1 | H35: 4 | I35: 3 | J35: 1 | K35: 0 | L35: 3 | M35: 2 | N35: 0 | O35: =SUM(C35:L35,N35) -> 22 | P35: =SUM(C35:N35) -> 24
B36: 13.30 - 13.45 | C36: 6 | D36: 1 | E36: 0 | F36: 5 | G36: 0 | H36: 2 | I36: 1 | J36: 0 | K36: 0 | L36: 14 | M36: 1 | N36: 0 | O36: =SUM(C36:L36,N36) -> 29 | P36: =SUM(C36:N36) -> 30
B37: 13.45 - 14.00 | C37: 5 | D37: 4 | E37: 4 | F37: 5 | G37: 0 | H37: 0 | I37: 0 | J37: 4 | K37: 2 | L37: 14 | M37: 3 | N37: 0 | O37: =SUM(C37:L37,N37) -> 38 | P37: =SUM(C37:N37) -> 41
B38: 14.00 - 14.15 | C38: 4 | D38: 3 | E38: 2 | F38: 3 | G38: 0 | H38: 0 | I38: 0 | J38: 5 | K38: 0 | L38: 9 | M38: 2 | N38: 0 | O38: =SUM(C38:L38,N38) -> 26 | P38: =SUM(C38:N38) -> 28
B39: 14.15 - 14.30 | C39: 7 | D39: 3 | E39: 0 | F39: 1 | G39: 0 | H39: 0 | I39: 0 | J39: 0 | K39: 0 | L39: 6 | M39: 1 | N39: 0 | O39: =SUM(C39:L39,N39) -> 17 | P39: =SUM(C39:N39) -> 18
B40: 14.30 - 14.45 | C40: 6 | D40: 3 | E40: 0 | F40: 6 | G40: 0 | H40: 1 | I40: 1 | J40: 3 | K40: 2 | L40: 11 | M40: 1 | N40: 0 | O40: =SUM(C40:L40,N40) -> 33 | P40: =SUM(C40:N40) -> 34
... B57: 18.45 - 19.00 | C57: 8 | D57: 3 | E57: 5 | F57: 2 | G57: 1 | H57: 0 | I57: 1 | J57: 0 | K57: 4 | L57: 7 | M57: 5 | N57: 0 | O57: =SUM(C57:L57,N57) -> 31 | P57: =SUM(C57:N57) -> 36
B58: Totals | C58: =SUM(C10:C57) -> 156 | D58: =SUM(D10:D57) -> 129 | E58: =SUM(E10:E57) -> 51 | F58: =SUM(F10:F57) -> 187 | G58: =SUM(G10:G57) -> 7 | H58: =SUM(H10:H57) -> 12 | I58: =SUM(I10:I57) -> 31 | J58: =SUM(J10:J57) -> 75 | ... P58: =SUM(P10:P57) -> 1314
...

Sheet 24.08 BUSITEMA-TORORO-24h
B1: Consultancy services for Preparation of Expressway Development Master Plan (EDMP) for Uganda
B2: MANUAL CLASSIFIED COUNT (MCC)
B3: ROAD NAME: | C3: ='22.08 TORORO-BUSITEMA'!C3:G3 -> TORORO TO BUSITEMA
C5: Date | D5: 24.08.19 | F5: Location | G5: ='26.08 TORORO-BUSITEMA'!G5:H5 -> STATION 98 | J5: Surveyor | K5: ='26.08 TORORO-BUSITEMA'!K5:L5 -> AMONY JOVANA BELLA
C6: Dir. From | D6: BUSITEMA | F6: Dir. To | G6: TORORO | J6: Supervisor | K6: ='26.08 TORORO-BUSITEMA'!K6:L6 -> IVAN
B8: Time / Veh Type | R8: SUMMARY TRAFFIC VOLUMES
C9: 1. Car | D9: 2. Station Wagon | E9: 3. Pickups | F9: 4. Minibus, matatu | G9: 5. Medium bus | H9: 6. Large Bus | I9: 7. Light Truck | J9: 8. Medium Truck | K9: 9. Heavy truck | L9: 10. Truck Trailer | M9: 11. Motor cycles | N9: 12. Tractors | O9: Total Excl M/Cycles | P9: Total All | R9: Time | S9: 1. Car | T9: 2. Station Wagon | U9: 3. Pickups | V9: 4. Minibus, matatu | W9: 5. Medium bus | X9: 6. Large Bus | Y9: 7. Light Truck | Z9: 8. Medium Truck | AA9: 9. Heavy truck | AB9: 10. Truck Trailer | AC9: 11. Motorcycles | AD9: 12. Tractors, Graders | AE9: Total Excl M/ Cycles | AF9: Total All
B10: 07.00 - 07.15 | C10: 0 | D10: 0 | E10: 0 | F10: 3 | G10: 0 | H10: 0 | I10: 0 | J10: 0 | K10: 0 | L10: 11 | M10: 5 | N10: 0 | O10: =SUM(C10:L10,N10) -> 14 | P10: =SUM(C10:N10) -> 19 | R10: 0700-0800 | S10: =SUM(C10:C13) -> 6 | T10: =SUM(D10:D13) -> 2 | U10: =SUM(E10:E13) -> 1 | V10: =SUM(F10:F13) -> 9 | W10: =SUM(G10:G13) -> 0 | X10: =SUM(H10:H13) -> 0 | Y10: =SUM(I10:I13) -> 2 | Z10: =SUM(J10:J13) -> 0 | ... AF10: =SUM(P10:P13) -> 74
B11: 07.15 - 07.30 | C11: 1 | D11: 2 | E11: 1 | F11: 4 | G11: 0 | H11: 0 | I11: 0 | J11: 0 | K11: 0 | L11: 12 | M11: 6 | N11: 0 | O11: =SUM(C11:L11,N11) -> 20 | P11: =SUM(C11:N11) -> 26 | R11: 0800-0900 | S11: =SUM(C14:C17) -> 8 | T11: =SUM(D14:D17) -> 10 | U11: =SUM(E14:E17) -> 4 | V11: =SUM(F14:F17) -> 12 | W11: =SUM(G14:G17) -> 0 | X11: =SUM(H14:H17) -> 0 | Y11: =SUM(I14:I17) -> 0 | Z11: =SUM(J14:J17) -> 1 | ... AF11: =SUM(P14:P17) -> 79
B12: 07.30 - 07.45 | C12: 2 | D12: 0 | E12: 0 | F12: 1 | G12: 0 | H12: 0 | I12: 0 | J12: 0 | K12: 1 | L12: 8 | M12: 4 | N12: 0 | O12: =SUM(C12:L12,N12) -> 12 | P12: =SUM(C12:N12) -> 16 | R12: 0900-1000 | S12: =SUM(C18:C21) -> 7 | T12: =SUM(D18:D21) -> 17 | U12: =SUM(E18:E21) -> 4 | V12: =SUM(F18:F21) -> 16 | W12: =SUM(G18:G21) -> 1 | X12: =SUM(H18:H21) -> 0 | Y12: =SUM(I18:I21) -> 5 | Z12: =SUM(J18:J21) -> 2 | ... AF12: =SUM(P18:P21) -> 79
B13: 07.45 - 08.00 | C13: 3 | D13: 0 | E13: 0 | F13: 1 | G13: 0 | H13: 0 | I13: 2 | J13: 0 | K13: 0 | L13: 1 | M13: 6 | N13: 0 | O13: =SUM(C13:L13,N13) -> 7 | P13: =SUM(C13:N13) -> 13 | R13: 1000-1100 | S13: =SUM(C22:C25) -> 0 | T13: =SUM(D22:D25) -> 12 | U13: =SUM(E22:E25) -> 1 | V13: =SUM(F22:F25) -> 13 | W13: =SUM(G22:G25) -> 2 | X13: =SUM(H22:H25) -> 0 | Y13: =SUM(I22:I25) -> 1 | Z13: =SUM(J22:J25) -> 1 | ... AF13: =SUM(P22:P25) -> 69
B14: 08.00 - 08.15 | C14: 4 | D14: 0 | E14: 1 | F14: 1 | G14: 0 | H14: 0 | I14: 0 | J14: 0 | K14: 0 | L14: 6 | M14: 5 | N14: 0 | O14: =SUM(C14:L14,N14) -> 12 | P14: =SUM(C14:N14) -> 17 | R14: 1100-1200 | S14: =SUM(C26:C29) -> 10 | T14: =SUM(D26:D29) -> 15 | U14: =SUM(E26:E29) -> 5 | V14: =SUM(F26:F29) -> 18 | W14: =SUM(G26:G29) -> 2 | X14: =SUM(H26:H29) -> 0 | Y14: =SUM(I26:I29) -> 3 | Z14: =SUM(J26:J29) -> 0 | ... AF14: =SUM(P26:P29) -> 88
B15: 08.15 - 08.30 | C15: 3 | D15: 4 | E15: 0 | F15: 5 | G15: 0 | H15: 0 | I15: 0 | J15: 0 | K15: 0 | L15: 7 | M15: 3 | N15: 1 | O15: =SUM(C15:L15,N15) -> 20 | P15: =SUM(C15:N15) -> 23 | R15: 1200-1300 | S15: =SUM(C30:C33) -> 3 | T15: =SUM(D30:D33) -> 10 | U15: =SUM(E30:E33) -> 5 | V15: =SUM(F30:F33) -> 13 | W15: =SUM(G30:G33) -> 0 | X15: =SUM(H30:H33) -> 0 | Y15: =SUM(I30:I33) -> 2 | Z15: =SUM(J30:J33) -> 1 | ... AF15: =SUM(P30:P33) -> 67
B16: 08.30 - 08.45 | C16: 0 | D16: 4 | E16: 3 | F16: 3 | G16: 0 | H16: 0 | I16: 0 | J16: 0 | K16: 0 | L16: 6 | M16: 5 | N16: 0 | O16: =SUM(C16:L16,N16) -> 16 | P16: =SUM(C16:N16) -> 21 | R16: 1300-1400 | S16: =SUM(C34:C37) -> 7 | T16: =SUM(D34:D37) -> 8 | U16: =SUM(E34:E37) -> 4 | V16: =SUM(F34:F37) -> 12 | W16: =SUM(G34:G37) -> 1 | X16: =SUM(H34:H37) -> 0 | Y16: =SUM(I34:I37) -> 3 | Z16: =SUM(J34:J37) -> 3 | ... AF16: =SUM(P34:P37) -> 89
B17: 08.45 - 9.00 | C17: 1 | D17: 2 | E17: 0 | F17: 3 | G17: 0 | H17: 0 | I17: 0 | J17: 1 | K17: 0 | L17: 8 | M17: 3 | N17: 0 | O17: =SUM(C17:L17,N17) -> 15 | P17: =SUM(C17:N17) -> 18 | R17: 1400-1500 | S17: =SUM(C38:C41) -> 4 | T17: =SUM(D38:D41) -> 4 | U17: =SUM(E38:E41) -> 1 | V17: =SUM(F38:F41) -> 7 | W17: =SUM(G38:G41) -> 0 | X17: =SUM(H38:H41) -> 1 | Y17: =SUM(I38:I41) -> 3 | Z17: =SUM(J38:J41) -> 3 | ... AF17: =SUM(P38:P41) -> 55
B18: 09.00 - 09.15 | C18: 3 | D18: 5 | E18: 1 | F18: 4 | G18: 1 | H18: 0 | I18: 2 | J18: 2 | K18: 2 | L18: 0 | M18: 3 | N18: 0 | O18: =SUM(C18:L18,N18) -> 20 | P18: =SUM(C18:N18) -> 23 | R18: 1500-1600 | S18: =SUM(C42:C45) -> 2 | T18: =SUM(D42:D45) -> 11 | U18: =SUM(E42:E45) -> 0 | V18: =SUM(F42:F45) -> 17 | W18: =SUM(G42:G45) -> 1 | X18: =SUM(H42:H45) -> 0 | Y18: =SUM(I42:I45) -> 4 | Z18: =SUM(J42:J45) -> 2 | ... AF18: =SUM(P42:P45) -> 64
B19: 09.15 - 09.30 | C19: 4 | D19: 5 | E19: 3 | F19: 3 | G19: 0 | H19: 0 | I19: 1 | J19: 0 | K19: 0 | L19: 5 | M19: 1 | N19: 0 | O19: =SUM(C19:L19,N19) -> 21 | P19: =SUM(C19:N19) -> 22 | R19: 1600-1700 | S19: =SUM(C46:C49) -> 3 | T19: =SUM(D46:D49) -> 4 | U19: =SUM(E46:E49) -> 0 | V19: =SUM(F46:F49) -> 8 | W19: =SUM(G46:G49) -> 0 | X19: =SUM(H46:H49) -> 0 | Y19: =SUM(I46:I49) -> 1 | Z19: =SUM(J46:J49) -> 0 | ... AF19: =SUM(P46:P49) -> 55
B20: 09.30 - 09.45 | C20: 0 | D20: 3 | E20: 0 | F20: 7 | G20: 0 | H20: 0 | I20: 1 | J20: 0 | K20: 0 | L20: 2 | M20: 8 | N20: 0 | O20: =SUM(C20:L20,N20) -> 13 | P20: =SUM(C20:N20) -> 21 | R20: 1700-1800 | S20: =SUM(C50:C53) -> 9 | T20: =SUM(D50:D53) -> 17 | U20: =SUM(E50:E53) -> 8 | V20: =SUM(F50:F53) -> 14 | W20: =SUM(G50:G53) -> 2 | X20: =SUM(H50:H53) -> 0 | Y20: =SUM(I50:I53) -> 5 | Z20: =SUM(J50:J53) -> 10 | ... AF20: =SUM(P50:P53) -> 205
B21: 09.45 - 10.00 | C21: 0 | D21: 4 | E21: 0 | F21: 2 | G21: 0 | H21: 0 | I21: 1 | J21: 0 | K21: 0 | L21: 3 | M21: 3 | N21: 0 | O21: =SUM(C21:L21,N21) -> 10 | P21: =SUM(C21:N21) -> 13 | R21: 1800-1900 | S21: =SUM(C54:C57) -> 9 | T21: =SUM(D54:D57) -> 17 | U21: =SUM(E54:E57) -> 3 | V21: =SUM(F54:F57) -> 24 | W21: =SUM(G54:G57) -> 0 | X21: =SUM(H54:H57) -> 0 | Y21: =SUM(I54:I57) -> 12 | Z21: =SUM(J54:J57) -> 0 | ... AF21: =SUM(P54:P57) -> 215
B22: 10.00 - 10.15 | C22: 0 | D22: 3 | E22: 0 | F22: 1 | G22: 0 | H22: 0 | I22: 1 | J22: 0 | K22: 0 | L22: 8 | M22: 0 | N22: 0 | O22: =SUM(C22:L22,N22) -> 13 | P22: =SUM(C22:N22) -> 13 | R22: 1900-2000 | S22: =SUM(C58:C61) -> 5 | T22: =SUM(D58:D61) -> 10 | U22: =SUM(E58:E61) -> 2 | V22: =SUM(F58:F61) -> 13 | W22: =SUM(G58:G61) -> 1 | X22: =SUM(H58:H61) -> 0 | Y22: =SUM(I58:I61) -> 6 | Z22: =SUM(J58:J61) -> 4 | ... AF22: =SUM(P58:P61) -> 127
B23: 10.15 - 10.30 | C23: 0 | D23: 1 | E23: 0 | F23: 2 | G23: 0 | H23: 0 | I23: 0 | J23: 1 | K23: 0 | L23: 7 | M23: 4 | N23: 0 | O23: =SUM(C23:L23,N23) -> 11 | P23: =SUM(C23:N23) -> 15 | R23: 2000-2100 | S23: =SUM(C62:C65) -> 4 | T23: =SUM(D62:D65) -> 8 | U23: =SUM(E62:E65) -> 0 | V23: =SUM(F62:F65) -> 5 | W23: =SUM(G62:G65) -> 0 | X23: =SUM(H62:H65) -> 4 | Y23: =SUM(I62:I65) -> 0 | Z23: =SUM(J62:J65) -> 7 | ... AF23: =SUM(P62:P65) -> 90
B24: 10.30 - 10.45 | C24: 0 | D24: 5 | E24: 1 | F24: 4 | G24: 2 | H24: 0 | I24: 0 | J24: 0 | K24: 2 | L24: 4 | M24: 3 | N24: 0 | O24: =SUM(C24:L24,N24) -> 18 | P24: =SUM(C24:N24) -> 21 | R24: 2100-2200 | S24: =SUM(C66:C69) -> 9 | T24: =SUM(D66:D69) -> 7 | U24: =SUM(E66:E69) -> 2 | V24: =SUM(F66:F69) -> 7 | W24: =SUM(G66:G69) -> 0 | X24: =SUM(H66:H69) -> 0 | Y24: =SUM(I66:I69) -> 4 | Z24: =SUM(J66:J69) -> 5 | ... AF24: =SUM(P66:P69) -> 122
B25: 10.45 - 11.00 | C25: 0 | D25: 3 | E25: 0 | F25: 6 | G25: 0 | H25: 0 | I25: 0 | J25: 0 | K25: 0 | L25: 4 | M25: 7 | N25: 0 | O25: =SUM(C25:L25,N25) -> 13 | P25: =SUM(C25:N25) -> 20 | R25: 2200-2300 | S25: =SUM(C70:C73) -> 3 | T25: =SUM(D70:D73) -> 4 | U25: =SUM(E70:E73) -> 0 | V25: =SUM(F70:F73) -> 7 | W25: =SUM(G70:G73) -> 0 | X25: =SUM(H70:H73) -> 1 | Y25: =SUM(I70:I73) -> 0 | Z25: =SUM(J70:J73) -> 0 | ... AF25: =SUM(P70:P73) -> 77
B26: 11.00 - 11.15 | C26: 3 | D26: 8 | E26: 0 | F26: 8 | G26: 0 | H26: 0 | I26: 3 | J26: 0 | K26: 0 | L26: 1 | M26: 6 | N26: 0 | O26: =SUM(C26:L26,N26) -> 23 | P26: =SUM(C26:N26) -> 29 | R26: 2300-0000 | S26: =SUM(C74:C77) -> 0 | T26: =SUM(D74:D77) -> 5 | U26: =SUM(E74:E77) -> 2 | V26: =SUM(F74:F77) -> 0 | W26: =SUM(G74:G77) -> 0 | X26: =SUM(H74:H77) -> 0 | Y26: =SUM(I74:I77) -> 0 | Z26: =SUM(J74:J77) -> 0 | ... AF26: =SUM(P74:P77) -> 63
B27: 11.15 - 11.30 | C27: 0 | D27: 2 | E27: 1 | F27: 2 | G27: 2 | H27: 0 | I27: 0 | J27: 0 | K27: 0 | L27: 5 | M27: 4 | N27: 0 | O27: =SUM(C27:L27,N27) -> 12 | P27: =SUM(C27:N27) -> 16 | R27: 0000-0100 | S27: =SUM(C78:C81) -> 0 | T27: =SUM(D78:D81) -> 2 | U27: =SUM(E78:E81) -> 1 | V27: =SUM(F78:F81) -> 1 | W27: =SUM(G78:G81) -> 0 | X27: =SUM(H78:H81) -> 0 | Y27: =SUM(I78:I81) -> 0 | Z27: =SUM(J78:J81) -> 0 | ... AF27: =SUM(P78:P81) -> 84
B28: 11.30 - 11.45 | C28: 7 | D28: 3 | E28: 4 | F28: 5 | G28: 0 | H28: 0 | I28: 0 | J28: 0 | K28: 0 | L28: 8 | M28: 4 | N28: 0 | O28: =SUM(C28:L28,N28) -> 27 | P28: =SUM(C28:N28) -> 31 | R28: 0100-0200 | S28: =SUM(C82:C85) -> 2 | T28: =SUM(D82:D85) -> 3 | U28: =SUM(E82:E85) -> 1 | V28: =SUM(F82:F85) -> 2 | W28: =SUM(G82:G85) -> 0 | X28: =SUM(H82:H85) -> 0 | Y28: =SUM(I82:I85) -> 0 | Z28: =SUM(J82:J85) -> 0 | ... AF28: =SUM(P82:P85) -> 32
B29: 11.45 - 12.00 | C29: 0 | D29: 2 | E29: 0 | F29: 3 | G29: 0 | H29: 0 | I29: 0 | J29: 0 | K29: 0 | L29: 5 | M29: 2 | N29: 0 | O29: =SUM(C29:L29,N29) -> 10 | P29: =SUM(C29:N29) -> 12 | R29: 0200-0300 | S29: =SUM(C86:C89) -> 1 | T29: =SUM(D86:D89) -> 4 | U29: =SUM(E86:E89) -> 1 | V29: =SUM(F86:F89) -> 1 | W29: =SUM(G86:G89) -> 0 | X29: =SUM(H86:H89) -> 0 | Y29: =SUM(I86:I89) -> 3 | Z29: =SUM(J86:J89) -> 2 | ... AF29: =SUM(P86:P89) -> 24
B30: 12.00 - 12.15 | C30: 0 | D30: 3 | E30: 0 | F30: 0 | G30: 0 | H30: 0 | I30: 0 | J30: 0 | K30: 0 | L30: 3 | M30: 5 | N30: 0 | O30: =SUM(C30:L30,N30) -> 6 | P30: =SUM(C30:N30) -> 11 | R30: 0300-0400 | S30: =SUM(C90:C93) -> 1 | T30: =SUM(D90:D93) -> 3 | U30: =SUM(E90:E93) -> 0 | V30: =SUM(F90:F93) -> 1 | W30: =SUM(G90:G93) -> 1 | X30: =SUM(H90:H93) -> 1 | Y30: =SUM(I90:I93) -> 0 | Z30: =SUM(J90:J93) -> 0 | ... AF30: =SUM(P90:P93) -> 25
