Workbook

Sheet 22.07 Bwaise-Kawempe
B1: Consultancy services for Preparation of Expressway Development Master Plan (EDMP) for Uganda
B2: MANUAL CLASSIFIED COUNT (MCC)
B3: ROAD NAME: | C3: MCC - C1 - STN23 - BOMBO ROAD
C5: Date | D5: 22.07.19 | F5: Location | G5: Before Steel and Tube | J5: Surveyor | K5: Kajjubi Eddie
C6: Dir. From | D6: Bwaise | F6: Dir. To | G6: Kawempe | J6: Supervisor | K6: Salima
B8: Time / Veh Type | R8: SUMMARY TRAFFIC VOLUMES
C9: 1. Car | D9: 2. Station Wagon | E9: 3. Pickups | F9: 4. Minibus, matatu | G9: 5. Medium bus | H9: 6. Large Bus | I9: 7. Light Truck | J9: 8. Medium Truck | K9: 9. Heavy truck | L9: 10. Truck Trailer | M9: 11. Motor cycles | N9: 12. Tractors | O9: Total Excl M/Cycles | P9: Total All | R9: Time | S9: 1. Car | T9: 2. Station Wagon | U9: 3. Pickups | V9: 4. Minibus, matatu | W9: 5. Medium bus | X9: 6. Large Bus | Y9: 7. Light Truck | Z9: 8. Medium Truck | AA9: 9. Heavy truck | AB9: 10. Truck Trailer | AC9: 11. Motorcycles | AD9: 12. Tractors, Graders | AE9: Total Excl M/ Cycles | AF9: Total All
B10: 07.00 - 07.15 | C10: 28 | D10: 2 | E10: 5 | F10: 39 | G10: 2 | H10: 1 | I10: 4 | J10: 4 | K10: 0 | L10: 1 | M10: 149 | N10: 0 | O10: =SUM(C10:L10,N10) -> 86 | P10: =SUM(C10:N10) -> 235 | R10: 0700-0800 | S10: =SUM(C10:C13) -> 114 | T10: =SUM(D10:D13) -> 14 | U10: =SUM(E10:E13) -> 22 | V10: =SUM(F10:F13) -> 181 | W10: =SUM(G10:G13) -> 7 | X10: =SUM(H10:H13) -> 3 | Y10: =SUM(I10:I13) -> 16 | Z10: =SUM(J10:J13) -> 6 | ... AF10: =SUM(P10:P13) -> 977
B11: 07.15 - 07.30 | C11: 22 | D11: 3 | E11: 4 | F11: 44 | G11: 2 | H11: 2 | I11: 3 | J11: 2 | K11: 0 | L11: 0 | M11: 173 | N11: 0 | O11: =SUM(C11:L11,N11) -> 82 | P11: =SUM(C11:N11) -> 255 | R11: 0800-0900 | S11: =SUM(C14:C17) -> 102 | T11: =SUM(D14:D17) -> 22 | U11: =SUM(E14:E17) -> 18 | V11: =SUM(F14:F17) -> 218 | W11: =SUM(G14:G17) -> 5 | X11: =SUM(H14:H17) -> 3 | Y11: =SUM(I14:I17) -> 22 | Z11: =SUM(J14:J17) -> 5 | ... AF11: =SUM(P14:P17) -> 1106
B12: 07.30 - 07.45 | C12: 30 | D12: 3 | E12: 3 | F12: 49 | G12: 0 | H12: 0 | I12: 6 | J12: 0 | K12: 1 | L12: 0 | M12: 156 | N12: 0 | O12: =SUM(C12:L12,N12) -> 92 | P12: =SUM(C12:N12) -> 248 | R12: 0900-1000 | S12: =SUM(C18:C21) -> 141 | T12: =SUM(D18:D21) -> 33 | U12: =SUM(E18:E21) -> 26 | V12: =SUM(F18:F21) -> 233 | W12: =SUM(G18:G21) -> 5 | X12: =SUM(H18:H21) -> 1 | Y12: =SUM(I18:I21) -> 40 | Z12: =SUM(J18:J21) -> 10 | ... AF12: =SUM(P18:P21) -> 1154
B13: 07.45 - 08.00 | C13: 34 | D13: 6 | E13: 10 | F13: 49 | G13: 3 | H13: 0 | I13: 3 | J13: 0 | K13: 1 | L13: 0 | M13: 133 | N13: 0 | O13: =SUM(C13:L13,N13) -> 106 | P13: =SUM(C13:N13) -> 239 | R13: 1000-1100 | S13: =SUM(C22:C25) -> 127 | T13: =SUM(D22:D25) -> 27 | U13: =SUM(E22:E25) -> 34 | V13: =SUM(F22:F25) -> 202 | W13: =SUM(G22:G25) -> 6 | X13: =SUM(H22:H25) -> 0 | Y13: =SUM(I22:I25) -> 65 | Z13: =SUM(J22:J25) -> 10 | ... AF13: =SUM(P22:P25) -> 942
B14: 08.00 - 08.15 | C14: 24 | D14: 3 | E14: 4 | F14: 30 | G14: 2 | H14: 0 | I14: 5 | J14: 2 | K14: 0 | L14: 3 | M14: 123 | N14: 0 | O14: =SUM(C14:L14,N14) -> 73 | P14: =SUM(C14:N14) -> 196 | R14: 1100-1200 | S14: =SUM(C26:C29) -> 149 | T14: =SUM(D26:D29) -> 16 | U14: =SUM(E26:E29) -> 39 | V14: =SUM(F26:F29) -> 187 | W14: =SUM(G26:G29) -> 4 | X14: =SUM(H26:H29) -> 3 | Y14: =SUM(I26:I29) -> 55 | Z14: =SUM(J26:J29) -> 3 | ... AF14: =SUM(P26:P29) -> 984
B15: 08.15 - 08.30 | C15: 34 | D15: 9 | E15: 3 | F15: 51 | G15: 1 | H15: 1 | I15: 3 | J15: 0 | K15: 1 | L15: 1 | M15: 162 | N15: 0 | O15: =SUM(C15:L15,N15) -> 104 | P15: =SUM(C15:N15) -> 266 | R15: 1200-1300 | S15: =SUM(C30:C33) -> 144 | T15: =SUM(D30:D33) -> 30 | U15: =SUM(E30:E33) -> 25 | V15: =SUM(F30:F33) -> 193 | W15: =SUM(G30:G33) -> 10 | X15: =SUM(H30:H33) -> 4 | Y15: =SUM(I30:I33) -> 51 | Z15: =SUM(J30:J33) -> 19 | ... AF15: =SUM(P30:P33) -> 835
B16: 08.30 - 08.45 | C16: 22 | D16: 7 | E16: 4 | F16: 58 | G16: 1 | H16: 0 | I16: 6 | J16: 1 | K16: 3 | L16: 1 | M16: 205 | N16: 0 | O16: =SUM(C16:L16,N16) -> 103 | P16: =SUM(C16:N16) -> 308 | R16: 1300-1400 | S16: =SUM(C34:C37) -> 163 | T16: =SUM(D34:D37) -> 36 | U16: =SUM(E34:E37) -> 38 | V16: =SUM(F34:F37) -> 188 | W16: =SUM(G34:G37) -> 4 | X16: =SUM(H34:H37) -> 2 | Y16: =SUM(I34:I37) -> 60 | Z16: =SUM(J34:J37) -> 23 | ... AF16: =SUM(P34:P37) -> 844
B17: 08.45 - 9.00 | C17: 22 | D17: 3 | E17: 7 | F17: 79 | G17: 1 | H17: 2 | I17: 8 | J17: 2 | K17: 1 | L17: 2 | M17: 209 | N17: 0 | O17: =SUM(C17:L17,N17) -> 127 | P17: =SUM(C17:N17) -> 336 | R17: 1400-1500 | S17: =SUM(C38:C41) -> 138 | T17: =SUM(D38:D41) -> 31 | U17: =SUM(E38:E41) -> 28 | V17: =SUM(F38:F41) -> 153 | W17: =SUM(G38:G41) -> 6 | X17: =SUM(H38:H41) -> 4 | Y17: =SUM(I38:I41) -> 48 | Z17: =SUM(J38:J41) -> 6 | ... AF17: =SUM(P38:P41) -> 736
B18: 09.00 - 09.15 | C18: 27 | D18: 10 | E18: 8 | F18: 58 | G18: 0 | H18: 1 | I18: 10 | J18: 5 | K18: 4 | L18: 0 | M18: 171 | N18: 0 | O18: =SUM(C18:L18,N18) -> 123 | P18: =SUM(C18:N18) -> 294 | R18: 1500-1600 | S18: =SUM(C42:C45) -> 164 | T18: =SUM(D42:D45) -> 29 | U18: =SUM(E42:E45) -> 35 | V18: =SUM(F42:F45) -> 117 | W18: =SUM(G42:G45) -> 7 | X18: =SUM(H42:H45) -> 2 | Y18: =SUM(I42:I45) -> 52 | Z18: =SUM(J42:J45) -> 23 | ... AF18: =SUM(P42:P45) -> 561
B19: 09.15 - 09.30 | C19: 30 | D19: 9 | E19: 6 | F19: 52 | G19: 2 | H19: 0 | I19: 5 | J19: 3 | K19: 2 | L19: 0 | M19: 180 | N19: 0 | O19: =SUM(C19:L19,N19) -> 109 | P19: =SUM(C19:N19) -> 289 | R19: 1600-1700 | S19: =SUM(C46:C49) -> 171 | T19: =SUM(D46:D49) -> 34 | U19: =SUM(E46:E49) -> 23 | V19: =SUM(F46:F49) -> 187 | W19: =SUM(G46:G49) -> 7 | X19: =SUM(H46:H49) -> 1 | Y19: =SUM(I46:I49) -> 56 | Z19: =SUM(J46:J49) -> 11 | ... AF19: =SUM(P46:P49) -> 899
B20: 09.30 - 09.45 | C20: 43 | D20: 5 | E20: 9 | F20: 68 | G20: 2 | H20: 0 | I20: 13 | J20: 0 | K20: 0 | L20: 4 | M20: 161 | N20: 0 | O20: =SUM(C20:L20,N20) -> 144 | P20: =SUM(C20:N20) -> 305 | R20: 1700-1800 | S20: =SUM(C50:C53) -> 190 | T20: =SUM(D50:D53) -> 28 | U20: =SUM(E50:E53) -> 27 | V20: =SUM(F50:F53) -> 155 | W20: =SUM(G50:G53) -> 2 | X20: =SUM(H50:H53) -> 0 | Y20: =SUM(I50:I53) -> 45 | Z20: =SUM(J50:J53) -> 17 | ... AF20: =SUM(P50:P53) -> 833
B21: 09.45 - 10.00 | C21: 41 | D21: 9 | E21: 3 | F21: 55 | G21: 1 | H21: 0 | I21: 12 | J21: 2 | K21: 2 | L21: 1 | M21: 140 | N21: 0 | O21: =SUM(C21:L21,N21) -> 126 | P21: =SUM(C21:N21) -> 266 | R21: 1800-1900 | S21: =SUM(C54:C57) -> 253 | T21: =SUM(D54:D57) -> 29 | U21: =SUM(E54:E57) -> 18 | V21: =SUM(F54:F57) -> 186 | W21: =SUM(G54:G57) -> 5 | X21: =SUM(H54:H57) -> 2 | Y21: =SUM(I54:I57) -> 48 | Z21: =SUM(J54:J57) -> 8 | ... AF21: =SUM(P54:P57) -> 1263
B22: 10.00 - 10.15 | C22: 24 | D22: 4 | E22: 6 | F22: 45 | G22: 1 | H22: 0 | I22: 13 | J22: 1 | K22: 1 | L22: 1 | M22: 142 | N22: 0 | O22: =SUM(C22:L22,N22) -> 96 | P22: =SUM(C22:N22) -> 238 | R22: AM Peak Hr | S22: =MAX(S10:S12) -> 141 | T22: =MAX(T10:T12) -> 33 | U22: =MAX(U10:U12) -> 26 | V22: =MAX(V10:V12) -> 233 | W22: =MAX(W10:W12) -> 7 | X22: =MAX(X10:X12) -> 3 | Y22: =MAX(Y10:Y12) -> 40 | Z22: =MAX(Z10:Z12) -> 10 | ... AF22: =MAX(AF10:AF12) -> 1154
B23: 10.15 - 10.30 | C23: 39 | D23: 13 | E23: 8 | F23: 63 | G23: 2 | H23: 0 | I23: 20 | J23: 3 | K23: 1 | L23: 1 | M23: 106 | N23: 0 | O23: =SUM(C23:L23,N23) -> 150 | P23: =SUM(C23:N23) -> 256 | R23: IP Peak Hr | S23: =MAX(S13:S18) -> 164 | T23: =MAX(T13:T18) -> 36 | U23: =MAX(U13:U18) -> 39 | V23: =MAX(V13:V18) -> 202 | W23: =MAX(W13:W18) -> 10 | X23: =MAX(X13:X18) -> 4 | Y23: =MAX(Y13:Y18) -> 65 | Z23: =MAX(Z13:Z18) -> 23 | ... AF23: =MAX(AF13:AF18) -> 984
B24: 10.30 - 10.45 | C24: 40 | D24: 4 | E24: 13 | F24: 50 | G24: 2 | H24: 0 | I24: 12 | J24: 0 | K24: 3 | L24: 3 | M24: 115 | N24: 0 | O24: =SUM(C24:L24,N24) -> 127 | P24: =SUM(C24:N24) -> 242 | R24: PM Peak Hr | S24: =MAX(S19:S21) -> 253 | T24: =MAX(T19:T21) -> 34 | U24: =MAX(U19:U21) -> 27 | V24: =MAX(V19:V21) -> 187 | W24: =MAX(W19:W21) -> 7 | X24: =MAX(X19:X21) -> 2 | Y24: =MAX(Y19:Y21) -> 56 | Z24: =MAX(Z19:Z21) -> 17 | ... AF24: =MAX(AF19:AF21) -> 1263
B25: 10.45 - 11.00 | C25: 24 | D25: 6 | E25: 7 | F25: 44 | G25: 1 | H25: 0 | I25: 20 | J25: 6 | K25: 2 | L25: 6 | M25: 90 | N25: 0 | O25: =SUM(C25:L25,N25) -> 116 | P25: =SUM(C25:N25) -> 206 | R25: AM Period | S25: =SUM(S10:S12) -> 357 | T25: =SUM(T10:T12) -> 69 | U25: =SUM(U10:U12) -> 66 | V25: =SUM(V10:V12) -> 632 | W25: =SUM(W10:W12) -> 17 | X25: =SUM(X10:X12) -> 7 | Y25: =SUM(Y10:Y12) -> 78 | Z25: =SUM(Z10:Z12) -> 21 | ... AF25: =SUM(AF10:AF12) -> 3237
B26: 11.00 - 11.15 | C26: 39 | D26: 2 | E26: 12 | F26: 49 | G26: 1 | H26: 0 | I26: 14 | J26: 3 | K26: 2 | L26: 2 | M26: 150 | N26: 0 | O26: =SUM(C26:L26,N26) -> 124 | P26: =SUM(C26:N26) -> 274 | R26: IP Period | S26: =SUM(S13:S18) -> 885 | T26: =SUM(T13:T18) -> 169 | U26: =SUM(U13:U18) -> 199 | V26: =SUM(V13:V18) -> 1040 | W26: =SUM(W13:W18) -> 37 | X26: =SUM(X13:X18) -> 15 | Y26: =SUM(Y13:Y18) -> 331 | Z26: =SUM(Z13:Z18) -> 84 | ... AF26: =SUM(AF13:AF18) -> 4902
B27: 11.15 - 11.30 | C27: 32 | D27: 4 | E27: 7 | F27: 46 | G27: 2 | H27: 3 | I27: 15 | J27: 0 | K27: 1 | L27: 0 | M27: 107 | N27: 0 | O27: =SUM(C27:L27,N27) -> 110 | P27: =SUM(C27:N27) -> 217 | R27: PM Period | S27: =SUM(S19:S21) -> 614 | T27: =SUM(T19:T21) -> 91 | U27: =SUM(U19:U21) -> 68 | V27: =SUM(V19:V21) -> 528 | W27: =SUM(W19:W21) -> 14 | X27: =SUM(X19:X21) -> 3 | Y27: =SUM(Y19:Y21) -> 149 | Z27: =SUM(Z19:Z21) -> 36 | ... AF27: =SUM(AF19:AF21) -> 2995
B28: 11.30 - 11.45 | C28: 33 | D28: 8 | E28: 11 | F28: 40 | G28: 0 | H28: 0 | I28: 14 | J28: 0 | K28: 0 | L28: 9 | M28: 106 | N28: 0 | O28: =SUM(C28:L28,N28) -> 115 | P28: =SUM(C28:N28) -> 221 | R28: 12 Hours | S28: =SUM(S10:S21) -> 1856 | T28: =SUM(T10:T21) -> 329 | U28: =SUM(U10:U21) -> 333 | V28: =SUM(V10:V21) -> 2200 | W28: =SUM(W10:W21) -> 68 | X28: =SUM(X10:X21) -> 25 | Y28: =SUM(Y10:Y21) -> 558 | Z28: =SUM(Z10:Z21) -> 141 | ... AF28: =SUM(AF10:AF21) -> 11134
B29: 11.45 - 12.00 | C29: 45 | D29: 2 | E29: 9 | F29: 52 | G29: 1 | H29: 0 | I29: 12 | J29: 0 | K29: 0 | L29: 1 | M29: 150 | N29: 0 | O29: =SUM(C29:L29,N29) -> 122 | P29: =SUM(C29:N29) -> 272
B30: 12.00 - 12.15 | C30: 41 | D30: 8 | E30: 9 | F30: 63 | G30: 4 | H30: 2 | I30: 18 | J30: 3 | K30: 1 | L30: 5 | M30: 119 | N30: 0 | O30: =SUM(C30:L30,N30) -> 154 | P30: =SUM(C30:N30) -> 273
B31: 12.15 - 12.30 | C31: 22 | D31: 4 | E31: 2 | F31: 43 | G31: 2 | H31: 1 | I31: 5 | J31: 1 | K31: 0 | L31: 1 | M31: 49 | N31: 0 | O31: =SUM(C31:L31,N31) -> 81 | P31: =SUM(C31:N31) -> 130
B32: 12.30 - 12.45 | C32: 39 | D32: 10 | E32: 11 | F32: 42 | G32: 2 | H32: 1 | I32: 13 | J32: 10 | K32: 1 | L32: 3 | M32: 75 | N32: 0 | O32: =SUM(C32:L32,N32) -> 132 | P32: =SUM(C32:N32) -> 207
B33: 12.45 - 13.00 | C33: 42 | D33: 8 | E33: 3 | F33: 45 | G33: 2 | H33: 0 | I33: 15 | J33: 5 | K33: 0 | L33: 0 | M33: 105 | N33: 0 | O33: =SUM(C33:L33,N33) -> 120 | P33: =SUM(C33:N33) -> 225
B34: 13.00 - 13.15 | C34: 42 | D34: 10 | E34: 5 | F34: 50 | G34: 0 | H34: 1 | I34: 19 | J34: 9 | K34: 0 | L34: 4 | M34: 82 | N34: 0 | O34: =SUM(C34:L34,N34) -> 140 | P34: =SUM(C34:N34) -> 222
B35: 13.15 - 13.30 | C35: 31 | D35: 11 | E35: 12 | F35: 38 | G35: 2 | H35: 1 | I35: 19 | J35: 9 | K35: 1 | L35: 3 | M35: 55 | N35: 0 | O35: =SUM(C35:L35,N35) -> 127 | P35: =SUM(C35:N35) -> 182
B36: 13.30 - 13.45 | C36: 39 | D36: 5 | E36: 15 | F36: 44 | G36: 1 | H36: 0 | I36: 11 | J36: 3 | K36: 2 | L36: 4 | M36: 90 | N36: 0 | O36: =SUM(C36:L36,N36) -> 124 | P36: =SUM(C36:N36) -> 214
B37: 13.45 - 14.00 | C37: 51 | D37: 10 | E37: 6 | F37: 56 | G37: 1 | H37: 0 | I37: 11 | J37: 2 | K37: 0 | L37: 1 | M37: 88 | N37: 0 | O37: =SUM(C37:L37,N37) -> 138 | P37: =SUM(C37:N37) -> 226
B38: 14.00 - 14.15 | C38: 46 | D38: 9 | E38: 8 | F38: 28 | G38: 3 | H38: 0 | I38: 12 | J38: 0 | K38: 1 | L38: 3 | M38: 93 | N38: 0 | O38: =SUM(C38:L38,N38) -> 110 | P38: =SUM(C38:N38) -> 203
B39: 14.15 - 14.30 | C39: 28 | D39: 5 | E39: 4 | F39: 40 | G39: 0 | H39: 0 | I39: 12 | J39: 1 | K39: 1 | L39: 1 | M39: 75 | N39: 0 | O39: =SUM(C39:L39,N39) -> 92 | P39: =SUM(C39:N39) -> 167
B40: 14.30 - 14.45 | C40: 36 | D40: 11 | E40: 7 | F40: 39 | G40: 2 | H40: 1 | I40: 13 | J40: 3 | K40: 1 | L40: 2 | M40: 88 | N40: 0 | O40: =SUM(C40:L40,N40) -> 115 | P40: =SUM(C40:N40) -> 203
... B57: 18.45 - 19.00 | C57: 94 | D57: 6 | E57: 3 | F57: 35 | G57: 2 | H57: 0 | I57: 8 | J57: 3 | K57: 1 | L57: 2 | M57: 215 | N57: 0 | O57: =SUM(C57:L57,N57) -> 154 | P57: =SUM(C57:N57) -> 369
B58: Totals | C58: =SUM(C10:C57) -> 1856 | D58: =SUM(D10:D57) -> 329 | E58: =SUM(E10:E57) -> 333 | F58: =SUM(F10:F57) -> 2200 | G58: =SUM(G10:G57) -> 68 | H58: =SUM(H10:H57) -> 25 | I58: =SUM(I10:I57) -> 558 | J58: =SUM(J10:J57) -> 141 | ... P58: =SUM(P10:P57) -> 11134
...

Sheet 22.07 kawempe-Bwaise
B1: Consultancy services for Preparation of Expressway Development Master Plan (EDMP) for Uganda
B2: MANUAL CLASSIFIED COUNT (MCC)
B3: ROAD NAME: | C3: ='22.07 Bwaise-Kawempe'!C3:G3 -> MCC - C1 - STN23 - BOMBO ROAD
C5: Date | D5: ='22.07 Bwaise-Kawempe'!D5 -> 22.07.19 | F5: Location | G5: ='22.07 Bwaise-Kawempe'!G5:H5 -> Before Steel and Tube | J5: Surveyor | K5: Catherine
C6: Dir. From | D6: Kawempe | F6: Dir. To | G6: Bwaise | J6: Supervisor | K6: ='22.07 Bwaise-Kawempe'!K6:L6 -> Salima
B8: Time / Veh Type | R8: SUMMARY TRAFFIC VOLUMES
C9: 1. Car | D9: 2. Station Wagon | E9: 3. Pickups | F9: 4. Minibus, matatu | G9: 5. Medium bus | H9: 6. Large Bus | I9: 7. Light Truck | J9: 8. Medium Truck | K9: 9. Heavy truck | L9: 10. Truck Trailer | M9: 11. Motor cycles | N9: 12. Tractors | O9: Total Excl M/Cycles | P9: Total All | R9: Time | S9: 1. Car | T9: 2. Station Wagon | U9: 3. Pickups | V9: 4. Minibus, matatu | W9: 5. Medium bus | X9: 6. Large Bus | Y9: 7. Light Truck | Z9: 8. Medium Truck | AA9: 9. Heavy truck | AB9: 10. Truck Trailer | AC9: 11. Motorcycles | AD9: 12. Tractors, Graders | AE9: Total Excl M/ Cycles | AF9: Total All
B10: 07.00 - 07.15 | C10: 70 | D10: 14 | E10: 7 | F10: 53 | G10: 5 | H10: 0 | I10: 7 | J10: 3 | K10: 0 | L10: 3 | M10: 380 | N10: 0 | O10: =SUM(C10:L10,N10) -> 162 | P10: =SUM(C10:N10) -> 542 | R10: 0700-0800 | S10: =SUM(C10:C13) -> 230 | T10: =SUM(D10:D13) -> 42 | U10: =SUM(E10:E13) -> 25 | V10: =SUM(F10:F13) -> 177 | W10: =SUM(G10:G13) -> 9 | X10: =SUM(H10:H13) -> 0 | Y10: =SUM(I10:I13) -> 27 | Z10: =SUM(J10:J13) -> 8 | ... AF10: =SUM(P10:P13) -> 1993
B11: 07.15 - 07.30 | C11: 55 | D11: 6 | E11: 8 | F11: 39 | G11: 3 | H11: 0 | I11: 6 | J11: 0 | K11: 4 | L11: 2 | M11: 415 | N11: 0 | O11: =SUM(C11:L11,N11) -> 123 | P11: =SUM(C11:N11) -> 538 | R11: 0800-0900 | S11: =SUM(C14:C17) -> 237 | T11: =SUM(D14:D17) -> 63 | U11: =SUM(E14:E17) -> 28 | V11: =SUM(F14:F17) -> 242 | W11: =SUM(G14:G17) -> 9 | X11: =SUM(H14:H17) -> 1 | Y11: =SUM(I14:I17) -> 39 | Z11: =SUM(J14:J17) -> 14 | ... AF11: =SUM(P14:P17) -> 2191
B12: 07.30 - 07.45 | C12: 51 | D12: 13 | E12: 8 | F12: 50 | G12: 1 | H12: 0 | I12: 6 | J12: 3 | K12: 1 | L12: 2 | M12: 350 | N12: 0 | O12: =SUM(C12:L12,N12) -> 135 | P12: =SUM(C12:N12) -> 485 | R12: 0900-1000 | S12: =SUM(C18:C21) -> 163 | T12: =SUM(D18:D21) -> 49 | U12: =SUM(E18:E21) -> 29 | V12: =SUM(F18:F21) -> 210 | W12: =SUM(G18:G21) -> 2 | X12: =SUM(H18:H21) -> 2 | Y12: =SUM(I18:I21) -> 39 | Z12: =SUM(J18:J21) -> 20 | ... AF12: =SUM(P18:P21) -> 1846
B13: 07.45 - 08.00 | C13: 54 | D13: 9 | E13: 2 | F13: 35 | G13: 0 | H13: 0 | I13: 8 | J13: 2 | K13: 0 | L13: 3 | M13: 315 | N13: 0 | O13: =SUM(C13:L13,N13) -> 113 | P13: =SUM(C13:N13) -> 428 | R13: 1000-1100 | S13: =SUM(C22:C25) -> 160 | T13: =SUM(D22:D25) -> 37 | U13: =SUM(E22:E25) -> 23 | V13: =SUM(F22:F25) -> 217 | W13: =SUM(G22:G25) -> 4 | X13: =SUM(H22:H25) -> 0 | Y13: =SUM(I22:I25) -> 54 | Z13: =SUM(J22:J25) -> 19 | ... AF13: =SUM(P22:P25) -> 1419
B14: 08.00 - 08.15 | C14: 75 | D14: 16 | E14: 10 | F14: 78 | G14: 3 | H14: 0 | I14: 10 | J14: 4 | K14: 1 | L14: 3 | M14: 318 | N14: 0 | O14: =SUM(C14:L14,N14) -> 200 | P14: =SUM(C14:N14) -> 518 | R14: 1100-1200 | S14: =SUM(C26:C29) -> 175 | T14: =SUM(D26:D29) -> 58 | U14: =SUM(E26:E29) -> 32 | V14: =SUM(F26:F29) -> 184 | W14: =SUM(G26:G29) -> 7 | X14: =SUM(H26:H29) -> 0 | Y14: =SUM(I26:I29) -> 54 | Z14: =SUM(J26:J29) -> 12 | ... AF14: =SUM(P26:P29) -> 1372
B15: 08.15 - 08.30 | C15: 55 | D15: 18 | E15: 7 | F15: 56 | G15: 1 | H15: 1 | I15: 8 | J15: 2 | K15: 2 | L15: 5 | M15: 396 | N15: 0 | O15: =SUM(C15:L15,N15) -> 155 | P15: =SUM(C15:N15) -> 551 | R15: 1200-1300 | S15: =SUM(C30:C33) -> 150 | T15: =SUM(D30:D33) -> 37 | U15: =SUM(E30:E33) -> 23 | V15: =SUM(F30:F33) -> 169 | W15: =SUM(G30:G33) -> 7 | X15: =SUM(H30:H33) -> 4 | Y15: =SUM(I30:I33) -> 37 | Z15: =SUM(J30:J33) -> 23 | ... AF15: =SUM(P30:P33) -> 1153
B16: 08.30 - 08.45 | C16: 59 | D16: 15 | E16: 5 | F16: 55 | G16: 2 | H16: 0 | I16: 11 | J16: 5 | K16: 1 | L16: 0 | M16: 465 | N16: 0 | O16: =SUM(C16:L16,N16) -> 153 | P16: =SUM(C16:N16) -> 618 | R16: 1300-1400 | S16: =SUM(C34:C37) -> 124 | T16: =SUM(D34:D37) -> 57 | U16: =SUM(E34:E37) -> 33 | V16: =SUM(F34:F37) -> 161 | W16: =SUM(G34:G37) -> 2 | X16: =SUM(H34:H37) -> 2 | Y16: =SUM(I34:I37) -> 40 | Z16: =SUM(J34:J37) -> 15 | ... AF16: =SUM(P34:P37) -> 1139
B17: 08.45 - 9.00 | C17: 48 | D17: 14 | E17: 6 | F17: 53 | G17: 3 | H17: 0 | I17: 10 | J17: 3 | K17: 3 | L17: 4 | M17: 360 | N17: 0 | O17: =SUM(C17:L17,N17) -> 144 | P17: =SUM(C17:N17) -> 504 | R17: 1400-1500 | S17: =SUM(C38:C41) -> 147 | T17: =SUM(D38:D41) -> 69 | U17: =SUM(E38:E41) -> 29 | V17: =SUM(F38:F41) -> 161 | W17: =SUM(G38:G41) -> 5 | X17: =SUM(H38:H41) -> 3 | Y17: =SUM(I38:I41) -> 38 | Z17: =SUM(J38:J41) -> 17 | ... AF17: =SUM(P38:P41) -> 968
B18: 09.00 - 09.15 | C18: 43 | D18: 14 | E18: 7 | F18: 53 | G18: 0 | H18: 0 | I18: 9 | J18: 3 | K18: 4 | L18: 1 | M18: 243 | N18: 0 | O18: =SUM(C18:L18,N18) -> 134 | P18: =SUM(C18:N18) -> 377 | R18: 1500-1600 | S18: =SUM(C42:C45) -> 133 | T18: =SUM(D42:D45) -> 60 | U18: =SUM(E42:E45) -> 32 | V18: =SUM(F42:F45) -> 189 | W18: =SUM(G42:G45) -> 6 | X18: =SUM(H42:H45) -> 6 | Y18: =SUM(I42:I45) -> 38 | Z18: =SUM(J42:J45) -> 18 | ... AF18: =SUM(P42:P45) -> 660
B19: 09.15 - 09.30 | C19: 45 | D19: 11 | E19: 6 | F19: 48 | G19: 1 | H19: 0 | I19: 10 | J19: 8 | K19: 2 | L19: 0 | M19: 415 | N19: 0 | O19: =SUM(C19:L19,N19) -> 131 | P19: =SUM(C19:N19) -> 546 | R19: 1600-1700 | S19: =SUM(C46:C49) -> 170 | T19: =SUM(D46:D49) -> 80 | U19: =SUM(E46:E49) -> 52 | V19: =SUM(F46:F49) -> 214 | W19: =SUM(G46:G49) -> 7 | X19: =SUM(H46:H49) -> 3 | Y19: =SUM(I46:I49) -> 48 | Z19: =SUM(J46:J49) -> 18 | ... AF19: =SUM(P46:P49) -> 1621
B20: 09.30 - 09.45 | C20: 38 | D20: 9 | E20: 9 | F20: 53 | G20: 0 | H20: 1 | I20: 10 | J20: 3 | K20: 1 | L20: 0 | M20: 330 | N20: 0 | O20: =SUM(C20:L20,N20) -> 124 | P20: =SUM(C20:N20) -> 454 | R20: 1700-1800 | S20: =SUM(C50:C53) -> 97 | T20: =SUM(D50:D53) -> 27 | U20: =SUM(E50:E53) -> 23 | V20: =SUM(F50:F53) -> 154 | W20: =SUM(G50:G53) -> 11 | X20: =SUM(H50:H53) -> 2 | Y20: =SUM(I50:I53) -> 14 | Z20: =SUM(J50:J53) -> 20 | ... AF20: =SUM(P50:P53) -> 1509
B21: 09.45 - 10.00 | C21: 37 | D21: 15 | E21: 7 | F21: 56 | G21: 1 | H21: 1 | I21: 10 | J21: 6 | K21: 5 | L21: 1 | M21: 330 | N21: 0 | O21: =SUM(C21:L21,N21) -> 139 | P21: =SUM(C21:N21) -> 469 | R21: 1800-1900 | S21: =SUM(C54:C57) -> 87 | T21: =SUM(D54:D57) -> 32 | U21: =SUM(E54:E57) -> 21 | V21: =SUM(F54:F57) -> 148 | W21: =SUM(G54:G57) -> 6 | X21: =SUM(H54:H57) -> 2 | Y21: =SUM(I54:I57) -> 23 | Z21: =SUM(J54:J57) -> 17 | ... AF21: =SUM(P54:P57) -> 1482
B22: 10.00 - 10.15 | C22: 45 | D22: 6 | E22: 3 | F22: 37 | G22: 2 | H22: 0 | I22: 11 | J22: 5 | K22: 0 | L22: 2 | M22: 300 | N22: 0 | O22: =SUM(C22:L22,N22) -> 111 | P22: =SUM(C22:N22) -> 411 | R22: AM Peak Hr | S22: =MAX(S10:S12) -> 237 | T22: =MAX(T10:T12) -> 63 | U22: =MAX(U10:U12) -> 29 | V22: =MAX(V10:V12) -> 242 | W22: =MAX(W10:W12) -> 9 | X22: =MAX(X10:X12) -> 2 | Y22: =MAX(Y10:Y12) -> 39 | Z22: =MAX(Z10:Z12) -> 20 | ... AF22: =MAX(AF10:AF12) -> 2191
B23: 10.15 - 10.30 | C23: 39 | D23: 11 | E23: 9 | F23: 54 | G23: 1 | H23: 0 | I23: 13 | J23: 4 | K23: 2 | L23: 4 | M23: 105 | N23: 0 | O23: =SUM(C23:L23,N23) -> 137 | P23: =SUM(C23:N23) -> 242 | R23: IP Peak Hr | S23: =MAX(S13:S18) -> 175 | T23: =MAX(T13:T18) -> 69 | U23: =MAX(U13:U18) -> 33 | V23: =MAX(V13:V18) -> 217 | W23: =MAX(W13:W18) -> 7 | X23: =MAX(X13:X18) -> 6 | Y23: =MAX(Y13:Y18) -> 54 | Z23: =MAX(Z13:Z18) -> 23 | ... AF23: =MAX(AF13:AF18) -> 1419
B24: 10.30 - 10.45 | C24: 30 | D24: 10 | E24: 5 | F24: 56 | G24: 0 | H24: 0 | I24: 14 | J24: 7 | K24: 5 | L24: 3 | M24: 345 | N24: 0 | O24: =SUM(C24:L24,N24) -> 130 | P24: =SUM(C24:N24) -> 475 | R24: PM Peak Hr | S24: =MAX(S19:S21) -> 170 | T24: =MAX(T19:T21) -> 80 | U24: =MAX(U19:U21) -> 52 | V24: =MAX(V19:V21) -> 214 | W24: =MAX(W19:W21) -> 11 | X24: =MAX(X19:X21) -> 3 | Y24: =MAX(Y19:Y21) -> 48 | Z24: =MAX(Z19:Z21) -> 20 | ... AF24: =MAX(AF19:AF21) -> 1621
B25: 10.45 - 11.00 | C25: 46 | D25: 10 | E25: 6 | F25: 70 | G25: 1 | H25: 0 | I25: 16 | J25: 3 | K25: 3 | L25: 3 | M25: 133 | N25: 0 | O25: =SUM(C25:L25,N25) -> 158 | P25: =SUM(C25:N25) -> 291 | R25: AM Period | S25: =SUM(S10:S12) -> 630 | T25: =SUM(T10:T12) -> 154 | U25: =SUM(U10:U12) -> 82 | V25: =SUM(V10:V12) -> 629 | W25: =SUM(W10:W12) -> 20 | X25: =SUM(X10:X12) -> 3 | Y25: =SUM(Y10:Y12) -> 105 | Z25: =SUM(Z10:Z12) -> 42 | ... AF25: =SUM(AF10:AF12) -> 6030
B26: 11.00 - 11.15 | C26: 54 | D26: 12 | E26: 7 | F26: 40 | G26: 0 | H26: 0 | I26: 12 | J26: 4 | K26: 0 | L26: 3 | M26: 118 | N26: 0 | O26: =SUM(C26:L26,N26) -> 132 | P26: =SUM(C26:N26) -> 250 | R26: IP Period | S26: =SUM(S13:S18) -> 889 | T26: =SUM(T13:T18) -> 318 | U26: =SUM(U13:U18) -> 172 | V26: =SUM(V13:V18) -> 1081 | W26: =SUM(W13:W18) -> 31 | X26: =SUM(X13:X18) -> 15 | Y26: =SUM(Y13:Y18) -> 261 | Z26: =SUM(Z13:Z18) -> 104 | ... AF26: =SUM(AF13:AF18) -> 6711
B27: 11.15 - 11.30 | C27: 48 | D27: 18 | E27: 8 | F27: 61 | G27: 1 | H27: 0 | I27: 18 | J27: 1 | K27: 1 | L27: 3 | M27: 288 | N27: 0 | O27: =SUM(C27:L27,N27) -> 159 | P27: =SUM(C27:N27) -> 447 | R27: PM Period | S27: =SUM(S19:S21) -> 354 | T27: =SUM(T19:T21) -> 139 | U27: =SUM(U19:U21) -> 96 | V27: =SUM(V19:V21) -> 516 | W27: =SUM(W19:W21) -> 24 | X27: =SUM(X19:X21) -> 7 | Y27: =SUM(Y19:Y21) -> 85 | Z27: =SUM(Z19:Z21) -> 55 | ... AF27: =SUM(AF19:AF21) -> 4612
B28: 11.30 - 11.45 | C28: 37 | D28: 16 | E28: 8 | F28: 28 | G28: 1 | H28: 0 | I28: 12 | J28: 3 | K28: 3 | L28: 3 | M28: 245 | N28: 0 | O28: =SUM(C28:L28,N28) -> 111 | P28: =SUM(C28:N28) -> 356 | R28: 12 Hours | S28: =SUM(S10:S21) -> 1873 | T28: =SUM(T10:T21) -> 611 | U28: =SUM(U10:U21) -> 350 | V28: =SUM(V10:V21) -> 2226 | W28: =SUM(W10:W21) -> 75 | X28: =SUM(X10:X21) -> 25 | Y28: =SUM(Y10:Y21) -> 451 | Z28: =SUM(Z10:Z21) -> 201 | ... AF28: =SUM(AF10:AF21) -> 17353
B29: 11.45 - 12.00 | C29: 36 | D29: 12 | E29: 9 | F29: 55 | G29: 5 | H29: 0 | I29: 12 | J29: 4 | K29: 4 | L29: 4 | M29: 178 | N29: 0 | O29: =SUM(C29:L29,N29) -> 141 | P29: =SUM(C29:N29) -> 319
B30: 12.00 - 12.15 | C30: 48 | D30: 14 | E30: 10 | F30: 53 | G30: 2 | H30: 0 | I30: 15 | J30: 6 | K30: 5 | L30: 8 | M30: 233 | N30: 0 | O30: =SUM(C30:L30,N30) -> 161 | P30: =SUM(C30:N30) -> 394
B31: 12.15 - 12.30 | C31: 30 | D31: 6 | E31: 6 | F31: 27 | G31: 1 | H31: 0 | I31: 2 | J31: 3 | K31: 0 | L31: 0 | M31: 128 | N31: 0 | O31: =SUM(C31:L31,N31) -> 75 | P31: =SUM(C31:N31) -> 203
B32: 12.30 - 12.45 | C32: 34 | D32: 11 | E32: 3 | F32: 49 | G32: 1 | H32: 3 | I32: 5 | J32: 6 | K32: 1 | L32: 1 | M32: 147 | N32: 0 | O32: =SUM(C32:L32,N32) -> 114 | P32: =SUM(C32:N32) -> 261
B33: 12.45 - 13.00 | C33: 38 | D33: 6 | E33: 4 | F33: 40 | G33: 3 | H33: 1 | I33: 15 | J33: 8 | K33: 4 | L33: 1 | M33: 175 | N33: 0 | O33: =SUM(C33:L33,N33) -> 120 | P33: =SUM(C33:N33) -> 295
B34: 13.00 - 13.15 | C34: 21 | D34: 14 | E34: 7 | F34: 40 | G34: 0 | H34: 0 | I34: 10 | J34: 2 | K34: 5 | L34: 2 | M34: 140 | N34: 0 | O34: =SUM(C34:L34,N34) -> 101 | P34: =SUM(C34:N34) -> 241
B35: 13.15 - 13.30 | C35: 31 | D35: 28 | E35: 10 | F35: 33 | G35: 0 | H35: 0 | I35: 10 | J35: 4 | K35: 5 | L35: 2 | M35: 90 | N35: 0 | O35: =SUM(C35:L35,N35) -> 123 | P35: =SUM(C35:N35) -> 213
B36: 13.30 - 13.45 | C36: 43 | D36: 7 | E36: 9 | F36: 43 | G36: 2 | H36: 1 | I36: 9 | J36: 5 | K36: 2 | L36: 2 | M36: 278 | N36: 0 | O36: =SUM(C36:L36,N36) -> 123 | P36: =SUM(C36:N36) -> 401
B37: 13.45 - 14.00 | C37: 29 | D37: 8 | E37: 7 | F37: 45 | G37: 0 | H37: 1 | I37: 11 | J37: 4 | K37: 1 | L37: 0 | M37: 178 | N37: 0 | O37: =SUM(C37:L37,N37) -> 106 | P37: =SUM(C37:N37) -> 284
B38: 14.00 - 14.15 | C38: 40 | D38: 20 | E38: 9 | F38: 40 | G38: 2 | H38: 2 | I38: 12 | J38: 2 | K38: 2 | L38: 0 | M38: 170 | N38: 0 | O38: =SUM(C38:L38,N38) -> 129 | P38: =SUM(C38:N38) -> 299
B39: 14.15 - 14.30 | C39: 39 | D39: 16 | E39: 5 | F39: 33 | G39: 1 | H39: 1 | I39: 9 | J39: 7 | K39: 0 | L39: 2 | M39: 134 | N39: 0 | O39: =SUM(C39:L39,N39) -> 113 | P39: =SUM(C39:N39) -> 247
B40: 14.30 - 14.45 | C40: 30 | D40: 17 | E40: 7 | F40: 40 | G40: 1 | H40: 0 | I40: 10 | J40: 3 | K40: 3 | L40: 2 | M40: 135 | N40: 0 | O40: =SUM(C40:L40,N40) -> 113 | P40: =SUM(C40:N40) -> 248
... B57: 18.45 - 19.00 | C57: 18 | D57: 8 | E57: 2 | F57: 44 | G57: 2 | H57: 1 | I57: 9 | J57: 10 | K57: 4 | L57: 5 | M57: 275 | N57: 0 | O57: =SUM(C57:L57,N57) -> 103 | P57: =SUM(C57:N57) -> 378
B58: Totals | C58: =SUM(C10:C57) -> 1873 | D58: =SUM(D10:D57) -> 611 | E58: =SUM(E10:E57) -> 350 | F58: =SUM(F10:F57) -> 2226 | G58: =SUM(G10:G57) -> 75 | H58: =SUM(H10:H57) -> 25 | I58: =SUM(I10:I57) -> 451 | J58: =SUM(J10:J57) -> 201 | ... P58: =SUM(P10:P57) -> 17353
...

Sheet 23.07 Bwaise-Kawempe
B1: Consultancy services for Preparation of Expressway Development Master Plan (EDMP) for Uganda
B2: MANUAL CLASSIFIED COUNT (MCC)
B3: ROAD NAME: | C3: ='22.07 Bwaise-Kawempe'!C3:G3 -> MCC - C1 - STN23 - BOMBO ROAD
C5: Date | D5: 23.07.19 | F5: Location | G5: ='22.07 Bwaise-Kawempe'!G5:H5 -> Before Steel and Tube | J5: Surveyor | K5: Kajjubi Eddie
C6: Dir. From | D6: ='22.07 Bwaise-Kawempe'!D6:E6 -> Bwaise | F6: Dir. To | G6: ='22.07 Bwaise-Kawempe'!G6:H6 -> Kawempe | J6: Supervisor | K6: ='22.07 Bwaise-Kawempe'!K6:L6 -> Salima
B8: Time / Veh Type | R8: SUMMARY TRAFFIC VOLUMES
C9: 1. Car | D9: 2. Station Wagon | E9: 3. Pickups | F9: 4. Minibus, matatu | G9: 5. Medium bus | H9: 6. Large Bus | I9: 7. Light Truck | J9: 8. Medium Truck | K9: 9. Heavy truck | L9: 10. Truck Trailer | M9: 11. Motor cycles | N9: 12. Tractors | O9: Total Excl M/Cycles | P9: Total All | R9: Time | S9: 1. Car | T9: 2. Station Wagon | U9: 3. Pickups | V9: 4. Minibus, matatu | W9: 5. Medium bus | X9: 6. Large Bus | Y9: 7. Light Truck | Z9: 8. Medium Truck | AA9: 9. Heavy truck | AB9: 10. Truck Trailer | AC9: 11. Motorcycles | AD9: 12. Tractors, Graders | AE9: Total Excl M/ Cycles | AF9: Total All
B10: 07.00 - 07.15 | C10: 24 | D10: 5 | E10: 7 | F10: 27 | G10: 1 | H10: 1 | I10: 5 | J10: 4 | K10: 1 | L10: 2 | M10: 101 | N10: 0 | O10: =SUM(C10:L10,N10) -> 77 | P10: =SUM(C10:N10) -> 178 | R10: 0700-0800 | S10: =SUM(C10:C13) -> 87 | T10: =SUM(D10:D13) -> 14 | U10: =SUM(E10:E13) -> 14 | V10: =SUM(F10:F13) -> 118 | W10: =SUM(G10:G13) -> 6 | X10: =SUM(H10:H13) -> 3 | Y10: =SUM(I10:I13) -> 17 | Z10: =SUM(J10:J13) -> 6 | ... AF10: =SUM(P10:P13) -> 833
B11: 07.15 - 07.30 | C11: 27 | D11: 3 | E11: 1 | F11: 26 | G11: 0 | H11: 2 | I11: 4 | J11: 1 | K11: 1 | L11: 0 | M11: 100 | N11: 0 | O11: =SUM(C11:L11,N11) -> 65 | P11: =SUM(C11:N11) -> 165 | R11: 0800-0900 | S11: =SUM(C14:C17) -> 101 | T11: =SUM(D14:D17) -> 11 | U11: =SUM(E14:E17) -> 16 | V11: =SUM(F14:F17) -> 173 | W11: =SUM(G14:G17) -> 10 | X11: =SUM(H14:H17) -> 5 | Y11: =SUM(I14:I17) -> 32 | Z11: =SUM(J14:J17) -> 13 | ... AF11: =SUM(P14:P17) -> 1044
B12: 07.30 - 07.45 | C12: 12 | D12: 3 | E12: 3 | F12: 32 | G12: 2 | H12: 0 | I12: 3 | J12: 1 | K12: 0 | L12: 0 | M12: 170 | N12: 0 | O12: =SUM(C12:L12,N12) -> 56 | P12: =SUM(C12:N12) -> 226 | R12: 0900-1000 | S12: =SUM(C18:C21) -> 123 | T12: =SUM(D18:D21) -> 31 | U12: =SUM(E18:E21) -> 31 | V12: =SUM(F18:F21) -> 213 | W12: =SUM(G18:G21) -> 5 | X12: =SUM(H18:H21) -> 2 | Y12: =SUM(I18:I21) -> 32 | Z12: =SUM(J18:J21) -> 9 | ... AF12: =SUM(P18:P21) -> 1067
B13: 07.45 - 08.00 | C13: 24 | D13: 3 | E13: 3 | F13: 33 | G13: 3 | H13: 0 | I13: 5 | J13: 0 | K13: 0 | L13: 3 | M13: 190 | N13: 0 | O13: =SUM(C13:L13,N13) -> 74 | P13: =SUM(C13:N13) -> 264 | R13: 1000-1100 | S13: =SUM(C22:C25) -> 125 | T13: =SUM(D22:D25) -> 28 | U13: =SUM(E22:E25) -> 29 | V13: =SUM(F22:F25) -> 154 | W13: =SUM(G22:G25) -> 11 | X13: =SUM(H22:H25) -> 1 | Y13: =SUM(I22:I25) -> 46 | Z13: =SUM(J22:J25) -> 9 | ... AF13: =SUM(P22:P25) -> 902
B14: 08.00 - 08.15 | C14: 20 | D14: 3 | E14: 4 | F14: 49 | G14: 6 | H14: 2 | I14: 10 | J14: 3 | K14: 2 | L14: 3 | M14: 145 | N14: 0 | O14: =SUM(C14:L14,N14) -> 102 | P14: =SUM(C14:N14) -> 247 | R14: 1100-1200 | S14: =SUM(C26:C29) -> 150 | T14: =SUM(D26:D29) -> 39 | U14: =SUM(E26:E29) -> 35 | V14: =SUM(F26:F29) -> 186 | W14: =SUM(G26:G29) -> 7 | X14: =SUM(H26:H29) -> 6 | Y14: =SUM(I26:I29) -> 44 | Z14: =SUM(J26:J29) -> 6 | ... AF14: =SUM(P26:P29) -> 916
B15: 08.15 - 08.30 | C15: 25 | D15: 4 | E15: 5 | F15: 38 | G15: 3 | H15: 1 | I15: 10 | J15: 2 | K15: 2 | L15: 5 | M15: 160 | N15: 0 | O15: =SUM(C15:L15,N15) -> 95 | P15: =SUM(C15:N15) -> 255 | R15: 1200-1300 | S15: =SUM(C30:C33) -> 110 | T15: =SUM(D30:D33) -> 23 | U15: =SUM(E30:E33) -> 18 | V15: =SUM(F30:F33) -> 140 | W15: =SUM(G30:G33) -> 4 | X15: =SUM(H30:H33) -> 3 | Y15: =SUM(I30:I33) -> 51 | Z15: =SUM(J30:J33) -> 10 | ... AF15: =SUM(P30:P33) -> 750
B16: 08.30 - 08.45 | C16: 31 | D16: 2 | E16: 1 | F16: 37 | G16: 1 | H16: 0 | I16: 8 | J16: 4 | K16: 1 | L16: 2 | M16: 175 | N16: 0 | O16: =SUM(C16:L16,N16) -> 87 | P16: =SUM(C16:N16) -> 262 | R16: 1300-1400 | S16: =SUM(C34:C37) -> 144 | T16: =SUM(D34:D37) -> 22 | U16: =SUM(E34:E37) -> 31 | V16: =SUM(F34:F37) -> 171 | W16: =SUM(G34:G37) -> 6 | X16: =SUM(H34:H37) -> 3 | Y16: =SUM(I34:I37) -> 66 | Z16: =SUM(J34:J37) -> 8 | ... AF16: =SUM(P34:P37) -> 904
B17: 08.45 - 9.00 | C17: 25 | D17: 2 | E17: 6 | F17: 49 | G17: 0 | H17: 2 | I17: 4 | J17: 4 | K17: 1 | L17: 2 | M17: 185 | N17: 0 | O17: =SUM(C17:L17,N17) -> 95 | P17: =SUM(C17:N17) -> 280 | R17: 1400-1500 | S17: =SUM(C38:C41) -> 104 | T17: =SUM(D38:D41) -> 25 | U17: =SUM(E38:E41) -> 14 | V17: =SUM(F38:F41) -> 122 | W17: =SUM(G38:G41) -> 3 | X17: =SUM(H38:H41) -> 4 | Y17: =SUM(I38:I41) -> 69 | Z17: =SUM(J38:J41) -> 25 | ... AF17: =SUM(P38:P41) -> 572
B18: 09.00 - 09.15 | C18: 15 | D18: 6 | E18: 4 | F18: 48 | G18: 1 | H18: 1 | I18: 9 | J18: 2 | K18: 1 | L18: 2 | M18: 217 | N18: 0 | O18: =SUM(C18:L18,N18) -> 89 | P18: =SUM(C18:N18) -> 306 | R18: 1500-1600 | S18: =SUM(C42:C45) -> 111 | T18: =SUM(D42:D45) -> 22 | U18: =SUM(E42:E45) -> 34 | V18: =SUM(F42:F45) -> 149 | W18: =SUM(G42:G45) -> 5 | X18: =SUM(H42:H45) -> 1 | Y18: =SUM(I42:I45) -> 62 | Z18: =SUM(J42:J45) -> 15 | ... AF18: =SUM(P42:P45) -> 840
B19: 09.15 - 09.30 | C19: 43 | D19: 10 | E19: 13 | F19: 63 | G19: 1 | H19: 0 | I19: 9 | J19: 2 | K19: 2 | L19: 0 | M19: 145 | N19: 0 | O19: =SUM(C19:L19,N19) -> 143 | P19: =SUM(C19:N19) -> 288 | R19: 1600-1700 | S19: =SUM(C46:C49) -> 171 | T19: =SUM(D46:D49) -> 25 | U19: =SUM(E46:E49) -> 21 | V19: =SUM(F46:F49) -> 143 | W19: =SUM(G46:G49) -> 6 | X19: =SUM(H46:H49) -> 4 | Y19: =SUM(I46:I49) -> 38 | Z19: =SUM(J46:J49) -> 11 | ... AF19: =SUM(P46:P49) -> 848
B20: 09.30 - 09.45 | C20: 45 | D20: 10 | E20: 10 | F20: 80 | G20: 3 | H20: 0 | I20: 5 | J20: 3 | K20: 3 | L20: 2 | M20: 180 | N20: 0 | O20: =SUM(C20:L20,N20) -> 161 | P20: =SUM(C20:N20) -> 341 | R20: 1700-1800 | S20: =SUM(C50:C53) -> 184 | T20: =SUM(D50:D53) -> 17 | U20: =SUM(E50:E53) -> 24 | V20: =SUM(F50:F53) -> 168 | W20: =SUM(G50:G53) -> 7 | X20: =SUM(H50:H53) -> 1 | Y20: =SUM(I50:I53) -> 45 | Z20: =SUM(J50:J53) -> 17 | ... AF20: =SUM(P50:P53) -> 1008
B21: 09.45 - 10.00 | C21: 20 | D21: 5 | E21: 4 | F21: 22 | G21: 0 | H21: 1 | I21: 9 | J21: 2 | K21: 1 | L21: 1 | M21: 67 | N21: 0 | O21: =SUM(C21:L21,N21) -> 65 | P21: =SUM(C21:N21) -> 132 | R21: 1800-1900 | S21: =SUM(C54:C57) -> 200 | T21: =SUM(D54:D57) -> 22 | U21: =SUM(E54:E57) -> 18 | V21: =SUM(F54:F57) -> 114 | W21: =SUM(G54:G57) -> 5 | X21: =SUM(H54:H57) -> 0 | Y21: =SUM(I54:I57) -> 36 | Z21: =SUM(J54:J57) -> 15 | ... AF21: =SUM(P54:P57) -> 1104
B22: 10.00 - 10.15 | C22: 44 | D22: 7 | E22: 9 | F22: 40 | G22: 5 | H22: 0 | I22: 20 | J22: 1 | K22: 1 | L22: 1 | M22: 126 | N22: 0 | O22: =SUM(C22:L22,N22) -> 128 | P22: =SUM(C22:N22) -> 254 | R22: AM Peak Hr | S22: =MAX(S10:S12) -> 123 | T22: =MAX(T10:T12) -> 31 | U22: =MAX(U10:U12) -> 31 | V22: =MAX(V10:V12) -> 213 | W22: =MAX(W10:W12) -> 10 | X22: =MAX(X10:X12) -> 5 | Y22: =MAX(Y10:Y12) -> 32 | Z22: =MAX(Z10:Z12) -> 13 | ... AF22: =MAX(AF10:AF12) -> 1067
B23: 10.15 - 10.30 | C23: 15 | D23: 4 | E23: 5 | F23: 25 | G23: 2 | H23: 0 | I23: 9 | J23: 2 | K23: 1 | L23: 3 | M23: 100 | N23: 0 | O23: =SUM(C23:L23,N23) -> 66 | P23: =SUM(C23:N23) -> 166 | R23: IP Peak Hr | S23: =MAX(S13:S18) -> 150 | T23: =MAX(T13:T18) -> 39 | U23: =MAX(U13:U18) -> 35 | V23: =MAX(V13:V18) -> 186 | W23: =MAX(W13:W18) -> 11 | X23: =MAX(X13:X18) -> 6 | Y23: =MAX(Y13:Y18) -> 69 | Z23: =MAX(Z13:Z18) -> 25 | ... AF23: =MAX(AF13:AF18) -> 916
B24: 10.30 - 10.45 | C24: 26 | D24: 10 | E24: 4 | F24: 41 | G24: 3 | H24: 1 | I24: 15 | J24: 1 | K24: 4 | L24: 5 | M24: 122 | N24: 0 | O24: =SUM(C24:L24,N24) -> 110 | P24: =SUM(C24:N24) -> 232 | R24: PM Peak Hr | S24: =MAX(S19:S21) -> 200 | T24: =MAX(T19:T21) -> 25 | U24: =MAX(U19:U21) -> 24 | V24: =MAX(V19:V21) -> 168 | W24: =MAX(W19:W21) -> 7 | X24: =MAX(X19:X21) -> 4 | Y24: =MAX(Y19:Y21) -> 45 | Z24: =MAX(Z19:Z21) -> 17 | ... AF24: =MAX(AF19:AF21) -> 1104
B25: 10.45 - 11.00 | C25: 40 | D25: 7 | E25: 11 | F25: 48 | G25: 1 | H25: 0 | I25: 2 | J25: 5 | K25: 2 | L25: 3 | M25: 131 | N25: 0 | O25: =SUM(C25:L25,N25) -> 119 | P25: =SUM(C25:N25) -> 250 | R25: AM Period | S25: =SUM(S10:S12) -> 311 | T25: =SUM(T10:T12) -> 56 | U25: =SUM(U10:U12) -> 61 | V25: =SUM(V10:V12) -> 504 | W25: =SUM(W10:W12) -> 21 | X25: =SUM(X10:X12) -> 10 | Y25: =SUM(Y10:Y12) -> 81 | Z25: =SUM(Z10:Z12) -> 28 | ... AF25: =SUM(AF10:AF12) -> 2944
B26: 11.00 - 11.15 | C26: 27 | D26: 13 | E26: 8 | F26: 33 | G26: 0 | H26: 1 | I26: 13 | J26: 1 | K26: 3 | L26: 5 | M26: 90 | N26: 0 | O26: =SUM(C26:L26,N26) -> 104 | P26: =SUM(C26:N26) -> 194 | R26: IP Period | S26: =SUM(S13:S18) -> 744 | T26: =SUM(T13:T18) -> 159 | U26: =SUM(U13:U18) -> 161 | V26: =SUM(V13:V18) -> 922 | W26: =SUM(W13:W18) -> 36 | X26: =SUM(X13:X18) -> 18 | Y26: =SUM(Y13:Y18) -> 338 | Z26: =SUM(Z13:Z18) -> 73 | ... AF26: =SUM(AF13:AF18) -> 4884
B27: 11.15 - 11.30 | C27: 42 | D27: 8 | E27: 12 | F27: 61 | G27: 2 | H27: 0 | I27: 12 | J27: 0 | K27: 3 | L27: 5 | M27: 152 | N27: 0 | O27: =SUM(C27:L27,N27) -> 145 | P27: =SUM(C27:N27) -> 297 | R27: PM Period | S27: =SUM(S19:S21) -> 555 | T27: =SUM(T19:T21) -> 64 | U27: =SUM(U19:U21) -> 63 | V27: =SUM(V19:V21) -> 425 | W27: =SUM(W19:W21) -> 18 | X27: =SUM(X19:X21) -> 5 | Y27: =SUM(Y19:Y21) -> 119 | Z27: =SUM(Z19:Z21) -> 43 | ... AF27: =SUM(AF19:AF21) -> 2960
B28: 11.30 - 11.45 | C28: 20 | D28: 5 | E28: 8 | F28: 32 | G28: 1 | H28: 4 | I28: 7 | J28: 1 | K28: 1 | L28: 4 | M28: 75 | N28: 0 | O28: =SUM(C28:L28,N28) -> 83 | P28: =SUM(C28:N28) -> 158 | R28: 12 Hours | S28: =SUM(S10:S21) -> 1610 | T28: =SUM(T10:T21) -> 279 | U28: =SUM(U10:U21) -> 285 | V28: =SUM(V10:V21) -> 1851 | W28: =SUM(W10:W21) -> 75 | X28: =SUM(X10:X21) -> 33 | Y28: =SUM(Y10:Y21) -> 538 | Z28: =SUM(Z10:Z21) -> 144 | ... AF28: =SUM(AF10:AF21) -> 10788
B29: 11.45 - 12.00 | C29: 61 | D29: 13 | E29: 7 | F29: 60 | G29: 4 | H29: 1 | I29: 12 | J29: 4 | K29: 4 | L29: 4 | M29: 97 | N29: 0 | O29: =SUM(C29:L29,N29) -> 170 | P29: =SUM(C29:N29) -> 267
B30: 12.00 - 12.15 | C30: 34 | D30: 6 | E30: 5 | F30: 36 | G30: 1 | H30: 1 | I30: 18 | J30: 4 | K30: 1 | L30: 4 | M30: 75 | N30: 0 | O30: =SUM(C30:L30,N30) -> 110 | P30: =SUM(C30:N30) -> 185
B31: 12.15 - 12.30 | C31: 24 | D31: 4 | E31: 4 | F31: 31 | G31: 0 | H31: 0 | I31: 10 | J31: 1 | K31: 0 | L31: 5 | M31: 105 | N31: 0 | O31: =SUM(C31:L31,N31) -> 79 | P31: =SUM(C31:N31) -> 184
B32: 12.30 - 12.45 | C32: 25 | D32: 6 | E32: 4 | F32: 41 | G32: 2 | H32: 2 | I32: 8 | J32: 5 | K32: 3 | L32: 2 | M32: 86 | N32: 0 | O32: =SUM(C32:L32,N32) -> 98 | P32: =SUM(C32:N32) -> 184
B33: 12.45 - 13.00 | C33: 27 | D33: 7 | E33: 5 | F33: 32 | G33: 1 | H33: 0 | I33: 15 | J33: 0 | K33: 1 | L33: 4 | M33: 105 | N33: 0 | O33: =SUM(C33:L33,N33) -> 92 | P33: =SUM(C33:N33) -> 197
B34: 13.00 - 13.15 | C34: 32 | D34: 6 | E34: 8 | F34: 36 | G34: 1 | H34: 0 | I34: 14 | J34: 0 | K34: 1 | L34: 4 | M34: 111 | N34: 0 | O34: =SUM(C34:L34,N34) -> 102 | P34: =SUM(C34:N34) -> 213
B35: 13.15 - 13.30 | C35: 40 | D35: 1 | E35: 10 | F35: 38 | G35: 1 | H35: 1 | I35: 21 | J35: 3 | K35: 2 | L35: 2 | M35: 125 | N35: 0 | O35: =SUM(C35:L35,N35) -> 119 | P35: =SUM(C35:N35) -> 244
B36: 13.30 - 13.45 | C36: 52 | D36: 13 | E36: 12 | F36: 72 | G36: 2 | H36: 1 | I36: 22 | J36: 2 | K36: 3 | L36: 8 | M36: 145 | N36: 0 | O36: =SUM(C36:L36,N36) -> 187 | P36: =SUM(C36:N36) -> 332
B37: 13.45 - 14.00 | C37: 20 | D37: 2 | E37: 1 | F37: 25 | G37: 2 | H37: 1 | I37: 9 | J37: 3 | K37: 2 | L37: 5 | M37: 45 | N37: 0 | O37: =SUM(C37:L37,N37) -> 70 | P37: =SUM(C37:N37) -> 115
B38: 14.00 - 14.15 | C38: 30 | D38: 5 | E38: 2 | F38: 35 | G38: 2 | H38: 2 | I38: 20 | J38: 2 | K38: 0 | L38: 0 | M38: 45 | N38: 0 | O38: =SUM(C38:L38,N38) -> 98 | P38: =SUM(C38:N38) -> 143
B39: 14.15 - 14.30 | C39: 20 | D39: 1 | E39: 0 | F39: 25 | G39: 0 | H39: 0 | I39: 5 | J39: 20 | K39: 0 | L39: 0 | M39: 30 | N39: 0 | O39: =SUM(C39:L39,N39) -> 71 | P39: =SUM(C39:N39) -> 101
B40: 14.30 - 14.45 | C40: 24 | D40: 8 | E40: 8 | F40: 25 | G40: 1 | H40: 0 | I40: 26 | J40: 2 | K40: 2 | L40: 11 | M40: 48 | N40: 0 | O40: =SUM(C40:L40,N40) -> 107 | P40: =SUM(C40:N40) -> 155
... B57: 18.45 - 19.00 | C57: 48 | D57: 3 | E57: 5 | F57: 6 | G57: 1 | H57: 0 | I57: 7 | J57: 3 | K57: 4 | L57: 4 | M57: 220 | N57: 0 | O57: =SUM(C57:L57,N57) -> 81 | P57: =SUM(C57:N57) -> 301
B58: Totals | C58: =SUM(C10:C57) -> 1610 | D58: =SUM(D10:D57) -> 279 | E58: =SUM(E10:E57) -> 285 | F58: =SUM(F10:F57) -> 1851 | G58: =SUM(G10:G57) -> 75 | H58: =SUM(H10:H57) -> 33 | I58: =SUM(I10:I57) -> 538 | J58: =SUM(J10:J57) -> 144 | ... P58: =SUM(P10:P57) -> 10788
...

Sheet 23.07 Kawempe-Bwaise
B1: Consultancy services for Preparation of Expressway Development Master Plan (EDMP) for Uganda
B2: MANUAL CLASSIFIED COUNT (MCC)
B3: ROAD NAME: | C3: ='22.07 kawempe-Bwaise'!C3:G3 -> MCC - C1 - STN23 - BOMBO ROAD
C5: Date | D5: ='23.07 Bwaise-Kawempe'!D5 -> 23.07.19 | F5: Location | G5: ='22.07 Bwaise-Kawempe'!G5:H5 -> Before Steel and Tube | J5: Surveyor | K5: Catherine
C6: Dir. From | D6: ='22.07 kawempe-Bwaise'!D6:E6 -> Kawempe | F6: Dir. To | G6: ='22.07 kawempe-Bwaise'!G6:H6 -> Bwaise | J6: Supervisor | K6: ='22.07 Bwaise-Kawempe'!K6:L6 -> Salima
B8: Time / Veh Type | R8: SUMMARY TRAFFIC VOLUMES
C9: 1. Car | D9: 2. Station Wagon | E9: 3. Pickups | F9: 4. Minibus, matatu | G9: 5. Medium bus | H9: 6. Large Bus | I9: 7. Light Truck | J9: 8. Medium Truck | K9: 9. Heavy truck | L9: 10. Truck Trailer | M9: 11. Motor cycles | N9: 12. Tractors | O9: Total Excl M/Cycles | P9: Total All | R9: Time | S9: 1. Car | T9: 2. Station Wagon | U9: 3. Pickups | V9: 4. Minibus, matatu | W9: 5. Medium bus | X9: 6. Large Bus | Y9: 7. Light Truck | Z9: 8. Medium Truck | AA9: 9. Heavy truck | AB9: 10. Truck Trailer | AC9: 11. Motorcycles | AD9: 12. Tractors, Graders | AE9: Total Excl M/ Cycles | AF9: Total All
B10: 07.00 - 07.15 | C10: 54 | D10: 11 | E10: 5 | F10: 56 | G10: 3 | H10: 1 | I10: 3 | J10: 2 | K10: 4 | L10: 3 | M10: 295 | N10: 0 | O10: =SUM(C10:L10,N10) -> 142 | P10: =SUM(C10:N10) -> 437 | R10: 0700-0800 | S10: =SUM(C10:C13) -> 196 | T10: =SUM(D10:D13) -> 41 | U10: =SUM(E10:E13) -> 29 | V10: =SUM(F10:F13) -> 201 | W10: =SUM(G10:G13) -> 8 | X10: =SUM(H10:H13) -> 2 | Y10: =SUM(I10:I13) -> 23 | Z10: =SUM(J10:J13) -> 12 | ... AF10: =SUM(P10:P13) -> 1801
B11: 07.15 - 07.30 | C11: 45 | D11: 8 | E11: 7 | F11: 44 | G11: 4 | H11: 0 | I11: 3 | J11: 2 | K11: 1 | L11: 0 | M11: 265 | N11: 0 | O11: =SUM(C11:L11,N11) -> 114 | P11: =SUM(C11:N11) -> 379 | R11: 0800-0900 | S11: =SUM(C14:C17) -> 131 | T11: =SUM(D14:D17) -> 36 | U11: =SUM(E14:E17) -> 19 | V11: =SUM(F14:F17) -> 196 | W11: =SUM(G14:G17) -> 6 | X11: =SUM(H14:H17) -> 1 | Y11: =SUM(I14:I17) -> 18 | Z11: =SUM(J14:J17) -> 6 | ... AF11: =SUM(P14:P17) -> 1735
B12: 07.30 - 07.45 | C12: 54 | D12: 14 | E12: 7 | F12: 59 | G12: 1 | H12: 0 | I12: 10 | J12: 5 | K12: 1 | L12: 3 | M12: 355 | N12: 0 | O12: =SUM(C12:L12,N12) -> 154 | P12: =SUM(C12:N12) -> 509 | R12: 0900-1000 | S12: =SUM(C18:C21) -> 127 | T12: =SUM(D18:D21) -> 16 | U12: =SUM(E18:E21) -> 26 | V12: =SUM(F18:F21) -> 152 | W12: =SUM(G18:G21) -> 4 | X12: =SUM(H18:H21) -> 0 | Y12: =SUM(I18:I21) -> 23 | Z12: =SUM(J18:J21) -> 14 | ... AF12: =SUM(P18:P21) -> 1688
B13: 07.45 - 08.00 | C13: 43 | D13: 8 | E13: 10 | F13: 42 | G13: 0 | H13: 1 | I13: 7 | J13: 3 | K13: 4 | L13: 3 | M13: 355 | N13: 0 | O13: =SUM(C13:L13,N13) -> 121 | P13: =SUM(C13:N13) -> 476 | R13: 1000-1100 | S13: =SUM(C22:C25) -> 157 | T13: =SUM(D22:D25) -> 41 | U13: =SUM(E22:E25) -> 32 | V13: =SUM(F22:F25) -> 169 | W13: =SUM(G22:G25) -> 7 | X13: =SUM(H22:H25) -> 1 | Y13: =SUM(I22:I25) -> 33 | Z13: =SUM(J22:J25) -> 21 | ... AF13: =SUM(P22:P25) -> 1805
B14: 08.00 - 08.15 | C14: 35 | D14: 12 | E14: 4 | F14: 65 | G14: 2 | H14: 0 | I14: 3 | J14: 0 | K14: 2 | L14: 3 | M14: 285 | N14: 0 | O14: =SUM(C14:L14,N14) -> 126 | P14: =SUM(C14:N14) -> 411 | R14: 1100-1200 | S14: =SUM(C26:C29) -> 139 | T14: =SUM(D26:D29) -> 53 | U14: =SUM(E26:E29) -> 46 | V14: =SUM(F26:F29) -> 162 | W14: =SUM(G26:G29) -> 5 | X14: =SUM(H26:H29) -> 0 | Y14: =SUM(I26:I29) -> 31 | Z14: =SUM(J26:J29) -> 15 | ... AF14: =SUM(P26:P29) -> 1257
B15: 08.15 - 08.30 | C15: 37 | D15: 7 | E15: 3 | F15: 50 | G15: 0 | H15: 1 | I15: 6 | J15: 2 | K15: 1 | L15: 3 | M15: 370 | N15: 0 | O15: =SUM(C15:L15,N15) -> 110 | P15: =SUM(C15:N15) -> 480 | R15: 1200-1300 | S15: =SUM(C30:C33) -> 158 | T15: =SUM(D30:D33) -> 32 | U15: =SUM(E30:E33) -> 36 | V15: =SUM(F30:F33) -> 152 | W15: =SUM(G30:G33) -> 8 | X15: =SUM(H30:H33) -> 2 | Y15: =SUM(I30:I33) -> 33 | Z15: =SUM(J30:J33) -> 15 | ... AF15: =SUM(P30:P33) -> 985
B16: 08.30 - 08.45 | C16: 22 | D16: 13 | E16: 6 | F16: 46 | G16: 2 | H16: 0 | I16: 6 | J16: 1 | K16: 2 | L16: 3 | M16: 350 | N16: 0 | O16: =SUM(C16:L16,N16) -> 101 | P16: =SUM(C16:N16) -> 451 | R16: 1300-1400 | S16: =SUM(C34:C37) -> 118 | T16: =SUM(D34:D37) -> 35 | U16: =SUM(E34:E37) -> 35 | V16: =SUM(F34:F37) -> 165 | W16: =SUM(G34:G37) -> 9 | X16: =SUM(H34:H37) -> 3 | Y16: =SUM(I34:I37) -> 18 | Z16: =SUM(J34:J37) -> 15 | ... AF16: =SUM(P34:P37) -> 815
B17: 08.45 - 9.00 | C17: 37 | D17: 4 | E17: 6 | F17: 35 | G17: 2 | H17: 0 | I17: 3 | J17: 3 | K17: 3 | L17: 0 | M17: 300 | N17: 0 | O17: =SUM(C17:L17,N17) -> 93 | P17: =SUM(C17:N17) -> 393 | R17: 1400-1500 | S17: =SUM(C38:C41) -> 69 | T17: =SUM(D38:D41) -> 23 | U17: =SUM(E38:E41) -> 21 | V17: =SUM(F38:F41) -> 94 | W17: =SUM(G38:G41) -> 10 | X17: =SUM(H38:H41) -> 5 | Y17: =SUM(I38:I41) -> 21 | Z17: =SUM(J38:J41) -> 7 | ... AF17: =SUM(P38:P41) -> 615
B18: 09.00 - 09.15 | C18: 33 | D18: 6 | E18: 10 | F18: 38 | G18: 2 | H18: 0 | I18: 3 | J18: 4 | K18: 4 | L18: 3 | M18: 375 | N18: 0 | O18: =SUM(C18:L18,N18) -> 103 | P18: =SUM(C18:N18) -> 478 | R18: 1500-1600 | S18: =SUM(C42:C45) -> 150 | T18: =SUM(D42:D45) -> 59 | U18: =SUM(E42:E45) -> 52 | V18: =SUM(F42:F45) -> 169 | W18: =SUM(G42:G45) -> 8 | X18: =SUM(H42:H45) -> 4 | Y18: =SUM(I42:I45) -> 22 | Z18: =SUM(J42:J45) -> 16 | ... AF18: =SUM(P42:P45) -> 1171
B19: 09.15 - 09.30 | C19: 25 | D19: 3 | E19: 5 | F19: 41 | G19: 1 | H19: 0 | I19: 5 | J19: 5 | K19: 6 | L19: 4 | M19: 410 | N19: 0 | O19: =SUM(C19:L19,N19) -> 95 | P19: =SUM(C19:N19) -> 505 | R19: 1600-1700 | S19: =SUM(C46:C49) -> 113 | T19: =SUM(D46:D49) -> 56 | U19: =SUM(E46:E49) -> 28 | V19: =SUM(F46:F49) -> 138 | W19: =SUM(G46:G49) -> 3 | X19: =SUM(H46:H49) -> 2 | Y19: =SUM(I46:I49) -> 31 | Z19: =SUM(J46:J49) -> 10 | ... AF19: =SUM(P46:P49) -> 1279
B20: 09.30 - 09.45 | C20: 33 | D20: 4 | E20: 5 | F20: 38 | G20: 0 | H20: 0 | I20: 8 | J20: 4 | K20: 1 | L20: 4 | M20: 345 | N20: 0 | O20: =SUM(C20:L20,N20) -> 97 | P20: =SUM(C20:N20) -> 442 | R20: 1700-1800 | S20: =SUM(C50:C53) -> 116 | T20: =SUM(D50:D53) -> 40 | U20: =SUM(E50:E53) -> 22 | V20: =SUM(F50:F53) -> 117 | W20: =SUM(G50:G53) -> 9 | X20: =SUM(H50:H53) -> 2 | Y20: =SUM(I50:I53) -> 32 | Z20: =SUM(J50:J53) -> 9 | ... AF20: =SUM(P50:P53) -> 1180
B21: 09.45 - 10.00 | C21: 36 | D21: 3 | E21: 6 | F21: 35 | G21: 1 | H21: 0 | I21: 7 | J21: 1 | K21: 4 | L21: 1 | M21: 169 | N21: 0 | O21: =SUM(C21:L21,N21) -> 94 | P21: =SUM(C21:N21) -> 263 | R21: 1800-1900 | S21: =SUM(C54:C57) -> 108 | T21: =SUM(D54:D57) -> 45 | U21: =SUM(E54:E57) -> 15 | V21: =SUM(F54:F57) -> 165 | W21: =SUM(G54:G57) -> 12 | X21: =SUM(H54:H57) -> 5 | Y21: =SUM(I54:I57) -> 17 | Z21: =SUM(J54:J57) -> 9 | ... AF21: =SUM(P54:P57) -> 1526
B22: 10.00 - 10.15 | C22: 48 | D22: 9 | E22: 8 | F22: 30 | G22: 1 | H22: 0 | I22: 8 | J22: 8 | K22: 6 | L22: 2 | M22: 370 | N22: 0 | O22: =SUM(C22:L22,N22) -> 120 | P22: =SUM(C22:N22) -> 490 | R22: AM Peak Hr | S22: =MAX(S10:S12) -> 196 | T22: =MAX(T10:T12) -> 41 | U22: =MAX(U10:U12) -> 29 | V22: =MAX(V10:V12) -> 201 | W22: =MAX(W10:W12) -> 8 | X22: =MAX(X10:X12) -> 2 | Y22: =MAX(Y10:Y12) -> 23 | Z22: =MAX(Z10:Z12) -> 14 | ... AF22: =MAX(AF10:AF12) -> 1801
B23: 10.15 - 10.30 | C23: 33 | D23: 10 | E23: 7 | F23: 39 | G23: 1 | H23: 0 | I23: 1 | J23: 3 | K23: 1 | L23: 1 | M23: 455 | N23: 0 | O23: =SUM(C23:L23,N23) -> 96 | P23: =SUM(C23:N23) -> 551 | R23: IP Peak Hr | S23: =MAX(S13:S18) -> 158 | T23: =MAX(T13:T18) -> 59 | U23: =MAX(U13:U18) -> 52 | V23: =MAX(V13:V18) -> 169 | W23: =MAX(W13:W18) -> 10 | X23: =MAX(X13:X18) -> 5 | Y23: =MAX(Y13:Y18) -> 33 | Z23: =MAX(Z13:Z18) -> 21 | ... AF23: =MAX(AF13:AF18) -> 1805
B24: 10.30 - 10.45 | C24: 45 | D24: 9 | E24: 8 | F24: 68 | G24: 1 | H24: 1 | I24: 15 | J24: 2 | K24: 3 | L24: 2 | M24: 388 | N24: 0 | O24: =SUM(C24:L24,N24) -> 154 | P24: =SUM(C24:N24) -> 542 | R24: PM Peak Hr | S24: =MAX(S19:S21) -> 116 | T24: =MAX(T19:T21) -> 56 | U24: =MAX(U19:U21) -> 28 | V24: =MAX(V19:V21) -> 165 | W24: =MAX(W19:W21) -> 12 | X24: =MAX(X19:X21) -> 5 | Y24: =MAX(Y19:Y21) -> 32 | Z24: =MAX(Z19:Z21) -> 10 | ... AF24: =MAX(AF19:AF21) -> 1526
B25: 10.45 - 11.00 | C25: 31 | D25: 13 | E25: 9 | F25: 32 | G25: 4 | H25: 0 | I25: 9 | J25: 8 | K25: 4 | L25: 1 | M25: 111 | N25: 0 | O25: =SUM(C25:L25,N25) -> 111 | P25: =SUM(C25:N25) -> 222 | R25: AM Period | S25: =SUM(S10:S12) -> 454 | T25: =SUM(T10:T12) -> 93 | U25: =SUM(U10:U12) -> 74 | V25: =SUM(V10:V12) -> 549 | W25: =SUM(W10:W12) -> 18 | X25: =SUM(X10:X12) -> 3 | Y25: =SUM(Y10:Y12) -> 64 | Z25: =SUM(Z10:Z12) -> 32 | ... AF25: =SUM(AF10:AF12) -> 5224
B26: 11.00 - 11.15 | C26: 31 | D26: 10 | E26: 9 | F26: 35 | G26: 1 | H26: 0 | I26: 10 | J26: 4 | K26: 7 | L26: 4 | M26: 198 | N26: 0 | O26: =SUM(C26:L26,N26) -> 111 | P26: =SUM(C26:N26) -> 309 | R26: IP Period | S26: =SUM(S13:S18) -> 791 | T26: =SUM(T13:T18) -> 243 | U26: =SUM(U13:U18) -> 222 | V26: =SUM(V13:V18) -> 911 | W26: =SUM(W13:W18) -> 47 | X26: =SUM(X13:X18) -> 15 | Y26: =SUM(Y13:Y18) -> 158 | Z26: =SUM(Z13:Z18) -> 89 | ... AF26: =SUM(AF13:AF18) -> 6648
B27: 11.15 - 11.30 | C27: 39 | D27: 18 | E27: 12 | F27: 43 | G27: 1 | H27: 0 | I27: 8 | J27: 2 | K27: 1 | L27: 1 | M27: 223 | N27: 0 | O27: =SUM(C27:L27,N27) -> 125 | P27: =SUM(C27:N27) -> 348 | R27: PM Period | S27: =SUM(S19:S21) -> 337 | T27: =SUM(T19:T21) -> 141 | U27: =SUM(U19:U21) -> 65 | V27: =SUM(V19:V21) -> 420 | W27: =SUM(W19:W21) -> 24 | X27: =SUM(X19:X21) -> 9 | Y27: =SUM(Y19:Y21) -> 80 | Z27: =SUM(Z19:Z21) -> 28 | ... AF27: =SUM(AF19:AF21) -> 3985
B28: 11.30 - 11.45 | C28: 39 | D28: 14 | E28: 15 | F28: 42 | G28: 3 | H28: 0 | I28: 6 | J28: 4 | K28: 0 | L28: 2 | M28: 170 | N28: 0 | O28: =SUM(C28:L28,N28) -> 125 | P28: =SUM(C28:N28) -> 295 | R28: 12 Hours | S28: =SUM(S10:S21) -> 1582 | T28: =SUM(T10:T21) -> 477 | U28: =SUM(U10:U21) -> 361 | V28: =SUM(V10:V21) -> 1880 | W28: =SUM(W10:W21) -> 89 | X28: =SUM(X10:X21) -> 27 | Y28: =SUM(Y10:Y21) -> 302 | Z28: =SUM(Z10:Z21) -> 149 | ... AF28: =SUM(AF10:AF21) -> 15857
B29: 11.45 - 12.00 | C29: 30 | D29: 11 | E29: 10 | F29: 42 | G29: 0 | H29: 0 | I29: 7 | J29: 5 | K29: 1 | L29: 2 | M29: 197 | N29: 0 | O29: =SUM(C29:L29,N29) -> 108 | P29: =SUM(C29:N29) -> 305
B30: 12.00 - 12.15 | C30: 42 | D30: 5 | E30: 11 | F30: 33 | G30: 2 | H30: 0 | I30: 3 | J30: 3 | K30: 3 | L30: 2 | M30: 130 | N30: 0 | O30: =SUM(C30:L30,N30) -> 104 | P30: =SUM(C30:N30) -> 234
B31: 12.15 - 12.30 | C31: 47 | D31: 9 | E31: 8 | F31: 33 | G31: 1 | H31: 0 | I31: 10 | J31: 4 | K31: 1 | L31: 5 | M31: 157 | N31: 0 | O31: =SUM(C31:L31,N31) -> 118 | P31: =SUM(C31:N31) -> 275
B32: 12.30 - 12.45 | C32: 49 | D32: 8 | E32: 8 | F32: 49 | G32: 1 | H32: 1 | I32: 13 | J32: 4 | K32: 1 | L32: 2 | M32: 123 | N32: 0 | O32: =SUM(C32:L32,N32) -> 136 | P32: =SUM(C32:N32) -> 259
B33: 12.45 - 13.00 | C33: 20 | D33: 10 | E33: 9 | F33: 37 | G33: 4 | H33: 1 | I33: 7 | J33: 4 | K33: 2 | L33: 5 | M33: 118 | N33: 0 | O33: =SUM(C33:L33,N33) -> 99 | P33: =SUM(C33:N33) -> 217
B34: 13.00 - 13.15 | C34: 47 | D34: 12 | E34: 8 | F34: 47 | G34: 2 | H34: 0 | I34: 4 | J34: 6 | K34: 4 | L34: 1 | M34: 104 | N34: 0 | O34: =SUM(C34:L34,N34) -> 131 | P34: =SUM(C34:N34) -> 235
B35: 13.15 - 13.30 | C35: 33 | D35: 10 | E35: 13 | F35: 50 | G35: 4 | H35: 1 | I35: 7 | J35: 2 | K35: 4 | L35: 2 | M35: 124 | N35: 0 | O35: =SUM(C35:L35,N35) -> 126 | P35: =SUM(C35:N35) -> 250
B36: 13.30 - 13.45 | C36: 17 | D36: 3 | E36: 6 | F36: 28 | G36: 2 | H36: 0 | I36: 4 | J36: 6 | K36: 0 | L36: 1 | M36: 90 | N36: 0 | O36: =SUM(C36:L36,N36) -> 67 | P36: =SUM(C36:N36) -> 157
B37: 13.45 - 14.00 | C37: 21 | D37: 10 | E37: 8 | F37: 40 | G37: 1 | H37: 2 | I37: 3 | J37: 1 | K37: 4 | L37: 1 | M37: 82 | N37: 0 | O37: =SUM(C37:L37,N37) -> 91 | P37: =SUM(C37:N37) -> 173
B38: 14.00 - 14.15 | C38: 24 | D38: 5 | E38: 4 | F38: 24 | G38: 3 | H38: 1 | I38: 3 | J38: 1 | K38: 3 | L38: 2 | M38: 73 | N38: 0 | O38: =SUM(C38:L38,N38) -> 70 | P38: =SUM(C38:N38) -> 143
B39: 14.15 - 14.30 | C39: 10 | D39: 4 | E39: 5 | F39: 15 | G39: 3 | H39: 1 | I39: 2 | J39: 0 | K39: 2 | L39: 3 | M39: 38 | N39: 0 | O39: =SUM(C39:L39,N39) -> 45 | P39: =SUM(C39:N39) -> 83
B40: 14.30 - 14.45 | C40: 11 | D40: 5 | E40: 5 | F40: 28 | G40: 2 | H40: 1 | I40: 9 | J40: 2 | K40: 4 | L40: 5 | M40: 104 | N40: 0 | O40: =SUM(C40:L40,N40) -> 72 | P40: =SUM(C40:N40) -> 176
... B57: 18.45 - 19.00 | C57: 15 | D57: 12 | E57: 3 | F57: 40 | G57: 3 | H57: 3 | I57: 5 | J57: 3 | K57: 5 | L57: 1 | M57: 321 | N57: 0 | O57: =SUM(C57:L57,N57) -> 90 | P57: =SUM(C57:N57) -> 411
B58: Totals | C58: =SUM(C10:C57) -> 1582 | D58: =SUM(D10:D57) -> 477 | E58: =SUM(E10:E57) -> 361 | F58: =SUM(F10:F57) -> 1880 | G58: =SUM(G10:G57) -> 89 | H58: =SUM(H10:H57) -> 27 | I58: =SUM(I10:I57) -> 302 | J58: =SUM(J10:J57) -> 149 | ... P58: =SUM(P10:P57) -> 15857
...

Sheet 24.07 Bwaise-Kawempe
B1: Consultancy services for Preparation of Expressway Development Master Plan (EDMP) for Uganda
B2: 27
B3: ROAD NAME: | C3: ='22.07 Bwaise-Kawempe'!C3:G3 -> MCC - C1 - STN23 - BOMBO ROAD
C5: Date | D5: 24.07.19 | F5: Location | G5: ='22.07 Bwaise-Kawempe'!G5:H5 -> Before Steel and Tube | J5: Surveyor | K5: ='22.07 Bwaise-Kawempe'!K5:L5 -> Kajjubi Eddie
C6: Dir. From | D6: ='22.07 Bwaise-Kawempe'!D6:E6 -> Bwaise | F6: Dir. To | G6: ='22.07 Bwaise-Kawempe'!G6:H6 -> Kawempe | J6: Supervisor | K6: ='22.07 Bwaise-Kawempe'!K6:L6 -> Salima
B8: Time / Veh Type | R8: SUMMARY TRAFFIC VOLUMES
C9: 1. Car | D9: 2. Station Wagon | E9: 3. Pickups | F9: 4. Minibus, matatu | G9: 5. Medium bus | H9: 6. Large Bus | I9: 7. Light Truck | J9: 8. Medium Truck | K9: 9. Heavy truck | L9: 10. Truck Trailer | M9: 11. Motor cycles | N9: 12. Tractors | O9: Total Excl M/Cycles | P9: Total All | R9: Time | S9: 1. Car | T9: 2. Station Wagon | U9: 3. Pickups | V9: 4. Minibus, matatu | W9: 5. Medium bus | X9: 6. Large Bus | Y9: 7. Light Truck | Z9: 8. Medium Truck | AA9: 9. Heavy truck | AB9: 10. Truck Trailer | AC9: 11. Motorcycles | AD9: 12. Tractors, Graders | AE9: Total Excl M/ Cycles | AF9: Total All
B10: 07.00 - 07.15 | C10: 10 | D10: 1 | E10: 1 | F10: 27 | G10: 0 | H10: 0 | I10: 5 | J10: 0 | K10: 1 | L10: 2 | M10: 110 | N10: 0 | O10: =SUM(C10:L10,N10) -> 47 | P10: =SUM(C10:N10) -> 157 | R10: 0700-0800 | S10: =SUM(C10:C13) -> 100 | T10: =SUM(D10:D13) -> 8 | U10: =SUM(E10:E13) -> 12 | V10: =SUM(F10:F13) -> 144 | W10: =SUM(G10:G13) -> 10 | X10: =SUM(H10:H13) -> 2 | Y10: =SUM(I10:I13) -> 31 | Z10: =SUM(J10:J13) -> 4 | ... AF10: =SUM(P10:P13) -> 1117
B11: 07.15 - 07.30 | C11: 28 | D11: 2 | E11: 4 | F11: 34 | G11: 0 | H11: 1 | I11: 6 | J11: 1 | K11: 1 | L11: 1 | M11: 200 | N11: 0 | O11: =SUM(C11:L11,N11) -> 78 | P11: =SUM(C11:N11) -> 278 | R11: 0800-0900 | S11: =SUM(C14:C17) -> 106 | T11: =SUM(D14:D17) -> 12 | U11: =SUM(E14:E17) -> 18 | V11: =SUM(F14:F17) -> 178 | W11: =SUM(G14:G17) -> 6 | X11: =SUM(H14:H17) -> 3 | Y11: =SUM(I14:I17) -> 33 | Z11: =SUM(J14:J17) -> 5 | ... AF11: =SUM(P14:P17) -> 1446
B12: 07.30 - 07.45 | C12: 33 | D12: 4 | E12: 2 | F12: 39 | G12: 3 | H12: 1 | I12: 7 | J12: 2 | K12: 1 | L12: 1 | M12: 263 | N12: 0 | O12: =SUM(C12:L12,N12) -> 93 | P12: =SUM(C12:N12) -> 356 | R12: 0900-1000 | S12: =SUM(C18:C21) -> 96 | T12: =SUM(D18:D21) -> 14 | U12: =SUM(E18:E21) -> 20 | V12: =SUM(F18:F21) -> 183 | W12: =SUM(G18:G21) -> 9 | X12: =SUM(H18:H21) -> 2 | Y12: =SUM(I18:I21) -> 50 | Z12: =SUM(J18:J21) -> 0 | ... AF12: =SUM(P18:P21) -> 1115
B13: 07.45 - 08.00 | C13: 29 | D13: 1 | E13: 5 | F13: 44 | G13: 7 | H13: 0 | I13: 13 | J13: 1 | K13: 1 | L13: 0 | M13: 225 | N13: 0 | O13: =SUM(C13:L13,N13) -> 101 | P13: =SUM(C13:N13) -> 326 | R13: 1000-1100 | S13: =SUM(C22:C25) -> 145 | T13: =SUM(D22:D25) -> 23 | U13: =SUM(E22:E25) -> 23 | V13: =SUM(F22:F25) -> 194 | W13: =SUM(G22:G25) -> 2 | X13: =SUM(H22:H25) -> 1 | Y13: =SUM(I22:I25) -> 54 | Z13: =SUM(J22:J25) -> 9 | ... AF13: =SUM(P22:P25) -> 1047
B14: 08.00 - 08.15 | C14: 25 | D14: 3 | E14: 3 | F14: 39 | G14: 4 | H14: 2 | I14: 2 | J14: 1 | K14: 1 | L14: 2 | M14: 285 | N14: 0 | O14: =SUM(C14:L14,N14) -> 82 | P14: =SUM(C14:N14) -> 367 | R14: 1100-1200 | S14: =SUM(C26:C29) -> 216 | T14: =SUM(D26:D29) -> 26 | U14: =SUM(E26:E29) -> 32 | V14: =SUM(F26:F29) -> 150 | W14: =SUM(G26:G29) -> 3 | X14: =SUM(H26:H29) -> 3 | Y14: =SUM(I26:I29) -> 53 | Z14: =SUM(J26:J29) -> 12 | ... AF14: =SUM(P26:P29) -> 1040
B15: 08.15 - 08.30 | C15: 23 | D15: 4 | E15: 3 | F15: 33 | G15: 1 | H15: 0 | I15: 8 | J15: 2 | K15: 3 | L15: 2 | M15: 270 | N15: 1 | O15: =SUM(C15:L15,N15) -> 80 | P15: =SUM(C15:N15) -> 350 | R15: 1200-1300 | S15: =SUM(C30:C33) -> 131 | T15: =SUM(D30:D33) -> 26 | U15: =SUM(E30:E33) -> 22 | V15: =SUM(F30:F33) -> 109 | W15: =SUM(G30:G33) -> 9 | X15: =SUM(H30:H33) -> 3 | Y15: =SUM(I30:I33) -> 53 | Z15: =SUM(J30:J33) -> 21 | ... AF15: =SUM(P30:P33) -> 836
B16: 08.30 - 08.45 | C16: 31 | D16: 3 | E16: 5 | F16: 54 | G16: 1 | H16: 0 | I16: 10 | J16: 0 | K16: 1 | L16: 2 | M16: 255 | N16: 0 | O16: =SUM(C16:L16,N16) -> 107 | P16: =SUM(C16:N16) -> 362 | R16: 1300-1400 | S16: =SUM(C34:C37) -> 109 | T16: =SUM(D34:D37) -> 21 | U16: =SUM(E34:E37) -> 14 | V16: =SUM(F34:F37) -> 125 | W16: =SUM(G34:G37) -> 5 | X16: =SUM(H34:H37) -> 2 | Y16: =SUM(I34:I37) -> 40 | Z16: =SUM(J34:J37) -> 13 | ... AF16: =SUM(P34:P37) -> 707
B17: 08.45 - 9.00 | C17: 27 | D17: 2 | E17: 7 | F17: 52 | G17: 0 | H17: 1 | I17: 13 | J17: 2 | K17: 3 | L17: 4 | M17: 255 | N17: 1 | O17: =SUM(C17:L17,N17) -> 112 | P17: =SUM(C17:N17) -> 367 | R17: 1400-1500 | S17: =SUM(C38:C41) -> 104 | T17: =SUM(D38:D41) -> 17 | U17: =SUM(E38:E41) -> 29 | V17: =SUM(F38:F41) -> 142 | W17: =SUM(G38:G41) -> 4 | X17: =SUM(H38:H41) -> 2 | Y17: =SUM(I38:I41) -> 50 | Z17: =SUM(J38:J41) -> 16 | ... AF17: =SUM(P38:P41) -> 749
B18: 09.00 - 09.15 | C18: 29 | D18: 5 | E18: 5 | F18: 30 | G18: 3 | H18: 1 | I18: 13 | J18: 0 | K18: 1 | L18: 4 | M18: 160 | N18: 0 | O18: =SUM(C18:L18,N18) -> 91 | P18: =SUM(C18:N18) -> 251 | R18: 1500-1600 | S18: =SUM(C42:C45) -> 132 | T18: =SUM(D42:D45) -> 13 | U18: =SUM(E42:E45) -> 28 | V18: =SUM(F42:F45) -> 128 | W18: =SUM(G42:G45) -> 4 | X18: =SUM(H42:H45) -> 0 | Y18: =SUM(I42:I45) -> 59 | Z18: =SUM(J42:J45) -> 25 | ... AF18: =SUM(P42:P45) -> 770
B19: 09.15 - 09.30 | C19: 26 | D19: 4 | E19: 4 | F19: 55 | G19: 2 | H19: 0 | I19: 14 | J19: 0 | K19: 2 | L19: 3 | M19: 215 | N19: 0 | O19: =SUM(C19:L19,N19) -> 110 | P19: =SUM(C19:N19) -> 325 | R19: 1600-1700 | S19: =SUM(C46:C49) -> 144 | T19: =SUM(D46:D49) -> 20 | U19: =SUM(E46:E49) -> 24 | V19: =SUM(F46:F49) -> 162 | W19: =SUM(G46:G49) -> 8 | X19: =SUM(H46:H49) -> 1 | Y19: =SUM(I46:I49) -> 47 | Z19: =SUM(J46:J49) -> 23 | ... AF19: =SUM(P46:P49) -> 936
B20: 09.30 - 09.45 | C20: 28 | D20: 2 | E20: 9 | F20: 62 | G20: 2 | H20: 1 | I20: 13 | J20: 0 | K20: 0 | L20: 0 | M20: 195 | N20: 0 | O20: =SUM(C20:L20,N20) -> 117 | P20: =SUM(C20:N20) -> 312 | R20: 1700-1800 | S20: =SUM(C50:C53) -> 151 | T20: =SUM(D50:D53) -> 18 | U20: =SUM(E50:E53) -> 11 | V20: =SUM(F50:F53) -> 122 | W20: =SUM(G50:G53) -> 4 | X20: =SUM(H50:H53) -> 1 | Y20: =SUM(I50:I53) -> 27 | Z20: =SUM(J50:J53) -> 24 | ... AF20: =SUM(P50:P53) -> 783
B21: 09.45 - 10.00 | C21: 13 | D21: 3 | E21: 2 | F21: 36 | G21: 2 | H21: 0 | I21: 10 | J21: 0 | K21: 0 | L21: 1 | M21: 160 | N21: 0 | O21: =SUM(C21:L21,N21) -> 67 | P21: =SUM(C21:N21) -> 227 | R21: 1800-1900 | S21: =SUM(C54:C57) -> 175 | T21: =SUM(D54:D57) -> 26 | U21: =SUM(E54:E57) -> 13 | V21: =SUM(F54:F57) -> 147 | W21: =SUM(G54:G57) -> 13 | X21: =SUM(H54:H57) -> 0 | Y21: =SUM(I54:I57) -> 47 | Z21: =SUM(J54:J57) -> 17 | ... AF21: =SUM(P54:P57) -> 1125
B22: 10.00 - 10.15 | C22: 27 | D22: 4 | E22: 6 | F22: 48 | G22: 1 | H22: 0 | I22: 12 | J22: 1 | K22: 3 | L22: 6 | M22: 145 | N22: 0 | O22: =SUM(C22:L22,N22) -> 108 | P22: =SUM(C22:N22) -> 253 | R22: AM Peak Hr | S22: =MAX(S10:S12) -> 106 | T22: =MAX(T10:T12) -> 14 | U22: =MAX(U10:U12) -> 20 | V22: =MAX(V10:V12) -> 183 | W22: =MAX(W10:W12) -> 10 | X22: =MAX(X10:X12) -> 3 | Y22: =MAX(Y10:Y12) -> 50 | Z22: =MAX(Z10:Z12) -> 5 | ... AF22: =MAX(AF10:AF12) -> 1446
B23: 10.15 - 10.30 | C23: 26 | D23: 6 | E23: 2 | F23: 53 | G23: 0 | H23: 1 | I23: 10 | J23: 3 | K23: 5 | L23: 4 | M23: 225 | N23: 0 | O23: =SUM(C23:L23,N23) -> 110 | P23: =SUM(C23:N23) -> 335 | R23: IP Peak Hr | S23: =MAX(S13:S18) -> 216 | T23: =MAX(T13:T18) -> 26 | U23: =MAX(U13:U18) -> 32 | V23: =MAX(V13:V18) -> 194 | W23: =MAX(W13:W18) -> 9 | X23: =MAX(X13:X18) -> 3 | Y23: =MAX(Y13:Y18) -> 59 | Z23: =MAX(Z13:Z18) -> 25 | ... AF23: =MAX(AF13:AF18) -> 1047
B24: 10.30 - 10.45 | C24: 47 | D24: 8 | E24: 8 | F24: 51 | G24: 1 | H24: 0 | I24: 23 | J24: 0 | K24: 6 | L24: 2 | M24: 19 | N24: 0 | O24: =SUM(C24:L24,N24) -> 146 | P24: =SUM(C24:N24) -> 165 | R24: PM Peak Hr | S24: =MAX(S19:S21) -> 175 | T24: =MAX(T19:T21) -> 26 | U24: =MAX(U19:U21) -> 24 | V24: =MAX(V19:V21) -> 162 | W24: =MAX(W19:W21) -> 13 | X24: =MAX(X19:X21) -> 1 | Y24: =MAX(Y19:Y21) -> 47 | Z24: =MAX(Z19:Z21) -> 24 | ... AF24: =MAX(AF19:AF21) -> 1125
B25: 10.45 - 11.00 | C25: 45 | D25: 5 | E25: 7 | F25: 42 | G25: 0 | H25: 0 | I25: 9 | J25: 5 | K25: 0 | L25: 1 | M25: 180 | N25: 0 | O25: =SUM(C25:L25,N25) -> 114 | P25: =SUM(C25:N25) -> 294 | R25: AM Period | S25: =SUM(S10:S12) -> 302 | T25: =SUM(T10:T12) -> 34 | U25: =SUM(U10:U12) -> 50 | V25: =SUM(V10:V12) -> 505 | W25: =SUM(W10:W12) -> 25 | X25: =SUM(X10:X12) -> 7 | Y25: =SUM(Y10:Y12) -> 114 | Z25: =SUM(Z10:Z12) -> 9 | ... AF25: =SUM(AF10:AF12) -> 3678
B26: 11.00 - 11.15 | C26: 52 | D26: 9 | E26: 7 | F26: 45 | G26: 0 | H26: 1 | I26: 20 | J26: 1 | K26: 4 | L26: 7 | M26: 145 | N26: 0 | O26: =SUM(C26:L26,N26) -> 146 | P26: =SUM(C26:N26) -> 291 | R26: IP Period | S26: =SUM(S13:S18) -> 837 | T26: =SUM(T13:T18) -> 126 | U26: =SUM(U13:U18) -> 148 | V26: =SUM(V13:V18) -> 848 | W26: =SUM(W13:W18) -> 27 | X26: =SUM(X13:X18) -> 11 | Y26: =SUM(Y13:Y18) -> 309 | Z26: =SUM(Z13:Z18) -> 96 | ... AF26: =SUM(AF13:AF18) -> 5149
