Workbook

Sheet ALL
B1: Consultancy services for Preparation of Expressway Development Master Plan (EDMP) for Uganda
B2: MANUAL CLASSIFIED COUNT (MCC)
B3: ROAD NAME: | C3: ='[1]28.07 Entebbe-Kampala'!C3:G3 -> MCC - C1 - STN02 - KAMPALA-ENTEBBE ROAD
C5: Date | D5: AVERAGE WEEK | F5: Location | G5: ='[1]Avg Week Entebbe-Kampala'!G5:H5 -> Nyondo Club | J5: Surveyor
C6: Dir. From | D6: BOTH DIRECTIONS | F6: Dir. To | G6: BOTH DIRECTIONS | J6: Supervisor
B8: Time / Veh Type | R8: SUMMARY TRAFFIC VOLUMES
C9: 1. Car | D9: 2. Station Wagon | E9: 3. Pickups | F9: 4. Minibus, matatu | G9: 5. Medium bus | H9: 6. Large Bus | I9: 7. Light Truck | J9: 8. Medium Truck | K9: 9. Heavy truck | L9: 10. Truck Trailer | M9: 11. Motor cycles | N9: 12. Tractors | O9: Total Excl M/Cycles | P9: Total All | R9: Time | S9: 1. Car | T9: 2. Station Wagon | U9: 3. Pickups | V9: 4. Minibus, matatu | W9: 5. Medium bus | X9: 6. Large Bus | Y9: 7. Light Truck | Z9: 8. Medium Truck | AA9: 9. Heavy truck | AB9: 10. Truck Trailer | AC9: 11. Motorcycles | AD9: 12. Tractors, Graders | AE9: Total Excl M/ Cycles | AF9: Total All
B10: 07.00 - 07.15 | C10: =AVERAGE('78'!C10,'79'!C10,'80'!C10,'81'!C10,'82'!C10,'83'!C10,'84A'!C10,'84'!C10,'85'!C10,'86'!C10,'87'!C10,'88'!C10,'89'!C10,'91'!C10,'92'!C10,'93'!C10,'94'!C10,'94A'!C10,'95'!C10,'96'!C10,'97'!C10,'98'!C10,'142'!C10,'143'!C10,'90'!C10,'93A'!C10) -> 5.3214286 | D10: =AVERAGE('78'!D10,'79'!D10,'80'!D10,'81'!D10,'82'!D10,'83'!D10,'84A'!D10,'84'!D10,'85'!D10,'86'!D10,'87'!D10,'88'!D10,'89'!D10,'91'!D10,'92'!D10,'93'!D10,'94'!D10,'94A'!D10,'95'!D10,'96'!D10,'97'!D10,'98'!D10,'142'!D10,'143'!D10,'90'!D10,'93A'!D10) -> 1.339011 | E10: =AVERAGE('78'!E10,'79'!E10,'80'!E10,'81'!E10,'82'!E10,'83'!E10,'84A'!E10,'84'!E10,'85'!E10,'86'!E10,'87'!E10,'88'!E10,'89'!E10,'91'!E10,'92'!E10,'93'!E10,'94'!E10,'94A'!E10,'95'!E10,'96'!E10,'97'!E10,'98'!E10,'142'!E10,'143'!E10,'90'!E10,'93A'!E10) -> 2.4417582 | F10: =AVERAGE('78'!F10,'79'!F10,'80'!F10,'81'!F10,'82'!F10,'83'!F10,'84A'!F10,'84'!F10,'85'!F10,'86'!F10,'87'!F10,'88'!F10,'89'!F10,'91'!F10,'92'!F10,'93'!F10,'94'!F10,'94A'!F10,'95'!F10,'96'!F10,'97'!F10,'98'!F10,'142'!F10,'143'!F10,'90'!F10,'93A'!F10) -> 7.2510989 | G10: =AVERAGE('78'!G10,'79'!G10,'80'!G10,'81'!G10,'82'!G10,'83'!G10,'84A'!G10,'84'!G10,'85'!G10,'86'!G10,'87'!G10,'88'!G10,'89'!G10,'91'!G10,'92'!G10,'93'!G10,'94'!G10,'94A'!G10,'95'!G10,'96'!G10,'97'!G10,'98'!G10,'142'!G10,'143'!G10,'90'!G10,'93A'!G10) -> 0.92967033 | H10: =AVERAGE('78'!H10,'79'!H10,'80'!H10,'81'!H10,'82'!H10,'83'!H10,'84A'!H10,'84'!H10,'85'!H10,'86'!H10,'87'!H10,'88'!H10,'89'!H10,'91'!H10,'92'!H10,'93'!H10,'94'!H10,'94A'!H10,'95'!H10,'96'!H10,'97'!H10,'98'!H10,'142'!H10,'143'!H10,'90'!H10,'93A'!H10) -> 0.37307692 | I10: =AVERAGE('78'!I10,'79'!I10,'80'!I10,'81'!I10,'82'!I10,'83'!I10,'84A'!I10,'84'!I10,'85'!I10,'86'!I10,'87'!I10,'88'!I10,'89'!I10,'91'!I10,'92'!I10,'93'!I10,'94'!I10,'94A'!I10,'95'!I10,'96'!I10,'97'!I10,'98'!I10,'142'!I10,'143'!I10,'90'!I10,'93A'!I10) -> 2.5961538 | J10: =AVERAGE('78'!J10,'79'!J10,'80'!J10,'81'!J10,'82'!J10,'83'!J10,'84A'!J10,'84'!J10,'85'!J10,'86'!J10,'87'!J10,'88'!J10,'89'!J10,'91'!J10,'92'!J10,'93'!J10,'94'!J10,'94A'!J10,'95'!J10,'96'!J10,'97'!J10,'98'!J10,'142'!J10,'143'!J10,'90'!J10,'93A'!J10) -> 1.8373626 | ... N10: =AVERAGE('78'!N10,'79'!N10,'80'!N10,'81'!N10,'82'!N10,'83'!N10,'84A'!N10,'84'!N10,'85'!N10,'86'!N10,'87'!N10,'88'!N10,'89'!N10,'91'!N10,'92'!N10,'93'!N10,'94'!N10,'94A'!N10,'95'!N10,'96'!N10,'97'!N10,'98'!N10,'142'!N10,'143'!N10,'90'!N10,'93A'!N10) -> 0.082417582 | O10: =AVERAGE('78'!O10,'79'!O10,'80'!O10,'81'!O10,'82'!O10,'83'!O10,'84A'!O10,'84'!O10,'85'!O10,'86'!O10,'87'!O10,'88'!O10,'89'!O10,'91'!O10,'92'!O10,'93'!O10,'94'!O10,'94A'!O10,'95'!O10,'96'!O10,'97'!O10,'98'!O10,'142'!O10,'143'!O10,'90'!O10) -> 25.011429 | P10: =AVERAGE('78'!P10,'79'!P10,'80'!P10,'81'!P10,'82'!P10,'83'!P10,'84A'!P10,'84'!P10,'85'!P10,'86'!P10,'87'!P10,'88'!P10,'89'!P10,'91'!P10,'92'!P10,'93'!P10,'94'!P10,'94A'!P10,'95'!P10,'96'!P10,'97'!P10,'98'!P10,'142'!P10,'143'!P10,'90'!P10) -> 53.434286 | R10: 0700-0800 | S10: =SUM(C10:C13) -> 23.786264 | T10: =SUM(D10:D13) -> 6.4708791 | U10: =SUM(E10:E13) -> 10.771429 | V10: =SUM(F10:F13) -> 34.998901 | W10: =SUM(G10:G13) -> 3.0362637 | X10: =SUM(H10:H13) -> 1.6642857 | Y10: =SUM(I10:I13) -> 10.344505 | Z10: =SUM(J10:J13) -> 7.8318681 | ... AF10: =SUM(P10:P13) -> 247.36
B11: 07.15 - 07.30 | C11: =AVERAGE('78'!C11,'79'!C11,'80'!C11,'81'!C11,'82'!C11,'83'!C11,'84A'!C11,'84'!C11,'85'!C11,'86'!C11,'87'!C11,'88'!C11,'89'!C11,'91'!C11,'92'!C11,'93'!C11,'94'!C11,'94A'!C11,'95'!C11,'96'!C11,'97'!C11,'98'!C11,'142'!C11,'143'!C11,'90'!C11,'93A'!C11) -> 5.4093407 | D11: =AVERAGE('78'!D11,'79'!D11,'80'!D11,'81'!D11,'82'!D11,'83'!D11,'84A'!D11,'84'!D11,'85'!D11,'86'!D11,'87'!D11,'88'!D11,'89'!D11,'91'!D11,'92'!D11,'93'!D11,'94'!D11,'94A'!D11,'95'!D11,'96'!D11,'97'!D11,'98'!D11,'142'!D11,'143'!D11,'90'!D11,'93A'!D11) -> 1.4313187 | E11: =AVERAGE('78'!E11,'79'!E11,'80'!E11,'81'!E11,'82'!E11,'83'!E11,'84A'!E11,'84'!E11,'85'!E11,'86'!E11,'87'!E11,'88'!E11,'89'!E11,'91'!E11,'92'!E11,'93'!E11,'94'!E11,'94A'!E11,'95'!E11,'96'!E11,'97'!E11,'98'!E11,'142'!E11,'143'!E11,'90'!E11,'93A'!E11) -> 2.4159341 | F11: =AVERAGE('78'!F11,'79'!F11,'80'!F11,'81'!F11,'82'!F11,'83'!F11,'84A'!F11,'84'!F11,'85'!F11,'86'!F11,'87'!F11,'88'!F11,'89'!F11,'91'!F11,'92'!F11,'93'!F11,'94'!F11,'94A'!F11,'95'!F11,'96'!F11,'97'!F11,'98'!F11,'142'!F11,'143'!F11,'90'!F11,'93A'!F11) -> 8.1967033 | G11: =AVERAGE('78'!G11,'79'!G11,'80'!G11,'81'!G11,'82'!G11,'83'!G11,'84A'!G11,'84'!G11,'85'!G11,'86'!G11,'87'!G11,'88'!G11,'89'!G11,'91'!G11,'92'!G11,'93'!G11,'94'!G11,'94A'!G11,'95'!G11,'96'!G11,'97'!G11,'98'!G11,'142'!G11,'143'!G11,'90'!G11,'93A'!G11) -> 0.58681319 | H11: =AVERAGE('78'!H11,'79'!H11,'80'!H11,'81'!H11,'82'!H11,'83'!H11,'84A'!H11,'84'!H11,'85'!H11,'86'!H11,'87'!H11,'88'!H11,'89'!H11,'91'!H11,'92'!H11,'93'!H11,'94'!H11,'94A'!H11,'95'!H11,'96'!H11,'97'!H11,'98'!H11,'142'!H11,'143'!H11,'90'!H11,'93A'!H11) -> 0.42857143 | I11: =AVERAGE('78'!I11,'79'!I11,'80'!I11,'81'!I11,'82'!I11,'83'!I11,'84A'!I11,'84'!I11,'85'!I11,'86'!I11,'87'!I11,'88'!I11,'89'!I11,'91'!I11,'92'!I11,'93'!I11,'94'!I11,'94A'!I11,'95'!I11,'96'!I11,'97'!I11,'98'!I11,'142'!I11,'143'!I11,'90'!I11,'93A'!I11) -> 2.4065934 | J11: =AVERAGE('78'!J11,'79'!J11,'80'!J11,'81'!J11,'82'!J11,'83'!J11,'84A'!J11,'84'!J11,'85'!J11,'86'!J11,'87'!J11,'88'!J11,'89'!J11,'91'!J11,'92'!J11,'93'!J11,'94'!J11,'94A'!J11,'95'!J11,'96'!J11,'97'!J11,'98'!J11,'142'!J11,'143'!J11,'90'!J11,'93A'!J11) -> 1.8593407 | ... N11: =AVERAGE('78'!N11,'79'!N11,'80'!N11,'81'!N11,'82'!N11,'83'!N11,'84A'!N11,'84'!N11,'85'!N11,'86'!N11,'87'!N11,'88'!N11,'89'!N11,'91'!N11,'92'!N11,'93'!N11,'94'!N11,'94A'!N11,'95'!N11,'96'!N11,'97'!N11,'98'!N11,'142'!N11,'143'!N11,'90'!N11,'93A'!N11) -> 0.076923077 | O11: =AVERAGE('78'!O11,'79'!O11,'80'!O11,'81'!O11,'82'!O11,'83'!O11,'84A'!O11,'84'!O11,'85'!O11,'86'!O11,'87'!O11,'88'!O11,'89'!O11,'91'!O11,'92'!O11,'93'!O11,'94'!O11,'94A'!O11,'95'!O11,'96'!O11,'97'!O11,'98'!O11,'142'!O11,'143'!O11,'90'!O11) -> 25.148571 | P11: =AVERAGE('78'!P11,'79'!P11,'80'!P11,'81'!P11,'82'!P11,'83'!P11,'84A'!P11,'84'!P11,'85'!P11,'86'!P11,'87'!P11,'88'!P11,'89'!P11,'91'!P11,'92'!P11,'93'!P11,'94'!P11,'94A'!P11,'95'!P11,'96'!P11,'97'!P11,'98'!P11,'142'!P11,'143'!P11,'90'!P11) -> 58.611429 | R11: 0800-0900 | S11: =SUM(C14:C17) -> 29.578571 | T11: =SUM(D14:D17) -> 9.9857143 | U11: =SUM(E14:E17) -> 13.682967 | V11: =SUM(F14:F17) -> 42.014835 | W11: =SUM(G14:G17) -> 1.9758242 | X11: =SUM(H14:H17) -> 1.556044 | Y11: =SUM(I14:I17) -> 11.076923 | Z11: =SUM(J14:J17) -> 7.2126374 | ... AF11: =SUM(P14:P17) -> 284.30286
B12: 07.30 - 07.45 | C12: =AVERAGE('78'!C12,'79'!C12,'80'!C12,'81'!C12,'82'!C12,'83'!C12,'84A'!C12,'84'!C12,'85'!C12,'86'!C12,'87'!C12,'88'!C12,'89'!C12,'91'!C12,'92'!C12,'93'!C12,'94'!C12,'94A'!C12,'95'!C12,'96'!C12,'97'!C12,'98'!C12,'142'!C12,'143'!C12,'90'!C12,'93A'!C12) -> 6.0269231 | D12: =AVERAGE('78'!D12,'79'!D12,'80'!D12,'81'!D12,'82'!D12,'83'!D12,'84A'!D12,'84'!D12,'85'!D12,'86'!D12,'87'!D12,'88'!D12,'89'!D12,'91'!D12,'92'!D12,'93'!D12,'94'!D12,'94A'!D12,'95'!D12,'96'!D12,'97'!D12,'98'!D12,'142'!D12,'143'!D12,'90'!D12,'93A'!D12) -> 1.7263736 | E12: =AVERAGE('78'!E12,'79'!E12,'80'!E12,'81'!E12,'82'!E12,'83'!E12,'84A'!E12,'84'!E12,'85'!E12,'86'!E12,'87'!E12,'88'!E12,'89'!E12,'91'!E12,'92'!E12,'93'!E12,'94'!E12,'94A'!E12,'95'!E12,'96'!E12,'97'!E12,'98'!E12,'142'!E12,'143'!E12,'90'!E12,'93A'!E12) -> 2.6296703 | F12: =AVERAGE('78'!F12,'79'!F12,'80'!F12,'81'!F12,'82'!F12,'83'!F12,'84A'!F12,'84'!F12,'85'!F12,'86'!F12,'87'!F12,'88'!F12,'89'!F12,'91'!F12,'92'!F12,'93'!F12,'94'!F12,'94A'!F12,'95'!F12,'96'!F12,'97'!F12,'98'!F12,'142'!F12,'143'!F12,'90'!F12,'93A'!F12) -> 9.4895604 | G12: =AVERAGE('78'!G12,'79'!G12,'80'!G12,'81'!G12,'82'!G12,'83'!G12,'84A'!G12,'84'!G12,'85'!G12,'86'!G12,'87'!G12,'88'!G12,'89'!G12,'91'!G12,'92'!G12,'93'!G12,'94'!G12,'94A'!G12,'95'!G12,'96'!G12,'97'!G12,'98'!G12,'142'!G12,'143'!G12,'90'!G12,'93A'!G12) -> 0.81538462 | H12: =AVERAGE('78'!H12,'79'!H12,'80'!H12,'81'!H12,'82'!H12,'83'!H12,'84A'!H12,'84'!H12,'85'!H12,'86'!H12,'87'!H12,'88'!H12,'89'!H12,'91'!H12,'92'!H12,'93'!H12,'94'!H12,'94A'!H12,'95'!H12,'96'!H12,'97'!H12,'98'!H12,'142'!H12,'143'!H12,'90'!H12,'93A'!H12) -> 0.34725275 | I12: =AVERAGE('78'!I12,'79'!I12,'80'!I12,'81'!I12,'82'!I12,'83'!I12,'84A'!I12,'84'!I12,'85'!I12,'86'!I12,'87'!I12,'88'!I12,'89'!I12,'91'!I12,'92'!I12,'93'!I12,'94'!I12,'94A'!I12,'95'!I12,'96'!I12,'97'!I12,'98'!I12,'142'!I12,'143'!I12,'90'!I12,'93A'!I12) -> 2.55 | J12: =AVERAGE('78'!J12,'79'!J12,'80'!J12,'81'!J12,'82'!J12,'83'!J12,'84A'!J12,'84'!J12,'85'!J12,'86'!J12,'87'!J12,'88'!J12,'89'!J12,'91'!J12,'92'!J12,'93'!J12,'94'!J12,'94A'!J12,'95'!J12,'96'!J12,'97'!J12,'98'!J12,'142'!J12,'143'!J12,'90'!J12,'93A'!J12) -> 2.0857143 | ... N12: =AVERAGE('78'!N12,'79'!N12,'80'!N12,'81'!N12,'82'!N12,'83'!N12,'84A'!N12,'84'!N12,'85'!N12,'86'!N12,'87'!N12,'88'!N12,'89'!N12,'91'!N12,'92'!N12,'93'!N12,'94'!N12,'94A'!N12,'95'!N12,'96'!N12,'97'!N12,'98'!N12,'142'!N12,'143'!N12,'90'!N12,'93A'!N12) -> 0.07032967 | O12: =AVERAGE('78'!O12,'79'!O12,'80'!O12,'81'!O12,'82'!O12,'83'!O12,'84A'!O12,'84'!O12,'85'!O12,'86'!O12,'87'!O12,'88'!O12,'89'!O12,'91'!O12,'92'!O12,'93'!O12,'94'!O12,'94A'!O12,'95'!O12,'96'!O12,'97'!O12,'98'!O12,'142'!O12,'143'!O12,'90'!O12) -> 27.942857 | P12: =AVERAGE('78'!P12,'79'!P12,'80'!P12,'81'!P12,'82'!P12,'83'!P12,'84A'!P12,'84'!P12,'85'!P12,'86'!P12,'87'!P12,'88'!P12,'89'!P12,'91'!P12,'92'!P12,'93'!P12,'94'!P12,'94A'!P12,'95'!P12,'96'!P12,'97'!P12,'98'!P12,'142'!P12,'143'!P12,'90'!P12) -> 65.742857 | R12: 0900-1000 | S12: =SUM(C18:C21) -> 33.30989 | T12: =SUM(D18:D21) -> 11.599451 | U12: =SUM(E18:E21) -> 15.820879 | V12: =SUM(F18:F21) -> 46.902198 | W12: =SUM(G18:G21) -> 1.8681319 | X12: =SUM(H18:H21) -> 1.5434066 | Y12: =SUM(I18:I21) -> 11.696154 | Z12: =SUM(J18:J21) -> 6.5796703 | ... AF12: =SUM(P18:P21) -> 302.86286
B13: 07.45 - 08.00 | C13: =AVERAGE('78'!C13,'79'!C13,'80'!C13,'81'!C13,'82'!C13,'83'!C13,'84A'!C13,'84'!C13,'85'!C13,'86'!C13,'87'!C13,'88'!C13,'89'!C13,'91'!C13,'92'!C13,'93'!C13,'94'!C13,'94A'!C13,'95'!C13,'96'!C13,'97'!C13,'98'!C13,'142'!C13,'143'!C13,'90'!C13,'93A'!C13) -> 7.0285714 | D13: =AVERAGE('78'!D13,'79'!D13,'80'!D13,'81'!D13,'82'!D13,'83'!D13,'84A'!D13,'84'!D13,'85'!D13,'86'!D13,'87'!D13,'88'!D13,'89'!D13,'91'!D13,'92'!D13,'93'!D13,'94'!D13,'94A'!D13,'95'!D13,'96'!D13,'97'!D13,'98'!D13,'142'!D13,'143'!D13,'90'!D13,'93A'!D13) -> 1.9741758 | E13: =AVERAGE('78'!E13,'79'!E13,'80'!E13,'81'!E13,'82'!E13,'83'!E13,'84A'!E13,'84'!E13,'85'!E13,'86'!E13,'87'!E13,'88'!E13,'89'!E13,'91'!E13,'92'!E13,'93'!E13,'94'!E13,'94A'!E13,'95'!E13,'96'!E13,'97'!E13,'98'!E13,'142'!E13,'143'!E13,'90'!E13,'93A'!E13) -> 3.2840659 | F13: =AVERAGE('78'!F13,'79'!F13,'80'!F13,'81'!F13,'82'!F13,'83'!F13,'84A'!F13,'84'!F13,'85'!F13,'86'!F13,'87'!F13,'88'!F13,'89'!F13,'91'!F13,'92'!F13,'93'!F13,'94'!F13,'94A'!F13,'95'!F13,'96'!F13,'97'!F13,'98'!F13,'142'!F13,'143'!F13,'90'!F13,'93A'!F13) -> 10.061538 | G13: =AVERAGE('78'!G13,'79'!G13,'80'!G13,'81'!G13,'82'!G13,'83'!G13,'84A'!G13,'84'!G13,'85'!G13,'86'!G13,'87'!G13,'88'!G13,'89'!G13,'91'!G13,'92'!G13,'93'!G13,'94'!G13,'94A'!G13,'95'!G13,'96'!G13,'97'!G13,'98'!G13,'142'!G13,'143'!G13,'90'!G13,'93A'!G13) -> 0.7043956 | H13: =AVERAGE('78'!H13,'79'!H13,'80'!H13,'81'!H13,'82'!H13,'83'!H13,'84A'!H13,'84'!H13,'85'!H13,'86'!H13,'87'!H13,'88'!H13,'89'!H13,'91'!H13,'92'!H13,'93'!H13,'94'!H13,'94A'!H13,'95'!H13,'96'!H13,'97'!H13,'98'!H13,'142'!H13,'143'!H13,'90'!H13,'93A'!H13) -> 0.51538462 | I13: =AVERAGE('78'!I13,'79'!I13,'80'!I13,'81'!I13,'82'!I13,'83'!I13,'84A'!I13,'84'!I13,'85'!I13,'86'!I13,'87'!I13,'88'!I13,'89'!I13,'91'!I13,'92'!I13,'93'!I13,'94'!I13,'94A'!I13,'95'!I13,'96'!I13,'97'!I13,'98'!I13,'142'!I13,'143'!I13,'90'!I13,'93A'!I13) -> 2.7917582 | J13: =AVERAGE('78'!J13,'79'!J13,'80'!J13,'81'!J13,'82'!J13,'83'!J13,'84A'!J13,'84'!J13,'85'!J13,'86'!J13,'87'!J13,'88'!J13,'89'!J13,'91'!J13,'92'!J13,'93'!J13,'94'!J13,'94A'!J13,'95'!J13,'96'!J13,'97'!J13,'98'!J13,'142'!J13,'143'!J13,'90'!J13,'93A'!J13) -> 2.0494505 | ... N13: =AVERAGE('78'!N13,'79'!N13,'80'!N13,'81'!N13,'82'!N13,'83'!N13,'84A'!N13,'84'!N13,'85'!N13,'86'!N13,'87'!N13,'88'!N13,'89'!N13,'91'!N13,'92'!N13,'93'!N13,'94'!N13,'94A'!N13,'95'!N13,'96'!N13,'97'!N13,'98'!N13,'142'!N13,'143'!N13,'90'!N13,'93A'!N13) -> 0.074725275 | O13: =AVERAGE('78'!O13,'79'!O13,'80'!O13,'81'!O13,'82'!O13,'83'!O13,'84A'!O13,'84'!O13,'85'!O13,'86'!O13,'87'!O13,'88'!O13,'89'!O13,'91'!O13,'92'!O13,'93'!O13,'94'!O13,'94A'!O13,'95'!O13,'96'!O13,'97'!O13,'98'!O13,'142'!O13,'143'!O13,'90'!O13) -> 29.754286 | P13: =AVERAGE('78'!P13,'79'!P13,'80'!P13,'81'!P13,'82'!P13,'83'!P13,'84A'!P13,'84'!P13,'85'!P13,'86'!P13,'87'!P13,'88'!P13,'89'!P13,'91'!P13,'92'!P13,'93'!P13,'94'!P13,'94A'!P13,'95'!P13,'96'!P13,'97'!P13,'98'!P13,'142'!P13,'143'!P13,'90'!P13) -> 69.571429 | R13: 1000-1100 | S13: =SUM(C22:C25) -> 35.04011 | T13: =SUM(D22:D25) -> 11.983516 | U13: =SUM(E22:E25) -> 17.377473 | V13: =SUM(F22:F25) -> 48.913187 | W13: =SUM(G22:G25) -> 1.3 | X13: =SUM(H22:H25) -> 1.732967 | Y13: =SUM(I22:I25) -> 13.135165 | Z13: =SUM(J22:J25) -> 7.7142857 | ... AF13: =SUM(P22:P25) -> 315.82343
B14: 08.00 - 08.15 | C14: =AVERAGE('78'!C14,'79'!C14,'80'!C14,'81'!C14,'82'!C14,'83'!C14,'84A'!C14,'84'!C14,'85'!C14,'86'!C14,'87'!C14,'88'!C14,'89'!C14,'91'!C14,'92'!C14,'93'!C14,'94'!C14,'94A'!C14,'95'!C14,'96'!C14,'97'!C14,'98'!C14,'142'!C14,'143'!C14,'90'!C14,'93A'!C14) -> 7.2708791 | D14: =AVERAGE('78'!D14,'79'!D14,'80'!D14,'81'!D14,'82'!D14,'83'!D14,'84A'!D14,'84'!D14,'85'!D14,'86'!D14,'87'!D14,'88'!D14,'89'!D14,'91'!D14,'92'!D14,'93'!D14,'94'!D14,'94A'!D14,'95'!D14,'96'!D14,'97'!D14,'98'!D14,'142'!D14,'143'!D14,'90'!D14,'93A'!D14) -> 2.2203297 | E14: =AVERAGE('78'!E14,'79'!E14,'80'!E14,'81'!E14,'82'!E14,'83'!E14,'84A'!E14,'84'!E14,'85'!E14,'86'!E14,'87'!E14,'88'!E14,'89'!E14,'91'!E14,'92'!E14,'93'!E14,'94'!E14,'94A'!E14,'95'!E14,'96'!E14,'97'!E14,'98'!E14,'142'!E14,'143'!E14,'90'!E14,'93A'!E14) -> 3.0813187 | F14: =AVERAGE('78'!F14,'79'!F14,'80'!F14,'81'!F14,'82'!F14,'83'!F14,'84A'!F14,'84'!F14,'85'!F14,'86'!F14,'87'!F14,'88'!F14,'89'!F14,'91'!F14,'92'!F14,'93'!F14,'94'!F14,'94A'!F14,'95'!F14,'96'!F14,'97'!F14,'98'!F14,'142'!F14,'143'!F14,'90'!F14,'93A'!F14) -> 10.291758 | G14: =AVERAGE('78'!G14,'79'!G14,'80'!G14,'81'!G14,'82'!G14,'83'!G14,'84A'!G14,'84'!G14,'85'!G14,'86'!G14,'87'!G14,'88'!G14,'89'!G14,'91'!G14,'92'!G14,'93'!G14,'94'!G14,'94A'!G14,'95'!G14,'96'!G14,'97'!G14,'98'!G14,'142'!G14,'143'!G14,'90'!G14,'93A'!G14) -> 0.49835165 | H14: =AVERAGE('78'!H14,'79'!H14,'80'!H14,'81'!H14,'82'!H14,'83'!H14,'84A'!H14,'84'!H14,'85'!H14,'86'!H14,'87'!H14,'88'!H14,'89'!H14,'91'!H14,'92'!H14,'93'!H14,'94'!H14,'94A'!H14,'95'!H14,'96'!H14,'97'!H14,'98'!H14,'142'!H14,'143'!H14,'90'!H14,'93A'!H14) -> 0.39725275 | I14: =AVERAGE('78'!I14,'79'!I14,'80'!I14,'81'!I14,'82'!I14,'83'!I14,'84A'!I14,'84'!I14,'85'!I14,'86'!I14,'87'!I14,'88'!I14,'89'!I14,'91'!I14,'92'!I14,'93'!I14,'94'!I14,'94A'!I14,'95'!I14,'96'!I14,'97'!I14,'98'!I14,'142'!I14,'143'!I14,'90'!I14,'93A'!I14) -> 2.7593407 | J14: =AVERAGE('78'!J14,'79'!J14,'80'!J14,'81'!J14,'82'!J14,'83'!J14,'84A'!J14,'84'!J14,'85'!J14,'86'!J14,'87'!J14,'88'!J14,'89'!J14,'91'!J14,'92'!J14,'93'!J14,'94'!J14,'94A'!J14,'95'!J14,'96'!J14,'97'!J14,'98'!J14,'142'!J14,'143'!J14,'90'!J14,'93A'!J14) -> 1.6934066 | ... N14: =AVERAGE('78'!N14,'79'!N14,'80'!N14,'81'!N14,'82'!N14,'83'!N14,'84A'!N14,'84'!N14,'85'!N14,'86'!N14,'87'!N14,'88'!N14,'89'!N14,'91'!N14,'92'!N14,'93'!N14,'94'!N14,'94A'!N14,'95'!N14,'96'!N14,'97'!N14,'98'!N14,'142'!N14,'143'!N14,'90'!N14,'93A'!N14) -> 0.048351648 | O14: =AVERAGE('78'!O14,'79'!O14,'80'!O14,'81'!O14,'82'!O14,'83'!O14,'84A'!O14,'84'!O14,'85'!O14,'86'!O14,'87'!O14,'88'!O14,'89'!O14,'91'!O14,'92'!O14,'93'!O14,'94'!O14,'94A'!O14,'95'!O14,'96'!O14,'97'!O14,'98'!O14,'142'!O14,'143'!O14,'90'!O14) -> 29 | P14: =AVERAGE('78'!P14,'79'!P14,'80'!P14,'81'!P14,'82'!P14,'83'!P14,'84A'!P14,'84'!P14,'85'!P14,'86'!P14,'87'!P14,'88'!P14,'89'!P14,'91'!P14,'92'!P14,'93'!P14,'94'!P14,'94A'!P14,'95'!P14,'96'!P14,'97'!P14,'98'!P14,'142'!P14,'143'!P14,'90'!P14) -> 67.628571 | R14: 1100-1200 | S14: =SUM(C26:C29) -> 39.714286 | T14: =SUM(D26:D29) -> 12.583516 | U14: =SUM(E26:E29) -> 17.581868 | V14: =SUM(F26:F29) -> 49.045604 | W14: =SUM(G26:G29) -> 1.810989 | X14: =SUM(H26:H29) -> 1.6708791 | Y14: =SUM(I26:I29) -> 13.637912 | Z14: =SUM(J26:J29) -> 8.3714286 | ... AF14: =SUM(P26:P29) -> 328.99429
B15: 08.15 - 08.30 | C15: =AVERAGE('78'!C15,'79'!C15,'80'!C15,'81'!C15,'82'!C15,'83'!C15,'84A'!C15,'84'!C15,'85'!C15,'86'!C15,'87'!C15,'88'!C15,'89'!C15,'91'!C15,'92'!C15,'93'!C15,'94'!C15,'94A'!C15,'95'!C15,'96'!C15,'97'!C15,'98'!C15,'142'!C15,'143'!C15,'90'!C15,'93A'!C15) -> 7.4324176 | D15: =AVERAGE('78'!D15,'79'!D15,'80'!D15,'81'!D15,'82'!D15,'83'!D15,'84A'!D15,'84'!D15,'85'!D15,'86'!D15,'87'!D15,'88'!D15,'89'!D15,'91'!D15,'92'!D15,'93'!D15,'94'!D15,'94A'!D15,'95'!D15,'96'!D15,'97'!D15,'98'!D15,'142'!D15,'143'!D15,'90'!D15,'93A'!D15) -> 2.5263736 | E15: =AVERAGE('78'!E15,'79'!E15,'80'!E15,'81'!E15,'82'!E15,'83'!E15,'84A'!E15,'84'!E15,'85'!E15,'86'!E15,'87'!E15,'88'!E15,'89'!E15,'91'!E15,'92'!E15,'93'!E15,'94'!E15,'94A'!E15,'95'!E15,'96'!E15,'97'!E15,'98'!E15,'142'!E15,'143'!E15,'90'!E15,'93A'!E15) -> 3.4241758 | F15: =AVERAGE('78'!F15,'79'!F15,'80'!F15,'81'!F15,'82'!F15,'83'!F15,'84A'!F15,'84'!F15,'85'!F15,'86'!F15,'87'!F15,'88'!F15,'89'!F15,'91'!F15,'92'!F15,'93'!F15,'94'!F15,'94A'!F15,'95'!F15,'96'!F15,'97'!F15,'98'!F15,'142'!F15,'143'!F15,'90'!F15,'93A'!F15) -> 9.9758242 | G15: =AVERAGE('78'!G15,'79'!G15,'80'!G15,'81'!G15,'82'!G15,'83'!G15,'84A'!G15,'84'!G15,'85'!G15,'86'!G15,'87'!G15,'88'!G15,'89'!G15,'91'!G15,'92'!G15,'93'!G15,'94'!G15,'94A'!G15,'95'!G15,'96'!G15,'97'!G15,'98'!G15,'142'!G15,'143'!G15,'90'!G15,'93A'!G15) -> 0.46153846 | H15: =AVERAGE('78'!H15,'79'!H15,'80'!H15,'81'!H15,'82'!H15,'83'!H15,'84A'!H15,'84'!H15,'85'!H15,'86'!H15,'87'!H15,'88'!H15,'89'!H15,'91'!H15,'92'!H15,'93'!H15,'94'!H15,'94A'!H15,'95'!H15,'96'!H15,'97'!H15,'98'!H15,'142'!H15,'143'!H15,'90'!H15,'93A'!H15) -> 0.43406593 | I15: =AVERAGE('78'!I15,'79'!I15,'80'!I15,'81'!I15,'82'!I15,'83'!I15,'84A'!I15,'84'!I15,'85'!I15,'86'!I15,'87'!I15,'88'!I15,'89'!I15,'91'!I15,'92'!I15,'93'!I15,'94'!I15,'94A'!I15,'95'!I15,'96'!I15,'97'!I15,'98'!I15,'142'!I15,'143'!I15,'90'!I15,'93A'!I15) -> 2.7258242 | J15: =AVERAGE('78'!J15,'79'!J15,'80'!J15,'81'!J15,'82'!J15,'83'!J15,'84A'!J15,'84'!J15,'85'!J15,'86'!J15,'87'!J15,'88'!J15,'89'!J15,'91'!J15,'92'!J15,'93'!J15,'94'!J15,'94A'!J15,'95'!J15,'96'!J15,'97'!J15,'98'!J15,'142'!J15,'143'!J15,'90'!J15,'93A'!J15) -> 2.0175824 | ... N15: =AVERAGE('78'!N15,'79'!N15,'80'!N15,'81'!N15,'82'!N15,'83'!N15,'84A'!N15,'84'!N15,'85'!N15,'86'!N15,'87'!N15,'88'!N15,'89'!N15,'91'!N15,'92'!N15,'93'!N15,'94'!N15,'94A'!N15,'95'!N15,'96'!N15,'97'!N15,'98'!N15,'142'!N15,'143'!N15,'90'!N15,'93A'!N15) -> 0.13681319 | O15: =AVERAGE('78'!O15,'79'!O15,'80'!O15,'81'!O15,'82'!O15,'83'!O15,'84A'!O15,'84'!O15,'85'!O15,'86'!O15,'87'!O15,'88'!O15,'89'!O15,'91'!O15,'92'!O15,'93'!O15,'94'!O15,'94A'!O15,'95'!O15,'96'!O15,'97'!O15,'98'!O15,'142'!O15,'143'!O15,'90'!O15) -> 29.428571 | P15: =AVERAGE('78'!P15,'79'!P15,'80'!P15,'81'!P15,'82'!P15,'83'!P15,'84A'!P15,'84'!P15,'85'!P15,'86'!P15,'87'!P15,'88'!P15,'89'!P15,'91'!P15,'92'!P15,'93'!P15,'94'!P15,'94A'!P15,'95'!P15,'96'!P15,'97'!P15,'98'!P15,'142'!P15,'143'!P15,'90'!P15) -> 69.577143 | R15: 1200-1300 | S15: =SUM(C30:C33) -> 39.932967 | T15: =SUM(D30:D33) -> 12.628571 | U15: =SUM(E30:E33) -> 17.658242 | V15: =SUM(F30:F33) -> 49.734615 | W15: =SUM(G30:G33) -> 2.2697802 | X15: =SUM(H30:H33) -> 1.932967 | Y15: =SUM(I30:I33) -> 14.953846 | Z15: =SUM(J30:J33) -> 8.1252747 | ... AF15: =SUM(P30:P33) -> 329.04571
B16: 08.30 - 08.45 | C16: =AVERAGE('78'!C16,'79'!C16,'80'!C16,'81'!C16,'82'!C16,'83'!C16,'84A'!C16,'84'!C16,'85'!C16,'86'!C16,'87'!C16,'88'!C16,'89'!C16,'91'!C16,'92'!C16,'93'!C16,'94'!C16,'94A'!C16,'95'!C16,'96'!C16,'97'!C16,'98'!C16,'142'!C16,'143'!C16,'90'!C16,'93A'!C16) -> 7.4846154 | D16: =AVERAGE('78'!D16,'79'!D16,'80'!D16,'81'!D16,'82'!D16,'83'!D16,'84A'!D16,'84'!D16,'85'!D16,'86'!D16,'87'!D16,'88'!D16,'89'!D16,'91'!D16,'92'!D16,'93'!D16,'94'!D16,'94A'!D16,'95'!D16,'96'!D16,'97'!D16,'98'!D16,'142'!D16,'143'!D16,'90'!D16,'93A'!D16) -> 2.693956 | E16: =AVERAGE('78'!E16,'79'!E16,'80'!E16,'81'!E16,'82'!E16,'83'!E16,'84A'!E16,'84'!E16,'85'!E16,'86'!E16,'87'!E16,'88'!E16,'89'!E16,'91'!E16,'92'!E16,'93'!E16,'94'!E16,'94A'!E16,'95'!E16,'96'!E16,'97'!E16,'98'!E16,'142'!E16,'143'!E16,'90'!E16,'93A'!E16) -> 3.4983516 | F16: =AVERAGE('78'!F16,'79'!F16,'80'!F16,'81'!F16,'82'!F16,'83'!F16,'84A'!F16,'84'!F16,'85'!F16,'86'!F16,'87'!F16,'88'!F16,'89'!F16,'91'!F16,'92'!F16,'93'!F16,'94'!F16,'94A'!F16,'95'!F16,'96'!F16,'97'!F16,'98'!F16,'142'!F16,'143'!F16,'90'!F16,'93A'!F16) -> 10.873077 | G16: =AVERAGE('78'!G16,'79'!G16,'80'!G16,'81'!G16,'82'!G16,'83'!G16,'84A'!G16,'84'!G16,'85'!G16,'86'!G16,'87'!G16,'88'!G16,'89'!G16,'91'!G16,'92'!G16,'93'!G16,'94'!G16,'94A'!G16,'95'!G16,'96'!G16,'97'!G16,'98'!G16,'142'!G16,'143'!G16,'90'!G16,'93A'!G16) -> 0.43571429 | H16: =AVERAGE('78'!H16,'79'!H16,'80'!H16,'81'!H16,'82'!H16,'83'!H16,'84A'!H16,'84'!H16,'85'!H16,'86'!H16,'87'!H16,'88'!H16,'89'!H16,'91'!H16,'92'!H16,'93'!H16,'94'!H16,'94A'!H16,'95'!H16,'96'!H16,'97'!H16,'98'!H16,'142'!H16,'143'!H16,'90'!H16,'93A'!H16) -> 0.35384615 | I16: =AVERAGE('78'!I16,'79'!I16,'80'!I16,'81'!I16,'82'!I16,'83'!I16,'84A'!I16,'84'!I16,'85'!I16,'86'!I16,'87'!I16,'88'!I16,'89'!I16,'91'!I16,'92'!I16,'93'!I16,'94'!I16,'94A'!I16,'95'!I16,'96'!I16,'97'!I16,'98'!I16,'142'!I16,'143'!I16,'90'!I16,'93A'!I16) -> 2.928022 | J16: =AVERAGE('78'!J16,'79'!J16,'80'!J16,'81'!J16,'82'!J16,'83'!J16,'84A'!J16,'84'!J16,'85'!J16,'86'!J16,'87'!J16,'88'!J16,'89'!J16,'91'!J16,'92'!J16,'93'!J16,'94'!J16,'94A'!J16,'95'!J16,'96'!J16,'97'!J16,'98'!J16,'142'!J16,'143'!J16,'90'!J16,'93A'!J16) -> 1.9659341 | ... N16: =AVERAGE('78'!N16,'79'!N16,'80'!N16,'81'!N16,'82'!N16,'83'!N16,'84A'!N16,'84'!N16,'85'!N16,'86'!N16,'87'!N16,'88'!N16,'89'!N16,'91'!N16,'92'!N16,'93'!N16,'94'!N16,'94A'!N16,'95'!N16,'96'!N16,'97'!N16,'98'!N16,'142'!N16,'143'!N16,'90'!N16,'93A'!N16) -> 0.090659341 | O16: =AVERAGE('78'!O16,'79'!O16,'80'!O16,'81'!O16,'82'!O16,'83'!O16,'84A'!O16,'84'!O16,'85'!O16,'86'!O16,'87'!O16,'88'!O16,'89'!O16,'91'!O16,'92'!O16,'93'!O16,'94'!O16,'94A'!O16,'95'!O16,'96'!O16,'97'!O16,'98'!O16,'142'!O16,'143'!O16,'90'!O16) -> 30.937143 | P16: =AVERAGE('78'!P16,'79'!P16,'80'!P16,'81'!P16,'82'!P16,'83'!P16,'84A'!P16,'84'!P16,'85'!P16,'86'!P16,'87'!P16,'88'!P16,'89'!P16,'91'!P16,'92'!P16,'93'!P16,'94'!P16,'94A'!P16,'95'!P16,'96'!P16,'97'!P16,'98'!P16,'142'!P16,'143'!P16,'90'!P16) -> 73.371429 | R16: 1300-1400 | S16: =SUM(C34:C37) -> 40.451099 | T16: =SUM(D34:D37) -> 11.499451 | U16: =SUM(E34:E37) -> 18.456593 | V16: =SUM(F34:F37) -> 51.50989 | W16: =SUM(G34:G37) -> 2.2373626 | X16: =SUM(H34:H37) -> 2.2115385 | Y16: =SUM(I34:I37) -> 16.585165 | Z16: =SUM(J34:J37) -> 9.2049451 | ... AF16: =SUM(P34:P37) -> 329.14286
B17: 08.45 - 9.00 | C17: =AVERAGE('78'!C17,'79'!C17,'80'!C17,'81'!C17,'82'!C17,'83'!C17,'84A'!C17,'84'!C17,'85'!C17,'86'!C17,'87'!C17,'88'!C17,'89'!C17,'91'!C17,'92'!C17,'93'!C17,'94'!C17,'94A'!C17,'95'!C17,'96'!C17,'97'!C17,'98'!C17,'142'!C17,'143'!C17,'90'!C17,'93A'!C17) -> 7.3906593 | D17: =AVERAGE('78'!D17,'79'!D17,'80'!D17,'81'!D17,'82'!D17,'83'!D17,'84A'!D17,'84'!D17,'85'!D17,'86'!D17,'87'!D17,'88'!D17,'89'!D17,'91'!D17,'92'!D17,'93'!D17,'94'!D17,'94A'!D17,'95'!D17,'96'!D17,'97'!D17,'98'!D17,'142'!D17,'143'!D17,'90'!D17,'93A'!D17) -> 2.5450549 | E17: =AVERAGE('78'!E17,'79'!E17,'80'!E17,'81'!E17,'82'!E17,'83'!E17,'84A'!E17,'84'!E17,'85'!E17,'86'!E17,'87'!E17,'88'!E17,'89'!E17,'91'!E17,'92'!E17,'93'!E17,'94'!E17,'94A'!E17,'95'!E17,'96'!E17,'97'!E17,'98'!E17,'142'!E17,'143'!E17,'90'!E17,'93A'!E17) -> 3.6791209 | F17: =AVERAGE('78'!F17,'79'!F17,'80'!F17,'81'!F17,'82'!F17,'83'!F17,'84A'!F17,'84'!F17,'85'!F17,'86'!F17,'87'!F17,'88'!F17,'89'!F17,'91'!F17,'92'!F17,'93'!F17,'94'!F17,'94A'!F17,'95'!F17,'96'!F17,'97'!F17,'98'!F17,'142'!F17,'143'!F17,'90'!F17,'93A'!F17) -> 10.874176 | G17: =AVERAGE('78'!G17,'79'!G17,'80'!G17,'81'!G17,'82'!G17,'83'!G17,'84A'!G17,'84'!G17,'85'!G17,'86'!G17,'87'!G17,'88'!G17,'89'!G17,'91'!G17,'92'!G17,'93'!G17,'94'!G17,'94A'!G17,'95'!G17,'96'!G17,'97'!G17,'98'!G17,'142'!G17,'143'!G17,'90'!G17,'93A'!G17) -> 0.58021978 | H17: =AVERAGE('78'!H17,'79'!H17,'80'!H17,'81'!H17,'82'!H17,'83'!H17,'84A'!H17,'84'!H17,'85'!H17,'86'!H17,'87'!H17,'88'!H17,'89'!H17,'91'!H17,'92'!H17,'93'!H17,'94'!H17,'94A'!H17,'95'!H17,'96'!H17,'97'!H17,'98'!H17,'142'!H17,'143'!H17,'90'!H17,'93A'!H17) -> 0.37087912 | I17: =AVERAGE('78'!I17,'79'!I17,'80'!I17,'81'!I17,'82'!I17,'83'!I17,'84A'!I17,'84'!I17,'85'!I17,'86'!I17,'87'!I17,'88'!I17,'89'!I17,'91'!I17,'92'!I17,'93'!I17,'94'!I17,'94A'!I17,'95'!I17,'96'!I17,'97'!I17,'98'!I17,'142'!I17,'143'!I17,'90'!I17,'93A'!I17) -> 2.6637363 | J17: =AVERAGE('78'!J17,'79'!J17,'80'!J17,'81'!J17,'82'!J17,'83'!J17,'84A'!J17,'84'!J17,'85'!J17,'86'!J17,'87'!J17,'88'!J17,'89'!J17,'91'!J17,'92'!J17,'93'!J17,'94'!J17,'94A'!J17,'95'!J17,'96'!J17,'97'!J17,'98'!J17,'142'!J17,'143'!J17,'90'!J17,'93A'!J17) -> 1.5357143 | ... N17: =AVERAGE('78'!N17,'79'!N17,'80'!N17,'81'!N17,'82'!N17,'83'!N17,'84A'!N17,'84'!N17,'85'!N17,'86'!N17,'87'!N17,'88'!N17,'89'!N17,'91'!N17,'92'!N17,'93'!N17,'94'!N17,'94A'!N17,'95'!N17,'96'!N17,'97'!N17,'98'!N17,'142'!N17,'143'!N17,'90'!N17,'93A'!N17) -> 0.16978022 | O17: =AVERAGE('78'!O17,'79'!O17,'80'!O17,'81'!O17,'82'!O17,'83'!O17,'84A'!O17,'84'!O17,'85'!O17,'86'!O17,'87'!O17,'88'!O17,'89'!O17,'91'!O17,'92'!O17,'93'!O17,'94'!O17,'94A'!O17,'95'!O17,'96'!O17,'97'!O17,'98'!O17,'142'!O17,'143'!O17,'90'!O17) -> 30.754286 | P17: =AVERAGE('78'!P17,'79'!P17,'80'!P17,'81'!P17,'82'!P17,'83'!P17,'84A'!P17,'84'!P17,'85'!P17,'86'!P17,'87'!P17,'88'!P17,'89'!P17,'91'!P17,'92'!P17,'93'!P17,'94'!P17,'94A'!P17,'95'!P17,'96'!P17,'97'!P17,'98'!P17,'142'!P17,'143'!P17,'90'!P17) -> 73.725714 | R17: 1400-1500 | S17: =SUM(C38:C41) -> 38.82033 | T17: =SUM(D38:D41) -> 12.431319 | U17: =SUM(E38:E41) -> 19.258791 | V17: =SUM(F38:F41) -> 50.431319 | W17: =SUM(G38:G41) -> 1.9840659 | X17: =SUM(H38:H41) -> 2.767033 | Y17: =SUM(I38:I41) -> 16.277473 | Z17: =SUM(J38:J41) -> 9.9104396 | ... AF17: =SUM(P38:P41) -> 324.01714
B18: 09.00 - 09.15 | C18: =AVERAGE('78'!C18,'79'!C18,'80'!C18,'81'!C18,'82'!C18,'83'!C18,'84A'!C18,'84'!C18,'85'!C18,'86'!C18,'87'!C18,'88'!C18,'89'!C18,'91'!C18,'92'!C18,'93'!C18,'94'!C18,'94A'!C18,'95'!C18,'96'!C18,'97'!C18,'98'!C18,'142'!C18,'143'!C18,'90'!C18,'93A'!C18) -> 7.7851648 | D18: =AVERAGE('78'!D18,'79'!D18,'80'!D18,'81'!D18,'82'!D18,'83'!D18,'84A'!D18,'84'!D18,'85'!D18,'86'!D18,'87'!D18,'88'!D18,'89'!D18,'91'!D18,'92'!D18,'93'!D18,'94'!D18,'94A'!D18,'95'!D18,'96'!D18,'97'!D18,'98'!D18,'142'!D18,'143'!D18,'90'!D18,'93A'!D18) -> 2.6972527 | E18: =AVERAGE('78'!E18,'79'!E18,'80'!E18,'81'!E18,'82'!E18,'83'!E18,'84A'!E18,'84'!E18,'85'!E18,'86'!E18,'87'!E18,'88'!E18,'89'!E18,'91'!E18,'92'!E18,'93'!E18,'94'!E18,'94A'!E18,'95'!E18,'96'!E18,'97'!E18,'98'!E18,'142'!E18,'143'!E18,'90'!E18,'93A'!E18) -> 3.6741758 | F18: =AVERAGE('78'!F18,'79'!F18,'80'!F18,'81'!F18,'82'!F18,'83'!F18,'84A'!F18,'84'!F18,'85'!F18,'86'!F18,'87'!F18,'88'!F18,'89'!F18,'91'!F18,'92'!F18,'93'!F18,'94'!F18,'94A'!F18,'95'!F18,'96'!F18,'97'!F18,'98'!F18,'142'!F18,'143'!F18,'90'!F18,'93A'!F18) -> 10.800549 | G18: =AVERAGE('78'!G18,'79'!G18,'80'!G18,'81'!G18,'82'!G18,'83'!G18,'84A'!G18,'84'!G18,'85'!G18,'86'!G18,'87'!G18,'88'!G18,'89'!G18,'91'!G18,'92'!G18,'93'!G18,'94'!G18,'94A'!G18,'95'!G18,'96'!G18,'97'!G18,'98'!G18,'142'!G18,'143'!G18,'90'!G18,'93A'!G18) -> 0.58131868 | H18: =AVERAGE('78'!H18,'79'!H18,'80'!H18,'81'!H18,'82'!H18,'83'!H18,'84A'!H18,'84'!H18,'85'!H18,'86'!H18,'87'!H18,'88'!H18,'89'!H18,'91'!H18,'92'!H18,'93'!H18,'94'!H18,'94A'!H18,'95'!H18,'96'!H18,'97'!H18,'98'!H18,'142'!H18,'143'!H18,'90'!H18,'93A'!H18) -> 0.34010989 | I18: =AVERAGE('78'!I18,'79'!I18,'80'!I18,'81'!I18,'82'!I18,'83'!I18,'84A'!I18,'84'!I18,'85'!I18,'86'!I18,'87'!I18,'88'!I18,'89'!I18,'91'!I18,'92'!I18,'93'!I18,'94'!I18,'94A'!I18,'95'!I18,'96'!I18,'97'!I18,'98'!I18,'142'!I18,'143'!I18,'90'!I18,'93A'!I18) -> 2.8703297 | J18: =AVERAGE('78'!J18,'79'!J18,'80'!J18,'81'!J18,'82'!J18,'83'!J18,'84A'!J18,'84'!J18,'85'!J18,'86'!J18,'87'!J18,'88'!J18,'89'!J18,'91'!J18,'92'!J18,'93'!J18,'94'!J18,'94A'!J18,'95'!J18,'96'!J18,'97'!J18,'98'!J18,'142'!J18,'143'!J18,'90'!J18,'93A'!J18) -> 1.7450549 | ... N18: =AVERAGE('78'!N18,'79'!N18,'80'!N18,'81'!N18,'82'!N18,'83'!N18,'84A'!N18,'84'!N18,'85'!N18,'86'!N18,'87'!N18,'88'!N18,'89'!N18,'91'!N18,'92'!N18,'93'!N18,'94'!N18,'94A'!N18,'95'!N18,'96'!N18,'97'!N18,'98'!N18,'142'!N18,'143'!N18,'90'!N18,'93A'!N18) -> 0.081318681 | O18: =AVERAGE('78'!O18,'79'!O18,'80'!O18,'81'!O18,'82'!O18,'83'!O18,'84A'!O18,'84'!O18,'85'!O18,'86'!O18,'87'!O18,'88'!O18,'89'!O18,'91'!O18,'92'!O18,'93'!O18,'94'!O18,'94A'!O18,'95'!O18,'96'!O18,'97'!O18,'98'!O18,'142'!O18,'143'!O18,'90'!O18) -> 31.32 | P18: =AVERAGE('78'!P18,'79'!P18,'80'!P18,'81'!P18,'82'!P18,'83'!P18,'84A'!P18,'84'!P18,'85'!P18,'86'!P18,'87'!P18,'88'!P18,'89'!P18,'91'!P18,'92'!P18,'93'!P18,'94'!P18,'94A'!P18,'95'!P18,'96'!P18,'97'!P18,'98'!P18,'142'!P18,'143'!P18,'90'!P18) -> 73.188571 | R18: 1500-1600 | S18: =SUM(C42:C45) -> 40.041209 | T18: =SUM(D42:D45) -> 13.094505 | U18: =SUM(E42:E45) -> 19.474725 | V18: =SUM(F42:F45) -> 52.034615 | W18: =SUM(G42:G45) -> 1.6664835 | X18: =SUM(H42:H45) -> 2.321978 | Y18: =SUM(I42:I45) -> 17.079121 | Z18: =SUM(J42:J45) -> 10.921429 | ... AF18: =SUM(P42:P45) -> 332.21714
B19: 09.15 - 09.30 | C19: =AVERAGE('78'!C19,'79'!C19,'80'!C19,'81'!C19,'82'!C19,'83'!C19,'84A'!C19,'84'!C19,'85'!C19,'86'!C19,'87'!C19,'88'!C19,'89'!C19,'91'!C19,'92'!C19,'93'!C19,'94'!C19,'94A'!C19,'95'!C19,'96'!C19,'97'!C19,'98'!C19,'142'!C19,'143'!C19,'90'!C19,'93A'!C19) -> 7.9978022 | D19: =AVERAGE('78'!D19,'79'!D19,'80'!D19,'81'!D19,'82'!D19,'83'!D19,'84A'!D19,'84'!D19,'85'!D19,'86'!D19,'87'!D19,'88'!D19,'89'!D19,'91'!D19,'92'!D19,'93'!D19,'94'!D19,'94A'!D19,'95'!D19,'96'!D19,'97'!D19,'98'!D19,'142'!D19,'143'!D19,'90'!D19,'93A'!D19) -> 3.0104396 | E19: =AVERAGE('78'!E19,'79'!E19,'80'!E19,'81'!E19,'82'!E19,'83'!E19,'84A'!E19,'84'!E19,'85'!E19,'86'!E19,'87'!E19,'88'!E19,'89'!E19,'91'!E19,'92'!E19,'93'!E19,'94'!E19,'94A'!E19,'95'!E19,'96'!E19,'97'!E19,'98'!E19,'142'!E19,'143'!E19,'90'!E19,'93A'!E19) -> 3.8912088 | F19: =AVERAGE('78'!F19,'79'!F19,'80'!F19,'81'!F19,'82'!F19,'83'!F19,'84A'!F19,'84'!F19,'85'!F19,'86'!F19,'87'!F19,'88'!F19,'89'!F19,'91'!F19,'92'!F19,'93'!F19,'94'!F19,'94A'!F19,'95'!F19,'96'!F19,'97'!F19,'98'!F19,'142'!F19,'143'!F19,'90'!F19,'93A'!F19) -> 11.931868 | G19: =AVERAGE('78'!G19,'79'!G19,'80'!G19,'81'!G19,'82'!G19,'83'!G19,'84A'!G19,'84'!G19,'85'!G19,'86'!G19,'87'!G19,'88'!G19,'89'!G19,'91'!G19,'92'!G19,'93'!G19,'94'!G19,'94A'!G19,'95'!G19,'96'!G19,'97'!G19,'98'!G19,'142'!G19,'143'!G19,'90'!G19,'93A'!G19) -> 0.53791209 | H19: =AVERAGE('78'!H19,'79'!H19,'80'!H19,'81'!H19,'82'!H19,'83'!H19,'84A'!H19,'84'!H19,'85'!H19,'86'!H19,'87'!H19,'88'!H19,'89'!H19,'91'!H19,'92'!H19,'93'!H19,'94'!H19,'94A'!H19,'95'!H19,'96'!H19,'97'!H19,'98'!H19,'142'!H19,'143'!H19,'90'!H19,'93A'!H19) -> 0.44285714 | I19: =AVERAGE('78'!I19,'79'!I19,'80'!I19,'81'!I19,'82'!I19,'83'!I19,'84A'!I19,'84'!I19,'85'!I19,'86'!I19,'87'!I19,'88'!I19,'89'!I19,'91'!I19,'92'!I19,'93'!I19,'94'!I19,'94A'!I19,'95'!I19,'96'!I19,'97'!I19,'98'!I19,'142'!I19,'143'!I19,'90'!I19,'93A'!I19) -> 2.8648352 | J19: =AVERAGE('78'!J19,'79'!J19,'80'!J19,'81'!J19,'82'!J19,'83'!J19,'84A'!J19,'84'!J19,'85'!J19,'86'!J19,'87'!J19,'88'!J19,'89'!J19,'91'!J19,'92'!J19,'93'!J19,'94'!J19,'94A'!J19,'95'!J19,'96'!J19,'97'!J19,'98'!J19,'142'!J19,'143'!J19,'90'!J19,'93A'!J19) -> 1.6076923 | ... N19: =AVERAGE('78'!N19,'79'!N19,'80'!N19,'81'!N19,'82'!N19,'83'!N19,'84A'!N19,'84'!N19,'85'!N19,'86'!N19,'87'!N19,'88'!N19,'89'!N19,'91'!N19,'92'!N19,'93'!N19,'94'!N19,'94A'!N19,'95'!N19,'96'!N19,'97'!N19,'98'!N19,'142'!N19,'143'!N19,'90'!N19,'93A'!N19) -> 0.06978022 | O19: =AVERAGE('78'!O19,'79'!O19,'80'!O19,'81'!O19,'82'!O19,'83'!O19,'84A'!O19,'84'!O19,'85'!O19,'86'!O19,'87'!O19,'88'!O19,'89'!O19,'91'!O19,'92'!O19,'93'!O19,'94'!O19,'94A'!O19,'95'!O19,'96'!O19,'97'!O19,'98'!O19,'142'!O19,'143'!O19,'90'!O19) -> 33.171429 | P19: =AVERAGE('78'!P19,'79'!P19,'80'!P19,'81'!P19,'82'!P19,'83'!P19,'84A'!P19,'84'!P19,'85'!P19,'86'!P19,'87'!P19,'88'!P19,'89'!P19,'91'!P19,'92'!P19,'93'!P19,'94'!P19,'94A'!P19,'95'!P19,'96'!P19,'97'!P19,'98'!P19,'142'!P19,'143'!P19,'90'!P19) -> 75.365714 | R19: 1600-1700 | S19: =SUM(C46:C49) -> 42.226374 | T19: =SUM(D46:D49) -> 13.925275 | U19: =SUM(E46:E49) -> 20.451099 | V19: =SUM(F46:F49) -> 51.051648 | W19: =SUM(G46:G49) -> 1.8148352 | X19: =SUM(H46:H49) -> 2.1824176 | Y19: =SUM(I46:I49) -> 18.604396 | Z19: =SUM(J46:J49) -> 10.775275 | ... AF19: =SUM(P46:P49) -> 349.30857
B20: 09.30 - 09.45 | C20: =AVERAGE('78'!C20,'79'!C20,'80'!C20,'81'!C20,'82'!C20,'83'!C20,'84A'!C20,'84'!C20,'85'!C20,'86'!C20,'87'!C20,'88'!C20,'89'!C20,'91'!C20,'92'!C20,'93'!C20,'94'!C20,'94A'!C20,'95'!C20,'96'!C20,'97'!C20,'98'!C20,'142'!C20,'143'!C20,'90'!C20,'93A'!C20) -> 8.771978 | D20: =AVERAGE('78'!D20,'79'!D20,'80'!D20,'81'!D20,'82'!D20,'83'!D20,'84A'!D20,'84'!D20,'85'!D20,'86'!D20,'87'!D20,'88'!D20,'89'!D20,'91'!D20,'92'!D20,'93'!D20,'94'!D20,'94A'!D20,'95'!D20,'96'!D20,'97'!D20,'98'!D20,'142'!D20,'143'!D20,'90'!D20,'93A'!D20) -> 2.8016484 | E20: =AVERAGE('78'!E20,'79'!E20,'80'!E20,'81'!E20,'82'!E20,'83'!E20,'84A'!E20,'84'!E20,'85'!E20,'86'!E20,'87'!E20,'88'!E20,'89'!E20,'91'!E20,'92'!E20,'93'!E20,'94'!E20,'94A'!E20,'95'!E20,'96'!E20,'97'!E20,'98'!E20,'142'!E20,'143'!E20,'90'!E20,'93A'!E20) -> 4.1565934 | F20: =AVERAGE('78'!F20,'79'!F20,'80'!F20,'81'!F20,'82'!F20,'83'!F20,'84A'!F20,'84'!F20,'85'!F20,'86'!F20,'87'!F20,'88'!F20,'89'!F20,'91'!F20,'92'!F20,'93'!F20,'94'!F20,'94A'!F20,'95'!F20,'96'!F20,'97'!F20,'98'!F20,'142'!F20,'143'!F20,'90'!F20,'93A'!F20) -> 12.074725 | G20: =AVERAGE('78'!G20,'79'!G20,'80'!G20,'81'!G20,'82'!G20,'83'!G20,'84A'!G20,'84'!G20,'85'!G20,'86'!G20,'87'!G20,'88'!G20,'89'!G20,'91'!G20,'92'!G20,'93'!G20,'94'!G20,'94A'!G20,'95'!G20,'96'!G20,'97'!G20,'98'!G20,'142'!G20,'143'!G20,'90'!G20,'93A'!G20) -> 0.39395604 | H20: =AVERAGE('78'!H20,'79'!H20,'80'!H20,'81'!H20,'82'!H20,'83'!H20,'84A'!H20,'84'!H20,'85'!H20,'86'!H20,'87'!H20,'88'!H20,'89'!H20,'91'!H20,'92'!H20,'93'!H20,'94'!H20,'94A'!H20,'95'!H20,'96'!H20,'97'!H20,'98'!H20,'142'!H20,'143'!H20,'90'!H20,'93A'!H20) -> 0.42747253 | I20: =AVERAGE('78'!I20,'79'!I20,'80'!I20,'81'!I20,'82'!I20,'83'!I20,'84A'!I20,'84'!I20,'85'!I20,'86'!I20,'87'!I20,'88'!I20,'89'!I20,'91'!I20,'92'!I20,'93'!I20,'94'!I20,'94A'!I20,'95'!I20,'96'!I20,'97'!I20,'98'!I20,'142'!I20,'143'!I20,'90'!I20,'93A'!I20) -> 2.9005495 | J20: =AVERAGE('78'!J20,'79'!J20,'80'!J20,'81'!J20,'82'!J20,'83'!J20,'84A'!J20,'84'!J20,'85'!J20,'86'!J20,'87'!J20,'88'!J20,'89'!J20,'91'!J20,'92'!J20,'93'!J20,'94'!J20,'94A'!J20,'95'!J20,'96'!J20,'97'!J20,'98'!J20,'142'!J20,'143'!J20,'90'!J20,'93A'!J20) -> 1.6857143 | ... N20: =AVERAGE('78'!N20,'79'!N20,'80'!N20,'81'!N20,'82'!N20,'83'!N20,'84A'!N20,'84'!N20,'85'!N20,'86'!N20,'87'!N20,'88'!N20,'89'!N20,'91'!N20,'92'!N20,'93'!N20,'94'!N20,'94A'!N20,'95'!N20,'96'!N20,'97'!N20,'98'!N20,'142'!N20,'143'!N20,'90'!N20,'93A'!N20) -> 0.11153846 | O20: =AVERAGE('78'!O20,'79'!O20,'80'!O20,'81'!O20,'82'!O20,'83'!O20,'84A'!O20,'84'!O20,'85'!O20,'86'!O20,'87'!O20,'88'!O20,'89'!O20,'91'!O20,'92'!O20,'93'!O20,'94'!O20,'94A'!O20,'95'!O20,'96'!O20,'97'!O20,'98'!O20,'142'!O20,'143'!O20,'90'!O20) -> 34.228571 | P20: =AVERAGE('78'!P20,'79'!P20,'80'!P20,'81'!P20,'82'!P20,'83'!P20,'84A'!P20,'84'!P20,'85'!P20,'86'!P20,'87'!P20,'88'!P20,'89'!P20,'91'!P20,'92'!P20,'93'!P20,'94'!P20,'94A'!P20,'95'!P20,'96'!P20,'97'!P20,'98'!P20,'142'!P20,'143'!P20,'90'!P20) -> 77.554286 | R20: 1700-1800 | S20: =SUM(C50:C53) -> 46.33022 | T20: =SUM(D50:D53) -> 15.868132 | U20: =SUM(E50:E53) -> 21.467582 | V20: =SUM(F50:F53) -> 55.871429 | W20: =SUM(G50:G53) -> 2.6615385 | X20: =SUM(H50:H53) -> 2.2247253 | Y20: =SUM(I50:I53) -> 18.624176 | Z20: =SUM(J50:J53) -> 11.728022 | ... AF20: =SUM(P50:P53) -> 376.66857
B21: 09.45 - 10.00 | C21: =AVERAGE('78'!C21,'79'!C21,'80'!C21,'81'!C21,'82'!C21,'83'!C21,'84A'!C21,'84'!C21,'85'!C21,'86'!C21,'87'!C21,'88'!C21,'89'!C21,'91'!C21,'92'!C21,'93'!C21,'94'!C21,'94A'!C21,'95'!C21,'96'!C21,'97'!C21,'98'!C21,'142'!C21,'143'!C21,'90'!C21,'93A'!C21) -> 8.7549451 | D21: =AVERAGE('78'!D21,'79'!D21,'80'!D21,'81'!D21,'82'!D21,'83'!D21,'84A'!D21,'84'!D21,'85'!D21,'86'!D21,'87'!D21,'88'!D21,'89'!D21,'91'!D21,'92'!D21,'93'!D21,'94'!D21,'94A'!D21,'95'!D21,'96'!D21,'97'!D21,'98'!D21,'142'!D21,'143'!D21,'90'!D21,'93A'!D21) -> 3.0901099 | E21: =AVERAGE('78'!E21,'79'!E21,'80'!E21,'81'!E21,'82'!E21,'83'!E21,'84A'!E21,'84'!E21,'85'!E21,'86'!E21,'87'!E21,'88'!E21,'89'!E21,'91'!E21,'92'!E21,'93'!E21,'94'!E21,'94A'!E21,'95'!E21,'96'!E21,'97'!E21,'98'!E21,'142'!E21,'143'!E21,'90'!E21,'93A'!E21) -> 4.0989011 | F21: =AVERAGE('78'!F21,'79'!F21,'80'!F21,'81'!F21,'82'!F21,'83'!F21,'84A'!F21,'84'!F21,'85'!F21,'86'!F21,'87'!F21,'88'!F21,'89'!F21,'91'!F21,'92'!F21,'93'!F21,'94'!F21,'94A'!F21,'95'!F21,'96'!F21,'97'!F21,'98'!F21,'142'!F21,'143'!F21,'90'!F21,'93A'!F21) -> 12.095055 | G21: =AVERAGE('78'!G21,'79'!G21,'80'!G21,'81'!G21,'82'!G21,'83'!G21,'84A'!G21,'84'!G21,'85'!G21,'86'!G21,'87'!G21,'88'!G21,'89'!G21,'91'!G21,'92'!G21,'93'!G21,'94'!G21,'94A'!G21,'95'!G21,'96'!G21,'97'!G21,'98'!G21,'142'!G21,'143'!G21,'90'!G21,'93A'!G21) -> 0.35494505 | H21: =AVERAGE('78'!H21,'79'!H21,'80'!H21,'81'!H21,'82'!H21,'83'!H21,'84A'!H21,'84'!H21,'85'!H21,'86'!H21,'87'!H21,'88'!H21,'89'!H21,'91'!H21,'92'!H21,'93'!H21,'94'!H21,'94A'!H21,'95'!H21,'96'!H21,'97'!H21,'98'!H21,'142'!H21,'143'!H21,'90'!H21,'93A'!H21) -> 0.33296703 | I21: =AVERAGE('78'!I21,'79'!I21,'80'!I21,'81'!I21,'82'!I21,'83'!I21,'84A'!I21,'84'!I21,'85'!I21,'86'!I21,'87'!I21,'88'!I21,'89'!I21,'91'!I21,'92'!I21,'93'!I21,'94'!I21,'94A'!I21,'95'!I21,'96'!I21,'97'!I21,'98'!I21,'142'!I21,'143'!I21,'90'!I21,'93A'!I21) -> 3.0604396 | J21: =AVERAGE('78'!J21,'79'!J21,'80'!J21,'81'!J21,'82'!J21,'83'!J21,'84A'!J21,'84'!J21,'85'!J21,'86'!J21,'87'!J21,'88'!J21,'89'!J21,'91'!J21,'92'!J21,'93'!J21,'94'!J21,'94A'!J21,'95'!J21,'96'!J21,'97'!J21,'98'!J21,'142'!J21,'143'!J21,'90'!J21,'93A'!J21) -> 1.5412088 | ... N21: =AVERAGE('78'!N21,'79'!N21,'80'!N21,'81'!N21,'82'!N21,'83'!N21,'84A'!N21,'84'!N21,'85'!N21,'86'!N21,'87'!N21,'88'!N21,'89'!N21,'91'!N21,'92'!N21,'93'!N21,'94'!N21,'94A'!N21,'95'!N21,'96'!N21,'97'!N21,'98'!N21,'142'!N21,'143'!N21,'90'!N21,'93A'!N21) -> 0.043956044 | O21: =AVERAGE('78'!O21,'79'!O21,'80'!O21,'81'!O21,'82'!O21,'83'!O21,'84A'!O21,'84'!O21,'85'!O21,'86'!O21,'87'!O21,'88'!O21,'89'!O21,'91'!O21,'92'!O21,'93'!O21,'94'!O21,'94A'!O21,'95'!O21,'96'!O21,'97'!O21,'98'!O21,'142'!O21,'143'!O21,'90'!O21) -> 33.24 | P21: =AVERAGE('78'!P21,'79'!P21,'80'!P21,'81'!P21,'82'!P21,'83'!P21,'84A'!P21,'84'!P21,'85'!P21,'86'!P21,'87'!P21,'88'!P21,'89'!P21,'91'!P21,'92'!P21,'93'!P21,'94'!P21,'94A'!P21,'95'!P21,'96'!P21,'97'!P21,'98'!P21,'142'!P21,'143'!P21,'90'!P21) -> 76.754286 | R21: 1800-1900 | S21: =SUM(C54:C57) -> 46.959341 | T21: =SUM(D54:D57) -> 14.356044 | U21: =SUM(E54:E57) -> 21.673077 | V21: =SUM(F54:F57) -> 55.191209 | W21: =SUM(G54:G57) -> 3.7043956 | X21: =SUM(H54:H57) -> 2.5785714 | Y21: =SUM(I54:I57) -> 19.516484 | Z21: =SUM(J54:J57) -> 12.486813 | ... AF21: =SUM(P54:P57) -> 374.43619
B22: 10.00 - 10.15 | C22: =AVERAGE('78'!C22,'79'!C22,'80'!C22,'81'!C22,'82'!C22,'83'!C22,'84A'!C22,'84'!C22,'85'!C22,'86'!C22,'87'!C22,'88'!C22,'89'!C22,'91'!C22,'92'!C22,'93'!C22,'94'!C22,'94A'!C22,'95'!C22,'96'!C22,'97'!C22,'98'!C22,'142'!C22,'143'!C22,'90'!C22,'93A'!C22) -> 9.1478022 | D22: =AVERAGE('78'!D22,'79'!D22,'80'!D22,'81'!D22,'82'!D22,'83'!D22,'84A'!D22,'84'!D22,'85'!D22,'86'!D22,'87'!D22,'88'!D22,'89'!D22,'91'!D22,'92'!D22,'93'!D22,'94'!D22,'94A'!D22,'95'!D22,'96'!D22,'97'!D22,'98'!D22,'142'!D22,'143'!D22,'90'!D22,'93A'!D22) -> 3.1428571 | E22: =AVERAGE('78'!E22,'79'!E22,'80'!E22,'81'!E22,'82'!E22,'83'!E22,'84A'!E22,'84'!E22,'85'!E22,'86'!E22,'87'!E22,'88'!E22,'89'!E22,'91'!E22,'92'!E22,'93'!E22,'94'!E22,'94A'!E22,'95'!E22,'96'!E22,'97'!E22,'98'!E22,'142'!E22,'143'!E22,'90'!E22,'93A'!E22) -> 4.132967 | F22: =AVERAGE('78'!F22,'79'!F22,'80'!F22,'81'!F22,'82'!F22,'83'!F22,'84A'!F22,'84'!F22,'85'!F22,'86'!F22,'87'!F22,'88'!F22,'89'!F22,'91'!F22,'92'!F22,'93'!F22,'94'!F22,'94A'!F22,'95'!F22,'96'!F22,'97'!F22,'98'!F22,'142'!F22,'143'!F22,'90'!F22,'93A'!F22) -> 12.028022 | G22: =AVERAGE('78'!G22,'79'!G22,'80'!G22,'81'!G22,'82'!G22,'83'!G22,'84A'!G22,'84'!G22,'85'!G22,'86'!G22,'87'!G22,'88'!G22,'89'!G22,'91'!G22,'92'!G22,'93'!G22,'94'!G22,'94A'!G22,'95'!G22,'96'!G22,'97'!G22,'98'!G22,'142'!G22,'143'!G22,'90'!G22,'93A'!G22) -> 0.3489011 | H22: =AVERAGE('78'!H22,'79'!H22,'80'!H22,'81'!H22,'82'!H22,'83'!H22,'84A'!H22,'84'!H22,'85'!H22,'86'!H22,'87'!H22,'88'!H22,'89'!H22,'91'!H22,'92'!H22,'93'!H22,'94'!H22,'94A'!H22,'95'!H22,'96'!H22,'97'!H22,'98'!H22,'142'!H22,'143'!H22,'90'!H22,'93A'!H22) -> 0.48241758 | I22: =AVERAGE('78'!I22,'79'!I22,'80'!I22,'81'!I22,'82'!I22,'83'!I22,'84A'!I22,'84'!I22,'85'!I22,'86'!I22,'87'!I22,'88'!I22,'89'!I22,'91'!I22,'92'!I22,'93'!I22,'94'!I22,'94A'!I22,'95'!I22,'96'!I22,'97'!I22,'98'!I22,'142'!I22,'143'!I22,'90'!I22,'93A'!I22) -> 3.2785714 | J22: =AVERAGE('78'!J22,'79'!J22,'80'!J22,'81'!J22,'82'!J22,'83'!J22,'84A'!J22,'84'!J22,'85'!J22,'86'!J22,'87'!J22,'88'!J22,'89'!J22,'91'!J22,'92'!J22,'93'!J22,'94'!J22,'94A'!J22,'95'!J22,'96'!J22,'97'!J22,'98'!J22,'142'!J22,'143'!J22,'90'!J22,'93A'!J22) -> 1.8653846 | ... N22: =AVERAGE('78'!N22,'79'!N22,'80'!N22,'81'!N22,'82'!N22,'83'!N22,'84A'!N22,'84'!N22,'85'!N22,'86'!N22,'87'!N22,'88'!N22,'89'!N22,'91'!N22,'92'!N22,'93'!N22,'94'!N22,'94A'!N22,'95'!N22,'96'!N22,'97'!N22,'98'!N22,'142'!N22,'143'!N22,'90'!N22,'93A'!N22) -> 0.062637363 | O22: =AVERAGE('78'!O22,'79'!O22,'80'!O22,'81'!O22,'82'!O22,'83'!O22,'84A'!O22,'84'!O22,'85'!O22,'86'!O22,'87'!O22,'88'!O22,'89'!O22,'91'!O22,'92'!O22,'93'!O22,'94'!O22,'94A'!O22,'95'!O22,'96'!O22,'97'!O22,'98'!O22,'142'!O22,'143'!O22,'90'!O22) -> 34.668571 | P22: =AVERAGE('78'!P22,'79'!P22,'80'!P22,'81'!P22,'82'!P22,'83'!P22,'84A'!P22,'84'!P22,'85'!P22,'86'!P22,'87'!P22,'88'!P22,'89'!P22,'91'!P22,'92'!P22,'93'!P22,'94'!P22,'94A'!P22,'95'!P22,'96'!P22,'97'!P22,'98'!P22,'142'!P22,'143'!P22,'90'!P22) -> 78.377143 | R22: 1900-2000 | S22: =SUM(C58:C61) -> 47.103846 | T22: =SUM(D58:D61) -> 11.307692 | U22: =SUM(E58:E61) -> 13.934615 | V22: =SUM(F58:F61) -> 42.076923 | W22: =SUM(G58:G61) -> 3.0923077 | X22: =SUM(H58:H61) -> 4.2865385 | Y22: =SUM(I58:I61) -> 17.896154 | Z22: =SUM(J58:J61) -> 11.113462 | ... AF22: =SUM(P58:P61) -> 322.76
B23: 10.15 - 10.30 | C23: =AVERAGE('78'!C23,'79'!C23,'80'!C23,'81'!C23,'82'!C23,'83'!C23,'84A'!C23,'84'!C23,'85'!C23,'86'!C23,'87'!C23,'88'!C23,'89'!C23,'91'!C23,'92'!C23,'93'!C23,'94'!C23,'94A'!C23,'95'!C23,'96'!C23,'97'!C23,'98'!C23,'142'!C23,'143'!C23,'90'!C23,'93A'!C23) -> 8.7318681 | D23: =AVERAGE('78'!D23,'79'!D23,'80'!D23,'81'!D23,'82'!D23,'83'!D23,'84A'!D23,'84'!D23,'85'!D23,'86'!D23,'87'!D23,'88'!D23,'89'!D23,'91'!D23,'92'!D23,'93'!D23,'94'!D23,'94A'!D23,'95'!D23,'96'!D23,'97'!D23,'98'!D23,'142'!D23,'143'!D23,'90'!D23,'93A'!D23) -> 3.0159341 | E23: =AVERAGE('78'!E23,'79'!E23,'80'!E23,'81'!E23,'82'!E23,'83'!E23,'84A'!E23,'84'!E23,'85'!E23,'86'!E23,'87'!E23,'88'!E23,'89'!E23,'91'!E23,'92'!E23,'93'!E23,'94'!E23,'94A'!E23,'95'!E23,'96'!E23,'97'!E23,'98'!E23,'142'!E23,'143'!E23,'90'!E23,'93A'!E23) -> 4.3543956 | F23: =AVERAGE('78'!F23,'79'!F23,'80'!F23,'81'!F23,'82'!F23,'83'!F23,'84A'!F23,'84'!F23,'85'!F23,'86'!F23,'87'!F23,'88'!F23,'89'!F23,'91'!F23,'92'!F23,'93'!F23,'94'!F23,'94A'!F23,'95'!F23,'96'!F23,'97'!F23,'98'!F23,'142'!F23,'143'!F23,'90'!F23,'93A'!F23) -> 12.316484 | G23: =AVERAGE('78'!G23,'79'!G23,'80'!G23,'81'!G23,'82'!G23,'83'!G23,'84A'!G23,'84'!G23,'85'!G23,'86'!G23,'87'!G23,'88'!G23,'89'!G23,'91'!G23,'92'!G23,'93'!G23,'94'!G23,'94A'!G23,'95'!G23,'96'!G23,'97'!G23,'98'!G23,'142'!G23,'143'!G23,'90'!G23,'93A'!G23) -> 0.25164835 | H23: =AVERAGE('78'!H23,'79'!H23,'80'!H23,'81'!H23,'82'!H23,'83'!H23,'84A'!H23,'84'!H23,'85'!H23,'86'!H23,'87'!H23,'88'!H23,'89'!H23,'91'!H23,'92'!H23,'93'!H23,'94'!H23,'94A'!H23,'95'!H23,'96'!H23,'97'!H23,'98'!H23,'142'!H23,'143'!H23,'90'!H23,'93A'!H23) -> 0.35 | I23: =AVERAGE('78'!I23,'79'!I23,'80'!I23,'81'!I23,'82'!I23,'83'!I23,'84A'!I23,'84'!I23,'85'!I23,'86'!I23,'87'!I23,'88'!I23,'89'!I23,'91'!I23,'92'!I23,'93'!I23,'94'!I23,'94A'!I23,'95'!I23,'96'!I23,'97'!I23,'98'!I23,'142'!I23,'143'!I23,'90'!I23,'93A'!I23) -> 3.3131868 | J23: =AVERAGE('78'!J23,'79'!J23,'80'!J23,'81'!J23,'82'!J23,'83'!J23,'84A'!J23,'84'!J23,'85'!J23,'86'!J23,'87'!J23,'88'!J23,'89'!J23,'91'!J23,'92'!J23,'93'!J23,'94'!J23,'94A'!J23,'95'!J23,'96'!J23,'97'!J23,'98'!J23,'142'!J23,'143'!J23,'90'!J23,'93A'!J23) -> 1.9510989 | ... N23: =AVERAGE('78'!N23,'79'!N23,'80'!N23,'81'!N23,'82'!N23,'83'!N23,'84A'!N23,'84'!N23,'85'!N23,'86'!N23,'87'!N23,'88'!N23,'89'!N23,'91'!N23,'92'!N23,'93'!N23,'94'!N23,'94A'!N23,'95'!N23,'96'!N23,'97'!N23,'98'!N23,'142'!N23,'143'!N23,'90'!N23,'93A'!N23) -> 0.064835165 | O23: =AVERAGE('78'!O23,'79'!O23,'80'!O23,'81'!O23,'82'!O23,'83'!O23,'84A'!O23,'84'!O23,'85'!O23,'86'!O23,'87'!O23,'88'!O23,'89'!O23,'91'!O23,'92'!O23,'93'!O23,'94'!O23,'94A'!O23,'95'!O23,'96'!O23,'97'!O23,'98'!O23,'142'!O23,'143'!O23,'90'!O23) -> 34.806286 | P23: =AVERAGE('78'!P23,'79'!P23,'80'!P23,'81'!P23,'82'!P23,'83'!P23,'84A'!P23,'84'!P23,'85'!P23,'86'!P23,'87'!P23,'88'!P23,'89'!P23,'91'!P23,'92'!P23,'93'!P23,'94'!P23,'94A'!P23,'95'!P23,'96'!P23,'97'!P23,'98'!P23,'142'!P23,'143'!P23,'90'!P23) -> 79.532 | R23: 2000-2100 | S23: =SUM(C62:C65) -> 38.815385 | T23: =SUM(D62:D65) -> 9.8615385 | U23: =SUM(E62:E65) -> 12.528846 | V23: =SUM(F62:F65) -> 33.5 | W23: =SUM(G62:G65) -> 2.7442308 | X23: =SUM(H62:H65) -> 4.3538462 | Y23: =SUM(I62:I65) -> 15.890385 | Z23: =SUM(J62:J65) -> 10.817308 | ... AF23: =SUM(P62:P65) -> 259.3
B24: 10.30 - 10.45 | C24: =AVERAGE('78'!C24,'79'!C24,'80'!C24,'81'!C24,'82'!C24,'83'!C24,'84A'!C24,'84'!C24,'85'!C24,'86'!C24,'87'!C24,'88'!C24,'89'!C24,'91'!C24,'92'!C24,'93'!C24,'94'!C24,'94A'!C24,'95'!C24,'96'!C24,'97'!C24,'98'!C24,'142'!C24,'143'!C24,'90'!C24,'93A'!C24) -> 8.7549451 | D24: =AVERAGE('78'!D24,'79'!D24,'80'!D24,'81'!D24,'82'!D24,'83'!D24,'84A'!D24,'84'!D24,'85'!D24,'86'!D24,'87'!D24,'88'!D24,'89'!D24,'91'!D24,'92'!D24,'93'!D24,'94'!D24,'94A'!D24,'95'!D24,'96'!D24,'97'!D24,'98'!D24,'142'!D24,'143'!D24,'90'!D24,'93A'!D24) -> 2.8972527 | E24: =AVERAGE('78'!E24,'79'!E24,'80'!E24,'81'!E24,'82'!E24,'83'!E24,'84A'!E24,'84'!E24,'85'!E24,'86'!E24,'87'!E24,'88'!E24,'89'!E24,'91'!E24,'92'!E24,'93'!E24,'94'!E24,'94A'!E24,'95'!E24,'96'!E24,'97'!E24,'98'!E24,'142'!E24,'143'!E24,'90'!E24,'93A'!E24) -> 4.343956 | F24: =AVERAGE('78'!F24,'79'!F24,'80'!F24,'81'!F24,'82'!F24,'83'!F24,'84A'!F24,'84'!F24,'85'!F24,'86'!F24,'87'!F24,'88'!F24,'89'!F24,'91'!F24,'92'!F24,'93'!F24,'94'!F24,'94A'!F24,'95'!F24,'96'!F24,'97'!F24,'98'!F24,'142'!F24,'143'!F24,'90'!F24,'93A'!F24) -> 12.235714 | G24: =AVERAGE('78'!G24,'79'!G24,'80'!G24,'81'!G24,'82'!G24,'83'!G24,'84A'!G24,'84'!G24,'85'!G24,'86'!G24,'87'!G24,'88'!G24,'89'!G24,'91'!G24,'92'!G24,'93'!G24,'94'!G24,'94A'!G24,'95'!G24,'96'!G24,'97'!G24,'98'!G24,'142'!G24,'143'!G24,'90'!G24,'93A'!G24) -> 0.39835165 | H24: =AVERAGE('78'!H24,'79'!H24,'80'!H24,'81'!H24,'82'!H24,'83'!H24,'84A'!H24,'84'!H24,'85'!H24,'86'!H24,'87'!H24,'88'!H24,'89'!H24,'91'!H24,'92'!H24,'93'!H24,'94'!H24,'94A'!H24,'95'!H24,'96'!H24,'97'!H24,'98'!H24,'142'!H24,'143'!H24,'90'!H24,'93A'!H24) -> 0.43681319 | I24: =AVERAGE('78'!I24,'79'!I24,'80'!I24,'81'!I24,'82'!I24,'83'!I24,'84A'!I24,'84'!I24,'85'!I24,'86'!I24,'87'!I24,'88'!I24,'89'!I24,'91'!I24,'92'!I24,'93'!I24,'94'!I24,'94A'!I24,'95'!I24,'96'!I24,'97'!I24,'98'!I24,'142'!I24,'143'!I24,'90'!I24,'93A'!I24) -> 3.3263736 | J24: =AVERAGE('78'!J24,'79'!J24,'80'!J24,'81'!J24,'82'!J24,'83'!J24,'84A'!J24,'84'!J24,'85'!J24,'86'!J24,'87'!J24,'88'!J24,'89'!J24,'91'!J24,'92'!J24,'93'!J24,'94'!J24,'94A'!J24,'95'!J24,'96'!J24,'97'!J24,'98'!J24,'142'!J24,'143'!J24,'90'!J24,'93A'!J24) -> 1.9818681 | ... N24: =AVERAGE('78'!N24,'79'!N24,'80'!N24,'81'!N24,'82'!N24,'83'!N24,'84A'!N24,'84'!N24,'85'!N24,'86'!N24,'87'!N24,'88'!N24,'89'!N24,'91'!N24,'92'!N24,'93'!N24,'94'!N24,'94A'!N24,'95'!N24,'96'!N24,'97'!N24,'98'!N24,'142'!N24,'143'!N24,'90'!N24,'93A'!N24) -> 0.054395604 | O24: =AVERAGE('78'!O24,'79'!O24,'80'!O24,'81'!O24,'82'!O24,'83'!O24,'84A'!O24,'84'!O24,'85'!O24,'86'!O24,'87'!O24,'88'!O24,'89'!O24,'91'!O24,'92'!O24,'93'!O24,'94'!O24,'94A'!O24,'95'!O24,'96'!O24,'97'!O24,'98'!O24,'142'!O24,'143'!O24,'90'!O24) -> 34.782857 | P24: =AVERAGE('78'!P24,'79'!P24,'80'!P24,'81'!P24,'82'!P24,'83'!P24,'84A'!P24,'84'!P24,'85'!P24,'86'!P24,'87'!P24,'88'!P24,'89'!P24,'91'!P24,'92'!P24,'93'!P24,'94'!P24,'94A'!P24,'95'!P24,'96'!P24,'97'!P24,'98'!P24,'142'!P24,'143'!P24,'90'!P24) -> 79.617143 | R24: 2100-2200 | S24: =SUM(C66:C69) -> 28.765385 | T24: =SUM(D66:D69) -> 7.3576923 | U24: =SUM(E66:E69) -> 10.769231 | V24: =SUM(F66:F69) -> 25.569231 | W24: =SUM(G66:G69) -> 2.2615385 | X24: =SUM(H66:H69) -> 3.6557692 | Y24: =SUM(I66:I69) -> 12.107692 | Z24: =SUM(J66:J69) -> 9.7057692 | ... AF24: =SUM(P66:P69) -> 192.92
B25: 10.45 - 11.00 | C25: =AVERAGE('78'!C25,'79'!C25,'80'!C25,'81'!C25,'82'!C25,'83'!C25,'84A'!C25,'84'!C25,'85'!C25,'86'!C25,'87'!C25,'88'!C25,'89'!C25,'91'!C25,'92'!C25,'93'!C25,'94'!C25,'94A'!C25,'95'!C25,'96'!C25,'97'!C25,'98'!C25,'142'!C25,'143'!C25,'90'!C25,'93A'!C25) -> 8.4054945 | D25: =AVERAGE('78'!D25,'79'!D25,'80'!D25,'81'!D25,'82'!D25,'83'!D25,'84A'!D25,'84'!D25,'85'!D25,'86'!D25,'87'!D25,'88'!D25,'89'!D25,'91'!D25,'92'!D25,'93'!D25,'94'!D25,'94A'!D25,'95'!D25,'96'!D25,'97'!D25,'98'!D25,'142'!D25,'143'!D25,'90'!D25,'93A'!D25) -> 2.9274725 | E25: =AVERAGE('78'!E25,'79'!E25,'80'!E25,'81'!E25,'82'!E25,'83'!E25,'84A'!E25,'84'!E25,'85'!E25,'86'!E25,'87'!E25,'88'!E25,'89'!E25,'91'!E25,'92'!E25,'93'!E25,'94'!E25,'94A'!E25,'95'!E25,'96'!E25,'97'!E25,'98'!E25,'142'!E25,'143'!E25,'90'!E25,'93A'!E25) -> 4.5461538 | F25: =AVERAGE('78'!F25,'79'!F25,'80'!F25,'81'!F25,'82'!F25,'83'!F25,'84A'!F25,'84'!F25,'85'!F25,'86'!F25,'87'!F25,'88'!F25,'89'!F25,'91'!F25,'92'!F25,'93'!F25,'94'!F25,'94A'!F25,'95'!F25,'96'!F25,'97'!F25,'98'!F25,'142'!F25,'143'!F25,'90'!F25,'93A'!F25) -> 12.332967 | G25: =AVERAGE('78'!G25,'79'!G25,'80'!G25,'81'!G25,'82'!G25,'83'!G25,'84A'!G25,'84'!G25,'85'!G25,'86'!G25,'87'!G25,'88'!G25,'89'!G25,'91'!G25,'92'!G25,'93'!G25,'94'!G25,'94A'!G25,'95'!G25,'96'!G25,'97'!G25,'98'!G25,'142'!G25,'143'!G25,'90'!G25,'93A'!G25) -> 0.3010989 | H25: =AVERAGE('78'!H25,'79'!H25,'80'!H25,'81'!H25,'82'!H25,'83'!H25,'84A'!H25,'84'!H25,'85'!H25,'86'!H25,'87'!H25,'88'!H25,'89'!H25,'91'!H25,'92'!H25,'93'!H25,'94'!H25,'94A'!H25,'95'!H25,'96'!H25,'97'!H25,'98'!H25,'142'!H25,'143'!H25,'90'!H25,'93A'!H25) -> 0.46373626 | I25: =AVERAGE('78'!I25,'79'!I25,'80'!I25,'81'!I25,'82'!I25,'83'!I25,'84A'!I25,'84'!I25,'85'!I25,'86'!I25,'87'!I25,'88'!I25,'89'!I25,'91'!I25,'92'!I25,'93'!I25,'94'!I25,'94A'!I25,'95'!I25,'96'!I25,'97'!I25,'98'!I25,'142'!I25,'143'!I25,'90'!I25,'93A'!I25) -> 3.217033 | J25: =AVERAGE('78'!J25,'79'!J25,'80'!J25,'81'!J25,'82'!J25,'83'!J25,'84A'!J25,'84'!J25,'85'!J25,'86'!J25,'87'!J25,'88'!J25,'89'!J25,'91'!J25,'92'!J25,'93'!J25,'94'!J25,'94A'!J25,'95'!J25,'96'!J25,'97'!J25,'98'!J25,'142'!J25,'143'!J25,'90'!J25,'93A'!J25) -> 1.9159341 | ... N25: =AVERAGE('78'!N25,'79'!N25,'80'!N25,'81'!N25,'82'!N25,'83'!N25,'84A'!N25,'84'!N25,'85'!N25,'86'!N25,'87'!N25,'88'!N25,'89'!N25,'91'!N25,'92'!N25,'93'!N25,'94'!N25,'94A'!N25,'95'!N25,'96'!N25,'97'!N25,'98'!N25,'142'!N25,'143'!N25,'90'!N25,'93A'!N25) -> 0.049450549 | O25: =AVERAGE('78'!O25,'79'!O25,'80'!O25,'81'!O25,'82'!O25,'83'!O25,'84A'!O25,'84'!O25,'85'!O25,'86'!O25,'87'!O25,'88'!O25,'89'!O25,'91'!O25,'92'!O25,'93'!O25,'94'!O25,'94A'!O25,'95'!O25,'96'!O25,'97'!O25,'98'!O25,'142'!O25,'143'!O25,'90'!O25) -> 34.28 | P25: =AVERAGE('78'!P25,'79'!P25,'80'!P25,'81'!P25,'82'!P25,'83'!P25,'84A'!P25,'84'!P25,'85'!P25,'86'!P25,'87'!P25,'88'!P25,'89'!P25,'91'!P25,'92'!P25,'93'!P25,'94'!P25,'94A'!P25,'95'!P25,'96'!P25,'97'!P25,'98'!P25,'142'!P25,'143'!P25,'90'!P25) -> 78.297143 | R25: 2200-2300 | S25: =SUM(C70:C73) -> 20.907692 | T25: =SUM(D70:D73) -> 5.3346154 | U25: =SUM(E70:E73) -> 6.6019231 | V25: =SUM(F70:F73) -> 16.826923 | W25: =SUM(G70:G73) -> 1.6269231 | X25: =SUM(H70:H73) -> 2.3942308 | Y25: =SUM(I70:I73) -> 10.913462 | Z25: =SUM(J70:J73) -> 10.105769 | ... AF25: =SUM(P70:P73) -> 133.94
B26: 11.00 - 11.15 | C26: =AVERAGE('78'!C26,'79'!C26,'80'!C26,'81'!C26,'82'!C26,'83'!C26,'84A'!C26,'84'!C26,'85'!C26,'86'!C26,'87'!C26,'88'!C26,'89'!C26,'91'!C26,'92'!C26,'93'!C26,'94'!C26,'94A'!C26,'95'!C26,'96'!C26,'97'!C26,'98'!C26,'142'!C26,'143'!C26,'90'!C26,'93A'!C26) -> 9.7692308 | D26: =AVERAGE('78'!D26,'79'!D26,'80'!D26,'81'!D26,'82'!D26,'83'!D26,'84A'!D26,'84'!D26,'85'!D26,'86'!D26,'87'!D26,'88'!D26,'89'!D26,'91'!D26,'92'!D26,'93'!D26,'94'!D26,'94A'!D26,'95'!D26,'96'!D26,'97'!D26,'98'!D26,'142'!D26,'143'!D26,'90'!D26,'93A'!D26) -> 2.9483516 | E26: =AVERAGE('78'!E26,'79'!E26,'80'!E26,'81'!E26,'82'!E26,'83'!E26,'84A'!E26,'84'!E26,'85'!E26,'86'!E26,'87'!E26,'88'!E26,'89'!E26,'91'!E26,'92'!E26,'93'!E26,'94'!E26,'94A'!E26,'95'!E26,'96'!E26,'97'!E26,'98'!E26,'142'!E26,'143'!E26,'90'!E26,'93A'!E26) -> 4.4291209 | F26: =AVERAGE('78'!F26,'79'!F26,'80'!F26,'81'!F26,'82'!F26,'83'!F26,'84A'!F26,'84'!F26,'85'!F26,'86'!F26,'87'!F26,'88'!F26,'89'!F26,'91'!F26,'92'!F26,'93'!F26,'94'!F26,'94A'!F26,'95'!F26,'96'!F26,'97'!F26,'98'!F26,'142'!F26,'143'!F26,'90'!F26,'93A'!F26) -> 12.169231 | G26: =AVERAGE('78'!G26,'79'!G26,'80'!G26,'81'!G26,'82'!G26,'83'!G26,'84A'!G26,'84'!G26,'85'!G26,'86'!G26,'87'!G26,'88'!G26,'89'!G26,'91'!G26,'92'!G26,'93'!G26,'94'!G26,'94A'!G26,'95'!G26,'96'!G26,'97'!G26,'98'!G26,'142'!G26,'143'!G26,'90'!G26,'93A'!G26) -> 0.43241758 | H26: =AVERAGE('78'!H26,'79'!H26,'80'!H26,'81'!H26,'82'!H26,'83'!H26,'84A'!H26,'84'!H26,'85'!H26,'86'!H26,'87'!H26,'88'!H26,'89'!H26,'91'!H26,'92'!H26,'93'!H26,'94'!H26,'94A'!H26,'95'!H26,'96'!H26,'97'!H26,'98'!H26,'142'!H26,'143'!H26,'90'!H26,'93A'!H26) -> 0.4032967 | I26: =AVERAGE('78'!I26,'79'!I26,'80'!I26,'81'!I26,'82'!I26,'83'!I26,'84A'!I26,'84'!I26,'85'!I26,'86'!I26,'87'!I26,'88'!I26,'89'!I26,'91'!I26,'92'!I26,'93'!I26,'94'!I26,'94A'!I26,'95'!I26,'96'!I26,'97'!I26,'98'!I26,'142'!I26,'143'!I26,'90'!I26,'93A'!I26) -> 3.4016484 | J26: =AVERAGE('78'!J26,'79'!J26,'80'!J26,'81'!J26,'82'!J26,'83'!J26,'84A'!J26,'84'!J26,'85'!J26,'86'!J26,'87'!J26,'88'!J26,'89'!J26,'91'!J26,'92'!J26,'93'!J26,'94'!J26,'94A'!J26,'95'!J26,'96'!J26,'97'!J26,'98'!J26,'142'!J26,'143'!J26,'90'!J26,'93A'!J26) -> 1.95 | ... N26: =AVERAGE('78'!N26,'79'!N26,'80'!N26,'81'!N26,'82'!N26,'83'!N26,'84A'!N26,'84'!N26,'85'!N26,'86'!N26,'87'!N26,'88'!N26,'89'!N26,'91'!N26,'92'!N26,'93'!N26,'94'!N26,'94A'!N26,'95'!N26,'96'!N26,'97'!N26,'98'!N26,'142'!N26,'143'!N26,'90'!N26,'93A'!N26) -> 0.054395604 | O26: =AVERAGE('78'!O26,'79'!O26,'80'!O26,'81'!O26,'82'!O26,'83'!O26,'84A'!O26,'84'!O26,'85'!O26,'86'!O26,'87'!O26,'88'!O26,'89'!O26,'91'!O26,'92'!O26,'93'!O26,'94'!O26,'94A'!O26,'95'!O26,'96'!O26,'97'!O26,'98'!O26,'142'!O26,'143'!O26,'90'!O26) -> 36.297143 | P26: =AVERAGE('78'!P26,'79'!P26,'80'!P26,'81'!P26,'82'!P26,'83'!P26,'84A'!P26,'84'!P26,'85'!P26,'86'!P26,'87'!P26,'88'!P26,'89'!P26,'91'!P26,'92'!P26,'93'!P26,'94'!P26,'94A'!P26,'95'!P26,'96'!P26,'97'!P26,'98'!P26,'142'!P26,'143'!P26,'90'!P26) -> 82.36 | R26: 2300-0000 | S26: =SUM(C74:C77) -> 14.355769 | T26: =SUM(D74:D77) -> 4.4942308 | U26: =SUM(E74:E77) -> 5.5538462 | V26: =SUM(F74:F77) -> 11.238462 | W26: =SUM(G74:G77) -> 1.8 | X26: =SUM(H74:H77) -> 2.6711538 | Y26: =SUM(I74:I77) -> 8.5923077 | Z26: =SUM(J74:J77) -> 8.2 | ... AF26: =SUM(P74:P77) -> 99.54
