Workbook

Sheet ALL
B1: Consultancy services for Preparation of Expressway Development Master Plan (EDMP) for Uganda
B2: MANUAL CLASSIFIED COUNT (MCC)
B3: ROAD NAME: | C3: ='[1]28.07 Entebbe-Kampala'!C3:G3 -> MCC - C1 - STN02 - KAMPALA-ENTEBBE ROAD
C5: Date | D5: AVERAGE WEEK | F5: Location | G5: ='[1]Avg Week Entebbe-Kampala'!G5:H5 -> Nyondo Club | J5: Surveyor | K5: ='[1]Avg Week Entebbe-Kampala'!K5:L5 -> Adong agnes/Ashanut
C6: Dir. From | D6: BOTH DIRECTIONS | F6: Dir. To | G6: BOTH DIRECTIONS | J6: Supervisor | K6: ='[1]Avg Week Entebbe-Kampala'!K6:L6 -> Emma
B8: Time / Veh Type | R8: SUMMARY TRAFFIC VOLUMES
C9: 1. Car | D9: 2. Station Wagon | E9: 3. Pickups | F9: 4. Minibus, matatu | G9: 5. Medium bus | H9: 6. Large Bus | I9: 7. Light Truck | J9: 8. Medium Truck | K9: 9. Heavy truck | L9: 10. Truck Trailer | M9: 11. Motor cycles | N9: 12. Tractors | O9: Total Excl M/Cycles | P9: Total All | R9: Time | S9: 1. Car | T9: 2. Station Wagon | U9: 3. Pickups | V9: 4. Minibus, matatu | W9: 5. Medium bus | X9: 6. Large Bus | Y9: 7. Light Truck | Z9: 8. Medium Truck | AA9: 9. Heavy truck | AB9: 10. Truck Trailer | AC9: 11. Motorcycles | AD9: 12. Tractors, Graders | AE9: Total Excl M/ Cycles | AF9: Total All
B10: 07.00 - 07.15 | C10: =AVERAGE('114'!C10,'115'!C10,'116'!C10,'117'!C10,'118'!C10,'119'!C10,'121'!C10,'122'!C10,'123'!C10,'124'!C10,'125'!C10,'126'!C10,'127'!C10,'128'!C10,'129'!C10,'130'!C10,'131'!C10,'138'!C10,'139'!C10,'140'!C10) -> 2.1010024 | D10: =AVERAGE('114'!D10,'115'!D10,'116'!D10,'117'!D10,'118'!D10,'119'!D10,'121'!D10,'122'!D10,'123'!D10,'124'!D10,'125'!D10,'126'!D10,'127'!D10,'128'!D10,'129'!D10,'130'!D10,'131'!D10,'138'!D10,'139'!D10,'140'!D10) -> 0.96535714 | E10: =AVERAGE('114'!E10,'115'!E10,'116'!E10,'117'!E10,'118'!E10,'119'!E10,'121'!E10,'122'!E10,'123'!E10,'124'!E10,'125'!E10,'126'!E10,'127'!E10,'128'!E10,'129'!E10,'130'!E10,'131'!E10,'138'!E10,'139'!E10,'140'!E10) -> 1.5863095 | F10: =AVERAGE('114'!F10,'115'!F10,'116'!F10,'117'!F10,'118'!F10,'119'!F10,'121'!F10,'122'!F10,'123'!F10,'124'!F10,'125'!F10,'126'!F10,'127'!F10,'128'!F10,'129'!F10,'130'!F10,'131'!F10,'138'!F10,'139'!F10,'140'!F10) -> 0.90095238 | G10: =AVERAGE('114'!G10,'115'!G10,'116'!G10,'117'!G10,'118'!G10,'119'!G10,'121'!G10,'122'!G10,'123'!G10,'124'!G10,'125'!G10,'126'!G10,'127'!G10,'128'!G10,'129'!G10,'130'!G10,'131'!G10,'138'!G10,'139'!G10,'140'!G10) -> 0.21428571 | H10: =AVERAGE('114'!H10,'115'!H10,'116'!H10,'117'!H10,'118'!H10,'119'!H10,'121'!H10,'122'!H10,'123'!H10,'124'!H10,'125'!H10,'126'!H10,'127'!H10,'128'!H10,'129'!H10,'130'!H10,'131'!H10,'138'!H10,'139'!H10,'140'!H10) -> 0.3560024 | I10: =AVERAGE('114'!I10,'115'!I10,'116'!I10,'117'!I10,'118'!I10,'119'!I10,'121'!I10,'122'!I10,'123'!I10,'124'!I10,'125'!I10,'126'!I10,'127'!I10,'128'!I10,'129'!I10,'130'!I10,'131'!I10,'138'!I10,'139'!I10,'140'!I10) -> 1.1928571 | J10: =AVERAGE('114'!J10,'115'!J10,'116'!J10,'117'!J10,'118'!J10,'119'!J10,'121'!J10,'122'!J10,'123'!J10,'124'!J10,'125'!J10,'126'!J10,'127'!J10,'128'!J10,'129'!J10,'130'!J10,'131'!J10,'138'!J10,'139'!J10,'140'!J10) -> 0.52171669 | ... P10: =AVERAGE('114'!P10,'115'!P10,'116'!P10,'117'!P10,'118'!P10,'119'!P10,'121'!P10,'122'!P10,'123'!P10,'124'!P10,'125'!P10,'126'!P10,'127'!P10,'128'!P10,'129'!P10,'130'!P10,'131'!P10,'138'!P10,'139'!P10,'140'!P10) -> 27.633007 | R10: 0700-0800 | S10: =SUM(C10:C13) -> 8.0695858 | T10: =SUM(D10:D13) -> 3.8291096 | U10: =SUM(E10:E13) -> 6.6530812 | V10: =SUM(F10:F13) -> 3.9122929 | W10: =SUM(G10:G13) -> 0.82404762 | X10: =SUM(H10:H13) -> 1.4706263 | Y10: =SUM(I10:I13) -> 4.6821549 | Z10: =SUM(J10:J13) -> 1.8712405 | ... AF10: =SUM(P10:P13) -> 116.65047
B11: 07.15 - 07.30 | C11: =AVERAGE('114'!C11,'115'!C11,'116'!C11,'117'!C11,'118'!C11,'119'!C11,'121'!C11,'122'!C11,'123'!C11,'124'!C11,'125'!C11,'126'!C11,'127'!C11,'128'!C11,'129'!C11,'130'!C11,'131'!C11,'138'!C11,'139'!C11,'140'!C11) -> 1.8767167 | D11: =AVERAGE('114'!D11,'115'!D11,'116'!D11,'117'!D11,'118'!D11,'119'!D11,'121'!D11,'122'!D11,'123'!D11,'124'!D11,'125'!D11,'126'!D11,'127'!D11,'128'!D11,'129'!D11,'130'!D11,'131'!D11,'138'!D11,'139'!D11,'140'!D11) -> 1.0414786 | E11: =AVERAGE('114'!E11,'115'!E11,'116'!E11,'117'!E11,'118'!E11,'119'!E11,'121'!E11,'122'!E11,'123'!E11,'124'!E11,'125'!E11,'126'!E11,'127'!E11,'128'!E11,'129'!E11,'130'!E11,'131'!E11,'138'!E11,'139'!E11,'140'!E11) -> 1.5115286 | F11: =AVERAGE('114'!F11,'115'!F11,'116'!F11,'117'!F11,'118'!F11,'119'!F11,'121'!F11,'122'!F11,'123'!F11,'124'!F11,'125'!F11,'126'!F11,'127'!F11,'128'!F11,'129'!F11,'130'!F11,'131'!F11,'138'!F11,'139'!F11,'140'!F11) -> 0.80119048 | G11: =AVERAGE('114'!G11,'115'!G11,'116'!G11,'117'!G11,'118'!G11,'119'!G11,'121'!G11,'122'!G11,'123'!G11,'124'!G11,'125'!G11,'126'!G11,'127'!G11,'128'!G11,'129'!G11,'130'!G11,'131'!G11,'138'!G11,'139'!G11,'140'!G11) -> 0.19285714 | H11: =AVERAGE('114'!H11,'115'!H11,'116'!H11,'117'!H11,'118'!H11,'119'!H11,'121'!H11,'122'!H11,'123'!H11,'124'!H11,'125'!H11,'126'!H11,'127'!H11,'128'!H11,'129'!H11,'130'!H11,'131'!H11,'138'!H11,'139'!H11,'140'!H11) -> 0.25261905 | I11: =AVERAGE('114'!I11,'115'!I11,'116'!I11,'117'!I11,'118'!I11,'119'!I11,'121'!I11,'122'!I11,'123'!I11,'124'!I11,'125'!I11,'126'!I11,'127'!I11,'128'!I11,'129'!I11,'130'!I11,'131'!I11,'138'!I11,'139'!I11,'140'!I11) -> 1.1726691 | J11: =AVERAGE('114'!J11,'115'!J11,'116'!J11,'117'!J11,'118'!J11,'119'!J11,'121'!J11,'122'!J11,'123'!J11,'124'!J11,'125'!J11,'126'!J11,'127'!J11,'128'!J11,'129'!J11,'130'!J11,'131'!J11,'138'!J11,'139'!J11,'140'!J11) -> 0.47 | ... P11: =AVERAGE('114'!P11,'115'!P11,'116'!P11,'117'!P11,'118'!P11,'119'!P11,'121'!P11,'122'!P11,'123'!P11,'124'!P11,'125'!P11,'126'!P11,'127'!P11,'128'!P11,'129'!P11,'130'!P11,'131'!P11,'138'!P11,'139'!P11,'140'!P11) -> 27.213107 | R11: 0800-0900 | S11: =SUM(C14:C17) -> 9.7805502 | T11: =SUM(D14:D17) -> 3.924917 | U11: =SUM(E14:E17) -> 7.7572459 | V11: =SUM(F14:F17) -> 4.927481 | W11: =SUM(G14:G17) -> 0.50285714 | X11: =SUM(H14:H17) -> 0.75748099 | Y11: =SUM(I14:I17) -> 5.0285454 | Z11: =SUM(J14:J17) -> 1.9064286 | ... AF11: =SUM(P14:P17) -> 132.80532
B12: 07.30 - 07.45 | C12: =AVERAGE('114'!C12,'115'!C12,'116'!C12,'117'!C12,'118'!C12,'119'!C12,'121'!C12,'122'!C12,'123'!C12,'124'!C12,'125'!C12,'126'!C12,'127'!C12,'128'!C12,'129'!C12,'130'!C12,'131'!C12,'138'!C12,'139'!C12,'140'!C12) -> 2.0512405 | D12: =AVERAGE('114'!D12,'115'!D12,'116'!D12,'117'!D12,'118'!D12,'119'!D12,'121'!D12,'122'!D12,'123'!D12,'124'!D12,'125'!D12,'126'!D12,'127'!D12,'128'!D12,'129'!D12,'130'!D12,'131'!D12,'138'!D12,'139'!D12,'140'!D12) -> 0.80593337 | E12: =AVERAGE('114'!E12,'115'!E12,'116'!E12,'117'!E12,'118'!E12,'119'!E12,'121'!E12,'122'!E12,'123'!E12,'124'!E12,'125'!E12,'126'!E12,'127'!E12,'128'!E12,'129'!E12,'130'!E12,'131'!E12,'138'!E12,'139'!E12,'140'!E12) -> 1.7127501 | F12: =AVERAGE('114'!F12,'115'!F12,'116'!F12,'117'!F12,'118'!F12,'119'!F12,'121'!F12,'122'!F12,'123'!F12,'124'!F12,'125'!F12,'126'!F12,'127'!F12,'128'!F12,'129'!F12,'130'!F12,'131'!F12,'138'!F12,'139'!F12,'140'!F12) -> 0.96028812 | G12: =AVERAGE('114'!G12,'115'!G12,'116'!G12,'117'!G12,'118'!G12,'119'!G12,'121'!G12,'122'!G12,'123'!G12,'124'!G12,'125'!G12,'126'!G12,'127'!G12,'128'!G12,'129'!G12,'130'!G12,'131'!G12,'138'!G12,'139'!G12,'140'!G12) -> 0.25714286 | H12: =AVERAGE('114'!H12,'115'!H12,'116'!H12,'117'!H12,'118'!H12,'119'!H12,'121'!H12,'122'!H12,'123'!H12,'124'!H12,'125'!H12,'126'!H12,'127'!H12,'128'!H12,'129'!H12,'130'!H12,'131'!H12,'138'!H12,'139'!H12,'140'!H12) -> 0.27629052 | I12: =AVERAGE('114'!I12,'115'!I12,'116'!I12,'117'!I12,'118'!I12,'119'!I12,'121'!I12,'122'!I12,'123'!I12,'124'!I12,'125'!I12,'126'!I12,'127'!I12,'128'!I12,'129'!I12,'130'!I12,'131'!I12,'138'!I12,'139'!I12,'140'!I12) -> 1.2602881 | J12: =AVERAGE('114'!J12,'115'!J12,'116'!J12,'117'!J12,'118'!J12,'119'!J12,'121'!J12,'122'!J12,'123'!J12,'124'!J12,'125'!J12,'126'!J12,'127'!J12,'128'!J12,'129'!J12,'130'!J12,'131'!J12,'138'!J12,'139'!J12,'140'!J12) -> 0.39142857 | ... P12: =AVERAGE('114'!P12,'115'!P12,'116'!P12,'117'!P12,'118'!P12,'119'!P12,'121'!P12,'122'!P12,'123'!P12,'124'!P12,'125'!P12,'126'!P12,'127'!P12,'128'!P12,'129'!P12,'130'!P12,'131'!P12,'138'!P12,'139'!P12,'140'!P12) -> 30.32941 | R12: 0900-1000 | S12: =SUM(C18:C21) -> 11.480862 | T12: =SUM(D18:D21) -> 4.6147669 | U12: =SUM(E18:E21) -> 8.8957553 | V12: =SUM(F18:F21) -> 5.094974 | W12: =SUM(G18:G21) -> 0.46338335 | X12: =SUM(H18:H21) -> 1.1919548 | Y12: =SUM(I18:I21) -> 5.2771409 | Z12: =SUM(J18:J21) -> 1.9680952 | ... AF12: =SUM(P18:P21) -> 137.43946
B13: 07.45 - 08.00 | C13: =AVERAGE('114'!C13,'115'!C13,'116'!C13,'117'!C13,'118'!C13,'119'!C13,'121'!C13,'122'!C13,'123'!C13,'124'!C13,'125'!C13,'126'!C13,'127'!C13,'128'!C13,'129'!C13,'130'!C13,'131'!C13,'138'!C13,'139'!C13,'140'!C13) -> 2.0406263 | D13: =AVERAGE('114'!D13,'115'!D13,'116'!D13,'117'!D13,'118'!D13,'119'!D13,'121'!D13,'122'!D13,'123'!D13,'124'!D13,'125'!D13,'126'!D13,'127'!D13,'128'!D13,'129'!D13,'130'!D13,'131'!D13,'138'!D13,'139'!D13,'140'!D13) -> 1.0163405 | E13: =AVERAGE('114'!E13,'115'!E13,'116'!E13,'117'!E13,'118'!E13,'119'!E13,'121'!E13,'122'!E13,'123'!E13,'124'!E13,'125'!E13,'126'!E13,'127'!E13,'128'!E13,'129'!E13,'130'!E13,'131'!E13,'138'!E13,'139'!E13,'140'!E13) -> 1.842493 | F13: =AVERAGE('114'!F13,'115'!F13,'116'!F13,'117'!F13,'118'!F13,'119'!F13,'121'!F13,'122'!F13,'123'!F13,'124'!F13,'125'!F13,'126'!F13,'127'!F13,'128'!F13,'129'!F13,'130'!F13,'131'!F13,'138'!F13,'139'!F13,'140'!F13) -> 1.2498619 | G13: =AVERAGE('114'!G13,'115'!G13,'116'!G13,'117'!G13,'118'!G13,'119'!G13,'121'!G13,'122'!G13,'123'!G13,'124'!G13,'125'!G13,'126'!G13,'127'!G13,'128'!G13,'129'!G13,'130'!G13,'131'!G13,'138'!G13,'139'!G13,'140'!G13) -> 0.1597619 | H13: =AVERAGE('114'!H13,'115'!H13,'116'!H13,'117'!H13,'118'!H13,'119'!H13,'121'!H13,'122'!H13,'123'!H13,'124'!H13,'125'!H13,'126'!H13,'127'!H13,'128'!H13,'129'!H13,'130'!H13,'131'!H13,'138'!H13,'139'!H13,'140'!H13) -> 0.58571429 | I13: =AVERAGE('114'!I13,'115'!I13,'116'!I13,'117'!I13,'118'!I13,'119'!I13,'121'!I13,'122'!I13,'123'!I13,'124'!I13,'125'!I13,'126'!I13,'127'!I13,'128'!I13,'129'!I13,'130'!I13,'131'!I13,'138'!I13,'139'!I13,'140'!I13) -> 1.0563405 | J13: =AVERAGE('114'!J13,'115'!J13,'116'!J13,'117'!J13,'118'!J13,'119'!J13,'121'!J13,'122'!J13,'123'!J13,'124'!J13,'125'!J13,'126'!J13,'127'!J13,'128'!J13,'129'!J13,'130'!J13,'131'!J13,'138'!J13,'139'!J13,'140'!J13) -> 0.48809524 | ... P13: =AVERAGE('114'!P13,'115'!P13,'116'!P13,'117'!P13,'118'!P13,'119'!P13,'121'!P13,'122'!P13,'123'!P13,'124'!P13,'125'!P13,'126'!P13,'127'!P13,'128'!P13,'129'!P13,'130'!P13,'131'!P13,'138'!P13,'139'!P13,'140'!P13) -> 31.474948 | R13: 1000-1100 | S13: =SUM(C22:C25) -> 11.834484 | T13: =SUM(D22:D25) -> 5.0984454 | U13: =SUM(E22:E25) -> 9.5139456 | V13: =SUM(F22:F25) -> 5.4041597 | W13: =SUM(G22:G25) -> 0.56547619 | X13: =SUM(H22:H25) -> 1.0346739 | Y13: =SUM(I22:I25) -> 5.3066026 | Z13: =SUM(J22:J25) -> 1.8597619 | ... AF13: =SUM(P22:P25) -> 138.84195
B14: 08.00 - 08.15 | C14: =AVERAGE('114'!C14,'115'!C14,'116'!C14,'117'!C14,'118'!C14,'119'!C14,'121'!C14,'122'!C14,'123'!C14,'124'!C14,'125'!C14,'126'!C14,'127'!C14,'128'!C14,'129'!C14,'130'!C14,'131'!C14,'138'!C14,'139'!C14,'140'!C14) -> 2.2820048 | D14: =AVERAGE('114'!D14,'115'!D14,'116'!D14,'117'!D14,'118'!D14,'119'!D14,'121'!D14,'122'!D14,'123'!D14,'124'!D14,'125'!D14,'126'!D14,'127'!D14,'128'!D14,'129'!D14,'130'!D14,'131'!D14,'138'!D14,'139'!D14,'140'!D14) -> 1.0067977 | E14: =AVERAGE('114'!E14,'115'!E14,'116'!E14,'117'!E14,'118'!E14,'119'!E14,'121'!E14,'122'!E14,'123'!E14,'124'!E14,'125'!E14,'126'!E14,'127'!E14,'128'!E14,'129'!E14,'130'!E14,'131'!E14,'138'!E14,'139'!E14,'140'!E14) -> 1.8970978 | F14: =AVERAGE('114'!F14,'115'!F14,'116'!F14,'117'!F14,'118'!F14,'119'!F14,'121'!F14,'122'!F14,'123'!F14,'124'!F14,'125'!F14,'126'!F14,'127'!F14,'128'!F14,'129'!F14,'130'!F14,'131'!F14,'138'!F14,'139'!F14,'140'!F14) -> 1.052619 | G14: =AVERAGE('114'!G14,'115'!G14,'116'!G14,'117'!G14,'118'!G14,'119'!G14,'121'!G14,'122'!G14,'123'!G14,'124'!G14,'125'!G14,'126'!G14,'127'!G14,'128'!G14,'129'!G14,'130'!G14,'131'!G14,'138'!G14,'139'!G14,'140'!G14) -> 0.071428571 | H14: =AVERAGE('114'!H14,'115'!H14,'116'!H14,'117'!H14,'118'!H14,'119'!H14,'121'!H14,'122'!H14,'123'!H14,'124'!H14,'125'!H14,'126'!H14,'127'!H14,'128'!H14,'129'!H14,'130'!H14,'131'!H14,'138'!H14,'139'!H14,'140'!H14) -> 0.22285714 | I14: =AVERAGE('114'!I14,'115'!I14,'116'!I14,'117'!I14,'118'!I14,'119'!I14,'121'!I14,'122'!I14,'123'!I14,'124'!I14,'125'!I14,'126'!I14,'127'!I14,'128'!I14,'129'!I14,'130'!I14,'131'!I14,'138'!I14,'139'!I14,'140'!I14) -> 1.22005 | J14: =AVERAGE('114'!J14,'115'!J14,'116'!J14,'117'!J14,'118'!J14,'119'!J14,'121'!J14,'122'!J14,'123'!J14,'124'!J14,'125'!J14,'126'!J14,'127'!J14,'128'!J14,'129'!J14,'130'!J14,'131'!J14,'138'!J14,'139'!J14,'140'!J14) -> 0.32547619 | ... P14: =AVERAGE('114'!P14,'115'!P14,'116'!P14,'117'!P14,'118'!P14,'119'!P14,'121'!P14,'122'!P14,'123'!P14,'124'!P14,'125'!P14,'126'!P14,'127'!P14,'128'!P14,'129'!P14,'130'!P14,'131'!P14,'138'!P14,'139'!P14,'140'!P14) -> 32.471665 | R14: 1100-1200 | S14: =SUM(C26:C29) -> 11.820574 | T14: =SUM(D26:D29) -> 4.724936 | U14: =SUM(E26:E29) -> 9.4578291 | V14: =SUM(F26:F29) -> 5.4216287 | W14: =SUM(G26:G29) -> 0.47380952 | X14: =SUM(H26:H29) -> 0.81557623 | Y14: =SUM(I26:I29) -> 5.5548479 | Z14: =SUM(J26:J29) -> 1.9535714 | ... AF14: =SUM(P26:P29) -> 134.36953
B15: 08.15 - 08.30 | C15: =AVERAGE('114'!C15,'115'!C15,'116'!C15,'117'!C15,'118'!C15,'119'!C15,'121'!C15,'122'!C15,'123'!C15,'124'!C15,'125'!C15,'126'!C15,'127'!C15,'128'!C15,'129'!C15,'130'!C15,'131'!C15,'138'!C15,'139'!C15,'140'!C15) -> 2.4421048 | D15: =AVERAGE('114'!D15,'115'!D15,'116'!D15,'117'!D15,'118'!D15,'119'!D15,'121'!D15,'122'!D15,'123'!D15,'124'!D15,'125'!D15,'126'!D15,'127'!D15,'128'!D15,'129'!D15,'130'!D15,'131'!D15,'138'!D15,'139'!D15,'140'!D15) -> 0.92640956 | E15: =AVERAGE('114'!E15,'115'!E15,'116'!E15,'117'!E15,'118'!E15,'119'!E15,'121'!E15,'122'!E15,'123'!E15,'124'!E15,'125'!E15,'126'!E15,'127'!E15,'128'!E15,'129'!E15,'130'!E15,'131'!E15,'138'!E15,'139'!E15,'140'!E15) -> 1.5393667 | F15: =AVERAGE('114'!F15,'115'!F15,'116'!F15,'117'!F15,'118'!F15,'119'!F15,'121'!F15,'122'!F15,'123'!F15,'124'!F15,'125'!F15,'126'!F15,'127'!F15,'128'!F15,'129'!F15,'130'!F15,'131'!F15,'138'!F15,'139'!F15,'140'!F15) -> 1.1383834 | G15: =AVERAGE('114'!G15,'115'!G15,'116'!G15,'117'!G15,'118'!G15,'119'!G15,'121'!G15,'122'!G15,'123'!G15,'124'!G15,'125'!G15,'126'!G15,'127'!G15,'128'!G15,'129'!G15,'130'!G15,'131'!G15,'138'!G15,'139'!G15,'140'!G15) -> 0.10119048 | H15: =AVERAGE('114'!H15,'115'!H15,'116'!H15,'117'!H15,'118'!H15,'119'!H15,'121'!H15,'122'!H15,'123'!H15,'124'!H15,'125'!H15,'126'!H15,'127'!H15,'128'!H15,'129'!H15,'130'!H15,'131'!H15,'138'!H15,'139'!H15,'140'!H15) -> 0.15 | I15: =AVERAGE('114'!I15,'115'!I15,'116'!I15,'117'!I15,'118'!I15,'119'!I15,'121'!I15,'122'!I15,'123'!I15,'124'!I15,'125'!I15,'126'!I15,'127'!I15,'128'!I15,'129'!I15,'130'!I15,'131'!I15,'138'!I15,'139'!I15,'140'!I15) -> 1.2229072 | J15: =AVERAGE('114'!J15,'115'!J15,'116'!J15,'117'!J15,'118'!J15,'119'!J15,'121'!J15,'122'!J15,'123'!J15,'124'!J15,'125'!J15,'126'!J15,'127'!J15,'128'!J15,'129'!J15,'130'!J15,'131'!J15,'138'!J15,'139'!J15,'140'!J15) -> 0.47142857 | ... P15: =AVERAGE('114'!P15,'115'!P15,'116'!P15,'117'!P15,'118'!P15,'119'!P15,'121'!P15,'122'!P15,'123'!P15,'124'!P15,'125'!P15,'126'!P15,'127'!P15,'128'!P15,'129'!P15,'130'!P15,'131'!P15,'138'!P15,'139'!P15,'140'!P15) -> 32.405362 | R15: 1200-1300 | S15: =SUM(C30:C33) -> 12.178093 | T15: =SUM(D30:D33) -> 4.2388335 | U15: =SUM(E30:E33) -> 9.1176671 | V15: =SUM(F30:F33) -> 5.7134834 | W15: =SUM(G30:G33) -> 0.36195478 | X15: =SUM(H30:H33) -> 0.88581433 | Y15: =SUM(I30:I33) -> 5.8285574 | Z15: =SUM(J30:J33) -> 1.9762905 | ... AF15: =SUM(P30:P33) -> 133.60792
B16: 08.30 - 08.45 | C16: =AVERAGE('114'!C16,'115'!C16,'116'!C16,'117'!C16,'118'!C16,'119'!C16,'121'!C16,'122'!C16,'123'!C16,'124'!C16,'125'!C16,'126'!C16,'127'!C16,'128'!C16,'129'!C16,'130'!C16,'131'!C16,'138'!C16,'139'!C16,'140'!C16) -> 2.6346238 | D16: =AVERAGE('114'!D16,'115'!D16,'116'!D16,'117'!D16,'118'!D16,'119'!D16,'121'!D16,'122'!D16,'123'!D16,'124'!D16,'125'!D16,'126'!D16,'127'!D16,'128'!D16,'129'!D16,'130'!D16,'131'!D16,'138'!D16,'139'!D16,'140'!D16) -> 0.89741196 | E16: =AVERAGE('114'!E16,'115'!E16,'116'!E16,'117'!E16,'118'!E16,'119'!E16,'121'!E16,'122'!E16,'123'!E16,'124'!E16,'125'!E16,'126'!E16,'127'!E16,'128'!E16,'129'!E16,'130'!E16,'131'!E16,'138'!E16,'139'!E16,'140'!E16) -> 2.0592787 | F16: =AVERAGE('114'!F16,'115'!F16,'116'!F16,'117'!F16,'118'!F16,'119'!F16,'121'!F16,'122'!F16,'123'!F16,'124'!F16,'125'!F16,'126'!F16,'127'!F16,'128'!F16,'129'!F16,'130'!F16,'131'!F16,'138'!F16,'139'!F16,'140'!F16) -> 1.2769548 | G16: =AVERAGE('114'!G16,'115'!G16,'116'!G16,'117'!G16,'118'!G16,'119'!G16,'121'!G16,'122'!G16,'123'!G16,'124'!G16,'125'!G16,'126'!G16,'127'!G16,'128'!G16,'129'!G16,'130'!G16,'131'!G16,'138'!G16,'139'!G16,'140'!G16) -> 0.13142857 | H16: =AVERAGE('114'!H16,'115'!H16,'116'!H16,'117'!H16,'118'!H16,'119'!H16,'121'!H16,'122'!H16,'123'!H16,'124'!H16,'125'!H16,'126'!H16,'127'!H16,'128'!H16,'129'!H16,'130'!H16,'131'!H16,'138'!H16,'139'!H16,'140'!H16) -> 0.20486194 | I16: =AVERAGE('114'!I16,'115'!I16,'116'!I16,'117'!I16,'118'!I16,'119'!I16,'121'!I16,'122'!I16,'123'!I16,'124'!I16,'125'!I16,'126'!I16,'127'!I16,'128'!I16,'129'!I16,'130'!I16,'131'!I16,'138'!I16,'139'!I16,'140'!I16) -> 1.2612525 | J16: =AVERAGE('114'!J16,'115'!J16,'116'!J16,'117'!J16,'118'!J16,'119'!J16,'121'!J16,'122'!J16,'123'!J16,'124'!J16,'125'!J16,'126'!J16,'127'!J16,'128'!J16,'129'!J16,'130'!J16,'131'!J16,'138'!J16,'139'!J16,'140'!J16) -> 0.44571429 | ... P16: =AVERAGE('114'!P16,'115'!P16,'116'!P16,'117'!P16,'118'!P16,'119'!P16,'121'!P16,'122'!P16,'123'!P16,'124'!P16,'125'!P16,'126'!P16,'127'!P16,'128'!P16,'129'!P16,'130'!P16,'131'!P16,'138'!P16,'139'!P16,'140'!P16) -> 33.797529 | R16: 1300-1400 | S16: =SUM(C34:C37) -> 11.339272 | T16: =SUM(D34:D37) -> 4.7828621 | U16: =SUM(E34:E37) -> 9.4707553 | V16: =SUM(F34:F37) -> 5.4839596 | W16: =SUM(G34:G37) -> 0.43333333 | X16: =SUM(H34:H37) -> 2.2589096 | Y16: =SUM(I34:I37) -> 5.7516146 | Z16: =SUM(J34:J37) -> 1.9648119 | ... AF16: =SUM(P34:P37) -> 130.59147
B17: 08.45 - 9.00 | C17: =AVERAGE('114'!C17,'115'!C17,'116'!C17,'117'!C17,'118'!C17,'119'!C17,'121'!C17,'122'!C17,'123'!C17,'124'!C17,'125'!C17,'126'!C17,'127'!C17,'128'!C17,'129'!C17,'130'!C17,'131'!C17,'138'!C17,'139'!C17,'140'!C17) -> 2.4218167 | D17: =AVERAGE('114'!D17,'115'!D17,'116'!D17,'117'!D17,'118'!D17,'119'!D17,'121'!D17,'122'!D17,'123'!D17,'124'!D17,'125'!D17,'126'!D17,'127'!D17,'128'!D17,'129'!D17,'130'!D17,'131'!D17,'138'!D17,'139'!D17,'140'!D17) -> 1.0942977 | E17: =AVERAGE('114'!E17,'115'!E17,'116'!E17,'117'!E17,'118'!E17,'119'!E17,'121'!E17,'122'!E17,'123'!E17,'124'!E17,'125'!E17,'126'!E17,'127'!E17,'128'!E17,'129'!E17,'130'!E17,'131'!E17,'138'!E17,'139'!E17,'140'!E17) -> 2.2615026 | F17: =AVERAGE('114'!F17,'115'!F17,'116'!F17,'117'!F17,'118'!F17,'119'!F17,'121'!F17,'122'!F17,'123'!F17,'124'!F17,'125'!F17,'126'!F17,'127'!F17,'128'!F17,'129'!F17,'130'!F17,'131'!F17,'138'!F17,'139'!F17,'140'!F17) -> 1.4595238 | G17: =AVERAGE('114'!G17,'115'!G17,'116'!G17,'117'!G17,'118'!G17,'119'!G17,'121'!G17,'122'!G17,'123'!G17,'124'!G17,'125'!G17,'126'!G17,'127'!G17,'128'!G17,'129'!G17,'130'!G17,'131'!G17,'138'!G17,'139'!G17,'140'!G17) -> 0.19880952 | H17: =AVERAGE('114'!H17,'115'!H17,'116'!H17,'117'!H17,'118'!H17,'119'!H17,'121'!H17,'122'!H17,'123'!H17,'124'!H17,'125'!H17,'126'!H17,'127'!H17,'128'!H17,'129'!H17,'130'!H17,'131'!H17,'138'!H17,'139'!H17,'140'!H17) -> 0.1797619 | I17: =AVERAGE('114'!I17,'115'!I17,'116'!I17,'117'!I17,'118'!I17,'119'!I17,'121'!I17,'122'!I17,'123'!I17,'124'!I17,'125'!I17,'126'!I17,'127'!I17,'128'!I17,'129'!I17,'130'!I17,'131'!I17,'138'!I17,'139'!I17,'140'!I17) -> 1.3243357 | J17: =AVERAGE('114'!J17,'115'!J17,'116'!J17,'117'!J17,'118'!J17,'119'!J17,'121'!J17,'122'!J17,'123'!J17,'124'!J17,'125'!J17,'126'!J17,'127'!J17,'128'!J17,'129'!J17,'130'!J17,'131'!J17,'138'!J17,'139'!J17,'140'!J17) -> 0.66380952 | ... P17: =AVERAGE('114'!P17,'115'!P17,'116'!P17,'117'!P17,'118'!P17,'119'!P17,'121'!P17,'122'!P17,'123'!P17,'124'!P17,'125'!P17,'126'!P17,'127'!P17,'128'!P17,'129'!P17,'130'!P17,'131'!P17,'138'!P17,'139'!P17,'140'!P17) -> 34.130762 | R17: 1400-1500 | S17: =SUM(C38:C41) -> 11.483758 | T17: =SUM(D38:D41) -> 4.4154502 | U17: =SUM(E38:E41) -> 9.1452361 | V17: =SUM(F38:F41) -> 5.3683453 | W17: =SUM(G38:G41) -> 0.40238095 | X17: =SUM(H38:H41) -> 2.4179572 | Y17: =SUM(I38:I41) -> 6.1496098 | Z17: =SUM(J38:J41) -> 1.8441977 | ... AF17: =SUM(P38:P41) -> 126.30563
B18: 09.00 - 09.15 | C18: =AVERAGE('114'!C18,'115'!C18,'116'!C18,'117'!C18,'118'!C18,'119'!C18,'121'!C18,'122'!C18,'123'!C18,'124'!C18,'125'!C18,'126'!C18,'127'!C18,'128'!C18,'129'!C18,'130'!C18,'131'!C18,'138'!C18,'139'!C18,'140'!C18) -> 2.900024 | D18: =AVERAGE('114'!D18,'115'!D18,'116'!D18,'117'!D18,'118'!D18,'119'!D18,'121'!D18,'122'!D18,'123'!D18,'124'!D18,'125'!D18,'126'!D18,'127'!D18,'128'!D18,'129'!D18,'130'!D18,'131'!D18,'138'!D18,'139'!D18,'140'!D18) -> 0.9840096 | E18: =AVERAGE('114'!E18,'115'!E18,'116'!E18,'117'!E18,'118'!E18,'119'!E18,'121'!E18,'122'!E18,'123'!E18,'124'!E18,'125'!E18,'126'!E18,'127'!E18,'128'!E18,'129'!E18,'130'!E18,'131'!E18,'138'!E18,'139'!E18,'140'!E18) -> 2.0783073 | F18: =AVERAGE('114'!F18,'115'!F18,'116'!F18,'117'!F18,'118'!F18,'119'!F18,'121'!F18,'122'!F18,'123'!F18,'124'!F18,'125'!F18,'126'!F18,'127'!F18,'128'!F18,'129'!F18,'130'!F18,'131'!F18,'138'!F18,'139'!F18,'140'!F18) -> 1.1998119 | G18: =AVERAGE('114'!G18,'115'!G18,'116'!G18,'117'!G18,'118'!G18,'119'!G18,'121'!G18,'122'!G18,'123'!G18,'124'!G18,'125'!G18,'126'!G18,'127'!G18,'128'!G18,'129'!G18,'130'!G18,'131'!G18,'138'!G18,'139'!G18,'140'!G18) -> 0.085714286 | H18: =AVERAGE('114'!H18,'115'!H18,'116'!H18,'117'!H18,'118'!H18,'119'!H18,'121'!H18,'122'!H18,'123'!H18,'124'!H18,'125'!H18,'126'!H18,'127'!H18,'128'!H18,'129'!H18,'130'!H18,'131'!H18,'138'!H18,'139'!H18,'140'!H18) -> 0.27857143 | I18: =AVERAGE('114'!I18,'115'!I18,'116'!I18,'117'!I18,'118'!I18,'119'!I18,'121'!I18,'122'!I18,'123'!I18,'124'!I18,'125'!I18,'126'!I18,'127'!I18,'128'!I18,'129'!I18,'130'!I18,'131'!I18,'138'!I18,'139'!I18,'140'!I18) -> 1.3037715 | J18: =AVERAGE('114'!J18,'115'!J18,'116'!J18,'117'!J18,'118'!J18,'119'!J18,'121'!J18,'122'!J18,'123'!J18,'124'!J18,'125'!J18,'126'!J18,'127'!J18,'128'!J18,'129'!J18,'130'!J18,'131'!J18,'138'!J18,'139'!J18,'140'!J18) -> 0.41714286 | ... P18: =AVERAGE('114'!P18,'115'!P18,'116'!P18,'117'!P18,'118'!P18,'119'!P18,'121'!P18,'122'!P18,'123'!P18,'124'!P18,'125'!P18,'126'!P18,'127'!P18,'128'!P18,'129'!P18,'130'!P18,'131'!P18,'138'!P18,'139'!P18,'140'!P18) -> 33.074734 | R18: 1500-1600 | S18: =SUM(C42:C45) -> 11.987943 | T18: =SUM(D42:D45) -> 4.9814526 | U18: =SUM(E42:E45) -> 9.4946218 | V18: =SUM(F42:F45) -> 5.3640596 | W18: =SUM(G42:G45) -> 0.36214286 | X18: =SUM(H42:H45) -> 2.0820048 | Y18: =SUM(I42:I45) -> 6.172467 | Z18: =SUM(J42:J45) -> 1.7810524 | ... AF18: =SUM(P42:P45) -> 132.05463
B19: 09.15 - 09.30 | C19: =AVERAGE('114'!C19,'115'!C19,'116'!C19,'117'!C19,'118'!C19,'119'!C19,'121'!C19,'122'!C19,'123'!C19,'124'!C19,'125'!C19,'126'!C19,'127'!C19,'128'!C19,'129'!C19,'130'!C19,'131'!C19,'138'!C19,'139'!C19,'140'!C19) -> 2.832393 | D19: =AVERAGE('114'!D19,'115'!D19,'116'!D19,'117'!D19,'118'!D19,'119'!D19,'121'!D19,'122'!D19,'123'!D19,'124'!D19,'125'!D19,'126'!D19,'127'!D19,'128'!D19,'129'!D19,'130'!D19,'131'!D19,'138'!D19,'139'!D19,'140'!D19) -> 1.0382643 | E19: =AVERAGE('114'!E19,'115'!E19,'116'!E19,'117'!E19,'118'!E19,'119'!E19,'121'!E19,'122'!E19,'123'!E19,'124'!E19,'125'!E19,'126'!E19,'127'!E19,'128'!E19,'129'!E19,'130'!E19,'131'!E19,'138'!E19,'139'!E19,'140'!E19) -> 2.0309834 | F19: =AVERAGE('114'!F19,'115'!F19,'116'!F19,'117'!F19,'118'!F19,'119'!F19,'121'!F19,'122'!F19,'123'!F19,'124'!F19,'125'!F19,'126'!F19,'127'!F19,'128'!F19,'129'!F19,'130'!F19,'131'!F19,'138'!F19,'139'!F19,'140'!F19) -> 1.4662025 | G19: =AVERAGE('114'!G19,'115'!G19,'116'!G19,'117'!G19,'118'!G19,'119'!G19,'121'!G19,'122'!G19,'123'!G19,'124'!G19,'125'!G19,'126'!G19,'127'!G19,'128'!G19,'129'!G19,'130'!G19,'131'!G19,'138'!G19,'139'!G19,'140'!G19) -> 0.12857143 | H19: =AVERAGE('114'!H19,'115'!H19,'116'!H19,'117'!H19,'118'!H19,'119'!H19,'121'!H19,'122'!H19,'123'!H19,'124'!H19,'125'!H19,'126'!H19,'127'!H19,'128'!H19,'129'!H19,'130'!H19,'131'!H19,'138'!H19,'139'!H19,'140'!H19) -> 0.40119048 | I19: =AVERAGE('114'!I19,'115'!I19,'116'!I19,'117'!I19,'118'!I19,'119'!I19,'121'!I19,'122'!I19,'123'!I19,'124'!I19,'125'!I19,'126'!I19,'127'!I19,'128'!I19,'129'!I19,'130'!I19,'131'!I19,'138'!I19,'139'!I19,'140'!I19) -> 1.3263906 | J19: =AVERAGE('114'!J19,'115'!J19,'116'!J19,'117'!J19,'118'!J19,'119'!J19,'121'!J19,'122'!J19,'123'!J19,'124'!J19,'125'!J19,'126'!J19,'127'!J19,'128'!J19,'129'!J19,'130'!J19,'131'!J19,'138'!J19,'139'!J19,'140'!J19) -> 0.58547619 | ... P19: =AVERAGE('114'!P19,'115'!P19,'116'!P19,'117'!P19,'118'!P19,'119'!P19,'121'!P19,'122'!P19,'123'!P19,'124'!P19,'125'!P19,'126'!P19,'127'!P19,'128'!P19,'129'!P19,'130'!P19,'131'!P19,'138'!P19,'139'!P19,'140'!P19) -> 33.833093 | R19: 1600-1700 | S19: =SUM(C46:C49) -> 13.39531 | T19: =SUM(D46:D49) -> 4.887612 | U19: =SUM(E46:E49) -> 9.8146789 | V19: =SUM(F46:F49) -> 6.1347739 | W19: =SUM(G46:G49) -> 0.65833333 | X19: =SUM(H46:H49) -> 2.6501501 | Y19: =SUM(I46:I49) -> 6.2905362 | Z19: =SUM(J46:J49) -> 2.2394358 | ... AF19: =SUM(P46:P49) -> 140.83629
B20: 09.30 - 09.45 | C20: =AVERAGE('114'!C20,'115'!C20,'116'!C20,'117'!C20,'118'!C20,'119'!C20,'121'!C20,'122'!C20,'123'!C20,'124'!C20,'125'!C20,'126'!C20,'127'!C20,'128'!C20,'129'!C20,'130'!C20,'131'!C20,'138'!C20,'139'!C20,'140'!C20) -> 2.7812025 | D20: =AVERAGE('114'!D20,'115'!D20,'116'!D20,'117'!D20,'118'!D20,'119'!D20,'121'!D20,'122'!D20,'123'!D20,'124'!D20,'125'!D20,'126'!D20,'127'!D20,'128'!D20,'129'!D20,'130'!D20,'131'!D20,'138'!D20,'139'!D20,'140'!D20) -> 1.4088215 | E20: =AVERAGE('114'!E20,'115'!E20,'116'!E20,'117'!E20,'118'!E20,'119'!E20,'121'!E20,'122'!E20,'123'!E20,'124'!E20,'125'!E20,'126'!E20,'127'!E20,'128'!E20,'129'!E20,'130'!E20,'131'!E20,'138'!E20,'139'!E20,'140'!E20) -> 2.457405 | F20: =AVERAGE('114'!F20,'115'!F20,'116'!F20,'117'!F20,'118'!F20,'119'!F20,'121'!F20,'122'!F20,'123'!F20,'124'!F20,'125'!F20,'126'!F20,'127'!F20,'128'!F20,'129'!F20,'130'!F20,'131'!F20,'138'!F20,'139'!F20,'140'!F20) -> 1.3584834 | G20: =AVERAGE('114'!G20,'115'!G20,'116'!G20,'117'!G20,'118'!G20,'119'!G20,'121'!G20,'122'!G20,'123'!G20,'124'!G20,'125'!G20,'126'!G20,'127'!G20,'128'!G20,'129'!G20,'130'!G20,'131'!G20,'138'!G20,'139'!G20,'140'!G20) -> 0.12171669 | H20: =AVERAGE('114'!H20,'115'!H20,'116'!H20,'117'!H20,'118'!H20,'119'!H20,'121'!H20,'122'!H20,'123'!H20,'124'!H20,'125'!H20,'126'!H20,'127'!H20,'128'!H20,'129'!H20,'130'!H20,'131'!H20,'138'!H20,'139'!H20,'140'!H20) -> 0.28695478 | I20: =AVERAGE('114'!I20,'115'!I20,'116'!I20,'117'!I20,'118'!I20,'119'!I20,'121'!I20,'122'!I20,'123'!I20,'124'!I20,'125'!I20,'126'!I20,'127'!I20,'128'!I20,'129'!I20,'130'!I20,'131'!I20,'138'!I20,'139'!I20,'140'!I20) -> 1.4372549 | J20: =AVERAGE('114'!J20,'115'!J20,'116'!J20,'117'!J20,'118'!J20,'119'!J20,'121'!J20,'122'!J20,'123'!J20,'124'!J20,'125'!J20,'126'!J20,'127'!J20,'128'!J20,'129'!J20,'130'!J20,'131'!J20,'138'!J20,'139'!J20,'140'!J20) -> 0.48880952 | ... P20: =AVERAGE('114'!P20,'115'!P20,'116'!P20,'117'!P20,'118'!P20,'119'!P20,'121'!P20,'122'!P20,'123'!P20,'124'!P20,'125'!P20,'126'!P20,'127'!P20,'128'!P20,'129'!P20,'130'!P20,'131'!P20,'138'!P20,'139'!P20,'140'!P20) -> 35.888555 | R20: 1700-1800 | S20: =SUM(C50:C53) -> 14.815486 | T20: =SUM(D50:D53) -> 5.5205002 | U20: =SUM(E50:E53) -> 11.007053 | V20: =SUM(F50:F53) -> 6.0244478 | W20: =SUM(G50:G53) -> 0.8720048 | X20: =SUM(H50:H53) -> 1.3271549 | Y20: =SUM(I50:I53) -> 6.1540336 | Z20: =SUM(J50:J53) -> 2.8066667 | ... AF20: =SUM(P50:P53) -> 153.19289
B21: 09.45 - 10.00 | C21: =AVERAGE('114'!C21,'115'!C21,'116'!C21,'117'!C21,'118'!C21,'119'!C21,'121'!C21,'122'!C21,'123'!C21,'124'!C21,'125'!C21,'126'!C21,'127'!C21,'128'!C21,'129'!C21,'130'!C21,'131'!C21,'138'!C21,'139'!C21,'140'!C21) -> 2.9672429 | D21: =AVERAGE('114'!D21,'115'!D21,'116'!D21,'117'!D21,'118'!D21,'119'!D21,'121'!D21,'122'!D21,'123'!D21,'124'!D21,'125'!D21,'126'!D21,'127'!D21,'128'!D21,'129'!D21,'130'!D21,'131'!D21,'138'!D21,'139'!D21,'140'!D21) -> 1.1836715 | E21: =AVERAGE('114'!E21,'115'!E21,'116'!E21,'117'!E21,'118'!E21,'119'!E21,'121'!E21,'122'!E21,'123'!E21,'124'!E21,'125'!E21,'126'!E21,'127'!E21,'128'!E21,'129'!E21,'130'!E21,'131'!E21,'138'!E21,'139'!E21,'140'!E21) -> 2.3290596 | F21: =AVERAGE('114'!F21,'115'!F21,'116'!F21,'117'!F21,'118'!F21,'119'!F21,'121'!F21,'122'!F21,'123'!F21,'124'!F21,'125'!F21,'126'!F21,'127'!F21,'128'!F21,'129'!F21,'130'!F21,'131'!F21,'138'!F21,'139'!F21,'140'!F21) -> 1.0704762 | G21: =AVERAGE('114'!G21,'115'!G21,'116'!G21,'117'!G21,'118'!G21,'119'!G21,'121'!G21,'122'!G21,'123'!G21,'124'!G21,'125'!G21,'126'!G21,'127'!G21,'128'!G21,'129'!G21,'130'!G21,'131'!G21,'138'!G21,'139'!G21,'140'!G21) -> 0.12738095 | H21: =AVERAGE('114'!H21,'115'!H21,'116'!H21,'117'!H21,'118'!H21,'119'!H21,'121'!H21,'122'!H21,'123'!H21,'124'!H21,'125'!H21,'126'!H21,'127'!H21,'128'!H21,'129'!H21,'130'!H21,'131'!H21,'138'!H21,'139'!H21,'140'!H21) -> 0.2252381 | I21: =AVERAGE('114'!I21,'115'!I21,'116'!I21,'117'!I21,'118'!I21,'119'!I21,'121'!I21,'122'!I21,'123'!I21,'124'!I21,'125'!I21,'126'!I21,'127'!I21,'128'!I21,'129'!I21,'130'!I21,'131'!I21,'138'!I21,'139'!I21,'140'!I21) -> 1.2097239 | J21: =AVERAGE('114'!J21,'115'!J21,'116'!J21,'117'!J21,'118'!J21,'119'!J21,'121'!J21,'122'!J21,'123'!J21,'124'!J21,'125'!J21,'126'!J21,'127'!J21,'128'!J21,'129'!J21,'130'!J21,'131'!J21,'138'!J21,'139'!J21,'140'!J21) -> 0.47666667 | ... P21: =AVERAGE('114'!P21,'115'!P21,'116'!P21,'117'!P21,'118'!P21,'119'!P21,'121'!P21,'122'!P21,'123'!P21,'124'!P21,'125'!P21,'126'!P21,'127'!P21,'128'!P21,'129'!P21,'130'!P21,'131'!P21,'138'!P21,'139'!P21,'140'!P21) -> 34.643081 | R21: 1800-1900 | S21: =SUM(C54:C57) -> 13.341715 | T21: =SUM(D54:D57) -> 4.9868597 | U21: =SUM(E54:E57) -> 9.8951291 | V21: =SUM(F54:F57) -> 5.9745978 | W21: =SUM(G54:G57) -> 0.93695478 | X21: =SUM(H54:H57) -> 1.4486214 | Y21: =SUM(I54:I57) -> 6.6135574 | Z21: =SUM(J54:J57) -> 2.3890976 | ... AF21: =SUM(P54:P57) -> 147.77469
B22: 10.00 - 10.15 | C22: =AVERAGE('114'!C22,'115'!C22,'116'!C22,'117'!C22,'118'!C22,'119'!C22,'121'!C22,'122'!C22,'123'!C22,'124'!C22,'125'!C22,'126'!C22,'127'!C22,'128'!C22,'129'!C22,'130'!C22,'131'!C22,'138'!C22,'139'!C22,'140'!C22) -> 2.845112 | D22: =AVERAGE('114'!D22,'115'!D22,'116'!D22,'117'!D22,'118'!D22,'119'!D22,'121'!D22,'122'!D22,'123'!D22,'124'!D22,'125'!D22,'126'!D22,'127'!D22,'128'!D22,'129'!D22,'130'!D22,'131'!D22,'138'!D22,'139'!D22,'140'!D22) -> 1.4571238 | E22: =AVERAGE('114'!E22,'115'!E22,'116'!E22,'117'!E22,'118'!E22,'119'!E22,'121'!E22,'122'!E22,'123'!E22,'124'!E22,'125'!E22,'126'!E22,'127'!E22,'128'!E22,'129'!E22,'130'!E22,'131'!E22,'138'!E22,'139'!E22,'140'!E22) -> 2.5941787 | F22: =AVERAGE('114'!F22,'115'!F22,'116'!F22,'117'!F22,'118'!F22,'119'!F22,'121'!F22,'122'!F22,'123'!F22,'124'!F22,'125'!F22,'126'!F22,'127'!F22,'128'!F22,'129'!F22,'130'!F22,'131'!F22,'138'!F22,'139'!F22,'140'!F22) -> 1.4062405 | G22: =AVERAGE('114'!G22,'115'!G22,'116'!G22,'117'!G22,'118'!G22,'119'!G22,'121'!G22,'122'!G22,'123'!G22,'124'!G22,'125'!G22,'126'!G22,'127'!G22,'128'!G22,'129'!G22,'130'!G22,'131'!G22,'138'!G22,'139'!G22,'140'!G22) -> 0.15357143 | H22: =AVERAGE('114'!H22,'115'!H22,'116'!H22,'117'!H22,'118'!H22,'119'!H22,'121'!H22,'122'!H22,'123'!H22,'124'!H22,'125'!H22,'126'!H22,'127'!H22,'128'!H22,'129'!H22,'130'!H22,'131'!H22,'138'!H22,'139'!H22,'140'!H22) -> 0.27385954 | I22: =AVERAGE('114'!I22,'115'!I22,'116'!I22,'117'!I22,'118'!I22,'119'!I22,'121'!I22,'122'!I22,'123'!I22,'124'!I22,'125'!I22,'126'!I22,'127'!I22,'128'!I22,'129'!I22,'130'!I22,'131'!I22,'138'!I22,'139'!I22,'140'!I22) -> 1.4421048 | J22: =AVERAGE('114'!J22,'115'!J22,'116'!J22,'117'!J22,'118'!J22,'119'!J22,'121'!J22,'122'!J22,'123'!J22,'124'!J22,'125'!J22,'126'!J22,'127'!J22,'128'!J22,'129'!J22,'130'!J22,'131'!J22,'138'!J22,'139'!J22,'140'!J22) -> 0.46166667 | ... P22: =AVERAGE('114'!P22,'115'!P22,'116'!P22,'117'!P22,'118'!P22,'119'!P22,'121'!P22,'122'!P22,'123'!P22,'124'!P22,'125'!P22,'126'!P22,'127'!P22,'128'!P22,'129'!P22,'130'!P22,'131'!P22,'138'!P22,'139'!P22,'140'!P22) -> 35.570336 | R22: 1900-2000 | S22: =SUM(C58:C61) -> 11.632493 | T22: =SUM(D58:D61) -> 4.0302836 | U22: =SUM(E58:E61) -> 7.8634839 | V22: =SUM(F58:F61) -> 5.3546919 | W22: =SUM(G58:G61) -> 0.69166667 | X22: =SUM(H58:H61) -> 0.61267507 | Y22: =SUM(I58:I61) -> 4.5640756 | Z22: =SUM(J58:J61) -> 2.3 | ... AF22: =SUM(P58:P61) -> 136.24174
B23: 10.15 - 10.30 | C23: =AVERAGE('114'!C23,'115'!C23,'116'!C23,'117'!C23,'118'!C23,'119'!C23,'121'!C23,'122'!C23,'123'!C23,'124'!C23,'125'!C23,'126'!C23,'127'!C23,'128'!C23,'129'!C23,'130'!C23,'131'!C23,'138'!C23,'139'!C23,'140'!C23) -> 3.0073429 | D23: =AVERAGE('114'!D23,'115'!D23,'116'!D23,'117'!D23,'118'!D23,'119'!D23,'121'!D23,'122'!D23,'123'!D23,'124'!D23,'125'!D23,'126'!D23,'127'!D23,'128'!D23,'129'!D23,'130'!D23,'131'!D23,'138'!D23,'139'!D23,'140'!D23) -> 1.1908143 | E23: =AVERAGE('114'!E23,'115'!E23,'116'!E23,'117'!E23,'118'!E23,'119'!E23,'121'!E23,'122'!E23,'123'!E23,'124'!E23,'125'!E23,'126'!E23,'127'!E23,'128'!E23,'129'!E23,'130'!E23,'131'!E23,'138'!E23,'139'!E23,'140'!E23) -> 2.2685834 | F23: =AVERAGE('114'!F23,'115'!F23,'116'!F23,'117'!F23,'118'!F23,'119'!F23,'121'!F23,'122'!F23,'123'!F23,'124'!F23,'125'!F23,'126'!F23,'127'!F23,'128'!F23,'129'!F23,'130'!F23,'131'!F23,'138'!F23,'139'!F23,'140'!F23) -> 1.3606263 | G23: =AVERAGE('114'!G23,'115'!G23,'116'!G23,'117'!G23,'118'!G23,'119'!G23,'121'!G23,'122'!G23,'123'!G23,'124'!G23,'125'!G23,'126'!G23,'127'!G23,'128'!G23,'129'!G23,'130'!G23,'131'!G23,'138'!G23,'139'!G23,'140'!G23) -> 0.16190476 | H23: =AVERAGE('114'!H23,'115'!H23,'116'!H23,'117'!H23,'118'!H23,'119'!H23,'121'!H23,'122'!H23,'123'!H23,'124'!H23,'125'!H23,'126'!H23,'127'!H23,'128'!H23,'129'!H23,'130'!H23,'131'!H23,'138'!H23,'139'!H23,'140'!H23) -> 0.26909764 | I23: =AVERAGE('114'!I23,'115'!I23,'116'!I23,'117'!I23,'118'!I23,'119'!I23,'121'!I23,'122'!I23,'123'!I23,'124'!I23,'125'!I23,'126'!I23,'127'!I23,'128'!I23,'129'!I23,'130'!I23,'131'!I23,'138'!I23,'139'!I23,'140'!I23) -> 1.2070048 | J23: =AVERAGE('114'!J23,'115'!J23,'116'!J23,'117'!J23,'118'!J23,'119'!J23,'121'!J23,'122'!J23,'123'!J23,'124'!J23,'125'!J23,'126'!J23,'127'!J23,'128'!J23,'129'!J23,'130'!J23,'131'!J23,'138'!J23,'139'!J23,'140'!J23) -> 0.42 | ... P23: =AVERAGE('114'!P23,'115'!P23,'116'!P23,'117'!P23,'118'!P23,'119'!P23,'121'!P23,'122'!P23,'123'!P23,'124'!P23,'125'!P23,'126'!P23,'127'!P23,'128'!P23,'129'!P23,'130'!P23,'131'!P23,'138'!P23,'139'!P23,'140'!P23) -> 34.412191 | R23: 2000-2100 | S23: =SUM(C62:C65) -> 9.2037115 | T23: =SUM(D62:D65) -> 3.875042 | U23: =SUM(E62:E65) -> 6.9697759 | V23: =SUM(F62:F65) -> 3.3630252 | W23: =SUM(G62:G65) -> 0.57934174 | X23: =SUM(H62:H65) -> 0.65 | Y23: =SUM(I62:I65) -> 3.7093838 | Z23: =SUM(J62:J65) -> 1.9420168 | ... AF23: =SUM(P62:P65) -> 106.85672
B24: 10.30 - 10.45 | C24: =AVERAGE('114'!C24,'115'!C24,'116'!C24,'117'!C24,'118'!C24,'119'!C24,'121'!C24,'122'!C24,'123'!C24,'124'!C24,'125'!C24,'126'!C24,'127'!C24,'128'!C24,'129'!C24,'130'!C24,'131'!C24,'138'!C24,'139'!C24,'140'!C24) -> 2.9828691 | D24: =AVERAGE('114'!D24,'115'!D24,'116'!D24,'117'!D24,'118'!D24,'119'!D24,'121'!D24,'122'!D24,'123'!D24,'124'!D24,'125'!D24,'126'!D24,'127'!D24,'128'!D24,'129'!D24,'130'!D24,'131'!D24,'138'!D24,'139'!D24,'140'!D24) -> 1.2529072 | E24: =AVERAGE('114'!E24,'115'!E24,'116'!E24,'117'!E24,'118'!E24,'119'!E24,'121'!E24,'122'!E24,'123'!E24,'124'!E24,'125'!E24,'126'!E24,'127'!E24,'128'!E24,'129'!E24,'130'!E24,'131'!E24,'138'!E24,'139'!E24,'140'!E24) -> 2.3501501 | F24: =AVERAGE('114'!F24,'115'!F24,'116'!F24,'117'!F24,'118'!F24,'119'!F24,'121'!F24,'122'!F24,'123'!F24,'124'!F24,'125'!F24,'126'!F24,'127'!F24,'128'!F24,'129'!F24,'130'!F24,'131'!F24,'138'!F24,'139'!F24,'140'!F24) -> 1.2142857 | G24: =AVERAGE('114'!G24,'115'!G24,'116'!G24,'117'!G24,'118'!G24,'119'!G24,'121'!G24,'122'!G24,'123'!G24,'124'!G24,'125'!G24,'126'!G24,'127'!G24,'128'!G24,'129'!G24,'130'!G24,'131'!G24,'138'!G24,'139'!G24,'140'!G24) -> 0.10595238 | H24: =AVERAGE('114'!H24,'115'!H24,'116'!H24,'117'!H24,'118'!H24,'119'!H24,'121'!H24,'122'!H24,'123'!H24,'124'!H24,'125'!H24,'126'!H24,'127'!H24,'128'!H24,'129'!H24,'130'!H24,'131'!H24,'138'!H24,'139'!H24,'140'!H24) -> 0.19642857 | I24: =AVERAGE('114'!I24,'115'!I24,'116'!I24,'117'!I24,'118'!I24,'119'!I24,'121'!I24,'122'!I24,'123'!I24,'124'!I24,'125'!I24,'126'!I24,'127'!I24,'128'!I24,'129'!I24,'130'!I24,'131'!I24,'138'!I24,'139'!I24,'140'!I24) -> 1.4609644 | J24: =AVERAGE('114'!J24,'115'!J24,'116'!J24,'117'!J24,'118'!J24,'119'!J24,'121'!J24,'122'!J24,'123'!J24,'124'!J24,'125'!J24,'126'!J24,'127'!J24,'128'!J24,'129'!J24,'130'!J24,'131'!J24,'138'!J24,'139'!J24,'140'!J24) -> 0.47380952 | ... P24: =AVERAGE('114'!P24,'115'!P24,'116'!P24,'117'!P24,'118'!P24,'119'!P24,'121'!P24,'122'!P24,'123'!P24,'124'!P24,'125'!P24,'126'!P24,'127'!P24,'128'!P24,'129'!P24,'130'!P24,'131'!P24,'138'!P24,'139'!P24,'140'!P24) -> 34.821703 | R24: 2100-2200 | S24: =SUM(C66:C69) -> 7.4457283 | T24: =SUM(D66:D69) -> 2.3860504 | U24: =SUM(E66:E69) -> 5.3551261 | V24: =SUM(F66:F69) -> 3.0083333 | W24: =SUM(G66:G69) -> 0.2710084 | X24: =SUM(H66:H69) -> 0.825 | Y24: =SUM(I66:I69) -> 2.9177171 | Z24: =SUM(J66:J69) -> 1.1170168 | ... AF24: =SUM(P66:P69) -> 79.453782
B25: 10.45 - 11.00 | C25: =AVERAGE('114'!C25,'115'!C25,'116'!C25,'117'!C25,'118'!C25,'119'!C25,'121'!C25,'122'!C25,'123'!C25,'124'!C25,'125'!C25,'126'!C25,'127'!C25,'128'!C25,'129'!C25,'130'!C25,'131'!C25,'138'!C25,'139'!C25,'140'!C25) -> 2.9991597 | D25: =AVERAGE('114'!D25,'115'!D25,'116'!D25,'117'!D25,'118'!D25,'119'!D25,'121'!D25,'122'!D25,'123'!D25,'124'!D25,'125'!D25,'126'!D25,'127'!D25,'128'!D25,'129'!D25,'130'!D25,'131'!D25,'138'!D25,'139'!D25,'140'!D25) -> 1.1976 | E25: =AVERAGE('114'!E25,'115'!E25,'116'!E25,'117'!E25,'118'!E25,'119'!E25,'121'!E25,'122'!E25,'123'!E25,'124'!E25,'125'!E25,'126'!E25,'127'!E25,'128'!E25,'129'!E25,'130'!E25,'131'!E25,'138'!E25,'139'!E25,'140'!E25) -> 2.3010334 | F25: =AVERAGE('114'!F25,'115'!F25,'116'!F25,'117'!F25,'118'!F25,'119'!F25,'121'!F25,'122'!F25,'123'!F25,'124'!F25,'125'!F25,'126'!F25,'127'!F25,'128'!F25,'129'!F25,'130'!F25,'131'!F25,'138'!F25,'139'!F25,'140'!F25) -> 1.4230072 | G25: =AVERAGE('114'!G25,'115'!G25,'116'!G25,'117'!G25,'118'!G25,'119'!G25,'121'!G25,'122'!G25,'123'!G25,'124'!G25,'125'!G25,'126'!G25,'127'!G25,'128'!G25,'129'!G25,'130'!G25,'131'!G25,'138'!G25,'139'!G25,'140'!G25) -> 0.14404762 | H25: =AVERAGE('114'!H25,'115'!H25,'116'!H25,'117'!H25,'118'!H25,'119'!H25,'121'!H25,'122'!H25,'123'!H25,'124'!H25,'125'!H25,'126'!H25,'127'!H25,'128'!H25,'129'!H25,'130'!H25,'131'!H25,'138'!H25,'139'!H25,'140'!H25) -> 0.29528812 | I25: =AVERAGE('114'!I25,'115'!I25,'116'!I25,'117'!I25,'118'!I25,'119'!I25,'121'!I25,'122'!I25,'123'!I25,'124'!I25,'125'!I25,'126'!I25,'127'!I25,'128'!I25,'129'!I25,'130'!I25,'131'!I25,'138'!I25,'139'!I25,'140'!I25) -> 1.1965286 | J25: =AVERAGE('114'!J25,'115'!J25,'116'!J25,'117'!J25,'118'!J25,'119'!J25,'121'!J25,'122'!J25,'123'!J25,'124'!J25,'125'!J25,'126'!J25,'127'!J25,'128'!J25,'129'!J25,'130'!J25,'131'!J25,'138'!J25,'139'!J25,'140'!J25) -> 0.50428571 | ... P25: =AVERAGE('114'!P25,'115'!P25,'116'!P25,'117'!P25,'118'!P25,'119'!P25,'121'!P25,'122'!P25,'123'!P25,'124'!P25,'125'!P25,'126'!P25,'127'!P25,'128'!P25,'129'!P25,'130'!P25,'131'!P25,'138'!P25,'139'!P25,'140'!P25) -> 34.037717 | R25: 2200-2300 | S25: =SUM(C70:C73) -> 5.534944 | T25: =SUM(D70:D73) -> 2.322584 | U25: =SUM(E70:E73) -> 4.4370098 | V25: =SUM(F70:F73) -> 2.0416667 | W25: =SUM(G70:G73) -> 0.18802521 | X25: =SUM(H70:H73) -> 0.91267507 | Y25: =SUM(I70:I73) -> 2.9553922 | Z25: =SUM(J70:J73) -> 1.4840336 | ... AF25: =SUM(P70:P73) -> 57.038165
B26: 11.00 - 11.15 | C26: =AVERAGE('114'!C26,'115'!C26,'116'!C26,'117'!C26,'118'!C26,'119'!C26,'121'!C26,'122'!C26,'123'!C26,'124'!C26,'125'!C26,'126'!C26,'127'!C26,'128'!C26,'129'!C26,'130'!C26,'131'!C26,'138'!C26,'139'!C26,'140'!C26) -> 3.2426811 | D26: =AVERAGE('114'!D26,'115'!D26,'116'!D26,'117'!D26,'118'!D26,'119'!D26,'121'!D26,'122'!D26,'123'!D26,'124'!D26,'125'!D26,'126'!D26,'127'!D26,'128'!D26,'129'!D26,'130'!D26,'131'!D26,'138'!D26,'139'!D26,'140'!D26) -> 1.0341477 | E26: =AVERAGE('114'!E26,'115'!E26,'116'!E26,'117'!E26,'118'!E26,'119'!E26,'121'!E26,'122'!E26,'123'!E26,'124'!E26,'125'!E26,'126'!E26,'127'!E26,'128'!E26,'129'!E26,'130'!E26,'131'!E26,'138'!E26,'139'!E26,'140'!E26) -> 2.2681072 | F26: =AVERAGE('114'!F26,'115'!F26,'116'!F26,'117'!F26,'118'!F26,'119'!F26,'121'!F26,'122'!F26,'123'!F26,'124'!F26,'125'!F26,'126'!F26,'127'!F26,'128'!F26,'129'!F26,'130'!F26,'131'!F26,'138'!F26,'139'!F26,'140'!F26) -> 1.4861024 | G26: =AVERAGE('114'!G26,'115'!G26,'116'!G26,'117'!G26,'118'!G26,'119'!G26,'121'!G26,'122'!G26,'123'!G26,'124'!G26,'125'!G26,'126'!G26,'127'!G26,'128'!G26,'129'!G26,'130'!G26,'131'!G26,'138'!G26,'139'!G26,'140'!G26) -> 0.09047619 | H26: =AVERAGE('114'!H26,'115'!H26,'116'!H26,'117'!H26,'118'!H26,'119'!H26,'121'!H26,'122'!H26,'123'!H26,'124'!H26,'125'!H26,'126'!H26,'127'!H26,'128'!H26,'129'!H26,'130'!H26,'131'!H26,'138'!H26,'139'!H26,'140'!H26) -> 0.175 | I26: =AVERAGE('114'!I26,'115'!I26,'116'!I26,'117'!I26,'118'!I26,'119'!I26,'121'!I26,'122'!I26,'123'!I26,'124'!I26,'125'!I26,'126'!I26,'127'!I26,'128'!I26,'129'!I26,'130'!I26,'131'!I26,'138'!I26,'139'!I26,'140'!I26) -> 1.4920548 | J26: =AVERAGE('114'!J26,'115'!J26,'116'!J26,'117'!J26,'118'!J26,'119'!J26,'121'!J26,'122'!J26,'123'!J26,'124'!J26,'125'!J26,'126'!J26,'127'!J26,'128'!J26,'129'!J26,'130'!J26,'131'!J26,'138'!J26,'139'!J26,'140'!J26) -> 0.49 | ... P26: =AVERAGE('114'!P26,'115'!P26,'116'!P26,'117'!P26,'118'!P26,'119'!P26,'121'!P26,'122'!P26,'123'!P26,'124'!P26,'125'!P26,'126'!P26,'127'!P26,'128'!P26,'129'!P26,'130'!P26,'131'!P26,'138'!P26,'139'!P26,'140'!P26) -> 34.781477 | R26: 2300-0000 | S26: =SUM(C74:C77) -> 4.1668768 | T26: =SUM(D74:D77) -> 2.4370588 | U26: =SUM(E74:E77) -> 3.9834594 | V26: =SUM(F74:F77) -> 1.225 | W26: =SUM(G74:G77) -> 0.1710084 | X26: =SUM(H74:H77) -> 0.5960084 | Y26: =SUM(I74:I77) -> 2.5470588 | Z26: =SUM(J74:J77) -> 0.8710084 | ... AF26: =SUM(P74:P77) -> 39.064846
B27: 11.15 - 11.30 | C27: =AVERAGE('114'!C27,'115'!C27,'116'!C27,'117'!C27,'118'!C27,'119'!C27,'121'!C27,'122'!C27,'123'!C27,'124'!C27,'125'!C27,'126'!C27,'127'!C27,'128'!C27,'129'!C27,'130'!C27,'131'!C27,'138'!C27,'139'!C27,'140'!C27) -> 2.8563906 | D27: =AVERAGE('114'!D27,'115'!D27,'116'!D27,'117'!D27,'118'!D27,'119'!D27,'121'!D27,'122'!D27,'123'!D27,'124'!D27,'125'!D27,'126'!D27,'127'!D27,'128'!D27,'129'!D27,'130'!D27,'131'!D27,'138'!D27,'139'!D27,'140'!D27) -> 1.1946549 | E27: =AVERAGE('114'!E27,'115'!E27,'116'!E27,'117'!E27,'118'!E27,'119'!E27,'121'!E27,'122'!E27,'123'!E27,'124'!E27,'125'!E27,'126'!E27,'127'!E27,'128'!E27,'129'!E27,'130'!E27,'131'!E27,'138'!E27,'139'!E27,'140'!E27) -> 2.4510954 | F27: =AVERAGE('114'!F27,'115'!F27,'116'!F27,'117'!F27,'118'!F27,'119'!F27,'121'!F27,'122'!F27,'123'!F27,'124'!F27,'125'!F27,'126'!F27,'127'!F27,'128'!F27,'129'!F27,'130'!F27,'131'!F27,'138'!F27,'139'!F27,'140'!F27) -> 1.3328571 | G27: =AVERAGE('114'!G27,'115'!G27,'116'!G27,'117'!G27,'118'!G27,'119'!G27,'121'!G27,'122'!G27,'123'!G27,'124'!G27,'125'!G27,'126'!G27,'127'!G27,'128'!G27,'129'!G27,'130'!G27,'131'!G27,'138'!G27,'139'!G27,'140'!G27) -> 0.12738095 | H27: =AVERAGE('114'!H27,'115'!H27,'116'!H27,'117'!H27,'118'!H27,'119'!H27,'121'!H27,'122'!H27,'123'!H27,'124'!H27,'125'!H27,'126'!H27,'127'!H27,'128'!H27,'129'!H27,'130'!H27,'131'!H27,'138'!H27,'139'!H27,'140'!H27) -> 0.16909764 | I27: =AVERAGE('114'!I27,'115'!I27,'116'!I27,'117'!I27,'118'!I27,'119'!I27,'121'!I27,'122'!I27,'123'!I27,'124'!I27,'125'!I27,'126'!I27,'127'!I27,'128'!I27,'129'!I27,'130'!I27,'131'!I27,'138'!I27,'139'!I27,'140'!I27) -> 1.3244358 | J27: =AVERAGE('114'!J27,'115'!J27,'116'!J27,'117'!J27,'118'!J27,'119'!J27,'121'!J27,'122'!J27,'123'!J27,'124'!J27,'125'!J27,'126'!J27,'127'!J27,'128'!J27,'129'!J27,'130'!J27,'131'!J27,'138'!J27,'139'!J27,'140'!J27) -> 0.4702381 | ... P27: =AVERAGE('114'!P27,'115'!P27,'116'!P27,'117'!P27,'118'!P27,'119'!P27,'121'!P27,'122'!P27,'123'!P27,'124'!P27,'125'!P27,'126'!P27,'127'!P27,'128'!P27,'129'!P27,'130'!P27,'131'!P27,'138'!P27,'139'!P27,'140'!P27) -> 33.008631 | R27: 0000-0100 | S27: =SUM(C78:C81) -> 3.7845938 | T27: =SUM(D78:D81) -> 1.5198004 | U27: =SUM(E78:E81) -> 3.0876926 | V27: =SUM(F78:F81) -> 0.83403361 | W27: =SUM(G78:G81) -> 0.14201681 | X27: =SUM(H78:H81) -> 0.49201681 | Y27: =SUM(I78:I81) -> 2.4137255 | Z27: =SUM(J78:J81) -> 0.93004202 | ... AF27: =SUM(P78:P81) -> 30.385714
B28: 11.30 - 11.45 | C28: =AVERAGE('114'!C28,'115'!C28,'116'!C28,'117'!C28,'118'!C28,'119'!C28,'121'!C28,'122'!C28,'123'!C28,'124'!C28,'125'!C28,'126'!C28,'127'!C28,'128'!C28,'129'!C28,'130'!C28,'131'!C28,'138'!C28,'139'!C28,'140'!C28) -> 2.8782073 | D28: =AVERAGE('114'!D28,'115'!D28,'116'!D28,'117'!D28,'118'!D28,'119'!D28,'121'!D28,'122'!D28,'123'!D28,'124'!D28,'125'!D28,'126'!D28,'127'!D28,'128'!D28,'129'!D28,'130'!D28,'131'!D28,'138'!D28,'139'!D28,'140'!D28) -> 1.247481 | E28: =AVERAGE('114'!E28,'115'!E28,'116'!E28,'117'!E28,'118'!E28,'119'!E28,'121'!E28,'122'!E28,'123'!E28,'124'!E28,'125'!E28,'126'!E28,'127'!E28,'128'!E28,'129'!E28,'130'!E28,'131'!E28,'138'!E28,'139'!E28,'140'!E28) -> 2.4254882 | F28: =AVERAGE('114'!F28,'115'!F28,'116'!F28,'117'!F28,'118'!F28,'119'!F28,'121'!F28,'122'!F28,'123'!F28,'124'!F28,'125'!F28,'126'!F28,'127'!F28,'128'!F28,'129'!F28,'130'!F28,'131'!F28,'138'!F28,'139'!F28,'140'!F28) -> 1.2095238 | G28: =AVERAGE('114'!G28,'115'!G28,'116'!G28,'117'!G28,'118'!G28,'119'!G28,'121'!G28,'122'!G28,'123'!G28,'124'!G28,'125'!G28,'126'!G28,'127'!G28,'128'!G28,'129'!G28,'130'!G28,'131'!G28,'138'!G28,'139'!G28,'140'!G28) -> 0.13690476 | H28: =AVERAGE('114'!H28,'115'!H28,'116'!H28,'117'!H28,'118'!H28,'119'!H28,'121'!H28,'122'!H28,'123'!H28,'124'!H28,'125'!H28,'126'!H28,'127'!H28,'128'!H28,'129'!H28,'130'!H28,'131'!H28,'138'!H28,'139'!H28,'140'!H28) -> 0.16547619 | I28: =AVERAGE('114'!I28,'115'!I28,'116'!I28,'117'!I28,'118'!I28,'119'!I28,'121'!I28,'122'!I28,'123'!I28,'124'!I28,'125'!I28,'126'!I28,'127'!I28,'128'!I28,'129'!I28,'130'!I28,'131'!I28,'138'!I28,'139'!I28,'140'!I28) -> 1.302393 | J28: =AVERAGE('114'!J28,'115'!J28,'116'!J28,'117'!J28,'118'!J28,'119'!J28,'121'!J28,'122'!J28,'123'!J28,'124'!J28,'125'!J28,'126'!J28,'127'!J28,'128'!J28,'129'!J28,'130'!J28,'131'!J28,'138'!J28,'139'!J28,'140'!J28) -> 0.54833333 | ... P28: =AVERAGE('114'!P28,'115'!P28,'116'!P28,'117'!P28,'118'!P28,'119'!P28,'121'!P28,'122'!P28,'123'!P28,'124'!P28,'125'!P28,'126'!P28,'127'!P28,'128'!P28,'129'!P28,'130'!P28,'131'!P28,'138'!P28,'139'!P28,'140'!P28) -> 33.374396 | R28: 0100-0200 | S28: =SUM(C82:C85) -> 3.1828431 | T28: =SUM(D82:D85) -> 1.8873424 | U28: =SUM(E82:E85) -> 3.2976015 | V28: =SUM(F82:F85) -> 0.75504202 | W28: =SUM(G82:G85) -> 0.30504202 | X28: =SUM(H82:H85) -> 0.48802521 | Y28: =SUM(I82:I85) -> 2.2177171 | Z28: =SUM(J82:J85) -> 0.63767507 | ... AF28: =SUM(P82:P85) -> 25.590056
B29: 11.45 - 12.00 | C29: =AVERAGE('114'!C29,'115'!C29,'116'!C29,'117'!C29,'118'!C29,'119'!C29,'121'!C29,'122'!C29,'123'!C29,'124'!C29,'125'!C29,'126'!C29,'127'!C29,'128'!C29,'129'!C29,'130'!C29,'131'!C29,'138'!C29,'139'!C29,'140'!C29) -> 2.8432953 | D29: =AVERAGE('114'!D29,'115'!D29,'116'!D29,'117'!D29,'118'!D29,'119'!D29,'121'!D29,'122'!D29,'123'!D29,'124'!D29,'125'!D29,'126'!D29,'127'!D29,'128'!D29,'129'!D29,'130'!D29,'131'!D29,'138'!D29,'139'!D29,'140'!D29) -> 1.2486525 | E29: =AVERAGE('114'!E29,'115'!E29,'116'!E29,'117'!E29,'118'!E29,'119'!E29,'121'!E29,'122'!E29,'123'!E29,'124'!E29,'125'!E29,'126'!E29,'127'!E29,'128'!E29,'129'!E29,'130'!E29,'131'!E29,'138'!E29,'139'!E29,'140'!E29) -> 2.3131383 | F29: =AVERAGE('114'!F29,'115'!F29,'116'!F29,'117'!F29,'118'!F29,'119'!F29,'121'!F29,'122'!F29,'123'!F29,'124'!F29,'125'!F29,'126'!F29,'127'!F29,'128'!F29,'129'!F29,'130'!F29,'131'!F29,'138'!F29,'139'!F29,'140'!F29) -> 1.3931453 | G29: =AVERAGE('114'!G29,'115'!G29,'116'!G29,'117'!G29,'118'!G29,'119'!G29,'121'!G29,'122'!G29,'123'!G29,'124'!G29,'125'!G29,'126'!G29,'127'!G29,'128'!G29,'129'!G29,'130'!G29,'131'!G29,'138'!G29,'139'!G29,'140'!G29) -> 0.11904762 | H29: =AVERAGE('114'!H29,'115'!H29,'116'!H29,'117'!H29,'118'!H29,'119'!H29,'121'!H29,'122'!H29,'123'!H29,'124'!H29,'125'!H29,'126'!H29,'127'!H29,'128'!H29,'129'!H29,'130'!H29,'131'!H29,'138'!H29,'139'!H29,'140'!H29) -> 0.3060024 | I29: =AVERAGE('114'!I29,'115'!I29,'116'!I29,'117'!I29,'118'!I29,'119'!I29,'121'!I29,'122'!I29,'123'!I29,'124'!I29,'125'!I29,'126'!I29,'127'!I29,'128'!I29,'129'!I29,'130'!I29,'131'!I29,'138'!I29,'139'!I29,'140'!I29) -> 1.4359644 | J29: =AVERAGE('114'!J29,'115'!J29,'116'!J29,'117'!J29,'118'!J29,'119'!J29,'121'!J29,'122'!J29,'123'!J29,'124'!J29,'125'!J29,'126'!J29,'127'!J29,'128'!J29,'129'!J29,'130'!J29,'131'!J29,'138'!J29,'139'!J29,'140'!J29) -> 0.445 | ... P29: =AVERAGE('114'!P29,'115'!P29,'116'!P29,'117'!P29,'118'!P29,'119'!P29,'121'!P29,'122'!P29,'123'!P29,'124'!P29,'125'!P29,'126'!P29,'127'!P29,'128'!P29,'129'!P29,'130'!P29,'131'!P29,'138'!P29,'139'!P29,'140'!P29) -> 33.205022 | R29: 0200-0300 | S29: =SUM(C86:C89) -> 2.3708683 | T29: =SUM(D86:D89) -> 1.0052836 | U29: =SUM(E86:E89) -> 2.6475175 | V29: =SUM(F86:F89) -> 0.7460084 | W29: =SUM(G86:G89) -> 0.096008403 | X29: =SUM(H86:H89) -> 0.45 | Y29: =SUM(I86:I89) -> 1.8140756 | Z29: =SUM(J86:J89) -> 0.48333333 | ... AF29: =SUM(P86:P89) -> 16.702521
B30: 12.00 - 12.15 | C30: =AVERAGE('114'!C30,'115'!C30,'116'!C30,'117'!C30,'118'!C30,'119'!C30,'121'!C30,'122'!C30,'123'!C30,'124'!C30,'125'!C30,'126'!C30,'127'!C30,'128'!C30,'129'!C30,'130'!C30,'131'!C30,'138'!C30,'139'!C30,'140'!C30) -> 2.9922049 | D30: =AVERAGE('114'!D30,'115'!D30,'116'!D30,'117'!D30,'118'!D30,'119'!D30,'121'!D30,'122'!D30,'123'!D30,'124'!D30,'125'!D30,'126'!D30,'127'!D30,'128'!D30,'129'!D30,'130'!D30,'131'!D30,'138'!D30,'139'!D30,'140'!D30) -> 1.1230072 | E30: =AVERAGE('114'!E30,'115'!E30,'116'!E30,'117'!E30,'118'!E30,'119'!E30,'121'!E30,'122'!E30,'123'!E30,'124'!E30,'125'!E30,'126'!E30,'127'!E30,'128'!E30,'129'!E30,'130'!E30,'131'!E30,'138'!E30,'139'!E30,'140'!E30) -> 2.3545858 | F30: =AVERAGE('114'!F30,'115'!F30,'116'!F30,'117'!F30,'118'!F30,'119'!F30,'121'!F30,'122'!F30,'123'!F30,'124'!F30,'125'!F30,'126'!F30,'127'!F30,'128'!F30,'129'!F30,'130'!F30,'131'!F30,'138'!F30,'139'!F30,'140'!F30) -> 1.7581453 | G30: =AVERAGE('114'!G30,'115'!G30,'116'!G30,'117'!G30,'118'!G30,'119'!G30,'121'!G30,'122'!G30,'123'!G30,'124'!G30,'125'!G30,'126'!G30,'127'!G30,'128'!G30,'129'!G30,'130'!G30,'131'!G30,'138'!G30,'139'!G30,'140'!G30) -> 0.057142857 | H30: =AVERAGE('114'!H30,'115'!H30,'116'!H30,'117'!H30,'118'!H30,'119'!H30,'121'!H30,'122'!H30,'123'!H30,'124'!H30,'125'!H30,'126'!H30,'127'!H30,'128'!H30,'129'!H30,'130'!H30,'131'!H30,'138'!H30,'139'!H30,'140'!H30) -> 0.23095238 | I30: =AVERAGE('114'!I30,'115'!I30,'116'!I30,'117'!I30,'118'!I30,'119'!I30,'121'!I30,'122'!I30,'123'!I30,'124'!I30,'125'!I30,'126'!I30,'127'!I30,'128'!I30,'129'!I30,'130'!I30,'131'!I30,'138'!I30,'139'!I30,'140'!I30) -> 1.5688715 | J30: =AVERAGE('114'!J30,'115'!J30,'116'!J30,'117'!J30,'118'!J30,'119'!J30,'121'!J30,'122'!J30,'123'!J30,'124'!J30,'125'!J30,'126'!J30,'127'!J30,'128'!J30,'129'!J30,'130'!J30,'131'!J30,'138'!J30,'139'!J30,'140'!J30) -> 0.58719288 | ... P30: =AVERAGE('114'!P30,'115'!P30,'116'!P30,'117'!P30,'118'!P30,'119'!P30,'121'!P30,'122'!P30,'123'!P30,'124'!P30,'125'!P30,'126'!P30,'127'!P30,'128'!P30,'129'!P30,'130'!P30,'131'!P30,'138'!P30,'139'!P30,'140'!P30) -> 34.490686 | R30: 0300-0400 | S30: =SUM(C90:C93) -> 3.6729692 | T30: =SUM(D90:D93) -> 1.4290756 | U30: =SUM(E90:E93) -> 3.6301681 | V30: =SUM(F90:F93) -> 0.6960084 | W30: =SUM(G90:G93) -> 0.016666667 | X30: =SUM(H90:H93) -> 0.71302521 | Y30: =SUM(I90:I93) -> 1.9390756 | Z30: =SUM(J90:J93) -> 0.74201681 | ... AF30: =SUM(P90:P93) -> 20.498389
B31: 12.15 - 12.30 | C31: =AVERAGE('114'!C31,'115'!C31,'116'!C31,'117'!C31,'118'!C31,'119'!C31,'121'!C31,'122'!C31,'123'!C31,'124'!C31,'125'!C31,'126'!C31,'127'!C31,'128'!C31,'129'!C31,'130'!C31,'131'!C31,'138'!C31,'139'!C31,'140'!C31) -> 2.9732453 | D31: =AVERAGE('114'!D31,'115'!D31,'116'!D31,'117'!D31,'118'!D31,'119'!D31,'121'!D31,'122'!D31,'123'!D31,'124'!D31,'125'!D31,'126'!D31,'127'!D31,'128'!D31,'129'!D31,'130'!D31,'131'!D31,'138'!D31,'139'!D31,'140'!D31) -> 1.0651691 | E31: =AVERAGE('114'!E31,'115'!E31,'116'!E31,'117'!E31,'118'!E31,'119'!E31,'121'!E31,'122'!E31,'123'!E31,'124'!E31,'125'!E31,'126'!E31,'127'!E31,'128'!E31,'129'!E31,'130'!E31,'131'!E31,'138'!E31,'139'!E31,'140'!E31) -> 2.3440286 | F31: =AVERAGE('114'!F31,'115'!F31,'116'!F31,'117'!F31,'118'!F31,'119'!F31,'121'!F31,'122'!F31,'123'!F31,'124'!F31,'125'!F31,'126'!F31,'127'!F31,'128'!F31,'129'!F31,'130'!F31,'131'!F31,'138'!F31,'139'!F31,'140'!F31) -> 1.2240476 | G31: =AVERAGE('114'!G31,'115'!G31,'116'!G31,'117'!G31,'118'!G31,'119'!G31,'121'!G31,'122'!G31,'123'!G31,'124'!G31,'125'!G31,'126'!G31,'127'!G31,'128'!G31,'129'!G31,'130'!G31,'131'!G31,'138'!G31,'139'!G31,'140'!G31) -> 0.063145258 | H31: =AVERAGE('114'!H31,'115'!H31,'116'!H31,'117'!H31,'118'!H31,'119'!H31,'121'!H31,'122'!H31,'123'!H31,'124'!H31,'125'!H31,'126'!H31,'127'!H31,'128'!H31,'129'!H31,'130'!H31,'131'!H31,'138'!H31,'139'!H31,'140'!H31) -> 0.25357143 | I31: =AVERAGE('114'!I31,'115'!I31,'116'!I31,'117'!I31,'118'!I31,'119'!I31,'121'!I31,'122'!I31,'123'!I31,'124'!I31,'125'!I31,'126'!I31,'127'!I31,'128'!I31,'129'!I31,'130'!I31,'131'!I31,'138'!I31,'139'!I31,'140'!I31) -> 1.6334834 | J31: =AVERAGE('114'!J31,'115'!J31,'116'!J31,'117'!J31,'118'!J31,'119'!J31,'121'!J31,'122'!J31,'123'!J31,'124'!J31,'125'!J31,'126'!J31,'127'!J31,'128'!J31,'129'!J31,'130'!J31,'131'!J31,'138'!J31,'139'!J31,'140'!J31) -> 0.50357143 | ... P31: =AVERAGE('114'!P31,'115'!P31,'116'!P31,'117'!P31,'118'!P31,'119'!P31,'121'!P31,'122'!P31,'123'!P31,'124'!P31,'125'!P31,'126'!P31,'127'!P31,'128'!P31,'129'!P31,'130'!P31,'131'!P31,'138'!P31,'139'!P31,'140'!P31) -> 33.851465 | R31: 0400-0500 | S31: =SUM(C94:C97) -> 3.6186275 | T31: =SUM(D94:D97) -> 1.9116176 | U31: =SUM(E94:E97) -> 3.800077 | V31: =SUM(F94:F97) -> 1.0130252 | W31: =SUM(G94:G97) -> 0.14201681 | X31: =SUM(H94:H97) -> 0.78767507 | Y31: =SUM(I94:I97) -> 2.0180672 | Z31: =SUM(J94:J97) -> 0.58802521 | ... AF31: =SUM(P94:P97) -> 22.763165
B32: 12.30 - 12.45 | C32: =AVERAGE('114'!C32,'115'!C32,'116'!C32,'117'!C32,'118'!C32,'119'!C32,'121'!C32,'122'!C32,'123'!C32,'124'!C32,'125'!C32,'126'!C32,'127'!C32,'128'!C32,'129'!C32,'130'!C32,'131'!C32,'138'!C32,'139'!C32,'140'!C32) -> 2.8847239 | D32: =AVERAGE('114'!D32,'115'!D32,'116'!D32,'117'!D32,'118'!D32,'119'!D32,'121'!D32,'122'!D32,'123'!D32,'124'!D32,'125'!D32,'126'!D32,'127'!D32,'128'!D32,'129'!D32,'130'!D32,'131'!D32,'138'!D32,'139'!D32,'140'!D32) -> 0.91836435 | E32: =AVERAGE('114'!E32,'115'!E32,'116'!E32,'117'!E32,'118'!E32,'119'!E32,'121'!E32,'122'!E32,'123'!E32,'124'!E32,'125'!E32,'126'!E32,'127'!E32,'128'!E32,'129'!E32,'130'!E32,'131'!E32,'138'!E32,'139'!E32,'140'!E32) -> 2.2639906 | F32: =AVERAGE('114'!F32,'115'!F32,'116'!F32,'117'!F32,'118'!F32,'119'!F32,'121'!F32,'122'!F32,'123'!F32,'124'!F32,'125'!F32,'126'!F32,'127'!F32,'128'!F32,'129'!F32,'130'!F32,'131'!F32,'138'!F32,'139'!F32,'140'!F32) -> 1.2416667 | G32: =AVERAGE('114'!G32,'115'!G32,'116'!G32,'117'!G32,'118'!G32,'119'!G32,'121'!G32,'122'!G32,'123'!G32,'124'!G32,'125'!G32,'126'!G32,'127'!G32,'128'!G32,'129'!G32,'130'!G32,'131'!G32,'138'!G32,'139'!G32,'140'!G32) -> 0.11071429 | H32: =AVERAGE('114'!H32,'115'!H32,'116'!H32,'117'!H32,'118'!H32,'119'!H32,'121'!H32,'122'!H32,'123'!H32,'124'!H32,'125'!H32,'126'!H32,'127'!H32,'128'!H32,'129'!H32,'130'!H32,'131'!H32,'138'!H32,'139'!H32,'140'!H32) -> 0.22261905 | I32: =AVERAGE('114'!I32,'115'!I32,'116'!I32,'117'!I32,'118'!I32,'119'!I32,'121'!I32,'122'!I32,'123'!I32,'124'!I32,'125'!I32,'126'!I32,'127'!I32,'128'!I32,'129'!I32,'130'!I32,'131'!I32,'138'!I32,'139'!I32,'140'!I32) -> 1.3006763 | J32: =AVERAGE('114'!J32,'115'!J32,'116'!J32,'117'!J32,'118'!J32,'119'!J32,'121'!J32,'122'!J32,'123'!J32,'124'!J32,'125'!J32,'126'!J32,'127'!J32,'128'!J32,'129'!J32,'130'!J32,'131'!J32,'138'!J32,'139'!J32,'140'!J32) -> 0.46547619 | ... P32: =AVERAGE('114'!P32,'115'!P32,'116'!P32,'117'!P32,'118'!P32,'119'!P32,'121'!P32,'122'!P32,'123'!P32,'124'!P32,'125'!P32,'126'!P32,'127'!P32,'128'!P32,'129'!P32,'130'!P32,'131'!P32,'138'!P32,'139'!P32,'140'!P32) -> 32.073043 | R32: 0500-0600 | S32: =SUM(C98:C101) -> 4.7797619 | T32: =SUM(D98:D101) -> 2.6051261 | U32: =SUM(E98:E101) -> 5.0822689 | V32: =SUM(F98:F101) -> 1.2510504 | W32: =SUM(G98:G101) -> 0.19166667 | X32: =SUM(H98:H101) -> 1.0296919 | Y32: =SUM(I98:I101) -> 2.4137255 | Z32: =SUM(J98:J101) -> 0.94201681 | ... AF32: =SUM(P98:P101) -> 33.409384
B33: 12.45 - 13.00 | C33: =AVERAGE('114'!C33,'115'!C33,'116'!C33,'117'!C33,'118'!C33,'119'!C33,'121'!C33,'122'!C33,'123'!C33,'124'!C33,'125'!C33,'126'!C33,'127'!C33,'128'!C33,'129'!C33,'130'!C33,'131'!C33,'138'!C33,'139'!C33,'140'!C33) -> 3.3279192 | D33: =AVERAGE('114'!D33,'115'!D33,'116'!D33,'117'!D33,'118'!D33,'119'!D33,'121'!D33,'122'!D33,'123'!D33,'124'!D33,'125'!D33,'126'!D33,'127'!D33,'128'!D33,'129'!D33,'130'!D33,'131'!D33,'138'!D33,'139'!D33,'140'!D33) -> 1.1322929 | E33: =AVERAGE('114'!E33,'115'!E33,'116'!E33,'117'!E33,'118'!E33,'119'!E33,'121'!E33,'122'!E33,'123'!E33,'124'!E33,'125'!E33,'126'!E33,'127'!E33,'128'!E33,'129'!E33,'130'!E33,'131'!E33,'138'!E33,'139'!E33,'140'!E33) -> 2.155062 | F33: =AVERAGE('114'!F33,'115'!F33,'116'!F33,'117'!F33,'118'!F33,'119'!F33,'121'!F33,'122'!F33,'123'!F33,'124'!F33,'125'!F33,'126'!F33,'127'!F33,'128'!F33,'129'!F33,'130'!F33,'131'!F33,'138'!F33,'139'!F33,'140'!F33) -> 1.4896238 | G33: =AVERAGE('114'!G33,'115'!G33,'116'!G33,'117'!G33,'118'!G33,'119'!G33,'121'!G33,'122'!G33,'123'!G33,'124'!G33,'125'!G33,'126'!G33,'127'!G33,'128'!G33,'129'!G33,'130'!G33,'131'!G33,'138'!G33,'139'!G33,'140'!G33) -> 0.13095238 | H33: =AVERAGE('114'!H33,'115'!H33,'116'!H33,'117'!H33,'118'!H33,'119'!H33,'121'!H33,'122'!H33,'123'!H33,'124'!H33,'125'!H33,'126'!H33,'127'!H33,'128'!H33,'129'!H33,'130'!H33,'131'!H33,'138'!H33,'139'!H33,'140'!H33) -> 0.17867147 | I33: =AVERAGE('114'!I33,'115'!I33,'116'!I33,'117'!I33,'118'!I33,'119'!I33,'121'!I33,'122'!I33,'123'!I33,'124'!I33,'125'!I33,'126'!I33,'127'!I33,'128'!I33,'129'!I33,'130'!I33,'131'!I33,'138'!I33,'139'!I33,'140'!I33) -> 1.3255262 | J33: =AVERAGE('114'!J33,'115'!J33,'116'!J33,'117'!J33,'118'!J33,'119'!J33,'121'!J33,'122'!J33,'123'!J33,'124'!J33,'125'!J33,'126'!J33,'127'!J33,'128'!J33,'129'!J33,'130'!J33,'131'!J33,'138'!J33,'139'!J33,'140'!J33) -> 0.42005002 | ... P33: =AVERAGE('114'!P33,'115'!P33,'116'!P33,'117'!P33,'118'!P33,'119'!P33,'121'!P33,'122'!P33,'123'!P33,'124'!P33,'125'!P33,'126'!P33,'127'!P33,'128'!P33,'129'!P33,'130'!P33,'131'!P33,'138'!P33,'139'!P33,'140'!P33) -> 33.192729 | R33: 0600-0700 | S33: =SUM(C102:C105) -> 5.9910364 | T33: =SUM(D102:D105) -> 3.5172689 | U33: =SUM(E102:E105) -> 7.5332213 | V33: =SUM(F102:F105) -> 2.8640756 | W33: =SUM(G102:G105) -> 0.4460084 | X33: =SUM(H102:H105) -> 1.7753501 | Y33: =SUM(I102:I105) -> 3.422409 | Z33: =SUM(J102:J105) -> 1.3796919 | ... AF33: =SUM(P102:P105) -> 59.898529
