Workbook

Sheet ALL
B1: Consultancy services for Preparation of Expressway Development Master Plan (EDMP) for Uganda
B2: MANUAL CLASSIFIED COUNT (MCC)
B3: ROAD NAME: | C3: AVERAGE WEEK
C5: Date | D5: AVERAGE WEEK | F5: Location | G5: ='[1]Avg Week Munyonyo-Salama'!G5:H5 -> MUNYONYO P/S | J5: Surveyor
C6: Dir. From | D6: BOTH DIRECTIONS | F6: Dir. To | G6: BOTH DIRECTIONS | J6: Supervisor
B8: Time / Veh Type | R8: SUMMARY TRAFFIC VOLUMES
C9: 1. Car | D9: 2. Station Wagon | E9: 3. Pickups | F9: 4. Minibus, matatu | G9: 5. Medium bus | H9: 6. Large Bus | I9: 7. Light Truck | J9: 8. Medium Truck | K9: 9. Heavy truck | L9: 10. Truck Trailer | M9: 11. Motor cycles | N9: 12. Tractors | O9: Total Excl M/Cycles | P9: Total All | R9: Time | S9: 1. Car | T9: 2. Station Wagon | U9: 3. Pickups | V9: 4. Minibus, matatu | W9: 5. Medium bus | X9: 6. Large Bus | Y9: 7. Light Truck | Z9: 8. Medium Truck | AA9: 9. Heavy truck | AB9: 10. Truck Trailer | AC9: 11. Motorcycles | AD9: 12. Tractors, Graders | AE9: Total Excl M/ Cycles | AF9: Total All
B10: 07.00 - 07.15 | C10: =AVERAGE('51'!C10,'52'!C10,'53'!C10,'55'!C10,'56'!C10,'57'!C10,'58'!C10,'59A'!C10,'59'!C10,'60'!C10,'61'!C10,'62'!C10,'63'!C10,'64'!C10,'65'!C10,'66'!C10,'67'!C10,'68'!C10,'69'!C10,'70'!C10,'71'!C10,'72'!C10,'73'!C10,'74'!C10,'76'!C10,'77'!C10,) -> 38.703704 | D10: =AVERAGE('51'!D10,'52'!D10,'53'!D10,'55'!D10,'56'!D10,'57'!D10,'58'!D10,'59A'!D10,'59'!D10,'60'!D10,'61'!D10,'62'!D10,'63'!D10,'64'!D10,'65'!D10,'66'!D10,'67'!D10,'68'!D10,'69'!D10,'70'!D10,'71'!D10,'72'!D10,'73'!D10,'74'!D10,'76'!D10,'77'!D10,) -> 10.742196 | E10: =AVERAGE('51'!E10,'52'!E10,'53'!E10,'55'!E10,'56'!E10,'57'!E10,'58'!E10,'59A'!E10,'59'!E10,'60'!E10,'61'!E10,'62'!E10,'63'!E10,'64'!E10,'65'!E10,'66'!E10,'67'!E10,'68'!E10,'69'!E10,'70'!E10,'71'!E10,'72'!E10,'73'!E10,'74'!E10,'76'!E10,'77'!E10,) -> 6.3609788 | F10: =AVERAGE('51'!F10,'52'!F10,'53'!F10,'55'!F10,'56'!F10,'57'!F10,'58'!F10,'59A'!F10,'59'!F10,'60'!F10,'61'!F10,'62'!F10,'63'!F10,'64'!F10,'65'!F10,'66'!F10,'67'!F10,'68'!F10,'69'!F10,'70'!F10,'71'!F10,'72'!F10,'73'!F10,'74'!F10,'76'!F10,'77'!F10,) -> 19.156746 | G10: =AVERAGE('51'!G10,'52'!G10,'53'!G10,'55'!G10,'56'!G10,'57'!G10,'58'!G10,'59A'!G10,'59'!G10,'60'!G10,'61'!G10,'62'!G10,'63'!G10,'64'!G10,'65'!G10,'66'!G10,'67'!G10,'68'!G10,'69'!G10,'70'!G10,'71'!G10,'72'!G10,'73'!G10,'74'!G10,'76'!G10,'77'!G10,) -> 1.4001323 | H10: =AVERAGE('51'!H10,'52'!H10,'53'!H10,'55'!H10,'56'!H10,'57'!H10,'58'!H10,'59A'!H10,'59'!H10,'60'!H10,'61'!H10,'62'!H10,'63'!H10,'64'!H10,'65'!H10,'66'!H10,'67'!H10,'68'!H10,'69'!H10,'70'!H10,'71'!H10,'72'!H10,'73'!H10,'74'!H10,'76'!H10,'77'!H10,) -> 0.59060847 | I10: =AVERAGE('51'!I10,'52'!I10,'53'!I10,'55'!I10,'56'!I10,'57'!I10,'58'!I10,'59A'!I10,'59'!I10,'60'!I10,'61'!I10,'62'!I10,'63'!I10,'64'!I10,'65'!I10,'66'!I10,'67'!I10,'68'!I10,'69'!I10,'70'!I10,'71'!I10,'72'!I10,'73'!I10,'74'!I10,'76'!I10,'77'!I10,) -> 5.2698413 | J10: =AVERAGE('51'!J10,'52'!J10,'53'!J10,'55'!J10,'56'!J10,'57'!J10,'58'!J10,'59A'!J10,'59'!J10,'60'!J10,'61'!J10,'62'!J10,'63'!J10,'64'!J10,'65'!J10,'66'!J10,'67'!J10,'68'!J10,'69'!J10,'70'!J10,'71'!J10,'72'!J10,'73'!J10,'74'!J10,'76'!J10,'77'!J10,) -> 1.8619929 | ... P10: =AVERAGE('51'!P10,'52'!P10,'53'!P10,'55'!P10,'56'!P10,'57'!P10,'58'!P10,'59A'!P10,'59'!P10,'60'!P10,'61'!P10,'62'!P10,'63'!P10,'64'!P10,'65'!P10,'66'!P10,'67'!P10,'68'!P10,'69'!P10,'70'!P10,'71'!P10,'72'!P10,'73'!P10,'74'!P10,'76'!P10,'77'!P10,) -> 160.14175 | R10: 0700-0800 | S10: =SUM(C10:C13) -> 158.59656 | T10: =SUM(D10:D13) -> 45.049206 | U10: =SUM(E10:E13) -> 27.348942 | V10: =SUM(F10:F13) -> 85.299603 | W10: =SUM(G10:G13) -> 4.2374339 | X10: =SUM(H10:H13) -> 1.6448413 | Y10: =SUM(I10:I13) -> 24.21627 | Z10: =SUM(J10:J13) -> 7.8342152 | ... AF10: =SUM(P10:P13) -> 699.21583
B11: 07.15 - 07.30 | C11: =AVERAGE('51'!C11,'52'!C11,'53'!C11,'55'!C11,'56'!C11,'57'!C11,'58'!C11,'59A'!C11,'59'!C11,'60'!C11,'61'!C11,'62'!C11,'63'!C11,'64'!C11,'65'!C11,'66'!C11,'67'!C11,'68'!C11,'69'!C11,'70'!C11,'71'!C11,'72'!C11,'73'!C11,'74'!C11,'76'!C11,'77'!C11,) -> 39.074735 | D11: =AVERAGE('51'!D11,'52'!D11,'53'!D11,'55'!D11,'56'!D11,'57'!D11,'58'!D11,'59A'!D11,'59'!D11,'60'!D11,'61'!D11,'62'!D11,'63'!D11,'64'!D11,'65'!D11,'66'!D11,'67'!D11,'68'!D11,'69'!D11,'70'!D11,'71'!D11,'72'!D11,'73'!D11,'74'!D11,'76'!D11,'77'!D11,) -> 11.461376 | E11: =AVERAGE('51'!E11,'52'!E11,'53'!E11,'55'!E11,'56'!E11,'57'!E11,'58'!E11,'59A'!E11,'59'!E11,'60'!E11,'61'!E11,'62'!E11,'63'!E11,'64'!E11,'65'!E11,'66'!E11,'67'!E11,'68'!E11,'69'!E11,'70'!E11,'71'!E11,'72'!E11,'73'!E11,'74'!E11,'76'!E11,'77'!E11,) -> 6.7039683 | F11: =AVERAGE('51'!F11,'52'!F11,'53'!F11,'55'!F11,'56'!F11,'57'!F11,'58'!F11,'59A'!F11,'59'!F11,'60'!F11,'61'!F11,'62'!F11,'63'!F11,'64'!F11,'65'!F11,'66'!F11,'67'!F11,'68'!F11,'69'!F11,'70'!F11,'71'!F11,'72'!F11,'73'!F11,'74'!F11,'76'!F11,'77'!F11,) -> 21.710979 | G11: =AVERAGE('51'!G11,'52'!G11,'53'!G11,'55'!G11,'56'!G11,'57'!G11,'58'!G11,'59A'!G11,'59'!G11,'60'!G11,'61'!G11,'62'!G11,'63'!G11,'64'!G11,'65'!G11,'66'!G11,'67'!G11,'68'!G11,'69'!G11,'70'!G11,'71'!G11,'72'!G11,'73'!G11,'74'!G11,'76'!G11,'77'!G11,) -> 1.0568783 | H11: =AVERAGE('51'!H11,'52'!H11,'53'!H11,'55'!H11,'56'!H11,'57'!H11,'58'!H11,'59A'!H11,'59'!H11,'60'!H11,'61'!H11,'62'!H11,'63'!H11,'64'!H11,'65'!H11,'66'!H11,'67'!H11,'68'!H11,'69'!H11,'70'!H11,'71'!H11,'72'!H11,'73'!H11,'74'!H11,'76'!H11,'77'!H11,) -> 0.31878307 | I11: =AVERAGE('51'!I11,'52'!I11,'53'!I11,'55'!I11,'56'!I11,'57'!I11,'58'!I11,'59A'!I11,'59'!I11,'60'!I11,'61'!I11,'62'!I11,'63'!I11,'64'!I11,'65'!I11,'66'!I11,'67'!I11,'68'!I11,'69'!I11,'70'!I11,'71'!I11,'72'!I11,'73'!I11,'74'!I11,'76'!I11,'77'!I11,) -> 6.0152116 | J11: =AVERAGE('51'!J11,'52'!J11,'53'!J11,'55'!J11,'56'!J11,'57'!J11,'58'!J11,'59A'!J11,'59'!J11,'60'!J11,'61'!J11,'62'!J11,'63'!J11,'64'!J11,'65'!J11,'66'!J11,'67'!J11,'68'!J11,'69'!J11,'70'!J11,'71'!J11,'72'!J11,'73'!J11,'74'!J11,'76'!J11,'77'!J11,) -> 1.7837302 | ... P11: =AVERAGE('51'!P11,'52'!P11,'53'!P11,'55'!P11,'56'!P11,'57'!P11,'58'!P11,'59A'!P11,'59'!P11,'60'!P11,'61'!P11,'62'!P11,'63'!P11,'64'!P11,'65'!P11,'66'!P11,'67'!P11,'68'!P11,'69'!P11,'70'!P11,'71'!P11,'72'!P11,'73'!P11,'74'!P11,'76'!P11,'77'!P11,) -> 172.04696 | R11: 0800-0900 | S11: =SUM(C14:C17) -> 156.53638 | T11: =SUM(D14:D17) -> 49.068122 | U11: =SUM(E14:E17) -> 30.416005 | V11: =SUM(F14:F17) -> 90.459656 | W11: =SUM(G14:G17) -> 3.5833333 | X11: =SUM(H14:H17) -> 1.7513228 | Y11: =SUM(I14:I17) -> 28.537698 | Z11: =SUM(J14:J17) -> 8.7480159 | ... AF11: =SUM(P14:P17) -> 744.8578
B12: 07.30 - 07.45 | C12: =AVERAGE('51'!C12,'52'!C12,'53'!C12,'55'!C12,'56'!C12,'57'!C12,'58'!C12,'59A'!C12,'59'!C12,'60'!C12,'61'!C12,'62'!C12,'63'!C12,'64'!C12,'65'!C12,'66'!C12,'67'!C12,'68'!C12,'69'!C12,'70'!C12,'71'!C12,'72'!C12,'73'!C12,'74'!C12,'76'!C12,'77'!C12,) -> 40.03836 | D12: =AVERAGE('51'!D12,'52'!D12,'53'!D12,'55'!D12,'56'!D12,'57'!D12,'58'!D12,'59A'!D12,'59'!D12,'60'!D12,'61'!D12,'62'!D12,'63'!D12,'64'!D12,'65'!D12,'66'!D12,'67'!D12,'68'!D12,'69'!D12,'70'!D12,'71'!D12,'72'!D12,'73'!D12,'74'!D12,'76'!D12,'77'!D12,) -> 11.367857 | E12: =AVERAGE('51'!E12,'52'!E12,'53'!E12,'55'!E12,'56'!E12,'57'!E12,'58'!E12,'59A'!E12,'59'!E12,'60'!E12,'61'!E12,'62'!E12,'63'!E12,'64'!E12,'65'!E12,'66'!E12,'67'!E12,'68'!E12,'69'!E12,'70'!E12,'71'!E12,'72'!E12,'73'!E12,'74'!E12,'76'!E12,'77'!E12,) -> 7.0951058 | F12: =AVERAGE('51'!F12,'52'!F12,'53'!F12,'55'!F12,'56'!F12,'57'!F12,'58'!F12,'59A'!F12,'59'!F12,'60'!F12,'61'!F12,'62'!F12,'63'!F12,'64'!F12,'65'!F12,'66'!F12,'67'!F12,'68'!F12,'69'!F12,'70'!F12,'71'!F12,'72'!F12,'73'!F12,'74'!F12,'76'!F12,'77'!F12,) -> 23.005291 | G12: =AVERAGE('51'!G12,'52'!G12,'53'!G12,'55'!G12,'56'!G12,'57'!G12,'58'!G12,'59A'!G12,'59'!G12,'60'!G12,'61'!G12,'62'!G12,'63'!G12,'64'!G12,'65'!G12,'66'!G12,'67'!G12,'68'!G12,'69'!G12,'70'!G12,'71'!G12,'72'!G12,'73'!G12,'74'!G12,'76'!G12,'77'!G12,) -> 0.93055556 | H12: =AVERAGE('51'!H12,'52'!H12,'53'!H12,'55'!H12,'56'!H12,'57'!H12,'58'!H12,'59A'!H12,'59'!H12,'60'!H12,'61'!H12,'62'!H12,'63'!H12,'64'!H12,'65'!H12,'66'!H12,'67'!H12,'68'!H12,'69'!H12,'70'!H12,'71'!H12,'72'!H12,'73'!H12,'74'!H12,'76'!H12,'77'!H12,) -> 0.39351852 | I12: =AVERAGE('51'!I12,'52'!I12,'53'!I12,'55'!I12,'56'!I12,'57'!I12,'58'!I12,'59A'!I12,'59'!I12,'60'!I12,'61'!I12,'62'!I12,'63'!I12,'64'!I12,'65'!I12,'66'!I12,'67'!I12,'68'!I12,'69'!I12,'70'!I12,'71'!I12,'72'!I12,'73'!I12,'74'!I12,'76'!I12,'77'!I12,) -> 6.1269841 | J12: =AVERAGE('51'!J12,'52'!J12,'53'!J12,'55'!J12,'56'!J12,'57'!J12,'58'!J12,'59A'!J12,'59'!J12,'60'!J12,'61'!J12,'62'!J12,'63'!J12,'64'!J12,'65'!J12,'66'!J12,'67'!J12,'68'!J12,'69'!J12,'70'!J12,'71'!J12,'72'!J12,'73'!J12,'74'!J12,'76'!J12,'77'!J12,) -> 2.0753968 | ... P12: =AVERAGE('51'!P12,'52'!P12,'53'!P12,'55'!P12,'56'!P12,'57'!P12,'58'!P12,'59A'!P12,'59'!P12,'60'!P12,'61'!P12,'62'!P12,'63'!P12,'64'!P12,'65'!P12,'66'!P12,'67'!P12,'68'!P12,'69'!P12,'70'!P12,'71'!P12,'72'!P12,'73'!P12,'74'!P12,'76'!P12,'77'!P12,) -> 181.60384 | R12: 0900-1000 | S12: =SUM(C18:C21) -> 154.71362 | T12: =SUM(D18:D21) -> 48.227116 | U12: =SUM(E18:E21) -> 30.387302 | V12: =SUM(F18:F21) -> 88.618386 | W12: =SUM(G18:G21) -> 3.4589947 | X12: =SUM(H18:H21) -> 1.6944444 | Y12: =SUM(I18:I21) -> 32.943122 | Z12: =SUM(J18:J21) -> 10.278439 | ... AF12: =SUM(P18:P21) -> 734.33377
B13: 07.45 - 08.00 | C13: =AVERAGE('51'!C13,'52'!C13,'53'!C13,'55'!C13,'56'!C13,'57'!C13,'58'!C13,'59A'!C13,'59'!C13,'60'!C13,'61'!C13,'62'!C13,'63'!C13,'64'!C13,'65'!C13,'66'!C13,'67'!C13,'68'!C13,'69'!C13,'70'!C13,'71'!C13,'72'!C13,'73'!C13,'74'!C13,'76'!C13,'77'!C13,) -> 40.779762 | D13: =AVERAGE('51'!D13,'52'!D13,'53'!D13,'55'!D13,'56'!D13,'57'!D13,'58'!D13,'59A'!D13,'59'!D13,'60'!D13,'61'!D13,'62'!D13,'63'!D13,'64'!D13,'65'!D13,'66'!D13,'67'!D13,'68'!D13,'69'!D13,'70'!D13,'71'!D13,'72'!D13,'73'!D13,'74'!D13,'76'!D13,'77'!D13,) -> 11.477778 | E13: =AVERAGE('51'!E13,'52'!E13,'53'!E13,'55'!E13,'56'!E13,'57'!E13,'58'!E13,'59A'!E13,'59'!E13,'60'!E13,'61'!E13,'62'!E13,'63'!E13,'64'!E13,'65'!E13,'66'!E13,'67'!E13,'68'!E13,'69'!E13,'70'!E13,'71'!E13,'72'!E13,'73'!E13,'74'!E13,'76'!E13,'77'!E13,) -> 7.1888889 | F13: =AVERAGE('51'!F13,'52'!F13,'53'!F13,'55'!F13,'56'!F13,'57'!F13,'58'!F13,'59A'!F13,'59'!F13,'60'!F13,'61'!F13,'62'!F13,'63'!F13,'64'!F13,'65'!F13,'66'!F13,'67'!F13,'68'!F13,'69'!F13,'70'!F13,'71'!F13,'72'!F13,'73'!F13,'74'!F13,'76'!F13,'77'!F13,) -> 21.426587 | G13: =AVERAGE('51'!G13,'52'!G13,'53'!G13,'55'!G13,'56'!G13,'57'!G13,'58'!G13,'59A'!G13,'59'!G13,'60'!G13,'61'!G13,'62'!G13,'63'!G13,'64'!G13,'65'!G13,'66'!G13,'67'!G13,'68'!G13,'69'!G13,'70'!G13,'71'!G13,'72'!G13,'73'!G13,'74'!G13,'76'!G13,'77'!G13,) -> 0.84986772 | H13: =AVERAGE('51'!H13,'52'!H13,'53'!H13,'55'!H13,'56'!H13,'57'!H13,'58'!H13,'59A'!H13,'59'!H13,'60'!H13,'61'!H13,'62'!H13,'63'!H13,'64'!H13,'65'!H13,'66'!H13,'67'!H13,'68'!H13,'69'!H13,'70'!H13,'71'!H13,'72'!H13,'73'!H13,'74'!H13,'76'!H13,'77'!H13,) -> 0.34193122 | I13: =AVERAGE('51'!I13,'52'!I13,'53'!I13,'55'!I13,'56'!I13,'57'!I13,'58'!I13,'59A'!I13,'59'!I13,'60'!I13,'61'!I13,'62'!I13,'63'!I13,'64'!I13,'65'!I13,'66'!I13,'67'!I13,'68'!I13,'69'!I13,'70'!I13,'71'!I13,'72'!I13,'73'!I13,'74'!I13,'76'!I13,'77'!I13,) -> 6.8042328 | J13: =AVERAGE('51'!J13,'52'!J13,'53'!J13,'55'!J13,'56'!J13,'57'!J13,'58'!J13,'59A'!J13,'59'!J13,'60'!J13,'61'!J13,'62'!J13,'63'!J13,'64'!J13,'65'!J13,'66'!J13,'67'!J13,'68'!J13,'69'!J13,'70'!J13,'71'!J13,'72'!J13,'73'!J13,'74'!J13,'76'!J13,'77'!J13,) -> 2.1130952 | ... P13: =AVERAGE('51'!P13,'52'!P13,'53'!P13,'55'!P13,'56'!P13,'57'!P13,'58'!P13,'59A'!P13,'59'!P13,'60'!P13,'61'!P13,'62'!P13,'63'!P13,'64'!P13,'65'!P13,'66'!P13,'67'!P13,'68'!P13,'69'!P13,'70'!P13,'71'!P13,'72'!P13,'73'!P13,'74'!P13,'76'!P13,'77'!P13,) -> 185.42328 | R13: 1000-1100 | S13: =SUM(C22:C25) -> 161.68849 | T13: =SUM(D22:D25) -> 49.641005 | U13: =SUM(E22:E25) -> 30.542196 | V13: =SUM(F22:F25) -> 87.653439 | W13: =SUM(G22:G25) -> 3.9464286 | X13: =SUM(H22:H25) -> 1.5965608 | Y13: =SUM(I22:I25) -> 36.58664 | Z13: =SUM(J22:J25) -> 11.573413 | ... AF13: =SUM(P22:P25) -> 731.49206
B14: 08.00 - 08.15 | C14: =AVERAGE('51'!C14,'52'!C14,'53'!C14,'55'!C14,'56'!C14,'57'!C14,'58'!C14,'59A'!C14,'59'!C14,'60'!C14,'61'!C14,'62'!C14,'63'!C14,'64'!C14,'65'!C14,'66'!C14,'67'!C14,'68'!C14,'69'!C14,'70'!C14,'71'!C14,'72'!C14,'73'!C14,'74'!C14,'76'!C14,'77'!C14,) -> 39.714286 | D14: =AVERAGE('51'!D14,'52'!D14,'53'!D14,'55'!D14,'56'!D14,'57'!D14,'58'!D14,'59A'!D14,'59'!D14,'60'!D14,'61'!D14,'62'!D14,'63'!D14,'64'!D14,'65'!D14,'66'!D14,'67'!D14,'68'!D14,'69'!D14,'70'!D14,'71'!D14,'72'!D14,'73'!D14,'74'!D14,'76'!D14,'77'!D14,) -> 12.15172 | E14: =AVERAGE('51'!E14,'52'!E14,'53'!E14,'55'!E14,'56'!E14,'57'!E14,'58'!E14,'59A'!E14,'59'!E14,'60'!E14,'61'!E14,'62'!E14,'63'!E14,'64'!E14,'65'!E14,'66'!E14,'67'!E14,'68'!E14,'69'!E14,'70'!E14,'71'!E14,'72'!E14,'73'!E14,'74'!E14,'76'!E14,'77'!E14,) -> 7.7768519 | F14: =AVERAGE('51'!F14,'52'!F14,'53'!F14,'55'!F14,'56'!F14,'57'!F14,'58'!F14,'59A'!F14,'59'!F14,'60'!F14,'61'!F14,'62'!F14,'63'!F14,'64'!F14,'65'!F14,'66'!F14,'67'!F14,'68'!F14,'69'!F14,'70'!F14,'71'!F14,'72'!F14,'73'!F14,'74'!F14,'76'!F14,'77'!F14,) -> 23.690476 | G14: =AVERAGE('51'!G14,'52'!G14,'53'!G14,'55'!G14,'56'!G14,'57'!G14,'58'!G14,'59A'!G14,'59'!G14,'60'!G14,'61'!G14,'62'!G14,'63'!G14,'64'!G14,'65'!G14,'66'!G14,'67'!G14,'68'!G14,'69'!G14,'70'!G14,'71'!G14,'72'!G14,'73'!G14,'74'!G14,'76'!G14,'77'!G14,) -> 0.92328042 | H14: =AVERAGE('51'!H14,'52'!H14,'53'!H14,'55'!H14,'56'!H14,'57'!H14,'58'!H14,'59A'!H14,'59'!H14,'60'!H14,'61'!H14,'62'!H14,'63'!H14,'64'!H14,'65'!H14,'66'!H14,'67'!H14,'68'!H14,'69'!H14,'70'!H14,'71'!H14,'72'!H14,'73'!H14,'74'!H14,'76'!H14,'77'!H14,) -> 0.5297619 | I14: =AVERAGE('51'!I14,'52'!I14,'53'!I14,'55'!I14,'56'!I14,'57'!I14,'58'!I14,'59A'!I14,'59'!I14,'60'!I14,'61'!I14,'62'!I14,'63'!I14,'64'!I14,'65'!I14,'66'!I14,'67'!I14,'68'!I14,'69'!I14,'70'!I14,'71'!I14,'72'!I14,'73'!I14,'74'!I14,'76'!I14,'77'!I14,) -> 7.3009259 | J14: =AVERAGE('51'!J14,'52'!J14,'53'!J14,'55'!J14,'56'!J14,'57'!J14,'58'!J14,'59A'!J14,'59'!J14,'60'!J14,'61'!J14,'62'!J14,'63'!J14,'64'!J14,'65'!J14,'66'!J14,'67'!J14,'68'!J14,'69'!J14,'70'!J14,'71'!J14,'72'!J14,'73'!J14,'74'!J14,'76'!J14,'77'!J14,) -> 2.1415344 | ... P14: =AVERAGE('51'!P14,'52'!P14,'53'!P14,'55'!P14,'56'!P14,'57'!P14,'58'!P14,'59A'!P14,'59'!P14,'60'!P14,'61'!P14,'62'!P14,'63'!P14,'64'!P14,'65'!P14,'66'!P14,'67'!P14,'68'!P14,'69'!P14,'70'!P14,'71'!P14,'72'!P14,'73'!P14,'74'!P14,'76'!P14,'77'!P14,) -> 189.58929 | R14: 1100-1200 | S14: =SUM(C26:C29) -> 162.44312 | T14: =SUM(D26:D29) -> 48.938624 | U14: =SUM(E26:E29) -> 31.244577 | V14: =SUM(F26:F29) -> 87.888007 | W14: =SUM(G26:G29) -> 3.0575397 | X14: =SUM(H26:H29) -> 1.3928571 | Y14: =SUM(I26:I29) -> 39.343915 | Z14: =SUM(J26:J29) -> 12.12037 | ... AF14: =SUM(P26:P29) -> 724.77756
B15: 08.15 - 08.30 | C15: =AVERAGE('51'!C15,'52'!C15,'53'!C15,'55'!C15,'56'!C15,'57'!C15,'58'!C15,'59A'!C15,'59'!C15,'60'!C15,'61'!C15,'62'!C15,'63'!C15,'64'!C15,'65'!C15,'66'!C15,'67'!C15,'68'!C15,'69'!C15,'70'!C15,'71'!C15,'72'!C15,'73'!C15,'74'!C15,'76'!C15,'77'!C15,) -> 37.818783 | D15: =AVERAGE('51'!D15,'52'!D15,'53'!D15,'55'!D15,'56'!D15,'57'!D15,'58'!D15,'59A'!D15,'59'!D15,'60'!D15,'61'!D15,'62'!D15,'63'!D15,'64'!D15,'65'!D15,'66'!D15,'67'!D15,'68'!D15,'69'!D15,'70'!D15,'71'!D15,'72'!D15,'73'!D15,'74'!D15,'76'!D15,'77'!D15,) -> 11.964286 | E15: =AVERAGE('51'!E15,'52'!E15,'53'!E15,'55'!E15,'56'!E15,'57'!E15,'58'!E15,'59A'!E15,'59'!E15,'60'!E15,'61'!E15,'62'!E15,'63'!E15,'64'!E15,'65'!E15,'66'!E15,'67'!E15,'68'!E15,'69'!E15,'70'!E15,'71'!E15,'72'!E15,'73'!E15,'74'!E15,'76'!E15,'77'!E15,) -> 7.0780423 | F15: =AVERAGE('51'!F15,'52'!F15,'53'!F15,'55'!F15,'56'!F15,'57'!F15,'58'!F15,'59A'!F15,'59'!F15,'60'!F15,'61'!F15,'62'!F15,'63'!F15,'64'!F15,'65'!F15,'66'!F15,'67'!F15,'68'!F15,'69'!F15,'70'!F15,'71'!F15,'72'!F15,'73'!F15,'74'!F15,'76'!F15,'77'!F15,) -> 23.453704 | G15: =AVERAGE('51'!G15,'52'!G15,'53'!G15,'55'!G15,'56'!G15,'57'!G15,'58'!G15,'59A'!G15,'59'!G15,'60'!G15,'61'!G15,'62'!G15,'63'!G15,'64'!G15,'65'!G15,'66'!G15,'67'!G15,'68'!G15,'69'!G15,'70'!G15,'71'!G15,'72'!G15,'73'!G15,'74'!G15,'76'!G15,'77'!G15,) -> 0.78968254 | H15: =AVERAGE('51'!H15,'52'!H15,'53'!H15,'55'!H15,'56'!H15,'57'!H15,'58'!H15,'59A'!H15,'59'!H15,'60'!H15,'61'!H15,'62'!H15,'63'!H15,'64'!H15,'65'!H15,'66'!H15,'67'!H15,'68'!H15,'69'!H15,'70'!H15,'71'!H15,'72'!H15,'73'!H15,'74'!H15,'76'!H15,'77'!H15,) -> 0.34259259 | I15: =AVERAGE('51'!I15,'52'!I15,'53'!I15,'55'!I15,'56'!I15,'57'!I15,'58'!I15,'59A'!I15,'59'!I15,'60'!I15,'61'!I15,'62'!I15,'63'!I15,'64'!I15,'65'!I15,'66'!I15,'67'!I15,'68'!I15,'69'!I15,'70'!I15,'71'!I15,'72'!I15,'73'!I15,'74'!I15,'76'!I15,'77'!I15,) -> 6.9146825 | J15: =AVERAGE('51'!J15,'52'!J15,'53'!J15,'55'!J15,'56'!J15,'57'!J15,'58'!J15,'59A'!J15,'59'!J15,'60'!J15,'61'!J15,'62'!J15,'63'!J15,'64'!J15,'65'!J15,'66'!J15,'67'!J15,'68'!J15,'69'!J15,'70'!J15,'71'!J15,'72'!J15,'73'!J15,'74'!J15,'76'!J15,'77'!J15,) -> 2.0694444 | ... P15: =AVERAGE('51'!P15,'52'!P15,'53'!P15,'55'!P15,'56'!P15,'57'!P15,'58'!P15,'59A'!P15,'59'!P15,'60'!P15,'61'!P15,'62'!P15,'63'!P15,'64'!P15,'65'!P15,'66'!P15,'67'!P15,'68'!P15,'69'!P15,'70'!P15,'71'!P15,'72'!P15,'73'!P15,'74'!P15,'76'!P15,'77'!P15,) -> 183.8373 | R15: 1200-1300 | S15: =SUM(C30:C33) -> 164.39815 | T15: =SUM(D30:D33) -> 49.397928 | U15: =SUM(E30:E33) -> 33.191799 | V15: =SUM(F30:F33) -> 87.722222 | W15: =SUM(G30:G33) -> 3.8134921 | X15: =SUM(H30:H33) -> 2.0469577 | Y15: =SUM(I30:I33) -> 40.268519 | Z15: =SUM(J30:J33) -> 13.614198 | ... AF15: =SUM(P30:P33) -> 703.37522
B16: 08.30 - 08.45 | C16: =AVERAGE('51'!C16,'52'!C16,'53'!C16,'55'!C16,'56'!C16,'57'!C16,'58'!C16,'59A'!C16,'59'!C16,'60'!C16,'61'!C16,'62'!C16,'63'!C16,'64'!C16,'65'!C16,'66'!C16,'67'!C16,'68'!C16,'69'!C16,'70'!C16,'71'!C16,'72'!C16,'73'!C16,'74'!C16,'76'!C16,'77'!C16,) -> 38.584656 | D16: =AVERAGE('51'!D16,'52'!D16,'53'!D16,'55'!D16,'56'!D16,'57'!D16,'58'!D16,'59A'!D16,'59'!D16,'60'!D16,'61'!D16,'62'!D16,'63'!D16,'64'!D16,'65'!D16,'66'!D16,'67'!D16,'68'!D16,'69'!D16,'70'!D16,'71'!D16,'72'!D16,'73'!D16,'74'!D16,'76'!D16,'77'!D16,) -> 12.576455 | E16: =AVERAGE('51'!E16,'52'!E16,'53'!E16,'55'!E16,'56'!E16,'57'!E16,'58'!E16,'59A'!E16,'59'!E16,'60'!E16,'61'!E16,'62'!E16,'63'!E16,'64'!E16,'65'!E16,'66'!E16,'67'!E16,'68'!E16,'69'!E16,'70'!E16,'71'!E16,'72'!E16,'73'!E16,'74'!E16,'76'!E16,'77'!E16,) -> 7.4070106 | F16: =AVERAGE('51'!F16,'52'!F16,'53'!F16,'55'!F16,'56'!F16,'57'!F16,'58'!F16,'59A'!F16,'59'!F16,'60'!F16,'61'!F16,'62'!F16,'63'!F16,'64'!F16,'65'!F16,'66'!F16,'67'!F16,'68'!F16,'69'!F16,'70'!F16,'71'!F16,'72'!F16,'73'!F16,'74'!F16,'76'!F16,'77'!F16,) -> 21.65873 | G16: =AVERAGE('51'!G16,'52'!G16,'53'!G16,'55'!G16,'56'!G16,'57'!G16,'58'!G16,'59A'!G16,'59'!G16,'60'!G16,'61'!G16,'62'!G16,'63'!G16,'64'!G16,'65'!G16,'66'!G16,'67'!G16,'68'!G16,'69'!G16,'70'!G16,'71'!G16,'72'!G16,'73'!G16,'74'!G16,'76'!G16,'77'!G16,) -> 1.0205026 | H16: =AVERAGE('51'!H16,'52'!H16,'53'!H16,'55'!H16,'56'!H16,'57'!H16,'58'!H16,'59A'!H16,'59'!H16,'60'!H16,'61'!H16,'62'!H16,'63'!H16,'64'!H16,'65'!H16,'66'!H16,'67'!H16,'68'!H16,'69'!H16,'70'!H16,'71'!H16,'72'!H16,'73'!H16,'74'!H16,'76'!H16,'77'!H16,) -> 0.51388889 | I16: =AVERAGE('51'!I16,'52'!I16,'53'!I16,'55'!I16,'56'!I16,'57'!I16,'58'!I16,'59A'!I16,'59'!I16,'60'!I16,'61'!I16,'62'!I16,'63'!I16,'64'!I16,'65'!I16,'66'!I16,'67'!I16,'68'!I16,'69'!I16,'70'!I16,'71'!I16,'72'!I16,'73'!I16,'74'!I16,'76'!I16,'77'!I16,) -> 7.2010582 | J16: =AVERAGE('51'!J16,'52'!J16,'53'!J16,'55'!J16,'56'!J16,'57'!J16,'58'!J16,'59A'!J16,'59'!J16,'60'!J16,'61'!J16,'62'!J16,'63'!J16,'64'!J16,'65'!J16,'66'!J16,'67'!J16,'68'!J16,'69'!J16,'70'!J16,'71'!J16,'72'!J16,'73'!J16,'74'!J16,'76'!J16,'77'!J16,) -> 2.2982804 | ... P16: =AVERAGE('51'!P16,'52'!P16,'53'!P16,'55'!P16,'56'!P16,'57'!P16,'58'!P16,'59A'!P16,'59'!P16,'60'!P16,'61'!P16,'62'!P16,'63'!P16,'64'!P16,'65'!P16,'66'!P16,'67'!P16,'68'!P16,'69'!P16,'70'!P16,'71'!P16,'72'!P16,'73'!P16,'74'!P16,'76'!P16,'77'!P16,) -> 186.11508 | R16: 1300-1400 | S16: =SUM(C34:C37) -> 158.21892 | T16: =SUM(D34:D37) -> 49.710317 | U16: =SUM(E34:E37) -> 32.294312 | V16: =SUM(F34:F37) -> 85.30291 | W16: =SUM(G34:G37) -> 3.1468254 | X16: =SUM(H34:H37) -> 1.8968254 | Y16: =SUM(I34:I37) -> 39.665344 | Z16: =SUM(J34:J37) -> 12.744709 | ... AF16: =SUM(P34:P37) -> 669.25595
B17: 08.45 - 9.00 | C17: =AVERAGE('51'!C17,'52'!C17,'53'!C17,'55'!C17,'56'!C17,'57'!C17,'58'!C17,'59A'!C17,'59'!C17,'60'!C17,'61'!C17,'62'!C17,'63'!C17,'64'!C17,'65'!C17,'66'!C17,'67'!C17,'68'!C17,'69'!C17,'70'!C17,'71'!C17,'72'!C17,'73'!C17,'74'!C17,'76'!C17,'77'!C17,) -> 40.418651 | D17: =AVERAGE('51'!D17,'52'!D17,'53'!D17,'55'!D17,'56'!D17,'57'!D17,'58'!D17,'59A'!D17,'59'!D17,'60'!D17,'61'!D17,'62'!D17,'63'!D17,'64'!D17,'65'!D17,'66'!D17,'67'!D17,'68'!D17,'69'!D17,'70'!D17,'71'!D17,'72'!D17,'73'!D17,'74'!D17,'76'!D17,'77'!D17,) -> 12.375661 | E17: =AVERAGE('51'!E17,'52'!E17,'53'!E17,'55'!E17,'56'!E17,'57'!E17,'58'!E17,'59A'!E17,'59'!E17,'60'!E17,'61'!E17,'62'!E17,'63'!E17,'64'!E17,'65'!E17,'66'!E17,'67'!E17,'68'!E17,'69'!E17,'70'!E17,'71'!E17,'72'!E17,'73'!E17,'74'!E17,'76'!E17,'77'!E17,) -> 8.1541005 | F17: =AVERAGE('51'!F17,'52'!F17,'53'!F17,'55'!F17,'56'!F17,'57'!F17,'58'!F17,'59A'!F17,'59'!F17,'60'!F17,'61'!F17,'62'!F17,'63'!F17,'64'!F17,'65'!F17,'66'!F17,'67'!F17,'68'!F17,'69'!F17,'70'!F17,'71'!F17,'72'!F17,'73'!F17,'74'!F17,'76'!F17,'77'!F17,) -> 21.656746 | G17: =AVERAGE('51'!G17,'52'!G17,'53'!G17,'55'!G17,'56'!G17,'57'!G17,'58'!G17,'59A'!G17,'59'!G17,'60'!G17,'61'!G17,'62'!G17,'63'!G17,'64'!G17,'65'!G17,'66'!G17,'67'!G17,'68'!G17,'69'!G17,'70'!G17,'71'!G17,'72'!G17,'73'!G17,'74'!G17,'76'!G17,'77'!G17,) -> 0.84986772 | H17: =AVERAGE('51'!H17,'52'!H17,'53'!H17,'55'!H17,'56'!H17,'57'!H17,'58'!H17,'59A'!H17,'59'!H17,'60'!H17,'61'!H17,'62'!H17,'63'!H17,'64'!H17,'65'!H17,'66'!H17,'67'!H17,'68'!H17,'69'!H17,'70'!H17,'71'!H17,'72'!H17,'73'!H17,'74'!H17,'76'!H17,'77'!H17,) -> 0.36507937 | I17: =AVERAGE('51'!I17,'52'!I17,'53'!I17,'55'!I17,'56'!I17,'57'!I17,'58'!I17,'59A'!I17,'59'!I17,'60'!I17,'61'!I17,'62'!I17,'63'!I17,'64'!I17,'65'!I17,'66'!I17,'67'!I17,'68'!I17,'69'!I17,'70'!I17,'71'!I17,'72'!I17,'73'!I17,'74'!I17,'76'!I17,'77'!I17,) -> 7.1210317 | J17: =AVERAGE('51'!J17,'52'!J17,'53'!J17,'55'!J17,'56'!J17,'57'!J17,'58'!J17,'59A'!J17,'59'!J17,'60'!J17,'61'!J17,'62'!J17,'63'!J17,'64'!J17,'65'!J17,'66'!J17,'67'!J17,'68'!J17,'69'!J17,'70'!J17,'71'!J17,'72'!J17,'73'!J17,'74'!J17,'76'!J17,'77'!J17,) -> 2.2387566 | ... P17: =AVERAGE('51'!P17,'52'!P17,'53'!P17,'55'!P17,'56'!P17,'57'!P17,'58'!P17,'59A'!P17,'59'!P17,'60'!P17,'61'!P17,'62'!P17,'63'!P17,'64'!P17,'65'!P17,'66'!P17,'67'!P17,'68'!P17,'69'!P17,'70'!P17,'71'!P17,'72'!P17,'73'!P17,'74'!P17,'76'!P17,'77'!P17,) -> 185.31614 | R17: 1400-1500 | S17: =SUM(C38:C41) -> 171.97487 | T17: =SUM(D38:D41) -> 52.96045 | U17: =SUM(E38:E41) -> 33.088492 | V17: =SUM(F38:F41) -> 87.449735 | W17: =SUM(G38:G41) -> 3.8048942 | X17: =SUM(H38:H41) -> 1.7116402 | Y17: =SUM(I38:I41) -> 40.431217 | Z17: =SUM(J38:J41) -> 13.151455 | ... AF17: =SUM(P38:P41) -> 681.74735
B18: 09.00 - 09.15 | C18: =AVERAGE('51'!C18,'52'!C18,'53'!C18,'55'!C18,'56'!C18,'57'!C18,'58'!C18,'59A'!C18,'59'!C18,'60'!C18,'61'!C18,'62'!C18,'63'!C18,'64'!C18,'65'!C18,'66'!C18,'67'!C18,'68'!C18,'69'!C18,'70'!C18,'71'!C18,'72'!C18,'73'!C18,'74'!C18,'76'!C18,'77'!C18,) -> 39.762566 | D18: =AVERAGE('51'!D18,'52'!D18,'53'!D18,'55'!D18,'56'!D18,'57'!D18,'58'!D18,'59A'!D18,'59'!D18,'60'!D18,'61'!D18,'62'!D18,'63'!D18,'64'!D18,'65'!D18,'66'!D18,'67'!D18,'68'!D18,'69'!D18,'70'!D18,'71'!D18,'72'!D18,'73'!D18,'74'!D18,'76'!D18,'77'!D18,) -> 12.14828 | E18: =AVERAGE('51'!E18,'52'!E18,'53'!E18,'55'!E18,'56'!E18,'57'!E18,'58'!E18,'59A'!E18,'59'!E18,'60'!E18,'61'!E18,'62'!E18,'63'!E18,'64'!E18,'65'!E18,'66'!E18,'67'!E18,'68'!E18,'69'!E18,'70'!E18,'71'!E18,'72'!E18,'73'!E18,'74'!E18,'76'!E18,'77'!E18,) -> 7.7029101 | F18: =AVERAGE('51'!F18,'52'!F18,'53'!F18,'55'!F18,'56'!F18,'57'!F18,'58'!F18,'59A'!F18,'59'!F18,'60'!F18,'61'!F18,'62'!F18,'63'!F18,'64'!F18,'65'!F18,'66'!F18,'67'!F18,'68'!F18,'69'!F18,'70'!F18,'71'!F18,'72'!F18,'73'!F18,'74'!F18,'76'!F18,'77'!F18,) -> 23.202381 | G18: =AVERAGE('51'!G18,'52'!G18,'53'!G18,'55'!G18,'56'!G18,'57'!G18,'58'!G18,'59A'!G18,'59'!G18,'60'!G18,'61'!G18,'62'!G18,'63'!G18,'64'!G18,'65'!G18,'66'!G18,'67'!G18,'68'!G18,'69'!G18,'70'!G18,'71'!G18,'72'!G18,'73'!G18,'74'!G18,'76'!G18,'77'!G18,) -> 0.88955026 | H18: =AVERAGE('51'!H18,'52'!H18,'53'!H18,'55'!H18,'56'!H18,'57'!H18,'58'!H18,'59A'!H18,'59'!H18,'60'!H18,'61'!H18,'62'!H18,'63'!H18,'64'!H18,'65'!H18,'66'!H18,'67'!H18,'68'!H18,'69'!H18,'70'!H18,'71'!H18,'72'!H18,'73'!H18,'74'!H18,'76'!H18,'77'!H18,) -> 0.45436508 | I18: =AVERAGE('51'!I18,'52'!I18,'53'!I18,'55'!I18,'56'!I18,'57'!I18,'58'!I18,'59A'!I18,'59'!I18,'60'!I18,'61'!I18,'62'!I18,'63'!I18,'64'!I18,'65'!I18,'66'!I18,'67'!I18,'68'!I18,'69'!I18,'70'!I18,'71'!I18,'72'!I18,'73'!I18,'74'!I18,'76'!I18,'77'!I18,) -> 7.8928571 | J18: =AVERAGE('51'!J18,'52'!J18,'53'!J18,'55'!J18,'56'!J18,'57'!J18,'58'!J18,'59A'!J18,'59'!J18,'60'!J18,'61'!J18,'62'!J18,'63'!J18,'64'!J18,'65'!J18,'66'!J18,'67'!J18,'68'!J18,'69'!J18,'70'!J18,'71'!J18,'72'!J18,'73'!J18,'74'!J18,'76'!J18,'77'!J18,) -> 2.4378307 | ... P18: =AVERAGE('51'!P18,'52'!P18,'53'!P18,'55'!P18,'56'!P18,'57'!P18,'58'!P18,'59A'!P18,'59'!P18,'60'!P18,'61'!P18,'62'!P18,'63'!P18,'64'!P18,'65'!P18,'66'!P18,'67'!P18,'68'!P18,'69'!P18,'70'!P18,'71'!P18,'72'!P18,'73'!P18,'74'!P18,'76'!P18,'77'!P18,) -> 187.48589 | R18: 1500-1600 | S18: =SUM(C42:C45) -> 186.43871 | T18: =SUM(D42:D45) -> 52.482407 | U18: =SUM(E42:E45) -> 33.688228 | V18: =SUM(F42:F45) -> 84.978175 | W18: =SUM(G42:G45) -> 2.9484127 | X18: =SUM(H42:H45) -> 2.0787037 | Y18: =SUM(I42:I45) -> 39.412037 | Z18: =SUM(J42:J45) -> 13.12037 | ... AF18: =SUM(P42:P45) -> 700.88668
B19: 09.15 - 09.30 | C19: =AVERAGE('51'!C19,'52'!C19,'53'!C19,'55'!C19,'56'!C19,'57'!C19,'58'!C19,'59A'!C19,'59'!C19,'60'!C19,'61'!C19,'62'!C19,'63'!C19,'64'!C19,'65'!C19,'66'!C19,'67'!C19,'68'!C19,'69'!C19,'70'!C19,'71'!C19,'72'!C19,'73'!C19,'74'!C19,'76'!C19,'77'!C19,) -> 38.724206 | D19: =AVERAGE('51'!D19,'52'!D19,'53'!D19,'55'!D19,'56'!D19,'57'!D19,'58'!D19,'59A'!D19,'59'!D19,'60'!D19,'61'!D19,'62'!D19,'63'!D19,'64'!D19,'65'!D19,'66'!D19,'67'!D19,'68'!D19,'69'!D19,'70'!D19,'71'!D19,'72'!D19,'73'!D19,'74'!D19,'76'!D19,'77'!D19,) -> 11.793915 | E19: =AVERAGE('51'!E19,'52'!E19,'53'!E19,'55'!E19,'56'!E19,'57'!E19,'58'!E19,'59A'!E19,'59'!E19,'60'!E19,'61'!E19,'62'!E19,'63'!E19,'64'!E19,'65'!E19,'66'!E19,'67'!E19,'68'!E19,'69'!E19,'70'!E19,'71'!E19,'72'!E19,'73'!E19,'74'!E19,'76'!E19,'77'!E19,) -> 7.3965608 | F19: =AVERAGE('51'!F19,'52'!F19,'53'!F19,'55'!F19,'56'!F19,'57'!F19,'58'!F19,'59A'!F19,'59'!F19,'60'!F19,'61'!F19,'62'!F19,'63'!F19,'64'!F19,'65'!F19,'66'!F19,'67'!F19,'68'!F19,'69'!F19,'70'!F19,'71'!F19,'72'!F19,'73'!F19,'74'!F19,'76'!F19,'77'!F19,) -> 21.935847 | G19: =AVERAGE('51'!G19,'52'!G19,'53'!G19,'55'!G19,'56'!G19,'57'!G19,'58'!G19,'59A'!G19,'59'!G19,'60'!G19,'61'!G19,'62'!G19,'63'!G19,'64'!G19,'65'!G19,'66'!G19,'67'!G19,'68'!G19,'69'!G19,'70'!G19,'71'!G19,'72'!G19,'73'!G19,'74'!G19,'76'!G19,'77'!G19,) -> 0.79563492 | H19: =AVERAGE('51'!H19,'52'!H19,'53'!H19,'55'!H19,'56'!H19,'57'!H19,'58'!H19,'59A'!H19,'59'!H19,'60'!H19,'61'!H19,'62'!H19,'63'!H19,'64'!H19,'65'!H19,'66'!H19,'67'!H19,'68'!H19,'69'!H19,'70'!H19,'71'!H19,'72'!H19,'73'!H19,'74'!H19,'76'!H19,'77'!H19,) -> 0.35978836 | I19: =AVERAGE('51'!I19,'52'!I19,'53'!I19,'55'!I19,'56'!I19,'57'!I19,'58'!I19,'59A'!I19,'59'!I19,'60'!I19,'61'!I19,'62'!I19,'63'!I19,'64'!I19,'65'!I19,'66'!I19,'67'!I19,'68'!I19,'69'!I19,'70'!I19,'71'!I19,'72'!I19,'73'!I19,'74'!I19,'76'!I19,'77'!I19,) -> 7.8148148 | J19: =AVERAGE('51'!J19,'52'!J19,'53'!J19,'55'!J19,'56'!J19,'57'!J19,'58'!J19,'59A'!J19,'59'!J19,'60'!J19,'61'!J19,'62'!J19,'63'!J19,'64'!J19,'65'!J19,'66'!J19,'67'!J19,'68'!J19,'69'!J19,'70'!J19,'71'!J19,'72'!J19,'73'!J19,'74'!J19,'76'!J19,'77'!J19,) -> 2.4708995 | ... P19: =AVERAGE('51'!P19,'52'!P19,'53'!P19,'55'!P19,'56'!P19,'57'!P19,'58'!P19,'59A'!P19,'59'!P19,'60'!P19,'61'!P19,'62'!P19,'63'!P19,'64'!P19,'65'!P19,'66'!P19,'67'!P19,'68'!P19,'69'!P19,'70'!P19,'71'!P19,'72'!P19,'73'!P19,'74'!P19,'76'!P19,'77'!P19,) -> 181.55556 | R19: 1600-1700 | S19: =SUM(C46:C49) -> 189.29233 | T19: =SUM(D46:D49) -> 61.376455 | U19: =SUM(E46:E49) -> 38.089153 | V19: =SUM(F46:F49) -> 91.558862 | W19: =SUM(G46:G49) -> 4.662037 | X19: =SUM(H46:H49) -> 2.4986772 | Y19: =SUM(I46:I49) -> 40.017857 | Z19: =SUM(J46:J49) -> 11.917328 | ... AF19: =SUM(P46:P49) -> 756.38492
B20: 09.30 - 09.45 | C20: =AVERAGE('51'!C20,'52'!C20,'53'!C20,'55'!C20,'56'!C20,'57'!C20,'58'!C20,'59A'!C20,'59'!C20,'60'!C20,'61'!C20,'62'!C20,'63'!C20,'64'!C20,'65'!C20,'66'!C20,'67'!C20,'68'!C20,'69'!C20,'70'!C20,'71'!C20,'72'!C20,'73'!C20,'74'!C20,'76'!C20,'77'!C20,) -> 37.867725 | D20: =AVERAGE('51'!D20,'52'!D20,'53'!D20,'55'!D20,'56'!D20,'57'!D20,'58'!D20,'59A'!D20,'59'!D20,'60'!D20,'61'!D20,'62'!D20,'63'!D20,'64'!D20,'65'!D20,'66'!D20,'67'!D20,'68'!D20,'69'!D20,'70'!D20,'71'!D20,'72'!D20,'73'!D20,'74'!D20,'76'!D20,'77'!D20,) -> 11.819048 | E20: =AVERAGE('51'!E20,'52'!E20,'53'!E20,'55'!E20,'56'!E20,'57'!E20,'58'!E20,'59A'!E20,'59'!E20,'60'!E20,'61'!E20,'62'!E20,'63'!E20,'64'!E20,'65'!E20,'66'!E20,'67'!E20,'68'!E20,'69'!E20,'70'!E20,'71'!E20,'72'!E20,'73'!E20,'74'!E20,'76'!E20,'77'!E20,) -> 7.8026455 | F20: =AVERAGE('51'!F20,'52'!F20,'53'!F20,'55'!F20,'56'!F20,'57'!F20,'58'!F20,'59A'!F20,'59'!F20,'60'!F20,'61'!F20,'62'!F20,'63'!F20,'64'!F20,'65'!F20,'66'!F20,'67'!F20,'68'!F20,'69'!F20,'70'!F20,'71'!F20,'72'!F20,'73'!F20,'74'!F20,'76'!F20,'77'!F20,) -> 21.308862 | G20: =AVERAGE('51'!G20,'52'!G20,'53'!G20,'55'!G20,'56'!G20,'57'!G20,'58'!G20,'59A'!G20,'59'!G20,'60'!G20,'61'!G20,'62'!G20,'63'!G20,'64'!G20,'65'!G20,'66'!G20,'67'!G20,'68'!G20,'69'!G20,'70'!G20,'71'!G20,'72'!G20,'73'!G20,'74'!G20,'76'!G20,'77'!G20,) -> 0.85449735 | H20: =AVERAGE('51'!H20,'52'!H20,'53'!H20,'55'!H20,'56'!H20,'57'!H20,'58'!H20,'59A'!H20,'59'!H20,'60'!H20,'61'!H20,'62'!H20,'63'!H20,'64'!H20,'65'!H20,'66'!H20,'67'!H20,'68'!H20,'69'!H20,'70'!H20,'71'!H20,'72'!H20,'73'!H20,'74'!H20,'76'!H20,'77'!H20,) -> 0.41071429 | I20: =AVERAGE('51'!I20,'52'!I20,'53'!I20,'55'!I20,'56'!I20,'57'!I20,'58'!I20,'59A'!I20,'59'!I20,'60'!I20,'61'!I20,'62'!I20,'63'!I20,'64'!I20,'65'!I20,'66'!I20,'67'!I20,'68'!I20,'69'!I20,'70'!I20,'71'!I20,'72'!I20,'73'!I20,'74'!I20,'76'!I20,'77'!I20,) -> 8.3247354 | J20: =AVERAGE('51'!J20,'52'!J20,'53'!J20,'55'!J20,'56'!J20,'57'!J20,'58'!J20,'59A'!J20,'59'!J20,'60'!J20,'61'!J20,'62'!J20,'63'!J20,'64'!J20,'65'!J20,'66'!J20,'67'!J20,'68'!J20,'69'!J20,'70'!J20,'71'!J20,'72'!J20,'73'!J20,'74'!J20,'76'!J20,'77'!J20,) -> 2.6970899 | ... P20: =AVERAGE('51'!P20,'52'!P20,'53'!P20,'55'!P20,'56'!P20,'57'!P20,'58'!P20,'59A'!P20,'59'!P20,'60'!P20,'61'!P20,'62'!P20,'63'!P20,'64'!P20,'65'!P20,'66'!P20,'67'!P20,'68'!P20,'69'!P20,'70'!P20,'71'!P20,'72'!P20,'73'!P20,'74'!P20,'76'!P20,'77'!P20,) -> 182.20172 | R20: 1700-1800 | S20: =SUM(C50:C53) -> 208.35119 | T20: =SUM(D50:D53) -> 64.313757 | U20: =SUM(E50:E53) -> 39.302646 | V20: =SUM(F50:F53) -> 103.19709 | W20: =SUM(G50:G53) -> 6.1130952 | X20: =SUM(H50:H53) -> 2.5165344 | Y20: =SUM(I50:I53) -> 38.278439 | Z20: =SUM(J50:J53) -> 12.056878 | ... AF20: =SUM(P50:P53) -> 812.70701
B21: 09.45 - 10.00 | C21: =AVERAGE('51'!C21,'52'!C21,'53'!C21,'55'!C21,'56'!C21,'57'!C21,'58'!C21,'59A'!C21,'59'!C21,'60'!C21,'61'!C21,'62'!C21,'63'!C21,'64'!C21,'65'!C21,'66'!C21,'67'!C21,'68'!C21,'69'!C21,'70'!C21,'71'!C21,'72'!C21,'73'!C21,'74'!C21,'76'!C21,'77'!C21,) -> 38.359127 | D21: =AVERAGE('51'!D21,'52'!D21,'53'!D21,'55'!D21,'56'!D21,'57'!D21,'58'!D21,'59A'!D21,'59'!D21,'60'!D21,'61'!D21,'62'!D21,'63'!D21,'64'!D21,'65'!D21,'66'!D21,'67'!D21,'68'!D21,'69'!D21,'70'!D21,'71'!D21,'72'!D21,'73'!D21,'74'!D21,'76'!D21,'77'!D21,) -> 12.465873 | E21: =AVERAGE('51'!E21,'52'!E21,'53'!E21,'55'!E21,'56'!E21,'57'!E21,'58'!E21,'59A'!E21,'59'!E21,'60'!E21,'61'!E21,'62'!E21,'63'!E21,'64'!E21,'65'!E21,'66'!E21,'67'!E21,'68'!E21,'69'!E21,'70'!E21,'71'!E21,'72'!E21,'73'!E21,'74'!E21,'76'!E21,'77'!E21,) -> 7.4851852 | F21: =AVERAGE('51'!F21,'52'!F21,'53'!F21,'55'!F21,'56'!F21,'57'!F21,'58'!F21,'59A'!F21,'59'!F21,'60'!F21,'61'!F21,'62'!F21,'63'!F21,'64'!F21,'65'!F21,'66'!F21,'67'!F21,'68'!F21,'69'!F21,'70'!F21,'71'!F21,'72'!F21,'73'!F21,'74'!F21,'76'!F21,'77'!F21,) -> 22.171296 | G21: =AVERAGE('51'!G21,'52'!G21,'53'!G21,'55'!G21,'56'!G21,'57'!G21,'58'!G21,'59A'!G21,'59'!G21,'60'!G21,'61'!G21,'62'!G21,'63'!G21,'64'!G21,'65'!G21,'66'!G21,'67'!G21,'68'!G21,'69'!G21,'70'!G21,'71'!G21,'72'!G21,'73'!G21,'74'!G21,'76'!G21,'77'!G21,) -> 0.91931217 | H21: =AVERAGE('51'!H21,'52'!H21,'53'!H21,'55'!H21,'56'!H21,'57'!H21,'58'!H21,'59A'!H21,'59'!H21,'60'!H21,'61'!H21,'62'!H21,'63'!H21,'64'!H21,'65'!H21,'66'!H21,'67'!H21,'68'!H21,'69'!H21,'70'!H21,'71'!H21,'72'!H21,'73'!H21,'74'!H21,'76'!H21,'77'!H21,) -> 0.46957672 | I21: =AVERAGE('51'!I21,'52'!I21,'53'!I21,'55'!I21,'56'!I21,'57'!I21,'58'!I21,'59A'!I21,'59'!I21,'60'!I21,'61'!I21,'62'!I21,'63'!I21,'64'!I21,'65'!I21,'66'!I21,'67'!I21,'68'!I21,'69'!I21,'70'!I21,'71'!I21,'72'!I21,'73'!I21,'74'!I21,'76'!I21,'77'!I21,) -> 8.9107143 | J21: =AVERAGE('51'!J21,'52'!J21,'53'!J21,'55'!J21,'56'!J21,'57'!J21,'58'!J21,'59A'!J21,'59'!J21,'60'!J21,'61'!J21,'62'!J21,'63'!J21,'64'!J21,'65'!J21,'66'!J21,'67'!J21,'68'!J21,'69'!J21,'70'!J21,'71'!J21,'72'!J21,'73'!J21,'74'!J21,'76'!J21,'77'!J21,) -> 2.672619 | ... P21: =AVERAGE('51'!P21,'52'!P21,'53'!P21,'55'!P21,'56'!P21,'57'!P21,'58'!P21,'59A'!P21,'59'!P21,'60'!P21,'61'!P21,'62'!P21,'63'!P21,'64'!P21,'65'!P21,'66'!P21,'67'!P21,'68'!P21,'69'!P21,'70'!P21,'71'!P21,'72'!P21,'73'!P21,'74'!P21,'76'!P21,'77'!P21,) -> 183.09061 | R21: 1800-1900 | S21: =SUM(C54:C57) -> 219.00728 | T21: =SUM(D54:D57) -> 63.396825 | U21: =SUM(E54:E57) -> 40.894841 | V21: =SUM(F54:F57) -> 105.71032 | W21: =SUM(G54:G57) -> 7.0425485 | X21: =SUM(H54:H57) -> 2.5806878 | Y21: =SUM(I54:I57) -> 35.710979 | Z21: =SUM(J54:J57) -> 12.115741 | ... AF21: =SUM(P54:P57) -> 848.5119
B22: 10.00 - 10.15 | C22: =AVERAGE('51'!C22,'52'!C22,'53'!C22,'55'!C22,'56'!C22,'57'!C22,'58'!C22,'59A'!C22,'59'!C22,'60'!C22,'61'!C22,'62'!C22,'63'!C22,'64'!C22,'65'!C22,'66'!C22,'67'!C22,'68'!C22,'69'!C22,'70'!C22,'71'!C22,'72'!C22,'73'!C22,'74'!C22,'76'!C22,'77'!C22,) -> 40.07209 | D22: =AVERAGE('51'!D22,'52'!D22,'53'!D22,'55'!D22,'56'!D22,'57'!D22,'58'!D22,'59A'!D22,'59'!D22,'60'!D22,'61'!D22,'62'!D22,'63'!D22,'64'!D22,'65'!D22,'66'!D22,'67'!D22,'68'!D22,'69'!D22,'70'!D22,'71'!D22,'72'!D22,'73'!D22,'74'!D22,'76'!D22,'77'!D22,) -> 12.105688 | E22: =AVERAGE('51'!E22,'52'!E22,'53'!E22,'55'!E22,'56'!E22,'57'!E22,'58'!E22,'59A'!E22,'59'!E22,'60'!E22,'61'!E22,'62'!E22,'63'!E22,'64'!E22,'65'!E22,'66'!E22,'67'!E22,'68'!E22,'69'!E22,'70'!E22,'71'!E22,'72'!E22,'73'!E22,'74'!E22,'76'!E22,'77'!E22,) -> 7.5543651 | F22: =AVERAGE('51'!F22,'52'!F22,'53'!F22,'55'!F22,'56'!F22,'57'!F22,'58'!F22,'59A'!F22,'59'!F22,'60'!F22,'61'!F22,'62'!F22,'63'!F22,'64'!F22,'65'!F22,'66'!F22,'67'!F22,'68'!F22,'69'!F22,'70'!F22,'71'!F22,'72'!F22,'73'!F22,'74'!F22,'76'!F22,'77'!F22,) -> 21.773148 | G22: =AVERAGE('51'!G22,'52'!G22,'53'!G22,'55'!G22,'56'!G22,'57'!G22,'58'!G22,'59A'!G22,'59'!G22,'60'!G22,'61'!G22,'62'!G22,'63'!G22,'64'!G22,'65'!G22,'66'!G22,'67'!G22,'68'!G22,'69'!G22,'70'!G22,'71'!G22,'72'!G22,'73'!G22,'74'!G22,'76'!G22,'77'!G22,) -> 0.84193122 | H22: =AVERAGE('51'!H22,'52'!H22,'53'!H22,'55'!H22,'56'!H22,'57'!H22,'58'!H22,'59A'!H22,'59'!H22,'60'!H22,'61'!H22,'62'!H22,'63'!H22,'64'!H22,'65'!H22,'66'!H22,'67'!H22,'68'!H22,'69'!H22,'70'!H22,'71'!H22,'72'!H22,'73'!H22,'74'!H22,'76'!H22,'77'!H22,) -> 0.45833333 | I22: =AVERAGE('51'!I22,'52'!I22,'53'!I22,'55'!I22,'56'!I22,'57'!I22,'58'!I22,'59A'!I22,'59'!I22,'60'!I22,'61'!I22,'62'!I22,'63'!I22,'64'!I22,'65'!I22,'66'!I22,'67'!I22,'68'!I22,'69'!I22,'70'!I22,'71'!I22,'72'!I22,'73'!I22,'74'!I22,'76'!I22,'77'!I22,) -> 8.8353175 | J22: =AVERAGE('51'!J22,'52'!J22,'53'!J22,'55'!J22,'56'!J22,'57'!J22,'58'!J22,'59A'!J22,'59'!J22,'60'!J22,'61'!J22,'62'!J22,'63'!J22,'64'!J22,'65'!J22,'66'!J22,'67'!J22,'68'!J22,'69'!J22,'70'!J22,'71'!J22,'72'!J22,'73'!J22,'74'!J22,'76'!J22,'77'!J22,) -> 2.603836 | ... P22: =AVERAGE('51'!P22,'52'!P22,'53'!P22,'55'!P22,'56'!P22,'57'!P22,'58'!P22,'59A'!P22,'59'!P22,'60'!P22,'61'!P22,'62'!P22,'63'!P22,'64'!P22,'65'!P22,'66'!P22,'67'!P22,'68'!P22,'69'!P22,'70'!P22,'71'!P22,'72'!P22,'73'!P22,'74'!P22,'76'!P22,'77'!P22,) -> 181.25198 | R22: 1900-2000 | S22: =SUM(C58:C61) -> 183.63956 | T22: =SUM(D58:D61) -> 60.071347 | U22: =SUM(E58:E61) -> 35.468131 | V22: =SUM(F58:F61) -> 87.185287 | W22: =SUM(G58:G61) -> 5.3482068 | X22: =SUM(H58:H61) -> 3.3870664 | Y22: =SUM(I58:I61) -> 32.215484 | Z22: =SUM(J58:J61) -> 12.520709 | ... AF22: =SUM(P58:P61) -> 761.54082
B23: 10.15 - 10.30 | C23: =AVERAGE('51'!C23,'52'!C23,'53'!C23,'55'!C23,'56'!C23,'57'!C23,'58'!C23,'59A'!C23,'59'!C23,'60'!C23,'61'!C23,'62'!C23,'63'!C23,'64'!C23,'65'!C23,'66'!C23,'67'!C23,'68'!C23,'69'!C23,'70'!C23,'71'!C23,'72'!C23,'73'!C23,'74'!C23,'76'!C23,'77'!C23,) -> 39.781746 | D23: =AVERAGE('51'!D23,'52'!D23,'53'!D23,'55'!D23,'56'!D23,'57'!D23,'58'!D23,'59A'!D23,'59'!D23,'60'!D23,'61'!D23,'62'!D23,'63'!D23,'64'!D23,'65'!D23,'66'!D23,'67'!D23,'68'!D23,'69'!D23,'70'!D23,'71'!D23,'72'!D23,'73'!D23,'74'!D23,'76'!D23,'77'!D23,) -> 12.868122 | E23: =AVERAGE('51'!E23,'52'!E23,'53'!E23,'55'!E23,'56'!E23,'57'!E23,'58'!E23,'59A'!E23,'59'!E23,'60'!E23,'61'!E23,'62'!E23,'63'!E23,'64'!E23,'65'!E23,'66'!E23,'67'!E23,'68'!E23,'69'!E23,'70'!E23,'71'!E23,'72'!E23,'73'!E23,'74'!E23,'76'!E23,'77'!E23,) -> 7.4519841 | F23: =AVERAGE('51'!F23,'52'!F23,'53'!F23,'55'!F23,'56'!F23,'57'!F23,'58'!F23,'59A'!F23,'59'!F23,'60'!F23,'61'!F23,'62'!F23,'63'!F23,'64'!F23,'65'!F23,'66'!F23,'67'!F23,'68'!F23,'69'!F23,'70'!F23,'71'!F23,'72'!F23,'73'!F23,'74'!F23,'76'!F23,'77'!F23,) -> 21.779101 | G23: =AVERAGE('51'!G23,'52'!G23,'53'!G23,'55'!G23,'56'!G23,'57'!G23,'58'!G23,'59A'!G23,'59'!G23,'60'!G23,'61'!G23,'62'!G23,'63'!G23,'64'!G23,'65'!G23,'66'!G23,'67'!G23,'68'!G23,'69'!G23,'70'!G23,'71'!G23,'72'!G23,'73'!G23,'74'!G23,'76'!G23,'77'!G23,) -> 1.2619048 | H23: =AVERAGE('51'!H23,'52'!H23,'53'!H23,'55'!H23,'56'!H23,'57'!H23,'58'!H23,'59A'!H23,'59'!H23,'60'!H23,'61'!H23,'62'!H23,'63'!H23,'64'!H23,'65'!H23,'66'!H23,'67'!H23,'68'!H23,'69'!H23,'70'!H23,'71'!H23,'72'!H23,'73'!H23,'74'!H23,'76'!H23,'77'!H23,) -> 0.37830688 | I23: =AVERAGE('51'!I23,'52'!I23,'53'!I23,'55'!I23,'56'!I23,'57'!I23,'58'!I23,'59A'!I23,'59'!I23,'60'!I23,'61'!I23,'62'!I23,'63'!I23,'64'!I23,'65'!I23,'66'!I23,'67'!I23,'68'!I23,'69'!I23,'70'!I23,'71'!I23,'72'!I23,'73'!I23,'74'!I23,'76'!I23,'77'!I23,) -> 9.1296296 | J23: =AVERAGE('51'!J23,'52'!J23,'53'!J23,'55'!J23,'56'!J23,'57'!J23,'58'!J23,'59A'!J23,'59'!J23,'60'!J23,'61'!J23,'62'!J23,'63'!J23,'64'!J23,'65'!J23,'66'!J23,'67'!J23,'68'!J23,'69'!J23,'70'!J23,'71'!J23,'72'!J23,'73'!J23,'74'!J23,'76'!J23,'77'!J23,) -> 2.7301587 | ... P23: =AVERAGE('51'!P23,'52'!P23,'53'!P23,'55'!P23,'56'!P23,'57'!P23,'58'!P23,'59A'!P23,'59'!P23,'60'!P23,'61'!P23,'62'!P23,'63'!P23,'64'!P23,'65'!P23,'66'!P23,'67'!P23,'68'!P23,'69'!P23,'70'!P23,'71'!P23,'72'!P23,'73'!P23,'74'!P23,'76'!P23,'77'!P23,) -> 183.2381 | R23: 2000-2100 | S23: =SUM(C62:C65) -> 175.50779 | T23: =SUM(D62:D65) -> 53.195679 | U23: =SUM(E62:E65) -> 31.386111 | V23: =SUM(F62:F65) -> 86.325304 | W23: =SUM(G62:G65) -> 5.1063958 | X23: =SUM(H62:H65) -> 2.2032507 | Y23: =SUM(I62:I65) -> 28.849907 | Z23: =SUM(J62:J65) -> 10.819521 | ... AF23: =SUM(P62:P65) -> 706.89486
B24: 10.30 - 10.45 | C24: =AVERAGE('51'!C24,'52'!C24,'53'!C24,'55'!C24,'56'!C24,'57'!C24,'58'!C24,'59A'!C24,'59'!C24,'60'!C24,'61'!C24,'62'!C24,'63'!C24,'64'!C24,'65'!C24,'66'!C24,'67'!C24,'68'!C24,'69'!C24,'70'!C24,'71'!C24,'72'!C24,'73'!C24,'74'!C24,'76'!C24,'77'!C24,) -> 41.444444 | D24: =AVERAGE('51'!D24,'52'!D24,'53'!D24,'55'!D24,'56'!D24,'57'!D24,'58'!D24,'59A'!D24,'59'!D24,'60'!D24,'61'!D24,'62'!D24,'63'!D24,'64'!D24,'65'!D24,'66'!D24,'67'!D24,'68'!D24,'69'!D24,'70'!D24,'71'!D24,'72'!D24,'73'!D24,'74'!D24,'76'!D24,'77'!D24,) -> 12.861772 | E24: =AVERAGE('51'!E24,'52'!E24,'53'!E24,'55'!E24,'56'!E24,'57'!E24,'58'!E24,'59A'!E24,'59'!E24,'60'!E24,'61'!E24,'62'!E24,'63'!E24,'64'!E24,'65'!E24,'66'!E24,'67'!E24,'68'!E24,'69'!E24,'70'!E24,'71'!E24,'72'!E24,'73'!E24,'74'!E24,'76'!E24,'77'!E24,) -> 8.0720899 | F24: =AVERAGE('51'!F24,'52'!F24,'53'!F24,'55'!F24,'56'!F24,'57'!F24,'58'!F24,'59A'!F24,'59'!F24,'60'!F24,'61'!F24,'62'!F24,'63'!F24,'64'!F24,'65'!F24,'66'!F24,'67'!F24,'68'!F24,'69'!F24,'70'!F24,'71'!F24,'72'!F24,'73'!F24,'74'!F24,'76'!F24,'77'!F24,) -> 22.17791 | G24: =AVERAGE('51'!G24,'52'!G24,'53'!G24,'55'!G24,'56'!G24,'57'!G24,'58'!G24,'59A'!G24,'59'!G24,'60'!G24,'61'!G24,'62'!G24,'63'!G24,'64'!G24,'65'!G24,'66'!G24,'67'!G24,'68'!G24,'69'!G24,'70'!G24,'71'!G24,'72'!G24,'73'!G24,'74'!G24,'76'!G24,'77'!G24,) -> 1.0390212 | H24: =AVERAGE('51'!H24,'52'!H24,'53'!H24,'55'!H24,'56'!H24,'57'!H24,'58'!H24,'59A'!H24,'59'!H24,'60'!H24,'61'!H24,'62'!H24,'63'!H24,'64'!H24,'65'!H24,'66'!H24,'67'!H24,'68'!H24,'69'!H24,'70'!H24,'71'!H24,'72'!H24,'73'!H24,'74'!H24,'76'!H24,'77'!H24,) -> 0.32275132 | I24: =AVERAGE('51'!I24,'52'!I24,'53'!I24,'55'!I24,'56'!I24,'57'!I24,'58'!I24,'59A'!I24,'59'!I24,'60'!I24,'61'!I24,'62'!I24,'63'!I24,'64'!I24,'65'!I24,'66'!I24,'67'!I24,'68'!I24,'69'!I24,'70'!I24,'71'!I24,'72'!I24,'73'!I24,'74'!I24,'76'!I24,'77'!I24,) -> 9.0582011 | J24: =AVERAGE('51'!J24,'52'!J24,'53'!J24,'55'!J24,'56'!J24,'57'!J24,'58'!J24,'59A'!J24,'59'!J24,'60'!J24,'61'!J24,'62'!J24,'63'!J24,'64'!J24,'65'!J24,'66'!J24,'67'!J24,'68'!J24,'69'!J24,'70'!J24,'71'!J24,'72'!J24,'73'!J24,'74'!J24,'76'!J24,'77'!J24,) -> 3.2771164 | ... P24: =AVERAGE('51'!P24,'52'!P24,'53'!P24,'55'!P24,'56'!P24,'57'!P24,'58'!P24,'59A'!P24,'59'!P24,'60'!P24,'61'!P24,'62'!P24,'63'!P24,'64'!P24,'65'!P24,'66'!P24,'67'!P24,'68'!P24,'69'!P24,'70'!P24,'71'!P24,'72'!P24,'73'!P24,'74'!P24,'76'!P24,'77'!P24,) -> 184.59788 | R24: 2100-2200 | S24: =SUM(C66:C69) -> 153.88981 | T24: =SUM(D66:D69) -> 46.723057 | U24: =SUM(E66:E69) -> 27.103105 | V24: =SUM(F66:F69) -> 77.406674 | W24: =SUM(G66:G69) -> 4.7261762 | X24: =SUM(H66:H69) -> 3.4156531 | Y24: =SUM(I66:I69) -> 25.549168 | Z24: =SUM(J66:J69) -> 10.689926 | ... AF24: =SUM(P66:P69) -> 602.61824
B25: 10.45 - 11.00 | C25: =AVERAGE('51'!C25,'52'!C25,'53'!C25,'55'!C25,'56'!C25,'57'!C25,'58'!C25,'59A'!C25,'59'!C25,'60'!C25,'61'!C25,'62'!C25,'63'!C25,'64'!C25,'65'!C25,'66'!C25,'67'!C25,'68'!C25,'69'!C25,'70'!C25,'71'!C25,'72'!C25,'73'!C25,'74'!C25,'76'!C25,'77'!C25,) -> 40.390212 | D25: =AVERAGE('51'!D25,'52'!D25,'53'!D25,'55'!D25,'56'!D25,'57'!D25,'58'!D25,'59A'!D25,'59'!D25,'60'!D25,'61'!D25,'62'!D25,'63'!D25,'64'!D25,'65'!D25,'66'!D25,'67'!D25,'68'!D25,'69'!D25,'70'!D25,'71'!D25,'72'!D25,'73'!D25,'74'!D25,'76'!D25,'77'!D25,) -> 11.805423 | E25: =AVERAGE('51'!E25,'52'!E25,'53'!E25,'55'!E25,'56'!E25,'57'!E25,'58'!E25,'59A'!E25,'59'!E25,'60'!E25,'61'!E25,'62'!E25,'63'!E25,'64'!E25,'65'!E25,'66'!E25,'67'!E25,'68'!E25,'69'!E25,'70'!E25,'71'!E25,'72'!E25,'73'!E25,'74'!E25,'76'!E25,'77'!E25,) -> 7.4637566 | F25: =AVERAGE('51'!F25,'52'!F25,'53'!F25,'55'!F25,'56'!F25,'57'!F25,'58'!F25,'59A'!F25,'59'!F25,'60'!F25,'61'!F25,'62'!F25,'63'!F25,'64'!F25,'65'!F25,'66'!F25,'67'!F25,'68'!F25,'69'!F25,'70'!F25,'71'!F25,'72'!F25,'73'!F25,'74'!F25,'76'!F25,'77'!F25,) -> 21.92328 | G25: =AVERAGE('51'!G25,'52'!G25,'53'!G25,'55'!G25,'56'!G25,'57'!G25,'58'!G25,'59A'!G25,'59'!G25,'60'!G25,'61'!G25,'62'!G25,'63'!G25,'64'!G25,'65'!G25,'66'!G25,'67'!G25,'68'!G25,'69'!G25,'70'!G25,'71'!G25,'72'!G25,'73'!G25,'74'!G25,'76'!G25,'77'!G25,) -> 0.80357143 | H25: =AVERAGE('51'!H25,'52'!H25,'53'!H25,'55'!H25,'56'!H25,'57'!H25,'58'!H25,'59A'!H25,'59'!H25,'60'!H25,'61'!H25,'62'!H25,'63'!H25,'64'!H25,'65'!H25,'66'!H25,'67'!H25,'68'!H25,'69'!H25,'70'!H25,'71'!H25,'72'!H25,'73'!H25,'74'!H25,'76'!H25,'77'!H25,) -> 0.43716931 | I25: =AVERAGE('51'!I25,'52'!I25,'53'!I25,'55'!I25,'56'!I25,'57'!I25,'58'!I25,'59A'!I25,'59'!I25,'60'!I25,'61'!I25,'62'!I25,'63'!I25,'64'!I25,'65'!I25,'66'!I25,'67'!I25,'68'!I25,'69'!I25,'70'!I25,'71'!I25,'72'!I25,'73'!I25,'74'!I25,'76'!I25,'77'!I25,) -> 9.5634921 | J25: =AVERAGE('51'!J25,'52'!J25,'53'!J25,'55'!J25,'56'!J25,'57'!J25,'58'!J25,'59A'!J25,'59'!J25,'60'!J25,'61'!J25,'62'!J25,'63'!J25,'64'!J25,'65'!J25,'66'!J25,'67'!J25,'68'!J25,'69'!J25,'70'!J25,'71'!J25,'72'!J25,'73'!J25,'74'!J25,'76'!J25,'77'!J25,) -> 2.9623016 | ... P25: =AVERAGE('51'!P25,'52'!P25,'53'!P25,'55'!P25,'56'!P25,'57'!P25,'58'!P25,'59A'!P25,'59'!P25,'60'!P25,'61'!P25,'62'!P25,'63'!P25,'64'!P25,'65'!P25,'66'!P25,'67'!P25,'68'!P25,'69'!P25,'70'!P25,'71'!P25,'72'!P25,'73'!P25,'74'!P25,'76'!P25,'77'!P25,) -> 182.4041 | R25: 2200-2300 | S25: =SUM(C70:C73) -> 124.57799 | T25: =SUM(D70:D73) -> 40.370525 | U25: =SUM(E70:E73) -> 20.352084 | V25: =SUM(F70:F73) -> 61.407763 | W25: =SUM(G70:G73) -> 3.9195205 | X25: =SUM(H70:H73) -> 2.5801306 | Y25: =SUM(I70:I73) -> 19.337158 | Z25: =SUM(J70:J73) -> 9.0605891 | ... AF25: =SUM(P70:P73) -> 476.44421
B26: 11.00 - 11.15 | C26: =AVERAGE('51'!C26,'52'!C26,'53'!C26,'55'!C26,'56'!C26,'57'!C26,'58'!C26,'59A'!C26,'59'!C26,'60'!C26,'61'!C26,'62'!C26,'63'!C26,'64'!C26,'65'!C26,'66'!C26,'67'!C26,'68'!C26,'69'!C26,'70'!C26,'71'!C26,'72'!C26,'73'!C26,'74'!C26,'76'!C26,'77'!C26,) -> 39.022487 | D26: =AVERAGE('51'!D26,'52'!D26,'53'!D26,'55'!D26,'56'!D26,'57'!D26,'58'!D26,'59A'!D26,'59'!D26,'60'!D26,'61'!D26,'62'!D26,'63'!D26,'64'!D26,'65'!D26,'66'!D26,'67'!D26,'68'!D26,'69'!D26,'70'!D26,'71'!D26,'72'!D26,'73'!D26,'74'!D26,'76'!D26,'77'!D26,) -> 12.391138 | E26: =AVERAGE('51'!E26,'52'!E26,'53'!E26,'55'!E26,'56'!E26,'57'!E26,'58'!E26,'59A'!E26,'59'!E26,'60'!E26,'61'!E26,'62'!E26,'63'!E26,'64'!E26,'65'!E26,'66'!E26,'67'!E26,'68'!E26,'69'!E26,'70'!E26,'71'!E26,'72'!E26,'73'!E26,'74'!E26,'76'!E26,'77'!E26,) -> 7.6207672 | F26: =AVERAGE('51'!F26,'52'!F26,'53'!F26,'55'!F26,'56'!F26,'57'!F26,'58'!F26,'59A'!F26,'59'!F26,'60'!F26,'61'!F26,'62'!F26,'63'!F26,'64'!F26,'65'!F26,'66'!F26,'67'!F26,'68'!F26,'69'!F26,'70'!F26,'71'!F26,'72'!F26,'73'!F26,'74'!F26,'76'!F26,'77'!F26,) -> 22.185185 | G26: =AVERAGE('51'!G26,'52'!G26,'53'!G26,'55'!G26,'56'!G26,'57'!G26,'58'!G26,'59A'!G26,'59'!G26,'60'!G26,'61'!G26,'62'!G26,'63'!G26,'64'!G26,'65'!G26,'66'!G26,'67'!G26,'68'!G26,'69'!G26,'70'!G26,'71'!G26,'72'!G26,'73'!G26,'74'!G26,'76'!G26,'77'!G26,) -> 0.63161376 | H26: =AVERAGE('51'!H26,'52'!H26,'53'!H26,'55'!H26,'56'!H26,'57'!H26,'58'!H26,'59A'!H26,'59'!H26,'60'!H26,'61'!H26,'62'!H26,'63'!H26,'64'!H26,'65'!H26,'66'!H26,'67'!H26,'68'!H26,'69'!H26,'70'!H26,'71'!H26,'72'!H26,'73'!H26,'74'!H26,'76'!H26,'77'!H26,) -> 0.38558201 | I26: =AVERAGE('51'!I26,'52'!I26,'53'!I26,'55'!I26,'56'!I26,'57'!I26,'58'!I26,'59A'!I26,'59'!I26,'60'!I26,'61'!I26,'62'!I26,'63'!I26,'64'!I26,'65'!I26,'66'!I26,'67'!I26,'68'!I26,'69'!I26,'70'!I26,'71'!I26,'72'!I26,'73'!I26,'74'!I26,'76'!I26,'77'!I26,) -> 9.6984127 | J26: =AVERAGE('51'!J26,'52'!J26,'53'!J26,'55'!J26,'56'!J26,'57'!J26,'58'!J26,'59A'!J26,'59'!J26,'60'!J26,'61'!J26,'62'!J26,'63'!J26,'64'!J26,'65'!J26,'66'!J26,'67'!J26,'68'!J26,'69'!J26,'70'!J26,'71'!J26,'72'!J26,'73'!J26,'74'!J26,'76'!J26,'77'!J26,) -> 3.0145503 | ... P26: =AVERAGE('51'!P26,'52'!P26,'53'!P26,'55'!P26,'56'!P26,'57'!P26,'58'!P26,'59A'!P26,'59'!P26,'60'!P26,'61'!P26,'62'!P26,'63'!P26,'64'!P26,'65'!P26,'66'!P26,'67'!P26,'68'!P26,'69'!P26,'70'!P26,'71'!P26,'72'!P26,'73'!P26,'74'!P26,'76'!P26,'77'!P26,) -> 181.03571 | R26: 2300-0000 | S26: =SUM(C74:C77) -> 88.643076 | T26: =SUM(D74:D77) -> 30.404058 | U26: =SUM(E74:E77) -> 13.06905 | V26: =SUM(F74:F77) -> 36.077542 | W26: =SUM(G74:G77) -> 2.5991642 | X26: =SUM(H74:H77) -> 1.9940266 | Y26: =SUM(I74:I77) -> 14.852581 | Z26: =SUM(J74:J77) -> 8.429796 | ... AF26: =SUM(P74:P77) -> 334.09377
B27: 11.15 - 11.30 | C27: =AVERAGE('51'!C27,'52'!C27,'53'!C27,'55'!C27,'56'!C27,'57'!C27,'58'!C27,'59A'!C27,'59'!C27,'60'!C27,'61'!C27,'62'!C27,'63'!C27,'64'!C27,'65'!C27,'66'!C27,'67'!C27,'68'!C27,'69'!C27,'70'!C27,'71'!C27,'72'!C27,'73'!C27,'74'!C27,'76'!C27,'77'!C27,) -> 41.353836 | D27: =AVERAGE('51'!D27,'52'!D27,'53'!D27,'55'!D27,'56'!D27,'57'!D27,'58'!D27,'59A'!D27,'59'!D27,'60'!D27,'61'!D27,'62'!D27,'63'!D27,'64'!D27,'65'!D27,'66'!D27,'67'!D27,'68'!D27,'69'!D27,'70'!D27,'71'!D27,'72'!D27,'73'!D27,'74'!D27,'76'!D27,'77'!D27,) -> 11.863624 | E27: =AVERAGE('51'!E27,'52'!E27,'53'!E27,'55'!E27,'56'!E27,'57'!E27,'58'!E27,'59A'!E27,'59'!E27,'60'!E27,'61'!E27,'62'!E27,'63'!E27,'64'!E27,'65'!E27,'66'!E27,'67'!E27,'68'!E27,'69'!E27,'70'!E27,'71'!E27,'72'!E27,'73'!E27,'74'!E27,'76'!E27,'77'!E27,) -> 7.6244709 | F27: =AVERAGE('51'!F27,'52'!F27,'53'!F27,'55'!F27,'56'!F27,'57'!F27,'58'!F27,'59A'!F27,'59'!F27,'60'!F27,'61'!F27,'62'!F27,'63'!F27,'64'!F27,'65'!F27,'66'!F27,'67'!F27,'68'!F27,'69'!F27,'70'!F27,'71'!F27,'72'!F27,'73'!F27,'74'!F27,'76'!F27,'77'!F27,) -> 21.71627 | G27: =AVERAGE('51'!G27,'52'!G27,'53'!G27,'55'!G27,'56'!G27,'57'!G27,'58'!G27,'59A'!G27,'59'!G27,'60'!G27,'61'!G27,'62'!G27,'63'!G27,'64'!G27,'65'!G27,'66'!G27,'67'!G27,'68'!G27,'69'!G27,'70'!G27,'71'!G27,'72'!G27,'73'!G27,'74'!G27,'76'!G27,'77'!G27,) -> 0.76455026 | H27: =AVERAGE('51'!H27,'52'!H27,'53'!H27,'55'!H27,'56'!H27,'57'!H27,'58'!H27,'59A'!H27,'59'!H27,'60'!H27,'61'!H27,'62'!H27,'63'!H27,'64'!H27,'65'!H27,'66'!H27,'67'!H27,'68'!H27,'69'!H27,'70'!H27,'71'!H27,'72'!H27,'73'!H27,'74'!H27,'76'!H27,'77'!H27,) -> 0.36441799 | I27: =AVERAGE('51'!I27,'52'!I27,'53'!I27,'55'!I27,'56'!I27,'57'!I27,'58'!I27,'59A'!I27,'59'!I27,'60'!I27,'61'!I27,'62'!I27,'63'!I27,'64'!I27,'65'!I27,'66'!I27,'67'!I27,'68'!I27,'69'!I27,'70'!I27,'71'!I27,'72'!I27,'73'!I27,'74'!I27,'76'!I27,'77'!I27,) -> 9.4722222 | J27: =AVERAGE('51'!J27,'52'!J27,'53'!J27,'55'!J27,'56'!J27,'57'!J27,'58'!J27,'59A'!J27,'59'!J27,'60'!J27,'61'!J27,'62'!J27,'63'!J27,'64'!J27,'65'!J27,'66'!J27,'67'!J27,'68'!J27,'69'!J27,'70'!J27,'71'!J27,'72'!J27,'73'!J27,'74'!J27,'76'!J27,'77'!J27,) -> 3.0734127 | ... P27: =AVERAGE('51'!P27,'52'!P27,'53'!P27,'55'!P27,'56'!P27,'57'!P27,'58'!P27,'59A'!P27,'59'!P27,'60'!P27,'61'!P27,'62'!P27,'63'!P27,'64'!P27,'65'!P27,'66'!P27,'67'!P27,'68'!P27,'69'!P27,'70'!P27,'71'!P27,'72'!P27,'73'!P27,'74'!P27,'76'!P27,'77'!P27,) -> 181.62632 | R27: 0000-0100 | S27: =SUM(C78:C81) -> 52.780021 | T27: =SUM(D78:D81) -> 14.796939 | U27: =SUM(E78:E81) -> 8.0380016 | V27: =SUM(F78:F81) -> 15.887633 | W27: =SUM(G78:G81) -> 1.4360521 | X27: =SUM(H78:H81) -> 1.643952 | Y27: =SUM(I78:I81) -> 11.901194 | Z27: =SUM(J78:J81) -> 7.7061629 | ... AF27: =SUM(P78:P81) -> 193.93589
B28: 11.30 - 11.45 | C28: =AVERAGE('51'!C28,'52'!C28,'53'!C28,'55'!C28,'56'!C28,'57'!C28,'58'!C28,'59A'!C28,'59'!C28,'60'!C28,'61'!C28,'62'!C28,'63'!C28,'64'!C28,'65'!C28,'66'!C28,'67'!C28,'68'!C28,'69'!C28,'70'!C28,'71'!C28,'72'!C28,'73'!C28,'74'!C28,'76'!C28,'77'!C28,) -> 40.675265 | D28: =AVERAGE('51'!D28,'52'!D28,'53'!D28,'55'!D28,'56'!D28,'57'!D28,'58'!D28,'59A'!D28,'59'!D28,'60'!D28,'61'!D28,'62'!D28,'63'!D28,'64'!D28,'65'!D28,'66'!D28,'67'!D28,'68'!D28,'69'!D28,'70'!D28,'71'!D28,'72'!D28,'73'!D28,'74'!D28,'76'!D28,'77'!D28,) -> 12.71746 | E28: =AVERAGE('51'!E28,'52'!E28,'53'!E28,'55'!E28,'56'!E28,'57'!E28,'58'!E28,'59A'!E28,'59'!E28,'60'!E28,'61'!E28,'62'!E28,'63'!E28,'64'!E28,'65'!E28,'66'!E28,'67'!E28,'68'!E28,'69'!E28,'70'!E28,'71'!E28,'72'!E28,'73'!E28,'74'!E28,'76'!E28,'77'!E28,) -> 7.5828042 | F28: =AVERAGE('51'!F28,'52'!F28,'53'!F28,'55'!F28,'56'!F28,'57'!F28,'58'!F28,'59A'!F28,'59'!F28,'60'!F28,'61'!F28,'62'!F28,'63'!F28,'64'!F28,'65'!F28,'66'!F28,'67'!F28,'68'!F28,'69'!F28,'70'!F28,'71'!F28,'72'!F28,'73'!F28,'74'!F28,'76'!F28,'77'!F28,) -> 22.433642 | G28: =AVERAGE('51'!G28,'52'!G28,'53'!G28,'55'!G28,'56'!G28,'57'!G28,'58'!G28,'59A'!G28,'59'!G28,'60'!G28,'61'!G28,'62'!G28,'63'!G28,'64'!G28,'65'!G28,'66'!G28,'67'!G28,'68'!G28,'69'!G28,'70'!G28,'71'!G28,'72'!G28,'73'!G28,'74'!G28,'76'!G28,'77'!G28,) -> 0.74404762 | H28: =AVERAGE('51'!H28,'52'!H28,'53'!H28,'55'!H28,'56'!H28,'57'!H28,'58'!H28,'59A'!H28,'59'!H28,'60'!H28,'61'!H28,'62'!H28,'63'!H28,'64'!H28,'65'!H28,'66'!H28,'67'!H28,'68'!H28,'69'!H28,'70'!H28,'71'!H28,'72'!H28,'73'!H28,'74'!H28,'76'!H28,'77'!H28,) -> 0.3207672 | I28: =AVERAGE('51'!I28,'52'!I28,'53'!I28,'55'!I28,'56'!I28,'57'!I28,'58'!I28,'59A'!I28,'59'!I28,'60'!I28,'61'!I28,'62'!I28,'63'!I28,'64'!I28,'65'!I28,'66'!I28,'67'!I28,'68'!I28,'69'!I28,'70'!I28,'71'!I28,'72'!I28,'73'!I28,'74'!I28,'76'!I28,'77'!I28,) -> 10.40873 | J28: =AVERAGE('51'!J28,'52'!J28,'53'!J28,'55'!J28,'56'!J28,'57'!J28,'58'!J28,'59A'!J28,'59'!J28,'60'!J28,'61'!J28,'62'!J28,'63'!J28,'64'!J28,'65'!J28,'66'!J28,'67'!J28,'68'!J28,'69'!J28,'70'!J28,'71'!J28,'72'!J28,'73'!J28,'74'!J28,'76'!J28,'77'!J28,) -> 2.6779101 | ... P28: =AVERAGE('51'!P28,'52'!P28,'53'!P28,'55'!P28,'56'!P28,'57'!P28,'58'!P28,'59A'!P28,'59'!P28,'60'!P28,'61'!P28,'62'!P28,'63'!P28,'64'!P28,'65'!P28,'66'!P28,'67'!P28,'68'!P28,'69'!P28,'70'!P28,'71'!P28,'72'!P28,'73'!P28,'74'!P28,'76'!P28,'77'!P28,) -> 181.84171 | R28: 0100-0200 | S28: =SUM(C82:C85) -> 29.405364 | T28: =SUM(D82:D85) -> 9.3230991 | U28: =SUM(E82:E85) -> 5.4568709 | V28: =SUM(F82:F85) -> 7.1707442 | W28: =SUM(G82:G85) -> 0.61754448 | X28: =SUM(H82:H85) -> 0.8180315 | Y28: =SUM(I82:I85) -> 8.8983362 | Z28: =SUM(J82:J85) -> 6.3560854 | ... AF28: =SUM(P82:P85) -> 120.42161
B29: 11.45 - 12.00 | C29: =AVERAGE('51'!C29,'52'!C29,'53'!C29,'55'!C29,'56'!C29,'57'!C29,'58'!C29,'59A'!C29,'59'!C29,'60'!C29,'61'!C29,'62'!C29,'63'!C29,'64'!C29,'65'!C29,'66'!C29,'67'!C29,'68'!C29,'69'!C29,'70'!C29,'71'!C29,'72'!C29,'73'!C29,'74'!C29,'76'!C29,'77'!C29,) -> 41.391534 | D29: =AVERAGE('51'!D29,'52'!D29,'53'!D29,'55'!D29,'56'!D29,'57'!D29,'58'!D29,'59A'!D29,'59'!D29,'60'!D29,'61'!D29,'62'!D29,'63'!D29,'64'!D29,'65'!D29,'66'!D29,'67'!D29,'68'!D29,'69'!D29,'70'!D29,'71'!D29,'72'!D29,'73'!D29,'74'!D29,'76'!D29,'77'!D29,) -> 11.966402 | E29: =AVERAGE('51'!E29,'52'!E29,'53'!E29,'55'!E29,'56'!E29,'57'!E29,'58'!E29,'59A'!E29,'59'!E29,'60'!E29,'61'!E29,'62'!E29,'63'!E29,'64'!E29,'65'!E29,'66'!E29,'67'!E29,'68'!E29,'69'!E29,'70'!E29,'71'!E29,'72'!E29,'73'!E29,'74'!E29,'76'!E29,'77'!E29,) -> 8.4165344 | F29: =AVERAGE('51'!F29,'52'!F29,'53'!F29,'55'!F29,'56'!F29,'57'!F29,'58'!F29,'59A'!F29,'59'!F29,'60'!F29,'61'!F29,'62'!F29,'63'!F29,'64'!F29,'65'!F29,'66'!F29,'67'!F29,'68'!F29,'69'!F29,'70'!F29,'71'!F29,'72'!F29,'73'!F29,'74'!F29,'76'!F29,'77'!F29,) -> 21.55291 | G29: =AVERAGE('51'!G29,'52'!G29,'53'!G29,'55'!G29,'56'!G29,'57'!G29,'58'!G29,'59A'!G29,'59'!G29,'60'!G29,'61'!G29,'62'!G29,'63'!G29,'64'!G29,'65'!G29,'66'!G29,'67'!G29,'68'!G29,'69'!G29,'70'!G29,'71'!G29,'72'!G29,'73'!G29,'74'!G29,'76'!G29,'77'!G29,) -> 0.91732804 | H29: =AVERAGE('51'!H29,'52'!H29,'53'!H29,'55'!H29,'56'!H29,'57'!H29,'58'!H29,'59A'!H29,'59'!H29,'60'!H29,'61'!H29,'62'!H29,'63'!H29,'64'!H29,'65'!H29,'66'!H29,'67'!H29,'68'!H29,'69'!H29,'70'!H29,'71'!H29,'72'!H29,'73'!H29,'74'!H29,'76'!H29,'77'!H29,) -> 0.32208995 | I29: =AVERAGE('51'!I29,'52'!I29,'53'!I29,'55'!I29,'56'!I29,'57'!I29,'58'!I29,'59A'!I29,'59'!I29,'60'!I29,'61'!I29,'62'!I29,'63'!I29,'64'!I29,'65'!I29,'66'!I29,'67'!I29,'68'!I29,'69'!I29,'70'!I29,'71'!I29,'72'!I29,'73'!I29,'74'!I29,'76'!I29,'77'!I29,) -> 9.7645503 | J29: =AVERAGE('51'!J29,'52'!J29,'53'!J29,'55'!J29,'56'!J29,'57'!J29,'58'!J29,'59A'!J29,'59'!J29,'60'!J29,'61'!J29,'62'!J29,'63'!J29,'64'!J29,'65'!J29,'66'!J29,'67'!J29,'68'!J29,'69'!J29,'70'!J29,'71'!J29,'72'!J29,'73'!J29,'74'!J29,'76'!J29,'77'!J29,) -> 3.3544974 | ... P29: =AVERAGE('51'!P29,'52'!P29,'53'!P29,'55'!P29,'56'!P29,'57'!P29,'58'!P29,'59A'!P29,'59'!P29,'60'!P29,'61'!P29,'62'!P29,'63'!P29,'64'!P29,'65'!P29,'66'!P29,'67'!P29,'68'!P29,'69'!P29,'70'!P29,'71'!P29,'72'!P29,'73'!P29,'74'!P29,'76'!P29,'77'!P29,) -> 180.27381 | R29: 0200-0300 | S29: =SUM(C86:C89) -> 20.098344 | T29: =SUM(D86:D89) -> 6.3380959 | U29: =SUM(E86:E89) -> 3.9330697 | V29: =SUM(F86:F89) -> 4.4041729 | W29: =SUM(G86:G89) -> 0.41486703 | X29: =SUM(H86:H89) -> 1.0685446 | Y29: =SUM(I86:I89) -> 7.3558453 | Z29: =SUM(J86:J89) -> 4.6659568 | ... AF29: =SUM(P86:P89) -> 83.896569
B30: 12.00 - 12.15 | C30: =AVERAGE('51'!C30,'52'!C30,'53'!C30,'55'!C30,'56'!C30,'57'!C30,'58'!C30,'59A'!C30,'59'!C30,'60'!C30,'61'!C30,'62'!C30,'63'!C30,'64'!C30,'65'!C30,'66'!C30,'67'!C30,'68'!C30,'69'!C30,'70'!C30,'71'!C30,'72'!C30,'73'!C30,'74'!C30,'76'!C30,'77'!C30,) -> 41.518519 | D30: =AVERAGE('51'!D30,'52'!D30,'53'!D30,'55'!D30,'56'!D30,'57'!D30,'58'!D30,'59A'!D30,'59'!D30,'60'!D30,'61'!D30,'62'!D30,'63'!D30,'64'!D30,'65'!D30,'66'!D30,'67'!D30,'68'!D30,'69'!D30,'70'!D30,'71'!D30,'72'!D30,'73'!D30,'74'!D30,'76'!D30,'77'!D30,) -> 12.49246 | E30: =AVERAGE('51'!E30,'52'!E30,'53'!E30,'55'!E30,'56'!E30,'57'!E30,'58'!E30,'59A'!E30,'59'!E30,'60'!E30,'61'!E30,'62'!E30,'63'!E30,'64'!E30,'65'!E30,'66'!E30,'67'!E30,'68'!E30,'69'!E30,'70'!E30,'71'!E30,'72'!E30,'73'!E30,'74'!E30,'76'!E30,'77'!E30,) -> 8.5862434 | F30: =AVERAGE('51'!F30,'52'!F30,'53'!F30,'55'!F30,'56'!F30,'57'!F30,'58'!F30,'59A'!F30,'59'!F30,'60'!F30,'61'!F30,'62'!F30,'63'!F30,'64'!F30,'65'!F30,'66'!F30,'67'!F30,'68'!F30,'69'!F30,'70'!F30,'71'!F30,'72'!F30,'73'!F30,'74'!F30,'76'!F30,'77'!F30,) -> 21.537037 | G30: =AVERAGE('51'!G30,'52'!G30,'53'!G30,'55'!G30,'56'!G30,'57'!G30,'58'!G30,'59A'!G30,'59'!G30,'60'!G30,'61'!G30,'62'!G30,'63'!G30,'64'!G30,'65'!G30,'66'!G30,'67'!G30,'68'!G30,'69'!G30,'70'!G30,'71'!G30,'72'!G30,'73'!G30,'74'!G30,'76'!G30,'77'!G30,) -> 0.80820106 | H30: =AVERAGE('51'!H30,'52'!H30,'53'!H30,'55'!H30,'56'!H30,'57'!H30,'58'!H30,'59A'!H30,'59'!H30,'60'!H30,'61'!H30,'62'!H30,'63'!H30,'64'!H30,'65'!H30,'66'!H30,'67'!H30,'68'!H30,'69'!H30,'70'!H30,'71'!H30,'72'!H30,'73'!H30,'74'!H30,'76'!H30,'77'!H30,) -> 0.63227513 | I30: =AVERAGE('51'!I30,'52'!I30,'53'!I30,'55'!I30,'56'!I30,'57'!I30,'58'!I30,'59A'!I30,'59'!I30,'60'!I30,'61'!I30,'62'!I30,'63'!I30,'64'!I30,'65'!I30,'66'!I30,'67'!I30,'68'!I30,'69'!I30,'70'!I30,'71'!I30,'72'!I30,'73'!I30,'74'!I30,'76'!I30,'77'!I30,) -> 10.024471 | J30: =AVERAGE('51'!J30,'52'!J30,'53'!J30,'55'!J30,'56'!J30,'57'!J30,'58'!J30,'59A'!J30,'59'!J30,'60'!J30,'61'!J30,'62'!J30,'63'!J30,'64'!J30,'65'!J30,'66'!J30,'67'!J30,'68'!J30,'69'!J30,'70'!J30,'71'!J30,'72'!J30,'73'!J30,'74'!J30,'76'!J30,'77'!J30,) -> 3.5019841 | ... P30: =AVERAGE('51'!P30,'52'!P30,'53'!P30,'55'!P30,'56'!P30,'57'!P30,'58'!P30,'59A'!P30,'59'!P30,'60'!P30,'61'!P30,'62'!P30,'63'!P30,'64'!P30,'65'!P30,'66'!P30,'67'!P30,'68'!P30,'69'!P30,'70'!P30,'71'!P30,'72'!P30,'73'!P30,'74'!P30,'76'!P30,'77'!P30,) -> 180.18122 | R30: 0300-0400 | S30: =SUM(C90:C93) -> 15.994357 | T30: =SUM(D90:D93) -> 5.2398161 | U30: =SUM(E90:E93) -> 3.1652798 | V30: =SUM(F90:F93) -> 4.6146762 | W30: =SUM(G90:G93) -> 0.36770217 | X30: =SUM(H90:H93) -> 1.2671844 | Y30: =SUM(I90:I93) -> 6.4826747 | Z30: =SUM(J90:J93) -> 5.6445761 | ... AF30: =SUM(P90:P93) -> 73.424957
