Workbook

Sheet ALL
B1: Consultancy services for Preparation of Expressway Development Master Plan (EDMP) for Uganda
B2: MANUAL CLASSIFIED COUNT (MCC)
B3: ROAD NAME: | C3: MCC AVERAGE-C-4
C5: Date | D5: AVERAGE WEEK | F5: Location | G5: ='[1]Avg Week Mbale- Sironko'!G5:H5 -> xxx | J5: Surveyor
C6: Dir. From | D6: BOTH DIRECTIONS | F6: Dir. To | G6: BOTH DIRECTIONS | J6: Supervisor
B8: Time / Veh Type | R8: SUMMARY TRAFFIC VOLUMES
C9: 1. Car | D9: 2. Station Wagon | E9: 3. Pickups | F9: 4. Minibus, matatu | G9: 5. Medium bus | H9: 6. Large Bus | I9: 7. Light Truck | J9: 8. Medium Truck | K9: 9. Heavy truck | L9: 10. Truck Trailer | M9: 11. Motor cycles | N9: 12. Tractors | O9: Total Excl M/Cycles | P9: Total All | R9: Time | S9: 1. Car | T9: 2. Station Wagon | U9: 3. Pickups | V9: 4. Minibus, matatu | W9: 5. Medium bus | X9: 6. Large Bus | Y9: 7. Light Truck | Z9: 8. Medium Truck | AA9: 9. Heavy truck | AB9: 10. Truck Trailer | AC9: 11. Motorcycles | AD9: 12. Tractors, Graders | AE9: Total Excl M/ Cycles | AF9: Total All
B10: 07.00 - 07.15 | C10: =AVERAGE('120'!C10,'99'!C10,'100A'!C10,'100'!C10,'101'!C10,'102'!C10,'103'!C10,'104'!C10,'105'!C10,'106'!C10,'107'!C10,'108'!C10,'109'!C10,'110'!C10,'111A'!C10,'111'!C10,'112'!C10,'113'!C10,'133'!C10,'134'!C10,'135'!C10,'137'!C10,'141'!C10,'144'!C10,'141'!C10,'144'!C10,'141'!C10,'144'!C10,) -> 3.5944171 | D10: =AVERAGE('120'!D10,'99'!D10,'100A'!D10,'100'!D10,'101'!D10,'102'!D10,'103'!D10,'104'!D10,'105'!D10,'106'!D10,'107'!D10,'108'!D10,'109'!D10,'110'!D10,'111A'!D10,'111'!D10,'112'!D10,'113'!D10,'133'!D10,'134'!D10,'135'!D10,'137'!D10,'141'!D10,'144'!D10,'141'!D10,'144'!D10,'141'!D10,'144'!D10,) -> 0.57323481 | E10: =AVERAGE('120'!E10,'99'!E10,'100A'!E10,'100'!E10,'101'!E10,'102'!E10,'103'!E10,'104'!E10,'105'!E10,'106'!E10,'107'!E10,'108'!E10,'109'!E10,'110'!E10,'111A'!E10,'111'!E10,'112'!E10,'113'!E10,'133'!E10,'134'!E10,'135'!E10,'137'!E10,'141'!E10,'144'!E10,'141'!E10,'144'!E10,'141'!E10,'144'!E10,) -> 0.84466338 | F10: =AVERAGE('120'!F10,'99'!F10,'100A'!F10,'100'!F10,'101'!F10,'102'!F10,'103'!F10,'104'!F10,'105'!F10,'106'!F10,'107'!F10,'108'!F10,'109'!F10,'110'!F10,'111A'!F10,'111'!F10,'112'!F10,'113'!F10,'133'!F10,'134'!F10,'135'!F10,'137'!F10,'141'!F10,'144'!F10,'141'!F10,'144'!F10,'141'!F10,'144'!F10,) -> 2.3152709 | G10: =AVERAGE('120'!G10,'99'!G10,'100A'!G10,'100'!G10,'101'!G10,'102'!G10,'103'!G10,'104'!G10,'105'!G10,'106'!G10,'107'!G10,'108'!G10,'109'!G10,'110'!G10,'111A'!G10,'111'!G10,'112'!G10,'113'!G10,'133'!G10,'134'!G10,'135'!G10,'137'!G10,'141'!G10,'144'!G10,'141'!G10,'144'!G10,'141'!G10,'144'!G10,) -> 0.096059113 | H10: =AVERAGE('120'!H10,'99'!H10,'100A'!H10,'100'!H10,'101'!H10,'102'!H10,'103'!H10,'104'!H10,'105'!H10,'106'!H10,'107'!H10,'108'!H10,'109'!H10,'110'!H10,'111A'!H10,'111'!H10,'112'!H10,'113'!H10,'133'!H10,'134'!H10,'135'!H10,'137'!H10,'141'!H10,'144'!H10,'141'!H10,'144'!H10,'141'!H10,'144'!H10,) -> 0.27586207 | I10: =AVERAGE('120'!I10,'99'!I10,'100A'!I10,'100'!I10,'101'!I10,'102'!I10,'103'!I10,'104'!I10,'105'!I10,'106'!I10,'107'!I10,'108'!I10,'109'!I10,'110'!I10,'111A'!I10,'111'!I10,'112'!I10,'113'!I10,'133'!I10,'134'!I10,'135'!I10,'137'!I10,'141'!I10,'144'!I10,'141'!I10,'144'!I10,'141'!I10,'144'!I10,) -> 0.92939245 | J10: =AVERAGE('120'!J10,'99'!J10,'100A'!J10,'100'!J10,'101'!J10,'102'!J10,'103'!J10,'104'!J10,'105'!J10,'106'!J10,'107'!J10,'108'!J10,'109'!J10,'110'!J10,'111A'!J10,'111'!J10,'112'!J10,'113'!J10,'133'!J10,'134'!J10,'135'!J10,'137'!J10,'141'!J10,'144'!J10,'141'!J10,'144'!J10,'141'!J10,'144'!J10,) -> 0.77339901 | ... P10: =AVERAGE('120'!P10,'99'!P10,'100A'!P10,'100'!P10,'101'!P10,'102'!P10,'103'!P10,'104'!P10,'105'!P10,'106'!P10,'107'!P10,'108'!P10,'109'!P10,'110'!P10,'111A'!P10,'111'!P10,'112'!P10,'113'!P10,'133'!P10,'134'!P10,'135'!P10,'137'!P10,'141'!P10,'144'!P10,'141'!P10,'144'!P10,'141'!P10,'144'!P10,) -> 28.942529 | R10: 0700-0800 | S10: =SUM(C10:C13) -> 17.971264 | T10: =SUM(D10:D13) -> 3.3186371 | U10: =SUM(E10:E13) -> 4.415353 | V10: =SUM(F10:F13) -> 8.5952381 | W10: =SUM(G10:G13) -> 0.36699507 | X10: =SUM(H10:H13) -> 0.62397373 | Y10: =SUM(I10:I13) -> 4.1650246 | Z10: =SUM(J10:J13) -> 2.8119869 | ... AF10: =SUM(P10:P13) -> 147.91872
B11: 07.15 - 07.30 | C11: =AVERAGE('120'!C11,'99'!C11,'100A'!C11,'100'!C11,'101'!C11,'102'!C11,'103'!C11,'104'!C11,'105'!C11,'106'!C11,'107'!C11,'108'!C11,'109'!C11,'110'!C11,'111A'!C11,'111'!C11,'112'!C11,'113'!C11,'133'!C11,'134'!C11,'135'!C11,'137'!C11,'141'!C11,'144'!C11,'141'!C11,'144'!C11,'141'!C11,'144'!C11,) -> 4.1970443 | D11: =AVERAGE('120'!D11,'99'!D11,'100A'!D11,'100'!D11,'101'!D11,'102'!D11,'103'!D11,'104'!D11,'105'!D11,'106'!D11,'107'!D11,'108'!D11,'109'!D11,'110'!D11,'111A'!D11,'111'!D11,'112'!D11,'113'!D11,'133'!D11,'134'!D11,'135'!D11,'137'!D11,'141'!D11,'144'!D11,'141'!D11,'144'!D11,'141'!D11,'144'!D11,) -> 0.61461412 | E11: =AVERAGE('120'!E11,'99'!E11,'100A'!E11,'100'!E11,'101'!E11,'102'!E11,'103'!E11,'104'!E11,'105'!E11,'106'!E11,'107'!E11,'108'!E11,'109'!E11,'110'!E11,'111A'!E11,'111'!E11,'112'!E11,'113'!E11,'133'!E11,'134'!E11,'135'!E11,'137'!E11,'141'!E11,'144'!E11,'141'!E11,'144'!E11,'141'!E11,'144'!E11,) -> 1.0003284 | F11: =AVERAGE('120'!F11,'99'!F11,'100A'!F11,'100'!F11,'101'!F11,'102'!F11,'103'!F11,'104'!F11,'105'!F11,'106'!F11,'107'!F11,'108'!F11,'109'!F11,'110'!F11,'111A'!F11,'111'!F11,'112'!F11,'113'!F11,'133'!F11,'134'!F11,'135'!F11,'137'!F11,'141'!F11,'144'!F11,'141'!F11,'144'!F11,'141'!F11,'144'!F11,) -> 1.998358 | G11: =AVERAGE('120'!G11,'99'!G11,'100A'!G11,'100'!G11,'101'!G11,'102'!G11,'103'!G11,'104'!G11,'105'!G11,'106'!G11,'107'!G11,'108'!G11,'109'!G11,'110'!G11,'111A'!G11,'111'!G11,'112'!G11,'113'!G11,'133'!G11,'134'!G11,'135'!G11,'137'!G11,'141'!G11,'144'!G11,'141'!G11,'144'!G11,'141'!G11,'144'!G11,) -> 0.068965517 | H11: =AVERAGE('120'!H11,'99'!H11,'100A'!H11,'100'!H11,'101'!H11,'102'!H11,'103'!H11,'104'!H11,'105'!H11,'106'!H11,'107'!H11,'108'!H11,'109'!H11,'110'!H11,'111A'!H11,'111'!H11,'112'!H11,'113'!H11,'133'!H11,'134'!H11,'135'!H11,'137'!H11,'141'!H11,'144'!H11,'141'!H11,'144'!H11,'141'!H11,'144'!H11,) -> 0.072249589 | I11: =AVERAGE('120'!I11,'99'!I11,'100A'!I11,'100'!I11,'101'!I11,'102'!I11,'103'!I11,'104'!I11,'105'!I11,'106'!I11,'107'!I11,'108'!I11,'109'!I11,'110'!I11,'111A'!I11,'111'!I11,'112'!I11,'113'!I11,'133'!I11,'134'!I11,'135'!I11,'137'!I11,'141'!I11,'144'!I11,'141'!I11,'144'!I11,'141'!I11,'144'!I11,) -> 1.0098522 | J11: =AVERAGE('120'!J11,'99'!J11,'100A'!J11,'100'!J11,'101'!J11,'102'!J11,'103'!J11,'104'!J11,'105'!J11,'106'!J11,'107'!J11,'108'!J11,'109'!J11,'110'!J11,'111A'!J11,'111'!J11,'112'!J11,'113'!J11,'133'!J11,'134'!J11,'135'!J11,'137'!J11,'141'!J11,'144'!J11,'141'!J11,'144'!J11,'141'!J11,'144'!J11,) -> 0.61740558 | ... P11: =AVERAGE('120'!P11,'99'!P11,'100A'!P11,'100'!P11,'101'!P11,'102'!P11,'103'!P11,'104'!P11,'105'!P11,'106'!P11,'107'!P11,'108'!P11,'109'!P11,'110'!P11,'111A'!P11,'111'!P11,'112'!P11,'113'!P11,'133'!P11,'134'!P11,'135'!P11,'137'!P11,'141'!P11,'144'!P11,'141'!P11,'144'!P11,'141'!P11,'144'!P11,) -> 34.163383 | R11: 0800-0900 | S11: =SUM(C14:C17) -> 23.278325 | T11: =SUM(D14:D17) -> 4.5022167 | U11: =SUM(E14:E17) -> 7.0462233 | V11: =SUM(F14:F17) -> 9.7898194 | W11: =SUM(G14:G17) -> 0.38587849 | X11: =SUM(H14:H17) -> 0.68226601 | Y11: =SUM(I14:I17) -> 5.3243021 | Z11: =SUM(J14:J17) -> 3.2142857 | ... AF11: =SUM(P14:P17) -> 187.9376
B12: 07.30 - 07.45 | C12: =AVERAGE('120'!C12,'99'!C12,'100A'!C12,'100'!C12,'101'!C12,'102'!C12,'103'!C12,'104'!C12,'105'!C12,'106'!C12,'107'!C12,'108'!C12,'109'!C12,'110'!C12,'111A'!C12,'111'!C12,'112'!C12,'113'!C12,'133'!C12,'134'!C12,'135'!C12,'137'!C12,'141'!C12,'144'!C12,'141'!C12,'144'!C12,'141'!C12,'144'!C12,) -> 5.2824302 | D12: =AVERAGE('120'!D12,'99'!D12,'100A'!D12,'100'!D12,'101'!D12,'102'!D12,'103'!D12,'104'!D12,'105'!D12,'106'!D12,'107'!D12,'108'!D12,'109'!D12,'110'!D12,'111A'!D12,'111'!D12,'112'!D12,'113'!D12,'133'!D12,'134'!D12,'135'!D12,'137'!D12,'141'!D12,'144'!D12,'141'!D12,'144'!D12,'141'!D12,'144'!D12,) -> 1.006486 | E12: =AVERAGE('120'!E12,'99'!E12,'100A'!E12,'100'!E12,'101'!E12,'102'!E12,'103'!E12,'104'!E12,'105'!E12,'106'!E12,'107'!E12,'108'!E12,'109'!E12,'110'!E12,'111A'!E12,'111'!E12,'112'!E12,'113'!E12,'133'!E12,'134'!E12,'135'!E12,'137'!E12,'141'!E12,'144'!E12,'141'!E12,'144'!E12,'141'!E12,'144'!E12,) -> 1.1281609 | F12: =AVERAGE('120'!F12,'99'!F12,'100A'!F12,'100'!F12,'101'!F12,'102'!F12,'103'!F12,'104'!F12,'105'!F12,'106'!F12,'107'!F12,'108'!F12,'109'!F12,'110'!F12,'111A'!F12,'111'!F12,'112'!F12,'113'!F12,'133'!F12,'134'!F12,'135'!F12,'137'!F12,'141'!F12,'144'!F12,'141'!F12,'144'!F12,'141'!F12,'144'!F12,) -> 2.1995074 | G12: =AVERAGE('120'!G12,'99'!G12,'100A'!G12,'100'!G12,'101'!G12,'102'!G12,'103'!G12,'104'!G12,'105'!G12,'106'!G12,'107'!G12,'108'!G12,'109'!G12,'110'!G12,'111A'!G12,'111'!G12,'112'!G12,'113'!G12,'133'!G12,'134'!G12,'135'!G12,'137'!G12,'141'!G12,'144'!G12,'141'!G12,'144'!G12,'141'!G12,'144'!G12,) -> 0.098522167 | H12: =AVERAGE('120'!H12,'99'!H12,'100A'!H12,'100'!H12,'101'!H12,'102'!H12,'103'!H12,'104'!H12,'105'!H12,'106'!H12,'107'!H12,'108'!H12,'109'!H12,'110'!H12,'111A'!H12,'111'!H12,'112'!H12,'113'!H12,'133'!H12,'134'!H12,'135'!H12,'137'!H12,'141'!H12,'144'!H12,'141'!H12,'144'!H12,'141'!H12,'144'!H12,) -> 0.10180624 | I12: =AVERAGE('120'!I12,'99'!I12,'100A'!I12,'100'!I12,'101'!I12,'102'!I12,'103'!I12,'104'!I12,'105'!I12,'106'!I12,'107'!I12,'108'!I12,'109'!I12,'110'!I12,'111A'!I12,'111'!I12,'112'!I12,'113'!I12,'133'!I12,'134'!I12,'135'!I12,'137'!I12,'141'!I12,'144'!I12,'141'!I12,'144'!I12,'141'!I12,'144'!I12,) -> 1.1272578 | J12: =AVERAGE('120'!J12,'99'!J12,'100A'!J12,'100'!J12,'101'!J12,'102'!J12,'103'!J12,'104'!J12,'105'!J12,'106'!J12,'107'!J12,'108'!J12,'109'!J12,'110'!J12,'111A'!J12,'111'!J12,'112'!J12,'113'!J12,'133'!J12,'134'!J12,'135'!J12,'137'!J12,'141'!J12,'144'!J12,'141'!J12,'144'!J12,'141'!J12,'144'!J12,) -> 0.79967159 | ... P12: =AVERAGE('120'!P12,'99'!P12,'100A'!P12,'100'!P12,'101'!P12,'102'!P12,'103'!P12,'104'!P12,'105'!P12,'106'!P12,'107'!P12,'108'!P12,'109'!P12,'110'!P12,'111A'!P12,'111'!P12,'112'!P12,'113'!P12,'133'!P12,'134'!P12,'135'!P12,'137'!P12,'141'!P12,'144'!P12,'141'!P12,'144'!P12,'141'!P12,'144'!P12,) -> 41.853859 | R12: 0900-1000 | S12: =SUM(C18:C21) -> 25.697865 | T12: =SUM(D18:D21) -> 5.477422 | U12: =SUM(E18:E21) -> 8.4642857 | V12: =SUM(F18:F21) -> 11.011494 | W12: =SUM(G18:G21) -> 0.49671593 | X12: =SUM(H18:H21) -> 1.2528736 | Y12: =SUM(I18:I21) -> 6.1962233 | Z12: =SUM(J18:J21) -> 3.6075534 | ... AF12: =SUM(P18:P21) -> 207.71018
B13: 07.45 - 08.00 | C13: =AVERAGE('120'!C13,'99'!C13,'100A'!C13,'100'!C13,'101'!C13,'102'!C13,'103'!C13,'104'!C13,'105'!C13,'106'!C13,'107'!C13,'108'!C13,'109'!C13,'110'!C13,'111A'!C13,'111'!C13,'112'!C13,'113'!C13,'133'!C13,'134'!C13,'135'!C13,'137'!C13,'141'!C13,'144'!C13,'141'!C13,'144'!C13,'141'!C13,'144'!C13,) -> 4.8973727 | D13: =AVERAGE('120'!D13,'99'!D13,'100A'!D13,'100'!D13,'101'!D13,'102'!D13,'103'!D13,'104'!D13,'105'!D13,'106'!D13,'107'!D13,'108'!D13,'109'!D13,'110'!D13,'111A'!D13,'111'!D13,'112'!D13,'113'!D13,'133'!D13,'134'!D13,'135'!D13,'137'!D13,'141'!D13,'144'!D13,'141'!D13,'144'!D13,'141'!D13,'144'!D13,) -> 1.1243021 | E13: =AVERAGE('120'!E13,'99'!E13,'100A'!E13,'100'!E13,'101'!E13,'102'!E13,'103'!E13,'104'!E13,'105'!E13,'106'!E13,'107'!E13,'108'!E13,'109'!E13,'110'!E13,'111A'!E13,'111'!E13,'112'!E13,'113'!E13,'133'!E13,'134'!E13,'135'!E13,'137'!E13,'141'!E13,'144'!E13,'141'!E13,'144'!E13,'141'!E13,'144'!E13,) -> 1.4422003 | F13: =AVERAGE('120'!F13,'99'!F13,'100A'!F13,'100'!F13,'101'!F13,'102'!F13,'103'!F13,'104'!F13,'105'!F13,'106'!F13,'107'!F13,'108'!F13,'109'!F13,'110'!F13,'111A'!F13,'111'!F13,'112'!F13,'113'!F13,'133'!F13,'134'!F13,'135'!F13,'137'!F13,'141'!F13,'144'!F13,'141'!F13,'144'!F13,'141'!F13,'144'!F13,) -> 2.0821018 | G13: =AVERAGE('120'!G13,'99'!G13,'100A'!G13,'100'!G13,'101'!G13,'102'!G13,'103'!G13,'104'!G13,'105'!G13,'106'!G13,'107'!G13,'108'!G13,'109'!G13,'110'!G13,'111A'!G13,'111'!G13,'112'!G13,'113'!G13,'133'!G13,'134'!G13,'135'!G13,'137'!G13,'141'!G13,'144'!G13,'141'!G13,'144'!G13,'141'!G13,'144'!G13,) -> 0.10344828 | H13: =AVERAGE('120'!H13,'99'!H13,'100A'!H13,'100'!H13,'101'!H13,'102'!H13,'103'!H13,'104'!H13,'105'!H13,'106'!H13,'107'!H13,'108'!H13,'109'!H13,'110'!H13,'111A'!H13,'111'!H13,'112'!H13,'113'!H13,'133'!H13,'134'!H13,'135'!H13,'137'!H13,'141'!H13,'144'!H13,'141'!H13,'144'!H13,'141'!H13,'144'!H13,) -> 0.17405583 | I13: =AVERAGE('120'!I13,'99'!I13,'100A'!I13,'100'!I13,'101'!I13,'102'!I13,'103'!I13,'104'!I13,'105'!I13,'106'!I13,'107'!I13,'108'!I13,'109'!I13,'110'!I13,'111A'!I13,'111'!I13,'112'!I13,'113'!I13,'133'!I13,'134'!I13,'135'!I13,'137'!I13,'141'!I13,'144'!I13,'141'!I13,'144'!I13,'141'!I13,'144'!I13,) -> 1.0985222 | J13: =AVERAGE('120'!J13,'99'!J13,'100A'!J13,'100'!J13,'101'!J13,'102'!J13,'103'!J13,'104'!J13,'105'!J13,'106'!J13,'107'!J13,'108'!J13,'109'!J13,'110'!J13,'111A'!J13,'111'!J13,'112'!J13,'113'!J13,'133'!J13,'134'!J13,'135'!J13,'137'!J13,'141'!J13,'144'!J13,'141'!J13,'144'!J13,'141'!J13,'144'!J13,) -> 0.62151067 | ... P13: =AVERAGE('120'!P13,'99'!P13,'100A'!P13,'100'!P13,'101'!P13,'102'!P13,'103'!P13,'104'!P13,'105'!P13,'106'!P13,'107'!P13,'108'!P13,'109'!P13,'110'!P13,'111A'!P13,'111'!P13,'112'!P13,'113'!P13,'133'!P13,'134'!P13,'135'!P13,'137'!P13,'141'!P13,'144'!P13,'141'!P13,'144'!P13,'141'!P13,'144'!P13,) -> 42.958949 | R13: 1000-1100 | S13: =SUM(C22:C25) -> 27.784072 | T13: =SUM(D22:D25) -> 5.6461412 | U13: =SUM(E22:E25) -> 8.5295567 | V13: =SUM(F22:F25) -> 11.481117 | W13: =SUM(G22:G25) -> 0.34400657 | X13: =SUM(H22:H25) -> 1.0213465 | Y13: =SUM(I22:I25) -> 7.181445 | Z13: =SUM(J22:J25) -> 3.4425287 | ... AF13: =SUM(P22:P25) -> 219.88916
B14: 08.00 - 08.15 | C14: =AVERAGE('120'!C14,'99'!C14,'100A'!C14,'100'!C14,'101'!C14,'102'!C14,'103'!C14,'104'!C14,'105'!C14,'106'!C14,'107'!C14,'108'!C14,'109'!C14,'110'!C14,'111A'!C14,'111'!C14,'112'!C14,'113'!C14,'133'!C14,'134'!C14,'135'!C14,'137'!C14,'141'!C14,'144'!C14,'141'!C14,'144'!C14,'141'!C14,'144'!C14,) -> 5.6124795 | D14: =AVERAGE('120'!D14,'99'!D14,'100A'!D14,'100'!D14,'101'!D14,'102'!D14,'103'!D14,'104'!D14,'105'!D14,'106'!D14,'107'!D14,'108'!D14,'109'!D14,'110'!D14,'111A'!D14,'111'!D14,'112'!D14,'113'!D14,'133'!D14,'134'!D14,'135'!D14,'137'!D14,'141'!D14,'144'!D14,'141'!D14,'144'!D14,'141'!D14,'144'!D14,) -> 0.96141215 | E14: =AVERAGE('120'!E14,'99'!E14,'100A'!E14,'100'!E14,'101'!E14,'102'!E14,'103'!E14,'104'!E14,'105'!E14,'106'!E14,'107'!E14,'108'!E14,'109'!E14,'110'!E14,'111A'!E14,'111'!E14,'112'!E14,'113'!E14,'133'!E14,'134'!E14,'135'!E14,'137'!E14,'141'!E14,'144'!E14,'141'!E14,'144'!E14,'141'!E14,'144'!E14,) -> 1.544335 | F14: =AVERAGE('120'!F14,'99'!F14,'100A'!F14,'100'!F14,'101'!F14,'102'!F14,'103'!F14,'104'!F14,'105'!F14,'106'!F14,'107'!F14,'108'!F14,'109'!F14,'110'!F14,'111A'!F14,'111'!F14,'112'!F14,'113'!F14,'133'!F14,'134'!F14,'135'!F14,'137'!F14,'141'!F14,'144'!F14,'141'!F14,'144'!F14,'141'!F14,'144'!F14,) -> 2.320197 | G14: =AVERAGE('120'!G14,'99'!G14,'100A'!G14,'100'!G14,'101'!G14,'102'!G14,'103'!G14,'104'!G14,'105'!G14,'106'!G14,'107'!G14,'108'!G14,'109'!G14,'110'!G14,'111A'!G14,'111'!G14,'112'!G14,'113'!G14,'133'!G14,'134'!G14,'135'!G14,'137'!G14,'141'!G14,'144'!G14,'141'!G14,'144'!G14,'141'!G14,'144'!G14,) -> 0.10837438 | H14: =AVERAGE('120'!H14,'99'!H14,'100A'!H14,'100'!H14,'101'!H14,'102'!H14,'103'!H14,'104'!H14,'105'!H14,'106'!H14,'107'!H14,'108'!H14,'109'!H14,'110'!H14,'111A'!H14,'111'!H14,'112'!H14,'113'!H14,'133'!H14,'134'!H14,'135'!H14,'137'!H14,'141'!H14,'144'!H14,'141'!H14,'144'!H14,'141'!H14,'144'!H14,) -> 0.16912972 | I14: =AVERAGE('120'!I14,'99'!I14,'100A'!I14,'100'!I14,'101'!I14,'102'!I14,'103'!I14,'104'!I14,'105'!I14,'106'!I14,'107'!I14,'108'!I14,'109'!I14,'110'!I14,'111A'!I14,'111'!I14,'112'!I14,'113'!I14,'133'!I14,'134'!I14,'135'!I14,'137'!I14,'141'!I14,'144'!I14,'141'!I14,'144'!I14,'141'!I14,'144'!I14,) -> 1.1707718 | J14: =AVERAGE('120'!J14,'99'!J14,'100A'!J14,'100'!J14,'101'!J14,'102'!J14,'103'!J14,'104'!J14,'105'!J14,'106'!J14,'107'!J14,'108'!J14,'109'!J14,'110'!J14,'111A'!J14,'111'!J14,'112'!J14,'113'!J14,'133'!J14,'134'!J14,'135'!J14,'137'!J14,'141'!J14,'144'!J14,'141'!J14,'144'!J14,'141'!J14,'144'!J14,) -> 0.75287356 | ... P14: =AVERAGE('120'!P14,'99'!P14,'100A'!P14,'100'!P14,'101'!P14,'102'!P14,'103'!P14,'104'!P14,'105'!P14,'106'!P14,'107'!P14,'108'!P14,'109'!P14,'110'!P14,'111A'!P14,'111'!P14,'112'!P14,'113'!P14,'133'!P14,'134'!P14,'135'!P14,'137'!P14,'141'!P14,'144'!P14,'141'!P14,'144'!P14,'141'!P14,'144'!P14,) -> 44.330049 | R14: 1100-1200 | S14: =SUM(C26:C29) -> 28.687192 | T14: =SUM(D26:D29) -> 6.0258621 | U14: =SUM(E26:E29) -> 8.5357143 | V14: =SUM(F26:F29) -> 11.13711 | W14: =SUM(G26:G29) -> 0.29146141 | X14: =SUM(H26:H29) -> 0.88013136 | Y14: =SUM(I26:I29) -> 6.5188834 | Z14: =SUM(J26:J29) -> 3.7561576 | ... AF14: =SUM(P26:P29) -> 223.71182
B15: 08.15 - 08.30 | C15: =AVERAGE('120'!C15,'99'!C15,'100A'!C15,'100'!C15,'101'!C15,'102'!C15,'103'!C15,'104'!C15,'105'!C15,'106'!C15,'107'!C15,'108'!C15,'109'!C15,'110'!C15,'111A'!C15,'111'!C15,'112'!C15,'113'!C15,'133'!C15,'134'!C15,'135'!C15,'137'!C15,'141'!C15,'144'!C15,'141'!C15,'144'!C15,'141'!C15,'144'!C15,) -> 5.6034483 | D15: =AVERAGE('120'!D15,'99'!D15,'100A'!D15,'100'!D15,'101'!D15,'102'!D15,'103'!D15,'104'!D15,'105'!D15,'106'!D15,'107'!D15,'108'!D15,'109'!D15,'110'!D15,'111A'!D15,'111'!D15,'112'!D15,'113'!D15,'133'!D15,'134'!D15,'135'!D15,'137'!D15,'141'!D15,'144'!D15,'141'!D15,'144'!D15,'141'!D15,'144'!D15,) -> 1.1336617 | E15: =AVERAGE('120'!E15,'99'!E15,'100A'!E15,'100'!E15,'101'!E15,'102'!E15,'103'!E15,'104'!E15,'105'!E15,'106'!E15,'107'!E15,'108'!E15,'109'!E15,'110'!E15,'111A'!E15,'111'!E15,'112'!E15,'113'!E15,'133'!E15,'134'!E15,'135'!E15,'137'!E15,'141'!E15,'144'!E15,'141'!E15,'144'!E15,'141'!E15,'144'!E15,) -> 1.8466338 | F15: =AVERAGE('120'!F15,'99'!F15,'100A'!F15,'100'!F15,'101'!F15,'102'!F15,'103'!F15,'104'!F15,'105'!F15,'106'!F15,'107'!F15,'108'!F15,'109'!F15,'110'!F15,'111A'!F15,'111'!F15,'112'!F15,'113'!F15,'133'!F15,'134'!F15,'135'!F15,'137'!F15,'141'!F15,'144'!F15,'141'!F15,'144'!F15,'141'!F15,'144'!F15,) -> 2.3218391 | G15: =AVERAGE('120'!G15,'99'!G15,'100A'!G15,'100'!G15,'101'!G15,'102'!G15,'103'!G15,'104'!G15,'105'!G15,'106'!G15,'107'!G15,'108'!G15,'109'!G15,'110'!G15,'111A'!G15,'111'!G15,'112'!G15,'113'!G15,'133'!G15,'134'!G15,'135'!G15,'137'!G15,'141'!G15,'144'!G15,'141'!G15,'144'!G15,'141'!G15,'144'!G15,) -> 0.068965517 | H15: =AVERAGE('120'!H15,'99'!H15,'100A'!H15,'100'!H15,'101'!H15,'102'!H15,'103'!H15,'104'!H15,'105'!H15,'106'!H15,'107'!H15,'108'!H15,'109'!H15,'110'!H15,'111A'!H15,'111'!H15,'112'!H15,'113'!H15,'133'!H15,'134'!H15,'135'!H15,'137'!H15,'141'!H15,'144'!H15,'141'!H15,'144'!H15,'141'!H15,'144'!H15,) -> 0.13136289 | I15: =AVERAGE('120'!I15,'99'!I15,'100A'!I15,'100'!I15,'101'!I15,'102'!I15,'103'!I15,'104'!I15,'105'!I15,'106'!I15,'107'!I15,'108'!I15,'109'!I15,'110'!I15,'111A'!I15,'111'!I15,'112'!I15,'113'!I15,'133'!I15,'134'!I15,'135'!I15,'137'!I15,'141'!I15,'144'!I15,'141'!I15,'144'!I15,'141'!I15,'144'!I15,) -> 1.3530378 | J15: =AVERAGE('120'!J15,'99'!J15,'100A'!J15,'100'!J15,'101'!J15,'102'!J15,'103'!J15,'104'!J15,'105'!J15,'106'!J15,'107'!J15,'108'!J15,'109'!J15,'110'!J15,'111A'!J15,'111'!J15,'112'!J15,'113'!J15,'133'!J15,'134'!J15,'135'!J15,'137'!J15,'141'!J15,'144'!J15,'141'!J15,'144'!J15,'141'!J15,'144'!J15,) -> 0.64696223 | ... P15: =AVERAGE('120'!P15,'99'!P15,'100A'!P15,'100'!P15,'101'!P15,'102'!P15,'103'!P15,'104'!P15,'105'!P15,'106'!P15,'107'!P15,'108'!P15,'109'!P15,'110'!P15,'111A'!P15,'111'!P15,'112'!P15,'113'!P15,'133'!P15,'134'!P15,'135'!P15,'137'!P15,'141'!P15,'144'!P15,'141'!P15,'144'!P15,'141'!P15,'144'!P15,) -> 47.393268 | R15: 1200-1300 | S15: =SUM(C30:C33) -> 27.503284 | T15: =SUM(D30:D33) -> 6.0001642 | U15: =SUM(E30:E33) -> 8.3692939 | V15: =SUM(F30:F33) -> 11.866995 | W15: =SUM(G30:G33) -> 0.39573071 | X15: =SUM(H30:H33) -> 1.1050903 | Y15: =SUM(I30:I33) -> 6.9975369 | Z15: =SUM(J30:J33) -> 3.7438424 | ... AF15: =SUM(P30:P33) -> 215.08621
B16: 08.30 - 08.45 | C16: =AVERAGE('120'!C16,'99'!C16,'100A'!C16,'100'!C16,'101'!C16,'102'!C16,'103'!C16,'104'!C16,'105'!C16,'106'!C16,'107'!C16,'108'!C16,'109'!C16,'110'!C16,'111A'!C16,'111'!C16,'112'!C16,'113'!C16,'133'!C16,'134'!C16,'135'!C16,'137'!C16,'141'!C16,'144'!C16,'141'!C16,'144'!C16,'141'!C16,'144'!C16,) -> 6.4893268 | D16: =AVERAGE('120'!D16,'99'!D16,'100A'!D16,'100'!D16,'101'!D16,'102'!D16,'103'!D16,'104'!D16,'105'!D16,'106'!D16,'107'!D16,'108'!D16,'109'!D16,'110'!D16,'111A'!D16,'111'!D16,'112'!D16,'113'!D16,'133'!D16,'134'!D16,'135'!D16,'137'!D16,'141'!D16,'144'!D16,'141'!D16,'144'!D16,'141'!D16,'144'!D16,) -> 1.2634647 | E16: =AVERAGE('120'!E16,'99'!E16,'100A'!E16,'100'!E16,'101'!E16,'102'!E16,'103'!E16,'104'!E16,'105'!E16,'106'!E16,'107'!E16,'108'!E16,'109'!E16,'110'!E16,'111A'!E16,'111'!E16,'112'!E16,'113'!E16,'133'!E16,'134'!E16,'135'!E16,'137'!E16,'141'!E16,'144'!E16,'141'!E16,'144'!E16,'141'!E16,'144'!E16,) -> 1.6872742 | F16: =AVERAGE('120'!F16,'99'!F16,'100A'!F16,'100'!F16,'101'!F16,'102'!F16,'103'!F16,'104'!F16,'105'!F16,'106'!F16,'107'!F16,'108'!F16,'109'!F16,'110'!F16,'111A'!F16,'111'!F16,'112'!F16,'113'!F16,'133'!F16,'134'!F16,'135'!F16,'137'!F16,'141'!F16,'144'!F16,'141'!F16,'144'!F16,'141'!F16,'144'!F16,) -> 2.7660099 | G16: =AVERAGE('120'!G16,'99'!G16,'100A'!G16,'100'!G16,'101'!G16,'102'!G16,'103'!G16,'104'!G16,'105'!G16,'106'!G16,'107'!G16,'108'!G16,'109'!G16,'110'!G16,'111A'!G16,'111'!G16,'112'!G16,'113'!G16,'133'!G16,'134'!G16,'135'!G16,'137'!G16,'141'!G16,'144'!G16,'141'!G16,'144'!G16,'141'!G16,'144'!G16,) -> 0.11986864 | H16: =AVERAGE('120'!H16,'99'!H16,'100A'!H16,'100'!H16,'101'!H16,'102'!H16,'103'!H16,'104'!H16,'105'!H16,'106'!H16,'107'!H16,'108'!H16,'109'!H16,'110'!H16,'111A'!H16,'111'!H16,'112'!H16,'113'!H16,'133'!H16,'134'!H16,'135'!H16,'137'!H16,'141'!H16,'144'!H16,'141'!H16,'144'!H16,'141'!H16,'144'!H16,) -> 0.21592775 | I16: =AVERAGE('120'!I16,'99'!I16,'100A'!I16,'100'!I16,'101'!I16,'102'!I16,'103'!I16,'104'!I16,'105'!I16,'106'!I16,'107'!I16,'108'!I16,'109'!I16,'110'!I16,'111A'!I16,'111'!I16,'112'!I16,'113'!I16,'133'!I16,'134'!I16,'135'!I16,'137'!I16,'141'!I16,'144'!I16,'141'!I16,'144'!I16,'141'!I16,'144'!I16,) -> 1.41133 | J16: =AVERAGE('120'!J16,'99'!J16,'100A'!J16,'100'!J16,'101'!J16,'102'!J16,'103'!J16,'104'!J16,'105'!J16,'106'!J16,'107'!J16,'108'!J16,'109'!J16,'110'!J16,'111A'!J16,'111'!J16,'112'!J16,'113'!J16,'133'!J16,'134'!J16,'135'!J16,'137'!J16,'141'!J16,'144'!J16,'141'!J16,'144'!J16,'141'!J16,'144'!J16,) -> 1.1970443 | ... P16: =AVERAGE('120'!P16,'99'!P16,'100A'!P16,'100'!P16,'101'!P16,'102'!P16,'103'!P16,'104'!P16,'105'!P16,'106'!P16,'107'!P16,'108'!P16,'109'!P16,'110'!P16,'111A'!P16,'111'!P16,'112'!P16,'113'!P16,'133'!P16,'134'!P16,'135'!P16,'137'!P16,'141'!P16,'144'!P16,'141'!P16,'144'!P16,'141'!P16,'144'!P16,) -> 48.7422 | R16: 1300-1400 | S16: =SUM(C34:C37) -> 29.228243 | T16: =SUM(D34:D37) -> 6.003202 | U16: =SUM(E34:E37) -> 9.0066502 | V16: =SUM(F34:F37) -> 11.591133 | W16: =SUM(G34:G37) -> 0.46305419 | X16: =SUM(H34:H37) -> 1.0213465 | Y16: =SUM(I34:I37) -> 7.3571429 | Z16: =SUM(J34:J37) -> 3.7668309 | ... AF16: =SUM(P34:P37) -> 220.56897
B17: 08.45 - 9.00 | C17: =AVERAGE('120'!C17,'99'!C17,'100A'!C17,'100'!C17,'101'!C17,'102'!C17,'103'!C17,'104'!C17,'105'!C17,'106'!C17,'107'!C17,'108'!C17,'109'!C17,'110'!C17,'111A'!C17,'111'!C17,'112'!C17,'113'!C17,'133'!C17,'134'!C17,'135'!C17,'137'!C17,'141'!C17,'144'!C17,'141'!C17,'144'!C17,'141'!C17,'144'!C17,) -> 5.5730706 | D17: =AVERAGE('120'!D17,'99'!D17,'100A'!D17,'100'!D17,'101'!D17,'102'!D17,'103'!D17,'104'!D17,'105'!D17,'106'!D17,'107'!D17,'108'!D17,'109'!D17,'110'!D17,'111A'!D17,'111'!D17,'112'!D17,'113'!D17,'133'!D17,'134'!D17,'135'!D17,'137'!D17,'141'!D17,'144'!D17,'141'!D17,'144'!D17,'141'!D17,'144'!D17,) -> 1.1436782 | E17: =AVERAGE('120'!E17,'99'!E17,'100A'!E17,'100'!E17,'101'!E17,'102'!E17,'103'!E17,'104'!E17,'105'!E17,'106'!E17,'107'!E17,'108'!E17,'109'!E17,'110'!E17,'111A'!E17,'111'!E17,'112'!E17,'113'!E17,'133'!E17,'134'!E17,'135'!E17,'137'!E17,'141'!E17,'144'!E17,'141'!E17,'144'!E17,'141'!E17,'144'!E17,) -> 1.9679803 | F17: =AVERAGE('120'!F17,'99'!F17,'100A'!F17,'100'!F17,'101'!F17,'102'!F17,'103'!F17,'104'!F17,'105'!F17,'106'!F17,'107'!F17,'108'!F17,'109'!F17,'110'!F17,'111A'!F17,'111'!F17,'112'!F17,'113'!F17,'133'!F17,'134'!F17,'135'!F17,'137'!F17,'141'!F17,'144'!F17,'141'!F17,'144'!F17,'141'!F17,'144'!F17,) -> 2.3817734 | G17: =AVERAGE('120'!G17,'99'!G17,'100A'!G17,'100'!G17,'101'!G17,'102'!G17,'103'!G17,'104'!G17,'105'!G17,'106'!G17,'107'!G17,'108'!G17,'109'!G17,'110'!G17,'111A'!G17,'111'!G17,'112'!G17,'113'!G17,'133'!G17,'134'!G17,'135'!G17,'137'!G17,'141'!G17,'144'!G17,'141'!G17,'144'!G17,'141'!G17,'144'!G17,) -> 0.088669951 | H17: =AVERAGE('120'!H17,'99'!H17,'100A'!H17,'100'!H17,'101'!H17,'102'!H17,'103'!H17,'104'!H17,'105'!H17,'106'!H17,'107'!H17,'108'!H17,'109'!H17,'110'!H17,'111A'!H17,'111'!H17,'112'!H17,'113'!H17,'133'!H17,'134'!H17,'135'!H17,'137'!H17,'141'!H17,'144'!H17,'141'!H17,'144'!H17,'141'!H17,'144'!H17,) -> 0.16584565 | I17: =AVERAGE('120'!I17,'99'!I17,'100A'!I17,'100'!I17,'101'!I17,'102'!I17,'103'!I17,'104'!I17,'105'!I17,'106'!I17,'107'!I17,'108'!I17,'109'!I17,'110'!I17,'111A'!I17,'111'!I17,'112'!I17,'113'!I17,'133'!I17,'134'!I17,'135'!I17,'137'!I17,'141'!I17,'144'!I17,'141'!I17,'144'!I17,'141'!I17,'144'!I17,) -> 1.3891626 | J17: =AVERAGE('120'!J17,'99'!J17,'100A'!J17,'100'!J17,'101'!J17,'102'!J17,'103'!J17,'104'!J17,'105'!J17,'106'!J17,'107'!J17,'108'!J17,'109'!J17,'110'!J17,'111A'!J17,'111'!J17,'112'!J17,'113'!J17,'133'!J17,'134'!J17,'135'!J17,'137'!J17,'141'!J17,'144'!J17,'141'!J17,'144'!J17,'141'!J17,'144'!J17,) -> 0.61740558 | ... P17: =AVERAGE('120'!P17,'99'!P17,'100A'!P17,'100'!P17,'101'!P17,'102'!P17,'103'!P17,'104'!P17,'105'!P17,'106'!P17,'107'!P17,'108'!P17,'109'!P17,'110'!P17,'111A'!P17,'111'!P17,'112'!P17,'113'!P17,'133'!P17,'134'!P17,'135'!P17,'137'!P17,'141'!P17,'144'!P17,'141'!P17,'144'!P17,'141'!P17,'144'!P17,) -> 47.472085 | R17: 1400-1500 | S17: =SUM(C38:C41) -> 28.176519 | T17: =SUM(D38:D41) -> 5.8392447 | U17: =SUM(E38:E41) -> 9.0573071 | V17: =SUM(F38:F41) -> 10.738916 | W17: =SUM(G38:G41) -> 0.28981938 | X17: =SUM(H38:H41) -> 1.2175698 | Y17: =SUM(I38:I41) -> 8.0517241 | Z17: =SUM(J38:J41) -> 3.7635468 | ... AF17: =SUM(P38:P41) -> 213.70936
B18: 09.00 - 09.15 | C18: =AVERAGE('120'!C18,'99'!C18,'100A'!C18,'100'!C18,'101'!C18,'102'!C18,'103'!C18,'104'!C18,'105'!C18,'106'!C18,'107'!C18,'108'!C18,'109'!C18,'110'!C18,'111A'!C18,'111'!C18,'112'!C18,'113'!C18,'133'!C18,'134'!C18,'135'!C18,'137'!C18,'141'!C18,'144'!C18,'141'!C18,'144'!C18,'141'!C18,'144'!C18,) -> 6.5977011 | D18: =AVERAGE('120'!D18,'99'!D18,'100A'!D18,'100'!D18,'101'!D18,'102'!D18,'103'!D18,'104'!D18,'105'!D18,'106'!D18,'107'!D18,'108'!D18,'109'!D18,'110'!D18,'111A'!D18,'111'!D18,'112'!D18,'113'!D18,'133'!D18,'134'!D18,'135'!D18,'137'!D18,'141'!D18,'144'!D18,'141'!D18,'144'!D18,'141'!D18,'144'!D18,) -> 1.2732348 | E18: =AVERAGE('120'!E18,'99'!E18,'100A'!E18,'100'!E18,'101'!E18,'102'!E18,'103'!E18,'104'!E18,'105'!E18,'106'!E18,'107'!E18,'108'!E18,'109'!E18,'110'!E18,'111A'!E18,'111'!E18,'112'!E18,'113'!E18,'133'!E18,'134'!E18,'135'!E18,'137'!E18,'141'!E18,'144'!E18,'141'!E18,'144'!E18,'141'!E18,'144'!E18,) -> 1.8581281 | F18: =AVERAGE('120'!F18,'99'!F18,'100A'!F18,'100'!F18,'101'!F18,'102'!F18,'103'!F18,'104'!F18,'105'!F18,'106'!F18,'107'!F18,'108'!F18,'109'!F18,'110'!F18,'111A'!F18,'111'!F18,'112'!F18,'113'!F18,'133'!F18,'134'!F18,'135'!F18,'137'!F18,'141'!F18,'144'!F18,'141'!F18,'144'!F18,'141'!F18,'144'!F18,) -> 3.0082102 | G18: =AVERAGE('120'!G18,'99'!G18,'100A'!G18,'100'!G18,'101'!G18,'102'!G18,'103'!G18,'104'!G18,'105'!G18,'106'!G18,'107'!G18,'108'!G18,'109'!G18,'110'!G18,'111A'!G18,'111'!G18,'112'!G18,'113'!G18,'133'!G18,'134'!G18,'135'!G18,'137'!G18,'141'!G18,'144'!G18,'141'!G18,'144'!G18,'141'!G18,'144'!G18,) -> 0.10837438 | H18: =AVERAGE('120'!H18,'99'!H18,'100A'!H18,'100'!H18,'101'!H18,'102'!H18,'103'!H18,'104'!H18,'105'!H18,'106'!H18,'107'!H18,'108'!H18,'109'!H18,'110'!H18,'111A'!H18,'111'!H18,'112'!H18,'113'!H18,'133'!H18,'134'!H18,'135'!H18,'137'!H18,'141'!H18,'144'!H18,'141'!H18,'144'!H18,'141'!H18,'144'!H18,) -> 0.45320197 | I18: =AVERAGE('120'!I18,'99'!I18,'100A'!I18,'100'!I18,'101'!I18,'102'!I18,'103'!I18,'104'!I18,'105'!I18,'106'!I18,'107'!I18,'108'!I18,'109'!I18,'110'!I18,'111A'!I18,'111'!I18,'112'!I18,'113'!I18,'133'!I18,'134'!I18,'135'!I18,'137'!I18,'141'!I18,'144'!I18,'141'!I18,'144'!I18,'141'!I18,'144'!I18,) -> 1.7175698 | J18: =AVERAGE('120'!J18,'99'!J18,'100A'!J18,'100'!J18,'101'!J18,'102'!J18,'103'!J18,'104'!J18,'105'!J18,'106'!J18,'107'!J18,'108'!J18,'109'!J18,'110'!J18,'111A'!J18,'111'!J18,'112'!J18,'113'!J18,'133'!J18,'134'!J18,'135'!J18,'137'!J18,'141'!J18,'144'!J18,'141'!J18,'144'!J18,'141'!J18,'144'!J18,) -> 1.1617406 | ... P18: =AVERAGE('120'!P18,'99'!P18,'100A'!P18,'100'!P18,'101'!P18,'102'!P18,'103'!P18,'104'!P18,'105'!P18,'106'!P18,'107'!P18,'108'!P18,'109'!P18,'110'!P18,'111A'!P18,'111'!P18,'112'!P18,'113'!P18,'133'!P18,'134'!P18,'135'!P18,'137'!P18,'141'!P18,'144'!P18,'141'!P18,'144'!P18,'141'!P18,'144'!P18,) -> 51.418719 | R18: 1500-1600 | S18: =SUM(C42:C45) -> 27.899015 | T18: =SUM(D42:D45) -> 6.1857964 | U18: =SUM(E42:E45) -> 8.9036946 | V18: =SUM(F42:F45) -> 11.688834 | W18: =SUM(G42:G45) -> 0.36453202 | X18: =SUM(H42:H45) -> 1.454023 | Y18: =SUM(I42:I45) -> 7.2504105 | Z18: =SUM(J42:J45) -> 3.7512315 | ... AF18: =SUM(P42:P45) -> 216.54269
B19: 09.15 - 09.30 | C19: =AVERAGE('120'!C19,'99'!C19,'100A'!C19,'100'!C19,'101'!C19,'102'!C19,'103'!C19,'104'!C19,'105'!C19,'106'!C19,'107'!C19,'108'!C19,'109'!C19,'110'!C19,'111A'!C19,'111'!C19,'112'!C19,'113'!C19,'133'!C19,'134'!C19,'135'!C19,'137'!C19,'141'!C19,'144'!C19,'141'!C19,'144'!C19,'141'!C19,'144'!C19,) -> 5.7167488 | D19: =AVERAGE('120'!D19,'99'!D19,'100A'!D19,'100'!D19,'101'!D19,'102'!D19,'103'!D19,'104'!D19,'105'!D19,'106'!D19,'107'!D19,'108'!D19,'109'!D19,'110'!D19,'111A'!D19,'111'!D19,'112'!D19,'113'!D19,'133'!D19,'134'!D19,'135'!D19,'137'!D19,'141'!D19,'144'!D19,'141'!D19,'144'!D19,'141'!D19,'144'!D19,) -> 1.2871921 | E19: =AVERAGE('120'!E19,'99'!E19,'100A'!E19,'100'!E19,'101'!E19,'102'!E19,'103'!E19,'104'!E19,'105'!E19,'106'!E19,'107'!E19,'108'!E19,'109'!E19,'110'!E19,'111A'!E19,'111'!E19,'112'!E19,'113'!E19,'133'!E19,'134'!E19,'135'!E19,'137'!E19,'141'!E19,'144'!E19,'141'!E19,'144'!E19,'141'!E19,'144'!E19,) -> 2.1807882 | F19: =AVERAGE('120'!F19,'99'!F19,'100A'!F19,'100'!F19,'101'!F19,'102'!F19,'103'!F19,'104'!F19,'105'!F19,'106'!F19,'107'!F19,'108'!F19,'109'!F19,'110'!F19,'111A'!F19,'111'!F19,'112'!F19,'113'!F19,'133'!F19,'134'!F19,'135'!F19,'137'!F19,'141'!F19,'144'!F19,'141'!F19,'144'!F19,'141'!F19,'144'!F19,) -> 2.4121511 | G19: =AVERAGE('120'!G19,'99'!G19,'100A'!G19,'100'!G19,'101'!G19,'102'!G19,'103'!G19,'104'!G19,'105'!G19,'106'!G19,'107'!G19,'108'!G19,'109'!G19,'110'!G19,'111A'!G19,'111'!G19,'112'!G19,'113'!G19,'133'!G19,'134'!G19,'135'!G19,'137'!G19,'141'!G19,'144'!G19,'141'!G19,'144'!G19,'141'!G19,'144'!G19,) -> 0.061576355 | H19: =AVERAGE('120'!H19,'99'!H19,'100A'!H19,'100'!H19,'101'!H19,'102'!H19,'103'!H19,'104'!H19,'105'!H19,'106'!H19,'107'!H19,'108'!H19,'109'!H19,'110'!H19,'111A'!H19,'111'!H19,'112'!H19,'113'!H19,'133'!H19,'134'!H19,'135'!H19,'137'!H19,'141'!H19,'144'!H19,'141'!H19,'144'!H19,'141'!H19,'144'!H19,) -> 0.12807882 | I19: =AVERAGE('120'!I19,'99'!I19,'100A'!I19,'100'!I19,'101'!I19,'102'!I19,'103'!I19,'104'!I19,'105'!I19,'106'!I19,'107'!I19,'108'!I19,'109'!I19,'110'!I19,'111A'!I19,'111'!I19,'112'!I19,'113'!I19,'133'!I19,'134'!I19,'135'!I19,'137'!I19,'141'!I19,'144'!I19,'141'!I19,'144'!I19,'141'!I19,'144'!I19,) -> 1.5738916 | J19: =AVERAGE('120'!J19,'99'!J19,'100A'!J19,'100'!J19,'101'!J19,'102'!J19,'103'!J19,'104'!J19,'105'!J19,'106'!J19,'107'!J19,'108'!J19,'109'!J19,'110'!J19,'111A'!J19,'111'!J19,'112'!J19,'113'!J19,'133'!J19,'134'!J19,'135'!J19,'137'!J19,'141'!J19,'144'!J19,'141'!J19,'144'!J19,'141'!J19,'144'!J19,) -> 0.65517241 | ... P19: =AVERAGE('120'!P19,'99'!P19,'100A'!P19,'100'!P19,'101'!P19,'102'!P19,'103'!P19,'104'!P19,'105'!P19,'106'!P19,'107'!P19,'108'!P19,'109'!P19,'110'!P19,'111A'!P19,'111'!P19,'112'!P19,'113'!P19,'133'!P19,'134'!P19,'135'!P19,'137'!P19,'141'!P19,'144'!P19,'141'!P19,'144'!P19,'141'!P19,'144'!P19,) -> 50.162562 | R19: 1600-1700 | S19: =SUM(C46:C49) -> 30.143678 | T19: =SUM(D46:D49) -> 6.3779146 | U19: =SUM(E46:E49) -> 9.0621511 | V19: =SUM(F46:F49) -> 11.470443 | W19: =SUM(G46:G49) -> 0.38423645 | X19: =SUM(H46:H49) -> 1.3029557 | Y19: =SUM(I46:I49) -> 7.7389163 | Z19: =SUM(J46:J49) -> 4.4400657 | ... AF19: =SUM(P46:P49) -> 230.58046
B20: 09.30 - 09.45 | C20: =AVERAGE('120'!C20,'99'!C20,'100A'!C20,'100'!C20,'101'!C20,'102'!C20,'103'!C20,'104'!C20,'105'!C20,'106'!C20,'107'!C20,'108'!C20,'109'!C20,'110'!C20,'111A'!C20,'111'!C20,'112'!C20,'113'!C20,'133'!C20,'134'!C20,'135'!C20,'137'!C20,'141'!C20,'144'!C20,'141'!C20,'144'!C20,'141'!C20,'144'!C20,) -> 6.9490969 | D20: =AVERAGE('120'!D20,'99'!D20,'100A'!D20,'100'!D20,'101'!D20,'102'!D20,'103'!D20,'104'!D20,'105'!D20,'106'!D20,'107'!D20,'108'!D20,'109'!D20,'110'!D20,'111A'!D20,'111'!D20,'112'!D20,'113'!D20,'133'!D20,'134'!D20,'135'!D20,'137'!D20,'141'!D20,'144'!D20,'141'!D20,'144'!D20,'141'!D20,'144'!D20,) -> 1.4018062 | E20: =AVERAGE('120'!E20,'99'!E20,'100A'!E20,'100'!E20,'101'!E20,'102'!E20,'103'!E20,'104'!E20,'105'!E20,'106'!E20,'107'!E20,'108'!E20,'109'!E20,'110'!E20,'111A'!E20,'111'!E20,'112'!E20,'113'!E20,'133'!E20,'134'!E20,'135'!E20,'137'!E20,'141'!E20,'144'!E20,'141'!E20,'144'!E20,'141'!E20,'144'!E20,) -> 2.3034483 | F20: =AVERAGE('120'!F20,'99'!F20,'100A'!F20,'100'!F20,'101'!F20,'102'!F20,'103'!F20,'104'!F20,'105'!F20,'106'!F20,'107'!F20,'108'!F20,'109'!F20,'110'!F20,'111A'!F20,'111'!F20,'112'!F20,'113'!F20,'133'!F20,'134'!F20,'135'!F20,'137'!F20,'141'!F20,'144'!F20,'141'!F20,'144'!F20,'141'!F20,'144'!F20,) -> 2.8932677 | G20: =AVERAGE('120'!G20,'99'!G20,'100A'!G20,'100'!G20,'101'!G20,'102'!G20,'103'!G20,'104'!G20,'105'!G20,'106'!G20,'107'!G20,'108'!G20,'109'!G20,'110'!G20,'111A'!G20,'111'!G20,'112'!G20,'113'!G20,'133'!G20,'134'!G20,'135'!G20,'137'!G20,'141'!G20,'144'!G20,'141'!G20,'144'!G20,'141'!G20,'144'!G20,) -> 0.17487685 | H20: =AVERAGE('120'!H20,'99'!H20,'100A'!H20,'100'!H20,'101'!H20,'102'!H20,'103'!H20,'104'!H20,'105'!H20,'106'!H20,'107'!H20,'108'!H20,'109'!H20,'110'!H20,'111A'!H20,'111'!H20,'112'!H20,'113'!H20,'133'!H20,'134'!H20,'135'!H20,'137'!H20,'141'!H20,'144'!H20,'141'!H20,'144'!H20,'141'!H20,'144'!H20,) -> 0.40558292 | I20: =AVERAGE('120'!I20,'99'!I20,'100A'!I20,'100'!I20,'101'!I20,'102'!I20,'103'!I20,'104'!I20,'105'!I20,'106'!I20,'107'!I20,'108'!I20,'109'!I20,'110'!I20,'111A'!I20,'111'!I20,'112'!I20,'113'!I20,'133'!I20,'134'!I20,'135'!I20,'137'!I20,'141'!I20,'144'!I20,'141'!I20,'144'!I20,'141'!I20,'144'!I20,) -> 1.5615764 | J20: =AVERAGE('120'!J20,'99'!J20,'100A'!J20,'100'!J20,'101'!J20,'102'!J20,'103'!J20,'104'!J20,'105'!J20,'106'!J20,'107'!J20,'108'!J20,'109'!J20,'110'!J20,'111A'!J20,'111'!J20,'112'!J20,'113'!J20,'133'!J20,'134'!J20,'135'!J20,'137'!J20,'141'!J20,'144'!J20,'141'!J20,'144'!J20,'141'!J20,'144'!J20,) -> 1.0985222 | ... P20: =AVERAGE('120'!P20,'99'!P20,'100A'!P20,'100'!P20,'101'!P20,'102'!P20,'103'!P20,'104'!P20,'105'!P20,'106'!P20,'107'!P20,'108'!P20,'109'!P20,'110'!P20,'111A'!P20,'111'!P20,'112'!P20,'113'!P20,'133'!P20,'134'!P20,'135'!P20,'137'!P20,'141'!P20,'144'!P20,'141'!P20,'144'!P20,'141'!P20,'144'!P20,) -> 53.347291 | R20: 1700-1800 | S20: =SUM(C50:C53) -> 32.665846 | T20: =SUM(D50:D53) -> 6.8198686 | U20: =SUM(E50:E53) -> 10.173563 | V20: =SUM(F50:F53) -> 11.920361 | W20: =SUM(G50:G53) -> 0.41050903 | X20: =SUM(H50:H53) -> 1.1280788 | Y20: =SUM(I50:I53) -> 8.2857143 | Z20: =SUM(J50:J53) -> 4.0509031 | ... AF20: =SUM(P50:P53) -> 244.73974
B21: 09.45 - 10.00 | C21: =AVERAGE('120'!C21,'99'!C21,'100A'!C21,'100'!C21,'101'!C21,'102'!C21,'103'!C21,'104'!C21,'105'!C21,'106'!C21,'107'!C21,'108'!C21,'109'!C21,'110'!C21,'111A'!C21,'111'!C21,'112'!C21,'113'!C21,'133'!C21,'134'!C21,'135'!C21,'137'!C21,'141'!C21,'144'!C21,'141'!C21,'144'!C21,'141'!C21,'144'!C21,) -> 6.4343186 | D21: =AVERAGE('120'!D21,'99'!D21,'100A'!D21,'100'!D21,'101'!D21,'102'!D21,'103'!D21,'104'!D21,'105'!D21,'106'!D21,'107'!D21,'108'!D21,'109'!D21,'110'!D21,'111A'!D21,'111'!D21,'112'!D21,'113'!D21,'133'!D21,'134'!D21,'135'!D21,'137'!D21,'141'!D21,'144'!D21,'141'!D21,'144'!D21,'141'!D21,'144'!D21,) -> 1.5151888 | E21: =AVERAGE('120'!E21,'99'!E21,'100A'!E21,'100'!E21,'101'!E21,'102'!E21,'103'!E21,'104'!E21,'105'!E21,'106'!E21,'107'!E21,'108'!E21,'109'!E21,'110'!E21,'111A'!E21,'111'!E21,'112'!E21,'113'!E21,'133'!E21,'134'!E21,'135'!E21,'137'!E21,'141'!E21,'144'!E21,'141'!E21,'144'!E21,'141'!E21,'144'!E21,) -> 2.1219212 | F21: =AVERAGE('120'!F21,'99'!F21,'100A'!F21,'100'!F21,'101'!F21,'102'!F21,'103'!F21,'104'!F21,'105'!F21,'106'!F21,'107'!F21,'108'!F21,'109'!F21,'110'!F21,'111A'!F21,'111'!F21,'112'!F21,'113'!F21,'133'!F21,'134'!F21,'135'!F21,'137'!F21,'141'!F21,'144'!F21,'141'!F21,'144'!F21,'141'!F21,'144'!F21,) -> 2.6978654 | G21: =AVERAGE('120'!G21,'99'!G21,'100A'!G21,'100'!G21,'101'!G21,'102'!G21,'103'!G21,'104'!G21,'105'!G21,'106'!G21,'107'!G21,'108'!G21,'109'!G21,'110'!G21,'111A'!G21,'111'!G21,'112'!G21,'113'!G21,'133'!G21,'134'!G21,'135'!G21,'137'!G21,'141'!G21,'144'!G21,'141'!G21,'144'!G21,'141'!G21,'144'!G21,) -> 0.15188834 | H21: =AVERAGE('120'!H21,'99'!H21,'100A'!H21,'100'!H21,'101'!H21,'102'!H21,'103'!H21,'104'!H21,'105'!H21,'106'!H21,'107'!H21,'108'!H21,'109'!H21,'110'!H21,'111A'!H21,'111'!H21,'112'!H21,'113'!H21,'133'!H21,'134'!H21,'135'!H21,'137'!H21,'141'!H21,'144'!H21,'141'!H21,'144'!H21,'141'!H21,'144'!H21,) -> 0.26600985 | I21: =AVERAGE('120'!I21,'99'!I21,'100A'!I21,'100'!I21,'101'!I21,'102'!I21,'103'!I21,'104'!I21,'105'!I21,'106'!I21,'107'!I21,'108'!I21,'109'!I21,'110'!I21,'111A'!I21,'111'!I21,'112'!I21,'113'!I21,'133'!I21,'134'!I21,'135'!I21,'137'!I21,'141'!I21,'144'!I21,'141'!I21,'144'!I21,'141'!I21,'144'!I21,) -> 1.3431856 | J21: =AVERAGE('120'!J21,'99'!J21,'100A'!J21,'100'!J21,'101'!J21,'102'!J21,'103'!J21,'104'!J21,'105'!J21,'106'!J21,'107'!J21,'108'!J21,'109'!J21,'110'!J21,'111A'!J21,'111'!J21,'112'!J21,'113'!J21,'133'!J21,'134'!J21,'135'!J21,'137'!J21,'141'!J21,'144'!J21,'141'!J21,'144'!J21,'141'!J21,'144'!J21,) -> 0.69211823 | ... P21: =AVERAGE('120'!P21,'99'!P21,'100A'!P21,'100'!P21,'101'!P21,'102'!P21,'103'!P21,'104'!P21,'105'!P21,'106'!P21,'107'!P21,'108'!P21,'109'!P21,'110'!P21,'111A'!P21,'111'!P21,'112'!P21,'113'!P21,'133'!P21,'134'!P21,'135'!P21,'137'!P21,'141'!P21,'144'!P21,'141'!P21,'144'!P21,'141'!P21,'144'!P21,) -> 52.781609 | R21: 1800-1900 | S21: =SUM(C54:C57) -> 33.367816 | T21: =SUM(D54:D57) -> 6.2383415 | U21: =SUM(E54:E57) -> 9.240312 | V21: =SUM(F54:F57) -> 11.070608 | W21: =SUM(G54:G57) -> 0.60837438 | X21: =SUM(H54:H57) -> 0.91461412 | Y21: =SUM(I54:I57) -> 7.9146141 | Z21: =SUM(J54:J57) -> 4.4679803 | ... AF21: =SUM(P54:P57) -> 244.87603
B22: 10.00 - 10.15 | C22: =AVERAGE('120'!C22,'99'!C22,'100A'!C22,'100'!C22,'101'!C22,'102'!C22,'103'!C22,'104'!C22,'105'!C22,'106'!C22,'107'!C22,'108'!C22,'109'!C22,'110'!C22,'111A'!C22,'111'!C22,'112'!C22,'113'!C22,'133'!C22,'134'!C22,'135'!C22,'137'!C22,'141'!C22,'144'!C22,'141'!C22,'144'!C22,'141'!C22,'144'!C22,) -> 6.9794745 | D22: =AVERAGE('120'!D22,'99'!D22,'100A'!D22,'100'!D22,'101'!D22,'102'!D22,'103'!D22,'104'!D22,'105'!D22,'106'!D22,'107'!D22,'108'!D22,'109'!D22,'110'!D22,'111A'!D22,'111'!D22,'112'!D22,'113'!D22,'133'!D22,'134'!D22,'135'!D22,'137'!D22,'141'!D22,'144'!D22,'141'!D22,'144'!D22,'141'!D22,'144'!D22,) -> 1.4582102 | E22: =AVERAGE('120'!E22,'99'!E22,'100A'!E22,'100'!E22,'101'!E22,'102'!E22,'103'!E22,'104'!E22,'105'!E22,'106'!E22,'107'!E22,'108'!E22,'109'!E22,'110'!E22,'111A'!E22,'111'!E22,'112'!E22,'113'!E22,'133'!E22,'134'!E22,'135'!E22,'137'!E22,'141'!E22,'144'!E22,'141'!E22,'144'!E22,'141'!E22,'144'!E22,) -> 2.1805419 | F22: =AVERAGE('120'!F22,'99'!F22,'100A'!F22,'100'!F22,'101'!F22,'102'!F22,'103'!F22,'104'!F22,'105'!F22,'106'!F22,'107'!F22,'108'!F22,'109'!F22,'110'!F22,'111A'!F22,'111'!F22,'112'!F22,'113'!F22,'133'!F22,'134'!F22,'135'!F22,'137'!F22,'141'!F22,'144'!F22,'141'!F22,'144'!F22,'141'!F22,'144'!F22,) -> 2.8924466 | G22: =AVERAGE('120'!G22,'99'!G22,'100A'!G22,'100'!G22,'101'!G22,'102'!G22,'103'!G22,'104'!G22,'105'!G22,'106'!G22,'107'!G22,'108'!G22,'109'!G22,'110'!G22,'111A'!G22,'111'!G22,'112'!G22,'113'!G22,'133'!G22,'134'!G22,'135'!G22,'137'!G22,'141'!G22,'144'!G22,'141'!G22,'144'!G22,'141'!G22,'144'!G22,) -> 0.073891626 | H22: =AVERAGE('120'!H22,'99'!H22,'100A'!H22,'100'!H22,'101'!H22,'102'!H22,'103'!H22,'104'!H22,'105'!H22,'106'!H22,'107'!H22,'108'!H22,'109'!H22,'110'!H22,'111A'!H22,'111'!H22,'112'!H22,'113'!H22,'133'!H22,'134'!H22,'135'!H22,'137'!H22,'141'!H22,'144'!H22,'141'!H22,'144'!H22,'141'!H22,'144'!H22,) -> 0.28243021 | I22: =AVERAGE('120'!I22,'99'!I22,'100A'!I22,'100'!I22,'101'!I22,'102'!I22,'103'!I22,'104'!I22,'105'!I22,'106'!I22,'107'!I22,'108'!I22,'109'!I22,'110'!I22,'111A'!I22,'111'!I22,'112'!I22,'113'!I22,'133'!I22,'134'!I22,'135'!I22,'137'!I22,'141'!I22,'144'!I22,'141'!I22,'144'!I22,'141'!I22,'144'!I22,) -> 1.7405583 | J22: =AVERAGE('120'!J22,'99'!J22,'100A'!J22,'100'!J22,'101'!J22,'102'!J22,'103'!J22,'104'!J22,'105'!J22,'106'!J22,'107'!J22,'108'!J22,'109'!J22,'110'!J22,'111A'!J22,'111'!J22,'112'!J22,'113'!J22,'133'!J22,'134'!J22,'135'!J22,'137'!J22,'141'!J22,'144'!J22,'141'!J22,'144'!J22,'141'!J22,'144'!J22,) -> 0.83004926 | ... P22: =AVERAGE('120'!P22,'99'!P22,'100A'!P22,'100'!P22,'101'!P22,'102'!P22,'103'!P22,'104'!P22,'105'!P22,'106'!P22,'107'!P22,'108'!P22,'109'!P22,'110'!P22,'111A'!P22,'111'!P22,'112'!P22,'113'!P22,'133'!P22,'134'!P22,'135'!P22,'137'!P22,'141'!P22,'144'!P22,'141'!P22,'144'!P22,'141'!P22,'144'!P22,) -> 53.433498 | R22: 1900-2000 | S22: =SUM(C58:C61) -> 32.982759 | T22: =SUM(D58:D61) -> 5.8060345 | U22: =SUM(E58:E61) -> 8.0560345 | V22: =SUM(F58:F61) -> 10.827586 | W22: =SUM(G58:G61) -> 0.5 | X22: =SUM(H58:H61) -> 0.82758621 | Y22: =SUM(I58:I61) -> 7.2241379 | Z22: =SUM(J58:J61) -> 3.7413793 | ... AF22: =SUM(P58:P61) -> 220.53448
B23: 10.15 - 10.30 | C23: =AVERAGE('120'!C23,'99'!C23,'100A'!C23,'100'!C23,'101'!C23,'102'!C23,'103'!C23,'104'!C23,'105'!C23,'106'!C23,'107'!C23,'108'!C23,'109'!C23,'110'!C23,'111A'!C23,'111'!C23,'112'!C23,'113'!C23,'133'!C23,'134'!C23,'135'!C23,'137'!C23,'141'!C23,'144'!C23,'141'!C23,'144'!C23,'141'!C23,'144'!C23,) -> 6.7183908 | D23: =AVERAGE('120'!D23,'99'!D23,'100A'!D23,'100'!D23,'101'!D23,'102'!D23,'103'!D23,'104'!D23,'105'!D23,'106'!D23,'107'!D23,'108'!D23,'109'!D23,'110'!D23,'111A'!D23,'111'!D23,'112'!D23,'113'!D23,'133'!D23,'134'!D23,'135'!D23,'137'!D23,'141'!D23,'144'!D23,'141'!D23,'144'!D23,'141'!D23,'144'!D23,) -> 1.2499179 | E23: =AVERAGE('120'!E23,'99'!E23,'100A'!E23,'100'!E23,'101'!E23,'102'!E23,'103'!E23,'104'!E23,'105'!E23,'106'!E23,'107'!E23,'108'!E23,'109'!E23,'110'!E23,'111A'!E23,'111'!E23,'112'!E23,'113'!E23,'133'!E23,'134'!E23,'135'!E23,'137'!E23,'141'!E23,'144'!E23,'141'!E23,'144'!E23,'141'!E23,'144'!E23,) -> 2.3001642 | F23: =AVERAGE('120'!F23,'99'!F23,'100A'!F23,'100'!F23,'101'!F23,'102'!F23,'103'!F23,'104'!F23,'105'!F23,'106'!F23,'107'!F23,'108'!F23,'109'!F23,'110'!F23,'111A'!F23,'111'!F23,'112'!F23,'113'!F23,'133'!F23,'134'!F23,'135'!F23,'137'!F23,'141'!F23,'144'!F23,'141'!F23,'144'!F23,'141'!F23,'144'!F23,) -> 2.6453202 | G23: =AVERAGE('120'!G23,'99'!G23,'100A'!G23,'100'!G23,'101'!G23,'102'!G23,'103'!G23,'104'!G23,'105'!G23,'106'!G23,'107'!G23,'108'!G23,'109'!G23,'110'!G23,'111A'!G23,'111'!G23,'112'!G23,'113'!G23,'133'!G23,'134'!G23,'135'!G23,'137'!G23,'141'!G23,'144'!G23,'141'!G23,'144'!G23,'141'!G23,'144'!G23,) -> 0.075533662 | H23: =AVERAGE('120'!H23,'99'!H23,'100A'!H23,'100'!H23,'101'!H23,'102'!H23,'103'!H23,'104'!H23,'105'!H23,'106'!H23,'107'!H23,'108'!H23,'109'!H23,'110'!H23,'111A'!H23,'111'!H23,'112'!H23,'113'!H23,'133'!H23,'134'!H23,'135'!H23,'137'!H23,'141'!H23,'144'!H23,'141'!H23,'144'!H23,'141'!H23,'144'!H23,) -> 0.18226601 | I23: =AVERAGE('120'!I23,'99'!I23,'100A'!I23,'100'!I23,'101'!I23,'102'!I23,'103'!I23,'104'!I23,'105'!I23,'106'!I23,'107'!I23,'108'!I23,'109'!I23,'110'!I23,'111A'!I23,'111'!I23,'112'!I23,'113'!I23,'133'!I23,'134'!I23,'135'!I23,'137'!I23,'141'!I23,'144'!I23,'141'!I23,'144'!I23,'141'!I23,'144'!I23,) -> 1.7627258 | J23: =AVERAGE('120'!J23,'99'!J23,'100A'!J23,'100'!J23,'101'!J23,'102'!J23,'103'!J23,'104'!J23,'105'!J23,'106'!J23,'107'!J23,'108'!J23,'109'!J23,'110'!J23,'111A'!J23,'111'!J23,'112'!J23,'113'!J23,'133'!J23,'134'!J23,'135'!J23,'137'!J23,'141'!J23,'144'!J23,'141'!J23,'144'!J23,'141'!J23,'144'!J23,) -> 0.70279146 | ... P23: =AVERAGE('120'!P23,'99'!P23,'100A'!P23,'100'!P23,'101'!P23,'102'!P23,'103'!P23,'104'!P23,'105'!P23,'106'!P23,'107'!P23,'108'!P23,'109'!P23,'110'!P23,'111A'!P23,'111'!P23,'112'!P23,'113'!P23,'133'!P23,'134'!P23,'135'!P23,'137'!P23,'141'!P23,'144'!P23,'141'!P23,'144'!P23,'141'!P23,'144'!P23,) -> 54.287356 | R23: 2000-2100 | S23: =SUM(C62:C65) -> 25.827586 | T23: =SUM(D62:D65) -> 5.7318966 | U23: =SUM(E62:E65) -> 7.1301724 | V23: =SUM(F62:F65) -> 7.1896552 | W23: =SUM(G62:G65) -> 0.44827586 | X23: =SUM(H62:H65) -> 0.87931034 | Y23: =SUM(I62:I65) -> 6.637931 | Z23: =SUM(J62:J65) -> 3.7068966 | ... AF23: =SUM(P62:P65) -> 150.41379
B24: 10.30 - 10.45 | C24: =AVERAGE('120'!C24,'99'!C24,'100A'!C24,'100'!C24,'101'!C24,'102'!C24,'103'!C24,'104'!C24,'105'!C24,'106'!C24,'107'!C24,'108'!C24,'109'!C24,'110'!C24,'111A'!C24,'111'!C24,'112'!C24,'113'!C24,'133'!C24,'134'!C24,'135'!C24,'137'!C24,'141'!C24,'144'!C24,'141'!C24,'144'!C24,'141'!C24,'144'!C24,) -> 7.2561576 | D24: =AVERAGE('120'!D24,'99'!D24,'100A'!D24,'100'!D24,'101'!D24,'102'!D24,'103'!D24,'104'!D24,'105'!D24,'106'!D24,'107'!D24,'108'!D24,'109'!D24,'110'!D24,'111A'!D24,'111'!D24,'112'!D24,'113'!D24,'133'!D24,'134'!D24,'135'!D24,'137'!D24,'141'!D24,'144'!D24,'141'!D24,'144'!D24,'141'!D24,'144'!D24,) -> 1.6181445 | E24: =AVERAGE('120'!E24,'99'!E24,'100A'!E24,'100'!E24,'101'!E24,'102'!E24,'103'!E24,'104'!E24,'105'!E24,'106'!E24,'107'!E24,'108'!E24,'109'!E24,'110'!E24,'111A'!E24,'111'!E24,'112'!E24,'113'!E24,'133'!E24,'134'!E24,'135'!E24,'137'!E24,'141'!E24,'144'!E24,'141'!E24,'144'!E24,'141'!E24,'144'!E24,) -> 2.0009031 | F24: =AVERAGE('120'!F24,'99'!F24,'100A'!F24,'100'!F24,'101'!F24,'102'!F24,'103'!F24,'104'!F24,'105'!F24,'106'!F24,'107'!F24,'108'!F24,'109'!F24,'110'!F24,'111A'!F24,'111'!F24,'112'!F24,'113'!F24,'133'!F24,'134'!F24,'135'!F24,'137'!F24,'141'!F24,'144'!F24,'141'!F24,'144'!F24,'141'!F24,'144'!F24,) -> 3.0525452 | G24: =AVERAGE('120'!G24,'99'!G24,'100A'!G24,'100'!G24,'101'!G24,'102'!G24,'103'!G24,'104'!G24,'105'!G24,'106'!G24,'107'!G24,'108'!G24,'109'!G24,'110'!G24,'111A'!G24,'111'!G24,'112'!G24,'113'!G24,'133'!G24,'134'!G24,'135'!G24,'137'!G24,'141'!G24,'144'!G24,'141'!G24,'144'!G24,'141'!G24,'144'!G24,) -> 0.11083744 | H24: =AVERAGE('120'!H24,'99'!H24,'100A'!H24,'100'!H24,'101'!H24,'102'!H24,'103'!H24,'104'!H24,'105'!H24,'106'!H24,'107'!H24,'108'!H24,'109'!H24,'110'!H24,'111A'!H24,'111'!H24,'112'!H24,'113'!H24,'133'!H24,'134'!H24,'135'!H24,'137'!H24,'141'!H24,'144'!H24,'141'!H24,'144'!H24,'141'!H24,'144'!H24,) -> 0.28078818 | I24: =AVERAGE('120'!I24,'99'!I24,'100A'!I24,'100'!I24,'101'!I24,'102'!I24,'103'!I24,'104'!I24,'105'!I24,'106'!I24,'107'!I24,'108'!I24,'109'!I24,'110'!I24,'111A'!I24,'111'!I24,'112'!I24,'113'!I24,'133'!I24,'134'!I24,'135'!I24,'137'!I24,'141'!I24,'144'!I24,'141'!I24,'144'!I24,'141'!I24,'144'!I24,) -> 1.7684729 | J24: =AVERAGE('120'!J24,'99'!J24,'100A'!J24,'100'!J24,'101'!J24,'102'!J24,'103'!J24,'104'!J24,'105'!J24,'106'!J24,'107'!J24,'108'!J24,'109'!J24,'110'!J24,'111A'!J24,'111'!J24,'112'!J24,'113'!J24,'133'!J24,'134'!J24,'135'!J24,'137'!J24,'141'!J24,'144'!J24,'141'!J24,'144'!J24,'141'!J24,'144'!J24,) -> 1.226601 | ... P24: =AVERAGE('120'!P24,'99'!P24,'100A'!P24,'100'!P24,'101'!P24,'102'!P24,'103'!P24,'104'!P24,'105'!P24,'106'!P24,'107'!P24,'108'!P24,'109'!P24,'110'!P24,'111A'!P24,'111'!P24,'112'!P24,'113'!P24,'133'!P24,'134'!P24,'135'!P24,'137'!P24,'141'!P24,'144'!P24,'141'!P24,'144'!P24,'141'!P24,'144'!P24,) -> 56.545977 | R24: 2100-2200 | S24: =SUM(C66:C69) -> 18.224138 | T24: =SUM(D66:D69) -> 3.9862069 | U24: =SUM(E66:E69) -> 4.9793103 | V24: =SUM(F66:F69) -> 5.0172414 | W24: =SUM(G66:G69) -> 0.37931034 | X24: =SUM(H66:H69) -> 0.87931034 | Y24: =SUM(I66:I69) -> 4.5344828 | Z24: =SUM(J66:J69) -> 2.5 | ... AF24: =SUM(P66:P69) -> 104
B25: 10.45 - 11.00 | C25: =AVERAGE('120'!C25,'99'!C25,'100A'!C25,'100'!C25,'101'!C25,'102'!C25,'103'!C25,'104'!C25,'105'!C25,'106'!C25,'107'!C25,'108'!C25,'109'!C25,'110'!C25,'111A'!C25,'111'!C25,'112'!C25,'113'!C25,'133'!C25,'134'!C25,'135'!C25,'137'!C25,'141'!C25,'144'!C25,'141'!C25,'144'!C25,'141'!C25,'144'!C25,) -> 6.8300493 | D25: =AVERAGE('120'!D25,'99'!D25,'100A'!D25,'100'!D25,'101'!D25,'102'!D25,'103'!D25,'104'!D25,'105'!D25,'106'!D25,'107'!D25,'108'!D25,'109'!D25,'110'!D25,'111A'!D25,'111'!D25,'112'!D25,'113'!D25,'133'!D25,'134'!D25,'135'!D25,'137'!D25,'141'!D25,'144'!D25,'141'!D25,'144'!D25,'141'!D25,'144'!D25,) -> 1.3198686 | E25: =AVERAGE('120'!E25,'99'!E25,'100A'!E25,'100'!E25,'101'!E25,'102'!E25,'103'!E25,'104'!E25,'105'!E25,'106'!E25,'107'!E25,'108'!E25,'109'!E25,'110'!E25,'111A'!E25,'111'!E25,'112'!E25,'113'!E25,'133'!E25,'134'!E25,'135'!E25,'137'!E25,'141'!E25,'144'!E25,'141'!E25,'144'!E25,'141'!E25,'144'!E25,) -> 2.0479475 | F25: =AVERAGE('120'!F25,'99'!F25,'100A'!F25,'100'!F25,'101'!F25,'102'!F25,'103'!F25,'104'!F25,'105'!F25,'106'!F25,'107'!F25,'108'!F25,'109'!F25,'110'!F25,'111A'!F25,'111'!F25,'112'!F25,'113'!F25,'133'!F25,'134'!F25,'135'!F25,'137'!F25,'141'!F25,'144'!F25,'141'!F25,'144'!F25,'141'!F25,'144'!F25,) -> 2.8908046 | G25: =AVERAGE('120'!G25,'99'!G25,'100A'!G25,'100'!G25,'101'!G25,'102'!G25,'103'!G25,'104'!G25,'105'!G25,'106'!G25,'107'!G25,'108'!G25,'109'!G25,'110'!G25,'111A'!G25,'111'!G25,'112'!G25,'113'!G25,'133'!G25,'134'!G25,'135'!G25,'137'!G25,'141'!G25,'144'!G25,'141'!G25,'144'!G25,'141'!G25,'144'!G25,) -> 0.083743842 | H25: =AVERAGE('120'!H25,'99'!H25,'100A'!H25,'100'!H25,'101'!H25,'102'!H25,'103'!H25,'104'!H25,'105'!H25,'106'!H25,'107'!H25,'108'!H25,'109'!H25,'110'!H25,'111A'!H25,'111'!H25,'112'!H25,'113'!H25,'133'!H25,'134'!H25,'135'!H25,'137'!H25,'141'!H25,'144'!H25,'141'!H25,'144'!H25,'141'!H25,'144'!H25,) -> 0.27586207 | I25: =AVERAGE('120'!I25,'99'!I25,'100A'!I25,'100'!I25,'101'!I25,'102'!I25,'103'!I25,'104'!I25,'105'!I25,'106'!I25,'107'!I25,'108'!I25,'109'!I25,'110'!I25,'111A'!I25,'111'!I25,'112'!I25,'113'!I25,'133'!I25,'134'!I25,'135'!I25,'137'!I25,'141'!I25,'144'!I25,'141'!I25,'144'!I25,'141'!I25,'144'!I25,) -> 1.909688 | J25: =AVERAGE('120'!J25,'99'!J25,'100A'!J25,'100'!J25,'101'!J25,'102'!J25,'103'!J25,'104'!J25,'105'!J25,'106'!J25,'107'!J25,'108'!J25,'109'!J25,'110'!J25,'111A'!J25,'111'!J25,'112'!J25,'113'!J25,'133'!J25,'134'!J25,'135'!J25,'137'!J25,'141'!J25,'144'!J25,'141'!J25,'144'!J25,'141'!J25,'144'!J25,) -> 0.68308703 | ... P25: =AVERAGE('120'!P25,'99'!P25,'100A'!P25,'100'!P25,'101'!P25,'102'!P25,'103'!P25,'104'!P25,'105'!P25,'106'!P25,'107'!P25,'108'!P25,'109'!P25,'110'!P25,'111A'!P25,'111'!P25,'112'!P25,'113'!P25,'133'!P25,'134'!P25,'135'!P25,'137'!P25,'141'!P25,'144'!P25,'141'!P25,'144'!P25,'141'!P25,'144'!P25,) -> 55.622332 | R25: 2200-2300 | S25: =SUM(C70:C73) -> 12.706897 | T25: =SUM(D70:D73) -> 2.5948276 | U25: =SUM(E70:E73) -> 3.887931 | V25: =SUM(F70:F73) -> 3.3793103 | W25: =SUM(G70:G73) -> 0.086206897 | X25: =SUM(H70:H73) -> 0.89655172 | Y25: =SUM(I70:I73) -> 3.6896552 | Z25: =SUM(J70:J73) -> 3.1034483 | ... AF25: =SUM(P70:P73) -> 68.706897
B26: 11.00 - 11.15 | C26: =AVERAGE('120'!C26,'99'!C26,'100A'!C26,'100'!C26,'101'!C26,'102'!C26,'103'!C26,'104'!C26,'105'!C26,'106'!C26,'107'!C26,'108'!C26,'109'!C26,'110'!C26,'111A'!C26,'111'!C26,'112'!C26,'113'!C26,'133'!C26,'134'!C26,'135'!C26,'137'!C26,'141'!C26,'144'!C26,'141'!C26,'144'!C26,'141'!C26,'144'!C26,) -> 7.5041051 | D26: =AVERAGE('120'!D26,'99'!D26,'100A'!D26,'100'!D26,'101'!D26,'102'!D26,'103'!D26,'104'!D26,'105'!D26,'106'!D26,'107'!D26,'108'!D26,'109'!D26,'110'!D26,'111A'!D26,'111'!D26,'112'!D26,'113'!D26,'133'!D26,'134'!D26,'135'!D26,'137'!D26,'141'!D26,'144'!D26,'141'!D26,'144'!D26,'141'!D26,'144'!D26,) -> 1.5370279 | E26: =AVERAGE('120'!E26,'99'!E26,'100A'!E26,'100'!E26,'101'!E26,'102'!E26,'103'!E26,'104'!E26,'105'!E26,'106'!E26,'107'!E26,'108'!E26,'109'!E26,'110'!E26,'111A'!E26,'111'!E26,'112'!E26,'113'!E26,'133'!E26,'134'!E26,'135'!E26,'137'!E26,'141'!E26,'144'!E26,'141'!E26,'144'!E26,'141'!E26,'144'!E26,) -> 2.2396552 | F26: =AVERAGE('120'!F26,'99'!F26,'100A'!F26,'100'!F26,'101'!F26,'102'!F26,'103'!F26,'104'!F26,'105'!F26,'106'!F26,'107'!F26,'108'!F26,'109'!F26,'110'!F26,'111A'!F26,'111'!F26,'112'!F26,'113'!F26,'133'!F26,'134'!F26,'135'!F26,'137'!F26,'141'!F26,'144'!F26,'141'!F26,'144'!F26,'141'!F26,'144'!F26,) -> 3.2118227 | G26: =AVERAGE('120'!G26,'99'!G26,'100A'!G26,'100'!G26,'101'!G26,'102'!G26,'103'!G26,'104'!G26,'105'!G26,'106'!G26,'107'!G26,'108'!G26,'109'!G26,'110'!G26,'111A'!G26,'111'!G26,'112'!G26,'113'!G26,'133'!G26,'134'!G26,'135'!G26,'137'!G26,'141'!G26,'144'!G26,'141'!G26,'144'!G26,'141'!G26,'144'!G26,) -> 0.091954023 | H26: =AVERAGE('120'!H26,'99'!H26,'100A'!H26,'100'!H26,'101'!H26,'102'!H26,'103'!H26,'104'!H26,'105'!H26,'106'!H26,'107'!H26,'108'!H26,'109'!H26,'110'!H26,'111A'!H26,'111'!H26,'112'!H26,'113'!H26,'133'!H26,'134'!H26,'135'!H26,'137'!H26,'141'!H26,'144'!H26,'141'!H26,'144'!H26,'141'!H26,'144'!H26,) -> 0.22824302 | I26: =AVERAGE('120'!I26,'99'!I26,'100A'!I26,'100'!I26,'101'!I26,'102'!I26,'103'!I26,'104'!I26,'105'!I26,'106'!I26,'107'!I26,'108'!I26,'109'!I26,'110'!I26,'111A'!I26,'111'!I26,'112'!I26,'113'!I26,'133'!I26,'134'!I26,'135'!I26,'137'!I26,'141'!I26,'144'!I26,'141'!I26,'144'!I26,'141'!I26,'144'!I26,) -> 1.6740558 | J26: =AVERAGE('120'!J26,'99'!J26,'100A'!J26,'100'!J26,'101'!J26,'102'!J26,'103'!J26,'104'!J26,'105'!J26,'106'!J26,'107'!J26,'108'!J26,'109'!J26,'110'!J26,'111A'!J26,'111'!J26,'112'!J26,'113'!J26,'133'!J26,'134'!J26,'135'!J26,'137'!J26,'141'!J26,'144'!J26,'141'!J26,'144'!J26,'141'!J26,'144'!J26,) -> 1.0410509 | ... P26: =AVERAGE('120'!P26,'99'!P26,'100A'!P26,'100'!P26,'101'!P26,'102'!P26,'103'!P26,'104'!P26,'105'!P26,'106'!P26,'107'!P26,'108'!P26,'109'!P26,'110'!P26,'111A'!P26,'111'!P26,'112'!P26,'113'!P26,'133'!P26,'134'!P26,'135'!P26,'137'!P26,'141'!P26,'144'!P26,'141'!P26,'144'!P26,'141'!P26,'144'!P26,) -> 56.102627 | R26: 2300-0000 | S26: =SUM(C74:C77) -> 7.6206897 | T26: =SUM(D74:D77) -> 2.0362069 | U26: =SUM(E74:E77) -> 2.0844828 | V26: =SUM(F74:F77) -> 2.6206897 | W26: =SUM(G74:G77) -> 0.18965517 | X26: =SUM(H74:H77) -> 0.89655172 | Y26: =SUM(I74:I77) -> 2.9310345 | Z26: =SUM(J74:J77) -> 2.1206897 | ... AF26: =SUM(P74:P77) -> 40.896552
B27: 11.15 - 11.30 | C27: =AVERAGE('120'!C27,'99'!C27,'100A'!C27,'100'!C27,'101'!C27,'102'!C27,'103'!C27,'104'!C27,'105'!C27,'106'!C27,'107'!C27,'108'!C27,'109'!C27,'110'!C27,'111A'!C27,'111'!C27,'112'!C27,'113'!C27,'133'!C27,'134'!C27,'135'!C27,'137'!C27,'141'!C27,'144'!C27,'141'!C27,'144'!C27,'141'!C27,'144'!C27,) -> 6.7668309 | D27: =AVERAGE('120'!D27,'99'!D27,'100A'!D27,'100'!D27,'101'!D27,'102'!D27,'103'!D27,'104'!D27,'105'!D27,'106'!D27,'107'!D27,'108'!D27,'109'!D27,'110'!D27,'111A'!D27,'111'!D27,'112'!D27,'113'!D27,'133'!D27,'134'!D27,'135'!D27,'137'!D27,'141'!D27,'144'!D27,'141'!D27,'144'!D27,'141'!D27,'144'!D27,) -> 1.5231527 | E27: =AVERAGE('120'!E27,'99'!E27,'100A'!E27,'100'!E27,'101'!E27,'102'!E27,'103'!E27,'104'!E27,'105'!E27,'106'!E27,'107'!E27,'108'!E27,'109'!E27,'110'!E27,'111A'!E27,'111'!E27,'112'!E27,'113'!E27,'133'!E27,'134'!E27,'135'!E27,'137'!E27,'141'!E27,'144'!E27,'141'!E27,'144'!E27,'141'!E27,'144'!E27,) -> 2.0014778 | F27: =AVERAGE('120'!F27,'99'!F27,'100A'!F27,'100'!F27,'101'!F27,'102'!F27,'103'!F27,'104'!F27,'105'!F27,'106'!F27,'107'!F27,'108'!F27,'109'!F27,'110'!F27,'111A'!F27,'111'!F27,'112'!F27,'113'!F27,'133'!F27,'134'!F27,'135'!F27,'137'!F27,'141'!F27,'144'!F27,'141'!F27,'144'!F27,'141'!F27,'144'!F27,) -> 2.6871921 | G27: =AVERAGE('120'!G27,'99'!G27,'100A'!G27,'100'!G27,'101'!G27,'102'!G27,'103'!G27,'104'!G27,'105'!G27,'106'!G27,'107'!G27,'108'!G27,'109'!G27,'110'!G27,'111A'!G27,'111'!G27,'112'!G27,'113'!G27,'133'!G27,'134'!G27,'135'!G27,'137'!G27,'141'!G27,'144'!G27,'141'!G27,'144'!G27,'141'!G27,'144'!G27,) -> 0.073891626 | H27: =AVERAGE('120'!H27,'99'!H27,'100A'!H27,'100'!H27,'101'!H27,'102'!H27,'103'!H27,'104'!H27,'105'!H27,'106'!H27,'107'!H27,'108'!H27,'109'!H27,'110'!H27,'111A'!H27,'111'!H27,'112'!H27,'113'!H27,'133'!H27,'134'!H27,'135'!H27,'137'!H27,'141'!H27,'144'!H27,'141'!H27,'144'!H27,'141'!H27,'144'!H27,) -> 0.22003284 | I27: =AVERAGE('120'!I27,'99'!I27,'100A'!I27,'100'!I27,'101'!I27,'102'!I27,'103'!I27,'104'!I27,'105'!I27,'106'!I27,'107'!I27,'108'!I27,'109'!I27,'110'!I27,'111A'!I27,'111'!I27,'112'!I27,'113'!I27,'133'!I27,'134'!I27,'135'!I27,'137'!I27,'141'!I27,'144'!I27,'141'!I27,'144'!I27,'141'!I27,'144'!I27,) -> 1.5139573 | J27: =AVERAGE('120'!J27,'99'!J27,'100A'!J27,'100'!J27,'101'!J27,'102'!J27,'103'!J27,'104'!J27,'105'!J27,'106'!J27,'107'!J27,'108'!J27,'109'!J27,'110'!J27,'111A'!J27,'111'!J27,'112'!J27,'113'!J27,'133'!J27,'134'!J27,'135'!J27,'137'!J27,'141'!J27,'144'!J27,'141'!J27,'144'!J27,'141'!J27,'144'!J27,) -> 0.73727422 | ... P27: =AVERAGE('120'!P27,'99'!P27,'100A'!P27,'100'!P27,'101'!P27,'102'!P27,'103'!P27,'104'!P27,'105'!P27,'106'!P27,'107'!P27,'108'!P27,'109'!P27,'110'!P27,'111A'!P27,'111'!P27,'112'!P27,'113'!P27,'133'!P27,'134'!P27,'135'!P27,'137'!P27,'141'!P27,'144'!P27,'141'!P27,'144'!P27,'141'!P27,'144'!P27,) -> 57.125616 | R27: 0000-0100 | S27: =SUM(C78:C81) -> 4.8448276 | T27: =SUM(D78:D81) -> 1.6474138 | U27: =SUM(E78:E81) -> 1.8698276 | V27: =SUM(F78:F81) -> 1.8275862 | W27: =SUM(G78:G81) -> 0.4137931 | X27: =SUM(H78:H81) -> 0.84482759 | Y27: =SUM(I78:I81) -> 2.6034483 | Z27: =SUM(J78:J81) -> 1.5172414 | ... AF27: =SUM(P78:P81) -> 28.155172
