Workbook

Sheet 25.10 Lyantonde-Rushere
B1: Consultancy services for Preparation of Expressway Development Master Plan (EDMP) for Uganda
B2: MANUAL CLASSIFIED COUNT (MCC)
B3: ROAD NAME: | C3: MCC- C4- TN103 - LYANTONDE-RUSHERE ROAD
C5: Date | D5: 25.10.19 | F5: Location | G5: Kaguta road JTC | J5: Surveyor | K5: Josephine
C6: Dir. From | D6: Lyantonde | F6: Dir. To | G6: Rushere | J6: Supervisor | K6: Nusulah
B8: Time / Veh Type | R8: SUMMARY TRAFFIC VOLUMES
C9: 1. Car | D9: 2. Station Wagon | E9: 3. Pickups | F9: 4. Minibus, matatu | G9: 5. Medium bus | H9: 6. Large Bus | I9: 7. Light Truck | J9: 8. Medium Truck | K9: 9. Heavy truck | L9: 10. Truck Trailer | M9: 11. Motor cycles | N9: 12. Tractors | O9: Total Excl M/Cycles | P9: Total All | R9: Time | S9: 1. Car | T9: 2. Station Wagon | U9: 3. Pickups | V9: 4. Minibus, matatu | W9: 5. Medium bus | X9: 6. Large Bus | Y9: 7. Light Truck | Z9: 8. Medium Truck | AA9: 9. Heavy truck | AB9: 10. Truck Trailer | AC9: 11. Motorcycles | AD9: 12. Tractors, Graders | AE9: Total Excl M/ Cycles | AF9: Total All
B10: 07.00 - 07.15 | C10: 1 | D10: 2 | E10: 0 | F10: 1 | G10: 0 | H10: 0 | I10: 0 | J10: 0 | K10: 0 | L10: 0 | M10: 4 | N10: 0 | O10: =SUM(C10:L10,N10) -> 4 | P10: =SUM(C10:N10) -> 8 | R10: 0700-0800 | S10: =SUM(C10:C13) -> 8 | T10: =SUM(D10:D13) -> 2 | U10: =SUM(E10:E13) -> 0 | V10: =SUM(F10:F13) -> 1 | W10: =SUM(G10:G13) -> 0 | X10: =SUM(H10:H13) -> 0 | Y10: =SUM(I10:I13) -> 0 | Z10: =SUM(J10:J13) -> 0 | ... AF10: =SUM(P10:P13) -> 22
B11: 07.15 - 07.30 | C11: 1 | D11: 0 | E11: 0 | F11: 0 | G11: 0 | H11: 0 | I11: 0 | J11: 0 | K11: 0 | L11: 0 | M11: 2 | N11: 0 | O11: =SUM(C11:L11,N11) -> 1 | P11: =SUM(C11:N11) -> 3 | R11: 0800-0900 | S11: =SUM(C14:C17) -> 12 | T11: =SUM(D14:D17) -> 2 | U11: =SUM(E14:E17) -> 1 | V11: =SUM(F14:F17) -> 0 | W11: =SUM(G14:G17) -> 0 | X11: =SUM(H14:H17) -> 0 | Y11: =SUM(I14:I17) -> 3 | Z11: =SUM(J14:J17) -> 0 | ... AF11: =SUM(P14:P17) -> 40
B12: 07.30 - 07.45 | C12: 2 | D12: 0 | E12: 0 | F12: 0 | G12: 0 | H12: 0 | I12: 0 | J12: 0 | K12: 0 | L12: 0 | M12: 3 | N12: 0 | O12: =SUM(C12:L12,N12) -> 2 | P12: =SUM(C12:N12) -> 5 | R12: 0900-1000 | S12: =SUM(C18:C21) -> 16 | T12: =SUM(D18:D21) -> 2 | U12: =SUM(E18:E21) -> 7 | V12: =SUM(F18:F21) -> 1 | W12: =SUM(G18:G21) -> 0 | X12: =SUM(H18:H21) -> 1 | Y12: =SUM(I18:I21) -> 2 | Z12: =SUM(J18:J21) -> 3 | ... AF12: =SUM(P18:P21) -> 54
B13: 07.45 - 08.00 | C13: 4 | D13: 0 | E13: 0 | F13: 0 | G13: 0 | H13: 0 | I13: 0 | J13: 0 | K13: 0 | L13: 0 | M13: 2 | N13: 0 | O13: =SUM(C13:L13,N13) -> 4 | P13: =SUM(C13:N13) -> 6 | R13: 1000-1100 | S13: =SUM(C22:C25) -> 6 | T13: =SUM(D22:D25) -> 8 | U13: =SUM(E22:E25) -> 3 | V13: =SUM(F22:F25) -> 0 | W13: =SUM(G22:G25) -> 0 | X13: =SUM(H22:H25) -> 0 | Y13: =SUM(I22:I25) -> 2 | Z13: =SUM(J22:J25) -> 1 | ... AF13: =SUM(P22:P25) -> 54
B14: 08.00 - 08.15 | C14: 6 | D14: 0 | E14: 0 | F14: 0 | G14: 0 | H14: 0 | I14: 0 | J14: 0 | K14: 0 | L14: 0 | M14: 4 | N14: 0 | O14: =SUM(C14:L14,N14) -> 6 | P14: =SUM(C14:N14) -> 10 | R14: 1100-1200 | S14: =SUM(C26:C29) -> 16 | T14: =SUM(D26:D29) -> 6 | U14: =SUM(E26:E29) -> 3 | V14: =SUM(F26:F29) -> 1 | W14: =SUM(G26:G29) -> 0 | X14: =SUM(H26:H29) -> 0 | Y14: =SUM(I26:I29) -> 5 | Z14: =SUM(J26:J29) -> 2 | ... AF14: =SUM(P26:P29) -> 61
B15: 08.15 - 08.30 | C15: 4 | D15: 1 | E15: 0 | F15: 0 | G15: 0 | H15: 0 | I15: 1 | J15: 0 | K15: 0 | L15: 0 | M15: 4 | N15: 0 | O15: =SUM(C15:L15,N15) -> 6 | P15: =SUM(C15:N15) -> 10 | R15: 1200-1300 | S15: =SUM(C30:C33) -> 13 | T15: =SUM(D30:D33) -> 8 | U15: =SUM(E30:E33) -> 2 | V15: =SUM(F30:F33) -> 2 | W15: =SUM(G30:G33) -> 0 | X15: =SUM(H30:H33) -> 0 | Y15: =SUM(I30:I33) -> 0 | Z15: =SUM(J30:J33) -> 1 | ... AF15: =SUM(P30:P33) -> 51
B16: 08.30 - 08.45 | C16: 1 | D16: 1 | E16: 0 | F16: 0 | G16: 0 | H16: 0 | I16: 1 | J16: 0 | K16: 0 | L16: 0 | M16: 6 | N16: 0 | O16: =SUM(C16:L16,N16) -> 3 | P16: =SUM(C16:N16) -> 9 | R16: 1300-1400 | S16: =SUM(C34:C37) -> 19 | T16: =SUM(D34:D37) -> 8 | U16: =SUM(E34:E37) -> 0 | V16: =SUM(F34:F37) -> 1 | W16: =SUM(G34:G37) -> 0 | X16: =SUM(H34:H37) -> 0 | Y16: =SUM(I34:I37) -> 1 | Z16: =SUM(J34:J37) -> 6 | ... AF16: =SUM(P34:P37) -> 64
B17: 08.45 - 9.00 | C17: 1 | D17: 0 | E17: 1 | F17: 0 | G17: 0 | H17: 0 | I17: 1 | J17: 0 | K17: 1 | L17: 0 | M17: 7 | N17: 0 | O17: =SUM(C17:L17,N17) -> 4 | P17: =SUM(C17:N17) -> 11 | R17: 1400-1500 | S17: =SUM(C38:C41) -> 9 | T17: =SUM(D38:D41) -> 3 | U17: =SUM(E38:E41) -> 3 | V17: =SUM(F38:F41) -> 1 | W17: =SUM(G38:G41) -> 0 | X17: =SUM(H38:H41) -> 0 | Y17: =SUM(I38:I41) -> 2 | Z17: =SUM(J38:J41) -> 5 | ... AF17: =SUM(P38:P41) -> 52
B18: 09.00 - 09.15 | C18: 5 | D18: 2 | E18: 0 | F18: 0 | G18: 0 | H18: 0 | I18: 0 | J18: 1 | K18: 0 | L18: 0 | M18: 5 | N18: 0 | O18: =SUM(C18:L18,N18) -> 8 | P18: =SUM(C18:N18) -> 13 | R18: 1500-1600 | S18: =SUM(C42:C45) -> 17 | T18: =SUM(D42:D45) -> 9 | U18: =SUM(E42:E45) -> 2 | V18: =SUM(F42:F45) -> 0 | W18: =SUM(G42:G45) -> 0 | X18: =SUM(H42:H45) -> 1 | Y18: =SUM(I42:I45) -> 2 | Z18: =SUM(J42:J45) -> 4 | ... AF18: =SUM(P42:P45) -> 58
B19: 09.15 - 09.30 | C19: 5 | D19: 0 | E19: 6 | F19: 0 | G19: 0 | H19: 0 | I19: 0 | J19: 0 | K19: 0 | L19: 0 | M19: 5 | N19: 0 | O19: =SUM(C19:L19,N19) -> 11 | P19: =SUM(C19:N19) -> 16 | R19: 1600-1700 | S19: =SUM(C46:C49) -> 12 | T19: =SUM(D46:D49) -> 3 | U19: =SUM(E46:E49) -> 1 | V19: =SUM(F46:F49) -> 0 | W19: =SUM(G46:G49) -> 0 | X19: =SUM(H46:H49) -> 0 | Y19: =SUM(I46:I49) -> 0 | Z19: =SUM(J46:J49) -> 2 | ... AF19: =SUM(P46:P49) -> 48
B20: 09.30 - 09.45 | C20: 3 | D20: 0 | E20: 1 | F20: 1 | G20: 0 | H20: 0 | I20: 1 | J20: 2 | K20: 0 | L20: 0 | M20: 8 | N20: 0 | O20: =SUM(C20:L20,N20) -> 8 | P20: =SUM(C20:N20) -> 16 | R20: 1700-1800 | S20: =SUM(C50:C53) -> 15 | T20: =SUM(D50:D53) -> 8 | U20: =SUM(E50:E53) -> 0 | V20: =SUM(F50:F53) -> 2 | W20: =SUM(G50:G53) -> 0 | X20: =SUM(H50:H53) -> 1 | Y20: =SUM(I50:I53) -> 3 | Z20: =SUM(J50:J53) -> 1 | ... AF20: =SUM(P50:P53) -> 61
B21: 09.45 - 10.00 | C21: 3 | D21: 0 | E21: 0 | F21: 0 | G21: 0 | H21: 1 | I21: 1 | J21: 0 | K21: 0 | L21: 0 | M21: 4 | N21: 0 | O21: =SUM(C21:L21,N21) -> 5 | P21: =SUM(C21:N21) -> 9 | R21: 1800-1900 | S21: =SUM(C54:C57) -> 27 | T21: =SUM(D54:D57) -> 6 | U21: =SUM(E54:E57) -> 3 | V21: =SUM(F54:F57) -> 1 | W21: =SUM(G54:G57) -> 0 | X21: =SUM(H54:H57) -> 0 | Y21: =SUM(I54:I57) -> 7 | Z21: =SUM(J54:J57) -> 1 | ... AF21: =SUM(P54:P57) -> 87
B22: 10.00 - 10.15 | C22: 1 | D22: 3 | E22: 1 | F22: 0 | G22: 0 | H22: 0 | I22: 0 | J22: 0 | K22: 0 | L22: 0 | M22: 7 | N22: 0 | O22: =SUM(C22:L22,N22) -> 5 | P22: =SUM(C22:N22) -> 12 | R22: AM Peak Hr | S22: =MAX(S10:S12) -> 16 | T22: =MAX(T10:T12) -> 2 | U22: =MAX(U10:U12) -> 7 | V22: =MAX(V10:V12) -> 1 | W22: =MAX(W10:W12) -> 0 | X22: =MAX(X10:X12) -> 1 | Y22: =MAX(Y10:Y12) -> 3 | Z22: =MAX(Z10:Z12) -> 3 | ... AF22: =MAX(AF10:AF12) -> 54
B23: 10.15 - 10.30 | C23: 3 | D23: 3 | E23: 2 | F23: 0 | G23: 0 | H23: 0 | I23: 0 | J23: 0 | K23: 1 | L23: 2 | M23: 8 | N23: 0 | O23: =SUM(C23:L23,N23) -> 11 | P23: =SUM(C23:N23) -> 19 | R23: IP Peak Hr | S23: =MAX(S13:S18) -> 19 | T23: =MAX(T13:T18) -> 9 | U23: =MAX(U13:U18) -> 3 | V23: =MAX(V13:V18) -> 2 | W23: =MAX(W13:W18) -> 0 | X23: =MAX(X13:X18) -> 1 | Y23: =MAX(Y13:Y18) -> 5 | Z23: =MAX(Z13:Z18) -> 6 | ... AF23: =MAX(AF13:AF18) -> 64
B24: 10.30 - 10.45 | C24: 2 | D24: 1 | E24: 0 | F24: 0 | G24: 0 | H24: 0 | I24: 1 | J24: 1 | K24: 0 | L24: 0 | M24: 7 | N24: 0 | O24: =SUM(C24:L24,N24) -> 5 | P24: =SUM(C24:N24) -> 12 | R24: PM Peak Hr | S24: =MAX(S19:S21) -> 27 | T24: =MAX(T19:T21) -> 8 | U24: =MAX(U19:U21) -> 3 | V24: =MAX(V19:V21) -> 2 | W24: =MAX(W19:W21) -> 0 | X24: =MAX(X19:X21) -> 1 | Y24: =MAX(Y19:Y21) -> 7 | Z24: =MAX(Z19:Z21) -> 2 | ... AF24: =MAX(AF19:AF21) -> 87
B25: 10.45 - 11.00 | C25: 0 | D25: 1 | E25: 0 | F25: 0 | G25: 0 | H25: 0 | I25: 1 | J25: 0 | K25: 0 | L25: 0 | M25: 9 | N25: 0 | O25: =SUM(C25:L25,N25) -> 2 | P25: =SUM(C25:N25) -> 11 | R25: AM Period | S25: =SUM(S10:S12) -> 36 | T25: =SUM(T10:T12) -> 6 | U25: =SUM(U10:U12) -> 8 | V25: =SUM(V10:V12) -> 2 | W25: =SUM(W10:W12) -> 0 | X25: =SUM(X10:X12) -> 1 | Y25: =SUM(Y10:Y12) -> 5 | Z25: =SUM(Z10:Z12) -> 3 | ... AF25: =SUM(AF10:AF12) -> 116
B26: 11.00 - 11.15 | C26: 2 | D26: 2 | E26: 0 | F26: 0 | G26: 0 | H26: 0 | I26: 2 | J26: 0 | K26: 0 | L26: 0 | M26: 6 | N26: 0 | O26: =SUM(C26:L26,N26) -> 6 | P26: =SUM(C26:N26) -> 12 | R26: IP Period | S26: =SUM(S13:S18) -> 80 | T26: =SUM(T13:T18) -> 42 | U26: =SUM(U13:U18) -> 13 | V26: =SUM(V13:V18) -> 5 | W26: =SUM(W13:W18) -> 0 | X26: =SUM(X13:X18) -> 1 | Y26: =SUM(Y13:Y18) -> 12 | Z26: =SUM(Z13:Z18) -> 19 | ... AF26: =SUM(AF13:AF18) -> 340
B27: 11.15 - 11.30 | C27: 2 | D27: 2 | E27: 0 | F27: 0 | G27: 0 | H27: 0 | I27: 0 | J27: 1 | K27: 0 | L27: 0 | M27: 6 | N27: 0 | O27: =SUM(C27:L27,N27) -> 5 | P27: =SUM(C27:N27) -> 11 | R27: PM Period | S27: =SUM(S19:S21) -> 54 | T27: =SUM(T19:T21) -> 17 | U27: =SUM(U19:U21) -> 4 | V27: =SUM(V19:V21) -> 3 | W27: =SUM(W19:W21) -> 0 | X27: =SUM(X19:X21) -> 1 | Y27: =SUM(Y19:Y21) -> 10 | Z27: =SUM(Z19:Z21) -> 4 | ... AF27: =SUM(AF19:AF21) -> 196
B28: 11.30 - 11.45 | C28: 9 | D28: 2 | E28: 0 | F28: 0 | G28: 0 | H28: 0 | I28: 3 | J28: 1 | K28: 0 | L28: 0 | M28: 7 | N28: 0 | O28: =SUM(C28:L28,N28) -> 15 | P28: =SUM(C28:N28) -> 22 | R28: 12 Hours | S28: =SUM(S10:S21) -> 170 | T28: =SUM(T10:T21) -> 65 | U28: =SUM(U10:U21) -> 25 | V28: =SUM(V10:V21) -> 10 | W28: =SUM(W10:W21) -> 0 | X28: =SUM(X10:X21) -> 3 | Y28: =SUM(Y10:Y21) -> 27 | Z28: =SUM(Z10:Z21) -> 26 | ... AF28: =SUM(AF10:AF21) -> 652
B29: 11.45 - 12.00 | C29: 3 | D29: 0 | E29: 3 | F29: 1 | G29: 0 | H29: 0 | I29: 0 | J29: 0 | K29: 0 | L29: 0 | M29: 9 | N29: 0 | O29: =SUM(C29:L29,N29) -> 7 | P29: =SUM(C29:N29) -> 16
B30: 12.00 - 12.15 | C30: 2 | D30: 2 | E30: 0 | F30: 0 | G30: 0 | H30: 0 | I30: 0 | J30: 0 | K30: 1 | L30: 0 | M30: 6 | N30: 0 | O30: =SUM(C30:L30,N30) -> 5 | P30: =SUM(C30:N30) -> 11
B31: 12.15 - 12.30 | C31: 3 | D31: 4 | E31: 1 | F31: 0 | G31: 0 | H31: 0 | I31: 0 | J31: 1 | K31: 0 | L31: 0 | M31: 3 | N31: 0 | O31: =SUM(C31:L31,N31) -> 9 | P31: =SUM(C31:N31) -> 12
B32: 12.30 - 12.45 | C32: 4 | D32: 1 | E32: 0 | F32: 2 | G32: 0 | H32: 0 | I32: 0 | J32: 0 | K32: 1 | L32: 2 | M32: 6 | N32: 0 | O32: =SUM(C32:L32,N32) -> 10 | P32: =SUM(C32:N32) -> 16
B33: 12.45 - 13.00 | C33: 4 | D33: 1 | E33: 1 | F33: 0 | G33: 0 | H33: 0 | I33: 0 | J33: 0 | K33: 2 | L33: 0 | M33: 4 | N33: 0 | O33: =SUM(C33:L33,N33) -> 8 | P33: =SUM(C33:N33) -> 12
B34: 13.00 - 13.15 | C34: 5 | D34: 4 | E34: 0 | F34: 0 | G34: 0 | H34: 0 | I34: 0 | J34: 0 | K34: 0 | L34: 0 | M34: 9 | N34: 0 | O34: =SUM(C34:L34,N34) -> 9 | P34: =SUM(C34:N34) -> 18
B35: 13.15 - 13.30 | C35: 7 | D35: 0 | E35: 0 | F35: 0 | G35: 0 | H35: 0 | I35: 0 | J35: 3 | K35: 0 | L35: 0 | M35: 6 | N35: 0 | O35: =SUM(C35:L35,N35) -> 10 | P35: =SUM(C35:N35) -> 16
B36: 13.30 - 13.45 | C36: 3 | D36: 0 | E36: 0 | F36: 0 | G36: 0 | H36: 0 | I36: 1 | J36: 1 | K36: 0 | L36: 0 | M36: 5 | N36: 0 | O36: =SUM(C36:L36,N36) -> 5 | P36: =SUM(C36:N36) -> 10
B37: 13.45 - 14.00 | C37: 4 | D37: 4 | E37: 0 | F37: 1 | G37: 0 | H37: 0 | I37: 0 | J37: 2 | K37: 1 | L37: 0 | M37: 8 | N37: 0 | O37: =SUM(C37:L37,N37) -> 12 | P37: =SUM(C37:N37) -> 20
B38: 14.00 - 14.15 | C38: 2 | D38: 1 | E38: 0 | F38: 0 | G38: 0 | H38: 0 | I38: 1 | J38: 2 | K38: 0 | L38: 2 | M38: 6 | N38: 0 | O38: =SUM(C38:L38,N38) -> 8 | P38: =SUM(C38:N38) -> 14
B39: 14.15 - 14.30 | C39: 1 | D39: 0 | E39: 0 | F39: 0 | G39: 0 | H39: 0 | I39: 0 | J39: 0 | K39: 0 | L39: 0 | M39: 8 | N39: 0 | O39: =SUM(C39:L39,N39) -> 1 | P39: =SUM(C39:N39) -> 9
B40: 14.30 - 14.45 | C40: 4 | D40: 2 | E40: 2 | F40: 1 | G40: 0 | H40: 0 | I40: 0 | J40: 1 | K40: 0 | L40: 1 | M40: 7 | N40: 0 | O40: =SUM(C40:L40,N40) -> 11 | P40: =SUM(C40:N40) -> 18
... B57: 18.45 - 19.00 | C57: 8 | D57: 3 | E57: 1 | F57: 0 | G57: 0 | H57: 0 | I57: 2 | J57: 0 | K57: 2 | L57: 1 | M57: 12 | N57: 0 | O57: =SUM(C57:L57,N57) -> 17 | P57: =SUM(C57:N57) -> 29
B58: Totals | C58: =SUM(C10:C57) -> 170 | D58: =SUM(D10:D57) -> 65 | E58: =SUM(E10:E57) -> 25 | F58: =SUM(F10:F57) -> 10 | G58: =SUM(G10:G57) -> 0 | H58: =SUM(H10:H57) -> 3 | I58: =SUM(I10:I57) -> 27 | J58: =SUM(J10:J57) -> 26 | ... P58: =SUM(P10:P57) -> 652
...

Sheet 25.10 Rushere-Lyantonde
B1: Consultancy services for Preparation of Expressway Development Master Plan (EDMP) for Uganda
B2: MANUAL CLASSIFIED COUNT (MCC)
B3: ROAD NAME: | C3: ='25.10 Lyantonde-Rushere'!C3:G3 -> MCC- C4- TN103 - LYANTONDE-RUSHERE ROAD
C5: Date | D5: ='25.10 Lyantonde-Rushere'!D5 -> 25.10.19 | F5: Location | G5: ='25.10 Lyantonde-Rushere'!G5:H5 -> Kaguta road JTC | J5: Surveyor | K5: Nusulah
C6: Dir. From | D6: Rushere | F6: Dir. To | G6: Lyantonde | J6: Supervisor | K6: ='25.10 Lyantonde-Rushere'!K6:L6 -> Nusulah
B8: Time / Veh Type | R8: SUMMARY TRAFFIC VOLUMES
C9: 1. Car | D9: 2. Station Wagon | E9: 3. Pickups | F9: 4. Minibus, matatu | G9: 5. Medium bus | H9: 6. Large Bus | I9: 7. Light Truck | J9: 8. Medium Truck | K9: 9. Heavy truck | L9: 10. Truck Trailer | M9: 11. Motor cycles | N9: 12. Tractors | O9: Total Excl M/Cycles | P9: Total All | R9: Time | S9: 1. Car | T9: 2. Station Wagon | U9: 3. Pickups | V9: 4. Minibus, matatu | W9: 5. Medium bus | X9: 6. Large Bus | Y9: 7. Light Truck | Z9: 8. Medium Truck | AA9: 9. Heavy truck | AB9: 10. Truck Trailer | AC9: 11. Motorcycles | AD9: 12. Tractors, Graders | AE9: Total Excl M/ Cycles | AF9: Total All
B10: 07.00 - 07.15 | C10: 2 | D10: 1 | E10: 1 | F10: 2 | G10: 1 | H10: 0 | I10: 0 | J10: 0 | K10: 0 | L10: 0 | M10: 2 | N10: 0 | O10: =SUM(C10:L10,N10) -> 7 | P10: =SUM(C10:N10) -> 9 | R10: 0700-0800 | S10: =SUM(C10:C13) -> 8 | T10: =SUM(D10:D13) -> 6 | U10: =SUM(E10:E13) -> 2 | V10: =SUM(F10:F13) -> 5 | W10: =SUM(G10:G13) -> 1 | X10: =SUM(H10:H13) -> 1 | Y10: =SUM(I10:I13) -> 0 | Z10: =SUM(J10:J13) -> 0 | ... AF10: =SUM(P10:P13) -> 34
B11: 07.15 - 07.30 | C11: 1 | D11: 2 | E11: 1 | F11: 2 | G11: 0 | H11: 1 | I11: 0 | J11: 0 | K11: 0 | L11: 0 | M11: 3 | N11: 0 | O11: =SUM(C11:L11,N11) -> 7 | P11: =SUM(C11:N11) -> 10 | R11: 0800-0900 | S11: =SUM(C14:C17) -> 7 | T11: =SUM(D14:D17) -> 1 | U11: =SUM(E14:E17) -> 0 | V11: =SUM(F14:F17) -> 0 | W11: =SUM(G14:G17) -> 0 | X11: =SUM(H14:H17) -> 0 | Y11: =SUM(I14:I17) -> 0 | Z11: =SUM(J14:J17) -> 1 | ... AF11: =SUM(P14:P17) -> 24
B12: 07.30 - 07.45 | C12: 2 | D12: 0 | E12: 0 | F12: 1 | G12: 0 | H12: 0 | I12: 0 | J12: 0 | K12: 0 | L12: 0 | M12: 4 | N12: 0 | O12: =SUM(C12:L12,N12) -> 3 | P12: =SUM(C12:N12) -> 7 | R12: 0900-1000 | S12: =SUM(C18:C21) -> 24 | T12: =SUM(D18:D21) -> 6 | U12: =SUM(E18:E21) -> 2 | V12: =SUM(F18:F21) -> 0 | W12: =SUM(G18:G21) -> 0 | X12: =SUM(H18:H21) -> 1 | Y12: =SUM(I18:I21) -> 5 | Z12: =SUM(J18:J21) -> 1 | ... AF12: =SUM(P18:P21) -> 60
B13: 07.45 - 08.00 | C13: 3 | D13: 3 | E13: 0 | F13: 0 | G13: 0 | H13: 0 | I13: 0 | J13: 0 | K13: 0 | L13: 0 | M13: 2 | N13: 0 | O13: =SUM(C13:L13,N13) -> 6 | P13: =SUM(C13:N13) -> 8 | R13: 1000-1100 | S13: =SUM(C22:C25) -> 11 | T13: =SUM(D22:D25) -> 4 | U13: =SUM(E22:E25) -> 0 | V13: =SUM(F22:F25) -> 0 | W13: =SUM(G22:G25) -> 1 | X13: =SUM(H22:H25) -> 1 | Y13: =SUM(I22:I25) -> 0 | Z13: =SUM(J22:J25) -> 0 | ... AF13: =SUM(P22:P25) -> 38
B14: 08.00 - 08.15 | C14: 3 | D14: 1 | E14: 0 | F14: 0 | G14: 0 | H14: 0 | I14: 0 | J14: 0 | K14: 0 | L14: 0 | M14: 0 | N14: 0 | O14: =SUM(C14:L14,N14) -> 4 | P14: =SUM(C14:N14) -> 4 | R14: 1100-1200 | S14: =SUM(C26:C29) -> 9 | T14: =SUM(D26:D29) -> 1 | U14: =SUM(E26:E29) -> 3 | V14: =SUM(F26:F29) -> 0 | W14: =SUM(G26:G29) -> 0 | X14: =SUM(H26:H29) -> 0 | Y14: =SUM(I26:I29) -> 1 | Z14: =SUM(J26:J29) -> 0 | ... AF14: =SUM(P26:P29) -> 42
B15: 08.15 - 08.30 | C15: 1 | D15: 0 | E15: 0 | F15: 0 | G15: 0 | H15: 0 | I15: 0 | J15: 0 | K15: 0 | L15: 0 | M15: 3 | N15: 0 | O15: =SUM(C15:L15,N15) -> 1 | P15: =SUM(C15:N15) -> 4 | R15: 1200-1300 | S15: =SUM(C30:C33) -> 10 | T15: =SUM(D30:D33) -> 8 | U15: =SUM(E30:E33) -> 5 | V15: =SUM(F30:F33) -> 0 | W15: =SUM(G30:G33) -> 0 | X15: =SUM(H30:H33) -> 0 | Y15: =SUM(I30:I33) -> 1 | Z15: =SUM(J30:J33) -> 2 | ... AF15: =SUM(P30:P33) -> 56
B16: 08.30 - 08.45 | C16: 2 | D16: 0 | E16: 0 | F16: 0 | G16: 0 | H16: 0 | I16: 0 | J16: 0 | K16: 0 | L16: 0 | M16: 8 | N16: 0 | O16: =SUM(C16:L16,N16) -> 2 | P16: =SUM(C16:N16) -> 10 | R16: 1300-1400 | S16: =SUM(C34:C37) -> 11 | T16: =SUM(D34:D37) -> 6 | U16: =SUM(E34:E37) -> 4 | V16: =SUM(F34:F37) -> 1 | W16: =SUM(G34:G37) -> 0 | X16: =SUM(H34:H37) -> 0 | Y16: =SUM(I34:I37) -> 6 | Z16: =SUM(J34:J37) -> 0 | ... AF16: =SUM(P34:P37) -> 53
B17: 08.45 - 9.00 | C17: 1 | D17: 0 | E17: 0 | F17: 0 | G17: 0 | H17: 0 | I17: 0 | J17: 1 | K17: 0 | L17: 0 | M17: 4 | N17: 0 | O17: =SUM(C17:L17,N17) -> 2 | P17: =SUM(C17:N17) -> 6 | R17: 1400-1500 | S17: =SUM(C38:C41) -> 10 | T17: =SUM(D38:D41) -> 7 | U17: =SUM(E38:E41) -> 3 | V17: =SUM(F38:F41) -> 0 | W17: =SUM(G38:G41) -> 0 | X17: =SUM(H38:H41) -> 0 | Y17: =SUM(I38:I41) -> 2 | Z17: =SUM(J38:J41) -> 3 | ... AF17: =SUM(P38:P41) -> 44
B18: 09.00 - 09.15 | C18: 6 | D18: 3 | E18: 0 | F18: 0 | G18: 0 | H18: 0 | I18: 0 | J18: 0 | K18: 0 | L18: 0 | M18: 5 | N18: 0 | O18: =SUM(C18:L18,N18) -> 9 | P18: =SUM(C18:N18) -> 14 | R18: 1500-1600 | S18: =SUM(C42:C45) -> 11 | T18: =SUM(D42:D45) -> 6 | U18: =SUM(E42:E45) -> 3 | V18: =SUM(F42:F45) -> 0 | W18: =SUM(G42:G45) -> 0 | X18: =SUM(H42:H45) -> 0 | Y18: =SUM(I42:I45) -> 4 | Z18: =SUM(J42:J45) -> 4 | ... AF18: =SUM(P42:P45) -> 54
B19: 09.15 - 09.30 | C19: 5 | D19: 1 | E19: 1 | F19: 0 | G19: 0 | H19: 0 | I19: 1 | J19: 0 | K19: 0 | L19: 0 | M19: 4 | N19: 0 | O19: =SUM(C19:L19,N19) -> 8 | P19: =SUM(C19:N19) -> 12 | R19: 1600-1700 | S19: =SUM(C46:C49) -> 11 | T19: =SUM(D46:D49) -> 11 | U19: =SUM(E46:E49) -> 4 | V19: =SUM(F46:F49) -> 1 | W19: =SUM(G46:G49) -> 0 | X19: =SUM(H46:H49) -> 0 | Y19: =SUM(I46:I49) -> 4 | Z19: =SUM(J46:J49) -> 6 | ... AF19: =SUM(P46:P49) -> 75
B20: 09.30 - 09.45 | C20: 7 | D20: 0 | E20: 0 | F20: 0 | G20: 0 | H20: 1 | I20: 3 | J20: 0 | K20: 0 | L20: 0 | M20: 3 | N20: 0 | O20: =SUM(C20:L20,N20) -> 11 | P20: =SUM(C20:N20) -> 14 | R20: 1700-1800 | S20: =SUM(C50:C53) -> 20 | T20: =SUM(D50:D53) -> 6 | U20: =SUM(E50:E53) -> 3 | V20: =SUM(F50:F53) -> 3 | W20: =SUM(G50:G53) -> 0 | X20: =SUM(H50:H53) -> 0 | Y20: =SUM(I50:I53) -> 3 | Z20: =SUM(J50:J53) -> 7 | ... AF20: =SUM(P50:P53) -> 93
B21: 09.45 - 10.00 | C21: 6 | D21: 2 | E21: 1 | F21: 0 | G21: 0 | H21: 0 | I21: 1 | J21: 1 | K21: 0 | L21: 0 | M21: 9 | N21: 0 | O21: =SUM(C21:L21,N21) -> 11 | P21: =SUM(C21:N21) -> 20 | R21: 1800-1900 | S21: =SUM(C54:C57) -> 12 | T21: =SUM(D54:D57) -> 8 | U21: =SUM(E54:E57) -> 6 | V21: =SUM(F54:F57) -> 3 | W21: =SUM(G54:G57) -> 2 | X21: =SUM(H54:H57) -> 0 | Y21: =SUM(I54:I57) -> 10 | Z21: =SUM(J54:J57) -> 8 | ... AF21: =SUM(P54:P57) -> 68
B22: 10.00 - 10.15 | C22: 5 | D22: 1 | E22: 0 | F22: 0 | G22: 0 | H22: 0 | I22: 0 | J22: 0 | K22: 0 | L22: 0 | M22: 4 | N22: 0 | O22: =SUM(C22:L22,N22) -> 6 | P22: =SUM(C22:N22) -> 10 | R22: AM Peak Hr | S22: =MAX(S10:S12) -> 24 | T22: =MAX(T10:T12) -> 6 | U22: =MAX(U10:U12) -> 2 | V22: =MAX(V10:V12) -> 5 | W22: =MAX(W10:W12) -> 1 | X22: =MAX(X10:X12) -> 1 | Y22: =MAX(Y10:Y12) -> 5 | Z22: =MAX(Z10:Z12) -> 1 | ... AF22: =MAX(AF10:AF12) -> 60
B23: 10.15 - 10.30 | C23: 3 | D23: 2 | E23: 0 | F23: 0 | G23: 0 | H23: 0 | I23: 0 | J23: 0 | K23: 0 | L23: 0 | M23: 0 | N23: 0 | O23: =SUM(C23:L23,N23) -> 5 | P23: =SUM(C23:N23) -> 5 | R23: IP Peak Hr | S23: =MAX(S13:S18) -> 11 | T23: =MAX(T13:T18) -> 8 | U23: =MAX(U13:U18) -> 5 | V23: =MAX(V13:V18) -> 1 | W23: =MAX(W13:W18) -> 1 | X23: =MAX(X13:X18) -> 1 | Y23: =MAX(Y13:Y18) -> 6 | Z23: =MAX(Z13:Z18) -> 4 | ... AF23: =MAX(AF13:AF18) -> 56
B24: 10.30 - 10.45 | C24: 2 | D24: 1 | E24: 0 | F24: 0 | G24: 1 | H24: 1 | I24: 0 | J24: 0 | K24: 0 | L24: 0 | M24: 7 | N24: 0 | O24: =SUM(C24:L24,N24) -> 5 | P24: =SUM(C24:N24) -> 12 | R24: PM Peak Hr | S24: =MAX(S19:S21) -> 20 | T24: =MAX(T19:T21) -> 11 | U24: =MAX(U19:U21) -> 6 | V24: =MAX(V19:V21) -> 3 | W24: =MAX(W19:W21) -> 2 | X24: =MAX(X19:X21) -> 0 | Y24: =MAX(Y19:Y21) -> 10 | Z24: =MAX(Z19:Z21) -> 8 | ... AF24: =MAX(AF19:AF21) -> 93
B25: 10.45 - 11.00 | C25: 1 | D25: 0 | E25: 0 | F25: 0 | G25: 0 | H25: 0 | I25: 0 | J25: 0 | K25: 0 | L25: 0 | M25: 10 | N25: 0 | O25: =SUM(C25:L25,N25) -> 1 | P25: =SUM(C25:N25) -> 11 | R25: AM Period | S25: =SUM(S10:S12) -> 39 | T25: =SUM(T10:T12) -> 13 | U25: =SUM(U10:U12) -> 4 | V25: =SUM(V10:V12) -> 5 | W25: =SUM(W10:W12) -> 1 | X25: =SUM(X10:X12) -> 2 | Y25: =SUM(Y10:Y12) -> 5 | Z25: =SUM(Z10:Z12) -> 2 | ... AF25: =SUM(AF10:AF12) -> 118
B26: 11.00 - 11.15 | C26: 2 | D26: 0 | E26: 1 | F26: 0 | G26: 0 | H26: 0 | I26: 1 | J26: 0 | K26: 0 | L26: 0 | M26: 6 | N26: 0 | O26: =SUM(C26:L26,N26) -> 4 | P26: =SUM(C26:N26) -> 10 | R26: IP Period | S26: =SUM(S13:S18) -> 62 | T26: =SUM(T13:T18) -> 32 | U26: =SUM(U13:U18) -> 18 | V26: =SUM(V13:V18) -> 1 | W26: =SUM(W13:W18) -> 1 | X26: =SUM(X13:X18) -> 1 | Y26: =SUM(Y13:Y18) -> 14 | Z26: =SUM(Z13:Z18) -> 9 | ... AF26: =SUM(AF13:AF18) -> 287
B27: 11.15 - 11.30 | C27: 6 | D27: 0 | E27: 0 | F27: 0 | G27: 0 | H27: 0 | I27: 0 | J27: 0 | K27: 0 | L27: 1 | M27: 5 | N27: 0 | O27: =SUM(C27:L27,N27) -> 7 | P27: =SUM(C27:N27) -> 12 | R27: PM Period | S27: =SUM(S19:S21) -> 43 | T27: =SUM(T19:T21) -> 25 | U27: =SUM(U19:U21) -> 13 | V27: =SUM(V19:V21) -> 7 | W27: =SUM(W19:W21) -> 2 | X27: =SUM(X19:X21) -> 0 | Y27: =SUM(Y19:Y21) -> 17 | Z27: =SUM(Z19:Z21) -> 21 | ... AF27: =SUM(AF19:AF21) -> 236
B28: 11.30 - 11.45 | C28: 0 | D28: 1 | E28: 2 | F28: 0 | G28: 0 | H28: 0 | I28: 0 | J28: 0 | K28: 0 | L28: 0 | M28: 8 | N28: 0 | O28: =SUM(C28:L28,N28) -> 3 | P28: =SUM(C28:N28) -> 11 | R28: 12 Hours | S28: =SUM(S10:S21) -> 144 | T28: =SUM(T10:T21) -> 70 | U28: =SUM(U10:U21) -> 35 | V28: =SUM(V10:V21) -> 13 | W28: =SUM(W10:W21) -> 4 | X28: =SUM(X10:X21) -> 3 | Y28: =SUM(Y10:Y21) -> 36 | Z28: =SUM(Z10:Z21) -> 32 | ... AF28: =SUM(AF10:AF21) -> 641
B29: 11.45 - 12.00 | C29: 1 | D29: 0 | E29: 0 | F29: 0 | G29: 0 | H29: 0 | I29: 0 | J29: 0 | K29: 0 | L29: 0 | M29: 8 | N29: 0 | O29: =SUM(C29:L29,N29) -> 1 | P29: =SUM(C29:N29) -> 9
B30: 12.00 - 12.15 | C30: 0 | D30: 0 | E30: 0 | F30: 0 | G30: 0 | H30: 0 | I30: 0 | J30: 0 | K30: 0 | L30: 0 | M30: 10 | N30: 0 | O30: =SUM(C30:L30,N30) -> 0 | P30: =SUM(C30:N30) -> 10
B31: 12.15 - 12.30 | C31: 5 | D31: 2 | E31: 0 | F31: 0 | G31: 0 | H31: 0 | I31: 0 | J31: 0 | K31: 0 | L31: 0 | M31: 5 | N31: 0 | O31: =SUM(C31:L31,N31) -> 7 | P31: =SUM(C31:N31) -> 12
B32: 12.30 - 12.45 | C32: 2 | D32: 2 | E32: 2 | F32: 0 | G32: 0 | H32: 0 | I32: 1 | J32: 2 | K32: 0 | L32: 0 | M32: 8 | N32: 0 | O32: =SUM(C32:L32,N32) -> 9 | P32: =SUM(C32:N32) -> 17
B33: 12.45 - 13.00 | C33: 3 | D33: 4 | E33: 3 | F33: 0 | G33: 0 | H33: 0 | I33: 0 | J33: 0 | K33: 0 | L33: 0 | M33: 7 | N33: 0 | O33: =SUM(C33:L33,N33) -> 10 | P33: =SUM(C33:N33) -> 17
B34: 13.00 - 13.15 | C34: 3 | D34: 1 | E34: 0 | F34: 0 | G34: 0 | H34: 0 | I34: 2 | J34: 0 | K34: 0 | L34: 0 | M34: 7 | N34: 0 | O34: =SUM(C34:L34,N34) -> 6 | P34: =SUM(C34:N34) -> 13
B35: 13.15 - 13.30 | C35: 4 | D35: 1 | E35: 0 | F35: 0 | G35: 0 | H35: 0 | I35: 0 | J35: 0 | K35: 0 | L35: 0 | M35: 6 | N35: 0 | O35: =SUM(C35:L35,N35) -> 5 | P35: =SUM(C35:N35) -> 11
B36: 13.30 - 13.45 | C36: 1 | D36: 2 | E36: 4 | F36: 1 | G36: 0 | H36: 0 | I36: 3 | J36: 0 | K36: 0 | L36: 1 | M36: 4 | N36: 0 | O36: =SUM(C36:L36,N36) -> 12 | P36: =SUM(C36:N36) -> 16
B37: 13.45 - 14.00 | C37: 3 | D37: 2 | E37: 0 | F37: 0 | G37: 0 | H37: 0 | I37: 1 | J37: 0 | K37: 0 | L37: 0 | M37: 7 | N37: 0 | O37: =SUM(C37:L37,N37) -> 6 | P37: =SUM(C37:N37) -> 13
B38: 14.00 - 14.15 | C38: 3 | D38: 2 | E38: 0 | F38: 0 | G38: 0 | H38: 0 | I38: 0 | J38: 1 | K38: 0 | L38: 1 | M38: 5 | N38: 0 | O38: =SUM(C38:L38,N38) -> 7 | P38: =SUM(C38:N38) -> 12
B39: 14.15 - 14.30 | C39: 3 | D39: 1 | E39: 0 | F39: 0 | G39: 0 | H39: 0 | I39: 0 | J39: 0 | K39: 0 | L39: 0 | M39: 3 | N39: 0 | O39: =SUM(C39:L39,N39) -> 4 | P39: =SUM(C39:N39) -> 7
B40: 14.30 - 14.45 | C40: 2 | D40: 4 | E40: 1 | F40: 0 | G40: 0 | H40: 0 | I40: 2 | J40: 1 | K40: 0 | L40: 0 | M40: 6 | N40: 0 | O40: =SUM(C40:L40,N40) -> 10 | P40: =SUM(C40:N40) -> 16
... B57: 18.45 - 19.00 | C57: 5 | D57: 5 | E57: 2 | F57: 0 | G57: 0 | H57: 0 | I57: 3 | J57: 2 | K57: 2 | L57: 1 | M57: 4 | N57: 0 | O57: =SUM(C57:L57,N57) -> 20 | P57: =SUM(C57:N57) -> 24
B58: Totals | C58: =SUM(C10:C57) -> 144 | D58: =SUM(D10:D57) -> 70 | E58: =SUM(E10:E57) -> 35 | F58: =SUM(F10:F57) -> 13 | G58: =SUM(G10:G57) -> 4 | H58: =SUM(H10:H57) -> 3 | I58: =SUM(I10:I57) -> 36 | J58: =SUM(J10:J57) -> 32 | ... P58: =SUM(P10:P57) -> 641
...

Sheet 26.10 Lyantonde-Rushere-24hr
B1: Consultancy services for Preparation of Expressway Development Master Plan (EDMP) for Uganda
B2: MANUAL CLASSIFIED COUNT (MCC)
B3: ROAD NAME: | C3: ='25.10 Lyantonde-Rushere'!C3:G3 -> MCC- C4- TN103 - LYANTONDE-RUSHERE ROAD
C5: Date | D5: 26.10.19 | F5: Location | G5: ='30.10 Rushere-Lyantonde'!G5:H5 -> Kaguta road JTC | J5: Surveyor | K5: Josephine, Kobusingye
C6: Dir. From | D6: ='25.10 Lyantonde-Rushere'!D6:E6 -> Lyantonde | F6: Dir. To | G6: ='25.10 Lyantonde-Rushere'!G6:H6 -> Rushere | J6: Supervisor | K6: ='30.10 Rushere-Lyantonde'!K6:L6 -> Nusulah
B8: Time / Veh Type | R8: SUMMARY TRAFFIC VOLUMES
C9: 1. Car | D9: 2. Station Wagon | E9: 3. Pickups | F9: 4. Minibus, matatu | G9: 5. Medium bus | H9: 6. Large Bus | I9: 7. Light Truck | J9: 8. Medium Truck | K9: 9. Heavy truck | L9: 10. Truck Trailer | M9: 11. Motor cycles | N9: 12. Tractors | O9: Total Excl M/Cycles | P9: Total All | R9: Time | S9: 1. Car | T9: 2. Station Wagon | U9: 3. Pickups | V9: 4. Minibus, matatu | W9: 5. Medium bus | X9: 6. Large Bus | Y9: 7. Light Truck | Z9: 8. Medium Truck | AA9: 9. Heavy truck | AB9: 10. Truck Trailer | AC9: 11. Motorcycles | AD9: 12. Tractors, Graders | AE9: Total Excl M/ Cycles | AF9: Total All
B10: 07.00 - 07.15 | C10: 3 | D10: 1 | E10: 0 | F10: 1 | G10: 0 | H10: 0 | I10: 2 | J10: 0 | K10: 0 | L10: 1 | M10: 3 | N10: 0 | O10: =SUM(C10:L10,N10) -> 8 | P10: =SUM(C10:N10) -> 11 | R10: 0700-0800 | S10: =SUM(C10:C13) -> 16 | T10: =SUM(D10:D13) -> 7 | U10: =SUM(E10:E13) -> 2 | V10: =SUM(F10:F13) -> 1 | W10: =SUM(G10:G13) -> 0 | X10: =SUM(H10:H13) -> 0 | Y10: =SUM(I10:I13) -> 2 | Z10: =SUM(J10:J13) -> 0 | ... AF10: =SUM(P10:P13) -> 48
B11: 07.15 - 07.30 | C11: 4 | D11: 2 | E11: 0 | F11: 0 | G11: 0 | H11: 0 | I11: 0 | J11: 0 | K11: 2 | L11: 0 | M11: 4 | N11: 0 | O11: =SUM(C11:L11,N11) -> 8 | P11: =SUM(C11:N11) -> 12 | R11: 0800-0900 | S11: =SUM(C14:C17) -> 9 | T11: =SUM(D14:D17) -> 7 | U11: =SUM(E14:E17) -> 1 | V11: =SUM(F14:F17) -> 2 | W11: =SUM(G14:G17) -> 0 | X11: =SUM(H14:H17) -> 0 | Y11: =SUM(I14:I17) -> 0 | Z11: =SUM(J14:J17) -> 0 | ... AF11: =SUM(P14:P17) -> 28
B12: 07.30 - 07.45 | C12: 4 | D12: 1 | E12: 2 | F12: 0 | G12: 0 | H12: 0 | I12: 0 | J12: 0 | K12: 0 | L12: 0 | M12: 6 | N12: 0 | O12: =SUM(C12:L12,N12) -> 7 | P12: =SUM(C12:N12) -> 13 | R12: 0900-1000 | S12: =SUM(C18:C21) -> 14 | T12: =SUM(D18:D21) -> 18 | U12: =SUM(E18:E21) -> 1 | V12: =SUM(F18:F21) -> 2 | W12: =SUM(G18:G21) -> 0 | X12: =SUM(H18:H21) -> 0 | Y12: =SUM(I18:I21) -> 0 | Z12: =SUM(J18:J21) -> 0 | ... AF12: =SUM(P18:P21) -> 45
B13: 07.45 - 08.00 | C13: 5 | D13: 3 | E13: 0 | F13: 0 | G13: 0 | H13: 0 | I13: 0 | J13: 0 | K13: 0 | L13: 1 | M13: 3 | N13: 0 | O13: =SUM(C13:L13,N13) -> 9 | P13: =SUM(C13:N13) -> 12 | R13: 1000-1100 | S13: =SUM(C22:C25) -> 12 | T13: =SUM(D22:D25) -> 12 | U13: =SUM(E22:E25) -> 4 | V13: =SUM(F22:F25) -> 2 | W13: =SUM(G22:G25) -> 1 | X13: =SUM(H22:H25) -> 0 | Y13: =SUM(I22:I25) -> 0 | Z13: =SUM(J22:J25) -> 1 | ... AF13: =SUM(P22:P25) -> 48
B14: 08.00 - 08.15 | C14: 2 | D14: 2 | E14: 0 | F14: 0 | G14: 0 | H14: 0 | I14: 0 | J14: 0 | K14: 0 | L14: 2 | M14: 0 | N14: 0 | O14: =SUM(C14:L14,N14) -> 6 | P14: =SUM(C14:N14) -> 6 | R14: 1100-1200 | S14: =SUM(C26:C29) -> 20 | T14: =SUM(D26:D29) -> 15 | U14: =SUM(E26:E29) -> 8 | V14: =SUM(F26:F29) -> 4 | W14: =SUM(G26:G29) -> 0 | X14: =SUM(H26:H29) -> 0 | Y14: =SUM(I26:I29) -> 0 | Z14: =SUM(J26:J29) -> 2 | ... AF14: =SUM(P26:P29) -> 68
B15: 08.15 - 08.30 | C15: 3 | D15: 1 | E15: 0 | F15: 0 | G15: 0 | H15: 0 | I15: 0 | J15: 0 | K15: 0 | L15: 1 | M15: 2 | N15: 0 | O15: =SUM(C15:L15,N15) -> 5 | P15: =SUM(C15:N15) -> 7 | R15: 1200-1300 | S15: =SUM(C30:C33) -> 28 | T15: =SUM(D30:D33) -> 8 | U15: =SUM(E30:E33) -> 3 | V15: =SUM(F30:F33) -> 4 | W15: =SUM(G30:G33) -> 0 | X15: =SUM(H30:H33) -> 0 | Y15: =SUM(I30:I33) -> 0 | Z15: =SUM(J30:J33) -> 2 | ... AF15: =SUM(P30:P33) -> 70
B16: 08.30 - 08.45 | C16: 3 | D16: 3 | E16: 1 | F16: 1 | G16: 0 | H16: 0 | I16: 0 | J16: 0 | K16: 0 | L16: 1 | M16: 0 | N16: 0 | O16: =SUM(C16:L16,N16) -> 9 | P16: =SUM(C16:N16) -> 9 | R16: 1300-1400 | S16: =SUM(C34:C37) -> 21 | T16: =SUM(D34:D37) -> 4 | U16: =SUM(E34:E37) -> 2 | V16: =SUM(F34:F37) -> 0 | W16: =SUM(G34:G37) -> 0 | X16: =SUM(H34:H37) -> 0 | Y16: =SUM(I34:I37) -> 3 | Z16: =SUM(J34:J37) -> 2 | ... AF16: =SUM(P34:P37) -> 54
B17: 08.45 - 9.00 | C17: 1 | D17: 1 | E17: 0 | F17: 1 | G17: 0 | H17: 0 | I17: 0 | J17: 0 | K17: 0 | L17: 1 | M17: 2 | N17: 0 | O17: =SUM(C17:L17,N17) -> 4 | P17: =SUM(C17:N17) -> 6 | R17: 1400-1500 | S17: =SUM(C38:C41) -> 28 | T17: =SUM(D38:D41) -> 3 | U17: =SUM(E38:E41) -> 4 | V17: =SUM(F38:F41) -> 0 | W17: =SUM(G38:G41) -> 0 | X17: =SUM(H38:H41) -> 0 | Y17: =SUM(I38:I41) -> 2 | Z17: =SUM(J38:J41) -> 3 | ... AF17: =SUM(P38:P41) -> 64
B18: 09.00 - 09.15 | C18: 4 | D18: 4 | E18: 1 | F18: 1 | G18: 0 | H18: 0 | I18: 0 | J18: 0 | K18: 0 | L18: 0 | M18: 2 | N18: 0 | O18: =SUM(C18:L18,N18) -> 10 | P18: =SUM(C18:N18) -> 12 | R18: 1500-1600 | S18: =SUM(C42:C45) -> 18 | T18: =SUM(D42:D45) -> 5 | U18: =SUM(E42:E45) -> 3 | V18: =SUM(F42:F45) -> 0 | W18: =SUM(G42:G45) -> 0 | X18: =SUM(H42:H45) -> 1 | Y18: =SUM(I42:I45) -> 1 | Z18: =SUM(J42:J45) -> 4 | ... AF18: =SUM(P42:P45) -> 53
B19: 09.15 - 09.30 | C19: 5 | D19: 9 | E19: 0 | F19: 0 | G19: 0 | H19: 0 | I19: 0 | J19: 0 | K19: 0 | L19: 0 | M19: 3 | N19: 0 | O19: =SUM(C19:L19,N19) -> 14 | P19: =SUM(C19:N19) -> 17 | R19: 1600-1700 | S19: =SUM(C46:C49) -> 11 | T19: =SUM(D46:D49) -> 4 | U19: =SUM(E46:E49) -> 0 | V19: =SUM(F46:F49) -> 0 | W19: =SUM(G46:G49) -> 0 | X19: =SUM(H46:H49) -> 0 | Y19: =SUM(I46:I49) -> 3 | Z19: =SUM(J46:J49) -> 0 | ... AF19: =SUM(P46:P49) -> 42
B20: 09.30 - 09.45 | C20: 3 | D20: 3 | E20: 0 | F20: 1 | G20: 0 | H20: 0 | I20: 0 | J20: 0 | K20: 0 | L20: 0 | M20: 3 | N20: 0 | O20: =SUM(C20:L20,N20) -> 7 | P20: =SUM(C20:N20) -> 10 | R20: 1700-1800 | S20: =SUM(C50:C53) -> 26 | T20: =SUM(D50:D53) -> 7 | U20: =SUM(E50:E53) -> 3 | V20: =SUM(F50:F53) -> 3 | W20: =SUM(G50:G53) -> 0 | X20: =SUM(H50:H53) -> 0 | Y20: =SUM(I50:I53) -> 1 | Z20: =SUM(J50:J53) -> 0 | ... AF20: =SUM(P50:P53) -> 74
B21: 09.45 - 10.00 | C21: 2 | D21: 2 | E21: 0 | F21: 0 | G21: 0 | H21: 0 | I21: 0 | J21: 0 | K21: 0 | L21: 0 | M21: 2 | N21: 0 | O21: =SUM(C21:L21,N21) -> 4 | P21: =SUM(C21:N21) -> 6 | R21: 1800-1900 | S21: =SUM(C54:C57) -> 22 | T21: =SUM(D54:D57) -> 9 | U21: =SUM(E54:E57) -> 8 | V21: =SUM(F54:F57) -> 1 | W21: =SUM(G54:G57) -> 0 | X21: =SUM(H54:H57) -> 0 | Y21: =SUM(I54:I57) -> 0 | Z21: =SUM(J54:J57) -> 0 | ... AF21: =SUM(P54:P57) -> 78
B22: 10.00 - 10.15 | C22: 1 | D22: 3 | E22: 1 | F22: 1 | G22: 0 | H22: 0 | I22: 0 | J22: 0 | K22: 0 | L22: 1 | M22: 5 | N22: 0 | O22: =SUM(C22:L22,N22) -> 7 | P22: =SUM(C22:N22) -> 12 | R22: 1900-2000 | S22: =SUM(C58:C61) -> 31 | T22: =SUM(D58:D61) -> 6 | U22: =SUM(E58:E61) -> 1 | V22: =SUM(F58:F61) -> 0 | W22: =SUM(G58:G61) -> 2 | X22: =SUM(H58:H61) -> 0 | Y22: =SUM(I58:I61) -> 1 | Z22: =SUM(J58:J61) -> 3 | ... AF22: =SUM(P58:P61) -> 68
B23: 10.15 - 10.30 | C23: 4 | D23: 3 | E23: 2 | F23: 1 | G23: 0 | H23: 0 | I23: 0 | J23: 0 | K23: 0 | L23: 0 | M23: 2 | N23: 0 | O23: =SUM(C23:L23,N23) -> 10 | P23: =SUM(C23:N23) -> 12 | R23: 2000-2100 | S23: =SUM(C62:C65) -> 26 | T23: =SUM(D62:D65) -> 5 | U23: =SUM(E62:E65) -> 5 | V23: =SUM(F62:F65) -> 0 | W23: =SUM(G62:G65) -> 0 | X23: =SUM(H62:H65) -> 0 | Y23: =SUM(I62:I65) -> 1 | Z23: =SUM(J62:J65) -> 0 | ... AF23: =SUM(P62:P65) -> 50
B24: 10.30 - 10.45 | C24: 1 | D24: 4 | E24: 0 | F24: 0 | G24: 1 | H24: 0 | I24: 0 | J24: 1 | K24: 1 | L24: 1 | M24: 5 | N24: 0 | O24: =SUM(C24:L24,N24) -> 9 | P24: =SUM(C24:N24) -> 14 | R24: 2100-2200 | S24: =SUM(C66:C69) -> 18 | T24: =SUM(D66:D69) -> 7 | U24: =SUM(E66:E69) -> 4 | V24: =SUM(F66:F69) -> 2 | W24: =SUM(G66:G69) -> 0 | X24: =SUM(H66:H69) -> 0 | Y24: =SUM(I66:I69) -> 3 | Z24: =SUM(J66:J69) -> 2 | ... AF24: =SUM(P66:P69) -> 52
B25: 10.45 - 11.00 | C25: 6 | D25: 2 | E25: 1 | F25: 0 | G25: 0 | H25: 0 | I25: 0 | J25: 0 | K25: 0 | L25: 0 | M25: 1 | N25: 0 | O25: =SUM(C25:L25,N25) -> 9 | P25: =SUM(C25:N25) -> 10 | R25: 2200-2300 | S25: =SUM(C70:C73) -> 14 | T25: =SUM(D70:D73) -> 4 | U25: =SUM(E70:E73) -> 4 | V25: =SUM(F70:F73) -> 2 | W25: =SUM(G70:G73) -> 0 | X25: =SUM(H70:H73) -> 1 | Y25: =SUM(I70:I73) -> 6 | Z25: =SUM(J70:J73) -> 0 | ... AF25: =SUM(P70:P73) -> 50
B26: 11.00 - 11.15 | C26: 3 | D26: 1 | E26: 2 | F26: 0 | G26: 0 | H26: 0 | I26: 0 | J26: 1 | K26: 0 | L26: 0 | M26: 3 | N26: 0 | O26: =SUM(C26:L26,N26) -> 7 | P26: =SUM(C26:N26) -> 10 | R26: 2300-0000 | S26: =SUM(C74:C77) -> 28 | T26: =SUM(D74:D77) -> 12 | U26: =SUM(E74:E77) -> 5 | V26: =SUM(F74:F77) -> 1 | W26: =SUM(G74:G77) -> 0 | X26: =SUM(H74:H77) -> 0 | Y26: =SUM(I74:I77) -> 2 | Z26: =SUM(J74:J77) -> 0 | ... AF26: =SUM(P74:P77) -> 68
B27: 11.15 - 11.30 | C27: 3 | D27: 2 | E27: 2 | F27: 0 | G27: 0 | H27: 0 | I27: 0 | J27: 0 | K27: 0 | L27: 1 | M27: 3 | N27: 0 | O27: =SUM(C27:L27,N27) -> 8 | P27: =SUM(C27:N27) -> 11 | R27: 0000-0100 | S27: =SUM(C78:C81) -> 9 | T27: =SUM(D78:D81) -> 4 | U27: =SUM(E78:E81) -> 2 | V27: =SUM(F78:F81) -> 0 | W27: =SUM(G78:G81) -> 0 | X27: =SUM(H78:H81) -> 0 | Y27: =SUM(I78:I81) -> 3 | Z27: =SUM(J78:J81) -> 2 | ... AF27: =SUM(P78:P81) -> 30
B28: 11.30 - 11.45 | C28: 7 | D28: 4 | E28: 4 | F28: 0 | G28: 0 | H28: 0 | I28: 0 | J28: 1 | K28: 0 | L28: 1 | M28: 2 | N28: 0 | O28: =SUM(C28:L28,N28) -> 17 | P28: =SUM(C28:N28) -> 19 | R28: 0100-0200 | S28: =SUM(C82:C85) -> 7 | T28: =SUM(D82:D85) -> 2 | U28: =SUM(E82:E85) -> 2 | V28: =SUM(F82:F85) -> 0 | W28: =SUM(G82:G85) -> 0 | X28: =SUM(H82:H85) -> 0 | Y28: =SUM(I82:I85) -> 2 | Z28: =SUM(J82:J85) -> 2 | ... AF28: =SUM(P82:P85) -> 25
B29: 11.45 - 12.00 | C29: 7 | D29: 8 | E29: 0 | F29: 4 | G29: 0 | H29: 0 | I29: 0 | J29: 0 | K29: 0 | L29: 2 | M29: 7 | N29: 0 | O29: =SUM(C29:L29,N29) -> 21 | P29: =SUM(C29:N29) -> 28 | R29: 0200-0300 | S29: =SUM(C86:C89) -> 7 | T29: =SUM(D86:D89) -> 5 | U29: =SUM(E86:E89) -> 2 | V29: =SUM(F86:F89) -> 0 | W29: =SUM(G86:G89) -> 0 | X29: =SUM(H86:H89) -> 0 | Y29: =SUM(I86:I89) -> 3 | Z29: =SUM(J86:J89) -> 2 | ... AF29: =SUM(P86:P89) -> 27
B30: 12.00 - 12.15 | C30: 5 | D30: 4 | E30: 0 | F30: 2 | G30: 0 | H30: 0 | I30: 0 | J30: 0 | K30: 0 | L30: 0 | M30: 4 | N30: 0 | O30: =SUM(C30:L30,N30) -> 11 | P30: =SUM(C30:N30) -> 15 | R30: 0300-0400 | S30: =SUM(C90:C93) -> 13 | T30: =SUM(D90:D93) -> 3 | U30: =SUM(E90:E93) -> 1 | V30: =SUM(F90:F93) -> 1 | W30: =SUM(G90:G93) -> 2 | X30: =SUM(H90:H93) -> 1 | Y30: =SUM(I90:I93) -> 0 | Z30: =SUM(J90:J93) -> 2 | ... AF30: =SUM(P90:P93) -> 40
B31: 12.15 - 12.30 | C31: 9 | D31: 1 | E31: 2 | F31: 0 | G31: 0 | H31: 0 | I31: 0 | J31: 1 | K31: 0 | L31: 4 | M31: 3 | N31: 0 | O31: =SUM(C31:L31,N31) -> 17 | P31: =SUM(C31:N31) -> 20 | R31: 0400-0500 | S31: =SUM(C94:C97) -> 15 | T31: =SUM(D94:D97) -> 2 | U31: =SUM(E94:E97) -> 2 | V31: =SUM(F94:F97) -> 3 | W31: =SUM(G94:G97) -> 2 | X31: =SUM(H94:H97) -> 3 | Y31: =SUM(I94:I97) -> 4 | Z31: =SUM(J94:J97) -> 1 | ... AF31: =SUM(P94:P97) -> 53
B32: 12.30 - 12.45 | C32: 7 | D32: 0 | E32: 0 | F32: 1 | G32: 0 | H32: 0 | I32: 0 | J32: 0 | K32: 0 | L32: 3 | M32: 4 | N32: 0 | O32: =SUM(C32:L32,N32) -> 11 | P32: =SUM(C32:N32) -> 15 | R32: 0500-0600 | S32: =SUM(C98:C101) -> 12 | T32: =SUM(D98:D101) -> 9 | U32: =SUM(E98:E101) -> 1 | V32: =SUM(F98:F101) -> 4 | W32: =SUM(G98:G101) -> 0 | X32: =SUM(H98:H101) -> 0 | Y32: =SUM(I98:I101) -> 4 | Z32: =SUM(J98:J101) -> 1 | ... AF32: =SUM(P98:P101) -> 69
B33: 12.45 - 13.00 | C33: 7 | D33: 3 | E33: 1 | F33: 1 | G33: 0 | H33: 0 | I33: 0 | J33: 1 | K33: 1 | L33: 1 | M33: 5 | N33: 0 | O33: =SUM(C33:L33,N33) -> 15 | P33: =SUM(C33:N33) -> 20 | R33: 0600-0700 | S33: =SUM(C102:C105) -> 10 | T33: =SUM(D102:D105) -> 7 | U33: =SUM(E102:E105) -> 2 | V33: =SUM(F102:F105) -> 3 | W33: =SUM(G102:G105) -> 0 | X33: =SUM(H102:H105) -> 0 | Y33: =SUM(I102:I105) -> 2 | Z33: =SUM(J102:J105) -> 2 | ... AF33: =SUM(P102:P105) -> 50
B34: 13.00 - 13.15 | C34: 9 | D34: 0 | E34: 0 | F34: 0 | G34: 0 | H34: 0 | I34: 1 | J34: 2 | K34: 0 | L34: 0 | M34: 2 | N34: 0 | O34: =SUM(C34:L34,N34) -> 12 | P34: =SUM(C34:N34) -> 14 | R34: AM Peak Hr | S34: =MAX(S10:S12) -> 16 | T34: =MAX(T10:T12) -> 18 | U34: =MAX(U10:U12) -> 2 | V34: =MAX(V10:V12) -> 2 | W34: =MAX(W10:W12) -> 0 | X34: =MAX(X10:X12) -> 0 | Y34: =MAX(Y10:Y12) -> 2 | Z34: =MAX(Z10:Z12) -> 0 | ... AF34: =MAX(AF10:AF12) -> 48
B35: 13.15 - 13.30 | C35: 8 | D35: 0 | E35: 1 | F35: 0 | G35: 0 | H35: 0 | I35: 0 | J35: 0 | K35: 0 | L35: 0 | M35: 7 | N35: 0 | O35: =SUM(C35:L35,N35) -> 9 | P35: =SUM(C35:N35) -> 16 | R35: IP Peak Hr | S35: =MAX(S13:S18) -> 28 | T35: =MAX(T13:T18) -> 15 | U35: =MAX(U13:U18) -> 8 | V35: =MAX(V13:V18) -> 4 | W35: =MAX(W13:W18) -> 1 | X35: =MAX(X13:X18) -> 1 | Y35: =MAX(Y13:Y18) -> 3 | Z35: =MAX(Z13:Z18) -> 4 | ... AF35: =MAX(AF13:AF18) -> 70
B36: 13.30 - 13.45 | C36: 4 | D36: 2 | E36: 1 | F36: 0 | G36: 0 | H36: 0 | I36: 2 | J36: 0 | K36: 0 | L36: 0 | M36: 4 | N36: 0 | O36: =SUM(C36:L36,N36) -> 9 | P36: =SUM(C36:N36) -> 13 | R36: PM Peak Hr | S36: =MAX(S19:S21) -> 26 | T36: =MAX(T19:T21) -> 9 | U36: =MAX(U19:U21) -> 8 | V36: =MAX(V19:V21) -> 3 | W36: =MAX(W19:W21) -> 0 | X36: =MAX(X19:X21) -> 0 | Y36: =MAX(Y19:Y21) -> 3 | Z36: =MAX(Z19:Z21) -> 0 | ... AF36: =MAX(AF19:AF21) -> 78
B37: 13.45 - 14.00 | C37: 0 | D37: 2 | E37: 0 | F37: 0 | G37: 0 | H37: 0 | I37: 0 | J37: 0 | K37: 0 | L37: 1 | M37: 8 | N37: 0 | O37: =SUM(C37:L37,N37) -> 3 | P37: =SUM(C37:N37) -> 11 | R37: AM Period | S37: =SUM(S10:S12) -> 39 | T37: =SUM(T10:T12) -> 32 | U37: =SUM(U10:U12) -> 4 | V37: =SUM(V10:V12) -> 5 | W37: =SUM(W10:W12) -> 0 | X37: =SUM(X10:X12) -> 0 | Y37: =SUM(Y10:Y12) -> 2 | Z37: =SUM(Z10:Z12) -> 0 | ... AF37: =SUM(AF10:AF12) -> 121
B38: 14.00 - 14.15 | C38: 10 | D38: 0 | E38: 3 | F38: 0 | G38: 0 | H38: 0 | I38: 1 | J38: 1 | K38: 2 | L38: 0 | M38: 5 | N38: 0 | O38: =SUM(C38:L38,N38) -> 17 | P38: =SUM(C38:N38) -> 22 | R38: IP Period | S38: =SUM(S13:S18) -> 127 | T38: =SUM(T13:T18) -> 47 | U38: =SUM(U13:U18) -> 24 | V38: =SUM(V13:V18) -> 10 | W38: =SUM(W13:W18) -> 1 | X38: =SUM(X13:X18) -> 1 | Y38: =SUM(Y13:Y18) -> 6 | Z38: =SUM(Z13:Z18) -> 14 | ... AF38: =SUM(AF13:AF18) -> 357
B39: 14.15 - 14.30 | C39: 6 | D39: 3 | E39: 0 | F39: 0 | G39: 0 | H39: 0 | I39: 1 | J39: 0 | K39: 1 | L39: 0 | M39: 4 | N39: 0 | O39: =SUM(C39:L39,N39) -> 11 | P39: =SUM(C39:N39) -> 15 | R39: PM Period | S39: =SUM(S19:S21) -> 59 | T39: =SUM(T19:T21) -> 20 | U39: =SUM(U19:U21) -> 11 | V39: =SUM(V19:V21) -> 4 | W39: =SUM(W19:W21) -> 0 | X39: =SUM(X19:X21) -> 0 | Y39: =SUM(Y19:Y21) -> 4 | Z39: =SUM(Z19:Z21) -> 0 | ... AF39: =SUM(AF19:AF21) -> 194
B40: 14.30 - 14.45 | C40: 4 | D40: 0 | E40: 0 | F40: 0 | G40: 0 | H40: 0 | I40: 0 | J40: 2 | K40: 0 | L40: 0 | M40: 5 | N40: 0 | O40: =SUM(C40:L40,N40) -> 6 | P40: =SUM(C40:N40) -> 11 | R40: 12 Hours | S40: =SUM(S10:S21) -> 225 | T40: =SUM(T10:T21) -> 99 | U40: =SUM(U10:U21) -> 39 | V40: =SUM(V10:V21) -> 19 | W40: =SUM(W10:W21) -> 1 | X40: =SUM(X10:X21) -> 1 | Y40: =SUM(Y10:Y21) -> 12 | Z40: =SUM(Z10:Z21) -> 14 | ... AF40: =SUM(AF10:AF21) -> 672
B41: 14.45 - 15.00 | C41: 8 | D41: 0 | E41: 1 | F41: 0 | G41: 0 | H41: 0 | I41: 0 | J41: 0 | K41: 0 | L41: 1 | M41: 6 | N41: 0 | O41: =SUM(C41:L41,N41) -> 10 | P41: =SUM(C41:N41) -> 16 | R41: 24 Hrs/ADT | S41: =SUM(S10:S33) -> 415 | T41: =SUM(T10:T33) -> 165 | U41: =SUM(U10:U33) -> 70 | V41: =SUM(V10:V33) -> 35 | W41: =SUM(W10:W33) -> 7 | X41: =SUM(X10:X33) -> 6 | Y41: =SUM(Y10:Y33) -> 43 | Z41: =SUM(Z10:Z33) -> 31 | ... AF41: =SUM(AF10:AF33) -> 1254
B42: 15.00 - 15.15 | C42: 5 | D42: 1 | E42: 0 | F42: 0 | G42: 0 | H42: 0 | I42: 0 | J42: 3 | K42: 1 | L42: 0 | M42: 3 | N42: 0 | O42: =SUM(C42:L42,N42) -> 10 | P42: =SUM(C42:N42) -> 13 | R42: NEF | S42: =S41/S40 -> 1.8444444 | T42: =T41/T40 -> 1.6666667 | U42: =U41/U40 -> 1.7948718 | V42: =V41/V40 -> 1.8421053 | W42: =W41/W40 -> 7 | X42: =X41/X40 -> 6 | Y42: =Y41/Y40 -> 3.5833333 | Z42: =Z41/Z40 -> 2.2142857 | ... AF42: =AF41/AF40 -> 1.8660714
...

Sheet 26.10 Rushere-Lyantonde-24hr
B1: Consultancy services for Preparation of Expressway Development Master Plan (EDMP) for Uganda
B2: MANUAL CLASSIFIED COUNT (MCC)
B3: ROAD NAME: | C3: ='25.10 Lyantonde-Rushere'!C3:G3 -> MCC- C4- TN103 - LYANTONDE-RUSHERE ROAD
C5: Date | D5: ='26.10 Lyantonde-Rushere-24hr'!D5 -> 26.10.19 | F5: Location | G5: ='26.10 Lyantonde-Rushere-24hr'!G5:H5 -> Kaguta road JTC | J5: Surveyor | K5: Nusulah, Ashaba
C6: Dir. From | D6: ='25.10 Rushere-Lyantonde'!D6:E6 -> Rushere | F6: Dir. To | G6: ='27.10 Rushere-Lyantonde'!G6:H6 -> Lyantonde | J6: Supervisor | K6: ='26.10 Lyantonde-Rushere-24hr'!K6:L6 -> Nusulah
B8: Time / Veh Type | R8: SUMMARY TRAFFIC VOLUMES
C9: 1. Car | D9: 2. Station Wagon | E9: 3. Pickups | F9: 4. Minibus, matatu | G9: 5. Medium bus | H9: 6. Large Bus | I9: 7. Light Truck | J9: 8. Medium Truck | K9: 9. Heavy truck | L9: 10. Truck Trailer | M9: 11. Motor cycles | N9: 12. Tractors | O9: Total Excl M/Cycles | P9: Total All | R9: Time | S9: 1. Car | T9: 2. Station Wagon | U9: 3. Pickups | V9: 4. Minibus, matatu | W9: 5. Medium bus | X9: 6. Large Bus | Y9: 7. Light Truck | Z9: 8. Medium Truck | AA9: 9. Heavy truck | AB9: 10. Truck Trailer | AC9: 11. Motorcycles | AD9: 12. Tractors, Graders | AE9: Total Excl M/ Cycles | AF9: Total All
B10: 07.00 - 07.15 | C10: 2 | D10: 1 | E10: 2 | F10: 1 | G10: 0 | H10: 0 | I10: 2 | J10: 0 | K10: 0 | L10: 0 | M10: 2 | N10: 0 | O10: =SUM(C10:L10,N10) -> 8 | P10: =SUM(C10:N10) -> 10 | R10: 0700-0800 | S10: =SUM(C10:C13) -> 11 | T10: =SUM(D10:D13) -> 4 | U10: =SUM(E10:E13) -> 2 | V10: =SUM(F10:F13) -> 1 | W10: =SUM(G10:G13) -> 0 | X10: =SUM(H10:H13) -> 0 | Y10: =SUM(I10:I13) -> 4 | Z10: =SUM(J10:J13) -> 0 | ... AF10: =SUM(P10:P13) -> 27
B11: 07.15 - 07.30 | C11: 3 | D11: 2 | E11: 0 | F11: 0 | G11: 0 | H11: 0 | I11: 1 | J11: 0 | K11: 0 | L11: 0 | M11: 0 | N11: 0 | O11: =SUM(C11:L11,N11) -> 6 | P11: =SUM(C11:N11) -> 6 | R11: 0800-0900 | S11: =SUM(C14:C17) -> 4 | T11: =SUM(D14:D17) -> 3 | U11: =SUM(E14:E17) -> 0 | V11: =SUM(F14:F17) -> 0 | W11: =SUM(G14:G17) -> 0 | X11: =SUM(H14:H17) -> 0 | Y11: =SUM(I14:I17) -> 0 | Z11: =SUM(J14:J17) -> 1 | ... AF11: =SUM(P14:P17) -> 23
B12: 07.30 - 07.45 | C12: 4 | D12: 1 | E12: 0 | F12: 0 | G12: 0 | H12: 0 | I12: 1 | J12: 0 | K12: 0 | L12: 0 | M12: 3 | N12: 0 | O12: =SUM(C12:L12,N12) -> 6 | P12: =SUM(C12:N12) -> 9 | R12: 0900-1000 | S12: =SUM(C18:C21) -> 9 | T12: =SUM(D18:D21) -> 5 | U12: =SUM(E18:E21) -> 1 | V12: =SUM(F18:F21) -> 0 | W12: =SUM(G18:G21) -> 0 | X12: =SUM(H18:H21) -> 1 | Y12: =SUM(I18:I21) -> 0 | Z12: =SUM(J18:J21) -> 1 | ... AF12: =SUM(P18:P21) -> 36
B13: 07.45 - 08.00 | C13: 2 | D13: 0 | E13: 0 | F13: 0 | G13: 0 | H13: 0 | I13: 0 | J13: 0 | K13: 0 | L13: 0 | M13: 0 | N13: 0 | O13: =SUM(C13:L13,N13) -> 2 | P13: =SUM(C13:N13) -> 2 | R13: 1000-1100 | S13: =SUM(C22:C25) -> 14 | T13: =SUM(D22:D25) -> 5 | U13: =SUM(E22:E25) -> 3 | V13: =SUM(F22:F25) -> 0 | W13: =SUM(G22:G25) -> 0 | X13: =SUM(H22:H25) -> 1 | Y13: =SUM(I22:I25) -> 2 | Z13: =SUM(J22:J25) -> 0 | ... AF13: =SUM(P22:P25) -> 39
B14: 08.00 - 08.15 | C14: 0 | D14: 1 | E14: 0 | F14: 0 | G14: 0 | H14: 0 | I14: 0 | J14: 1 | K14: 0 | L14: 0 | M14: 1 | N14: 0 | O14: =SUM(C14:L14,N14) -> 2 | P14: =SUM(C14:N14) -> 3 | R14: 1100-1200 | S14: =SUM(C26:C29) -> 18 | T14: =SUM(D26:D29) -> 1 | U14: =SUM(E26:E29) -> 1 | V14: =SUM(F26:F29) -> 0 | W14: =SUM(G26:G29) -> 0 | X14: =SUM(H26:H29) -> 0 | Y14: =SUM(I26:I29) -> 0 | Z14: =SUM(J26:J29) -> 0 | ... AF14: =SUM(P26:P29) -> 41
B15: 08.15 - 08.30 | C15: 2 | D15: 1 | E15: 0 | F15: 0 | G15: 0 | H15: 0 | I15: 0 | J15: 0 | K15: 0 | L15: 0 | M15: 4 | N15: 0 | O15: =SUM(C15:L15,N15) -> 3 | P15: =SUM(C15:N15) -> 7 | R15: 1200-1300 | S15: =SUM(C30:C33) -> 16 | T15: =SUM(D30:D33) -> 4 | U15: =SUM(E30:E33) -> 3 | V15: =SUM(F30:F33) -> 1 | W15: =SUM(G30:G33) -> 0 | X15: =SUM(H30:H33) -> 0 | Y15: =SUM(I30:I33) -> 1 | Z15: =SUM(J30:J33) -> 2 | ... AF15: =SUM(P30:P33) -> 57
B16: 08.30 - 08.45 | C16: 1 | D16: 1 | E16: 0 | F16: 0 | G16: 0 | H16: 0 | I16: 0 | J16: 0 | K16: 0 | L16: 0 | M16: 3 | N16: 0 | O16: =SUM(C16:L16,N16) -> 2 | P16: =SUM(C16:N16) -> 5 | R16: 1300-1400 | S16: =SUM(C34:C37) -> 17 | T16: =SUM(D34:D37) -> 4 | U16: =SUM(E34:E37) -> 2 | V16: =SUM(F34:F37) -> 1 | W16: =SUM(G34:G37) -> 0 | X16: =SUM(H34:H37) -> 0 | Y16: =SUM(I34:I37) -> 3 | Z16: =SUM(J34:J37) -> 0 | ... AF16: =SUM(P34:P37) -> 47
B17: 08.45 - 9.00 | C17: 1 | D17: 0 | E17: 0 | F17: 0 | G17: 0 | H17: 0 | I17: 0 | J17: 0 | K17: 0 | L17: 0 | M17: 7 | N17: 0 | O17: =SUM(C17:L17,N17) -> 1 | P17: =SUM(C17:N17) -> 8 | R17: 1400-1500 | S17: =SUM(C38:C41) -> 26 | T17: =SUM(D38:D41) -> 4 | U17: =SUM(E38:E41) -> 2 | V17: =SUM(F38:F41) -> 0 | W17: =SUM(G38:G41) -> 0 | X17: =SUM(H38:H41) -> 0 | Y17: =SUM(I38:I41) -> 2 | Z17: =SUM(J38:J41) -> 0 | ... AF17: =SUM(P38:P41) -> 62
B18: 09.00 - 09.15 | C18: 2 | D18: 0 | E18: 0 | F18: 0 | G18: 0 | H18: 0 | I18: 0 | J18: 1 | K18: 0 | L18: 0 | M18: 4 | N18: 0 | O18: =SUM(C18:L18,N18) -> 3 | P18: =SUM(C18:N18) -> 7 | R18: 1500-1600 | S18: =SUM(C42:C45) -> 18 | T18: =SUM(D42:D45) -> 0 | U18: =SUM(E42:E45) -> 8 | V18: =SUM(F42:F45) -> 0 | W18: =SUM(G42:G45) -> 0 | X18: =SUM(H42:H45) -> 0 | Y18: =SUM(I42:I45) -> 4 | Z18: =SUM(J42:J45) -> 4 | ... AF18: =SUM(P42:P45) -> 61
B19: 09.15 - 09.30 | C19: 1 | D19: 3 | E19: 0 | F19: 0 | G19: 0 | H19: 0 | I19: 0 | J19: 0 | K19: 0 | L19: 0 | M19: 5 | N19: 0 | O19: =SUM(C19:L19,N19) -> 4 | P19: =SUM(C19:N19) -> 9 | R19: 1600-1700 | S19: =SUM(C46:C49) -> 26 | T19: =SUM(D46:D49) -> 2 | U19: =SUM(E46:E49) -> 6 | V19: =SUM(F46:F49) -> 0 | W19: =SUM(G46:G49) -> 0 | X19: =SUM(H46:H49) -> 0 | Y19: =SUM(I46:I49) -> 3 | Z19: =SUM(J46:J49) -> 1 | ... AF19: =SUM(P46:P49) -> 66
B20: 09.30 - 09.45 | C20: 3 | D20: 0 | E20: 1 | F20: 0 | G20: 0 | H20: 1 | I20: 0 | J20: 0 | K20: 1 | L20: 1 | M20: 3 | N20: 0 | O20: =SUM(C20:L20,N20) -> 7 | P20: =SUM(C20:N20) -> 10 | R20: 1700-1800 | S20: =SUM(C50:C53) -> 19 | T20: =SUM(D50:D53) -> 7 | U20: =SUM(E50:E53) -> 2 | V20: =SUM(F50:F53) -> 0 | W20: =SUM(G50:G53) -> 0 | X20: =SUM(H50:H53) -> 0 | Y20: =SUM(I50:I53) -> 4 | Z20: =SUM(J50:J53) -> 3 | ... AF20: =SUM(P50:P53) -> 63
B21: 09.45 - 10.00 | C21: 3 | D21: 2 | E21: 0 | F21: 0 | G21: 0 | H21: 0 | I21: 0 | J21: 0 | K21: 0 | L21: 0 | M21: 5 | N21: 0 | O21: =SUM(C21:L21,N21) -> 5 | P21: =SUM(C21:N21) -> 10 | R21: 1800-1900 | S21: =SUM(C54:C57) -> 19 | T21: =SUM(D54:D57) -> 4 | U21: =SUM(E54:E57) -> 4 | V21: =SUM(F54:F57) -> 0 | W21: =SUM(G54:G57) -> 0 | X21: =SUM(H54:H57) -> 0 | Y21: =SUM(I54:I57) -> 3 | Z21: =SUM(J54:J57) -> 2 | ... AF21: =SUM(P54:P57) -> 66
B22: 10.00 - 10.15 | C22: 3 | D22: 1 | E22: 0 | F22: 0 | G22: 0 | H22: 0 | I22: 1 | J22: 0 | K22: 0 | L22: 0 | M22: 2 | N22: 0 | O22: =SUM(C22:L22,N22) -> 5 | P22: =SUM(C22:N22) -> 7 | R22: 1900-2000 | S22: =SUM(C58:C61) -> 17 | T22: =SUM(D58:D61) -> 6 | U22: =SUM(E58:E61) -> 3 | V22: =SUM(F58:F61) -> 3 | W22: =SUM(G58:G61) -> 0 | X22: =SUM(H58:H61) -> 0 | Y22: =SUM(I58:I61) -> 0 | Z22: =SUM(J58:J61) -> 2 | ... AF22: =SUM(P58:P61) -> 47
B23: 10.15 - 10.30 | C23: 3 | D23: 0 | E23: 2 | F23: 0 | G23: 0 | H23: 0 | I23: 1 | J23: 0 | K23: 0 | L23: 0 | M23: 3 | N23: 0 | O23: =SUM(C23:L23,N23) -> 6 | P23: =SUM(C23:N23) -> 9 | R23: 2000-2100 | S23: =SUM(C62:C65) -> 18 | T23: =SUM(D62:D65) -> 1 | U23: =SUM(E62:E65) -> 5 | V23: =SUM(F62:F65) -> 1 | W23: =SUM(G62:G65) -> 0 | X23: =SUM(H62:H65) -> 0 | Y23: =SUM(I62:I65) -> 3 | Z23: =SUM(J62:J65) -> 1 | ... AF23: =SUM(P62:P65) -> 35
B24: 10.30 - 10.45 | C24: 3 | D24: 3 | E24: 0 | F24: 0 | G24: 0 | H24: 1 | I24: 0 | J24: 0 | K24: 0 | L24: 0 | M24: 3 | N24: 1 | O24: =SUM(C24:L24,N24) -> 8 | P24: =SUM(C24:N24) -> 11 | R24: 2100-2200 | S24: =SUM(C66:C69) -> 13 | T24: =SUM(D66:D69) -> 5 | U24: =SUM(E66:E69) -> 4 | V24: =SUM(F66:F69) -> 1 | W24: =SUM(G66:G69) -> 2 | X24: =SUM(H66:H69) -> 1 | Y24: =SUM(I66:I69) -> 6 | Z24: =SUM(J66:J69) -> 6 | ... AF24: =SUM(P66:P69) -> 38
B25: 10.45 - 11.00 | C25: 5 | D25: 1 | E25: 1 | F25: 0 | G25: 0 | H25: 0 | I25: 0 | J25: 0 | K25: 0 | L25: 0 | M25: 5 | N25: 0 | O25: =SUM(C25:L25,N25) -> 7 | P25: =SUM(C25:N25) -> 12 | R25: 2200-2300 | S25: =SUM(C70:C73) -> 6 | T25: =SUM(D70:D73) -> 4 | U25: =SUM(E70:E73) -> 4 | V25: =SUM(F70:F73) -> 0 | W25: =SUM(G70:G73) -> 0 | X25: =SUM(H70:H73) -> 0 | Y25: =SUM(I70:I73) -> 3 | Z25: =SUM(J70:J73) -> 6 | ... AF25: =SUM(P70:P73) -> 24
B26: 11.00 - 11.15 | C26: 6 | D26: 1 | E26: 1 | F26: 0 | G26: 0 | H26: 0 | I26: 0 | J26: 0 | K26: 0 | L26: 0 | M26: 3 | N26: 0 | O26: =SUM(C26:L26,N26) -> 8 | P26: =SUM(C26:N26) -> 11 | R26: 2300-0000 | S26: =SUM(C74:C77) -> 6 | T26: =SUM(D74:D77) -> 3 | U26: =SUM(E74:E77) -> 2 | V26: =SUM(F74:F77) -> 0 | W26: =SUM(G74:G77) -> 0 | X26: =SUM(H74:H77) -> 0 | Y26: =SUM(I74:I77) -> 3 | Z26: =SUM(J74:J77) -> 4 | ... AF26: =SUM(P74:P77) -> 20
B27: 11.15 - 11.30 | C27: 6 | D27: 0 | E27: 0 | F27: 0 | G27: 0 | H27: 0 | I27: 0 | J27: 0 | K27: 0 | L27: 0 | M27: 4 | N27: 0 | O27: =SUM(C27:L27,N27) -> 6 | P27: =SUM(C27:N27) -> 10 | R27: 0000-0100 | S27: =SUM(C78:C81) -> 4 | T27: =SUM(D78:D81) -> 1 | U27: =SUM(E78:E81) -> 4 | V27: =SUM(F78:F81) -> 0 | W27: =SUM(G78:G81) -> 0 | X27: =SUM(H78:H81) -> 0 | Y27: =SUM(I78:I81) -> 4 | Z27: =SUM(J78:J81) -> 7 | ... AF27: =SUM(P78:P81) -> 27
B28: 11.30 - 11.45 | C28: 5 | D28: 0 | E28: 0 | F28: 0 | G28: 0 | H28: 0 | I28: 0 | J28: 0 | K28: 0 | L28: 3 | M28: 4 | N28: 0 | O28: =SUM(C28:L28,N28) -> 8 | P28: =SUM(C28:N28) -> 12 | R28: 0100-0200 | S28: =SUM(C82:C85) -> 1 | T28: =SUM(D82:D85) -> 0 | U28: =SUM(E82:E85) -> 5 | V28: =SUM(F82:F85) -> 0 | W28: =SUM(G82:G85) -> 0 | X28: =SUM(H82:H85) -> 0 | Y28: =SUM(I82:I85) -> 1 | Z28: =SUM(J82:J85) -> 0 | ... AF28: =SUM(P82:P85) -> 12
B29: 11.45 - 12.00 | C29: 1 | D29: 0 | E29: 0 | F29: 0 | G29: 0 | H29: 0 | I29: 0 | J29: 0 | K29: 0 | L29: 0 | M29: 7 | N29: 0 | O29: =SUM(C29:L29,N29) -> 1 | P29: =SUM(C29:N29) -> 8 | R29: 0200-0300 | S29: =SUM(C86:C89) -> 3 | T29: =SUM(D86:D89) -> 3 | U29: =SUM(E86:E89) -> 4 | V29: =SUM(F86:F89) -> 0 | W29: =SUM(G86:G89) -> 0 | X29: =SUM(H86:H89) -> 1 | Y29: =SUM(I86:I89) -> 3 | Z29: =SUM(J86:J89) -> 0 | ... AF29: =SUM(P86:P89) -> 20
B30: 12.00 - 12.15 | C30: 1 | D30: 0 | E30: 1 | F30: 1 | G30: 0 | H30: 0 | I30: 0 | J30: 0 | K30: 0 | L30: 0 | M30: 6 | N30: 0 | O30: =SUM(C30:L30,N30) -> 3 | P30: =SUM(C30:N30) -> 9 | R30: 0300-0400 | S30: =SUM(C90:C93) -> 2 | T30: =SUM(D90:D93) -> 2 | U30: =SUM(E90:E93) -> 1 | V30: =SUM(F90:F93) -> 1 | W30: =SUM(G90:G93) -> 0 | X30: =SUM(H90:H93) -> 0 | Y30: =SUM(I90:I93) -> 1 | Z30: =SUM(J90:J93) -> 5 | ... AF30: =SUM(P90:P93) -> 14
B31: 12.15 - 12.30 | C31: 5 | D31: 2 | E31: 1 | F31: 0 | G31: 0 | H31: 0 | I31: 1 | J31: 2 | K31: 0 | L31: 1 | M31: 6 | N31: 0 | O31: =SUM(C31:L31,N31) -> 12 | P31: =SUM(C31:N31) -> 18 | R31: 0400-0500 | S31: =SUM(C94:C97) -> 2 | T31: =SUM(D94:D97) -> 1 | U31: =SUM(E94:E97) -> 3 | V31: =SUM(F94:F97) -> 1 | W31: =SUM(G94:G97) -> 1 | X31: =SUM(H94:H97) -> 1 | Y31: =SUM(I94:I97) -> 1 | Z31: =SUM(J94:J97) -> 3 | ... AF31: =SUM(P94:P97) -> 15
B32: 12.30 - 12.45 | C32: 8 | D32: 0 | E32: 1 | F32: 0 | G32: 0 | H32: 0 | I32: 0 | J32: 0 | K32: 0 | L32: 0 | M32: 7 | N32: 0 | O32: =SUM(C32:L32,N32) -> 9 | P32: =SUM(C32:N32) -> 16 | R32: 0500-0600 | S32: =SUM(C98:C101) -> 8 | T32: =SUM(D98:D101) -> 5 | U32: =SUM(E98:E101) -> 2 | V32: =SUM(F98:F101) -> 1 | W32: =SUM(G98:G101) -> 0 | X32: =SUM(H98:H101) -> 1 | Y32: =SUM(I98:I101) -> 1 | Z32: =SUM(J98:J101) -> 7 | ... AF32: =SUM(P98:P101) -> 33
B33: 12.45 - 13.00 | C33: 2 | D33: 2 | E33: 0 | F33: 0 | G33: 0 | H33: 0 | I33: 0 | J33: 0 | K33: 0 | L33: 0 | M33: 10 | N33: 0 | O33: =SUM(C33:L33,N33) -> 4 | P33: =SUM(C33:N33) -> 14 | R33: 0600-0700 | S33: =SUM(C102:C105) -> 11 | T33: =SUM(D102:D105) -> 10 | U33: =SUM(E102:E105) -> 10 | V33: =SUM(F102:F105) -> 4 | W33: =SUM(G102:G105) -> 1 | X33: =SUM(H102:H105) -> 2 | Y33: =SUM(I102:I105) -> 6 | Z33: =SUM(J102:J105) -> 8 | ... AF33: =SUM(P102:P105) -> 68
B34: 13.00 - 13.15 | C34: 4 | D34: 2 | E34: 0 | F34: 1 | G34: 0 | H34: 0 | I34: 1 | J34: 0 | K34: 0 | L34: 0 | M34: 11 | N34: 0 | O34: =SUM(C34:L34,N34) -> 8 | P34: =SUM(C34:N34) -> 19 | R34: AM Peak Hr | S34: =MAX(S10:S12) -> 11 | T34: =MAX(T10:T12) -> 5 | U34: =MAX(U10:U12) -> 2 | V34: =MAX(V10:V12) -> 1 | W34: =MAX(W10:W12) -> 0 | X34: =MAX(X10:X12) -> 1 | Y34: =MAX(Y10:Y12) -> 4 | Z34: =MAX(Z10:Z12) -> 1 | ... AF34: =MAX(AF10:AF12) -> 36
B35: 13.15 - 13.30 | C35: 6 | D35: 0 | E35: 1 | F35: 0 | G35: 0 | H35: 0 | I35: 2 | J35: 0 | K35: 0 | L35: 0 | M35: 4 | N35: 0 | O35: =SUM(C35:L35,N35) -> 9 | P35: =SUM(C35:N35) -> 13 | R35: IP Peak Hr | S35: =MAX(S13:S18) -> 26 | T35: =MAX(T13:T18) -> 5 | U35: =MAX(U13:U18) -> 8 | V35: =MAX(V13:V18) -> 1 | W35: =MAX(W13:W18) -> 0 | X35: =MAX(X13:X18) -> 1 | Y35: =MAX(Y13:Y18) -> 4 | Z35: =MAX(Z13:Z18) -> 4 | ... AF35: =MAX(AF13:AF18) -> 62
B36: 13.30 - 13.45 | C36: 4 | D36: 1 | E36: 1 | F36: 0 | G36: 0 | H36: 0 | I36: 0 | J36: 0 | K36: 0 | L36: 0 | M36: 1 | N36: 0 | O36: =SUM(C36:L36,N36) -> 6 | P36: =SUM(C36:N36) -> 7 | R36: PM Peak Hr | S36: =MAX(S19:S21) -> 26 | T36: =MAX(T19:T21) -> 7 | U36: =MAX(U19:U21) -> 6 | V36: =MAX(V19:V21) -> 0 | W36: =MAX(W19:W21) -> 0 | X36: =MAX(X19:X21) -> 0 | Y36: =MAX(Y19:Y21) -> 4 | Z36: =MAX(Z19:Z21) -> 3 | ... AF36: =MAX(AF19:AF21) -> 66
B37: 13.45 - 14.00 | C37: 3 | D37: 1 | E37: 0 | F37: 0 | G37: 0 | H37: 0 | I37: 0 | J37: 0 | K37: 1 | L37: 0 | M37: 3 | N37: 0 | O37: =SUM(C37:L37,N37) -> 5 | P37: =SUM(C37:N37) -> 8 | R37: AM Period | S37: =SUM(S10:S12) -> 24 | T37: =SUM(T10:T12) -> 12 | U37: =SUM(U10:U12) -> 3 | V37: =SUM(V10:V12) -> 1 | W37: =SUM(W10:W12) -> 0 | X37: =SUM(X10:X12) -> 1 | Y37: =SUM(Y10:Y12) -> 4 | Z37: =SUM(Z10:Z12) -> 2 | ... AF37: =SUM(AF10:AF12) -> 86
B38: 14.00 - 14.15 | C38: 10 | D38: 1 | E38: 0 | F38: 0 | G38: 0 | H38: 0 | I38: 0 | J38: 0 | K38: 1 | L38: 0 | M38: 8 | N38: 0 | O38: =SUM(C38:L38,N38) -> 12 | P38: =SUM(C38:N38) -> 20 | R38: IP Period | S38: =SUM(S13:S18) -> 109 | T38: =SUM(T13:T18) -> 18 | U38: =SUM(U13:U18) -> 19 | V38: =SUM(V13:V18) -> 2 | W38: =SUM(W13:W18) -> 0 | X38: =SUM(X13:X18) -> 1 | Y38: =SUM(Y13:Y18) -> 12 | Z38: =SUM(Z13:Z18) -> 6 | ... AF38: =SUM(AF13:AF18) -> 307
B39: 14.15 - 14.30 | C39: 7 | D39: 2 | E39: 1 | F39: 0 | G39: 0 | H39: 0 | I39: 2 | J39: 0 | K39: 0 | L39: 0 | M39: 7 | N39: 0 | O39: =SUM(C39:L39,N39) -> 12 | P39: =SUM(C39:N39) -> 19 | R39: PM Period | S39: =SUM(S19:S21) -> 64 | T39: =SUM(T19:T21) -> 13 | U39: =SUM(U19:U21) -> 12 | V39: =SUM(V19:V21) -> 0 | W39: =SUM(W19:W21) -> 0 | X39: =SUM(X19:X21) -> 0 | Y39: =SUM(Y19:Y21) -> 10 | Z39: =SUM(Z19:Z21) -> 6 | ... AF39: =SUM(AF19:AF21) -> 195
B40: 14.30 - 14.45 | C40: 3 | D40: 1 | E40: 1 | F40: 0 | G40: 0 | H40: 0 | I40: 0 | J40: 0 | K40: 0 | L40: 0 | M40: 6 | N40: 0 | O40: =SUM(C40:L40,N40) -> 5 | P40: =SUM(C40:N40) -> 11 | R40: 12 Hours | S40: =SUM(S10:S21) -> 197 | T40: =SUM(T10:T21) -> 43 | U40: =SUM(U10:U21) -> 34 | V40: =SUM(V10:V21) -> 3 | W40: =SUM(W10:W21) -> 0 | X40: =SUM(X10:X21) -> 2 | Y40: =SUM(Y10:Y21) -> 26 | Z40: =SUM(Z10:Z21) -> 14 | ... AF40: =SUM(AF10:AF21) -> 588
B41: 14.45 - 15.00 | C41: 6 | D41: 0 | E41: 0 | F41: 0 | G41: 0 | H41: 0 | I41: 0 | J41: 0 | K41: 1 | L41: 0 | M41: 5 | N41: 0 | O41: =SUM(C41:L41,N41) -> 7 | P41: =SUM(C41:N41) -> 12 | R41: 24 Hrs/ADT | S41: =SUM(S10:S33) -> 288 | T41: =SUM(T10:T33) -> 84 | U41: =SUM(U10:U33) -> 81 | V41: =SUM(V10:V33) -> 15 | W41: =SUM(W10:W33) -> 4 | X41: =SUM(X10:X33) -> 8 | Y41: =SUM(Y10:Y33) -> 58 | Z41: =SUM(Z10:Z33) -> 63 | ... AF41: =SUM(AF10:AF33) -> 941
B42: 15.00 - 15.15 | C42: 3 | D42: 0 | E42: 5 | F42: 0 | G42: 0 | H42: 0 | I42: 2 | J42: 2 | K42: 0 | L42: 0 | M42: 7 | N42: 0 | O42: =SUM(C42:L42,N42) -> 12 | P42: =SUM(C42:N42) -> 19 | R42: NEF | S42: =S41/S40 -> 1.4619289 | T42: =T41/T40 -> 1.9534884 | U42: =U41/U40 -> 2.3823529 | V42: =V41/V40 -> 5 | W42: =W41/W40 -> #DIV/0! | X42: =X41/X40 -> 4 | Y42: =Y41/Y40 -> 2.2307692 | Z42: =Z41/Z40 -> 4.5 | ... AF42: =AF41/AF40 -> 1.6003401
...

Sheet 27.10 Lyantonde-Rushere
B1: Consultancy services for Preparation of Expressway Development Master Plan (EDMP) for Uganda
B2: MANUAL CLASSIFIED COUNT (MCC)
B3: ROAD NAME: | C3: ='25.10 Lyantonde-Rushere'!C3:G3 -> MCC- C4- TN103 - LYANTONDE-RUSHERE ROAD
C5: Date | D5: 27.10.19 | F5: Location | G5: ='25.10 Lyantonde-Rushere'!G5:H5 -> Kaguta road JTC | J5: Surveyor | K5: ='25.10 Lyantonde-Rushere'!K5:L5 -> Josephine
C6: Dir. From | D6: ='25.10 Lyantonde-Rushere'!D6:E6 -> Lyantonde | F6: Dir. To | G6: ='25.10 Lyantonde-Rushere'!G6:H6 -> Rushere | J6: Supervisor | K6: ='25.10 Lyantonde-Rushere'!K6:L6 -> Nusulah
B8: Time / Veh Type | R8: SUMMARY TRAFFIC VOLUMES
C9: 1. Car | D9: 2. Station Wagon | E9: 3. Pickups | F9: 4. Minibus, matatu | G9: 5. Medium bus | H9: 6. Large Bus | I9: 7. Light Truck | J9: 8. Medium Truck | K9: 9. Heavy truck | L9: 10. Truck Trailer | M9: 11. Motor cycles | N9: 12. Tractors | O9: Total Excl M/Cycles | P9: Total All | R9: Time | S9: 1. Car | T9: 2. Station Wagon | U9: 3. Pickups | V9: 4. Minibus, matatu | W9: 5. Medium bus | X9: 6. Large Bus | Y9: 7. Light Truck | Z9: 8. Medium Truck | AA9: 9. Heavy truck | AB9: 10. Truck Trailer | AC9: 11. Motorcycles | AD9: 12. Tractors, Graders | AE9: Total Excl M/ Cycles | AF9: Total All
B10: 07.00 - 07.15 | C10: 1 | D10: 0 | E10: 0 | F10: 0 | G10: 0 | H10: 0 | I10: 0 | J10: 0 | K10: 1 | L10: 0 | M10: 5 | N10: 0 | O10: =SUM(C10:L10,N10) -> 2 | P10: =SUM(C10:N10) -> 7 | R10: 0700-0800 | S10: =SUM(C10:C13) -> 6 | T10: =SUM(D10:D13) -> 0 | U10: =SUM(E10:E13) -> 1 | V10: =SUM(F10:F13) -> 1 | W10: =SUM(G10:G13) -> 0 | X10: =SUM(H10:H13) -> 0 | Y10: =SUM(I10:I13) -> 0 | Z10: =SUM(J10:J13) -> 2 | ... AF10: =SUM(P10:P13) -> 34
B11: 07.15 - 07.30 | C11: 4 | D11: 0 | E11: 1 | F11: 1 | G11: 0 | H11: 0 | I11: 0 | J11: 2 | K11: 0 | L11: 0 | M11: 5 | N11: 0 | O11: =SUM(C11:L11,N11) -> 8 | P11: =SUM(C11:N11) -> 13 | R11: 0800-0900 | S11: =SUM(C14:C17) -> 7 | T11: =SUM(D14:D17) -> 2 | U11: =SUM(E14:E17) -> 0 | V11: =SUM(F14:F17) -> 0 | W11: =SUM(G14:G17) -> 0 | X11: =SUM(H14:H17) -> 0 | Y11: =SUM(I14:I17) -> 0 | Z11: =SUM(J14:J17) -> 3 | ... AF11: =SUM(P14:P17) -> 27
B12: 07.30 - 07.45 | C12: 1 | D12: 0 | E12: 0 | F12: 0 | G12: 0 | H12: 0 | I12: 0 | J12: 0 | K12: 0 | L12: 0 | M12: 6 | N12: 2 | O12: =SUM(C12:L12,N12) -> 3 | P12: =SUM(C12:N12) -> 9 | R12: 0900-1000 | S12: =SUM(C18:C21) -> 9 | T12: =SUM(D18:D21) -> 13 | U12: =SUM(E18:E21) -> 1 | V12: =SUM(F18:F21) -> 2 | W12: =SUM(G18:G21) -> 0 | X12: =SUM(H18:H21) -> 0 | Y12: =SUM(I18:I21) -> 1 | Z12: =SUM(J18:J21) -> 0 | ... AF12: =SUM(P18:P21) -> 44
B13: 07.45 - 08.00 | C13: 0 | D13: 0 | E13: 0 | F13: 0 | G13: 0 | H13: 0 | I13: 0 | J13: 0 | K13: 0 | L13: 0 | M13: 5 | N13: 0 | O13: =SUM(C13:L13,N13) -> 0 | P13: =SUM(C13:N13) -> 5 | R13: 1000-1100 | S13: =SUM(C22:C25) -> 15 | T13: =SUM(D22:D25) -> 7 | U13: =SUM(E22:E25) -> 2 | V13: =SUM(F22:F25) -> 2 | W13: =SUM(G22:G25) -> 0 | X13: =SUM(H22:H25) -> 0 | Y13: =SUM(I22:I25) -> 2 | Z13: =SUM(J22:J25) -> 0 | ... AF13: =SUM(P22:P25) -> 53
B14: 08.00 - 08.15 | C14: 1 | D14: 1 | E14: 0 | F14: 0 | G14: 0 | H14: 0 | I14: 0 | J14: 0 | K14: 0 | L14: 1 | M14: 4 | N14: 0 | O14: =SUM(C14:L14,N14) -> 3 | P14: =SUM(C14:N14) -> 7 | R14: 1100-1200 | S14: =SUM(C26:C29) -> 16 | T14: =SUM(D26:D29) -> 5 | U14: =SUM(E26:E29) -> 4 | V14: =SUM(F26:F29) -> 0 | W14: =SUM(G26:G29) -> 0 | X14: =SUM(H26:H29) -> 0 | Y14: =SUM(I26:I29) -> 4 | Z14: =SUM(J26:J29) -> 5 | ... AF14: =SUM(P26:P29) -> 55
