Workbook

Sheet 23.09.19 Entebbe-Busabala
B1: Consultancy services for Preparation of Expressway Development Master Plan (EDMP) for Uganda
B2: MANUAL CLASSIFIED COUNT (MCC)
B3: ROAD NAME: | C3: MCC - C2 - STN053 - Busabala RD
C5: Date | D5: 23.09.19 | F5: Location | G5: Ziranumbu town | J5: Surveyor | K5: Ssemuko S
C6: Dir. From | D6: ENTEBBE | F6: Dir. To | G6: BUSABALA | J6: Supervisor | K6: Steven
B8: Time / Veh Type | R8: SUMMARY TRAFFIC VOLUMES
C9: 1. Car | D9: 2. Station Wagon | E9: 3. Pickups | F9: 4. Minibus, matatu | G9: 5. Medium bus | H9: 6. Large Bus | I9: 7. Light Truck | J9: 8. Medium Truck | K9: 9. Heavy truck | L9: 10. Truck Trailer | M9: 11. Motor cycles | N9: 12. Tractors | O9: Total Excl M/Cycles | P9: Total All | R9: Time | S9: 1. Car | T9: 2. Station Wagon | U9: 3. Pickups | V9: 4. Minibus, matatu | W9: 5. Medium bus | X9: 6. Large Bus | Y9: 7. Light Truck | Z9: 8. Medium Truck | AA9: 9. Heavy truck | AB9: 10. Truck Trailer | AC9: 11. Motorcycles | AD9: 12. Tractors, Graders | AE9: Total Excl M/ Cycles | AF9: Total All
B10: 07.00 - 07.15 | C10: 4 | D10: 0 | E10: 0 | F10: 0 | G10: 3 | H10: 0 | I10: 0 | J10: 0 | K10: 0 | L10: 0 | M10: 9 | N10: 0 | O10: =SUM(C10:L10,N10) -> 7 | P10: =SUM(C10:N10) -> 16 | R10: 0700-0800 | S10: =SUM(C10:C13) -> 34 | T10: =SUM(D10:D13) -> 6 | U10: =SUM(E10:E13) -> 3 | V10: =SUM(F10:F13) -> 16 | W10: =SUM(G10:G13) -> 3 | X10: =SUM(H10:H13) -> 0 | Y10: =SUM(I10:I13) -> 2 | Z10: =SUM(J10:J13) -> 6 | ... AF10: =SUM(P10:P13) -> 197
B11: 07.15 - 07.30 | C11: 9 | D11: 2 | E11: 2 | F11: 4 | G11: 0 | H11: 0 | I11: 0 | J11: 4 | K11: 0 | L11: 0 | M11: 43 | N11: 0 | O11: =SUM(C11:L11,N11) -> 21 | P11: =SUM(C11:N11) -> 64 | R11: 0800-0900 | S11: =SUM(C14:C17) -> 23 | T11: =SUM(D14:D17) -> 1 | U11: =SUM(E14:E17) -> 1 | V11: =SUM(F14:F17) -> 17 | W11: =SUM(G14:G17) -> 0 | X11: =SUM(H14:H17) -> 0 | Y11: =SUM(I14:I17) -> 12 | Z11: =SUM(J14:J17) -> 4 | ... AF11: =SUM(P14:P17) -> 150
B12: 07.30 - 07.45 | C12: 12 | D12: 1 | E12: 1 | F12: 8 | G12: 0 | H12: 0 | I12: 1 | J12: 2 | K12: 0 | L12: 0 | M12: 40 | N12: 0 | O12: =SUM(C12:L12,N12) -> 25 | P12: =SUM(C12:N12) -> 65 | R12: 0900-1000 | S12: =SUM(C18:C21) -> 19 | T12: =SUM(D18:D21) -> 0 | U12: =SUM(E18:E21) -> 1 | V12: =SUM(F18:F21) -> 17 | W12: =SUM(G18:G21) -> 0 | X12: =SUM(H18:H21) -> 0 | Y12: =SUM(I18:I21) -> 8 | Z12: =SUM(J18:J21) -> 2 | ... AF12: =SUM(P18:P21) -> 127
B13: 07.45 - 08.00 | C13: 9 | D13: 3 | E13: 0 | F13: 4 | G13: 0 | H13: 0 | I13: 1 | J13: 0 | K13: 0 | L13: 0 | M13: 35 | N13: 0 | O13: =SUM(C13:L13,N13) -> 17 | P13: =SUM(C13:N13) -> 52 | R13: 1000-1100 | S13: =SUM(C22:C25) -> 24 | T13: =SUM(D22:D25) -> 2 | U13: =SUM(E22:E25) -> 1 | V13: =SUM(F22:F25) -> 12 | W13: =SUM(G22:G25) -> 0 | X13: =SUM(H22:H25) -> 0 | Y13: =SUM(I22:I25) -> 6 | Z13: =SUM(J22:J25) -> 3 | ... AF13: =SUM(P22:P25) -> 115
B14: 08.00 - 08.15 | C14: 6 | D14: 1 | E14: 0 | F14: 7 | G14: 0 | H14: 0 | I14: 2 | J14: 0 | K14: 0 | L14: 0 | M14: 27 | N14: 0 | O14: =SUM(C14:L14,N14) -> 16 | P14: =SUM(C14:N14) -> 43 | R14: 1100-1200 | S14: =SUM(C26:C29) -> 15 | T14: =SUM(D26:D29) -> 3 | U14: =SUM(E26:E29) -> 1 | V14: =SUM(F26:F29) -> 19 | W14: =SUM(G26:G29) -> 0 | X14: =SUM(H26:H29) -> 0 | Y14: =SUM(I26:I29) -> 12 | Z14: =SUM(J26:J29) -> 3 | ... AF14: =SUM(P26:P29) -> 120
B15: 08.15 - 08.30 | C15: 7 | D15: 0 | E15: 0 | F15: 3 | G15: 0 | H15: 0 | I15: 2 | J15: 2 | K15: 0 | L15: 0 | M15: 26 | N15: 0 | O15: =SUM(C15:L15,N15) -> 14 | P15: =SUM(C15:N15) -> 40 | R15: 1200-1300 | S15: =SUM(C30:C33) -> 14 | T15: =SUM(D30:D33) -> 0 | U15: =SUM(E30:E33) -> 2 | V15: =SUM(F30:F33) -> 12 | W15: =SUM(G30:G33) -> 0 | X15: =SUM(H30:H33) -> 0 | Y15: =SUM(I30:I33) -> 13 | Z15: =SUM(J30:J33) -> 8 | ... AF15: =SUM(P30:P33) -> 113
B16: 08.30 - 08.45 | C16: 4 | D16: 0 | E16: 0 | F16: 3 | G16: 0 | H16: 0 | I16: 5 | J16: 2 | K16: 0 | L16: 0 | M16: 22 | N16: 0 | O16: =SUM(C16:L16,N16) -> 14 | P16: =SUM(C16:N16) -> 36 | R16: 1300-1400 | S16: =SUM(C34:C37) -> 21 | T16: =SUM(D34:D37) -> 2 | U16: =SUM(E34:E37) -> 1 | V16: =SUM(F34:F37) -> 18 | W16: =SUM(G34:G37) -> 0 | X16: =SUM(H34:H37) -> 0 | Y16: =SUM(I34:I37) -> 11 | Z16: =SUM(J34:J37) -> 5 | ... AF16: =SUM(P34:P37) -> 110
B17: 08.45 - 9.00 | C17: 6 | D17: 0 | E17: 1 | F17: 4 | G17: 0 | H17: 0 | I17: 3 | J17: 0 | K17: 0 | L17: 0 | M17: 17 | N17: 0 | O17: =SUM(C17:L17,N17) -> 14 | P17: =SUM(C17:N17) -> 31 | R17: 1400-1500 | S17: =SUM(C38:C41) -> 26 | T17: =SUM(D38:D41) -> 1 | U17: =SUM(E38:E41) -> 2 | V17: =SUM(F38:F41) -> 17 | W17: =SUM(G38:G41) -> 0 | X17: =SUM(H38:H41) -> 0 | Y17: =SUM(I38:I41) -> 13 | Z17: =SUM(J38:J41) -> 3 | ... AF17: =SUM(P38:P41) -> 124
B18: 09.00 - 09.15 | C18: 4 | D18: 0 | E18: 0 | F18: 5 | G18: 0 | H18: 0 | I18: 2 | J18: 2 | K18: 0 | L18: 0 | M18: 26 | N18: 0 | O18: =SUM(C18:L18,N18) -> 13 | P18: =SUM(C18:N18) -> 39 | R18: 1500-1600 | S18: =SUM(C42:C45) -> 12 | T18: =SUM(D42:D45) -> 2 | U18: =SUM(E42:E45) -> 1 | V18: =SUM(F42:F45) -> 16 | W18: =SUM(G42:G45) -> 0 | X18: =SUM(H42:H45) -> 0 | Y18: =SUM(I42:I45) -> 11 | Z18: =SUM(J42:J45) -> 3 | ... AF18: =SUM(P42:P45) -> 112
B19: 09.15 - 09.30 | C19: 4 | D19: 0 | E19: 0 | F19: 6 | G19: 0 | H19: 0 | I19: 2 | J19: 0 | K19: 0 | L19: 0 | M19: 19 | N19: 0 | O19: =SUM(C19:L19,N19) -> 12 | P19: =SUM(C19:N19) -> 31 | R19: 1600-1700 | S19: =SUM(C46:C49) -> 16 | T19: =SUM(D46:D49) -> 2 | U19: =SUM(E46:E49) -> 2 | V19: =SUM(F46:F49) -> 27 | W19: =SUM(G46:G49) -> 0 | X19: =SUM(H46:H49) -> 0 | Y19: =SUM(I46:I49) -> 16 | Z19: =SUM(J46:J49) -> 3 | ... AF19: =SUM(P46:P49) -> 111
B20: 09.30 - 09.45 | C20: 4 | D20: 0 | E20: 1 | F20: 3 | G20: 0 | H20: 0 | I20: 1 | J20: 0 | K20: 0 | L20: 0 | M20: 23 | N20: 0 | O20: =SUM(C20:L20,N20) -> 9 | P20: =SUM(C20:N20) -> 32 | R20: 1700-1800 | S20: =SUM(C50:C53) -> 17 | T20: =SUM(D50:D53) -> 6 | U20: =SUM(E50:E53) -> 0 | V20: =SUM(F50:F53) -> 36 | W20: =SUM(G50:G53) -> 2 | X20: =SUM(H50:H53) -> 0 | Y20: =SUM(I50:I53) -> 10 | Z20: =SUM(J50:J53) -> 1 | ... AF20: =SUM(P50:P53) -> 137
B21: 09.45 - 10.00 | C21: 7 | D21: 0 | E21: 0 | F21: 3 | G21: 0 | H21: 0 | I21: 3 | J21: 0 | K21: 0 | L21: 0 | M21: 12 | N21: 0 | O21: =SUM(C21:L21,N21) -> 13 | P21: =SUM(C21:N21) -> 25 | R21: 1800-1900 | S21: =SUM(C54:C57) -> 32 | T21: =SUM(D54:D57) -> 2 | U21: =SUM(E54:E57) -> 2 | V21: =SUM(F54:F57) -> 40 | W21: =SUM(G54:G57) -> 3 | X21: =SUM(H54:H57) -> 0 | Y21: =SUM(I54:I57) -> 7 | Z21: =SUM(J54:J57) -> 1 | ... AF21: =SUM(P54:P57) -> 141
B22: 10.00 - 10.15 | C22: 8 | D22: 0 | E22: 0 | F22: 2 | G22: 0 | H22: 0 | I22: 2 | J22: 0 | K22: 0 | L22: 0 | M22: 12 | N22: 0 | O22: =SUM(C22:L22,N22) -> 12 | P22: =SUM(C22:N22) -> 24 | R22: AM Peak Hr | S22: =MAX(S10:S12) -> 34 | T22: =MAX(T10:T12) -> 6 | U22: =MAX(U10:U12) -> 3 | V22: =MAX(V10:V12) -> 17 | W22: =MAX(W10:W12) -> 3 | X22: =MAX(X10:X12) -> 0 | Y22: =MAX(Y10:Y12) -> 12 | Z22: =MAX(Z10:Z12) -> 6 | ... AF22: =MAX(AF10:AF12) -> 197
B23: 10.15 - 10.30 | C23: 7 | D23: 0 | E23: 0 | F23: 2 | G23: 0 | H23: 0 | I23: 2 | J23: 0 | K23: 0 | L23: 0 | M23: 23 | N23: 0 | O23: =SUM(C23:L23,N23) -> 11 | P23: =SUM(C23:N23) -> 34 | R23: IP Peak Hr | S23: =MAX(S13:S18) -> 26 | T23: =MAX(T13:T18) -> 3 | U23: =MAX(U13:U18) -> 2 | V23: =MAX(V13:V18) -> 19 | W23: =MAX(W13:W18) -> 0 | X23: =MAX(X13:X18) -> 0 | Y23: =MAX(Y13:Y18) -> 13 | Z23: =MAX(Z13:Z18) -> 8 | ... AF23: =MAX(AF13:AF18) -> 124
B24: 10.30 - 10.45 | C24: 7 | D24: 2 | E24: 0 | F24: 4 | G24: 0 | H24: 0 | I24: 1 | J24: 2 | K24: 0 | L24: 0 | M24: 14 | N24: 0 | O24: =SUM(C24:L24,N24) -> 16 | P24: =SUM(C24:N24) -> 30 | R24: PM Peak Hr | S24: =MAX(S19:S21) -> 32 | T24: =MAX(T19:T21) -> 6 | U24: =MAX(U19:U21) -> 2 | V24: =MAX(V19:V21) -> 40 | W24: =MAX(W19:W21) -> 3 | X24: =MAX(X19:X21) -> 0 | Y24: =MAX(Y19:Y21) -> 16 | Z24: =MAX(Z19:Z21) -> 3 | ... AF24: =MAX(AF19:AF21) -> 141
B25: 10.45 - 11.00 | C25: 2 | D25: 0 | E25: 1 | F25: 4 | G25: 0 | H25: 0 | I25: 1 | J25: 1 | K25: 0 | L25: 0 | M25: 18 | N25: 0 | O25: =SUM(C25:L25,N25) -> 9 | P25: =SUM(C25:N25) -> 27 | R25: AM Period | S25: =SUM(S10:S12) -> 76 | T25: =SUM(T10:T12) -> 7 | U25: =SUM(U10:U12) -> 5 | V25: =SUM(V10:V12) -> 50 | W25: =SUM(W10:W12) -> 3 | X25: =SUM(X10:X12) -> 0 | Y25: =SUM(Y10:Y12) -> 22 | Z25: =SUM(Z10:Z12) -> 12 | ... AF25: =SUM(AF10:AF12) -> 474
B26: 11.00 - 11.15 | C26: 8 | D26: 2 | E26: 1 | F26: 5 | G26: 0 | H26: 0 | I26: 5 | J26: 1 | K26: 0 | L26: 0 | M26: 23 | N26: 0 | O26: =SUM(C26:L26,N26) -> 22 | P26: =SUM(C26:N26) -> 45 | R26: IP Period | S26: =SUM(S13:S18) -> 112 | T26: =SUM(T13:T18) -> 10 | U26: =SUM(U13:U18) -> 8 | V26: =SUM(V13:V18) -> 94 | W26: =SUM(W13:W18) -> 0 | X26: =SUM(X13:X18) -> 0 | Y26: =SUM(Y13:Y18) -> 66 | Z26: =SUM(Z13:Z18) -> 25 | ... AF26: =SUM(AF13:AF18) -> 694
B27: 11.15 - 11.30 | C27: 3 | D27: 0 | E27: 0 | F27: 10 | G27: 0 | H27: 0 | I27: 6 | J27: 1 | K27: 0 | L27: 0 | M27: 16 | N27: 0 | O27: =SUM(C27:L27,N27) -> 20 | P27: =SUM(C27:N27) -> 36 | R27: PM Period | S27: =SUM(S19:S21) -> 65 | T27: =SUM(T19:T21) -> 10 | U27: =SUM(U19:U21) -> 4 | V27: =SUM(V19:V21) -> 103 | W27: =SUM(W19:W21) -> 5 | X27: =SUM(X19:X21) -> 0 | Y27: =SUM(Y19:Y21) -> 33 | Z27: =SUM(Z19:Z21) -> 5 | ... AF27: =SUM(AF19:AF21) -> 389
B28: 11.30 - 11.45 | C28: 1 | D28: 0 | E28: 0 | F28: 2 | G28: 0 | H28: 0 | I28: 0 | J28: 0 | K28: 0 | L28: 0 | M28: 5 | N28: 0 | O28: =SUM(C28:L28,N28) -> 3 | P28: =SUM(C28:N28) -> 8 | R28: 12 Hours | S28: =SUM(S10:S21) -> 253 | T28: =SUM(T10:T21) -> 27 | U28: =SUM(U10:U21) -> 17 | V28: =SUM(V10:V21) -> 247 | W28: =SUM(W10:W21) -> 8 | X28: =SUM(X10:X21) -> 0 | Y28: =SUM(Y10:Y21) -> 121 | Z28: =SUM(Z10:Z21) -> 42 | ... AF28: =SUM(AF10:AF21) -> 1557
B29: 11.45 - 12.00 | C29: 3 | D29: 1 | E29: 0 | F29: 2 | G29: 0 | H29: 0 | I29: 1 | J29: 1 | K29: 0 | L29: 0 | M29: 23 | N29: 0 | O29: =SUM(C29:L29,N29) -> 8 | P29: =SUM(C29:N29) -> 31
B30: 12.00 - 12.15 | C30: 3 | D30: 0 | E30: 1 | F30: 4 | G30: 0 | H30: 0 | I30: 2 | J30: 0 | K30: 0 | L30: 0 | M30: 15 | N30: 0 | O30: =SUM(C30:L30,N30) -> 10 | P30: =SUM(C30:N30) -> 25
B31: 12.15 - 12.30 | C31: 3 | D31: 0 | E31: 1 | F31: 3 | G31: 0 | H31: 0 | I31: 1 | J31: 1 | K31: 0 | L31: 0 | M31: 17 | N31: 0 | O31: =SUM(C31:L31,N31) -> 9 | P31: =SUM(C31:N31) -> 26
B32: 12.30 - 12.45 | C32: 3 | D32: 0 | E32: 0 | F32: 3 | G32: 0 | H32: 0 | I32: 4 | J32: 3 | K32: 0 | L32: 0 | M32: 22 | N32: 0 | O32: =SUM(C32:L32,N32) -> 13 | P32: =SUM(C32:N32) -> 35
B33: 12.45 - 13.00 | C33: 5 | D33: 0 | E33: 0 | F33: 2 | G33: 0 | H33: 0 | I33: 6 | J33: 4 | K33: 0 | L33: 0 | M33: 10 | N33: 0 | O33: =SUM(C33:L33,N33) -> 17 | P33: =SUM(C33:N33) -> 27
B34: 13.00 - 13.15 | C34: 6 | D34: 1 | E34: 0 | F34: 4 | G34: 0 | H34: 0 | I34: 1 | J34: 1 | K34: 0 | L34: 0 | M34: 21 | N34: 0 | O34: =SUM(C34:L34,N34) -> 13 | P34: =SUM(C34:N34) -> 34
B35: 13.15 - 13.30 | C35: 5 | D35: 1 | E35: 0 | F35: 9 | G35: 0 | H35: 0 | I35: 3 | J35: 2 | K35: 0 | L35: 0 | M35: 15 | N35: 0 | O35: =SUM(C35:L35,N35) -> 20 | P35: =SUM(C35:N35) -> 35
B36: 13.30 - 13.45 | C36: 3 | D36: 0 | E36: 0 | F36: 2 | G36: 0 | H36: 0 | I36: 2 | J36: 2 | K36: 0 | L36: 0 | M36: 8 | N36: 0 | O36: =SUM(C36:L36,N36) -> 9 | P36: =SUM(C36:N36) -> 17
B37: 13.45 - 14.00 | C37: 7 | D37: 0 | E37: 1 | F37: 3 | G37: 0 | H37: 0 | I37: 5 | J37: 0 | K37: 0 | L37: 0 | M37: 8 | N37: 0 | O37: =SUM(C37:L37,N37) -> 16 | P37: =SUM(C37:N37) -> 24
B38: 14.00 - 14.15 | C38: 6 | D38: 0 | E38: 0 | F38: 9 | G38: 0 | H38: 0 | I38: 6 | J38: 0 | K38: 0 | L38: 0 | M38: 27 | N38: 0 | O38: =SUM(C38:L38,N38) -> 21 | P38: =SUM(C38:N38) -> 48
B39: 14.15 - 14.30 | C39: 9 | D39: 0 | E39: 0 | F39: 0 | G39: 0 | H39: 0 | I39: 1 | J39: 0 | K39: 0 | L39: 0 | M39: 5 | N39: 0 | O39: =SUM(C39:L39,N39) -> 10 | P39: =SUM(C39:N39) -> 15
B40: 14.30 - 14.45 | C40: 3 | D40: 0 | E40: 0 | F40: 5 | G40: 0 | H40: 0 | I40: 2 | J40: 2 | K40: 0 | L40: 0 | M40: 9 | N40: 0 | O40: =SUM(C40:L40,N40) -> 12 | P40: =SUM(C40:N40) -> 21
... B57: 18.45 - 19.00 | C57: 13 | D57: 0 | E57: 0 | F57: 9 | G57: 1 | H57: 0 | I57: 2 | J57: 0 | K57: 0 | L57: 0 | M57: 17 | N57: 0 | O57: =SUM(C57:L57,N57) -> 25 | P57: =SUM(C57:N57) -> 42
B58: Totals | C58: =SUM(C10:C57) -> 253 | D58: =SUM(D10:D57) -> 27 | E58: =SUM(E10:E57) -> 17 | F58: =SUM(F10:F57) -> 247 | G58: =SUM(G10:G57) -> 8 | H58: =SUM(H10:H57) -> 0 | I58: =SUM(I10:I57) -> 121 | J58: =SUM(J10:J57) -> 42 | ... P58: =SUM(P10:P57) -> 1557
...

Sheet 23.09.19 Busabala-Entebbe
B1: Consultancy services for Preparation of Expressway Development Master Plan (EDMP) for Uganda
B2: MANUAL CLASSIFIED COUNT (MCC)
B3: ROAD NAME: | C3: ='23.09.19 Entebbe-Busabala'!C3:G3 -> MCC - C2 - STN053 - Busabala RD
C5: Date | D5: 23.09.19 | F5: Location | G5: Busabala | J5: Surveyor | K5: Godfrey
C6: Dir. From | D6: BUSABALA | F6: Dir. To | G6: ENTEBBE | J6: Supervisor | K6: Steven
B8: Time / Veh Type | R8: SUMMARY TRAFFIC VOLUMES
C9: 1. Car | D9: 2. Station Wagon | E9: 3. Pickups | F9: 4. Minibus, matatu | G9: 5. Medium bus | H9: 6. Large Bus | I9: 7. Light Truck | J9: 8. Medium Truck | K9: 9. Heavy truck | L9: 10. Truck Trailer | M9: 11. Motor cycles | N9: 12. Tractors | O9: Total Excl M/Cycles | P9: Total All | R9: Time | S9: 1. Car | T9: 2. Station Wagon | U9: 3. Pickups | V9: 4. Minibus, matatu | W9: 5. Medium bus | X9: 6. Large Bus | Y9: 7. Light Truck | Z9: 8. Medium Truck | AA9: 9. Heavy truck | AB9: 10. Truck Trailer | AC9: 11. Motorcycles | AD9: 12. Tractors, Graders | AE9: Total Excl M/ Cycles | AF9: Total All
B10: 07.00 - 07.15 | C10: 0 | D10: 1 | E10: 0 | F10: 2 | G10: 1 | H10: 0 | I10: 1 | J10: 1 | K10: 0 | L10: 0 | M10: 7 | N10: 0 | O10: =SUM(C10:L10,N10) -> 6 | P10: =SUM(C10:N10) -> 13 | R10: 0700-0800 | S10: =SUM(C10:C13) -> 11 | T10: =SUM(D10:D13) -> 7 | U10: =SUM(E10:E13) -> 1 | V10: =SUM(F10:F13) -> 10 | W10: =SUM(G10:G13) -> 1 | X10: =SUM(H10:H13) -> 0 | Y10: =SUM(I10:I13) -> 3 | Z10: =SUM(J10:J13) -> 1 | ... AF10: =SUM(P10:P13) -> 87
B11: 07.15 - 07.30 | C11: 5 | D11: 4 | E11: 0 | F11: 1 | G11: 0 | H11: 0 | I11: 2 | J11: 0 | K11: 0 | L11: 0 | M11: 8 | N11: 0 | O11: =SUM(C11:L11,N11) -> 12 | P11: =SUM(C11:N11) -> 20 | R11: 0800-0900 | S11: =SUM(C14:C17) -> 10 | T11: =SUM(D14:D17) -> 2 | U11: =SUM(E14:E17) -> 1 | V11: =SUM(F14:F17) -> 11 | W11: =SUM(G14:G17) -> 0 | X11: =SUM(H14:H17) -> 0 | Y11: =SUM(I14:I17) -> 4 | Z11: =SUM(J14:J17) -> 2 | ... AF11: =SUM(P14:P17) -> 56
B12: 07.30 - 07.45 | C12: 5 | D12: 1 | E12: 1 | F12: 3 | G12: 0 | H12: 0 | I12: 0 | J12: 0 | K12: 0 | L12: 0 | M12: 23 | N12: 0 | O12: =SUM(C12:L12,N12) -> 10 | P12: =SUM(C12:N12) -> 33 | R12: 0900-1000 | S12: =SUM(C18:C21) -> 4 | T12: =SUM(D18:D21) -> 5 | U12: =SUM(E18:E21) -> 2 | V12: =SUM(F18:F21) -> 11 | W12: =SUM(G18:G21) -> 0 | X12: =SUM(H18:H21) -> 0 | Y12: =SUM(I18:I21) -> 6 | Z12: =SUM(J18:J21) -> 1 | ... AF12: =SUM(P18:P21) -> 62
B13: 07.45 - 08.00 | C13: 1 | D13: 1 | E13: 0 | F13: 4 | G13: 0 | H13: 0 | I13: 0 | J13: 0 | K13: 0 | L13: 0 | M13: 15 | N13: 0 | O13: =SUM(C13:L13,N13) -> 6 | P13: =SUM(C13:N13) -> 21 | R13: 1000-1100 | S13: =SUM(C22:C25) -> 11 | T13: =SUM(D22:D25) -> 3 | U13: =SUM(E22:E25) -> 1 | V13: =SUM(F22:F25) -> 13 | W13: =SUM(G22:G25) -> 0 | X13: =SUM(H22:H25) -> 0 | Y13: =SUM(I22:I25) -> 8 | Z13: =SUM(J22:J25) -> 0 | ... AF13: =SUM(P22:P25) -> 71
B14: 08.00 - 08.15 | C14: 2 | D14: 0 | E14: 0 | F14: 2 | G14: 0 | H14: 0 | I14: 2 | J14: 0 | K14: 0 | L14: 0 | M14: 7 | N14: 0 | O14: =SUM(C14:L14,N14) -> 6 | P14: =SUM(C14:N14) -> 13 | R14: 1100-1200 | S14: =SUM(C26:C29) -> 10 | T14: =SUM(D26:D29) -> 5 | U14: =SUM(E26:E29) -> 2 | V14: =SUM(F26:F29) -> 12 | W14: =SUM(G26:G29) -> 0 | X14: =SUM(H26:H29) -> 0 | Y14: =SUM(I26:I29) -> 11 | Z14: =SUM(J26:J29) -> 4 | ... AF14: =SUM(P26:P29) -> 76
B15: 08.15 - 08.30 | C15: 2 | D15: 0 | E15: 0 | F15: 3 | G15: 0 | H15: 0 | I15: 1 | J15: 2 | K15: 0 | L15: 0 | M15: 7 | N15: 0 | O15: =SUM(C15:L15,N15) -> 8 | P15: =SUM(C15:N15) -> 15 | R15: 1200-1300 | S15: =SUM(C30:C33) -> 9 | T15: =SUM(D30:D33) -> 6 | U15: =SUM(E30:E33) -> 0 | V15: =SUM(F30:F33) -> 14 | W15: =SUM(G30:G33) -> 0 | X15: =SUM(H30:H33) -> 0 | Y15: =SUM(I30:I33) -> 7 | Z15: =SUM(J30:J33) -> 1 | ... AF15: =SUM(P30:P33) -> 70
B16: 08.30 - 08.45 | C16: 4 | D16: 2 | E16: 1 | F16: 5 | G16: 0 | H16: 0 | I16: 1 | J16: 0 | K16: 0 | L16: 0 | M16: 6 | N16: 0 | O16: =SUM(C16:L16,N16) -> 13 | P16: =SUM(C16:N16) -> 19 | R16: 1300-1400 | S16: =SUM(C34:C37) -> 18 | T16: =SUM(D34:D37) -> 6 | U16: =SUM(E34:E37) -> 2 | V16: =SUM(F34:F37) -> 8 | W16: =SUM(G34:G37) -> 0 | X16: =SUM(H34:H37) -> 0 | Y16: =SUM(I34:I37) -> 11 | Z16: =SUM(J34:J37) -> 2 | ... AF16: =SUM(P34:P37) -> 81
B17: 08.45 - 9.00 | C17: 2 | D17: 0 | E17: 0 | F17: 1 | G17: 0 | H17: 0 | I17: 0 | J17: 0 | K17: 0 | L17: 0 | M17: 6 | N17: 0 | O17: =SUM(C17:L17,N17) -> 3 | P17: =SUM(C17:N17) -> 9 | R17: 1400-1500 | S17: =SUM(C38:C41) -> 11 | T17: =SUM(D38:D41) -> 8 | U17: =SUM(E38:E41) -> 0 | V17: =SUM(F38:F41) -> 11 | W17: =SUM(G38:G41) -> 0 | X17: =SUM(H38:H41) -> 0 | Y17: =SUM(I38:I41) -> 8 | Z17: =SUM(J38:J41) -> 0 | ... AF17: =SUM(P38:P41) -> 63
B18: 09.00 - 09.15 | C18: 0 | D18: 2 | E18: 0 | F18: 3 | G18: 0 | H18: 0 | I18: 1 | J18: 1 | K18: 0 | L18: 0 | M18: 15 | N18: 0 | O18: =SUM(C18:L18,N18) -> 7 | P18: =SUM(C18:N18) -> 22 | R18: 1500-1600 | S18: =SUM(C42:C45) -> 9 | T18: =SUM(D42:D45) -> 3 | U18: =SUM(E42:E45) -> 2 | V18: =SUM(F42:F45) -> 19 | W18: =SUM(G42:G45) -> 0 | X18: =SUM(H42:H45) -> 0 | Y18: =SUM(I42:I45) -> 6 | Z18: =SUM(J42:J45) -> 3 | ... AF18: =SUM(P42:P45) -> 60
B19: 09.15 - 09.30 | C19: 0 | D19: 2 | E19: 1 | F19: 4 | G19: 0 | H19: 0 | I19: 4 | J19: 0 | K19: 0 | L19: 0 | M19: 2 | N19: 2 | O19: =SUM(C19:L19,N19) -> 13 | P19: =SUM(C19:N19) -> 15 | R19: 1600-1700 | S19: =SUM(C46:C49) -> 9 | T19: =SUM(D46:D49) -> 5 | U19: =SUM(E46:E49) -> 2 | V19: =SUM(F46:F49) -> 9 | W19: =SUM(G46:G49) -> 0 | X19: =SUM(H46:H49) -> 0 | Y19: =SUM(I46:I49) -> 9 | Z19: =SUM(J46:J49) -> 1 | ... AF19: =SUM(P46:P49) -> 55
B20: 09.30 - 09.45 | C20: 3 | D20: 0 | E20: 0 | F20: 3 | G20: 0 | H20: 0 | I20: 1 | J20: 0 | K20: 0 | L20: 0 | M20: 4 | N20: 0 | O20: =SUM(C20:L20,N20) -> 7 | P20: =SUM(C20:N20) -> 11 | R20: 1700-1800 | S20: =SUM(C50:C53) -> 19 | T20: =SUM(D50:D53) -> 12 | U20: =SUM(E50:E53) -> 0 | V20: =SUM(F50:F53) -> 13 | W20: =SUM(G50:G53) -> 0 | X20: =SUM(H50:H53) -> 0 | Y20: =SUM(I50:I53) -> 8 | Z20: =SUM(J50:J53) -> 0 | ... AF20: =SUM(P50:P53) -> 81
B21: 09.45 - 10.00 | C21: 1 | D21: 1 | E21: 1 | F21: 1 | G21: 0 | H21: 0 | I21: 0 | J21: 0 | K21: 0 | L21: 0 | M21: 10 | N21: 0 | O21: =SUM(C21:L21,N21) -> 4 | P21: =SUM(C21:N21) -> 14 | R21: 1800-1900 | S21: =SUM(C54:C57) -> 18 | T21: =SUM(D54:D57) -> 6 | U21: =SUM(E54:E57) -> 4 | V21: =SUM(F54:F57) -> 18 | W21: =SUM(G54:G57) -> 0 | X21: =SUM(H54:H57) -> 0 | Y21: =SUM(I54:I57) -> 10 | Z21: =SUM(J54:J57) -> 4 | ... AF21: =SUM(P54:P57) -> 84
B22: 10.00 - 10.15 | C22: 3 | D22: 0 | E22: 0 | F22: 3 | G22: 0 | H22: 0 | I22: 2 | J22: 0 | K22: 0 | L22: 0 | M22: 8 | N22: 0 | O22: =SUM(C22:L22,N22) -> 8 | P22: =SUM(C22:N22) -> 16 | R22: AM Peak Hr | S22: =MAX(S10:S12) -> 11 | T22: =MAX(T10:T12) -> 7 | U22: =MAX(U10:U12) -> 2 | V22: =MAX(V10:V12) -> 11 | W22: =MAX(W10:W12) -> 1 | X22: =MAX(X10:X12) -> 0 | Y22: =MAX(Y10:Y12) -> 6 | Z22: =MAX(Z10:Z12) -> 2 | ... AF22: =MAX(AF10:AF12) -> 87
B23: 10.15 - 10.30 | C23: 4 | D23: 2 | E23: 1 | F23: 4 | G23: 0 | H23: 0 | I23: 3 | J23: 0 | K23: 0 | L23: 0 | M23: 13 | N23: 0 | O23: =SUM(C23:L23,N23) -> 14 | P23: =SUM(C23:N23) -> 27 | R23: IP Peak Hr | S23: =MAX(S13:S18) -> 18 | T23: =MAX(T13:T18) -> 8 | U23: =MAX(U13:U18) -> 2 | V23: =MAX(V13:V18) -> 19 | W23: =MAX(W13:W18) -> 0 | X23: =MAX(X13:X18) -> 0 | Y23: =MAX(Y13:Y18) -> 11 | Z23: =MAX(Z13:Z18) -> 4 | ... AF23: =MAX(AF13:AF18) -> 81
B24: 10.30 - 10.45 | C24: 2 | D24: 0 | E24: 0 | F24: 4 | G24: 0 | H24: 0 | I24: 3 | J24: 0 | K24: 0 | L24: 0 | M24: 7 | N24: 0 | O24: =SUM(C24:L24,N24) -> 9 | P24: =SUM(C24:N24) -> 16 | R24: PM Peak Hr | S24: =MAX(S19:S21) -> 19 | T24: =MAX(T19:T21) -> 12 | U24: =MAX(U19:U21) -> 4 | V24: =MAX(V19:V21) -> 18 | W24: =MAX(W19:W21) -> 0 | X24: =MAX(X19:X21) -> 0 | Y24: =MAX(Y19:Y21) -> 10 | Z24: =MAX(Z19:Z21) -> 4 | ... AF24: =MAX(AF19:AF21) -> 84
B25: 10.45 - 11.00 | C25: 2 | D25: 1 | E25: 0 | F25: 2 | G25: 0 | H25: 0 | I25: 0 | J25: 0 | K25: 0 | L25: 0 | M25: 7 | N25: 0 | O25: =SUM(C25:L25,N25) -> 5 | P25: =SUM(C25:N25) -> 12 | R25: AM Period | S25: =SUM(S10:S12) -> 25 | T25: =SUM(T10:T12) -> 14 | U25: =SUM(U10:U12) -> 4 | V25: =SUM(V10:V12) -> 32 | W25: =SUM(W10:W12) -> 1 | X25: =SUM(X10:X12) -> 0 | Y25: =SUM(Y10:Y12) -> 13 | Z25: =SUM(Z10:Z12) -> 4 | ... AF25: =SUM(AF10:AF12) -> 205
B26: 11.00 - 11.15 | C26: 2 | D26: 2 | E26: 2 | F26: 3 | G26: 0 | H26: 0 | I26: 3 | J26: 0 | K26: 0 | L26: 0 | M26: 11 | N26: 0 | O26: =SUM(C26:L26,N26) -> 12 | P26: =SUM(C26:N26) -> 23 | R26: IP Period | S26: =SUM(S13:S18) -> 68 | T26: =SUM(T13:T18) -> 31 | U26: =SUM(U13:U18) -> 7 | V26: =SUM(V13:V18) -> 77 | W26: =SUM(W13:W18) -> 0 | X26: =SUM(X13:X18) -> 0 | Y26: =SUM(Y13:Y18) -> 51 | Z26: =SUM(Z13:Z18) -> 10 | ... AF26: =SUM(AF13:AF18) -> 421
B27: 11.15 - 11.30 | C27: 3 | D27: 1 | E27: 0 | F27: 4 | G27: 0 | H27: 0 | I27: 6 | J27: 3 | K27: 0 | L27: 0 | M27: 11 | N27: 0 | O27: =SUM(C27:L27,N27) -> 17 | P27: =SUM(C27:N27) -> 28 | R27: PM Period | S27: =SUM(S19:S21) -> 46 | T27: =SUM(T19:T21) -> 23 | U27: =SUM(U19:U21) -> 6 | V27: =SUM(V19:V21) -> 40 | W27: =SUM(W19:W21) -> 0 | X27: =SUM(X19:X21) -> 0 | Y27: =SUM(Y19:Y21) -> 27 | Z27: =SUM(Z19:Z21) -> 5 | ... AF27: =SUM(AF19:AF21) -> 220
B28: 11.30 - 11.45 | C28: 0 | D28: 2 | E28: 0 | F28: 1 | G28: 0 | H28: 0 | I28: 1 | J28: 0 | K28: 0 | L28: 0 | M28: 3 | N28: 0 | O28: =SUM(C28:L28,N28) -> 4 | P28: =SUM(C28:N28) -> 7 | R28: 12 Hours | S28: =SUM(S10:S21) -> 139 | T28: =SUM(T10:T21) -> 68 | U28: =SUM(U10:U21) -> 17 | V28: =SUM(V10:V21) -> 149 | W28: =SUM(W10:W21) -> 1 | X28: =SUM(X10:X21) -> 0 | Y28: =SUM(Y10:Y21) -> 91 | Z28: =SUM(Z10:Z21) -> 19 | ... AF28: =SUM(AF10:AF21) -> 846
B29: 11.45 - 12.00 | C29: 5 | D29: 0 | E29: 0 | F29: 4 | G29: 0 | H29: 0 | I29: 1 | J29: 1 | K29: 0 | L29: 0 | M29: 7 | N29: 0 | O29: =SUM(C29:L29,N29) -> 11 | P29: =SUM(C29:N29) -> 18
B30: 12.00 - 12.15 | C30: 2 | D30: 0 | E30: 0 | F30: 3 | G30: 0 | H30: 0 | I30: 1 | J30: 0 | K30: 0 | L30: 0 | M30: 3 | N30: 0 | O30: =SUM(C30:L30,N30) -> 6 | P30: =SUM(C30:N30) -> 9
B31: 12.15 - 12.30 | C31: 2 | D31: 4 | E31: 0 | F31: 5 | G31: 0 | H31: 0 | I31: 5 | J31: 1 | K31: 0 | L31: 0 | M31: 16 | N31: 0 | O31: =SUM(C31:L31,N31) -> 17 | P31: =SUM(C31:N31) -> 33
B32: 12.30 - 12.45 | C32: 3 | D32: 1 | E32: 0 | F32: 3 | G32: 0 | H32: 0 | I32: 0 | J32: 0 | K32: 0 | L32: 0 | M32: 7 | N32: 0 | O32: =SUM(C32:L32,N32) -> 7 | P32: =SUM(C32:N32) -> 14
B33: 12.45 - 13.00 | C33: 2 | D33: 1 | E33: 0 | F33: 3 | G33: 0 | H33: 0 | I33: 1 | J33: 0 | K33: 0 | L33: 0 | M33: 7 | N33: 0 | O33: =SUM(C33:L33,N33) -> 7 | P33: =SUM(C33:N33) -> 14
B34: 13.00 - 13.15 | C34: 5 | D34: 1 | E34: 0 | F34: 1 | G34: 0 | H34: 0 | I34: 1 | J34: 0 | K34: 0 | L34: 0 | M34: 13 | N34: 0 | O34: =SUM(C34:L34,N34) -> 8 | P34: =SUM(C34:N34) -> 21
B35: 13.15 - 13.30 | C35: 1 | D35: 2 | E35: 0 | F35: 1 | G35: 0 | H35: 0 | I35: 6 | J35: 1 | K35: 0 | L35: 0 | M35: 5 | N35: 0 | O35: =SUM(C35:L35,N35) -> 11 | P35: =SUM(C35:N35) -> 16
B36: 13.30 - 13.45 | C36: 7 | D36: 1 | E36: 1 | F36: 2 | G36: 0 | H36: 0 | I36: 0 | J36: 1 | K36: 0 | L36: 0 | M36: 3 | N36: 0 | O36: =SUM(C36:L36,N36) -> 12 | P36: =SUM(C36:N36) -> 15
B37: 13.45 - 14.00 | C37: 5 | D37: 2 | E37: 1 | F37: 4 | G37: 0 | H37: 0 | I37: 4 | J37: 0 | K37: 1 | L37: 0 | M37: 12 | N37: 0 | O37: =SUM(C37:L37,N37) -> 17 | P37: =SUM(C37:N37) -> 29
B38: 14.00 - 14.15 | C38: 3 | D38: 0 | E38: 0 | F38: 2 | G38: 0 | H38: 0 | I38: 2 | J38: 0 | K38: 0 | L38: 0 | M38: 5 | N38: 0 | O38: =SUM(C38:L38,N38) -> 7 | P38: =SUM(C38:N38) -> 12
B39: 14.15 - 14.30 | C39: 2 | D39: 1 | E39: 0 | F39: 4 | G39: 0 | H39: 0 | I39: 2 | J39: 0 | K39: 0 | L39: 0 | M39: 11 | N39: 0 | O39: =SUM(C39:L39,N39) -> 9 | P39: =SUM(C39:N39) -> 20
B40: 14.30 - 14.45 | C40: 2 | D40: 2 | E40: 0 | F40: 1 | G40: 0 | H40: 0 | I40: 1 | J40: 0 | K40: 0 | L40: 0 | M40: 2 | N40: 0 | O40: =SUM(C40:L40,N40) -> 6 | P40: =SUM(C40:N40) -> 8
... B57: 18.45 - 19.00 | C57: 5 | D57: 1 | E57: 0 | F57: 6 | G57: 0 | H57: 0 | I57: 2 | J57: 0 | K57: 0 | L57: 0 | M57: 7 | N57: 0 | O57: =SUM(C57:L57,N57) -> 14 | P57: =SUM(C57:N57) -> 21
B58: Totals | C58: =SUM(C10:C57) -> 139 | D58: =SUM(D10:D57) -> 68 | E58: =SUM(E10:E57) -> 17 | F58: =SUM(F10:F57) -> 149 | G58: =SUM(G10:G57) -> 1 | H58: =SUM(H10:H57) -> 0 | I58: =SUM(I10:I57) -> 91 | J58: =SUM(J10:J57) -> 19 | ... P58: =SUM(P10:P57) -> 846
...

Sheet 24.09 Entebbe-Busabala
B1: Consultancy services for Preparation of Expressway Development Master Plan (EDMP) for Uganda
B2: MANUAL CLASSIFIED COUNT (MCC)
B3: ROAD NAME: | C3: MCC-C2-STN53-BUSABALA ROAD
C5: Date | D5: 24.09.19 | F5: Location | G5: ZIRANUMBU TOWN | J5: Surveyor | K5: SSEMUKO SAMUEL
C6: Dir. From | D6: ENTEBBE RD | F6: Dir. To | G6: BUSABALA RD | J6: Supervisor | K6: STEVEN
B8: Time / Veh Type | R8: SUMMARY TRAFFIC VOLUMES
C9: 1. Car | D9: 2. Station Wagon | E9: 3. Pickups | F9: 4. Minibus, matatu | G9: 5. Medium bus | H9: 6. Large Bus | I9: 7. Light Truck | J9: 8. Medium Truck | K9: 9. Heavy truck | L9: 10. Truck Trailer | M9: 11. Motor cycles | N9: 12. Tractors | O9: Total Excl M/Cycles | P9: Total All | R9: Time | S9: 1. Car | T9: 2. Station Wagon | U9: 3. Pickups | V9: 4. Minibus, matatu | W9: 5. Medium bus | X9: 6. Large Bus | Y9: 7. Light Truck | Z9: 8. Medium Truck | AA9: 9. Heavy truck | AB9: 10. Truck Trailer | AC9: 11. Motorcycles | AD9: 12. Tractors, Graders | AE9: Total Excl M/ Cycles | AF9: Total All
B10: 07.00 - 07.15 | C10: 11 | D10: 1 | E10: 1 | F10: 7 | G10: 0 | H10: 0 | I10: 1 | J10: 0 | K10: 0 | L10: 0 | M10: 24 | N10: 0 | O10: =SUM(C10:L10,N10) -> 21 | P10: =SUM(C10:N10) -> 45 | R10: 0700-0800 | S10: =SUM(C10:C13) -> 33 | T10: =SUM(D10:D13) -> 7 | U10: =SUM(E10:E13) -> 3 | V10: =SUM(F10:F13) -> 27 | W10: =SUM(G10:G13) -> 0 | X10: =SUM(H10:H13) -> 0 | Y10: =SUM(I10:I13) -> 9 | Z10: =SUM(J10:J13) -> 2 | ... AF10: =SUM(P10:P13) -> 195
B11: 07.15 - 07.30 | C11: 5 | D11: 2 | E11: 0 | F11: 6 | G11: 0 | H11: 0 | I11: 3 | J11: 0 | K11: 0 | L11: 0 | M11: 35 | N11: 0 | O11: =SUM(C11:L11,N11) -> 16 | P11: =SUM(C11:N11) -> 51 | R11: 0800-0900 | S11: =SUM(C14:C17) -> 24 | T11: =SUM(D14:D17) -> 4 | U11: =SUM(E14:E17) -> 1 | V11: =SUM(F14:F17) -> 19 | W11: =SUM(G14:G17) -> 0 | X11: =SUM(H14:H17) -> 0 | Y11: =SUM(I14:I17) -> 10 | Z11: =SUM(J14:J17) -> 2 | ... AF11: =SUM(P14:P17) -> 141
B12: 07.30 - 07.45 | C12: 8 | D12: 2 | E12: 2 | F12: 6 | G12: 0 | H12: 0 | I12: 2 | J12: 1 | K12: 0 | L12: 0 | M12: 26 | N12: 0 | O12: =SUM(C12:L12,N12) -> 21 | P12: =SUM(C12:N12) -> 47 | R12: 0900-1000 | S12: =SUM(C18:C21) -> 23 | T12: =SUM(D18:D21) -> 5 | U12: =SUM(E18:E21) -> 4 | V12: =SUM(F18:F21) -> 15 | W12: =SUM(G18:G21) -> 0 | X12: =SUM(H18:H21) -> 0 | Y12: =SUM(I18:I21) -> 9 | Z12: =SUM(J18:J21) -> 7 | ... AF12: =SUM(P18:P21) -> 118
B13: 07.45 - 08.00 | C13: 9 | D13: 2 | E13: 0 | F13: 8 | G13: 0 | H13: 0 | I13: 3 | J13: 1 | K13: 0 | L13: 0 | M13: 29 | N13: 0 | O13: =SUM(C13:L13,N13) -> 23 | P13: =SUM(C13:N13) -> 52 | R13: 1000-1100 | S13: =SUM(C22:C25) -> 14 | T13: =SUM(D22:D25) -> 5 | U13: =SUM(E22:E25) -> 1 | V13: =SUM(F22:F25) -> 17 | W13: =SUM(G22:G25) -> 0 | X13: =SUM(H22:H25) -> 0 | Y13: =SUM(I22:I25) -> 13 | Z13: =SUM(J22:J25) -> 2 | ... AF13: =SUM(P22:P25) -> 116
B14: 08.00 - 08.15 | C14: 9 | D14: 3 | E14: 0 | F14: 7 | G14: 0 | H14: 0 | I14: 0 | J14: 0 | K14: 0 | L14: 0 | M14: 19 | N14: 0 | O14: =SUM(C14:L14,N14) -> 19 | P14: =SUM(C14:N14) -> 38 | R14: 1100-1200 | S14: =SUM(C26:C29) -> 11 | T14: =SUM(D26:D29) -> 5 | U14: =SUM(E26:E29) -> 1 | V14: =SUM(F26:F29) -> 18 | W14: =SUM(G26:G29) -> 0 | X14: =SUM(H26:H29) -> 0 | Y14: =SUM(I26:I29) -> 7 | Z14: =SUM(J26:J29) -> 7 | ... AF14: =SUM(P26:P29) -> 111
B15: 08.15 - 08.30 | C15: 3 | D15: 1 | E15: 0 | F15: 3 | G15: 0 | H15: 0 | I15: 3 | J15: 2 | K15: 0 | L15: 0 | M15: 28 | N15: 0 | O15: =SUM(C15:L15,N15) -> 12 | P15: =SUM(C15:N15) -> 40 | R15: 1200-1300 | S15: =SUM(C30:C33) -> 7 | T15: =SUM(D30:D33) -> 2 | U15: =SUM(E30:E33) -> 2 | V15: =SUM(F30:F33) -> 18 | W15: =SUM(G30:G33) -> 0 | X15: =SUM(H30:H33) -> 0 | Y15: =SUM(I30:I33) -> 9 | Z15: =SUM(J30:J33) -> 1 | ... AF15: =SUM(P30:P33) -> 95
B16: 08.30 - 08.45 | C16: 10 | D16: 0 | E16: 0 | F16: 4 | G16: 0 | H16: 0 | I16: 3 | J16: 0 | K16: 0 | L16: 0 | M16: 10 | N16: 0 | O16: =SUM(C16:L16,N16) -> 17 | P16: =SUM(C16:N16) -> 27 | R16: 1300-1400 | S16: =SUM(C34:C37) -> 12 | T16: =SUM(D34:D37) -> 1 | U16: =SUM(E34:E37) -> 0 | V16: =SUM(F34:F37) -> 24 | W16: =SUM(G34:G37) -> 0 | X16: =SUM(H34:H37) -> 0 | Y16: =SUM(I34:I37) -> 12 | Z16: =SUM(J34:J37) -> 2 | ... AF16: =SUM(P34:P37) -> 91
B17: 08.45 - 9.00 | C17: 2 | D17: 0 | E17: 1 | F17: 5 | G17: 0 | H17: 0 | I17: 4 | J17: 0 | K17: 0 | L17: 0 | M17: 24 | N17: 0 | O17: =SUM(C17:L17,N17) -> 12 | P17: =SUM(C17:N17) -> 36 | R17: 1400-1500 | S17: =SUM(C38:C41) -> 6 | T17: =SUM(D38:D41) -> 4 | U17: =SUM(E38:E41) -> 2 | V17: =SUM(F38:F41) -> 18 | W17: =SUM(G38:G41) -> 0 | X17: =SUM(H38:H41) -> 0 | Y17: =SUM(I38:I41) -> 9 | Z17: =SUM(J38:J41) -> 1 | ... AF17: =SUM(P38:P41) -> 80
B18: 09.00 - 09.15 | C18: 7 | D18: 1 | E18: 2 | F18: 4 | G18: 0 | H18: 0 | I18: 3 | J18: 2 | K18: 0 | L18: 0 | M18: 12 | N18: 0 | O18: =SUM(C18:L18,N18) -> 19 | P18: =SUM(C18:N18) -> 31 | R18: 1500-1600 | S18: =SUM(C42:C45) -> 19 | T18: =SUM(D42:D45) -> 1 | U18: =SUM(E42:E45) -> 0 | V18: =SUM(F42:F45) -> 21 | W18: =SUM(G42:G45) -> 0 | X18: =SUM(H42:H45) -> 0 | Y18: =SUM(I42:I45) -> 10 | Z18: =SUM(J42:J45) -> 3 | ... AF18: =SUM(P42:P45) -> 94
B19: 09.15 - 09.30 | C19: 5 | D19: 1 | E19: 1 | F19: 4 | G19: 0 | H19: 0 | I19: 3 | J19: 1 | K19: 0 | L19: 0 | M19: 15 | N19: 0 | O19: =SUM(C19:L19,N19) -> 15 | P19: =SUM(C19:N19) -> 30 | R19: 1600-1700 | S19: =SUM(C46:C49) -> 17 | T19: =SUM(D46:D49) -> 5 | U19: =SUM(E46:E49) -> 3 | V19: =SUM(F46:F49) -> 27 | W19: =SUM(G46:G49) -> 0 | X19: =SUM(H46:H49) -> 0 | Y19: =SUM(I46:I49) -> 6 | Z19: =SUM(J46:J49) -> 1 | ... AF19: =SUM(P46:P49) -> 110
B20: 09.30 - 09.45 | C20: 1 | D20: 1 | E20: 1 | F20: 2 | G20: 0 | H20: 0 | I20: 1 | J20: 0 | K20: 0 | L20: 0 | M20: 4 | N20: 0 | O20: =SUM(C20:L20,N20) -> 6 | P20: =SUM(C20:N20) -> 10 | R20: 1700-1800 | S20: =SUM(C50:C53) -> 18 | T20: =SUM(D50:D53) -> 3 | U20: =SUM(E50:E53) -> 1 | V20: =SUM(F50:F53) -> 32 | W20: =SUM(G50:G53) -> 2 | X20: =SUM(H50:H53) -> 0 | Y20: =SUM(I50:I53) -> 11 | Z20: =SUM(J50:J53) -> 0 | ... AF20: =SUM(P50:P53) -> 127
B21: 09.45 - 10.00 | C21: 10 | D21: 2 | E21: 0 | F21: 5 | G21: 0 | H21: 0 | I21: 2 | J21: 4 | K21: 0 | L21: 0 | M21: 24 | N21: 0 | O21: =SUM(C21:L21,N21) -> 23 | P21: =SUM(C21:N21) -> 47 | R21: 1800-1900 | S21: =SUM(C54:C57) -> 18 | T21: =SUM(D54:D57) -> 3 | U21: =SUM(E54:E57) -> 3 | V21: =SUM(F54:F57) -> 30 | W21: =SUM(G54:G57) -> 4 | X21: =SUM(H54:H57) -> 0 | Y21: =SUM(I54:I57) -> 10 | Z21: =SUM(J54:J57) -> 3 | ... AF21: =SUM(P54:P57) -> 125
B22: 10.00 - 10.15 | C22: 4 | D22: 2 | E22: 1 | F22: 4 | G22: 0 | H22: 0 | I22: 1 | J22: 0 | K22: 0 | L22: 0 | M22: 14 | N22: 0 | O22: =SUM(C22:L22,N22) -> 12 | P22: =SUM(C22:N22) -> 26 | R22: AM Peak Hr | S22: =MAX(S10:S12) -> 33 | T22: =MAX(T10:T12) -> 7 | U22: =MAX(U10:U12) -> 4 | V22: =MAX(V10:V12) -> 27 | W22: =MAX(W10:W12) -> 0 | X22: =MAX(X10:X12) -> 0 | Y22: =MAX(Y10:Y12) -> 10 | Z22: =MAX(Z10:Z12) -> 7 | ... AF22: =MAX(AF10:AF12) -> 195
B23: 10.15 - 10.30 | C23: 4 | D23: 1 | E23: 0 | F23: 3 | G23: 0 | H23: 0 | I23: 5 | J23: 0 | K23: 0 | L23: 0 | M23: 21 | N23: 0 | O23: =SUM(C23:L23,N23) -> 13 | P23: =SUM(C23:N23) -> 34 | R23: IP Peak Hr | S23: =MAX(S13:S18) -> 19 | T23: =MAX(T13:T18) -> 5 | U23: =MAX(U13:U18) -> 2 | V23: =MAX(V13:V18) -> 24 | W23: =MAX(W13:W18) -> 0 | X23: =MAX(X13:X18) -> 0 | Y23: =MAX(Y13:Y18) -> 13 | Z23: =MAX(Z13:Z18) -> 7 | ... AF23: =MAX(AF13:AF18) -> 116
B24: 10.30 - 10.45 | C24: 1 | D24: 0 | E24: 0 | F24: 5 | G24: 0 | H24: 0 | I24: 5 | J24: 2 | K24: 0 | L24: 0 | M24: 12 | N24: 0 | O24: =SUM(C24:L24,N24) -> 13 | P24: =SUM(C24:N24) -> 25 | R24: PM Peak Hr | S24: =MAX(S19:S21) -> 18 | T24: =MAX(T19:T21) -> 5 | U24: =MAX(U19:U21) -> 3 | V24: =MAX(V19:V21) -> 32 | W24: =MAX(W19:W21) -> 4 | X24: =MAX(X19:X21) -> 0 | Y24: =MAX(Y19:Y21) -> 11 | Z24: =MAX(Z19:Z21) -> 3 | ... AF24: =MAX(AF19:AF21) -> 127
B25: 10.45 - 11.00 | C25: 5 | D25: 2 | E25: 0 | F25: 5 | G25: 0 | H25: 0 | I25: 2 | J25: 0 | K25: 0 | L25: 0 | M25: 17 | N25: 0 | O25: =SUM(C25:L25,N25) -> 14 | P25: =SUM(C25:N25) -> 31 | R25: AM Period | S25: =SUM(S10:S12) -> 80 | T25: =SUM(T10:T12) -> 16 | U25: =SUM(U10:U12) -> 8 | V25: =SUM(V10:V12) -> 61 | W25: =SUM(W10:W12) -> 0 | X25: =SUM(X10:X12) -> 0 | Y25: =SUM(Y10:Y12) -> 28 | Z25: =SUM(Z10:Z12) -> 11 | ... AF25: =SUM(AF10:AF12) -> 454
B26: 11.00 - 11.15 | C26: 4 | D26: 1 | E26: 1 | F26: 7 | G26: 0 | H26: 0 | I26: 1 | J26: 1 | K26: 1 | L26: 0 | M26: 22 | N26: 0 | O26: =SUM(C26:L26,N26) -> 16 | P26: =SUM(C26:N26) -> 38 | R26: IP Period | S26: =SUM(S13:S18) -> 69 | T26: =SUM(T13:T18) -> 18 | U26: =SUM(U13:U18) -> 6 | V26: =SUM(V13:V18) -> 116 | W26: =SUM(W13:W18) -> 0 | X26: =SUM(X13:X18) -> 0 | Y26: =SUM(Y13:Y18) -> 60 | Z26: =SUM(Z13:Z18) -> 16 | ... AF26: =SUM(AF13:AF18) -> 587
B27: 11.15 - 11.30 | C27: 4 | D27: 2 | E27: 0 | F27: 4 | G27: 0 | H27: 0 | I27: 3 | J27: 2 | K27: 0 | L27: 1 | M27: 13 | N27: 0 | O27: =SUM(C27:L27,N27) -> 16 | P27: =SUM(C27:N27) -> 29 | R27: PM Period | S27: =SUM(S19:S21) -> 53 | T27: =SUM(T19:T21) -> 11 | U27: =SUM(U19:U21) -> 7 | V27: =SUM(V19:V21) -> 89 | W27: =SUM(W19:W21) -> 6 | X27: =SUM(X19:X21) -> 0 | Y27: =SUM(Y19:Y21) -> 27 | Z27: =SUM(Z19:Z21) -> 4 | ... AF27: =SUM(AF19:AF21) -> 362
B28: 11.30 - 11.45 | C28: 2 | D28: 1 | E28: 0 | F28: 4 | G28: 0 | H28: 0 | I28: 1 | J28: 2 | K28: 0 | L28: 0 | M28: 12 | N28: 0 | O28: =SUM(C28:L28,N28) -> 10 | P28: =SUM(C28:N28) -> 22 | R28: 12 Hours | S28: =SUM(S10:S21) -> 202 | T28: =SUM(T10:T21) -> 45 | U28: =SUM(U10:U21) -> 21 | V28: =SUM(V10:V21) -> 266 | W28: =SUM(W10:W21) -> 6 | X28: =SUM(X10:X21) -> 0 | Y28: =SUM(Y10:Y21) -> 115 | Z28: =SUM(Z10:Z21) -> 31 | ... AF28: =SUM(AF10:AF21) -> 1403
B29: 11.45 - 12.00 | C29: 1 | D29: 1 | E29: 0 | F29: 3 | G29: 0 | H29: 0 | I29: 2 | J29: 2 | K29: 0 | L29: 0 | M29: 13 | N29: 0 | O29: =SUM(C29:L29,N29) -> 9 | P29: =SUM(C29:N29) -> 22
B30: 12.00 - 12.15 | C30: 2 | D30: 0 | E30: 1 | F30: 5 | G30: 0 | H30: 0 | I30: 5 | J30: 0 | K30: 0 | L30: 0 | M30: 22 | N30: 0 | O30: =SUM(C30:L30,N30) -> 13 | P30: =SUM(C30:N30) -> 35
B31: 12.15 - 12.30 | C31: 1 | D31: 0 | E31: 0 | F31: 4 | G31: 0 | H31: 0 | I31: 1 | J31: 0 | K31: 0 | L31: 0 | M31: 10 | N31: 0 | O31: =SUM(C31:L31,N31) -> 6 | P31: =SUM(C31:N31) -> 16
B32: 12.30 - 12.45 | C32: 3 | D32: 2 | E32: 1 | F32: 5 | G32: 0 | H32: 0 | I32: 0 | J32: 1 | K32: 0 | L32: 0 | M32: 16 | N32: 0 | O32: =SUM(C32:L32,N32) -> 12 | P32: =SUM(C32:N32) -> 28
B33: 12.45 - 13.00 | C33: 1 | D33: 0 | E33: 0 | F33: 4 | G33: 0 | H33: 0 | I33: 3 | J33: 0 | K33: 0 | L33: 0 | M33: 8 | N33: 0 | O33: =SUM(C33:L33,N33) -> 8 | P33: =SUM(C33:N33) -> 16
B34: 13.00 - 13.15 | C34: 3 | D34: 1 | E34: 0 | F34: 2 | G34: 0 | H34: 0 | I34: 3 | J34: 1 | K34: 0 | L34: 0 | M34: 10 | N34: 0 | O34: =SUM(C34:L34,N34) -> 10 | P34: =SUM(C34:N34) -> 20
B35: 13.15 - 13.30 | C35: 0 | D35: 0 | E35: 0 | F35: 9 | G35: 0 | H35: 0 | I35: 2 | J35: 1 | K35: 0 | L35: 0 | M35: 7 | O35: =SUM(C35:L35,N35) -> 12 | P35: =SUM(C35:N35) -> 19
B36: 13.30 - 13.45 | C36: 3 | D36: 0 | E36: 0 | F36: 8 | G36: 0 | H36: 0 | I36: 5 | J36: 0 | K36: 0 | L36: 0 | M36: 14 | N36: 0 | O36: =SUM(C36:L36,N36) -> 16 | P36: =SUM(C36:N36) -> 30
B37: 13.45 - 14.00 | C37: 6 | D37: 0 | E37: 0 | F37: 5 | G37: 0 | H37: 0 | I37: 2 | J37: 0 | K37: 0 | L37: 0 | M37: 9 | N37: 0 | O37: =SUM(C37:L37,N37) -> 13 | P37: =SUM(C37:N37) -> 22
B38: 14.00 - 14.15 | C38: 0 | D38: 2 | E38: 0 | F38: 5 | G38: 0 | H38: 0 | I38: 3 | J38: 0 | K38: 0 | L38: 0 | M38: 9 | N38: 0 | O38: =SUM(C38:L38,N38) -> 10 | P38: =SUM(C38:N38) -> 19
B39: 14.15 - 14.30 | C39: 2 | D39: 1 | E39: 1 | F39: 3 | G39: 0 | H39: 0 | I39: 2 | J39: 0 | K39: 0 | L39: 0 | M39: 11 | N39: 0 | O39: =SUM(C39:L39,N39) -> 9 | P39: =SUM(C39:N39) -> 20
B40: 14.30 - 14.45 | C40: 1 | D40: 1 | E40: 1 | F40: 4 | G40: 0 | H40: 0 | I40: 3 | J40: 0 | K40: 0 | L40: 0 | M40: 9 | N40: 0 | O40: =SUM(C40:L40,N40) -> 10 | P40: =SUM(C40:N40) -> 19
B41: 14.45 - 15.00 | C41: 3 | D41: 0 | E41: 0 | F41: 6 | G41: 0 | H41: 0 | I41: 1 | J41: 1 | K41: 0 | L41: 0 | M41: 11 | N41: 0 | O41: =SUM(C41:L41,N41) -> 11 | P41: =SUM(C41:N41) -> 22
B42: 15.00 - 15.15 | C42: 8 | D42: 0 | E42: 0 | F42: 4 | G42: 0 | H42: 0 | I42: 1 | J42: 0 | K42: 0 | L42: 0 | M42: 7 | N42: 0 | O42: =SUM(C42:L42,N42) -> 13 | P42: =SUM(C42:N42) -> 20
...

Sheet 24.09 Busabala-Entebbe
B1: Consultancy services for Preparation of Expressway Development Master Plan (EDMP) for Uganda
B2: MANUAL CLASSIFIED COUNT (MCC)
B3: ROAD NAME: | C3: ='[1]24.09.2019 ENTEBBE RD-BUSABALA '!C3:G3 -> MCC-C2-STN53-BUSABALA ROAD
C5: Date | D5: ='[1]24.09.2019 ENTEBBE RD-BUSABALA '!D5 -> 24.09.19 | F5: Location | G5: ='[1]24.09.2019 ENTEBBE RD-BUSABALA '!G5:H5 -> ZIRANUMBU TOWN | J5: Surveyor | K5: GODFREY
C6: Dir. From | D6: BUSABALA RD | F6: Dir. To | G6: ENTEBBE RD | J6: Supervisor | K6: ='[1]24.09.2019 ENTEBBE RD-BUSABALA '!K6:L6 -> STEVEN
B8: Time / Veh Type | R8: SUMMARY TRAFFIC VOLUMES
C9: 1. Car | D9: 2. Station Wagon | E9: 3. Pickups | F9: 4. Minibus, matatu | G9: 5. Medium bus | H9: 6. Large Bus | I9: 7. Light Truck | J9: 8. Medium Truck | K9: 9. Heavy truck | L9: 10. Truck Trailer | M9: 11. Motor cycles | N9: 12. Tractors | O9: Total Excl M/Cycles | P9: Total All | R9: Time | S9: 1. Car | T9: 2. Station Wagon | U9: 3. Pickups | V9: 4. Minibus, matatu | W9: 5. Medium bus | X9: 6. Large Bus | Y9: 7. Light Truck | Z9: 8. Medium Truck | AA9: 9. Heavy truck | AB9: 10. Truck Trailer | AC9: 11. Motorcycles | AD9: 12. Tractors, Graders | AE9: Total Excl M/ Cycles | AF9: Total All
B10: 07.00 - 07.15 | C10: 4 | D10: 4 | E10: 0 | F10: 2 | G10: 0 | H10: 0 | I10: 0 | J10: 1 | K10: 0 | L10: 0 | M10: 7 | N10: 0 | O10: =SUM(C10:L10,N10) -> 11 | P10: =SUM(C10:N10) -> 18 | R10: 0700-0800 | S10: =SUM(C10:C13) -> 16 | T10: =SUM(D10:D13) -> 12 | U10: =SUM(E10:E13) -> 1 | V10: =SUM(F10:F13) -> 13 | W10: =SUM(G10:G13) -> 0 | X10: =SUM(H10:H13) -> 0 | Y10: =SUM(I10:I13) -> 5 | Z10: =SUM(J10:J13) -> 2 | ... AF10: =SUM(P10:P13) -> 86
B11: 07.15 - 07.30 | C11: 9 | D11: 4 | E11: 1 | F11: 2 | G11: 0 | H11: 0 | I11: 1 | J11: 1 | K11: 0 | L11: 0 | M11: 12 | N11: 0 | O11: =SUM(C11:L11,N11) -> 18 | P11: =SUM(C11:N11) -> 30 | R11: 0800-0900 | S11: =SUM(C14:C17) -> 11 | T11: =SUM(D14:D17) -> 4 | U11: =SUM(E14:E17) -> 2 | V11: =SUM(F14:F17) -> 10 | W11: =SUM(G14:G17) -> 0 | X11: =SUM(H14:H17) -> 0 | Y11: =SUM(I14:I17) -> 4 | Z11: =SUM(J14:J17) -> 0 | ... AF11: =SUM(P14:P17) -> 60
B12: 07.30 - 07.45 | C12: 2 | D12: 1 | E12: 0 | F12: 5 | G12: 0 | H12: 0 | I12: 2 | J12: 0 | K12: 0 | L12: 0 | M12: 11 | N12: 0 | O12: =SUM(C12:L12,N12) -> 10 | P12: =SUM(C12:N12) -> 21 | R12: 0900-1000 | S12: =SUM(C18:C21) -> 5 | T12: =SUM(D18:D21) -> 2 | U12: =SUM(E18:E21) -> 0 | V12: =SUM(F18:F21) -> 13 | W12: =SUM(G18:G21) -> 1 | X12: =SUM(H18:H21) -> 0 | Y12: =SUM(I18:I21) -> 7 | Z12: =SUM(J18:J21) -> 1 | ... AF12: =SUM(P18:P21) -> 63
B13: 07.45 - 08.00 | C13: 1 | D13: 3 | E13: 0 | F13: 4 | G13: 0 | H13: 0 | I13: 2 | J13: 0 | K13: 0 | L13: 0 | M13: 7 | N13: 0 | O13: =SUM(C13:L13,N13) -> 10 | P13: =SUM(C13:N13) -> 17 | R13: 1000-1100 | S13: =SUM(C22:C25) -> 8 | T13: =SUM(D22:D25) -> 4 | U13: =SUM(E22:E25) -> 1 | V13: =SUM(F22:F25) -> 12 | W13: =SUM(G22:G25) -> 0 | X13: =SUM(H22:H25) -> 0 | Y13: =SUM(I22:I25) -> 7 | Z13: =SUM(J22:J25) -> 1 | ... AF13: =SUM(P22:P25) -> 80
B14: 08.00 - 08.15 | C14: 2 | D14: 1 | E14: 0 | F14: 4 | G14: 0 | H14: 0 | I14: 1 | J14: 0 | K14: 0 | L14: 0 | M14: 3 | N14: 0 | O14: =SUM(C14:L14,N14) -> 8 | P14: =SUM(C14:N14) -> 11 | R14: 1100-1200 | S14: =SUM(C26:C29) -> 6 | T14: =SUM(D26:D29) -> 4 | U14: =SUM(E26:E29) -> 2 | V14: =SUM(F26:F29) -> 13 | W14: =SUM(G26:G29) -> 0 | X14: =SUM(H26:H29) -> 0 | Y14: =SUM(I26:I29) -> 8 | Z14: =SUM(J26:J29) -> 3 | ... AF14: =SUM(P26:P29) -> 74
B15: 08.15 - 08.30 | C15: 4 | D15: 3 | E15: 0 | F15: 2 | G15: 0 | H15: 0 | I15: 1 | J15: 0 | K15: 0 | L15: 0 | M15: 11 | N15: 0 | O15: =SUM(C15:L15,N15) -> 10 | P15: =SUM(C15:N15) -> 21 | R15: 1200-1300 | S15: =SUM(C30:C33) -> 12 | T15: =SUM(D30:D33) -> 8 | U15: =SUM(E30:E33) -> 3 | V15: =SUM(F30:F33) -> 11 | W15: =SUM(G30:G33) -> 0 | X15: =SUM(H30:H33) -> 0 | Y15: =SUM(I30:I33) -> 8 | Z15: =SUM(J30:J33) -> 3 | ... AF15: =SUM(P30:P33) -> 77
B16: 08.30 - 08.45 | C16: 0 | D16: 0 | E16: 0 | F16: 2 | G16: 0 | H16: 0 | I16: 1 | J16: 0 | K16: 0 | L16: 0 | M16: 5 | N16: 0 | O16: =SUM(C16:L16,N16) -> 3 | P16: =SUM(C16:N16) -> 8 | R16: 1300-1400 | S16: =SUM(C34:C37) -> 10 | T16: =SUM(D34:D37) -> 4 | U16: =SUM(E34:E37) -> 0 | V16: =SUM(F34:F37) -> 9 | W16: =SUM(G34:G37) -> 0 | X16: =SUM(H34:H37) -> 0 | Y16: =SUM(I34:I37) -> 5 | Z16: =SUM(J34:J37) -> 1 | ... AF16: =SUM(P34:P37) -> 51
B17: 08.45 - 9.00 | C17: 5 | D17: 0 | E17: 2 | F17: 2 | G17: 0 | H17: 0 | I17: 1 | J17: 0 | K17: 0 | L17: 0 | M17: 10 | N17: 0 | O17: =SUM(C17:L17,N17) -> 10 | P17: =SUM(C17:N17) -> 20 | R17: 1400-1500 | S17: =SUM(C38:C41) -> 22 | T17: =SUM(D38:D41) -> 6 | U17: =SUM(E38:E41) -> 4 | V17: =SUM(F38:F41) -> 13 | W17: =SUM(G38:G41) -> 0 | X17: =SUM(H38:H41) -> 0 | Y17: =SUM(I38:I41) -> 4 | Z17: =SUM(J38:J41) -> 0 | ... AF17: =SUM(P38:P41) -> 77
B18: 09.00 - 09.15 | C18: 1 | D18: 0 | E18: 0 | F18: 3 | G18: 0 | H18: 0 | I18: 2 | J18: 0 | K18: 0 | L18: 0 | M18: 7 | N18: 0 | O18: =SUM(C18:L18,N18) -> 6 | P18: =SUM(C18:N18) -> 13 | R18: 1500-1600 | S18: =SUM(C42:C45) -> 13 | T18: =SUM(D42:D45) -> 7 | U18: =SUM(E42:E45) -> 1 | V18: =SUM(F42:F45) -> 14 | W18: =SUM(G42:G45) -> 0 | X18: =SUM(H42:H45) -> 0 | Y18: =SUM(I42:I45) -> 12 | Z18: =SUM(J42:J45) -> 1 | ... AF18: =SUM(P42:P45) -> 76
B19: 09.15 - 09.30 | C19: 2 | D19: 2 | E19: 0 | F19: 3 | G19: 0 | H19: 0 | I19: 0 | J19: 0 | K19: 0 | L19: 0 | M19: 16 | N19: 0 | O19: =SUM(C19:L19,N19) -> 7 | P19: =SUM(C19:N19) -> 23 | R19: 1600-1700 | S19: =SUM(C46:C49) -> 15 | T19: =SUM(D46:D49) -> 11 | U19: =SUM(E46:E49) -> 4 | V19: =SUM(F46:F49) -> 11 | W19: =SUM(G46:G49) -> 0 | X19: =SUM(H46:H49) -> 0 | Y19: =SUM(I46:I49) -> 6 | Z19: =SUM(J46:J49) -> 2 | ... AF19: =SUM(P46:P49) -> 82
B20: 09.30 - 09.45 | C20: 0 | D20: 0 | E20: 0 | F20: 3 | G20: 1 | H20: 0 | I20: 1 | J20: 1 | K20: 0 | L20: 0 | M20: 3 | N20: 0 | O20: =SUM(C20:L20,N20) -> 6 | P20: =SUM(C20:N20) -> 9 | R20: 1700-1800 | S20: =SUM(C50:C53) -> 19 | T20: =SUM(D50:D53) -> 3 | U20: =SUM(E50:E53) -> 1 | V20: =SUM(F50:F53) -> 16 | W20: =SUM(G50:G53) -> 0 | X20: =SUM(H50:H53) -> 0 | Y20: =SUM(I50:I53) -> 9 | Z20: =SUM(J50:J53) -> 2 | ... AF20: =SUM(P50:P53) -> 83
B21: 09.45 - 10.00 | C21: 2 | D21: 0 | E21: 0 | F21: 4 | G21: 0 | H21: 0 | I21: 4 | J21: 0 | K21: 0 | L21: 0 | M21: 8 | N21: 0 | O21: =SUM(C21:L21,N21) -> 10 | P21: =SUM(C21:N21) -> 18 | R21: 1800-1900 | S21: =SUM(C54:C57) -> 26 | T21: =SUM(D54:D57) -> 16 | U21: =SUM(E54:E57) -> 4 | V21: =SUM(F54:F57) -> 17 | W21: =SUM(G54:G57) -> 0 | X21: =SUM(H54:H57) -> 0 | Y21: =SUM(I54:I57) -> 12 | Z21: =SUM(J54:J57) -> 0 | ... AF21: =SUM(P54:P57) -> 122
B22: 10.00 - 10.15 | C22: 4 | D22: 2 | E22: 1 | F22: 4 | G22: 0 | H22: 0 | I22: 3 | J22: 0 | K22: 0 | L22: 0 | M22: 7 | N22: 0 | O22: =SUM(C22:L22,N22) -> 14 | P22: =SUM(C22:N22) -> 21 | R22: AM Peak Hr | S22: =MAX(S10:S12) -> 16 | T22: =MAX(T10:T12) -> 12 | U22: =MAX(U10:U12) -> 2 | V22: =MAX(V10:V12) -> 13 | W22: =MAX(W10:W12) -> 1 | X22: =MAX(X10:X12) -> 0 | Y22: =MAX(Y10:Y12) -> 7 | Z22: =MAX(Z10:Z12) -> 2 | ... AF22: =MAX(AF10:AF12) -> 86
B23: 10.15 - 10.30 | C23: 2 | D23: 1 | E23: 0 | F23: 3 | G23: 0 | H23: 0 | I23: 0 | J23: 0 | K23: 0 | L23: 0 | M23: 17 | N23: 0 | O23: =SUM(C23:L23,N23) -> 6 | P23: =SUM(C23:N23) -> 23 | R23: IP Peak Hr | S23: =MAX(S13:S18) -> 22 | T23: =MAX(T13:T18) -> 8 | U23: =MAX(U13:U18) -> 4 | V23: =MAX(V13:V18) -> 14 | W23: =MAX(W13:W18) -> 0 | X23: =MAX(X13:X18) -> 0 | Y23: =MAX(Y13:Y18) -> 12 | Z23: =MAX(Z13:Z18) -> 3 | ... AF23: =MAX(AF13:AF18) -> 80
B24: 10.30 - 10.45 | C24: 1 | D24: 0 | E24: 0 | F24: 2 | G24: 0 | H24: 0 | I24: 3 | J24: 1 | K24: 0 | L24: 0 | M24: 6 | N24: 0 | O24: =SUM(C24:L24,N24) -> 7 | P24: =SUM(C24:N24) -> 13 | R24: PM Peak Hr | S24: =MAX(S19:S21) -> 26 | T24: =MAX(T19:T21) -> 16 | U24: =MAX(U19:U21) -> 4 | V24: =MAX(V19:V21) -> 17 | W24: =MAX(W19:W21) -> 0 | X24: =MAX(X19:X21) -> 0 | Y24: =MAX(Y19:Y21) -> 12 | Z24: =MAX(Z19:Z21) -> 2 | ... AF24: =MAX(AF19:AF21) -> 122
B25: 10.45 - 11.00 | C25: 1 | D25: 1 | E25: 0 | F25: 3 | G25: 0 | H25: 0 | I25: 1 | J25: 0 | K25: 0 | L25: 0 | M25: 17 | N25: 0 | O25: =SUM(C25:L25,N25) -> 6 | P25: =SUM(C25:N25) -> 23 | R25: AM Period | S25: =SUM(S10:S12) -> 32 | T25: =SUM(T10:T12) -> 18 | U25: =SUM(U10:U12) -> 3 | V25: =SUM(V10:V12) -> 36 | W25: =SUM(W10:W12) -> 1 | X25: =SUM(X10:X12) -> 0 | Y25: =SUM(Y10:Y12) -> 16 | Z25: =SUM(Z10:Z12) -> 3 | ... AF25: =SUM(AF10:AF12) -> 209
B26: 11.00 - 11.15 | C26: 3 | D26: 1 | E26: 1 | F26: 4 | G26: 0 | H26: 0 | I26: 3 | J26: 0 | K26: 0 | L26: 0 | M26: 12 | N26: 0 | O26: =SUM(C26:L26,N26) -> 12 | P26: =SUM(C26:N26) -> 24 | R26: IP Period | S26: =SUM(S13:S18) -> 71 | T26: =SUM(T13:T18) -> 33 | U26: =SUM(U13:U18) -> 11 | V26: =SUM(V13:V18) -> 72 | W26: =SUM(W13:W18) -> 0 | X26: =SUM(X13:X18) -> 0 | Y26: =SUM(Y13:Y18) -> 44 | Z26: =SUM(Z13:Z18) -> 9 | ... AF26: =SUM(AF13:AF18) -> 435
B27: 11.15 - 11.30 | C27: 3 | D27: 0 | E27: 0 | F27: 4 | G27: 0 | H27: 0 | I27: 2 | J27: 3 | K27: 0 | L27: 0 | M27: 15 | N27: 0 | O27: =SUM(C27:L27,N27) -> 12 | P27: =SUM(C27:N27) -> 27 | R27: PM Period | S27: =SUM(S19:S21) -> 60 | T27: =SUM(T19:T21) -> 30 | U27: =SUM(U19:U21) -> 9 | V27: =SUM(V19:V21) -> 44 | W27: =SUM(W19:W21) -> 0 | X27: =SUM(X19:X21) -> 0 | Y27: =SUM(Y19:Y21) -> 27 | Z27: =SUM(Z19:Z21) -> 4 | ... AF27: =SUM(AF19:AF21) -> 287
B28: 11.30 - 11.45 | C28: 0 | D28: 1 | E28: 0 | F28: 1 | G28: 0 | H28: 0 | I28: 2 | J28: 0 | K28: 0 | L28: 0 | M28: 7 | N28: 0 | O28: =SUM(C28:L28,N28) -> 4 | P28: =SUM(C28:N28) -> 11 | R28: 12 Hours | S28: =SUM(S10:S21) -> 163 | T28: =SUM(T10:T21) -> 81 | U28: =SUM(U10:U21) -> 23 | V28: =SUM(V10:V21) -> 152 | W28: =SUM(W10:W21) -> 1 | X28: =SUM(X10:X21) -> 0 | Y28: =SUM(Y10:Y21) -> 87 | Z28: =SUM(Z10:Z21) -> 16 | ... AF28: =SUM(AF10:AF21) -> 931
B29: 11.45 - 12.00 | C29: 0 | D29: 2 | E29: 1 | F29: 4 | G29: 0 | H29: 0 | I29: 1 | J29: 0 | K29: 0 | L29: 0 | M29: 4 | N29: 0 | O29: =SUM(C29:L29,N29) -> 8 | P29: =SUM(C29:N29) -> 12
B30: 12.00 - 12.15 | C30: 3 | D30: 1 | E30: 2 | F30: 3 | G30: 0 | H30: 0 | I30: 0 | J30: 0 | K30: 0 | L30: 0 | M30: 7 | N30: 0 | O30: =SUM(C30:L30,N30) -> 9 | P30: =SUM(C30:N30) -> 16
B31: 12.15 - 12.30 | C31: 4 | D31: 2 | E31: 0 | F31: 2 | G31: 0 | H31: 0 | I31: 2 | J31: 1 | K31: 0 | L31: 0 | M31: 7 | N31: 0 | O31: =SUM(C31:L31,N31) -> 11 | P31: =SUM(C31:N31) -> 18
B32: 12.30 - 12.45 | C32: 2 | D32: 0 | E32: 0 | F32: 4 | G32: 0 | H32: 0 | I32: 1 | J32: 1 | K32: 0 | L32: 0 | M32: 14 | N32: 0 | O32: =SUM(C32:L32,N32) -> 8 | P32: =SUM(C32:N32) -> 22
B33: 12.45 - 13.00 | C33: 3 | D33: 5 | E33: 1 | F33: 2 | G33: 0 | H33: 0 | I33: 5 | J33: 1 | K33: 0 | L33: 0 | M33: 4 | N33: 0 | O33: =SUM(C33:L33,N33) -> 17 | P33: =SUM(C33:N33) -> 21
B34: 13.00 - 13.15 | C34: 3 | D34: 0 | E34: 0 | F34: 0 | G34: 0 | H34: 0 | I34: 0 | J34: 1 | K34: 0 | L34: 0 | M34: 8 | N34: 0 | O34: =SUM(C34:L34,N34) -> 4 | P34: =SUM(C34:N34) -> 12
B35: 13.15 - 13.30 | C35: 2 | D35: 3 | E35: 0 | F35: 4 | G35: 0 | H35: 0 | I35: 2 | J35: 0 | K35: 0 | L35: 0 | M35: 4 | N35: 0 | O35: =SUM(C35:L35,N35) -> 11 | P35: =SUM(C35:N35) -> 15
B36: 13.30 - 13.45 | C36: 2 | D36: 0 | E36: 0 | F36: 2 | G36: 0 | H36: 0 | I36: 1 | J36: 0 | K36: 0 | L36: 0 | M36: 1 | N36: 0 | O36: =SUM(C36:L36,N36) -> 5 | P36: =SUM(C36:N36) -> 6
B37: 13.45 - 14.00 | C37: 3 | D37: 1 | E37: 0 | F37: 3 | G37: 0 | H37: 0 | I37: 2 | J37: 0 | K37: 0 | L37: 0 | M37: 9 | N37: 0 | O37: =SUM(C37:L37,N37) -> 9 | P37: =SUM(C37:N37) -> 18
B38: 14.00 - 14.15 | C38: 8 | D38: 0 | E38: 1 | F38: 3 | G38: 0 | H38: 0 | I38: 1 | J38: 0 | K38: 0 | L38: 0 | M38: 5 | N38: 0 | O38: =SUM(C38:L38,N38) -> 13 | P38: =SUM(C38:N38) -> 18
B39: 14.15 - 14.30 | C39: 9 | D39: 2 | E39: 1 | F39: 2 | G39: 0 | H39: 0 | I39: 1 | J39: 0 | K39: 0 | L39: 0 | M39: 8 | N39: 0 | O39: =SUM(C39:L39,N39) -> 15 | P39: =SUM(C39:N39) -> 23
B40: 14.30 - 14.45 | C40: 3 | D40: 2 | E40: 0 | F40: 4 | G40: 0 | H40: 0 | I40: 2 | J40: 0 | K40: 0 | L40: 0 | M40: 5 | N40: 0 | O40: =SUM(C40:L40,N40) -> 11 | P40: =SUM(C40:N40) -> 16
... B57: 18.45 - 19.00 | C57: 6 | D57: 6 | E57: 1 | F57: 7 | G57: 0 | H57: 0 | I57: 3 | J57: 0 | K57: 0 | L57: 0 | M57: 16 | N57: 0 | O57: =SUM(C57:L57,N57) -> 23 | P57: =SUM(C57:N57) -> 39
B58: Totals | C58: =SUM(C10:C57) -> 163 | D58: =SUM(D10:D57) -> 81 | E58: =SUM(E10:E57) -> 23 | F58: =SUM(F10:F57) -> 152 | G58: =SUM(G10:G57) -> 1 | H58: =SUM(H10:H57) -> 0 | I58: =SUM(I10:I57) -> 87 | J58: =SUM(J10:J57) -> 16 | ... P58: =SUM(P10:P57) -> 931
...

Sheet 25.09 Entebbe-Busabala
B1: Consultancy services for Preparation of Expressway Development Master Plan (EDMP) for Uganda
B2: MANUAL CLASSIFIED COUNT (MCC)
B3: ROAD NAME: | C3: ='23.09.19 Entebbe-Busabala'!C3:G3 -> MCC - C2 - STN053 - Busabala RD
C5: Date | D5: 25.09.19 | F5: Location | G5: ='23.09.19 Entebbe-Busabala'!G5:H5 -> Ziranumbu town | J5: Surveyor | K5: ='23.09.19 Entebbe-Busabala'!K5:L5 -> Ssemuko S
C6: Dir. From | D6: ='23.09.19 Entebbe-Busabala'!D6:E6 -> ENTEBBE | F6: Dir. To | G6: ='23.09.19 Entebbe-Busabala'!G6:H6 -> BUSABALA | J6: Supervisor | K6: ='23.09.19 Entebbe-Busabala'!K6:L6 -> Steven
B8: Time / Veh Type | R8: SUMMARY TRAFFIC VOLUMES
C9: 1. Car | D9: 2. Station Wagon | E9: 3. Pickups | F9: 4. Minibus, matatu | G9: 5. Medium bus | H9: 6. Large Bus | I9: 7. Light Truck | J9: 8. Medium Truck | K9: 9. Heavy truck | L9: 10. Truck Trailer | M9: 11. Motor cycles | N9: 12. Tractors | O9: Total Excl M/Cycles | P9: Total All | R9: Time | S9: 1. Car | T9: 2. Station Wagon | U9: 3. Pickups | V9: 4. Minibus, matatu | W9: 5. Medium bus | X9: 6. Large Bus | Y9: 7. Light Truck | Z9: 8. Medium Truck | AA9: 9. Heavy truck | AB9: 10. Truck Trailer | AC9: 11. Motorcycles | AD9: 12. Tractors, Graders | AE9: Total Excl M/ Cycles | AF9: Total All
B10: 07.00 - 07.15 | C10: 13 | D10: 4 | E10: 1 | F10: 10 | G10: 0 | H10: 0 | I10: 1 | J10: 1 | K10: 0 | L10: 0 | M10: 33 | N10: 0 | O10: =SUM(C10:L10,N10) -> 30 | P10: =SUM(C10:N10) -> 63 | R10: 0700-0800 | S10: =SUM(C10:C13) -> 47 | T10: =SUM(D10:D13) -> 9 | U10: =SUM(E10:E13) -> 4 | V10: =SUM(F10:F13) -> 28 | W10: =SUM(G10:G13) -> 0 | X10: =SUM(H10:H13) -> 0 | Y10: =SUM(I10:I13) -> 12 | Z10: =SUM(J10:J13) -> 2 | ... AF10: =SUM(P10:P13) -> 212
B11: 07.15 - 07.30 | C11: 14 | D11: 2 | E11: 1 | F11: 4 | G11: 0 | H11: 0 | I11: 6 | J11: 0 | K11: 0 | L11: 0 | M11: 28 | N11: 0 | O11: =SUM(C11:L11,N11) -> 27 | P11: =SUM(C11:N11) -> 55 | R11: 0800-0900 | S11: =SUM(C14:C17) -> 21 | T11: =SUM(D14:D17) -> 3 | U11: =SUM(E14:E17) -> 0 | V11: =SUM(F14:F17) -> 18 | W11: =SUM(G14:G17) -> 0 | X11: =SUM(H14:H17) -> 0 | Y11: =SUM(I14:I17) -> 14 | Z11: =SUM(J14:J17) -> 3 | ... AF11: =SUM(P14:P17) -> 122
B12: 07.30 - 07.45 | C12: 12 | D12: 1 | E12: 1 | F12: 7 | G12: 0 | H12: 0 | I12: 1 | J12: 1 | K12: 0 | L12: 0 | M12: 27 | N12: 0 | O12: =SUM(C12:L12,N12) -> 23 | P12: =SUM(C12:N12) -> 50 | R12: 0900-1000 | S12: =SUM(C18:C21) -> 19 | T12: =SUM(D18:D21) -> 5 | U12: =SUM(E18:E21) -> 2 | V12: =SUM(F18:F21) -> 18 | W12: =SUM(G18:G21) -> 0 | X12: =SUM(H18:H21) -> 0 | Y12: =SUM(I18:I21) -> 8 | Z12: =SUM(J18:J21) -> 2 | ... AF12: =SUM(P18:P21) -> 109
B13: 07.45 - 08.00 | C13: 8 | D13: 2 | E13: 1 | F13: 7 | G13: 0 | H13: 0 | I13: 4 | J13: 0 | K13: 0 | L13: 0 | M13: 22 | N13: 0 | O13: =SUM(C13:L13,N13) -> 22 | P13: =SUM(C13:N13) -> 44 | R13: 1000-1100 | S13: =SUM(C22:C25) -> 23 | T13: =SUM(D22:D25) -> 4 | U13: =SUM(E22:E25) -> 2 | V13: =SUM(F22:F25) -> 17 | W13: =SUM(G22:G25) -> 0 | X13: =SUM(H22:H25) -> 0 | Y13: =SUM(I22:I25) -> 11 | Z13: =SUM(J22:J25) -> 3 | ... AF13: =SUM(P22:P25) -> 101
B14: 08.00 - 08.15 | C14: 5 | D14: 1 | E14: 0 | F14: 3 | G14: 0 | H14: 0 | I14: 5 | J14: 0 | K14: 1 | L14: 0 | M14: 15 | N14: 0 | O14: =SUM(C14:L14,N14) -> 15 | P14: =SUM(C14:N14) -> 30 | R14: 1100-1200 | S14: =SUM(C26:C29) -> 12 | T14: =SUM(D26:D29) -> 3 | U14: =SUM(E26:E29) -> 1 | V14: =SUM(F26:F29) -> 15 | W14: =SUM(G26:G29) -> 1 | X14: =SUM(H26:H29) -> 0 | Y14: =SUM(I26:I29) -> 8 | Z14: =SUM(J26:J29) -> 3 | ... AF14: =SUM(P26:P29) -> 109
B15: 08.15 - 08.30 | C15: 5 | D15: 0 | E15: 0 | F15: 2 | G15: 0 | H15: 0 | I15: 3 | J15: 0 | K15: 0 | L15: 0 | M15: 11 | N15: 0 | O15: =SUM(C15:L15,N15) -> 10 | P15: =SUM(C15:N15) -> 21 | R15: 1200-1300 | S15: =SUM(C30:C33) -> 12 | T15: =SUM(D30:D33) -> 1 | U15: =SUM(E30:E33) -> 2 | V15: =SUM(F30:F33) -> 15 | W15: =SUM(G30:G33) -> 0 | X15: =SUM(H30:H33) -> 0 | Y15: =SUM(I30:I33) -> 11 | Z15: =SUM(J30:J33) -> 3 | ... AF15: =SUM(P30:P33) -> 100
B16: 08.30 - 08.45 | C16: 4 | D16: 1 | E16: 0 | F16: 6 | G16: 0 | H16: 0 | I16: 3 | J16: 1 | K16: 0 | L16: 0 | M16: 8 | N16: 0 | O16: =SUM(C16:L16,N16) -> 15 | P16: =SUM(C16:N16) -> 23 | R16: 1300-1400 | S16: =SUM(C34:C37) -> 11 | T16: =SUM(D34:D37) -> 3 | U16: =SUM(E34:E37) -> 1 | V16: =SUM(F34:F37) -> 15 | W16: =SUM(G34:G37) -> 0 | X16: =SUM(H34:H37) -> 0 | Y16: =SUM(I34:I37) -> 11 | Z16: =SUM(J34:J37) -> 2 | ... AF16: =SUM(P34:P37) -> 105
B17: 08.45 - 9.00 | C17: 7 | D17: 1 | E17: 0 | F17: 7 | G17: 0 | H17: 0 | I17: 3 | J17: 2 | K17: 0 | L17: 0 | M17: 28 | N17: 0 | O17: =SUM(C17:L17,N17) -> 20 | P17: =SUM(C17:N17) -> 48 | R17: 1400-1500 | S17: =SUM(C38:C41) -> 16 | T17: =SUM(D38:D41) -> 2 | U17: =SUM(E38:E41) -> 1 | V17: =SUM(F38:F41) -> 21 | W17: =SUM(G38:G41) -> 0 | X17: =SUM(H38:H41) -> 0 | Y17: =SUM(I38:I41) -> 9 | Z17: =SUM(J38:J41) -> 0 | ... AF17: =SUM(P38:P41) -> 85
B18: 09.00 - 09.15 | C18: 4 | D18: 3 | E18: 1 | F18: 2 | G18: 0 | H18: 0 | I18: 3 | J18: 0 | K18: 0 | L18: 0 | M18: 21 | N18: 0 | O18: =SUM(C18:L18,N18) -> 13 | P18: =SUM(C18:N18) -> 34 | R18: 1500-1600 | S18: =SUM(C42:C45) -> 10 | T18: =SUM(D42:D45) -> 1 | U18: =SUM(E42:E45) -> 1 | V18: =SUM(F42:F45) -> 13 | W18: =SUM(G42:G45) -> 0 | X18: =SUM(H42:H45) -> 0 | Y18: =SUM(I42:I45) -> 9 | Z18: =SUM(J42:J45) -> 3 | ... AF18: =SUM(P42:P45) -> 74
B19: 09.15 - 09.30 | C19: 4 | D19: 1 | E19: 1 | F19: 6 | G19: 0 | H19: 0 | I19: 1 | J19: 1 | K19: 0 | L19: 0 | M19: 10 | N19: 0 | O19: =SUM(C19:L19,N19) -> 14 | P19: =SUM(C19:N19) -> 24 | R19: 1600-1700 | S19: =SUM(C46:C49) -> 8 | T19: =SUM(D46:D49) -> 4 | U19: =SUM(E46:E49) -> 1 | V19: =SUM(F46:F49) -> 26 | W19: =SUM(G46:G49) -> 0 | X19: =SUM(H46:H49) -> 0 | Y19: =SUM(I46:I49) -> 7 | Z19: =SUM(J46:J49) -> 1 | ... AF19: =SUM(P46:P49) -> 78
B20: 09.30 - 09.45 | C20: 6 | D20: 0 | E20: 0 | F20: 7 | G20: 0 | H20: 0 | I20: 2 | J20: 1 | K20: 0 | L20: 0 | M20: 5 | N20: 0 | O20: =SUM(C20:L20,N20) -> 16 | P20: =SUM(C20:N20) -> 21 | R20: 1700-1800 | S20: =SUM(C50:C53) -> 19 | T20: =SUM(D50:D53) -> 2 | U20: =SUM(E50:E53) -> 1 | V20: =SUM(F50:F53) -> 24 | W20: =SUM(G50:G53) -> 2 | X20: =SUM(H50:H53) -> 0 | Y20: =SUM(I50:I53) -> 8 | Z20: =SUM(J50:J53) -> 3 | ... AF20: =SUM(P50:P53) -> 112
B21: 09.45 - 10.00 | C21: 5 | D21: 1 | E21: 0 | F21: 3 | G21: 0 | H21: 0 | I21: 2 | J21: 0 | K21: 0 | L21: 0 | M21: 18 | N21: 1 | O21: =SUM(C21:L21,N21) -> 12 | P21: =SUM(C21:N21) -> 30 | R21: 1800-1900 | S21: =SUM(C54:C57) -> 16 | T21: =SUM(D54:D57) -> 3 | U21: =SUM(E54:E57) -> 6 | V21: =SUM(F54:F57) -> 35 | W21: =SUM(G54:G57) -> 4 | X21: =SUM(H54:H57) -> 0 | Y21: =SUM(I54:I57) -> 8 | Z21: =SUM(J54:J57) -> 4 | ... AF21: =SUM(P54:P57) -> 136
B22: 10.00 - 10.15 | C22: 8 | D22: 1 | E22: 0 | F22: 4 | G22: 0 | H22: 0 | I22: 0 | J22: 1 | K22: 0 | L22: 0 | M22: 13 | N22: 0 | O22: =SUM(C22:L22,N22) -> 14 | P22: =SUM(C22:N22) -> 27 | R22: AM Peak Hr | S22: =MAX(S10:S12) -> 47 | T22: =MAX(T10:T12) -> 9 | U22: =MAX(U10:U12) -> 4 | V22: =MAX(V10:V12) -> 28 | W22: =MAX(W10:W12) -> 0 | X22: =MAX(X10:X12) -> 0 | Y22: =MAX(Y10:Y12) -> 14 | Z22: =MAX(Z10:Z12) -> 3 | ... AF22: =MAX(AF10:AF12) -> 212
B23: 10.15 - 10.30 | C23: 3 | D23: 1 | E23: 0 | F23: 6 | G23: 0 | H23: 0 | I23: 2 | J23: 0 | K23: 0 | L23: 0 | M23: 5 | N23: 0 | O23: =SUM(C23:L23,N23) -> 12 | P23: =SUM(C23:N23) -> 17 | R23: IP Peak Hr | S23: =MAX(S13:S18) -> 23 | T23: =MAX(T13:T18) -> 4 | U23: =MAX(U13:U18) -> 2 | V23: =MAX(V13:V18) -> 21 | W23: =MAX(W13:W18) -> 1 | X23: =MAX(X13:X18) -> 0 | Y23: =MAX(Y13:Y18) -> 11 | Z23: =MAX(Z13:Z18) -> 3 | ... AF23: =MAX(AF13:AF18) -> 109
B24: 10.30 - 10.45 | C24: 9 | D24: 0 | E24: 1 | F24: 2 | G24: 0 | H24: 0 | I24: 7 | J24: 0 | K24: 0 | L24: 0 | M24: 17 | N24: 0 | O24: =SUM(C24:L24,N24) -> 19 | P24: =SUM(C24:N24) -> 36 | R24: PM Peak Hr | S24: =MAX(S19:S21) -> 19 | T24: =MAX(T19:T21) -> 4 | U24: =MAX(U19:U21) -> 6 | V24: =MAX(V19:V21) -> 35 | W24: =MAX(W19:W21) -> 4 | X24: =MAX(X19:X21) -> 0 | Y24: =MAX(Y19:Y21) -> 8 | Z24: =MAX(Z19:Z21) -> 4 | ... AF24: =MAX(AF19:AF21) -> 136
B25: 10.45 - 11.00 | C25: 3 | D25: 2 | E25: 1 | F25: 5 | G25: 0 | H25: 0 | I25: 2 | J25: 2 | K25: 0 | L25: 0 | M25: 6 | N25: 0 | O25: =SUM(C25:L25,N25) -> 15 | P25: =SUM(C25:N25) -> 21 | R25: AM Period | S25: =SUM(S10:S12) -> 87 | T25: =SUM(T10:T12) -> 17 | U25: =SUM(U10:U12) -> 6 | V25: =SUM(V10:V12) -> 64 | W25: =SUM(W10:W12) -> 0 | X25: =SUM(X10:X12) -> 0 | Y25: =SUM(Y10:Y12) -> 34 | Z25: =SUM(Z10:Z12) -> 7 | ... AF25: =SUM(AF10:AF12) -> 443
B26: 11.00 - 11.15 | C26: 3 | D26: 2 | E26: 0 | F26: 5 | G26: 0 | H26: 0 | I26: 4 | J26: 2 | K26: 0 | L26: 0 | M26: 16 | N26: 0 | O26: =SUM(C26:L26,N26) -> 16 | P26: =SUM(C26:N26) -> 32 | R26: IP Period | S26: =SUM(S13:S18) -> 84 | T26: =SUM(T13:T18) -> 14 | U26: =SUM(U13:U18) -> 8 | V26: =SUM(V13:V18) -> 96 | W26: =SUM(W13:W18) -> 1 | X26: =SUM(X13:X18) -> 0 | Y26: =SUM(Y13:Y18) -> 59 | Z26: =SUM(Z13:Z18) -> 14 | ... AF26: =SUM(AF13:AF18) -> 574
B27: 11.15 - 11.30 | C27: 3 | D27: 0 | E27: 1 | F27: 3 | G27: 0 | H27: 0 | I27: 1 | J27: 0 | K27: 0 | L27: 0 | M27: 10 | N27: 0 | O27: =SUM(C27:L27,N27) -> 8 | P27: =SUM(C27:N27) -> 18 | R27: PM Period | S27: =SUM(S19:S21) -> 43 | T27: =SUM(T19:T21) -> 9 | U27: =SUM(U19:U21) -> 8 | V27: =SUM(V19:V21) -> 85 | W27: =SUM(W19:W21) -> 6 | X27: =SUM(X19:X21) -> 0 | Y27: =SUM(Y19:Y21) -> 23 | Z27: =SUM(Z19:Z21) -> 8 | ... AF27: =SUM(AF19:AF21) -> 326
B28: 11.30 - 11.45 | C28: 3 | D28: 0 | E28: 0 | F28: 3 | G28: 0 | H28: 0 | I28: 1 | J28: 0 | K28: 0 | L28: 0 | M28: 27 | N28: 0 | O28: =SUM(C28:L28,N28) -> 7 | P28: =SUM(C28:N28) -> 34 | R28: 12 Hours | S28: =SUM(S10:S21) -> 214 | T28: =SUM(T10:T21) -> 40 | U28: =SUM(U10:U21) -> 22 | V28: =SUM(V10:V21) -> 245 | W28: =SUM(W10:W21) -> 7 | X28: =SUM(X10:X21) -> 0 | Y28: =SUM(Y10:Y21) -> 116 | Z28: =SUM(Z10:Z21) -> 29 | ... AF28: =SUM(AF10:AF21) -> 1343
B29: 11.45 - 12.00 | C29: 3 | D29: 1 | E29: 0 | F29: 4 | G29: 1 | H29: 0 | I29: 2 | J29: 1 | K29: 0 | L29: 0 | M29: 13 | N29: 0 | O29: =SUM(C29:L29,N29) -> 12 | P29: =SUM(C29:N29) -> 25
B30: 12.00 - 12.15 | C30: 3 | D30: 0 | E30: 0 | F30: 5 | G30: 0 | H30: 0 | I30: 3 | J30: 1 | K30: 0 | L30: 0 | M30: 13 | N30: 0 | O30: =SUM(C30:L30,N30) -> 12 | P30: =SUM(C30:N30) -> 25
B31: 12.15 - 12.30 | C31: 4 | D31: 0 | E31: 1 | F31: 2 | G31: 0 | H31: 0 | I31: 4 | J31: 1 | K31: 0 | L31: 0 | M31: 17 | N31: 0 | O31: =SUM(C31:L31,N31) -> 12 | P31: =SUM(C31:N31) -> 29
B32: 12.30 - 12.45 | C32: 2 | D32: 0 | E32: 1 | F32: 3 | G32: 0 | H32: 0 | I32: 3 | J32: 0 | K32: 0 | L32: 0 | M32: 18 | N32: 0 | O32: =SUM(C32:L32,N32) -> 9 | P32: =SUM(C32:N32) -> 27
B33: 12.45 - 13.00 | C33: 3 | D33: 1 | E33: 0 | F33: 5 | G33: 0 | H33: 0 | I33: 1 | J33: 1 | K33: 0 | L33: 0 | M33: 8 | N33: 0 | O33: =SUM(C33:L33,N33) -> 11 | P33: =SUM(C33:N33) -> 19
B34: 13.00 - 13.15 | C34: 4 | D34: 0 | E34: 0 | F34: 4 | G34: 0 | H34: 0 | I34: 4 | J34: 0 | K34: 0 | L34: 0 | M34: 22 | N34: 0 | O34: 22 | P34: =SUM(C34:N34) -> 34
