Workbook

Sheet 22.07 Kibuye-Makindye
B1: Consultancy services for Preparation of Expressway Development Master Plan (EDMP) for Uganda
B2: MANUAL CLASSIFIED COUNT (MCC)
B3: ROAD NAME: | C3: MCC - C1 - STN01 - MOBUTU ROAD
C5: Date | D5: 22.07.19 | F5: Location | G5: FUELEX MAKINDYE | J5: Surveyor | K5: WAKWESA ALLAN/CHEMONGES KENNETH/SSONKO SAMUEL/OWOMUGISHA BRENDA
C6: Dir. From | D6: KIBUYE | F6: Dir. To | G6: MAKINDYE | J6: Supervisor | K6: EMMA
B8: Time / Veh Type | R8: SUMMARY TRAFFIC VOLUMES
C9: 1. Car | D9: 2. Station Wagon | E9: 3. Pickups | F9: 4. Minibus, matatu | G9: 5. Medium bus | H9: 6. Large Bus | I9: 7. Light Truck | J9: 8. Medium Truck | K9: 9. Heavy truck | L9: 10. Truck Trailer | M9: 11. Motor cycles | N9: 12. Tractors | O9: Total Excl M/Cycles | P9: Total All | R9: Time | S9: 1. Car | T9: 2. Station Wagon | U9: 3. Pickups | V9: 4. Minibus, matatu | W9: 5. Medium bus | X9: 6. Large Bus | Y9: 7. Light Truck | Z9: 8. Medium Truck | AA9: 9. Heavy truck | AB9: 10. Truck Trailer | AC9: 11. Motorcycles | AD9: 12. Tractors, Graders | AE9: Total Excl M/ Cycles | AF9: Total All
B10: 07.00 - 07.15 | C10: 0 | D10: 0 | E10: 0 | F10: 0 | G10: 0 | H10: 0 | I10: 0 | J10: 0 | K10: 0 | L10: 0 | M10: 0 | N10: 0 | O10: =SUM(C10:L10,N10) -> 0 | P10: =SUM(C10:N10) -> 0 | R10: 0700-0800 | S10: =SUM(C10:C13) -> 57 | T10: =SUM(D10:D13) -> 10 | U10: =SUM(E10:E13) -> 11 | V10: =SUM(F10:F13) -> 52 | W10: =SUM(G10:G13) -> 0 | X10: =SUM(H10:H13) -> 0 | Y10: =SUM(I10:I13) -> 4 | Z10: =SUM(J10:J13) -> 3 | ... AF10: =SUM(P10:P13) -> 473
B11: 07.15 - 07.30 | C11: 0 | D11: 0 | E11: 0 | F11: 0 | G11: 0 | H11: 0 | I11: 0 | J11: 0 | K11: 0 | L11: 0 | M11: 0 | N11: 0 | O11: =SUM(C11:L11,N11) -> 0 | P11: =SUM(C11:N11) -> 0 | R11: 0800-0900 | S11: =SUM(C14:C17) -> 141 | T11: =SUM(D14:D17) -> 47 | U11: =SUM(E14:E17) -> 21 | V11: =SUM(F14:F17) -> 145 | W11: =SUM(G14:G17) -> 2 | X11: =SUM(H14:H17) -> 0 | Y11: =SUM(I14:I17) -> 8 | Z11: =SUM(J14:J17) -> 8 | ... AF11: =SUM(P14:P17) -> 1293
B12: 07.30 - 07.45 | C12: 22 | D12: 4 | E12: 3 | F12: 12 | G12: 0 | H12: 0 | I12: 3 | J12: 0 | K12: 0 | L12: 0 | M12: 185 | N12: 0 | O12: =SUM(C12:L12,N12) -> 44 | P12: =SUM(C12:N12) -> 229 | R12: 0900-1000 | S12: =SUM(C18:C21) -> 130 | T12: =SUM(D18:D21) -> 75 | U12: =SUM(E18:E21) -> 26 | V12: =SUM(F18:F21) -> 111 | W12: =SUM(G18:G21) -> 1 | X12: =SUM(H18:H21) -> 1 | Y12: =SUM(I18:I21) -> 8 | Z12: =SUM(J18:J21) -> 10 | ... AF12: =SUM(P18:P21) -> 1173
B13: 07.45 - 08.00 | C13: 35 | D13: 6 | E13: 8 | F13: 40 | G13: 0 | H13: 0 | I13: 1 | J13: 3 | K13: 0 | L13: 1 | M13: 150 | N13: 0 | O13: =SUM(C13:L13,N13) -> 94 | P13: =SUM(C13:N13) -> 244 | R13: 1000-1100 | S13: =SUM(C22:C25) -> 122 | T13: =SUM(D22:D25) -> 48 | U13: =SUM(E22:E25) -> 35 | V13: =SUM(F22:F25) -> 88 | W13: =SUM(G22:G25) -> 4 | X13: =SUM(H22:H25) -> 1 | Y13: =SUM(I22:I25) -> 12 | Z13: =SUM(J22:J25) -> 9 | ... AF13: =SUM(P22:P25) -> 893
B14: 08.00 - 08.15 | C14: 40 | D14: 7 | E14: 5 | F14: 39 | G14: 0 | H14: 0 | I14: 1 | J14: 1 | K14: 0 | L14: 0 | M14: 240 | N14: 0 | O14: =SUM(C14:L14,N14) -> 93 | P14: =SUM(C14:N14) -> 333 | R14: 1100-1200 | S14: =SUM(C26:C29) -> 157 | T14: =SUM(D26:D29) -> 67 | U14: =SUM(E26:E29) -> 27 | V14: =SUM(F26:F29) -> 101 | W14: =SUM(G26:G29) -> 0 | X14: =SUM(H26:H29) -> 0 | Y14: =SUM(I26:I29) -> 16 | Z14: =SUM(J26:J29) -> 14 | ... AF14: =SUM(P26:P29) -> 1011
B15: 08.15 - 08.30 | C15: 30 | D15: 11 | E15: 10 | F15: 33 | G15: 1 | H15: 0 | I15: 1 | J15: 2 | K15: 0 | L15: 0 | M15: 245 | N15: 0 | O15: =SUM(C15:L15,N15) -> 88 | P15: =SUM(C15:N15) -> 333 | R15: 1200-1300 | S15: =SUM(C30:C33) -> 123 | T15: =SUM(D30:D33) -> 73 | U15: =SUM(E30:E33) -> 20 | V15: =SUM(F30:F33) -> 97 | W15: =SUM(G30:G33) -> 0 | X15: =SUM(H30:H33) -> 0 | Y15: =SUM(I30:I33) -> 19 | Z15: =SUM(J30:J33) -> 14 | ... AF15: =SUM(P30:P33) -> 1066
B16: 08.30 - 08.45 | C16: 29 | D16: 14 | E16: 1 | F16: 38 | G16: 0 | H16: 0 | I16: 4 | J16: 2 | K16: 1 | L16: 0 | M16: 230 | N16: 0 | O16: =SUM(C16:L16,N16) -> 89 | P16: =SUM(C16:N16) -> 319 | R16: 1300-1400 | S16: =SUM(C34:C37) -> 160 | T16: =SUM(D34:D37) -> 73 | U16: =SUM(E34:E37) -> 32 | V16: =SUM(F34:F37) -> 92 | W16: =SUM(G34:G37) -> 0 | X16: =SUM(H34:H37) -> 0 | Y16: =SUM(I34:I37) -> 13 | Z16: =SUM(J34:J37) -> 8 | ... AF16: =SUM(P34:P37) -> 1082
B17: 08.45 - 9.00 | C17: 42 | D17: 15 | E17: 5 | F17: 35 | G17: 1 | H17: 0 | I17: 2 | J17: 3 | K17: 0 | L17: 0 | M17: 205 | N17: 0 | O17: =SUM(C17:L17,N17) -> 103 | P17: =SUM(C17:N17) -> 308 | R17: 1400-1500 | S17: =SUM(C38:C41) -> 162 | T17: =SUM(D38:D41) -> 68 | U17: =SUM(E38:E41) -> 27 | V17: =SUM(F38:F41) -> 83 | W17: =SUM(G38:G41) -> 0 | X17: =SUM(H38:H41) -> 0 | Y17: =SUM(I38:I41) -> 12 | Z17: =SUM(J38:J41) -> 10 | ... AF17: =SUM(P38:P41) -> 897
B18: 09.00 - 09.15 | C18: 37 | D18: 20 | E18: 8 | F18: 32 | G18: 1 | H18: 1 | I18: 2 | J18: 1 | K18: 0 | L18: 1 | M18: 250 | N18: 0 | O18: =SUM(C18:L18,N18) -> 103 | P18: =SUM(C18:N18) -> 353 | R18: 1500-1600 | S18: =SUM(C42:C45) -> 172 | T18: =SUM(D42:D45) -> 82 | U18: =SUM(E42:E45) -> 22 | V18: =SUM(F42:F45) -> 37 | W18: =SUM(G42:G45) -> 1 | X18: =SUM(H42:H45) -> 0 | Y18: =SUM(I42:I45) -> 16 | Z18: =SUM(J42:J45) -> 7 | ... AF18: =SUM(P42:P45) -> 700
B19: 09.15 - 09.30 | C19: 34 | D19: 15 | E19: 8 | F19: 29 | G19: 0 | H19: 0 | I19: 1 | J19: 3 | K19: 1 | L19: 0 | M19: 135 | N19: 0 | O19: =SUM(C19:L19,N19) -> 91 | P19: =SUM(C19:N19) -> 226 | R19: 1600-1700 | S19: =SUM(C46:C49) -> 267 | T19: =SUM(D46:D49) -> 101 | U19: =SUM(E46:E49) -> 29 | V19: =SUM(F46:F49) -> 72 | W19: =SUM(G46:G49) -> 0 | X19: =SUM(H46:H49) -> 0 | Y19: =SUM(I46:I49) -> 11 | Z19: =SUM(J46:J49) -> 8 | ... AF19: =SUM(P46:P49) -> 1013
B20: 09.30 - 09.45 | C20: 22 | D20: 25 | E20: 4 | F20: 27 | G20: 0 | H20: 0 | I20: 2 | J20: 3 | K20: 3 | L20: 0 | M20: 220 | N20: 0 | O20: =SUM(C20:L20,N20) -> 86 | P20: =SUM(C20:N20) -> 306 | R20: 1700-1800 | S20: =SUM(C50:C53) -> 241 | T20: =SUM(D50:D53) -> 79 | U20: =SUM(E50:E53) -> 32 | V20: =SUM(F50:F53) -> 54 | W20: =SUM(G50:G53) -> 4 | X20: =SUM(H50:H53) -> 2 | Y20: =SUM(I50:I53) -> 16 | Z20: =SUM(J50:J53) -> 10 | ... AF20: =SUM(P50:P53) -> 963
B21: 09.45 - 10.00 | C21: 37 | D21: 15 | E21: 6 | F21: 23 | G21: 0 | H21: 0 | I21: 3 | J21: 3 | K21: 1 | L21: 0 | M21: 200 | N21: 0 | O21: =SUM(C21:L21,N21) -> 88 | P21: =SUM(C21:N21) -> 288 | R21: 1800-1900 | S21: =SUM(C54:C57) -> 198 | T21: =SUM(D54:D57) -> 72 | U21: =SUM(E54:E57) -> 24 | V21: =SUM(F54:F57) -> 50 | W21: =SUM(G54:G57) -> 4 | X21: =SUM(H54:H57) -> 0 | Y21: =SUM(I54:I57) -> 11 | Z21: =SUM(J54:J57) -> 7 | ... AF21: =SUM(P54:P57) -> 922
B22: 10.00 - 10.15 | C22: 42 | D22: 18 | E22: 16 | F22: 22 | G22: 2 | H22: 0 | I22: 5 | J22: 2 | K22: 1 | L22: 0 | M22: 170 | N22: 0 | O22: =SUM(C22:L22,N22) -> 108 | P22: =SUM(C22:N22) -> 278 | R22: AM Peak Hr | S22: =MAX(S10:S12) -> 141 | T22: =MAX(T10:T12) -> 75 | U22: =MAX(U10:U12) -> 26 | V22: =MAX(V10:V12) -> 145 | W22: =MAX(W10:W12) -> 2 | X22: =MAX(X10:X12) -> 1 | Y22: =MAX(Y10:Y12) -> 8 | Z22: =MAX(Z10:Z12) -> 10 | ... AF22: =MAX(AF10:AF12) -> 1293
B23: 10.15 - 10.30 | C23: 28 | D23: 10 | E23: 2 | F23: 16 | G23: 1 | H23: 0 | I23: 1 | J23: 3 | K23: 0 | L23: 1 | M23: 140 | N23: 0 | O23: =SUM(C23:L23,N23) -> 62 | P23: =SUM(C23:N23) -> 202 | R23: IP Peak Hr | S23: =MAX(S13:S18) -> 172 | T23: =MAX(T13:T18) -> 82 | U23: =MAX(U13:U18) -> 35 | V23: =MAX(V13:V18) -> 101 | W23: =MAX(W13:W18) -> 4 | X23: =MAX(X13:X18) -> 1 | Y23: =MAX(Y13:Y18) -> 19 | Z23: =MAX(Z13:Z18) -> 14 | ... AF23: =MAX(AF13:AF18) -> 1082
B24: 10.30 - 10.45 | C24: 22 | D24: 7 | E24: 5 | F24: 24 | G24: 1 | H24: 1 | I24: 3 | J24: 2 | K24: 1 | L24: 0 | M24: 110 | N24: 0 | O24: =SUM(C24:L24,N24) -> 66 | P24: =SUM(C24:N24) -> 176 | R24: PM Peak Hr | S24: =MAX(S19:S21) -> 267 | T24: =MAX(T19:T21) -> 101 | U24: =MAX(U19:U21) -> 32 | V24: =MAX(V19:V21) -> 72 | W24: =MAX(W19:W21) -> 4 | X24: =MAX(X19:X21) -> 2 | Y24: =MAX(Y19:Y21) -> 16 | Z24: =MAX(Z19:Z21) -> 10 | ... AF24: =MAX(AF19:AF21) -> 1013
B25: 10.45 - 11.00 | C25: 30 | D25: 13 | E25: 12 | F25: 26 | G25: 0 | H25: 0 | I25: 3 | J25: 2 | K25: 1 | L25: 0 | M25: 150 | N25: 0 | O25: =SUM(C25:L25,N25) -> 87 | P25: =SUM(C25:N25) -> 237 | R25: AM Period | S25: =SUM(S10:S12) -> 328 | T25: =SUM(T10:T12) -> 132 | U25: =SUM(U10:U12) -> 58 | V25: =SUM(V10:V12) -> 308 | W25: =SUM(W10:W12) -> 3 | X25: =SUM(X10:X12) -> 1 | Y25: =SUM(Y10:Y12) -> 20 | Z25: =SUM(Z10:Z12) -> 21 | ... AF25: =SUM(AF10:AF12) -> 2939
B26: 11.00 - 11.15 | C26: 42 | D26: 11 | E26: 7 | F26: 30 | G26: 0 | H26: 0 | I26: 3 | J26: 3 | K26: 4 | L26: 0 | M26: 150 | N26: 0 | O26: =SUM(C26:L26,N26) -> 100 | P26: =SUM(C26:N26) -> 250 | R26: IP Period | S26: =SUM(S13:S18) -> 896 | T26: =SUM(T13:T18) -> 411 | U26: =SUM(U13:U18) -> 163 | V26: =SUM(V13:V18) -> 498 | W26: =SUM(W13:W18) -> 5 | X26: =SUM(X13:X18) -> 1 | Y26: =SUM(Y13:Y18) -> 88 | Z26: =SUM(Z13:Z18) -> 62 | ... AF26: =SUM(AF13:AF18) -> 5649
B27: 11.15 - 11.30 | C27: 39 | D27: 26 | E27: 7 | F27: 25 | G27: 0 | H27: 0 | I27: 9 | J27: 4 | K27: 1 | L27: 0 | M27: 175 | N27: 0 | O27: =SUM(C27:L27,N27) -> 111 | P27: =SUM(C27:N27) -> 286 | R27: PM Period | S27: =SUM(S19:S21) -> 706 | T27: =SUM(T19:T21) -> 252 | U27: =SUM(U19:U21) -> 85 | V27: =SUM(V19:V21) -> 176 | W27: =SUM(W19:W21) -> 8 | X27: =SUM(X19:X21) -> 2 | Y27: =SUM(Y19:Y21) -> 38 | Z27: =SUM(Z19:Z21) -> 25 | ... AF27: =SUM(AF19:AF21) -> 2898
B28: 11.30 - 11.45 | C28: 32 | D28: 17 | E28: 8 | F28: 25 | G28: 0 | H28: 0 | I28: 2 | J28: 3 | K28: 2 | L28: 0 | M28: 185 | N28: 0 | O28: =SUM(C28:L28,N28) -> 89 | P28: =SUM(C28:N28) -> 274 | R28: 12 Hours | S28: =SUM(S10:S21) -> 1930 | T28: =SUM(T10:T21) -> 795 | U28: =SUM(U10:U21) -> 306 | V28: =SUM(V10:V21) -> 982 | W28: =SUM(W10:W21) -> 16 | X28: =SUM(X10:X21) -> 4 | Y28: =SUM(Y10:Y21) -> 146 | Z28: =SUM(Z10:Z21) -> 108 | ... AF28: =SUM(AF10:AF21) -> 11486
B29: 11.45 - 12.00 | C29: 44 | D29: 13 | E29: 5 | F29: 21 | G29: 0 | H29: 0 | I29: 2 | J29: 4 | K29: 2 | L29: 0 | M29: 110 | N29: 0 | O29: =SUM(C29:L29,N29) -> 91 | P29: =SUM(C29:N29) -> 201
B30: 12.00 - 12.15 | C30: 35 | D30: 20 | E30: 4 | F30: 41 | G30: 0 | H30: 0 | I30: 6 | J30: 2 | K30: 2 | L30: 0 | M30: 205 | N30: 0 | O30: =SUM(C30:L30,N30) -> 110 | P30: =SUM(C30:N30) -> 315
B31: 12.15 - 12.30 | C31: 33 | D31: 17 | E31: 5 | F31: 28 | G31: 0 | H31: 0 | I31: 3 | J31: 5 | K31: 1 | L31: 1 | M31: 165 | N31: 0 | O31: =SUM(C31:L31,N31) -> 93 | P31: =SUM(C31:N31) -> 258
B32: 12.30 - 12.45 | C32: 30 | D32: 24 | E32: 8 | F32: 15 | G32: 0 | H32: 0 | I32: 5 | J32: 2 | K32: 1 | L32: 0 | M32: 185 | N32: 0 | O32: =SUM(C32:L32,N32) -> 85 | P32: =SUM(C32:N32) -> 270
B33: 12.45 - 13.00 | C33: 25 | D33: 12 | E33: 3 | F33: 13 | G33: 0 | H33: 0 | I33: 5 | J33: 5 | K33: 0 | L33: 0 | M33: 160 | N33: 0 | O33: =SUM(C33:L33,N33) -> 63 | P33: =SUM(C33:N33) -> 223
B34: 13.00 - 13.15 | C34: 25 | D34: 19 | E34: 7 | F34: 24 | G34: 0 | H34: 0 | I34: 0 | J34: 2 | K34: 1 | L34: 0 | M34: 210 | N34: 0 | O34: =SUM(C34:L34,N34) -> 78 | P34: =SUM(C34:N34) -> 288
B35: 13.15 - 13.30 | C35: 47 | D35: 19 | E35: 10 | F35: 19 | G35: 0 | H35: 0 | I35: 5 | J35: 3 | K35: 1 | L35: 0 | M35: 175 | N35: 0 | O35: =SUM(C35:L35,N35) -> 104 | P35: =SUM(C35:N35) -> 279
B36: 13.30 - 13.45 | C36: 45 | D36: 26 | E36: 10 | F36: 27 | G36: 0 | H36: 0 | I36: 6 | J36: 1 | K36: 0 | L36: 0 | M36: 165 | N36: 0 | O36: =SUM(C36:L36,N36) -> 115 | P36: =SUM(C36:N36) -> 280
B37: 13.45 - 14.00 | C37: 43 | D37: 9 | E37: 5 | F37: 22 | G37: 0 | H37: 0 | I37: 2 | J37: 2 | K37: 2 | L37: 0 | M37: 150 | N37: 0 | O37: =SUM(C37:L37,N37) -> 85 | P37: =SUM(C37:N37) -> 235
B38: 14.00 - 14.15 | C38: 37 | D38: 20 | E38: 8 | F38: 19 | G38: 0 | H38: 0 | I38: 4 | J38: 5 | K38: 0 | L38: 1 | M38: 145 | N38: 0 | O38: =SUM(C38:L38,N38) -> 94 | P38: =SUM(C38:N38) -> 239
B39: 14.15 - 14.30 | C39: 44 | D39: 19 | E39: 6 | F39: 26 | G39: 0 | H39: 0 | I39: 4 | J39: 4 | K39: 1 | L39: 0 | M39: 135 | N39: 0 | O39: =SUM(C39:L39,N39) -> 104 | P39: =SUM(C39:N39) -> 239
B40: 14.30 - 14.45 | C40: 48 | D40: 17 | E40: 9 | F40: 24 | G40: 0 | H40: 0 | I40: 2 | J40: 0 | K40: 0 | L40: 0 | M40: 120 | N40: 0 | O40: =SUM(C40:L40,N40) -> 100 | P40: =SUM(C40:N40) -> 220
... B57: 18.45 - 19.00 | C57: 40 | D57: 16 | E57: 6 | F57: 17 | G57: 1 | H57: 0 | I57: 1 | J57: 0 | K57: 0 | L57: 0 | M57: 130 | N57: 0 | O57: =SUM(C57:L57,N57) -> 81 | P57: =SUM(C57:N57) -> 211
B58: Totals | C58: =SUM(C10:C57) -> 1930 | D58: =SUM(D10:D57) -> 795 | E58: =SUM(E10:E57) -> 306 | F58: =SUM(F10:F57) -> 982 | G58: =SUM(G10:G57) -> 16 | H58: =SUM(H10:H57) -> 4 | I58: =SUM(I10:I57) -> 146 | J58: =SUM(J10:J57) -> 108 | ... P58: =SUM(P10:P57) -> 11486
...

Sheet 22.07 Makindye-Kibuye
B1: Consultancy services for Preparation of Expressway Development Master Plan (EDMP) for Uganda
B2: MANUAL CLASSIFIED COUNT (MCC)
B3: ROAD NAME: | C3: ='22.07 Kibuye-Makindye'!C3:G3 -> MCC - C1 - STN01 - MOBUTU ROAD
C5: Date | D5: ='22.07 Kibuye-Makindye'!D5 -> 22.07.19 | F5: Location | G5: ='22.07 Kibuye-Makindye'!G5:H5 -> FUELEX MAKINDYE | J5: Surveyor | K5: ='22.07 Kibuye-Makindye'!K5:L5 -> WAKWESA ALLAN/CHEMONGES KENNETH/SSONKO SAMUEL/OWOMUGISHA BRENDA
C6: Dir. From | D6: MAKINDYE | F6: Dir. To | G6: KIBUYE | J6: Supervisor | K6: ='22.07 Kibuye-Makindye'!K6:L6 -> EMMA
B8: Time / Veh Type | R8: SUMMARY TRAFFIC VOLUMES
C9: 1. Car | D9: 2. Station Wagon | E9: 3. Pickups | F9: 4. Minibus, matatu | G9: 5. Medium bus | H9: 6. Large Bus | I9: 7. Light Truck | J9: 8. Medium Truck | K9: 9. Heavy truck | L9: 10. Truck Trailer | M9: 11. Motor cycles | N9: 12. Tractors | O9: Total Excl M/Cycles | P9: Total All | R9: Time | S9: 1. Car | T9: 2. Station Wagon | U9: 3. Pickups | V9: 4. Minibus, matatu | W9: 5. Medium bus | X9: 6. Large Bus | Y9: 7. Light Truck | Z9: 8. Medium Truck | AA9: 9. Heavy truck | AB9: 10. Truck Trailer | AC9: 11. Motorcycles | AD9: 12. Tractors, Graders | AE9: Total Excl M/ Cycles | AF9: Total All
B10: 07.00 - 07.15 | C10: 35 | D10: 3 | E10: 3 | F10: 2 | G10: 0 | H10: 0 | I10: 0 | J10: 0 | K10: 0 | L10: 0 | M10: 120 | N10: 0 | O10: =SUM(C10:L10,N10) -> 43 | P10: =SUM(C10:N10) -> 163 | R10: 0700-0800 | S10: =SUM(C10:C13) -> 140 | T10: =SUM(D10:D13) -> 13 | U10: =SUM(E10:E13) -> 6 | V10: =SUM(F10:F13) -> 3 | W10: =SUM(G10:G13) -> 0 | X10: =SUM(H10:H13) -> 0 | Y10: =SUM(I10:I13) -> 4 | Z10: =SUM(J10:J13) -> 2 | ... AF10: =SUM(P10:P13) -> 738
B11: 07.15 - 07.30 | C11: 45 | D11: 2 | E11: 1 | F11: 0 | G11: 0 | H11: 0 | I11: 0 | J11: 0 | K11: 0 | L11: 0 | M11: 125 | N11: 0 | O11: =SUM(C11:L11,N11) -> 48 | P11: =SUM(C11:N11) -> 173 | R11: 0800-0900 | S11: =SUM(C14:C17) -> 233 | T11: =SUM(D14:D17) -> 23 | U11: =SUM(E14:E17) -> 24 | V11: =SUM(F14:F17) -> 18 | W11: =SUM(G14:G17) -> 0 | X11: =SUM(H14:H17) -> 0 | Y11: =SUM(I14:I17) -> 8 | Z11: =SUM(J14:J17) -> 6 | ... AF11: =SUM(P14:P17) -> 984
B12: 07.30 - 07.45 | C12: 16 | D12: 2 | E12: 0 | F12: 1 | G12: 0 | H12: 0 | I12: 1 | J12: 2 | K12: 0 | L12: 0 | M12: 150 | N12: 0 | O12: =SUM(C12:L12,N12) -> 22 | P12: =SUM(C12:N12) -> 172 | R12: 0900-1000 | S12: =SUM(C18:C21) -> 217 | T12: =SUM(D18:D21) -> 33 | U12: =SUM(E18:E21) -> 21 | V12: =SUM(F18:F21) -> 106 | W12: =SUM(G18:G21) -> 0 | X12: =SUM(H18:H21) -> 0 | Y12: =SUM(I18:I21) -> 11 | Z12: =SUM(J18:J21) -> 9 | ... AF12: =SUM(P18:P21) -> 988
B13: 07.45 - 08.00 | C13: 44 | D13: 6 | E13: 2 | F13: 0 | G13: 0 | H13: 0 | I13: 3 | J13: 0 | K13: 0 | L13: 0 | M13: 175 | N13: 0 | O13: =SUM(C13:L13,N13) -> 55 | P13: =SUM(C13:N13) -> 230 | R13: 1000-1100 | S13: =SUM(C22:C25) -> 174 | T13: =SUM(D22:D25) -> 21 | U13: =SUM(E22:E25) -> 28 | V13: =SUM(F22:F25) -> 156 | W13: =SUM(G22:G25) -> 2 | X13: =SUM(H22:H25) -> 0 | Y13: =SUM(I22:I25) -> 6 | Z13: =SUM(J22:J25) -> 9 | ... AF13: =SUM(P22:P25) -> 1256
B14: 08.00 - 08.15 | C14: 36 | D14: 2 | E14: 6 | F14: 3 | G14: 0 | H14: 0 | I14: 2 | J14: 0 | K14: 0 | L14: 0 | M14: 65 | N14: 0 | O14: =SUM(C14:L14,N14) -> 49 | P14: =SUM(C14:N14) -> 114 | R14: 1100-1200 | S14: =SUM(C26:C29) -> 178 | T14: =SUM(D26:D29) -> 16 | U14: =SUM(E26:E29) -> 25 | V14: =SUM(F26:F29) -> 170 | W14: =SUM(G26:G29) -> 1 | X14: =SUM(H26:H29) -> 0 | Y14: =SUM(I26:I29) -> 10 | Z14: =SUM(J26:J29) -> 1 | ... AF14: =SUM(P26:P29) -> 1209
B15: 08.15 - 08.30 | C15: 61 | D15: 5 | E15: 5 | F15: 2 | G15: 0 | H15: 0 | I15: 1 | J15: 2 | K15: 1 | L15: 0 | M15: 210 | N15: 0 | O15: =SUM(C15:L15,N15) -> 77 | P15: =SUM(C15:N15) -> 287 | R15: 1200-1300 | S15: =SUM(C30:C33) -> 140 | T15: =SUM(D30:D33) -> 17 | U15: =SUM(E30:E33) -> 12 | V15: =SUM(F30:F33) -> 206 | W15: =SUM(G30:G33) -> 0 | X15: =SUM(H30:H33) -> 0 | Y15: =SUM(I30:I33) -> 6 | Z15: =SUM(J30:J33) -> 4 | ... AF15: =SUM(P30:P33) -> 1135
B16: 08.30 - 08.45 | C16: 71 | D16: 5 | E16: 7 | F16: 6 | G16: 0 | H16: 0 | I16: 3 | J16: 3 | K16: 0 | L16: 0 | M16: 210 | N16: 0 | O16: =SUM(C16:L16,N16) -> 95 | P16: =SUM(C16:N16) -> 305 | R16: 1300-1400 | S16: =SUM(C34:C37) -> 161 | T16: =SUM(D34:D37) -> 11 | U16: =SUM(E34:E37) -> 23 | V16: =SUM(F34:F37) -> 159 | W16: =SUM(G34:G37) -> 0 | X16: =SUM(H34:H37) -> 0 | Y16: =SUM(I34:I37) -> 16 | Z16: =SUM(J34:J37) -> 8 | ... AF16: =SUM(P34:P37) -> 1080
B17: 08.45 - 9.00 | C17: 65 | D17: 11 | E17: 6 | F17: 7 | G17: 0 | H17: 0 | I17: 2 | J17: 1 | K17: 1 | L17: 0 | M17: 185 | N17: 0 | O17: =SUM(C17:L17,N17) -> 93 | P17: =SUM(C17:N17) -> 278 | R17: 1400-1500 | S17: =SUM(C38:C41) -> 160 | T17: =SUM(D38:D41) -> 20 | U17: =SUM(E38:E41) -> 13 | V17: =SUM(F38:F41) -> 137 | W17: =SUM(G38:G41) -> 3 | X17: =SUM(H38:H41) -> 0 | Y17: =SUM(I38:I41) -> 11 | Z17: =SUM(J38:J41) -> 5 | ... AF17: =SUM(P38:P41) -> 895
B18: 09.00 - 09.15 | C18: 52 | D18: 4 | E18: 5 | F18: 19 | G18: 0 | H18: 0 | I18: 2 | J18: 0 | K18: 0 | L18: 0 | M18: 140 | N18: 0 | O18: =SUM(C18:L18,N18) -> 82 | P18: =SUM(C18:N18) -> 222 | R18: 1500-1600 | S18: =SUM(C42:C45) -> 172 | T18: =SUM(D42:D45) -> 18 | U18: =SUM(E42:E45) -> 15 | V18: =SUM(F42:F45) -> 103 | W18: =SUM(G42:G45) -> 1 | X18: =SUM(H42:H45) -> 0 | Y18: =SUM(I42:I45) -> 4 | Z18: =SUM(J42:J45) -> 12 | ... AF18: =SUM(P42:P45) -> 643
B19: 09.15 - 09.30 | C19: 72 | D19: 10 | E19: 9 | F19: 24 | G19: 0 | H19: 0 | I19: 3 | J19: 3 | K19: 0 | L19: 0 | M19: 135 | N19: 0 | O19: =SUM(C19:L19,N19) -> 121 | P19: =SUM(C19:N19) -> 256 | R19: 1600-1700 | S19: =SUM(C46:C49) -> 236 | T19: =SUM(D46:D49) -> 29 | U19: =SUM(E46:E49) -> 33 | V19: =SUM(F46:F49) -> 87 | W19: =SUM(G46:G49) -> 1 | X19: =SUM(H46:H49) -> 0 | Y19: =SUM(I46:I49) -> 10 | Z19: =SUM(J46:J49) -> 9 | ... AF19: =SUM(P46:P49) -> 1085
B20: 09.30 - 09.45 | C20: 46 | D20: 9 | E20: 6 | F20: 28 | G20: 0 | H20: 0 | I20: 3 | J20: 6 | K20: 0 | L20: 0 | M20: 105 | N20: 0 | O20: =SUM(C20:L20,N20) -> 98 | P20: =SUM(C20:N20) -> 203 | R20: 1700-1800 | S20: =SUM(C50:C53) -> 160 | T20: =SUM(D50:D53) -> 13 | U20: =SUM(E50:E53) -> 8 | V20: =SUM(F50:F53) -> 70 | W20: =SUM(G50:G53) -> 0 | X20: =SUM(H50:H53) -> 0 | Y20: =SUM(I50:I53) -> 6 | Z20: =SUM(J50:J53) -> 11 | ... AF20: =SUM(P50:P53) -> 606
B21: 09.45 - 10.00 | C21: 47 | D21: 10 | E21: 1 | F21: 35 | G21: 0 | H21: 0 | I21: 3 | J21: 0 | K21: 1 | L21: 0 | M21: 210 | N21: 0 | O21: =SUM(C21:L21,N21) -> 97 | P21: =SUM(C21:N21) -> 307 | R21: 1800-1900 | S21: =SUM(C54:C57) -> 111 | T21: =SUM(D54:D57) -> 7 | U21: =SUM(E54:E57) -> 8 | V21: =SUM(F54:F57) -> 119 | W21: =SUM(G54:G57) -> 2 | X21: =SUM(H54:H57) -> 0 | Y21: =SUM(I54:I57) -> 6 | Z21: =SUM(J54:J57) -> 2 | ... AF21: =SUM(P54:P57) -> 648
B22: 10.00 - 10.15 | C22: 38 | D22: 4 | E22: 9 | F22: 30 | G22: 0 | H22: 0 | I22: 2 | J22: 0 | K22: 0 | L22: 0 | M22: 235 | N22: 0 | O22: =SUM(C22:L22,N22) -> 83 | P22: =SUM(C22:N22) -> 318 | R22: AM Peak Hr | S22: =MAX(S10:S12) -> 233 | T22: =MAX(T10:T12) -> 33 | U22: =MAX(U10:U12) -> 24 | V22: =MAX(V10:V12) -> 106 | W22: =MAX(W10:W12) -> 0 | X22: =MAX(X10:X12) -> 0 | Y22: =MAX(Y10:Y12) -> 11 | Z22: =MAX(Z10:Z12) -> 9 | ... AF22: =MAX(AF10:AF12) -> 988
B23: 10.15 - 10.30 | C23: 61 | D23: 10 | E23: 9 | F23: 57 | G23: 0 | H23: 0 | I23: 0 | J23: 3 | K23: 0 | L23: 0 | M23: 205 | N23: 0 | O23: =SUM(C23:L23,N23) -> 140 | P23: =SUM(C23:N23) -> 345 | R23: IP Peak Hr | S23: =MAX(S13:S18) -> 178 | T23: =MAX(T13:T18) -> 21 | U23: =MAX(U13:U18) -> 28 | V23: =MAX(V13:V18) -> 206 | W23: =MAX(W13:W18) -> 3 | X23: =MAX(X13:X18) -> 0 | Y23: =MAX(Y13:Y18) -> 16 | Z23: =MAX(Z13:Z18) -> 12 | ... AF23: =MAX(AF13:AF18) -> 1256
B24: 10.30 - 10.45 | C24: 35 | D24: 3 | E24: 5 | F24: 47 | G24: 1 | H24: 0 | I24: 0 | J24: 2 | K24: 0 | L24: 0 | M24: 210 | N24: 0 | O24: =SUM(C24:L24,N24) -> 93 | P24: =SUM(C24:N24) -> 303 | R24: PM Peak Hr | S24: =MAX(S19:S21) -> 236 | T24: =MAX(T19:T21) -> 29 | U24: =MAX(U19:U21) -> 33 | V24: =MAX(V19:V21) -> 119 | W24: =MAX(W19:W21) -> 2 | X24: =MAX(X19:X21) -> 0 | Y24: =MAX(Y19:Y21) -> 10 | Z24: =MAX(Z19:Z21) -> 11 | ... AF24: =MAX(AF19:AF21) -> 1085
B25: 10.45 - 11.00 | C25: 40 | D25: 4 | E25: 5 | F25: 22 | G25: 1 | H25: 0 | I25: 4 | J25: 4 | K25: 0 | L25: 0 | M25: 210 | N25: 0 | O25: =SUM(C25:L25,N25) -> 80 | P25: =SUM(C25:N25) -> 290 | R25: AM Period | S25: =SUM(S10:S12) -> 590 | T25: =SUM(T10:T12) -> 69 | U25: =SUM(U10:U12) -> 51 | V25: =SUM(V10:V12) -> 127 | W25: =SUM(W10:W12) -> 0 | X25: =SUM(X10:X12) -> 0 | Y25: =SUM(Y10:Y12) -> 23 | Z25: =SUM(Z10:Z12) -> 17 | ... AF25: =SUM(AF10:AF12) -> 2710
B26: 11.00 - 11.15 | C26: 50 | D26: 4 | E26: 7 | F26: 36 | G26: 0 | H26: 0 | I26: 3 | J26: 1 | K26: 0 | L26: 0 | M26: 195 | N26: 0 | O26: =SUM(C26:L26,N26) -> 101 | P26: =SUM(C26:N26) -> 296 | R26: IP Period | S26: =SUM(S13:S18) -> 985 | T26: =SUM(T13:T18) -> 103 | U26: =SUM(U13:U18) -> 116 | V26: =SUM(V13:V18) -> 931 | W26: =SUM(W13:W18) -> 7 | X26: =SUM(X13:X18) -> 0 | Y26: =SUM(Y13:Y18) -> 53 | Z26: =SUM(Z13:Z18) -> 39 | ... AF26: =SUM(AF13:AF18) -> 6218
B27: 11.15 - 11.30 | C27: 51 | D27: 3 | E27: 8 | F27: 45 | G27: 0 | H27: 0 | I27: 2 | J27: 0 | K27: 0 | L27: 1 | M27: 205 | N27: 0 | O27: =SUM(C27:L27,N27) -> 110 | P27: =SUM(C27:N27) -> 315 | R27: PM Period | S27: =SUM(S19:S21) -> 507 | T27: =SUM(T19:T21) -> 49 | U27: =SUM(U19:U21) -> 49 | V27: =SUM(V19:V21) -> 276 | W27: =SUM(W19:W21) -> 3 | X27: =SUM(X19:X21) -> 0 | Y27: =SUM(Y19:Y21) -> 22 | Z27: =SUM(Z19:Z21) -> 22 | ... AF27: =SUM(AF19:AF21) -> 2339
B28: 11.30 - 11.45 | C28: 51 | D28: 4 | E28: 6 | F28: 40 | G28: 1 | H28: 0 | I28: 2 | J28: 0 | K28: 1 | L28: 0 | M28: 210 | N28: 0 | O28: =SUM(C28:L28,N28) -> 105 | P28: =SUM(C28:N28) -> 315 | R28: 12 Hours | S28: =SUM(S10:S21) -> 2082 | T28: =SUM(T10:T21) -> 221 | U28: =SUM(U10:U21) -> 216 | V28: =SUM(V10:V21) -> 1334 | W28: =SUM(W10:W21) -> 10 | X28: =SUM(X10:X21) -> 0 | Y28: =SUM(Y10:Y21) -> 98 | Z28: =SUM(Z10:Z21) -> 78 | ... AF28: =SUM(AF10:AF21) -> 11267
B29: 11.45 - 12.00 | C29: 26 | D29: 5 | E29: 4 | F29: 49 | G29: 0 | H29: 0 | I29: 3 | J29: 0 | K29: 1 | L29: 0 | M29: 195 | N29: 0 | O29: =SUM(C29:L29,N29) -> 88 | P29: =SUM(C29:N29) -> 283
B30: 12.00 - 12.15 | C30: 36 | D30: 4 | E30: 3 | F30: 49 | G30: 0 | H30: 0 | I30: 2 | J30: 2 | K30: 0 | L30: 0 | M30: 210 | N30: 0 | O30: =SUM(C30:L30,N30) -> 96 | P30: =SUM(C30:N30) -> 306
B31: 12.15 - 12.30 | C31: 39 | D31: 5 | E31: 4 | F31: 47 | G31: 0 | H31: 0 | I31: 2 | J31: 0 | K31: 0 | L31: 0 | M31: 210 | N31: 0 | O31: =SUM(C31:L31,N31) -> 97 | P31: =SUM(C31:N31) -> 307
B32: 12.30 - 12.45 | C32: 30 | D32: 4 | E32: 3 | F32: 49 | G32: 0 | H32: 0 | I32: 1 | J32: 1 | K32: 0 | L32: 0 | M32: 210 | N32: 0 | O32: =SUM(C32:L32,N32) -> 88 | P32: =SUM(C32:N32) -> 298
B33: 12.45 - 13.00 | C33: 35 | D33: 4 | E33: 2 | F33: 61 | G33: 0 | H33: 0 | I33: 1 | J33: 1 | K33: 0 | L33: 0 | M33: 120 | N33: 0 | O33: =SUM(C33:L33,N33) -> 104 | P33: =SUM(C33:N33) -> 224
B34: 13.00 - 13.15 | C34: 46 | D34: 3 | E34: 5 | F34: 55 | G34: 0 | H34: 0 | I34: 4 | J34: 1 | K34: 0 | L34: 0 | M34: 210 | N34: 0 | O34: =SUM(C34:L34,N34) -> 114 | P34: =SUM(C34:N34) -> 324
B35: 13.15 - 13.30 | C35: 39 | D35: 3 | E35: 6 | F35: 26 | G35: 0 | H35: 0 | I35: 3 | J35: 4 | K35: 0 | L35: 0 | M35: 120 | N35: 0 | O35: =SUM(C35:L35,N35) -> 81 | P35: =SUM(C35:N35) -> 201
B36: 13.30 - 13.45 | C36: 39 | D36: 2 | E36: 3 | F36: 56 | G36: 0 | H36: 0 | I36: 2 | J36: 2 | K36: 0 | L36: 0 | M36: 210 | N36: 0 | O36: =SUM(C36:L36,N36) -> 104 | P36: =SUM(C36:N36) -> 314
B37: 13.45 - 14.00 | C37: 37 | D37: 3 | E37: 9 | F37: 22 | G37: 0 | H37: 0 | I37: 7 | J37: 1 | K37: 0 | L37: 1 | M37: 160 | N37: 1 | O37: =SUM(C37:L37,N37) -> 81 | P37: =SUM(C37:N37) -> 241
B38: 14.00 - 14.15 | C38: 45 | D38: 4 | E38: 2 | F38: 34 | G38: 0 | H38: 0 | I38: 6 | J38: 3 | K38: 0 | L38: 0 | M38: 140 | N38: 0 | O38: =SUM(C38:L38,N38) -> 94 | P38: =SUM(C38:N38) -> 234
B39: 14.15 - 14.30 | C39: 36 | D39: 10 | E39: 8 | F39: 45 | G39: 1 | H39: 0 | I39: 1 | J39: 1 | K39: 1 | L39: 0 | M39: 105 | N39: 0 | O39: =SUM(C39:L39,N39) -> 103 | P39: =SUM(C39:N39) -> 208
B40: 14.30 - 14.45 | C40: 66 | D40: 4 | E40: 2 | F40: 48 | G40: 2 | H40: 0 | I40: 3 | J40: 0 | K40: 0 | L40: 0 | M40: 210 | N40: 0 | O40: =SUM(C40:L40,N40) -> 125 | P40: =SUM(C40:N40) -> 335
... B57: 18.45 - 19.00 | C57: 30 | D57: 2 | E57: 3 | F57: 27 | G57: 0 | H57: 0 | I57: 2 | J57: 1 | K57: 0 | L57: 0 | M57: 120 | N57: 0 | O57: =SUM(C57:L57,N57) -> 65 | P57: =SUM(C57:N57) -> 185
B58: Totals | C58: =SUM(C10:C57) -> 2082 | D58: =SUM(D10:D57) -> 221 | E58: =SUM(E10:E57) -> 216 | F58: =SUM(F10:F57) -> 1334 | G58: =SUM(G10:G57) -> 10 | H58: =SUM(H10:H57) -> 0 | I58: =SUM(I10:I57) -> 98 | J58: =SUM(J10:J57) -> 78 | ... P58: =SUM(P10:P57) -> 11267
...

Sheet 23.07 Kibuye-Makindye
B1: Consultancy services for Preparation of Expressway Development Master Plan (EDMP) for Uganda
B2: MANUAL CLASSIFIED COUNT (MCC)
B3: ROAD NAME: | C3: ='22.07 Kibuye-Makindye'!C3:G3 -> MCC - C1 - STN01 - MOBUTU ROAD
C5: Date | D5: 23.07.19 | F5: Location | G5: ='22.07 Kibuye-Makindye'!G5:H5 -> FUELEX MAKINDYE | J5: Surveyor | K5: ='22.07 Kibuye-Makindye'!K5:L5 -> WAKWESA ALLAN/CHEMONGES KENNETH/SSONKO SAMUEL/OWOMUGISHA BRENDA
C6: Dir. From | D6: ='22.07 Kibuye-Makindye'!D6:E6 -> KIBUYE | F6: Dir. To | G6: ='22.07 Kibuye-Makindye'!G6:H6 -> MAKINDYE | J6: Supervisor | K6: ='22.07 Kibuye-Makindye'!K6:L6 -> EMMA
B8: Time / Veh Type | R8: SUMMARY TRAFFIC VOLUMES
C9: 1. Car | D9: 2. Station Wagon | E9: 3. Pickups | F9: 4. Minibus, matatu | G9: 5. Medium bus | H9: 6. Large Bus | I9: 7. Light Truck | J9: 8. Medium Truck | K9: 9. Heavy truck | L9: 10. Truck Trailer | M9: 11. Motor cycles | N9: 12. Tractors | O9: Total Excl M/Cycles | P9: Total All | R9: Time | S9: 1. Car | T9: 2. Station Wagon | U9: 3. Pickups | V9: 4. Minibus, matatu | W9: 5. Medium bus | X9: 6. Large Bus | Y9: 7. Light Truck | Z9: 8. Medium Truck | AA9: 9. Heavy truck | AB9: 10. Truck Trailer | AC9: 11. Motorcycles | AD9: 12. Tractors, Graders | AE9: Total Excl M/ Cycles | AF9: Total All
B10: 07.00 - 07.15 | C10: 16 | D10: 2 | E10: 1 | F10: 30 | G10: 0 | H10: 0 | I10: 1 | J10: 1 | K10: 0 | L10: 0 | M10: 180 | N10: 0 | O10: =SUM(C10:L10,N10) -> 51 | P10: =SUM(C10:N10) -> 231 | R10: 0700-0800 | S10: =SUM(C10:C13) -> 129 | T10: =SUM(D10:D13) -> 37 | U10: =SUM(E10:E13) -> 15 | V10: =SUM(F10:F13) -> 160 | W10: =SUM(G10:G13) -> 1 | X10: =SUM(H10:H13) -> 0 | Y10: =SUM(I10:I13) -> 6 | Z10: =SUM(J10:J13) -> 4 | ... AF10: =SUM(P10:P13) -> 959
B11: 07.15 - 07.30 | C11: 46 | D11: 16 | E11: 5 | F11: 38 | G11: 0 | H11: 0 | I11: 2 | J11: 0 | K11: 1 | L11: 0 | M11: 145 | N11: 0 | O11: =SUM(C11:L11,N11) -> 108 | P11: =SUM(C11:N11) -> 253 | R11: 0800-0900 | S11: =SUM(C14:C17) -> 122 | T11: =SUM(D14:D17) -> 40 | U11: =SUM(E14:E17) -> 17 | V11: =SUM(F14:F17) -> 157 | W11: =SUM(G14:G17) -> 0 | X11: =SUM(H14:H17) -> 0 | Y11: =SUM(I14:I17) -> 5 | Z11: =SUM(J14:J17) -> 8 | ... AF11: =SUM(P14:P17) -> 980
B12: 07.30 - 07.45 | C12: 28 | D12: 7 | E12: 5 | F12: 43 | G12: 0 | H12: 0 | I12: 2 | J12: 0 | K12: 0 | L12: 0 | M12: 135 | N12: 0 | O12: =SUM(C12:L12,N12) -> 85 | P12: =SUM(C12:N12) -> 220 | R12: 0900-1000 | S12: =SUM(C18:C21) -> 155 | T12: =SUM(D18:D21) -> 51 | U12: =SUM(E18:E21) -> 20 | V12: =SUM(F18:F21) -> 131 | W12: =SUM(G18:G21) -> 0 | X12: =SUM(H18:H21) -> 1 | Y12: =SUM(I18:I21) -> 10 | Z12: =SUM(J18:J21) -> 14 | ... AF12: =SUM(P18:P21) -> 1050
B13: 07.45 - 08.00 | C13: 39 | D13: 12 | E13: 4 | F13: 49 | G13: 1 | H13: 0 | I13: 1 | J13: 3 | K13: 1 | L13: 0 | M13: 145 | N13: 0 | O13: =SUM(C13:L13,N13) -> 110 | P13: =SUM(C13:N13) -> 255 | R13: 1000-1100 | S13: =SUM(C22:C25) -> 147 | T13: =SUM(D22:D25) -> 60 | U13: =SUM(E22:E25) -> 32 | V13: =SUM(F22:F25) -> 118 | W13: =SUM(G22:G25) -> 0 | X13: =SUM(H22:H25) -> 0 | Y13: =SUM(I22:I25) -> 13 | Z13: =SUM(J22:J25) -> 16 | ... AF13: =SUM(P22:P25) -> 1140
B14: 08.00 - 08.15 | C14: 29 | D14: 12 | E14: 3 | F14: 37 | G14: 0 | H14: 0 | I14: 2 | J14: 2 | K14: 1 | L14: 0 | M14: 160 | N14: 0 | O14: =SUM(C14:L14,N14) -> 86 | P14: =SUM(C14:N14) -> 246 | R14: 1100-1200 | S14: =SUM(C26:C29) -> 135 | T14: =SUM(D26:D29) -> 57 | U14: =SUM(E26:E29) -> 26 | V14: =SUM(F26:F29) -> 97 | W14: =SUM(G26:G29) -> 0 | X14: =SUM(H26:H29) -> 0 | Y14: =SUM(I26:I29) -> 9 | Z14: =SUM(J26:J29) -> 18 | ... AF14: =SUM(P26:P29) -> 1030
B15: 08.15 - 08.30 | C15: 32 | D15: 5 | E15: 2 | F15: 45 | G15: 0 | H15: 0 | I15: 1 | J15: 2 | K15: 0 | L15: 0 | M15: 155 | N15: 0 | O15: =SUM(C15:L15,N15) -> 87 | P15: =SUM(C15:N15) -> 242 | R15: 1200-1300 | S15: =SUM(C30:C33) -> 206 | T15: =SUM(D30:D33) -> 73 | U15: =SUM(E30:E33) -> 27 | V15: =SUM(F30:F33) -> 100 | W15: =SUM(G30:G33) -> 0 | X15: =SUM(H30:H33) -> 0 | Y15: =SUM(I30:I33) -> 11 | Z15: =SUM(J30:J33) -> 12 | ... AF15: =SUM(P30:P33) -> 1155
B16: 08.30 - 08.45 | C16: 40 | D16: 11 | E16: 7 | F16: 48 | G16: 0 | H16: 0 | I16: 1 | J16: 3 | K16: 0 | L16: 0 | M16: 160 | N16: 0 | O16: =SUM(C16:L16,N16) -> 110 | P16: =SUM(C16:N16) -> 270 | R16: 1300-1400 | S16: =SUM(C34:C37) -> 194 | T16: =SUM(D34:D37) -> 76 | U16: =SUM(E34:E37) -> 40 | V16: =SUM(F34:F37) -> 89 | W16: =SUM(G34:G37) -> 0 | X16: =SUM(H34:H37) -> 0 | Y16: =SUM(I34:I37) -> 12 | Z16: =SUM(J34:J37) -> 11 | ... AF16: =SUM(P34:P37) -> 1053
B17: 08.45 - 9.00 | C17: 21 | D17: 12 | E17: 5 | F17: 27 | G17: 0 | H17: 0 | I17: 1 | J17: 1 | K17: 0 | L17: 0 | M17: 155 | N17: 0 | O17: =SUM(C17:L17,N17) -> 67 | P17: =SUM(C17:N17) -> 222 | R17: 1400-1500 | S17: =SUM(C38:C41) -> 210 | T17: =SUM(D38:D41) -> 89 | U17: =SUM(E38:E41) -> 25 | V17: =SUM(F38:F41) -> 97 | W17: =SUM(G38:G41) -> 1 | X17: =SUM(H38:H41) -> 0 | Y17: =SUM(I38:I41) -> 17 | Z17: =SUM(J38:J41) -> 15 | ... AF17: =SUM(P38:P41) -> 933
B18: 09.00 - 09.15 | C18: 54 | D18: 18 | E18: 4 | F18: 31 | G18: 0 | H18: 0 | I18: 2 | J18: 2 | K18: 1 | L18: 0 | M18: 165 | N18: 0 | O18: =SUM(C18:L18,N18) -> 112 | P18: =SUM(C18:N18) -> 277 | R18: 1500-1600 | S18: =SUM(C42:C45) -> 206 | T18: =SUM(D42:D45) -> 90 | U18: =SUM(E42:E45) -> 45 | V18: =SUM(F42:F45) -> 81 | W18: =SUM(G42:G45) -> 1 | X18: =SUM(H42:H45) -> 0 | Y18: =SUM(I42:I45) -> 14 | Z18: =SUM(J42:J45) -> 10 | ... AF18: =SUM(P42:P45) -> 1107
B19: 09.15 - 09.30 | C19: 36 | D19: 7 | E19: 2 | F19: 34 | G19: 0 | H19: 1 | I19: 2 | J19: 5 | K19: 1 | L19: 0 | M19: 175 | N19: 0 | O19: =SUM(C19:L19,N19) -> 88 | P19: =SUM(C19:N19) -> 263 | R19: 1600-1700 | S19: =SUM(C46:C49) -> 172 | T19: =SUM(D46:D49) -> 84 | U19: =SUM(E46:E49) -> 42 | V19: =SUM(F46:F49) -> 68 | W19: =SUM(G46:G49) -> 3 | X19: =SUM(H46:H49) -> 0 | Y19: =SUM(I46:I49) -> 15 | Z19: =SUM(J46:J49) -> 7 | ... AF19: =SUM(P46:P49) -> 1032
B20: 09.30 - 09.45 | C20: 37 | D20: 16 | E20: 5 | F20: 34 | G20: 0 | H20: 0 | I20: 2 | J20: 5 | K20: 1 | L20: 0 | M20: 145 | N20: 0 | O20: =SUM(C20:L20,N20) -> 100 | P20: =SUM(C20:N20) -> 245 | R20: 1700-1800 | S20: =SUM(C50:C53) -> 251 | T20: =SUM(D50:D53) -> 105 | U20: =SUM(E50:E53) -> 35 | V20: =SUM(F50:F53) -> 58 | W20: =SUM(G50:G53) -> 7 | X20: =SUM(H50:H53) -> 0 | Y20: =SUM(I50:I53) -> 10 | Z20: =SUM(J50:J53) -> 10 | ... AF20: =SUM(P50:P53) -> 1151
B21: 09.45 - 10.00 | C21: 28 | D21: 10 | E21: 9 | F21: 32 | G21: 0 | H21: 0 | I21: 4 | J21: 2 | K21: 0 | L21: 0 | M21: 180 | N21: 0 | O21: =SUM(C21:L21,N21) -> 85 | P21: =SUM(C21:N21) -> 265 | R21: 1800-1900 | S21: =SUM(C54:C57) -> 127 | T21: =SUM(D54:D57) -> 63 | U21: =SUM(E54:E57) -> 25 | V21: =SUM(F54:F57) -> 55 | W21: =SUM(G54:G57) -> 7 | X21: =SUM(H54:H57) -> 1 | Y21: =SUM(I54:I57) -> 13 | Z21: =SUM(J54:J57) -> 7 | ... AF21: =SUM(P54:P57) -> 859
B22: 10.00 - 10.15 | C22: 32 | D22: 13 | E22: 7 | F22: 37 | G22: 0 | H22: 0 | I22: 2 | J22: 7 | K22: 0 | L22: 0 | M22: 185 | N22: 0 | O22: =SUM(C22:L22,N22) -> 98 | P22: =SUM(C22:N22) -> 283 | R22: AM Peak Hr | S22: =MAX(S10:S12) -> 155 | T22: =MAX(T10:T12) -> 51 | U22: =MAX(U10:U12) -> 20 | V22: =MAX(V10:V12) -> 160 | W22: =MAX(W10:W12) -> 1 | X22: =MAX(X10:X12) -> 1 | Y22: =MAX(Y10:Y12) -> 10 | Z22: =MAX(Z10:Z12) -> 14 | ... AF22: =MAX(AF10:AF12) -> 1050
B23: 10.15 - 10.30 | C23: 30 | D23: 19 | E23: 8 | F23: 23 | G23: 0 | H23: 0 | I23: 2 | J23: 3 | K23: 1 | L23: 0 | M23: 200 | N23: 0 | O23: =SUM(C23:L23,N23) -> 86 | P23: =SUM(C23:N23) -> 286 | R23: IP Peak Hr | S23: =MAX(S13:S18) -> 210 | T23: =MAX(T13:T18) -> 90 | U23: =MAX(U13:U18) -> 45 | V23: =MAX(V13:V18) -> 118 | W23: =MAX(W13:W18) -> 1 | X23: =MAX(X13:X18) -> 0 | Y23: =MAX(Y13:Y18) -> 17 | Z23: =MAX(Z13:Z18) -> 18 | ... AF23: =MAX(AF13:AF18) -> 1155
B24: 10.30 - 10.45 | C24: 39 | D24: 14 | E24: 11 | F24: 26 | G24: 0 | H24: 0 | I24: 7 | J24: 4 | K24: 3 | L24: 0 | M24: 180 | N24: 0 | O24: =SUM(C24:L24,N24) -> 104 | P24: =SUM(C24:N24) -> 284 | R24: PM Peak Hr | S24: =MAX(S19:S21) -> 251 | T24: =MAX(T19:T21) -> 105 | U24: =MAX(U19:U21) -> 42 | V24: =MAX(V19:V21) -> 68 | W24: =MAX(W19:W21) -> 7 | X24: =MAX(X19:X21) -> 1 | Y24: =MAX(Y19:Y21) -> 15 | Z24: =MAX(Z19:Z21) -> 10 | ... AF24: =MAX(AF19:AF21) -> 1151
B25: 10.45 - 11.00 | C25: 46 | D25: 14 | E25: 6 | F25: 32 | G25: 0 | H25: 0 | I25: 2 | J25: 2 | K25: 0 | L25: 0 | M25: 185 | N25: 0 | O25: =SUM(C25:L25,N25) -> 102 | P25: =SUM(C25:N25) -> 287 | R25: AM Period | S25: =SUM(S10:S12) -> 406 | T25: =SUM(T10:T12) -> 128 | U25: =SUM(U10:U12) -> 52 | V25: =SUM(V10:V12) -> 448 | W25: =SUM(W10:W12) -> 1 | X25: =SUM(X10:X12) -> 1 | Y25: =SUM(Y10:Y12) -> 21 | Z25: =SUM(Z10:Z12) -> 26 | ... AF25: =SUM(AF10:AF12) -> 2989
B26: 11.00 - 11.15 | C26: 31 | D26: 11 | E26: 4 | F26: 29 | G26: 0 | H26: 0 | I26: 3 | J26: 3 | K26: 1 | L26: 0 | M26: 160 | N26: 0 | O26: =SUM(C26:L26,N26) -> 82 | P26: =SUM(C26:N26) -> 242 | R26: IP Period | S26: =SUM(S13:S18) -> 1098 | T26: =SUM(T13:T18) -> 445 | U26: =SUM(U13:U18) -> 195 | V26: =SUM(V13:V18) -> 582 | W26: =SUM(W13:W18) -> 2 | X26: =SUM(X13:X18) -> 0 | Y26: =SUM(Y13:Y18) -> 76 | Z26: =SUM(Z13:Z18) -> 82 | ... AF26: =SUM(AF13:AF18) -> 6418
B27: 11.15 - 11.30 | C27: 32 | D27: 14 | E27: 9 | F27: 26 | G27: 0 | H27: 0 | I27: 4 | J27: 4 | K27: 2 | L27: 0 | M27: 170 | N27: 0 | O27: =SUM(C27:L27,N27) -> 91 | P27: =SUM(C27:N27) -> 261 | R27: PM Period | S27: =SUM(S19:S21) -> 550 | T27: =SUM(T19:T21) -> 252 | U27: =SUM(U19:U21) -> 102 | V27: =SUM(V19:V21) -> 181 | W27: =SUM(W19:W21) -> 17 | X27: =SUM(X19:X21) -> 1 | Y27: =SUM(Y19:Y21) -> 38 | Z27: =SUM(Z19:Z21) -> 24 | ... AF27: =SUM(AF19:AF21) -> 3042
B28: 11.30 - 11.45 | C28: 30 | D28: 21 | E28: 7 | F28: 16 | G28: 0 | H28: 0 | I28: 1 | J28: 5 | K28: 0 | L28: 0 | M28: 145 | N28: 0 | O28: =SUM(C28:L28,N28) -> 80 | P28: =SUM(C28:N28) -> 225 | R28: 12 Hours | S28: =SUM(S10:S21) -> 2054 | T28: =SUM(T10:T21) -> 825 | U28: =SUM(U10:U21) -> 349 | V28: =SUM(V10:V21) -> 1211 | W28: =SUM(W10:W21) -> 20 | X28: =SUM(X10:X21) -> 2 | Y28: =SUM(Y10:Y21) -> 135 | Z28: =SUM(Z10:Z21) -> 132 | ... AF28: =SUM(AF10:AF21) -> 12449
B29: 11.45 - 12.00 | C29: 42 | D29: 11 | E29: 6 | F29: 26 | G29: 0 | H29: 0 | I29: 1 | J29: 6 | K29: 0 | L29: 0 | M29: 210 | N29: 0 | O29: =SUM(C29:L29,N29) -> 92 | P29: =SUM(C29:N29) -> 302
B30: 12.00 - 12.15 | C30: 47 | D30: 18 | E30: 7 | F30: 25 | G30: 0 | H30: 0 | I30: 4 | J30: 2 | K30: 0 | L30: 0 | M30: 185 | N30: 0 | O30: =SUM(C30:L30,N30) -> 103 | P30: =SUM(C30:N30) -> 288
B31: 12.15 - 12.30 | C31: 48 | D31: 13 | E31: 8 | F31: 26 | G31: 0 | H31: 0 | I31: 5 | J31: 3 | K31: 0 | L31: 0 | M31: 190 | N31: 0 | O31: =SUM(C31:L31,N31) -> 103 | P31: =SUM(C31:N31) -> 293
B32: 12.30 - 12.45 | C32: 44 | D32: 18 | E32: 7 | F32: 27 | G32: 0 | H32: 0 | I32: 1 | J32: 3 | K32: 2 | L32: 0 | M32: 195 | N32: 1 | O32: =SUM(C32:L32,N32) -> 103 | P32: =SUM(C32:N32) -> 298
B33: 12.45 - 13.00 | C33: 67 | D33: 24 | E33: 5 | F33: 22 | G33: 0 | H33: 0 | I33: 1 | J33: 4 | K33: 1 | L33: 0 | M33: 152 | N33: 0 | O33: =SUM(C33:L33,N33) -> 124 | P33: =SUM(C33:N33) -> 276
B34: 13.00 - 13.15 | C34: 58 | D34: 14 | E34: 13 | F34: 23 | G34: 0 | H34: 0 | I34: 2 | J34: 2 | K34: 0 | L34: 0 | M34: 155 | N34: 0 | O34: =SUM(C34:L34,N34) -> 112 | P34: =SUM(C34:N34) -> 267
B35: 13.15 - 13.30 | C35: 53 | D35: 24 | E35: 10 | F35: 26 | G35: 0 | H35: 0 | I35: 0 | J35: 0 | K35: 0 | L35: 0 | M35: 149 | N35: 0 | O35: =SUM(C35:L35,N35) -> 113 | P35: =SUM(C35:N35) -> 262
B36: 13.30 - 13.45 | C36: 42 | D36: 6 | E36: 11 | F36: 15 | G36: 0 | H36: 0 | I36: 3 | J36: 4 | K36: 1 | L36: 0 | M36: 145 | N36: 0 | O36: =SUM(C36:L36,N36) -> 82 | P36: =SUM(C36:N36) -> 227
B37: 13.45 - 14.00 | C37: 41 | D37: 32 | E37: 6 | F37: 25 | G37: 0 | H37: 0 | I37: 7 | J37: 5 | K37: 1 | L37: 0 | M37: 180 | N37: 0 | O37: =SUM(C37:L37,N37) -> 117 | P37: =SUM(C37:N37) -> 297
B38: 14.00 - 14.15 | C38: 48 | D38: 18 | E38: 7 | F38: 24 | G38: 0 | H38: 0 | I38: 8 | J38: 5 | K38: 0 | L38: 0 | M38: 152 | N38: 0 | O38: =SUM(C38:L38,N38) -> 110 | P38: =SUM(C38:N38) -> 262
B39: 14.15 - 14.30 | C39: 53 | D39: 20 | E39: 5 | F39: 16 | G39: 1 | H39: 0 | I39: 4 | J39: 4 | K39: 0 | L39: 0 | M39: 150 | N39: 0 | O39: =SUM(C39:L39,N39) -> 103 | P39: =SUM(C39:N39) -> 253
B40: 14.30 - 14.45 | C40: 48 | D40: 16 | E40: 2 | F40: 17 | G40: 0 | H40: 0 | I40: 4 | J40: 3 | K40: 2 | L40: 0 | M40: 75 | N40: 0 | O40: =SUM(C40:L40,N40) -> 92 | P40: =SUM(C40:N40) -> 167
... B57: 18.45 - 19.00 | C57: 11 | D57: 6 | E57: 2 | F57: 8 | G57: 2 | H57: 1 | I57: 1 | J57: 2 | K57: 0 | L57: 0 | M57: 110 | N57: 0 | O57: =SUM(C57:L57,N57) -> 33 | P57: =SUM(C57:N57) -> 143
B58: Totals | C58: =SUM(C10:C57) -> 2054 | D58: =SUM(D10:D57) -> 825 | E58: =SUM(E10:E57) -> 349 | F58: =SUM(F10:F57) -> 1211 | G58: =SUM(G10:G57) -> 20 | H58: =SUM(H10:H57) -> 2 | I58: =SUM(I10:I57) -> 135 | J58: =SUM(J10:J57) -> 132 | ... P58: =SUM(P10:P57) -> 12449
...

Sheet 23.07 Makindye-Kibuye
B1: Consultancy services for Preparation of Expressway Development Master Plan (EDMP) for Uganda
B2: MANUAL CLASSIFIED COUNT (MCC)
B3: ROAD NAME: | C3: ='22.07 Makindye-Kibuye'!C3:G3 -> MCC - C1 - STN01 - MOBUTU ROAD
C5: Date | D5: ='23.07 Kibuye-Makindye'!D5 -> 23.07.19 | F5: Location | G5: ='22.07 Kibuye-Makindye'!G5:H5 -> FUELEX MAKINDYE | J5: Surveyor | K5: ='22.07 Kibuye-Makindye'!K5:L5 -> WAKWESA ALLAN/CHEMONGES KENNETH/SSONKO SAMUEL/OWOMUGISHA BRENDA
C6: Dir. From | D6: ='22.07 Makindye-Kibuye'!D6:E6 -> MAKINDYE | F6: Dir. To | G6: ='22.07 Makindye-Kibuye'!G6:H6 -> KIBUYE | J6: Supervisor | K6: ='22.07 Kibuye-Makindye'!K6:L6 -> EMMA
B8: Time / Veh Type | R8: SUMMARY TRAFFIC VOLUMES
C9: 1. Car | D9: 2. Station Wagon | E9: 3. Pickups | F9: 4. Minibus, matatu | G9: 5. Medium bus | H9: 6. Large Bus | I9: 7. Light Truck | J9: 8. Medium Truck | K9: 9. Heavy truck | L9: 10. Truck Trailer | M9: 11. Motor cycles | N9: 12. Tractors | O9: Total Excl M/Cycles | P9: Total All | R9: Time | S9: 1. Car | T9: 2. Station Wagon | U9: 3. Pickups | V9: 4. Minibus, matatu | W9: 5. Medium bus | X9: 6. Large Bus | Y9: 7. Light Truck | Z9: 8. Medium Truck | AA9: 9. Heavy truck | AB9: 10. Truck Trailer | AC9: 11. Motorcycles | AD9: 12. Tractors, Graders | AE9: Total Excl M/ Cycles | AF9: Total All
B10: 07.00 - 07.15 | C10: 34 | D10: 2 | E10: 7 | F10: 4 | G10: 0 | H10: 0 | I10: 1 | J10: 2 | K10: 0 | L10: 0 | M10: 150 | N10: 0 | O10: =SUM(C10:L10,N10) -> 50 | P10: =SUM(C10:N10) -> 200 | R10: 0700-0800 | S10: =SUM(C10:C13) -> 197 | T10: =SUM(D10:D13) -> 18 | U10: =SUM(E10:E13) -> 21 | V10: =SUM(F10:F13) -> 15 | W10: =SUM(G10:G13) -> 0 | X10: =SUM(H10:H13) -> 0 | Y10: =SUM(I10:I13) -> 8 | Z10: =SUM(J10:J13) -> 9 | ... AF10: =SUM(P10:P13) -> 953
B11: 07.15 - 07.30 | C11: 38 | D11: 5 | E11: 6 | F11: 7 | G11: 0 | H11: 0 | I11: 3 | J11: 1 | K11: 0 | L11: 0 | M11: 150 | N11: 0 | O11: =SUM(C11:L11,N11) -> 60 | P11: =SUM(C11:N11) -> 210 | R11: 0800-0900 | S11: =SUM(C14:C17) -> 195 | T11: =SUM(D14:D17) -> 23 | U11: =SUM(E14:E17) -> 26 | V11: =SUM(F14:F17) -> 46 | W11: =SUM(G14:G17) -> 0 | X11: =SUM(H14:H17) -> 0 | Y11: =SUM(I14:I17) -> 8 | Z11: =SUM(J14:J17) -> 9 | ... AF11: =SUM(P14:P17) -> 1112
B12: 07.30 - 07.45 | C12: 57 | D12: 4 | E12: 5 | F12: 3 | G12: 0 | H12: 0 | I12: 1 | J12: 5 | K12: 0 | L12: 0 | M12: 180 | N12: 0 | O12: =SUM(C12:L12,N12) -> 75 | P12: =SUM(C12:N12) -> 255 | R12: 0900-1000 | S12: =SUM(C18:C21) -> 198 | T12: =SUM(D18:D21) -> 23 | U12: =SUM(E18:E21) -> 23 | V12: =SUM(F18:F21) -> 121 | W12: =SUM(G18:G21) -> 1 | X12: =SUM(H18:H21) -> 0 | Y12: =SUM(I18:I21) -> 9 | Z12: =SUM(J18:J21) -> 8 | ... AF12: =SUM(P18:P21) -> 1209
B13: 07.45 - 08.00 | C13: 68 | D13: 7 | E13: 3 | F13: 1 | G13: 0 | H13: 0 | I13: 3 | J13: 1 | K13: 0 | L13: 0 | M13: 205 | N13: 0 | O13: =SUM(C13:L13,N13) -> 83 | P13: =SUM(C13:N13) -> 288 | R13: 1000-1100 | S13: =SUM(C22:C25) -> 192 | T13: =SUM(D22:D25) -> 33 | U13: =SUM(E22:E25) -> 25 | V13: =SUM(F22:F25) -> 142 | W13: =SUM(G22:G25) -> 1 | X13: =SUM(H22:H25) -> 0 | Y13: =SUM(I22:I25) -> 16 | Z13: =SUM(J22:J25) -> 10 | ... AF13: =SUM(P22:P25) -> 1216
B14: 08.00 - 08.15 | C14: 56 | D14: 7 | E14: 7 | F14: 4 | G14: 0 | H14: 0 | I14: 1 | J14: 1 | K14: 0 | L14: 0 | M14: 190 | N14: 0 | O14: =SUM(C14:L14,N14) -> 76 | P14: =SUM(C14:N14) -> 266 | R14: 1100-1200 | S14: =SUM(C26:C29) -> 163 | T14: =SUM(D26:D29) -> 48 | U14: =SUM(E26:E29) -> 26 | V14: =SUM(F26:F29) -> 151 | W14: =SUM(G26:G29) -> 0 | X14: =SUM(H26:H29) -> 0 | Y14: =SUM(I26:I29) -> 14 | Z14: =SUM(J26:J29) -> 8 | ... AF14: =SUM(P26:P29) -> 936
B15: 08.15 - 08.30 | C15: 42 | D15: 5 | E15: 7 | F15: 15 | G15: 0 | H15: 0 | I15: 1 | J15: 3 | K15: 0 | L15: 0 | M15: 210 | N15: 0 | O15: =SUM(C15:L15,N15) -> 73 | P15: =SUM(C15:N15) -> 283 | R15: 1200-1300 | S15: =SUM(C30:C33) -> 176 | T15: =SUM(D30:D33) -> 63 | U15: =SUM(E30:E33) -> 33 | V15: =SUM(F30:F33) -> 143 | W15: =SUM(G30:G33) -> 1 | X15: =SUM(H30:H33) -> 0 | Y15: =SUM(I30:I33) -> 17 | Z15: =SUM(J30:J33) -> 9 | ... AF15: =SUM(P30:P33) -> 1133
B16: 08.30 - 08.45 | C16: 50 | D16: 6 | E16: 4 | F16: 11 | G16: 0 | H16: 0 | I16: 1 | J16: 1 | K16: 0 | L16: 0 | M16: 240 | N16: 0 | O16: =SUM(C16:L16,N16) -> 73 | P16: =SUM(C16:N16) -> 313 | R16: 1300-1400 | S16: =SUM(C34:C37) -> 131 | T16: =SUM(D34:D37) -> 57 | U16: =SUM(E34:E37) -> 21 | V16: =SUM(F34:F37) -> 124 | W16: =SUM(G34:G37) -> 0 | X16: =SUM(H34:H37) -> 0 | Y16: =SUM(I34:I37) -> 15 | Z16: =SUM(J34:J37) -> 12 | ... AF16: =SUM(P34:P37) -> 996
B17: 08.45 - 9.00 | C17: 47 | D17: 5 | E17: 8 | F17: 16 | G17: 0 | H17: 0 | I17: 5 | J17: 4 | K17: 0 | L17: 0 | M17: 165 | N17: 0 | O17: =SUM(C17:L17,N17) -> 85 | P17: =SUM(C17:N17) -> 250 | R17: 1400-1500 | S17: =SUM(C38:C41) -> 135 | T17: =SUM(D38:D41) -> 42 | U17: =SUM(E38:E41) -> 30 | V17: =SUM(F38:F41) -> 141 | W17: =SUM(G38:G41) -> 0 | X17: =SUM(H38:H41) -> 0 | Y17: =SUM(I38:I41) -> 17 | Z17: =SUM(J38:J41) -> 11 | ... AF17: =SUM(P38:P41) -> 1043
B18: 09.00 - 09.15 | C18: 55 | D18: 10 | E18: 7 | F18: 23 | G18: 0 | H18: 0 | I18: 1 | J18: 3 | K18: 0 | L18: 0 | M18: 210 | N18: 0 | O18: =SUM(C18:L18,N18) -> 99 | P18: =SUM(C18:N18) -> 309 | R18: 1500-1600 | S18: =SUM(C42:C45) -> 104 | T18: =SUM(D42:D45) -> 26 | U18: =SUM(E42:E45) -> 23 | V18: =SUM(F42:F45) -> 110 | W18: =SUM(G42:G45) -> 1 | X18: =SUM(H42:H45) -> 1 | Y18: =SUM(I42:I45) -> 14 | Z18: =SUM(J42:J45) -> 6 | ... AF18: =SUM(P42:P45) -> 912
B19: 09.15 - 09.30 | C19: 65 | D19: 9 | E19: 7 | F19: 30 | G19: 1 | H19: 0 | I19: 3 | J19: 2 | K19: 1 | L19: 0 | M19: 200 | N19: 0 | O19: =SUM(C19:L19,N19) -> 118 | P19: =SUM(C19:N19) -> 318 | R19: 1600-1700 | S19: =SUM(C46:C49) -> 112 | T19: =SUM(D46:D49) -> 41 | U19: =SUM(E46:E49) -> 32 | V19: =SUM(F46:F49) -> 102 | W19: =SUM(G46:G49) -> 0 | X19: =SUM(H46:H49) -> 0 | Y19: =SUM(I46:I49) -> 13 | Z19: =SUM(J46:J49) -> 9 | ... AF19: =SUM(P46:P49) -> 996
B20: 09.30 - 09.45 | C20: 41 | D20: 1 | E20: 3 | F20: 34 | G20: 0 | H20: 0 | I20: 3 | J20: 1 | K20: 0 | L20: 0 | M20: 205 | N20: 0 | O20: =SUM(C20:L20,N20) -> 83 | P20: =SUM(C20:N20) -> 288 | R20: 1700-1800 | S20: =SUM(C50:C53) -> 107 | T20: =SUM(D50:D53) -> 22 | U20: =SUM(E50:E53) -> 12 | V20: =SUM(F50:F53) -> 94 | W20: =SUM(G50:G53) -> 0 | X20: =SUM(H50:H53) -> 0 | Y20: =SUM(I50:I53) -> 4 | Z20: =SUM(J50:J53) -> 9 | ... AF20: =SUM(P50:P53) -> 909
B21: 09.45 - 10.00 | C21: 37 | D21: 3 | E21: 6 | F21: 34 | G21: 0 | H21: 0 | I21: 2 | J21: 2 | K21: 0 | L21: 0 | M21: 210 | N21: 0 | O21: =SUM(C21:L21,N21) -> 84 | P21: =SUM(C21:N21) -> 294 | R21: 1800-1900 | S21: =SUM(C54:C57) -> 70 | T21: =SUM(D54:D57) -> 18 | U21: =SUM(E54:E57) -> 8 | V21: =SUM(F54:F57) -> 59 | W21: =SUM(G54:G57) -> 0 | X21: =SUM(H54:H57) -> 0 | Y21: =SUM(I54:I57) -> 7 | Z21: =SUM(J54:J57) -> 3 | ... AF21: =SUM(P54:P57) -> 778
B22: 10.00 - 10.15 | C22: 65 | D22: 7 | E22: 7 | F22: 33 | G22: 0 | H22: 0 | I22: 2 | J22: 3 | K22: 0 | L22: 0 | M22: 210 | N22: 0 | O22: =SUM(C22:L22,N22) -> 117 | P22: =SUM(C22:N22) -> 327 | R22: AM Peak Hr | S22: =MAX(S10:S12) -> 198 | T22: =MAX(T10:T12) -> 23 | U22: =MAX(U10:U12) -> 26 | V22: =MAX(V10:V12) -> 121 | W22: =MAX(W10:W12) -> 1 | X22: =MAX(X10:X12) -> 0 | Y22: =MAX(Y10:Y12) -> 9 | Z22: =MAX(Z10:Z12) -> 9 | ... AF22: =MAX(AF10:AF12) -> 1209
B23: 10.15 - 10.30 | C23: 50 | D23: 7 | E23: 5 | F23: 40 | G23: 1 | H23: 0 | I23: 5 | J23: 0 | K23: 0 | L23: 0 | M23: 205 | N23: 0 | O23: =SUM(C23:L23,N23) -> 108 | P23: =SUM(C23:N23) -> 313 | R23: IP Peak Hr | S23: =MAX(S13:S18) -> 192 | T23: =MAX(T13:T18) -> 63 | U23: =MAX(U13:U18) -> 33 | V23: =MAX(V13:V18) -> 151 | W23: =MAX(W13:W18) -> 1 | X23: =MAX(X13:X18) -> 1 | Y23: =MAX(Y13:Y18) -> 17 | Z23: =MAX(Z13:Z18) -> 12 | ... AF23: =MAX(AF13:AF18) -> 1216
B24: 10.30 - 10.45 | C24: 28 | D24: 9 | E24: 8 | F24: 34 | G24: 0 | H24: 0 | I24: 4 | J24: 3 | K24: 0 | L24: 1 | M24: 200 | N24: 0 | O24: =SUM(C24:L24,N24) -> 87 | P24: =SUM(C24:N24) -> 287 | R24: PM Peak Hr | S24: =MAX(S19:S21) -> 112 | T24: =MAX(T19:T21) -> 41 | U24: =MAX(U19:U21) -> 32 | V24: =MAX(V19:V21) -> 102 | W24: =MAX(W19:W21) -> 0 | X24: =MAX(X19:X21) -> 0 | Y24: =MAX(Y19:Y21) -> 13 | Z24: =MAX(Z19:Z21) -> 9 | ... AF24: =MAX(AF19:AF21) -> 996
B25: 10.45 - 11.00 | C25: 49 | D25: 10 | E25: 5 | F25: 35 | G25: 0 | H25: 0 | I25: 5 | J25: 4 | K25: 1 | L25: 0 | M25: 180 | N25: 0 | O25: =SUM(C25:L25,N25) -> 109 | P25: =SUM(C25:N25) -> 289 | R25: AM Period | S25: =SUM(S10:S12) -> 590 | T25: =SUM(T10:T12) -> 64 | U25: =SUM(U10:U12) -> 70 | V25: =SUM(V10:V12) -> 182 | W25: =SUM(W10:W12) -> 1 | X25: =SUM(X10:X12) -> 0 | Y25: =SUM(Y10:Y12) -> 25 | Z25: =SUM(Z10:Z12) -> 26 | ... AF25: =SUM(AF10:AF12) -> 3274
B26: 11.00 - 11.15 | C26: 41 | D26: 11 | E26: 6 | F26: 35 | G26: 0 | H26: 0 | I26: 3 | J26: 1 | K26: 0 | L26: 0 | M26: 130 | N26: 0 | O26: =SUM(C26:L26,N26) -> 97 | P26: =SUM(C26:N26) -> 227 | R26: IP Period | S26: =SUM(S13:S18) -> 901 | T26: =SUM(T13:T18) -> 269 | U26: =SUM(U13:U18) -> 158 | V26: =SUM(V13:V18) -> 811 | W26: =SUM(W13:W18) -> 3 | X26: =SUM(X13:X18) -> 1 | Y26: =SUM(Y13:Y18) -> 93 | Z26: =SUM(Z13:Z18) -> 56 | ... AF26: =SUM(AF13:AF18) -> 6236
B27: 11.15 - 11.30 | C27: 50 | D27: 10 | E27: 5 | F27: 44 | G27: 0 | H27: 0 | I27: 2 | J27: 1 | K27: 1 | L27: 0 | M27: 75 | N27: 0 | O27: =SUM(C27:L27,N27) -> 113 | P27: =SUM(C27:N27) -> 188 | R27: PM Period | S27: =SUM(S19:S21) -> 289 | T27: =SUM(T19:T21) -> 81 | U27: =SUM(U19:U21) -> 52 | V27: =SUM(V19:V21) -> 255 | W27: =SUM(W19:W21) -> 0 | X27: =SUM(X19:X21) -> 0 | Y27: =SUM(Y19:Y21) -> 24 | Z27: =SUM(Z19:Z21) -> 21 | ... AF27: =SUM(AF19:AF21) -> 2683
B28: 11.30 - 11.45 | C28: 32 | D28: 18 | E28: 11 | F28: 32 | G28: 0 | H28: 0 | I28: 4 | J28: 2 | K28: 0 | L28: 0 | M28: 170 | N28: 0 | O28: =SUM(C28:L28,N28) -> 99 | P28: =SUM(C28:N28) -> 269 | R28: 12 Hours | S28: =SUM(S10:S21) -> 1780 | T28: =SUM(T10:T21) -> 414 | U28: =SUM(U10:U21) -> 280 | V28: =SUM(V10:V21) -> 1248 | W28: =SUM(W10:W21) -> 4 | X28: =SUM(X10:X21) -> 1 | Y28: =SUM(Y10:Y21) -> 142 | Z28: =SUM(Z10:Z21) -> 103 | ... AF28: =SUM(AF10:AF21) -> 12193
B29: 11.45 - 12.00 | C29: 40 | D29: 9 | E29: 4 | F29: 40 | G29: 0 | H29: 0 | I29: 5 | J29: 4 | K29: 0 | L29: 0 | M29: 150 | N29: 0 | O29: =SUM(C29:L29,N29) -> 102 | P29: =SUM(C29:N29) -> 252
B30: 12.00 - 12.15 | C30: 47 | D30: 13 | E30: 9 | F30: 34 | G30: 1 | H30: 0 | I30: 5 | J30: 3 | K30: 3 | L30: 0 | M30: 175 | N30: 0 | O30: =SUM(C30:L30,N30) -> 115 | P30: =SUM(C30:N30) -> 290
B31: 12.15 - 12.30 | C31: 46 | D31: 13 | E31: 6 | F31: 34 | G31: 0 | H31: 0 | I31: 4 | J31: 1 | K31: 1 | L31: 0 | M31: 175 | N31: 0 | O31: =SUM(C31:L31,N31) -> 105 | P31: =SUM(C31:N31) -> 280
B32: 12.30 - 12.45 | C32: 38 | D32: 19 | E32: 7 | F32: 35 | G32: 0 | H32: 0 | I32: 4 | J32: 1 | K32: 1 | L32: 0 | M32: 170 | N32: 0 | O32: =SUM(C32:L32,N32) -> 105 | P32: =SUM(C32:N32) -> 275
B33: 12.45 - 13.00 | C33: 45 | D33: 18 | E33: 11 | F33: 40 | G33: 0 | H33: 0 | I33: 4 | J33: 4 | K33: 0 | L33: 1 | M33: 165 | N33: 0 | O33: =SUM(C33:L33,N33) -> 123 | P33: =SUM(C33:N33) -> 288
B34: 13.00 - 13.15 | C34: 36 | D34: 15 | E34: 9 | F34: 33 | G34: 0 | H34: 0 | I34: 3 | J34: 3 | K34: 0 | L34: 0 | M34: 170 | N34: 0 | O34: =SUM(C34:L34,N34) -> 99 | P34: =SUM(C34:N34) -> 269
B35: 13.15 - 13.30 | C35: 32 | D35: 15 | E35: 3 | F35: 38 | G35: 0 | H35: 0 | I35: 5 | J35: 3 | K35: 0 | L35: 0 | M35: 170 | N35: 0 | O35: =SUM(C35:L35,N35) -> 96 | P35: =SUM(C35:N35) -> 266
B36: 13.30 - 13.45 | C36: 28 | D36: 17 | E36: 6 | F36: 24 | G36: 0 | H36: 0 | I36: 3 | J36: 4 | K36: 0 | L36: 0 | M36: 100 | N36: 0 | O36: =SUM(C36:L36,N36) -> 82 | P36: =SUM(C36:N36) -> 182
B37: 13.45 - 14.00 | C37: 35 | D37: 10 | E37: 3 | F37: 29 | G37: 0 | H37: 0 | I37: 4 | J37: 2 | K37: 0 | L37: 0 | M37: 195 | N37: 1 | O37: =SUM(C37:L37,N37) -> 84 | P37: =SUM(C37:N37) -> 279
B38: 14.00 - 14.15 | C38: 46 | D38: 8 | E38: 7 | F38: 35 | G38: 0 | H38: 0 | I38: 6 | J38: 4 | K38: 0 | L38: 0 | M38: 160 | N38: 0 | O38: =SUM(C38:L38,N38) -> 106 | P38: =SUM(C38:N38) -> 266
B39: 14.15 - 14.30 | C39: 30 | D39: 12 | E39: 11 | F39: 34 | G39: 0 | H39: 0 | I39: 5 | J39: 7 | K39: 0 | L39: 0 | M39: 175 | N39: 0 | O39: =SUM(C39:L39,N39) -> 99 | P39: =SUM(C39:N39) -> 274
B40: 14.30 - 14.45 | C40: 32 | D40: 11 | E40: 7 | F40: 45 | G40: 0 | H40: 0 | I40: 3 | J40: 0 | K40: 2 | L40: 0 | M40: 150 | N40: 0 | O40: =SUM(C40:L40,N40) -> 100 | P40: =SUM(C40:N40) -> 250
... B57: 18.45 - 19.00 | C57: 5 | D57: 4 | E57: 0 | F57: 14 | G57: 0 | H57: 0 | I57: 1 | J57: 0 | K57: 0 | L57: 0 | M57: 180 | N57: 0 | O57: =SUM(C57:L57,N57) -> 24 | P57: =SUM(C57:N57) -> 204
B58: Totals | C58: =SUM(C10:C57) -> 1780 | D58: =SUM(D10:D57) -> 414 | E58: =SUM(E10:E57) -> 280 | F58: =SUM(F10:F57) -> 1248 | G58: =SUM(G10:G57) -> 4 | H58: =SUM(H10:H57) -> 1 | I58: =SUM(I10:I57) -> 142 | J58: =SUM(J10:J57) -> 103 | ... P58: =SUM(P10:P57) -> 12193
...

Sheet 24.07 Kibuye-Makindye
B1: Consultancy services for Preparation of Expressway Development Master Plan (EDMP) for Uganda
B2: MANUAL CLASSIFIED COUNT (MCC)
B3: ROAD NAME: | C3: ='22.07 Kibuye-Makindye'!C3:G3 -> MCC - C1 - STN01 - MOBUTU ROAD
C5: Date | D5: 24.07.19 | F5: Location | G5: ='22.07 Kibuye-Makindye'!G5:H5 -> FUELEX MAKINDYE | J5: Surveyor | K5: ='22.07 Kibuye-Makindye'!K5:L5 -> WAKWESA ALLAN/CHEMONGES KENNETH/SSONKO SAMUEL/OWOMUGISHA BRENDA
C6: Dir. From | D6: ='22.07 Kibuye-Makindye'!D6:E6 -> KIBUYE | F6: Dir. To | G6: ='22.07 Kibuye-Makindye'!G6:H6 -> MAKINDYE | J6: Supervisor | K6: ='22.07 Kibuye-Makindye'!K6:L6 -> EMMA
B8: Time / Veh Type | R8: SUMMARY TRAFFIC VOLUMES
C9: 1. Car | D9: 2. Station Wagon | E9: 3. Pickups | F9: 4. Minibus, matatu | G9: 5. Medium bus | H9: 6. Large Bus | I9: 7. Light Truck | J9: 8. Medium Truck | K9: 9. Heavy truck | L9: 10. Truck Trailer | M9: 11. Motor cycles | N9: 12. Tractors | O9: Total Excl M/Cycles | P9: Total All | R9: Time | S9: 1. Car | T9: 2. Station Wagon | U9: 3. Pickups | V9: 4. Minibus, matatu | W9: 5. Medium bus | X9: 6. Large Bus | Y9: 7. Light Truck | Z9: 8. Medium Truck | AA9: 9. Heavy truck | AB9: 10. Truck Trailer | AC9: 11. Motorcycles | AD9: 12. Tractors, Graders | AE9: Total Excl M/ Cycles | AF9: Total All
B10: 07.00 - 07.15 | C10: 18 | D10: 4 | E10: 2 | F10: 18 | G10: 0 | H10: 0 | I10: 1 | J10: 2 | K10: 0 | L10: 0 | M10: 120 | N10: 0 | O10: =SUM(C10:L10,N10) -> 45 | P10: =SUM(C10:N10) -> 165 | R10: 0700-0800 | S10: =SUM(C10:C13) -> 141 | T10: =SUM(D10:D13) -> 35 | U10: =SUM(E10:E13) -> 14 | V10: =SUM(F10:F13) -> 132 | W10: =SUM(G10:G13) -> 1 | X10: =SUM(H10:H13) -> 0 | Y10: =SUM(I10:I13) -> 4 | Z10: =SUM(J10:J13) -> 8 | ... AF10: =SUM(P10:P13) -> 1031
B11: 07.15 - 07.30 | C11: 42 | D11: 7 | E11: 2 | F11: 31 | G11: 0 | H11: 0 | I11: 1 | J11: 1 | K11: 1 | L11: 0 | M11: 180 | N11: 0 | O11: =SUM(C11:L11,N11) -> 85 | P11: =SUM(C11:N11) -> 265 | R11: 0800-0900 | S11: =SUM(C14:C17) -> 190 | T11: =SUM(D14:D17) -> 72 | U11: =SUM(E14:E17) -> 20 | V11: =SUM(F14:F17) -> 192 | W11: =SUM(G14:G17) -> 2 | X11: =SUM(H14:H17) -> 1 | Y11: =SUM(I14:I17) -> 16 | Z11: =SUM(J14:J17) -> 5 | ... AF11: =SUM(P14:P17) -> 1118
B12: 07.30 - 07.45 | C12: 40 | D12: 9 | E12: 4 | F12: 45 | G12: 1 | H12: 0 | I12: 1 | J12: 3 | K12: 0 | L12: 0 | M12: 205 | N12: 0 | O12: =SUM(C12:L12,N12) -> 103 | P12: =SUM(C12:N12) -> 308 | R12: 0900-1000 | S12: =SUM(C18:C21) -> 148 | T12: =SUM(D18:D21) -> 53 | U12: =SUM(E18:E21) -> 22 | V12: =SUM(F18:F21) -> 168 | W12: =SUM(G18:G21) -> 3 | X12: =SUM(H18:H21) -> 0 | Y12: =SUM(I18:I21) -> 12 | Z12: =SUM(J18:J21) -> 17 | ... AF12: =SUM(P18:P21) -> 1238
B13: 07.45 - 08.00 | C13: 41 | D13: 15 | E13: 6 | F13: 38 | G13: 0 | H13: 0 | I13: 1 | J13: 2 | K13: 0 | L13: 0 | M13: 190 | N13: 0 | O13: =SUM(C13:L13,N13) -> 103 | P13: =SUM(C13:N13) -> 293 | R13: 1000-1100 | S13: =SUM(C22:C25) -> 114 | T13: =SUM(D22:D25) -> 36 | U13: =SUM(E22:E25) -> 18 | V13: =SUM(F22:F25) -> 91 | W13: =SUM(G22:G25) -> 1 | X13: =SUM(H22:H25) -> 0 | Y13: =SUM(I22:I25) -> 12 | Z13: =SUM(J22:J25) -> 10 | ... AF13: =SUM(P22:P25) -> 977
B14: 08.00 - 08.15 | C14: 56 | D14: 19 | E14: 3 | F14: 54 | G14: 1 | H14: 0 | I14: 3 | J14: 2 | K14: 0 | L14: 0 | M14: 135 | N14: 0 | O14: =SUM(C14:L14,N14) -> 138 | P14: =SUM(C14:N14) -> 273 | R14: 1100-1200 | S14: =SUM(C26:C29) -> 164 | T14: =SUM(D26:D29) -> 57 | U14: =SUM(E26:E29) -> 29 | V14: =SUM(F26:F29) -> 107 | W14: =SUM(G26:G29) -> 0 | X14: =SUM(H26:H29) -> 0 | Y14: =SUM(I26:I29) -> 7 | Z14: =SUM(J26:J29) -> 17 | ... AF14: =SUM(P26:P29) -> 1032
B15: 08.15 - 08.30 | C15: 50 | D15: 25 | E15: 7 | F15: 45 | G15: 0 | H15: 0 | I15: 4 | J15: 1 | K15: 0 | L15: 0 | M15: 100 | N15: 0 | O15: =SUM(C15:L15,N15) -> 132 | P15: =SUM(C15:N15) -> 232 | R15: 1200-1300 | S15: =SUM(C30:C33) -> 189 | T15: =SUM(D30:D33) -> 71 | U15: =SUM(E30:E33) -> 25 | V15: =SUM(F30:F33) -> 89 | W15: =SUM(G30:G33) -> 0 | X15: =SUM(H30:H33) -> 1 | Y15: =SUM(I30:I33) -> 4 | Z15: =SUM(J30:J33) -> 10 | ... AF15: =SUM(P30:P33) -> 1010
B16: 08.30 - 08.45 | C16: 50 | D16: 20 | E16: 6 | F16: 52 | G16: 1 | H16: 0 | I16: 6 | J16: 1 | K16: 0 | L16: 0 | M16: 170 | N16: 0 | O16: =SUM(C16:L16,N16) -> 136 | P16: =SUM(C16:N16) -> 306 | R16: 1300-1400 | S16: =SUM(C34:C37) -> 196 | T16: =SUM(D34:D37) -> 45 | U16: =SUM(E34:E37) -> 25 | V16: =SUM(F34:F37) -> 70 | W16: =SUM(G34:G37) -> 0 | X16: =SUM(H34:H37) -> 0 | Y16: =SUM(I34:I37) -> 6 | Z16: =SUM(J34:J37) -> 8 | ... AF16: =SUM(P34:P37) -> 1091
B17: 08.45 - 9.00 | C17: 34 | D17: 8 | E17: 4 | F17: 41 | G17: 0 | H17: 1 | I17: 3 | J17: 1 | K17: 0 | L17: 0 | M17: 215 | N17: 0 | O17: =SUM(C17:L17,N17) -> 92 | P17: =SUM(C17:N17) -> 307 | R17: 1400-1500 | S17: =SUM(C38:C41) -> 189 | T17: =SUM(D38:D41) -> 50 | U17: =SUM(E38:E41) -> 26 | V17: =SUM(F38:F41) -> 83 | W17: =SUM(G38:G41) -> 0 | X17: =SUM(H38:H41) -> 0 | Y17: =SUM(I38:I41) -> 10 | Z17: =SUM(J38:J41) -> 5 | ... AF17: =SUM(P38:P41) -> 977
B18: 09.00 - 09.15 | C18: 46 | D18: 13 | E18: 5 | F18: 60 | G18: 0 | H18: 0 | I18: 5 | J18: 7 | K18: 1 | L18: 0 | M18: 190 | N18: 0 | O18: =SUM(C18:L18,N18) -> 137 | P18: =SUM(C18:N18) -> 327 | R18: 1500-1600 | S18: =SUM(C42:C45) -> 190 | T18: =SUM(D42:D45) -> 75 | U18: =SUM(E42:E45) -> 35 | V18: =SUM(F42:F45) -> 70 | W18: =SUM(G42:G45) -> 0 | X18: =SUM(H42:H45) -> 0 | Y18: =SUM(I42:I45) -> 16 | Z18: =SUM(J42:J45) -> 17 | ... AF18: =SUM(P42:P45) -> 1091
B19: 09.15 - 09.30 | C19: 32 | D19: 17 | E19: 7 | F19: 50 | G19: 1 | H19: 0 | I19: 3 | J19: 5 | K19: 1 | L19: 0 | M19: 220 | N19: 0 | O19: =SUM(C19:L19,N19) -> 116 | P19: =SUM(C19:N19) -> 336 | R19: 1600-1700 | S19: =SUM(C46:C49) -> 199 | T19: =SUM(D46:D49) -> 92 | U19: =SUM(E46:E49) -> 38 | V19: =SUM(F46:F49) -> 61 | W19: =SUM(G46:G49) -> 1 | X19: =SUM(H46:H49) -> 0 | Y19: =SUM(I46:I49) -> 11 | Z19: =SUM(J46:J49) -> 13 | ... AF19: =SUM(P46:P49) -> 1226
B20: 09.30 - 09.45 | C20: 27 | D20: 12 | E20: 6 | F20: 32 | G20: 1 | H20: 0 | I20: 1 | J20: 1 | K20: 0 | L20: 1 | M20: 240 | N20: 0 | O20: =SUM(C20:L20,N20) -> 81 | P20: =SUM(C20:N20) -> 321 | R20: 1700-1800 | S20: =SUM(C50:C53) -> 308 | T20: =SUM(D50:D53) -> 115 | U20: =SUM(E50:E53) -> 40 | V20: =SUM(F50:F53) -> 48 | W20: =SUM(G50:G53) -> 2 | X20: =SUM(H50:H53) -> 0 | Y20: =SUM(I50:I53) -> 8 | Z20: =SUM(J50:J53) -> 11 | ... AF20: =SUM(P50:P53) -> 1326
B21: 09.45 - 10.00 | C21: 43 | D21: 11 | E21: 4 | F21: 26 | G21: 1 | H21: 0 | I21: 3 | J21: 4 | K21: 2 | L21: 0 | M21: 160 | N21: 0 | O21: =SUM(C21:L21,N21) -> 94 | P21: =SUM(C21:N21) -> 254 | R21: 1800-1900 | S21: =SUM(C54:C57) -> 318 | T21: =SUM(D54:D57) -> 57 | U21: =SUM(E54:E57) -> 19 | V21: =SUM(F54:F57) -> 51 | W21: =SUM(G54:G57) -> 1 | X21: =SUM(H54:H57) -> 0 | Y21: =SUM(I54:I57) -> 5 | Z21: =SUM(J54:J57) -> 5 | ... AF21: =SUM(P54:P57) -> 1129
B22: 10.00 - 10.15 | C22: 29 | D22: 3 | E22: 5 | F22: 21 | G22: 0 | H22: 0 | I22: 1 | J22: 5 | K22: 1 | L22: 0 | M22: 185 | N22: 0 | O22: =SUM(C22:L22,N22) -> 65 | P22: =SUM(C22:N22) -> 250 | R22: AM Peak Hr | S22: =MAX(S10:S12) -> 190 | T22: =MAX(T10:T12) -> 72 | U22: =MAX(U10:U12) -> 22 | V22: =MAX(V10:V12) -> 192 | W22: =MAX(W10:W12) -> 3 | X22: =MAX(X10:X12) -> 1 | Y22: =MAX(Y10:Y12) -> 16 | Z22: =MAX(Z10:Z12) -> 17 | ... AF22: =MAX(AF10:AF12) -> 1238
B23: 10.15 - 10.30 | C23: 26 | D23: 15 | E23: 5 | F23: 22 | G23: 0 | H23: 0 | I23: 2 | J23: 3 | K23: 1 | L23: 1 | M23: 170 | N23: 0 | O23: =SUM(C23:L23,N23) -> 75 | P23: =SUM(C23:N23) -> 245 | R23: IP Peak Hr | S23: =MAX(S13:S18) -> 196 | T23: =MAX(T13:T18) -> 75 | U23: =MAX(U13:U18) -> 35 | V23: =MAX(V13:V18) -> 107 | W23: =MAX(W13:W18) -> 1 | X23: =MAX(X13:X18) -> 1 | Y23: =MAX(Y13:Y18) -> 16 | Z23: =MAX(Z13:Z18) -> 17 | ... AF23: =MAX(AF13:AF18) -> 1091
B24: 10.30 - 10.45 | C24: 33 | D24: 10 | E24: 6 | F24: 29 | G24: 0 | H24: 0 | I24: 4 | J24: 0 | K24: 1 | L24: 0 | M24: 160 | N24: 0 | O24: =SUM(C24:L24,N24) -> 83 | P24: =SUM(C24:N24) -> 243 | R24: PM Peak Hr | S24: =MAX(S19:S21) -> 318 | T24: =MAX(T19:T21) -> 115 | U24: =MAX(U19:U21) -> 40 | V24: =MAX(V19:V21) -> 61 | W24: =MAX(W19:W21) -> 2 | X24: =MAX(X19:X21) -> 0 | Y24: =MAX(Y19:Y21) -> 11 | Z24: =MAX(Z19:Z21) -> 13 | ... AF24: =MAX(AF19:AF21) -> 1326
B25: 10.45 - 11.00 | C25: 26 | D25: 8 | E25: 2 | F25: 19 | G25: 1 | H25: 0 | I25: 5 | J25: 2 | K25: 1 | L25: 0 | M25: 175 | N25: 0 | O25: =SUM(C25:L25,N25) -> 64 | P25: =SUM(C25:N25) -> 239 | R25: AM Period | S25: =SUM(S10:S12) -> 479 | T25: =SUM(T10:T12) -> 160 | U25: =SUM(U10:U12) -> 56 | V25: =SUM(V10:V12) -> 492 | W25: =SUM(W10:W12) -> 6 | X25: =SUM(X10:X12) -> 1 | Y25: =SUM(Y10:Y12) -> 32 | Z25: =SUM(Z10:Z12) -> 30 | ... AF25: =SUM(AF10:AF12) -> 3387
B26: 11.00 - 11.15 | C26: 34 | D26: 10 | E26: 11 | F26: 26 | G26: 0 | H26: 0 | I26: 0 | J26: 4 | K26: 3 | L26: 1 | M26: 150 | N26: 0 | O26: =SUM(C26:L26,N26) -> 89 | P26: =SUM(C26:N26) -> 239 | R26: IP Period | S26: =SUM(S13:S18) -> 1042 | T26: =SUM(T13:T18) -> 334 | U26: =SUM(U13:U18) -> 158 | V26: =SUM(V13:V18) -> 510 | W26: =SUM(W13:W18) -> 1 | X26: =SUM(X13:X18) -> 1 | Y26: =SUM(Y13:Y18) -> 55 | Z26: =SUM(Z13:Z18) -> 67 | ... AF26: =SUM(AF13:AF18) -> 6178
