Workbook

Sheet 19.8 Kayunga-Kangulumira
B1: Consultancy services for Preparation of Expressway Development Master Plan (EDMP) for Uganda
B2: MANUAL CLASSIFIED COUNT (MCC)
B3: ROAD NAME: | C3: MCC-C3-STN90-KAYUNGA-KANGULUMIRA ROAD
C5: Date | D5: 19.08.19 | F5: Location | G5: Kayunga | J5: Surveyor | K5: Comfort
C6: Dir. From | D6: KAYUNGA | F6: Dir. To | G6: KANGULUMIRA | J6: Supervisor | K6: Bella
B8: Time / Veh Type | R8: SUMMARY TRAFFIC VOLUMES
C9: 1. Car | D9: 2. Station Wagon | E9: 3. Pickups | F9: 4. Minibus, matatu | G9: 5. Medium bus | H9: 6. Large Bus | I9: 7. Light Truck | J9: 8. Medium Truck | K9: 9. Heavy truck | L9: 10. Truck Trailer | M9: 11. Motor cycles | N9: 12. Tractors | O9: Total Excl M/Cycles | P9: Total All | R9: Time | S9: 1. Car | T9: 2. Station Wagon | U9: 3. Pickups | V9: 4. Minibus, matatu | W9: 5. Medium bus | X9: 6. Large Bus | Y9: 7. Light Truck | Z9: 8. Medium Truck | AA9: 9. Heavy truck | AB9: 10. Truck Trailer | AC9: 11. Motorcycles | AD9: 12. Tractors, Graders | AE9: Total Excl M/ Cycles | AF9: Total All
B10: 07.00 - 07.15 | C10: 1 | D10: 0 | E10: 2 | F10: 3 | G10: 0 | H10: 0 | I10: 4 | J10: 0 | K10: 0 | L10: 0 | M10: 26 | N10: 0 | O10: =SUM(C10:L10,N10) -> 10 | P10: =SUM(C10:N10) -> 36 | R10: 0700-0800 | S10: =SUM(C10:C13) -> 18 | T10: =SUM(D10:D13) -> 0 | U10: =SUM(E10:E13) -> 13 | V10: =SUM(F10:F13) -> 20 | W10: =SUM(G10:G13) -> 1 | X10: =SUM(H10:H13) -> 0 | Y10: =SUM(I10:I13) -> 7 | Z10: =SUM(J10:J13) -> 0 | ... AF10: =SUM(P10:P13) -> 189
B11: 07.15 - 07.30 | C11: 3 | D11: 0 | E11: 4 | F11: 8 | G11: 0 | H11: 0 | I11: 1 | J11: 0 | K11: 0 | L11: 0 | M11: 28 | N11: 0 | O11: =SUM(C11:L11,N11) -> 16 | P11: =SUM(C11:N11) -> 44 | R11: 0800-0900 | S11: =SUM(C14:C17) -> 20 | T11: =SUM(D14:D17) -> 0 | U11: =SUM(E14:E17) -> 21 | V11: =SUM(F14:F17) -> 19 | W11: =SUM(G14:G17) -> 0 | X11: =SUM(H14:H17) -> 0 | Y11: =SUM(I14:I17) -> 6 | Z11: =SUM(J14:J17) -> 0 | ... AF11: =SUM(P14:P17) -> 222
B12: 07.30 - 07.45 | C12: 4 | D12: 0 | E12: 1 | F12: 7 | G12: 0 | H12: 0 | I12: 2 | J12: 0 | K12: 0 | L12: 0 | M12: 37 | N12: 0 | O12: =SUM(C12:L12,N12) -> 14 | P12: =SUM(C12:N12) -> 51 | R12: 0900-1000 | S12: =SUM(C18:C21) -> 23 | T12: =SUM(D18:D21) -> 0 | U12: =SUM(E18:E21) -> 21 | V12: =SUM(F18:F21) -> 16 | W12: =SUM(G18:G21) -> 1 | X12: =SUM(H18:H21) -> 0 | Y12: =SUM(I18:I21) -> 8 | Z12: =SUM(J18:J21) -> 0 | ... AF12: =SUM(P18:P21) -> 199
B13: 07.45 - 08.00 | C13: 10 | D13: 0 | E13: 6 | F13: 2 | G13: 1 | H13: 0 | I13: 0 | J13: 0 | K13: 0 | L13: 0 | M13: 39 | N13: 0 | O13: =SUM(C13:L13,N13) -> 19 | P13: =SUM(C13:N13) -> 58 | R13: 1000-1100 | S13: =SUM(C22:C25) -> 25 | T13: =SUM(D22:D25) -> 0 | U13: =SUM(E22:E25) -> 15 | V13: =SUM(F22:F25) -> 19 | W13: =SUM(G22:G25) -> 0 | X13: =SUM(H22:H25) -> 1 | Y13: =SUM(I22:I25) -> 9 | Z13: =SUM(J22:J25) -> 1 | ... AF13: =SUM(P22:P25) -> 195
B14: 08.00 - 08.15 | C14: 7 | D14: 0 | E14: 2 | F14: 5 | G14: 0 | H14: 0 | I14: 2 | J14: 0 | K14: 0 | L14: 0 | M14: 40 | N14: 0 | O14: =SUM(C14:L14,N14) -> 16 | P14: =SUM(C14:N14) -> 56 | R14: 1100-1200 | S14: =SUM(C26:C29) -> 22 | T14: =SUM(D26:D29) -> 0 | U14: =SUM(E26:E29) -> 24 | V14: =SUM(F26:F29) -> 20 | W14: =SUM(G26:G29) -> 3 | X14: =SUM(H26:H29) -> 1 | Y14: =SUM(I26:I29) -> 7 | Z14: =SUM(J26:J29) -> 1 | ... AF14: =SUM(P26:P29) -> 212
B15: 08.15 - 08.30 | C15: 6 | D15: 0 | E15: 7 | F15: 5 | G15: 0 | H15: 0 | I15: 0 | J15: 0 | K15: 0 | L15: 0 | M15: 37 | N15: 0 | O15: =SUM(C15:L15,N15) -> 18 | P15: =SUM(C15:N15) -> 55 | R15: 1200-1300 | S15: =SUM(C30:C33) -> 22 | T15: =SUM(D30:D33) -> 0 | U15: =SUM(E30:E33) -> 14 | V15: =SUM(F30:F33) -> 19 | W15: =SUM(G30:G33) -> 1 | X15: =SUM(H30:H33) -> 2 | Y15: =SUM(I30:I33) -> 11 | Z15: =SUM(J30:J33) -> 1 | ... AF15: =SUM(P30:P33) -> 171
B16: 08.30 - 08.45 | C16: 4 | D16: 0 | E16: 8 | F16: 7 | G16: 0 | H16: 0 | I16: 2 | J16: 0 | K16: 1 | L16: 0 | M16: 43 | N16: 0 | O16: =SUM(C16:L16,N16) -> 22 | P16: =SUM(C16:N16) -> 65 | R16: 1300-1400 | S16: =SUM(C34:C37) -> 12 | T16: =SUM(D34:D37) -> 0 | U16: =SUM(E34:E37) -> 12 | V16: =SUM(F34:F37) -> 17 | W16: =SUM(G34:G37) -> 1 | X16: =SUM(H34:H37) -> 0 | Y16: =SUM(I34:I37) -> 12 | Z16: =SUM(J34:J37) -> 3 | ... AF16: =SUM(P34:P37) -> 151
B17: 08.45 - 9.00 | C17: 3 | D17: 0 | E17: 4 | F17: 2 | G17: 0 | H17: 0 | I17: 2 | J17: 0 | K17: 0 | L17: 0 | M17: 35 | N17: 0 | O17: =SUM(C17:L17,N17) -> 11 | P17: =SUM(C17:N17) -> 46 | R17: 1400-1500 | S17: =SUM(C38:C41) -> 13 | T17: =SUM(D38:D41) -> 0 | U17: =SUM(E38:E41) -> 18 | V17: =SUM(F38:F41) -> 12 | W17: =SUM(G38:G41) -> 1 | X17: =SUM(H38:H41) -> 0 | Y17: =SUM(I38:I41) -> 12 | Z17: =SUM(J38:J41) -> 0 | ... AF17: =SUM(P38:P41) -> 159
B18: 09.00 - 09.15 | C18: 6 | D18: 0 | E18: 3 | F18: 6 | G18: 0 | H18: 0 | I18: 3 | J18: 0 | K18: 0 | L18: 0 | M18: 24 | N18: 0 | O18: =SUM(C18:L18,N18) -> 18 | P18: =SUM(C18:N18) -> 42 | R18: 1500-1600 | S18: =SUM(C42:C45) -> 18 | T18: =SUM(D42:D45) -> 0 | U18: =SUM(E42:E45) -> 16 | V18: =SUM(F42:F45) -> 16 | W18: =SUM(G42:G45) -> 1 | X18: =SUM(H42:H45) -> 0 | Y18: =SUM(I42:I45) -> 20 | Z18: =SUM(J42:J45) -> 1 | ... AF18: =SUM(P42:P45) -> 181
B19: 09.15 - 09.30 | C19: 4 | D19: 0 | E19: 7 | F19: 4 | G19: 1 | H19: 0 | I19: 3 | J19: 0 | K19: 2 | L19: 0 | M19: 37 | N19: 0 | O19: =SUM(C19:L19,N19) -> 21 | P19: =SUM(C19:N19) -> 58 | R19: 1600-1700 | S19: =SUM(C46:C49) -> 24 | T19: =SUM(D46:D49) -> 0 | U19: =SUM(E46:E49) -> 24 | V19: =SUM(F46:F49) -> 26 | W19: =SUM(G46:G49) -> 1 | X19: =SUM(H46:H49) -> 1 | Y19: =SUM(I46:I49) -> 16 | Z19: =SUM(J46:J49) -> 3 | ... AF19: =SUM(P46:P49) -> 197
B20: 09.30 - 09.45 | C20: 7 | D20: 0 | E20: 4 | F20: 2 | G20: 0 | H20: 0 | I20: 1 | J20: 0 | K20: 0 | L20: 0 | M20: 32 | N20: 0 | O20: =SUM(C20:L20,N20) -> 14 | P20: =SUM(C20:N20) -> 46 | R20: 1700-1800 | S20: =SUM(C50:C53) -> 24 | T20: =SUM(D50:D53) -> 0 | U20: =SUM(E50:E53) -> 24 | V20: =SUM(F50:F53) -> 23 | W20: =SUM(G50:G53) -> 2 | X20: =SUM(H50:H53) -> 3 | Y20: =SUM(I50:I53) -> 9 | Z20: =SUM(J50:J53) -> 3 | ... AF20: =SUM(P50:P53) -> 225
B21: 09.45 - 10.00 | C21: 6 | D21: 0 | E21: 7 | F21: 4 | G21: 0 | H21: 0 | I21: 1 | J21: 0 | K21: 2 | L21: 0 | M21: 33 | N21: 0 | O21: =SUM(C21:L21,N21) -> 20 | P21: =SUM(C21:N21) -> 53 | R21: 1800-1900 | S21: =SUM(C54:C57) -> 16 | T21: =SUM(D54:D57) -> 0 | U21: =SUM(E54:E57) -> 22 | V21: =SUM(F54:F57) -> 15 | W21: =SUM(G54:G57) -> 0 | X21: =SUM(H54:H57) -> 3 | Y21: =SUM(I54:I57) -> 15 | Z21: =SUM(J54:J57) -> 3 | ... AF21: =SUM(P54:P57) -> 203
B22: 10.00 - 10.15 | C22: 10 | D22: 0 | E22: 7 | F22: 3 | G22: 0 | H22: 0 | I22: 1 | J22: 0 | K22: 0 | L22: 0 | M22: 30 | N22: 0 | O22: =SUM(C22:L22,N22) -> 21 | P22: =SUM(C22:N22) -> 51 | R22: AM Peak Hr | S22: =MAX(S10:S12) -> 23 | T22: =MAX(T10:T12) -> 0 | U22: =MAX(U10:U12) -> 21 | V22: =MAX(V10:V12) -> 20 | W22: =MAX(W10:W12) -> 1 | X22: =MAX(X10:X12) -> 0 | Y22: =MAX(Y10:Y12) -> 8 | Z22: =MAX(Z10:Z12) -> 0 | ... AF22: =MAX(AF10:AF12) -> 222
B23: 10.15 - 10.30 | C23: 5 | D23: 0 | E23: 3 | F23: 6 | G23: 0 | H23: 0 | I23: 1 | J23: 0 | K23: 0 | L23: 0 | M23: 37 | N23: 0 | O23: =SUM(C23:L23,N23) -> 15 | P23: =SUM(C23:N23) -> 52 | R23: IP Peak Hr | S23: =MAX(S13:S18) -> 25 | T23: =MAX(T13:T18) -> 0 | U23: =MAX(U13:U18) -> 24 | V23: =MAX(V13:V18) -> 20 | W23: =MAX(W13:W18) -> 3 | X23: =MAX(X13:X18) -> 2 | Y23: =MAX(Y13:Y18) -> 20 | Z23: =MAX(Z13:Z18) -> 3 | ... AF23: =MAX(AF13:AF18) -> 212
B24: 10.30 - 10.45 | C24: 6 | D24: 0 | E24: 2 | F24: 4 | G24: 0 | H24: 1 | I24: 6 | J24: 0 | K24: 0 | L24: 0 | M24: 22 | N24: 0 | O24: =SUM(C24:L24,N24) -> 19 | P24: =SUM(C24:N24) -> 41 | R24: PM Peak Hr | S24: =MAX(S19:S21) -> 24 | T24: =MAX(T19:T21) -> 0 | U24: =MAX(U19:U21) -> 24 | V24: =MAX(V19:V21) -> 26 | W24: =MAX(W19:W21) -> 2 | X24: =MAX(X19:X21) -> 3 | Y24: =MAX(Y19:Y21) -> 16 | Z24: =MAX(Z19:Z21) -> 3 | ... AF24: =MAX(AF19:AF21) -> 225
B25: 10.45 - 11.00 | C25: 4 | D25: 0 | E25: 3 | F25: 6 | G25: 0 | H25: 0 | I25: 1 | J25: 1 | K25: 0 | L25: 0 | M25: 36 | N25: 0 | O25: =SUM(C25:L25,N25) -> 15 | P25: =SUM(C25:N25) -> 51 | R25: AM Period | S25: =SUM(S10:S12) -> 61 | T25: =SUM(T10:T12) -> 0 | U25: =SUM(U10:U12) -> 55 | V25: =SUM(V10:V12) -> 55 | W25: =SUM(W10:W12) -> 2 | X25: =SUM(X10:X12) -> 0 | Y25: =SUM(Y10:Y12) -> 21 | Z25: =SUM(Z10:Z12) -> 0 | ... AF25: =SUM(AF10:AF12) -> 610
B26: 11.00 - 11.15 | C26: 9 | D26: 0 | E26: 5 | F26: 6 | G26: 2 | H26: 1 | I26: 2 | J26: 0 | K26: 0 | L26: 0 | M26: 40 | N26: 0 | O26: =SUM(C26:L26,N26) -> 25 | P26: =SUM(C26:N26) -> 65 | R26: IP Period | S26: =SUM(S13:S18) -> 112 | T26: =SUM(T13:T18) -> 0 | U26: =SUM(U13:U18) -> 99 | V26: =SUM(V13:V18) -> 103 | W26: =SUM(W13:W18) -> 7 | X26: =SUM(X13:X18) -> 4 | Y26: =SUM(Y13:Y18) -> 71 | Z26: =SUM(Z13:Z18) -> 7 | ... AF26: =SUM(AF13:AF18) -> 1069
B27: 11.15 - 11.30 | C27: 4 | D27: 0 | E27: 8 | F27: 4 | G27: 1 | H27: 0 | I27: 1 | J27: 1 | K27: 0 | L27: 0 | M27: 31 | N27: 0 | O27: =SUM(C27:L27,N27) -> 19 | P27: =SUM(C27:N27) -> 50 | R27: PM Period | S27: =SUM(S19:S21) -> 64 | T27: =SUM(T19:T21) -> 0 | U27: =SUM(U19:U21) -> 70 | V27: =SUM(V19:V21) -> 64 | W27: =SUM(W19:W21) -> 3 | X27: =SUM(X19:X21) -> 7 | Y27: =SUM(Y19:Y21) -> 40 | Z27: =SUM(Z19:Z21) -> 9 | ... AF27: =SUM(AF19:AF21) -> 625
B28: 11.30 - 11.45 | C28: 6 | D28: 0 | E28: 7 | F28: 3 | G28: 0 | H28: 0 | I28: 2 | J28: 0 | K28: 0 | L28: 0 | M28: 36 | N28: 0 | O28: =SUM(C28:L28,N28) -> 18 | P28: =SUM(C28:N28) -> 54 | R28: 12 Hours | S28: =SUM(S10:S21) -> 237 | T28: =SUM(T10:T21) -> 0 | U28: =SUM(U10:U21) -> 224 | V28: =SUM(V10:V21) -> 222 | W28: =SUM(W10:W21) -> 12 | X28: =SUM(X10:X21) -> 11 | Y28: =SUM(Y10:Y21) -> 132 | Z28: =SUM(Z10:Z21) -> 16 | ... AF28: =SUM(AF10:AF21) -> 2304
B29: 11.45 - 12.00 | C29: 3 | D29: 0 | E29: 4 | F29: 7 | G29: 0 | H29: 0 | I29: 2 | J29: 0 | K29: 0 | L29: 0 | M29: 27 | N29: 0 | O29: =SUM(C29:L29,N29) -> 16 | P29: =SUM(C29:N29) -> 43
B30: 12.00 - 12.15 | C30: 6 | D30: 0 | E30: 5 | F30: 6 | G30: 0 | H30: 0 | I30: 3 | J30: 1 | K30: 1 | L30: 1 | M30: 28 | N30: 0 | O30: =SUM(C30:L30,N30) -> 23 | P30: =SUM(C30:N30) -> 51
B31: 12.15 - 12.30 | C31: 5 | D31: 0 | E31: 1 | F31: 7 | G31: 1 | H31: 2 | I31: 2 | J31: 0 | K31: 0 | L31: 0 | M31: 20 | N31: 0 | O31: =SUM(C31:L31,N31) -> 18 | P31: =SUM(C31:N31) -> 38
B32: 12.30 - 12.45 | C32: 6 | D32: 0 | E32: 1 | F32: 1 | G32: 0 | H32: 0 | I32: 5 | J32: 0 | K32: 0 | L32: 0 | M32: 32 | N32: 0 | O32: =SUM(C32:L32,N32) -> 13 | P32: =SUM(C32:N32) -> 45
B33: 12.45 - 13.00 | C33: 5 | D33: 0 | E33: 7 | F33: 5 | G33: 0 | H33: 0 | I33: 1 | J33: 0 | K33: 0 | L33: 1 | M33: 18 | N33: 0 | O33: =SUM(C33:L33,N33) -> 19 | P33: =SUM(C33:N33) -> 37
B34: 13.00 - 13.15 | C34: 1 | D34: 0 | E34: 0 | F34: 3 | G34: 0 | H34: 0 | I34: 6 | J34: 0 | K34: 1 | L34: 0 | M34: 21 | N34: 0 | O34: =SUM(C34:L34,N34) -> 11 | P34: =SUM(C34:N34) -> 32
B35: 13.15 - 13.30 | C35: 6 | D35: 0 | E35: 3 | F35: 5 | G35: 0 | H35: 0 | I35: 0 | J35: 1 | K35: 0 | L35: 0 | M35: 18 | N35: 0 | O35: =SUM(C35:L35,N35) -> 15 | P35: =SUM(C35:N35) -> 33
B36: 13.30 - 13.45 | C36: 1 | D36: 0 | E36: 3 | F36: 3 | G36: 1 | H36: 0 | I36: 3 | J36: 0 | K36: 0 | L36: 0 | M36: 22 | N36: 0 | O36: =SUM(C36:L36,N36) -> 11 | P36: =SUM(C36:N36) -> 33
B37: 13.45 - 14.00 | C37: 4 | D37: 0 | E37: 6 | F37: 6 | G37: 0 | H37: 0 | I37: 3 | J37: 2 | K37: 0 | L37: 1 | M37: 31 | N37: 0 | O37: =SUM(C37:L37,N37) -> 22 | P37: =SUM(C37:N37) -> 53
B38: 14.00 - 14.15 | C38: 6 | D38: 0 | E38: 5 | F38: 3 | G38: 0 | H38: 0 | I38: 3 | J38: 0 | K38: 0 | L38: 0 | M38: 26 | N38: 0 | O38: =SUM(C38:L38,N38) -> 17 | P38: =SUM(C38:N38) -> 43
B39: 14.15 - 14.30 | C39: 2 | D39: 0 | E39: 5 | F39: 3 | G39: 0 | H39: 0 | I39: 2 | J39: 0 | K39: 1 | L39: 0 | M39: 31 | N39: 0 | O39: =SUM(C39:L39,N39) -> 13 | P39: =SUM(C39:N39) -> 44
B40: 14.30 - 14.45 | C40: 1 | D40: 0 | E40: 5 | F40: 2 | G40: 0 | H40: 0 | I40: 4 | J40: 0 | K40: 0 | L40: 0 | M40: 21 | N40: 0 | O40: =SUM(C40:L40,N40) -> 12 | P40: =SUM(C40:N40) -> 33
... B57: 18.45 - 19.00 | C57: 2 | D57: 0 | E57: 5 | F57: 2 | G57: 0 | H57: 1 | I57: 5 | J57: 1 | K57: 2 | L57: 0 | M57: 28 | N57: 0 | O57: =SUM(C57:L57,N57) -> 18 | P57: =SUM(C57:N57) -> 46
B58: Totals | C58: =SUM(C10:C57) -> 237 | D58: =SUM(D10:D57) -> 0 | E58: =SUM(E10:E57) -> 224 | F58: =SUM(F10:F57) -> 222 | G58: =SUM(G10:G57) -> 12 | H58: =SUM(H10:H57) -> 11 | I58: =SUM(I10:I57) -> 132 | J58: =SUM(J10:J57) -> 16 | ... P58: =SUM(P10:P57) -> 2304
...

Sheet 19.8 Kangulumira-Kayunga
B1: Consultancy services for Preparation of Expressway Development Master Plan (EDMP) for Uganda
B2: MANUAL CLASSIFIED COUNT (MCC)
B3: ROAD NAME: | C3: ='20.8 Kayunga-Kangulumira'!C3:G3 -> MCC-C3-STN90-KAYUNGA-KANGULUMIRA ROAD
C5: Date | D5: 19.08.19 | F5: Location | G5: ='25.8 Kayunga-Kangulumira'!G5:H5 -> Kayunga | J5: Surveyor | K5: ='25.8 Kayunga-Kangulumira'!K5:L5 -> Comfort
C6: Dir. From | D6: KANGULUMIRA | F6: Dir. To | G6: KAYUNGA | J6: Supervisor | K6: ='25.8 Kayunga-Kangulumira'!K6:L6 -> Bella
B8: Time / Veh Type | R8: SUMMARY TRAFFIC VOLUMES
C9: 1. Car | D9: 2. Station Wagon | E9: 3. Pickups | F9: 4. Minibus, matatu | G9: 5. Medium bus | H9: 6. Large Bus | I9: 7. Light Truck | J9: 8. Medium Truck | K9: 9. Heavy truck | L9: 10. Truck Trailer | M9: 11. Motor cycles | N9: 12. Tractors | O9: Total Excl M/Cycles | P9: Total All | R9: Time | S9: 1. Car | T9: 2. Station Wagon | U9: 3. Pickups | V9: 4. Minibus, matatu | W9: 5. Medium bus | X9: 6. Large Bus | Y9: 7. Light Truck | Z9: 8. Medium Truck | AA9: 9. Heavy truck | AB9: 10. Truck Trailer | AC9: 11. Motorcycles | AD9: 12. Tractors, Graders | AE9: Total Excl M/ Cycles | AF9: Total All
B10: 07.00 - 07.15 | C10: 4 | D10: 0 | E10: 3 | F10: 4 | G10: 0 | H10: 0 | I10: 3 | J10: 2 | K10: 1 | L10: 0 | M10: 8 | N10: 0 | O10: =SUM(C10:L10,N10) -> 17 | P10: =SUM(C10:N10) -> 25 | R10: 0700-0800 | S10: =SUM(C10:C13) -> 18 | T10: =SUM(D10:D13) -> 0 | U10: =SUM(E10:E13) -> 10 | V10: =SUM(F10:F13) -> 15 | W10: =SUM(G10:G13) -> 2 | X10: =SUM(H10:H13) -> 1 | Y10: =SUM(I10:I13) -> 9 | Z10: =SUM(J10:J13) -> 3 | ... AF10: =SUM(P10:P13) -> 111
B11: 07.15 - 07.30 | C11: 3 | D11: 0 | E11: 2 | F11: 3 | G11: 0 | H11: 0 | I11: 1 | J11: 0 | K11: 0 | L11: 0 | M11: 7 | N11: 0 | O11: =SUM(C11:L11,N11) -> 9 | P11: =SUM(C11:N11) -> 16 | R11: 0800-0900 | S11: =SUM(C14:C17) -> 23 | T11: =SUM(D14:D17) -> 0 | U11: =SUM(E14:E17) -> 10 | V11: =SUM(F14:F17) -> 13 | W11: =SUM(G14:G17) -> 0 | X11: =SUM(H14:H17) -> 0 | Y11: =SUM(I14:I17) -> 7 | Z11: =SUM(J14:J17) -> 4 | ... AF11: =SUM(P14:P17) -> 158
B12: 07.30 - 07.45 | C12: 7 | D12: 0 | E12: 4 | F12: 5 | G12: 1 | H12: 0 | I12: 1 | J12: 0 | K12: 0 | L12: 0 | M12: 15 | N12: 0 | O12: =SUM(C12:L12,N12) -> 18 | P12: =SUM(C12:N12) -> 33 | R12: 0900-1000 | S12: =SUM(C18:C21) -> 19 | T12: =SUM(D18:D21) -> 0 | U12: =SUM(E18:E21) -> 16 | V12: =SUM(F18:F21) -> 15 | W12: =SUM(G18:G21) -> 1 | X12: =SUM(H18:H21) -> 0 | Y12: =SUM(I18:I21) -> 6 | Z12: =SUM(J18:J21) -> 1 | ... AF12: =SUM(P18:P21) -> 171
B13: 07.45 - 08.00 | C13: 4 | D13: 0 | E13: 1 | F13: 3 | G13: 1 | H13: 1 | I13: 4 | J13: 1 | K13: 0 | L13: 0 | M13: 22 | N13: 0 | O13: =SUM(C13:L13,N13) -> 15 | P13: =SUM(C13:N13) -> 37 | R13: 1000-1100 | S13: =SUM(C22:C25) -> 18 | T13: =SUM(D22:D25) -> 0 | U13: =SUM(E22:E25) -> 8 | V13: =SUM(F22:F25) -> 17 | W13: =SUM(G22:G25) -> 0 | X13: =SUM(H22:H25) -> 0 | Y13: =SUM(I22:I25) -> 10 | Z13: =SUM(J22:J25) -> 2 | ... AF13: =SUM(P22:P25) -> 168
B14: 08.00 - 08.15 | C14: 5 | D14: 0 | E14: 1 | F14: 4 | G14: 0 | H14: 0 | I14: 1 | J14: 1 | K14: 0 | L14: 0 | M14: 28 | N14: 0 | O14: =SUM(C14:L14,N14) -> 12 | P14: =SUM(C14:N14) -> 40 | R14: 1100-1200 | S14: =SUM(C26:C29) -> 21 | T14: =SUM(D26:D29) -> 0 | U14: =SUM(E26:E29) -> 21 | V14: =SUM(F26:F29) -> 19 | W14: =SUM(G26:G29) -> 2 | X14: =SUM(H26:H29) -> 1 | Y14: =SUM(I26:I29) -> 9 | Z14: =SUM(J26:J29) -> 1 | ... AF14: =SUM(P26:P29) -> 192
B15: 08.15 - 08.30 | C15: 7 | D15: 0 | E15: 4 | F15: 3 | G15: 0 | H15: 0 | I15: 2 | J15: 0 | K15: 0 | L15: 0 | M15: 23 | N15: 0 | O15: =SUM(C15:L15,N15) -> 16 | P15: =SUM(C15:N15) -> 39 | R15: 1200-1300 | S15: =SUM(C30:C33) -> 23 | T15: =SUM(D30:D33) -> 0 | U15: =SUM(E30:E33) -> 12 | V15: =SUM(F30:F33) -> 15 | W15: =SUM(G30:G33) -> 0 | X15: =SUM(H30:H33) -> 1 | Y15: =SUM(I30:I33) -> 13 | Z15: =SUM(J30:J33) -> 1 | ... AF15: =SUM(P30:P33) -> 186
B16: 08.30 - 08.45 | C16: 5 | D16: 0 | E16: 3 | F16: 4 | G16: 0 | H16: 0 | I16: 3 | J16: 2 | K16: 0 | L16: 1 | M16: 28 | N16: 0 | O16: =SUM(C16:L16,N16) -> 18 | P16: =SUM(C16:N16) -> 46 | R16: 1300-1400 | S16: =SUM(C34:C37) -> 24 | T16: =SUM(D34:D37) -> 0 | U16: =SUM(E34:E37) -> 9 | V16: =SUM(F34:F37) -> 18 | W16: =SUM(G34:G37) -> 0 | X16: =SUM(H34:H37) -> 1 | Y16: =SUM(I34:I37) -> 15 | Z16: =SUM(J34:J37) -> 3 | ... AF16: =SUM(P34:P37) -> 177
B17: 08.45 - 9.00 | C17: 6 | D17: 0 | E17: 2 | F17: 2 | G17: 0 | H17: 0 | I17: 1 | J17: 1 | K17: 0 | L17: 0 | M17: 21 | N17: 0 | O17: =SUM(C17:L17,N17) -> 12 | P17: =SUM(C17:N17) -> 33 | R17: 1400-1500 | S17: =SUM(C38:C41) -> 27 | T17: =SUM(D38:D41) -> 0 | U17: =SUM(E38:E41) -> 16 | V17: =SUM(F38:F41) -> 15 | W17: =SUM(G38:G41) -> 2 | X17: =SUM(H38:H41) -> 0 | Y17: =SUM(I38:I41) -> 13 | Z17: =SUM(J38:J41) -> 1 | ... AF17: =SUM(P38:P41) -> 180
B18: 09.00 - 09.15 | C18: 7 | D18: 0 | E18: 3 | F18: 6 | G18: 0 | H18: 0 | I18: 1 | J18: 1 | K18: 0 | L18: 0 | M18: 36 | N18: 0 | O18: =SUM(C18:L18,N18) -> 18 | P18: =SUM(C18:N18) -> 54 | R18: 1500-1600 | S18: =SUM(C42:C45) -> 24 | T18: =SUM(D42:D45) -> 0 | U18: =SUM(E42:E45) -> 12 | V18: =SUM(F42:F45) -> 17 | W18: =SUM(G42:G45) -> 1 | X18: =SUM(H42:H45) -> 0 | Y18: =SUM(I42:I45) -> 12 | Z18: =SUM(J42:J45) -> 1 | ... AF18: =SUM(P42:P45) -> 170
B19: 09.15 - 09.30 | C19: 3 | D19: 0 | E19: 5 | F19: 3 | G19: 0 | H19: 0 | I19: 2 | J19: 0 | K19: 0 | L19: 1 | M19: 23 | N19: 0 | O19: =SUM(C19:L19,N19) -> 14 | P19: =SUM(C19:N19) -> 37 | R19: 1600-1700 | S19: =SUM(C46:C49) -> 23 | T19: =SUM(D46:D49) -> 0 | U19: =SUM(E46:E49) -> 12 | V19: =SUM(F46:F49) -> 15 | W19: =SUM(G46:G49) -> 0 | X19: =SUM(H46:H49) -> 0 | Y19: =SUM(I46:I49) -> 15 | Z19: =SUM(J46:J49) -> 1 | ... AF19: =SUM(P46:P49) -> 171
B20: 09.30 - 09.45 | C20: 4 | D20: 0 | E20: 5 | F20: 2 | G20: 1 | H20: 0 | I20: 3 | J20: 0 | K20: 0 | L20: 0 | M20: 24 | N20: 0 | O20: =SUM(C20:L20,N20) -> 15 | P20: =SUM(C20:N20) -> 39 | R20: 1700-1800 | S20: =SUM(C50:C53) -> 23 | T20: =SUM(D50:D53) -> 0 | U20: =SUM(E50:E53) -> 26 | V20: =SUM(F50:F53) -> 14 | W20: =SUM(G50:G53) -> 0 | X20: =SUM(H50:H53) -> 0 | Y20: =SUM(I50:I53) -> 13 | Z20: =SUM(J50:J53) -> 3 | ... AF20: =SUM(P50:P53) -> 208
B21: 09.45 - 10.00 | C21: 5 | D21: 0 | E21: 3 | F21: 4 | G21: 0 | H21: 0 | I21: 0 | J21: 0 | K21: 0 | L21: 1 | M21: 28 | N21: 0 | O21: =SUM(C21:L21,N21) -> 13 | P21: =SUM(C21:N21) -> 41 | R21: 1800-1900 | S21: =SUM(C54:C57) -> 27 | T21: =SUM(D54:D57) -> 0 | U21: =SUM(E54:E57) -> 23 | V21: =SUM(F54:F57) -> 22 | W21: =SUM(G54:G57) -> 1 | X21: =SUM(H54:H57) -> 0 | Y21: =SUM(I54:I57) -> 23 | Z21: =SUM(J54:J57) -> 1 | ... AF21: =SUM(P54:P57) -> 229
B22: 10.00 - 10.15 | C22: 4 | D22: 0 | E22: 1 | F22: 3 | G22: 0 | H22: 0 | I22: 2 | J22: 0 | K22: 1 | L22: 1 | M22: 20 | N22: 0 | O22: =SUM(C22:L22,N22) -> 12 | P22: =SUM(C22:N22) -> 32 | R22: AM Peak Hr | S22: =MAX(S10:S12) -> 23 | T22: =MAX(T10:T12) -> 0 | U22: =MAX(U10:U12) -> 16 | V22: =MAX(V10:V12) -> 15 | W22: =MAX(W10:W12) -> 2 | X22: =MAX(X10:X12) -> 1 | Y22: =MAX(Y10:Y12) -> 9 | Z22: =MAX(Z10:Z12) -> 4 | ... AF22: =MAX(AF10:AF12) -> 171
B23: 10.15 - 10.30 | C23: 3 | D23: 0 | E23: 1 | F23: 6 | G23: 0 | H23: 0 | I23: 3 | J23: 0 | K23: 1 | L23: 0 | M23: 26 | N23: 0 | O23: =SUM(C23:L23,N23) -> 14 | P23: =SUM(C23:N23) -> 40 | R23: IP Peak Hr | S23: =MAX(S13:S18) -> 27 | T23: =MAX(T13:T18) -> 0 | U23: =MAX(U13:U18) -> 21 | V23: =MAX(V13:V18) -> 19 | W23: =MAX(W13:W18) -> 2 | X23: =MAX(X13:X18) -> 1 | Y23: =MAX(Y13:Y18) -> 15 | Z23: =MAX(Z13:Z18) -> 3 | ... AF23: =MAX(AF13:AF18) -> 192
B24: 10.30 - 10.45 | C24: 5 | D24: 0 | E24: 3 | F24: 3 | G24: 0 | H24: 0 | I24: 2 | J24: 1 | K24: 0 | L24: 0 | M24: 35 | N24: 0 | O24: =SUM(C24:L24,N24) -> 14 | P24: =SUM(C24:N24) -> 49 | R24: PM Peak Hr | S24: =MAX(S19:S21) -> 27 | T24: =MAX(T19:T21) -> 0 | U24: =MAX(U19:U21) -> 26 | V24: =MAX(V19:V21) -> 22 | W24: =MAX(W19:W21) -> 1 | X24: =MAX(X19:X21) -> 0 | Y24: =MAX(Y19:Y21) -> 23 | Z24: =MAX(Z19:Z21) -> 3 | ... AF24: =MAX(AF19:AF21) -> 229
B25: 10.45 - 11.00 | C25: 6 | D25: 0 | E25: 3 | F25: 5 | G25: 0 | H25: 0 | I25: 3 | J25: 1 | K25: 0 | L25: 1 | M25: 28 | N25: 0 | O25: =SUM(C25:L25,N25) -> 19 | P25: =SUM(C25:N25) -> 47 | R25: AM Period | S25: =SUM(S10:S12) -> 60 | T25: =SUM(T10:T12) -> 0 | U25: =SUM(U10:U12) -> 36 | V25: =SUM(V10:V12) -> 43 | W25: =SUM(W10:W12) -> 3 | X25: =SUM(X10:X12) -> 1 | Y25: =SUM(Y10:Y12) -> 22 | Z25: =SUM(Z10:Z12) -> 8 | ... AF25: =SUM(AF10:AF12) -> 440
B26: 11.00 - 11.15 | C26: 7 | D26: 0 | E26: 5 | F26: 6 | G26: 1 | H26: 0 | I26: 2 | J26: 0 | K26: 0 | L26: 0 | M26: 27 | N26: 0 | O26: =SUM(C26:L26,N26) -> 21 | P26: =SUM(C26:N26) -> 48 | R26: IP Period | S26: =SUM(S13:S18) -> 137 | T26: =SUM(T13:T18) -> 0 | U26: =SUM(U13:U18) -> 78 | V26: =SUM(V13:V18) -> 101 | W26: =SUM(W13:W18) -> 5 | X26: =SUM(X13:X18) -> 3 | Y26: =SUM(Y13:Y18) -> 72 | Z26: =SUM(Z13:Z18) -> 9 | ... AF26: =SUM(AF13:AF18) -> 1073
B27: 11.15 - 11.30 | C27: 7 | D27: 0 | E27: 4 | F27: 3 | G27: 0 | H27: 0 | I27: 3 | J27: 0 | K27: 1 | L27: 0 | M27: 29 | N27: 0 | O27: =SUM(C27:L27,N27) -> 18 | P27: =SUM(C27:N27) -> 47 | R27: PM Period | S27: =SUM(S19:S21) -> 73 | T27: =SUM(T19:T21) -> 0 | U27: =SUM(U19:U21) -> 61 | V27: =SUM(V19:V21) -> 51 | W27: =SUM(W19:W21) -> 1 | X27: =SUM(X19:X21) -> 0 | Y27: =SUM(Y19:Y21) -> 51 | Z27: =SUM(Z19:Z21) -> 5 | ... AF27: =SUM(AF19:AF21) -> 608
B28: 11.30 - 11.45 | C28: 6 | D28: 0 | E28: 10 | F28: 5 | G28: 0 | H28: 1 | I28: 3 | J28: 1 | K28: 0 | L28: 1 | M28: 34 | N28: 0 | O28: =SUM(C28:L28,N28) -> 27 | P28: =SUM(C28:N28) -> 61 | R28: 12 Hours | S28: =SUM(S10:S21) -> 270 | T28: =SUM(T10:T21) -> 0 | U28: =SUM(U10:U21) -> 175 | V28: =SUM(V10:V21) -> 195 | W28: =SUM(W10:W21) -> 9 | X28: =SUM(X10:X21) -> 4 | Y28: =SUM(Y10:Y21) -> 145 | Z28: =SUM(Z10:Z21) -> 22 | ... AF28: =SUM(AF10:AF21) -> 2121
B29: 11.45 - 12.00 | C29: 1 | D29: 0 | E29: 2 | F29: 5 | G29: 1 | H29: 0 | I29: 1 | J29: 0 | K29: 0 | L29: 0 | M29: 26 | N29: 0 | O29: =SUM(C29:L29,N29) -> 10 | P29: =SUM(C29:N29) -> 36
B30: 12.00 - 12.15 | C30: 4 | D30: 0 | E30: 2 | F30: 4 | G30: 0 | H30: 0 | I30: 6 | J30: 0 | K30: 0 | L30: 1 | M30: 28 | N30: 0 | O30: =SUM(C30:L30,N30) -> 17 | P30: =SUM(C30:N30) -> 45
B31: 12.15 - 12.30 | C31: 6 | D31: 0 | E31: 3 | F31: 3 | G31: 0 | H31: 1 | I31: 3 | J31: 1 | K31: 0 | L31: 0 | M31: 30 | N31: 0 | O31: =SUM(C31:L31,N31) -> 17 | P31: =SUM(C31:N31) -> 47
B32: 12.30 - 12.45 | C32: 3 | D32: 0 | E32: 3 | F32: 6 | G32: 0 | H32: 0 | I32: 1 | J32: 0 | K32: 1 | L32: 0 | M32: 31 | N32: 0 | O32: =SUM(C32:L32,N32) -> 14 | P32: =SUM(C32:N32) -> 45
B33: 12.45 - 13.00 | C33: 10 | D33: 0 | E33: 4 | F33: 2 | G33: 0 | H33: 0 | I33: 3 | J33: 0 | K33: 1 | L33: 0 | M33: 29 | N33: 0 | O33: =SUM(C33:L33,N33) -> 20 | P33: =SUM(C33:N33) -> 49
B34: 13.00 - 13.15 | C34: 3 | D34: 0 | E34: 1 | F34: 5 | G34: 0 | H34: 0 | I34: 3 | J34: 0 | K34: 1 | L34: 0 | M34: 28 | N34: 0 | O34: =SUM(C34:L34,N34) -> 13 | P34: =SUM(C34:N34) -> 41
B35: 13.15 - 13.30 | C35: 4 | D35: 0 | E35: 4 | F35: 2 | G35: 0 | H35: 0 | I35: 3 | J35: 1 | K35: 0 | L35: 0 | M35: 25 | N35: 0 | O35: =SUM(C35:L35,N35) -> 14 | P35: =SUM(C35:N35) -> 39
B36: 13.30 - 13.45 | C36: 9 | D36: 0 | E36: 4 | F36: 6 | G36: 0 | H36: 0 | I36: 4 | J36: 0 | K36: 0 | L36: 0 | M36: 27 | N36: 0 | O36: =SUM(C36:L36,N36) -> 23 | P36: =SUM(C36:N36) -> 50
B37: 13.45 - 14.00 | C37: 8 | D37: 0 | E37: 0 | F37: 5 | G37: 0 | H37: 1 | I37: 5 | J37: 2 | K37: 0 | L37: 0 | M37: 26 | N37: 0 | O37: =SUM(C37:L37,N37) -> 21 | P37: =SUM(C37:N37) -> 47
B38: 14.00 - 14.15 | C38: 5 | D38: 0 | E38: 3 | F38: 3 | G38: 0 | H38: 0 | I38: 3 | J38: 0 | K38: 1 | L38: 0 | M38: 33 | N38: 0 | O38: =SUM(C38:L38,N38) -> 15 | P38: =SUM(C38:N38) -> 48
B39: 14.15 - 14.30 | C39: 6 | D39: 0 | E39: 8 | F39: 4 | G39: 1 | H39: 0 | I39: 3 | J39: 1 | K39: 0 | L39: 0 | M39: 18 | N39: 0 | O39: =SUM(C39:L39,N39) -> 23 | P39: =SUM(C39:N39) -> 41
B40: 14.30 - 14.45 | C40: 12 | D40: 0 | E40: 1 | F40: 5 | G40: 0 | H40: 0 | I40: 4 | J40: 0 | K40: 0 | L40: 0 | M40: 36 | N40: 0 | O40: =SUM(C40:L40,N40) -> 22 | P40: =SUM(C40:N40) -> 58
... B57: 18.45 - 19.00 | C57: 7 | D57: 0 | E57: 7 | F57: 6 | G57: 0 | H57: 0 | I57: 7 | J57: 1 | K57: 0 | L57: 0 | M57: 23 | N57: 0 | O57: =SUM(C57:L57,N57) -> 28 | P57: =SUM(C57:N57) -> 51
B58: Totals | C58: =SUM(C10:C57) -> 270 | D58: =SUM(D10:D57) -> 0 | E58: =SUM(E10:E57) -> 175 | F58: =SUM(F10:F57) -> 195 | G58: =SUM(G10:G57) -> 9 | H58: =SUM(H10:H57) -> 4 | I58: =SUM(I10:I57) -> 145 | J58: =SUM(J10:J57) -> 22 | ... P58: =SUM(P10:P57) -> 2121
...

Sheet 20.8 Kayunga-Kangulumira
B1: Consultancy services for Preparation of Expressway Development Master Plan (EDMP) for Uganda
B2: MANUAL CLASSIFIED COUNT (MCC)
B3: ROAD NAME: | C3: ='19.8 Kayunga-Kangulumira'!C3:G3 -> MCC-C3-STN90-KAYUNGA-KANGULUMIRA ROAD
C5: Date | D5: 20.08.19 | F5: Location | G5: ='19.8 Kayunga-Kangulumira'!G5:H5 -> Kayunga | J5: Surveyor | K5: ='19.8 Kayunga-Kangulumira'!K5:L5 -> Comfort
C6: Dir. From | D6: KAYUNGA | F6: Dir. To | G6: KANGULUMIRA | J6: Supervisor | K6: ='19.8 Kayunga-Kangulumira'!K6:L6 -> Bella
B8: Time / Veh Type | R8: SUMMARY TRAFFIC VOLUMES
C9: 1. Car | D9: 2. Station Wagon | E9: 3. Pickups | F9: 4. Minibus, matatu | G9: 5. Medium bus | H9: 6. Large Bus | I9: 7. Light Truck | J9: 8. Medium Truck | K9: 9. Heavy truck | L9: 10. Truck Trailer | M9: 11. Motor cycles | N9: 12. Tractors | O9: Total Excl M/Cycles | P9: Total All | R9: Time | S9: 1. Car | T9: 2. Station Wagon | U9: 3. Pickups | V9: 4. Minibus, matatu | W9: 5. Medium bus | X9: 6. Large Bus | Y9: 7. Light Truck | Z9: 8. Medium Truck | AA9: 9. Heavy truck | AB9: 10. Truck Trailer | AC9: 11. Motorcycles | AD9: 12. Tractors, Graders | AE9: Total Excl M/ Cycles | AF9: Total All
B10: 07.00 - 07.15 | C10: 3 | D10: 0 | E10: 1 | F10: 7 | G10: 0 | H10: 0 | I10: 1 | J10: 0 | K10: 0 | L10: 0 | M10: 24 | N10: 0 | O10: =SUM(C10:L10,N10) -> 12 | P10: =SUM(C10:N10) -> 36 | R10: 0700-0800 | S10: =SUM(C10:C13) -> 14 | T10: =SUM(D10:D13) -> 0 | U10: =SUM(E10:E13) -> 8 | V10: =SUM(F10:F13) -> 32 | W10: =SUM(G10:G13) -> 0 | X10: =SUM(H10:H13) -> 0 | Y10: =SUM(I10:I13) -> 2 | Z10: =SUM(J10:J13) -> 0 | ... AF10: =SUM(P10:P13) -> 199
B11: 07.15 - 07.30 | C11: 1 | D11: 0 | E11: 3 | F11: 8 | G11: 0 | H11: 0 | I11: 0 | J11: 0 | K11: 0 | L11: 0 | M11: 35 | N11: 0 | O11: =SUM(C11:L11,N11) -> 12 | P11: =SUM(C11:N11) -> 47 | R11: 0800-0900 | S11: =SUM(C14:C17) -> 21 | T11: =SUM(D14:D17) -> 0 | U11: =SUM(E14:E17) -> 25 | V11: =SUM(F14:F17) -> 19 | W11: =SUM(G14:G17) -> 0 | X11: =SUM(H14:H17) -> 0 | Y11: =SUM(I14:I17) -> 12 | Z11: =SUM(J14:J17) -> 0 | ... AF11: =SUM(P14:P17) -> 228
B12: 07.30 - 07.45 | C12: 5 | D12: 0 | E12: 1 | F12: 10 | G12: 0 | H12: 0 | I12: 0 | J12: 0 | K12: 0 | L12: 0 | M12: 31 | N12: 0 | O12: =SUM(C12:L12,N12) -> 16 | P12: =SUM(C12:N12) -> 47 | R12: 0900-1000 | S12: =SUM(C18:C21) -> 25 | T12: =SUM(D18:D21) -> 0 | U12: =SUM(E18:E21) -> 15 | V12: =SUM(F18:F21) -> 17 | W12: =SUM(G18:G21) -> 1 | X12: =SUM(H18:H21) -> 0 | Y12: =SUM(I18:I21) -> 4 | Z12: =SUM(J18:J21) -> 0 | ... AF12: =SUM(P18:P21) -> 180
B13: 07.45 - 08.00 | C13: 5 | D13: 0 | E13: 3 | F13: 7 | G13: 0 | H13: 0 | I13: 1 | J13: 0 | K13: 0 | L13: 0 | M13: 53 | N13: 0 | O13: =SUM(C13:L13,N13) -> 16 | P13: =SUM(C13:N13) -> 69 | R13: 1000-1100 | S13: =SUM(C22:C25) -> 17 | T13: =SUM(D22:D25) -> 0 | U13: =SUM(E22:E25) -> 16 | V13: =SUM(F22:F25) -> 15 | W13: =SUM(G22:G25) -> 0 | X13: =SUM(H22:H25) -> 0 | Y13: =SUM(I22:I25) -> 8 | Z13: =SUM(J22:J25) -> 2 | ... AF13: =SUM(P22:P25) -> 159
B14: 08.00 - 08.15 | C14: 9 | D14: 0 | E14: 7 | F14: 3 | G14: 0 | H14: 0 | I14: 5 | J14: 0 | K14: 0 | L14: 0 | M14: 42 | N14: 0 | O14: =SUM(C14:L14,N14) -> 24 | P14: =SUM(C14:N14) -> 66 | R14: 1100-1200 | S14: =SUM(C26:C29) -> 16 | T14: =SUM(D26:D29) -> 0 | U14: =SUM(E26:E29) -> 21 | V14: =SUM(F26:F29) -> 16 | W14: =SUM(G26:G29) -> 1 | X14: =SUM(H26:H29) -> 1 | Y14: =SUM(I26:I29) -> 9 | Z14: =SUM(J26:J29) -> 1 | ... AF14: =SUM(P26:P29) -> 171
B15: 08.15 - 08.30 | C15: 5 | D15: 0 | E15: 5 | F15: 4 | G15: 0 | H15: 0 | I15: 4 | J15: 0 | K15: 0 | L15: 0 | M15: 44 | N15: 0 | O15: =SUM(C15:L15,N15) -> 18 | P15: =SUM(C15:N15) -> 62 | R15: 1200-1300 | S15: =SUM(C30:C33) -> 15 | T15: =SUM(D30:D33) -> 0 | U15: =SUM(E30:E33) -> 17 | V15: =SUM(F30:F33) -> 18 | W15: =SUM(G30:G33) -> 5 | X15: =SUM(H30:H33) -> 0 | Y15: =SUM(I30:I33) -> 13 | Z15: =SUM(J30:J33) -> 0 | ... AF15: =SUM(P30:P33) -> 162
B16: 08.30 - 08.45 | C16: 3 | D16: 0 | E16: 6 | F16: 10 | G16: 0 | H16: 0 | I16: 1 | J16: 0 | K16: 1 | L16: 0 | M16: 29 | N16: 0 | O16: =SUM(C16:L16,N16) -> 21 | P16: =SUM(C16:N16) -> 50 | R16: 1300-1400 | S16: =SUM(C34:C37) -> 23 | T16: =SUM(D34:D37) -> 0 | U16: =SUM(E34:E37) -> 16 | V16: =SUM(F34:F37) -> 14 | W16: =SUM(G34:G37) -> 3 | X16: =SUM(H34:H37) -> 0 | Y16: =SUM(I34:I37) -> 18 | Z16: =SUM(J34:J37) -> 2 | ... AF16: =SUM(P34:P37) -> 187
B17: 08.45 - 9.00 | C17: 4 | D17: 0 | E17: 7 | F17: 2 | G17: 0 | H17: 0 | I17: 2 | J17: 0 | K17: 0 | L17: 0 | M17: 35 | N17: 0 | O17: =SUM(C17:L17,N17) -> 15 | P17: =SUM(C17:N17) -> 50 | R17: 1400-1500 | S17: =SUM(C38:C41) -> 15 | T17: =SUM(D38:D41) -> 0 | U17: =SUM(E38:E41) -> 23 | V17: =SUM(F38:F41) -> 24 | W17: =SUM(G38:G41) -> 1 | X17: =SUM(H38:H41) -> 1 | Y17: =SUM(I38:I41) -> 15 | Z17: =SUM(J38:J41) -> 1 | ... AF17: =SUM(P38:P41) -> 167
B18: 09.00 - 09.15 | C18: 9 | D18: 0 | E18: 4 | F18: 2 | G18: 1 | H18: 0 | I18: 2 | J18: 0 | K18: 0 | L18: 0 | M18: 21 | N18: 0 | O18: =SUM(C18:L18,N18) -> 18 | P18: =SUM(C18:N18) -> 39 | R18: 1500-1600 | S18: =SUM(C42:C45) -> 13 | T18: =SUM(D42:D45) -> 0 | U18: =SUM(E42:E45) -> 20 | V18: =SUM(F42:F45) -> 12 | W18: =SUM(G42:G45) -> 0 | X18: =SUM(H42:H45) -> 0 | Y18: =SUM(I42:I45) -> 14 | Z18: =SUM(J42:J45) -> 3 | ... AF18: =SUM(P42:P45) -> 121
B19: 09.15 - 09.30 | C19: 6 | D19: 0 | E19: 0 | F19: 4 | G19: 0 | H19: 0 | I19: 0 | J19: 0 | K19: 2 | L19: 0 | M19: 27 | N19: 0 | O19: =SUM(C19:L19,N19) -> 12 | P19: =SUM(C19:N19) -> 39 | R19: 1600-1700 | S19: =SUM(C46:C49) -> 19 | T19: =SUM(D46:D49) -> 0 | U19: =SUM(E46:E49) -> 31 | V19: =SUM(F46:F49) -> 20 | W19: =SUM(G46:G49) -> 1 | X19: =SUM(H46:H49) -> 2 | Y19: =SUM(I46:I49) -> 23 | Z19: =SUM(J46:J49) -> 3 | ... AF19: =SUM(P46:P49) -> 233
B20: 09.30 - 09.45 | C20: 5 | D20: 0 | E20: 5 | F20: 8 | G20: 0 | H20: 0 | I20: 0 | J20: 0 | K20: 1 | L20: 0 | M20: 41 | N20: 0 | O20: =SUM(C20:L20,N20) -> 19 | P20: =SUM(C20:N20) -> 60 | R20: 1700-1800 | S20: =SUM(C50:C53) -> 16 | T20: =SUM(D50:D53) -> 0 | U20: =SUM(E50:E53) -> 23 | V20: =SUM(F50:F53) -> 21 | W20: =SUM(G50:G53) -> 2 | X20: =SUM(H50:H53) -> 4 | Y20: =SUM(I50:I53) -> 17 | Z20: =SUM(J50:J53) -> 3 | ... AF20: =SUM(P50:P53) -> 223
B21: 09.45 - 10.00 | C21: 5 | D21: 0 | E21: 6 | F21: 3 | G21: 0 | H21: 0 | I21: 2 | J21: 0 | K21: 0 | L21: 0 | M21: 26 | N21: 0 | O21: =SUM(C21:L21,N21) -> 16 | P21: =SUM(C21:N21) -> 42 | R21: 1800-1900 | S21: =SUM(C54:C57) -> 22 | T21: =SUM(D54:D57) -> 0 | U21: =SUM(E54:E57) -> 25 | V21: =SUM(F54:F57) -> 13 | W21: =SUM(G54:G57) -> 1 | X21: =SUM(H54:H57) -> 2 | Y21: =SUM(I54:I57) -> 17 | Z21: =SUM(J54:J57) -> 2 | ... AF21: =SUM(P54:P57) -> 187
B22: 10.00 - 10.15 | C22: 3 | D22: 0 | E22: 3 | F22: 3 | G22: 0 | H22: 0 | I22: 4 | J22: 1 | K22: 0 | L22: 0 | M22: 22 | N22: 0 | O22: =SUM(C22:L22,N22) -> 14 | P22: =SUM(C22:N22) -> 36 | R22: AM Peak Hr | S22: =MAX(S10:S12) -> 25 | T22: =MAX(T10:T12) -> 0 | U22: =MAX(U10:U12) -> 25 | V22: =MAX(V10:V12) -> 32 | W22: =MAX(W10:W12) -> 1 | X22: =MAX(X10:X12) -> 0 | Y22: =MAX(Y10:Y12) -> 12 | Z22: =MAX(Z10:Z12) -> 0 | ... AF22: =MAX(AF10:AF12) -> 228
B23: 10.15 - 10.30 | C23: 4 | D23: 0 | E23: 3 | F23: 6 | G23: 0 | H23: 0 | I23: 2 | J23: 0 | K23: 1 | L23: 0 | M23: 29 | N23: 0 | O23: =SUM(C23:L23,N23) -> 16 | P23: =SUM(C23:N23) -> 45 | R23: IP Peak Hr | S23: =MAX(S13:S18) -> 23 | T23: =MAX(T13:T18) -> 0 | U23: =MAX(U13:U18) -> 23 | V23: =MAX(V13:V18) -> 24 | W23: =MAX(W13:W18) -> 5 | X23: =MAX(X13:X18) -> 1 | Y23: =MAX(Y13:Y18) -> 18 | Z23: =MAX(Z13:Z18) -> 3 | ... AF23: =MAX(AF13:AF18) -> 187
B24: 10.30 - 10.45 | C24: 8 | D24: 0 | E24: 4 | F24: 4 | G24: 0 | H24: 0 | I24: 2 | J24: 1 | K24: 0 | L24: 1 | M24: 21 | N24: 0 | O24: =SUM(C24:L24,N24) -> 20 | P24: =SUM(C24:N24) -> 41 | R24: PM Peak Hr | S24: =MAX(S19:S21) -> 22 | T24: =MAX(T19:T21) -> 0 | U24: =MAX(U19:U21) -> 31 | V24: =MAX(V19:V21) -> 21 | W24: =MAX(W19:W21) -> 2 | X24: =MAX(X19:X21) -> 4 | Y24: =MAX(Y19:Y21) -> 23 | Z24: =MAX(Z19:Z21) -> 3 | ... AF24: =MAX(AF19:AF21) -> 233
B25: 10.45 - 11.00 | C25: 2 | D25: 0 | E25: 6 | F25: 2 | G25: 0 | H25: 0 | I25: 0 | J25: 0 | K25: 0 | L25: 1 | M25: 26 | N25: 0 | O25: =SUM(C25:L25,N25) -> 11 | P25: =SUM(C25:N25) -> 37 | R25: AM Period | S25: =SUM(S10:S12) -> 60 | T25: =SUM(T10:T12) -> 0 | U25: =SUM(U10:U12) -> 48 | V25: =SUM(V10:V12) -> 68 | W25: =SUM(W10:W12) -> 1 | X25: =SUM(X10:X12) -> 0 | Y25: =SUM(Y10:Y12) -> 18 | Z25: =SUM(Z10:Z12) -> 0 | ... AF25: =SUM(AF10:AF12) -> 607
B26: 11.00 - 11.15 | C26: 3 | D26: 0 | E26: 3 | F26: 4 | G26: 0 | H26: 0 | I26: 1 | J26: 0 | K26: 0 | L26: 1 | M26: 24 | N26: 0 | O26: =SUM(C26:L26,N26) -> 12 | P26: =SUM(C26:N26) -> 36 | R26: IP Period | S26: =SUM(S13:S18) -> 99 | T26: =SUM(T13:T18) -> 0 | U26: =SUM(U13:U18) -> 113 | V26: =SUM(V13:V18) -> 99 | W26: =SUM(W13:W18) -> 10 | X26: =SUM(X13:X18) -> 2 | Y26: =SUM(Y13:Y18) -> 77 | Z26: =SUM(Z13:Z18) -> 9 | ... AF26: =SUM(AF13:AF18) -> 967
B27: 11.15 - 11.30 | C27: 4 | D27: 0 | E27: 6 | F27: 4 | G27: 0 | H27: 1 | I27: 2 | J27: 0 | K27: 1 | L27: 0 | M27: 28 | N27: 0 | O27: =SUM(C27:L27,N27) -> 18 | P27: =SUM(C27:N27) -> 46 | R27: PM Period | S27: =SUM(S19:S21) -> 57 | T27: =SUM(T19:T21) -> 0 | U27: =SUM(U19:U21) -> 79 | V27: =SUM(V19:V21) -> 54 | W27: =SUM(W19:W21) -> 4 | X27: =SUM(X19:X21) -> 8 | Y27: =SUM(Y19:Y21) -> 57 | Z27: =SUM(Z19:Z21) -> 8 | ... AF27: =SUM(AF19:AF21) -> 643
B28: 11.30 - 11.45 | C28: 4 | D28: 0 | E28: 8 | F28: 2 | G28: 1 | H28: 0 | I28: 3 | J28: 0 | K28: 1 | L28: 0 | M28: 25 | N28: 0 | O28: =SUM(C28:L28,N28) -> 19 | P28: =SUM(C28:N28) -> 44 | R28: 12 Hours | S28: =SUM(S10:S21) -> 216 | T28: =SUM(T10:T21) -> 0 | U28: =SUM(U10:U21) -> 240 | V28: =SUM(V10:V21) -> 221 | W28: =SUM(W10:W21) -> 15 | X28: =SUM(X10:X21) -> 10 | Y28: =SUM(Y10:Y21) -> 152 | Z28: =SUM(Z10:Z21) -> 17 | ... AF28: =SUM(AF10:AF21) -> 2217
B29: 11.45 - 12.00 | C29: 5 | D29: 0 | E29: 4 | F29: 6 | G29: 0 | H29: 0 | I29: 3 | J29: 1 | K29: 0 | L29: 0 | M29: 26 | N29: 0 | O29: =SUM(C29:L29,N29) -> 19 | P29: =SUM(C29:N29) -> 45
B30: 12.00 - 12.15 | C30: 4 | D30: 0 | E30: 4 | F30: 7 | G30: 2 | H30: 0 | I30: 2 | J30: 0 | K30: 0 | L30: 0 | M30: 25 | N30: 0 | O30: =SUM(C30:L30,N30) -> 19 | P30: =SUM(C30:N30) -> 44
B31: 12.15 - 12.30 | C31: 6 | D31: 0 | E31: 5 | F31: 3 | G31: 0 | H31: 0 | I31: 6 | J31: 0 | K31: 1 | L31: 0 | M31: 19 | N31: 0 | O31: =SUM(C31:L31,N31) -> 21 | P31: =SUM(C31:N31) -> 40
B32: 12.30 - 12.45 | C32: 3 | D32: 0 | E32: 3 | F32: 5 | G32: 1 | H32: 0 | I32: 3 | J32: 0 | K32: 0 | L32: 0 | M32: 22 | N32: 0 | O32: =SUM(C32:L32,N32) -> 15 | P32: =SUM(C32:N32) -> 37
B33: 12.45 - 13.00 | C33: 2 | D33: 0 | E33: 5 | F33: 3 | G33: 2 | H33: 0 | I33: 2 | J33: 0 | K33: 0 | L33: 0 | M33: 27 | N33: 0 | O33: =SUM(C33:L33,N33) -> 14 | P33: =SUM(C33:N33) -> 41
B34: 13.00 - 13.15 | C34: 5 | D34: 0 | E34: 3 | F34: 3 | G34: 2 | H34: 0 | I34: 2 | J34: 0 | K34: 2 | L34: 2 | M34: 37 | N34: 0 | O34: =SUM(C34:L34,N34) -> 19 | P34: =SUM(C34:N34) -> 56
B35: 13.15 - 13.30 | C35: 2 | D35: 0 | E35: 5 | F35: 3 | G35: 0 | H35: 0 | I35: 5 | J35: 0 | K35: 1 | L35: 0 | M35: 23 | N35: 0 | O35: =SUM(C35:L35,N35) -> 16 | P35: =SUM(C35:N35) -> 39
B36: 13.30 - 13.45 | C36: 9 | D36: 0 | E36: 5 | F36: 3 | G36: 0 | H36: 0 | I36: 5 | J36: 1 | K36: 0 | L36: 0 | M36: 27 | N36: 0 | O36: =SUM(C36:L36,N36) -> 23 | P36: =SUM(C36:N36) -> 50
B37: 13.45 - 14.00 | C37: 7 | D37: 0 | E37: 3 | F37: 5 | G37: 1 | H37: 0 | I37: 6 | J37: 1 | K37: 0 | L37: 0 | M37: 19 | N37: 0 | O37: =SUM(C37:L37,N37) -> 23 | P37: =SUM(C37:N37) -> 42
B38: 14.00 - 14.15 | C38: 3 | D38: 0 | E38: 6 | F38: 3 | G38: 0 | H38: 1 | I38: 4 | J38: 1 | K38: 0 | L38: 0 | M38: 29 | N38: 0 | O38: =SUM(C38:L38,N38) -> 18 | P38: =SUM(C38:N38) -> 47
B39: 14.15 - 14.30 | C39: 3 | D39: 0 | E39: 5 | F39: 7 | G39: 0 | H39: 0 | I39: 4 | J39: 0 | K39: 0 | L39: 0 | M39: 22 | N39: 0 | O39: =SUM(C39:L39,N39) -> 19 | P39: =SUM(C39:N39) -> 41
B40: 14.30 - 14.45 | C40: 5 | D40: 0 | E40: 4 | F40: 7 | G40: 0 | H40: 0 | I40: 3 | J40: 0 | K40: 2 | L40: 1 | M40: 11 | N40: 0 | O40: =SUM(C40:L40,N40) -> 22 | P40: =SUM(C40:N40) -> 33
... B105: 06.45 - 07.00 | C105: 1 | D105: 0 | E105: 1 | F105: 1 | G105: 0 | H105: 0 | I105: 1 | J105: 2 | K105: 1 | L105: 0 | M105: 1 | N105: 0 | O105: =SUM(C105:L105,N105) -> 7 | P105: =SUM(C105:N105) -> 8
B106: Totals | C106: =SUM(C10:C105) -> 269 | D106: =SUM(D10:D105) -> 0 | E106: =SUM(E10:E105) -> 328 | F106: =SUM(F10:F105) -> 280 | G106: =SUM(G10:G105) -> 25 | H106: =SUM(H10:H105) -> 30 | I106: =SUM(I10:I105) -> 207 | J106: =SUM(J10:J105) -> 53 | ... P106: =SUM(P10:P105) -> 2788
...

Sheet 20.8 Kangulumira-Kayunga
B1: Consultancy services for Preparation of Expressway Development Master Plan (EDMP) for Uganda
B2: MANUAL CLASSIFIED COUNT (MCC)
B3: ROAD NAME: | C3: ='20.8 Kayunga-Kangulumira'!C3:G3 -> MCC-C3-STN90-KAYUNGA-KANGULUMIRA ROAD
C5: Date | D5: ='20.8 Kayunga-Kangulumira'!D5 -> 20.08.19 | F5: Location | J5: Surveyor
C6: Dir. From | D6: KANGULUMIRA | F6: Dir. To | G6: KAYUNGA | J6: Supervisor
B8: Time / Veh Type | R8: SUMMARY TRAFFIC VOLUMES
C9: 1. Car | D9: 2. Station Wagon | E9: 3. Pickups | F9: 4. Minibus, matatu | G9: 5. Medium bus | H9: 6. Large Bus | I9: 7. Light Truck | J9: 8. Medium Truck | K9: 9. Heavy truck | L9: 10. Truck Trailer | M9: 11. Motor cycles | N9: 12. Tractors | O9: Total Excl M/Cycles | P9: Total All | R9: Time | S9: 1. Car | T9: 2. Station Wagon | U9: 3. Pickups | V9: 4. Minibus, matatu | W9: 5. Medium bus | X9: 6. Large Bus | Y9: 7. Light Truck | Z9: 8. Medium Truck | AA9: 9. Heavy truck | AB9: 10. Truck Trailer | AC9: 11. Motorcycles | AD9: 12. Tractors, Graders | AE9: Total Excl M/ Cycles | AF9: Total All
B10: 07.00 - 07.15 | C10: 4 | D10: 0 | E10: 1 | F10: 8 | G10: 0 | H10: 0 | I10: 2 | J10: 0 | K10: 1 | L10: 0 | M10: 10 | N10: 0 | O10: =SUM(C10:L10,N10) -> 16 | P10: =SUM(C10:N10) -> 26 | R10: 0700-0800 | S10: =SUM(C10:C13) -> 11 | T10: =SUM(D10:D13) -> 0 | U10: =SUM(E10:E13) -> 11 | V10: =SUM(F10:F13) -> 22 | W10: =SUM(G10:G13) -> 0 | X10: =SUM(H10:H13) -> 0 | Y10: =SUM(I10:I13) -> 7 | Z10: =SUM(J10:J13) -> 0 | ... AF10: =SUM(P10:P13) -> 133
B11: 07.15 - 07.30 | C11: 3 | D11: 0 | E11: 5 | F11: 3 | G11: 0 | H11: 0 | I11: 1 | J11: 0 | K11: 0 | L11: 0 | M11: 19 | N11: 1 | O11: =SUM(C11:L11,N11) -> 13 | P11: =SUM(C11:N11) -> 32 | R11: 0800-0900 | S11: =SUM(C14:C17) -> 17 | T11: =SUM(D14:D17) -> 0 | U11: =SUM(E14:E17) -> 8 | V11: =SUM(F14:F17) -> 15 | W11: =SUM(G14:G17) -> 0 | X11: =SUM(H14:H17) -> 0 | Y11: =SUM(I14:I17) -> 9 | Z11: =SUM(J14:J17) -> 2 | ... AF11: =SUM(P14:P17) -> 147
B12: 07.30 - 07.45 | C12: 3 | D12: 0 | E12: 4 | F12: 9 | G12: 0 | H12: 0 | I12: 3 | J12: 0 | K12: 3 | L12: 0 | M12: 19 | N12: 0 | O12: =SUM(C12:L12,N12) -> 22 | P12: =SUM(C12:N12) -> 41 | R12: 0900-1000 | S12: =SUM(C18:C21) -> 14 | T12: =SUM(D18:D21) -> 0 | U12: =SUM(E18:E21) -> 17 | V12: =SUM(F18:F21) -> 15 | W12: =SUM(G18:G21) -> 0 | X12: =SUM(H18:H21) -> 1 | Y12: =SUM(I18:I21) -> 7 | Z12: =SUM(J18:J21) -> 1 | ... AF12: =SUM(P18:P21) -> 143
B13: 07.45 - 08.00 | C13: 1 | D13: 0 | E13: 1 | F13: 2 | G13: 0 | H13: 0 | I13: 1 | J13: 0 | K13: 0 | L13: 3 | M13: 26 | N13: 0 | O13: =SUM(C13:L13,N13) -> 8 | P13: =SUM(C13:N13) -> 34 | R13: 1000-1100 | S13: =SUM(C22:C25) -> 14 | T13: =SUM(D22:D25) -> 0 | U13: =SUM(E22:E25) -> 19 | V13: =SUM(F22:F25) -> 15 | W13: =SUM(G22:G25) -> 0 | X13: =SUM(H22:H25) -> 0 | Y13: =SUM(I22:I25) -> 10 | Z13: =SUM(J22:J25) -> 1 | ... AF13: =SUM(P22:P25) -> 155
B14: 08.00 - 08.15 | C14: 3 | D14: 0 | E14: 1 | F14: 2 | G14: 0 | H14: 0 | I14: 2 | J14: 0 | K14: 0 | L14: 0 | M14: 27 | N14: 0 | O14: =SUM(C14:L14,N14) -> 8 | P14: =SUM(C14:N14) -> 35 | R14: 1100-1200 | S14: =SUM(C26:C29) -> 16 | T14: =SUM(D26:D29) -> 0 | U14: =SUM(E26:E29) -> 13 | V14: =SUM(F26:F29) -> 13 | W14: =SUM(G26:G29) -> 1 | X14: =SUM(H26:H29) -> 0 | Y14: =SUM(I26:I29) -> 15 | Z14: =SUM(J26:J29) -> 3 | ... AF14: =SUM(P26:P29) -> 178
B15: 08.15 - 08.30 | C15: 5 | D15: 0 | E15: 2 | F15: 1 | G15: 0 | H15: 0 | I15: 2 | J15: 0 | K15: 1 | L15: 0 | M15: 27 | N15: 0 | O15: =SUM(C15:L15,N15) -> 11 | P15: =SUM(C15:N15) -> 38 | R15: 1200-1300 | S15: =SUM(C30:C33) -> 11 | T15: =SUM(D30:D33) -> 0 | U15: =SUM(E30:E33) -> 6 | V15: =SUM(F30:F33) -> 19 | W15: =SUM(G30:G33) -> 2 | X15: =SUM(H30:H33) -> 0 | Y15: =SUM(I30:I33) -> 16 | Z15: =SUM(J30:J33) -> 1 | ... AF15: =SUM(P30:P33) -> 162
B16: 08.30 - 08.45 | C16: 5 | D16: 0 | E16: 2 | F16: 6 | G16: 0 | H16: 0 | I16: 3 | J16: 2 | K16: 0 | L16: 0 | M16: 19 | N16: 0 | O16: =SUM(C16:L16,N16) -> 18 | P16: =SUM(C16:N16) -> 37 | R16: 1300-1400 | S16: =SUM(C34:C37) -> 19 | T16: =SUM(D34:D37) -> 0 | U16: =SUM(E34:E37) -> 21 | V16: =SUM(F34:F37) -> 14 | W16: =SUM(G34:G37) -> 1 | X16: =SUM(H34:H37) -> 0 | Y16: =SUM(I34:I37) -> 19 | Z16: =SUM(J34:J37) -> 2 | ... AF16: =SUM(P34:P37) -> 178
B17: 08.45 - 9.00 | C17: 4 | D17: 0 | E17: 3 | F17: 6 | G17: 0 | H17: 0 | I17: 2 | J17: 0 | K17: 0 | L17: 0 | M17: 22 | N17: 0 | O17: =SUM(C17:L17,N17) -> 15 | P17: =SUM(C17:N17) -> 37 | R17: 1400-1500 | S17: =SUM(C38:C41) -> 20 | T17: =SUM(D38:D41) -> 0 | U17: =SUM(E38:E41) -> 20 | V17: =SUM(F38:F41) -> 19 | W17: =SUM(G38:G41) -> 0 | X17: =SUM(H38:H41) -> 2 | Y17: =SUM(I38:I41) -> 18 | Z17: =SUM(J38:J41) -> 1 | ... AF17: =SUM(P38:P41) -> 187
B18: 09.00 - 09.15 | C18: 4 | D18: 0 | E18: 3 | F18: 4 | G18: 0 | H18: 0 | I18: 3 | J18: 0 | K18: 0 | L18: 1 | M18: 19 | N18: 0 | O18: =SUM(C18:L18,N18) -> 15 | P18: =SUM(C18:N18) -> 34 | R18: 1500-1600 | S18: =SUM(C42:C45) -> 29 | T18: =SUM(D42:D45) -> 0 | U18: =SUM(E42:E45) -> 37 | V18: =SUM(F42:F45) -> 17 | W18: =SUM(G42:G45) -> 1 | X18: =SUM(H42:H45) -> 0 | Y18: =SUM(I42:I45) -> 11 | Z18: =SUM(J42:J45) -> 1 | ... AF18: =SUM(P42:P45) -> 180
B19: 09.15 - 09.30 | C19: 2 | D19: 0 | E19: 8 | F19: 4 | G19: 0 | H19: 1 | I19: 2 | J19: 1 | K19: 0 | L19: 1 | M19: 22 | N19: 0 | O19: =SUM(C19:L19,N19) -> 19 | P19: =SUM(C19:N19) -> 41 | R19: 1600-1700 | S19: =SUM(C46:C49) -> 25 | T19: =SUM(D46:D49) -> 0 | U19: =SUM(E46:E49) -> 35 | V19: =SUM(F46:F49) -> 15 | W19: =SUM(G46:G49) -> 0 | X19: =SUM(H46:H49) -> 0 | Y19: =SUM(I46:I49) -> 18 | Z19: =SUM(J46:J49) -> 2 | ... AF19: =SUM(P46:P49) -> 204
B20: 09.30 - 09.45 | C20: 5 | D20: 0 | E20: 2 | F20: 2 | G20: 0 | H20: 0 | I20: 0 | J20: 0 | K20: 1 | L20: 0 | M20: 22 | N20: 0 | O20: =SUM(C20:L20,N20) -> 10 | P20: =SUM(C20:N20) -> 32 | R20: 1700-1800 | S20: =SUM(C50:C53) -> 21 | T20: =SUM(D50:D53) -> 0 | U20: =SUM(E50:E53) -> 33 | V20: =SUM(F50:F53) -> 18 | W20: =SUM(G50:G53) -> 6 | X20: =SUM(H50:H53) -> 1 | Y20: =SUM(I50:I53) -> 10 | Z20: =SUM(J50:J53) -> 4 | ... AF20: =SUM(P50:P53) -> 205
B21: 09.45 - 10.00 | C21: 3 | D21: 0 | E21: 4 | F21: 5 | G21: 0 | H21: 0 | I21: 2 | J21: 0 | K21: 0 | L21: 0 | M21: 22 | N21: 0 | O21: =SUM(C21:L21,N21) -> 14 | P21: =SUM(C21:N21) -> 36 | R21: 1800-1900 | S21: =SUM(C54:C57) -> 27 | T21: =SUM(D54:D57) -> 0 | U21: =SUM(E54:E57) -> 30 | V21: =SUM(F54:F57) -> 25 | W21: =SUM(G54:G57) -> 1 | X21: =SUM(H54:H57) -> 0 | Y21: =SUM(I54:I57) -> 13 | Z21: =SUM(J54:J57) -> 0 | ... AF21: =SUM(P54:P57) -> 203
B22: 10.00 - 10.15 | C22: 2 | D22: 0 | E22: 2 | F22: 4 | G22: 0 | H22: 0 | I22: 1 | J22: 0 | K22: 2 | L22: 0 | M22: 21 | N22: 0 | O22: =SUM(C22:L22,N22) -> 11 | P22: =SUM(C22:N22) -> 32 | R22: 1900-2000 | S22: =SUM(C58:C61) -> 9 | T22: =SUM(D58:D61) -> 0 | U22: =SUM(E58:E61) -> 16 | V22: =SUM(F58:F61) -> 10 | W22: =SUM(G58:G61) -> 1 | X22: =SUM(H58:H61) -> 2 | Y22: =SUM(I58:I61) -> 12 | Z22: =SUM(J58:J61) -> 3 | ... AF22: =SUM(P58:P61) -> 138
B23: 10.15 - 10.30 | C23: 5 | D23: 0 | E23: 4 | F23: 2 | G23: 0 | H23: 0 | I23: 1 | J23: 1 | K23: 1 | L23: 0 | M23: 23 | N23: 0 | O23: =SUM(C23:L23,N23) -> 14 | P23: =SUM(C23:N23) -> 37 | R23: 2000-2100 | S23: =SUM(C62:C65) -> 12 | T23: =SUM(D62:D65) -> 0 | U23: =SUM(E62:E65) -> 13 | V23: =SUM(F62:F65) -> 12 | W23: =SUM(G62:G65) -> 1 | X23: =SUM(H62:H65) -> 1 | Y23: =SUM(I62:I65) -> 10 | Z23: =SUM(J62:J65) -> 4 | ... AF23: =SUM(P62:P65) -> 118
B24: 10.30 - 10.45 | C24: 4 | D24: 0 | E24: 6 | F24: 5 | G24: 0 | H24: 0 | I24: 4 | J24: 0 | K24: 0 | L24: 0 | M24: 18 | N24: 0 | O24: =SUM(C24:L24,N24) -> 19 | P24: =SUM(C24:N24) -> 37 | R24: 2100-2200 | S24: =SUM(C66:C69) -> 9 | T24: =SUM(D66:D69) -> 0 | U24: =SUM(E66:E69) -> 13 | V24: =SUM(F66:F69) -> 9 | W24: =SUM(G66:G69) -> 1 | X24: =SUM(H66:H69) -> 3 | Y24: =SUM(I66:I69) -> 11 | Z24: =SUM(J66:J69) -> 2 | ... AF24: =SUM(P66:P69) -> 99
B25: 10.45 - 11.00 | C25: 3 | D25: 0 | E25: 7 | F25: 4 | G25: 0 | H25: 0 | I25: 4 | J25: 0 | K25: 1 | L25: 3 | M25: 27 | N25: 0 | O25: =SUM(C25:L25,N25) -> 22 | P25: =SUM(C25:N25) -> 49 | R25: 2200-2300 | S25: =SUM(C70:C73) -> 9 | T25: =SUM(D70:D73) -> 0 | U25: =SUM(E70:E73) -> 9 | V25: =SUM(F70:F73) -> 6 | W25: =SUM(G70:G73) -> 0 | X25: =SUM(H70:H73) -> 0 | Y25: =SUM(I70:I73) -> 6 | Z25: =SUM(J70:J73) -> 3 | ... AF25: =SUM(P70:P73) -> 49
B26: 11.00 - 11.15 | C26: 3 | D26: 0 | E26: 3 | F26: 5 | G26: 0 | H26: 0 | I26: 5 | J26: 0 | K26: 0 | L26: 0 | M26: 30 | N26: 0 | O26: =SUM(C26:L26,N26) -> 16 | P26: =SUM(C26:N26) -> 46 | R26: 2300-0000 | S26: =SUM(C74:C77) -> 2 | T26: =SUM(D74:D77) -> 0 | U26: =SUM(E74:E77) -> 9 | V26: =SUM(F74:F77) -> 6 | W26: =SUM(G74:G77) -> 1 | X26: =SUM(H74:H77) -> 2 | Y26: =SUM(I74:I77) -> 5 | Z26: =SUM(J74:J77) -> 3 | ... AF26: =SUM(P74:P77) -> 43
B27: 11.15 - 11.30 | C27: 2 | D27: 0 | E27: 3 | F27: 3 | G27: 0 | H27: 0 | I27: 3 | J27: 0 | K27: 3 | L27: 0 | M27: 23 | N27: 0 | O27: =SUM(C27:L27,N27) -> 14 | P27: =SUM(C27:N27) -> 37 | R27: 0000-0100 | S27: =SUM(C78:C81) -> 4 | T27: =SUM(D78:D81) -> 0 | U27: =SUM(E78:E81) -> 7 | V27: =SUM(F78:F81) -> 7 | W27: =SUM(G78:G81) -> 1 | X27: =SUM(H78:H81) -> 2 | Y27: =SUM(I78:I81) -> 6 | Z27: =SUM(J78:J81) -> 3 | ... AF27: =SUM(P78:P81) -> 35
B28: 11.30 - 11.45 | C28: 4 | D28: 0 | E28: 5 | F28: 4 | G28: 0 | H28: 0 | I28: 4 | J28: 2 | K28: 0 | L28: 0 | M28: 31 | N28: 0 | O28: =SUM(C28:L28,N28) -> 19 | P28: =SUM(C28:N28) -> 50 | R28: 0100-0200 | S28: =SUM(C82:C85) -> 4 | T28: =SUM(D82:D85) -> 0 | U28: =SUM(E82:E85) -> 6 | V28: =SUM(F82:F85) -> 5 | W28: =SUM(G82:G85) -> 1 | X28: =SUM(H82:H85) -> 2 | Y28: =SUM(I82:I85) -> 2 | Z28: =SUM(J82:J85) -> 2 | ... AF28: =SUM(P82:P85) -> 24
B29: 11.45 - 12.00 | C29: 7 | D29: 0 | E29: 2 | F29: 1 | G29: 1 | H29: 0 | I29: 3 | J29: 1 | K29: 0 | L29: 0 | M29: 30 | N29: 0 | O29: =SUM(C29:L29,N29) -> 15 | P29: =SUM(C29:N29) -> 45 | R29: 0200-0300 | S29: =SUM(C86:C89) -> 1 | T29: =SUM(D86:D89) -> 0 | U29: =SUM(E86:E89) -> 2 | V29: =SUM(F86:F89) -> 2 | W29: =SUM(G86:G89) -> 1 | X29: =SUM(H86:H89) -> 2 | Y29: =SUM(I86:I89) -> 0 | Z29: =SUM(J86:J89) -> 3 | ... AF29: =SUM(P86:P89) -> 15
B30: 12.00 - 12.15 | C30: 3 | D30: 0 | E30: 2 | F30: 7 | G30: 0 | H30: 0 | I30: 3 | J30: 1 | K30: 0 | L30: 0 | M30: 35 | N30: 0 | O30: =SUM(C30:L30,N30) -> 16 | P30: =SUM(C30:N30) -> 51 | R30: 0300-0400 | S30: =SUM(C90:C93) -> 0 | T30: =SUM(D90:D93) -> 0 | U30: =SUM(E90:E93) -> 1 | V30: =SUM(F90:F93) -> 0 | W30: =SUM(G90:G93) -> 1 | X30: =SUM(H90:H93) -> 1 | Y30: =SUM(I90:I93) -> 0 | Z30: =SUM(J90:J93) -> 4 | ... AF30: =SUM(P90:P93) -> 11
B31: 12.15 - 12.30 | C31: 2 | D31: 0 | E31: 1 | F31: 5 | G31: 1 | H31: 0 | I31: 1 | J31: 0 | K31: 0 | L31: 1 | M31: 26 | N31: 0 | O31: =SUM(C31:L31,N31) -> 11 | P31: =SUM(C31:N31) -> 37 | R31: 0400-0500 | S31: =SUM(C94:C97) -> 0 | T31: =SUM(D94:D97) -> 0 | U31: =SUM(E94:E97) -> 4 | V31: =SUM(F94:F97) -> 0 | W31: =SUM(G94:G97) -> 1 | X31: =SUM(H94:H97) -> 3 | Y31: =SUM(I94:I97) -> 0 | Z31: =SUM(J94:J97) -> 2 | ... AF31: =SUM(P94:P97) -> 14
B32: 12.30 - 12.45 | C32: 1 | D32: 0 | E32: 2 | F32: 3 | G32: 0 | H32: 0 | I32: 7 | J32: 0 | K32: 1 | L32: 0 | M32: 27 | N32: 0 | O32: =SUM(C32:L32,N32) -> 14 | P32: =SUM(C32:N32) -> 41 | R32: 0500-0600 | S32: =SUM(C98:C101) -> 2 | T32: =SUM(D98:D101) -> 0 | U32: =SUM(E98:E101) -> 4 | V32: =SUM(F98:F101) -> 0 | W32: =SUM(G98:G101) -> 0 | X32: =SUM(H98:H101) -> 0 | Y32: =SUM(I98:I101) -> 0 | Z32: =SUM(J98:J101) -> 3 | ... AF32: =SUM(P98:P101) -> 10
B33: 12.45 - 13.00 | C33: 5 | D33: 0 | E33: 1 | F33: 4 | G33: 1 | H33: 0 | I33: 5 | J33: 0 | K33: 1 | L33: 0 | M33: 16 | N33: 0 | O33: =SUM(C33:L33,N33) -> 17 | P33: =SUM(C33:N33) -> 33 | R33: 0600-0700 | S33: =SUM(C102:C105) -> 2 | T33: =SUM(D102:D105) -> 0 | U33: =SUM(E102:E105) -> 5 | V33: =SUM(F102:F105) -> 2 | W33: =SUM(G102:G105) -> 1 | X33: =SUM(H102:H105) -> 2 | Y33: =SUM(I102:I105) -> 3 | Z33: =SUM(J102:J105) -> 4 | ... AF33: =SUM(P102:P105) -> 27
B34: 13.00 - 13.15 | C34: 4 | D34: 0 | E34: 5 | F34: 5 | G34: 0 | H34: 0 | I34: 2 | J34: 1 | K34: 1 | L34: 0 | M34: 20 | N34: 0 | O34: =SUM(C34:L34,N34) -> 18 | P34: =SUM(C34:N34) -> 38 | R34: AM Peak Hr | S34: =MAX(S10:S12) -> 17 | T34: =MAX(T10:T12) -> 0 | U34: =MAX(U10:U12) -> 17 | V34: =MAX(V10:V12) -> 22 | W34: =MAX(W10:W12) -> 0 | X34: =MAX(X10:X12) -> 1 | Y34: =MAX(Y10:Y12) -> 9 | Z34: =MAX(Z10:Z12) -> 2 | ... AF34: =MAX(AF10:AF12) -> 147
B35: 13.15 - 13.30 | C35: 6 | D35: 0 | E35: 7 | F35: 4 | G35: 0 | H35: 0 | I35: 6 | J35: 1 | K35: 1 | L35: 0 | M35: 30 | N35: 0 | O35: =SUM(C35:L35,N35) -> 25 | P35: =SUM(C35:N35) -> 55 | R35: IP Peak Hr | S35: =MAX(S13:S18) -> 29 | T35: =MAX(T13:T18) -> 0 | U35: =MAX(U13:U18) -> 37 | V35: =MAX(V13:V18) -> 19 | W35: =MAX(W13:W18) -> 2 | X35: =MAX(X13:X18) -> 2 | Y35: =MAX(Y13:Y18) -> 19 | Z35: =MAX(Z13:Z18) -> 3 | ... AF35: =MAX(AF13:AF18) -> 187
B36: 13.30 - 13.45 | C36: 4 | D36: 0 | E36: 3 | F36: 3 | G36: 1 | H36: 0 | I36: 4 | J36: 0 | K36: 0 | L36: 0 | M36: 23 | N36: 0 | O36: =SUM(C36:L36,N36) -> 15 | P36: =SUM(C36:N36) -> 38 | R36: PM Peak Hr | S36: =MAX(S19:S21) -> 27 | T36: =MAX(T19:T21) -> 0 | U36: =MAX(U19:U21) -> 35 | V36: =MAX(V19:V21) -> 25 | W36: =MAX(W19:W21) -> 6 | X36: =MAX(X19:X21) -> 1 | Y36: =MAX(Y19:Y21) -> 18 | Z36: =MAX(Z19:Z21) -> 4 | ... AF36: =MAX(AF19:AF21) -> 205
B37: 13.45 - 14.00 | C37: 5 | D37: 0 | E37: 6 | F37: 2 | G37: 0 | H37: 0 | I37: 7 | J37: 0 | K37: 0 | L37: 1 | M37: 26 | N37: 0 | O37: =SUM(C37:L37,N37) -> 21 | P37: =SUM(C37:N37) -> 47 | R37: AM Period | S37: =SUM(S10:S12) -> 42 | T37: =SUM(T10:T12) -> 0 | U37: =SUM(U10:U12) -> 36 | V37: =SUM(V10:V12) -> 52 | W37: =SUM(W10:W12) -> 0 | X37: =SUM(X10:X12) -> 1 | Y37: =SUM(Y10:Y12) -> 23 | Z37: =SUM(Z10:Z12) -> 3 | ... AF37: =SUM(AF10:AF12) -> 423
B38: 14.00 - 14.15 | C38: 5 | D38: 0 | E38: 2 | F38: 5 | G38: 0 | H38: 1 | I38: 2 | J38: 0 | K38: 0 | L38: 0 | M38: 14 | N38: 0 | O38: =SUM(C38:L38,N38) -> 15 | P38: =SUM(C38:N38) -> 29 | R38: IP Period | S38: =SUM(S13:S18) -> 109 | T38: =SUM(T13:T18) -> 0 | U38: =SUM(U13:U18) -> 116 | V38: =SUM(V13:V18) -> 97 | W38: =SUM(W13:W18) -> 5 | X38: =SUM(X13:X18) -> 2 | Y38: =SUM(Y13:Y18) -> 89 | Z38: =SUM(Z13:Z18) -> 9 | ... AF38: =SUM(AF13:AF18) -> 1040
B39: 14.15 - 14.30 | C39: 4 | D39: 0 | E39: 3 | F39: 4 | G39: 0 | H39: 0 | I39: 3 | J39: 0 | K39: 0 | L39: 0 | M39: 31 | N39: 0 | O39: =SUM(C39:L39,N39) -> 14 | P39: =SUM(C39:N39) -> 45 | R39: PM Period | S39: =SUM(S19:S21) -> 73 | T39: =SUM(T19:T21) -> 0 | U39: =SUM(U19:U21) -> 98 | V39: =SUM(V19:V21) -> 58 | W39: =SUM(W19:W21) -> 7 | X39: =SUM(X19:X21) -> 1 | Y39: =SUM(Y19:Y21) -> 41 | Z39: =SUM(Z19:Z21) -> 6 | ... AF39: =SUM(AF19:AF21) -> 612
B40: 14.30 - 14.45 | C40: 8 | D40: 0 | E40: 3 | F40: 6 | G40: 0 | H40: 1 | I40: 5 | J40: 0 | K40: 0 | L40: 1 | M40: 33 | N40: 0 | O40: =SUM(C40:L40,N40) -> 24 | P40: =SUM(C40:N40) -> 57 | R40: 12 Hours | S40: =SUM(S10:S21) -> 224 | T40: =SUM(T10:T21) -> 0 | U40: =SUM(U10:U21) -> 250 | V40: =SUM(V10:V21) -> 207 | W40: =SUM(W10:W21) -> 12 | X40: =SUM(X10:X21) -> 4 | Y40: =SUM(Y10:Y21) -> 153 | Z40: =SUM(Z10:Z21) -> 18 | ... AF40: =SUM(AF10:AF21) -> 2075
B41: 14.45 - 15.00 | C41: 3 | D41: 0 | E41: 12 | F41: 4 | G41: 0 | H41: 0 | I41: 8 | J41: 1 | K41: 1 | L41: 0 | M41: 27 | N41: 0 | O41: =SUM(C41:L41,N41) -> 29 | P41: =SUM(C41:N41) -> 56 | R41: 24 Hrs/ADT | S41: =SUM(S10:S33) -> 278 | T41: =SUM(T10:T33) -> 0 | U41: =SUM(U10:U33) -> 339 | V41: =SUM(V10:V33) -> 266 | W41: =SUM(W10:W33) -> 22 | X41: =SUM(X10:X33) -> 24 | Y41: =SUM(Y10:Y33) -> 208 | Z41: =SUM(Z10:Z33) -> 54 | ... AF41: =SUM(AF10:AF33) -> 2658
B42: 15.00 - 15.15 | C42: 11 | D42: 0 | E42: 9 | F42: 5 | G42: 0 | H42: 0 | I42: 0 | J42: 0 | K42: 1 | L42: 0 | M42: 29 | N42: 0 | O42: =SUM(C42:L42,N42) -> 26 | P42: =SUM(C42:N42) -> 55 | R42: NEF | S42: =S41/S40 -> 1.2410714 | T42: =T41/T40 -> #DIV/0! | U42: =U41/U40 -> 1.356 | V42: =V41/V40 -> 1.2850242 | W42: =W41/W40 -> 1.8333333 | X42: =X41/X40 -> 6 | Y42: =Y41/Y40 -> 1.3594771 | Z42: =Z41/Z40 -> 3 | ... AF42: =AF41/AF40 -> 1.2809639
...

Sheet 21.8 Kayunga-Kangulumira
B1: Consultancy services for Preparation of Expressway Development Master Plan (EDMP) for Uganda
B2: MANUAL CLASSIFIED COUNT (MCC)
B3: ROAD NAME: | C3: ='19.8 Kayunga-Kangulumira'!C3:G3 -> MCC-C3-STN90-KAYUNGA-KANGULUMIRA ROAD
C5: Date | D5: 21.08.19 | F5: Location | G5: ='19.8 Kayunga-Kangulumira'!G5:H5 -> Kayunga | J5: Surveyor | K5: ='19.8 Kayunga-Kangulumira'!K5:L5 -> Comfort
C6: Dir. From | D6: ='19.8 Kayunga-Kangulumira'!D6:E6 -> KAYUNGA | F6: Dir. To | G6: ='19.8 Kayunga-Kangulumira'!G6:H6 -> KANGULUMIRA | J6: Supervisor | K6: ='19.8 Kayunga-Kangulumira'!K6:L6 -> Bella
B8: Time / Veh Type | R8: SUMMARY TRAFFIC VOLUMES
C9: 1. Car | D9: 2. Station Wagon | E9: 3. Pickups | F9: 4. Minibus, matatu | G9: 5. Medium bus | H9: 6. Large Bus | I9: 7. Light Truck | J9: 8. Medium Truck | K9: 9. Heavy truck | L9: 10. Truck Trailer | M9: 11. Motor cycles | N9: 12. Tractors | O9: Total Excl M/Cycles | P9: Total All | R9: Time | S9: 1. Car | T9: 2. Station Wagon | U9: 3. Pickups | V9: 4. Minibus, matatu | W9: 5. Medium bus | X9: 6. Large Bus | Y9: 7. Light Truck | Z9: 8. Medium Truck | AA9: 9. Heavy truck | AB9: 10. Truck Trailer | AC9: 11. Motorcycles | AD9: 12. Tractors, Graders | AE9: Total Excl M/ Cycles | AF9: Total All
B10: 07.00 - 07.15 | C10: 2 | D10: 0 | E10: 2 | F10: 8 | G10: 0 | H10: 0 | I10: 0 | J10: 0 | K10: 0 | L10: 0 | M10: 13 | N10: 0 | O10: =SUM(C10:L10,N10) -> 12 | P10: =SUM(C10:N10) -> 25 | R10: 0700-0800 | S10: =SUM(C10:C13) -> 9 | T10: =SUM(D10:D13) -> 0 | U10: =SUM(E10:E13) -> 14 | V10: =SUM(F10:F13) -> 29 | W10: =SUM(G10:G13) -> 0 | X10: =SUM(H10:H13) -> 0 | Y10: =SUM(I10:I13) -> 5 | Z10: =SUM(J10:J13) -> 0 | ... AF10: =SUM(P10:P13) -> 165
B11: 07.15 - 07.30 | C11: 2 | D11: 0 | E11: 3 | F11: 7 | G11: 0 | H11: 0 | I11: 2 | J11: 0 | K11: 0 | L11: 0 | M11: 20 | N11: 0 | O11: =SUM(C11:L11,N11) -> 14 | P11: =SUM(C11:N11) -> 34 | R11: 0800-0900 | S11: =SUM(C14:C17) -> 11 | T11: =SUM(D14:D17) -> 0 | U11: =SUM(E14:E17) -> 15 | V11: =SUM(F14:F17) -> 17 | W11: =SUM(G14:G17) -> 0 | X11: =SUM(H14:H17) -> 0 | Y11: =SUM(I14:I17) -> 6 | Z11: =SUM(J14:J17) -> 0 | ... AF11: =SUM(P14:P17) -> 189
B12: 07.30 - 07.45 | C12: 3 | D12: 0 | E12: 3 | F12: 7 | G12: 0 | H12: 0 | I12: 2 | J12: 0 | K12: 0 | L12: 0 | M12: 35 | N12: 0 | O12: =SUM(C12:L12,N12) -> 15 | P12: =SUM(C12:N12) -> 50 | R12: 0900-1000 | S12: =SUM(C18:C21) -> 21 | T12: =SUM(D18:D21) -> 0 | U12: =SUM(E18:E21) -> 20 | V12: =SUM(F18:F21) -> 15 | W12: =SUM(G18:G21) -> 2 | X12: =SUM(H18:H21) -> 0 | Y12: =SUM(I18:I21) -> 6 | Z12: =SUM(J18:J21) -> 0 | ... AF12: =SUM(P18:P21) -> 157
B13: 07.45 - 08.00 | C13: 2 | D13: 0 | E13: 6 | F13: 7 | G13: 0 | H13: 0 | I13: 1 | J13: 0 | K13: 0 | L13: 0 | M13: 40 | N13: 0 | O13: =SUM(C13:L13,N13) -> 16 | P13: =SUM(C13:N13) -> 56 | R13: 1000-1100 | S13: =SUM(C22:C25) -> 15 | T13: =SUM(D22:D25) -> 0 | U13: =SUM(E22:E25) -> 15 | V13: =SUM(F22:F25) -> 11 | W13: =SUM(G22:G25) -> 0 | X13: =SUM(H22:H25) -> 1 | Y13: =SUM(I22:I25) -> 8 | Z13: =SUM(J22:J25) -> 1 | ... AF13: =SUM(P22:P25) -> 162
B14: 08.00 - 08.15 | C14: 5 | D14: 0 | E14: 4 | F14: 7 | G14: 0 | H14: 0 | I14: 0 | J14: 0 | K14: 0 | L14: 0 | M14: 25 | N14: 0 | O14: =SUM(C14:L14,N14) -> 16 | P14: =SUM(C14:N14) -> 41 | R14: 1100-1200 | S14: =SUM(C26:C29) -> 17 | T14: =SUM(D26:D29) -> 0 | U14: =SUM(E26:E29) -> 21 | V14: =SUM(F26:F29) -> 20 | W14: =SUM(G26:G29) -> 0 | X14: =SUM(H26:H29) -> 0 | Y14: =SUM(I26:I29) -> 10 | Z14: =SUM(J26:J29) -> 0 | ... AF14: =SUM(P26:P29) -> 155
B15: 08.15 - 08.30 | C15: 2 | D15: 0 | E15: 4 | F15: 3 | G15: 0 | H15: 0 | I15: 1 | J15: 0 | K15: 0 | L15: 0 | M15: 45 | N15: 0 | O15: =SUM(C15:L15,N15) -> 10 | P15: =SUM(C15:N15) -> 55 | R15: 1200-1300 | S15: =SUM(C30:C33) -> 18 | T15: =SUM(D30:D33) -> 0 | U15: =SUM(E30:E33) -> 24 | V15: =SUM(F30:F33) -> 13 | W15: =SUM(G30:G33) -> 2 | X15: =SUM(H30:H33) -> 0 | Y15: =SUM(I30:I33) -> 10 | Z15: =SUM(J30:J33) -> 0 | ... AF15: =SUM(P30:P33) -> 188
B16: 08.30 - 08.45 | C16: 2 | D16: 0 | E16: 3 | F16: 4 | G16: 0 | H16: 0 | I16: 1 | J16: 0 | K16: 1 | L16: 0 | M16: 34 | N16: 0 | O16: =SUM(C16:L16,N16) -> 11 | P16: =SUM(C16:N16) -> 45 | R16: 1300-1400 | S16: =SUM(C34:C37) -> 18 | T16: =SUM(D34:D37) -> 0 | U16: =SUM(E34:E37) -> 10 | V16: =SUM(F34:F37) -> 21 | W16: =SUM(G34:G37) -> 0 | X16: =SUM(H34:H37) -> 0 | Y16: =SUM(I34:I37) -> 7 | Z16: =SUM(J34:J37) -> 2 | ... AF16: =SUM(P34:P37) -> 161
B17: 08.45 - 9.00 | C17: 2 | D17: 0 | E17: 4 | F17: 3 | G17: 0 | H17: 0 | I17: 4 | J17: 0 | K17: 1 | L17: 0 | M17: 34 | N17: 0 | O17: =SUM(C17:L17,N17) -> 14 | P17: =SUM(C17:N17) -> 48 | R17: 1400-1500 | S17: =SUM(C38:C41) -> 14 | T17: =SUM(D38:D41) -> 0 | U17: =SUM(E38:E41) -> 16 | V17: =SUM(F38:F41) -> 13 | W17: =SUM(G38:G41) -> 0 | X17: =SUM(H38:H41) -> 0 | Y17: =SUM(I38:I41) -> 12 | Z17: =SUM(J38:J41) -> 2 | ... AF17: =SUM(P38:P41) -> 143
B18: 09.00 - 09.15 | C18: 5 | D18: 0 | E18: 4 | F18: 3 | G18: 1 | H18: 0 | I18: 3 | J18: 0 | K18: 2 | L18: 0 | M18: 31 | N18: 0 | O18: =SUM(C18:L18,N18) -> 18 | P18: =SUM(C18:N18) -> 49 | R18: 1500-1600 | S18: =SUM(C42:C45) -> 17 | T18: =SUM(D42:D45) -> 0 | U18: =SUM(E42:E45) -> 13 | V18: =SUM(F42:F45) -> 10 | W18: =SUM(G42:G45) -> 1 | X18: =SUM(H42:H45) -> 1 | Y18: =SUM(I42:I45) -> 17 | Z18: =SUM(J42:J45) -> 1 | ... AF18: =SUM(P42:P45) -> 158
B19: 09.15 - 09.30 | C19: 8 | D19: 0 | E19: 4 | F19: 7 | G19: 1 | H19: 0 | I19: 2 | J19: 0 | K19: 2 | L19: 0 | M19: 14 | N19: 0 | O19: =SUM(C19:L19,N19) -> 24 | P19: =SUM(C19:N19) -> 38 | R19: 1600-1700 | S19: =SUM(C46:C49) -> 23 | T19: =SUM(D46:D49) -> 0 | U19: =SUM(E46:E49) -> 21 | V19: =SUM(F46:F49) -> 18 | W19: =SUM(G46:G49) -> 6 | X19: =SUM(H46:H49) -> 0 | Y19: =SUM(I46:I49) -> 17 | Z19: =SUM(J46:J49) -> 2 | ... AF19: =SUM(P46:P49) -> 230
B20: 09.30 - 09.45 | C20: 2 | D20: 0 | E20: 7 | F20: 3 | G20: 0 | H20: 0 | I20: 1 | J20: 0 | K20: 1 | L20: 0 | M20: 26 | N20: 0 | O20: =SUM(C20:L20,N20) -> 14 | P20: =SUM(C20:N20) -> 40 | R20: 1700-1800 | S20: =SUM(C50:C53) -> 13 | T20: =SUM(D50:D53) -> 0 | U20: =SUM(E50:E53) -> 32 | V20: =SUM(F50:F53) -> 17 | W20: =SUM(G50:G53) -> 3 | X20: =SUM(H50:H53) -> 3 | Y20: =SUM(I50:I53) -> 38 | Z20: =SUM(J50:J53) -> 1 | ... AF20: =SUM(P50:P53) -> 231
B21: 09.45 - 10.00 | C21: 6 | D21: 0 | E21: 5 | F21: 2 | G21: 0 | H21: 0 | I21: 0 | J21: 0 | K21: 0 | L21: 0 | M21: 17 | N21: 0 | O21: =SUM(C21:L21,N21) -> 13 | P21: =SUM(C21:N21) -> 30 | R21: 1800-1900 | S21: =SUM(C54:C57) -> 22 | T21: =SUM(D54:D57) -> 0 | U21: =SUM(E54:E57) -> 28 | V21: =SUM(F54:F57) -> 11 | W21: =SUM(G54:G57) -> 4 | X21: =SUM(H54:H57) -> 4 | Y21: =SUM(I54:I57) -> 12 | Z21: =SUM(J54:J57) -> 2 | ... AF21: =SUM(P54:P57) -> 205
