Workbook

Sheet 22.07 Kibuye-Munyonyo
B1: Consultancy services for Preparation of Expressway Development Master Plan (EDMP) for Uganda
B2: MANUAL CLASSIFIED COUNT (MCC)
B3: ROAD NAME: | C3: MCC - C1 - STN01A - SALAMA ROAD
C5: Date | D5: 22.07.19 | F5: Location | G5: Salama road 1A | J5: Surveyor | K5: Racheal
C6: Dir. From | D6: Kibuye | F6: Dir. To | G6: Munyonyo | J6: Supervisor | K6: Emma
B8: Time / Veh Type | R8: SUMMARY TRAFFIC VOLUMES
C9: 1. Car | D9: 2. Station Wagon | E9: 3. Pickups | F9: 4. Minibus, matatu | G9: 5. Medium bus | H9: 6. Large Bus | I9: 7. Light Truck | J9: 8. Medium Truck | K9: 9. Heavy truck | L9: 10. Truck Trailer | M9: 11. Motor cycles | N9: 12. Tractors | O9: Total Excl M/Cycles | P9: Total All | R9: Time | S9: 1. Car | T9: 2. Station Wagon | U9: 3. Pickups | V9: 4. Minibus, matatu | W9: 5. Medium bus | X9: 6. Large Bus | Y9: 7. Light Truck | Z9: 8. Medium Truck | AA9: 9. Heavy truck | AB9: 10. Truck Trailer | AC9: 11. Motorcycles | AD9: 12. Tractors, Graders | AE9: Total Excl M/ Cycles | AF9: Total All
B10: 07.00 - 07.15 | C10: 0 | D10: 0 | E10: 0 | F10: 4 | G10: 0 | H10: 0 | I10: 0 | J10: 0 | K10: 0 | L10: 0 | M10: 1 | N10: 0 | O10: =SUM(C10:L10,N10) -> 4 | P10: =SUM(C10:N10) -> 5 | R10: 0700-0800 | S10: =SUM(C10:C13) -> 0 | T10: =SUM(D10:D13) -> 4 | U10: =SUM(E10:E13) -> 2 | V10: =SUM(F10:F13) -> 60 | W10: =SUM(G10:G13) -> 0 | X10: =SUM(H10:H13) -> 1 | Y10: =SUM(I10:I13) -> 1 | Z10: =SUM(J10:J13) -> 0 | ... AF10: =SUM(P10:P13) -> 199
B11: 07.15 - 07.30 | C11: 0 | D11: 0 | E11: 0 | F11: 0 | G11: 0 | H11: 0 | I11: 0 | J11: 0 | K11: 0 | L11: 0 | M11: 0 | N11: 0 | O11: =SUM(C11:L11,N11) -> 0 | P11: =SUM(C11:N11) -> 0 | R11: 0800-0900 | S11: =SUM(C14:C17) -> 29 | T11: =SUM(D14:D17) -> 23 | U11: =SUM(E14:E17) -> 4 | V11: =SUM(F14:F17) -> 240 | W11: =SUM(G14:G17) -> 3 | X11: =SUM(H14:H17) -> 0 | Y11: =SUM(I14:I17) -> 5 | Z11: =SUM(J14:J17) -> 1 | ... AF11: =SUM(P14:P17) -> 945
B12: 07.30 - 07.45 | C12: 0 | D12: 0 | E12: 0 | F12: 0 | G12: 0 | H12: 0 | I12: 0 | J12: 0 | K12: 0 | L12: 0 | M12: 2 | N12: 0 | O12: =SUM(C12:L12,N12) -> 0 | P12: =SUM(C12:N12) -> 2 | R12: 0900-1000 | S12: =SUM(C18:C21) -> 26 | T12: =SUM(D18:D21) -> 25 | U12: =SUM(E18:E21) -> 8 | V12: =SUM(F18:F21) -> 178 | W12: =SUM(G18:G21) -> 2 | X12: =SUM(H18:H21) -> 3 | Y12: =SUM(I18:I21) -> 9 | Z12: =SUM(J18:J21) -> 1 | ... AF12: =SUM(P18:P21) -> 871
B13: 07.45 - 08.00 | C13: 0 | D13: 4 | E13: 2 | F13: 56 | G13: 0 | H13: 1 | I13: 1 | J13: 0 | K13: 0 | L13: 0 | M13: 128 | N13: 0 | O13: =SUM(C13:L13,N13) -> 64 | P13: =SUM(C13:N13) -> 192 | R13: 1000-1100 | S13: =SUM(C22:C25) -> 47 | T13: =SUM(D22:D25) -> 18 | U13: =SUM(E22:E25) -> 8 | V13: =SUM(F22:F25) -> 112 | W13: =SUM(G22:G25) -> 0 | X13: =SUM(H22:H25) -> 0 | Y13: =SUM(I22:I25) -> 15 | Z13: =SUM(J22:J25) -> 0 | ... AF13: =SUM(P22:P25) -> 705
B14: 08.00 - 08.15 | C14: 12 | D14: 7 | E14: 1 | F14: 61 | G14: 2 | H14: 0 | I14: 0 | J14: 0 | K14: 0 | L14: 0 | M14: 135 | N14: 0 | O14: =SUM(C14:L14,N14) -> 83 | P14: =SUM(C14:N14) -> 218 | R14: 1100-1200 | S14: =SUM(C26:C29) -> 71 | T14: =SUM(D26:D29) -> 20 | U14: =SUM(E26:E29) -> 5 | V14: =SUM(F26:F29) -> 131 | W14: =SUM(G26:G29) -> 0 | X14: =SUM(H26:H29) -> 0 | Y14: =SUM(I26:I29) -> 19 | Z14: =SUM(J26:J29) -> 3 | ... AF14: =SUM(P26:P29) -> 808
B15: 08.15 - 08.30 | C15: 6 | D15: 5 | E15: 0 | F15: 68 | G15: 0 | H15: 0 | I15: 2 | J15: 1 | K15: 0 | L15: 0 | M15: 195 | N15: 0 | O15: =SUM(C15:L15,N15) -> 82 | P15: =SUM(C15:N15) -> 277 | R15: 1200-1300 | S15: =SUM(C30:C33) -> 58 | T15: =SUM(D30:D33) -> 30 | U15: =SUM(E30:E33) -> 11 | V15: =SUM(F30:F33) -> 101 | W15: =SUM(G30:G33) -> 0 | X15: =SUM(H30:H33) -> 0 | Y15: =SUM(I30:I33) -> 19 | Z15: =SUM(J30:J33) -> 0 | ... AF15: =SUM(P30:P33) -> 710
B16: 08.30 - 08.45 | C16: 6 | D16: 4 | E16: 2 | F16: 57 | G16: 0 | H16: 0 | I16: 3 | J16: 0 | K16: 0 | L16: 0 | M16: 140 | N16: 0 | O16: =SUM(C16:L16,N16) -> 72 | P16: =SUM(C16:N16) -> 212 | R16: 1300-1400 | S16: =SUM(C34:C37) -> 76 | T16: =SUM(D34:D37) -> 32 | U16: =SUM(E34:E37) -> 11 | V16: =SUM(F34:F37) -> 100 | W16: =SUM(G34:G37) -> 0 | X16: =SUM(H34:H37) -> 0 | Y16: =SUM(I34:I37) -> 18 | Z16: =SUM(J34:J37) -> 0 | ... AF16: =SUM(P34:P37) -> 742
B17: 08.45 - 9.00 | C17: 5 | D17: 7 | E17: 1 | F17: 54 | G17: 1 | H17: 0 | I17: 0 | J17: 0 | K17: 0 | L17: 0 | M17: 170 | N17: 0 | O17: =SUM(C17:L17,N17) -> 68 | P17: =SUM(C17:N17) -> 238 | R17: 1400-1500 | S17: =SUM(C38:C41) -> 74 | T17: =SUM(D38:D41) -> 37 | U17: =SUM(E38:E41) -> 9 | V17: =SUM(F38:F41) -> 87 | W17: =SUM(G38:G41) -> 0 | X17: =SUM(H38:H41) -> 0 | Y17: =SUM(I38:I41) -> 25 | Z17: =SUM(J38:J41) -> 1 | ... AF17: =SUM(P38:P41) -> 644
B18: 09.00 - 09.15 | C18: 6 | D18: 9 | E18: 2 | F18: 50 | G18: 0 | H18: 0 | I18: 0 | J18: 0 | K18: 0 | L18: 0 | M18: 161 | N18: 0 | O18: =SUM(C18:L18,N18) -> 67 | P18: =SUM(C18:N18) -> 228 | R18: 1500-1600 | S18: =SUM(C42:C45) -> 50 | T18: =SUM(D42:D45) -> 30 | U18: =SUM(E42:E45) -> 6 | V18: =SUM(F42:F45) -> 31 | W18: =SUM(G42:G45) -> 0 | X18: =SUM(H42:H45) -> 0 | Y18: =SUM(I42:I45) -> 9 | Z18: =SUM(J42:J45) -> 2 | ... AF18: =SUM(P42:P45) -> 201
B19: 09.15 - 09.30 | C19: 6 | D19: 4 | E19: 2 | F19: 51 | G19: 1 | H19: 0 | I19: 5 | J19: 1 | K19: 0 | L19: 0 | M19: 181 | N19: 0 | O19: =SUM(C19:L19,N19) -> 70 | P19: =SUM(C19:N19) -> 251 | R19: 1600-1700 | S19: =SUM(C46:C49) -> 99 | T19: =SUM(D46:D49) -> 73 | U19: =SUM(E46:E49) -> 13 | V19: =SUM(F46:F49) -> 118 | W19: =SUM(G46:G49) -> 3 | X19: =SUM(H46:H49) -> 0 | Y19: =SUM(I46:I49) -> 17 | Z19: =SUM(J46:J49) -> 4 | ... AF19: =SUM(P46:P49) -> 763
B20: 09.30 - 09.45 | C20: 7 | D20: 5 | E20: 3 | F20: 42 | G20: 0 | H20: 2 | I20: 2 | J20: 0 | K20: 0 | L20: 0 | M20: 155 | N20: 0 | O20: =SUM(C20:L20,N20) -> 61 | P20: =SUM(C20:N20) -> 216 | R20: 1700-1800 | S20: =SUM(C50:C53) -> 123 | T20: =SUM(D50:D53) -> 47 | U20: =SUM(E50:E53) -> 14 | V20: =SUM(F50:F53) -> 118 | W20: =SUM(G50:G53) -> 3 | X20: =SUM(H50:H53) -> 0 | Y20: =SUM(I50:I53) -> 24 | Z20: =SUM(J50:J53) -> 2 | ... AF20: =SUM(P50:P53) -> 751
B21: 09.45 - 10.00 | C21: 7 | D21: 7 | E21: 1 | F21: 35 | G21: 1 | H21: 1 | I21: 2 | J21: 0 | K21: 0 | L21: 0 | M21: 122 | N21: 0 | O21: =SUM(C21:L21,N21) -> 54 | P21: =SUM(C21:N21) -> 176 | R21: 1800-1900 | S21: =SUM(C54:C57) -> 96 | T21: =SUM(D54:D57) -> 72 | U21: =SUM(E54:E57) -> 8 | V21: =SUM(F54:F57) -> 143 | W21: =SUM(G54:G57) -> 3 | X21: =SUM(H54:H57) -> 0 | Y21: =SUM(I54:I57) -> 20 | Z21: =SUM(J54:J57) -> 1 | ... AF21: =SUM(P54:P57) -> 894
B22: 10.00 - 10.15 | C22: 10 | D22: 3 | E22: 1 | F22: 27 | G22: 0 | H22: 0 | I22: 3 | J22: 0 | K22: 0 | L22: 0 | M22: 137 | N22: 0 | O22: =SUM(C22:L22,N22) -> 44 | P22: =SUM(C22:N22) -> 181 | R22: AM Peak Hr | S22: =MAX(S10:S12) -> 29 | T22: =MAX(T10:T12) -> 25 | U22: =MAX(U10:U12) -> 8 | V22: =MAX(V10:V12) -> 240 | W22: =MAX(W10:W12) -> 3 | X22: =MAX(X10:X12) -> 3 | Y22: =MAX(Y10:Y12) -> 9 | Z22: =MAX(Z10:Z12) -> 1 | ... AF22: =MAX(AF10:AF12) -> 945
B23: 10.15 - 10.30 | C23: 12 | D23: 4 | E23: 4 | F23: 35 | G23: 0 | H23: 0 | I23: 0 | J23: 0 | K23: 0 | L23: 0 | M23: 135 | N23: 0 | O23: =SUM(C23:L23,N23) -> 55 | P23: =SUM(C23:N23) -> 190 | R23: IP Peak Hr | S23: =MAX(S13:S18) -> 76 | T23: =MAX(T13:T18) -> 37 | U23: =MAX(U13:U18) -> 11 | V23: =MAX(V13:V18) -> 131 | W23: =MAX(W13:W18) -> 0 | X23: =MAX(X13:X18) -> 0 | Y23: =MAX(Y13:Y18) -> 25 | Z23: =MAX(Z13:Z18) -> 3 | ... AF23: =MAX(AF13:AF18) -> 808
B24: 10.30 - 10.45 | C24: 14 | D24: 3 | E24: 2 | F24: 28 | G24: 0 | H24: 0 | I24: 9 | J24: 0 | K24: 0 | L24: 0 | M24: 132 | N24: 0 | O24: =SUM(C24:L24,N24) -> 56 | P24: =SUM(C24:N24) -> 188 | R24: PM Peak Hr | S24: =MAX(S19:S21) -> 123 | T24: =MAX(T19:T21) -> 73 | U24: =MAX(U19:U21) -> 14 | V24: =MAX(V19:V21) -> 143 | W24: =MAX(W19:W21) -> 3 | X24: =MAX(X19:X21) -> 0 | Y24: =MAX(Y19:Y21) -> 24 | Z24: =MAX(Z19:Z21) -> 4 | ... AF24: =MAX(AF19:AF21) -> 894
B25: 10.45 - 11.00 | C25: 11 | D25: 8 | E25: 1 | F25: 22 | G25: 0 | H25: 0 | I25: 3 | J25: 0 | K25: 0 | L25: 0 | M25: 101 | N25: 0 | O25: =SUM(C25:L25,N25) -> 45 | P25: =SUM(C25:N25) -> 146 | R25: AM Period | S25: =SUM(S10:S12) -> 55 | T25: =SUM(T10:T12) -> 52 | U25: =SUM(U10:U12) -> 14 | V25: =SUM(V10:V12) -> 478 | W25: =SUM(W10:W12) -> 5 | X25: =SUM(X10:X12) -> 4 | Y25: =SUM(Y10:Y12) -> 15 | Z25: =SUM(Z10:Z12) -> 2 | ... AF25: =SUM(AF10:AF12) -> 2015
B26: 11.00 - 11.15 | C26: 23 | D26: 6 | E26: 1 | F26: 38 | G26: 0 | H26: 0 | I26: 0 | J26: 0 | K26: 0 | L26: 0 | M26: 143 | N26: 0 | O26: =SUM(C26:L26,N26) -> 68 | P26: =SUM(C26:N26) -> 211 | R26: IP Period | S26: =SUM(S13:S18) -> 376 | T26: =SUM(T13:T18) -> 167 | U26: =SUM(U13:U18) -> 50 | V26: =SUM(V13:V18) -> 562 | W26: =SUM(W13:W18) -> 0 | X26: =SUM(X13:X18) -> 0 | Y26: =SUM(Y13:Y18) -> 105 | Z26: =SUM(Z13:Z18) -> 6 | ... AF26: =SUM(AF13:AF18) -> 3810
B27: 11.15 - 11.30 | C27: 19 | D27: 5 | E27: 1 | F27: 38 | G27: 0 | H27: 0 | I27: 8 | J27: 2 | K27: 0 | L27: 0 | M27: 140 | N27: 0 | O27: =SUM(C27:L27,N27) -> 73 | P27: =SUM(C27:N27) -> 213 | R27: PM Period | S27: =SUM(S19:S21) -> 318 | T27: =SUM(T19:T21) -> 192 | U27: =SUM(U19:U21) -> 35 | V27: =SUM(V19:V21) -> 379 | W27: =SUM(W19:W21) -> 9 | X27: =SUM(X19:X21) -> 0 | Y27: =SUM(Y19:Y21) -> 61 | Z27: =SUM(Z19:Z21) -> 7 | ... AF27: =SUM(AF19:AF21) -> 2408
B28: 11.30 - 11.45 | C28: 19 | D28: 6 | E28: 2 | F28: 21 | G28: 0 | H28: 0 | I28: 3 | J28: 1 | K28: 0 | L28: 0 | M28: 151 | N28: 0 | O28: =SUM(C28:L28,N28) -> 52 | P28: =SUM(C28:N28) -> 203 | R28: 12 Hours | S28: =SUM(S10:S21) -> 749 | T28: =SUM(T10:T21) -> 411 | U28: =SUM(U10:U21) -> 99 | V28: =SUM(V10:V21) -> 1419 | W28: =SUM(W10:W21) -> 14 | X28: =SUM(X10:X21) -> 4 | Y28: =SUM(Y10:Y21) -> 181 | Z28: =SUM(Z10:Z21) -> 15 | ... AF28: =SUM(AF10:AF21) -> 8233
B29: 11.45 - 12.00 | C29: 10 | D29: 3 | E29: 1 | F29: 34 | G29: 0 | H29: 0 | I29: 8 | J29: 0 | K29: 0 | L29: 0 | M29: 125 | N29: 0 | O29: =SUM(C29:L29,N29) -> 56 | P29: =SUM(C29:N29) -> 181
B30: 12.00 - 12.15 | C30: 9 | D30: 6 | E30: 3 | F30: 27 | G30: 0 | H30: 0 | I30: 5 | J30: 0 | K30: 0 | L30: 0 | M30: 125 | N30: 0 | O30: =SUM(C30:L30,N30) -> 50 | P30: =SUM(C30:N30) -> 175
B31: 12.15 - 12.30 | C31: 20 | D31: 12 | E31: 3 | F31: 26 | G31: 0 | H31: 0 | I31: 6 | J31: 0 | K31: 0 | L31: 0 | M31: 164 | N31: 0 | O31: =SUM(C31:L31,N31) -> 67 | P31: =SUM(C31:N31) -> 231
B32: 12.30 - 12.45 | C32: 16 | D32: 7 | E32: 1 | F32: 22 | G32: 0 | H32: 0 | I32: 1 | J32: 0 | K32: 0 | L32: 0 | M32: 91 | N32: 0 | O32: =SUM(C32:L32,N32) -> 47 | P32: =SUM(C32:N32) -> 138
B33: 12.45 - 13.00 | C33: 13 | D33: 5 | E33: 4 | F33: 26 | G33: 0 | H33: 0 | I33: 7 | J33: 0 | K33: 1 | L33: 0 | M33: 110 | N33: 0 | O33: =SUM(C33:L33,N33) -> 56 | P33: =SUM(C33:N33) -> 166
B34: 13.00 - 13.15 | C34: 11 | D34: 11 | E34: 5 | F34: 21 | G34: 0 | H34: 0 | I34: 3 | J34: 0 | K34: 0 | L34: 0 | M34: 105 | N34: 0 | O34: =SUM(C34:L34,N34) -> 51 | P34: =SUM(C34:N34) -> 156
B35: 13.15 - 13.30 | C35: 25 | D35: 6 | E35: 2 | F35: 21 | G35: 0 | H35: 0 | I35: 6 | J35: 0 | K35: 0 | L35: 0 | M35: 144 | N35: 0 | O35: =SUM(C35:L35,N35) -> 60 | P35: =SUM(C35:N35) -> 204
B36: 13.30 - 13.45 | C36: 24 | D36: 4 | E36: 2 | F36: 34 | G36: 0 | H36: 0 | I36: 3 | J36: 0 | K36: 1 | L36: 0 | M36: 131 | N36: 0 | O36: =SUM(C36:L36,N36) -> 68 | P36: =SUM(C36:N36) -> 199
B37: 13.45 - 14.00 | C37: 16 | D37: 11 | E37: 2 | F37: 24 | G37: 0 | H37: 0 | I37: 6 | J37: 0 | K37: 0 | L37: 0 | M37: 124 | N37: 0 | O37: =SUM(C37:L37,N37) -> 59 | P37: =SUM(C37:N37) -> 183
B38: 14.00 - 14.15 | C38: 27 | D38: 7 | E38: 2 | F38: 34 | G38: 0 | H38: 0 | I38: 4 | J38: 0 | K38: 0 | L38: 0 | M38: 135 | N38: 0 | O38: =SUM(C38:L38,N38) -> 74 | P38: =SUM(C38:N38) -> 209
B39: 14.15 - 14.30 | C39: 15 | D39: 11 | E39: 2 | F39: 20 | G39: 0 | H39: 0 | I39: 6 | J39: 0 | K39: 0 | L39: 0 | M39: 125 | N39: 0 | O39: =SUM(C39:L39,N39) -> 54 | P39: =SUM(C39:N39) -> 179
B40: 14.30 - 14.45 | C40: 17 | D40: 12 | E40: 2 | F40: 22 | G40: 0 | H40: 0 | I40: 7 | J40: 1 | K40: 0 | L40: 0 | M40: 122 | N40: 0 | O40: =SUM(C40:L40,N40) -> 61 | P40: =SUM(C40:N40) -> 183
... B57: 18.45 - 19.00 | C57: 28 | D57: 19 | E57: 1 | F57: 39 | G57: 0 | H57: 0 | I57: 2 | J57: 0 | K57: 0 | L57: 0 | M57: 150 | N57: 0 | O57: =SUM(C57:L57,N57) -> 89 | P57: =SUM(C57:N57) -> 239
B58: Totals | C58: =SUM(C10:C57) -> 749 | D58: =SUM(D10:D57) -> 411 | E58: =SUM(E10:E57) -> 99 | F58: =SUM(F10:F57) -> 1419 | G58: =SUM(G10:G57) -> 14 | H58: =SUM(H10:H57) -> 4 | I58: =SUM(I10:I57) -> 181 | J58: =SUM(J10:J57) -> 15 | ... P58: =SUM(P10:P57) -> 8233
...

Sheet 22.07 Munyonyo-Kibuye
B1: Consultancy services for Preparation of Expressway Development Master Plan (EDMP) for Uganda
B2: MANUAL CLASSIFIED COUNT (MCC)
B3: ROAD NAME: | C3: ='22.07 Kibuye-Munyonyo'!C3:G3 -> MCC - C1 - STN01A - SALAMA ROAD
C5: Date | D5: ='22.07 Kibuye-Munyonyo'!D5 -> 22.07.19 | F5: Location | G5: ='22.07 Kibuye-Munyonyo'!G5:H5 -> Salama road 1A | J5: Surveyor | K5: Gerald
C6: Dir. From | D6: Munyonyo | F6: Dir. To | G6: Kibuye | J6: Supervisor | K6: ='22.07 Kibuye-Munyonyo'!K6:L6 -> Emma
B8: Time / Veh Type | R8: SUMMARY TRAFFIC VOLUMES
C9: 1. Car | D9: 2. Station Wagon | E9: 3. Pickups | F9: 4. Minibus, matatu | G9: 5. Medium bus | H9: 6. Large Bus | I9: 7. Light Truck | J9: 8. Medium Truck | K9: 9. Heavy truck | L9: 10. Truck Trailer | M9: 11. Motor cycles | N9: 12. Tractors | O9: Total Excl M/Cycles | P9: Total All | R9: Time | S9: 1. Car | T9: 2. Station Wagon | U9: 3. Pickups | V9: 4. Minibus, matatu | W9: 5. Medium bus | X9: 6. Large Bus | Y9: 7. Light Truck | Z9: 8. Medium Truck | AA9: 9. Heavy truck | AB9: 10. Truck Trailer | AC9: 11. Motorcycles | AD9: 12. Tractors, Graders | AE9: Total Excl M/ Cycles | AF9: Total All
B10: 07.00 - 07.15 | C10: 5 | D10: 2 | E10: 0 | F10: 15 | G10: 0 | H10: 0 | I10: 0 | J10: 0 | K10: 0 | L10: 0 | M10: 83 | N10: 0 | O10: =SUM(C10:L10,N10) -> 22 | P10: =SUM(C10:N10) -> 105 | R10: 0700-0800 | S10: =SUM(C10:C13) -> 17 | T10: =SUM(D10:D13) -> 4 | U10: =SUM(E10:E13) -> 2 | V10: =SUM(F10:F13) -> 46 | W10: =SUM(G10:G13) -> 0 | X10: =SUM(H10:H13) -> 0 | Y10: =SUM(I10:I13) -> 1 | Z10: =SUM(J10:J13) -> 0 | ... AF10: =SUM(P10:P13) -> 263
B11: 07.15 - 07.30 | C11: 0 | D11: 0 | E11: 0 | F11: 0 | G11: 0 | H11: 0 | I11: 0 | J11: 0 | K11: 0 | L11: 0 | M11: 0 | N11: 0 | O11: =SUM(C11:L11,N11) -> 0 | P11: =SUM(C11:N11) -> 0 | R11: 0800-0900 | S11: =SUM(C14:C17) -> 126 | T11: =SUM(D14:D17) -> 51 | U11: =SUM(E14:E17) -> 24 | V11: =SUM(F14:F17) -> 247 | W11: =SUM(G14:G17) -> 3 | X11: =SUM(H14:H17) -> 0 | Y11: =SUM(I14:I17) -> 24 | Z11: =SUM(J14:J17) -> 0 | ... AF11: =SUM(P14:P17) -> 1390
B12: 07.30 - 07.45 | C12: 0 | D12: 0 | E12: 0 | F12: 0 | G12: 0 | H12: 0 | I12: 0 | J12: 0 | K12: 0 | L12: 0 | M12: 0 | N12: 0 | O12: =SUM(C12:L12,N12) -> 0 | P12: =SUM(C12:N12) -> 0 | R12: 0900-1000 | S12: =SUM(C18:C21) -> 131 | T12: =SUM(D18:D21) -> 61 | U12: =SUM(E18:E21) -> 21 | V12: =SUM(F18:F21) -> 200 | W12: =SUM(G18:G21) -> 1 | X12: =SUM(H18:H21) -> 0 | Y12: =SUM(I18:I21) -> 10 | Z12: =SUM(J18:J21) -> 4 | ... AF12: =SUM(P18:P21) -> 1323
B13: 07.45 - 08.00 | C13: 12 | D13: 2 | E13: 2 | F13: 31 | G13: 0 | H13: 0 | I13: 1 | J13: 0 | K13: 0 | L13: 0 | M13: 110 | N13: 0 | O13: =SUM(C13:L13,N13) -> 48 | P13: =SUM(C13:N13) -> 158 | R13: 1000-1100 | S13: =SUM(C22:C25) -> 86 | T13: =SUM(D22:D25) -> 45 | U13: =SUM(E22:E25) -> 10 | V13: =SUM(F22:F25) -> 158 | W13: =SUM(G22:G25) -> 1 | X13: =SUM(H22:H25) -> 0 | Y13: =SUM(I22:I25) -> 14 | Z13: =SUM(J22:J25) -> 1 | ... AF13: =SUM(P22:P25) -> 1019
B14: 08.00 - 08.15 | C14: 30 | D14: 12 | E14: 8 | F14: 61 | G14: 2 | H14: 0 | I14: 9 | J14: 0 | K14: 0 | L14: 0 | M14: 255 | N14: 0 | O14: =SUM(C14:L14,N14) -> 122 | P14: =SUM(C14:N14) -> 377 | R14: 1100-1200 | S14: =SUM(C26:C29) -> 114 | T14: =SUM(D26:D29) -> 32 | U14: =SUM(E26:E29) -> 21 | V14: =SUM(F26:F29) -> 124 | W14: =SUM(G26:G29) -> 2 | X14: =SUM(H26:H29) -> 0 | Y14: =SUM(I26:I29) -> 21 | Z14: =SUM(J26:J29) -> 0 | ... AF14: =SUM(P26:P29) -> 871
B15: 08.15 - 08.30 | C15: 33 | D15: 12 | E15: 6 | F15: 65 | G15: 0 | H15: 0 | I15: 5 | J15: 0 | K15: 0 | L15: 0 | M15: 245 | N15: 0 | O15: =SUM(C15:L15,N15) -> 121 | P15: =SUM(C15:N15) -> 366 | R15: 1200-1300 | S15: =SUM(C30:C33) -> 84 | T15: =SUM(D30:D33) -> 30 | U15: =SUM(E30:E33) -> 10 | V15: =SUM(F30:F33) -> 111 | W15: =SUM(G30:G33) -> 1 | X15: =SUM(H30:H33) -> 0 | Y15: =SUM(I30:I33) -> 15 | Z15: =SUM(J30:J33) -> 2 | ... AF15: =SUM(P30:P33) -> 706
B16: 08.30 - 08.45 | C16: 38 | D16: 14 | E16: 1 | F16: 69 | G16: 0 | H16: 0 | I16: 5 | J16: 0 | K16: 0 | L16: 0 | M16: 185 | N16: 0 | O16: =SUM(C16:L16,N16) -> 127 | P16: =SUM(C16:N16) -> 312 | R16: 1300-1400 | S16: =SUM(C34:C37) -> 59 | T16: =SUM(D34:D37) -> 28 | U16: =SUM(E34:E37) -> 18 | V16: =SUM(F34:F37) -> 78 | W16: =SUM(G34:G37) -> 0 | X16: =SUM(H34:H37) -> 0 | Y16: =SUM(I34:I37) -> 7 | Z16: =SUM(J34:J37) -> 2 | ... AF16: =SUM(P34:P37) -> 481
B17: 08.45 - 9.00 | C17: 25 | D17: 13 | E17: 9 | F17: 52 | G17: 1 | H17: 0 | I17: 5 | J17: 0 | K17: 1 | L17: 0 | M17: 229 | N17: 0 | O17: =SUM(C17:L17,N17) -> 106 | P17: =SUM(C17:N17) -> 335 | R17: 1400-1500 | S17: =SUM(C38:C41) -> 77 | T17: =SUM(D38:D41) -> 21 | U17: =SUM(E38:E41) -> 14 | V17: =SUM(F38:F41) -> 81 | W17: =SUM(G38:G41) -> 0 | X17: =SUM(H38:H41) -> 0 | Y17: =SUM(I38:I41) -> 11 | Z17: =SUM(J38:J41) -> 0 | ... AF17: =SUM(P38:P41) -> 569
B18: 09.00 - 09.15 | C18: 29 | D18: 14 | E18: 5 | F18: 55 | G18: 0 | H18: 0 | I18: 0 | J18: 0 | K18: 0 | L18: 0 | M18: 240 | N18: 0 | O18: =SUM(C18:L18,N18) -> 103 | P18: =SUM(C18:N18) -> 343 | R18: 1500-1600 | S18: =SUM(C42:C45) -> 63 | T18: =SUM(D42:D45) -> 19 | U18: =SUM(E42:E45) -> 11 | V18: =SUM(F42:F45) -> 60 | W18: =SUM(G42:G45) -> 0 | X18: =SUM(H42:H45) -> 0 | Y18: =SUM(I42:I45) -> 11 | Z18: =SUM(J42:J45) -> 0 | ... AF18: =SUM(P42:P45) -> 280
B19: 09.15 - 09.30 | C19: 39 | D19: 18 | E19: 5 | F19: 54 | G19: 0 | H19: 0 | I19: 4 | J19: 1 | K19: 0 | L19: 0 | M19: 230 | N19: 0 | O19: =SUM(C19:L19,N19) -> 121 | P19: =SUM(C19:N19) -> 351 | R19: 1600-1700 | S19: =SUM(C46:C49) -> 107 | T19: =SUM(D46:D49) -> 35 | U19: =SUM(E46:E49) -> 9 | V19: =SUM(F46:F49) -> 88 | W19: =SUM(G46:G49) -> 2 | X19: =SUM(H46:H49) -> 0 | Y19: =SUM(I46:I49) -> 23 | Z19: =SUM(J46:J49) -> 2 | ... AF19: =SUM(P46:P49) -> 749
B20: 09.30 - 09.45 | C20: 29 | D20: 16 | E20: 6 | F20: 49 | G20: 1 | H20: 0 | I20: 0 | J20: 3 | K20: 1 | L20: 0 | M20: 230 | N20: 0 | O20: =SUM(C20:L20,N20) -> 105 | P20: =SUM(C20:N20) -> 335 | R20: 1700-1800 | S20: =SUM(C50:C53) -> 102 | T20: =SUM(D50:D53) -> 26 | U20: =SUM(E50:E53) -> 12 | V20: =SUM(F50:F53) -> 107 | W20: =SUM(G50:G53) -> 3 | X20: =SUM(H50:H53) -> 0 | Y20: =SUM(I50:I53) -> 13 | Z20: =SUM(J50:J53) -> 1 | ... AF20: =SUM(P50:P53) -> 822
B21: 09.45 - 10.00 | C21: 34 | D21: 13 | E21: 5 | F21: 42 | G21: 0 | H21: 0 | I21: 6 | J21: 0 | K21: 0 | L21: 0 | M21: 194 | N21: 0 | O21: =SUM(C21:L21,N21) -> 100 | P21: =SUM(C21:N21) -> 294 | R21: 1800-1900 | S21: =SUM(C54:C57) -> 60 | T21: =SUM(D54:D57) -> 25 | U21: =SUM(E54:E57) -> 6 | V21: =SUM(F54:F57) -> 108 | W21: =SUM(G54:G57) -> 2 | X21: =SUM(H54:H57) -> 1 | Y21: =SUM(I54:I57) -> 8 | Z21: =SUM(J54:J57) -> 5 | ... AF21: =SUM(P54:P57) -> 729
B22: 10.00 - 10.15 | C22: 21 | D22: 15 | E22: 2 | F22: 56 | G22: 0 | H22: 0 | I22: 3 | J22: 0 | K22: 0 | L22: 0 | M22: 210 | N22: 0 | O22: =SUM(C22:L22,N22) -> 97 | P22: =SUM(C22:N22) -> 307 | R22: AM Peak Hr | S22: =MAX(S10:S12) -> 131 | T22: =MAX(T10:T12) -> 61 | U22: =MAX(U10:U12) -> 24 | V22: =MAX(V10:V12) -> 247 | W22: =MAX(W10:W12) -> 3 | X22: =MAX(X10:X12) -> 0 | Y22: =MAX(Y10:Y12) -> 24 | Z22: =MAX(Z10:Z12) -> 4 | ... AF22: =MAX(AF10:AF12) -> 1390
B23: 10.15 - 10.30 | C23: 23 | D23: 12 | E23: 1 | F23: 40 | G23: 1 | H23: 0 | I23: 3 | J23: 1 | K23: 0 | L23: 0 | M23: 191 | N23: 0 | O23: =SUM(C23:L23,N23) -> 81 | P23: =SUM(C23:N23) -> 272 | R23: IP Peak Hr | S23: =MAX(S13:S18) -> 114 | T23: =MAX(T13:T18) -> 45 | U23: =MAX(U13:U18) -> 21 | V23: =MAX(V13:V18) -> 158 | W23: =MAX(W13:W18) -> 2 | X23: =MAX(X13:X18) -> 0 | Y23: =MAX(Y13:Y18) -> 21 | Z23: =MAX(Z13:Z18) -> 2 | ... AF23: =MAX(AF13:AF18) -> 1019
B24: 10.30 - 10.45 | C24: 21 | D24: 8 | E24: 6 | F24: 28 | G24: 0 | H24: 0 | I24: 5 | J24: 0 | K24: 0 | L24: 0 | M24: 166 | N24: 0 | O24: =SUM(C24:L24,N24) -> 68 | P24: =SUM(C24:N24) -> 234 | R24: PM Peak Hr | S24: =MAX(S19:S21) -> 107 | T24: =MAX(T19:T21) -> 35 | U24: =MAX(U19:U21) -> 12 | V24: =MAX(V19:V21) -> 108 | W24: =MAX(W19:W21) -> 3 | X24: =MAX(X19:X21) -> 1 | Y24: =MAX(Y19:Y21) -> 23 | Z24: =MAX(Z19:Z21) -> 5 | ... AF24: =MAX(AF19:AF21) -> 822
B25: 10.45 - 11.00 | C25: 21 | D25: 10 | E25: 1 | F25: 34 | G25: 0 | H25: 0 | I25: 3 | J25: 0 | K25: 0 | L25: 0 | M25: 137 | N25: 0 | O25: =SUM(C25:L25,N25) -> 69 | P25: =SUM(C25:N25) -> 206 | R25: AM Period | S25: =SUM(S10:S12) -> 274 | T25: =SUM(T10:T12) -> 116 | U25: =SUM(U10:U12) -> 47 | V25: =SUM(V10:V12) -> 493 | W25: =SUM(W10:W12) -> 4 | X25: =SUM(X10:X12) -> 0 | Y25: =SUM(Y10:Y12) -> 35 | Z25: =SUM(Z10:Z12) -> 4 | ... AF25: =SUM(AF10:AF12) -> 2976
B26: 11.00 - 11.15 | C26: 32 | D26: 5 | E26: 4 | F26: 36 | G26: 0 | H26: 0 | I26: 6 | J26: 0 | K26: 0 | L26: 0 | M26: 125 | N26: 0 | O26: =SUM(C26:L26,N26) -> 83 | P26: =SUM(C26:N26) -> 208 | R26: IP Period | S26: =SUM(S13:S18) -> 483 | T26: =SUM(T13:T18) -> 175 | U26: =SUM(U13:U18) -> 84 | V26: =SUM(V13:V18) -> 612 | W26: =SUM(W13:W18) -> 4 | X26: =SUM(X13:X18) -> 0 | Y26: =SUM(Y13:Y18) -> 79 | Z26: =SUM(Z13:Z18) -> 5 | ... AF26: =SUM(AF13:AF18) -> 3926
B27: 11.15 - 11.30 | C27: 24 | D27: 6 | E27: 4 | F27: 26 | G27: 1 | H27: 0 | I27: 5 | J27: 0 | K27: 0 | L27: 0 | M27: 135 | N27: 0 | O27: =SUM(C27:L27,N27) -> 66 | P27: =SUM(C27:N27) -> 201 | R27: PM Period | S27: =SUM(S19:S21) -> 269 | T27: =SUM(T19:T21) -> 86 | U27: =SUM(U19:U21) -> 27 | V27: =SUM(V19:V21) -> 303 | W27: =SUM(W19:W21) -> 7 | X27: =SUM(X19:X21) -> 1 | Y27: =SUM(Y19:Y21) -> 44 | Z27: =SUM(Z19:Z21) -> 8 | ... AF27: =SUM(AF19:AF21) -> 2300
B28: 11.30 - 11.45 | C28: 30 | D28: 14 | E28: 7 | F28: 33 | G28: 0 | H28: 0 | I28: 7 | J28: 0 | K28: 0 | L28: 0 | M28: 163 | N28: 0 | O28: =SUM(C28:L28,N28) -> 91 | P28: =SUM(C28:N28) -> 254 | R28: 12 Hours | S28: =SUM(S10:S21) -> 1026 | T28: =SUM(T10:T21) -> 377 | U28: =SUM(U10:U21) -> 158 | V28: =SUM(V10:V21) -> 1408 | W28: =SUM(W10:W21) -> 15 | X28: =SUM(X10:X21) -> 1 | Y28: =SUM(Y10:Y21) -> 158 | Z28: =SUM(Z10:Z21) -> 17 | ... AF28: =SUM(AF10:AF21) -> 9202
B29: 11.45 - 12.00 | C29: 28 | D29: 7 | E29: 6 | F29: 29 | G29: 1 | H29: 0 | I29: 3 | J29: 0 | K29: 0 | L29: 0 | M29: 134 | N29: 0 | O29: =SUM(C29:L29,N29) -> 74 | P29: =SUM(C29:N29) -> 208
B30: 12.00 - 12.15 | C30: 29 | D30: 6 | E30: 4 | F30: 30 | G30: 0 | H30: 0 | I30: 7 | J30: 0 | K30: 0 | L30: 0 | M30: 128 | N30: 0 | O30: =SUM(C30:L30,N30) -> 76 | P30: =SUM(C30:N30) -> 204
B31: 12.15 - 12.30 | C31: 23 | D31: 9 | E31: 4 | F31: 29 | G31: 0 | H31: 0 | I31: 6 | J31: 0 | K31: 0 | L31: 0 | M31: 130 | N31: 0 | O31: =SUM(C31:L31,N31) -> 71 | P31: =SUM(C31:N31) -> 201
B32: 12.30 - 12.45 | C32: 22 | D32: 8 | E32: 0 | F32: 26 | G32: 1 | H32: 0 | I32: 1 | J32: 0 | K32: 0 | L32: 0 | M32: 108 | N32: 0 | O32: =SUM(C32:L32,N32) -> 58 | P32: =SUM(C32:N32) -> 166
B33: 12.45 - 13.00 | C33: 10 | D33: 7 | E33: 2 | F33: 26 | G33: 0 | H33: 0 | I33: 1 | J33: 2 | K33: 0 | L33: 0 | M33: 87 | N33: 0 | O33: =SUM(C33:L33,N33) -> 48 | P33: =SUM(C33:N33) -> 135
B34: 13.00 - 13.15 | C34: 18 | D34: 4 | E34: 2 | F34: 13 | G34: 0 | H34: 0 | I34: 2 | J34: 1 | K34: 0 | L34: 0 | M34: 108 | N34: 0 | O34: =SUM(C34:L34,N34) -> 40 | P34: =SUM(C34:N34) -> 148
B35: 13.15 - 13.30 | C35: 7 | D35: 11 | E35: 8 | F35: 33 | G35: 0 | H35: 0 | I35: 2 | J35: 0 | K35: 0 | L35: 0 | M35: 67 | N35: 0 | O35: =SUM(C35:L35,N35) -> 61 | P35: =SUM(C35:N35) -> 128
B36: 13.30 - 13.45 | C36: 20 | D36: 11 | E36: 7 | F36: 20 | G36: 0 | H36: 0 | I36: 3 | J36: 1 | K36: 0 | L36: 0 | M36: 64 | N36: 0 | O36: =SUM(C36:L36,N36) -> 62 | P36: =SUM(C36:N36) -> 126
B37: 13.45 - 14.00 | C37: 14 | D37: 2 | E37: 1 | F37: 12 | G37: 0 | H37: 0 | I37: 0 | J37: 0 | K37: 0 | L37: 0 | M37: 50 | N37: 0 | O37: =SUM(C37:L37,N37) -> 29 | P37: =SUM(C37:N37) -> 79
B38: 14.00 - 14.15 | C38: 16 | D38: 10 | E38: 6 | F38: 26 | G38: 0 | H38: 0 | I38: 4 | J38: 0 | K38: 1 | L38: 0 | M38: 94 | N38: 0 | O38: =SUM(C38:L38,N38) -> 63 | P38: =SUM(C38:N38) -> 157
B39: 14.15 - 14.30 | C39: 25 | D39: 6 | E39: 1 | F39: 10 | G39: 0 | H39: 0 | I39: 1 | J39: 0 | K39: 0 | L39: 0 | M39: 110 | N39: 0 | O39: =SUM(C39:L39,N39) -> 43 | P39: =SUM(C39:N39) -> 153
B40: 14.30 - 14.45 | C40: 17 | D40: 3 | E40: 5 | F40: 22 | G40: 0 | H40: 0 | I40: 4 | J40: 0 | K40: 0 | L40: 0 | M40: 102 | N40: 0 | O40: =SUM(C40:L40,N40) -> 51 | P40: =SUM(C40:N40) -> 153
... B57: 18.45 - 19.00 | C57: 12 | D57: 7 | E57: 3 | F57: 30 | G57: 2 | H57: 0 | I57: 2 | J57: 3 | K57: 0 | L57: 0 | M57: 181 | N57: 0 | O57: =SUM(C57:L57,N57) -> 59 | P57: =SUM(C57:N57) -> 240
B58: Totals | C58: =SUM(C10:C57) -> 1026 | D58: =SUM(D10:D57) -> 377 | E58: =SUM(E10:E57) -> 158 | F58: =SUM(F10:F57) -> 1408 | G58: =SUM(G10:G57) -> 15 | H58: =SUM(H10:H57) -> 1 | I58: =SUM(I10:I57) -> 158 | J58: =SUM(J10:J57) -> 17 | ... P58: =SUM(P10:P57) -> 9202
...

Sheet 23.07 Kibuye-Munyonyo
B1: Consultancy services for Preparation of Expressway Development Master Plan (EDMP) for Uganda
B2: MANUAL CLASSIFIED COUNT (MCC)
B3: ROAD NAME: | C3: ='22.07 Kibuye-Munyonyo'!C3:G3 -> MCC - C1 - STN01A - SALAMA ROAD
C5: Date | D5: 23.07.19 | F5: Location | G5: Salama road 1A | J5: Surveyor | K5: Racheal
C6: Dir. From | D6: ='22.07 Kibuye-Munyonyo'!D6:E6 -> Kibuye | F6: Dir. To | G6: Munyonyo | J6: Supervisor | K6: Emma
B8: Time / Veh Type | R8: SUMMARY TRAFFIC VOLUMES
C9: 1. Car | D9: 2. Station Wagon | E9: 3. Pickups | F9: 4. Minibus, matatu | G9: 5. Medium bus | H9: 6. Large Bus | I9: 7. Light Truck | J9: 8. Medium Truck | K9: 9. Heavy truck | L9: 10. Truck Trailer | M9: 11. Motor cycles | N9: 12. Tractors | O9: Total Excl M/Cycles | P9: Total All | R9: Time | S9: 1. Car | T9: 2. Station Wagon | U9: 3. Pickups | V9: 4. Minibus, matatu | W9: 5. Medium bus | X9: 6. Large Bus | Y9: 7. Light Truck | Z9: 8. Medium Truck | AA9: 9. Heavy truck | AB9: 10. Truck Trailer | AC9: 11. Motorcycles | AD9: 12. Tractors, Graders | AE9: Total Excl M/ Cycles | AF9: Total All
B10: 07.00 - 07.15 | C10: 15 | D10: 10 | E10: 2 | F10: 60 | G10: 0 | H10: 0 | I10: 1 | J10: 0 | K10: 0 | L10: 0 | M10: 115 | N10: 0 | O10: =SUM(C10:L10,N10) -> 88 | P10: =SUM(C10:N10) -> 203 | R10: 0700-0800 | S10: =SUM(C10:C13) -> 48 | T10: =SUM(D10:D13) -> 35 | U10: =SUM(E10:E13) -> 8 | V10: =SUM(F10:F13) -> 266 | W10: =SUM(G10:G13) -> 4 | X10: =SUM(H10:H13) -> 0 | Y10: =SUM(I10:I13) -> 7 | Z10: =SUM(J10:J13) -> 4 | ... AF10: =SUM(P10:P13) -> 909
B11: 07.15 - 07.30 | C11: 11 | D11: 11 | E11: 1 | F11: 60 | G11: 0 | H11: 0 | I11: 2 | J11: 1 | K11: 0 | L11: 0 | M11: 117 | N11: 0 | O11: =SUM(C11:L11,N11) -> 86 | P11: =SUM(C11:N11) -> 203 | R11: 0800-0900 | S11: =SUM(C14:C17) -> 41 | T11: =SUM(D14:D17) -> 28 | U11: =SUM(E14:E17) -> 6 | V11: =SUM(F14:F17) -> 284 | W11: =SUM(G14:G17) -> 2 | X11: =SUM(H14:H17) -> 0 | Y11: =SUM(I14:I17) -> 16 | Z11: =SUM(J14:J17) -> 6 | ... AF11: =SUM(P14:P17) -> 1100
B12: 07.30 - 07.45 | C12: 11 | D12: 9 | E12: 4 | F12: 69 | G12: 4 | H12: 0 | I12: 1 | J12: 1 | K12: 0 | L12: 0 | M12: 153 | N12: 0 | O12: =SUM(C12:L12,N12) -> 99 | P12: =SUM(C12:N12) -> 252 | R12: 0900-1000 | S12: =SUM(C18:C21) -> 59 | T12: =SUM(D18:D21) -> 31 | U12: =SUM(E18:E21) -> 7 | V12: =SUM(F18:F21) -> 301 | W12: =SUM(G18:G21) -> 0 | X12: =SUM(H18:H21) -> 0 | Y12: =SUM(I18:I21) -> 12 | Z12: =SUM(J18:J21) -> 3 | ... AF12: =SUM(P18:P21) -> 1143
B13: 07.45 - 08.00 | C13: 11 | D13: 5 | E13: 1 | F13: 77 | G13: 0 | H13: 0 | I13: 3 | J13: 2 | K13: 0 | L13: 0 | M13: 152 | N13: 0 | O13: =SUM(C13:L13,N13) -> 99 | P13: =SUM(C13:N13) -> 251 | R13: 1000-1100 | S13: =SUM(C22:C25) -> 51 | T13: =SUM(D22:D25) -> 27 | U13: =SUM(E22:E25) -> 5 | V13: =SUM(F22:F25) -> 144 | W13: =SUM(G22:G25) -> 1 | X13: =SUM(H22:H25) -> 0 | Y13: =SUM(I22:I25) -> 11 | Z13: =SUM(J22:J25) -> 8 | ... AF13: =SUM(P22:P25) -> 922
B14: 08.00 - 08.15 | C14: 13 | D14: 7 | E14: 0 | F14: 81 | G14: 0 | H14: 0 | I14: 5 | J14: 1 | K14: 0 | L14: 0 | M14: 170 | N14: 0 | O14: =SUM(C14:L14,N14) -> 107 | P14: =SUM(C14:N14) -> 277 | R14: 1100-1200 | S14: =SUM(C26:C29) -> 58 | T14: =SUM(D26:D29) -> 41 | U14: =SUM(E26:E29) -> 6 | V14: =SUM(F26:F29) -> 126 | W14: =SUM(G26:G29) -> 0 | X14: =SUM(H26:H29) -> 0 | Y14: =SUM(I26:I29) -> 17 | Z14: =SUM(J26:J29) -> 2 | ... AF14: =SUM(P26:P29) -> 806
B15: 08.15 - 08.30 | C15: 8 | D15: 8 | E15: 2 | F15: 71 | G15: 1 | H15: 0 | I15: 3 | J15: 2 | K15: 0 | L15: 0 | M15: 180 | N15: 0 | O15: =SUM(C15:L15,N15) -> 95 | P15: =SUM(C15:N15) -> 275 | R15: 1200-1300 | S15: =SUM(C30:C33) -> 55 | T15: =SUM(D30:D33) -> 34 | U15: =SUM(E30:E33) -> 8 | V15: =SUM(F30:F33) -> 88 | W15: =SUM(G30:G33) -> 0 | X15: =SUM(H30:H33) -> 0 | Y15: =SUM(I30:I33) -> 13 | Z15: =SUM(J30:J33) -> 1 | ... AF15: =SUM(P30:P33) -> 726
B16: 08.30 - 08.45 | C16: 11 | D16: 9 | E16: 2 | F16: 61 | G16: 0 | H16: 0 | I16: 2 | J16: 2 | K16: 2 | L16: 0 | M16: 200 | N16: 0 | O16: =SUM(C16:L16,N16) -> 89 | P16: =SUM(C16:N16) -> 289 | R16: 1300-1400 | S16: =SUM(C34:C37) -> 54 | T16: =SUM(D34:D37) -> 38 | U16: =SUM(E34:E37) -> 3 | V16: =SUM(F34:F37) -> 84 | W16: =SUM(G34:G37) -> 0 | X16: =SUM(H34:H37) -> 0 | Y16: =SUM(I34:I37) -> 11 | Z16: =SUM(J34:J37) -> 3 | ... AF16: =SUM(P34:P37) -> 584
B17: 08.45 - 9.00 | C17: 9 | D17: 4 | E17: 2 | F17: 71 | G17: 1 | H17: 0 | I17: 6 | J17: 1 | K17: 0 | L17: 0 | M17: 165 | N17: 0 | O17: =SUM(C17:L17,N17) -> 94 | P17: =SUM(C17:N17) -> 259 | R17: 1400-1500 | S17: =SUM(C38:C41) -> 67 | T17: =SUM(D38:D41) -> 38 | U17: =SUM(E38:E41) -> 9 | V17: =SUM(F38:F41) -> 84 | W17: =SUM(G38:G41) -> 1 | X17: =SUM(H38:H41) -> 0 | Y17: =SUM(I38:I41) -> 16 | Z17: =SUM(J38:J41) -> 2 | ... AF17: =SUM(P38:P41) -> 637
B18: 09.00 - 09.15 | C18: 17 | D18: 7 | E18: 4 | F18: 48 | G18: 0 | H18: 0 | I18: 3 | J18: 2 | K18: 0 | L18: 0 | M18: 175 | N18: 0 | O18: =SUM(C18:L18,N18) -> 81 | P18: =SUM(C18:N18) -> 256 | R18: 1500-1600 | S18: =SUM(C42:C45) -> 71 | T18: =SUM(D42:D45) -> 49 | U18: =SUM(E42:E45) -> 8 | V18: =SUM(F42:F45) -> 94 | W18: =SUM(G42:G45) -> 0 | X18: =SUM(H42:H45) -> 0 | Y18: =SUM(I42:I45) -> 23 | Z18: =SUM(J42:J45) -> 5 | ... AF18: =SUM(P42:P45) -> 692
B19: 09.15 - 09.30 | C19: 13 | D19: 5 | E19: 0 | F19: 150 | G19: 0 | H19: 0 | I19: 4 | J19: 1 | K19: 0 | L19: 0 | M19: 190 | N19: 0 | O19: =SUM(C19:L19,N19) -> 173 | P19: =SUM(C19:N19) -> 363 | R19: 1600-1700 | S19: =SUM(C46:C49) -> 91 | T19: =SUM(D46:D49) -> 62 | U19: =SUM(E46:E49) -> 12 | V19: =SUM(F46:F49) -> 86 | W19: =SUM(G46:G49) -> 2 | X19: =SUM(H46:H49) -> 0 | Y19: =SUM(I46:I49) -> 14 | Z19: =SUM(J46:J49) -> 2 | ... AF19: =SUM(P46:P49) -> 729
B20: 09.30 - 09.45 | C20: 10 | D20: 9 | E20: 0 | F20: 57 | G20: 0 | H20: 0 | I20: 2 | J20: 0 | K20: 0 | L20: 0 | M20: 190 | N20: 0 | O20: =SUM(C20:L20,N20) -> 78 | P20: =SUM(C20:N20) -> 268 | R20: 1700-1800 | S20: =SUM(C50:C53) -> 109 | T20: =SUM(D50:D53) -> 106 | U20: =SUM(E50:E53) -> 11 | V20: =SUM(F50:F53) -> 120 | W20: =SUM(G50:G53) -> 1 | X20: =SUM(H50:H53) -> 0 | Y20: =SUM(I50:I53) -> 17 | Z20: =SUM(J50:J53) -> 1 | ... AF20: =SUM(P50:P53) -> 871
B21: 09.45 - 10.00 | C21: 19 | D21: 10 | E21: 3 | F21: 46 | G21: 0 | H21: 0 | I21: 3 | J21: 0 | K21: 0 | L21: 0 | M21: 175 | N21: 0 | O21: =SUM(C21:L21,N21) -> 81 | P21: =SUM(C21:N21) -> 256 | R21: 1800-1900 | S21: =SUM(C54:C57) -> 122 | T21: =SUM(D54:D57) -> 67 | U21: =SUM(E54:E57) -> 6 | V21: =SUM(F54:F57) -> 145 | W21: =SUM(G54:G57) -> 3 | X21: =SUM(H54:H57) -> 0 | Y21: =SUM(I54:I57) -> 21 | Z21: =SUM(J54:J57) -> 1 | ... AF21: =SUM(P54:P57) -> 911
B22: 10.00 - 10.15 | C22: 14 | D22: 8 | E22: 1 | F22: 45 | G22: 1 | H22: 0 | I22: 3 | J22: 1 | K22: 1 | L22: 0 | M22: 180 | N22: 0 | O22: =SUM(C22:L22,N22) -> 74 | P22: =SUM(C22:N22) -> 254 | R22: AM Peak Hr | S22: =MAX(S10:S12) -> 59 | T22: =MAX(T10:T12) -> 35 | U22: =MAX(U10:U12) -> 8 | V22: =MAX(V10:V12) -> 301 | W22: =MAX(W10:W12) -> 4 | X22: =MAX(X10:X12) -> 0 | Y22: =MAX(Y10:Y12) -> 16 | Z22: =MAX(Z10:Z12) -> 6 | ... AF22: =MAX(AF10:AF12) -> 1143
B23: 10.15 - 10.30 | C23: 10 | D23: 4 | E23: 0 | F23: 30 | G23: 0 | H23: 0 | I23: 3 | J23: 0 | K23: 0 | L23: 0 | M23: 161 | N23: 0 | O23: =SUM(C23:L23,N23) -> 47 | P23: =SUM(C23:N23) -> 208 | R23: IP Peak Hr | S23: =MAX(S13:S18) -> 71 | T23: =MAX(T13:T18) -> 49 | U23: =MAX(U13:U18) -> 9 | V23: =MAX(V13:V18) -> 144 | W23: =MAX(W13:W18) -> 1 | X23: =MAX(X13:X18) -> 0 | Y23: =MAX(Y13:Y18) -> 23 | Z23: =MAX(Z13:Z18) -> 8 | ... AF23: =MAX(AF13:AF18) -> 922
B24: 10.30 - 10.45 | C24: 13 | D24: 7 | E24: 2 | F24: 36 | G24: 0 | H24: 0 | I24: 0 | J24: 4 | K24: 1 | L24: 0 | M24: 190 | N24: 0 | O24: =SUM(C24:L24,N24) -> 63 | P24: =SUM(C24:N24) -> 253 | R24: PM Peak Hr | S24: =MAX(S19:S21) -> 122 | T24: =MAX(T19:T21) -> 106 | U24: =MAX(U19:U21) -> 12 | V24: =MAX(V19:V21) -> 145 | W24: =MAX(W19:W21) -> 3 | X24: =MAX(X19:X21) -> 0 | Y24: =MAX(Y19:Y21) -> 21 | Z24: =MAX(Z19:Z21) -> 2 | ... AF24: =MAX(AF19:AF21) -> 911
B25: 10.45 - 11.00 | C25: 14 | D25: 8 | E25: 2 | F25: 33 | G25: 0 | H25: 0 | I25: 5 | J25: 3 | K25: 1 | L25: 0 | M25: 141 | N25: 0 | O25: =SUM(C25:L25,N25) -> 66 | P25: =SUM(C25:N25) -> 207 | R25: AM Period | S25: =SUM(S10:S12) -> 148 | T25: =SUM(T10:T12) -> 94 | U25: =SUM(U10:U12) -> 21 | V25: =SUM(V10:V12) -> 851 | W25: =SUM(W10:W12) -> 6 | X25: =SUM(X10:X12) -> 0 | Y25: =SUM(Y10:Y12) -> 35 | Z25: =SUM(Z10:Z12) -> 13 | ... AF25: =SUM(AF10:AF12) -> 3152
B26: 11.00 - 11.15 | C26: 13 | D26: 13 | E26: 2 | F26: 36 | G26: 0 | H26: 0 | I26: 4 | J26: 1 | K26: 0 | L26: 0 | M26: 150 | N26: 0 | O26: =SUM(C26:L26,N26) -> 69 | P26: =SUM(C26:N26) -> 219 | R26: IP Period | S26: =SUM(S13:S18) -> 356 | T26: =SUM(T13:T18) -> 227 | U26: =SUM(U13:U18) -> 39 | V26: =SUM(V13:V18) -> 620 | W26: =SUM(W13:W18) -> 2 | X26: =SUM(X13:X18) -> 0 | Y26: =SUM(Y13:Y18) -> 91 | Z26: =SUM(Z13:Z18) -> 21 | ... AF26: =SUM(AF13:AF18) -> 4367
B27: 11.15 - 11.30 | C27: 11 | D27: 13 | E27: 2 | F27: 37 | G27: 0 | H27: 0 | I27: 6 | J27: 0 | K27: 0 | L27: 0 | M27: 121 | N27: 0 | O27: =SUM(C27:L27,N27) -> 69 | P27: =SUM(C27:N27) -> 190 | R27: PM Period | S27: =SUM(S19:S21) -> 322 | T27: =SUM(T19:T21) -> 235 | U27: =SUM(U19:U21) -> 29 | V27: =SUM(V19:V21) -> 351 | W27: =SUM(W19:W21) -> 6 | X27: =SUM(X19:X21) -> 0 | Y27: =SUM(Y19:Y21) -> 52 | Z27: =SUM(Z19:Z21) -> 4 | ... AF27: =SUM(AF19:AF21) -> 2511
B28: 11.30 - 11.45 | C28: 11 | D28: 10 | E28: 0 | F28: 23 | G28: 0 | H28: 0 | I28: 4 | J28: 1 | K28: 0 | L28: 0 | M28: 140 | N28: 0 | O28: =SUM(C28:L28,N28) -> 49 | P28: =SUM(C28:N28) -> 189 | R28: 12 Hours | S28: =SUM(S10:S21) -> 826 | T28: =SUM(T10:T21) -> 556 | U28: =SUM(U10:U21) -> 89 | V28: =SUM(V10:V21) -> 1822 | W28: =SUM(W10:W21) -> 14 | X28: =SUM(X10:X21) -> 0 | Y28: =SUM(Y10:Y21) -> 178 | Z28: =SUM(Z10:Z21) -> 38 | ... AF28: =SUM(AF10:AF21) -> 10030
B29: 11.45 - 12.00 | C29: 23 | D29: 5 | E29: 2 | F29: 30 | G29: 0 | H29: 0 | I29: 3 | J29: 0 | K29: 0 | L29: 0 | M29: 145 | N29: 0 | O29: =SUM(C29:L29,N29) -> 63 | P29: =SUM(C29:N29) -> 208
B30: 12.00 - 12.15 | C30: 13 | D30: 9 | E30: 0 | F30: 20 | G30: 0 | H30: 0 | I30: 4 | J30: 0 | K30: 1 | L30: 0 | M30: 140 | N30: 0 | O30: =SUM(C30:L30,N30) -> 47 | P30: =SUM(C30:N30) -> 187
B31: 12.15 - 12.30 | C31: 8 | D31: 10 | E31: 7 | F31: 15 | G31: 0 | H31: 0 | I31: 3 | J31: 0 | K31: 1 | L31: 0 | M31: 125 | N31: 0 | O31: =SUM(C31:L31,N31) -> 44 | P31: =SUM(C31:N31) -> 169
B32: 12.30 - 12.45 | C32: 15 | D32: 7 | E32: 1 | F32: 24 | G32: 0 | H32: 0 | I32: 3 | J32: 1 | K32: 0 | L32: 0 | M32: 120 | N32: 0 | O32: =SUM(C32:L32,N32) -> 51 | P32: =SUM(C32:N32) -> 171
B33: 12.45 - 13.00 | C33: 19 | D33: 8 | E33: 0 | F33: 29 | G33: 0 | H33: 0 | I33: 3 | J33: 0 | K33: 0 | L33: 0 | M33: 140 | N33: 0 | O33: =SUM(C33:L33,N33) -> 59 | P33: =SUM(C33:N33) -> 199
B34: 13.00 - 13.15 | C34: 14 | D34: 12 | E34: 0 | F34: 24 | G34: 0 | H34: 0 | I34: 3 | J34: 1 | K34: 0 | L34: 0 | M34: 100 | N34: 0 | O34: =SUM(C34:L34,N34) -> 54 | P34: =SUM(C34:N34) -> 154
B35: 13.15 - 13.30 | C35: 19 | D35: 14 | E35: 3 | F35: 24 | G35: 0 | H35: 0 | I35: 3 | J35: 1 | K35: 1 | L35: 0 | M35: 115 | N35: 0 | O35: =SUM(C35:L35,N35) -> 65 | P35: =SUM(C35:N35) -> 180
B36: 13.30 - 13.45 | C36: 10 | D36: 1 | E36: 0 | F36: 19 | G36: 0 | H36: 0 | I36: 3 | J36: 1 | K36: 0 | L36: 0 | M36: 115 | N36: 0 | O36: =SUM(C36:L36,N36) -> 34 | P36: =SUM(C36:N36) -> 149
B37: 13.45 - 14.00 | C37: 11 | D37: 11 | E37: 0 | F37: 17 | G37: 0 | H37: 0 | I37: 2 | J37: 0 | K37: 0 | L37: 0 | M37: 60 | N37: 0 | O37: =SUM(C37:L37,N37) -> 41 | P37: =SUM(C37:N37) -> 101
B38: 14.00 - 14.15 | C38: 24 | D38: 15 | E38: 3 | F38: 24 | G38: 0 | H38: 0 | I38: 5 | J38: 1 | K38: 1 | L38: 0 | M38: 130 | N38: 0 | O38: =SUM(C38:L38,N38) -> 73 | P38: =SUM(C38:N38) -> 203
B39: 14.15 - 14.30 | C39: 16 | D39: 5 | E39: 2 | F39: 16 | G39: 1 | H39: 0 | I39: 0 | J39: 1 | K39: 1 | L39: 0 | M39: 92 | N39: 0 | O39: =SUM(C39:L39,N39) -> 42 | P39: =SUM(C39:N39) -> 134
B40: 14.30 - 14.45 | C40: 18 | D40: 6 | E40: 0 | F40: 24 | G40: 0 | H40: 0 | I40: 4 | J40: 0 | K40: 1 | L40: 0 | M40: 70 | N40: 0 | O40: =SUM(C40:L40,N40) -> 53 | P40: =SUM(C40:N40) -> 123
... B57: 18.45 - 19.00 | C57: 27 | D57: 14 | E57: 1 | F57: 42 | G57: 0 | H57: 0 | I57: 3 | J57: 0 | K57: 1 | L57: 0 | M57: 120 | N57: 0 | O57: =SUM(C57:L57,N57) -> 88 | P57: =SUM(C57:N57) -> 208
B58: Totals | C58: =SUM(C10:C57) -> 826 | D58: =SUM(D10:D57) -> 556 | E58: =SUM(E10:E57) -> 89 | F58: =SUM(F10:F57) -> 1822 | G58: =SUM(G10:G57) -> 14 | H58: =SUM(H10:H57) -> 0 | I58: =SUM(I10:I57) -> 178 | J58: =SUM(J10:J57) -> 38 | ... P58: =SUM(P10:P57) -> 10030
...

Sheet 23.07 Munyonyo-Kibuye
B1: Consultancy services for Preparation of Expressway Development Master Plan (EDMP) for Uganda
B2: MANUAL CLASSIFIED COUNT (MCC)
B3: ROAD NAME: | C3: ='22.07 Kibuye-Munyonyo'!C3:G3 -> MCC - C1 - STN01A - SALAMA ROAD
C5: Date | D5: ='23.07 Kibuye-Munyonyo'!D5 -> 23.07.19 | F5: Location | G5: Salama road 1A | J5: Surveyor | K5: Gerald
C6: Dir. From | D6: Munyonyo | F6: Dir. To | G6: ='22.07 Munyonyo-Kibuye'!G6:H6 -> Kibuye | J6: Supervisor | K6: Emma
B8: Time / Veh Type | R8: SUMMARY TRAFFIC VOLUMES
C9: 1. Car | D9: 2. Station Wagon | E9: 3. Pickups | F9: 4. Minibus, matatu | G9: 5. Medium bus | H9: 6. Large Bus | I9: 7. Light Truck | J9: 8. Medium Truck | K9: 9. Heavy truck | L9: 10. Truck Trailer | M9: 11. Motor cycles | N9: 12. Tractors | O9: Total Excl M/Cycles | P9: Total All | R9: Time | S9: 1. Car | T9: 2. Station Wagon | U9: 3. Pickups | V9: 4. Minibus, matatu | W9: 5. Medium bus | X9: 6. Large Bus | Y9: 7. Light Truck | Z9: 8. Medium Truck | AA9: 9. Heavy truck | AB9: 10. Truck Trailer | AC9: 11. Motorcycles | AD9: 12. Tractors, Graders | AE9: Total Excl M/ Cycles | AF9: Total All
B10: 07.00 - 07.15 | C10: 71 | D10: 20 | E10: 7 | F10: 78 | G10: 1 | H10: 0 | I10: 7 | J10: 1 | K10: 1 | L10: 0 | M10: 181 | N10: 0 | O10: =SUM(C10:L10,N10) -> 186 | P10: =SUM(C10:N10) -> 367 | R10: 0700-0800 | S10: =SUM(C10:C13) -> 142 | T10: =SUM(D10:D13) -> 62 | U10: =SUM(E10:E13) -> 19 | V10: =SUM(F10:F13) -> 245 | W10: =SUM(G10:G13) -> 1 | X10: =SUM(H10:H13) -> 0 | Y10: =SUM(I10:I13) -> 19 | Z10: =SUM(J10:J13) -> 4 | ... AF10: =SUM(P10:P13) -> 1359
B11: 07.15 - 07.30 | C11: 25 | D11: 18 | E11: 4 | F11: 50 | G11: 0 | H11: 0 | I11: 4 | J11: 0 | K11: 0 | L11: 0 | M11: 184 | N11: 0 | O11: =SUM(C11:L11,N11) -> 101 | P11: =SUM(C11:N11) -> 285 | R11: 0800-0900 | S11: =SUM(C14:C17) -> 110 | T11: =SUM(D14:D17) -> 54 | U11: =SUM(E14:E17) -> 13 | V11: =SUM(F14:F17) -> 219 | W11: =SUM(G14:G17) -> 1 | X11: =SUM(H14:H17) -> 0 | Y11: =SUM(I14:I17) -> 11 | Z11: =SUM(J14:J17) -> 1 | ... AF11: =SUM(P14:P17) -> 1249
B12: 07.30 - 07.45 | C12: 23 | D12: 16 | E12: 2 | F12: 61 | G12: 0 | H12: 0 | I12: 4 | J12: 3 | K12: 0 | L12: 0 | M12: 224 | N12: 0 | O12: =SUM(C12:L12,N12) -> 109 | P12: =SUM(C12:N12) -> 333 | R12: 0900-1000 | S12: =SUM(C18:C21) -> 90 | T12: =SUM(D18:D21) -> 56 | U12: =SUM(E18:E21) -> 22 | V12: =SUM(F18:F21) -> 177 | W12: =SUM(G18:G21) -> 0 | X12: =SUM(H18:H21) -> 0 | Y12: =SUM(I18:I21) -> 15 | Z12: =SUM(J18:J21) -> 3 | ... AF12: =SUM(P18:P21) -> 992
B13: 07.45 - 08.00 | C13: 23 | D13: 8 | E13: 6 | F13: 56 | G13: 0 | H13: 0 | I13: 4 | J13: 0 | K13: 0 | L13: 0 | M13: 277 | N13: 0 | O13: =SUM(C13:L13,N13) -> 97 | P13: =SUM(C13:N13) -> 374 | R13: 1000-1100 | S13: =SUM(C22:C25) -> 100 | T13: =SUM(D22:D25) -> 67 | U13: =SUM(E22:E25) -> 4 | V13: =SUM(F22:F25) -> 167 | W13: =SUM(G22:G25) -> 2 | X13: =SUM(H22:H25) -> 0 | Y13: =SUM(I22:I25) -> 19 | Z13: =SUM(J22:J25) -> 4 | ... AF13: =SUM(P22:P25) -> 969
B14: 08.00 - 08.15 | C14: 29 | D14: 15 | E14: 3 | F14: 62 | G14: 1 | H14: 0 | I14: 3 | J14: 0 | K14: 0 | L14: 0 | M14: 231 | N14: 0 | O14: =SUM(C14:L14,N14) -> 113 | P14: =SUM(C14:N14) -> 344 | R14: 1100-1200 | S14: =SUM(C26:C29) -> 77 | T14: =SUM(D26:D29) -> 45 | U14: =SUM(E26:E29) -> 17 | V14: =SUM(F26:F29) -> 128 | W14: =SUM(G26:G29) -> 0 | X14: =SUM(H26:H29) -> 0 | Y14: =SUM(I26:I29) -> 14 | Z14: =SUM(J26:J29) -> 3 | ... AF14: =SUM(P26:P29) -> 840
B15: 08.15 - 08.30 | C15: 28 | D15: 13 | E15: 2 | F15: 58 | G15: 0 | H15: 0 | I15: 5 | J15: 0 | K15: 0 | L15: 0 | M15: 229 | N15: 0 | O15: =SUM(C15:L15,N15) -> 106 | P15: =SUM(C15:N15) -> 335 | R15: 1200-1300 | S15: =SUM(C30:C33) -> 59 | T15: =SUM(D30:D33) -> 44 | U15: =SUM(E30:E33) -> 9 | V15: =SUM(F30:F33) -> 92 | W15: =SUM(G30:G33) -> 1 | X15: =SUM(H30:H33) -> 0 | Y15: =SUM(I30:I33) -> 9 | Z15: =SUM(J30:J33) -> 3 | ... AF15: =SUM(P30:P33) -> 647
B16: 08.30 - 08.45 | C16: 31 | D16: 18 | E16: 4 | F16: 55 | G16: 0 | H16: 0 | I16: 2 | J16: 0 | K16: 0 | L16: 0 | M16: 205 | N16: 0 | O16: =SUM(C16:L16,N16) -> 110 | P16: =SUM(C16:N16) -> 315 | R16: 1300-1400 | S16: =SUM(C34:C37) -> 70 | T16: =SUM(D34:D37) -> 42 | U16: =SUM(E34:E37) -> 17 | V16: =SUM(F34:F37) -> 97 | W16: =SUM(G34:G37) -> 0 | X16: =SUM(H34:H37) -> 0 | Y16: =SUM(I34:I37) -> 21 | Z16: =SUM(J34:J37) -> 2 | ... AF16: =SUM(P34:P37) -> 741
B17: 08.45 - 9.00 | C17: 22 | D17: 8 | E17: 4 | F17: 44 | G17: 0 | H17: 0 | I17: 1 | J17: 1 | K17: 0 | L17: 0 | M17: 175 | N17: 0 | O17: =SUM(C17:L17,N17) -> 80 | P17: =SUM(C17:N17) -> 255 | R17: 1400-1500 | S17: =SUM(C38:C41) -> 73 | T17: =SUM(D38:D41) -> 32 | U17: =SUM(E38:E41) -> 13 | V17: =SUM(F38:F41) -> 98 | W17: =SUM(G38:G41) -> 0 | X17: =SUM(H38:H41) -> 0 | Y17: =SUM(I38:I41) -> 14 | Z17: =SUM(J38:J41) -> 2 | ... AF17: =SUM(P38:P41) -> 794
B18: 09.00 - 09.15 | C18: 22 | D18: 19 | E18: 7 | F18: 52 | G18: 0 | H18: 0 | I18: 5 | J18: 1 | K18: 0 | L18: 0 | M18: 175 | N18: 0 | O18: =SUM(C18:L18,N18) -> 106 | P18: =SUM(C18:N18) -> 281 | R18: 1500-1600 | S18: =SUM(C42:C45) -> 84 | T18: =SUM(D42:D45) -> 34 | U18: =SUM(E42:E45) -> 16 | V18: =SUM(F42:F45) -> 74 | W18: =SUM(G42:G45) -> 0 | X18: =SUM(H42:H45) -> 0 | Y18: =SUM(I42:I45) -> 10 | Z18: =SUM(J42:J45) -> 5 | ... AF18: =SUM(P42:P45) -> 664
B19: 09.15 - 09.30 | C19: 27 | D19: 13 | E19: 3 | F19: 55 | G19: 0 | H19: 0 | I19: 1 | J19: 0 | K19: 1 | L19: 0 | M19: 185 | N19: 0 | O19: =SUM(C19:L19,N19) -> 100 | P19: =SUM(C19:N19) -> 285 | R19: 1600-1700 | S19: =SUM(C46:C49) -> 83 | T19: =SUM(D46:D49) -> 51 | U19: =SUM(E46:E49) -> 16 | V19: =SUM(F46:F49) -> 102 | W19: =SUM(G46:G49) -> 4 | X19: =SUM(H46:H49) -> 0 | Y19: =SUM(I46:I49) -> 19 | Z19: =SUM(J46:J49) -> 1 | ... AF19: =SUM(P46:P49) -> 876
B20: 09.30 - 09.45 | C20: 21 | D20: 10 | E20: 6 | F20: 39 | G20: 0 | H20: 0 | I20: 4 | J20: 0 | K20: 0 | L20: 0 | M20: 129 | N20: 0 | O20: =SUM(C20:L20,N20) -> 80 | P20: =SUM(C20:N20) -> 209 | R20: 1700-1800 | S20: =SUM(C50:C53) -> 75 | T20: =SUM(D50:D53) -> 35 | U20: =SUM(E50:E53) -> 13 | V20: =SUM(F50:F53) -> 93 | W20: =SUM(G50:G53) -> 2 | X20: =SUM(H50:H53) -> 0 | Y20: =SUM(I50:I53) -> 12 | Z20: =SUM(J50:J53) -> 1 | ... AF20: =SUM(P50:P53) -> 822
B21: 09.45 - 10.00 | C21: 20 | D21: 14 | E21: 6 | F21: 31 | G21: 0 | H21: 0 | I21: 5 | J21: 2 | K21: 0 | L21: 0 | M21: 139 | N21: 0 | O21: =SUM(C21:L21,N21) -> 78 | P21: =SUM(C21:N21) -> 217 | R21: 1800-1900 | S21: =SUM(C54:C57) -> 65 | T21: =SUM(D54:D57) -> 35 | U21: =SUM(E54:E57) -> 14 | V21: =SUM(F54:F57) -> 90 | W21: =SUM(G54:G57) -> 4 | X21: =SUM(H54:H57) -> 1 | Y21: =SUM(I54:I57) -> 14 | Z21: =SUM(J54:J57) -> 1 | ... AF21: =SUM(P54:P57) -> 807
B22: 10.00 - 10.15 | C22: 34 | D22: 16 | E22: 0 | F22: 49 | G22: 1 | H22: 0 | I22: 6 | J22: 2 | K22: 0 | L22: 0 | M22: 175 | N22: 0 | O22: =SUM(C22:L22,N22) -> 108 | P22: =SUM(C22:N22) -> 283 | R22: AM Peak Hr | S22: =MAX(S10:S12) -> 142 | T22: =MAX(T10:T12) -> 62 | U22: =MAX(U10:U12) -> 22 | V22: =MAX(V10:V12) -> 245 | W22: =MAX(W10:W12) -> 1 | X22: =MAX(X10:X12) -> 0 | Y22: =MAX(Y10:Y12) -> 19 | Z22: =MAX(Z10:Z12) -> 4 | ... AF22: =MAX(AF10:AF12) -> 1359
B23: 10.15 - 10.30 | C23: 19 | D23: 17 | E23: 2 | F23: 35 | G23: 0 | H23: 0 | I23: 5 | J23: 0 | K23: 0 | L23: 0 | M23: 155 | N23: 0 | O23: =SUM(C23:L23,N23) -> 78 | P23: =SUM(C23:N23) -> 233 | R23: IP Peak Hr | S23: =MAX(S13:S18) -> 100 | T23: =MAX(T13:T18) -> 67 | U23: =MAX(U13:U18) -> 17 | V23: =MAX(V13:V18) -> 167 | W23: =MAX(W13:W18) -> 2 | X23: =MAX(X13:X18) -> 0 | Y23: =MAX(Y13:Y18) -> 21 | Z23: =MAX(Z13:Z18) -> 5 | ... AF23: =MAX(AF13:AF18) -> 969
B24: 10.30 - 10.45 | C24: 23 | D24: 16 | E24: 0 | F24: 44 | G24: 0 | H24: 0 | I24: 4 | J24: 2 | K24: 0 | L24: 0 | M24: 115 | N24: 0 | O24: =SUM(C24:L24,N24) -> 89 | P24: =SUM(C24:N24) -> 204 | R24: PM Peak Hr | S24: =MAX(S19:S21) -> 83 | T24: =MAX(T19:T21) -> 51 | U24: =MAX(U19:U21) -> 16 | V24: =MAX(V19:V21) -> 102 | W24: =MAX(W19:W21) -> 4 | X24: =MAX(X19:X21) -> 1 | Y24: =MAX(Y19:Y21) -> 19 | Z24: =MAX(Z19:Z21) -> 1 | ... AF24: =MAX(AF19:AF21) -> 876
B25: 10.45 - 11.00 | C25: 24 | D25: 18 | E25: 2 | F25: 39 | G25: 1 | H25: 0 | I25: 4 | J25: 0 | K25: 0 | L25: 0 | M25: 161 | N25: 0 | O25: =SUM(C25:L25,N25) -> 88 | P25: =SUM(C25:N25) -> 249 | R25: AM Period | S25: =SUM(S10:S12) -> 342 | T25: =SUM(T10:T12) -> 172 | U25: =SUM(U10:U12) -> 54 | V25: =SUM(V10:V12) -> 641 | W25: =SUM(W10:W12) -> 2 | X25: =SUM(X10:X12) -> 0 | Y25: =SUM(Y10:Y12) -> 45 | Z25: =SUM(Z10:Z12) -> 8 | ... AF25: =SUM(AF10:AF12) -> 3600
B26: 11.00 - 11.15 | C26: 23 | D26: 14 | E26: 7 | F26: 35 | G26: 0 | H26: 0 | I26: 4 | K26: 0 | L26: 0 | M26: 145 | N26: 0 | O26: =SUM(C26:L26,N26) -> 83 | P26: =SUM(C26:N26) -> 228 | R26: IP Period | S26: =SUM(S13:S18) -> 463 | T26: =SUM(T13:T18) -> 264 | U26: =SUM(U13:U18) -> 76 | V26: =SUM(V13:V18) -> 656 | W26: =SUM(W13:W18) -> 3 | X26: =SUM(X13:X18) -> 0 | Y26: =SUM(Y13:Y18) -> 87 | Z26: =SUM(Z13:Z18) -> 19 | ... AF26: =SUM(AF13:AF18) -> 4655
B27: 11.15 - 11.30 | C27: 20 | D27: 16 | E27: 1 | F27: 32 | G27: 0 | H27: 0 | I27: 3 | J27: 1 | K27: 0 | L27: 0 | M27: 159 | N27: 0 | O27: =SUM(C27:L27,N27) -> 73 | P27: =SUM(C27:N27) -> 232 | R27: PM Period | S27: =SUM(S19:S21) -> 223 | T27: =SUM(T19:T21) -> 121 | U27: =SUM(U19:U21) -> 43 | V27: =SUM(V19:V21) -> 285 | W27: =SUM(W19:W21) -> 10 | X27: =SUM(X19:X21) -> 1 | Y27: =SUM(Y19:Y21) -> 45 | Z27: =SUM(Z19:Z21) -> 3 | ... AF27: =SUM(AF19:AF21) -> 2505
B28: 11.30 - 11.45 | C28: 14 | D28: 5 | E28: 6 | F28: 32 | G28: 0 | H28: 0 | I28: 2 | J28: 0 | K28: 0 | L28: 0 | M28: 120 | N28: 0 | O28: =SUM(C28:L28,N28) -> 59 | P28: =SUM(C28:N28) -> 179 | R28: 12 Hours | S28: =SUM(S10:S21) -> 1028 | T28: =SUM(T10:T21) -> 557 | U28: =SUM(U10:U21) -> 173 | V28: =SUM(V10:V21) -> 1582 | W28: =SUM(W10:W21) -> 15 | X28: =SUM(X10:X21) -> 1 | Y28: =SUM(Y10:Y21) -> 177 | Z28: =SUM(Z10:Z21) -> 30 | ... AF28: =SUM(AF10:AF21) -> 10760
B29: 11.45 - 12.00 | C29: 20 | D29: 10 | E29: 3 | F29: 29 | G29: 0 | H29: 0 | I29: 5 | J29: 2 | K29: 0 | L29: 0 | M29: 132 | N29: 0 | O29: =SUM(C29:L29,N29) -> 69 | P29: =SUM(C29:N29) -> 201
B30: 12.00 - 12.15 | C30: 16 | D30: 13 | E30: 2 | F30: 32 | G30: 0 | H30: 0 | I30: 3 | J30: 2 | K30: 0 | L30: 0 | M30: 145 | N30: 0 | O30: =SUM(C30:L30,N30) -> 68 | P30: =SUM(C30:N30) -> 213
B31: 12.15 - 12.30 | C31: 11 | D31: 7 | E31: 2 | F31: 19 | G31: 0 | H31: 0 | I31: 0 | J31: 0 | K31: 1 | L31: 0 | M31: 89 | N31: 0 | O31: =SUM(C31:L31,N31) -> 40 | P31: =SUM(C31:N31) -> 129
B32: 12.30 - 12.45 | C32: 13 | D32: 9 | E32: 2 | F32: 22 | G32: 1 | H32: 0 | I32: 1 | J32: 1 | K32: 0 | L32: 0 | M32: 91 | N32: 0 | O32: =SUM(C32:L32,N32) -> 49 | P32: =SUM(C32:N32) -> 140
B33: 12.45 - 13.00 | C33: 19 | D33: 15 | E33: 3 | F33: 19 | G33: 0 | H33: 0 | I33: 5 | J33: 0 | K33: 1 | L33: 0 | M33: 103 | N33: 0 | O33: =SUM(C33:L33,N33) -> 62 | P33: =SUM(C33:N33) -> 165
B34: 13.00 - 13.15 | C34: 10 | D34: 10 | E34: 7 | F34: 16 | G34: 0 | H34: 0 | I34: 6 | J34: 1 | K34: 0 | L34: 0 | M34: 124 | N34: 0 | O34: =SUM(C34:L34,N34) -> 50 | P34: =SUM(C34:N34) -> 174
B35: 13.15 - 13.30 | C35: 24 | D35: 4 | E35: 1 | F35: 25 | G35: 0 | H35: 0 | I35: 5 | J35: 1 | K35: 0 | L35: 0 | M35: 156 | N35: 0 | O35: =SUM(C35:L35,N35) -> 60 | P35: =SUM(C35:N35) -> 216
B36: 13.30 - 13.45 | C36: 21 | D36: 16 | E36: 5 | F36: 32 | G36: 0 | H36: 0 | I36: 7 | J36: 0 | K36: 0 | L36: 0 | M36: 102 | N36: 0 | O36: =SUM(C36:L36,N36) -> 81 | P36: =SUM(C36:N36) -> 183
B37: 13.45 - 14.00 | C37: 15 | D37: 12 | E37: 4 | F37: 24 | G37: 0 | H37: 0 | I37: 3 | J37: 0 | K37: 0 | L37: 0 | M37: 110 | N37: 0 | O37: =SUM(C37:L37,N37) -> 58 | P37: =SUM(C37:N37) -> 168
B38: 14.00 - 14.15 | C38: 21 | D38: 9 | E38: 2 | F38: 29 | G38: 0 | H38: 0 | I38: 5 | J38: 1 | K38: 0 | L38: 0 | M38: 139 | N38: 0 | O38: =SUM(C38:L38,N38) -> 67 | P38: =SUM(C38:N38) -> 206
B39: 14.15 - 14.30 | C39: 14 | D39: 8 | E39: 2 | F39: 23 | G39: 0 | H39: 0 | I39: 3 | J39: 0 | K39: 0 | L39: 0 | M39: 159 | N39: 0 | O39: =SUM(C39:L39,N39) -> 50 | P39: =SUM(C39:N39) -> 209
B40: 14.30 - 14.45 | C40: 18 | D40: 10 | E40: 4 | F40: 27 | G40: 0 | H40: 0 | I40: 5 | J40: 1 | K40: 0 | L40: 0 | M40: 139 | N40: 0 | O40: =SUM(C40:L40,N40) -> 65 | P40: =SUM(C40:N40) -> 204
... B57: 18.45 - 19.00 | C57: 28 | D57: 6 | E57: 5 | F57: 26 | G57: 1 | H57: 0 | I57: 2 | J57: 0 | K57: 0 | L57: 0 | M57: 185 | N57: 0 | O57: =SUM(C57:L57,N57) -> 68 | P57: =SUM(C57:N57) -> 253
B58: Totals | C58: =SUM(C10:C57) -> 1028 | D58: =SUM(D10:D57) -> 557 | E58: =SUM(E10:E57) -> 173 | F58: =SUM(F10:F57) -> 1582 | G58: =SUM(G10:G57) -> 15 | H58: =SUM(H10:H57) -> 1 | I58: =SUM(I10:I57) -> 177 | J58: =SUM(J10:J57) -> 30 | ... P58: =SUM(P10:P57) -> 10760
...

Sheet 24.07 Kibuye-Munyonyo
B1: Consultancy services for Preparation of Expressway Development Master Plan (EDMP) for Uganda
B2: MANUAL CLASSIFIED COUNT (MCC)
B3: ROAD NAME: | C3: ='22.07 Kibuye-Munyonyo'!C3:G3 -> MCC - C1 - STN01A - SALAMA ROAD
C5: Date | D5: 24.07.19 | F5: Location | G5: ='22.07 Kibuye-Munyonyo'!G5:H5 -> Salama road 1A | J5: Surveyor | K5: ='22.07 Kibuye-Munyonyo'!K5:L5 -> Racheal
C6: Dir. From | D6: ='22.07 Kibuye-Munyonyo'!D6:E6 -> Kibuye | F6: Dir. To | G6: ='22.07 Kibuye-Munyonyo'!G6:H6 -> Munyonyo | J6: Supervisor | K6: ='22.07 Kibuye-Munyonyo'!K6:L6 -> Emma
B8: Time / Veh Type | R8: SUMMARY TRAFFIC VOLUMES
C9: 1. Car | D9: 2. Station Wagon | E9: 3. Pickups | F9: 4. Minibus, matatu | G9: 5. Medium bus | H9: 6. Large Bus | I9: 7. Light Truck | J9: 8. Medium Truck | K9: 9. Heavy truck | L9: 10. Truck Trailer | M9: 11. Motor cycles | N9: 12. Tractors | O9: Total Excl M/Cycles | P9: Total All | R9: Time | S9: 1. Car | T9: 2. Station Wagon | U9: 3. Pickups | V9: 4. Minibus, matatu | W9: 5. Medium bus | X9: 6. Large Bus | Y9: 7. Light Truck | Z9: 8. Medium Truck | AA9: 9. Heavy truck | AB9: 10. Truck Trailer | AC9: 11. Motorcycles | AD9: 12. Tractors, Graders | AE9: Total Excl M/ Cycles | AF9: Total All
B10: 07.00 - 07.15 | C10: 14 | D10: 8 | E10: 0 | F10: 78 | G10: 1 | H10: 0 | I10: 2 | J10: 0 | K10: 1 | L10: 0 | M10: 110 | N10: 0 | O10: =SUM(C10:L10,N10) -> 104 | P10: =SUM(C10:N10) -> 214 | R10: 0700-0800 | S10: =SUM(C10:C13) -> 45 | T10: =SUM(D10:D13) -> 32 | U10: =SUM(E10:E13) -> 3 | V10: =SUM(F10:F13) -> 263 | W10: =SUM(G10:G13) -> 5 | X10: =SUM(H10:H13) -> 2 | Y10: =SUM(I10:I13) -> 6 | Z10: =SUM(J10:J13) -> 2 | ... AF10: =SUM(P10:P13) -> 838
B11: 07.15 - 07.30 | C11: 10 | D11: 12 | E11: 2 | F11: 65 | G11: 1 | H11: 0 | I11: 2 | J11: 1 | K11: 1 | L11: 0 | M11: 115 | N11: 0 | O11: =SUM(C11:L11,N11) -> 94 | P11: =SUM(C11:N11) -> 209 | R11: 0800-0900 | S11: =SUM(C14:C17) -> 42 | T11: =SUM(D14:D17) -> 22 | U11: =SUM(E14:E17) -> 6 | V11: =SUM(F14:F17) -> 263 | W11: =SUM(G14:G17) -> 4 | X11: =SUM(H14:H17) -> 0 | Y11: =SUM(I14:I17) -> 9 | Z11: =SUM(J14:J17) -> 4 | ... AF11: =SUM(P14:P17) -> 989
B12: 07.30 - 07.45 | C12: 13 | D12: 3 | E12: 0 | F12: 60 | G12: 1 | H12: 2 | I12: 1 | J12: 1 | K12: 0 | L12: 0 | M12: 120 | N12: 0 | O12: =SUM(C12:L12,N12) -> 81 | P12: =SUM(C12:N12) -> 201 | R12: 0900-1000 | S12: =SUM(C18:C21) -> 53 | T12: =SUM(D18:D21) -> 27 | U12: =SUM(E18:E21) -> 7 | V12: =SUM(F18:F21) -> 188 | W12: =SUM(G18:G21) -> 1 | X12: =SUM(H18:H21) -> 0 | Y12: =SUM(I18:I21) -> 11 | Z12: =SUM(J18:J21) -> 7 | ... AF12: =SUM(P18:P21) -> 735
B13: 07.45 - 08.00 | C13: 8 | D13: 9 | E13: 1 | F13: 60 | G13: 2 | H13: 0 | I13: 1 | J13: 0 | K13: 0 | L13: 0 | M13: 133 | N13: 0 | O13: =SUM(C13:L13,N13) -> 81 | P13: =SUM(C13:N13) -> 214 | R13: 1000-1100 | S13: =SUM(C22:C25) -> 24 | T13: =SUM(D22:D25) -> 22 | U13: =SUM(E22:E25) -> 4 | V13: =SUM(F22:F25) -> 228 | W13: =SUM(G22:G25) -> 0 | X13: =SUM(H22:H25) -> 0 | Y13: =SUM(I22:I25) -> 6 | Z13: =SUM(J22:J25) -> 4 | ... AF13: =SUM(P22:P25) -> 912
B14: 08.00 - 08.15 | C14: 13 | D14: 7 | E14: 3 | F14: 75 | G14: 0 | H14: 0 | I14: 4 | J14: 2 | K14: 0 | L14: 0 | M14: 145 | N14: 0 | O14: =SUM(C14:L14,N14) -> 104 | P14: =SUM(C14:N14) -> 249 | R14: 1100-1200 | S14: =SUM(C26:C29) -> 45 | T14: =SUM(D26:D29) -> 26 | U14: =SUM(E26:E29) -> 7 | V14: =SUM(F26:F29) -> 123 | W14: =SUM(G26:G29) -> 0 | X14: =SUM(H26:H29) -> 0 | Y14: =SUM(I26:I29) -> 15 | Z14: =SUM(J26:J29) -> 1 | ... AF14: =SUM(P26:P29) -> 682
B15: 08.15 - 08.30 | C15: 13 | D15: 4 | E15: 1 | F15: 67 | G15: 1 | H15: 0 | I15: 4 | J15: 2 | K15: 0 | L15: 0 | M15: 165 | N15: 0 | O15: =SUM(C15:L15,N15) -> 92 | P15: =SUM(C15:N15) -> 257 | R15: 1200-1300 | S15: =SUM(C30:C33) -> 46 | T15: =SUM(D30:D33) -> 47 | U15: =SUM(E30:E33) -> 15 | V15: =SUM(F30:F33) -> 108 | W15: =SUM(G30:G33) -> 1 | X15: =SUM(H30:H33) -> 0 | Y15: =SUM(I30:I33) -> 12 | Z15: =SUM(J30:J33) -> 3 | ... AF15: =SUM(P30:P33) -> 604
B16: 08.30 - 08.45 | C16: 6 | D16: 7 | E16: 1 | F16: 69 | G16: 2 | H16: 0 | I16: 0 | J16: 0 | K16: 0 | L16: 0 | M16: 165 | N16: 0 | O16: =SUM(C16:L16,N16) -> 85 | P16: =SUM(C16:N16) -> 250 | R16: 1300-1400 | S16: =SUM(C34:C37) -> 41 | T16: =SUM(D34:D37) -> 25 | U16: =SUM(E34:E37) -> 18 | V16: =SUM(F34:F37) -> 90 | W16: =SUM(G34:G37) -> 1 | X16: =SUM(H34:H37) -> 0 | Y16: =SUM(I34:I37) -> 10 | Z16: =SUM(J34:J37) -> 2 | ... AF16: =SUM(P34:P37) -> 440
B17: 08.45 - 9.00 | C17: 10 | D17: 4 | E17: 1 | F17: 52 | G17: 1 | H17: 0 | I17: 1 | J17: 0 | K17: 0 | L17: 0 | M17: 164 | N17: 0 | O17: =SUM(C17:L17,N17) -> 69 | P17: =SUM(C17:N17) -> 233 | R17: 1400-1500 | S17: =SUM(C38:C41) -> 58 | T17: =SUM(D38:D41) -> 46 | U17: =SUM(E38:E41) -> 12 | V17: =SUM(F38:F41) -> 84 | W17: =SUM(G38:G41) -> 0 | X17: =SUM(H38:H41) -> 0 | Y17: =SUM(I38:I41) -> 16 | Z17: =SUM(J38:J41) -> 2 | ... AF17: =SUM(P38:P41) -> 673
B18: 09.00 - 09.15 | C18: 4 | D18: 8 | E18: 2 | F18: 52 | G18: 0 | H18: 0 | I18: 1 | J18: 0 | K18: 0 | L18: 0 | M18: 117 | N18: 0 | O18: =SUM(C18:L18,N18) -> 67 | P18: =SUM(C18:N18) -> 184 | R18: 1500-1600 | S18: =SUM(C42:C45) -> 85 | T18: =SUM(D42:D45) -> 43 | U18: =SUM(E42:E45) -> 15 | V18: =SUM(F42:F45) -> 97 | W18: =SUM(G42:G45) -> 0 | X18: =SUM(H42:H45) -> 0 | Y18: =SUM(I42:I45) -> 25 | Z18: =SUM(J42:J45) -> 8 | ... AF18: =SUM(P42:P45) -> 753
B19: 09.15 - 09.30 | C19: 15 | D19: 2 | E19: 3 | F19: 42 | G19: 0 | H19: 0 | I19: 2 | J19: 2 | K19: 0 | L19: 0 | M19: 154 | N19: 0 | O19: =SUM(C19:L19,N19) -> 66 | P19: =SUM(C19:N19) -> 220 | R19: 1600-1700 | S19: =SUM(C46:C49) -> 103 | T19: =SUM(D46:D49) -> 59 | U19: =SUM(E46:E49) -> 18 | V19: =SUM(F46:F49) -> 93 | W19: =SUM(G46:G49) -> 1 | X19: =SUM(H46:H49) -> 1 | Y19: =SUM(I46:I49) -> 20 | Z19: =SUM(J46:J49) -> 2 | ... AF19: =SUM(P46:P49) -> 775
B20: 09.30 - 09.45 | C20: 17 | D20: 11 | E20: 0 | F20: 47 | G20: 0 | H20: 0 | I20: 2 | J20: 2 | K20: 0 | L20: 0 | M20: 154 | N20: 0 | O20: =SUM(C20:L20,N20) -> 79 | P20: =SUM(C20:N20) -> 233 | R20: 1700-1800 | S20: =SUM(C50:C53) -> 109 | T20: =SUM(D50:D53) -> 65 | U20: =SUM(E50:E53) -> 18 | V20: =SUM(F50:F53) -> 117 | W20: =SUM(G50:G53) -> 1 | X20: =SUM(H50:H53) -> 3 | Y20: =SUM(I50:I53) -> 22 | Z20: =SUM(J50:J53) -> 2 | ... AF20: =SUM(P50:P53) -> 867
B21: 09.45 - 10.00 | C21: 17 | D21: 6 | E21: 2 | F21: 47 | G21: 1 | H21: 0 | I21: 6 | J21: 3 | K21: 1 | L21: 0 | M21: 15 | N21: 0 | O21: =SUM(C21:L21,N21) -> 83 | P21: =SUM(C21:N21) -> 98 | R21: 1800-1900 | S21: =SUM(C54:C57) -> 144 | T21: =SUM(D54:D57) -> 53 | U21: =SUM(E54:E57) -> 17 | V21: =SUM(F54:F57) -> 152 | W21: =SUM(G54:G57) -> 4 | X21: =SUM(H54:H57) -> 1 | Y21: =SUM(I54:I57) -> 14 | Z21: =SUM(J54:J57) -> 0 | ... AF21: =SUM(P54:P57) -> 953
B22: 10.00 - 10.15 | C22: 14 | D22: 5 | E22: 0 | F22: 40 | G22: 0 | H22: 0 | I22: 4 | J22: 2 | K22: 0 | L22: 0 | M22: 145 | N22: 0 | O22: =SUM(C22:L22,N22) -> 65 | P22: =SUM(C22:N22) -> 210 | R22: AM Peak Hr | S22: =MAX(S10:S12) -> 53 | T22: =MAX(T10:T12) -> 32 | U22: =MAX(U10:U12) -> 7 | V22: =MAX(V10:V12) -> 263 | W22: =MAX(W10:W12) -> 5 | X22: =MAX(X10:X12) -> 2 | Y22: =MAX(Y10:Y12) -> 11 | Z22: =MAX(Z10:Z12) -> 7 | ... AF22: =MAX(AF10:AF12) -> 989
B23: 10.15 - 10.30 | C23: 6 | D23: 6 | E23: 4 | F23: 43 | G23: 0 | H23: 0 | I23: 2 | J23: 2 | K23: 1 | L23: 0 | M23: 225 | N23: 0 | O23: =SUM(C23:L23,N23) -> 64 | P23: =SUM(C23:N23) -> 289 | R23: IP Peak Hr | S23: =MAX(S13:S18) -> 85 | T23: =MAX(T13:T18) -> 47 | U23: =MAX(U13:U18) -> 18 | V23: =MAX(V13:V18) -> 228 | W23: =MAX(W13:W18) -> 1 | X23: =MAX(X13:X18) -> 0 | Y23: =MAX(Y13:Y18) -> 25 | Z23: =MAX(Z13:Z18) -> 8 | ... AF23: =MAX(AF13:AF18) -> 912
B24: 10.30 - 10.45 | C24: 1 | D24: 4 | E24: 0 | F24: 85 | G24: 0 | H24: 0 | I24: 0 | J24: 0 | K24: 1 | L24: 0 | M24: 125 | N24: 0 | O24: =SUM(C24:L24,N24) -> 91 | P24: =SUM(C24:N24) -> 216 | R24: PM Peak Hr | S24: =MAX(S19:S21) -> 144 | T24: =MAX(T19:T21) -> 65 | U24: =MAX(U19:U21) -> 18 | V24: =MAX(V19:V21) -> 152 | W24: =MAX(W19:W21) -> 4 | X24: =MAX(X19:X21) -> 3 | Y24: =MAX(Y19:Y21) -> 22 | Z24: =MAX(Z19:Z21) -> 2 | ... AF24: =MAX(AF19:AF21) -> 953
B25: 10.45 - 11.00 | C25: 3 | D25: 7 | E25: 0 | F25: 60 | G25: 0 | H25: 0 | I25: 0 | J25: 0 | K25: 2 | L25: 0 | M25: 125 | N25: 0 | O25: =SUM(C25:L25,N25) -> 72 | P25: =SUM(C25:N25) -> 197 | R25: AM Period | S25: =SUM(S10:S12) -> 140 | T25: =SUM(T10:T12) -> 81 | U25: =SUM(U10:U12) -> 16 | V25: =SUM(V10:V12) -> 714 | W25: =SUM(W10:W12) -> 10 | X25: =SUM(X10:X12) -> 2 | Y25: =SUM(Y10:Y12) -> 26 | Z25: =SUM(Z10:Z12) -> 13 | ... AF25: =SUM(AF10:AF12) -> 2562
B26: 11.00 - 11.15 | C26: 9 | D26: 8 | E26: 2 | F26: 40 | G26: 0 | H26: 0 | I26: 1 | J26: 0 | K26: 1 | L26: 0 | M26: 120 | N26: 0 | O26: =SUM(C26:L26,N26) -> 61 | P26: =SUM(C26:N26) -> 181 | R26: IP Period | S26: =SUM(S13:S18) -> 299 | T26: =SUM(T13:T18) -> 209 | U26: =SUM(U13:U18) -> 71 | V26: =SUM(V13:V18) -> 730 | W26: =SUM(W13:W18) -> 2 | X26: =SUM(X13:X18) -> 0 | Y26: =SUM(Y13:Y18) -> 84 | Z26: =SUM(Z13:Z18) -> 20 | ... AF26: =SUM(AF13:AF18) -> 4064
B27: 11.15 - 11.30 | C27: 14 | D27: 5 | E27: 2 | F27: 36 | G27: 0 | H27: 0 | I27: 4 | J27: 0 | K27: 1 | L27: 0 | M27: 120 | N27: 0 | O27: =SUM(C27:L27,N27) -> 62 | P27: =SUM(C27:N27) -> 182 | R27: PM Period | S27: =SUM(S19:S21) -> 356 | T27: =SUM(T19:T21) -> 177 | U27: =SUM(U19:U21) -> 53 | V27: =SUM(V19:V21) -> 362 | W27: =SUM(W19:W21) -> 6 | X27: =SUM(X19:X21) -> 5 | Y27: =SUM(Y19:Y21) -> 56 | Z27: =SUM(Z19:Z21) -> 4 | ... AF27: =SUM(AF19:AF21) -> 2595
B28: 11.30 - 11.45 | C28: 11 | D28: 3 | E28: 1 | F28: 24 | G28: 0 | H28: 0 | I28: 6 | J28: 0 | K28: 2 | L28: 0 | M28: 106 | N28: 0 | O28: =SUM(C28:L28,N28) -> 47 | P28: =SUM(C28:N28) -> 153 | R28: 12 Hours | S28: =SUM(S10:S21) -> 795 | T28: =SUM(T10:T21) -> 467 | U28: =SUM(U10:U21) -> 140 | V28: =SUM(V10:V21) -> 1806 | W28: =SUM(W10:W21) -> 18 | X28: =SUM(X10:X21) -> 7 | Y28: =SUM(Y10:Y21) -> 166 | Z28: =SUM(Z10:Z21) -> 37 | ... AF28: =SUM(AF10:AF21) -> 9221
