Workbook

Sheet 29.07 Najjeera-Kiwatule
B1: Consultancy services for Preparation of Expressway Development Master Plan (EDMP) for Uganda
B2: MANUAL CLASSIFIED COUNT (MCC)
B3: ROAD NAME: | C3: MCC - C1 - STN36 - MBOGO ROAD
C5: Date | D5: 29.07.19 | F5: Location | G5: U Save Kiwatule | J5: Surveyor | K5: Anthony
C6: Dir. From | D6: Najjeera | F6: Dir. To | G6: Kiwatule | J6: Supervisor | K6: Steven
B8: Time / Veh Type | R8: SUMMARY TRAFFIC VOLUMES
C9: 1. Car | D9: 2. Station Wagon | E9: 3. Pickups | F9: 4. Minibus, matatu | G9: 5. Medium bus | H9: 6. Large Bus | I9: 7. Light Truck | J9: 8. Medium Truck | K9: 9. Heavy truck | L9: 10. Truck Trailer | M9: 11. Motor cycles | N9: 12. Tractors | O9: Total Excl M/Cycles | P9: Total All | R9: Time | S9: 1. Car | T9: 2. Station Wagon | U9: 3. Pickups | V9: 4. Minibus, matatu | W9: 5. Medium bus | X9: 6. Large Bus | Y9: 7. Light Truck | Z9: 8. Medium Truck | AA9: 9. Heavy truck | AB9: 10. Truck Trailer | AC9: 11. Motorcycles | AD9: 12. Tractors, Graders | AE9: Total Excl M/ Cycles | AF9: Total All
B10: 07.00 - 07.15 | C10: 94 | D10: 19 | E10: 11 | F10: 22 | G10: 0 | H10: 0 | I10: 2 | J10: 4 | K10: 1 | L10: 2 | M10: 80 | N10: 0 | O10: =SUM(C10:L10,N10) -> 155 | P10: =SUM(C10:N10) -> 235 | R10: 0700-0800 | S10: =SUM(C10:C13) -> 383 | T10: =SUM(D10:D13) -> 80 | U10: =SUM(E10:E13) -> 59 | V10: =SUM(F10:F13) -> 75 | W10: =SUM(G10:G13) -> 0 | X10: =SUM(H10:H13) -> 0 | Y10: =SUM(I10:I13) -> 11 | Z10: =SUM(J10:J13) -> 10 | ... AF10: =SUM(P10:P13) -> 994
B11: 07.15 - 07.30 | C11: 93 | D11: 22 | E11: 16 | F11: 13 | G11: 0 | H11: 0 | I11: 1 | J11: 0 | K11: 2 | L11: 0 | M11: 100 | N11: 0 | O11: =SUM(C11:L11,N11) -> 147 | P11: =SUM(C11:N11) -> 247 | R11: 0800-0900 | S11: =SUM(C14:C17) -> 346 | T11: =SUM(D14:D17) -> 97 | U11: =SUM(E14:E17) -> 61 | V11: =SUM(F14:F17) -> 108 | W11: =SUM(G14:G17) -> 0 | X11: =SUM(H14:H17) -> 0 | Y11: =SUM(I14:I17) -> 9 | Z11: =SUM(J14:J17) -> 3 | ... AF11: =SUM(P14:P17) -> 910
B12: 07.30 - 07.45 | C12: 96 | D12: 18 | E12: 13 | F12: 19 | G12: 0 | H12: 0 | I12: 6 | J12: 5 | K12: 0 | L12: 1 | M12: 110 | N12: 0 | O12: =SUM(C12:L12,N12) -> 158 | P12: =SUM(C12:N12) -> 268 | R12: 0900-1000 | S12: =SUM(C18:C21) -> 364 | T12: =SUM(D18:D21) -> 55 | U12: =SUM(E18:E21) -> 38 | V12: =SUM(F18:F21) -> 58 | W12: =SUM(G18:G21) -> 0 | X12: =SUM(H18:H21) -> 0 | Y12: =SUM(I18:I21) -> 9 | Z12: =SUM(J18:J21) -> 1 | ... AF12: =SUM(P18:P21) -> 901
B13: 07.45 - 08.00 | C13: 100 | D13: 21 | E13: 19 | F13: 21 | G13: 0 | H13: 0 | I13: 2 | J13: 1 | K13: 0 | L13: 0 | M13: 80 | N13: 0 | O13: =SUM(C13:L13,N13) -> 164 | P13: =SUM(C13:N13) -> 244 | R13: 1000-1100 | S13: =SUM(C22:C25) -> 372 | T13: =SUM(D22:D25) -> 61 | U13: =SUM(E22:E25) -> 40 | V13: =SUM(F22:F25) -> 64 | W13: =SUM(G22:G25) -> 0 | X13: =SUM(H22:H25) -> 0 | Y13: =SUM(I22:I25) -> 10 | Z13: =SUM(J22:J25) -> 15 | ... AF13: =SUM(P22:P25) -> 898
B14: 08.00 - 08.15 | C14: 86 | D14: 28 | E14: 11 | F14: 32 | G14: 0 | H14: 0 | I14: 4 | J14: 1 | K14: 3 | L14: 0 | M14: 65 | N14: 0 | O14: =SUM(C14:L14,N14) -> 165 | P14: =SUM(C14:N14) -> 230 | R14: 1100-1200 | S14: =SUM(C26:C29) -> 370 | T14: =SUM(D26:D29) -> 42 | U14: =SUM(E26:E29) -> 46 | V14: =SUM(F26:F29) -> 70 | W14: =SUM(G26:G29) -> 0 | X14: =SUM(H26:H29) -> 0 | Y14: =SUM(I26:I29) -> 11 | Z14: =SUM(J26:J29) -> 6 | ... AF14: =SUM(P26:P29) -> 886
B15: 08.15 - 08.30 | C15: 77 | D15: 13 | E15: 15 | F15: 28 | G15: 0 | H15: 0 | I15: 2 | J15: 0 | K15: 0 | L15: 0 | M15: 75 | N15: 0 | O15: =SUM(C15:L15,N15) -> 135 | P15: =SUM(C15:N15) -> 210 | R15: 1200-1300 | S15: =SUM(C30:C33) -> 295 | T15: =SUM(D30:D33) -> 48 | U15: =SUM(E30:E33) -> 33 | V15: =SUM(F30:F33) -> 51 | W15: =SUM(G30:G33) -> 0 | X15: =SUM(H30:H33) -> 0 | Y15: =SUM(I30:I33) -> 15 | Z15: =SUM(J30:J33) -> 8 | ... AF15: =SUM(P30:P33) -> 714
B16: 08.30 - 08.45 | C16: 75 | D16: 22 | E16: 19 | F16: 21 | G16: 0 | H16: 0 | I16: 0 | J16: 0 | K16: 1 | L16: 2 | M16: 80 | N16: 0 | O16: =SUM(C16:L16,N16) -> 140 | P16: =SUM(C16:N16) -> 220 | R16: 1300-1400 | S16: =SUM(C34:C37) -> 263 | T16: =SUM(D34:D37) -> 30 | U16: =SUM(E34:E37) -> 37 | V16: =SUM(F34:F37) -> 51 | W16: =SUM(G34:G37) -> 1 | X16: =SUM(H34:H37) -> 0 | Y16: =SUM(I34:I37) -> 13 | Z16: =SUM(J34:J37) -> 6 | ... AF16: =SUM(P34:P37) -> 665
B17: 08.45 - 9.00 | C17: 108 | D17: 34 | E17: 16 | F17: 27 | G17: 0 | H17: 0 | I17: 3 | J17: 2 | K17: 0 | L17: 0 | M17: 60 | N17: 0 | O17: =SUM(C17:L17,N17) -> 190 | P17: =SUM(C17:N17) -> 250 | R17: 1400-1500 | S17: =SUM(C38:C41) -> 192 | T17: =SUM(D38:D41) -> 29 | U17: =SUM(E38:E41) -> 22 | V17: =SUM(F38:F41) -> 46 | W17: =SUM(G38:G41) -> 0 | X17: =SUM(H38:H41) -> 0 | Y17: =SUM(I38:I41) -> 16 | Z17: =SUM(J38:J41) -> 6 | ... AF17: =SUM(P38:P41) -> 599
B18: 09.00 - 09.15 | C18: 55 | D18: 9 | E18: 2 | F18: 7 | G18: 0 | H18: 0 | I18: 0 | J18: 1 | K18: 0 | L18: 0 | M18: 90 | N18: 0 | O18: =SUM(C18:L18,N18) -> 74 | P18: =SUM(C18:N18) -> 164 | R18: 1500-1600 | S18: =SUM(C42:C45) -> 232 | T18: =SUM(D42:D45) -> 31 | U18: =SUM(E42:E45) -> 25 | V18: =SUM(F42:F45) -> 37 | W18: =SUM(G42:G45) -> 0 | X18: =SUM(H42:H45) -> 0 | Y18: =SUM(I42:I45) -> 23 | Z18: =SUM(J42:J45) -> 4 | ... AF18: =SUM(P42:P45) -> 671
B19: 09.15 - 09.30 | C19: 81 | D19: 9 | E19: 12 | F19: 13 | G19: 0 | H19: 0 | I19: 2 | J19: 0 | K19: 0 | L19: 0 | M19: 75 | N19: 0 | O19: =SUM(C19:L19,N19) -> 117 | P19: =SUM(C19:N19) -> 192 | R19: 1600-1700 | S19: =SUM(C46:C49) -> 264 | T19: =SUM(D46:D49) -> 34 | U19: =SUM(E46:E49) -> 32 | V19: =SUM(F46:F49) -> 45 | W19: =SUM(G46:G49) -> 1 | X19: =SUM(H46:H49) -> 0 | Y19: =SUM(I46:I49) -> 13 | Z19: =SUM(J46:J49) -> 2 | ... AF19: =SUM(P46:P49) -> 667
B20: 09.30 - 09.45 | C20: 110 | D20: 11 | E20: 15 | F20: 17 | G20: 0 | H20: 0 | I20: 3 | J20: 0 | K20: 0 | L20: 0 | M20: 111 | N20: 0 | O20: =SUM(C20:L20,N20) -> 156 | P20: =SUM(C20:N20) -> 267 | R20: 1700-1800 | S20: =SUM(C50:C53) -> 242 | T20: =SUM(D50:D53) -> 26 | U20: =SUM(E50:E53) -> 28 | V20: =SUM(F50:F53) -> 51 | W20: =SUM(G50:G53) -> 6 | X20: =SUM(H50:H53) -> 0 | Y20: =SUM(I50:I53) -> 12 | Z20: =SUM(J50:J53) -> 3 | ... AF20: =SUM(P50:P53) -> 675
B21: 09.45 - 10.00 | C21: 118 | D21: 26 | E21: 9 | F21: 21 | G21: 0 | H21: 0 | I21: 4 | J21: 0 | K21: 0 | L21: 0 | M21: 100 | N21: 0 | O21: =SUM(C21:L21,N21) -> 178 | P21: =SUM(C21:N21) -> 278 | R21: 1800-1900 | S21: =SUM(C54:C57) -> 181 | T21: =SUM(D54:D57) -> 25 | U21: =SUM(E54:E57) -> 31 | V21: =SUM(F54:F57) -> 87 | W21: =SUM(G54:G57) -> 1 | X21: =SUM(H54:H57) -> 0 | Y21: =SUM(I54:I57) -> 10 | Z21: =SUM(J54:J57) -> 2 | ... AF21: =SUM(P54:P57) -> 693
B22: 10.00 - 10.15 | C22: 100 | D22: 12 | E22: 7 | F22: 15 | G22: 0 | H22: 0 | I22: 4 | J22: 3 | K22: 0 | L22: 0 | M22: 85 | N22: 0 | O22: =SUM(C22:L22,N22) -> 141 | P22: =SUM(C22:N22) -> 226 | R22: AM Peak Hr | S22: =MAX(S10:S12) -> 383 | T22: =MAX(T10:T12) -> 97 | U22: =MAX(U10:U12) -> 61 | V22: =MAX(V10:V12) -> 108 | W22: =MAX(W10:W12) -> 0 | X22: =MAX(X10:X12) -> 0 | Y22: =MAX(Y10:Y12) -> 11 | Z22: =MAX(Z10:Z12) -> 10 | ... AF22: =MAX(AF10:AF12) -> 994
B23: 10.15 - 10.30 | C23: 91 | D23: 24 | E23: 9 | F23: 17 | G23: 0 | H23: 0 | I23: 2 | J23: 6 | K23: 0 | L23: 0 | M23: 80 | N23: 0 | O23: =SUM(C23:L23,N23) -> 149 | P23: =SUM(C23:N23) -> 229 | R23: IP Peak Hr | S23: =MAX(S13:S18) -> 372 | T23: =MAX(T13:T18) -> 61 | U23: =MAX(U13:U18) -> 46 | V23: =MAX(V13:V18) -> 70 | W23: =MAX(W13:W18) -> 1 | X23: =MAX(X13:X18) -> 0 | Y23: =MAX(Y13:Y18) -> 23 | Z23: =MAX(Z13:Z18) -> 15 | ... AF23: =MAX(AF13:AF18) -> 898
B24: 10.30 - 10.45 | C24: 91 | D24: 10 | E24: 15 | F24: 15 | G24: 0 | H24: 0 | I24: 2 | J24: 1 | K24: 1 | L24: 0 | M24: 90 | N24: 0 | O24: =SUM(C24:L24,N24) -> 135 | P24: =SUM(C24:N24) -> 225 | R24: PM Peak Hr | S24: =MAX(S19:S21) -> 264 | T24: =MAX(T19:T21) -> 34 | U24: =MAX(U19:U21) -> 32 | V24: =MAX(V19:V21) -> 87 | W24: =MAX(W19:W21) -> 6 | X24: =MAX(X19:X21) -> 0 | Y24: =MAX(Y19:Y21) -> 13 | Z24: =MAX(Z19:Z21) -> 3 | ... AF24: =MAX(AF19:AF21) -> 693
B25: 10.45 - 11.00 | C25: 90 | D25: 15 | E25: 9 | F25: 17 | G25: 0 | H25: 0 | I25: 2 | J25: 5 | K25: 0 | L25: 0 | M25: 80 | N25: 0 | O25: =SUM(C25:L25,N25) -> 138 | P25: =SUM(C25:N25) -> 218 | R25: AM Period | S25: =SUM(S10:S12) -> 1093 | T25: =SUM(T10:T12) -> 232 | U25: =SUM(U10:U12) -> 158 | V25: =SUM(V10:V12) -> 241 | W25: =SUM(W10:W12) -> 0 | X25: =SUM(X10:X12) -> 0 | Y25: =SUM(Y10:Y12) -> 29 | Z25: =SUM(Z10:Z12) -> 14 | ... AF25: =SUM(AF10:AF12) -> 2805
B26: 11.00 - 11.15 | C26: 126 | D26: 14 | E26: 18 | F26: 24 | G26: 0 | H26: 0 | I26: 3 | J26: 1 | K26: 2 | L26: 0 | M26: 85 | N26: 0 | O26: =SUM(C26:L26,N26) -> 188 | P26: =SUM(C26:N26) -> 273 | R26: IP Period | S26: =SUM(S13:S18) -> 1724 | T26: =SUM(T13:T18) -> 241 | U26: =SUM(U13:U18) -> 203 | V26: =SUM(V13:V18) -> 319 | W26: =SUM(W13:W18) -> 1 | X26: =SUM(X13:X18) -> 0 | Y26: =SUM(Y13:Y18) -> 88 | Z26: =SUM(Z13:Z18) -> 45 | ... AF26: =SUM(AF13:AF18) -> 4433
B27: 11.15 - 11.30 | C27: 107 | D27: 14 | E27: 12 | F27: 13 | G27: 0 | H27: 0 | I27: 4 | J27: 2 | K27: 2 | L27: 0 | M27: 75 | N27: 0 | O27: =SUM(C27:L27,N27) -> 154 | P27: =SUM(C27:N27) -> 229 | R27: PM Period | S27: =SUM(S19:S21) -> 687 | T27: =SUM(T19:T21) -> 85 | U27: =SUM(U19:U21) -> 91 | V27: =SUM(V19:V21) -> 183 | W27: =SUM(W19:W21) -> 8 | X27: =SUM(X19:X21) -> 0 | Y27: =SUM(Y19:Y21) -> 35 | Z27: =SUM(Z19:Z21) -> 7 | ... AF27: =SUM(AF19:AF21) -> 2035
B28: 11.30 - 11.45 | C28: 60 | D28: 6 | E28: 8 | F28: 16 | G28: 0 | H28: 0 | I28: 3 | J28: 0 | K28: 0 | L28: 0 | M28: 120 | N28: 0 | O28: =SUM(C28:L28,N28) -> 93 | P28: =SUM(C28:N28) -> 213 | R28: 12 Hours | S28: =SUM(S10:S21) -> 3504 | T28: =SUM(T10:T21) -> 558 | U28: =SUM(U10:U21) -> 452 | V28: =SUM(V10:V21) -> 743 | W28: =SUM(W10:W21) -> 9 | X28: =SUM(X10:X21) -> 0 | Y28: =SUM(Y10:Y21) -> 152 | Z28: =SUM(Z10:Z21) -> 66 | ... AF28: =SUM(AF10:AF21) -> 9273
B29: 11.45 - 12.00 | C29: 77 | D29: 8 | E29: 8 | F29: 17 | G29: 0 | H29: 0 | I29: 1 | J29: 3 | K29: 1 | L29: 1 | M29: 55 | N29: 0 | O29: =SUM(C29:L29,N29) -> 116 | P29: =SUM(C29:N29) -> 171
B30: 12.00 - 12.15 | C30: 54 | D30: 14 | E30: 7 | F30: 11 | G30: 0 | H30: 0 | I30: 5 | J30: 4 | K30: 1 | L30: 0 | M30: 65 | N30: 0 | O30: =SUM(C30:L30,N30) -> 96 | P30: =SUM(C30:N30) -> 161
B31: 12.15 - 12.30 | C31: 106 | D31: 13 | E31: 5 | F31: 12 | G31: 0 | H31: 0 | I31: 4 | J31: 1 | K31: 1 | L31: 1 | M31: 65 | N31: 0 | O31: =SUM(C31:L31,N31) -> 143 | P31: =SUM(C31:N31) -> 208
B32: 12.30 - 12.45 | C32: 60 | D32: 10 | E32: 11 | F32: 15 | G32: 0 | H32: 0 | I32: 1 | J32: 2 | K32: 0 | L32: 0 | M32: 72 | N32: 0 | O32: =SUM(C32:L32,N32) -> 99 | P32: =SUM(C32:N32) -> 171
B33: 12.45 - 13.00 | C33: 75 | D33: 11 | E33: 10 | F33: 13 | G33: 0 | H33: 0 | I33: 5 | J33: 1 | K33: 2 | L33: 0 | M33: 57 | N33: 0 | O33: =SUM(C33:L33,N33) -> 117 | P33: =SUM(C33:N33) -> 174
B34: 13.00 - 13.15 | C34: 70 | D34: 6 | E34: 10 | F34: 12 | G34: 0 | H34: 0 | I34: 3 | J34: 1 | K34: 2 | L34: 0 | M34: 70 | N34: 0 | O34: =SUM(C34:L34,N34) -> 104 | P34: =SUM(C34:N34) -> 174
B35: 13.15 - 13.30 | C35: 62 | D35: 8 | E35: 8 | F35: 12 | G35: 0 | H35: 0 | I35: 4 | J35: 1 | K35: 1 | L35: 0 | M35: 85 | N35: 0 | O35: =SUM(C35:L35,N35) -> 96 | P35: =SUM(C35:N35) -> 181
B36: 13.30 - 13.45 | C36: 58 | D36: 6 | E36: 9 | F36: 14 | G36: 1 | H36: 0 | I36: 3 | J36: 1 | K36: 1 | L36: 0 | M36: 50 | N36: 0 | O36: =SUM(C36:L36,N36) -> 93 | P36: =SUM(C36:N36) -> 143
B37: 13.45 - 14.00 | C37: 73 | D37: 10 | E37: 10 | F37: 13 | G37: 0 | H37: 0 | I37: 3 | J37: 3 | K37: 0 | L37: 0 | M37: 55 | N37: 0 | O37: =SUM(C37:L37,N37) -> 112 | P37: =SUM(C37:N37) -> 167
B38: 14.00 - 14.15 | C38: 57 | D38: 9 | E38: 6 | F38: 11 | G38: 0 | H38: 0 | I38: 6 | J38: 3 | K38: 2 | L38: 0 | M38: 80 | N38: 0 | O38: =SUM(C38:L38,N38) -> 94 | P38: =SUM(C38:N38) -> 174
B39: 14.15 - 14.30 | C39: 30 | D39: 3 | E39: 3 | F39: 6 | G39: 0 | H39: 0 | I39: 4 | J39: 1 | K39: 1 | L39: 0 | M39: 72 | N39: 0 | O39: =SUM(C39:L39,N39) -> 48 | P39: =SUM(C39:N39) -> 120
B40: 14.30 - 14.45 | C40: 62 | D40: 11 | E40: 7 | F40: 12 | G40: 0 | H40: 0 | I40: 3 | J40: 2 | K40: 0 | L40: 0 | M40: 64 | N40: 0 | O40: =SUM(C40:L40,N40) -> 97 | P40: =SUM(C40:N40) -> 161
... B57: 18.45 - 19.00 | C57: 43 | D57: 5 | E57: 14 | F57: 35 | G57: 0 | H57: 0 | I57: 1 | J57: 0 | K57: 0 | L57: 0 | M57: 90 | N57: 0 | O57: =SUM(C57:L57,N57) -> 98 | P57: =SUM(C57:N57) -> 188
B58: Totals | C58: =SUM(C10:C57) -> 3504 | D58: =SUM(D10:D57) -> 558 | E58: =SUM(E10:E57) -> 452 | F58: =SUM(F10:F57) -> 743 | G58: =SUM(G10:G57) -> 9 | H58: =SUM(H10:H57) -> 0 | I58: =SUM(I10:I57) -> 152 | J58: =SUM(J10:J57) -> 66 | ... P58: =SUM(P10:P57) -> 9273
...

Sheet 29.07 Kiwatule-Najjeera
B1: Consultancy services for Preparation of Expressway Development Master Plan (EDMP) for Uganda
B2: MANUAL CLASSIFIED COUNT (MCC)
B3: ROAD NAME: | C3: ='29.07 Najjeera-Kiwatule'!C3:G3 -> MCC - C1 - STN36 - MBOGO ROAD
C5: Date | D5: ='29.07 Najjeera-Kiwatule'!D5 -> 29.07.19 | F5: Location | G5: ='29.07 Najjeera-Kiwatule'!G5:H5 -> U Save Kiwatule | J5: Surveyor | K5: Beteth
C6: Dir. From | D6: Kiwatule | F6: Dir. To | G6: Najjeera | J6: Supervisor | K6: ='29.07 Najjeera-Kiwatule'!K6:L6 -> Steven
B8: Time / Veh Type | R8: SUMMARY TRAFFIC VOLUMES
C9: 1. Car | D9: 2. Station Wagon | E9: 3. Pickups | F9: 4. Minibus, matatu | G9: 5. Medium bus | H9: 6. Large Bus | I9: 7. Light Truck | J9: 8. Medium Truck | K9: 9. Heavy truck | L9: 10. Truck Trailer | M9: 11. Motor cycles | N9: 12. Tractors | O9: Total Excl M/Cycles | P9: Total All | R9: Time | S9: 1. Car | T9: 2. Station Wagon | U9: 3. Pickups | V9: 4. Minibus, matatu | W9: 5. Medium bus | X9: 6. Large Bus | Y9: 7. Light Truck | Z9: 8. Medium Truck | AA9: 9. Heavy truck | AB9: 10. Truck Trailer | AC9: 11. Motorcycles | AD9: 12. Tractors, Graders | AE9: Total Excl M/ Cycles | AF9: Total All
B10: 07.00 - 07.15 | C10: 15 | D10: 7 | E10: 1 | F10: 15 | G10: 2 | H10: 0 | I10: 3 | J10: 0 | K10: 0 | L10: 0 | M10: 22 | N10: 0 | O10: =SUM(C10:L10,N10) -> 43 | P10: =SUM(C10:N10) -> 65 | R10: 0700-0800 | S10: =SUM(C10:C13) -> 44 | T10: =SUM(D10:D13) -> 15 | U10: =SUM(E10:E13) -> 3 | V10: =SUM(F10:F13) -> 47 | W10: =SUM(G10:G13) -> 3 | X10: =SUM(H10:H13) -> 0 | Y10: =SUM(I10:I13) -> 6 | Z10: =SUM(J10:J13) -> 1 | ... AF10: =SUM(P10:P13) -> 173
B11: 07.15 - 07.30 | C11: 8 | D11: 4 | E11: 0 | F11: 10 | G11: 0 | H11: 0 | I11: 1 | J11: 1 | K11: 0 | L11: 0 | M11: 13 | N11: 0 | O11: =SUM(C11:L11,N11) -> 24 | P11: =SUM(C11:N11) -> 37 | R11: 0800-0900 | S11: =SUM(C14:C17) -> 29 | T11: =SUM(D14:D17) -> 6 | U11: =SUM(E14:E17) -> 3 | V11: =SUM(F14:F17) -> 42 | W11: =SUM(G14:G17) -> 1 | X11: =SUM(H14:H17) -> 0 | Y11: =SUM(I14:I17) -> 9 | Z11: =SUM(J14:J17) -> 0 | ... AF11: =SUM(P14:P17) -> 125
B12: 07.30 - 07.45 | C12: 12 | D12: 3 | E12: 2 | F12: 13 | G12: 1 | H12: 0 | I12: 2 | J12: 0 | K12: 0 | L12: 0 | M12: 10 | N12: 0 | O12: =SUM(C12:L12,N12) -> 33 | P12: =SUM(C12:N12) -> 43 | R12: 0900-1000 | S12: =SUM(C18:C21) -> 106 | T12: =SUM(D18:D21) -> 16 | U12: =SUM(E18:E21) -> 5 | V12: =SUM(F18:F21) -> 74 | W12: =SUM(G18:G21) -> 0 | X12: =SUM(H18:H21) -> 0 | Y12: =SUM(I18:I21) -> 22 | Z12: =SUM(J18:J21) -> 0 | ... AF12: =SUM(P18:P21) -> 447
B13: 07.45 - 08.00 | C13: 9 | D13: 1 | E13: 0 | F13: 9 | G13: 0 | H13: 0 | I13: 0 | J13: 0 | K13: 0 | L13: 0 | M13: 9 | N13: 0 | O13: =SUM(C13:L13,N13) -> 19 | P13: =SUM(C13:N13) -> 28 | R13: 1000-1100 | S13: =SUM(C22:C25) -> 152 | T13: =SUM(D22:D25) -> 23 | U13: =SUM(E22:E25) -> 14 | V13: =SUM(F22:F25) -> 92 | W13: =SUM(G22:G25) -> 0 | X13: =SUM(H22:H25) -> 0 | Y13: =SUM(I22:I25) -> 31 | Z13: =SUM(J22:J25) -> 2 | ... AF13: =SUM(P22:P25) -> 571
B14: 08.00 - 08.15 | C14: 10 | D14: 3 | E14: 1 | F14: 15 | G14: 0 | H14: 0 | I14: 5 | J14: 0 | K14: 0 | L14: 0 | M14: 10 | N14: 0 | O14: =SUM(C14:L14,N14) -> 34 | P14: =SUM(C14:N14) -> 44 | R14: 1100-1200 | S14: =SUM(C26:C29) -> 134 | T14: =SUM(D26:D29) -> 15 | U14: =SUM(E26:E29) -> 10 | V14: =SUM(F26:F29) -> 100 | W14: =SUM(G26:G29) -> 6 | X14: =SUM(H26:H29) -> 3 | Y14: =SUM(I26:I29) -> 51 | Z14: =SUM(J26:J29) -> 2 | ... AF14: =SUM(P26:P29) -> 501
B15: 08.15 - 08.30 | C15: 4 | D15: 1 | E15: 0 | F15: 9 | G15: 1 | H15: 0 | I15: 3 | J15: 0 | K15: 0 | L15: 0 | M15: 8 | N15: 0 | O15: =SUM(C15:L15,N15) -> 18 | P15: =SUM(C15:N15) -> 26 | R15: 1200-1300 | S15: =SUM(C30:C33) -> 93 | T15: =SUM(D30:D33) -> 25 | U15: =SUM(E30:E33) -> 5 | V15: =SUM(F30:F33) -> 98 | W15: =SUM(G30:G33) -> 5 | X15: =SUM(H30:H33) -> 2 | Y15: =SUM(I30:I33) -> 27 | Z15: =SUM(J30:J33) -> 3 | ... AF15: =SUM(P30:P33) -> 391
B16: 08.30 - 08.45 | C16: 6 | D16: 0 | E16: 0 | F16: 10 | G16: 0 | H16: 0 | I16: 1 | J16: 0 | K16: 0 | L16: 0 | M16: 9 | N16: 0 | O16: =SUM(C16:L16,N16) -> 17 | P16: =SUM(C16:N16) -> 26 | R16: 1300-1400 | S16: =SUM(C34:C37) -> 110 | T16: =SUM(D34:D37) -> 28 | U16: =SUM(E34:E37) -> 12 | V16: =SUM(F34:F37) -> 100 | W16: =SUM(G34:G37) -> 9 | X16: =SUM(H34:H37) -> 2 | Y16: =SUM(I34:I37) -> 14 | Z16: =SUM(J34:J37) -> 4 | ... AF16: =SUM(P34:P37) -> 420
B17: 08.45 - 9.00 | C17: 9 | D17: 2 | E17: 2 | F17: 8 | G17: 0 | H17: 0 | I17: 0 | J17: 0 | K17: 0 | L17: 0 | M17: 8 | N17: 0 | O17: =SUM(C17:L17,N17) -> 21 | P17: =SUM(C17:N17) -> 29 | R17: 1400-1500 | S17: =SUM(C38:C41) -> 162 | T17: =SUM(D38:D41) -> 26 | U17: =SUM(E38:E41) -> 12 | V17: =SUM(F38:F41) -> 42 | W17: =SUM(G38:G41) -> 3 | X17: =SUM(H38:H41) -> 1 | Y17: =SUM(I38:I41) -> 25 | Z17: =SUM(J38:J41) -> 5 | ... AF17: =SUM(P38:P41) -> 470
B18: 09.00 - 09.15 | C18: 18 | D18: 0 | E18: 0 | F18: 20 | G18: 0 | H18: 0 | I18: 1 | J18: 0 | K18: 0 | L18: 0 | M18: 40 | N18: 0 | O18: =SUM(C18:L18,N18) -> 39 | P18: =SUM(C18:N18) -> 79 | R18: 1500-1600 | S18: =SUM(C42:C45) -> 207 | T18: =SUM(D42:D45) -> 33 | U18: =SUM(E42:E45) -> 20 | V18: =SUM(F42:F45) -> 79 | W18: =SUM(G42:G45) -> 4 | X18: =SUM(H42:H45) -> 0 | Y18: =SUM(I42:I45) -> 34 | Z18: =SUM(J42:J45) -> 1 | ... AF18: =SUM(P42:P45) -> 671
B19: 09.15 - 09.30 | C19: 37 | D19: 9 | E19: 2 | F19: 15 | G19: 0 | H19: 0 | I19: 9 | J19: 0 | K19: 0 | L19: 0 | M19: 77 | N19: 0 | O19: =SUM(C19:L19,N19) -> 72 | P19: =SUM(C19:N19) -> 149 | R19: 1600-1700 | S19: =SUM(C46:C49) -> 285 | T19: =SUM(D46:D49) -> 71 | U19: =SUM(E46:E49) -> 28 | V19: =SUM(F46:F49) -> 102 | W19: =SUM(G46:G49) -> 6 | X19: =SUM(H46:H49) -> 1 | Y19: =SUM(I46:I49) -> 29 | Z19: =SUM(J46:J49) -> 5 | ... AF19: =SUM(P46:P49) -> 759
B20: 09.30 - 09.45 | C20: 19 | D20: 0 | E20: 0 | F20: 22 | G20: 0 | H20: 0 | I20: 4 | J20: 0 | K20: 0 | L20: 0 | M20: 57 | N20: 0 | O20: =SUM(C20:L20,N20) -> 45 | P20: =SUM(C20:N20) -> 102 | R20: 1700-1800 | S20: =SUM(C50:C53) -> 311 | T20: =SUM(D50:D53) -> 56 | U20: =SUM(E50:E53) -> 18 | V20: =SUM(F50:F53) -> 55 | W20: =SUM(G50:G53) -> 5 | X20: =SUM(H50:H53) -> 0 | Y20: =SUM(I50:I53) -> 25 | Z20: =SUM(J50:J53) -> 4 | ... AF20: =SUM(P50:P53) -> 720
B21: 09.45 - 10.00 | C21: 32 | D21: 7 | E21: 3 | F21: 17 | G21: 0 | H21: 0 | I21: 8 | J21: 0 | K21: 0 | L21: 0 | M21: 50 | N21: 0 | O21: =SUM(C21:L21,N21) -> 67 | P21: =SUM(C21:N21) -> 117 | R21: 1800-1900 | S21: =SUM(C54:C57) -> 420 | T21: =SUM(D54:D57) -> 56 | U21: =SUM(E54:E57) -> 23 | V21: =SUM(F54:F57) -> 55 | W21: =SUM(G54:G57) -> 2 | X21: =SUM(H54:H57) -> 2 | Y21: =SUM(I54:I57) -> 20 | Z21: =SUM(J54:J57) -> 3 | ... AF21: =SUM(P54:P57) -> 836
B22: 10.00 - 10.15 | C22: 38 | D22: 3 | E22: 4 | F22: 19 | G22: 0 | H22: 0 | I22: 8 | J22: 1 | K22: 0 | L22: 0 | M22: 55 | N22: 0 | O22: =SUM(C22:L22,N22) -> 73 | P22: =SUM(C22:N22) -> 128 | R22: AM Peak Hr | S22: =MAX(S10:S12) -> 106 | T22: =MAX(T10:T12) -> 16 | U22: =MAX(U10:U12) -> 5 | V22: =MAX(V10:V12) -> 74 | W22: =MAX(W10:W12) -> 3 | X22: =MAX(X10:X12) -> 0 | Y22: =MAX(Y10:Y12) -> 22 | Z22: =MAX(Z10:Z12) -> 1 | ... AF22: =MAX(AF10:AF12) -> 447
B23: 10.15 - 10.30 | C23: 51 | D23: 6 | E23: 3 | F23: 30 | G23: 0 | H23: 0 | I23: 6 | J23: 1 | K23: 0 | L23: 0 | M23: 74 | N23: 0 | O23: =SUM(C23:L23,N23) -> 97 | P23: =SUM(C23:N23) -> 171 | R23: IP Peak Hr | S23: =MAX(S13:S18) -> 207 | T23: =MAX(T13:T18) -> 33 | U23: =MAX(U13:U18) -> 20 | V23: =MAX(V13:V18) -> 100 | W23: =MAX(W13:W18) -> 9 | X23: =MAX(X13:X18) -> 3 | Y23: =MAX(Y13:Y18) -> 51 | Z23: =MAX(Z13:Z18) -> 5 | ... AF23: =MAX(AF13:AF18) -> 671
B24: 10.30 - 10.45 | C24: 33 | D24: 6 | E24: 2 | F24: 24 | G24: 0 | H24: 0 | I24: 12 | J24: 0 | K24: 0 | L24: 0 | M24: 81 | N24: 0 | O24: =SUM(C24:L24,N24) -> 77 | P24: =SUM(C24:N24) -> 158 | R24: PM Peak Hr | S24: =MAX(S19:S21) -> 420 | T24: =MAX(T19:T21) -> 71 | U24: =MAX(U19:U21) -> 28 | V24: =MAX(V19:V21) -> 102 | W24: =MAX(W19:W21) -> 6 | X24: =MAX(X19:X21) -> 2 | Y24: =MAX(Y19:Y21) -> 29 | Z24: =MAX(Z19:Z21) -> 5 | ... AF24: =MAX(AF19:AF21) -> 836
B25: 10.45 - 11.00 | C25: 30 | D25: 8 | E25: 5 | F25: 19 | G25: 0 | H25: 0 | I25: 5 | J25: 0 | K25: 0 | L25: 0 | M25: 47 | N25: 0 | O25: =SUM(C25:L25,N25) -> 67 | P25: =SUM(C25:N25) -> 114 | R25: AM Period | S25: =SUM(S10:S12) -> 179 | T25: =SUM(T10:T12) -> 37 | U25: =SUM(U10:U12) -> 11 | V25: =SUM(V10:V12) -> 163 | W25: =SUM(W10:W12) -> 4 | X25: =SUM(X10:X12) -> 0 | Y25: =SUM(Y10:Y12) -> 37 | Z25: =SUM(Z10:Z12) -> 1 | ... AF25: =SUM(AF10:AF12) -> 745
B26: 11.00 - 11.15 | C26: 40 | D26: 3 | E26: 2 | F26: 18 | G26: 2 | H26: 0 | I26: 20 | J26: 0 | K26: 0 | L26: 0 | M26: 37 | N26: 0 | O26: =SUM(C26:L26,N26) -> 85 | P26: =SUM(C26:N26) -> 122 | R26: IP Period | S26: =SUM(S13:S18) -> 858 | T26: =SUM(T13:T18) -> 150 | U26: =SUM(U13:U18) -> 73 | V26: =SUM(V13:V18) -> 511 | W26: =SUM(W13:W18) -> 27 | X26: =SUM(X13:X18) -> 8 | Y26: =SUM(Y13:Y18) -> 182 | Z26: =SUM(Z13:Z18) -> 17 | ... AF26: =SUM(AF13:AF18) -> 3024
B27: 11.15 - 11.30 | C27: 35 | D27: 2 | E27: 3 | F27: 26 | G27: 0 | H27: 1 | I27: 11 | J27: 1 | K27: 1 | L27: 0 | M27: 46 | N27: 0 | O27: =SUM(C27:L27,N27) -> 80 | P27: =SUM(C27:N27) -> 126 | R27: PM Period | S27: =SUM(S19:S21) -> 1016 | T27: =SUM(T19:T21) -> 183 | U27: =SUM(U19:U21) -> 69 | V27: =SUM(V19:V21) -> 212 | W27: =SUM(W19:W21) -> 13 | X27: =SUM(X19:X21) -> 3 | Y27: =SUM(Y19:Y21) -> 74 | Z27: =SUM(Z19:Z21) -> 12 | ... AF27: =SUM(AF19:AF21) -> 2315
B28: 11.30 - 11.45 | C28: 26 | D28: 6 | E28: 1 | F28: 29 | G28: 1 | H28: 0 | I28: 8 | J28: 1 | K28: 1 | L28: 0 | M28: 43 | N28: 0 | O28: =SUM(C28:L28,N28) -> 73 | P28: =SUM(C28:N28) -> 116 | R28: 12 Hours | S28: =SUM(S10:S21) -> 2053 | T28: =SUM(T10:T21) -> 370 | U28: =SUM(U10:U21) -> 153 | V28: =SUM(V10:V21) -> 886 | W28: =SUM(W10:W21) -> 44 | X28: =SUM(X10:X21) -> 11 | Y28: =SUM(Y10:Y21) -> 293 | Z28: =SUM(Z10:Z21) -> 30 | ... AF28: =SUM(AF10:AF21) -> 6084
B29: 11.45 - 12.00 | C29: 33 | D29: 4 | E29: 4 | F29: 27 | G29: 3 | H29: 2 | I29: 12 | J29: 0 | K29: 0 | L29: 0 | M29: 52 | N29: 0 | O29: =SUM(C29:L29,N29) -> 85 | P29: =SUM(C29:N29) -> 137
B30: 12.00 - 12.15 | C30: 29 | D30: 9 | E30: 0 | F30: 23 | G30: 2 | H30: 0 | I30: 7 | J30: 0 | K30: 0 | L30: 0 | M30: 44 | N30: 0 | O30: =SUM(C30:L30,N30) -> 70 | P30: =SUM(C30:N30) -> 114
B31: 12.15 - 12.30 | C31: 22 | D31: 6 | E31: 2 | F31: 29 | G31: 1 | H31: 1 | I31: 11 | J31: 2 | K31: 1 | L31: 0 | M31: 45 | N31: 0 | O31: =SUM(C31:L31,N31) -> 75 | P31: =SUM(C31:N31) -> 120
B32: 12.30 - 12.45 | C32: 33 | D32: 7 | E32: 0 | F32: 21 | G32: 0 | H32: 0 | I32: 4 | J32: 1 | K32: 0 | L32: 0 | M32: 12 | N32: 0 | O32: =SUM(C32:L32,N32) -> 66 | P32: =SUM(C32:N32) -> 78
B33: 12.45 - 13.00 | C33: 9 | D33: 3 | E33: 3 | F33: 25 | G33: 2 | H33: 1 | I33: 5 | J33: 0 | K33: 1 | L33: 0 | M33: 30 | N33: 0 | O33: =SUM(C33:L33,N33) -> 49 | P33: =SUM(C33:N33) -> 79
B34: 13.00 - 13.15 | C34: 30 | D34: 6 | E34: 1 | F34: 30 | G34: 5 | H34: 0 | I34: 1 | J34: 1 | K34: 0 | L34: 0 | M34: 35 | N34: 0 | O34: =SUM(C34:L34,N34) -> 74 | P34: =SUM(C34:N34) -> 109
B35: 13.15 - 13.30 | C35: 17 | D35: 9 | E35: 3 | F35: 10 | G35: 0 | H35: 1 | I35: 7 | J35: 0 | K35: 2 | L35: 0 | M35: 25 | N35: 0 | O35: =SUM(C35:L35,N35) -> 49 | P35: =SUM(C35:N35) -> 74
B36: 13.30 - 13.45 | C36: 20 | D36: 2 | E36: 3 | F36: 35 | G36: 3 | H36: 1 | I36: 0 | J36: 2 | K36: 0 | L36: 0 | M36: 39 | N36: 0 | O36: =SUM(C36:L36,N36) -> 66 | P36: =SUM(C36:N36) -> 105
B37: 13.45 - 14.00 | C37: 43 | D37: 11 | E37: 5 | F37: 25 | G37: 1 | H37: 0 | I37: 6 | J37: 1 | K37: 0 | L37: 0 | M37: 40 | N37: 0 | O37: =SUM(C37:L37,N37) -> 92 | P37: =SUM(C37:N37) -> 132
B38: 14.00 - 14.15 | C38: 43 | D38: 7 | E38: 2 | F38: 3 | G38: 0 | H38: 0 | I38: 11 | J38: 1 | K38: 0 | L38: 0 | M38: 60 | N38: 0 | O38: =SUM(C38:L38,N38) -> 67 | P38: =SUM(C38:N38) -> 127
B39: 14.15 - 14.30 | C39: 35 | D39: 8 | E39: 2 | F39: 20 | G39: 1 | H39: 1 | I39: 3 | J39: 0 | K39: 2 | L39: 0 | M39: 38 | N39: 0 | O39: =SUM(C39:L39,N39) -> 72 | P39: =SUM(C39:N39) -> 110
B40: 14.30 - 14.45 | C40: 43 | D40: 6 | E40: 4 | F40: 7 | G40: 2 | H40: 0 | I40: 9 | J40: 4 | K40: 0 | L40: 0 | M40: 57 | N40: 0 | O40: =SUM(C40:L40,N40) -> 75 | P40: =SUM(C40:N40) -> 132
... B57: 18.45 - 19.00 | C57: 90 | D57: 9 | E57: 8 | F57: 14 | G57: 0 | H57: 1 | I57: 0 | J57: 0 | K57: 0 | L57: 0 | M57: 70 | N57: 0 | O57: =SUM(C57:L57,N57) -> 122 | P57: =SUM(C57:N57) -> 192
B58: Totals | C58: =SUM(C10:C57) -> 2053 | D58: =SUM(D10:D57) -> 370 | E58: =SUM(E10:E57) -> 153 | F58: =SUM(F10:F57) -> 886 | G58: =SUM(G10:G57) -> 44 | H58: =SUM(H10:H57) -> 11 | I58: =SUM(I10:I57) -> 293 | J58: =SUM(J10:J57) -> 30 | ... P58: =SUM(P10:P57) -> 6084
...

Sheet 30.07 Najjeera-Kiwatule
B1: Consultancy services for Preparation of Expressway Development Master Plan (EDMP) for Uganda
B2: MANUAL CLASSIFIED COUNT (MCC)
B3: ROAD NAME: | C3: ='29.07 Najjeera-Kiwatule'!C3:G3 -> MCC - C1 - STN36 - MBOGO ROAD
C5: Date | D5: 30.07.19 | F5: Location | G5: ='29.07 Najjeera-Kiwatule'!G5:H5 -> U Save Kiwatule | J5: Surveyor | K5: Anthony
C6: Dir. From | D6: ='29.07 Najjeera-Kiwatule'!D6:E6 -> Najjeera | F6: Dir. To | G6: ='29.07 Najjeera-Kiwatule'!G6:H6 -> Kiwatule | J6: Supervisor | K6: ='29.07 Najjeera-Kiwatule'!K6:L6 -> Steven
B8: Time / Veh Type | R8: SUMMARY TRAFFIC VOLUMES
C9: 1. Car | D9: 2. Station Wagon | E9: 3. Pickups | F9: 4. Minibus, matatu | G9: 5. Medium bus | H9: 6. Large Bus | I9: 7. Light Truck | J9: 8. Medium Truck | K9: 9. Heavy truck | L9: 10. Truck Trailer | M9: 11. Motor cycles | N9: 12. Tractors | O9: Total Excl M/Cycles | P9: Total All | R9: Time | S9: 1. Car | T9: 2. Station Wagon | U9: 3. Pickups | V9: 4. Minibus, matatu | W9: 5. Medium bus | X9: 6. Large Bus | Y9: 7. Light Truck | Z9: 8. Medium Truck | AA9: 9. Heavy truck | AB9: 10. Truck Trailer | AC9: 11. Motorcycles | AD9: 12. Tractors, Graders | AE9: Total Excl M/ Cycles | AF9: Total All
B10: 07.00 - 07.15 | C10: 165 | D10: 25 | E10: 7 | F10: 12 | G10: 1 | H10: 0 | I10: 2 | J10: 0 | K10: 0 | L10: 0 | M10: 90 | N10: 0 | O10: =SUM(C10:L10,N10) -> 212 | P10: =SUM(C10:N10) -> 302 | R10: 0700-0800 | S10: =SUM(C10:C13) -> 586 | T10: =SUM(D10:D13) -> 59 | U10: =SUM(E10:E13) -> 28 | V10: =SUM(F10:F13) -> 71 | W10: =SUM(G10:G13) -> 2 | X10: =SUM(H10:H13) -> 0 | Y10: =SUM(I10:I13) -> 8 | Z10: =SUM(J10:J13) -> 0 | ... AF10: =SUM(P10:P13) -> 1210
B11: 07.15 - 07.30 | C11: 126 | D11: 9 | E11: 10 | F11: 20 | G11: 0 | H11: 0 | I11: 3 | J11: 0 | K11: 0 | L11: 0 | M11: 110 | N11: 0 | O11: =SUM(C11:L11,N11) -> 168 | P11: =SUM(C11:N11) -> 278 | R11: 0800-0900 | S11: =SUM(C14:C17) -> 578 | T11: =SUM(D14:D17) -> 82 | U11: =SUM(E14:E17) -> 26 | V11: =SUM(F14:F17) -> 90 | W11: =SUM(G14:G17) -> 2 | X11: =SUM(H14:H17) -> 0 | Y11: =SUM(I14:I17) -> 11 | Z11: =SUM(J14:J17) -> 4 | ... AF11: =SUM(P14:P17) -> 1288
B12: 07.30 - 07.45 | C12: 155 | D12: 16 | E12: 4 | F12: 15 | G12: 0 | H12: 0 | I12: 2 | J12: 0 | K12: 1 | L12: 0 | M12: 115 | N12: 0 | O12: =SUM(C12:L12,N12) -> 193 | P12: =SUM(C12:N12) -> 308 | R12: 0900-1000 | S12: =SUM(C18:C21) -> 318 | T12: =SUM(D18:D21) -> 51 | U12: =SUM(E18:E21) -> 30 | V12: =SUM(F18:F21) -> 52 | W12: =SUM(G18:G21) -> 0 | X12: =SUM(H18:H21) -> 0 | Y12: =SUM(I18:I21) -> 15 | Z12: =SUM(J18:J21) -> 2 | ... AF12: =SUM(P18:P21) -> 905
B13: 07.45 - 08.00 | C13: 140 | D13: 9 | E13: 7 | F13: 24 | G13: 1 | H13: 0 | I13: 1 | J13: 0 | K13: 0 | L13: 0 | M13: 140 | N13: 0 | O13: =SUM(C13:L13,N13) -> 182 | P13: =SUM(C13:N13) -> 322 | R13: 1000-1100 | S13: =SUM(C22:C25) -> 294 | T13: =SUM(D22:D25) -> 45 | U13: =SUM(E22:E25) -> 24 | V13: =SUM(F22:F25) -> 49 | W13: =SUM(G22:G25) -> 0 | X13: =SUM(H22:H25) -> 0 | Y13: =SUM(I22:I25) -> 15 | Z13: =SUM(J22:J25) -> 4 | ... AF13: =SUM(P22:P25) -> 842
B14: 08.00 - 08.15 | C14: 153 | D14: 15 | E14: 5 | F14: 17 | G14: 0 | H14: 0 | I14: 1 | J14: 0 | K14: 0 | L14: 0 | M14: 145 | N14: 0 | O14: =SUM(C14:L14,N14) -> 191 | P14: =SUM(C14:N14) -> 336 | R14: 1100-1200 | S14: =SUM(C26:C29) -> 318 | T14: =SUM(D26:D29) -> 49 | U14: =SUM(E26:E29) -> 33 | V14: =SUM(F26:F29) -> 48 | W14: =SUM(G26:G29) -> 0 | X14: =SUM(H26:H29) -> 0 | Y14: =SUM(I26:I29) -> 17 | Z14: =SUM(J26:J29) -> 3 | ... AF14: =SUM(P26:P29) -> 905
B15: 08.15 - 08.30 | C15: 145 | D15: 19 | E15: 4 | F15: 17 | G15: 0 | H15: 0 | I15: 5 | J15: 0 | K15: 0 | L15: 0 | M15: 135 | N15: 0 | O15: =SUM(C15:L15,N15) -> 190 | P15: =SUM(C15:N15) -> 325 | R15: 1200-1300 | S15: =SUM(C30:C33) -> 296 | T15: =SUM(D30:D33) -> 30 | U15: =SUM(E30:E33) -> 23 | V15: =SUM(F30:F33) -> 59 | W15: =SUM(G30:G33) -> 0 | X15: =SUM(H30:H33) -> 0 | Y15: =SUM(I30:I33) -> 15 | Z15: =SUM(J30:J33) -> 6 | ... AF15: =SUM(P30:P33) -> 783
B16: 08.30 - 08.45 | C16: 155 | D16: 20 | E16: 9 | F16: 27 | G16: 0 | H16: 0 | I16: 1 | J16: 3 | K16: 0 | L16: 0 | M16: 110 | N16: 0 | O16: =SUM(C16:L16,N16) -> 215 | P16: =SUM(C16:N16) -> 325 | R16: 1300-1400 | S16: =SUM(C34:C37) -> 232 | T16: =SUM(D34:D37) -> 35 | U16: =SUM(E34:E37) -> 26 | V16: =SUM(F34:F37) -> 54 | W16: =SUM(G34:G37) -> 0 | X16: =SUM(H34:H37) -> 0 | Y16: =SUM(I34:I37) -> 16 | Z16: =SUM(J34:J37) -> 3 | ... AF16: =SUM(P34:P37) -> 820
B17: 08.45 - 9.00 | C17: 125 | D17: 28 | E17: 8 | F17: 29 | G17: 2 | H17: 0 | I17: 4 | J17: 1 | K17: 0 | L17: 0 | M17: 105 | N17: 0 | O17: =SUM(C17:L17,N17) -> 197 | P17: =SUM(C17:N17) -> 302 | R17: 1400-1500 | S17: =SUM(C38:C41) -> 173 | T17: =SUM(D38:D41) -> 31 | U17: =SUM(E38:E41) -> 11 | V17: =SUM(F38:F41) -> 46 | W17: =SUM(G38:G41) -> 1 | X17: =SUM(H38:H41) -> 0 | Y17: =SUM(I38:I41) -> 10 | Z17: =SUM(J38:J41) -> 2 | ... AF17: =SUM(P38:P41) -> 586
B18: 09.00 - 09.15 | C18: 50 | D18: 8 | E18: 7 | F18: 8 | G18: 0 | H18: 0 | I18: 3 | J18: 0 | K18: 0 | L18: 0 | M18: 105 | N18: 0 | O18: =SUM(C18:L18,N18) -> 76 | P18: =SUM(C18:N18) -> 181 | R18: 1500-1600 | S18: =SUM(C42:C45) -> 221 | T18: =SUM(D42:D45) -> 32 | U18: =SUM(E42:E45) -> 22 | V18: =SUM(F42:F45) -> 50 | W18: =SUM(G42:G45) -> 1 | X18: =SUM(H42:H45) -> 0 | Y18: =SUM(I42:I45) -> 23 | Z18: =SUM(J42:J45) -> 8 | ... AF18: =SUM(P42:P45) -> 647
B19: 09.15 - 09.30 | C19: 108 | D19: 16 | E19: 7 | F19: 13 | G19: 0 | H19: 0 | I19: 5 | J19: 2 | K19: 1 | L19: 0 | M19: 100 | N19: 0 | O19: =SUM(C19:L19,N19) -> 152 | P19: =SUM(C19:N19) -> 252 | R19: 1600-1700 | S19: =SUM(C46:C49) -> 245 | T19: =SUM(D46:D49) -> 41 | U19: =SUM(E46:E49) -> 17 | V19: =SUM(F46:F49) -> 55 | W19: =SUM(G46:G49) -> 1 | X19: =SUM(H46:H49) -> 0 | Y19: =SUM(I46:I49) -> 23 | Z19: =SUM(J46:J49) -> 14 | ... AF19: =SUM(P46:P49) -> 693
B20: 09.30 - 09.45 | C20: 90 | D20: 6 | E20: 8 | F20: 17 | G20: 0 | H20: 0 | I20: 2 | J20: 0 | K20: 0 | L20: 0 | M20: 140 | N20: 0 | O20: =SUM(C20:L20,N20) -> 123 | P20: =SUM(C20:N20) -> 263 | R20: 1700-1800 | S20: =SUM(C50:C53) -> 229 | T20: =SUM(D50:D53) -> 33 | U20: =SUM(E50:E53) -> 13 | V20: =SUM(F50:F53) -> 52 | W20: =SUM(G50:G53) -> 3 | X20: =SUM(H50:H53) -> 0 | Y20: =SUM(I50:I53) -> 21 | Z20: =SUM(J50:J53) -> 3 | ... AF20: =SUM(P50:P53) -> 760
B21: 09.45 - 10.00 | C21: 70 | D21: 21 | E21: 8 | F21: 14 | G21: 0 | H21: 0 | I21: 5 | J21: 0 | K21: 1 | L21: 0 | M21: 90 | N21: 0 | O21: =SUM(C21:L21,N21) -> 119 | P21: =SUM(C21:N21) -> 209 | R21: 1800-1900 | S21: =SUM(C54:C57) -> 208 | T21: =SUM(D54:D57) -> 27 | U21: =SUM(E54:E57) -> 9 | V21: =SUM(F54:F57) -> 42 | W21: =SUM(G54:G57) -> 2 | X21: =SUM(H54:H57) -> 0 | Y21: =SUM(I54:I57) -> 11 | Z21: =SUM(J54:J57) -> 4 | ... AF21: =SUM(P54:P57) -> 778
B22: 10.00 - 10.15 | C22: 68 | D22: 6 | E22: 5 | F22: 12 | G22: 0 | H22: 0 | I22: 4 | J22: 2 | K22: 1 | L22: 0 | M22: 90 | N22: 0 | O22: =SUM(C22:L22,N22) -> 98 | P22: =SUM(C22:N22) -> 188 | R22: AM Peak Hr | S22: =MAX(S10:S12) -> 586 | T22: =MAX(T10:T12) -> 82 | U22: =MAX(U10:U12) -> 30 | V22: =MAX(V10:V12) -> 90 | W22: =MAX(W10:W12) -> 2 | X22: =MAX(X10:X12) -> 0 | Y22: =MAX(Y10:Y12) -> 15 | Z22: =MAX(Z10:Z12) -> 4 | ... AF22: =MAX(AF10:AF12) -> 1288
B23: 10.15 - 10.30 | C23: 75 | D23: 14 | E23: 8 | F23: 8 | G23: 0 | H23: 0 | I23: 3 | J23: 0 | K23: 0 | L23: 0 | M23: 110 | N23: 0 | O23: =SUM(C23:L23,N23) -> 108 | P23: =SUM(C23:N23) -> 218 | R23: IP Peak Hr | S23: =MAX(S13:S18) -> 318 | T23: =MAX(T13:T18) -> 49 | U23: =MAX(U13:U18) -> 33 | V23: =MAX(V13:V18) -> 59 | W23: =MAX(W13:W18) -> 1 | X23: =MAX(X13:X18) -> 0 | Y23: =MAX(Y13:Y18) -> 23 | Z23: =MAX(Z13:Z18) -> 8 | ... AF23: =MAX(AF13:AF18) -> 905
B24: 10.30 - 10.45 | C24: 86 | D24: 16 | E24: 8 | F24: 15 | G24: 0 | H24: 0 | I24: 2 | J24: 0 | K24: 0 | L24: 0 | M24: 100 | N24: 0 | O24: =SUM(C24:L24,N24) -> 127 | P24: =SUM(C24:N24) -> 227 | R24: PM Peak Hr | S24: =MAX(S19:S21) -> 245 | T24: =MAX(T19:T21) -> 41 | U24: =MAX(U19:U21) -> 17 | V24: =MAX(V19:V21) -> 55 | W24: =MAX(W19:W21) -> 3 | X24: =MAX(X19:X21) -> 0 | Y24: =MAX(Y19:Y21) -> 23 | Z24: =MAX(Z19:Z21) -> 14 | ... AF24: =MAX(AF19:AF21) -> 778
B25: 10.45 - 11.00 | C25: 65 | D25: 9 | E25: 3 | F25: 14 | G25: 0 | H25: 0 | I25: 6 | J25: 2 | K25: 0 | L25: 0 | M25: 110 | N25: 0 | O25: =SUM(C25:L25,N25) -> 99 | P25: =SUM(C25:N25) -> 209 | R25: AM Period | S25: =SUM(S10:S12) -> 1482 | T25: =SUM(T10:T12) -> 192 | U25: =SUM(U10:U12) -> 84 | V25: =SUM(V10:V12) -> 213 | W25: =SUM(W10:W12) -> 4 | X25: =SUM(X10:X12) -> 0 | Y25: =SUM(Y10:Y12) -> 34 | Z25: =SUM(Z10:Z12) -> 6 | ... AF25: =SUM(AF10:AF12) -> 3403
B26: 11.00 - 11.15 | C26: 66 | D26: 16 | E26: 7 | F26: 13 | G26: 0 | H26: 0 | I26: 5 | J26: 2 | K26: 0 | L26: 1 | M26: 118 | N26: 0 | O26: =SUM(C26:L26,N26) -> 110 | P26: =SUM(C26:N26) -> 228 | R26: IP Period | S26: =SUM(S13:S18) -> 1534 | T26: =SUM(T13:T18) -> 222 | U26: =SUM(U13:U18) -> 139 | V26: =SUM(V13:V18) -> 306 | W26: =SUM(W13:W18) -> 2 | X26: =SUM(X13:X18) -> 0 | Y26: =SUM(Y13:Y18) -> 96 | Z26: =SUM(Z13:Z18) -> 26 | ... AF26: =SUM(AF13:AF18) -> 4583
B27: 11.15 - 11.30 | C27: 93 | D27: 4 | E27: 9 | F27: 8 | G27: 0 | H27: 0 | I27: 2 | J27: 0 | K27: 0 | L27: 0 | M27: 85 | N27: 0 | O27: =SUM(C27:L27,N27) -> 116 | P27: =SUM(C27:N27) -> 201 | R27: PM Period | S27: =SUM(S19:S21) -> 682 | T27: =SUM(T19:T21) -> 101 | U27: =SUM(U19:U21) -> 39 | V27: =SUM(V19:V21) -> 149 | W27: =SUM(W19:W21) -> 6 | X27: =SUM(X19:X21) -> 0 | Y27: =SUM(Y19:Y21) -> 55 | Z27: =SUM(Z19:Z21) -> 21 | ... AF27: =SUM(AF19:AF21) -> 2231
B28: 11.30 - 11.45 | C28: 83 | D28: 15 | E28: 9 | F28: 17 | G28: 0 | H28: 0 | I28: 5 | J28: 1 | K28: 2 | L28: 0 | M28: 140 | N28: 0 | O28: =SUM(C28:L28,N28) -> 132 | P28: =SUM(C28:N28) -> 272 | R28: 12 Hours | S28: =SUM(S10:S21) -> 3698 | T28: =SUM(T10:T21) -> 515 | U28: =SUM(U10:U21) -> 262 | V28: =SUM(V10:V21) -> 668 | W28: =SUM(W10:W21) -> 12 | X28: =SUM(X10:X21) -> 0 | Y28: =SUM(Y10:Y21) -> 185 | Z28: =SUM(Z10:Z21) -> 53 | ... AF28: =SUM(AF10:AF21) -> 10217
B29: 11.45 - 12.00 | C29: 76 | D29: 14 | E29: 8 | F29: 10 | G29: 0 | H29: 0 | I29: 5 | J29: 0 | K29: 1 | L29: 0 | M29: 90 | N29: 0 | O29: =SUM(C29:L29,N29) -> 114 | P29: =SUM(C29:N29) -> 204
B30: 12.00 - 12.15 | C30: 69 | D30: 7 | E30: 6 | F30: 10 | G30: 0 | H30: 0 | I30: 3 | J30: 2 | K30: 2 | L30: 0 | M30: 110 | N30: 0 | O30: =SUM(C30:L30,N30) -> 99 | P30: =SUM(C30:N30) -> 209
B31: 12.15 - 12.30 | C31: 87 | D31: 8 | E31: 7 | F31: 21 | G31: 0 | H31: 0 | I31: 4 | J31: 1 | K31: 1 | L31: 0 | M31: 85 | N31: 0 | O31: =SUM(C31:L31,N31) -> 129 | P31: =SUM(C31:N31) -> 214
B32: 12.30 - 12.45 | C32: 105 | D32: 12 | E32: 7 | F32: 15 | G32: 0 | H32: 0 | I32: 5 | J32: 1 | K32: 1 | L32: 0 | M32: 85 | N32: 0 | O32: =SUM(C32:L32,N32) -> 146 | P32: =SUM(C32:N32) -> 231
B33: 12.45 - 13.00 | C33: 35 | D33: 3 | E33: 3 | F33: 13 | G33: 0 | H33: 0 | I33: 3 | J33: 2 | K33: 0 | L33: 0 | M33: 70 | N33: 0 | O33: =SUM(C33:L33,N33) -> 59 | P33: =SUM(C33:N33) -> 129
B34: 13.00 - 13.15 | C34: 57 | D34: 11 | E34: 10 | F34: 20 | G34: 0 | H34: 0 | I34: 4 | J34: 1 | K34: 1 | L34: 0 | M34: 125 | N34: 0 | O34: =SUM(C34:L34,N34) -> 104 | P34: =SUM(C34:N34) -> 229
B35: 13.15 - 13.30 | C35: 60 | D35: 5 | E35: 3 | F35: 12 | G35: 0 | H35: 0 | I35: 3 | J35: 1 | K35: 1 | L35: 0 | M35: 130 | N35: 0 | O35: =SUM(C35:L35,N35) -> 85 | P35: =SUM(C35:N35) -> 215
B36: 13.30 - 13.45 | C36: 55 | D36: 9 | E36: 5 | F36: 13 | G36: 0 | H36: 0 | I36: 4 | J36: 1 | K36: 0 | L36: 0 | M36: 125 | N36: 0 | O36: =SUM(C36:L36,N36) -> 87 | P36: =SUM(C36:N36) -> 212
B37: 13.45 - 14.00 | C37: 60 | D37: 10 | E37: 8 | F37: 9 | G37: 0 | H37: 0 | I37: 5 | J37: 0 | K37: 0 | L37: 0 | M37: 72 | N37: 0 | O37: =SUM(C37:L37,N37) -> 92 | P37: =SUM(C37:N37) -> 164
B38: 14.00 - 14.15 | C38: 40 | D38: 9 | E38: 3 | F38: 9 | G38: 0 | H38: 0 | I38: 2 | J38: 0 | K38: 0 | L38: 1 | M38: 85 | N38: 0 | O38: =SUM(C38:L38,N38) -> 64 | P38: =SUM(C38:N38) -> 149
B39: 14.15 - 14.30 | C39: 53 | D39: 12 | E39: 2 | F39: 17 | G39: 0 | H39: 0 | I39: 1 | J39: 0 | K39: 0 | L39: 0 | M39: 75 | N39: 0 | O39: =SUM(C39:L39,N39) -> 85 | P39: =SUM(C39:N39) -> 160
B40: 14.30 - 14.45 | C40: 40 | D40: 6 | E40: 4 | F40: 11 | G40: 0 | H40: 0 | I40: 3 | J40: 2 | K40: 0 | L40: 0 | M40: 70 | N40: 0 | O40: =SUM(C40:L40,N40) -> 66 | P40: =SUM(C40:N40) -> 136
... B57: 18.45 - 19.00 | C57: 42 | D57: 7 | E57: 2 | F57: 15 | G57: 0 | H57: 0 | I57: 1 | J57: 0 | K57: 0 | L57: 0 | M57: 135 | N57: 0 | O57: =SUM(C57:L57,N57) -> 67 | P57: =SUM(C57:N57) -> 202
B58: Totals | C58: =SUM(C10:C57) -> 3698 | D58: =SUM(D10:D57) -> 515 | E58: =SUM(E10:E57) -> 262 | F58: =SUM(F10:F57) -> 668 | G58: =SUM(G10:G57) -> 12 | H58: =SUM(H10:H57) -> 0 | I58: =SUM(I10:I57) -> 185 | J58: =SUM(J10:J57) -> 53 | ... P58: =SUM(P10:P57) -> 10217
...

Sheet 30.07 Kiwatule-Najjeera
B1: Consultancy services for Preparation of Expressway Development Master Plan (EDMP) for Uganda
B2: MANUAL CLASSIFIED COUNT (MCC)
B3: ROAD NAME: | C3: ='29.07 Kiwatule-Najjeera'!C3:G3 -> MCC - C1 - STN36 - MBOGO ROAD
C5: Date | D5: ='30.07 Najjeera-Kiwatule'!D5 -> 30.07.19 | F5: Location | G5: ='29.07 Najjeera-Kiwatule'!G5:H5 -> U Save Kiwatule | J5: Surveyor | K5: Beteth
C6: Dir. From | D6: ='29.07 Kiwatule-Najjeera'!D6:E6 -> Kiwatule | F6: Dir. To | G6: ='29.07 Kiwatule-Najjeera'!G6:H6 -> Najjeera | J6: Supervisor | K6: ='29.07 Najjeera-Kiwatule'!K6:L6 -> Steven
B8: Time / Veh Type | R8: SUMMARY TRAFFIC VOLUMES
C9: 1. Car | D9: 2. Station Wagon | E9: 3. Pickups | F9: 4. Minibus, matatu | G9: 5. Medium bus | H9: 6. Large Bus | I9: 7. Light Truck | J9: 8. Medium Truck | K9: 9. Heavy truck | L9: 10. Truck Trailer | M9: 11. Motor cycles | N9: 12. Tractors | O9: Total Excl M/Cycles | P9: Total All | R9: Time | S9: 1. Car | T9: 2. Station Wagon | U9: 3. Pickups | V9: 4. Minibus, matatu | W9: 5. Medium bus | X9: 6. Large Bus | Y9: 7. Light Truck | Z9: 8. Medium Truck | AA9: 9. Heavy truck | AB9: 10. Truck Trailer | AC9: 11. Motorcycles | AD9: 12. Tractors, Graders | AE9: Total Excl M/ Cycles | AF9: Total All
B10: 07.00 - 07.15 | C10: 12 | D10: 5 | E10: 2 | F10: 11 | G10: 1 | H10: 0 | I10: 3 | J10: 0 | K10: 0 | L10: 0 | M10: 35 | N10: 0 | O10: =SUM(C10:L10,N10) -> 34 | P10: =SUM(C10:N10) -> 69 | R10: 0700-0800 | S10: =SUM(C10:C13) -> 130 | T10: =SUM(D10:D13) -> 29 | U10: =SUM(E10:E13) -> 10 | V10: =SUM(F10:F13) -> 68 | W10: =SUM(G10:G13) -> 5 | X10: =SUM(H10:H13) -> 0 | Y10: =SUM(I10:I13) -> 24 | Z10: =SUM(J10:J13) -> 0 | ... AF10: =SUM(P10:P13) -> 416
B11: 07.15 - 07.30 | C11: 42 | D11: 9 | E11: 4 | F11: 14 | G11: 2 | H11: 0 | I11: 11 | J11: 0 | K11: 0 | L11: 0 | M11: 38 | N11: 0 | O11: =SUM(C11:L11,N11) -> 82 | P11: =SUM(C11:N11) -> 120 | R11: 0800-0900 | S11: =SUM(C14:C17) -> 81 | T11: =SUM(D14:D17) -> 21 | U11: =SUM(E14:E17) -> 8 | V11: =SUM(F14:F17) -> 67 | W11: =SUM(G14:G17) -> 3 | X11: =SUM(H14:H17) -> 0 | Y11: =SUM(I14:I17) -> 29 | Z11: =SUM(J14:J17) -> 1 | ... AF11: =SUM(P14:P17) -> 436
B12: 07.30 - 07.45 | C12: 39 | D12: 7 | E12: 2 | F12: 18 | G12: 0 | H12: 0 | I12: 8 | J12: 0 | K12: 0 | L12: 0 | M12: 33 | N12: 0 | O12: =SUM(C12:L12,N12) -> 74 | P12: =SUM(C12:N12) -> 107 | R12: 0900-1000 | S12: =SUM(C18:C21) -> 81 | T12: =SUM(D18:D21) -> 21 | U12: =SUM(E18:E21) -> 8 | V12: =SUM(F18:F21) -> 41 | W12: =SUM(G18:G21) -> 3 | X12: =SUM(H18:H21) -> 0 | Y12: =SUM(I18:I21) -> 29 | Z12: =SUM(J18:J21) -> 1 | ... AF12: =SUM(P18:P21) -> 410
B13: 07.45 - 08.00 | C13: 37 | D13: 8 | E13: 2 | F13: 25 | G13: 2 | H13: 0 | I13: 2 | J13: 0 | K13: 0 | L13: 0 | M13: 44 | N13: 0 | O13: =SUM(C13:L13,N13) -> 76 | P13: =SUM(C13:N13) -> 120 | R13: 1000-1100 | S13: =SUM(C22:C25) -> 70 | T13: =SUM(D22:D25) -> 17 | U13: =SUM(E22:E25) -> 7 | V13: =SUM(F22:F25) -> 45 | W13: =SUM(G22:G25) -> 3 | X13: =SUM(H22:H25) -> 0 | Y13: =SUM(I22:I25) -> 15 | Z13: =SUM(J22:J25) -> 2 | ... AF13: =SUM(P22:P25) -> 260
B14: 08.00 - 08.15 | C14: 36 | D14: 11 | E14: 3 | F14: 31 | G14: 1 | H14: 0 | I14: 12 | J14: 0 | K14: 0 | L14: 0 | M14: 50 | N14: 0 | O14: =SUM(C14:L14,N14) -> 94 | P14: =SUM(C14:N14) -> 144 | R14: 1100-1200 | S14: =SUM(C26:C29) -> 104 | T14: =SUM(D26:D29) -> 30 | U14: =SUM(E26:E29) -> 10 | V14: =SUM(F26:F29) -> 74 | W14: =SUM(G26:G29) -> 1 | X14: =SUM(H26:H29) -> 0 | Y14: =SUM(I26:I29) -> 15 | Z14: =SUM(J26:J29) -> 2 | ... AF14: =SUM(P26:P29) -> 379
B15: 08.15 - 08.30 | C15: 17 | D15: 2 | E15: 0 | F15: 12 | G15: 0 | H15: 0 | I15: 2 | J15: 0 | K15: 0 | L15: 0 | M15: 51 | N15: 0 | O15: =SUM(C15:L15,N15) -> 33 | P15: =SUM(C15:N15) -> 84 | R15: 1200-1300 | S15: =SUM(C30:C33) -> 133 | T15: =SUM(D30:D33) -> 25 | U15: =SUM(E30:E33) -> 10 | V15: =SUM(F30:F33) -> 68 | W15: =SUM(G30:G33) -> 0 | X15: =SUM(H30:H33) -> 0 | Y15: =SUM(I30:I33) -> 18 | Z15: =SUM(J30:J33) -> 3 | ... AF15: =SUM(P30:P33) -> 401
B16: 08.30 - 08.45 | C16: 20 | D16: 5 | E16: 4 | F16: 14 | G16: 2 | H16: 0 | I16: 5 | J16: 1 | K16: 0 | L16: 0 | M16: 55 | N16: 0 | O16: =SUM(C16:L16,N16) -> 51 | P16: =SUM(C16:N16) -> 106 | R16: 1300-1400 | S16: =SUM(C34:C37) -> 193 | T16: =SUM(D34:D37) -> 23 | U16: =SUM(E34:E37) -> 11 | V16: =SUM(F34:F37) -> 63 | W16: =SUM(G34:G37) -> 0 | X16: =SUM(H34:H37) -> 0 | Y16: =SUM(I34:I37) -> 19 | Z16: =SUM(J34:J37) -> 0 | ... AF16: =SUM(P34:P37) -> 442
B17: 08.45 - 9.00 | C17: 8 | D17: 3 | E17: 1 | F17: 10 | G17: 0 | H17: 0 | I17: 10 | J17: 0 | K17: 0 | L17: 0 | M17: 70 | N17: 0 | O17: =SUM(C17:L17,N17) -> 32 | P17: =SUM(C17:N17) -> 102 | R17: 1400-1500 | S17: =SUM(C38:C41) -> 101 | T17: =SUM(D38:D41) -> 26 | U17: =SUM(E38:E41) -> 4 | V17: =SUM(F38:F41) -> 43 | W17: =SUM(G38:G41) -> 1 | X17: =SUM(H38:H41) -> 0 | Y17: =SUM(I38:I41) -> 21 | Z17: =SUM(J38:J41) -> 3 | ... AF17: =SUM(P38:P41) -> 281
B18: 09.00 - 09.15 | C18: 36 | D18: 11 | E18: 3 | F18: 3 | G18: 1 | H18: 0 | I18: 12 | J18: 0 | K18: 0 | L18: 0 | M18: 50 | N18: 0 | O18: =SUM(C18:L18,N18) -> 66 | P18: =SUM(C18:N18) -> 116 | R18: 1500-1600 | S18: =SUM(C42:C45) -> 292 | T18: =SUM(D42:D45) -> 31 | U18: =SUM(E42:E45) -> 18 | V18: =SUM(F42:F45) -> 49 | W18: =SUM(G42:G45) -> 2 | X18: =SUM(H42:H45) -> 0 | Y18: =SUM(I42:I45) -> 20 | Z18: =SUM(J42:J45) -> 6 | ... AF18: =SUM(P42:P45) -> 552
B19: 09.15 - 09.30 | C19: 17 | D19: 2 | E19: 0 | F19: 12 | G19: 0 | H19: 0 | I19: 2 | J19: 0 | K19: 0 | L19: 0 | M19: 51 | N19: 0 | O19: =SUM(C19:L19,N19) -> 33 | P19: =SUM(C19:N19) -> 84 | R19: 1600-1700 | S19: =SUM(C46:C49) -> 458 | T19: =SUM(D46:D49) -> 63 | U19: =SUM(E46:E49) -> 11 | V19: =SUM(F46:F49) -> 42 | W19: =SUM(G46:G49) -> 0 | X19: =SUM(H46:H49) -> 0 | Y19: =SUM(I46:I49) -> 8 | Z19: =SUM(J46:J49) -> 2 | ... AF19: =SUM(P46:P49) -> 778
B20: 09.30 - 09.45 | C20: 20 | D20: 5 | E20: 4 | F20: 14 | G20: 2 | H20: 0 | I20: 5 | J20: 1 | K20: 0 | L20: 0 | M20: 55 | N20: 0 | O20: =SUM(C20:L20,N20) -> 51 | P20: =SUM(C20:N20) -> 106 | R20: 1700-1800 | S20: =SUM(C50:C53) -> 490 | T20: =SUM(D50:D53) -> 64 | U20: =SUM(E50:E53) -> 44 | V20: =SUM(F50:F53) -> 48 | W20: =SUM(G50:G53) -> 1 | X20: =SUM(H50:H53) -> 1 | Y20: =SUM(I50:I53) -> 19 | Z20: =SUM(J50:J53) -> 1 | ... AF20: =SUM(P50:P53) -> 952
B21: 09.45 - 10.00 | C21: 8 | D21: 3 | E21: 1 | F21: 12 | G21: 0 | H21: 0 | I21: 10 | J21: 0 | K21: 0 | L21: 0 | M21: 70 | N21: 0 | O21: =SUM(C21:L21,N21) -> 34 | P21: =SUM(C21:N21) -> 104 | R21: 1800-1900 | S21: =SUM(C54:C57) -> 575 | T21: =SUM(D54:D57) -> 98 | U21: =SUM(E54:E57) -> 32 | V21: =SUM(F54:F57) -> 75 | W21: =SUM(G54:G57) -> 4 | X21: =SUM(H54:H57) -> 0 | Y21: =SUM(I54:I57) -> 14 | Z21: =SUM(J54:J57) -> 0 | ... AF21: =SUM(P54:P57) -> 1122
B22: 10.00 - 10.15 | C22: 23 | D22: 4 | E22: 2 | F22: 13 | G22: 0 | H22: 0 | I22: 2 | J22: 1 | K22: 0 | L22: 0 | M22: 30 | N22: 0 | O22: =SUM(C22:L22,N22) -> 45 | P22: =SUM(C22:N22) -> 75 | R22: AM Peak Hr | S22: =MAX(S10:S12) -> 130 | T22: =MAX(T10:T12) -> 29 | U22: =MAX(U10:U12) -> 10 | V22: =MAX(V10:V12) -> 68 | W22: =MAX(W10:W12) -> 5 | X22: =MAX(X10:X12) -> 0 | Y22: =MAX(Y10:Y12) -> 29 | Z22: =MAX(Z10:Z12) -> 1 | ... AF22: =MAX(AF10:AF12) -> 436
B23: 10.15 - 10.30 | C23: 15 | D23: 3 | E23: 1 | F23: 6 | G23: 1 | H23: 0 | I23: 6 | J23: 0 | K23: 0 | L23: 0 | M23: 20 | N23: 0 | O23: =SUM(C23:L23,N23) -> 32 | P23: =SUM(C23:N23) -> 52 | R23: IP Peak Hr | S23: =MAX(S13:S18) -> 292 | T23: =MAX(T13:T18) -> 31 | U23: =MAX(U13:U18) -> 18 | V23: =MAX(V13:V18) -> 74 | W23: =MAX(W13:W18) -> 3 | X23: =MAX(X13:X18) -> 0 | Y23: =MAX(Y13:Y18) -> 21 | Z23: =MAX(Z13:Z18) -> 6 | ... AF23: =MAX(AF13:AF18) -> 552
B24: 10.30 - 10.45 | C24: 17 | D24: 4 | E24: 0 | F24: 15 | G24: 0 | H24: 0 | I24: 4 | J24: 1 | K24: 0 | L24: 0 | M24: 33 | N24: 0 | O24: =SUM(C24:L24,N24) -> 41 | P24: =SUM(C24:N24) -> 74 | R24: PM Peak Hr | S24: =MAX(S19:S21) -> 575 | T24: =MAX(T19:T21) -> 98 | U24: =MAX(U19:U21) -> 44 | V24: =MAX(V19:V21) -> 75 | W24: =MAX(W19:W21) -> 4 | X24: =MAX(X19:X21) -> 1 | Y24: =MAX(Y19:Y21) -> 19 | Z24: =MAX(Z19:Z21) -> 2 | ... AF24: =MAX(AF19:AF21) -> 1122
B25: 10.45 - 11.00 | C25: 15 | D25: 6 | E25: 4 | F25: 11 | G25: 2 | H25: 0 | I25: 3 | J25: 0 | K25: 0 | L25: 0 | M25: 18 | N25: 0 | O25: =SUM(C25:L25,N25) -> 41 | P25: =SUM(C25:N25) -> 59 | R25: AM Period | S25: =SUM(S10:S12) -> 292 | T25: =SUM(T10:T12) -> 71 | U25: =SUM(U10:U12) -> 26 | V25: =SUM(V10:V12) -> 176 | W25: =SUM(W10:W12) -> 11 | X25: =SUM(X10:X12) -> 0 | Y25: =SUM(Y10:Y12) -> 82 | Z25: =SUM(Z10:Z12) -> 2 | ... AF25: =SUM(AF10:AF12) -> 1262
B26: 11.00 - 11.15 | C26: 15 | D26: 3 | E26: 3 | F26: 12 | G26: 1 | H26: 0 | I26: 4 | J26: 0 | K26: 0 | L26: 0 | M26: 23 | N26: 0 | O26: =SUM(C26:L26,N26) -> 38 | P26: =SUM(C26:N26) -> 61 | R26: IP Period | S26: =SUM(S13:S18) -> 893 | T26: =SUM(T13:T18) -> 152 | U26: =SUM(U13:U18) -> 60 | V26: =SUM(V13:V18) -> 342 | W26: =SUM(W13:W18) -> 7 | X26: =SUM(X13:X18) -> 0 | Y26: =SUM(Y13:Y18) -> 108 | Z26: =SUM(Z13:Z18) -> 16 | ... AF26: =SUM(AF13:AF18) -> 2315
B27: 11.15 - 11.30 | C27: 26 | D27: 5 | E27: 0 | F27: 13 | G27: 0 | H27: 0 | I27: 6 | J27: 0 | K27: 0 | L27: 0 | M27: 45 | N27: 0 | O27: =SUM(C27:L27,N27) -> 50 | P27: =SUM(C27:N27) -> 95 | R27: PM Period | S27: =SUM(S19:S21) -> 1523 | T27: =SUM(T19:T21) -> 225 | U27: =SUM(U19:U21) -> 87 | V27: =SUM(V19:V21) -> 165 | W27: =SUM(W19:W21) -> 5 | X27: =SUM(X19:X21) -> 1 | Y27: =SUM(Y19:Y21) -> 41 | Z27: =SUM(Z19:Z21) -> 3 | ... AF27: =SUM(AF19:AF21) -> 2852
B28: 11.30 - 11.45 | C28: 38 | D28: 15 | E28: 3 | F28: 25 | G28: 0 | H28: 0 | I28: 3 | J28: 0 | K28: 0 | L28: 0 | M28: 45 | N28: 0 | O28: =SUM(C28:L28,N28) -> 84 | P28: =SUM(C28:N28) -> 129 | R28: 12 Hours | S28: =SUM(S10:S21) -> 2708 | T28: =SUM(T10:T21) -> 448 | U28: =SUM(U10:U21) -> 173 | V28: =SUM(V10:V21) -> 683 | W28: =SUM(W10:W21) -> 23 | X28: =SUM(X10:X21) -> 1 | Y28: =SUM(Y10:Y21) -> 231 | Z28: =SUM(Z10:Z21) -> 21 | ... AF28: =SUM(AF10:AF21) -> 6429
B29: 11.45 - 12.00 | C29: 25 | D29: 7 | E29: 4 | F29: 24 | G29: 0 | H29: 0 | I29: 2 | J29: 2 | K29: 0 | L29: 0 | M29: 30 | N29: 0 | O29: =SUM(C29:L29,N29) -> 64 | P29: =SUM(C29:N29) -> 94
B30: 12.00 - 12.15 | C30: 35 | D30: 4 | E30: 2 | F30: 26 | G30: 0 | H30: 0 | I30: 7 | J30: 1 | K30: 2 | L30: 0 | M30: 60 | N30: 0 | O30: =SUM(C30:L30,N30) -> 77 | P30: =SUM(C30:N30) -> 137
B31: 12.15 - 12.30 | C31: 35 | D31: 5 | E31: 4 | F31: 20 | G31: 0 | H31: 0 | I31: 3 | J31: 0 | K31: 0 | L31: 0 | M31: 22 | N31: 0 | O31: =SUM(C31:L31,N31) -> 67 | P31: =SUM(C31:N31) -> 89
B32: 12.30 - 12.45 | C32: 33 | D32: 7 | E32: 0 | F32: 15 | G32: 0 | H32: 0 | I32: 4 | J32: 0 | K32: 0 | L32: 0 | M32: 35 | N32: 0 | O32: =SUM(C32:L32,N32) -> 59 | P32: =SUM(C32:N32) -> 94
B33: 12.45 - 13.00 | C33: 30 | D33: 9 | E33: 4 | F33: 7 | G33: 0 | H33: 0 | I33: 4 | J33: 2 | K33: 0 | L33: 0 | M33: 25 | N33: 0 | O33: =SUM(C33:L33,N33) -> 56 | P33: =SUM(C33:N33) -> 81
B34: 13.00 - 13.15 | C34: 37 | D34: 4 | E34: 1 | F34: 10 | G34: 0 | H34: 0 | I34: 6 | J34: 0 | K34: 0 | L34: 0 | M34: 35 | N34: 0 | O34: =SUM(C34:L34,N34) -> 58 | P34: =SUM(C34:N34) -> 93
B35: 13.15 - 13.30 | C35: 46 | D35: 8 | E35: 2 | F35: 19 | G35: 0 | H35: 0 | I35: 6 | J35: 0 | K35: 0 | L35: 0 | M35: 42 | N35: 0 | O35: =SUM(C35:L35,N35) -> 81 | P35: =SUM(C35:N35) -> 123
B36: 13.30 - 13.45 | C36: 50 | D36: 5 | E36: 2 | F36: 19 | G36: 0 | H36: 0 | I36: 2 | J36: 0 | K36: 0 | L36: 0 | M36: 30 | N36: 0 | O36: =SUM(C36:L36,N36) -> 78 | P36: =SUM(C36:N36) -> 108
B37: 13.45 - 14.00 | C37: 60 | D37: 6 | E37: 6 | F37: 15 | G37: 0 | H37: 0 | I37: 5 | J37: 0 | K37: 0 | L37: 0 | M37: 26 | N37: 0 | O37: =SUM(C37:L37,N37) -> 92 | P37: =SUM(C37:N37) -> 118
B38: 14.00 - 14.15 | C38: 26 | D38: 7 | E38: 0 | F38: 10 | G38: 0 | H38: 0 | I38: 6 | J38: 0 | K38: 0 | L38: 1 | M38: 20 | N38: 0 | O38: =SUM(C38:L38,N38) -> 50 | P38: =SUM(C38:N38) -> 70
B39: 14.15 - 14.30 | C39: 22 | D39: 3 | E39: 2 | F39: 11 | G39: 1 | H39: 0 | I39: 4 | J39: 1 | K39: 0 | L39: 0 | M39: 12 | N39: 0 | O39: =SUM(C39:L39,N39) -> 44 | P39: =SUM(C39:N39) -> 56
B40: 14.30 - 14.45 | C40: 28 | D40: 4 | E40: 1 | F40: 12 | G40: 0 | H40: 0 | I40: 5 | J40: 2 | K40: 1 | L40: 0 | M40: 18 | N40: 0 | O40: =SUM(C40:L40,N40) -> 53 | P40: =SUM(C40:N40) -> 71
... B57: 18.45 - 19.00 | C57: 160 | D57: 24 | E57: 5 | F57: 10 | G57: 0 | H57: 0 | I57: 1 | J57: 0 | K57: 0 | L57: 0 | M57: 78 | N57: 0 | O57: =SUM(C57:L57,N57) -> 200 | P57: =SUM(C57:N57) -> 278
B58: Totals | C58: =SUM(C10:C57) -> 2708 | D58: =SUM(D10:D57) -> 448 | E58: =SUM(E10:E57) -> 173 | F58: =SUM(F10:F57) -> 683 | G58: =SUM(G10:G57) -> 23 | H58: =SUM(H10:H57) -> 1 | I58: =SUM(I10:I57) -> 231 | J58: =SUM(J10:J57) -> 21 | ... P58: =SUM(P10:P57) -> 6429
...

Sheet 31.07 Najjeera-Kiwatule
B1: Consultancy services for Preparation of Expressway Development Master Plan (EDMP) for Uganda
B2: MANUAL CLASSIFIED COUNT (MCC)
B3: ROAD NAME: | C3: ='29.07 Najjeera-Kiwatule'!C3:G3 -> MCC - C1 - STN36 - MBOGO ROAD
C5: Date | D5: 31.07.19 | F5: Location | G5: ='30.07 Kiwatule-Najjeera'!G5:H5 -> U Save Kiwatule | J5: Surveyor | K5: Anthony
C6: Dir. From | D6: ='29.07 Najjeera-Kiwatule'!D6:E6 -> Najjeera | F6: Dir. To | G6: ='29.07 Najjeera-Kiwatule'!G6:H6 -> Kiwatule | J6: Supervisor | K6: ='30.07 Kiwatule-Najjeera'!K6:L6 -> Steven
B8: Time / Veh Type | R8: SUMMARY TRAFFIC VOLUMES
C9: 1. Car | D9: 2. Station Wagon | E9: 3. Pickups | F9: 4. Minibus, matatu | G9: 5. Medium bus | H9: 6. Large Bus | I9: 7. Light Truck | J9: 8. Medium Truck | K9: 9. Heavy truck | L9: 10. Truck Trailer | M9: 11. Motor cycles | N9: 12. Tractors | O9: Total Excl M/Cycles | P9: Total All | R9: Time | S9: 1. Car | T9: 2. Station Wagon | U9: 3. Pickups | V9: 4. Minibus, matatu | W9: 5. Medium bus | X9: 6. Large Bus | Y9: 7. Light Truck | Z9: 8. Medium Truck | AA9: 9. Heavy truck | AB9: 10. Truck Trailer | AC9: 11. Motorcycles | AD9: 12. Tractors, Graders | AE9: Total Excl M/ Cycles | AF9: Total All
B10: 07.00 - 07.15 | C10: 147 | D10: 15 | E10: 7 | F10: 17 | G10: 0 | H10: 0 | I10: 1 | J10: 0 | K10: 0 | L10: 0 | M10: 75 | N10: 0 | O10: =SUM(C10:L10,N10) -> 187 | P10: =SUM(C10:N10) -> 262 | R10: 0700-0800 | S10: =SUM(C10:C13) -> 655 | T10: =SUM(D10:D13) -> 60 | U10: =SUM(E10:E13) -> 30 | V10: =SUM(F10:F13) -> 78 | W10: =SUM(G10:G13) -> 1 | X10: =SUM(H10:H13) -> 0 | Y10: =SUM(I10:I13) -> 10 | Z10: =SUM(J10:J13) -> 1 | ... AF10: =SUM(P10:P13) -> 1285
B11: 07.15 - 07.30 | C11: 143 | D11: 15 | E11: 4 | F11: 15 | G11: 0 | H11: 0 | I11: 2 | J11: 1 | K11: 0 | L11: 0 | M11: 105 | N11: 0 | O11: =SUM(C11:L11,N11) -> 180 | P11: =SUM(C11:N11) -> 285 | R11: 0800-0900 | S11: =SUM(C14:C17) -> 580 | T11: =SUM(D14:D17) -> 83 | U11: =SUM(E14:E17) -> 29 | V11: =SUM(F14:F17) -> 82 | W11: =SUM(G14:G17) -> 0 | X11: =SUM(H14:H17) -> 0 | Y11: =SUM(I14:I17) -> 17 | Z11: =SUM(J14:J17) -> 7 | ... AF11: =SUM(P14:P17) -> 1383
B12: 07.30 - 07.45 | C12: 170 | D12: 15 | E12: 7 | F12: 28 | G12: 0 | H12: 0 | I12: 2 | J12: 0 | K12: 0 | L12: 0 | M12: 150 | N12: 0 | O12: =SUM(C12:L12,N12) -> 222 | P12: =SUM(C12:N12) -> 372 | R12: 0900-1000 | S12: =SUM(C18:C21) -> 395 | T12: =SUM(D18:D21) -> 47 | U12: =SUM(E18:E21) -> 31 | V12: =SUM(F18:F21) -> 54 | W12: =SUM(G18:G21) -> 0 | X12: =SUM(H18:H21) -> 0 | Y12: =SUM(I18:I21) -> 16 | Z12: =SUM(J18:J21) -> 2 | ... AF12: =SUM(P18:P21) -> 1022
B13: 07.45 - 08.00 | C13: 195 | D13: 15 | E13: 12 | F13: 18 | G13: 1 | H13: 0 | I13: 5 | J13: 0 | K13: 0 | L13: 0 | M13: 120 | N13: 0 | O13: =SUM(C13:L13,N13) -> 246 | P13: =SUM(C13:N13) -> 366 | R13: 1000-1100 | S13: =SUM(C22:C25) -> 317 | T13: =SUM(D22:D25) -> 62 | U13: =SUM(E22:E25) -> 37 | V13: =SUM(F22:F25) -> 59 | W13: =SUM(G22:G25) -> 1 | X13: =SUM(H22:H25) -> 0 | Y13: =SUM(I22:I25) -> 19 | Z13: =SUM(J22:J25) -> 2 | ... AF13: =SUM(P22:P25) -> 838
B14: 08.00 - 08.15 | C14: 155 | D14: 19 | E14: 5 | F14: 24 | G14: 0 | H14: 0 | I14: 6 | J14: 1 | K14: 2 | L14: 0 | M14: 161 | N14: 0 | O14: =SUM(C14:L14,N14) -> 212 | P14: =SUM(C14:N14) -> 373 | R14: 1100-1200 | S14: =SUM(C26:C29) -> 275 | T14: =SUM(D26:D29) -> 41 | U14: =SUM(E26:E29) -> 33 | V14: =SUM(F26:F29) -> 66 | W14: =SUM(G26:G29) -> 0 | X14: =SUM(H26:H29) -> 0 | Y14: =SUM(I26:I29) -> 26 | Z14: =SUM(J26:J29) -> 8 | ... AF14: =SUM(P26:P29) -> 776
B15: 08.15 - 08.30 | C15: 150 | D15: 13 | E15: 4 | F15: 19 | G15: 0 | H15: 0 | I15: 2 | J15: 3 | K15: 0 | L15: 0 | M15: 140 | N15: 0 | O15: =SUM(C15:L15,N15) -> 191 | P15: =SUM(C15:N15) -> 331 | R15: 1200-1300 | S15: =SUM(C30:C33) -> 226 | T15: =SUM(D30:D33) -> 32 | U15: =SUM(E30:E33) -> 13 | V15: =SUM(F30:F33) -> 52 | W15: =SUM(G30:G33) -> 0 | X15: =SUM(H30:H33) -> 0 | Y15: =SUM(I30:I33) -> 20 | Z15: =SUM(J30:J33) -> 3 | ... AF15: =SUM(P30:P33) -> 702
B16: 08.30 - 08.45 | C16: 175 | D16: 39 | E16: 15 | F16: 25 | G16: 0 | H16: 0 | I16: 5 | J16: 1 | K16: 0 | L16: 0 | M16: 153 | N16: 0 | O16: =SUM(C16:L16,N16) -> 260 | P16: =SUM(C16:N16) -> 413 | R16: 1300-1400 | S16: =SUM(C34:C37) -> 317 | T16: =SUM(D34:D37) -> 35 | U16: =SUM(E34:E37) -> 27 | V16: =SUM(F34:F37) -> 58 | W16: =SUM(G34:G37) -> 1 | X16: =SUM(H34:H37) -> 0 | Y16: =SUM(I34:I37) -> 21 | Z16: =SUM(J34:J37) -> 4 | ... AF16: =SUM(P34:P37) -> 787
B17: 08.45 - 9.00 | C17: 100 | D17: 12 | E17: 5 | F17: 14 | G17: 0 | H17: 0 | I17: 4 | J17: 2 | K17: 1 | L17: 0 | M17: 128 | N17: 0 | O17: =SUM(C17:L17,N17) -> 138 | P17: =SUM(C17:N17) -> 266 | R17: 1400-1500 | S17: =SUM(C38:C41) -> 239 | T17: =SUM(D38:D41) -> 30 | U17: =SUM(E38:E41) -> 21 | V17: =SUM(F38:F41) -> 54 | W17: =SUM(G38:G41) -> 1 | X17: =SUM(H38:H41) -> 0 | Y17: =SUM(I38:I41) -> 22 | Z17: =SUM(J38:J41) -> 2 | ... AF17: =SUM(P38:P41) -> 729
B18: 09.00 - 09.15 | C18: 119 | D18: 17 | E18: 11 | F18: 15 | G18: 0 | H18: 0 | I18: 4 | J18: 0 | K18: 0 | L18: 0 | M18: 159 | N18: 0 | O18: =SUM(C18:L18,N18) -> 166 | P18: =SUM(C18:N18) -> 325 | R18: 1500-1600 | S18: =SUM(C42:C45) -> 245 | T18: =SUM(D42:D45) -> 35 | U18: =SUM(E42:E45) -> 28 | V18: =SUM(F42:F45) -> 55 | W18: =SUM(G42:G45) -> 0 | X18: =SUM(H42:H45) -> 0 | Y18: =SUM(I42:I45) -> 14 | Z18: =SUM(J42:J45) -> 1 | ... AF18: =SUM(P42:P45) -> 666
B19: 09.15 - 09.30 | C19: 91 | D19: 14 | E19: 6 | F19: 13 | G19: 0 | H19: 0 | I19: 4 | J19: 1 | K19: 0 | L19: 0 | M19: 110 | N19: 0 | O19: =SUM(C19:L19,N19) -> 129 | P19: =SUM(C19:N19) -> 239 | R19: 1600-1700 | S19: =SUM(C46:C49) -> 282 | T19: =SUM(D46:D49) -> 48 | U19: =SUM(E46:E49) -> 32 | V19: =SUM(F46:F49) -> 53 | W19: =SUM(G46:G49) -> 1 | X19: =SUM(H46:H49) -> 0 | Y19: =SUM(I46:I49) -> 12 | Z19: =SUM(J46:J49) -> 0 | ... AF19: =SUM(P46:P49) -> 751
B20: 09.30 - 09.45 | C20: 125 | D20: 10 | E20: 9 | F20: 15 | G20: 0 | H20: 0 | I20: 5 | J20: 1 | K20: 0 | L20: 1 | M20: 120 | N20: 0 | O20: =SUM(C20:L20,N20) -> 166 | P20: =SUM(C20:N20) -> 286 | R20: 1700-1800 | S20: =SUM(C50:C53) -> 211 | T20: =SUM(D50:D53) -> 29 | U20: =SUM(E50:E53) -> 24 | V20: =SUM(F50:F53) -> 56 | W20: =SUM(G50:G53) -> 6 | X20: =SUM(H50:H53) -> 0 | Y20: =SUM(I50:I53) -> 21 | Z20: =SUM(J50:J53) -> 2 | ... AF20: =SUM(P50:P53) -> 750
B21: 09.45 - 10.00 | C21: 60 | D21: 6 | E21: 5 | F21: 11 | G21: 0 | H21: 0 | I21: 3 | J21: 0 | K21: 0 | L21: 0 | M21: 87 | N21: 0 | O21: =SUM(C21:L21,N21) -> 85 | P21: =SUM(C21:N21) -> 172 | R21: 1800-1900 | S21: =SUM(C54:C57) -> 145 | T21: =SUM(D54:D57) -> 20 | U21: =SUM(E54:E57) -> 18 | V21: =SUM(F54:F57) -> 50 | W21: =SUM(G54:G57) -> 5 | X21: =SUM(H54:H57) -> 0 | Y21: =SUM(I54:I57) -> 16 | Z21: =SUM(J54:J57) -> 2 | ... AF21: =SUM(P54:P57) -> 671
B22: 10.00 - 10.15 | C22: 105 | D22: 20 | E22: 10 | F22: 15 | G22: 0 | H22: 0 | I22: 7 | J22: 0 | K22: 0 | L22: 1 | M22: 71 | N22: 0 | O22: =SUM(C22:L22,N22) -> 158 | P22: =SUM(C22:N22) -> 229 | R22: AM Peak Hr | S22: =MAX(S10:S12) -> 655 | T22: =MAX(T10:T12) -> 83 | U22: =MAX(U10:U12) -> 31 | V22: =MAX(V10:V12) -> 82 | W22: =MAX(W10:W12) -> 1 | X22: =MAX(X10:X12) -> 0 | Y22: =MAX(Y10:Y12) -> 17 | Z22: =MAX(Z10:Z12) -> 7 | ... AF22: =MAX(AF10:AF12) -> 1383
B23: 10.15 - 10.30 | C23: 87 | D23: 12 | E23: 10 | F23: 16 | G23: 1 | H23: 0 | I23: 5 | J23: 0 | K23: 0 | L23: 0 | M23: 76 | N23: 0 | O23: =SUM(C23:L23,N23) -> 131 | P23: =SUM(C23:N23) -> 207 | R23: IP Peak Hr | S23: =MAX(S13:S18) -> 317 | T23: =MAX(T13:T18) -> 62 | U23: =MAX(U13:U18) -> 37 | V23: =MAX(V13:V18) -> 66 | W23: =MAX(W13:W18) -> 1 | X23: =MAX(X13:X18) -> 0 | Y23: =MAX(Y13:Y18) -> 26 | Z23: =MAX(Z13:Z18) -> 8 | ... AF23: =MAX(AF13:AF18) -> 838
B24: 10.30 - 10.45 | C24: 75 | D24: 20 | E24: 12 | F24: 15 | G24: 0 | H24: 0 | I24: 3 | J24: 1 | K24: 0 | L24: 1 | M24: 80 | N24: 0 | O24: =SUM(C24:L24,N24) -> 127 | P24: =SUM(C24:N24) -> 207 | R24: PM Peak Hr | S24: =MAX(S19:S21) -> 282 | T24: =MAX(T19:T21) -> 48 | U24: =MAX(U19:U21) -> 32 | V24: =MAX(V19:V21) -> 56 | W24: =MAX(W19:W21) -> 6 | X24: =MAX(X19:X21) -> 0 | Y24: =MAX(Y19:Y21) -> 21 | Z24: =MAX(Z19:Z21) -> 2 | ... AF24: =MAX(AF19:AF21) -> 751
B25: 10.45 - 11.00 | C25: 50 | D25: 10 | E25: 5 | F25: 13 | G25: 0 | H25: 0 | I25: 4 | J25: 1 | K25: 1 | L25: 0 | M25: 111 | N25: 0 | O25: =SUM(C25:L25,N25) -> 84 | P25: =SUM(C25:N25) -> 195 | R25: AM Period | S25: =SUM(S10:S12) -> 1630 | T25: =SUM(T10:T12) -> 190 | U25: =SUM(U10:U12) -> 90 | V25: =SUM(V10:V12) -> 214 | W25: =SUM(W10:W12) -> 1 | X25: =SUM(X10:X12) -> 0 | Y25: =SUM(Y10:Y12) -> 43 | Z25: =SUM(Z10:Z12) -> 10 | ... AF25: =SUM(AF10:AF12) -> 3690
B26: 11.00 - 11.15 | C26: 90 | D26: 16 | E26: 10 | F26: 19 | G26: 0 | H26: 0 | I26: 3 | J26: 0 | K26: 0 | L26: 0 | M26: 65 | N26: 0 | O26: =SUM(C26:L26,N26) -> 138 | P26: =SUM(C26:N26) -> 203 | R26: IP Period | S26: =SUM(S13:S18) -> 1619 | T26: =SUM(T13:T18) -> 235 | U26: =SUM(U13:U18) -> 159 | V26: =SUM(V13:V18) -> 344 | W26: =SUM(W13:W18) -> 3 | X26: =SUM(X13:X18) -> 0 | Y26: =SUM(Y13:Y18) -> 122 | Z26: =SUM(Z13:Z18) -> 20 | ... AF26: =SUM(AF13:AF18) -> 4498
B27: 11.15 - 11.30 | C27: 85 | D27: 8 | E27: 7 | F27: 17 | G27: 0 | H27: 0 | I27: 7 | J27: 1 | K27: 1 | L27: 1 | M27: 85 | N27: 0 | O27: =SUM(C27:L27,N27) -> 127 | P27: =SUM(C27:N27) -> 212 | R27: PM Period | S27: =SUM(S19:S21) -> 638 | T27: =SUM(T19:T21) -> 97 | U27: =SUM(U19:U21) -> 74 | V27: =SUM(V19:V21) -> 159 | W27: =SUM(W19:W21) -> 12 | X27: =SUM(X19:X21) -> 0 | Y27: =SUM(Y19:Y21) -> 49 | Z27: =SUM(Z19:Z21) -> 4 | ... AF27: =SUM(AF19:AF21) -> 2172
