Workbook

Sheet 11.08 BUSUNJU-KAMPALA
B1: Consultancy services for Preparation of Expressway Development Master Plan (EDMP) for Uganda
B2: MANUAL CLASSIFIED COUNT (MCC)
B3: ROAD NAME: | C3: MCC - C3 - STN85 - HOIMA ROAD
C5: Date | D5: 11.08.19 | F5: Location | G5: MATTE | J5: Surveyor | K5: xxx
C6: Dir. From | D6: BUSUNJU | F6: Dir. To | G6: KAMPALA | J6: Supervisor | K6: xxx
B8: Time / Veh Type | R8: SUMMARY TRAFFIC VOLUMES
C9: 1. Car | D9: 2. Station Wagon | E9: 3. Pickups | F9: 4. Minibus, matatu | G9: 5. Medium bus | H9: 6. Large Bus | I9: 7. Light Truck | J9: 8. Medium Truck | K9: 9. Heavy truck | L9: 10. Truck Trailer | M9: 11. Motor cycles | N9: 12. Tractors | O9: Total Excl M/Cycles | P9: Total All | R9: Time | S9: 1. Car | T9: 2. Station Wagon | U9: 3. Pickups | V9: 4. Minibus, matatu | W9: 5. Medium bus | X9: 6. Large Bus | Y9: 7. Light Truck | Z9: 8. Medium Truck | AA9: 9. Heavy truck | AB9: 10. Truck Trailer | AC9: 11. Motorcycles | AD9: 12. Tractors, Graders | AE9: Total Excl M/ Cycles | AF9: Total All
B10: 07.00 - 07.15 | C10: 0 | D10: 0 | E10: 0 | F10: 0 | G10: 0 | H10: 0 | I10: 0 | J10: 0 | K10: 0 | L10: 0 | M10: 5 | N10: 0 | O10: =SUM(C10:L10,N10) -> 0 | P10: =SUM(C10:N10) -> 5 | R10: 0700-0800 | S10: =SUM(C10:C13) -> 1 | T10: =SUM(D10:D13) -> 0 | U10: =SUM(E10:E13) -> 2 | V10: =SUM(F10:F13) -> 0 | W10: =SUM(G10:G13) -> 0 | X10: =SUM(H10:H13) -> 0 | Y10: =SUM(I10:I13) -> 0 | Z10: =SUM(J10:J13) -> 0 | ... AF10: =SUM(P10:P13) -> 47
B11: 07.15 - 07.30 | C11: 0 | D11: 0 | E11: 0 | F11: 0 | G11: 0 | H11: 0 | I11: 0 | J11: 0 | K11: 0 | L11: 0 | M11: 16 | N11: 0 | O11: =SUM(C11:L11,N11) -> 0 | P11: =SUM(C11:N11) -> 16 | R11: 0800-0900 | S11: =SUM(C14:C17) -> 6 | T11: =SUM(D14:D17) -> 0 | U11: =SUM(E14:E17) -> 1 | V11: =SUM(F14:F17) -> 1 | W11: =SUM(G14:G17) -> 0 | X11: =SUM(H14:H17) -> 0 | Y11: =SUM(I14:I17) -> 0 | Z11: =SUM(J14:J17) -> 0 | ... AF11: =SUM(P14:P17) -> 59
B12: 07.30 - 07.45 | C12: 1 | D12: 0 | E12: 1 | F12: 0 | G12: 0 | H12: 0 | I12: 0 | J12: 0 | K12: 0 | L12: 0 | M12: 8 | N12: 0 | O12: =SUM(C12:L12,N12) -> 2 | P12: =SUM(C12:N12) -> 10 | R12: 0900-1000 | S12: =SUM(C18:C21) -> 6 | T12: =SUM(D18:D21) -> 0 | U12: =SUM(E18:E21) -> 3 | V12: =SUM(F18:F21) -> 2 | W12: =SUM(G18:G21) -> 0 | X12: =SUM(H18:H21) -> 0 | Y12: =SUM(I18:I21) -> 0 | Z12: =SUM(J18:J21) -> 2 | ... AF12: =SUM(P18:P21) -> 88
B13: 07.45 - 08.00 | C13: 0 | D13: 0 | E13: 1 | F13: 0 | G13: 0 | H13: 0 | I13: 0 | J13: 0 | K13: 0 | L13: 0 | M13: 15 | N13: 0 | O13: =SUM(C13:L13,N13) -> 1 | P13: =SUM(C13:N13) -> 16 | R13: 1000-1100 | S13: =SUM(C22:C25) -> 5 | T13: =SUM(D22:D25) -> 0 | U13: =SUM(E22:E25) -> 2 | V13: =SUM(F22:F25) -> 1 | W13: =SUM(G22:G25) -> 0 | X13: =SUM(H22:H25) -> 0 | Y13: =SUM(I22:I25) -> 1 | Z13: =SUM(J22:J25) -> 2 | ... AF13: =SUM(P22:P25) -> 84
B14: 08.00 - 08.15 | C14: 2 | D14: 0 | E14: 0 | F14: 1 | G14: 0 | H14: 0 | I14: 0 | J14: 0 | K14: 0 | L14: 0 | M14: 13 | N14: 0 | O14: =SUM(C14:L14,N14) -> 3 | P14: =SUM(C14:N14) -> 16 | R14: 1100-1200 | S14: =SUM(C26:C29) -> 6 | T14: =SUM(D26:D29) -> 0 | U14: =SUM(E26:E29) -> 4 | V14: =SUM(F26:F29) -> 1 | W14: =SUM(G26:G29) -> 0 | X14: =SUM(H26:H29) -> 0 | Y14: =SUM(I26:I29) -> 1 | Z14: =SUM(J26:J29) -> 3 | ... AF14: =SUM(P26:P29) -> 100
B15: 08.15 - 08.30 | C15: 1 | D15: 0 | E15: 1 | F15: 0 | G15: 0 | H15: 0 | I15: 0 | J15: 0 | K15: 0 | L15: 0 | M15: 10 | N15: 0 | O15: =SUM(C15:L15,N15) -> 2 | P15: =SUM(C15:N15) -> 12 | R15: 1200-1300 | S15: =SUM(C30:C33) -> 4 | T15: =SUM(D30:D33) -> 0 | U15: =SUM(E30:E33) -> 4 | V15: =SUM(F30:F33) -> 2 | W15: =SUM(G30:G33) -> 0 | X15: =SUM(H30:H33) -> 0 | Y15: =SUM(I30:I33) -> 0 | Z15: =SUM(J30:J33) -> 3 | ... AF15: =SUM(P30:P33) -> 77
B16: 08.30 - 08.45 | C16: 3 | D16: 0 | E16: 0 | F16: 0 | G16: 0 | H16: 0 | I16: 0 | J16: 0 | K16: 0 | L16: 0 | M16: 10 | N16: 0 | O16: =SUM(C16:L16,N16) -> 3 | P16: =SUM(C16:N16) -> 13 | R16: 1300-1400 | S16: =SUM(C34:C37) -> 3 | T16: =SUM(D34:D37) -> 0 | U16: =SUM(E34:E37) -> 6 | V16: =SUM(F34:F37) -> 0 | W16: =SUM(G34:G37) -> 0 | X16: =SUM(H34:H37) -> 0 | Y16: =SUM(I34:I37) -> 0 | Z16: =SUM(J34:J37) -> 2 | ... AF16: =SUM(P34:P37) -> 59
B17: 08.45 - 9.00 | C17: 0 | D17: 0 | E17: 0 | F17: 0 | G17: 0 | H17: 0 | I17: 0 | J17: 0 | K17: 0 | L17: 0 | M17: 18 | N17: 0 | O17: =SUM(C17:L17,N17) -> 0 | P17: =SUM(C17:N17) -> 18 | R17: 1400-1500 | S17: =SUM(C38:C41) -> 5 | T17: =SUM(D38:D41) -> 0 | U17: =SUM(E38:E41) -> 3 | V17: =SUM(F38:F41) -> 0 | W17: =SUM(G38:G41) -> 0 | X17: =SUM(H38:H41) -> 0 | Y17: =SUM(I38:I41) -> 1 | Z17: =SUM(J38:J41) -> 0 | ... AF17: =SUM(P38:P41) -> 61
B18: 09.00 - 09.15 | C18: 1 | D18: 0 | E18: 2 | F18: 1 | G18: 0 | H18: 0 | I18: 0 | J18: 0 | K18: 0 | L18: 0 | M18: 18 | N18: 0 | O18: =SUM(C18:L18,N18) -> 4 | P18: =SUM(C18:N18) -> 22 | R18: 1500-1600 | S18: =SUM(C42:C45) -> 5 | T18: =SUM(D42:D45) -> 0 | U18: =SUM(E42:E45) -> 6 | V18: =SUM(F42:F45) -> 1 | W18: =SUM(G42:G45) -> 0 | X18: =SUM(H42:H45) -> 0 | Y18: =SUM(I42:I45) -> 1 | Z18: =SUM(J42:J45) -> 0 | ... AF18: =SUM(P42:P45) -> 68
B19: 09.15 - 09.30 | C19: 1 | D19: 0 | E19: 0 | F19: 0 | G19: 0 | H19: 0 | I19: 0 | J19: 0 | K19: 0 | L19: 0 | M19: 14 | N19: 0 | O19: =SUM(C19:L19,N19) -> 1 | P19: =SUM(C19:N19) -> 15 | R19: 1600-1700 | S19: =SUM(C46:C49) -> 4 | T19: =SUM(D46:D49) -> 0 | U19: =SUM(E46:E49) -> 0 | V19: =SUM(F46:F49) -> 1 | W19: =SUM(G46:G49) -> 0 | X19: =SUM(H46:H49) -> 0 | Y19: =SUM(I46:I49) -> 0 | Z19: =SUM(J46:J49) -> 0 | ... AF19: =SUM(P46:P49) -> 59
B20: 09.30 - 09.45 | C20: 2 | D20: 0 | E20: 0 | F20: 0 | G20: 0 | H20: 0 | I20: 0 | J20: 1 | K20: 0 | L20: 0 | M20: 22 | N20: 0 | O20: =SUM(C20:L20,N20) -> 3 | P20: =SUM(C20:N20) -> 25 | R20: 1700-1800 | S20: =SUM(C50:C53) -> 3 | T20: =SUM(D50:D53) -> 0 | U20: =SUM(E50:E53) -> 6 | V20: =SUM(F50:F53) -> 0 | W20: =SUM(G50:G53) -> 0 | X20: =SUM(H50:H53) -> 0 | Y20: =SUM(I50:I53) -> 2 | Z20: =SUM(J50:J53) -> 1 | ... AF20: =SUM(P50:P53) -> 74
B21: 09.45 - 10.00 | C21: 2 | D21: 0 | E21: 1 | F21: 1 | G21: 0 | H21: 0 | I21: 0 | J21: 1 | K21: 0 | L21: 0 | M21: 21 | N21: 0 | O21: =SUM(C21:L21,N21) -> 5 | P21: =SUM(C21:N21) -> 26 | R21: 1800-1900 | S21: =SUM(C54:C57) -> 11 | T21: =SUM(D54:D57) -> 0 | U21: =SUM(E54:E57) -> 3 | V21: =SUM(F54:F57) -> 2 | W21: =SUM(G54:G57) -> 0 | X21: =SUM(H54:H57) -> 0 | Y21: =SUM(I54:I57) -> 2 | Z21: =SUM(J54:J57) -> 1 | ... AF21: =SUM(P54:P57) -> 80
B22: 10.00 - 10.15 | C22: 0 | D22: 0 | E22: 0 | F22: 1 | G22: 0 | H22: 0 | I22: 0 | J22: 1 | K22: 0 | L22: 0 | M22: 22 | N22: 0 | O22: =SUM(C22:L22,N22) -> 2 | P22: =SUM(C22:N22) -> 24 | R22: AM Peak Hr | S22: =MAX(S10:S12) -> 6 | T22: =MAX(T10:T12) -> 0 | U22: =MAX(U10:U12) -> 3 | V22: =MAX(V10:V12) -> 2 | W22: =MAX(W10:W12) -> 0 | X22: =MAX(X10:X12) -> 0 | Y22: =MAX(Y10:Y12) -> 0 | Z22: =MAX(Z10:Z12) -> 2 | ... AF22: =MAX(AF10:AF12) -> 88
B23: 10.15 - 10.30 | C23: 2 | D23: 0 | E23: 1 | F23: 0 | G23: 0 | H23: 0 | I23: 1 | J23: 0 | K23: 0 | L23: 0 | M23: 13 | N23: 0 | O23: =SUM(C23:L23,N23) -> 4 | P23: =SUM(C23:N23) -> 17 | R23: IP Peak Hr | S23: =MAX(S13:S18) -> 6 | T23: =MAX(T13:T18) -> 0 | U23: =MAX(U13:U18) -> 6 | V23: =MAX(V13:V18) -> 2 | W23: =MAX(W13:W18) -> 0 | X23: =MAX(X13:X18) -> 0 | Y23: =MAX(Y13:Y18) -> 1 | Z23: =MAX(Z13:Z18) -> 3 | ... AF23: =MAX(AF13:AF18) -> 100
B24: 10.30 - 10.45 | C24: 1 | D24: 0 | E24: 0 | F24: 0 | G24: 0 | H24: 0 | I24: 0 | J24: 1 | K24: 0 | L24: 0 | M24: 22 | N24: 0 | O24: =SUM(C24:L24,N24) -> 2 | P24: =SUM(C24:N24) -> 24 | R24: PM Peak Hr | S24: =MAX(S19:S21) -> 11 | T24: =MAX(T19:T21) -> 0 | U24: =MAX(U19:U21) -> 6 | V24: =MAX(V19:V21) -> 2 | W24: =MAX(W19:W21) -> 0 | X24: =MAX(X19:X21) -> 0 | Y24: =MAX(Y19:Y21) -> 2 | Z24: =MAX(Z19:Z21) -> 1 | ... AF24: =MAX(AF19:AF21) -> 80
B25: 10.45 - 11.00 | C25: 2 | D25: 0 | E25: 1 | F25: 0 | G25: 0 | H25: 0 | I25: 0 | J25: 0 | K25: 0 | L25: 0 | M25: 16 | N25: 0 | O25: =SUM(C25:L25,N25) -> 3 | P25: =SUM(C25:N25) -> 19 | R25: AM Period | S25: =SUM(S10:S12) -> 13 | T25: =SUM(T10:T12) -> 0 | U25: =SUM(U10:U12) -> 6 | V25: =SUM(V10:V12) -> 3 | W25: =SUM(W10:W12) -> 0 | X25: =SUM(X10:X12) -> 0 | Y25: =SUM(Y10:Y12) -> 0 | Z25: =SUM(Z10:Z12) -> 2 | ... AF25: =SUM(AF10:AF12) -> 194
B26: 11.00 - 11.15 | C26: 2 | D26: 0 | E26: 1 | F26: 0 | G26: 0 | H26: 0 | I26: 0 | J26: 1 | K26: 0 | L26: 0 | M26: 16 | N26: 0 | O26: =SUM(C26:L26,N26) -> 4 | P26: =SUM(C26:N26) -> 20 | R26: IP Period | S26: =SUM(S13:S18) -> 28 | T26: =SUM(T13:T18) -> 0 | U26: =SUM(U13:U18) -> 25 | V26: =SUM(V13:V18) -> 5 | W26: =SUM(W13:W18) -> 0 | X26: =SUM(X13:X18) -> 0 | Y26: =SUM(Y13:Y18) -> 4 | Z26: =SUM(Z13:Z18) -> 10 | ... AF26: =SUM(AF13:AF18) -> 449
B27: 11.15 - 11.30 | C27: 2 | D27: 0 | E27: 1 | F27: 1 | G27: 0 | H27: 0 | I27: 0 | J27: 1 | K27: 0 | L27: 0 | M27: 27 | N27: 0 | O27: =SUM(C27:L27,N27) -> 5 | P27: =SUM(C27:N27) -> 32 | R27: PM Period | S27: =SUM(S19:S21) -> 18 | T27: =SUM(T19:T21) -> 0 | U27: =SUM(U19:U21) -> 9 | V27: =SUM(V19:V21) -> 3 | W27: =SUM(W19:W21) -> 0 | X27: =SUM(X19:X21) -> 0 | Y27: =SUM(Y19:Y21) -> 4 | Z27: =SUM(Z19:Z21) -> 2 | ... AF27: =SUM(AF19:AF21) -> 213
B28: 11.30 - 11.45 | C28: 1 | D28: 0 | E28: 1 | F28: 0 | G28: 0 | H28: 0 | I28: 1 | J28: 0 | K28: 0 | L28: 0 | M28: 24 | N28: 0 | O28: =SUM(C28:L28,N28) -> 3 | P28: =SUM(C28:N28) -> 27 | R28: 12 Hours | S28: =SUM(S10:S21) -> 59 | T28: =SUM(T10:T21) -> 0 | U28: =SUM(U10:U21) -> 40 | V28: =SUM(V10:V21) -> 11 | W28: =SUM(W10:W21) -> 0 | X28: =SUM(X10:X21) -> 0 | Y28: =SUM(Y10:Y21) -> 8 | Z28: =SUM(Z10:Z21) -> 14 | ... AF28: =SUM(AF10:AF21) -> 856
B29: 11.45 - 12.00 | C29: 1 | D29: 0 | E29: 1 | F29: 0 | G29: 0 | H29: 0 | I29: 0 | J29: 1 | K29: 0 | L29: 0 | M29: 18 | N29: 0 | O29: =SUM(C29:L29,N29) -> 3 | P29: =SUM(C29:N29) -> 21
B30: 12.00 - 12.15 | C30: 2 | D30: 0 | E30: 1 | F30: 0 | G30: 0 | H30: 0 | I30: 0 | J30: 2 | K30: 0 | L30: 0 | M30: 17 | N30: 0 | O30: =SUM(C30:L30,N30) -> 5 | P30: =SUM(C30:N30) -> 22
B31: 12.15 - 12.30 | C31: 0 | D31: 0 | E31: 1 | F31: 1 | G31: 0 | H31: 0 | I31: 0 | J31: 0 | K31: 0 | L31: 0 | M31: 6 | N31: 0 | O31: =SUM(C31:L31,N31) -> 2 | P31: =SUM(C31:N31) -> 8
B32: 12.30 - 12.45 | C32: 2 | D32: 0 | E32: 1 | F32: 0 | G32: 0 | H32: 0 | I32: 0 | J32: 0 | K32: 0 | L32: 0 | M32: 21 | N32: 0 | O32: =SUM(C32:L32,N32) -> 3 | P32: =SUM(C32:N32) -> 24
B33: 12.45 - 13.00 | C33: 0 | D33: 0 | E33: 1 | F33: 1 | G33: 0 | H33: 0 | I33: 0 | J33: 1 | K33: 0 | L33: 0 | M33: 20 | N33: 0 | O33: =SUM(C33:L33,N33) -> 3 | P33: =SUM(C33:N33) -> 23
B34: 13.00 - 13.15 | C34: 0 | D34: 0 | E34: 2 | F34: 0 | G34: 0 | H34: 0 | I34: 0 | J34: 2 | K34: 0 | L34: 0 | M34: 14 | N34: 0 | O34: =SUM(C34:L34,N34) -> 4 | P34: =SUM(C34:N34) -> 18
B35: 13.15 - 13.30 | C35: 2 | D35: 0 | E35: 2 | F35: 0 | G35: 0 | H35: 0 | I35: 0 | J35: 0 | K35: 0 | L35: 0 | M35: 20 | N35: 0 | O35: =SUM(C35:L35,N35) -> 4 | P35: =SUM(C35:N35) -> 24
B36: 13.30 - 13.45 | C36: 1 | D36: 0 | E36: 1 | F36: 0 | G36: 0 | H36: 0 | I36: 0 | J36: 0 | K36: 0 | L36: 0 | M36: 6 | N36: 0 | O36: =SUM(C36:L36,N36) -> 2 | P36: =SUM(C36:N36) -> 8
B37: 13.45 - 14.00 | C37: 0 | D37: 0 | E37: 1 | F37: 0 | G37: 0 | H37: 0 | I37: 0 | J37: 0 | K37: 0 | L37: 0 | M37: 8 | N37: 0 | O37: =SUM(C37:L37,N37) -> 1 | P37: =SUM(C37:N37) -> 9
B38: 14.00 - 14.15 | C38: 1 | D38: 0 | E38: 1 | F38: 0 | G38: 0 | H38: 0 | I38: 1 | J38: 0 | K38: 0 | L38: 0 | M38: 11 | N38: 0 | O38: =SUM(C38:L38,N38) -> 3 | P38: =SUM(C38:N38) -> 14
B39: 14.15 - 14.30 | C39: 0 | D39: 0 | E39: 0 | F39: 0 | G39: 0 | H39: 0 | I39: 0 | J39: 0 | K39: 0 | L39: 0 | M39: 13 | N39: 0 | O39: =SUM(C39:L39,N39) -> 0 | P39: =SUM(C39:N39) -> 13
B40: 14.30 - 14.45 | C40: 2 | D40: 0 | E40: 0 | F40: 0 | G40: 0 | H40: 0 | I40: 0 | J40: 0 | K40: 0 | L40: 0 | M40: 14 | N40: 0 | O40: =SUM(C40:L40,N40) -> 2 | P40: =SUM(C40:N40) -> 16
... B57: 18.45 - 19.00 | C57: 1 | D57: 0 | E57: 0 | F57: 1 | G57: 0 | H57: 0 | I57: 1 | J57: 0 | K57: 0 | L57: 0 | M57: 18 | N57: 0 | O57: =SUM(C57:L57,N57) -> 3 | P57: =SUM(C57:N57) -> 21
B58: Totals | C58: =SUM(C10:C57) -> 59 | D58: =SUM(D10:D57) -> 0 | E58: =SUM(E10:E57) -> 40 | F58: =SUM(F10:F57) -> 11 | G58: =SUM(G10:G57) -> 0 | H58: =SUM(H10:H57) -> 0 | I58: =SUM(I10:I57) -> 8 | J58: =SUM(J10:J57) -> 14 | ... P58: =SUM(P10:P57) -> 856
...

Sheet 11.08 KAMPALA-BUSUNJU
B1: Consultancy services for Preparation of Expressway Development Master Plan (EDMP) for Uganda
B2: MANUAL CLASSIFIED COUNT (MCC)
B3: ROAD NAME: | C3: ='11.08 BUSUNJU-KAMPALA'!C3:G3 -> MCC - C3 - STN85 - HOIMA ROAD
C5: Date | D5: ='11.08 BUSUNJU-KAMPALA'!D5 -> 11.08.19 | F5: Location | G5: ='11.08 BUSUNJU-KAMPALA'!G5:H5 -> MATTE | J5: Surveyor | K5: ='11.08 BUSUNJU-KAMPALA'!K5:L5 -> xxx
C6: Dir. From | D6: KAMPALA | F6: Dir. To | G6: BUSUNJU | J6: Supervisor | K6: ='11.08 BUSUNJU-KAMPALA'!K6:L6 -> xxx
B8: Time / Veh Type | R8: SUMMARY TRAFFIC VOLUMES
C9: 1. Car | D9: 2. Station Wagon | E9: 3. Pickups | F9: 4. Minibus, matatu | G9: 5. Medium bus | H9: 6. Large Bus | I9: 7. Light Truck | J9: 8. Medium Truck | K9: 9. Heavy truck | L9: 10. Truck Trailer | M9: 11. Motor cycles | N9: 12. Tractors | O9: Total Excl M/Cycles | P9: Total All | R9: Time | S9: 1. Car | T9: 2. Station Wagon | U9: 3. Pickups | V9: 4. Minibus, matatu | W9: 5. Medium bus | X9: 6. Large Bus | Y9: 7. Light Truck | Z9: 8. Medium Truck | AA9: 9. Heavy truck | AB9: 10. Truck Trailer | AC9: 11. Motorcycles | AD9: 12. Tractors, Graders | AE9: Total Excl M/ Cycles | AF9: Total All
B10: 07.00 - 07.15 | C10: 0 | D10: 0 | E10: 0 | F10: 1 | G10: 0 | H10: 0 | I10: 0 | J10: 0 | K10: 0 | L10: 0 | M10: 12 | N10: 0 | O10: =SUM(C10:L10,N10) -> 1 | P10: =SUM(C10:N10) -> 13 | R10: 0700-0800 | S10: =SUM(C10:C13) -> 3 | T10: =SUM(D10:D13) -> 0 | U10: =SUM(E10:E13) -> 0 | V10: =SUM(F10:F13) -> 2 | W10: =SUM(G10:G13) -> 0 | X10: =SUM(H10:H13) -> 0 | Y10: =SUM(I10:I13) -> 1 | Z10: =SUM(J10:J13) -> 0 | ... AF10: =SUM(P10:P13) -> 38
B11: 07.15 - 07.30 | C11: 1 | D11: 0 | E11: 0 | F11: 0 | G11: 0 | H11: 0 | I11: 0 | J11: 0 | K11: 0 | L11: 0 | M11: 5 | N11: 0 | O11: =SUM(C11:L11,N11) -> 1 | P11: =SUM(C11:N11) -> 6 | R11: 0800-0900 | S11: =SUM(C14:C17) -> 1 | T11: =SUM(D14:D17) -> 0 | U11: =SUM(E14:E17) -> 1 | V11: =SUM(F14:F17) -> 0 | W11: =SUM(G14:G17) -> 0 | X11: =SUM(H14:H17) -> 0 | Y11: =SUM(I14:I17) -> 2 | Z11: =SUM(J14:J17) -> 0 | ... AF11: =SUM(P14:P17) -> 54
B12: 07.30 - 07.45 | C12: 1 | D12: 0 | E12: 0 | F12: 0 | G12: 0 | H12: 0 | I12: 0 | J12: 0 | K12: 0 | L12: 0 | M12: 8 | N12: 0 | O12: =SUM(C12:L12,N12) -> 1 | P12: =SUM(C12:N12) -> 9 | R12: 0900-1000 | S12: =SUM(C18:C21) -> 6 | T12: =SUM(D18:D21) -> 0 | U12: =SUM(E18:E21) -> 0 | V12: =SUM(F18:F21) -> 2 | W12: =SUM(G18:G21) -> 0 | X12: =SUM(H18:H21) -> 0 | Y12: =SUM(I18:I21) -> 4 | Z12: =SUM(J18:J21) -> 0 | ... AF12: =SUM(P18:P21) -> 79
B13: 07.45 - 08.00 | C13: 1 | D13: 0 | E13: 0 | F13: 1 | G13: 0 | H13: 0 | I13: 1 | J13: 0 | K13: 0 | L13: 0 | M13: 7 | N13: 0 | O13: =SUM(C13:L13,N13) -> 3 | P13: =SUM(C13:N13) -> 10 | R13: 1000-1100 | S13: =SUM(C22:C25) -> 4 | T13: =SUM(D22:D25) -> 0 | U13: =SUM(E22:E25) -> 5 | V13: =SUM(F22:F25) -> 0 | W13: =SUM(G22:G25) -> 0 | X13: =SUM(H22:H25) -> 0 | Y13: =SUM(I22:I25) -> 6 | Z13: =SUM(J22:J25) -> 0 | ... AF13: =SUM(P22:P25) -> 92
B14: 08.00 - 08.15 | C14: 0 | D14: 0 | E14: 0 | F14: 0 | G14: 0 | H14: 0 | I14: 0 | J14: 0 | K14: 0 | L14: 0 | M14: 10 | N14: 0 | O14: =SUM(C14:L14,N14) -> 0 | P14: =SUM(C14:N14) -> 10 | R14: 1100-1200 | S14: =SUM(C26:C29) -> 6 | T14: =SUM(D26:D29) -> 0 | U14: =SUM(E26:E29) -> 7 | V14: =SUM(F26:F29) -> 3 | W14: =SUM(G26:G29) -> 0 | X14: =SUM(H26:H29) -> 0 | Y14: =SUM(I26:I29) -> 4 | Z14: =SUM(J26:J29) -> 0 | ... AF14: =SUM(P26:P29) -> 90
B15: 08.15 - 08.30 | C15: 0 | D15: 0 | E15: 1 | F15: 0 | G15: 0 | H15: 0 | I15: 2 | J15: 0 | K15: 0 | L15: 0 | M15: 10 | N15: 0 | O15: =SUM(C15:L15,N15) -> 3 | P15: =SUM(C15:N15) -> 13 | R15: 1200-1300 | S15: =SUM(C30:C33) -> 4 | T15: =SUM(D30:D33) -> 0 | U15: =SUM(E30:E33) -> 4 | V15: =SUM(F30:F33) -> 1 | W15: =SUM(G30:G33) -> 0 | X15: =SUM(H30:H33) -> 0 | Y15: =SUM(I30:I33) -> 4 | Z15: =SUM(J30:J33) -> 0 | ... AF15: =SUM(P30:P33) -> 80
B16: 08.30 - 08.45 | C16: 1 | D16: 0 | E16: 0 | F16: 0 | G16: 0 | H16: 0 | I16: 0 | J16: 0 | K16: 0 | L16: 0 | M16: 13 | N16: 0 | O16: =SUM(C16:L16,N16) -> 1 | P16: =SUM(C16:N16) -> 14 | R16: 1300-1400 | S16: =SUM(C34:C37) -> 6 | T16: =SUM(D34:D37) -> 0 | U16: =SUM(E34:E37) -> 7 | V16: =SUM(F34:F37) -> 0 | W16: =SUM(G34:G37) -> 0 | X16: =SUM(H34:H37) -> 0 | Y16: =SUM(I34:I37) -> 4 | Z16: =SUM(J34:J37) -> 0 | ... AF16: =SUM(P34:P37) -> 62
B17: 08.45 - 9.00 | C17: 0 | D17: 0 | E17: 0 | F17: 0 | G17: 0 | H17: 0 | I17: 0 | J17: 0 | K17: 0 | L17: 0 | M17: 17 | N17: 0 | O17: =SUM(C17:L17,N17) -> 0 | P17: =SUM(C17:N17) -> 17 | R17: 1400-1500 | S17: =SUM(C38:C41) -> 4 | T17: =SUM(D38:D41) -> 0 | U17: =SUM(E38:E41) -> 7 | V17: =SUM(F38:F41) -> 1 | W17: =SUM(G38:G41) -> 0 | X17: =SUM(H38:H41) -> 0 | Y17: =SUM(I38:I41) -> 0 | Z17: =SUM(J38:J41) -> 0 | ... AF17: =SUM(P38:P41) -> 69
B18: 09.00 - 09.15 | C18: 1 | D18: 0 | E18: 0 | F18: 0 | G18: 0 | H18: 0 | I18: 0 | J18: 0 | K18: 0 | L18: 0 | M18: 15 | N18: 0 | O18: =SUM(C18:L18,N18) -> 1 | P18: =SUM(C18:N18) -> 16 | R18: 1500-1600 | S18: =SUM(C42:C45) -> 4 | T18: =SUM(D42:D45) -> 0 | U18: =SUM(E42:E45) -> 4 | V18: =SUM(F42:F45) -> 1 | W18: =SUM(G42:G45) -> 0 | X18: =SUM(H42:H45) -> 0 | Y18: =SUM(I42:I45) -> 4 | Z18: =SUM(J42:J45) -> 0 | ... AF18: =SUM(P42:P45) -> 70
B19: 09.15 - 09.30 | C19: 1 | D19: 0 | E19: 0 | F19: 0 | G19: 0 | H19: 0 | I19: 0 | J19: 0 | K19: 0 | L19: 0 | M19: 16 | N19: 0 | O19: =SUM(C19:L19,N19) -> 1 | P19: =SUM(C19:N19) -> 17 | R19: 1600-1700 | S19: =SUM(C46:C49) -> 7 | T19: =SUM(D46:D49) -> 0 | U19: =SUM(E46:E49) -> 5 | V19: =SUM(F46:F49) -> 1 | W19: =SUM(G46:G49) -> 0 | X19: =SUM(H46:H49) -> 0 | Y19: =SUM(I46:I49) -> 2 | Z19: =SUM(J46:J49) -> 0 | ... AF19: =SUM(P46:P49) -> 71
B20: 09.30 - 09.45 | C20: 2 | D20: 0 | E20: 0 | F20: 1 | G20: 0 | H20: 0 | I20: 3 | J20: 0 | K20: 0 | L20: 0 | M20: 18 | N20: 0 | O20: =SUM(C20:L20,N20) -> 6 | P20: =SUM(C20:N20) -> 24 | R20: 1700-1800 | S20: =SUM(C50:C53) -> 4 | T20: =SUM(D50:D53) -> 0 | U20: =SUM(E50:E53) -> 3 | V20: =SUM(F50:F53) -> 1 | W20: =SUM(G50:G53) -> 0 | X20: =SUM(H50:H53) -> 0 | Y20: =SUM(I50:I53) -> 0 | Z20: =SUM(J50:J53) -> 0 | ... AF20: =SUM(P50:P53) -> 74
B21: 09.45 - 10.00 | C21: 2 | D21: 0 | E21: 0 | F21: 1 | G21: 0 | H21: 0 | I21: 1 | J21: 0 | K21: 0 | L21: 0 | M21: 18 | N21: 0 | O21: =SUM(C21:L21,N21) -> 4 | P21: =SUM(C21:N21) -> 22 | R21: 1800-1900 | S21: =SUM(C54:C57) -> 11 | T21: =SUM(D54:D57) -> 0 | U21: =SUM(E54:E57) -> 4 | V21: =SUM(F54:F57) -> 1 | W21: =SUM(G54:G57) -> 0 | X21: =SUM(H54:H57) -> 0 | Y21: =SUM(I54:I57) -> 2 | Z21: =SUM(J54:J57) -> 0 | ... AF21: =SUM(P54:P57) -> 84
B22: 10.00 - 10.15 | C22: 1 | D22: 0 | E22: 1 | F22: 0 | G22: 0 | H22: 0 | I22: 1 | J22: 0 | K22: 0 | L22: 0 | M22: 22 | N22: 0 | O22: =SUM(C22:L22,N22) -> 3 | P22: =SUM(C22:N22) -> 25 | R22: AM Peak Hr | S22: =MAX(S10:S12) -> 6 | T22: =MAX(T10:T12) -> 0 | U22: =MAX(U10:U12) -> 1 | V22: =MAX(V10:V12) -> 2 | W22: =MAX(W10:W12) -> 0 | X22: =MAX(X10:X12) -> 0 | Y22: =MAX(Y10:Y12) -> 4 | Z22: =MAX(Z10:Z12) -> 0 | ... AF22: =MAX(AF10:AF12) -> 79
B23: 10.15 - 10.30 | C23: 2 | D23: 0 | E23: 1 | F23: 0 | G23: 0 | H23: 0 | I23: 1 | J23: 0 | K23: 0 | L23: 0 | M23: 20 | N23: 0 | O23: =SUM(C23:L23,N23) -> 4 | P23: =SUM(C23:N23) -> 24 | R23: IP Peak Hr | S23: =MAX(S13:S18) -> 6 | T23: =MAX(T13:T18) -> 0 | U23: =MAX(U13:U18) -> 7 | V23: =MAX(V13:V18) -> 3 | W23: =MAX(W13:W18) -> 0 | X23: =MAX(X13:X18) -> 0 | Y23: =MAX(Y13:Y18) -> 6 | Z23: =MAX(Z13:Z18) -> 0 | ... AF23: =MAX(AF13:AF18) -> 92
B24: 10.30 - 10.45 | C24: 1 | D24: 0 | E24: 0 | F24: 0 | G24: 0 | H24: 0 | I24: 3 | J24: 0 | K24: 0 | L24: 0 | M24: 19 | N24: 0 | O24: =SUM(C24:L24,N24) -> 4 | P24: =SUM(C24:N24) -> 23 | R24: PM Peak Hr | S24: =MAX(S19:S21) -> 11 | T24: =MAX(T19:T21) -> 0 | U24: =MAX(U19:U21) -> 5 | V24: =MAX(V19:V21) -> 1 | W24: =MAX(W19:W21) -> 0 | X24: =MAX(X19:X21) -> 0 | Y24: =MAX(Y19:Y21) -> 2 | Z24: =MAX(Z19:Z21) -> 0 | ... AF24: =MAX(AF19:AF21) -> 84
B25: 10.45 - 11.00 | C25: 0 | D25: 0 | E25: 3 | F25: 0 | G25: 0 | H25: 0 | I25: 1 | J25: 0 | K25: 0 | L25: 0 | M25: 16 | N25: 0 | O25: =SUM(C25:L25,N25) -> 4 | P25: =SUM(C25:N25) -> 20 | R25: AM Period | S25: =SUM(S10:S12) -> 10 | T25: =SUM(T10:T12) -> 0 | U25: =SUM(U10:U12) -> 1 | V25: =SUM(V10:V12) -> 4 | W25: =SUM(W10:W12) -> 0 | X25: =SUM(X10:X12) -> 0 | Y25: =SUM(Y10:Y12) -> 7 | Z25: =SUM(Z10:Z12) -> 0 | ... AF25: =SUM(AF10:AF12) -> 171
B26: 11.00 - 11.15 | C26: 0 | D26: 0 | E26: 0 | F26: 2 | G26: 0 | H26: 0 | I26: 0 | J26: 0 | K26: 0 | L26: 0 | M26: 17 | N26: 0 | O26: =SUM(C26:L26,N26) -> 2 | P26: =SUM(C26:N26) -> 19 | R26: IP Period | S26: =SUM(S13:S18) -> 28 | T26: =SUM(T13:T18) -> 0 | U26: =SUM(U13:U18) -> 34 | V26: =SUM(V13:V18) -> 6 | W26: =SUM(W13:W18) -> 0 | X26: =SUM(X13:X18) -> 0 | Y26: =SUM(Y13:Y18) -> 22 | Z26: =SUM(Z13:Z18) -> 0 | ... AF26: =SUM(AF13:AF18) -> 463
B27: 11.15 - 11.30 | C27: 3 | D27: 0 | E27: 3 | F27: 0 | G27: 0 | H27: 0 | I27: 0 | J27: 0 | K27: 0 | L27: 0 | M27: 21 | N27: 0 | O27: =SUM(C27:L27,N27) -> 6 | P27: =SUM(C27:N27) -> 27 | R27: PM Period | S27: =SUM(S19:S21) -> 22 | T27: =SUM(T19:T21) -> 0 | U27: =SUM(U19:U21) -> 12 | V27: =SUM(V19:V21) -> 3 | W27: =SUM(W19:W21) -> 0 | X27: =SUM(X19:X21) -> 0 | Y27: =SUM(Y19:Y21) -> 4 | Z27: =SUM(Z19:Z21) -> 0 | ... AF27: =SUM(AF19:AF21) -> 229
B28: 11.30 - 11.45 | C28: 2 | D28: 0 | E28: 1 | F28: 0 | G28: 0 | H28: 0 | I28: 3 | J28: 0 | K28: 0 | L28: 0 | M28: 17 | N28: 0 | O28: =SUM(C28:L28,N28) -> 6 | P28: =SUM(C28:N28) -> 23 | R28: 12 Hours | S28: =SUM(S10:S21) -> 60 | T28: =SUM(T10:T21) -> 0 | U28: =SUM(U10:U21) -> 47 | V28: =SUM(V10:V21) -> 13 | W28: =SUM(W10:W21) -> 0 | X28: =SUM(X10:X21) -> 0 | Y28: =SUM(Y10:Y21) -> 33 | Z28: =SUM(Z10:Z21) -> 0 | ... AF28: =SUM(AF10:AF21) -> 863
B29: 11.45 - 12.00 | C29: 1 | D29: 0 | E29: 3 | F29: 1 | G29: 0 | H29: 0 | I29: 1 | J29: 0 | K29: 0 | L29: 0 | M29: 15 | N29: 0 | O29: =SUM(C29:L29,N29) -> 6 | P29: =SUM(C29:N29) -> 21
B30: 12.00 - 12.15 | C30: 0 | D30: 0 | E30: 0 | F30: 0 | G30: 0 | H30: 0 | I30: 2 | J30: 0 | K30: 0 | L30: 0 | M30: 19 | N30: 0 | O30: =SUM(C30:L30,N30) -> 2 | P30: =SUM(C30:N30) -> 21
B31: 12.15 - 12.30 | C31: 2 | D31: 0 | E31: 1 | F31: 1 | G31: 0 | H31: 0 | I31: 1 | J31: 0 | K31: 0 | L31: 0 | M31: 15 | N31: 0 | O31: =SUM(C31:L31,N31) -> 5 | P31: =SUM(C31:N31) -> 20
B32: 12.30 - 12.45 | C32: 1 | D32: 0 | E32: 0 | F32: 0 | G32: 0 | H32: 0 | I32: 0 | J32: 0 | K32: 0 | L32: 0 | M32: 16 | N32: 0 | O32: =SUM(C32:L32,N32) -> 1 | P32: =SUM(C32:N32) -> 17
B33: 12.45 - 13.00 | C33: 1 | D33: 0 | E33: 3 | F33: 0 | G33: 0 | H33: 0 | I33: 1 | J33: 0 | K33: 0 | L33: 0 | M33: 17 | N33: 0 | O33: =SUM(C33:L33,N33) -> 5 | P33: =SUM(C33:N33) -> 22
B34: 13.00 - 13.15 | C34: 3 | D34: 0 | E34: 1 | F34: 0 | G34: 0 | H34: 0 | I34: 2 | J34: 0 | K34: 0 | L34: 0 | M34: 19 | N34: 0 | O34: =SUM(C34:L34,N34) -> 6 | P34: =SUM(C34:N34) -> 25
B35: 13.15 - 13.30 | C35: 1 | D35: 0 | E35: 3 | F35: 0 | G35: 0 | H35: 0 | I35: 0 | J35: 0 | K35: 0 | L35: 0 | M35: 15 | N35: 0 | O35: =SUM(C35:L35,N35) -> 4 | P35: =SUM(C35:N35) -> 19
B36: 13.30 - 13.45 | C36: 0 | D36: 0 | E36: 1 | F36: 0 | G36: 0 | H36: 0 | I36: 1 | J36: 0 | K36: 0 | L36: 0 | M36: 1 | N36: 0 | O36: =SUM(C36:L36,N36) -> 2 | P36: =SUM(C36:N36) -> 3
B37: 13.45 - 14.00 | C37: 2 | D37: 0 | E37: 2 | F37: 0 | G37: 0 | H37: 0 | I37: 1 | J37: 0 | K37: 0 | L37: 0 | M37: 10 | N37: 0 | O37: =SUM(C37:L37,N37) -> 5 | P37: =SUM(C37:N37) -> 15
B38: 14.00 - 14.15 | C38: 2 | D38: 0 | E38: 1 | F38: 0 | G38: 0 | H38: 0 | I38: 0 | J38: 0 | K38: 0 | L38: 0 | M38: 20 | N38: 0 | O38: =SUM(C38:L38,N38) -> 3 | P38: =SUM(C38:N38) -> 23
B39: 14.15 - 14.30 | C39: 0 | D39: 0 | E39: 3 | F39: 0 | G39: 0 | H39: 0 | I39: 0 | J39: 0 | K39: 0 | L39: 0 | M39: 11 | N39: 0 | O39: =SUM(C39:L39,N39) -> 3 | P39: =SUM(C39:N39) -> 14
B40: 14.30 - 14.45 | C40: 1 | D40: 0 | E40: 2 | F40: 1 | G40: 0 | H40: 0 | I40: 0 | J40: 0 | K40: 0 | L40: 0 | M40: 9 | N40: 0 | O40: =SUM(C40:L40,N40) -> 4 | P40: =SUM(C40:N40) -> 13
... B57: 18.45 - 19.00 | C57: 4 | D57: 0 | E57: 0 | F57: 0 | G57: 0 | H57: 0 | I57: 0 | J57: 0 | K57: 0 | L57: 0 | M57: 17 | N57: 0 | O57: =SUM(C57:L57,N57) -> 4 | P57: =SUM(C57:N57) -> 21
B58: Totals | C58: =SUM(C10:C57) -> 60 | D58: =SUM(D10:D57) -> 0 | E58: =SUM(E10:E57) -> 47 | F58: =SUM(F10:F57) -> 13 | G58: =SUM(G10:G57) -> 0 | H58: =SUM(H10:H57) -> 0 | I58: =SUM(I10:I57) -> 33 | J58: =SUM(J10:J57) -> 0 | ... P58: =SUM(P10:P57) -> 863
...

Sheet 12.08 BUSUNJU-KAMPALA
B1: Consultancy services for Preparation of Expressway Development Master Plan (EDMP) for Uganda
B2: MANUAL CLASSIFIED COUNT (MCC)
B3: ROAD NAME: | C3: ='11.08 BUSUNJU-KAMPALA'!C3:G3 -> MCC - C3 - STN85 - HOIMA ROAD
C5: Date | D5: 12.08.19 | F5: Location | G5: ='11.08 BUSUNJU-KAMPALA'!G5:H5 -> MATTE | J5: Surveyor | K5: ='11.08 BUSUNJU-KAMPALA'!K5:L5 -> xxx
C6: Dir. From | D6: ='11.08 BUSUNJU-KAMPALA'!D6:E6 -> BUSUNJU | F6: Dir. To | G6: ='11.08 BUSUNJU-KAMPALA'!G6:H6 -> KAMPALA | J6: Supervisor | K6: ='11.08 BUSUNJU-KAMPALA'!K6:L6 -> xxx
B8: Time / Veh Type | R8: SUMMARY TRAFFIC VOLUMES
C9: 1. Car | D9: 2. Station Wagon | E9: 3. Pickups | F9: 4. Minibus, matatu | G9: 5. Medium bus | H9: 6. Large Bus | I9: 7. Light Truck | J9: 8. Medium Truck | K9: 9. Heavy truck | L9: 10. Truck Trailer | M9: 11. Motor cycles | N9: 12. Tractors | O9: Total Excl M/Cycles | P9: Total All | R9: Time | S9: 1. Car | T9: 2. Station Wagon | U9: 3. Pickups | V9: 4. Minibus, matatu | W9: 5. Medium bus | X9: 6. Large Bus | Y9: 7. Light Truck | Z9: 8. Medium Truck | AA9: 9. Heavy truck | AB9: 10. Truck Trailer | AC9: 11. Motorcycles | AD9: 12. Tractors, Graders | AE9: Total Excl M/ Cycles | AF9: Total All
B10: 07.00 - 07.15 | C10: 4 | D10: 0 | E10: 0 | F10: 0 | G10: 0 | H10: 0 | I10: 0 | J10: 0 | K10: 0 | L10: 0 | M10: 8 | N10: 0 | O10: =SUM(C10:L10,N10) -> 4 | P10: =SUM(C10:N10) -> 12 | R10: 0700-0800 | S10: =SUM(C10:C13) -> 7 | T10: =SUM(D10:D13) -> 0 | U10: =SUM(E10:E13) -> 1 | V10: =SUM(F10:F13) -> 2 | W10: =SUM(G10:G13) -> 0 | X10: =SUM(H10:H13) -> 0 | Y10: =SUM(I10:I13) -> 1 | Z10: =SUM(J10:J13) -> 0 | ... AF10: =SUM(P10:P13) -> 57
B11: 07.15 - 07.30 | C11: 1 | D11: 0 | E11: 0 | F11: 1 | G11: 0 | H11: 0 | I11: 0 | J11: 0 | K11: 0 | L11: 0 | M11: 9 | N11: 0 | O11: =SUM(C11:L11,N11) -> 2 | P11: =SUM(C11:N11) -> 11 | R11: 0800-0900 | S11: =SUM(C14:C17) -> 3 | T11: =SUM(D14:D17) -> 0 | U11: =SUM(E14:E17) -> 3 | V11: =SUM(F14:F17) -> 2 | W11: =SUM(G14:G17) -> 0 | X11: =SUM(H14:H17) -> 0 | Y11: =SUM(I14:I17) -> 3 | Z11: =SUM(J14:J17) -> 0 | ... AF11: =SUM(P14:P17) -> 77
B12: 07.30 - 07.45 | C12: 0 | D12: 0 | E12: 0 | F12: 1 | G12: 0 | H12: 0 | I12: 0 | J12: 0 | K12: 0 | L12: 0 | M12: 15 | N12: 0 | O12: =SUM(C12:L12,N12) -> 1 | P12: =SUM(C12:N12) -> 16 | R12: 0900-1000 | S12: =SUM(C18:C21) -> 0 | T12: =SUM(D18:D21) -> 0 | U12: =SUM(E18:E21) -> 3 | V12: =SUM(F18:F21) -> 0 | W12: =SUM(G18:G21) -> 0 | X12: =SUM(H18:H21) -> 0 | Y12: =SUM(I18:I21) -> 2 | Z12: =SUM(J18:J21) -> 0 | ... AF12: =SUM(P18:P21) -> 55
B13: 07.45 - 08.00 | C13: 2 | D13: 0 | E13: 1 | F13: 0 | G13: 0 | H13: 0 | I13: 1 | J13: 0 | K13: 0 | L13: 0 | M13: 14 | N13: 0 | O13: =SUM(C13:L13,N13) -> 4 | P13: =SUM(C13:N13) -> 18 | R13: 1000-1100 | S13: =SUM(C22:C25) -> 1 | T13: =SUM(D22:D25) -> 0 | U13: =SUM(E22:E25) -> 5 | V13: =SUM(F22:F25) -> 1 | W13: =SUM(G22:G25) -> 0 | X13: =SUM(H22:H25) -> 0 | Y13: =SUM(I22:I25) -> 6 | Z13: =SUM(J22:J25) -> 0 | ... AF13: =SUM(P22:P25) -> 75
B14: 08.00 - 08.15 | C14: 0 | D14: 0 | E14: 1 | F14: 0 | G14: 0 | H14: 0 | I14: 0 | J14: 0 | K14: 0 | L14: 0 | M14: 17 | N14: 0 | O14: =SUM(C14:L14,N14) -> 1 | P14: =SUM(C14:N14) -> 18 | R14: 1100-1200 | S14: =SUM(C26:C29) -> 3 | T14: =SUM(D26:D29) -> 0 | U14: =SUM(E26:E29) -> 4 | V14: =SUM(F26:F29) -> 1 | W14: =SUM(G26:G29) -> 0 | X14: =SUM(H26:H29) -> 0 | Y14: =SUM(I26:I29) -> 5 | Z14: =SUM(J26:J29) -> 0 | ... AF14: =SUM(P26:P29) -> 60
B15: 08.15 - 08.30 | C15: 1 | D15: 0 | E15: 1 | F15: 0 | G15: 0 | H15: 0 | I15: 0 | J15: 0 | K15: 0 | L15: 0 | M15: 15 | N15: 0 | O15: =SUM(C15:L15,N15) -> 2 | P15: =SUM(C15:N15) -> 17 | R15: 1200-1300 | S15: =SUM(C30:C33) -> 5 | T15: =SUM(D30:D33) -> 0 | U15: =SUM(E30:E33) -> 1 | V15: =SUM(F30:F33) -> 2 | W15: =SUM(G30:G33) -> 0 | X15: =SUM(H30:H33) -> 0 | Y15: =SUM(I30:I33) -> 2 | Z15: =SUM(J30:J33) -> 0 | ... AF15: =SUM(P30:P33) -> 70
B16: 08.30 - 08.45 | C16: 0 | D16: 0 | E16: 1 | F16: 1 | G16: 0 | H16: 0 | I16: 2 | J16: 0 | K16: 0 | L16: 0 | M16: 15 | N16: 0 | O16: =SUM(C16:L16,N16) -> 4 | P16: =SUM(C16:N16) -> 19 | R16: 1300-1400 | S16: =SUM(C34:C37) -> 5 | T16: =SUM(D34:D37) -> 0 | U16: =SUM(E34:E37) -> 4 | V16: =SUM(F34:F37) -> 2 | W16: =SUM(G34:G37) -> 0 | X16: =SUM(H34:H37) -> 0 | Y16: =SUM(I34:I37) -> 4 | Z16: =SUM(J34:J37) -> 1 | ... AF16: =SUM(P34:P37) -> 80
B17: 08.45 - 9.00 | C17: 2 | D17: 0 | E17: 0 | F17: 1 | G17: 0 | H17: 0 | I17: 1 | J17: 0 | K17: 0 | L17: 0 | M17: 19 | N17: 0 | O17: =SUM(C17:L17,N17) -> 4 | P17: =SUM(C17:N17) -> 23 | R17: 1400-1500 | S17: =SUM(C38:C41) -> 6 | T17: =SUM(D38:D41) -> 0 | U17: =SUM(E38:E41) -> 1 | V17: =SUM(F38:F41) -> 1 | W17: =SUM(G38:G41) -> 0 | X17: =SUM(H38:H41) -> 0 | Y17: =SUM(I38:I41) -> 3 | Z17: =SUM(J38:J41) -> 0 | ... AF17: =SUM(P38:P41) -> 57
B18: 09.00 - 09.15 | C18: 0 | D18: 0 | E18: 1 | F18: 0 | G18: 0 | H18: 0 | I18: 0 | J18: 0 | K18: 0 | L18: 0 | M18: 15 | N18: 0 | O18: =SUM(C18:L18,N18) -> 1 | P18: =SUM(C18:N18) -> 16 | R18: 1500-1600 | S18: =SUM(C42:C45) -> 1 | T18: =SUM(D42:D45) -> 0 | U18: =SUM(E42:E45) -> 1 | V18: =SUM(F42:F45) -> 0 | W18: =SUM(G42:G45) -> 0 | X18: =SUM(H42:H45) -> 0 | Y18: =SUM(I42:I45) -> 7 | Z18: =SUM(J42:J45) -> 0 | ... AF18: =SUM(P42:P45) -> 56
B19: 09.15 - 09.30 | C19: 0 | D19: 0 | E19: 1 | F19: 0 | G19: 0 | H19: 0 | I19: 0 | J19: 0 | K19: 0 | L19: 0 | M19: 12 | N19: 0 | O19: =SUM(C19:L19,N19) -> 1 | P19: =SUM(C19:N19) -> 13 | R19: 1600-1700 | S19: =SUM(C46:C49) -> 5 | T19: =SUM(D46:D49) -> 0 | U19: =SUM(E46:E49) -> 4 | V19: =SUM(F46:F49) -> 1 | W19: =SUM(G46:G49) -> 0 | X19: =SUM(H46:H49) -> 0 | Y19: =SUM(I46:I49) -> 6 | Z19: =SUM(J46:J49) -> 0 | ... AF19: =SUM(P46:P49) -> 69
B20: 09.30 - 09.45 | C20: 0 | D20: 0 | E20: 1 | F20: 0 | G20: 0 | H20: 0 | I20: 2 | J20: 0 | K20: 0 | L20: 0 | M20: 10 | N20: 0 | O20: =SUM(C20:L20,N20) -> 3 | P20: =SUM(C20:N20) -> 13 | R20: 1700-1800 | S20: =SUM(C50:C53) -> 3 | T20: =SUM(D50:D53) -> 0 | U20: =SUM(E50:E53) -> 6 | V20: =SUM(F50:F53) -> 3 | W20: =SUM(G50:G53) -> 0 | X20: =SUM(H50:H53) -> 0 | Y20: =SUM(I50:I53) -> 8 | Z20: =SUM(J50:J53) -> 0 | ... AF20: =SUM(P50:P53) -> 69
B21: 09.45 - 10.00 | C21: 0 | D21: 0 | E21: 0 | F21: 0 | G21: 0 | H21: 0 | I21: 0 | J21: 0 | K21: 0 | L21: 0 | M21: 13 | N21: 0 | O21: =SUM(C21:L21,N21) -> 0 | P21: =SUM(C21:N21) -> 13 | R21: 1800-1900 | S21: =SUM(C54:C57) -> 0 | T21: =SUM(D54:D57) -> 0 | U21: =SUM(E54:E57) -> 4 | V21: =SUM(F54:F57) -> 1 | W21: =SUM(G54:G57) -> 1 | X21: =SUM(H54:H57) -> 0 | Y21: =SUM(I54:I57) -> 1 | Z21: =SUM(J54:J57) -> 0 | ... AF21: =SUM(P54:P57) -> 45
B22: 10.00 - 10.15 | C22: 0 | D22: 0 | E22: 0 | F22: 1 | G22: 0 | H22: 0 | I22: 1 | J22: 0 | K22: 0 | L22: 0 | M22: 13 | N22: 0 | O22: =SUM(C22:L22,N22) -> 2 | P22: =SUM(C22:N22) -> 15 | R22: AM Peak Hr | S22: =MAX(S10:S12) -> 7 | T22: =MAX(T10:T12) -> 0 | U22: =MAX(U10:U12) -> 3 | V22: =MAX(V10:V12) -> 2 | W22: =MAX(W10:W12) -> 0 | X22: =MAX(X10:X12) -> 0 | Y22: =MAX(Y10:Y12) -> 3 | Z22: =MAX(Z10:Z12) -> 0 | ... AF22: =MAX(AF10:AF12) -> 77
B23: 10.15 - 10.30 | C23: 0 | D23: 0 | E23: 3 | F23: 0 | G23: 0 | H23: 0 | I23: 2 | J23: 0 | K23: 0 | L23: 0 | M23: 20 | N23: 0 | O23: =SUM(C23:L23,N23) -> 5 | P23: =SUM(C23:N23) -> 25 | R23: IP Peak Hr | S23: =MAX(S13:S18) -> 6 | T23: =MAX(T13:T18) -> 0 | U23: =MAX(U13:U18) -> 5 | V23: =MAX(V13:V18) -> 2 | W23: =MAX(W13:W18) -> 0 | X23: =MAX(X13:X18) -> 0 | Y23: =MAX(Y13:Y18) -> 7 | Z23: =MAX(Z13:Z18) -> 1 | ... AF23: =MAX(AF13:AF18) -> 80
B24: 10.30 - 10.45 | C24: 1 | D24: 0 | E24: 2 | F24: 0 | G24: 0 | H24: 0 | I24: 1 | J24: 0 | K24: 0 | L24: 0 | M24: 9 | N24: 0 | O24: =SUM(C24:L24,N24) -> 4 | P24: =SUM(C24:N24) -> 13 | R24: PM Peak Hr | S24: =MAX(S19:S21) -> 5 | T24: =MAX(T19:T21) -> 0 | U24: =MAX(U19:U21) -> 6 | V24: =MAX(V19:V21) -> 3 | W24: =MAX(W19:W21) -> 1 | X24: =MAX(X19:X21) -> 0 | Y24: =MAX(Y19:Y21) -> 8 | Z24: =MAX(Z19:Z21) -> 0 | ... AF24: =MAX(AF19:AF21) -> 69
B25: 10.45 - 11.00 | C25: 0 | D25: 0 | E25: 0 | F25: 0 | G25: 0 | H25: 0 | I25: 2 | J25: 0 | K25: 0 | L25: 0 | M25: 20 | N25: 0 | O25: =SUM(C25:L25,N25) -> 2 | P25: =SUM(C25:N25) -> 22 | R25: AM Period | S25: =SUM(S10:S12) -> 10 | T25: =SUM(T10:T12) -> 0 | U25: =SUM(U10:U12) -> 7 | V25: =SUM(V10:V12) -> 4 | W25: =SUM(W10:W12) -> 0 | X25: =SUM(X10:X12) -> 0 | Y25: =SUM(Y10:Y12) -> 6 | Z25: =SUM(Z10:Z12) -> 0 | ... AF25: =SUM(AF10:AF12) -> 189
B26: 11.00 - 11.15 | C26: 2 | D26: 0 | E26: 2 | F26: 1 | G26: 0 | H26: 0 | I26: 1 | J26: 0 | K26: 0 | L26: 0 | M26: 15 | N26: 0 | O26: =SUM(C26:L26,N26) -> 6 | P26: =SUM(C26:N26) -> 21 | R26: IP Period | S26: =SUM(S13:S18) -> 21 | T26: =SUM(T13:T18) -> 0 | U26: =SUM(U13:U18) -> 16 | V26: =SUM(V13:V18) -> 7 | W26: =SUM(W13:W18) -> 0 | X26: =SUM(X13:X18) -> 0 | Y26: =SUM(Y13:Y18) -> 27 | Z26: =SUM(Z13:Z18) -> 1 | ... AF26: =SUM(AF13:AF18) -> 398
B27: 11.15 - 11.30 | C27: 0 | D27: 0 | E27: 1 | F27: 0 | G27: 0 | H27: 0 | I27: 1 | J27: 0 | K27: 0 | L27: 0 | M27: 10 | N27: 0 | O27: =SUM(C27:L27,N27) -> 2 | P27: =SUM(C27:N27) -> 12 | R27: PM Period | S27: =SUM(S19:S21) -> 8 | T27: =SUM(T19:T21) -> 0 | U27: =SUM(U19:U21) -> 14 | V27: =SUM(V19:V21) -> 5 | W27: =SUM(W19:W21) -> 1 | X27: =SUM(X19:X21) -> 0 | Y27: =SUM(Y19:Y21) -> 15 | Z27: =SUM(Z19:Z21) -> 0 | ... AF27: =SUM(AF19:AF21) -> 183
B28: 11.30 - 11.45 | C28: 1 | D28: 0 | E28: 0 | F28: 0 | G28: 0 | H28: 0 | I28: 1 | J28: 0 | K28: 0 | L28: 0 | M28: 8 | N28: 0 | O28: =SUM(C28:L28,N28) -> 2 | P28: =SUM(C28:N28) -> 10 | R28: 12 Hours | S28: =SUM(S10:S21) -> 39 | T28: =SUM(T10:T21) -> 0 | U28: =SUM(U10:U21) -> 37 | V28: =SUM(V10:V21) -> 16 | W28: =SUM(W10:W21) -> 1 | X28: =SUM(X10:X21) -> 0 | Y28: =SUM(Y10:Y21) -> 48 | Z28: =SUM(Z10:Z21) -> 1 | ... AF28: =SUM(AF10:AF21) -> 770
B29: 11.45 - 12.00 | C29: 0 | D29: 0 | E29: 1 | F29: 0 | G29: 0 | H29: 0 | I29: 2 | J29: 0 | K29: 0 | L29: 0 | M29: 14 | N29: 0 | O29: =SUM(C29:L29,N29) -> 3 | P29: =SUM(C29:N29) -> 17
B30: 12.00 - 12.15 | C30: 3 | D30: 0 | E30: 1 | F30: 1 | G30: 0 | H30: 0 | I30: 0 | J30: 0 | K30: 0 | L30: 0 | M30: 21 | N30: 0 | O30: =SUM(C30:L30,N30) -> 5 | P30: =SUM(C30:N30) -> 26
B31: 12.15 - 12.30 | C31: 0 | D31: 0 | E31: 0 | F31: 0 | G31: 0 | H31: 0 | I31: 1 | J31: 0 | K31: 0 | L31: 0 | M31: 16 | N31: 0 | O31: =SUM(C31:L31,N31) -> 1 | P31: =SUM(C31:N31) -> 17
B32: 12.30 - 12.45 | C32: 2 | D32: 0 | E32: 0 | F32: 0 | G32: 0 | H32: 0 | I32: 0 | J32: 0 | K32: 0 | L32: 0 | M32: 11 | N32: 0 | O32: =SUM(C32:L32,N32) -> 2 | P32: =SUM(C32:N32) -> 13
B33: 12.45 - 13.00 | C33: 0 | D33: 0 | E33: 0 | F33: 1 | G33: 0 | H33: 0 | I33: 1 | J33: 0 | K33: 0 | L33: 0 | M33: 12 | N33: 0 | O33: =SUM(C33:L33,N33) -> 2 | P33: =SUM(C33:N33) -> 14
B34: 13.00 - 13.15 | C34: 2 | D34: 0 | E34: 2 | F34: 0 | G34: 0 | H34: 0 | I34: 0 | J34: 1 | K34: 0 | L34: 0 | M34: 20 | N34: 0 | O34: =SUM(C34:L34,N34) -> 5 | P34: =SUM(C34:N34) -> 25
B35: 13.15 - 13.30 | C35: 0 | D35: 0 | E35: 0 | F35: 2 | G35: 0 | H35: 0 | I35: 3 | J35: 0 | K35: 0 | L35: 0 | M35: 14 | N35: 0 | O35: =SUM(C35:L35,N35) -> 5 | P35: =SUM(C35:N35) -> 19
B36: 13.30 - 13.45 | C36: 3 | D36: 0 | E36: 1 | F36: 0 | G36: 0 | H36: 0 | I36: 0 | J36: 0 | K36: 0 | L36: 0 | M36: 16 | N36: 0 | O36: =SUM(C36:L36,N36) -> 4 | P36: =SUM(C36:N36) -> 20
B37: 13.45 - 14.00 | C37: 0 | D37: 0 | E37: 1 | F37: 0 | G37: 0 | H37: 0 | I37: 1 | J37: 0 | K37: 0 | L37: 0 | M37: 14 | N37: 0 | O37: =SUM(C37:L37,N37) -> 2 | P37: =SUM(C37:N37) -> 16
B38: 14.00 - 14.15 | C38: 0 | D38: 0 | E38: 0 | F38: 1 | G38: 0 | H38: 0 | I38: 0 | J38: 0 | K38: 0 | L38: 0 | M38: 11 | N38: 0 | O38: =SUM(C38:L38,N38) -> 1 | P38: =SUM(C38:N38) -> 12
B39: 14.15 - 14.30 | C39: 2 | D39: 0 | E39: 0 | F39: 0 | G39: 0 | H39: 0 | I39: 1 | J39: 0 | K39: 0 | L39: 0 | M39: 17 | N39: 0 | O39: =SUM(C39:L39,N39) -> 3 | P39: =SUM(C39:N39) -> 20
B40: 14.30 - 14.45 | C40: 1 | D40: 0 | E40: 0 | F40: 0 | G40: 0 | H40: 0 | I40: 0 | J40: 0 | K40: 0 | L40: 0 | M40: 8 | N40: 0 | O40: =SUM(C40:L40,N40) -> 1 | P40: =SUM(C40:N40) -> 9
... B57: 18.45 - 19.00 | C57: 0 | D57: 0 | E57: 0 | F57: 0 | G57: 0 | H57: 0 | I57: 0 | J57: 0 | K57: 0 | L57: 0 | M57: 0 | N57: 0 | O57: =SUM(C57:L57,N57) -> 0 | P57: =SUM(C57:N57) -> 0
B58: Totals | C58: =SUM(C10:C57) -> 39 | D58: =SUM(D10:D57) -> 0 | E58: =SUM(E10:E57) -> 37 | F58: =SUM(F10:F57) -> 16 | G58: =SUM(G10:G57) -> 1 | H58: =SUM(H10:H57) -> 0 | I58: =SUM(I10:I57) -> 48 | J58: =SUM(J10:J57) -> 1 | ... P58: =SUM(P10:P57) -> 770
...

Sheet 12.08 KAMPALA-BUSUNJU
B1: Consultancy services for Preparation of Expressway Development Master Plan (EDMP) for Uganda
B2: MANUAL CLASSIFIED COUNT (MCC)
B3: ROAD NAME: | C3: ='11.08 KAMPALA-BUSUNJU'!C3:G3 -> MCC - C3 - STN85 - HOIMA ROAD
C5: Date | D5: ='12.08 BUSUNJU-KAMPALA'!D5 -> 12.08.19 | F5: Location | G5: ='11.08 BUSUNJU-KAMPALA'!G5:H5 -> MATTE | J5: Surveyor | K5: ='11.08 BUSUNJU-KAMPALA'!K5:L5 -> xxx
C6: Dir. From | D6: ='11.08 KAMPALA-BUSUNJU'!D6:E6 -> KAMPALA | F6: Dir. To | G6: ='11.08 KAMPALA-BUSUNJU'!G6:H6 -> BUSUNJU | J6: Supervisor | K6: ='11.08 BUSUNJU-KAMPALA'!K6:L6 -> xxx
B8: Time / Veh Type | R8: SUMMARY TRAFFIC VOLUMES
C9: 1. Car | D9: 2. Station Wagon | E9: 3. Pickups | F9: 4. Minibus, matatu | G9: 5. Medium bus | H9: 6. Large Bus | I9: 7. Light Truck | J9: 8. Medium Truck | K9: 9. Heavy truck | L9: 10. Truck Trailer | M9: 11. Motor cycles | N9: 12. Tractors | O9: Total Excl M/Cycles | P9: Total All | R9: Time | S9: 1. Car | T9: 2. Station Wagon | U9: 3. Pickups | V9: 4. Minibus, matatu | W9: 5. Medium bus | X9: 6. Large Bus | Y9: 7. Light Truck | Z9: 8. Medium Truck | AA9: 9. Heavy truck | AB9: 10. Truck Trailer | AC9: 11. Motorcycles | AD9: 12. Tractors, Graders | AE9: Total Excl M/ Cycles | AF9: Total All
B10: 07.00 - 07.15 | C10: 0 | D10: 0 | E10: 0 | F10: 0 | G10: 0 | H10: 0 | I10: 2 | J10: 0 | K10: 0 | L10: 0 | M10: 11 | N10: 0 | O10: =SUM(C10:L10,N10) -> 2 | P10: =SUM(C10:N10) -> 13 | R10: 0700-0800 | S10: =SUM(C10:C13) -> 2 | T10: =SUM(D10:D13) -> 0 | U10: =SUM(E10:E13) -> 0 | V10: =SUM(F10:F13) -> 2 | W10: =SUM(G10:G13) -> 0 | X10: =SUM(H10:H13) -> 0 | Y10: =SUM(I10:I13) -> 4 | Z10: =SUM(J10:J13) -> 0 | ... AF10: =SUM(P10:P13) -> 57
B11: 07.15 - 07.30 | C11: 0 | D11: 0 | E11: 0 | F11: 1 | G11: 0 | H11: 0 | I11: 0 | J11: 0 | K11: 0 | L11: 0 | M11: 12 | N11: 0 | O11: =SUM(C11:L11,N11) -> 1 | P11: =SUM(C11:N11) -> 13 | R11: 0800-0900 | S11: =SUM(C14:C17) -> 2 | T11: =SUM(D14:D17) -> 0 | U11: =SUM(E14:E17) -> 1 | V11: =SUM(F14:F17) -> 1 | W11: =SUM(G14:G17) -> 0 | X11: =SUM(H14:H17) -> 0 | Y11: =SUM(I14:I17) -> 3 | Z11: =SUM(J14:J17) -> 0 | ... AF11: =SUM(P14:P17) -> 56
B12: 07.30 - 07.45 | C12: 0 | D12: 0 | E12: 0 | F12: 0 | G12: 0 | H12: 0 | I12: 1 | J12: 0 | K12: 0 | L12: 0 | M12: 12 | N12: 0 | O12: =SUM(C12:L12,N12) -> 1 | P12: =SUM(C12:N12) -> 13 | R12: 0900-1000 | S12: =SUM(C18:C21) -> 0 | T12: =SUM(D18:D21) -> 0 | U12: =SUM(E18:E21) -> 1 | V12: =SUM(F18:F21) -> 1 | W12: =SUM(G18:G21) -> 0 | X12: =SUM(H18:H21) -> 0 | Y12: =SUM(I18:I21) -> 4 | Z12: =SUM(J18:J21) -> 0 | ... AF12: =SUM(P18:P21) -> 51
B13: 07.45 - 08.00 | C13: 2 | D13: 0 | E13: 0 | F13: 1 | G13: 0 | H13: 0 | I13: 1 | J13: 0 | K13: 0 | L13: 0 | M13: 14 | N13: 0 | O13: =SUM(C13:L13,N13) -> 4 | P13: =SUM(C13:N13) -> 18 | R13: 1000-1100 | S13: =SUM(C22:C25) -> 2 | T13: =SUM(D22:D25) -> 0 | U13: =SUM(E22:E25) -> 2 | V13: =SUM(F22:F25) -> 0 | W13: =SUM(G22:G25) -> 0 | X13: =SUM(H22:H25) -> 0 | Y13: =SUM(I22:I25) -> 4 | Z13: =SUM(J22:J25) -> 0 | ... AF13: =SUM(P22:P25) -> 66
B14: 08.00 - 08.15 | C14: 0 | D14: 0 | E14: 0 | F14: 0 | G14: 0 | H14: 0 | I14: 2 | J14: 0 | K14: 0 | L14: 0 | M14: 12 | N14: 0 | O14: =SUM(C14:L14,N14) -> 2 | P14: =SUM(C14:N14) -> 14 | R14: 1100-1200 | S14: =SUM(C26:C29) -> 9 | T14: =SUM(D26:D29) -> 0 | U14: =SUM(E26:E29) -> 11 | V14: =SUM(F26:F29) -> 1 | W14: =SUM(G26:G29) -> 0 | X14: =SUM(H26:H29) -> 0 | Y14: =SUM(I26:I29) -> 1 | Z14: =SUM(J26:J29) -> 0 | ... AF14: =SUM(P26:P29) -> 69
B15: 08.15 - 08.30 | C15: 1 | D15: 0 | E15: 1 | F15: 0 | G15: 0 | H15: 0 | I15: 0 | J15: 0 | K15: 0 | L15: 0 | M15: 12 | N15: 0 | O15: =SUM(C15:L15,N15) -> 2 | P15: =SUM(C15:N15) -> 14 | R15: 1200-1300 | S15: =SUM(C30:C33) -> 3 | T15: =SUM(D30:D33) -> 0 | U15: =SUM(E30:E33) -> 5 | V15: =SUM(F30:F33) -> 2 | W15: =SUM(G30:G33) -> 0 | X15: =SUM(H30:H33) -> 0 | Y15: =SUM(I30:I33) -> 4 | Z15: =SUM(J30:J33) -> 1 | ... AF15: =SUM(P30:P33) -> 64
B16: 08.30 - 08.45 | C16: 1 | D16: 0 | E16: 0 | F16: 1 | G16: 0 | H16: 0 | I16: 0 | J16: 0 | K16: 0 | L16: 0 | M16: 13 | N16: 0 | O16: =SUM(C16:L16,N16) -> 2 | P16: =SUM(C16:N16) -> 15 | R16: 1300-1400 | S16: =SUM(C34:C37) -> 2 | T16: =SUM(D34:D37) -> 0 | U16: =SUM(E34:E37) -> 0 | V16: =SUM(F34:F37) -> 2 | W16: =SUM(G34:G37) -> 0 | X16: =SUM(H34:H37) -> 0 | Y16: =SUM(I34:I37) -> 7 | Z16: =SUM(J34:J37) -> 0 | ... AF16: =SUM(P34:P37) -> 67
B17: 08.45 - 9.00 | C17: 0 | D17: 0 | E17: 0 | F17: 0 | G17: 0 | H17: 0 | I17: 1 | J17: 0 | K17: 0 | L17: 0 | M17: 12 | N17: 0 | O17: =SUM(C17:L17,N17) -> 1 | P17: =SUM(C17:N17) -> 13 | R17: 1400-1500 | S17: =SUM(C38:C41) -> 1 | T17: =SUM(D38:D41) -> 0 | U17: =SUM(E38:E41) -> 4 | V17: =SUM(F38:F41) -> 0 | W17: =SUM(G38:G41) -> 0 | X17: =SUM(H38:H41) -> 0 | Y17: =SUM(I38:I41) -> 9 | Z17: =SUM(J38:J41) -> 0 | ... AF17: =SUM(P38:P41) -> 65
B18: 09.00 - 09.15 | C18: 0 | D18: 0 | E18: 0 | F18: 0 | G18: 0 | H18: 0 | I18: 1 | J18: 0 | K18: 0 | L18: 0 | M18: 11 | N18: 0 | O18: =SUM(C18:L18,N18) -> 1 | P18: =SUM(C18:N18) -> 12 | R18: 1500-1600 | S18: =SUM(C42:C45) -> 4 | T18: =SUM(D42:D45) -> 0 | U18: =SUM(E42:E45) -> 4 | V18: =SUM(F42:F45) -> 0 | W18: =SUM(G42:G45) -> 0 | X18: =SUM(H42:H45) -> 0 | Y18: =SUM(I42:I45) -> 3 | Z18: =SUM(J42:J45) -> 0 | ... AF18: =SUM(P42:P45) -> 57
B19: 09.15 - 09.30 | C19: 0 | D19: 0 | E19: 0 | F19: 0 | G19: 0 | H19: 0 | I19: 1 | J19: 0 | K19: 0 | L19: 0 | M19: 11 | N19: 0 | O19: =SUM(C19:L19,N19) -> 1 | P19: =SUM(C19:N19) -> 12 | R19: 1600-1700 | S19: =SUM(C46:C49) -> 3 | T19: =SUM(D46:D49) -> 0 | U19: =SUM(E46:E49) -> 1 | V19: =SUM(F46:F49) -> 0 | W19: =SUM(G46:G49) -> 0 | X19: =SUM(H46:H49) -> 0 | Y19: =SUM(I46:I49) -> 7 | Z19: =SUM(J46:J49) -> 0 | ... AF19: =SUM(P46:P49) -> 75
B20: 09.30 - 09.45 | C20: 0 | D20: 0 | E20: 0 | F20: 1 | G20: 0 | H20: 0 | I20: 1 | J20: 0 | K20: 0 | L20: 0 | M20: 10 | N20: 0 | O20: =SUM(C20:L20,N20) -> 2 | P20: =SUM(C20:N20) -> 12 | R20: 1700-1800 | S20: =SUM(C50:C53) -> 3 | T20: =SUM(D50:D53) -> 0 | U20: =SUM(E50:E53) -> 2 | V20: =SUM(F50:F53) -> 4 | W20: =SUM(G50:G53) -> 0 | X20: =SUM(H50:H53) -> 0 | Y20: =SUM(I50:I53) -> 5 | Z20: =SUM(J50:J53) -> 0 | ... AF20: =SUM(P50:P53) -> 62
B21: 09.45 - 10.00 | C21: 0 | D21: 0 | E21: 1 | F21: 0 | G21: 0 | H21: 0 | I21: 1 | J21: 0 | K21: 0 | L21: 0 | M21: 13 | N21: 0 | O21: =SUM(C21:L21,N21) -> 2 | P21: =SUM(C21:N21) -> 15 | R21: 1800-1900 | S21: =SUM(C54:C57) -> 2 | T21: =SUM(D54:D57) -> 0 | U21: =SUM(E54:E57) -> 0 | V21: =SUM(F54:F57) -> 1 | W21: =SUM(G54:G57) -> 1 | X21: =SUM(H54:H57) -> 0 | Y21: =SUM(I54:I57) -> 0 | Z21: =SUM(J54:J57) -> 0 | ... AF21: =SUM(P54:P57) -> 39
B22: 10.00 - 10.15 | C22: 0 | D22: 0 | E22: 1 | F22: 0 | G22: 0 | H22: 0 | I22: 2 | J22: 0 | K22: 0 | L22: 0 | M22: 15 | N22: 0 | O22: =SUM(C22:L22,N22) -> 3 | P22: =SUM(C22:N22) -> 18 | R22: AM Peak Hr | S22: =MAX(S10:S12) -> 2 | T22: =MAX(T10:T12) -> 0 | U22: =MAX(U10:U12) -> 1 | V22: =MAX(V10:V12) -> 2 | W22: =MAX(W10:W12) -> 0 | X22: =MAX(X10:X12) -> 0 | Y22: =MAX(Y10:Y12) -> 4 | Z22: =MAX(Z10:Z12) -> 0 | ... AF22: =MAX(AF10:AF12) -> 57
B23: 10.15 - 10.30 | C23: 0 | D23: 0 | E23: 1 | F23: 0 | G23: 0 | H23: 0 | I23: 0 | J23: 0 | K23: 0 | L23: 0 | M23: 16 | N23: 0 | O23: =SUM(C23:L23,N23) -> 1 | P23: =SUM(C23:N23) -> 17 | R23: IP Peak Hr | S23: =MAX(S13:S18) -> 9 | T23: =MAX(T13:T18) -> 0 | U23: =MAX(U13:U18) -> 11 | V23: =MAX(V13:V18) -> 2 | W23: =MAX(W13:W18) -> 0 | X23: =MAX(X13:X18) -> 0 | Y23: =MAX(Y13:Y18) -> 9 | Z23: =MAX(Z13:Z18) -> 1 | ... AF23: =MAX(AF13:AF18) -> 69
B24: 10.30 - 10.45 | C24: 0 | D24: 0 | E24: 0 | F24: 0 | G24: 0 | H24: 0 | I24: 1 | J24: 0 | K24: 0 | L24: 0 | M24: 13 | N24: 0 | O24: =SUM(C24:L24,N24) -> 1 | P24: =SUM(C24:N24) -> 14 | R24: PM Peak Hr | S24: =MAX(S19:S21) -> 3 | T24: =MAX(T19:T21) -> 0 | U24: =MAX(U19:U21) -> 2 | V24: =MAX(V19:V21) -> 4 | W24: =MAX(W19:W21) -> 1 | X24: =MAX(X19:X21) -> 0 | Y24: =MAX(Y19:Y21) -> 7 | Z24: =MAX(Z19:Z21) -> 0 | ... AF24: =MAX(AF19:AF21) -> 75
B25: 10.45 - 11.00 | C25: 2 | D25: 0 | E25: 0 | F25: 0 | G25: 0 | H25: 0 | I25: 1 | J25: 0 | K25: 0 | L25: 0 | M25: 14 | N25: 0 | O25: =SUM(C25:L25,N25) -> 3 | P25: =SUM(C25:N25) -> 17 | R25: AM Period | S25: =SUM(S10:S12) -> 4 | T25: =SUM(T10:T12) -> 0 | U25: =SUM(U10:U12) -> 2 | V25: =SUM(V10:V12) -> 4 | W25: =SUM(W10:W12) -> 0 | X25: =SUM(X10:X12) -> 0 | Y25: =SUM(Y10:Y12) -> 11 | Z25: =SUM(Z10:Z12) -> 0 | ... AF25: =SUM(AF10:AF12) -> 164
B26: 11.00 - 11.15 | C26: 2 | D26: 0 | E26: 5 | F26: 0 | G26: 0 | H26: 0 | I26: 0 | J26: 0 | K26: 0 | L26: 0 | M26: 8 | N26: 0 | O26: =SUM(C26:L26,N26) -> 7 | P26: =SUM(C26:N26) -> 15 | R26: IP Period | S26: =SUM(S13:S18) -> 21 | T26: =SUM(T13:T18) -> 0 | U26: =SUM(U13:U18) -> 26 | V26: =SUM(V13:V18) -> 5 | W26: =SUM(W13:W18) -> 0 | X26: =SUM(X13:X18) -> 0 | Y26: =SUM(Y13:Y18) -> 28 | Z26: =SUM(Z13:Z18) -> 1 | ... AF26: =SUM(AF13:AF18) -> 388
B27: 11.15 - 11.30 | C27: 3 | D27: 0 | E27: 4 | F27: 1 | G27: 0 | H27: 0 | I27: 0 | J27: 0 | K27: 0 | L27: 0 | M27: 12 | N27: 0 | O27: =SUM(C27:L27,N27) -> 8 | P27: =SUM(C27:N27) -> 20 | R27: PM Period | S27: =SUM(S19:S21) -> 8 | T27: =SUM(T19:T21) -> 0 | U27: =SUM(U19:U21) -> 3 | V27: =SUM(V19:V21) -> 5 | W27: =SUM(W19:W21) -> 1 | X27: =SUM(X19:X21) -> 0 | Y27: =SUM(Y19:Y21) -> 12 | Z27: =SUM(Z19:Z21) -> 0 | ... AF27: =SUM(AF19:AF21) -> 176
B28: 11.30 - 11.45 | C28: 1 | D28: 0 | E28: 0 | F28: 0 | G28: 0 | H28: 0 | I28: 0 | J28: 0 | K28: 0 | L28: 0 | M28: 18 | N28: 0 | O28: =SUM(C28:L28,N28) -> 1 | P28: =SUM(C28:N28) -> 19 | R28: 12 Hours | S28: =SUM(S10:S21) -> 33 | T28: =SUM(T10:T21) -> 0 | U28: =SUM(U10:U21) -> 31 | V28: =SUM(V10:V21) -> 14 | W28: =SUM(W10:W21) -> 1 | X28: =SUM(X10:X21) -> 0 | Y28: =SUM(Y10:Y21) -> 51 | Z28: =SUM(Z10:Z21) -> 1 | ... AF28: =SUM(AF10:AF21) -> 728
B29: 11.45 - 12.00 | C29: 3 | D29: 0 | E29: 2 | F29: 0 | G29: 0 | H29: 0 | I29: 1 | J29: 0 | K29: 0 | L29: 0 | M29: 9 | N29: 0 | O29: =SUM(C29:L29,N29) -> 6 | P29: =SUM(C29:N29) -> 15
B30: 12.00 - 12.15 | C30: 1 | D30: 0 | E30: 3 | F30: 0 | G30: 0 | H30: 0 | I30: 0 | J30: 0 | K30: 0 | L30: 0 | M30: 12 | N30: 0 | O30: =SUM(C30:L30,N30) -> 4 | P30: =SUM(C30:N30) -> 16
B31: 12.15 - 12.30 | C31: 1 | D31: 0 | E31: 0 | F31: 0 | G31: 0 | H31: 0 | I31: 1 | J31: 1 | K31: 0 | L31: 0 | M31: 9 | N31: 0 | O31: =SUM(C31:L31,N31) -> 3 | P31: =SUM(C31:N31) -> 12
B32: 12.30 - 12.45 | C32: 0 | D32: 0 | E32: 1 | F32: 1 | G32: 0 | H32: 0 | I32: 2 | J32: 0 | K32: 0 | L32: 0 | M32: 13 | N32: 0 | O32: =SUM(C32:L32,N32) -> 4 | P32: =SUM(C32:N32) -> 17
B33: 12.45 - 13.00 | C33: 1 | D33: 0 | E33: 1 | F33: 1 | G33: 0 | H33: 0 | I33: 1 | J33: 0 | K33: 0 | L33: 0 | M33: 15 | N33: 0 | O33: =SUM(C33:L33,N33) -> 4 | P33: =SUM(C33:N33) -> 19
B34: 13.00 - 13.15 | C34: 0 | D34: 0 | E34: 0 | F34: 0 | G34: 0 | H34: 0 | I34: 2 | J34: 0 | K34: 0 | L34: 0 | M34: 11 | N34: 0 | O34: =SUM(C34:L34,N34) -> 2 | P34: =SUM(C34:N34) -> 13
B35: 13.15 - 13.30 | C35: 2 | D35: 0 | E35: 0 | F35: 1 | G35: 0 | H35: 0 | I35: 1 | J35: 0 | K35: 0 | L35: 0 | M35: 14 | N35: 0 | O35: =SUM(C35:L35,N35) -> 4 | P35: =SUM(C35:N35) -> 18
B36: 13.30 - 13.45 | C36: 0 | D36: 0 | E36: 0 | F36: 0 | G36: 0 | H36: 0 | I36: 2 | J36: 0 | K36: 0 | L36: 0 | M36: 18 | N36: 0 | O36: =SUM(C36:L36,N36) -> 2 | P36: =SUM(C36:N36) -> 20
B37: 13.45 - 14.00 | C37: 0 | D37: 0 | E37: 0 | F37: 1 | G37: 0 | H37: 0 | I37: 2 | J37: 0 | K37: 0 | L37: 0 | M37: 13 | N37: 0 | O37: =SUM(C37:L37,N37) -> 3 | P37: =SUM(C37:N37) -> 16
B38: 14.00 - 14.15 | C38: 1 | D38: 0 | E38: 0 | F38: 0 | G38: 0 | H38: 0 | I38: 0 | J38: 0 | K38: 0 | L38: 0 | M38: 13 | N38: 0 | O38: =SUM(C38:L38,N38) -> 1 | P38: =SUM(C38:N38) -> 14
B39: 14.15 - 14.30 | C39: 0 | D39: 0 | E39: 2 | F39: 0 | G39: 0 | H39: 0 | I39: 2 | J39: 0 | K39: 0 | L39: 0 | M39: 14 | N39: 0 | O39: =SUM(C39:L39,N39) -> 4 | P39: =SUM(C39:N39) -> 18
B40: 14.30 - 14.45 | C40: 0 | D40: 0 | E40: 2 | F40: 0 | G40: 0 | H40: 0 | I40: 2 | J40: 0 | K40: 0 | L40: 0 | M40: 12 | N40: 0 | O40: =SUM(C40:L40,N40) -> 4 | P40: =SUM(C40:N40) -> 16
... B57: 18.45 - 19.00 | C57: 0 | D57: 0 | E57: 0 | F57: 0 | G57: 0 | H57: 0 | I57: 0 | J57: 0 | K57: 0 | L57: 0 | M57: 0 | N57: 0 | O57: =SUM(C57:L57,N57) -> 0 | P57: =SUM(C57:N57) -> 0
B58: Totals | C58: =SUM(C10:C57) -> 33 | D58: =SUM(D10:D57) -> 0 | E58: =SUM(E10:E57) -> 31 | F58: =SUM(F10:F57) -> 14 | G58: =SUM(G10:G57) -> 1 | H58: =SUM(H10:H57) -> 0 | I58: =SUM(I10:I57) -> 51 | J58: =SUM(J10:J57) -> 1 | ... P58: =SUM(P10:P57) -> 728
...

Sheet 13.08 BUSUNJU-KAMPALA
B1: Consultancy services for Preparation of Expressway Development Master Plan (EDMP) for Uganda
B2: MANUAL CLASSIFIED COUNT (MCC)
B3: ROAD NAME: | C3: ='11.08 BUSUNJU-KAMPALA'!C3:G3 -> MCC - C3 - STN85 - HOIMA ROAD
C5: Date | D5: 13.08.19 | F5: Location | G5: ='11.08 BUSUNJU-KAMPALA'!G5:H5 -> MATTE | J5: Surveyor | K5: ='11.08 BUSUNJU-KAMPALA'!K5:L5 -> xxx
C6: Dir. From | D6: ='11.08 BUSUNJU-KAMPALA'!D6:E6 -> BUSUNJU | F6: Dir. To | G6: ='11.08 BUSUNJU-KAMPALA'!G6:H6 -> KAMPALA | J6: Supervisor | K6: ='11.08 BUSUNJU-KAMPALA'!K6:L6 -> xxx
B8: Time / Veh Type | R8: SUMMARY TRAFFIC VOLUMES
C9: 1. Car | D9: 2. Station Wagon | E9: 3. Pickups | F9: 4. Minibus, matatu | G9: 5. Medium bus | H9: 6. Large Bus | I9: 7. Light Truck | J9: 8. Medium Truck | K9: 9. Heavy truck | L9: 10. Truck Trailer | M9: 11. Motor cycles | N9: 12. Tractors | O9: Total Excl M/Cycles | P9: Total All | R9: Time | S9: 1. Car | T9: 2. Station Wagon | U9: 3. Pickups | V9: 4. Minibus, matatu | W9: 5. Medium bus | X9: 6. Large Bus | Y9: 7. Light Truck | Z9: 8. Medium Truck | AA9: 9. Heavy truck | AB9: 10. Truck Trailer | AC9: 11. Motorcycles | AD9: 12. Tractors, Graders | AE9: Total Excl M/ Cycles | AF9: Total All
B10: 07.00 - 07.15 | C10: 2 | D10: 0 | E10: 1 | F10: 0 | G10: 0 | H10: 0 | I10: 1 | J10: 0 | K10: 0 | L10: 0 | M10: 7 | N10: 0 | O10: =SUM(C10:L10,N10) -> 4 | P10: =SUM(C10:N10) -> 11 | R10: 0700-0800 | S10: =SUM(C10:C13) -> 6 | T10: =SUM(D10:D13) -> 0 | U10: =SUM(E10:E13) -> 2 | V10: =SUM(F10:F13) -> 0 | W10: =SUM(G10:G13) -> 0 | X10: =SUM(H10:H13) -> 0 | Y10: =SUM(I10:I13) -> 4 | Z10: =SUM(J10:J13) -> 0 | ... AF10: =SUM(P10:P13) -> 52
B11: 07.15 - 07.30 | C11: 0 | D11: 0 | E11: 0 | F11: 0 | G11: 0 | H11: 0 | I11: 0 | J11: 0 | K11: 0 | L11: 0 | M11: 8 | N11: 0 | O11: =SUM(C11:L11,N11) -> 0 | P11: =SUM(C11:N11) -> 8 | R11: 0800-0900 | S11: =SUM(C14:C17) -> 2 | T11: =SUM(D14:D17) -> 0 | U11: =SUM(E14:E17) -> 3 | V11: =SUM(F14:F17) -> 2 | W11: =SUM(G14:G17) -> 0 | X11: =SUM(H14:H17) -> 0 | Y11: =SUM(I14:I17) -> 7 | Z11: =SUM(J14:J17) -> 0 | ... AF11: =SUM(P14:P17) -> 81
B12: 07.30 - 07.45 | C12: 3 | D12: 0 | E12: 0 | F12: 0 | G12: 0 | H12: 0 | I12: 1 | J12: 0 | K12: 0 | L12: 0 | M12: 13 | N12: 0 | O12: =SUM(C12:L12,N12) -> 4 | P12: =SUM(C12:N12) -> 17 | R12: 0900-1000 | S12: =SUM(C18:C21) -> 1 | T12: =SUM(D18:D21) -> 0 | U12: =SUM(E18:E21) -> 2 | V12: =SUM(F18:F21) -> 1 | W12: =SUM(G18:G21) -> 0 | X12: =SUM(H18:H21) -> 0 | Y12: =SUM(I18:I21) -> 6 | Z12: =SUM(J18:J21) -> 0 | ... AF12: =SUM(P18:P21) -> 73
B13: 07.45 - 08.00 | C13: 1 | D13: 0 | E13: 1 | F13: 0 | G13: 0 | H13: 0 | I13: 2 | J13: 0 | K13: 0 | L13: 0 | M13: 12 | N13: 0 | O13: =SUM(C13:L13,N13) -> 4 | P13: =SUM(C13:N13) -> 16 | R13: 1000-1100 | S13: =SUM(C22:C25) -> 3 | T13: =SUM(D22:D25) -> 0 | U13: =SUM(E22:E25) -> 1 | V13: =SUM(F22:F25) -> 0 | W13: =SUM(G22:G25) -> 0 | X13: =SUM(H22:H25) -> 0 | Y13: =SUM(I22:I25) -> 8 | Z13: =SUM(J22:J25) -> 0 | ... AF13: =SUM(P22:P25) -> 71
B14: 08.00 - 08.15 | C14: 1 | D14: 0 | E14: 0 | F14: 1 | G14: 0 | H14: 0 | I14: 0 | J14: 0 | K14: 0 | L14: 0 | M14: 13 | N14: 0 | O14: =SUM(C14:L14,N14) -> 2 | P14: =SUM(C14:N14) -> 15 | R14: 1100-1200 | S14: =SUM(C26:C29) -> 3 | T14: =SUM(D26:D29) -> 0 | U14: =SUM(E26:E29) -> 1 | V14: =SUM(F26:F29) -> 1 | W14: =SUM(G26:G29) -> 0 | X14: =SUM(H26:H29) -> 0 | Y14: =SUM(I26:I29) -> 5 | Z14: =SUM(J26:J29) -> 1 | ... AF14: =SUM(P26:P29) -> 86
B15: 08.15 - 08.30 | C15: 0 | D15: 0 | E15: 0 | F15: 0 | G15: 0 | H15: 0 | I15: 2 | J15: 0 | K15: 0 | L15: 0 | M15: 16 | N15: 0 | O15: =SUM(C15:L15,N15) -> 2 | P15: =SUM(C15:N15) -> 18 | R15: 1200-1300 | S15: =SUM(C30:C33) -> 3 | T15: =SUM(D30:D33) -> 0 | U15: =SUM(E30:E33) -> 2 | V15: =SUM(F30:F33) -> 4 | W15: =SUM(G30:G33) -> 0 | X15: =SUM(H30:H33) -> 0 | Y15: =SUM(I30:I33) -> 8 | Z15: =SUM(J30:J33) -> 0 | ... AF15: =SUM(P30:P33) -> 96
B16: 08.30 - 08.45 | C16: 1 | D16: 0 | E16: 2 | F16: 1 | G16: 0 | H16: 0 | I16: 3 | J16: 0 | K16: 0 | L16: 0 | M16: 21 | N16: 0 | O16: =SUM(C16:L16,N16) -> 7 | P16: =SUM(C16:N16) -> 28 | R16: 1300-1400 | S16: =SUM(C34:C37) -> 1 | T16: =SUM(D34:D37) -> 0 | U16: =SUM(E34:E37) -> 6 | V16: =SUM(F34:F37) -> 0 | W16: =SUM(G34:G37) -> 0 | X16: =SUM(H34:H37) -> 0 | Y16: =SUM(I34:I37) -> 3 | Z16: =SUM(J34:J37) -> 0 | ... AF16: =SUM(P34:P37) -> 74
B17: 08.45 - 9.00 | C17: 0 | D17: 0 | E17: 1 | F17: 0 | G17: 0 | H17: 0 | I17: 2 | J17: 0 | K17: 0 | L17: 0 | M17: 17 | N17: 0 | O17: =SUM(C17:L17,N17) -> 3 | P17: =SUM(C17:N17) -> 20 | R17: 1400-1500 | S17: =SUM(C38:C41) -> 5 | T17: =SUM(D38:D41) -> 0 | U17: =SUM(E38:E41) -> 4 | V17: =SUM(F38:F41) -> 1 | W17: =SUM(G38:G41) -> 0 | X17: =SUM(H38:H41) -> 0 | Y17: =SUM(I38:I41) -> 5 | Z17: =SUM(J38:J41) -> 0 | ... AF17: =SUM(P38:P41) -> 91
B18: 09.00 - 09.15 | C18: 0 | D18: 0 | E18: 0 | F18: 0 | G18: 0 | H18: 0 | I18: 1 | J18: 0 | K18: 0 | L18: 0 | M18: 15 | N18: 0 | O18: =SUM(C18:L18,N18) -> 1 | P18: =SUM(C18:N18) -> 16 | R18: 1500-1600 | S18: =SUM(C42:C45) -> 3 | T18: =SUM(D42:D45) -> 0 | U18: =SUM(E42:E45) -> 2 | V18: =SUM(F42:F45) -> 0 | W18: =SUM(G42:G45) -> 0 | X18: =SUM(H42:H45) -> 0 | Y18: =SUM(I42:I45) -> 9 | Z18: =SUM(J42:J45) -> 1 | ... AF18: =SUM(P42:P45) -> 97
B19: 09.15 - 09.30 | C19: 0 | D19: 0 | E19: 1 | F19: 0 | G19: 0 | H19: 0 | I19: 1 | J19: 0 | K19: 0 | L19: 0 | M19: 17 | N19: 0 | O19: =SUM(C19:L19,N19) -> 2 | P19: =SUM(C19:N19) -> 19 | R19: 1600-1700 | S19: =SUM(C46:C49) -> 4 | T19: =SUM(D46:D49) -> 0 | U19: =SUM(E46:E49) -> 8 | V19: =SUM(F46:F49) -> 4 | W19: =SUM(G46:G49) -> 0 | X19: =SUM(H46:H49) -> 0 | Y19: =SUM(I46:I49) -> 7 | Z19: =SUM(J46:J49) -> 0 | ... AF19: =SUM(P46:P49) -> 110
B20: 09.30 - 09.45 | C20: 1 | D20: 0 | E20: 0 | F20: 1 | G20: 0 | H20: 0 | I20: 0 | J20: 0 | K20: 0 | L20: 0 | M20: 14 | N20: 0 | O20: =SUM(C20:L20,N20) -> 2 | P20: =SUM(C20:N20) -> 16 | R20: 1700-1800 | S20: =SUM(C50:C53) -> 12 | T20: =SUM(D50:D53) -> 0 | U20: =SUM(E50:E53) -> 9 | V20: =SUM(F50:F53) -> 4 | W20: =SUM(G50:G53) -> 0 | X20: =SUM(H50:H53) -> 0 | Y20: =SUM(I50:I53) -> 4 | Z20: =SUM(J50:J53) -> 0 | ... AF20: =SUM(P50:P53) -> 111
B21: 09.45 - 10.00 | C21: 0 | D21: 0 | E21: 1 | F21: 0 | G21: 0 | H21: 0 | I21: 4 | J21: 0 | K21: 0 | L21: 0 | M21: 17 | N21: 0 | O21: =SUM(C21:L21,N21) -> 5 | P21: =SUM(C21:N21) -> 22 | R21: 1800-1900 | S21: =SUM(C54:C57) -> 5 | T21: =SUM(D54:D57) -> 0 | U21: =SUM(E54:E57) -> 6 | V21: =SUM(F54:F57) -> 3 | W21: =SUM(G54:G57) -> 1 | X21: =SUM(H54:H57) -> 0 | Y21: =SUM(I54:I57) -> 3 | Z21: =SUM(J54:J57) -> 0 | ... AF21: =SUM(P54:P57) -> 85
B22: 10.00 - 10.15 | C22: 1 | D22: 0 | E22: 0 | F22: 0 | G22: 0 | H22: 0 | I22: 0 | J22: 0 | K22: 0 | L22: 0 | M22: 13 | N22: 0 | O22: =SUM(C22:L22,N22) -> 1 | P22: =SUM(C22:N22) -> 14 | R22: AM Peak Hr | S22: =MAX(S10:S12) -> 6 | T22: =MAX(T10:T12) -> 0 | U22: =MAX(U10:U12) -> 3 | V22: =MAX(V10:V12) -> 2 | W22: =MAX(W10:W12) -> 0 | X22: =MAX(X10:X12) -> 0 | Y22: =MAX(Y10:Y12) -> 7 | Z22: =MAX(Z10:Z12) -> 0 | ... AF22: =MAX(AF10:AF12) -> 81
B23: 10.15 - 10.30 | C23: 1 | D23: 0 | E23: 1 | F23: 0 | G23: 0 | H23: 0 | I23: 4 | J23: 0 | K23: 0 | L23: 0 | M23: 13 | N23: 0 | O23: =SUM(C23:L23,N23) -> 6 | P23: =SUM(C23:N23) -> 19 | R23: IP Peak Hr | S23: =MAX(S13:S18) -> 5 | T23: =MAX(T13:T18) -> 0 | U23: =MAX(U13:U18) -> 6 | V23: =MAX(V13:V18) -> 4 | W23: =MAX(W13:W18) -> 0 | X23: =MAX(X13:X18) -> 0 | Y23: =MAX(Y13:Y18) -> 9 | Z23: =MAX(Z13:Z18) -> 1 | ... AF23: =MAX(AF13:AF18) -> 97
B24: 10.30 - 10.45 | C24: 1 | D24: 0 | E24: 0 | F24: 0 | G24: 0 | H24: 0 | I24: 2 | J24: 0 | K24: 0 | L24: 0 | M24: 16 | N24: 0 | O24: =SUM(C24:L24,N24) -> 3 | P24: =SUM(C24:N24) -> 19 | R24: PM Peak Hr | S24: =MAX(S19:S21) -> 12 | T24: =MAX(T19:T21) -> 0 | U24: =MAX(U19:U21) -> 9 | V24: =MAX(V19:V21) -> 4 | W24: =MAX(W19:W21) -> 1 | X24: =MAX(X19:X21) -> 0 | Y24: =MAX(Y19:Y21) -> 7 | Z24: =MAX(Z19:Z21) -> 0 | ... AF24: =MAX(AF19:AF21) -> 111
B25: 10.45 - 11.00 | C25: 0 | D25: 0 | E25: 0 | F25: 0 | G25: 0 | H25: 0 | I25: 2 | J25: 0 | K25: 0 | L25: 0 | M25: 17 | N25: 0 | O25: =SUM(C25:L25,N25) -> 2 | P25: =SUM(C25:N25) -> 19 | R25: AM Period | S25: =SUM(S10:S12) -> 9 | T25: =SUM(T10:T12) -> 0 | U25: =SUM(U10:U12) -> 7 | V25: =SUM(V10:V12) -> 3 | W25: =SUM(W10:W12) -> 0 | X25: =SUM(X10:X12) -> 0 | Y25: =SUM(Y10:Y12) -> 17 | Z25: =SUM(Z10:Z12) -> 0 | ... AF25: =SUM(AF10:AF12) -> 206
B26: 11.00 - 11.15 | C26: 1 | D26: 0 | E26: 0 | F26: 0 | G26: 0 | H26: 0 | I26: 4 | J26: 0 | K26: 0 | L26: 0 | M26: 17 | N26: 0 | O26: =SUM(C26:L26,N26) -> 5 | P26: =SUM(C26:N26) -> 22 | R26: IP Period | S26: =SUM(S13:S18) -> 18 | T26: =SUM(T13:T18) -> 0 | U26: =SUM(U13:U18) -> 16 | V26: =SUM(V13:V18) -> 6 | W26: =SUM(W13:W18) -> 0 | X26: =SUM(X13:X18) -> 0 | Y26: =SUM(Y13:Y18) -> 38 | Z26: =SUM(Z13:Z18) -> 2 | ... AF26: =SUM(AF13:AF18) -> 515
B27: 11.15 - 11.30 | C27: 1 | D27: 0 | E27: 1 | F27: 0 | G27: 0 | H27: 0 | I27: 1 | J27: 1 | K27: 1 | L27: 0 | M27: 17 | N27: 0 | O27: =SUM(C27:L27,N27) -> 5 | P27: =SUM(C27:N27) -> 22 | R27: PM Period | S27: =SUM(S19:S21) -> 21 | T27: =SUM(T19:T21) -> 0 | U27: =SUM(U19:U21) -> 23 | V27: =SUM(V19:V21) -> 11 | W27: =SUM(W19:W21) -> 1 | X27: =SUM(X19:X21) -> 0 | Y27: =SUM(Y19:Y21) -> 14 | Z27: =SUM(Z19:Z21) -> 0 | ... AF27: =SUM(AF19:AF21) -> 306
B28: 11.30 - 11.45 | C28: 0 | D28: 0 | E28: 0 | F28: 0 | G28: 0 | H28: 0 | I28: 0 | J28: 0 | K28: 0 | L28: 0 | M28: 27 | N28: 0 | O28: =SUM(C28:L28,N28) -> 0 | P28: =SUM(C28:N28) -> 27 | R28: 12 Hours | S28: =SUM(S10:S21) -> 48 | T28: =SUM(T10:T21) -> 0 | U28: =SUM(U10:U21) -> 46 | V28: =SUM(V10:V21) -> 20 | W28: =SUM(W10:W21) -> 1 | X28: =SUM(X10:X21) -> 0 | Y28: =SUM(Y10:Y21) -> 69 | Z28: =SUM(Z10:Z21) -> 2 | ... AF28: =SUM(AF10:AF21) -> 1027
B29: 11.45 - 12.00 | C29: 1 | D29: 0 | E29: 0 | F29: 1 | G29: 0 | H29: 0 | I29: 0 | J29: 0 | K29: 0 | L29: 0 | M29: 13 | N29: 0 | O29: =SUM(C29:L29,N29) -> 2 | P29: =SUM(C29:N29) -> 15
B30: 12.00 - 12.15 | C30: 1 | D30: 0 | E30: 0 | F30: 0 | G30: 0 | H30: 0 | I30: 2 | J30: 0 | K30: 0 | L30: 0 | M30: 18 | N30: 0 | O30: =SUM(C30:L30,N30) -> 3 | P30: =SUM(C30:N30) -> 21
B31: 12.15 - 12.30 | C31: 1 | D31: 0 | E31: 0 | F31: 1 | G31: 0 | H31: 0 | I31: 1 | J31: 0 | K31: 0 | L31: 0 | M31: 16 | N31: 0 | O31: =SUM(C31:L31,N31) -> 3 | P31: =SUM(C31:N31) -> 19
B32: 12.30 - 12.45 | C32: 1 | D32: 0 | E32: 1 | F32: 1 | G32: 0 | H32: 0 | I32: 4 | J32: 0 | K32: 0 | L32: 0 | M32: 22 | N32: 0 | O32: =SUM(C32:L32,N32) -> 7 | P32: =SUM(C32:N32) -> 29
B33: 12.45 - 13.00 | C33: 0 | D33: 0 | E33: 1 | F33: 2 | G33: 0 | H33: 0 | I33: 1 | J33: 0 | K33: 0 | L33: 0 | M33: 23 | N33: 0 | O33: =SUM(C33:L33,N33) -> 4 | P33: =SUM(C33:N33) -> 27
B34: 13.00 - 13.15 | C34: 1 | D34: 0 | E34: 0 | F34: 0 | G34: 0 | H34: 0 | I34: 1 | J34: 0 | K34: 0 | L34: 0 | M34: 14 | N34: 0 | O34: =SUM(C34:L34,N34) -> 2 | P34: =SUM(C34:N34) -> 16
