Workbook

Sheet 22.07 RUBAGA-KABUSU
B1: Consultancy services for Preparation of Expressway Development Master Plan (EDMP) for Uganda
B2: MANUAL CLASSIFIED COUNT (MCC)
B3: ROAD NAME: | C3: MCC - C1 - STN05 - KABUSU ROAD
C5: Date | D5: 22.07.19 | F5: Location | G5: CHAD SUPERMARKET | J5: Surveyor | K5: EMMANUEL EGIMU
C6: Dir. From | D6: RUBAGA | F6: Dir. To | G6: KABUSU | J6: Supervisor | K6: DENIS
B8: Time / Veh Type | R8: SUMMARY TRAFFIC VOLUMES
C9: 1. Car | D9: 2. Station Wagon | E9: 3. Pickups | F9: 4. Minibus, matatu | G9: 5. Medium bus | H9: 6. Large Bus | I9: 7. Light Truck | J9: 8. Medium Truck | K9: 9. Heavy truck | L9: 10. Truck Trailer | M9: 11. Motor cycles | N9: 12. Tractors | O9: Total Excl M/Cycles | P9: Total All | R9: Time | S9: 1. Car | T9: 2. Station Wagon | U9: 3. Pickups | V9: 4. Minibus, matatu | W9: 5. Medium bus | X9: 6. Large Bus | Y9: 7. Light Truck | Z9: 8. Medium Truck | AA9: 9. Heavy truck | AB9: 10. Truck Trailer | AC9: 11. Motorcycles | AD9: 12. Tractors, Graders | AE9: Total Excl M/ Cycles | AF9: Total All
B10: 07.00 - 07.15 | C10: 10 | D10: 9 | E10: 1 | F10: 10 | G10: 2 | H10: 0 | I10: 0 | J10: 0 | K10: 0 | L10: 0 | M10: 60 | N10: 0 | O10: =SUM(C10:L10,N10) -> 32 | P10: =SUM(C10:N10) -> 92 | R10: 0700-0800 | S10: =SUM(C10:C13) -> 63 | T10: =SUM(D10:D13) -> 17 | U10: =SUM(E10:E13) -> 6 | V10: =SUM(F10:F13) -> 72 | W10: =SUM(G10:G13) -> 3 | X10: =SUM(H10:H13) -> 0 | Y10: =SUM(I10:I13) -> 7 | Z10: =SUM(J10:J13) -> 3 | ... AF10: =SUM(P10:P13) -> 564
B11: 07.15 - 07.30 | C11: 7 | D11: 0 | E11: 1 | F11: 14 | G11: 0 | H11: 0 | I11: 2 | J11: 0 | K11: 0 | L11: 0 | M11: 58 | N11: 0 | O11: =SUM(C11:L11,N11) -> 24 | P11: =SUM(C11:N11) -> 82 | R11: 0800-0900 | S11: =SUM(C14:C17) -> 77 | T11: =SUM(D14:D17) -> 21 | U11: =SUM(E14:E17) -> 9 | V11: =SUM(F14:F17) -> 106 | W11: =SUM(G14:G17) -> 2 | X11: =SUM(H14:H17) -> 1 | Y11: =SUM(I14:I17) -> 17 | Z11: =SUM(J14:J17) -> 7 | ... AF11: =SUM(P14:P17) -> 1375
B12: 07.30 - 07.45 | C12: 15 | D12: 3 | E12: 3 | F12: 20 | G12: 0 | H12: 0 | I12: 2 | J12: 1 | K12: 0 | L12: 0 | M12: 70 | N12: 0 | O12: =SUM(C12:L12,N12) -> 44 | P12: =SUM(C12:N12) -> 114 | R12: 0900-1000 | S12: =SUM(C18:C21) -> 81 | T12: =SUM(D18:D21) -> 17 | U12: =SUM(E18:E21) -> 11 | V12: =SUM(F18:F21) -> 94 | W12: =SUM(G18:G21) -> 7 | X12: =SUM(H18:H21) -> 3 | Y12: =SUM(I18:I21) -> 10 | Z12: =SUM(J18:J21) -> 10 | ... AF12: =SUM(P18:P21) -> 1199
B13: 07.45 - 08.00 | C13: 31 | D13: 5 | E13: 1 | F13: 28 | G13: 1 | H13: 0 | I13: 3 | J13: 2 | K13: 0 | L13: 0 | M13: 205 | N13: 0 | O13: =SUM(C13:L13,N13) -> 71 | P13: =SUM(C13:N13) -> 276 | R13: 1000-1100 | S13: =SUM(C22:C25) -> 91 | T13: =SUM(D22:D25) -> 28 | U13: =SUM(E22:E25) -> 14 | V13: =SUM(F22:F25) -> 84 | W13: =SUM(G22:G25) -> 1 | X13: =SUM(H22:H25) -> 2 | Y13: =SUM(I22:I25) -> 21 | Z13: =SUM(J22:J25) -> 10 | ... AF13: =SUM(P22:P25) -> 966
B14: 08.00 - 08.15 | C14: 18 | D14: 7 | E14: 2 | F14: 21 | G14: 0 | H14: 0 | I14: 5 | J14: 2 | K14: 0 | L14: 0 | M14: 252 | N14: 0 | O14: =SUM(C14:L14,N14) -> 55 | P14: =SUM(C14:N14) -> 307 | R14: 1100-1200 | S14: =SUM(C26:C29) -> 107 | T14: =SUM(D26:D29) -> 17 | U14: =SUM(E26:E29) -> 9 | V14: =SUM(F26:F29) -> 68 | W14: =SUM(G26:G29) -> 1 | X14: =SUM(H26:H29) -> 0 | Y14: =SUM(I26:I29) -> 23 | Z14: =SUM(J26:J29) -> 17 | ... AF14: =SUM(P26:P29) -> 848
B15: 08.15 - 08.30 | C15: 22 | D15: 4 | E15: 4 | F15: 19 | G15: 1 | H15: 0 | I15: 4 | J15: 1 | K15: 0 | L15: 0 | M15: 241 | N15: 0 | O15: =SUM(C15:L15,N15) -> 55 | P15: =SUM(C15:N15) -> 296 | R15: 1200-1300 | S15: =SUM(C30:C33) -> 107 | T15: =SUM(D30:D33) -> 29 | U15: =SUM(E30:E33) -> 20 | V15: =SUM(F30:F33) -> 61 | W15: =SUM(G30:G33) -> 0 | X15: =SUM(H30:H33) -> 2 | Y15: =SUM(I30:I33) -> 19 | Z15: =SUM(J30:J33) -> 14 | ... AF15: =SUM(P30:P33) -> 894
B16: 08.30 - 08.45 | C16: 18 | D16: 1 | E16: 1 | F16: 47 | G16: 0 | H16: 0 | I16: 5 | J16: 2 | K16: 0 | L16: 0 | M16: 286 | N16: 0 | O16: =SUM(C16:L16,N16) -> 74 | P16: =SUM(C16:N16) -> 360 | R16: 1300-1400 | S16: =SUM(C34:C37) -> 140 | T16: =SUM(D34:D37) -> 19 | U16: =SUM(E34:E37) -> 9 | V16: =SUM(F34:F37) -> 75 | W16: =SUM(G34:G37) -> 0 | X16: =SUM(H34:H37) -> 0 | Y16: =SUM(I34:I37) -> 21 | Z16: =SUM(J34:J37) -> 22 | ... AF16: =SUM(P34:P37) -> 867
B17: 08.45 - 9.00 | C17: 19 | D17: 9 | E17: 2 | F17: 19 | G17: 1 | H17: 1 | I17: 3 | J17: 2 | K17: 0 | L17: 1 | M17: 355 | N17: 0 | O17: =SUM(C17:L17,N17) -> 57 | P17: =SUM(C17:N17) -> 412 | R17: 1400-1500 | S17: =SUM(C38:C41) -> 132 | T17: =SUM(D38:D41) -> 22 | U17: =SUM(E38:E41) -> 8 | V17: =SUM(F38:F41) -> 62 | W17: =SUM(G38:G41) -> 1 | X17: =SUM(H38:H41) -> 1 | Y17: =SUM(I38:I41) -> 15 | Z17: =SUM(J38:J41) -> 13 | ... AF17: =SUM(P38:P41) -> 818
B18: 09.00 - 09.15 | C18: 16 | D18: 4 | E18: 3 | F18: 35 | G18: 1 | H18: 0 | I18: 2 | J18: 3 | K18: 0 | L18: 0 | M18: 315 | N18: 0 | O18: =SUM(C18:L18,N18) -> 64 | P18: =SUM(C18:N18) -> 379 | R18: 1500-1600 | S18: =SUM(C42:C45) -> 143 | T18: =SUM(D42:D45) -> 27 | U18: =SUM(E42:E45) -> 11 | V18: =SUM(F42:F45) -> 43 | W18: =SUM(G42:G45) -> 4 | X18: =SUM(H42:H45) -> 1 | Y18: =SUM(I42:I45) -> 7 | Z18: =SUM(J42:J45) -> 13 | ... AF18: =SUM(P42:P45) -> 401
B19: 09.15 - 09.30 | C19: 16 | D19: 7 | E19: 1 | F19: 14 | G19: 1 | H19: 0 | I19: 1 | J19: 4 | K19: 0 | L19: 0 | M19: 182 | N19: 0 | O19: =SUM(C19:L19,N19) -> 44 | P19: =SUM(C19:N19) -> 226 | R19: 1600-1700 | S19: =SUM(C46:C49) -> 188 | T19: =SUM(D46:D49) -> 30 | U19: =SUM(E46:E49) -> 16 | V19: =SUM(F46:F49) -> 52 | W19: =SUM(G46:G49) -> 1 | X19: =SUM(H46:H49) -> 1 | Y19: =SUM(I46:I49) -> 14 | Z19: =SUM(J46:J49) -> 11 | ... AF19: =SUM(P46:P49) -> 899
B20: 09.30 - 09.45 | C20: 25 | D20: 1 | E20: 3 | F20: 22 | G20: 1 | H20: 2 | I20: 3 | J20: 1 | K20: 0 | L20: 0 | M20: 235 | N20: 0 | O20: =SUM(C20:L20,N20) -> 58 | P20: =SUM(C20:N20) -> 293 | R20: 1700-1800 | S20: =SUM(C50:C53) -> 271 | T20: =SUM(D50:D53) -> 41 | U20: =SUM(E50:E53) -> 19 | V20: =SUM(F50:F53) -> 45 | W20: =SUM(G50:G53) -> 1 | X20: =SUM(H50:H53) -> 0 | Y20: =SUM(I50:I53) -> 14 | Z20: =SUM(J50:J53) -> 21 | ... AF20: =SUM(P50:P53) -> 983
B21: 09.45 - 10.00 | C21: 24 | D21: 5 | E21: 4 | F21: 23 | G21: 4 | H21: 1 | I21: 4 | J21: 2 | K21: 1 | L21: 0 | M21: 233 | N21: 0 | O21: =SUM(C21:L21,N21) -> 68 | P21: =SUM(C21:N21) -> 301 | R21: 1800-1900 | S21: =SUM(C54:C57) -> 388 | T21: =SUM(D54:D57) -> 57 | U21: =SUM(E54:E57) -> 30 | V21: =SUM(F54:F57) -> 25 | W21: =SUM(G54:G57) -> 11 | X21: =SUM(H54:H57) -> 0 | Y21: =SUM(I54:I57) -> 15 | Z21: =SUM(J54:J57) -> 8 | ... AF21: =SUM(P54:P57) -> 1169
B22: 10.00 - 10.15 | C22: 19 | D22: 13 | E22: 4 | F22: 27 | G22: 1 | H22: 1 | I22: 4 | J22: 1 | K22: 0 | L22: 0 | M22: 181 | N22: 0 | O22: =SUM(C22:L22,N22) -> 70 | P22: =SUM(C22:N22) -> 251 | R22: AM Peak Hr | S22: =MAX(S10:S12) -> 81 | T22: =MAX(T10:T12) -> 21 | U22: =MAX(U10:U12) -> 11 | V22: =MAX(V10:V12) -> 106 | W22: =MAX(W10:W12) -> 7 | X22: =MAX(X10:X12) -> 3 | Y22: =MAX(Y10:Y12) -> 17 | Z22: =MAX(Z10:Z12) -> 10 | ... AF22: =MAX(AF10:AF12) -> 1375
B23: 10.15 - 10.30 | C23: 18 | D23: 3 | E23: 2 | F23: 21 | G23: 0 | H23: 0 | I23: 3 | J23: 5 | K23: 0 | L23: 0 | M23: 168 | N23: 0 | O23: =SUM(C23:L23,N23) -> 52 | P23: =SUM(C23:N23) -> 220 | R23: IP Peak Hr | S23: =MAX(S13:S18) -> 143 | T23: =MAX(T13:T18) -> 29 | U23: =MAX(U13:U18) -> 20 | V23: =MAX(V13:V18) -> 84 | W23: =MAX(W13:W18) -> 4 | X23: =MAX(X13:X18) -> 2 | Y23: =MAX(Y13:Y18) -> 23 | Z23: =MAX(Z13:Z18) -> 22 | ... AF23: =MAX(AF13:AF18) -> 966
B24: 10.30 - 10.45 | C24: 22 | D24: 5 | E24: 2 | F24: 15 | G24: 0 | H24: 0 | I24: 5 | J24: 0 | K24: 0 | L24: 0 | M24: 180 | N24: 0 | O24: =SUM(C24:L24,N24) -> 49 | P24: =SUM(C24:N24) -> 229 | R24: PM Peak Hr | S24: =MAX(S19:S21) -> 388 | T24: =MAX(T19:T21) -> 57 | U24: =MAX(U19:U21) -> 30 | V24: =MAX(V19:V21) -> 52 | W24: =MAX(W19:W21) -> 11 | X24: =MAX(X19:X21) -> 1 | Y24: =MAX(Y19:Y21) -> 15 | Z24: =MAX(Z19:Z21) -> 21 | ... AF24: =MAX(AF19:AF21) -> 1169
B25: 10.45 - 11.00 | C25: 32 | D25: 7 | E25: 6 | F25: 21 | G25: 0 | H25: 1 | I25: 9 | J25: 4 | K25: 1 | L25: 0 | M25: 185 | N25: 0 | O25: =SUM(C25:L25,N25) -> 81 | P25: =SUM(C25:N25) -> 266 | R25: AM Period | S25: =SUM(S10:S12) -> 221 | T25: =SUM(T10:T12) -> 55 | U25: =SUM(U10:U12) -> 26 | V25: =SUM(V10:V12) -> 272 | W25: =SUM(W10:W12) -> 12 | X25: =SUM(X10:X12) -> 4 | Y25: =SUM(Y10:Y12) -> 34 | Z25: =SUM(Z10:Z12) -> 20 | ... AF25: =SUM(AF10:AF12) -> 3138
B26: 11.00 - 11.15 | C26: 26 | D26: 2 | E26: 2 | F26: 18 | G26: 0 | H26: 0 | I26: 7 | J26: 4 | K26: 2 | L26: 1 | M26: 177 | N26: 0 | O26: =SUM(C26:L26,N26) -> 62 | P26: =SUM(C26:N26) -> 239 | R26: IP Period | S26: =SUM(S13:S18) -> 720 | T26: =SUM(T13:T18) -> 142 | U26: =SUM(U13:U18) -> 71 | V26: =SUM(V13:V18) -> 393 | W26: =SUM(W13:W18) -> 7 | X26: =SUM(X13:X18) -> 6 | Y26: =SUM(Y13:Y18) -> 106 | Z26: =SUM(Z13:Z18) -> 89 | ... AF26: =SUM(AF13:AF18) -> 4794
B27: 11.15 - 11.30 | C27: 26 | D27: 5 | E27: 2 | F27: 12 | G27: 0 | H27: 0 | I27: 3 | J27: 9 | K27: 2 | L27: 0 | M27: 146 | N27: 0 | O27: =SUM(C27:L27,N27) -> 59 | P27: =SUM(C27:N27) -> 205 | R27: PM Period | S27: =SUM(S19:S21) -> 847 | T27: =SUM(T19:T21) -> 128 | U27: =SUM(U19:U21) -> 65 | V27: =SUM(V19:V21) -> 122 | W27: =SUM(W19:W21) -> 13 | X27: =SUM(X19:X21) -> 1 | Y27: =SUM(Y19:Y21) -> 43 | Z27: =SUM(Z19:Z21) -> 40 | ... AF27: =SUM(AF19:AF21) -> 3051
B28: 11.30 - 11.45 | C28: 23 | D28: 3 | E28: 2 | F28: 17 | G28: 1 | H28: 0 | I28: 10 | J28: 1 | K28: 1 | L28: 0 | M28: 134 | N28: 0 | O28: =SUM(C28:L28,N28) -> 58 | P28: =SUM(C28:N28) -> 192 | R28: 12 Hours | S28: =SUM(S10:S21) -> 1788 | T28: =SUM(T10:T21) -> 325 | U28: =SUM(U10:U21) -> 162 | V28: =SUM(V10:V21) -> 787 | W28: =SUM(W10:W21) -> 32 | X28: =SUM(X10:X21) -> 11 | Y28: =SUM(Y10:Y21) -> 183 | Z28: =SUM(Z10:Z21) -> 149 | ... AF28: =SUM(AF10:AF21) -> 10983
B29: 11.45 - 12.00 | C29: 32 | D29: 7 | E29: 3 | F29: 21 | G29: 0 | H29: 0 | I29: 3 | J29: 3 | K29: 3 | L29: 0 | M29: 140 | N29: 0 | O29: =SUM(C29:L29,N29) -> 72 | P29: =SUM(C29:N29) -> 212
B30: 12.00 - 12.15 | C30: 23 | D30: 4 | E30: 6 | F30: 19 | G30: 0 | H30: 0 | I30: 2 | J30: 4 | K30: 1 | L30: 1 | M30: 181 | N30: 0 | O30: =SUM(C30:L30,N30) -> 60 | P30: =SUM(C30:N30) -> 241
B31: 12.15 - 12.30 | C31: 22 | D31: 10 | E31: 3 | F31: 10 | G31: 0 | H31: 1 | I31: 6 | J31: 6 | K31: 2 | L31: 0 | M31: 150 | N31: 0 | O31: =SUM(C31:L31,N31) -> 60 | P31: =SUM(C31:N31) -> 210
B32: 12.30 - 12.45 | C32: 27 | D32: 10 | E32: 4 | F32: 22 | G32: 0 | H32: 0 | I32: 6 | J32: 1 | K32: 1 | L32: 0 | M32: 147 | N32: 0 | O32: =SUM(C32:L32,N32) -> 71 | P32: =SUM(C32:N32) -> 218
B33: 12.45 - 13.00 | C33: 35 | D33: 5 | E33: 7 | F33: 10 | G33: 0 | H33: 1 | I33: 5 | J33: 3 | K33: 1 | L33: 0 | M33: 158 | N33: 0 | O33: =SUM(C33:L33,N33) -> 67 | P33: =SUM(C33:N33) -> 225
B34: 13.00 - 13.15 | C34: 31 | D34: 3 | E34: 3 | F34: 18 | G34: 0 | H34: 0 | I34: 6 | J34: 9 | K34: 2 | L34: 0 | M34: 148 | N34: 0 | O34: =SUM(C34:L34,N34) -> 72 | P34: =SUM(C34:N34) -> 220
B35: 13.15 - 13.30 | C35: 39 | D35: 7 | E35: 0 | F35: 22 | G35: 0 | H35: 0 | I35: 1 | J35: 4 | K35: 1 | L35: 0 | M35: 144 | N35: 0 | O35: =SUM(C35:L35,N35) -> 74 | P35: =SUM(C35:N35) -> 218
B36: 13.30 - 13.45 | C36: 30 | D36: 3 | E36: 5 | F36: 11 | G36: 0 | H36: 0 | I36: 5 | J36: 2 | K36: 1 | L36: 0 | M36: 120 | N36: 0 | O36: =SUM(C36:L36,N36) -> 57 | P36: =SUM(C36:N36) -> 177
B37: 13.45 - 14.00 | C37: 40 | D37: 6 | E37: 1 | F37: 24 | G37: 0 | H37: 0 | I37: 9 | J37: 7 | K37: 0 | L37: 0 | M37: 165 | N37: 0 | O37: =SUM(C37:L37,N37) -> 87 | P37: =SUM(C37:N37) -> 252
B38: 14.00 - 14.15 | C38: 24 | D38: 2 | E38: 3 | F38: 15 | G38: 0 | H38: 0 | I38: 3 | J38: 2 | K38: 0 | L38: 0 | M38: 115 | N38: 0 | O38: =SUM(C38:L38,N38) -> 49 | P38: =SUM(C38:N38) -> 164
B39: 14.15 - 14.30 | C39: 31 | D39: 6 | E39: 0 | F39: 13 | G39: 1 | H39: 0 | I39: 3 | J39: 5 | K39: 1 | L39: 3 | M39: 138 | N39: 0 | O39: =SUM(C39:L39,N39) -> 63 | P39: =SUM(C39:N39) -> 201
B40: 14.30 - 14.45 | C40: 35 | D40: 5 | E40: 1 | F40: 14 | G40: 0 | H40: 0 | I40: 6 | J40: 5 | K40: 0 | L40: 0 | M40: 150 | N40: 0 | O40: =SUM(C40:L40,N40) -> 66 | P40: =SUM(C40:N40) -> 216
... B57: 18.45 - 19.00 | C57: 88 | D57: 12 | E57: 17 | F57: 6 | G57: 0 | H57: 0 | I57: 0 | J57: 3 | K57: 0 | L57: 0 | M57: 166 | N57: 0 | O57: =SUM(C57:L57,N57) -> 126 | P57: =SUM(C57:N57) -> 292
B58: Totals | C58: =SUM(C10:C57) -> 1788 | D58: =SUM(D10:D57) -> 325 | E58: =SUM(E10:E57) -> 162 | F58: =SUM(F10:F57) -> 787 | G58: =SUM(G10:G57) -> 32 | H58: =SUM(H10:H57) -> 11 | I58: =SUM(I10:I57) -> 183 | J58: =SUM(J10:J57) -> 149 | ... P58: =SUM(P10:P57) -> 10983
...

Sheet 22.07 KABUSU-RUBAGA
B1: Consultancy services for Preparation of Expressway Development Master Plan (EDMP) for Uganda
B2: MANUAL CLASSIFIED COUNT (MCC)
B3: ROAD NAME: | C3: ='22.07 RUBAGA-KABUSU'!C3:G3 -> MCC - C1 - STN05 - KABUSU ROAD
C5: Date | D5: ='22.07 RUBAGA-KABUSU'!D5 -> 22.07.19 | F5: Location | G5: ='22.07 RUBAGA-KABUSU'!G5:H5 -> CHAD SUPERMARKET | J5: Surveyor | K5: MBERE IVAN
C6: Dir. From | D6: KABUSU | F6: Dir. To | G6: RUBAGA | J6: Supervisor | K6: ='22.07 RUBAGA-KABUSU'!K6:L6 -> DENIS
B8: Time / Veh Type | R8: SUMMARY TRAFFIC VOLUMES
C9: 1. Car | D9: 2. Station Wagon | E9: 3. Pickups | F9: 4. Minibus, matatu | G9: 5. Medium bus | H9: 6. Large Bus | I9: 7. Light Truck | J9: 8. Medium Truck | K9: 9. Heavy truck | L9: 10. Truck Trailer | M9: 11. Motor cycles | N9: 12. Tractors | O9: Total Excl M/Cycles | P9: Total All | R9: Time | S9: 1. Car | T9: 2. Station Wagon | U9: 3. Pickups | V9: 4. Minibus, matatu | W9: 5. Medium bus | X9: 6. Large Bus | Y9: 7. Light Truck | Z9: 8. Medium Truck | AA9: 9. Heavy truck | AB9: 10. Truck Trailer | AC9: 11. Motorcycles | AD9: 12. Tractors, Graders | AE9: Total Excl M/ Cycles | AF9: Total All
B10: 07.00 - 07.15 | C10: 35 | D10: 25 | E10: 1 | F10: 26 | G10: 0 | H10: 1 | I10: 1 | J10: 0 | K10: 0 | L10: 0 | M10: 146 | N10: 0 | O10: =SUM(C10:L10,N10) -> 89 | P10: =SUM(C10:N10) -> 235 | R10: 0700-0800 | S10: =SUM(C10:C13) -> 160 | T10: =SUM(D10:D13) -> 111 | U10: =SUM(E10:E13) -> 7 | V10: =SUM(F10:F13) -> 102 | W10: =SUM(G10:G13) -> 1 | X10: =SUM(H10:H13) -> 1 | Y10: =SUM(I10:I13) -> 11 | Z10: =SUM(J10:J13) -> 2 | ... AF10: =SUM(P10:P13) -> 1131
B11: 07.15 - 07.30 | C11: 11 | D11: 4 | E11: 2 | F11: 2 | G11: 0 | H11: 0 | I11: 1 | J11: 0 | K11: 0 | L11: 0 | M11: 155 | N11: 0 | O11: =SUM(C11:L11,N11) -> 20 | P11: =SUM(C11:N11) -> 175 | R11: 0800-0900 | S11: =SUM(C14:C17) -> 153 | T11: =SUM(D14:D17) -> 176 | U11: =SUM(E14:E17) -> 24 | V11: =SUM(F14:F17) -> 129 | W11: =SUM(G14:G17) -> 0 | X11: =SUM(H14:H17) -> 0 | Y11: =SUM(I14:I17) -> 21 | Z11: =SUM(J14:J17) -> 4 | ... AF11: =SUM(P14:P17) -> 1589
B12: 07.30 - 07.45 | C12: 54 | D12: 28 | E12: 2 | F12: 29 | G12: 0 | H12: 0 | I12: 3 | J12: 1 | K12: 0 | L12: 0 | M12: 175 | N12: 0 | O12: =SUM(C12:L12,N12) -> 117 | P12: =SUM(C12:N12) -> 292 | R12: 0900-1000 | S12: =SUM(C18:C21) -> 158 | T12: =SUM(D18:D21) -> 136 | U12: =SUM(E18:E21) -> 29 | V12: =SUM(F18:F21) -> 89 | W12: =SUM(G18:G21) -> 1 | X12: =SUM(H18:H21) -> 0 | Y12: =SUM(I18:I21) -> 21 | Z12: =SUM(J18:J21) -> 12 | ... AF12: =SUM(P18:P21) -> 1408
B13: 07.45 - 08.00 | C13: 60 | D13: 54 | E13: 2 | F13: 45 | G13: 1 | H13: 0 | I13: 6 | J13: 1 | K13: 0 | L13: 0 | M13: 260 | N13: 0 | O13: =SUM(C13:L13,N13) -> 169 | P13: =SUM(C13:N13) -> 429 | R13: 1000-1100 | S13: =SUM(C22:C25) -> 132 | T13: =SUM(D22:D25) -> 117 | U13: =SUM(E22:E25) -> 40 | V13: =SUM(F22:F25) -> 108 | W13: =SUM(G22:G25) -> 0 | X13: =SUM(H22:H25) -> 0 | Y13: =SUM(I22:I25) -> 21 | Z13: =SUM(J22:J25) -> 5 | ... AF13: =SUM(P22:P25) -> 1097
B14: 08.00 - 08.15 | C14: 40 | D14: 58 | E14: 6 | F14: 38 | G14: 0 | H14: 0 | I14: 5 | J14: 2 | K14: 0 | L14: 0 | M14: 320 | N14: 0 | O14: =SUM(C14:L14,N14) -> 149 | P14: =SUM(C14:N14) -> 469 | R14: 1100-1200 | S14: =SUM(C26:C29) -> 109 | T14: =SUM(D26:D29) -> 79 | U14: =SUM(E26:E29) -> 23 | V14: =SUM(F26:F29) -> 125 | W14: =SUM(G26:G29) -> 2 | X14: =SUM(H26:H29) -> 0 | Y14: =SUM(I26:I29) -> 14 | Z14: =SUM(J26:J29) -> 6 | ... AF14: =SUM(P26:P29) -> 1034
B15: 08.15 - 08.30 | C15: 35 | D15: 30 | E15: 3 | F15: 26 | G15: 0 | H15: 0 | I15: 5 | J15: 2 | K15: 1 | L15: 0 | M15: 261 | N15: 0 | O15: =SUM(C15:L15,N15) -> 102 | P15: =SUM(C15:N15) -> 363 | R15: 1200-1300 | S15: =SUM(C30:C33) -> 111 | T15: =SUM(D30:D33) -> 113 | U15: =SUM(E30:E33) -> 11 | V15: =SUM(F30:F33) -> 127 | W15: =SUM(G30:G33) -> 2 | X15: =SUM(H30:H33) -> 1 | Y15: =SUM(I30:I33) -> 15 | Z15: =SUM(J30:J33) -> 7 | ... AF15: =SUM(P30:P33) -> 1141
B16: 08.30 - 08.45 | C16: 42 | D16: 46 | E16: 3 | F16: 36 | G16: 0 | H16: 0 | I16: 10 | J16: 0 | K16: 1 | L16: 0 | M16: 299 | N16: 0 | O16: =SUM(C16:L16,N16) -> 138 | P16: =SUM(C16:N16) -> 437 | R16: 1300-1400 | S16: =SUM(C34:C37) -> 92 | T16: =SUM(D34:D37) -> 71 | U16: =SUM(E34:E37) -> 26 | V16: =SUM(F34:F37) -> 113 | W16: =SUM(G34:G37) -> 1 | X16: =SUM(H34:H37) -> 2 | Y16: =SUM(I34:I37) -> 17 | Z16: =SUM(J34:J37) -> 4 | ... AF16: =SUM(P34:P37) -> 927
B17: 08.45 - 9.00 | C17: 36 | D17: 42 | E17: 12 | F17: 29 | G17: 0 | H17: 0 | I17: 1 | J17: 0 | K17: 0 | L17: 0 | M17: 200 | N17: 0 | O17: =SUM(C17:L17,N17) -> 120 | P17: =SUM(C17:N17) -> 320 | R17: 1400-1500 | S17: =SUM(C38:C41) -> 85 | T17: =SUM(D38:D41) -> 68 | U17: =SUM(E38:E41) -> 13 | V17: =SUM(F38:F41) -> 72 | W17: =SUM(G38:G41) -> 2 | X17: =SUM(H38:H41) -> 3 | Y17: =SUM(I38:I41) -> 18 | Z17: =SUM(J38:J41) -> 12 | ... AF17: =SUM(P38:P41) -> 878
B18: 09.00 - 09.15 | C18: 41 | D18: 34 | E18: 8 | F18: 25 | G18: 1 | H18: 0 | I18: 6 | J18: 0 | K18: 0 | L18: 0 | M18: 232 | N18: 0 | O18: =SUM(C18:L18,N18) -> 115 | P18: =SUM(C18:N18) -> 347 | R18: 1500-1600 | S18: =SUM(C42:C45) -> 89 | T18: =SUM(D42:D45) -> 73 | U18: =SUM(E42:E45) -> 16 | V18: =SUM(F42:F45) -> 79 | W18: =SUM(G42:G45) -> 2 | X18: =SUM(H42:H45) -> 2 | Y18: =SUM(I42:I45) -> 24 | Z18: =SUM(J42:J45) -> 10 | ... AF18: =SUM(P42:P45) -> 523
B19: 09.15 - 09.30 | C19: 35 | D19: 31 | E19: 8 | F19: 2 | G19: 0 | H19: 0 | I19: 5 | J19: 4 | K19: 0 | L19: 0 | M19: 207 | N19: 0 | O19: =SUM(C19:L19,N19) -> 85 | P19: =SUM(C19:N19) -> 292 | R19: 1600-1700 | S19: =SUM(C46:C49) -> 96 | T19: =SUM(D46:D49) -> 88 | U19: =SUM(E46:E49) -> 18 | V19: =SUM(F46:F49) -> 91 | W19: =SUM(G46:G49) -> 1 | X19: =SUM(H46:H49) -> 2 | Y19: =SUM(I46:I49) -> 20 | Z19: =SUM(J46:J49) -> 4 | ... AF19: =SUM(P46:P49) -> 1070
B20: 09.30 - 09.45 | C20: 49 | D20: 41 | E20: 7 | F20: 26 | G20: 0 | H20: 0 | I20: 4 | J20: 4 | K20: 0 | L20: 1 | M20: 260 | N20: 0 | O20: =SUM(C20:L20,N20) -> 132 | P20: =SUM(C20:N20) -> 392 | R20: 1700-1800 | S20: =SUM(C50:C53) -> 104 | T20: =SUM(D50:D53) -> 99 | U20: =SUM(E50:E53) -> 15 | V20: =SUM(F50:F53) -> 108 | W20: =SUM(G50:G53) -> 1 | X20: =SUM(H50:H53) -> 0 | Y20: =SUM(I50:I53) -> 26 | Z20: =SUM(J50:J53) -> 6 | ... AF20: =SUM(P50:P53) -> 1184
B21: 09.45 - 10.00 | C21: 33 | D21: 30 | E21: 6 | F21: 36 | G21: 0 | H21: 0 | I21: 6 | J21: 4 | K21: 0 | L21: 1 | M21: 261 | N21: 0 | O21: =SUM(C21:L21,N21) -> 116 | P21: =SUM(C21:N21) -> 377 | R21: 1800-1900 | S21: =SUM(C54:C57) -> 100 | T21: =SUM(D54:D57) -> 78 | U21: =SUM(E54:E57) -> 20 | V21: =SUM(F54:F57) -> 134 | W21: =SUM(G54:G57) -> 5 | X21: =SUM(H54:H57) -> 5 | Y21: =SUM(I54:I57) -> 16 | Z21: =SUM(J54:J57) -> 7 | ... AF21: =SUM(P54:P57) -> 1399
B22: 10.00 - 10.15 | C22: 28 | D22: 29 | E22: 10 | F22: 34 | G22: 0 | H22: 0 | I22: 3 | J22: 2 | K22: 0 | L22: 0 | M22: 115 | N22: 0 | O22: =SUM(C22:L22,N22) -> 106 | P22: =SUM(C22:N22) -> 221 | R22: AM Peak Hr | S22: =MAX(S10:S12) -> 160 | T22: =MAX(T10:T12) -> 176 | U22: =MAX(U10:U12) -> 29 | V22: =MAX(V10:V12) -> 129 | W22: =MAX(W10:W12) -> 1 | X22: =MAX(X10:X12) -> 1 | Y22: =MAX(Y10:Y12) -> 21 | Z22: =MAX(Z10:Z12) -> 12 | ... AF22: =MAX(AF10:AF12) -> 1589
B23: 10.15 - 10.30 | C23: 32 | D23: 26 | E23: 11 | F23: 21 | G23: 0 | H23: 0 | I23: 6 | J23: 0 | K23: 0 | L23: 0 | M23: 214 | N23: 0 | O23: =SUM(C23:L23,N23) -> 96 | P23: =SUM(C23:N23) -> 310 | R23: IP Peak Hr | S23: =MAX(S13:S18) -> 132 | T23: =MAX(T13:T18) -> 117 | U23: =MAX(U13:U18) -> 40 | V23: =MAX(V13:V18) -> 127 | W23: =MAX(W13:W18) -> 2 | X23: =MAX(X13:X18) -> 3 | Y23: =MAX(Y13:Y18) -> 24 | Z23: =MAX(Z13:Z18) -> 12 | ... AF23: =MAX(AF13:AF18) -> 1141
B24: 10.30 - 10.45 | C24: 29 | D24: 29 | E24: 13 | F24: 26 | G24: 0 | H24: 0 | I24: 4 | J24: 3 | K24: 1 | L24: 0 | M24: 157 | N24: 0 | O24: =SUM(C24:L24,N24) -> 105 | P24: =SUM(C24:N24) -> 262 | R24: PM Peak Hr | S24: =MAX(S19:S21) -> 104 | T24: =MAX(T19:T21) -> 99 | U24: =MAX(U19:U21) -> 20 | V24: =MAX(V19:V21) -> 134 | W24: =MAX(W19:W21) -> 5 | X24: =MAX(X19:X21) -> 5 | Y24: =MAX(Y19:Y21) -> 26 | Z24: =MAX(Z19:Z21) -> 7 | ... AF24: =MAX(AF19:AF21) -> 1399
B25: 10.45 - 11.00 | C25: 43 | D25: 33 | E25: 6 | F25: 27 | G25: 0 | H25: 0 | I25: 8 | J25: 0 | K25: 1 | L25: 1 | M25: 185 | N25: 0 | O25: =SUM(C25:L25,N25) -> 119 | P25: =SUM(C25:N25) -> 304 | R25: AM Period | S25: =SUM(S10:S12) -> 471 | T25: =SUM(T10:T12) -> 423 | U25: =SUM(U10:U12) -> 60 | V25: =SUM(V10:V12) -> 320 | W25: =SUM(W10:W12) -> 2 | X25: =SUM(X10:X12) -> 1 | Y25: =SUM(Y10:Y12) -> 53 | Z25: =SUM(Z10:Z12) -> 18 | ... AF25: =SUM(AF10:AF12) -> 4128
B26: 11.00 - 11.15 | C26: 27 | D26: 21 | E26: 8 | F26: 37 | G26: 0 | H26: 0 | I26: 6 | J26: 2 | K26: 1 | L26: 1 | M26: 175 | N26: 0 | O26: =SUM(C26:L26,N26) -> 103 | P26: =SUM(C26:N26) -> 278 | R26: IP Period | S26: =SUM(S13:S18) -> 618 | T26: =SUM(T13:T18) -> 521 | U26: =SUM(U13:U18) -> 129 | V26: =SUM(V13:V18) -> 624 | W26: =SUM(W13:W18) -> 9 | X26: =SUM(X13:X18) -> 8 | Y26: =SUM(Y13:Y18) -> 109 | Z26: =SUM(Z13:Z18) -> 44 | ... AF26: =SUM(AF13:AF18) -> 5600
B27: 11.15 - 11.30 | C27: 37 | D27: 11 | E27: 5 | F27: 27 | G27: 0 | H27: 0 | I27: 0 | J27: 0 | K27: 0 | L27: 0 | M27: 144 | N27: 0 | O27: =SUM(C27:L27,N27) -> 80 | P27: =SUM(C27:N27) -> 224 | R27: PM Period | S27: =SUM(S19:S21) -> 300 | T27: =SUM(T19:T21) -> 265 | U27: =SUM(U19:U21) -> 53 | V27: =SUM(V19:V21) -> 333 | W27: =SUM(W19:W21) -> 7 | X27: =SUM(X19:X21) -> 7 | Y27: =SUM(Y19:Y21) -> 62 | Z27: =SUM(Z19:Z21) -> 17 | ... AF27: =SUM(AF19:AF21) -> 3653
B28: 11.30 - 11.45 | C28: 23 | D28: 28 | E28: 9 | F28: 36 | G28: 0 | H28: 0 | I28: 5 | J28: 3 | K28: 1 | L28: 0 | M28: 161 | N28: 0 | O28: =SUM(C28:L28,N28) -> 105 | P28: =SUM(C28:N28) -> 266 | R28: 12 Hours | S28: =SUM(S10:S21) -> 1389 | T28: =SUM(T10:T21) -> 1209 | U28: =SUM(U10:U21) -> 242 | V28: =SUM(V10:V21) -> 1277 | W28: =SUM(W10:W21) -> 18 | X28: =SUM(X10:X21) -> 16 | Y28: =SUM(Y10:Y21) -> 224 | Z28: =SUM(Z10:Z21) -> 79 | ... AF28: =SUM(AF10:AF21) -> 13381
B29: 11.45 - 12.00 | C29: 22 | D29: 19 | E29: 1 | F29: 25 | G29: 2 | H29: 0 | I29: 3 | J29: 1 | K29: 1 | L29: 1 | M29: 191 | N29: 0 | O29: =SUM(C29:L29,N29) -> 75 | P29: =SUM(C29:N29) -> 266
B30: 12.00 - 12.15 | C30: 27 | D30: 36 | E30: 0 | F30: 30 | G30: 1 | H30: 0 | I30: 3 | J30: 3 | K30: 1 | L30: 0 | M30: 189 | N30: 0 | O30: =SUM(C30:L30,N30) -> 101 | P30: =SUM(C30:N30) -> 290
B31: 12.15 - 12.30 | C31: 28 | D31: 28 | E31: 2 | F31: 30 | G31: 0 | H31: 1 | I31: 5 | J31: 1 | K31: 1 | L31: 0 | M31: 185 | N31: 0 | O31: =SUM(C31:L31,N31) -> 96 | P31: =SUM(C31:N31) -> 281
B32: 12.30 - 12.45 | C32: 33 | D32: 30 | E32: 4 | F32: 36 | G32: 1 | H32: 0 | I32: 4 | J32: 1 | K32: 0 | L32: 1 | M32: 200 | N32: 0 | O32: =SUM(C32:L32,N32) -> 110 | P32: =SUM(C32:N32) -> 310
B33: 12.45 - 13.00 | C33: 23 | D33: 19 | E33: 5 | F33: 31 | G33: 0 | H33: 0 | I33: 3 | J33: 2 | K33: 3 | L33: 0 | M33: 174 | N33: 0 | O33: =SUM(C33:L33,N33) -> 86 | P33: =SUM(C33:N33) -> 260
B34: 13.00 - 13.15 | C34: 21 | D34: 16 | E34: 5 | F34: 28 | G34: 0 | H34: 1 | I34: 6 | J34: 1 | K34: 1 | L34: 0 | M34: 181 | N34: 0 | O34: =SUM(C34:L34,N34) -> 79 | P34: =SUM(C34:N34) -> 260
B35: 13.15 - 13.30 | C35: 27 | D35: 18 | E35: 8 | F35: 37 | G35: 0 | H35: 0 | I35: 2 | J35: 3 | K35: 1 | L35: 2 | M35: 138 | N35: 0 | O35: =SUM(C35:L35,N35) -> 98 | P35: =SUM(C35:N35) -> 236
B36: 13.30 - 13.45 | C36: 23 | D36: 17 | E36: 5 | F36: 24 | G36: 1 | H36: 1 | I36: 6 | J36: 0 | K36: 1 | L36: 1 | M36: 150 | N36: 0 | O36: =SUM(C36:L36,N36) -> 79 | P36: =SUM(C36:N36) -> 229
B37: 13.45 - 14.00 | C37: 21 | D37: 20 | E37: 8 | F37: 24 | G37: 0 | H37: 0 | I37: 3 | J37: 0 | K37: 1 | L37: 0 | M37: 125 | N37: 0 | O37: =SUM(C37:L37,N37) -> 77 | P37: =SUM(C37:N37) -> 202
B38: 14.00 - 14.15 | C38: 17 | D38: 14 | E38: 1 | F38: 13 | G38: 1 | H38: 1 | I38: 4 | J38: 3 | K38: 0 | L38: 0 | M38: 165 | N38: 0 | O38: =SUM(C38:L38,N38) -> 54 | P38: =SUM(C38:N38) -> 219
B39: 14.15 - 14.30 | C39: 18 | D39: 14 | E39: 5 | F39: 19 | G39: 0 | H39: 0 | I39: 6 | J39: 5 | K39: 0 | L39: 1 | M39: 135 | N39: 0 | O39: =SUM(C39:L39,N39) -> 68 | P39: =SUM(C39:N39) -> 203
B40: 14.30 - 14.45 | C40: 29 | D40: 14 | E40: 4 | F40: 18 | G40: 0 | H40: 0 | I40: 2 | J40: 4 | K40: 3 | L40: 0 | M40: 168 | N40: 0 | O40: =SUM(C40:L40,N40) -> 74 | P40: =SUM(C40:N40) -> 242
... B57: 18.45 - 19.00 | C57: 13 | D57: 18 | E57: 8 | F57: 29 | G57: 0 | H57: 0 | I57: 2 | J57: 2 | K57: 2 | L57: 0 | M57: 270 | N57: 0 | O57: =SUM(C57:L57,N57) -> 74 | P57: =SUM(C57:N57) -> 344
B58: Totals | C58: =SUM(C10:C57) -> 1389 | D58: =SUM(D10:D57) -> 1209 | E58: =SUM(E10:E57) -> 242 | F58: =SUM(F10:F57) -> 1277 | G58: =SUM(G10:G57) -> 18 | H58: =SUM(H10:H57) -> 16 | I58: =SUM(I10:I57) -> 224 | J58: =SUM(J10:J57) -> 79 | ... P58: =SUM(P10:P57) -> 13381
...

Sheet 23.07 RUBAGA-KABUSU
B1: Consultancy services for Preparation of Expressway Development Master Plan (EDMP) for Uganda
B2: MANUAL CLASSIFIED COUNT (MCC)
B3: ROAD NAME: | C3: ='22.07 RUBAGA-KABUSU'!C3:G3 -> MCC - C1 - STN05 - KABUSU ROAD
C5: Date | D5: 23.07.19 | F5: Location | G5: ='22.07 RUBAGA-KABUSU'!G5:H5 -> CHAD SUPERMARKET | J5: Surveyor | K5: ='22.07 RUBAGA-KABUSU'!K5:L5 -> EMMANUEL EGIMU
C6: Dir. From | D6: ='22.07 RUBAGA-KABUSU'!D6:E6 -> RUBAGA | F6: Dir. To | G6: ='22.07 RUBAGA-KABUSU'!G6:H6 -> KABUSU | J6: Supervisor | K6: ='22.07 RUBAGA-KABUSU'!K6:L6 -> DENIS
B8: Time / Veh Type | R8: SUMMARY TRAFFIC VOLUMES
C9: 1. Car | D9: 2. Station Wagon | E9: 3. Pickups | F9: 4. Minibus, matatu | G9: 5. Medium bus | H9: 6. Large Bus | I9: 7. Light Truck | J9: 8. Medium Truck | K9: 9. Heavy truck | L9: 10. Truck Trailer | M9: 11. Motor cycles | N9: 12. Tractors | O9: Total Excl M/Cycles | P9: Total All | R9: Time | S9: 1. Car | T9: 2. Station Wagon | U9: 3. Pickups | V9: 4. Minibus, matatu | W9: 5. Medium bus | X9: 6. Large Bus | Y9: 7. Light Truck | Z9: 8. Medium Truck | AA9: 9. Heavy truck | AB9: 10. Truck Trailer | AC9: 11. Motorcycles | AD9: 12. Tractors, Graders | AE9: Total Excl M/ Cycles | AF9: Total All
B10: 07.00 - 07.15 | C10: 33 | D10: 6 | E10: 4 | F10: 32 | G10: 0 | H10: 0 | I10: 0 | J10: 0 | K10: 0 | L10: 0 | M10: 85 | N10: 0 | O10: =SUM(C10:L10,N10) -> 75 | P10: =SUM(C10:N10) -> 160 | R10: 0700-0800 | S10: =SUM(C10:C13) -> 130 | T10: =SUM(D10:D13) -> 18 | U10: =SUM(E10:E13) -> 9 | V10: =SUM(F10:F13) -> 108 | W10: =SUM(G10:G13) -> 1 | X10: =SUM(H10:H13) -> 2 | Y10: =SUM(I10:I13) -> 2 | Z10: =SUM(J10:J13) -> 9 | ... AF10: =SUM(P10:P13) -> 809
B11: 07.15 - 07.30 | C11: 31 | D11: 4 | E11: 1 | F11: 30 | G11: 0 | H11: 1 | I11: 1 | J11: 4 | K11: 0 | L11: 0 | M11: 122 | N11: 0 | O11: =SUM(C11:L11,N11) -> 72 | P11: =SUM(C11:N11) -> 194 | R11: 0800-0900 | S11: =SUM(C14:C17) -> 74 | T11: =SUM(D14:D17) -> 13 | U11: =SUM(E14:E17) -> 9 | V11: =SUM(F14:F17) -> 67 | W11: =SUM(G14:G17) -> 3 | X11: =SUM(H14:H17) -> 2 | Y11: =SUM(I14:I17) -> 6 | Z11: =SUM(J14:J17) -> 9 | ... AF11: =SUM(P14:P17) -> 928
B12: 07.30 - 07.45 | C12: 28 | D12: 4 | E12: 2 | F12: 17 | G12: 0 | H12: 1 | I12: 0 | J12: 2 | K12: 0 | L12: 0 | M12: 173 | N12: 0 | O12: =SUM(C12:L12,N12) -> 54 | P12: =SUM(C12:N12) -> 227 | R12: 0900-1000 | S12: =SUM(C18:C21) -> 80 | T12: =SUM(D18:D21) -> 22 | U12: =SUM(E18:E21) -> 7 | V12: =SUM(F18:F21) -> 68 | W12: =SUM(G18:G21) -> 1 | X12: =SUM(H18:H21) -> 0 | Y12: =SUM(I18:I21) -> 6 | Z12: =SUM(J18:J21) -> 21 | ... AF12: =SUM(P18:P21) -> 919
B13: 07.45 - 08.00 | C13: 38 | D13: 4 | E13: 2 | F13: 29 | G13: 1 | H13: 0 | I13: 1 | J13: 3 | K13: 0 | L13: 0 | M13: 150 | N13: 0 | O13: =SUM(C13:L13,N13) -> 78 | P13: =SUM(C13:N13) -> 228 | R13: 1000-1100 | S13: =SUM(C22:C25) -> 113 | T13: =SUM(D22:D25) -> 18 | U13: =SUM(E22:E25) -> 18 | V13: =SUM(F22:F25) -> 74 | W13: =SUM(G22:G25) -> 1 | X13: =SUM(H22:H25) -> 0 | Y13: =SUM(I22:I25) -> 15 | Z13: =SUM(J22:J25) -> 13 | ... AF13: =SUM(P22:P25) -> 827
B14: 08.00 - 08.15 | C14: 15 | D14: 2 | E14: 3 | F14: 13 | G14: 1 | H14: 0 | I14: 1 | J14: 3 | K14: 0 | L14: 1 | M14: 207 | N14: 0 | O14: =SUM(C14:L14,N14) -> 39 | P14: =SUM(C14:N14) -> 246 | R14: 1100-1200 | S14: =SUM(C26:C29) -> 115 | T14: =SUM(D26:D29) -> 30 | U14: =SUM(E26:E29) -> 22 | V14: =SUM(F26:F29) -> 53 | W14: =SUM(G26:G29) -> 2 | X14: =SUM(H26:H29) -> 1 | Y14: =SUM(I26:I29) -> 13 | Z14: =SUM(J26:J29) -> 18 | ... AF14: =SUM(P26:P29) -> 916
B15: 08.15 - 08.30 | C15: 20 | D15: 5 | E15: 1 | F15: 18 | G15: 1 | H15: 0 | I15: 0 | J15: 1 | K15: 0 | L15: 0 | M15: 199 | N15: 0 | O15: =SUM(C15:L15,N15) -> 46 | P15: =SUM(C15:N15) -> 245 | R15: 1200-1300 | S15: =SUM(C30:C33) -> 111 | T15: =SUM(D30:D33) -> 26 | U15: =SUM(E30:E33) -> 15 | V15: =SUM(F30:F33) -> 69 | W15: =SUM(G30:G33) -> 4 | X15: =SUM(H30:H33) -> 1 | Y15: =SUM(I30:I33) -> 14 | Z15: =SUM(J30:J33) -> 23 | ... AF15: =SUM(P30:P33) -> 734
B16: 08.30 - 08.45 | C16: 17 | D16: 6 | E16: 1 | F16: 22 | G16: 0 | H16: 2 | I16: 3 | J16: 4 | K16: 1 | L16: 1 | M16: 150 | N16: 0 | O16: =SUM(C16:L16,N16) -> 57 | P16: =SUM(C16:N16) -> 207 | R16: 1300-1400 | S16: =SUM(C34:C37) -> 119 | T16: =SUM(D34:D37) -> 21 | U16: =SUM(E34:E37) -> 13 | V16: =SUM(F34:F37) -> 63 | W16: =SUM(G34:G37) -> 1 | X16: =SUM(H34:H37) -> 0 | Y16: =SUM(I34:I37) -> 13 | Z16: =SUM(J34:J37) -> 21 | ... AF16: =SUM(P34:P37) -> 759
B17: 08.45 - 9.00 | C17: 22 | D17: 0 | E17: 4 | F17: 14 | G17: 1 | H17: 0 | I17: 2 | J17: 1 | K17: 1 | L17: 0 | M17: 185 | N17: 0 | O17: =SUM(C17:L17,N17) -> 45 | P17: =SUM(C17:N17) -> 230 | R17: 1400-1500 | S17: =SUM(C38:C41) -> 115 | T17: =SUM(D38:D41) -> 15 | U17: =SUM(E38:E41) -> 21 | V17: =SUM(F38:F41) -> 53 | W17: =SUM(G38:G41) -> 1 | X17: =SUM(H38:H41) -> 0 | Y17: =SUM(I38:I41) -> 7 | Z17: =SUM(J38:J41) -> 10 | ... AF17: =SUM(P38:P41) -> 757
B18: 09.00 - 09.15 | C18: 25 | D18: 4 | E18: 2 | F18: 15 | G18: 0 | H18: 0 | I18: 3 | J18: 4 | K18: 0 | L18: 2 | M18: 210 | N18: 0 | O18: =SUM(C18:L18,N18) -> 55 | P18: =SUM(C18:N18) -> 265 | R18: 1500-1600 | S18: =SUM(C42:C45) -> 158 | T18: =SUM(D42:D45) -> 25 | U18: =SUM(E42:E45) -> 10 | V18: =SUM(F42:F45) -> 46 | W18: =SUM(G42:G45) -> 0 | X18: =SUM(H42:H45) -> 1 | Y18: =SUM(I42:I45) -> 18 | Z18: =SUM(J42:J45) -> 19 | ... AF18: =SUM(P42:P45) -> 868
B19: 09.15 - 09.30 | C19: 15 | D19: 13 | E19: 1 | F19: 24 | G19: 0 | H19: 0 | I19: 1 | J19: 7 | K19: 0 | L19: 0 | M19: 164 | N19: 0 | O19: =SUM(C19:L19,N19) -> 61 | P19: =SUM(C19:N19) -> 225 | R19: 1600-1700 | S19: =SUM(C46:C49) -> 199 | T19: =SUM(D46:D49) -> 26 | U19: =SUM(E46:E49) -> 19 | V19: =SUM(F46:F49) -> 50 | W19: =SUM(G46:G49) -> 2 | X19: =SUM(H46:H49) -> 1 | Y19: =SUM(I46:I49) -> 15 | Z19: =SUM(J46:J49) -> 10 | ... AF19: =SUM(P46:P49) -> 916
B20: 09.30 - 09.45 | C20: 20 | D20: 0 | E20: 2 | F20: 12 | G20: 0 | H20: 0 | I20: 2 | J20: 3 | K20: 0 | L20: 0 | M20: 170 | N20: 0 | O20: =SUM(C20:L20,N20) -> 39 | P20: =SUM(C20:N20) -> 209 | R20: 1700-1800 | S20: =SUM(C50:C53) -> 294 | T20: =SUM(D50:D53) -> 39 | U20: =SUM(E50:E53) -> 11 | V20: =SUM(F50:F53) -> 45 | W20: =SUM(G50:G53) -> 0 | X20: =SUM(H50:H53) -> 0 | Y20: =SUM(I50:I53) -> 11 | Z20: =SUM(J50:J53) -> 14 | ... AF20: =SUM(P50:P53) -> 1121
B21: 09.45 - 10.00 | C21: 20 | D21: 5 | E21: 2 | F21: 17 | G21: 1 | H21: 0 | I21: 0 | J21: 7 | K21: 1 | L21: 167 | M21: 0 | N21: 0 | O21: =SUM(C21:L21,N21) -> 220 | P21: =SUM(C21:N21) -> 220 | R21: 1800-1900 | S21: =SUM(C54:C57) -> 233 | T21: =SUM(D54:D57) -> 64 | U21: =SUM(E54:E57) -> 15 | V21: =SUM(F54:F57) -> 21 | W21: =SUM(G54:G57) -> 0 | X21: =SUM(H54:H57) -> 0 | Y21: =SUM(I54:I57) -> 13 | Z21: =SUM(J54:J57) -> 14 | ... AF21: =SUM(P54:P57) -> 910
B22: 10.00 - 10.15 | C22: 32 | D22: 6 | E22: 5 | F22: 20 | G22: 1 | H22: 0 | I22: 0 | J22: 6 | K22: 0 | L22: 0 | M22: 203 | N22: 0 | O22: =SUM(C22:L22,N22) -> 70 | P22: =SUM(C22:N22) -> 273 | R22: AM Peak Hr | S22: =MAX(S10:S12) -> 130 | T22: =MAX(T10:T12) -> 22 | U22: =MAX(U10:U12) -> 9 | V22: =MAX(V10:V12) -> 108 | W22: =MAX(W10:W12) -> 3 | X22: =MAX(X10:X12) -> 2 | Y22: =MAX(Y10:Y12) -> 6 | Z22: =MAX(Z10:Z12) -> 21 | ... AF22: =MAX(AF10:AF12) -> 928
B23: 10.15 - 10.30 | C23: 23 | D23: 9 | E23: 3 | F23: 20 | G23: 0 | H23: 0 | I23: 5 | J23: 3 | K23: 2 | L23: 0 | M23: 145 | N23: 0 | O23: =SUM(C23:L23,N23) -> 65 | P23: =SUM(C23:N23) -> 210 | R23: IP Peak Hr | S23: =MAX(S13:S18) -> 158 | T23: =MAX(T13:T18) -> 30 | U23: =MAX(U13:U18) -> 22 | V23: =MAX(V13:V18) -> 74 | W23: =MAX(W13:W18) -> 4 | X23: =MAX(X13:X18) -> 1 | Y23: =MAX(Y13:Y18) -> 18 | Z23: =MAX(Z13:Z18) -> 23 | ... AF23: =MAX(AF13:AF18) -> 916
B24: 10.30 - 10.45 | C24: 26 | D24: 1 | E24: 4 | F24: 16 | G24: 0 | H24: 0 | I24: 4 | J24: 2 | K24: 0 | L24: 0 | M24: 123 | N24: 0 | O24: =SUM(C24:L24,N24) -> 53 | P24: =SUM(C24:N24) -> 176 | R24: PM Peak Hr | S24: =MAX(S19:S21) -> 294 | T24: =MAX(T19:T21) -> 64 | U24: =MAX(U19:U21) -> 19 | V24: =MAX(V19:V21) -> 50 | W24: =MAX(W19:W21) -> 2 | X24: =MAX(X19:X21) -> 1 | Y24: =MAX(Y19:Y21) -> 15 | Z24: =MAX(Z19:Z21) -> 14 | ... AF24: =MAX(AF19:AF21) -> 1121
B25: 10.45 - 11.00 | C25: 32 | D25: 2 | E25: 6 | F25: 18 | G25: 0 | H25: 0 | I25: 6 | J25: 2 | K25: 0 | L25: 0 | M25: 102 | N25: 0 | O25: =SUM(C25:L25,N25) -> 66 | P25: =SUM(C25:N25) -> 168 | R25: AM Period | S25: =SUM(S10:S12) -> 284 | T25: =SUM(T10:T12) -> 53 | U25: =SUM(U10:U12) -> 25 | V25: =SUM(V10:V12) -> 243 | W25: =SUM(W10:W12) -> 5 | X25: =SUM(X10:X12) -> 4 | Y25: =SUM(Y10:Y12) -> 14 | Z25: =SUM(Z10:Z12) -> 39 | ... AF25: =SUM(AF10:AF12) -> 2656
B26: 11.00 - 11.15 | C26: 28 | D26: 7 | E26: 4 | F26: 13 | G26: 0 | H26: 1 | I26: 5 | J26: 8 | K26: 2 | L26: 2 | M26: 111 | N26: 0 | O26: =SUM(C26:L26,N26) -> 70 | P26: =SUM(C26:N26) -> 181 | R26: IP Period | S26: =SUM(S13:S18) -> 731 | T26: =SUM(T13:T18) -> 135 | U26: =SUM(U13:U18) -> 99 | V26: =SUM(V13:V18) -> 358 | W26: =SUM(W13:W18) -> 9 | X26: =SUM(X13:X18) -> 3 | Y26: =SUM(Y13:Y18) -> 80 | Z26: =SUM(Z13:Z18) -> 104 | ... AF26: =SUM(AF13:AF18) -> 4861
B27: 11.15 - 11.30 | C27: 25 | D27: 12 | E27: 7 | F27: 9 | G27: 1 | H27: 0 | I27: 1 | J27: 8 | K27: 0 | L27: 0 | M27: 215 | N27: 0 | O27: =SUM(C27:L27,N27) -> 63 | P27: =SUM(C27:N27) -> 278 | R27: PM Period | S27: =SUM(S19:S21) -> 726 | T27: =SUM(T19:T21) -> 129 | U27: =SUM(U19:U21) -> 45 | V27: =SUM(V19:V21) -> 116 | W27: =SUM(W19:W21) -> 2 | X27: =SUM(X19:X21) -> 1 | Y27: =SUM(Y19:Y21) -> 39 | Z27: =SUM(Z19:Z21) -> 38 | ... AF27: =SUM(AF19:AF21) -> 2947
B28: 11.30 - 11.45 | C28: 29 | D28: 7 | E28: 7 | F28: 19 | G28: 1 | H28: 0 | I28: 2 | J28: 1 | K28: 1 | L28: 1 | M28: 195 | N28: 0 | O28: =SUM(C28:L28,N28) -> 68 | P28: =SUM(C28:N28) -> 263 | R28: 12 Hours | S28: =SUM(S10:S21) -> 1741 | T28: =SUM(T10:T21) -> 317 | U28: =SUM(U10:U21) -> 169 | V28: =SUM(V10:V21) -> 717 | W28: =SUM(W10:W21) -> 16 | X28: =SUM(X10:X21) -> 8 | Y28: =SUM(Y10:Y21) -> 133 | Z28: =SUM(Z10:Z21) -> 181 | ... AF28: =SUM(AF10:AF21) -> 10464
B29: 11.45 - 12.00 | C29: 33 | D29: 4 | E29: 4 | F29: 12 | G29: 0 | H29: 0 | I29: 5 | J29: 1 | K29: 0 | L29: 0 | M29: 135 | N29: 0 | O29: =SUM(C29:L29,N29) -> 59 | P29: =SUM(C29:N29) -> 194
B30: 12.00 - 12.15 | C30: 26 | D30: 9 | E30: 4 | F30: 13 | G30: 0 | H30: 0 | I30: 1 | J30: 8 | K30: 0 | L30: 0 | M30: 175 | N30: 0 | O30: =SUM(C30:L30,N30) -> 61 | P30: =SUM(C30:N30) -> 236
B31: 12.15 - 12.30 | C31: 26 | D31: 2 | E31: 5 | F31: 19 | G31: 1 | H31: 0 | I31: 3 | J31: 9 | K31: 1 | L31: 2 | M31: 105 | N31: 0 | O31: =SUM(C31:L31,N31) -> 68 | P31: =SUM(C31:N31) -> 173
B32: 12.30 - 12.45 | C32: 32 | D32: 6 | E32: 3 | F32: 17 | G32: 1 | H32: 1 | I32: 4 | J32: 3 | K32: 1 | L32: 0 | M32: 89 | N32: 0 | O32: =SUM(C32:L32,N32) -> 68 | P32: =SUM(C32:N32) -> 157
B33: 12.45 - 13.00 | C33: 27 | D33: 9 | E33: 3 | F33: 20 | G33: 2 | H33: 0 | I33: 6 | J33: 3 | K33: 2 | L33: 0 | M33: 96 | N33: 0 | O33: =SUM(C33:L33,N33) -> 72 | P33: =SUM(C33:N33) -> 168
B34: 13.00 - 13.15 | C34: 25 | D34: 8 | E34: 3 | F34: 21 | G34: 0 | H34: 0 | I34: 5 | J34: 6 | K34: 0 | L34: 1 | M34: 123 | N34: 0 | O34: =SUM(C34:L34,N34) -> 69 | P34: =SUM(C34:N34) -> 192
B35: 13.15 - 13.30 | C35: 34 | D35: 5 | E35: 3 | F35: 18 | G35: 0 | H35: 0 | I35: 1 | J35: 2 | K35: 0 | L35: 1 | M35: 154 | N35: 0 | O35: =SUM(C35:L35,N35) -> 64 | P35: =SUM(C35:N35) -> 218
B36: 13.30 - 13.45 | C36: 24 | D36: 1 | E36: 4 | F36: 16 | G36: 0 | H36: 0 | I36: 0 | J36: 5 | K36: 0 | L36: 0 | M36: 128 | N36: 0 | O36: =SUM(C36:L36,N36) -> 50 | P36: =SUM(C36:N36) -> 178
B37: 13.45 - 14.00 | C37: 36 | D37: 7 | E37: 3 | F37: 8 | G37: 1 | H37: 0 | I37: 7 | J37: 8 | K37: 1 | L37: 1 | M37: 99 | N37: 0 | O37: =SUM(C37:L37,N37) -> 72 | P37: =SUM(C37:N37) -> 171
B38: 14.00 - 14.15 | C38: 30 | D38: 3 | E38: 5 | F38: 14 | G38: 0 | H38: 0 | I38: 3 | J38: 3 | K38: 0 | L38: 0 | M38: 90 | N38: 0 | O38: =SUM(C38:L38,N38) -> 58 | P38: =SUM(C38:N38) -> 148
B39: 14.15 - 14.30 | C39: 33 | D39: 3 | E39: 4 | F39: 11 | G39: 0 | H39: 0 | I39: 3 | J39: 3 | K39: 0 | L39: 1 | M39: 121 | N39: 0 | O39: =SUM(C39:L39,N39) -> 58 | P39: =SUM(C39:N39) -> 179
B40: 14.30 - 14.45 | C40: 27 | D40: 1 | E40: 9 | F40: 15 | G40: 1 | H40: 0 | I40: 0 | J40: 0 | K40: 2 | L40: 1 | M40: 142 | N40: 0 | O40: =SUM(C40:L40,N40) -> 56 | P40: =SUM(C40:N40) -> 198
... B57: 18.45 - 19.00 | C57: 44 | D57: 8 | E57: 1 | F57: 3 | G57: 0 | H57: 0 | I57: 3 | J57: 1 | K57: 1 | L57: 0 | M57: 83 | N57: 0 | O57: =SUM(C57:L57,N57) -> 61 | P57: =SUM(C57:N57) -> 144
B58: Totals | C58: =SUM(C10:C57) -> 1741 | D58: =SUM(D10:D57) -> 317 | E58: =SUM(E10:E57) -> 169 | F58: =SUM(F10:F57) -> 717 | G58: =SUM(G10:G57) -> 16 | H58: =SUM(H10:H57) -> 8 | I58: =SUM(I10:I57) -> 133 | J58: =SUM(J10:J57) -> 181 | ... P58: =SUM(P10:P57) -> 10464
...

Sheet 23.07 KABUSU-RUBAGA
B1: Consultancy services for Preparation of Expressway Development Master Plan (EDMP) for Uganda
B2: MANUAL CLASSIFIED COUNT (MCC)
B3: ROAD NAME: | C3: ='22.07 KABUSU-RUBAGA'!C3:G3 -> MCC - C1 - STN05 - KABUSU ROAD
C5: Date | D5: ='23.07 RUBAGA-KABUSU'!D5 -> 23.07.19 | F5: Location | G5: ='22.07 RUBAGA-KABUSU'!G5:H5 -> CHAD SUPERMARKET | J5: Surveyor | K5: MBERE IVAN
C6: Dir. From | D6: KABUSU | F6: Dir. To | G6: RUBAGA | J6: Supervisor | K6: DENIS
B8: Time / Veh Type | R8: SUMMARY TRAFFIC VOLUMES
C9: 1. Car | D9: 2. Station Wagon | E9: 3. Pickups | F9: 4. Minibus, matatu | G9: 5. Medium bus | H9: 6. Large Bus | I9: 7. Light Truck | J9: 8. Medium Truck | K9: 9. Heavy truck | L9: 10. Truck Trailer | M9: 11. Motor cycles | N9: 12. Tractors | O9: Total Excl M/Cycles | P9: Total All | R9: Time | S9: 1. Car | T9: 2. Station Wagon | U9: 3. Pickups | V9: 4. Minibus, matatu | W9: 5. Medium bus | X9: 6. Large Bus | Y9: 7. Light Truck | Z9: 8. Medium Truck | AA9: 9. Heavy truck | AB9: 10. Truck Trailer | AC9: 11. Motorcycles | AD9: 12. Tractors, Graders | AE9: Total Excl M/ Cycles | AF9: Total All
B10: 07.00 - 07.15 | C10: 74 | D10: 52 | E10: 6 | F10: 42 | G10: 0 | H10: 0 | I10: 5 | J10: 1 | K10: 0 | L10: 1 | M10: 195 | N10: 0 | O10: =SUM(C10:L10,N10) -> 181 | P10: =SUM(C10:N10) -> 376 | R10: 0700-0800 | S10: =SUM(C10:C13) -> 222 | T10: =SUM(D10:D13) -> 215 | U10: =SUM(E10:E13) -> 25 | V10: =SUM(F10:F13) -> 270 | W10: =SUM(G10:G13) -> 0 | X10: =SUM(H10:H13) -> 1 | Y10: =SUM(I10:I13) -> 13 | Z10: =SUM(J10:J13) -> 5 | ... AF10: =SUM(P10:P13) -> 2021
B11: 07.15 - 07.30 | C11: 43 | D11: 48 | E11: 4 | F11: 37 | G11: 0 | H11: 0 | I11: 2 | J11: 1 | K11: 1 | L11: 2 | M11: 328 | N11: 0 | O11: =SUM(C11:L11,N11) -> 138 | P11: =SUM(C11:N11) -> 466 | R11: 0800-0900 | S11: =SUM(C14:C17) -> 199 | T11: =SUM(D14:D17) -> 174 | U11: =SUM(E14:E17) -> 24 | V11: =SUM(F14:F17) -> 148 | W11: =SUM(G14:G17) -> 0 | X11: =SUM(H14:H17) -> 0 | Y11: =SUM(I14:I17) -> 19 | Z11: =SUM(J14:J17) -> 7 | ... AF11: =SUM(P14:P17) -> 1853
B12: 07.30 - 07.45 | C12: 59 | D12: 56 | E12: 8 | F12: 151 | G12: 0 | H12: 0 | I12: 2 | J12: 1 | K12: 0 | L12: 0 | M12: 425 | N12: 0 | O12: =SUM(C12:L12,N12) -> 277 | P12: =SUM(C12:N12) -> 702 | R12: 0900-1000 | S12: =SUM(C18:C21) -> 163 | T12: =SUM(D18:D21) -> 130 | U12: =SUM(E18:E21) -> 20 | V12: =SUM(F18:F21) -> 124 | W12: =SUM(G18:G21) -> 0 | X12: =SUM(H18:H21) -> 1 | Y12: =SUM(I18:I21) -> 15 | Z12: =SUM(J18:J21) -> 5 | ... AF12: =SUM(P18:P21) -> 1314
B13: 07.45 - 08.00 | C13: 46 | D13: 59 | E13: 7 | F13: 40 | G13: 0 | H13: 1 | I13: 4 | J13: 2 | K13: 1 | L13: 0 | M13: 317 | N13: 0 | O13: =SUM(C13:L13,N13) -> 160 | P13: =SUM(C13:N13) -> 477 | R13: 1000-1100 | S13: =SUM(C22:C25) -> 114 | T13: =SUM(D22:D25) -> 98 | U13: =SUM(E22:E25) -> 24 | V13: =SUM(F22:F25) -> 130 | W13: =SUM(G22:G25) -> 0 | X13: =SUM(H22:H25) -> 0 | Y13: =SUM(I22:I25) -> 22 | Z13: =SUM(J22:J25) -> 11 | ... AF13: =SUM(P22:P25) -> 1121
B14: 08.00 - 08.15 | C14: 58 | D14: 55 | E14: 10 | F14: 37 | G14: 0 | H14: 0 | I14: 6 | J14: 3 | K14: 0 | L14: 0 | M14: 301 | N14: 0 | O14: =SUM(C14:L14,N14) -> 169 | P14: =SUM(C14:N14) -> 470 | R14: 1100-1200 | S14: =SUM(C26:C29) -> 101 | T14: =SUM(D26:D29) -> 90 | U14: =SUM(E26:E29) -> 19 | V14: =SUM(F26:F29) -> 113 | W14: =SUM(G26:G29) -> 0 | X14: =SUM(H26:H29) -> 1 | Y14: =SUM(I26:I29) -> 22 | Z14: =SUM(J26:J29) -> 7 | ... AF14: =SUM(P26:P29) -> 1056
B15: 08.15 - 08.30 | C15: 54 | D15: 33 | E15: 4 | F15: 32 | G15: 0 | H15: 0 | I15: 3 | J15: 0 | K15: 1 | L15: 0 | M15: 345 | N15: 0 | O15: =SUM(C15:L15,N15) -> 127 | P15: =SUM(C15:N15) -> 472 | R15: 1200-1300 | S15: =SUM(C30:C33) -> 87 | T15: =SUM(D30:D33) -> 80 | U15: =SUM(E30:E33) -> 34 | V15: =SUM(F30:F33) -> 117 | W15: =SUM(G30:G33) -> 1 | X15: =SUM(H30:H33) -> 0 | Y15: =SUM(I30:I33) -> 25 | Z15: =SUM(J30:J33) -> 8 | ... AF15: =SUM(P30:P33) -> 1074
B16: 08.30 - 08.45 | C16: 44 | D16: 45 | E16: 8 | F16: 44 | G16: 0 | H16: 0 | I16: 6 | J16: 3 | K16: 0 | L16: 0 | M16: 315 | N16: 0 | O16: =SUM(C16:L16,N16) -> 150 | P16: =SUM(C16:N16) -> 465 | R16: 1300-1400 | S16: =SUM(C34:C37) -> 95 | T16: =SUM(D34:D37) -> 66 | U16: =SUM(E34:E37) -> 10 | V16: =SUM(F34:F37) -> 95 | W16: =SUM(G34:G37) -> 2 | X16: =SUM(H34:H37) -> 2 | Y16: =SUM(I34:I37) -> 13 | Z16: =SUM(J34:J37) -> 9 | ... AF16: =SUM(P34:P37) -> 896
B17: 08.45 - 9.00 | C17: 43 | D17: 41 | E17: 2 | F17: 35 | G17: 0 | H17: 0 | I17: 4 | J17: 1 | K17: 0 | L17: 0 | M17: 320 | N17: 0 | O17: =SUM(C17:L17,N17) -> 126 | P17: =SUM(C17:N17) -> 446 | R17: 1400-1500 | S17: =SUM(C38:C41) -> 91 | T17: =SUM(D38:D41) -> 77 | U17: =SUM(E38:E41) -> 24 | V17: =SUM(F38:F41) -> 79 | W17: =SUM(G38:G41) -> 1 | X17: =SUM(H38:H41) -> 0 | Y17: =SUM(I38:I41) -> 28 | Z17: =SUM(J38:J41) -> 6 | ... AF17: =SUM(P38:P41) -> 906
B18: 09.00 - 09.15 | C18: 36 | D18: 31 | E18: 5 | F18: 26 | G18: 0 | H18: 0 | I18: 1 | J18: 1 | K18: 1 | L18: 0 | M18: 191 | N18: 0 | O18: =SUM(C18:L18,N18) -> 101 | P18: =SUM(C18:N18) -> 292 | R18: 1500-1600 | S18: =SUM(C42:C45) -> 105 | T18: =SUM(D42:D45) -> 79 | U18: =SUM(E42:E45) -> 17 | V18: =SUM(F42:F45) -> 95 | W18: =SUM(G42:G45) -> 0 | X18: =SUM(H42:H45) -> 1 | Y18: =SUM(I42:I45) -> 23 | Z18: =SUM(J42:J45) -> 12 | ... AF18: =SUM(P42:P45) -> 831
B19: 09.15 - 09.30 | C19: 46 | D19: 30 | E19: 4 | F19: 35 | G19: 0 | H19: 0 | I19: 4 | J19: 2 | K19: 1 | L19: 0 | M19: 234 | N19: 0 | O19: =SUM(C19:L19,N19) -> 122 | P19: =SUM(C19:N19) -> 356 | R19: 1600-1700 | S19: =SUM(C46:C49) -> 113 | T19: =SUM(D46:D49) -> 82 | U19: =SUM(E46:E49) -> 16 | V19: =SUM(F46:F49) -> 82 | W19: =SUM(G46:G49) -> 3 | X19: =SUM(H46:H49) -> 3 | Y19: =SUM(I46:I49) -> 21 | Z19: =SUM(J46:J49) -> 11 | ... AF19: =SUM(P46:P49) -> 1024
B20: 09.30 - 09.45 | C20: 47 | D20: 39 | E20: 6 | F20: 36 | G20: 0 | H20: 0 | I20: 5 | J20: 2 | K20: 1 | L20: 0 | M20: 211 | N20: 0 | O20: =SUM(C20:L20,N20) -> 136 | P20: =SUM(C20:N20) -> 347 | R20: 1700-1800 | S20: =SUM(C50:C53) -> 97 | T20: =SUM(D50:D53) -> 85 | U20: =SUM(E50:E53) -> 10 | V20: =SUM(F50:F53) -> 95 | W20: =SUM(G50:G53) -> 3 | X20: =SUM(H50:H53) -> 3 | Y20: =SUM(I50:I53) -> 11 | Z20: =SUM(J50:J53) -> 13 | ... AF20: =SUM(P50:P53) -> 983
B21: 09.45 - 10.00 | C21: 34 | D21: 30 | E21: 5 | F21: 27 | G21: 0 | H21: 1 | I21: 5 | J21: 0 | K21: 0 | L21: 0 | M21: 217 | N21: 0 | O21: =SUM(C21:L21,N21) -> 102 | P21: =SUM(C21:N21) -> 319 | R21: 1800-1900 | S21: =SUM(C54:C57) -> 136 | T21: =SUM(D54:D57) -> 73 | U21: =SUM(E54:E57) -> 17 | V21: =SUM(F54:F57) -> 123 | W21: =SUM(G54:G57) -> 6 | X21: =SUM(H54:H57) -> 3 | Y21: =SUM(I54:I57) -> 11 | Z21: =SUM(J54:J57) -> 6 | ... AF21: =SUM(P54:P57) -> 1284
B22: 10.00 - 10.15 | C22: 25 | D22: 26 | E22: 7 | F22: 34 | G22: 0 | H22: 0 | I22: 8 | J22: 3 | K22: 1 | L22: 1 | M22: 188 | N22: 0 | O22: =SUM(C22:L22,N22) -> 105 | P22: =SUM(C22:N22) -> 293 | R22: AM Peak Hr | S22: =MAX(S10:S12) -> 222 | T22: =MAX(T10:T12) -> 215 | U22: =MAX(U10:U12) -> 25 | V22: =MAX(V10:V12) -> 270 | W22: =MAX(W10:W12) -> 0 | X22: =MAX(X10:X12) -> 1 | Y22: =MAX(Y10:Y12) -> 19 | Z22: =MAX(Z10:Z12) -> 7 | ... AF22: =MAX(AF10:AF12) -> 2021
B23: 10.15 - 10.30 | C23: 28 | D23: 21 | E23: 5 | F23: 31 | G23: 0 | H23: 0 | I23: 5 | J23: 1 | K23: 0 | L23: 2 | M23: 179 | N23: 0 | O23: =SUM(C23:L23,N23) -> 93 | P23: =SUM(C23:N23) -> 272 | R23: IP Peak Hr | S23: =MAX(S13:S18) -> 114 | T23: =MAX(T13:T18) -> 98 | U23: =MAX(U13:U18) -> 34 | V23: =MAX(V13:V18) -> 130 | W23: =MAX(W13:W18) -> 2 | X23: =MAX(X13:X18) -> 2 | Y23: =MAX(Y13:Y18) -> 28 | Z23: =MAX(Z13:Z18) -> 12 | ... AF23: =MAX(AF13:AF18) -> 1121
B24: 10.30 - 10.45 | C24: 41 | D24: 25 | E24: 8 | F24: 31 | G24: 0 | H24: 0 | I24: 2 | J24: 3 | K24: 2 | L24: 1 | M24: 160 | N24: 0 | O24: =SUM(C24:L24,N24) -> 113 | P24: =SUM(C24:N24) -> 273 | R24: PM Peak Hr | S24: =MAX(S19:S21) -> 136 | T24: =MAX(T19:T21) -> 85 | U24: =MAX(U19:U21) -> 17 | V24: =MAX(V19:V21) -> 123 | W24: =MAX(W19:W21) -> 6 | X24: =MAX(X19:X21) -> 3 | Y24: =MAX(Y19:Y21) -> 21 | Z24: =MAX(Z19:Z21) -> 13 | ... AF24: =MAX(AF19:AF21) -> 1284
B25: 10.45 - 11.00 | C25: 20 | D25: 26 | E25: 4 | F25: 34 | G25: 0 | H25: 0 | I25: 7 | J25: 4 | K25: 1 | L25: 2 | M25: 185 | N25: 0 | O25: =SUM(C25:L25,N25) -> 98 | P25: =SUM(C25:N25) -> 283 | R25: AM Period | S25: =SUM(S10:S12) -> 584 | T25: =SUM(T10:T12) -> 519 | U25: =SUM(U10:U12) -> 69 | V25: =SUM(V10:V12) -> 542 | W25: =SUM(W10:W12) -> 0 | X25: =SUM(X10:X12) -> 2 | Y25: =SUM(Y10:Y12) -> 47 | Z25: =SUM(Z10:Z12) -> 17 | ... AF25: =SUM(AF10:AF12) -> 5188
B26: 11.00 - 11.15 | C26: 22 | D26: 21 | E26: 7 | F26: 37 | G26: 0 | H26: 1 | I26: 6 | J26: 1 | K26: 2 | L26: 0 | M26: 163 | N26: 0 | O26: =SUM(C26:L26,N26) -> 97 | P26: =SUM(C26:N26) -> 260 | R26: IP Period | S26: =SUM(S13:S18) -> 593 | T26: =SUM(T13:T18) -> 490 | U26: =SUM(U13:U18) -> 128 | V26: =SUM(V13:V18) -> 629 | W26: =SUM(W13:W18) -> 4 | X26: =SUM(X13:X18) -> 4 | Y26: =SUM(Y13:Y18) -> 133 | Z26: =SUM(Z13:Z18) -> 53 | ... AF26: =SUM(AF13:AF18) -> 5884
B27: 11.15 - 11.30 | C27: 32 | D27: 25 | E27: 2 | F27: 24 | G27: 0 | H27: 0 | I27: 6 | J27: 4 | K27: 3 | L27: 2 | M27: 148 | N27: 0 | O27: =SUM(C27:L27,N27) -> 98 | P27: =SUM(C27:N27) -> 246 | R27: PM Period | S27: =SUM(S19:S21) -> 346 | T27: =SUM(T19:T21) -> 240 | U27: =SUM(U19:U21) -> 43 | V27: =SUM(V19:V21) -> 300 | W27: =SUM(W19:W21) -> 12 | X27: =SUM(X19:X21) -> 9 | Y27: =SUM(Y19:Y21) -> 43 | Z27: =SUM(Z19:Z21) -> 30 | ... AF27: =SUM(AF19:AF21) -> 3291
B28: 11.30 - 11.45 | C28: 29 | D28: 23 | E28: 3 | F28: 27 | G28: 0 | H28: 0 | I28: 4 | J28: 1 | K28: 1 | L28: 3 | M28: 166 | N28: 0 | O28: =SUM(C28:L28,N28) -> 91 | P28: =SUM(C28:N28) -> 257 | R28: 12 Hours | S28: =SUM(S10:S21) -> 1523 | T28: =SUM(T10:T21) -> 1249 | U28: =SUM(U10:U21) -> 240 | V28: =SUM(V10:V21) -> 1471 | W28: =SUM(W10:W21) -> 16 | X28: =SUM(X10:X21) -> 15 | Y28: =SUM(Y10:Y21) -> 223 | Z28: =SUM(Z10:Z21) -> 100 | ... AF28: =SUM(AF10:AF21) -> 14363
B29: 11.45 - 12.00 | C29: 18 | D29: 21 | E29: 7 | F29: 25 | G29: 0 | H29: 0 | I29: 6 | J29: 1 | K29: 0 | L29: 2 | M29: 213 | N29: 0 | O29: =SUM(C29:L29,N29) -> 80 | P29: =SUM(C29:N29) -> 293
B30: 12.00 - 12.15 | C30: 27 | D30: 25 | E30: 8 | F30: 30 | G30: 1 | H30: 0 | I30: 13 | J30: 4 | K30: 0 | L30: 2 | M30: 160 | N30: 0 | O30: =SUM(C30:L30,N30) -> 110 | P30: =SUM(C30:N30) -> 270
B31: 12.15 - 12.30 | C31: 27 | D31: 15 | E31: 7 | F31: 36 | G31: 0 | H31: 0 | I31: 3 | J31: 0 | K31: 1 | L31: 1 | M31: 182 | N31: 0 | O31: =SUM(C31:L31,N31) -> 90 | P31: =SUM(C31:N31) -> 272
B32: 12.30 - 12.45 | C32: 16 | D32: 22 | E32: 5 | F32: 23 | G32: 0 | H32: 0 | I32: 1 | J32: 4 | K32: 1 | L32: 0 | M32: 178 | N32: 0 | O32: =SUM(C32:L32,N32) -> 72 | P32: =SUM(C32:N32) -> 250
B33: 12.45 - 13.00 | C33: 17 | D33: 18 | E33: 14 | F33: 28 | G33: 0 | H33: 0 | I33: 8 | J33: 0 | K33: 1 | L33: 0 | M33: 196 | N33: 0 | O33: =SUM(C33:L33,N33) -> 86 | P33: =SUM(C33:N33) -> 282
B34: 13.00 - 13.15 | C34: 22 | D34: 17 | E34: 2 | F34: 24 | G34: 1 | H34: 1 | I34: 2 | J34: 3 | K34: 2 | L34: 3 | M34: 168 | N34: 0 | O34: =SUM(C34:L34,N34) -> 77 | P34: =SUM(C34:N34) -> 245
B35: 13.15 - 13.30 | C35: 26 | D35: 20 | E35: 3 | F35: 25 | G35: 0 | H35: 0 | I35: 5 | J35: 1 | K35: 0 | L35: 2 | M35: 132 | N35: 0 | O35: =SUM(C35:L35,N35) -> 82 | P35: =SUM(C35:N35) -> 214
B36: 13.30 - 13.45 | C36: 24 | D36: 11 | E36: 2 | F36: 27 | G36: 1 | H36: 0 | I36: 2 | J36: 1 | K36: 1 | L36: 2 | M36: 131 | N36: 0 | O36: =SUM(C36:L36,N36) -> 71 | P36: =SUM(C36:N36) -> 202
B37: 13.45 - 14.00 | C37: 23 | D37: 18 | E37: 3 | F37: 19 | G37: 0 | H37: 1 | I37: 4 | J37: 4 | K37: 1 | L37: 1 | M37: 161 | N37: 0 | O37: =SUM(C37:L37,N37) -> 74 | P37: =SUM(C37:N37) -> 235
B38: 14.00 - 14.15 | C38: 21 | D38: 16 | E38: 2 | F38: 22 | G38: 1 | H38: 0 | I38: 7 | J38: 1 | K38: 0 | L38: 3 | M38: 167 | N38: 0 | O38: =SUM(C38:L38,N38) -> 73 | P38: =SUM(C38:N38) -> 240
B39: 14.15 - 14.30 | C39: 23 | D39: 19 | E39: 7 | F39: 21 | G39: 0 | H39: 0 | I39: 9 | J39: 3 | K39: 0 | L39: 1 | M39: 123 | N39: 0 | O39: =SUM(C39:L39,N39) -> 83 | P39: =SUM(C39:N39) -> 206
B40: 14.30 - 14.45 | C40: 26 | D40: 22 | E40: 2 | F40: 18 | G40: 0 | H40: 0 | I40: 8 | J40: 1 | K40: 1 | L40: 2 | M40: 161 | N40: 0 | O40: =SUM(C40:L40,N40) -> 80 | P40: =SUM(C40:N40) -> 241
... B44: 15.30 - 15.45 | C44: 21 | D44: 25 | E44: 7 | F44: 22 | G44: 0 | H44: 0 | I44: 9 | J44: 2 | K44: 1 | L44: 1 | M44: 188 | N44: 0 | O44: =SUM(C44:L44,N44) -> 88 | P44: =SUM(C44:N44) -> 276
B45: 15.45 - 16.00 | C45: 34 | D45: 15 | E45: 2 | F45: 31 | G45: 0 | H45: 0 | I45: 6 | J45: 1 | K45: 2 | L45: 0 | M45: 186 | N45: 14 | O45: 9 | P45: 21 | S45: 7 | T45: 4 | U45: 1 | V45: 1 | W45: 168
...

Sheet 24.07 RUBAGA-KABUSU
B1: Consultancy services for Preparation of Expressway Development Master Plan (EDMP) for Uganda
B2: MANUAL CLASSIFIED COUNT (MCC)
B3: ROAD NAME: | C3: ='22.07 RUBAGA-KABUSU'!C3:G3 -> MCC - C1 - STN05 - KABUSU ROAD
C5: Date | D5: 24.07.19 | F5: Location | G5: ='22.07 RUBAGA-KABUSU'!G5:H5 -> CHAD SUPERMARKET | J5: Surveyor | K5: ='22.07 RUBAGA-KABUSU'!K5:L5 -> EMMANUEL EGIMU
C6: Dir. From | D6: ='22.07 RUBAGA-KABUSU'!D6:E6 -> RUBAGA | F6: Dir. To | G6: ='22.07 RUBAGA-KABUSU'!G6:H6 -> KABUSU | J6: Supervisor | K6: ='22.07 RUBAGA-KABUSU'!K6:L6 -> DENIS
B8: Time / Veh Type | R8: SUMMARY TRAFFIC VOLUMES
C9: 1. Car | D9: 2. Station Wagon | E9: 3. Pickups | F9: 4. Minibus, matatu | G9: 5. Medium bus | H9: 6. Large Bus | I9: 7. Light Truck | J9: 8. Medium Truck | K9: 9. Heavy truck | L9: 10. Truck Trailer | M9: 11. Motor cycles | N9: 12. Tractors | O9: Total Excl M/Cycles | P9: Total All | R9: Time | S9: 1. Car | T9: 2. Station Wagon | U9: 3. Pickups | V9: 4. Minibus, matatu | W9: 5. Medium bus | X9: 6. Large Bus | Y9: 7. Light Truck | Z9: 8. Medium Truck | AA9: 9. Heavy truck | AB9: 10. Truck Trailer | AC9: 11. Motorcycles | AD9: 12. Tractors, Graders | AE9: Total Excl M/ Cycles | AF9: Total All
B10: 07.00 - 07.15 | C10: 31 | D10: 7 | E10: 4 | F10: 13 | G10: 0 | H10: 0 | I10: 4 | J10: 2 | K10: 0 | L10: 0 | M10: 68 | N10: 0 | O10: =SUM(C10:L10,N10) -> 61 | P10: =SUM(C10:N10) -> 129 | R10: 0700-0800 | S10: =SUM(C10:C13) -> 127 | T10: =SUM(D10:D13) -> 17 | U10: =SUM(E10:E13) -> 9 | V10: =SUM(F10:F13) -> 76 | W10: =SUM(G10:G13) -> 0 | X10: =SUM(H10:H13) -> 1 | Y10: =SUM(I10:I13) -> 8 | Z10: =SUM(J10:J13) -> 5 | ... AF10: =SUM(P10:P13) -> 581
B11: 07.15 - 07.30 | C11: 45 | D11: 4 | E11: 1 | F11: 18 | G11: 0 | H11: 0 | I11: 1 | J11: 2 | K11: 0 | L11: 2 | M11: 79 | N11: 0 | O11: =SUM(C11:L11,N11) -> 73 | P11: =SUM(C11:N11) -> 152 | R11: 0800-0900 | S11: =SUM(C14:C17) -> 84 | T11: =SUM(D14:D17) -> 22 | U11: =SUM(E14:E17) -> 8 | V11: =SUM(F14:F17) -> 92 | W11: =SUM(G14:G17) -> 5 | X11: =SUM(H14:H17) -> 1 | Y11: =SUM(I14:I17) -> 13 | Z11: =SUM(J14:J17) -> 14 | ... AF11: =SUM(P14:P17) -> 795
B12: 07.30 - 07.45 | C12: 18 | D12: 3 | E12: 3 | F12: 22 | G12: 0 | H12: 1 | I12: 1 | J12: 1 | K12: 1 | L12: 0 | M12: 91 | N12: 0 | O12: =SUM(C12:L12,N12) -> 50 | P12: =SUM(C12:N12) -> 141 | R12: 0900-1000 | S12: =SUM(C18:C21) -> 64 | T12: =SUM(D18:D21) -> 19 | U12: =SUM(E18:E21) -> 19 | V12: =SUM(F18:F21) -> 84 | W12: =SUM(G18:G21) -> 2 | X12: =SUM(H18:H21) -> 0 | Y12: =SUM(I18:I21) -> 6 | Z12: =SUM(J18:J21) -> 11 | ... AF12: =SUM(P18:P21) -> 762
B13: 07.45 - 08.00 | C13: 33 | D13: 3 | E13: 1 | F13: 23 | G13: 0 | H13: 0 | I13: 2 | J13: 0 | K13: 0 | L13: 0 | M13: 97 | N13: 0 | O13: =SUM(C13:L13,N13) -> 62 | P13: =SUM(C13:N13) -> 159 | R13: 1000-1100 | S13: =SUM(C22:C25) -> 91 | T13: =SUM(D22:D25) -> 34 | U13: =SUM(E22:E25) -> 10 | V13: =SUM(F22:F25) -> 69 | W13: =SUM(G22:G25) -> 4 | X13: =SUM(H22:H25) -> 0 | Y13: =SUM(I22:I25) -> 4 | Z13: =SUM(J22:J25) -> 21 | ... AF13: =SUM(P22:P25) -> 1032
B14: 08.00 - 08.15 | C14: 31 | D14: 1 | E14: 3 | F14: 23 | G14: 3 | H14: 1 | I14: 6 | J14: 3 | K14: 0 | L14: 1 | M14: 112 | N14: 0 | O14: =SUM(C14:L14,N14) -> 72 | P14: =SUM(C14:N14) -> 184 | R14: 1100-1200 | S14: =SUM(C26:C29) -> 110 | T14: =SUM(D26:D29) -> 26 | U14: =SUM(E26:E29) -> 9 | V14: =SUM(F26:F29) -> 69 | W14: =SUM(G26:G29) -> 1 | X14: =SUM(H26:H29) -> 1 | Y14: =SUM(I26:I29) -> 8 | Z14: =SUM(J26:J29) -> 16 | ... AF14: =SUM(P26:P29) -> 845
B15: 08.15 - 08.30 | C15: 22 | D15: 5 | E15: 1 | F15: 24 | G15: 2 | H15: 0 | I15: 6 | J15: 5 | K15: 0 | L15: 2 | M15: 149 | N15: 0 | O15: =SUM(C15:L15,N15) -> 67 | P15: =SUM(C15:N15) -> 216 | R15: 1200-1300 | S15: =SUM(C30:C33) -> 113 | T15: =SUM(D30:D33) -> 23 | U15: =SUM(E30:E33) -> 16 | V15: =SUM(F30:F33) -> 48 | W15: =SUM(G30:G33) -> 4 | X15: =SUM(H30:H33) -> 2 | Y15: =SUM(I30:I33) -> 10 | Z15: =SUM(J30:J33) -> 22 | ... AF15: =SUM(P30:P33) -> 776
B16: 08.30 - 08.45 | C16: 14 | D16: 7 | E16: 3 | F16: 20 | G16: 0 | H16: 0 | I16: 1 | J16: 3 | K16: 2 | L16: 0 | M16: 161 | N16: 0 | O16: =SUM(C16:L16,N16) -> 50 | P16: =SUM(C16:N16) -> 211 | R16: 1300-1400 | S16: =SUM(C34:C37) -> 105 | T16: =SUM(D34:D37) -> 22 | U16: =SUM(E34:E37) -> 9 | V16: =SUM(F34:F37) -> 57 | W16: =SUM(G34:G37) -> 3 | X16: =SUM(H34:H37) -> 3 | Y16: =SUM(I34:I37) -> 8 | Z16: =SUM(J34:J37) -> 13 | ... AF16: =SUM(P34:P37) -> 702
B17: 08.45 - 9.00 | C17: 17 | D17: 9 | E17: 1 | F17: 25 | G17: 0 | H17: 0 | I17: 0 | J17: 3 | K17: 1 | L17: 0 | M17: 128 | N17: 0 | O17: =SUM(C17:L17,N17) -> 56 | P17: =SUM(C17:N17) -> 184 | R17: 1400-1500 | S17: =SUM(C38:C41) -> 118 | T17: =SUM(D38:D41) -> 14 | U17: =SUM(E38:E41) -> 21 | V17: =SUM(F38:F41) -> 43 | W17: =SUM(G38:G41) -> 0 | X17: =SUM(H38:H41) -> 0 | Y17: =SUM(I38:I41) -> 18 | Z17: =SUM(J38:J41) -> 11 | ... AF17: =SUM(P38:P41) -> 748
B18: 09.00 - 09.15 | C18: 19 | D18: 5 | E18: 6 | F18: 17 | G18: 0 | H18: 0 | I18: 1 | J18: 3 | K18: 1 | L18: 1 | M18: 142 | N18: 0 | O18: =SUM(C18:L18,N18) -> 53 | P18: =SUM(C18:N18) -> 195 | R18: 1500-1600 | S18: =SUM(C42:C45) -> 152 | T18: =SUM(D42:D45) -> 27 | U18: =SUM(E42:E45) -> 22 | V18: =SUM(F42:F45) -> 67 | W18: =SUM(G42:G45) -> 0 | X18: =SUM(H42:H45) -> 1 | Y18: =SUM(I42:I45) -> 13 | Z18: =SUM(J42:J45) -> 17 | ... AF18: =SUM(P42:P45) -> 1103
B19: 09.15 - 09.30 | C19: 18 | D19: 2 | E19: 6 | F19: 22 | G19: 0 | H19: 0 | I19: 2 | J19: 3 | K19: 0 | L19: 0 | M19: 102 | N19: 0 | O19: =SUM(C19:L19,N19) -> 53 | P19: =SUM(C19:N19) -> 155 | R19: 1600-1700 | S19: =SUM(C46:C49) -> 184 | T19: =SUM(D46:D49) -> 47 | U19: =SUM(E46:E49) -> 19 | V19: =SUM(F46:F49) -> 45 | W19: =SUM(G46:G49) -> 1 | X19: =SUM(H46:H49) -> 4 | Y19: =SUM(I46:I49) -> 13 | Z19: =SUM(J46:J49) -> 14 | ... AF19: =SUM(P46:P49) -> 881
B20: 09.30 - 09.45 | C20: 7 | D20: 5 | E20: 5 | F20: 22 | G20: 0 | H20: 0 | I20: 2 | J20: 3 | K20: 0 | L20: 0 | M20: 127 | N20: 0 | O20: =SUM(C20:L20,N20) -> 44 | P20: =SUM(C20:N20) -> 171 | R20: 1700-1800 | S20: =SUM(C50:C53) -> 260 | T20: =SUM(D50:D53) -> 38 | U20: =SUM(E50:E53) -> 18 | V20: =SUM(F50:F53) -> 41 | W20: =SUM(G50:G53) -> 0 | X20: =SUM(H50:H53) -> 1 | Y20: =SUM(I50:I53) -> 14 | Z20: =SUM(J50:J53) -> 15 | ... AF20: =SUM(P50:P53) -> 843
B21: 09.45 - 10.00 | C21: 20 | D21: 7 | E21: 2 | F21: 23 | G21: 2 | H21: 0 | I21: 1 | J21: 2 | K21: 1 | L21: 0 | M21: 183 | N21: 0 | O21: =SUM(C21:L21,N21) -> 58 | P21: =SUM(C21:N21) -> 241 | R21: 1800-1900 | S21: =SUM(C54:C57) -> 298 | T21: =SUM(D54:D57) -> 68 | U21: =SUM(E54:E57) -> 13 | V21: =SUM(F54:F57) -> 26 | W21: =SUM(G54:G57) -> 0 | X21: =SUM(H54:H57) -> 0 | Y21: =SUM(I54:I57) -> 5 | Z21: =SUM(J54:J57) -> 5 | ... AF21: =SUM(P54:P57) -> 682
B22: 10.00 - 10.15 | C22: 25 | D22: 11 | E22: 2 | F22: 15 | G22: 0 | H22: 0 | I22: 2 | J22: 4 | K22: 0 | L22: 0 | M22: 206 | N22: 0 | O22: =SUM(C22:L22,N22) -> 59 | P22: =SUM(C22:N22) -> 265 | R22: AM Peak Hr | S22: =MAX(S10:S12) -> 127 | T22: =MAX(T10:T12) -> 22 | U22: =MAX(U10:U12) -> 19 | V22: =MAX(V10:V12) -> 92 | W22: =MAX(W10:W12) -> 5 | X22: =MAX(X10:X12) -> 1 | Y22: =MAX(Y10:Y12) -> 13 | Z22: =MAX(Z10:Z12) -> 14 | ... AF22: =MAX(AF10:AF12) -> 795
B23: 10.15 - 10.30 | C23: 17 | D23: 8 | E23: 4 | F23: 21 | G23: 2 | H23: 0 | I23: 1 | J23: 5 | K23: 1 | L23: 1 | M23: 190 | N23: 0 | O23: =SUM(C23:L23,N23) -> 60 | P23: =SUM(C23:N23) -> 250 | R23: IP Peak Hr | S23: =MAX(S13:S18) -> 152 | T23: =MAX(T13:T18) -> 34 | U23: =MAX(U13:U18) -> 22 | V23: =MAX(V13:V18) -> 69 | W23: =MAX(W13:W18) -> 4 | X23: =MAX(X13:X18) -> 3 | Y23: =MAX(Y13:Y18) -> 18 | Z23: =MAX(Z13:Z18) -> 22 | ... AF23: =MAX(AF13:AF18) -> 1103
B24: 10.30 - 10.45 | C24: 19 | D24: 7 | E24: 2 | F24: 19 | G24: 1 | H24: 0 | I24: 1 | J24: 6 | K24: 1 | L24: 0 | M24: 216 | N24: 0 | O24: =SUM(C24:L24,N24) -> 56 | P24: =SUM(C24:N24) -> 272 | R24: PM Peak Hr | S24: =MAX(S19:S21) -> 298 | T24: =MAX(T19:T21) -> 68 | U24: =MAX(U19:U21) -> 19 | V24: =MAX(V19:V21) -> 45 | W24: =MAX(W19:W21) -> 1 | X24: =MAX(X19:X21) -> 4 | Y24: =MAX(Y19:Y21) -> 14 | Z24: =MAX(Z19:Z21) -> 15 | ... AF24: =MAX(AF19:AF21) -> 881
B25: 10.45 - 11.00 | C25: 30 | D25: 8 | E25: 2 | F25: 14 | G25: 1 | H25: 0 | I25: 0 | J25: 6 | K25: 1 | L25: 0 | M25: 183 | N25: 0 | O25: =SUM(C25:L25,N25) -> 62 | P25: =SUM(C25:N25) -> 245 | R25: AM Period | S25: =SUM(S10:S12) -> 275 | T25: =SUM(T10:T12) -> 58 | U25: =SUM(U10:U12) -> 36 | V25: =SUM(V10:V12) -> 252 | W25: =SUM(W10:W12) -> 7 | X25: =SUM(X10:X12) -> 2 | Y25: =SUM(Y10:Y12) -> 27 | Z25: =SUM(Z10:Z12) -> 30 | ... AF25: =SUM(AF10:AF12) -> 2138
B26: 11.00 - 11.15 | C26: 25 | D26: 7 | E26: 0 | F26: 19 | G26: 0 | H26: 0 | I26: 3 | J26: 2 | K26: 1 | L26: 0 | M26: 154 | N26: 0 | O26: =SUM(C26:L26,N26) -> 57 | P26: =SUM(C26:N26) -> 211 | R26: IP Period | S26: =SUM(S13:S18) -> 689 | T26: =SUM(T13:T18) -> 146 | U26: =SUM(U13:U18) -> 87 | V26: =SUM(V13:V18) -> 353 | W26: =SUM(W13:W18) -> 12 | X26: =SUM(X13:X18) -> 7 | Y26: =SUM(Y13:Y18) -> 61 | Z26: =SUM(Z13:Z18) -> 100 | ... AF26: =SUM(AF13:AF18) -> 5206
B27: 11.15 - 11.30 | C27: 24 | D27: 5 | E27: 2 | F27: 16 | G27: 0 | H27: 0 | I27: 0 | J27: 7 | K27: 0 | L27: 0 | M27: 161 | N27: 0 | O27: =SUM(C27:L27,N27) -> 54 | P27: =SUM(C27:N27) -> 215 | R27: PM Period | S27: =SUM(S19:S21) -> 742 | T27: =SUM(T19:T21) -> 153 | U27: =SUM(U19:U21) -> 50 | V27: =SUM(V19:V21) -> 112 | W27: =SUM(W19:W21) -> 1 | X27: =SUM(X19:X21) -> 5 | Y27: =SUM(Y19:Y21) -> 32 | Z27: =SUM(Z19:Z21) -> 34 | ... AF27: =SUM(AF19:AF21) -> 2406
