Workbook

Sheet 17.10 jinja-kampala
B1: Consultancy services for Preparation of Expressway Development Master Plan (EDMP) for Uganda
B2: MANUAL CLASSIFIED COUNT (MCC)
B3: ROAD NAME: | C3: MCC - C 4- STN19 -Kampala-Jinja highway
C5: Date | D5: 17.10.19 | F5: Location | G5: Nakibbizi | J5: Surveyor | K5: Micheal
C6: Dir. From | D6: Jinja | F6: Dir. To | G6: Kampala | J6: Supervisor | K6: Emma
B8: Time / Veh Type | R8: SUMMARY TRAFFIC VOLUMES
C9: 1. Car | D9: 2. Station Wagon | E9: 3. Pickups | F9: 4. Minibus, matatu | G9: 5. Medium bus | H9: 6. Large Bus | I9: 7. Light Truck | J9: 8. Medium Truck | K9: 9. Heavy truck | L9: 10. Truck Trailer | M9: 11. Motor cycles | N9: 12. Tractors | O9: Total Excl M/Cycles | P9: Total All | R9: Time | S9: 1. Car | T9: 2. Station Wagon | U9: 3. Pickups | V9: 4. Minibus, matatu | W9: 5. Medium bus | X9: 6. Large Bus | Y9: 7. Light Truck | Z9: 8. Medium Truck | AA9: 9. Heavy truck | AB9: 10. Truck Trailer | AC9: 11. Motorcycles | AD9: 12. Tractors, Graders | AE9: Total Excl M/ Cycles | AF9: Total All
B10: 07.00 - 07.15 | C10: 8 | D10: 2 | E10: 3 | F10: 37 | G10: 1 | H10: 1 | I10: 2 | J10: 2 | K10: 0 | L10: 16 | M10: 23 | N10: 0 | O10: =SUM(C10:L10,N10) -> 72 | P10: =SUM(C10:N10) -> 95 | R10: 0700-0800 | S10: =SUM(C10:C13) -> 34 | T10: =SUM(D10:D13) -> 8 | U10: =SUM(E10:E13) -> 8 | V10: =SUM(F10:F13) -> 144 | W10: =SUM(G10:G13) -> 4 | X10: =SUM(H10:H13) -> 3 | Y10: =SUM(I10:I13) -> 9 | Z10: =SUM(J10:J13) -> 8 | ... AF10: =SUM(P10:P13) -> 361
B11: 07.15 - 07.30 | C11: 11 | D11: 2 | E11: 2 | F11: 38 | G11: 0 | H11: 1 | I11: 2 | J11: 2 | K11: 1 | L11: 15 | M11: 22 | N11: 0 | O11: =SUM(C11:L11,N11) -> 74 | P11: =SUM(C11:N11) -> 96 | R11: 0800-0900 | S11: =SUM(C14:C17) -> 59 | T11: =SUM(D14:D17) -> 10 | U11: =SUM(E14:E17) -> 11 | V11: =SUM(F14:F17) -> 128 | W11: =SUM(G14:G17) -> 1 | X11: =SUM(H14:H17) -> 3 | Y11: =SUM(I14:I17) -> 13 | Z11: =SUM(J14:J17) -> 14 | ... AF11: =SUM(P14:P17) -> 380
B12: 07.30 - 07.45 | C12: 8 | D12: 1 | E12: 2 | F12: 27 | G12: 2 | H12: 0 | I12: 3 | J12: 1 | K12: 3 | L12: 11 | M12: 16 | N12: 0 | O12: =SUM(C12:L12,N12) -> 58 | P12: =SUM(C12:N12) -> 74 | R12: 0900-1000 | S12: =SUM(C18:C21) -> 33 | T12: =SUM(D18:D21) -> 8 | U12: =SUM(E18:E21) -> 13 | V12: =SUM(F18:F21) -> 116 | W12: =SUM(G18:G21) -> 3 | X12: =SUM(H18:H21) -> 4 | Y12: =SUM(I18:I21) -> 17 | Z12: =SUM(J18:J21) -> 14 | ... AF12: =SUM(P18:P21) -> 335
B13: 07.45 - 08.00 | C13: 7 | D13: 3 | E13: 1 | F13: 42 | G13: 1 | H13: 1 | I13: 2 | J13: 3 | K13: 5 | L13: 10 | M13: 21 | N13: 0 | O13: =SUM(C13:L13,N13) -> 75 | P13: =SUM(C13:N13) -> 96 | R13: 1000-1100 | S13: =SUM(C22:C25) -> 41 | T13: =SUM(D22:D25) -> 11 | U13: =SUM(E22:E25) -> 18 | V13: =SUM(F22:F25) -> 94 | W13: =SUM(G22:G25) -> 5 | X13: =SUM(H22:H25) -> 2 | Y13: =SUM(I22:I25) -> 16 | Z13: =SUM(J22:J25) -> 11 | ... AF13: =SUM(P22:P25) -> 321
B14: 08.00 - 08.15 | C14: 17 | D14: 2 | E14: 4 | F14: 36 | G14: 0 | H14: 0 | I14: 4 | J14: 2 | K14: 0 | L14: 13 | M14: 18 | N14: 0 | O14: =SUM(C14:L14,N14) -> 78 | P14: =SUM(C14:N14) -> 96 | R14: 1100-1200 | S14: =SUM(C26:C29) -> 40 | T14: =SUM(D26:D29) -> 10 | U14: =SUM(E26:E29) -> 13 | V14: =SUM(F26:F29) -> 87 | W14: =SUM(G26:G29) -> 0 | X14: =SUM(H26:H29) -> 2 | Y14: =SUM(I26:I29) -> 23 | Z14: =SUM(J26:J29) -> 18 | ... AF14: =SUM(P26:P29) -> 330
B15: 08.15 - 08.30 | C15: 11 | D15: 2 | E15: 2 | F15: 30 | G15: 0 | H15: 0 | I15: 3 | J15: 5 | K15: 0 | L15: 15 | M15: 22 | N15: 0 | O15: =SUM(C15:L15,N15) -> 68 | P15: =SUM(C15:N15) -> 90 | R15: 1200-1300 | S15: =SUM(C30:C33) -> 51 | T15: =SUM(D30:D33) -> 5 | U15: =SUM(E30:E33) -> 11 | V15: =SUM(F30:F33) -> 84 | W15: =SUM(G30:G33) -> 2 | X15: =SUM(H30:H33) -> 1 | Y15: =SUM(I30:I33) -> 21 | Z15: =SUM(J30:J33) -> 20 | ... AF15: =SUM(P30:P33) -> 313
B16: 08.30 - 08.45 | C16: 15 | D16: 6 | E16: 1 | F16: 24 | G16: 0 | H16: 2 | I16: 4 | J16: 3 | K16: 0 | L16: 23 | M16: 14 | N16: 0 | O16: =SUM(C16:L16,N16) -> 78 | P16: =SUM(C16:N16) -> 92 | R16: 1300-1400 | S16: =SUM(C34:C37) -> 68 | T16: =SUM(D34:D37) -> 15 | U16: =SUM(E34:E37) -> 14 | V16: =SUM(F34:F37) -> 105 | W16: =SUM(G34:G37) -> 0 | X16: =SUM(H34:H37) -> 0 | Y16: =SUM(I34:I37) -> 21 | Z16: =SUM(J34:J37) -> 24 | ... AF16: =SUM(P34:P37) -> 376
B17: 08.45 - 9.00 | C17: 16 | D17: 0 | E17: 4 | F17: 38 | G17: 1 | H17: 1 | I17: 2 | J17: 4 | K17: 1 | L17: 11 | M17: 24 | N17: 0 | O17: =SUM(C17:L17,N17) -> 78 | P17: =SUM(C17:N17) -> 102 | R17: 1400-1500 | S17: =SUM(C38:C41) -> 56 | T17: =SUM(D38:D41) -> 28 | U17: =SUM(E38:E41) -> 15 | V17: =SUM(F38:F41) -> 105 | W17: =SUM(G38:G41) -> 0 | X17: =SUM(H38:H41) -> 4 | Y17: =SUM(I38:I41) -> 25 | Z17: =SUM(J38:J41) -> 19 | ... AF17: =SUM(P38:P41) -> 405
B18: 09.00 - 09.15 | C18: 4 | D18: 3 | E18: 4 | F18: 20 | G18: 3 | H18: 2 | I18: 2 | J18: 3 | K18: 2 | L18: 14 | M18: 12 | N18: 0 | O18: =SUM(C18:L18,N18) -> 57 | P18: =SUM(C18:N18) -> 69 | R18: 1500-1600 | S18: =SUM(C42:C45) -> 70 | T18: =SUM(D42:D45) -> 22 | U18: =SUM(E42:E45) -> 17 | V18: =SUM(F42:F45) -> 107 | W18: =SUM(G42:G45) -> 7 | X18: =SUM(H42:H45) -> 2 | Y18: =SUM(I42:I45) -> 19 | Z18: =SUM(J42:J45) -> 32 | ... AF18: =SUM(P42:P45) -> 408
B19: 09.15 - 09.30 | C19: 9 | D19: 4 | E19: 6 | F19: 41 | G19: 0 | H19: 1 | I19: 4 | J19: 6 | K19: 0 | L19: 17 | M19: 14 | N19: 0 | O19: =SUM(C19:L19,N19) -> 88 | P19: =SUM(C19:N19) -> 102 | R19: 1600-1700 | S19: =SUM(C46:C49) -> 63 | T19: =SUM(D46:D49) -> 12 | U19: =SUM(E46:E49) -> 14 | V19: =SUM(F46:F49) -> 101 | W19: =SUM(G46:G49) -> 2 | X19: =SUM(H46:H49) -> 2 | Y19: =SUM(I46:I49) -> 20 | Z19: =SUM(J46:J49) -> 24 | ... AF19: =SUM(P46:P49) -> 403
B20: 09.30 - 09.45 | C20: 11 | D20: 0 | E20: 1 | F20: 36 | G20: 0 | H20: 0 | I20: 6 | J20: 1 | K20: 1 | L20: 15 | M20: 17 | N20: 0 | O20: =SUM(C20:L20,N20) -> 71 | P20: =SUM(C20:N20) -> 88 | R20: 1700-1800 | S20: =SUM(C50:C53) -> 74 | T20: =SUM(D50:D53) -> 18 | U20: =SUM(E50:E53) -> 20 | V20: =SUM(F50:F53) -> 115 | W20: =SUM(G50:G53) -> 3 | X20: =SUM(H50:H53) -> 3 | Y20: =SUM(I50:I53) -> 22 | Z20: =SUM(J50:J53) -> 24 | ... AF20: =SUM(P50:P53) -> 447
B21: 09.45 - 10.00 | C21: 9 | D21: 1 | E21: 2 | F21: 19 | G21: 0 | H21: 1 | I21: 5 | J21: 4 | K21: 0 | L21: 12 | M21: 23 | N21: 0 | O21: =SUM(C21:L21,N21) -> 53 | P21: =SUM(C21:N21) -> 76 | R21: 1800-1900 | S21: =SUM(C54:C57) -> 58 | T21: =SUM(D54:D57) -> 13 | U21: =SUM(E54:E57) -> 17 | V21: =SUM(F54:F57) -> 93 | W21: =SUM(G54:G57) -> 7 | X21: =SUM(H54:H57) -> 2 | Y21: =SUM(I54:I57) -> 25 | Z21: =SUM(J54:J57) -> 27 | ... AF21: =SUM(P54:P57) -> 353
B22: 10.00 - 10.15 | C22: 15 | D22: 3 | E22: 4 | F22: 19 | G22: 1 | H22: 2 | I22: 4 | J22: 0 | K22: 0 | L22: 14 | M22: 19 | N22: 0 | O22: =SUM(C22:L22,N22) -> 62 | P22: =SUM(C22:N22) -> 81 | R22: AM Peak Hr | S22: =MAX(S10:S12) -> 59 | T22: =MAX(T10:T12) -> 10 | U22: =MAX(U10:U12) -> 13 | V22: =MAX(V10:V12) -> 144 | W22: =MAX(W10:W12) -> 4 | X22: =MAX(X10:X12) -> 4 | Y22: =MAX(Y10:Y12) -> 17 | Z22: =MAX(Z10:Z12) -> 14 | ... AF22: =MAX(AF10:AF12) -> 380
B23: 10.15 - 10.30 | C23: 7 | D23: 0 | E23: 4 | F23: 26 | G23: 0 | H23: 0 | I23: 3 | J23: 6 | K23: 1 | L23: 11 | M23: 16 | N23: 0 | O23: =SUM(C23:L23,N23) -> 58 | P23: =SUM(C23:N23) -> 74 | R23: IP Peak Hr | S23: =MAX(S13:S18) -> 70 | T23: =MAX(T13:T18) -> 28 | U23: =MAX(U13:U18) -> 18 | V23: =MAX(V13:V18) -> 107 | W23: =MAX(W13:W18) -> 7 | X23: =MAX(X13:X18) -> 4 | Y23: =MAX(Y13:Y18) -> 25 | Z23: =MAX(Z13:Z18) -> 32 | ... AF23: =MAX(AF13:AF18) -> 408
B24: 10.30 - 10.45 | C24: 13 | D24: 7 | E24: 4 | F24: 26 | G24: 1 | H24: 0 | I24: 6 | J24: 2 | K24: 1 | L24: 12 | M24: 18 | N24: 0 | O24: =SUM(C24:L24,N24) -> 72 | P24: =SUM(C24:N24) -> 90 | R24: PM Peak Hr | S24: =MAX(S19:S21) -> 74 | T24: =MAX(T19:T21) -> 18 | U24: =MAX(U19:U21) -> 20 | V24: =MAX(V19:V21) -> 115 | W24: =MAX(W19:W21) -> 7 | X24: =MAX(X19:X21) -> 3 | Y24: =MAX(Y19:Y21) -> 25 | Z24: =MAX(Z19:Z21) -> 27 | ... AF24: =MAX(AF19:AF21) -> 447
B25: 10.45 - 11.00 | C25: 6 | D25: 1 | E25: 6 | F25: 23 | G25: 3 | H25: 0 | I25: 3 | J25: 3 | K25: 2 | L25: 11 | M25: 18 | N25: 0 | O25: =SUM(C25:L25,N25) -> 58 | P25: =SUM(C25:N25) -> 76 | R25: AM Period | S25: =SUM(S10:S12) -> 126 | T25: =SUM(T10:T12) -> 26 | U25: =SUM(U10:U12) -> 32 | V25: =SUM(V10:V12) -> 388 | W25: =SUM(W10:W12) -> 8 | X25: =SUM(X10:X12) -> 10 | Y25: =SUM(Y10:Y12) -> 39 | Z25: =SUM(Z10:Z12) -> 36 | ... AF25: =SUM(AF10:AF12) -> 1076
B26: 11.00 - 11.15 | C26: 5 | D26: 1 | E26: 2 | F26: 14 | G26: 0 | H26: 0 | I26: 5 | J26: 4 | K26: 0 | L26: 12 | M26: 15 | N26: 0 | O26: =SUM(C26:L26,N26) -> 43 | P26: =SUM(C26:N26) -> 58 | R26: IP Period | S26: =SUM(S13:S18) -> 326 | T26: =SUM(T13:T18) -> 91 | U26: =SUM(U13:U18) -> 88 | V26: =SUM(V13:V18) -> 582 | W26: =SUM(W13:W18) -> 14 | X26: =SUM(X13:X18) -> 11 | Y26: =SUM(Y13:Y18) -> 125 | Z26: =SUM(Z13:Z18) -> 124 | ... AF26: =SUM(AF13:AF18) -> 2153
B27: 11.15 - 11.30 | C27: 8 | D27: 1 | E27: 7 | F27: 28 | G27: 0 | H27: 1 | I27: 7 | J27: 4 | K27: 0 | L27: 11 | M27: 27 | N27: 0 | O27: =SUM(C27:L27,N27) -> 67 | P27: =SUM(C27:N27) -> 94 | R27: PM Period | S27: =SUM(S19:S21) -> 195 | T27: =SUM(T19:T21) -> 43 | U27: =SUM(U19:U21) -> 51 | V27: =SUM(V19:V21) -> 309 | W27: =SUM(W19:W21) -> 12 | X27: =SUM(X19:X21) -> 7 | Y27: =SUM(Y19:Y21) -> 67 | Z27: =SUM(Z19:Z21) -> 75 | ... AF27: =SUM(AF19:AF21) -> 1203
B28: 11.30 - 11.45 | C28: 10 | D28: 5 | E28: 2 | F28: 21 | G28: 0 | H28: 1 | I28: 7 | J28: 4 | K28: 1 | L28: 18 | M28: 17 | N28: 0 | O28: =SUM(C28:L28,N28) -> 69 | P28: =SUM(C28:N28) -> 86 | R28: 12 Hours | S28: =SUM(S10:S21) -> 647 | T28: =SUM(T10:T21) -> 160 | U28: =SUM(U10:U21) -> 171 | V28: =SUM(V10:V21) -> 1279 | W28: =SUM(W10:W21) -> 34 | X28: =SUM(X10:X21) -> 28 | Y28: =SUM(Y10:Y21) -> 231 | Z28: =SUM(Z10:Z21) -> 235 | ... AF28: =SUM(AF10:AF21) -> 4432
B29: 11.45 - 12.00 | C29: 17 | D29: 3 | E29: 2 | F29: 24 | G29: 0 | H29: 0 | I29: 4 | J29: 6 | K29: 3 | L29: 12 | M29: 21 | N29: 0 | O29: =SUM(C29:L29,N29) -> 71 | P29: =SUM(C29:N29) -> 92
B30: 12.00 - 12.15 | C30: 15 | D30: 0 | E30: 3 | F30: 19 | G30: 0 | H30: 1 | I30: 7 | J30: 8 | K30: 0 | L30: 6 | M30: 19 | N30: 0 | O30: =SUM(C30:L30,N30) -> 59 | P30: =SUM(C30:N30) -> 78
B31: 12.15 - 12.30 | C31: 9 | D31: 4 | E31: 7 | F31: 16 | G31: 0 | H31: 0 | I31: 4 | J31: 4 | K31: 0 | L31: 16 | M31: 16 | N31: 1 | O31: =SUM(C31:L31,N31) -> 61 | P31: =SUM(C31:N31) -> 77
B32: 12.30 - 12.45 | C32: 18 | D32: 0 | E32: 1 | F32: 27 | G32: 1 | H32: 0 | I32: 3 | J32: 4 | K32: 1 | L32: 7 | M32: 15 | N32: 0 | O32: =SUM(C32:L32,N32) -> 62 | P32: =SUM(C32:N32) -> 77
B33: 12.45 - 13.00 | C33: 9 | D33: 1 | E33: 0 | F33: 22 | G33: 1 | H33: 0 | I33: 7 | J33: 4 | K33: 7 | L33: 15 | M33: 15 | N33: 0 | O33: =SUM(C33:L33,N33) -> 66 | P33: =SUM(C33:N33) -> 81
B34: 13.00 - 13.15 | C34: 17 | D34: 3 | E34: 2 | F34: 34 | G34: 0 | H34: 0 | I34: 6 | J34: 10 | K34: 1 | L34: 6 | M34: 17 | N34: 0 | O34: =SUM(C34:L34,N34) -> 79 | P34: =SUM(C34:N34) -> 96
B35: 13.15 - 13.30 | C35: 24 | D35: 3 | E35: 4 | F35: 26 | G35: 0 | H35: 0 | I35: 5 | J35: 7 | K35: 4 | L35: 9 | M35: 26 | N35: 0 | O35: =SUM(C35:L35,N35) -> 82 | P35: =SUM(C35:N35) -> 108
B36: 13.30 - 13.45 | C36: 11 | D36: 6 | E36: 5 | F36: 21 | G36: 0 | H36: 0 | I36: 4 | J36: 5 | K36: 1 | L36: 11 | M36: 24 | N36: 0 | O36: =SUM(C36:L36,N36) -> 64 | P36: =SUM(C36:N36) -> 88
B37: 13.45 - 14.00 | C37: 16 | D37: 3 | E37: 3 | F37: 24 | G37: 0 | H37: 0 | I37: 6 | J37: 2 | K37: 0 | L37: 5 | M37: 25 | N37: 0 | O37: =SUM(C37:L37,N37) -> 59 | P37: =SUM(C37:N37) -> 84
B38: 14.00 - 14.15 | C38: 5 | D38: 2 | E38: 3 | F38: 25 | G38: 0 | H38: 2 | I38: 6 | J38: 4 | K38: 1 | L38: 10 | M38: 34 | N38: 0 | O38: =SUM(C38:L38,N38) -> 58 | P38: =SUM(C38:N38) -> 92
B39: 14.15 - 14.30 | C39: 22 | D39: 8 | E39: 2 | F39: 31 | G39: 0 | H39: 1 | I39: 3 | J39: 5 | K39: 0 | L39: 12 | M39: 22 | N39: 0 | O39: =SUM(C39:L39,N39) -> 84 | P39: =SUM(C39:N39) -> 106
B40: 14.30 - 14.45 | C40: 14 | D40: 13 | E40: 5 | F40: 24 | G40: 0 | H40: 1 | I40: 7 | J40: 3 | K40: 2 | L40: 11 | M40: 14 | N40: 0 | O40: =SUM(C40:L40,N40) -> 80 | P40: =SUM(C40:N40) -> 94
... B57: 18.45 - 19.00 | C57: 0 | D57: 0 | E57: 0 | F57: 0 | G57: 0 | H57: 0 | I57: 0 | J57: 0 | K57: 0 | L57: 0 | M57: 0 | N57: 0 | O57: =SUM(C57:L57,N57) -> 0 | P57: =SUM(C57:N57) -> 0
B58: Totals | C58: =SUM(C10:C57) -> 647 | D58: =SUM(D10:D57) -> 160 | E58: =SUM(E10:E57) -> 171 | F58: =SUM(F10:F57) -> 1279 | G58: =SUM(G10:G57) -> 34 | H58: =SUM(H10:H57) -> 28 | I58: =SUM(I10:I57) -> 231 | J58: =SUM(J10:J57) -> 235 | ... P58: =SUM(P10:P57) -> 4432
...

Sheet 17.10 Kampala-Jinja
B1: Consultancy services for Preparation of Expressway Development Master Plan (EDMP) for Uganda
B2: MANUAL CLASSIFIED COUNT (MCC)
B3: ROAD NAME: | C3: ='17.10 jinja-kampala'!C3:G3 -> MCC - C 4- STN19 -Kampala-Jinja highway
C5: Date | D5: ='17.10 jinja-kampala'!D5 -> 17.10.19 | F5: Location | G5: ='17.10 jinja-kampala'!G5:H5 -> Nakibbizi | J5: Surveyor | K5: Jerome
C6: Dir. From | D6: Kampala | F6: Dir. To | G6: Jinja | J6: Supervisor | K6: ='17.10 jinja-kampala'!K6:L6 -> Emma
B8: Time / Veh Type | R8: SUMMARY TRAFFIC VOLUMES
C9: 1. Car | D9: 2. Station Wagon | E9: 3. Pickups | F9: 4. Minibus, matatu | G9: 5. Medium bus | H9: 6. Large Bus | I9: 7. Light Truck | J9: 8. Medium Truck | K9: 9. Heavy truck | L9: 10. Truck Trailer | M9: 11. Motor cycles | N9: 12. Tractors | O9: Total Excl M/Cycles | P9: Total All | R9: Time | S9: 1. Car | T9: 2. Station Wagon | U9: 3. Pickups | V9: 4. Minibus, matatu | W9: 5. Medium bus | X9: 6. Large Bus | Y9: 7. Light Truck | Z9: 8. Medium Truck | AA9: 9. Heavy truck | AB9: 10. Truck Trailer | AC9: 11. Motorcycles | AD9: 12. Tractors, Graders | AE9: Total Excl M/ Cycles | AF9: Total All
B10: 07.00 - 07.15 | C10: 64 | D10: 5 | E10: 2 | F10: 30 | G10: 1 | H10: 0 | I10: 4 | J10: 7 | K10: 4 | L10: 10 | M10: 25 | N10: 0 | O10: =SUM(C10:L10,N10) -> 127 | P10: =SUM(C10:N10) -> 152 | R10: 0700-0800 | S10: =SUM(C10:C13) -> 97 | T10: =SUM(D10:D13) -> 26 | U10: =SUM(E10:E13) -> 11 | V10: =SUM(F10:F13) -> 107 | W10: =SUM(G10:G13) -> 3 | X10: =SUM(H10:H13) -> 0 | Y10: =SUM(I10:I13) -> 17 | Z10: =SUM(J10:J13) -> 28 | ... AF10: =SUM(P10:P13) -> 418
B11: 07.15 - 07.30 | C11: 8 | D11: 6 | E11: 3 | F11: 23 | G11: 2 | H11: 0 | I11: 4 | J11: 6 | K11: 3 | L11: 6 | M11: 25 | N11: 0 | O11: =SUM(C11:L11,N11) -> 61 | P11: =SUM(C11:N11) -> 86 | R11: 0800-0900 | S11: =SUM(C14:C17) -> 32 | T11: =SUM(D14:D17) -> 15 | U11: =SUM(E14:E17) -> 13 | V11: =SUM(F14:F17) -> 101 | W11: =SUM(G14:G17) -> 1 | X11: =SUM(H14:H17) -> 2 | Y11: =SUM(I14:I17) -> 8 | Z11: =SUM(J14:J17) -> 10 | ... AF11: =SUM(P14:P17) -> 265
B12: 07.30 - 07.45 | C12: 11 | D12: 8 | E12: 3 | F12: 30 | G12: 0 | H12: 0 | I12: 7 | J12: 5 | K12: 2 | L12: 6 | M12: 20 | N12: 0 | O12: =SUM(C12:L12,N12) -> 72 | P12: =SUM(C12:N12) -> 92 | R12: 0900-1000 | S12: =SUM(C18:C21) -> 35 | T12: =SUM(D18:D21) -> 18 | U12: =SUM(E18:E21) -> 11 | V12: =SUM(F18:F21) -> 121 | W12: =SUM(G18:G21) -> 2 | X12: =SUM(H18:H21) -> 2 | Y12: =SUM(I18:I21) -> 14 | Z12: =SUM(J18:J21) -> 14 | ... AF12: =SUM(P18:P21) -> 291
B13: 07.45 - 08.00 | C13: 14 | D13: 7 | E13: 3 | F13: 24 | G13: 0 | H13: 0 | I13: 2 | J13: 10 | K13: 1 | L13: 6 | M13: 21 | N13: 0 | O13: =SUM(C13:L13,N13) -> 67 | P13: =SUM(C13:N13) -> 88 | R13: 1000-1100 | S13: =SUM(C22:C25) -> 28 | T13: =SUM(D22:D25) -> 12 | U13: =SUM(E22:E25) -> 8 | V13: =SUM(F22:F25) -> 93 | W13: =SUM(G22:G25) -> 4 | X13: =SUM(H22:H25) -> 1 | Y13: =SUM(I22:I25) -> 13 | Z13: =SUM(J22:J25) -> 13 | ... AF13: =SUM(P22:P25) -> 267
B14: 08.00 - 08.15 | C14: 7 | D14: 4 | E14: 3 | F14: 28 | G14: 0 | H14: 1 | I14: 4 | J14: 4 | K14: 0 | L14: 4 | M14: 14 | N14: 0 | O14: =SUM(C14:L14,N14) -> 55 | P14: =SUM(C14:N14) -> 69 | R14: 1100-1200 | S14: =SUM(C26:C29) -> 52 | T14: =SUM(D26:D29) -> 22 | U14: =SUM(E26:E29) -> 12 | V14: =SUM(F26:F29) -> 97 | W14: =SUM(G26:G29) -> 3 | X14: =SUM(H26:H29) -> 0 | Y14: =SUM(I26:I29) -> 26 | Z14: =SUM(J26:J29) -> 25 | ... AF14: =SUM(P26:P29) -> 342
B15: 08.15 - 08.30 | C15: 12 | D15: 4 | E15: 5 | F15: 29 | G15: 1 | H15: 0 | I15: 3 | J15: 1 | K15: 3 | L15: 4 | M15: 13 | N15: 0 | O15: =SUM(C15:L15,N15) -> 62 | P15: =SUM(C15:N15) -> 75 | R15: 1200-1300 | S15: =SUM(C30:C33) -> 43 | T15: =SUM(D30:D33) -> 29 | U15: =SUM(E30:E33) -> 21 | V15: =SUM(F30:F33) -> 127 | W15: =SUM(G30:G33) -> 6 | X15: =SUM(H30:H33) -> 2 | Y15: =SUM(I30:I33) -> 11 | Z15: =SUM(J30:J33) -> 18 | ... AF15: =SUM(P30:P33) -> 353
B16: 08.30 - 08.45 | C16: 7 | D16: 1 | E16: 3 | F16: 18 | G16: 0 | H16: 1 | I16: 1 | J16: 4 | K16: 4 | L16: 3 | M16: 18 | N16: 0 | O16: =SUM(C16:L16,N16) -> 42 | P16: =SUM(C16:N16) -> 60 | R16: 1300-1400 | S16: =SUM(C34:C37) -> 51 | T16: =SUM(D34:D37) -> 19 | U16: =SUM(E34:E37) -> 10 | V16: =SUM(F34:F37) -> 125 | W16: =SUM(G34:G37) -> 3 | X16: =SUM(H34:H37) -> 3 | Y16: =SUM(I34:I37) -> 16 | Z16: =SUM(J34:J37) -> 17 | ... AF16: =SUM(P34:P37) -> 367
B17: 08.45 - 9.00 | C17: 6 | D17: 6 | E17: 2 | F17: 26 | G17: 0 | H17: 0 | I17: 0 | J17: 1 | K17: 1 | L17: 5 | M17: 14 | N17: 0 | O17: =SUM(C17:L17,N17) -> 47 | P17: =SUM(C17:N17) -> 61 | R17: 1400-1500 | S17: =SUM(C38:C41) -> 31 | T17: =SUM(D38:D41) -> 14 | U17: =SUM(E38:E41) -> 14 | V17: =SUM(F38:F41) -> 115 | W17: =SUM(G38:G41) -> 6 | X17: =SUM(H38:H41) -> 1 | Y17: =SUM(I38:I41) -> 19 | Z17: =SUM(J38:J41) -> 16 | ... AF17: =SUM(P38:P41) -> 339
B18: 09.00 - 09.15 | C18: 7 | D18: 5 | E18: 5 | F18: 36 | G18: 1 | H18: 1 | I18: 5 | J18: 5 | K18: 2 | L18: 5 | M18: 17 | N18: 0 | O18: =SUM(C18:L18,N18) -> 72 | P18: =SUM(C18:N18) -> 89 | R18: 1500-1600 | S18: =SUM(C42:C45) -> 39 | T18: =SUM(D42:D45) -> 23 | U18: =SUM(E42:E45) -> 15 | V18: =SUM(F42:F45) -> 111 | W18: =SUM(G42:G45) -> 4 | X18: =SUM(H42:H45) -> 2 | Y18: =SUM(I42:I45) -> 17 | Z18: =SUM(J42:J45) -> 38 | ... AF18: =SUM(P42:P45) -> 394
B19: 09.15 - 09.30 | C19: 8 | D19: 2 | E19: 2 | F19: 23 | G19: 0 | H19: 0 | I19: 2 | J19: 3 | K19: 2 | L19: 1 | M19: 12 | N19: 0 | O19: =SUM(C19:L19,N19) -> 43 | P19: =SUM(C19:N19) -> 55 | R19: 1600-1700 | S19: =SUM(C46:C49) -> 36 | T19: =SUM(D46:D49) -> 17 | U19: =SUM(E46:E49) -> 13 | V19: =SUM(F46:F49) -> 91 | W19: =SUM(G46:G49) -> 3 | X19: =SUM(H46:H49) -> 2 | Y19: =SUM(I46:I49) -> 16 | Z19: =SUM(J46:J49) -> 22 | ... AF19: =SUM(P46:P49) -> 372
B20: 09.30 - 09.45 | C20: 9 | D20: 6 | E20: 2 | F20: 26 | G20: 0 | H20: 0 | I20: 4 | J20: 1 | K20: 1 | L20: 1 | M20: 18 | N20: 0 | O20: =SUM(C20:L20,N20) -> 50 | P20: =SUM(C20:N20) -> 68 | R20: 1700-1800 | S20: =SUM(C50:C53) -> 25 | T20: =SUM(D50:D53) -> 18 | U20: =SUM(E50:E53) -> 12 | V20: =SUM(F50:F53) -> 128 | W20: =SUM(G50:G53) -> 3 | X20: =SUM(H50:H53) -> 1 | Y20: =SUM(I50:I53) -> 16 | Z20: =SUM(J50:J53) -> 30 | ... AF20: =SUM(P50:P53) -> 390
B21: 09.45 - 10.00 | C21: 11 | D21: 5 | E21: 2 | F21: 36 | G21: 1 | H21: 1 | I21: 3 | J21: 5 | K21: 1 | L21: 3 | M21: 10 | N21: 1 | O21: =SUM(C21:L21,N21) -> 69 | P21: =SUM(C21:N21) -> 79 | R21: 1800-1900 | S21: =SUM(C54:C57) -> 47 | T21: =SUM(D54:D57) -> 22 | U21: =SUM(E54:E57) -> 19 | V21: =SUM(F54:F57) -> 105 | W21: =SUM(G54:G57) -> 5 | X21: =SUM(H54:H57) -> 5 | Y21: =SUM(I54:I57) -> 21 | Z21: =SUM(J54:J57) -> 24 | ... AF21: =SUM(P54:P57) -> 394
B22: 10.00 - 10.15 | C22: 7 | D22: 4 | E22: 5 | F22: 25 | G22: 1 | H22: 1 | I22: 4 | J22: 4 | K22: 0 | L22: 2 | M22: 25 | N22: 0 | O22: =SUM(C22:L22,N22) -> 53 | P22: =SUM(C22:N22) -> 78 | R22: AM Peak Hr | S22: =MAX(S10:S12) -> 97 | T22: =MAX(T10:T12) -> 26 | U22: =MAX(U10:U12) -> 13 | V22: =MAX(V10:V12) -> 121 | W22: =MAX(W10:W12) -> 3 | X22: =MAX(X10:X12) -> 2 | Y22: =MAX(Y10:Y12) -> 17 | Z22: =MAX(Z10:Z12) -> 28 | ... AF22: =MAX(AF10:AF12) -> 418
B23: 10.15 - 10.30 | C23: 10 | D23: 2 | E23: 0 | F23: 10 | G23: 2 | H23: 0 | I23: 1 | J23: 1 | K23: 1 | L23: 1 | M23: 17 | N23: 0 | O23: =SUM(C23:L23,N23) -> 28 | P23: =SUM(C23:N23) -> 45 | R23: IP Peak Hr | S23: =MAX(S13:S18) -> 52 | T23: =MAX(T13:T18) -> 29 | U23: =MAX(U13:U18) -> 21 | V23: =MAX(V13:V18) -> 127 | W23: =MAX(W13:W18) -> 6 | X23: =MAX(X13:X18) -> 3 | Y23: =MAX(Y13:Y18) -> 26 | Z23: =MAX(Z13:Z18) -> 38 | ... AF23: =MAX(AF13:AF18) -> 394
B24: 10.30 - 10.45 | C24: 5 | D24: 1 | E24: 1 | F24: 33 | G24: 1 | H24: 0 | I24: 4 | J24: 5 | K24: 1 | L24: 4 | M24: 23 | N24: 0 | O24: =SUM(C24:L24,N24) -> 55 | P24: =SUM(C24:N24) -> 78 | R24: PM Peak Hr | S24: =MAX(S19:S21) -> 47 | T24: =MAX(T19:T21) -> 22 | U24: =MAX(U19:U21) -> 19 | V24: =MAX(V19:V21) -> 128 | W24: =MAX(W19:W21) -> 5 | X24: =MAX(X19:X21) -> 5 | Y24: =MAX(Y19:Y21) -> 21 | Z24: =MAX(Z19:Z21) -> 30 | ... AF24: =MAX(AF19:AF21) -> 394
B25: 10.45 - 11.00 | C25: 6 | D25: 5 | E25: 2 | F25: 25 | G25: 0 | H25: 0 | I25: 4 | J25: 3 | K25: 4 | L25: 3 | M25: 14 | N25: 0 | O25: =SUM(C25:L25,N25) -> 52 | P25: =SUM(C25:N25) -> 66 | R25: AM Period | S25: =SUM(S10:S12) -> 164 | T25: =SUM(T10:T12) -> 59 | U25: =SUM(U10:U12) -> 35 | V25: =SUM(V10:V12) -> 329 | W25: =SUM(W10:W12) -> 6 | X25: =SUM(X10:X12) -> 4 | Y25: =SUM(Y10:Y12) -> 39 | Z25: =SUM(Z10:Z12) -> 52 | ... AF25: =SUM(AF10:AF12) -> 974
B26: 11.00 - 11.15 | C26: 11 | D26: 7 | E26: 4 | F26: 2 | G26: 2 | H26: 0 | I26: 8 | J26: 7 | K26: 1 | L26: 5 | M26: 15 | N26: 0 | O26: =SUM(C26:L26,N26) -> 47 | P26: =SUM(C26:N26) -> 62 | R26: IP Period | S26: =SUM(S13:S18) -> 244 | T26: =SUM(T13:T18) -> 119 | U26: =SUM(U13:U18) -> 80 | V26: =SUM(V13:V18) -> 668 | W26: =SUM(W13:W18) -> 26 | X26: =SUM(X13:X18) -> 9 | Y26: =SUM(Y13:Y18) -> 102 | Z26: =SUM(Z13:Z18) -> 127 | ... AF26: =SUM(AF13:AF18) -> 2062
B27: 11.15 - 11.30 | C27: 14 | D27: 5 | E27: 1 | F27: 43 | G27: 1 | H27: 0 | I27: 6 | J27: 5 | K27: 0 | L27: 11 | M27: 18 | N27: 0 | O27: =SUM(C27:L27,N27) -> 86 | P27: =SUM(C27:N27) -> 104 | R27: PM Period | S27: =SUM(S19:S21) -> 108 | T27: =SUM(T19:T21) -> 57 | U27: =SUM(U19:U21) -> 44 | V27: =SUM(V19:V21) -> 324 | W27: =SUM(W19:W21) -> 11 | X27: =SUM(X19:X21) -> 8 | Y27: =SUM(Y19:Y21) -> 53 | Z27: =SUM(Z19:Z21) -> 76 | ... AF27: =SUM(AF19:AF21) -> 1156
B28: 11.30 - 11.45 | C28: 15 | D28: 5 | E28: 3 | F28: 35 | G28: 0 | H28: 0 | I28: 4 | J28: 6 | K28: 2 | L28: 7 | M28: 18 | N28: 0 | O28: =SUM(C28:L28,N28) -> 77 | P28: =SUM(C28:N28) -> 95 | R28: 12 Hours | S28: =SUM(S10:S21) -> 516 | T28: =SUM(T10:T21) -> 235 | U28: =SUM(U10:U21) -> 159 | V28: =SUM(V10:V21) -> 1321 | W28: =SUM(W10:W21) -> 43 | X28: =SUM(X10:X21) -> 21 | Y28: =SUM(Y10:Y21) -> 194 | Z28: =SUM(Z10:Z21) -> 255 | ... AF28: =SUM(AF10:AF21) -> 4192
B29: 11.45 - 12.00 | C29: 12 | D29: 5 | E29: 4 | F29: 17 | G29: 0 | H29: 0 | I29: 8 | J29: 7 | K29: 2 | L29: 7 | M29: 19 | N29: 0 | O29: =SUM(C29:L29,N29) -> 62 | P29: =SUM(C29:N29) -> 81
B30: 12.00 - 12.15 | C30: 9 | D30: 5 | E30: 3 | F30: 25 | G30: 2 | H30: 1 | I30: 4 | J30: 2 | K30: 0 | L30: 8 | M30: 19 | N30: 0 | O30: =SUM(C30:L30,N30) -> 59 | P30: =SUM(C30:N30) -> 78
B31: 12.15 - 12.30 | C31: 16 | D31: 7 | E31: 7 | F31: 32 | G31: 0 | H31: 0 | I31: 4 | J31: 5 | K31: 1 | L31: 8 | M31: 14 | N31: 0 | O31: =SUM(C31:L31,N31) -> 80 | P31: =SUM(C31:N31) -> 94
B32: 12.30 - 12.45 | C32: 8 | D32: 10 | E32: 5 | F32: 47 | G32: 1 | H32: 1 | I32: 2 | J32: 8 | K32: 1 | L32: 7 | M32: 12 | N32: 0 | O32: =SUM(C32:L32,N32) -> 90 | P32: =SUM(C32:N32) -> 102
B33: 12.45 - 13.00 | C33: 10 | D33: 7 | E33: 6 | F33: 23 | G33: 3 | H33: 0 | I33: 1 | J33: 3 | K33: 2 | L33: 7 | M33: 17 | N33: 0 | O33: =SUM(C33:L33,N33) -> 62 | P33: =SUM(C33:N33) -> 79
B34: 13.00 - 13.15 | C34: 16 | D34: 2 | E34: 1 | F34: 32 | G34: 1 | H34: 0 | I34: 5 | J34: 5 | K34: 2 | L34: 5 | M34: 24 | N34: 0 | O34: =SUM(C34:L34,N34) -> 69 | P34: =SUM(C34:N34) -> 93
B35: 13.15 - 13.30 | C35: 7 | D35: 2 | E35: 5 | F35: 30 | G35: 1 | H35: 2 | I35: 3 | J35: 5 | K35: 1 | L35: 10 | M35: 13 | N35: 0 | O35: =SUM(C35:L35,N35) -> 66 | P35: =SUM(C35:N35) -> 79
B36: 13.30 - 13.45 | C36: 14 | D36: 7 | E36: 0 | F36: 30 | G36: 0 | H36: 1 | I36: 4 | J36: 2 | K36: 1 | L36: 22 | M36: 20 | N36: 0 | O36: =SUM(C36:L36,N36) -> 81 | P36: =SUM(C36:N36) -> 101
B37: 13.45 - 14.00 | C37: 14 | D37: 8 | E37: 4 | F37: 33 | G37: 1 | H37: 0 | I37: 4 | J37: 5 | K37: 2 | L37: 9 | M37: 14 | N37: 0 | O37: =SUM(C37:L37,N37) -> 80 | P37: =SUM(C37:N37) -> 94
B38: 14.00 - 14.15 | C38: 6 | D38: 4 | E38: 2 | F38: 35 | G38: 3 | H38: 0 | I38: 3 | J38: 4 | K38: 4 | L38: 8 | M38: 17 | N38: 0 | O38: =SUM(C38:L38,N38) -> 69 | P38: =SUM(C38:N38) -> 86
B39: 14.15 - 14.30 | C39: 4 | D39: 2 | E39: 2 | F39: 29 | G39: 0 | H39: 0 | I39: 4 | J39: 3 | K39: 1 | L39: 11 | M39: 16 | N39: 0 | O39: =SUM(C39:L39,N39) -> 56 | P39: =SUM(C39:N39) -> 72
B40: 14.30 - 14.45 | C40: 12 | D40: 6 | E40: 5 | F40: 37 | G40: 1 | H40: 1 | I40: 4 | J40: 5 | K40: 6 | L40: 13 | M40: 16 | N40: 0 | O40: =SUM(C40:L40,N40) -> 90 | P40: =SUM(C40:N40) -> 106
... B57: 18.45 - 19.00 | C57: 0 | D57: 0 | E57: 0 | F57: 0 | G57: 0 | H57: 0 | I57: 0 | J57: 0 | K57: 0 | L57: 0 | M57: 0 | N57: 0 | O57: =SUM(C57:L57,N57) -> 0 | P57: =SUM(C57:N57) -> 0
B58: Totals | C58: =SUM(C10:C57) -> 516 | D58: =SUM(D10:D57) -> 235 | E58: =SUM(E10:E57) -> 159 | F58: =SUM(F10:F57) -> 1321 | G58: =SUM(G10:G57) -> 43 | H58: =SUM(H10:H57) -> 21 | I58: =SUM(I10:I57) -> 194 | J58: =SUM(J10:J57) -> 255 | ... P58: =SUM(P10:P57) -> 4192
...

Sheet 18.10 Jinja-Kampala
B1: Consultancy services for Preparation of Expressway Development Master Plan (EDMP) for Uganda
B2: MANUAL CLASSIFIED COUNT (MCC)
B3: ROAD NAME: | C3: ='17.10 jinja-kampala'!C3:G3 -> MCC - C 4- STN19 -Kampala-Jinja highway
C5: Date | D5: 18.10.19 | F5: Location | G5: ='17.10 jinja-kampala'!G5:H5 -> Nakibbizi | J5: Surveyor | K5: ='17.10 jinja-kampala'!K5:L5 -> Micheal
C6: Dir. From | D6: ='17.10 jinja-kampala'!D6:E6 -> Jinja | F6: Dir. To | G6: ='17.10 jinja-kampala'!G6:H6 -> Kampala | J6: Supervisor | K6: ='17.10 jinja-kampala'!K6:L6 -> Emma
B8: Time / Veh Type | R8: SUMMARY TRAFFIC VOLUMES
C9: 1. Car | D9: 2. Station Wagon | E9: 3. Pickups | F9: 4. Minibus, matatu | G9: 5. Medium bus | H9: 6. Large Bus | I9: 7. Light Truck | J9: 8. Medium Truck | K9: 9. Heavy truck | L9: 10. Truck Trailer | M9: 11. Motor cycles | N9: 12. Tractors | O9: Total Excl M/Cycles | P9: Total All | R9: Time | S9: 1. Car | T9: 2. Station Wagon | U9: 3. Pickups | V9: 4. Minibus, matatu | W9: 5. Medium bus | X9: 6. Large Bus | Y9: 7. Light Truck | Z9: 8. Medium Truck | AA9: 9. Heavy truck | AB9: 10. Truck Trailer | AC9: 11. Motorcycles | AD9: 12. Tractors, Graders | AE9: Total Excl M/ Cycles | AF9: Total All
B10: 07.00 - 07.15 | C10: 3 | D10: 1 | E10: 0 | F10: 18 | G10: 6 | H10: 0 | I10: 1 | J10: 2 | K10: 1 | L10: 17 | M10: 6 | N10: 0 | O10: =SUM(C10:L10,N10) -> 49 | P10: =SUM(C10:N10) -> 55 | R10: 0700-0800 | S10: =SUM(C10:C13) -> 30 | T10: =SUM(D10:D13) -> 9 | U10: =SUM(E10:E13) -> 6 | V10: =SUM(F10:F13) -> 106 | W10: =SUM(G10:G13) -> 15 | X10: =SUM(H10:H13) -> 3 | Y10: =SUM(I10:I13) -> 7 | Z10: =SUM(J10:J13) -> 10 | ... AF10: =SUM(P10:P13) -> 296
B11: 07.15 - 07.30 | C11: 9 | D11: 0 | E11: 3 | F11: 29 | G11: 1 | H11: 2 | I11: 4 | J11: 2 | K11: 1 | L11: 6 | M11: 19 | N11: 0 | O11: =SUM(C11:L11,N11) -> 57 | P11: =SUM(C11:N11) -> 76 | R11: 0800-0900 | S11: =SUM(C14:C17) -> 40 | T11: =SUM(D14:D17) -> 6 | U11: =SUM(E14:E17) -> 7 | V11: =SUM(F14:F17) -> 111 | W11: =SUM(G14:G17) -> 9 | X11: =SUM(H14:H17) -> 8 | Y11: =SUM(I14:I17) -> 10 | Z11: =SUM(J14:J17) -> 8 | ... AF11: =SUM(P14:P17) -> 327
B12: 07.30 - 07.45 | C12: 9 | D12: 6 | E12: 1 | F12: 30 | G12: 1 | H12: 0 | I12: 1 | J12: 2 | K12: 3 | L12: 9 | M12: 17 | N12: 1 | O12: =SUM(C12:L12,N12) -> 63 | P12: =SUM(C12:N12) -> 80 | R12: 0900-1000 | S12: =SUM(C18:C21) -> 46 | T12: =SUM(D18:D21) -> 23 | U12: =SUM(E18:E21) -> 22 | V12: =SUM(F18:F21) -> 121 | W12: =SUM(G18:G21) -> 7 | X12: =SUM(H18:H21) -> 6 | Y12: =SUM(I18:I21) -> 5 | Z12: =SUM(J18:J21) -> 16 | ... AF12: =SUM(P18:P21) -> 365
B13: 07.45 - 08.00 | C13: 9 | D13: 2 | E13: 2 | F13: 29 | G13: 7 | H13: 1 | I13: 1 | J13: 4 | K13: 3 | L13: 14 | M13: 13 | N13: 0 | O13: =SUM(C13:L13,N13) -> 72 | P13: =SUM(C13:N13) -> 85 | R13: 1000-1100 | S13: =SUM(C22:C25) -> 56 | T13: =SUM(D22:D25) -> 26 | U13: =SUM(E22:E25) -> 9 | V13: =SUM(F22:F25) -> 104 | W13: =SUM(G22:G25) -> 1 | X13: =SUM(H22:H25) -> 5 | Y13: =SUM(I22:I25) -> 15 | Z13: =SUM(J22:J25) -> 24 | ... AF13: =SUM(P22:P25) -> 399
B14: 08.00 - 08.15 | C14: 8 | D14: 1 | E14: 1 | F14: 34 | G14: 1 | H14: 0 | I14: 3 | J14: 1 | K14: 0 | L14: 13 | M14: 12 | N14: 0 | O14: =SUM(C14:L14,N14) -> 62 | P14: =SUM(C14:N14) -> 74 | R14: 1100-1200 | S14: =SUM(C26:C29) -> 44 | T14: =SUM(D26:D29) -> 15 | U14: =SUM(E26:E29) -> 15 | V14: =SUM(F26:F29) -> 104 | W14: =SUM(G26:G29) -> 2 | X14: =SUM(H26:H29) -> 3 | Y14: =SUM(I26:I29) -> 10 | Z14: =SUM(J26:J29) -> 31 | ... AF14: =SUM(P26:P29) -> 351
B15: 08.15 - 08.30 | C15: 10 | D15: 0 | E15: 2 | F15: 22 | G15: 1 | H15: 4 | I15: 2 | J15: 1 | K15: 0 | L15: 11 | M15: 19 | N15: 0 | O15: =SUM(C15:L15,N15) -> 53 | P15: =SUM(C15:N15) -> 72 | R15: 1200-1300 | S15: =SUM(C30:C33) -> 54 | T15: =SUM(D30:D33) -> 15 | U15: =SUM(E30:E33) -> 9 | V15: =SUM(F30:F33) -> 117 | W15: =SUM(G30:G33) -> 1 | X15: =SUM(H30:H33) -> 1 | Y15: =SUM(I30:I33) -> 12 | Z15: =SUM(J30:J33) -> 28 | ... AF15: =SUM(P30:P33) -> 369
B16: 08.30 - 08.45 | C16: 16 | D16: 2 | E16: 1 | F16: 29 | G16: 6 | H16: 3 | I16: 2 | J16: 4 | K16: 2 | L16: 15 | M16: 19 | N16: 0 | O16: =SUM(C16:L16,N16) -> 80 | P16: =SUM(C16:N16) -> 99 | R16: 1300-1400 | S16: =SUM(C34:C37) -> 46 | T16: =SUM(D34:D37) -> 30 | U16: =SUM(E34:E37) -> 18 | V16: =SUM(F34:F37) -> 100 | W16: =SUM(G34:G37) -> 3 | X16: =SUM(H34:H37) -> 1 | Y16: =SUM(I34:I37) -> 9 | Z16: =SUM(J34:J37) -> 22 | ... AF16: =SUM(P34:P37) -> 386
B17: 08.45 - 9.00 | C17: 6 | D17: 3 | E17: 3 | F17: 26 | G17: 1 | H17: 1 | I17: 3 | J17: 2 | K17: 1 | L17: 14 | M17: 22 | N17: 0 | O17: =SUM(C17:L17,N17) -> 60 | P17: =SUM(C17:N17) -> 82 | R17: 1400-1500 | S17: =SUM(C38:C41) -> 72 | T17: =SUM(D38:D41) -> 28 | U17: =SUM(E38:E41) -> 14 | V17: =SUM(F38:F41) -> 120 | W17: =SUM(G38:G41) -> 4 | X17: =SUM(H38:H41) -> 2 | Y17: =SUM(I38:I41) -> 12 | Z17: =SUM(J38:J41) -> 26 | ... AF17: =SUM(P38:P41) -> 408
B18: 09.00 - 09.15 | C18: 18 | D18: 7 | E18: 8 | F18: 28 | G18: 1 | H18: 1 | I18: 2 | J18: 6 | K18: 1 | L18: 8 | M18: 17 | N18: 0 | O18: =SUM(C18:L18,N18) -> 80 | P18: =SUM(C18:N18) -> 97 | R18: 1500-1600 | S18: =SUM(C42:C45) -> 81 | T18: =SUM(D42:D45) -> 20 | U18: =SUM(E42:E45) -> 15 | V18: =SUM(F42:F45) -> 104 | W18: =SUM(G42:G45) -> 5 | X18: =SUM(H42:H45) -> 2 | Y18: =SUM(I42:I45) -> 13 | Z18: =SUM(J42:J45) -> 40 | ... AF18: =SUM(P42:P45) -> 430
B19: 09.15 - 09.30 | C19: 11 | D19: 9 | E19: 3 | F19: 35 | G19: 1 | H19: 3 | I19: 2 | J19: 4 | K19: 2 | L19: 12 | M19: 15 | N19: 0 | O19: =SUM(C19:L19,N19) -> 82 | P19: =SUM(C19:N19) -> 97 | R19: 1600-1700 | S19: =SUM(C46:C49) -> 107 | T19: =SUM(D46:D49) -> 23 | U19: =SUM(E46:E49) -> 36 | V19: =SUM(F46:F49) -> 121 | W19: =SUM(G46:G49) -> 3 | X19: =SUM(H46:H49) -> 2 | Y19: =SUM(I46:I49) -> 12 | Z19: =SUM(J46:J49) -> 41 | ... AF19: =SUM(P46:P49) -> 508
B20: 09.30 - 09.45 | C20: 7 | D20: 2 | E20: 4 | F20: 23 | G20: 3 | H20: 1 | I20: 1 | J20: 2 | K20: 0 | L20: 10 | M20: 18 | N20: 0 | O20: =SUM(C20:L20,N20) -> 53 | P20: =SUM(C20:N20) -> 71 | R20: 1700-1800 | S20: =SUM(C50:C53) -> 92 | T20: =SUM(D50:D53) -> 20 | U20: =SUM(E50:E53) -> 29 | V20: =SUM(F50:F53) -> 128 | W20: =SUM(G50:G53) -> 3 | X20: =SUM(H50:H53) -> 6 | Y20: =SUM(I50:I53) -> 17 | Z20: =SUM(J50:J53) -> 26 | ... AF20: =SUM(P50:P53) -> 492
B21: 09.45 - 10.00 | C21: 10 | D21: 5 | E21: 7 | F21: 35 | G21: 2 | H21: 1 | I21: 0 | J21: 4 | K21: 2 | L21: 12 | M21: 22 | N21: 0 | O21: =SUM(C21:L21,N21) -> 78 | P21: =SUM(C21:N21) -> 100 | R21: 1800-1900 | S21: =SUM(C54:C57) -> 77 | T21: =SUM(D54:D57) -> 26 | U21: =SUM(E54:E57) -> 22 | V21: =SUM(F54:F57) -> 110 | W21: =SUM(G54:G57) -> 10 | X21: =SUM(H54:H57) -> 2 | Y21: =SUM(I54:I57) -> 2 | Z21: =SUM(J54:J57) -> 31 | ... AF21: =SUM(P54:P57) -> 449
B22: 10.00 - 10.15 | C22: 16 | D22: 3 | E22: 4 | F22: 24 | G22: 0 | H22: 4 | I22: 3 | J22: 5 | K22: 0 | L22: 15 | M22: 16 | N22: 0 | O22: =SUM(C22:L22,N22) -> 74 | P22: =SUM(C22:N22) -> 90 | R22: AM Peak Hr | S22: =MAX(S10:S12) -> 46 | T22: =MAX(T10:T12) -> 23 | U22: =MAX(U10:U12) -> 22 | V22: =MAX(V10:V12) -> 121 | W22: =MAX(W10:W12) -> 15 | X22: =MAX(X10:X12) -> 8 | Y22: =MAX(Y10:Y12) -> 10 | Z22: =MAX(Z10:Z12) -> 16 | ... AF22: =MAX(AF10:AF12) -> 365
B23: 10.15 - 10.30 | C23: 15 | D23: 7 | E23: 1 | F23: 27 | G23: 1 | H23: 0 | I23: 2 | J23: 5 | K23: 3 | L23: 11 | M23: 35 | N23: 0 | O23: =SUM(C23:L23,N23) -> 72 | P23: =SUM(C23:N23) -> 107 | R23: IP Peak Hr | S23: =MAX(S13:S18) -> 81 | T23: =MAX(T13:T18) -> 30 | U23: =MAX(U13:U18) -> 18 | V23: =MAX(V13:V18) -> 120 | W23: =MAX(W13:W18) -> 5 | X23: =MAX(X13:X18) -> 5 | Y23: =MAX(Y13:Y18) -> 15 | Z23: =MAX(Z13:Z18) -> 40 | ... AF23: =MAX(AF13:AF18) -> 430
B24: 10.30 - 10.45 | C24: 14 | D24: 4 | E24: 2 | F24: 28 | G24: 0 | H24: 0 | I24: 4 | J24: 9 | K24: 0 | L24: 11 | M24: 23 | N24: 0 | O24: =SUM(C24:L24,N24) -> 72 | P24: =SUM(C24:N24) -> 95 | R24: PM Peak Hr | S24: =MAX(S19:S21) -> 107 | T24: =MAX(T19:T21) -> 26 | U24: =MAX(U19:U21) -> 36 | V24: =MAX(V19:V21) -> 128 | W24: =MAX(W19:W21) -> 10 | X24: =MAX(X19:X21) -> 6 | Y24: =MAX(Y19:Y21) -> 17 | Z24: =MAX(Z19:Z21) -> 41 | ... AF24: =MAX(AF19:AF21) -> 508
B25: 10.45 - 11.00 | C25: 11 | D25: 12 | E25: 2 | F25: 25 | G25: 0 | H25: 1 | I25: 6 | J25: 5 | K25: 0 | L25: 12 | M25: 33 | N25: 0 | O25: =SUM(C25:L25,N25) -> 74 | P25: =SUM(C25:N25) -> 107 | R25: AM Period | S25: =SUM(S10:S12) -> 116 | T25: =SUM(T10:T12) -> 38 | U25: =SUM(U10:U12) -> 35 | V25: =SUM(V10:V12) -> 338 | W25: =SUM(W10:W12) -> 31 | X25: =SUM(X10:X12) -> 17 | Y25: =SUM(Y10:Y12) -> 22 | Z25: =SUM(Z10:Z12) -> 34 | ... AF25: =SUM(AF10:AF12) -> 988
B26: 11.00 - 11.15 | C26: 12 | D26: 5 | E26: 2 | F26: 23 | G26: 2 | H26: 0 | I26: 1 | J26: 7 | K26: 1 | L26: 10 | M26: 30 | N26: 0 | O26: =SUM(C26:L26,N26) -> 63 | P26: =SUM(C26:N26) -> 93 | R26: IP Period | S26: =SUM(S13:S18) -> 353 | T26: =SUM(T13:T18) -> 134 | U26: =SUM(U13:U18) -> 80 | V26: =SUM(V13:V18) -> 649 | W26: =SUM(W13:W18) -> 16 | X26: =SUM(X13:X18) -> 14 | Y26: =SUM(Y13:Y18) -> 71 | Z26: =SUM(Z13:Z18) -> 171 | ... AF26: =SUM(AF13:AF18) -> 2343
B27: 11.15 - 11.30 | C27: 7 | D27: 2 | E27: 5 | F27: 24 | G27: 0 | H27: 2 | I27: 3 | J27: 9 | K27: 0 | L27: 10 | M27: 15 | N27: 0 | O27: =SUM(C27:L27,N27) -> 62 | P27: =SUM(C27:N27) -> 77 | R27: PM Period | S27: =SUM(S19:S21) -> 276 | T27: =SUM(T19:T21) -> 69 | U27: =SUM(U19:U21) -> 87 | V27: =SUM(V19:V21) -> 359 | W27: =SUM(W19:W21) -> 16 | X27: =SUM(X19:X21) -> 10 | Y27: =SUM(Y19:Y21) -> 31 | Z27: =SUM(Z19:Z21) -> 98 | ... AF27: =SUM(AF19:AF21) -> 1449
B28: 11.30 - 11.45 | C28: 10 | D28: 6 | E28: 4 | F28: 28 | G28: 0 | H28: 1 | I28: 5 | J28: 4 | K28: 1 | L28: 11 | M28: 23 | N28: 0 | O28: =SUM(C28:L28,N28) -> 70 | P28: =SUM(C28:N28) -> 93 | R28: 12 Hours | S28: =SUM(S10:S21) -> 745 | T28: =SUM(T10:T21) -> 241 | U28: =SUM(U10:U21) -> 202 | V28: =SUM(V10:V21) -> 1346 | W28: =SUM(W10:W21) -> 63 | X28: =SUM(X10:X21) -> 41 | Y28: =SUM(Y10:Y21) -> 124 | Z28: =SUM(Z10:Z21) -> 303 | ... AF28: =SUM(AF10:AF21) -> 4780
B29: 11.45 - 12.00 | C29: 15 | D29: 2 | E29: 4 | F29: 29 | G29: 0 | H29: 0 | I29: 1 | J29: 11 | K29: 1 | L29: 6 | M29: 19 | N29: 0 | O29: =SUM(C29:L29,N29) -> 69 | P29: =SUM(C29:N29) -> 88
B30: 12.00 - 12.15 | C30: 18 | D30: 2 | E30: 2 | F30: 29 | G30: 0 | H30: 0 | I30: 2 | J30: 7 | K30: 4 | L30: 15 | M30: 16 | N30: 0 | O30: =SUM(C30:L30,N30) -> 79 | P30: =SUM(C30:N30) -> 95
B31: 12.15 - 12.30 | C31: 12 | D31: 2 | E31: 2 | F31: 34 | G31: 1 | H31: 0 | I31: 4 | J31: 6 | K31: 0 | L31: 7 | M31: 24 | N31: 0 | O31: =SUM(C31:L31,N31) -> 68 | P31: =SUM(C31:N31) -> 92
B32: 12.30 - 12.45 | C32: 12 | D32: 7 | E32: 5 | F32: 30 | G32: 0 | H32: 0 | I32: 3 | J32: 7 | K32: 0 | L32: 10 | M32: 21 | N32: 0 | O32: =SUM(C32:L32,N32) -> 74 | P32: =SUM(C32:N32) -> 95
B33: 12.45 - 13.00 | C33: 12 | D33: 4 | E33: 0 | F33: 24 | G33: 0 | H33: 1 | I33: 3 | J33: 8 | K33: 2 | L33: 15 | M33: 18 | N33: 0 | O33: =SUM(C33:L33,N33) -> 69 | P33: =SUM(C33:N33) -> 87
B34: 13.00 - 13.15 | C34: 9 | D34: 6 | E34: 5 | F34: 22 | G34: 0 | H34: 0 | I34: 1 | J34: 1 | K34: 3 | L34: 12 | M34: 26 | N34: 0 | O34: =SUM(C34:L34,N34) -> 59 | P34: =SUM(C34:N34) -> 85
B35: 13.15 - 13.30 | C35: 11 | D35: 12 | E35: 2 | F35: 36 | G35: 1 | H35: 0 | I35: 5 | J35: 12 | K35: 5 | L35: 15 | M35: 35 | N35: 0 | O35: =SUM(C35:L35,N35) -> 99 | P35: =SUM(C35:N35) -> 134
B36: 13.30 - 13.45 | C36: 14 | D36: 8 | E36: 9 | F36: 23 | G36: 1 | H36: 1 | I36: 1 | J36: 4 | K36: 2 | L36: 5 | M36: 16 | N36: 0 | O36: =SUM(C36:L36,N36) -> 68 | P36: =SUM(C36:N36) -> 84
B37: 13.45 - 14.00 | C37: 12 | D37: 4 | E37: 2 | F37: 19 | G37: 1 | H37: 0 | I37: 2 | J37: 5 | K37: 0 | L37: 16 | M37: 22 | N37: 0 | O37: =SUM(C37:L37,N37) -> 61 | P37: =SUM(C37:N37) -> 83
B38: 14.00 - 14.15 | C38: 18 | D38: 9 | E38: 4 | F38: 23 | G38: 0 | H38: 1 | I38: 4 | J38: 2 | K38: 1 | L38: 12 | M38: 17 | N38: 0 | O38: =SUM(C38:L38,N38) -> 74 | P38: =SUM(C38:N38) -> 91
B39: 14.15 - 14.30 | C39: 21 | D39: 8 | E39: 2 | F39: 25 | G39: 2 | H39: 0 | I39: 5 | J39: 7 | K39: 2 | L39: 13 | M39: 20 | N39: 0 | O39: =SUM(C39:L39,N39) -> 85 | P39: =SUM(C39:N39) -> 105
B40: 14.30 - 14.45 | C40: 23 | D40: 7 | E40: 5 | F40: 33 | G40: 0 | H40: 1 | I40: 3 | J40: 10 | K40: 5 | L40: 12 | M40: 25 | N40: 0 | O40: =SUM(C40:L40,N40) -> 99 | P40: =SUM(C40:N40) -> 124
... B57: 18.45 - 19.00 | C57: 21 | D57: 9 | E57: 2 | F57: 23 | G57: 1 | H57: 0 | I57: 2 | J57: 5 | K57: 8 | L57: 22 | M57: 27 | N57: 0 | O57: =SUM(C57:L57,N57) -> 93 | P57: =SUM(C57:N57) -> 120
B58: Totals | C58: =SUM(C10:C57) -> 745 | D58: =SUM(D10:D57) -> 241 | E58: =SUM(E10:E57) -> 202 | F58: =SUM(F10:F57) -> 1346 | G58: =SUM(G10:G57) -> 63 | H58: =SUM(H10:H57) -> 41 | I58: =SUM(I10:I57) -> 124 | J58: =SUM(J10:J57) -> 303 | ... P58: =SUM(P10:P57) -> 4780
...

Sheet 18.10 Kampala-Jinja
B1: Consultancy services for Preparation of Expressway Development Master Plan (EDMP) for Uganda
B2: MANUAL CLASSIFIED COUNT (MCC)
B3: ROAD NAME: | C3: ='17.10 Kampala-Jinja'!C3:G3 -> MCC - C 4- STN19 -Kampala-Jinja highway
C5: Date | D5: ='18.10 Jinja-Kampala'!D5 -> 18.10.19 | F5: Location | G5: ='17.10 jinja-kampala'!G5:H5 -> Nakibbizi | J5: Surveyor | K5: Jerome
C6: Dir. From | D6: ='17.10 Kampala-Jinja'!D6:E6 -> Kampala | F6: Dir. To | G6: ='17.10 Kampala-Jinja'!G6:H6 -> Jinja | J6: Supervisor | K6: ='17.10 jinja-kampala'!K6:L6 -> Emma
B8: Time / Veh Type | R8: SUMMARY TRAFFIC VOLUMES
C9: 1. Car | D9: 2. Station Wagon | E9: 3. Pickups | F9: 4. Minibus, matatu | G9: 5. Medium bus | H9: 6. Large Bus | I9: 7. Light Truck | J9: 8. Medium Truck | K9: 9. Heavy truck | L9: 10. Truck Trailer | M9: 11. Motor cycles | N9: 12. Tractors | O9: Total Excl M/Cycles | P9: Total All | R9: Time | S9: 1. Car | T9: 2. Station Wagon | U9: 3. Pickups | V9: 4. Minibus, matatu | W9: 5. Medium bus | X9: 6. Large Bus | Y9: 7. Light Truck | Z9: 8. Medium Truck | AA9: 9. Heavy truck | AB9: 10. Truck Trailer | AC9: 11. Motorcycles | AD9: 12. Tractors, Graders | AE9: Total Excl M/ Cycles | AF9: Total All
B10: 07.00 - 07.15 | C10: 5 | D10: 0 | E10: 2 | F10: 30 | G10: 1 | H10: 0 | I10: 4 | J10: 3 | K10: 1 | L10: 19 | M10: 12 | N10: 0 | O10: =SUM(C10:L10,N10) -> 65 | P10: =SUM(C10:N10) -> 77 | R10: 0700-0800 | S10: =SUM(C10:C13) -> 34 | T10: =SUM(D10:D13) -> 19 | U10: =SUM(E10:E13) -> 16 | V10: =SUM(F10:F13) -> 111 | W10: =SUM(G10:G13) -> 2 | X10: =SUM(H10:H13) -> 1 | Y10: =SUM(I10:I13) -> 11 | Z10: =SUM(J10:J13) -> 18 | ... AF10: =SUM(P10:P13) -> 348
B11: 07.15 - 07.30 | C11: 12 | D11: 7 | E11: 2 | F11: 22 | G11: 0 | H11: 0 | I11: 1 | J11: 6 | K11: 3 | L11: 7 | M11: 20 | N11: 0 | O11: =SUM(C11:L11,N11) -> 60 | P11: =SUM(C11:N11) -> 80 | R11: 0800-0900 | S11: =SUM(C14:C17) -> 45 | T11: =SUM(D14:D17) -> 18 | U11: =SUM(E14:E17) -> 16 | V11: =SUM(F14:F17) -> 117 | W11: =SUM(G14:G17) -> 1 | X11: =SUM(H14:H17) -> 2 | Y11: =SUM(I14:I17) -> 8 | Z11: =SUM(J14:J17) -> 17 | ... AF11: =SUM(P14:P17) -> 321
B12: 07.30 - 07.45 | C12: 4 | D12: 3 | E12: 3 | F12: 31 | G12: 1 | H12: 0 | I12: 4 | J12: 6 | K12: 2 | L12: 16 | M12: 26 | N12: 0 | O12: =SUM(C12:L12,N12) -> 70 | P12: =SUM(C12:N12) -> 96 | R12: 0900-1000 | S12: =SUM(C18:C21) -> 56 | T12: =SUM(D18:D21) -> 34 | U12: =SUM(E18:E21) -> 18 | V12: =SUM(F18:F21) -> 109 | W12: =SUM(G18:G21) -> 4 | X12: =SUM(H18:H21) -> 0 | Y12: =SUM(I18:I21) -> 9 | Z12: =SUM(J18:J21) -> 14 | ... AF12: =SUM(P18:P21) -> 336
B13: 07.45 - 08.00 | C13: 13 | D13: 9 | E13: 9 | F13: 28 | G13: 0 | H13: 1 | I13: 2 | J13: 3 | K13: 1 | L13: 4 | M13: 25 | N13: 0 | O13: =SUM(C13:L13,N13) -> 70 | P13: =SUM(C13:N13) -> 95 | R13: 1000-1100 | S13: =SUM(C22:C25) -> 51 | T13: =SUM(D22:D25) -> 23 | U13: =SUM(E22:E25) -> 16 | V13: =SUM(F22:F25) -> 129 | W13: =SUM(G22:G25) -> 4 | X13: =SUM(H22:H25) -> 2 | Y13: =SUM(I22:I25) -> 2 | Z13: =SUM(J22:J25) -> 21 | ... AF13: =SUM(P22:P25) -> 343
B14: 08.00 - 08.15 | C14: 12 | D14: 9 | E14: 3 | F14: 34 | G14: 1 | H14: 0 | I14: 2 | J14: 3 | K14: 0 | L14: 7 | M14: 13 | N14: 0 | O14: =SUM(C14:L14,N14) -> 71 | P14: =SUM(C14:N14) -> 84 | R14: 1100-1200 | S14: =SUM(C26:C29) -> 53 | T14: =SUM(D26:D29) -> 29 | U14: =SUM(E26:E29) -> 22 | V14: =SUM(F26:F29) -> 103 | W14: =SUM(G26:G29) -> 2 | X14: =SUM(H26:H29) -> 3 | Y14: =SUM(I26:I29) -> 6 | Z14: =SUM(J26:J29) -> 28 | ... AF14: =SUM(P26:P29) -> 366
B15: 08.15 - 08.30 | C15: 14 | D15: 6 | E15: 7 | F15: 32 | G15: 0 | H15: 0 | I15: 4 | J15: 4 | K15: 0 | L15: 7 | M15: 13 | N15: 0 | O15: =SUM(C15:L15,N15) -> 74 | P15: =SUM(C15:N15) -> 87 | R15: 1200-1300 | S15: =SUM(C30:C33) -> 41 | T15: =SUM(D30:D33) -> 21 | U15: =SUM(E30:E33) -> 15 | V15: =SUM(F30:F33) -> 121 | W15: =SUM(G30:G33) -> 7 | X15: =SUM(H30:H33) -> 3 | Y15: =SUM(I30:I33) -> 7 | Z15: =SUM(J30:J33) -> 24 | ... AF15: =SUM(P30:P33) -> 370
B16: 08.30 - 08.45 | C16: 10 | D16: 2 | E16: 2 | F16: 21 | G16: 0 | H16: 1 | I16: 1 | J16: 4 | K16: 2 | L16: 2 | M16: 23 | N16: 0 | O16: =SUM(C16:L16,N16) -> 45 | P16: =SUM(C16:N16) -> 68 | R16: 1300-1400 | S16: =SUM(C34:C37) -> 60 | T16: =SUM(D34:D37) -> 29 | U16: =SUM(E34:E37) -> 13 | V16: =SUM(F34:F37) -> 120 | W16: =SUM(G34:G37) -> 8 | X16: =SUM(H34:H37) -> 1 | Y16: =SUM(I34:I37) -> 22 | Z16: =SUM(J34:J37) -> 31 | ... AF16: =SUM(P34:P37) -> 435
B17: 08.45 - 9.00 | C17: 9 | D17: 1 | E17: 4 | F17: 30 | G17: 0 | H17: 1 | I17: 1 | J17: 6 | K17: 3 | L17: 5 | M17: 22 | N17: 0 | O17: =SUM(C17:L17,N17) -> 60 | P17: =SUM(C17:N17) -> 82 | R17: 1400-1500 | S17: =SUM(C38:C41) -> 46 | T17: =SUM(D38:D41) -> 17 | U17: =SUM(E38:E41) -> 19 | V17: =SUM(F38:F41) -> 135 | W17: =SUM(G38:G41) -> 8 | X17: =SUM(H38:H41) -> 4 | Y17: =SUM(I38:I41) -> 17 | Z17: =SUM(J38:J41) -> 27 | ... AF17: =SUM(P38:P41) -> 424
B18: 09.00 - 09.15 | C18: 12 | D18: 9 | E18: 5 | F18: 24 | G18: 3 | H18: 0 | I18: 1 | J18: 2 | K18: 1 | L18: 5 | M18: 17 | N18: 0 | O18: =SUM(C18:L18,N18) -> 62 | P18: =SUM(C18:N18) -> 79 | R18: 1500-1600 | S18: =SUM(C42:C45) -> 46 | T18: =SUM(D42:D45) -> 31 | U18: =SUM(E42:E45) -> 18 | V18: =SUM(F42:F45) -> 124 | W18: =SUM(G42:G45) -> 6 | X18: =SUM(H42:H45) -> 3 | Y18: =SUM(I42:I45) -> 22 | Z18: =SUM(J42:J45) -> 26 | ... AF18: =SUM(P42:P45) -> 403
B19: 09.15 - 09.30 | C19: 15 | D19: 8 | E19: 9 | F19: 28 | G19: 0 | H19: 0 | I19: 2 | J19: 3 | K19: 1 | L19: 4 | M19: 17 | N19: 0 | O19: =SUM(C19:L19,N19) -> 70 | P19: =SUM(C19:N19) -> 87 | R19: 1600-1700 | S19: =SUM(C46:C49) -> 62 | T19: =SUM(D46:D49) -> 28 | U19: =SUM(E46:E49) -> 25 | V19: =SUM(F46:F49) -> 106 | W19: =SUM(G46:G49) -> 5 | X19: =SUM(H46:H49) -> 1 | Y19: =SUM(I46:I49) -> 16 | Z19: =SUM(J46:J49) -> 33 | ... AF19: =SUM(P46:P49) -> 414
B20: 09.30 - 09.45 | C20: 8 | D20: 5 | E20: 3 | F20: 21 | G20: 0 | H20: 0 | I20: 2 | J20: 5 | K20: 0 | L20: 3 | M20: 22 | N20: 0 | O20: =SUM(C20:L20,N20) -> 47 | P20: =SUM(C20:N20) -> 69 | R20: 1700-1800 | S20: =SUM(C50:C53) -> 86 | T20: =SUM(D50:D53) -> 42 | U20: =SUM(E50:E53) -> 21 | V20: =SUM(F50:F53) -> 152 | W20: =SUM(G50:G53) -> 7 | X20: =SUM(H50:H53) -> 2 | Y20: =SUM(I50:I53) -> 22 | Z20: =SUM(J50:J53) -> 30 | ... AF20: =SUM(P50:P53) -> 562
B21: 09.45 - 10.00 | C21: 21 | D21: 12 | E21: 1 | F21: 36 | G21: 1 | H21: 0 | I21: 4 | J21: 4 | K21: 2 | L21: 5 | M21: 15 | N21: 0 | O21: =SUM(C21:L21,N21) -> 86 | P21: =SUM(C21:N21) -> 101 | R21: 1800-1900 | S21: =SUM(C54:C57) -> 68 | T21: =SUM(D54:D57) -> 24 | U21: =SUM(E54:E57) -> 20 | V21: =SUM(F54:F57) -> 109 | W21: =SUM(G54:G57) -> 4 | X21: =SUM(H54:H57) -> 5 | Y21: =SUM(I54:I57) -> 16 | Z21: =SUM(J54:J57) -> 23 | ... AF21: =SUM(P54:P57) -> 455
B22: 10.00 - 10.15 | C22: 12 | D22: 7 | E22: 4 | F22: 29 | G22: 2 | H22: 1 | I22: 1 | J22: 3 | K22: 0 | L22: 3 | M22: 25 | N22: 0 | O22: =SUM(C22:L22,N22) -> 62 | P22: =SUM(C22:N22) -> 87 | R22: AM Peak Hr | S22: =MAX(S10:S12) -> 56 | T22: =MAX(T10:T12) -> 34 | U22: =MAX(U10:U12) -> 18 | V22: =MAX(V10:V12) -> 117 | W22: =MAX(W10:W12) -> 4 | X22: =MAX(X10:X12) -> 2 | Y22: =MAX(Y10:Y12) -> 11 | Z22: =MAX(Z10:Z12) -> 18 | ... AF22: =MAX(AF10:AF12) -> 348
B23: 10.15 - 10.30 | C23: 14 | D23: 3 | E23: 1 | F23: 31 | G23: 1 | H23: 0 | I23: 0 | J23: 5 | K23: 0 | L23: 2 | M23: 21 | N23: 0 | O23: =SUM(C23:L23,N23) -> 57 | P23: =SUM(C23:N23) -> 78 | R23: IP Peak Hr | S23: =MAX(S13:S18) -> 60 | T23: =MAX(T13:T18) -> 31 | U23: =MAX(U13:U18) -> 22 | V23: =MAX(V13:V18) -> 135 | W23: =MAX(W13:W18) -> 8 | X23: =MAX(X13:X18) -> 4 | Y23: =MAX(Y13:Y18) -> 22 | Z23: =MAX(Z13:Z18) -> 31 | ... AF23: =MAX(AF13:AF18) -> 435
B24: 10.30 - 10.45 | C24: 14 | D24: 7 | E24: 7 | F24: 35 | G24: 0 | H24: 1 | I24: 0 | J24: 9 | K24: 0 | L24: 2 | M24: 26 | N24: 0 | O24: =SUM(C24:L24,N24) -> 75 | P24: =SUM(C24:N24) -> 101 | R24: PM Peak Hr | S24: =MAX(S19:S21) -> 86 | T24: =MAX(T19:T21) -> 42 | U24: =MAX(U19:U21) -> 25 | V24: =MAX(V19:V21) -> 152 | W24: =MAX(W19:W21) -> 7 | X24: =MAX(X19:X21) -> 5 | Y24: =MAX(Y19:Y21) -> 22 | Z24: =MAX(Z19:Z21) -> 33 | ... AF24: =MAX(AF19:AF21) -> 562
B25: 10.45 - 11.00 | C25: 11 | D25: 6 | E25: 4 | F25: 34 | G25: 1 | H25: 0 | I25: 1 | J25: 4 | K25: 0 | L25: 4 | M25: 12 | N25: 0 | O25: =SUM(C25:L25,N25) -> 65 | P25: =SUM(C25:N25) -> 77 | R25: AM Period | S25: =SUM(S10:S12) -> 135 | T25: =SUM(T10:T12) -> 71 | U25: =SUM(U10:U12) -> 50 | V25: =SUM(V10:V12) -> 337 | W25: =SUM(W10:W12) -> 7 | X25: =SUM(X10:X12) -> 3 | Y25: =SUM(Y10:Y12) -> 28 | Z25: =SUM(Z10:Z12) -> 49 | ... AF25: =SUM(AF10:AF12) -> 1005
B26: 11.00 - 11.15 | C26: 13 | D26: 6 | E26: 6 | F26: 31 | G26: 0 | H26: 1 | I26: 2 | J26: 4 | K26: 0 | L26: 3 | M26: 24 | N26: 0 | O26: =SUM(C26:L26,N26) -> 66 | P26: =SUM(C26:N26) -> 90 | R26: IP Period | S26: =SUM(S13:S18) -> 297 | T26: =SUM(T13:T18) -> 150 | U26: =SUM(U13:U18) -> 103 | V26: =SUM(V13:V18) -> 732 | W26: =SUM(W13:W18) -> 35 | X26: =SUM(X13:X18) -> 16 | Y26: =SUM(Y13:Y18) -> 76 | Z26: =SUM(Z13:Z18) -> 157 | ... AF26: =SUM(AF13:AF18) -> 2341
B27: 11.15 - 11.30 | C27: 14 | D27: 10 | E27: 5 | F27: 29 | G27: 1 | H27: 2 | I27: 0 | J27: 7 | K27: 1 | L27: 5 | M27: 32 | N27: 0 | O27: =SUM(C27:L27,N27) -> 74 | P27: =SUM(C27:N27) -> 106 | R27: PM Period | S27: =SUM(S19:S21) -> 216 | T27: =SUM(T19:T21) -> 94 | U27: =SUM(U19:U21) -> 66 | V27: =SUM(V19:V21) -> 367 | W27: =SUM(W19:W21) -> 16 | X27: =SUM(X19:X21) -> 8 | Y27: =SUM(Y19:Y21) -> 54 | Z27: =SUM(Z19:Z21) -> 86 | ... AF27: =SUM(AF19:AF21) -> 1431
B28: 11.30 - 11.45 | C28: 8 | D28: 8 | E28: 6 | F28: 23 | G28: 0 | H28: 0 | I28: 3 | J28: 8 | K28: 0 | L28: 8 | M28: 20 | N28: 0 | O28: =SUM(C28:L28,N28) -> 64 | P28: =SUM(C28:N28) -> 84 | R28: 12 Hours | S28: =SUM(S10:S21) -> 648 | T28: =SUM(T10:T21) -> 315 | U28: =SUM(U10:U21) -> 219 | V28: =SUM(V10:V21) -> 1436 | W28: =SUM(W10:W21) -> 58 | X28: =SUM(X10:X21) -> 27 | Y28: =SUM(Y10:Y21) -> 158 | Z28: =SUM(Z10:Z21) -> 292 | ... AF28: =SUM(AF10:AF21) -> 4777
B29: 11.45 - 12.00 | C29: 18 | D29: 5 | E29: 5 | F29: 20 | G29: 1 | H29: 0 | I29: 1 | J29: 9 | K29: 1 | L29: 8 | M29: 18 | N29: 0 | O29: =SUM(C29:L29,N29) -> 68 | P29: =SUM(C29:N29) -> 86
B30: 12.00 - 12.15 | C30: 14 | D30: 7 | E30: 5 | F30: 41 | G30: 1 | H30: 0 | I30: 3 | J30: 9 | K30: 2 | L30: 1 | M30: 20 | N30: 0 | O30: =SUM(C30:L30,N30) -> 83 | P30: =SUM(C30:N30) -> 103
B31: 12.15 - 12.30 | C31: 9 | D31: 2 | E31: 3 | F31: 23 | G31: 2 | H31: 3 | I31: 1 | J31: 7 | K31: 1 | L31: 8 | M31: 24 | N31: 0 | O31: =SUM(C31:L31,N31) -> 59 | P31: =SUM(C31:N31) -> 83
B32: 12.30 - 12.45 | C32: 11 | D32: 8 | E32: 5 | F32: 20 | G32: 0 | H32: 0 | I32: 3 | J32: 4 | K32: 1 | L32: 14 | M32: 19 | N32: 0 | O32: =SUM(C32:L32,N32) -> 66 | P32: =SUM(C32:N32) -> 85
B33: 12.45 - 13.00 | C33: 7 | D33: 4 | E33: 2 | F33: 37 | G33: 4 | H33: 0 | I33: 0 | J33: 4 | K33: 3 | L33: 12 | M33: 26 | N33: 0 | O33: =SUM(C33:L33,N33) -> 73 | P33: =SUM(C33:N33) -> 99
B34: 13.00 - 13.15 | C34: 14 | D34: 3 | E34: 4 | F34: 30 | G34: 2 | H34: 0 | I34: 9 | J34: 8 | K34: 1 | L34: 10 | M34: 24 | N34: 0 | O34: =SUM(C34:L34,N34) -> 81 | P34: =SUM(C34:N34) -> 105
B35: 13.15 - 13.30 | C35: 12 | D35: 9 | E35: 3 | F35: 31 | G35: 4 | H35: 0 | I35: 3 | J35: 13 | K35: 0 | L35: 13 | M35: 20 | N35: 0 | O35: =SUM(C35:L35,N35) -> 88 | P35: =SUM(C35:N35) -> 108
B36: 13.30 - 13.45 | C36: 21 | D36: 8 | E36: 4 | F36: 37 | G36: 0 | H36: 0 | I36: 8 | J36: 4 | K36: 1 | L36: 15 | M36: 33 | N36: 0 | O36: =SUM(C36:L36,N36) -> 98 | P36: =SUM(C36:N36) -> 131
B37: 13.45 - 14.00 | C37: 13 | D37: 9 | E37: 2 | F37: 22 | G37: 2 | H37: 1 | I37: 2 | J37: 6 | K37: 0 | L37: 17 | M37: 17 | N37: 0 | O37: =SUM(C37:L37,N37) -> 74 | P37: =SUM(C37:N37) -> 91
B38: 14.00 - 14.15 | C38: 9 | D38: 8 | E38: 5 | F38: 32 | G38: 4 | H38: 2 | I38: 3 | J38: 3 | K38: 9 | L38: 10 | M38: 14 | N38: 0 | O38: =SUM(C38:L38,N38) -> 85 | P38: =SUM(C38:N38) -> 99
B39: 14.15 - 14.30 | C39: 12 | D39: 5 | E39: 5 | F39: 37 | G39: 1 | H39: 0 | I39: 4 | J39: 12 | K39: 2 | L39: 20 | M39: 21 | N39: 0 | O39: =SUM(C39:L39,N39) -> 98 | P39: =SUM(C39:N39) -> 119
B40: 14.30 - 14.45 | C40: 14 | D40: 0 | E40: 6 | F40: 32 | G40: 2 | H40: 1 | I40: 3 | J40: 8 | K40: 1 | L40: 15 | M40: 20 | N40: 0 | O40: =SUM(C40:L40,N40) -> 82 | P40: =SUM(C40:N40) -> 102
... B57: 18.45 - 19.00 | C57: 35 | D57: 2 | E57: 8 | F57: 15 | G57: 1 | H57: 3 | I57: 3 | J57: 5 | K57: 0 | L57: 30 | M57: 40 | N57: 0 | O57: =SUM(C57:L57,N57) -> 102 | P57: =SUM(C57:N57) -> 142
B58: Totals | C58: =SUM(C10:C57) -> 648 | D58: =SUM(D10:D57) -> 315 | E58: =SUM(E10:E57) -> 219 | F58: =SUM(F10:F57) -> 1436 | G58: =SUM(G10:G57) -> 58 | H58: =SUM(H10:H57) -> 27 | I58: =SUM(I10:I57) -> 158 | J58: =SUM(J10:J57) -> 292 | ... P58: =SUM(P10:P57) -> 4777
...

Sheet 19.10 Jinja-Kampala-24hr
B1: Consultancy services for Preparation of Expressway Development Master Plan (EDMP) for Uganda
B2: MANUAL CLASSIFIED COUNT (MCC)
B3: ROAD NAME: | C3: ='17.10 jinja-kampala'!C3:G3 -> MCC - C 4- STN19 -Kampala-Jinja highway
C5: Date | D5: 19.10.19 | F5: Location | G5: ='27.10 KAMPALA-JINJA'!G5:H5 -> Nakibbizi | J5: Surveyor | K5: ='27.10 KAMPALA-JINJA'!K5:L5 -> JEROME
C6: Dir. From | D6: ='17.10 jinja-kampala'!D6:E6 -> Jinja | F6: Dir. To | G6: ='17.10 jinja-kampala'!G6:H6 -> Kampala | J6: Supervisor | K6: ='27.10 KAMPALA-JINJA'!K6:L6 -> Emma
B8: Time / Veh Type | R8: SUMMARY TRAFFIC VOLUMES
C9: 1. Car | D9: 2. Station Wagon | E9: 3. Pickups | F9: 4. Minibus, matatu | G9: 5. Medium bus | H9: 6. Large Bus | I9: 7. Light Truck | J9: 8. Medium Truck | K9: 9. Heavy truck | L9: 10. Truck Trailer | M9: 11. Motor cycles | N9: 12. Tractors | O9: Total Excl M/Cycles | P9: Total All | R9: Time | S9: 1. Car | T9: 2. Station Wagon | U9: 3. Pickups | V9: 4. Minibus, matatu | W9: 5. Medium bus | X9: 6. Large Bus | Y9: 7. Light Truck | Z9: 8. Medium Truck | AA9: 9. Heavy truck | AB9: 10. Truck Trailer | AC9: 11. Motorcycles | AD9: 12. Tractors, Graders | AE9: Total Excl M/ Cycles | AF9: Total All
B10: 07.00 - 07.15 | C10: 9 | D10: 2 | E10: 0 | F10: 32 | G10: 0 | H10: 1 | I10: 2 | J10: 6 | K10: 2 | L10: 20 | M10: 15 | N10: 0 | O10: =SUM(C10:L10,N10) -> 74 | P10: =SUM(C10:N10) -> 89 | R10: 0700-0800 | S10: =SUM(C10:C13) -> 40 | T10: =SUM(D10:D13) -> 11 | U10: =SUM(E10:E13) -> 11 | V10: =SUM(F10:F13) -> 140 | W10: =SUM(G10:G13) -> 2 | X10: =SUM(H10:H13) -> 5 | Y10: =SUM(I10:I13) -> 6 | Z10: =SUM(J10:J13) -> 15 | ... AF10: =SUM(P10:P13) -> 354
B11: 07.15 - 07.30 | C11: 12 | D11: 4 | E11: 4 | F11: 40 | G11: 0 | H11: 3 | I11: 0 | J11: 4 | K11: 1 | L11: 5 | M11: 21 | N11: 0 | O11: =SUM(C11:L11,N11) -> 73 | P11: =SUM(C11:N11) -> 94 | R11: 0800-0900 | S11: =SUM(C14:C17) -> 59 | T11: =SUM(D14:D17) -> 20 | U11: =SUM(E14:E17) -> 11 | V11: =SUM(F14:F17) -> 145 | W11: =SUM(G14:G17) -> 2 | X11: =SUM(H14:H17) -> 5 | Y11: =SUM(I14:I17) -> 11 | Z11: =SUM(J14:J17) -> 19 | ... AF11: =SUM(P14:P17) -> 399
B12: 07.30 - 07.45 | C12: 7 | D12: 0 | E12: 4 | F12: 34 | G12: 1 | H12: 1 | I12: 4 | J12: 2 | K12: 2 | L12: 6 | M12: 14 | N12: 0 | O12: =SUM(C12:L12,N12) -> 61 | P12: =SUM(C12:N12) -> 75 | R12: 0900-1000 | S12: =SUM(C18:C21) -> 66 | T12: =SUM(D18:D21) -> 19 | U12: =SUM(E18:E21) -> 15 | V12: =SUM(F18:F21) -> 125 | W12: =SUM(G18:G21) -> 4 | X12: =SUM(H18:H21) -> 3 | Y12: =SUM(I18:I21) -> 18 | Z12: =SUM(J18:J21) -> 8 | ... AF12: =SUM(P18:P21) -> 397
B13: 07.45 - 08.00 | C13: 12 | D13: 5 | E13: 3 | F13: 34 | G13: 1 | H13: 0 | I13: 0 | J13: 3 | K13: 0 | L13: 17 | M13: 21 | N13: 0 | O13: =SUM(C13:L13,N13) -> 75 | P13: =SUM(C13:N13) -> 96 | R13: 1000-1100 | S13: =SUM(C22:C25) -> 65 | T13: =SUM(D22:D25) -> 23 | U13: =SUM(E22:E25) -> 14 | V13: =SUM(F22:F25) -> 118 | W13: =SUM(G22:G25) -> 5 | X13: =SUM(H22:H25) -> 3 | Y13: =SUM(I22:I25) -> 20 | Z13: =SUM(J22:J25) -> 16 | ... AF13: =SUM(P22:P25) -> 411
B14: 08.00 - 08.15 | C14: 22 | D14: 9 | E14: 5 | F14: 38 | G14: 0 | H14: 0 | I14: 3 | J14: 6 | K14: 3 | L14: 12 | M14: 23 | N14: 0 | O14: =SUM(C14:L14,N14) -> 98 | P14: =SUM(C14:N14) -> 121 | R14: 1100-1200 | S14: =SUM(C26:C29) -> 67 | T14: =SUM(D26:D29) -> 24 | U14: =SUM(E26:E29) -> 19 | V14: =SUM(F26:F29) -> 125 | W14: =SUM(G26:G29) -> 4 | X14: =SUM(H26:H29) -> 2 | Y14: =SUM(I26:I29) -> 9 | Z14: =SUM(J26:J29) -> 12 | ... AF14: =SUM(P26:P29) -> 418
B15: 08.15 - 08.30 | C15: 19 | D15: 6 | E15: 3 | F15: 34 | G15: 1 | H15: 3 | I15: 3 | J15: 5 | K15: 2 | L15: 9 | M15: 17 | N15: 0 | O15: =SUM(C15:L15,N15) -> 85 | P15: =SUM(C15:N15) -> 102 | R15: 1200-1300 | S15: =SUM(C30:C33) -> 97 | T15: =SUM(D30:D33) -> 24 | U15: =SUM(E30:E33) -> 15 | V15: =SUM(F30:F33) -> 116 | W15: =SUM(G30:G33) -> 1 | X15: =SUM(H30:H33) -> 2 | Y15: =SUM(I30:I33) -> 16 | Z15: =SUM(J30:J33) -> 27 | ... AF15: =SUM(P30:P33) -> 415
B16: 08.30 - 08.45 | C16: 5 | D16: 4 | E16: 2 | F16: 30 | G16: 1 | H16: 0 | I16: 2 | J16: 8 | K16: 2 | L16: 10 | M16: 21 | N16: 0 | O16: =SUM(C16:L16,N16) -> 64 | P16: =SUM(C16:N16) -> 85 | R16: 1300-1400 | S16: =SUM(C34:C37) -> 94 | T16: =SUM(D34:D37) -> 23 | U16: =SUM(E34:E37) -> 22 | V16: =SUM(F34:F37) -> 110 | W16: =SUM(G34:G37) -> 1 | X16: =SUM(H34:H37) -> 0 | Y16: =SUM(I34:I37) -> 19 | Z16: =SUM(J34:J37) -> 27 | ... AF16: =SUM(P34:P37) -> 440
B17: 08.45 - 9.00 | C17: 13 | D17: 1 | E17: 1 | F17: 43 | G17: 0 | H17: 2 | I17: 3 | J17: 0 | K17: 0 | L17: 8 | M17: 20 | N17: 0 | O17: =SUM(C17:L17,N17) -> 71 | P17: =SUM(C17:N17) -> 91 | R17: 1400-1500 | S17: =SUM(C38:C41) -> 68 | T17: =SUM(D38:D41) -> 18 | U17: =SUM(E38:E41) -> 7 | V17: =SUM(F38:F41) -> 90 | W17: =SUM(G38:G41) -> 0 | X17: =SUM(H38:H41) -> 3 | Y17: =SUM(I38:I41) -> 15 | Z17: =SUM(J38:J41) -> 13 | ... AF17: =SUM(P38:P41) -> 281
B18: 09.00 - 09.15 | C18: 16 | D18: 6 | E18: 3 | F18: 28 | G18: 3 | H18: 1 | I18: 3 | J18: 4 | K18: 1 | L18: 11 | M18: 31 | N18: 0 | O18: =SUM(C18:L18,N18) -> 76 | P18: =SUM(C18:N18) -> 107 | R18: 1500-1600 | S18: =SUM(C42:C45) -> 94 | T18: =SUM(D42:D45) -> 24 | U18: =SUM(E42:E45) -> 20 | V18: =SUM(F42:F45) -> 125 | W18: =SUM(G42:G45) -> 2 | X18: =SUM(H42:H45) -> 3 | Y18: =SUM(I42:I45) -> 12 | Z18: =SUM(J42:J45) -> 10 | ... AF18: =SUM(P42:P45) -> 428
B19: 09.15 - 09.30 | C19: 19 | D19: 3 | E19: 5 | F19: 27 | G19: 0 | H19: 1 | I19: 5 | J19: 2 | K19: 1 | L19: 7 | M19: 30 | N19: 0 | O19: =SUM(C19:L19,N19) -> 70 | P19: =SUM(C19:N19) -> 100 | R19: 1600-1700 | S19: =SUM(C46:C49) -> 53 | T19: =SUM(D46:D49) -> 30 | U19: =SUM(E46:E49) -> 14 | V19: =SUM(F46:F49) -> 116 | W19: =SUM(G46:G49) -> 6 | X19: =SUM(H46:H49) -> 2 | Y19: =SUM(I46:I49) -> 19 | Z19: =SUM(J46:J49) -> 18 | ... AF19: =SUM(P46:P49) -> 424
B20: 09.30 - 09.45 | C20: 16 | D20: 7 | E20: 6 | F20: 33 | G20: 0 | H20: 0 | I20: 5 | J20: 1 | K20: 1 | L20: 4 | M20: 19 | N20: 0 | O20: =SUM(C20:L20,N20) -> 73 | P20: =SUM(C20:N20) -> 92 | R20: 1700-1800 | S20: =SUM(C50:C53) -> 90 | T20: =SUM(D50:D53) -> 37 | U20: =SUM(E50:E53) -> 19 | V20: =SUM(F50:F53) -> 157 | W20: =SUM(G50:G53) -> 8 | X20: =SUM(H50:H53) -> 5 | Y20: =SUM(I50:I53) -> 21 | Z20: =SUM(J50:J53) -> 24 | ... AF20: =SUM(P50:P53) -> 486
B21: 09.45 - 10.00 | C21: 15 | D21: 3 | E21: 1 | F21: 37 | G21: 1 | H21: 1 | I21: 5 | J21: 1 | K21: 1 | L21: 8 | M21: 25 | N21: 0 | O21: =SUM(C21:L21,N21) -> 73 | P21: =SUM(C21:N21) -> 98 | R21: 1800-1900 | S21: =SUM(C54:C57) -> 116 | T21: =SUM(D54:D57) -> 32 | U21: =SUM(E54:E57) -> 17 | V21: =SUM(F54:F57) -> 140 | W21: =SUM(G54:G57) -> 11 | X21: =SUM(H54:H57) -> 3 | Y21: =SUM(I54:I57) -> 32 | Z21: =SUM(J54:J57) -> 29 | ... AF21: =SUM(P54:P57) -> 525
B22: 10.00 - 10.15 | C22: 11 | D22: 2 | E22: 4 | F22: 33 | G22: 2 | H22: 1 | I22: 7 | J22: 1 | K22: 0 | L22: 9 | M22: 24 | N22: 0 | O22: =SUM(C22:L22,N22) -> 70 | P22: =SUM(C22:N22) -> 94 | R22: 1900-2000 | S22: =SUM(C58:C61) -> 94 | T22: =SUM(D58:D61) -> 43 | U22: =SUM(E58:E61) -> 23 | V22: =SUM(F58:F61) -> 126 | W22: =SUM(G58:G61) -> 8 | X22: =SUM(H58:H61) -> 7 | Y22: =SUM(I58:I61) -> 5 | Z22: =SUM(J58:J61) -> 23 | ... AF22: =SUM(P58:P61) -> 472
B23: 10.15 - 10.30 | C23: 24 | D23: 6 | E23: 6 | F23: 30 | G23: 2 | H23: 0 | I23: 7 | J23: 5 | K23: 3 | L23: 8 | M23: 26 | N23: 0 | O23: =SUM(C23:L23,N23) -> 91 | P23: =SUM(C23:N23) -> 117 | R23: 2000-2100 | S23: =SUM(C62:C65) -> 107 | T23: =SUM(D62:D65) -> 55 | U23: =SUM(E62:E65) -> 25 | V23: =SUM(F62:F65) -> 105 | W23: =SUM(G62:G65) -> 7 | X23: =SUM(H62:H65) -> 2 | Y23: =SUM(I62:I65) -> 13 | Z23: =SUM(J62:J65) -> 24 | ... AF23: =SUM(P62:P65) -> 485
B24: 10.30 - 10.45 | C24: 12 | D24: 6 | E24: 3 | F24: 30 | G24: 0 | H24: 1 | I24: 3 | J24: 2 | K24: 0 | L24: 9 | M24: 24 | N24: 0 | O24: =SUM(C24:L24,N24) -> 66 | P24: =SUM(C24:N24) -> 90 | R24: 2100-2200 | S24: =SUM(C66:C69) -> 102 | T24: =SUM(D66:D69) -> 58 | U24: =SUM(E66:E69) -> 46 | V24: =SUM(F66:F69) -> 102 | W24: =SUM(G66:G69) -> 5 | X24: =SUM(H66:H69) -> 2 | Y24: =SUM(I66:I69) -> 6 | Z24: =SUM(J66:J69) -> 22 | ... AF24: =SUM(P66:P69) -> 471
B25: 10.45 - 11.00 | C25: 18 | D25: 9 | E25: 1 | F25: 25 | G25: 1 | H25: 1 | I25: 3 | J25: 8 | K25: 1 | L25: 14 | M25: 29 | N25: 0 | O25: =SUM(C25:L25,N25) -> 81 | P25: =SUM(C25:N25) -> 110 | R25: 2200-2300 | S25: =SUM(C70:C73) -> 59 | T25: =SUM(D70:D73) -> 26 | U25: =SUM(E70:E73) -> 12 | V25: =SUM(F70:F73) -> 69 | W25: =SUM(G70:G73) -> 1 | X25: =SUM(H70:H73) -> 2 | Y25: =SUM(I70:I73) -> 4 | Z25: =SUM(J70:J73) -> 26 | ... AF25: =SUM(P70:P73) -> 274
B26: 11.00 - 11.15 | C26: 21 | D26: 3 | E26: 3 | F26: 38 | G26: 0 | H26: 1 | I26: 4 | J26: 1 | K26: 1 | L26: 11 | M26: 31 | N26: 0 | O26: =SUM(C26:L26,N26) -> 83 | P26: =SUM(C26:N26) -> 114 | R26: 2300-0000 | S26: =SUM(C74:C77) -> 27 | T26: =SUM(D74:D77) -> 18 | U26: =SUM(E74:E77) -> 5 | V26: =SUM(F74:F77) -> 24 | W26: =SUM(G74:G77) -> 3 | X26: =SUM(H74:H77) -> 0 | Y26: =SUM(I74:I77) -> 7 | Z26: =SUM(J74:J77) -> 17 | ... AF26: =SUM(P74:P77) -> 152
B27: 11.15 - 11.30 | C27: 14 | D27: 9 | E27: 5 | F27: 29 | G27: 2 | H27: 0 | I27: 1 | J27: 5 | K27: 1 | L27: 10 | M27: 28 | N27: 0 | O27: =SUM(C27:L27,N27) -> 76 | P27: =SUM(C27:N27) -> 104 | R27: 0000-0100 | S27: =SUM(C78:C81) -> 2 | T27: =SUM(D78:D81) -> 1 | U27: =SUM(E78:E81) -> 1 | V27: =SUM(F78:F81) -> 4 | W27: =SUM(G78:G81) -> 0 | X27: =SUM(H78:H81) -> 0 | Y27: =SUM(I78:I81) -> 0 | Z27: =SUM(J78:J81) -> 0 | ... AF27: =SUM(P78:P81) -> 9
B28: 11.30 - 11.45 | C28: 16 | D28: 5 | E28: 5 | F28: 27 | G28: 0 | H28: 0 | I28: 2 | J28: 3 | K28: 0 | L28: 9 | M28: 30 | N28: 1 | O28: =SUM(C28:L28,N28) -> 68 | P28: =SUM(C28:N28) -> 98 | R28: 0100-0200 | S28: =SUM(C82:C85) -> 6 | T28: =SUM(D82:D85) -> 2 | U28: =SUM(E82:E85) -> 1 | V28: =SUM(F82:F85) -> 13 | W28: =SUM(G82:G85) -> 1 | X28: =SUM(H82:H85) -> 3 | Y28: =SUM(I82:I85) -> 5 | Z28: =SUM(J82:J85) -> 7 | ... AF28: =SUM(P82:P85) -> 55
