Workbook

Sheet 22.07 SentemaRBT-Sentema
B1: Consultancy services for Preparation of Expressway Development Master Plan (EDMP) for Uganda
B2: MANUAL CLASSIFIED COUNT (MCC)
B3: ROAD NAME: | C3: MCC - C1 - STN15 - SENTEMA ROAD
C5: Date | D5: 22.07.19 | F5: Location | G5: Ku roofings | J5: Surveyor | K5: Naido Grace
C6: Dir. From | D6: Sentema RBT | F6: Dir. To | G6: Sentema | J6: Supervisor | K6: Isaac
B8: Time / Veh Type | R8: SUMMARY TRAFFIC VOLUMES
C9: 1. Car | D9: 2. Station Wagon | E9: 3. Pickups | F9: 4. Minibus, matatu | G9: 5. Medium bus | H9: 6. Large Bus | I9: 7. Light Truck | J9: 8. Medium Truck | K9: 9. Heavy truck | L9: 10. Truck Trailer | M9: 11. Motor cycles | N9: 12. Tractors | O9: Total Excl M/Cycles | P9: Total All | R9: Time | S9: 1. Car | T9: 2. Station Wagon | U9: 3. Pickups | V9: 4. Minibus, matatu | W9: 5. Medium bus | X9: 6. Large Bus | Y9: 7. Light Truck | Z9: 8. Medium Truck | AA9: 9. Heavy truck | AB9: 10. Truck Trailer | AC9: 11. Motorcycles | AD9: 12. Tractors, Graders | AE9: Total Excl M/ Cycles | AF9: Total All
B10: 07.00 - 07.15 | C10: 7 | D10: 1 | E10: 0 | F10: 8 | G10: 0 | H10: 0 | I10: 1 | J10: 2 | K10: 0 | L10: 0 | M10: 33 | N10: 0 | O10: =SUM(C10:L10,N10) -> 19 | P10: =SUM(C10:N10) -> 52 | R10: 0700-0800 | S10: =SUM(C10:C13) -> 38 | T10: =SUM(D10:D13) -> 10 | U10: =SUM(E10:E13) -> 3 | V10: =SUM(F10:F13) -> 44 | W10: =SUM(G10:G13) -> 1 | X10: =SUM(H10:H13) -> 0 | Y10: =SUM(I10:I13) -> 6 | Z10: =SUM(J10:J13) -> 5 | ... AF10: =SUM(P10:P13) -> 291
B11: 07.15 - 07.30 | C11: 13 | D11: 3 | E11: 0 | F11: 16 | G11: 1 | H11: 0 | I11: 0 | J11: 2 | K11: 0 | L11: 0 | M11: 35 | N11: 0 | O11: =SUM(C11:L11,N11) -> 35 | P11: =SUM(C11:N11) -> 70 | R11: 0800-0900 | S11: =SUM(C14:C17) -> 25 | T11: =SUM(D14:D17) -> 9 | U11: =SUM(E14:E17) -> 4 | V11: =SUM(F14:F17) -> 53 | W11: =SUM(G14:G17) -> 0 | X11: =SUM(H14:H17) -> 2 | Y11: =SUM(I14:I17) -> 5 | Z11: =SUM(J14:J17) -> 5 | ... AF11: =SUM(P14:P17) -> 303
B12: 07.30 - 07.45 | C12: 11 | D12: 1 | E12: 3 | F12: 8 | G12: 0 | H12: 0 | I12: 5 | J12: 1 | K12: 1 | L12: 0 | M12: 50 | N12: 0 | O12: =SUM(C12:L12,N12) -> 30 | P12: =SUM(C12:N12) -> 80 | R12: 0900-1000 | S12: =SUM(C18:C21) -> 31 | T12: =SUM(D18:D21) -> 18 | U12: =SUM(E18:E21) -> 2 | V12: =SUM(F18:F21) -> 62 | W12: =SUM(G18:G21) -> 0 | X12: =SUM(H18:H21) -> 3 | Y12: =SUM(I18:I21) -> 22 | Z12: =SUM(J18:J21) -> 9 | ... AF12: =SUM(P18:P21) -> 365
B13: 07.45 - 08.00 | C13: 7 | D13: 5 | E13: 0 | F13: 12 | G13: 0 | H13: 0 | I13: 0 | J13: 0 | K13: 0 | L13: 1 | M13: 64 | N13: 0 | O13: =SUM(C13:L13,N13) -> 25 | P13: =SUM(C13:N13) -> 89 | R13: 1000-1100 | S13: =SUM(C22:C25) -> 28 | T13: =SUM(D22:D25) -> 11 | U13: =SUM(E22:E25) -> 5 | V13: =SUM(F22:F25) -> 49 | W13: =SUM(G22:G25) -> 0 | X13: =SUM(H22:H25) -> 0 | Y13: =SUM(I22:I25) -> 14 | Z13: =SUM(J22:J25) -> 4 | ... AF13: =SUM(P22:P25) -> 339
B14: 08.00 - 08.15 | C14: 7 | D14: 3 | E14: 0 | F14: 16 | G14: 0 | H14: 0 | I14: 2 | J14: 1 | K14: 0 | L14: 0 | M14: 54 | N14: 0 | O14: =SUM(C14:L14,N14) -> 29 | P14: =SUM(C14:N14) -> 83 | R14: 1100-1200 | S14: =SUM(C26:C29) -> 20 | T14: =SUM(D26:D29) -> 10 | U14: =SUM(E26:E29) -> 7 | V14: =SUM(F26:F29) -> 26 | W14: =SUM(G26:G29) -> 0 | X14: =SUM(H26:H29) -> 0 | Y14: =SUM(I26:I29) -> 17 | Z14: =SUM(J26:J29) -> 5 | ... AF14: =SUM(P26:P29) -> 262
B15: 08.15 - 08.30 | C15: 11 | D15: 2 | E15: 2 | F15: 17 | G15: 0 | H15: 2 | I15: 2 | J15: 2 | K15: 0 | L15: 0 | M15: 66 | N15: 0 | O15: =SUM(C15:L15,N15) -> 38 | P15: =SUM(C15:N15) -> 104 | R15: 1200-1300 | S15: =SUM(C30:C33) -> 18 | T15: =SUM(D30:D33) -> 10 | U15: =SUM(E30:E33) -> 4 | V15: =SUM(F30:F33) -> 25 | W15: =SUM(G30:G33) -> 0 | X15: =SUM(H30:H33) -> 0 | Y15: =SUM(I30:I33) -> 22 | Z15: =SUM(J30:J33) -> 3 | ... AF15: =SUM(P30:P33) -> 232
B16: 08.30 - 08.45 | C16: 7 | D16: 4 | E16: 2 | F16: 16 | G16: 0 | H16: 0 | I16: 1 | J16: 2 | K16: 0 | L16: 0 | M16: 70 | N16: 0 | O16: =SUM(C16:L16,N16) -> 32 | P16: =SUM(C16:N16) -> 102 | R16: 1300-1400 | S16: =SUM(C34:C37) -> 27 | T16: =SUM(D34:D37) -> 8 | U16: =SUM(E34:E37) -> 4 | V16: =SUM(F34:F37) -> 24 | W16: =SUM(G34:G37) -> 0 | X16: =SUM(H34:H37) -> 0 | Y16: =SUM(I34:I37) -> 14 | Z16: =SUM(J34:J37) -> 4 | ... AF16: =SUM(P34:P37) -> 229
B17: 08.45 - 9.00 | C17: 0 | D17: 0 | E17: 0 | F17: 4 | G17: 0 | H17: 0 | I17: 0 | J17: 0 | K17: 0 | L17: 0 | M17: 10 | N17: 0 | O17: =SUM(C17:L17,N17) -> 4 | P17: =SUM(C17:N17) -> 14 | R17: 1400-1500 | S17: =SUM(C38:C41) -> 39 | T17: =SUM(D38:D41) -> 8 | U17: =SUM(E38:E41) -> 7 | V17: =SUM(F38:F41) -> 24 | W17: =SUM(G38:G41) -> 1 | X17: =SUM(H38:H41) -> 0 | Y17: =SUM(I38:I41) -> 19 | Z17: =SUM(J38:J41) -> 6 | ... AF17: =SUM(P38:P41) -> 262
B18: 09.00 - 09.15 | C18: 8 | D18: 2 | E18: 0 | F18: 23 | G18: 0 | H18: 2 | I18: 2 | J18: 0 | K18: 0 | L18: 0 | M18: 61 | N18: 0 | O18: =SUM(C18:L18,N18) -> 37 | P18: =SUM(C18:N18) -> 98 | R18: 1500-1600 | S18: =SUM(C42:C45) -> 38 | T18: =SUM(D42:D45) -> 14 | U18: =SUM(E42:E45) -> 7 | V18: =SUM(F42:F45) -> 25 | W18: =SUM(G42:G45) -> 0 | X18: =SUM(H42:H45) -> 0 | Y18: =SUM(I42:I45) -> 2 | Z18: =SUM(J42:J45) -> 2 | ... AF18: =SUM(P42:P45) -> 204
B19: 09.15 - 09.30 | C19: 6 | D19: 4 | E19: 1 | F19: 15 | G19: 0 | H19: 0 | I19: 6 | J19: 0 | K19: 0 | L19: 1 | M19: 69 | N19: 0 | O19: =SUM(C19:L19,N19) -> 33 | P19: =SUM(C19:N19) -> 102 | R19: 1600-1700 | S19: =SUM(C46:C49) -> 50 | T19: =SUM(D46:D49) -> 9 | U19: =SUM(E46:E49) -> 4 | V19: =SUM(F46:F49) -> 28 | W19: =SUM(G46:G49) -> 1 | X19: =SUM(H46:H49) -> 0 | Y19: =SUM(I46:I49) -> 10 | Z19: =SUM(J46:J49) -> 6 | ... AF19: =SUM(P46:P49) -> 293
B20: 09.30 - 09.45 | C20: 12 | D20: 7 | E20: 0 | F20: 14 | G20: 0 | H20: 0 | I20: 9 | J20: 6 | K20: 0 | L20: 0 | M20: 45 | N20: 0 | O20: =SUM(C20:L20,N20) -> 48 | P20: =SUM(C20:N20) -> 93 | R20: 1700-1800 | S20: =SUM(C50:C53) -> 96 | T20: =SUM(D50:D53) -> 24 | U20: =SUM(E50:E53) -> 4 | V20: =SUM(F50:F53) -> 47 | W20: =SUM(G50:G53) -> 1 | X20: =SUM(H50:H53) -> 0 | Y20: =SUM(I50:I53) -> 13 | Z20: =SUM(J50:J53) -> 3 | ... AF20: =SUM(P50:P53) -> 419
B21: 09.45 - 10.00 | C21: 5 | D21: 5 | E21: 1 | F21: 10 | G21: 0 | H21: 1 | I21: 5 | J21: 3 | K21: 0 | L21: 0 | M21: 42 | N21: 0 | O21: =SUM(C21:L21,N21) -> 30 | P21: =SUM(C21:N21) -> 72 | R21: 1800-1900 | S21: =SUM(C54:C57) -> 140 | T21: =SUM(D54:D57) -> 23 | U21: =SUM(E54:E57) -> 6 | V21: =SUM(F54:F57) -> 55 | W21: =SUM(G54:G57) -> 1 | X21: =SUM(H54:H57) -> 0 | Y21: =SUM(I54:I57) -> 11 | Z21: =SUM(J54:J57) -> 8 | ... AF21: =SUM(P54:P57) -> 520
B22: 10.00 - 10.15 | C22: 9 | D22: 3 | E22: 1 | F22: 11 | G22: 0 | H22: 0 | I22: 8 | J22: 0 | K22: 1 | L22: 0 | M22: 67 | N22: 0 | O22: =SUM(C22:L22,N22) -> 33 | P22: =SUM(C22:N22) -> 100 | R22: AM Peak Hr | S22: =MAX(S10:S12) -> 38 | T22: =MAX(T10:T12) -> 18 | U22: =MAX(U10:U12) -> 4 | V22: =MAX(V10:V12) -> 62 | W22: =MAX(W10:W12) -> 1 | X22: =MAX(X10:X12) -> 3 | Y22: =MAX(Y10:Y12) -> 22 | Z22: =MAX(Z10:Z12) -> 9 | ... AF22: =MAX(AF10:AF12) -> 365
B23: 10.15 - 10.30 | C23: 7 | D23: 3 | E23: 2 | F23: 17 | G23: 0 | H23: 0 | I23: 1 | J23: 2 | K23: 0 | L23: 0 | M23: 61 | N23: 0 | O23: =SUM(C23:L23,N23) -> 32 | P23: =SUM(C23:N23) -> 93 | R23: IP Peak Hr | S23: =MAX(S13:S18) -> 39 | T23: =MAX(T13:T18) -> 14 | U23: =MAX(U13:U18) -> 7 | V23: =MAX(V13:V18) -> 49 | W23: =MAX(W13:W18) -> 1 | X23: =MAX(X13:X18) -> 0 | Y23: =MAX(Y13:Y18) -> 22 | Z23: =MAX(Z13:Z18) -> 6 | ... AF23: =MAX(AF13:AF18) -> 339
B24: 10.30 - 10.45 | C24: 7 | D24: 5 | E24: 0 | F24: 12 | G24: 0 | H24: 0 | I24: 2 | J24: 0 | K24: 0 | L24: 0 | M24: 65 | N24: 0 | O24: =SUM(C24:L24,N24) -> 26 | P24: =SUM(C24:N24) -> 91 | R24: PM Peak Hr | S24: =MAX(S19:S21) -> 140 | T24: =MAX(T19:T21) -> 24 | U24: =MAX(U19:U21) -> 6 | V24: =MAX(V19:V21) -> 55 | W24: =MAX(W19:W21) -> 1 | X24: =MAX(X19:X21) -> 0 | Y24: =MAX(Y19:Y21) -> 13 | Z24: =MAX(Z19:Z21) -> 8 | ... AF24: =MAX(AF19:AF21) -> 520
B25: 10.45 - 11.00 | C25: 5 | D25: 0 | E25: 2 | F25: 9 | G25: 0 | H25: 0 | I25: 3 | J25: 2 | K25: 0 | L25: 0 | M25: 34 | N25: 0 | O25: =SUM(C25:L25,N25) -> 21 | P25: =SUM(C25:N25) -> 55 | R25: AM Period | S25: =SUM(S10:S12) -> 94 | T25: =SUM(T10:T12) -> 37 | U25: =SUM(U10:U12) -> 9 | V25: =SUM(V10:V12) -> 159 | W25: =SUM(W10:W12) -> 1 | X25: =SUM(X10:X12) -> 5 | Y25: =SUM(Y10:Y12) -> 33 | Z25: =SUM(Z10:Z12) -> 19 | ... AF25: =SUM(AF10:AF12) -> 959
B26: 11.00 - 11.15 | C26: 5 | D26: 4 | E26: 1 | F26: 10 | G26: 0 | H26: 0 | I26: 2 | J26: 0 | K26: 2 | L26: 0 | M26: 43 | N26: 0 | O26: =SUM(C26:L26,N26) -> 24 | P26: =SUM(C26:N26) -> 67 | R26: IP Period | S26: =SUM(S13:S18) -> 170 | T26: =SUM(T13:T18) -> 61 | U26: =SUM(U13:U18) -> 34 | V26: =SUM(V13:V18) -> 173 | W26: =SUM(W13:W18) -> 1 | X26: =SUM(X13:X18) -> 0 | Y26: =SUM(Y13:Y18) -> 88 | Z26: =SUM(Z13:Z18) -> 24 | ... AF26: =SUM(AF13:AF18) -> 1528
B27: 11.15 - 11.30 | C27: 6 | D27: 1 | E27: 0 | F27: 8 | G27: 0 | H27: 0 | I27: 6 | J27: 1 | K27: 0 | L27: 0 | M27: 31 | N27: 0 | O27: =SUM(C27:L27,N27) -> 22 | P27: =SUM(C27:N27) -> 53 | R27: PM Period | S27: =SUM(S19:S21) -> 286 | T27: =SUM(T19:T21) -> 56 | U27: =SUM(U19:U21) -> 14 | V27: =SUM(V19:V21) -> 130 | W27: =SUM(W19:W21) -> 3 | X27: =SUM(X19:X21) -> 0 | Y27: =SUM(Y19:Y21) -> 34 | Z27: =SUM(Z19:Z21) -> 17 | ... AF27: =SUM(AF19:AF21) -> 1232
B28: 11.30 - 11.45 | C28: 6 | D28: 1 | E28: 1 | F28: 5 | G28: 0 | H28: 0 | I28: 5 | J28: 1 | K28: 1 | L28: 0 | M28: 59 | N28: 0 | O28: =SUM(C28:L28,N28) -> 20 | P28: =SUM(C28:N28) -> 79 | R28: 12 Hours | S28: =SUM(S10:S21) -> 550 | T28: =SUM(T10:T21) -> 154 | U28: =SUM(U10:U21) -> 57 | V28: =SUM(V10:V21) -> 462 | W28: =SUM(W10:W21) -> 5 | X28: =SUM(X10:X21) -> 5 | Y28: =SUM(Y10:Y21) -> 155 | Z28: =SUM(Z10:Z21) -> 60 | ... AF28: =SUM(AF10:AF21) -> 3719
B29: 11.45 - 12.00 | C29: 3 | D29: 4 | E29: 5 | F29: 3 | G29: 0 | H29: 0 | I29: 4 | J29: 3 | K29: 0 | L29: 0 | M29: 41 | N29: 0 | O29: =SUM(C29:L29,N29) -> 22 | P29: =SUM(C29:N29) -> 63
B30: 12.00 - 12.15 | C30: 6 | D30: 1 | E30: 1 | F30: 10 | G30: 0 | H30: 0 | I30: 4 | J30: 1 | K30: 0 | L30: 0 | M30: 24 | N30: 0 | O30: =SUM(C30:L30,N30) -> 23 | P30: =SUM(C30:N30) -> 47
B31: 12.15 - 12.30 | C31: 1 | D31: 3 | E31: 1 | F31: 3 | G31: 0 | H31: 0 | I31: 7 | J31: 1 | K31: 0 | L31: 0 | M31: 40 | N31: 0 | O31: =SUM(C31:L31,N31) -> 16 | P31: =SUM(C31:N31) -> 56
B32: 12.30 - 12.45 | C32: 7 | D32: 3 | E32: 0 | F32: 8 | G32: 0 | H32: 0 | I32: 4 | J32: 1 | K32: 0 | L32: 0 | M32: 46 | N32: 0 | O32: =SUM(C32:L32,N32) -> 23 | P32: =SUM(C32:N32) -> 69
B33: 12.45 - 13.00 | C33: 4 | D33: 3 | E33: 2 | F33: 4 | G33: 0 | H33: 0 | I33: 7 | J33: 0 | K33: 0 | L33: 0 | M33: 39 | N33: 1 | O33: =SUM(C33:L33,N33) -> 21 | P33: =SUM(C33:N33) -> 60
B34: 13.00 - 13.15 | C34: 9 | D34: 0 | E34: 2 | F34: 7 | G34: 0 | H34: 0 | I34: 5 | J34: 0 | K34: 0 | L34: 0 | M34: 44 | N34: 0 | O34: =SUM(C34:L34,N34) -> 23 | P34: =SUM(C34:N34) -> 67
B35: 13.15 - 13.30 | C35: 6 | D35: 2 | E35: 0 | F35: 7 | G35: 0 | H35: 0 | I35: 4 | J35: 1 | K35: 0 | L35: 0 | M35: 40 | N35: 0 | O35: =SUM(C35:L35,N35) -> 20 | P35: =SUM(C35:N35) -> 60
B36: 13.30 - 13.45 | C36: 7 | D36: 3 | E36: 1 | F36: 3 | G36: 0 | H36: 0 | I36: 2 | J36: 1 | K36: 0 | L36: 0 | M36: 28 | N36: 0 | O36: =SUM(C36:L36,N36) -> 17 | P36: =SUM(C36:N36) -> 45
B37: 13.45 - 14.00 | C37: 5 | D37: 3 | E37: 1 | F37: 7 | G37: 0 | H37: 0 | I37: 3 | J37: 2 | K37: 0 | L37: 1 | M37: 35 | N37: 0 | O37: =SUM(C37:L37,N37) -> 22 | P37: =SUM(C37:N37) -> 57
B38: 14.00 - 14.15 | C38: 6 | D38: 2 | E38: 4 | F38: 6 | G38: 1 | H38: 0 | I38: 6 | J38: 3 | K38: 1 | L38: 0 | M38: 37 | N38: 0 | O38: =SUM(C38:L38,N38) -> 29 | P38: =SUM(C38:N38) -> 66
B39: 14.15 - 14.30 | C39: 13 | D39: 1 | E39: 1 | F39: 7 | G39: 0 | H39: 0 | I39: 4 | J39: 1 | K39: 0 | L39: 0 | M39: 33 | N39: 0 | O39: =SUM(C39:L39,N39) -> 27 | P39: =SUM(C39:N39) -> 60
B40: 14.30 - 14.45 | C40: 8 | D40: 2 | E40: 1 | F40: 4 | G40: 0 | H40: 0 | I40: 3 | J40: 2 | K40: 0 | L40: 0 | M40: 41 | N40: 0 | O40: =SUM(C40:L40,N40) -> 20 | P40: =SUM(C40:N40) -> 61
... B57: 18.45 - 19.00 | C57: 31 | D57: 2 | E57: 3 | F57: 15 | G57: 0 | H57: 0 | I57: 3 | J57: 3 | K57: 0 | L57: 0 | M57: 80 | N57: 1 | O57: =SUM(C57:L57,N57) -> 58 | P57: =SUM(C57:N57) -> 138
B58: Totals | C58: =SUM(C10:C57) -> 550 | D58: =SUM(D10:D57) -> 154 | E58: =SUM(E10:E57) -> 57 | F58: =SUM(F10:F57) -> 462 | G58: =SUM(G10:G57) -> 5 | H58: =SUM(H10:H57) -> 5 | I58: =SUM(I10:I57) -> 155 | J58: =SUM(J10:J57) -> 60 | ... P58: =SUM(P10:P57) -> 3719
...

Sheet 22.07 Sentema-Sentema RBT
B1: Consultancy services for Preparation of Expressway Development Master Plan (EDMP) for Uganda
B2: MANUAL CLASSIFIED COUNT (MCC)
B3: ROAD NAME: | C3: ='22.07 SentemaRBT-Sentema'!C3:G3 -> MCC - C1 - STN15 - SENTEMA ROAD
C5: Date | D5: ='22.07 SentemaRBT-Sentema'!D5 -> 22.07.19 | F5: Location | G5: ='22.07 SentemaRBT-Sentema'!G5:H5 -> Ku roofings | J5: Surveyor | K5: Mbaha James
C6: Dir. From | D6: Sentema | F6: Dir. To | G6: Sentema RBT | J6: Supervisor | K6: Isaac
B8: Time / Veh Type | R8: SUMMARY TRAFFIC VOLUMES
C9: 1. Car | D9: 2. Station Wagon | E9: 3. Pickups | F9: 4. Minibus, matatu | G9: 5. Medium bus | H9: 6. Large Bus | I9: 7. Light Truck | J9: 8. Medium Truck | K9: 9. Heavy truck | L9: 10. Truck Trailer | M9: 11. Motor cycles | N9: 12. Tractors | O9: Total Excl M/Cycles | P9: Total All | R9: Time | S9: 1. Car | T9: 2. Station Wagon | U9: 3. Pickups | V9: 4. Minibus, matatu | W9: 5. Medium bus | X9: 6. Large Bus | Y9: 7. Light Truck | Z9: 8. Medium Truck | AA9: 9. Heavy truck | AB9: 10. Truck Trailer | AC9: 11. Motorcycles | AD9: 12. Tractors, Graders | AE9: Total Excl M/ Cycles | AF9: Total All
B10: 07.00 - 07.15 | C10: 63 | D10: 3 | E10: 10 | F10: 31 | G10: 0 | H10: 0 | I10: 1 | J10: 2 | K10: 1 | L10: 1 | M10: 59 | N10: 0 | O10: =SUM(C10:L10,N10) -> 112 | P10: =SUM(C10:N10) -> 171 | R10: 0700-0800 | S10: =SUM(C10:C13) -> 289 | T10: =SUM(D10:D13) -> 14 | U10: =SUM(E10:E13) -> 24 | V10: =SUM(F10:F13) -> 127 | W10: =SUM(G10:G13) -> 1 | X10: =SUM(H10:H13) -> 0 | Y10: =SUM(I10:I13) -> 10 | Z10: =SUM(J10:J13) -> 3 | ... AF10: =SUM(P10:P13) -> 833
B11: 07.15 - 07.30 | C11: 71 | D11: 4 | E11: 6 | F11: 42 | G11: 0 | H11: 0 | I11: 5 | J11: 0 | K11: 1 | L11: 0 | M11: 91 | N11: 0 | O11: =SUM(C11:L11,N11) -> 129 | P11: =SUM(C11:N11) -> 220 | R11: 0800-0900 | S11: =SUM(C14:C17) -> 152 | T11: =SUM(D14:D17) -> 18 | U11: =SUM(E14:E17) -> 15 | V11: =SUM(F14:F17) -> 53 | W11: =SUM(G14:G17) -> 0 | X11: =SUM(H14:H17) -> 0 | Y11: =SUM(I14:I17) -> 12 | Z11: =SUM(J14:J17) -> 3 | ... AF11: =SUM(P14:P17) -> 629
B12: 07.30 - 07.45 | C12: 73 | D12: 1 | E12: 2 | F12: 24 | G12: 1 | H12: 0 | I12: 2 | J12: 0 | K12: 0 | L12: 0 | M12: 114 | N12: 0 | O12: =SUM(C12:L12,N12) -> 103 | P12: =SUM(C12:N12) -> 217 | R12: 0900-1000 | S12: =SUM(C18:C21) -> 136 | T12: =SUM(D18:D21) -> 13 | U12: =SUM(E18:E21) -> 14 | V12: =SUM(F18:F21) -> 51 | W12: =SUM(G18:G21) -> 0 | X12: =SUM(H18:H21) -> 0 | Y12: =SUM(I18:I21) -> 13 | Z12: =SUM(J18:J21) -> 6 | ... AF12: =SUM(P18:P21) -> 516
B13: 07.45 - 08.00 | C13: 82 | D13: 6 | E13: 6 | F13: 30 | G13: 0 | H13: 0 | I13: 2 | J13: 1 | K13: 0 | L13: 2 | M13: 96 | N13: 0 | O13: =SUM(C13:L13,N13) -> 129 | P13: =SUM(C13:N13) -> 225 | R13: 1000-1100 | S13: =SUM(C22:C25) -> 62 | T13: =SUM(D22:D25) -> 15 | U13: =SUM(E22:E25) -> 12 | V13: =SUM(F22:F25) -> 38 | W13: =SUM(G22:G25) -> 1 | X13: =SUM(H22:H25) -> 0 | Y13: =SUM(I22:I25) -> 15 | Z13: =SUM(J22:J25) -> 3 | ... AF13: =SUM(P22:P25) -> 310
B14: 08.00 - 08.15 | C14: 73 | D14: 4 | E14: 4 | F14: 23 | G14: 0 | H14: 0 | I14: 4 | J14: 3 | K14: 0 | L14: 0 | M14: 117 | N14: 0 | O14: =SUM(C14:L14,N14) -> 111 | P14: =SUM(C14:N14) -> 228 | R14: 1100-1200 | S14: =SUM(C26:C29) -> 34 | T14: =SUM(D26:D29) -> 20 | U14: =SUM(E26:E29) -> 12 | V14: =SUM(F26:F29) -> 28 | W14: =SUM(G26:G29) -> 0 | X14: =SUM(H26:H29) -> 0 | Y14: =SUM(I26:I29) -> 14 | Z14: =SUM(J26:J29) -> 2 | ... AF14: =SUM(P26:P29) -> 272
B15: 08.15 - 08.30 | C15: 45 | D15: 9 | E15: 7 | F15: 16 | G15: 0 | H15: 0 | I15: 4 | J15: 0 | K15: 0 | L15: 0 | M15: 145 | N15: 0 | O15: =SUM(C15:L15,N15) -> 81 | P15: =SUM(C15:N15) -> 226 | R15: 1200-1300 | S15: =SUM(C30:C33) -> 50 | T15: =SUM(D30:D33) -> 11 | U15: =SUM(E30:E33) -> 6 | V15: =SUM(F30:F33) -> 14 | W15: =SUM(G30:G33) -> 0 | X15: =SUM(H30:H33) -> 0 | Y15: =SUM(I30:I33) -> 19 | Z15: =SUM(J30:J33) -> 7 | ... AF15: =SUM(P30:P33) -> 240
B16: 08.30 - 08.45 | C16: 29 | D16: 4 | E16: 4 | F16: 11 | G16: 0 | H16: 0 | I16: 3 | J16: 0 | K16: 0 | L16: 0 | M16: 89 | N16: 0 | O16: =SUM(C16:L16,N16) -> 51 | P16: =SUM(C16:N16) -> 140 | R16: 1300-1400 | S16: =SUM(C34:C37) -> 35 | T16: =SUM(D34:D37) -> 6 | U16: =SUM(E34:E37) -> 2 | V16: =SUM(F34:F37) -> 15 | W16: =SUM(G34:G37) -> 0 | X16: =SUM(H34:H37) -> 0 | Y16: =SUM(I34:I37) -> 14 | Z16: =SUM(J34:J37) -> 3 | ... AF16: =SUM(P34:P37) -> 180
B17: 08.45 - 9.00 | C17: 5 | D17: 1 | E17: 0 | F17: 3 | G17: 0 | H17: 0 | I17: 1 | J17: 0 | K17: 0 | L17: 0 | M17: 25 | N17: 0 | O17: =SUM(C17:L17,N17) -> 10 | P17: =SUM(C17:N17) -> 35 | R17: 1400-1500 | S17: =SUM(C38:C41) -> 37 | T17: =SUM(D38:D41) -> 9 | U17: =SUM(E38:E41) -> 5 | V17: =SUM(F38:F41) -> 29 | W17: =SUM(G38:G41) -> 0 | X17: =SUM(H38:H41) -> 1 | Y17: =SUM(I38:I41) -> 17 | Z17: =SUM(J38:J41) -> 3 | ... AF17: =SUM(P38:P41) -> 281
B18: 09.00 - 09.15 | C18: 35 | D18: 2 | E18: 7 | F18: 16 | G18: 0 | H18: 0 | I18: 5 | J18: 0 | K18: 0 | L18: 0 | M18: 90 | N18: 0 | O18: =SUM(C18:L18,N18) -> 65 | P18: =SUM(C18:N18) -> 155 | R18: 1500-1600 | S18: =SUM(C42:C45) -> 38 | T18: =SUM(D42:D45) -> 12 | U18: =SUM(E42:E45) -> 4 | V18: =SUM(F42:F45) -> 19 | W18: =SUM(G42:G45) -> 0 | X18: =SUM(H42:H45) -> 0 | Y18: =SUM(I42:I45) -> 16 | Z18: =SUM(J42:J45) -> 4 | ... AF18: =SUM(P42:P45) -> 238
B19: 09.15 - 09.30 | C19: 29 | D19: 3 | E19: 0 | F19: 13 | G19: 0 | H19: 0 | I19: 2 | J19: 3 | K19: 0 | L19: 0 | M19: 81 | N19: 0 | O19: =SUM(C19:L19,N19) -> 50 | P19: =SUM(C19:N19) -> 131 | R19: 1600-1700 | S19: =SUM(C46:C49) -> 40 | T19: =SUM(D46:D49) -> 8 | U19: =SUM(E46:E49) -> 7 | V19: =SUM(F46:F49) -> 15 | W19: =SUM(G46:G49) -> 0 | X19: =SUM(H46:H49) -> 0 | Y19: =SUM(I46:I49) -> 10 | Z19: =SUM(J46:J49) -> 5 | ... AF19: =SUM(P46:P49) -> 273
B20: 09.30 - 09.45 | C20: 38 | D20: 4 | E20: 4 | F20: 9 | G20: 0 | H20: 0 | I20: 2 | J20: 3 | K20: 0 | L20: 1 | M20: 67 | N20: 0 | O20: =SUM(C20:L20,N20) -> 61 | P20: =SUM(C20:N20) -> 128 | R20: 1700-1800 | S20: =SUM(C50:C53) -> 49 | T20: =SUM(D50:D53) -> 17 | U20: =SUM(E50:E53) -> 5 | V20: =SUM(F50:F53) -> 40 | W20: =SUM(G50:G53) -> 2 | X20: =SUM(H50:H53) -> 1 | Y20: =SUM(I50:I53) -> 10 | Z20: =SUM(J50:J53) -> 3 | ... AF20: =SUM(P50:P53) -> 366
B21: 09.45 - 10.00 | C21: 34 | D21: 4 | E21: 3 | F21: 13 | G21: 0 | H21: 0 | I21: 4 | J21: 0 | K21: 0 | L21: 0 | M21: 44 | N21: 0 | O21: =SUM(C21:L21,N21) -> 58 | P21: =SUM(C21:N21) -> 102 | R21: 1800-1900 | S21: =SUM(C54:C57) -> 48 | T21: =SUM(D54:D57) -> 14 | U21: =SUM(E54:E57) -> 3 | V21: =SUM(F54:F57) -> 54 | W21: =SUM(G54:G57) -> 1 | X21: =SUM(H54:H57) -> 1 | Y21: =SUM(I54:I57) -> 14 | Z21: =SUM(J54:J57) -> 1 | ... AF21: =SUM(P54:P57) -> 382
B22: 10.00 - 10.15 | C22: 26 | D22: 4 | E22: 5 | F22: 10 | G22: 1 | H22: 0 | I22: 4 | J22: 1 | K22: 0 | L22: 0 | M22: 63 | N22: 0 | O22: =SUM(C22:L22,N22) -> 51 | P22: =SUM(C22:N22) -> 114 | R22: AM Peak Hr | S22: =MAX(S10:S12) -> 289 | T22: =MAX(T10:T12) -> 18 | U22: =MAX(U10:U12) -> 24 | V22: =MAX(V10:V12) -> 127 | W22: =MAX(W10:W12) -> 1 | X22: =MAX(X10:X12) -> 0 | Y22: =MAX(Y10:Y12) -> 13 | Z22: =MAX(Z10:Z12) -> 6 | ... AF22: =MAX(AF10:AF12) -> 833
B23: 10.15 - 10.30 | C23: 18 | D23: 2 | E23: 1 | F23: 12 | G23: 0 | H23: 0 | I23: 5 | J23: 1 | K23: 1 | L23: 0 | M23: 29 | N23: 0 | O23: =SUM(C23:L23,N23) -> 40 | P23: =SUM(C23:N23) -> 69 | R23: IP Peak Hr | S23: =MAX(S13:S18) -> 62 | T23: =MAX(T13:T18) -> 20 | U23: =MAX(U13:U18) -> 12 | V23: =MAX(V13:V18) -> 38 | W23: =MAX(W13:W18) -> 1 | X23: =MAX(X13:X18) -> 1 | Y23: =MAX(Y13:Y18) -> 19 | Z23: =MAX(Z13:Z18) -> 7 | ... AF23: =MAX(AF13:AF18) -> 310
B24: 10.30 - 10.45 | C24: 9 | D24: 4 | E24: 2 | F24: 10 | G24: 0 | H24: 0 | I24: 5 | J24: 0 | K24: 0 | L24: 0 | M24: 40 | N24: 0 | O24: =SUM(C24:L24,N24) -> 30 | P24: =SUM(C24:N24) -> 70 | R24: PM Peak Hr | S24: =MAX(S19:S21) -> 49 | T24: =MAX(T19:T21) -> 17 | U24: =MAX(U19:U21) -> 7 | V24: =MAX(V19:V21) -> 54 | W24: =MAX(W19:W21) -> 2 | X24: =MAX(X19:X21) -> 1 | Y24: =MAX(Y19:Y21) -> 14 | Z24: =MAX(Z19:Z21) -> 5 | ... AF24: =MAX(AF19:AF21) -> 382
B25: 10.45 - 11.00 | C25: 9 | D25: 5 | E25: 4 | F25: 6 | G25: 0 | H25: 0 | I25: 1 | J25: 1 | K25: 0 | L25: 0 | M25: 31 | N25: 0 | O25: =SUM(C25:L25,N25) -> 26 | P25: =SUM(C25:N25) -> 57 | R25: AM Period | S25: =SUM(S10:S12) -> 577 | T25: =SUM(T10:T12) -> 45 | U25: =SUM(U10:U12) -> 53 | V25: =SUM(V10:V12) -> 231 | W25: =SUM(W10:W12) -> 1 | X25: =SUM(X10:X12) -> 0 | Y25: =SUM(Y10:Y12) -> 35 | Z25: =SUM(Z10:Z12) -> 12 | ... AF25: =SUM(AF10:AF12) -> 1978
B26: 11.00 - 11.15 | C26: 8 | D26: 4 | E26: 1 | F26: 5 | G26: 0 | H26: 0 | I26: 5 | J26: 0 | K26: 0 | L26: 0 | M26: 38 | N26: 0 | O26: =SUM(C26:L26,N26) -> 23 | P26: =SUM(C26:N26) -> 61 | R26: IP Period | S26: =SUM(S13:S18) -> 256 | T26: =SUM(T13:T18) -> 73 | U26: =SUM(U13:U18) -> 41 | V26: =SUM(V13:V18) -> 143 | W26: =SUM(W13:W18) -> 1 | X26: =SUM(X13:X18) -> 1 | Y26: =SUM(Y13:Y18) -> 95 | Z26: =SUM(Z13:Z18) -> 22 | ... AF26: =SUM(AF13:AF18) -> 1521
B27: 11.15 - 11.30 | C27: 7 | D27: 5 | E27: 4 | F27: 11 | G27: 0 | H27: 0 | I27: 4 | J27: 1 | K27: 4 | L27: 0 | M27: 33 | N27: 0 | O27: =SUM(C27:L27,N27) -> 36 | P27: =SUM(C27:N27) -> 69 | R27: PM Period | S27: =SUM(S19:S21) -> 137 | T27: =SUM(T19:T21) -> 39 | U27: =SUM(U19:U21) -> 15 | V27: =SUM(V19:V21) -> 109 | W27: =SUM(W19:W21) -> 3 | X27: =SUM(X19:X21) -> 2 | Y27: =SUM(Y19:Y21) -> 34 | Z27: =SUM(Z19:Z21) -> 9 | ... AF27: =SUM(AF19:AF21) -> 1021
B28: 11.30 - 11.45 | C28: 12 | D28: 4 | E28: 5 | F28: 6 | G28: 0 | H28: 0 | I28: 2 | J28: 0 | K28: 1 | L28: 0 | M28: 43 | N28: 0 | O28: =SUM(C28:L28,N28) -> 30 | P28: =SUM(C28:N28) -> 73 | R28: 12 Hours | S28: =SUM(S10:S21) -> 970 | T28: =SUM(T10:T21) -> 157 | U28: =SUM(U10:U21) -> 109 | V28: =SUM(V10:V21) -> 483 | W28: =SUM(W10:W21) -> 5 | X28: =SUM(X10:X21) -> 3 | Y28: =SUM(Y10:Y21) -> 164 | Z28: =SUM(Z10:Z21) -> 43 | ... AF28: =SUM(AF10:AF21) -> 4520
B29: 11.45 - 12.00 | C29: 7 | D29: 7 | E29: 2 | F29: 6 | G29: 0 | H29: 0 | I29: 3 | J29: 1 | K29: 1 | L29: 1 | M29: 41 | N29: 0 | O29: =SUM(C29:L29,N29) -> 28 | P29: =SUM(C29:N29) -> 69
B30: 12.00 - 12.15 | C30: 20 | D30: 6 | E30: 3 | F30: 5 | G30: 0 | H30: 0 | I30: 4 | J30: 5 | K30: 1 | L30: 0 | M30: 46 | N30: 0 | O30: =SUM(C30:L30,N30) -> 44 | P30: =SUM(C30:N30) -> 90
B31: 12.15 - 12.30 | C31: 14 | D31: 2 | E31: 0 | F31: 0 | G31: 0 | H31: 0 | I31: 4 | J31: 0 | K31: 0 | L31: 0 | M31: 32 | N31: 0 | O31: =SUM(C31:L31,N31) -> 20 | P31: =SUM(C31:N31) -> 52
B32: 12.30 - 12.45 | C32: 8 | D32: 2 | E32: 2 | F32: 6 | G32: 0 | H32: 0 | I32: 5 | J32: 1 | K32: 1 | L32: 0 | M32: 31 | N32: 0 | O32: =SUM(C32:L32,N32) -> 25 | P32: =SUM(C32:N32) -> 56
B33: 12.45 - 13.00 | C33: 8 | D33: 1 | E33: 1 | F33: 3 | G33: 0 | H33: 0 | I33: 6 | J33: 1 | K33: 0 | L33: 0 | M33: 22 | N33: 0 | O33: =SUM(C33:L33,N33) -> 20 | P33: =SUM(C33:N33) -> 42
B34: 13.00 - 13.15 | C34: 9 | D34: 4 | E34: 0 | F34: 4 | G34: 0 | H34: 0 | I34: 3 | J34: 0 | K34: 0 | L34: 0 | M34: 40 | N34: 0 | O34: =SUM(C34:L34,N34) -> 20 | P34: =SUM(C34:N34) -> 60
B35: 13.15 - 13.30 | C35: 6 | D35: 1 | E35: 1 | F35: 4 | G35: 0 | H35: 0 | I35: 4 | J35: 1 | K35: 0 | L35: 0 | M35: 30 | N35: 0 | O35: =SUM(C35:L35,N35) -> 17 | P35: =SUM(C35:N35) -> 47
B36: 13.30 - 13.45 | C36: 7 | D36: 1 | E36: 0 | F36: 7 | G36: 0 | H36: 0 | I36: 2 | J36: 1 | K36: 0 | L36: 0 | M36: 15 | N36: 0 | O36: =SUM(C36:L36,N36) -> 18 | P36: =SUM(C36:N36) -> 33
B37: 13.45 - 14.00 | C37: 13 | D37: 0 | E37: 1 | F37: 0 | G37: 0 | H37: 0 | I37: 5 | J37: 1 | K37: 0 | L37: 0 | M37: 20 | N37: 0 | O37: =SUM(C37:L37,N37) -> 20 | P37: =SUM(C37:N37) -> 40
B38: 14.00 - 14.15 | C38: 6 | D38: 4 | E38: 1 | F38: 12 | G38: 0 | H38: 1 | I38: 4 | J38: 1 | K38: 0 | L38: 0 | M38: 40 | N38: 0 | O38: =SUM(C38:L38,N38) -> 29 | P38: =SUM(C38:N38) -> 69
B39: 14.15 - 14.30 | C39: 9 | D39: 1 | E39: 2 | F39: 3 | G39: 0 | H39: 0 | I39: 6 | J39: 1 | K39: 1 | L39: 0 | M39: 47 | N39: 0 | O39: =SUM(C39:L39,N39) -> 23 | P39: =SUM(C39:N39) -> 70
B40: 14.30 - 14.45 | C40: 13 | D40: 3 | E40: 2 | F40: 8 | G40: 0 | H40: 0 | I40: 3 | J40: 1 | K40: 0 | L40: 0 | M40: 46 | N40: 0 | O40: =SUM(C40:L40,N40) -> 30 | P40: =SUM(C40:N40) -> 76
... B57: 18.45 - 19.00 | C57: 12 | D57: 5 | E57: 1 | F57: 14 | G57: 0 | H57: 0 | I57: 3 | J57: 1 | K57: 0 | L57: 0 | M57: 59 | N57: 0 | O57: =SUM(C57:L57,N57) -> 36 | P57: =SUM(C57:N57) -> 95
B58: Totals | C58: =SUM(C10:C57) -> 970 | D58: =SUM(D10:D57) -> 157 | E58: =SUM(E10:E57) -> 109 | F58: =SUM(F10:F57) -> 483 | G58: =SUM(G10:G57) -> 5 | H58: =SUM(H10:H57) -> 3 | I58: =SUM(I10:I57) -> 164 | J58: =SUM(J10:J57) -> 43 | ... P58: =SUM(P10:P57) -> 4520
...

Sheet 23.07 Sentema RBT-Sentema
B1: Consultancy services for Preparation of Expressway Development Master Plan (EDMP) for Uganda
B2: MANUAL CLASSIFIED COUNT (MCC)
B3: ROAD NAME: | C3: MCC - C1 - STN15 - SENTEMA ROAD
C5: Date | D5: 23.07.19 | F5: Location | G5: Ku roofings | J5: Surveyor | K5: Naido Grace
C6: Dir. From | D6: ='22.07 SentemaRBT-Sentema'!D6:E6 -> Sentema RBT | F6: Dir. To | G6: Sentema | J6: Supervisor | K6: Isaac
B8: Time / Veh Type | R8: SUMMARY TRAFFIC VOLUMES
C9: 1. Car | D9: 2. Station Wagon | E9: 3. Pickups | F9: 4. Minibus, matatu | G9: 5. Medium bus | H9: 6. Large Bus | I9: 7. Light Truck | J9: 8. Medium Truck | K9: 9. Heavy truck | L9: 10. Truck Trailer | M9: 11. Motor cycles | N9: 12. Tractors | O9: Total Excl M/Cycles | P9: Total All | R9: Time | S9: 1. Car | T9: 2. Station Wagon | U9: 3. Pickups | V9: 4. Minibus, matatu | W9: 5. Medium bus | X9: 6. Large Bus | Y9: 7. Light Truck | Z9: 8. Medium Truck | AA9: 9. Heavy truck | AB9: 10. Truck Trailer | AC9: 11. Motorcycles | AD9: 12. Tractors, Graders | AE9: Total Excl M/ Cycles | AF9: Total All
B10: 07.00 - 07.15 | C10: 9 | D10: 1 | E10: 1 | F10: 4 | G10: 0 | H10: 0 | I10: 2 | J10: 1 | K10: 0 | L10: 1 | M10: 26 | N10: 0 | O10: =SUM(C10:L10,N10) -> 19 | P10: =SUM(C10:N10) -> 45 | R10: 0700-0800 | S10: =SUM(C10:C13) -> 47 | T10: =SUM(D10:D13) -> 7 | U10: =SUM(E10:E13) -> 4 | V10: =SUM(F10:F13) -> 33 | W10: =SUM(G10:G13) -> 1 | X10: =SUM(H10:H13) -> 0 | Y10: =SUM(I10:I13) -> 6 | Z10: =SUM(J10:J13) -> 10 | ... AF10: =SUM(P10:P13) -> 234
B11: 07.15 - 07.30 | C11: 13 | D11: 5 | E11: 0 | F11: 11 | G11: 1 | H11: 0 | I11: 1 | J11: 3 | K11: 0 | L11: 0 | M11: 36 | N11: 0 | O11: =SUM(C11:L11,N11) -> 34 | P11: =SUM(C11:N11) -> 70 | R11: 0800-0900 | S11: =SUM(C14:C17) -> 28 | T11: =SUM(D14:D17) -> 9 | U11: =SUM(E14:E17) -> 2 | V11: =SUM(F14:F17) -> 55 | W11: =SUM(G14:G17) -> 0 | X11: =SUM(H14:H17) -> 0 | Y11: =SUM(I14:I17) -> 6 | Z11: =SUM(J14:J17) -> 5 | ... AF11: =SUM(P14:P17) -> 274
B12: 07.30 - 07.45 | C12: 15 | D12: 1 | E12: 2 | F12: 10 | G12: 0 | H12: 0 | I12: 1 | J12: 3 | K12: 0 | L12: 0 | M12: 36 | N12: 0 | O12: =SUM(C12:L12,N12) -> 32 | P12: =SUM(C12:N12) -> 68 | R12: 0900-1000 | S12: =SUM(C18:C21) -> 31 | T12: =SUM(D18:D21) -> 6 | U12: =SUM(E18:E21) -> 7 | V12: =SUM(F18:F21) -> 53 | W12: =SUM(G18:G21) -> 0 | X12: =SUM(H18:H21) -> 1 | Y12: =SUM(I18:I21) -> 7 | Z12: =SUM(J18:J21) -> 5 | ... AF12: =SUM(P18:P21) -> 300
B13: 07.45 - 08.00 | C13: 10 | D13: 0 | E13: 1 | F13: 8 | G13: 0 | H13: 0 | I13: 2 | J13: 3 | K13: 0 | L13: 0 | M13: 27 | N13: 0 | O13: =SUM(C13:L13,N13) -> 24 | P13: =SUM(C13:N13) -> 51 | R13: 1000-1100 | S13: =SUM(C22:C25) -> 29 | T13: =SUM(D22:D25) -> 4 | U13: =SUM(E22:E25) -> 13 | V13: =SUM(F22:F25) -> 29 | W13: =SUM(G22:G25) -> 0 | X13: =SUM(H22:H25) -> 2 | Y13: =SUM(I22:I25) -> 17 | Z13: =SUM(J22:J25) -> 3 | ... AF13: =SUM(P22:P25) -> 272
B14: 08.00 - 08.15 | C14: 6 | D14: 3 | E14: 1 | F14: 20 | G14: 0 | H14: 0 | I14: 1 | J14: 3 | K14: 0 | L14: 0 | M14: 38 | N14: 0 | O14: =SUM(C14:L14,N14) -> 34 | P14: =SUM(C14:N14) -> 72 | R14: 1100-1200 | S14: =SUM(C26:C29) -> 32 | T14: =SUM(D26:D29) -> 10 | U14: =SUM(E26:E29) -> 9 | V14: =SUM(F26:F29) -> 26 | W14: =SUM(G26:G29) -> 0 | X14: =SUM(H26:H29) -> 0 | Y14: =SUM(I26:I29) -> 12 | Z14: =SUM(J26:J29) -> 9 | ... AF14: =SUM(P26:P29) -> 289
B15: 08.15 - 08.30 | C15: 7 | D15: 1 | E15: 0 | F15: 14 | G15: 0 | H15: 0 | I15: 0 | J15: 0 | K15: 0 | L15: 0 | M15: 39 | N15: 0 | O15: =SUM(C15:L15,N15) -> 22 | P15: =SUM(C15:N15) -> 61 | R15: 1200-1300 | S15: =SUM(C30:C33) -> 29 | T15: =SUM(D30:D33) -> 2 | U15: =SUM(E30:E33) -> 8 | V15: =SUM(F30:F33) -> 17 | W15: =SUM(G30:G33) -> 1 | X15: =SUM(H30:H33) -> 0 | Y15: =SUM(I30:I33) -> 14 | Z15: =SUM(J30:J33) -> 4 | ... AF15: =SUM(P30:P33) -> 266
B16: 08.30 - 08.45 | C16: 5 | D16: 1 | E16: 0 | F16: 10 | G16: 0 | H16: 0 | I16: 1 | J16: 1 | K16: 0 | L16: 0 | M16: 47 | N16: 0 | O16: =SUM(C16:L16,N16) -> 18 | P16: =SUM(C16:N16) -> 65 | R16: 1300-1400 | S16: =SUM(C34:C37) -> 39 | T16: =SUM(D34:D37) -> 4 | U16: =SUM(E34:E37) -> 5 | V16: =SUM(F34:F37) -> 25 | W16: =SUM(G34:G37) -> 1 | X16: =SUM(H34:H37) -> 0 | Y16: =SUM(I34:I37) -> 14 | Z16: =SUM(J34:J37) -> 4 | ... AF16: =SUM(P34:P37) -> 267
B17: 08.45 - 9.00 | C17: 10 | D17: 4 | E17: 1 | F17: 11 | G17: 0 | H17: 0 | I17: 4 | J17: 1 | K17: 1 | L17: 1 | M17: 43 | N17: 0 | O17: =SUM(C17:L17,N17) -> 33 | P17: =SUM(C17:N17) -> 76 | R17: 1400-1500 | S17: =SUM(C38:C41) -> 44 | T17: =SUM(D38:D41) -> 4 | U17: =SUM(E38:E41) -> 12 | V17: =SUM(F38:F41) -> 23 | W17: =SUM(G38:G41) -> 0 | X17: =SUM(H38:H41) -> 1 | Y17: =SUM(I38:I41) -> 12 | Z17: =SUM(J38:J41) -> 0 | ... AF17: =SUM(P38:P41) -> 257
B18: 09.00 - 09.15 | C18: 7 | D18: 1 | E18: 2 | F18: 17 | G18: 0 | H18: 0 | I18: 2 | J18: 2 | K18: 1 | L18: 1 | M18: 12 | N18: 0 | O18: =SUM(C18:L18,N18) -> 33 | P18: =SUM(C18:N18) -> 45 | R18: 1500-1600 | S18: =SUM(C42:C45) -> 35 | T18: =SUM(D42:D45) -> 8 | U18: =SUM(E42:E45) -> 11 | V18: =SUM(F42:F45) -> 28 | W18: =SUM(G42:G45) -> 0 | X18: =SUM(H42:H45) -> 0 | Y18: =SUM(I42:I45) -> 18 | Z18: =SUM(J42:J45) -> 3 | ... AF18: =SUM(P42:P45) -> 241
B19: 09.15 - 09.30 | C19: 9 | D19: 2 | E19: 2 | F19: 9 | G19: 0 | H19: 0 | I19: 1 | J19: 2 | K19: 0 | L19: 0 | M19: 60 | N19: 0 | O19: =SUM(C19:L19,N19) -> 25 | P19: =SUM(C19:N19) -> 85 | R19: 1600-1700 | S19: =SUM(C46:C49) -> 61 | T19: =SUM(D46:D49) -> 14 | U19: =SUM(E46:E49) -> 8 | V19: =SUM(F46:F49) -> 27 | W19: =SUM(G46:G49) -> 1 | X19: =SUM(H46:H49) -> 0 | Y19: =SUM(I46:I49) -> 11 | Z19: =SUM(J46:J49) -> 2 | ... AF19: =SUM(P46:P49) -> 279
B20: 09.30 - 09.45 | C20: 12 | D20: 1 | E20: 2 | F20: 10 | G20: 0 | H20: 1 | I20: 4 | J20: 1 | K20: 0 | L20: 0 | M20: 62 | N20: 0 | O20: =SUM(C20:L20,N20) -> 31 | P20: =SUM(C20:N20) -> 93 | R20: 1700-1800 | S20: =SUM(C50:C53) -> 107 | T20: =SUM(D50:D53) -> 20 | U20: =SUM(E50:E53) -> 8 | V20: =SUM(F50:F53) -> 39 | W20: =SUM(G50:G53) -> 0 | X20: =SUM(H50:H53) -> 0 | Y20: =SUM(I50:I53) -> 7 | Z20: =SUM(J50:J53) -> 0 | ... AF20: =SUM(P50:P53) -> 388
B21: 09.45 - 10.00 | C21: 3 | D21: 2 | E21: 1 | F21: 17 | G21: 0 | H21: 0 | I21: 0 | J21: 0 | K21: 0 | L21: 2 | M21: 52 | N21: 0 | O21: =SUM(C21:L21,N21) -> 25 | P21: =SUM(C21:N21) -> 77 | R21: 1800-1900 | S21: =SUM(C54:C57) -> 133 | T21: =SUM(D54:D57) -> 17 | U21: =SUM(E54:E57) -> 11 | V21: =SUM(F54:F57) -> 52 | W21: =SUM(G54:G57) -> 0 | X21: =SUM(H54:H57) -> 0 | Y21: =SUM(I54:I57) -> 15 | Z21: =SUM(J54:J57) -> 1 | ... AF21: =SUM(P54:P57) -> 469
B22: 10.00 - 10.15 | C22: 4 | D22: 2 | E22: 1 | F22: 10 | G22: 0 | H22: 2 | I22: 5 | J22: 0 | K22: 0 | L22: 2 | M22: 35 | N22: 0 | O22: =SUM(C22:L22,N22) -> 26 | P22: =SUM(C22:N22) -> 61 | R22: AM Peak Hr | S22: =MAX(S10:S12) -> 47 | T22: =MAX(T10:T12) -> 9 | U22: =MAX(U10:U12) -> 7 | V22: =MAX(V10:V12) -> 55 | W22: =MAX(W10:W12) -> 1 | X22: =MAX(X10:X12) -> 1 | Y22: =MAX(Y10:Y12) -> 7 | Z22: =MAX(Z10:Z12) -> 10 | ... AF22: =MAX(AF10:AF12) -> 300
B23: 10.15 - 10.30 | C23: 8 | D23: 1 | E23: 4 | F23: 9 | G23: 0 | H23: 0 | I23: 4 | J23: 1 | K23: 0 | L23: 0 | M23: 41 | N23: 0 | O23: =SUM(C23:L23,N23) -> 27 | P23: =SUM(C23:N23) -> 68 | R23: IP Peak Hr | S23: =MAX(S13:S18) -> 44 | T23: =MAX(T13:T18) -> 10 | U23: =MAX(U13:U18) -> 13 | V23: =MAX(V13:V18) -> 29 | W23: =MAX(W13:W18) -> 1 | X23: =MAX(X13:X18) -> 2 | Y23: =MAX(Y13:Y18) -> 18 | Z23: =MAX(Z13:Z18) -> 9 | ... AF23: =MAX(AF13:AF18) -> 289
B24: 10.30 - 10.45 | C24: 5 | D24: 1 | E24: 3 | F24: 6 | G24: 0 | H24: 0 | I24: 5 | J24: 0 | K24: 0 | L24: 1 | M24: 56 | N24: 0 | O24: =SUM(C24:L24,N24) -> 21 | P24: =SUM(C24:N24) -> 77 | R24: PM Peak Hr | S24: =MAX(S19:S21) -> 133 | T24: =MAX(T19:T21) -> 20 | U24: =MAX(U19:U21) -> 11 | V24: =MAX(V19:V21) -> 52 | W24: =MAX(W19:W21) -> 1 | X24: =MAX(X19:X21) -> 0 | Y24: =MAX(Y19:Y21) -> 15 | Z24: =MAX(Z19:Z21) -> 2 | ... AF24: =MAX(AF19:AF21) -> 469
B25: 10.45 - 11.00 | C25: 12 | D25: 0 | E25: 5 | F25: 4 | G25: 0 | H25: 0 | I25: 3 | J25: 2 | K25: 0 | L25: 1 | M25: 39 | N25: 0 | O25: =SUM(C25:L25,N25) -> 27 | P25: =SUM(C25:N25) -> 66 | R25: AM Period | S25: =SUM(S10:S12) -> 106 | T25: =SUM(T10:T12) -> 22 | U25: =SUM(U10:U12) -> 13 | V25: =SUM(V10:V12) -> 141 | W25: =SUM(W10:W12) -> 1 | X25: =SUM(X10:X12) -> 1 | Y25: =SUM(Y10:Y12) -> 19 | Z25: =SUM(Z10:Z12) -> 20 | ... AF25: =SUM(AF10:AF12) -> 808
B26: 11.00 - 11.15 | C26: 8 | D26: 2 | E26: 0 | F26: 6 | G26: 0 | H26: 0 | I26: 3 | J26: 4 | K26: 0 | L26: 0 | M26: 45 | N26: 0 | O26: =SUM(C26:L26,N26) -> 23 | P26: =SUM(C26:N26) -> 68 | R26: IP Period | S26: =SUM(S13:S18) -> 208 | T26: =SUM(T13:T18) -> 32 | U26: =SUM(U13:U18) -> 58 | V26: =SUM(V13:V18) -> 148 | W26: =SUM(W13:W18) -> 2 | X26: =SUM(X13:X18) -> 3 | Y26: =SUM(Y13:Y18) -> 87 | Z26: =SUM(Z13:Z18) -> 23 | ... AF26: =SUM(AF13:AF18) -> 1592
B27: 11.15 - 11.30 | C27: 10 | D27: 1 | E27: 3 | F27: 9 | G27: 0 | H27: 0 | I27: 2 | J27: 2 | K27: 0 | L27: 0 | M27: 48 | N27: 0 | O27: =SUM(C27:L27,N27) -> 27 | P27: =SUM(C27:N27) -> 75 | R27: PM Period | S27: =SUM(S19:S21) -> 301 | T27: =SUM(T19:T21) -> 51 | U27: =SUM(U19:U21) -> 27 | V27: =SUM(V19:V21) -> 118 | W27: =SUM(W19:W21) -> 1 | X27: =SUM(X19:X21) -> 0 | Y27: =SUM(Y19:Y21) -> 33 | Z27: =SUM(Z19:Z21) -> 3 | ... AF27: =SUM(AF19:AF21) -> 1136
B28: 11.30 - 11.45 | C28: 9 | D28: 3 | E28: 3 | F28: 6 | G28: 0 | H28: 0 | I28: 3 | J28: 1 | K28: 1 | L28: 0 | M28: 51 | N28: 0 | O28: =SUM(C28:L28,N28) -> 26 | P28: =SUM(C28:N28) -> 77 | R28: 12 Hours | S28: =SUM(S10:S21) -> 615 | T28: =SUM(T10:T21) -> 105 | U28: =SUM(U10:U21) -> 98 | V28: =SUM(V10:V21) -> 407 | W28: =SUM(W10:W21) -> 4 | X28: =SUM(X10:X21) -> 4 | Y28: =SUM(Y10:Y21) -> 139 | Z28: =SUM(Z10:Z21) -> 46 | ... AF28: =SUM(AF10:AF21) -> 3536
B29: 11.45 - 12.00 | C29: 5 | D29: 4 | E29: 3 | F29: 5 | G29: 0 | H29: 0 | I29: 4 | J29: 2 | K29: 1 | L29: 0 | M29: 45 | N29: 0 | O29: =SUM(C29:L29,N29) -> 24 | P29: =SUM(C29:N29) -> 69
B30: 12.00 - 12.15 | C30: 3 | D30: 1 | E30: 4 | F30: 5 | G30: 0 | H30: 0 | I30: 6 | J30: 0 | K30: 0 | L30: 0 | M30: 42 | N30: 0 | O30: =SUM(C30:L30,N30) -> 19 | P30: =SUM(C30:N30) -> 61
B31: 12.15 - 12.30 | C31: 8 | D31: 0 | E31: 0 | F31: 8 | G31: 0 | H31: 0 | I31: 4 | J31: 2 | K31: 0 | L31: 0 | M31: 60 | N31: 0 | O31: =SUM(C31:L31,N31) -> 22 | P31: =SUM(C31:N31) -> 82
B32: 12.30 - 12.45 | C32: 9 | D32: 1 | E32: 1 | F32: 2 | G32: 0 | H32: 0 | I32: 0 | J32: 0 | K32: 0 | L32: 0 | M32: 40 | N32: 0 | O32: =SUM(C32:L32,N32) -> 13 | P32: =SUM(C32:N32) -> 53
B33: 12.45 - 13.00 | C33: 9 | D33: 0 | E33: 3 | F33: 2 | G33: 1 | H33: 0 | I33: 4 | J33: 2 | K33: 0 | L33: 0 | M33: 49 | N33: 0 | O33: =SUM(C33:L33,N33) -> 21 | P33: =SUM(C33:N33) -> 70
B34: 13.00 - 13.15 | C34: 7 | D34: 0 | E34: 3 | F34: 7 | G34: 0 | H34: 0 | I34: 6 | J34: 2 | K34: 0 | L34: 2 | M34: 51 | N34: 0 | O34: =SUM(C34:L34,N34) -> 27 | P34: =SUM(C34:N34) -> 78
B35: 13.15 - 13.30 | C35: 7 | D35: 2 | E35: 0 | F35: 5 | G35: 1 | H35: 0 | I35: 1 | J35: 1 | K35: 0 | L35: 0 | M35: 48 | N35: 0 | O35: =SUM(C35:L35,N35) -> 17 | P35: =SUM(C35:N35) -> 65
B36: 13.30 - 13.45 | C36: 20 | D36: 0 | E36: 1 | F36: 5 | G36: 0 | H36: 0 | I36: 7 | J36: 0 | K36: 0 | L36: 0 | M36: 41 | N36: 0 | O36: =SUM(C36:L36,N36) -> 33 | P36: =SUM(C36:N36) -> 74
B37: 13.45 - 14.00 | C37: 5 | D37: 2 | E37: 1 | F37: 8 | G37: 0 | H37: 0 | I37: 0 | J37: 1 | K37: 1 | L37: 2 | M37: 30 | N37: 0 | O37: =SUM(C37:L37,N37) -> 20 | P37: =SUM(C37:N37) -> 50
B38: 14.00 - 14.15 | C38: 11 | D38: 0 | E38: 4 | F38: 4 | G38: 0 | H38: 1 | I38: 3 | J38: 0 | K38: 0 | L38: 0 | M38: 39 | N38: 0 | O38: =SUM(C38:L38,N38) -> 23 | P38: =SUM(C38:N38) -> 62
B39: 14.15 - 14.30 | C39: 13 | D39: 1 | E39: 4 | F39: 9 | G39: 0 | H39: 0 | I39: 3 | J39: 0 | K39: 0 | L39: 0 | M39: 47 | N39: 0 | O39: =SUM(C39:L39,N39) -> 30 | P39: =SUM(C39:N39) -> 77
B40: 14.30 - 14.45 | C40: 9 | D40: 1 | E40: 1 | F40: 5 | G40: 0 | H40: 0 | I40: 3 | J40: 0 | K40: 0 | L40: 0 | M40: 39 | N40: 0 | O40: =SUM(C40:L40,N40) -> 19 | P40: =SUM(C40:N40) -> 58
... B57: 18.45 - 19.00 | C57: 29 | D57: 3 | E57: 2 | F57: 13 | G57: 0 | H57: 0 | I57: 6 | J57: 0 | K57: 1 | L57: 0 | M57: 59 | N57: 0 | O57: =SUM(C57:L57,N57) -> 54 | P57: =SUM(C57:N57) -> 113
B58: Totals | C58: =SUM(C10:C57) -> 615 | D58: =SUM(D10:D57) -> 105 | E58: =SUM(E10:E57) -> 98 | F58: =SUM(F10:F57) -> 407 | G58: =SUM(G10:G57) -> 4 | H58: =SUM(H10:H57) -> 4 | I58: =SUM(I10:I57) -> 139 | J58: =SUM(J10:J57) -> 46 | ... P58: =SUM(P10:P57) -> 3536
...

Sheet 23.07 Sentema-Sentema RBT
B1: Consultancy services for Preparation of Expressway Development Master Plan (EDMP) for Uganda
B2: MANUAL CLASSIFIED COUNT (MCC)
B3: ROAD NAME: | C3: MCC - C1 - STN15 - SENTEMA ROAD
C5: Date | D5: ='23.07 Sentema RBT-Sentema'!D5 -> 23.07.19 | F5: Location | G5: Ku roofings | J5: Surveyor | K5: Ngugo Hamuza
C6: Dir. From | D6: Sentema | F6: Dir. To | G6: ='22.07 Sentema-Sentema RBT'!G6:H6 -> Sentema RBT | J6: Supervisor | K6: Isaac
B8: Time / Veh Type | R8: SUMMARY TRAFFIC VOLUMES
C9: 1. Car | D9: 2. Station Wagon | E9: 3. Pickups | F9: 4. Minibus, matatu | G9: 5. Medium bus | H9: 6. Large Bus | I9: 7. Light Truck | J9: 8. Medium Truck | K9: 9. Heavy truck | L9: 10. Truck Trailer | M9: 11. Motor cycles | N9: 12. Tractors | O9: Total Excl M/Cycles | P9: Total All | R9: Time | S9: 1. Car | T9: 2. Station Wagon | U9: 3. Pickups | V9: 4. Minibus, matatu | W9: 5. Medium bus | X9: 6. Large Bus | Y9: 7. Light Truck | Z9: 8. Medium Truck | AA9: 9. Heavy truck | AB9: 10. Truck Trailer | AC9: 11. Motorcycles | AD9: 12. Tractors, Graders | AE9: Total Excl M/ Cycles | AF9: Total All
B10: 07.00 - 07.15 | C10: 70 | D10: 6 | E10: 2 | F10: 26 | G10: 0 | H10: 0 | I10: 1 | J10: 1 | K10: 2 | L10: 1 | M10: 95 | N10: 0 | O10: =SUM(C10:L10,N10) -> 109 | P10: =SUM(C10:N10) -> 204 | R10: 0700-0800 | S10: =SUM(C10:C13) -> 270 | T10: =SUM(D10:D13) -> 13 | U10: =SUM(E10:E13) -> 20 | V10: =SUM(F10:F13) -> 100 | W10: =SUM(G10:G13) -> 0 | X10: =SUM(H10:H13) -> 0 | Y10: =SUM(I10:I13) -> 6 | Z10: =SUM(J10:J13) -> 2 | ... AF10: =SUM(P10:P13) -> 783
B11: 07.15 - 07.30 | C11: 76 | D11: 1 | E11: 7 | F11: 21 | G11: 0 | H11: 0 | I11: 2 | J11: 0 | K11: 0 | L11: 0 | M11: 85 | N11: 0 | O11: =SUM(C11:L11,N11) -> 107 | P11: =SUM(C11:N11) -> 192 | R11: 0800-0900 | S11: =SUM(C14:C17) -> 179 | T11: =SUM(D14:D17) -> 24 | U11: =SUM(E14:E17) -> 16 | V11: =SUM(F14:F17) -> 111 | W11: =SUM(G14:G17) -> 0 | X11: =SUM(H14:H17) -> 0 | Y11: =SUM(I14:I17) -> 11 | Z11: =SUM(J14:J17) -> 9 | ... AF11: =SUM(P14:P17) -> 690
B12: 07.30 - 07.45 | C12: 68 | D12: 5 | E12: 6 | F12: 30 | G12: 0 | H12: 0 | I12: 3 | J12: 0 | K12: 0 | L12: 0 | M12: 111 | N12: 0 | O12: =SUM(C12:L12,N12) -> 112 | P12: =SUM(C12:N12) -> 223 | R12: 0900-1000 | S12: =SUM(C18:C21) -> 116 | T12: =SUM(D18:D21) -> 17 | U12: =SUM(E18:E21) -> 19 | V12: =SUM(F18:F21) -> 59 | W12: =SUM(G18:G21) -> 0 | X12: =SUM(H18:H21) -> 0 | Y12: =SUM(I18:I21) -> 10 | Z12: =SUM(J18:J21) -> 8 | ... AF12: =SUM(P18:P21) -> 473
B13: 07.45 - 08.00 | C13: 56 | D13: 1 | E13: 5 | F13: 23 | G13: 0 | H13: 0 | I13: 0 | J13: 1 | K13: 0 | L13: 0 | M13: 78 | N13: 0 | O13: =SUM(C13:L13,N13) -> 86 | P13: =SUM(C13:N13) -> 164 | R13: 1000-1100 | S13: =SUM(C22:C25) -> 69 | T13: =SUM(D22:D25) -> 6 | U13: =SUM(E22:E25) -> 13 | V13: =SUM(F22:F25) -> 40 | W13: =SUM(G22:G25) -> 0 | X13: =SUM(H22:H25) -> 0 | Y13: =SUM(I22:I25) -> 13 | Z13: =SUM(J22:J25) -> 12 | ... AF13: =SUM(P22:P25) -> 364
B14: 08.00 - 08.15 | C14: 68 | D14: 5 | E14: 7 | F14: 37 | G14: 0 | H14: 0 | I14: 3 | J14: 5 | K14: 1 | L14: 0 | M14: 112 | N14: 0 | O14: =SUM(C14:L14,N14) -> 126 | P14: =SUM(C14:N14) -> 238 | R14: 1100-1200 | S14: =SUM(C26:C29) -> 65 | T14: =SUM(D26:D29) -> 8 | U14: =SUM(E26:E29) -> 12 | V14: =SUM(F26:F29) -> 32 | W14: =SUM(G26:G29) -> 1 | X14: =SUM(H26:H29) -> 1 | Y14: =SUM(I26:I29) -> 7 | Z14: =SUM(J26:J29) -> 11 | ... AF14: =SUM(P26:P29) -> 403
B15: 08.15 - 08.30 | C15: 37 | D15: 7 | E15: 6 | F15: 37 | G15: 0 | H15: 0 | I15: 2 | J15: 2 | K15: 0 | L15: 0 | M15: 73 | N15: 0 | O15: =SUM(C15:L15,N15) -> 91 | P15: =SUM(C15:N15) -> 164 | R15: 1200-1300 | S15: =SUM(C30:C33) -> 41 | T15: =SUM(D30:D33) -> 8 | U15: =SUM(E30:E33) -> 11 | V15: =SUM(F30:F33) -> 27 | W15: =SUM(G30:G33) -> 0 | X15: =SUM(H30:H33) -> 1 | Y15: =SUM(I30:I33) -> 8 | Z15: =SUM(J30:J33) -> 9 | ... AF15: =SUM(P30:P33) -> 308
B16: 08.30 - 08.45 | C16: 39 | D16: 5 | E16: 2 | F16: 21 | G16: 0 | H16: 0 | I16: 2 | J16: 1 | K16: 0 | L16: 0 | M16: 62 | N16: 0 | O16: =SUM(C16:L16,N16) -> 70 | P16: =SUM(C16:N16) -> 132 | R16: 1300-1400 | S16: =SUM(C34:C37) -> 46 | T16: =SUM(D34:D37) -> 3 | U16: =SUM(E34:E37) -> 10 | V16: =SUM(F34:F37) -> 19 | W16: =SUM(G34:G37) -> 0 | X16: =SUM(H34:H37) -> 0 | Y16: =SUM(I34:I37) -> 18 | Z16: =SUM(J34:J37) -> 13 | ... AF16: =SUM(P34:P37) -> 308
B17: 08.45 - 9.00 | C17: 35 | D17: 7 | E17: 1 | F17: 16 | G17: 0 | H17: 0 | I17: 4 | J17: 1 | K17: 1 | L17: 0 | M17: 91 | N17: 0 | O17: =SUM(C17:L17,N17) -> 65 | P17: =SUM(C17:N17) -> 156 | R17: 1400-1500 | S17: =SUM(C38:C41) -> 50 | T17: =SUM(D38:D41) -> 5 | U17: =SUM(E38:E41) -> 13 | V17: =SUM(F38:F41) -> 24 | W17: =SUM(G38:G41) -> 1 | X17: =SUM(H38:H41) -> 0 | Y17: =SUM(I38:I41) -> 7 | Z17: =SUM(J38:J41) -> 8 | ... AF17: =SUM(P38:P41) -> 312
B18: 09.00 - 09.15 | C18: 28 | D18: 7 | E18: 7 | F18: 13 | G18: 0 | H18: 0 | I18: 1 | J18: 1 | K18: 0 | L18: 0 | M18: 76 | N18: 0 | O18: =SUM(C18:L18,N18) -> 57 | P18: =SUM(C18:N18) -> 133 | R18: 1500-1600 | S18: =SUM(C42:C45) -> 40 | T18: =SUM(D42:D45) -> 5 | U18: =SUM(E42:E45) -> 6 | V18: =SUM(F42:F45) -> 24 | W18: =SUM(G42:G45) -> 0 | X18: =SUM(H42:H45) -> 0 | Y18: =SUM(I42:I45) -> 15 | Z18: =SUM(J42:J45) -> 6 | ... AF18: =SUM(P42:P45) -> 261
B19: 09.15 - 09.30 | C19: 40 | D19: 1 | E19: 5 | F19: 18 | G19: 0 | H19: 0 | I19: 3 | J19: 2 | K19: 0 | L19: 0 | M19: 72 | N19: 0 | O19: =SUM(C19:L19,N19) -> 69 | P19: =SUM(C19:N19) -> 141 | R19: 1600-1700 | S19: =SUM(C46:C49) -> 43 | T19: =SUM(D46:D49) -> 6 | U19: =SUM(E46:E49) -> 11 | V19: =SUM(F46:F49) -> 23 | W19: =SUM(G46:G49) -> 1 | X19: =SUM(H46:H49) -> 1 | Y19: =SUM(I46:I49) -> 12 | Z19: =SUM(J46:J49) -> 3 | ... AF19: =SUM(P46:P49) -> 322
B20: 09.30 - 09.45 | C20: 17 | D20: 5 | E20: 2 | F20: 14 | G20: 0 | H20: 0 | I20: 3 | J20: 2 | K20: 1 | L20: 0 | M20: 58 | N20: 0 | O20: =SUM(C20:L20,N20) -> 44 | P20: =SUM(C20:N20) -> 102 | R20: 1700-1800 | S20: =SUM(C50:C53) -> 61 | T20: =SUM(D50:D53) -> 9 | U20: =SUM(E50:E53) -> 8 | V20: =SUM(F50:F53) -> 29 | W20: =SUM(G50:G53) -> 1 | X20: =SUM(H50:H53) -> 0 | Y20: =SUM(I50:I53) -> 8 | Z20: =SUM(J50:J53) -> 3 | ... AF20: =SUM(P50:P53) -> 359
B21: 09.45 - 10.00 | C21: 31 | D21: 4 | E21: 5 | F21: 14 | G21: 0 | H21: 0 | I21: 3 | J21: 3 | K21: 0 | L21: 0 | M21: 37 | N21: 0 | O21: =SUM(C21:L21,N21) -> 60 | P21: =SUM(C21:N21) -> 97 | R21: 1800-1900 | S21: =SUM(C54:C57) -> 47 | T21: =SUM(D54:D57) -> 6 | U21: =SUM(E54:E57) -> 9 | V21: =SUM(F54:F57) -> 48 | W21: =SUM(G54:G57) -> 1 | X21: =SUM(H54:H57) -> 1 | Y21: =SUM(I54:I57) -> 11 | Z21: =SUM(J54:J57) -> 0 | ... AF21: =SUM(P54:P57) -> 307
B22: 10.00 - 10.15 | C22: 9 | D22: 3 | E22: 3 | F22: 10 | G22: 0 | H22: 0 | I22: 3 | J22: 2 | K22: 0 | L22: 0 | M22: 44 | N22: 0 | O22: =SUM(C22:L22,N22) -> 30 | P22: =SUM(C22:N22) -> 74 | R22: AM Peak Hr | S22: =MAX(S10:S12) -> 270 | T22: =MAX(T10:T12) -> 24 | U22: =MAX(U10:U12) -> 20 | V22: =MAX(V10:V12) -> 111 | W22: =MAX(W10:W12) -> 0 | X22: =MAX(X10:X12) -> 0 | Y22: =MAX(Y10:Y12) -> 11 | Z22: =MAX(Z10:Z12) -> 9 | ... AF22: =MAX(AF10:AF12) -> 783
B23: 10.15 - 10.30 | C23: 21 | D23: 0 | E23: 6 | F23: 13 | G23: 0 | H23: 0 | I23: 3 | J23: 5 | K23: 0 | L23: 0 | M23: 61 | N23: 0 | O23: =SUM(C23:L23,N23) -> 48 | P23: =SUM(C23:N23) -> 109 | R23: IP Peak Hr | S23: =MAX(S13:S18) -> 69 | T23: =MAX(T13:T18) -> 8 | U23: =MAX(U13:U18) -> 13 | V23: =MAX(V13:V18) -> 40 | W23: =MAX(W13:W18) -> 1 | X23: =MAX(X13:X18) -> 1 | Y23: =MAX(Y13:Y18) -> 18 | Z23: =MAX(Z13:Z18) -> 13 | ... AF23: =MAX(AF13:AF18) -> 403
B24: 10.30 - 10.45 | C24: 23 | D24: 2 | E24: 2 | F24: 10 | G24: 0 | H24: 0 | I24: 2 | J24: 2 | K24: 1 | L24: 1 | M24: 61 | N24: 0 | O24: =SUM(C24:L24,N24) -> 43 | P24: =SUM(C24:N24) -> 104 | R24: PM Peak Hr | S24: =MAX(S19:S21) -> 61 | T24: =MAX(T19:T21) -> 9 | U24: =MAX(U19:U21) -> 11 | V24: =MAX(V19:V21) -> 48 | W24: =MAX(W19:W21) -> 1 | X24: =MAX(X19:X21) -> 1 | Y24: =MAX(Y19:Y21) -> 12 | Z24: =MAX(Z19:Z21) -> 3 | ... AF24: =MAX(AF19:AF21) -> 359
B25: 10.45 - 11.00 | C25: 16 | D25: 1 | E25: 2 | F25: 7 | G25: 0 | H25: 0 | I25: 5 | J25: 3 | K25: 1 | L25: 42 | M25: 0 | N25: 0 | O25: =SUM(C25:L25,N25) -> 77 | P25: =SUM(C25:N25) -> 77 | R25: AM Period | S25: =SUM(S10:S12) -> 565 | T25: =SUM(T10:T12) -> 54 | U25: =SUM(U10:U12) -> 55 | V25: =SUM(V10:V12) -> 270 | W25: =SUM(W10:W12) -> 0 | X25: =SUM(X10:X12) -> 0 | Y25: =SUM(Y10:Y12) -> 27 | Z25: =SUM(Z10:Z12) -> 19 | ... AF25: =SUM(AF10:AF12) -> 1946
B26: 11.00 - 11.15 | C26: 19 | D26: 2 | E26: 3 | F26: 7 | G26: 0 | H26: 0 | I26: 3 | J26: 2 | K26: 0 | L26: 1 | M26: 52 | N26: 0 | O26: =SUM(C26:L26,N26) -> 37 | P26: =SUM(C26:N26) -> 89 | R26: IP Period | S26: =SUM(S13:S18) -> 311 | T26: =SUM(T13:T18) -> 35 | U26: =SUM(U13:U18) -> 65 | V26: =SUM(V13:V18) -> 166 | W26: =SUM(W13:W18) -> 2 | X26: =SUM(X13:X18) -> 2 | Y26: =SUM(Y13:Y18) -> 68 | Z26: =SUM(Z13:Z18) -> 59 | ... AF26: =SUM(AF13:AF18) -> 1956
B27: 11.15 - 11.30 | C27: 11 | D27: 0 | E27: 1 | F27: 12 | G27: 1 | H27: 0 | I27: 0 | J27: 5 | K27: 0 | L27: 0 | M27: 83 | N27: 0 | O27: =SUM(C27:L27,N27) -> 30 | P27: =SUM(C27:N27) -> 113 | R27: PM Period | S27: =SUM(S19:S21) -> 151 | T27: =SUM(T19:T21) -> 21 | U27: =SUM(U19:U21) -> 28 | V27: =SUM(V19:V21) -> 100 | W27: =SUM(W19:W21) -> 3 | X27: =SUM(X19:X21) -> 2 | Y27: =SUM(Y19:Y21) -> 31 | Z27: =SUM(Z19:Z21) -> 6 | ... AF27: =SUM(AF19:AF21) -> 988
B28: 11.30 - 11.45 | C28: 13 | D28: 3 | E28: 6 | F28: 4 | G28: 0 | H28: 0 | I28: 3 | J28: 2 | K28: 0 | L28: 0 | M28: 62 | N28: 0 | O28: =SUM(C28:L28,N28) -> 31 | P28: =SUM(C28:N28) -> 93 | R28: 12 Hours | S28: =SUM(S10:S21) -> 1027 | T28: =SUM(T10:T21) -> 110 | U28: =SUM(U10:U21) -> 148 | V28: =SUM(V10:V21) -> 536 | W28: =SUM(W10:W21) -> 5 | X28: =SUM(X10:X21) -> 4 | Y28: =SUM(Y10:Y21) -> 126 | Z28: =SUM(Z10:Z21) -> 84 | ... AF28: =SUM(AF10:AF21) -> 4890
B29: 11.45 - 12.00 | C29: 22 | D29: 3 | E29: 2 | F29: 9 | G29: 0 | H29: 1 | I29: 1 | J29: 2 | K29: 0 | L29: 0 | M29: 68 | N29: 0 | O29: =SUM(C29:L29,N29) -> 40 | P29: =SUM(C29:N29) -> 108
B30: 12.00 - 12.15 | C30: 10 | D30: 5 | E30: 2 | F30: 7 | G30: 0 | H30: 0 | I30: 2 | J30: 4 | K30: 0 | L30: 0 | M30: 45 | N30: 0 | O30: =SUM(C30:L30,N30) -> 30 | P30: =SUM(C30:N30) -> 75
B31: 12.15 - 12.30 | C31: 13 | D31: 1 | E31: 2 | F31: 8 | G31: 0 | H31: 0 | I31: 2 | J31: 1 | K31: 1 | L31: 0 | M31: 47 | N31: 0 | O31: =SUM(C31:L31,N31) -> 28 | P31: =SUM(C31:N31) -> 75
B32: 12.30 - 12.45 | C32: 12 | D32: 0 | E32: 5 | F32: 5 | G32: 0 | H32: 1 | I32: 2 | J32: 2 | K32: 0 | L32: 0 | M32: 55 | N32: 0 | O32: =SUM(C32:L32,N32) -> 27 | P32: =SUM(C32:N32) -> 82
B33: 12.45 - 13.00 | C33: 6 | D33: 2 | E33: 2 | F33: 7 | G33: 0 | H33: 0 | I33: 2 | J33: 2 | K33: 0 | L33: 0 | M33: 55 | N33: 0 | O33: =SUM(C33:L33,N33) -> 21 | P33: =SUM(C33:N33) -> 76
B34: 13.00 - 13.15 | C34: 10 | D34: 1 | E34: 1 | F34: 5 | G34: 0 | H34: 0 | I34: 3 | J34: 3 | K34: 0 | L34: 0 | M34: 55 | N34: 0 | O34: =SUM(C34:L34,N34) -> 23 | P34: =SUM(C34:N34) -> 78
B35: 13.15 - 13.30 | C35: 17 | D35: 1 | E35: 2 | F35: 8 | G35: 0 | H35: 0 | I35: 3 | J35: 6 | K35: 0 | L35: 1 | M35: 57 | N35: 0 | O35: =SUM(C35:L35,N35) -> 38 | P35: =SUM(C35:N35) -> 95
B36: 13.30 - 13.45 | C36: 8 | D36: 1 | E36: 2 | F36: 4 | G36: 0 | H36: 0 | I36: 5 | J36: 2 | K36: 1 | L36: 0 | M36: 52 | N36: 0 | O36: =SUM(C36:L36,N36) -> 23 | P36: =SUM(C36:N36) -> 75
B37: 13.45 - 14.00 | C37: 11 | D37: 0 | E37: 5 | F37: 2 | G37: 0 | H37: 0 | I37: 7 | J37: 2 | K37: 1 | L37: 1 | M37: 31 | N37: 0 | O37: =SUM(C37:L37,N37) -> 29 | P37: =SUM(C37:N37) -> 60
B38: 14.00 - 14.15 | C38: 10 | D38: 0 | E38: 0 | F38: 4 | G38: 0 | H38: 0 | I38: 1 | J38: 1 | K38: 0 | L38: 0 | M38: 38 | N38: 0 | O38: =SUM(C38:L38,N38) -> 16 | P38: =SUM(C38:N38) -> 54
B39: 14.15 - 14.30 | C39: 15 | D39: 1 | E39: 4 | F39: 10 | G39: 1 | H39: 0 | I39: 3 | J39: 2 | K39: 1 | L39: 0 | M39: 47 | N39: 0 | O39: =SUM(C39:L39,N39) -> 37 | P39: =SUM(C39:N39) -> 84
B40: 14.30 - 14.45 | C40: 10 | D40: 4 | E40: 5 | F40: 4 | G40: 0 | H40: 0 | I40: 1 | J40: 3 | K40: 0 | L40: 0 | M40: 60 | N40: 0 | O40: =SUM(C40:L40,N40) -> 27 | P40: =SUM(C40:N40) -> 87
... B56: 18.30 - 18.45 | C56: 11 | D56: 1 | E56: 2 | F56: 9 | G56: 0 | H56: 0 | I56: 2 | J56: 0 | K56: 0 | L56: 0 | M56: 72 | N56: 0 | O56: =SUM(C56:L56,N56) -> 25 | P56: =SUM(C56:N56) -> 97
B57: 18.45 - 19.00 | C57: 13 | D57: 1 | E57: 3 | F57: 15 | G57: 0 | H57: 0 | I57: 2 | J57: 0 | K57: 0 | L57: 0 | M57: 68s | N57: 0 | O57: =SUM(C57:L57,N57) -> 34 | P57: =SUM(C57:N57) -> 34
...

Sheet 24.07 SentemaRBT-Sentema
B1: Consultancy services for Preparation of Expressway Development Master Plan (EDMP) for Uganda
B2: MANUAL CLASSIFIED COUNT (MCC)
B3: ROAD NAME: | C3: ='22.07 SentemaRBT-Sentema'!C3:G3 -> MCC - C1 - STN15 - SENTEMA ROAD
C5: Date | D5: 24.07.19 | F5: Location | G5: ='22.07 SentemaRBT-Sentema'!G5:H5 -> Ku roofings | J5: Surveyor | K5: Weere Junior
C6: Dir. From | D6: ='22.07 SentemaRBT-Sentema'!D6:E6 -> Sentema RBT | F6: Dir. To | G6: ='22.07 SentemaRBT-Sentema'!G6:H6 -> Sentema | J6: Supervisor | K6: ='22.07 SentemaRBT-Sentema'!K6:L6 -> Isaac
B8: Time / Veh Type | R8: SUMMARY TRAFFIC VOLUMES
C9: 1. Car | D9: 2. Station Wagon | E9: 3. Pickups | F9: 4. Minibus, matatu | G9: 5. Medium bus | H9: 6. Large Bus | I9: 7. Light Truck | J9: 8. Medium Truck | K9: 9. Heavy truck | L9: 10. Truck Trailer | M9: 11. Motor cycles | N9: 12. Tractors | O9: Total Excl M/Cycles | P9: Total All | R9: Time | S9: 1. Car | T9: 2. Station Wagon | U9: 3. Pickups | V9: 4. Minibus, matatu | W9: 5. Medium bus | X9: 6. Large Bus | Y9: 7. Light Truck | Z9: 8. Medium Truck | AA9: 9. Heavy truck | AB9: 10. Truck Trailer | AC9: 11. Motorcycles | AD9: 12. Tractors, Graders | AE9: Total Excl M/ Cycles | AF9: Total All
B10: 07.00 - 07.15 | C10: 3 | D10: 0 | E10: 1 | F10: 1 | G10: 0 | H10: 1 | I10: 1 | J10: 0 | K10: 1 | L10: 0 | M10: 23 | N10: 0 | O10: =SUM(C10:L10,N10) -> 8 | P10: =SUM(C10:N10) -> 31 | R10: 0700-0800 | S10: =SUM(C10:C13) -> 22 | T10: =SUM(D10:D13) -> 0 | U10: =SUM(E10:E13) -> 2 | V10: =SUM(F10:F13) -> 31 | W10: =SUM(G10:G13) -> 0 | X10: =SUM(H10:H13) -> 1 | Y10: =SUM(I10:I13) -> 8 | Z10: =SUM(J10:J13) -> 9 | ... AF10: =SUM(P10:P13) -> 229
B11: 07.15 - 07.30 | C11: 7 | D11: 0 | E11: 0 | F11: 4 | G11: 0 | H11: 0 | I11: 3 | J11: 2 | K11: 0 | L11: 0 | M11: 26 | N11: 0 | O11: =SUM(C11:L11,N11) -> 16 | P11: =SUM(C11:N11) -> 42 | R11: 0800-0900 | S11: =SUM(C14:C17) -> 49 | T11: =SUM(D14:D17) -> 8 | U11: =SUM(E14:E17) -> 5 | V11: =SUM(F14:F17) -> 52 | W11: =SUM(G14:G17) -> 1 | X11: =SUM(H14:H17) -> 3 | Y11: =SUM(I14:I17) -> 6 | Z11: =SUM(J14:J17) -> 8 | ... AF11: =SUM(P14:P17) -> 338
B12: 07.30 - 07.45 | C12: 3 | D12: 0 | E12: 0 | F12: 6 | G12: 0 | H12: 0 | I12: 0 | J12: 3 | K12: 0 | L12: 0 | M12: 50 | N12: 0 | O12: =SUM(C12:L12,N12) -> 12 | P12: =SUM(C12:N12) -> 62 | R12: 0900-1000 | S12: =SUM(C18:C21) -> 18 | T12: =SUM(D18:D21) -> 4 | U12: =SUM(E18:E21) -> 7 | V12: =SUM(F18:F21) -> 42 | W12: =SUM(G18:G21) -> 0 | X12: =SUM(H18:H21) -> 1 | Y12: =SUM(I18:I21) -> 10 | Z12: =SUM(J18:J21) -> 5 | ... AF12: =SUM(P18:P21) -> 280
B13: 07.45 - 08.00 | C13: 9 | D13: 0 | E13: 1 | F13: 20 | G13: 0 | H13: 0 | I13: 4 | J13: 4 | K13: 0 | L13: 0 | M13: 56 | N13: 0 | O13: =SUM(C13:L13,N13) -> 38 | P13: =SUM(C13:N13) -> 94 | R13: 1000-1100 | S13: =SUM(C22:C25) -> 25 | T13: =SUM(D22:D25) -> 5 | U13: =SUM(E22:E25) -> 8 | V13: =SUM(F22:F25) -> 40 | W13: =SUM(G22:G25) -> 0 | X13: =SUM(H22:H25) -> 0 | Y13: =SUM(I22:I25) -> 16 | Z13: =SUM(J22:J25) -> 6 | ... AF13: =SUM(P22:P25) -> 289
B14: 08.00 - 08.15 | C14: 10 | D14: 2 | E14: 1 | F14: 10 | G14: 1 | H14: 1 | I14: 3 | J14: 3 | K14: 0 | L14: 0 | M14: 41 | N14: 0 | O14: =SUM(C14:L14,N14) -> 31 | P14: =SUM(C14:N14) -> 72 | R14: 1100-1200 | S14: =SUM(C26:C29) -> 95 | T14: =SUM(D26:D29) -> 9 | U14: =SUM(E26:E29) -> 12 | V14: =SUM(F26:F29) -> 33 | W14: =SUM(G26:G29) -> 0 | X14: =SUM(H26:H29) -> 0 | Y14: =SUM(I26:I29) -> 21 | Z14: =SUM(J26:J29) -> 3 | ... AF14: =SUM(P26:P29) -> 437
B15: 08.15 - 08.30 | C15: 14 | D15: 1 | E15: 1 | F15: 15 | G15: 0 | H15: 0 | I15: 2 | J15: 1 | K15: 0 | L15: 0 | M15: 53 | N15: 0 | O15: =SUM(C15:L15,N15) -> 34 | P15: =SUM(C15:N15) -> 87 | R15: 1200-1300 | S15: =SUM(C30:C33) -> 33 | T15: =SUM(D30:D33) -> 8 | U15: =SUM(E30:E33) -> 4 | V15: =SUM(F30:F33) -> 23 | W15: =SUM(G30:G33) -> 8 | X15: =SUM(H30:H33) -> 0 | Y15: =SUM(I30:I33) -> 17 | Z15: =SUM(J30:J33) -> 8 | ... AF15: =SUM(P30:P33) -> 347
B16: 08.30 - 08.45 | C16: 11 | D16: 2 | E16: 2 | F16: 7 | G16: 0 | H16: 0 | I16: 0 | J16: 4 | K16: 1 | L16: 0 | M16: 50 | N16: 0 | O16: =SUM(C16:L16,N16) -> 27 | P16: =SUM(C16:N16) -> 77 | R16: 1300-1400 | S16: =SUM(C34:C37) -> 25 | T16: =SUM(D34:D37) -> 10 | U16: =SUM(E34:E37) -> 9 | V16: =SUM(F34:F37) -> 24 | W16: =SUM(G34:G37) -> 0 | X16: =SUM(H34:H37) -> 0 | Y16: =SUM(I34:I37) -> 16 | Z16: =SUM(J34:J37) -> 7 | ... AF16: =SUM(P34:P37) -> 313
B17: 08.45 - 9.00 | C17: 14 | D17: 3 | E17: 1 | F17: 20 | G17: 0 | H17: 2 | I17: 1 | J17: 0 | K17: 0 | L17: 0 | M17: 61 | N17: 0 | O17: =SUM(C17:L17,N17) -> 41 | P17: =SUM(C17:N17) -> 102 | R17: 1400-1500 | S17: =SUM(C38:C41) -> 25 | T17: =SUM(D38:D41) -> 6 | U17: =SUM(E38:E41) -> 6 | V17: =SUM(F38:F41) -> 28 | W17: =SUM(G38:G41) -> 0 | X17: =SUM(H38:H41) -> 0 | Y17: =SUM(I38:I41) -> 16 | Z17: =SUM(J38:J41) -> 2 | ... AF17: =SUM(P38:P41) -> 269
B18: 09.00 - 09.15 | C18: 6 | D18: 3 | E18: 1 | F18: 14 | G18: 0 | H18: 0 | I18: 2 | J18: 3 | K18: 0 | L18: 0 | M18: 52 | N18: 0 | O18: =SUM(C18:L18,N18) -> 29 | P18: =SUM(C18:N18) -> 81 | R18: 1500-1600 | S18: =SUM(C42:C45) -> 37 | T18: =SUM(D42:D45) -> 8 | U18: =SUM(E42:E45) -> 4 | V18: =SUM(F42:F45) -> 31 | W18: =SUM(G42:G45) -> 0 | X18: =SUM(H42:H45) -> 0 | Y18: =SUM(I42:I45) -> 16 | Z18: =SUM(J42:J45) -> 4 | ... AF18: =SUM(P42:P45) -> 304
B19: 09.15 - 09.30 | C19: 7 | D19: 1 | E19: 3 | F19: 11 | G19: 0 | H19: 1 | I19: 4 | J19: 0 | K19: 0 | L19: 0 | M19: 42 | N19: 0 | O19: =SUM(C19:L19,N19) -> 27 | P19: =SUM(C19:N19) -> 69 | R19: 1600-1700 | S19: =SUM(C46:C49) -> 43 | T19: =SUM(D46:D49) -> 16 | U19: =SUM(E46:E49) -> 6 | V19: =SUM(F46:F49) -> 37 | W19: =SUM(G46:G49) -> 2 | X19: =SUM(H46:H49) -> 1 | Y19: =SUM(I46:I49) -> 13 | Z19: =SUM(J46:J49) -> 7 | ... AF19: =SUM(P46:P49) -> 348
B20: 09.30 - 09.45 | C20: 3 | D20: 0 | E20: 0 | F20: 7 | G20: 0 | H20: 0 | I20: 1 | J20: 0 | K20: 0 | L20: 0 | M20: 45 | N20: 0 | O20: =SUM(C20:L20,N20) -> 11 | P20: =SUM(C20:N20) -> 56 | R20: 1700-1800 | S20: =SUM(C50:C53) -> 86 | T20: =SUM(D50:D53) -> 18 | U20: =SUM(E50:E53) -> 16 | V20: =SUM(F50:F53) -> 43 | W20: =SUM(G50:G53) -> 3 | X20: =SUM(H50:H53) -> 0 | Y20: =SUM(I50:I53) -> 14 | Z20: =SUM(J50:J53) -> 6 | ... AF20: =SUM(P50:P53) -> 424
B21: 09.45 - 10.00 | C21: 2 | D21: 0 | E21: 3 | F21: 10 | G21: 0 | H21: 0 | I21: 3 | J21: 2 | K21: 0 | L21: 0 | M21: 54 | N21: 0 | O21: =SUM(C21:L21,N21) -> 20 | P21: =SUM(C21:N21) -> 74 | R21: 1800-1900 | S21: =SUM(C54:C57) -> 109 | T21: =SUM(D54:D57) -> 33 | U21: =SUM(E54:E57) -> 15 | V21: =SUM(F54:F57) -> 57 | W21: =SUM(G54:G57) -> 3 | X21: =SUM(H54:H57) -> 0 | Y21: =SUM(I54:I57) -> 11 | Z21: =SUM(J54:J57) -> 2 | ... AF21: =SUM(P54:P57) -> 459
B22: 10.00 - 10.15 | C22: 8 | D22: 2 | E22: 3 | F22: 13 | G22: 0 | H22: 0 | I22: 3 | J22: 1 | K22: 0 | L22: 0 | M22: 39 | N22: 0 | O22: =SUM(C22:L22,N22) -> 30 | P22: =SUM(C22:N22) -> 69 | R22: AM Peak Hr | S22: =MAX(S10:S12) -> 49 | T22: =MAX(T10:T12) -> 8 | U22: =MAX(U10:U12) -> 7 | V22: =MAX(V10:V12) -> 52 | W22: =MAX(W10:W12) -> 1 | X22: =MAX(X10:X12) -> 3 | Y22: =MAX(Y10:Y12) -> 10 | Z22: =MAX(Z10:Z12) -> 9 | ... AF22: =MAX(AF10:AF12) -> 338
B23: 10.15 - 10.30 | C23: 9 | D23: 1 | E23: 2 | F23: 4 | G23: 0 | H23: 0 | I23: 4 | J23: 1 | K23: 0 | L23: 0 | M23: 56 | N23: 0 | O23: =SUM(C23:L23,N23) -> 21 | P23: =SUM(C23:N23) -> 77 | R23: IP Peak Hr | S23: =MAX(S13:S18) -> 95 | T23: =MAX(T13:T18) -> 10 | U23: =MAX(U13:U18) -> 12 | V23: =MAX(V13:V18) -> 40 | W23: =MAX(W13:W18) -> 8 | X23: =MAX(X13:X18) -> 0 | Y23: =MAX(Y13:Y18) -> 21 | Z23: =MAX(Z13:Z18) -> 8 | ... AF23: =MAX(AF13:AF18) -> 437
B24: 10.30 - 10.45 | C24: 4 | D24: 2 | E24: 2 | F24: 9 | G24: 0 | H24: 0 | I24: 3 | J24: 1 | K24: 0 | L24: 0 | M24: 43 | N24: 0 | O24: =SUM(C24:L24,N24) -> 21 | P24: =SUM(C24:N24) -> 64 | R24: PM Peak Hr | S24: =MAX(S19:S21) -> 109 | T24: =MAX(T19:T21) -> 33 | U24: =MAX(U19:U21) -> 16 | V24: =MAX(V19:V21) -> 57 | W24: =MAX(W19:W21) -> 3 | X24: =MAX(X19:X21) -> 1 | Y24: =MAX(Y19:Y21) -> 14 | Z24: =MAX(Z19:Z21) -> 7 | ... AF24: =MAX(AF19:AF21) -> 459
B25: 10.45 - 11.00 | C25: 4 | D25: 0 | E25: 1 | F25: 14 | G25: 0 | H25: 0 | I25: 6 | J25: 3 | K25: 0 | L25: 0 | M25: 51 | N25: 0 | O25: =SUM(C25:L25,N25) -> 28 | P25: =SUM(C25:N25) -> 79 | R25: AM Period | S25: =SUM(S10:S12) -> 89 | T25: =SUM(T10:T12) -> 12 | U25: =SUM(U10:U12) -> 14 | V25: =SUM(V10:V12) -> 125 | W25: =SUM(W10:W12) -> 1 | X25: =SUM(X10:X12) -> 5 | Y25: =SUM(Y10:Y12) -> 24 | Z25: =SUM(Z10:Z12) -> 22 | ... AF25: =SUM(AF10:AF12) -> 847
B26: 11.00 - 11.15 | C26: 10 | D26: 1 | E26: 4 | F26: 6 | G26: 0 | H26: 0 | I26: 5 | J26: 0 | K26: 0 | L26: 0 | M26: 60 | N26: 0 | O26: =SUM(C26:L26,N26) -> 26 | P26: =SUM(C26:N26) -> 86 | R26: IP Period | S26: =SUM(S13:S18) -> 240 | T26: =SUM(T13:T18) -> 46 | U26: =SUM(U13:U18) -> 43 | V26: =SUM(V13:V18) -> 179 | W26: =SUM(W13:W18) -> 8 | X26: =SUM(X13:X18) -> 0 | Y26: =SUM(Y13:Y18) -> 102 | Z26: =SUM(Z13:Z18) -> 30 | ... AF26: =SUM(AF13:AF18) -> 1959
B27: 11.15 - 11.30 | C27: 61 | D27: 2 | E27: 4 | F27: 9 | G27: 0 | H27: 0 | I27: 5 | J27: 0 | K27: 0 | L27: 0 | M27: 81 | N27: 0 | O27: =SUM(C27:L27,N27) -> 81 | P27: =SUM(C27:N27) -> 162 | R27: PM Period | S27: =SUM(S19:S21) -> 238 | T27: =SUM(T19:T21) -> 67 | U27: =SUM(U19:U21) -> 37 | V27: =SUM(V19:V21) -> 137 | W27: =SUM(W19:W21) -> 8 | X27: =SUM(X19:X21) -> 1 | Y27: =SUM(Y19:Y21) -> 38 | Z27: =SUM(Z19:Z21) -> 15 | ... AF27: =SUM(AF19:AF21) -> 1231
B28: 11.30 - 11.45 | C28: 10 | D28: 4 | E28: 3 | F28: 7 | G28: 0 | H28: 0 | I28: 7 | J28: 1 | K28: 0 | L28: 0 | M28: 63 | N28: 0 | O28: =SUM(C28:L28,N28) -> 32 | P28: =SUM(C28:N28) -> 95 | R28: 12 Hours | S28: =SUM(S10:S21) -> 567 | T28: =SUM(T10:T21) -> 125 | U28: =SUM(U10:U21) -> 94 | V28: =SUM(V10:V21) -> 441 | W28: =SUM(W10:W21) -> 17 | X28: =SUM(X10:X21) -> 6 | Y28: =SUM(Y10:Y21) -> 164 | Z28: =SUM(Z10:Z21) -> 67 | ... AF28: =SUM(AF10:AF21) -> 4037
B29: 11.45 - 12.00 | C29: 14 | D29: 2 | E29: 1 | F29: 11 | G29: 0 | H29: 0 | I29: 4 | J29: 2 | K29: 0 | L29: 0 | M29: 60 | N29: 0 | O29: =SUM(C29:L29,N29) -> 34 | P29: =SUM(C29:N29) -> 94
B30: 12.00 - 12.15 | C30: 11 | D30: 1 | E30: 0 | F30: 7 | G30: 0 | H30: 0 | I30: 8 | J30: 0 | K30: 0 | L30: 0 | M30: 59 | N30: 0 | O30: =SUM(C30:L30,N30) -> 27 | P30: =SUM(C30:N30) -> 86
B31: 12.15 - 12.30 | C31: 10 | D31: 1 | E31: 3 | F31: 0 | G31: 7 | H31: 0 | I31: 0 | J31: 4 | K31: 1 | L31: 0 | M31: 67 | N31: 0 | O31: =SUM(C31:L31,N31) -> 26 | P31: =SUM(C31:N31) -> 93
