Workbook
Name Veh_Type: 'ARUA PARK'!$H$8:$H$81
Name zones: #REF!
Name Zones_Ndeke: #REF!

Sheet ARUA PARK
C1: Consultancy services for Preparation of Expressway Development Master Plan (EDMP) for Uganda
C2: Stated Preferance Survey
D4: Town | E4: ARUA | I4: Interviewer: | J4: NAMULI JULIET | N4: Supervisor: | O4: DENIS | R4: Coded By: | S4: RUTH K | W4: Chkd By: | X4: Deo B. M
B6: Date | C6: Time (24-h format) | D6: Veh_Reg_No. | E6: Driver or Passenger? D/P | F6: Mode No. | G6: Mode Description | H6: Veh_Type | I6: Veh_Type Desc | J6: Gender (M/F) | K6: Age Bracket No. | L6: Age Bracket Desc. | M6: Origin_Address | P6: Origin_Purpose | Q6: Origin-Purpose Desc | R6: Destination_Address | U6: Destination_Purpose | V6: Destination_Purpose Desc | W6: Journey_Purpose | X6: Cost of Trip (UGX) | Y6: Journey Dist (Km) | Z6: Journey Time (Hrs) | AA6: Profession No. | AB6: Profession Desc. | AC6: Monthly Income No. | AD6: Monthly Income | AE6: Rank of Issues NOT OK with Journey | AJ6: Would You Use Xpressways? Y/N | AK6: Pay How Much? (UGX) | AL6: Origin_Zone | AM6: Dest_Zone
M7: Village or Town | N7: District | O7: Country | R7: Village or Town | S7: District | T7: Country | AE7: Journey Time | AF7: Cost of Journey | AG7: Comfort | AH7: Safety | AI7: Reliability
B8: 43771 | C8: 0.39166667 | E8: D | F8: 2 | G8: =VLOOKUP(F8,Key!$A$17:$B$21,2,FALSE) -> Road Vehicle | H8: 9 | I8: =VLOOKUP(H8,Key!$A$2:$B$13,2,FALSE) -> Heavy truck | J8: M | K8: 2 | L8: =VLOOKUP(K8,Key!$A$24:$B$29,2,FALSE) -> 30-39 | M8: TOWN | N8: KAMPALA | O8: UGA | P8: 2 | Q8: =VLOOKUP(P8,Key!$E$2:$F$9,2,FALSE) -> Work | R8: TOWN | S8: HOIMA | T8: UGA | U8: 2 | V8: =VLOOKUP(U8,Key!$E$2:$F$9,2,FALSE) -> Work | W8: =Q8&"-"&V8 -> Work-Work | X8: 200000 | Y8: 200 | Z8: 3.5 | AA8: 6 | AB8: =VLOOKUP(AA8,Key!$C$20:$D$29,2,FALSE) -> Businessman | AC8: 4 | AD8: =VLOOKUP(AC8,Key!$E$20:$F$24,2,FALSE) -> 750,000-1,000,000 | AE8: 3 | AF8: 4 | AG8: 5 | AH8: 1 | AI8: 2 | AJ8: Y | AK8: 3000
B9: 43771 | C9: 0.39444444 | E9: D | F9: 2 | G9: =VLOOKUP(F9,Key!$A$17:$B$21,2,FALSE) -> Road Vehicle | H9: 9 | I9: =VLOOKUP(H9,Key!$A$2:$B$13,2,FALSE) -> Heavy truck | J9: M | K9: 2 | L9: =VLOOKUP(K9,Key!$A$24:$B$29,2,FALSE) -> 30-39 | M9: KAMPALA | N9: KAMPALA | O9: UGA | P9: 1 | Q9: =VLOOKUP(P9,Key!$E$2:$F$9,2,FALSE) -> Home | R9: ARUA | S9: ARUA | T9: UGA | U9: 2 | V9: =VLOOKUP(U9,Key!$E$2:$F$9,2,FALSE) -> Work | W9: =Q9&"-"&V9 -> Home-Work | X9: 300000 | Y9: 500 | Z9: 8 | AA9: 5 | AB9: =VLOOKUP(AA9,Key!$C$20:$D$29,2,FALSE) -> Professional | AC9: 3 | AD9: =VLOOKUP(AC9,Key!$E$20:$F$24,2,FALSE) -> 500,000-750,000 | AE9: 4 | AF9: 3 | AG9: 1 | AH9: 2 | AI9: 5 | AJ9: Y | AK9: 5000
B10: 43771 | C10: 0.53263889 | E10: D | F10: 2 | G10: =VLOOKUP(F10,Key!$A$17:$B$21,2,FALSE) -> Road Vehicle | H10: 9 | I10: =VLOOKUP(H10,Key!$A$2:$B$13,2,FALSE) -> Heavy truck | J10: M | K10: 2 | L10: =VLOOKUP(K10,Key!$A$24:$B$29,2,FALSE) -> 30-39 | M10: KAMPALA | N10: KAMPALA | O10: UGA | P10: 1 | Q10: =VLOOKUP(P10,Key!$E$2:$F$9,2,FALSE) -> Home | R10: KANONI | S10: KANONI | T10: UGA | U10: 2 | V10: =VLOOKUP(U10,Key!$E$2:$F$9,2,FALSE) -> Work | W10: =Q10&"-"&V10 -> Home-Work | X10: 65000 | Y10: 94 | Z10: 3 | AA10: 5 | AB10: =VLOOKUP(AA10,Key!$C$20:$D$29,2,FALSE) -> Professional | AC10: 3 | AD10: =VLOOKUP(AC10,Key!$E$20:$F$24,2,FALSE) -> 500,000-750,000 | AE10: 3 | AF10: 2 | AG10: 1 | AH10: 4 | AI10: 5 | AJ10: Y | AK10: 5000
B11: 43771 | C11: 0.64930556 | E11: D | F11: 2 | G11: =VLOOKUP(F11,Key!$A$17:$B$21,2,FALSE) -> Road Vehicle | H11: 9 | I11: =VLOOKUP(H11,Key!$A$2:$B$13,2,FALSE) -> Heavy truck | J11: M | K11: 3 | L11: =VLOOKUP(K11,Key!$A$24:$B$29,2,FALSE) -> 40-49 | M11: TOWN | N11: KAMPALA | O11: UGA | P11: 2 | Q11: =VLOOKUP(P11,Key!$E$2:$F$9,2,FALSE) -> Work | R11: TOWN | S11: MPIGI | T11: UGA | U11: 2 | V11: =VLOOKUP(U11,Key!$E$2:$F$9,2,FALSE) -> Work | W11: =Q11&"-"&V11 -> Work-Work | X11: 80000 | AA11: 6 | AB11: =VLOOKUP(AA11,Key!$C$20:$D$29,2,FALSE) -> Businessman | AC11: 4 | AD11: =VLOOKUP(AC11,Key!$E$20:$F$24,2,FALSE) -> 750,000-1,000,000 | AE11: 1 | AF11: 4 | AG11: 5 | AH11: 2 | AI11: 3 | AJ11: Y | AK11: 4000
B12: 43771 | C12: 0.40208333 | E12: D | F12: 2 | G12: =VLOOKUP(F12,Key!$A$17:$B$21,2,FALSE) -> Road Vehicle | H12: 9 | I12: =VLOOKUP(H12,Key!$A$2:$B$13,2,FALSE) -> Heavy truck | J12: M | K12: 3 | L12: =VLOOKUP(K12,Key!$A$24:$B$29,2,FALSE) -> 40-49 | M12: KAMPALA | N12: KAMPALA | O12: UGA | P12: 1 | Q12: =VLOOKUP(P12,Key!$E$2:$F$9,2,FALSE) -> Home | R12: HOIMA | S12: HOIMA | T12: UGA | U12: 3 | V12: =VLOOKUP(U12,Key!$E$2:$F$9,2,FALSE) -> Study | W12: =Q12&"-"&V12 -> Home-Study | X12: 200000 | Y12: 200 | Z12: 4 | AA12: 5 | AB12: =VLOOKUP(AA12,Key!$C$20:$D$29,2,FALSE) -> Professional | AC12: 3 | AD12: =VLOOKUP(AC12,Key!$E$20:$F$24,2,FALSE) -> 500,000-750,000 | AE12: 4 | AF12: 3 | AG12: 2 | AH12: 1 | AI12: 5 | AJ12: Y | AK12: 200
B13: 43771 | C13: 0.44027778 | E13: D | F13: 2 | G13: =VLOOKUP(F13,Key!$A$17:$B$21,2,FALSE) -> Road Vehicle | H13: 9 | I13: =VLOOKUP(H13,Key!$A$2:$B$13,2,FALSE) -> Heavy truck | J13: M | K13: 3 | L13: =VLOOKUP(K13,Key!$A$24:$B$29,2,FALSE) -> 40-49 | M13: KAMPALA | N13: KAMPALA | O13: UGA | P13: 2 | Q13: =VLOOKUP(P13,Key!$E$2:$F$9,2,FALSE) -> Work | R13: MASAKA | S13: MASAKA | T13: UGA | U13: 1 | V13: =VLOOKUP(U13,Key!$E$2:$F$9,2,FALSE) -> Home | W13: =Q13&"-"&V13 -> Work-Home | X13: 100000 | Y13: 127 | Z13: 3 | AA13: 5 | AB13: =VLOOKUP(AA13,Key!$C$20:$D$29,2,FALSE) -> Professional | AC13: 4 | AD13: =VLOOKUP(AC13,Key!$E$20:$F$24,2,FALSE) -> 750,000-1,000,000 | AE13: 3 | AF13: 5 | AG13: 1 | AH13: 2 | AI13: 3 | AJ13: Y | AK13: 3000
B14: 43771 | C14: 0.53819444 | E14: D | F14: 2 | G14: =VLOOKUP(F14,Key!$A$17:$B$21,2,FALSE) -> Road Vehicle | H14: 9 | I14: =VLOOKUP(H14,Key!$A$2:$B$13,2,FALSE) -> Heavy truck | J14: M | K14: 3 | L14: =VLOOKUP(K14,Key!$A$24:$B$29,2,FALSE) -> 40-49 | M14: KAMPALA | N14: KAMPALA | O14: UGA | P14: 1 | Q14: =VLOOKUP(P14,Key!$E$2:$F$9,2,FALSE) -> Home | R14: KAKOGE | S14: LUWERO | T14: UGA | U14: 2 | V14: =VLOOKUP(U14,Key!$E$2:$F$9,2,FALSE) -> Work | W14: =Q14&"-"&V14 -> Home-Work | X14: 100000 | Y14: 62 | Z14: 2 | AA14: 5 | AB14: =VLOOKUP(AA14,Key!$C$20:$D$29,2,FALSE) -> Professional | AC14: 3 | AD14: =VLOOKUP(AC14,Key!$E$20:$F$24,2,FALSE) -> 500,000-750,000 | AE14: 5 | AF14: 2 | AG14: 1 | AH14: 3 | AI14: 4 | AJ14: Y
B15: 43771 | C15: 0.44375 | E15: D | F15: 2 | G15: =VLOOKUP(F15,Key!$A$17:$B$21,2,FALSE) -> Road Vehicle | H15: 9 | I15: =VLOOKUP(H15,Key!$A$2:$B$13,2,FALSE) -> Heavy truck | J15: M | K15: 4 | L15: =VLOOKUP(K15,Key!$A$24:$B$29,2,FALSE) -> 50-59 | M15: TOWN | N15: KAMPALA | O15: UGA | P15: 2 | Q15: =VLOOKUP(P15,Key!$E$2:$F$9,2,FALSE) -> Work | R15: TOWN | S15: KAMPALA | T15: UGA | U15: 2 | V15: =VLOOKUP(U15,Key!$E$2:$F$9,2,FALSE) -> Work | W15: =Q15&"-"&V15 -> Work-Work | X15: 280000 | Y15: 244 | Z15: 5 | AA15: 7 | AB15: =VLOOKUP(AA15,Key!$C$20:$D$29,2,FALSE) -> Farmer | AC15: 4 | AD15: =VLOOKUP(AC15,Key!$E$20:$F$24,2,FALSE) -> 750,000-1,000,000 | AE15: 8 | AF15: 3 | AG15: 1 | AH15: 2 | AI15: 4 | AJ15: Y | AK15: 2000
B16: 43771 | C16: 0.6125 | E16: D | F16: 2 | G16: =VLOOKUP(F16,Key!$A$17:$B$21,2,FALSE) -> Road Vehicle | H16: 9 | I16: =VLOOKUP(H16,Key!$A$2:$B$13,2,FALSE) -> Heavy truck | J16: M | K16: 4 | L16: =VLOOKUP(K16,Key!$A$24:$B$29,2,FALSE) -> 50-59 | M16: KAMPALA | N16: KAMPALA | O16: UGA | P16: 1 | Q16: =VLOOKUP(P16,Key!$E$2:$F$9,2,FALSE) -> Home | R16: MASAKA | S16: MASAKA | T16: UGA | U16: 2 | V16: =VLOOKUP(U16,Key!$E$2:$F$9,2,FALSE) -> Work | W16: =Q16&"-"&V16 -> Home-Work | X16: 130000 | Y16: 140 | Z16: 3 | AA16: 5 | AB16: =VLOOKUP(AA16,Key!$C$20:$D$29,2,FALSE) -> Professional | AC16: 4 | AD16: =VLOOKUP(AC16,Key!$E$20:$F$24,2,FALSE) -> 750,000-1,000,000 | AE16: 5 | AF16: 1 | AG16: 2 | AH16: 3 | AI16: 4 | AJ16: Y | AK16: 5000
B17: 43771 | C17: 0.45416667 | E17: D | F17: 2 | G17: =VLOOKUP(F17,Key!$A$17:$B$21,2,FALSE) -> Road Vehicle | H17: 9 | I17: =VLOOKUP(H17,Key!$A$2:$B$13,2,FALSE) -> Heavy truck | J17: M | K17: 4 | L17: =VLOOKUP(K17,Key!$A$24:$B$29,2,FALSE) -> 50-59 | M17: KAMPALA | N17: KAMPALA | O17: UGA | P17: 1 | Q17: =VLOOKUP(P17,Key!$E$2:$F$9,2,FALSE) -> Home | R17: GULU | S17: GULU | T17: UGA | U17: 2 | V17: =VLOOKUP(U17,Key!$E$2:$F$9,2,FALSE) -> Work | W17: =Q17&"-"&V17 -> Home-Work | X17: 280000 | Y17: 335 | Z17: 6 | AA17: 5 | AB17: =VLOOKUP(AA17,Key!$C$20:$D$29,2,FALSE) -> Professional | AC17: 3 | AD17: =VLOOKUP(AC17,Key!$E$20:$F$24,2,FALSE) -> 500,000-750,000 | AE17: 3 | AF17: 1 | AG17: 2 | AH17: 5 | AI17: 4 | AJ17: Y | AK17: 5000
B18: 43771 | C18: 0.65763889 | E18: D | F18: 2 | G18: =VLOOKUP(F18,Key!$A$17:$B$21,2,FALSE) -> Road Vehicle | H18: 9 | I18: =VLOOKUP(H18,Key!$A$2:$B$13,2,FALSE) -> Heavy truck | J18: M | K18: 4 | L18: =VLOOKUP(K18,Key!$A$24:$B$29,2,FALSE) -> 50-59 | M18: KAMPALA | N18: KAMPALA | O18: UGA | P18: 1 | Q18: =VLOOKUP(P18,Key!$E$2:$F$9,2,FALSE) -> Home | R18: JINJA | S18: JINJA | T18: UGA | U18: 2 | V18: =VLOOKUP(U18,Key!$E$2:$F$9,2,FALSE) -> Work | W18: =Q18&"-"&V18 -> Home-Work | X18: 70000 | Y18: 80 | Z18: 2.5 | AA18: 6 | AB18: =VLOOKUP(AA18,Key!$C$20:$D$29,2,FALSE) -> Businessman | AC18: 2 | AD18: =VLOOKUP(AC18,Key!$E$20:$F$24,2,FALSE) -> 300,000-500,000 | AE18: 5 | AF18: 1 | AG18: 2 | AH18: 3 | AI18: 4 | AJ18: Y | AK18: 5000
B19: 43771 | C19: 0.62013889 | E19: P | F19: 2 | G19: =VLOOKUP(F19,Key!$A$17:$B$21,2,FALSE) -> Road Vehicle | H19: 6 | I19: =VLOOKUP(H19,Key!$A$2:$B$13,2,FALSE) -> Large Bus | J19: F | K19: 2 | L19: =VLOOKUP(K19,Key!$A$24:$B$29,2,FALSE) -> 30-39 | M19: HOIMA | N19: HOIMA | O19: UGA | P19: 1 | Q19: =VLOOKUP(P19,Key!$E$2:$F$9,2,FALSE) -> Home | R19: TOWN | S19: KAMPALA | T19: UGA | U19: 1 | V19: =VLOOKUP(U19,Key!$E$2:$F$9,2,FALSE) -> Home | W19: =Q19&"-"&V19 -> Home-Home | X19: 15000 | Y19: 201 | Z19: 4 | AA19: 7 | AB19: =VLOOKUP(AA19,Key!$C$20:$D$29,2,FALSE) -> Farmer | AC19: 2 | AD19: =VLOOKUP(AC19,Key!$E$20:$F$24,2,FALSE) -> 300,000-500,000 | AE19: 3 | AF19: 5 | AG19: 4 | AH19: 2 | AI19: 1 | AJ19: Y | AK19: 1000
B20: 43771 | C20: 0.40833333 | E20: P | F20: 2 | G20: =VLOOKUP(F20,Key!$A$17:$B$21,2,FALSE) -> Road Vehicle | H20: 6 | I20: =VLOOKUP(H20,Key!$A$2:$B$13,2,FALSE) -> Large Bus | J20: F | K20: 2 | L20: =VLOOKUP(K20,Key!$A$24:$B$29,2,FALSE) -> 30-39 | M20: HOIMA | N20: HOIMA | O20: UGA | P20: 1 | Q20: =VLOOKUP(P20,Key!$E$2:$F$9,2,FALSE) -> Home | R20: KAMPALA | S20: KAMPALA | T20: UGA | U20: 2 | V20: =VLOOKUP(U20,Key!$E$2:$F$9,2,FALSE) -> Work | W20: =Q20&"-"&V20 -> Home-Work | X20: 15000 | Y20: 201 | Z20: 4.5 | AA20: 2 | AB20: =VLOOKUP(AA20,Key!$C$20:$D$29,2,FALSE) -> Manual Labour | AC20: 1 | AD20: =VLOOKUP(AC20,Key!$E$20:$F$24,2,FALSE) -> <300,000 | AE20: 3 | AF20: 2 | AG20: 1 | AH20: 5 | AI20: 4 | AJ20: Y
B21: 43771 | C21: 0.42361111 | E21: D | F21: 2 | G21: =VLOOKUP(F21,Key!$A$17:$B$21,2,FALSE) -> Road Vehicle | H21: 6 | I21: =VLOOKUP(H21,Key!$A$2:$B$13,2,FALSE) -> Large Bus | J21: M | K21: 2 | L21: =VLOOKUP(K21,Key!$A$24:$B$29,2,FALSE) -> 30-39 | M21: TOWN | N21: KAMPALA | O21: UGA | P21: 2 | Q21: =VLOOKUP(P21,Key!$E$2:$F$9,2,FALSE) -> Work | R21: TOWN | S21: KAMPALA | T21: UGA | U21: 2 | V21: =VLOOKUP(U21,Key!$E$2:$F$9,2,FALSE) -> Work | W21: =Q21&"-"&V21 -> Work-Work | X21: 100000 | Y21: 66 | Z21: 2 | AA21: 5 | AB21: =VLOOKUP(AA21,Key!$C$20:$D$29,2,FALSE) -> Professional | AC21: 3 | AD21: =VLOOKUP(AC21,Key!$E$20:$F$24,2,FALSE) -> 500,000-750,000 | AE21: 4 | AF21: 2 | AG21: 3 | AH21: 5 | AI21: 1 | AJ21: Y | AK21: 3000
B22: 43771 | C22: 0.39652778 | E22: P | F22: 2 | G22: =VLOOKUP(F22,Key!$A$17:$B$21,2,FALSE) -> Road Vehicle | H22: 6 | I22: =VLOOKUP(H22,Key!$A$2:$B$13,2,FALSE) -> Large Bus | J22: M | K22: 2 | L22: =VLOOKUP(K22,Key!$A$24:$B$29,2,FALSE) -> 30-39 | M22: TOWN | N22: KAMPALA | O22: UGA | P22: 1 | Q22: =VLOOKUP(P22,Key!$E$2:$F$9,2,FALSE) -> Home | R22: BUKWELI | S22: HOIMA | T22: UGA | U22: 2 | V22: =VLOOKUP(U22,Key!$E$2:$F$9,2,FALSE) -> Work | W22: =Q22&"-"&V22 -> Home-Work | X22: 15000 | Y22: 60 | Z22: 3 | AA22: 6 | AB22: =VLOOKUP(AA22,Key!$C$20:$D$29,2,FALSE) -> Businessman | AC22: 3 | AD22: =VLOOKUP(AC22,Key!$E$20:$F$24,2,FALSE) -> 500,000-750,000 | AJ22: Y | AK22: 1000
B23: 43771 | C23: 0.62708333 | E23: D | F23: 2 | G23: =VLOOKUP(F23,Key!$A$17:$B$21,2,FALSE) -> Road Vehicle | H23: 6 | I23: =VLOOKUP(H23,Key!$A$2:$B$13,2,FALSE) -> Large Bus | J23: M | K23: 2 | L23: =VLOOKUP(K23,Key!$A$24:$B$29,2,FALSE) -> 30-39 | M23: KAMPALA | N23: KAMPALA | O23: UGA | P23: 1 | Q23: =VLOOKUP(P23,Key!$E$2:$F$9,2,FALSE) -> Home | R23: HOIMA | S23: HOI MA | T23: UGA | U23: 2 | V23: =VLOOKUP(U23,Key!$E$2:$F$9,2,FALSE) -> Work | W23: =Q23&"-"&V23 -> Home-Work | X23: 200000 | Y23: 200 | Z23: 4 | AA23: 5 | AB23: =VLOOKUP(AA23,Key!$C$20:$D$29,2,FALSE) -> Professional | AC23: 4 | AD23: =VLOOKUP(AC23,Key!$E$20:$F$24,2,FALSE) -> 750,000-1,000,000 | AE23: 5 | AF23: 2 | AG23: 1 | AH23: 3 | AI23: 4 | AJ23: Y | AK23: 1000
B24: 43771 | C24: 0.64930556 | E24: P | F24: 2 | G24: =VLOOKUP(F24,Key!$A$17:$B$21,2,FALSE) -> Road Vehicle | H24: 6 | I24: =VLOOKUP(H24,Key!$A$2:$B$13,2,FALSE) -> Large Bus | J24: M | K24: 3 | L24: =VLOOKUP(K24,Key!$A$24:$B$29,2,FALSE) -> 40-49 | M24: KAMPALA | N24: KAMPALA | O24: UGA | P24: 1 | Q24: =VLOOKUP(P24,Key!$E$2:$F$9,2,FALSE) -> Home | R24: KAMULI | S24: KAMULI | T24: UGA | U24: 2 | V24: =VLOOKUP(U24,Key!$E$2:$F$9,2,FALSE) -> Work | W24: =Q24&"-"&V24 -> Home-Work | Y24: 141 | Z24: 3 | AA24: 6 | AB24: =VLOOKUP(AA24,Key!$C$20:$D$29,2,FALSE) -> Businessman | AC24: 3 | AD24: =VLOOKUP(AC24,Key!$E$20:$F$24,2,FALSE) -> 500,000-750,000 | AJ24: Y | AK24: 3000
B25: 43771 | C25: 0.45 | E25: D | F25: 2 | G25: =VLOOKUP(F25,Key!$A$17:$B$21,2,FALSE) -> Road Vehicle | H25: 6 | I25: =VLOOKUP(H25,Key!$A$2:$B$13,2,FALSE) -> Large Bus | J25: M | K25: 4 | L25: =VLOOKUP(K25,Key!$A$24:$B$29,2,FALSE) -> 50-59 | M25: KAMPALA | N25: KAMPALA | O25: UGA | P25: 1 | Q25: =VLOOKUP(P25,Key!$E$2:$F$9,2,FALSE) -> Home | R25: MASINDI | S25: MASINDI | T25: UGA | U25: 2 | V25: =VLOOKUP(U25,Key!$E$2:$F$9,2,FALSE) -> Work | W25: =Q25&"-"&V25 -> Home-Work | X25: 300000 | Y25: 213 | Z25: 5 | AA25: 5 | AB25: =VLOOKUP(AA25,Key!$C$20:$D$29,2,FALSE) -> Professional | AC25: 3 | AD25: =VLOOKUP(AC25,Key!$E$20:$F$24,2,FALSE) -> 500,000-750,000 | AE25: 3 | AF25: 2 | AG25: 1 | AH25: 4 | AI25: 5 | AJ25: Y | AK25: 1000
B26: 43771 | C26: 0.41388889 | E26: D | F26: 2 | G26: =VLOOKUP(F26,Key!$A$17:$B$21,2,FALSE) -> Road Vehicle | H26: 7 | I26: =VLOOKUP(H26,Key!$A$2:$B$13,2,FALSE) -> Light Truck | J26: M | K26: 2 | L26: =VLOOKUP(K26,Key!$A$24:$B$29,2,FALSE) -> 30-39 | M26: TOWN | N26: KAMPALA | O26: UGA | P26: 2 | Q26: =VLOOKUP(P26,Key!$E$2:$F$9,2,FALSE) -> Work | R26: WANTONI | S26: MUKONO | T26: UGA | U26: 2 | V26: =VLOOKUP(U26,Key!$E$2:$F$9,2,FALSE) -> Work | W26: =Q26&"-"&V26 -> Work-Work | X26: 40000 | Y26: 2.5 | Z26: 1.5 | AA26: 5 | AB26: =VLOOKUP(AA26,Key!$C$20:$D$29,2,FALSE) -> Professional | AC26: 3 | AD26: =VLOOKUP(AC26,Key!$E$20:$F$24,2,FALSE) -> 500,000-750,000 | AE26: 5 | AF26: 3 | AG26: 4 | AH26: 2 | AI26: 1 | AJ26: Y | AK26: 4000
B27: 43771 | C27: 0.50625 | E27: D | F27: 2 | G27: =VLOOKUP(F27,Key!$A$17:$B$21,2,FALSE) -> Road Vehicle | H27: 7 | I27: =VLOOKUP(H27,Key!$A$2:$B$13,2,FALSE) -> Light Truck | J27: M | K27: 2 | L27: =VLOOKUP(K27,Key!$A$24:$B$29,2,FALSE) -> 30-39 | M27: TOWN | N27: KAMPALA | O27: UGA | P27: 2 | Q27: =VLOOKUP(P27,Key!$E$2:$F$9,2,FALSE) -> Work | R27: KAJANSI | S27: WAKISO | T27: UGA | U27: 2 | V27: =VLOOKUP(U27,Key!$E$2:$F$9,2,FALSE) -> Work | W27: =Q27&"-"&V27 -> Work-Work | X27: 35000 | Y27: 17 | Z27: 1 | AA27: 5 | AB27: =VLOOKUP(AA27,Key!$C$20:$D$29,2,FALSE) -> Professional | AD27: =VLOOKUP(AC27,Key!$E$20:$F$24,2,FALSE) -> #N/A | AE27: 1 | AF27: 2 | AG27: 3 | AH27: 4 | AI27: 5 | AJ27: Y | AK27: 3000
B28: 43771 | C28: 0.57083333 | E28: D | F28: 2 | G28: =VLOOKUP(F28,Key!$A$17:$B$21,2,FALSE) -> Road Vehicle | H28: 7 | I28: =VLOOKUP(H28,Key!$A$2:$B$13,2,FALSE) -> Light Truck | J28: M | K28: 2 | L28: =VLOOKUP(K28,Key!$A$24:$B$29,2,FALSE) -> 30-39 | M28: KAMPALA | N28: KAMPALA | O28: UGA | P28: 1 | Q28: =VLOOKUP(P28,Key!$E$2:$F$9,2,FALSE) -> Home | R28: MBALE | S28: MBALE | T28: UGA | U28: 2 | V28: =VLOOKUP(U28,Key!$E$2:$F$9,2,FALSE) -> Work | W28: =Q28&"-"&V28 -> Home-Work | X28: 240000 | Y28: 256 | Z28: 5 | AA28: 5 | AB28: =VLOOKUP(AA28,Key!$C$20:$D$29,2,FALSE) -> Professional | AC28: 4 | AD28: =VLOOKUP(AC28,Key!$E$20:$F$24,2,FALSE) -> 750,000-1,000,000 | AE28: 3 | AF28: 2 | AG28: 1 | AH28: 5 | AI28: 4 | AJ28: Y | AK28: 3000
B29: 43771 | C29: 0.69722222 | E29: D | F29: 2 | G29: =VLOOKUP(F29,Key!$A$17:$B$21,2,FALSE) -> Road Vehicle | H29: 7 | I29: =VLOOKUP(H29,Key!$A$2:$B$13,2,FALSE) -> Light Truck | J29: M | K29: 2 | L29: =VLOOKUP(K29,Key!$A$24:$B$29,2,FALSE) -> 30-39 | M29: KAMPALA | N29: KAMPALA | O29: UGA | P29: 1 | Q29: =VLOOKUP(P29,Key!$E$2:$F$9,2,FALSE) -> Home | R29: KAGEGE | S29: NAKASEKE | T29: UGA | U29: 1 | V29: =VLOOKUP(U29,Key!$E$2:$F$9,2,FALSE) -> Home | W29: =Q29&"-"&V29 -> Home-Home | X29: 130000 | Y29: 150 | Z29: 4 | AA29: 5 | AB29: =VLOOKUP(AA29,Key!$C$20:$D$29,2,FALSE) -> Professional | AC29: 3 | AD29: =VLOOKUP(AC29,Key!$E$20:$F$24,2,FALSE) -> 500,000-750,000 | AE29: 3 | AF29: 1 | AG29: 5 | AH29: 2 | AI29: 4 | AJ29: Y | AK29: 4000
B30: 43771 | C30: 0.70972222 | E30: D | F30: 2 | G30: =VLOOKUP(F30,Key!$A$17:$B$21,2,FALSE) -> Road Vehicle | H30: 7 | I30: =VLOOKUP(H30,Key!$A$2:$B$13,2,FALSE) -> Light Truck | J30: M | K30: 2 | L30: =VLOOKUP(K30,Key!$A$24:$B$29,2,FALSE) -> 30-39 | M30: KAMPALA | N30: KAMPALA | O30: UGA | P30: 1 | Q30: =VLOOKUP(P30,Key!$E$2:$F$9,2,FALSE) -> Home | R30: MPIGI | S30: MPIGI | T30: UGA | U30: 2 | V30: =VLOOKUP(U30,Key!$E$2:$F$9,2,FALSE) -> Work | W30: =Q30&"-"&V30 -> Home-Work | X30: 5000 | Y30: 35 | Z30: 2 | AA30: 2 | AB30: =VLOOKUP(AA30,Key!$C$20:$D$29,2,FALSE) -> Manual Labour | AC30: 3 | AD30: =VLOOKUP(AC30,Key!$E$20:$F$24,2,FALSE) -> 500,000-750,000 | AE30: 3 | AF30: 1 | AG30: 2 | AH30: 5 | AI30: 4 | AJ30: Y | AK30: 5000
B31: 43771 | C31: 0.73541667 | E31: D | F31: 2 | G31: =VLOOKUP(F31,Key!$A$17:$B$21,2,FALSE) -> Road Vehicle | H31: 7 | I31: =VLOOKUP(H31,Key!$A$2:$B$13,2,FALSE) -> Light Truck | J31: M | K31: 2 | L31: =VLOOKUP(K31,Key!$A$24:$B$29,2,FALSE) -> 30-39 | M31: TOWN | N31: KAMPALA | O31: UGA | P31: 2 | Q31: =VLOOKUP(P31,Key!$E$2:$F$9,2,FALSE) -> Work | R31: TOWN | S31: KASESE | T31: UGA | U31: 2 | V31: =VLOOKUP(U31,Key!$E$2:$F$9,2,FALSE) -> Work | W31: =Q31&"-"&V31 -> Work-Work | X31: 300000 | Y31: 370 | Z31: 6 | AA31: 5 | AB31: =VLOOKUP(AA31,Key!$C$20:$D$29,2,FALSE) -> Professional | AC31: 4 | AD31: =VLOOKUP(AC31,Key!$E$20:$F$24,2,FALSE) -> 750,000-1,000,000 | AE31: 1 | AF31: 2 | AG31: 5 | AH31: 4 | AI31: 3 | AJ31: Y | AK31: 4000
B32: 43771 | C32: 0.46666667 | E32: D | F32: 2 | G32: =VLOOKUP(F32,Key!$A$17:$B$21,2,FALSE) -> Road Vehicle | H32: 7 | I32: =VLOOKUP(H32,Key!$A$2:$B$13,2,FALSE) -> Light Truck | J32: M | K32: 3 | L32: =VLOOKUP(K32,Key!$A$24:$B$29,2,FALSE) -> 40-49 | M32: KAMPALA | N32: KAMPALA | O32: UGA | P32: 1 | Q32: =VLOOKUP(P32,Key!$E$2:$F$9,2,FALSE) -> Home | R32: SOROTI | S32: SOROTI | T32: UGA | U32: 2 | V32: =VLOOKUP(U32,Key!$E$2:$F$9,2,FALSE) -> Work | W32: =Q32&"-"&V32 -> Home-Work | X32: 270000 | Y32: 323 | Z32: 5 | AA32: 5 | AB32: =VLOOKUP(AA32,Key!$C$20:$D$29,2,FALSE) -> Professional | AC32: 4 | AD32: =VLOOKUP(AC32,Key!$E$20:$F$24,2,FALSE) -> 750,000-1,000,000 | AE32: 5 | AF32: 4 | AG32: 1 | AH32: 2 | AI32: 3 | AJ32: Y | AK32: 3000
B33: 43771 | C33: 0.52916667 | E33: D | F33: 2 | G33: =VLOOKUP(F33,Key!$A$17:$B$21,2,FALSE) -> Road Vehicle | H33: 7 | I33: =VLOOKUP(H33,Key!$A$2:$B$13,2,FALSE) -> Light Truck | J33: M | K33: 3 | L33: =VLOOKUP(K33,Key!$A$24:$B$29,2,FALSE) -> 40-49 | M33: KAMPALA | N33: KAMPALA | O33: UGA | P33: 1 | Q33: =VLOOKUP(P33,Key!$E$2:$F$9,2,FALSE) -> Home | R33: BUWATE | S33: WAKISO | T33: UGA | U33: 2 | V33: =VLOOKUP(U33,Key!$E$2:$F$9,2,FALSE) -> Work | W33: =Q33&"-"&V33 -> Home-Work | X33: 15000 | Y33: 16 | Z33: 0.8 | AA33: 5 | AB33: =VLOOKUP(AA33,Key!$C$20:$D$29,2,FALSE) -> Professional | AC33: 4 | AD33: =VLOOKUP(AC33,Key!$E$20:$F$24,2,FALSE) -> 750,000-1,000,000 | AE33: 5 | AF33: 3 | AG33: 1 | AH33: 2 | AI33: 4 | AJ33: Y | AK33: 1000
B34: 43771 | C34: 0.60833333 | E34: D | F34: 2 | G34: =VLOOKUP(F34,Key!$A$17:$B$21,2,FALSE) -> Road Vehicle | H34: 7 | I34: =VLOOKUP(H34,Key!$A$2:$B$13,2,FALSE) -> Light Truck | J34: M | K34: 3 | L34: =VLOOKUP(K34,Key!$A$24:$B$29,2,FALSE) -> 40-49 | M34: KAMPALA | N34: KAMPALA | O34: UGA | P34: 1 | Q34: =VLOOKUP(P34,Key!$E$2:$F$9,2,FALSE) -> Home | R34: KAMULI | S34: KAMULI | T34: UGA | U34: 2 | V34: =VLOOKUP(U34,Key!$E$2:$F$9,2,FALSE) -> Work | W34: =Q34&"-"&V34 -> Home-Work | X34: 170000 | Y34: 140 | Z34: 3 | AA34: 5 | AB34: =VLOOKUP(AA34,Key!$C$20:$D$29,2,FALSE) -> Professional | AC34: 4 | AD34: =VLOOKUP(AC34,Key!$E$20:$F$24,2,FALSE) -> 750,000-1,000,000 | AE34: 5 | AF34: 2 | AG34: 1 | AH34: 3 | AI34: 4 | AJ34: Y | AK34: 5000
B35: 43771 | C35: 0.50069444 | E35: D | F35: 2 | G35: =VLOOKUP(F35,Key!$A$17:$B$21,2,FALSE) -> Road Vehicle | H35: 7 | I35: =VLOOKUP(H35,Key!$A$2:$B$13,2,FALSE) -> Light Truck | J35: M | K35: 5 | L35: =VLOOKUP(K35,Key!$A$24:$B$29,2,FALSE) -> 60-69 | M35: KAMPALA | N35: KAMPALA | O35: UGA | P35: 1 | Q35: =VLOOKUP(P35,Key!$E$2:$F$9,2,FALSE) -> Home | R35: LIRA | S35: LIRA | T35: UGA | U35: 2 | V35: =VLOOKUP(U35,Key!$E$2:$F$9,2,FALSE) -> Work | W35: =Q35&"-"&V35 -> Home-Work | X35: 280000 | Y35: 330 | Z35: 6 | AA35: 5 | AB35: =VLOOKUP(AA35,Key!$C$20:$D$29,2,FALSE) -> Professional | AC35: 4 | AD35: =VLOOKUP(AC35,Key!$E$20:$F$24,2,FALSE) -> 750,000-1,000,000 | AE35: 3 | AF35: 5 | AG35: 1 | AH35: 2 | AI35: 3 | AJ35: Y | AK35: 3000
B36: 43771 | C36: 0.49375 | E36: D | F36: 2 | G36: =VLOOKUP(F36,Key!$A$17:$B$21,2,FALSE) -> Road Vehicle | H36: 7 | I36: =VLOOKUP(H36,Key!$A$2:$B$13,2,FALSE) -> Light Truck | J36: M | K36: 5 | L36: =VLOOKUP(K36,Key!$A$24:$B$29,2,FALSE) -> 60-69 | M36: KAMPALA | N36: KAMPALA | O36: UGA | P36: 1 | Q36: =VLOOKUP(P36,Key!$E$2:$F$9,2,FALSE) -> Home | R36: SOROTI | S36: SOROTI | T36: UGA | U36: 2 | V36: =VLOOKUP(U36,Key!$E$2:$F$9,2,FALSE) -> Work | W36: =Q36&"-"&V36 -> Home-Work | X36: 240000 | Y36: 290 | Z36: 8 | AA36: 5 | AB36: =VLOOKUP(AA36,Key!$C$20:$D$29,2,FALSE) -> Professional | AC36: 4 | AD36: =VLOOKUP(AC36,Key!$E$20:$F$24,2,FALSE) -> 750,000-1,000,000 | AE36: 3 | AF36: 5 | AG36: 1 | AH36: 2 | AI36: 4 | AJ36: Y | AK36: 2000
B37: 43771 | C37: 0.58680556 | E37: P | F37: 2 | G37: =VLOOKUP(F37,Key!$A$17:$B$21,2,FALSE) -> Road Vehicle | H37: 5 | I37: =VLOOKUP(H37,Key!$A$2:$B$13,2,FALSE) -> Medium bus | J37: M | K37: 1 | L37: =VLOOKUP(K37,Key!$A$24:$B$29,2,FALSE) -> 20-29 | M37: KITIMBWA | N37: KAYUNGA | O37: UGA | P37: 1 | Q37: =VLOOKUP(P37,Key!$E$2:$F$9,2,FALSE) -> Home | R37: KAMPALA | S37: KAMPALA | T37: UGA | U37: 4 | V37: =VLOOKUP(U37,Key!$E$2:$F$9,2,FALSE) -> Commercial | W37: =Q37&"-"&V37 -> Home-Commercial | X37: 6000 | Y37: 36 | Z37: 2 | AA37: 6 | AB37: =VLOOKUP(AA37,Key!$C$20:$D$29,2,FALSE) -> Businessman | AC37: 3 | AD37: =VLOOKUP(AC37,Key!$E$20:$F$24,2,FALSE) -> 500,000-750,000 | AE37: 5 | AF37: 2 | AG37: 1 | AH37: 3 | AI37: 4 | AJ37: Y | AK37: 5000
B38: 43771 | C38: 0.59375 | E38: D | F38: 2 | G38: =VLOOKUP(F38,Key!$A$17:$B$21,2,FALSE) -> Road Vehicle | H38: 5 | I38: =VLOOKUP(H38,Key!$A$2:$B$13,2,FALSE) -> Medium bus | J38: M | K38: 1 | L38: =VLOOKUP(K38,Key!$A$24:$B$29,2,FALSE) -> 20-29 | M38: ARUA | N38: ARUA | O38: UGA | P38: 1 | Q38: =VLOOKUP(P38,Key!$E$2:$F$9,2,FALSE) -> Home | R38: KAMPALA | S38: KAMPALA | T38: UGA | U38: 4 | V38: =VLOOKUP(U38,Key!$E$2:$F$9,2,FALSE) -> Commercial | W38: =Q38&"-"&V38 -> Home-Commercial | X38: 300000 | Y38: 500 | Z38: 7 | AA38: 5 | AB38: =VLOOKUP(AA38,Key!$C$20:$D$29,2,FALSE) -> Professional | AC38: 2 | AD38: =VLOOKUP(AC38,Key!$E$20:$F$24,2,FALSE) -> 300,000-500,000 | AE38: 5 | AF38: 4 | AG38: 1 | AH38: 2 | AI38: 3 | AJ38: Y
B39: 43771 | C39: 0.47430556 | E39: D | F39: 2 | G39: =VLOOKUP(F39,Key!$A$17:$B$21,2,FALSE) -> Road Vehicle | H39: 5 | I39: =VLOOKUP(H39,Key!$A$2:$B$13,2,FALSE) -> Medium bus | J39: M | K39: 2 | L39: =VLOOKUP(K39,Key!$A$24:$B$29,2,FALSE) -> 30-39 | M39: KAMPALA | N39: KAMPALA | O39: UGA | P39: 1 | Q39: =VLOOKUP(P39,Key!$E$2:$F$9,2,FALSE) -> Home | R39: HOIMA | S39: HOIMA | T39: UGA | U39: 2 | V39: =VLOOKUP(U39,Key!$E$2:$F$9,2,FALSE) -> Work | W39: =Q39&"-"&V39 -> Home-Work | X39: 200000 | Y39: 201 | Z39: 4.5 | AA39: 5 | AB39: =VLOOKUP(AA39,Key!$C$20:$D$29,2,FALSE) -> Professional | AC39: 3 | AD39: =VLOOKUP(AC39,Key!$E$20:$F$24,2,FALSE) -> 500,000-750,000 | AE39: 3 | AF39: 1 | AG39: 5 | AH39: 2 | AI39: 4 | AJ39: Y | AK39: 3000
B40: 43771 | C40: 10:44 | E40: D | F40: 2 | G40: =VLOOKUP(F40,Key!$A$17:$B$21,2,FALSE) -> Road Vehicle | H40: 5 | I40: =VLOOKUP(H40,Key!$A$2:$B$13,2,FALSE) -> Medium bus | J40: M | K40: 3 | L40: =VLOOKUP(K40,Key!$A$24:$B$29,2,FALSE) -> 40-49 | M40: TOWN | N40: KAMPALA | O40: UGA | P40: 2 | Q40: =VLOOKUP(P40,Key!$E$2:$F$9,2,FALSE) -> Work | R40: MUKONO | S40: MUKONO | T40: UGA | U40: 2 | V40: =VLOOKUP(U40,Key!$E$2:$F$9,2,FALSE) -> Work | W40: =Q40&"-"&V40 -> Work-Work | X40: 70000 | Y40: 15 | Z40: 3 | AA40: 6 | AB40: =VLOOKUP(AA40,Key!$C$20:$D$29,2,FALSE) -> Businessman | AC40: 4 | AD40: =VLOOKUP(AC40,Key!$E$20:$F$24,2,FALSE) -> 750,000-1,000,000 | AE40: 3 | AF40: 4 | AG40: 5 | AH40: 2 | AI40: 1 | AJ40: Y | AK40: 2000
B41: 43771 | C41: 0.525 | E41: D | F41: 2 | G41: =VLOOKUP(F41,Key!$A$17:$B$21,2,FALSE) -> Road Vehicle | H41: 5 | I41: =VLOOKUP(H41,Key!$A$2:$B$13,2,FALSE) -> Medium bus | J41: M | K41: 3 | L41: =VLOOKUP(K41,Key!$A$24:$B$29,2,FALSE) -> 40-49 | M41: KAMPALA | N41: KAMPALA | O41: UGA | P41: 1 | Q41: =VLOOKUP(P41,Key!$E$2:$F$9,2,FALSE) -> Home | R41: MPIGI | S41: MPIGI | T41: UGA | U41: 2 | V41: =VLOOKUP(U41,Key!$E$2:$F$9,2,FALSE) -> Work | W41: =Q41&"-"&V41 -> Home-Work | X41: 40000 | Y41: 39 | Z41: 2 | AA41: 5 | AB41: =VLOOKUP(AA41,Key!$C$20:$D$29,2,FALSE) -> Professional | AC41: 3 | AD41: =VLOOKUP(AC41,Key!$E$20:$F$24,2,FALSE) -> 500,000-750,000 | AE41: 3 | AF41: 1 | AG41: 2 | AH41: 5 | AI41: 4 | AJ41: Y | AK41: 2000
B42: 43771 | C42: 0.40625 | E42: D | F42: 2 | G42: =VLOOKUP(F42,Key!$A$17:$B$21,2,FALSE) -> Road Vehicle | H42: 5 | I42: =VLOOKUP(H42,Key!$A$2:$B$13,2,FALSE) -> Medium bus | J42: M | K42: 4 | L42: =VLOOKUP(K42,Key!$A$24:$B$29,2,FALSE) -> 50-59 | M42: KAMPALA | N42: KAMPALA | O42: UGA | P42: 2 | Q42: =VLOOKUP(P42,Key!$E$2:$F$9,2,FALSE) -> Work | R42: KYEGWEGWA | S42: KYEGWEGWA | T42: UGA | U42: 2 | V42: =VLOOKUP(U42,Key!$E$2:$F$9,2,FALSE) -> Work | W42: =Q42&"-"&V42 -> Work-Work | X42: 165000 | Y42: 192 | Z42: 4 | AA42: 5 | AB42: =VLOOKUP(AA42,Key!$C$20:$D$29,2,FALSE) -> Professional | AC42: 4 | AD42: =VLOOKUP(AC42,Key!$E$20:$F$24,2,FALSE) -> 750,000-1,000,000 | AE42: 3 | AF42: 4 | AG42: 5 | AH42: 1 | AI42: 2 | AJ42: Y | AK42: 4000
...

Sheet RSI FORM
B1: Feasibility Study and Detailed Design of Kampala - Jinja Highway
B2: Roadside OD Interview Survey
B4: Date: | C4: 40465 | D4: Interviewer: | G4: Survey Station: | H4: Bweyogerere | J4: Direction: | K4: Bweyogerere-Kireka | L4: Coded By: | N4: Chkd By:
B7: Time Period | C7: Veh_Type | D7: Veh_Other | E7: Occupancy | F7: Origin_Address | H7: Origin_Purpose | I7: Origin_other | J7: Destination_Address | L7: Destination_Purpose | M7: Destination_Other | N7: Origin_Zone | O7: Dest_Zone | P7: WTP
F8: Village/Town | G8: City/Country | J8: Village/Town | K8: City/Country
B9: AM | C9: 3 | E9: 2 | F9: Entebbe | G9: Kla, Ug | H9: 1 | J9: Kla | K9: Kla, Ug | L9: 2 | N9: Blank | O9: Blank | P9: Yes | Q9: 3000
B10: AM | C10: 1 | E10: 1 | F10: Kiwanga | G10: Kla, Ug | H10: 1 | J10: Kla | K10: Kla, Ug | L10: 2 | N10: Blank | O10: Blank | P10: Yes | Q10: 2000
B11: AM | E11: 1 | F11: Bukoto | G11: Kla, Ug | H11: 3 | J11: Kla | K11: Kla, Ug | L11: 1 | N11: Blank | O11: Blank
B12: AM
B13: AM
B14: AM
B15: AM
B16: AM
B17: AM
B18: AM
B19: AM
B20: AM
B21: AM
B22: AM
B23: AM
... B53: AM

Sheet Key
B1: Vehicle Type | D1: Establishment Type | F1: Origin / Destination Purpose | H1: Trip Frequency | J1: Goods Type
A2: 1 | B2: Car | C2: 1 | D2: Residential | E2: 1 | F2: Home | G2: 1 | H2: more than 2 times every day | I2: 1 | J2: Food crop (Maize,rice,wheat etc)
A3: 2 | B3: Station Wagon | C3: 2 | D3: Office | E3: 2 | F3: Work | G3: 2 | H3: Daily (Up and Down) | I3: 2 | J3: Cash Crops (coffee,tea etc)
A4: 3 | B4: Pickups | C4: 3 | D4: Factory | E4: 3 | F4: Study | G4: 3 | H4: 2/3 times a week | I4: 3 | J4: Perishable (fish,milk,tea etc)
A5: 4 | B5: Minibus | C5: 4 | D5: Educational Facility | E5: 4 | F5: Commercial | G5: 4 | H5: Once a week | I5: 4 | J5: Construction Material (cement, gravel,stones,gravel,pipes)
A6: 5 | B6: Medium bus | C6: 5 | D6: Hospital | E6: 5 | F6: Tourism | G6: 5 | H6: Once a month | I6: 5 | J6: Metal/machinery
A7: 6 | B7: Large Bus | C7: 6 | D7: Bus / Taxi Park | E7: 6 | F7: Leisure/Social | G7: 6 | H7: Once in a while | I7: 6 | J7: Forestry products (timber & charcoal)
A8: 7 | B8: Light Truck | C8: 7 | D8: Wholesale shopping | E8: 7 | F8: Hospital | I8: 7 | J8: Fuels (any petroleum products)
A9: 8 | B9: Medium Truck | C9: 8 | D9: Boda boda stage | E9: 8 | F9: Others | I9: 8 | J9: Chemical Products (fertilizer,paints)
A10: 9 | B10: Heavy truck | C10: 9 | D10: Farm | I10: 9 | J10: Livestock (cows,goats,camel etc)
A11: 10 | B11: Truck Trailer | C11: 10 | D11: Construction Site | I11: 10 | J11: Household retail products (beverage,oil,sugar,salt,flour)
A12: 11 | B12: Motor cycles | C12: 11 | D12: Retail Shop/Market | I12: 11 | J12: Empty
A13: 12 | B13: Tractors | C13: 12 | D13: Warehouse | I13: 12 | J13: Others (Pl specify)
C14: 13 | D14: Harbour
C15: 14 | D15: Timber Centre
B16: Mode Number | C16: 15 | D16: Quarry
A17: 1 | B17: Walking/Cycling | C17: 16 | D17: Others (to be specified)
A18: 2 | B18: Road Vehicle
A19: 3 | B19: Rail | D19: Profession | F19: Monthly Income
A20: 4 | B20: Water/Ferry | C20: 1 | D20: Unemployed | E20: 1 | F20: <300,000
A21: 5 | B21: Air | C21: 2 | D21: Manual Labour | E21: 2 | F21: 300,000-500,000
C22: 3 | D22: Artisan/Domestic | E22: 3 | F22: 500,000-750,000
B23: Age Bracket No. | C23: 4 | D23: Office Worker | E23: 4 | F23: 750,000-1,000,000
A24: 1 | B24: 20-29 | C24: 5 | D24: Professional | E24: 5 | F24: >1,000,000
A25: 2 | B25: 30-39 | C25: 6 | D25: Businessman
A26: 3 | B26: 40-49 | C26: 7 | D26: Farmer
A27: 4 | B27: 50-59 | C27: 8 | D27: Student
A28: 5 | B28: 60-69 | C28: 9 | D28: Retired
A29: 6 | B29: 70- | C29: 10 | D29: Other
