Workbook

Sheet 25.10 MASAKA-MUTUKULA
B1: Consultancy services for Preparation of Expressway Development Master Plan (EDMP) for Uganda
B2: MANUAL CLASSIFIED COUNT (MCC)
B3: ROAD NAME: | C3: ='31.10 Masaka-Mutukula'!C3:G3 -> MCC - C4- STN99-MASAKA-MUTUKULA
C5: Date | D5: 25.10.19 | F5: Location | G5: ='26.10 MUTUKULA-MASAKA-24HR'!G5:H5 -> MUTUKULA | J5: Surveyor | K5: Steven
C6: Dir. From | D6: ='31.10 Masaka-Mutukula'!D6:E6 -> MASAKA | F6: Dir. To | G6: ='31.10 Masaka-Mutukula'!G6:H6 -> MUTUKULA | J6: Supervisor | K6: ='26.10 MUTUKULA-MASAKA-24HR'!K6:L6 -> SANDRA
B8: Time / Veh Type | R8: SUMMARY TRAFFIC VOLUMES
C9: 1. Car | D9: 2. Station Wagon | E9: 3. Pickups | F9: 4. Minibus, matatu | G9: 5. Medium bus | H9: 6. Large Bus | I9: 7. Light Truck | J9: 8. Medium Truck | K9: 9. Heavy truck | L9: 10. Truck Trailer | M9: 11. Motor cycles | N9: 12. Tractors | O9: Total Excl M/Cycles | P9: Total All | R9: Time | S9: 1. Car | T9: 2. Station Wagon | U9: 3. Pickups | V9: 4. Minibus, matatu | W9: 5. Medium bus | X9: 6. Large Bus | Y9: 7. Light Truck | Z9: 8. Medium Truck | AA9: 9. Heavy truck | AB9: 10. Truck Trailer | AC9: 11. Motorcycles | AD9: 12. Tractors, Graders | AE9: Total Excl M/ Cycles | AF9: Total All
B10: 07.00 - 07.15 | C10: 2 | D10: 0 | E10: 0 | F10: 2 | G10: 0 | H10: 0 | I10: 1 | J10: 0 | K10: 0 | L10: 0 | M10: 7 | N10: 0 | O10: =SUM(C10:L10,N10) -> 5 | P10: =SUM(C10:N10) -> 12 | R10: 0700-0800 | S10: =SUM(C10:C13) -> 12 | T10: =SUM(D10:D13) -> 0 | U10: =SUM(E10:E13) -> 0 | V10: =SUM(F10:F13) -> 6 | W10: =SUM(G10:G13) -> 0 | X10: =SUM(H10:H13) -> 0 | Y10: =SUM(I10:I13) -> 5 | Z10: =SUM(J10:J13) -> 0 | ... AF10: =SUM(P10:P13) -> 66
B11: 07.15 - 07.30 | C11: 4 | D11: 0 | E11: 0 | F11: 3 | G11: 0 | H11: 0 | I11: 1 | J11: 0 | K11: 0 | L11: 0 | M11: 15 | N11: 0 | O11: =SUM(C11:L11,N11) -> 8 | P11: =SUM(C11:N11) -> 23 | R11: 0800-0900 | S11: =SUM(C14:C17) -> 24 | T11: =SUM(D14:D17) -> 0 | U11: =SUM(E14:E17) -> 0 | V11: =SUM(F14:F17) -> 6 | W11: =SUM(G14:G17) -> 0 | X11: =SUM(H14:H17) -> 0 | Y11: =SUM(I14:I17) -> 11 | Z11: =SUM(J14:J17) -> 0 | ... AF11: =SUM(P14:P17) -> 126
B12: 07.30 - 07.45 | C12: 2 | D12: 0 | E12: 0 | F12: 0 | G12: 0 | H12: 0 | I12: 2 | J12: 0 | K12: 1 | L12: 0 | M12: 8 | N12: 0 | O12: =SUM(C12:L12,N12) -> 5 | P12: =SUM(C12:N12) -> 13 | R12: 0900-1000 | S12: =SUM(C18:C21) -> 8 | T12: =SUM(D18:D21) -> 0 | U12: =SUM(E18:E21) -> 1 | V12: =SUM(F18:F21) -> 7 | W12: =SUM(G18:G21) -> 0 | X12: =SUM(H18:H21) -> 0 | Y12: =SUM(I18:I21) -> 5 | Z12: =SUM(J18:J21) -> 2 | ... AF12: =SUM(P18:P21) -> 85
B13: 07.45 - 08.00 | C13: 4 | D13: 0 | E13: 0 | F13: 1 | G13: 0 | H13: 0 | I13: 1 | J13: 0 | K13: 0 | L13: 0 | M13: 12 | N13: 0 | O13: =SUM(C13:L13,N13) -> 6 | P13: =SUM(C13:N13) -> 18 | R13: 1000-1100 | S13: =SUM(C22:C25) -> 13 | T13: =SUM(D22:D25) -> 2 | U13: =SUM(E22:E25) -> 0 | V13: =SUM(F22:F25) -> 8 | W13: =SUM(G22:G25) -> 0 | X13: =SUM(H22:H25) -> 0 | Y13: =SUM(I22:I25) -> 13 | Z13: =SUM(J22:J25) -> 1 | ... AF13: =SUM(P22:P25) -> 112
B14: 08.00 - 08.15 | C14: 6 | D14: 0 | E14: 0 | F14: 0 | G14: 0 | H14: 0 | I14: 3 | J14: 0 | K14: 0 | L14: 0 | M14: 25 | N14: 0 | O14: =SUM(C14:L14,N14) -> 9 | P14: =SUM(C14:N14) -> 34 | R14: 1100-1200 | S14: =SUM(C26:C29) -> 12 | T14: =SUM(D26:D29) -> 0 | U14: =SUM(E26:E29) -> 1 | V14: =SUM(F26:F29) -> 9 | W14: =SUM(G26:G29) -> 0 | X14: =SUM(H26:H29) -> 0 | Y14: =SUM(I26:I29) -> 3 | Z14: =SUM(J26:J29) -> 1 | ... AF14: =SUM(P26:P29) -> 89
B15: 08.15 - 08.30 | C15: 7 | D15: 0 | E15: 0 | F15: 1 | G15: 0 | H15: 0 | I15: 4 | J15: 0 | K15: 0 | L15: 0 | M15: 20 | N15: 0 | O15: =SUM(C15:L15,N15) -> 12 | P15: =SUM(C15:N15) -> 32 | R15: 1200-1300 | S15: =SUM(C30:C33) -> 9 | T15: =SUM(D30:D33) -> 0 | U15: =SUM(E30:E33) -> 1 | V15: =SUM(F30:F33) -> 7 | W15: =SUM(G30:G33) -> 0 | X15: =SUM(H30:H33) -> 0 | Y15: =SUM(I30:I33) -> 4 | Z15: =SUM(J30:J33) -> 2 | ... AF15: =SUM(P30:P33) -> 80
B16: 08.30 - 08.45 | C16: 7 | D16: 0 | E16: 0 | F16: 3 | G16: 0 | H16: 0 | I16: 1 | J16: 0 | K16: 1 | L16: 0 | M16: 21 | N16: 0 | O16: =SUM(C16:L16,N16) -> 12 | P16: =SUM(C16:N16) -> 33 | R16: 1300-1400 | S16: =SUM(C34:C37) -> 13 | T16: =SUM(D34:D37) -> 0 | U16: =SUM(E34:E37) -> 0 | V16: =SUM(F34:F37) -> 9 | W16: =SUM(G34:G37) -> 0 | X16: =SUM(H34:H37) -> 0 | Y16: =SUM(I34:I37) -> 2 | Z16: =SUM(J34:J37) -> 0 | ... AF16: =SUM(P34:P37) -> 90
B17: 08.45 - 9.00 | C17: 4 | D17: 0 | E17: 0 | F17: 2 | G17: 0 | H17: 0 | I17: 3 | J17: 0 | K17: 2 | L17: 0 | M17: 16 | N17: 0 | O17: =SUM(C17:L17,N17) -> 11 | P17: =SUM(C17:N17) -> 27 | R17: 1400-1500 | S17: =SUM(C38:C41) -> 16 | T17: =SUM(D38:D41) -> 0 | U17: =SUM(E38:E41) -> 42 | V17: =SUM(F38:F41) -> 11 | W17: =SUM(G38:G41) -> 0 | X17: =SUM(H38:H41) -> 1 | Y17: =SUM(I38:I41) -> 4 | Z17: =SUM(J38:J41) -> 0 | ... AF17: =SUM(P38:P41) -> 128
B18: 09.00 - 09.15 | C18: 2 | D18: 0 | E18: 1 | F18: 2 | G18: 0 | H18: 0 | I18: 3 | J18: 0 | K18: 0 | L18: 0 | M18: 11 | N18: 0 | O18: =SUM(C18:L18,N18) -> 8 | P18: =SUM(C18:N18) -> 19 | R18: 1500-1600 | S18: =SUM(C42:C45) -> 13 | T18: =SUM(D42:D45) -> 0 | U18: =SUM(E42:E45) -> 5 | V18: =SUM(F42:F45) -> 7 | W18: =SUM(G42:G45) -> 0 | X18: =SUM(H42:H45) -> 0 | Y18: =SUM(I42:I45) -> 12 | Z18: =SUM(J42:J45) -> 1 | ... AF18: =SUM(P42:P45) -> 106
B19: 09.15 - 09.30 | C19: 4 | D19: 0 | E19: 0 | F19: 3 | G19: 0 | H19: 0 | I19: 1 | J19: 2 | K19: 1 | L19: 0 | M19: 14 | N19: 0 | O19: =SUM(C19:L19,N19) -> 11 | P19: =SUM(C19:N19) -> 25 | R19: 1600-1700 | S19: =SUM(C46:C49) -> 9 | T19: =SUM(D46:D49) -> 2 | U19: =SUM(E46:E49) -> 1 | V19: =SUM(F46:F49) -> 7 | W19: =SUM(G46:G49) -> 0 | X19: =SUM(H46:H49) -> 0 | Y19: =SUM(I46:I49) -> 3 | Z19: =SUM(J46:J49) -> 4 | ... AF19: =SUM(P46:P49) -> 99
B20: 09.30 - 09.45 | C20: 1 | D20: 0 | E20: 0 | F20: 2 | G20: 0 | H20: 0 | I20: 1 | J20: 0 | K20: 0 | L20: 0 | M20: 17 | N20: 0 | O20: =SUM(C20:L20,N20) -> 4 | P20: =SUM(C20:N20) -> 21 | R20: 1700-1800 | S20: =SUM(C50:C53) -> 18 | T20: =SUM(D50:D53) -> 0 | U20: =SUM(E50:E53) -> 2 | V20: =SUM(F50:F53) -> 7 | W20: =SUM(G50:G53) -> 0 | X20: =SUM(H50:H53) -> 0 | Y20: =SUM(I50:I53) -> 6 | Z20: =SUM(J50:J53) -> 0 | ... AF20: =SUM(P50:P53) -> 98
B21: 09.45 - 10.00 | C21: 1 | D21: 0 | E21: 0 | F21: 0 | G21: 0 | H21: 0 | I21: 0 | J21: 0 | K21: 0 | L21: 0 | M21: 19 | N21: 0 | O21: =SUM(C21:L21,N21) -> 1 | P21: =SUM(C21:N21) -> 20 | R21: 1800-1900 | S21: =SUM(C54:C57) -> 25 | T21: =SUM(D54:D57) -> 1 | U21: =SUM(E54:E57) -> 4 | V21: =SUM(F54:F57) -> 5 | W21: =SUM(G54:G57) -> 0 | X21: =SUM(H54:H57) -> 0 | Y21: =SUM(I54:I57) -> 3 | Z21: =SUM(J54:J57) -> 1 | ... AF21: =SUM(P54:P57) -> 132
B22: 10.00 - 10.15 | C22: 3 | D22: 1 | E22: 0 | F22: 1 | G22: 0 | H22: 0 | I22: 4 | J22: 0 | K22: 1 | L22: 0 | M22: 21 | N22: 0 | O22: =SUM(C22:L22,N22) -> 10 | P22: =SUM(C22:N22) -> 31 | R22: AM Peak Hr | S22: =MAX(S10:S12) -> 24 | T22: =MAX(T10:T12) -> 0 | U22: =MAX(U10:U12) -> 1 | V22: =MAX(V10:V12) -> 7 | W22: =MAX(W10:W12) -> 0 | X22: =MAX(X10:X12) -> 0 | Y22: =MAX(Y10:Y12) -> 11 | Z22: =MAX(Z10:Z12) -> 2 | ... AF22: =MAX(AF10:AF12) -> 126
B23: 10.15 - 10.30 | C23: 2 | D23: 0 | E23: 0 | F23: 2 | G23: 0 | H23: 0 | I23: 3 | J23: 0 | K23: 0 | L23: 0 | M23: 9 | N23: 0 | O23: =SUM(C23:L23,N23) -> 7 | P23: =SUM(C23:N23) -> 16 | R23: IP Peak Hr | S23: =MAX(S13:S18) -> 16 | T23: =MAX(T13:T18) -> 2 | U23: =MAX(U13:U18) -> 42 | V23: =MAX(V13:V18) -> 11 | W23: =MAX(W13:W18) -> 0 | X23: =MAX(X13:X18) -> 1 | Y23: =MAX(Y13:Y18) -> 13 | Z23: =MAX(Z13:Z18) -> 2 | ... AF23: =MAX(AF13:AF18) -> 128
B24: 10.30 - 10.45 | C24: 4 | D24: 1 | E24: 0 | F24: 3 | G24: 0 | H24: 0 | I24: 2 | J24: 0 | K24: 0 | L24: 0 | M24: 19 | N24: 0 | O24: =SUM(C24:L24,N24) -> 10 | P24: =SUM(C24:N24) -> 29 | R24: PM Peak Hr | S24: =MAX(S19:S21) -> 25 | T24: =MAX(T19:T21) -> 2 | U24: =MAX(U19:U21) -> 4 | V24: =MAX(V19:V21) -> 7 | W24: =MAX(W19:W21) -> 0 | X24: =MAX(X19:X21) -> 0 | Y24: =MAX(Y19:Y21) -> 6 | Z24: =MAX(Z19:Z21) -> 4 | ... AF24: =MAX(AF19:AF21) -> 132
B25: 10.45 - 11.00 | C25: 4 | D25: 0 | E25: 0 | F25: 2 | G25: 0 | H25: 0 | I25: 4 | J25: 1 | K25: 0 | L25: 0 | M25: 25 | N25: 0 | O25: =SUM(C25:L25,N25) -> 11 | P25: =SUM(C25:N25) -> 36 | R25: AM Period | S25: =SUM(S10:S12) -> 44 | T25: =SUM(T10:T12) -> 0 | U25: =SUM(U10:U12) -> 1 | V25: =SUM(V10:V12) -> 19 | W25: =SUM(W10:W12) -> 0 | X25: =SUM(X10:X12) -> 0 | Y25: =SUM(Y10:Y12) -> 21 | Z25: =SUM(Z10:Z12) -> 2 | ... AF25: =SUM(AF10:AF12) -> 277
B26: 11.00 - 11.15 | C26: 1 | D26: 0 | E26: 0 | F26: 5 | G26: 0 | H26: 0 | I26: 0 | J26: 0 | K26: 0 | L26: 0 | M26: 15 | N26: 0 | O26: =SUM(C26:L26,N26) -> 6 | P26: =SUM(C26:N26) -> 21 | R26: IP Period | S26: =SUM(S13:S18) -> 76 | T26: =SUM(T13:T18) -> 2 | U26: =SUM(U13:U18) -> 49 | V26: =SUM(V13:V18) -> 51 | W26: =SUM(W13:W18) -> 0 | X26: =SUM(X13:X18) -> 1 | Y26: =SUM(Y13:Y18) -> 38 | Z26: =SUM(Z13:Z18) -> 5 | ... AF26: =SUM(AF13:AF18) -> 605
B27: 11.15 - 11.30 | C27: 3 | D27: 0 | E27: 1 | F27: 0 | G27: 0 | H27: 0 | I27: 1 | J27: 1 | K27: 0 | L27: 0 | M27: 18 | N27: 0 | O27: =SUM(C27:L27,N27) -> 6 | P27: =SUM(C27:N27) -> 24 | R27: PM Period | S27: =SUM(S19:S21) -> 52 | T27: =SUM(T19:T21) -> 3 | U27: =SUM(U19:U21) -> 7 | V27: =SUM(V19:V21) -> 19 | W27: =SUM(W19:W21) -> 0 | X27: =SUM(X19:X21) -> 0 | Y27: =SUM(Y19:Y21) -> 12 | Z27: =SUM(Z19:Z21) -> 5 | ... AF27: =SUM(AF19:AF21) -> 329
B28: 11.30 - 11.45 | C28: 4 | D28: 0 | E28: 0 | F28: 2 | G28: 0 | H28: 0 | I28: 1 | J28: 0 | K28: 0 | L28: 0 | M28: 14 | N28: 0 | O28: =SUM(C28:L28,N28) -> 7 | P28: =SUM(C28:N28) -> 21 | R28: 12 Hours | S28: =SUM(S10:S21) -> 172 | T28: =SUM(T10:T21) -> 5 | U28: =SUM(U10:U21) -> 57 | V28: =SUM(V10:V21) -> 89 | W28: =SUM(W10:W21) -> 0 | X28: =SUM(X10:X21) -> 1 | Y28: =SUM(Y10:Y21) -> 71 | Z28: =SUM(Z10:Z21) -> 12 | ... AF28: =SUM(AF10:AF21) -> 1211
B29: 11.45 - 12.00 | C29: 4 | D29: 0 | E29: 0 | F29: 2 | G29: 0 | H29: 0 | I29: 1 | J29: 0 | K29: 0 | L29: 0 | M29: 16 | N29: 0 | O29: =SUM(C29:L29,N29) -> 7 | P29: =SUM(C29:N29) -> 23
B30: 12.00 - 12.15 | C30: 4 | D30: 0 | E30: 0 | F30: 2 | G30: 0 | H30: 0 | I30: 2 | J30: 0 | K30: 0 | L30: 0 | M30: 17 | N30: 0 | O30: =SUM(C30:L30,N30) -> 8 | P30: =SUM(C30:N30) -> 25
B31: 12.15 - 12.30 | C31: 1 | D31: 0 | E31: 1 | F31: 0 | G31: 0 | H31: 0 | I31: 2 | J31: 1 | K31: 0 | L31: 0 | M31: 16 | N31: 0 | O31: =SUM(C31:L31,N31) -> 5 | P31: =SUM(C31:N31) -> 21
B32: 12.30 - 12.45 | C32: 3 | D32: 0 | E32: 0 | F32: 2 | G32: 0 | H32: 0 | I32: 0 | J32: 0 | K32: 0 | L32: 0 | M32: 11 | N32: 0 | O32: =SUM(C32:L32,N32) -> 5 | P32: =SUM(C32:N32) -> 16
B33: 12.45 - 13.00 | C33: 1 | D33: 0 | E33: 0 | F33: 3 | G33: 0 | H33: 0 | I33: 0 | J33: 1 | K33: 0 | L33: 0 | M33: 13 | N33: 0 | O33: =SUM(C33:L33,N33) -> 5 | P33: =SUM(C33:N33) -> 18
B34: 13.00 - 13.15 | C34: 6 | D34: 0 | E34: 0 | F34: 5 | G34: 0 | H34: 0 | I34: 0 | J34: 0 | K34: 1 | L34: 0 | M34: 30 | N34: 0 | O34: =SUM(C34:L34,N34) -> 12 | P34: =SUM(C34:N34) -> 42
B35: 13.15 - 13.30 | C35: 3 | D35: 0 | E35: 0 | F35: 0 | G35: 0 | H35: 0 | I35: 0 | J35: 0 | K35: 0 | L35: 0 | M35: 8 | N35: 0 | O35: =SUM(C35:L35,N35) -> 3 | P35: =SUM(C35:N35) -> 11
B36: 13.30 - 13.45 | C36: 0 | D36: 0 | E36: 0 | F36: 2 | G36: 0 | H36: 0 | I36: 0 | J36: 0 | K36: 0 | L36: 0 | M36: 14 | N36: 0 | O36: =SUM(C36:L36,N36) -> 2 | P36: =SUM(C36:N36) -> 16
B37: 13.45 - 14.00 | C37: 4 | D37: 0 | E37: 0 | F37: 2 | G37: 0 | H37: 0 | I37: 2 | J37: 0 | K37: 2 | L37: 0 | M37: 11 | N37: 0 | O37: =SUM(C37:L37,N37) -> 10 | P37: =SUM(C37:N37) -> 21
B38: 14.00 - 14.15 | C38: 4 | D38: 0 | E38: 0 | F38: 3 | G38: 0 | H38: 0 | I38: 2 | J38: 0 | K38: 1 | L38: 0 | M38: 14 | N38: 0 | O38: =SUM(C38:L38,N38) -> 10 | P38: =SUM(C38:N38) -> 24
B39: 14.15 - 14.30 | C39: 5 | D39: 0 | E39: 0 | F39: 3 | G39: 0 | H39: 0 | I39: 2 | J39: 0 | K39: 0 | L39: 0 | M39: 10 | N39: 0 | O39: =SUM(C39:L39,N39) -> 10 | P39: =SUM(C39:N39) -> 20
B40: 14.30 - 14.45 | C40: 3 | D40: 0 | E40: 0 | F40: 3 | G40: 0 | H40: 1 | I40: 0 | J40: 0 | K40: 0 | L40: 0 | M40: 8 | N40: 0 | O40: =SUM(C40:L40,N40) -> 7 | P40: =SUM(C40:N40) -> 15
... B50: 17.00 -17.15 | C50: 3 | D50: 0 | E50: 0 | F50: 0 | G50: 0 | H50: 0 | I50: 1 | J50: 0 | K50: 2 | L50: 0 | M50: 16 | N50: 0 | O50: =SUM(C50:L50,N50) -> 6 | P50: =SUM(C50:N50) -> 22
B51: 17.15 -17.30 | C51: 6 | D51: 0 | F51: 2 | G51: 0 | H51: 0 | I51: 2 | J51: 0 | K51: 1 | L51: 0 | M51: 18 | N51: 0 | O51: =SUM(C51:L51,N51) -> 11 | P51: =SUM(C51:N51) -> 29
...

Sheet 25.10 MUTUKULA-MASAKA
B1: Consultancy services for Preparation of Expressway Development Master Plan (EDMP) for Uganda
B2: MANUAL CLASSIFIED COUNT (MCC)
B3: ROAD NAME: | C3: ='31.10.MUTUKULA-MASAKA'!C3:G3 -> MCC-C4-STN99-MASAKA-MUTUKULA
C5: Date | D5: 25.10.19 | F5: Location | G5: MUTUKULA | J5: Surveyor | K5: SANDRA
C6: Dir. From | D6: Mutukula | F6: Dir. To | G6: Masaka | J6: Supervisor | K6: SANDRA
B8: Time / Veh Type | R8: SUMMARY TRAFFIC VOLUMES
C9: 1. Car | D9: 2. Station Wagon | E9: 3. Pickups | F9: 4. Minibus, matatu | G9: 5. Medium bus | H9: 6. Large Bus | I9: 7. Light Truck | J9: 8. Medium Truck | K9: 9. Heavy truck | L9: 10. Truck Trailer | M9: 11. Motor cycles | N9: 12. Tractors | O9: Total Excl M/Cycles | P9: Total All | R9: Time | S9: 1. Car | T9: 2. Station Wagon | U9: 3. Pickups | V9: 4. Minibus, matatu | W9: 5. Medium bus | X9: 6. Large Bus | Y9: 7. Light Truck | Z9: 8. Medium Truck | AA9: 9. Heavy truck | AB9: 10. Truck Trailer | AC9: 11. Motorcycles | AD9: 12. Tractors, Graders | AE9: Total Excl M/ Cycles | AF9: Total All
B10: 07.00 - 07.15 | C10: 1 | D10: 0 | E10: 0 | F10: 2 | G10: 0 | H10: 0 | I10: 0 | J10: 0 | K10: 0 | L10: 0 | M10: 5 | N10: 0 | O10: =SUM(C10:L10,N10) -> 3 | P10: =SUM(C10:N10) -> 8 | R10: 0700-0800 | S10: =SUM(C10:C13) -> 9 | T10: =SUM(D10:D13) -> 0 | U10: =SUM(E10:E13) -> 1 | V10: =SUM(F10:F13) -> 7 | W10: =SUM(G10:G13) -> 0 | X10: =SUM(H10:H13) -> 0 | Y10: =SUM(I10:I13) -> 2 | Z10: =SUM(J10:J13) -> 0 | ... AF10: =SUM(P10:P13) -> 48
B11: 07.15 - 07.30 | C11: 2 | D11: 0 | E11: 0 | F11: 1 | G11: 0 | H11: 0 | I11: 0 | J11: 0 | K11: 0 | L11: 0 | M11: 7 | N11: 0 | O11: =SUM(C11:L11,N11) -> 3 | P11: =SUM(C11:N11) -> 10 | R11: 0800-0900 | S11: =SUM(C14:C17) -> 13 | T11: =SUM(D14:D17) -> 2 | U11: =SUM(E14:E17) -> 0 | V11: =SUM(F14:F17) -> 2 | W11: =SUM(G14:G17) -> 0 | X11: =SUM(H14:H17) -> 0 | Y11: =SUM(I14:I17) -> 4 | Z11: =SUM(J14:J17) -> 1 | ... AF11: =SUM(P14:P17) -> 66
B12: 07.30 - 07.45 | C12: 2 | D12: 0 | E12: 1 | F12: 2 | G12: 0 | H12: 0 | I12: 1 | J12: 0 | K12: 0 | L12: 0 | M12: 5 | N12: 0 | O12: =SUM(C12:L12,N12) -> 6 | P12: =SUM(C12:N12) -> 11 | R12: 0900-1000 | S12: =SUM(C18:C21) -> 7 | T12: =SUM(D18:D21) -> 0 | U12: =SUM(E18:E21) -> 1 | V12: =SUM(F18:F21) -> 2 | W12: =SUM(G18:G21) -> 1 | X12: =SUM(H18:H21) -> 0 | Y12: =SUM(I18:I21) -> 5 | Z12: =SUM(J18:J21) -> 1 | ... AF12: =SUM(P18:P21) -> 86
B13: 07.45 - 08.00 | C13: 4 | D13: 0 | E13: 0 | F13: 2 | G13: 0 | H13: 0 | I13: 1 | J13: 0 | K13: 0 | L13: 0 | M13: 12 | N13: 0 | O13: =SUM(C13:L13,N13) -> 7 | P13: =SUM(C13:N13) -> 19 | R13: 1000-1100 | S13: =SUM(C22:C25) -> 17 | T13: =SUM(D22:D25) -> 7 | U13: =SUM(E22:E25) -> 1 | V13: =SUM(F22:F25) -> 6 | W13: =SUM(G22:G25) -> 0 | X13: =SUM(H22:H25) -> 0 | Y13: =SUM(I22:I25) -> 5 | Z13: =SUM(J22:J25) -> 5 | ... AF13: =SUM(P22:P25) -> 100
B14: 08.00 - 08.15 | C14: 4 | D14: 0 | E14: 0 | F14: 0 | G14: 0 | H14: 0 | I14: 2 | J14: 0 | K14: 0 | L14: 0 | M14: 13 | N14: 0 | O14: =SUM(C14:L14,N14) -> 6 | P14: =SUM(C14:N14) -> 19 | R14: 1100-1200 | S14: =SUM(C26:C29) -> 8 | T14: =SUM(D26:D29) -> 1 | U14: =SUM(E26:E29) -> 1 | V14: =SUM(F26:F29) -> 6 | W14: =SUM(G26:G29) -> 0 | X14: =SUM(H26:H29) -> 0 | Y14: =SUM(I26:I29) -> 6 | Z14: =SUM(J26:J29) -> 0 | ... AF14: =SUM(P26:P29) -> 77
B15: 08.15 - 08.30 | C15: 2 | D15: 0 | E15: 0 | F15: 0 | G15: 0 | H15: 0 | I15: 0 | J15: 0 | K15: 0 | L15: 0 | M15: 11 | N15: 0 | O15: =SUM(C15:L15,N15) -> 2 | P15: =SUM(C15:N15) -> 13 | R15: 1200-1300 | S15: =SUM(C30:C33) -> 9 | T15: =SUM(D30:D33) -> 3 | U15: =SUM(E30:E33) -> 2 | V15: =SUM(F30:F33) -> 6 | W15: =SUM(G30:G33) -> 0 | X15: =SUM(H30:H33) -> 0 | Y15: =SUM(I30:I33) -> 5 | Z15: =SUM(J30:J33) -> 3 | ... AF15: =SUM(P30:P33) -> 75
B16: 08.30 - 08.45 | C16: 2 | D16: 1 | E16: 0 | F16: 1 | G16: 0 | H16: 0 | I16: 1 | J16: 0 | K16: 0 | L16: 0 | M16: 11 | N16: 0 | O16: =SUM(C16:L16,N16) -> 5 | P16: =SUM(C16:N16) -> 16 | R16: 1300-1400 | S16: =SUM(C34:C37) -> 9 | T16: =SUM(D34:D37) -> 0 | U16: =SUM(E34:E37) -> 2 | V16: =SUM(F34:F37) -> 6 | W16: =SUM(G34:G37) -> 2 | X16: =SUM(H34:H37) -> 0 | Y16: =SUM(I34:I37) -> 3 | Z16: =SUM(J34:J37) -> 2 | ... AF16: =SUM(P34:P37) -> 81
B17: 08.45 - 9.00 | C17: 5 | D17: 1 | E17: 0 | F17: 1 | G17: 0 | H17: 0 | I17: 1 | J17: 1 | K17: 0 | L17: 0 | M17: 9 | N17: 0 | O17: =SUM(C17:L17,N17) -> 9 | P17: =SUM(C17:N17) -> 18 | R17: 1400-1500 | S17: =SUM(C38:C41) -> 15 | T17: =SUM(D38:D41) -> 1 | U17: =SUM(E38:E41) -> 1 | V17: =SUM(F38:F41) -> 6 | W17: =SUM(G38:G41) -> 0 | X17: =SUM(H38:H41) -> 0 | Y17: =SUM(I38:I41) -> 6 | Z17: =SUM(J38:J41) -> 1 | ... AF17: =SUM(P38:P41) -> 90
B18: 09.00 - 09.15 | C18: 1 | D18: 0 | E18: 0 | F18: 1 | G18: 0 | H18: 0 | I18: 2 | J18: 0 | K18: 0 | L18: 0 | M18: 10 | N18: 0 | O18: =SUM(C18:L18,N18) -> 4 | P18: =SUM(C18:N18) -> 14 | R18: 1500-1600 | S18: =SUM(C42:C45) -> 8 | T18: =SUM(D42:D45) -> 2 | U18: =SUM(E42:E45) -> 0 | V18: =SUM(F42:F45) -> 9 | W18: =SUM(G42:G45) -> 0 | X18: =SUM(H42:H45) -> 0 | Y18: =SUM(I42:I45) -> 3 | Z18: =SUM(J42:J45) -> 6 | ... AF18: =SUM(P42:P45) -> 101
B19: 09.15 - 09.30 | C19: 0 | D19: 0 | E19: 0 | F19: 0 | G19: 1 | H19: 0 | I19: 0 | J19: 0 | K19: 0 | L19: 0 | M19: 11 | N19: 0 | O19: =SUM(C19:L19,N19) -> 1 | P19: =SUM(C19:N19) -> 12 | R19: 1600-1700 | S19: =SUM(C46:C49) -> 10 | T19: =SUM(D46:D49) -> 1 | U19: =SUM(E46:E49) -> 1 | V19: =SUM(F46:F49) -> 5 | W19: =SUM(G46:G49) -> 1 | X19: =SUM(H46:H49) -> 2 | Y19: =SUM(I46:I49) -> 4 | Z19: =SUM(J46:J49) -> 8 | ... AF19: =SUM(P46:P49) -> 89
B20: 09.30 - 09.45 | C20: 2 | D20: 0 | E20: 1 | F20: 0 | G20: 0 | H20: 0 | I20: 2 | J20: 0 | K20: 0 | L20: 0 | M20: 16 | N20: 0 | O20: =SUM(C20:L20,N20) -> 5 | P20: =SUM(C20:N20) -> 21 | R20: 1700-1800 | S20: =SUM(C50:C53) -> 8 | T20: =SUM(D50:D53) -> 1 | U20: =SUM(E50:E53) -> 1 | V20: =SUM(F50:F53) -> 5 | W20: =SUM(G50:G53) -> 0 | X20: =SUM(H50:H53) -> 0 | Y20: =SUM(I50:I53) -> 4 | Z20: =SUM(J50:J53) -> 3 | ... AF20: =SUM(P50:P53) -> 96
B21: 09.45 - 10.00 | C21: 4 | D21: 0 | E21: 0 | F21: 1 | G21: 0 | H21: 0 | I21: 1 | J21: 1 | K21: 0 | L21: 0 | M21: 32 | N21: 0 | O21: =SUM(C21:L21,N21) -> 7 | P21: =SUM(C21:N21) -> 39 | R21: 1800-1900 | S21: =SUM(C54:C57) -> 10 | T21: =SUM(D54:D57) -> 0 | U21: =SUM(E54:E57) -> 1 | V21: =SUM(F54:F57) -> 4 | W21: =SUM(G54:G57) -> 0 | X21: =SUM(H54:H57) -> 0 | Y21: =SUM(I54:I57) -> 2 | Z21: =SUM(J54:J57) -> 8 | ... AF21: =SUM(P54:P57) -> 99
B22: 10.00 - 10.15 | C22: 4 | D22: 0 | E22: 1 | F22: 1 | G22: 0 | H22: 0 | I22: 3 | J22: 0 | K22: 1 | L22: 0 | M22: 10 | N22: 0 | O22: =SUM(C22:L22,N22) -> 10 | P22: =SUM(C22:N22) -> 20 | R22: AM Peak Hr | S22: =MAX(S10:S12) -> 13 | T22: =MAX(T10:T12) -> 2 | U22: =MAX(U10:U12) -> 1 | V22: =MAX(V10:V12) -> 7 | W22: =MAX(W10:W12) -> 1 | X22: =MAX(X10:X12) -> 0 | Y22: =MAX(Y10:Y12) -> 5 | Z22: =MAX(Z10:Z12) -> 1 | ... AF22: =MAX(AF10:AF12) -> 86
B23: 10.15 - 10.30 | C23: 5 | D23: 2 | E23: 0 | F23: 0 | G23: 0 | H23: 0 | I23: 1 | J23: 2 | K23: 0 | L23: 0 | M23: 14 | N23: 0 | O23: =SUM(C23:L23,N23) -> 10 | P23: =SUM(C23:N23) -> 24 | R23: IP Peak Hr | S23: =MAX(S13:S18) -> 17 | T23: =MAX(T13:T18) -> 7 | U23: =MAX(U13:U18) -> 2 | V23: =MAX(V13:V18) -> 9 | W23: =MAX(W13:W18) -> 2 | X23: =MAX(X13:X18) -> 0 | Y23: =MAX(Y13:Y18) -> 6 | Z23: =MAX(Z13:Z18) -> 6 | ... AF23: =MAX(AF13:AF18) -> 101
B24: 10.30 - 10.45 | C24: 5 | D24: 1 | E24: 0 | F24: 1 | G24: 0 | H24: 0 | I24: 0 | J24: 2 | K24: 0 | L24: 0 | M24: 16 | N24: 0 | O24: =SUM(C24:L24,N24) -> 9 | P24: =SUM(C24:N24) -> 25 | R24: PM Peak Hr | S24: =MAX(S19:S21) -> 10 | T24: =MAX(T19:T21) -> 1 | U24: =MAX(U19:U21) -> 1 | V24: =MAX(V19:V21) -> 5 | W24: =MAX(W19:W21) -> 1 | X24: =MAX(X19:X21) -> 2 | Y24: =MAX(Y19:Y21) -> 4 | Z24: =MAX(Z19:Z21) -> 8 | ... AF24: =MAX(AF19:AF21) -> 99
B25: 10.45 - 11.00 | C25: 3 | D25: 4 | E25: 0 | F25: 4 | G25: 0 | H25: 0 | I25: 1 | J25: 1 | K25: 0 | L25: 0 | M25: 18 | N25: 0 | O25: =SUM(C25:L25,N25) -> 13 | P25: =SUM(C25:N25) -> 31 | R25: AM Period | S25: =SUM(S10:S12) -> 29 | T25: =SUM(T10:T12) -> 2 | U25: =SUM(U10:U12) -> 2 | V25: =SUM(V10:V12) -> 11 | W25: =SUM(W10:W12) -> 1 | X25: =SUM(X10:X12) -> 0 | Y25: =SUM(Y10:Y12) -> 11 | Z25: =SUM(Z10:Z12) -> 2 | ... AF25: =SUM(AF10:AF12) -> 200
B26: 11.00 - 11.15 | C26: 2 | D26: 0 | E26: 0 | F26: 2 | G26: 0 | H26: 0 | I26: 0 | J26: 0 | K26: 1 | L26: 1 | M26: 15 | N26: 0 | O26: =SUM(C26:L26,N26) -> 6 | P26: =SUM(C26:N26) -> 21 | R26: IP Period | S26: =SUM(S13:S18) -> 66 | T26: =SUM(T13:T18) -> 14 | U26: =SUM(U13:U18) -> 7 | V26: =SUM(V13:V18) -> 39 | W26: =SUM(W13:W18) -> 2 | X26: =SUM(X13:X18) -> 0 | Y26: =SUM(Y13:Y18) -> 28 | Z26: =SUM(Z13:Z18) -> 17 | ... AF26: =SUM(AF13:AF18) -> 524
B27: 11.15 - 11.30 | C27: 2 | D27: 0 | E27: 0 | F27: 2 | G27: 0 | H27: 0 | I27: 2 | J27: 0 | K27: 0 | L27: 0 | M27: 12 | N27: 0 | O27: =SUM(C27:L27,N27) -> 6 | P27: =SUM(C27:N27) -> 18 | R27: PM Period | S27: =SUM(S19:S21) -> 28 | T27: =SUM(T19:T21) -> 2 | U27: =SUM(U19:U21) -> 3 | V27: =SUM(V19:V21) -> 14 | W27: =SUM(W19:W21) -> 1 | X27: =SUM(X19:X21) -> 2 | Y27: =SUM(Y19:Y21) -> 10 | Z27: =SUM(Z19:Z21) -> 19 | ... AF27: =SUM(AF19:AF21) -> 284
B28: 11.30 - 11.45 | C28: 3 | D28: 1 | E28: 1 | F28: 0 | G28: 0 | H28: 0 | I28: 1 | J28: 0 | K28: 0 | L28: 0 | M28: 11 | N28: 0 | O28: =SUM(C28:L28,N28) -> 6 | P28: =SUM(C28:N28) -> 17 | R28: 12 Hours | S28: =SUM(S10:S21) -> 123 | T28: =SUM(T10:T21) -> 18 | U28: =SUM(U10:U21) -> 12 | V28: =SUM(V10:V21) -> 64 | W28: =SUM(W10:W21) -> 4 | X28: =SUM(X10:X21) -> 2 | Y28: =SUM(Y10:Y21) -> 49 | Z28: =SUM(Z10:Z21) -> 38 | ... AF28: =SUM(AF10:AF21) -> 1008
B29: 11.45 - 12.00 | C29: 1 | D29: 0 | E29: 0 | F29: 2 | G29: 0 | H29: 0 | I29: 3 | J29: 0 | K29: 0 | L29: 0 | M29: 15 | N29: 0 | O29: =SUM(C29:L29,N29) -> 6 | P29: =SUM(C29:N29) -> 21
B30: 12.00 - 12.15 | C30: 1 | D30: 2 | E30: 0 | F30: 1 | G30: 0 | H30: 0 | I30: 1 | J30: 1 | K30: 0 | L30: 0 | M30: 12 | N30: 0 | O30: =SUM(C30:L30,N30) -> 6 | P30: =SUM(C30:N30) -> 18
B31: 12.15 - 12.30 | C31: 3 | D31: 1 | E31: 0 | F31: 1 | G31: 0 | H31: 0 | I31: 1 | J31: 2 | K31: 0 | L31: 0 | M31: 9 | N31: 0 | O31: =SUM(C31:L31,N31) -> 8 | P31: =SUM(C31:N31) -> 17
B32: 12.30 - 12.45 | C32: 2 | D32: 0 | E32: 1 | F32: 3 | G32: 0 | H32: 0 | I32: 2 | J32: 0 | K32: 0 | L32: 0 | M32: 11 | N32: 0 | O32: =SUM(C32:L32,N32) -> 8 | P32: =SUM(C32:N32) -> 19
B33: 12.45 - 13.00 | C33: 3 | D33: 0 | E33: 1 | F33: 1 | G33: 0 | H33: 0 | I33: 1 | J33: 0 | K33: 0 | L33: 0 | M33: 15 | N33: 0 | O33: =SUM(C33:L33,N33) -> 6 | P33: =SUM(C33:N33) -> 21
B34: 13.00 - 13.15 | C34: 3 | D34: 0 | E34: 0 | F34: 2 | G34: 0 | H34: 0 | I34: 1 | J34: 0 | K34: 2 | L34: 0 | M34: 14 | N34: 0 | O34: =SUM(C34:L34,N34) -> 8 | P34: =SUM(C34:N34) -> 22
B35: 13.15 - 13.30 | C35: 4 | D35: 0 | E35: 0 | F35: 2 | G35: 0 | H35: 0 | I35: 0 | J35: 1 | K35: 0 | L35: 2 | M35: 18 | N35: 0 | O35: =SUM(C35:L35,N35) -> 9 | P35: =SUM(C35:N35) -> 27
B36: 13.30 - 13.45 | C36: 0 | D36: 0 | E36: 1 | F36: 1 | G36: 1 | H36: 0 | I36: 1 | J36: 0 | K36: 2 | L36: 0 | M36: 5 | N36: 0 | O36: =SUM(C36:L36,N36) -> 6 | P36: =SUM(C36:N36) -> 11
B37: 13.45 - 14.00 | C37: 2 | D37: 0 | E37: 1 | F37: 1 | G37: 1 | H37: 0 | I37: 1 | J37: 1 | K37: 1 | L37: 1 | M37: 12 | N37: 0 | O37: =SUM(C37:L37,N37) -> 9 | P37: =SUM(C37:N37) -> 21
B38: 14.00 - 14.15 | C38: 3 | D38: 1 | E38: 0 | F38: 0 | G38: 0 | H38: 0 | I38: 2 | J38: 0 | K38: 1 | L38: 0 | M38: 16 | N38: 0 | O38: =SUM(C38:L38,N38) -> 7 | P38: =SUM(C38:N38) -> 23
B39: 14.15 - 14.30 | C39: 5 | D39: 0 | E39: 0 | F39: 2 | G39: 0 | H39: 0 | I39: 1 | J39: 0 | K39: 0 | L39: 0 | M39: 12 | N39: 0 | O39: =SUM(C39:L39,N39) -> 8 | P39: =SUM(C39:N39) -> 20
B40: 14.30 - 14.45 | C40: 3 | D40: 0 | E40: 1 | F40: 2 | G40: 0 | H40: 0 | I40: 1 | J40: 0 | K40: 1 | L40: 0 | M40: 14 | N40: 0 | O40: =SUM(C40:L40,N40) -> 8 | P40: =SUM(C40:N40) -> 22
... B57: 18.45 - 19.00 | C57: 2 | D57: 0 | E57: 1 | F57: 0 | G57: 0 | H57: 0 | I57: 0 | J57: 2 | K57: 2 | L57: 4 | M57: 21 | N57: 0 | O57: =SUM(C57:L57,N57) -> 11 | P57: =SUM(C57:N57) -> 32
B58: Totals | C58: =SUM(C10:C57) -> 123 | D58: =SUM(D10:D57) -> 18 | E58: =SUM(E10:E57) -> 12 | F58: =SUM(F10:F57) -> 64 | G58: =SUM(G10:G57) -> 4 | H58: =SUM(H10:H57) -> 2 | I58: =SUM(I10:I57) -> 49 | J58: =SUM(J10:J57) -> 38 | ... P58: =SUM(P10:P57) -> 1008
...

Sheet 26.10 MASAKA-MUTUKULA-24HR
B1: Consultancy services for Preparation of Expressway Development Master Plan (EDMP) for Uganda
B2: MANUAL CLASSIFIED COUNT (MCC)
B3: ROAD NAME: | C3: ='31.10 Masaka-Mutukula'!C3:G3 -> MCC - C4- STN99-MASAKA-MUTUKULA
C5: Date | D5: 26.10.19 | F5: Location | G5: ='28.10 MUTUKULA-MASAKA-24HR'!G5:H5 -> MUTUKULA | J5: Surveyor | K5: Steven & Omeje
C6: Dir. From | D6: ='31.10 Masaka-Mutukula'!D6:E6 -> MASAKA | F6: Dir. To | G6: ='31.10 Masaka-Mutukula'!G6:H6 -> MUTUKULA | J6: Supervisor | K6: ='28.10 MUTUKULA-MASAKA-24HR'!K6:L6 -> SANDRA
B8: Time / Veh Type | R8: SUMMARY TRAFFIC VOLUMES
C9: 1. Car | D9: 2. Station Wagon | E9: 3. Pickups | F9: 4. Minibus, matatu | G9: 5. Medium bus | H9: 6. Large Bus | I9: 7. Light Truck | J9: 8. Medium Truck | K9: 9. Heavy truck | L9: 10. Truck Trailer | M9: 11. Motor cycles | N9: 12. Tractors | O9: Total Excl M/Cycles | P9: Total All | R9: Time | S9: 1. Car | T9: 2. Station Wagon | U9: 3. Pickups | V9: 4. Minibus, matatu | W9: 5. Medium bus | X9: 6. Large Bus | Y9: 7. Light Truck | Z9: 8. Medium Truck | AA9: 9. Heavy truck | AB9: 10. Truck Trailer | AC9: 11. Motorcycles | AD9: 12. Tractors, Graders | AE9: Total Excl M/ Cycles | AF9: Total All
B10: 07.00 - 07.15 | C10: 1 | D10: 0 | E10: 0 | F10: 0 | G10: 0 | H10: 0 | I10: 0 | J10: 0 | K10: 0 | L10: 0 | M10: 1 | N10: 0 | O10: =SUM(C10:L10,N10) -> 1 | P10: =SUM(C10:N10) -> 2 | R10: 0700-0800 | S10: =SUM(C10:C13) -> 7 | T10: =SUM(D10:D13) -> 1 | U10: =SUM(E10:E13) -> 0 | V10: =SUM(F10:F13) -> 1 | W10: =SUM(G10:G13) -> 0 | X10: =SUM(H10:H13) -> 0 | Y10: =SUM(I10:I13) -> 1 | Z10: =SUM(J10:J13) -> 0 | ... AF10: =SUM(P10:P13) -> 39
B11: 07.15 - 07.30 | C11: 3 | D11: 1 | E11: 0 | F11: 0 | G11: 0 | H11: 0 | I11: 0 | J11: 0 | K11: 0 | L11: 0 | M11: 6 | N11: 0 | O11: =SUM(C11:L11,N11) -> 4 | P11: =SUM(C11:N11) -> 10 | R11: 0800-0900 | S11: =SUM(C14:C17) -> 17 | T11: =SUM(D14:D17) -> 2 | U11: =SUM(E14:E17) -> 0 | V11: =SUM(F14:F17) -> 2 | W11: =SUM(G14:G17) -> 0 | X11: =SUM(H14:H17) -> 0 | Y11: =SUM(I14:I17) -> 1 | Z11: =SUM(J14:J17) -> 2 | ... AF11: =SUM(P14:P17) -> 86
B12: 07.30 - 07.45 | C12: 1 | D12: 0 | E12: 0 | F12: 0 | G12: 0 | H12: 0 | I12: 0 | J12: 0 | K12: 0 | L12: 0 | M12: 8 | N12: 0 | O12: =SUM(C12:L12,N12) -> 1 | P12: =SUM(C12:N12) -> 9 | R12: 0900-1000 | S12: =SUM(C18:C21) -> 5 | T12: =SUM(D18:D21) -> 0 | U12: =SUM(E18:E21) -> 2 | V12: =SUM(F18:F21) -> 3 | W12: =SUM(G18:G21) -> 0 | X12: =SUM(H18:H21) -> 1 | Y12: =SUM(I18:I21) -> 12 | Z12: =SUM(J18:J21) -> 2 | ... AF12: =SUM(P18:P21) -> 72
B13: 07.45 - 08.00 | C13: 2 | D13: 0 | E13: 0 | F13: 1 | G13: 0 | H13: 0 | I13: 1 | J13: 0 | K13: 2 | L13: 0 | M13: 12 | N13: 0 | O13: =SUM(C13:L13,N13) -> 6 | P13: =SUM(C13:N13) -> 18 | R13: 1000-1100 | S13: =SUM(C22:C25) -> 4 | T13: =SUM(D22:D25) -> 0 | U13: =SUM(E22:E25) -> 0 | V13: =SUM(F22:F25) -> 3 | W13: =SUM(G22:G25) -> 0 | X13: =SUM(H22:H25) -> 0 | Y13: =SUM(I22:I25) -> 1 | Z13: =SUM(J22:J25) -> 0 | ... AF13: =SUM(P22:P25) -> 26
B14: 08.00 - 08.15 | C14: 4 | D14: 0 | E14: 0 | F14: 0 | G14: 0 | H14: 0 | I14: 1 | J14: 0 | K14: 3 | L14: 0 | M14: 13 | N14: 0 | O14: =SUM(C14:L14,N14) -> 8 | P14: =SUM(C14:N14) -> 21 | R14: 1100-1200 | S14: =SUM(C26:C29) -> 9 | T14: =SUM(D26:D29) -> 1 | U14: =SUM(E26:E29) -> 1 | V14: =SUM(F26:F29) -> 9 | W14: =SUM(G26:G29) -> 0 | X14: =SUM(H26:H29) -> 0 | Y14: =SUM(I26:I29) -> 1 | Z14: =SUM(J26:J29) -> 1 | ... AF14: =SUM(P26:P29) -> 61
B15: 08.15 - 08.30 | C15: 7 | D15: 0 | E15: 0 | F15: 0 | G15: 0 | H15: 0 | I15: 0 | J15: 1 | K15: 0 | L15: 1 | M15: 10 | N15: 0 | O15: =SUM(C15:L15,N15) -> 9 | P15: =SUM(C15:N15) -> 19 | R15: 1200-1300 | S15: =SUM(C30:C33) -> 11 | T15: =SUM(D30:D33) -> 2 | U15: =SUM(E30:E33) -> 0 | V15: =SUM(F30:F33) -> 7 | W15: =SUM(G30:G33) -> 0 | X15: =SUM(H30:H33) -> 0 | Y15: =SUM(I30:I33) -> 1 | Z15: =SUM(J30:J33) -> 1 | ... AF15: =SUM(P30:P33) -> 67
B16: 08.30 - 08.45 | C16: 3 | D16: 1 | E16: 0 | F16: 2 | G16: 0 | H16: 0 | I16: 0 | J16: 1 | K16: 1 | L16: 1 | M16: 15 | N16: 0 | O16: =SUM(C16:L16,N16) -> 9 | P16: =SUM(C16:N16) -> 24 | R16: 1300-1400 | S16: =SUM(C34:C37) -> 8 | T16: =SUM(D34:D37) -> 2 | U16: =SUM(E34:E37) -> 0 | V16: =SUM(F34:F37) -> 6 | W16: =SUM(G34:G37) -> 0 | X16: =SUM(H34:H37) -> 0 | Y16: =SUM(I34:I37) -> 3 | Z16: =SUM(J34:J37) -> 4 | ... AF16: =SUM(P34:P37) -> 66
B17: 08.45 - 9.00 | C17: 3 | D17: 1 | E17: 0 | F17: 0 | G17: 0 | H17: 0 | I17: 0 | J17: 0 | K17: 3 | L17: 0 | M17: 15 | N17: 0 | O17: =SUM(C17:L17,N17) -> 7 | P17: =SUM(C17:N17) -> 22 | R17: 1400-1500 | S17: =SUM(C38:C41) -> 17 | T17: =SUM(D38:D41) -> 2 | U17: =SUM(E38:E41) -> 0 | V17: =SUM(F38:F41) -> 6 | W17: =SUM(G38:G41) -> 0 | X17: =SUM(H38:H41) -> 0 | Y17: =SUM(I38:I41) -> 2 | Z17: =SUM(J38:J41) -> 6 | ... AF17: =SUM(P38:P41) -> 94
B18: 09.00 - 09.15 | C18: 2 | D18: 0 | E18: 1 | F18: 2 | G18: 0 | H18: 0 | I18: 5 | J18: 1 | K18: 0 | L18: 1 | M18: 11 | N18: 0 | O18: =SUM(C18:L18,N18) -> 12 | P18: =SUM(C18:N18) -> 23 | R18: 1500-1600 | S18: =SUM(C42:C45) -> 12 | T18: =SUM(D42:D45) -> 2 | U18: =SUM(E42:E45) -> 0 | V18: =SUM(F42:F45) -> 13 | W18: =SUM(G42:G45) -> 0 | X18: =SUM(H42:H45) -> 0 | Y18: =SUM(I42:I45) -> 5 | Z18: =SUM(J42:J45) -> 4 | ... AF18: =SUM(P42:P45) -> 63
B19: 09.15 - 09.30 | C19: 0 | D19: 0 | E19: 1 | F19: 0 | G19: 0 | H19: 1 | I19: 1 | J19: 0 | K19: 0 | L19: 0 | M19: 16 | N19: 0 | O19: =SUM(C19:L19,N19) -> 3 | P19: =SUM(C19:N19) -> 19 | R19: 1600-1700 | S19: =SUM(C46:C49) -> 14 | T19: =SUM(D46:D49) -> 6 | U19: =SUM(E46:E49) -> 1 | V19: =SUM(F46:F49) -> 10 | W19: =SUM(G46:G49) -> 0 | X19: =SUM(H46:H49) -> 0 | Y19: =SUM(I46:I49) -> 1 | Z19: =SUM(J46:J49) -> 1 | ... AF19: =SUM(P46:P49) -> 54
B20: 09.30 - 09.45 | C20: 2 | D20: 0 | E20: 0 | F20: 1 | G20: 0 | H20: 0 | I20: 6 | J20: 1 | K20: 0 | L20: 1 | M20: 5 | N20: 0 | O20: =SUM(C20:L20,N20) -> 11 | P20: =SUM(C20:N20) -> 16 | R20: 1700-1800 | S20: =SUM(C50:C53) -> 6 | T20: =SUM(D50:D53) -> 1 | U20: =SUM(E50:E53) -> 1 | V20: =SUM(F50:F53) -> 5 | W20: =SUM(G50:G53) -> 0 | X20: =SUM(H50:H53) -> 0 | Y20: =SUM(I50:I53) -> 2 | Z20: =SUM(J50:J53) -> 2 | ... AF20: =SUM(P50:P53) -> 53
B21: 09.45 - 10.00 | C21: 1 | D21: 0 | E21: 0 | F21: 0 | G21: 0 | H21: 0 | I21: 0 | J21: 0 | K21: 2 | L21: 0 | M21: 11 | N21: 0 | O21: =SUM(C21:L21,N21) -> 3 | P21: =SUM(C21:N21) -> 14 | R21: 1800-1900 | S21: =SUM(C54:C57) -> 4 | T21: =SUM(D54:D57) -> 2 | U21: =SUM(E54:E57) -> 0 | V21: =SUM(F54:F57) -> 8 | W21: =SUM(G54:G57) -> 0 | X21: =SUM(H54:H57) -> 0 | Y21: =SUM(I54:I57) -> 0 | Z21: =SUM(J54:J57) -> 1 | ... AF21: =SUM(P54:P57) -> 71
B22: 10.00 - 10.15 | C22: 2 | D22: 0 | E22: 0 | F22: 1 | G22: 0 | H22: 0 | I22: 0 | J22: 0 | K22: 3 | L22: 0 | M22: 4 | N22: 0 | O22: =SUM(C22:L22,N22) -> 6 | P22: =SUM(C22:N22) -> 10 | R22: 1900-2000 | S22: =SUM(C58:C61) -> 10 | T22: =SUM(D58:D61) -> 3 | U22: =SUM(E58:E61) -> 0 | V22: =SUM(F58:F61) -> 9 | W22: =SUM(G58:G61) -> 0 | X22: =SUM(H58:H61) -> 0 | Y22: =SUM(I58:I61) -> 2 | Z22: =SUM(J58:J61) -> 2 | ... AF22: =SUM(P58:P61) -> 122
B23: 10.15 - 10.30 | C23: 0 | D23: 0 | E23: 0 | F23: 0 | G23: 0 | H23: 0 | I23: 0 | J23: 0 | K23: 0 | L23: 0 | M23: 2 | N23: 0 | O23: =SUM(C23:L23,N23) -> 0 | P23: =SUM(C23:N23) -> 2 | R23: 2000-2100 | S23: =SUM(C62:C65) -> 15 | T23: =SUM(D62:D65) -> 0 | U23: =SUM(E62:E65) -> 0 | V23: =SUM(F62:F65) -> 3 | W23: =SUM(G62:G65) -> 0 | X23: =SUM(H62:H65) -> 1 | Y23: =SUM(I62:I65) -> 2 | Z23: =SUM(J62:J65) -> 0 | ... AF23: =SUM(P62:P65) -> 46
B24: 10.30 - 10.45 | C24: 1 | D24: 0 | E24: 0 | F24: 0 | G24: 0 | H24: 0 | I24: 0 | J24: 0 | K24: 1 | L24: 0 | M24: 2 | N24: 0 | O24: =SUM(C24:L24,N24) -> 2 | P24: =SUM(C24:N24) -> 4 | R24: 2100-2200 | S24: =SUM(C66:C69) -> 13 | T24: =SUM(D66:D69) -> 1 | U24: =SUM(E66:E69) -> 0 | V24: =SUM(F66:F69) -> 2 | W24: =SUM(G66:G69) -> 0 | X24: =SUM(H66:H69) -> 0 | Y24: =SUM(I66:I69) -> 0 | Z24: =SUM(J66:J69) -> 2 | ... AF24: =SUM(P66:P69) -> 50
B25: 10.45 - 11.00 | C25: 1 | D25: 0 | E25: 0 | F25: 2 | G25: 0 | H25: 0 | I25: 1 | J25: 0 | K25: 0 | L25: 0 | M25: 6 | N25: 0 | O25: =SUM(C25:L25,N25) -> 4 | P25: =SUM(C25:N25) -> 10 | R25: 2200-2300 | S25: =SUM(C70:C73) -> 9 | T25: =SUM(D70:D73) -> 0 | U25: =SUM(E70:E73) -> 0 | V25: =SUM(F70:F73) -> 2 | W25: =SUM(G70:G73) -> 0 | X25: =SUM(H70:H73) -> 0 | Y25: =SUM(I70:I73) -> 3 | Z25: =SUM(J70:J73) -> 1 | ... AF25: =SUM(P70:P73) -> 32
B26: 11.00 - 11.15 | C26: 2 | D26: 1 | E26: 0 | F26: 4 | G26: 0 | H26: 0 | I26: 0 | J26: 0 | K26: 0 | L26: 0 | M26: 8 | N26: 0 | O26: =SUM(C26:L26,N26) -> 7 | P26: =SUM(C26:N26) -> 15 | R26: 2300-0000 | S26: =SUM(C74:C77) -> 1 | T26: =SUM(D74:D77) -> 0 | U26: =SUM(E74:E77) -> 0 | V26: =SUM(F74:F77) -> 1 | W26: =SUM(G74:G77) -> 1 | X26: =SUM(H74:H77) -> 0 | Y26: =SUM(I74:I77) -> 0 | Z26: =SUM(J74:J77) -> 0 | ... AF26: =SUM(P74:P77) -> 12
B27: 11.15 - 11.30 | C27: 3 | D27: 0 | E27: 0 | F27: 2 | G27: 0 | H27: 0 | I27: 1 | J27: 1 | K27: 0 | L27: 0 | M27: 13 | N27: 0 | O27: =SUM(C27:L27,N27) -> 7 | P27: =SUM(C27:N27) -> 20 | R27: 0000-0100 | S27: =SUM(C78:C81) -> 3 | T27: =SUM(D78:D81) -> 2 | U27: =SUM(E78:E81) -> 0 | V27: =SUM(F78:F81) -> 2 | W27: =SUM(G78:G81) -> 0 | X27: =SUM(H78:H81) -> 0 | Y27: =SUM(I78:I81) -> 0 | Z27: =SUM(J78:J81) -> 0 | ... AF27: =SUM(P78:P81) -> 12
B28: 11.30 - 11.45 | C28: 2 | D28: 0 | E28: 1 | F28: 2 | G28: 0 | H28: 0 | I28: 0 | J28: 0 | K28: 1 | L28: 0 | M28: 8 | N28: 0 | O28: =SUM(C28:L28,N28) -> 6 | P28: =SUM(C28:N28) -> 14 | R28: 0100-0200 | S28: =SUM(C82:C85) -> 1 | T28: =SUM(D82:D85) -> 0 | U28: =SUM(E82:E85) -> 0 | V28: =SUM(F82:F85) -> 0 | W28: =SUM(G82:G85) -> 0 | X28: =SUM(H82:H85) -> 0 | Y28: =SUM(I82:I85) -> 0 | Z28: =SUM(J82:J85) -> 0 | ... AF28: =SUM(P82:P85) -> 2
B29: 11.45 - 12.00 | C29: 2 | D29: 0 | E29: 0 | F29: 1 | G29: 0 | H29: 0 | I29: 0 | J29: 0 | K29: 0 | L29: 0 | M29: 9 | N29: 0 | O29: =SUM(C29:L29,N29) -> 3 | P29: =SUM(C29:N29) -> 12 | R29: 0200-0300 | S29: =SUM(C86:C89) -> 1 | T29: =SUM(D86:D89) -> 0 | U29: =SUM(E86:E89) -> 0 | V29: =SUM(F86:F89) -> 1 | W29: =SUM(G86:G89) -> 0 | X29: =SUM(H86:H89) -> 0 | Y29: =SUM(I86:I89) -> 0 | Z29: =SUM(J86:J89) -> 0 | ... AF29: =SUM(P86:P89) -> 7
B30: 12.00 - 12.15 | C30: 4 | D30: 0 | E30: 0 | F30: 0 | G30: 0 | H30: 0 | I30: 0 | J30: 0 | K30: 2 | L30: 0 | M30: 18 | N30: 0 | O30: =SUM(C30:L30,N30) -> 6 | P30: =SUM(C30:N30) -> 24 | R30: 0300-0400 | S30: =SUM(C90:C93) -> 0 | T30: =SUM(D90:D93) -> 1 | U30: =SUM(E90:E93) -> 0 | V30: =SUM(F90:F93) -> 0 | W30: =SUM(G90:G93) -> 0 | X30: =SUM(H90:H93) -> 2 | Y30: =SUM(I90:I93) -> 0 | Z30: =SUM(J90:J93) -> 0 | ... AF30: =SUM(P90:P93) -> 5
B31: 12.15 - 12.30 | C31: 1 | D31: 0 | E31: 0 | F31: 6 | G31: 0 | H31: 0 | I31: 1 | J31: 1 | K31: 0 | L31: 0 | M31: 9 | N31: 0 | O31: =SUM(C31:L31,N31) -> 9 | P31: =SUM(C31:N31) -> 18 | R31: 0400-0500 | S31: =SUM(C94:C97) -> 1 | T31: =SUM(D94:D97) -> 0 | U31: =SUM(E94:E97) -> 0 | V31: =SUM(F94:F97) -> 0 | W31: =SUM(G94:G97) -> 0 | X31: =SUM(H94:H97) -> 0 | Y31: =SUM(I94:I97) -> 0 | Z31: =SUM(J94:J97) -> 2 | ... AF31: =SUM(P94:P97) -> 7
B32: 12.30 - 12.45 | C32: 4 | D32: 0 | E32: 0 | F32: 0 | G32: 0 | H32: 0 | I32: 0 | J32: 0 | K32: 0 | L32: 0 | M32: 10 | N32: 0 | O32: =SUM(C32:L32,N32) -> 4 | P32: =SUM(C32:N32) -> 14 | R32: 0500-0600 | S32: =SUM(C98:C101) -> 3 | T32: =SUM(D98:D101) -> 0 | U32: =SUM(E98:E101) -> 0 | V32: =SUM(F98:F101) -> 1 | W32: =SUM(G98:G101) -> 0 | X32: =SUM(H98:H101) -> 0 | Y32: =SUM(I98:I101) -> 1 | Z32: =SUM(J98:J101) -> 1 | ... AF32: =SUM(P98:P101) -> 13
B33: 12.45 - 13.00 | C33: 2 | D33: 2 | E33: 0 | F33: 1 | G33: 0 | H33: 0 | I33: 0 | J33: 0 | K33: 0 | L33: 0 | M33: 6 | N33: 0 | O33: =SUM(C33:L33,N33) -> 5 | P33: =SUM(C33:N33) -> 11 | R33: 0600-0700 | S33: =SUM(C102:C105) -> 5 | T33: =SUM(D102:D105) -> 0 | U33: =SUM(E102:E105) -> 0 | V33: =SUM(F102:F105) -> 26 | W33: =SUM(G102:G105) -> 0 | X33: =SUM(H102:H105) -> 0 | Y33: =SUM(I102:I105) -> 4 | Z33: =SUM(J102:J105) -> 0 | ... AF33: =SUM(P102:P105) -> 52
B34: 13.00 - 13.15 | C34: 2 | D34: 0 | E34: 0 | F34: 1 | G34: 0 | H34: 0 | I34: 1 | J34: 0 | K34: 0 | L34: 2 | M34: 9 | N34: 0 | O34: =SUM(C34:L34,N34) -> 6 | P34: =SUM(C34:N34) -> 15 | R34: AM Peak Hr | S34: =MAX(S10:S12) -> 17 | T34: =MAX(T10:T12) -> 2 | U34: =MAX(U10:U12) -> 2 | V34: =MAX(V10:V12) -> 3 | W34: =MAX(W10:W12) -> 0 | X34: =MAX(X10:X12) -> 1 | Y34: =MAX(Y10:Y12) -> 12 | Z34: =MAX(Z10:Z12) -> 2 | ... AF34: =MAX(AF10:AF12) -> 86
B35: 13.15 - 13.30 | C35: 1 | D35: 0 | E35: 0 | F35: 1 | G35: 0 | H35: 0 | I35: 2 | J35: 1 | K35: 1 | L35: 0 | M35: 8 | N35: 0 | O35: =SUM(C35:L35,N35) -> 6 | P35: =SUM(C35:N35) -> 14 | R35: IP Peak Hr | S35: =MAX(S13:S18) -> 17 | T35: =MAX(T13:T18) -> 2 | U35: =MAX(U13:U18) -> 1 | V35: =MAX(V13:V18) -> 13 | W35: =MAX(W13:W18) -> 0 | X35: =MAX(X13:X18) -> 0 | Y35: =MAX(Y13:Y18) -> 5 | Z35: =MAX(Z13:Z18) -> 6 | ... AF35: =MAX(AF13:AF18) -> 94
B36: 13.30 - 13.45 | C36: 1 | D36: 1 | E36: 0 | F36: 3 | G36: 0 | H36: 0 | I36: 0 | J36: 3 | K36: 0 | L36: 0 | M36: 14 | N36: 0 | O36: =SUM(C36:L36,N36) -> 8 | P36: =SUM(C36:N36) -> 22 | R36: PM Peak Hr | S36: =MAX(S19:S21) -> 14 | T36: =MAX(T19:T21) -> 6 | U36: =MAX(U19:U21) -> 1 | V36: =MAX(V19:V21) -> 10 | W36: =MAX(W19:W21) -> 0 | X36: =MAX(X19:X21) -> 0 | Y36: =MAX(Y19:Y21) -> 2 | Z36: =MAX(Z19:Z21) -> 2 | ... AF36: =MAX(AF19:AF21) -> 71
B37: 13.45 - 14.00 | C37: 4 | D37: 1 | E37: 0 | F37: 1 | G37: 0 | H37: 0 | I37: 0 | J37: 0 | K37: 0 | L37: 0 | M37: 9 | N37: 0 | O37: =SUM(C37:L37,N37) -> 6 | P37: =SUM(C37:N37) -> 15 | R37: AM Period | S37: =SUM(S10:S12) -> 29 | T37: =SUM(T10:T12) -> 3 | U37: =SUM(U10:U12) -> 2 | V37: =SUM(V10:V12) -> 6 | W37: =SUM(W10:W12) -> 0 | X37: =SUM(X10:X12) -> 1 | Y37: =SUM(Y10:Y12) -> 14 | Z37: =SUM(Z10:Z12) -> 4 | ... AF37: =SUM(AF10:AF12) -> 197
B38: 14.00 - 14.15 | C38: 3 | D38: 1 | E38: 0 | F38: 1 | G38: 0 | H38: 0 | I38: 0 | J38: 1 | K38: 0 | L38: 0 | M38: 16 | N38: 0 | O38: =SUM(C38:L38,N38) -> 6 | P38: =SUM(C38:N38) -> 22 | R38: IP Period | S38: =SUM(S13:S18) -> 61 | T38: =SUM(T13:T18) -> 9 | U38: =SUM(U13:U18) -> 1 | V38: =SUM(V13:V18) -> 44 | W38: =SUM(W13:W18) -> 0 | X38: =SUM(X13:X18) -> 0 | Y38: =SUM(Y13:Y18) -> 13 | Z38: =SUM(Z13:Z18) -> 16 | ... AF38: =SUM(AF13:AF18) -> 377
B39: 14.15 - 14.30 | C39: 2 | D39: 0 | E39: 0 | F39: 2 | G39: 0 | H39: 0 | I39: 1 | J39: 3 | K39: 0 | L39: 0 | M39: 12 | N39: 0 | O39: =SUM(C39:L39,N39) -> 8 | P39: =SUM(C39:N39) -> 20 | R39: PM Period | S39: =SUM(S19:S21) -> 24 | T39: =SUM(T19:T21) -> 9 | U39: =SUM(U19:U21) -> 2 | V39: =SUM(V19:V21) -> 23 | W39: =SUM(W19:W21) -> 0 | X39: =SUM(X19:X21) -> 0 | Y39: =SUM(Y19:Y21) -> 3 | Z39: =SUM(Z19:Z21) -> 4 | ... AF39: =SUM(AF19:AF21) -> 178
B40: 14.30 - 14.45 | C40: 7 | D40: 1 | E40: 0 | F40: 1 | G40: 0 | H40: 0 | I40: 1 | J40: 1 | K40: 0 | L40: 0 | M40: 24 | N40: 0 | O40: =SUM(C40:L40,N40) -> 11 | P40: =SUM(C40:N40) -> 35 | R40: 12 Hours | S40: =SUM(S10:S21) -> 114 | T40: =SUM(T10:T21) -> 21 | U40: =SUM(U10:U21) -> 5 | V40: =SUM(V10:V21) -> 73 | W40: =SUM(W10:W21) -> 0 | X40: =SUM(X10:X21) -> 1 | Y40: =SUM(Y10:Y21) -> 30 | Z40: =SUM(Z10:Z21) -> 24 | ... AF40: =SUM(AF10:AF21) -> 752
B41: 14.45 - 15.00 | C41: 5 | D41: 0 | E41: 0 | F41: 2 | G41: 0 | H41: 0 | I41: 0 | J41: 1 | K41: 0 | L41: 0 | M41: 9 | N41: 0 | O41: =SUM(C41:L41,N41) -> 8 | P41: =SUM(C41:N41) -> 17 | R41: 24 Hrs/ADT | S41: =SUM(S10:S33) -> 176 | T41: =SUM(T10:T33) -> 28 | U41: =SUM(U10:U33) -> 5 | V41: =SUM(V10:V33) -> 120 | W41: =SUM(W10:W33) -> 1 | X41: =SUM(X10:X33) -> 4 | Y41: =SUM(Y10:Y33) -> 42 | Z41: =SUM(Z10:Z33) -> 32 | ... AF41: =SUM(AF10:AF33) -> 1112
B42: 15.00 - 15.15 | C42: 5 | D42: 0 | E42: 0 | F42: 1 | G42: 0 | H42: 0 | I42: 2 | J42: 0 | K42: 0 | L42: 0 | M42: 8 | N42: 0 | O42: =SUM(C42:L42,N42) -> 8 | P42: =SUM(C42:N42) -> 16 | R42: NEF | S42: =S41/S40 -> 1.5438596 | T42: =T41/T40 -> 1.3333333 | U42: =U41/U40 -> 1 | V42: =V41/V40 -> 1.6438356 | W42: =W41/W40 -> #DIV/0! | X42: =X41/X40 -> 4 | Y42: =Y41/Y40 -> 1.4 | Z42: =Z41/Z40 -> 1.3333333 | ... AF42: =AF41/AF40 -> 1.4787234
...

Sheet 26.10 MUTUKULA-MASAKA-24HR
B1: Consultancy services for Preparation of Expressway Development Master Plan (EDMP) for Uganda
B2: MANUAL CLASSIFIED COUNT (MCC)
B3: ROAD NAME: | C3: ='31.10 Masaka-Mutukula'!C3:G3 -> MCC - C4- STN99-MASAKA-MUTUKULA
C5: Date | D5: 26.10.19 | F5: Location | G5: ='26.10 MASAKA-MUTUKULA-24HR'!G5:H5 -> MUTUKULA | J5: Surveyor | K5: WILLIAM
C6: Dir. From | D6: ='31.10.MUTUKULA-MASAKA'!D6:E6 -> MUTUKULA | F6: Dir. To | G6: ='31.10.MUTUKULA-MASAKA'!G6:H6 -> MASAKA | J6: Supervisor | K6: ='26.10 MASAKA-MUTUKULA-24HR'!K6:L6 -> SANDRA
B8: Time / Veh Type | R8: SUMMARY TRAFFIC VOLUMES
C9: 1. Car | D9: 2. Station Wagon | E9: 3. Pickups | F9: 4. Minibus, matatu | G9: 5. Medium bus | H9: 6. Large Bus | I9: 7. Light Truck | J9: 8. Medium Truck | K9: 9. Heavy truck | L9: 10. Truck Trailer | M9: 11. Motor cycles | N9: 12. Tractors | O9: Total Excl M/Cycles | P9: Total All | R9: Time | S9: 1. Car | T9: 2. Station Wagon | U9: 3. Pickups | V9: 4. Minibus, matatu | W9: 5. Medium bus | X9: 6. Large Bus | Y9: 7. Light Truck | Z9: 8. Medium Truck | AA9: 9. Heavy truck | AB9: 10. Truck Trailer | AC9: 11. Motorcycles | AD9: 12. Tractors, Graders | AE9: Total Excl M/ Cycles | AF9: Total All
B10: 07.00 - 07.15 | C10: 2 | D10: 0 | E10: 0 | F10: 1 | G10: 1 | H10: 0 | I10: 2 | J10: 0 | K10: 0 | L10: 0 | M10: 9 | N10: 0 | O10: =SUM(C10:L10,N10) -> 6 | P10: =SUM(C10:N10) -> 15 | R10: 0700-0800 | S10: =SUM(C10:C13) -> 8 | T10: =SUM(D10:D13) -> 0 | U10: =SUM(E10:E13) -> 0 | V10: =SUM(F10:F13) -> 1 | W10: =SUM(G10:G13) -> 2 | X10: =SUM(H10:H13) -> 0 | Y10: =SUM(I10:I13) -> 2 | Z10: =SUM(J10:J13) -> 1 | ... AF10: =SUM(P10:P13) -> 42
B11: 07.15 - 07.30 | C11: 1 | D11: 0 | E11: 0 | F11: 0 | G11: 0 | H11: 0 | I11: 0 | J11: 0 | K11: 0 | L11: 0 | M11: 9 | N11: 0 | O11: =SUM(C11:L11,N11) -> 1 | P11: =SUM(C11:N11) -> 10 | R11: 0800-0900 | S11: =SUM(C14:C17) -> 10 | T11: =SUM(D14:D17) -> 1 | U11: =SUM(E14:E17) -> 0 | V11: =SUM(F14:F17) -> 3 | W11: =SUM(G14:G17) -> 0 | X11: =SUM(H14:H17) -> 0 | Y11: =SUM(I14:I17) -> 0 | Z11: =SUM(J14:J17) -> 0 | ... AF11: =SUM(P14:P17) -> 46
B12: 07.30 - 07.45 | C12: 5 | D12: 0 | E12: 0 | F12: 0 | G12: 0 | H12: 0 | I12: 0 | J12: 0 | K12: 0 | L12: 0 | M12: 1 | N12: 0 | O12: =SUM(C12:L12,N12) -> 5 | P12: =SUM(C12:N12) -> 6 | R12: 0900-1000 | S12: =SUM(C18:C21) -> 10 | T12: =SUM(D18:D21) -> 2 | U12: =SUM(E18:E21) -> 2 | V12: =SUM(F18:F21) -> 7 | W12: =SUM(G18:G21) -> 0 | X12: =SUM(H18:H21) -> 0 | Y12: =SUM(I18:I21) -> 3 | Z12: =SUM(J18:J21) -> 2 | ... AF12: =SUM(P18:P21) -> 68
B13: 07.45 - 08.00 | C13: 0 | D13: 0 | E13: 0 | F13: 0 | G13: 1 | H13: 0 | I13: 0 | J13: 1 | K13: 0 | L13: 0 | M13: 9 | N13: 0 | O13: =SUM(C13:L13,N13) -> 2 | P13: =SUM(C13:N13) -> 11 | R13: 1000-1100 | S13: =SUM(C22:C25) -> 8 | T13: =SUM(D22:D25) -> 3 | U13: =SUM(E22:E25) -> 2 | V13: =SUM(F22:F25) -> 1 | W13: =SUM(G22:G25) -> 0 | X13: =SUM(H22:H25) -> 0 | Y13: =SUM(I22:I25) -> 2 | Z13: =SUM(J22:J25) -> 2 | ... AF13: =SUM(P22:P25) -> 53
B14: 08.00 - 08.15 | C14: 1 | D14: 0 | E14: 0 | F14: 1 | G14: 0 | H14: 0 | I14: 0 | J14: 0 | K14: 0 | L14: 0 | M14: 15 | N14: 0 | O14: =SUM(C14:L14,N14) -> 2 | P14: =SUM(C14:N14) -> 17 | R14: 1100-1200 | S14: =SUM(C26:C29) -> 8 | T14: =SUM(D26:D29) -> 2 | U14: =SUM(E26:E29) -> 0 | V14: =SUM(F26:F29) -> 5 | W14: =SUM(G26:G29) -> 0 | X14: =SUM(H26:H29) -> 0 | Y14: =SUM(I26:I29) -> 7 | Z14: =SUM(J26:J29) -> 0 | ... AF14: =SUM(P26:P29) -> 70
B15: 08.15 - 08.30 | C15: 4 | D15: 1 | E15: 0 | F15: 1 | G15: 0 | H15: 0 | I15: 0 | J15: 0 | K15: 4 | L15: 0 | M15: 4 | N15: 0 | O15: =SUM(C15:L15,N15) -> 10 | P15: =SUM(C15:N15) -> 14 | R15: 1200-1300 | S15: =SUM(C30:C33) -> 14 | T15: =SUM(D30:D33) -> 5 | U15: =SUM(E30:E33) -> 0 | V15: =SUM(F30:F33) -> 5 | W15: =SUM(G30:G33) -> 0 | X15: =SUM(H30:H33) -> 0 | Y15: =SUM(I30:I33) -> 2 | Z15: =SUM(J30:J33) -> 2 | ... AF15: =SUM(P30:P33) -> 65
B16: 08.30 - 08.45 | C16: 2 | D16: 0 | E16: 0 | F16: 0 | G16: 0 | H16: 0 | I16: 0 | J16: 0 | K16: 0 | L16: 0 | M16: 4 | N16: 0 | O16: =SUM(C16:L16,N16) -> 2 | P16: =SUM(C16:N16) -> 6 | R16: 1300-1400 | S16: =SUM(C34:C37) -> 11 | T16: =SUM(D34:D37) -> 2 | U16: =SUM(E34:E37) -> 0 | V16: =SUM(F34:F37) -> 4 | W16: =SUM(G34:G37) -> 0 | X16: =SUM(H34:H37) -> 0 | Y16: =SUM(I34:I37) -> 1 | Z16: =SUM(J34:J37) -> 1 | ... AF16: =SUM(P34:P37) -> 58
B17: 08.45 - 9.00 | C17: 3 | D17: 0 | E17: 0 | F17: 1 | G17: 0 | H17: 0 | I17: 0 | J17: 0 | K17: 0 | L17: 0 | M17: 5 | N17: 0 | O17: =SUM(C17:L17,N17) -> 4 | P17: =SUM(C17:N17) -> 9 | R17: 1400-1500 | S17: =SUM(C38:C41) -> 10 | T17: =SUM(D38:D41) -> 3 | U17: =SUM(E38:E41) -> 3 | V17: =SUM(F38:F41) -> 4 | W17: =SUM(G38:G41) -> 0 | X17: =SUM(H38:H41) -> 0 | Y17: =SUM(I38:I41) -> 5 | Z17: =SUM(J38:J41) -> 3 | ... AF17: =SUM(P38:P41) -> 76
B18: 09.00 - 09.15 | C18: 2 | D18: 2 | E18: 1 | F18: 2 | G18: 0 | H18: 0 | I18: 0 | J18: 0 | K18: 0 | L18: 0 | M18: 10 | N18: 0 | O18: =SUM(C18:L18,N18) -> 7 | P18: =SUM(C18:N18) -> 17 | R18: 1500-1600 | S18: =SUM(C42:C45) -> 14 | T18: =SUM(D42:D45) -> 2 | U18: =SUM(E42:E45) -> 2 | V18: =SUM(F42:F45) -> 8 | W18: =SUM(G42:G45) -> 0 | X18: =SUM(H42:H45) -> 0 | Y18: =SUM(I42:I45) -> 6 | Z18: =SUM(J42:J45) -> 3 | ... AF18: =SUM(P42:P45) -> 73
B19: 09.15 - 09.30 | C19: 1 | D19: 0 | E19: 0 | F19: 1 | G19: 0 | H19: 0 | I19: 0 | J19: 1 | K19: 0 | L19: 0 | M19: 8 | N19: 0 | O19: =SUM(C19:L19,N19) -> 3 | P19: =SUM(C19:N19) -> 11 | R19: 1600-1700 | S19: =SUM(C46:C49) -> 12 | T19: =SUM(D46:D49) -> 4 | U19: =SUM(E46:E49) -> 1 | V19: =SUM(F46:F49) -> 9 | W19: =SUM(G46:G49) -> 0 | X19: =SUM(H46:H49) -> 1 | Y19: =SUM(I46:I49) -> 4 | Z19: =SUM(J46:J49) -> 6 | ... AF19: =SUM(P46:P49) -> 60
B20: 09.30 - 09.45 | C20: 5 | D20: 0 | E20: 1 | F20: 3 | G20: 0 | H20: 0 | I20: 3 | J20: 1 | K20: 0 | L20: 1 | M20: 19 | N20: 0 | O20: =SUM(C20:L20,N20) -> 14 | P20: =SUM(C20:N20) -> 33 | R20: 1700-1800 | S20: =SUM(C50:C53) -> 15 | T20: =SUM(D50:D53) -> 4 | U20: =SUM(E50:E53) -> 0 | V20: =SUM(F50:F53) -> 6 | W20: =SUM(G50:G53) -> 0 | X20: =SUM(H50:H53) -> 0 | Y20: =SUM(I50:I53) -> 4 | Z20: =SUM(J50:J53) -> 0 | ... AF20: =SUM(P50:P53) -> 84
B21: 09.45 - 10.00 | C21: 2 | D21: 0 | E21: 0 | F21: 1 | G21: 0 | H21: 0 | I21: 0 | J21: 0 | K21: 0 | L21: 0 | M21: 4 | N21: 0 | O21: =SUM(C21:L21,N21) -> 3 | P21: =SUM(C21:N21) -> 7 | R21: 1800-1900 | S21: =SUM(C54:C57) -> 14 | T21: =SUM(D54:D57) -> 4 | U21: =SUM(E54:E57) -> 0 | V21: =SUM(F54:F57) -> 12 | W21: =SUM(G54:G57) -> 0 | X21: =SUM(H54:H57) -> 0 | Y21: =SUM(I54:I57) -> 0 | Z21: =SUM(J54:J57) -> 6 | ... AF21: =SUM(P54:P57) -> 107
B22: 10.00 - 10.15 | C22: 2 | D22: 1 | E22: 0 | F22: 0 | G22: 0 | H22: 0 | I22: 0 | J22: 0 | K22: 0 | L22: 0 | M22: 4 | N22: 0 | O22: =SUM(C22:L22,N22) -> 3 | P22: =SUM(C22:N22) -> 7 | R22: 1900-2000 | S22: =SUM(C58:C61) -> 9 | T22: =SUM(D58:D61) -> 6 | U22: =SUM(E58:E61) -> 0 | V22: =SUM(F58:F61) -> 5 | W22: =SUM(G58:G61) -> 0 | X22: =SUM(H58:H61) -> 0 | Y22: =SUM(I58:I61) -> 3 | Z22: =SUM(J58:J61) -> 2 | ... AF22: =SUM(P58:P61) -> 124
B23: 10.15 - 10.30 | C23: 1 | D23: 1 | E23: 0 | F23: 0 | G23: 0 | H23: 0 | I23: 1 | J23: 0 | K23: 0 | L23: 0 | M23: 5 | N23: 0 | O23: =SUM(C23:L23,N23) -> 3 | P23: =SUM(C23:N23) -> 8 | R23: 2000-2100 | S23: =SUM(C62:C65) -> 16 | T23: =SUM(D62:D65) -> 3 | U23: =SUM(E62:E65) -> 1 | V23: =SUM(F62:F65) -> 3 | W23: =SUM(G62:G65) -> 0 | X23: =SUM(H62:H65) -> 0 | Y23: =SUM(I62:I65) -> 4 | Z23: =SUM(J62:J65) -> 7 | ... AF23: =SUM(P62:P65) -> 77
B24: 10.30 - 10.45 | C24: 3 | D24: 0 | E24: 0 | F24: 1 | G24: 0 | H24: 0 | I24: 0 | J24: 2 | K24: 0 | L24: 1 | M24: 6 | N24: 0 | O24: =SUM(C24:L24,N24) -> 7 | P24: =SUM(C24:N24) -> 13 | R24: 2100-2200 | S24: =SUM(C66:C69) -> 12 | T24: =SUM(D66:D69) -> 4 | U24: =SUM(E66:E69) -> 0 | V24: =SUM(F66:F69) -> 1 | W24: =SUM(G66:G69) -> 0 | X24: =SUM(H66:H69) -> 1 | Y24: =SUM(I66:I69) -> 2 | Z24: =SUM(J66:J69) -> 3 | ... AF24: =SUM(P66:P69) -> 62
B25: 10.45 - 11.00 | C25: 2 | D25: 1 | E25: 2 | F25: 0 | G25: 0 | H25: 0 | I25: 1 | J25: 0 | K25: 10 | L25: 0 | M25: 9 | N25: 0 | O25: =SUM(C25:L25,N25) -> 16 | P25: =SUM(C25:N25) -> 25 | R25: 2200-2300 | S25: =SUM(C70:C73) -> 3 | T25: =SUM(D70:D73) -> 2 | U25: =SUM(E70:E73) -> 0 | V25: =SUM(F70:F73) -> 0 | W25: =SUM(G70:G73) -> 0 | X25: =SUM(H70:H73) -> 0 | Y25: =SUM(I70:I73) -> 2 | Z25: =SUM(J70:J73) -> 0 | ... AF25: =SUM(P70:P73) -> 30
B26: 11.00 - 11.15 | C26: 1 | D26: 0 | E26: 0 | F26: 1 | G26: 0 | H26: 0 | I26: 3 | J26: 0 | K26: 0 | L26: 0 | M26: 12 | N26: 0 | O26: =SUM(C26:L26,N26) -> 5 | P26: =SUM(C26:N26) -> 17 | R26: 2300-0000 | S26: =SUM(C74:C77) -> 3 | T26: =SUM(D74:D77) -> 0 | U26: =SUM(E74:E77) -> 0 | V26: =SUM(F74:F77) -> 1 | W26: =SUM(G74:G77) -> 0 | X26: =SUM(H74:H77) -> 0 | Y26: =SUM(I74:I77) -> 1 | Z26: =SUM(J74:J77) -> 0 | ... AF26: =SUM(P74:P77) -> 12
B27: 11.15 - 11.30 | C27: 2 | D27: 0 | E27: 0 | F27: 1 | G27: 0 | H27: 0 | I27: 2 | J27: 0 | K27: 0 | L27: 0 | M27: 11 | N27: 0 | O27: =SUM(C27:L27,N27) -> 5 | P27: =SUM(C27:N27) -> 16 | R27: 0000-0100 | S27: =SUM(C78:C81) -> 0 | T27: =SUM(D78:D81) -> 0 | U27: =SUM(E78:E81) -> 0 | V27: =SUM(F78:F81) -> 2 | W27: =SUM(G78:G81) -> 0 | X27: =SUM(H78:H81) -> 0 | Y27: =SUM(I78:I81) -> 0 | Z27: =SUM(J78:J81) -> 0 | ... AF27: =SUM(P78:P81) -> 3
B28: 11.30 - 11.45 | C28: 2 | D28: 2 | E28: 0 | F28: 3 | G28: 0 | H28: 0 | I28: 1 | J28: 0 | K28: 0 | L28: 0 | M28: 12 | N28: 0 | O28: =SUM(C28:L28,N28) -> 8 | P28: =SUM(C28:N28) -> 20 | R28: 0100-0200 | S28: =SUM(C82:C85) -> 0 | T28: =SUM(D82:D85) -> 0 | U28: =SUM(E82:E85) -> 0 | V28: =SUM(F82:F85) -> 0 | W28: =SUM(G82:G85) -> 0 | X28: =SUM(H82:H85) -> 0 | Y28: =SUM(I82:I85) -> 0 | Z28: =SUM(J82:J85) -> 0 | ... AF28: =SUM(P82:P85) -> 3
B29: 11.45 - 12.00 | C29: 3 | D29: 0 | E29: 0 | F29: 0 | G29: 0 | H29: 0 | I29: 1 | J29: 0 | K29: 0 | L29: 0 | M29: 13 | N29: 0 | O29: =SUM(C29:L29,N29) -> 4 | P29: =SUM(C29:N29) -> 17 | R29: 0200-0300 | S29: =SUM(C86:C89) -> 0 | T29: =SUM(D86:D89) -> 0 | U29: =SUM(E86:E89) -> 0 | V29: =SUM(F86:F89) -> 0 | W29: =SUM(G86:G89) -> 0 | X29: =SUM(H86:H89) -> 0 | Y29: =SUM(I86:I89) -> 0 | Z29: =SUM(J86:J89) -> 0 | ... AF29: =SUM(P86:P89) -> 0
B30: 12.00 - 12.15 | C30: 1 | D30: 1 | E30: 0 | F30: 2 | G30: 0 | H30: 0 | I30: 2 | J30: 1 | K30: 1 | L30: 1 | M30: 5 | N30: 0 | O30: =SUM(C30:L30,N30) -> 9 | P30: =SUM(C30:N30) -> 14 | R30: 0300-0400 | S30: =SUM(C90:C93) -> 0 | T30: =SUM(D90:D93) -> 0 | U30: =SUM(E90:E93) -> 0 | V30: =SUM(F90:F93) -> 0 | W30: =SUM(G90:G93) -> 0 | X30: =SUM(H90:H93) -> 0 | Y30: =SUM(I90:I93) -> 0 | Z30: =SUM(J90:J93) -> 0 | ... AF30: =SUM(P90:P93) -> 0
B31: 12.15 - 12.30 | C31: 4 | D31: 2 | E31: 0 | F31: 1 | G31: 0 | H31: 0 | I31: 0 | J31: 0 | K31: 1 | L31: 0 | M31: 9 | N31: 0 | O31: =SUM(C31:L31,N31) -> 8 | P31: =SUM(C31:N31) -> 17 | R31: 0400-0500 | S31: =SUM(C94:C97) -> 0 | T31: =SUM(D94:D97) -> 0 | U31: =SUM(E94:E97) -> 0 | V31: =SUM(F94:F97) -> 0 | W31: =SUM(G94:G97) -> 0 | X31: =SUM(H94:H97) -> 0 | Y31: =SUM(I94:I97) -> 0 | Z31: =SUM(J94:J97) -> 0 | ... AF31: =SUM(P94:P97) -> 1
B32: 12.30 - 12.45 | C32: 4 | D32: 0 | E32: 0 | F32: 2 | G32: 0 | H32: 0 | I32: 0 | J32: 1 | K32: 1 | L32: 0 | M32: 9 | N32: 0 | O32: =SUM(C32:L32,N32) -> 8 | P32: =SUM(C32:N32) -> 17 | R32: 0500-0600 | S32: =SUM(C98:C101) -> 1 | T32: =SUM(D98:D101) -> 0 | U32: =SUM(E98:E101) -> 0 | V32: =SUM(F98:F101) -> 2 | W32: =SUM(G98:G101) -> 0 | X32: =SUM(H98:H101) -> 0 | Y32: =SUM(I98:I101) -> 0 | Z32: =SUM(J98:J101) -> 0 | ... AF32: =SUM(P98:P101) -> 5
B33: 12.45 - 13.00 | C33: 5 | D33: 2 | E33: 0 | F33: 0 | G33: 0 | H33: 0 | I33: 0 | J33: 0 | K33: 2 | L33: 0 | M33: 8 | N33: 0 | O33: =SUM(C33:L33,N33) -> 9 | P33: =SUM(C33:N33) -> 17 | R33: 0600-0700 | S33: =SUM(C102:C105) -> 0 | T33: =SUM(D102:D105) -> 0 | U33: =SUM(E102:E105) -> 0 | V33: =SUM(F102:F105) -> 5 | W33: =SUM(G102:G105) -> 0 | X33: =SUM(H102:H105) -> 0 | Y33: =SUM(I102:I105) -> 1 | Z33: =SUM(J102:J105) -> 0 | ... AF33: =SUM(P102:P105) -> 11
B34: 13.00 - 13.15 | C34: 3 | D34: 1 | E34: 0 | F34: 1 | G34: 0 | H34: 0 | I34: 0 | J34: 0 | K34: 2 | L34: 0 | M34: 8 | N34: 0 | O34: =SUM(C34:L34,N34) -> 7 | P34: =SUM(C34:N34) -> 15 | R34: AM Peak Hr | S34: =MAX(S10:S12) -> 10 | T34: =MAX(T10:T12) -> 2 | U34: =MAX(U10:U12) -> 2 | V34: =MAX(V10:V12) -> 7 | W34: =MAX(W10:W12) -> 2 | X34: =MAX(X10:X12) -> 0 | Y34: =MAX(Y10:Y12) -> 3 | Z34: =MAX(Z10:Z12) -> 2 | ... AF34: =MAX(AF10:AF12) -> 68
B35: 13.15 - 13.30 | C35: 3 | D35: 1 | E35: 0 | F35: 1 | G35: 0 | H35: 0 | I35: 1 | J35: 0 | K35: 0 | L35: 0 | M35: 6 | N35: 0 | O35: =SUM(C35:L35,N35) -> 6 | P35: =SUM(C35:N35) -> 12 | R35: IP Peak Hr | S35: =MAX(S13:S18) -> 14 | T35: =MAX(T13:T18) -> 5 | U35: =MAX(U13:U18) -> 3 | V35: =MAX(V13:V18) -> 8 | W35: =MAX(W13:W18) -> 0 | X35: =MAX(X13:X18) -> 0 | Y35: =MAX(Y13:Y18) -> 7 | Z35: =MAX(Z13:Z18) -> 3 | ... AF35: =MAX(AF13:AF18) -> 76
B36: 13.30 - 13.45 | C36: 2 | D36: 0 | E36: 0 | F36: 2 | G36: 0 | H36: 0 | I36: 0 | J36: 0 | K36: 0 | L36: 0 | M36: 14 | N36: 0 | O36: =SUM(C36:L36,N36) -> 4 | P36: =SUM(C36:N36) -> 18 | R36: PM Peak Hr | S36: =MAX(S19:S21) -> 15 | T36: =MAX(T19:T21) -> 4 | U36: =MAX(U19:U21) -> 1 | V36: =MAX(V19:V21) -> 12 | W36: =MAX(W19:W21) -> 0 | X36: =MAX(X19:X21) -> 1 | Y36: =MAX(Y19:Y21) -> 4 | Z36: =MAX(Z19:Z21) -> 6 | ... AF36: =MAX(AF19:AF21) -> 107
B37: 13.45 - 14.00 | C37: 3 | D37: 0 | E37: 0 | F37: 0 | G37: 0 | H37: 0 | I37: 0 | J37: 1 | K37: 4 | L37: 0 | M37: 5 | N37: 0 | O37: =SUM(C37:L37,N37) -> 8 | P37: =SUM(C37:N37) -> 13 | R37: AM Period | S37: =SUM(S10:S12) -> 28 | T37: =SUM(T10:T12) -> 3 | U37: =SUM(U10:U12) -> 2 | V37: =SUM(V10:V12) -> 11 | W37: =SUM(W10:W12) -> 2 | X37: =SUM(X10:X12) -> 0 | Y37: =SUM(Y10:Y12) -> 5 | Z37: =SUM(Z10:Z12) -> 3 | ... AF37: =SUM(AF10:AF12) -> 156
B38: 14.00 - 14.15 | C38: 4 | D38: 0 | E38: 3 | F38: 0 | G38: 0 | H38: 0 | I38: 2 | J38: 1 | K38: 0 | L38: 0 | M38: 10 | N38: 0 | O38: =SUM(C38:L38,N38) -> 10 | P38: =SUM(C38:N38) -> 20 | R38: IP Period | S38: =SUM(S13:S18) -> 65 | T38: =SUM(T13:T18) -> 17 | U38: =SUM(U13:U18) -> 7 | V38: =SUM(V13:V18) -> 27 | W38: =SUM(W13:W18) -> 0 | X38: =SUM(X13:X18) -> 0 | Y38: =SUM(Y13:Y18) -> 23 | Z38: =SUM(Z13:Z18) -> 11 | ... AF38: =SUM(AF13:AF18) -> 395
B39: 14.15 - 14.30 | C39: 2 | D39: 3 | E39: 0 | F39: 1 | G39: 0 | H39: 0 | I39: 1 | J39: 0 | K39: 0 | L39: 2 | M39: 10 | N39: 0 | O39: =SUM(C39:L39,N39) -> 9 | P39: =SUM(C39:N39) -> 19 | R39: PM Period | S39: =SUM(S19:S21) -> 41 | T39: =SUM(T19:T21) -> 12 | U39: =SUM(U19:U21) -> 1 | V39: =SUM(V19:V21) -> 27 | W39: =SUM(W19:W21) -> 0 | X39: =SUM(X19:X21) -> 1 | Y39: =SUM(Y19:Y21) -> 8 | Z39: =SUM(Z19:Z21) -> 12 | ... AF39: =SUM(AF19:AF21) -> 251
B40: 14.30 - 14.45 | C40: 3 | D40: 0 | E40: 0 | F40: 1 | G40: 0 | H40: 0 | I40: 0 | J40: 1 | K40: 2 | L40: 0 | M40: 7 | N40: 0 | O40: =SUM(C40:L40,N40) -> 7 | P40: =SUM(C40:N40) -> 14 | R40: 12 Hours | S40: =SUM(S10:S21) -> 134 | T40: =SUM(T10:T21) -> 32 | U40: =SUM(U10:U21) -> 10 | V40: =SUM(V10:V21) -> 65 | W40: =SUM(W10:W21) -> 2 | X40: =SUM(X10:X21) -> 1 | Y40: =SUM(Y10:Y21) -> 36 | Z40: =SUM(Z10:Z21) -> 26 | ... AF40: =SUM(AF10:AF21) -> 802
B41: 14.45 - 15.00 | C41: 1 | D41: 0 | E41: 0 | F41: 2 | G41: 0 | H41: 0 | I41: 2 | J41: 1 | K41: 1 | L41: 0 | M41: 16 | N41: 0 | O41: =SUM(C41:L41,N41) -> 7 | P41: =SUM(C41:N41) -> 23 | R41: 24 Hrs/ADT | S41: =SUM(S10:S33) -> 178 | T41: =SUM(T10:T33) -> 47 | U41: =SUM(U10:U33) -> 11 | V41: =SUM(V10:V33) -> 84 | W41: =SUM(W10:W33) -> 2 | X41: =SUM(X10:X33) -> 2 | Y41: =SUM(Y10:Y33) -> 49 | Z41: =SUM(Z10:Z33) -> 38 | ... AF41: =SUM(AF10:AF33) -> 1130
B42: 15.00 - 15.15 | C42: 2 | D42: 1 | E42: 0 | F42: 3 | G42: 0 | H42: 0 | I42: 1 | J42: 0 | K42: 2 | L42: 0 | M42: 8 | N42: 0 | O42: =SUM(C42:L42,N42) -> 9 | P42: =SUM(C42:N42) -> 17 | R42: NEF | S42: =S41/S40 -> 1.3283582 | T42: =T41/T40 -> 1.46875 | U42: =U41/U40 -> 1.1 | V42: =V41/V40 -> 1.2923077 | W42: =W41/W40 -> 1 | X42: =X41/X40 -> 2 | Y42: =Y41/Y40 -> 1.3611111 | Z42: =Z41/Z40 -> 1.4615385 | ... AF42: =AF41/AF40 -> 1.4089776
...

Sheet 27.10 Masaka-Mutukula
B1: Consultancy services for Preparation of Expressway Development Master Plan (EDMP) for Uganda
B2: MANUAL CLASSIFIED COUNT (MCC)
B3: ROAD NAME: | C3: ='31.10.MUTUKULA-MASAKA'!C3:G3 -> MCC-C4-STN99-MASAKA-MUTUKULA
C5: Date | D5: 27.10.19 | F5: Location | G5: ='25.10 MASAKA-MUTUKULA'!G5:H5 -> MUTUKULA | J5: Surveyor | K5: Walter
C6: Dir. From | D6: MASAKA | F6: Dir. To | G6: MUTUKULA | J6: Supervisor | K6: ='25.10 MASAKA-MUTUKULA'!K6:L6 -> SANDRA
B8: Time / Veh Type | R8: SUMMARY TRAFFIC VOLUMES
C9: 1. Car | D9: 2. Station Wagon | E9: 3. Pickups | F9: 4. Minibus, matatu | G9: 5. Medium bus | H9: 6. Large Bus | I9: 7. Light Truck | J9: 8. Medium Truck | K9: 9. Heavy truck | L9: 10. Truck Trailer | M9: 11. Motor cycles | N9: 12. Tractors | O9: Total Excl M/Cycles | P9: Total All | R9: Time | S9: 1. Car | T9: 2. Station Wagon | U9: 3. Pickups | V9: 4. Minibus, matatu | W9: 5. Medium bus | X9: 6. Large Bus | Y9: 7. Light Truck | Z9: 8. Medium Truck | AA9: 9. Heavy truck | AB9: 10. Truck Trailer | AC9: 11. Motorcycles | AD9: 12. Tractors, Graders | AE9: Total Excl M/ Cycles | AF9: Total All
B10: 07.00 - 07.15 | C10: 1 | D10: 2 | E10: 0 | F10: 0 | G10: 0 | H10: 0 | I10: 0 | J10: 2 | K10: 1 | L10: 0 | M10: 1 | N10: 0 | O10: =SUM(C10:L10,N10) -> 6 | P10: =SUM(C10:N10) -> 7 | R10: 0700-0800 | S10: =SUM(C10:C13) -> 4 | T10: =SUM(D10:D13) -> 2 | U10: =SUM(E10:E13) -> 0 | V10: =SUM(F10:F13) -> 0 | W10: =SUM(G10:G13) -> 0 | X10: =SUM(H10:H13) -> 0 | Y10: =SUM(I10:I13) -> 0 | Z10: =SUM(J10:J13) -> 4 | ... AF10: =SUM(P10:P13) -> 35
B11: 07.15 - 07.30 | C11: 0 | D11: 0 | E11: 0 | F11: 0 | G11: 0 | H11: 0 | I11: 0 | J11: 1 | K11: 0 | L11: 0 | M11: 0 | N11: 0 | O11: =SUM(C11:L11,N11) -> 1 | P11: =SUM(C11:N11) -> 1 | R11: 0800-0900 | S11: =SUM(C14:C17) -> 12 | T11: =SUM(D14:D17) -> 1 | U11: =SUM(E14:E17) -> 0 | V11: =SUM(F14:F17) -> 4 | W11: =SUM(G14:G17) -> 0 | X11: =SUM(H14:H17) -> 1 | Y11: =SUM(I14:I17) -> 2 | Z11: =SUM(J14:J17) -> 1 | ... AF11: =SUM(P14:P17) -> 69
B12: 07.30 - 07.45 | C12: 2 | D12: 0 | E12: 0 | F12: 0 | G12: 0 | H12: 0 | I12: 0 | J12: 0 | K12: 0 | L12: 0 | M12: 7 | N12: 0 | O12: =SUM(C12:L12,N12) -> 2 | P12: =SUM(C12:N12) -> 9 | R12: 0900-1000 | S12: =SUM(C18:C21) -> 9 | T12: =SUM(D18:D21) -> 1 | U12: =SUM(E18:E21) -> 1 | V12: =SUM(F18:F21) -> 4 | W12: =SUM(G18:G21) -> 0 | X12: =SUM(H18:H21) -> 0 | Y12: =SUM(I18:I21) -> 2 | Z12: =SUM(J18:J21) -> 0 | ... AF12: =SUM(P18:P21) -> 86
B13: 07.45 - 08.00 | C13: 1 | D13: 0 | E13: 0 | F13: 0 | G13: 0 | H13: 0 | I13: 0 | J13: 1 | K13: 0 | L13: 0 | M13: 16 | N13: 0 | O13: =SUM(C13:L13,N13) -> 2 | P13: =SUM(C13:N13) -> 18 | R13: 1000-1100 | S13: =SUM(C22:C25) -> 14 | T13: =SUM(D22:D25) -> 0 | U13: =SUM(E22:E25) -> 1 | V13: =SUM(F22:F25) -> 7 | W13: =SUM(G22:G25) -> 0 | X13: =SUM(H22:H25) -> 0 | Y13: =SUM(I22:I25) -> 5 | Z13: =SUM(J22:J25) -> 0 | ... AF13: =SUM(P22:P25) -> 92
B14: 08.00 - 08.15 | C14: 1 | D14: 0 | E14: 0 | F14: 0 | G14: 0 | H14: 0 | I14: 0 | J14: 1 | K14: 0 | L14: 0 | M14: 8 | N14: 0 | O14: =SUM(C14:L14,N14) -> 2 | P14: =SUM(C14:N14) -> 10 | R14: 1100-1200 | S14: =SUM(C26:C29) -> 7 | T14: =SUM(D26:D29) -> 0 | U14: =SUM(E26:E29) -> 0 | V14: =SUM(F26:F29) -> 5 | W14: =SUM(G26:G29) -> 0 | X14: =SUM(H26:H29) -> 0 | Y14: =SUM(I26:I29) -> 2 | Z14: =SUM(J26:J29) -> 0 | ... AF14: =SUM(P26:P29) -> 62
B15: 08.15 - 08.30 | C15: 4 | D15: 1 | E15: 0 | F15: 0 | G15: 0 | H15: 0 | I15: 1 | J15: 0 | K15: 0 | L15: 0 | M15: 13 | N15: 0 | O15: =SUM(C15:L15,N15) -> 6 | P15: =SUM(C15:N15) -> 19 | R15: 1200-1300 | S15: =SUM(C30:C33) -> 10 | T15: =SUM(D30:D33) -> 1 | U15: =SUM(E30:E33) -> 1 | V15: =SUM(F30:F33) -> 9 | W15: =SUM(G30:G33) -> 0 | X15: =SUM(H30:H33) -> 1 | Y15: =SUM(I30:I33) -> 7 | Z15: =SUM(J30:J33) -> 0 | ... AF15: =SUM(P30:P33) -> 75
