Workbook
Name Dist: 'ALL DATA'!$S:$S
Name Jtime: 'ALL DATA'!$T:$T
Name Pay: 'ALL DATA'!$Z:$Z
Name Tripfreq: 'ALL DATA'!$U:$U
Name veh: 'ALL DATA'!$D:$D
Name Veh_Type: '24.08 Kaliro-Iganga'!$D$9:$D$55
Name Veh_Type: '26.08 Kaliro-Iganga'!$D$9:$D$68
Name Veh_Type: 'ALL DATA'!$D$9:$D$63
Name Veh_Type: '[1]25.07 BUSEGA-NATEETE'!$D:$D
Name Veh_Type: '24.08 Iganga-Kaliro'!$D$9:$D$63
Name zones: #REF!
Name zones: #REF!
Name Zones_Ndeke: #REF!
Name Zones_Ndeke: #REF!

Sheet Analysis
B3: Vehicle OD Sample Proportions | N3: Average Journey Time
B4: Vehicle Types | C4: OD Sample | D4: OD Sample, % | N4: Journey Time Range (Hrs) | O4: Cummu-lative | P4: No of Vehicles | Q4: No. of Vehicles, %
B5: Car | C5: =COUNTIF('ALL DATA'!$D$9:$D$5000,"1") -> 79 | D5: =C5/$C$17 -> 0.28014184 | N5: 0-0.25 | O5: =COUNTIF(Jtime,"<=0.25") -> 16 | P5: =O5 -> 16 | Q5: =P5/$O$15 -> 0.057971014
B6: Station Wagon | C6: =COUNTIF('ALL DATA'!$D$9:$D$5000,"2") -> 52 | D6: =C6/$C$17 -> 0.18439716 | N6: 0.25-0.50 | O6: =COUNTIF(Jtime,"<=0.5") -> 109 | P6: =O6-O5 -> 93 | Q6: =P6/$O$15 -> 0.33695652
B7: Pickups | C7: =COUNTIF('ALL DATA'!$D$9:$D$5000,"3") -> 29 | D7: =C7/$C$17 -> 0.10283688 | N7: 0.50-0.75 | O7: =COUNTIF(Jtime,"<=0.75") -> 115 | P7: =O7-O6 -> 6 | Q7: =P7/$O$15 -> 0.02173913
B8: Minibus, matatu | C8: =COUNTIF('ALL DATA'!$D$9:$D$5000,"4") -> 55 | D8: =C8/$C$17 -> 0.19503546 | N8: 0.75-1.00 | O8: =COUNTIF(Jtime,"<=1.0") -> 193 | P8: =O8-O7 -> 78 | Q8: =P8/$O$15 -> 0.2826087
B9: Medium bus | C9: =COUNTIF('ALL DATA'!$D$9:$D$5000,"5") -> 10 | D9: =C9/$C$17 -> 0.035460993 | N9: 1.00-1.50 | O9: =COUNTIF(Jtime,"<=1.5") -> 209 | P9: =O9-O8 -> 16 | Q9: =P9/$O$15 -> 0.057971014
B10: Large Bus | C10: =COUNTIF('ALL DATA'!$D$9:$D$5000,"6") -> 1 | D10: =C10/$C$17 -> 0.0035460993 | N10: 1.5-2.0 | O10: =COUNTIF(Jtime,"<=2") -> 250 | P10: =O10-O9 -> 41 | Q10: =P10/$O$15 -> 0.14855072
B11: Light Truck | C11: =COUNTIF('ALL DATA'!$D$9:$D$5000,"7") -> 17 | D11: =C11/$C$17 -> 0.060283688 | N11: 2.0-3.0 | O11: =COUNTIF(Jtime,"<=3") -> 258 | P11: =O11-O10 -> 8 | Q11: =P11/$O$15 -> 0.028985507
B12: Medium Truck | C12: =COUNTIF('ALL DATA'!$D$9:$D$5000,"8") -> 25 | D12: =C12/$C$17 -> 0.088652482 | N12: 3.0-5.0 | O12: =COUNTIF(Jtime,"<=5") -> 276 | P12: =O12-O11 -> 18 | Q12: =P12/$O$15 -> 0.065217391
B13: Heavy truck | C13: =COUNTIF('ALL DATA'!$D$9:$D$5000,"9") -> 2 | D13: =C13/$C$17 -> 0.0070921986 | N13: 5.0-7.5 | O13: =COUNTIF(Jtime,"<=7.5") -> 276 | P13: =O13-O12 -> 0 | Q13: =P13/$O$15 -> 0
B14: Truck Trailer | C14: =COUNTIF('ALL DATA'!$D$9:$D$5000,"10") -> 0 | D14: =C14/$C$17 -> 0 | N14: 7.5-10 | O14: =COUNTIF(Jtime,"<=10") -> 276 | P14: =O14-O13 -> 0 | Q14: =P14/$O$15 -> 0
B15: Motor cycles | C15: =COUNTIF('ALL DATA'!$D$9:$D$5000,"11") -> 12 | D15: =C15/$C$17 -> 0.042553191 | N15: Over 10 | O15: =COUNTIF(Jtime,"<=15") -> 276 | P15: =O15-O14 -> 0 | Q15: =P15/$O$15 -> 0
B16: Tractors | C16: =COUNTIF('ALL DATA'!$D$9:$D$5000,"12") -> 0 | D16: =C16/$C$17 -> 0
C17: =SUM(C5:C16) -> 282
N21: Trip Frequency
B22: Journey Purpose | N22: Trip Frequency | O22: No of Vehicles | P22: No. of Vehicles, %
B23: Purpose | C23: Respondents | D23: Percent | N23: More than 2 times every day | O23: =COUNTIF(Tripfreq,"=1") -> 15 | P23: =O23/$O$29 -> 0.055762082
B24: Home-Work | C24: =COUNTIF('ALL DATA'!$R$9:$R$5000,"Home-Work") -> 57 | D24: =C24/$C$29 -> 0.20212766 | N24: Daily (Up and Down) | O24: =COUNTIF(Tripfreq,"=2") -> 178 | P24: =O24/$O$29 -> 0.66171004
B25: Home-Study | C25: =COUNTIF('ALL DATA'!$R$9:$R$369,"Home-Study") -> 4 | D25: =C25/$C$29 -> 0.014184397 | N25: 2/3 times a week | O25: =COUNTIF(Tripfreq,"=3") -> 12 | P25: =O25/$O$29 -> 0.044609665
B26: Work-Home | C26: =COUNTIF('ALL DATA'!$R$9:$R$369,"Work-Home") -> 63 | D26: =C26/$C$29 -> 0.22340426 | N26: Once a week | O26: =COUNTIF(Tripfreq,"=4") -> 19 | P26: =O26/$O$29 -> 0.07063197
B27: Work-Work | C27: =COUNTIF('ALL DATA'!$R$9:$R$369,"Work-Work") -> 78 | D27: =C27/$C$29 -> 0.27659574 | N27: Once a month | O27: =COUNTIF(Tripfreq,"=5") -> 8 | P27: =O27/$O$29 -> 0.029739777
B28: Others | C28: =C29-SUM(C24:C27) -> 80 | D28: =C28/$C$29 -> 0.28368794 | N28: Once in a while | O28: =COUNTIF(Tripfreq,"=6") -> 37 | P28: =O28/$O$29 -> 0.13754647
B29: Total | C29: =C17 -> 282 | O29: =SUM(O23:O28) -> 269
B40: Expressway Use
B41: Response | C41: Number | D41: Percent
B42: Yes | C42: =COUNTIF('ALL DATA'!$Y$9:$Y$5000,"Y") -> 209 | D42: =C42/$C$44 -> 0.74113475
B43: No | C43: =C44-C42 -> 73 | D43: =C43/$C$44 -> 0.25886525
B44: Total | C44: =C29 -> 282
R47: Home | S47: Work | T47: Study | U47: Commercial | V47: Tourism | W47: Leisure/Social | X47: Hospital | Y47: Others
P48: 1 | Q48: Home | R48: =R59/SUM($R$59:$Y$66) -> 0.021276596 | S48: =S59/SUM($R$59:$Y$66) -> 0.20212766 | T48: =T59/SUM($R$59:$Y$66) -> 0.014184397 | U48: =U59/SUM($R$59:$Y$66) -> 0.0070921986 | V48: =V59/SUM($R$59:$Y$66) -> 0 | W48: =W59/SUM($R$59:$Y$66) -> 0 | X48: =X59/SUM($R$59:$Y$66) -> 0.024822695 | Y48: =Y59/SUM($R$59:$Y$66) -> 0.081560284
P49: 2 | Q49: Work | R49: =R60/SUM($R$59:$Y$66) -> 0.22340426 | S49: =S60/SUM($R$59:$Y$66) -> 0.27659574 | T49: =T60/SUM($R$59:$Y$66) -> 0 | U49: =U60/SUM($R$59:$Y$66) -> 0 | V49: =V60/SUM($R$59:$Y$66) -> 0 | W49: =W60/SUM($R$59:$Y$66) -> 0 | X49: =X60/SUM($R$59:$Y$66) -> 0.0070921986 | Y49: =Y60/SUM($R$59:$Y$66) -> 0.014184397
P50: 3 | Q50: Study | R50: =R61/SUM($R$59:$Y$66) -> 0.0070921986 | S50: =S61/SUM($R$59:$Y$66) -> 0 | T50: =T61/SUM($R$59:$Y$66) -> 0.0035460993 | U50: =U61/SUM($R$59:$Y$66) -> 0 | V50: =V61/SUM($R$59:$Y$66) -> 0 | W50: =W61/SUM($R$59:$Y$66) -> 0 | X50: =X61/SUM($R$59:$Y$66) -> 0 | Y50: =Y61/SUM($R$59:$Y$66) -> 0.0070921986
P51: 4 | Q51: Commercial | R51: =R62/SUM($R$59:$Y$66) -> 0.0035460993 | S51: =S62/SUM($R$59:$Y$66) -> 0 | T51: =T62/SUM($R$59:$Y$66) -> 0 | U51: =U62/SUM($R$59:$Y$66) -> 0.0070921986 | V51: =V62/SUM($R$59:$Y$66) -> 0 | W51: =W62/SUM($R$59:$Y$66) -> 0 | X51: =X62/SUM($R$59:$Y$66) -> 0 | Y51: =Y62/SUM($R$59:$Y$66) -> 0
P52: 5 | Q52: Tourism | R52: =R63/SUM($R$59:$Y$66) -> 0 | S52: =S63/SUM($R$59:$Y$66) -> 0 | T52: =T63/SUM($R$59:$Y$66) -> 0 | U52: =U63/SUM($R$59:$Y$66) -> 0 | V52: =V63/SUM($R$59:$Y$66) -> 0 | W52: =W63/SUM($R$59:$Y$66) -> 0 | X52: =X63/SUM($R$59:$Y$66) -> 0 | Y52: =Y63/SUM($R$59:$Y$66) -> 0
P53: 6 | Q53: Leisure/Social | R53: =R64/SUM($R$59:$Y$66) -> 0 | S53: =S64/SUM($R$59:$Y$66) -> 0 | T53: =T64/SUM($R$59:$Y$66) -> 0 | U53: =U64/SUM($R$59:$Y$66) -> 0 | V53: =V64/SUM($R$59:$Y$66) -> 0 | W53: =W64/SUM($R$59:$Y$66) -> 0 | X53: =X64/SUM($R$59:$Y$66) -> 0 | Y53: =Y64/SUM($R$59:$Y$66) -> 0
P54: 7 | Q54: Hospital | R54: =R65/SUM($R$59:$Y$66) -> 0.010638298 | S54: =S65/SUM($R$59:$Y$66) -> 0 | T54: =T65/SUM($R$59:$Y$66) -> 0 | U54: =U65/SUM($R$59:$Y$66) -> 0 | V54: =V65/SUM($R$59:$Y$66) -> 0 | W54: =W65/SUM($R$59:$Y$66) -> 0 | X54: =X65/SUM($R$59:$Y$66) -> 0 | Y54: =Y65/SUM($R$59:$Y$66) -> 0
P55: 8 | Q55: Others | R55: =R66/SUM($R$59:$Y$66) -> 0.067375887 | S55: =S66/SUM($R$59:$Y$66) -> 0.0035460993 | T55: =T66/SUM($R$59:$Y$66) -> 0 | U55: =U66/SUM($R$59:$Y$66) -> 0 | V55: =V66/SUM($R$59:$Y$66) -> 0 | W55: =W66/SUM($R$59:$Y$66) -> 0 | X55: =X66/SUM($R$59:$Y$66) -> 0 | Y55: =Y66/SUM($R$59:$Y$66) -> 0.017730496
R57: 1 | S57: 2 | T57: 3 | U57: 4 | V57: 5 | W57: 6 | X57: 7 | Y57: 8
B58: Willingness to Pay | R58: Home | S58: Work | T58: Study | U58: Commercial | V58: Tourism | W58: Leisure/Social | X58: Hospital | Y58: Others
...

Sheet ALL DATA
B1: Consultancy services for Preparation of Expressway Development Master Plan (EDMP) for Uganda
B2: Roadside OD Interview Survey
B4: Date: | C4: 24.08.19 | E4: Road Name: | F4: Iganga-Kaliro Rd | I4: Direction From: | L4: Iganga | N4: Interviewers: | O4: Kirabo Edith | V4: Supervisor: | W4: Felix C. | Y4: Coded By: | Z4: Isaac Akure | AA4: Chkd By: | AB4: Isaac M.
I5: Direction To: | L5: Kaliro
B7: Time | C7: Veh_Reg_No. | D7: Veh_Type | E7: No. Occupants | F7: Origin_Address | I7: Origin_Establish | J7: Origin_Purpose | K7: Origin-Purpose Desc | L7: Destination_Address | O7: Destination_Establish | P7: Destination_Purpose | Q7: Destination_Purpose Desc | R7: Journey_Purpose | S7: Approx_Distance (Km) | T7: Approx_Journey Time (Hrs) | U7: Trip_Frequency | V7: GOODS VEHICLES ONLY | Y7: Would You Use Xpressways? | Z7: Pay How Much? (UGX) | AA7: Origin_Zone | AB7: Dest_Zone
F8: Village or Town | G8: District | H8: Country | L8: Village or Town | M8: District | N8: Country | V8: Goods_Type | W8: Goods_Quantity (Ton) | X8: Goods_Value (UGXm)
B9: 0.43680556 | C9: UBB 204G | D9: 1 | E9: 1 | F9: Entebbe | G9: Wakiso | H9: Uga | I9: 16 | J9: 8 | K9: =VLOOKUP(J9,Key!$E$2:$F$9,2,FALSE) -> Others | L9: Kabira | M9: Iganga | N9: Uga | O9: 1 | P9: 1 | Q9: =VLOOKUP(P9,Key!$E$2:$F$9,2,FALSE) -> Home | R9: =K9&"-"&Q9 -> Others-Home | S9: 27 | T9: 1 | U9: 2 | Y9: Y | AA9: =VLOOKUP(F9,Zones!$A$2:$F$151534,6,FALSE) -> 1388 | AB9: =VLOOKUP(L9,Zones!$A$2:$F$151477,6,FALSE) -> 845
B10: 0.43055556 | C10: UAJ 283F | D10: 1 | E10: 2 | F10: Jinja | G10: Jinja | H10: Uga | I10: 1 | J10: 1 | K10: =VLOOKUP(J10,Key!$E$2:$F$9,2,FALSE) -> Home | L10: Kaliro | M10: Kaliro | N10: Uga | O10: 3 | P10: 2 | Q10: =VLOOKUP(P10,Key!$E$2:$F$9,2,FALSE) -> Work | R10: =K10&"-"&Q10 -> Home-Work | S10: 1 | T10: 1 | U10: 2 | Y10: Y | AA10: =VLOOKUP(F10,Zones!$A$2:$F$151534,6,FALSE) -> 403 | AB10: =VLOOKUP(L10,Zones!$A$2:$F$151477,6,FALSE) -> 498
B11: 0.020138889 | C11: UAN 195Q | D11: 1 | E11: 4 | F11: Mukono | G11: Mukono | H11: Uga | I11: 1 | J11: 1 | K11: =VLOOKUP(J11,Key!$E$2:$F$9,2,FALSE) -> Home | L11: Kaliro | M11: Kaliro | N11: Uga | O11: 10 | P11: 2 | Q11: =VLOOKUP(P11,Key!$E$2:$F$9,2,FALSE) -> Work | R11: =K11&"-"&Q11 -> Home-Work | S11: 5 | T11: 1 | U11: 2 | Y11: Y | AA11: =VLOOKUP(F11,Zones!$A$2:$F$151534,6,FALSE) -> 1064 | AB11: =VLOOKUP(L11,Zones!$A$2:$F$151477,6,FALSE) -> 498
B12: 0.48472222 | C12: UBA 865V | D12: 1 | E12: 1 | F12: Kampala | G12: Kampala | H12: Uga | I12: 1 | J12: 1 | K12: =VLOOKUP(J12,Key!$E$2:$F$9,2,FALSE) -> Home | L12: Namungalwe | M12: Iganga | N12: Uga | O12: 16 | P12: 8 | Q12: =VLOOKUP(P12,Key!$E$2:$F$9,2,FALSE) -> Others | R12: =K12&"-"&Q12 -> Home-Others | S12: 160 | T12: 4 | U12: 2 | Y12: Y | AA12: =VLOOKUP(F12,Zones!$A$2:$F$151534,6,FALSE) -> 521 | AB12: =VLOOKUP(L12,Zones!$A$2:$F$151477,6,FALSE) -> 373
B13: 0.47777778 | C13: UAS 126A | D13: 4 | E13: 14 | F13: Iganga | G13: Iganga | H13: Uga | I13: 6 | J13: 2 | K13: =VLOOKUP(J13,Key!$E$2:$F$9,2,FALSE) -> Work | L13: Kaliro | M13: Kaliro | N13: Uga | O13: 6 | P13: 2 | Q13: =VLOOKUP(P13,Key!$E$2:$F$9,2,FALSE) -> Work | R13: =K13&"-"&Q13 -> Work-Work | S13: 15 | T13: 2 | U13: 2 | Y13: Y | AA13: =VLOOKUP(F13,Zones!$A$2:$F$151534,6,FALSE) -> 365 | AB13: =VLOOKUP(L13,Zones!$A$2:$F$151477,6,FALSE) -> 498
B14: 0.48055556 | C14: UAW 781F | D14: 3 | E14: 6 | F14: Bugerwi | G14: Iganga | H14: Uga | I14: 1 | J14: 1 | K14: =VLOOKUP(J14,Key!$E$2:$F$9,2,FALSE) -> Home | L14: Namungalwe | M14: Iganga | N14: Uga | O14: 16 | P14: 2 | Q14: =VLOOKUP(P14,Key!$E$2:$F$9,2,FALSE) -> Work | R14: =K14&"-"&Q14 -> Home-Work | S14: 10 | T14: 0.3 | U14: 2 | Y14: Y | AA14: =VLOOKUP(F14,Zones!$A$2:$F$151534,6,FALSE) -> 362 | AB14: =VLOOKUP(L14,Zones!$A$2:$F$151477,6,FALSE) -> 373
B15: 0.43402778 | C15: UAE 400F | D15: 8 | E15: 1 | F15: Iganga | G15: Iganga | H15: Uga | I15: 1 | J15: 1 | K15: =VLOOKUP(J15,Key!$E$2:$F$9,2,FALSE) -> Home | L15: Namungalwe | M15: Iganga | N15: Uga | O15: 16 | P15: 8 | Q15: =VLOOKUP(P15,Key!$E$2:$F$9,2,FALSE) -> Others | R15: =K15&"-"&Q15 -> Home-Others | S15: 16 | T15: 0.5 | U15: 2 | Y15: Y | AA15: =VLOOKUP(F15,Zones!$A$2:$F$151534,6,FALSE) -> 365 | AB15: =VLOOKUP(L15,Zones!$A$2:$F$151477,6,FALSE) -> 373
B16: 0.47638889 | C16: UAJ 126D | D16: 8 | E16: 3 | F16: Iganga | G16: Iganga | H16: Uga | I16: 1 | J16: 1 | K16: =VLOOKUP(J16,Key!$E$2:$F$9,2,FALSE) -> Home | L16: Magamaga | M16: Iganga | N16: Uga | O16: 10 | P16: 2 | Q16: =VLOOKUP(P16,Key!$E$2:$F$9,2,FALSE) -> Work | R16: =K16&"-"&Q16 -> Home-Work | T16: 0.5 | U16: 2 | Y16: Y | AA16: =VLOOKUP(F16,Zones!$A$2:$F$151534,6,FALSE) -> 365 | AB16: =VLOOKUP(L16,Zones!$A$2:$F$151477,6,FALSE) -> 954
B17: 0.41319444 | C17: UAY 720N | D17: 3 | E17: 4 | F17: Iganga | G17: Iganga | H17: Uga | I17: 1 | J17: 1 | K17: =VLOOKUP(J17,Key!$E$2:$F$9,2,FALSE) -> Home | L17: Namungalwe | M17: Iganga | N17: Uga | O17: 16 | P17: 8 | Q17: =VLOOKUP(P17,Key!$E$2:$F$9,2,FALSE) -> Others | R17: =K17&"-"&Q17 -> Home-Others | S17: 10 | T17: 0.5 | U17: 2 | Y17: Y | AA17: =VLOOKUP(F17,Zones!$A$2:$F$151534,6,FALSE) -> 365 | AB17: =VLOOKUP(L17,Zones!$A$2:$F$151477,6,FALSE) -> 373
B18: 0.40833333 | C18: UAX 893Y | D18: 8 | E18: 3 | F18: Iganga | G18: Iganga | H18: Uga | I18: 16 | J18: 8 | K18: =VLOOKUP(J18,Key!$E$2:$F$9,2,FALSE) -> Others | L18: Irinda | M18: Iganga | N18: Uga | O18: 16 | P18: 8 | Q18: =VLOOKUP(P18,Key!$E$2:$F$9,2,FALSE) -> Others | R18: =K18&"-"&Q18 -> Others-Others | S18: 85 | T18: 2 | U18: 2 | Y18: Y | AA18: =VLOOKUP(F18,Zones!$A$2:$F$151534,6,FALSE) -> 365 | AB18: =VLOOKUP(L18,Zones!$A$2:$F$151477,6,FALSE) -> 365
B19: 0.42638889 | C19: UBA 982B | D19: 1 | E19: 4 | F19: Jinja | G19: Jinja | H19: Uga | I19: 1 | J19: 1 | K19: =VLOOKUP(J19,Key!$E$2:$F$9,2,FALSE) -> Home | L19: Kaliro | M19: Kaliro | N19: Uga | O19: 4 | P19: 3 | Q19: =VLOOKUP(P19,Key!$E$2:$F$9,2,FALSE) -> Study | R19: =K19&"-"&Q19 -> Home-Study | T19: 0.5 | U19: 2 | Y19: Y | AA19: =VLOOKUP(F19,Zones!$A$2:$F$151534,6,FALSE) -> 403 | AB19: =VLOOKUP(L19,Zones!$A$2:$F$151477,6,FALSE) -> 498
B20: 0.425 | C20: UAK 473X | D20: 5 | E20: 28 | F20: Jinja | G20: Jinja | H20: Uga | I20: 6 | J20: 2 | K20: =VLOOKUP(J20,Key!$E$2:$F$9,2,FALSE) -> Work | L20: Kaliro | M20: Kaliro | N20: Uga | O20: 6 | P20: 2 | Q20: =VLOOKUP(P20,Key!$E$2:$F$9,2,FALSE) -> Work | R20: =K20&"-"&Q20 -> Work-Work | S20: 30 | T20: 3 | U20: 6 | Y20: Y | AA20: =VLOOKUP(F20,Zones!$A$2:$F$151534,6,FALSE) -> 403 | AB20: =VLOOKUP(L20,Zones!$A$2:$F$151477,6,FALSE) -> 498
B21: 0.4375 | C21: UAL 681Z | D21: 8 | E21: 3 | F21: Kakira | G21: Iganga | H21: Uga | I21: 3 | J21: 2 | K21: =VLOOKUP(J21,Key!$E$2:$F$9,2,FALSE) -> Work | L21: Kaliro | M21: Kaliro | N21: Uga | O21: 16 | P21: 8 | Q21: =VLOOKUP(P21,Key!$E$2:$F$9,2,FALSE) -> Others | R21: =K21&"-"&Q21 -> Work-Others | T21: 0.7 | U21: 4 | Y21: Y | AA21: =VLOOKUP(F21,Zones!$A$2:$F$151534,6,FALSE) -> 404 | AB21: =VLOOKUP(L21,Zones!$A$2:$F$151477,6,FALSE) -> 498
B22: 0.43819444 | C22: UAL 758V | D22: 1 | E22: 2 | F22: Busesa | G22: Iganga | H22: Uga | I22: 1 | J22: 1 | K22: =VLOOKUP(J22,Key!$E$2:$F$9,2,FALSE) -> Home | L22: Nabitovu | M22: Iganga | N22: Uga | O22: 3 | P22: 2 | Q22: =VLOOKUP(P22,Key!$E$2:$F$9,2,FALSE) -> Work | R22: =K22&"-"&Q22 -> Home-Work | S22: 15 | T22: 0.8 | U22: 2 | Y22: Y | AA22: =VLOOKUP(F22,Zones!$A$2:$F$151534,6,FALSE) -> 364 | AB22: =VLOOKUP(L22,Zones!$A$2:$F$151477,6,FALSE) -> 372
B23: 0.42361111 | C23: UAZ 355H | D23: 8 | E23: 2 | F23: Iganga | G23: Iganga | H23: Uga | I23: 1 | J23: 1 | K23: =VLOOKUP(J23,Key!$E$2:$F$9,2,FALSE) -> Home | L23: Kyani | M23: Kaliro | N23: Uga | O23: 10 | P23: 2 | Q23: =VLOOKUP(P23,Key!$E$2:$F$9,2,FALSE) -> Work | R23: =K23&"-"&Q23 -> Home-Work | T23: 0.5 | U23: 2 | Y23: Y | AA23: =VLOOKUP(F23,Zones!$A$2:$F$151534,6,FALSE) -> 365 | AB23: =VLOOKUP(L23,Zones!$A$2:$F$151477,6,FALSE) -> 495
B24: 0.42777778 | C24: UAK 002F | D24: 1 | E24: 5 | F24: Iganga | G24: Iganga | H24: Uga | I24: 4 | J24: 3 | K24: =VLOOKUP(J24,Key!$E$2:$F$9,2,FALSE) -> Study | L24: Kaliro | M24: Kaliro | N24: Uga | O24: 1 | P24: 1 | Q24: =VLOOKUP(P24,Key!$E$2:$F$9,2,FALSE) -> Home | R24: =K24&"-"&Q24 -> Study-Home | T24: 0.5 | U24: 5 | Y24: Y | AA24: =VLOOKUP(F24,Zones!$A$2:$F$151534,6,FALSE) -> 365 | AB24: =VLOOKUP(L24,Zones!$A$2:$F$151477,6,FALSE) -> 498
B25: 0.39097222 | C25: UAV 252E | D25: 4 | E25: 2 | F25: Iganga | G25: Iganga | H25: Uga | I25: 1 | J25: 1 | K25: =VLOOKUP(J25,Key!$E$2:$F$9,2,FALSE) -> Home | L25: Bunyiiro | M25: Iganga | N25: Uga | O25: 6 | P25: 2 | Q25: =VLOOKUP(P25,Key!$E$2:$F$9,2,FALSE) -> Work | R25: =K25&"-"&Q25 -> Home-Work | S25: 5 | T25: 0.1 | U25: 4 | Y25: Y | AA25: =VLOOKUP(F25,Zones!$A$2:$F$151534,6,FALSE) -> 365 | AB25: =VLOOKUP(L25,Zones!$A$2:$F$151477,6,FALSE) -> 373
B26: 0.39166667 | C26: UAQ 598E | D26: 4 | E26: 1 | F26: Iganga | G26: Iganga | H26: Uga | I26: 1 | J26: 1 | K26: =VLOOKUP(J26,Key!$E$2:$F$9,2,FALSE) -> Home | L26: Nawangaiza | M26: Iganga | N26: Uga | O26: 6 | P26: 2 | Q26: =VLOOKUP(P26,Key!$E$2:$F$9,2,FALSE) -> Work | R26: =K26&"-"&Q26 -> Home-Work | T26: 0.5 | U26: 1 | Y26: Y | AA26: =VLOOKUP(F26,Zones!$A$2:$F$151534,6,FALSE) -> 365 | AB26: =VLOOKUP(L26,Zones!$A$2:$F$151477,6,FALSE) -> 374
B27: 0.38819444 | C27: UAZ 329W | D27: 8 | E27: 3 | F27: Magamaga | G27: Iganga | H27: Uga | I27: 1 | J27: 1 | K27: =VLOOKUP(J27,Key!$E$2:$F$9,2,FALSE) -> Home | L27: Kaliro | M27: Kaliro | N27: Uga | O27: 3 | P27: 2 | Q27: =VLOOKUP(P27,Key!$E$2:$F$9,2,FALSE) -> Work | R27: =K27&"-"&Q27 -> Home-Work | T27: 0.8 | U27: 2 | Y27: Y | AA27: =VLOOKUP(F27,Zones!$A$2:$F$151534,6,FALSE) -> 954 | AB27: =VLOOKUP(L27,Zones!$A$2:$F$151477,6,FALSE) -> 498
B28: 0.38541667 | C28: UEN 384H | D28: 11 | E28: 2 | F28: Iganga | G28: Iganga | H28: Uga | I28: 8 | J28: 2 | K28: =VLOOKUP(J28,Key!$E$2:$F$9,2,FALSE) -> Work | L28: Buwolera | M28: Iganga | N28: Uga | O28: 8 | P28: 2 | Q28: =VLOOKUP(P28,Key!$E$2:$F$9,2,FALSE) -> Work | R28: =K28&"-"&Q28 -> Work-Work | S28: 8 | T28: 0.5 | U28: 2 | Y28: Y | AA28: =VLOOKUP(F28,Zones!$A$2:$F$151534,6,FALSE) -> 365 | AB28: =VLOOKUP(L28,Zones!$A$2:$F$151477,6,FALSE) -> 400
B29: 0.39652778 | C29: UAL 373H | D29: 3 | E29: 5 | F29: Iganga | G29: Iganga | H29: Uga | I29: 1 | J29: 1 | K29: =VLOOKUP(J29,Key!$E$2:$F$9,2,FALSE) -> Home | L29: Bunyiiro | M29: Iganga | N29: Uga | O29: 10 | P29: 2 | Q29: =VLOOKUP(P29,Key!$E$2:$F$9,2,FALSE) -> Work | R29: =K29&"-"&Q29 -> Home-Work | S29: 3 | T29: 0.5 | U29: 2 | Y29: Y | AA29: =VLOOKUP(F29,Zones!$A$2:$F$151534,6,FALSE) -> 365 | AB29: =VLOOKUP(L29,Zones!$A$2:$F$151477,6,FALSE) -> 373
B30: 0.39444444 | C30: UAZ 293J | D30: 5 | E30: 30 | F30: Kayunga | G30: Kayunga | H30: Uga | I30: 6 | J30: 2 | K30: =VLOOKUP(J30,Key!$E$2:$F$9,2,FALSE) -> Work | L30: Kilama | M30: Kibaale | N30: Uga | O30: 6 | P30: 2 | Q30: =VLOOKUP(P30,Key!$E$2:$F$9,2,FALSE) -> Work | R30: =K30&"-"&Q30 -> Work-Work | T30: 1 | U30: 4 | Y30: Y | Z30: 20000 | AA30: =VLOOKUP(F30,Zones!$A$2:$F$151534,6,FALSE) -> 685 | AB30: =VLOOKUP(L30,Zones!$A$2:$F$151477,6,FALSE) -> 693
B31: 0.36458333 | C31: UBA 419Q | D31: 8 | E31: 3 | F31: Iganga | G31: Iganga | H31: Uga | I31: 1 | J31: 1 | K31: =VLOOKUP(J31,Key!$E$2:$F$9,2,FALSE) -> Home | L31: Namungalwe | M31: Iganga | N31: Uga | O31: 10 | P31: 2 | Q31: =VLOOKUP(P31,Key!$E$2:$F$9,2,FALSE) -> Work | R31: =K31&"-"&Q31 -> Home-Work | S31: 6 | T31: 0.4 | U31: 4 | Y31: Y | AA31: =VLOOKUP(F31,Zones!$A$2:$F$151534,6,FALSE) -> 365 | AB31: =VLOOKUP(L31,Zones!$A$2:$F$151477,6,FALSE) -> 373
B32: 0.35972222 | C32: UBC 278D | D32: 4 | E32: 14 | F32: Jinja | G32: Jinja | H32: Uga | I32: 6 | J32: 2 | K32: =VLOOKUP(J32,Key!$E$2:$F$9,2,FALSE) -> Work | L32: Kilama | M32: Iganga | N32: Uga | O32: 6 | P32: 2 | Q32: =VLOOKUP(P32,Key!$E$2:$F$9,2,FALSE) -> Work | R32: =K32&"-"&Q32 -> Work-Work | T32: 1 | U32: 4 | Y32: Y | Z32: 1000 | AA32: =VLOOKUP(F32,Zones!$A$2:$F$151534,6,FALSE) -> 403 | AB32: =VLOOKUP(L32,Zones!$A$2:$F$151477,6,FALSE) -> 693
B33: 0.70625 | C33: UAW 666X | D33: 1 | E33: 2 | F33: Iganga | G33: Iganga | H33: Uga | I33: 2 | J33: 2 | K33: =VLOOKUP(J33,Key!$E$2:$F$9,2,FALSE) -> Work | L33: Bunyiiro | M33: Iganga | N33: Uga | O33: 1 | P33: 1 | Q33: =VLOOKUP(P33,Key!$E$2:$F$9,2,FALSE) -> Home | R33: =K33&"-"&Q33 -> Work-Home | S33: 2 | T33: 0.5 | U33: 2 | Y33: Y | AA33: =VLOOKUP(F33,Zones!$A$2:$F$151534,6,FALSE) -> 365 | AB33: =VLOOKUP(L33,Zones!$A$2:$F$151477,6,FALSE) -> 373
B34: 0.71666667 | C34: UBC 299T | D34: 1 | E34: 4 | F34: Iganga | G34: Iganga | H34: Uga | I34: 14 | J34: 8 | K34: =VLOOKUP(J34,Key!$E$2:$F$9,2,FALSE) -> Others | L34: Kaliro | M34: Kaliro | N34: Uga | O34: 1 | P34: 1 | Q34: =VLOOKUP(P34,Key!$E$2:$F$9,2,FALSE) -> Home | R34: =K34&"-"&Q34 -> Others-Home | S34: 15 | T34: 0.8 | U34: 2 | Y34: Y | AA34: =VLOOKUP(F34,Zones!$A$2:$F$151534,6,FALSE) -> 365 | AB34: =VLOOKUP(L34,Zones!$A$2:$F$151477,6,FALSE) -> 498
B35: 0.72361111 | C35: UAE 723H | D35: 2 | E35: 3 | F35: Iganga | G35: Iganga | H35: Uga | I35: 16 | J35: 8 | K35: =VLOOKUP(J35,Key!$E$2:$F$9,2,FALSE) -> Others | L35: Bunyiiro | M35: Iganga | N35: Uga | O35: 1 | P35: 1 | Q35: =VLOOKUP(P35,Key!$E$2:$F$9,2,FALSE) -> Home | R35: =K35&"-"&Q35 -> Others-Home | S35: 15 | T35: 2 | U35: 2 | Y35: Y | AA35: =VLOOKUP(F35,Zones!$A$2:$F$151534,6,FALSE) -> 365 | AB35: =VLOOKUP(L35,Zones!$A$2:$F$151477,6,FALSE) -> 373
B36: 0.73263889 | C36: UAV 662X | D36: 7 | E36: 4 | F36: Bugiri | G36: Bugiri | H36: Uga | I36: 10 | J36: 2 | K36: =VLOOKUP(J36,Key!$E$2:$F$9,2,FALSE) -> Work | L36: Bunyiiro | M36: Iganga | N36: Uga | O36: 1 | P36: 1 | Q36: =VLOOKUP(P36,Key!$E$2:$F$9,2,FALSE) -> Home | R36: =K36&"-"&Q36 -> Work-Home | S36: 20 | T36: 2 | U36: 4 | Y36: Y | AA36: =VLOOKUP(F36,Zones!$A$2:$F$151534,6,FALSE) -> 145 | AB36: =VLOOKUP(L36,Zones!$A$2:$F$151477,6,FALSE) -> 373
B37: 0.74166667 | C37: UBD 600D | D37: 4 | E37: 14 | F37: Iganga | G37: Iganga | H37: Uga | I37: 6 | J37: 2 | K37: =VLOOKUP(J37,Key!$E$2:$F$9,2,FALSE) -> Work | L37: Bunyiiro | M37: Iganga | N37: Uga | O37: 6 | P37: 2 | Q37: =VLOOKUP(P37,Key!$E$2:$F$9,2,FALSE) -> Work | R37: =K37&"-"&Q37 -> Work-Work | S37: 27 | T37: 1.5 | U37: 2 | Y37: Y | AA37: =VLOOKUP(F37,Zones!$A$2:$F$151534,6,FALSE) -> 365 | AB37: =VLOOKUP(L37,Zones!$A$2:$F$151477,6,FALSE) -> 373
B38: 0.46597222 | C38: UAY 781C | D38: 1 | E38: 4 | F38: Entebbe | G38: Kampala | H38: Uga | I38: 1 | J38: 1 | K38: =VLOOKUP(J38,Key!$E$2:$F$9,2,FALSE) -> Home | L38: Nabigalata | M38: Namutumba | N38: Uga | O38: 16 | P38: 8 | Q38: =VLOOKUP(P38,Key!$E$2:$F$9,2,FALSE) -> Others | R38: =K38&"-"&Q38 -> Home-Others | S38: 160 | T38: 2 | U38: 6 | Y38: Y | AA38: =VLOOKUP(F38,Zones!$A$2:$F$151534,6,FALSE) -> 1388 | AB38: =VLOOKUP(L38,Zones!$A$2:$F$151477,6,FALSE) -> 1135
B39: 0.47430556 | C39: UAJ 344A | D39: 2 | E39: 4 | F39: Iganga | G39: Iganga | H39: Uga | I39: 2 | J39: 2 | K39: =VLOOKUP(J39,Key!$E$2:$F$9,2,FALSE) -> Work | L39: Kaliro | M39: Kaliro | N39: Uga | O39: 1 | P39: 1 | Q39: =VLOOKUP(P39,Key!$E$2:$F$9,2,FALSE) -> Home | R39: =K39&"-"&Q39 -> Work-Home | T39: 0.4 | U39: 2 | Y39: N | AA39: =VLOOKUP(F39,Zones!$A$2:$F$151534,6,FALSE) -> 365 | AB39: =VLOOKUP(L39,Zones!$A$2:$F$151477,6,FALSE) -> 498
B40: 0.41458333 | C40: UBA 707P | D40: 2 | E40: 6 | F40: Mbalala | G40: Mukono | H40: Uga | I40: 1 | J40: 1 | K40: =VLOOKUP(J40,Key!$E$2:$F$9,2,FALSE) -> Home | L40: Kilama | M40: Iganga | N40: Uga | O40: 16 | P40: 8 | Q40: =VLOOKUP(P40,Key!$E$2:$F$9,2,FALSE) -> Others | R40: =K40&"-"&Q40 -> Home-Others | S40: 45 | T40: 2 | U40: 6 | Y40: Y | Z40: 2000 | AA40: =VLOOKUP(F40,Zones!$A$2:$F$151534,6,FALSE) -> 1064 | AB40: =VLOOKUP(L40,Zones!$A$2:$F$151477,6,FALSE) -> 693
B41: 0.41388889 | C41: UBD 162K | D41: 1 | E41: 3 | F41: Iganga | G41: Iganga | H41: Uga | I41: 1 | J41: 1 | K41: =VLOOKUP(J41,Key!$E$2:$F$9,2,FALSE) -> Home | L41: Kigulu | M41: Iganga | N41: Uga | O41: 2 | P41: 2 | Q41: =VLOOKUP(P41,Key!$E$2:$F$9,2,FALSE) -> Work | R41: =K41&"-"&Q41 -> Home-Work | T41: 0.3 | U41: 4 | Y41: Y | AA41: =VLOOKUP(F41,Zones!$A$2:$F$151534,6,FALSE) -> 365 | AB41: =VLOOKUP(L41,Zones!$A$2:$F$151477,6,FALSE) -> 369
B42: 0.38333333 | C42: UDY 560V | D42: 11 | E42: 1 | F42: Iganga | G42: Iganga | H42: Uga | I42: 8 | J42: 2 | K42: =VLOOKUP(J42,Key!$E$2:$F$9,2,FALSE) -> Work | L42: Bunyiiro | M42: Iganga | N42: Uga | O42: 8 | P42: 2 | Q42: =VLOOKUP(P42,Key!$E$2:$F$9,2,FALSE) -> Work | R42: =K42&"-"&Q42 -> Work-Work | S42: 2 | T42: 0.1 | U42: 2 | Y42: Y | Z42: 1000 | AA42: =VLOOKUP(F42,Zones!$A$2:$F$151534,6,FALSE) -> 365 | AB42: =VLOOKUP(L42,Zones!$A$2:$F$151477,6,FALSE) -> 373
...

Sheet Zones
A1: ZONE NAME | B1: DISTRICT | C1: COUNTY | D1: SUBCOUNTY | E1: Parish | F1: ZONE No.
A2: Abim | B2: Abim | C2: Labwor | D2: =A2 -> Abim | F2: 1
A3: Abim Town Council | B3: Abim | C3: Labwor | D3: =A3 -> Abim Town Council | F3: 2
A4: Alerek | B4: Abim | C4: Labwor | D4: =A4 -> Alerek | F4: 3
A5: Lotukei | B5: Abim | C5: Labwor | D5: =A5 -> Lotukei | F5: 4
A6: Morulem | B6: Abim | C6: Labwor | D6: =A6 -> Morulem | F6: 5
A7: Nyakwae | B7: Abim | C7: Labwor | D7: =A7 -> Nyakwae | F7: 6
A8: Adjumani Town Council | B8: Adjumani | C8: East Moyo | D8: =A8 -> Adjumani Town Council | F8: 7
A9: Adjumani | D9: =A9 -> Adjumani | F9: 7
A10: Adropi | B10: Adjumani | C10: East Moyo | D10: =A10 -> Adropi | F10: 8
A11: Arinyapi | B11: Adjumani | C11: East Moyo | D11: =A11 -> Arinyapi | F11: 9
A12: Ciforo | B12: Adjumani | C12: East Moyo | D12: =A12 -> Ciforo | F12: 10
A13: Dzaipi | B13: Adjumani | C13: East Moyo | D13: =A13 -> Dzaipi | F13: 11
A14: Itirikwa | B14: Adjumani | C14: East Moyo | D14: =A14 -> Itirikwa | F14: 12
A15: Ofua | B15: Adjumani | C15: East Moyo | D15: =A15 -> Ofua | F15: 13
A16: Pacara | B16: Adjumani | C16: East Moyo | D16: =A16 -> Pacara | F16: 14
A17: Pakele | B17: Adjumani | C17: East Moyo | D17: =A17 -> Pakele | F17: 15
A18: Ukusijoni | B18: Adjumani | C18: East Moyo | D18: =A18 -> Ukusijoni | F18: 16
A19: Adilang | B19: Agago | C19: Agago | D19: =A19 -> Adilang | F19: 17
A20: Agago Town Council | B20: Agago | C20: Agago | D20: =A20 -> Agago Town Council | F20: 18
A21: Arum | B21: Agago | C21: Agago | D21: =A21 -> Arum | F21: 19
... A84: Apac Muicipality | B84: Apac | C84: Apac Municipality | D84: =A84 -> Apac Muicipality | F84: 82
A85: Apac | D85: =A85 -> Apac | F85: 82
A86: Chawente | B86: Apac | C86: Kwania | D86: =A86 -> Chawente | F86: 83
A87: Chegere | B87: Apac | C87: Maruzi | D87: =A87 -> Chegere | F87: 84
A88: Ibuje | B88: Apac | C88: Maruzi | D88: =A88 -> Ibuje | F88: 85
A89: Inomo | B89: Apac | C89: Kwania | D89: =A89 -> Inomo | F89: 86
A90: Nambieso | B90: Apac | C90: Kwania | D90: =A90 -> Nambieso | F90: 87
A91: Adumi | B91: Arua | C91: Ayivu | D91: =A91 -> Adumi | F91: 88
A92: Aii-Vu | B92: Arua | C92: Terego | D92: =A92 -> Aii-Vu | F92: 89
A93: Ajia | B93: Arua | C93: Vurra | D93: =A93 -> Ajia | F93: 90
A94: Anyiribu | B94: Arua | C94: Madi Okollo | D94: =A94 -> Anyiribu | F94: 91
A95: Arivu | B95: Arua | C95: Vurra | D95: =A95 -> Arivu | F95: 92
A96: Aroi | B96: Arua | C96: Ayivu | D96: =A96 -> Aroi | F96: 93
A97: Arua Municipality | B97: Arua | C97: Arua Municipality | D97: =A97 -> Arua Municipality | F97: 94
A98: Arua | D98: =A98 -> Arua | F98: 94
A99: Ayivuni | B99: Arua | C99: Ayivu | D99: =A99 -> Ayivuni | F99: 95
A100: Bileafe | B100: Arua | C100: Terego | D100: =A100 -> Bileafe | F100: 96
A101: Dadamu | B101: Arua | C101: Ayivu | D101: =A101 -> Dadamu | F101: 97
A102: Ewanga | B102: Arua | C102: Madi Okollo | D102: =A102 -> Ewanga | F102: 98
...

Sheet 24.08 Iganga-Kaliro
B1: Consultancy services for Preparation of Expressway Development Master Plan (EDMP) for Uganda
B2: Roadside OD Interview Survey
B4: Date: | C4: 24.08.19 | E4: Road Name: | F4: Iganga-Kaliro Rd | I4: Direction From: | L4: Iganga | N4: Interviewers: | O4: Kirabo Edith | V4: Supervisor: | W4: Felix C. | Y4: Coded By: | Z4: Isaac Akure | AA4: Chkd By: | AB4: Isaac M.
I5: Direction To: | L5: Kaliro
B7: Time | C7: Veh_Reg_No. | D7: Veh_Type | E7: No. Occupants | F7: Origin_Address | I7: Origin_Establish | J7: Origin_Purpose | K7: Origin-Purpose Desc | L7: Destination_Address | O7: Destination_Establish | P7: Destination_Purpose | Q7: Destination_Purpose Desc | R7: Journey_Purpose | S7: Approx_Distance (Km) | T7: Approx_Journey Time (Hrs) | U7: Trip_Frequency | V7: GOODS VEHICLES ONLY | Y7: Would You Use Xpressways? | Z7: Pay How Much? (UGX) | AA7: Origin_Zone | AB7: Dest_Zone
F8: Village or Town | G8: District | H8: Country | L8: Village or Town | M8: District | N8: Country | V8: Goods_Type | W8: Goods_Quantity (Ton) | X8: Goods_Value (UGXm)
B9: 0.43680556 | C9: UBB 204G | D9: 1 | E9: 1 | F9: Entebbe | G9: Wakiso | H9: Uga | I9: 16 | J9: 8 | K9: =VLOOKUP(J9,Key!$E$2:$F$9,2,FALSE) -> Others | L9: Kabira | M9: Iganga | N9: Uga | O9: 1 | P9: 1 | Q9: =VLOOKUP(P9,Key!$E$2:$F$9,2,FALSE) -> Home | R9: =K9&"-"&Q9 -> Others-Home | S9: 27 | T9: 1 | U9: 2 | Y9: Y
B10: 0.43055556 | C10: UAJ 283F | D10: 1 | E10: 2 | F10: Jinja | G10: Jinja | H10: Uga | I10: 1 | J10: 1 | K10: =VLOOKUP(J10,Key!$E$2:$F$9,2,FALSE) -> Home | L10: Kaliro | M10: Iganga | N10: Uga | O10: 3 | P10: 2 | Q10: =VLOOKUP(P10,Key!$E$2:$F$9,2,FALSE) -> Work | R10: =K10&"-"&Q10 -> Home-Work | S10: 1 | T10: 1 | U10: 2 | Y10: Y
B11: 0.020138889 | C11: UAN 195Q | D11: 1 | E11: 4 | F11: Mukono | G11: Mukono | H11: Uga | I11: 1 | J11: 1 | K11: =VLOOKUP(J11,Key!$E$2:$F$9,2,FALSE) -> Home | L11: Kaliro | M11: Iganga | N11: Uga | O11: 10 | P11: 2 | Q11: =VLOOKUP(P11,Key!$E$2:$F$9,2,FALSE) -> Work | R11: =K11&"-"&Q11 -> Home-Work | S11: 5 | T11: 1 | U11: 2 | Y11: Y
B12: 0.48472222 | C12: UBA 865V | D12: 1 | E12: 1 | F12: Kampala | G12: Kampala | H12: Uga | I12: 1 | J12: 1 | K12: =VLOOKUP(J12,Key!$E$2:$F$9,2,FALSE) -> Home | L12: Nabigalo | M12: Iganga | N12: Uga | O12: 16 | P12: 8 | Q12: =VLOOKUP(P12,Key!$E$2:$F$9,2,FALSE) -> Others | R12: =K12&"-"&Q12 -> Home-Others | S12: 160 | T12: 4 | U12: 2 | Y12: Y
B13: 0.47777778 | C13: UAS 126A | D13: 4 | E13: 14 | F13: Iganga | G13: Iganga | H13: Uga | I13: 6 | J13: 2 | K13: =VLOOKUP(J13,Key!$E$2:$F$9,2,FALSE) -> Work | L13: Kaliro | M13: Iganga | N13: Uga | O13: 6 | P13: 2 | Q13: =VLOOKUP(P13,Key!$E$2:$F$9,2,FALSE) -> Work | R13: =K13&"-"&Q13 -> Work-Work | S13: 15 | T13: 2 | U13: 2 | Y13: Y
B14: 0.48055556 | C14: UAW 781F | D14: 3 | E14: 6 | F14: Bugerwe | G14: Iganga | H14: Uga | I14: 1 | J14: 1 | K14: =VLOOKUP(J14,Key!$E$2:$F$9,2,FALSE) -> Home | L14: Namugala | M14: Iganga | N14: Uga | O14: 16 | P14: 2 | Q14: =VLOOKUP(P14,Key!$E$2:$F$9,2,FALSE) -> Work | R14: =K14&"-"&Q14 -> Home-Work | S14: 10 | T14: 0.3 | U14: 2 | Y14: Y
B15: 0.43402778 | C15: UAE 400F | D15: 8 | E15: 1 | F15: Iganga | G15: Iganga | H15: Uga | I15: 1 | J15: 1 | K15: =VLOOKUP(J15,Key!$E$2:$F$9,2,FALSE) -> Home | L15: Namugala | M15: Iganga | N15: Uga | O15: 16 | P15: 8 | Q15: =VLOOKUP(P15,Key!$E$2:$F$9,2,FALSE) -> Others | R15: =K15&"-"&Q15 -> Home-Others | S15: 16 | T15: 0.5 | U15: 2 | Y15: Y
B16: 0.47638889 | C16: UAJ 126D | D16: 8 | E16: 3 | F16: Iganga | G16: Iganga | H16: Uga | I16: 1 | J16: 1 | K16: =VLOOKUP(J16,Key!$E$2:$F$9,2,FALSE) -> Home | L16: Magamaga | M16: Iganga | N16: Uga | O16: 10 | P16: 2 | Q16: =VLOOKUP(P16,Key!$E$2:$F$9,2,FALSE) -> Work | R16: =K16&"-"&Q16 -> Home-Work | T16: 0.5 | U16: 2 | Y16: Y
B17: 0.41319444 | C17: UAY 720N | D17: 3 | E17: 4 | F17: Iganga | G17: Iganga | H17: Uga | I17: 1 | J17: 1 | K17: =VLOOKUP(J17,Key!$E$2:$F$9,2,FALSE) -> Home | L17: Namugala | M17: Iganga | N17: Uga | O17: 16 | P17: 8 | Q17: =VLOOKUP(P17,Key!$E$2:$F$9,2,FALSE) -> Others | R17: =K17&"-"&Q17 -> Home-Others | S17: 10 | T17: 0.5 | U17: 2 | Y17: Y
B18: 0.40833333 | C18: UAX 893Y | D18: 8 | E18: 3 | F18: Iganga | G18: Iganga | H18: Uga | I18: 16 | J18: 8 | K18: =VLOOKUP(J18,Key!$E$2:$F$9,2,FALSE) -> Others | L18: Irinda | M18: Iganga | N18: Uga | O18: 16 | P18: 8 | Q18: =VLOOKUP(P18,Key!$E$2:$F$9,2,FALSE) -> Others | R18: =K18&"-"&Q18 -> Others-Others | S18: 85 | T18: 2 | U18: 2 | Y18: Y
B19: 0.42638889 | C19: UBA 982B | D19: 1 | E19: 4 | F19: Jinja | G19: Jinja | H19: Uga | I19: 1 | J19: 1 | K19: =VLOOKUP(J19,Key!$E$2:$F$9,2,FALSE) -> Home | L19: Kaliro | M19: Iganga | N19: Uga | O19: 4 | P19: 3 | Q19: =VLOOKUP(P19,Key!$E$2:$F$9,2,FALSE) -> Study | R19: =K19&"-"&Q19 -> Home-Study | T19: 0.5 | U19: 2 | Y19: Y
B20: 0.425 | C20: UAK 473X | D20: 5 | E20: 28 | F20: Jinja | G20: Jinja | H20: Uga | I20: 6 | J20: 2 | K20: =VLOOKUP(J20,Key!$E$2:$F$9,2,FALSE) -> Work | L20: Kaliro | M20: Iganga | N20: Uga | O20: 6 | P20: 2 | Q20: =VLOOKUP(P20,Key!$E$2:$F$9,2,FALSE) -> Work | R20: =K20&"-"&Q20 -> Work-Work | S20: 30 | T20: 3 | U20: 6 | Y20: Y
B21: 0.4375 | C21: UAL 681Z | D21: 8 | E21: 3 | F21: Kakira | G21: Iganga | H21: Uga | I21: 3 | J21: 2 | K21: =VLOOKUP(J21,Key!$E$2:$F$9,2,FALSE) -> Work | L21: Kaliro | M21: Iganga | N21: Uga | O21: 16 | P21: 8 | Q21: =VLOOKUP(P21,Key!$E$2:$F$9,2,FALSE) -> Others | R21: =K21&"-"&Q21 -> Work-Others | T21: 0.7 | U21: 4 | Y21: Y
B22: 0.43819444 | C22: UAL 758V | D22: 1 | E22: 2 | F22: Busesa | G22: Bugweri | H22: Uga | I22: 1 | J22: 1 | K22: =VLOOKUP(J22,Key!$E$2:$F$9,2,FALSE) -> Home | L22: Nabitovu | M22: Iganga | N22: Uga | O22: 3 | P22: 2 | Q22: =VLOOKUP(P22,Key!$E$2:$F$9,2,FALSE) -> Work | R22: =K22&"-"&Q22 -> Home-Work | S22: 15 | T22: 0.8 | U22: 2 | Y22: Y
B23: 0.42361111 | C23: UAZ 355H | D23: 8 | E23: 2 | F23: Iganga | G23: Iganga | H23: Uga | I23: 1 | J23: 1 | K23: =VLOOKUP(J23,Key!$E$2:$F$9,2,FALSE) -> Home | L23: Kyanga | M23: Iganga | N23: Uga | O23: 10 | P23: 2 | Q23: =VLOOKUP(P23,Key!$E$2:$F$9,2,FALSE) -> Work | R23: =K23&"-"&Q23 -> Home-Work | T23: 0.5 | U23: 2 | Y23: Y
B24: 0.42777778 | C24: UAK 002F | D24: 1 | E24: 5 | F24: Iganga | G24: Iganga | H24: Uga | I24: 4 | J24: 3 | K24: =VLOOKUP(J24,Key!$E$2:$F$9,2,FALSE) -> Study | L24: Kaliro | M24: Iganga | N24: Uga | O24: 1 | P24: 1 | Q24: =VLOOKUP(P24,Key!$E$2:$F$9,2,FALSE) -> Home | R24: =K24&"-"&Q24 -> Study-Home | T24: 0.5 | U24: 5 | Y24: Y
B25: 0.39097222 | C25: UAV 252E | D25: 4 | E25: 2 | F25: Iganga | G25: Iganga | H25: Uga | I25: 1 | J25: 1 | K25: =VLOOKUP(J25,Key!$E$2:$F$9,2,FALSE) -> Home | L25: Bunyiiro | M25: Iganga | N25: Uga | O25: 6 | P25: 2 | Q25: =VLOOKUP(P25,Key!$E$2:$F$9,2,FALSE) -> Work | R25: =K25&"-"&Q25 -> Home-Work | S25: 5 | T25: 0.1 | U25: 4 | Y25: Y
B26: 0.39166667 | C26: UAQ 598E | D26: 4 | E26: 1 | F26: Iganga | G26: Iganga | H26: Uga | I26: 1 | J26: 1 | K26: =VLOOKUP(J26,Key!$E$2:$F$9,2,FALSE) -> Home | L26: Nawanika | M26: Iganga | N26: Uga | O26: 6 | P26: 2 | Q26: =VLOOKUP(P26,Key!$E$2:$F$9,2,FALSE) -> Work | R26: =K26&"-"&Q26 -> Home-Work | T26: 0.5 | U26: 1 | Y26: Y
B27: 0.38819444 | C27: UAZ 329W | D27: 8 | E27: 3 | F27: Magamaga | G27: Iganga | H27: Uga | I27: 1 | J27: 1 | K27: =VLOOKUP(J27,Key!$E$2:$F$9,2,FALSE) -> Home | L27: Kaliro | M27: Iganga | N27: Uga | O27: 3 | P27: 2 | Q27: =VLOOKUP(P27,Key!$E$2:$F$9,2,FALSE) -> Work | R27: =K27&"-"&Q27 -> Home-Work | T27: 0.8 | U27: 2 | Y27: Y
B28: 0.38541667 | C28: UEN 384H | D28: 11 | E28: 2 | F28: Iganga | G28: Iganga | H28: Uga | I28: 8 | J28: 2 | K28: =VLOOKUP(J28,Key!$E$2:$F$9,2,FALSE) -> Work | L28: Buwolmera | M28: Iganga | N28: Uga | O28: 8 | P28: 2 | Q28: =VLOOKUP(P28,Key!$E$2:$F$9,2,FALSE) -> Work | R28: =K28&"-"&Q28 -> Work-Work | S28: 8 | T28: 0.5 | U28: 2 | Y28: Y
B29: 0.39652778 | C29: UAL 373H | D29: 3 | E29: 5 | F29: Iganga | G29: Iganga | H29: Uga | I29: 1 | J29: 1 | K29: =VLOOKUP(J29,Key!$E$2:$F$9,2,FALSE) -> Home | L29: Bunyiiro | M29: Iganga | N29: Uga | O29: 10 | P29: 2 | Q29: =VLOOKUP(P29,Key!$E$2:$F$9,2,FALSE) -> Work | R29: =K29&"-"&Q29 -> Home-Work | S29: 3 | T29: 0.5 | U29: 2 | Y29: Y
B30: 0.39444444 | C30: UAZ 293J | D30: 5 | E30: 30 | F30: Kayunga | G30: Kayunga | H30: Uga | I30: 6 | J30: 2 | K30: =VLOOKUP(J30,Key!$E$2:$F$9,2,FALSE) -> Work | L30: Kilama | M30: Kaliro | N30: Uga | O30: 6 | P30: 2 | Q30: =VLOOKUP(P30,Key!$E$2:$F$9,2,FALSE) -> Work | R30: =K30&"-"&Q30 -> Work-Work | T30: 1 | U30: 4 | Y30: Y | Z30: 20000
B31: 0.36458333 | C31: UBA 419Q | D31: 8 | E31: 3 | F31: Iganga | G31: Iganga | H31: Uga | I31: 1 | J31: 1 | K31: =VLOOKUP(J31,Key!$E$2:$F$9,2,FALSE) -> Home | L31: Mamumagala | M31: Iganga | N31: Uga | O31: 10 | P31: 2 | Q31: =VLOOKUP(P31,Key!$E$2:$F$9,2,FALSE) -> Work | R31: =K31&"-"&Q31 -> Home-Work | S31: 6 | T31: 0.4 | U31: 4 | Y31: Y
B32: 0.35972222 | C32: UBC 278D | D32: 4 | E32: 14 | F32: Jinja | G32: Jinja | H32: Uga | I32: 6 | J32: 2 | K32: =VLOOKUP(J32,Key!$E$2:$F$9,2,FALSE) -> Work | L32: Kilama | M32: Iganga | N32: Uga | O32: 6 | P32: 2 | Q32: =VLOOKUP(P32,Key!$E$2:$F$9,2,FALSE) -> Work | R32: =K32&"-"&Q32 -> Work-Work | T32: 1 | U32: 4 | Y32: Y | Z32: 1000
B33: 0.70625 | C33: UAW 666X | D33: 1 | E33: 2 | F33: Iganga | G33: Iganga | H33: Uga | I33: 2 | J33: 2 | K33: =VLOOKUP(J33,Key!$E$2:$F$9,2,FALSE) -> Work | L33: Bunyiiro | M33: Iganga | N33: Uga | O33: 1 | P33: 1 | Q33: =VLOOKUP(P33,Key!$E$2:$F$9,2,FALSE) -> Home | R33: =K33&"-"&Q33 -> Work-Home | S33: 2 | T33: 0.5 | U33: 2 | Y33: Y
B34: 0.71666667 | C34: UBC 299T | D34: 1 | E34: 4 | F34: Iganga | G34: Iganga | H34: Uga | I34: 14 | J34: 8 | K34: =VLOOKUP(J34,Key!$E$2:$F$9,2,FALSE) -> Others | L34: Kaliro | M34: Iganga | N34: Uga | O34: 1 | P34: 1 | Q34: =VLOOKUP(P34,Key!$E$2:$F$9,2,FALSE) -> Home | R34: =K34&"-"&Q34 -> Others-Home | S34: 15 | T34: 0.8 | U34: 2 | Y34: Y
B35: 0.72361111 | C35: UAE 723H | D35: 2 | E35: 3 | F35: Iganga | G35: Iganga | H35: Uga | I35: 16 | J35: 8 | K35: =VLOOKUP(J35,Key!$E$2:$F$9,2,FALSE) -> Others | L35: Bunyiiro | M35: Iganga | N35: Uga | O35: 1 | P35: 1 | Q35: =VLOOKUP(P35,Key!$E$2:$F$9,2,FALSE) -> Home | R35: =K35&"-"&Q35 -> Others-Home | S35: 15 | T35: 2 | U35: 2 | Y35: Y
B36: 0.73263889 | C36: UAV 662X | D36: 7 | E36: 4 | F36: Bugiri | G36: Bugiri | H36: Uga | I36: 10 | J36: 2 | K36: =VLOOKUP(J36,Key!$E$2:$F$9,2,FALSE) -> Work | L36: Bunyiiro | M36: Iganga | N36: Uga | O36: 1 | P36: 1 | Q36: =VLOOKUP(P36,Key!$E$2:$F$9,2,FALSE) -> Home | R36: =K36&"-"&Q36 -> Work-Home | S36: 20 | T36: 2 | U36: 4 | Y36: Y
B37: 0.74166667 | C37: UBD 600D | D37: 4 | E37: 14 | F37: Iganga | G37: Iganga | H37: Uga | I37: 6 | J37: 2 | K37: =VLOOKUP(J37,Key!$E$2:$F$9,2,FALSE) -> Work | L37: Bunyiiro | M37: Iganga | N37: Uga | O37: 6 | P37: 2 | Q37: =VLOOKUP(P37,Key!$E$2:$F$9,2,FALSE) -> Work | R37: =K37&"-"&Q37 -> Work-Work | S37: 27 | T37: 1.5 | U37: 2 | Y37: Y
B38: 0.46597222 | C38: UAY 781C | D38: 1 | E38: 4 | F38: Entebbe | G38: Kampala | H38: Uga | I38: 1 | J38: 1 | K38: =VLOOKUP(J38,Key!$E$2:$F$9,2,FALSE) -> Home | L38: Nabigalo | M38: Iganga | N38: Uga | O38: 16 | P38: 8 | Q38: =VLOOKUP(P38,Key!$E$2:$F$9,2,FALSE) -> Others | R38: =K38&"-"&Q38 -> Home-Others | S38: 160 | T38: 2 | U38: 6 | Y38: Y
B39: 0.47430556 | C39: UAJ 344A | D39: 2 | E39: 4 | F39: Iganga | G39: Iganga | H39: Uga | I39: 2 | J39: 2 | K39: =VLOOKUP(J39,Key!$E$2:$F$9,2,FALSE) -> Work | L39: Kaliro | M39: Iganga | N39: Uga | O39: 1 | P39: 1 | Q39: =VLOOKUP(P39,Key!$E$2:$F$9,2,FALSE) -> Home | R39: =K39&"-"&Q39 -> Work-Home | T39: 0.4 | U39: 2 | Y39: N
B40: 0.41458333 | C40: UBA 707P | D40: 2 | E40: 6 | F40: Mbalala | G40: Mukono | H40: Uga | I40: 1 | J40: 1 | K40: =VLOOKUP(J40,Key!$E$2:$F$9,2,FALSE) -> Home | L40: Kilama | M40: Iganga | N40: Uga | O40: 16 | P40: 8 | Q40: =VLOOKUP(P40,Key!$E$2:$F$9,2,FALSE) -> Others | R40: =K40&"-"&Q40 -> Home-Others | S40: 45 | T40: 2 | U40: 6 | Y40: Y | Z40: 2000
B41: 0.41388889 | C41: UBD 162K | D41: 1 | E41: 3 | F41: Iganga | G41: Iganga | H41: Uga | I41: 1 | J41: 1 | K41: =VLOOKUP(J41,Key!$E$2:$F$9,2,FALSE) -> Home | L41: Kigulo | M41: Iganga | N41: Uga | O41: 2 | P41: 2 | Q41: =VLOOKUP(P41,Key!$E$2:$F$9,2,FALSE) -> Work | R41: =K41&"-"&Q41 -> Home-Work | T41: 0.3 | U41: 4 | Y41: Y
B42: 0.38333333 | C42: UDY 560V | D42: 11 | E42: 1 | F42: Iganga | G42: Iganga | H42: Uga | I42: 8 | J42: 2 | K42: =VLOOKUP(J42,Key!$E$2:$F$9,2,FALSE) -> Work | L42: Bunyiiro | M42: Iganga | N42: Uga | O42: 8 | P42: 2 | Q42: =VLOOKUP(P42,Key!$E$2:$F$9,2,FALSE) -> Work | R42: =K42&"-"&Q42 -> Work-Work | S42: 2 | T42: 0.1 | U42: 2 | Y42: Y | Z42: 1000
...

Sheet RSI FORM
B1: Feasibility Study and Detailed Design of Kampala - Jinja Highway
B2: Roadside OD Interview Survey
B4: Date: | C4: 40465 | D4: Interviewer: | G4: Survey Station: | H4: Bweyogerere | J4: Direction: | K4: Bweyogerere-Kireka | L4: Coded By: | N4: Chkd By:
B7: Time Period | C7: Veh_Type | D7: Veh_Other | E7: Occupancy | F7: Origin_Address | H7: Origin_Purpose | I7: Origin_other | J7: Destination_Address | L7: Destination_Purpose | M7: Destination_Other | N7: Origin_Zone | O7: Dest_Zone | P7: WTP
F8: Village/Town | G8: City/Country | J8: Village/Town | K8: City/Country
B9: AM | C9: 3 | E9: 2 | F9: Entebbe | G9: Kla, Ug | H9: 1 | J9: Kla | K9: Kla, Ug | L9: 2 | N9: Blank | O9: Blank | P9: Yes | Q9: 3000
B10: AM | C10: 1 | E10: 1 | F10: Kiwanga | G10: Kla, Ug | H10: 1 | J10: Kla | K10: Kla, Ug | L10: 2 | N10: Blank | O10: Blank | P10: Yes | Q10: 2000
B11: AM | E11: 1 | F11: Bukoto | G11: Kla, Ug | H11: 3 | J11: Kla | K11: Kla, Ug | L11: 1 | N11: Blank | O11: Blank
B12: AM
B13: AM
B14: AM
B15: AM
B16: AM
B17: AM
B18: AM
B19: AM
B20: AM
B21: AM
B22: AM
B23: AM
... B53: AM

Sheet 24.08 Kaliro-Iganga
B1: Consultancy services for Preparation of Expressway Development Master Plan (EDMP) for Uganda
B2: Roadside OD Interview Survey
B4: Date: | C4: ='24.08 Iganga-Kaliro'!C4 -> 24.08.19 | E4: Road Name: | F4: ='24.08 Iganga-Kaliro'!F4:G4 -> Iganga-Kaliro Rd | I4: Direction From: | L4: Kaliro | N4: Interviewers: | O4: Racheal | V4: Supervisor: | Y4: Coded By: | Z4: ='24.08 Iganga-Kaliro'!Z4 -> Isaac Akure | AA4: Chkd By: | AB4: ='24.08 Iganga-Kaliro'!AB4 -> Isaac M.
I5: Direction To: | L5: Iganga
B7: Time | C7: Veh_Reg_No. | D7: Veh_Type | E7: No. Occupants | F7: Origin_Address | I7: Origin_Establish | J7: Origin_Purpose | K7: Origin-Purpose Desc | L7: Destination_Address | O7: Destination_Establish | P7: Destination_Purpose | Q7: Destination_Purpose Desc | R7: Journey_Purpose | S7: Approx_Distance (Km) | T7: Approx_Journey Time (Hrs) | U7: Trip_Frequency | V7: GOODS VEHICLES ONLY | Y7: Would You Use Xpressways? | Z7: Pay How Much? (UGX) | AA7: Origin_Zone | AB7: Dest_Zone
F8: Village or Town | G8: District | H8: Country | L8: Village or Town | M8: District | N8: Country | V8: Goods_Type | W8: Goods_Quantity (Ton) | X8: Goods_Value (UGXm)
B9: 0.38541667 | C9: UAY 695F | D9: 8 | E9: 2 | F9: Kigulu | G9: Iganga | H9: Uga | I9: 2 | J9: 2 | K9: =VLOOKUP(J9,Key!$E$2:$F$9,2,FALSE) -> Work | L9: Nakalama | M9: Iganga | N9: Uga | O9: 2 | P9: 2 | Q9: =VLOOKUP(P9,Key!$E$2:$F$9,2,FALSE) -> Work | R9: =K9&"-"&Q9 -> Work-Work | T9: 1 | U9: 2 | V9: 11 | Y9: Y
B10: 0.017361111 | C10: UWO 251C | D10: 7 | E10: 3 | F10: Buwolumera | G10: Iganga | H10: Uga | I10: 9 | J10: 4 | K10: =VLOOKUP(J10,Key!$E$2:$F$9,2,FALSE) -> Commercial | L10: Kakira | M10: Jinja | N10: Uga | O10: 3 | P10: 4 | Q10: =VLOOKUP(P10,Key!$E$2:$F$9,2,FALSE) -> Commercial | R10: =K10&"-"&Q10 -> Commercial-Commercial | S10: 34 | T10: 2 | V10: 1 | W10: 10 | Y10: Y
B11: 0.027777778 | C11: UAT 889B | D11: 4 | E11: 14 | F11: Kaliro | G11: Kaliro | H11: Uga | I11: 16 | J11: 2 | K11: =VLOOKUP(J11,Key!$E$2:$F$9,2,FALSE) -> Work | L11: Jinja | M11: Jinja | N11: Uga | O11: 2 | P11: 2 | Q11: =VLOOKUP(P11,Key!$E$2:$F$9,2,FALSE) -> Work | R11: =K11&"-"&Q11 -> Work-Work | S11: 20 | T11: 1 | U11: 6 | Y11: Y
B12: 0.59652778 | C12: UAK 508K | D12: 1 | E12: 3 | F12: Kawete | G12: Kaliro | H12: Uga | I12: 1 | J12: 1 | K12: =VLOOKUP(J12,Key!$E$2:$F$9,2,FALSE) -> Home | L12: Jinja | M12: Jinja | N12: Uga | O12: 2 | P12: 2 | Q12: =VLOOKUP(P12,Key!$E$2:$F$9,2,FALSE) -> Work | R12: =K12&"-"&Q12 -> Home-Work | S12: 20 | T12: 1.5 | U12: 2 | Y12: N
B13: 0.59375 | C13: UAJ 114D | D13: 4 | E13: 14 | F13: Kaliro | G13: Kaliro | H13: Uga | I13: 6 | J13: 2 | K13: =VLOOKUP(J13,Key!$E$2:$F$9,2,FALSE) -> Work | L13: Iganga | M13: Iganga | N13: Uga | O13: 6 | P13: 2 | Q13: =VLOOKUP(P13,Key!$E$2:$F$9,2,FALSE) -> Work | R13: =K13&"-"&Q13 -> Work-Work | S13: 32 | T13: 1 | U13: 1 | Y13: Y
B14: 0.45763889 | C14: UDG 017K | D14: 2 | E14: 4 | F14: Kaliro | G14: Kaliro | H14: Uga | I14: 1 | J14: 1 | K14: =VLOOKUP(J14,Key!$E$2:$F$9,2,FALSE) -> Home | L14: Iganga | M14: Iganga | N14: Uga | O14: 5 | P14: 7 | Q14: =VLOOKUP(P14,Key!$E$2:$F$9,2,FALSE) -> Hospital | R14: =K14&"-"&Q14 -> Home-Hospital | S14: 32 | T14: 1 | U14: 6 | Y14: Y
B15: 0.45486111 | C15: UBE 157B | D15: 1 | E15: 1 | F15: Kaliro | G15: Kaliro | H15: Uga | I15: 1 | J15: 1 | K15: =VLOOKUP(J15,Key!$E$2:$F$9,2,FALSE) -> Home | L15: Iganga | M15: Iganga | N15: Uga | O15: 16 | P15: 8 | Q15: =VLOOKUP(P15,Key!$E$2:$F$9,2,FALSE) -> Others | R15: =K15&"-"&Q15 -> Home-Others | S15: 32 | T15: 1 | U15: 4 | Y15: Y
B16: 0.37430556 | C16: UAU 413G | D16: 1 | E16: 4 | F16: Kirama | G16: Kaliro | H16: Uga | I16: 1 | J16: 1 | K16: =VLOOKUP(J16,Key!$E$2:$F$9,2,FALSE) -> Home | L16: Mayuge | M16: Mayuge | N16: Uga | O16: 1 | P16: 1 | Q16: =VLOOKUP(P16,Key!$E$2:$F$9,2,FALSE) -> Home | R16: =K16&"-"&Q16 -> Home-Home | T16: 1 | U16: 5 | Y16: Y
B17: 0.37152778 | C17: UEW 992D | D17: 11 | E17: 2 | F17: Nasuti | G17: Kaliro | H17: Uga | I17: 1 | J17: 1 | K17: =VLOOKUP(J17,Key!$E$2:$F$9,2,FALSE) -> Home | L17: Iganga | M17: Iganga | N17: Uga | O17: 2 | P17: 2 | Q17: =VLOOKUP(P17,Key!$E$2:$F$9,2,FALSE) -> Work | R17: =K17&"-"&Q17 -> Home-Work | S17: 16 | T17: 0.5 | U17: 2 | Y17: Y
B18: 0.60347222 | C18: UAR 406K | D18: 2 | E18: 4 | F18: Buhuka | G18: Kaliro | H18: Uga | I18: 1 | J18: 1 | K18: =VLOOKUP(J18,Key!$E$2:$F$9,2,FALSE) -> Home | L18: Jinja | M18: Jinja | N18: Uga | O18: 2 | P18: 2 | Q18: =VLOOKUP(P18,Key!$E$2:$F$9,2,FALSE) -> Work | R18: =K18&"-"&Q18 -> Home-Work | S18: 36 | T18: 2 | U18: 2 | Y18: Y
B19: 0.61805556 | C19: UEX 117N | D19: 11 | E19: 3 | F19: Namungaala | G19: Iganga | H19: Uga | I19: 8 | J19: 2 | K19: =VLOOKUP(J19,Key!$E$2:$F$9,2,FALSE) -> Work | L19: Iganga | M19: Iganga | N19: Uga | O19: 2 | P19: 2 | Q19: =VLOOKUP(P19,Key!$E$2:$F$9,2,FALSE) -> Work | R19: =K19&"-"&Q19 -> Work-Work | T19: 0.2 | U19: 2 | Y19: Y
B20: 0.7125 | C20: UAM 808V | D20: 8 | E20: 2 | F20: Gandumire | G20: Iganga | H20: Uga | I20: 9 | J20: 2 | K20: =VLOOKUP(J20,Key!$E$2:$F$9,2,FALSE) -> Work | L20: Iganga | M20: Iganga | N20: Uga | O20: 3 | P20: 2 | Q20: =VLOOKUP(P20,Key!$E$2:$F$9,2,FALSE) -> Work | R20: =K20&"-"&Q20 -> Work-Work | T20: 0.5 | Y20: Y
B21: 0.72222222 | C21: UBE 131B | D21: 2 | E21: 1 | F21: Kaliro | G21: Kaliro | H21: Uga | I21: 1 | J21: 1 | K21: =VLOOKUP(J21,Key!$E$2:$F$9,2,FALSE) -> Home | L21: Iganga | M21: Iganga | N21: Uga | O21: 4 | P21: 3 | Q21: =VLOOKUP(P21,Key!$E$2:$F$9,2,FALSE) -> Study | R21: =K21&"-"&Q21 -> Home-Study | S21: 30 | T21: 1 | U21: 2 | Y21: Y
B22: 0.70138889 | C22: UAW 103W | D22: 4 | E22: 14 | F22: Kaliro | G22: Kaliro | H22: Uga | I22: 6 | J22: 2 | K22: =VLOOKUP(J22,Key!$E$2:$F$9,2,FALSE) -> Work | L22: Iganga | M22: Iganga | N22: Uga | O22: 6 | P22: 2 | Q22: =VLOOKUP(P22,Key!$E$2:$F$9,2,FALSE) -> Work | R22: =K22&"-"&Q22 -> Work-Work | S22: 32 | T22: 1.5 | U22: 2 | Y22: Y
B23: 0.69097222 | C23: UAP 080Y | D23: 11 | E23: 3 | F23: Kigulu | G23: Iganga | H23: Uga | I23: 8 | J23: 2 | K23: =VLOOKUP(J23,Key!$E$2:$F$9,2,FALSE) -> Work | L23: Iganga | M23: Iganga | N23: Uga | O23: 2 | P23: 2 | Q23: =VLOOKUP(P23,Key!$E$2:$F$9,2,FALSE) -> Work | R23: =K23&"-"&Q23 -> Work-Work | T23: 0.3 | U23: 2 | Y23: Y
B24: 0.67361111 | C24: UAL 234P | D24: 5 | E24: 32 | F24: Kaliro | G24: Kaliro | H24: Uga | I24: 6 | J24: 2 | K24: =VLOOKUP(J24,Key!$E$2:$F$9,2,FALSE) -> Work | L24: Kampala | M24: Kampala | N24: Uga | O24: 6 | P24: 2 | Q24: =VLOOKUP(P24,Key!$E$2:$F$9,2,FALSE) -> Work | R24: =K24&"-"&Q24 -> Work-Work | S24: 135 | T24: 4 | U24: 2 | Y24: Y
B25: 0.68055556 | C25: UAQ 118C | D25: 2 | E25: 5 | F25: Buhuka | G25: Kaliro | H25: Uga | I25: 1 | J25: 1 | K25: =VLOOKUP(J25,Key!$E$2:$F$9,2,FALSE) -> Home | L25: Iganga | M25: Iganga | N25: Uga | O25: 1 | P25: 1 | Q25: =VLOOKUP(P25,Key!$E$2:$F$9,2,FALSE) -> Home | R25: =K25&"-"&Q25 -> Home-Home | T25: 0.5 | U25: 6 | Y25: Y
B26: 0.43125 | C26: UBD 179R | D26: 4 | E26: 14 | F26: Kaliro | G26: Kaliro | H26: Uga | I26: 1 | J26: 1 | K26: =VLOOKUP(J26,Key!$E$2:$F$9,2,FALSE) -> Home | L26: Jinja | M26: Jinja | N26: Uga | O26: 16 | P26: 8 | Q26: =VLOOKUP(P26,Key!$E$2:$F$9,2,FALSE) -> Others | R26: =K26&"-"&Q26 -> Home-Others | S26: 78 | T26: 1.5 | U26: 2 | Y26: N
B27: 0.38958333 | C27: UEF 225L | D27: 11 | E27: 3 | F27: Kigulu | G27: Iganga | H27: Uga | I27: 2 | J27: 2 | K27: =VLOOKUP(J27,Key!$E$2:$F$9,2,FALSE) -> Work | L27: Iganga | M27: Iganga | N27: Uga | O27: 2 | P27: 2 | Q27: =VLOOKUP(P27,Key!$E$2:$F$9,2,FALSE) -> Work | R27: =K27&"-"&Q27 -> Work-Work | T27: 0.3 | U27: 2 | Y27: Y
B28: 0.39930556 | C28: UAA 029B | D28: 1 | E28: 6 | F28: Kaliro | G28: Kaliro | H28: Uga | I28: 2 | J28: 2 | K28: =VLOOKUP(J28,Key!$E$2:$F$9,2,FALSE) -> Work | L28: Iganga | M28: Iganga | N28: Uga | O28: 2 | P28: 2 | Q28: =VLOOKUP(P28,Key!$E$2:$F$9,2,FALSE) -> Work | R28: =K28&"-"&Q28 -> Work-Work | S28: 34 | T28: 1 | U28: 2 | Y28: Y
B29: 0.74930556 | C29: UBD 655C | D29: 1 | E29: 2 | F29: Kaliro | G29: Kaliro | H29: Uga | I29: 2 | J29: 2 | K29: =VLOOKUP(J29,Key!$E$2:$F$9,2,FALSE) -> Work | L29: Iganga | M29: Iganga | N29: Uga | O29: 1 | P29: 1 | Q29: =VLOOKUP(P29,Key!$E$2:$F$9,2,FALSE) -> Home | R29: =K29&"-"&Q29 -> Work-Home | S29: 32 | T29: 1 | U29: 2 | Y29: Y
B30: 0.74861111 | C30: UAF 220Q | D30: 11 | E30: 3 | F30: Buweremera | G30: Iganga | H30: Uga | I30: 8 | J30: 2 | K30: =VLOOKUP(J30,Key!$E$2:$F$9,2,FALSE) -> Work | L30: Iganga | M30: Iganga | N30: Uga | O30: 2 | P30: 2 | Q30: =VLOOKUP(P30,Key!$E$2:$F$9,2,FALSE) -> Work | R30: =K30&"-"&Q30 -> Work-Work | S30: 34 | T30: 0.5 | Y30: Y
B31: 0.39930556 | C31: UBF 963M | D31: 1 | E31: 4 | F31: Namungaala | G31: Iganga | H31: Uga | I31: 1 | J31: 1 | K31: =VLOOKUP(J31,Key!$E$2:$F$9,2,FALSE) -> Home | L31: Iganga | M31: Iganga | N31: Uga | O31: 5 | P31: 7 | Q31: =VLOOKUP(P31,Key!$E$2:$F$9,2,FALSE) -> Hospital | R31: =K31&"-"&Q31 -> Home-Hospital | S31: 7 | T31: 0.2 | U31: 1 | Y31: Y
B32: 0.39722222 | C32: UAK 727X | D32: 4 | E32: 14 | F32: Kaliro | G32: Kaliro | H32: Uga | I32: 1 | J32: 1 | K32: =VLOOKUP(J32,Key!$E$2:$F$9,2,FALSE) -> Home | L32: Iganga | M32: Iganga | N32: Uga | O32: 6 | P32: 2 | Q32: =VLOOKUP(P32,Key!$E$2:$F$9,2,FALSE) -> Work | R32: =K32&"-"&Q32 -> Home-Work | S32: 32 | T32: 0.5 | U32: 2 | Y32: Y
B33: 0.63541667 | C33: UAL 676U | D33: 1 | E33: 5 | F33: Buwotomera | G33: Iganga | H33: Uga | I33: 16 | J33: 8 | K33: =VLOOKUP(J33,Key!$E$2:$F$9,2,FALSE) -> Others | L33: Iganga | M33: Iganga | N33: Uga | O33: 2 | P33: 2 | Q33: =VLOOKUP(P33,Key!$E$2:$F$9,2,FALSE) -> Work | R33: =K33&"-"&Q33 -> Others-Work | S33: 34 | T33: 2 | U33: 6 | Y33: Y
B34: 0.62847222 | C34: UAJ 214P | D34: 8 | E34: 2 | F34: Kawete | G34: Kaliro | H34: Uga | I34: 9 | J34: 2 | K34: =VLOOKUP(J34,Key!$E$2:$F$9,2,FALSE) -> Work | L34: Kakira | M34: Jinja | N34: Uga | O34: 3 | P34: 2 | Q34: =VLOOKUP(P34,Key!$E$2:$F$9,2,FALSE) -> Work | R34: =K34&"-"&Q34 -> Work-Work | T34: 1.5 | U34: 4 | Y34: Y
B35: 0.86458333 | C35: UAU 950H | D35: 1 | E35: 1 | F35: Namungaala | G35: Iganga | H35: Uga | I35: 1 | J35: 1 | K35: =VLOOKUP(J35,Key!$E$2:$F$9,2,FALSE) -> Home | L35: Iganga | M35: Iganga | N35: Uga | O35: 2 | P35: 2 | Q35: =VLOOKUP(P35,Key!$E$2:$F$9,2,FALSE) -> Work | R35: =K35&"-"&Q35 -> Home-Work | T35: 0.2 | Y35: Y
B36: 0.86666667 | C36: UAJ 178Z | D36: 5 | E36: 14 | F36: Pallisa | G36: Pallisa | H36: Uga | I36: 6 | J36: 2 | K36: =VLOOKUP(J36,Key!$E$2:$F$9,2,FALSE) -> Work | L36: Kampala | M36: Kampala | N36: Uga | O36: 2 | P36: 2 | Q36: =VLOOKUP(P36,Key!$E$2:$F$9,2,FALSE) -> Work | R36: =K36&"-"&Q36 -> Work-Work | S36: 140 | T36: 4 | U36: 2 | Y36: Y
B37: 0.875 | C37: UAV 280V | D37: 3 | E37: 2 | F37: Masuti | G37: Iganga | H37: Uga | I37: 1 | J37: 1 | K37: =VLOOKUP(J37,Key!$E$2:$F$9,2,FALSE) -> Home | L37: Iganga | M37: Iganga | N37: Uga | O37: 2 | P37: 2 | Q37: =VLOOKUP(P37,Key!$E$2:$F$9,2,FALSE) -> Work | R37: =K37&"-"&Q37 -> Home-Work | S37: 15 | T37: 0.3 | U37: 1 | Y37: Y
B38: 0.90277778 | C38: UAF 866H | D38: 5 | E38: 29 | F38: Kaliro | G38: Kaliro | H38: Uga | I38: 6 | J38: 4 | K38: =VLOOKUP(J38,Key!$E$2:$F$9,2,FALSE) -> Commercial | L38: Iganga | M38: Iganga | N38: Uga | O38: 6 | P38: 4 | Q38: =VLOOKUP(P38,Key!$E$2:$F$9,2,FALSE) -> Commercial | R38: =K38&"-"&Q38 -> Commercial-Commercial | S38: 30 | T38: 1.5 | U38: 2 | Y38: Y
B39: 0.96458333 | C39: UAQ 870S | D39: 1 | E39: 4 | F39: Kawete | G39: Kaliro | H39: Uga | I39: 1 | J39: 1 | K39: =VLOOKUP(J39,Key!$E$2:$F$9,2,FALSE) -> Home | L39: Jinja | M39: Jinja | N39: Uga | O39: 1 | P39: 1 | Q39: =VLOOKUP(P39,Key!$E$2:$F$9,2,FALSE) -> Home | R39: =K39&"-"&Q39 -> Home-Home | S39: 20 | T39: 1 | U39: 5 | Y39: Y
B40: 0.46180556 | C40: UAQ 275Z | D40: 4 | E40: 14 | F40: Kaliro | G40: Kaliro | H40: Uga | I40: 1 | J40: 1 | K40: =VLOOKUP(J40,Key!$E$2:$F$9,2,FALSE) -> Home | L40: Jinja | M40: Jinja | N40: Uga | O40: 16 | P40: 2 | Q40: =VLOOKUP(P40,Key!$E$2:$F$9,2,FALSE) -> Work | R40: =K40&"-"&Q40 -> Home-Work | T40: 1.5 | U40: 2 | Y40: N
B41: 0.66666667 | C41: UAN 146J | D41: 7 | E41: 2 | F41: Kaliro | G41: Kaliro | H41: Uga | I41: 2 | J41: 2 | K41: =VLOOKUP(J41,Key!$E$2:$F$9,2,FALSE) -> Work | L41: Jinja | M41: Jinja | N41: Uga | O41: 2 | P41: 2 | Q41: =VLOOKUP(P41,Key!$E$2:$F$9,2,FALSE) -> Work | R41: =K41&"-"&Q41 -> Work-Work | S41: 36 | T41: 2 | U41: 4 | V41: 1 | W41: 12 | Y41: Y
B42: 0.65833333 | C42: UAB 512B | D42: 3 | E42: 1 | F42: Kaliro | G42: Kaliro | H42: Uga | I42: 1 | J42: 1 | K42: =VLOOKUP(J42,Key!$E$2:$F$9,2,FALSE) -> Home | L42: Iganga | M42: Iganga | N42: Uga | O42: 2 | P42: 2 | Q42: =VLOOKUP(P42,Key!$E$2:$F$9,2,FALSE) -> Work | R42: =K42&"-"&Q42 -> Home-Work | S42: 32 | T42: 1 | U42: 2 | Y42: Y
...

Sheet 26.08 Iganga-Kaliro
B1: Consultancy services for Preparation of Expressway Development Master Plan (EDMP) for Uganda
B2: Roadside OD Interview Survey
B4: Date: | C4: 26.08.19 | E4: Road Name: | F4: ='24.08 Iganga-Kaliro'!F4:G4 -> Iganga-Kaliro Rd | I4: Direction From: | L4: Iganga | N4: Interviewers: | O4: Edith Kirabo | V4: Supervisor: | Y4: Coded By: | Z4: ='24.08 Iganga-Kaliro'!Z4 -> Isaac Akure | AA4: Chkd By: | AB4: ='24.08 Iganga-Kaliro'!AB4 -> Isaac M.
I5: Direction To: | L5: kaliro
B7: Time | C7: Veh_Reg_No. | D7: Veh_Type | E7: No. Occupants | F7: Origin_Address | I7: Origin_Establish | J7: Origin_Purpose | K7: Origin-Purpose Desc | L7: Destination_Address | O7: Destination_Establish | P7: Destination_Purpose | Q7: Destination_Purpose Desc | R7: Journey_Purpose | S7: Approx_Distance (Km) | T7: Approx_Journey Time (Hrs) | U7: Trip_Frequency | V7: GOODS VEHICLES ONLY | Y7: Would You Use Xpressways? | Z7: Pay How Much? (UGX) | AA7: Origin_Zone | AB7: Dest_Zone
F8: Village or Town | G8: District | H8: Country | L8: Village or Town | M8: District | N8: Country | V8: Goods_Type | W8: Goods_Quantity (Ton) | X8: Goods_Value (UGXm)
B9: 0.6875 | C9: UAT 226L | D9: 1 | E9: 2 | F9: Iganga | G9: Iganga | H9: Uga | I9: 1 | J9: 1 | K9: =VLOOKUP(J9,Key!$E$2:$F$9,2,FALSE) -> Home | L9: Kigulu | M9: Iganga | N9: Uga | O9: 16 | P9: 8 | Q9: =VLOOKUP(P9,Key!$E$2:$F$9,2,FALSE) -> Others | R9: =K9&"-"&Q9 -> Home-Others | T9: 0.5 | U9: 6 | Y9: Y
B10: 0.69097222 | C10: UAP 924V | D10: 2 | E10: 3 | F10: Iganga | G10: Iganga | H10: Uga | I10: 1 | J10: 1 | K10: =VLOOKUP(J10,Key!$E$2:$F$9,2,FALSE) -> Home | L10: Kalama | M10: Kaliro | N10: Uga | O10: 16 | P10: 8 | Q10: =VLOOKUP(P10,Key!$E$2:$F$9,2,FALSE) -> Others | R10: =K10&"-"&Q10 -> Home-Others | T10: 1 | U10: 3 | Y10: Y
B11: 0.68055556 | C11: UAY 151K | D11: 2 | E11: 1 | F11: Iganga | G11: Iganga | H11: Uga | I11: 2 | J11: 2 | K11: =VLOOKUP(J11,Key!$E$2:$F$9,2,FALSE) -> Work | L11: Kigulu | M11: Iganga | N11: Uga | O11: 1 | P11: 1 | Q11: =VLOOKUP(P11,Key!$E$2:$F$9,2,FALSE) -> Home | R11: =K11&"-"&Q11 -> Work-Home | T11: 0.5 | U11: 2 | Y11: Y
B12: 0.67708333 | C12: UAU 785L | D12: 8 | E12: 1 | F12: Iganga | G12: Iganga | H12: Uga | I12: 1 | J12: 1 | K12: =VLOOKUP(J12,Key!$E$2:$F$9,2,FALSE) -> Home | L12: Kigulu | M12: Iganga | N12: Uga | O12: 9 | P12: 2 | Q12: =VLOOKUP(P12,Key!$E$2:$F$9,2,FALSE) -> Work | R12: =K12&"-"&Q12 -> Home-Work | T12: 0.5 | U12: 2 | Y12: Y
B13: 0.69791667 | C13: UBB 027Q | D13: 1 | E13: 2 | F13: Iganga | G13: Iganga | H13: Uga | I13: 16 | J13: 8 | K13: =VLOOKUP(J13,Key!$E$2:$F$9,2,FALSE) -> Others | L13: Kabira | M13: Iganga | N13: Uga | O13: 1 | P13: 1 | Q13: =VLOOKUP(P13,Key!$E$2:$F$9,2,FALSE) -> Home | R13: =K13&"-"&Q13 -> Others-Home | S13: 27 | T13: 2 | U13: 6 | Y13: Y
B14: 0.69305556 | C14: UAQ 296R | D14: 7 | E14: 4 | F14: Iganga | G14: Iganga | H14: Uga | I14: 10 | J14: 2 | K14: =VLOOKUP(J14,Key!$E$2:$F$9,2,FALSE) -> Work | L14: Nabingala | M14: Iganga | N14: Uga | O14: 1 | P14: 1 | Q14: =VLOOKUP(P14,Key!$E$2:$F$9,2,FALSE) -> Home | R14: =K14&"-"&Q14 -> Work-Home | T14: 1 | U14: 2 | Y14: Y
B15: 0.70486111 | C15: UAQ 270K | D15: 3 | E15: 3 | F15: Iganga | G15: Iganga | H15: Uga | I15: 1 | J15: 1 | K15: =VLOOKUP(J15,Key!$E$2:$F$9,2,FALSE) -> Home | L15: Kalama | M15: Kaliro | N15: Uga | O15: 11 | P15: 2 | Q15: =VLOOKUP(P15,Key!$E$2:$F$9,2,FALSE) -> Work | R15: =K15&"-"&Q15 -> Home-Work | T15: 2 | U15: 2 | Y15: Y
B16: 0.70069444 | C16: UAS 728L | D16: 4 | E16: 14 | F16: Iganga | G16: Iganga | H16: Uga | I16: 6 | J16: 2 | K16: =VLOOKUP(J16,Key!$E$2:$F$9,2,FALSE) -> Work | L16: Kalama | M16: Kaliro | N16: Uga | O16: 6 | P16: 2 | Q16: =VLOOKUP(P16,Key!$E$2:$F$9,2,FALSE) -> Work | R16: =K16&"-"&Q16 -> Work-Work | T16: 2 | U16: 2 | Y16: Y
B17: 0.72569444 | C17: UAF 298L | D17: 2 | E17: 1 | F17: Iganga | G17: Iganga | H17: Uga | I17: 1 | J17: 1 | K17: =VLOOKUP(J17,Key!$E$2:$F$9,2,FALSE) -> Home | L17: Kigulu | M17: Iganga | N17: Uga | O17: 16 | P17: 8 | Q17: =VLOOKUP(P17,Key!$E$2:$F$9,2,FALSE) -> Others | R17: =K17&"-"&Q17 -> Home-Others | T17: 0.3 | U17: 2 | Y17: Y
B18: 0.62847222 | C18: UAL 897Q | D18: 4 | E18: 14 | F18: Iganga | G18: Iganga | H18: Uga | I18: 6 | J18: 2 | K18: =VLOOKUP(J18,Key!$E$2:$F$9,2,FALSE) -> Work | L18: Bunyiro | M18: Iganga | N18: Uga | O18: 6 | P18: 2 | Q18: =VLOOKUP(P18,Key!$E$2:$F$9,2,FALSE) -> Work | R18: =K18&"-"&Q18 -> Work-Work | S18: 2 | U18: 2 | Y18: Y
B19: 0.71875 | C19: UAX 257V | D19: 3 | E19: 4 | F19: Iganga | G19: Iganga | H19: Uga | I19: 1 | J19: 1 | K19: =VLOOKUP(J19,Key!$E$2:$F$9,2,FALSE) -> Home | L19: Nabitovu | M19: Iganga | N19: Uga | O19: 16 | P19: 8 | Q19: =VLOOKUP(P19,Key!$E$2:$F$9,2,FALSE) -> Others | R19: =K19&"-"&Q19 -> Home-Others | U19: 2 | Y19: Y
B20: 0.65486111 | C20: UAT 723D | D20: 1 | E20: 3 | F20: Iganga | G20: Iganga | H20: Uga | I20: 16 | J20: 8 | K20: =VLOOKUP(J20,Key!$E$2:$F$9,2,FALSE) -> Others | L20: Kalama | M20: Kaliro | N20: Uga | O20: 1 | P20: 1 | Q20: =VLOOKUP(P20,Key!$E$2:$F$9,2,FALSE) -> Home | R20: =K20&"-"&Q20 -> Others-Home | S20: 27 | T20: 2 | U20: 6 | Y20: Y
B21: 0.65069444 | C21: UAB 520H | D21: 4 | E21: 14 | F21: Iganga | G21: Iganga | H21: Uga | I21: 6 | J21: 2 | K21: =VLOOKUP(J21,Key!$E$2:$F$9,2,FALSE) -> Work | L21: Kaliro | M21: Iganga | N21: Uga | O21: 6 | P21: 2 | Q21: =VLOOKUP(P21,Key!$E$2:$F$9,2,FALSE) -> Work | R21: =K21&"-"&Q21 -> Work-Work | S21: 15 | T21: 1 | U21: 2 | Y21: Y
B22: 0.66527778 | C22: UAT 004D | D22: 1 | E22: 3 | F22: Iganga | G22: Iganga | H22: Uga | I22: 9 | J22: 2 | K22: =VLOOKUP(J22,Key!$E$2:$F$9,2,FALSE) -> Work | L22: Kalama | M22: Kaliro | N22: Uga | O22: 1 | P22: 1 | Q22: =VLOOKUP(P22,Key!$E$2:$F$9,2,FALSE) -> Home | R22: =K22&"-"&Q22 -> Work-Home | T22: 1.5 | U22: 1 | Y22: Y
B23: 0.67361111 | C23: UAV 928B | D23: 4 | E23: 14 | F23: Kampala | G23: Kampala | H23: Uga | I23: 6 | J23: 2 | K23: =VLOOKUP(J23,Key!$E$2:$F$9,2,FALSE) -> Work | L23: Kaliro | M23: Kaliro | N23: Uga | O23: 6 | P23: 2 | Q23: =VLOOKUP(P23,Key!$E$2:$F$9,2,FALSE) -> Work | R23: =K23&"-"&Q23 -> Work-Work | S23: 160 | T23: 4 | U23: 2 | Y23: Y
B24: 0.66319444 | C24: UBB 773L | D24: 4 | E24: 3 | F24: Busesa | G24: Bugwere | H24: Uga | I24: 1 | J24: 1 | K24: =VLOOKUP(J24,Key!$E$2:$F$9,2,FALSE) -> Home | L24: Kalama | M24: Kaliro | N24: Uga | O24: 6 | P24: 2 | Q24: =VLOOKUP(P24,Key!$E$2:$F$9,2,FALSE) -> Work | R24: =K24&"-"&Q24 -> Home-Work | T24: 2 | U24: 2 | Y24: Y
B25: 0.65763889 | C25: UBB 009K | D25: 2 | E25: 2 | F25: Iganga | G25: Iganga | H25: Uga | I25: 1 | J25: 1 | K25: =VLOOKUP(J25,Key!$E$2:$F$9,2,FALSE) -> Home | L25: Kaliro | M25: Kaliro | N25: Uga | O25: 11 | P25: 2 | Q25: =VLOOKUP(P25,Key!$E$2:$F$9,2,FALSE) -> Work | R25: =K25&"-"&Q25 -> Home-Work | S25: 15 | U25: 2 | Y25: Y
