Workbook

Sheet 19.08 Kampala-Bukaya
B1: Consultancy services for Preparation of Expressway Development Master Plan (EDMP) for Uganda
B2: MANUAL CLASSIFIED COUNT (MCC)
B3: ROAD NAME: | C3: MCC - C3 - STN92 - NALUBAALE ROAD
C5: Date | D5: 19.08.19 | F5: Location | G5: Nyenga | J5: Surveyor | K5: xxx
C6: Dir. From | D6: Kampala | F6: Dir. To | G6: Bukaya | J6: Supervisor | K6: xxx
B8: Time / Veh Type | R8: SUMMARY TRAFFIC VOLUMES
C9: 1. Car | D9: 2. Station Wagon | E9: 3. Pickups | F9: 4. Minibus, matatu | G9: 5. Medium bus | H9: 6. Large Bus | I9: 7. Light Truck | J9: 8. Medium Truck | K9: 9. Heavy truck | L9: 10. Truck Trailer | M9: 11. Motor cycles | N9: 12. Tractors | O9: Total Excl M/Cycles | P9: Total All | R9: Time | S9: 1. Car | T9: 2. Station Wagon | U9: 3. Pickups | V9: 4. Minibus, matatu | W9: 5. Medium bus | X9: 6. Large Bus | Y9: 7. Light Truck | Z9: 8. Medium Truck | AA9: 9. Heavy truck | AB9: 10. Truck Trailer | AC9: 11. Motorcycles | AD9: 12. Tractors, Graders | AE9: Total Excl M/ Cycles | AF9: Total All
B10: 07.00 - 07.15 | C10: 1 | D10: 0 | E10: 0 | F10: 0 | G10: 0 | H10: 0 | I10: 2 | J10: 0 | K10: 0 | L10: 0 | M10: 11 | N10: 0 | O10: =SUM(C10:L10,N10) -> 3 | P10: =SUM(C10:N10) -> 14 | R10: 0700-0800 | S10: =SUM(C10:C13) -> 7 | T10: =SUM(D10:D13) -> 0 | U10: =SUM(E10:E13) -> 5 | V10: =SUM(F10:F13) -> 4 | W10: =SUM(G10:G13) -> 0 | X10: =SUM(H10:H13) -> 0 | Y10: =SUM(I10:I13) -> 3 | Z10: =SUM(J10:J13) -> 0 | ... AF10: =SUM(P10:P13) -> 73
B11: 07.15 - 07.30 | C11: 1 | D11: 0 | E11: 0 | F11: 1 | G11: 0 | H11: 0 | I11: 0 | J11: 0 | K11: 0 | L11: 0 | M11: 10 | N11: 0 | O11: =SUM(C11:L11,N11) -> 2 | P11: =SUM(C11:N11) -> 12 | R11: 0800-0900 | S11: =SUM(C14:C17) -> 6 | T11: =SUM(D14:D17) -> 0 | U11: =SUM(E14:E17) -> 9 | V11: =SUM(F14:F17) -> 5 | W11: =SUM(G14:G17) -> 0 | X11: =SUM(H14:H17) -> 0 | Y11: =SUM(I14:I17) -> 4 | Z11: =SUM(J14:J17) -> 0 | ... AF11: =SUM(P14:P17) -> 81
B12: 07.30 - 07.45 | C12: 2 | D12: 0 | E12: 2 | F12: 0 | G12: 0 | H12: 0 | I12: 1 | J12: 0 | K12: 0 | L12: 0 | M12: 20 | N12: 1 | O12: =SUM(C12:L12,N12) -> 6 | P12: =SUM(C12:N12) -> 26 | R12: 0900-1000 | S12: =SUM(C18:C21) -> 10 | T12: =SUM(D18:D21) -> 0 | U12: =SUM(E18:E21) -> 5 | V12: =SUM(F18:F21) -> 7 | W12: =SUM(G18:G21) -> 0 | X12: =SUM(H18:H21) -> 0 | Y12: =SUM(I18:I21) -> 7 | Z12: =SUM(J18:J21) -> 2 | ... AF12: =SUM(P18:P21) -> 118
B13: 07.45 - 08.00 | C13: 3 | D13: 0 | E13: 3 | F13: 3 | G13: 0 | H13: 0 | I13: 0 | J13: 0 | K13: 0 | L13: 0 | M13: 12 | N13: 0 | O13: =SUM(C13:L13,N13) -> 9 | P13: =SUM(C13:N13) -> 21 | R13: 1000-1100 | S13: =SUM(C22:C25) -> 12 | T13: =SUM(D22:D25) -> 0 | U13: =SUM(E22:E25) -> 12 | V13: =SUM(F22:F25) -> 6 | W13: =SUM(G22:G25) -> 0 | X13: =SUM(H22:H25) -> 0 | Y13: =SUM(I22:I25) -> 7 | Z13: =SUM(J22:J25) -> 0 | ... AF13: =SUM(P22:P25) -> 122
B14: 08.00 - 08.15 | C14: 3 | D14: 0 | E14: 4 | F14: 0 | G14: 0 | H14: 0 | I14: 0 | J14: 0 | K14: 1 | L14: 0 | M14: 16 | N14: 0 | O14: =SUM(C14:L14,N14) -> 8 | P14: =SUM(C14:N14) -> 24 | R14: 1100-1200 | S14: =SUM(C26:C29) -> 13 | T14: =SUM(D26:D29) -> 0 | U14: =SUM(E26:E29) -> 13 | V14: =SUM(F26:F29) -> 10 | W14: =SUM(G26:G29) -> 0 | X14: =SUM(H26:H29) -> 0 | Y14: =SUM(I26:I29) -> 11 | Z14: =SUM(J26:J29) -> 0 | ... AF14: =SUM(P26:P29) -> 135
B15: 08.15 - 08.30 | C15: 0 | D15: 0 | E15: 0 | F15: 0 | G15: 0 | H15: 0 | I15: 1 | J15: 0 | K15: 0 | L15: 0 | M15: 13 | N15: 0 | O15: =SUM(C15:L15,N15) -> 1 | P15: =SUM(C15:N15) -> 14 | R15: 1200-1300 | S15: =SUM(C30:C33) -> 16 | T15: =SUM(D30:D33) -> 0 | U15: =SUM(E30:E33) -> 10 | V15: =SUM(F30:F33) -> 10 | W15: =SUM(G30:G33) -> 0 | X15: =SUM(H30:H33) -> 0 | Y15: =SUM(I30:I33) -> 11 | Z15: =SUM(J30:J33) -> 0 | ... AF15: =SUM(P30:P33) -> 132
B16: 08.30 - 08.45 | C16: 2 | D16: 0 | E16: 3 | F16: 2 | G16: 0 | H16: 0 | I16: 2 | J16: 0 | K16: 0 | L16: 0 | M16: 14 | N16: 0 | O16: =SUM(C16:L16,N16) -> 9 | P16: =SUM(C16:N16) -> 23 | R16: 1300-1400 | S16: =SUM(C34:C37) -> 16 | T16: =SUM(D34:D37) -> 0 | U16: =SUM(E34:E37) -> 13 | V16: =SUM(F34:F37) -> 16 | W16: =SUM(G34:G37) -> 1 | X16: =SUM(H34:H37) -> 0 | Y16: =SUM(I34:I37) -> 9 | Z16: =SUM(J34:J37) -> 0 | ... AF16: =SUM(P34:P37) -> 135
B17: 08.45 - 9.00 | C17: 1 | D17: 0 | E17: 2 | F17: 3 | G17: 0 | H17: 0 | I17: 1 | J17: 0 | K17: 0 | L17: 0 | M17: 13 | N17: 0 | O17: =SUM(C17:L17,N17) -> 7 | P17: =SUM(C17:N17) -> 20 | R17: 1400-1500 | S17: =SUM(C38:C41) -> 19 | T17: =SUM(D38:D41) -> 0 | U17: =SUM(E38:E41) -> 12 | V17: =SUM(F38:F41) -> 8 | W17: =SUM(G38:G41) -> 0 | X17: =SUM(H38:H41) -> 0 | Y17: =SUM(I38:I41) -> 7 | Z17: =SUM(J38:J41) -> 0 | ... AF17: =SUM(P38:P41) -> 134
B18: 09.00 - 09.15 | C18: 4 | D18: 0 | E18: 3 | F18: 1 | G18: 0 | H18: 0 | I18: 1 | J18: 0 | K18: 0 | L18: 0 | M18: 29 | N18: 0 | O18: =SUM(C18:L18,N18) -> 9 | P18: =SUM(C18:N18) -> 38 | R18: 1500-1600 | S18: =SUM(C42:C45) -> 11 | T18: =SUM(D42:D45) -> 0 | U18: =SUM(E42:E45) -> 10 | V18: =SUM(F42:F45) -> 8 | W18: =SUM(G42:G45) -> 0 | X18: =SUM(H42:H45) -> 0 | Y18: =SUM(I42:I45) -> 10 | Z18: =SUM(J42:J45) -> 0 | ... AF18: =SUM(P42:P45) -> 122
B19: 09.15 - 09.30 | C19: 1 | D19: 0 | E19: 1 | F19: 2 | G19: 0 | H19: 0 | I19: 3 | J19: 1 | K19: 0 | L19: 0 | M19: 19 | N19: 0 | O19: =SUM(C19:L19,N19) -> 8 | P19: =SUM(C19:N19) -> 27 | R19: 1600-1700 | S19: =SUM(C46:C49) -> 7 | T19: =SUM(D46:D49) -> 0 | U19: =SUM(E46:E49) -> 7 | V19: =SUM(F46:F49) -> 7 | W19: =SUM(G46:G49) -> 0 | X19: =SUM(H46:H49) -> 0 | Y19: =SUM(I46:I49) -> 6 | Z19: =SUM(J46:J49) -> 0 | ... AF19: =SUM(P46:P49) -> 138
B20: 09.30 - 09.45 | C20: 2 | D20: 0 | E20: 1 | F20: 0 | G20: 0 | H20: 0 | I20: 0 | J20: 1 | K20: 0 | L20: 0 | M20: 18 | N20: 0 | O20: =SUM(C20:L20,N20) -> 4 | P20: =SUM(C20:N20) -> 22 | R20: 1700-1800 | S20: =SUM(C50:C53) -> 11 | T20: =SUM(D50:D53) -> 0 | U20: =SUM(E50:E53) -> 14 | V20: =SUM(F50:F53) -> 8 | W20: =SUM(G50:G53) -> 0 | X20: =SUM(H50:H53) -> 0 | Y20: =SUM(I50:I53) -> 8 | Z20: =SUM(J50:J53) -> 0 | ... AF20: =SUM(P50:P53) -> 142
B21: 09.45 - 10.00 | C21: 3 | D21: 0 | E21: 0 | F21: 4 | G21: 0 | H21: 0 | I21: 3 | J21: 0 | K21: 0 | L21: 1 | M21: 20 | N21: 0 | O21: =SUM(C21:L21,N21) -> 11 | P21: =SUM(C21:N21) -> 31 | R21: 1800-1900 | S21: =SUM(C54:C57) -> 13 | T21: =SUM(D54:D57) -> 0 | U21: =SUM(E54:E57) -> 13 | V21: =SUM(F54:F57) -> 6 | W21: =SUM(G54:G57) -> 0 | X21: =SUM(H54:H57) -> 0 | Y21: =SUM(I54:I57) -> 7 | Z21: =SUM(J54:J57) -> 0 | ... AF21: =SUM(P54:P57) -> 163
B22: 10.00 - 10.15 | C22: 2 | D22: 0 | E22: 1 | F22: 1 | G22: 0 | H22: 0 | I22: 4 | J22: 0 | K22: 0 | L22: 0 | M22: 20 | N22: 0 | O22: =SUM(C22:L22,N22) -> 8 | P22: =SUM(C22:N22) -> 28 | R22: AM Peak Hr | S22: =MAX(S10:S12) -> 10 | T22: =MAX(T10:T12) -> 0 | U22: =MAX(U10:U12) -> 9 | V22: =MAX(V10:V12) -> 7 | W22: =MAX(W10:W12) -> 0 | X22: =MAX(X10:X12) -> 0 | Y22: =MAX(Y10:Y12) -> 7 | Z22: =MAX(Z10:Z12) -> 2 | ... AF22: =MAX(AF10:AF12) -> 118
B23: 10.15 - 10.30 | C23: 5 | D23: 0 | E23: 3 | F23: 2 | G23: 0 | H23: 0 | I23: 1 | J23: 0 | K23: 0 | L23: 0 | M23: 23 | N23: 0 | O23: =SUM(C23:L23,N23) -> 11 | P23: =SUM(C23:N23) -> 34 | R23: IP Peak Hr | S23: =MAX(S13:S18) -> 19 | T23: =MAX(T13:T18) -> 0 | U23: =MAX(U13:U18) -> 13 | V23: =MAX(V13:V18) -> 16 | W23: =MAX(W13:W18) -> 1 | X23: =MAX(X13:X18) -> 0 | Y23: =MAX(Y13:Y18) -> 11 | Z23: =MAX(Z13:Z18) -> 0 | ... AF23: =MAX(AF13:AF18) -> 135
B24: 10.30 - 10.45 | C24: 2 | D24: 0 | E24: 6 | F24: 0 | G24: 0 | H24: 0 | I24: 2 | J24: 0 | K24: 0 | L24: 0 | M24: 17 | N24: 0 | O24: =SUM(C24:L24,N24) -> 10 | P24: =SUM(C24:N24) -> 27 | R24: PM Peak Hr | S24: =MAX(S19:S21) -> 13 | T24: =MAX(T19:T21) -> 0 | U24: =MAX(U19:U21) -> 14 | V24: =MAX(V19:V21) -> 8 | W24: =MAX(W19:W21) -> 0 | X24: =MAX(X19:X21) -> 0 | Y24: =MAX(Y19:Y21) -> 8 | Z24: =MAX(Z19:Z21) -> 0 | ... AF24: =MAX(AF19:AF21) -> 163
B25: 10.45 - 11.00 | C25: 3 | D25: 0 | E25: 2 | F25: 3 | G25: 0 | H25: 0 | I25: 0 | J25: 0 | K25: 2 | L25: 0 | M25: 23 | N25: 0 | O25: =SUM(C25:L25,N25) -> 10 | P25: =SUM(C25:N25) -> 33 | R25: AM Period | S25: =SUM(S10:S12) -> 23 | T25: =SUM(T10:T12) -> 0 | U25: =SUM(U10:U12) -> 19 | V25: =SUM(V10:V12) -> 16 | W25: =SUM(W10:W12) -> 0 | X25: =SUM(X10:X12) -> 0 | Y25: =SUM(Y10:Y12) -> 14 | Z25: =SUM(Z10:Z12) -> 2 | ... AF25: =SUM(AF10:AF12) -> 272
B26: 11.00 - 11.15 | C26: 3 | D26: 0 | E26: 5 | F26: 3 | G26: 0 | H26: 0 | I26: 1 | J26: 0 | K26: 1 | L26: 0 | M26: 27 | N26: 0 | O26: =SUM(C26:L26,N26) -> 13 | P26: =SUM(C26:N26) -> 40 | R26: IP Period | S26: =SUM(S13:S18) -> 87 | T26: =SUM(T13:T18) -> 0 | U26: =SUM(U13:U18) -> 70 | V26: =SUM(V13:V18) -> 58 | W26: =SUM(W13:W18) -> 1 | X26: =SUM(X13:X18) -> 0 | Y26: =SUM(Y13:Y18) -> 55 | Z26: =SUM(Z13:Z18) -> 0 | ... AF26: =SUM(AF13:AF18) -> 780
B27: 11.15 - 11.30 | C27: 1 | D27: 0 | E27: 2 | F27: 1 | G27: 0 | H27: 0 | I27: 2 | J27: 0 | K27: 0 | L27: 0 | M27: 25 | N27: 0 | O27: =SUM(C27:L27,N27) -> 6 | P27: =SUM(C27:N27) -> 31 | R27: PM Period | S27: =SUM(S19:S21) -> 31 | T27: =SUM(T19:T21) -> 0 | U27: =SUM(U19:U21) -> 34 | V27: =SUM(V19:V21) -> 21 | W27: =SUM(W19:W21) -> 0 | X27: =SUM(X19:X21) -> 0 | Y27: =SUM(Y19:Y21) -> 21 | Z27: =SUM(Z19:Z21) -> 0 | ... AF27: =SUM(AF19:AF21) -> 443
B28: 11.30 - 11.45 | C28: 5 | D28: 0 | E28: 1 | F28: 5 | G28: 0 | H28: 0 | I28: 5 | J28: 0 | K28: 0 | L28: 0 | M28: 17 | N28: 0 | O28: =SUM(C28:L28,N28) -> 16 | P28: =SUM(C28:N28) -> 33 | R28: 12 Hours | S28: =SUM(S10:S21) -> 141 | T28: =SUM(T10:T21) -> 0 | U28: =SUM(U10:U21) -> 123 | V28: =SUM(V10:V21) -> 95 | W28: =SUM(W10:W21) -> 1 | X28: =SUM(X10:X21) -> 0 | Y28: =SUM(Y10:Y21) -> 90 | Z28: =SUM(Z10:Z21) -> 2 | ... AF28: =SUM(AF10:AF21) -> 1495
B29: 11.45 - 12.00 | C29: 4 | D29: 0 | E29: 5 | F29: 1 | G29: 0 | H29: 0 | I29: 3 | J29: 0 | K29: 0 | L29: 0 | M29: 18 | N29: 0 | O29: =SUM(C29:L29,N29) -> 13 | P29: =SUM(C29:N29) -> 31
B30: 12.00 - 12.15 | C30: 4 | D30: 0 | E30: 3 | F30: 4 | G30: 0 | H30: 0 | I30: 2 | J30: 0 | K30: 0 | L30: 0 | M30: 24 | N30: 0 | O30: =SUM(C30:L30,N30) -> 13 | P30: =SUM(C30:N30) -> 37
B31: 12.15 - 12.30 | C31: 4 | D31: 0 | E31: 2 | F31: 2 | G31: 0 | H31: 0 | I31: 3 | J31: 0 | K31: 0 | L31: 0 | M31: 16 | N31: 0 | O31: =SUM(C31:L31,N31) -> 11 | P31: =SUM(C31:N31) -> 27
B32: 12.30 - 12.45 | C32: 3 | D32: 0 | E32: 2 | F32: 1 | G32: 0 | H32: 0 | I32: 1 | J32: 0 | K32: 0 | L32: 0 | M32: 26 | N32: 0 | O32: =SUM(C32:L32,N32) -> 7 | P32: =SUM(C32:N32) -> 33
B33: 12.45 - 13.00 | C33: 5 | D33: 0 | E33: 3 | F33: 3 | G33: 0 | H33: 0 | I33: 5 | J33: 0 | K33: 0 | L33: 0 | M33: 19 | N33: 0 | O33: =SUM(C33:L33,N33) -> 16 | P33: =SUM(C33:N33) -> 35
B34: 13.00 - 13.15 | C34: 3 | D34: 0 | E34: 1 | F34: 2 | G34: 0 | H34: 0 | I34: 3 | J34: 0 | K34: 0 | L34: 0 | M34: 30 | N34: 0 | O34: =SUM(C34:L34,N34) -> 9 | P34: =SUM(C34:N34) -> 39
B35: 13.15 - 13.30 | C35: 2 | D35: 0 | E35: 3 | F35: 3 | G35: 0 | H35: 0 | I35: 3 | J35: 0 | K35: 1 | L35: 0 | M35: 13 | N35: 0 | O35: =SUM(C35:L35,N35) -> 12 | P35: =SUM(C35:N35) -> 25
B36: 13.30 - 13.45 | C36: 7 | D36: 0 | E36: 5 | F36: 6 | G36: 0 | H36: 0 | I36: 1 | J36: 0 | K36: 0 | L36: 0 | M36: 16 | N36: 0 | O36: =SUM(C36:L36,N36) -> 19 | P36: =SUM(C36:N36) -> 35
B37: 13.45 - 14.00 | C37: 4 | D37: 0 | E37: 4 | F37: 5 | G37: 1 | H37: 0 | I37: 2 | J37: 0 | K37: 0 | L37: 0 | M37: 20 | N37: 0 | O37: =SUM(C37:L37,N37) -> 16 | P37: =SUM(C37:N37) -> 36
B38: 14.00 - 14.15 | C38: 7 | D38: 0 | E38: 2 | F38: 2 | G38: 0 | H38: 0 | I38: 3 | J38: 0 | K38: 0 | L38: 0 | M38: 20 | N38: 0 | O38: =SUM(C38:L38,N38) -> 14 | P38: =SUM(C38:N38) -> 34
B39: 14.15 - 14.30 | C39: 6 | D39: 0 | E39: 4 | F39: 0 | G39: 0 | H39: 0 | I39: 2 | J39: 0 | K39: 1 | L39: 0 | M39: 23 | N39: 0 | O39: =SUM(C39:L39,N39) -> 13 | P39: =SUM(C39:N39) -> 36
B40: 14.30 - 14.45 | C40: 4 | D40: 0 | E40: 2 | F40: 5 | G40: 0 | H40: 0 | I40: 0 | J40: 0 | K40: 0 | L40: 0 | M40: 27 | N40: 0 | O40: =SUM(C40:L40,N40) -> 11 | P40: =SUM(C40:N40) -> 38
... B57: 18.45 - 19.00 | C57: 3 | D57: 0 | E57: 1 | F57: 2 | G57: 0 | H57: 0 | I57: 3 | J57: 0 | K57: 0 | L57: 0 | M57: 27 | N57: 0 | O57: =SUM(C57:L57,N57) -> 9 | P57: =SUM(C57:N57) -> 36
B58: Totals | C58: =SUM(C10:C57) -> 141 | D58: =SUM(D10:D57) -> 0 | E58: =SUM(E10:E57) -> 123 | F58: =SUM(F10:F57) -> 95 | G58: =SUM(G10:G57) -> 1 | H58: =SUM(H10:H57) -> 0 | I58: =SUM(I10:I57) -> 90 | J58: =SUM(J10:J57) -> 2 | ... P58: =SUM(P10:P57) -> 1495
...

Sheet 19.08 Bukaya-Kampala
B1: Consultancy services for Preparation of Expressway Development Master Plan (EDMP) for Uganda
B2: MANUAL CLASSIFIED COUNT (MCC)
B3: ROAD NAME: | C3: ='19.08 Kampala-Bukaya'!C3:G3 -> MCC - C3 - STN92 - NALUBAALE ROAD
C5: Date | D5: ='19.08 Kampala-Bukaya'!D5 -> 19.08.19 | F5: Location | G5: ='19.08 Kampala-Bukaya'!G5:H5 -> Nyenga | J5: Surveyor | K5: ='19.08 Kampala-Bukaya'!K5:L5 -> xxx
C6: Dir. From | D6: Bukaya | F6: Dir. To | G6: Kampala | J6: Supervisor | K6: ='19.08 Kampala-Bukaya'!K6:L6 -> xxx
B8: Time / Veh Type | R8: SUMMARY TRAFFIC VOLUMES
C9: 1. Car | D9: 2. Station Wagon | E9: 3. Pickups | F9: 4. Minibus, matatu | G9: 5. Medium bus | H9: 6. Large Bus | I9: 7. Light Truck | J9: 8. Medium Truck | K9: 9. Heavy truck | L9: 10. Truck Trailer | M9: 11. Motor cycles | N9: 12. Tractors | O9: Total Excl M/Cycles | P9: Total All | R9: Time | S9: 1. Car | T9: 2. Station Wagon | U9: 3. Pickups | V9: 4. Minibus, matatu | W9: 5. Medium bus | X9: 6. Large Bus | Y9: 7. Light Truck | Z9: 8. Medium Truck | AA9: 9. Heavy truck | AB9: 10. Truck Trailer | AC9: 11. Motorcycles | AD9: 12. Tractors, Graders | AE9: Total Excl M/ Cycles | AF9: Total All
B10: 07.00 - 07.15 | C10: 1 | D10: 0 | E10: 0 | F10: 2 | G10: 0 | H10: 0 | I10: 0 | J10: 0 | K10: 0 | L10: 0 | M10: 10 | N10: 0 | O10: =SUM(C10:L10,N10) -> 3 | P10: =SUM(C10:N10) -> 13 | R10: 0700-0800 | S10: =SUM(C10:C13) -> 2 | T10: =SUM(D10:D13) -> 0 | U10: =SUM(E10:E13) -> 2 | V10: =SUM(F10:F13) -> 7 | W10: =SUM(G10:G13) -> 0 | X10: =SUM(H10:H13) -> 0 | Y10: =SUM(I10:I13) -> 1 | Z10: =SUM(J10:J13) -> 0 | ... AF10: =SUM(P10:P13) -> 76
B11: 07.15 - 07.30 | C11: 0 | D11: 0 | E11: 0 | F11: 1 | G11: 0 | H11: 0 | I11: 1 | J11: 0 | K11: 0 | L11: 0 | M11: 17 | N11: 0 | O11: =SUM(C11:L11,N11) -> 2 | P11: =SUM(C11:N11) -> 19 | R11: 0800-0900 | S11: =SUM(C14:C17) -> 3 | T11: =SUM(D14:D17) -> 0 | U11: =SUM(E14:E17) -> 1 | V11: =SUM(F14:F17) -> 8 | W11: =SUM(G14:G17) -> 0 | X11: =SUM(H14:H17) -> 0 | Y11: =SUM(I14:I17) -> 3 | Z11: =SUM(J14:J17) -> 0 | ... AF11: =SUM(P14:P17) -> 81
B12: 07.30 - 07.45 | C12: 0 | D12: 0 | E12: 1 | F12: 4 | G12: 0 | H12: 0 | I12: 0 | J12: 0 | K12: 0 | L12: 0 | M12: 20 | N12: 0 | O12: =SUM(C12:L12,N12) -> 5 | P12: =SUM(C12:N12) -> 25 | R12: 0900-1000 | S12: =SUM(C18:C21) -> 5 | T12: =SUM(D18:D21) -> 0 | U12: =SUM(E18:E21) -> 3 | V12: =SUM(F18:F21) -> 3 | W12: =SUM(G18:G21) -> 0 | X12: =SUM(H18:H21) -> 0 | Y12: =SUM(I18:I21) -> 5 | Z12: =SUM(J18:J21) -> 1 | ... AF12: =SUM(P18:P21) -> 87
B13: 07.45 - 08.00 | C13: 1 | D13: 0 | E13: 1 | F13: 0 | G13: 0 | H13: 0 | I13: 0 | J13: 0 | K13: 0 | L13: 0 | M13: 17 | N13: 0 | O13: =SUM(C13:L13,N13) -> 2 | P13: =SUM(C13:N13) -> 19 | R13: 1000-1100 | S13: =SUM(C22:C25) -> 3 | T13: =SUM(D22:D25) -> 0 | U13: =SUM(E22:E25) -> 7 | V13: =SUM(F22:F25) -> 6 | W13: =SUM(G22:G25) -> 0 | X13: =SUM(H22:H25) -> 0 | Y13: =SUM(I22:I25) -> 1 | Z13: =SUM(J22:J25) -> 0 | ... AF13: =SUM(P22:P25) -> 93
B14: 08.00 - 08.15 | C14: 2 | D14: 0 | E14: 0 | F14: 3 | G14: 0 | H14: 0 | I14: 0 | J14: 0 | K14: 1 | L14: 1 | M14: 16 | N14: 0 | O14: =SUM(C14:L14,N14) -> 7 | P14: =SUM(C14:N14) -> 23 | R14: 1100-1200 | S14: =SUM(C26:C29) -> 9 | T14: =SUM(D26:D29) -> 0 | U14: =SUM(E26:E29) -> 5 | V14: =SUM(F26:F29) -> 6 | W14: =SUM(G26:G29) -> 0 | X14: =SUM(H26:H29) -> 0 | Y14: =SUM(I26:I29) -> 8 | Z14: =SUM(J26:J29) -> 0 | ... AF14: =SUM(P26:P29) -> 105
B15: 08.15 - 08.30 | C15: 1 | D15: 0 | E15: 0 | F15: 1 | G15: 0 | H15: 0 | I15: 1 | J15: 0 | K15: 0 | L15: 0 | M15: 14 | N15: 0 | O15: =SUM(C15:L15,N15) -> 3 | P15: =SUM(C15:N15) -> 17 | R15: 1200-1300 | S15: =SUM(C30:C33) -> 4 | T15: =SUM(D30:D33) -> 0 | U15: =SUM(E30:E33) -> 7 | V15: =SUM(F30:F33) -> 6 | W15: =SUM(G30:G33) -> 0 | X15: =SUM(H30:H33) -> 0 | Y15: =SUM(I30:I33) -> 4 | Z15: =SUM(J30:J33) -> 0 | ... AF15: =SUM(P30:P33) -> 101
B16: 08.30 - 08.45 | C16: 0 | D16: 0 | E16: 1 | F16: 2 | G16: 0 | H16: 0 | I16: 0 | J16: 0 | K16: 0 | L16: 0 | M16: 16 | N16: 0 | O16: =SUM(C16:L16,N16) -> 3 | P16: =SUM(C16:N16) -> 19 | R16: 1300-1400 | S16: =SUM(C34:C37) -> 8 | T16: =SUM(D34:D37) -> 0 | U16: =SUM(E34:E37) -> 3 | V16: =SUM(F34:F37) -> 6 | W16: =SUM(G34:G37) -> 0 | X16: =SUM(H34:H37) -> 0 | Y16: =SUM(I34:I37) -> 4 | Z16: =SUM(J34:J37) -> 0 | ... AF16: =SUM(P34:P37) -> 96
B17: 08.45 - 9.00 | C17: 0 | D17: 0 | E17: 0 | F17: 2 | G17: 0 | H17: 0 | I17: 2 | J17: 0 | K17: 0 | L17: 0 | M17: 18 | N17: 0 | O17: =SUM(C17:L17,N17) -> 4 | P17: =SUM(C17:N17) -> 22 | R17: 1400-1500 | S17: =SUM(C38:C41) -> 9 | T17: =SUM(D38:D41) -> 0 | U17: =SUM(E38:E41) -> 11 | V17: =SUM(F38:F41) -> 4 | W17: =SUM(G38:G41) -> 0 | X17: =SUM(H38:H41) -> 0 | Y17: =SUM(I38:I41) -> 10 | Z17: =SUM(J38:J41) -> 0 | ... AF17: =SUM(P38:P41) -> 129
B18: 09.00 - 09.15 | C18: 2 | D18: 0 | E18: 1 | F18: 2 | G18: 0 | H18: 0 | I18: 1 | J18: 1 | K18: 0 | L18: 0 | M18: 16 | N18: 0 | O18: =SUM(C18:L18,N18) -> 7 | P18: =SUM(C18:N18) -> 23 | R18: 1500-1600 | S18: =SUM(C42:C45) -> 11 | T18: =SUM(D42:D45) -> 0 | U18: =SUM(E42:E45) -> 9 | V18: =SUM(F42:F45) -> 5 | W18: =SUM(G42:G45) -> 1 | X18: =SUM(H42:H45) -> 0 | Y18: =SUM(I42:I45) -> 8 | Z18: =SUM(J42:J45) -> 1 | ... AF18: =SUM(P42:P45) -> 127
B19: 09.15 - 09.30 | C19: 1 | D19: 0 | E19: 0 | F19: 0 | G19: 0 | H19: 0 | I19: 0 | J19: 0 | K19: 1 | L19: 0 | M19: 15 | N19: 0 | O19: =SUM(C19:L19,N19) -> 2 | P19: =SUM(C19:N19) -> 17 | R19: 1600-1700 | S19: =SUM(C46:C49) -> 10 | T19: =SUM(D46:D49) -> 0 | U19: =SUM(E46:E49) -> 21 | V19: =SUM(F46:F49) -> 9 | W19: =SUM(G46:G49) -> 0 | X19: =SUM(H46:H49) -> 0 | Y19: =SUM(I46:I49) -> 11 | Z19: =SUM(J46:J49) -> 0 | ... AF19: =SUM(P46:P49) -> 147
B20: 09.30 - 09.45 | C20: 1 | D20: 0 | E20: 2 | F20: 1 | G20: 0 | H20: 0 | I20: 3 | J20: 0 | K20: 0 | L20: 0 | M20: 15 | N20: 0 | O20: =SUM(C20:L20,N20) -> 7 | P20: =SUM(C20:N20) -> 22 | R20: 1700-1800 | S20: =SUM(C50:C53) -> 24 | T20: =SUM(D50:D53) -> 0 | U20: =SUM(E50:E53) -> 26 | V20: =SUM(F50:F53) -> 17 | W20: =SUM(G50:G53) -> 1 | X20: =SUM(H50:H53) -> 0 | Y20: =SUM(I50:I53) -> 6 | Z20: =SUM(J50:J53) -> 0 | ... AF20: =SUM(P50:P53) -> 204
B21: 09.45 - 10.00 | C21: 1 | D21: 0 | E21: 0 | F21: 0 | G21: 0 | H21: 0 | I21: 1 | J21: 0 | K21: 0 | L21: 0 | M21: 23 | N21: 0 | O21: =SUM(C21:L21,N21) -> 2 | P21: =SUM(C21:N21) -> 25 | R21: 1800-1900 | S21: =SUM(C54:C57) -> 19 | T21: =SUM(D54:D57) -> 0 | U21: =SUM(E54:E57) -> 22 | V21: =SUM(F54:F57) -> 12 | W21: =SUM(G54:G57) -> 0 | X21: =SUM(H54:H57) -> 0 | Y21: =SUM(I54:I57) -> 13 | Z21: =SUM(J54:J57) -> 0 | ... AF21: =SUM(P54:P57) -> 190
B22: 10.00 - 10.15 | C22: 0 | D22: 0 | E22: 3 | F22: 1 | G22: 0 | H22: 0 | I22: 0 | J22: 0 | K22: 0 | L22: 0 | M22: 15 | N22: 0 | O22: =SUM(C22:L22,N22) -> 4 | P22: =SUM(C22:N22) -> 19 | R22: AM Peak Hr | S22: =MAX(S10:S12) -> 5 | T22: =MAX(T10:T12) -> 0 | U22: =MAX(U10:U12) -> 3 | V22: =MAX(V10:V12) -> 8 | W22: =MAX(W10:W12) -> 0 | X22: =MAX(X10:X12) -> 0 | Y22: =MAX(Y10:Y12) -> 5 | Z22: =MAX(Z10:Z12) -> 1 | ... AF22: =MAX(AF10:AF12) -> 87
B23: 10.15 - 10.30 | C23: 1 | D23: 0 | E23: 2 | F23: 2 | G23: 0 | H23: 0 | I23: 1 | J23: 0 | K23: 0 | L23: 0 | M23: 23 | N23: 0 | O23: =SUM(C23:L23,N23) -> 6 | P23: =SUM(C23:N23) -> 29 | R23: IP Peak Hr | S23: =MAX(S13:S18) -> 11 | T23: =MAX(T13:T18) -> 0 | U23: =MAX(U13:U18) -> 11 | V23: =MAX(V13:V18) -> 6 | W23: =MAX(W13:W18) -> 1 | X23: =MAX(X13:X18) -> 0 | Y23: =MAX(Y13:Y18) -> 10 | Z23: =MAX(Z13:Z18) -> 1 | ... AF23: =MAX(AF13:AF18) -> 129
B24: 10.30 - 10.45 | C24: 2 | D24: 0 | E24: 2 | F24: 2 | G24: 0 | H24: 0 | I24: 0 | J24: 0 | K24: 0 | L24: 0 | M24: 15 | N24: 0 | O24: =SUM(C24:L24,N24) -> 6 | P24: =SUM(C24:N24) -> 21 | R24: PM Peak Hr | S24: =MAX(S19:S21) -> 24 | T24: =MAX(T19:T21) -> 0 | U24: =MAX(U19:U21) -> 26 | V24: =MAX(V19:V21) -> 17 | W24: =MAX(W19:W21) -> 1 | X24: =MAX(X19:X21) -> 0 | Y24: =MAX(Y19:Y21) -> 13 | Z24: =MAX(Z19:Z21) -> 0 | ... AF24: =MAX(AF19:AF21) -> 204
B25: 10.45 - 11.00 | C25: 0 | D25: 0 | E25: 0 | F25: 1 | G25: 0 | H25: 0 | I25: 0 | J25: 0 | K25: 0 | L25: 0 | M25: 23 | N25: 0 | O25: =SUM(C25:L25,N25) -> 1 | P25: =SUM(C25:N25) -> 24 | R25: AM Period | S25: =SUM(S10:S12) -> 10 | T25: =SUM(T10:T12) -> 0 | U25: =SUM(U10:U12) -> 6 | V25: =SUM(V10:V12) -> 18 | W25: =SUM(W10:W12) -> 0 | X25: =SUM(X10:X12) -> 0 | Y25: =SUM(Y10:Y12) -> 9 | Z25: =SUM(Z10:Z12) -> 1 | ... AF25: =SUM(AF10:AF12) -> 244
B26: 11.00 - 11.15 | C26: 3 | D26: 0 | E26: 1 | F26: 2 | G26: 0 | H26: 0 | I26: 3 | J26: 0 | K26: 0 | L26: 0 | M26: 17 | N26: 0 | O26: =SUM(C26:L26,N26) -> 9 | P26: =SUM(C26:N26) -> 26 | R26: IP Period | S26: =SUM(S13:S18) -> 44 | T26: =SUM(T13:T18) -> 0 | U26: =SUM(U13:U18) -> 42 | V26: =SUM(V13:V18) -> 33 | W26: =SUM(W13:W18) -> 1 | X26: =SUM(X13:X18) -> 0 | Y26: =SUM(Y13:Y18) -> 35 | Z26: =SUM(Z13:Z18) -> 1 | ... AF26: =SUM(AF13:AF18) -> 651
B27: 11.15 - 11.30 | C27: 3 | D27: 0 | E27: 1 | F27: 2 | G27: 0 | H27: 0 | I27: 0 | J27: 0 | K27: 0 | L27: 0 | M27: 18 | N27: 0 | O27: =SUM(C27:L27,N27) -> 6 | P27: =SUM(C27:N27) -> 24 | R27: PM Period | S27: =SUM(S19:S21) -> 53 | T27: =SUM(T19:T21) -> 0 | U27: =SUM(U19:U21) -> 69 | V27: =SUM(V19:V21) -> 38 | W27: =SUM(W19:W21) -> 1 | X27: =SUM(X19:X21) -> 0 | Y27: =SUM(Y19:Y21) -> 30 | Z27: =SUM(Z19:Z21) -> 0 | ... AF27: =SUM(AF19:AF21) -> 541
B28: 11.30 - 11.45 | C28: 2 | D28: 0 | E28: 2 | F28: 1 | G28: 0 | H28: 0 | I28: 5 | J28: 0 | K28: 0 | L28: 0 | M28: 28 | N28: 0 | O28: =SUM(C28:L28,N28) -> 10 | P28: =SUM(C28:N28) -> 38 | R28: 12 Hours | S28: =SUM(S10:S21) -> 107 | T28: =SUM(T10:T21) -> 0 | U28: =SUM(U10:U21) -> 117 | V28: =SUM(V10:V21) -> 89 | W28: =SUM(W10:W21) -> 2 | X28: =SUM(X10:X21) -> 0 | Y28: =SUM(Y10:Y21) -> 74 | Z28: =SUM(Z10:Z21) -> 2 | ... AF28: =SUM(AF10:AF21) -> 1436
B29: 11.45 - 12.00 | C29: 1 | D29: 0 | E29: 1 | F29: 1 | G29: 0 | H29: 0 | I29: 0 | J29: 0 | K29: 0 | L29: 0 | M29: 14 | N29: 0 | O29: =SUM(C29:L29,N29) -> 3 | P29: =SUM(C29:N29) -> 17
B30: 12.00 - 12.15 | C30: 1 | D30: 0 | E30: 3 | F30: 2 | G30: 0 | H30: 0 | I30: 0 | J30: 0 | K30: 2 | L30: 0 | M30: 20 | N30: 0 | O30: =SUM(C30:L30,N30) -> 8 | P30: =SUM(C30:N30) -> 28
B31: 12.15 - 12.30 | C31: 1 | D31: 0 | E31: 1 | F31: 2 | G31: 0 | H31: 0 | I31: 1 | J31: 0 | K31: 0 | L31: 0 | M31: 17 | N31: 0 | O31: =SUM(C31:L31,N31) -> 5 | P31: =SUM(C31:N31) -> 22
B32: 12.30 - 12.45 | C32: 2 | D32: 0 | E32: 2 | F32: 0 | G32: 0 | H32: 0 | I32: 1 | J32: 0 | K32: 0 | L32: 0 | M32: 19 | N32: 0 | O32: =SUM(C32:L32,N32) -> 5 | P32: =SUM(C32:N32) -> 24
B33: 12.45 - 13.00 | C33: 0 | D33: 0 | E33: 1 | F33: 2 | G33: 0 | H33: 0 | I33: 2 | J33: 0 | K33: 0 | L33: 0 | M33: 22 | N33: 0 | O33: =SUM(C33:L33,N33) -> 5 | P33: =SUM(C33:N33) -> 27
B34: 13.00 - 13.15 | C34: 2 | D34: 0 | E34: 1 | F34: 0 | G34: 0 | H34: 0 | I34: 1 | J34: 0 | K34: 0 | L34: 0 | M34: 25 | N34: 0 | O34: =SUM(C34:L34,N34) -> 4 | P34: =SUM(C34:N34) -> 29
B35: 13.15 - 13.30 | C35: 3 | D35: 0 | E35: 0 | F35: 0 | G35: 0 | H35: 0 | I35: 0 | J35: 0 | K35: 0 | L35: 0 | M35: 21 | N35: 0 | O35: =SUM(C35:L35,N35) -> 3 | P35: =SUM(C35:N35) -> 24
B36: 13.30 - 13.45 | C36: 1 | D36: 0 | E36: 0 | F36: 3 | G36: 0 | H36: 0 | I36: 2 | J36: 0 | K36: 0 | L36: 0 | M36: 19 | N36: 0 | O36: =SUM(C36:L36,N36) -> 6 | P36: =SUM(C36:N36) -> 25
B37: 13.45 - 14.00 | C37: 2 | D37: 0 | E37: 2 | F37: 3 | G37: 0 | H37: 0 | I37: 1 | J37: 0 | K37: 0 | L37: 0 | M37: 10 | N37: 0 | O37: =SUM(C37:L37,N37) -> 8 | P37: =SUM(C37:N37) -> 18
B38: 14.00 - 14.15 | C38: 2 | D38: 0 | E38: 2 | F38: 2 | G38: 0 | H38: 0 | I38: 3 | J38: 0 | K38: 0 | L38: 0 | M38: 28 | N38: 0 | O38: =SUM(C38:L38,N38) -> 9 | P38: =SUM(C38:N38) -> 37
B39: 14.15 - 14.30 | C39: 0 | D39: 0 | E39: 2 | F39: 1 | G39: 0 | H39: 0 | I39: 3 | J39: 0 | K39: 0 | L39: 0 | M39: 19 | N39: 0 | O39: =SUM(C39:L39,N39) -> 6 | P39: =SUM(C39:N39) -> 25
B40: 14.30 - 14.45 | C40: 5 | D40: 0 | E40: 5 | F40: 0 | G40: 0 | H40: 0 | I40: 2 | J40: 0 | K40: 1 | L40: 0 | M40: 32 | N40: 0 | O40: =SUM(C40:L40,N40) -> 13 | P40: =SUM(C40:N40) -> 45
... B57: 18.45 - 19.00 | C57: 6 | D57: 0 | E57: 3 | F57: 2 | G57: 0 | H57: 0 | I57: 3 | J57: 0 | K57: 0 | L57: 0 | M57: 38 | N57: 0 | O57: =SUM(C57:L57,N57) -> 14 | P57: =SUM(C57:N57) -> 52
B58: Totals | C58: =SUM(C10:C57) -> 107 | D58: =SUM(D10:D57) -> 0 | E58: =SUM(E10:E57) -> 117 | F58: =SUM(F10:F57) -> 89 | G58: =SUM(G10:G57) -> 2 | H58: =SUM(H10:H57) -> 0 | I58: =SUM(I10:I57) -> 74 | J58: =SUM(J10:J57) -> 2 | ... P58: =SUM(P10:P57) -> 1436
...

Sheet 20.08 Kampala-Bukaya
B1: Consultancy services for Preparation of Expressway Development Master Plan (EDMP) for Uganda
B2: MANUAL CLASSIFIED COUNT (MCC)
B3: ROAD NAME: | C3: ='19.08 Kampala-Bukaya'!C3:G3 -> MCC - C3 - STN92 - NALUBAALE ROAD
C5: Date | D5: 20.08.19 | F5: Location | G5: ='19.08 Kampala-Bukaya'!G5:H5 -> Nyenga | J5: Surveyor | K5: ='19.08 Kampala-Bukaya'!K5:L5 -> xxx
C6: Dir. From | D6: ='19.08 Kampala-Bukaya'!D6:E6 -> Kampala | F6: Dir. To | G6: ='19.08 Kampala-Bukaya'!G6:H6 -> Bukaya | J6: Supervisor | K6: ='19.08 Kampala-Bukaya'!K6:L6 -> xxx
B8: Time / Veh Type | R8: SUMMARY TRAFFIC VOLUMES
C9: 1. Car | D9: 2. Station Wagon | E9: 3. Pickups | F9: 4. Minibus, matatu | G9: 5. Medium bus | H9: 6. Large Bus | I9: 7. Light Truck | J9: 8. Medium Truck | K9: 9. Heavy truck | L9: 10. Truck Trailer | M9: 11. Motor cycles | N9: 12. Tractors | O9: Total Excl M/Cycles | P9: Total All | R9: Time | S9: 1. Car | T9: 2. Station Wagon | U9: 3. Pickups | V9: 4. Minibus, matatu | W9: 5. Medium bus | X9: 6. Large Bus | Y9: 7. Light Truck | Z9: 8. Medium Truck | AA9: 9. Heavy truck | AB9: 10. Truck Trailer | AC9: 11. Motorcycles | AD9: 12. Tractors, Graders | AE9: Total Excl M/ Cycles | AF9: Total All
B10: 07.00 - 07.15 | C10: 0 | D10: 0 | E10: 0 | F10: 0 | G10: 0 | H10: 0 | I10: 1 | J10: 0 | K10: 0 | L10: 0 | M10: 13 | N10: 0 | O10: =SUM(C10:L10,N10) -> 1 | P10: =SUM(C10:N10) -> 14 | R10: 0700-0800 | S10: =SUM(C10:C13) -> 5 | T10: =SUM(D10:D13) -> 0 | U10: =SUM(E10:E13) -> 7 | V10: =SUM(F10:F13) -> 2 | W10: =SUM(G10:G13) -> 0 | X10: =SUM(H10:H13) -> 0 | Y10: =SUM(I10:I13) -> 7 | Z10: =SUM(J10:J13) -> 0 | ... AF10: =SUM(P10:P13) -> 75
B11: 07.15 - 07.30 | C11: 2 | D11: 0 | E11: 2 | F11: 1 | G11: 0 | H11: 0 | I11: 1 | J11: 0 | K11: 0 | L11: 0 | M11: 9 | N11: 0 | O11: =SUM(C11:L11,N11) -> 6 | P11: =SUM(C11:N11) -> 15 | R11: 0800-0900 | S11: =SUM(C14:C17) -> 5 | T11: =SUM(D14:D17) -> 0 | U11: =SUM(E14:E17) -> 10 | V11: =SUM(F14:F17) -> 4 | W11: =SUM(G14:G17) -> 0 | X11: =SUM(H14:H17) -> 0 | Y11: =SUM(I14:I17) -> 7 | Z11: =SUM(J14:J17) -> 0 | ... AF11: =SUM(P14:P17) -> 98
B12: 07.30 - 07.45 | C12: 1 | D12: 0 | E12: 2 | F12: 1 | G12: 0 | H12: 0 | I12: 2 | J12: 0 | K12: 0 | L12: 0 | M12: 12 | N12: 0 | O12: =SUM(C12:L12,N12) -> 6 | P12: =SUM(C12:N12) -> 18 | R12: 0900-1000 | S12: =SUM(C18:C21) -> 6 | T12: =SUM(D18:D21) -> 0 | U12: =SUM(E18:E21) -> 7 | V12: =SUM(F18:F21) -> 8 | W12: =SUM(G18:G21) -> 0 | X12: =SUM(H18:H21) -> 0 | Y12: =SUM(I18:I21) -> 7 | Z12: =SUM(J18:J21) -> 0 | ... AF12: =SUM(P18:P21) -> 98
B13: 07.45 - 08.00 | C13: 2 | D13: 0 | E13: 3 | F13: 0 | G13: 0 | H13: 0 | I13: 3 | J13: 0 | K13: 0 | L13: 0 | M13: 20 | N13: 0 | O13: =SUM(C13:L13,N13) -> 8 | P13: =SUM(C13:N13) -> 28 | R13: 1000-1100 | S13: =SUM(C22:C25) -> 12 | T13: =SUM(D22:D25) -> 0 | U13: =SUM(E22:E25) -> 14 | V13: =SUM(F22:F25) -> 6 | W13: =SUM(G22:G25) -> 0 | X13: =SUM(H22:H25) -> 0 | Y13: =SUM(I22:I25) -> 13 | Z13: =SUM(J22:J25) -> 0 | ... AF13: =SUM(P22:P25) -> 131
B14: 08.00 - 08.15 | C14: 1 | D14: 0 | E14: 2 | F14: 0 | G14: 0 | H14: 0 | I14: 3 | J14: 0 | K14: 0 | L14: 0 | M14: 21 | N14: 0 | O14: =SUM(C14:L14,N14) -> 6 | P14: =SUM(C14:N14) -> 27 | R14: 1100-1200 | S14: =SUM(C26:C29) -> 11 | T14: =SUM(D26:D29) -> 0 | U14: =SUM(E26:E29) -> 17 | V14: =SUM(F26:F29) -> 7 | W14: =SUM(G26:G29) -> 0 | X14: =SUM(H26:H29) -> 0 | Y14: =SUM(I26:I29) -> 11 | Z14: =SUM(J26:J29) -> 1 | ... AF14: =SUM(P26:P29) -> 132
B15: 08.15 - 08.30 | C15: 1 | D15: 0 | E15: 5 | F15: 0 | G15: 0 | H15: 0 | I15: 1 | J15: 0 | K15: 0 | L15: 0 | M15: 17 | N15: 1 | O15: =SUM(C15:L15,N15) -> 8 | P15: =SUM(C15:N15) -> 25 | R15: 1200-1300 | S15: =SUM(C30:C33) -> 8 | T15: =SUM(D30:D33) -> 0 | U15: =SUM(E30:E33) -> 15 | V15: =SUM(F30:F33) -> 7 | W15: =SUM(G30:G33) -> 2 | X15: =SUM(H30:H33) -> 0 | Y15: =SUM(I30:I33) -> 6 | Z15: =SUM(J30:J33) -> 0 | ... AF15: =SUM(P30:P33) -> 118
B16: 08.30 - 08.45 | C16: 2 | D16: 0 | E16: 1 | F16: 2 | G16: 0 | H16: 0 | I16: 2 | J16: 0 | K16: 0 | L16: 0 | M16: 14 | N16: 0 | O16: =SUM(C16:L16,N16) -> 7 | P16: =SUM(C16:N16) -> 21 | R16: 1300-1400 | S16: =SUM(C34:C37) -> 13 | T16: =SUM(D34:D37) -> 0 | U16: =SUM(E34:E37) -> 17 | V16: =SUM(F34:F37) -> 5 | W16: =SUM(G34:G37) -> 0 | X16: =SUM(H34:H37) -> 5 | Y16: =SUM(I34:I37) -> 6 | Z16: =SUM(J34:J37) -> 0 | ... AF16: =SUM(P34:P37) -> 94
B17: 08.45 - 9.00 | C17: 1 | D17: 0 | E17: 2 | F17: 2 | G17: 0 | H17: 0 | I17: 1 | J17: 0 | K17: 0 | L17: 0 | M17: 19 | N17: 0 | O17: =SUM(C17:L17,N17) -> 6 | P17: =SUM(C17:N17) -> 25 | R17: 1400-1500 | S17: =SUM(C38:C41) -> 14 | T17: =SUM(D38:D41) -> 0 | U17: =SUM(E38:E41) -> 12 | V17: =SUM(F38:F41) -> 10 | W17: =SUM(G38:G41) -> 0 | X17: =SUM(H38:H41) -> 0 | Y17: =SUM(I38:I41) -> 8 | Z17: =SUM(J38:J41) -> 0 | ... AF17: =SUM(P38:P41) -> 122
B18: 09.00 - 09.15 | C18: 0 | D18: 0 | E18: 1 | F18: 1 | G18: 0 | H18: 0 | I18: 3 | J18: 0 | K18: 0 | L18: 0 | M18: 8 | N18: 0 | O18: =SUM(C18:L18,N18) -> 5 | P18: =SUM(C18:N18) -> 13 | R18: 1500-1600 | S18: =SUM(C42:C45) -> 14 | T18: =SUM(D42:D45) -> 0 | U18: =SUM(E42:E45) -> 13 | V18: =SUM(F42:F45) -> 7 | W18: =SUM(G42:G45) -> 0 | X18: =SUM(H42:H45) -> 0 | Y18: =SUM(I42:I45) -> 6 | Z18: =SUM(J42:J45) -> 1 | ... AF18: =SUM(P42:P45) -> 130
B19: 09.15 - 09.30 | C19: 0 | D19: 0 | E19: 2 | F19: 0 | G19: 0 | H19: 0 | I19: 1 | J19: 0 | K19: 0 | L19: 0 | M19: 20 | N19: 0 | O19: =SUM(C19:L19,N19) -> 3 | P19: =SUM(C19:N19) -> 23 | R19: 1600-1700 | S19: =SUM(C46:C49) -> 13 | T19: =SUM(D46:D49) -> 0 | U19: =SUM(E46:E49) -> 8 | V19: =SUM(F46:F49) -> 6 | W19: =SUM(G46:G49) -> 0 | X19: =SUM(H46:H49) -> 0 | Y19: =SUM(I46:I49) -> 7 | Z19: =SUM(J46:J49) -> 0 | ... AF19: =SUM(P46:P49) -> 124
B20: 09.30 - 09.45 | C20: 5 | D20: 0 | E20: 2 | F20: 6 | G20: 0 | H20: 0 | I20: 2 | J20: 0 | K20: 0 | L20: 0 | M20: 26 | N20: 0 | O20: =SUM(C20:L20,N20) -> 15 | P20: =SUM(C20:N20) -> 41 | R20: 1700-1800 | S20: =SUM(C50:C53) -> 7 | T20: =SUM(D50:D53) -> 0 | U20: =SUM(E50:E53) -> 6 | V20: =SUM(F50:F53) -> 11 | W20: =SUM(G50:G53) -> 1 | X20: =SUM(H50:H53) -> 0 | Y20: =SUM(I50:I53) -> 10 | Z20: =SUM(J50:J53) -> 0 | ... AF20: =SUM(P50:P53) -> 134
B21: 09.45 - 10.00 | C21: 1 | D21: 0 | E21: 2 | F21: 1 | G21: 0 | H21: 0 | I21: 1 | J21: 0 | K21: 0 | L21: 0 | M21: 16 | N21: 0 | O21: =SUM(C21:L21,N21) -> 5 | P21: =SUM(C21:N21) -> 21 | R21: 1800-1900 | S21: =SUM(C54:C57) -> 6 | T21: =SUM(D54:D57) -> 0 | U21: =SUM(E54:E57) -> 6 | V21: =SUM(F54:F57) -> 7 | W21: =SUM(G54:G57) -> 0 | X21: =SUM(H54:H57) -> 0 | Y21: =SUM(I54:I57) -> 8 | Z21: =SUM(J54:J57) -> 0 | ... AF21: =SUM(P54:P57) -> 121
B22: 10.00 - 10.15 | C22: 2 | D22: 0 | E22: 7 | F22: 1 | G22: 0 | H22: 0 | I22: 3 | J22: 0 | K22: 1 | L22: 0 | M22: 24 | N22: 0 | O22: =SUM(C22:L22,N22) -> 14 | P22: =SUM(C22:N22) -> 38 | R22: AM Peak Hr | S22: =MAX(S10:S12) -> 6 | T22: =MAX(T10:T12) -> 0 | U22: =MAX(U10:U12) -> 10 | V22: =MAX(V10:V12) -> 8 | W22: =MAX(W10:W12) -> 0 | X22: =MAX(X10:X12) -> 0 | Y22: =MAX(Y10:Y12) -> 7 | Z22: =MAX(Z10:Z12) -> 0 | ... AF22: =MAX(AF10:AF12) -> 98
B23: 10.15 - 10.30 | C23: 6 | D23: 0 | E23: 3 | F23: 0 | G23: 0 | H23: 0 | I23: 2 | J23: 0 | K23: 0 | L23: 0 | M23: 15 | N23: 0 | O23: =SUM(C23:L23,N23) -> 11 | P23: =SUM(C23:N23) -> 26 | R23: IP Peak Hr | S23: =MAX(S13:S18) -> 14 | T23: =MAX(T13:T18) -> 0 | U23: =MAX(U13:U18) -> 17 | V23: =MAX(V13:V18) -> 10 | W23: =MAX(W13:W18) -> 2 | X23: =MAX(X13:X18) -> 5 | Y23: =MAX(Y13:Y18) -> 13 | Z23: =MAX(Z13:Z18) -> 1 | ... AF23: =MAX(AF13:AF18) -> 132
B24: 10.30 - 10.45 | C24: 4 | D24: 0 | E24: 2 | F24: 3 | G24: 0 | H24: 0 | I24: 4 | J24: 0 | K24: 1 | L24: 0 | M24: 23 | N24: 0 | O24: =SUM(C24:L24,N24) -> 14 | P24: =SUM(C24:N24) -> 37 | R24: PM Peak Hr | S24: =MAX(S19:S21) -> 13 | T24: =MAX(T19:T21) -> 0 | U24: =MAX(U19:U21) -> 8 | V24: =MAX(V19:V21) -> 11 | W24: =MAX(W19:W21) -> 1 | X24: =MAX(X19:X21) -> 0 | Y24: =MAX(Y19:Y21) -> 10 | Z24: =MAX(Z19:Z21) -> 0 | ... AF24: =MAX(AF19:AF21) -> 134
B25: 10.45 - 11.00 | C25: 0 | D25: 0 | E25: 2 | F25: 2 | G25: 0 | H25: 0 | I25: 4 | J25: 0 | K25: 0 | L25: 0 | M25: 22 | N25: 0 | O25: =SUM(C25:L25,N25) -> 8 | P25: =SUM(C25:N25) -> 30 | R25: AM Period | S25: =SUM(S10:S12) -> 16 | T25: =SUM(T10:T12) -> 0 | U25: =SUM(U10:U12) -> 24 | V25: =SUM(V10:V12) -> 14 | W25: =SUM(W10:W12) -> 0 | X25: =SUM(X10:X12) -> 0 | Y25: =SUM(Y10:Y12) -> 21 | Z25: =SUM(Z10:Z12) -> 0 | ... AF25: =SUM(AF10:AF12) -> 271
B26: 11.00 - 11.15 | C26: 4 | D26: 0 | E26: 6 | F26: 3 | G26: 0 | H26: 0 | I26: 3 | J26: 0 | K26: 0 | L26: 0 | M26: 19 | N26: 0 | O26: =SUM(C26:L26,N26) -> 16 | P26: =SUM(C26:N26) -> 35 | R26: IP Period | S26: =SUM(S13:S18) -> 72 | T26: =SUM(T13:T18) -> 0 | U26: =SUM(U13:U18) -> 88 | V26: =SUM(V13:V18) -> 42 | W26: =SUM(W13:W18) -> 2 | X26: =SUM(X13:X18) -> 5 | Y26: =SUM(Y13:Y18) -> 50 | Z26: =SUM(Z13:Z18) -> 2 | ... AF26: =SUM(AF13:AF18) -> 727
B27: 11.15 - 11.30 | C27: 2 | D27: 0 | E27: 7 | F27: 0 | G27: 0 | H27: 0 | I27: 3 | J27: 1 | K27: 0 | L27: 0 | M27: 18 | N27: 0 | O27: =SUM(C27:L27,N27) -> 13 | P27: =SUM(C27:N27) -> 31 | R27: PM Period | S27: =SUM(S19:S21) -> 26 | T27: =SUM(T19:T21) -> 0 | U27: =SUM(U19:U21) -> 20 | V27: =SUM(V19:V21) -> 24 | W27: =SUM(W19:W21) -> 1 | X27: =SUM(X19:X21) -> 0 | Y27: =SUM(Y19:Y21) -> 25 | Z27: =SUM(Z19:Z21) -> 0 | ... AF27: =SUM(AF19:AF21) -> 379
B28: 11.30 - 11.45 | C28: 3 | D28: 0 | E28: 0 | F28: 2 | G28: 0 | H28: 0 | I28: 2 | J28: 0 | K28: 0 | L28: 0 | M28: 25 | N28: 0 | O28: =SUM(C28:L28,N28) -> 7 | P28: =SUM(C28:N28) -> 32 | R28: 12 Hours | S28: =SUM(S10:S21) -> 114 | T28: =SUM(T10:T21) -> 0 | U28: =SUM(U10:U21) -> 132 | V28: =SUM(V10:V21) -> 80 | W28: =SUM(W10:W21) -> 3 | X28: =SUM(X10:X21) -> 5 | Y28: =SUM(Y10:Y21) -> 96 | Z28: =SUM(Z10:Z21) -> 2 | ... AF28: =SUM(AF10:AF21) -> 1377
B29: 11.45 - 12.00 | C29: 2 | D29: 0 | E29: 4 | F29: 2 | G29: 0 | H29: 0 | I29: 3 | J29: 0 | K29: 0 | L29: 0 | M29: 23 | N29: 0 | O29: =SUM(C29:L29,N29) -> 11 | P29: =SUM(C29:N29) -> 34
B30: 12.00 - 12.15 | C30: 3 | D30: 0 | E30: 5 | F30: 3 | G30: 0 | H30: 0 | I30: 1 | J30: 0 | K30: 0 | L30: 0 | M30: 22 | N30: 0 | O30: =SUM(C30:L30,N30) -> 12 | P30: =SUM(C30:N30) -> 34
B31: 12.15 - 12.30 | C31: 2 | D31: 0 | E31: 3 | F31: 0 | G31: 0 | H31: 0 | I31: 0 | J31: 0 | K31: 0 | L31: 0 | M31: 21 | N31: 0 | O31: =SUM(C31:L31,N31) -> 5 | P31: =SUM(C31:N31) -> 26
B32: 12.30 - 12.45 | C32: 1 | D32: 0 | E32: 4 | F32: 1 | G32: 2 | H32: 0 | I32: 3 | J32: 0 | K32: 0 | L32: 0 | M32: 23 | N32: 0 | O32: =SUM(C32:L32,N32) -> 11 | P32: =SUM(C32:N32) -> 34
B33: 12.45 - 13.00 | C33: 2 | D33: 0 | E33: 3 | F33: 3 | G33: 0 | H33: 0 | I33: 2 | J33: 0 | K33: 0 | L33: 0 | M33: 14 | N33: 0 | O33: =SUM(C33:L33,N33) -> 10 | P33: =SUM(C33:N33) -> 24
B34: 13.00 - 13.15 | C34: 4 | D34: 0 | E34: 4 | F34: 0 | G34: 0 | H34: 0 | I34: 0 | J34: 0 | K34: 0 | L34: 0 | M34: 15 | N34: 0 | O34: =SUM(C34:L34,N34) -> 8 | P34: =SUM(C34:N34) -> 23
B35: 13.15 - 13.30 | C35: 4 | D35: 0 | E35: 4 | F35: 3 | G35: 0 | H35: 0 | I35: 2 | J35: 0 | K35: 0 | L35: 0 | M35: 8 | N35: 0 | O35: =SUM(C35:L35,N35) -> 13 | P35: =SUM(C35:N35) -> 21
B36: 13.30 - 13.45 | C36: 2 | D36: 0 | E36: 4 | F36: 0 | G36: 0 | H36: 5 | I36: 1 | J36: 0 | K36: 1 | L36: 0 | M36: 11 | N36: 0 | O36: =SUM(C36:L36,N36) -> 13 | P36: =SUM(C36:N36) -> 24
B37: 13.45 - 14.00 | C37: 3 | D37: 0 | E37: 5 | F37: 2 | G37: 0 | H37: 0 | I37: 3 | J37: 0 | K37: 1 | L37: 0 | M37: 12 | N37: 0 | O37: =SUM(C37:L37,N37) -> 14 | P37: =SUM(C37:N37) -> 26
B38: 14.00 - 14.15 | C38: 4 | D38: 0 | E38: 5 | F38: 3 | G38: 0 | H38: 0 | I38: 2 | J38: 0 | K38: 0 | L38: 0 | M38: 16 | N38: 0 | O38: =SUM(C38:L38,N38) -> 14 | P38: =SUM(C38:N38) -> 30
B39: 14.15 - 14.30 | C39: 3 | D39: 0 | E39: 4 | F39: 2 | G39: 0 | H39: 0 | I39: 2 | J39: 0 | K39: 0 | L39: 0 | M39: 16 | N39: 0 | O39: =SUM(C39:L39,N39) -> 11 | P39: =SUM(C39:N39) -> 27
B40: 14.30 - 14.45 | C40: 4 | D40: 0 | E40: 0 | F40: 4 | G40: 0 | H40: 0 | I40: 2 | J40: 0 | K40: 0 | L40: 0 | M40: 26 | N40: 0 | O40: =SUM(C40:L40,N40) -> 10 | P40: =SUM(C40:N40) -> 36
... B57: 18.45 - 19.00 | C57: 1 | D57: 0 | E57: 2 | F57: 3 | G57: 0 | H57: 0 | I57: 1 | J57: 0 | K57: 0 | L57: 0 | M57: 24 | N57: 1 | O57: =SUM(C57:L57,N57) -> 8 | P57: =SUM(C57:N57) -> 32
B58: Totals | C58: =SUM(C10:C57) -> 114 | D58: =SUM(D10:D57) -> 0 | E58: =SUM(E10:E57) -> 132 | F58: =SUM(F10:F57) -> 80 | G58: =SUM(G10:G57) -> 3 | H58: =SUM(H10:H57) -> 5 | I58: =SUM(I10:I57) -> 96 | J58: =SUM(J10:J57) -> 2 | ... P58: =SUM(P10:P57) -> 1377
...

Sheet 20.08 Bukaya-Kampala
B1: Consultancy services for Preparation of Expressway Development Master Plan (EDMP) for Uganda
B2: MANUAL CLASSIFIED COUNT (MCC)
B3: ROAD NAME: | C3: ='19.08 Bukaya-Kampala'!C3:G3 -> MCC - C3 - STN92 - NALUBAALE ROAD
C5: Date | D5: ='20.08 Kampala-Bukaya'!D5 -> 20.08.19 | F5: Location | G5: ='19.08 Kampala-Bukaya'!G5:H5 -> Nyenga | J5: Surveyor | K5: ='19.08 Kampala-Bukaya'!K5:L5 -> xxx
C6: Dir. From | D6: ='19.08 Bukaya-Kampala'!D6:E6 -> Bukaya | F6: Dir. To | G6: ='19.08 Bukaya-Kampala'!G6:H6 -> Kampala | J6: Supervisor | K6: ='19.08 Kampala-Bukaya'!K6:L6 -> xxx
B8: Time / Veh Type | R8: SUMMARY TRAFFIC VOLUMES
C9: 1. Car | D9: 2. Station Wagon | E9: 3. Pickups | F9: 4. Minibus, matatu | G9: 5. Medium bus | H9: 6. Large Bus | I9: 7. Light Truck | J9: 8. Medium Truck | K9: 9. Heavy truck | L9: 10. Truck Trailer | M9: 11. Motor cycles | N9: 12. Tractors | O9: Total Excl M/Cycles | P9: Total All | R9: Time | S9: 1. Car | T9: 2. Station Wagon | U9: 3. Pickups | V9: 4. Minibus, matatu | W9: 5. Medium bus | X9: 6. Large Bus | Y9: 7. Light Truck | Z9: 8. Medium Truck | AA9: 9. Heavy truck | AB9: 10. Truck Trailer | AC9: 11. Motorcycles | AD9: 12. Tractors, Graders | AE9: Total Excl M/ Cycles | AF9: Total All
B10: 07.00 - 07.15 | C10: 1 | D10: 0 | E10: 0 | F10: 1 | G10: 0 | H10: 0 | I10: 1 | J10: 0 | K10: 0 | L10: 0 | M10: 12 | N10: 0 | O10: =SUM(C10:L10,N10) -> 3 | P10: =SUM(C10:N10) -> 15 | R10: 0700-0800 | S10: =SUM(C10:C13) -> 3 | T10: =SUM(D10:D13) -> 0 | U10: =SUM(E10:E13) -> 0 | V10: =SUM(F10:F13) -> 6 | W10: =SUM(G10:G13) -> 0 | X10: =SUM(H10:H13) -> 0 | Y10: =SUM(I10:I13) -> 2 | Z10: =SUM(J10:J13) -> 1 | ... AF10: =SUM(P10:P13) -> 60
B11: 07.15 - 07.30 | C11: 0 | D11: 0 | E11: 0 | F11: 0 | G11: 0 | H11: 0 | I11: 0 | J11: 0 | K11: 0 | L11: 0 | M11: 10 | N11: 0 | O11: =SUM(C11:L11,N11) -> 0 | P11: =SUM(C11:N11) -> 10 | R11: 0800-0900 | S11: =SUM(C14:C17) -> 9 | T11: =SUM(D14:D17) -> 0 | U11: =SUM(E14:E17) -> 3 | V11: =SUM(F14:F17) -> 3 | W11: =SUM(G14:G17) -> 0 | X11: =SUM(H14:H17) -> 0 | Y11: =SUM(I14:I17) -> 4 | Z11: =SUM(J14:J17) -> 0 | ... AF11: =SUM(P14:P17) -> 81
B12: 07.30 - 07.45 | C12: 1 | D12: 0 | E12: 0 | F12: 4 | G12: 0 | H12: 0 | I12: 1 | J12: 1 | K12: 0 | L12: 0 | M12: 8 | N12: 0 | O12: =SUM(C12:L12,N12) -> 7 | P12: =SUM(C12:N12) -> 15 | R12: 0900-1000 | S12: =SUM(C18:C21) -> 2 | T12: =SUM(D18:D21) -> 0 | U12: =SUM(E18:E21) -> 3 | V12: =SUM(F18:F21) -> 6 | W12: =SUM(G18:G21) -> 0 | X12: =SUM(H18:H21) -> 0 | Y12: =SUM(I18:I21) -> 8 | Z12: =SUM(J18:J21) -> 0 | ... AF12: =SUM(P18:P21) -> 82
B13: 07.45 - 08.00 | C13: 1 | D13: 0 | E13: 0 | F13: 1 | G13: 0 | H13: 0 | I13: 0 | J13: 0 | K13: 0 | L13: 0 | M13: 18 | N13: 0 | O13: =SUM(C13:L13,N13) -> 2 | P13: =SUM(C13:N13) -> 20 | R13: 1000-1100 | S13: =SUM(C22:C25) -> 5 | T13: =SUM(D22:D25) -> 0 | U13: =SUM(E22:E25) -> 6 | V13: =SUM(F22:F25) -> 3 | W13: =SUM(G22:G25) -> 1 | X13: =SUM(H22:H25) -> 0 | Y13: =SUM(I22:I25) -> 10 | Z13: =SUM(J22:J25) -> 0 | ... AF13: =SUM(P22:P25) -> 106
B14: 08.00 - 08.15 | C14: 3 | D14: 0 | E14: 2 | F14: 1 | G14: 0 | H14: 0 | I14: 2 | J14: 0 | K14: 1 | L14: 0 | M14: 21 | N14: 0 | O14: =SUM(C14:L14,N14) -> 9 | P14: =SUM(C14:N14) -> 30 | R14: 1100-1200 | S14: =SUM(C26:C29) -> 7 | T14: =SUM(D26:D29) -> 0 | U14: =SUM(E26:E29) -> 6 | V14: =SUM(F26:F29) -> 5 | W14: =SUM(G26:G29) -> 0 | X14: =SUM(H26:H29) -> 0 | Y14: =SUM(I26:I29) -> 5 | Z14: =SUM(J26:J29) -> 2 | ... AF14: =SUM(P26:P29) -> 101
B15: 08.15 - 08.30 | C15: 2 | D15: 0 | E15: 1 | F15: 0 | G15: 0 | H15: 0 | I15: 0 | J15: 0 | K15: 1 | L15: 0 | M15: 15 | N15: 0 | O15: =SUM(C15:L15,N15) -> 4 | P15: =SUM(C15:N15) -> 19 | R15: 1200-1300 | S15: =SUM(C30:C33) -> 4 | T15: =SUM(D30:D33) -> 0 | U15: =SUM(E30:E33) -> 7 | V15: =SUM(F30:F33) -> 6 | W15: =SUM(G30:G33) -> 0 | X15: =SUM(H30:H33) -> 0 | Y15: =SUM(I30:I33) -> 8 | Z15: =SUM(J30:J33) -> 0 | ... AF15: =SUM(P30:P33) -> 120
B16: 08.30 - 08.45 | C16: 3 | D16: 0 | E16: 0 | F16: 1 | G16: 0 | H16: 0 | I16: 2 | J16: 0 | K16: 0 | L16: 0 | M16: 12 | N16: 0 | O16: =SUM(C16:L16,N16) -> 6 | P16: =SUM(C16:N16) -> 18 | R16: 1300-1400 | S16: =SUM(C34:C37) -> 6 | T16: =SUM(D34:D37) -> 0 | U16: =SUM(E34:E37) -> 12 | V16: =SUM(F34:F37) -> 8 | W16: =SUM(G34:G37) -> 0 | X16: =SUM(H34:H37) -> 0 | Y16: =SUM(I34:I37) -> 5 | Z16: =SUM(J34:J37) -> 0 | ... AF16: =SUM(P34:P37) -> 98
B17: 08.45 - 9.00 | C17: 1 | D17: 0 | E17: 0 | F17: 1 | G17: 0 | H17: 0 | I17: 0 | J17: 0 | K17: 0 | L17: 0 | M17: 12 | N17: 0 | O17: =SUM(C17:L17,N17) -> 2 | P17: =SUM(C17:N17) -> 14 | R17: 1400-1500 | S17: =SUM(C38:C41) -> 8 | T17: =SUM(D38:D41) -> 0 | U17: =SUM(E38:E41) -> 6 | V17: =SUM(F38:F41) -> 8 | W17: =SUM(G38:G41) -> 0 | X17: =SUM(H38:H41) -> 0 | Y17: =SUM(I38:I41) -> 3 | Z17: =SUM(J38:J41) -> 1 | ... AF17: =SUM(P38:P41) -> 126
B18: 09.00 - 09.15 | C18: 0 | D18: 0 | E18: 1 | F18: 1 | G18: 0 | H18: 0 | I18: 3 | J18: 0 | K18: 0 | L18: 0 | M18: 9 | N18: 0 | O18: =SUM(C18:L18,N18) -> 5 | P18: =SUM(C18:N18) -> 14 | R18: 1500-1600 | S18: =SUM(C42:C45) -> 8 | T18: =SUM(D42:D45) -> 0 | U18: =SUM(E42:E45) -> 17 | V18: =SUM(F42:F45) -> 6 | W18: =SUM(G42:G45) -> 0 | X18: =SUM(H42:H45) -> 0 | Y18: =SUM(I42:I45) -> 12 | Z18: =SUM(J42:J45) -> 0 | ... AF18: =SUM(P42:P45) -> 126
B19: 09.15 - 09.30 | C19: 1 | D19: 0 | E19: 1 | F19: 2 | G19: 0 | H19: 0 | I19: 1 | J19: 0 | K19: 0 | L19: 0 | M19: 15 | N19: 0 | O19: =SUM(C19:L19,N19) -> 5 | P19: =SUM(C19:N19) -> 20 | R19: 1600-1700 | S19: =SUM(C46:C49) -> 7 | T19: =SUM(D46:D49) -> 0 | U19: =SUM(E46:E49) -> 10 | V19: =SUM(F46:F49) -> 10 | W19: =SUM(G46:G49) -> 0 | X19: =SUM(H46:H49) -> 0 | Y19: =SUM(I46:I49) -> 13 | Z19: =SUM(J46:J49) -> 0 | ... AF19: =SUM(P46:P49) -> 130
B20: 09.30 - 09.45 | C20: 1 | D20: 0 | E20: 0 | F20: 3 | G20: 0 | H20: 0 | I20: 1 | J20: 0 | K20: 0 | L20: 0 | M20: 16 | N20: 0 | O20: =SUM(C20:L20,N20) -> 5 | P20: =SUM(C20:N20) -> 21 | R20: 1700-1800 | S20: =SUM(C50:C53) -> 22 | T20: =SUM(D50:D53) -> 0 | U20: =SUM(E50:E53) -> 19 | V20: =SUM(F50:F53) -> 14 | W20: =SUM(G50:G53) -> 3 | X20: =SUM(H50:H53) -> 0 | Y20: =SUM(I50:I53) -> 8 | Z20: =SUM(J50:J53) -> 0 | ... AF20: =SUM(P50:P53) -> 158
B21: 09.45 - 10.00 | C21: 0 | D21: 0 | E21: 1 | F21: 0 | G21: 0 | H21: 0 | I21: 3 | J21: 0 | K21: 0 | L21: 0 | M21: 23 | N21: 0 | O21: =SUM(C21:L21,N21) -> 4 | P21: =SUM(C21:N21) -> 27 | R21: 1800-1900 | S21: =SUM(C54:C57) -> 10 | T21: =SUM(D54:D57) -> 0 | U21: =SUM(E54:E57) -> 18 | V21: =SUM(F54:F57) -> 6 | W21: =SUM(G54:G57) -> 0 | X21: =SUM(H54:H57) -> 0 | Y21: =SUM(I54:I57) -> 8 | Z21: =SUM(J54:J57) -> 0 | ... AF21: =SUM(P54:P57) -> 137
B22: 10.00 - 10.15 | C22: 3 | D22: 0 | E22: 3 | F22: 1 | G22: 0 | H22: 0 | I22: 0 | J22: 0 | K22: 0 | L22: 0 | M22: 18 | N22: 0 | O22: =SUM(C22:L22,N22) -> 7 | P22: =SUM(C22:N22) -> 25 | R22: AM Peak Hr | S22: =MAX(S10:S12) -> 9 | T22: =MAX(T10:T12) -> 0 | U22: =MAX(U10:U12) -> 3 | V22: =MAX(V10:V12) -> 6 | W22: =MAX(W10:W12) -> 0 | X22: =MAX(X10:X12) -> 0 | Y22: =MAX(Y10:Y12) -> 8 | Z22: =MAX(Z10:Z12) -> 1 | ... AF22: =MAX(AF10:AF12) -> 82
B23: 10.15 - 10.30 | C23: 2 | D23: 0 | E23: 0 | F23: 1 | G23: 0 | H23: 0 | I23: 2 | J23: 0 | K23: 0 | L23: 0 | M23: 25 | N23: 0 | O23: =SUM(C23:L23,N23) -> 5 | P23: =SUM(C23:N23) -> 30 | R23: IP Peak Hr | S23: =MAX(S13:S18) -> 8 | T23: =MAX(T13:T18) -> 0 | U23: =MAX(U13:U18) -> 17 | V23: =MAX(V13:V18) -> 8 | W23: =MAX(W13:W18) -> 1 | X23: =MAX(X13:X18) -> 0 | Y23: =MAX(Y13:Y18) -> 12 | Z23: =MAX(Z13:Z18) -> 2 | ... AF23: =MAX(AF13:AF18) -> 126
B24: 10.30 - 10.45 | C24: 0 | D24: 0 | E24: 3 | F24: 0 | G24: 1 | H24: 0 | I24: 5 | J24: 0 | K24: 0 | L24: 0 | M24: 14 | N24: 0 | O24: =SUM(C24:L24,N24) -> 9 | P24: =SUM(C24:N24) -> 23 | R24: PM Peak Hr | S24: =MAX(S19:S21) -> 22 | T24: =MAX(T19:T21) -> 0 | U24: =MAX(U19:U21) -> 19 | V24: =MAX(V19:V21) -> 14 | W24: =MAX(W19:W21) -> 3 | X24: =MAX(X19:X21) -> 0 | Y24: =MAX(Y19:Y21) -> 13 | Z24: =MAX(Z19:Z21) -> 0 | ... AF24: =MAX(AF19:AF21) -> 158
B25: 10.45 - 11.00 | C25: 0 | D25: 0 | E25: 0 | F25: 1 | G25: 0 | H25: 0 | I25: 3 | J25: 0 | K25: 0 | L25: 0 | M25: 24 | N25: 0 | O25: =SUM(C25:L25,N25) -> 4 | P25: =SUM(C25:N25) -> 28 | R25: AM Period | S25: =SUM(S10:S12) -> 14 | T25: =SUM(T10:T12) -> 0 | U25: =SUM(U10:U12) -> 6 | V25: =SUM(V10:V12) -> 15 | W25: =SUM(W10:W12) -> 0 | X25: =SUM(X10:X12) -> 0 | Y25: =SUM(Y10:Y12) -> 14 | Z25: =SUM(Z10:Z12) -> 1 | ... AF25: =SUM(AF10:AF12) -> 223
B26: 11.00 - 11.15 | C26: 3 | D26: 0 | E26: 1 | F26: 1 | G26: 0 | H26: 0 | I26: 0 | J26: 0 | K26: 0 | L26: 0 | M26: 20 | N26: 0 | O26: =SUM(C26:L26,N26) -> 5 | P26: =SUM(C26:N26) -> 25 | R26: IP Period | S26: =SUM(S13:S18) -> 38 | T26: =SUM(T13:T18) -> 0 | U26: =SUM(U13:U18) -> 54 | V26: =SUM(V13:V18) -> 36 | W26: =SUM(W13:W18) -> 1 | X26: =SUM(X13:X18) -> 0 | Y26: =SUM(Y13:Y18) -> 43 | Z26: =SUM(Z13:Z18) -> 3 | ... AF26: =SUM(AF13:AF18) -> 677
B27: 11.15 - 11.30 | C27: 2 | D27: 0 | E27: 3 | F27: 1 | G27: 0 | H27: 0 | I27: 1 | J27: 2 | K27: 0 | L27: 0 | M27: 17 | N27: 0 | O27: =SUM(C27:L27,N27) -> 9 | P27: =SUM(C27:N27) -> 26 | R27: PM Period | S27: =SUM(S19:S21) -> 39 | T27: =SUM(T19:T21) -> 0 | U27: =SUM(U19:U21) -> 47 | V27: =SUM(V19:V21) -> 30 | W27: =SUM(W19:W21) -> 3 | X27: =SUM(X19:X21) -> 0 | Y27: =SUM(Y19:Y21) -> 29 | Z27: =SUM(Z19:Z21) -> 0 | ... AF27: =SUM(AF19:AF21) -> 425
B28: 11.30 - 11.45 | C28: 2 | D28: 0 | E28: 2 | F28: 2 | G28: 0 | H28: 0 | I28: 3 | J28: 0 | K28: 1 | L28: 0 | M28: 20 | N28: 0 | O28: =SUM(C28:L28,N28) -> 10 | P28: =SUM(C28:N28) -> 30 | R28: 12 Hours | S28: =SUM(S10:S21) -> 91 | T28: =SUM(T10:T21) -> 0 | U28: =SUM(U10:U21) -> 107 | V28: =SUM(V10:V21) -> 81 | W28: =SUM(W10:W21) -> 4 | X28: =SUM(X10:X21) -> 0 | Y28: =SUM(Y10:Y21) -> 86 | Z28: =SUM(Z10:Z21) -> 4 | ... AF28: =SUM(AF10:AF21) -> 1325
B29: 11.45 - 12.00 | C29: 0 | D29: 0 | E29: 0 | F29: 1 | G29: 0 | H29: 0 | I29: 1 | J29: 0 | K29: 0 | L29: 0 | M29: 18 | N29: 0 | O29: =SUM(C29:L29,N29) -> 2 | P29: =SUM(C29:N29) -> 20
B30: 12.00 - 12.15 | C30: 0 | D30: 0 | E30: 3 | F30: 3 | G30: 0 | H30: 0 | I30: 1 | J30: 0 | K30: 1 | L30: 0 | M30: 20 | N30: 0 | O30: =SUM(C30:L30,N30) -> 8 | P30: =SUM(C30:N30) -> 28
B31: 12.15 - 12.30 | C31: 0 | D31: 0 | E31: 1 | F31: 0 | G31: 0 | H31: 0 | I31: 3 | J31: 0 | K31: 0 | L31: 0 | M31: 31 | N31: 0 | O31: =SUM(C31:L31,N31) -> 4 | P31: =SUM(C31:N31) -> 35
B32: 12.30 - 12.45 | C32: 0 | D32: 0 | E32: 3 | F32: 1 | G32: 0 | H32: 0 | I32: 2 | J32: 0 | K32: 0 | L32: 0 | M32: 22 | N32: 0 | O32: =SUM(C32:L32,N32) -> 6 | P32: =SUM(C32:N32) -> 28
B33: 12.45 - 13.00 | C33: 4 | D33: 0 | E33: 0 | F33: 2 | G33: 0 | H33: 0 | I33: 2 | J33: 0 | K33: 0 | L33: 0 | M33: 21 | N33: 0 | O33: =SUM(C33:L33,N33) -> 8 | P33: =SUM(C33:N33) -> 29
B34: 13.00 - 13.15 | C34: 1 | D34: 0 | E34: 3 | F34: 2 | G34: 0 | H34: 0 | I34: 2 | J34: 0 | K34: 0 | L34: 0 | M34: 17 | N34: 0 | O34: =SUM(C34:L34,N34) -> 8 | P34: =SUM(C34:N34) -> 25
B35: 13.15 - 13.30 | C35: 2 | D35: 0 | E35: 2 | F35: 2 | G35: 0 | H35: 0 | I35: 2 | J35: 0 | K35: 0 | L35: 0 | M35: 14 | N35: 0 | O35: =SUM(C35:L35,N35) -> 8 | P35: =SUM(C35:N35) -> 22
B36: 13.30 - 13.45 | C36: 1 | D36: 0 | E36: 3 | F36: 0 | G36: 0 | H36: 0 | I36: 1 | J36: 0 | K36: 0 | L36: 0 | M36: 19 | N36: 0 | O36: =SUM(C36:L36,N36) -> 5 | P36: =SUM(C36:N36) -> 24
B37: 13.45 - 14.00 | C37: 2 | D37: 0 | E37: 4 | F37: 4 | G37: 0 | H37: 0 | I37: 0 | J37: 0 | K37: 0 | L37: 0 | M37: 17 | N37: 0 | O37: =SUM(C37:L37,N37) -> 10 | P37: =SUM(C37:N37) -> 27
B38: 14.00 - 14.15 | C38: 2 | D38: 0 | E38: 1 | F38: 0 | G38: 0 | H38: 0 | I38: 1 | J38: 0 | K38: 0 | L38: 0 | M38: 29 | N38: 0 | O38: =SUM(C38:L38,N38) -> 4 | P38: =SUM(C38:N38) -> 33
B39: 14.15 - 14.30 | C39: 1 | D39: 0 | E39: 3 | F39: 5 | G39: 0 | H39: 0 | I39: 0 | J39: 1 | K39: 0 | L39: 0 | M39: 22 | N39: 0 | O39: =SUM(C39:L39,N39) -> 10 | P39: =SUM(C39:N39) -> 32
B40: 14.30 - 14.45 | C40: 3 | D40: 0 | E40: 0 | F40: 2 | G40: 0 | H40: 0 | I40: 1 | J40: 0 | K40: 0 | L40: 0 | M40: 23 | N40: 0 | O40: =SUM(C40:L40,N40) -> 6 | P40: =SUM(C40:N40) -> 29
... B57: 18.45 - 19.00 | C57: 3 | D57: 0 | E57: 2 | F57: 0 | G57: 0 | H57: 0 | I57: 3 | J57: 0 | K57: 0 | L57: 0 | M57: 27 | N57: 0 | O57: =SUM(C57:L57,N57) -> 8 | P57: =SUM(C57:N57) -> 35
B58: Totals | C58: =SUM(C10:C57) -> 91 | D58: =SUM(D10:D57) -> 0 | E58: =SUM(E10:E57) -> 107 | F58: =SUM(F10:F57) -> 81 | G58: =SUM(G10:G57) -> 4 | H58: =SUM(H10:H57) -> 0 | I58: =SUM(I10:I57) -> 86 | J58: =SUM(J10:J57) -> 4 | ... P58: =SUM(P10:P57) -> 1325
...

Sheet 21.08 Kampala-Bukaya
B1: Consultancy services for Preparation of Expressway Development Master Plan (EDMP) for Uganda
B2: MANUAL CLASSIFIED COUNT (MCC)
B3: ROAD NAME: | C3: ='19.08 Kampala-Bukaya'!C3:G3 -> MCC - C3 - STN92 - NALUBAALE ROAD
C5: Date | D5: 21.08.19 | F5: Location | G5: ='19.08 Kampala-Bukaya'!G5:H5 -> Nyenga | J5: Surveyor | K5: ='19.08 Kampala-Bukaya'!K5:L5 -> xxx
C6: Dir. From | D6: ='19.08 Kampala-Bukaya'!D6:E6 -> Kampala | F6: Dir. To | G6: ='19.08 Kampala-Bukaya'!G6:H6 -> Bukaya | J6: Supervisor | K6: ='19.08 Kampala-Bukaya'!K6:L6 -> xxx
B8: Time / Veh Type | R8: SUMMARY TRAFFIC VOLUMES
C9: 1. Car | D9: 2. Station Wagon | E9: 3. Pickups | F9: 4. Minibus, matatu | G9: 5. Medium bus | H9: 6. Large Bus | I9: 7. Light Truck | J9: 8. Medium Truck | K9: 9. Heavy truck | L9: 10. Truck Trailer | M9: 11. Motor cycles | N9: 12. Tractors | O9: Total Excl M/Cycles | P9: Total All | R9: Time | S9: 1. Car | T9: 2. Station Wagon | U9: 3. Pickups | V9: 4. Minibus, matatu | W9: 5. Medium bus | X9: 6. Large Bus | Y9: 7. Light Truck | Z9: 8. Medium Truck | AA9: 9. Heavy truck | AB9: 10. Truck Trailer | AC9: 11. Motorcycles | AD9: 12. Tractors, Graders | AE9: Total Excl M/ Cycles | AF9: Total All
B10: 07.00 - 07.15 | C10: 2 | D10: 0 | E10: 2 | F10: 0 | G10: 0 | H10: 0 | I10: 0 | J10: 0 | K10: 0 | L10: 0 | M10: 8 | N10: 0 | O10: =SUM(C10:L10,N10) -> 4 | P10: =SUM(C10:N10) -> 12 | R10: 0700-0800 | S10: =SUM(C10:C13) -> 8 | T10: =SUM(D10:D13) -> 0 | U10: =SUM(E10:E13) -> 7 | V10: =SUM(F10:F13) -> 1 | W10: =SUM(G10:G13) -> 0 | X10: =SUM(H10:H13) -> 0 | Y10: =SUM(I10:I13) -> 4 | Z10: =SUM(J10:J13) -> 0 | ... AF10: =SUM(P10:P13) -> 64
B11: 07.15 - 07.30 | C11: 3 | D11: 0 | E11: 2 | F11: 0 | G11: 0 | H11: 0 | I11: 1 | J11: 0 | K11: 0 | L11: 0 | M11: 6 | N11: 0 | O11: =SUM(C11:L11,N11) -> 6 | P11: =SUM(C11:N11) -> 12 | R11: 0800-0900 | S11: =SUM(C14:C17) -> 10 | T11: =SUM(D14:D17) -> 0 | U11: =SUM(E14:E17) -> 5 | V11: =SUM(F14:F17) -> 3 | W11: =SUM(G14:G17) -> 2 | X11: =SUM(H14:H17) -> 0 | Y11: =SUM(I14:I17) -> 5 | Z11: =SUM(J14:J17) -> 0 | ... AF11: =SUM(P14:P17) -> 92
B12: 07.30 - 07.45 | C12: 2 | D12: 0 | E12: 3 | F12: 0 | G12: 0 | H12: 0 | I12: 1 | J12: 0 | K12: 0 | L12: 0 | M12: 14 | N12: 0 | O12: =SUM(C12:L12,N12) -> 6 | P12: =SUM(C12:N12) -> 20 | R12: 0900-1000 | S12: =SUM(C18:C21) -> 14 | T12: =SUM(D18:D21) -> 0 | U12: =SUM(E18:E21) -> 14 | V12: =SUM(F18:F21) -> 6 | W12: =SUM(G18:G21) -> 2 | X12: =SUM(H18:H21) -> 0 | Y12: =SUM(I18:I21) -> 7 | Z12: =SUM(J18:J21) -> 0 | ... AF12: =SUM(P18:P21) -> 94
B13: 07.45 - 08.00 | C13: 1 | D13: 0 | E13: 0 | F13: 1 | G13: 0 | H13: 0 | I13: 2 | J13: 0 | K13: 0 | L13: 0 | M13: 16 | N13: 0 | O13: =SUM(C13:L13,N13) -> 4 | P13: =SUM(C13:N13) -> 20 | R13: 1000-1100 | S13: =SUM(C22:C25) -> 7 | T13: =SUM(D22:D25) -> 0 | U13: =SUM(E22:E25) -> 7 | V13: =SUM(F22:F25) -> 7 | W13: =SUM(G22:G25) -> 0 | X13: =SUM(H22:H25) -> 0 | Y13: =SUM(I22:I25) -> 6 | Z13: =SUM(J22:J25) -> 1 | ... AF13: =SUM(P22:P25) -> 100
B14: 08.00 - 08.15 | C14: 2 | D14: 0 | E14: 0 | F14: 2 | G14: 0 | H14: 0 | I14: 3 | J14: 0 | K14: 0 | L14: 0 | M14: 11 | N14: 0 | O14: =SUM(C14:L14,N14) -> 7 | P14: =SUM(C14:N14) -> 18 | R14: 1100-1200 | S14: =SUM(C26:C29) -> 7 | T14: =SUM(D26:D29) -> 0 | U14: =SUM(E26:E29) -> 8 | V14: =SUM(F26:F29) -> 2 | W14: =SUM(G26:G29) -> 1 | X14: =SUM(H26:H29) -> 0 | Y14: =SUM(I26:I29) -> 6 | Z14: =SUM(J26:J29) -> 0 | ... AF14: =SUM(P26:P29) -> 95
B15: 08.15 - 08.30 | C15: 3 | D15: 0 | E15: 2 | F15: 0 | G15: 0 | H15: 0 | I15: 0 | J15: 0 | K15: 0 | L15: 0 | M15: 12 | N15: 0 | O15: =SUM(C15:L15,N15) -> 5 | P15: =SUM(C15:N15) -> 17 | R15: 1200-1300 | S15: =SUM(C30:C33) -> 9 | T15: =SUM(D30:D33) -> 0 | U15: =SUM(E30:E33) -> 7 | V15: =SUM(F30:F33) -> 13 | W15: =SUM(G30:G33) -> 2 | X15: =SUM(H30:H33) -> 0 | Y15: =SUM(I30:I33) -> 7 | Z15: =SUM(J30:J33) -> 0 | ... AF15: =SUM(P30:P33) -> 117
B16: 08.30 - 08.45 | C16: 0 | D16: 0 | E16: 2 | F16: 1 | G16: 2 | H16: 0 | I16: 1 | J16: 0 | K16: 0 | L16: 0 | M16: 18 | N16: 0 | O16: =SUM(C16:L16,N16) -> 6 | P16: =SUM(C16:N16) -> 24 | R16: 1300-1400 | S16: =SUM(C34:C37) -> 15 | T16: =SUM(D34:D37) -> 0 | U16: =SUM(E34:E37) -> 14 | V16: =SUM(F34:F37) -> 8 | W16: =SUM(G34:G37) -> 1 | X16: =SUM(H34:H37) -> 0 | Y16: =SUM(I34:I37) -> 10 | Z16: =SUM(J34:J37) -> 0 | ... AF16: =SUM(P34:P37) -> 133
B17: 08.45 - 9.00 | C17: 5 | D17: 0 | E17: 1 | F17: 0 | G17: 0 | H17: 0 | I17: 1 | J17: 0 | K17: 0 | L17: 0 | M17: 26 | N17: 0 | O17: =SUM(C17:L17,N17) -> 7 | P17: =SUM(C17:N17) -> 33 | R17: 1400-1500 | S17: =SUM(C38:C41) -> 11 | T17: =SUM(D38:D41) -> 0 | U17: =SUM(E38:E41) -> 9 | V17: =SUM(F38:F41) -> 7 | W17: =SUM(G38:G41) -> 0 | X17: =SUM(H38:H41) -> 0 | Y17: =SUM(I38:I41) -> 9 | Z17: =SUM(J38:J41) -> 0 | ... AF17: =SUM(P38:P41) -> 108
B18: 09.00 - 09.15 | C18: 3 | D18: 0 | E18: 2 | F18: 1 | G18: 0 | H18: 0 | I18: 1 | J18: 0 | K18: 0 | L18: 0 | M18: 13 | N18: 0 | O18: =SUM(C18:L18,N18) -> 7 | P18: =SUM(C18:N18) -> 20 | R18: 1500-1600 | S18: =SUM(C42:C45) -> 10 | T18: =SUM(D42:D45) -> 0 | U18: =SUM(E42:E45) -> 7 | V18: =SUM(F42:F45) -> 10 | W18: =SUM(G42:G45) -> 0 | X18: =SUM(H42:H45) -> 0 | Y18: =SUM(I42:I45) -> 9 | Z18: =SUM(J42:J45) -> 1 | ... AF18: =SUM(P42:P45) -> 92
B19: 09.15 - 09.30 | C19: 4 | D19: 0 | E19: 4 | F19: 3 | G19: 1 | H19: 0 | I19: 2 | J19: 0 | K19: 0 | L19: 0 | M19: 14 | N19: 0 | O19: =SUM(C19:L19,N19) -> 14 | P19: =SUM(C19:N19) -> 28 | R19: 1600-1700 | S19: =SUM(C46:C49) -> 11 | T19: =SUM(D46:D49) -> 0 | U19: =SUM(E46:E49) -> 7 | V19: =SUM(F46:F49) -> 7 | W19: =SUM(G46:G49) -> 0 | X19: =SUM(H46:H49) -> 0 | Y19: =SUM(I46:I49) -> 13 | Z19: =SUM(J46:J49) -> 1 | ... AF19: =SUM(P46:P49) -> 138
B20: 09.30 - 09.45 | C20: 2 | D20: 0 | E20: 4 | F20: 0 | G20: 1 | H20: 0 | I20: 4 | J20: 0 | K20: 0 | L20: 0 | M20: 8 | N20: 0 | O20: =SUM(C20:L20,N20) -> 11 | P20: =SUM(C20:N20) -> 19 | R20: 1700-1800 | S20: =SUM(C50:C53) -> 8 | T20: =SUM(D50:D53) -> 0 | U20: =SUM(E50:E53) -> 4 | V20: =SUM(F50:F53) -> 10 | W20: =SUM(G50:G53) -> 0 | X20: =SUM(H50:H53) -> 0 | Y20: =SUM(I50:I53) -> 1 | Z20: =SUM(J50:J53) -> 0 | ... AF20: =SUM(P50:P53) -> 86
B21: 09.45 - 10.00 | C21: 5 | D21: 0 | E21: 4 | F21: 2 | G21: 0 | H21: 0 | I21: 0 | J21: 0 | K21: 0 | L21: 0 | M21: 16 | N21: 0 | O21: =SUM(C21:L21,N21) -> 11 | P21: =SUM(C21:N21) -> 27 | R21: 1800-1900 | S21: =SUM(C54:C57) -> 6 | T21: =SUM(D54:D57) -> 0 | U21: =SUM(E54:E57) -> 2 | V21: =SUM(F54:F57) -> 9 | W21: =SUM(G54:G57) -> 0 | X21: =SUM(H54:H57) -> 1 | Y21: =SUM(I54:I57) -> 7 | Z21: =SUM(J54:J57) -> 0 | ... AF21: =SUM(P54:P57) -> 98
B22: 10.00 - 10.15 | C22: 4 | D22: 0 | E22: 1 | F22: 2 | G22: 0 | H22: 0 | I22: 0 | J22: 0 | K22: 0 | L22: 0 | M22: 16 | N22: 0 | O22: =SUM(C22:L22,N22) -> 7 | P22: =SUM(C22:N22) -> 23 | R22: AM Peak Hr | S22: =MAX(S10:S12) -> 14 | T22: =MAX(T10:T12) -> 0 | U22: =MAX(U10:U12) -> 14 | V22: =MAX(V10:V12) -> 6 | W22: =MAX(W10:W12) -> 2 | X22: =MAX(X10:X12) -> 0 | Y22: =MAX(Y10:Y12) -> 7 | Z22: =MAX(Z10:Z12) -> 0 | ... AF22: =MAX(AF10:AF12) -> 94
B23: 10.15 - 10.30 | C23: 1 | D23: 0 | E23: 0 | F23: 1 | G23: 0 | H23: 0 | I23: 2 | J23: 0 | K23: 0 | L23: 0 | M23: 17 | N23: 0 | O23: =SUM(C23:L23,N23) -> 4 | P23: =SUM(C23:N23) -> 21 | R23: IP Peak Hr | S23: =MAX(S13:S18) -> 15 | T23: =MAX(T13:T18) -> 0 | U23: =MAX(U13:U18) -> 14 | V23: =MAX(V13:V18) -> 13 | W23: =MAX(W13:W18) -> 2 | X23: =MAX(X13:X18) -> 0 | Y23: =MAX(Y13:Y18) -> 10 | Z23: =MAX(Z13:Z18) -> 1 | ... AF23: =MAX(AF13:AF18) -> 133
B24: 10.30 - 10.45 | C24: 2 | D24: 0 | E24: 3 | F24: 1 | G24: 0 | H24: 0 | I24: 2 | J24: 1 | K24: 1 | L24: 0 | M24: 18 | N24: 0 | O24: =SUM(C24:L24,N24) -> 10 | P24: =SUM(C24:N24) -> 28 | R24: PM Peak Hr | S24: =MAX(S19:S21) -> 11 | T24: =MAX(T19:T21) -> 0 | U24: =MAX(U19:U21) -> 7 | V24: =MAX(V19:V21) -> 10 | W24: =MAX(W19:W21) -> 0 | X24: =MAX(X19:X21) -> 1 | Y24: =MAX(Y19:Y21) -> 13 | Z24: =MAX(Z19:Z21) -> 1 | ... AF24: =MAX(AF19:AF21) -> 138
B25: 10.45 - 11.00 | C25: 0 | D25: 0 | E25: 3 | F25: 3 | G25: 0 | H25: 0 | I25: 2 | J25: 0 | K25: 1 | L25: 0 | M25: 19 | N25: 0 | O25: =SUM(C25:L25,N25) -> 9 | P25: =SUM(C25:N25) -> 28 | R25: AM Period | S25: =SUM(S10:S12) -> 32 | T25: =SUM(T10:T12) -> 0 | U25: =SUM(U10:U12) -> 26 | V25: =SUM(V10:V12) -> 10 | W25: =SUM(W10:W12) -> 4 | X25: =SUM(X10:X12) -> 0 | Y25: =SUM(Y10:Y12) -> 16 | Z25: =SUM(Z10:Z12) -> 0 | ... AF25: =SUM(AF10:AF12) -> 250
B26: 11.00 - 11.15 | C26: 3 | D26: 0 | E26: 2 | F26: 1 | G26: 0 | H26: 0 | I26: 0 | J26: 0 | K26: 0 | L26: 0 | M26: 15 | N26: 0 | O26: =SUM(C26:L26,N26) -> 6 | P26: =SUM(C26:N26) -> 21 | R26: IP Period | S26: =SUM(S13:S18) -> 59 | T26: =SUM(T13:T18) -> 0 | U26: =SUM(U13:U18) -> 52 | V26: =SUM(V13:V18) -> 47 | W26: =SUM(W13:W18) -> 4 | X26: =SUM(X13:X18) -> 0 | Y26: =SUM(Y13:Y18) -> 47 | Z26: =SUM(Z13:Z18) -> 2 | ... AF26: =SUM(AF13:AF18) -> 645
B27: 11.15 - 11.30 | C27: 1 | D27: 0 | E27: 3 | F27: 1 | G27: 1 | H27: 0 | I27: 2 | J27: 0 | K27: 0 | L27: 0 | M27: 18 | N27: 0 | O27: =SUM(C27:L27,N27) -> 8 | P27: =SUM(C27:N27) -> 26 | R27: PM Period | S27: =SUM(S19:S21) -> 25 | T27: =SUM(T19:T21) -> 0 | U27: =SUM(U19:U21) -> 13 | V27: =SUM(V19:V21) -> 26 | W27: =SUM(W19:W21) -> 0 | X27: =SUM(X19:X21) -> 1 | Y27: =SUM(Y19:Y21) -> 21 | Z27: =SUM(Z19:Z21) -> 1 | ... AF27: =SUM(AF19:AF21) -> 322
B28: 11.30 - 11.45 | C28: 1 | D28: 0 | E28: 2 | F28: 0 | G28: 0 | H28: 0 | I28: 3 | J28: 0 | K28: 0 | L28: 0 | M28: 15 | N28: 0 | O28: =SUM(C28:L28,N28) -> 6 | P28: =SUM(C28:N28) -> 21 | R28: 12 Hours | S28: =SUM(S10:S21) -> 116 | T28: =SUM(T10:T21) -> 0 | U28: =SUM(U10:U21) -> 91 | V28: =SUM(V10:V21) -> 83 | W28: =SUM(W10:W21) -> 8 | X28: =SUM(X10:X21) -> 1 | Y28: =SUM(Y10:Y21) -> 84 | Z28: =SUM(Z10:Z21) -> 3 | ... AF28: =SUM(AF10:AF21) -> 1217
B29: 11.45 - 12.00 | C29: 2 | D29: 0 | E29: 1 | F29: 0 | G29: 0 | H29: 0 | I29: 1 | J29: 0 | K29: 0 | L29: 0 | M29: 23 | N29: 0 | O29: =SUM(C29:L29,N29) -> 4 | P29: =SUM(C29:N29) -> 27
B30: 12.00 - 12.15 | C30: 2 | D30: 0 | E30: 0 | F30: 5 | G30: 2 | H30: 0 | I30: 2 | J30: 0 | K30: 0 | L30: 0 | M30: 17 | N30: 0 | O30: =SUM(C30:L30,N30) -> 11 | P30: =SUM(C30:N30) -> 28
B31: 12.15 - 12.30 | C31: 2 | D31: 0 | E31: 5 | F31: 2 | G31: 0 | H31: 0 | I31: 4 | J31: 0 | K31: 0 | L31: 0 | M31: 23 | N31: 0 | O31: =SUM(C31:L31,N31) -> 13 | P31: =SUM(C31:N31) -> 36
B32: 12.30 - 12.45 | C32: 3 | D32: 0 | E32: 0 | F32: 4 | G32: 0 | H32: 0 | I32: 1 | J32: 0 | K32: 0 | L32: 0 | M32: 19 | N32: 0 | O32: =SUM(C32:L32,N32) -> 8 | P32: =SUM(C32:N32) -> 27
B33: 12.45 - 13.00 | C33: 2 | D33: 0 | E33: 2 | F33: 2 | G33: 0 | H33: 0 | I33: 0 | J33: 0 | K33: 0 | L33: 0 | M33: 20 | N33: 0 | O33: =SUM(C33:L33,N33) -> 6 | P33: =SUM(C33:N33) -> 26
