Workbook

Sheet 26.10 KASESE-PONDWE
B1: Consultancy services for Preparation of Expressway Development Master Plan (EDMP) for Uganda
B2: MANUAL CLASSIFIED COUNT (MCC)
B3: ROAD NAME: | C3: MCC - C4 - STN137 - KASESE ROAD
C5: Date | D5: 26.10.19 | F5: Location | G5: KABUYIRI | J5: Surveyor | K5: NGURU WILLY
C6: Dir. From | D6: KASESE | F6: Dir. To | G6: PONDWE | J6: Supervisor | K6: GODFREY
B8: Time / Veh Type | R8: SUMMARY TRAFFIC VOLUMES
C9: 1. Car | D9: 2. Station Wagon | E9: 3. Pickups | F9: 4. Minibus, matatu | G9: 5. Medium bus | H9: 6. Large Bus | I9: 7. Light Truck | J9: 8. Medium Truck | K9: 9. Heavy truck | L9: 10. Truck Trailer | M9: 11. Motor cycles | N9: 12. Tractors | O9: Total Excl M/Cycles | P9: Total All | R9: Time | S9: 1. Car | T9: 2. Station Wagon | U9: 3. Pickups | V9: 4. Minibus, matatu | W9: 5. Medium bus | X9: 6. Large Bus | Y9: 7. Light Truck | Z9: 8. Medium Truck | AA9: 9. Heavy truck | AB9: 10. Truck Trailer | AC9: 11. Motorcycles | AD9: 12. Tractors, Graders | AE9: Total Excl M/ Cycles | AF9: Total All
B10: 07.00 - 07.15 | C10: 0 | D10: 0 | E10: 0 | F10: 0 | G10: 0 | H10: 0 | I10: 1 | J10: 0 | K10: 0 | L10: 0 | M10: 2 | N10: 0 | O10: =SUM(C10:L10,N10) -> 1 | P10: =SUM(C10:N10) -> 3 | R10: 0700-0800 | S10: =SUM(C10:C13) -> 1 | T10: =SUM(D10:D13) -> 0 | U10: =SUM(E10:E13) -> 0 | V10: =SUM(F10:F13) -> 1 | W10: =SUM(G10:G13) -> 0 | X10: =SUM(H10:H13) -> 0 | Y10: =SUM(I10:I13) -> 1 | Z10: =SUM(J10:J13) -> 1 | ... AF10: =SUM(P10:P13) -> 16
B11: 07.15 - 07.30 | C11: 1 | D11: 0 | E11: 0 | F11: 1 | G11: 0 | H11: 0 | I11: 0 | J11: 1 | K11: 0 | L11: 0 | M11: 0 | N11: 0 | O11: =SUM(C11:L11,N11) -> 3 | P11: =SUM(C11:N11) -> 3 | R11: 0800-0900 | S11: =SUM(C14:C17) -> 12 | T11: =SUM(D14:D17) -> 2 | U11: =SUM(E14:E17) -> 1 | V11: =SUM(F14:F17) -> 1 | W11: =SUM(G14:G17) -> 0 | X11: =SUM(H14:H17) -> 3 | Y11: =SUM(I14:I17) -> 3 | Z11: =SUM(J14:J17) -> 3 | ... AF11: =SUM(P14:P17) -> 141
B12: 07.30 - 07.45 | C12: 0 | D12: 0 | E12: 0 | F12: 0 | G12: 0 | H12: 0 | I12: 0 | J12: 0 | K12: 0 | L12: 1 | M12: 4 | N12: 0 | O12: =SUM(C12:L12,N12) -> 1 | P12: =SUM(C12:N12) -> 5 | R12: 0900-1000 | S12: =SUM(C18:C21) -> 9 | T12: =SUM(D18:D21) -> 2 | U12: =SUM(E18:E21) -> 1 | V12: =SUM(F18:F21) -> 0 | W12: =SUM(G18:G21) -> 0 | X12: =SUM(H18:H21) -> 0 | Y12: =SUM(I18:I21) -> 1 | Z12: =SUM(J18:J21) -> 4 | ... AF12: =SUM(P18:P21) -> 39
B13: 07.45 - 08.00 | C13: 0 | D13: 0 | E13: 0 | F13: 0 | G13: 0 | H13: 0 | I13: 0 | J13: 0 | K13: 0 | L13: 0 | M13: 5 | N13: 0 | O13: =SUM(C13:L13,N13) -> 0 | P13: =SUM(C13:N13) -> 5 | R13: 1000-1100 | S13: =SUM(C22:C25) -> 11 | T13: =SUM(D22:D25) -> 2 | U13: =SUM(E22:E25) -> 0 | V13: =SUM(F22:F25) -> 1 | W13: =SUM(G22:G25) -> 0 | X13: =SUM(H22:H25) -> 1 | Y13: =SUM(I22:I25) -> 1 | Z13: =SUM(J22:J25) -> 3 | ... AF13: =SUM(P22:P25) -> 66
B14: 08.00 - 08.15 | C14: 0 | D14: 0 | E14: 1 | F14: 1 | G14: 0 | H14: 2 | I14: 3 | J14: 1 | K14: 1 | L14: 0 | M14: 18 | N14: 0 | O14: =SUM(C14:L14,N14) -> 9 | P14: =SUM(C14:N14) -> 27 | R14: 1100-1200 | S14: =SUM(C26:C29) -> 25 | T14: =SUM(D26:D29) -> 0 | U14: =SUM(E26:E29) -> 0 | V14: =SUM(F26:F29) -> 3 | W14: =SUM(G26:G29) -> 0 | X14: =SUM(H26:H29) -> 2 | Y14: =SUM(I26:I29) -> 0 | Z14: =SUM(J26:J29) -> 0 | ... AF14: =SUM(P26:P29) -> 200
B15: 08.15 - 08.30 | C15: 5 | D15: 1 | E15: 0 | F15: 0 | G15: 0 | H15: 0 | I15: 0 | J15: 1 | K15: 0 | L15: 0 | M15: 47 | N15: 0 | O15: =SUM(C15:L15,N15) -> 7 | P15: =SUM(C15:N15) -> 54 | R15: 1200-1300 | S15: =SUM(C30:C33) -> 20 | T15: =SUM(D30:D33) -> 1 | U15: =SUM(E30:E33) -> 1 | V15: =SUM(F30:F33) -> 5 | W15: =SUM(G30:G33) -> 0 | X15: =SUM(H30:H33) -> 2 | Y15: =SUM(I30:I33) -> 0 | Z15: =SUM(J30:J33) -> 2 | ... AF15: =SUM(P30:P33) -> 231
B16: 08.30 - 08.45 | C16: 5 | D16: 1 | E16: 0 | F16: 0 | G16: 0 | H16: 1 | I16: 0 | J16: 0 | K16: 0 | L16: 0 | M16: 35 | N16: 0 | O16: =SUM(C16:L16,N16) -> 7 | P16: =SUM(C16:N16) -> 42 | R16: 1300-1400 | S16: =SUM(C34:C37) -> 13 | T16: =SUM(D34:D37) -> 3 | U16: =SUM(E34:E37) -> 3 | V16: =SUM(F34:F37) -> 5 | W16: =SUM(G34:G37) -> 0 | X16: =SUM(H34:H37) -> 1 | Y16: =SUM(I34:I37) -> 1 | Z16: =SUM(J34:J37) -> 1 | ... AF16: =SUM(P34:P37) -> 191
B17: 08.45 - 9.00 | C17: 2 | D17: 0 | E17: 0 | F17: 0 | G17: 0 | H17: 0 | I17: 0 | J17: 1 | K17: 0 | L17: 2 | M17: 13 | N17: 0 | O17: =SUM(C17:L17,N17) -> 5 | P17: =SUM(C17:N17) -> 18 | R17: 1400-1500 | S17: =SUM(C38:C41) -> 7 | T17: =SUM(D38:D41) -> 0 | U17: =SUM(E38:E41) -> 0 | V17: =SUM(F38:F41) -> 7 | W17: =SUM(G38:G41) -> 0 | X17: =SUM(H38:H41) -> 0 | Y17: =SUM(I38:I41) -> 0 | Z17: =SUM(J38:J41) -> 2 | ... AF17: =SUM(P38:P41) -> 131
B18: 09.00 - 09.15 | C18: 3 | D18: 0 | E18: 0 | F18: 0 | G18: 0 | H18: 0 | I18: 1 | J18: 1 | K18: 0 | L18: 0 | M18: 18 | N18: 0 | O18: =SUM(C18:L18,N18) -> 5 | P18: =SUM(C18:N18) -> 23 | R18: 1500-1600 | S18: =SUM(C42:C45) -> 11 | T18: =SUM(D42:D45) -> 1 | U18: =SUM(E42:E45) -> 1 | V18: =SUM(F42:F45) -> 4 | W18: =SUM(G42:G45) -> 0 | X18: =SUM(H42:H45) -> 1 | Y18: =SUM(I42:I45) -> 1 | Z18: =SUM(J42:J45) -> 3 | ... AF18: =SUM(P42:P45) -> 181
B19: 09.15 - 09.30 | C19: 5 | D19: 0 | E19: 0 | F19: 0 | G19: 0 | H19: 0 | I19: 0 | J19: 2 | K19: 0 | L19: 0 | M19: 1 | N19: 0 | O19: =SUM(C19:L19,N19) -> 7 | P19: =SUM(C19:N19) -> 8 | R19: 1600-1700 | S19: =SUM(C46:C49) -> 15 | T19: =SUM(D46:D49) -> 1 | U19: =SUM(E46:E49) -> 1 | V19: =SUM(F46:F49) -> 8 | W19: =SUM(G46:G49) -> 0 | X19: =SUM(H46:H49) -> 1 | Y19: =SUM(I46:I49) -> 0 | Z19: =SUM(J46:J49) -> 1 | ... AF19: =SUM(P46:P49) -> 299
B20: 09.30 - 09.45 | C20: 0 | D20: 2 | E20: 0 | F20: 0 | G20: 0 | H20: 0 | I20: 0 | J20: 0 | K20: 0 | L20: 0 | M20: 2 | N20: 0 | O20: =SUM(C20:L20,N20) -> 2 | P20: =SUM(C20:N20) -> 4 | R20: 1700-1800 | S20: =SUM(C50:C53) -> 14 | T20: =SUM(D50:D53) -> 2 | U20: =SUM(E50:E53) -> 1 | V20: =SUM(F50:F53) -> 5 | W20: =SUM(G50:G53) -> 0 | X20: =SUM(H50:H53) -> 1 | Y20: =SUM(I50:I53) -> 2 | Z20: =SUM(J50:J53) -> 0 | ... AF20: =SUM(P50:P53) -> 191
B21: 09.45 - 10.00 | C21: 1 | D21: 0 | E21: 1 | F21: 0 | G21: 0 | H21: 0 | I21: 0 | J21: 1 | K21: 0 | L21: 0 | M21: 1 | N21: 0 | O21: =SUM(C21:L21,N21) -> 3 | P21: =SUM(C21:N21) -> 4 | R21: 1800-1900 | S21: =SUM(C54:C57) -> 11 | T21: =SUM(D54:D57) -> 3 | U21: =SUM(E54:E57) -> 0 | V21: =SUM(F54:F57) -> 2 | W21: =SUM(G54:G57) -> 0 | X21: =SUM(H54:H57) -> 1 | Y21: =SUM(I54:I57) -> 2 | Z21: =SUM(J54:J57) -> 0 | ... AF21: =SUM(P54:P57) -> 300
B22: 10.00 - 10.15 | C22: 3 | D22: 1 | E22: 0 | F22: 0 | G22: 0 | H22: 1 | I22: 0 | J22: 1 | K22: 0 | L22: 0 | M22: 3 | N22: 0 | O22: =SUM(C22:L22,N22) -> 6 | P22: =SUM(C22:N22) -> 9 | R22: AM Peak Hr | S22: =MAX(S10:S12) -> 12 | T22: =MAX(T10:T12) -> 2 | U22: =MAX(U10:U12) -> 1 | V22: =MAX(V10:V12) -> 1 | W22: =MAX(W10:W12) -> 0 | X22: =MAX(X10:X12) -> 3 | Y22: =MAX(Y10:Y12) -> 3 | Z22: =MAX(Z10:Z12) -> 4 | ... AF22: =MAX(AF10:AF12) -> 141
B23: 10.15 - 10.30 | C23: 1 | D23: 0 | E23: 0 | F23: 1 | G23: 0 | H23: 0 | I23: 1 | J23: 0 | K23: 0 | L23: 0 | M23: 10 | N23: 0 | O23: =SUM(C23:L23,N23) -> 3 | P23: =SUM(C23:N23) -> 13 | R23: IP Peak Hr | S23: =MAX(S13:S18) -> 25 | T23: =MAX(T13:T18) -> 3 | U23: =MAX(U13:U18) -> 3 | V23: =MAX(V13:V18) -> 7 | W23: =MAX(W13:W18) -> 0 | X23: =MAX(X13:X18) -> 2 | Y23: =MAX(Y13:Y18) -> 1 | Z23: =MAX(Z13:Z18) -> 3 | ... AF23: =MAX(AF13:AF18) -> 231
B24: 10.30 - 10.45 | C24: 4 | D24: 1 | E24: 0 | F24: 0 | G24: 0 | H24: 0 | I24: 0 | J24: 0 | K24: 0 | L24: 0 | M24: 20 | N24: 0 | O24: =SUM(C24:L24,N24) -> 5 | P24: =SUM(C24:N24) -> 25 | R24: PM Peak Hr | S24: =MAX(S19:S21) -> 15 | T24: =MAX(T19:T21) -> 3 | U24: =MAX(U19:U21) -> 1 | V24: =MAX(V19:V21) -> 8 | W24: =MAX(W19:W21) -> 0 | X24: =MAX(X19:X21) -> 1 | Y24: =MAX(Y19:Y21) -> 2 | Z24: =MAX(Z19:Z21) -> 1 | ... AF24: =MAX(AF19:AF21) -> 300
B25: 10.45 - 11.00 | C25: 3 | D25: 0 | E25: 0 | F25: 0 | G25: 0 | H25: 0 | I25: 0 | J25: 2 | K25: 0 | L25: 1 | M25: 13 | N25: 0 | O25: =SUM(C25:L25,N25) -> 6 | P25: =SUM(C25:N25) -> 19 | R25: AM Period | S25: =SUM(S10:S12) -> 22 | T25: =SUM(T10:T12) -> 4 | U25: =SUM(U10:U12) -> 2 | V25: =SUM(V10:V12) -> 2 | W25: =SUM(W10:W12) -> 0 | X25: =SUM(X10:X12) -> 3 | Y25: =SUM(Y10:Y12) -> 5 | Z25: =SUM(Z10:Z12) -> 8 | ... AF25: =SUM(AF10:AF12) -> 196
B26: 11.00 - 11.15 | C26: 2 | D26: 0 | E26: 0 | F26: 0 | G26: 0 | H26: 0 | I26: 0 | J26: 0 | K26: 0 | L26: 0 | M26: 25 | N26: 0 | O26: =SUM(C26:L26,N26) -> 2 | P26: =SUM(C26:N26) -> 27 | R26: IP Period | S26: =SUM(S13:S18) -> 87 | T26: =SUM(T13:T18) -> 7 | U26: =SUM(U13:U18) -> 5 | V26: =SUM(V13:V18) -> 25 | W26: =SUM(W13:W18) -> 0 | X26: =SUM(X13:X18) -> 7 | Y26: =SUM(Y13:Y18) -> 3 | Z26: =SUM(Z13:Z18) -> 11 | ... AF26: =SUM(AF13:AF18) -> 1000
B27: 11.15 - 11.30 | C27: 10 | D27: 0 | E27: 0 | F27: 1 | G27: 0 | H27: 0 | I27: 0 | J27: 0 | K27: 0 | L27: 0 | M27: 53 | N27: 0 | O27: =SUM(C27:L27,N27) -> 11 | P27: =SUM(C27:N27) -> 64 | R27: PM Period | S27: =SUM(S19:S21) -> 40 | T27: =SUM(T19:T21) -> 6 | U27: =SUM(U19:U21) -> 2 | V27: =SUM(V19:V21) -> 15 | W27: =SUM(W19:W21) -> 0 | X27: =SUM(X19:X21) -> 3 | Y27: =SUM(Y19:Y21) -> 4 | Z27: =SUM(Z19:Z21) -> 1 | ... AF27: =SUM(AF19:AF21) -> 790
B28: 11.30 - 11.45 | C28: 4 | D28: 0 | E28: 0 | F28: 0 | G28: 0 | H28: 2 | I28: 0 | J28: 0 | K28: 0 | L28: 1 | M28: 41 | N28: 0 | O28: =SUM(C28:L28,N28) -> 7 | P28: =SUM(C28:N28) -> 48 | R28: 12 Hours | S28: =SUM(S10:S21) -> 149 | T28: =SUM(T10:T21) -> 17 | U28: =SUM(U10:U21) -> 9 | V28: =SUM(V10:V21) -> 42 | W28: =SUM(W10:W21) -> 0 | X28: =SUM(X10:X21) -> 13 | Y28: =SUM(Y10:Y21) -> 12 | Z28: =SUM(Z10:Z21) -> 20 | ... AF28: =SUM(AF10:AF21) -> 1986
B29: 11.45 - 12.00 | C29: 9 | D29: 0 | E29: 0 | F29: 2 | G29: 0 | H29: 0 | I29: 0 | J29: 0 | K29: 0 | L29: 1 | M29: 49 | N29: 0 | O29: =SUM(C29:L29,N29) -> 12 | P29: =SUM(C29:N29) -> 61
B30: 12.00 - 12.15 | C30: 5 | D30: 0 | E30: 1 | F30: 0 | G30: 0 | H30: 0 | I30: 0 | J30: 0 | K30: 0 | L30: 0 | M30: 64 | N30: 0 | O30: =SUM(C30:L30,N30) -> 6 | P30: =SUM(C30:N30) -> 70
B31: 12.15 - 12.30 | C31: 5 | D31: 0 | E31: 0 | F31: 1 | G31: 0 | H31: 1 | I31: 0 | J31: 2 | K31: 0 | L31: 0 | M31: 48 | N31: 0 | O31: =SUM(C31:L31,N31) -> 9 | P31: =SUM(C31:N31) -> 57
B32: 12.30 - 12.45 | C32: 8 | D32: 1 | E32: 0 | F32: 0 | G32: 0 | H32: 1 | I32: 0 | J32: 0 | K32: 1 | L32: 2 | M32: 37 | N32: 0 | O32: =SUM(C32:L32,N32) -> 13 | P32: =SUM(C32:N32) -> 50
B33: 12.45 - 13.00 | C33: 2 | D33: 0 | E33: 0 | F33: 4 | G33: 0 | H33: 0 | I33: 0 | J33: 0 | K33: 0 | L33: 1 | M33: 47 | N33: 0 | O33: =SUM(C33:L33,N33) -> 7 | P33: =SUM(C33:N33) -> 54
B34: 13.00 - 13.15 | C34: 4 | D34: 1 | E34: 1 | F34: 0 | G34: 0 | H34: 0 | I34: 0 | J34: 0 | K34: 1 | L34: 0 | M34: 72 | N34: 0 | O34: =SUM(C34:L34,N34) -> 7 | P34: =SUM(C34:N34) -> 79
B35: 13.15 - 13.30 | C35: 3 | D35: 2 | E35: 0 | F35: 0 | G35: 0 | H35: 0 | I35: 0 | J35: 0 | K35: 0 | L35: 1 | M35: 24 | N35: 0 | O35: =SUM(C35:L35,N35) -> 6 | P35: =SUM(C35:N35) -> 30
B36: 13.30 - 13.45 | C36: 3 | D36: 0 | E36: 0 | F36: 1 | G36: 0 | H36: 1 | I36: 1 | J36: 1 | K36: 0 | L36: 1 | M36: 21 | N36: 0 | O36: =SUM(C36:L36,N36) -> 8 | P36: =SUM(C36:N36) -> 29
B37: 13.45 - 14.00 | C37: 3 | D37: 0 | E37: 2 | F37: 4 | G37: 0 | H37: 0 | I37: 0 | J37: 0 | K37: 0 | L37: 2 | M37: 42 | N37: 0 | O37: =SUM(C37:L37,N37) -> 11 | P37: =SUM(C37:N37) -> 53
B38: 14.00 - 14.15 | C38: 0 | D38: 0 | E38: 0 | F38: 0 | G38: 0 | H38: 0 | I38: 0 | J38: 0 | K38: 0 | L38: 0 | M38: 18 | N38: 0 | O38: =SUM(C38:L38,N38) -> 0 | P38: =SUM(C38:N38) -> 18
B39: 14.15 - 14.30 | C39: 2 | D39: 0 | E39: 0 | F39: 2 | G39: 0 | H39: 0 | I39: 0 | J39: 1 | K39: 0 | L39: 4 | M39: 23 | N39: 0 | O39: =SUM(C39:L39,N39) -> 9 | P39: =SUM(C39:N39) -> 32
B40: 14.30 - 14.45 | C40: 2 | D40: 0 | E40: 0 | F40: 3 | G40: 0 | H40: 0 | I40: 0 | J40: 0 | K40: 0 | L40: 0 | M40: 36 | N40: 0 | O40: =SUM(C40:L40,N40) -> 5 | P40: =SUM(C40:N40) -> 41
... B57: 18.45 - 19.00 | C57: 2 | D57: 1 | E57: 0 | F57: 1 | G57: 0 | H57: 0 | I57: 1 | J57: 0 | K57: 0 | L57: 0 | M57: 51 | N57: 0 | O57: =SUM(C57:L57,N57) -> 5 | P57: =SUM(C57:N57) -> 56
B58: Totals | C58: =SUM(C10:C57) -> 149 | D58: =SUM(D10:D57) -> 17 | E58: =SUM(E10:E57) -> 9 | F58: =SUM(F10:F57) -> 42 | G58: =SUM(G10:G57) -> 0 | H58: =SUM(H10:H57) -> 13 | I58: =SUM(I10:I57) -> 12 | J58: =SUM(J10:J57) -> 20 | ... P58: =SUM(P10:P57) -> 1986
...

Sheet 26.10.PONDWE-KASESE
B1: Consultancy services for Preparation of Expressway Development Master Plan (EDMP) for Uganda
B2: MANUAL CLASSIFIED COUNT (MCC)
B3: ROAD NAME: | C3: ='26.10 KASESE-PONDWE'!C3:G3 -> MCC - C4 - STN137 - KASESE ROAD
C5: Date | D5: ='26.10 KASESE-PONDWE'!D5 -> 26.10.19 | F5: Location | G5: ='26.10 KASESE-PONDWE'!G5:H5 -> KABUYIRI | J5: Surveyor | K5: NAKIWUGE ALLEN
C6: Dir. From | D6: PONDWE | F6: Dir. To | G6: KASESE | J6: Supervisor | K6: ='26.10 KASESE-PONDWE'!K6:L6 -> GODFREY
B8: Time / Veh Type | R8: SUMMARY TRAFFIC VOLUMES
C9: 1. Car | D9: 2. Station Wagon | E9: 3. Pickups | F9: 4. Minibus, matatu | G9: 5. Medium bus | H9: 6. Large Bus | I9: 7. Light Truck | J9: 8. Medium Truck | K9: 9. Heavy truck | L9: 10. Truck Trailer | M9: 11. Motor cycles | N9: 12. Tractors | O9: Total Excl M/Cycles | P9: Total All | R9: Time | S9: 1. Car | T9: 2. Station Wagon | U9: 3. Pickups | V9: 4. Minibus, matatu | W9: 5. Medium bus | X9: 6. Large Bus | Y9: 7. Light Truck | Z9: 8. Medium Truck | AA9: 9. Heavy truck | AB9: 10. Truck Trailer | AC9: 11. Motorcycles | AD9: 12. Tractors, Graders | AE9: Total Excl M/ Cycles | AF9: Total All
B10: 07.00 - 07.15 | C10: 1 | D10: 0 | E10: 0 | F10: 0 | G10: 0 | H10: 0 | I10: 0 | J10: 0 | K10: 0 | L10: 0 | M10: 17 | N10: 0 | O10: =SUM(C10:L10,N10) -> 1 | P10: =SUM(C10:N10) -> 18 | R10: 0700-0800 | S10: =SUM(C10:C13) -> 4 | T10: =SUM(D10:D13) -> 0 | U10: =SUM(E10:E13) -> 0 | V10: =SUM(F10:F13) -> 0 | W10: =SUM(G10:G13) -> 0 | X10: =SUM(H10:H13) -> 1 | Y10: =SUM(I10:I13) -> 1 | Z10: =SUM(J10:J13) -> 0 | ... AF10: =SUM(P10:P13) -> 80
B11: 07.15 - 07.30 | C11: 0 | D11: 0 | E11: 0 | F11: 0 | G11: 0 | H11: 0 | I11: 1 | J11: 0 | K11: 0 | L11: 0 | M11: 22 | N11: 0 | O11: =SUM(C11:L11,N11) -> 1 | P11: =SUM(C11:N11) -> 23 | R11: 0800-0900 | S11: =SUM(C14:C17) -> 7 | T11: =SUM(D14:D17) -> 1 | U11: =SUM(E14:E17) -> 0 | V11: =SUM(F14:F17) -> 0 | W11: =SUM(G14:G17) -> 0 | X11: =SUM(H14:H17) -> 3 | Y11: =SUM(I14:I17) -> 1 | Z11: =SUM(J14:J17) -> 0 | ... AF11: =SUM(P14:P17) -> 88
B12: 07.30 - 07.45 | C12: 2 | D12: 0 | E12: 0 | F12: 0 | G12: 0 | H12: 1 | I12: 0 | J12: 0 | K12: 0 | L12: 0 | M12: 21 | N12: 0 | O12: =SUM(C12:L12,N12) -> 3 | P12: =SUM(C12:N12) -> 24 | R12: 0900-1000 | S12: =SUM(C18:C21) -> 10 | T12: =SUM(D18:D21) -> 1 | U12: =SUM(E18:E21) -> 1 | V12: =SUM(F18:F21) -> 0 | W12: =SUM(G18:G21) -> 0 | X12: =SUM(H18:H21) -> 1 | Y12: =SUM(I18:I21) -> 1 | Z12: =SUM(J18:J21) -> 2 | ... AF12: =SUM(P18:P21) -> 53
B13: 07.45 - 08.00 | C13: 1 | D13: 0 | E13: 0 | F13: 0 | G13: 0 | H13: 0 | I13: 0 | J13: 0 | K13: 0 | L13: 0 | M13: 14 | N13: 0 | O13: =SUM(C13:L13,N13) -> 1 | P13: =SUM(C13:N13) -> 15 | R13: 1000-1100 | S13: =SUM(C22:C25) -> 9 | T13: =SUM(D22:D25) -> 0 | U13: =SUM(E22:E25) -> 0 | V13: =SUM(F22:F25) -> 0 | W13: =SUM(G22:G25) -> 0 | X13: =SUM(H22:H25) -> 0 | Y13: =SUM(I22:I25) -> 1 | Z13: =SUM(J22:J25) -> 1 | ... AF13: =SUM(P22:P25) -> 70
B14: 08.00 - 08.15 | C14: 2 | D14: 0 | E14: 0 | F14: 0 | G14: 0 | H14: 1 | I14: 0 | J14: 0 | K14: 0 | L14: 0 | M14: 24 | N14: 0 | O14: =SUM(C14:L14,N14) -> 3 | P14: =SUM(C14:N14) -> 27 | R14: 1100-1200 | S14: =SUM(C26:C29) -> 21 | T14: =SUM(D26:D29) -> 2 | U14: =SUM(E26:E29) -> 2 | V14: =SUM(F26:F29) -> 0 | W14: =SUM(G26:G29) -> 0 | X14: =SUM(H26:H29) -> 1 | Y14: =SUM(I26:I29) -> 1 | Z14: =SUM(J26:J29) -> 2 | ... AF14: =SUM(P26:P29) -> 187
B15: 08.15 - 08.30 | C15: 2 | D15: 0 | E15: 0 | F15: 0 | G15: 0 | H15: 1 | I15: 0 | J15: 0 | K15: 0 | L15: 0 | M15: 15 | N15: 0 | O15: =SUM(C15:L15,N15) -> 3 | P15: =SUM(C15:N15) -> 18 | R15: 1200-1300 | S15: =SUM(C30:C33) -> 36 | T15: =SUM(D30:D33) -> 2 | U15: =SUM(E30:E33) -> 3 | V15: =SUM(F30:F33) -> 1 | W15: =SUM(G30:G33) -> 0 | X15: =SUM(H30:H33) -> 1 | Y15: =SUM(I30:I33) -> 0 | Z15: =SUM(J30:J33) -> 6 | ... AF15: =SUM(P30:P33) -> 250
B16: 08.30 - 08.45 | C16: 1 | D16: 1 | E16: 0 | F16: 0 | G16: 0 | H16: 0 | I16: 1 | J16: 0 | K16: 0 | L16: 0 | M16: 17 | N16: 0 | O16: =SUM(C16:L16,N16) -> 3 | P16: =SUM(C16:N16) -> 20 | R16: 1300-1400 | S16: =SUM(C34:C37) -> 13 | T16: =SUM(D34:D37) -> 2 | U16: =SUM(E34:E37) -> 0 | V16: =SUM(F34:F37) -> 0 | W16: =SUM(G34:G37) -> 0 | X16: =SUM(H34:H37) -> 1 | Y16: =SUM(I34:I37) -> 0 | Z16: =SUM(J34:J37) -> 2 | ... AF16: =SUM(P34:P37) -> 226
B17: 08.45 - 9.00 | C17: 2 | D17: 0 | E17: 0 | F17: 0 | G17: 0 | H17: 1 | I17: 0 | J17: 0 | K17: 0 | L17: 0 | M17: 20 | N17: 0 | O17: =SUM(C17:L17,N17) -> 3 | P17: =SUM(C17:N17) -> 23 | R17: 1400-1500 | S17: =SUM(C38:C41) -> 20 | T17: =SUM(D38:D41) -> 1 | U17: =SUM(E38:E41) -> 0 | V17: =SUM(F38:F41) -> 2 | W17: =SUM(G38:G41) -> 0 | X17: =SUM(H38:H41) -> 1 | Y17: =SUM(I38:I41) -> 2 | Z17: =SUM(J38:J41) -> 0 | ... AF17: =SUM(P38:P41) -> 300
B18: 09.00 - 09.15 | C18: 0 | D18: 0 | E18: 1 | F18: 0 | G18: 0 | H18: 0 | I18: 0 | J18: 0 | K18: 0 | L18: 0 | M18: 11 | N18: 0 | O18: =SUM(C18:L18,N18) -> 1 | P18: =SUM(C18:N18) -> 12 | R18: 1500-1600 | S18: =SUM(C42:C45) -> 27 | T18: =SUM(D42:D45) -> 2 | U18: =SUM(E42:E45) -> 2 | V18: =SUM(F42:F45) -> 0 | W18: =SUM(G42:G45) -> 0 | X18: =SUM(H42:H45) -> 1 | Y18: =SUM(I42:I45) -> 2 | Z18: =SUM(J42:J45) -> 2 | ... AF18: =SUM(P42:P45) -> 314
B19: 09.15 - 09.30 | C19: 4 | D19: 1 | E19: 0 | F19: 0 | G19: 0 | H19: 0 | I19: 0 | J19: 1 | K19: 0 | L19: 0 | M19: 15 | N19: 0 | O19: =SUM(C19:L19,N19) -> 6 | P19: =SUM(C19:N19) -> 21 | R19: 1600-1700 | S19: =SUM(C46:C49) -> 26 | T19: =SUM(D46:D49) -> 4 | U19: =SUM(E46:E49) -> 2 | V19: =SUM(F46:F49) -> 0 | W19: =SUM(G46:G49) -> 0 | X19: =SUM(H46:H49) -> 1 | Y19: =SUM(I46:I49) -> 3 | Z19: =SUM(J46:J49) -> 4 | ... AF19: =SUM(P46:P49) -> 297
B20: 09.30 - 09.45 | C20: 3 | D20: 0 | E20: 0 | F20: 0 | G20: 0 | H20: 0 | I20: 0 | J20: 0 | K20: 0 | L20: 0 | M20: 1 | N20: 0 | O20: =SUM(C20:L20,N20) -> 3 | P20: =SUM(C20:N20) -> 4 | R20: 1700-1800 | S20: =SUM(C50:C53) -> 25 | T20: =SUM(D50:D53) -> 2 | U20: =SUM(E50:E53) -> 2 | V20: =SUM(F50:F53) -> 4 | W20: =SUM(G50:G53) -> 0 | X20: =SUM(H50:H53) -> 0 | Y20: =SUM(I50:I53) -> 2 | Z20: =SUM(J50:J53) -> 1 | ... AF20: =SUM(P50:P53) -> 276
B21: 09.45 - 10.00 | C21: 3 | D21: 0 | E21: 0 | F21: 0 | G21: 0 | H21: 1 | I21: 1 | J21: 1 | K21: 0 | L21: 1 | M21: 9 | N21: 0 | O21: =SUM(C21:L21,N21) -> 7 | P21: =SUM(C21:N21) -> 16 | R21: 1800-1900 | S21: =SUM(C54:C57) -> 14 | T21: =SUM(D54:D57) -> 1 | U21: =SUM(E54:E57) -> 1 | V21: =SUM(F54:F57) -> 0 | W21: =SUM(G54:G57) -> 0 | X21: =SUM(H54:H57) -> 1 | Y21: =SUM(I54:I57) -> 2 | Z21: =SUM(J54:J57) -> 1 | ... AF21: =SUM(P54:P57) -> 267
B22: 10.00 - 10.15 | C22: 0 | D22: 0 | E22: 0 | F22: 0 | G22: 0 | H22: 0 | I22: 0 | J22: 0 | K22: 0 | L22: 0 | M22: 10 | N22: 0 | O22: =SUM(C22:L22,N22) -> 0 | P22: =SUM(C22:N22) -> 10 | R22: AM Peak Hr | S22: =MAX(S10:S12) -> 10 | T22: =MAX(T10:T12) -> 1 | U22: =MAX(U10:U12) -> 1 | V22: =MAX(V10:V12) -> 0 | W22: =MAX(W10:W12) -> 0 | X22: =MAX(X10:X12) -> 3 | Y22: =MAX(Y10:Y12) -> 1 | Z22: =MAX(Z10:Z12) -> 2 | ... AF22: =MAX(AF10:AF12) -> 88
B23: 10.15 - 10.30 | C23: 5 | D23: 0 | E23: 0 | F23: 0 | G23: 0 | H23: 0 | I23: 0 | J23: 1 | K23: 0 | L23: 0 | M23: 23 | N23: 0 | O23: =SUM(C23:L23,N23) -> 6 | P23: =SUM(C23:N23) -> 29 | R23: IP Peak Hr | S23: =MAX(S13:S18) -> 36 | T23: =MAX(T13:T18) -> 2 | U23: =MAX(U13:U18) -> 3 | V23: =MAX(V13:V18) -> 2 | W23: =MAX(W13:W18) -> 0 | X23: =MAX(X13:X18) -> 1 | Y23: =MAX(Y13:Y18) -> 2 | Z23: =MAX(Z13:Z18) -> 6 | ... AF23: =MAX(AF13:AF18) -> 314
B24: 10.30 - 10.45 | C24: 0 | D24: 0 | E24: 0 | F24: 0 | G24: 0 | H24: 0 | I24: 0 | J24: 0 | K24: 0 | L24: 0 | M24: 5 | N24: 0 | O24: =SUM(C24:L24,N24) -> 0 | P24: =SUM(C24:N24) -> 5 | R24: PM Peak Hr | S24: =MAX(S19:S21) -> 26 | T24: =MAX(T19:T21) -> 4 | U24: =MAX(U19:U21) -> 2 | V24: =MAX(V19:V21) -> 4 | W24: =MAX(W19:W21) -> 0 | X24: =MAX(X19:X21) -> 1 | Y24: =MAX(Y19:Y21) -> 3 | Z24: =MAX(Z19:Z21) -> 4 | ... AF24: =MAX(AF19:AF21) -> 297
B25: 10.45 - 11.00 | C25: 4 | D25: 0 | E25: 0 | F25: 0 | G25: 0 | H25: 0 | I25: 1 | J25: 0 | K25: 0 | L25: 0 | M25: 21 | N25: 0 | O25: =SUM(C25:L25,N25) -> 5 | P25: =SUM(C25:N25) -> 26 | R25: AM Period | S25: =SUM(S10:S12) -> 21 | T25: =SUM(T10:T12) -> 2 | U25: =SUM(U10:U12) -> 1 | V25: =SUM(V10:V12) -> 0 | W25: =SUM(W10:W12) -> 0 | X25: =SUM(X10:X12) -> 5 | Y25: =SUM(Y10:Y12) -> 3 | Z25: =SUM(Z10:Z12) -> 2 | ... AF25: =SUM(AF10:AF12) -> 221
B26: 11.00 - 11.15 | C26: 4 | D26: 1 | E26: 0 | F26: 0 | G26: 0 | H26: 0 | I26: 0 | J26: 2 | K26: 0 | L26: 0 | M26: 42 | N26: 0 | O26: =SUM(C26:L26,N26) -> 7 | P26: =SUM(C26:N26) -> 49 | R26: IP Period | S26: =SUM(S13:S18) -> 126 | T26: =SUM(T13:T18) -> 9 | U26: =SUM(U13:U18) -> 7 | V26: =SUM(V13:V18) -> 3 | W26: =SUM(W13:W18) -> 0 | X26: =SUM(X13:X18) -> 5 | Y26: =SUM(Y13:Y18) -> 6 | Z26: =SUM(Z13:Z18) -> 13 | ... AF26: =SUM(AF13:AF18) -> 1347
B27: 11.15 - 11.30 | C27: 4 | D27: 1 | E27: 0 | F27: 0 | G27: 0 | H27: 1 | I27: 0 | J27: 0 | K27: 0 | L27: 0 | M27: 45 | N27: 0 | O27: =SUM(C27:L27,N27) -> 6 | P27: =SUM(C27:N27) -> 51 | R27: PM Period | S27: =SUM(S19:S21) -> 65 | T27: =SUM(T19:T21) -> 7 | U27: =SUM(U19:U21) -> 5 | V27: =SUM(V19:V21) -> 4 | W27: =SUM(W19:W21) -> 0 | X27: =SUM(X19:X21) -> 2 | Y27: =SUM(Y19:Y21) -> 7 | Z27: =SUM(Z19:Z21) -> 6 | ... AF27: =SUM(AF19:AF21) -> 840
B28: 11.30 - 11.45 | C28: 8 | D28: 0 | E28: 2 | F28: 0 | G28: 0 | H28: 0 | I28: 0 | J28: 0 | K28: 0 | L28: 0 | M28: 43 | N28: 0 | O28: =SUM(C28:L28,N28) -> 10 | P28: =SUM(C28:N28) -> 53 | R28: 12 Hours | S28: =SUM(S10:S21) -> 212 | T28: =SUM(T10:T21) -> 18 | U28: =SUM(U10:U21) -> 13 | V28: =SUM(V10:V21) -> 7 | W28: =SUM(W10:W21) -> 0 | X28: =SUM(X10:X21) -> 12 | Y28: =SUM(Y10:Y21) -> 16 | Z28: =SUM(Z10:Z21) -> 21 | ... AF28: =SUM(AF10:AF21) -> 2408
B29: 11.45 - 12.00 | C29: 5 | D29: 0 | E29: 0 | F29: 0 | G29: 0 | H29: 0 | I29: 1 | J29: 0 | K29: 0 | L29: 0 | M29: 28 | N29: 0 | O29: =SUM(C29:L29,N29) -> 6 | P29: =SUM(C29:N29) -> 34
B30: 12.00 - 12.15 | C30: 11 | D30: 0 | E30: 0 | F30: 1 | G30: 0 | H30: 0 | I30: 0 | J30: 0 | K30: 0 | L30: 0 | M30: 42 | N30: 0 | O30: =SUM(C30:L30,N30) -> 12 | P30: =SUM(C30:N30) -> 54
B31: 12.15 - 12.30 | C31: 8 | D31: 1 | E31: 2 | F31: 0 | G31: 0 | H31: 1 | I31: 0 | J31: 3 | K31: 0 | L31: 0 | M31: 59 | N31: 0 | O31: =SUM(C31:L31,N31) -> 15 | P31: =SUM(C31:N31) -> 74
B32: 12.30 - 12.45 | C32: 8 | D32: 0 | E32: 0 | F32: 0 | G32: 0 | H32: 0 | I32: 0 | J32: 3 | K32: 0 | L32: 0 | M32: 59 | N32: 0 | O32: =SUM(C32:L32,N32) -> 11 | P32: =SUM(C32:N32) -> 70
B33: 12.45 - 13.00 | C33: 9 | D33: 1 | E33: 1 | F33: 0 | G33: 0 | H33: 0 | I33: 0 | J33: 0 | K33: 0 | L33: 0 | M33: 41 | N33: 0 | O33: =SUM(C33:L33,N33) -> 11 | P33: =SUM(C33:N33) -> 52
B34: 13.00 - 13.15 | C34: 4 | D34: 1 | E34: 0 | F34: 0 | G34: 0 | H34: 1 | I34: 0 | J34: 0 | K34: 0 | L34: 0 | M34: 41 | N34: 0 | O34: =SUM(C34:L34,N34) -> 6 | P34: =SUM(C34:N34) -> 47
B35: 13.15 - 13.30 | C35: 3 | D35: 1 | E35: 0 | F35: 0 | G35: 0 | H35: 0 | I35: 0 | J35: 0 | K35: 1 | L35: 0 | M35: 63 | N35: 0 | O35: =SUM(C35:L35,N35) -> 5 | P35: =SUM(C35:N35) -> 68
B36: 13.30 - 13.45 | C36: 2 | D36: 0 | E36: 0 | F36: 0 | G36: 0 | H36: 0 | I36: 0 | J36: 2 | K36: 0 | L36: 0 | M36: 59 | N36: 0 | O36: =SUM(C36:L36,N36) -> 4 | P36: =SUM(C36:N36) -> 63
B37: 13.45 - 14.00 | C37: 4 | D37: 0 | E37: 0 | F37: 0 | G37: 0 | H37: 0 | I37: 0 | J37: 0 | K37: 0 | L37: 0 | M37: 44 | N37: 0 | O37: =SUM(C37:L37,N37) -> 4 | P37: =SUM(C37:N37) -> 48
B38: 14.00 - 14.15 | C38: 4 | D38: 1 | E38: 0 | F38: 1 | G38: 0 | H38: 0 | I38: 1 | J38: 0 | K38: 0 | L38: 0 | M38: 64 | N38: 0 | O38: =SUM(C38:L38,N38) -> 7 | P38: =SUM(C38:N38) -> 71
B39: 14.15 - 14.30 | C39: 7 | D39: 0 | E39: 0 | F39: 1 | G39: 0 | H39: 1 | I39: 0 | J39: 0 | K39: 0 | L39: 0 | M39: 72 | N39: 0 | O39: =SUM(C39:L39,N39) -> 9 | P39: =SUM(C39:N39) -> 81
B40: 14.30 - 14.45 | C40: 4 | D40: 0 | E40: 0 | F40: 0 | G40: 0 | H40: 0 | I40: 0 | J40: 0 | K40: 1 | L40: 0 | M40: 66 | N40: 0 | O40: =SUM(C40:L40,N40) -> 5 | P40: =SUM(C40:N40) -> 71
... B57: 18.45 - 19.00 | C57: 6 | D57: 0 | E57: 0 | F57: 0 | G57: 0 | H57: 0 | I57: 0 | J57: 0 | K57: 0 | L57: 1 | M57: 63 | N57: 0 | O57: =SUM(C57:L57,N57) -> 7 | P57: =SUM(C57:N57) -> 70
B58: Totals | C58: =SUM(C10:C57) -> 212 | D58: =SUM(D10:D57) -> 18 | E58: =SUM(E10:E57) -> 13 | F58: =SUM(F10:F57) -> 7 | G58: =SUM(G10:G57) -> 0 | H58: =SUM(H10:H57) -> 12 | I58: =SUM(I10:I57) -> 16 | J58: =SUM(J10:J57) -> 21 | ... P58: =SUM(P10:P57) -> 2408
...

Sheet 27.10 KASESE-PONDWE
B1: Consultancy services for Preparation of Expressway Development Master Plan (EDMP) for Uganda
B2: MANUAL CLASSIFIED COUNT (MCC)
B3: ROAD NAME: | C3: ='26.10 KASESE-PONDWE'!C3:G3 -> MCC - C4 - STN137 - KASESE ROAD
C5: Date | D5: 27.10.19 | F5: Location | G5: ='26.10 KASESE-PONDWE'!G5:H5 -> KABUYIRI | J5: Surveyor | K5: GODFREY
C6: Dir. From | D6: ='26.10 KASESE-PONDWE'!D6:E6 -> KASESE | F6: Dir. To | G6: ='26.10 KASESE-PONDWE'!G6:H6 -> PONDWE | J6: Supervisor | K6: ='26.10 KASESE-PONDWE'!K6:L6 -> GODFREY
B8: Time / Veh Type | R8: SUMMARY TRAFFIC VOLUMES
C9: 1. Car | D9: 2. Station Wagon | E9: 3. Pickups | F9: 4. Minibus, matatu | G9: 5. Medium bus | H9: 6. Large Bus | I9: 7. Light Truck | J9: 8. Medium Truck | K9: 9. Heavy truck | L9: 10. Truck Trailer | M9: 11. Motor cycles | N9: 12. Tractors | O9: Total Excl M/Cycles | P9: Total All | R9: Time | S9: 1. Car | T9: 2. Station Wagon | U9: 3. Pickups | V9: 4. Minibus, matatu | W9: 5. Medium bus | X9: 6. Large Bus | Y9: 7. Light Truck | Z9: 8. Medium Truck | AA9: 9. Heavy truck | AB9: 10. Truck Trailer | AC9: 11. Motorcycles | AD9: 12. Tractors, Graders | AE9: Total Excl M/ Cycles | AF9: Total All
B10: 07.00 - 07.15 | C10: 1 | D10: 0 | E10: 0 | F10: 0 | G10: 0 | H10: 0 | I10: 0 | J10: 0 | K10: 0 | L10: 0 | M10: 7 | N10: 0 | O10: =SUM(C10:L10,N10) -> 1 | P10: =SUM(C10:N10) -> 8 | R10: 0700-0800 | S10: =SUM(C10:C13) -> 4 | T10: =SUM(D10:D13) -> 0 | U10: =SUM(E10:E13) -> 0 | V10: =SUM(F10:F13) -> 2 | W10: =SUM(G10:G13) -> 0 | X10: =SUM(H10:H13) -> 1 | Y10: =SUM(I10:I13) -> 1 | Z10: =SUM(J10:J13) -> 3 | ... AF10: =SUM(P10:P13) -> 87
B11: 07.15 - 07.30 | C11: 2 | D11: 0 | E11: 0 | F11: 0 | G11: 0 | H11: 1 | I11: 0 | J11: 0 | K11: 0 | L11: 0 | M11: 12 | N11: 0 | O11: =SUM(C11:L11,N11) -> 3 | P11: =SUM(C11:N11) -> 15 | R11: 0800-0900 | S11: =SUM(C14:C17) -> 11 | T11: =SUM(D14:D17) -> 0 | U11: =SUM(E14:E17) -> 0 | V11: =SUM(F14:F17) -> 3 | W11: =SUM(G14:G17) -> 0 | X11: =SUM(H14:H17) -> 1 | Y11: =SUM(I14:I17) -> 0 | Z11: =SUM(J14:J17) -> 2 | ... AF11: =SUM(P14:P17) -> 177
B12: 07.30 - 07.45 | C12: 0 | D12: 0 | E12: 0 | F12: 0 | G12: 0 | H12: 0 | I12: 0 | J12: 0 | K12: 0 | L12: 1 | M12: 17 | N12: 0 | O12: =SUM(C12:L12,N12) -> 1 | P12: =SUM(C12:N12) -> 18 | R12: 0900-1000 | S12: =SUM(C18:C21) -> 20 | T12: =SUM(D18:D21) -> 1 | U12: =SUM(E18:E21) -> 2 | V12: =SUM(F18:F21) -> 3 | W12: =SUM(G18:G21) -> 0 | X12: =SUM(H18:H21) -> 1 | Y12: =SUM(I18:I21) -> 1 | Z12: =SUM(J18:J21) -> 2 | ... AF12: =SUM(P18:P21) -> 284
B13: 07.45 - 08.00 | C13: 1 | D13: 0 | E13: 0 | F13: 2 | G13: 0 | H13: 0 | I13: 1 | J13: 3 | K13: 0 | L13: 2 | M13: 37 | N13: 0 | O13: =SUM(C13:L13,N13) -> 9 | P13: =SUM(C13:N13) -> 46 | R13: 1000-1100 | S13: =SUM(C22:C25) -> 17 | T13: =SUM(D22:D25) -> 1 | U13: =SUM(E22:E25) -> 2 | V13: =SUM(F22:F25) -> 2 | W13: =SUM(G22:G25) -> 0 | X13: =SUM(H22:H25) -> 0 | Y13: =SUM(I22:I25) -> 1 | Z13: =SUM(J22:J25) -> 3 | ... AF13: =SUM(P22:P25) -> 154
B14: 08.00 - 08.15 | C14: 4 | D14: 0 | E14: 0 | F14: 0 | G14: 0 | H14: 0 | I14: 0 | J14: 0 | K14: 0 | L14: 0 | M14: 51 | N14: 0 | O14: =SUM(C14:L14,N14) -> 4 | P14: =SUM(C14:N14) -> 55 | R14: 1100-1200 | S14: =SUM(C26:C29) -> 16 | T14: =SUM(D26:D29) -> 0 | U14: =SUM(E26:E29) -> 0 | V14: =SUM(F26:F29) -> 3 | W14: =SUM(G26:G29) -> 0 | X14: =SUM(H26:H29) -> 1 | Y14: =SUM(I26:I29) -> 1 | Z14: =SUM(J26:J29) -> 1 | ... AF14: =SUM(P26:P29) -> 148
B15: 08.15 - 08.30 | C15: 1 | D15: 0 | E15: 0 | F15: 1 | G15: 0 | H15: 1 | I15: 0 | J15: 0 | K15: 0 | L15: 1 | M15: 29 | N15: 0 | O15: =SUM(C15:L15,N15) -> 4 | P15: =SUM(C15:N15) -> 33 | R15: 1200-1300 | S15: =SUM(C30:C33) -> 7 | T15: =SUM(D30:D33) -> 1 | U15: =SUM(E30:E33) -> 1 | V15: =SUM(F30:F33) -> 8 | W15: =SUM(G30:G33) -> 0 | X15: =SUM(H30:H33) -> 0 | Y15: =SUM(I30:I33) -> 4 | Z15: =SUM(J30:J33) -> 1 | ... AF15: =SUM(P30:P33) -> 149
B16: 08.30 - 08.45 | C16: 3 | D16: 0 | E16: 0 | F16: 2 | G16: 0 | H16: 0 | I16: 0 | J16: 2 | K16: 0 | L16: 3 | M16: 28 | N16: 0 | O16: =SUM(C16:L16,N16) -> 10 | P16: =SUM(C16:N16) -> 38 | R16: 1300-1400 | S16: =SUM(C34:C37) -> 10 | T16: =SUM(D34:D37) -> 0 | U16: =SUM(E34:E37) -> 1 | V16: =SUM(F34:F37) -> 6 | W16: =SUM(G34:G37) -> 0 | X16: =SUM(H34:H37) -> 0 | Y16: =SUM(I34:I37) -> 1 | Z16: =SUM(J34:J37) -> 1 | ... AF16: =SUM(P34:P37) -> 176
B17: 08.45 - 9.00 | C17: 3 | D17: 0 | E17: 0 | F17: 0 | G17: 0 | H17: 0 | I17: 0 | J17: 0 | K17: 0 | L17: 0 | M17: 48 | N17: 0 | O17: =SUM(C17:L17,N17) -> 3 | P17: =SUM(C17:N17) -> 51 | R17: 1400-1500 | S17: =SUM(C38:C41) -> 9 | T17: =SUM(D38:D41) -> 0 | U17: =SUM(E38:E41) -> 1 | V17: =SUM(F38:F41) -> 3 | W17: =SUM(G38:G41) -> 0 | X17: =SUM(H38:H41) -> 1 | Y17: =SUM(I38:I41) -> 0 | Z17: =SUM(J38:J41) -> 0 | ... AF17: =SUM(P38:P41) -> 208
B18: 09.00 - 09.15 | C18: 3 | D18: 0 | E18: 1 | F18: 2 | G18: 0 | H18: 0 | I18: 1 | J18: 1 | K18: 1 | L18: 1 | M18: 52 | N18: 0 | O18: =SUM(C18:L18,N18) -> 10 | P18: =SUM(C18:N18) -> 62 | R18: 1500-1600 | S18: =SUM(C42:C45) -> 17 | T18: =SUM(D42:D45) -> 3 | U18: =SUM(E42:E45) -> 0 | V18: =SUM(F42:F45) -> 7 | W18: =SUM(G42:G45) -> 0 | X18: =SUM(H42:H45) -> 0 | Y18: =SUM(I42:I45) -> 4 | Z18: =SUM(J42:J45) -> 0 | ... AF18: =SUM(P42:P45) -> 210
B19: 09.15 - 09.30 | C19: 3 | D19: 1 | E19: 0 | F19: 1 | G19: 0 | H19: 0 | I19: 0 | J19: 0 | K19: 0 | L19: 0 | M19: 57 | N19: 0 | O19: =SUM(C19:L19,N19) -> 5 | P19: =SUM(C19:N19) -> 62 | R19: 1600-1700 | S19: =SUM(C46:C49) -> 11 | T19: =SUM(D46:D49) -> 3 | U19: =SUM(E46:E49) -> 1 | V19: =SUM(F46:F49) -> 6 | W19: =SUM(G46:G49) -> 0 | X19: =SUM(H46:H49) -> 0 | Y19: =SUM(I46:I49) -> 0 | Z19: =SUM(J46:J49) -> 1 | ... AF19: =SUM(P46:P49) -> 265
B20: 09.30 - 09.45 | C20: 3 | D20: 0 | E20: 1 | F20: 0 | G20: 0 | H20: 0 | I20: 0 | J20: 0 | K20: 0 | L20: 1 | M20: 69 | N20: 0 | O20: =SUM(C20:L20,N20) -> 5 | P20: =SUM(C20:N20) -> 74 | R20: 1700-1800 | S20: =SUM(C50:C53) -> 20 | T20: =SUM(D50:D53) -> 3 | U20: =SUM(E50:E53) -> 0 | V20: =SUM(F50:F53) -> 3 | W20: =SUM(G50:G53) -> 0 | X20: =SUM(H50:H53) -> 2 | Y20: =SUM(I50:I53) -> 1 | Z20: =SUM(J50:J53) -> 0 | ... AF20: =SUM(P50:P53) -> 208
B21: 09.45 - 10.00 | C21: 11 | D21: 0 | E21: 0 | F21: 0 | G21: 0 | H21: 1 | I21: 0 | J21: 1 | K21: 0 | L21: 1 | M21: 72 | N21: 0 | O21: =SUM(C21:L21,N21) -> 14 | P21: =SUM(C21:N21) -> 86 | R21: 1800-1900 | S21: =SUM(C54:C57) -> 15 | T21: =SUM(D54:D57) -> 1 | U21: =SUM(E54:E57) -> 1 | V21: =SUM(F54:F57) -> 3 | W21: =SUM(G54:G57) -> 0 | X21: =SUM(H54:H57) -> 0 | Y21: =SUM(I54:I57) -> 4 | Z21: =SUM(J54:J57) -> 0 | ... AF21: =SUM(P54:P57) -> 245
B22: 10.00 - 10.15 | C22: 3 | D22: 1 | E22: 0 | F22: 0 | G22: 0 | H22: 0 | I22: 1 | J22: 0 | K22: 0 | L22: 0 | M22: 17 | N22: 0 | O22: =SUM(C22:L22,N22) -> 5 | P22: =SUM(C22:N22) -> 22 | R22: AM Peak Hr | S22: =MAX(S10:S12) -> 20 | T22: =MAX(T10:T12) -> 1 | U22: =MAX(U10:U12) -> 2 | V22: =MAX(V10:V12) -> 3 | W22: =MAX(W10:W12) -> 0 | X22: =MAX(X10:X12) -> 1 | Y22: =MAX(Y10:Y12) -> 1 | Z22: =MAX(Z10:Z12) -> 3 | ... AF22: =MAX(AF10:AF12) -> 284
B23: 10.15 - 10.30 | C23: 7 | D23: 0 | E23: 1 | F23: 0 | G23: 0 | H23: 0 | I23: 0 | J23: 2 | K23: 0 | L23: 0 | M23: 47 | N23: 0 | O23: =SUM(C23:L23,N23) -> 10 | P23: =SUM(C23:N23) -> 57 | R23: IP Peak Hr | S23: =MAX(S13:S18) -> 17 | T23: =MAX(T13:T18) -> 3 | U23: =MAX(U13:U18) -> 2 | V23: =MAX(V13:V18) -> 8 | W23: =MAX(W13:W18) -> 0 | X23: =MAX(X13:X18) -> 1 | Y23: =MAX(Y13:Y18) -> 4 | Z23: =MAX(Z13:Z18) -> 3 | ... AF23: =MAX(AF13:AF18) -> 210
B24: 10.30 - 10.45 | C24: 2 | D24: 0 | E24: 1 | F24: 2 | G24: 0 | H24: 0 | I24: 0 | J24: 1 | K24: 0 | L24: 0 | M24: 34 | N24: 0 | O24: =SUM(C24:L24,N24) -> 6 | P24: =SUM(C24:N24) -> 40 | R24: PM Peak Hr | S24: =MAX(S19:S21) -> 20 | T24: =MAX(T19:T21) -> 3 | U24: =MAX(U19:U21) -> 1 | V24: =MAX(V19:V21) -> 6 | W24: =MAX(W19:W21) -> 0 | X24: =MAX(X19:X21) -> 2 | Y24: =MAX(Y19:Y21) -> 4 | Z24: =MAX(Z19:Z21) -> 1 | ... AF24: =MAX(AF19:AF21) -> 265
B25: 10.45 - 11.00 | C25: 5 | D25: 0 | E25: 0 | F25: 0 | G25: 0 | H25: 0 | I25: 0 | J25: 0 | K25: 1 | L25: 1 | M25: 28 | N25: 0 | O25: =SUM(C25:L25,N25) -> 7 | P25: =SUM(C25:N25) -> 35 | R25: AM Period | S25: =SUM(S10:S12) -> 35 | T25: =SUM(T10:T12) -> 1 | U25: =SUM(U10:U12) -> 2 | V25: =SUM(V10:V12) -> 8 | W25: =SUM(W10:W12) -> 0 | X25: =SUM(X10:X12) -> 3 | Y25: =SUM(Y10:Y12) -> 2 | Z25: =SUM(Z10:Z12) -> 7 | ... AF25: =SUM(AF10:AF12) -> 548
B26: 11.00 - 11.15 | C26: 8 | D26: 0 | E26: 0 | F26: 1 | G26: 0 | H26: 1 | I26: 0 | J26: 0 | K26: 0 | L26: 0 | M26: 32 | N26: 0 | O26: =SUM(C26:L26,N26) -> 10 | P26: =SUM(C26:N26) -> 42 | R26: IP Period | S26: =SUM(S13:S18) -> 76 | T26: =SUM(T13:T18) -> 5 | U26: =SUM(U13:U18) -> 5 | V26: =SUM(V13:V18) -> 29 | W26: =SUM(W13:W18) -> 0 | X26: =SUM(X13:X18) -> 2 | Y26: =SUM(Y13:Y18) -> 11 | Z26: =SUM(Z13:Z18) -> 6 | ... AF26: =SUM(AF13:AF18) -> 1045
B27: 11.15 - 11.30 | C27: 2 | D27: 0 | E27: 0 | F27: 0 | G27: 0 | H27: 0 | I27: 0 | J27: 1 | K27: 0 | L27: 0 | M27: 28 | N27: 0 | O27: =SUM(C27:L27,N27) -> 3 | P27: =SUM(C27:N27) -> 31 | R27: PM Period | S27: =SUM(S19:S21) -> 46 | T27: =SUM(T19:T21) -> 7 | U27: =SUM(U19:U21) -> 2 | V27: =SUM(V19:V21) -> 12 | W27: =SUM(W19:W21) -> 0 | X27: =SUM(X19:X21) -> 2 | Y27: =SUM(Y19:Y21) -> 5 | Z27: =SUM(Z19:Z21) -> 1 | ... AF27: =SUM(AF19:AF21) -> 718
B28: 11.30 - 11.45 | C28: 4 | D28: 0 | E28: 0 | F28: 0 | G28: 0 | H28: 0 | I28: 0 | J28: 0 | K28: 0 | L28: 0 | M28: 36 | N28: 0 | O28: =SUM(C28:L28,N28) -> 4 | P28: =SUM(C28:N28) -> 40 | R28: 12 Hours | S28: =SUM(S10:S21) -> 157 | T28: =SUM(T10:T21) -> 13 | U28: =SUM(U10:U21) -> 9 | V28: =SUM(V10:V21) -> 49 | W28: =SUM(W10:W21) -> 0 | X28: =SUM(X10:X21) -> 7 | Y28: =SUM(Y10:Y21) -> 18 | Z28: =SUM(Z10:Z21) -> 14 | ... AF28: =SUM(AF10:AF21) -> 2311
B29: 11.45 - 12.00 | C29: 2 | D29: 0 | E29: 0 | F29: 2 | G29: 0 | H29: 0 | I29: 1 | J29: 0 | K29: 0 | L29: 0 | M29: 30 | N29: 0 | O29: =SUM(C29:L29,N29) -> 5 | P29: =SUM(C29:N29) -> 35
B30: 12.00 - 12.15 | C30: 0 | D30: 0 | E30: 1 | F30: 2 | G30: 0 | H30: 0 | I30: 0 | J30: 0 | K30: 1 | L30: 0 | M30: 27 | N30: 0 | O30: =SUM(C30:L30,N30) -> 4 | P30: =SUM(C30:N30) -> 31
B31: 12.15 - 12.30 | C31: 1 | D31: 1 | E31: 0 | F31: 3 | G31: 0 | H31: 0 | I31: 1 | J31: 0 | K31: 0 | L31: 0 | M31: 43 | N31: 0 | O31: =SUM(C31:L31,N31) -> 6 | P31: =SUM(C31:N31) -> 49
B32: 12.30 - 12.45 | C32: 4 | D32: 0 | E32: 0 | F32: 1 | G32: 0 | H32: 0 | I32: 0 | J32: 1 | K32: 0 | L32: 0 | M32: 30 | N32: 0 | O32: =SUM(C32:L32,N32) -> 6 | P32: =SUM(C32:N32) -> 36
B33: 12.45 - 13.00 | C33: 2 | D33: 0 | E33: 0 | F33: 2 | G33: 0 | H33: 0 | I33: 3 | J33: 0 | K33: 1 | L33: 1 | M33: 24 | N33: 0 | O33: =SUM(C33:L33,N33) -> 9 | P33: =SUM(C33:N33) -> 33
B34: 13.00 - 13.15 | C34: 3 | D34: 0 | E34: 0 | F34: 1 | G34: 0 | H34: 0 | I34: 0 | J34: 0 | K34: 0 | L34: 1 | M34: 24 | N34: 0 | O34: =SUM(C34:L34,N34) -> 5 | P34: =SUM(C34:N34) -> 29
B35: 13.15 - 13.30 | C35: 2 | D35: 0 | E35: 0 | F35: 3 | G35: 0 | H35: 0 | I35: 0 | J35: 0 | K35: 0 | L35: 0 | M35: 42 | N35: 0 | O35: =SUM(C35:L35,N35) -> 5 | P35: =SUM(C35:N35) -> 47
B36: 13.30 - 13.45 | C36: 0 | D36: 0 | E36: 0 | F36: 1 | G36: 0 | H36: 0 | I36: 0 | J36: 1 | K36: 0 | L36: 0 | M36: 33 | N36: 0 | O36: =SUM(C36:L36,N36) -> 2 | P36: =SUM(C36:N36) -> 35
B37: 13.45 - 14.00 | C37: 5 | D37: 0 | E37: 1 | F37: 1 | G37: 0 | H37: 0 | I37: 1 | J37: 0 | K37: 0 | L37: 2 | M37: 55 | N37: 0 | O37: =SUM(C37:L37,N37) -> 10 | P37: =SUM(C37:N37) -> 65
B38: 14.00 - 14.15 | C38: 0 | D38: 0 | E38: 1 | F38: 2 | G38: 0 | H38: 0 | I38: 0 | J38: 0 | K38: 1 | L38: 0 | M38: 57 | N38: 0 | O38: =SUM(C38:L38,N38) -> 4 | P38: =SUM(C38:N38) -> 61
B39: 14.15 - 14.30 | C39: 2 | D39: 0 | E39: 0 | F39: 0 | G39: 0 | H39: 1 | I39: 0 | J39: 0 | K39: 0 | L39: 0 | M39: 58 | N39: 0 | O39: =SUM(C39:L39,N39) -> 3 | P39: =SUM(C39:N39) -> 61
B40: 14.30 - 14.45 | C40: 1 | D40: 0 | E40: 0 | F40: 0 | G40: 0 | H40: 0 | I40: 0 | J40: 0 | K40: 0 | L40: 1 | M40: 30 | N40: 0 | O40: =SUM(C40:L40,N40) -> 2 | P40: =SUM(C40:N40) -> 32
... B57: 18.45 - 19.00 | C57: 2 | D57: 0 | E57: 1 | F57: 0 | G57: 0 | H57: 0 | I57: 0 | J57: 0 | K57: 0 | L57: 0 | M57: 55 | N57: 0 | O57: =SUM(C57:L57,N57) -> 3 | P57: =SUM(C57:N57) -> 58
B58: Totals | C58: =SUM(C10:C57) -> 157 | D58: =SUM(D10:D57) -> 13 | E58: =SUM(E10:E57) -> 9 | F58: =SUM(F10:F57) -> 49 | G58: =SUM(G10:G57) -> 0 | H58: =SUM(H10:H57) -> 7 | I58: =SUM(I10:I57) -> 18 | J58: =SUM(J10:J57) -> 14 | ... P58: =SUM(P10:P57) -> 2311
...

Sheet 27.10 PONDWE-KASESE
B1: Consultancy services for Preparation of Expressway Development Master Plan (EDMP) for Uganda
B2: MANUAL CLASSIFIED COUNT (MCC)
B3: ROAD NAME: | C3: ='26.10.PONDWE-KASESE'!C3:G3 -> MCC - C4 - STN137 - KASESE ROAD
C5: Date | D5: ='27.10 KASESE-PONDWE'!D5 -> 27.10.19 | F5: Location | G5: ='26.10 KASESE-PONDWE'!G5:H5 -> KABUYIRI | J5: Surveyor | K5: NABIWUGE ALLEN
C6: Dir. From | D6: ='26.10.PONDWE-KASESE'!D6:E6 -> PONDWE | F6: Dir. To | G6: ='26.10.PONDWE-KASESE'!G6:H6 -> KASESE | J6: Supervisor | K6: ='26.10 KASESE-PONDWE'!K6:L6 -> GODFREY
B8: Time / Veh Type | R8: SUMMARY TRAFFIC VOLUMES
C9: 1. Car | D9: 2. Station Wagon | E9: 3. Pickups | F9: 4. Minibus, matatu | G9: 5. Medium bus | H9: 6. Large Bus | I9: 7. Light Truck | J9: 8. Medium Truck | K9: 9. Heavy truck | L9: 10. Truck Trailer | M9: 11. Motor cycles | N9: 12. Tractors | O9: Total Excl M/Cycles | P9: Total All | R9: Time | S9: 1. Car | T9: 2. Station Wagon | U9: 3. Pickups | V9: 4. Minibus, matatu | W9: 5. Medium bus | X9: 6. Large Bus | Y9: 7. Light Truck | Z9: 8. Medium Truck | AA9: 9. Heavy truck | AB9: 10. Truck Trailer | AC9: 11. Motorcycles | AD9: 12. Tractors, Graders | AE9: Total Excl M/ Cycles | AF9: Total All
B10: 07.00 - 07.15 | C10: 3 | D10: 0 | E10: 1 | F10: 0 | G10: 0 | H10: 0 | I10: 0 | J10: 0 | K10: 0 | L10: 0 | M10: 10 | N10: 0 | O10: =SUM(C10:L10,N10) -> 4 | P10: =SUM(C10:N10) -> 14 | R10: 0700-0800 | S10: =SUM(C10:C13) -> 6 | T10: =SUM(D10:D13) -> 0 | U10: =SUM(E10:E13) -> 1 | V10: =SUM(F10:F13) -> 0 | W10: =SUM(G10:G13) -> 0 | X10: =SUM(H10:H13) -> 1 | Y10: =SUM(I10:I13) -> 0 | Z10: =SUM(J10:J13) -> 1 | ... AF10: =SUM(P10:P13) -> 104
B11: 07.15 - 07.30 | C11: 1 | D11: 0 | E11: 0 | F11: 0 | G11: 0 | H11: 0 | I11: 0 | J11: 0 | K11: 0 | L11: 0 | M11: 17 | N11: 0 | O11: =SUM(C11:L11,N11) -> 1 | P11: =SUM(C11:N11) -> 18 | R11: 0800-0900 | S11: =SUM(C14:C17) -> 11 | T11: =SUM(D14:D17) -> 0 | U11: =SUM(E14:E17) -> 0 | V11: =SUM(F14:F17) -> 0 | W11: =SUM(G14:G17) -> 0 | X11: =SUM(H14:H17) -> 2 | Y11: =SUM(I14:I17) -> 0 | Z11: =SUM(J14:J17) -> 1 | ... AF11: =SUM(P14:P17) -> 131
B12: 07.30 - 07.45 | C12: 1 | D12: 0 | E12: 0 | F12: 0 | G12: 0 | H12: 1 | I12: 0 | J12: 0 | K12: 0 | L12: 0 | M12: 33 | N12: 0 | O12: =SUM(C12:L12,N12) -> 2 | P12: =SUM(C12:N12) -> 35 | R12: 0900-1000 | S12: =SUM(C18:C21) -> 13 | T12: =SUM(D18:D21) -> 0 | U12: =SUM(E18:E21) -> 2 | V12: =SUM(F18:F21) -> 0 | W12: =SUM(G18:G21) -> 1 | X12: =SUM(H18:H21) -> 0 | Y12: =SUM(I18:I21) -> 2 | Z12: =SUM(J18:J21) -> 2 | ... AF12: =SUM(P18:P21) -> 244
B13: 07.45 - 08.00 | C13: 1 | D13: 0 | E13: 0 | F13: 0 | G13: 0 | H13: 0 | I13: 0 | J13: 1 | K13: 0 | L13: 0 | M13: 35 | N13: 0 | O13: =SUM(C13:L13,N13) -> 2 | P13: =SUM(C13:N13) -> 37 | R13: 1000-1100 | S13: =SUM(C22:C25) -> 11 | T13: =SUM(D22:D25) -> 0 | U13: =SUM(E22:E25) -> 3 | V13: =SUM(F22:F25) -> 0 | W13: =SUM(G22:G25) -> 0 | X13: =SUM(H22:H25) -> 0 | Y13: =SUM(I22:I25) -> 1 | Z13: =SUM(J22:J25) -> 1 | ... AF13: =SUM(P22:P25) -> 233
B14: 08.00 - 08.15 | C14: 3 | D14: 0 | E14: 0 | F14: 0 | G14: 0 | H14: 1 | I14: 0 | J14: 0 | K14: 0 | L14: 1 | M14: 24 | N14: 0 | O14: =SUM(C14:L14,N14) -> 5 | P14: =SUM(C14:N14) -> 29 | R14: 1100-1200 | S14: =SUM(C26:C29) -> 21 | T14: =SUM(D26:D29) -> 0 | U14: =SUM(E26:E29) -> 1 | V14: =SUM(F26:F29) -> 0 | W14: =SUM(G26:G29) -> 1 | X14: =SUM(H26:H29) -> 1 | Y14: =SUM(I26:I29) -> 4 | Z14: =SUM(J26:J29) -> 2 | ... AF14: =SUM(P26:P29) -> 290
B15: 08.15 - 08.30 | C15: 0 | D15: 0 | E15: 0 | F15: 0 | G15: 0 | H15: 0 | I15: 0 | J15: 0 | K15: 0 | L15: 0 | M15: 30 | N15: 0 | O15: =SUM(C15:L15,N15) -> 0 | P15: =SUM(C15:N15) -> 30 | R15: 1200-1300 | S15: =SUM(C30:C33) -> 15 | T15: =SUM(D30:D33) -> 0 | U15: =SUM(E30:E33) -> 0 | V15: =SUM(F30:F33) -> 0 | W15: =SUM(G30:G33) -> 0 | X15: =SUM(H30:H33) -> 0 | Y15: =SUM(I30:I33) -> 1 | Z15: =SUM(J30:J33) -> 2 | ... AF15: =SUM(P30:P33) -> 219
B16: 08.30 - 08.45 | C16: 4 | D16: 0 | E16: 0 | F16: 0 | G16: 0 | H16: 0 | I16: 0 | J16: 0 | K16: 0 | L16: 0 | M16: 23 | N16: 0 | O16: =SUM(C16:L16,N16) -> 4 | P16: =SUM(C16:N16) -> 27 | R16: 1300-1400 | S16: =SUM(C34:C37) -> 23 | T16: =SUM(D34:D37) -> 0 | U16: =SUM(E34:E37) -> 1 | V16: =SUM(F34:F37) -> 1 | W16: =SUM(G34:G37) -> 0 | X16: =SUM(H34:H37) -> 1 | Y16: =SUM(I34:I37) -> 1 | Z16: =SUM(J34:J37) -> 5 | ... AF16: =SUM(P34:P37) -> 313
B17: 08.45 - 9.00 | C17: 4 | D17: 0 | E17: 0 | F17: 0 | G17: 0 | H17: 1 | I17: 0 | J17: 1 | K17: 0 | L17: 0 | M17: 39 | N17: 0 | O17: =SUM(C17:L17,N17) -> 6 | P17: =SUM(C17:N17) -> 45 | R17: 1400-1500 | S17: =SUM(C38:C41) -> 24 | T17: =SUM(D38:D41) -> 0 | U17: =SUM(E38:E41) -> 1 | V17: =SUM(F38:F41) -> 2 | W17: =SUM(G38:G41) -> 0 | X17: =SUM(H38:H41) -> 1 | Y17: =SUM(I38:I41) -> 3 | Z17: =SUM(J38:J41) -> 1 | ... AF17: =SUM(P38:P41) -> 321
B18: 09.00 - 09.15 | C18: 2 | D18: 0 | E18: 1 | F18: 0 | G18: 0 | H18: 0 | I18: 2 | J18: 0 | K18: 0 | L18: 0 | M18: 50 | N18: 0 | O18: =SUM(C18:L18,N18) -> 5 | P18: =SUM(C18:N18) -> 55 | R18: 1500-1600 | S18: =SUM(C42:C45) -> 25 | T18: =SUM(D42:D45) -> 1 | U18: =SUM(E42:E45) -> 0 | V18: =SUM(F42:F45) -> 0 | W18: =SUM(G42:G45) -> 0 | X18: =SUM(H42:H45) -> 0 | Y18: =SUM(I42:I45) -> 3 | Z18: =SUM(J42:J45) -> 4 | ... AF18: =SUM(P42:P45) -> 264
B19: 09.15 - 09.30 | C19: 5 | D19: 0 | E19: 1 | F19: 0 | G19: 0 | H19: 0 | I19: 0 | J19: 2 | K19: 0 | L19: 0 | M19: 39 | N19: 0 | O19: =SUM(C19:L19,N19) -> 8 | P19: =SUM(C19:N19) -> 47 | R19: 1600-1700 | S19: =SUM(C46:C49) -> 28 | T19: =SUM(D46:D49) -> 0 | U19: =SUM(E46:E49) -> 2 | V19: =SUM(F46:F49) -> 2 | W19: =SUM(G46:G49) -> 0 | X19: =SUM(H46:H49) -> 1 | Y19: =SUM(I46:I49) -> 6 | Z19: =SUM(J46:J49) -> 1 | ... AF19: =SUM(P46:P49) -> 362
B20: 09.30 - 09.45 | C20: 4 | D20: 0 | E20: 0 | F20: 0 | G20: 0 | H20: 0 | I20: 0 | J20: 0 | K20: 0 | L20: 0 | M20: 69 | N20: 0 | O20: =SUM(C20:L20,N20) -> 4 | P20: =SUM(C20:N20) -> 73 | R20: 1700-1800 | S20: =SUM(C50:C53) -> 29 | T20: =SUM(D50:D53) -> 3 | U20: =SUM(E50:E53) -> 0 | V20: =SUM(F50:F53) -> 0 | W20: =SUM(G50:G53) -> 0 | X20: =SUM(H50:H53) -> 0 | Y20: =SUM(I50:I53) -> 2 | Z20: =SUM(J50:J53) -> 0 | ... AF20: =SUM(P50:P53) -> 236
B21: 09.45 - 10.00 | C21: 2 | D21: 0 | E21: 0 | F21: 0 | G21: 1 | H21: 0 | I21: 0 | J21: 0 | K21: 0 | L21: 1 | M21: 65 | N21: 0 | O21: =SUM(C21:L21,N21) -> 4 | P21: =SUM(C21:N21) -> 69 | R21: 1800-1900 | S21: =SUM(C54:C57) -> 19 | T21: =SUM(D54:D57) -> 0 | U21: =SUM(E54:E57) -> 0 | V21: =SUM(F54:F57) -> 1 | W21: =SUM(G54:G57) -> 0 | X21: =SUM(H54:H57) -> 0 | Y21: =SUM(I54:I57) -> 1 | Z21: =SUM(J54:J57) -> 2 | ... AF21: =SUM(P54:P57) -> 280
B22: 10.00 - 10.15 | C22: 5 | D22: 0 | E22: 1 | F22: 0 | G22: 0 | H22: 0 | I22: 0 | J22: 0 | K22: 0 | L22: 0 | M22: 61 | N22: 0 | O22: =SUM(C22:L22,N22) -> 6 | P22: =SUM(C22:N22) -> 67 | R22: AM Peak Hr | S22: =MAX(S10:S12) -> 13 | T22: =MAX(T10:T12) -> 0 | U22: =MAX(U10:U12) -> 2 | V22: =MAX(V10:V12) -> 0 | W22: =MAX(W10:W12) -> 1 | X22: =MAX(X10:X12) -> 2 | Y22: =MAX(Y10:Y12) -> 2 | Z22: =MAX(Z10:Z12) -> 2 | ... AF22: =MAX(AF10:AF12) -> 244
B23: 10.15 - 10.30 | C23: 2 | D23: 0 | E23: 0 | F23: 0 | G23: 0 | H23: 0 | I23: 1 | J23: 1 | K23: 0 | L23: 0 | M23: 46 | N23: 0 | O23: =SUM(C23:L23,N23) -> 4 | P23: =SUM(C23:N23) -> 50 | R23: IP Peak Hr | S23: =MAX(S13:S18) -> 25 | T23: =MAX(T13:T18) -> 1 | U23: =MAX(U13:U18) -> 3 | V23: =MAX(V13:V18) -> 2 | W23: =MAX(W13:W18) -> 1 | X23: =MAX(X13:X18) -> 1 | Y23: =MAX(Y13:Y18) -> 4 | Z23: =MAX(Z13:Z18) -> 5 | ... AF23: =MAX(AF13:AF18) -> 321
B24: 10.30 - 10.45 | C24: 2 | D24: 0 | E24: 0 | F24: 0 | G24: 0 | H24: 0 | I24: 0 | J24: 0 | K24: 0 | L24: 2 | M24: 55 | N24: 0 | O24: =SUM(C24:L24,N24) -> 4 | P24: =SUM(C24:N24) -> 59 | R24: PM Peak Hr | S24: =MAX(S19:S21) -> 29 | T24: =MAX(T19:T21) -> 3 | U24: =MAX(U19:U21) -> 2 | V24: =MAX(V19:V21) -> 2 | W24: =MAX(W19:W21) -> 0 | X24: =MAX(X19:X21) -> 1 | Y24: =MAX(Y19:Y21) -> 6 | Z24: =MAX(Z19:Z21) -> 2 | ... AF24: =MAX(AF19:AF21) -> 362
B25: 10.45 - 11.00 | C25: 2 | D25: 0 | E25: 2 | F25: 0 | G25: 0 | H25: 0 | I25: 0 | J25: 0 | K25: 0 | L25: 5 | M25: 48 | N25: 0 | O25: =SUM(C25:L25,N25) -> 9 | P25: =SUM(C25:N25) -> 57 | R25: AM Period | S25: =SUM(S10:S12) -> 30 | T25: =SUM(T10:T12) -> 0 | U25: =SUM(U10:U12) -> 3 | V25: =SUM(V10:V12) -> 0 | W25: =SUM(W10:W12) -> 1 | X25: =SUM(X10:X12) -> 3 | Y25: =SUM(Y10:Y12) -> 2 | Z25: =SUM(Z10:Z12) -> 4 | ... AF25: =SUM(AF10:AF12) -> 479
B26: 11.00 - 11.15 | C26: 6 | D26: 0 | E26: 1 | F26: 0 | G26: 1 | H26: 0 | I26: 2 | J26: 2 | K26: 1 | L26: 2 | M26: 58 | N26: 0 | O26: =SUM(C26:L26,N26) -> 15 | P26: =SUM(C26:N26) -> 73 | R26: IP Period | S26: =SUM(S13:S18) -> 119 | T26: =SUM(T13:T18) -> 1 | U26: =SUM(U13:U18) -> 6 | V26: =SUM(V13:V18) -> 3 | W26: =SUM(W13:W18) -> 1 | X26: =SUM(X13:X18) -> 3 | Y26: =SUM(Y13:Y18) -> 13 | Z26: =SUM(Z13:Z18) -> 15 | ... AF26: =SUM(AF13:AF18) -> 1640
B27: 11.15 - 11.30 | C27: 3 | D27: 0 | E27: 0 | F27: 0 | G27: 0 | H27: 0 | I27: 1 | J27: 0 | K27: 0 | L27: 2 | M27: 74 | N27: 0 | O27: =SUM(C27:L27,N27) -> 6 | P27: =SUM(C27:N27) -> 80 | R27: PM Period | S27: =SUM(S19:S21) -> 76 | T27: =SUM(T19:T21) -> 3 | U27: =SUM(U19:U21) -> 2 | V27: =SUM(V19:V21) -> 3 | W27: =SUM(W19:W21) -> 0 | X27: =SUM(X19:X21) -> 1 | Y27: =SUM(Y19:Y21) -> 9 | Z27: =SUM(Z19:Z21) -> 3 | ... AF27: =SUM(AF19:AF21) -> 878
B28: 11.30 - 11.45 | C28: 7 | D28: 0 | E28: 0 | F28: 0 | G28: 0 | H28: 1 | I28: 1 | J28: 0 | K28: 0 | L28: 1 | M28: 81 | N28: 0 | O28: =SUM(C28:L28,N28) -> 10 | P28: =SUM(C28:N28) -> 91 | R28: 12 Hours | S28: =SUM(S10:S21) -> 225 | T28: =SUM(T10:T21) -> 4 | U28: =SUM(U10:U21) -> 11 | V28: =SUM(V10:V21) -> 6 | W28: =SUM(W10:W21) -> 2 | X28: =SUM(X10:X21) -> 7 | Y28: =SUM(Y10:Y21) -> 24 | Z28: =SUM(Z10:Z21) -> 22 | ... AF28: =SUM(AF10:AF21) -> 2997
B29: 11.45 - 12.00 | C29: 5 | D29: 0 | E29: 0 | F29: 0 | G29: 0 | H29: 0 | I29: 0 | J29: 0 | K29: 0 | L29: 0 | M29: 41 | N29: 0 | O29: =SUM(C29:L29,N29) -> 5 | P29: =SUM(C29:N29) -> 46
B30: 12.00 - 12.15 | C30: 2 | D30: 0 | E30: 0 | F30: 0 | G30: 0 | H30: 0 | I30: 0 | J30: 1 | K30: 0 | L30: 0 | M30: 44 | N30: 0 | O30: =SUM(C30:L30,N30) -> 3 | P30: =SUM(C30:N30) -> 47
B31: 12.15 - 12.30 | C31: 1 | D31: 0 | E31: 0 | F31: 0 | G31: 0 | H31: 0 | I31: 1 | J31: 0 | K31: 0 | L31: 0 | M31: 52 | N31: 0 | O31: =SUM(C31:L31,N31) -> 2 | P31: =SUM(C31:N31) -> 54
B32: 12.30 - 12.45 | C32: 8 | D32: 0 | E32: 0 | F32: 0 | G32: 0 | H32: 0 | I32: 0 | J32: 0 | K32: 0 | L32: 0 | M32: 43 | N32: 0 | O32: =SUM(C32:L32,N32) -> 8 | P32: =SUM(C32:N32) -> 51
B33: 12.45 - 13.00 | C33: 4 | D33: 0 | E33: 0 | F33: 0 | G33: 0 | H33: 0 | I33: 0 | J33: 1 | K33: 2 | L33: 0 | M33: 60 | N33: 0 | O33: =SUM(C33:L33,N33) -> 7 | P33: =SUM(C33:N33) -> 67
B34: 13.00 - 13.15 | C34: 5 | D34: 0 | E34: 1 | F34: 0 | G34: 0 | H34: 1 | I34: 0 | J34: 2 | K34: 0 | L34: 1 | M34: 66 | N34: 0 | O34: =SUM(C34:L34,N34) -> 10 | P34: =SUM(C34:N34) -> 76
B35: 13.15 - 13.30 | C35: 8 | D35: 0 | E35: 0 | F35: 0 | G35: 0 | H35: 0 | I35: 1 | J35: 1 | K35: 0 | L35: 0 | M35: 61 | N35: 0 | O35: =SUM(C35:L35,N35) -> 10 | P35: =SUM(C35:N35) -> 71
B36: 13.30 - 13.45 | C36: 8 | D36: 0 | E36: 0 | F36: 1 | G36: 0 | H36: 0 | I36: 0 | J36: 1 | K36: 0 | L36: 2 | M36: 89 | N36: 0 | O36: =SUM(C36:L36,N36) -> 12 | P36: =SUM(C36:N36) -> 101
B37: 13.45 - 14.00 | C37: 2 | D37: 0 | E37: 0 | F37: 0 | G37: 0 | H37: 0 | I37: 0 | J37: 1 | K37: 0 | L37: 0 | M37: 62 | N37: 0 | O37: =SUM(C37:L37,N37) -> 3 | P37: =SUM(C37:N37) -> 65
B38: 14.00 - 14.15 | C38: 5 | D38: 0 | E38: 0 | F38: 0 | G38: 0 | H38: 0 | I38: 1 | J38: 0 | K38: 0 | L38: 0 | M38: 52 | N38: 0 | O38: =SUM(C38:L38,N38) -> 6 | P38: =SUM(C38:N38) -> 58
B39: 14.15 - 14.30 | C39: 9 | D39: 0 | E39: 1 | F39: 0 | G39: 0 | H39: 1 | I39: 0 | J39: 0 | K39: 0 | L39: 1 | M39: 98 | N39: 0 | O39: =SUM(C39:L39,N39) -> 12 | P39: =SUM(C39:N39) -> 110
B40: 14.30 - 14.45 | C40: 3 | D40: 0 | E40: 0 | F40: 0 | G40: 0 | H40: 0 | I40: 2 | J40: 1 | K40: 0 | L40: 4 | M40: 57 | N40: 0 | O40: =SUM(C40:L40,N40) -> 10 | P40: =SUM(C40:N40) -> 67
... B57: 18.45 - 19.00 | C57: 5 | D57: 0 | E57: 0 | F57: 0 | G57: 0 | H57: 0 | I57: 1 | J57: 0 | K57: 0 | L57: 0 | M57: 65 | N57: 0 | O57: =SUM(C57:L57,N57) -> 6 | P57: =SUM(C57:N57) -> 71
B58: Totals | C58: =SUM(C10:C57) -> 225 | D58: =SUM(D10:D57) -> 4 | E58: =SUM(E10:E57) -> 11 | F58: =SUM(F10:F57) -> 6 | G58: =SUM(G10:G57) -> 2 | H58: =SUM(H10:H57) -> 7 | I58: =SUM(I10:I57) -> 24 | J58: =SUM(J10:J57) -> 22 | ... P58: =SUM(P10:P57) -> 2997
...

Sheet 25.10.19 PONDWE-KASESE-24h
B1: Consultancy services for Preparation of Expressway Development Master Plan (EDMP) for Uganda
B2: MANUAL CLASSIFIED COUNT (MCC)
B3: ROAD NAME: | C3: ='26.10 KASESE-PONDWE'!C3:G3 -> MCC - C4 - STN137 - KASESE ROAD
C5: Date | D5: 25.10.19 | F5: Location | G5: KABUYIRI | J5: Surveyor | K5: NAKIWUGE ALLEN
C6: Dir. From | D6: PONDWE | F6: Dir. To | G6: KASESE | J6: Supervisor | K6: GODFREY
B8: Time / Veh Type | R8: SUMMARY TRAFFIC VOLUMES
C9: 1. Car | D9: 2. Station Wagon | E9: 3. Pickups | F9: 4. Minibus, matatu | G9: 5. Medium bus | H9: 6. Large Bus | I9: 7. Light Truck | J9: 8. Medium Truck | K9: 9. Heavy truck | L9: 10. Truck Trailer | M9: 11. Motor cycles | N9: 12. Tractors | O9: Total Excl M/Cycles | P9: Total All | R9: Time | S9: 1. Car | T9: 2. Station Wagon | U9: 3. Pickups | V9: 4. Minibus, matatu | W9: 5. Medium bus | X9: 6. Large Bus | Y9: 7. Light Truck | Z9: 8. Medium Truck | AA9: 9. Heavy truck | AB9: 10. Truck Trailer | AC9: 11. Motorcycles | AD9: 12. Tractors, Graders | AE9: Total Excl M/ Cycles | AF9: Total All
B10: 07.00 - 07.15 | C10: 3 | D10: 0 | E10: 0 | F10: 0 | G10: 0 | H10: 0 | I10: 0 | J10: 0 | K10: 0 | L10: 0 | M10: 52 | N10: 0 | O10: =SUM(C10:L10,N10) -> 3 | P10: =SUM(C10:N10) -> 55 | R10: 0700-0800 | S10: =SUM(C10:C13) -> 19 | T10: =SUM(D10:D13) -> 0 | U10: =SUM(E10:E13) -> 0 | V10: =SUM(F10:F13) -> 3 | W10: =SUM(G10:G13) -> 0 | X10: =SUM(H10:H13) -> 2 | Y10: =SUM(I10:I13) -> 2 | Z10: =SUM(J10:J13) -> 0 | ... AF10: =SUM(P10:P13) -> 468
B11: 07.15 - 07.30 | C11: 7 | D11: 0 | E11: 0 | F11: 1 | G11: 0 | H11: 1 | I11: 1 | J11: 0 | K11: 0 | L11: 0 | M11: 102 | N11: 0 | O11: =SUM(C11:L11,N11) -> 10 | P11: =SUM(C11:N11) -> 112 | R11: 0800-0900 | S11: =SUM(C14:C17) -> 23 | T11: =SUM(D14:D17) -> 1 | U11: =SUM(E14:E17) -> 1 | V11: =SUM(F14:F17) -> 2 | W11: =SUM(G14:G17) -> 0 | X11: =SUM(H14:H17) -> 0 | Y11: =SUM(I14:I17) -> 3 | Z11: =SUM(J14:J17) -> 1 | ... AF11: =SUM(P14:P17) -> 465
B12: 07.30 - 07.45 | C12: 5 | D12: 0 | E12: 0 | F12: 0 | G12: 0 | H12: 0 | I12: 1 | J12: 0 | K12: 0 | L12: 0 | M12: 135 | N12: 0 | O12: =SUM(C12:L12,N12) -> 6 | P12: =SUM(C12:N12) -> 141 | R12: 0900-1000 | S12: =SUM(C18:C21) -> 21 | T12: =SUM(D18:D21) -> 1 | U12: =SUM(E18:E21) -> 3 | V12: =SUM(F18:F21) -> 1 | W12: =SUM(G18:G21) -> 0 | X12: =SUM(H18:H21) -> 1 | Y12: =SUM(I18:I21) -> 5 | Z12: =SUM(J18:J21) -> 1 | ... AF12: =SUM(P18:P21) -> 355
B13: 07.45 - 08.00 | C13: 4 | D13: 0 | E13: 0 | F13: 2 | G13: 0 | H13: 1 | I13: 0 | J13: 0 | K13: 0 | L13: 0 | M13: 153 | N13: 0 | O13: =SUM(C13:L13,N13) -> 7 | P13: =SUM(C13:N13) -> 160 | R13: 1000-1100 | S13: =SUM(C22:C25) -> 24 | T13: =SUM(D22:D25) -> 2 | U13: =SUM(E22:E25) -> 2 | V13: =SUM(F22:F25) -> 0 | W13: =SUM(G22:G25) -> 0 | X13: =SUM(H22:H25) -> 0 | Y13: =SUM(I22:I25) -> 10 | Z13: =SUM(J22:J25) -> 1 | ... AF13: =SUM(P22:P25) -> 354
B14: 08.00 - 08.15 | C14: 2 | D14: 0 | E14: 0 | F14: 0 | G14: 0 | H14: 0 | I14: 0 | J14: 0 | K14: 0 | L14: 0 | M14: 135 | N14: 0 | O14: =SUM(C14:L14,N14) -> 2 | P14: =SUM(C14:N14) -> 137 | R14: 1100-1200 | S14: =SUM(C26:C29) -> 41 | T14: =SUM(D26:D29) -> 1 | U14: =SUM(E26:E29) -> 3 | V14: =SUM(F26:F29) -> 1 | W14: =SUM(G26:G29) -> 0 | X14: =SUM(H26:H29) -> 1 | Y14: =SUM(I26:I29) -> 10 | Z14: =SUM(J26:J29) -> 2 | ... AF14: =SUM(P26:P29) -> 499
B15: 08.15 - 08.30 | C15: 8 | D15: 0 | E15: 0 | F15: 1 | G15: 0 | H15: 0 | I15: 3 | J15: 0 | K15: 0 | L15: 0 | M15: 98 | N15: 0 | O15: =SUM(C15:L15,N15) -> 12 | P15: =SUM(C15:N15) -> 110 | R15: 1200-1300 | S15: =SUM(C30:C33) -> 20 | T15: =SUM(D30:D33) -> 3 | U15: =SUM(E30:E33) -> 3 | V15: =SUM(F30:F33) -> 0 | W15: =SUM(G30:G33) -> 1 | X15: =SUM(H30:H33) -> 1 | Y15: =SUM(I30:I33) -> 8 | Z15: =SUM(J30:J33) -> 1 | ... AF15: =SUM(P30:P33) -> 316
B16: 08.30 - 08.45 | C16: 7 | D16: 0 | E16: 0 | F16: 0 | G16: 0 | H16: 0 | I16: 0 | J16: 1 | K16: 0 | L16: 0 | M16: 102 | N16: 0 | O16: =SUM(C16:L16,N16) -> 8 | P16: =SUM(C16:N16) -> 110 | R16: 1300-1400 | S16: =SUM(C34:C37) -> 46 | T16: =SUM(D34:D37) -> 7 | U16: =SUM(E34:E37) -> 4 | V16: =SUM(F34:F37) -> 2 | W16: =SUM(G34:G37) -> 0 | X16: =SUM(H34:H37) -> 1 | Y16: =SUM(I34:I37) -> 9 | Z16: =SUM(J34:J37) -> 2 | ... AF16: =SUM(P34:P37) -> 398
B17: 08.45 - 9.00 | C17: 6 | D17: 1 | E17: 1 | F17: 1 | G17: 0 | H17: 0 | I17: 0 | J17: 0 | K17: 1 | L17: 0 | M17: 98 | N17: 0 | O17: =SUM(C17:L17,N17) -> 10 | P17: =SUM(C17:N17) -> 108 | R17: 1400-1500 | S17: =SUM(C38:C41) -> 26 | T17: =SUM(D38:D41) -> 3 | U17: =SUM(E38:E41) -> 3 | V17: =SUM(F38:F41) -> 3 | W17: =SUM(G38:G41) -> 0 | X17: =SUM(H38:H41) -> 2 | Y17: =SUM(I38:I41) -> 5 | Z17: =SUM(J38:J41) -> 4 | ... AF17: =SUM(P38:P41) -> 401
B18: 09.00 - 09.15 | C18: 6 | D18: 0 | E18: 1 | F18: 0 | G18: 0 | H18: 0 | I18: 0 | J18: 0 | K18: 0 | L18: 0 | M18: 94 | N18: 0 | O18: =SUM(C18:L18,N18) -> 7 | P18: =SUM(C18:N18) -> 101 | R18: 1500-1600 | S18: =SUM(C42:C45) -> 22 | T18: =SUM(D42:D45) -> 2 | U18: =SUM(E42:E45) -> 2 | V18: =SUM(F42:F45) -> 12 | W18: =SUM(G42:G45) -> 0 | X18: =SUM(H42:H45) -> 0 | Y18: =SUM(I42:I45) -> 4 | Z18: =SUM(J42:J45) -> 2 | ... AF18: =SUM(P42:P45) -> 380
B19: 09.15 - 09.30 | C19: 4 | D19: 0 | E19: 0 | F19: 1 | G19: 0 | H19: 0 | I19: 2 | J19: 0 | K19: 0 | L19: 0 | M19: 80 | N19: 0 | O19: =SUM(C19:L19,N19) -> 7 | P19: =SUM(C19:N19) -> 87 | R19: 1600-1700 | S19: =SUM(C46:C49) -> 55 | T19: =SUM(D46:D49) -> 3 | U19: =SUM(E46:E49) -> 2 | V19: =SUM(F46:F49) -> 3 | W19: =SUM(G46:G49) -> 0 | X19: =SUM(H46:H49) -> 0 | Y19: =SUM(I46:I49) -> 8 | Z19: =SUM(J46:J49) -> 3 | ... AF19: =SUM(P46:P49) -> 364
B20: 09.30 - 09.45 | C20: 6 | D20: 0 | E20: 1 | F20: 0 | G20: 0 | H20: 0 | I20: 2 | J20: 0 | K20: 1 | L20: 6 | M20: 75 | N20: 0 | O20: =SUM(C20:L20,N20) -> 16 | P20: =SUM(C20:N20) -> 91 | R20: 1700-1800 | S20: =SUM(C50:C53) -> 36 | T20: =SUM(D50:D53) -> 2 | U20: =SUM(E50:E53) -> 1 | V20: =SUM(F50:F53) -> 5 | W20: =SUM(G50:G53) -> 0 | X20: =SUM(H50:H53) -> 0 | Y20: =SUM(I50:I53) -> 7 | Z20: =SUM(J50:J53) -> 2 | ... AF20: =SUM(P50:P53) -> 398
B21: 09.45 - 10.00 | C21: 5 | D21: 1 | E21: 1 | F21: 0 | G21: 0 | H21: 1 | I21: 1 | J21: 1 | K21: 0 | L21: 0 | M21: 66 | N21: 0 | O21: =SUM(C21:L21,N21) -> 10 | P21: =SUM(C21:N21) -> 76 | R21: 1800-1900 | S21: =SUM(C54:C57) -> 59 | T21: =SUM(D54:D57) -> 1 | U21: =SUM(E54:E57) -> 1 | V21: =SUM(F54:F57) -> 8 | W21: =SUM(G54:G57) -> 0 | X21: =SUM(H54:H57) -> 0 | Y21: =SUM(I54:I57) -> 7 | Z21: =SUM(J54:J57) -> 7 | ... AF21: =SUM(P54:P57) -> 634
B22: 10.00 - 10.15 | C22: 6 | D22: 0 | E22: 1 | F22: 0 | G22: 0 | H22: 0 | I22: 0 | J22: 0 | K22: 0 | L22: 0 | M22: 59 | N22: 0 | O22: =SUM(C22:L22,N22) -> 7 | P22: =SUM(C22:N22) -> 66 | R22: 1900-2000 | S22: =SUM(C58:C61) -> 36 | T22: =SUM(D58:D61) -> 3 | U22: =SUM(E58:E61) -> 1 | V22: =SUM(F58:F61) -> 5 | W22: =SUM(G58:G61) -> 1 | X22: =SUM(H58:H61) -> 3 | Y22: =SUM(I58:I61) -> 5 | Z22: =SUM(J58:J61) -> 4 | ... AF22: =SUM(P58:P61) -> 422
B23: 10.15 - 10.30 | C23: 6 | D23: 0 | E23: 1 | F23: 0 | G23: 0 | H23: 0 | I23: 2 | J23: 0 | K23: 0 | L23: 0 | M23: 72 | N23: 0 | O23: =SUM(C23:L23,N23) -> 9 | P23: =SUM(C23:N23) -> 81 | R23: 2000-2100 | S23: =SUM(C62:C65) -> 22 | T23: =SUM(D62:D65) -> 1 | U23: =SUM(E62:E65) -> 0 | V23: =SUM(F62:F65) -> 0 | W23: =SUM(G62:G65) -> 0 | X23: =SUM(H62:H65) -> 3 | Y23: =SUM(I62:I65) -> 1 | Z23: =SUM(J62:J65) -> 4 | ... AF23: =SUM(P62:P65) -> 187
B24: 10.30 - 10.45 | C24: 8 | D24: 2 | E24: 0 | F24: 0 | G24: 0 | H24: 0 | I24: 5 | J24: 1 | K24: 0 | L24: 1 | M24: 100 | N24: 0 | O24: =SUM(C24:L24,N24) -> 17 | P24: =SUM(C24:N24) -> 117 | R24: 2100-2200 | S24: =SUM(C66:C69) -> 12 | T24: =SUM(D66:D69) -> 0 | U24: =SUM(E66:E69) -> 0 | V24: =SUM(F66:F69) -> 0 | W24: =SUM(G66:G69) -> 0 | X24: =SUM(H66:H69) -> 1 | Y24: =SUM(I66:I69) -> 1 | Z24: =SUM(J66:J69) -> 0 | ... AF24: =SUM(P66:P69) -> 60
B25: 10.45 - 11.00 | C25: 4 | D25: 0 | E25: 0 | F25: 0 | G25: 0 | H25: 0 | I25: 3 | J25: 0 | K25: 0 | L25: 0 | M25: 83 | N25: 0 | O25: =SUM(C25:L25,N25) -> 7 | P25: =SUM(C25:N25) -> 90 | R25: 2200-2300 | S25: =SUM(C70:C73) -> 11 | T25: =SUM(D70:D73) -> 0 | U25: =SUM(E70:E73) -> 1 | V25: =SUM(F70:F73) -> 0 | W25: =SUM(G70:G73) -> 0 | X25: =SUM(H70:H73) -> 0 | Y25: =SUM(I70:I73) -> 0 | Z25: =SUM(J70:J73) -> 0 | ... AF25: =SUM(P70:P73) -> 46
B26: 11.00 - 11.15 | C26: 5 | D26: 1 | E26: 0 | F26: 0 | G26: 0 | H26: 0 | I26: 3 | J26: 1 | K26: 0 | L26: 0 | M26: 107 | N26: 0 | O26: =SUM(C26:L26,N26) -> 10 | P26: =SUM(C26:N26) -> 117 | R26: 2300-0000 | S26: =SUM(C74:C77) -> 0 | T26: =SUM(D74:D77) -> 0 | U26: =SUM(E74:E77) -> 0 | V26: =SUM(F74:F77) -> 0 | W26: =SUM(G74:G77) -> 0 | X26: =SUM(H74:H77) -> 0 | Y26: =SUM(I74:I77) -> 0 | Z26: =SUM(J74:J77) -> 0 | ... AF26: =SUM(P74:P77) -> 16
B27: 11.15 - 11.30 | C27: 9 | D27: 0 | E27: 0 | F27: 1 | G27: 0 | H27: 0 | I27: 3 | J27: 0 | K27: 0 | L27: 0 | M27: 157 | N27: 0 | O27: =SUM(C27:L27,N27) -> 13 | P27: =SUM(C27:N27) -> 170 | R27: 0000-0100 | S27: =SUM(C78:C81) -> 1 | T27: =SUM(D78:D81) -> 1 | U27: =SUM(E78:E81) -> 0 | V27: =SUM(F78:F81) -> 0 | W27: =SUM(G78:G81) -> 0 | X27: =SUM(H78:H81) -> 0 | Y27: =SUM(I78:I81) -> 0 | Z27: =SUM(J78:J81) -> 0 | ... AF27: =SUM(P78:P81) -> 16
B28: 11.30 - 11.45 | C28: 16 | D28: 0 | E28: 2 | F28: 0 | G28: 0 | H28: 1 | I28: 1 | J28: 1 | K28: 0 | L28: 3 | M28: 101 | N28: 0 | O28: =SUM(C28:L28,N28) -> 24 | P28: =SUM(C28:N28) -> 125 | R28: 0100-0200 | S28: =SUM(C82:C85) -> 1 | T28: =SUM(D82:D85) -> 0 | U28: =SUM(E82:E85) -> 0 | V28: =SUM(F82:F85) -> 0 | W28: =SUM(G82:G85) -> 0 | X28: =SUM(H82:H85) -> 0 | Y28: =SUM(I82:I85) -> 0 | Z28: =SUM(J82:J85) -> 0 | ... AF28: =SUM(P82:P85) -> 8
B29: 11.45 - 12.00 | C29: 11 | D29: 0 | E29: 1 | F29: 0 | G29: 0 | H29: 0 | I29: 3 | J29: 0 | K29: 0 | L29: 0 | M29: 72 | N29: 0 | O29: =SUM(C29:L29,N29) -> 15 | P29: =SUM(C29:N29) -> 87 | R29: 0200-0300 | S29: =SUM(C86:C89) -> 2 | T29: =SUM(D86:D89) -> 1 | U29: =SUM(E86:E89) -> 0 | V29: =SUM(F86:F89) -> 0 | W29: =SUM(G86:G89) -> 0 | X29: =SUM(H86:H89) -> 0 | Y29: =SUM(I86:I89) -> 0 | Z29: =SUM(J86:J89) -> 0 | ... AF29: =SUM(P86:P89) -> 10
B30: 12.00 - 12.15 | C30: 6 | D30: 0 | E30: 0 | F30: 0 | G30: 1 | H30: 0 | I30: 3 | J30: 1 | K30: 0 | L30: 0 | M30: 60 | N30: 0 | O30: =SUM(C30:L30,N30) -> 11 | P30: =SUM(C30:N30) -> 71 | R30: 0300-0400 | S30: =SUM(C90:C93) -> 1 | T30: =SUM(D90:D93) -> 0 | U30: =SUM(E90:E93) -> 0 | V30: =SUM(F90:F93) -> 0 | W30: =SUM(G90:G93) -> 0 | X30: =SUM(H90:H93) -> 0 | Y30: =SUM(I90:I93) -> 0 | Z30: =SUM(J90:J93) -> 0 | ... AF30: =SUM(P90:P93) -> 35
