Workbook

Sheet 31.07 Goli-Nebbi
B1: Consultancy services for Preparation of Expressway Development Master Plan (EDMP) for Uganda
B2: MANUAL CLASSIFIED COUNT (MCC)
B3: ROAD NAME: | C3: MCC - C4 - STN138 - NEBBI-GOLI ROAD
C5: Date | D5: 31.07.19 | F5: Location | G5: Goli | J5: Surveyor | K5: Moreen
C6: Dir. From | D6: Goli | F6: Dir. To | G6: Nebbi | J6: Supervisor | K6: Herbert
B8: Time / Veh Type | R8: SUMMARY TRAFFIC VOLUMES
C9: 1. Car | D9: 2. Station Wagon | E9: 3. Pickups | F9: 4. Minibus, matatu | G9: 5. Medium bus | H9: 6. Large Bus | I9: 7. Light Truck | J9: 8. Medium Truck | K9: 9. Heavy truck | L9: 10. Truck Trailer | M9: 11. Motor cycles | N9: 12. Tractors | O9: Total Excl M/Cycles | P9: Total All | R9: Time | S9: 1. Car | T9: 2. Station Wagon | U9: 3. Pickups | V9: 4. Minibus, matatu | W9: 5. Medium bus | X9: 6. Large Bus | Y9: 7. Light Truck | Z9: 8. Medium Truck | AA9: 9. Heavy truck | AB9: 10. Truck Trailer | AC9: 11. Motorcycles | AD9: 12. Tractors, Graders | AE9: Total Excl M/ Cycles | AF9: Total All
B10: 07.00 - 07.15 | C10: 0 | D10: 0 | E10: 0 | F10: 0 | G10: 0 | H10: 0 | I10: 0 | J10: 0 | K10: 0 | L10: =ROUNDDOWN((0.4*E10),0) -> 0 | M10: 6 | N10: 0 | O10: =SUM(C10:L10,N10) -> 0 | P10: =SUM(C10:N10) -> 6 | R10: 0700-0800 | S10: =SUM(C10:C13) -> 6 | T10: =SUM(D10:D13) -> 0 | U10: =SUM(E10:E13) -> 1 | V10: =SUM(F10:F13) -> 1 | W10: =SUM(G10:G13) -> 0 | X10: =SUM(H10:H13) -> 0 | Y10: =SUM(I10:I13) -> 2 | Z10: =SUM(J10:J13) -> 1 | ... AF10: =SUM(P10:P13) -> 56
B11: 07.15 - 07.30 | C11: 1 | D11: 0 | E11: 0 | F11: 0 | G11: 0 | H11: 0 | I11: 1 | J11: 0 | K11: 0 | L11: 0 | M11: 6 | N11: 0 | O11: =SUM(C11:L11,N11) -> 2 | P11: =SUM(C11:N11) -> 8 | R11: 0800-0900 | S11: =SUM(C14:C17) -> 8 | T11: =SUM(D14:D17) -> 1 | U11: =SUM(E14:E17) -> 2 | V11: =SUM(F14:F17) -> 1 | W11: =SUM(G14:G17) -> 0 | X11: =SUM(H14:H17) -> 0 | Y11: =SUM(I14:I17) -> 1 | Z11: =SUM(J14:J17) -> 2 | ... AF11: =SUM(P14:P17) -> 68
B12: 07.30 - 07.45 | C12: 3 | D12: 0 | E12: 0 | F12: 1 | G12: 0 | H12: 0 | I12: 1 | J12: 0 | K12: 0 | L12: 0 | M12: 15 | N12: 0 | O12: =SUM(C12:L12,N12) -> 5 | P12: =SUM(C12:N12) -> 20 | R12: 0900-1000 | S12: =SUM(C18:C21) -> 8 | T12: =SUM(D18:D21) -> 2 | U12: =SUM(E18:E21) -> 5 | V12: =SUM(F18:F21) -> 4 | W12: =SUM(G18:G21) -> 0 | X12: =SUM(H18:H21) -> 0 | Y12: =SUM(I18:I21) -> 2 | Z12: =SUM(J18:J21) -> 1 | ... AF12: =SUM(P18:P21) -> 88
B13: 07.45 - 08.00 | C13: 2 | D13: 0 | E13: 1 | F13: 0 | G13: 0 | H13: 0 | I13: 0 | J13: 1 | K13: 2 | L13: 0 | M13: 16 | N13: 0 | O13: =SUM(C13:L13,N13) -> 6 | P13: =SUM(C13:N13) -> 22 | R13: 1000-1100 | S13: =SUM(C22:C25) -> 5 | T13: =SUM(D22:D25) -> 1 | U13: =SUM(E22:E25) -> 3 | V13: =SUM(F22:F25) -> 1 | W13: =SUM(G22:G25) -> 0 | X13: =SUM(H22:H25) -> 0 | Y13: =SUM(I22:I25) -> 0 | Z13: =SUM(J22:J25) -> 4 | ... AF13: =SUM(P22:P25) -> 77
B14: 08.00 - 08.15 | C14: 1 | D14: 0 | E14: 0 | F14: 1 | G14: 0 | H14: 0 | I14: 0 | J14: 1 | K14: 0 | L14: 0 | M14: 6 | N14: 0 | O14: =SUM(C14:L14,N14) -> 3 | P14: =SUM(C14:N14) -> 9 | R14: 1100-1200 | S14: =SUM(C26:C29) -> 4 | T14: =SUM(D26:D29) -> 2 | U14: =SUM(E26:E29) -> 4 | V14: =SUM(F26:F29) -> 1 | W14: =SUM(G26:G29) -> 0 | X14: =SUM(H26:H29) -> 0 | Y14: =SUM(I26:I29) -> 2 | Z14: =SUM(J26:J29) -> 0 | ... AF14: =SUM(P26:P29) -> 55
B15: 08.15 - 08.30 | C15: 2 | D15: 1 | E15: 2 | F15: 0 | G15: 0 | H15: 0 | I15: 0 | J15: 0 | K15: 0 | L15: 0 | M15: 10 | N15: 0 | O15: =SUM(C15:L15,N15) -> 5 | P15: =SUM(C15:N15) -> 15 | R15: 1200-1300 | S15: =SUM(C30:C33) -> 4 | T15: =SUM(D30:D33) -> 0 | U15: =SUM(E30:E33) -> 2 | V15: =SUM(F30:F33) -> 1 | W15: =SUM(G30:G33) -> 2 | X15: =SUM(H30:H33) -> 0 | Y15: =SUM(I30:I33) -> 0 | Z15: =SUM(J30:J33) -> 1 | ... AF15: =SUM(P30:P33) -> 63
B16: 08.30 - 08.45 | C16: 2 | D16: 0 | E16: 0 | F16: 0 | G16: 0 | H16: 0 | I16: 1 | J16: 1 | K16: 1 | L16: 0 | M16: 18 | N16: 0 | O16: =SUM(C16:L16,N16) -> 5 | P16: =SUM(C16:N16) -> 23 | R16: 1300-1400 | S16: =SUM(C34:C37) -> 2 | T16: =SUM(D34:D37) -> 0 | U16: =SUM(E34:E37) -> 1 | V16: =SUM(F34:F37) -> 1 | W16: =SUM(G34:G37) -> 0 | X16: =SUM(H34:H37) -> 0 | Y16: =SUM(I34:I37) -> 2 | Z16: =SUM(J34:J37) -> 0 | ... AF16: =SUM(P34:P37) -> 61
B17: 08.45 - 9.00 | C17: 3 | D17: 0 | E17: 0 | F17: 0 | G17: 0 | H17: 0 | I17: 0 | J17: 0 | K17: 0 | L17: 0 | M17: 18 | N17: 0 | O17: =SUM(C17:L17,N17) -> 3 | P17: =SUM(C17:N17) -> 21 | R17: 1400-1500 | S17: =SUM(C38:C41) -> 3 | T17: =SUM(D38:D41) -> 0 | U17: =SUM(E38:E41) -> 1 | V17: =SUM(F38:F41) -> 5 | W17: =SUM(G38:G41) -> 0 | X17: =SUM(H38:H41) -> 0 | Y17: =SUM(I38:I41) -> 1 | Z17: =SUM(J38:J41) -> 5 | ... AF17: =SUM(P38:P41) -> 53
B18: 09.00 - 09.15 | C18: 3 | D18: 1 | E18: 2 | F18: 0 | G18: 0 | H18: 0 | I18: 1 | J18: 0 | K18: 0 | L18: 3 | M18: 8 | N18: 0 | O18: =SUM(C18:L18,N18) -> 10 | P18: =SUM(C18:N18) -> 18 | R18: 1500-1600 | S18: =SUM(C42:C45) -> 9 | T18: =SUM(D42:D45) -> 0 | U18: =SUM(E42:E45) -> 2 | V18: =SUM(F42:F45) -> 2 | W18: =SUM(G42:G45) -> 0 | X18: =SUM(H42:H45) -> 0 | Y18: =SUM(I42:I45) -> 5 | Z18: =SUM(J42:J45) -> 0 | ... AF18: =SUM(P42:P45) -> 73
B19: 09.15 - 09.30 | C19: 1 | D19: 0 | E19: 1 | F19: 3 | G19: 0 | H19: 0 | I19: 1 | J19: 1 | K19: 3 | L19: 1 | M19: 16 | N19: 0 | O19: =SUM(C19:L19,N19) -> 11 | P19: =SUM(C19:N19) -> 27 | R19: 1600-1700 | S19: =SUM(C46:C49) -> 5 | T19: =SUM(D46:D49) -> 1 | U19: =SUM(E46:E49) -> 2 | V19: =SUM(F46:F49) -> 0 | W19: =SUM(G46:G49) -> 1 | X19: =SUM(H46:H49) -> 0 | Y19: =SUM(I46:I49) -> 3 | Z19: =SUM(J46:J49) -> 1 | ... AF19: =SUM(P46:P49) -> 54
B20: 09.30 - 09.45 | C20: 3 | D20: 0 | E20: 1 | F20: 1 | G20: 0 | H20: 0 | I20: 0 | J20: 0 | K20: 0 | L20: 0 | M20: 19 | N20: 0 | O20: =SUM(C20:L20,N20) -> 5 | P20: =SUM(C20:N20) -> 24 | R20: 1700-1800 | S20: =SUM(C50:C53) -> 6 | T20: =SUM(D50:D53) -> 1 | U20: =SUM(E50:E53) -> 4 | V20: =SUM(F50:F53) -> 3 | W20: =SUM(G50:G53) -> 0 | X20: =SUM(H50:H53) -> 0 | Y20: =SUM(I50:I53) -> 1 | Z20: =SUM(J50:J53) -> 1 | ... AF20: =SUM(P50:P53) -> 87
B21: 09.45 - 10.00 | C21: 1 | D21: 1 | E21: 1 | F21: 0 | G21: 0 | H21: 0 | I21: 0 | J21: 0 | K21: 0 | L21: 0 | M21: 16 | N21: 0 | O21: =SUM(C21:L21,N21) -> 3 | P21: =SUM(C21:N21) -> 19 | R21: 1800-1900 | S21: =SUM(C54:C57) -> 4 | T21: =SUM(D54:D57) -> 2 | U21: =SUM(E54:E57) -> 5 | V21: =SUM(F54:F57) -> 3 | W21: =SUM(G54:G57) -> 1 | X21: =SUM(H54:H57) -> 1 | Y21: =SUM(I54:I57) -> 3 | Z21: =SUM(J54:J57) -> 0 | ... AF21: =SUM(P54:P57) -> 92
B22: 10.00 - 10.15 | C22: 0 | D22: 0 | E22: 1 | F22: 0 | G22: 0 | H22: 0 | I22: 0 | J22: 0 | K22: 0 | L22: 0 | M22: 19 | N22: 0 | O22: =SUM(C22:L22,N22) -> 1 | P22: =SUM(C22:N22) -> 20 | R22: AM Peak Hr | S22: =MAX(S10:S12) -> 8 | T22: =MAX(T10:T12) -> 2 | U22: =MAX(U10:U12) -> 5 | V22: =MAX(V10:V12) -> 4 | W22: =MAX(W10:W12) -> 0 | X22: =MAX(X10:X12) -> 0 | Y22: =MAX(Y10:Y12) -> 2 | Z22: =MAX(Z10:Z12) -> 2 | ... AF22: =MAX(AF10:AF12) -> 88
B23: 10.15 - 10.30 | C23: 3 | D23: 0 | E23: 0 | F23: 1 | G23: 0 | H23: 0 | I23: 0 | J23: 1 | K23: 0 | L23: 0 | M23: 13 | N23: 0 | O23: =SUM(C23:L23,N23) -> 5 | P23: =SUM(C23:N23) -> 18 | R23: IP Peak Hr | S23: =MAX(S13:S18) -> 9 | T23: =MAX(T13:T18) -> 2 | U23: =MAX(U13:U18) -> 4 | V23: =MAX(V13:V18) -> 5 | W23: =MAX(W13:W18) -> 2 | X23: =MAX(X13:X18) -> 0 | Y23: =MAX(Y13:Y18) -> 5 | Z23: =MAX(Z13:Z18) -> 5 | ... AF23: =MAX(AF13:AF18) -> 77
B24: 10.30 - 10.45 | C24: 2 | D24: 0 | E24: 1 | F24: 0 | G24: 0 | H24: 0 | I24: 0 | J24: 3 | K24: 0 | L24: 0 | M24: 18 | N24: 0 | O24: =SUM(C24:L24,N24) -> 6 | P24: =SUM(C24:N24) -> 24 | R24: PM Peak Hr | S24: =MAX(S19:S21) -> 6 | T24: =MAX(T19:T21) -> 2 | U24: =MAX(U19:U21) -> 5 | V24: =MAX(V19:V21) -> 3 | W24: =MAX(W19:W21) -> 1 | X24: =MAX(X19:X21) -> 1 | Y24: =MAX(Y19:Y21) -> 3 | Z24: =MAX(Z19:Z21) -> 1 | ... AF24: =MAX(AF19:AF21) -> 92
B25: 10.45 - 11.00 | C25: 0 | D25: 1 | E25: 1 | F25: 0 | G25: 0 | H25: 0 | I25: 0 | J25: 0 | K25: 0 | L25: 0 | M25: 13 | N25: 0 | O25: =SUM(C25:L25,N25) -> 2 | P25: =SUM(C25:N25) -> 15 | R25: AM Period | S25: =SUM(S10:S12) -> 22 | T25: =SUM(T10:T12) -> 3 | U25: =SUM(U10:U12) -> 8 | V25: =SUM(V10:V12) -> 6 | W25: =SUM(W10:W12) -> 0 | X25: =SUM(X10:X12) -> 0 | Y25: =SUM(Y10:Y12) -> 5 | Z25: =SUM(Z10:Z12) -> 4 | ... AF25: =SUM(AF10:AF12) -> 212
B26: 11.00 - 11.15 | C26: 0 | D26: 1 | E26: 1 | F26: 1 | G26: 0 | H26: 0 | I26: 0 | J26: 0 | K26: 0 | L26: 0 | M26: 7 | N26: 0 | O26: =SUM(C26:L26,N26) -> 3 | P26: =SUM(C26:N26) -> 10 | R26: IP Period | S26: =SUM(S13:S18) -> 27 | T26: =SUM(T13:T18) -> 3 | U26: =SUM(U13:U18) -> 13 | V26: =SUM(V13:V18) -> 11 | W26: =SUM(W13:W18) -> 2 | X26: =SUM(X13:X18) -> 0 | Y26: =SUM(Y13:Y18) -> 10 | Z26: =SUM(Z13:Z18) -> 10 | ... AF26: =SUM(AF13:AF18) -> 382
B27: 11.15 - 11.30 | C27: 0 | D27: 0 | E27: 0 | F27: 0 | G27: 0 | H27: 0 | I27: 0 | J27: 0 | K27: 0 | L27: 0 | M27: 13 | N27: 0 | O27: =SUM(C27:L27,N27) -> 0 | P27: =SUM(C27:N27) -> 13 | R27: PM Period | S27: =SUM(S19:S21) -> 15 | T27: =SUM(T19:T21) -> 4 | U27: =SUM(U19:U21) -> 11 | V27: =SUM(V19:V21) -> 6 | W27: =SUM(W19:W21) -> 2 | X27: =SUM(X19:X21) -> 1 | Y27: =SUM(Y19:Y21) -> 7 | Z27: =SUM(Z19:Z21) -> 2 | ... AF27: =SUM(AF19:AF21) -> 233
B28: 11.30 - 11.45 | C28: 3 | D28: 0 | E28: 1 | F28: 0 | G28: 0 | H28: 0 | I28: 2 | J28: 0 | K28: 0 | L28: 0 | M28: 11 | N28: 0 | O28: =SUM(C28:L28,N28) -> 6 | P28: =SUM(C28:N28) -> 17 | R28: 12 Hours | S28: =SUM(S10:S21) -> 64 | T28: =SUM(T10:T21) -> 10 | U28: =SUM(U10:U21) -> 32 | V28: =SUM(V10:V21) -> 23 | W28: =SUM(W10:W21) -> 4 | X28: =SUM(X10:X21) -> 1 | Y28: =SUM(Y10:Y21) -> 22 | Z28: =SUM(Z10:Z21) -> 16 | ... AF28: =SUM(AF10:AF21) -> 827
B29: 11.45 - 12.00 | C29: 1 | D29: 1 | E29: 2 | F29: 0 | G29: 0 | H29: 0 | I29: 0 | J29: 0 | K29: 0 | L29: 2 | M29: 9 | N29: 0 | O29: =SUM(C29:L29,N29) -> 6 | P29: =SUM(C29:N29) -> 15
B30: 12.00 - 12.15 | C30: 2 | D30: 0 | E30: 1 | F30: 0 | G30: 0 | H30: 0 | I30: 0 | J30: 1 | K30: 2 | L30: 0 | M30: 17 | N30: 0 | O30: =SUM(C30:L30,N30) -> 6 | P30: =SUM(C30:N30) -> 23
B31: 12.15 - 12.30 | C31: 0 | D31: 0 | E31: 0 | F31: 0 | G31: 0 | H31: 0 | I31: 0 | J31: 0 | K31: 0 | L31: 0 | M31: 3 | N31: 0 | O31: =SUM(C31:L31,N31) -> 0 | P31: =SUM(C31:N31) -> 3
B32: 12.30 - 12.45 | C32: 2 | D32: 0 | E32: 1 | F32: 0 | G32: 0 | H32: 0 | I32: 0 | J32: 0 | K32: 0 | L32: 0 | M32: 14 | N32: 0 | O32: =SUM(C32:L32,N32) -> 3 | P32: =SUM(C32:N32) -> 17
B33: 12.45 - 13.00 | C33: 0 | D33: 0 | E33: 0 | F33: 1 | G33: 2 | H33: 0 | I33: 0 | J33: 0 | K33: 0 | L33: 0 | M33: 17 | N33: 0 | O33: =SUM(C33:L33,N33) -> 3 | P33: =SUM(C33:N33) -> 20
B34: 13.00 - 13.15 | C34: 0 | D34: 0 | E34: 0 | F34: 1 | G34: 0 | H34: 0 | I34: 1 | J34: 0 | K34: 0 | L34: 1 | M34: 9 | N34: 0 | O34: =SUM(C34:L34,N34) -> 3 | P34: =SUM(C34:N34) -> 12
B35: 13.15 - 13.30 | C35: 1 | D35: 0 | E35: 1 | F35: 0 | G35: 0 | H35: 0 | I35: 1 | J35: 0 | K35: 0 | L35: 0 | M35: 18 | N35: 0 | O35: =SUM(C35:L35,N35) -> 3 | P35: =SUM(C35:N35) -> 21
B36: 13.30 - 13.45 | C36: 1 | D36: 0 | E36: 0 | F36: 0 | G36: 0 | H36: 0 | I36: 0 | J36: 0 | K36: 0 | L36: 0 | M36: 18 | N36: 0 | O36: =SUM(C36:L36,N36) -> 1 | P36: =SUM(C36:N36) -> 19
B37: 13.45 - 14.00 | C37: 0 | D37: 0 | E37: 0 | F37: 0 | G37: 0 | H37: 0 | I37: 0 | J37: 0 | K37: 0 | L37: 1 | M37: 8 | N37: 0 | O37: =SUM(C37:L37,N37) -> 1 | P37: =SUM(C37:N37) -> 9
B38: 14.00 - 14.15 | C38: 0 | D38: 0 | E38: 1 | F38: 0 | G38: 0 | H38: 0 | I38: 0 | J38: 1 | K38: 0 | L38: 0 | M38: 10 | N38: 0 | O38: =SUM(C38:L38,N38) -> 2 | P38: =SUM(C38:N38) -> 12
B39: 14.15 - 14.30 | C39: 0 | D39: 0 | E39: 0 | F39: 2 | G39: 0 | H39: 0 | I39: 1 | J39: 3 | K39: 0 | L39: 0 | M39: 5 | N39: 0 | O39: =SUM(C39:L39,N39) -> 6 | P39: =SUM(C39:N39) -> 11
B40: 14.30 - 14.45 | C40: 2 | D40: 0 | E40: 0 | F40: 2 | G40: 0 | H40: 0 | I40: 0 | J40: 1 | K40: 0 | L40: 0 | M40: 18 | N40: 0 | O40: =SUM(C40:L40,N40) -> 5 | P40: =SUM(C40:N40) -> 23
... B57: 18.45 - 19.00 | C57: 1 | D57: 0 | E57: 1 | F57: 0 | G57: 0 | H57: 1 | I57: 0 | J57: 0 | K57: 0 | L57: 1 | M57: 13 | N57: 0 | O57: =SUM(C57:L57,N57) -> 4 | P57: =SUM(C57:N57) -> 17
B58: Totals | C58: =SUM(C10:C57) -> 64 | D58: =SUM(D10:D57) -> 10 | E58: =SUM(E10:E57) -> 32 | F58: =SUM(F10:F57) -> 23 | G58: =SUM(G10:G57) -> 4 | H58: =SUM(H10:H57) -> 1 | I58: =SUM(I10:I57) -> 22 | J58: =SUM(J10:J57) -> 16 | ... P58: =SUM(P10:P57) -> 827
...

Sheet 31.07 Nebbi-Goli
B1: Consultancy services for Preparation of Expressway Development Master Plan (EDMP) for Uganda
B2: MANUAL CLASSIFIED COUNT (MCC)
B3: ROAD NAME: | C3: ='31.07 Goli-Nebbi'!C3:G3 -> MCC - C4 - STN138 - NEBBI-GOLI ROAD
C5: Date | D5: ='31.07 Goli-Nebbi'!D5 -> 31.07.19 | F5: Location | G5: ='31.07 Goli-Nebbi'!G5:H5 -> Goli | J5: Surveyor | K5: ='31.07 Goli-Nebbi'!K5:L5 -> Moreen
C6: Dir. From | D6: Nebbi | F6: Dir. To | G6: Goli | J6: Supervisor | K6: ='31.07 Goli-Nebbi'!K6:L6 -> Herbert
B8: Time / Veh Type | R8: SUMMARY TRAFFIC VOLUMES
C9: 1. Car | D9: 2. Station Wagon | E9: 3. Pickups | F9: 4. Minibus, matatu | G9: 5. Medium bus | H9: 6. Large Bus | I9: 7. Light Truck | J9: 8. Medium Truck | K9: 9. Heavy truck | L9: 10. Truck Trailer | M9: 11. Motor cycles | N9: 12. Tractors | O9: Total Excl M/Cycles | P9: Total All | R9: Time | S9: 1. Car | T9: 2. Station Wagon | U9: 3. Pickups | V9: 4. Minibus, matatu | W9: 5. Medium bus | X9: 6. Large Bus | Y9: 7. Light Truck | Z9: 8. Medium Truck | AA9: 9. Heavy truck | AB9: 10. Truck Trailer | AC9: 11. Motorcycles | AD9: 12. Tractors, Graders | AE9: Total Excl M/ Cycles | AF9: Total All
B10: 07.00 - 07.15 | C10: 1 | D10: =ROUNDDOWN((0.4*E10),0) -> 0 | E10: 0 | F10: 0 | G10: 0 | H10: 0 | I10: 0 | J10: 0 | K10: 0 | L10: 0 | M10: 6 | N10: 0 | O10: =SUM(C10:L10,N10) -> 1 | P10: =SUM(C10:N10) -> 7 | R10: 0700-0800 | S10: =SUM(C10:C13) -> 1 | T10: =SUM(D10:D13) -> 0 | U10: =SUM(E10:E13) -> 1 | V10: =SUM(F10:F13) -> 0 | W10: =SUM(G10:G13) -> 0 | X10: =SUM(H10:H13) -> 1 | Y10: =SUM(I10:I13) -> 0 | Z10: =SUM(J10:J13) -> 1 | ... AF10: =SUM(P10:P13) -> 37
B11: 07.15 - 07.30 | C11: 0 | D11: =ROUNDDOWN((0.4*E11),0) -> 0 | E11: 0 | F11: 0 | G11: 0 | H11: 0 | I11: 0 | J11: 0 | K11: 0 | L11: 0 | M11: 7 | N11: 0 | O11: =SUM(C11:L11,N11) -> 0 | P11: =SUM(C11:N11) -> 7 | R11: 0800-0900 | S11: =SUM(C14:C17) -> 3 | T11: =SUM(D14:D17) -> 0 | U11: =SUM(E14:E17) -> 0 | V11: =SUM(F14:F17) -> 1 | W11: =SUM(G14:G17) -> 1 | X11: =SUM(H14:H17) -> 0 | Y11: =SUM(I14:I17) -> 1 | Z11: =SUM(J14:J17) -> 3 | ... AF11: =SUM(P14:P17) -> 71
B12: 07.30 - 07.45 | C12: 0 | D12: =ROUNDDOWN((0.4*E12),0) -> 0 | E12: 0 | F12: 0 | G12: 0 | H12: 0 | I12: 0 | J12: 0 | K12: 0 | L12: 0 | M12: 7 | N12: 0 | O12: =SUM(C12:L12,N12) -> 0 | P12: =SUM(C12:N12) -> 7 | R12: 0900-1000 | S12: =SUM(C18:C21) -> 3 | T12: =SUM(D18:D21) -> 0 | U12: =SUM(E18:E21) -> 1 | V12: =SUM(F18:F21) -> 2 | W12: =SUM(G18:G21) -> 0 | X12: =SUM(H18:H21) -> 0 | Y12: =SUM(I18:I21) -> 0 | Z12: =SUM(J18:J21) -> 0 | ... AF12: =SUM(P18:P21) -> 68
B13: 07.45 - 08.00 | C13: 0 | D13: =ROUNDDOWN((0.4*E13),0) -> 0 | E13: 1 | F13: 0 | G13: 0 | H13: 1 | I13: 0 | J13: 1 | K13: 0 | L13: 1 | M13: 12 | N13: 0 | O13: =SUM(C13:L13,N13) -> 4 | P13: =SUM(C13:N13) -> 16 | R13: 1000-1100 | S13: =SUM(C22:C25) -> 4 | T13: =SUM(D22:D25) -> 0 | U13: =SUM(E22:E25) -> 2 | V13: =SUM(F22:F25) -> 2 | W13: =SUM(G22:G25) -> 0 | X13: =SUM(H22:H25) -> 0 | Y13: =SUM(I22:I25) -> 0 | Z13: =SUM(J22:J25) -> 0 | ... AF13: =SUM(P22:P25) -> 63
B14: 08.00 - 08.15 | C14: 0 | D14: =ROUNDDOWN((0.4*E14),0) -> 0 | E14: 0 | F14: 0 | G14: 0 | H14: 0 | I14: 1 | J14: 1 | K14: 0 | L14: 0 | M14: 10 | N14: 0 | O14: =SUM(C14:L14,N14) -> 2 | P14: =SUM(C14:N14) -> 12 | R14: 1100-1200 | S14: =SUM(C26:C29) -> 2 | T14: =SUM(D26:D29) -> 1 | U14: =SUM(E26:E29) -> 5 | V14: =SUM(F26:F29) -> 1 | W14: =SUM(G26:G29) -> 0 | X14: =SUM(H26:H29) -> 0 | Y14: =SUM(I26:I29) -> 2 | Z14: =SUM(J26:J29) -> 1 | ... AF14: =SUM(P26:P29) -> 64
B15: 08.15 - 08.30 | C15: 2 | D15: =ROUNDDOWN((0.4*E15),0) -> 0 | E15: 0 | F15: 1 | G15: 0 | H15: 0 | I15: 0 | J15: 0 | K15: 0 | L15: 0 | M15: 12 | N15: 0 | O15: =SUM(C15:L15,N15) -> 3 | P15: =SUM(C15:N15) -> 15 | R15: 1200-1300 | S15: =SUM(C30:C33) -> 2 | T15: =SUM(D30:D33) -> 0 | U15: =SUM(E30:E33) -> 3 | V15: =SUM(F30:F33) -> 5 | W15: =SUM(G30:G33) -> 1 | X15: =SUM(H30:H33) -> 1 | Y15: =SUM(I30:I33) -> 3 | Z15: =SUM(J30:J33) -> 4 | ... AF15: =SUM(P30:P33) -> 87
B16: 08.30 - 08.45 | C16: 0 | D16: =ROUNDDOWN((0.4*E16),0) -> 0 | E16: 0 | F16: 0 | G16: 1 | H16: 0 | I16: 0 | J16: 1 | K16: 0 | L16: 0 | M16: 17 | N16: 0 | O16: =SUM(C16:L16,N16) -> 2 | P16: =SUM(C16:N16) -> 19 | R16: 1300-1400 | S16: =SUM(C34:C37) -> 2 | T16: =SUM(D34:D37) -> 1 | U16: =SUM(E34:E37) -> 6 | V16: =SUM(F34:F37) -> 3 | W16: =SUM(G34:G37) -> 0 | X16: =SUM(H34:H37) -> 0 | Y16: =SUM(I34:I37) -> 4 | Z16: =SUM(J34:J37) -> 1 | ... AF16: =SUM(P34:P37) -> 74
B17: 08.45 - 9.00 | C17: 1 | D17: =ROUNDDOWN((0.4*E17),0) -> 0 | E17: 0 | F17: 0 | G17: 0 | H17: 0 | I17: 0 | J17: 1 | K17: 0 | L17: 0 | M17: 23 | N17: 0 | O17: =SUM(C17:L17,N17) -> 2 | P17: =SUM(C17:N17) -> 25 | R17: 1400-1500 | S17: =SUM(C38:C41) -> 4 | T17: =SUM(D38:D41) -> 0 | U17: =SUM(E38:E41) -> 2 | V17: =SUM(F38:F41) -> 3 | W17: =SUM(G38:G41) -> 0 | X17: =SUM(H38:H41) -> 0 | Y17: =SUM(I38:I41) -> 3 | Z17: =SUM(J38:J41) -> 1 | ... AF17: =SUM(P38:P41) -> 64
B18: 09.00 - 09.15 | C18: 1 | D18: =ROUNDDOWN((0.4*E18),0) -> 0 | E18: 0 | F18: 1 | G18: 0 | H18: 0 | I18: 0 | J18: 0 | K18: 0 | L18: 0 | M18: 11 | N18: 0 | O18: =SUM(C18:L18,N18) -> 2 | P18: =SUM(C18:N18) -> 13 | R18: 1500-1600 | S18: =SUM(C42:C45) -> 3 | T18: =SUM(D42:D45) -> 0 | U18: =SUM(E42:E45) -> 4 | V18: =SUM(F42:F45) -> 3 | W18: =SUM(G42:G45) -> 0 | X18: =SUM(H42:H45) -> 0 | Y18: =SUM(I42:I45) -> 4 | Z18: =SUM(J42:J45) -> 1 | ... AF18: =SUM(P42:P45) -> 66
B19: 09.15 - 09.30 | C19: 1 | D19: =ROUNDDOWN((0.4*E19),0) -> 0 | E19: 0 | F19: 0 | G19: 0 | H19: 0 | I19: 0 | J19: 0 | K19: 0 | L19: 0 | M19: 20 | N19: 0 | O19: =SUM(C19:L19,N19) -> 1 | P19: =SUM(C19:N19) -> 21 | R19: 1600-1700 | S19: =SUM(C46:C49) -> 7 | T19: =SUM(D46:D49) -> 1 | U19: =SUM(E46:E49) -> 7 | V19: =SUM(F46:F49) -> 0 | W19: =SUM(G46:G49) -> 0 | X19: =SUM(H46:H49) -> 0 | Y19: =SUM(I46:I49) -> 4 | Z19: =SUM(J46:J49) -> 1 | ... AF19: =SUM(P46:P49) -> 88
B20: 09.30 - 09.45 | C20: 0 | D20: =ROUNDDOWN((0.4*E20),0) -> 0 | E20: 1 | F20: 1 | G20: 0 | H20: 0 | I20: 0 | J20: 0 | K20: 0 | L20: 0 | M20: 19 | N20: 0 | O20: =SUM(C20:L20,N20) -> 2 | P20: =SUM(C20:N20) -> 21 | R20: 1700-1800 | S20: =SUM(C50:C53) -> 8 | T20: =SUM(D50:D53) -> 2 | U20: =SUM(E50:E53) -> 10 | V20: =SUM(F50:F53) -> 3 | W20: =SUM(G50:G53) -> 0 | X20: =SUM(H50:H53) -> 0 | Y20: =SUM(I50:I53) -> 3 | Z20: =SUM(J50:J53) -> 1 | ... AF20: =SUM(P50:P53) -> 93
B21: 09.45 - 10.00 | C21: 1 | D21: =ROUNDDOWN((0.4*E21),0) -> 0 | E21: 0 | F21: 0 | G21: 0 | H21: 0 | I21: 0 | J21: 0 | K21: 0 | L21: 0 | M21: 12 | N21: 0 | O21: =SUM(C21:L21,N21) -> 1 | P21: =SUM(C21:N21) -> 13 | R21: 1800-1900 | S21: =SUM(C54:C57) -> 2 | T21: =SUM(D54:D57) -> 1 | U21: =SUM(E54:E57) -> 5 | V21: =SUM(F54:F57) -> 2 | W21: =SUM(G54:G57) -> 0 | X21: =SUM(H54:H57) -> 0 | Y21: =SUM(I54:I57) -> 2 | Z21: =SUM(J54:J57) -> 1 | ... AF21: =SUM(P54:P57) -> 98
B22: 10.00 - 10.15 | C22: 1 | D22: =ROUNDDOWN((0.4*E22),0) -> 0 | E22: 0 | F22: 0 | G22: 0 | H22: 0 | I22: 0 | J22: 0 | K22: 0 | L22: 0 | M22: 11 | N22: 0 | O22: =SUM(C22:L22,N22) -> 1 | P22: =SUM(C22:N22) -> 12 | R22: AM Peak Hr | S22: =MAX(S10:S12) -> 3 | T22: =MAX(T10:T12) -> 0 | U22: =MAX(U10:U12) -> 1 | V22: =MAX(V10:V12) -> 2 | W22: =MAX(W10:W12) -> 1 | X22: =MAX(X10:X12) -> 1 | Y22: =MAX(Y10:Y12) -> 1 | Z22: =MAX(Z10:Z12) -> 3 | ... AF22: =MAX(AF10:AF12) -> 71
B23: 10.15 - 10.30 | C23: 0 | D23: =ROUNDDOWN((0.4*E23),0) -> 0 | E23: 0 | F23: 1 | G23: 0 | H23: 0 | I23: 0 | J23: 0 | K23: 1 | L23: 4 | M23: 20 | N23: 0 | O23: =SUM(C23:L23,N23) -> 6 | P23: =SUM(C23:N23) -> 26 | R23: IP Peak Hr | S23: =MAX(S13:S18) -> 4 | T23: =MAX(T13:T18) -> 1 | U23: =MAX(U13:U18) -> 6 | V23: =MAX(V13:V18) -> 5 | W23: =MAX(W13:W18) -> 1 | X23: =MAX(X13:X18) -> 1 | Y23: =MAX(Y13:Y18) -> 4 | Z23: =MAX(Z13:Z18) -> 4 | ... AF23: =MAX(AF13:AF18) -> 87
B24: 10.30 - 10.45 | C24: 2 | D24: =ROUNDDOWN((0.4*E24),0) -> 0 | E24: 0 | F24: 0 | G24: 0 | H24: 0 | I24: 0 | J24: 0 | K24: 0 | L24: 0 | M24: 15 | N24: 0 | O24: =SUM(C24:L24,N24) -> 2 | P24: =SUM(C24:N24) -> 17 | R24: PM Peak Hr | S24: =MAX(S19:S21) -> 8 | T24: =MAX(T19:T21) -> 2 | U24: =MAX(U19:U21) -> 10 | V24: =MAX(V19:V21) -> 3 | W24: =MAX(W19:W21) -> 0 | X24: =MAX(X19:X21) -> 0 | Y24: =MAX(Y19:Y21) -> 4 | Z24: =MAX(Z19:Z21) -> 1 | ... AF24: =MAX(AF19:AF21) -> 98
B25: 10.45 - 11.00 | C25: 1 | D25: =ROUNDDOWN((0.4*E25),0) -> 0 | E25: 2 | F25: 1 | G25: 0 | H25: 0 | I25: 0 | J25: 0 | K25: 0 | L25: 0 | M25: 4 | N25: 0 | O25: =SUM(C25:L25,N25) -> 4 | P25: =SUM(C25:N25) -> 8 | R25: AM Period | S25: =SUM(S10:S12) -> 7 | T25: =SUM(T10:T12) -> 0 | U25: =SUM(U10:U12) -> 2 | V25: =SUM(V10:V12) -> 3 | W25: =SUM(W10:W12) -> 1 | X25: =SUM(X10:X12) -> 1 | Y25: =SUM(Y10:Y12) -> 1 | Z25: =SUM(Z10:Z12) -> 4 | ... AF25: =SUM(AF10:AF12) -> 176
B26: 11.00 - 11.15 | C26: 0 | D26: =ROUNDDOWN((0.4*E26),0) -> 0 | E26: 2 | F26: 0 | G26: 0 | H26: 0 | I26: 0 | J26: 0 | K26: 1 | L26: 1 | M26: 12 | N26: 0 | O26: =SUM(C26:L26,N26) -> 4 | P26: =SUM(C26:N26) -> 16 | R26: IP Period | S26: =SUM(S13:S18) -> 17 | T26: =SUM(T13:T18) -> 2 | U26: =SUM(U13:U18) -> 22 | V26: =SUM(V13:V18) -> 17 | W26: =SUM(W13:W18) -> 1 | X26: =SUM(X13:X18) -> 1 | Y26: =SUM(Y13:Y18) -> 16 | Z26: =SUM(Z13:Z18) -> 8 | ... AF26: =SUM(AF13:AF18) -> 418
B27: 11.15 - 11.30 | C27: 0 | D27: =ROUNDDOWN((0.4*E27),0) -> 0 | E27: 0 | F27: 1 | G27: 0 | H27: 0 | I27: 0 | J27: 0 | K27: 0 | L27: 1 | M27: 11 | N27: 0 | O27: =SUM(C27:L27,N27) -> 2 | P27: =SUM(C27:N27) -> 13 | R27: PM Period | S27: =SUM(S19:S21) -> 17 | T27: =SUM(T19:T21) -> 4 | U27: =SUM(U19:U21) -> 22 | V27: =SUM(V19:V21) -> 5 | W27: =SUM(W19:W21) -> 0 | X27: =SUM(X19:X21) -> 0 | Y27: =SUM(Y19:Y21) -> 9 | Z27: =SUM(Z19:Z21) -> 3 | ... AF27: =SUM(AF19:AF21) -> 279
B28: 11.30 - 11.45 | C28: 0 | D28: =ROUNDDOWN((0.4*E28),0) -> 1 | E28: 3 | F28: 0 | G28: 0 | H28: 0 | I28: 0 | J28: 0 | K28: 0 | L28: 0 | M28: 12 | N28: 0 | O28: =SUM(C28:L28,N28) -> 4 | P28: =SUM(C28:N28) -> 16 | R28: 12 Hours | S28: =SUM(S10:S21) -> 41 | T28: =SUM(T10:T21) -> 6 | U28: =SUM(U10:U21) -> 46 | V28: =SUM(V10:V21) -> 25 | W28: =SUM(W10:W21) -> 2 | X28: =SUM(X10:X21) -> 2 | Y28: =SUM(Y10:Y21) -> 26 | Z28: =SUM(Z10:Z21) -> 15 | ... AF28: =SUM(AF10:AF21) -> 873
B29: 11.45 - 12.00 | C29: 2 | D29: =ROUNDDOWN((0.4*E29),0) -> 0 | E29: 0 | F29: 0 | G29: 0 | H29: 0 | I29: 2 | J29: 1 | K29: 0 | L29: 1 | M29: 13 | N29: 0 | O29: =SUM(C29:L29,N29) -> 6 | P29: =SUM(C29:N29) -> 19
B30: 12.00 - 12.15 | C30: 2 | D30: =ROUNDDOWN((0.4*E30),0) -> 0 | E30: 2 | F30: 0 | G30: 0 | H30: 1 | I30: 1 | J30: 1 | K30: 0 | L30: 1 | M30: 17 | N30: 0 | O30: =SUM(C30:L30,N30) -> 8 | P30: =SUM(C30:N30) -> 25
B31: 12.15 - 12.30 | C31: 0 | D31: =ROUNDDOWN((0.4*E31),0) -> 0 | E31: 0 | F31: 4 | G31: 1 | H31: 0 | I31: 0 | J31: 0 | K31: 0 | L31: 0 | M31: 18 | N31: 0 | O31: =SUM(C31:L31,N31) -> 5 | P31: =SUM(C31:N31) -> 23
B32: 12.30 - 12.45 | C32: 0 | D32: =ROUNDDOWN((0.4*E32),0) -> 0 | E32: 0 | F32: 0 | G32: 0 | H32: 0 | I32: 0 | J32: 1 | K32: 0 | L32: 1 | M32: 19 | N32: 0 | O32: =SUM(C32:L32,N32) -> 2 | P32: =SUM(C32:N32) -> 21
B33: 12.45 - 13.00 | C33: 0 | D33: =ROUNDDOWN((0.4*E33),0) -> 0 | E33: 1 | F33: 1 | G33: 0 | H33: 0 | I33: 2 | J33: 2 | K33: 0 | L33: 1 | M33: 11 | N33: 0 | O33: =SUM(C33:L33,N33) -> 7 | P33: =SUM(C33:N33) -> 18
B34: 13.00 - 13.15 | C34: 1 | D34: =ROUNDDOWN((0.4*E34),0) -> 0 | E34: 0 | F34: 0 | G34: 0 | H34: 0 | I34: 1 | J34: 0 | K34: 0 | L34: 1 | M34: 11 | N34: 0 | O34: =SUM(C34:L34,N34) -> 3 | P34: =SUM(C34:N34) -> 14
B35: 13.15 - 13.30 | C35: 0 | D35: =ROUNDDOWN((0.4*E35),0) -> 1 | E35: 3 | F35: 2 | G35: 0 | H35: 0 | I35: 2 | J35: 1 | K35: 0 | L35: 2 | M35: 20 | N35: 0 | O35: =SUM(C35:L35,N35) -> 11 | P35: =SUM(C35:N35) -> 31
B36: 13.30 - 13.45 | C36: 0 | D36: =ROUNDDOWN((0.4*E36),0) -> 0 | E36: 2 | F36: 1 | G36: 0 | H36: 0 | I36: 0 | J36: 0 | K36: 0 | L36: 0 | M36: 12 | N36: 0 | O36: =SUM(C36:L36,N36) -> 3 | P36: =SUM(C36:N36) -> 15
B37: 13.45 - 14.00 | C37: 1 | D37: =ROUNDDOWN((0.4*E37),0) -> 0 | E37: 1 | F37: 0 | G37: 0 | H37: 0 | I37: 1 | J37: 0 | K37: 0 | L37: 0 | M37: 11 | N37: 0 | O37: =SUM(C37:L37,N37) -> 3 | P37: =SUM(C37:N37) -> 14
B38: 14.00 - 14.15 | C38: 0 | D38: =ROUNDDOWN((0.4*E38),0) -> 0 | E38: 1 | F38: 1 | G38: 0 | H38: 0 | I38: 1 | J38: 0 | K38: 0 | L38: 0 | M38: 12 | N38: 0 | O38: =SUM(C38:L38,N38) -> 3 | P38: =SUM(C38:N38) -> 15
B39: 14.15 - 14.30 | C39: 1 | D39: =ROUNDDOWN((0.4*E39),0) -> 0 | E39: 0 | F39: 1 | G39: 0 | H39: 0 | I39: 1 | J39: 0 | K39: 2 | L39: 2 | M39: 14 | N39: 0 | O39: =SUM(C39:L39,N39) -> 7 | P39: =SUM(C39:N39) -> 21
B40: 14.30 - 14.45 | C40: 2 | D40: =ROUNDDOWN((0.4*E40),0) -> 0 | E40: 1 | F40: 0 | G40: 0 | H40: 0 | I40: 1 | J40: 0 | K40: 2 | L40: 0 | M40: 10 | N40: 0 | O40: =SUM(C40:L40,N40) -> 6 | P40: =SUM(C40:N40) -> 16
... B57: 18.45 - 19.00 | C57: 0 | D57: =ROUNDDOWN((0.4*E57),0) -> 0 | E57: 1 | F57: 1 | G57: 0 | H57: 0 | I57: 0 | J57: 0 | K57: 0 | L57: 6 | M57: 22 | N57: 0 | O57: =SUM(C57:L57,N57) -> 8 | P57: =SUM(C57:N57) -> 30
B58: Totals | C58: =SUM(C10:C57) -> 41 | D58: =SUM(D10:D57) -> 6 | E58: =SUM(E10:E57) -> 46 | F58: =SUM(F10:F57) -> 25 | G58: =SUM(G10:G57) -> 2 | H58: =SUM(H10:H57) -> 2 | I58: =SUM(I10:I57) -> 26 | J58: =SUM(J10:J57) -> 15 | ... P58: =SUM(P10:P57) -> 873
...

Sheet 01.08 Goli-Nebbi
B1: Consultancy services for Preparation of Expressway Development Master Plan (EDMP) for Uganda
B2: MANUAL CLASSIFIED COUNT (MCC)
B3: ROAD NAME: | C3: ='31.07 Goli-Nebbi'!C3:G3 -> MCC - C4 - STN138 - NEBBI-GOLI ROAD
C5: Date | D5: 01.08.19 | F5: Location | G5: ='31.07 Goli-Nebbi'!G5:H5 -> Goli | J5: Surveyor | K5: ='31.07 Goli-Nebbi'!K5:L5 -> Moreen
C6: Dir. From | D6: ='31.07 Goli-Nebbi'!D6:E6 -> Goli | F6: Dir. To | G6: ='31.07 Goli-Nebbi'!G6:H6 -> Nebbi | J6: Supervisor | K6: ='31.07 Goli-Nebbi'!K6:L6 -> Herbert
B8: Time / Veh Type | R8: SUMMARY TRAFFIC VOLUMES
C9: 1. Car | D9: 2. Station Wagon | E9: 3. Pickups | F9: 4. Minibus, matatu | G9: 5. Medium bus | H9: 6. Large Bus | I9: 7. Light Truck | J9: 8. Medium Truck | K9: 9. Heavy truck | L9: 10. Truck Trailer | M9: 11. Motor cycles | N9: 12. Tractors | O9: Total Excl M/Cycles | P9: Total All | R9: Time | S9: 1. Car | T9: 2. Station Wagon | U9: 3. Pickups | V9: 4. Minibus, matatu | W9: 5. Medium bus | X9: 6. Large Bus | Y9: 7. Light Truck | Z9: 8. Medium Truck | AA9: 9. Heavy truck | AB9: 10. Truck Trailer | AC9: 11. Motorcycles | AD9: 12. Tractors, Graders | AE9: Total Excl M/ Cycles | AF9: Total All
B10: 07.00 - 07.15 | C10: 1 | D10: 0 | E10: 0 | F10: 0 | G10: 0 | H10: 0 | I10: 0 | J10: 3 | K10: 0 | L10: 0 | M10: 24 | N10: 0 | O10: =SUM(C10:L10,N10) -> 4 | P10: =SUM(C10:N10) -> 28 | R10: 0700-0800 | S10: =SUM(C10:C13) -> 3 | T10: =SUM(D10:D13) -> 0 | U10: =SUM(E10:E13) -> 1 | V10: =SUM(F10:F13) -> 0 | W10: =SUM(G10:G13) -> 0 | X10: =SUM(H10:H13) -> 0 | Y10: =SUM(I10:I13) -> 5 | Z10: =SUM(J10:J13) -> 3 | ... AF10: =SUM(P10:P13) -> 60
B11: 07.15 - 07.30 | C11: 2 | D11: 0 | E11: 0 | F11: 0 | G11: 0 | H11: 0 | I11: 2 | J11: 0 | K11: 0 | L11: 0 | M11: 9 | N11: 0 | O11: =SUM(C11:L11,N11) -> 4 | P11: =SUM(C11:N11) -> 13 | R11: 0800-0900 | S11: =SUM(C14:C17) -> 3 | T11: =SUM(D14:D17) -> 1 | U11: =SUM(E14:E17) -> 4 | V11: =SUM(F14:F17) -> 0 | W11: =SUM(G14:G17) -> 0 | X11: =SUM(H14:H17) -> 0 | Y11: =SUM(I14:I17) -> 7 | Z11: =SUM(J14:J17) -> 0 | ... AF11: =SUM(P14:P17) -> 68
B12: 07.30 - 07.45 | C12: 0 | D12: 0 | E12: 0 | F12: 0 | G12: 0 | H12: 0 | I12: 0 | J12: 0 | K12: 0 | L12: 2 | M12: 6 | N12: 0 | O12: =SUM(C12:L12,N12) -> 2 | P12: =SUM(C12:N12) -> 8 | R12: 0900-1000 | S12: =SUM(C18:C21) -> 4 | T12: =SUM(D18:D21) -> 3 | U12: =SUM(E18:E21) -> 6 | V12: =SUM(F18:F21) -> 3 | W12: =SUM(G18:G21) -> 0 | X12: =SUM(H18:H21) -> 0 | Y12: =SUM(I18:I21) -> 1 | Z12: =SUM(J18:J21) -> 0 | ... AF12: =SUM(P18:P21) -> 74
B13: 07.45 - 08.00 | C13: 0 | D13: 0 | E13: 1 | F13: 0 | G13: 0 | H13: 0 | I13: 3 | J13: 0 | K13: 0 | L13: 0 | M13: 7 | N13: 0 | O13: =SUM(C13:L13,N13) -> 4 | P13: =SUM(C13:N13) -> 11 | R13: 1000-1100 | S13: =SUM(C22:C25) -> 4 | T13: =SUM(D22:D25) -> 0 | U13: =SUM(E22:E25) -> 0 | V13: =SUM(F22:F25) -> 2 | W13: =SUM(G22:G25) -> 0 | X13: =SUM(H22:H25) -> 0 | Y13: =SUM(I22:I25) -> 7 | Z13: =SUM(J22:J25) -> 0 | ... AF13: =SUM(P22:P25) -> 72
B14: 08.00 - 08.15 | C14: 1 | D14: 0 | E14: 1 | F14: 0 | G14: 0 | H14: 0 | I14: 4 | J14: 0 | K14: 0 | L14: 1 | M14: 11 | N14: 0 | O14: =SUM(C14:L14,N14) -> 7 | P14: =SUM(C14:N14) -> 18 | R14: 1100-1200 | S14: =SUM(C26:C29) -> 2 | T14: =SUM(D26:D29) -> 0 | U14: =SUM(E26:E29) -> 1 | V14: =SUM(F26:F29) -> 0 | W14: =SUM(G26:G29) -> 0 | X14: =SUM(H26:H29) -> 0 | Y14: =SUM(I26:I29) -> 1 | Z14: =SUM(J26:J29) -> 0 | ... AF14: =SUM(P26:P29) -> 66
B15: 08.15 - 08.30 | C15: 1 | D15: 1 | E15: 2 | F15: 0 | G15: 0 | H15: 0 | I15: 1 | J15: 0 | K15: 0 | L15: 1 | M15: 9 | N15: 0 | O15: =SUM(C15:L15,N15) -> 6 | P15: =SUM(C15:N15) -> 15 | R15: 1200-1300 | S15: =SUM(C30:C33) -> 8 | T15: =SUM(D30:D33) -> 2 | U15: =SUM(E30:E33) -> 5 | V15: =SUM(F30:F33) -> 0 | W15: =SUM(G30:G33) -> 0 | X15: =SUM(H30:H33) -> 0 | Y15: =SUM(I30:I33) -> 2 | Z15: =SUM(J30:J33) -> 1 | ... AF15: =SUM(P30:P33) -> 67
B16: 08.30 - 08.45 | C16: 1 | D16: 0 | E16: 0 | F16: 0 | G16: 0 | H16: 0 | I16: 1 | J16: 0 | K16: 0 | L16: 1 | M16: 13 | N16: 0 | O16: =SUM(C16:L16,N16) -> 3 | P16: =SUM(C16:N16) -> 16 | R16: 1300-1400 | S16: =SUM(C34:C37) -> 8 | T16: =SUM(D34:D37) -> 1 | U16: =SUM(E34:E37) -> 4 | V16: =SUM(F34:F37) -> 0 | W16: =SUM(G34:G37) -> 0 | X16: =SUM(H34:H37) -> 0 | Y16: =SUM(I34:I37) -> 2 | Z16: =SUM(J34:J37) -> 0 | ... AF16: =SUM(P34:P37) -> 56
B17: 08.45 - 9.00 | C17: 0 | D17: 0 | E17: 1 | F17: 0 | G17: 0 | H17: 0 | I17: 1 | J17: 0 | K17: 0 | L17: 0 | M17: 17 | N17: 0 | O17: =SUM(C17:L17,N17) -> 2 | P17: =SUM(C17:N17) -> 19 | R17: 1400-1500 | S17: =SUM(C38:C41) -> 4 | T17: =SUM(D38:D41) -> 0 | U17: =SUM(E38:E41) -> 2 | V17: =SUM(F38:F41) -> 3 | W17: =SUM(G38:G41) -> 0 | X17: =SUM(H38:H41) -> 0 | Y17: =SUM(I38:I41) -> 3 | Z17: =SUM(J38:J41) -> 1 | ... AF17: =SUM(P38:P41) -> 80
B18: 09.00 - 09.15 | C18: 1 | D18: 0 | E18: 0 | F18: 2 | G18: 0 | H18: 0 | I18: 0 | J18: 0 | K18: 0 | L18: 1 | M18: 3 | N18: 0 | O18: =SUM(C18:L18,N18) -> 4 | P18: =SUM(C18:N18) -> 7 | R18: 1500-1600 | S18: =SUM(C42:C45) -> 5 | T18: =SUM(D42:D45) -> 0 | U18: =SUM(E42:E45) -> 1 | V18: =SUM(F42:F45) -> 2 | W18: =SUM(G42:G45) -> 1 | X18: =SUM(H42:H45) -> 0 | Y18: =SUM(I42:I45) -> 1 | Z18: =SUM(J42:J45) -> 0 | ... AF18: =SUM(P42:P45) -> 54
B19: 09.15 - 09.30 | C19: 1 | D19: 1 | E19: 2 | F19: 0 | G19: 0 | H19: 0 | I19: 1 | J19: 0 | K19: 0 | L19: 0 | M19: 20 | N19: 0 | O19: =SUM(C19:L19,N19) -> 5 | P19: =SUM(C19:N19) -> 25 | R19: 1600-1700 | S19: =SUM(C46:C49) -> 5 | T19: =SUM(D46:D49) -> 2 | U19: =SUM(E46:E49) -> 4 | V19: =SUM(F46:F49) -> 3 | W19: =SUM(G46:G49) -> 0 | X19: =SUM(H46:H49) -> 0 | Y19: =SUM(I46:I49) -> 4 | Z19: =SUM(J46:J49) -> 0 | ... AF19: =SUM(P46:P49) -> 69
B20: 09.30 - 09.45 | C20: 1 | D20: 1 | E20: 2 | F20: 1 | G20: 0 | H20: 0 | I20: 0 | J20: 0 | K20: 0 | L20: 0 | M20: 16 | N20: 0 | O20: =SUM(C20:L20,N20) -> 5 | P20: =SUM(C20:N20) -> 21 | R20: 1700-1800 | S20: =SUM(C50:C53) -> 5 | T20: =SUM(D50:D53) -> 1 | U20: =SUM(E50:E53) -> 3 | V20: =SUM(F50:F53) -> 0 | W20: =SUM(G50:G53) -> 0 | X20: =SUM(H50:H53) -> 0 | Y20: =SUM(I50:I53) -> 3 | Z20: =SUM(J50:J53) -> 0 | ... AF20: =SUM(P50:P53) -> 66
B21: 09.45 - 10.00 | C21: 1 | D21: 1 | E21: 2 | F21: 0 | G21: 0 | H21: 0 | I21: 0 | J21: 0 | K21: 0 | L21: 0 | M21: 17 | N21: 0 | O21: =SUM(C21:L21,N21) -> 4 | P21: =SUM(C21:N21) -> 21 | R21: 1800-1900 | S21: =SUM(C54:C57) -> 5 | T21: =SUM(D54:D57) -> 0 | U21: =SUM(E54:E57) -> 1 | V21: =SUM(F54:F57) -> 2 | W21: =SUM(G54:G57) -> 0 | X21: =SUM(H54:H57) -> 0 | Y21: =SUM(I54:I57) -> 5 | Z21: =SUM(J54:J57) -> 0 | ... AF21: =SUM(P54:P57) -> 74
B22: 10.00 - 10.15 | C22: 1 | D22: 0 | E22: 0 | F22: 0 | G22: 0 | H22: 0 | I22: 3 | J22: 0 | K22: 0 | L22: 0 | M22: 9 | N22: 0 | O22: =SUM(C22:L22,N22) -> 4 | P22: =SUM(C22:N22) -> 13 | R22: AM Peak Hr | S22: =MAX(S10:S12) -> 4 | T22: =MAX(T10:T12) -> 3 | U22: =MAX(U10:U12) -> 6 | V22: =MAX(V10:V12) -> 3 | W22: =MAX(W10:W12) -> 0 | X22: =MAX(X10:X12) -> 0 | Y22: =MAX(Y10:Y12) -> 7 | Z22: =MAX(Z10:Z12) -> 3 | ... AF22: =MAX(AF10:AF12) -> 74
B23: 10.15 - 10.30 | C23: 1 | D23: 0 | E23: 0 | F23: 0 | G23: 0 | H23: 0 | I23: 0 | J23: 0 | K23: 0 | L23: 1 | M23: 16 | N23: 0 | O23: =SUM(C23:L23,N23) -> 2 | P23: =SUM(C23:N23) -> 18 | R23: IP Peak Hr | S23: =MAX(S13:S18) -> 8 | T23: =MAX(T13:T18) -> 2 | U23: =MAX(U13:U18) -> 5 | V23: =MAX(V13:V18) -> 3 | W23: =MAX(W13:W18) -> 1 | X23: =MAX(X13:X18) -> 0 | Y23: =MAX(Y13:Y18) -> 7 | Z23: =MAX(Z13:Z18) -> 1 | ... AF23: =MAX(AF13:AF18) -> 80
B24: 10.30 - 10.45 | C24: 2 | D24: 0 | E24: 0 | F24: 2 | G24: 0 | H24: 0 | I24: 3 | J24: 0 | K24: 0 | L24: 0 | M24: 16 | N24: 0 | O24: =SUM(C24:L24,N24) -> 7 | P24: =SUM(C24:N24) -> 23 | R24: PM Peak Hr | S24: =MAX(S19:S21) -> 5 | T24: =MAX(T19:T21) -> 2 | U24: =MAX(U19:U21) -> 4 | V24: =MAX(V19:V21) -> 3 | W24: =MAX(W19:W21) -> 0 | X24: =MAX(X19:X21) -> 0 | Y24: =MAX(Y19:Y21) -> 5 | Z24: =MAX(Z19:Z21) -> 0 | ... AF24: =MAX(AF19:AF21) -> 74
B25: 10.45 - 11.00 | C25: 0 | D25: 0 | E25: 0 | F25: 0 | G25: 0 | H25: 0 | I25: 1 | J25: 0 | K25: 0 | L25: 2 | M25: 15 | N25: 0 | O25: =SUM(C25:L25,N25) -> 3 | P25: =SUM(C25:N25) -> 18 | R25: AM Period | S25: =SUM(S10:S12) -> 10 | T25: =SUM(T10:T12) -> 4 | U25: =SUM(U10:U12) -> 11 | V25: =SUM(V10:V12) -> 3 | W25: =SUM(W10:W12) -> 0 | X25: =SUM(X10:X12) -> 0 | Y25: =SUM(Y10:Y12) -> 13 | Z25: =SUM(Z10:Z12) -> 3 | ... AF25: =SUM(AF10:AF12) -> 202
B26: 11.00 - 11.15 | C26: 1 | D26: 0 | E26: 0 | F26: 0 | G26: 0 | H26: 0 | I26: 0 | J26: 0 | K26: 0 | L26: 0 | M26: 17 | N26: 0 | O26: =SUM(C26:L26,N26) -> 1 | P26: =SUM(C26:N26) -> 18 | R26: IP Period | S26: =SUM(S13:S18) -> 31 | T26: =SUM(T13:T18) -> 3 | U26: =SUM(U13:U18) -> 13 | V26: =SUM(V13:V18) -> 7 | W26: =SUM(W13:W18) -> 1 | X26: =SUM(X13:X18) -> 0 | Y26: =SUM(Y13:Y18) -> 16 | Z26: =SUM(Z13:Z18) -> 2 | ... AF26: =SUM(AF13:AF18) -> 395
B27: 11.15 - 11.30 | C27: 0 | D27: 0 | E27: 1 | F27: 0 | G27: 0 | H27: 0 | I27: 1 | J27: 0 | K27: 0 | L27: 2 | M27: 11 | N27: 0 | O27: =SUM(C27:L27,N27) -> 4 | P27: =SUM(C27:N27) -> 15 | R27: PM Period | S27: =SUM(S19:S21) -> 15 | T27: =SUM(T19:T21) -> 3 | U27: =SUM(U19:U21) -> 8 | V27: =SUM(V19:V21) -> 5 | W27: =SUM(W19:W21) -> 0 | X27: =SUM(X19:X21) -> 0 | Y27: =SUM(Y19:Y21) -> 12 | Z27: =SUM(Z19:Z21) -> 0 | ... AF27: =SUM(AF19:AF21) -> 209
B28: 11.30 - 11.45 | C28: 0 | D28: 0 | E28: 0 | F28: 0 | G28: 0 | H28: 0 | I28: 0 | J28: 0 | K28: 0 | L28: 0 | M28: 13 | N28: 0 | O28: =SUM(C28:L28,N28) -> 0 | P28: =SUM(C28:N28) -> 13 | R28: 12 Hours | S28: =SUM(S10:S21) -> 56 | T28: =SUM(T10:T21) -> 10 | U28: =SUM(U10:U21) -> 32 | V28: =SUM(V10:V21) -> 15 | W28: =SUM(W10:W21) -> 1 | X28: =SUM(X10:X21) -> 0 | Y28: =SUM(Y10:Y21) -> 41 | Z28: =SUM(Z10:Z21) -> 5 | ... AF28: =SUM(AF10:AF21) -> 806
B29: 11.45 - 12.00 | C29: 1 | D29: 0 | E29: 0 | F29: 0 | G29: 0 | H29: 0 | I29: 0 | J29: 0 | K29: 0 | L29: 1 | M29: 18 | N29: 0 | O29: =SUM(C29:L29,N29) -> 2 | P29: =SUM(C29:N29) -> 20
B30: 12.00 - 12.15 | C30: 1 | D30: 0 | E30: 0 | F30: 0 | G30: 0 | H30: 0 | I30: 1 | J30: 1 | K30: 0 | L30: 0 | M30: 13 | N30: 0 | O30: =SUM(C30:L30,N30) -> 3 | P30: =SUM(C30:N30) -> 16
B31: 12.15 - 12.30 | C31: 1 | D31: 1 | E31: 2 | F31: 0 | G31: 0 | H31: 0 | I31: 0 | J31: 0 | K31: 0 | L31: 0 | M31: 12 | N31: 0 | O31: =SUM(C31:L31,N31) -> 4 | P31: =SUM(C31:N31) -> 16
B32: 12.30 - 12.45 | C32: 2 | D32: 1 | E32: 2 | F32: 0 | G32: 0 | H32: 0 | I32: 1 | J32: 0 | K32: 0 | L32: 0 | M32: 11 | N32: 0 | O32: =SUM(C32:L32,N32) -> 6 | P32: =SUM(C32:N32) -> 17
B33: 12.45 - 13.00 | C33: 4 | D33: 0 | E33: 1 | F33: 0 | G33: 0 | H33: 0 | I33: 0 | J33: 0 | K33: 0 | L33: 2 | M33: 11 | N33: 0 | O33: =SUM(C33:L33,N33) -> 7 | P33: =SUM(C33:N33) -> 18
B34: 13.00 - 13.15 | C34: 2 | D34: 0 | E34: 1 | F34: 0 | G34: 0 | H34: 0 | I34: 0 | J34: 0 | K34: 0 | L34: 0 | M34: 11 | N34: 0 | O34: =SUM(C34:L34,N34) -> 3 | P34: =SUM(C34:N34) -> 14
B35: 13.15 - 13.30 | C35: 0 | D35: 0 | E35: 1 | F35: 0 | G35: 0 | H35: 0 | I35: 1 | J35: 0 | K35: 0 | L35: 0 | M35: 11 | N35: 0 | O35: =SUM(C35:L35,N35) -> 2 | P35: =SUM(C35:N35) -> 13
B36: 13.30 - 13.45 | C36: 2 | D36: 1 | E36: 2 | F36: 0 | G36: 0 | H36: 0 | I36: 1 | J36: 0 | K36: 0 | L36: 1 | M36: 11 | N36: 0 | O36: =SUM(C36:L36,N36) -> 7 | P36: =SUM(C36:N36) -> 18
B37: 13.45 - 14.00 | C37: 4 | D37: 0 | E37: 0 | F37: 0 | G37: 0 | H37: 0 | I37: 0 | J37: 0 | K37: 0 | L37: 1 | M37: 6 | N37: 0 | O37: =SUM(C37:L37,N37) -> 5 | P37: =SUM(C37:N37) -> 11
B38: 14.00 - 14.15 | C38: 1 | D38: 0 | E38: 0 | F38: 0 | G38: 0 | H38: 0 | I38: 0 | J38: 0 | K38: 0 | L38: 0 | M38: 16 | N38: 0 | O38: =SUM(C38:L38,N38) -> 1 | P38: =SUM(C38:N38) -> 17
B39: 14.15 - 14.30 | C39: 1 | D39: 0 | E39: 0 | F39: 0 | G39: 0 | H39: 0 | I39: 1 | J39: 0 | K39: 0 | L39: 0 | M39: 21 | N39: 0 | O39: =SUM(C39:L39,N39) -> 2 | P39: =SUM(C39:N39) -> 23
B40: 14.30 - 14.45 | C40: 1 | D40: 0 | E40: 1 | F40: 2 | G40: 0 | H40: 0 | I40: 1 | J40: 1 | K40: 0 | L40: 1 | M40: 13 | N40: 0 | O40: =SUM(C40:L40,N40) -> 7 | P40: =SUM(C40:N40) -> 20
... B57: 18.45 - 19.00 | C57: 2 | D57: 0 | E57: 0 | F57: 0 | G57: 0 | H57: 0 | I57: 0 | J57: 0 | K57: 0 | L57: 2 | M57: 11 | N57: 0 | O57: =SUM(C57:L57,N57) -> 4 | P57: =SUM(C57:N57) -> 15
B58: Totals | C58: =SUM(C10:C57) -> 56 | D58: =SUM(D10:D57) -> 10 | E58: =SUM(E10:E57) -> 32 | F58: =SUM(F10:F57) -> 15 | G58: =SUM(G10:G57) -> 1 | H58: =SUM(H10:H57) -> 0 | I58: =SUM(I10:I57) -> 41 | J58: =SUM(J10:J57) -> 5 | ... P58: =SUM(P10:P57) -> 806
...

Sheet 01.08 Nebbi-Goli
B1: Consultancy services for Preparation of Expressway Development Master Plan (EDMP) for Uganda
B2: MANUAL CLASSIFIED COUNT (MCC)
B3: ROAD NAME: | C3: ='31.07 Nebbi-Goli'!C3:G3 -> MCC - C4 - STN138 - NEBBI-GOLI ROAD
C5: Date | D5: ='01.08 Goli-Nebbi'!D5 -> 01.08.19 | F5: Location | G5: ='31.07 Goli-Nebbi'!G5:H5 -> Goli | J5: Surveyor | K5: ='31.07 Goli-Nebbi'!K5:L5 -> Moreen
C6: Dir. From | D6: ='31.07 Nebbi-Goli'!D6:E6 -> Nebbi | F6: Dir. To | G6: ='31.07 Nebbi-Goli'!G6:H6 -> Goli | J6: Supervisor | K6: ='31.07 Goli-Nebbi'!K6:L6 -> Herbert
B8: Time / Veh Type | R8: SUMMARY TRAFFIC VOLUMES
C9: 1. Car | D9: 2. Station Wagon | E9: 3. Pickups | F9: 4. Minibus, matatu | G9: 5. Medium bus | H9: 6. Large Bus | I9: 7. Light Truck | J9: 8. Medium Truck | K9: 9. Heavy truck | L9: 10. Truck Trailer | M9: 11. Motor cycles | N9: 12. Tractors | O9: Total Excl M/Cycles | P9: Total All | R9: Time | S9: 1. Car | T9: 2. Station Wagon | U9: 3. Pickups | V9: 4. Minibus, matatu | W9: 5. Medium bus | X9: 6. Large Bus | Y9: 7. Light Truck | Z9: 8. Medium Truck | AA9: 9. Heavy truck | AB9: 10. Truck Trailer | AC9: 11. Motorcycles | AD9: 12. Tractors, Graders | AE9: Total Excl M/ Cycles | AF9: Total All
B10: 07.00 - 07.15 | C10: 0 | D10: 0 | E10: 0 | F10: 1 | G10: 1 | H10: 0 | I10: 1 | J10: 1 | K10: 0 | L10: 0 | M10: 9 | N10: 0 | O10: =SUM(C10:L10,N10) -> 4 | P10: =SUM(C10:N10) -> 13 | R10: 0700-0800 | S10: =SUM(C10:C13) -> 2 | T10: =SUM(D10:D13) -> 0 | U10: =SUM(E10:E13) -> 1 | V10: =SUM(F10:F13) -> 4 | W10: =SUM(G10:G13) -> 1 | X10: =SUM(H10:H13) -> 1 | Y10: =SUM(I10:I13) -> 3 | Z10: =SUM(J10:J13) -> 1 | ... AF10: =SUM(P10:P13) -> 42
B11: 07.15 - 07.30 | C11: 0 | D11: 0 | E11: 0 | F11: 3 | G11: 0 | H11: 0 | I11: 0 | J11: 0 | K11: 0 | L11: 2 | M11: 10 | N11: 0 | O11: =SUM(C11:L11,N11) -> 5 | P11: =SUM(C11:N11) -> 15 | R11: 0800-0900 | S11: =SUM(C14:C17) -> 3 | T11: =SUM(D14:D17) -> 0 | U11: =SUM(E14:E17) -> 3 | V11: =SUM(F14:F17) -> 8 | W11: =SUM(G14:G17) -> 3 | X11: =SUM(H14:H17) -> 0 | Y11: =SUM(I14:I17) -> 5 | Z11: =SUM(J14:J17) -> 0 | ... AF11: =SUM(P14:P17) -> 70
B12: 07.30 - 07.45 | C12: 1 | D12: 0 | E12: 0 | F12: 0 | G12: 0 | H12: 1 | I12: 2 | J12: 0 | K12: 0 | L12: 0 | M12: 0 | N12: 0 | O12: =SUM(C12:L12,N12) -> 4 | P12: =SUM(C12:N12) -> 4 | R12: 0900-1000 | S12: =SUM(C18:C21) -> 3 | T12: =SUM(D18:D21) -> 0 | U12: =SUM(E18:E21) -> 1 | V12: =SUM(F18:F21) -> 5 | W12: =SUM(G18:G21) -> 3 | X12: =SUM(H18:H21) -> 0 | Y12: =SUM(I18:I21) -> 0 | Z12: =SUM(J18:J21) -> 0 | ... AF12: =SUM(P18:P21) -> 66
B13: 07.45 - 08.00 | C13: 1 | D13: 0 | E13: 1 | F13: 0 | G13: 0 | H13: 0 | I13: 0 | J13: 0 | K13: 0 | L13: 0 | M13: 8 | N13: 0 | O13: =SUM(C13:L13,N13) -> 2 | P13: =SUM(C13:N13) -> 10 | R13: 1000-1100 | S13: =SUM(C22:C25) -> 6 | T13: =SUM(D22:D25) -> 0 | U13: =SUM(E22:E25) -> 3 | V13: =SUM(F22:F25) -> 3 | W13: =SUM(G22:G25) -> 1 | X13: =SUM(H22:H25) -> 0 | Y13: =SUM(I22:I25) -> 0 | Z13: =SUM(J22:J25) -> 0 | ... AF13: =SUM(P22:P25) -> 57
B14: 08.00 - 08.15 | C14: 1 | D14: 0 | E14: 0 | F14: 4 | G14: 1 | H14: 0 | I14: 0 | J14: 0 | K14: 0 | L14: 2 | M14: 9 | N14: 0 | O14: =SUM(C14:L14,N14) -> 8 | P14: =SUM(C14:N14) -> 17 | R14: 1100-1200 | S14: =SUM(C26:C29) -> 4 | T14: =SUM(D26:D29) -> 0 | U14: =SUM(E26:E29) -> 2 | V14: =SUM(F26:F29) -> 4 | W14: =SUM(G26:G29) -> 4 | X14: =SUM(H26:H29) -> 0 | Y14: =SUM(I26:I29) -> 4 | Z14: =SUM(J26:J29) -> 0 | ... AF14: =SUM(P26:P29) -> 63
B15: 08.15 - 08.30 | C15: 1 | D15: 0 | E15: 0 | F15: 0 | G15: 0 | H15: 0 | I15: 4 | J15: 0 | K15: 0 | L15: 3 | M15: 13 | N15: 0 | O15: =SUM(C15:L15,N15) -> 8 | P15: =SUM(C15:N15) -> 21 | R15: 1200-1300 | S15: =SUM(C30:C33) -> 2 | T15: =SUM(D30:D33) -> 0 | U15: =SUM(E30:E33) -> 4 | V15: =SUM(F30:F33) -> 3 | W15: =SUM(G30:G33) -> 1 | X15: =SUM(H30:H33) -> 1 | Y15: =SUM(I30:I33) -> 1 | Z15: =SUM(J30:J33) -> 0 | ... AF15: =SUM(P30:P33) -> 55
B16: 08.30 - 08.45 | C16: 1 | D16: 0 | E16: 1 | F16: 3 | G16: 1 | H16: 0 | I16: 1 | J16: 0 | K16: 0 | L16: 0 | M16: 10 | N16: 0 | O16: =SUM(C16:L16,N16) -> 7 | P16: =SUM(C16:N16) -> 17 | R16: 1300-1400 | S16: =SUM(C34:C37) -> 3 | T16: =SUM(D34:D37) -> 0 | U16: =SUM(E34:E37) -> 3 | V16: =SUM(F34:F37) -> 1 | W16: =SUM(G34:G37) -> 0 | X16: =SUM(H34:H37) -> 0 | Y16: =SUM(I34:I37) -> 4 | Z16: =SUM(J34:J37) -> 4 | ... AF16: =SUM(P34:P37) -> 66
B17: 08.45 - 9.00 | C17: 0 | D17: 0 | E17: 2 | F17: 1 | G17: 1 | H17: 0 | I17: 0 | J17: 0 | K17: 0 | L17: 0 | M17: 11 | N17: 0 | O17: =SUM(C17:L17,N17) -> 4 | P17: =SUM(C17:N17) -> 15 | R17: 1400-1500 | S17: =SUM(C38:C41) -> 1 | T17: =SUM(D38:D41) -> 0 | U17: =SUM(E38:E41) -> 1 | V17: =SUM(F38:F41) -> 3 | W17: =SUM(G38:G41) -> 0 | X17: =SUM(H38:H41) -> 0 | Y17: =SUM(I38:I41) -> 5 | Z17: =SUM(J38:J41) -> 0 | ... AF17: =SUM(P38:P41) -> 59
B18: 09.00 - 09.15 | C18: 0 | D18: 0 | E18: 1 | F18: 0 | G18: 0 | H18: 0 | I18: 0 | J18: 0 | K18: 0 | L18: 1 | M18: 11 | N18: 0 | O18: =SUM(C18:L18,N18) -> 2 | P18: =SUM(C18:N18) -> 13 | R18: 1500-1600 | S18: =SUM(C42:C45) -> 5 | T18: =SUM(D42:D45) -> 2 | U18: =SUM(E42:E45) -> 9 | V18: =SUM(F42:F45) -> 3 | W18: =SUM(G42:G45) -> 2 | X18: =SUM(H42:H45) -> 0 | Y18: =SUM(I42:I45) -> 5 | Z18: =SUM(J42:J45) -> 0 | ... AF18: =SUM(P42:P45) -> 66
B19: 09.15 - 09.30 | C19: 0 | D19: 0 | E19: 0 | F19: 2 | G19: 2 | H19: 0 | I19: 0 | J19: 0 | K19: 0 | L19: 1 | M19: 10 | N19: 0 | O19: =SUM(C19:L19,N19) -> 5 | P19: =SUM(C19:N19) -> 15 | R19: 1600-1700 | S19: =SUM(C46:C49) -> 3 | T19: =SUM(D46:D49) -> 0 | U19: =SUM(E46:E49) -> 1 | V19: =SUM(F46:F49) -> 1 | W19: =SUM(G46:G49) -> 2 | X19: =SUM(H46:H49) -> 0 | Y19: =SUM(I46:I49) -> 3 | Z19: =SUM(J46:J49) -> 1 | ... AF19: =SUM(P46:P49) -> 67
B20: 09.30 - 09.45 | C20: 1 | D20: 0 | E20: 0 | F20: 3 | G20: 1 | H20: 0 | I20: 0 | J20: 0 | K20: 0 | L20: 0 | M20: 16 | N20: 0 | O20: =SUM(C20:L20,N20) -> 5 | P20: =SUM(C20:N20) -> 21 | R20: 1700-1800 | S20: =SUM(C50:C53) -> 6 | T20: =SUM(D50:D53) -> 1 | U20: =SUM(E50:E53) -> 6 | V20: =SUM(F50:F53) -> 5 | W20: =SUM(G50:G53) -> 0 | X20: =SUM(H50:H53) -> 0 | Y20: =SUM(I50:I53) -> 4 | Z20: =SUM(J50:J53) -> 0 | ... AF20: =SUM(P50:P53) -> 81
B21: 09.45 - 10.00 | C21: 2 | D21: 0 | E21: 0 | F21: 0 | G21: 0 | H21: 0 | I21: 0 | J21: 0 | K21: 0 | L21: 3 | M21: 12 | N21: 0 | O21: =SUM(C21:L21,N21) -> 5 | P21: =SUM(C21:N21) -> 17 | R21: 1800-1900 | S21: =SUM(C54:C57) -> 4 | T21: =SUM(D54:D57) -> 0 | U21: =SUM(E54:E57) -> 2 | V21: =SUM(F54:F57) -> 1 | W21: =SUM(G54:G57) -> 1 | X21: =SUM(H54:H57) -> 0 | Y21: =SUM(I54:I57) -> 2 | Z21: =SUM(J54:J57) -> 0 | ... AF21: =SUM(P54:P57) -> 61
B22: 10.00 - 10.15 | C22: 3 | D22: 0 | E22: 1 | F22: 2 | G22: 1 | H22: 0 | I22: 0 | J22: 0 | K22: 0 | L22: 1 | M22: 10 | N22: 0 | O22: =SUM(C22:L22,N22) -> 8 | P22: =SUM(C22:N22) -> 18 | R22: AM Peak Hr | S22: =MAX(S10:S12) -> 3 | T22: =MAX(T10:T12) -> 0 | U22: =MAX(U10:U12) -> 3 | V22: =MAX(V10:V12) -> 8 | W22: =MAX(W10:W12) -> 3 | X22: =MAX(X10:X12) -> 1 | Y22: =MAX(Y10:Y12) -> 5 | Z22: =MAX(Z10:Z12) -> 1 | ... AF22: =MAX(AF10:AF12) -> 70
B23: 10.15 - 10.30 | C23: 0 | D23: 0 | E23: 1 | F23: 1 | G23: 0 | H23: 0 | I23: 0 | J23: 0 | K23: 0 | L23: 1 | M23: 10 | N23: 0 | O23: =SUM(C23:L23,N23) -> 3 | P23: =SUM(C23:N23) -> 13 | R23: IP Peak Hr | S23: =MAX(S13:S18) -> 6 | T23: =MAX(T13:T18) -> 2 | U23: =MAX(U13:U18) -> 9 | V23: =MAX(V13:V18) -> 4 | W23: =MAX(W13:W18) -> 4 | X23: =MAX(X13:X18) -> 1 | Y23: =MAX(Y13:Y18) -> 5 | Z23: =MAX(Z13:Z18) -> 4 | ... AF23: =MAX(AF13:AF18) -> 66
B24: 10.30 - 10.45 | C24: 1 | D24: 0 | E24: 1 | F24: 0 | G24: 0 | H24: 0 | I24: 0 | J24: 0 | K24: 0 | L24: 0 | M24: 15 | N24: 0 | O24: =SUM(C24:L24,N24) -> 2 | P24: =SUM(C24:N24) -> 17 | R24: PM Peak Hr | S24: =MAX(S19:S21) -> 6 | T24: =MAX(T19:T21) -> 1 | U24: =MAX(U19:U21) -> 6 | V24: =MAX(V19:V21) -> 5 | W24: =MAX(W19:W21) -> 2 | X24: =MAX(X19:X21) -> 0 | Y24: =MAX(Y19:Y21) -> 4 | Z24: =MAX(Z19:Z21) -> 1 | ... AF24: =MAX(AF19:AF21) -> 81
B25: 10.45 - 11.00 | C25: 2 | D25: 0 | E25: 0 | F25: 0 | G25: 0 | H25: 0 | I25: 0 | J25: 0 | K25: 0 | L25: 0 | M25: 7 | N25: 0 | O25: =SUM(C25:L25,N25) -> 2 | P25: =SUM(C25:N25) -> 9 | R25: AM Period | S25: =SUM(S10:S12) -> 8 | T25: =SUM(T10:T12) -> 0 | U25: =SUM(U10:U12) -> 5 | V25: =SUM(V10:V12) -> 17 | W25: =SUM(W10:W12) -> 7 | X25: =SUM(X10:X12) -> 1 | Y25: =SUM(Y10:Y12) -> 8 | Z25: =SUM(Z10:Z12) -> 1 | ... AF25: =SUM(AF10:AF12) -> 178
B26: 11.00 - 11.15 | C26: 0 | D26: 0 | E26: 0 | F26: 2 | G26: 1 | H26: 0 | I26: 2 | J26: 0 | K26: 0 | L26: 1 | M26: 11 | N26: 0 | O26: =SUM(C26:L26,N26) -> 6 | P26: =SUM(C26:N26) -> 17 | R26: IP Period | S26: =SUM(S13:S18) -> 21 | T26: =SUM(T13:T18) -> 2 | U26: =SUM(U13:U18) -> 22 | V26: =SUM(V13:V18) -> 17 | W26: =SUM(W13:W18) -> 8 | X26: =SUM(X13:X18) -> 1 | Y26: =SUM(Y13:Y18) -> 19 | Z26: =SUM(Z13:Z18) -> 4 | ... AF26: =SUM(AF13:AF18) -> 366
B27: 11.15 - 11.30 | C27: 1 | D27: 0 | E27: 1 | F27: 0 | G27: 0 | H27: 0 | I27: 0 | J27: 0 | K27: 0 | L27: 0 | M27: 9 | N27: 0 | O27: =SUM(C27:L27,N27) -> 2 | P27: =SUM(C27:N27) -> 11 | R27: PM Period | S27: =SUM(S19:S21) -> 13 | T27: =SUM(T19:T21) -> 1 | U27: =SUM(U19:U21) -> 9 | V27: =SUM(V19:V21) -> 7 | W27: =SUM(W19:W21) -> 3 | X27: =SUM(X19:X21) -> 0 | Y27: =SUM(Y19:Y21) -> 9 | Z27: =SUM(Z19:Z21) -> 1 | ... AF27: =SUM(AF19:AF21) -> 209
B28: 11.30 - 11.45 | C28: 1 | D28: 0 | E28: 1 | F28: 0 | G28: 2 | H28: 0 | I28: 2 | J28: 0 | K28: 0 | L28: 2 | M28: 11 | N28: 0 | O28: =SUM(C28:L28,N28) -> 8 | P28: =SUM(C28:N28) -> 19 | R28: 12 Hours | S28: =SUM(S10:S21) -> 42 | T28: =SUM(T10:T21) -> 3 | U28: =SUM(U10:U21) -> 36 | V28: =SUM(V10:V21) -> 41 | W28: =SUM(W10:W21) -> 18 | X28: =SUM(X10:X21) -> 2 | Y28: =SUM(Y10:Y21) -> 36 | Z28: =SUM(Z10:Z21) -> 6 | ... AF28: =SUM(AF10:AF21) -> 753
B29: 11.45 - 12.00 | C29: 2 | D29: 0 | E29: 0 | F29: 2 | G29: 1 | H29: 0 | I29: 0 | J29: 0 | K29: 0 | L29: 2 | M29: 9 | N29: 0 | O29: =SUM(C29:L29,N29) -> 7 | P29: =SUM(C29:N29) -> 16
B30: 12.00 - 12.15 | C30: 0 | D30: 0 | E30: 2 | F30: 1 | G30: 0 | H30: 1 | I30: 0 | J30: 0 | K30: 0 | L30: 2 | M30: 18 | N30: 0 | O30: =SUM(C30:L30,N30) -> 6 | P30: =SUM(C30:N30) -> 24
B31: 12.15 - 12.30 | C31: 0 | D31: 0 | E31: 1 | F31: 0 | G31: 0 | H31: 0 | I31: 1 | J31: 0 | K31: 0 | L31: 0 | M31: 4 | N31: 0 | O31: =SUM(C31:L31,N31) -> 2 | P31: =SUM(C31:N31) -> 6
B32: 12.30 - 12.45 | C32: 1 | D32: 0 | E32: 1 | F32: 0 | G32: 1 | H32: 0 | I32: 0 | J32: 0 | K32: 0 | L32: 0 | M32: 12 | N32: 0 | O32: =SUM(C32:L32,N32) -> 3 | P32: =SUM(C32:N32) -> 15
B33: 12.45 - 13.00 | C33: 1 | D33: 0 | E33: 0 | F33: 2 | G33: 0 | H33: 0 | I33: 0 | J33: 0 | K33: 0 | L33: 0 | M33: 7 | N33: 0 | O33: =SUM(C33:L33,N33) -> 3 | P33: =SUM(C33:N33) -> 10
B34: 13.00 - 13.15 | C34: 0 | D34: 0 | E34: 0 | F34: 0 | G34: 0 | H34: 0 | I34: 1 | J34: 0 | K34: 0 | L34: 2 | M34: 16 | N34: 0 | O34: =SUM(C34:L34,N34) -> 3 | P34: =SUM(C34:N34) -> 19
B35: 13.15 - 13.30 | C35: 1 | D35: 0 | E35: 1 | F35: 0 | G35: 0 | H35: 0 | I35: 0 | J35: 2 | K35: 0 | L35: 0 | M35: 10 | N35: 0 | O35: =SUM(C35:L35,N35) -> 4 | P35: =SUM(C35:N35) -> 14
B36: 13.30 - 13.45 | C36: 1 | D36: 0 | E36: 0 | F36: 1 | G36: 0 | H36: 0 | I36: 1 | J36: 2 | K36: 0 | L36: 0 | M36: 14 | N36: 0 | O36: =SUM(C36:L36,N36) -> 5 | P36: =SUM(C36:N36) -> 19
B37: 13.45 - 14.00 | C37: 1 | D37: 0 | E37: 2 | F37: 0 | G37: 0 | H37: 0 | I37: 2 | J37: 0 | K37: 0 | L37: 1 | M37: 8 | N37: 0 | O37: =SUM(C37:L37,N37) -> 6 | P37: =SUM(C37:N37) -> 14
B38: 14.00 - 14.15 | C38: 0 | D38: 0 | E38: 0 | F38: 0 | G38: 0 | H38: 0 | I38: 0 | J38: 0 | K38: 0 | L38: 1 | M38: 7 | N38: 0 | O38: =SUM(C38:L38,N38) -> 1 | P38: =SUM(C38:N38) -> 8
B39: 14.15 - 14.30 | C39: 0 | D39: 0 | E39: 0 | F39: 0 | G39: 0 | H39: 0 | I39: 0 | J39: 0 | K39: 0 | L39: 0 | M39: 14 | N39: 0 | O39: =SUM(C39:L39,N39) -> 0 | P39: =SUM(C39:N39) -> 14
B40: 14.30 - 14.45 | C40: 0 | D40: 0 | E40: 1 | F40: 3 | G40: 0 | H40: 0 | I40: 3 | J40: 0 | K40: 0 | L40: 0 | M40: 9 | N40: 0 | O40: =SUM(C40:L40,N40) -> 7 | P40: =SUM(C40:N40) -> 16
... B57: 18.45 - 19.00 | C57: 0 | D57: 0 | E57: 0 | F57: 0 | G57: 0 | H57: 0 | I57: 0 | J57: 0 | K57: 1 | L57: 3 | M57: 12 | N57: 0 | O57: =SUM(C57:L57,N57) -> 4 | P57: =SUM(C57:N57) -> 16
B58: Totals | C58: =SUM(C10:C57) -> 42 | D58: =SUM(D10:D57) -> 3 | E58: =SUM(E10:E57) -> 36 | F58: =SUM(F10:F57) -> 41 | G58: =SUM(G10:G57) -> 18 | H58: =SUM(H10:H57) -> 2 | I58: =SUM(I10:I57) -> 36 | J58: =SUM(J10:J57) -> 6 | ... P58: =SUM(P10:P57) -> 753
...

Sheet 02.08 Goli-Nebbi-24h
B1: Consultancy services for Preparation of Expressway Development Master Plan (EDMP) for Uganda
B2: MANUAL CLASSIFIED COUNT (MCC)
B3: ROAD NAME: | C3: ='31.07 Goli-Nebbi'!C3:G3 -> MCC - C4 - STN138 - NEBBI-GOLI ROAD
C5: Date | D5: 02.08.19 | F5: Location | G5: ='05.08 Nebbi-Goli'!G5:H5 -> Goli | J5: Surveyor | K5: ='05.08 Nebbi-Goli'!K5:L5 -> Moreen
C6: Dir. From | D6: ='31.07 Goli-Nebbi'!D6:E6 -> Goli | F6: Dir. To | G6: ='31.07 Goli-Nebbi'!G6:H6 -> Nebbi | J6: Supervisor | K6: ='05.08 Nebbi-Goli'!K6:L6 -> Herbert
B8: Time / Veh Type | R8: SUMMARY TRAFFIC VOLUMES
C9: 1. Car | D9: 2. Station Wagon | E9: 3. Pickups | F9: 4. Minibus, matatu | G9: 5. Medium bus | H9: 6. Large Bus | I9: 7. Light Truck | J9: 8. Medium Truck | K9: 9. Heavy truck | L9: 10. Truck Trailer | M9: 11. Motor cycles | N9: 12. Tractors | O9: Total Excl M/Cycles | P9: Total All | R9: Time | S9: 1. Car | T9: 2. Station Wagon | U9: 3. Pickups | V9: 4. Minibus, matatu | W9: 5. Medium bus | X9: 6. Large Bus | Y9: 7. Light Truck | Z9: 8. Medium Truck | AA9: 9. Heavy truck | AB9: 10. Truck Trailer | AC9: 11. Motorcycles | AD9: 12. Tractors, Graders | AE9: Total Excl M/ Cycles | AF9: Total All
B10: 07.00 - 07.15 | C10: 5 | D10: 0 | E10: 0 | F10: 1 | G10: 0 | H10: 0 | I10: 0 | J10: 0 | K10: 0 | L10: 1 | M10: 7 | N10: 0 | O10: =SUM(C10:L10,N10) -> 7 | P10: =SUM(C10:N10) -> 14 | R10: 0700-0800 | S10: =SUM(C10:C13) -> 7 | T10: =SUM(D10:D13) -> 1 | U10: =SUM(E10:E13) -> 2 | V10: =SUM(F10:F13) -> 2 | W10: =SUM(G10:G13) -> 0 | X10: =SUM(H10:H13) -> 0 | Y10: =SUM(I10:I13) -> 1 | Z10: =SUM(J10:J13) -> 0 | ... AF10: =SUM(P10:P13) -> 49
B11: 07.15 - 07.30 | C11: 1 | D11: 0 | E11: 0 | F11: 0 | G11: 0 | H11: 0 | I11: 0 | J11: 0 | K11: 0 | L11: 1 | M11: 9 | N11: 0 | O11: =SUM(C11:L11,N11) -> 2 | P11: =SUM(C11:N11) -> 11 | R11: 0800-0900 | S11: =SUM(C14:C17) -> 1 | T11: =SUM(D14:D17) -> 0 | U11: =SUM(E14:E17) -> 1 | V11: =SUM(F14:F17) -> 0 | W11: =SUM(G14:G17) -> 0 | X11: =SUM(H14:H17) -> 0 | Y11: =SUM(I14:I17) -> 6 | Z11: =SUM(J14:J17) -> 0 | ... AF11: =SUM(P14:P17) -> 50
B12: 07.30 - 07.45 | C12: 1 | D12: 0 | E12: 0 | F12: 1 | G12: 0 | H12: 0 | I12: 1 | J12: 0 | K12: 0 | L12: 0 | M12: 9 | N12: 0 | O12: =SUM(C12:L12,N12) -> 3 | P12: =SUM(C12:N12) -> 12 | R12: 0900-1000 | S12: =SUM(C18:C21) -> 6 | T12: =SUM(D18:D21) -> 0 | U12: =SUM(E18:E21) -> 3 | V12: =SUM(F18:F21) -> 4 | W12: =SUM(G18:G21) -> 0 | X12: =SUM(H18:H21) -> 0 | Y12: =SUM(I18:I21) -> 2 | Z12: =SUM(J18:J21) -> 0 | ... AF12: =SUM(P18:P21) -> 70
B13: 07.45 - 08.00 | C13: 0 | D13: 1 | E13: 2 | F13: 0 | G13: 0 | H13: 0 | I13: 0 | J13: 0 | K13: 1 | L13: 1 | M13: 7 | N13: 0 | O13: =SUM(C13:L13,N13) -> 5 | P13: =SUM(C13:N13) -> 12 | R13: 1000-1100 | S13: =SUM(C22:C25) -> 2 | T13: =SUM(D22:D25) -> 0 | U13: =SUM(E22:E25) -> 2 | V13: =SUM(F22:F25) -> 1 | W13: =SUM(G22:G25) -> 0 | X13: =SUM(H22:H25) -> 0 | Y13: =SUM(I22:I25) -> 4 | Z13: =SUM(J22:J25) -> 0 | ... AF13: =SUM(P22:P25) -> 58
B14: 08.00 - 08.15 | C14: 1 | D14: 0 | E14: 0 | F14: 0 | G14: 0 | H14: 0 | I14: 3 | J14: 0 | K14: 0 | L14: 1 | M14: 8 | N14: 0 | O14: =SUM(C14:L14,N14) -> 5 | P14: =SUM(C14:N14) -> 13 | R14: 1100-1200 | S14: =SUM(C26:C29) -> 3 | T14: =SUM(D26:D29) -> 1 | U14: =SUM(E26:E29) -> 5 | V14: =SUM(F26:F29) -> 2 | W14: =SUM(G26:G29) -> 0 | X14: =SUM(H26:H29) -> 0 | Y14: =SUM(I26:I29) -> 1 | Z14: =SUM(J26:J29) -> 0 | ... AF14: =SUM(P26:P29) -> 75
B15: 08.15 - 08.30 | C15: 0 | D15: 0 | E15: 0 | F15: 0 | G15: 0 | H15: 0 | I15: 2 | J15: 0 | K15: 0 | L15: 1 | M15: 13 | N15: 0 | O15: =SUM(C15:L15,N15) -> 3 | P15: =SUM(C15:N15) -> 16 | R15: 1200-1300 | S15: =SUM(C30:C33) -> 5 | T15: =SUM(D30:D33) -> 0 | U15: =SUM(E30:E33) -> 1 | V15: =SUM(F30:F33) -> 2 | W15: =SUM(G30:G33) -> 0 | X15: =SUM(H30:H33) -> 0 | Y15: =SUM(I30:I33) -> 3 | Z15: =SUM(J30:J33) -> 0 | ... AF15: =SUM(P30:P33) -> 65
B16: 08.30 - 08.45 | C16: 0 | D16: 0 | E16: 0 | F16: 0 | G16: 0 | H16: 0 | I16: 0 | J16: 0 | K16: 0 | L16: 1 | M16: 6 | N16: 0 | O16: =SUM(C16:L16,N16) -> 1 | P16: =SUM(C16:N16) -> 7 | R16: 1300-1400 | S16: =SUM(C34:C37) -> 5 | T16: =SUM(D34:D37) -> 3 | U16: =SUM(E34:E37) -> 6 | V16: =SUM(F34:F37) -> 1 | W16: =SUM(G34:G37) -> 0 | X16: =SUM(H34:H37) -> 0 | Y16: =SUM(I34:I37) -> 5 | Z16: =SUM(J34:J37) -> 0 | ... AF16: =SUM(P34:P37) -> 71
B17: 08.45 - 9.00 | C17: 0 | D17: 0 | E17: 1 | F17: 0 | G17: 0 | H17: 0 | I17: 1 | J17: 0 | K17: 0 | L17: 2 | M17: 10 | N17: 0 | O17: =SUM(C17:L17,N17) -> 4 | P17: =SUM(C17:N17) -> 14 | R17: 1400-1500 | S17: =SUM(C38:C41) -> 3 | T17: =SUM(D38:D41) -> 1 | U17: =SUM(E38:E41) -> 4 | V17: =SUM(F38:F41) -> 2 | W17: =SUM(G38:G41) -> 0 | X17: =SUM(H38:H41) -> 0 | Y17: =SUM(I38:I41) -> 1 | Z17: =SUM(J38:J41) -> 0 | ... AF17: =SUM(P38:P41) -> 44
B18: 09.00 - 09.15 | C18: 0 | D18: 0 | E18: 0 | F18: 1 | G18: 0 | H18: 0 | I18: 0 | J18: 0 | K18: 0 | L18: 0 | M18: 14 | N18: 0 | O18: =SUM(C18:L18,N18) -> 1 | P18: =SUM(C18:N18) -> 15 | R18: 1500-1600 | S18: =SUM(C42:C45) -> 3 | T18: =SUM(D42:D45) -> 0 | U18: =SUM(E42:E45) -> 2 | V18: =SUM(F42:F45) -> 3 | W18: =SUM(G42:G45) -> 0 | X18: =SUM(H42:H45) -> 0 | Y18: =SUM(I42:I45) -> 4 | Z18: =SUM(J42:J45) -> 0 | ... AF18: =SUM(P42:P45) -> 63
B19: 09.15 - 09.30 | C19: 2 | D19: 0 | E19: 1 | F19: 1 | G19: 0 | H19: 0 | I19: 0 | J19: 0 | K19: 0 | L19: 1 | M19: 11 | N19: 0 | O19: =SUM(C19:L19,N19) -> 5 | P19: =SUM(C19:N19) -> 16 | R19: 1600-1700 | S19: =SUM(C46:C49) -> 10 | T19: =SUM(D46:D49) -> 1 | U19: =SUM(E46:E49) -> 4 | V19: =SUM(F46:F49) -> 1 | W19: =SUM(G46:G49) -> 0 | X19: =SUM(H46:H49) -> 0 | Y19: =SUM(I46:I49) -> 8 | Z19: =SUM(J46:J49) -> 0 | ... AF19: =SUM(P46:P49) -> 79
B20: 09.30 - 09.45 | C20: 4 | D20: 0 | E20: 1 | F20: 2 | G20: 0 | H20: 0 | I20: 1 | J20: 0 | K20: 0 | L20: 0 | M20: 13 | N20: 0 | O20: =SUM(C20:L20,N20) -> 8 | P20: =SUM(C20:N20) -> 21 | R20: 1700-1800 | S20: =SUM(C50:C53) -> 5 | T20: =SUM(D50:D53) -> 1 | U20: =SUM(E50:E53) -> 3 | V20: =SUM(F50:F53) -> 1 | W20: =SUM(G50:G53) -> 0 | X20: =SUM(H50:H53) -> 0 | Y20: =SUM(I50:I53) -> 5 | Z20: =SUM(J50:J53) -> 0 | ... AF20: =SUM(P50:P53) -> 66
B21: 09.45 - 10.00 | C21: 0 | D21: 0 | E21: 1 | F21: 0 | G21: 0 | H21: 0 | I21: 1 | J21: 0 | K21: 0 | L21: 2 | M21: 14 | N21: 0 | O21: =SUM(C21:L21,N21) -> 4 | P21: =SUM(C21:N21) -> 18 | R21: 1800-1900 | S21: =SUM(C54:C57) -> 7 | T21: =SUM(D54:D57) -> 1 | U21: =SUM(E54:E57) -> 2 | V21: =SUM(F54:F57) -> 1 | W21: =SUM(G54:G57) -> 1 | X21: =SUM(H54:H57) -> 0 | Y21: =SUM(I54:I57) -> 0 | Z21: =SUM(J54:J57) -> 0 | ... AF21: =SUM(P54:P57) -> 81
B22: 10.00 - 10.15 | C22: 0 | D22: 0 | E22: 0 | F22: 0 | G22: 0 | H22: 0 | I22: 2 | J22: 0 | K22: 0 | L22: 0 | M22: 9 | N22: 0 | O22: =SUM(C22:L22,N22) -> 2 | P22: =SUM(C22:N22) -> 11 | R22: 1900-2000 | S22: =SUM(C58:C61) -> 3 | T22: =SUM(D58:D61) -> 0 | U22: =SUM(E58:E61) -> 1 | V22: =SUM(F58:F61) -> 4 | W22: =SUM(G58:G61) -> 1 | X22: =SUM(H58:H61) -> 2 | Y22: =SUM(I58:I61) -> 2 | Z22: =SUM(J58:J61) -> 0 | ... AF22: =SUM(P58:P61) -> 122
B23: 10.15 - 10.30 | C23: 0 | D23: 0 | E23: 1 | F23: 1 | G23: 0 | H23: 0 | I23: 0 | J23: 0 | K23: 0 | L23: 1 | M23: 8 | N23: 0 | O23: =SUM(C23:L23,N23) -> 3 | P23: =SUM(C23:N23) -> 11 | R23: 2000-2100 | S23: =SUM(C62:C65) -> 4 | T23: =SUM(D62:D65) -> 0 | U23: =SUM(E62:E65) -> 1 | V23: =SUM(F62:F65) -> 0 | W23: =SUM(G62:G65) -> 0 | X23: =SUM(H62:H65) -> 0 | Y23: =SUM(I62:I65) -> 1 | Z23: =SUM(J62:J65) -> 0 | ... AF23: =SUM(P62:P65) -> 43
B24: 10.30 - 10.45 | C24: 1 | D24: 0 | E24: 1 | F24: 0 | G24: 0 | H24: 0 | I24: 0 | J24: 0 | K24: 0 | L24: 1 | M24: 14 | N24: 0 | O24: =SUM(C24:L24,N24) -> 3 | P24: =SUM(C24:N24) -> 17 | R24: 2100-2200 | S24: =SUM(C66:C69) -> 3 | T24: =SUM(D66:D69) -> 0 | U24: =SUM(E66:E69) -> 0 | V24: =SUM(F66:F69) -> 1 | W24: =SUM(G66:G69) -> 0 | X24: =SUM(H66:H69) -> 0 | Y24: =SUM(I66:I69) -> 2 | Z24: =SUM(J66:J69) -> 0 | ... AF24: =SUM(P66:P69) -> 30
B25: 10.45 - 11.00 | C25: 1 | D25: 0 | E25: 0 | F25: 0 | G25: 0 | H25: 0 | I25: 2 | J25: 0 | K25: 0 | L25: 0 | M25: 16 | N25: 0 | O25: =SUM(C25:L25,N25) -> 3 | P25: =SUM(C25:N25) -> 19 | R25: 2200-2300 | S25: =SUM(C70:C73) -> 0 | T25: =SUM(D70:D73) -> 0 | U25: =SUM(E70:E73) -> 1 | V25: =SUM(F70:F73) -> 0 | W25: =SUM(G70:G73) -> 0 | X25: =SUM(H70:H73) -> 0 | Y25: =SUM(I70:I73) -> 1 | Z25: =SUM(J70:J73) -> 0 | ... AF25: =SUM(P70:P73) -> 16
B26: 11.00 - 11.15 | C26: 1 | D26: 1 | E26: 2 | F26: 0 | G26: 0 | H26: 0 | I26: 0 | J26: 0 | K26: 0 | L26: 0 | M26: 12 | N26: 0 | O26: =SUM(C26:L26,N26) -> 4 | P26: =SUM(C26:N26) -> 16 | R26: 2300-0000 | S26: =SUM(C74:C77) -> 1 | T26: =SUM(D74:D77) -> 0 | U26: =SUM(E74:E77) -> 0 | V26: =SUM(F74:F77) -> 0 | W26: =SUM(G74:G77) -> 0 | X26: =SUM(H74:H77) -> 0 | Y26: =SUM(I74:I77) -> 0 | Z26: =SUM(J74:J77) -> 0 | ... AF26: =SUM(P74:P77) -> 10
B27: 11.15 - 11.30 | C27: 0 | D27: 0 | E27: 1 | F27: 1 | G27: 0 | H27: 0 | I27: 1 | J27: 0 | K27: 0 | L27: 0 | M27: 19 | N27: 0 | O27: =SUM(C27:L27,N27) -> 3 | P27: =SUM(C27:N27) -> 22 | R27: 0000-0100 | S27: =SUM(C78:C81) -> 2 | T27: =SUM(D78:D81) -> 0 | U27: =SUM(E78:E81) -> 0 | V27: =SUM(F78:F81) -> 0 | W27: =SUM(G78:G81) -> 0 | X27: =SUM(H78:H81) -> 0 | Y27: =SUM(I78:I81) -> 0 | Z27: =SUM(J78:J81) -> 0 | ... AF27: =SUM(P78:P81) -> 5
B28: 11.30 - 11.45 | C28: 1 | D28: 0 | E28: 1 | F28: 0 | G28: 0 | H28: 0 | I28: 0 | J28: 0 | K28: 0 | L28: 0 | M28: 16 | N28: 0 | O28: =SUM(C28:L28,N28) -> 2 | P28: =SUM(C28:N28) -> 18 | R28: 0100-0200 | S28: =SUM(C82:C85) -> 0 | T28: =SUM(D82:D85) -> 0 | U28: =SUM(E82:E85) -> 0 | V28: =SUM(F82:F85) -> 0 | W28: =SUM(G82:G85) -> 0 | X28: =SUM(H82:H85) -> 0 | Y28: =SUM(I82:I85) -> 1 | Z28: =SUM(J82:J85) -> 1 | ... AF28: =SUM(P82:P85) -> 7
B29: 11.45 - 12.00 | C29: 1 | D29: 0 | E29: 1 | F29: 1 | G29: 0 | H29: 0 | I29: 0 | J29: 0 | K29: 0 | L29: 2 | M29: 14 | N29: 0 | O29: =SUM(C29:L29,N29) -> 5 | P29: =SUM(C29:N29) -> 19 | R29: 0200-0300 | S29: =SUM(C86:C89) -> 1 | T29: =SUM(D86:D89) -> 0 | U29: =SUM(E86:E89) -> 1 | V29: =SUM(F86:F89) -> 0 | W29: =SUM(G86:G89) -> 0 | X29: =SUM(H86:H89) -> 0 | Y29: =SUM(I86:I89) -> 0 | Z29: =SUM(J86:J89) -> 0 | ... AF29: =SUM(P86:P89) -> 4
