Workbook
Name Veh_Type: 'PT-19'!$C$10:$C$39
Name zones: #REF!
Name zones: #REF!
Name Zones_Ndeke: #REF!
Name Zones_Ndeke: #REF!

Sheet PT-19
B1: Consultancy services for Preparation of Expressway Development Master Plan (EDMP) for Uganda
B2: Public Transport/Bus Surveys
B4: Date: | D4: 01.08.19 | G4: Location | J4: Coded By: | N4: Chkd By: | O4: Bakole. D.M
B5: Enumerator: | G5: Supervisor:
B7: Time | C7: Veh_Type | D7: Type of Veh. | E7: Veh_Reg_No. | F7: IN / OUT | G7: Origin_Address | J7: Destination_Address | M7: No. Passengers | N7: Cost of Trip (UGX) | O7: Approx_Journey Time (Hrs)
G8: Town | H8: District | I8: Country | J8: Town | K8: District | L8: Journey_Desc
B9: 43703
B10: 0.375 | C10: 6 | D10: =IF(C10="", "",VLOOKUP(C10,Key!$A$5:$B$7,2,FALSE)) -> Large Bus | F10: OUT | G10: KITGUM | H10: KITGUM | J10: KAMPALA | K10: KAMPALA | L10: =H10&"-"&K10 -> KITGUM-KAMPALA | M10: 50 | N10: 30000 | O10: 6.5
B11: 0.41666667 | C11: 6 | D11: =IF(C11="", "",VLOOKUP(C11,Key!$A$5:$B$7,2,FALSE)) -> Large Bus | F11: OUT | G11: KITGUM | H11: KITGUM | J11: KAMPALA | K11: KAMPALA | L11: =H11&"-"&K11 -> KITGUM-KAMPALA | M11: 46 | N11: 30000 | O11: 6.5
B12: 0.4375 | C12: 6 | D12: =IF(C12="", "",VLOOKUP(C12,Key!$A$5:$B$7,2,FALSE)) -> Large Bus | F12: OUT | G12: KITGUM | H12: KITGUM | J12: KAMPALA | K12: KAMPALA | L12: =H12&"-"&K12 -> KITGUM-KAMPALA | M12: 46 | N12: 30000 | O12: 6.5
B13: 0.47916667 | C13: 6 | D13: =IF(C13="", "",VLOOKUP(C13,Key!$A$5:$B$7,2,FALSE)) -> Large Bus | F13: OUT | G13: KITGUM | H13: KITGUM | J13: KAMPALA | K13: KAMPALA | L13: =H13&"-"&K13 -> KITGUM-KAMPALA | M13: 37 | N13: 30000 | O13: 6.5
B14: 0.50208333 | C14: 6 | D14: =IF(C14="", "",VLOOKUP(C14,Key!$A$5:$B$7,2,FALSE)) -> Large Bus | F14: OUT | G14: KITGUM | H14: KITGUM | J14: KAMPALA | K14: KAMPALA | L14: =H14&"-"&K14 -> KITGUM-KAMPALA | M14: 45 | N14: 30000 | O14: 6.5
B15: 0.54236111 | C15: 6 | D15: =IF(C15="", "",VLOOKUP(C15,Key!$A$5:$B$7,2,FALSE)) -> Large Bus | F15: OUT | G15: LAMWO | H15: LAMWO | J15: KAMPALA | K15: KAMPALA | L15: =H15&"-"&K15 -> LAMWO-KAMPALA | M15: 40 | N15: 35000 | O15: 7.5
B16: 0.55555556 | C16: 6 | D16: =IF(C16="", "",VLOOKUP(C16,Key!$A$5:$B$7,2,FALSE)) -> Large Bus | F16: OUT | G16: KITGUM | H16: KITGUM | J16: KAMPALA | K16: KAMPALA | L16: =H16&"-"&K16 -> KITGUM-KAMPALA | M16: 49 | N16: 30000 | O16: 6.5
B17: 0.58055556 | C17: 6 | D17: =IF(C17="", "",VLOOKUP(C17,Key!$A$5:$B$7,2,FALSE)) -> Large Bus | F17: IN | G17: KAMPALA | H17: KAMPALA | J17: OROM | K17: KITGUM | L17: =H17&"-"&K17 -> KAMPALA-KITGUM | M17: 30 | N17: 30000 | O17: 6.5
B18: 0.60555556 | C18: 6 | D18: =IF(C18="", "",VLOOKUP(C18,Key!$A$5:$B$7,2,FALSE)) -> Large Bus | F18: IN | G18: KAMPALA | H18: KAMPALA | J18: OROM | K18: KITGUM | L18: =H18&"-"&K18 -> KAMPALA-KITGUM | M18: 30 | N18: 30000 | O18: 6.5
B19: 0.63680556 | C19: 6 | D19: =IF(C19="", "",VLOOKUP(C19,Key!$A$5:$B$7,2,FALSE)) -> Large Bus | F19: OUT | G19: KITGUM | H19: KITGUM | J19: KAMPALA | K19: KAMPALA | L19: =H19&"-"&K19 -> KITGUM-KAMPALA | M19: 15 | N19: 30000 | O19: 6.5
B20: 0.66111111 | C20: 6 | D20: =IF(C20="", "",VLOOKUP(C20,Key!$A$5:$B$7,2,FALSE)) -> Large Bus | F20: IN | G20: KAMPALA | H20: KAMPALA | J20: KITGUM | K20: KITGUM | L20: =H20&"-"&K20 -> KAMPALA-KITGUM | M20: 30 | N20: 30000 | O20: 6.5
B21: 0.71388889 | C21: 6 | D21: =IF(C21="", "",VLOOKUP(C21,Key!$A$5:$B$7,2,FALSE)) -> Large Bus | F21: IN | G21: KAMPALA | H21: KAMPALA | J21: KITGUM | K21: KITGUM | L21: =H21&"-"&K21 -> KAMPALA-KITGUM | M21: 30 | N21: 30000 | O21: 6.5
... B29: 0.91666667 | C29: 6 | D29: =IF(C29="", "",VLOOKUP(C29,Key!$A$5:$B$7,2,FALSE)) -> Large Bus | F29: OUT | G29: KITGUM | H29: KITGUM | J29: KAMPALA | K29: KAMPALA | L29: =H29&"-"&K29 -> KITGUM-KAMPALA | M29: 51 | N29: 30000 | O29: 6.5
B30: 43704 | L30: =H30&"-"&K30 -> -
B31: 0.29166667 | C31: 6 | D31: =IF(C31="", "",VLOOKUP(C31,Key!$A$5:$B$7,2,FALSE)) -> Large Bus | F31: OUT | G31: KITGUM | H31: KITGUM | J31: KAMPALA | K31: KAMPALA | L31: =H31&"-"&K31 -> KITGUM-KAMPALA | M31: 50 | N31: 30000 | O31: 6.5
B32: 0.34722222 | C32: 6 | D32: =IF(C32="", "",VLOOKUP(C32,Key!$A$5:$B$7,2,FALSE)) -> Large Bus | F32: IN | G32: KAMPALA | H32: KAMPALA | J32: KITGUM | K32: KITGUM | L32: =H32&"-"&K32 -> KAMPALA-KITGUM | M32: 40 | N32: 30000 | O32: 6.5
B33: 0.37083333 | C33: 6 | D33: =IF(C33="", "",VLOOKUP(C33,Key!$A$5:$B$7,2,FALSE)) -> Large Bus | F33: OUT | G33: KITGUM | H33: KITGUM | J33: KAMPALA | K33: KAMPALA | L33: =H33&"-"&K33 -> KITGUM-KAMPALA | M33: 46 | N33: 30000 | O33: 6.5
B34: 0.38194444 | C34: 6 | D34: =IF(C34="", "",VLOOKUP(C34,Key!$A$5:$B$7,2,FALSE)) -> Large Bus | F34: OUT | G34: KITGUM | H34: KITGUM | J34: KAMPALA | K34: KAMPALA | L34: =H34&"-"&K34 -> KITGUM-KAMPALA | M34: 35 | N34: 30000 | O34: 6.5
B35: 0.40625 | C35: 6 | D35: =IF(C35="", "",VLOOKUP(C35,Key!$A$5:$B$7,2,FALSE)) -> Large Bus | F35: OUT | G35: KITGUM | H35: KITGUM | J35: KAMPALA | K35: KAMPALA | L35: =H35&"-"&K35 -> KITGUM-KAMPALA | M35: 45 | N35: 30000 | O35: 6.5
B36: 0.45138889 | C36: 6 | D36: =IF(C36="", "",VLOOKUP(C36,Key!$A$5:$B$7,2,FALSE)) -> Large Bus | F36: OUT | G36: KITGUM | H36: KITGUM | J36: KAMPALA | K36: KAMPALA | L36: =H36&"-"&K36 -> KITGUM-KAMPALA | M36: 47 | N36: 30000 | O36: 6.5
B37: 0.45833333 | C37: 6 | D37: =IF(C37="", "",VLOOKUP(C37,Key!$A$5:$B$7,2,FALSE)) -> Large Bus | F37: OUT | G37: KITGUM | H37: KITGUM | J37: KAMPALA | K37: KAMPALA | L37: =H37&"-"&K37 -> KITGUM-KAMPALA | M37: 40 | N37: 30000 | O37: 6.5
B38: 0.47986111 | C38: 6 | D38: =IF(C38="", "",VLOOKUP(C38,Key!$A$5:$B$7,2,FALSE)) -> Large Bus | F38: OUT | G38: KITGUM | H38: KITGUM | J38: KAMPALA | K38: KAMPALA | L38: =H38&"-"&K38 -> KITGUM-KAMPALA | M38: 35 | N38: 30000 | O38: 6.5
B39: 0.4875 | C39: 6 | D39: =IF(C39="", "",VLOOKUP(C39,Key!$A$5:$B$7,2,FALSE)) -> Large Bus | F39: OUT | G39: KITGUM | H39: KITGUM | J39: KAMPALA | K39: KAMPALA | L39: =H39&"-"&K39 -> KITGUM-KAMPALA | M39: 57 | N39: 30000 | O39: 6.5
B40: 0.55208333 | C40: 6 | D40: =IF(C40="", "",VLOOKUP(C40,Key!$A$5:$B$7,2,FALSE)) -> Large Bus | F40: OUT | G40: PALOGA | H40: KITGUM | J40: KAMPALA | K40: KAMPALA | L40: =H40&"-"&K40 -> KITGUM-KAMPALA | M40: 57 | N40: 30000 | O40: 6.5
B41: 0.57361111 | C41: 6 | D41: =IF(C41="", "",VLOOKUP(C41,Key!$A$5:$B$7,2,FALSE)) -> Large Bus | F41: OUT | G41: KITGUM | H41: KITGUM | J41: KAMPALA | K41: KAMPALA | L41: =H41&"-"&K41 -> KITGUM-KAMPALA | M41: 59 | N41: 30000 | O41: 6.5
B42: 0.66736111 | C42: 6 | D42: =IF(C42="", "",VLOOKUP(C42,Key!$A$5:$B$7,2,FALSE)) -> Large Bus | F42: IN | G42: KAMPALA | H42: KAMPALA | J42: OROM | K42: KITGUM | L42: =H42&"-"&K42 -> KAMPALA-KITGUM | M42: 40 | N42: 30000 | O42: 6.5
... B51: 0.91666667 | C51: 6 | D51: =IF(C51="", "",VLOOKUP(C51,Key!$A$5:$B$7,2,FALSE)) -> Large Bus | F51: OUT | G51: OROM | H51: KITGUM | J51: KAMPALA | K51: KAMPALA | L51: =H51&"-"&K51 -> KITGUM-KAMPALA | M51: 40 | N51: 30000 | O51: 6.5
B52: 43705 | L52: =H52&"-"&K52 -> -
B53: 0.32152778 | C53: 6 | D53: =IF(C53="", "",VLOOKUP(C53,Key!$A$5:$B$7,2,FALSE)) -> Large Bus | F53: OUT | G53: OROM | H53: KITGUM | J53: KAMPALA | K53: KAMPALA | L53: =H53&"-"&K53 -> KITGUM-KAMPALA | M53: 57 | N53: 30000 | O53: 6.5
B54: 0.32847222 | C54: 6 | D54: =IF(C54="", "",VLOOKUP(C54,Key!$A$5:$B$7,2,FALSE)) -> Large Bus | F54: OUT | G54: OROM | H54: KITGUM | J54: KAMPALA | K54: KAMPALA | L54: =H54&"-"&K54 -> KITGUM-KAMPALA | M54: 57 | N54: 30000 | O54: 6.5
B55: 0.34513889 | C55: 6 | D55: =IF(C55="", "",VLOOKUP(C55,Key!$A$5:$B$7,2,FALSE)) -> Large Bus | F55: OUT | G55: OROM | H55: KITGUM | J55: KAMPALA | K55: KAMPALA | L55: =H55&"-"&K55 -> KITGUM-KAMPALA | M55: 41 | N55: 30000 | O55: 6.5
B56: 0.35555556 | C56: 6 | D56: =IF(C56="", "",VLOOKUP(C56,Key!$A$5:$B$7,2,FALSE)) -> Large Bus | F56: OUT | G56: OROM | H56: KITGUM | J56: KAMPALA | K56: KAMPALA | L56: =H56&"-"&K56 -> KITGUM-KAMPALA | M56: 41 | N56: 30000 | O56: 6.5
B57: 0.35972222 | C57: 6 | D57: =IF(C57="", "",VLOOKUP(C57,Key!$A$5:$B$7,2,FALSE)) -> Large Bus | F57: OUT | G57: LAMWO | H57: LAMWO | J57: KAMPALA | K57: KAMPALA | L57: =H57&"-"&K57 -> LAMWO-KAMPALA | M57: 7 | N57: 35000 | O57: 7.5
...

Sheet RSI FORM
B1: Feasibility Study and Detailed Design of Kampala - Jinja Highway
B2: Roadside OD Interview Survey
B4: Date: | C4: 40465 | D4: Interviewer: | G4: Survey Station: | H4: Bweyogerere | J4: Direction: | K4: Bweyogerere-Kireka | L4: Coded By: | N4: Chkd By:
B7: Time Period | C7: Veh_Type | D7: Veh_Other | E7: Occupancy | F7: Origin_Address | H7: Origin_Purpose | I7: Origin_other | J7: Destination_Address | L7: Destination_Purpose | M7: Destination_Other | N7: Origin_Zone | O7: Dest_Zone | P7: WTP
F8: Village/Town | G8: City/Country | J8: Village/Town | K8: City/Country
B9: AM | C9: 3 | E9: 2 | F9: Entebbe | G9: Kla, Ug | H9: 1 | J9: Kla | K9: Kla, Ug | L9: 2 | N9: Blank | O9: Blank | P9: Yes | Q9: 3000
B10: AM | C10: 1 | E10: 1 | F10: Kiwanga | G10: Kla, Ug | H10: 1 | J10: Kla | K10: Kla, Ug | L10: 2 | N10: Blank | O10: Blank | P10: Yes | Q10: 2000
B11: AM | E11: 1 | F11: Bukoto | G11: Kla, Ug | H11: 3 | J11: Kla | K11: Kla, Ug | L11: 1 | N11: Blank | O11: Blank
B12: AM
B13: AM
B14: AM
B15: AM
B16: AM
B17: AM
B18: AM
B19: AM
B20: AM
B21: AM
B22: AM
B23: AM
... B53: AM

Sheet Summary
B2: BUS OPERATIONS AT KITGUM
D4: BUS JOURNEY | J4: PASSENGER DETAILS
B5: STATION | C5: DIRECTION | D5: ORIGIN | E5: DESTINATION | F5: ROUTE ID | G5: BUS TRIPS / DAY | H5: JOURNEY DISTANCE (KM) | I5: JOURNEY TIME/ TRIP (HRS) | J5: EST. PAX/ BUS | K5: AVERAGE PAX FARE (UGX)
B6: KITGUM | C6: FROM KAMPALA | D6: KAMPALA | E6: KITGUM | F6: =D6&"-"&E6 -> KAMPALA-KITGUM | G6: =ROUNDUP(COUNTIF('PT-19'!$L$9:$L$433,Summary!F6)/5,0) -> 4 | H6: 435 | I6: =AVERAGEIF('PT-19'!$L$9:$L$433,Summary!F6,'PT-19'!$O$9:$O$433) -> 6.5 | J6: =AVERAGEIF('PT-19'!$L$9:$L$433,Summary!F6,'PT-19'!$M$9:$M$433) -> 39 | K6: =AVERAGEIF('PT-19'!$L$9:$L$433,Summary!F6,'PT-19'!$N$9:$N$433) -> 30000
B7: KITGUM | C7: TO KAMPALA | D7: KAABONG | E7: KAMPALA | F7: =D7&"-"&E7 -> KAABONG-KAMPALA | G7: =ROUNDUP(COUNTIF('PT-19'!$L$9:$L$433,Summary!F7)/5,0) -> 1 | H7: 586 | I7: =AVERAGEIF('PT-19'!$L$9:$L$433,Summary!F7,'PT-19'!$O$9:$O$433) -> 9.5 | J7: =AVERAGEIF('PT-19'!$L$9:$L$433,Summary!F7,'PT-19'!$M$9:$M$433) -> 28.8 | K7: =AVERAGEIF('PT-19'!$L$9:$L$433,Summary!F7,'PT-19'!$N$9:$N$433) -> 45000
B8: KITGUM | C8: TO KAMPALA | D8: KITGUM | E8: KAMPALA | F8: =D8&"-"&E8 -> KITGUM-KAMPALA | G8: =ROUNDUP(COUNTIF('PT-19'!$L$9:$L$433,Summary!F8)/5,0) -> 14 | H8: 435 | I8: =AVERAGEIF('PT-19'!$L$9:$L$433,Summary!F8,'PT-19'!$O$9:$O$433) -> 6.5 | J8: =AVERAGEIF('PT-19'!$L$9:$L$433,Summary!F8,'PT-19'!$M$9:$M$433) -> 46.272727 | K8: =AVERAGEIF('PT-19'!$L$9:$L$433,Summary!F8,'PT-19'!$N$9:$N$433) -> 30000
B9: KITGUM | C9: TO KAMPALA | D9: LAMWO | E9: KAMPALA | F9: =D9&"-"&E9 -> LAMWO-KAMPALA | G9: =ROUNDUP(COUNTIF('PT-19'!$L$9:$L$433,Summary!F9)/5,0) -> 2 | H9: 454 | I9: =AVERAGEIF('PT-19'!$L$9:$L$433,Summary!F9,'PT-19'!$O$9:$O$433) -> 7.5 | J9: =AVERAGEIF('PT-19'!$L$9:$L$433,Summary!F9,'PT-19'!$M$9:$M$433) -> 27.5 | K9: =AVERAGEIF('PT-19'!$L$9:$L$433,Summary!F9,'PT-19'!$N$9:$N$433) -> 35000
B10: KITGUM | C10: FROM KITGUM | D10: KITGUM | E10: KAABONG | F10: =D10&"-"&E10 -> KITGUM-KAABONG | G10: =ROUNDUP(COUNTIF('PT-19'!$L$9:$L$433,Summary!F10)/5,0) -> 1 | H10: 185 | I10: =AVERAGEIF('PT-19'!$L$9:$L$433,Summary!F10,'PT-19'!$O$9:$O$433) -> 4 | J10: =AVERAGEIF('PT-19'!$L$9:$L$433,Summary!F10,'PT-19'!$M$9:$M$433) -> 24 | K10: =AVERAGEIF('PT-19'!$L$9:$L$433,Summary!F10,'PT-19'!$N$9:$N$433) -> 15000

Sheet Key
B1: Vehicle Type
A2: 1 | B2: Car
A3: 2 | B3: Station Wagon
A4: 3 | B4: Pickups
A5: 4 | B5: Minibus, matatu
A6: 5 | B6: Medium bus
A7: 6 | B7: Large Bus
A8: 7 | B8: Light Truck
A9: 8 | B9: Medium Truck
A10: 9 | B10: Heavy truck
A11: 10 | B11: Truck Trailer
A12: 11 | B12: Motor cycles
A13: 12 | B13: Tractors
