Workbook

Sheet 29.07 Kyebando-Bukoto
B1: Consultancy services for Preparation of Expressway Development Master Plan (EDMP) for Uganda
B2: MANUAL CLASSIFIED COUNT (MCC)
B3: ROAD NAME: | C3: MCC - C1 - STN30 - KYEBANDO - KISALOSALO ROAD
C5: Date | D5: 29.07.19 | F5: Location | G5: Kyebando Round | J5: Surveyor | K5: AHISIBWE SARAH
C6: Dir. From | D6: Kyebando | F6: Dir. To | G6: Bukoto | J6: Supervisor | K6: STEVEN
B8: Time / Veh Type | R8: SUMMARY TRAFFIC VOLUMES
C9: 1. Car | D9: 2. Station Wagon | E9: 3. Pickups | F9: 4. Minibus, matatu | G9: 5. Medium bus | H9: 6. Large Bus | I9: 7. Light Truck | J9: 8. Medium Truck | K9: 9. Heavy truck | L9: 10. Truck Trailer | M9: 11. Motor cycles | N9: 12. Tractors | O9: Total Excl M/Cycles | P9: Total All | R9: Time | S9: 1. Car | T9: 2. Station Wagon | U9: 3. Pickups | V9: 4. Minibus, matatu | W9: 5. Medium bus | X9: 6. Large Bus | Y9: 7. Light Truck | Z9: 8. Medium Truck | AA9: 9. Heavy truck | AB9: 10. Truck Trailer | AC9: 11. Motorcycles | AD9: 12. Tractors, Graders | AE9: Total Excl M/ Cycles | AF9: Total All
B10: 07.00 - 07.15 | C10: 75 | D10: 27 | E10: 12 | F10: 0 | G10: 0 | H10: 0 | I10: 1 | J10: 0 | K10: 0 | L10: 0 | M10: 67 | N10: 0 | O10: =SUM(C10:L10,N10) -> 115 | P10: =SUM(C10:N10) -> 182 | R10: 0700-0800 | S10: =SUM(C10:C13) -> 310 | T10: =SUM(D10:D13) -> 84 | U10: =SUM(E10:E13) -> 34 | V10: =SUM(F10:F13) -> 4 | W10: =SUM(G10:G13) -> 2 | X10: =SUM(H10:H13) -> 0 | Y10: =SUM(I10:I13) -> 9 | Z10: =SUM(J10:J13) -> 1 | ... AF10: =SUM(P10:P13) -> 721
B11: 07.15 - 07.30 | C11: 85 | D11: 20 | E11: 5 | F11: 0 | G11: 2 | H11: 0 | I11: 4 | J11: 1 | K11: 0 | L11: 0 | M11: 75 | N11: 0 | O11: =SUM(C11:L11,N11) -> 117 | P11: =SUM(C11:N11) -> 192 | R11: 0800-0900 | S11: =SUM(C14:C17) -> 285 | T11: =SUM(D14:D17) -> 96 | U11: =SUM(E14:E17) -> 53 | V11: =SUM(F14:F17) -> 16 | W11: =SUM(G14:G17) -> 1 | X11: =SUM(H14:H17) -> 0 | Y11: =SUM(I14:I17) -> 12 | Z11: =SUM(J14:J17) -> 3 | ... AF11: =SUM(P14:P17) -> 811
B12: 07.30 - 07.45 | C12: 70 | D12: 13 | E12: 10 | F12: 2 | G12: 0 | H12: 0 | I12: 1 | J12: 0 | K12: 0 | L12: 0 | M12: 60 | N12: 0 | O12: =SUM(C12:L12,N12) -> 96 | P12: =SUM(C12:N12) -> 156 | R12: 0900-1000 | S12: =SUM(C18:C21) -> 176 | T12: =SUM(D18:D21) -> 57 | U12: =SUM(E18:E21) -> 36 | V12: =SUM(F18:F21) -> 9 | W12: =SUM(G18:G21) -> 0 | X12: =SUM(H18:H21) -> 0 | Y12: =SUM(I18:I21) -> 33 | Z12: =SUM(J18:J21) -> 3 | ... AF12: =SUM(P18:P21) -> 589
B13: 07.45 - 08.00 | C13: 80 | D13: 24 | E13: 7 | F13: 2 | G13: 0 | H13: 0 | I13: 3 | J13: 0 | K13: 0 | L13: 0 | M13: 75 | N13: 0 | O13: =SUM(C13:L13,N13) -> 116 | P13: =SUM(C13:N13) -> 191 | R13: 1000-1100 | S13: =SUM(C22:C25) -> 123 | T13: =SUM(D22:D25) -> 45 | U13: =SUM(E22:E25) -> 24 | V13: =SUM(F22:F25) -> 6 | W13: =SUM(G22:G25) -> 0 | X13: =SUM(H22:H25) -> 0 | Y13: =SUM(I22:I25) -> 16 | Z13: =SUM(J22:J25) -> 1 | ... AF13: =SUM(P22:P25) -> 459
B14: 08.00 - 08.15 | C14: 75 | D14: 36 | E14: 20 | F14: 5 | G14: 1 | H14: 0 | I14: 2 | J14: 2 | K14: 0 | L14: 0 | M14: 95 | N14: 0 | O14: =SUM(C14:L14,N14) -> 141 | P14: =SUM(C14:N14) -> 236 | R14: 1100-1200 | S14: =SUM(C26:C29) -> 113 | T14: =SUM(D26:D29) -> 27 | U14: =SUM(E26:E29) -> 17 | V14: =SUM(F26:F29) -> 12 | W14: =SUM(G26:G29) -> 0 | X14: =SUM(H26:H29) -> 0 | Y14: =SUM(I26:I29) -> 17 | Z14: =SUM(J26:J29) -> 0 | ... AF14: =SUM(P26:P29) -> 424
B15: 08.15 - 08.30 | C15: 70 | D15: 18 | E15: 10 | F15: 2 | G15: 0 | H15: 0 | I15: 4 | J15: 0 | K15: 0 | L15: 0 | M15: 90 | N15: 0 | O15: =SUM(C15:L15,N15) -> 104 | P15: =SUM(C15:N15) -> 194 | R15: 1200-1300 | S15: =SUM(C30:C33) -> 106 | T15: =SUM(D30:D33) -> 15 | U15: =SUM(E30:E33) -> 26 | V15: =SUM(F30:F33) -> 13 | W15: =SUM(G30:G33) -> 0 | X15: =SUM(H30:H33) -> 0 | Y15: =SUM(I30:I33) -> 18 | Z15: =SUM(J30:J33) -> 3 | ... AF15: =SUM(P30:P33) -> 364
B16: 08.30 - 08.45 | C16: 75 | D16: 21 | E16: 9 | F16: 3 | G16: 0 | H16: 0 | I16: 2 | J16: 0 | K16: 0 | L16: 0 | M16: 80 | N16: 0 | O16: =SUM(C16:L16,N16) -> 110 | P16: =SUM(C16:N16) -> 190 | R16: 1300-1400 | S16: =SUM(C34:C37) -> 104 | T16: =SUM(D34:D37) -> 37 | U16: =SUM(E34:E37) -> 19 | V16: =SUM(F34:F37) -> 11 | W16: =SUM(G34:G37) -> 0 | X16: =SUM(H34:H37) -> 0 | Y16: =SUM(I34:I37) -> 8 | Z16: =SUM(J34:J37) -> 4 | ... AF16: =SUM(P34:P37) -> 332
B17: 08.45 - 9.00 | C17: 65 | D17: 21 | E17: 14 | F17: 6 | G17: 0 | H17: 0 | I17: 4 | J17: 1 | K17: 0 | L17: 0 | M17: 80 | N17: 0 | O17: =SUM(C17:L17,N17) -> 111 | P17: =SUM(C17:N17) -> 191 | R17: 1400-1500 | S17: =SUM(C38:C41) -> 80 | T17: =SUM(D38:D41) -> 41 | U17: =SUM(E38:E41) -> 24 | V17: =SUM(F38:F41) -> 11 | W17: =SUM(G38:G41) -> 0 | X17: =SUM(H38:H41) -> 0 | Y17: =SUM(I38:I41) -> 11 | Z17: =SUM(J38:J41) -> 8 | ... AF17: =SUM(P38:P41) -> 312
B18: 09.00 - 09.15 | C18: 30 | D18: 15 | E18: 9 | F18: 2 | G18: 0 | H18: 0 | I18: 9 | J18: 1 | K18: 1 | L18: 1 | M18: 80 | N18: 0 | O18: =SUM(C18:L18,N18) -> 68 | P18: =SUM(C18:N18) -> 148 | R18: 1500-1600 | S18: =SUM(C42:C45) -> 108 | T18: =SUM(D42:D45) -> 31 | U18: =SUM(E42:E45) -> 25 | V18: =SUM(F42:F45) -> 7 | W18: =SUM(G42:G45) -> 0 | X18: =SUM(H42:H45) -> 0 | Y18: =SUM(I42:I45) -> 7 | Z18: =SUM(J42:J45) -> 2 | ... AF18: =SUM(P42:P45) -> 364
B19: 09.15 - 09.30 | C19: 45 | D19: 16 | E19: 12 | F19: 3 | G19: 0 | H19: 0 | I19: 11 | J19: 2 | K19: 0 | L19: 0 | M19: 70 | N19: 0 | O19: =SUM(C19:L19,N19) -> 89 | P19: =SUM(C19:N19) -> 159 | R19: 1600-1700 | S19: =SUM(C46:C49) -> 119 | T19: =SUM(D46:D49) -> 50 | U19: =SUM(E46:E49) -> 30 | V19: =SUM(F46:F49) -> 20 | W19: =SUM(G46:G49) -> 3 | X19: =SUM(H46:H49) -> 0 | Y19: =SUM(I46:I49) -> 9 | Z19: =SUM(J46:J49) -> 5 | ... AF19: =SUM(P46:P49) -> 442
B20: 09.30 - 09.45 | C20: 56 | D20: 16 | E20: 10 | F20: 1 | G20: 0 | H20: 0 | I20: 3 | J20: 0 | K20: 2 | L20: 0 | M20: 60 | N20: 0 | O20: =SUM(C20:L20,N20) -> 88 | P20: =SUM(C20:N20) -> 148 | R20: 1700-1800 | S20: =SUM(C50:C53) -> 128 | T20: =SUM(D50:D53) -> 39 | U20: =SUM(E50:E53) -> 26 | V20: =SUM(F50:F53) -> 23 | W20: =SUM(G50:G53) -> 3 | X20: =SUM(H50:H53) -> 2 | Y20: =SUM(I50:I53) -> 23 | Z20: =SUM(J50:J53) -> 5 | ... AF20: =SUM(P50:P53) -> 493
B21: 09.45 - 10.00 | C21: 45 | D21: 10 | E21: 5 | F21: 3 | G21: 0 | H21: 0 | I21: 10 | J21: 0 | K21: 1 | L21: 0 | M21: 60 | N21: 0 | O21: =SUM(C21:L21,N21) -> 74 | P21: =SUM(C21:N21) -> 134 | R21: 1800-1900 | S21: =SUM(C54:C57) -> 117 | T21: =SUM(D54:D57) -> 58 | U21: =SUM(E54:E57) -> 18 | V21: =SUM(F54:F57) -> 24 | W21: =SUM(G54:G57) -> 0 | X21: =SUM(H54:H57) -> 0 | Y21: =SUM(I54:I57) -> 9 | Z21: =SUM(J54:J57) -> 5 | ... AF21: =SUM(P54:P57) -> 459
B22: 10.00 - 10.15 | C22: 32 | D22: 10 | E22: 3 | F22: 2 | G22: 0 | H22: 0 | I22: 4 | J22: 0 | K22: 0 | L22: 0 | M22: 60 | N22: 0 | O22: =SUM(C22:L22,N22) -> 51 | P22: =SUM(C22:N22) -> 111 | R22: AM Peak Hr | S22: =MAX(S10:S12) -> 310 | T22: =MAX(T10:T12) -> 96 | U22: =MAX(U10:U12) -> 53 | V22: =MAX(V10:V12) -> 16 | W22: =MAX(W10:W12) -> 2 | X22: =MAX(X10:X12) -> 0 | Y22: =MAX(Y10:Y12) -> 33 | Z22: =MAX(Z10:Z12) -> 3 | ... AF22: =MAX(AF10:AF12) -> 811
B23: 10.15 - 10.30 | C23: 34 | D23: 19 | E23: 9 | F23: 1 | G23: 0 | H23: 0 | I23: 5 | J23: 0 | K23: 0 | L23: 0 | M23: 53 | N23: 0 | O23: =SUM(C23:L23,N23) -> 68 | P23: =SUM(C23:N23) -> 121 | R23: IP Peak Hr | S23: =MAX(S13:S18) -> 123 | T23: =MAX(T13:T18) -> 45 | U23: =MAX(U13:U18) -> 26 | V23: =MAX(V13:V18) -> 13 | W23: =MAX(W13:W18) -> 0 | X23: =MAX(X13:X18) -> 0 | Y23: =MAX(Y13:Y18) -> 18 | Z23: =MAX(Z13:Z18) -> 8 | ... AF23: =MAX(AF13:AF18) -> 459
B24: 10.30 - 10.45 | C24: 26 | D24: 10 | E24: 9 | F24: 1 | G24: 0 | H24: 0 | I24: 3 | J24: 1 | K24: 1 | L24: 0 | M24: 70 | N24: 0 | O24: =SUM(C24:L24,N24) -> 51 | P24: =SUM(C24:N24) -> 121 | R24: PM Peak Hr | S24: =MAX(S19:S21) -> 128 | T24: =MAX(T19:T21) -> 58 | U24: =MAX(U19:U21) -> 30 | V24: =MAX(V19:V21) -> 24 | W24: =MAX(W19:W21) -> 3 | X24: =MAX(X19:X21) -> 2 | Y24: =MAX(Y19:Y21) -> 23 | Z24: =MAX(Z19:Z21) -> 5 | ... AF24: =MAX(AF19:AF21) -> 493
B25: 10.45 - 11.00 | C25: 31 | D25: 6 | E25: 3 | F25: 2 | G25: 0 | H25: 0 | I25: 4 | J25: 0 | K25: 0 | L25: 0 | M25: 60 | N25: 0 | O25: =SUM(C25:L25,N25) -> 46 | P25: =SUM(C25:N25) -> 106 | R25: AM Period | S25: =SUM(S10:S12) -> 771 | T25: =SUM(T10:T12) -> 237 | U25: =SUM(U10:U12) -> 123 | V25: =SUM(V10:V12) -> 29 | W25: =SUM(W10:W12) -> 3 | X25: =SUM(X10:X12) -> 0 | Y25: =SUM(Y10:Y12) -> 54 | Z25: =SUM(Z10:Z12) -> 7 | ... AF25: =SUM(AF10:AF12) -> 2121
B26: 11.00 - 11.15 | C26: 35 | D26: 10 | E26: 3 | F26: 3 | G26: 0 | H26: 0 | I26: 3 | J26: 0 | K26: 0 | L26: 0 | M26: 65 | N26: 0 | O26: =SUM(C26:L26,N26) -> 54 | P26: =SUM(C26:N26) -> 119 | R26: IP Period | S26: =SUM(S13:S18) -> 634 | T26: =SUM(T13:T18) -> 196 | U26: =SUM(U13:U18) -> 135 | V26: =SUM(V13:V18) -> 60 | W26: =SUM(W13:W18) -> 0 | X26: =SUM(X13:X18) -> 0 | Y26: =SUM(Y13:Y18) -> 77 | Z26: =SUM(Z13:Z18) -> 18 | ... AF26: =SUM(AF13:AF18) -> 2255
B27: 11.15 - 11.30 | C27: 25 | D27: 6 | E27: 5 | F27: 1 | G27: 0 | H27: 0 | I27: 7 | J27: 0 | K27: 1 | L27: 1 | M27: 68 | N27: 0 | O27: =SUM(C27:L27,N27) -> 46 | P27: =SUM(C27:N27) -> 114 | R27: PM Period | S27: =SUM(S19:S21) -> 364 | T27: =SUM(T19:T21) -> 147 | U27: =SUM(U19:U21) -> 74 | V27: =SUM(V19:V21) -> 67 | W27: =SUM(W19:W21) -> 6 | X27: =SUM(X19:X21) -> 2 | Y27: =SUM(Y19:Y21) -> 41 | Z27: =SUM(Z19:Z21) -> 15 | ... AF27: =SUM(AF19:AF21) -> 1394
B28: 11.30 - 11.45 | C28: 25 | D28: 6 | E28: 4 | F28: 5 | G28: 0 | H28: 0 | I28: 4 | J28: 0 | K28: 0 | L28: 1 | M28: 57 | N28: 0 | O28: =SUM(C28:L28,N28) -> 45 | P28: =SUM(C28:N28) -> 102 | R28: 12 Hours | S28: =SUM(S10:S21) -> 1769 | T28: =SUM(T10:T21) -> 580 | U28: =SUM(U10:U21) -> 332 | V28: =SUM(V10:V21) -> 156 | W28: =SUM(W10:W21) -> 9 | X28: =SUM(X10:X21) -> 2 | Y28: =SUM(Y10:Y21) -> 172 | Z28: =SUM(Z10:Z21) -> 40 | ... AF28: =SUM(AF10:AF21) -> 5770
B29: 11.45 - 12.00 | C29: 28 | D29: 5 | E29: 5 | F29: 3 | G29: 0 | H29: 0 | I29: 3 | J29: 0 | K29: 0 | L29: 0 | M29: 45 | N29: 0 | O29: =SUM(C29:L29,N29) -> 44 | P29: =SUM(C29:N29) -> 89
B30: 12.00 - 12.15 | C30: 27 | D30: 5 | E30: 8 | F30: 1 | G30: 0 | H30: 0 | I30: 7 | J30: 0 | K30: 0 | L30: 0 | M30: 46 | N30: 0 | O30: =SUM(C30:L30,N30) -> 48 | P30: =SUM(C30:N30) -> 94
B31: 12.15 - 12.30 | C31: 24 | D31: 6 | E31: 1 | F31: 3 | G31: 0 | H31: 0 | I31: 3 | J31: 0 | K31: 0 | L31: 0 | M31: 55 | N31: 0 | O31: =SUM(C31:L31,N31) -> 37 | P31: =SUM(C31:N31) -> 92
B32: 12.30 - 12.45 | C32: 20 | D32: 2 | E32: 5 | F32: 6 | G32: 0 | H32: 0 | I32: 5 | J32: 2 | K32: 1 | L32: 0 | M32: 43 | N32: 0 | O32: =SUM(C32:L32,N32) -> 41 | P32: =SUM(C32:N32) -> 84
B33: 12.45 - 13.00 | C33: 35 | D33: 2 | E33: 12 | F33: 3 | G33: 0 | H33: 0 | I33: 3 | J33: 1 | K33: 0 | L33: 0 | M33: 38 | N33: 0 | O33: =SUM(C33:L33,N33) -> 56 | P33: =SUM(C33:N33) -> 94
B34: 13.00 - 13.15 | C34: 20 | D34: 8 | E34: 4 | F34: 2 | G34: 0 | H34: 0 | I34: 3 | J34: 0 | K34: 0 | L34: 0 | M34: 35 | N34: 0 | O34: =SUM(C34:L34,N34) -> 37 | P34: =SUM(C34:N34) -> 72
B35: 13.15 - 13.30 | C35: 27 | D35: 10 | E35: 5 | F35: 3 | G35: 0 | H35: 0 | I35: 1 | J35: 1 | K35: 1 | L35: 0 | M35: 42 | N35: 0 | O35: =SUM(C35:L35,N35) -> 48 | P35: =SUM(C35:N35) -> 90
B36: 13.30 - 13.45 | C36: 32 | D36: 13 | E36: 7 | F36: 4 | G36: 0 | H36: 0 | I36: 2 | J36: 1 | K36: 1 | L36: 0 | M36: 32 | N36: 0 | O36: =SUM(C36:L36,N36) -> 60 | P36: =SUM(C36:N36) -> 92
B37: 13.45 - 14.00 | C37: 25 | D37: 6 | E37: 3 | F37: 2 | G37: 0 | H37: 0 | I37: 2 | J37: 2 | K37: 0 | L37: 0 | M37: 38 | N37: 0 | O37: =SUM(C37:L37,N37) -> 40 | P37: =SUM(C37:N37) -> 78
B38: 14.00 - 14.15 | C38: 21 | D38: 10 | E38: 0 | F38: 2 | G38: 0 | H38: 0 | I38: 0 | J38: 2 | K38: 0 | L38: 0 | M38: 41 | N38: 0 | O38: =SUM(C38:L38,N38) -> 35 | P38: =SUM(C38:N38) -> 76
B39: 14.15 - 14.30 | C39: 25 | D39: 17 | E39: 17 | F39: 4 | G39: 0 | H39: 0 | I39: 3 | J39: 3 | K39: 0 | L39: 0 | M39: 35 | N39: 0 | O39: =SUM(C39:L39,N39) -> 69 | P39: =SUM(C39:N39) -> 104
B40: 14.30 - 14.45 | C40: 20 | D40: 5 | E40: 3 | F40: 3 | G40: 0 | H40: 0 | I40: 5 | J40: 3 | K40: 4 | L40: 0 | M40: 33 | N40: 0 | O40: =SUM(C40:L40,N40) -> 43 | P40: =SUM(C40:N40) -> 76
... B57: 18.45 - 19.00 | C57: 37 | D57: 5 | E57: 2 | F57: 4 | G57: 0 | H57: 0 | I57: 6 | J57: 3 | K57: 0 | L57: 0 | M57: 55 | N57: 0 | O57: =SUM(C57:L57,N57) -> 57 | P57: =SUM(C57:N57) -> 112
B58: Totals | C58: =SUM(C10:C57) -> 1769 | D58: =SUM(D10:D57) -> 580 | E58: =SUM(E10:E57) -> 332 | F58: =SUM(F10:F57) -> 156 | G58: =SUM(G10:G57) -> 9 | H58: =SUM(H10:H57) -> 2 | I58: =SUM(I10:I57) -> 172 | J58: =SUM(J10:J57) -> 40 | ... P58: =SUM(P10:P57) -> 5770
...

Sheet 29.07 Bukoto-Kyebando
B1: Consultancy services for Preparation of Expressway Development Master Plan (EDMP) for Uganda
B2: MANUAL CLASSIFIED COUNT (MCC)
B3: ROAD NAME: | C3: ='29.07 Kyebando-Bukoto'!C3:G3 -> MCC - C1 - STN30 - KYEBANDO - KISALOSALO ROAD
C5: Date | D5: ='29.07 Kyebando-Bukoto'!D5 -> 29.07.19 | F5: Location | G5: ='29.07 Kyebando-Bukoto'!G5:H5 -> Kyebando Round | J5: Surveyor | K5: Ahimbisibwe Godfrey
C6: Dir. From | D6: Bukoto | F6: Dir. To | G6: Kyebando | J6: Supervisor | K6: ='29.07 Kyebando-Bukoto'!K6:L6 -> STEVEN
B8: Time / Veh Type | R8: SUMMARY TRAFFIC VOLUMES
C9: 1. Car | D9: 2. Station Wagon | E9: 3. Pickups | F9: 4. Minibus, matatu | G9: 5. Medium bus | H9: 6. Large Bus | I9: 7. Light Truck | J9: 8. Medium Truck | K9: 9. Heavy truck | L9: 10. Truck Trailer | M9: 11. Motor cycles | N9: 12. Tractors | O9: Total Excl M/Cycles | P9: Total All | R9: Time | S9: 1. Car | T9: 2. Station Wagon | U9: 3. Pickups | V9: 4. Minibus, matatu | W9: 5. Medium bus | X9: 6. Large Bus | Y9: 7. Light Truck | Z9: 8. Medium Truck | AA9: 9. Heavy truck | AB9: 10. Truck Trailer | AC9: 11. Motorcycles | AD9: 12. Tractors, Graders | AE9: Total Excl M/ Cycles | AF9: Total All
B10: 07.00 - 07.15 | C10: 10 | D10: 7 | E10: 1 | F10: 3 | G10: 0 | H10: 0 | I10: 0 | J10: 0 | K10: 1 | L10: 0 | M10: 47 | N10: 0 | O10: =SUM(C10:L10,N10) -> 22 | P10: =SUM(C10:N10) -> 69 | R10: 0700-0800 | S10: =SUM(C10:C13) -> 56 | T10: =SUM(D10:D13) -> 43 | U10: =SUM(E10:E13) -> 12 | V10: =SUM(F10:F13) -> 6 | W10: =SUM(G10:G13) -> 1 | X10: =SUM(H10:H13) -> 0 | Y10: =SUM(I10:I13) -> 0 | Z10: =SUM(J10:J13) -> 3 | ... AF10: =SUM(P10:P13) -> 389
B11: 07.15 - 07.30 | C11: 16 | D11: 10 | E11: 3 | F11: 0 | G11: 1 | H11: 0 | I11: 0 | J11: 0 | K11: 0 | L11: 0 | M11: 59 | N11: 0 | O11: =SUM(C11:L11,N11) -> 30 | P11: =SUM(C11:N11) -> 89 | R11: 0800-0900 | S11: =SUM(C14:C17) -> 44 | T11: =SUM(D14:D17) -> 17 | U11: =SUM(E14:E17) -> 18 | V11: =SUM(F14:F17) -> 7 | W11: =SUM(G14:G17) -> 1 | X11: =SUM(H14:H17) -> 0 | Y11: =SUM(I14:I17) -> 10 | Z11: =SUM(J14:J17) -> 2 | ... AF11: =SUM(P14:P17) -> 427
B12: 07.30 - 07.45 | C12: 17 | D12: 12 | E12: 4 | F12: 0 | G12: 0 | H12: 0 | I12: 0 | J12: 1 | K12: 2 | L12: 0 | M12: 64 | N12: 0 | O12: =SUM(C12:L12,N12) -> 36 | P12: =SUM(C12:N12) -> 100 | R12: 0900-1000 | S12: =SUM(C18:C21) -> 59 | T12: =SUM(D18:D21) -> 49 | U12: =SUM(E18:E21) -> 14 | V12: =SUM(F18:F21) -> 13 | W12: =SUM(G18:G21) -> 0 | X12: =SUM(H18:H21) -> 0 | Y12: =SUM(I18:I21) -> 9 | Z12: =SUM(J18:J21) -> 6 | ... AF12: =SUM(P18:P21) -> 525
B13: 07.45 - 08.00 | C13: 13 | D13: 14 | E13: 4 | F13: 3 | G13: 0 | H13: 0 | I13: 0 | J13: 2 | K13: 1 | L13: 0 | M13: 94 | N13: 0 | O13: =SUM(C13:L13,N13) -> 37 | P13: =SUM(C13:N13) -> 131 | R13: 1000-1100 | S13: =SUM(C22:C25) -> 68 | T13: =SUM(D22:D25) -> 41 | U13: =SUM(E22:E25) -> 17 | V13: =SUM(F22:F25) -> 5 | W13: =SUM(G22:G25) -> 0 | X13: =SUM(H22:H25) -> 0 | Y13: =SUM(I22:I25) -> 7 | Z13: =SUM(J22:J25) -> 12 | ... AF13: =SUM(P22:P25) -> 414
B14: 08.00 - 08.15 | C14: 1 | D14: 3 | E14: 2 | F14: 2 | G14: 0 | H14: 0 | I14: 1 | J14: 1 | K14: 0 | L14: 0 | M14: 53 | N14: 0 | O14: =SUM(C14:L14,N14) -> 10 | P14: =SUM(C14:N14) -> 63 | R14: 1100-1200 | S14: =SUM(C26:C29) -> 57 | T14: =SUM(D26:D29) -> 39 | U14: =SUM(E26:E29) -> 16 | V14: =SUM(F26:F29) -> 10 | W14: =SUM(G26:G29) -> 0 | X14: =SUM(H26:H29) -> 0 | Y14: =SUM(I26:I29) -> 8 | Z14: =SUM(J26:J29) -> 9 | ... AF14: =SUM(P26:P29) -> 421
B15: 08.15 - 08.30 | C15: 20 | D15: 2 | E15: 8 | F15: 3 | G15: 1 | H15: 0 | I15: 6 | J15: 0 | K15: 2 | L15: 0 | M15: 79 | N15: 0 | O15: =SUM(C15:L15,N15) -> 42 | P15: =SUM(C15:N15) -> 121 | R15: 1200-1300 | S15: =SUM(C30:C33) -> 61 | T15: =SUM(D30:D33) -> 31 | U15: =SUM(E30:E33) -> 23 | V15: =SUM(F30:F33) -> 22 | W15: =SUM(G30:G33) -> 0 | X15: =SUM(H30:H33) -> 4 | Y15: =SUM(I30:I33) -> 11 | Z15: =SUM(J30:J33) -> 7 | ... AF15: =SUM(P30:P33) -> 409
B16: 08.30 - 08.45 | C16: 13 | D16: 6 | E16: 5 | F16: 0 | G16: 0 | H16: 0 | I16: 1 | J16: 0 | K16: 1 | L16: 0 | M16: 83 | N16: 0 | O16: =SUM(C16:L16,N16) -> 26 | P16: =SUM(C16:N16) -> 109 | R16: 1300-1400 | S16: =SUM(C34:C37) -> 83 | T16: =SUM(D34:D37) -> 20 | U16: =SUM(E34:E37) -> 11 | V16: =SUM(F34:F37) -> 33 | W16: =SUM(G34:G37) -> 0 | X16: =SUM(H34:H37) -> 0 | Y16: =SUM(I34:I37) -> 6 | Z16: =SUM(J34:J37) -> 8 | ... AF16: =SUM(P34:P37) -> 432
B17: 08.45 - 9.00 | C17: 10 | D17: 6 | E17: 3 | F17: 2 | G17: 0 | H17: 0 | I17: 2 | J17: 1 | K17: 1 | L17: 0 | M17: 109 | N17: 0 | O17: =SUM(C17:L17,N17) -> 25 | P17: =SUM(C17:N17) -> 134 | R17: 1400-1500 | S17: =SUM(C38:C41) -> 44 | T17: =SUM(D38:D41) -> 22 | U17: =SUM(E38:E41) -> 21 | V17: =SUM(F38:F41) -> 26 | W17: =SUM(G38:G41) -> 0 | X17: =SUM(H38:H41) -> 1 | Y17: =SUM(I38:I41) -> 9 | Z17: =SUM(J38:J41) -> 3 | ... AF17: =SUM(P38:P41) -> 339
B18: 09.00 - 09.15 | C18: 11 | D18: 14 | E18: 6 | F18: 3 | G18: 0 | H18: 0 | I18: 3 | J18: 3 | K18: 1 | L18: 0 | M18: 117 | N18: 0 | O18: =SUM(C18:L18,N18) -> 41 | P18: =SUM(C18:N18) -> 158 | R18: 1500-1600 | S18: =SUM(C42:C45) -> 60 | T18: =SUM(D42:D45) -> 41 | U18: =SUM(E42:E45) -> 19 | V18: =SUM(F42:F45) -> 18 | W18: =SUM(G42:G45) -> 0 | X18: =SUM(H42:H45) -> 1 | Y18: =SUM(I42:I45) -> 8 | Z18: =SUM(J42:J45) -> 11 | ... AF18: =SUM(P42:P45) -> 383
B19: 09.15 - 09.30 | C19: 17 | D19: 8 | E19: 4 | F19: 6 | G19: 0 | H19: 0 | I19: 2 | J19: 3 | K19: 2 | L19: 0 | M19: 104 | N19: 0 | O19: =SUM(C19:L19,N19) -> 42 | P19: =SUM(C19:N19) -> 146 | R19: 1600-1700 | S19: =SUM(C46:C49) -> 96 | T19: =SUM(D46:D49) -> 58 | U19: =SUM(E46:E49) -> 29 | V19: =SUM(F46:F49) -> 12 | W19: =SUM(G46:G49) -> 5 | X19: =SUM(H46:H49) -> 1 | Y19: =SUM(I46:I49) -> 15 | Z19: =SUM(J46:J49) -> 4 | ... AF19: =SUM(P46:P49) -> 424
B20: 09.30 - 09.45 | C20: 23 | D20: 14 | E20: 3 | F20: 3 | G20: 0 | H20: 0 | I20: 4 | J20: 0 | K20: 1 | L20: 0 | M20: 97 | N20: 0 | O20: =SUM(C20:L20,N20) -> 48 | P20: =SUM(C20:N20) -> 145 | R20: 1700-1800 | S20: =SUM(C50:C53) -> 173 | T20: =SUM(D50:D53) -> 109 | U20: =SUM(E50:E53) -> 28 | V20: =SUM(F50:F53) -> 42 | W20: =SUM(G50:G53) -> 0 | X20: =SUM(H50:H53) -> 0 | Y20: =SUM(I50:I53) -> 9 | Z20: =SUM(J50:J53) -> 10 | ... AF20: =SUM(P50:P53) -> 696
B21: 09.45 - 10.00 | C21: 8 | D21: 13 | E21: 1 | F21: 1 | G21: 0 | H21: 0 | I21: 0 | J21: 0 | K21: 1 | L21: 0 | M21: 52 | N21: 0 | O21: =SUM(C21:L21,N21) -> 24 | P21: =SUM(C21:N21) -> 76 | R21: 1800-1900 | S21: =SUM(C54:C57) -> 163 | T21: =SUM(D54:D57) -> 121 | U21: =SUM(E54:E57) -> 24 | V21: =SUM(F54:F57) -> 53 | W21: =SUM(G54:G57) -> 0 | X21: =SUM(H54:H57) -> 0 | Y21: =SUM(I54:I57) -> 5 | Z21: =SUM(J54:J57) -> 6 | ... AF21: =SUM(P54:P57) -> 712
B22: 10.00 - 10.15 | C22: 27 | D22: 11 | E22: 3 | F22: 2 | G22: 0 | H22: 0 | I22: 3 | J22: 5 | K22: 3 | L22: 0 | M22: 84 | N22: 0 | O22: =SUM(C22:L22,N22) -> 54 | P22: =SUM(C22:N22) -> 138 | R22: AM Peak Hr | S22: =MAX(S10:S12) -> 59 | T22: =MAX(T10:T12) -> 49 | U22: =MAX(U10:U12) -> 18 | V22: =MAX(V10:V12) -> 13 | W22: =MAX(W10:W12) -> 1 | X22: =MAX(X10:X12) -> 0 | Y22: =MAX(Y10:Y12) -> 10 | Z22: =MAX(Z10:Z12) -> 6 | ... AF22: =MAX(AF10:AF12) -> 525
B23: 10.15 - 10.30 | C23: 23 | D23: 7 | E23: 4 | F23: 1 | G23: 0 | H23: 0 | I23: 2 | J23: 0 | K23: 3 | L23: 0 | M23: 40 | N23: 0 | O23: =SUM(C23:L23,N23) -> 40 | P23: =SUM(C23:N23) -> 80 | R23: IP Peak Hr | S23: =MAX(S13:S18) -> 83 | T23: =MAX(T13:T18) -> 41 | U23: =MAX(U13:U18) -> 23 | V23: =MAX(V13:V18) -> 33 | W23: =MAX(W13:W18) -> 0 | X23: =MAX(X13:X18) -> 4 | Y23: =MAX(Y13:Y18) -> 11 | Z23: =MAX(Z13:Z18) -> 12 | ... AF23: =MAX(AF13:AF18) -> 432
B24: 10.30 - 10.45 | C24: 8 | D24: 6 | E24: 5 | F24: 0 | G24: 0 | H24: 0 | I24: 1 | J24: 1 | K24: 1 | L24: 0 | M24: 77 | N24: 0 | O24: =SUM(C24:L24,N24) -> 22 | P24: =SUM(C24:N24) -> 99 | R24: PM Peak Hr | S24: =MAX(S19:S21) -> 173 | T24: =MAX(T19:T21) -> 121 | U24: =MAX(U19:U21) -> 29 | V24: =MAX(V19:V21) -> 53 | W24: =MAX(W19:W21) -> 5 | X24: =MAX(X19:X21) -> 1 | Y24: =MAX(Y19:Y21) -> 15 | Z24: =MAX(Z19:Z21) -> 10 | ... AF24: =MAX(AF19:AF21) -> 712
B25: 10.45 - 11.00 | C25: 10 | D25: 17 | E25: 5 | F25: 2 | G25: 0 | H25: 0 | I25: 1 | J25: 6 | K25: 0 | L25: 0 | M25: 56 | N25: 0 | O25: =SUM(C25:L25,N25) -> 41 | P25: =SUM(C25:N25) -> 97 | R25: AM Period | S25: =SUM(S10:S12) -> 159 | T25: =SUM(T10:T12) -> 109 | U25: =SUM(U10:U12) -> 44 | V25: =SUM(V10:V12) -> 26 | W25: =SUM(W10:W12) -> 2 | X25: =SUM(X10:X12) -> 0 | Y25: =SUM(Y10:Y12) -> 19 | Z25: =SUM(Z10:Z12) -> 11 | ... AF25: =SUM(AF10:AF12) -> 1341
B26: 11.00 - 11.15 | C26: 10 | D26: 3 | E26: 5 | F26: 1 | G26: 0 | H26: 0 | I26: 5 | J26: 4 | K26: 1 | L26: 0 | M26: 75 | N26: 0 | O26: =SUM(C26:L26,N26) -> 29 | P26: =SUM(C26:N26) -> 104 | R26: IP Period | S26: =SUM(S13:S18) -> 373 | T26: =SUM(T13:T18) -> 194 | U26: =SUM(U13:U18) -> 107 | V26: =SUM(V13:V18) -> 114 | W26: =SUM(W13:W18) -> 0 | X26: =SUM(X13:X18) -> 6 | Y26: =SUM(Y13:Y18) -> 49 | Z26: =SUM(Z13:Z18) -> 50 | ... AF26: =SUM(AF13:AF18) -> 2398
B27: 11.15 - 11.30 | C27: 13 | D27: 5 | E27: 2 | F27: 1 | G27: 0 | H27: 0 | I27: 2 | J27: 0 | K27: 0 | L27: 0 | M27: 54 | N27: 0 | O27: =SUM(C27:L27,N27) -> 23 | P27: =SUM(C27:N27) -> 77 | R27: PM Period | S27: =SUM(S19:S21) -> 432 | T27: =SUM(T19:T21) -> 288 | U27: =SUM(U19:U21) -> 81 | V27: =SUM(V19:V21) -> 107 | W27: =SUM(W19:W21) -> 5 | X27: =SUM(X19:X21) -> 1 | Y27: =SUM(Y19:Y21) -> 29 | Z27: =SUM(Z19:Z21) -> 20 | ... AF27: =SUM(AF19:AF21) -> 1832
B28: 11.30 - 11.45 | C28: 12 | D28: 15 | E28: 5 | F28: 5 | G28: 0 | H28: 0 | I28: 0 | J28: 3 | K28: 1 | L28: 0 | M28: 73 | N28: 0 | O28: =SUM(C28:L28,N28) -> 41 | P28: =SUM(C28:N28) -> 114 | R28: 12 Hours | S28: =SUM(S10:S21) -> 964 | T28: =SUM(T10:T21) -> 591 | U28: =SUM(U10:U21) -> 232 | V28: =SUM(V10:V21) -> 247 | W28: =SUM(W10:W21) -> 7 | X28: =SUM(X10:X21) -> 7 | Y28: =SUM(Y10:Y21) -> 97 | Z28: =SUM(Z10:Z21) -> 81 | ... AF28: =SUM(AF10:AF21) -> 5571
B29: 11.45 - 12.00 | C29: 22 | D29: 16 | E29: 4 | F29: 3 | G29: 0 | H29: 0 | I29: 1 | J29: 2 | K29: 1 | L29: 0 | M29: 77 | N29: 0 | O29: =SUM(C29:L29,N29) -> 49 | P29: =SUM(C29:N29) -> 126
B30: 12.00 - 12.15 | C30: 12 | D30: 8 | E30: 4 | F30: 5 | G30: 0 | H30: 2 | I30: 1 | J30: 2 | K30: 5 | L30: 0 | M30: 65 | N30: 0 | O30: =SUM(C30:L30,N30) -> 39 | P30: =SUM(C30:N30) -> 104
B31: 12.15 - 12.30 | C31: 12 | D31: 5 | E31: 2 | F31: 2 | G31: 0 | H31: 0 | I31: 7 | J31: 0 | K31: 0 | L31: 0 | M31: 64 | N31: 0 | O31: =SUM(C31:L31,N31) -> 28 | P31: =SUM(C31:N31) -> 92
B32: 12.30 - 12.45 | C32: 24 | D32: 6 | E32: 7 | F32: 8 | G32: 0 | H32: 0 | I32: 3 | J32: 3 | K32: 0 | L32: 0 | M32: 78 | N32: 0 | O32: =SUM(C32:L32,N32) -> 51 | P32: =SUM(C32:N32) -> 129
B33: 12.45 - 13.00 | C33: 13 | D33: 12 | E33: 10 | F33: 7 | G33: 0 | H33: 2 | I33: 0 | J33: 2 | K33: 0 | L33: 0 | M33: 38 | N33: 0 | O33: =SUM(C33:L33,N33) -> 46 | P33: =SUM(C33:N33) -> 84
B34: 13.00 - 13.15 | C34: 14 | D34: 13 | E34: 2 | F34: 11 | G34: 0 | H34: 0 | I34: 2 | J34: 5 | K34: 2 | L34: 0 | M34: 67 | N34: 0 | O34: =SUM(C34:L34,N34) -> 49 | P34: =SUM(C34:N34) -> 116
B35: 13.15 - 13.30 | C35: 23 | D35: 0 | E35: 6 | F35: 7 | G35: 0 | H35: 0 | I35: 1 | J35: 1 | K35: 0 | L35: 0 | M35: 67 | N35: 0 | O35: =SUM(C35:L35,N35) -> 38 | P35: =SUM(C35:N35) -> 105
B36: 13.30 - 13.45 | C36: 28 | D36: 3 | E36: 3 | F36: 11 | G36: 0 | H36: 0 | I36: 3 | J36: 1 | K36: 0 | L36: 0 | M36: 66 | N36: 0 | O36: =SUM(C36:L36,N36) -> 49 | P36: =SUM(C36:N36) -> 115
B37: 13.45 - 14.00 | C37: 18 | D37: 4 | E37: 0 | F37: 4 | G37: 0 | H37: 0 | I37: 0 | J37: 1 | K37: 2 | L37: 0 | M37: 67 | N37: 0 | O37: =SUM(C37:L37,N37) -> 29 | P37: =SUM(C37:N37) -> 96
B38: 14.00 - 14.15 | C38: 18 | D38: 7 | E38: 2 | F38: 11 | G38: 0 | H38: 1 | I38: 2 | J38: 1 | K38: 0 | L38: 0 | M38: 83 | N38: 0 | O38: =SUM(C38:L38,N38) -> 42 | P38: =SUM(C38:N38) -> 125
B39: 14.15 - 14.30 | C39: 8 | D39: 5 | E39: 13 | F39: 4 | G39: 0 | H39: 0 | I39: 6 | J39: 2 | K39: 1 | L39: 0 | M39: 53 | N39: 0 | O39: =SUM(C39:L39,N39) -> 39 | P39: =SUM(C39:N39) -> 92
B40: 14.30 - 14.45 | C40: 7 | D40: 3 | E40: 1 | F40: 2 | G40: 0 | H40: 0 | I40: 0 | J40: 0 | K40: 1 | L40: 0 | M40: 35 | N40: 0 | O40: =SUM(C40:L40,N40) -> 14 | P40: =SUM(C40:N40) -> 49
... B57: 18.45 - 19.00 | C57: 36 | D57: 16 | E57: 4 | F57: 8 | G57: 0 | H57: 0 | I57: 2 | J57: 1 | K57: 0 | L57: 0 | M57: 64 | N57: 0 | O57: =SUM(C57:L57,N57) -> 67 | P57: =SUM(C57:N57) -> 131
B58: Totals | C58: =SUM(C10:C57) -> 964 | D58: =SUM(D10:D57) -> 591 | E58: =SUM(E10:E57) -> 232 | F58: =SUM(F10:F57) -> 247 | G58: =SUM(G10:G57) -> 7 | H58: =SUM(H10:H57) -> 7 | I58: =SUM(I10:I57) -> 97 | J58: =SUM(J10:J57) -> 81 | ... P58: =SUM(P10:P57) -> 5571
...

Sheet 30.07 Kyebando-Bukoto
B1: Consultancy services for Preparation of Expressway Development Master Plan (EDMP) for Uganda
B2: MANUAL CLASSIFIED COUNT (MCC)
B3: ROAD NAME: | C3: ='29.07 Kyebando-Bukoto'!C3:G3 -> MCC - C1 - STN30 - KYEBANDO - KISALOSALO ROAD
C5: Date | D5: 30.07.19 | F5: Location | G5: ='29.07 Kyebando-Bukoto'!G5:H5 -> Kyebando Round | J5: Surveyor | K5: ='29.07 Kyebando-Bukoto'!K5:L5 -> AHISIBWE SARAH
C6: Dir. From | D6: ='29.07 Kyebando-Bukoto'!D6:E6 -> Kyebando | F6: Dir. To | G6: ='29.07 Kyebando-Bukoto'!G6:H6 -> Bukoto | J6: Supervisor | K6: ='29.07 Kyebando-Bukoto'!K6:L6 -> STEVEN
B8: Time / Veh Type | R8: SUMMARY TRAFFIC VOLUMES
C9: 1. Car | D9: 2. Station Wagon | E9: 3. Pickups | F9: 4. Minibus, matatu | G9: 5. Medium bus | H9: 6. Large Bus | I9: 7. Light Truck | J9: 8. Medium Truck | K9: 9. Heavy truck | L9: 10. Truck Trailer | M9: 11. Motor cycles | N9: 12. Tractors | O9: Total Excl M/Cycles | P9: Total All | R9: Time | S9: 1. Car | T9: 2. Station Wagon | U9: 3. Pickups | V9: 4. Minibus, matatu | W9: 5. Medium bus | X9: 6. Large Bus | Y9: 7. Light Truck | Z9: 8. Medium Truck | AA9: 9. Heavy truck | AB9: 10. Truck Trailer | AC9: 11. Motorcycles | AD9: 12. Tractors, Graders | AE9: Total Excl M/ Cycles | AF9: Total All
B10: 07.00 - 07.15 | C10: 0 | D10: 0 | E10: 0 | F10: 0 | G10: 0 | H10: 0 | I10: 0 | J10: 0 | K10: 0 | L10: 0 | M10: 0 | N10: 0 | O10: =SUM(C10:L10,N10) -> 0 | P10: =SUM(C10:N10) -> 0 | R10: 0700-0800 | S10: =SUM(C10:C13) -> 0 | T10: =SUM(D10:D13) -> 0 | U10: =SUM(E10:E13) -> 0 | V10: =SUM(F10:F13) -> 0 | W10: =SUM(G10:G13) -> 0 | X10: =SUM(H10:H13) -> 0 | Y10: =SUM(I10:I13) -> 0 | Z10: =SUM(J10:J13) -> 0 | ... AF10: =SUM(P10:P13) -> 0
B11: 07.15 - 07.30 | C11: 0 | D11: 0 | E11: 0 | F11: 0 | G11: 0 | H11: 0 | I11: 0 | J11: 0 | K11: 0 | L11: 0 | M11: 0 | N11: 0 | O11: =SUM(C11:L11,N11) -> 0 | P11: =SUM(C11:N11) -> 0 | R11: 0800-0900 | S11: =SUM(C14:C17) -> 0 | T11: =SUM(D14:D17) -> 0 | U11: =SUM(E14:E17) -> 0 | V11: =SUM(F14:F17) -> 0 | W11: =SUM(G14:G17) -> 0 | X11: =SUM(H14:H17) -> 0 | Y11: =SUM(I14:I17) -> 0 | Z11: =SUM(J14:J17) -> 0 | ... AF11: =SUM(P14:P17) -> 0
B12: 07.30 - 07.45 | C12: 0 | D12: 0 | E12: 0 | F12: 0 | G12: 0 | H12: 0 | I12: 0 | J12: 0 | K12: 0 | L12: 0 | M12: 0 | N12: 0 | O12: =SUM(C12:L12,N12) -> 0 | P12: =SUM(C12:N12) -> 0 | R12: 0900-1000 | S12: =SUM(C18:C21) -> 78 | T12: =SUM(D18:D21) -> 47 | U12: =SUM(E18:E21) -> 21 | V12: =SUM(F18:F21) -> 7 | W12: =SUM(G18:G21) -> 0 | X12: =SUM(H18:H21) -> 0 | Y12: =SUM(I18:I21) -> 9 | Z12: =SUM(J18:J21) -> 0 | ... AF12: =SUM(P18:P21) -> 291
B13: 07.45 - 08.00 | C13: 0 | D13: 0 | E13: 0 | F13: 0 | G13: 0 | H13: 0 | I13: 0 | J13: 0 | K13: 0 | L13: 0 | M13: 0 | N13: 0 | O13: =SUM(C13:L13,N13) -> 0 | P13: =SUM(C13:N13) -> 0 | R13: 1000-1100 | S13: =SUM(C22:C25) -> 77 | T13: =SUM(D22:D25) -> 62 | U13: =SUM(E22:E25) -> 23 | V13: =SUM(F22:F25) -> 11 | W13: =SUM(G22:G25) -> 0 | X13: =SUM(H22:H25) -> 0 | Y13: =SUM(I22:I25) -> 11 | Z13: =SUM(J22:J25) -> 0 | ... AF13: =SUM(P22:P25) -> 388
B14: 08.00 - 08.15 | C14: 0 | D14: 0 | E14: 0 | F14: 0 | G14: 0 | H14: 0 | I14: 0 | J14: 0 | K14: 0 | L14: 0 | M14: 0 | N14: 0 | O14: =SUM(C14:L14,N14) -> 0 | P14: =SUM(C14:N14) -> 0 | R14: 1100-1200 | S14: =SUM(C26:C29) -> 98 | T14: =SUM(D26:D29) -> 39 | U14: =SUM(E26:E29) -> 23 | V14: =SUM(F26:F29) -> 7 | W14: =SUM(G26:G29) -> 0 | X14: =SUM(H26:H29) -> 0 | Y14: =SUM(I26:I29) -> 4 | Z14: =SUM(J26:J29) -> 1 | ... AF14: =SUM(P26:P29) -> 364
B15: 08.15 - 08.30 | C15: 0 | D15: 0 | E15: 0 | F15: 0 | G15: 0 | H15: 0 | I15: 0 | J15: 0 | K15: 0 | L15: 0 | M15: 0 | N15: 0 | O15: =SUM(C15:L15,N15) -> 0 | P15: =SUM(C15:N15) -> 0 | R15: 1200-1300 | S15: =SUM(C30:C33) -> 104 | T15: =SUM(D30:D33) -> 36 | U15: =SUM(E30:E33) -> 32 | V15: =SUM(F30:F33) -> 4 | W15: =SUM(G30:G33) -> 0 | X15: =SUM(H30:H33) -> 0 | Y15: =SUM(I30:I33) -> 4 | Z15: =SUM(J30:J33) -> 8 | ... AF15: =SUM(P30:P33) -> 388
B16: 08.30 - 08.45 | C16: 0 | D16: 0 | E16: 0 | F16: 0 | G16: 0 | H16: 0 | I16: 0 | J16: 0 | K16: 0 | L16: 0 | M16: 0 | N16: 0 | O16: =SUM(C16:L16,N16) -> 0 | P16: =SUM(C16:N16) -> 0 | R16: 1300-1400 | S16: =SUM(C34:C37) -> 102 | T16: =SUM(D34:D37) -> 40 | U16: =SUM(E34:E37) -> 25 | V16: =SUM(F34:F37) -> 11 | W16: =SUM(G34:G37) -> 1 | X16: =SUM(H34:H37) -> 0 | Y16: =SUM(I34:I37) -> 7 | Z16: =SUM(J34:J37) -> 8 | ... AF16: =SUM(P34:P37) -> 403
B17: 08.45 - 9.00 | C17: 0 | D17: 0 | E17: 0 | F17: 0 | G17: 0 | H17: 0 | I17: 0 | J17: 0 | K17: 0 | L17: 0 | M17: 0 | N17: 0 | O17: =SUM(C17:L17,N17) -> 0 | P17: =SUM(C17:N17) -> 0 | R17: 1400-1500 | S17: =SUM(C38:C41) -> 82 | T17: =SUM(D38:D41) -> 50 | U17: =SUM(E38:E41) -> 29 | V17: =SUM(F38:F41) -> 8 | W17: =SUM(G38:G41) -> 0 | X17: =SUM(H38:H41) -> 0 | Y17: =SUM(I38:I41) -> 12 | Z17: =SUM(J38:J41) -> 5 | ... AF17: =SUM(P38:P41) -> 396
B18: 09.00 - 09.15 | C18: 0 | D18: 0 | E18: 0 | F18: 0 | G18: 0 | H18: 0 | I18: 0 | J18: 0 | K18: 0 | L18: 0 | M18: 0 | N18: 0 | O18: =SUM(C18:L18,N18) -> 0 | P18: =SUM(C18:N18) -> 0 | R18: 1500-1600 | S18: =SUM(C42:C45) -> 86 | T18: =SUM(D42:D45) -> 58 | U18: =SUM(E42:E45) -> 36 | V18: =SUM(F42:F45) -> 6 | W18: =SUM(G42:G45) -> 1 | X18: =SUM(H42:H45) -> 0 | Y18: =SUM(I42:I45) -> 7 | Z18: =SUM(J42:J45) -> 7 | ... AF18: =SUM(P42:P45) -> 390
B19: 09.15 - 09.30 | C19: 25 | D19: 19 | E19: 10 | F19: 2 | G19: 0 | H19: 0 | I19: 1 | J19: 0 | K19: 0 | L19: 0 | M19: 33 | N19: 0 | O19: =SUM(C19:L19,N19) -> 57 | P19: =SUM(C19:N19) -> 90 | R19: 1600-1700 | S19: =SUM(C46:C49) -> 110 | T19: =SUM(D46:D49) -> 63 | U19: =SUM(E46:E49) -> 45 | V19: =SUM(F46:F49) -> 7 | W19: =SUM(G46:G49) -> 0 | X19: =SUM(H46:H49) -> 0 | Y19: =SUM(I46:I49) -> 2 | Z19: =SUM(J46:J49) -> 3 | ... AF19: =SUM(P46:P49) -> 447
B20: 09.30 - 09.45 | C20: 20 | D20: 15 | E20: 5 | F20: 2 | G20: 0 | H20: 0 | I20: 3 | J20: 0 | K20: 0 | L20: 0 | M20: 33 | N20: 0 | O20: =SUM(C20:L20,N20) -> 45 | P20: =SUM(C20:N20) -> 78 | R20: 1700-1800 | S20: =SUM(C50:C53) -> 136 | T20: =SUM(D50:D53) -> 52 | U20: =SUM(E50:E53) -> 35 | V20: =SUM(F50:F53) -> 12 | W20: =SUM(G50:G53) -> 1 | X20: =SUM(H50:H53) -> 0 | Y20: =SUM(I50:I53) -> 1 | Z20: =SUM(J50:J53) -> 10 | ... AF20: =SUM(P50:P53) -> 449
B21: 09.45 - 10.00 | C21: 33 | D21: 13 | E21: 6 | F21: 3 | G21: 0 | H21: 0 | I21: 5 | J21: 0 | K21: 0 | L21: 0 | M21: 63 | N21: 0 | O21: =SUM(C21:L21,N21) -> 60 | P21: =SUM(C21:N21) -> 123 | R21: 1800-1900 | S21: =SUM(C54:C57) -> 87 | T21: =SUM(D54:D57) -> 38 | U21: =SUM(E54:E57) -> 28 | V21: =SUM(F54:F57) -> 9 | W21: =SUM(G54:G57) -> 4 | X21: =SUM(H54:H57) -> 1 | Y21: =SUM(I54:I57) -> 3 | Z21: =SUM(J54:J57) -> 10 | ... AF21: =SUM(P54:P57) -> 375
B22: 10.00 - 10.15 | C22: 15 | D22: 12 | E22: 7 | F22: 2 | G22: 0 | H22: 0 | I22: 3 | J22: 0 | K22: 0 | L22: 0 | M22: 45 | N22: 0 | O22: =SUM(C22:L22,N22) -> 39 | P22: =SUM(C22:N22) -> 84 | R22: AM Peak Hr | S22: =MAX(S10:S12) -> 78 | T22: =MAX(T10:T12) -> 47 | U22: =MAX(U10:U12) -> 21 | V22: =MAX(V10:V12) -> 7 | W22: =MAX(W10:W12) -> 0 | X22: =MAX(X10:X12) -> 0 | Y22: =MAX(Y10:Y12) -> 9 | Z22: =MAX(Z10:Z12) -> 0 | ... AF22: =MAX(AF10:AF12) -> 291
B23: 10.15 - 10.30 | C23: 22 | D23: 16 | E23: 5 | F23: 5 | G23: 0 | H23: 0 | I23: 2 | J23: 0 | K23: 3 | L23: 0 | M23: 59 | N23: 0 | O23: =SUM(C23:L23,N23) -> 53 | P23: =SUM(C23:N23) -> 112 | R23: IP Peak Hr | S23: =MAX(S13:S18) -> 104 | T23: =MAX(T13:T18) -> 62 | U23: =MAX(U13:U18) -> 36 | V23: =MAX(V13:V18) -> 11 | W23: =MAX(W13:W18) -> 1 | X23: =MAX(X13:X18) -> 0 | Y23: =MAX(Y13:Y18) -> 12 | Z23: =MAX(Z13:Z18) -> 8 | ... AF23: =MAX(AF13:AF18) -> 403
B24: 10.30 - 10.45 | C24: 15 | D24: 14 | E24: 3 | F24: 1 | G24: 0 | H24: 0 | I24: 3 | J24: 0 | K24: 0 | L24: 0 | M24: 35 | N24: 0 | O24: =SUM(C24:L24,N24) -> 36 | P24: =SUM(C24:N24) -> 71 | R24: PM Peak Hr | S24: =MAX(S19:S21) -> 136 | T24: =MAX(T19:T21) -> 63 | U24: =MAX(U19:U21) -> 45 | V24: =MAX(V19:V21) -> 12 | W24: =MAX(W19:W21) -> 4 | X24: =MAX(X19:X21) -> 1 | Y24: =MAX(Y19:Y21) -> 3 | Z24: =MAX(Z19:Z21) -> 10 | ... AF24: =MAX(AF19:AF21) -> 449
B25: 10.45 - 11.00 | C25: 25 | D25: 20 | E25: 8 | F25: 3 | G25: 0 | H25: 0 | I25: 3 | J25: 0 | K25: 2 | L25: 0 | M25: 60 | N25: 0 | O25: =SUM(C25:L25,N25) -> 61 | P25: =SUM(C25:N25) -> 121 | R25: AM Period | S25: =SUM(S10:S12) -> 78 | T25: =SUM(T10:T12) -> 47 | U25: =SUM(U10:U12) -> 21 | V25: =SUM(V10:V12) -> 7 | W25: =SUM(W10:W12) -> 0 | X25: =SUM(X10:X12) -> 0 | Y25: =SUM(Y10:Y12) -> 9 | Z25: =SUM(Z10:Z12) -> 0 | ... AF25: =SUM(AF10:AF12) -> 291
B26: 11.00 - 11.15 | C26: 32 | D26: 13 | E26: 1 | F26: 3 | G26: 0 | H26: 0 | I26: 0 | J26: 0 | K26: 1 | L26: 0 | M26: 35 | N26: 0 | O26: =SUM(C26:L26,N26) -> 50 | P26: =SUM(C26:N26) -> 85 | R26: IP Period | S26: =SUM(S13:S18) -> 549 | T26: =SUM(T13:T18) -> 285 | U26: =SUM(U13:U18) -> 168 | V26: =SUM(V13:V18) -> 47 | W26: =SUM(W13:W18) -> 2 | X26: =SUM(X13:X18) -> 0 | Y26: =SUM(Y13:Y18) -> 45 | Z26: =SUM(Z13:Z18) -> 29 | ... AF26: =SUM(AF13:AF18) -> 2329
B27: 11.15 - 11.30 | C27: 19 | D27: 7 | E27: 10 | F27: 0 | G27: 0 | H27: 0 | I27: 1 | J27: 0 | K27: 6 | L27: 0 | M27: 63 | N27: 0 | O27: =SUM(C27:L27,N27) -> 43 | P27: =SUM(C27:N27) -> 106 | R27: PM Period | S27: =SUM(S19:S21) -> 333 | T27: =SUM(T19:T21) -> 153 | U27: =SUM(U19:U21) -> 108 | V27: =SUM(V19:V21) -> 28 | W27: =SUM(W19:W21) -> 5 | X27: =SUM(X19:X21) -> 1 | Y27: =SUM(Y19:Y21) -> 6 | Z27: =SUM(Z19:Z21) -> 23 | ... AF27: =SUM(AF19:AF21) -> 1271
B28: 11.30 - 11.45 | C28: 25 | D28: 12 | E28: 10 | F28: 2 | G28: 0 | H28: 0 | I28: 1 | J28: 0 | K28: 2 | L28: 0 | M28: 40 | N28: 0 | O28: =SUM(C28:L28,N28) -> 52 | P28: =SUM(C28:N28) -> 92 | R28: 12 Hours | S28: =SUM(S10:S21) -> 960 | T28: =SUM(T10:T21) -> 485 | U28: =SUM(U10:U21) -> 297 | V28: =SUM(V10:V21) -> 82 | W28: =SUM(W10:W21) -> 7 | X28: =SUM(X10:X21) -> 1 | Y28: =SUM(Y10:Y21) -> 60 | Z28: =SUM(Z10:Z21) -> 52 | ... AF28: =SUM(AF10:AF21) -> 3891
B29: 11.45 - 12.00 | C29: 22 | D29: 7 | E29: 2 | F29: 2 | G29: 0 | H29: 0 | I29: 2 | J29: 1 | K29: 0 | L29: 0 | M29: 45 | N29: 0 | O29: =SUM(C29:L29,N29) -> 36 | P29: =SUM(C29:N29) -> 81
B30: 12.00 - 12.15 | C30: 23 | D30: 7 | E30: 7 | F30: 3 | G30: 0 | H30: 0 | I30: 2 | J30: 0 | K30: 2 | L30: 0 | M30: 52 | N30: 0 | O30: =SUM(C30:L30,N30) -> 44 | P30: =SUM(C30:N30) -> 96
B31: 12.15 - 12.30 | C31: 29 | D31: 13 | E31: 5 | F31: 0 | G31: 0 | H31: 0 | I31: 1 | J31: 1 | K31: 1 | L31: 0 | M31: 55 | N31: 0 | O31: =SUM(C31:L31,N31) -> 50 | P31: =SUM(C31:N31) -> 105
B32: 12.30 - 12.45 | C32: 23 | D32: 10 | E32: 13 | F32: 0 | G32: 0 | H32: 0 | I32: 0 | J32: 4 | K32: 0 | L32: 0 | M32: 35 | N32: 0 | O32: =SUM(C32:L32,N32) -> 50 | P32: =SUM(C32:N32) -> 85
B33: 12.45 - 13.00 | C33: 29 | D33: 6 | E33: 7 | F33: 1 | G33: 0 | H33: 0 | I33: 1 | J33: 3 | K33: 0 | L33: 0 | M33: 55 | N33: 0 | O33: =SUM(C33:L33,N33) -> 47 | P33: =SUM(C33:N33) -> 102
B34: 13.00 - 13.15 | C34: 31 | D34: 8 | E34: 8 | F34: 1 | G34: 1 | H34: 0 | I34: 2 | J34: 1 | K34: 0 | L34: 0 | M34: 50 | N34: 0 | O34: =SUM(C34:L34,N34) -> 52 | P34: =SUM(C34:N34) -> 102
B35: 13.15 - 13.30 | C35: 26 | D35: 12 | E35: 5 | F35: 3 | G35: 0 | H35: 0 | I35: 3 | J35: 3 | K35: 0 | L35: 0 | M35: 51 | N35: 0 | O35: =SUM(C35:L35,N35) -> 52 | P35: =SUM(C35:N35) -> 103
B36: 13.30 - 13.45 | C36: 25 | D36: 5 | E36: 6 | F36: 4 | G36: 0 | H36: 0 | I36: 1 | J36: 1 | K36: 0 | L36: 0 | M36: 45 | N36: 0 | O36: =SUM(C36:L36,N36) -> 42 | P36: =SUM(C36:N36) -> 87
B37: 13.45 - 14.00 | C37: 20 | D37: 15 | E37: 6 | F37: 3 | G37: 0 | H37: 0 | I37: 1 | J37: 3 | K37: 0 | L37: 0 | M37: 63 | N37: 0 | O37: =SUM(C37:L37,N37) -> 48 | P37: =SUM(C37:N37) -> 111
B38: 14.00 - 14.15 | C38: 10 | D38: 9 | E38: 6 | F38: 2 | G38: 0 | H38: 0 | I38: 2 | J38: 1 | K38: 0 | L38: 0 | M38: 40 | N38: 0 | O38: =SUM(C38:L38,N38) -> 30 | P38: =SUM(C38:N38) -> 70
B39: 14.15 - 14.30 | C39: 34 | D39: 12 | E39: 7 | F39: 3 | G39: 0 | H39: 0 | I39: 3 | J39: 0 | K39: 0 | L39: 0 | M39: 50 | N39: 0 | O39: =SUM(C39:L39,N39) -> 59 | P39: =SUM(C39:N39) -> 109
B40: 14.30 - 14.45 | C40: 18 | D40: 17 | E40: 5 | F40: 1 | G40: 0 | H40: 0 | I40: 5 | J40: 3 | K40: 0 | L40: 0 | M40: 60 | N40: 0 | O40: =SUM(C40:L40,N40) -> 49 | P40: =SUM(C40:N40) -> 109
... B48: 16.30 -16.45 | C48: 30 | D48: 13 | E48: 8 | F48: 3 | G48: 0 | H48: 0 | I48: 0 | J48: 1 | K48: 0 | L48: 0 | M48: 55 | N48: 0 | O48: =SUM(C48:L48,N48) -> 55 | P48: =SUM(C48:N48) -> 110
B49: 16.45 -17.00 | C49: 23 | D49: 23 | E49: 10 | F49: 2 | G49: 0 | H49: 0 | I49: 0 | J49: 0 | L49: 0 | M49: 55 | N49: 0 | O49: =SUM(C49:L49,N49) -> 58 | P49: =SUM(C49:N49) -> 113
...

Sheet 30.07 Bukoto-Kyebando
B1: Consultancy services for Preparation of Expressway Development Master Plan (EDMP) for Uganda
B2: MANUAL CLASSIFIED COUNT (MCC)
B3: ROAD NAME: | C3: ='29.07 Bukoto-Kyebando'!C3:G3 -> MCC - C1 - STN30 - KYEBANDO - KISALOSALO ROAD
C5: Date | D5: ='30.07 Kyebando-Bukoto'!D5 -> 30.07.19 | F5: Location | G5: ='29.07 Kyebando-Bukoto'!G5:H5 -> Kyebando Round | J5: Surveyor | K5: ='29.07 Kyebando-Bukoto'!K5:L5 -> AHISIBWE SARAH
C6: Dir. From | D6: ='29.07 Bukoto-Kyebando'!D6:E6 -> Bukoto | F6: Dir. To | G6: ='29.07 Bukoto-Kyebando'!G6:H6 -> Kyebando | J6: Supervisor | K6: ='29.07 Kyebando-Bukoto'!K6:L6 -> STEVEN
B8: Time / Veh Type | R8: SUMMARY TRAFFIC VOLUMES
C9: 1. Car | D9: 2. Station Wagon | E9: 3. Pickups | F9: 4. Minibus, matatu | G9: 5. Medium bus | H9: 6. Large Bus | I9: 7. Light Truck | J9: 8. Medium Truck | K9: 9. Heavy truck | L9: 10. Truck Trailer | M9: 11. Motor cycles | N9: 12. Tractors | O9: Total Excl M/Cycles | P9: Total All | R9: Time | S9: 1. Car | T9: 2. Station Wagon | U9: 3. Pickups | V9: 4. Minibus, matatu | W9: 5. Medium bus | X9: 6. Large Bus | Y9: 7. Light Truck | Z9: 8. Medium Truck | AA9: 9. Heavy truck | AB9: 10. Truck Trailer | AC9: 11. Motorcycles | AD9: 12. Tractors, Graders | AE9: Total Excl M/ Cycles | AF9: Total All
B10: 07.00 - 07.15 | C10: 0 | D10: 0 | E10: 0 | F10: 0 | G10: 0 | H10: 0 | I10: 0 | J10: 0 | K10: 0 | L10: 0 | M10: 0 | N10: 0 | O10: =SUM(C10:L10,N10) -> 0 | P10: =SUM(C10:N10) -> 0 | R10: 0700-0800 | S10: =SUM(C10:C13) -> 0 | T10: =SUM(D10:D13) -> 0 | U10: =SUM(E10:E13) -> 0 | V10: =SUM(F10:F13) -> 0 | W10: =SUM(G10:G13) -> 0 | X10: =SUM(H10:H13) -> 0 | Y10: =SUM(I10:I13) -> 0 | Z10: =SUM(J10:J13) -> 0 | ... AF10: =SUM(P10:P13) -> 0
B11: 07.15 - 07.30 | C11: 0 | D11: 0 | E11: 0 | F11: 0 | G11: 0 | H11: 0 | I11: 0 | J11: 0 | K11: 0 | L11: 0 | M11: 0 | N11: 0 | O11: =SUM(C11:L11,N11) -> 0 | P11: =SUM(C11:N11) -> 0 | R11: 0800-0900 | S11: =SUM(C14:C17) -> 0 | T11: =SUM(D14:D17) -> 0 | U11: =SUM(E14:E17) -> 0 | V11: =SUM(F14:F17) -> 0 | W11: =SUM(G14:G17) -> 0 | X11: =SUM(H14:H17) -> 0 | Y11: =SUM(I14:I17) -> 0 | Z11: =SUM(J14:J17) -> 0 | ... AF11: =SUM(P14:P17) -> 0
B12: 07.30 - 07.45 | C12: 0 | D12: 0 | E12: 0 | F12: 0 | G12: 0 | H12: 0 | I12: 0 | J12: 0 | K12: 0 | L12: 0 | M12: 0 | N12: 0 | O12: =SUM(C12:L12,N12) -> 0 | P12: =SUM(C12:N12) -> 0 | R12: 0900-1000 | S12: =SUM(C18:C21) -> 0 | T12: =SUM(D18:D21) -> 0 | U12: =SUM(E18:E21) -> 0 | V12: =SUM(F18:F21) -> 0 | W12: =SUM(G18:G21) -> 0 | X12: =SUM(H18:H21) -> 0 | Y12: =SUM(I18:I21) -> 0 | Z12: =SUM(J18:J21) -> 0 | ... AF12: =SUM(P18:P21) -> 0
B13: 07.45 - 08.00 | C13: 0 | D13: 0 | E13: 0 | F13: 0 | G13: 0 | H13: 0 | I13: 0 | J13: 0 | K13: 0 | L13: 0 | M13: 0 | N13: 0 | O13: =SUM(C13:L13,N13) -> 0 | P13: =SUM(C13:N13) -> 0 | R13: 1000-1100 | S13: =SUM(C22:C25) -> 45 | T13: =SUM(D22:D25) -> 28 | U13: =SUM(E22:E25) -> 10 | V13: =SUM(F22:F25) -> 5 | W13: =SUM(G22:G25) -> 0 | X13: =SUM(H22:H25) -> 0 | Y13: =SUM(I22:I25) -> 12 | Z13: =SUM(J22:J25) -> 3 | ... AF13: =SUM(P22:P25) -> 277
B14: 08.00 - 08.15 | C14: 0 | D14: 0 | E14: 0 | F14: 0 | G14: 0 | H14: 0 | I14: 0 | J14: 0 | K14: 0 | L14: 0 | M14: 0 | N14: 0 | O14: =SUM(C14:L14,N14) -> 0 | P14: =SUM(C14:N14) -> 0 | R14: 1100-1200 | S14: =SUM(C26:C29) -> 45 | T14: =SUM(D26:D29) -> 25 | U14: =SUM(E26:E29) -> 11 | V14: =SUM(F26:F29) -> 4 | W14: =SUM(G26:G29) -> 0 | X14: =SUM(H26:H29) -> 0 | Y14: =SUM(I26:I29) -> 8 | Z14: =SUM(J26:J29) -> 9 | ... AF14: =SUM(P26:P29) -> 274
B15: 08.15 - 08.30 | C15: 0 | D15: 0 | E15: 0 | F15: 0 | G15: 0 | H15: 0 | I15: 0 | J15: 0 | K15: 0 | L15: 0 | M15: 0 | N15: 0 | O15: =SUM(C15:L15,N15) -> 0 | P15: =SUM(C15:N15) -> 0 | R15: 1200-1300 | S15: =SUM(C30:C33) -> 59 | T15: =SUM(D30:D33) -> 39 | U15: =SUM(E30:E33) -> 13 | V15: =SUM(F30:F33) -> 4 | W15: =SUM(G30:G33) -> 0 | X15: =SUM(H30:H33) -> 0 | Y15: =SUM(I30:I33) -> 7 | Z15: =SUM(J30:J33) -> 10 | ... AF15: =SUM(P30:P33) -> 328
B16: 08.30 - 08.45 | C16: 0 | D16: 0 | E16: 0 | F16: 0 | G16: 0 | H16: 0 | I16: 0 | J16: 0 | K16: 0 | L16: 0 | M16: 0 | N16: 0 | O16: =SUM(C16:L16,N16) -> 0 | P16: =SUM(C16:N16) -> 0 | R16: 1300-1400 | S16: =SUM(C34:C37) -> 74 | T16: =SUM(D34:D37) -> 29 | U16: =SUM(E34:E37) -> 15 | V16: =SUM(F34:F37) -> 10 | W16: =SUM(G34:G37) -> 1 | X16: =SUM(H34:H37) -> 0 | Y16: =SUM(I34:I37) -> 8 | Z16: =SUM(J34:J37) -> 19 | ... AF16: =SUM(P34:P37) -> 416
B17: 08.45 - 9.00 | C17: 0 | D17: 0 | E17: 0 | F17: 0 | G17: 0 | H17: 0 | I17: 0 | J17: 0 | K17: 0 | L17: 0 | M17: 0 | N17: 0 | O17: =SUM(C17:L17,N17) -> 0 | P17: =SUM(C17:N17) -> 0 | R17: 1400-1500 | S17: =SUM(C38:C41) -> 69 | T17: =SUM(D38:D41) -> 36 | U17: =SUM(E38:E41) -> 17 | V17: =SUM(F38:F41) -> 16 | W17: =SUM(G38:G41) -> 0 | X17: =SUM(H38:H41) -> 0 | Y17: =SUM(I38:I41) -> 4 | Z17: =SUM(J38:J41) -> 20 | ... AF17: =SUM(P38:P41) -> 354
B18: 09.00 - 09.15 | C18: 0 | D18: 0 | E18: 0 | F18: 0 | G18: 0 | H18: 0 | I18: 0 | J18: 0 | K18: 0 | L18: 0 | M18: 0 | N18: 0 | O18: =SUM(C18:L18,N18) -> 0 | P18: =SUM(C18:N18) -> 0 | R18: 1500-1600 | S18: =SUM(C42:C45) -> 93 | T18: =SUM(D42:D45) -> 45 | U18: =SUM(E42:E45) -> 17 | V18: =SUM(F42:F45) -> 11 | W18: =SUM(G42:G45) -> 0 | X18: =SUM(H42:H45) -> 0 | Y18: =SUM(I42:I45) -> 8 | Z18: =SUM(J42:J45) -> 17 | ... AF18: =SUM(P42:P45) -> 385
B19: 09.15 - 09.30 | C19: 0 | D19: 0 | E19: 0 | F19: 0 | G19: 0 | H19: 0 | I19: 0 | J19: 0 | K19: 0 | L19: 0 | M19: 0 | N19: 0 | O19: =SUM(C19:L19,N19) -> 0 | P19: =SUM(C19:N19) -> 0 | R19: 1600-1700 | S19: =SUM(C46:C49) -> 140 | T19: =SUM(D46:D49) -> 62 | U19: =SUM(E46:E49) -> 39 | V19: =SUM(F46:F49) -> 15 | W19: =SUM(G46:G49) -> 1 | X19: =SUM(H46:H49) -> 1 | Y19: =SUM(I46:I49) -> 9 | Z19: =SUM(J46:J49) -> 10 | ... AF19: =SUM(P46:P49) -> 490
B20: 09.30 - 09.45 | C20: 0 | D20: 0 | E20: 0 | F20: 0 | G20: 0 | H20: 0 | I20: 0 | J20: 0 | K20: 0 | L20: 0 | M20: 0 | N20: 0 | O20: =SUM(C20:L20,N20) -> 0 | P20: =SUM(C20:N20) -> 0 | R20: 1700-1800 | S20: =SUM(C50:C53) -> 195 | T20: =SUM(D50:D53) -> 92 | U20: =SUM(E50:E53) -> 28 | V20: =SUM(F50:F53) -> 15 | W20: =SUM(G50:G53) -> 0 | X20: =SUM(H50:H53) -> 0 | Y20: =SUM(I50:I53) -> 10 | Z20: =SUM(J50:J53) -> 7 | ... AF20: =SUM(P50:P53) -> 604
B21: 09.45 - 10.00 | C21: 0 | D21: 0 | E21: 0 | F21: 0 | G21: 0 | H21: 0 | I21: 0 | J21: 0 | K21: 0 | L21: 0 | M21: 0 | N21: 0 | O21: =SUM(C21:L21,N21) -> 0 | P21: =SUM(C21:N21) -> 0 | R21: 1800-1900 | S21: =SUM(C54:C57) -> 181 | T21: =SUM(D54:D57) -> 61 | U21: =SUM(E54:E57) -> 17 | V21: =SUM(F54:F57) -> 18 | W21: =SUM(G54:G57) -> 1 | X21: =SUM(H54:H57) -> 0 | Y21: =SUM(I54:I57) -> 10 | Z21: =SUM(J54:J57) -> 11 | ... AF21: =SUM(P54:P57) -> 533
B22: 10.00 - 10.15 | C22: 9 | D22: 12 | E22: 5 | F22: 1 | G22: 0 | H22: 0 | I22: 3 | J22: 0 | K22: 1 | L22: 0 | M22: 40 | N22: 0 | O22: =SUM(C22:L22,N22) -> 31 | P22: =SUM(C22:N22) -> 71 | R22: AM Peak Hr | S22: =MAX(S10:S12) -> 0 | T22: =MAX(T10:T12) -> 0 | U22: =MAX(U10:U12) -> 0 | V22: =MAX(V10:V12) -> 0 | W22: =MAX(W10:W12) -> 0 | X22: =MAX(X10:X12) -> 0 | Y22: =MAX(Y10:Y12) -> 0 | Z22: =MAX(Z10:Z12) -> 0 | ... AF22: =MAX(AF10:AF12) -> 0
B23: 10.15 - 10.30 | C23: 16 | D23: 5 | E23: 2 | F23: 1 | G23: 0 | H23: 0 | I23: 3 | J23: 2 | K23: 0 | L23: 0 | M23: 47 | N23: 0 | O23: =SUM(C23:L23,N23) -> 29 | P23: =SUM(C23:N23) -> 76 | R23: IP Peak Hr | S23: =MAX(S13:S18) -> 93 | T23: =MAX(T13:T18) -> 45 | U23: =MAX(U13:U18) -> 17 | V23: =MAX(V13:V18) -> 16 | W23: =MAX(W13:W18) -> 1 | X23: =MAX(X13:X18) -> 0 | Y23: =MAX(Y13:Y18) -> 12 | Z23: =MAX(Z13:Z18) -> 20 | ... AF23: =MAX(AF13:AF18) -> 416
B24: 10.30 - 10.45 | C24: 9 | D24: 4 | E24: 2 | F24: 2 | G24: 0 | H24: 0 | I24: 2 | J24: 0 | K24: 0 | L24: 0 | M24: 28 | N24: 0 | O24: =SUM(C24:L24,N24) -> 19 | P24: =SUM(C24:N24) -> 47 | R24: PM Peak Hr | S24: =MAX(S19:S21) -> 195 | T24: =MAX(T19:T21) -> 92 | U24: =MAX(U19:U21) -> 39 | V24: =MAX(V19:V21) -> 18 | W24: =MAX(W19:W21) -> 1 | X24: =MAX(X19:X21) -> 1 | Y24: =MAX(Y19:Y21) -> 10 | Z24: =MAX(Z19:Z21) -> 11 | ... AF24: =MAX(AF19:AF21) -> 604
B25: 10.45 - 11.00 | C25: 11 | D25: 7 | E25: 1 | F25: 1 | G25: 0 | H25: 0 | I25: 4 | J25: 1 | K25: 1 | L25: 0 | M25: 57 | N25: 0 | O25: =SUM(C25:L25,N25) -> 26 | P25: =SUM(C25:N25) -> 83 | R25: AM Period | S25: =SUM(S10:S12) -> 0 | T25: =SUM(T10:T12) -> 0 | U25: =SUM(U10:U12) -> 0 | V25: =SUM(V10:V12) -> 0 | W25: =SUM(W10:W12) -> 0 | X25: =SUM(X10:X12) -> 0 | Y25: =SUM(Y10:Y12) -> 0 | Z25: =SUM(Z10:Z12) -> 0 | ... AF25: =SUM(AF10:AF12) -> 0
B26: 11.00 - 11.15 | C26: 12 | D26: 4 | E26: 2 | F26: 0 | G26: 0 | H26: 0 | I26: 4 | J26: 1 | K26: 1 | L26: 0 | M26: 25 | N26: 0 | O26: =SUM(C26:L26,N26) -> 24 | P26: =SUM(C26:N26) -> 49 | R26: IP Period | S26: =SUM(S13:S18) -> 385 | T26: =SUM(T13:T18) -> 202 | U26: =SUM(U13:U18) -> 83 | V26: =SUM(V13:V18) -> 50 | W26: =SUM(W13:W18) -> 1 | X26: =SUM(X13:X18) -> 0 | Y26: =SUM(Y13:Y18) -> 47 | Z26: =SUM(Z13:Z18) -> 78 | ... AF26: =SUM(AF13:AF18) -> 2034
B27: 11.15 - 11.30 | C27: 12 | D27: 8 | E27: 2 | F27: 1 | G27: 0 | H27: 0 | I27: 1 | J27: 3 | K27: 0 | L27: 0 | M27: 36 | N27: 0 | O27: =SUM(C27:L27,N27) -> 27 | P27: =SUM(C27:N27) -> 63 | R27: PM Period | S27: =SUM(S19:S21) -> 516 | T27: =SUM(T19:T21) -> 215 | U27: =SUM(U19:U21) -> 84 | V27: =SUM(V19:V21) -> 48 | W27: =SUM(W19:W21) -> 2 | X27: =SUM(X19:X21) -> 1 | Y27: =SUM(Y19:Y21) -> 29 | Z27: =SUM(Z19:Z21) -> 28 | ... AF27: =SUM(AF19:AF21) -> 1627
B28: 11.30 - 11.45 | C28: 12 | D28: 3 | E28: 4 | F28: 1 | G28: 0 | H28: 0 | I28: 1 | J28: 1 | K28: 3 | L28: 0 | M28: 48 | N28: 0 | O28: =SUM(C28:L28,N28) -> 25 | P28: =SUM(C28:N28) -> 73 | R28: 12 Hours | S28: =SUM(S10:S21) -> 901 | T28: =SUM(T10:T21) -> 417 | U28: =SUM(U10:U21) -> 167 | V28: =SUM(V10:V21) -> 98 | W28: =SUM(W10:W21) -> 3 | X28: =SUM(X10:X21) -> 1 | Y28: =SUM(Y10:Y21) -> 76 | Z28: =SUM(Z10:Z21) -> 106 | ... AF28: =SUM(AF10:AF21) -> 3661
B29: 11.45 - 12.00 | C29: 9 | D29: 10 | E29: 3 | F29: 2 | G29: 0 | H29: 0 | I29: 2 | J29: 4 | K29: 0 | L29: 0 | M29: 59 | N29: 0 | O29: =SUM(C29:L29,N29) -> 30 | P29: =SUM(C29:N29) -> 89
B30: 12.00 - 12.15 | C30: 15 | D30: 14 | E30: 5 | F30: 1 | G30: 0 | H30: 0 | I30: 5 | J30: 3 | K30: 0 | L30: 0 | M30: 42 | N30: 0 | O30: =SUM(C30:L30,N30) -> 43 | P30: =SUM(C30:N30) -> 85
B31: 12.15 - 12.30 | C31: 16 | D31: 7 | E31: 2 | F31: 0 | G31: 0 | H31: 0 | I31: 2 | J31: 1 | K31: 0 | L31: 0 | M31: 58 | N31: 0 | O31: =SUM(C31:L31,N31) -> 28 | P31: =SUM(C31:N31) -> 86
B32: 12.30 - 12.45 | C32: 11 | D32: 9 | E32: 2 | F32: 1 | G32: 0 | H32: 0 | I32: 0 | J32: 6 | K32: 3 | L32: 0 | M32: 46 | N32: 0 | O32: =SUM(C32:L32,N32) -> 32 | P32: =SUM(C32:N32) -> 78
B33: 12.45 - 13.00 | C33: 17 | D33: 9 | E33: 4 | F33: 2 | G33: 0 | H33: 0 | I33: 0 | J33: 0 | K33: 2 | L33: 0 | M33: 45 | N33: 0 | O33: =SUM(C33:L33,N33) -> 34 | P33: =SUM(C33:N33) -> 79
B34: 13.00 - 13.15 | C34: 25 | D34: 4 | E34: 2 | F34: 2 | G34: 1 | H34: 0 | I34: 2 | J34: 9 | K34: 1 | L34: 0 | M34: 60 | N34: 0 | O34: =SUM(C34:L34,N34) -> 46 | P34: =SUM(C34:N34) -> 106
B35: 13.15 - 13.30 | C35: 19 | D35: 4 | E35: 4 | F35: 1 | G35: 0 | H35: 0 | I35: 2 | J35: 4 | K35: 3 | L35: 0 | M35: 59 | N35: 0 | O35: =SUM(C35:L35,N35) -> 37 | P35: =SUM(C35:N35) -> 96
B36: 13.30 - 13.45 | C36: 14 | D36: 12 | E36: 1 | F36: 1 | G36: 0 | H36: 0 | I36: 2 | J36: 3 | K36: 5 | L36: 0 | M36: 65 | N36: 0 | O36: =SUM(C36:L36,N36) -> 38 | P36: =SUM(C36:N36) -> 103
B37: 13.45 - 14.00 | C37: 16 | D37: 9 | E37: 8 | F37: 6 | G37: 0 | H37: 0 | I37: 2 | J37: 3 | K37: 1 | L37: 0 | M37: 66 | N37: 0 | O37: =SUM(C37:L37,N37) -> 45 | P37: =SUM(C37:N37) -> 111
B38: 14.00 - 14.15 | C38: 17 | D38: 6 | E38: 4 | F38: 3 | G38: 0 | H38: 0 | I38: 1 | J38: 6 | K38: 2 | L38: 0 | M38: 46 | N38: 0 | O38: =SUM(C38:L38,N38) -> 39 | P38: =SUM(C38:N38) -> 85
B39: 14.15 - 14.30 | C39: 19 | D39: 7 | E39: 2 | F39: 4 | G39: 0 | H39: 0 | I39: 0 | J39: 4 | K39: 2 | L39: 0 | M39: 49 | N39: 0 | O39: =SUM(C39:L39,N39) -> 38 | P39: =SUM(C39:N39) -> 87
B40: 14.30 - 14.45 | C40: 17 | D40: 11 | E40: 6 | F40: 3 | G40: 0 | H40: 0 | I40: 3 | J40: 5 | K40: 0 | L40: 0 | M40: 57 | N40: 0 | O40: =SUM(C40:L40,N40) -> 45 | P40: =SUM(C40:N40) -> 102
... B57: 18.45 - 19.00 | C57: 35 | D57: 16 | E57: 2 | F57: 2 | G57: 0 | H57: 0 | I57: 3 | J57: 0 | K57: 1 | L57: 0 | M57: 60 | N57: 0 | O57: =SUM(C57:L57,N57) -> 59 | P57: =SUM(C57:N57) -> 119
B58: Totals | C58: =SUM(C10:C57) -> 901 | D58: =SUM(D10:D57) -> 417 | E58: =SUM(E10:E57) -> 167 | F58: =SUM(F10:F57) -> 98 | G58: =SUM(G10:G57) -> 3 | H58: =SUM(H10:H57) -> 1 | I58: =SUM(I10:I57) -> 76 | J58: =SUM(J10:J57) -> 106 | ... P58: =SUM(P10:P57) -> 3661
...

Sheet 31.07 Kyebando-Bukoto
B1: Consultancy services for Preparation of Expressway Development Master Plan (EDMP) for Uganda
B2: MANUAL CLASSIFIED COUNT (MCC)
B3: ROAD NAME: | C3: ='29.07 Kyebando-Bukoto'!C3:G3 -> MCC - C1 - STN30 - KYEBANDO - KISALOSALO ROAD
C5: Date | D5: 31.07.19 | F5: Location | G5: ='29.07 Kyebando-Bukoto'!G5:H5 -> Kyebando Round | J5: Surveyor | K5: ='29.07 Kyebando-Bukoto'!K5:L5 -> AHISIBWE SARAH
C6: Dir. From | D6: ='29.07 Kyebando-Bukoto'!D6:E6 -> Kyebando | F6: Dir. To | G6: ='29.07 Kyebando-Bukoto'!G6:H6 -> Bukoto | J6: Supervisor | K6: ='29.07 Kyebando-Bukoto'!K6:L6 -> STEVEN
B8: Time / Veh Type | R8: SUMMARY TRAFFIC VOLUMES
C9: 1. Car | D9: 2. Station Wagon | E9: 3. Pickups | F9: 4. Minibus, matatu | G9: 5. Medium bus | H9: 6. Large Bus | I9: 7. Light Truck | J9: 8. Medium Truck | K9: 9. Heavy truck | L9: 10. Truck Trailer | M9: 11. Motor cycles | N9: 12. Tractors | O9: Total Excl M/Cycles | P9: Total All | R9: Time | S9: 1. Car | T9: 2. Station Wagon | U9: 3. Pickups | V9: 4. Minibus, matatu | W9: 5. Medium bus | X9: 6. Large Bus | Y9: 7. Light Truck | Z9: 8. Medium Truck | AA9: 9. Heavy truck | AB9: 10. Truck Trailer | AC9: 11. Motorcycles | AD9: 12. Tractors, Graders | AE9: Total Excl M/ Cycles | AF9: Total All
B10: 07.00 - 07.15 | C10: 0 | D10: 0 | E10: 0 | F10: 0 | G10: 0 | H10: 0 | I10: 0 | J10: 0 | K10: 0 | L10: 0 | M10: 0 | N10: 0 | O10: =SUM(C10:L10,N10) -> 0 | P10: =SUM(C10:N10) -> 0 | R10: 0700-0800 | S10: =SUM(C10:C13) -> 0 | T10: =SUM(D10:D13) -> 0 | U10: =SUM(E10:E13) -> 0 | V10: =SUM(F10:F13) -> 0 | W10: =SUM(G10:G13) -> 0 | X10: =SUM(H10:H13) -> 0 | Y10: =SUM(I10:I13) -> 0 | Z10: =SUM(J10:J13) -> 0 | ... AF10: =SUM(P10:P13) -> 0
B11: 07.15 - 07.30 | C11: 0 | D11: 0 | E11: 0 | F11: 0 | G11: 0 | H11: 0 | I11: 0 | J11: 0 | K11: 0 | L11: 0 | M11: 0 | N11: 0 | O11: =SUM(C11:L11,N11) -> 0 | P11: =SUM(C11:N11) -> 0 | R11: 0800-0900 | S11: =SUM(C14:C17) -> 40 | T11: =SUM(D14:D17) -> 28 | U11: =SUM(E14:E17) -> 9 | V11: =SUM(F14:F17) -> 1 | W11: =SUM(G14:G17) -> 0 | X11: =SUM(H14:H17) -> 0 | Y11: =SUM(I14:I17) -> 1 | Z11: =SUM(J14:J17) -> 0 | ... AF11: =SUM(P14:P17) -> 154
B12: 07.30 - 07.45 | C12: 0 | D12: 0 | E12: 0 | F12: 0 | G12: 0 | H12: 0 | I12: 0 | J12: 0 | K12: 0 | L12: 0 | M12: 0 | N12: 0 | O12: =SUM(C12:L12,N12) -> 0 | P12: =SUM(C12:N12) -> 0 | R12: 0900-1000 | S12: =SUM(C18:C21) -> 150 | T12: =SUM(D18:D21) -> 65 | U12: =SUM(E18:E21) -> 40 | V12: =SUM(F18:F21) -> 13 | W12: =SUM(G18:G21) -> 2 | X12: =SUM(H18:H21) -> 0 | Y12: =SUM(I18:I21) -> 6 | Z12: =SUM(J18:J21) -> 9 | ... AF12: =SUM(P18:P21) -> 591
B13: 07.45 - 08.00 | C13: 0 | D13: 0 | E13: 0 | F13: 0 | G13: 0 | H13: 0 | I13: 0 | J13: 0 | K13: 0 | L13: 0 | M13: 0 | N13: 0 | O13: =SUM(C13:L13,N13) -> 0 | P13: =SUM(C13:N13) -> 0 | R13: 1000-1100 | S13: =SUM(C22:C25) -> 125 | T13: =SUM(D22:D25) -> 35 | U13: =SUM(E22:E25) -> 28 | V13: =SUM(F22:F25) -> 14 | W13: =SUM(G22:G25) -> 4 | X13: =SUM(H22:H25) -> 0 | Y13: =SUM(I22:I25) -> 6 | Z13: =SUM(J22:J25) -> 3 | ... AF13: =SUM(P22:P25) -> 449
B14: 08.00 - 08.15 | C14: 0 | D14: 0 | E14: 0 | F14: 0 | G14: 0 | H14: 0 | I14: 0 | J14: 0 | K14: 0 | L14: 0 | M14: 0 | N14: 0 | O14: =SUM(C14:L14,N14) -> 0 | P14: =SUM(C14:N14) -> 0 | R14: 1100-1200 | S14: =SUM(C26:C29) -> 109 | T14: =SUM(D26:D29) -> 44 | U14: =SUM(E26:E29) -> 22 | V14: =SUM(F26:F29) -> 9 | W14: =SUM(G26:G29) -> 0 | X14: =SUM(H26:H29) -> 1 | Y14: =SUM(I26:I29) -> 17 | Z14: =SUM(J26:J29) -> 7 | ... AF14: =SUM(P26:P29) -> 415
B15: 08.15 - 08.30 | C15: 0 | D15: 0 | E15: 0 | F15: 0 | G15: 0 | H15: 0 | I15: 0 | J15: 0 | K15: 0 | L15: 0 | M15: 0 | N15: 0 | O15: =SUM(C15:L15,N15) -> 0 | P15: =SUM(C15:N15) -> 0 | R15: 1200-1300 | S15: =SUM(C30:C33) -> 88 | T15: =SUM(D30:D33) -> 33 | U15: =SUM(E30:E33) -> 17 | V15: =SUM(F30:F33) -> 9 | W15: =SUM(G30:G33) -> 0 | X15: =SUM(H30:H33) -> 0 | Y15: =SUM(I30:I33) -> 8 | Z15: =SUM(J30:J33) -> 9 | ... AF15: =SUM(P30:P33) -> 362
B16: 08.30 - 08.45 | C16: 0 | D16: 0 | E16: 0 | F16: 0 | G16: 0 | H16: 0 | I16: 0 | J16: 0 | K16: 0 | L16: 0 | M16: 0 | N16: 0 | O16: =SUM(C16:L16,N16) -> 0 | P16: =SUM(C16:N16) -> 0 | R16: 1300-1400 | S16: =SUM(C34:C37) -> 81 | T16: =SUM(D34:D37) -> 31 | U16: =SUM(E34:E37) -> 19 | V16: =SUM(F34:F37) -> 17 | W16: =SUM(G34:G37) -> 0 | X16: =SUM(H34:H37) -> 0 | Y16: =SUM(I34:I37) -> 7 | Z16: =SUM(J34:J37) -> 7 | ... AF16: =SUM(P34:P37) -> 356
B17: 08.45 - 9.00 | C17: 40 | D17: 28 | E17: 9 | F17: 1 | G17: 0 | H17: 0 | I17: 1 | J17: 0 | K17: 0 | L17: 0 | M17: 75 | N17: 0 | O17: =SUM(C17:L17,N17) -> 79 | P17: =SUM(C17:N17) -> 154 | R17: 1400-1500 | S17: =SUM(C38:C41) -> 89 | T17: =SUM(D38:D41) -> 35 | U17: =SUM(E38:E41) -> 14 | V17: =SUM(F38:F41) -> 15 | W17: =SUM(G38:G41) -> 0 | X17: =SUM(H38:H41) -> 0 | Y17: =SUM(I38:I41) -> 6 | Z17: =SUM(J38:J41) -> 9 | ... AF17: =SUM(P38:P41) -> 336
B18: 09.00 - 09.15 | C18: 55 | D18: 30 | E18: 10 | F18: 7 | G18: 0 | H18: 0 | I18: 1 | J18: 5 | K18: 0 | L18: 0 | M18: 90 | N18: 0 | O18: =SUM(C18:L18,N18) -> 108 | P18: =SUM(C18:N18) -> 198 | R18: 1500-1600 | S18: =SUM(C42:C45) -> 100 | T18: =SUM(D42:D45) -> 58 | U18: =SUM(E42:E45) -> 33 | V18: =SUM(F42:F45) -> 21 | W18: =SUM(G42:G45) -> 0 | X18: =SUM(H42:H45) -> 0 | Y18: =SUM(I42:I45) -> 10 | Z18: =SUM(J42:J45) -> 10 | ... AF18: =SUM(P42:P45) -> 421
B19: 09.15 - 09.30 | C19: 30 | D19: 12 | E19: 15 | F19: 3 | G19: 2 | H19: 0 | I19: 0 | J19: 1 | K19: 0 | L19: 0 | M19: 80 | N19: 0 | O19: =SUM(C19:L19,N19) -> 63 | P19: =SUM(C19:N19) -> 143 | R19: 1600-1700 | S19: =SUM(C46:C49) -> 113 | T19: =SUM(D46:D49) -> 65 | U19: =SUM(E46:E49) -> 38 | V19: =SUM(F46:F49) -> 15 | W19: =SUM(G46:G49) -> 0 | X19: =SUM(H46:H49) -> 0 | Y19: =SUM(I46:I49) -> 11 | Z19: =SUM(J46:J49) -> 8 | ... AF19: =SUM(P46:P49) -> 432
B20: 09.30 - 09.45 | C20: 40 | D20: 10 | E20: 5 | F20: 2 | G20: 0 | H20: 0 | I20: 3 | J20: 3 | K20: 1 | L20: 0 | M20: 65 | N20: 0 | O20: =SUM(C20:L20,N20) -> 64 | P20: =SUM(C20:N20) -> 129 | R20: 1700-1800 | S20: =SUM(C50:C53) -> 112 | T20: =SUM(D50:D53) -> 57 | U20: =SUM(E50:E53) -> 28 | V20: =SUM(F50:F53) -> 27 | W20: =SUM(G50:G53) -> 1 | X20: =SUM(H50:H53) -> 1 | Y20: =SUM(I50:I53) -> 12 | Z20: =SUM(J50:J53) -> 4 | ... AF20: =SUM(P50:P53) -> 444
B21: 09.45 - 10.00 | C21: 25 | D21: 13 | E21: 10 | F21: 1 | G21: 0 | H21: 0 | I21: 2 | J21: 0 | K21: 0 | L21: 0 | M21: 70 | N21: 0 | O21: =SUM(C21:L21,N21) -> 51 | P21: =SUM(C21:N21) -> 121 | R21: 1800-1900 | S21: =SUM(C54:C57) -> 136 | T21: =SUM(D54:D57) -> 45 | U21: =SUM(E54:E57) -> 16 | V21: =SUM(F54:F57) -> 11 | W21: =SUM(G54:G57) -> 0 | X21: =SUM(H54:H57) -> 0 | Y21: =SUM(I54:I57) -> 7 | Z21: =SUM(J54:J57) -> 3 | ... AF21: =SUM(P54:P57) -> 482
B22: 10.00 - 10.15 | C22: 26 | D22: 10 | E22: 10 | F22: 5 | G22: 0 | H22: 0 | I22: 2 | J22: 0 | K22: 2 | L22: 0 | M22: 65 | N22: 0 | O22: =SUM(C22:L22,N22) -> 55 | P22: =SUM(C22:N22) -> 120 | R22: AM Peak Hr | S22: =MAX(S10:S12) -> 150 | T22: =MAX(T10:T12) -> 65 | U22: =MAX(U10:U12) -> 40 | V22: =MAX(V10:V12) -> 13 | W22: =MAX(W10:W12) -> 2 | X22: =MAX(X10:X12) -> 0 | Y22: =MAX(Y10:Y12) -> 6 | Z22: =MAX(Z10:Z12) -> 9 | ... AF22: =MAX(AF10:AF12) -> 591
B23: 10.15 - 10.30 | C23: 38 | D23: 8 | E23: 4 | F23: 1 | G23: 0 | H23: 0 | I23: 1 | J23: 0 | K23: 1 | L23: 0 | M23: 50 | N23: 0 | O23: =SUM(C23:L23,N23) -> 53 | P23: =SUM(C23:N23) -> 103 | R23: IP Peak Hr | S23: =MAX(S13:S18) -> 125 | T23: =MAX(T13:T18) -> 58 | U23: =MAX(U13:U18) -> 33 | V23: =MAX(V13:V18) -> 21 | W23: =MAX(W13:W18) -> 4 | X23: =MAX(X13:X18) -> 1 | Y23: =MAX(Y13:Y18) -> 17 | Z23: =MAX(Z13:Z18) -> 10 | ... AF23: =MAX(AF13:AF18) -> 449
B24: 10.30 - 10.45 | C24: 26 | D24: 8 | E24: 3 | F24: 2 | G24: 4 | H24: 0 | I24: 2 | J24: 0 | K24: 2 | L24: 0 | M24: 70 | N24: 0 | O24: =SUM(C24:L24,N24) -> 47 | P24: =SUM(C24:N24) -> 117 | R24: PM Peak Hr | S24: =MAX(S19:S21) -> 136 | T24: =MAX(T19:T21) -> 65 | U24: =MAX(U19:U21) -> 38 | V24: =MAX(V19:V21) -> 27 | W24: =MAX(W19:W21) -> 1 | X24: =MAX(X19:X21) -> 1 | Y24: =MAX(Y19:Y21) -> 12 | Z24: =MAX(Z19:Z21) -> 8 | ... AF24: =MAX(AF19:AF21) -> 482
B25: 10.45 - 11.00 | C25: 35 | D25: 9 | E25: 11 | F25: 6 | G25: 0 | H25: 0 | I25: 1 | J25: 3 | K25: 1 | L25: 0 | M25: 43 | N25: 0 | O25: =SUM(C25:L25,N25) -> 66 | P25: =SUM(C25:N25) -> 109 | R25: AM Period | S25: =SUM(S10:S12) -> 190 | T25: =SUM(T10:T12) -> 93 | U25: =SUM(U10:U12) -> 49 | V25: =SUM(V10:V12) -> 14 | W25: =SUM(W10:W12) -> 2 | X25: =SUM(X10:X12) -> 0 | Y25: =SUM(Y10:Y12) -> 7 | Z25: =SUM(Z10:Z12) -> 9 | ... AF25: =SUM(AF10:AF12) -> 745
B26: 11.00 - 11.15 | C26: 35 | D26: 15 | E26: 4 | F26: 3 | G26: 0 | H26: 0 | I26: 3 | J26: 3 | K26: 0 | L26: 0 | M26: 60 | N26: 0 | O26: =SUM(C26:L26,N26) -> 63 | P26: =SUM(C26:N26) -> 123 | R26: IP Period | S26: =SUM(S13:S18) -> 592 | T26: =SUM(T13:T18) -> 236 | U26: =SUM(U13:U18) -> 133 | V26: =SUM(V13:V18) -> 85 | W26: =SUM(W13:W18) -> 4 | X26: =SUM(X13:X18) -> 1 | Y26: =SUM(Y13:Y18) -> 54 | Z26: =SUM(Z13:Z18) -> 45 | ... AF26: =SUM(AF13:AF18) -> 2339
B27: 11.15 - 11.30 | C27: 25 | D27: 7 | E27: 10 | F27: 0 | G27: 0 | H27: 1 | I27: 3 | J27: 0 | K27: 0 | L27: 0 | M27: 47 | N27: 0 | O27: =SUM(C27:L27,N27) -> 46 | P27: =SUM(C27:N27) -> 93 | R27: PM Period | S27: =SUM(S19:S21) -> 361 | T27: =SUM(T19:T21) -> 167 | U27: =SUM(U19:U21) -> 82 | V27: =SUM(V19:V21) -> 53 | W27: =SUM(W19:W21) -> 1 | X27: =SUM(X19:X21) -> 1 | Y27: =SUM(Y19:Y21) -> 30 | Z27: =SUM(Z19:Z21) -> 15 | ... AF27: =SUM(AF19:AF21) -> 1358
B28: 11.30 - 11.45 | C28: 29 | D28: 12 | E28: 6 | F28: 3 | G28: 0 | H28: 0 | I28: 6 | J28: 2 | K28: 1 | L28: 0 | M28: 53 | N28: 0 | O28: =SUM(C28:L28,N28) -> 59 | P28: =SUM(C28:N28) -> 112 | R28: 12 Hours | S28: =SUM(S10:S21) -> 1143 | T28: =SUM(T10:T21) -> 496 | U28: =SUM(U10:U21) -> 264 | V28: =SUM(V10:V21) -> 152 | W28: =SUM(W10:W21) -> 7 | X28: =SUM(X10:X21) -> 2 | Y28: =SUM(Y10:Y21) -> 91 | Z28: =SUM(Z10:Z21) -> 69 | ... AF28: =SUM(AF10:AF21) -> 4442
B29: 11.45 - 12.00 | C29: 20 | D29: 10 | E29: 2 | F29: 3 | G29: 0 | H29: 0 | I29: 5 | J29: 2 | K29: 0 | L29: 0 | M29: 45 | N29: 0 | O29: =SUM(C29:L29,N29) -> 42 | P29: =SUM(C29:N29) -> 87
