Workbook
Name Veh_Type: 'WesternSP-Data'!$G$2:$G$239
Name zones: #REF!
Name Zones_Ndeke: #REF!

Sheet Age
A4: Count of Gender (M/F) | B4: Column Labels | G4: Row Labels | H4: F | I4: M | L4: Age | M4: Female | N4: Male | O4: Grand Total
A5: Row Labels | B5: F | C5: M | D5: (blank) | E5: Grand Total | G5: 20-29 | H5: 151 | I5: 266 | J5: 417 | L5: 20-29 | M5: =H5/$O$11 -> 0.097356544 | N5: =I5/$O$11 -> 0.17150226 | O5: 417
A6: 20-29 | B6: 151 | C6: 266 | E6: 417 | G6: 30-39 | H6: 228 | I6: 475 | J6: 703 | L6: 30-39 | M6: =H6/$O$11 -> 0.14700193 | N6: =I6/$O$11 -> 0.30625403 | O6: 703
A7: 30-39 | B7: 228 | C7: 475 | E7: 703 | G7: 40-49 | H7: 52 | I7: 277 | J7: 329 | L7: 40-49 | M7: =H7/$O$11 -> 0.033526757 | N7: =I7/$O$11 -> 0.17859446 | O7: 329
A8: 40-49 | B8: 52 | C8: 277 | E8: 329 | G8: 50-59 | H8: 14 | I8: 77 | J8: 91 | L8: 50-59 | M8: =H8/$O$11 -> 0.0090264346 | N8: =I8/$O$11 -> 0.04964539 | O8: 91
A9: 50-59 | B9: 14 | C9: 77 | E9: 91 | G9: 60-69 | H9: 3 | I9: 5 | J9: 8 | L9: 60-69 | M9: =H9/$O$11 -> 0.001934236 | N9: =I9/$O$11 -> 0.0032237266 | O9: 8
A10: 60-69 | B10: 3 | C10: 5 | E10: 8 | G10: 70- | H10: 2 | I10: 1 | J10: 3 | L10: 70- | M10: =H10/$O$11 -> 0.0012894907 | N10: =I10/$O$11 -> 0.00064474533 | O10: 3
A11: 70- | B11: 2 | C11: 1 | E11: 3 | L11: Grand Total | M11: =SUM(M5:M10) -> 0.2901354 | N11: =SUM(N5:N10) -> 0.7098646 | O11: =SUM(O5:O10) -> 1551
A12: (blank)
A13: Grand Total | B13: 450 | C13: 1101 | E13: 1551

Sheet Journey P
A3: Count of Gender (M/F) | B3: Column Labels
A4: Row Labels | B4: F | C4: M | D4: (blank) | E4: Grand Total | G4: Journey Purpose | H4: Female | I4: Male | J4: Grand Total | L4: Journey Purpose | M4: Female | N4: Male | O4: Grand Total | R4: Female | S4: Male
A5: Commercial-Commercial | B5: 28 | C5: 99 | E5: 127 | G5: Commercial-Commercial | H5: 28 | I5: 99 | J5: 127 | L5: Commercial | M5: =SUM(H5:H9) -> 37 | N5: =SUM(I5:I9) -> 134 | O5: =SUM(M5:N5) -> 171 | Q5: Commercial | R5: =M5/$O$13 -> 0.024088542 | S5: =N5/$O$13 -> 0.087239583
A6: Commercial-Home | B6: 6 | C6: 24 | E6: 30 | G6: Commercial-Home | H6: 6 | I6: 24 | J6: 30 | L6: Work | M6: =SUM(H37:H43) -> 100 | N6: =SUM(I37:I43) -> 360 | O6: =SUM(M6:N6) -> 460 | Q6: Work | R6: =M6/$O$13 -> 0.065104167 | S6: =N6/$O$13 -> 0.234375
A7: Commercial-Leisure/Social | B7: 2 | E7: 2 | G7: Commercial-Leisure/Social | H7: 2 | J7: 2 | L7: Home | M7: =SUM(H10:H17) -> 247 | N7: =SUM(I10:I17) -> 516 | O7: =SUM(M7:N7) -> 763 | Q7: Home | R7: =M7/$O$13 -> 0.16080729 | S7: =N7/$O$13 -> 0.3359375
A8: Commercial-Study | B8: 1 | C8: 1 | E8: 2 | G8: Commercial-Study | H8: 1 | I8: 1 | J8: 2 | L8: Hospital | M8: =SUM(H18) -> 1 | N8: =SUM(I18) -> 4 | O8: =SUM(M8:N8) -> 5 | Q8: Hospital | R8: =M8/$O$13 -> 0.00065104167 | S8: =N8/$O$13 -> 0.0026041667
A9: Commercial-Work | C9: 10 | E9: 10 | G9: Commercial-Work | I9: 10 | J9: 10 | L9: Leisure | M9: =SUM(H19:H23) -> 18 | N9: =SUM(I19:I23) -> 33 | O9: =SUM(M9:N9) -> 51 | Q9: Leisure | R9: =M9/$O$13 -> 0.01171875 | S9: =N9/$O$13 -> 0.021484375
A10: Home-Commercial | B10: 53 | C10: 88 | E10: 141 | G10: Home-Commercial | H10: 53 | I10: 88 | J10: 141 | L10: Study | M10: =SUM(H30:H33) -> 19 | N10: =SUM(I30:I33) -> 22 | O10: =SUM(M10:N10) -> 41 | Q10: Study | R10: =M10/$O$13 -> 0.012369792 | S10: =N10/$O$13 -> 0.014322917
A11: Home-Home | B11: 8 | C11: 14 | E11: 22 | G11: Home-Home | H11: 8 | I11: 14 | J11: 22 | L11: Tourism | M11: =SUM(H34:H36) -> 4 | N11: =SUM(I34:I36) -> 6 | O11: =SUM(M11:N11) -> 10 | Q11: Tourism | R11: =M11/$O$13 -> 0.0026041667 | S11: =N11/$O$13 -> 0.00390625
A12: Home-Hospital | B12: 9 | C12: 8 | E12: 17 | G12: Home-Hospital | H12: 9 | I12: 8 | J12: 17 | L12: Others | M12: =SUM(H24:H28) -> 21 | N12: =SUM(I24:I28) -> 14 | O12: =SUM(M12:N12) -> 35 | Q12: Others | R12: =M12/$O$13 -> 0.013671875 | S12: =N12/$O$13 -> 0.0091145833
A13: Home-Leisure/Social | B13: 39 | C13: 49 | E13: 88 | G13: Home-Leisure/Social | H13: 39 | I13: 49 | J13: 88 | O13: =SUM(O5:O12) -> 1536
A14: Home-Others | B14: 29 | C14: 23 | E14: 52 | G14: Home-Others | H14: 29 | I14: 23 | J14: 52
A15: Home-Study | B15: 22 | C15: 14 | E15: 36 | G15: Home-Study | H15: 22 | I15: 14 | J15: 36
A16: Home-Tourism | B16: 3 | C16: 15 | E16: 18 | G16: Home-Tourism | H16: 3 | I16: 15 | J16: 18
A17: Home-Work | B17: 84 | C17: 305 | E17: 389 | G17: Home-Work | H17: 84 | I17: 305 | J17: 389
A18: Hospital-Home | B18: 1 | C18: 4 | E18: 5 | G18: Hospital-Home | H18: 1 | I18: 4 | J18: 5
A19: Leisure/Social-Commercial | B19: 1 | C19: 1 | E19: 2 | G19: Leisure/Social-Commercial | H19: 1 | I19: 1 | J19: 2
A20: Leisure/Social-Home | B20: 14 | C20: 28 | E20: 42 | G20: Leisure/Social-Home | H20: 14 | I20: 28 | J20: 42
A21: Leisure/Social-Leisure/Social | B21: 3 | C21: 2 | E21: 5 | G21: Leisure/Social-Leisure/Social | H21: 3 | I21: 2 | J21: 5
A22: Leisure/Social-Others | C22: 1 | E22: 1 | G22: Leisure/Social-Others | I22: 1 | J22: 1
A23: Leisure/Social-Work | C23: 1 | E23: 1 | G23: Leisure/Social-Work | I23: 1 | J23: 1
A24: Others-Home | B24: 16 | C24: 7 | E24: 23 | G24: Others-Home | H24: 16 | I24: 7 | J24: 23
A25: Others-Hospital | C25: 1 | E25: 1 | G25: Others-Hospital | I25: 1 | J25: 1
A26: Others-Leisure/Social | B26: 1 | E26: 1 | G26: Others-Leisure/Social | H26: 1 | J26: 1
A27: Others-Others | B27: 3 | C27: 6 | E27: 9 | G27: Others-Others | H27: 3 | I27: 6 | J27: 9
A28: Others-Study | B28: 1 | E28: 1 | G28: Others-Study | H28: 1 | J28: 1
A29: Others-Work | B29: 3 | C29: 11 | E29: 14 | G29: Others-Work | H29: 3 | I29: 11 | J29: 14
A30: Study-Home | B30: 19 | C30: 16 | E30: 35 | G30: Study-Home | H30: 19 | I30: 16 | J30: 35
A31: Study-Study | C31: 1 | E31: 1 | G31: Study-Study | I31: 1 | J31: 1
A32: Study-Tourism | C32: 2 | E32: 2 | G32: Study-Tourism | I32: 2 | J32: 2
A33: Study-Work | C33: 3 | E33: 3 | G33: Study-Work | I33: 3 | J33: 3
A34: Tourism-Home | B34: 2 | C34: 4 | E34: 6 | G34: Tourism-Home | H34: 2 | I34: 4 | J34: 6
A35: Tourism-Tourism | B35: 1 | C35: 1 | E35: 2 | G35: Tourism-Tourism | H35: 1 | I35: 1 | J35: 2
A36: Tourism-Work | B36: 1 | C36: 1 | E36: 2 | G36: Tourism-Work | H36: 1 | I36: 1 | J36: 2
A37: Work-Commercial | B37: 12 | C37: 30 | E37: 42 | G37: Work-Commercial | H37: 12 | I37: 30 | J37: 42
A38: Work-Home | B38: 58 | C38: 186 | E38: 244 | G38: Work-Home | H38: 58 | I38: 186 | J38: 244
A39: Work-Hospital | B39: 2 | C39: 1 | E39: 3 | G39: Work-Hospital | H39: 2 | I39: 1 | J39: 3
A40: Work-Leisure/Social | B40: 8 | C40: 4 | E40: 12 | G40: Work-Leisure/Social | H40: 8 | I40: 4 | J40: 12
A41: Work-Others | B41: 7 | C41: 38 | E41: 45 | G41: Work-Others | H41: 7 | I41: 38 | J41: 45
A42: Work-Study | B42: 4 | C42: 1 | E42: 5 | G42: Work-Study | H42: 4 | I42: 1 | J42: 5
...

Sheet Dist-Time
A3: Row Labels | B3: Count of Dist Range | F3: Distance (Km) | G3: No. Responses | H3: %ge Responses
A4: 0-10 | B4: 540 | F4: 0-10 | G4: 540 | H4: =G4/$G$12 -> 0.34816248
A5: 100-200 | B5: 229 | F5: 10-20 | G5: 62 | H5: =G5/$G$12 -> 0.03997421
A6: 10-20 | B6: 62 | F6: 20-40 | G6: 92 | H6: =G6/$G$12 -> 0.05931657
A7: 20-40 | B7: 92 | F7: 40-70 | G7: 141 | H7: =G7/$G$12 -> 0.090909091
A8: 40-70 | B8: 141 | F8: 70-100 | G8: 123 | H8: =G8/$G$12 -> 0.079303675
A9: 70-100 | B9: 123 | F9: 100-200 | G9: 229 | H9: =G9/$G$12 -> 0.14764668
A10: Over 200 | B10: 364 | F10: Over 200 | G10: 364 | H10: =G10/$G$12 -> 0.2346873
A11: (blank)
A12: Grand Total | B12: 1551 | F12: Grand Total | G12: =SUM(G4:G10) -> 1551
A15: Row Labels | B15: Count of Time Range
A16: 0.5-1.0 | B16: 123
A17: 0-0.5 | B17: 183
A18: 1.0-2.0 | B18: 223
A19: 2.0-3.5 | B19: 458
A20: Over 3.5 | B20: 564
A21: (blank) | F21: Journey Time (Hours) | G21: No. Responses | H21: %ge Responses
A22: Grand Total | B22: 1551 | F22: 0-0.5 | G22: 183 | H22: =G22/$G$27 -> 0.11798839
F23: 0.5-1.0 | G23: 123 | H23: =G23/$G$27 -> 0.079303675
F24: 1.0-2.0 | G24: 223 | H24: =G24/$G$27 -> 0.14377821
F25: 2.0-3.5 | G25: 458 | H25: =G25/$G$27 -> 0.29529336
F26: Over 3.5 | G26: 564 | H26: =G26/$G$27 -> 0.36363636
F27: Grand Total | G27: =SUM(G22:G26) -> 1551

Sheet Dist-Time Toll
A3: Count of Toll Charge | B3: Column Labels | V3: Potential Expressway Toll Charge (UGX)
A4: Row Labels | B4: 0-1000 | C4: 1000-2000 | D4: 2000-3000 | E4: 3000-5000 | F4: 5000-10000 | G4: Over 10000 | H4: (blank) | I4: Grand Total | K4: Distance (Km) | L4: 0-1000 | M4: 1000-2000 | N4: 2000-3000 | O4: 3000-5000 | P4: 5000-10000 | Q4: Over 10000 | R4: Grand Total | U4: Journey Distance (Km) | V4: 0-1,000 | W4: 1,000-2,000 | X4: 2,000-3,000 | Y4: 3,000-5,000 | Z4: 5,000-10,000 | AA4: Over 10,000
A5: 0-10 | B5: 231 | C5: 118 | D5: 61 | E5: 37 | F5: 49 | G5: 44 | I5: 540 | K5: 0-10 | L5: 231 | M5: 118 | N5: 61 | O5: 37 | P5: 49 | Q5: 44 | R5: 540 | U5: 0-10 | V5: =L5/$R$13 -> 0.14893617 | W5: =M5/$R$13 -> 0.076079948 | X5: =N5/$R$13 -> 0.039329465 | Y5: =O5/$R$13 -> 0.023855577 | Z5: =P5/$R$13 -> 0.031592521 | AA5: =Q5/$R$13 -> 0.028368794
A6: 100-200 | B6: 79 | C6: 54 | D6: 30 | E6: 28 | F6: 32 | G6: 6 | I6: 229 | K6: 10-20 | L6: 25 | M6: 20 | N6: 9 | O6: 3 | P6: 5 | R6: 62 | U6: 10-20 | V6: =L10/$R$13 -> 0.050934881 | W6: =M10/$R$13 -> 0.034816248 | X6: =N10/$R$13 -> 0.01934236 | Y6: =O10/$R$13 -> 0.018052869 | Z6: =P10/$R$13 -> 0.02063185 | AA6: =Q10/$R$13 -> 0.003868472
A7: 10-20 | B7: 25 | C7: 20 | D7: 9 | E7: 3 | F7: 5 | I7: 62 | K7: 20-40 | L7: 33 | M7: 22 | N7: 15 | O7: 7 | P7: 12 | Q7: 3 | R7: 92 | U7: 20-40 | V7: =L6/$R$13 -> 0.016118633 | W7: =M6/$R$13 -> 0.012894907 | X7: =N6/$R$13 -> 0.0058027079 | Y7: =O6/$R$13 -> 0.001934236 | Z7: =P6/$R$13 -> 0.0032237266 | AA7: =Q6/$R$13 -> 0
A8: 20-40 | B8: 33 | C8: 22 | D8: 15 | E8: 7 | F8: 12 | G8: 3 | I8: 92 | K8: 40-70 | L8: 55 | M8: 36 | N8: 19 | O8: 9 | P8: 20 | Q8: 2 | R8: 141 | U8: 40-70 | V8: =L7/$R$13 -> 0.021276596 | W8: =M7/$R$13 -> 0.014184397 | X8: =N7/$R$13 -> 0.0096711799 | Y8: =O7/$R$13 -> 0.0045132173 | Z8: =P7/$R$13 -> 0.0077369439 | AA8: =Q7/$R$13 -> 0.001934236
A9: 40-70 | B9: 55 | C9: 36 | D9: 19 | E9: 9 | F9: 20 | G9: 2 | I9: 141 | K9: 70-100 | L9: 42 | M9: 31 | N9: 18 | O9: 11 | P9: 19 | Q9: 2 | R9: 123 | U9: 70-100 | V9: =L8/$R$13 -> 0.035460993 | W9: =M8/$R$13 -> 0.023210832 | X9: =N8/$R$13 -> 0.012250161 | Y9: =O8/$R$13 -> 0.0058027079 | Z9: =P8/$R$13 -> 0.012894907 | AA9: =Q8/$R$13 -> 0.0012894907
A10: 70-100 | B10: 42 | C10: 31 | D10: 18 | E10: 11 | F10: 19 | G10: 2 | I10: 123 | K10: 100-200 | L10: 79 | M10: 54 | N10: 30 | O10: 28 | P10: 32 | Q10: 6 | R10: 229 | U10: 100-150 | V10: =L9/$R$13 -> 0.027079304 | W10: =M9/$R$13 -> 0.019987105 | X10: =N9/$R$13 -> 0.011605416 | Y10: =O9/$R$13 -> 0.0070921986 | Z10: =P9/$R$13 -> 0.012250161 | AA10: =Q9/$R$13 -> 0.0012894907
A11: Over 200 | B11: 140 | C11: 60 | D11: 58 | E11: 47 | F11: 48 | G11: 11 | I11: 364 | K11: Over 200 | L11: 140 | M11: 60 | N11: 58 | O11: 47 | P11: 48 | Q11: 11 | R11: 364 | U11: Over 150 | V11: =L11/$R$13 -> 0.090264346 | W11: =M11/$R$13 -> 0.03868472 | X11: =N11/$R$13 -> 0.037395229 | Y11: =O11/$R$13 -> 0.03030303 | Z11: =P11/$R$13 -> 0.030947776 | AA11: =Q11/$R$13 -> 0.0070921986
A12: (blank)
A13: Grand Total | B13: 605 | C13: 341 | D13: 210 | E13: 142 | F13: 185 | G13: 68 | I13: 1551 | K13: Grand Total | L13: =SUM(L5:L11) -> 605 | M13: =SUM(M5:M11) -> 341 | N13: =SUM(N5:N11) -> 210 | O13: =SUM(O5:O11) -> 142 | P13: =SUM(P5:P11) -> 185 | Q13: =SUM(Q5:Q11) -> 68 | R13: =SUM(R5:R11) -> 1551
A16: Count of Toll Charge | B16: Column Labels
A17: Row Labels | B17: 0-1000 | C17: 1000-2000 | D17: 2000-3000 | E17: 3000-5000 | F17: 5000-10000 | G17: Over 10000 | H17: (blank) | I17: Grand Total
A18: 0.5-1.0 | B18: 53 | C18: 38 | D18: 19 | E18: 2 | F18: 10 | G18: 1 | I18: 123
A19: 0-0.5 | B19: 88 | C19: 55 | D19: 22 | E19: 6 | F19: 9 | G19: 3 | I19: 183
A20: 1.0-2.0 | B20: 86 | C20: 60 | D20: 27 | E20: 19 | F20: 26 | G20: 5 | I20: 223
A21: 2.0-3.5 | B21: 167 | C21: 100 | D21: 64 | E21: 48 | F21: 58 | G21: 21 | I21: 458
A22: Over 3.5 | B22: 211 | C22: 88 | D22: 78 | E22: 67 | F22: 82 | G22: 38 | I22: 564
A23: (blank)
A24: Grand Total | B24: 605 | C24: 341 | D24: 210 | E24: 142 | F24: 185 | G24: 68 | I24: 1551

Sheet Income-Toll
A3: Count of Toll Charge | B3: Column Labels | U3: Potential Expressway Toll Charge (UGX)
A4: Row Labels | B4: 0-1000 | C4: 1000-2000 | D4: 2000-3000 | E4: 3000-5000 | F4: 5000-10000 | G4: Over 10000 | H4: (blank) | I4: Grand Total | K4: Income (UGX) | L4: 0-1000 | M4: 1000-2000 | N4: 2000-3000 | O4: 3000-5000 | P4: 5000-10000 | Q4: Over 10000 | R4: Grand Total | T4: Income (UGX) | U4: 0-1,000 | V4: 1,000-2,000 | W4: 2,000-3,000 | X4: 3,000-5,000 | Y4: 5,000-10,000 | Z4: Over 10,000
A5: <300,000 | B5: 294 | C5: 121 | D5: 35 | E5: 26 | F5: 39 | G5: 13 | I5: 528 | K5: <300,000 | L5: 294 | M5: 121 | N5: 35 | O5: 26 | P5: 39 | Q5: 13 | R5: 528 | T5: <300,000 | U5: =L5/$R$12 -> 0.200409 | V5: =M5/$R$12 -> 0.082481254 | W5: =N5/$R$12 -> 0.023858214 | X5: =O5/$R$12 -> 0.017723245 | Y5: =P5/$R$12 -> 0.026584867 | Z5: =Q5/$R$12 -> 0.0088616224
A6: >1,000,000 | B6: 23 | C6: 10 | D6: 9 | E6: 11 | F6: 17 | G6: 14 | I6: 84 | K6: 300,000-500,000 | L6: 154 | M6: 118 | N6: 91 | O6: 39 | P6: 41 | Q6: 10 | R6: 453 | T6: 300,000-500,000 | U6: =L9/$R$12 -> 0.015678255 | V6: =M9/$R$12 -> 0.0068166326 | W6: =N9/$R$12 -> 0.0061349693 | X6: =O9/$R$12 -> 0.0074982958 | Y6: =P9/$R$12 -> 0.011588275 | Z6: =Q9/$R$12 -> 0.0095432856
A7: 300,000-500,000 | B7: 154 | C7: 118 | D7: 91 | E7: 39 | F7: 41 | G7: 10 | I7: 453 | K7: 500,000-750,000 | L7: 75 | M7: 59 | N7: 51 | O7: 32 | P7: 49 | Q7: 14 | R7: 280 | T7: 500,000-750,000 | U7: =L6/$R$12 -> 0.10497614 | V7: =M6/$R$12 -> 0.080436264 | W7: =N6/$R$12 -> 0.062031357 | X7: =O6/$R$12 -> 0.026584867 | Y7: =P6/$R$12 -> 0.027948194 | Z7: =Q6/$R$12 -> 0.0068166326
A8: 500,000-750,000 | B8: 75 | C8: 59 | D8: 51 | E8: 32 | F8: 49 | G8: 14 | I8: 280 | K8: 750,000-1,000,000 | L8: 59 | M8: 33 | N8: 24 | O8: 34 | P8: 39 | Q8: 17 | R8: 206 | T8: 750,000-1,000,000 | U8: =L7/$R$12 -> 0.051124744 | V8: =M7/$R$12 -> 0.040218132 | W8: =N7/$R$12 -> 0.034764826 | X8: =O7/$R$12 -> 0.021813224 | Y8: =P7/$R$12 -> 0.0334015 | Z8: =Q7/$R$12 -> 0.0095432856
A9: 750,000-1,000,000 | B9: 59 | C9: 33 | D9: 24 | E9: 34 | F9: 39 | G9: 17 | I9: 206 | K9: >1,000,000 | L9: 23 | M9: 10 | N9: 9 | O9: 11 | P9: 17 | Q9: 14 | R9: 84 | T9: >1,000,000 | U9: =L8/$R$12 -> 0.040218132 | V9: =M8/$R$12 -> 0.022494888 | W9: =N8/$R$12 -> 0.016359918 | X9: =O8/$R$12 -> 0.023176551 | Y9: =P8/$R$12 -> 0.026584867 | Z9: =Q8/$R$12 -> 0.011588275
A10: (blank) | T10: Totals | U10: =SUM(U5:U9) -> 0.41240627 | V10: =SUM(V5:V9) -> 0.23244717 | W10: =SUM(W5:W9) -> 0.14314928 | X10: =SUM(X5:X9) -> 0.096796183 | Y10: =SUM(Y5:Y9) -> 0.1261077 | Z10: =SUM(Z5:Z9) -> 0.046353102
A11: Grand Total | B11: 605 | C11: 341 | D11: 210 | E11: 142 | F11: 185 | G11: 68 | I11: 1551
K12: Grand Total | L12: 387 | M12: 256 | N12: 175 | O12: 66 | P12: 55 | Q12: 29 | R12: =SUM(R5:R8) -> 1467

Sheet Veh-Toll
A3: Count of Toll Charge | B3: Column Labels | U3: Potential Expressway Toll Charge (UGX)
A4: Row Labels | B4: 0-1000 | C4: 1000-2000 | D4: 2000-3000 | E4: 3000-5000 | F4: 5000-10000 | G4: Over 10000 | H4: (blank) | I4: Grand Total | K4: Vehicle Type | L4: 0-1000 | M4: 1000-2000 | N4: 2000-3000 | O4: 3000-5000 | P4: 5000-10000 | Q4: Over 10000 | R4: Grand Total | T4: Vehicle Type | U4: 0-1,000 | V4: 1,000-2,000 | W4: 2,000-3,00 | X4: 3,000-5,000 | Y4: 5,000-10,000 | Z4: Over 10,000
A5: Bicycle | E5: 1 | I5: 1 | K5: Car | L5: 75 | M5: 54 | N5: 24 | O5: 8 | P5: 17 | Q5: 7 | R5: 185 | S5: 185 | T5: Car | U5: =L5/$R$15 -> 0.051020408 | V5: =M5/$R$15 -> 0.036734694 | W5: =N5/$R$15 -> 0.016326531 | X5: =O5/$R$15 -> 0.0054421769 | Y5: =P5/$R$15 -> 0.011564626 | Z5: =Q5/$R$15 -> 0.0047619048
A6: Bicycles | B6: 44 | C6: 24 | D6: 7 | F6: 3 | G6: 1 | I6: 79 | K6: Heavy truck | L6: 1 | N6: 1 | P6: 3 | Q6: 1 | R6: 6 | S6: 6 | T6: Heavy truck | U6: =L6/$R$15 -> 0.00068027211 | V6: =M6/$R$15 -> 0 | W6: =N6/$R$15 -> 0.00068027211 | X6: =O6/$R$15 -> 0 | Y6: =P6/$R$15 -> 0.0020408163 | Z6: =Q6/$R$15 -> 0.00068027211
A7: Bicylces | G7: 1 | I7: 1 | K7: Large Bus | L7: 144 | M7: 68 | N7: 66 | O7: 43 | P7: 59 | Q7: 17 | R7: 397 | S7: 397 | T7: Large Bus | U7: =L7/$R$15 -> 0.097959184 | V7: =M7/$R$15 -> 0.046258503 | W7: =N7/$R$15 -> 0.044897959 | X7: =O7/$R$15 -> 0.029251701 | Y7: =P7/$R$15 -> 0.040136054 | Z7: =Q7/$R$15 -> 0.011564626
A8: Car | B8: 75 | C8: 54 | D8: 24 | E8: 8 | F8: 17 | G8: 7 | I8: 185 | K8: Light Truck | L8: 1 | M8: 4 | N8: 2 | O8: 1 | P8: 2 | R8: 10 | S8: 10 | T8: Light Truck | U8: =L8/$R$15 -> 0.00068027211 | V8: =M8/$R$15 -> 0.0027210884 | W8: =N8/$R$15 -> 0.0013605442 | X8: =O8/$R$15 -> 0.00068027211 | Y8: =P8/$R$15 -> 0.0013605442 | Z8: =Q8/$R$15 -> 0
A9: Heavy truck | B9: 1 | D9: 1 | F9: 3 | G9: 1 | I9: 6 | K9: Medium bus | L9: 9 | M9: 4 | N9: 5 | O9: 6 | P9: 3 | Q9: 3 | R9: 30 | S9: 30 | T9: Medium bus | U9: =L9/$R$15 -> 0.006122449 | V9: =M9/$R$15 -> 0.0027210884 | W9: =N9/$R$15 -> 0.0034013605 | X9: =O9/$R$15 -> 0.0040816327 | Y9: =P9/$R$15 -> 0.0020408163 | Z9: =Q9/$R$15 -> 0.0020408163
A10: Large Bus | B10: 144 | C10: 68 | D10: 66 | E10: 43 | F10: 59 | G10: 17 | I10: 397 | K10: Medium Truck | L10: 1 | P10: 2 | R10: 3 | S10: 3 | T10: Medium Truck | U10: =L10/$R$15 -> 0.00068027211 | V10: =M10/$R$15 -> 0 | W10: =N10/$R$15 -> 0 | X10: =O10/$R$15 -> 0 | Y10: =P10/$R$15 -> 0.0013605442 | Z10: =Q10/$R$15 -> 0
A11: Light Truck | B11: 1 | C11: 4 | D11: 2 | E11: 1 | F11: 2 | I11: 10 | K11: Minibus | L11: 302 | M11: 164 | N11: 94 | O11: 81 | P11: 86 | Q11: 32 | R11: 759 | S11: 759 | T11: Minibus | U11: =L11/$R$15 -> 0.20544218 | V11: =M11/$R$15 -> 0.11156463 | W11: =N11/$R$15 -> 0.063945578 | X11: =O11/$R$15 -> 0.055102041 | Y11: =P11/$R$15 -> 0.058503401 | Z11: =Q11/$R$15 -> 0.021768707
A12: Medium bus | B12: 9 | C12: 4 | D12: 5 | E12: 6 | F12: 3 | G12: 3 | I12: 30 | K12: Pickups | L12: 5 | M12: 5 | N12: 1 | P12: 3 | R12: 14 | S12: 14 | T12: Pickups | U12: =L12/$R$15 -> 0.0034013605 | V12: =M12/$R$15 -> 0.0034013605 | W12: =N12/$R$15 -> 0.00068027211 | X12: =O12/$R$15 -> 0 | Y12: =P12/$R$15 -> 0.0020408163 | Z12: =Q12/$R$15 -> 0
A13: Medium Truck | B13: 1 | F13: 2 | I13: 3 | K13: Station Wagon | L13: 23 | M13: 18 | N13: 10 | O13: 2 | P13: 7 | Q13: 6 | R13: 66 | S13: 66 | T13: Station Wagon | U13: =L13/$R$15 -> 0.015646259 | V13: =M13/$R$15 -> 0.012244898 | W13: =N13/$R$15 -> 0.0068027211 | X13: =O13/$R$15 -> 0.0013605442 | Y13: =P13/$R$15 -> 0.0047619048 | Z13: =Q13/$R$15 -> 0.0040816327
A14: Minibus | B14: 302 | C14: 164 | D14: 94 | E14: 81 | F14: 86 | G14: 32 | I14: 759 | K14: Truck Trailer | T14: Truck Trailer | U14: =L14/$R$15 -> 0 | V14: =M14/$R$15 -> 0 | W14: =N14/$R$15 -> 0 | X14: =O14/$R$15 -> 0 | Y14: =P14/$R$15 -> 0 | Z14: =Q14/$R$15 -> 0
A15: Pickups | B15: 5 | C15: 5 | D15: 1 | F15: 3 | I15: 14 | R15: =SUM(R5:R14) -> 1470
A16: Station Wagon | B16: 23 | C16: 18 | D16: 10 | E16: 2 | F16: 7 | G16: 6 | I16: 66
A17: (blank)
A18: Grand Total | B18: 605 | C18: 341 | D18: 210 | E18: 142 | F18: 185 | G18: 68 | I18: 1551

Sheet WesternSP-Data
A1: Date | B1: Time (24-h format) | C1: Veh_Reg_No. | D1: Driver or Passenger? D/P | E1: Mode No. | F1: Mode Description | G1: Veh_Type | H1: Veh_Type Desc | I1: Gender (M/F) | J1: Age Bracket No. | K1: Age Bracket Desc. | L1: Or Village | M1: Or District | N1: Or Country | O1: Origin_Purpose | P1: Origin-Purpose Desc | Q1: Dest Village | R1: Dest District | S1: Des Country | T1: Dest_Purpose | U1: Dest_Purpose Desc | V1: Journey_Purpose | W1: Cost of Trip (UGX) | X1: Journey Dist (Km) | Y1: Dist Range | Z1: Journey Time (Hrs) | AA1: Time Range | AB1: Profession No. | AC1: Profession Desc. | AD1: Monthly Income No. | AE1: Monthly Income | AF1: Journey Time | AG1: Cost of Journey | AH1: Comfort | AI1: Safety | AJ1: Reliability | AK1: Would You Use Xpressways? Y/N | AL1: Pay How Much? (UGX) | AM1: Toll Charge
A2: 43762 | B2: 0.73472222 | D2: P | E2: 2 | F2: =VLOOKUP(E2,Key!$A$17:$B$21,2,FALSE) -> Road Vehicle | G2: 1 | H2: =VLOOKUP(G2,Key!$A$2:$B$13,2,FALSE) -> Car | I2: M | J2: 1 | K2: =VLOOKUP(J2,Key!$A$24:$B$29,2,FALSE) -> 20-29 | L2: NANSANA | M2: WAKISO | N2: UG | O2: 1 | P2: =VLOOKUP(O2,Key!$E$2:$F$9,2,FALSE) -> Home | Q2: HIOMA | R2: HIOMA | S2: UG | T2: 4 | U2: =VLOOKUP(T2,Key!$E$2:$F$9,2,FALSE) -> Commercial | V2: =P2&"-"&U2 -> Home-Commercial | W2: 13000 | Y2: =IF(X2<10,"0-10",IF(X2<20,"10-20",IF(X2<40,"20-40",IF(X2<70,"40-70",IF(X2<100,"70-100",IF(X2<200,"100-200","Over 200")))))) -> 0-10 | Z2: 3 | AA2: =IF(Z2<0.5,"0-0.5",IF(Z2<1,"0.5-1.0",IF(Z2<2,"1.0-2.0",IF(Z2<3.5,"2.0-3.5","Over 3.5")))) -> 2.0-3.5 | AB2: 6 | AC2: =VLOOKUP(AB2,Key!$C$20:$D$29,2,FALSE) -> Businessman | AD2: 4 | AE2: =VLOOKUP(AD2,Key!$E$20:$F$24,2,FALSE) -> 750,000-1,000,000 | AF2: 2 | AG2: 3 | AH2: 4 | AI2: 1 | AJ2: 5 | AK2: Y | AL2: 3000 | AM2: =IF(AL2<1000,"0-1000",IF(AL2<2000,"1000-2000",IF(AL2<3000,"2000-3000",IF(AL2<5000,"3000-5000",IF(AL2<10000,"5000-10000","Over 10000"))))) -> 3000-5000
A3: 43763 | B3: 0.69166667 | D3: D | E3: 2 | F3: =VLOOKUP(E3,Key!$A$17:$B$21,2,FALSE) -> Road Vehicle | G3: 1 | H3: =VLOOKUP(G3,Key!$A$2:$B$13,2,FALSE) -> Car | I3: M | J3: 1 | K3: =VLOOKUP(J3,Key!$A$24:$B$29,2,FALSE) -> 20-29 | L3: HIOMA | M3: HIOMA | N3: UG | O3: 1 | P3: =VLOOKUP(O3,Key!$E$2:$F$9,2,FALSE) -> Home | Q3: BUKWIRI | R3: KYANKWENZI | S3: UG | T3: 2 | U3: =VLOOKUP(T3,Key!$E$2:$F$9,2,FALSE) -> Work | V3: =P3&"-"&U3 -> Home-Work | W3: 65000 | X3: 75 | Y3: =IF(X3<10,"0-10",IF(X3<20,"10-20",IF(X3<40,"20-40",IF(X3<70,"40-70",IF(X3<100,"70-100",IF(X3<200,"100-200","Over 200")))))) -> 70-100 | Z3: 1 | AA3: =IF(Z3<0.5,"0-0.5",IF(Z3<1,"0.5-1.0",IF(Z3<2,"1.0-2.0",IF(Z3<3.5,"2.0-3.5","Over 3.5")))) -> 1.0-2.0 | AB3: 5 | AC3: =VLOOKUP(AB3,Key!$C$20:$D$29,2,FALSE) -> Professional | AD3: 3 | AE3: =VLOOKUP(AD3,Key!$E$20:$F$24,2,FALSE) -> 500,000-750,000 | AF3: 2 | AG3: 1 | AH3: 1 | AI3: 1 | AJ3: 2 | AK3: Y | AL3: 2000 | AM3: =IF(AL3<1000,"0-1000",IF(AL3<2000,"1000-2000",IF(AL3<3000,"2000-3000",IF(AL3<5000,"3000-5000",IF(AL3<10000,"5000-10000","Over 10000"))))) -> 2000-3000
A4: 43763 | B4: 0.52916667 | D4: D | E4: 2 | F4: =VLOOKUP(E4,Key!$A$17:$B$21,2,FALSE) -> Road Vehicle | G4: 1 | H4: =VLOOKUP(G4,Key!$A$2:$B$13,2,FALSE) -> Car | I4: M | J4: 1 | K4: =VLOOKUP(J4,Key!$A$24:$B$29,2,FALSE) -> 20-29 | L4: HIOMA | M4: HIOMA | N4: UG | O4: 1 | P4: =VLOOKUP(O4,Key!$E$2:$F$9,2,FALSE) -> Home | Q4: KABAALE | R4: HIOMA | S4: UG | T4: 2 | U4: =VLOOKUP(T4,Key!$E$2:$F$9,2,FALSE) -> Work | V4: =P4&"-"&U4 -> Home-Work | W4: 50000 | Y4: =IF(X4<10,"0-10",IF(X4<20,"10-20",IF(X4<40,"20-40",IF(X4<70,"40-70",IF(X4<100,"70-100",IF(X4<200,"100-200","Over 200")))))) -> 0-10 | Z4: 2 | AA4: =IF(Z4<0.5,"0-0.5",IF(Z4<1,"0.5-1.0",IF(Z4<2,"1.0-2.0",IF(Z4<3.5,"2.0-3.5","Over 3.5")))) -> 2.0-3.5 | AB4: 2 | AC4: =VLOOKUP(AB4,Key!$C$20:$D$29,2,FALSE) -> Manual Labour | AD4: 1 | AE4: =VLOOKUP(AD4,Key!$E$20:$F$24,2,FALSE) -> <300,000 | AF4: 3 | AG4: 4 | AH4: 5 | AI4: 1 | AJ4: 2 | AK4: Y | AL4: 5000 | AM4: =IF(AL4<1000,"0-1000",IF(AL4<2000,"1000-2000",IF(AL4<3000,"2000-3000",IF(AL4<5000,"3000-5000",IF(AL4<10000,"5000-10000","Over 10000"))))) -> 5000-10000
A5: 43763 | B5: 0.57916667 | D5: D | E5: 2 | F5: =VLOOKUP(E5,Key!$A$17:$B$21,2,FALSE) -> Road Vehicle | G5: 1 | H5: =VLOOKUP(G5,Key!$A$2:$B$13,2,FALSE) -> Car | I5: M | J5: 1 | K5: =VLOOKUP(J5,Key!$A$24:$B$29,2,FALSE) -> 20-29 | L5: HIOMA | M5: HIOMA | N5: UG | O5: 1 | P5: =VLOOKUP(O5,Key!$E$2:$F$9,2,FALSE) -> Home | Q5: BULIISA | R5: BULIISA | S5: UG | T5: 2 | U5: =VLOOKUP(T5,Key!$E$2:$F$9,2,FALSE) -> Work | V5: =P5&"-"&U5 -> Home-Work | W5: 80000 | X5: 75 | Y5: =IF(X5<10,"0-10",IF(X5<20,"10-20",IF(X5<40,"20-40",IF(X5<70,"40-70",IF(X5<100,"70-100",IF(X5<200,"100-200","Over 200")))))) -> 70-100 | Z5: 2 | AA5: =IF(Z5<0.5,"0-0.5",IF(Z5<1,"0.5-1.0",IF(Z5<2,"1.0-2.0",IF(Z5<3.5,"2.0-3.5","Over 3.5")))) -> 2.0-3.5 | AB5: 5 | AC5: =VLOOKUP(AB5,Key!$C$20:$D$29,2,FALSE) -> Professional | AD5: 4 | AE5: =VLOOKUP(AD5,Key!$E$20:$F$24,2,FALSE) -> 750,000-1,000,000 | AF5: 1 | AG5: 1 | AH5: 1 | AI5: 1 | AJ5: 1 | AK5: Y | AM5: =IF(AL5<1000,"0-1000",IF(AL5<2000,"1000-2000",IF(AL5<3000,"2000-3000",IF(AL5<5000,"3000-5000",IF(AL5<10000,"5000-10000","Over 10000"))))) -> 0-1000
A6: 43763 | B6: 0.33402778 | D6: D | E6: 2 | F6: =VLOOKUP(E6,Key!$A$17:$B$21,2,FALSE) -> Road Vehicle | G6: 1 | H6: =VLOOKUP(G6,Key!$A$2:$B$13,2,FALSE) -> Car | I6: M | J6: 1 | K6: =VLOOKUP(J6,Key!$A$24:$B$29,2,FALSE) -> 20-29 | L6: HIOMA | M6: HIOMA | N6: UG | O6: 2 | P6: =VLOOKUP(O6,Key!$E$2:$F$9,2,FALSE) -> Work | Q6: KAMPALA | R6: KAMPALA | S6: UG | T6: 2 | U6: =VLOOKUP(T6,Key!$E$2:$F$9,2,FALSE) -> Work | V6: =P6&"-"&U6 -> Work-Work | W6: 100000 | X6: 175 | Y6: =IF(X6<10,"0-10",IF(X6<20,"10-20",IF(X6<40,"20-40",IF(X6<70,"40-70",IF(X6<100,"70-100",IF(X6<200,"100-200","Over 200")))))) -> 100-200 | Z6: 3 | AA6: =IF(Z6<0.5,"0-0.5",IF(Z6<1,"0.5-1.0",IF(Z6<2,"1.0-2.0",IF(Z6<3.5,"2.0-3.5","Over 3.5")))) -> 2.0-3.5 | AB6: 5 | AC6: =VLOOKUP(AB6,Key!$C$20:$D$29,2,FALSE) -> Professional | AD6: 4 | AE6: =VLOOKUP(AD6,Key!$E$20:$F$24,2,FALSE) -> 750,000-1,000,000 | AF6: 1 | AG6: 3 | AH6: 5 | AI6: 4 | AJ6: 2 | AK6: Y | AL6: 5000 | AM6: =IF(AL6<1000,"0-1000",IF(AL6<2000,"1000-2000",IF(AL6<3000,"2000-3000",IF(AL6<5000,"3000-5000",IF(AL6<10000,"5000-10000","Over 10000"))))) -> 5000-10000
A7: 43763 | B7: 0.75347222 | D7: P | E7: 2 | F7: =VLOOKUP(E7,Key!$A$17:$B$21,2,FALSE) -> Road Vehicle | G7: 1 | H7: =VLOOKUP(G7,Key!$A$2:$B$13,2,FALSE) -> Car | I7: M | J7: 1 | K7: =VLOOKUP(J7,Key!$A$24:$B$29,2,FALSE) -> 20-29 | L7: HIOMA | M7: HIOMA | N7: UG | O7: 4 | P7: =VLOOKUP(O7,Key!$E$2:$F$9,2,FALSE) -> Commercial | Q7: ARUA | R7: ARUA | S7: UG | T7: 1 | U7: =VLOOKUP(T7,Key!$E$2:$F$9,2,FALSE) -> Home | V7: =P7&"-"&U7 -> Commercial-Home | W7: 350000 | X7: 390 | Y7: =IF(X7<10,"0-10",IF(X7<20,"10-20",IF(X7<40,"20-40",IF(X7<70,"40-70",IF(X7<100,"70-100",IF(X7<200,"100-200","Over 200")))))) -> Over 200 | Z7: 8 | AA7: =IF(Z7<0.5,"0-0.5",IF(Z7<1,"0.5-1.0",IF(Z7<2,"1.0-2.0",IF(Z7<3.5,"2.0-3.5","Over 3.5")))) -> Over 3.5 | AB7: 5 | AC7: =VLOOKUP(AB7,Key!$C$20:$D$29,2,FALSE) -> Professional | AD7: 3 | AE7: =VLOOKUP(AD7,Key!$E$20:$F$24,2,FALSE) -> 500,000-750,000 | AF7: 3 | AG7: 2 | AH7: 1 | AI7: 5 | AJ7: 4 | AK7: Y | AL7: 7000 | AM7: =IF(AL7<1000,"0-1000",IF(AL7<2000,"1000-2000",IF(AL7<3000,"2000-3000",IF(AL7<5000,"3000-5000",IF(AL7<10000,"5000-10000","Over 10000"))))) -> 5000-10000
A8: 43763 | B8: 0.66180556 | D8: D | E8: 2 | F8: =VLOOKUP(E8,Key!$A$17:$B$21,2,FALSE) -> Road Vehicle | G8: 1 | H8: =VLOOKUP(G8,Key!$A$2:$B$13,2,FALSE) -> Car | I8: M | J8: 1 | K8: =VLOOKUP(J8,Key!$A$24:$B$29,2,FALSE) -> 20-29 | L8: HIOMA | M8: HIOMA | N8: UG | O8: 4 | P8: =VLOOKUP(O8,Key!$E$2:$F$9,2,FALSE) -> Commercial | Q8: KIBOGA | R8: KIBOGA | S8: UG | T8: 1 | U8: =VLOOKUP(T8,Key!$E$2:$F$9,2,FALSE) -> Home | V8: =P8&"-"&U8 -> Commercial-Home | W8: 70000 | X8: 115 | Y8: =IF(X8<10,"0-10",IF(X8<20,"10-20",IF(X8<40,"20-40",IF(X8<70,"40-70",IF(X8<100,"70-100",IF(X8<200,"100-200","Over 200")))))) -> 100-200 | Z8: 1 | AA8: =IF(Z8<0.5,"0-0.5",IF(Z8<1,"0.5-1.0",IF(Z8<2,"1.0-2.0",IF(Z8<3.5,"2.0-3.5","Over 3.5")))) -> 1.0-2.0 | AB8: 5 | AC8: =VLOOKUP(AB8,Key!$C$20:$D$29,2,FALSE) -> Professional | AD8: 3 | AE8: =VLOOKUP(AD8,Key!$E$20:$F$24,2,FALSE) -> 500,000-750,000 | AF8: 1 | AG8: 1 | AH8: 2 | AI8: 1 | AJ8: 1 | AK8: Y | AL8: 2000 | AM8: =IF(AL8<1000,"0-1000",IF(AL8<2000,"1000-2000",IF(AL8<3000,"2000-3000",IF(AL8<5000,"3000-5000",IF(AL8<10000,"5000-10000","Over 10000"))))) -> 2000-3000
A9: 43762 | B9: 0.67083333 | D9: P | E9: 2 | F9: =VLOOKUP(E9,Key!$A$17:$B$21,2,FALSE) -> Road Vehicle | G9: 6 | H9: =VLOOKUP(G9,Key!$A$2:$B$13,2,FALSE) -> Large Bus | I9: F | J9: 1 | K9: =VLOOKUP(J9,Key!$A$24:$B$29,2,FALSE) -> 20-29 | L9: HIOMA | M9: HIOMA | N9: UG | O9: 2 | P9: =VLOOKUP(O9,Key!$E$2:$F$9,2,FALSE) -> Work | Q9: KAMPALA | R9: KAMPALA | S9: UG | T9: 1 | U9: =VLOOKUP(T9,Key!$E$2:$F$9,2,FALSE) -> Home | V9: =P9&"-"&U9 -> Work-Home | W9: 13000 | X9: 200 | Y9: =IF(X9<10,"0-10",IF(X9<20,"10-20",IF(X9<40,"20-40",IF(X9<70,"40-70",IF(X9<100,"70-100",IF(X9<200,"100-200","Over 200")))))) -> Over 200 | Z9: 4 | AA9: =IF(Z9<0.5,"0-0.5",IF(Z9<1,"0.5-1.0",IF(Z9<2,"1.0-2.0",IF(Z9<3.5,"2.0-3.5","Over 3.5")))) -> Over 3.5 | AB9: 4 | AC9: =VLOOKUP(AB9,Key!$C$20:$D$29,2,FALSE) -> Office Worker | AD9: 3 | AE9: =VLOOKUP(AD9,Key!$E$20:$F$24,2,FALSE) -> 500,000-750,000 | AF9: 1 | AG9: 2 | AH9: 3 | AI9: 4 | AJ9: 5 | AK9: Y | AL9: 1000 | AM9: =IF(AL9<1000,"0-1000",IF(AL9<2000,"1000-2000",IF(AL9<3000,"2000-3000",IF(AL9<5000,"3000-5000",IF(AL9<10000,"5000-10000","Over 10000"))))) -> 1000-2000
A10: 43762 | B10: 0.61041667 | D10: P | E10: 2 | F10: =VLOOKUP(E10,Key!$A$17:$B$21,2,FALSE) -> Road Vehicle | G10: 6 | H10: =VLOOKUP(G10,Key!$A$2:$B$13,2,FALSE) -> Large Bus | I10: M | J10: 1 | K10: =VLOOKUP(J10,Key!$A$24:$B$29,2,FALSE) -> 20-29 | L10: HIOMA | M10: HIOMA | N10: UG | O10: 2 | P10: =VLOOKUP(O10,Key!$E$2:$F$9,2,FALSE) -> Work | Q10: KAMPALA | R10: KAMPALA | S10: UG | T10: 2 | U10: =VLOOKUP(T10,Key!$E$2:$F$9,2,FALSE) -> Work | V10: =P10&"-"&U10 -> Work-Work | W10: 13000 | X10: 200 | Y10: =IF(X10<10,"0-10",IF(X10<20,"10-20",IF(X10<40,"20-40",IF(X10<70,"40-70",IF(X10<100,"70-100",IF(X10<200,"100-200","Over 200")))))) -> Over 200 | Z10: 3 | AA10: =IF(Z10<0.5,"0-0.5",IF(Z10<1,"0.5-1.0",IF(Z10<2,"1.0-2.0",IF(Z10<3.5,"2.0-3.5","Over 3.5")))) -> 2.0-3.5 | AB10: 4 | AC10: =VLOOKUP(AB10,Key!$C$20:$D$29,2,FALSE) -> Office Worker | AD10: 4 | AE10: =VLOOKUP(AD10,Key!$E$20:$F$24,2,FALSE) -> 750,000-1,000,000 | AF10: 1 | AG10: 3 | AH10: 5 | AI10: 4 | AJ10: 2 | AK10: Y | AM10: =IF(AL10<1000,"0-1000",IF(AL10<2000,"1000-2000",IF(AL10<3000,"2000-3000",IF(AL10<5000,"3000-5000",IF(AL10<10000,"5000-10000","Over 10000"))))) -> 0-1000
A11: 43762 | B11: 0.6 | D11: P | E11: 2 | F11: =VLOOKUP(E11,Key!$A$17:$B$21,2,FALSE) -> Road Vehicle | G11: 6 | H11: =VLOOKUP(G11,Key!$A$2:$B$13,2,FALSE) -> Large Bus | I11: M | J11: 1 | K11: =VLOOKUP(J11,Key!$A$24:$B$29,2,FALSE) -> 20-29 | L11: HIOMA | M11: HIOMA | N11: UG | O11: 2 | P11: =VLOOKUP(O11,Key!$E$2:$F$9,2,FALSE) -> Work | Q11: KAMPALA | R11: KAMPALA | S11: UG | T11: 6 | U11: =VLOOKUP(T11,Key!$E$2:$F$9,2,FALSE) -> Leisure/Social | V11: =P11&"-"&U11 -> Work-Leisure/Social | W11: 13000 | X11: 195 | Y11: =IF(X11<10,"0-10",IF(X11<20,"10-20",IF(X11<40,"20-40",IF(X11<70,"40-70",IF(X11<100,"70-100",IF(X11<200,"100-200","Over 200")))))) -> 100-200 | Z11: 3 | AA11: =IF(Z11<0.5,"0-0.5",IF(Z11<1,"0.5-1.0",IF(Z11<2,"1.0-2.0",IF(Z11<3.5,"2.0-3.5","Over 3.5")))) -> 2.0-3.5 | AB11: 1 | AC11: =VLOOKUP(AB11,Key!$C$20:$D$29,2,FALSE) -> Unemployed | AD11: 1 | AE11: =VLOOKUP(AD11,Key!$E$20:$F$24,2,FALSE) -> <300,000 | AF11: 2 | AG11: 1 | AH11: 5 | AI11: 4 | AJ11: 3 | AK11: Y | AL11: 3000 | AM11: =IF(AL11<1000,"0-1000",IF(AL11<2000,"1000-2000",IF(AL11<3000,"2000-3000",IF(AL11<5000,"3000-5000",IF(AL11<10000,"5000-10000","Over 10000"))))) -> 3000-5000
A12: 43762 | B12: 0.59027778 | D12: P | E12: 2 | F12: =VLOOKUP(E12,Key!$A$17:$B$21,2,FALSE) -> Road Vehicle | G12: 6 | H12: =VLOOKUP(G12,Key!$A$2:$B$13,2,FALSE) -> Large Bus | I12: M | J12: 1 | K12: =VLOOKUP(J12,Key!$A$24:$B$29,2,FALSE) -> 20-29 | L12: HIOMA | M12: HIOMA | N12: UG | O12: 3 | P12: =VLOOKUP(O12,Key!$E$2:$F$9,2,FALSE) -> Study | Q12: KAMPALA | R12: KAMPALA | S12: UG | T12: 5 | U12: =VLOOKUP(T12,Key!$E$2:$F$9,2,FALSE) -> Tourism | V12: =P12&"-"&U12 -> Study-Tourism | W12: 13000 | X12: 200 | Y12: =IF(X12<10,"0-10",IF(X12<20,"10-20",IF(X12<40,"20-40",IF(X12<70,"40-70",IF(X12<100,"70-100",IF(X12<200,"100-200","Over 200")))))) -> Over 200 | Z12: 4 | AA12: =IF(Z12<0.5,"0-0.5",IF(Z12<1,"0.5-1.0",IF(Z12<2,"1.0-2.0",IF(Z12<3.5,"2.0-3.5","Over 3.5")))) -> Over 3.5 | AB12: 5 | AC12: =VLOOKUP(AB12,Key!$C$20:$D$29,2,FALSE) -> Professional | AD12: 4 | AE12: =VLOOKUP(AD12,Key!$E$20:$F$24,2,FALSE) -> 750,000-1,000,000 | AF12: 2 | AG12: 3 | AH12: 5 | AI12: 4 | AJ12: 7 | AK12: Y | AL12: 2000 | AM12: =IF(AL12<1000,"0-1000",IF(AL12<2000,"1000-2000",IF(AL12<3000,"2000-3000",IF(AL12<5000,"3000-5000",IF(AL12<10000,"5000-10000","Over 10000"))))) -> 2000-3000
A13: 43763 | B13: 0.33611111 | D13: P | E13: 2 | F13: =VLOOKUP(E13,Key!$A$17:$B$21,2,FALSE) -> Road Vehicle | G13: 6 | H13: =VLOOKUP(G13,Key!$A$2:$B$13,2,FALSE) -> Large Bus | I13: M | J13: 1 | K13: =VLOOKUP(J13,Key!$A$24:$B$29,2,FALSE) -> 20-29 | L13: HIOMA | M13: HIOMA | N13: UG | O13: 6 | P13: =VLOOKUP(O13,Key!$E$2:$F$9,2,FALSE) -> Leisure/Social | Q13: KYANKWENZI | R13: KIKUUBE | S13: UG | T13: 6 | U13: =VLOOKUP(T13,Key!$E$2:$F$9,2,FALSE) -> Leisure/Social | V13: =P13&"-"&U13 -> Leisure/Social-Leisure/Social | W13: 10000 | X13: 130 | Y13: =IF(X13<10,"0-10",IF(X13<20,"10-20",IF(X13<40,"20-40",IF(X13<70,"40-70",IF(X13<100,"70-100",IF(X13<200,"100-200","Over 200")))))) -> 100-200 | Z13: 2 | AA13: =IF(Z13<0.5,"0-0.5",IF(Z13<1,"0.5-1.0",IF(Z13<2,"1.0-2.0",IF(Z13<3.5,"2.0-3.5","Over 3.5")))) -> 2.0-3.5 | AB13: 3 | AC13: =VLOOKUP(AB13,Key!$C$20:$D$29,2,FALSE) -> Artisan/Domestic | AD13: 2 | AE13: =VLOOKUP(AD13,Key!$E$20:$F$24,2,FALSE) -> 300,000-500,000 | AF13: 1 | AG13: 1 | AH13: 1 | AI13: 1 | AJ13: 1 | AK13: Y | AM13: =IF(AL13<1000,"0-1000",IF(AL13<2000,"1000-2000",IF(AL13<3000,"2000-3000",IF(AL13<5000,"3000-5000",IF(AL13<10000,"5000-10000","Over 10000"))))) -> 0-1000
A14: 43763 | B14: 0.33611111 | D14: P | E14: 2 | F14: =VLOOKUP(E14,Key!$A$17:$B$21,2,FALSE) -> Road Vehicle | G14: 6 | H14: =VLOOKUP(G14,Key!$A$2:$B$13,2,FALSE) -> Large Bus | I14: M | J14: 1 | K14: =VLOOKUP(J14,Key!$A$24:$B$29,2,FALSE) -> 20-29 | L14: HIOMA | M14: HIOMA | N14: UG | O14: 1 | P14: =VLOOKUP(O14,Key!$E$2:$F$9,2,FALSE) -> Home | Q14: KYANKWENZI | R14: KIKUUBE | S14: UG | T14: 6 | U14: =VLOOKUP(T14,Key!$E$2:$F$9,2,FALSE) -> Leisure/Social | V14: =P14&"-"&U14 -> Home-Leisure/Social | W14: 10000 | X14: 130 | Y14: =IF(X14<10,"0-10",IF(X14<20,"10-20",IF(X14<40,"20-40",IF(X14<70,"40-70",IF(X14<100,"70-100",IF(X14<200,"100-200","Over 200")))))) -> 100-200 | Z14: 2 | AA14: =IF(Z14<0.5,"0-0.5",IF(Z14<1,"0.5-1.0",IF(Z14<2,"1.0-2.0",IF(Z14<3.5,"2.0-3.5","Over 3.5")))) -> 2.0-3.5 | AB14: 3 | AC14: =VLOOKUP(AB14,Key!$C$20:$D$29,2,FALSE) -> Artisan/Domestic | AD14: 2 | AE14: =VLOOKUP(AD14,Key!$E$20:$F$24,2,FALSE) -> 300,000-500,000 | AF14: 1 | AG14: 1 | AH14: 1 | AI14: 1 | AJ14: 1 | AK14: Y | AL14: 1000 | AM14: =IF(AL14<1000,"0-1000",IF(AL14<2000,"1000-2000",IF(AL14<3000,"2000-3000",IF(AL14<5000,"3000-5000",IF(AL14<10000,"5000-10000","Over 10000"))))) -> 1000-2000
A15: 43763 | B15: 0.71875 | D15: D | E15: 2 | F15: =VLOOKUP(E15,Key!$A$17:$B$21,2,FALSE) -> Road Vehicle | G15: 6 | H15: =VLOOKUP(G15,Key!$A$2:$B$13,2,FALSE) -> Large Bus | I15: M | J15: 1 | K15: =VLOOKUP(J15,Key!$A$24:$B$29,2,FALSE) -> 20-29 | L15: HIOMA | M15: HIOMA | N15: UG | O15: 2 | P15: =VLOOKUP(O15,Key!$E$2:$F$9,2,FALSE) -> Work | Q15: KIBUULE | R15: KIBUULE | S15: UG | T15: 1 | U15: =VLOOKUP(T15,Key!$E$2:$F$9,2,FALSE) -> Home | V15: =P15&"-"&U15 -> Work-Home | W15: 600000 | X15: 80 | Y15: =IF(X15<10,"0-10",IF(X15<20,"10-20",IF(X15<40,"20-40",IF(X15<70,"40-70",IF(X15<100,"70-100",IF(X15<200,"100-200","Over 200")))))) -> 70-100 | Z15: 3 | AA15: =IF(Z15<0.5,"0-0.5",IF(Z15<1,"0.5-1.0",IF(Z15<2,"1.0-2.0",IF(Z15<3.5,"2.0-3.5","Over 3.5")))) -> 2.0-3.5 | AB15: 10 | AC15: =VLOOKUP(AB15,Key!$C$20:$D$29,2,FALSE) -> Other | AD15: 4 | AE15: =VLOOKUP(AD15,Key!$E$20:$F$24,2,FALSE) -> 750,000-1,000,000 | AF15: 1 | AG15: 2 | AH15: 3 | AI15: 4 | AJ15: 5 | AK15: Y | AL15: 3000 | AM15: =IF(AL15<1000,"0-1000",IF(AL15<2000,"1000-2000",IF(AL15<3000,"2000-3000",IF(AL15<5000,"3000-5000",IF(AL15<10000,"5000-10000","Over 10000"))))) -> 3000-5000
A16: 43763 | B16: 0.65 | D16: P | E16: 2 | F16: =VLOOKUP(E16,Key!$A$17:$B$21,2,FALSE) -> Road Vehicle | G16: 6 | H16: =VLOOKUP(G16,Key!$A$2:$B$13,2,FALSE) -> Large Bus | I16: M | J16: 1 | K16: =VLOOKUP(J16,Key!$A$24:$B$29,2,FALSE) -> 20-29 | L16: HIOMA | M16: HIOMA | N16: UG | O16: 3 | P16: =VLOOKUP(O16,Key!$E$2:$F$9,2,FALSE) -> Study | Q16: KAMPALA | R16: KAMPALA | S16: UG | T16: 1 | U16: =VLOOKUP(T16,Key!$E$2:$F$9,2,FALSE) -> Home | V16: =P16&"-"&U16 -> Study-Home | W16: 130000 | X16: 190 | Y16: =IF(X16<10,"0-10",IF(X16<20,"10-20",IF(X16<40,"20-40",IF(X16<70,"40-70",IF(X16<100,"70-100",IF(X16<200,"100-200","Over 200")))))) -> 100-200 | Z16: 4 | AA16: =IF(Z16<0.5,"0-0.5",IF(Z16<1,"0.5-1.0",IF(Z16<2,"1.0-2.0",IF(Z16<3.5,"2.0-3.5","Over 3.5")))) -> Over 3.5 | AB16: 4 | AC16: =VLOOKUP(AB16,Key!$C$20:$D$29,2,FALSE) -> Office Worker | AD16: 4 | AE16: =VLOOKUP(AD16,Key!$E$20:$F$24,2,FALSE) -> 750,000-1,000,000 | AF16: 5 | AG16: 4 | AH16: 3 | AI16: 2 | AJ16: 1 | AK16: Y | AM16: =IF(AL16<1000,"0-1000",IF(AL16<2000,"1000-2000",IF(AL16<3000,"2000-3000",IF(AL16<5000,"3000-5000",IF(AL16<10000,"5000-10000","Over 10000"))))) -> 0-1000
A17: 43763 | B17: 0.64930556 | D17: P | E17: 2 | F17: =VLOOKUP(E17,Key!$A$17:$B$21,2,FALSE) -> Road Vehicle | G17: 6 | H17: =VLOOKUP(G17,Key!$A$2:$B$13,2,FALSE) -> Large Bus | I17: M | J17: 1 | K17: =VLOOKUP(J17,Key!$A$24:$B$29,2,FALSE) -> 20-29 | L17: HIOMA | M17: HIOMA | N17: UG | O17: 1 | P17: =VLOOKUP(O17,Key!$E$2:$F$9,2,FALSE) -> Home | Q17: KAMPALA | R17: KAMPALA | S17: UG | T17: 2 | U17: =VLOOKUP(T17,Key!$E$2:$F$9,2,FALSE) -> Work | V17: =P17&"-"&U17 -> Home-Work | W17: 130000 | X17: 190 | Y17: =IF(X17<10,"0-10",IF(X17<20,"10-20",IF(X17<40,"20-40",IF(X17<70,"40-70",IF(X17<100,"70-100",IF(X17<200,"100-200","Over 200")))))) -> 100-200 | Z17: 4 | AA17: =IF(Z17<0.5,"0-0.5",IF(Z17<1,"0.5-1.0",IF(Z17<2,"1.0-2.0",IF(Z17<3.5,"2.0-3.5","Over 3.5")))) -> Over 3.5 | AB17: 10 | AC17: =VLOOKUP(AB17,Key!$C$20:$D$29,2,FALSE) -> Other | AD17: 3 | AE17: =VLOOKUP(AD17,Key!$E$20:$F$24,2,FALSE) -> 500,000-750,000 | AF17: 5 | AG17: 4 | AH17: 3 | AI17: 2 | AJ17: 1 | AK17: Y | AL17: 5000 | AM17: =IF(AL17<1000,"0-1000",IF(AL17<2000,"1000-2000",IF(AL17<3000,"2000-3000",IF(AL17<5000,"3000-5000",IF(AL17<10000,"5000-10000","Over 10000"))))) -> 5000-10000
A18: 43763 | B18: 0.60902778 | D18: P | E18: 2 | F18: =VLOOKUP(E18,Key!$A$17:$B$21,2,FALSE) -> Road Vehicle | G18: 6 | H18: =VLOOKUP(G18,Key!$A$2:$B$13,2,FALSE) -> Large Bus | I18: M | J18: 1 | K18: =VLOOKUP(J18,Key!$A$24:$B$29,2,FALSE) -> 20-29 | L18: HIOMA | M18: HIOMA | N18: UG | O18: 2 | P18: =VLOOKUP(O18,Key!$E$2:$F$9,2,FALSE) -> Work | Q18: KAMPALA | R18: KAMPALA | S18: UG | T18: 1 | U18: =VLOOKUP(T18,Key!$E$2:$F$9,2,FALSE) -> Home | V18: =P18&"-"&U18 -> Work-Home | W18: 130000 | X18: 194 | Y18: =IF(X18<10,"0-10",IF(X18<20,"10-20",IF(X18<40,"20-40",IF(X18<70,"40-70",IF(X18<100,"70-100",IF(X18<200,"100-200","Over 200")))))) -> 100-200 | Z18: 4 | AA18: =IF(Z18<0.5,"0-0.5",IF(Z18<1,"0.5-1.0",IF(Z18<2,"1.0-2.0",IF(Z18<3.5,"2.0-3.5","Over 3.5")))) -> Over 3.5 | AB18: 6 | AC18: =VLOOKUP(AB18,Key!$C$20:$D$29,2,FALSE) -> Businessman | AD18: 3 | AE18: =VLOOKUP(AD18,Key!$E$20:$F$24,2,FALSE) -> 500,000-750,000 | AF18: 5 | AG18: 1 | AH18: 2 | AI18: 4 | AJ18: 3 | AK18: Y | AL18: 1000 | AM18: =IF(AL18<1000,"0-1000",IF(AL18<2000,"1000-2000",IF(AL18<3000,"2000-3000",IF(AL18<5000,"3000-5000",IF(AL18<10000,"5000-10000","Over 10000"))))) -> 1000-2000
A19: 43763 | B19: 0.56111111 | D19: P | E19: 2 | F19: =VLOOKUP(E19,Key!$A$17:$B$21,2,FALSE) -> Road Vehicle | G19: 6 | H19: =VLOOKUP(G19,Key!$A$2:$B$13,2,FALSE) -> Large Bus | I19: M | J19: 1 | K19: =VLOOKUP(J19,Key!$A$24:$B$29,2,FALSE) -> 20-29 | L19: HIOMA | M19: HIOMA | N19: UG | O19: 4 | P19: =VLOOKUP(O19,Key!$E$2:$F$9,2,FALSE) -> Commercial | Q19: KAMPALA | R19: KAMPALA | S19: UG | T19: 1 | U19: =VLOOKUP(T19,Key!$E$2:$F$9,2,FALSE) -> Home | V19: =P19&"-"&U19 -> Commercial-Home | W19: 130000 | X19: 200 | Y19: =IF(X19<10,"0-10",IF(X19<20,"10-20",IF(X19<40,"20-40",IF(X19<70,"40-70",IF(X19<100,"70-100",IF(X19<200,"100-200","Over 200")))))) -> Over 200 | Z19: 4 | AA19: =IF(Z19<0.5,"0-0.5",IF(Z19<1,"0.5-1.0",IF(Z19<2,"1.0-2.0",IF(Z19<3.5,"2.0-3.5","Over 3.5")))) -> Over 3.5 | AB19: 6 | AC19: =VLOOKUP(AB19,Key!$C$20:$D$29,2,FALSE) -> Businessman | AD19: 2 | AE19: =VLOOKUP(AD19,Key!$E$20:$F$24,2,FALSE) -> 300,000-500,000 | AF19: 1 | AG19: 2 | AH19: 5 | AI19: 4 | AJ19: 3 | AK19: Y | AM19: =IF(AL19<1000,"0-1000",IF(AL19<2000,"1000-2000",IF(AL19<3000,"2000-3000",IF(AL19<5000,"3000-5000",IF(AL19<10000,"5000-10000","Over 10000"))))) -> 0-1000
A20: 43763 | B20: 0.53472222 | D20: P | E20: 2 | F20: =VLOOKUP(E20,Key!$A$17:$B$21,2,FALSE) -> Road Vehicle | G20: 6 | H20: =VLOOKUP(G20,Key!$A$2:$B$13,2,FALSE) -> Large Bus | I20: M | J20: 1 | K20: =VLOOKUP(J20,Key!$A$24:$B$29,2,FALSE) -> 20-29 | L20: HIOMA | M20: HIOMA | N20: UG | O20: 6 | P20: =VLOOKUP(O20,Key!$E$2:$F$9,2,FALSE) -> Leisure/Social | Q20: KAMPALA | R20: KAMPALA | S20: UG | T20: 1 | U20: =VLOOKUP(T20,Key!$E$2:$F$9,2,FALSE) -> Home | V20: =P20&"-"&U20 -> Leisure/Social-Home | W20: 130000 | X20: 220 | Y20: =IF(X20<10,"0-10",IF(X20<20,"10-20",IF(X20<40,"20-40",IF(X20<70,"40-70",IF(X20<100,"70-100",IF(X20<200,"100-200","Over 200")))))) -> Over 200 | Z20: 5 | AA20: =IF(Z20<0.5,"0-0.5",IF(Z20<1,"0.5-1.0",IF(Z20<2,"1.0-2.0",IF(Z20<3.5,"2.0-3.5","Over 3.5")))) -> Over 3.5 | AB20: 3 | AC20: =VLOOKUP(AB20,Key!$C$20:$D$29,2,FALSE) -> Artisan/Domestic | AD20: 3 | AE20: =VLOOKUP(AD20,Key!$E$20:$F$24,2,FALSE) -> 500,000-750,000 | AF20: 5 | AG20: 2 | AH20: 1 | AI20: 4 | AJ20: 5 | AK20: Y | AL20: 2000 | AM20: =IF(AL20<1000,"0-1000",IF(AL20<2000,"1000-2000",IF(AL20<3000,"2000-3000",IF(AL20<5000,"3000-5000",IF(AL20<10000,"5000-10000","Over 10000"))))) -> 2000-3000
A21: 43763 | B21: 0.50972222 | D21: P | E21: 2 | F21: =VLOOKUP(E21,Key!$A$17:$B$21,2,FALSE) -> Road Vehicle | G21: 6 | H21: =VLOOKUP(G21,Key!$A$2:$B$13,2,FALSE) -> Large Bus | I21: M | J21: 1 | K21: =VLOOKUP(J21,Key!$A$24:$B$29,2,FALSE) -> 20-29 | L21: HIOMA | M21: HIOMA | N21: UG | O21: 2 | P21: =VLOOKUP(O21,Key!$E$2:$F$9,2,FALSE) -> Work | Q21: BULIISA | R21: BULIISA | S21: UG | T21: 1 | U21: =VLOOKUP(T21,Key!$E$2:$F$9,2,FALSE) -> Home | V21: =P21&"-"&U21 -> Work-Home | W21: 15000 | X21: 200 | Y21: =IF(X21<10,"0-10",IF(X21<20,"10-20",IF(X21<40,"20-40",IF(X21<70,"40-70",IF(X21<100,"70-100",IF(X21<200,"100-200","Over 200")))))) -> Over 200 | Z21: 3 | AA21: =IF(Z21<0.5,"0-0.5",IF(Z21<1,"0.5-1.0",IF(Z21<2,"1.0-2.0",IF(Z21<3.5,"2.0-3.5","Over 3.5")))) -> 2.0-3.5 | AB21: 4 | AC21: =VLOOKUP(AB21,Key!$C$20:$D$29,2,FALSE) -> Office Worker | AD21: 2 | AE21: =VLOOKUP(AD21,Key!$E$20:$F$24,2,FALSE) -> 300,000-500,000 | AF21: 1 | AG21: 2 | AH21: 3 | AI21: 4 | AJ21: 5 | AK21: Y | AM21: =IF(AL21<1000,"0-1000",IF(AL21<2000,"1000-2000",IF(AL21<3000,"2000-3000",IF(AL21<5000,"3000-5000",IF(AL21<10000,"5000-10000","Over 10000"))))) -> 0-1000
A22: 43763 | B22: 0.60486111 | D22: P | E22: 2 | F22: =VLOOKUP(E22,Key!$A$17:$B$21,2,FALSE) -> Road Vehicle | G22: 5 | H22: =VLOOKUP(G22,Key!$A$2:$B$13,2,FALSE) -> Medium bus | I22: M | J22: 1 | K22: =VLOOKUP(J22,Key!$A$24:$B$29,2,FALSE) -> 20-29 | L22: HIOMA | M22: HIOMA | N22: UG | O22: 2 | P22: =VLOOKUP(O22,Key!$E$2:$F$9,2,FALSE) -> Work | Q22: KAMPALA | R22: KAMPALA | S22: UG | T22: 2 | U22: =VLOOKUP(T22,Key!$E$2:$F$9,2,FALSE) -> Work | V22: =P22&"-"&U22 -> Work-Work | W22: 650000 | X22: 200 | Y22: =IF(X22<10,"0-10",IF(X22<20,"10-20",IF(X22<40,"20-40",IF(X22<70,"40-70",IF(X22<100,"70-100",IF(X22<200,"100-200","Over 200")))))) -> Over 200 | Z22: 5 | AA22: =IF(Z22<0.5,"0-0.5",IF(Z22<1,"0.5-1.0",IF(Z22<2,"1.0-2.0",IF(Z22<3.5,"2.0-3.5","Over 3.5")))) -> Over 3.5 | AB22: 10 | AC22: =VLOOKUP(AB22,Key!$C$20:$D$29,2,FALSE) -> Other | AD22: 5 | AE22: =VLOOKUP(AD22,Key!$E$20:$F$24,2,FALSE) -> >1,000,000 | AF22: 1 | AG22: 2 | AH22: 3 | AI22: 5 | AJ22: 4 | AK22: Y | AL22: 1000 | AM22: =IF(AL22<1000,"0-1000",IF(AL22<2000,"1000-2000",IF(AL22<3000,"2000-3000",IF(AL22<5000,"3000-5000",IF(AL22<10000,"5000-10000","Over 10000"))))) -> 1000-2000
A23: 43762 | B23: 0.76666667 | D23: P | E23: 2 | F23: =VLOOKUP(E23,Key!$A$17:$B$21,2,FALSE) -> Road Vehicle | G23: 4 | H23: =VLOOKUP(G23,Key!$A$2:$B$13,2,FALSE) -> Minibus | I23: F | J23: 1 | K23: =VLOOKUP(J23,Key!$A$24:$B$29,2,FALSE) -> 20-29 | L23: HIOMA | M23: HIOMA | N23: UG | O23: 2 | P23: =VLOOKUP(O23,Key!$E$2:$F$9,2,FALSE) -> Work | Q23: KAMPALA | R23: KAMPALA | S23: UG | T23: 1 | U23: =VLOOKUP(T23,Key!$E$2:$F$9,2,FALSE) -> Home | V23: =P23&"-"&U23 -> Work-Home | W23: 15000 | X23: 200 | Y23: =IF(X23<10,"0-10",IF(X23<20,"10-20",IF(X23<40,"20-40",IF(X23<70,"40-70",IF(X23<100,"70-100",IF(X23<200,"100-200","Over 200")))))) -> Over 200 | Z23: 3 | AA23: =IF(Z23<0.5,"0-0.5",IF(Z23<1,"0.5-1.0",IF(Z23<2,"1.0-2.0",IF(Z23<3.5,"2.0-3.5","Over 3.5")))) -> 2.0-3.5 | AB23: 2 | AC23: =VLOOKUP(AB23,Key!$C$20:$D$29,2,FALSE) -> Manual Labour | AD23: 2 | AE23: =VLOOKUP(AD23,Key!$E$20:$F$24,2,FALSE) -> 300,000-500,000 | AF23: 1 | AG23: 3 | AH23: 2 | AI23: 5 | AJ23: 4 | AK23: Y | AL23: 3000 | AM23: =IF(AL23<1000,"0-1000",IF(AL23<2000,"1000-2000",IF(AL23<3000,"2000-3000",IF(AL23<5000,"3000-5000",IF(AL23<10000,"5000-10000","Over 10000"))))) -> 3000-5000
A24: 43762 | B24: 0.725 | D24: P | E24: 2 | F24: =VLOOKUP(E24,Key!$A$17:$B$21,2,FALSE) -> Road Vehicle | G24: 4 | H24: =VLOOKUP(G24,Key!$A$2:$B$13,2,FALSE) -> Minibus | I24: F | J24: 1 | K24: =VLOOKUP(J24,Key!$A$24:$B$29,2,FALSE) -> 20-29 | L24: HIOMA | M24: HIOMA | N24: UG | O24: 1 | P24: =VLOOKUP(O24,Key!$E$2:$F$9,2,FALSE) -> Home | Q24: KABAALE | R24: KABAALE | S24: UG | T24: 2 | U24: =VLOOKUP(T24,Key!$E$2:$F$9,2,FALSE) -> Work | V24: =P24&"-"&U24 -> Home-Work | W24: 5000 | X24: 31 | Y24: =IF(X24<10,"0-10",IF(X24<20,"10-20",IF(X24<40,"20-40",IF(X24<70,"40-70",IF(X24<100,"70-100",IF(X24<200,"100-200","Over 200")))))) -> 20-40 | Z24: 24 | AA24: =IF(Z24<0.5,"0-0.5",IF(Z24<1,"0.5-1.0",IF(Z24<2,"1.0-2.0",IF(Z24<3.5,"2.0-3.5","Over 3.5")))) -> Over 3.5 | AB24: 2 | AC24: =VLOOKUP(AB24,Key!$C$20:$D$29,2,FALSE) -> Manual Labour | AD24: 1 | AE24: =VLOOKUP(AD24,Key!$E$20:$F$24,2,FALSE) -> <300,000 | AF24: 5 | AG24: 3 | AH24: 1 | AI24: 2 | AJ24: 4 | AK24: Y | AM24: =IF(AL24<1000,"0-1000",IF(AL24<2000,"1000-2000",IF(AL24<3000,"2000-3000",IF(AL24<5000,"3000-5000",IF(AL24<10000,"5000-10000","Over 10000"))))) -> 0-1000
A25: 43762 | B25: 0.64722222 | D25: P | E25: 2 | F25: =VLOOKUP(E25,Key!$A$17:$B$21,2,FALSE) -> Road Vehicle | G25: 4 | H25: =VLOOKUP(G25,Key!$A$2:$B$13,2,FALSE) -> Minibus | I25: F | J25: 1 | K25: =VLOOKUP(J25,Key!$A$24:$B$29,2,FALSE) -> 20-29 | L25: HIOMA | M25: HIOMA | N25: UG | O25: 2 | P25: =VLOOKUP(O25,Key!$E$2:$F$9,2,FALSE) -> Work | Q25: BUSUJJU | R25: BUSUJJU | S25: UG | T25: 2 | U25: =VLOOKUP(T25,Key!$E$2:$F$9,2,FALSE) -> Work | V25: =P25&"-"&U25 -> Work-Work | W25: 15000 | X25: 117 | Y25: =IF(X25<10,"0-10",IF(X25<20,"10-20",IF(X25<40,"20-40",IF(X25<70,"40-70",IF(X25<100,"70-100",IF(X25<200,"100-200","Over 200")))))) -> 100-200 | Z25: 2 | AA25: =IF(Z25<0.5,"0-0.5",IF(Z25<1,"0.5-1.0",IF(Z25<2,"1.0-2.0",IF(Z25<3.5,"2.0-3.5","Over 3.5")))) -> 2.0-3.5 | AB25: 4 | AC25: =VLOOKUP(AB25,Key!$C$20:$D$29,2,FALSE) -> Office Worker | AD25: 3 | AE25: =VLOOKUP(AD25,Key!$E$20:$F$24,2,FALSE) -> 500,000-750,000 | AF25: 1 | AG25: 2 | AH25: 3 | AI25: 5 | AJ25: 4 | AK25: Y | AM25: =IF(AL25<1000,"0-1000",IF(AL25<2000,"1000-2000",IF(AL25<3000,"2000-3000",IF(AL25<5000,"3000-5000",IF(AL25<10000,"5000-10000","Over 10000"))))) -> 0-1000
A26: 43762 | B26: 0.66875 | D26: P | E26: 2 | F26: =VLOOKUP(E26,Key!$A$17:$B$21,2,FALSE) -> Road Vehicle | G26: 4 | H26: =VLOOKUP(G26,Key!$A$2:$B$13,2,FALSE) -> Minibus | I26: F | J26: 1 | K26: =VLOOKUP(J26,Key!$A$24:$B$29,2,FALSE) -> 20-29 | L26: HIOMA | M26: HIOMA | N26: UG | O26: 8 | P26: =VLOOKUP(O26,Key!$E$2:$F$9,2,FALSE) -> Others | Q26: KAMPALA | R26: KAMPALA | S26: UG | T26: 3 | U26: =VLOOKUP(T26,Key!$E$2:$F$9,2,FALSE) -> Study | V26: =P26&"-"&U26 -> Others-Study | W26: 15000 | X26: 200 | Y26: =IF(X26<10,"0-10",IF(X26<20,"10-20",IF(X26<40,"20-40",IF(X26<70,"40-70",IF(X26<100,"70-100",IF(X26<200,"100-200","Over 200")))))) -> Over 200 | Z26: 3 | AA26: =IF(Z26<0.5,"0-0.5",IF(Z26<1,"0.5-1.0",IF(Z26<2,"1.0-2.0",IF(Z26<3.5,"2.0-3.5","Over 3.5")))) -> 2.0-3.5 | AB26: 8 | AC26: =VLOOKUP(AB26,Key!$C$20:$D$29,2,FALSE) -> Student | AD26: 2 | AE26: =VLOOKUP(AD26,Key!$E$20:$F$24,2,FALSE) -> 300,000-500,000 | AF26: 4 | AG26: 1 | AH26: 2 | AI26: 3 | AJ26: 5 | AK26: Y | AL26: 1000 | AM26: =IF(AL26<1000,"0-1000",IF(AL26<2000,"1000-2000",IF(AL26<3000,"2000-3000",IF(AL26<5000,"3000-5000",IF(AL26<10000,"5000-10000","Over 10000"))))) -> 1000-2000
A27: 43762 | B27: 0.62361111 | D27: P | E27: 2 | F27: =VLOOKUP(E27,Key!$A$17:$B$21,2,FALSE) -> Road Vehicle | G27: 4 | H27: =VLOOKUP(G27,Key!$A$2:$B$13,2,FALSE) -> Minibus | I27: F | J27: 1 | K27: =VLOOKUP(J27,Key!$A$24:$B$29,2,FALSE) -> 20-29 | L27: HIOMA | M27: HIOMA | N27: UG | O27: 2 | P27: =VLOOKUP(O27,Key!$E$2:$F$9,2,FALSE) -> Work | Q27: HIOMA | R27: HIOMA | S27: UG | T27: 2 | U27: =VLOOKUP(T27,Key!$E$2:$F$9,2,FALSE) -> Work | V27: =P27&"-"&U27 -> Work-Work | W27: 12000 | Y27: =IF(X27<10,"0-10",IF(X27<20,"10-20",IF(X27<40,"20-40",IF(X27<70,"40-70",IF(X27<100,"70-100",IF(X27<200,"100-200","Over 200")))))) -> 0-10 | Z27: 3 | AA27: =IF(Z27<0.5,"0-0.5",IF(Z27<1,"0.5-1.0",IF(Z27<2,"1.0-2.0",IF(Z27<3.5,"2.0-3.5","Over 3.5")))) -> 2.0-3.5 | AB27: 2 | AC27: =VLOOKUP(AB27,Key!$C$20:$D$29,2,FALSE) -> Manual Labour | AD27: 1 | AE27: =VLOOKUP(AD27,Key!$E$20:$F$24,2,FALSE) -> <300,000 | AF27: 1 | AG27: 4 | AH27: 1 | AI27: 2 | AJ27: 3 | AK27: Y | AL27: 3000 | AM27: =IF(AL27<1000,"0-1000",IF(AL27<2000,"1000-2000",IF(AL27<3000,"2000-3000",IF(AL27<5000,"3000-5000",IF(AL27<10000,"5000-10000","Over 10000"))))) -> 3000-5000
A28: 43762 | B28: 0.69375 | D28: P | E28: 2 | F28: =VLOOKUP(E28,Key!$A$17:$B$21,2,FALSE) -> Road Vehicle | G28: 4 | H28: =VLOOKUP(G28,Key!$A$2:$B$13,2,FALSE) -> Minibus | I28: F | J28: 1 | K28: =VLOOKUP(J28,Key!$A$24:$B$29,2,FALSE) -> 20-29 | L28: KIBOGA | M28: KIBOGA | N28: UG | O28: 8 | P28: =VLOOKUP(O28,Key!$E$2:$F$9,2,FALSE) -> Others | Q28: HIOMA | R28: HIOMA | S28: UG | T28: 1 | U28: =VLOOKUP(T28,Key!$E$2:$F$9,2,FALSE) -> Home | V28: =P28&"-"&U28 -> Others-Home | W28: 7000 | Y28: =IF(X28<10,"0-10",IF(X28<20,"10-20",IF(X28<40,"20-40",IF(X28<70,"40-70",IF(X28<100,"70-100",IF(X28<200,"100-200","Over 200")))))) -> 0-10 | Z28: 2 | AA28: =IF(Z28<0.5,"0-0.5",IF(Z28<1,"0.5-1.0",IF(Z28<2,"1.0-2.0",IF(Z28<3.5,"2.0-3.5","Over 3.5")))) -> 2.0-3.5 | AB28: 3 | AC28: =VLOOKUP(AB28,Key!$C$20:$D$29,2,FALSE) -> Artisan/Domestic | AD28: 1 | AE28: =VLOOKUP(AD28,Key!$E$20:$F$24,2,FALSE) -> <300,000 | AF28: 4 | AG28: 1 | AH28: 2 | AI28: 5 | AJ28: 2 | AK28: Y | AM28: =IF(AL28<1000,"0-1000",IF(AL28<2000,"1000-2000",IF(AL28<3000,"2000-3000",IF(AL28<5000,"3000-5000",IF(AL28<10000,"5000-10000","Over 10000"))))) -> 0-1000
A29: 43762 | B29: 0.74097222 | D29: P | E29: 2 | F29: =VLOOKUP(E29,Key!$A$17:$B$21,2,FALSE) -> Road Vehicle | G29: 4 | H29: =VLOOKUP(G29,Key!$A$2:$B$13,2,FALSE) -> Minibus | I29: F | J29: 1 | K29: =VLOOKUP(J29,Key!$A$24:$B$29,2,FALSE) -> 20-29 | L29: KASUBI | M29: KAMPALA | N29: UG | O29: 1 | P29: =VLOOKUP(O29,Key!$E$2:$F$9,2,FALSE) -> Home | Q29: HIOMA | R29: HIOMA | S29: UG | T29: 8 | U29: =VLOOKUP(T29,Key!$E$2:$F$9,2,FALSE) -> Others | V29: =P29&"-"&U29 -> Home-Others | W29: 15000 | Y29: =IF(X29<10,"0-10",IF(X29<20,"10-20",IF(X29<40,"20-40",IF(X29<70,"40-70",IF(X29<100,"70-100",IF(X29<200,"100-200","Over 200")))))) -> 0-10 | Z29: 4 | AA29: =IF(Z29<0.5,"0-0.5",IF(Z29<1,"0.5-1.0",IF(Z29<2,"1.0-2.0",IF(Z29<3.5,"2.0-3.5","Over 3.5")))) -> Over 3.5 | AB29: 8 | AC29: =VLOOKUP(AB29,Key!$C$20:$D$29,2,FALSE) -> Student | AD29: 4 | AE29: =VLOOKUP(AD29,Key!$E$20:$F$24,2,FALSE) -> 750,000-1,000,000 | AF29: 2 | AG29: 1 | AH29: 3 | AI29: 5 | AJ29: 4 | AK29: Y | AL29: 10000 | AM29: =IF(AL29<1000,"0-1000",IF(AL29<2000,"1000-2000",IF(AL29<3000,"2000-3000",IF(AL29<5000,"3000-5000",IF(AL29<10000,"5000-10000","Over 10000"))))) -> Over 10000
A30: 43762 | B30: 0.625 | D30: D | E30: 2 | F30: =VLOOKUP(E30,Key!$A$17:$B$21,2,FALSE) -> Road Vehicle | G30: 4 | H30: =VLOOKUP(G30,Key!$A$2:$B$13,2,FALSE) -> Minibus | I30: M | J30: 1 | K30: =VLOOKUP(J30,Key!$A$24:$B$29,2,FALSE) -> 20-29 | L30: HIOMA | M30: HIOMA | N30: UG | O30: 2 | P30: =VLOOKUP(O30,Key!$E$2:$F$9,2,FALSE) -> Work | Q30: KAMPALA | R30: KAMPALA | S30: UG | T30: 1 | U30: =VLOOKUP(T30,Key!$E$2:$F$9,2,FALSE) -> Home | V30: =P30&"-"&U30 -> Work-Home | W30: 180000 | X30: 198 | Y30: =IF(X30<10,"0-10",IF(X30<20,"10-20",IF(X30<40,"20-40",IF(X30<70,"40-70",IF(X30<100,"70-100",IF(X30<200,"100-200","Over 200")))))) -> 100-200 | Z30: 3 | AA30: =IF(Z30<0.5,"0-0.5",IF(Z30<1,"0.5-1.0",IF(Z30<2,"1.0-2.0",IF(Z30<3.5,"2.0-3.5","Over 3.5")))) -> 2.0-3.5 | AB30: 10 | AC30: =VLOOKUP(AB30,Key!$C$20:$D$29,2,FALSE) -> Other | AD30: 4 | AE30: =VLOOKUP(AD30,Key!$E$20:$F$24,2,FALSE) -> 750,000-1,000,000 | AF30: 4 | AG30: 2 | AH30: 1 | AI30: 3 | AJ30: 5 | AK30: Y | AL30: 3000 | AM30: =IF(AL30<1000,"0-1000",IF(AL30<2000,"1000-2000",IF(AL30<3000,"2000-3000",IF(AL30<5000,"3000-5000",IF(AL30<10000,"5000-10000","Over 10000"))))) -> 3000-5000
A31: 43762 | B31: 0.67291667 | D31: P | E31: 2 | F31: =VLOOKUP(E31,Key!$A$17:$B$21,2,FALSE) -> Road Vehicle | G31: 4 | H31: =VLOOKUP(G31,Key!$A$2:$B$13,2,FALSE) -> Minibus | I31: M | J31: 1 | K31: =VLOOKUP(J31,Key!$A$24:$B$29,2,FALSE) -> 20-29 | L31: HIOMA | M31: HIOMA | N31: UG | O31: 2 | P31: =VLOOKUP(O31,Key!$E$2:$F$9,2,FALSE) -> Work | Q31: HIOMA | R31: BUKIYIRI | S31: UG | T31: 1 | U31: =VLOOKUP(T31,Key!$E$2:$F$9,2,FALSE) -> Home | V31: =P31&"-"&U31 -> Work-Home | W31: 5000 | X31: 160 | Y31: =IF(X31<10,"0-10",IF(X31<20,"10-20",IF(X31<40,"20-40",IF(X31<70,"40-70",IF(X31<100,"70-100",IF(X31<200,"100-200","Over 200")))))) -> 100-200 | Z31: 1 | AA31: =IF(Z31<0.5,"0-0.5",IF(Z31<1,"0.5-1.0",IF(Z31<2,"1.0-2.0",IF(Z31<3.5,"2.0-3.5","Over 3.5")))) -> 1.0-2.0 | AB31: 2 | AC31: =VLOOKUP(AB31,Key!$C$20:$D$29,2,FALSE) -> Manual Labour | AD31: 1 | AE31: =VLOOKUP(AD31,Key!$E$20:$F$24,2,FALSE) -> <300,000 | AF31: 5 | AG31: 4 | AH31: 1 | AI31: 2 | AJ31: 3 | AK31: Y | AL31: 1000 | AM31: =IF(AL31<1000,"0-1000",IF(AL31<2000,"1000-2000",IF(AL31<3000,"2000-3000",IF(AL31<5000,"3000-5000",IF(AL31<10000,"5000-10000","Over 10000"))))) -> 1000-2000
A32: 43762 | B32: 0.66388889 | D32: P | E32: 2 | F32: =VLOOKUP(E32,Key!$A$17:$B$21,2,FALSE) -> Road Vehicle | G32: 4 | H32: =VLOOKUP(G32,Key!$A$2:$B$13,2,FALSE) -> Minibus | I32: M | J32: 1 | K32: =VLOOKUP(J32,Key!$A$24:$B$29,2,FALSE) -> 20-29 | L32: KIBOGA | M32: KIBOGA | N32: UG | O32: 8 | P32: =VLOOKUP(O32,Key!$E$2:$F$9,2,FALSE) -> Others | Q32: HIOMA | R32: HIOMA | S32: UG | T32: 2 | U32: =VLOOKUP(T32,Key!$E$2:$F$9,2,FALSE) -> Work | V32: =P32&"-"&U32 -> Others-Work | W32: 8000 | X32: 87 | Y32: =IF(X32<10,"0-10",IF(X32<20,"10-20",IF(X32<40,"20-40",IF(X32<70,"40-70",IF(X32<100,"70-100",IF(X32<200,"100-200","Over 200")))))) -> 70-100 | Z32: 3 | AA32: =IF(Z32<0.5,"0-0.5",IF(Z32<1,"0.5-1.0",IF(Z32<2,"1.0-2.0",IF(Z32<3.5,"2.0-3.5","Over 3.5")))) -> 2.0-3.5 | AB32: 2 | AC32: =VLOOKUP(AB32,Key!$C$20:$D$29,2,FALSE) -> Manual Labour | AD32: 2 | AE32: =VLOOKUP(AD32,Key!$E$20:$F$24,2,FALSE) -> 300,000-500,000 | AF32: 2 | AG32: 3 | AH32: 4 | AI32: 1 | AJ32: 5 | AK32: Y | AM32: =IF(AL32<1000,"0-1000",IF(AL32<2000,"1000-2000",IF(AL32<3000,"2000-3000",IF(AL32<5000,"3000-5000",IF(AL32<10000,"5000-10000","Over 10000"))))) -> 0-1000
A33: 43762 | B33: 0.65277778 | D33: P | E33: 2 | F33: =VLOOKUP(E33,Key!$A$17:$B$21,2,FALSE) -> Road Vehicle | G33: 4 | H33: =VLOOKUP(G33,Key!$A$2:$B$13,2,FALSE) -> Minibus | I33: M | J33: 1 | K33: =VLOOKUP(J33,Key!$A$24:$B$29,2,FALSE) -> 20-29 | L33: HIOMA | M33: HIOMA | N33: UG | O33: 8 | P33: =VLOOKUP(O33,Key!$E$2:$F$9,2,FALSE) -> Others | Q33: KYANKWENZI | R33: KYANKWENZI | S33: UG | T33: 8 | U33: =VLOOKUP(T33,Key!$E$2:$F$9,2,FALSE) -> Others | V33: =P33&"-"&U33 -> Others-Others | W33: 5000 | Y33: =IF(X33<10,"0-10",IF(X33<20,"10-20",IF(X33<40,"20-40",IF(X33<70,"40-70",IF(X33<100,"70-100",IF(X33<200,"100-200","Over 200")))))) -> 0-10 | Z33: 2 | AA33: =IF(Z33<0.5,"0-0.5",IF(Z33<1,"0.5-1.0",IF(Z33<2,"1.0-2.0",IF(Z33<3.5,"2.0-3.5","Over 3.5")))) -> 2.0-3.5 | AB33: 5 | AC33: =VLOOKUP(AB33,Key!$C$20:$D$29,2,FALSE) -> Professional | AD33: 5 | AE33: =VLOOKUP(AD33,Key!$E$20:$F$24,2,FALSE) -> >1,000,000 | AF33: 3 | AG33: 4 | AH33: 2 | AI33: 1 | AJ33: 5 | AK33: Y | AL33: 1000 | AM33: =IF(AL33<1000,"0-1000",IF(AL33<2000,"1000-2000",IF(AL33<3000,"2000-3000",IF(AL33<5000,"3000-5000",IF(AL33<10000,"5000-10000","Over 10000"))))) -> 1000-2000
A34: 43762 | B34: 0.64236111 | D34: P | E34: 2 | F34: =VLOOKUP(E34,Key!$A$17:$B$21,2,FALSE) -> Road Vehicle | G34: 4 | H34: =VLOOKUP(G34,Key!$A$2:$B$13,2,FALSE) -> Minibus | I34: M | J34: 1 | K34: =VLOOKUP(J34,Key!$A$24:$B$29,2,FALSE) -> 20-29 | L34: HIOMA | M34: HIOMA | N34: UG | O34: 1 | P34: =VLOOKUP(O34,Key!$E$2:$F$9,2,FALSE) -> Home | Q34: WAKISO | R34: WAKISO | S34: UG | T34: 2 | U34: =VLOOKUP(T34,Key!$E$2:$F$9,2,FALSE) -> Work | V34: =P34&"-"&U34 -> Home-Work | W34: 10000 | Y34: =IF(X34<10,"0-10",IF(X34<20,"10-20",IF(X34<40,"20-40",IF(X34<70,"40-70",IF(X34<100,"70-100",IF(X34<200,"100-200","Over 200")))))) -> 0-10 | Z34: 3 | AA34: =IF(Z34<0.5,"0-0.5",IF(Z34<1,"0.5-1.0",IF(Z34<2,"1.0-2.0",IF(Z34<3.5,"2.0-3.5","Over 3.5")))) -> 2.0-3.5 | AB34: 4 | AC34: =VLOOKUP(AB34,Key!$C$20:$D$29,2,FALSE) -> Office Worker | AD34: 2 | AE34: =VLOOKUP(AD34,Key!$E$20:$F$24,2,FALSE) -> 300,000-500,000 | AF34: 4 | AG34: 5 | AH34: 3 | AI34: 2 | AJ34: 1 | AK34: Y | AL34: 3000 | AM34: =IF(AL34<1000,"0-1000",IF(AL34<2000,"1000-2000",IF(AL34<3000,"2000-3000",IF(AL34<5000,"3000-5000",IF(AL34<10000,"5000-10000","Over 10000"))))) -> 3000-5000
A35: 43762 | B35: 0.63958333 | D35: P | E35: 2 | F35: =VLOOKUP(E35,Key!$A$17:$B$21,2,FALSE) -> Road Vehicle | G35: 4 | H35: =VLOOKUP(G35,Key!$A$2:$B$13,2,FALSE) -> Minibus | I35: M | J35: 1 | K35: =VLOOKUP(J35,Key!$A$24:$B$29,2,FALSE) -> 20-29 | L35: NANSANA | M35: WAKISO | N35: UG | O35: 1 | P35: =VLOOKUP(O35,Key!$E$2:$F$9,2,FALSE) -> Home | Q35: BULIISA | R35: HIOMA | S35: UG | T35: 2 | U35: =VLOOKUP(T35,Key!$E$2:$F$9,2,FALSE) -> Work | V35: =P35&"-"&U35 -> Home-Work | W35: 19000 | Y35: =IF(X35<10,"0-10",IF(X35<20,"10-20",IF(X35<40,"20-40",IF(X35<70,"40-70",IF(X35<100,"70-100",IF(X35<200,"100-200","Over 200")))))) -> 0-10 | Z35: 4 | AA35: =IF(Z35<0.5,"0-0.5",IF(Z35<1,"0.5-1.0",IF(Z35<2,"1.0-2.0",IF(Z35<3.5,"2.0-3.5","Over 3.5")))) -> Over 3.5 | AB35: 5 | AC35: =VLOOKUP(AB35,Key!$C$20:$D$29,2,FALSE) -> Professional | AD35: 4 | AE35: =VLOOKUP(AD35,Key!$E$20:$F$24,2,FALSE) -> 750,000-1,000,000 | AF35: 4 | AG35: 1 | AH35: 2 | AI35: 3 | AJ35: 5 | AK35: Y | AL35: 5000 | AM35: =IF(AL35<1000,"0-1000",IF(AL35<2000,"1000-2000",IF(AL35<3000,"2000-3000",IF(AL35<5000,"3000-5000",IF(AL35<10000,"5000-10000","Over 10000"))))) -> 5000-10000
A36: 43762 | B36: 0.72916667 | D36: P | E36: 2 | F36: =VLOOKUP(E36,Key!$A$17:$B$21,2,FALSE) -> Road Vehicle | G36: 4 | H36: =VLOOKUP(G36,Key!$A$2:$B$13,2,FALSE) -> Minibus | I36: M | J36: 1 | K36: =VLOOKUP(J36,Key!$A$24:$B$29,2,FALSE) -> 20-29 | L36: HIOMA | M36: HIOMA | N36: UG | O36: 1 | P36: =VLOOKUP(O36,Key!$E$2:$F$9,2,FALSE) -> Home | Q36: KAKIRI | R36: WAKISO | S36: UG | T36: 1 | U36: =VLOOKUP(T36,Key!$E$2:$F$9,2,FALSE) -> Home | V36: =P36&"-"&U36 -> Home-Home | W36: 13000 | Y36: =IF(X36<10,"0-10",IF(X36<20,"10-20",IF(X36<40,"20-40",IF(X36<70,"40-70",IF(X36<100,"70-100",IF(X36<200,"100-200","Over 200")))))) -> 0-10 | Z36: 3 | AA36: =IF(Z36<0.5,"0-0.5",IF(Z36<1,"0.5-1.0",IF(Z36<2,"1.0-2.0",IF(Z36<3.5,"2.0-3.5","Over 3.5")))) -> 2.0-3.5 | AB36: 4 | AC36: =VLOOKUP(AB36,Key!$C$20:$D$29,2,FALSE) -> Office Worker | AD36: 2 | AE36: =VLOOKUP(AD36,Key!$E$20:$F$24,2,FALSE) -> 300,000-500,000 | AF36: 4 | AG36: 1 | AH36: 2 | AI36: 3 | AJ36: 3 | AK36: Y | AL36: 2000 | AM36: =IF(AL36<1000,"0-1000",IF(AL36<2000,"1000-2000",IF(AL36<3000,"2000-3000",IF(AL36<5000,"3000-5000",IF(AL36<10000,"5000-10000","Over 10000"))))) -> 2000-3000
