Workbook

Sheet 29.07 JinjaRoad-Kira Road
B1: Consultancy services for Preparation of Expressway Development Master Plan (EDMP) for Uganda
B2: MANUAL CLASSIFIED COUNT (MCC)
B3: ROAD NAME: | C3: MCC - C1 - STN47 - LUGOGO BYPASS ROAD
C5: Date | D5: 29.07.19 | F5: Location | G5: DHL (47) | J5: Surveyor | K5: Nalubega Resty
C6: Dir. From | D6: Jinja Road | F6: Dir. To | G6: Kira Road | J6: Supervisor | K6: Felix
B8: Time / Veh Type | R8: SUMMARY TRAFFIC VOLUMES
C9: 1. Car | D9: 2. Station Wagon | E9: 3. Pickups | F9: 4. Minibus, matatu | G9: 5. Medium bus | H9: 6. Large Bus | I9: 7. Light Truck | J9: 8. Medium Truck | K9: 9. Heavy truck | L9: 10. Truck Trailer | M9: 11. Motor cycles | N9: 12. Tractors | O9: Total Excl M/Cycles | P9: Total All | R9: Time | S9: 1. Car | T9: 2. Station Wagon | U9: 3. Pickups | V9: 4. Minibus, matatu | W9: 5. Medium bus | X9: 6. Large Bus | Y9: 7. Light Truck | Z9: 8. Medium Truck | AA9: 9. Heavy truck | AB9: 10. Truck Trailer | AC9: 11. Motorcycles | AD9: 12. Tractors, Graders | AE9: Total Excl M/ Cycles | AF9: Total All
B10: 07.00 - 07.15 | C10: 120 | D10: 12 | E10: 5 | F10: 9 | G10: 1 | H10: 0 | I10: 2 | J10: 0 | K10: 1 | L10: 0 | M10: 175 | N10: 0 | O10: =SUM(C10:L10,N10) -> 150 | P10: =SUM(C10:N10) -> 325 | R10: 0700-0800 | S10: =SUM(C10:C13) -> 360 | T10: =SUM(D10:D13) -> 51 | U10: =SUM(E10:E13) -> 32 | V10: =SUM(F10:F13) -> 18 | W10: =SUM(G10:G13) -> 3 | X10: =SUM(H10:H13) -> 1 | Y10: =SUM(I10:I13) -> 14 | Z10: =SUM(J10:J13) -> 0 | ... AF10: =SUM(P10:P13) -> 1263
B11: 07.15 - 07.30 | C11: 85 | D11: 4 | E11: 15 | F11: 4 | G11: 0 | H11: 1 | I11: 5 | J11: 0 | K11: 0 | L11: 0 | M11: 180 | N11: 0 | O11: =SUM(C11:L11,N11) -> 114 | P11: =SUM(C11:N11) -> 294 | R11: 0800-0900 | S11: =SUM(C14:C17) -> 159 | T11: =SUM(D14:D17) -> 22 | U11: =SUM(E14:E17) -> 19 | V11: =SUM(F14:F17) -> 15 | W11: =SUM(G14:G17) -> 1 | X11: =SUM(H14:H17) -> 2 | Y11: =SUM(I14:I17) -> 15 | Z11: =SUM(J14:J17) -> 0 | ... AF11: =SUM(P14:P17) -> 555
B12: 07.30 - 07.45 | C12: 75 | D12: 20 | E12: 8 | F12: 3 | G12: 0 | H12: 0 | I12: 7 | J12: 0 | K12: 0 | L12: 2 | M12: 225 | N12: 0 | O12: =SUM(C12:L12,N12) -> 115 | P12: =SUM(C12:N12) -> 340 | R12: 0900-1000 | S12: =SUM(C18:C21) -> 425 | T12: =SUM(D18:D21) -> 97 | U12: =SUM(E18:E21) -> 36 | V12: =SUM(F18:F21) -> 14 | W12: =SUM(G18:G21) -> 2 | X12: =SUM(H18:H21) -> 0 | Y12: =SUM(I18:I21) -> 22 | Z12: =SUM(J18:J21) -> 3 | ... AF12: =SUM(P18:P21) -> 1268
B13: 07.45 - 08.00 | C13: 80 | D13: 15 | E13: 4 | F13: 2 | G13: 2 | H13: 0 | I13: 0 | J13: 0 | K13: 0 | L13: 1 | M13: 200 | N13: 0 | O13: =SUM(C13:L13,N13) -> 104 | P13: =SUM(C13:N13) -> 304 | R13: 1000-1100 | S13: =SUM(C22:C25) -> 585 | T13: =SUM(D22:D25) -> 146 | U13: =SUM(E22:E25) -> 50 | V13: =SUM(F22:F25) -> 24 | W13: =SUM(G22:G25) -> 1 | X13: =SUM(H22:H25) -> 0 | Y13: =SUM(I22:I25) -> 17 | Z13: =SUM(J22:J25) -> 8 | ... AF13: =SUM(P22:P25) -> 1907
B14: 08.00 - 08.15 | C14: 55 | D14: 6 | E14: 4 | F14: 4 | G14: 0 | H14: 0 | I14: 7 | J14: 0 | K14: 0 | L14: 0 | M14: 94 | N14: 0 | O14: =SUM(C14:L14,N14) -> 76 | P14: =SUM(C14:N14) -> 170 | R14: 1100-1200 | S14: =SUM(C26:C29) -> 470 | T14: =SUM(D26:D29) -> 79 | U14: =SUM(E26:E29) -> 26 | V14: =SUM(F26:F29) -> 19 | W14: =SUM(G26:G29) -> 0 | X14: =SUM(H26:H29) -> 0 | Y14: =SUM(I26:I29) -> 16 | Z14: =SUM(J26:J29) -> 0 | ... AF14: =SUM(P26:P29) -> 1447
B15: 08.15 - 08.30 | C15: 42 | D15: 4 | E15: 10 | F15: 4 | G15: 0 | H15: 2 | I15: 3 | J15: 0 | K15: 0 | L15: 1 | M15: 85 | N15: 0 | O15: =SUM(C15:L15,N15) -> 66 | P15: =SUM(C15:N15) -> 151 | R15: 1200-1300 | S15: =SUM(C30:C33) -> 542 | T15: =SUM(D30:D33) -> 380 | U15: =SUM(E30:E33) -> 206 | V15: =SUM(F30:F33) -> 16 | W15: =SUM(G30:G33) -> 0 | X15: =SUM(H30:H33) -> 0 | Y15: =SUM(I30:I33) -> 13 | Z15: =SUM(J30:J33) -> 5 | ... AF15: =SUM(P30:P33) -> 1706
B16: 08.30 - 08.45 | C16: 35 | D16: 10 | E16: 3 | F16: 6 | G16: 1 | H16: 0 | I16: 1 | J16: 0 | K16: 0 | L16: 0 | M16: 75 | N16: 0 | O16: =SUM(C16:L16,N16) -> 56 | P16: =SUM(C16:N16) -> 131 | R16: 1300-1400 | S16: =SUM(C34:C37) -> 495 | T16: =SUM(D34:D37) -> 311 | U16: =SUM(E34:E37) -> 176 | V16: =SUM(F34:F37) -> 7 | W16: =SUM(G34:G37) -> 2 | X16: =SUM(H34:H37) -> 0 | Y16: =SUM(I34:I37) -> 7 | Z16: =SUM(J34:J37) -> 8 | ... AF16: =SUM(P34:P37) -> 1391
B17: 08.45 - 9.00 | C17: 27 | D17: 2 | E17: 2 | F17: 1 | G17: 0 | H17: 0 | I17: 4 | J17: 0 | K17: 2 | L17: 1 | M17: 64 | N17: 0 | O17: =SUM(C17:L17,N17) -> 39 | P17: =SUM(C17:N17) -> 103 | R17: 1400-1500 | S17: =SUM(C38:C41) -> 477 | T17: =SUM(D38:D41) -> 307 | U17: =SUM(E38:E41) -> 119 | V17: =SUM(F38:F41) -> 16 | W17: =SUM(G38:G41) -> 1 | X17: =SUM(H38:H41) -> 0 | Y17: =SUM(I38:I41) -> 11 | Z17: =SUM(J38:J41) -> 3 | ... AF17: =SUM(P38:P41) -> 1542
B18: 09.00 - 09.15 | C18: 135 | D18: 39 | E18: 0 | F18: 0 | G18: 0 | H18: 0 | I18: 0 | J18: 0 | K18: 0 | L18: 0 | M18: 0 | N18: 0 | O18: =SUM(C18:L18,N18) -> 174 | P18: =SUM(C18:N18) -> 174 | R18: 1500-1600 | S18: =SUM(C42:C45) -> 438 | T18: =SUM(D42:D45) -> 232 | U18: =SUM(E42:E45) -> 74 | V18: =SUM(F42:F45) -> 9 | W18: =SUM(G42:G45) -> 1 | X18: =SUM(H42:H45) -> 0 | Y18: =SUM(I42:I45) -> 6 | Z18: =SUM(J42:J45) -> 3 | ... AF18: =SUM(P42:P45) -> 1347
B19: 09.15 - 09.30 | C19: 55 | D19: 17 | E19: 5 | F19: 3 | G19: 2 | H19: 0 | I19: 2 | J19: 0 | K19: 1 | L19: 0 | M19: 190 | N19: 1 | O19: =SUM(C19:L19,N19) -> 86 | P19: =SUM(C19:N19) -> 276 | R19: 1600-1700 | S19: =SUM(C46:C49) -> 331 | T19: =SUM(D46:D49) -> 234 | U19: =SUM(E46:E49) -> 126 | V19: =SUM(F46:F49) -> 13 | W19: =SUM(G46:G49) -> 1 | X19: =SUM(H46:H49) -> 0 | Y19: =SUM(I46:I49) -> 8 | Z19: =SUM(J46:J49) -> 3 | ... AF19: =SUM(P46:P49) -> 1597
B20: 09.30 - 09.45 | C20: 100 | D20: 26 | E20: 23 | F20: 9 | G20: 0 | H20: 0 | I20: 8 | J20: 1 | K20: 0 | L20: 1 | M20: 235 | N20: 0 | O20: =SUM(C20:L20,N20) -> 168 | P20: =SUM(C20:N20) -> 403 | R20: 1700-1800 | S20: =SUM(C50:C53) -> 510 | T20: =SUM(D50:D53) -> 284 | U20: =SUM(E50:E53) -> 131 | V20: =SUM(F50:F53) -> 22 | W20: =SUM(G50:G53) -> 6 | X20: =SUM(H50:H53) -> 0 | Y20: =SUM(I50:I53) -> 9 | Z20: =SUM(J50:J53) -> 8 | ... AF20: =SUM(P50:P53) -> 1426
B21: 09.45 - 10.00 | C21: 135 | D21: 15 | E21: 8 | F21: 2 | G21: 0 | H21: 0 | I21: 12 | J21: 2 | K21: 1 | L21: 0 | M21: 240 | N21: 0 | O21: =SUM(C21:L21,N21) -> 175 | P21: =SUM(C21:N21) -> 415 | R21: 1800-1900 | S21: =SUM(C54:C57) -> 537 | T21: =SUM(D54:D57) -> 300 | U21: =SUM(E54:E57) -> 157 | V21: =SUM(F54:F57) -> 52 | W21: =SUM(G54:G57) -> 6 | X21: =SUM(H54:H57) -> 1 | Y21: =SUM(I54:I57) -> 14 | Z21: =SUM(J54:J57) -> 1 | ... AF21: =SUM(P54:P57) -> 1879
B22: 10.00 - 10.15 | C22: 135 | D22: 60 | E22: 20 | F22: 10 | G22: 0 | H22: 0 | I22: 5 | J22: 3 | K22: 0 | L22: 0 | M22: 275 | N22: 0 | O22: =SUM(C22:L22,N22) -> 233 | P22: =SUM(C22:N22) -> 508 | R22: AM Peak Hr | S22: =MAX(S10:S12) -> 425 | T22: =MAX(T10:T12) -> 97 | U22: =MAX(U10:U12) -> 36 | V22: =MAX(V10:V12) -> 18 | W22: =MAX(W10:W12) -> 3 | X22: =MAX(X10:X12) -> 2 | Y22: =MAX(Y10:Y12) -> 22 | Z22: =MAX(Z10:Z12) -> 3 | ... AF22: =MAX(AF10:AF12) -> 1268
B23: 10.15 - 10.30 | C23: 160 | D23: 25 | E23: 10 | F23: 5 | G23: 1 | H23: 0 | I23: 4 | J23: 1 | K23: 0 | L23: 0 | M23: 280 | N23: 0 | O23: =SUM(C23:L23,N23) -> 206 | P23: =SUM(C23:N23) -> 486 | R23: IP Peak Hr | S23: =MAX(S13:S18) -> 585 | T23: =MAX(T13:T18) -> 380 | U23: =MAX(U13:U18) -> 206 | V23: =MAX(V13:V18) -> 24 | W23: =MAX(W13:W18) -> 2 | X23: =MAX(X13:X18) -> 0 | Y23: =MAX(Y13:Y18) -> 17 | Z23: =MAX(Z13:Z18) -> 8 | ... AF23: =MAX(AF13:AF18) -> 1907
B24: 10.30 - 10.45 | C24: 160 | D24: 11 | E24: 4 | F24: 8 | G24: 0 | H24: 0 | I24: 2 | J24: 4 | K24: 1 | L24: 0 | M24: 290 | N24: 0 | O24: =SUM(C24:L24,N24) -> 190 | P24: =SUM(C24:N24) -> 480 | R24: PM Peak Hr | S24: =MAX(S19:S21) -> 537 | T24: =MAX(T19:T21) -> 300 | U24: =MAX(U19:U21) -> 157 | V24: =MAX(V19:V21) -> 52 | W24: =MAX(W19:W21) -> 6 | X24: =MAX(X19:X21) -> 1 | Y24: =MAX(Y19:Y21) -> 14 | Z24: =MAX(Z19:Z21) -> 8 | ... AF24: =MAX(AF19:AF21) -> 1879
B25: 10.45 - 11.00 | C25: 130 | D25: 50 | E25: 16 | F25: 1 | G25: 0 | H25: 0 | I25: 6 | J25: 0 | K25: 0 | L25: 0 | M25: 230 | N25: 0 | O25: =SUM(C25:L25,N25) -> 203 | P25: =SUM(C25:N25) -> 433 | R25: AM Period | S25: =SUM(S10:S12) -> 944 | T25: =SUM(T10:T12) -> 170 | U25: =SUM(U10:U12) -> 87 | V25: =SUM(V10:V12) -> 47 | W25: =SUM(W10:W12) -> 6 | X25: =SUM(X10:X12) -> 3 | Y25: =SUM(Y10:Y12) -> 51 | Z25: =SUM(Z10:Z12) -> 3 | ... AF25: =SUM(AF10:AF12) -> 3086
B26: 11.00 - 11.15 | C26: 120 | D26: 19 | E26: 5 | F26: 1 | G26: 0 | H26: 0 | I26: 6 | J26: 0 | K26: 2 | L26: 0 | M26: 215 | N26: 0 | O26: =SUM(C26:L26,N26) -> 153 | P26: =SUM(C26:N26) -> 368 | R26: IP Period | S26: =SUM(S13:S18) -> 3007 | T26: =SUM(T13:T18) -> 1455 | U26: =SUM(U13:U18) -> 651 | V26: =SUM(V13:V18) -> 91 | W26: =SUM(W13:W18) -> 5 | X26: =SUM(X13:X18) -> 0 | Y26: =SUM(Y13:Y18) -> 70 | Z26: =SUM(Z13:Z18) -> 27 | ... AF26: =SUM(AF13:AF18) -> 9340
B27: 11.15 - 11.30 | C27: 140 | D27: 19 | E27: 8 | F27: 7 | G27: 0 | H27: 0 | I27: 5 | J27: 0 | K27: 0 | L27: 0 | M27: 275 | N27: 0 | O27: =SUM(C27:L27,N27) -> 179 | P27: =SUM(C27:N27) -> 454 | R27: PM Period | S27: =SUM(S19:S21) -> 1378 | T27: =SUM(T19:T21) -> 818 | U27: =SUM(U19:U21) -> 414 | V27: =SUM(V19:V21) -> 87 | W27: =SUM(W19:W21) -> 13 | X27: =SUM(X19:X21) -> 1 | Y27: =SUM(Y19:Y21) -> 31 | Z27: =SUM(Z19:Z21) -> 12 | ... AF27: =SUM(AF19:AF21) -> 4902
B28: 11.30 - 11.45 | C28: 100 | D28: 23 | E28: 5 | F28: 4 | G28: 0 | H28: 0 | I28: 2 | J28: 0 | K28: 5 | L28: 0 | M28: 175 | N28: 0 | O28: =SUM(C28:L28,N28) -> 139 | P28: =SUM(C28:N28) -> 314 | R28: 12 Hours | S28: =SUM(S10:S21) -> 5329 | T28: =SUM(T10:T21) -> 2443 | U28: =SUM(U10:U21) -> 1152 | V28: =SUM(V10:V21) -> 225 | W28: =SUM(W10:W21) -> 24 | X28: =SUM(X10:X21) -> 4 | Y28: =SUM(Y10:Y21) -> 152 | Z28: =SUM(Z10:Z21) -> 42 | ... AF28: =SUM(AF10:AF21) -> 17328
B29: 11.45 - 12.00 | C29: 110 | D29: 18 | E29: 8 | F29: 7 | G29: 0 | H29: 0 | I29: 3 | J29: 0 | K29: 0 | L29: 0 | M29: 165 | N29: 0 | O29: =SUM(C29:L29,N29) -> 146 | P29: =SUM(C29:N29) -> 311
B30: 12.00 - 12.15 | C30: 140 | D30: 100 | E30: 51 | F30: 6 | G30: 0 | H30: 0 | I30: 5 | J30: 3 | K30: 0 | L30: 0 | M30: 170 | N30: 0 | O30: =SUM(C30:L30,N30) -> 305 | P30: =SUM(C30:N30) -> 475
B31: 12.15 - 12.30 | C31: 130 | D31: 85 | E31: 46 | F31: 2 | G31: 0 | H31: 0 | I31: 3 | J31: 1 | K31: 1 | L31: 0 | M31: 75 | N31: 0 | O31: =SUM(C31:L31,N31) -> 268 | P31: =SUM(C31:N31) -> 343
B32: 12.30 - 12.45 | C32: 135 | D32: 95 | E32: 60 | F32: 3 | G32: 0 | H32: 0 | I32: 2 | J32: 0 | K32: 1 | L32: 0 | M32: 172 | N32: 0 | O32: =SUM(C32:L32,N32) -> 296 | P32: =SUM(C32:N32) -> 468
B33: 12.45 - 13.00 | C33: 137 | D33: 100 | E33: 49 | F33: 5 | G33: 0 | H33: 0 | I33: 3 | J33: 1 | K33: 0 | L33: 0 | M33: 125 | N33: 0 | O33: =SUM(C33:L33,N33) -> 295 | P33: =SUM(C33:N33) -> 420
B34: 13.00 - 13.15 | C34: 140 | D34: 79 | E34: 51 | F34: 3 | G34: 1 | H34: 0 | I34: 1 | J34: 3 | K34: 0 | L34: 0 | M34: 85 | N34: 0 | O34: =SUM(C34:L34,N34) -> 278 | P34: =SUM(C34:N34) -> 363
B35: 13.15 - 13.30 | C35: 105 | D35: 83 | E35: 65 | F35: 2 | G35: 0 | H35: 0 | I35: 1 | J35: 0 | K35: 0 | L35: 0 | M35: 98 | N35: 0 | O35: =SUM(C35:L35,N35) -> 256 | P35: =SUM(C35:N35) -> 354
B36: 13.30 - 13.45 | C36: 135 | D36: 95 | E36: 35 | F36: 2 | G36: 0 | H36: 0 | I36: 2 | J36: 2 | K36: 1 | L36: 1 | M36: 100 | N36: 0 | O36: =SUM(C36:L36,N36) -> 273 | P36: =SUM(C36:N36) -> 373
B37: 13.45 - 14.00 | C37: 115 | D37: 54 | E37: 25 | F37: 0 | G37: 1 | H37: 0 | I37: 3 | J37: 3 | K37: 0 | L37: 0 | M37: 100 | N37: 0 | O37: =SUM(C37:L37,N37) -> 201 | P37: =SUM(C37:N37) -> 301
B38: 14.00 - 14.15 | C38: 115 | D38: 80 | E38: 45 | F38: 5 | G38: 1 | H38: 0 | I38: 4 | J38: 1 | K38: 1 | L38: 0 | M38: 137 | N38: 0 | O38: =SUM(C38:L38,N38) -> 252 | P38: =SUM(C38:N38) -> 389
B39: 14.15 - 14.30 | C39: 140 | D39: 92 | E39: 42 | F39: 3 | G39: 0 | H39: 0 | I39: 3 | J39: 0 | K39: 0 | L39: 0 | M39: 145 | N39: 0 | O39: =SUM(C39:L39,N39) -> 280 | P39: =SUM(C39:N39) -> 425
B40: 14.30 - 14.45 | C40: 135 | D40: 80 | E40: 13 | F40: 6 | G40: 0 | H40: 0 | I40: 3 | J40: 0 | K40: 1 | L40: 0 | M40: 160 | N40: 0 | O40: =SUM(C40:L40,N40) -> 238 | P40: =SUM(C40:N40) -> 398
... B57: 18.45 - 19.00 | C57: 153 | D57: 88 | E57: 69 | F57: 22 | G57: 1 | H57: 1 | I57: 3 | J57: 0 | K57: 1 | L57: 0 | M57: 110 | N57: 0 | O57: =SUM(C57:L57,N57) -> 338 | P57: =SUM(C57:N57) -> 448
B58: Totals | C58: =SUM(C10:C57) -> 5329 | D58: =SUM(D10:D57) -> 2443 | E58: =SUM(E10:E57) -> 1152 | F58: =SUM(F10:F57) -> 225 | G58: =SUM(G10:G57) -> 24 | H58: =SUM(H10:H57) -> 4 | I58: =SUM(I10:I57) -> 152 | J58: =SUM(J10:J57) -> 42 | ... P58: =SUM(P10:P57) -> 17328
...

Sheet 29.07 Kira Road-Jinaj Road
B1: Consultancy services for Preparation of Expressway Development Master Plan (EDMP) for Uganda
B2: MANUAL CLASSIFIED COUNT (MCC)
B3: ROAD NAME: | C3: ='29.07 JinjaRoad-Kira Road'!C3:G3 -> MCC - C1 - STN47 - LUGOGO BYPASS ROAD
C5: Date | D5: ='29.07 JinjaRoad-Kira Road'!D5 -> 29.07.19 | F5: Location | G5: ='29.07 JinjaRoad-Kira Road'!G5:H5 -> DHL (47) | J5: Surveyor | K5: Ssemuko Samuel junior
C6: Dir. From | D6: Kira Road | F6: Dir. To | G6: Jinja Road | J6: Supervisor | K6: ='29.07 JinjaRoad-Kira Road'!K6:L6 -> Felix
B8: Time / Veh Type | R8: SUMMARY TRAFFIC VOLUMES
C9: 1. Car | D9: 2. Station Wagon | E9: 3. Pickups | F9: 4. Minibus, matatu | G9: 5. Medium bus | H9: 6. Large Bus | I9: 7. Light Truck | J9: 8. Medium Truck | K9: 9. Heavy truck | L9: 10. Truck Trailer | M9: 11. Motor cycles | N9: 12. Tractors | O9: Total Excl M/Cycles | P9: Total All | R9: Time | S9: 1. Car | T9: 2. Station Wagon | U9: 3. Pickups | V9: 4. Minibus, matatu | W9: 5. Medium bus | X9: 6. Large Bus | Y9: 7. Light Truck | Z9: 8. Medium Truck | AA9: 9. Heavy truck | AB9: 10. Truck Trailer | AC9: 11. Motorcycles | AD9: 12. Tractors, Graders | AE9: Total Excl M/ Cycles | AF9: Total All
B10: 07.00 - 07.15 | C10: 0 | D10: 0 | E10: 0 | F10: 0 | G10: 0 | H10: 0 | I10: 0 | J10: 0 | K10: 0 | L10: 0 | M10: 0 | N10: 0 | O10: =SUM(C10:L10,N10) -> 0 | P10: =SUM(C10:N10) -> 0 | R10: 0700-0800 | S10: =SUM(C10:C13) -> 0 | T10: =SUM(D10:D13) -> 0 | U10: =SUM(E10:E13) -> 0 | V10: =SUM(F10:F13) -> 0 | W10: =SUM(G10:G13) -> 0 | X10: =SUM(H10:H13) -> 0 | Y10: =SUM(I10:I13) -> 0 | Z10: =SUM(J10:J13) -> 0 | ... AF10: =SUM(P10:P13) -> 0
B11: 07.15 - 07.30 | C11: 0 | D11: 0 | E11: 0 | F11: 0 | G11: 0 | H11: 0 | I11: 0 | J11: 0 | K11: 0 | L11: 0 | M11: 0 | N11: 0 | O11: =SUM(C11:L11,N11) -> 0 | P11: =SUM(C11:N11) -> 0 | R11: 0800-0900 | S11: =SUM(C14:C17) -> 0 | T11: =SUM(D14:D17) -> 0 | U11: =SUM(E14:E17) -> 0 | V11: =SUM(F14:F17) -> 0 | W11: =SUM(G14:G17) -> 0 | X11: =SUM(H14:H17) -> 0 | Y11: =SUM(I14:I17) -> 0 | Z11: =SUM(J14:J17) -> 0 | ... AF11: =SUM(P14:P17) -> 0
B12: 07.30 - 07.45 | C12: 0 | D12: 0 | E12: 0 | F12: 0 | G12: 0 | H12: 0 | I12: 0 | J12: 0 | K12: 0 | L12: 0 | M12: 0 | N12: 0 | O12: =SUM(C12:L12,N12) -> 0 | P12: =SUM(C12:N12) -> 0 | R12: 0900-1000 | S12: =SUM(C18:C21) -> 296 | T12: =SUM(D18:D21) -> 76 | U12: =SUM(E18:E21) -> 51 | V12: =SUM(F18:F21) -> 1 | W12: =SUM(G18:G21) -> 0 | X12: =SUM(H18:H21) -> 1 | Y12: =SUM(I18:I21) -> 10 | Z12: =SUM(J18:J21) -> 4 | ... AF12: =SUM(P18:P21) -> 748
B13: 07.45 - 08.00 | C13: 0 | D13: 0 | E13: 0 | F13: 0 | G13: 0 | H13: 0 | I13: 0 | J13: 0 | K13: 0 | L13: 0 | M13: 0 | N13: 0 | O13: =SUM(C13:L13,N13) -> 0 | P13: =SUM(C13:N13) -> 0 | R13: 1000-1100 | S13: =SUM(C22:C25) -> 362 | T13: =SUM(D22:D25) -> 57 | U13: =SUM(E22:E25) -> 40 | V13: =SUM(F22:F25) -> 5 | W13: =SUM(G22:G25) -> 1 | X13: =SUM(H22:H25) -> 0 | Y13: =SUM(I22:I25) -> 11 | Z13: =SUM(J22:J25) -> 7 | ... AF13: =SUM(P22:P25) -> 971
B14: 08.00 - 08.15 | C14: 0 | D14: 0 | E14: 0 | F14: 0 | G14: 0 | H14: 0 | I14: 0 | J14: 0 | K14: 0 | L14: 0 | M14: 0 | N14: 0 | O14: =SUM(C14:L14,N14) -> 0 | P14: =SUM(C14:N14) -> 0 | R14: 1100-1200 | S14: =SUM(C26:C29) -> 249 | T14: =SUM(D26:D29) -> 46 | U14: =SUM(E26:E29) -> 18 | V14: =SUM(F26:F29) -> 3 | W14: =SUM(G26:G29) -> 1 | X14: =SUM(H26:H29) -> 7 | Y14: =SUM(I26:I29) -> 18 | Z14: =SUM(J26:J29) -> 2 | ... AF14: =SUM(P26:P29) -> 782
B15: 08.15 - 08.30 | C15: 0 | D15: 0 | E15: 0 | F15: 0 | G15: 0 | H15: 0 | I15: 0 | J15: 0 | K15: 0 | L15: 0 | M15: 0 | N15: 0 | O15: =SUM(C15:L15,N15) -> 0 | P15: =SUM(C15:N15) -> 0 | R15: 1200-1300 | S15: =SUM(C30:C33) -> 243 | T15: =SUM(D30:D33) -> 103 | U15: =SUM(E30:E33) -> 36 | V15: =SUM(F30:F33) -> 12 | W15: =SUM(G30:G33) -> 1 | X15: =SUM(H30:H33) -> 0 | Y15: =SUM(I30:I33) -> 20 | Z15: =SUM(J30:J33) -> 7 | ... AF15: =SUM(P30:P33) -> 1238
B16: 08.30 - 08.45 | C16: 0 | D16: 0 | E16: 0 | F16: 0 | G16: 0 | H16: 0 | I16: 0 | J16: 0 | K16: 0 | L16: 0 | M16: 0 | N16: 0 | O16: =SUM(C16:L16,N16) -> 0 | P16: =SUM(C16:N16) -> 0 | R16: 1300-1400 | S16: =SUM(C34:C37) -> 212 | T16: =SUM(D34:D37) -> 105 | U16: =SUM(E34:E37) -> 40 | V16: =SUM(F34:F37) -> 6 | W16: =SUM(G34:G37) -> 1 | X16: =SUM(H34:H37) -> 1 | Y16: =SUM(I34:I37) -> 20 | Z16: =SUM(J34:J37) -> 7 | ... AF16: =SUM(P34:P37) -> 1168
B17: 08.45 - 9.00 | C17: 0 | D17: 0 | E17: 0 | F17: 0 | G17: 0 | H17: 0 | I17: 0 | J17: 0 | K17: 0 | L17: 0 | M17: 0 | N17: 0 | O17: =SUM(C17:L17,N17) -> 0 | P17: =SUM(C17:N17) -> 0 | R17: 1400-1500 | S17: =SUM(C38:C41) -> 206 | T17: =SUM(D38:D41) -> 117 | U17: =SUM(E38:E41) -> 20 | V17: =SUM(F38:F41) -> 19 | W17: =SUM(G38:G41) -> 2 | X17: =SUM(H38:H41) -> 0 | Y17: =SUM(I38:I41) -> 25 | Z17: =SUM(J38:J41) -> 10 | ... AF17: =SUM(P38:P41) -> 1129
B18: 09.00 - 09.15 | C18: 0 | D18: 0 | E18: 0 | F18: 0 | G18: 0 | H18: 0 | I18: 0 | J18: 0 | K18: 0 | L18: 0 | M18: 2 | N18: 0 | O18: =SUM(C18:L18,N18) -> 0 | P18: =SUM(C18:N18) -> 2 | R18: 1500-1600 | S18: =SUM(C42:C45) -> 261 | T18: =SUM(D42:D45) -> 144 | U18: =SUM(E42:E45) -> 31 | V18: =SUM(F42:F45) -> 7 | W18: =SUM(G42:G45) -> 0 | X18: =SUM(H42:H45) -> 0 | Y18: =SUM(I42:I45) -> 33 | Z18: =SUM(J42:J45) -> 10 | ... AF18: =SUM(P42:P45) -> 1240
B19: 09.15 - 09.30 | C19: 135 | D19: 52 | E19: 23 | F19: 0 | G19: 0 | H19: 1 | I19: 4 | J19: 3 | K19: 1 | L19: 0 | M19: 112 | N19: 0 | O19: =SUM(C19:L19,N19) -> 219 | P19: =SUM(C19:N19) -> 331 | R19: 1600-1700 | S19: =SUM(C46:C49) -> 345 | T19: =SUM(D46:D49) -> 157 | U19: =SUM(E46:E49) -> 36 | V19: =SUM(F46:F49) -> 12 | W19: =SUM(G46:G49) -> 0 | X19: =SUM(H46:H49) -> 1 | Y19: =SUM(I46:I49) -> 23 | Z19: =SUM(J46:J49) -> 20 | ... AF19: =SUM(P46:P49) -> 1359
B20: 09.30 - 09.45 | C20: 60 | D20: 11 | E20: 12 | F20: 0 | G20: 0 | H20: 0 | I20: 2 | J20: 0 | K20: 0 | L20: 1 | M20: 82 | N20: 0 | O20: =SUM(C20:L20,N20) -> 86 | P20: =SUM(C20:N20) -> 168 | R20: 1700-1800 | S20: =SUM(C50:C53) -> 315 | T20: =SUM(D50:D53) -> 146 | U20: =SUM(E50:E53) -> 38 | V20: =SUM(F50:F53) -> 10 | W20: =SUM(G50:G53) -> 0 | X20: =SUM(H50:H53) -> 0 | Y20: =SUM(I50:I53) -> 20 | Z20: =SUM(J50:J53) -> 13 | ... AF20: =SUM(P50:P53) -> 1329
B21: 09.45 - 10.00 | C21: 101 | D21: 13 | E21: 16 | F21: 1 | G21: 0 | H21: 0 | I21: 4 | J21: 1 | K21: 1 | L21: 0 | M21: 110 | N21: 0 | O21: =SUM(C21:L21,N21) -> 137 | P21: =SUM(C21:N21) -> 247 | R21: 1800-1900 | S21: =SUM(C54:C57) -> 274 | T21: =SUM(D54:D57) -> 123 | U21: =SUM(E54:E57) -> 29 | V21: =SUM(F54:F57) -> 15 | W21: =SUM(G54:G57) -> 2 | X21: =SUM(H54:H57) -> 1 | Y21: =SUM(I54:I57) -> 20 | Z21: =SUM(J54:J57) -> 8 | ... AF21: =SUM(P54:P57) -> 1291
B22: 10.00 - 10.15 | C22: 125 | D22: 15 | E22: 22 | F22: 2 | G22: 0 | H22: 0 | I22: 2 | J22: 0 | K22: 0 | L22: 0 | M22: 110 | N22: 0 | O22: =SUM(C22:L22,N22) -> 166 | P22: =SUM(C22:N22) -> 276 | R22: AM Peak Hr | S22: =MAX(S10:S12) -> 296 | T22: =MAX(T10:T12) -> 76 | U22: =MAX(U10:U12) -> 51 | V22: =MAX(V10:V12) -> 1 | W22: =MAX(W10:W12) -> 0 | X22: =MAX(X10:X12) -> 1 | Y22: =MAX(Y10:Y12) -> 10 | Z22: =MAX(Z10:Z12) -> 4 | ... AF22: =MAX(AF10:AF12) -> 748
B23: 10.15 - 10.30 | C23: 81 | D23: 16 | E23: 6 | F23: 0 | G23: 0 | H23: 0 | I23: 3 | J23: 3 | K23: 2 | L23: 0 | M23: 130 | N23: 0 | O23: =SUM(C23:L23,N23) -> 111 | P23: =SUM(C23:N23) -> 241 | R23: IP Peak Hr | S23: =MAX(S13:S18) -> 362 | T23: =MAX(T13:T18) -> 144 | U23: =MAX(U13:U18) -> 40 | V23: =MAX(V13:V18) -> 19 | W23: =MAX(W13:W18) -> 2 | X23: =MAX(X13:X18) -> 7 | Y23: =MAX(Y13:Y18) -> 33 | Z23: =MAX(Z13:Z18) -> 10 | ... AF23: =MAX(AF13:AF18) -> 1240
B24: 10.30 - 10.45 | C24: 85 | D24: 15 | E24: 6 | F24: 2 | G24: 0 | H24: 0 | I24: 3 | J24: 3 | K24: 0 | L24: 0 | M24: 112 | N24: 0 | O24: =SUM(C24:L24,N24) -> 114 | P24: =SUM(C24:N24) -> 226 | R24: PM Peak Hr | S24: =MAX(S19:S21) -> 345 | T24: =MAX(T19:T21) -> 157 | U24: =MAX(U19:U21) -> 38 | V24: =MAX(V19:V21) -> 15 | W24: =MAX(W19:W21) -> 2 | X24: =MAX(X19:X21) -> 1 | Y24: =MAX(Y19:Y21) -> 23 | Z24: =MAX(Z19:Z21) -> 20 | ... AF24: =MAX(AF19:AF21) -> 1359
B25: 10.45 - 11.00 | C25: 71 | D25: 11 | E25: 6 | F25: 1 | G25: 1 | H25: 0 | I25: 3 | J25: 1 | K25: 1 | L25: 0 | M25: 133 | N25: 0 | O25: =SUM(C25:L25,N25) -> 95 | P25: =SUM(C25:N25) -> 228 | R25: AM Period | S25: =SUM(S10:S12) -> 296 | T25: =SUM(T10:T12) -> 76 | U25: =SUM(U10:U12) -> 51 | V25: =SUM(V10:V12) -> 1 | W25: =SUM(W10:W12) -> 0 | X25: =SUM(X10:X12) -> 1 | Y25: =SUM(Y10:Y12) -> 10 | Z25: =SUM(Z10:Z12) -> 4 | ... AF25: =SUM(AF10:AF12) -> 748
B26: 11.00 - 11.15 | C26: 81 | D26: 28 | E26: 4 | F26: 1 | G26: 1 | H26: 0 | I26: 7 | J26: 0 | K26: 0 | L26: 0 | M26: 89 | N26: 0 | O26: =SUM(C26:L26,N26) -> 122 | P26: =SUM(C26:N26) -> 211 | R26: IP Period | S26: =SUM(S13:S18) -> 1533 | T26: =SUM(T13:T18) -> 572 | U26: =SUM(U13:U18) -> 185 | V26: =SUM(V13:V18) -> 52 | W26: =SUM(W13:W18) -> 6 | X26: =SUM(X13:X18) -> 8 | Y26: =SUM(Y13:Y18) -> 127 | Z26: =SUM(Z13:Z18) -> 43 | ... AF26: =SUM(AF13:AF18) -> 6528
B27: 11.15 - 11.30 | C27: 97 | D27: 13 | E27: 9 | F27: 1 | G27: 0 | H27: 0 | I27: 2 | J27: 0 | K27: 0 | L27: 0 | M27: 97 | N27: 0 | O27: =SUM(C27:L27,N27) -> 122 | P27: =SUM(C27:N27) -> 219 | R27: PM Period | S27: =SUM(S19:S21) -> 934 | T27: =SUM(T19:T21) -> 426 | U27: =SUM(U19:U21) -> 103 | V27: =SUM(V19:V21) -> 37 | W27: =SUM(W19:W21) -> 2 | X27: =SUM(X19:X21) -> 2 | Y27: =SUM(Y19:Y21) -> 63 | Z27: =SUM(Z19:Z21) -> 41 | ... AF27: =SUM(AF19:AF21) -> 3979
B28: 11.30 - 11.45 | C28: 71 | D28: 5 | E28: 5 | F28: 1 | G28: 0 | H28: 1 | I28: 6 | J28: 2 | K28: 0 | L28: 1 | M28: 75 | N28: 0 | O28: =SUM(C28:L28,N28) -> 92 | P28: =SUM(C28:N28) -> 167 | R28: 12 Hours | S28: =SUM(S10:S21) -> 2763 | T28: =SUM(T10:T21) -> 1074 | U28: =SUM(U10:U21) -> 339 | V28: =SUM(V10:V21) -> 90 | W28: =SUM(W10:W21) -> 8 | X28: =SUM(X10:X21) -> 11 | Y28: =SUM(Y10:Y21) -> 200 | Z28: =SUM(Z10:Z21) -> 88 | ... AF28: =SUM(AF10:AF21) -> 11255
B29: 11.45 - 12.00 | C29: 0 | D29: 0 | E29: 0 | F29: 0 | G29: 0 | H29: 6 | I29: 3 | J29: 0 | K29: 0 | L29: 1 | M29: 175 | N29: 0 | O29: =SUM(C29:L29,N29) -> 10 | P29: =SUM(C29:N29) -> 185
B30: 12.00 - 12.15 | C30: 76 | D30: 32 | E30: 9 | F30: 3 | G30: 1 | H30: 0 | I30: 4 | J30: 1 | K30: 0 | L30: 0 | M30: 245 | N30: 0 | O30: =SUM(C30:L30,N30) -> 126 | P30: =SUM(C30:N30) -> 371
B31: 12.15 - 12.30 | C31: 56 | D31: 25 | E31: 11 | F31: 2 | G31: 0 | H31: 0 | I31: 5 | J31: 4 | K31: 0 | L31: 1 | M31: 211 | N31: 0 | O31: =SUM(C31:L31,N31) -> 104 | P31: =SUM(C31:N31) -> 315
B32: 12.30 - 12.45 | C32: 49 | D32: 24 | E32: 6 | F32: 1 | G32: 0 | H32: 0 | I32: 5 | J32: 2 | K32: 0 | L32: 0 | M32: 167 | N32: 0 | O32: =SUM(C32:L32,N32) -> 87 | P32: =SUM(C32:N32) -> 254
B33: 12.45 - 13.00 | C33: 62 | D33: 22 | E33: 10 | F33: 6 | G33: 0 | H33: 0 | I33: 6 | J33: 0 | K33: 1 | L33: 0 | M33: 191 | N33: 0 | O33: =SUM(C33:L33,N33) -> 107 | P33: =SUM(C33:N33) -> 298
B34: 13.00 - 13.15 | C34: 52 | D34: 28 | E34: 9 | F34: 3 | G34: 0 | H34: 0 | I34: 3 | J34: 1 | K34: 1 | L34: 1 | M34: 192 | N34: 0 | O34: =SUM(C34:L34,N34) -> 98 | P34: =SUM(C34:N34) -> 290
B35: 13.15 - 13.30 | C35: 54 | D35: 20 | E35: 12 | F35: 1 | G35: 1 | H35: 0 | I35: 6 | J35: 2 | K35: 0 | L35: 0 | M35: 201 | N35: 0 | O35: =SUM(C35:L35,N35) -> 96 | P35: =SUM(C35:N35) -> 297
B36: 13.30 - 13.45 | C36: 40 | D36: 27 | E36: 6 | F36: 1 | G36: 0 | H36: 0 | I36: 5 | J36: 0 | K36: 0 | L36: 0 | M36: 193 | N36: 0 | O36: =SUM(C36:L36,N36) -> 79 | P36: =SUM(C36:N36) -> 272
B37: 13.45 - 14.00 | C37: 66 | D37: 30 | E37: 13 | F37: 1 | G37: 0 | H37: 1 | I37: 6 | J37: 4 | K37: 0 | L37: 0 | M37: 188 | N37: 0 | O37: =SUM(C37:L37,N37) -> 121 | P37: =SUM(C37:N37) -> 309
B38: 14.00 - 14.15 | C38: 53 | D38: 24 | E38: 4 | F38: 4 | G38: 0 | H38: 0 | I38: 6 | J38: 0 | K38: 3 | L38: 0 | M38: 173 | N38: 0 | O38: =SUM(C38:L38,N38) -> 94 | P38: =SUM(C38:N38) -> 267
B39: 14.15 - 14.30 | C39: 56 | D39: 28 | E39: 7 | F39: 4 | G39: 0 | H39: 0 | I39: 4 | J39: 6 | K39: 0 | L39: 0 | M39: 184 | N39: 0 | O39: =SUM(C39:L39,N39) -> 105 | P39: =SUM(C39:N39) -> 289
B40: 14.30 - 14.45 | C40: 41 | D40: 36 | E40: 4 | F40: 2 | G40: 1 | H40: 0 | I40: 9 | J40: 3 | K40: 0 | L40: 1 | M40: 189 | N40: 0 | O40: =SUM(C40:L40,N40) -> 97 | P40: =SUM(C40:N40) -> 286
... B57: 18.45 - 19.00 | C57: 53 | D57: 28 | E57: 7 | F57: 3 | G57: 1 | H57: 0 | I57: 2 | J57: 3 | K57: 0 | L57: 0 | M57: 207 | N57: 0 | O57: =SUM(C57:L57,N57) -> 97 | P57: =SUM(C57:N57) -> 304
B58: Totals | C58: =SUM(C10:C57) -> 2763 | D58: =SUM(D10:D57) -> 1074 | E58: =SUM(E10:E57) -> 339 | F58: =SUM(F10:F57) -> 90 | G58: =SUM(G10:G57) -> 8 | H58: =SUM(H10:H57) -> 11 | I58: =SUM(I10:I57) -> 200 | J58: =SUM(J10:J57) -> 88 | ... P58: =SUM(P10:P57) -> 11255
...

Sheet 30.07 Jinja Road-Kira Road
B1: Consultancy services for Preparation of Expressway Development Master Plan (EDMP) for Uganda
B2: MANUAL CLASSIFIED COUNT (MCC)
B3: ROAD NAME: | C3: ='29.07 JinjaRoad-Kira Road'!C3:G3 -> MCC - C1 - STN47 - LUGOGO BYPASS ROAD
C5: Date | D5: 30.07.19 | F5: Location | G5: ='29.07 JinjaRoad-Kira Road'!G5:H5 -> DHL (47) | J5: Surveyor | K5: ='29.07 JinjaRoad-Kira Road'!K5:L5 -> Nalubega Resty
C6: Dir. From | D6: ='29.07 JinjaRoad-Kira Road'!D6:E6 -> Jinja Road | F6: Dir. To | G6: ='29.07 JinjaRoad-Kira Road'!G6:H6 -> Kira Road | J6: Supervisor | K6: ='29.07 JinjaRoad-Kira Road'!K6:L6 -> Felix
B8: Time / Veh Type | R8: SUMMARY TRAFFIC VOLUMES
C9: 1. Car | D9: 2. Station Wagon | E9: 3. Pickups | F9: 4. Minibus, matatu | G9: 5. Medium bus | H9: 6. Large Bus | I9: 7. Light Truck | J9: 8. Medium Truck | K9: 9. Heavy truck | L9: 10. Truck Trailer | M9: 11. Motor cycles | N9: 12. Tractors | O9: Total Excl M/Cycles | P9: Total All | R9: Time | S9: 1. Car | T9: 2. Station Wagon | U9: 3. Pickups | V9: 4. Minibus, matatu | W9: 5. Medium bus | X9: 6. Large Bus | Y9: 7. Light Truck | Z9: 8. Medium Truck | AA9: 9. Heavy truck | AB9: 10. Truck Trailer | AC9: 11. Motorcycles | AD9: 12. Tractors, Graders | AE9: Total Excl M/ Cycles | AF9: Total All
B10: 07.00 - 07.15 | C10: 54 | D10: 17 | E10: 3 | F10: 1 | G10: 0 | H10: 0 | I10: 1 | J10: 0 | K10: 0 | L10: 0 | M10: 85 | N10: 0 | O10: =SUM(C10:L10,N10) -> 76 | P10: =SUM(C10:N10) -> 161 | R10: 0700-0800 | S10: =SUM(C10:C13) -> 268 | T10: =SUM(D10:D13) -> 102 | U10: =SUM(E10:E13) -> 48 | V10: =SUM(F10:F13) -> 4 | W10: =SUM(G10:G13) -> 1 | X10: =SUM(H10:H13) -> 0 | Y10: =SUM(I10:I13) -> 6 | Z10: =SUM(J10:J13) -> 1 | ... AF10: =SUM(P10:P13) -> 1079
B11: 07.15 - 07.30 | C11: 62 | D11: 15 | E11: 25 | F11: 2 | G11: 0 | H11: 0 | I11: 0 | J11: 1 | K11: 0 | L11: 0 | M11: 147 | N11: 0 | O11: =SUM(C11:L11,N11) -> 105 | P11: =SUM(C11:N11) -> 252 | R11: 0800-0900 | S11: =SUM(C14:C17) -> 256 | T11: =SUM(D14:D17) -> 126 | U11: =SUM(E14:E17) -> 27 | V11: =SUM(F14:F17) -> 11 | W11: =SUM(G14:G17) -> 0 | X11: =SUM(H14:H17) -> 0 | Y11: =SUM(I14:I17) -> 19 | Z11: =SUM(J14:J17) -> 5 | ... AF11: =SUM(P14:P17) -> 1319
B12: 07.30 - 07.45 | C12: 65 | D12: 30 | E12: 12 | F12: 0 | G12: 1 | H12: 0 | I12: 1 | J12: 0 | K12: 0 | L12: 0 | M12: 187 | N12: 0 | O12: =SUM(C12:L12,N12) -> 109 | P12: =SUM(C12:N12) -> 296 | R12: 0900-1000 | S12: =SUM(C18:C21) -> 206 | T12: =SUM(D18:D21) -> 131 | U12: =SUM(E18:E21) -> 37 | V12: =SUM(F18:F21) -> 7 | W12: =SUM(G18:G21) -> 2 | X12: =SUM(H18:H21) -> 0 | Y12: =SUM(I18:I21) -> 21 | Z12: =SUM(J18:J21) -> 5 | ... AF12: =SUM(P18:P21) -> 977
B13: 07.45 - 08.00 | C13: 87 | D13: 40 | E13: 8 | F13: 1 | G13: 0 | H13: 0 | I13: 4 | J13: 0 | K13: 0 | L13: 0 | M13: 230 | N13: 0 | O13: =SUM(C13:L13,N13) -> 140 | P13: =SUM(C13:N13) -> 370 | R13: 1000-1100 | S13: =SUM(C22:C25) -> 271 | T13: =SUM(D22:D25) -> 141 | U13: =SUM(E22:E25) -> 28 | V13: =SUM(F22:F25) -> 13 | W13: =SUM(G22:G25) -> 0 | X13: =SUM(H22:H25) -> 0 | Y13: =SUM(I22:I25) -> 24 | Z13: =SUM(J22:J25) -> 3 | ... AF13: =SUM(P22:P25) -> 988
B14: 08.00 - 08.15 | C14: 56 | D14: 42 | E14: 7 | F14: 3 | G14: 0 | H14: 0 | I14: 4 | J14: 2 | K14: 0 | L14: 0 | M14: 221 | N14: 0 | O14: =SUM(C14:L14,N14) -> 114 | P14: =SUM(C14:N14) -> 335 | R14: 1100-1200 | S14: =SUM(C26:C29) -> 284 | T14: =SUM(D26:D29) -> 161 | U14: =SUM(E26:E29) -> 47 | V14: =SUM(F26:F29) -> 8 | W14: =SUM(G26:G29) -> 0 | X14: =SUM(H26:H29) -> 0 | Y14: =SUM(I26:I29) -> 13 | Z14: =SUM(J26:J29) -> 4 | ... AF14: =SUM(P26:P29) -> 1043
B15: 08.15 - 08.30 | C15: 81 | D15: 25 | E15: 6 | F15: 4 | G15: 0 | H15: 0 | I15: 7 | J15: 1 | K15: 0 | L15: 0 | M15: 217 | N15: 0 | O15: =SUM(C15:L15,N15) -> 124 | P15: =SUM(C15:N15) -> 341 | R15: 1200-1300 | S15: =SUM(C30:C33) -> 374 | T15: =SUM(D30:D33) -> 218 | U15: =SUM(E30:E33) -> 71 | V15: =SUM(F30:F33) -> 5 | W15: =SUM(G30:G33) -> 1 | X15: =SUM(H30:H33) -> 0 | Y15: =SUM(I30:I33) -> 15 | Z15: =SUM(J30:J33) -> 4 | ... AF15: =SUM(P30:P33) -> 1207
B16: 08.30 - 08.45 | C16: 64 | D16: 35 | E16: 7 | F16: 1 | G16: 0 | H16: 0 | I16: 6 | J16: 1 | K16: 0 | L16: 0 | M16: 237 | N16: 0 | O16: =SUM(C16:L16,N16) -> 114 | P16: =SUM(C16:N16) -> 351 | R16: 1300-1400 | S16: =SUM(C34:C37) -> 392 | T16: =SUM(D34:D37) -> 266 | U16: =SUM(E34:E37) -> 78 | V16: =SUM(F34:F37) -> 19 | W16: =SUM(G34:G37) -> 0 | X16: =SUM(H34:H37) -> 0 | Y16: =SUM(I34:I37) -> 12 | Z16: =SUM(J34:J37) -> 2 | ... AF16: =SUM(P34:P37) -> 1165
B17: 08.45 - 9.00 | C17: 55 | D17: 24 | E17: 7 | F17: 3 | G17: 0 | H17: 0 | I17: 2 | J17: 1 | K17: 0 | L17: 0 | M17: 200 | N17: 0 | O17: =SUM(C17:L17,N17) -> 92 | P17: =SUM(C17:N17) -> 292 | R17: 1400-1500 | S17: =SUM(C38:C41) -> 381 | T17: =SUM(D38:D41) -> 218 | U17: =SUM(E38:E41) -> 43 | V17: =SUM(F38:F41) -> 12 | W17: =SUM(G38:G41) -> 0 | X17: =SUM(H38:H41) -> 0 | Y17: =SUM(I38:I41) -> 18 | Z17: =SUM(J38:J41) -> 6 | ... AF17: =SUM(P38:P41) -> 1253
B18: 09.00 - 09.15 | C18: 48 | D18: 35 | E18: 12 | F18: 2 | G18: 0 | H18: 0 | I18: 4 | J18: 1 | K18: 0 | L18: 0 | M18: 188 | N18: 0 | O18: =SUM(C18:L18,N18) -> 102 | P18: =SUM(C18:N18) -> 290 | R18: 1500-1600 | S18: =SUM(C42:C45) -> 369 | T18: =SUM(D42:D45) -> 263 | U18: =SUM(E42:E45) -> 50 | V18: =SUM(F42:F45) -> 9 | W18: =SUM(G42:G45) -> 0 | X18: =SUM(H42:H45) -> 0 | Y18: =SUM(I42:I45) -> 12 | Z18: =SUM(J42:J45) -> 5 | ... AF18: =SUM(P42:P45) -> 1266
B19: 09.15 - 09.30 | C19: 49 | D19: 26 | E19: 12 | F19: 2 | G19: 0 | H19: 0 | I19: 4 | J19: 2 | K19: 3 | L19: 0 | M19: 110 | N19: 0 | O19: =SUM(C19:L19,N19) -> 98 | P19: =SUM(C19:N19) -> 208 | R19: 1600-1700 | S19: =SUM(C46:C49) -> 510 | T19: =SUM(D46:D49) -> 278 | U19: =SUM(E46:E49) -> 78 | V19: =SUM(F46:F49) -> 30 | W19: =SUM(G46:G49) -> 0 | X19: =SUM(H46:H49) -> 0 | Y19: =SUM(I46:I49) -> 6 | Z19: =SUM(J46:J49) -> 6 | ... AF19: =SUM(P46:P49) -> 1375
B20: 09.30 - 09.45 | C20: 47 | D20: 34 | E20: 1 | F20: 1 | G20: 2 | H20: 0 | I20: 6 | J20: 0 | K20: 1 | L20: 0 | M20: 75 | N20: 0 | O20: =SUM(C20:L20,N20) -> 92 | P20: =SUM(C20:N20) -> 167 | R20: 1700-1800 | S20: =SUM(C50:C53) -> 612 | T20: =SUM(D50:D53) -> 195 | U20: =SUM(E50:E53) -> 70 | V20: =SUM(F50:F53) -> 12 | W20: =SUM(G50:G53) -> 0 | X20: =SUM(H50:H53) -> 0 | Y20: =SUM(I50:I53) -> 12 | Z20: =SUM(J50:J53) -> 4 | ... AF20: =SUM(P50:P53) -> 1650
B21: 09.45 - 10.00 | C21: 62 | D21: 36 | E21: 12 | F21: 2 | G21: 0 | H21: 0 | I21: 7 | J21: 2 | K21: 0 | L21: 1 | M21: 190 | N21: 0 | O21: =SUM(C21:L21,N21) -> 122 | P21: =SUM(C21:N21) -> 312 | R21: 1800-1900 | S21: =SUM(C54:C57) -> 494 | T21: =SUM(D54:D57) -> 146 | U21: =SUM(E54:E57) -> 52 | V21: =SUM(F54:F57) -> 30 | W21: =SUM(G54:G57) -> 6 | X21: =SUM(H54:H57) -> 0 | Y21: =SUM(I54:I57) -> 10 | Z21: =SUM(J54:J57) -> 4 | ... AF21: =SUM(P54:P57) -> 1365
B22: 10.00 - 10.15 | C22: 82 | D22: 34 | E22: 12 | F22: 4 | G22: 0 | H22: 0 | I22: 4 | J22: 0 | K22: 2 | L22: 0 | M22: 50 | N22: 0 | O22: =SUM(C22:L22,N22) -> 138 | P22: =SUM(C22:N22) -> 188 | R22: AM Peak Hr | S22: =MAX(S10:S12) -> 268 | T22: =MAX(T10:T12) -> 131 | U22: =MAX(U10:U12) -> 48 | V22: =MAX(V10:V12) -> 11 | W22: =MAX(W10:W12) -> 2 | X22: =MAX(X10:X12) -> 0 | Y22: =MAX(Y10:Y12) -> 21 | Z22: =MAX(Z10:Z12) -> 5 | ... AF22: =MAX(AF10:AF12) -> 1319
B23: 10.15 - 10.30 | C23: 62 | D23: 23 | E23: 7 | F23: 3 | G23: 0 | H23: 0 | I23: 10 | J23: 1 | K23: 1 | L23: 0 | M23: 175 | N23: 0 | O23: =SUM(C23:L23,N23) -> 107 | P23: =SUM(C23:N23) -> 282 | R23: IP Peak Hr | S23: =MAX(S13:S18) -> 392 | T23: =MAX(T13:T18) -> 266 | U23: =MAX(U13:U18) -> 78 | V23: =MAX(V13:V18) -> 19 | W23: =MAX(W13:W18) -> 1 | X23: =MAX(X13:X18) -> 0 | Y23: =MAX(Y13:Y18) -> 24 | Z23: =MAX(Z13:Z18) -> 6 | ... AF23: =MAX(AF13:AF18) -> 1266
B24: 10.30 - 10.45 | C24: 51 | D24: 41 | E24: 1 | F24: 3 | G24: 0 | H24: 0 | I24: 4 | J24: 2 | K24: 1 | L24: 0 | M24: 130 | N24: 0 | O24: =SUM(C24:L24,N24) -> 103 | P24: =SUM(C24:N24) -> 233 | R24: PM Peak Hr | S24: =MAX(S19:S21) -> 612 | T24: =MAX(T19:T21) -> 278 | U24: =MAX(U19:U21) -> 78 | V24: =MAX(V19:V21) -> 30 | W24: =MAX(W19:W21) -> 6 | X24: =MAX(X19:X21) -> 0 | Y24: =MAX(Y19:Y21) -> 12 | Z24: =MAX(Z19:Z21) -> 6 | ... AF24: =MAX(AF19:AF21) -> 1650
B25: 10.45 - 11.00 | C25: 76 | D25: 43 | E25: 8 | F25: 3 | G25: 0 | H25: 0 | I25: 6 | J25: 0 | K25: 0 | L25: 0 | M25: 149 | N25: 0 | O25: =SUM(C25:L25,N25) -> 136 | P25: =SUM(C25:N25) -> 285 | R25: AM Period | S25: =SUM(S10:S12) -> 730 | T25: =SUM(T10:T12) -> 359 | U25: =SUM(U10:U12) -> 112 | V25: =SUM(V10:V12) -> 22 | W25: =SUM(W10:W12) -> 3 | X25: =SUM(X10:X12) -> 0 | Y25: =SUM(Y10:Y12) -> 46 | Z25: =SUM(Z10:Z12) -> 11 | ... AF25: =SUM(AF10:AF12) -> 3375
B26: 11.00 - 11.15 | C26: 74 | D26: 48 | E26: 15 | F26: 4 | G26: 0 | H26: 0 | I26: 7 | J26: 1 | K26: 0 | L26: 0 | M26: 130 | N26: 0 | O26: =SUM(C26:L26,N26) -> 149 | P26: =SUM(C26:N26) -> 279 | R26: IP Period | S26: =SUM(S13:S18) -> 2071 | T26: =SUM(T13:T18) -> 1267 | U26: =SUM(U13:U18) -> 317 | V26: =SUM(V13:V18) -> 66 | W26: =SUM(W13:W18) -> 1 | X26: =SUM(X13:X18) -> 0 | Y26: =SUM(Y13:Y18) -> 94 | Z26: =SUM(Z13:Z18) -> 24 | ... AF26: =SUM(AF13:AF18) -> 6922
B27: 11.15 - 11.30 | C27: 67 | D27: 30 | E27: 8 | F27: 2 | G27: 0 | H27: 0 | I27: 2 | J27: 2 | K27: 0 | L27: 0 | M27: 135 | N27: 0 | O27: =SUM(C27:L27,N27) -> 111 | P27: =SUM(C27:N27) -> 246 | R27: PM Period | S27: =SUM(S19:S21) -> 1616 | T27: =SUM(T19:T21) -> 619 | U27: =SUM(U19:U21) -> 200 | V27: =SUM(V19:V21) -> 72 | W27: =SUM(W19:W21) -> 6 | X27: =SUM(X19:X21) -> 0 | Y27: =SUM(Y19:Y21) -> 28 | Z27: =SUM(Z19:Z21) -> 14 | ... AF27: =SUM(AF19:AF21) -> 4390
B28: 11.30 - 11.45 | C28: 72 | D28: 52 | E28: 17 | F28: 1 | G28: 0 | H28: 0 | I28: 3 | J28: 0 | K28: 1 | L28: 0 | M28: 135 | N28: 0 | O28: =SUM(C28:L28,N28) -> 146 | P28: =SUM(C28:N28) -> 281 | R28: 12 Hours | S28: =SUM(S10:S21) -> 4417 | T28: =SUM(T10:T21) -> 2245 | U28: =SUM(U10:U21) -> 629 | V28: =SUM(V10:V21) -> 160 | W28: =SUM(W10:W21) -> 10 | X28: =SUM(X10:X21) -> 0 | Y28: =SUM(Y10:Y21) -> 168 | Z28: =SUM(Z10:Z21) -> 49 | ... AF28: =SUM(AF10:AF21) -> 14687
B29: 11.45 - 12.00 | C29: 71 | D29: 31 | E29: 7 | F29: 1 | G29: 0 | H29: 0 | I29: 1 | J29: 1 | K29: 0 | L29: 0 | M29: 125 | N29: 0 | O29: =SUM(C29:L29,N29) -> 112 | P29: =SUM(C29:N29) -> 237
B30: 12.00 - 12.15 | C30: 63 | D30: 41 | E30: 17 | F30: 1 | G30: 1 | H30: 0 | I30: 3 | J30: 0 | K30: 1 | L30: 0 | M30: 110 | N30: 0 | O30: =SUM(C30:L30,N30) -> 127 | P30: =SUM(C30:N30) -> 237
B31: 12.15 - 12.30 | C31: 83 | D31: 55 | E31: 9 | F31: 1 | G31: 0 | H31: 0 | I31: 6 | J31: 3 | K31: 0 | L31: 0 | M31: 130 | N31: 0 | O31: =SUM(C31:L31,N31) -> 157 | P31: =SUM(C31:N31) -> 287
B32: 12.30 - 12.45 | C32: 120 | D32: 59 | E32: 15 | F32: 0 | G32: 0 | H32: 0 | I32: 2 | J32: 1 | K32: 0 | L32: 1 | M32: 115 | N32: 0 | O32: =SUM(C32:L32,N32) -> 198 | P32: =SUM(C32:N32) -> 313
B33: 12.45 - 13.00 | C33: 108 | D33: 63 | E33: 30 | F33: 3 | G33: 0 | H33: 0 | I33: 4 | J33: 0 | K33: 0 | L33: 0 | M33: 162 | N33: 0 | O33: =SUM(C33:L33,N33) -> 208 | P33: =SUM(C33:N33) -> 370
B34: 13.00 - 13.15 | C34: 116 | D34: 78 | E34: 23 | F34: 3 | G34: 0 | H34: 0 | I34: 3 | J34: 1 | K34: 0 | L34: 0 | M34: 90 | N34: 0 | O34: =SUM(C34:L34,N34) -> 224 | P34: =SUM(C34:N34) -> 314
B35: 13.15 - 13.30 | C35: 125 | D35: 77 | E35: 23 | F35: 11 | G35: 0 | H35: 0 | I35: 2 | J35: 1 | K35: 0 | L35: 1 | M35: 155 | N35: 0 | O35: =SUM(C35:L35,N35) -> 240 | P35: =SUM(C35:N35) -> 395
B36: 13.30 - 13.45 | C36: 85 | D36: 63 | E36: 21 | F36: 4 | G36: 0 | H36: 0 | I36: 2 | J36: 0 | K36: 0 | L36: 0 | M36: 80 | N36: 0 | O36: =SUM(C36:L36,N36) -> 175 | P36: =SUM(C36:N36) -> 255
B37: 13.45 - 14.00 | C37: 66 | D37: 48 | E37: 11 | F37: 1 | G37: 0 | H37: 0 | I37: 5 | J37: 0 | K37: 0 | L37: 0 | M37: 70 | N37: 0 | O37: =SUM(C37:L37,N37) -> 131 | P37: =SUM(C37:N37) -> 201
B38: 14.00 - 14.15 | C38: 73 | D38: 43 | E38: 12 | F38: 4 | G38: 0 | H38: 0 | I38: 9 | J38: 2 | K38: 0 | L38: 0 | M38: 125 | N38: 0 | O38: =SUM(C38:L38,N38) -> 143 | P38: =SUM(C38:N38) -> 268
B39: 14.15 - 14.30 | C39: 102 | D39: 64 | E39: 7 | F39: 3 | G39: 0 | H39: 0 | I39: 5 | J39: 3 | K39: 1 | L39: 0 | M39: 165 | N39: 0 | O39: =SUM(C39:L39,N39) -> 185 | P39: =SUM(C39:N39) -> 350
B40: 14.30 - 14.45 | C40: 103 | D40: 55 | E40: 13 | F40: 2 | G40: 0 | H40: 0 | I40: 1 | J40: 0 | K40: 0 | L40: 1 | M40: 167 | N40: 0 | O40: =SUM(C40:L40,N40) -> 175 | P40: =SUM(C40:N40) -> 342
... B57: 18.45 - 19.00 | C57: 124 | D57: 34 | E57: 12 | F57: 7 | G57: 2 | H57: 0 | I57: 2 | J57: 0 | K57: 0 | L57: 0 | M57: 103 | N57: 0 | O57: =SUM(C57:L57,N57) -> 181 | P57: =SUM(C57:N57) -> 284
B58: Totals | C58: =SUM(C10:C57) -> 4417 | D58: =SUM(D10:D57) -> 2245 | E58: =SUM(E10:E57) -> 629 | F58: =SUM(F10:F57) -> 160 | G58: =SUM(G10:G57) -> 10 | H58: =SUM(H10:H57) -> 0 | I58: =SUM(I10:I57) -> 168 | J58: =SUM(J10:J57) -> 49 | ... P58: =SUM(P10:P57) -> 14687
...

Sheet 30.07 Kira Road-Jinja Road
B1: Consultancy services for Preparation of Expressway Development Master Plan (EDMP) for Uganda
B2: MANUAL CLASSIFIED COUNT (MCC)
B3: ROAD NAME: | C3: ='29.07 Kira Road-Jinaj Road'!C3:G3 -> MCC - C1 - STN47 - LUGOGO BYPASS ROAD
C5: Date | D5: ='30.07 Jinja Road-Kira Road'!D5 -> 30.07.19 | F5: Location | G5: ='29.07 JinjaRoad-Kira Road'!G5:H5 -> DHL (47) | J5: Surveyor | K5: ='29.07 JinjaRoad-Kira Road'!K5:L5 -> Nalubega Resty
C6: Dir. From | D6: Kira Road | F6: Dir. To | G6: Jinja Road | J6: Supervisor | K6: ='29.07 JinjaRoad-Kira Road'!K6:L6 -> Felix
B8: Time / Veh Type | R8: SUMMARY TRAFFIC VOLUMES
C9: 1. Car | D9: 2. Station Wagon | E9: 3. Pickups | F9: 4. Minibus, matatu | G9: 5. Medium bus | H9: 6. Large Bus | I9: 7. Light Truck | J9: 8. Medium Truck | K9: 9. Heavy truck | L9: 10. Truck Trailer | M9: 11. Motor cycles | N9: 12. Tractors | O9: Total Excl M/Cycles | P9: Total All | R9: Time | S9: 1. Car | T9: 2. Station Wagon | U9: 3. Pickups | V9: 4. Minibus, matatu | W9: 5. Medium bus | X9: 6. Large Bus | Y9: 7. Light Truck | Z9: 8. Medium Truck | AA9: 9. Heavy truck | AB9: 10. Truck Trailer | AC9: 11. Motorcycles | AD9: 12. Tractors, Graders | AE9: Total Excl M/ Cycles | AF9: Total All
B10: 07.00 - 07.15 | C10: 175 | D10: 80 | E10: 48 | F10: 3 | G10: 0 | H10: 0 | I10: 0 | J10: 0 | K10: 0 | L10: 0 | M10: 135 | N10: 0 | O10: =SUM(C10:L10,N10) -> 306 | P10: =SUM(C10:N10) -> 441 | R10: 0700-0800 | S10: =SUM(C10:C13) -> 688 | T10: =SUM(D10:D13) -> 292 | U10: =SUM(E10:E13) -> 132 | V10: =SUM(F10:F13) -> 30 | W10: =SUM(G10:G13) -> 1 | X10: =SUM(H10:H13) -> 0 | Y10: =SUM(I10:I13) -> 6 | Z10: =SUM(J10:J13) -> 1 | ... AF10: =SUM(P10:P13) -> 1830
B11: 07.15 - 07.30 | C11: 173 | D11: 58 | E11: 37 | F11: 8 | G11: 1 | H11: 0 | I11: 4 | J11: 1 | K11: 0 | L11: 0 | M11: 135 | N11: 0 | O11: =SUM(C11:L11,N11) -> 282 | P11: =SUM(C11:N11) -> 417 | R11: 0800-0900 | S11: =SUM(C14:C17) -> 740 | T11: =SUM(D14:D17) -> 307 | U11: =SUM(E14:E17) -> 125 | V11: =SUM(F14:F17) -> 22 | W11: =SUM(G14:G17) -> 3 | X11: =SUM(H14:H17) -> 0 | Y11: =SUM(I14:I17) -> 11 | Z11: =SUM(J14:J17) -> 5 | ... AF11: =SUM(P14:P17) -> 2205
B12: 07.30 - 07.45 | C12: 180 | D12: 74 | E12: 25 | F12: 2 | G12: 0 | H12: 0 | I12: 1 | J12: 0 | K12: 0 | L12: 0 | M12: 189 | N12: 0 | O12: =SUM(C12:L12,N12) -> 282 | P12: =SUM(C12:N12) -> 471 | R12: 0900-1000 | S12: =SUM(C18:C21) -> 749 | T12: =SUM(D18:D21) -> 301 | U12: =SUM(E18:E21) -> 147 | V12: =SUM(F18:F21) -> 17 | W12: =SUM(G18:G21) -> 6 | X12: =SUM(H18:H21) -> 1 | Y12: =SUM(I18:I21) -> 25 | Z12: =SUM(J18:J21) -> 8 | ... AF12: =SUM(P18:P21) -> 2059
B13: 07.45 - 08.00 | C13: 160 | D13: 80 | E13: 22 | F13: 17 | G13: 0 | H13: 0 | I13: 1 | J13: 0 | K13: 0 | L13: 0 | M13: 221 | N13: 0 | O13: =SUM(C13:L13,N13) -> 280 | P13: =SUM(C13:N13) -> 501 | R13: 1000-1100 | S13: =SUM(C22:C25) -> 679 | T13: =SUM(D22:D25) -> 276 | U13: =SUM(E22:E25) -> 166 | V13: =SUM(F22:F25) -> 14 | W13: =SUM(G22:G25) -> 2 | X13: =SUM(H22:H25) -> 0 | Y13: =SUM(I22:I25) -> 24 | Z13: =SUM(J22:J25) -> 8 | ... AF13: =SUM(P22:P25) -> 1941
B14: 08.00 - 08.15 | C14: 160 | D14: 77 | E14: 27 | F14: 3 | G14: 2 | H14: 0 | I14: 2 | J14: 0 | K14: 0 | L14: 0 | M14: 247 | N14: 0 | O14: =SUM(C14:L14,N14) -> 271 | P14: =SUM(C14:N14) -> 518 | R14: 1100-1200 | S14: =SUM(C26:C29) -> 622 | T14: =SUM(D26:D29) -> 279 | U14: =SUM(E26:E29) -> 149 | V14: =SUM(F26:F29) -> 15 | W14: =SUM(G26:G29) -> 1 | X14: =SUM(H26:H29) -> 0 | Y14: =SUM(I26:I29) -> 22 | Z14: =SUM(J26:J29) -> 6 | ... AF14: =SUM(P26:P29) -> 1886
B15: 08.15 - 08.30 | C15: 200 | D15: 64 | E15: 35 | F15: 7 | G15: 0 | H15: 0 | I15: 4 | J15: 1 | K15: 0 | L15: 0 | M15: 243 | N15: 0 | O15: =SUM(C15:L15,N15) -> 311 | P15: =SUM(C15:N15) -> 554 | R15: 1200-1300 | S15: =SUM(C30:C33) -> 672 | T15: =SUM(D30:D33) -> 97 | U15: =SUM(E30:E33) -> 58 | V15: =SUM(F30:F33) -> 9 | W15: =SUM(G30:G33) -> 0 | X15: =SUM(H30:H33) -> 0 | Y15: =SUM(I30:I33) -> 34 | Z15: =SUM(J30:J33) -> 6 | ... AF15: =SUM(P30:P33) -> 1578
B16: 08.30 - 08.45 | C16: 200 | D16: 82 | E16: 43 | F16: 10 | G16: 1 | H16: 0 | I16: 2 | J16: 3 | K16: 1 | L16: 0 | M16: 242 | N16: 0 | O16: =SUM(C16:L16,N16) -> 342 | P16: =SUM(C16:N16) -> 584 | R16: 1300-1400 | S16: =SUM(C34:C37) -> 670 | T16: =SUM(D34:D37) -> 217 | U16: =SUM(E34:E37) -> 115 | V16: =SUM(F34:F37) -> 18 | W16: =SUM(G34:G37) -> 1 | X16: =SUM(H34:H37) -> 0 | Y16: =SUM(I34:I37) -> 32 | Z16: =SUM(J34:J37) -> 6 | ... AF16: =SUM(P34:P37) -> 1842
B17: 08.45 - 9.00 | C17: 180 | D17: 84 | E17: 20 | F17: 2 | G17: 0 | H17: 0 | I17: 3 | J17: 1 | K17: 0 | L17: 0 | M17: 259 | N17: 0 | O17: =SUM(C17:L17,N17) -> 290 | P17: =SUM(C17:N17) -> 549 | R17: 1400-1500 | S17: =SUM(C38:C41) -> 687 | T17: =SUM(D38:D41) -> 213 | U17: =SUM(E38:E41) -> 88 | V17: =SUM(F38:F41) -> 15 | W17: =SUM(G38:G41) -> 1 | X17: =SUM(H38:H41) -> 0 | Y17: =SUM(I38:I41) -> 32 | Z17: =SUM(J38:J41) -> 10 | ... AF17: =SUM(P38:P41) -> 1816
B18: 09.00 - 09.15 | C18: 180 | D18: 80 | E18: 33 | F18: 7 | G18: 5 | H18: 0 | I18: 5 | J18: 1 | K18: 1 | L18: 0 | M18: 229 | N18: 0 | O18: =SUM(C18:L18,N18) -> 312 | P18: =SUM(C18:N18) -> 541 | R18: 1500-1600 | S18: =SUM(C42:C45) -> 579 | T18: =SUM(D42:D45) -> 276 | U18: =SUM(E42:E45) -> 122 | V18: =SUM(F42:F45) -> 26 | W18: =SUM(G42:G45) -> 1 | X18: =SUM(H42:H45) -> 0 | Y18: =SUM(I42:I45) -> 30 | Z18: =SUM(J42:J45) -> 12 | ... AF18: =SUM(P42:P45) -> 1884
B19: 09.15 - 09.30 | C19: 200 | D19: 69 | E19: 42 | F19: 2 | G19: 0 | H19: 1 | I19: 3 | J19: 2 | K19: 0 | L19: 0 | M19: 234 | N19: 0 | O19: =SUM(C19:L19,N19) -> 319 | P19: =SUM(C19:N19) -> 553 | R19: 1600-1700 | S19: =SUM(C46:C49) -> 611 | T19: =SUM(D46:D49) -> 264 | U19: =SUM(E46:E49) -> 184 | V19: =SUM(F46:F49) -> 79 | W19: =SUM(G46:G49) -> 1 | X19: =SUM(H46:H49) -> 0 | Y19: =SUM(I46:I49) -> 32 | Z19: =SUM(J46:J49) -> 13 | ... AF19: =SUM(P46:P49) -> 2076
B20: 09.30 - 09.45 | C20: 180 | D20: 68 | E20: 42 | F20: 3 | G20: 1 | H20: 0 | I20: 7 | J20: 3 | K20: 0 | L20: 0 | M20: 154 | N20: 0 | O20: =SUM(C20:L20,N20) -> 304 | P20: =SUM(C20:N20) -> 458 | R20: 1700-1800 | S20: =SUM(C50:C53) -> 670 | T20: =SUM(D50:D53) -> 323 | U20: =SUM(E50:E53) -> 150 | V20: =SUM(F50:F53) -> 72 | W20: =SUM(G50:G53) -> 2 | X20: =SUM(H50:H53) -> 0 | Y20: =SUM(I50:I53) -> 22 | Z20: =SUM(J50:J53) -> 5 | ... AF20: =SUM(P50:P53) -> 2217
B21: 09.45 - 10.00 | C21: 189 | D21: 84 | E21: 30 | F21: 5 | G21: 0 | H21: 0 | I21: 10 | J21: 2 | K21: 0 | L21: 0 | M21: 187 | N21: 0 | O21: =SUM(C21:L21,N21) -> 320 | P21: =SUM(C21:N21) -> 507 | R21: 1800-1900 | S21: =SUM(C54:C57) -> 580 | T21: =SUM(D54:D57) -> 230 | U21: =SUM(E54:E57) -> 111 | V21: =SUM(F54:F57) -> 16 | W21: =SUM(G54:G57) -> 1 | X21: =SUM(H54:H57) -> 0 | Y21: =SUM(I54:I57) -> 18 | Z21: =SUM(J54:J57) -> 10 | ... AF21: =SUM(P54:P57) -> 1807
B22: 10.00 - 10.15 | C22: 195 | D22: 75 | E22: 36 | F22: 2 | G22: 0 | H22: 0 | I22: 6 | J22: 2 | K22: 2 | L22: 0 | M22: 207 | N22: 0 | O22: =SUM(C22:L22,N22) -> 318 | P22: =SUM(C22:N22) -> 525 | R22: AM Peak Hr | S22: =MAX(S10:S12) -> 749 | T22: =MAX(T10:T12) -> 307 | U22: =MAX(U10:U12) -> 147 | V22: =MAX(V10:V12) -> 30 | W22: =MAX(W10:W12) -> 6 | X22: =MAX(X10:X12) -> 1 | Y22: =MAX(Y10:Y12) -> 25 | Z22: =MAX(Z10:Z12) -> 8 | ... AF22: =MAX(AF10:AF12) -> 2205
B23: 10.15 - 10.30 | C23: 163 | D23: 79 | E23: 60 | F23: 3 | G23: 0 | H23: 0 | I23: 5 | J23: 2 | K23: 0 | L23: 1 | M23: 148 | N23: 0 | O23: =SUM(C23:L23,N23) -> 313 | P23: =SUM(C23:N23) -> 461 | R23: IP Peak Hr | S23: =MAX(S13:S18) -> 687 | T23: =MAX(T13:T18) -> 279 | U23: =MAX(U13:U18) -> 166 | V23: =MAX(V13:V18) -> 26 | W23: =MAX(W13:W18) -> 2 | X23: =MAX(X13:X18) -> 0 | Y23: =MAX(Y13:Y18) -> 34 | Z23: =MAX(Z13:Z18) -> 12 | ... AF23: =MAX(AF13:AF18) -> 1941
B24: 10.30 - 10.45 | C24: 161 | D24: 62 | E24: 50 | F24: 6 | G24: 2 | H24: 0 | I24: 6 | J24: 1 | K24: 3 | L24: 0 | M24: 204 | N24: 0 | O24: =SUM(C24:L24,N24) -> 291 | P24: =SUM(C24:N24) -> 495 | R24: PM Peak Hr | S24: =MAX(S19:S21) -> 670 | T24: =MAX(T19:T21) -> 323 | U24: =MAX(U19:U21) -> 184 | V24: =MAX(V19:V21) -> 79 | W24: =MAX(W19:W21) -> 2 | X24: =MAX(X19:X21) -> 0 | Y24: =MAX(Y19:Y21) -> 32 | Z24: =MAX(Z19:Z21) -> 13 | ... AF24: =MAX(AF19:AF21) -> 2217
B25: 10.45 - 11.00 | C25: 160 | D25: 60 | E25: 20 | F25: 3 | G25: 0 | H25: 0 | I25: 7 | J25: 3 | K25: 3 | L25: 0 | M25: 204 | N25: 0 | O25: =SUM(C25:L25,N25) -> 256 | P25: =SUM(C25:N25) -> 460 | R25: AM Period | S25: =SUM(S10:S12) -> 2177 | T25: =SUM(T10:T12) -> 900 | U25: =SUM(U10:U12) -> 404 | V25: =SUM(V10:V12) -> 69 | W25: =SUM(W10:W12) -> 10 | X25: =SUM(X10:X12) -> 1 | Y25: =SUM(Y10:Y12) -> 42 | Z25: =SUM(Z10:Z12) -> 14 | ... AF25: =SUM(AF10:AF12) -> 6094
B26: 11.00 - 11.15 | C26: 155 | D26: 63 | E26: 47 | F26: 6 | G26: 1 | H26: 0 | I26: 5 | J26: 3 | K26: 0 | L26: 0 | M26: 199 | N26: 0 | O26: =SUM(C26:L26,N26) -> 280 | P26: =SUM(C26:N26) -> 479 | R26: IP Period | S26: =SUM(S13:S18) -> 3909 | T26: =SUM(T13:T18) -> 1358 | U26: =SUM(U13:U18) -> 698 | V26: =SUM(V13:V18) -> 97 | W26: =SUM(W13:W18) -> 6 | X26: =SUM(X13:X18) -> 0 | Y26: =SUM(Y13:Y18) -> 174 | Z26: =SUM(Z13:Z18) -> 48 | ... AF26: =SUM(AF13:AF18) -> 10947
B27: 11.15 - 11.30 | C27: 140 | D27: 80 | E27: 38 | F27: 3 | G27: 0 | H27: 0 | I27: 8 | J27: 0 | K27: 0 | L27: 1 | M27: 189 | N27: 0 | O27: =SUM(C27:L27,N27) -> 270 | P27: =SUM(C27:N27) -> 459 | R27: PM Period | S27: =SUM(S19:S21) -> 1861 | T27: =SUM(T19:T21) -> 817 | U27: =SUM(U19:U21) -> 445 | V27: =SUM(V19:V21) -> 167 | W27: =SUM(W19:W21) -> 4 | X27: =SUM(X19:X21) -> 0 | Y27: =SUM(Y19:Y21) -> 72 | Z27: =SUM(Z19:Z21) -> 28 | ... AF27: =SUM(AF19:AF21) -> 6100
B28: 11.30 - 11.45 | C28: 145 | D28: 68 | E28: 40 | F28: 2 | G28: 0 | H28: 0 | I28: 9 | J28: 3 | K28: 0 | L28: 0 | M28: 224 | N28: 0 | O28: =SUM(C28:L28,N28) -> 267 | P28: =SUM(C28:N28) -> 491 | R28: 12 Hours | S28: =SUM(S10:S21) -> 7947 | T28: =SUM(T10:T21) -> 3075 | U28: =SUM(U10:U21) -> 1547 | V28: =SUM(V10:V21) -> 333 | W28: =SUM(W10:W21) -> 20 | X28: =SUM(X10:X21) -> 1 | Y28: =SUM(Y10:Y21) -> 288 | Z28: =SUM(Z10:Z21) -> 90 | ... AF28: =SUM(AF10:AF21) -> 23141
B29: 11.45 - 12.00 | C29: 182 | D29: 68 | E29: 24 | F29: 4 | G29: 0 | H29: 0 | I29: 0 | J29: 0 | K29: 0 | L29: 0 | M29: 179 | N29: 0 | O29: =SUM(C29:L29,N29) -> 278 | P29: =SUM(C29:N29) -> 457
B30: 12.00 - 12.15 | C30: 165 | D30: 26 | E30: 13 | F30: 2 | G30: 0 | H30: 0 | I30: 11 | J30: 0 | K30: 1 | L30: 1 | M30: 132 | N30: 0 | O30: =SUM(C30:L30,N30) -> 219 | P30: =SUM(C30:N30) -> 351
B31: 12.15 - 12.30 | C31: 187 | D31: 31 | E31: 18 | F31: 2 | G31: 0 | H31: 0 | I31: 9 | J31: 1 | K31: 0 | L31: 0 | M31: 201 | N31: 0 | O31: =SUM(C31:L31,N31) -> 248 | P31: =SUM(C31:N31) -> 449
B32: 12.30 - 12.45 | C32: 175 | D32: 13 | E32: 13 | F32: 3 | G32: 0 | H32: 0 | I32: 5 | J32: 3 | K32: 1 | L32: 0 | M32: 189 | N32: 0 | O32: =SUM(C32:L32,N32) -> 213 | P32: =SUM(C32:N32) -> 402
B33: 12.45 - 13.00 | C33: 145 | D33: 27 | E33: 14 | F33: 2 | G33: 0 | H33: 0 | I33: 9 | J33: 2 | K33: 0 | L33: 0 | M33: 177 | N33: 0 | O33: =SUM(C33:L33,N33) -> 199 | P33: =SUM(C33:N33) -> 376
B34: 13.00 - 13.15 | C34: 227 | D34: 31 | E34: 23 | F34: 5 | G34: 0 | H34: 0 | I34: 6 | J34: 3 | K34: 0 | L34: 0 | M34: 154 | N34: 0 | O34: =SUM(C34:L34,N34) -> 295 | P34: =SUM(C34:N34) -> 449
B35: 13.15 - 13.30 | C35: 160 | D35: 60 | E35: 34 | F35: 3 | G35: 1 | H35: 0 | I35: 11 | J35: 1 | K35: 0 | L35: 0 | M35: 221 | N35: 0 | O35: =SUM(C35:L35,N35) -> 270 | P35: =SUM(C35:N35) -> 491
B36: 13.30 - 13.45 | C36: 120 | D36: 56 | E36: 20 | F36: 8 | G36: 0 | H36: 0 | I36: 9 | J36: 1 | K36: 0 | L36: 0 | M36: 207 | N36: 0 | O36: =SUM(C36:L36,N36) -> 214 | P36: =SUM(C36:N36) -> 421
B37: 13.45 - 14.00 | C37: 163 | D37: 70 | E37: 38 | F37: 2 | G37: 0 | H37: 0 | I37: 6 | J37: 1 | K37: 0 | L37: 0 | M37: 201 | N37: 0 | O37: =SUM(C37:L37,N37) -> 280 | P37: =SUM(C37:N37) -> 481
B38: 14.00 - 14.15 | C38: 200 | D38: 54 | E38: 30 | F38: 2 | G38: 0 | H38: 0 | I38: 6 | J38: 5 | K38: 0 | L38: 0 | M38: 216 | N38: 0 | O38: =SUM(C38:L38,N38) -> 297 | P38: =SUM(C38:N38) -> 513
B39: 14.15 - 14.30 | C39: 135 | D39: 40 | E39: 17 | F39: 3 | G39: 0 | H39: 0 | I39: 7 | J39: 2 | K39: 0 | L39: 0 | M39: 194 | N39: 0 | O39: =SUM(C39:L39,N39) -> 204 | P39: =SUM(C39:N39) -> 398
B40: 14.30 - 14.45 | C40: 170 | D40: 44 | E40: 21 | F40: 9 | G40: 0 | H40: 0 | I40: 10 | J40: 1 | K40: 1 | L40: 0 | M40: 190 | N40: 0 | O40: =SUM(C40:L40,N40) -> 256 | P40: =SUM(C40:N40) -> 446
... B57: 18.45 - 19.00 | C57: 108 | D57: 47 | E57: 15 | F57: 5 | G57: 0 | H57: 0 | I57: 3 | J57: 0 | K57: 0 | L57: 0 | M57: 160 | N57: 0 | O57: =SUM(C57:L57,N57) -> 178 | P57: =SUM(C57:N57) -> 338
B58: Totals | C58: =SUM(C10:C57) -> 7947 | D58: =SUM(D10:D57) -> 3075 | E58: =SUM(E10:E57) -> 1547 | F58: =SUM(F10:F57) -> 333 | G58: =SUM(G10:G57) -> 20 | H58: =SUM(H10:H57) -> 1 | I58: =SUM(I10:I57) -> 288 | J58: =SUM(J10:J57) -> 90 | ... P58: =SUM(P10:P57) -> 23141
...

Sheet 31.07 Jinja Road-Kira Road
B1: Consultancy services for Preparation of Expressway Development Master Plan (EDMP) for Uganda
B2: MANUAL CLASSIFIED COUNT (MCC)
B3: ROAD NAME: | C3: ='29.07 JinjaRoad-Kira Road'!C3:G3 -> MCC - C1 - STN47 - LUGOGO BYPASS ROAD
C5: Date | D5: 31.07.19 | F5: Location | G5: ='29.07 JinjaRoad-Kira Road'!G5:H5 -> DHL (47) | J5: Surveyor | K5: Orishaba Donitar
C6: Dir. From | D6: ='29.07 JinjaRoad-Kira Road'!D6:E6 -> Jinja Road | F6: Dir. To | G6: ='29.07 JinjaRoad-Kira Road'!G6:H6 -> Kira Road | J6: Supervisor | K6: Steven
B8: Time / Veh Type | R8: SUMMARY TRAFFIC VOLUMES
C9: 1. Car | D9: 2. Station Wagon | E9: 3. Pickups | F9: 4. Minibus, matatu | G9: 5. Medium bus | H9: 6. Large Bus | I9: 7. Light Truck | J9: 8. Medium Truck | K9: 9. Heavy truck | L9: 10. Truck Trailer | M9: 11. Motor cycles | N9: 12. Tractors | O9: Total Excl M/Cycles | P9: Total All | R9: Time | S9: 1. Car | T9: 2. Station Wagon | U9: 3. Pickups | V9: 4. Minibus, matatu | W9: 5. Medium bus | X9: 6. Large Bus | Y9: 7. Light Truck | Z9: 8. Medium Truck | AA9: 9. Heavy truck | AB9: 10. Truck Trailer | AC9: 11. Motorcycles | AD9: 12. Tractors, Graders | AE9: Total Excl M/ Cycles | AF9: Total All
B10: 07.00 - 07.15 | C10: 54 | D10: 23 | E10: 4 | F10: 0 | G10: 0 | H10: 0 | I10: 0 | J10: 1 | K10: 0 | L10: 0 | M10: 92 | N10: 0 | O10: =SUM(C10:L10,N10) -> 82 | P10: =SUM(C10:N10) -> 174 | R10: 0700-0800 | S10: =SUM(C10:C13) -> 289 | T10: =SUM(D10:D13) -> 107 | U10: =SUM(E10:E13) -> 32 | V10: =SUM(F10:F13) -> 6 | W10: =SUM(G10:G13) -> 1 | X10: =SUM(H10:H13) -> 0 | Y10: =SUM(I10:I13) -> 7 | Z10: =SUM(J10:J13) -> 2 | ... AF10: =SUM(P10:P13) -> 1080
B11: 07.15 - 07.30 | C11: 78 | D11: 33 | E11: 5 | F11: 4 | G11: 0 | H11: 0 | I11: 3 | J11: 1 | K11: 0 | L11: 1 | M11: 140 | N11: 0 | O11: =SUM(C11:L11,N11) -> 125 | P11: =SUM(C11:N11) -> 265 | R11: 0800-0900 | S11: =SUM(C14:C17) -> 275 | T11: =SUM(D14:D17) -> 127 | U11: =SUM(E14:E17) -> 37 | V11: =SUM(F14:F17) -> 20 | W11: =SUM(G14:G17) -> 1 | X11: =SUM(H14:H17) -> 0 | Y11: =SUM(I14:I17) -> 8 | Z11: =SUM(J14:J17) -> 7 | ... AF11: =SUM(P14:P17) -> 1472
B12: 07.30 - 07.45 | C12: 75 | D12: 23 | E12: 13 | F12: 0 | G12: 0 | H12: 0 | I12: 2 | J12: 0 | K12: 0 | L12: 1 | M12: 177 | N12: 0 | O12: =SUM(C12:L12,N12) -> 114 | P12: =SUM(C12:N12) -> 291 | R12: 0900-1000 | S12: =SUM(C18:C21) -> 212 | T12: =SUM(D18:D21) -> 116 | U12: =SUM(E18:E21) -> 42 | V12: =SUM(F18:F21) -> 13 | W12: =SUM(G18:G21) -> 0 | X12: =SUM(H18:H21) -> 0 | Y12: =SUM(I18:I21) -> 10 | Z12: =SUM(J18:J21) -> 9 | ... AF12: =SUM(P18:P21) -> 1063
B13: 07.45 - 08.00 | C13: 82 | D13: 28 | E13: 10 | F13: 2 | G13: 1 | H13: 0 | I13: 2 | J13: 0 | K13: 0 | L13: 0 | M13: 225 | N13: 0 | O13: =SUM(C13:L13,N13) -> 125 | P13: =SUM(C13:N13) -> 350 | R13: 1000-1100 | S13: =SUM(C22:C25) -> 253 | T13: =SUM(D22:D25) -> 152 | U13: =SUM(E22:E25) -> 53 | V13: =SUM(F22:F25) -> 20 | W13: =SUM(G22:G25) -> 4 | X13: =SUM(H22:H25) -> 0 | Y13: =SUM(I22:I25) -> 9 | Z13: =SUM(J22:J25) -> 11 | ... AF13: =SUM(P22:P25) -> 1239
B14: 08.00 - 08.15 | C14: 87 | D14: 26 | E14: 11 | F14: 8 | G14: 0 | H14: 0 | I14: 1 | J14: 0 | K14: 0 | L14: 2 | M14: 250 | N14: 0 | O14: =SUM(C14:L14,N14) -> 135 | P14: =SUM(C14:N14) -> 385 | R14: 1100-1200 | S14: =SUM(C26:C29) -> 260 | T14: =SUM(D26:D29) -> 172 | U14: =SUM(E26:E29) -> 51 | V14: =SUM(F26:F29) -> 9 | W14: =SUM(G26:G29) -> 0 | X14: =SUM(H26:H29) -> 0 | Y14: =SUM(I26:I29) -> 11 | Z14: =SUM(J26:J29) -> 8 | ... AF14: =SUM(P26:P29) -> 1285
B15: 08.15 - 08.30 | C15: 90 | D15: 45 | E15: 15 | F15: 9 | G15: 0 | H15: 0 | I15: 2 | J15: 3 | K15: 0 | L15: 2 | M15: 255 | N15: 0 | O15: =SUM(C15:L15,N15) -> 166 | P15: =SUM(C15:N15) -> 421 | R15: 1200-1300 | S15: =SUM(C30:C33) -> 279 | T15: =SUM(D30:D33) -> 169 | U15: =SUM(E30:E33) -> 40 | V15: =SUM(F30:F33) -> 15 | W15: =SUM(G30:G33) -> 0 | X15: =SUM(H30:H33) -> 0 | Y15: =SUM(I30:I33) -> 20 | Z15: =SUM(J30:J33) -> 10 | ... AF15: =SUM(P30:P33) -> 1094
B16: 08.30 - 08.45 | C16: 46 | D16: 22 | E16: 6 | F16: 0 | G16: 0 | H16: 0 | I16: 3 | J16: 2 | K16: 0 | L16: 0 | M16: 300 | N16: 0 | O16: =SUM(C16:L16,N16) -> 79 | P16: =SUM(C16:N16) -> 379 | R16: 1300-1400 | S16: =SUM(C34:C37) -> 320 | T16: =SUM(D34:D37) -> 178 | U16: =SUM(E34:E37) -> 57 | V16: =SUM(F34:F37) -> 17 | W16: =SUM(G34:G37) -> 2 | X16: =SUM(H34:H37) -> 0 | Y16: =SUM(I34:I37) -> 17 | Z16: =SUM(J34:J37) -> 6 | ... AF16: =SUM(P34:P37) -> 1286
B17: 08.45 - 9.00 | C17: 52 | D17: 34 | E17: 5 | F17: 3 | G17: 1 | H17: 0 | I17: 2 | J17: 2 | K17: 0 | L17: 1 | M17: 187 | N17: 0 | O17: =SUM(C17:L17,N17) -> 100 | P17: =SUM(C17:N17) -> 287 | R17: 1400-1500 | S17: =SUM(C38:C41) -> 368 | T17: =SUM(D38:D41) -> 202 | U17: =SUM(E38:E41) -> 47 | V17: =SUM(F38:F41) -> 10 | W17: =SUM(G38:G41) -> 0 | X17: =SUM(H38:H41) -> 0 | Y17: =SUM(I38:I41) -> 7 | Z17: =SUM(J38:J41) -> 3 | ... AF17: =SUM(P38:P41) -> 1092
B18: 09.00 - 09.15 | C18: 62 | D18: 33 | E18: 11 | F18: 4 | G18: 0 | H18: 0 | I18: 5 | J18: 1 | K18: 1 | L18: 2 | M18: 155 | N18: 0 | O18: =SUM(C18:L18,N18) -> 119 | P18: =SUM(C18:N18) -> 274 | R18: 1500-1600 | S18: =SUM(C42:C45) -> 414 | T18: =SUM(D42:D45) -> 203 | U18: =SUM(E42:E45) -> 44 | V18: =SUM(F42:F45) -> 16 | W18: =SUM(G42:G45) -> 1 | X18: =SUM(H42:H45) -> 2 | Y18: =SUM(I42:I45) -> 14 | Z18: =SUM(J42:J45) -> 8 | ... AF18: =SUM(P42:P45) -> 1588
B19: 09.15 - 09.30 | C19: 50 | D19: 26 | E19: 7 | F19: 1 | G19: 0 | H19: 0 | I19: 3 | J19: 4 | K19: 0 | L19: 0 | M19: 175 | N19: 0 | O19: =SUM(C19:L19,N19) -> 91 | P19: =SUM(C19:N19) -> 266 | R19: 1600-1700 | S19: =SUM(C46:C49) -> 475 | T19: =SUM(D46:D49) -> 239 | U19: =SUM(E46:E49) -> 51 | V19: =SUM(F46:F49) -> 28 | W19: =SUM(G46:G49) -> 0 | X19: =SUM(H46:H49) -> 0 | Y19: =SUM(I46:I49) -> 14 | Z19: =SUM(J46:J49) -> 2 | ... AF19: =SUM(P46:P49) -> 1460
B20: 09.30 - 09.45 | C20: 48 | D20: 35 | E20: 7 | F20: 4 | G20: 0 | H20: 0 | I20: 0 | J20: 2 | K20: 0 | L20: 0 | M20: 141 | N20: 0 | O20: =SUM(C20:L20,N20) -> 96 | P20: =SUM(C20:N20) -> 237 | R20: 1700-1800 | S20: =SUM(C50:C53) -> 490 | T20: =SUM(D50:D53) -> 202 | U20: =SUM(E50:E53) -> 47 | V20: =SUM(F50:F53) -> 7 | W20: =SUM(G50:G53) -> 2 | X20: =SUM(H50:H53) -> 0 | Y20: =SUM(I50:I53) -> 7 | Z20: =SUM(J50:J53) -> 7 | ... AF20: =SUM(P50:P53) -> 1710
B21: 09.45 - 10.00 | C21: 52 | D21: 22 | E21: 17 | F21: 4 | G21: 0 | H21: 0 | I21: 2 | J21: 2 | K21: 0 | L21: 2 | M21: 185 | N21: 0 | O21: =SUM(C21:L21,N21) -> 101 | P21: =SUM(C21:N21) -> 286 | R21: 1800-1900 | S21: =SUM(C54:C57) -> 448 | T21: =SUM(D54:D57) -> 236 | U21: =SUM(E54:E57) -> 49 | V21: =SUM(F54:F57) -> 22 | W21: =SUM(G54:G57) -> 0 | X21: =SUM(H54:H57) -> 0 | Y21: =SUM(I54:I57) -> 8 | Z21: =SUM(J54:J57) -> 5 | ... AF21: =SUM(P54:P57) -> 1262
B22: 10.00 - 10.15 | C22: 61 | D22: 36 | E22: 14 | F22: 4 | G22: 1 | H22: 0 | I22: 3 | J22: 1 | K22: 0 | L22: 1 | M22: 160 | N22: 0 | O22: =SUM(C22:L22,N22) -> 121 | P22: =SUM(C22:N22) -> 281 | R22: AM Peak Hr | S22: =MAX(S10:S12) -> 289 | T22: =MAX(T10:T12) -> 127 | U22: =MAX(U10:U12) -> 42 | V22: =MAX(V10:V12) -> 20 | W22: =MAX(W10:W12) -> 1 | X22: =MAX(X10:X12) -> 0 | Y22: =MAX(Y10:Y12) -> 10 | Z22: =MAX(Z10:Z12) -> 9 | ... AF22: =MAX(AF10:AF12) -> 1472
B23: 10.15 - 10.30 | C23: 55 | D23: 30 | E23: 11 | F23: 3 | G23: 0 | H23: 0 | I23: 2 | J23: 2 | K23: 1 | L23: 0 | M23: 125 | N23: 1 | O23: =SUM(C23:L23,N23) -> 105 | P23: =SUM(C23:N23) -> 230 | R23: IP Peak Hr | S23: =MAX(S13:S18) -> 414 | T23: =MAX(T13:T18) -> 203 | U23: =MAX(U13:U18) -> 57 | V23: =MAX(V13:V18) -> 20 | W23: =MAX(W13:W18) -> 4 | X23: =MAX(X13:X18) -> 2 | Y23: =MAX(Y13:Y18) -> 20 | Z23: =MAX(Z13:Z18) -> 11 | ... AF23: =MAX(AF13:AF18) -> 1588
B24: 10.30 - 10.45 | C24: 75 | D24: 52 | E24: 16 | F24: 9 | G24: 1 | H24: 0 | I24: 3 | J24: 4 | K24: 1 | L24: 2 | M24: 215 | N24: 0 | O24: =SUM(C24:L24,N24) -> 163 | P24: =SUM(C24:N24) -> 378 | R24: PM Peak Hr | S24: =MAX(S19:S21) -> 490 | T24: =MAX(T19:T21) -> 239 | U24: =MAX(U19:U21) -> 51 | V24: =MAX(V19:V21) -> 28 | W24: =MAX(W19:W21) -> 2 | X24: =MAX(X19:X21) -> 0 | Y24: =MAX(Y19:Y21) -> 14 | Z24: =MAX(Z19:Z21) -> 7 | ... AF24: =MAX(AF19:AF21) -> 1710
B25: 10.45 - 11.00 | C25: 62 | D25: 34 | E25: 12 | F25: 4 | G25: 2 | H25: 0 | I25: 1 | J25: 4 | K25: 0 | L25: 1 | M25: 230 | N25: 0 | O25: =SUM(C25:L25,N25) -> 120 | P25: =SUM(C25:N25) -> 350 | R25: AM Period | S25: =SUM(S10:S12) -> 776 | T25: =SUM(T10:T12) -> 350 | U25: =SUM(U10:U12) -> 111 | V25: =SUM(V10:V12) -> 39 | W25: =SUM(W10:W12) -> 2 | X25: =SUM(X10:X12) -> 0 | Y25: =SUM(Y10:Y12) -> 25 | Z25: =SUM(Z10:Z12) -> 18 | ... AF25: =SUM(AF10:AF12) -> 3615
B26: 11.00 - 11.15 | C26: 65 | D26: 40 | E26: 11 | F26: 5 | G26: 0 | H26: 0 | I26: 2 | J26: 3 | K26: 1 | L26: 1 | M26: 240 | N26: 0 | O26: =SUM(C26:L26,N26) -> 128 | P26: =SUM(C26:N26) -> 368 | R26: IP Period | S26: =SUM(S13:S18) -> 1894 | T26: =SUM(T13:T18) -> 1076 | U26: =SUM(U13:U18) -> 292 | V26: =SUM(V13:V18) -> 87 | W26: =SUM(W13:W18) -> 7 | X26: =SUM(X13:X18) -> 2 | Y26: =SUM(Y13:Y18) -> 78 | Z26: =SUM(Z13:Z18) -> 46 | ... AF26: =SUM(AF13:AF18) -> 7584
