Workbook

Sheet 12.08 Buwenge-Jinja
B1: Consultancy services for Preparation of Expressway Development Master Plan (EDMP) for Uganda
B2: MANUAL CLASSIFIED COUNT (MCC)
B3: ROAD NAME: | C3: MCC - C3b - STN93 - Jinja-Buwenge ROAD
C5: Date | D5: 12.08.19 | F5: Location | G5: xxx | J5: Surveyor | K5: xxx
C6: Dir. From | D6: Buwenge | F6: Dir. To | G6: Jinja | J6: Supervisor | K6: xxx
B8: Time / Veh Type | R8: SUMMARY TRAFFIC VOLUMES
C9: 1. Car | D9: 2. Station Wagon | E9: 3. Pickups | F9: 4. Minibus, matatu | G9: 5. Medium bus | H9: 6. Large Bus | I9: 7. Light Truck | J9: 8. Medium Truck | K9: 9. Heavy truck | L9: 10. Truck Trailer | M9: 11. Motor cycles | N9: 12. Tractors | O9: Total Excl M/Cycles | P9: Total All | R9: Time | S9: 1. Car | T9: 2. Station Wagon | U9: 3. Pickups | V9: 4. Minibus, matatu | W9: 5. Medium bus | X9: 6. Large Bus | Y9: 7. Light Truck | Z9: 8. Medium Truck | AA9: 9. Heavy truck | AB9: 10. Truck Trailer | AC9: 11. Motorcycles | AD9: 12. Tractors, Graders | AE9: Total Excl M/ Cycles | AF9: Total All
B10: 07.00 - 07.15 | C10: 3 | D10: 2 | E10: 2 | F10: 8 | G10: 6 | H10: 1 | I10: 4 | J10: 0 | K10: 0 | L10: =SUM('[1]RD4 MCC'!R54:U54) -> 0 | M10: 36 | N10: 0 | O10: =SUM(C10:L10,N10) -> 26 | P10: =SUM(C10:N10) -> 62 | R10: 0700-0800 | S10: =SUM(C10:C13) -> 12 | T10: =SUM(D10:D13) -> 5 | U10: =SUM(E10:E13) -> 7 | V10: =SUM(F10:F13) -> 42 | W10: =SUM(G10:G13) -> 17 | X10: =SUM(H10:H13) -> 1 | Y10: =SUM(I10:I13) -> 14 | Z10: =SUM(J10:J13) -> 0 | ... AF10: =SUM(P10:P13) -> 304
B11: 07.15 - 07.30 | C11: 2 | D11: 1 | E11: 2 | F11: 9 | G11: 1 | H11: 0 | I11: 4 | J11: 0 | K11: 0 | L11: =SUM('[1]RD4 MCC'!R55:U55) -> 0 | M11: 48 | N11: 0 | O11: =SUM(C11:L11,N11) -> 19 | P11: =SUM(C11:N11) -> 67 | R11: 0800-0900 | S11: =SUM(C14:C17) -> 27 | T11: =SUM(D14:D17) -> 4 | U11: =SUM(E14:E17) -> 4 | V11: =SUM(F14:F17) -> 41 | W11: =SUM(G14:G17) -> 14 | X11: =SUM(H14:H17) -> 1 | Y11: =SUM(I14:I17) -> 4 | Z11: =SUM(J14:J17) -> 0 | ... AF11: =SUM(P14:P17) -> 311
B12: 07.30 - 07.45 | C12: 3 | D12: 1 | E12: 1 | F12: 14 | G12: 6 | H12: 0 | I12: 5 | J12: 0 | K12: 0 | L12: =SUM('[1]RD4 MCC'!R56:U56) -> 0 | M12: 66 | N12: 0 | O12: =SUM(C12:L12,N12) -> 30 | P12: =SUM(C12:N12) -> 96 | R12: 0900-1000 | S12: =SUM(C18:C21) -> 14 | T12: =SUM(D18:D21) -> 4 | U12: =SUM(E18:E21) -> 7 | V12: =SUM(F18:F21) -> 46 | W12: =SUM(G18:G21) -> 3 | X12: =SUM(H18:H21) -> 1 | Y12: =SUM(I18:I21) -> 5 | Z12: =SUM(J18:J21) -> 0 | ... AF12: =SUM(P18:P21) -> 295
B13: 07.45 - 08.00 | C13: 4 | D13: 1 | E13: 2 | F13: 11 | G13: 4 | H13: 0 | I13: 1 | J13: 0 | K13: 0 | L13: =SUM('[1]RD4 MCC'!R57:U57) -> 0 | M13: 56 | N13: 0 | O13: =SUM(C13:L13,N13) -> 23 | P13: =SUM(C13:N13) -> 79 | R13: 1000-1100 | S13: =SUM(C22:C25) -> 16 | T13: =SUM(D22:D25) -> 5 | U13: =SUM(E22:E25) -> 6 | V13: =SUM(F22:F25) -> 45 | W13: =SUM(G22:G25) -> 0 | X13: =SUM(H22:H25) -> 0 | Y13: =SUM(I22:I25) -> 11 | Z13: =SUM(J22:J25) -> 0 | ... AF13: =SUM(P22:P25) -> 255
B14: 08.00 - 08.15 | C14: 6 | D14: 1 | E14: 1 | F14: 14 | G14: 5 | H14: 0 | I14: 1 | J14: 0 | K14: 0 | L14: =SUM('[1]RD4 MCC'!R58:U58) -> 0 | M14: 56 | N14: 0 | O14: =SUM(C14:L14,N14) -> 28 | P14: =SUM(C14:N14) -> 84 | R14: 1100-1200 | S14: =SUM(C26:C29) -> 24 | T14: =SUM(D26:D29) -> 8 | U14: =SUM(E26:E29) -> 9 | V14: =SUM(F26:F29) -> 46 | W14: =SUM(G26:G29) -> 1 | X14: =SUM(H26:H29) -> 0 | Y14: =SUM(I26:I29) -> 12 | Z14: =SUM(J26:J29) -> 0 | ... AF14: =SUM(P26:P29) -> 241
B15: 08.15 - 08.30 | C15: 4 | D15: 1 | E15: 1 | F15: 6 | G15: 2 | H15: 0 | I15: 1 | J15: 0 | K15: 0 | L15: =SUM('[1]RD4 MCC'!R59:U59) -> 0 | M15: 52 | N15: 1 | O15: =SUM(C15:L15,N15) -> 16 | P15: =SUM(C15:N15) -> 68 | R15: 1200-1300 | S15: =SUM(C30:C33) -> 21 | T15: =SUM(D30:D33) -> 8 | U15: =SUM(E30:E33) -> 9 | V15: =SUM(F30:F33) -> 33 | W15: =SUM(G30:G33) -> 3 | X15: =SUM(H30:H33) -> 0 | Y15: =SUM(I30:I33) -> 8 | Z15: =SUM(J30:J33) -> 2 | ... AF15: =SUM(P30:P33) -> 238
B16: 08.30 - 08.45 | C16: 11 | D16: 1 | E16: 1 | F16: 11 | G16: 4 | H16: 0 | I16: 1 | J16: 0 | K16: 0 | L16: =SUM('[1]RD4 MCC'!R60:U60) -> 0 | M16: 53 | N16: 0 | O16: =SUM(C16:L16,N16) -> 29 | P16: =SUM(C16:N16) -> 82 | R16: 1300-1400 | S16: =SUM(C34:C37) -> 15 | T16: =SUM(D34:D37) -> 14 | U16: =SUM(E34:E37) -> 15 | V16: =SUM(F34:F37) -> 49 | W16: =SUM(G34:G37) -> 5 | X16: =SUM(H34:H37) -> 0 | Y16: =SUM(I34:I37) -> 9 | Z16: =SUM(J34:J37) -> 2 | ... AF16: =SUM(P34:P37) -> 251
B17: 08.45 - 9.00 | C17: 6 | D17: 1 | E17: 1 | F17: 10 | G17: 3 | H17: 1 | I17: 1 | J17: 0 | K17: 0 | L17: =SUM('[1]RD4 MCC'!R61:U61) -> 0 | M17: 54 | N17: 0 | O17: =SUM(C17:L17,N17) -> 23 | P17: =SUM(C17:N17) -> 77 | R17: 1400-1500 | S17: =SUM(C38:C41) -> 19 | T17: =SUM(D38:D41) -> 13 | U17: =SUM(E38:E41) -> 16 | V17: =SUM(F38:F41) -> 47 | W17: =SUM(G38:G41) -> 7 | X17: =SUM(H38:H41) -> 0 | Y17: =SUM(I38:I41) -> 8 | Z17: =SUM(J38:J41) -> 1 | ... AF17: =SUM(P38:P41) -> 292
B18: 09.00 - 09.15 | C18: 1 | D18: 0 | E18: 1 | F18: 14 | G18: 2 | H18: 0 | I18: 0 | J18: 0 | K18: 0 | L18: =SUM('[1]RD4 MCC'!R62:U62) -> 0 | M18: 49 | N18: 0 | O18: =SUM(C18:L18,N18) -> 18 | P18: =SUM(C18:N18) -> 67 | R18: 1500-1600 | S18: =SUM(C42:C45) -> 30 | T18: =SUM(D42:D45) -> 34 | U18: =SUM(E42:E45) -> 38 | V18: =SUM(F42:F45) -> 49 | W18: =SUM(G42:G45) -> 12 | X18: =SUM(H42:H45) -> 1 | Y18: =SUM(I42:I45) -> 19 | Z18: =SUM(J42:J45) -> 2 | ... AF18: =SUM(P42:P45) -> 266
B19: 09.15 - 09.30 | C19: 2 | D19: 2 | E19: 3 | F19: 15 | G19: 0 | H19: 1 | I19: 3 | J19: 0 | K19: 0 | L19: =SUM('[1]RD4 MCC'!R63:U63) -> 0 | M19: 48 | N19: 0 | O19: =SUM(C19:L19,N19) -> 26 | P19: =SUM(C19:N19) -> 74 | R19: 1600-1700 | S19: =SUM(C46:C49) -> 55 | T19: =SUM(D46:D49) -> 46 | U19: =SUM(E46:E49) -> 47 | V19: =SUM(F46:F49) -> 54 | W19: =SUM(G46:G49) -> 11 | X19: =SUM(H46:H49) -> 1 | Y19: =SUM(I46:I49) -> 15 | Z19: =SUM(J46:J49) -> 0 | ... AF19: =SUM(P46:P49) -> 324
B20: 09.30 - 09.45 | C20: 7 | D20: 1 | E20: 2 | F20: 9 | G20: 1 | H20: 0 | I20: 0 | J20: 0 | K20: 0 | L20: =SUM('[1]RD4 MCC'!R64:U64) -> 0 | M20: 58 | N20: 0 | O20: =SUM(C20:L20,N20) -> 20 | P20: =SUM(C20:N20) -> 78 | R20: 1700-1800 | S20: =SUM(C50:C53) -> 53 | T20: =SUM(D50:D53) -> 27 | U20: =SUM(E50:E53) -> 30 | V20: =SUM(F50:F53) -> 51 | W20: =SUM(G50:G53) -> 14 | X20: =SUM(H50:H53) -> 1 | Y20: =SUM(I50:I53) -> 16 | Z20: =SUM(J50:J53) -> 1 | ... AF20: =SUM(P50:P53) -> 409
B21: 09.45 - 10.00 | C21: 4 | D21: 1 | E21: 1 | F21: 8 | G21: 0 | H21: 0 | I21: 2 | J21: 0 | K21: 0 | L21: =SUM('[1]RD4 MCC'!R65:U65) -> 0 | M21: 60 | N21: 0 | O21: =SUM(C21:L21,N21) -> 16 | P21: =SUM(C21:N21) -> 76 | R21: 1800-1900 | S21: =SUM(C54:C57) -> 44 | T21: =SUM(D54:D57) -> 18 | U21: =SUM(E54:E57) -> 21 | V21: =SUM(F54:F57) -> 54 | W21: =SUM(G54:G57) -> 21 | X21: =SUM(H54:H57) -> 1 | Y21: =SUM(I54:I57) -> 9 | Z21: =SUM(J54:J57) -> 1 | ... AF21: =SUM(P54:P57) -> 350
B22: 10.00 - 10.15 | C22: 6 | D22: 2 | E22: 2 | F22: 14 | G22: 0 | H22: 0 | I22: 1 | J22: 0 | K22: 0 | L22: =SUM('[1]RD4 MCC'!R66:U66) -> 0 | M22: 41 | N22: 0 | O22: =SUM(C22:L22,N22) -> 25 | P22: =SUM(C22:N22) -> 66 | R22: AM Peak Hr | S22: =MAX(S10:S12) -> 27 | T22: =MAX(T10:T12) -> 5 | U22: =MAX(U10:U12) -> 7 | V22: =MAX(V10:V12) -> 46 | W22: =MAX(W10:W12) -> 17 | X22: =MAX(X10:X12) -> 1 | Y22: =MAX(Y10:Y12) -> 14 | Z22: =MAX(Z10:Z12) -> 0 | ... AF22: =MAX(AF10:AF12) -> 311
B23: 10.15 - 10.30 | C23: 3 | D23: 1 | E23: 1 | F23: 9 | G23: 0 | H23: 0 | I23: 5 | J23: 0 | K23: 0 | L23: =SUM('[1]RD4 MCC'!R67:U67) -> 0 | M23: 44 | N23: 0 | O23: =SUM(C23:L23,N23) -> 19 | P23: =SUM(C23:N23) -> 63 | R23: IP Peak Hr | S23: =MAX(S13:S18) -> 30 | T23: =MAX(T13:T18) -> 34 | U23: =MAX(U13:U18) -> 38 | V23: =MAX(V13:V18) -> 49 | W23: =MAX(W13:W18) -> 12 | X23: =MAX(X13:X18) -> 1 | Y23: =MAX(Y13:Y18) -> 19 | Z23: =MAX(Z13:Z18) -> 2 | ... AF23: =MAX(AF13:AF18) -> 292
B24: 10.30 - 10.45 | C24: 1 | D24: 2 | E24: 2 | F24: 12 | G24: 0 | H24: 0 | I24: 3 | J24: 0 | K24: 0 | L24: =SUM('[1]RD4 MCC'!R68:U68) -> 0 | M24: 42 | N24: 0 | O24: =SUM(C24:L24,N24) -> 20 | P24: =SUM(C24:N24) -> 62 | R24: PM Peak Hr | S24: =MAX(S19:S21) -> 55 | T24: =MAX(T19:T21) -> 46 | U24: =MAX(U19:U21) -> 47 | V24: =MAX(V19:V21) -> 54 | W24: =MAX(W19:W21) -> 21 | X24: =MAX(X19:X21) -> 1 | Y24: =MAX(Y19:Y21) -> 16 | Z24: =MAX(Z19:Z21) -> 1 | ... AF24: =MAX(AF19:AF21) -> 409
B25: 10.45 - 11.00 | C25: 6 | D25: 0 | E25: 1 | F25: 10 | G25: 0 | H25: 0 | I25: 2 | J25: 0 | K25: 0 | L25: =SUM('[1]RD4 MCC'!R69:U69) -> 0 | M25: 45 | N25: 0 | O25: =SUM(C25:L25,N25) -> 19 | P25: =SUM(C25:N25) -> 64 | R25: AM Period | S25: =SUM(S10:S12) -> 53 | T25: =SUM(T10:T12) -> 13 | U25: =SUM(U10:U12) -> 18 | V25: =SUM(V10:V12) -> 129 | W25: =SUM(W10:W12) -> 34 | X25: =SUM(X10:X12) -> 3 | Y25: =SUM(Y10:Y12) -> 23 | Z25: =SUM(Z10:Z12) -> 0 | ... AF25: =SUM(AF10:AF12) -> 910
B26: 11.00 - 11.15 | C26: 8 | D26: 1 | E26: 2 | F26: 12 | G26: 0 | H26: 0 | I26: 4 | J26: 0 | K26: 0 | L26: =SUM('[1]RD4 MCC'!R70:U70) -> 0 | M26: 35 | N26: 0 | O26: =SUM(C26:L26,N26) -> 27 | P26: =SUM(C26:N26) -> 62 | R26: IP Period | S26: =SUM(S13:S18) -> 125 | T26: =SUM(T13:T18) -> 82 | U26: =SUM(U13:U18) -> 93 | V26: =SUM(V13:V18) -> 269 | W26: =SUM(W13:W18) -> 28 | X26: =SUM(X13:X18) -> 1 | Y26: =SUM(Y13:Y18) -> 67 | Z26: =SUM(Z13:Z18) -> 7 | ... AF26: =SUM(AF13:AF18) -> 1543
B27: 11.15 - 11.30 | C27: 6 | D27: 1 | E27: 1 | F27: 13 | G27: 0 | H27: 0 | I27: 1 | J27: 0 | K27: 0 | L27: =SUM('[1]RD4 MCC'!R71:U71) -> 0 | M27: 36 | N27: 0 | O27: =SUM(C27:L27,N27) -> 22 | P27: =SUM(C27:N27) -> 58 | R27: PM Period | S27: =SUM(S19:S21) -> 152 | T27: =SUM(T19:T21) -> 91 | U27: =SUM(U19:U21) -> 98 | V27: =SUM(V19:V21) -> 159 | W27: =SUM(W19:W21) -> 46 | X27: =SUM(X19:X21) -> 3 | Y27: =SUM(Y19:Y21) -> 40 | Z27: =SUM(Z19:Z21) -> 2 | ... AF27: =SUM(AF19:AF21) -> 1083
B28: 11.30 - 11.45 | C28: 2 | D28: 3 | E28: 3 | F28: 11 | G28: 1 | H28: 0 | I28: 3 | J28: 0 | K28: 0 | L28: =SUM('[1]RD4 MCC'!R72:U72) -> 0 | M28: 35 | N28: 0 | O28: =SUM(C28:L28,N28) -> 23 | P28: =SUM(C28:N28) -> 58 | R28: 12 Hours | S28: =SUM(S10:S21) -> 330 | T28: =SUM(T10:T21) -> 186 | U28: =SUM(U10:U21) -> 209 | V28: =SUM(V10:V21) -> 557 | W28: =SUM(W10:W21) -> 108 | X28: =SUM(X10:X21) -> 7 | Y28: =SUM(Y10:Y21) -> 130 | Z28: =SUM(Z10:Z21) -> 9 | ... AF28: =SUM(AF10:AF21) -> 3536
B29: 11.45 - 12.00 | C29: 8 | D29: 3 | E29: 3 | F29: 10 | G29: 0 | H29: 0 | I29: 4 | J29: 0 | K29: 0 | L29: =SUM('[1]RD4 MCC'!R73:U73) -> 0 | M29: 35 | N29: 0 | O29: =SUM(C29:L29,N29) -> 28 | P29: =SUM(C29:N29) -> 63
B30: 12.00 - 12.15 | C30: 6 | D30: 4 | E30: 4 | F30: 7 | G30: 0 | H30: 0 | I30: 2 | J30: 0 | K30: 0 | L30: =SUM('[1]RD4 MCC'!R74:U74) -> 0 | M30: 41 | N30: 0 | O30: =SUM(C30:L30,N30) -> 23 | P30: =SUM(C30:N30) -> 64
B31: 12.15 - 12.30 | C31: 3 | D31: 1 | E31: 2 | F31: 9 | G31: 2 | H31: 0 | I31: 2 | J31: 0 | K31: 0 | L31: =SUM('[1]RD4 MCC'!R75:U75) -> 0 | M31: 44 | N31: 0 | O31: =SUM(C31:L31,N31) -> 19 | P31: =SUM(C31:N31) -> 63
B32: 12.30 - 12.45 | C32: 7 | D32: 2 | E32: 2 | F32: 9 | G32: 1 | H32: 0 | I32: 3 | J32: 1 | K32: 0 | L32: =SUM('[1]RD4 MCC'!R76:U76) -> 0 | M32: 41 | N32: 1 | O32: =SUM(C32:L32,N32) -> 26 | P32: =SUM(C32:N32) -> 67
B33: 12.45 - 13.00 | C33: 5 | D33: 1 | E33: 1 | F33: 8 | G33: 0 | H33: 0 | I33: 1 | J33: 1 | K33: 0 | L33: =SUM('[1]RD4 MCC'!R77:U77) -> 0 | M33: 27 | N33: 0 | O33: =SUM(C33:L33,N33) -> 17 | P33: =SUM(C33:N33) -> 44
B34: 13.00 - 13.15 | C34: 3 | D34: 1 | E34: 2 | F34: 13 | G34: 2 | H34: 0 | I34: 2 | J34: 1 | K34: 0 | L34: =SUM('[1]RD4 MCC'!R78:U78) -> 0 | M34: 36 | N34: 0 | O34: =SUM(C34:L34,N34) -> 24 | P34: =SUM(C34:N34) -> 60
B35: 13.15 - 13.30 | C35: 3 | D35: 4 | E35: 4 | F35: 9 | G35: 1 | H35: 0 | I35: 0 | J35: 0 | K35: 0 | L35: =SUM('[1]RD4 MCC'!R79:U79) -> 0 | M35: 26 | N35: 0 | O35: =SUM(C35:L35,N35) -> 21 | P35: =SUM(C35:N35) -> 47
B36: 13.30 - 13.45 | C36: 2 | D36: 3 | E36: 3 | F36: 16 | G36: 1 | H36: 0 | I36: 1 | J36: 0 | K36: 0 | L36: =SUM('[1]RD4 MCC'!R80:U80) -> 0 | M36: 39 | N36: 0 | O36: =SUM(C36:L36,N36) -> 26 | P36: =SUM(C36:N36) -> 65
B37: 13.45 - 14.00 | C37: 7 | D37: 6 | E37: 6 | F37: 11 | G37: 1 | H37: 0 | I37: 6 | J37: 1 | K37: 0 | L37: =SUM('[1]RD4 MCC'!R81:U81) -> 0 | M37: 41 | N37: 0 | O37: =SUM(C37:L37,N37) -> 38 | P37: =SUM(C37:N37) -> 79
B38: 14.00 - 14.15 | C38: 4 | D38: 2 | E38: 3 | F38: 12 | G38: 3 | H38: 0 | I38: 0 | J38: 1 | K38: 0 | L38: =SUM('[1]RD4 MCC'!R82:U82) -> 0 | M38: 47 | N38: 0 | O38: =SUM(C38:L38,N38) -> 25 | P38: =SUM(C38:N38) -> 72
B39: 14.15 - 14.30 | C39: 5 | D39: 6 | E39: 6 | F39: 10 | G39: 0 | H39: 0 | I39: 2 | J39: 0 | K39: 0 | L39: =SUM('[1]RD4 MCC'!R83:U83) -> 0 | M39: 39 | N39: 0 | O39: =SUM(C39:L39,N39) -> 29 | P39: =SUM(C39:N39) -> 68
B40: 14.30 - 14.45 | C40: 5 | D40: 2 | E40: 3 | F40: 12 | G40: 2 | H40: 0 | I40: 1 | J40: 0 | K40: 0 | L40: =SUM('[1]RD4 MCC'!R84:U84) -> 0 | M40: 50 | N40: 0 | O40: =SUM(C40:L40,N40) -> 25 | P40: =SUM(C40:N40) -> 75
... B57: 18.45 - 19.00 | C57: 7 | D57: 4 | E57: 5 | F57: 15 | G57: 6 | H57: 0 | I57: 3 | J57: 0 | K57: 0 | L57: =SUM('[1]RD4 MCC'!R101:U101) -> 0 | M57: 41 | N57: 0 | O57: =SUM(C57:L57,N57) -> 40 | P57: =SUM(C57:N57) -> 81
B58: Totals | C58: =SUM(C10:C57) -> 330 | D58: =SUM(D10:D57) -> 186 | E58: =SUM(E10:E57) -> 209 | F58: =SUM(F10:F57) -> 557 | G58: =SUM(G10:G57) -> 108 | H58: =SUM(H10:H57) -> 7 | I58: =SUM(I10:I57) -> 130 | J58: =SUM(J10:J57) -> 9 | ... P58: =SUM(P10:P57) -> 3536
...

Sheet 12.08 Jinja-Buwenge
B1: Consultancy services for Preparation of Expressway Development Master Plan (EDMP) for Uganda
B2: MANUAL CLASSIFIED COUNT (MCC)
B3: ROAD NAME: | C3: ='12.08 Buwenge-Jinja'!C3:G3 -> MCC - C3b - STN93 - Jinja-Buwenge ROAD
C5: Date | D5: ='12.08 Buwenge-Jinja'!D5 -> 12.08.19 | F5: Location | G5: ='12.08 Buwenge-Jinja'!G5:H5 -> xxx | J5: Surveyor | K5: ='12.08 Buwenge-Jinja'!K5:L5 -> xxx
C6: Dir. From | D6: Jinja | F6: Dir. To | G6: Buwenge | J6: Supervisor | K6: ='12.08 Buwenge-Jinja'!K6:L6 -> xxx
B8: Time / Veh Type | R8: SUMMARY TRAFFIC VOLUMES
C9: 1. Car | D9: 2. Station Wagon | E9: 3. Pickups | F9: 4. Minibus, matatu | G9: 5. Medium bus | H9: 6. Large Bus | I9: 7. Light Truck | J9: 8. Medium Truck | K9: 9. Heavy truck | L9: 10. Truck Trailer | M9: 11. Motor cycles | N9: 12. Tractors | O9: Total Excl M/Cycles | P9: Total All | R9: Time | S9: 1. Car | T9: 2. Station Wagon | U9: 3. Pickups | V9: 4. Minibus, matatu | W9: 5. Medium bus | X9: 6. Large Bus | Y9: 7. Light Truck | Z9: 8. Medium Truck | AA9: 9. Heavy truck | AB9: 10. Truck Trailer | AC9: 11. Motorcycles | AD9: 12. Tractors, Graders | AE9: Total Excl M/ Cycles | AF9: Total All
B10: 07.00 - 07.15 | C10: 1 | D10: 0 | E10: 2 | F10: 5 | G10: 1 | H10: 0 | I10: 1 | J10: 2 | K10: 0 | L10: =SUM('[1]RD4 MCC'!R6:U6) -> 0 | M10: 18 | N10: 0 | O10: =SUM(C10:L10,N10) -> 12 | P10: =SUM(C10:N10) -> 30 | R10: 0700-0800 | S10: =SUM(C10:C13) -> 22 | T10: =SUM(D10:D13) -> 2 | U10: =SUM(E10:E13) -> 14 | V10: =SUM(F10:F13) -> 37 | W10: =SUM(G10:G13) -> 16 | X10: =SUM(H10:H13) -> 0 | Y10: =SUM(I10:I13) -> 8 | Z10: =SUM(J10:J13) -> 5 | ... AF10: =SUM(P10:P13) -> 205
B11: 07.15 - 07.30 | C11: 4 | D11: 1 | E11: 4 | F11: 11 | G11: 6 | H11: 0 | I11: 1 | J11: 2 | K11: 0 | L11: =SUM('[1]RD4 MCC'!R7:U7) -> 0 | M11: 21 | N11: 0 | O11: =SUM(C11:L11,N11) -> 29 | P11: =SUM(C11:N11) -> 50 | R11: 0800-0900 | S11: =SUM(C14:C17) -> 35 | T11: =SUM(D14:D17) -> 12 | U11: =SUM(E14:E17) -> 35 | V11: =SUM(F14:F17) -> 40 | W11: =SUM(G14:G17) -> 14 | X11: =SUM(H14:H17) -> 1 | Y11: =SUM(I14:I17) -> 10 | Z11: =SUM(J14:J17) -> 2 | ... AF11: =SUM(P14:P17) -> 265
B12: 07.30 - 07.45 | C12: 8 | D12: 0 | E12: 3 | F12: 8 | G12: 6 | H12: 0 | I12: 5 | J12: 1 | K12: 0 | L12: =SUM('[1]RD4 MCC'!R8:U8) -> 0 | M12: 27 | N12: 0 | O12: =SUM(C12:L12,N12) -> 31 | P12: =SUM(C12:N12) -> 58 | R12: 0900-1000 | S12: =SUM(C18:C21) -> 32 | T12: =SUM(D18:D21) -> 16 | U12: =SUM(E18:E21) -> 42 | V12: =SUM(F18:F21) -> 59 | W12: =SUM(G18:G21) -> 9 | X12: =SUM(H18:H21) -> 0 | Y12: =SUM(I18:I21) -> 10 | Z12: =SUM(J18:J21) -> 0 | ... AF12: =SUM(P18:P21) -> 335
B13: 07.45 - 08.00 | C13: 9 | D13: 1 | E13: 5 | F13: 13 | G13: 3 | H13: 0 | I13: 1 | J13: 0 | K13: 0 | L13: =SUM('[1]RD4 MCC'!R9:U9) -> 0 | M13: 35 | N13: 0 | O13: =SUM(C13:L13,N13) -> 32 | P13: =SUM(C13:N13) -> 67 | R13: 1000-1100 | S13: =SUM(C22:C25) -> 37 | T13: =SUM(D22:D25) -> 13 | U13: =SUM(E22:E25) -> 37 | V13: =SUM(F22:F25) -> 62 | W13: =SUM(G22:G25) -> 5 | X13: =SUM(H22:H25) -> 2 | Y13: =SUM(I22:I25) -> 19 | Z13: =SUM(J22:J25) -> 2 | ... AF13: =SUM(P22:P25) -> 340
B14: 08.00 - 08.15 | C14: 13 | D14: 4 | E14: 11 | F14: 10 | G14: 5 | H14: 0 | I14: 3 | J14: 0 | K14: 0 | L14: =SUM('[1]RD4 MCC'!R10:U10) -> 0 | M14: 15 | N14: 0 | O14: =SUM(C14:L14,N14) -> 46 | P14: =SUM(C14:N14) -> 61 | R14: 1100-1200 | S14: =SUM(C26:C29) -> 50 | T14: =SUM(D26:D29) -> 15 | U14: =SUM(E26:E29) -> 43 | V14: =SUM(F26:F29) -> 66 | W14: =SUM(G26:G29) -> 3 | X14: =SUM(H26:H29) -> 0 | Y14: =SUM(I26:I29) -> 15 | Z14: =SUM(J26:J29) -> 4 | ... AF14: =SUM(P26:P29) -> 385
B15: 08.15 - 08.30 | C15: 6 | D15: 3 | E15: 8 | F15: 7 | G15: 4 | H15: 0 | I15: 2 | J15: 2 | K15: 0 | L15: =SUM('[1]RD4 MCC'!R11:U11) -> 0 | M15: 46 | N15: 0 | O15: =SUM(C15:L15,N15) -> 32 | P15: =SUM(C15:N15) -> 78 | R15: 1200-1300 | S15: =SUM(C30:C33) -> 34 | T15: =SUM(D30:D33) -> 8 | U15: =SUM(E30:E33) -> 23 | V15: =SUM(F30:F33) -> 58 | W15: =SUM(G30:G33) -> 7 | X15: =SUM(H30:H33) -> 0 | Y15: =SUM(I30:I33) -> 14 | Z15: =SUM(J30:J33) -> 0 | ... AF15: =SUM(P30:P33) -> 321
B16: 08.30 - 08.45 | C16: 9 | D16: 2 | E16: 6 | F16: 12 | G16: 3 | H16: 0 | I16: 4 | J16: 0 | K16: 0 | L16: =SUM('[1]RD4 MCC'!R12:U12) -> 0 | M16: 27 | N16: 0 | O16: =SUM(C16:L16,N16) -> 36 | P16: =SUM(C16:N16) -> 63 | R16: 1300-1400 | S16: =SUM(C34:C37) -> 30 | T16: =SUM(D34:D37) -> 5 | U16: =SUM(E34:E37) -> 16 | V16: =SUM(F34:F37) -> 67 | W16: =SUM(G34:G37) -> 7 | X16: =SUM(H34:H37) -> 1 | Y16: =SUM(I34:I37) -> 12 | Z16: =SUM(J34:J37) -> 2 | ... AF16: =SUM(P34:P37) -> 328
B17: 08.45 - 9.00 | C17: 7 | D17: 3 | E17: 10 | F17: 11 | G17: 2 | H17: 1 | I17: 1 | J17: 0 | K17: 0 | L17: =SUM('[1]RD4 MCC'!R13:U13) -> 0 | M17: 28 | N17: 0 | O17: =SUM(C17:L17,N17) -> 35 | P17: =SUM(C17:N17) -> 63 | R17: 1400-1500 | S17: =SUM(C38:C41) -> 32 | T17: =SUM(D38:D41) -> 5 | U17: =SUM(E38:E41) -> 19 | V17: =SUM(F38:F41) -> 49 | W17: =SUM(G38:G41) -> 4 | X17: =SUM(H38:H41) -> 2 | Y17: =SUM(I38:I41) -> 15 | Z17: =SUM(J38:J41) -> 3 | ... AF17: =SUM(P38:P41) -> 332
B18: 09.00 - 09.15 | C18: 4 | D18: 2 | E18: 7 | F18: 14 | G18: 4 | H18: 0 | I18: 4 | J18: 0 | K18: 0 | L18: =SUM('[1]RD4 MCC'!R14:U14) -> 0 | M18: 38 | N18: 0 | O18: =SUM(C18:L18,N18) -> 35 | P18: =SUM(C18:N18) -> 73 | R18: 1500-1600 | S18: =SUM(C42:C45) -> 31 | T18: =SUM(D42:D45) -> 4 | U18: =SUM(E42:E45) -> 17 | V18: =SUM(F42:F45) -> 45 | W18: =SUM(G42:G45) -> 5 | X18: =SUM(H42:H45) -> 0 | Y18: =SUM(I42:I45) -> 14 | Z18: =SUM(J42:J45) -> 0 | ... AF18: =SUM(P42:P45) -> 258
B19: 09.15 - 09.30 | C19: 10 | D19: 3 | E19: 8 | F19: 12 | G19: 3 | H19: 0 | I19: 3 | J19: 0 | K19: 0 | L19: =SUM('[1]RD4 MCC'!R15:U15) -> 0 | M19: 47 | N19: 0 | O19: =SUM(C19:L19,N19) -> 39 | P19: =SUM(C19:N19) -> 86 | R19: 1600-1700 | S19: =SUM(C46:C49) -> 27 | T19: =SUM(D46:D49) -> 3 | U19: =SUM(E46:E49) -> 16 | V19: =SUM(F46:F49) -> 50 | W19: =SUM(G46:G49) -> 3 | X19: =SUM(H46:H49) -> 0 | Y19: =SUM(I46:I49) -> 15 | Z19: =SUM(J46:J49) -> 1 | ... AF19: =SUM(P46:P49) -> 260
B20: 09.30 - 09.45 | C20: 6 | D20: 9 | E20: 21 | F20: 16 | G20: 1 | H20: 0 | I20: 0 | J20: 0 | K20: 0 | L20: =SUM('[1]RD4 MCC'!R16:U16) -> 0 | M20: 37 | N20: 0 | O20: =SUM(C20:L20,N20) -> 53 | P20: =SUM(C20:N20) -> 90 | R20: 1700-1800 | S20: =SUM(C50:C53) -> 23 | T20: =SUM(D50:D53) -> 1 | U20: =SUM(E50:E53) -> 11 | V20: =SUM(F50:F53) -> 37 | W20: =SUM(G50:G53) -> 7 | X20: =SUM(H50:H53) -> 1 | Y20: =SUM(I50:I53) -> 12 | Z20: =SUM(J50:J53) -> 1 | ... AF20: =SUM(P50:P53) -> 238
B21: 09.45 - 10.00 | C21: 12 | D21: 2 | E21: 6 | F21: 17 | G21: 1 | H21: 0 | I21: 3 | J21: 0 | K21: 0 | L21: =SUM('[1]RD4 MCC'!R17:U17) -> 0 | M21: 45 | N21: 0 | O21: =SUM(C21:L21,N21) -> 41 | P21: =SUM(C21:N21) -> 86 | R21: 1800-1900 | S21: =SUM(C54:C57) -> 25 | T21: =SUM(D54:D57) -> 3 | U21: =SUM(E54:E57) -> 16 | V21: =SUM(F54:F57) -> 40 | W21: =SUM(G54:G57) -> 16 | X21: =SUM(H54:H57) -> 0 | Y21: =SUM(I54:I57) -> 13 | Z21: =SUM(J54:J57) -> 1 | ... AF21: =SUM(P54:P57) -> 293
B22: 10.00 - 10.15 | C22: 9 | D22: 4 | E22: 10 | F22: 17 | G22: 1 | H22: 1 | I22: 3 | J22: 1 | K22: 0 | L22: =SUM('[1]RD4 MCC'!R18:U18) -> 0 | M22: 37 | N22: 0 | O22: =SUM(C22:L22,N22) -> 46 | P22: =SUM(C22:N22) -> 83 | R22: AM Peak Hr | S22: =MAX(S10:S12) -> 35 | T22: =MAX(T10:T12) -> 16 | U22: =MAX(U10:U12) -> 42 | V22: =MAX(V10:V12) -> 59 | W22: =MAX(W10:W12) -> 16 | X22: =MAX(X10:X12) -> 1 | Y22: =MAX(Y10:Y12) -> 10 | Z22: =MAX(Z10:Z12) -> 5 | ... AF22: =MAX(AF10:AF12) -> 335
B23: 10.15 - 10.30 | C23: 10 | D23: 3 | E23: 10 | F23: 17 | G23: 1 | H23: 0 | I23: 5 | J23: 0 | K23: 0 | L23: =SUM('[1]RD4 MCC'!R19:U19) -> 0 | M23: 43 | N23: 0 | O23: =SUM(C23:L23,N23) -> 46 | P23: =SUM(C23:N23) -> 89 | R23: IP Peak Hr | S23: =MAX(S13:S18) -> 50 | T23: =MAX(T13:T18) -> 15 | U23: =MAX(U13:U18) -> 43 | V23: =MAX(V13:V18) -> 67 | W23: =MAX(W13:W18) -> 7 | X23: =MAX(X13:X18) -> 2 | Y23: =MAX(Y13:Y18) -> 19 | Z23: =MAX(Z13:Z18) -> 4 | ... AF23: =MAX(AF13:AF18) -> 385
B24: 10.30 - 10.45 | C24: 7 | D24: 2 | E24: 5 | F24: 15 | G24: 0 | H24: 1 | I24: 7 | J24: 1 | K24: 0 | L24: =SUM('[1]RD4 MCC'!R20:U20) -> 0 | M24: 34 | N24: 0 | O24: =SUM(C24:L24,N24) -> 38 | P24: =SUM(C24:N24) -> 72 | R24: PM Peak Hr | S24: =MAX(S19:S21) -> 27 | T24: =MAX(T19:T21) -> 3 | U24: =MAX(U19:U21) -> 16 | V24: =MAX(V19:V21) -> 50 | W24: =MAX(W19:W21) -> 16 | X24: =MAX(X19:X21) -> 1 | Y24: =MAX(Y19:Y21) -> 15 | Z24: =MAX(Z19:Z21) -> 1 | ... AF24: =MAX(AF19:AF21) -> 293
B25: 10.45 - 11.00 | C25: 11 | D25: 4 | E25: 12 | F25: 13 | G25: 3 | H25: 0 | I25: 4 | J25: 0 | K25: 0 | L25: =SUM('[1]RD4 MCC'!R21:U21) -> 0 | M25: 49 | N25: 0 | O25: =SUM(C25:L25,N25) -> 47 | P25: =SUM(C25:N25) -> 96 | R25: AM Period | S25: =SUM(S10:S12) -> 89 | T25: =SUM(T10:T12) -> 30 | U25: =SUM(U10:U12) -> 91 | V25: =SUM(V10:V12) -> 136 | W25: =SUM(W10:W12) -> 39 | X25: =SUM(X10:X12) -> 1 | Y25: =SUM(Y10:Y12) -> 28 | Z25: =SUM(Z10:Z12) -> 7 | ... AF25: =SUM(AF10:AF12) -> 805
B26: 11.00 - 11.15 | C26: 15 | D26: 4 | E26: 12 | F26: 14 | G26: 1 | H26: 0 | I26: 3 | J26: 0 | K26: 0 | L26: =SUM('[1]RD4 MCC'!R22:U22) -> 0 | M26: 35 | N26: 1 | O26: =SUM(C26:L26,N26) -> 50 | P26: =SUM(C26:N26) -> 85 | R26: IP Period | S26: =SUM(S13:S18) -> 214 | T26: =SUM(T13:T18) -> 50 | U26: =SUM(U13:U18) -> 155 | V26: =SUM(V13:V18) -> 347 | W26: =SUM(W13:W18) -> 31 | X26: =SUM(X13:X18) -> 5 | Y26: =SUM(Y13:Y18) -> 89 | Z26: =SUM(Z13:Z18) -> 11 | ... AF26: =SUM(AF13:AF18) -> 1964
B27: 11.15 - 11.30 | C27: 12 | D27: 3 | E27: 7 | F27: 16 | G27: 1 | H27: 0 | I27: 5 | J27: 2 | K27: 0 | L27: =SUM('[1]RD4 MCC'!R23:U23) -> 0 | M27: 49 | N27: 0 | O27: =SUM(C27:L27,N27) -> 46 | P27: =SUM(C27:N27) -> 95 | R27: PM Period | S27: =SUM(S19:S21) -> 75 | T27: =SUM(T19:T21) -> 7 | U27: =SUM(U19:U21) -> 43 | V27: =SUM(V19:V21) -> 127 | W27: =SUM(W19:W21) -> 26 | X27: =SUM(X19:X21) -> 1 | Y27: =SUM(Y19:Y21) -> 40 | Z27: =SUM(Z19:Z21) -> 3 | ... AF27: =SUM(AF19:AF21) -> 791
B28: 11.30 - 11.45 | C28: 16 | D28: 2 | E28: 7 | F28: 16 | G28: 0 | H28: 0 | I28: 3 | J28: 1 | K28: 0 | L28: =SUM('[1]RD4 MCC'!R24:U24) -> 0 | M28: 43 | N28: 0 | O28: =SUM(C28:L28,N28) -> 45 | P28: =SUM(C28:N28) -> 88 | R28: 12 Hours | S28: =SUM(S10:S21) -> 378 | T28: =SUM(T10:T21) -> 87 | U28: =SUM(U10:U21) -> 289 | V28: =SUM(V10:V21) -> 610 | W28: =SUM(W10:W21) -> 96 | X28: =SUM(X10:X21) -> 7 | Y28: =SUM(Y10:Y21) -> 157 | Z28: =SUM(Z10:Z21) -> 21 | ... AF28: =SUM(AF10:AF21) -> 3560
B29: 11.45 - 12.00 | C29: 7 | D29: 6 | E29: 17 | F29: 20 | G29: 1 | H29: 0 | I29: 4 | J29: 1 | K29: 0 | L29: =SUM('[1]RD4 MCC'!R25:U25) -> 0 | M29: 60 | N29: 1 | O29: =SUM(C29:L29,N29) -> 57 | P29: =SUM(C29:N29) -> 117
B30: 12.00 - 12.15 | C30: 13 | D30: 3 | E30: 8 | F30: 19 | G30: 0 | H30: 0 | I30: 5 | J30: 0 | K30: 0 | L30: =SUM('[1]RD4 MCC'!R26:U26) -> 0 | M30: 36 | N30: 0 | O30: =SUM(C30:L30,N30) -> 48 | P30: =SUM(C30:N30) -> 84
B31: 12.15 - 12.30 | C31: 7 | D31: 2 | E31: 5 | F31: 15 | G31: 2 | H31: 0 | I31: 2 | J31: 0 | K31: 0 | L31: =SUM('[1]RD4 MCC'!R27:U27) -> 0 | M31: 42 | N31: 0 | O31: =SUM(C31:L31,N31) -> 33 | P31: =SUM(C31:N31) -> 75
B32: 12.30 - 12.45 | C32: 7 | D32: 1 | E32: 5 | F32: 13 | G32: 4 | H32: 0 | I32: 3 | J32: 0 | K32: 0 | L32: =SUM('[1]RD4 MCC'!R28:U28) -> 0 | M32: 57 | N32: 0 | O32: =SUM(C32:L32,N32) -> 33 | P32: =SUM(C32:N32) -> 90
B33: 12.45 - 13.00 | C33: 7 | D33: 2 | E33: 5 | F33: 11 | G33: 1 | H33: 0 | I33: 4 | J33: 0 | K33: 0 | L33: =SUM('[1]RD4 MCC'!R29:U29) -> 0 | M33: 42 | N33: 0 | O33: =SUM(C33:L33,N33) -> 30 | P33: =SUM(C33:N33) -> 72
B34: 13.00 - 13.15 | C34: 5 | D34: 2 | E34: 6 | F34: 22 | G34: 0 | H34: 0 | I34: 2 | J34: 1 | K34: 0 | L34: =SUM('[1]RD4 MCC'!R30:U30) -> 0 | M34: 49 | N34: 0 | O34: =SUM(C34:L34,N34) -> 38 | P34: =SUM(C34:N34) -> 87
B35: 13.15 - 13.30 | C35: 7 | D35: 2 | E35: 5 | F35: 22 | G35: 3 | H35: 1 | I35: 0 | J35: 1 | K35: 0 | L35: =SUM('[1]RD4 MCC'!R31:U31) -> 0 | M35: 36 | N35: 0 | O35: =SUM(C35:L35,N35) -> 41 | P35: =SUM(C35:N35) -> 77
B36: 13.30 - 13.45 | C36: 6 | D36: 0 | E36: 1 | F36: 13 | G36: 2 | H36: 0 | I36: 5 | J36: 0 | K36: 0 | L36: =SUM('[1]RD4 MCC'!R32:U32) -> 0 | M36: 49 | N36: 0 | O36: =SUM(C36:L36,N36) -> 27 | P36: =SUM(C36:N36) -> 76
B37: 13.45 - 14.00 | C37: 12 | D37: 1 | E37: 4 | F37: 10 | G37: 2 | H37: 0 | I37: 5 | J37: 0 | K37: 0 | L37: =SUM('[1]RD4 MCC'!R33:U33) -> 0 | M37: 54 | N37: 0 | O37: =SUM(C37:L37,N37) -> 34 | P37: =SUM(C37:N37) -> 88
B38: 14.00 - 14.15 | C38: 13 | D38: 1 | E38: 5 | F38: 13 | G38: 2 | H38: 0 | I38: 3 | J38: 0 | K38: 0 | L38: =SUM('[1]RD4 MCC'!R34:U34) -> 0 | M38: 50 | N38: 0 | O38: =SUM(C38:L38,N38) -> 37 | P38: =SUM(C38:N38) -> 87
B39: 14.15 - 14.30 | C39: 6 | D39: 2 | E39: 5 | F39: 10 | G39: 0 | H39: 1 | I39: 6 | J39: 1 | K39: 0 | L39: =SUM('[1]RD4 MCC'!R35:U35) -> 0 | M39: 50 | N39: 0 | O39: =SUM(C39:L39,N39) -> 31 | P39: =SUM(C39:N39) -> 81
B40: 14.30 - 14.45 | C40: 5 | D40: 0 | E40: 3 | F40: 12 | G40: 2 | H40: 0 | I40: 5 | J40: 1 | K40: 0 | L40: =SUM('[1]RD4 MCC'!R36:U36) -> 0 | M40: 54 | N40: 0 | O40: =SUM(C40:L40,N40) -> 28 | P40: =SUM(C40:N40) -> 82
... B57: 18.45 - 19.00 | C57: 6 | D57: 0 | E57: 3 | F57: 9 | G57: 7 | H57: 0 | I57: 4 | J57: 1 | K57: 0 | L57: =SUM('[1]RD4 MCC'!R53:U53) -> 0 | M57: 46 | N57: 0 | O57: =SUM(C57:L57,N57) -> 30 | P57: =SUM(C57:N57) -> 76
B58: Totals | C58: =SUM(C10:C57) -> 378 | D58: =SUM(D10:D57) -> 87 | E58: =SUM(E10:E57) -> 289 | F58: =SUM(F10:F57) -> 610 | G58: =SUM(G10:G57) -> 96 | H58: =SUM(H10:H57) -> 7 | I58: =SUM(I10:I57) -> 157 | J58: =SUM(J10:J57) -> 21 | ... P58: =SUM(P10:P57) -> 3560
...

Sheet 13.08 Buwenge-Jinja
B1: Consultancy services for Preparation of Expressway Development Master Plan (EDMP) for Uganda
B2: MANUAL CLASSIFIED COUNT (MCC)
B3: ROAD NAME: | C3: ='12.08 Buwenge-Jinja'!C3:G3 -> MCC - C3b - STN93 - Jinja-Buwenge ROAD
C5: Date | D5: 13.08.19 | F5: Location | G5: ='12.08 Buwenge-Jinja'!G5:H5 -> xxx | J5: Surveyor | K5: ='12.08 Buwenge-Jinja'!K5:L5 -> xxx
C6: Dir. From | D6: ='12.08 Buwenge-Jinja'!D6:E6 -> Buwenge | F6: Dir. To | G6: ='12.08 Buwenge-Jinja'!G6:H6 -> Jinja | J6: Supervisor | K6: ='12.08 Buwenge-Jinja'!K6:L6 -> xxx
B8: Time / Veh Type | R8: SUMMARY TRAFFIC VOLUMES
C9: 1. Car | D9: 2. Station Wagon | E9: 3. Pickups | F9: 4. Minibus, matatu | G9: 5. Medium bus | H9: 6. Large Bus | I9: 7. Light Truck | J9: 8. Medium Truck | K9: 9. Heavy truck | L9: 10. Truck Trailer | M9: 11. Motor cycles | N9: 12. Tractors | O9: Total Excl M/Cycles | P9: Total All | R9: Time | S9: 1. Car | T9: 2. Station Wagon | U9: 3. Pickups | V9: 4. Minibus, matatu | W9: 5. Medium bus | X9: 6. Large Bus | Y9: 7. Light Truck | Z9: 8. Medium Truck | AA9: 9. Heavy truck | AB9: 10. Truck Trailer | AC9: 11. Motorcycles | AD9: 12. Tractors, Graders | AE9: Total Excl M/ Cycles | AF9: Total All
B10: 07.00 - 07.15 | C10: 5 | D10: 0 | E10: 0 | F10: 11 | G10: 5 | H10: 0 | I10: 1 | J10: 0 | K10: 0 | L10: =SUM('[1]RD4 MCC'!R150:U150) -> 0 | M10: 41 | N10: 0 | O10: =SUM(C10:L10,N10) -> 22 | P10: =SUM(C10:N10) -> 63 | R10: 0700-0800 | S10: =SUM(C10:C13) -> 12 | T10: =SUM(D10:D13) -> 0 | U10: =SUM(E10:E13) -> 3 | V10: =SUM(F10:F13) -> 36 | W10: =SUM(G10:G13) -> 17 | X10: =SUM(H10:H13) -> 1 | Y10: =SUM(I10:I13) -> 8 | Z10: =SUM(J10:J13) -> 0 | ... AF10: =SUM(P10:P13) -> 284
B11: 07.15 - 07.30 | C11: 3 | D11: 0 | E11: 1 | F11: 6 | G11: 3 | H11: 0 | I11: 4 | J11: 0 | K11: 0 | L11: =SUM('[1]RD4 MCC'!R151:U151) -> 0 | M11: 60 | N11: 0 | O11: =SUM(C11:L11,N11) -> 17 | P11: =SUM(C11:N11) -> 77 | R11: 0800-0900 | S11: =SUM(C14:C17) -> 25 | T11: =SUM(D14:D17) -> 1 | U11: =SUM(E14:E17) -> 9 | V11: =SUM(F14:F17) -> 43 | W11: =SUM(G14:G17) -> 11 | X11: =SUM(H14:H17) -> 2 | Y11: =SUM(I14:I17) -> 8 | Z11: =SUM(J14:J17) -> 0 | ... AF11: =SUM(P14:P17) -> 326
B12: 07.30 - 07.45 | C12: 1 | D12: 0 | E12: 2 | F12: 11 | G12: 6 | H12: 1 | I12: 2 | J12: 0 | K12: 0 | L12: =SUM('[1]RD4 MCC'!R152:U152) -> 0 | M12: 58 | N12: 0 | O12: =SUM(C12:L12,N12) -> 23 | P12: =SUM(C12:N12) -> 81 | R12: 0900-1000 | S12: =SUM(C18:C21) -> 11 | T12: =SUM(D18:D21) -> 1 | U12: =SUM(E18:E21) -> 10 | V12: =SUM(F18:F21) -> 50 | W12: =SUM(G18:G21) -> 5 | X12: =SUM(H18:H21) -> 1 | Y12: =SUM(I18:I21) -> 14 | Z12: =SUM(J18:J21) -> 3 | ... AF12: =SUM(P18:P21) -> 275
B13: 07.45 - 08.00 | C13: 3 | D13: 0 | E13: 0 | F13: 8 | G13: 3 | H13: 0 | I13: 1 | J13: 0 | K13: 0 | L13: =SUM('[1]RD4 MCC'!R153:U153) -> 0 | M13: 48 | N13: 0 | O13: =SUM(C13:L13,N13) -> 15 | P13: =SUM(C13:N13) -> 63 | R13: 1000-1100 | S13: =SUM(C22:C25) -> 23 | T13: =SUM(D22:D25) -> 1 | U13: =SUM(E22:E25) -> 7 | V13: =SUM(F22:F25) -> 48 | W13: =SUM(G22:G25) -> 1 | X13: =SUM(H22:H25) -> 0 | Y13: =SUM(I22:I25) -> 5 | Z13: =SUM(J22:J25) -> 1 | ... AF13: =SUM(P22:P25) -> 254
B14: 08.00 - 08.15 | C14: 6 | D14: 0 | E14: 2 | F14: 9 | G14: 4 | H14: 1 | I14: 1 | J14: 0 | K14: 0 | L14: =SUM('[1]RD4 MCC'!R154:U154) -> 0 | M14: 47 | N14: 0 | O14: =SUM(C14:L14,N14) -> 23 | P14: =SUM(C14:N14) -> 70 | R14: 1100-1200 | S14: =SUM(C26:C29) -> 18 | T14: =SUM(D26:D29) -> 1 | U14: =SUM(E26:E29) -> 7 | V14: =SUM(F26:F29) -> 35 | W14: =SUM(G26:G29) -> 0 | X14: =SUM(H26:H29) -> 1 | Y14: =SUM(I26:I29) -> 10 | Z14: =SUM(J26:J29) -> 3 | ... AF14: =SUM(P26:P29) -> 227
B15: 08.15 - 08.30 | C15: 8 | D15: 0 | E15: 2 | F15: 8 | G15: 2 | H15: 0 | I15: 2 | J15: 0 | K15: 0 | L15: =SUM('[1]RD4 MCC'!R155:U155) -> 0 | M15: 72 | N15: 0 | O15: =SUM(C15:L15,N15) -> 22 | P15: =SUM(C15:N15) -> 94 | R15: 1200-1300 | S15: =SUM(C30:C33) -> 20 | T15: =SUM(D30:D33) -> 1 | U15: =SUM(E30:E33) -> 12 | V15: =SUM(F30:F33) -> 31 | W15: =SUM(G30:G33) -> 2 | X15: =SUM(H30:H33) -> 0 | Y15: =SUM(I30:I33) -> 9 | Z15: =SUM(J30:J33) -> 0 | ... AF15: =SUM(P30:P33) -> 217
B16: 08.30 - 08.45 | C16: 6 | D16: 1 | E16: 3 | F16: 13 | G16: 2 | H16: 0 | I16: 1 | J16: 0 | K16: 0 | L16: =SUM('[1]RD4 MCC'!R156:U156) -> 0 | M16: 55 | N16: 0 | O16: =SUM(C16:L16,N16) -> 26 | P16: =SUM(C16:N16) -> 81 | R16: 1300-1400 | S16: =SUM(C34:C37) -> 11 | T16: =SUM(D34:D37) -> 2 | U16: =SUM(E34:E37) -> 9 | V16: =SUM(F34:F37) -> 34 | W16: =SUM(G34:G37) -> 8 | X16: =SUM(H34:H37) -> 0 | Y16: =SUM(I34:I37) -> 16 | Z16: =SUM(J34:J37) -> 2 | ... AF16: =SUM(P34:P37) -> 216
B17: 08.45 - 9.00 | C17: 5 | D17: 0 | E17: 2 | F17: 13 | G17: 3 | H17: 1 | I17: 4 | J17: 0 | K17: 0 | L17: =SUM('[1]RD4 MCC'!R157:U157) -> 0 | M17: 53 | N17: 0 | O17: =SUM(C17:L17,N17) -> 28 | P17: =SUM(C17:N17) -> 81 | R17: 1400-1500 | S17: =SUM(C38:C41) -> 20 | T17: =SUM(D38:D41) -> 3 | U17: =SUM(E38:E41) -> 14 | V17: =SUM(F38:F41) -> 30 | W17: =SUM(G38:G41) -> 1 | X17: =SUM(H38:H41) -> 0 | Y17: =SUM(I38:I41) -> 14 | Z17: =SUM(J38:J41) -> 1 | ... AF17: =SUM(P38:P41) -> 226
B18: 09.00 - 09.15 | C18: 3 | D18: 0 | E18: 2 | F18: 15 | G18: 3 | H18: 0 | I18: 3 | J18: 1 | K18: 0 | L18: =SUM('[1]RD4 MCC'!R158:U158) -> 0 | M18: 40 | N18: 0 | O18: =SUM(C18:L18,N18) -> 27 | P18: =SUM(C18:N18) -> 67 | R18: 1500-1600 | S18: =SUM(C42:C45) -> 17 | T18: =SUM(D42:D45) -> 2 | U18: =SUM(E42:E45) -> 11 | V18: =SUM(F42:F45) -> 38 | W18: =SUM(G42:G45) -> 3 | X18: =SUM(H42:H45) -> 0 | Y18: =SUM(I42:I45) -> 17 | Z18: =SUM(J42:J45) -> 1 | ... AF18: =SUM(P42:P45) -> 225
B19: 09.15 - 09.30 | C19: 3 | D19: 0 | E19: 2 | F19: 13 | G19: 1 | H19: 0 | I19: 5 | J19: 0 | K19: 0 | L19: =SUM('[1]RD4 MCC'!R159:U159) -> 0 | M19: 29 | N19: 0 | O19: =SUM(C19:L19,N19) -> 24 | P19: =SUM(C19:N19) -> 53 | R19: 1600-1700 | S19: =SUM(C46:C49) -> 22 | T19: =SUM(D46:D49) -> 1 | U19: =SUM(E46:E49) -> 9 | V19: =SUM(F46:F49) -> 41 | W19: =SUM(G46:G49) -> 7 | X19: =SUM(H46:H49) -> 0 | Y19: =SUM(I46:I49) -> 17 | Z19: =SUM(J46:J49) -> 1 | ... AF19: =SUM(P46:P49) -> 234
B20: 09.30 - 09.45 | C20: 1 | D20: 1 | E20: 4 | F20: 14 | G20: 0 | H20: 1 | I20: 5 | J20: 0 | K20: 0 | L20: =SUM('[1]RD4 MCC'!R160:U160) -> 0 | M20: 52 | N20: 0 | O20: =SUM(C20:L20,N20) -> 26 | P20: =SUM(C20:N20) -> 78 | R20: 1700-1800 | S20: =SUM(C50:C53) -> 22 | T20: =SUM(D50:D53) -> 3 | U20: =SUM(E50:E53) -> 15 | V20: =SUM(F50:F53) -> 34 | W20: =SUM(G50:G53) -> 4 | X20: =SUM(H50:H53) -> 0 | Y20: =SUM(I50:I53) -> 21 | Z20: =SUM(J50:J53) -> 0 | ... AF20: =SUM(P50:P53) -> 292
B21: 09.45 - 10.00 | C21: 4 | D21: 0 | E21: 2 | F21: 8 | G21: 1 | H21: 0 | I21: 1 | J21: 2 | K21: 0 | L21: =SUM('[1]RD4 MCC'!R161:U161) -> 0 | M21: 59 | N21: 0 | O21: =SUM(C21:L21,N21) -> 18 | P21: =SUM(C21:N21) -> 77 | R21: 1800-1900 | S21: =SUM(C54:C57) -> 28 | T21: =SUM(D54:D57) -> 7 | U21: =SUM(E54:E57) -> 23 | V21: =SUM(F54:F57) -> 52 | W21: =SUM(G54:G57) -> 13 | X21: =SUM(H54:H57) -> 0 | Y21: =SUM(I54:I57) -> 26 | Z21: =SUM(J54:J57) -> 3 | ... AF21: =SUM(P54:P57) -> 298
B22: 10.00 - 10.15 | C22: 7 | D22: 1 | E22: 4 | F22: 11 | G22: 0 | H22: 0 | I22: 0 | J22: 0 | K22: 0 | L22: =SUM('[1]RD4 MCC'!R162:U162) -> 0 | M22: 40 | N22: 0 | O22: =SUM(C22:L22,N22) -> 23 | P22: =SUM(C22:N22) -> 63 | R22: AM Peak Hr | S22: =MAX(S10:S12) -> 25 | T22: =MAX(T10:T12) -> 1 | U22: =MAX(U10:U12) -> 10 | V22: =MAX(V10:V12) -> 50 | W22: =MAX(W10:W12) -> 17 | X22: =MAX(X10:X12) -> 2 | Y22: =MAX(Y10:Y12) -> 14 | Z22: =MAX(Z10:Z12) -> 3 | ... AF22: =MAX(AF10:AF12) -> 326
B23: 10.15 - 10.30 | C23: 6 | D23: 0 | E23: 2 | F23: 12 | G23: 0 | H23: 0 | I23: 2 | J23: 0 | K23: 0 | L23: =SUM('[1]RD4 MCC'!R163:U163) -> 0 | M23: 39 | N23: 0 | O23: =SUM(C23:L23,N23) -> 22 | P23: =SUM(C23:N23) -> 61 | R23: IP Peak Hr | S23: =MAX(S13:S18) -> 23 | T23: =MAX(T13:T18) -> 3 | U23: =MAX(U13:U18) -> 14 | V23: =MAX(V13:V18) -> 48 | W23: =MAX(W13:W18) -> 8 | X23: =MAX(X13:X18) -> 1 | Y23: =MAX(Y13:Y18) -> 17 | Z23: =MAX(Z13:Z18) -> 3 | ... AF23: =MAX(AF13:AF18) -> 254
B24: 10.30 - 10.45 | C24: 5 | D24: 0 | E24: 1 | F24: 8 | G24: 1 | H24: 0 | I24: 2 | J24: 1 | K24: 0 | L24: =SUM('[1]RD4 MCC'!R164:U164) -> 0 | M24: 38 | N24: 0 | O24: =SUM(C24:L24,N24) -> 18 | P24: =SUM(C24:N24) -> 56 | R24: PM Peak Hr | S24: =MAX(S19:S21) -> 28 | T24: =MAX(T19:T21) -> 7 | U24: =MAX(U19:U21) -> 23 | V24: =MAX(V19:V21) -> 52 | W24: =MAX(W19:W21) -> 13 | X24: =MAX(X19:X21) -> 0 | Y24: =MAX(Y19:Y21) -> 26 | Z24: =MAX(Z19:Z21) -> 3 | ... AF24: =MAX(AF19:AF21) -> 298
B25: 10.45 - 11.00 | C25: 5 | D25: 0 | E25: 0 | F25: 17 | G25: 0 | H25: 0 | I25: 1 | J25: 0 | K25: 0 | L25: =SUM('[1]RD4 MCC'!R165:U165) -> 0 | M25: 51 | N25: 0 | O25: =SUM(C25:L25,N25) -> 23 | P25: =SUM(C25:N25) -> 74 | R25: AM Period | S25: =SUM(S10:S12) -> 48 | T25: =SUM(T10:T12) -> 2 | U25: =SUM(U10:U12) -> 22 | V25: =SUM(V10:V12) -> 129 | W25: =SUM(W10:W12) -> 33 | X25: =SUM(X10:X12) -> 4 | Y25: =SUM(Y10:Y12) -> 30 | Z25: =SUM(Z10:Z12) -> 3 | ... AF25: =SUM(AF10:AF12) -> 885
B26: 11.00 - 11.15 | C26: 4 | D26: 1 | E26: 3 | F26: 15 | G26: 0 | H26: 0 | I26: 2 | J26: 0 | K26: 0 | L26: =SUM('[1]RD4 MCC'!R166:U166) -> 0 | M26: 33 | N26: 0 | O26: =SUM(C26:L26,N26) -> 25 | P26: =SUM(C26:N26) -> 58 | R26: IP Period | S26: =SUM(S13:S18) -> 109 | T26: =SUM(T13:T18) -> 10 | U26: =SUM(U13:U18) -> 60 | V26: =SUM(V13:V18) -> 216 | W26: =SUM(W13:W18) -> 15 | X26: =SUM(X13:X18) -> 1 | Y26: =SUM(Y13:Y18) -> 71 | Z26: =SUM(Z13:Z18) -> 8 | ... AF26: =SUM(AF13:AF18) -> 1365
B27: 11.15 - 11.30 | C27: 5 | D27: 0 | E27: 1 | F27: 5 | G27: 0 | H27: 0 | I27: 3 | J27: 3 | K27: 0 | L27: =SUM('[1]RD4 MCC'!R167:U167) -> 0 | M27: 40 | N27: 0 | O27: =SUM(C27:L27,N27) -> 17 | P27: =SUM(C27:N27) -> 57 | R27: PM Period | S27: =SUM(S19:S21) -> 72 | T27: =SUM(T19:T21) -> 11 | U27: =SUM(U19:U21) -> 47 | V27: =SUM(V19:V21) -> 127 | W27: =SUM(W19:W21) -> 24 | X27: =SUM(X19:X21) -> 0 | Y27: =SUM(Y19:Y21) -> 64 | Z27: =SUM(Z19:Z21) -> 4 | ... AF27: =SUM(AF19:AF21) -> 824
B28: 11.30 - 11.45 | C28: 4 | D28: 0 | E28: 0 | F28: 6 | G28: 0 | H28: 1 | I28: 4 | J28: 0 | K28: 0 | L28: =SUM('[1]RD4 MCC'!R168:U168) -> 0 | M28: 47 | N28: 0 | O28: =SUM(C28:L28,N28) -> 15 | P28: =SUM(C28:N28) -> 62 | R28: 12 Hours | S28: =SUM(S10:S21) -> 229 | T28: =SUM(T10:T21) -> 23 | U28: =SUM(U10:U21) -> 129 | V28: =SUM(V10:V21) -> 472 | W28: =SUM(W10:W21) -> 72 | X28: =SUM(X10:X21) -> 5 | Y28: =SUM(Y10:Y21) -> 165 | Z28: =SUM(Z10:Z21) -> 15 | ... AF28: =SUM(AF10:AF21) -> 3074
B29: 11.45 - 12.00 | C29: 5 | D29: 0 | E29: 3 | F29: 9 | G29: 0 | H29: 0 | I29: 1 | J29: 0 | K29: 0 | L29: =SUM('[1]RD4 MCC'!R169:U169) -> 0 | M29: 32 | N29: 0 | O29: =SUM(C29:L29,N29) -> 18 | P29: =SUM(C29:N29) -> 50
B30: 12.00 - 12.15 | C30: 5 | D30: 0 | E30: 2 | F30: 8 | G30: 0 | H30: 0 | I30: 2 | J30: 0 | K30: 0 | L30: =SUM('[1]RD4 MCC'!R170:U170) -> 0 | M30: 43 | N30: 0 | O30: =SUM(C30:L30,N30) -> 17 | P30: =SUM(C30:N30) -> 60
B31: 12.15 - 12.30 | C31: 8 | D31: 0 | E31: 2 | F31: 6 | G31: 1 | H31: 0 | I31: 4 | J31: 0 | K31: 0 | L31: =SUM('[1]RD4 MCC'!R171:U171) -> 0 | M31: 38 | N31: 0 | O31: =SUM(C31:L31,N31) -> 21 | P31: =SUM(C31:N31) -> 59
B32: 12.30 - 12.45 | C32: 2 | D32: 1 | E32: 5 | F32: 8 | G32: 1 | H32: 0 | I32: 1 | J32: 0 | K32: 0 | L32: =SUM('[1]RD4 MCC'!R172:U172) -> 0 | M32: 31 | N32: 0 | O32: =SUM(C32:L32,N32) -> 18 | P32: =SUM(C32:N32) -> 49
B33: 12.45 - 13.00 | C33: 5 | D33: 0 | E33: 3 | F33: 9 | G33: 0 | H33: 0 | I33: 2 | J33: 0 | K33: 0 | L33: =SUM('[1]RD4 MCC'!R173:U173) -> 0 | M33: 30 | N33: 0 | O33: =SUM(C33:L33,N33) -> 19 | P33: =SUM(C33:N33) -> 49
B34: 13.00 - 13.15 | C34: 3 | D34: 0 | E34: 1 | F34: 9 | G34: 0 | H34: 0 | I34: 2 | J34: 0 | K34: 0 | L34: =SUM('[1]RD4 MCC'!R174:U174) -> 0 | M34: 42 | N34: 0 | O34: =SUM(C34:L34,N34) -> 15 | P34: =SUM(C34:N34) -> 57
B35: 13.15 - 13.30 | C35: 3 | D35: 2 | E35: 5 | F35: 7 | G35: 1 | H35: 0 | I35: 3 | J35: 1 | K35: 0 | L35: =SUM('[1]RD4 MCC'!R175:U175) -> 0 | M35: 29 | N35: 0 | O35: =SUM(C35:L35,N35) -> 22 | P35: =SUM(C35:N35) -> 51
B36: 13.30 - 13.45 | C36: 0 | D36: 0 | E36: 1 | F36: 10 | G36: 0 | H36: 0 | I36: 6 | J36: 1 | K36: 0 | L36: =SUM('[1]RD4 MCC'!R176:U176) -> 0 | M36: 33 | N36: 0 | O36: =SUM(C36:L36,N36) -> 18 | P36: =SUM(C36:N36) -> 51
B37: 13.45 - 14.00 | C37: 5 | D37: 0 | E37: 2 | F37: 8 | G37: 7 | H37: 0 | I37: 5 | J37: 0 | K37: 0 | L37: =SUM('[1]RD4 MCC'!R177:U177) -> 0 | M37: 30 | N37: 0 | O37: =SUM(C37:L37,N37) -> 27 | P37: =SUM(C37:N37) -> 57
B38: 14.00 - 14.15 | C38: 5 | D38: 0 | E38: 3 | F38: 8 | G38: 0 | H38: 0 | I38: 5 | J38: 0 | K38: 0 | L38: =SUM('[1]RD4 MCC'!R178:U178) -> 0 | M38: 20 | N38: 1 | O38: =SUM(C38:L38,N38) -> 22 | P38: =SUM(C38:N38) -> 42
B39: 14.15 - 14.30 | C39: 6 | D39: 1 | E39: 3 | F39: 6 | G39: 1 | H39: 0 | I39: 5 | J39: 1 | K39: 0 | L39: =SUM('[1]RD4 MCC'!R179:U179) -> 0 | M39: 49 | N39: 0 | O39: =SUM(C39:L39,N39) -> 23 | P39: =SUM(C39:N39) -> 72
B40: 14.30 - 14.45 | C40: 7 | D40: 0 | E40: 3 | F40: 12 | G40: 0 | H40: 0 | I40: 2 | J40: 0 | K40: 0 | L40: =SUM('[1]RD4 MCC'!R180:U180) -> 0 | M40: 47 | N40: 0 | O40: =SUM(C40:L40,N40) -> 24 | P40: =SUM(C40:N40) -> 71
... B57: 18.45 - 19.00 | C57: 10 | D57: 1 | E57: 4 | F57: 10 | G57: 2 | H57: 0 | I57: 2 | J57: 1 | K57: 0 | L57: =SUM('[1]RD4 MCC'!R197:U197) -> 0 | M57: 35 | N57: 0 | O57: =SUM(C57:L57,N57) -> 30 | P57: =SUM(C57:N57) -> 65
B58: Totals | C58: =SUM(C10:C57) -> 229 | D58: =SUM(D10:D57) -> 23 | E58: =SUM(E10:E57) -> 129 | F58: =SUM(F10:F57) -> 472 | G58: =SUM(G10:G57) -> 72 | H58: =SUM(H10:H57) -> 5 | I58: =SUM(I10:I57) -> 165 | J58: =SUM(J10:J57) -> 15 | ... P58: =SUM(P10:P57) -> 3074
...

Sheet 13.08 Jinja-Buwenge
B1: Consultancy services for Preparation of Expressway Development Master Plan (EDMP) for Uganda
B2: MANUAL CLASSIFIED COUNT (MCC)
B3: ROAD NAME: | C3: ='12.08 Jinja-Buwenge'!C3:G3 -> MCC - C3b - STN93 - Jinja-Buwenge ROAD
C5: Date | D5: ='13.08 Buwenge-Jinja'!D5 -> 13.08.19 | F5: Location | G5: ='12.08 Buwenge-Jinja'!G5:H5 -> xxx | J5: Surveyor | K5: ='12.08 Buwenge-Jinja'!K5:L5 -> xxx
C6: Dir. From | D6: ='12.08 Jinja-Buwenge'!D6:E6 -> Jinja | F6: Dir. To | G6: ='12.08 Jinja-Buwenge'!G6:H6 -> Buwenge | J6: Supervisor | K6: ='12.08 Buwenge-Jinja'!K6:L6 -> xxx
B8: Time / Veh Type | R8: SUMMARY TRAFFIC VOLUMES
C9: 1. Car | D9: 2. Station Wagon | E9: 3. Pickups | F9: 4. Minibus, matatu | G9: 5. Medium bus | H9: 6. Large Bus | I9: 7. Light Truck | J9: 8. Medium Truck | K9: 9. Heavy truck | L9: 10. Truck Trailer | M9: 11. Motor cycles | N9: 12. Tractors | O9: Total Excl M/Cycles | P9: Total All | R9: Time | S9: 1. Car | T9: 2. Station Wagon | U9: 3. Pickups | V9: 4. Minibus, matatu | W9: 5. Medium bus | X9: 6. Large Bus | Y9: 7. Light Truck | Z9: 8. Medium Truck | AA9: 9. Heavy truck | AB9: 10. Truck Trailer | AC9: 11. Motorcycles | AD9: 12. Tractors, Graders | AE9: Total Excl M/ Cycles | AF9: Total All
B10: 07.00 - 07.15 | C10: 3 | D10: 0 | E10: 1 | F10: 4 | G10: 5 | H10: 0 | I10: 4 | J10: 0 | K10: 0 | L10: =SUM('[1]RD4 MCC'!R102:U102) -> 0 | M10: 10 | N10: 0 | O10: =SUM(C10:L10,N10) -> 17 | P10: =SUM(C10:N10) -> 27 | R10: 0700-0800 | S10: =SUM(C10:C13) -> 21 | T10: =SUM(D10:D13) -> 0 | U10: =SUM(E10:E13) -> 2 | V10: =SUM(F10:F13) -> 25 | W10: =SUM(G10:G13) -> 17 | X10: =SUM(H10:H13) -> 0 | Y10: =SUM(I10:I13) -> 14 | Z10: =SUM(J10:J13) -> 2 | ... AF10: =SUM(P10:P13) -> 164
B11: 07.15 - 07.30 | C11: 7 | D11: 0 | E11: 0 | F11: 5 | G11: 2 | H11: 0 | I11: 3 | J11: 1 | K11: 0 | L11: =SUM('[1]RD4 MCC'!R103:U103) -> 0 | M11: 27 | N11: 0 | O11: =SUM(C11:L11,N11) -> 18 | P11: =SUM(C11:N11) -> 45 | R11: 0800-0900 | S11: =SUM(C14:C17) -> 13 | T11: =SUM(D14:D17) -> 1 | U11: =SUM(E14:E17) -> 9 | V11: =SUM(F14:F17) -> 31 | W11: =SUM(G14:G17) -> 8 | X11: =SUM(H14:H17) -> 0 | Y11: =SUM(I14:I17) -> 6 | Z11: =SUM(J14:J17) -> 3 | ... AF11: =SUM(P14:P17) -> 191
B12: 07.30 - 07.45 | C12: 3 | D12: 0 | E12: 1 | F12: 11 | G12: 4 | H12: 0 | I12: 3 | J12: 0 | K12: 0 | L12: =SUM('[1]RD4 MCC'!R104:U104) -> 0 | M12: 23 | N12: 0 | O12: =SUM(C12:L12,N12) -> 22 | P12: =SUM(C12:N12) -> 45 | R12: 0900-1000 | S12: =SUM(C18:C21) -> 25 | T12: =SUM(D18:D21) -> 2 | U12: =SUM(E18:E21) -> 9 | V12: =SUM(F18:F21) -> 44 | W12: =SUM(G18:G21) -> 3 | X12: =SUM(H18:H21) -> 0 | Y12: =SUM(I18:I21) -> 10 | Z12: =SUM(J18:J21) -> 0 | ... AF12: =SUM(P18:P21) -> 231
B13: 07.45 - 08.00 | C13: 8 | D13: 0 | E13: 0 | F13: 5 | G13: 6 | H13: 0 | I13: 4 | J13: 1 | K13: 0 | L13: =SUM('[1]RD4 MCC'!R105:U105) -> 0 | M13: 23 | N13: 0 | O13: =SUM(C13:L13,N13) -> 24 | P13: =SUM(C13:N13) -> 47 | R13: 1000-1100 | S13: =SUM(C22:C25) -> 22 | T13: =SUM(D22:D25) -> 3 | U13: =SUM(E22:E25) -> 17 | V13: =SUM(F22:F25) -> 44 | W13: =SUM(G22:G25) -> 1 | X13: =SUM(H22:H25) -> 0 | Y13: =SUM(I22:I25) -> 11 | Z13: =SUM(J22:J25) -> 2 | ... AF13: =SUM(P22:P25) -> 266
B14: 08.00 - 08.15 | C14: 3 | D14: 0 | E14: 0 | F14: 6 | G14: 2 | H14: 0 | I14: 0 | J14: 2 | K14: 0 | L14: =SUM('[1]RD4 MCC'!R106:U106) -> 0 | M14: 28 | N14: 0 | O14: =SUM(C14:L14,N14) -> 13 | P14: =SUM(C14:N14) -> 41 | R14: 1100-1200 | S14: =SUM(C26:C29) -> 26 | T14: =SUM(D26:D29) -> 4 | U14: =SUM(E26:E29) -> 16 | V14: =SUM(F26:F29) -> 46 | W14: =SUM(G26:G29) -> 1 | X14: =SUM(H26:H29) -> 0 | Y14: =SUM(I26:I29) -> 10 | Z14: =SUM(J26:J29) -> 0 | ... AF14: =SUM(P26:P29) -> 248
B15: 08.15 - 08.30 | C15: 2 | D15: 0 | E15: 2 | F15: 10 | G15: 0 | H15: 0 | I15: 3 | J15: 1 | K15: 0 | L15: =SUM('[1]RD4 MCC'!R107:U107) -> 0 | M15: 26 | N15: 0 | O15: =SUM(C15:L15,N15) -> 18 | P15: =SUM(C15:N15) -> 44 | R15: 1200-1300 | S15: =SUM(C30:C33) -> 21 | T15: =SUM(D30:D33) -> 1 | U15: =SUM(E30:E33) -> 9 | V15: =SUM(F30:F33) -> 41 | W15: =SUM(G30:G33) -> 7 | X15: =SUM(H30:H33) -> 0 | Y15: =SUM(I30:I33) -> 22 | Z15: =SUM(J30:J33) -> 1 | ... AF15: =SUM(P30:P33) -> 250
B16: 08.30 - 08.45 | C16: 5 | D16: 0 | E16: 3 | F16: 7 | G16: 4 | H16: 0 | I16: 1 | J16: 0 | K16: 0 | L16: =SUM('[1]RD4 MCC'!R108:U108) -> 0 | M16: 35 | N16: 0 | O16: =SUM(C16:L16,N16) -> 20 | P16: =SUM(C16:N16) -> 55 | R16: 1300-1400 | S16: =SUM(C34:C37) -> 24 | T16: =SUM(D34:D37) -> 2 | U16: =SUM(E34:E37) -> 13 | V16: =SUM(F34:F37) -> 47 | W16: =SUM(G34:G37) -> 7 | X16: =SUM(H34:H37) -> 1 | Y16: =SUM(I34:I37) -> 10 | Z16: =SUM(J34:J37) -> 0 | ... AF16: =SUM(P34:P37) -> 252
B17: 08.45 - 9.00 | C17: 3 | D17: 1 | E17: 4 | F17: 8 | G17: 2 | H17: 0 | I17: 2 | J17: 0 | K17: 0 | L17: =SUM('[1]RD4 MCC'!R109:U109) -> 0 | M17: 31 | N17: 0 | O17: =SUM(C17:L17,N17) -> 20 | P17: =SUM(C17:N17) -> 51 | R17: 1400-1500 | S17: =SUM(C38:C41) -> 26 | T17: =SUM(D38:D41) -> 5 | U17: =SUM(E38:E41) -> 21 | V17: =SUM(F38:F41) -> 42 | W17: =SUM(G38:G41) -> 2 | X17: =SUM(H38:H41) -> 2 | Y17: =SUM(I38:I41) -> 6 | Z17: =SUM(J38:J41) -> 0 | ... AF17: =SUM(P38:P41) -> 265
B18: 09.00 - 09.15 | C18: 4 | D18: 0 | E18: 0 | F18: 10 | G18: 2 | H18: 0 | I18: 4 | J18: 0 | K18: 0 | L18: =SUM('[1]RD4 MCC'!R110:U110) -> 0 | M18: 40 | N18: 0 | O18: =SUM(C18:L18,N18) -> 20 | P18: =SUM(C18:N18) -> 60 | R18: 1500-1600 | S18: =SUM(C42:C45) -> 24 | T18: =SUM(D42:D45) -> 2 | U18: =SUM(E42:E45) -> 11 | V18: =SUM(F42:F45) -> 37 | W18: =SUM(G42:G45) -> 2 | X18: =SUM(H42:H45) -> 0 | Y18: =SUM(I42:I45) -> 7 | Z18: =SUM(J42:J45) -> 0 | ... AF18: =SUM(P42:P45) -> 224
B19: 09.15 - 09.30 | C19: 5 | D19: 1 | E19: 4 | F19: 12 | G19: 0 | H19: 0 | I19: 2 | J19: 0 | K19: 0 | L19: =SUM('[1]RD4 MCC'!R111:U111) -> 0 | M19: 30 | N19: 0 | O19: =SUM(C19:L19,N19) -> 24 | P19: =SUM(C19:N19) -> 54 | R19: 1600-1700 | S19: =SUM(C46:C49) -> 23 | T19: =SUM(D46:D49) -> 1 | U19: =SUM(E46:E49) -> 9 | V19: =SUM(F46:F49) -> 41 | W19: =SUM(G46:G49) -> 3 | X19: =SUM(H46:H49) -> 1 | Y19: =SUM(I46:I49) -> 17 | Z19: =SUM(J46:J49) -> 0 | ... AF19: =SUM(P46:P49) -> 228
B20: 09.30 - 09.45 | C20: 10 | D20: 0 | E20: 1 | F20: 12 | G20: 1 | H20: 0 | I20: 3 | J20: 0 | K20: 0 | L20: =SUM('[1]RD4 MCC'!R112:U112) -> 0 | M20: 25 | N20: 0 | O20: =SUM(C20:L20,N20) -> 27 | P20: =SUM(C20:N20) -> 52 | R20: 1700-1800 | S20: =SUM(C50:C53) -> 35 | T20: =SUM(D50:D53) -> 4 | U20: =SUM(E50:E53) -> 14 | V20: =SUM(F50:F53) -> 46 | W20: =SUM(G50:G53) -> 6 | X20: =SUM(H50:H53) -> 1 | Y20: =SUM(I50:I53) -> 16 | Z20: =SUM(J50:J53) -> 0 | ... AF20: =SUM(P50:P53) -> 305
B21: 09.45 - 10.00 | C21: 6 | D21: 1 | E21: 4 | F21: 10 | G21: 0 | H21: 0 | I21: 1 | J21: 0 | K21: 0 | L21: =SUM('[1]RD4 MCC'!R113:U113) -> 0 | M21: 43 | N21: 0 | O21: =SUM(C21:L21,N21) -> 22 | P21: =SUM(C21:N21) -> 65 | R21: 1800-1900 | S21: =SUM(C54:C57) -> 26 | T21: =SUM(D54:D57) -> 1 | U21: =SUM(E54:E57) -> 12 | V21: =SUM(F54:F57) -> 43 | W21: =SUM(G54:G57) -> 12 | X21: =SUM(H54:H57) -> 0 | Y21: =SUM(I54:I57) -> 10 | Z21: =SUM(J54:J57) -> 1 | ... AF21: =SUM(P54:P57) -> 314
B22: 10.00 - 10.15 | C22: 7 | D22: 2 | E22: 7 | F22: 6 | G22: 0 | H22: 0 | I22: 1 | J22: 0 | K22: 0 | L22: =SUM('[1]RD4 MCC'!R114:U114) -> 0 | M22: 40 | N22: 0 | O22: =SUM(C22:L22,N22) -> 23 | P22: =SUM(C22:N22) -> 63 | R22: AM Peak Hr | S22: =MAX(S10:S12) -> 25 | T22: =MAX(T10:T12) -> 2 | U22: =MAX(U10:U12) -> 9 | V22: =MAX(V10:V12) -> 44 | W22: =MAX(W10:W12) -> 17 | X22: =MAX(X10:X12) -> 0 | Y22: =MAX(Y10:Y12) -> 14 | Z22: =MAX(Z10:Z12) -> 3 | ... AF22: =MAX(AF10:AF12) -> 231
B23: 10.15 - 10.30 | C23: 3 | D23: 1 | E23: 4 | F23: 12 | G23: 1 | H23: 0 | I23: 7 | J23: 1 | K23: 0 | L23: =SUM('[1]RD4 MCC'!R115:U115) -> 0 | M23: 33 | N23: 0 | O23: =SUM(C23:L23,N23) -> 29 | P23: =SUM(C23:N23) -> 62 | R23: IP Peak Hr | S23: =MAX(S13:S18) -> 26 | T23: =MAX(T13:T18) -> 5 | U23: =MAX(U13:U18) -> 21 | V23: =MAX(V13:V18) -> 47 | W23: =MAX(W13:W18) -> 7 | X23: =MAX(X13:X18) -> 2 | Y23: =MAX(Y13:Y18) -> 22 | Z23: =MAX(Z13:Z18) -> 2 | ... AF23: =MAX(AF13:AF18) -> 266
B24: 10.30 - 10.45 | C24: 5 | D24: 0 | E24: 3 | F24: 15 | G24: 0 | H24: 0 | I24: 1 | J24: 0 | K24: 0 | L24: =SUM('[1]RD4 MCC'!R116:U116) -> 0 | M24: 42 | N24: 0 | O24: =SUM(C24:L24,N24) -> 24 | P24: =SUM(C24:N24) -> 66 | R24: PM Peak Hr | S24: =MAX(S19:S21) -> 35 | T24: =MAX(T19:T21) -> 4 | U24: =MAX(U19:U21) -> 14 | V24: =MAX(V19:V21) -> 46 | W24: =MAX(W19:W21) -> 12 | X24: =MAX(X19:X21) -> 1 | Y24: =MAX(Y19:Y21) -> 17 | Z24: =MAX(Z19:Z21) -> 1 | ... AF24: =MAX(AF19:AF21) -> 314
B25: 10.45 - 11.00 | C25: 7 | D25: 0 | E25: 3 | F25: 11 | G25: 0 | H25: 0 | I25: 2 | J25: 1 | K25: 0 | L25: =SUM('[1]RD4 MCC'!R117:U117) -> 0 | M25: 50 | N25: 1 | O25: =SUM(C25:L25,N25) -> 25 | P25: =SUM(C25:N25) -> 75 | R25: AM Period | S25: =SUM(S10:S12) -> 59 | T25: =SUM(T10:T12) -> 3 | U25: =SUM(U10:U12) -> 20 | V25: =SUM(V10:V12) -> 100 | W25: =SUM(W10:W12) -> 28 | X25: =SUM(X10:X12) -> 0 | Y25: =SUM(Y10:Y12) -> 30 | Z25: =SUM(Z10:Z12) -> 5 | ... AF25: =SUM(AF10:AF12) -> 586
B26: 11.00 - 11.15 | C26: 7 | D26: 0 | E26: 2 | F26: 12 | G26: 0 | H26: 0 | I26: 3 | J26: 0 | K26: 0 | L26: =SUM('[1]RD4 MCC'!R118:U118) -> 0 | M26: 37 | N26: 0 | O26: =SUM(C26:L26,N26) -> 24 | P26: =SUM(C26:N26) -> 61 | R26: IP Period | S26: =SUM(S13:S18) -> 143 | T26: =SUM(T13:T18) -> 17 | U26: =SUM(U13:U18) -> 87 | V26: =SUM(V13:V18) -> 257 | W26: =SUM(W13:W18) -> 20 | X26: =SUM(X13:X18) -> 3 | Y26: =SUM(Y13:Y18) -> 66 | Z26: =SUM(Z13:Z18) -> 3 | ... AF26: =SUM(AF13:AF18) -> 1505
B27: 11.15 - 11.30 | C27: 6 | D27: 1 | E27: 3 | F27: 13 | G27: 0 | H27: 0 | I27: 2 | J27: 0 | K27: 1 | L27: =SUM('[1]RD4 MCC'!R119:U119) -> 0 | M27: 53 | N27: 0 | O27: =SUM(C27:L27,N27) -> 26 | P27: =SUM(C27:N27) -> 79 | R27: PM Period | S27: =SUM(S19:S21) -> 84 | T27: =SUM(T19:T21) -> 6 | U27: =SUM(U19:U21) -> 35 | V27: =SUM(V19:V21) -> 130 | W27: =SUM(W19:W21) -> 21 | X27: =SUM(X19:X21) -> 2 | Y27: =SUM(Y19:Y21) -> 43 | Z27: =SUM(Z19:Z21) -> 1 | ... AF27: =SUM(AF19:AF21) -> 847
B28: 11.30 - 11.45 | C28: 10 | D28: 1 | E28: 5 | F28: 12 | G28: 1 | H28: 0 | I28: 4 | J28: 0 | K28: 0 | L28: =SUM('[1]RD4 MCC'!R120:U120) -> 0 | M28: 26 | N28: 0 | O28: =SUM(C28:L28,N28) -> 33 | P28: =SUM(C28:N28) -> 59 | R28: 12 Hours | S28: =SUM(S10:S21) -> 286 | T28: =SUM(T10:T21) -> 26 | U28: =SUM(U10:U21) -> 142 | V28: =SUM(V10:V21) -> 487 | W28: =SUM(W10:W21) -> 69 | X28: =SUM(X10:X21) -> 5 | Y28: =SUM(Y10:Y21) -> 139 | Z28: =SUM(Z10:Z21) -> 9 | ... AF28: =SUM(AF10:AF21) -> 2938
B29: 11.45 - 12.00 | C29: 3 | D29: 2 | E29: 6 | F29: 9 | G29: 0 | H29: 0 | I29: 1 | J29: 0 | K29: 0 | L29: =SUM('[1]RD4 MCC'!R121:U121) -> 0 | M29: 28 | N29: 0 | O29: =SUM(C29:L29,N29) -> 21 | P29: =SUM(C29:N29) -> 49
B30: 12.00 - 12.15 | C30: 3 | D30: 0 | E30: 2 | F30: 7 | G30: 0 | H30: 0 | I30: 6 | J30: 0 | K30: 0 | L30: =SUM('[1]RD4 MCC'!R122:U122) -> 0 | M30: 44 | N30: 0 | O30: =SUM(C30:L30,N30) -> 18 | P30: =SUM(C30:N30) -> 62
B31: 12.15 - 12.30 | C31: 8 | D31: 0 | E31: 1 | F31: 12 | G31: 4 | H31: 0 | I31: 5 | J31: 1 | K31: 0 | L31: =SUM('[1]RD4 MCC'!R123:U123) -> 0 | M31: 45 | N31: 0 | O31: =SUM(C31:L31,N31) -> 31 | P31: =SUM(C31:N31) -> 76
B32: 12.30 - 12.45 | C32: 3 | D32: 0 | E32: 2 | F32: 15 | G32: 1 | H32: 0 | I32: 8 | J32: 0 | K32: 0 | L32: =SUM('[1]RD4 MCC'!R124:U124) -> 0 | M32: 29 | N32: 0 | O32: =SUM(C32:L32,N32) -> 29 | P32: =SUM(C32:N32) -> 58
B33: 12.45 - 13.00 | C33: 7 | D33: 1 | E33: 4 | F33: 7 | G33: 2 | H33: 0 | I33: 3 | J33: 0 | K33: 0 | L33: =SUM('[1]RD4 MCC'!R125:U125) -> 0 | M33: 30 | N33: 0 | O33: =SUM(C33:L33,N33) -> 24 | P33: =SUM(C33:N33) -> 54
B34: 13.00 - 13.15 | C34: 9 | D34: 1 | E34: 4 | F34: 10 | G34: 3 | H34: 1 | I34: 7 | J34: 0 | K34: 0 | L34: =SUM('[1]RD4 MCC'!R126:U126) -> 0 | M34: 34 | N34: 0 | O34: =SUM(C34:L34,N34) -> 35 | P34: =SUM(C34:N34) -> 69
B35: 13.15 - 13.30 | C35: 4 | D35: 0 | E35: 2 | F35: 13 | G35: 1 | H35: 0 | I35: 1 | J35: 0 | K35: 0 | L35: =SUM('[1]RD4 MCC'!R127:U127) -> 0 | M35: 43 | N35: 0 | O35: =SUM(C35:L35,N35) -> 21 | P35: =SUM(C35:N35) -> 64
B36: 13.30 - 13.45 | C36: 5 | D36: 0 | E36: 3 | F36: 13 | G36: 1 | H36: 0 | I36: 0 | J36: 0 | K36: 0 | L36: =SUM('[1]RD4 MCC'!R128:U128) -> 0 | M36: 27 | N36: 0 | O36: =SUM(C36:L36,N36) -> 22 | P36: =SUM(C36:N36) -> 49
B37: 13.45 - 14.00 | C37: 6 | D37: 1 | E37: 4 | F37: 11 | G37: 2 | H37: 0 | I37: 2 | J37: 0 | K37: 1 | L37: =SUM('[1]RD4 MCC'!R129:U129) -> 0 | M37: 43 | N37: 0 | O37: =SUM(C37:L37,N37) -> 27 | P37: =SUM(C37:N37) -> 70
B38: 14.00 - 14.15 | C38: 7 | D38: 1 | E38: 5 | F38: 7 | G38: 1 | H38: 0 | I38: 3 | J38: 0 | K38: 1 | L38: =SUM('[1]RD4 MCC'!R130:U130) -> 0 | M38: 35 | N38: 0 | O38: =SUM(C38:L38,N38) -> 25 | P38: =SUM(C38:N38) -> 60
B39: 14.15 - 14.30 | C39: 7 | D39: 2 | E39: 6 | F39: 13 | G39: 0 | H39: 1 | I39: 0 | J39: 0 | K39: 0 | L39: =SUM('[1]RD4 MCC'!R131:U131) -> 0 | M39: 43 | N39: 0 | O39: =SUM(C39:L39,N39) -> 29 | P39: =SUM(C39:N39) -> 72
B40: 14.30 - 14.45 | C40: 9 | D40: 0 | E40: 3 | F40: 9 | G40: 0 | H40: 1 | I40: 2 | J40: 0 | K40: 0 | L40: =SUM('[1]RD4 MCC'!R132:U132) -> 0 | M40: 47 | N40: 0 | O40: =SUM(C40:L40,N40) -> 24 | P40: =SUM(C40:N40) -> 71
... B57: 18.45 - 19.00 | C57: 7 | D57: 0 | E57: 3 | F57: 11 | G57: 4 | H57: 0 | I57: 2 | J57: 0 | K57: 0 | L57: =SUM('[1]RD4 MCC'!R149:U149) -> 0 | M57: 62 | N57: 0 | O57: =SUM(C57:L57,N57) -> 27 | P57: =SUM(C57:N57) -> 89
B58: Totals | C58: =SUM(C10:C57) -> 286 | D58: =SUM(D10:D57) -> 26 | E58: =SUM(E10:E57) -> 142 | F58: =SUM(F10:F57) -> 487 | G58: =SUM(G10:G57) -> 69 | H58: =SUM(H10:H57) -> 5 | I58: =SUM(I10:I57) -> 139 | J58: =SUM(J10:J57) -> 9 | ... P58: =SUM(P10:P57) -> 2938
...

Sheet 14.08 Buwenge-Jinja
B1: Consultancy services for Preparation of Expressway Development Master Plan (EDMP) for Uganda
B2: MANUAL CLASSIFIED COUNT (MCC)
B3: ROAD NAME: | C3: ='12.08 Buwenge-Jinja'!C3:G3 -> MCC - C3b - STN93 - Jinja-Buwenge ROAD
C5: Date | D5: 14.08.19 | F5: Location | G5: ='12.08 Buwenge-Jinja'!G5:H5 -> xxx | J5: Surveyor | K5: ='12.08 Buwenge-Jinja'!K5:L5 -> xxx
C6: Dir. From | D6: ='12.08 Buwenge-Jinja'!D6:E6 -> Buwenge | F6: Dir. To | G6: ='12.08 Buwenge-Jinja'!G6:H6 -> Jinja | J6: Supervisor | K6: ='12.08 Buwenge-Jinja'!K6:L6 -> xxx
B8: Time / Veh Type | R8: SUMMARY TRAFFIC VOLUMES
C9: 1. Car | D9: 2. Station Wagon | E9: 3. Pickups | F9: 4. Minibus, matatu | G9: 5. Medium bus | H9: 6. Large Bus | I9: 7. Light Truck | J9: 8. Medium Truck | K9: 9. Heavy truck | L9: 10. Truck Trailer | M9: 11. Motor cycles | N9: 12. Tractors | O9: Total Excl M/Cycles | P9: Total All | R9: Time | S9: 1. Car | T9: 2. Station Wagon | U9: 3. Pickups | V9: 4. Minibus, matatu | W9: 5. Medium bus | X9: 6. Large Bus | Y9: 7. Light Truck | Z9: 8. Medium Truck | AA9: 9. Heavy truck | AB9: 10. Truck Trailer | AC9: 11. Motorcycles | AD9: 12. Tractors, Graders | AE9: Total Excl M/ Cycles | AF9: Total All
B10: 07.00 - 07.15 | C10: 3 | D10: 0 | E10: 3 | F10: 5 | G10: 2 | H10: 1 | I10: 1 | J10: 0 | K10: 0 | L10: =SUM('[1]RD4 MCC'!R246:U246) -> 0 | M10: 60 | N10: 0 | O10: =SUM(C10:L10,N10) -> 15 | P10: =SUM(C10:N10) -> 75 | R10: 0700-0800 | S10: =SUM(C10:C13) -> 12 | T10: =SUM(D10:D13) -> 0 | U10: =SUM(E10:E13) -> 7 | V10: =SUM(F10:F13) -> 28 | W10: =SUM(G10:G13) -> 17 | X10: =SUM(H10:H13) -> 1 | Y10: =SUM(I10:I13) -> 7 | Z10: =SUM(J10:J13) -> 0 | ... AF10: =SUM(P10:P13) -> 306
B11: 07.15 - 07.30 | C11: 4 | D11: 0 | E11: 1 | F11: 6 | G11: 4 | H11: 0 | I11: 1 | J11: 0 | K11: 0 | L11: =SUM('[1]RD4 MCC'!R247:U247) -> 0 | M11: 45 | N11: 0 | O11: =SUM(C11:L11,N11) -> 16 | P11: =SUM(C11:N11) -> 61 | R11: 0800-0900 | S11: =SUM(C14:C17) -> 12 | T11: =SUM(D14:D17) -> 0 | U11: =SUM(E14:E17) -> 5 | V11: =SUM(F14:F17) -> 42 | W11: =SUM(G14:G17) -> 9 | X11: =SUM(H14:H17) -> 2 | Y11: =SUM(I14:I17) -> 11 | Z11: =SUM(J14:J17) -> 1 | ... AF11: =SUM(P14:P17) -> 279
B12: 07.30 - 07.45 | C12: 2 | D12: 0 | E12: 0 | F12: 9 | G12: 8 | H12: 0 | I12: 4 | J12: 0 | K12: 0 | L12: =SUM('[1]RD4 MCC'!R248:U248) -> 0 | M12: 70 | N12: 0 | O12: =SUM(C12:L12,N12) -> 23 | P12: =SUM(C12:N12) -> 93 | R12: 0900-1000 | S12: =SUM(C18:C21) -> 17 | T12: =SUM(D18:D21) -> 3 | U12: =SUM(E18:E21) -> 14 | V12: =SUM(F18:F21) -> 46 | W12: =SUM(G18:G21) -> 7 | X12: =SUM(H18:H21) -> 0 | Y12: =SUM(I18:I21) -> 9 | Z12: =SUM(J18:J21) -> 1 | ... AF12: =SUM(P18:P21) -> 273
B13: 07.45 - 08.00 | C13: 3 | D13: 0 | E13: 3 | F13: 8 | G13: 3 | H13: 0 | I13: 1 | J13: 0 | K13: 0 | L13: =SUM('[1]RD4 MCC'!R249:U249) -> 0 | M13: 59 | N13: 0 | O13: =SUM(C13:L13,N13) -> 18 | P13: =SUM(C13:N13) -> 77 | R13: 1000-1100 | S13: =SUM(C22:C25) -> 16 | T13: =SUM(D22:D25) -> 0 | U13: =SUM(E22:E25) -> 7 | V13: =SUM(F22:F25) -> 35 | W13: =SUM(G22:G25) -> 1 | X13: =SUM(H22:H25) -> 1 | Y13: =SUM(I22:I25) -> 8 | Z13: =SUM(J22:J25) -> 0 | ... AF13: =SUM(P22:P25) -> 194
B14: 08.00 - 08.15 | C14: 6 | D14: 0 | E14: 1 | F14: 12 | G14: 3 | H14: 0 | I14: 4 | J14: 1 | K14: 1 | L14: =SUM('[1]RD4 MCC'!R250:U250) -> 0 | M14: 59 | N14: 0 | O14: =SUM(C14:L14,N14) -> 28 | P14: =SUM(C14:N14) -> 87 | R14: 1100-1200 | S14: =SUM(C26:C29) -> 10 | T14: =SUM(D26:D29) -> 1 | U14: =SUM(E26:E29) -> 12 | V14: =SUM(F26:F29) -> 37 | W14: =SUM(G26:G29) -> 1 | X14: =SUM(H26:H29) -> 0 | Y14: =SUM(I26:I29) -> 8 | Z14: =SUM(J26:J29) -> 1 | ... AF14: =SUM(P26:P29) -> 209
B15: 08.15 - 08.30 | C15: 1 | D15: 0 | E15: 2 | F15: 9 | G15: 3 | H15: 1 | I15: 3 | J15: 0 | K15: 0 | L15: =SUM('[1]RD4 MCC'!R251:U251) -> 0 | M15: 29 | N15: 0 | O15: =SUM(C15:L15,N15) -> 19 | P15: =SUM(C15:N15) -> 48 | R15: 1200-1300 | S15: =SUM(C30:C33) -> 11 | T15: =SUM(D30:D33) -> 1 | U15: =SUM(E30:E33) -> 8 | V15: =SUM(F30:F33) -> 31 | W15: =SUM(G30:G33) -> 1 | X15: =SUM(H30:H33) -> 0 | Y15: =SUM(I30:I33) -> 8 | Z15: =SUM(J30:J33) -> 1 | ... AF15: =SUM(P30:P33) -> 181
B16: 08.30 - 08.45 | C16: 1 | D16: 0 | E16: 1 | F16: 8 | G16: 1 | H16: 0 | I16: 1 | J16: 0 | K16: 0 | L16: =SUM('[1]RD4 MCC'!R252:U252) -> 0 | M16: 60 | N16: 0 | O16: =SUM(C16:L16,N16) -> 12 | P16: =SUM(C16:N16) -> 72 | R16: 1300-1400 | S16: =SUM(C34:C37) -> 10 | T16: =SUM(D34:D37) -> 2 | U16: =SUM(E34:E37) -> 12 | V16: =SUM(F34:F37) -> 36 | W16: =SUM(G34:G37) -> 1 | X16: =SUM(H34:H37) -> 0 | Y16: =SUM(I34:I37) -> 9 | Z16: =SUM(J34:J37) -> 1 | ... AF16: =SUM(P34:P37) -> 199
B17: 08.45 - 9.00 | C17: 4 | D17: 0 | E17: 1 | F17: 13 | G17: 2 | H17: 1 | I17: 3 | J17: 0 | K17: 0 | L17: =SUM('[1]RD4 MCC'!R253:U253) -> 0 | M17: 48 | N17: 0 | O17: =SUM(C17:L17,N17) -> 24 | P17: =SUM(C17:N17) -> 72 | R17: 1400-1500 | S17: =SUM(C38:C41) -> 13 | T17: =SUM(D38:D41) -> 4 | U17: =SUM(E38:E41) -> 15 | V17: =SUM(F38:F41) -> 35 | W17: =SUM(G38:G41) -> 2 | X17: =SUM(H38:H41) -> 0 | Y17: =SUM(I38:I41) -> 14 | Z17: =SUM(J38:J41) -> 3 | ... AF17: =SUM(P38:P41) -> 208
B18: 09.00 - 09.15 | C18: 3 | D18: 1 | E18: 4 | F18: 10 | G18: 1 | H18: 0 | I18: 6 | J18: 0 | K18: 0 | L18: =SUM('[1]RD4 MCC'!R254:U254) -> 0 | M18: 44 | N18: 0 | O18: =SUM(C18:L18,N18) -> 25 | P18: =SUM(C18:N18) -> 69 | R18: 1500-1600 | S18: =SUM(C42:C45) -> 13 | T18: =SUM(D42:D45) -> 3 | U18: =SUM(E42:E45) -> 11 | V18: =SUM(F42:F45) -> 35 | W18: =SUM(G42:G45) -> 3 | X18: =SUM(H42:H45) -> 0 | Y18: =SUM(I42:I45) -> 10 | Z18: =SUM(J42:J45) -> 0 | ... AF18: =SUM(P42:P45) -> 215
B19: 09.15 - 09.30 | C19: 4 | D19: 0 | E19: 3 | F19: 9 | G19: 3 | H19: 0 | I19: 1 | J19: 0 | K19: 0 | L19: =SUM('[1]RD4 MCC'!R255:U255) -> 0 | M19: 54 | N19: 0 | O19: =SUM(C19:L19,N19) -> 20 | P19: =SUM(C19:N19) -> 74 | R19: 1600-1700 | S19: =SUM(C46:C49) -> 19 | T19: =SUM(D46:D49) -> 4 | U19: =SUM(E46:E49) -> 17 | V19: =SUM(F46:F49) -> 41 | W19: =SUM(G46:G49) -> 2 | X19: =SUM(H46:H49) -> 0 | Y19: =SUM(I46:I49) -> 12 | Z19: =SUM(J46:J49) -> 1 | ... AF19: =SUM(P46:P49) -> 259
