Workbook
Name Dist: 'ALL DATA'!$S:$S
Name Jtime: 'ALL DATA'!$T:$T
Name Pay: 'ALL DATA'!$Z:$Z
Name TripFreq: 'ALL DATA'!$U:$U
Name Veh: 'ALL DATA'!$D:$D
Name Veh_Type: '12.10 KASANGATTI-MATUGGA'!$D$9:$D$37
Name Veh_Type: '14.10 MATUGGA-KASANGATI'!$D$9:$D$37
Name Veh_Type: '[1]25.07 BUSEGA-NATEETE'!$D:$D
Name Veh_Type: '[1]25.07 BUSEGA-NATEETE'!$D:$D
Name Veh_Type: '14.10 KASANGATI-MATUGGA'!$D$9:$D$37
Name zones: #REF!
Name zones: #REF!
Name zones: #REF!
Name Zones_Ndeke: #REF!
Name Zones_Ndeke: #REF!
Name Zones_Ndeke: #REF!

Sheet RSI FORM
B1: Feasibility Study and Detailed Design of Kampala - Jinja Highway
B2: Roadside OD Interview Survey
B4: Date: | C4: 40465 | D4: Interviewer: | G4: Survey Station: | H4: Bweyogerere | J4: Direction: | K4: Bweyogerere-Kireka | L4: Coded By: | N4: Chkd By:
B7: Time Period | C7: Veh_Type | D7: Veh_Other | E7: Occupancy | F7: Origin_Address | H7: Origin_Purpose | I7: Origin_other | J7: Destination_Address | L7: Destination_Purpose | M7: Destination_Other | N7: Origin_Zone | O7: Dest_Zone | P7: WTP
F8: Village/Town | G8: City/Country | J8: Village/Town | K8: City/Country
B9: AM | C9: 3 | E9: 2 | F9: Entebbe | G9: Kla, Ug | H9: 1 | J9: Kla | K9: Kla, Ug | L9: 2 | N9: Blank | O9: Blank | P9: Yes | Q9: 3000
B10: AM | C10: 1 | E10: 1 | F10: Kiwanga | G10: Kla, Ug | H10: 1 | J10: Kla | K10: Kla, Ug | L10: 2 | N10: Blank | O10: Blank | P10: Yes | Q10: 2000
B11: AM | E11: 1 | F11: Bukoto | G11: Kla, Ug | H11: 3 | J11: Kla | K11: Kla, Ug | L11: 1 | N11: Blank | O11: Blank
B12: AM
B13: AM
B14: AM
B15: AM
B16: AM
B17: AM
B18: AM
B19: AM
B20: AM
B21: AM
B22: AM
B23: AM
... B53: AM

Sheet Analysis
B3: Vehicle OD Sample Proportions | N3: Average Journey Time
B4: Vehicle Types | C4: OD Sample | D4: OD Sample, % | N4: Journey Time Range (Hrs) | O4: Cummu-lative | P4: No of Vehicles | Q4: No. of Vehicles, %
B5: Car | C5: =COUNTIF('ALL DATA'!$D$9:$D$5000,"1") -> 271 | D5: =C5/$C$17 -> 0.55876289 | N5: 0-0.25 | O5: =COUNTIF(Jtime,"<=0.25") -> 128 | P5: =O5 -> 128 | Q5: =P5/$O$15 -> 0.28381375
B6: Station Wagon | C6: =COUNTIF('ALL DATA'!$D$9:$D$5000,"2") -> 64 | D6: =C6/$C$17 -> 0.13195876 | N6: 0.25-0.50 | O6: =COUNTIF(Jtime,"<=0.5") -> 250 | P6: =O6-O5 -> 122 | Q6: =P6/$O$15 -> 0.27050998
B7: Pickups | C7: =COUNTIF('ALL DATA'!$D$9:$D$5000,"3") -> 19 | D7: =C7/$C$17 -> 0.039175258 | N7: 0.50-0.75 | O7: =COUNTIF(Jtime,"<=0.75") -> 303 | P7: =O7-O6 -> 53 | Q7: =P7/$O$15 -> 0.11751663
B8: Minibus, matatu | C8: =COUNTIF('ALL DATA'!$D$9:$D$5000,"4") -> 33 | D8: =C8/$C$17 -> 0.068041237 | N8: 0.75-1.00 | O8: =COUNTIF(Jtime,"<=1.0") -> 384 | P8: =O8-O7 -> 81 | Q8: =P8/$O$15 -> 0.17960089
B9: Medium bus | C9: =COUNTIF('ALL DATA'!$D$9:$D$5000,"5") -> 1 | D9: =C9/$C$17 -> 0.0020618557 | N9: 1.00-1.50 | O9: =COUNTIF(Jtime,"<=1.5") -> 403 | P9: =O9-O8 -> 19 | Q9: =P9/$O$15 -> 0.042128603
B10: Large Bus | C10: =COUNTIF('ALL DATA'!$D$9:$D$5000,"6") -> 1 | D10: =C10/$C$17 -> 0.0020618557 | N10: 1.5-2.0 | O10: =COUNTIF(Jtime,"<=2") -> 425 | P10: =O10-O9 -> 22 | Q10: =P10/$O$15 -> 0.048780488
B11: Light Truck | C11: =COUNTIF('ALL DATA'!$D$9:$D$5000,"7") -> 66 | D11: =C11/$C$17 -> 0.13608247 | N11: 2.0-3.0 | O11: =COUNTIF(Jtime,"<=3") -> 438 | P11: =O11-O10 -> 13 | Q11: =P11/$O$15 -> 0.028824834
B12: Medium Truck | C12: =COUNTIF('ALL DATA'!$D$9:$D$5000,"8") -> 19 | D12: =C12/$C$17 -> 0.039175258 | N12: 3.0-5.0 | O12: =COUNTIF(Jtime,"<=5") -> 444 | P12: =O12-O11 -> 6 | Q12: =P12/$O$15 -> 0.013303769
B13: Heavy truck | C13: =COUNTIF('ALL DATA'!$D$9:$D$5000,"9") -> 5 | D13: =C13/$C$17 -> 0.010309278 | N13: 5.0-7.5 | O13: =COUNTIF(Jtime,"<=7.5") -> 447 | P13: =O13-O12 -> 3 | Q13: =P13/$O$15 -> 0.0066518847
B14: Truck Trailer | C14: =COUNTIF('ALL DATA'!$D$9:$D$5000,"10") -> 2 | D14: =C14/$C$17 -> 0.0041237113 | N14: 7.5-10 | O14: =COUNTIF(Jtime,"<=10") -> 450 | P14: =O14-O13 -> 3 | Q14: =P14/$O$15 -> 0.0066518847
B15: Motor cycles | C15: =COUNTIF('ALL DATA'!$D$9:$D$5000,"11") -> 3 | D15: =C15/$C$17 -> 0.006185567 | N15: Over 10 | O15: =COUNTIF(Jtime,"<=15") -> 451 | P15: =O15-O14 -> 1 | Q15: =P15/$O$15 -> 0.0022172949
B16: Tractors | C16: =COUNTIF('ALL DATA'!$D$9:$D$5000,"12") -> 1 | D16: =C16/$C$17 -> 0.0020618557
C17: =SUM(C5:C16) -> 485
N21: Trip Frequency
B22: Journey Purpose | N22: Trip Frequency | O22: No of Vehicles | P22: No. of Vehicles, %
B23: Purpose | C23: Respondents | D23: Percent | N23: More than 2 times every day | O23: =COUNTIF(TripFreq,"=1") -> 131 | P23: =O23/$O$29 -> 0.27578947
B24: Home-Work | C24: =COUNTIF('ALL DATA'!$R$9:$R$5000,"Home-Work") -> 122 | D24: =C24/$C$29 -> 0.25154639 | N24: Daily (Up and Down) | O24: =COUNTIF(TripFreq,"=2") -> 177 | P24: =O24/$O$29 -> 0.37263158
B25: Home-Study | C25: =COUNTIF('ALL DATA'!$R$9:$R$369,"Home-Study") -> 8 | D25: =C25/$C$29 -> 0.016494845 | N25: 2/3 times a week | O25: =COUNTIF(TripFreq,"=3") -> 54 | P25: =O25/$O$29 -> 0.11368421
B26: Work-Home | C26: =COUNTIF('ALL DATA'!$R$9:$R$369,"Work-Home") -> 35 | D26: =C26/$C$29 -> 0.072164948 | N26: Once a week | O26: =COUNTIF(TripFreq,"=4") -> 26 | P26: =O26/$O$29 -> 0.054736842
B27: Work-Work | C27: =COUNTIF('ALL DATA'!$R$9:$R$369,"Work-Work") -> 39 | D27: =C27/$C$29 -> 0.080412371 | N27: Once a month | O27: =COUNTIF(TripFreq,"=5") -> 10 | P27: =O27/$O$29 -> 0.021052632
B28: Others | C28: =C29-SUM(C24:C27) -> 281 | D28: =C28/$C$29 -> 0.57938144 | N28: Once in a while | O28: =COUNTIF(TripFreq,"=6") -> 77 | P28: =O28/$O$29 -> 0.16210526
B29: Total | C29: =C17 -> 485 | O29: =SUM(O23:O28) -> 475
B40: Expressway Use
B41: Response | C41: Number | D41: Percent
B42: Yes | C42: =COUNTIF('ALL DATA'!$Y$9:$Y$5000,"Y") -> 479 | D42: =C42/$C$44 -> 0.98762887
B43: No | C43: =C44-C42 -> 6 | D43: =C43/$C$44 -> 0.012371134
B44: Total | C44: =C29 -> 485
R47: Home | S47: Work | T47: Study | U47: Commercial | V47: Tourism | W47: Leisure/Social | X47: Hospital | Y47: Others
P48: 1 | Q48: Home | R48: =R59/SUM($R$59:$Y$66) -> 0.063917526 | S48: =S59/SUM($R$59:$Y$66) -> 0.25154639 | T48: =T59/SUM($R$59:$Y$66) -> 0.020618557 | U48: =U59/SUM($R$59:$Y$66) -> 0.065979381 | V48: =V59/SUM($R$59:$Y$66) -> 0.0020618557 | W48: =W59/SUM($R$59:$Y$66) -> 0.028865979 | X48: =X59/SUM($R$59:$Y$66) -> 0.012371134 | Y48: =Y59/SUM($R$59:$Y$66) -> 0.055670103
P49: 2 | Q49: Work | R49: =R60/SUM($R$59:$Y$66) -> 0.084536082 | S49: =S60/SUM($R$59:$Y$66) -> 0.096907216 | T49: =T60/SUM($R$59:$Y$66) -> 0.006185567 | U49: =U60/SUM($R$59:$Y$66) -> 0.012371134 | V49: =V60/SUM($R$59:$Y$66) -> 0 | W49: =W60/SUM($R$59:$Y$66) -> 0.012371134 | X49: =X60/SUM($R$59:$Y$66) -> 0 | Y49: =Y60/SUM($R$59:$Y$66) -> 0.020618557
P50: 3 | Q50: Study | R50: =R61/SUM($R$59:$Y$66) -> 0.01443299 | S50: =S61/SUM($R$59:$Y$66) -> 0 | T50: =T61/SUM($R$59:$Y$66) -> 0.006185567 | U50: =U61/SUM($R$59:$Y$66) -> 0.0020618557 | V50: =V61/SUM($R$59:$Y$66) -> 0 | W50: =W61/SUM($R$59:$Y$66) -> 0 | X50: =X61/SUM($R$59:$Y$66) -> 0 | Y50: =Y61/SUM($R$59:$Y$66) -> 0
P51: 4 | Q51: Commercial | R51: =R62/SUM($R$59:$Y$66) -> 0.039175258 | S51: =S62/SUM($R$59:$Y$66) -> 0.010309278 | T51: =T62/SUM($R$59:$Y$66) -> 0 | U51: =U62/SUM($R$59:$Y$66) -> 0.074226804 | V51: =V62/SUM($R$59:$Y$66) -> 0 | W51: =W62/SUM($R$59:$Y$66) -> 0 | X51: =X62/SUM($R$59:$Y$66) -> 0 | Y51: =Y62/SUM($R$59:$Y$66) -> 0.0041237113
P52: 5 | Q52: Tourism | R52: =R63/SUM($R$59:$Y$66) -> 0.0041237113 | S52: =S63/SUM($R$59:$Y$66) -> 0 | T52: =T63/SUM($R$59:$Y$66) -> 0 | U52: =U63/SUM($R$59:$Y$66) -> 0 | V52: =V63/SUM($R$59:$Y$66) -> 0 | W52: =W63/SUM($R$59:$Y$66) -> 0 | X52: =X63/SUM($R$59:$Y$66) -> 0 | Y52: =Y63/SUM($R$59:$Y$66) -> 0
P53: 6 | Q53: Leisure/Social | R53: =R64/SUM($R$59:$Y$66) -> 0.006185567 | S53: =S64/SUM($R$59:$Y$66) -> 0.0020618557 | T53: =T64/SUM($R$59:$Y$66) -> 0 | U53: =U64/SUM($R$59:$Y$66) -> 0.0041237113 | V53: =V64/SUM($R$59:$Y$66) -> 0 | W53: =W64/SUM($R$59:$Y$66) -> 0.012371134 | X53: =X64/SUM($R$59:$Y$66) -> 0 | Y53: =Y64/SUM($R$59:$Y$66) -> 0
P54: 7 | Q54: Hospital | R54: =R65/SUM($R$59:$Y$66) -> 0.0082474227 | S54: =S65/SUM($R$59:$Y$66) -> 0 | T54: =T65/SUM($R$59:$Y$66) -> 0 | U54: =U65/SUM($R$59:$Y$66) -> 0 | V54: =V65/SUM($R$59:$Y$66) -> 0 | W54: =W65/SUM($R$59:$Y$66) -> 0 | X54: =X65/SUM($R$59:$Y$66) -> 0.0082474227 | Y54: =Y65/SUM($R$59:$Y$66) -> 0
P55: 8 | Q55: Others | R55: =R66/SUM($R$59:$Y$66) -> 0.016494845 | S55: =S66/SUM($R$59:$Y$66) -> 0.022680412 | T55: =T66/SUM($R$59:$Y$66) -> 0.0020618557 | U55: =U66/SUM($R$59:$Y$66) -> 0.006185567 | V55: =V66/SUM($R$59:$Y$66) -> 0 | W55: =W66/SUM($R$59:$Y$66) -> 0 | X55: =X66/SUM($R$59:$Y$66) -> 0.0020618557 | Y55: =Y66/SUM($R$59:$Y$66) -> 0.020618557
R57: 1 | S57: 2 | T57: 3 | U57: 4 | V57: 5 | W57: 6 | X57: 7 | Y57: 8
B58: Willingness to Pay | R58: Home | S58: Work | T58: Study | U58: Commercial | V58: Tourism | W58: Leisure/Social | X58: Hospital | Y58: Others
...

Sheet ALL DATA
B1: Consultancy services for Preparation of Expressway Develo PMent Master Plan (EDMP) for Uganda
B2: Roadside OD Interview Survey
B4: Date: | C4: 12.10.19 | E4: Road Name: | F4: ='14.10 KASANGATI-MATUGGA'!F4:G4 -> MATUGGA-WAKISO ROAD | I4: Direction From: | L4: MATUGGA | N4: Interviewers: | O4: SHAMIRAH, JULIUS | V4: Supervisor: | W4: STEVEN | Y4: Coded By: | Z4: ='14.10 KASANGATI-MATUGGA'!Z4 -> DAVID | AA4: Chkd By: | AB4: Bakole Deo
I5: Direction To: | L5: KASANGATTI
B7: Time | C7: Veh_Reg_No. | D7: Veh_Type | E7: No. Occupants | F7: Origin_Address | I7: Origin_Establish | J7: Origin_Purpose | K7: Origin-Purpose Desc | L7: Destination_Address | O7: Destination_Establish | P7: Destination_Purpose | Q7: Destination_Purpose Desc | R7: Journey_Purpose | S7: Approx_Distance (Km) | T7: Approx_Journey Time (Hrs) | U7: Trip_Frequency | V7: GOODS VEHICLES ONLY | Y7: Would You Use Xpressways? | Z7: Pay How Much? (UGX) | AA7: Origin_Zone | AB7: Dest_Zone
F8: Village or Town | G8: District | H8: Country | L8: Village or Town | M8: District | N8: Country | V8: Goods_Type | W8: Goods_Quantity (Ton) | X8: Goods_Value (UGXm)
B9: 0.67152778 | C9: UAP 387B | D9: 8 | E9: 1 | F9: KASENGEJJE | G9: WAKISO | H9: UGA | I9: 9 | J9: 1 | K9: =VLOOKUP(J9,Key!$E$2:$F$9,2,FALSE) -> Home | L9: KASANGATTI | M9: WAKISO | N9: UGA | O9: 1 | P9: 1 | Q9: =VLOOKUP(P9,Key!$E$2:$F$9,2,FALSE) -> Home | R9: =K9&"-"&Q9 -> Home-Home | U9: 1 | V9: 11 | Y9: Y | Z9: 3000 | AA9: =VLOOKUP(F9,Zones!$A$2:$F$2186,6,FALSE) -> 1402 | AB9: =VLOOKUP(L9,Zones!$A$2:$F$2186,6,FALSE) -> 1393
B10: 0.67291667 | C10: UAN 185N | D10: 1 | E10: 2 | F10: KABUSU | G10: WAKISO | H10: UGA | I10: 7 | J10: 1 | K10: =VLOOKUP(J10,Key!$E$2:$F$9,2,FALSE) -> Home | L10: BUKOTO | M10: KAMPALA | N10: UGA | O10: 1 | P10: 1 | Q10: =VLOOKUP(P10,Key!$E$2:$F$9,2,FALSE) -> Home | R10: =K10&"-"&Q10 -> Home-Home | S10: 3 | U10: 1 | Y10: Y | Z10: 3500 | AA10: =VLOOKUP(F10,Zones!$A$2:$F$2186,6,FALSE) -> 565 | AB10: =VLOOKUP(L10,Zones!$A$2:$F$2186,6,FALSE) -> 516
B11: 0.62222222 | C11: UAK 338U | D11: 1 | E11: 5 | F11: KITI | G11: WAKISO | H11: UGA | I11: 1 | J11: 3 | K11: =VLOOKUP(J11,Key!$E$2:$F$9,2,FALSE) -> Study | L11: KIIRA | M11: WAKISO | N11: UGA | O11: 4 | P11: 3 | Q11: =VLOOKUP(P11,Key!$E$2:$F$9,2,FALSE) -> Study | R11: =K11&"-"&Q11 -> Study-Study | T11: 0.1 | U11: 1 | Y11: Y | Z11: 3500 | AA11: =VLOOKUP(F11,Zones!$A$2:$F$2186,6,FALSE) -> 1402 | AB11: =VLOOKUP(L11,Zones!$A$2:$F$2186,6,FALSE) -> 1396
B12: 0.625 | C12: UBE 33Q | D12: 1 | E12: 4 | F12: MATUGGA | G12: WAKISO | H12: UGA | I12: 1 | J12: 8 | K12: =VLOOKUP(J12,Key!$E$2:$F$9,2,FALSE) -> Others | L12: MULAGO | M12: KAMPALA | N12: UGA | O12: 4 | P12: 8 | Q12: =VLOOKUP(P12,Key!$E$2:$F$9,2,FALSE) -> Others | R12: =K12&"-"&Q12 -> Others-Others | S12: 7 | T12: 0.2 | U12: 5 | Y12: Y | Z12: 1000 | AA12: =VLOOKUP(F12,Zones!$A$2:$F$2186,6,FALSE) -> 1402 | AB12: =VLOOKUP(L12,Zones!$A$2:$F$2186,6,FALSE) -> 560
B13: 0.62986111 | C13: UAL 290P | D13: 1 | E13: 2 | F13: WAKISO TOWN | G13: WAKISO | H13: UGA | I13: 1 | J13: 2 | K13: =VLOOKUP(J13,Key!$E$2:$F$9,2,FALSE) -> Work | L13: KASANGATTI | M13: WAKISO | N13: UGA | O13: 7 | P13: 4 | Q13: =VLOOKUP(P13,Key!$E$2:$F$9,2,FALSE) -> Commercial | R13: =K13&"-"&Q13 -> Work-Commercial | T13: 0.1 | U13: 1 | Y13: Y | Z13: 400 | AA13: =VLOOKUP(F13,Zones!$A$2:$F$2186,6,FALSE) -> 1408 | AB13: =VLOOKUP(L13,Zones!$A$2:$F$2186,6,FALSE) -> 1393
B14: 0.62777778 | C14: UBB 241W | D14: 1 | E14: 1 | F14: KITI | G14: WAKISO | H14: UGA | I14: 1 | J14: 7 | K14: =VLOOKUP(J14,Key!$E$2:$F$9,2,FALSE) -> Hospital | L14: GAYAZA | M14: WAKISO | N14: UGA | O14: 5 | P14: 7 | Q14: =VLOOKUP(P14,Key!$E$2:$F$9,2,FALSE) -> Hospital | R14: =K14&"-"&Q14 -> Hospital-Hospital | S14: 5 | T14: 0.1 | U14: 1 | Y14: Y | Z14: 5000 | AA14: =VLOOKUP(F14,Zones!$A$2:$F$2186,6,FALSE) -> 1402 | AB14: =VLOOKUP(L14,Zones!$A$2:$F$2186,6,FALSE) -> 811
B15: 0.65833333 | C15: UBE 794R | D15: 1 | E15: 3 | F15: KITI | G15: WAKISO | H15: UGA | I15: 1 | J15: 1 | K15: =VLOOKUP(J15,Key!$E$2:$F$9,2,FALSE) -> Home | L15: KASANGATTI | M15: WAKISO | N15: UGA | O15: 5 | P15: 7 | Q15: =VLOOKUP(P15,Key!$E$2:$F$9,2,FALSE) -> Hospital | R15: =K15&"-"&Q15 -> Home-Hospital | S15: 2 | T15: 0.1 | U15: 6 | Y15: Y | Z15: 500 | AA15: =VLOOKUP(F15,Zones!$A$2:$F$2186,6,FALSE) -> 1402 | AB15: =VLOOKUP(L15,Zones!$A$2:$F$2186,6,FALSE) -> 1393
B16: 0.66319444 | C16: UBA 121B | D16: 3 | E16: 2 | F16: WAKISO TOWN | G16: WAKISO | H16: UGA | I16: 1 | J16: 6 | K16: =VLOOKUP(J16,Key!$E$2:$F$9,2,FALSE) -> Leisure/Social | L16: KASANGATTI | M16: WAKISO | N16: UGA | O16: 7 | P16: 6 | Q16: =VLOOKUP(P16,Key!$E$2:$F$9,2,FALSE) -> Leisure/Social | R16: =K16&"-"&Q16 -> Leisure/Social-Leisure/Social | S16: 0.5 | T16: 0.1 | U16: 1 | Y16: Y | Z16: 1000 | AA16: =VLOOKUP(F16,Zones!$A$2:$F$2186,6,FALSE) -> 1408 | AB16: =VLOOKUP(L16,Zones!$A$2:$F$2186,6,FALSE) -> 1393
B17: 0.61458333 | C17: UAY 217M | D17: 1 | E17: 2 | F17: MATUGGA | G17: WAKISO | H17: UGA | I17: 1 | J17: 6 | K17: =VLOOKUP(J17,Key!$E$2:$F$9,2,FALSE) -> Leisure/Social | L17: GAYAZA | M17: WAKISO | N17: UGA | O17: 1 | P17: 6 | Q17: =VLOOKUP(P17,Key!$E$2:$F$9,2,FALSE) -> Leisure/Social | R17: =K17&"-"&Q17 -> Leisure/Social-Leisure/Social | S17: 7 | T17: 0.1 | U17: 1 | Y17: Y | Z17: 1000 | AA17: =VLOOKUP(F17,Zones!$A$2:$F$2186,6,FALSE) -> 1402 | AB17: =VLOOKUP(L17,Zones!$A$2:$F$2186,6,FALSE) -> 811
B18: 0.61180556 | C18: UAZ 061X | D18: 1 | E18: 6 | F18: WAKISO TOWN | G18: WAKISO | H18: UGA | I18: 1 | J18: 6 | K18: =VLOOKUP(J18,Key!$E$2:$F$9,2,FALSE) -> Leisure/Social | L18: GAYAZA | M18: WAKISO | N18: UGA | O18: 1 | P18: 6 | Q18: =VLOOKUP(P18,Key!$E$2:$F$9,2,FALSE) -> Leisure/Social | R18: =K18&"-"&Q18 -> Leisure/Social-Leisure/Social | S18: 3 | T18: 0.1 | U18: 1 | Y18: Y | Z18: 200 | AA18: =VLOOKUP(F18,Zones!$A$2:$F$2186,6,FALSE) -> 1408 | AB18: =VLOOKUP(L18,Zones!$A$2:$F$2186,6,FALSE) -> 811
B19: 0.64097222 | C19: UBA 239X | D19: 1 | E19: 2 | F19: NANGABO | G19: WAKISO | H19: UGA | I19: 1 | J19: 6 | K19: =VLOOKUP(J19,Key!$E$2:$F$9,2,FALSE) -> Leisure/Social | L19: KASANGATTI | M19: WAKISO | N19: UGA | O19: 7 | P19: 6 | Q19: =VLOOKUP(P19,Key!$E$2:$F$9,2,FALSE) -> Leisure/Social | R19: =K19&"-"&Q19 -> Leisure/Social-Leisure/Social | S19: 0.5 | T19: 0.1 | U19: 6 | Y19: Y | Z19: 2000 | AA19: =VLOOKUP(F19,Zones!$A$2:$F$2186,6,FALSE) -> 1393 | AB19: =VLOOKUP(L19,Zones!$A$2:$F$2186,6,FALSE) -> 1393
B20: 0.6375 | C20: UBE 072G | D20: 1 | E20: 5 | F20: WAKISO TOWN | G20: WAKISO | H20: UGA | I20: 1 | J20: 5 | K20: =VLOOKUP(J20,Key!$E$2:$F$9,2,FALSE) -> Tourism | L20: KASANGATTI | M20: WAKISO | N20: UGA | O20: 1 | P20: 1 | Q20: =VLOOKUP(P20,Key!$E$2:$F$9,2,FALSE) -> Home | R20: =K20&"-"&Q20 -> Tourism-Home | T20: 0.1 | U20: 1 | Y20: Y | Z20: 500 | AA20: =VLOOKUP(F20,Zones!$A$2:$F$2186,6,FALSE) -> 1408 | AB20: =VLOOKUP(L20,Zones!$A$2:$F$2186,6,FALSE) -> 1393
B21: 0.61944444 | C21: UAM 669D | D21: 1 | E21: 4 | F21: NANGABO | G21: WAKISO | H21: UGA | I21: 1 | J21: 1 | K21: =VLOOKUP(J21,Key!$E$2:$F$9,2,FALSE) -> Home | L21: MULAGO | M21: KAMPALA | N21: UGA | O21: 1 | P21: 1 | Q21: =VLOOKUP(P21,Key!$E$2:$F$9,2,FALSE) -> Home | R21: =K21&"-"&Q21 -> Home-Home | S21: 2 | T21: 0.1 | U21: 1 | Y21: Y | Z21: 3000 | AA21: =VLOOKUP(F21,Zones!$A$2:$F$2186,6,FALSE) -> 1393 | AB21: =VLOOKUP(L21,Zones!$A$2:$F$2186,6,FALSE) -> 560
B22: 0.61666667 | C22: UBA 695R | D22: 2 | E22: 2 | F22: NANGABO | G22: WAKISO | H22: UGA | I22: 1 | J22: 2 | K22: =VLOOKUP(J22,Key!$E$2:$F$9,2,FALSE) -> Work | L22: KAMPALA | M22: KAMPALA | N22: UGA | O22: 2 | P22: 2 | Q22: =VLOOKUP(P22,Key!$E$2:$F$9,2,FALSE) -> Work | R22: =K22&"-"&Q22 -> Work-Work | S22: 1.5 | T22: 0.1 | U22: 1 | Y22: Y | Z22: 5000 | AA22: =VLOOKUP(F22,Zones!$A$2:$F$2186,6,FALSE) -> 1393 | AB22: =VLOOKUP(L22,Zones!$A$2:$F$2186,6,FALSE) -> 521
B23: 0.42986111 | C23: UAR 383B | D23: 1 | E23: 2 | F23: WAKISO TOWN | G23: WAKISO | H23: UGA | I23: 1 | J23: 2 | K23: =VLOOKUP(J23,Key!$E$2:$F$9,2,FALSE) -> Work | L23: KASANGATTI | M23: WAKISO | N23: UGA | O23: 3 | P23: 2 | Q23: =VLOOKUP(P23,Key!$E$2:$F$9,2,FALSE) -> Work | R23: =K23&"-"&Q23 -> Work-Work | S23: 1 | T23: 0.1 | U23: 1 | Y23: Y | Z23: 1000 | AA23: =VLOOKUP(F23,Zones!$A$2:$F$2186,6,FALSE) -> 1408 | AB23: =VLOOKUP(L23,Zones!$A$2:$F$2186,6,FALSE) -> 1393
B24: 0.43125 | C24: UAP 465T | D24: 1 | E24: 6 | F24: WAKISO TOWN | G24: WAKISO | H24: UGA | I24: 1 | J24: 6 | K24: =VLOOKUP(J24,Key!$E$2:$F$9,2,FALSE) -> Leisure/Social | L24: NATEETE | M24: KAMPALA | N24: UGA | O24: 1 | P24: 1 | Q24: =VLOOKUP(P24,Key!$E$2:$F$9,2,FALSE) -> Home | R24: =K24&"-"&Q24 -> Leisure/Social-Home | S24: 10 | T24: 0.3 | U24: 1 | Y24: Y | Z24: 1000 | AA24: =VLOOKUP(F24,Zones!$A$2:$F$2186,6,FALSE) -> 1408 | AB24: =VLOOKUP(L24,Zones!$A$2:$F$2186,6,FALSE) -> 572
B25: 0.58333333 | C25: UBE 012B | D25: 2 | E25: 3 | F25: MPERERWE | G25: KAMPALA | H25: UGA | I25: 3 | J25: 4 | K25: =VLOOKUP(J25,Key!$E$2:$F$9,2,FALSE) -> Commercial | L25: GAYAZA | M25: WAKISO | N25: UGA | O25: 4 | P25: 4 | Q25: =VLOOKUP(P25,Key!$E$2:$F$9,2,FALSE) -> Commercial | R25: =K25&"-"&Q25 -> Commercial-Commercial | T25: 0.1 | U25: 1 | V25: 4 | W25: 1.5 | X25: 2 | Y25: Y | Z25: 2500 | AA25: =VLOOKUP(F25,Zones!$A$2:$F$2186,6,FALSE) -> 559 | AB25: =VLOOKUP(L25,Zones!$A$2:$F$2186,6,FALSE) -> 811
B26: 0.83194444 | C26: UAG 516K | D26: 1 | E26: 2 | F26: KITAGOBWA | G26: WAKISO | H26: UGA | I26: 1 | J26: 1 | K26: =VLOOKUP(J26,Key!$E$2:$F$9,2,FALSE) -> Home | L26: KAMPALA | M26: KAMPALA | N26: UGA | O26: 5 | P26: 7 | Q26: =VLOOKUP(P26,Key!$E$2:$F$9,2,FALSE) -> Hospital | R26: =K26&"-"&Q26 -> Home-Hospital | S26: 3 | T26: 0.1 | U26: 1 | Y26: Y | Z26: 3000 | AA26: =VLOOKUP(F26,Zones!$A$2:$F$2186,6,FALSE) -> 1408 | AB26: =VLOOKUP(L26,Zones!$A$2:$F$2186,6,FALSE) -> 521
B27: 0.43402778 | C27: UAW 117W | D27: 1 | E27: 3 | F27: MASOOLI | G27: WAKISO | H27: UGA | I27: 1 | J27: 1 | K27: =VLOOKUP(J27,Key!$E$2:$F$9,2,FALSE) -> Home | L27: KAMPALA | M27: KAMPALA | N27: UGA | O27: 5 | P27: 7 | Q27: =VLOOKUP(P27,Key!$E$2:$F$9,2,FALSE) -> Hospital | R27: =K27&"-"&Q27 -> Home-Hospital | S27: 1.5 | T27: 0.1 | U27: 1 | Y27: Y | Z27: 2000 | AA27: =VLOOKUP(F27,Zones!$A$2:$F$2186,6,FALSE) -> 542 | AB27: =VLOOKUP(L27,Zones!$A$2:$F$2186,6,FALSE) -> 521
B28: 0.44027778 | C28: UAH 787V | D28: 2 | E28: 1 | F28: NANGABO | G28: WAKISO | H28: UGA | I28: 1 | J28: 1 | K28: =VLOOKUP(J28,Key!$E$2:$F$9,2,FALSE) -> Home | L28: GAYAZA | M28: WAKISO | N28: UGA | O28: 7 | P28: 4 | Q28: =VLOOKUP(P28,Key!$E$2:$F$9,2,FALSE) -> Commercial | R28: =K28&"-"&Q28 -> Home-Commercial | S28: 5 | T28: 0.1 | U28: 1 | Y28: Y | Z28: 1000 | AA28: =VLOOKUP(F28,Zones!$A$2:$F$2186,6,FALSE) -> 1393 | AB28: =VLOOKUP(L28,Zones!$A$2:$F$2186,6,FALSE) -> 811
B29: 0.44305556 | C29: UAZ 508R | D29: 1 | E29: 2 | F29: GITTA | G29: WAKISO | H29: UGA | I29: 1 | J29: 4 | K29: =VLOOKUP(J29,Key!$E$2:$F$9,2,FALSE) -> Commercial | L29: KASANGATTI | M29: WAKISO | N29: UGA | O29: 7 | P29: 4 | Q29: =VLOOKUP(P29,Key!$E$2:$F$9,2,FALSE) -> Commercial | R29: =K29&"-"&Q29 -> Commercial-Commercial | T29: 0.3 | U29: 1 | Y29: Y | Z29: 1000 | AA29: =VLOOKUP(F29,Zones!$A$2:$F$2186,6,FALSE) -> 1393 | AB29: =VLOOKUP(L29,Zones!$A$2:$F$2186,6,FALSE) -> 1393
B30: 0.44722222 | C30: UAL 858S | D30: 1 | E30: 2 | F30: KITAGOBWA | G30: WAKISO | H30: UGA | I30: 1 | J30: 4 | K30: =VLOOKUP(J30,Key!$E$2:$F$9,2,FALSE) -> Commercial | L30: KASANGATTI | M30: WAKISO | N30: UGA | O30: 7 | P30: 4 | Q30: =VLOOKUP(P30,Key!$E$2:$F$9,2,FALSE) -> Commercial | R30: =K30&"-"&Q30 -> Commercial-Commercial | S30: 10 | T30: 0.3 | U30: 4 | Y30: Y | Z30: 1000 | AA30: =VLOOKUP(F30,Zones!$A$2:$F$2186,6,FALSE) -> 1408 | AB30: =VLOOKUP(L30,Zones!$A$2:$F$2186,6,FALSE) -> 1393
B31: 0.50763889 | C31: UAM 016T | D31: 1 | E31: 1 | F31: KITI | G31: WAKISO | H31: UGA | I31: 1 | J31: 2 | K31: =VLOOKUP(J31,Key!$E$2:$F$9,2,FALSE) -> Work | L31: KASANGATTI | M31: WAKISO | N31: UGA | O31: 2 | P31: 2 | Q31: =VLOOKUP(P31,Key!$E$2:$F$9,2,FALSE) -> Work | R31: =K31&"-"&Q31 -> Work-Work | S31: 25 | T31: 0.1 | U31: 1 | Y31: Y | Z31: 1000 | AA31: =VLOOKUP(F31,Zones!$A$2:$F$2186,6,FALSE) -> 1402 | AB31: =VLOOKUP(L31,Zones!$A$2:$F$2186,6,FALSE) -> 1393
B32: 0.50416667 | C32: UBB 033X | D32: 1 | E32: 3 | F32: KITI | G32: WAKISO | H32: UGA | I32: 1 | J32: 3 | K32: =VLOOKUP(J32,Key!$E$2:$F$9,2,FALSE) -> Study | L32: NAALYA | M32: KAMPALA | N32: UGA | O32: 4 | P32: 3 | Q32: =VLOOKUP(P32,Key!$E$2:$F$9,2,FALSE) -> Study | R32: =K32&"-"&Q32 -> Study-Study | S32: 3 | T32: 0.1 | U32: 1 | Y32: Y | Z32: 1000 | AA32: =VLOOKUP(F32,Zones!$A$2:$F$2186,6,FALSE) -> 1402 | AB32: =VLOOKUP(L32,Zones!$A$2:$F$2186,6,FALSE) -> 1405
B33: 0.45486111 | C33: UAT 557Z | D33: 1 | E33: 1 | F33: KITAGOBWA | G33: WAKISO | H33: UGA | I33: 1 | J33: 4 | K33: =VLOOKUP(J33,Key!$E$2:$F$9,2,FALSE) -> Commercial | L33: KAMPALA | M33: KAMPALA | N33: UGA | O33: 7 | P33: 4 | Q33: =VLOOKUP(P33,Key!$E$2:$F$9,2,FALSE) -> Commercial | R33: =K33&"-"&Q33 -> Commercial-Commercial | S33: 3 | T33: 0.2 | U33: 1 | Y33: Y | Z33: 1000 | AA33: =VLOOKUP(F33,Zones!$A$2:$F$2186,6,FALSE) -> 1408 | AB33: =VLOOKUP(L33,Zones!$A$2:$F$2186,6,FALSE) -> 521
B34: 0.45347222 | C34: UAZ 646P | D34: 7 | E34: 1 | F34: ZANA | G34: KAMPALA | H34: UGA | I34: 1 | J34: 2 | K34: =VLOOKUP(J34,Key!$E$2:$F$9,2,FALSE) -> Work | L34: NAKASERO | M34: KAMPALA | N34: UGA | O34: 2 | P34: 2 | Q34: =VLOOKUP(P34,Key!$E$2:$F$9,2,FALSE) -> Work | R34: =K34&"-"&Q34 -> Work-Work | S34: 12 | T34: 3 | U34: 6 | V34: 11 | Y34: Y | Z34: 2000 | AA34: =VLOOKUP(F34,Zones!$A$2:$F$2186,6,FALSE) -> 565 | AB34: =VLOOKUP(L34,Zones!$A$2:$F$2186,6,FALSE) -> 566
B35: 0.45972222 | C35: UAP 666J | D35: 1 | E35: 2 | F35: KITAGOBWA | G35: WAKISO | H35: UGA | I35: 1 | J35: 2 | K35: =VLOOKUP(J35,Key!$E$2:$F$9,2,FALSE) -> Work | L35: KAMPALA | M35: KAMPALA | N35: UGA | O35: 2 | P35: 2 | Q35: =VLOOKUP(P35,Key!$E$2:$F$9,2,FALSE) -> Work | R35: =K35&"-"&Q35 -> Work-Work | S35: 4 | T35: 1 | U35: 1 | Y35: Y | Z35: 1000 | AA35: =VLOOKUP(F35,Zones!$A$2:$F$2186,6,FALSE) -> 1408 | AB35: =VLOOKUP(L35,Zones!$A$2:$F$2186,6,FALSE) -> 521
B36: 0.46180556 | C36: UBB 762V | D36: 1 | E36: 1 | F36: NANGABO | G36: WAKISO | H36: UGA | I36: 1 | J36: 2 | K36: =VLOOKUP(J36,Key!$E$2:$F$9,2,FALSE) -> Work | L36: KAMPALA | M36: KAMPALA | N36: UGA | O36: 2 | P36: 2 | Q36: =VLOOKUP(P36,Key!$E$2:$F$9,2,FALSE) -> Work | R36: =K36&"-"&Q36 -> Work-Work | S36: 2 | T36: 0.1 | U36: 1 | Y36: Y | Z36: 1000 | AA36: =VLOOKUP(F36,Zones!$A$2:$F$2186,6,FALSE) -> 1393 | AB36: =VLOOKUP(L36,Zones!$A$2:$F$2186,6,FALSE) -> 521
B37: 0.49652778 | C37: UBB 501B | D37: 1 | E37: 3 | F37: NANGABO | G37: WAKISO | H37: UGA | I37: 1 | J37: 1 | K37: =VLOOKUP(J37,Key!$E$2:$F$9,2,FALSE) -> Home | L37: KAMPALA | M37: KAMPALA | N37: UGA | O37: 2 | P37: 2 | Q37: =VLOOKUP(P37,Key!$E$2:$F$9,2,FALSE) -> Work | R37: =K37&"-"&Q37 -> Home-Work | S37: 2 | T37: 0.2 | U37: 2 | Y37: Y | Z37: 2000 | AA37: =VLOOKUP(F37,Zones!$A$2:$F$2186,6,FALSE) -> 1393 | AB37: =VLOOKUP(L37,Zones!$A$2:$F$2186,6,FALSE) -> 521
B38: 0.49583333 | C38: UAK 084B | D38: 1 | E38: 1 | F38: NANGABO | G38: WAKISO | H38: UGA | I38: 1 | J38: 1 | K38: =VLOOKUP(J38,Key!$E$2:$F$9,2,FALSE) -> Home | L38: MPERRWE | M38: KAMPALA | N38: UGA | O38: 10 | P38: 4 | Q38: =VLOOKUP(P38,Key!$E$2:$F$9,2,FALSE) -> Commercial | R38: =K38&"-"&Q38 -> Home-Commercial | S38: 2 | T38: 0.1 | U38: 1 | Y38: Y | Z38: 1500 | AA38: =VLOOKUP(F38,Zones!$A$2:$F$2186,6,FALSE) -> 1393 | AB38: =VLOOKUP(L38,Zones!$A$2:$F$2186,6,FALSE) -> 559
B39: 0.49930556 | C39: UAG 564B | D39: 4 | E39: 6 | F39: KITI | G39: WAKISO | H39: UGA | I39: 1 | J39: 7 | K39: =VLOOKUP(J39,Key!$E$2:$F$9,2,FALSE) -> Hospital | L39: KASANGATTI | M39: WAKISO | N39: UGA | O39: 5 | P39: 7 | Q39: =VLOOKUP(P39,Key!$E$2:$F$9,2,FALSE) -> Hospital | R39: =K39&"-"&Q39 -> Hospital-Hospital | S39: 5 | T39: 0.1 | U39: 1 | Y39: Y | Z39: 2000 | AA39: =VLOOKUP(F39,Zones!$A$2:$F$2186,6,FALSE) -> 1402 | AB39: =VLOOKUP(L39,Zones!$A$2:$F$2186,6,FALSE) -> 1393
B40: 0.49791667 | C40: UAQ 112T | D40: 1 | E40: 3 | F40: KITAGOBWA | G40: WAKISO | H40: UGA | I40: 1 | J40: 6 | K40: =VLOOKUP(J40,Key!$E$2:$F$9,2,FALSE) -> Leisure/Social | L40: LUTETE | M40: WAKISO | N40: UGA | O40: 1 | P40: 6 | Q40: =VLOOKUP(P40,Key!$E$2:$F$9,2,FALSE) -> Leisure/Social | R40: =K40&"-"&Q40 -> Leisure/Social-Leisure/Social | S40: 2 | T40: 0.1 | U40: 1 | Y40: Y | Z40: 1000 | AA40: =VLOOKUP(F40,Zones!$A$2:$F$2186,6,FALSE) -> 1408 | AB40: =VLOOKUP(L40,Zones!$A$2:$F$2186,6,FALSE) -> 542
B41: 0.46597222 | C41: UAV 218T | D41: 1 | E41: 1 | F41: KITI | G41: WAKISO | H41: UGA | I41: 1 | J41: 7 | K41: =VLOOKUP(J41,Key!$E$2:$F$9,2,FALSE) -> Hospital | L41: SEETA | M41: MUKONO | N41: UGA | O41: 5 | P41: 7 | Q41: =VLOOKUP(P41,Key!$E$2:$F$9,2,FALSE) -> Hospital | R41: =K41&"-"&Q41 -> Hospital-Hospital | S41: 5 | T41: 0.3 | U41: 6 | Y41: Y | Z41: 2000 | AA41: =VLOOKUP(F41,Zones!$A$2:$F$2186,6,FALSE) -> 1402 | AB41: =VLOOKUP(L41,Zones!$A$2:$F$2186,6,FALSE) -> 1071
B42: 0.47291667 | C42: UBF 607T | D42: 8 | E42: 1 | F42: NANGABO | G42: WAKISO | H42: UGA | I42: 1 | J42: 2 | K42: =VLOOKUP(J42,Key!$E$2:$F$9,2,FALSE) -> Work | L42: KASANGATTI | M42: WAKISO | N42: UGA | O42: 3 | P42: 3 | Q42: =VLOOKUP(P42,Key!$E$2:$F$9,2,FALSE) -> Study | R42: =K42&"-"&Q42 -> Work-Study | T42: 2 | U42: 1 | V42: 11 | Y42: Y | Z42: 15000 | AA42: =VLOOKUP(F42,Zones!$A$2:$F$2186,6,FALSE) -> 1393 | AB42: =VLOOKUP(L42,Zones!$A$2:$F$2186,6,FALSE) -> 1393
...

Sheet Zones
A1: ZONE NAME | B1: DISTRICT | C1: COUNTY | D1: SUBCOUNTY | E1: Parish | F1: ZONE No.
A2: Abim | B2: Abim | C2: Labwor | D2: =A2 -> Abim | F2: 1
A3: Abim Town Council | B3: Abim | C3: Labwor | D3: =A3 -> Abim Town Council | F3: 2
A4: Alerek | B4: Abim | C4: Labwor | D4: =A4 -> Alerek | F4: 3
A5: Lotukei | B5: Abim | C5: Labwor | D5: =A5 -> Lotukei | F5: 4
A6: Morulem | B6: Abim | C6: Labwor | D6: =A6 -> Morulem | F6: 5
A7: Nyakwae | B7: Abim | C7: Labwor | D7: =A7 -> Nyakwae | F7: 6
A8: Adjumani Town Council | B8: Adjumani | C8: East Moyo | D8: =A8 -> Adjumani Town Council | F8: 7
A9: Adropi | B9: Adjumani | C9: East Moyo | D9: =A9 -> Adropi | F9: 8
A10: Arinyapi | B10: Adjumani | C10: East Moyo | D10: =A10 -> Arinyapi | F10: 9
A11: Ciforo | B11: Adjumani | C11: East Moyo | D11: =A11 -> Ciforo | F11: 10
A12: Dzaipi | B12: Adjumani | C12: East Moyo | D12: =A12 -> Dzaipi | F12: 11
A13: Itirikwa | B13: Adjumani | C13: East Moyo | D13: =A13 -> Itirikwa | F13: 12
... A75: Amuru Town Council | B75: Amuru | C75: Kilak | D75: =A75 -> Amuru Town Council | F75: 74
A76: Amur town | D76: =A76 -> Amur town | F76: 74
A77: Attiak | B77: Amuru | C77: Kilak | D77: =A77 -> Attiak | F77: 75
A78: Lamogi | B78: Amuru | C78: Kilak | D78: =A78 -> Lamogi | F78: 76
A79: Pabo | B79: Amuru | C79: Kilak | D79: =A79 -> Pabo | F79: 77
A80: Abongomola | B80: Apac | C80: Kwania | D80: =A80 -> Abongomola | F80: 78
A81: Aduku | B81: Apac | C81: Kwania | D81: =A81 -> Aduku | F81: 79
A82: Aduku Town Council | B82: Apac | C82: Kwania | D82: =A82 -> Aduku Town Council | F82: 80
A83: Akokoro | B83: Apac | C83: Maruzi | D83: =A83 -> Akokoro | F83: 81
A84: Apac Muicipality | B84: Apac | C84: Apac Municipality | D84: =A84 -> Apac Muicipality | F84: 82
A85: Chawente | B85: Apac | C85: Kwania | D85: =A85 -> Chawente | F85: 83
A86: Chegere | B86: Apac | C86: Maruzi | D86: =A86 -> Chegere | F86: 84
A87: Ibuje | B87: Apac | C87: Maruzi | D87: =A87 -> Ibuje | F87: 85
A88: Inomo | B88: Apac | C88: Kwania | D88: =A88 -> Inomo | F88: 86
... A96: Arua Municipality | B96: Arua | C96: Arua Municipality | D96: =A96 -> Arua Municipality | F96: 94
A97: Arua | F97: 94
A98: Ayivuni | B98: Arua | C98: Ayivu | D98: =A98 -> Ayivuni | F98: 95
A99: Bileafe | B99: Arua | C99: Terego | D99: =A99 -> Bileafe | F99: 96
A100: Dadamu | B100: Arua | C100: Ayivu | D100: =A100 -> Dadamu | F100: 97
A101: Ewanga | B101: Arua | C101: Madi Okollo | D101: =A101 -> Ewanga | F101: 98
A102: Katrini | B102: Arua | C102: Terego | D102: =A102 -> Katrini | F102: 99
A103: Logiri | B103: Arua | C103: Vurra | D103: =A103 -> Logiri | F103: 100
A104: Manibe | B104: Arua | C104: Ayivu | D104: =A104 -> Manibe | F104: 101
A105: Odupi | B105: Arua | C105: Terego | D105: =A105 -> Odupi | F105: 102
A106: Offaka | B106: Arua | C106: Madi Okollo | D106: =A106 -> Offaka | F106: 103
A107: Ogoko | B107: Arua | C107: Madi Okollo | D107: =A107 -> Ogoko | F107: 104
A108: Okollo | B108: Arua | C108: Madi Okollo | D108: =A108 -> Okollo | F108: 105
...

Sheet Zone analysis
A1: Zone | B1: District | C1: County | D1: Subcounty | E1: Parish | F1: DRAFT FINAL ZONE LIST | G1: DISTRICT | H1: Subcounty
A2: 243 | B2: Alebtong | C2: Moroto | D2: Abako | F2: =D2 -> Abako | G2: =B2 -> Alebtong | H2: Abako
A3: 295 | B3: Zombo | C3: Okoro | D3: Abanga | F3: =D3 -> Abanga | G3: =B3 -> Zombo | H3: Abanga
A4: 886 | B4: Amuria | C4: Amuria | D4: Abarilela | F4: =D4 -> Abarilela | G4: =B4 -> Amuria | H4: Abarilela
A5: 215 | B5: Oyam | C5: Oyam | D5: Aber | F5: =D5 -> Aber | G5: =B5 -> Oyam | H5: Aber
A6: 244 | B6: Alebtong | C6: Moroto | D6: Abia | F6: =D6 -> Abia | G6: =B6 -> Alebtong | H6: Abia
A7: 151 | B7: Abim | C7: Labwor | D7: Abim | F7: =D7 -> Abim | G7: =B7 -> Abim | H7: Abim
A8: 152 | B8: Abim | C8: Labwor | D8: Abim Town Council | F8: =D8 -> Abim Town Council | G8: =B8 -> Abim | H8: Abim Town Council
A9: 107 | B9: Nebbi | C9: Nebbi Municipality | D9: Abindu Division | F9: =VLOOKUP(C9,[2]Municipalities!$C$9:$F$1522,4,FALSE) -> Nebbi Municipality | G9: =B9 -> Nebbi | H9: Abindu Division
A10: 216 | B10: Oyam | C10: Oyam | D10: Abok | F10: =D10 -> Abok | G10: =B10 -> Oyam | H10: Abok
A11: 256 | B11: Kole | C11: Kole | D11: Aboke | F11: =D11 -> Aboke | G11: =B11 -> Kole | H11: Aboke
A12: 11 | B12: Apac | C12: Kwania | D12: Abongomola | F12: =D12 -> Abongomola | G12: =B12 -> Apac | H12: Abongomola
A13: 198 | B13: Koboko | C13: Koboko | D13: Abuku | F13: =D13 -> Abuku | G13: =B13 -> Koboko | H13: Abuku
A14: 217 | B14: Oyam | C14: Oyam | D14: Acaba | F14: =D14 -> Acaba | G14: =B14 -> Oyam | H14: Acaba
A15: 126 | B15: Pader | C15: Aruu | D15: Acholibur | F15: =D15 -> Acholibur | G15: =B15 -> Pader | H15: Acholibur
A16: 897 | B16: Amuria | C16: Kapelebyong | D16: Acowa | F16: =D16 -> Acowa | G16: =B16 -> Amuria | H16: Acowa
A17: 173 | B17: Dokolo | C17: Dokolo | D17: Adeknino | F17: =D17 -> Adeknino | G17: =B17 -> Dokolo | H17: Adeknino
A18: 79 | B18: Lira | C18: Erute | D18: Adekokwok | F18: =D18 -> Adekokwok | G18: =B18 -> Lira | H18: Adekokwok
A19: 227 | B19: Agago | C19: Agago | D19: Adilang | F19: =D19 -> Adilang | G19: =B19 -> Agago | H19: Adilang
A20: 1 | B20: Adjumani | C20: East Moyo | D20: Adjumani Town Council | F20: =D20 -> Adjumani Town Council | G20: =B20 -> Adjumani | H20: Adjumani Town Council
A21: 174 | B21: Dokolo | C21: Dokolo | D21: Adok | F21: =D21 -> Adok | G21: =B21 -> Dokolo | H21: Adok
... A26: 287 | B26: Otuke | C26: Otuke | D26: Adwari | F26: =D26 -> Adwari | G26: =B26 -> Otuke | H26: Adwari
A27: 88 | B27: Lira | C27: Lira Municipality | D27: Adyel Division | F27: =VLOOKUP(C27,[2]Municipalities!$C$9:$F$1522,4,FALSE) -> Lira Municipality | G27: =B27 -> Lira | H27: Adyel Division
A28: 228 | B28: Agago | C28: Agago | D28: Agago Town Council | F28: =D28 -> Agago Town Council | G28: =B28 -> Agago | H28: Agago Town Council
A29: 80 | B29: Lira | C29: Erute | D29: Agali | F29: =D29 -> Agali | G29: =B29 -> Lira | H29: Agali
A30: 157 | B30: Amolatar | C30: Kioga | D30: Agikdak | F30: =D30 -> Agikdak | G30: =B30 -> Amolatar | H30: Agikdak
A31: 263 | B31: Lamwo | C31: Lamwo | D31: Agoro | F31: =D31 -> Agoro | G31: =B31 -> Lamwo | H31: Agoro
A32: 802 | B32: Pallisa | C32: Agule | D32: Agule | F32: =D32 -> Agule | G32: =B32 -> Pallisa | H32: Agule
A33: 175 | B33: Dokolo | C33: Dokolo | D33: Agwata | F33: =D33 -> Agwata | G33: =B33 -> Dokolo | H33: Agwata
A34: 81 | B34: Lira | C34: Erute | D34: Agweng | F34: =D34 -> Agweng | G34: =B34 -> Lira | H34: Agweng
A35: 158 | B35: Amolatar | C35: Kioga | D35: Agwingiri | F35: =D35 -> Agwingiri | G35: =B35 -> Amolatar | H35: Agwingiri
A36: 40 | B36: Arua | C36: Terego | D36: Aii-Vu | F36: =D36 -> Aii-Vu | G36: =B36 -> Arua | H36: Aii-Vu
A37: 46 | B37: Arua | C37: Vurra | D37: Ajia | F37: =D37 -> Ajia | G37: =B37 -> Arua | H37: Ajia
A38: 257 | B38: Kole | C38: Kole | D38: Akalo | F38: =D38 -> Akalo | G38: =B38 -> Kole | H38: Akalo
A39: 887 | B39: Amuria | C39: Amuria | D39: Akeriau | F39: =D39 -> Akeriau | G39: =B39 -> Amuria | H39: Akeriau
... A70: 31 | B70: Arua | C70: Madi Okollo | D70: Anyiribu | F70: =D70 -> Anyiribu | G70: =B70 -> Arua | H70: Anyiribu
A71: 20 | B71: Apac | C71: Apac Municipality | D71: Apac | F71: =VLOOKUP(C71,[2]Municipalities!$C$9:$F$1522,4,FALSE) -> Apac Muicipality | G71: =B71 -> Apac | H71: Apac
A72: 21 | B72: Apac | C72: Apac Municipality | D72: Apac Town Council | F72: =VLOOKUP(C72,[2]Municipalities!$C$9:$F$1522,4,FALSE) -> Apac Muicipality | G72: =B72 -> Apac | H72: Apac Town Council
A73: 249 | B73: Alebtong | C73: Moroto | D73: Apala | F73: =D73 -> Apala | G73: =B73 -> Alebtong | H73: Apala
A74: 846 | B74: Kaberamaido | C74: Kalaki | D74: Apapai | F74: =D74 -> Apapai | G74: =B74 -> Kaberamaido | H74: Apapai
...

Sheet 12.10 MATUGGA-KASANGATTI
B1: Consultancy services for Preparation of Expressway Develo PMent Master Plan (EDMP) for Uganda
B2: Roadside OD Interview Survey
B4: Date: | C4: 12.10.19 | E4: Road Name: | F4: ='14.10 KASANGATI-MATUGGA'!F4:G4 -> MATUGGA-WAKISO ROAD | I4: Direction From: | L4: MATUGGA | N4: Interviewers: | O4: SHAMIRAH, JULIUS | V4: Supervisor: | W4: STEVEN | Y4: Coded By: | Z4: ='14.10 KASANGATI-MATUGGA'!Z4 -> DAVID | AA4: Chkd By: | AB4: Bakole Deo
I5: Direction To: | L5: KASANGATTI
B7: Time | C7: Veh_Reg_No. | D7: Veh_Type | E7: No. Occupants | F7: Origin_Address | I7: Origin_Establish | J7: Origin_Purpose | K7: Origin-Purpose Desc | L7: Destination_Address | O7: Destination_Establish | P7: Destination_Purpose | Q7: Destination_Purpose Desc | R7: Journey_Purpose | S7: Approx_Distance (Km) | T7: Approx_Journey Time (Hrs) | U7: Trip_Frequency | V7: GOODS VEHICLES ONLY | Y7: Would You Use Xpressways? | Z7: Pay How Much? (UGX) | AA7: Origin_Zone | AB7: Dest_Zone
F8: Village or Town | G8: District | H8: Country | L8: Village or Town | M8: District | N8: Country | V8: Goods_Type | W8: Goods_Quantity (Ton) | X8: Goods_Value (UGXm)
B9: 0.67152778 | C9: UAP 387B | D9: 8 | E9: 1 | F9: MAGORA | G9: WAKISO | H9: UGA | I9: 9 | J9: 1 | K9: =VLOOKUP(J9,Key!$E$2:$F$9,2,FALSE) -> Home | L9: KASANGATTI | M9: WAKISO | N9: UGA | O9: 1 | P9: 1 | Q9: =VLOOKUP(P9,Key!$E$2:$F$9,2,FALSE) -> Home | R9: =K9&"-"&Q9 -> Home-Home | U9: 1 | V9: 11 | Y9: Y | Z9: 3000
B10: 0.67291667 | C10: UAN 185N | D10: 1 | E10: 2 | F10: MABUSU | G10: WAKISO | H10: UGA | I10: 7 | J10: 1 | K10: =VLOOKUP(J10,Key!$E$2:$F$9,2,FALSE) -> Home | L10: BUKOTO | M10: KAMPALA | N10: UGA | O10: 1 | P10: 1 | Q10: =VLOOKUP(P10,Key!$E$2:$F$9,2,FALSE) -> Home | R10: =K10&"-"&Q10 -> Home-Home | S10: 3 | U10: 1 | Y10: Y | Z10: 3500
B11: 0.62222222 | C11: UAK 338U | D11: 1 | E11: 5 | F11: KITI | G11: WAKISO | H11: UGA | I11: 1 | J11: 3 | K11: =VLOOKUP(J11,Key!$E$2:$F$9,2,FALSE) -> Study | L11: KIIRA | M11: WAKISO | N11: UGA | O11: 4 | P11: 3 | Q11: =VLOOKUP(P11,Key!$E$2:$F$9,2,FALSE) -> Study | R11: =K11&"-"&Q11 -> Study-Study | T11: 0.1 | U11: 1 | Y11: Y | Z11: 3500
B12: 0.625 | C12: UBE 33Q | D12: 1 | E12: 4 | F12: MATUGGA | G12: WAKISO | H12: UGA | I12: 1 | J12: 8 | K12: =VLOOKUP(J12,Key!$E$2:$F$9,2,FALSE) -> Others | L12: MULAGO | M12: KAMPALA | N12: UGA | O12: 4 | P12: 8 | Q12: =VLOOKUP(P12,Key!$E$2:$F$9,2,FALSE) -> Others | R12: =K12&"-"&Q12 -> Others-Others | S12: 7 | T12: 0.2 | U12: 5 | Y12: Y | Z12: 1000
B13: 0.62986111 | C13: UAL 290P | D13: 1 | E13: 2 | F13: MUGABO | G13: WAKISO | H13: UGA | I13: 1 | J13: 2 | K13: =VLOOKUP(J13,Key!$E$2:$F$9,2,FALSE) -> Work | L13: KASANGATTI | M13: WAKISO | N13: UGA | O13: 7 | P13: 4 | Q13: =VLOOKUP(P13,Key!$E$2:$F$9,2,FALSE) -> Commercial | R13: =K13&"-"&Q13 -> Work-Commercial | T13: 0.1 | U13: 1 | Y13: Y | Z13: 400
B14: 0.62777778 | C14: UBB 241W | D14: 1 | E14: 1 | F14: KITI | G14: WAKISO | H14: UGA | I14: 1 | J14: 7 | K14: =VLOOKUP(J14,Key!$E$2:$F$9,2,FALSE) -> Hospital | L14: GAYAZA | M14: WAKISO | N14: UGA | O14: 5 | P14: 7 | Q14: =VLOOKUP(P14,Key!$E$2:$F$9,2,FALSE) -> Hospital | R14: =K14&"-"&Q14 -> Hospital-Hospital | S14: 5 | T14: 0.1 | U14: 1 | Y14: Y | Z14: 5000
B15: 0.65833333 | C15: UBE 794R | D15: 1 | E15: 3 | F15: KITI | G15: WAKISO | H15: UGA | I15: 1 | J15: 1 | K15: =VLOOKUP(J15,Key!$E$2:$F$9,2,FALSE) -> Home | L15: KASANGATTI | M15: WAKISO | N15: UGA | O15: 5 | P15: 7 | Q15: =VLOOKUP(P15,Key!$E$2:$F$9,2,FALSE) -> Hospital | R15: =K15&"-"&Q15 -> Home-Hospital | S15: 2 | T15: 0.1 | U15: 6 | Y15: Y | Z15: 500
B16: 0.66319444 | C16: UBA 121B | D16: 3 | E16: 2 | F16: WAGABO | G16: WAKISO | H16: UGA | I16: 1 | J16: 6 | K16: =VLOOKUP(J16,Key!$E$2:$F$9,2,FALSE) -> Leisure/Social | L16: KASANGATTI | M16: WAKISO | N16: UGA | O16: 7 | P16: 6 | Q16: =VLOOKUP(P16,Key!$E$2:$F$9,2,FALSE) -> Leisure/Social | R16: =K16&"-"&Q16 -> Leisure/Social-Leisure/Social | S16: 0.5 | T16: 0.1 | U16: 1 | Y16: Y | Z16: 1000
B17: 0.61458333 | C17: UAY 217M | D17: 1 | E17: 2 | F17: MATUGGA | G17: WAKISO | H17: UGA | I17: 1 | J17: 6 | K17: =VLOOKUP(J17,Key!$E$2:$F$9,2,FALSE) -> Leisure/Social | L17: GAYAZA | M17: WAKISO | N17: UGA | O17: 1 | P17: 6 | Q17: =VLOOKUP(P17,Key!$E$2:$F$9,2,FALSE) -> Leisure/Social | R17: =K17&"-"&Q17 -> Leisure/Social-Leisure/Social | S17: 7 | T17: 0.1 | U17: 1 | Y17: Y | Z17: 1000
B18: 0.61180556 | C18: UAZ 061X | D18: 1 | E18: 6 | F18: MAWULAR | G18: WAKISO | H18: UGA | I18: 1 | J18: 6 | K18: =VLOOKUP(J18,Key!$E$2:$F$9,2,FALSE) -> Leisure/Social | L18: STAGAZA | M18: WAKISO | N18: UGA | O18: 1 | P18: 6 | Q18: =VLOOKUP(P18,Key!$E$2:$F$9,2,FALSE) -> Leisure/Social | R18: =K18&"-"&Q18 -> Leisure/Social-Leisure/Social | S18: 3 | T18: 0.1 | U18: 1 | Y18: Y | Z18: 200
B19: 0.64097222 | C19: UBA 239X | D19: 1 | E19: 2 | F19: NANGABO | G19: WAKISO | H19: UGA | I19: 1 | J19: 6 | K19: =VLOOKUP(J19,Key!$E$2:$F$9,2,FALSE) -> Leisure/Social | L19: KASANGATTI | M19: WAKISO | N19: UGA | O19: 7 | P19: 6 | Q19: =VLOOKUP(P19,Key!$E$2:$F$9,2,FALSE) -> Leisure/Social | R19: =K19&"-"&Q19 -> Leisure/Social-Leisure/Social | S19: 0.5 | T19: 0.1 | U19: 6 | Y19: Y | Z19: 2000
B20: 0.6375 | C20: UBE 072G | D20: 1 | E20: 5 | F20: MAKULO | G20: WAKISO | H20: UGA | I20: 1 | J20: 5 | K20: =VLOOKUP(J20,Key!$E$2:$F$9,2,FALSE) -> Tourism | L20: KASANGATTI | M20: WAKISO | N20: UGA | O20: 1 | P20: 1 | Q20: =VLOOKUP(P20,Key!$E$2:$F$9,2,FALSE) -> Home | R20: =K20&"-"&Q20 -> Tourism-Home | T20: 0.1 | U20: 1 | Y20: Y | Z20: 500
B21: 0.61944444 | C21: UAM 669D | D21: 1 | E21: 4 | F21: NANGABO | G21: WAKISO | H21: UGA | I21: 1 | J21: 1 | K21: =VLOOKUP(J21,Key!$E$2:$F$9,2,FALSE) -> Home | L21: MULAGO | M21: KAMPALA | N21: UGA | O21: 1 | P21: 1 | Q21: =VLOOKUP(P21,Key!$E$2:$F$9,2,FALSE) -> Home | R21: =K21&"-"&Q21 -> Home-Home | S21: 2 | T21: 0.1 | U21: 1 | Y21: Y | Z21: 3000
B22: 0.61666667 | C22: UBA 695R | D22: 2 | E22: 2 | F22: NANGABO | G22: WAKISO | H22: UGA | I22: 1 | J22: 2 | K22: =VLOOKUP(J22,Key!$E$2:$F$9,2,FALSE) -> Work | L22: KAMPALA | M22: KAMPALA | N22: UGA | O22: 2 | P22: 2 | Q22: =VLOOKUP(P22,Key!$E$2:$F$9,2,FALSE) -> Work | R22: =K22&"-"&Q22 -> Work-Work | S22: 1.5 | T22: 0.1 | U22: 1 | Y22: Y | Z22: 5000
B23: 0.42986111 | C23: UAR 383B | D23: 1 | E23: 2 | F23: MASAACHI | G23: WAKISO | H23: UGA | I23: 1 | J23: 2 | K23: =VLOOKUP(J23,Key!$E$2:$F$9,2,FALSE) -> Work | L23: KASANGATTI | M23: WAKISO | N23: UGA | O23: 3 | P23: 2 | Q23: =VLOOKUP(P23,Key!$E$2:$F$9,2,FALSE) -> Work | R23: =K23&"-"&Q23 -> Work-Work | S23: 1 | T23: 0.1 | U23: 1 | Y23: Y | Z23: 1000
B24: 0.43125 | C24: UAP 465T | D24: 1 | E24: 6 | F24: NAMALOLO | G24: WAKISO | H24: UGA | I24: 1 | J24: 6 | K24: =VLOOKUP(J24,Key!$E$2:$F$9,2,FALSE) -> Leisure/Social | L24: NATEETE | M24: KAMPALA | N24: UGA | O24: 1 | P24: 1 | Q24: =VLOOKUP(P24,Key!$E$2:$F$9,2,FALSE) -> Home | R24: =K24&"-"&Q24 -> Leisure/Social-Home | S24: 10 | T24: 0.3 | U24: 1 | Y24: Y | Z24: 1000
B25: 0.58333333 | C25: UBE 012B | D25: 2 | E25: 3 | F25: MPERERWE | G25: KAMPALA | H25: UGA | I25: 3 | J25: 4 | K25: =VLOOKUP(J25,Key!$E$2:$F$9,2,FALSE) -> Commercial | L25: GAYAZA | M25: WAKISO | N25: UGA | O25: 4 | P25: 4 | Q25: =VLOOKUP(P25,Key!$E$2:$F$9,2,FALSE) -> Commercial | R25: =K25&"-"&Q25 -> Commercial-Commercial | T25: 0.1 | U25: 1 | V25: 4 | W25: 1.5 | X25: 2 | Y25: Y | Z25: 2500
B26: 0.83194444 | C26: UAG 516K | D26: 1 | E26: 2 | F26: KITAGOBWA | G26: WAKISO | H26: UGA | I26: 1 | J26: 1 | K26: =VLOOKUP(J26,Key!$E$2:$F$9,2,FALSE) -> Home | L26: KAMPALA | M26: KAMPALA | N26: UGA | O26: 5 | P26: 7 | Q26: =VLOOKUP(P26,Key!$E$2:$F$9,2,FALSE) -> Hospital | R26: =K26&"-"&Q26 -> Home-Hospital | S26: 3 | T26: 0.1 | U26: 1 | Y26: Y | Z26: 3000
B27: 0.43402778 | C27: UAW 117W | D27: 1 | E27: 3 | F27: MASOOLI | G27: WAKISO | H27: UGA | I27: 1 | J27: 1 | K27: =VLOOKUP(J27,Key!$E$2:$F$9,2,FALSE) -> Home | L27: KAMPALA | M27: KAMPALA | N27: UGA | O27: 5 | P27: 7 | Q27: =VLOOKUP(P27,Key!$E$2:$F$9,2,FALSE) -> Hospital | R27: =K27&"-"&Q27 -> Home-Hospital | S27: 1.5 | T27: 0.1 | U27: 1 | Y27: Y | Z27: 2000
B28: 0.44027778 | C28: UAH 787V | D28: 2 | E28: 1 | F28: NANGABO | G28: WAKISO | H28: UGA | I28: 1 | J28: 1 | K28: =VLOOKUP(J28,Key!$E$2:$F$9,2,FALSE) -> Home | L28: GAYAZA | M28: WAKISO | N28: UGA | O28: 7 | P28: 4 | Q28: =VLOOKUP(P28,Key!$E$2:$F$9,2,FALSE) -> Commercial | R28: =K28&"-"&Q28 -> Home-Commercial | S28: 5 | T28: 0.1 | U28: 1 | Y28: Y | Z28: 1000
B29: 0.44305556 | C29: UAZ 508R | D29: 1 | E29: 2 | F29: GITTA | G29: WAKISO | H29: UGA | I29: 1 | J29: 4 | K29: =VLOOKUP(J29,Key!$E$2:$F$9,2,FALSE) -> Commercial | L29: KASANGATTI | M29: WAKISO | N29: UGA | O29: 7 | P29: 4 | Q29: =VLOOKUP(P29,Key!$E$2:$F$9,2,FALSE) -> Commercial | R29: =K29&"-"&Q29 -> Commercial-Commercial | T29: 0.3 | U29: 1 | Y29: Y | Z29: 1000
B30: 0.44722222 | C30: UAL 858S | D30: 1 | E30: 2 | F30: KITAGOBWA | G30: WAKISO | H30: UGA | I30: 1 | J30: 4 | K30: =VLOOKUP(J30,Key!$E$2:$F$9,2,FALSE) -> Commercial | L30: KASANGATTI | M30: WAKISO | N30: UGA | O30: 7 | P30: 4 | Q30: =VLOOKUP(P30,Key!$E$2:$F$9,2,FALSE) -> Commercial | R30: =K30&"-"&Q30 -> Commercial-Commercial | S30: 10 | T30: 0.3 | U30: 4 | Y30: Y | Z30: 1000
B31: 0.50763889 | C31: UAM 016T | D31: 1 | E31: 1 | F31: KITI | G31: WAKISO | H31: UGA | I31: 1 | J31: 2 | K31: =VLOOKUP(J31,Key!$E$2:$F$9,2,FALSE) -> Work | L31: KASANGATTI | M31: WAKISO | N31: UGA | O31: 2 | P31: 2 | Q31: =VLOOKUP(P31,Key!$E$2:$F$9,2,FALSE) -> Work | R31: =K31&"-"&Q31 -> Work-Work | S31: 25 | T31: 0.1 | U31: 1 | Y31: Y | Z31: 1000
B32: 0.50416667 | C32: UBB 033X | D32: 1 | E32: 3 | F32: KITI | G32: WAKISO | H32: UGA | I32: 1 | J32: 3 | K32: =VLOOKUP(J32,Key!$E$2:$F$9,2,FALSE) -> Study | L32: NAALYA | M32: KAMPALA | N32: UGA | O32: 4 | P32: 3 | Q32: =VLOOKUP(P32,Key!$E$2:$F$9,2,FALSE) -> Study | R32: =K32&"-"&Q32 -> Study-Study | S32: 3 | T32: 0.1 | U32: 1 | Y32: Y | Z32: 1000
B33: 0.45486111 | C33: UAT 557Z | D33: 1 | E33: 1 | F33: KITAGOBWA | G33: WAKISO | H33: UGA | I33: 1 | J33: 4 | K33: =VLOOKUP(J33,Key!$E$2:$F$9,2,FALSE) -> Commercial | L33: KAMPALA | M33: KAMPALA | N33: UGA | O33: 7 | P33: 4 | Q33: =VLOOKUP(P33,Key!$E$2:$F$9,2,FALSE) -> Commercial | R33: =K33&"-"&Q33 -> Commercial-Commercial | S33: 3 | T33: 0.2 | U33: 1 | Y33: Y | Z33: 1000
B34: 0.45347222 | C34: UAZ 646P | D34: 7 | E34: 1 | F34: ZANA | G34: KAMPALA | H34: UGA | I34: 1 | J34: 2 | K34: =VLOOKUP(J34,Key!$E$2:$F$9,2,FALSE) -> Work | L34: NAKASERO | M34: KAMPALA | N34: UGA | O34: 2 | P34: 2 | Q34: =VLOOKUP(P34,Key!$E$2:$F$9,2,FALSE) -> Work | R34: =K34&"-"&Q34 -> Work-Work | S34: 12 | T34: 3 | U34: 6 | V34: 11 | Y34: Y | Z34: 2000
B35: 0.45972222 | C35: UAP 666J | D35: 1 | E35: 2 | F35: KITAGOBWA | G35: WAKISO | H35: UGA | I35: 1 | J35: 2 | K35: =VLOOKUP(J35,Key!$E$2:$F$9,2,FALSE) -> Work | L35: KAMPALA | M35: KAMPALA | N35: UGA | O35: 2 | P35: 2 | Q35: =VLOOKUP(P35,Key!$E$2:$F$9,2,FALSE) -> Work | R35: =K35&"-"&Q35 -> Work-Work | S35: 4 | T35: 1 | U35: 1 | Y35: Y | Z35: 1000
B36: 0.46180556 | C36: UBB 762V | D36: 1 | E36: 1 | F36: NANGABO | G36: WAKISO | H36: UGA | I36: 1 | J36: 2 | K36: =VLOOKUP(J36,Key!$E$2:$F$9,2,FALSE) -> Work | L36: KAMPALA | M36: KAMPALA | N36: UGA | O36: 2 | P36: 2 | Q36: =VLOOKUP(P36,Key!$E$2:$F$9,2,FALSE) -> Work | R36: =K36&"-"&Q36 -> Work-Work | S36: 2 | T36: 0.1 | U36: 1 | Y36: Y | Z36: 1000
B37: 0.49652778 | C37: UBB 501B | D37: 1 | E37: 3 | F37: NANGABO | G37: WAKISO | H37: UGA | I37: 1 | J37: 1 | K37: =VLOOKUP(J37,Key!$E$2:$F$9,2,FALSE) -> Home | L37: KAMPALA | M37: KAMPALA | N37: UGA | O37: 2 | P37: 2 | Q37: =VLOOKUP(P37,Key!$E$2:$F$9,2,FALSE) -> Work | R37: =K37&"-"&Q37 -> Home-Work | S37: 2 | T37: 0.2 | U37: 2 | Y37: Y | Z37: 2000
B38: 0.49583333 | C38: UAK 084B | D38: 1 | E38: 1 | F38: NANGABO | G38: WAKISO | H38: UGA | I38: 1 | J38: 1 | K38: =VLOOKUP(J38,Key!$E$2:$F$9,2,FALSE) -> Home | L38: MPERRWE | M38: KAMPALA | N38: UGA | O38: 10 | P38: 4 | Q38: =VLOOKUP(P38,Key!$E$2:$F$9,2,FALSE) -> Commercial | R38: =K38&"-"&Q38 -> Home-Commercial | S38: 2 | T38: 0.1 | U38: 1 | Y38: Y | Z38: 1500
B39: 0.49930556 | C39: UAG 564B | D39: 4 | E39: 6 | F39: KITI | G39: WAKISO | H39: UGA | I39: 1 | J39: 7 | K39: =VLOOKUP(J39,Key!$E$2:$F$9,2,FALSE) -> Hospital | L39: KASANGATTI | M39: WAKISO | N39: UGA | O39: 5 | P39: 7 | Q39: =VLOOKUP(P39,Key!$E$2:$F$9,2,FALSE) -> Hospital | R39: =K39&"-"&Q39 -> Hospital-Hospital | S39: 5 | T39: 0.1 | U39: 1 | Y39: Y | Z39: 2000
B40: 0.49791667 | C40: UAQ 112T | D40: 1 | E40: 3 | F40: KITAGOBWA | G40: WAKISO | H40: UGA | I40: 1 | J40: 6 | K40: =VLOOKUP(J40,Key!$E$2:$F$9,2,FALSE) -> Leisure/Social | L40: LUTOOTO | M40: WAKISO | N40: UGA | O40: 1 | P40: 6 | Q40: =VLOOKUP(P40,Key!$E$2:$F$9,2,FALSE) -> Leisure/Social | R40: =K40&"-"&Q40 -> Leisure/Social-Leisure/Social | S40: 2 | T40: 0.1 | U40: 1 | Y40: Y | Z40: 1000
B41: 0.46597222 | C41: UAV 218T | D41: 1 | E41: 1 | F41: KITI | G41: WAKISO | H41: UGA | I41: 1 | J41: 7 | K41: =VLOOKUP(J41,Key!$E$2:$F$9,2,FALSE) -> Hospital | L41: SEETA | M41: MUKONO | N41: UGA | O41: 5 | P41: 7 | Q41: =VLOOKUP(P41,Key!$E$2:$F$9,2,FALSE) -> Hospital | R41: =K41&"-"&Q41 -> Hospital-Hospital | S41: 5 | T41: 0.3 | U41: 6 | Y41: Y | Z41: 2000
B42: 0.47291667 | C42: UBF 607T | D42: 8 | E42: 1 | F42: NANGABO | G42: WAKISO | H42: UGA | I42: 1 | J42: 2 | K42: =VLOOKUP(J42,Key!$E$2:$F$9,2,FALSE) -> Work | L42: KASANGATTI | M42: WAKISO | N42: UGA | O42: 3 | P42: 3 | Q42: =VLOOKUP(P42,Key!$E$2:$F$9,2,FALSE) -> Study | R42: =K42&"-"&Q42 -> Work-Study | T42: 2 | U42: 1 | V42: 11 | Y42: Y | Z42: 15000
...

Sheet 12.10 KASANGATTI-MATUGGA
B1: Consultancy services for Preparation of Expressway Develo PMent Master Plan (EDMP) for Uganda
B2: Roadside OD Interview Survey
B4: Date: | C4: ='12.10 MATUGGA-KASANGATTI'!C4 -> 12.10.19 | E4: Road Name: | F4: ='12.10 MATUGGA-KASANGATTI'!F4:G4 -> MATUGGA-WAKISO ROAD | I4: Direction From: | L4: KASANGATTI | N4: Interviewers: | O4: TUMWINE LINUS, SSEMUKO JUNIOR | V4: Supervisor: | W4: ='12.10 MATUGGA-KASANGATTI'!W4 -> STEVEN | Y4: Coded By: | Z4: ='12.10 MATUGGA-KASANGATTI'!Z4 -> DAVID | AA4: Chkd By: | AB4: ='12.10 MATUGGA-KASANGATTI'!AB4 -> Bakole Deo
I5: Direction To: | L5: MATUGGA
B7: Time | C7: Veh_Reg_No. | D7: Veh_Type | E7: No. Occupants | F7: Origin_Address | I7: Origin_Establish | J7: Origin_Purpose | K7: Origin-Purpose Desc | L7: Destination_Address | O7: Destination_Establish | P7: Destination_Purpose | Q7: Destination_Purpose Desc | R7: Journey_Purpose | S7: Approx_Distance (Km) | T7: Approx_Journey Time (Hrs) | U7: Trip_Frequency | V7: GOODS VEHICLES ONLY | Y7: Would You Use Xpressways? | Z7: Pay How Much? (UGX) | AA7: Origin_Zone | AB7: Dest_Zone
F8: Village or Town | G8: District | H8: Country | L8: Village or Town | M8: District | N8: Country | V8: Goods_Type | W8: Goods_Quantity (Ton) | X8: Goods_Value (UGXm)
B9: 0.57638889 | C9: UAS 950Y | D9: 1 | E9: 4 | F9: MUTUNGO | G9: KAMPALA | H9: UGA | I9: 1 | J9: 2 | K9: =VLOOKUP(J9,Key!$E$2:$F$9,2,FALSE) -> Work | L9: KITEGOBWA | M9: WAKISO | N9: UGA | O9: 16 | P9: 8 | Q9: =VLOOKUP(P9,Key!$E$2:$F$9,2,FALSE) -> Others | R9: =K9&"-"&Q9 -> Work-Others | T9: 1 | U9: 6 | Y9: Y | Z9: 1000
B10: 0.58055556 | C10: UAM 277S | D10: 1 | E10: 1 | F10: KASANGATTI | G10: WAKISO | H10: UGA | I10: 16 | J10: 8 | K10: =VLOOKUP(J10,Key!$E$2:$F$9,2,FALSE) -> Others | L10: KINTI | M10: WAKISO | N10: UGA | O10: 2 | P10: 2 | Q10: =VLOOKUP(P10,Key!$E$2:$F$9,2,FALSE) -> Work | R10: =K10&"-"&Q10 -> Others-Work | S10: 4 | T10: 0.1 | U10: 1 | Y10: Y | Z10: 1000
B11: 0.55902778 | C11: UAR 778L | D11: 2 | E11: 2 | F11: KIIRA | G11: WAKISO | H11: UGA | I11: 2 | J11: 2 | K11: =VLOOKUP(J11,Key!$E$2:$F$9,2,FALSE) -> Work | L11: BUWAMBO | M11: WAKISO | N11: UGA | O11: 1 | P11: 1 | Q11: =VLOOKUP(P11,Key!$E$2:$F$9,2,FALSE) -> Home | R11: =K11&"-"&Q11 -> Work-Home | S11: 20 | T11: 0.6 | U11: 1 | Y11: Y | Z11: 1000
B12: 0.55555556 | C12: UBE 302K | D12: 1 | E12: 3 | F12: GAYAZA | G12: WAKISO | H12: UGA | I12: 5 | J12: 7 | K12: =VLOOKUP(J12,Key!$E$2:$F$9,2,FALSE) -> Hospital | L12: NANGABO | M12: WAKISO | N12: UGA | O12: 1 | P12: 1 | Q12: =VLOOKUP(P12,Key!$E$2:$F$9,2,FALSE) -> Home | R12: =K12&"-"&Q12 -> Hospital-Home | S12: 12 | T12: 0.6 | U12: 1 | Y12: Y | Z12: 0
B13: 0.56736111 | C13: UBD 238A | D13: 2 | E13: 2 | F13: KAYUNGA | G13: KAYUNGA | H13: UGA | I13: 1 | J13: 1 | K13: =VLOOKUP(J13,Key!$E$2:$F$9,2,FALSE) -> Home | L13: MAIZIKIT | M13: WAKISO | N13: UGA | O13: 1 | P13: 1 | Q13: =VLOOKUP(P13,Key!$E$2:$F$9,2,FALSE) -> Home | R13: =K13&"-"&Q13 -> Home-Home | T13: 1.5 | U13: 3 | Y13: Y | Z13: 0
B14: 0.56458333 | C14: UAJ 072Y | D14: 1 | E14: 2 | F14: GWAFU | G14: MUKONO | H14: UGA | I14: 1 | J14: 1 | K14: =VLOOKUP(J14,Key!$E$2:$F$9,2,FALSE) -> Home | L14: BOMBO | M14: WAKISO | N14: UGA | O14: 9 | P14: 2 | Q14: =VLOOKUP(P14,Key!$E$2:$F$9,2,FALSE) -> Work | R14: =K14&"-"&Q14 -> Home-Work | S14: 80 | T14: 1.5 | U14: 3 | Y14: Y | Z14: 5000
B15: 0.50694444 | C15: UAJ 787Y | D15: 2 | E15: 1 | F15: GAYAZA | G15: WAKISO | H15: UGA | I15: 11 | J15: 4 | K15: =VLOOKUP(J15,Key!$E$2:$F$9,2,FALSE) -> Commercial | L15: NANGABO | M15: WAKISO | N15: UGA | O15: 1 | P15: 1 | Q15: =VLOOKUP(P15,Key!$E$2:$F$9,2,FALSE) -> Home | R15: =K15&"-"&Q15 -> Commercial-Home | S15: 2 | T15: 0.5 | U15: 1 | Y15: Y | Z15: 6000
B16: 0.50208333 | C16: UAH 749H | D16: 1 | E16: 2 | F16: MAGANJO | G16: WAKISO | H16: UGA | I16: 1 | J16: 1 | K16: =VLOOKUP(J16,Key!$E$2:$F$9,2,FALSE) -> Home | L16: KASANGATTI | M16: WAKISO | N16: UGA | O16: 16 | P16: 8 | Q16: =VLOOKUP(P16,Key!$E$2:$F$9,2,FALSE) -> Others | R16: =K16&"-"&Q16 -> Home-Others | T16: 0.5 | U16: 6 | Y16: Y | Z16: 2000
B17: 0.49791667 | C17: UAL 718T | D17: 1 | E17: 1 | F17: KASANGATTI | G17: WAKISO | H17: UGA | I17: 16 | J17: 2 | K17: =VLOOKUP(J17,Key!$E$2:$F$9,2,FALSE) -> Work | L17: NANGABO | M17: WAKISO | N17: UGA | O17: 2 | P17: 2 | Q17: =VLOOKUP(P17,Key!$E$2:$F$9,2,FALSE) -> Work | R17: =K17&"-"&Q17 -> Work-Work | S17: 2 | T17: 0.1 | U17: 1 | Y17: Y | Z17: 2000
B18: 0.49444444 | C18: UBA 458Q | D18: 1 | E18: 1 | F18: KOMAMBOGA | G18: WAKISO | H18: UGA | I18: 1 | J18: 1 | K18: =VLOOKUP(J18,Key!$E$2:$F$9,2,FALSE) -> Home | L18: KITI | M18: WAKISO | N18: UGA | O18: 1 | P18: 1 | Q18: =VLOOKUP(P18,Key!$E$2:$F$9,2,FALSE) -> Home | R18: =K18&"-"&Q18 -> Home-Home | S18: 15 | T18: 0.2 | U18: 4 | Y18: Y | Z18: 1000
B19: 0.46666667 | C19: UAG 330P | D19: 1 | E19: 3 | F19: KYAKIMA | G19: WAKISO | H19: UGA | I19: 1 | J19: 1 | K19: =VLOOKUP(J19,Key!$E$2:$F$9,2,FALSE) -> Home | L19: KITEGOBWA | M19: WAKISO | N19: UGA | O19: 3 | P19: 2 | Q19: =VLOOKUP(P19,Key!$E$2:$F$9,2,FALSE) -> Work | R19: =K19&"-"&Q19 -> Home-Work | S19: 2 | T19: 0.3 | U19: 1 | Y19: Y | Z19: 2000
B20: 0.47222222 | C20: UBF 875B | D20: 2 | E20: 2 | F20: KAYIMBA | G20: WAKISO | H20: UGA | I20: 10 | J20: 2 | K20: =VLOOKUP(J20,Key!$E$2:$F$9,2,FALSE) -> Work | L20: NAMGABOBWA | M20: WAKISO | N20: UGA | O20: 2 | P20: 2 | Q20: =VLOOKUP(P20,Key!$E$2:$F$9,2,FALSE) -> Work | R20: =K20&"-"&Q20 -> Work-Work | S20: 3 | T20: 0.1 | U20: 1 | Y20: Y | Z20: 1000
B21: 0.46180556 | C21: UAY 037S | D21: 7 | E21: 1 | F21: KASANGATTI | G21: WAKISO | H21: UGA | I21: 3 | J21: 2 | K21: =VLOOKUP(J21,Key!$E$2:$F$9,2,FALSE) -> Work | L21: KAPEEKA | M21: LUWERO | N21: UGA | O21: 3 | P21: 2 | Q21: =VLOOKUP(P21,Key!$E$2:$F$9,2,FALSE) -> Work | R21: =K21&"-"&Q21 -> Work-Work | S21: 55 | T21: 1.2 | U21: 4 | V21: 11 | Y21: Y | Z21: 1000
B22: 0.45625 | C22: UAV 468T | D22: 8 | E22: 2 | F22: LUTEETE | G22: WAKISO | H22: UGA | I22: 6 | J22: 2 | K22: =VLOOKUP(J22,Key!$E$2:$F$9,2,FALSE) -> Work | L22: NJINTA | M22: WAKISO | N22: UGA | O22: 1 | P22: 1 | Q22: =VLOOKUP(P22,Key!$E$2:$F$9,2,FALSE) -> Home | R22: =K22&"-"&Q22 -> Work-Home | S22: 2 | T22: 0.3 | U22: 6 | Y22: Y | Z22: 2000
B23: 0.45208333 | C23: UAM 431G | D23: 1 | E23: 1 | F23: KASANGATTI | G23: WAKISO | H23: UGA | I23: 1 | J23: 1 | K23: =VLOOKUP(J23,Key!$E$2:$F$9,2,FALSE) -> Home | L23: MAWULE | M23: WAKISO | N23: UGA | O23: 9 | P23: 2 | Q23: =VLOOKUP(P23,Key!$E$2:$F$9,2,FALSE) -> Work | R23: =K23&"-"&Q23 -> Home-Work | S23: 3 | T23: 0.5 | U23: 4 | Y23: Y | Z23: 2000
B24: 0.44513889 | C24: UBB 995G | D24: 4 | E24: 14 | F24: KANSANGA | G24: WAKISO | H24: UGA | I24: 6 | J24: 2 | K24: =VLOOKUP(J24,Key!$E$2:$F$9,2,FALSE) -> Work | L24: MATUGGA | M24: WAKISO | N24: UGA | O24: 6 | P24: 1 | Q24: =VLOOKUP(P24,Key!$E$2:$F$9,2,FALSE) -> Home | R24: =K24&"-"&Q24 -> Work-Home | T24: 0.3 | U24: 2 | Y24: N | Z24: 0
B25: 0.42777778 | C25: UAV 761T | D25: 4 | E25: 13 | F25: KASANGATTI | G25: WAKISO | H25: UGA | I25: 6 | J25: 2 | K25: =VLOOKUP(J25,Key!$E$2:$F$9,2,FALSE) -> Work | L25: MATUGGA | M25: WAKISO | N25: UGA | O25: 6 | P25: 2 | Q25: =VLOOKUP(P25,Key!$E$2:$F$9,2,FALSE) -> Work | R25: =K25&"-"&Q25 -> Work-Work | S25: 9.5 | T25: 0.2 | U25: 1 | Y25: Y | Z25: 10000
B26: 0.42361111 | C26: UAP 484R | D26: 6 | E26: 2 | F26: KIIRA | G26: WAKISO | H26: UGA | I26: 16 | J26: 2 | K26: =VLOOKUP(J26,Key!$E$2:$F$9,2,FALSE) -> Work | L26: KASANA | M26: LUWERO | N26: UGA | O26: 16 | P26: 2 | Q26: =VLOOKUP(P26,Key!$E$2:$F$9,2,FALSE) -> Work | R26: =K26&"-"&Q26 -> Work-Work | T26: 1 | U26: 6 | Y26: Y | Z26: 0
B27: 0.57361111 | C27: UBA 237N | D27: 1 | E27: 2 | F27: KOLOLO | G27: KAMPALA | H27: UGA | I27: 16 | J27: 2 | K27: =VLOOKUP(J27,Key!$E$2:$F$9,2,FALSE) -> Work | L27: KITEGOBWA | M27: WAKISO | N27: UGA | O27: 1 | P27: 1 | Q27: =VLOOKUP(P27,Key!$E$2:$F$9,2,FALSE) -> Home | R27: =K27&"-"&Q27 -> Work-Home | T27: 1 | U27: 3 | Y27: Y | Z27: 0
B28: 0.57083333 | C28: UAU 383G | D28: 7 | E28: 5 | F28: KIIRA | G28: WAKISO | H28: UGA | I28: 3 | J28: 2 | K28: =VLOOKUP(J28,Key!$E$2:$F$9,2,FALSE) -> Work | L28: MATUGGA | M28: WAKISO | N28: UGA | O28: 3 | P28: 2 | Q28: =VLOOKUP(P28,Key!$E$2:$F$9,2,FALSE) -> Work | R28: =K28&"-"&Q28 -> Work-Work | S28: 8 | T28: 0.5 | U28: 3 | V28: 11 | Y28: Y | Z28: 2000
B29: 0.44305556 | C29: UAV 056Q | D29: 7 | E29: 1 | F29: KISAASI | G29: WAKISO | H29: UGA | I29: 3 | J29: 1 | K29: =VLOOKUP(J29,Key!$E$2:$F$9,2,FALSE) -> Home | L29: BUWAMBO | M29: WAKISO | N29: UGA | O29: 11 | P29: 4 | Q29: =VLOOKUP(P29,Key!$E$2:$F$9,2,FALSE) -> Commercial | R29: =K29&"-"&Q29 -> Home-Commercial | S29: 1 | T29: 0.8 | U29: 4 | X29: 1.05 | Y29: Y | Z29: 1000
B30: 0.43819444 | C30: UAL 361D | D30: 4 | E30: 11 | F30: KALERWE | G30: KAMPALA | H30: UGA | I30: 6 | J30: 2 | K30: =VLOOKUP(J30,Key!$E$2:$F$9,2,FALSE) -> Work | L30: KITEGOBWA | M30: WAKISO | N30: UGA | O30: 16 | P30: 8 | Q30: =VLOOKUP(P30,Key!$E$2:$F$9,2,FALSE) -> Others | R30: =K30&"-"&Q30 -> Work-Others | T30: 0.5 | U30: 6 | Y30: N | Z30: 0
B31: 0.43125 | C31: UAZ 841S | D31: 7 | E31: 2 | F31: BWEYOGERERE | G31: WAKISO | H31: UGA | I31: 2 | J31: 2 | K31: =VLOOKUP(J31,Key!$E$2:$F$9,2,FALSE) -> Work | L31: WOBULENZI | M31: LUWERO | N31: UGA | O31: 1 | P31: 1 | Q31: =VLOOKUP(P31,Key!$E$2:$F$9,2,FALSE) -> Home | R31: =K31&"-"&Q31 -> Work-Home | T31: 1 | U31: 3 | Y31: Y | Z31: 1000
B32: 0.43472222 | C32: UAX 474M | D32: 8 | E32: 1 | F32: GAYAZA | G32: WAKISO | H32: UGA | I32: 14 | J32: 2 | K32: =VLOOKUP(J32,Key!$E$2:$F$9,2,FALSE) -> Work | L32: NANGABO | M32: WAKISO | N32: UGA | O32: 16 | P32: 6 | Q32: =VLOOKUP(P32,Key!$E$2:$F$9,2,FALSE) -> Leisure/Social | R32: =K32&"-"&Q32 -> Work-Leisure/Social | S32: 1 | T32: 0.1 | U32: 4 | Y32: Y | Z32: 0
B33: 0.70416667 | C33: UAQ 128A | D33: 1 | E33: 2 | F33: LUZIRA | G33: KAMPALA | H33: UGA | I33: 1 | J33: 1 | K33: =VLOOKUP(J33,Key!$E$2:$F$9,2,FALSE) -> Home | L33: MATUGGA | M33: WAKISO | N33: UGA | O33: 16 | P33: 8 | Q33: =VLOOKUP(P33,Key!$E$2:$F$9,2,FALSE) -> Others | R33: =K33&"-"&Q33 -> Home-Others | S33: 25 | T33: 2 | U33: 4 | Y33: Y | Z33: 2000
B34: 0.70763889 | C34: UBA 585R | D34: 7 | E34: 5 | F34: NAJERA | G34: WAKISO | H34: UGA | I34: 2 | J34: 2 | K34: =VLOOKUP(J34,Key!$E$2:$F$9,2,FALSE) -> Work | L34: MATUGGA | M34: WAKISO | N34: UGA | O34: 1 | P34: 1 | Q34: =VLOOKUP(P34,Key!$E$2:$F$9,2,FALSE) -> Home | R34: =K34&"-"&Q34 -> Work-Home | T34: 3 | U34: 3 | V34: 10 | Y34: Y | Z34: 1000
B35: 0.69930556 | C35: UAX 918A | D35: 1 | E35: 5 | F35: WANDEGEYA | G35: KAMPALA | H35: UGA | I35: 2 | J35: 2 | K35: =VLOOKUP(J35,Key!$E$2:$F$9,2,FALSE) -> Work | L35: KATIKAMU | M35: WAKISO | N35: UGA | O35: 16 | P35: 8 | Q35: =VLOOKUP(P35,Key!$E$2:$F$9,2,FALSE) -> Others | R35: =K35&"-"&Q35 -> Work-Others | S35: 22 | T35: 1 | U35: 3 | Y35: Y | Z35: 0
B36: 0.70138889 | C36: UBB 444N | D36: 7 | E36: 2 | F36: KIIRA | G36: WAKISO | H36: UGA | I36: 14 | J36: 2 | K36: =VLOOKUP(J36,Key!$E$2:$F$9,2,FALSE) -> Work | L36: NANGABO | M36: WAKISO | N36: UGA | O36: 1 | P36: 1 | Q36: =VLOOKUP(P36,Key!$E$2:$F$9,2,FALSE) -> Home | R36: =K36&"-"&Q36 -> Work-Home | S36: 5 | T36: 0.5 | U36: 6 | Y36: Y | Z36: 0
B37: 0.63541667 | C37: UAP 565W | D37: 1 | E37: 2 | F37: GAYAZA | G37: WAKISO | H37: UGA | I37: 10 | J37: 2 | K37: =VLOOKUP(J37,Key!$E$2:$F$9,2,FALSE) -> Work | L37: NAKALOLO | M37: WAKISO | N37: UGA | O37: 16 | P37: 8 | Q37: =VLOOKUP(P37,Key!$E$2:$F$9,2,FALSE) -> Others | R37: =K37&"-"&Q37 -> Work-Others | T37: 0.5 | U37: 2 | Y37: Y | Z37: 0
B38: 0.62916667 | C38: UBA 034G | D38: 7 | E38: 1 | F38: KASANGATTI | G38: WAKISO | H38: UGA | I38: 16 | J38: 2 | K38: =VLOOKUP(J38,Key!$E$2:$F$9,2,FALSE) -> Work | L38: KITEGOBWA | M38: WAKISO | N38: UGA | O38: 1 | P38: 1 | Q38: =VLOOKUP(P38,Key!$E$2:$F$9,2,FALSE) -> Home | R38: =K38&"-"&Q38 -> Work-Home | S38: 2 | T38: 0.1 | U38: 2 | Y38: Y | Z38: 1000
B39: 0.67986111 | C39: UAR 764B | D39: 2 | E39: 2 | F39: NSETA | G39: WAKISO | H39: UGA | I39: 1 | J39: 1 | K39: =VLOOKUP(J39,Key!$E$2:$F$9,2,FALSE) -> Home | L39: NKOWE | M39: WAKISO | N39: UGA | O39: 10 | P39: 2 | Q39: =VLOOKUP(P39,Key!$E$2:$F$9,2,FALSE) -> Work | R39: =K39&"-"&Q39 -> Home-Work | S39: 21 | T39: 0.5 | U39: 6 | Y39: Y | Z39: 1000
B40: 0.69375 | C40: UAW 801S | D40: 7 | E40: 2 | F40: KASANGATTI | G40: WAKISO | H40: UGA | I40: 3 | J40: 2 | K40: =VLOOKUP(J40,Key!$E$2:$F$9,2,FALSE) -> Work | L40: NANGABO | M40: WAKISO | N40: UGA | O40: 11 | P40: 2 | Q40: =VLOOKUP(P40,Key!$E$2:$F$9,2,FALSE) -> Work | R40: =K40&"-"&Q40 -> Work-Work | T40: 0.5 | U40: 3 | Y40: Y | Z40: 1000
