Workbook

Sheet 22.07 Lubiri -Ndeeba
B1: Consultancy services for Preparation of Expressway Development Master Plan (EDMP) for Uganda
B2: MANUAL CLASSIFIED COUNT (MCC)
B3: ROAD NAME: | C3: MCC - C1 - STN03- KALINDA ROAD
C5: Date | D5: 22.07.19 | F5: Location | G5: Before Shell | J5: Surveyor | K5: Maiso. M. Gadafi
C6: Dir. From | D6: Lubiri | F6: Dir. To | G6: Ndeeba | J6: Supervisor | K6: Denis
B8: Time / Veh Type | R8: SUMMARY TRAFFIC VOLUMES
C9: 1. Car | D9: 2. Station Wagon | E9: 3. Pickups | F9: 4. Minibus, matatu | G9: 5. Medium bus | H9: 6. Large Bus | I9: 7. Light Truck | J9: 8. Medium Truck | K9: 9. Heavy truck | L9: 10. Truck Trailer | M9: 11. Motor cycles | N9: 12. Tractors | O9: Total Excl M/Cycles | P9: Total All | R9: Time | S9: 1. Car | T9: 2. Station Wagon | U9: 3. Pickups | V9: 4. Minibus, matatu | W9: 5. Medium bus | X9: 6. Large Bus | Y9: 7. Light Truck | Z9: 8. Medium Truck | AA9: 9. Heavy truck | AB9: 10. Truck Trailer | AC9: 11. Motorcycles | AD9: 12. Tractors, Graders | AE9: Total Excl M/ Cycles | AF9: Total All
B10: 07.00 - 07.15 | C10: 5 | D10: 5 | E10: 1 | F10: 10 | G10: 0 | H10: 1 | I10: 1 | J10: 0 | K10: 0 | L10: 0 | M10: 40 | N10: 0 | O10: =SUM(C10:L10,N10) -> 23 | P10: =SUM(C10:N10) -> 63 | R10: 0700-0800 | S10: =SUM(C10:C13) -> 58 | T10: =SUM(D10:D13) -> 16 | U10: =SUM(E10:E13) -> 7 | V10: =SUM(F10:F13) -> 52 | W10: =SUM(G10:G13) -> 1 | X10: =SUM(H10:H13) -> 1 | Y10: =SUM(I10:I13) -> 8 | Z10: =SUM(J10:J13) -> 2 | ... AF10: =SUM(P10:P13) -> 562
B11: 07.15 - 07.30 | C11: 4 | D11: 2 | E11: 0 | F11: 3 | G11: 0 | H11: 0 | I11: 1 | J11: 0 | K11: 0 | L11: 0 | M11: 25 | N11: 0 | O11: =SUM(C11:L11,N11) -> 10 | P11: =SUM(C11:N11) -> 35 | R11: 0800-0900 | S11: =SUM(C14:C17) -> 86 | T11: =SUM(D14:D17) -> 21 | U11: =SUM(E14:E17) -> 6 | V11: =SUM(F14:F17) -> 103 | W11: =SUM(G14:G17) -> 4 | X11: =SUM(H14:H17) -> 0 | Y11: =SUM(I14:I17) -> 20 | Z11: =SUM(J14:J17) -> 9 | ... AF11: =SUM(P14:P17) -> 927
B12: 07.30 - 07.45 | C12: 22 | D12: 3 | E12: 3 | F12: 17 | G12: 1 | H12: 0 | I12: 2 | J12: 1 | K12: 2 | L12: 0 | M12: 153 | N12: 0 | O12: =SUM(C12:L12,N12) -> 51 | P12: =SUM(C12:N12) -> 204 | R12: 0900-1000 | S12: =SUM(C18:C21) -> 95 | T12: =SUM(D18:D21) -> 37 | U12: =SUM(E18:E21) -> 15 | V12: =SUM(F18:F21) -> 89 | W12: =SUM(G18:G21) -> 8 | X12: =SUM(H18:H21) -> 0 | Y12: =SUM(I18:I21) -> 22 | Z12: =SUM(J18:J21) -> 22 | ... AF12: =SUM(P18:P21) -> 883
B13: 07.45 - 08.00 | C13: 27 | D13: 6 | E13: 3 | F13: 22 | G13: 0 | H13: 0 | I13: 4 | J13: 1 | K13: 0 | L13: 0 | M13: 197 | N13: 0 | O13: =SUM(C13:L13,N13) -> 63 | P13: =SUM(C13:N13) -> 260 | R13: 1000-1100 | S13: =SUM(C22:C25) -> 131 | T13: =SUM(D22:D25) -> 37 | U13: =SUM(E22:E25) -> 15 | V13: =SUM(F22:F25) -> 57 | W13: =SUM(G22:G25) -> 0 | X13: =SUM(H22:H25) -> 0 | Y13: =SUM(I22:I25) -> 21 | Z13: =SUM(J22:J25) -> 27 | ... AF13: =SUM(P22:P25) -> 1169
B14: 08.00 - 08.15 | C14: 26 | D14: 3 | E14: 4 | F14: 21 | G14: 0 | H14: 0 | I14: 7 | J14: 1 | K14: 0 | L14: 0 | M14: 164 | N14: 0 | O14: =SUM(C14:L14,N14) -> 62 | P14: =SUM(C14:N14) -> 226 | R14: 1100-1200 | S14: =SUM(C26:C29) -> 139 | T14: =SUM(D26:D29) -> 19 | U14: =SUM(E26:E29) -> 8 | V14: =SUM(F26:F29) -> 52 | W14: =SUM(G26:G29) -> 2 | X14: =SUM(H26:H29) -> 0 | Y14: =SUM(I26:I29) -> 38 | Z14: =SUM(J26:J29) -> 16 | ... AF14: =SUM(P26:P29) -> 1302
B15: 08.15 - 08.30 | C15: 21 | D15: 5 | E15: 0 | F15: 35 | G15: 0 | H15: 0 | I15: 5 | J15: 2 | K15: 1 | L15: 1 | M15: 254 | N15: 0 | O15: =SUM(C15:L15,N15) -> 70 | P15: =SUM(C15:N15) -> 324 | R15: 1200-1300 | S15: =SUM(C30:C33) -> 137 | T15: =SUM(D30:D33) -> 29 | U15: =SUM(E30:E33) -> 16 | V15: =SUM(F30:F33) -> 63 | W15: =SUM(G30:G33) -> 2 | X15: =SUM(H30:H33) -> 0 | Y15: =SUM(I30:I33) -> 18 | Z15: =SUM(J30:J33) -> 26 | ... AF15: =SUM(P30:P33) -> 1384
B16: 08.30 - 08.45 | C16: 21 | D16: 4 | E16: 2 | F16: 23 | G16: 3 | H16: 0 | I16: 3 | J16: 3 | K16: 1 | L16: 0 | M16: 145 | N16: 0 | O16: =SUM(C16:L16,N16) -> 60 | P16: =SUM(C16:N16) -> 205 | R16: 1300-1400 | S16: =SUM(C34:C37) -> 152 | T16: =SUM(D34:D37) -> 34 | U16: =SUM(E34:E37) -> 10 | V16: =SUM(F34:F37) -> 52 | W16: =SUM(G34:G37) -> 1 | X16: =SUM(H34:H37) -> 0 | Y16: =SUM(I34:I37) -> 26 | Z16: =SUM(J34:J37) -> 24 | ... AF16: =SUM(P34:P37) -> 1006
B17: 08.45 - 9.00 | C17: 18 | D17: 9 | E17: 0 | F17: 24 | G17: 1 | H17: 0 | I17: 5 | J17: 3 | K17: 2 | L17: 0 | M17: 110 | N17: 0 | O17: =SUM(C17:L17,N17) -> 62 | P17: =SUM(C17:N17) -> 172 | R17: 1400-1500 | S17: =SUM(C38:C41) -> 128 | T17: =SUM(D38:D41) -> 15 | U17: =SUM(E38:E41) -> 17 | V17: =SUM(F38:F41) -> 25 | W17: =SUM(G38:G41) -> 2 | X17: =SUM(H38:H41) -> 1 | Y17: =SUM(I38:I41) -> 19 | Z17: =SUM(J38:J41) -> 22 | ... AF17: =SUM(P38:P41) -> 988
B18: 09.00 - 09.15 | C18: 18 | D18: 8 | E18: 1 | F18: 26 | G18: 2 | H18: 0 | I18: 4 | J18: 1 | K18: 0 | L18: 0 | M18: 102 | N18: 0 | O18: =SUM(C18:L18,N18) -> 60 | P18: =SUM(C18:N18) -> 162 | R18: 1500-1600 | S18: =SUM(C42:C45) -> 164 | T18: =SUM(D42:D45) -> 30 | U18: =SUM(E42:E45) -> 18 | V18: =SUM(F42:F45) -> 47 | W18: =SUM(G42:G45) -> 0 | X18: =SUM(H42:H45) -> 0 | Y18: =SUM(I42:I45) -> 25 | Z18: =SUM(J42:J45) -> 27 | ... AF18: =SUM(P42:P45) -> 645
B19: 09.15 - 09.30 | C19: 24 | D19: 7 | E19: 2 | F19: 21 | G19: 1 | H19: 0 | I19: 6 | J19: 4 | K19: 2 | L19: 2 | M19: 195 | N19: 0 | O19: =SUM(C19:L19,N19) -> 69 | P19: =SUM(C19:N19) -> 264 | R19: 1600-1700 | S19: =SUM(C46:C49) -> 178 | T19: =SUM(D46:D49) -> 25 | U19: =SUM(E46:E49) -> 18 | V19: =SUM(F46:F49) -> 60 | W19: =SUM(G46:G49) -> 3 | X19: =SUM(H46:H49) -> 0 | Y19: =SUM(I46:I49) -> 36 | Z19: =SUM(J46:J49) -> 19 | ... AF19: =SUM(P46:P49) -> 1443
B20: 09.30 - 09.45 | C20: 31 | D20: 13 | E20: 4 | F20: 22 | G20: 4 | H20: 0 | I20: 8 | J20: 9 | K20: 2 | L20: 0 | M20: 136 | N20: 0 | O20: =SUM(C20:L20,N20) -> 93 | P20: =SUM(C20:N20) -> 229 | R20: 1700-1800 | S20: =SUM(C50:C53) -> 230 | T20: =SUM(D50:D53) -> 36 | U20: =SUM(E50:E53) -> 16 | V20: =SUM(F50:F53) -> 100 | W20: =SUM(G50:G53) -> 2 | X20: =SUM(H50:H53) -> 1 | Y20: =SUM(I50:I53) -> 13 | Z20: =SUM(J50:J53) -> 25 | ... AF20: =SUM(P50:P53) -> 1826
B21: 09.45 - 10.00 | C21: 22 | D21: 9 | E21: 8 | F21: 20 | G21: 1 | H21: 0 | I21: 4 | J21: 8 | K21: 4 | L21: 4 | M21: 148 | N21: 0 | O21: =SUM(C21:L21,N21) -> 80 | P21: =SUM(C21:N21) -> 228 | R21: 1800-1900 | S21: =SUM(C54:C57) -> 261 | T21: =SUM(D54:D57) -> 29 | U21: =SUM(E54:E57) -> 21 | V21: =SUM(F54:F57) -> 30 | W21: =SUM(G54:G57) -> 1 | X21: =SUM(H54:H57) -> 0 | Y21: =SUM(I54:I57) -> 21 | Z21: =SUM(J54:J57) -> 21 | ... AF21: =SUM(P54:P57) -> 1621
B22: 10.00 - 10.15 | C22: 46 | D22: 8 | E22: 5 | F22: 13 | G22: 0 | H22: 0 | I22: 7 | J22: 20 | K22: 3 | L22: 1 | M22: 183 | N22: 0 | O22: =SUM(C22:L22,N22) -> 103 | P22: =SUM(C22:N22) -> 286 | R22: AM Peak Hr | S22: =MAX(S10:S12) -> 95 | T22: =MAX(T10:T12) -> 37 | U22: =MAX(U10:U12) -> 15 | V22: =MAX(V10:V12) -> 103 | W22: =MAX(W10:W12) -> 8 | X22: =MAX(X10:X12) -> 1 | Y22: =MAX(Y10:Y12) -> 22 | Z22: =MAX(Z10:Z12) -> 22 | ... AF22: =MAX(AF10:AF12) -> 927
B23: 10.15 - 10.30 | C23: 34 | D23: 4 | E23: 2 | F23: 12 | G23: 0 | H23: 0 | I23: 5 | J23: 2 | K23: 0 | L23: 0 | M23: 228 | N23: 0 | O23: =SUM(C23:L23,N23) -> 59 | P23: =SUM(C23:N23) -> 287 | R23: IP Peak Hr | S23: =MAX(S13:S18) -> 164 | T23: =MAX(T13:T18) -> 37 | U23: =MAX(U13:U18) -> 18 | V23: =MAX(V13:V18) -> 63 | W23: =MAX(W13:W18) -> 2 | X23: =MAX(X13:X18) -> 1 | Y23: =MAX(Y13:Y18) -> 38 | Z23: =MAX(Z13:Z18) -> 27 | ... AF23: =MAX(AF13:AF18) -> 1384
B24: 10.30 - 10.45 | C24: 27 | D24: 14 | E24: 3 | F24: 16 | G24: 0 | H24: 0 | I24: 4 | J24: 4 | K24: 1 | L24: 1 | M24: 254 | N24: 0 | O24: =SUM(C24:L24,N24) -> 70 | P24: =SUM(C24:N24) -> 324 | R24: PM Peak Hr | S24: =MAX(S19:S21) -> 261 | T24: =MAX(T19:T21) -> 36 | U24: =MAX(U19:U21) -> 21 | V24: =MAX(V19:V21) -> 100 | W24: =MAX(W19:W21) -> 3 | X24: =MAX(X19:X21) -> 1 | Y24: =MAX(Y19:Y21) -> 36 | Z24: =MAX(Z19:Z21) -> 25 | ... AF24: =MAX(AF19:AF21) -> 1826
B25: 10.45 - 11.00 | C25: 24 | D25: 11 | E25: 5 | F25: 16 | G25: 0 | H25: 0 | I25: 5 | J25: 1 | K25: 2 | L25: 0 | M25: 208 | N25: 0 | O25: =SUM(C25:L25,N25) -> 64 | P25: =SUM(C25:N25) -> 272 | R25: AM Period | S25: =SUM(S10:S12) -> 239 | T25: =SUM(T10:T12) -> 74 | U25: =SUM(U10:U12) -> 28 | V25: =SUM(V10:V12) -> 244 | W25: =SUM(W10:W12) -> 13 | X25: =SUM(X10:X12) -> 1 | Y25: =SUM(Y10:Y12) -> 50 | Z25: =SUM(Z10:Z12) -> 33 | ... AF25: =SUM(AF10:AF12) -> 2372
B26: 11.00 - 11.15 | C26: 29 | D26: 3 | E26: 4 | F26: 9 | G26: 1 | H26: 0 | I26: 7 | J26: 2 | K26: 0 | L26: 0 | M26: 284 | N26: 0 | O26: =SUM(C26:L26,N26) -> 55 | P26: =SUM(C26:N26) -> 339 | R26: IP Period | S26: =SUM(S13:S18) -> 851 | T26: =SUM(T13:T18) -> 164 | U26: =SUM(U13:U18) -> 84 | V26: =SUM(V13:V18) -> 296 | W26: =SUM(W13:W18) -> 7 | X26: =SUM(X13:X18) -> 1 | Y26: =SUM(Y13:Y18) -> 147 | Z26: =SUM(Z13:Z18) -> 142 | ... AF26: =SUM(AF13:AF18) -> 6494
B27: 11.15 - 11.30 | C27: 29 | D27: 6 | E27: 0 | F27: 12 | G27: 0 | H27: 0 | I27: 8 | J27: 5 | K27: 0 | L27: 1 | M27: 315 | N27: 0 | O27: =SUM(C27:L27,N27) -> 61 | P27: =SUM(C27:N27) -> 376 | R27: PM Period | S27: =SUM(S19:S21) -> 669 | T27: =SUM(T19:T21) -> 90 | U27: =SUM(U19:U21) -> 55 | V27: =SUM(V19:V21) -> 190 | W27: =SUM(W19:W21) -> 6 | X27: =SUM(X19:X21) -> 1 | Y27: =SUM(Y19:Y21) -> 70 | Z27: =SUM(Z19:Z21) -> 65 | ... AF27: =SUM(AF19:AF21) -> 4890
B28: 11.30 - 11.45 | C28: 49 | D28: 6 | E28: 3 | F28: 18 | G28: 0 | H28: 0 | I28: 8 | J28: 7 | K28: 4 | L28: 0 | M28: 180 | N28: 0 | O28: =SUM(C28:L28,N28) -> 95 | P28: =SUM(C28:N28) -> 275 | R28: 12 Hours | S28: =SUM(S10:S21) -> 1759 | T28: =SUM(T10:T21) -> 328 | U28: =SUM(U10:U21) -> 167 | V28: =SUM(V10:V21) -> 730 | W28: =SUM(W10:W21) -> 26 | X28: =SUM(X10:X21) -> 3 | Y28: =SUM(Y10:Y21) -> 267 | Z28: =SUM(Z10:Z21) -> 240 | ... AF28: =SUM(AF10:AF21) -> 13756
B29: 11.45 - 12.00 | C29: 32 | D29: 4 | E29: 1 | F29: 13 | G29: 1 | H29: 0 | I29: 15 | J29: 2 | K29: 0 | L29: 1 | M29: 243 | N29: 0 | O29: =SUM(C29:L29,N29) -> 69 | P29: =SUM(C29:N29) -> 312
B30: 12.00 - 12.15 | C30: 36 | D30: 8 | E30: 6 | F30: 22 | G30: 2 | H30: 0 | I30: 6 | J30: 6 | K30: 1 | L30: 0 | M30: 164 | N30: 0 | O30: =SUM(C30:L30,N30) -> 87 | P30: =SUM(C30:N30) -> 251
B31: 12.15 - 12.30 | C31: 41 | D31: 9 | E31: 4 | F31: 12 | G31: 0 | H31: 0 | I31: 5 | J31: 7 | K31: 2 | L31: 1 | M31: 282 | N31: 0 | O31: =SUM(C31:L31,N31) -> 81 | P31: =SUM(C31:N31) -> 363
B32: 12.30 - 12.45 | C32: 28 | D32: 8 | E32: 2 | F32: 18 | G32: 0 | H32: 0 | I32: 4 | J32: 5 | K32: 0 | L32: 0 | M32: 313 | N32: 0 | O32: =SUM(C32:L32,N32) -> 65 | P32: =SUM(C32:N32) -> 378
B33: 12.45 - 13.00 | C33: 32 | D33: 4 | E33: 4 | F33: 11 | G33: 0 | H33: 0 | I33: 3 | J33: 8 | K33: 1 | L33: 1 | M33: 328 | N33: 0 | O33: =SUM(C33:L33,N33) -> 64 | P33: =SUM(C33:N33) -> 392
B34: 13.00 - 13.15 | C34: 38 | D34: 6 | E34: 3 | F34: 11 | G34: 0 | H34: 0 | I34: 5 | J34: 6 | K34: 0 | L34: 0 | M34: 135 | N34: 0 | O34: =SUM(C34:L34,N34) -> 69 | P34: =SUM(C34:N34) -> 204
B35: 13.15 - 13.30 | C35: 38 | D35: 15 | E35: 4 | F35: 12 | G35: 0 | H35: 0 | I35: 7 | J35: 6 | K35: 0 | L35: 0 | M35: 148 | N35: 0 | O35: =SUM(C35:L35,N35) -> 82 | P35: =SUM(C35:N35) -> 230
B36: 13.30 - 13.45 | C36: 42 | D36: 6 | E36: 1 | F36: 15 | G36: 0 | H36: 0 | I36: 5 | J36: 4 | K36: 0 | L36: 2 | M36: 235 | N36: 1 | O36: =SUM(C36:L36,N36) -> 76 | P36: =SUM(C36:N36) -> 311
B37: 13.45 - 14.00 | C37: 34 | D37: 7 | E37: 2 | F37: 14 | G37: 1 | H37: 0 | I37: 9 | J37: 8 | K37: 0 | L37: 1 | M37: 185 | N37: 0 | O37: =SUM(C37:L37,N37) -> 76 | P37: =SUM(C37:N37) -> 261
B38: 14.00 - 14.15 | C38: 49 | D38: 4 | E38: 6 | F38: 6 | G38: 0 | H38: 0 | I38: 8 | J38: 8 | K38: 1 | L38: 0 | M38: 158 | N38: 0 | O38: =SUM(C38:L38,N38) -> 82 | P38: =SUM(C38:N38) -> 240
B39: 14.15 - 14.30 | C39: 25 | D39: 4 | E39: 5 | F39: 4 | G39: 0 | H39: 1 | I39: 3 | J39: 7 | K39: 3 | L39: 0 | M39: 225 | N39: 0 | O39: =SUM(C39:L39,N39) -> 52 | P39: =SUM(C39:N39) -> 277
B40: 14.30 - 14.45 | C40: 38 | D40: 5 | E40: 3 | F40: 13 | G40: 2 | H40: 0 | I40: 6 | J40: 6 | K40: 11 | L40: 0 | M40: 210 | N40: 0 | O40: =SUM(C40:L40,N40) -> 84 | P40: =SUM(C40:N40) -> 294
... B46: 16.00 - 16.15 | C46: 45 | D46: 5 | E46: 5 | F46: 12 | G46: 1 | H46: 0 | I46: 13 | J46: 7 | K46: 0 | L46: 1 | M46: 270 | N46: 0 | O46: =SUM(C46:L46,N46) -> 89 | P46: =SUM(C46:N46) -> 359
B47: 16.15 -16.30 | C47: 43 | D47: 9 | E47: 5 | F47: 17 | G47: 0 | H47: 0 | I47: 5 | J47: 8 | K47: 2 | M47: 290 | N47: 0 | O47: =SUM(C47:L47,N47) -> 89 | P47: =SUM(C47:N47) -> 379
...

Sheet 22.07 Ndeeba-Lubiri
B1: Consultancy services for Preparation of Expressway Development Master Plan (EDMP) for Uganda
B2: MANUAL CLASSIFIED COUNT (MCC)
B3: ROAD NAME: | C3: ='22.07 Lubiri -Ndeeba'!C3:G3 -> MCC - C1 - STN03- KALINDA ROAD
C5: Date | D5: ='22.07 Lubiri -Ndeeba'!D5 -> 22.07.19 | F5: Location | G5: ='22.07 Lubiri -Ndeeba'!G5:H5 -> Before Shell | J5: Surveyor | K5: Kizito Geofrey
C6: Dir. From | D6: Ndeeba | F6: Dir. To | G6: Lubiri | J6: Supervisor | K6: Kaisuka
B8: Time / Veh Type | R8: SUMMARY TRAFFIC VOLUMES
C9: 1. Car | D9: 2. Station Wagon | E9: 3. Pickups | F9: 4. Minibus, matatu | G9: 5. Medium bus | H9: 6. Large Bus | I9: 7. Light Truck | J9: 8. Medium Truck | K9: 9. Heavy truck | L9: 10. Truck Trailer | M9: 11. Motor cycles | N9: 12. Tractors | O9: Total Excl M/Cycles | P9: Total All | R9: Time | S9: 1. Car | T9: 2. Station Wagon | U9: 3. Pickups | V9: 4. Minibus, matatu | W9: 5. Medium bus | X9: 6. Large Bus | Y9: 7. Light Truck | Z9: 8. Medium Truck | AA9: 9. Heavy truck | AB9: 10. Truck Trailer | AC9: 11. Motorcycles | AD9: 12. Tractors, Graders | AE9: Total Excl M/ Cycles | AF9: Total All
B10: 07.00 - 07.15 | C10: 71 | D10: 6 | E10: 10 | F10: 25 | G10: 0 | H10: 3 | I10: 0 | J10: 2 | K10: 0 | L10: 0 | M10: 128 | N10: 0 | O10: =SUM(C10:L10,N10) -> 117 | P10: =SUM(C10:N10) -> 245 | R10: 0700-0800 | S10: =SUM(C10:C13) -> 259 | T10: =SUM(D10:D13) -> 29 | U10: =SUM(E10:E13) -> 23 | V10: =SUM(F10:F13) -> 89 | W10: =SUM(G10:G13) -> 0 | X10: =SUM(H10:H13) -> 3 | Y10: =SUM(I10:I13) -> 6 | Z10: =SUM(J10:J13) -> 13 | ... AF10: =SUM(P10:P13) -> 824
B11: 07.15 - 07.30 | C11: 83 | D11: 10 | E11: 3 | F11: 20 | G11: 0 | H11: 0 | I11: 4 | J11: 5 | K11: 0 | L11: 1 | M11: 107 | N11: 0 | O11: =SUM(C11:L11,N11) -> 126 | P11: =SUM(C11:N11) -> 233 | R11: 0800-0900 | S11: =SUM(C14:C17) -> 212 | T11: =SUM(D14:D17) -> 35 | U11: =SUM(E14:E17) -> 17 | V11: =SUM(F14:F17) -> 85 | W11: =SUM(G14:G17) -> 1 | X11: =SUM(H14:H17) -> 0 | Y11: =SUM(I14:I17) -> 11 | Z11: =SUM(J14:J17) -> 27 | ... AF11: =SUM(P14:P17) -> 854
B12: 07.30 - 07.45 | C12: 67 | D12: 12 | E12: 7 | F12: 27 | G12: 0 | H12: 0 | I12: 2 | J12: 5 | K12: 0 | L12: 0 | M12: 96 | N12: 0 | O12: =SUM(C12:L12,N12) -> 120 | P12: =SUM(C12:N12) -> 216 | R12: 0900-1000 | S12: =SUM(C18:C21) -> 302 | T12: =SUM(D18:D21) -> 26 | U12: =SUM(E18:E21) -> 28 | V12: =SUM(F18:F21) -> 64 | W12: =SUM(G18:G21) -> 2 | X12: =SUM(H18:H21) -> 0 | Y12: =SUM(I18:I21) -> 18 | Z12: =SUM(J18:J21) -> 12 | ... AF12: =SUM(P18:P21) -> 1110
B13: 07.45 - 08.00 | C13: 38 | D13: 1 | E13: 3 | F13: 17 | G13: 0 | H13: 0 | I13: 0 | J13: 1 | K13: 0 | L13: 0 | M13: 70 | N13: 0 | O13: =SUM(C13:L13,N13) -> 60 | P13: =SUM(C13:N13) -> 130 | R13: 1000-1100 | S13: =SUM(C22:C25) -> 278 | T13: =SUM(D22:D25) -> 44 | U13: =SUM(E22:E25) -> 44 | V13: =SUM(F22:F25) -> 60 | W13: =SUM(G22:G25) -> 2 | X13: =SUM(H22:H25) -> 0 | Y13: =SUM(I22:I25) -> 51 | Z13: =SUM(J22:J25) -> 17 | ... AF13: =SUM(P22:P25) -> 1306
B14: 08.00 - 08.15 | C14: 22 | D14: 3 | E14: 3 | F14: 12 | G14: 1 | H14: 0 | I14: 2 | J14: 2 | K14: 0 | L14: 0 | M14: 81 | N14: 0 | O14: =SUM(C14:L14,N14) -> 45 | P14: =SUM(C14:N14) -> 126 | R14: 1100-1200 | S14: =SUM(C26:C29) -> 252 | T14: =SUM(D26:D29) -> 33 | U14: =SUM(E26:E29) -> 39 | V14: =SUM(F26:F29) -> 31 | W14: =SUM(G26:G29) -> 4 | X14: =SUM(H26:H29) -> 0 | Y14: =SUM(I26:I29) -> 24 | Z14: =SUM(J26:J29) -> 18 | ... AF14: =SUM(P26:P29) -> 1098
B15: 08.15 - 08.30 | C15: 35 | D15: 10 | E15: 5 | F15: 12 | G15: 0 | H15: 0 | I15: 7 | J15: 13 | K15: 0 | L15: 0 | M15: 80 | N15: 0 | O15: =SUM(C15:L15,N15) -> 82 | P15: =SUM(C15:N15) -> 162 | R15: 1200-1300 | S15: =SUM(C30:C33) -> 257 | T15: =SUM(D30:D33) -> 36 | U15: =SUM(E30:E33) -> 45 | V15: =SUM(F30:F33) -> 26 | W15: =SUM(G30:G33) -> 0 | X15: =SUM(H30:H33) -> 0 | Y15: =SUM(I30:I33) -> 16 | Z15: =SUM(J30:J33) -> 20 | ... AF15: =SUM(P30:P33) -> 1144
B16: 08.30 - 08.45 | C16: 68 | D16: 17 | E16: 2 | F16: 45 | G16: 0 | H16: 0 | I16: 0 | J16: 6 | K16: 0 | L16: 0 | M16: 165 | N16: 0 | O16: =SUM(C16:L16,N16) -> 138 | P16: =SUM(C16:N16) -> 303 | R16: 1300-1400 | S16: =SUM(C34:C37) -> 190 | T16: =SUM(D34:D37) -> 25 | U16: =SUM(E34:E37) -> 34 | V16: =SUM(F34:F37) -> 23 | W16: =SUM(G34:G37) -> 1 | X16: =SUM(H34:H37) -> 0 | Y16: =SUM(I34:I37) -> 19 | Z16: =SUM(J34:J37) -> 20 | ... AF16: =SUM(P34:P37) -> 929
B17: 08.45 - 9.00 | C17: 87 | D17: 5 | E17: 7 | F17: 16 | G17: 0 | H17: 0 | I17: 2 | J17: 6 | K17: 0 | L17: 0 | M17: 140 | N17: 0 | O17: =SUM(C17:L17,N17) -> 123 | P17: =SUM(C17:N17) -> 263 | R17: 1400-1500 | S17: =SUM(C38:C41) -> 144 | T17: =SUM(D38:D41) -> 44 | U17: =SUM(E38:E41) -> 37 | V17: =SUM(F38:F41) -> 24 | W17: =SUM(G38:G41) -> 0 | X17: =SUM(H38:H41) -> 0 | Y17: =SUM(I38:I41) -> 21 | Z17: =SUM(J38:J41) -> 13 | ... AF17: =SUM(P38:P41) -> 892
B18: 09.00 - 09.15 | C18: 80 | D18: 10 | E18: 6 | F18: 28 | G18: 0 | H18: 0 | I18: 5 | J18: 1 | K18: 0 | L18: 0 | M18: 175 | N18: 0 | O18: =SUM(C18:L18,N18) -> 130 | P18: =SUM(C18:N18) -> 305 | R18: 1500-1600 | S18: =SUM(C42:C45) -> 143 | T18: =SUM(D42:D45) -> 22 | U18: =SUM(E42:E45) -> 34 | V18: =SUM(F42:F45) -> 18 | W18: =SUM(G42:G45) -> 0 | X18: =SUM(H42:H45) -> 0 | Y18: =SUM(I42:I45) -> 15 | Z18: =SUM(J42:J45) -> 8 | ... AF18: =SUM(P42:P45) -> 468
B19: 09.15 - 09.30 | C19: 80 | D19: 8 | E19: 8 | F19: 15 | G19: 1 | H19: 0 | I19: 6 | J19: 11 | K19: 0 | L19: 0 | M19: 180 | N19: 0 | O19: =SUM(C19:L19,N19) -> 129 | P19: =SUM(C19:N19) -> 309 | R19: 1600-1700 | S19: =SUM(C46:C49) -> 254 | T19: =SUM(D46:D49) -> 42 | U19: =SUM(E46:E49) -> 35 | V19: =SUM(F46:F49) -> 28 | W19: =SUM(G46:G49) -> 0 | X19: =SUM(H46:H49) -> 0 | Y19: =SUM(I46:I49) -> 15 | Z19: =SUM(J46:J49) -> 16 | ... AF19: =SUM(P46:P49) -> 1058
B20: 09.30 - 09.45 | C20: 89 | D20: 4 | E20: 7 | F20: 10 | G20: 1 | H20: 0 | I20: 5 | J20: 0 | K20: 0 | L20: 0 | M20: 146 | N20: 0 | O20: =SUM(C20:L20,N20) -> 116 | P20: =SUM(C20:N20) -> 262 | R20: 1700-1800 | S20: =SUM(C50:C53) -> 310 | T20: =SUM(D50:D53) -> 34 | U20: =SUM(E50:E53) -> 30 | V20: =SUM(F50:F53) -> 29 | W20: =SUM(G50:G53) -> 1 | X20: =SUM(H50:H53) -> 0 | Y20: =SUM(I50:I53) -> 12 | Z20: =SUM(J50:J53) -> 17 | ... AF20: =SUM(P50:P53) -> 1230
B21: 09.45 - 10.00 | C21: 53 | D21: 4 | E21: 7 | F21: 11 | G21: 0 | H21: 0 | I21: 2 | J21: 0 | K21: 2 | L21: 0 | M21: 155 | N21: 0 | O21: =SUM(C21:L21,N21) -> 79 | P21: =SUM(C21:N21) -> 234 | R21: 1800-1900 | S21: =SUM(C54:C57) -> 225 | T21: =SUM(D54:D57) -> 34 | U21: =SUM(E54:E57) -> 24 | V21: =SUM(F54:F57) -> 69 | W21: =SUM(G54:G57) -> 2 | X21: =SUM(H54:H57) -> 1 | Y21: =SUM(I54:I57) -> 12 | Z21: =SUM(J54:J57) -> 10 | ... AF21: =SUM(P54:P57) -> 1252
B22: 10.00 - 10.15 | C22: 100 | D22: 8 | E22: 8 | F22: 13 | G22: 0 | H22: 0 | I22: 14 | J22: 1 | K22: 1 | L22: 1 | M22: 191 | N22: 1 | O22: =SUM(C22:L22,N22) -> 147 | P22: =SUM(C22:N22) -> 338 | R22: AM Peak Hr | S22: =MAX(S10:S12) -> 302 | T22: =MAX(T10:T12) -> 35 | U22: =MAX(U10:U12) -> 28 | V22: =MAX(V10:V12) -> 89 | W22: =MAX(W10:W12) -> 2 | X22: =MAX(X10:X12) -> 3 | Y22: =MAX(Y10:Y12) -> 18 | Z22: =MAX(Z10:Z12) -> 27 | ... AF22: =MAX(AF10:AF12) -> 1110
B23: 10.15 - 10.30 | C23: 85 | D23: 20 | E23: 19 | F23: 25 | G23: 1 | H23: 0 | I23: 22 | J23: 10 | K23: 1 | L23: 0 | M23: 195 | N23: 0 | O23: =SUM(C23:L23,N23) -> 183 | P23: =SUM(C23:N23) -> 378 | R23: IP Peak Hr | S23: =MAX(S13:S18) -> 278 | T23: =MAX(T13:T18) -> 44 | U23: =MAX(U13:U18) -> 45 | V23: =MAX(V13:V18) -> 60 | W23: =MAX(W13:W18) -> 4 | X23: =MAX(X13:X18) -> 0 | Y23: =MAX(Y13:Y18) -> 51 | Z23: =MAX(Z13:Z18) -> 20 | ... AF23: =MAX(AF13:AF18) -> 1306
B24: 10.30 - 10.45 | C24: 48 | D24: 10 | E24: 9 | F24: 7 | G24: 0 | H24: 0 | I24: 6 | J24: 2 | K24: 0 | L24: 0 | M24: 230 | N24: 0 | O24: =SUM(C24:L24,N24) -> 82 | P24: =SUM(C24:N24) -> 312 | R24: PM Peak Hr | S24: =MAX(S19:S21) -> 310 | T24: =MAX(T19:T21) -> 42 | U24: =MAX(U19:U21) -> 35 | V24: =MAX(V19:V21) -> 69 | W24: =MAX(W19:W21) -> 2 | X24: =MAX(X19:X21) -> 1 | Y24: =MAX(Y19:Y21) -> 15 | Z24: =MAX(Z19:Z21) -> 17 | ... AF24: =MAX(AF19:AF21) -> 1252
B25: 10.45 - 11.00 | C25: 45 | D25: 6 | E25: 8 | F25: 15 | G25: 1 | H25: 0 | I25: 9 | J25: 4 | K25: 1 | L25: 0 | M25: 189 | N25: 0 | O25: =SUM(C25:L25,N25) -> 89 | P25: =SUM(C25:N25) -> 278 | R25: AM Period | S25: =SUM(S10:S12) -> 773 | T25: =SUM(T10:T12) -> 90 | U25: =SUM(U10:U12) -> 68 | V25: =SUM(V10:V12) -> 238 | W25: =SUM(W10:W12) -> 3 | X25: =SUM(X10:X12) -> 3 | Y25: =SUM(Y10:Y12) -> 35 | Z25: =SUM(Z10:Z12) -> 52 | ... AF25: =SUM(AF10:AF12) -> 2788
B26: 11.00 - 11.15 | C26: 75 | D26: 7 | E26: 13 | F26: 5 | G26: 0 | H26: 0 | I26: 7 | J26: 5 | K26: 1 | L26: 0 | M26: 196 | N26: 0 | O26: =SUM(C26:L26,N26) -> 113 | P26: =SUM(C26:N26) -> 309 | R26: IP Period | S26: =SUM(S13:S18) -> 1264 | T26: =SUM(T13:T18) -> 204 | U26: =SUM(U13:U18) -> 233 | V26: =SUM(V13:V18) -> 182 | W26: =SUM(W13:W18) -> 7 | X26: =SUM(X13:X18) -> 0 | Y26: =SUM(Y13:Y18) -> 146 | Z26: =SUM(Z13:Z18) -> 96 | ... AF26: =SUM(AF13:AF18) -> 5837
B27: 11.15 - 11.30 | C27: 78 | D27: 13 | E27: 9 | F27: 9 | G27: 2 | H27: 0 | I27: 13 | J27: 10 | K27: 1 | L27: 0 | M27: 198 | N27: 0 | O27: =SUM(C27:L27,N27) -> 135 | P27: =SUM(C27:N27) -> 333 | R27: PM Period | S27: =SUM(S19:S21) -> 789 | T27: =SUM(T19:T21) -> 110 | U27: =SUM(U19:U21) -> 89 | V27: =SUM(V19:V21) -> 126 | W27: =SUM(W19:W21) -> 3 | X27: =SUM(X19:X21) -> 1 | Y27: =SUM(Y19:Y21) -> 39 | Z27: =SUM(Z19:Z21) -> 43 | ... AF27: =SUM(AF19:AF21) -> 3540
B28: 11.30 - 11.45 | C28: 51 | D28: 2 | E28: 5 | F28: 12 | G28: 0 | H28: 0 | I28: 2 | J28: 2 | K28: 0 | L28: 1 | M28: 132 | N28: 0 | O28: =SUM(C28:L28,N28) -> 75 | P28: =SUM(C28:N28) -> 207 | R28: 12 Hours | S28: =SUM(S10:S21) -> 2826 | T28: =SUM(T10:T21) -> 404 | U28: =SUM(U10:U21) -> 390 | V28: =SUM(V10:V21) -> 546 | W28: =SUM(W10:W21) -> 13 | X28: =SUM(X10:X21) -> 4 | Y28: =SUM(Y10:Y21) -> 220 | Z28: =SUM(Z10:Z21) -> 191 | ... AF28: =SUM(AF10:AF21) -> 12165
B29: 11.45 - 12.00 | C29: 48 | D29: 11 | E29: 12 | F29: 5 | G29: 2 | H29: 0 | I29: 2 | J29: 1 | K29: 0 | L29: 1 | M29: 167 | N29: 0 | O29: =SUM(C29:L29,N29) -> 82 | P29: =SUM(C29:N29) -> 249
B30: 12.00 - 12.15 | C30: 65 | D30: 9 | E30: 11 | F30: 7 | G30: 0 | H30: 0 | I30: 2 | J30: 4 | K30: 0 | L30: 1 | M30: 180 | N30: 0 | O30: =SUM(C30:L30,N30) -> 99 | P30: =SUM(C30:N30) -> 279
B31: 12.15 - 12.30 | C31: 102 | D31: 14 | E31: 10 | F31: 4 | G31: 0 | H31: 0 | I31: 3 | J31: 6 | K31: 0 | L31: 2 | M31: 180 | N31: 0 | O31: =SUM(C31:L31,N31) -> 141 | P31: =SUM(C31:N31) -> 321
B32: 12.30 - 12.45 | C32: 43 | D32: 5 | E32: 10 | F32: 7 | G32: 0 | H32: 0 | I32: 3 | J32: 6 | K32: 0 | L32: 0 | M32: 215 | N32: 0 | O32: =SUM(C32:L32,N32) -> 74 | P32: =SUM(C32:N32) -> 289
B33: 12.45 - 13.00 | C33: 47 | D33: 8 | E33: 14 | F33: 8 | G33: 0 | H33: 0 | I33: 8 | J33: 4 | K33: 0 | L33: 1 | M33: 165 | N33: 0 | O33: =SUM(C33:L33,N33) -> 90 | P33: =SUM(C33:N33) -> 255
B34: 13.00 - 13.15 | C34: 51 | D34: 8 | E34: 11 | F34: 6 | G34: 1 | H34: 0 | I34: 6 | J34: 4 | K34: 0 | L34: 1 | M34: 154 | N34: 0 | O34: =SUM(C34:L34,N34) -> 88 | P34: =SUM(C34:N34) -> 242
B35: 13.15 - 13.30 | C35: 69 | D35: 9 | E35: 7 | F35: 5 | G35: 0 | H35: 0 | I35: 7 | J35: 4 | K35: 1 | L35: 1 | M35: 128 | N35: 0 | O35: =SUM(C35:L35,N35) -> 103 | P35: =SUM(C35:N35) -> 231
B36: 13.30 - 13.45 | C36: 39 | D36: 4 | E36: 7 | F36: 4 | G36: 0 | H36: 0 | I36: 2 | J36: 4 | K36: 1 | L36: 1 | M36: 166 | N36: 0 | O36: =SUM(C36:L36,N36) -> 62 | P36: =SUM(C36:N36) -> 228
B37: 13.45 - 14.00 | C37: 31 | D37: 4 | E37: 9 | F37: 8 | G37: 0 | H37: 0 | I37: 4 | J37: 8 | K37: 0 | L37: 1 | M37: 163 | N37: 0 | O37: =SUM(C37:L37,N37) -> 65 | P37: =SUM(C37:N37) -> 228
B38: 14.00 - 14.15 | C38: 40 | D38: 8 | E38: 5 | F38: 8 | G38: 0 | H38: 0 | I38: 4 | J38: 3 | K38: 1 | L38: 1 | M38: 180 | N38: 0 | O38: =SUM(C38:L38,N38) -> 70 | P38: =SUM(C38:N38) -> 250
B39: 14.15 - 14.30 | C39: 38 | D39: 16 | E39: 13 | F39: 2 | G39: 0 | H39: 0 | I39: 6 | J39: 4 | K39: 2 | L39: 4 | M39: 140 | N39: 0 | O39: =SUM(C39:L39,N39) -> 85 | P39: =SUM(C39:N39) -> 225
B40: 14.30 - 14.45 | C40: 22 | D40: 9 | E40: 9 | F40: 7 | G40: 0 | H40: 0 | I40: 7 | J40: 2 | K40: 0 | L40: 0 | M40: 129 | N40: 0 | O40: =SUM(C40:L40,N40) -> 56 | P40: =SUM(C40:N40) -> 185
... B57: 18.45 - 19.00 | C57: 60 | D57: 13 | E57: 6 | F57: 5 | G57: 0 | H57: 0 | I57: 1 | J57: 0 | K57: 0 | L57: 0 | M57: 185 | N57: 0 | O57: =SUM(C57:L57,N57) -> 85 | P57: =SUM(C57:N57) -> 270
B58: Totals | C58: =SUM(C10:C57) -> 2826 | D58: =SUM(D10:D57) -> 404 | E58: =SUM(E10:E57) -> 390 | F58: =SUM(F10:F57) -> 546 | G58: =SUM(G10:G57) -> 13 | H58: =SUM(H10:H57) -> 4 | I58: =SUM(I10:I57) -> 220 | J58: =SUM(J10:J57) -> 191 | ... P58: =SUM(P10:P57) -> 12165
...

Sheet 23.07 Lubiri-Ndeeba
B1: Consultancy services for Preparation of Expressway Development Master Plan (EDMP) for Uganda
B2: MANUAL CLASSIFIED COUNT (MCC)
B3: ROAD NAME: | C3: MCC - CI - STN03 - KALINDA ROAD
C5: Date | D5: 23.07.19 | F5: Location | G5: ='22.07 Lubiri -Ndeeba'!G5:H5 -> Before Shell | J5: Surveyor | K5: ='22.07 Lubiri -Ndeeba'!K5:L5 -> Maiso. M. Gadafi
C6: Dir. From | D6: ='22.07 Lubiri -Ndeeba'!D6:E6 -> Lubiri | F6: Dir. To | G6: ='22.07 Lubiri -Ndeeba'!G6:H6 -> Ndeeba | J6: Supervisor | K6: ='22.07 Lubiri -Ndeeba'!K6:L6 -> Denis
B8: Time / Veh Type | R8: SUMMARY TRAFFIC VOLUMES
C9: 1. Car | D9: 2. Station Wagon | E9: 3. Pickups | F9: 4. Minibus, matatu | G9: 5. Medium bus | H9: 6. Large Bus | I9: 7. Light Truck | J9: 8. Medium Truck | K9: 9. Heavy truck | L9: 10. Truck Trailer | M9: 11. Motor cycles | N9: 12. Tractors | O9: Total Excl M/Cycles | P9: Total All | R9: Time | S9: 1. Car | T9: 2. Station Wagon | U9: 3. Pickups | V9: 4. Minibus, matatu | W9: 5. Medium bus | X9: 6. Large Bus | Y9: 7. Light Truck | Z9: 8. Medium Truck | AA9: 9. Heavy truck | AB9: 10. Truck Trailer | AC9: 11. Motorcycles | AD9: 12. Tractors, Graders | AE9: Total Excl M/ Cycles | AF9: Total All
B10: 07.00 - 07.15 | C10: 22 | D10: 1 | E10: 0 | F10: 10 | G10: 0 | H10: 0 | I10: 0 | J10: 2 | K10: 0 | L10: 0 | M10: 91 | N10: 0 | O10: =SUM(C10:L10,N10) -> 35 | P10: =SUM(C10:N10) -> 126 | R10: 0700-0800 | S10: =SUM(C10:C13) -> 81 | T10: =SUM(D10:D13) -> 7 | U10: =SUM(E10:E13) -> 6 | V10: =SUM(F10:F13) -> 58 | W10: =SUM(G10:G13) -> 0 | X10: =SUM(H10:H13) -> 0 | Y10: =SUM(I10:I13) -> 4 | Z10: =SUM(J10:J13) -> 9 | ... AF10: =SUM(P10:P13) -> 732
B11: 07.15 - 07.30 | C11: 27 | D11: 2 | E11: 1 | F11: 15 | G11: 0 | H11: 0 | I11: 2 | J11: 1 | K11: 0 | L11: 0 | M11: 123 | N11: 0 | O11: =SUM(C11:L11,N11) -> 48 | P11: =SUM(C11:N11) -> 171 | R11: 0800-0900 | S11: =SUM(C14:C17) -> 81 | T11: =SUM(D14:D17) -> 14 | U11: =SUM(E14:E17) -> 11 | V11: =SUM(F14:F17) -> 82 | W11: =SUM(G14:G17) -> 1 | X11: =SUM(H14:H17) -> 0 | Y11: =SUM(I14:I17) -> 10 | Z11: =SUM(J14:J17) -> 4 | ... AF11: =SUM(P14:P17) -> 1500
B12: 07.30 - 07.45 | C12: 23 | D12: 1 | E12: 3 | F12: 17 | G12: 0 | H12: 0 | I12: 1 | J12: 3 | K12: 0 | L12: 0 | M12: 163 | N12: 0 | O12: =SUM(C12:L12,N12) -> 48 | P12: =SUM(C12:N12) -> 211 | R12: 0900-1000 | S12: =SUM(C18:C21) -> 86 | T12: =SUM(D18:D21) -> 23 | U12: =SUM(E18:E21) -> 15 | V12: =SUM(F18:F21) -> 68 | W12: =SUM(G18:G21) -> 4 | X12: =SUM(H18:H21) -> 0 | Y12: =SUM(I18:I21) -> 25 | Z12: =SUM(J18:J21) -> 17 | ... AF12: =SUM(P18:P21) -> 1442
B13: 07.45 - 08.00 | C13: 9 | D13: 3 | E13: 2 | F13: 16 | G13: 0 | H13: 0 | I13: 1 | J13: 3 | K13: 0 | L13: 0 | M13: 190 | N13: 0 | O13: =SUM(C13:L13,N13) -> 34 | P13: =SUM(C13:N13) -> 224 | R13: 1000-1100 | S13: =SUM(C22:C25) -> 118 | T13: =SUM(D22:D25) -> 25 | U13: =SUM(E22:E25) -> 12 | V13: =SUM(F22:F25) -> 64 | W13: =SUM(G22:G25) -> 0 | X13: =SUM(H22:H25) -> 1 | Y13: =SUM(I22:I25) -> 33 | Z13: =SUM(J22:J25) -> 13 | ... AF13: =SUM(P22:P25) -> 1231
B14: 08.00 - 08.15 | C14: 28 | D14: 4 | E14: 3 | F14: 28 | G14: 0 | H14: 0 | I14: 2 | J14: 0 | K14: 1 | L14: 0 | M14: 310 | N14: 0 | O14: =SUM(C14:L14,N14) -> 66 | P14: =SUM(C14:N14) -> 376 | R14: 1100-1200 | S14: =SUM(C26:C29) -> 143 | T14: =SUM(D26:D29) -> 28 | U14: =SUM(E26:E29) -> 15 | V14: =SUM(F26:F29) -> 59 | W14: =SUM(G26:G29) -> 2 | X14: =SUM(H26:H29) -> 0 | Y14: =SUM(I26:I29) -> 29 | Z14: =SUM(J26:J29) -> 24 | ... AF14: =SUM(P26:P29) -> 1312
B15: 08.15 - 08.30 | C15: 18 | D15: 2 | E15: 3 | F15: 20 | G15: 0 | H15: 0 | I15: 6 | J15: 0 | K15: 0 | L15: 0 | M15: 290 | N15: 0 | O15: =SUM(C15:L15,N15) -> 49 | P15: =SUM(C15:N15) -> 339 | R15: 1200-1300 | S15: =SUM(C30:C33) -> 135 | T15: =SUM(D30:D33) -> 42 | U15: =SUM(E30:E33) -> 17 | V15: =SUM(F30:F33) -> 58 | W15: =SUM(G30:G33) -> 5 | X15: =SUM(H30:H33) -> 0 | Y15: =SUM(I30:I33) -> 29 | Z15: =SUM(J30:J33) -> 23 | ... AF15: =SUM(P30:P33) -> 1415
B16: 08.30 - 08.45 | C16: 19 | D16: 4 | E16: 2 | F16: 18 | G16: 1 | H16: 0 | I16: 0 | J16: 1 | K16: 1 | L16: 0 | M16: 350 | N16: 0 | O16: =SUM(C16:L16,N16) -> 46 | P16: =SUM(C16:N16) -> 396 | R16: 1300-1400 | S16: =SUM(C34:C37) -> 147 | T16: =SUM(D34:D37) -> 29 | U16: =SUM(E34:E37) -> 19 | V16: =SUM(F34:F37) -> 57 | W16: =SUM(G34:G37) -> 1 | X16: =SUM(H34:H37) -> 0 | Y16: =SUM(I34:I37) -> 29 | Z16: =SUM(J34:J37) -> 22 | ... AF16: =SUM(P34:P37) -> 1262
B17: 08.45 - 9.00 | C17: 16 | D17: 4 | E17: 3 | F17: 16 | G17: 0 | H17: 0 | I17: 2 | J17: 3 | K17: 0 | L17: 0 | M17: 345 | N17: 0 | O17: =SUM(C17:L17,N17) -> 44 | P17: =SUM(C17:N17) -> 389 | R17: 1400-1500 | S17: =SUM(C38:C41) -> 155 | T17: =SUM(D38:D41) -> 25 | U17: =SUM(E38:E41) -> 12 | V17: =SUM(F38:F41) -> 48 | W17: =SUM(G38:G41) -> 1 | X17: =SUM(H38:H41) -> 0 | Y17: =SUM(I38:I41) -> 25 | Z17: =SUM(J38:J41) -> 17 | ... AF17: =SUM(P38:P41) -> 1007
B18: 09.00 - 09.15 | C18: 19 | D18: 4 | E18: 2 | F18: 12 | G18: 0 | H18: 0 | I18: 5 | J18: 2 | K18: 1 | L18: 0 | M18: 238 | N18: 0 | O18: =SUM(C18:L18,N18) -> 45 | P18: =SUM(C18:N18) -> 283 | R18: 1500-1600 | S18: =SUM(C42:C45) -> 160 | T18: =SUM(D42:D45) -> 24 | U18: =SUM(E42:E45) -> 13 | V18: =SUM(F42:F45) -> 71 | W18: =SUM(G42:G45) -> 1 | X18: =SUM(H42:H45) -> 0 | Y18: =SUM(I42:I45) -> 27 | Z18: =SUM(J42:J45) -> 30 | ... AF18: =SUM(P42:P45) -> 1219
B19: 09.15 - 09.30 | C19: 25 | D19: 3 | E19: 2 | F19: 22 | G19: 2 | H19: 0 | I19: 7 | J19: 4 | K19: 2 | L19: 0 | M19: 296 | N19: 0 | O19: =SUM(C19:L19,N19) -> 67 | P19: =SUM(C19:N19) -> 363 | R19: 1600-1700 | S19: =SUM(C46:C49) -> 162 | T19: =SUM(D46:D49) -> 40 | U19: =SUM(E46:E49) -> 19 | V19: =SUM(F46:F49) -> 63 | W19: =SUM(G46:G49) -> 4 | X19: =SUM(H46:H49) -> 0 | Y19: =SUM(I46:I49) -> 24 | Z19: =SUM(J46:J49) -> 21 | ... AF19: =SUM(P46:P49) -> 1147
B20: 09.30 - 09.45 | C20: 21 | D20: 6 | E20: 2 | F20: 16 | G20: 2 | H20: 0 | I20: 7 | J20: 10 | K20: 0 | L20: 0 | M20: 326 | N20: 0 | O20: =SUM(C20:L20,N20) -> 64 | P20: =SUM(C20:N20) -> 390 | R20: 1700-1800 | S20: =SUM(C50:C53) -> 283 | T20: =SUM(D50:D53) -> 47 | U20: =SUM(E50:E53) -> 18 | V20: =SUM(F50:F53) -> 69 | W20: =SUM(G50:G53) -> 0 | X20: =SUM(H50:H53) -> 0 | Y20: =SUM(I50:I53) -> 22 | Z20: =SUM(J50:J53) -> 14 | ... AF20: =SUM(P50:P53) -> 1675
B21: 09.45 - 10.00 | C21: 21 | D21: 10 | E21: 9 | F21: 18 | G21: 0 | H21: 0 | I21: 6 | J21: 1 | K21: 2 | L21: 0 | M21: 339 | N21: 0 | O21: =SUM(C21:L21,N21) -> 67 | P21: =SUM(C21:N21) -> 406 | R21: 1800-1900 | S21: =SUM(C54:C57) -> 196 | T21: =SUM(D54:D57) -> 28 | U21: =SUM(E54:E57) -> 17 | V21: =SUM(F54:F57) -> 107 | W21: =SUM(G54:G57) -> 2 | X21: =SUM(H54:H57) -> 0 | Y21: =SUM(I54:I57) -> 15 | Z21: =SUM(J54:J57) -> 18 | ... AF21: =SUM(P54:P57) -> 1348
B22: 10.00 - 10.15 | C22: 25 | D22: 10 | E22: 3 | F22: 17 | G22: 0 | H22: 0 | I22: 9 | J22: 0 | K22: 0 | L22: 0 | M22: 294 | N22: 0 | O22: =SUM(C22:L22,N22) -> 64 | P22: =SUM(C22:N22) -> 358 | R22: AM Peak Hr | S22: =MAX(S10:S12) -> 86 | T22: =MAX(T10:T12) -> 23 | U22: =MAX(U10:U12) -> 15 | V22: =MAX(V10:V12) -> 82 | W22: =MAX(W10:W12) -> 4 | X22: =MAX(X10:X12) -> 0 | Y22: =MAX(Y10:Y12) -> 25 | Z22: =MAX(Z10:Z12) -> 17 | ... AF22: =MAX(AF10:AF12) -> 1500
B23: 10.15 - 10.30 | C23: 28 | D23: 6 | E23: 2 | F23: 13 | G23: 0 | H23: 1 | I23: 8 | J23: 4 | K23: 0 | L23: 1 | M23: 240 | N23: 0 | O23: =SUM(C23:L23,N23) -> 63 | P23: =SUM(C23:N23) -> 303 | R23: IP Peak Hr | S23: =MAX(S13:S18) -> 160 | T23: =MAX(T13:T18) -> 42 | U23: =MAX(U13:U18) -> 19 | V23: =MAX(V13:V18) -> 71 | W23: =MAX(W13:W18) -> 5 | X23: =MAX(X13:X18) -> 1 | Y23: =MAX(Y13:Y18) -> 33 | Z23: =MAX(Z13:Z18) -> 30 | ... AF23: =MAX(AF13:AF18) -> 1415
B24: 10.30 - 10.45 | C24: 34 | D24: 6 | E24: 3 | F24: 16 | G24: 0 | H24: 0 | I24: 7 | J24: 8 | K24: 0 | L24: 0 | M24: 235 | N24: 0 | O24: =SUM(C24:L24,N24) -> 74 | P24: =SUM(C24:N24) -> 309 | R24: PM Peak Hr | S24: =MAX(S19:S21) -> 283 | T24: =MAX(T19:T21) -> 47 | U24: =MAX(U19:U21) -> 19 | V24: =MAX(V19:V21) -> 107 | W24: =MAX(W19:W21) -> 4 | X24: =MAX(X19:X21) -> 0 | Y24: =MAX(Y19:Y21) -> 24 | Z24: =MAX(Z19:Z21) -> 21 | ... AF24: =MAX(AF19:AF21) -> 1675
B25: 10.45 - 11.00 | C25: 31 | D25: 3 | E25: 4 | F25: 18 | G25: 0 | H25: 0 | I25: 9 | J25: 1 | K25: 0 | L25: 0 | M25: 195 | N25: 0 | O25: =SUM(C25:L25,N25) -> 66 | P25: =SUM(C25:N25) -> 261 | R25: AM Period | S25: =SUM(S10:S12) -> 248 | T25: =SUM(T10:T12) -> 44 | U25: =SUM(U10:U12) -> 32 | V25: =SUM(V10:V12) -> 208 | W25: =SUM(W10:W12) -> 5 | X25: =SUM(X10:X12) -> 0 | Y25: =SUM(Y10:Y12) -> 39 | Z25: =SUM(Z10:Z12) -> 30 | ... AF25: =SUM(AF10:AF12) -> 3674
B26: 11.00 - 11.15 | C26: 37 | D26: 6 | E26: 4 | F26: 19 | G26: 0 | H26: 0 | I26: 9 | J26: 8 | K26: 0 | L26: 0 | M26: 310 | N26: 1 | O26: =SUM(C26:L26,N26) -> 84 | P26: =SUM(C26:N26) -> 394 | R26: IP Period | S26: =SUM(S13:S18) -> 858 | T26: =SUM(T13:T18) -> 173 | U26: =SUM(U13:U18) -> 88 | V26: =SUM(V13:V18) -> 357 | W26: =SUM(W13:W18) -> 10 | X26: =SUM(X13:X18) -> 1 | Y26: =SUM(Y13:Y18) -> 172 | Z26: =SUM(Z13:Z18) -> 129 | ... AF26: =SUM(AF13:AF18) -> 7446
B27: 11.15 - 11.30 | C27: 39 | D27: 6 | E27: 5 | F27: 19 | G27: 2 | H27: 0 | I27: 7 | J27: 7 | K27: 0 | L27: 0 | M27: 245 | N27: 0 | O27: =SUM(C27:L27,N27) -> 85 | P27: =SUM(C27:N27) -> 330 | R27: PM Period | S27: =SUM(S19:S21) -> 641 | T27: =SUM(T19:T21) -> 115 | U27: =SUM(U19:U21) -> 54 | V27: =SUM(V19:V21) -> 239 | W27: =SUM(W19:W21) -> 6 | X27: =SUM(X19:X21) -> 0 | Y27: =SUM(Y19:Y21) -> 61 | Z27: =SUM(Z19:Z21) -> 53 | ... AF27: =SUM(AF19:AF21) -> 4170
B28: 11.30 - 11.45 | C28: 35 | D28: 7 | E28: 2 | F28: 7 | G28: 0 | H28: 0 | I28: 6 | J28: 7 | K28: 0 | L28: 1 | M28: 210 | N28: 0 | O28: =SUM(C28:L28,N28) -> 65 | P28: =SUM(C28:N28) -> 275 | R28: 12 Hours | S28: =SUM(S10:S21) -> 1747 | T28: =SUM(T10:T21) -> 332 | U28: =SUM(U10:U21) -> 174 | V28: =SUM(V10:V21) -> 804 | W28: =SUM(W10:W21) -> 21 | X28: =SUM(X10:X21) -> 1 | Y28: =SUM(Y10:Y21) -> 272 | Z28: =SUM(Z10:Z21) -> 212 | ... AF28: =SUM(AF10:AF21) -> 15290
B29: 11.45 - 12.00 | C29: 32 | D29: 9 | E29: 4 | F29: 14 | G29: 0 | H29: 0 | I29: 7 | J29: 2 | K29: 0 | L29: 0 | M29: 245 | N29: 0 | O29: =SUM(C29:L29,N29) -> 68 | P29: =SUM(C29:N29) -> 313
B30: 12.00 - 12.15 | C30: 34 | D30: 19 | E30: 6 | F30: 15 | G30: 0 | H30: 0 | I30: 15 | J30: 8 | K30: 0 | L30: 0 | M30: 292 | N30: 0 | O30: =SUM(C30:L30,N30) -> 97 | P30: =SUM(C30:N30) -> 389
B31: 12.15 - 12.30 | C31: 30 | D31: 8 | E31: 2 | F31: 8 | G31: 2 | H31: 0 | I31: 6 | J31: 11 | K31: 0 | L31: 0 | M31: 250 | N31: 0 | O31: =SUM(C31:L31,N31) -> 67 | P31: =SUM(C31:N31) -> 317
B32: 12.30 - 12.45 | C32: 32 | D32: 9 | E32: 5 | F32: 17 | G32: 3 | H32: 0 | I32: 1 | J32: 2 | K32: 1 | L32: 0 | M32: 285 | N32: 0 | O32: =SUM(C32:L32,N32) -> 70 | P32: =SUM(C32:N32) -> 355
B33: 12.45 - 13.00 | C33: 39 | D33: 6 | E33: 4 | F33: 18 | G33: 0 | H33: 0 | I33: 7 | J33: 2 | K33: 1 | L33: 2 | M33: 275 | N33: 0 | O33: =SUM(C33:L33,N33) -> 79 | P33: =SUM(C33:N33) -> 354
B34: 13.00 - 13.15 | C34: 34 | D34: 5 | E34: 4 | F34: 18 | G34: 0 | H34: 0 | I34: 7 | J34: 2 | K34: 0 | L34: 0 | M34: 222 | N34: 0 | O34: =SUM(C34:L34,N34) -> 70 | P34: =SUM(C34:N34) -> 292
B35: 13.15 - 13.30 | C35: 31 | D35: 5 | E35: 5 | F35: 13 | G35: 0 | H35: 0 | I35: 8 | J35: 10 | K35: 0 | L35: 0 | M35: 245 | N35: 0 | O35: =SUM(C35:L35,N35) -> 72 | P35: =SUM(C35:N35) -> 317
B36: 13.30 - 13.45 | C36: 37 | D36: 6 | E36: 4 | F36: 9 | G36: 1 | H36: 0 | I36: 5 | J36: 0 | K36: 0 | L36: 2 | M36: 198 | N36: 1 | O36: =SUM(C36:L36,N36) -> 65 | P36: =SUM(C36:N36) -> 263
B37: 13.45 - 14.00 | C37: 45 | D37: 13 | E37: 6 | F37: 17 | G37: 0 | H37: 0 | I37: 9 | J37: 10 | K37: 0 | L37: 0 | M37: 290 | N37: 0 | O37: =SUM(C37:L37,N37) -> 100 | P37: =SUM(C37:N37) -> 390
B38: 14.00 - 14.15 | C38: 46 | D38: 6 | E38: 5 | F38: 11 | G38: 0 | H38: 0 | I38: 6 | J38: 4 | K38: 0 | L38: 0 | M38: 220 | N38: 0 | O38: =SUM(C38:L38,N38) -> 78 | P38: =SUM(C38:N38) -> 298
B39: 14.15 - 14.30 | C39: 43 | D39: 5 | E39: 3 | F39: 11 | G39: 0 | H39: 0 | I39: 10 | J39: 9 | K39: 0 | L39: 0 | M39: 167 | N39: 0 | O39: =SUM(C39:L39,N39) -> 81 | P39: =SUM(C39:N39) -> 248
B40: 14.30 - 14.45 | C40: 35 | D40: 7 | E40: 2 | F40: 13 | G40: 1 | H40: 0 | I40: 4 | J40: 3 | K40: 1 | L40: 0 | M40: 135 | N40: 0 | O40: =SUM(C40:L40,N40) -> 66 | P40: =SUM(C40:N40) -> 201
... B57: 18.45 - 19.00 | C57: 38 | D57: 5 | E57: 8 | F57: 38 | G57: 0 | H57: 0 | I57: 4 | J57: 2 | K57: 0 | L57: 2 | M57: 112 | N57: 0 | O57: =SUM(C57:L57,N57) -> 97 | P57: =SUM(C57:N57) -> 209
B58: Totals | C58: =SUM(C10:C57) -> 1747 | D58: =SUM(D10:D57) -> 332 | E58: =SUM(E10:E57) -> 174 | F58: =SUM(F10:F57) -> 804 | G58: =SUM(G10:G57) -> 21 | H58: =SUM(H10:H57) -> 1 | I58: =SUM(I10:I57) -> 272 | J58: =SUM(J10:J57) -> 212 | ... P58: =SUM(P10:P57) -> 15290
...

Sheet 23.07 Ndeeba-Lubiri
B1: Consultancy services for Preparation of Expressway Development Master Plan (EDMP) for Uganda
B2: MANUAL CLASSIFIED COUNT (MCC)
B3: ROAD NAME: | C3: ='22.07 Ndeeba-Lubiri'!C3:G3 -> MCC - C1 - STN03- KALINDA ROAD
C5: Date | D5: ='23.07 Lubiri-Ndeeba'!D5 -> 23.07.19 | F5: Location | G5: ='22.07 Lubiri -Ndeeba'!G5:H5 -> Before Shell | J5: Surveyor | K5: Kizito Geofrey
C6: Dir. From | D6: Ndeeba | F6: Dir. To | G6: Lubiri | J6: Supervisor | K6: ='22.07 Lubiri -Ndeeba'!K6:L6 -> Denis
B8: Time / Veh Type | R8: SUMMARY TRAFFIC VOLUMES
C9: 1. Car | D9: 2. Station Wagon | E9: 3. Pickups | F9: 4. Minibus, matatu | G9: 5. Medium bus | H9: 6. Large Bus | I9: 7. Light Truck | J9: 8. Medium Truck | K9: 9. Heavy truck | L9: 10. Truck Trailer | M9: 11. Motor cycles | N9: 12. Tractors | O9: Total Excl M/Cycles | P9: Total All | R9: Time | S9: 1. Car | T9: 2. Station Wagon | U9: 3. Pickups | V9: 4. Minibus, matatu | W9: 5. Medium bus | X9: 6. Large Bus | Y9: 7. Light Truck | Z9: 8. Medium Truck | AA9: 9. Heavy truck | AB9: 10. Truck Trailer | AC9: 11. Motorcycles | AD9: 12. Tractors, Graders | AE9: Total Excl M/ Cycles | AF9: Total All
B10: 07.00 - 07.15 | C10: 100 | D10: 13 | E10: 9 | F10: 36 | G10: 0 | H10: 0 | I10: 5 | J10: 2 | K10: 0 | L10: 0 | M10: 120 | N10: 0 | O10: =SUM(C10:L10,N10) -> 165 | P10: =SUM(C10:N10) -> 285 | R10: 0700-0800 | S10: =SUM(C10:C13) -> 460 | T10: =SUM(D10:D13) -> 43 | U10: =SUM(E10:E13) -> 61 | V10: =SUM(F10:F13) -> 177 | W10: =SUM(G10:G13) -> 1 | X10: =SUM(H10:H13) -> 0 | Y10: =SUM(I10:I13) -> 19 | Z10: =SUM(J10:J13) -> 10 | ... AF10: =SUM(P10:P13) -> 1398
B11: 07.15 - 07.30 | C11: 110 | D11: 11 | E11: 20 | F11: 42 | G11: 1 | H11: 0 | I11: 6 | J11: 4 | K11: 0 | L11: 0 | M11: 145 | N11: 0 | O11: =SUM(C11:L11,N11) -> 194 | P11: =SUM(C11:N11) -> 339 | R11: 0800-0900 | S11: =SUM(C14:C17) -> 450 | T11: =SUM(D14:D17) -> 60 | U11: =SUM(E14:E17) -> 47 | V11: =SUM(F14:F17) -> 164 | W11: =SUM(G14:G17) -> 2 | X11: =SUM(H14:H17) -> 1 | Y11: =SUM(I14:I17) -> 27 | Z11: =SUM(J14:J17) -> 5 | ... AF11: =SUM(P14:P17) -> 1602
B12: 07.30 - 07.45 | C12: 110 | D12: 8 | E12: 5 | F12: 49 | G12: 0 | H12: 0 | I12: 5 | J12: 3 | K12: 4 | L12: 0 | M12: 175 | N12: 0 | O12: =SUM(C12:L12,N12) -> 184 | P12: =SUM(C12:N12) -> 359 | R12: 0900-1000 | S12: =SUM(C18:C21) -> 480 | T12: =SUM(D18:D21) -> 40 | U12: =SUM(E18:E21) -> 42 | V12: =SUM(F18:F21) -> 58 | W12: =SUM(G18:G21) -> 1 | X12: =SUM(H18:H21) -> 0 | Y12: =SUM(I18:I21) -> 27 | Z12: =SUM(J18:J21) -> 6 | ... AF12: =SUM(P18:P21) -> 1663
B13: 07.45 - 08.00 | C13: 140 | D13: 11 | E13: 27 | F13: 50 | G13: 0 | H13: 0 | I13: 3 | J13: 1 | K13: 3 | L13: 0 | M13: 180 | N13: 0 | O13: =SUM(C13:L13,N13) -> 235 | P13: =SUM(C13:N13) -> 415 | R13: 1000-1100 | S13: =SUM(C22:C25) -> 295 | T13: =SUM(D22:D25) -> 39 | U13: =SUM(E22:E25) -> 23 | V13: =SUM(F22:F25) -> 34 | W13: =SUM(G22:G25) -> 0 | X13: =SUM(H22:H25) -> 0 | Y13: =SUM(I22:I25) -> 24 | Z13: =SUM(J22:J25) -> 10 | ... AF13: =SUM(P22:P25) -> 1427
B14: 08.00 - 08.15 | C14: 110 | D14: 11 | E14: 10 | F14: 37 | G14: 0 | H14: 0 | I14: 5 | J14: 0 | K14: 0 | L14: 0 | M14: 195 | N14: 0 | O14: =SUM(C14:L14,N14) -> 173 | P14: =SUM(C14:N14) -> 368 | R14: 1100-1200 | S14: =SUM(C26:C29) -> 318 | T14: =SUM(D26:D29) -> 34 | U14: =SUM(E26:E29) -> 41 | V14: =SUM(F26:F29) -> 27 | W14: =SUM(G26:G29) -> 2 | X14: =SUM(H26:H29) -> 0 | Y14: =SUM(I26:I29) -> 24 | Z14: =SUM(J26:J29) -> 10 | ... AF14: =SUM(P26:P29) -> 1367
B15: 08.15 - 08.30 | C15: 115 | D15: 22 | E15: 12 | F15: 59 | G15: 0 | H15: 0 | I15: 6 | J15: 2 | K15: 0 | L15: 0 | M15: 190 | N15: 0 | O15: =SUM(C15:L15,N15) -> 216 | P15: =SUM(C15:N15) -> 406 | R15: 1200-1300 | S15: =SUM(C30:C33) -> 284 | T15: =SUM(D30:D33) -> 36 | U15: =SUM(E30:E33) -> 50 | V15: =SUM(F30:F33) -> 23 | W15: =SUM(G30:G33) -> 2 | X15: =SUM(H30:H33) -> 0 | Y15: =SUM(I30:I33) -> 32 | Z15: =SUM(J30:J33) -> 15 | ... AF15: =SUM(P30:P33) -> 1245
B16: 08.30 - 08.45 | C16: 115 | D16: 14 | E16: 13 | F16: 36 | G16: 2 | H16: 1 | I16: 12 | J16: 1 | K16: 0 | L16: 0 | M16: 220 | N16: 0 | O16: =SUM(C16:L16,N16) -> 194 | P16: =SUM(C16:N16) -> 414 | R16: 1300-1400 | S16: =SUM(C34:C37) -> 360 | T16: =SUM(D34:D37) -> 31 | U16: =SUM(E34:E37) -> 34 | V16: =SUM(F34:F37) -> 14 | W16: =SUM(G34:G37) -> 2 | X16: =SUM(H34:H37) -> 0 | Y16: =SUM(I34:I37) -> 15 | Z16: =SUM(J34:J37) -> 20 | ... AF16: =SUM(P34:P37) -> 1318
B17: 08.45 - 9.00 | C17: 110 | D17: 13 | E17: 12 | F17: 32 | G17: 0 | H17: 0 | I17: 4 | J17: 2 | K17: 1 | L17: 0 | M17: 240 | N17: 0 | O17: =SUM(C17:L17,N17) -> 174 | P17: =SUM(C17:N17) -> 414 | R17: 1400-1500 | S17: =SUM(C38:C41) -> 216 | T17: =SUM(D38:D41) -> 23 | U17: =SUM(E38:E41) -> 23 | V17: =SUM(F38:F41) -> 16 | W17: =SUM(G38:G41) -> 2 | X17: =SUM(H38:H41) -> 0 | Y17: =SUM(I38:I41) -> 14 | Z17: =SUM(J38:J41) -> 13 | ... AF17: =SUM(P38:P41) -> 1068
B18: 09.00 - 09.15 | C18: 110 | D18: 10 | E18: 6 | F18: 15 | G18: 1 | H18: 0 | I18: 8 | J18: 0 | K18: 2 | L18: 0 | M18: 225 | N18: 0 | O18: =SUM(C18:L18,N18) -> 152 | P18: =SUM(C18:N18) -> 377 | R18: 1500-1600 | S18: =SUM(C42:C45) -> 299 | T18: =SUM(D42:D45) -> 25 | U18: =SUM(E42:E45) -> 36 | V18: =SUM(F42:F45) -> 19 | W18: =SUM(G42:G45) -> 1 | X18: =SUM(H42:H45) -> 0 | Y18: =SUM(I42:I45) -> 19 | Z18: =SUM(J42:J45) -> 19 | ... AF18: =SUM(P42:P45) -> 1270
B19: 09.15 - 09.30 | C19: 120 | D19: 10 | E19: 15 | F19: 18 | G19: 0 | H19: 0 | I19: 7 | J19: 1 | K19: 0 | L19: 0 | M19: 265 | N19: 0 | O19: =SUM(C19:L19,N19) -> 171 | P19: =SUM(C19:N19) -> 436 | R19: 1600-1700 | S19: =SUM(C46:C49) -> 281 | T19: =SUM(D46:D49) -> 26 | U19: =SUM(E46:E49) -> 34 | V19: =SUM(F46:F49) -> 31 | W19: =SUM(G46:G49) -> 1 | X19: =SUM(H46:H49) -> 0 | Y19: =SUM(I46:I49) -> 12 | Z19: =SUM(J46:J49) -> 11 | ... AF19: =SUM(P46:P49) -> 1098
B20: 09.30 - 09.45 | C20: 135 | D20: 4 | E20: 8 | F20: 10 | G20: 0 | H20: 0 | I20: 5 | J20: 2 | K20: 2 | L20: 0 | M20: 235 | N20: 0 | O20: =SUM(C20:L20,N20) -> 166 | P20: =SUM(C20:N20) -> 401 | R20: 1700-1800 | S20: =SUM(C50:C53) -> 363 | T20: =SUM(D50:D53) -> 28 | U20: =SUM(E50:E53) -> 37 | V20: =SUM(F50:F53) -> 28 | W20: =SUM(G50:G53) -> 4 | X20: =SUM(H50:H53) -> 1 | Y20: =SUM(I50:I53) -> 26 | Z20: =SUM(J50:J53) -> 12 | ... AF20: =SUM(P50:P53) -> 1377
B21: 09.45 - 10.00 | C21: 115 | D21: 16 | E21: 13 | F21: 15 | G21: 0 | H21: 0 | I21: 7 | J21: 3 | K21: 0 | L21: 0 | M21: 280 | N21: 0 | O21: =SUM(C21:L21,N21) -> 169 | P21: =SUM(C21:N21) -> 449 | R21: 1800-1900 | S21: =SUM(C54:C57) -> 395 | T21: =SUM(D54:D57) -> 36 | U21: =SUM(E54:E57) -> 14 | V21: =SUM(F54:F57) -> 108 | W21: =SUM(G54:G57) -> 8 | X21: =SUM(H54:H57) -> 1 | Y21: =SUM(I54:I57) -> 13 | Z21: =SUM(J54:J57) -> 11 | ... AF21: =SUM(P54:P57) -> 1478
B22: 10.00 - 10.15 | C22: 100 | D22: 8 | E22: 4 | F22: 10 | G22: 0 | H22: 0 | I22: 8 | J22: 4 | K22: 1 | L22: 0 | M22: 270 | N22: 0 | O22: =SUM(C22:L22,N22) -> 135 | P22: =SUM(C22:N22) -> 405 | R22: AM Peak Hr | S22: =MAX(S10:S12) -> 480 | T22: =MAX(T10:T12) -> 60 | U22: =MAX(U10:U12) -> 61 | V22: =MAX(V10:V12) -> 177 | W22: =MAX(W10:W12) -> 2 | X22: =MAX(X10:X12) -> 1 | Y22: =MAX(Y10:Y12) -> 27 | Z22: =MAX(Z10:Z12) -> 10 | ... AF22: =MAX(AF10:AF12) -> 1663
B23: 10.15 - 10.30 | C23: 77 | D23: 9 | E23: 7 | F23: 10 | G23: 0 | H23: 0 | I23: 4 | J23: 2 | K23: 1 | L23: 0 | M23: 255 | N23: 0 | O23: =SUM(C23:L23,N23) -> 110 | P23: =SUM(C23:N23) -> 365 | R23: IP Peak Hr | S23: =MAX(S13:S18) -> 360 | T23: =MAX(T13:T18) -> 39 | U23: =MAX(U13:U18) -> 50 | V23: =MAX(V13:V18) -> 34 | W23: =MAX(W13:W18) -> 2 | X23: =MAX(X13:X18) -> 0 | Y23: =MAX(Y13:Y18) -> 32 | Z23: =MAX(Z13:Z18) -> 20 | ... AF23: =MAX(AF13:AF18) -> 1427
B24: 10.30 - 10.45 | C24: 58 | D24: 13 | E24: 8 | F24: 8 | G24: 0 | H24: 0 | I24: 7 | J24: 2 | K24: 0 | L24: 0 | M24: 250 | N24: 0 | O24: =SUM(C24:L24,N24) -> 96 | P24: =SUM(C24:N24) -> 346 | R24: PM Peak Hr | S24: =MAX(S19:S21) -> 395 | T24: =MAX(T19:T21) -> 36 | U24: =MAX(U19:U21) -> 37 | V24: =MAX(V19:V21) -> 108 | W24: =MAX(W19:W21) -> 8 | X24: =MAX(X19:X21) -> 1 | Y24: =MAX(Y19:Y21) -> 26 | Z24: =MAX(Z19:Z21) -> 12 | ... AF24: =MAX(AF19:AF21) -> 1478
B25: 10.45 - 11.00 | C25: 60 | D25: 9 | E25: 4 | F25: 6 | G25: 0 | H25: 0 | I25: 5 | J25: 2 | K25: 0 | L25: 0 | M25: 225 | N25: 0 | O25: =SUM(C25:L25,N25) -> 86 | P25: =SUM(C25:N25) -> 311 | R25: AM Period | S25: =SUM(S10:S12) -> 1390 | T25: =SUM(T10:T12) -> 143 | U25: =SUM(U10:U12) -> 150 | V25: =SUM(V10:V12) -> 399 | W25: =SUM(W10:W12) -> 4 | X25: =SUM(X10:X12) -> 1 | Y25: =SUM(Y10:Y12) -> 73 | Z25: =SUM(Z10:Z12) -> 21 | ... AF25: =SUM(AF10:AF12) -> 4663
B26: 11.00 - 11.15 | C26: 63 | D26: 8 | E26: 12 | F26: 5 | G26: 0 | H26: 0 | I26: 8 | J26: 1 | K26: 1 | L26: 1 | M26: 195 | N26: 0 | O26: =SUM(C26:L26,N26) -> 99 | P26: =SUM(C26:N26) -> 294 | R26: IP Period | S26: =SUM(S13:S18) -> 1772 | T26: =SUM(T13:T18) -> 188 | U26: =SUM(U13:U18) -> 207 | V26: =SUM(V13:V18) -> 133 | W26: =SUM(W13:W18) -> 9 | X26: =SUM(X13:X18) -> 0 | Y26: =SUM(Y13:Y18) -> 128 | Z26: =SUM(Z13:Z18) -> 87 | ... AF26: =SUM(AF13:AF18) -> 7695
B27: 11.15 - 11.30 | C27: 90 | D27: 10 | E27: 8 | F27: 8 | G27: 1 | H27: 0 | I27: 3 | J27: 1 | K27: 0 | L27: 0 | M27: 250 | N27: 0 | O27: =SUM(C27:L27,N27) -> 121 | P27: =SUM(C27:N27) -> 371 | R27: PM Period | S27: =SUM(S19:S21) -> 1039 | T27: =SUM(T19:T21) -> 90 | U27: =SUM(U19:U21) -> 85 | V27: =SUM(V19:V21) -> 167 | W27: =SUM(W19:W21) -> 13 | X27: =SUM(X19:X21) -> 2 | Y27: =SUM(Y19:Y21) -> 51 | Z27: =SUM(Z19:Z21) -> 34 | ... AF27: =SUM(AF19:AF21) -> 3953
B28: 11.30 - 11.45 | C28: 85 | D28: 9 | E28: 15 | F28: 5 | G28: 0 | H28: 0 | I28: 4 | J28: 3 | K28: 1 | L28: 1 | M28: 240 | N28: 0 | O28: =SUM(C28:L28,N28) -> 123 | P28: =SUM(C28:N28) -> 363 | R28: 12 Hours | S28: =SUM(S10:S21) -> 4201 | T28: =SUM(T10:T21) -> 421 | U28: =SUM(U10:U21) -> 442 | V28: =SUM(V10:V21) -> 699 | W28: =SUM(W10:W21) -> 26 | X28: =SUM(X10:X21) -> 3 | Y28: =SUM(Y10:Y21) -> 252 | Z28: =SUM(Z10:Z21) -> 142 | ... AF28: =SUM(AF10:AF21) -> 16311
B29: 11.45 - 12.00 | C29: 80 | D29: 7 | E29: 6 | F29: 9 | G29: 1 | H29: 0 | I29: 9 | J29: 5 | K29: 2 | L29: 0 | M29: 220 | N29: 0 | O29: =SUM(C29:L29,N29) -> 119 | P29: =SUM(C29:N29) -> 339
B30: 12.00 - 12.15 | C30: 80 | D30: 11 | E30: 23 | F30: 8 | G30: 1 | H30: 0 | I30: 9 | J30: 1 | K30: 0 | L30: 2 | M30: 210 | N30: 0 | O30: =SUM(C30:L30,N30) -> 135 | P30: =SUM(C30:N30) -> 345
B31: 12.15 - 12.30 | C31: 80 | D31: 5 | E31: 8 | F31: 3 | G31: 1 | H31: 0 | I31: 6 | J31: 5 | K31: 1 | L31: 0 | M31: 170 | N31: 0 | O31: =SUM(C31:L31,N31) -> 109 | P31: =SUM(C31:N31) -> 279
B32: 12.30 - 12.45 | C32: 67 | D32: 9 | E32: 9 | F32: 8 | G32: 0 | H32: 0 | I32: 7 | J32: 6 | K32: 0 | L32: 0 | M32: 200 | N32: 0 | O32: =SUM(C32:L32,N32) -> 106 | P32: =SUM(C32:N32) -> 306
B33: 12.45 - 13.00 | C33: 57 | D33: 11 | E33: 10 | F33: 4 | G33: 0 | H33: 0 | I33: 10 | J33: 3 | K33: 0 | L33: 0 | M33: 220 | N33: 0 | O33: =SUM(C33:L33,N33) -> 95 | P33: =SUM(C33:N33) -> 315
B34: 13.00 - 13.15 | C34: 80 | D34: 7 | E34: 16 | F34: 2 | G34: 0 | H34: 0 | I34: 5 | J34: 3 | K34: 2 | L34: 0 | M34: 225 | N34: 0 | O34: =SUM(C34:L34,N34) -> 115 | P34: =SUM(C34:N34) -> 340
B35: 13.15 - 13.30 | C35: 95 | D35: 7 | E35: 4 | F35: 0 | G35: 1 | H35: 0 | I35: 3 | J35: 2 | K35: 0 | L35: 0 | M35: 210 | N35: 0 | O35: =SUM(C35:L35,N35) -> 112 | P35: =SUM(C35:N35) -> 322
B36: 13.30 - 13.45 | C36: 90 | D36: 9 | E36: 9 | F36: 5 | G36: 0 | H36: 0 | I36: 5 | J36: 6 | K36: 0 | M36: 225 | N36: 0 | O36: =SUM(C36:L36,N36) -> 124 | P36: =SUM(C36:N36) -> 349
B37: 13.45 - 14.00 | C37: 95 | D37: 8 | E37: 5 | F37: 7 | G37: 1 | H37: 0 | I37: 2 | J37: 9 | K37: 0 | L37: 0 | M37: 180 | N37: 0 | O37: =SUM(C37:L37,N37) -> 127 | P37: =SUM(C37:N37) -> 307
B38: 14.00 - 14.15 | C38: 68 | D38: 1 | E38: 5 | F38: 2 | G38: 1 | H38: 0 | I38: 1 | J38: 1 | K38: 2 | L38: 0 | M38: 160 | N38: 0 | O38: =SUM(C38:L38,N38) -> 81 | P38: =SUM(C38:N38) -> 241
B39: 14.15 - 14.30 | C39: 51 | D39: 5 | E39: 6 | F39: 6 | G39: 1 | H39: 0 | I39: 6 | J39: 5 | K39: 0 | L39: 0 | M39: 210 | N39: 0 | O39: =SUM(C39:L39,N39) -> 80 | P39: =SUM(C39:N39) -> 290
B40: 14.30 - 14.45 | C40: 40 | D40: 9 | E40: 6 | F40: 4 | G40: 0 | H40: 0 | I40: 5 | J40: 5 | K40: 2 | L40: 1 | M40: 200 | N40: 0 | O40: =SUM(C40:L40,N40) -> 72 | P40: =SUM(C40:N40) -> 272
B41: 14.45 - 15.00 | C41: 57 | D41: 8 | E41: 6 | F41: 4 | G41: 0 | H41: 0 | I41: 2 | J41: 2 | K41: 1 | L41: 0 | M41: 185 | N41: 0 | O41: =SUM(C41:L41,N41) -> 80 | P41: =SUM(C41:N41) -> 265
B42: 15.00 - 15.15 | C42: 60 | D42: 5 | E42: 13 | F42: 6 | G42: 1 | H42: 0 | I42: 5 | J42: 6 | K42: 1 | L42: 3 | M42: 260 | N42: 0 | O42: =SUM(C42:L42,N42) -> 100 | P42: =SUM(C42:N42) -> 360
...

Sheet 24.07 Lubiri-Ndeeba
B1: Consultancy services for Preparation of Expressway Development Master Plan (EDMP) for Uganda
B2: MANUAL CLASSIFIED COUNT (MCC)
B3: ROAD NAME: | C3: ='22.07 Lubiri -Ndeeba'!C3:G3 -> MCC - C1 - STN03- KALINDA ROAD
C5: Date | D5: 24.07.19 | F5: Location | G5: ='22.07 Lubiri -Ndeeba'!G5:H5 -> Before Shell | J5: Surveyor | K5: ='22.07 Lubiri -Ndeeba'!K5:L5 -> Maiso. M. Gadafi
C6: Dir. From | D6: ='22.07 Lubiri -Ndeeba'!D6:E6 -> Lubiri | F6: Dir. To | G6: ='22.07 Lubiri -Ndeeba'!G6:H6 -> Ndeeba | J6: Supervisor | K6: ='22.07 Lubiri -Ndeeba'!K6:L6 -> Denis
B8: Time / Veh Type | R8: SUMMARY TRAFFIC VOLUMES
C9: 1. Car | D9: 2. Station Wagon | E9: 3. Pickups | F9: 4. Minibus, matatu | G9: 5. Medium bus | H9: 6. Large Bus | I9: 7. Light Truck | J9: 8. Medium Truck | K9: 9. Heavy truck | L9: 10. Truck Trailer | M9: 11. Motor cycles | N9: 12. Tractors | O9: Total Excl M/Cycles | P9: Total All | R9: Time | S9: 1. Car | T9: 2. Station Wagon | U9: 3. Pickups | V9: 4. Minibus, matatu | W9: 5. Medium bus | X9: 6. Large Bus | Y9: 7. Light Truck | Z9: 8. Medium Truck | AA9: 9. Heavy truck | AB9: 10. Truck Trailer | AC9: 11. Motorcycles | AD9: 12. Tractors, Graders | AE9: Total Excl M/ Cycles | AF9: Total All
B10: 07.00 - 07.15 | C10: 35 | D10: 5 | E10: 1 | F10: 4 | G10: 2 | H10: 0 | I10: 3 | J10: 1 | K10: 1 | L10: 0 | M10: 72 | N10: 0 | O10: =SUM(C10:L10,N10) -> 52 | P10: =SUM(C10:N10) -> 124 | R10: 0700-0800 | S10: =SUM(C10:C13) -> 97 | T10: =SUM(D10:D13) -> 11 | U10: =SUM(E10:E13) -> 8 | V10: =SUM(F10:F13) -> 63 | W10: =SUM(G10:G13) -> 2 | X10: =SUM(H10:H13) -> 0 | Y10: =SUM(I10:I13) -> 10 | Z10: =SUM(J10:J13) -> 4 | ... AF10: =SUM(P10:P13) -> 751
B11: 07.15 - 07.30 | C11: 27 | D11: 3 | E11: 2 | F11: 19 | G11: 0 | H11: 0 | I11: 1 | J11: 1 | K11: 0 | L11: 0 | M11: 108 | N11: 0 | O11: =SUM(C11:L11,N11) -> 53 | P11: =SUM(C11:N11) -> 161 | R11: 0800-0900 | S11: =SUM(C14:C17) -> 77 | T11: =SUM(D14:D17) -> 11 | U11: =SUM(E14:E17) -> 7 | V11: =SUM(F14:F17) -> 86 | W11: =SUM(G14:G17) -> 3 | X11: =SUM(H14:H17) -> 0 | Y11: =SUM(I14:I17) -> 12 | Z11: =SUM(J14:J17) -> 16 | ... AF11: =SUM(P14:P17) -> 1304
B12: 07.30 - 07.45 | C12: 23 | D12: 2 | E12: 1 | F12: 23 | G12: 0 | H12: 0 | I12: 2 | J12: 1 | K12: 1 | L12: 0 | M12: 180 | N12: 0 | O12: =SUM(C12:L12,N12) -> 53 | P12: =SUM(C12:N12) -> 233 | R12: 0900-1000 | S12: =SUM(C18:C21) -> 94 | T12: =SUM(D18:D21) -> 15 | U12: =SUM(E18:E21) -> 13 | V12: =SUM(F18:F21) -> 86 | W12: =SUM(G18:G21) -> 1 | X12: =SUM(H18:H21) -> 0 | Y12: =SUM(I18:I21) -> 19 | Z12: =SUM(J18:J21) -> 11 | ... AF12: =SUM(P18:P21) -> 1916
B13: 07.45 - 08.00 | C13: 12 | D13: 1 | E13: 4 | F13: 17 | G13: 0 | H13: 0 | I13: 4 | J13: 1 | K13: 0 | L13: 0 | M13: 194 | N13: 0 | O13: =SUM(C13:L13,N13) -> 39 | P13: =SUM(C13:N13) -> 233 | R13: 1000-1100 | S13: =SUM(C22:C25) -> 118 | T13: =SUM(D22:D25) -> 25 | U13: =SUM(E22:E25) -> 20 | V13: =SUM(F22:F25) -> 68 | W13: =SUM(G22:G25) -> 5 | X13: =SUM(H22:H25) -> 0 | Y13: =SUM(I22:I25) -> 28 | Z13: =SUM(J22:J25) -> 18 | ... AF13: =SUM(P22:P25) -> 1423
B14: 08.00 - 08.15 | C14: 21 | D14: 4 | E14: 3 | F14: 22 | G14: 0 | H14: 0 | I14: 1 | J14: 3 | K14: 0 | L14: 0 | M14: 240 | N14: 0 | O14: =SUM(C14:L14,N14) -> 54 | P14: =SUM(C14:N14) -> 294 | R14: 1100-1200 | S14: =SUM(C26:C29) -> 128 | T14: =SUM(D26:D29) -> 17 | U14: =SUM(E26:E29) -> 17 | V14: =SUM(F26:F29) -> 63 | W14: =SUM(G26:G29) -> 1 | X14: =SUM(H26:H29) -> 0 | Y14: =SUM(I26:I29) -> 34 | Z14: =SUM(J26:J29) -> 25 | ... AF14: =SUM(P26:P29) -> 1373
B15: 08.15 - 08.30 | C15: 25 | D15: 2 | E15: 2 | F15: 25 | G15: 1 | H15: 0 | I15: 4 | J15: 5 | K15: 0 | L15: 0 | M15: 285 | N15: 0 | O15: =SUM(C15:L15,N15) -> 64 | P15: =SUM(C15:N15) -> 349 | R15: 1200-1300 | S15: =SUM(C30:C33) -> 154 | T15: =SUM(D30:D33) -> 26 | U15: =SUM(E30:E33) -> 22 | V15: =SUM(F30:F33) -> 57 | W15: =SUM(G30:G33) -> 3 | X15: =SUM(H30:H33) -> 1 | Y15: =SUM(I30:I33) -> 22 | Z15: =SUM(J30:J33) -> 19 | ... AF15: =SUM(P30:P33) -> 1494
B16: 08.30 - 08.45 | C16: 15 | D16: 1 | E16: 2 | F16: 24 | G16: 0 | H16: 0 | I16: 7 | J16: 3 | K16: 0 | L16: 0 | M16: 262 | N16: 0 | O16: =SUM(C16:L16,N16) -> 52 | P16: =SUM(C16:N16) -> 314 | R16: 1300-1400 | S16: =SUM(C34:C37) -> 127 | T16: =SUM(D34:D37) -> 24 | U16: =SUM(E34:E37) -> 16 | V16: =SUM(F34:F37) -> 46 | W16: =SUM(G34:G37) -> 0 | X16: =SUM(H34:H37) -> 0 | Y16: =SUM(I34:I37) -> 31 | Z16: =SUM(J34:J37) -> 13 | ... AF16: =SUM(P34:P37) -> 1214
B17: 08.45 - 9.00 | C17: 16 | D17: 4 | E17: 0 | F17: 15 | G17: 2 | H17: 0 | I17: 0 | J17: 5 | K17: 0 | L17: 0 | M17: 305 | N17: 0 | O17: =SUM(C17:L17,N17) -> 42 | P17: =SUM(C17:N17) -> 347 | R17: 1400-1500 | S17: =SUM(C38:C41) -> 142 | T17: =SUM(D38:D41) -> 32 | U17: =SUM(E38:E41) -> 20 | V17: =SUM(F38:F41) -> 59 | W17: =SUM(G38:G41) -> 3 | X17: =SUM(H38:H41) -> 0 | Y17: =SUM(I38:I41) -> 26 | Z17: =SUM(J38:J41) -> 16 | ... AF17: =SUM(P38:P41) -> 1088
B18: 09.00 - 09.15 | C18: 25 | D18: 4 | E18: 5 | F18: 16 | G18: 0 | H18: 0 | I18: 5 | J18: 4 | K18: 0 | L18: 1 | M18: 420 | N18: 0 | O18: =SUM(C18:L18,N18) -> 60 | P18: =SUM(C18:N18) -> 480 | R18: 1500-1600 | S18: =SUM(C42:C45) -> 149 | T18: =SUM(D42:D45) -> 24 | U18: =SUM(E42:E45) -> 19 | V18: =SUM(F42:F45) -> 56 | W18: =SUM(G42:G45) -> 3 | X18: =SUM(H42:H45) -> 0 | Y18: =SUM(I42:I45) -> 19 | Z18: =SUM(J42:J45) -> 20 | ... AF18: =SUM(P42:P45) -> 1274
B19: 09.15 - 09.30 | C19: 16 | D19: 3 | E19: 0 | F19: 20 | G19: 0 | H19: 0 | I19: 3 | J19: 1 | K19: 2 | L19: 0 | M19: 473 | N19: 0 | O19: =SUM(C19:L19,N19) -> 45 | P19: =SUM(C19:N19) -> 518 | R19: 1600-1700 | S19: =SUM(C46:C49) -> 150 | T19: =SUM(D46:D49) -> 17 | U19: =SUM(E46:E49) -> 14 | V19: =SUM(F46:F49) -> 57 | W19: =SUM(G46:G49) -> 5 | X19: =SUM(H46:H49) -> 0 | Y19: =SUM(I46:I49) -> 24 | Z19: =SUM(J46:J49) -> 15 | ... AF19: =SUM(P46:P49) -> 1463
B20: 09.30 - 09.45 | C20: 29 | D20: 3 | E20: 3 | F20: 21 | G20: 0 | H20: 0 | I20: 4 | J20: 3 | K20: 0 | L20: 0 | M20: 394 | N20: 0 | O20: =SUM(C20:L20,N20) -> 63 | P20: =SUM(C20:N20) -> 457 | R20: 1700-1800 | S20: =SUM(C50:C53) -> 264 | T20: =SUM(D50:D53) -> 34 | U20: =SUM(E50:E53) -> 11 | V20: =SUM(F50:F53) -> 57 | W20: =SUM(G50:G53) -> 3 | X20: =SUM(H50:H53) -> 0 | Y20: =SUM(I50:I53) -> 19 | Z20: =SUM(J50:J53) -> 8 | ... AF20: =SUM(P50:P53) -> 1615
B21: 09.45 - 10.00 | C21: 24 | D21: 5 | E21: 5 | F21: 29 | G21: 1 | H21: 0 | I21: 7 | J21: 3 | K21: 0 | L21: 0 | M21: 387 | N21: 0 | O21: =SUM(C21:L21,N21) -> 74 | P21: =SUM(C21:N21) -> 461 | R21: 1800-1900 | S21: =SUM(C54:C57) -> 205 | T21: =SUM(D54:D57) -> 24 | U21: =SUM(E54:E57) -> 15 | V21: =SUM(F54:F57) -> 90 | W21: =SUM(G54:G57) -> 0 | X21: =SUM(H54:H57) -> 0 | Y21: =SUM(I54:I57) -> 21 | Z21: =SUM(J54:J57) -> 9 | ... AF21: =SUM(P54:P57) -> 1362
B22: 10.00 - 10.15 | C22: 29 | D22: 9 | E22: 3 | F22: 20 | G22: 1 | H22: 0 | I22: 6 | J22: 5 | K22: 0 | L22: 0 | M22: 318 | N22: 0 | O22: =SUM(C22:L22,N22) -> 73 | P22: =SUM(C22:N22) -> 391 | R22: AM Peak Hr | S22: =MAX(S10:S12) -> 97 | T22: =MAX(T10:T12) -> 15 | U22: =MAX(U10:U12) -> 13 | V22: =MAX(V10:V12) -> 86 | W22: =MAX(W10:W12) -> 3 | X22: =MAX(X10:X12) -> 0 | Y22: =MAX(Y10:Y12) -> 19 | Z22: =MAX(Z10:Z12) -> 16 | ... AF22: =MAX(AF10:AF12) -> 1916
B23: 10.15 - 10.30 | C23: 31 | D23: 2 | E23: 7 | F23: 9 | G23: 2 | H23: 0 | I23: 7 | J23: 5 | K23: 0 | L23: 2 | M23: 305 | N23: 0 | O23: =SUM(C23:L23,N23) -> 65 | P23: =SUM(C23:N23) -> 370 | R23: IP Peak Hr | S23: =MAX(S13:S18) -> 154 | T23: =MAX(T13:T18) -> 32 | U23: =MAX(U13:U18) -> 22 | V23: =MAX(V13:V18) -> 68 | W23: =MAX(W13:W18) -> 5 | X23: =MAX(X13:X18) -> 1 | Y23: =MAX(Y13:Y18) -> 34 | Z23: =MAX(Z13:Z18) -> 25 | ... AF23: =MAX(AF13:AF18) -> 1494
B24: 10.30 - 10.45 | C24: 26 | D24: 7 | E24: 8 | F24: 18 | G24: 2 | H24: 0 | I24: 7 | J24: 1 | K24: 1 | L24: 2 | M24: 166 | N24: 0 | O24: =SUM(C24:L24,N24) -> 72 | P24: =SUM(C24:N24) -> 238 | R24: PM Peak Hr | S24: =MAX(S19:S21) -> 264 | T24: =MAX(T19:T21) -> 34 | U24: =MAX(U19:U21) -> 15 | V24: =MAX(V19:V21) -> 90 | W24: =MAX(W19:W21) -> 5 | X24: =MAX(X19:X21) -> 0 | Y24: =MAX(Y19:Y21) -> 24 | Z24: =MAX(Z19:Z21) -> 15 | ... AF24: =MAX(AF19:AF21) -> 1615
B25: 10.45 - 11.00 | C25: 32 | D25: 7 | E25: 2 | F25: 21 | G25: 0 | H25: 0 | I25: 8 | J25: 7 | K25: 0 | L25: 1 | M25: 345 | N25: 1 | O25: =SUM(C25:L25,N25) -> 79 | P25: =SUM(C25:N25) -> 424 | R25: AM Period | S25: =SUM(S10:S12) -> 268 | T25: =SUM(T10:T12) -> 37 | U25: =SUM(U10:U12) -> 28 | V25: =SUM(V10:V12) -> 235 | W25: =SUM(W10:W12) -> 6 | X25: =SUM(X10:X12) -> 0 | Y25: =SUM(Y10:Y12) -> 41 | Z25: =SUM(Z10:Z12) -> 31 | ... AF25: =SUM(AF10:AF12) -> 3971
B26: 11.00 - 11.15 | C26: 34 | D26: 6 | E26: 2 | F26: 17 | G26: 0 | H26: 0 | I26: 10 | J26: 9 | K26: 0 | L26: 0 | M26: 220 | N26: 0 | O26: =SUM(C26:L26,N26) -> 78 | P26: =SUM(C26:N26) -> 298 | R26: IP Period | S26: =SUM(S13:S18) -> 818 | T26: =SUM(T13:T18) -> 148 | U26: =SUM(U13:U18) -> 114 | V26: =SUM(V13:V18) -> 349 | W26: =SUM(W13:W18) -> 15 | X26: =SUM(X13:X18) -> 1 | Y26: =SUM(Y13:Y18) -> 160 | Z26: =SUM(Z13:Z18) -> 111 | ... AF26: =SUM(AF13:AF18) -> 7866
B27: 11.15 - 11.30 | C27: 27 | D27: 1 | E27: 3 | F27: 12 | G27: 1 | H27: 0 | I27: 5 | J27: 5 | K27: 1 | L27: 0 | M27: 260 | N27: 0 | O27: =SUM(C27:L27,N27) -> 55 | P27: =SUM(C27:N27) -> 315 | R27: PM Period | S27: =SUM(S19:S21) -> 619 | T27: =SUM(T19:T21) -> 75 | U27: =SUM(U19:U21) -> 40 | V27: =SUM(V19:V21) -> 204 | W27: =SUM(W19:W21) -> 8 | X27: =SUM(X19:X21) -> 0 | Y27: =SUM(Y19:Y21) -> 64 | Z27: =SUM(Z19:Z21) -> 32 | ... AF27: =SUM(AF19:AF21) -> 4440
