Workbook

Sheet 22.07 Kalerwe-Kampala
B1: Consultancy services for Preparation of Expressway Development Master Plan (EDMP) for Uganda
B2: MANUAL CLASSIFIED COUNT (MCC)
B3: ROAD NAME: | C3: MCC - C1 - STN24 GAYAZA ROAD
C5: Date | D5: 22.07.19 | F5: Location | G5: Wandegeya | J5: Surveyor | K5: Christine
C6: Dir. From | D6: Kalewre | F6: Dir. To | G6: Kampala | J6: Supervisor | K6: Lawrence
B8: Time / Veh Type | R8: SUMMARY TRAFFIC VOLUMES
C9: 1. Car | D9: 2. Station Wagon | E9: 3. Pickups | F9: 4. Minibus, matatu | G9: 5. Medium bus | H9: 6. Large Bus | I9: 7. Light Truck | J9: 8. Medium Truck | K9: 9. Heavy truck | L9: 10. Truck Trailer | M9: 11. Motor cycles | N9: 12. Tractors | O9: Total Excl M/Cycles | P9: Total All | R9: Time | S9: 1. Car | T9: 2. Station Wagon | U9: 3. Pickups | V9: 4. Minibus, matatu | W9: 5. Medium bus | X9: 6. Large Bus | Y9: 7. Light Truck | Z9: 8. Medium Truck | AA9: 9. Heavy truck | AB9: 10. Truck Trailer | AC9: 11. Motorcycles | AD9: 12. Tractors, Graders | AE9: Total Excl M/ Cycles | AF9: Total All
B10: 07.00 - 07.15 | C10: 25 | D10: 40 | E10: 5 | F10: 20 | G10: 0 | H10: 1 | I10: 3 | J10: 0 | K10: 0 | L10: 0 | M10: 55 | N10: 0 | O10: =SUM(C10:L10,N10) -> 94 | P10: =SUM(C10:N10) -> 149 | R10: 0700-0800 | S10: =SUM(C10:C13) -> 86 | T10: =SUM(D10:D13) -> 145 | U10: =SUM(E10:E13) -> 19 | V10: =SUM(F10:F13) -> 92 | W10: =SUM(G10:G13) -> 2 | X10: =SUM(H10:H13) -> 1 | Y10: =SUM(I10:I13) -> 17 | Z10: =SUM(J10:J13) -> 3 | ... AF10: =SUM(P10:P13) -> 581
B11: 07.15 - 07.30 | C11: 19 | D11: 20 | E11: 6 | F11: 20 | G11: 0 | H11: 0 | I11: 3 | J11: 1 | K11: 0 | L11: 1 | M11: 50 | N11: 0 | O11: =SUM(C11:L11,N11) -> 70 | P11: =SUM(C11:N11) -> 120 | R11: 0800-0900 | S11: =SUM(C14:C17) -> 72 | T11: =SUM(D14:D17) -> 192 | U11: =SUM(E14:E17) -> 14 | V11: =SUM(F14:F17) -> 118 | W11: =SUM(G14:G17) -> 3 | X11: =SUM(H14:H17) -> 0 | Y11: =SUM(I14:I17) -> 28 | Z11: =SUM(J14:J17) -> 2 | ... AF11: =SUM(P14:P17) -> 710
B12: 07.30 - 07.45 | C12: 13 | D12: 45 | E12: 5 | F12: 19 | G12: 0 | H12: 0 | I12: 3 | J12: 0 | K12: 0 | L12: 0 | M12: 50 | N12: 0 | O12: =SUM(C12:L12,N12) -> 85 | P12: =SUM(C12:N12) -> 135 | R12: 0900-1000 | S12: =SUM(C18:C21) -> 89 | T12: =SUM(D18:D21) -> 176 | U12: =SUM(E18:E21) -> 26 | V12: =SUM(F18:F21) -> 107 | W12: =SUM(G18:G21) -> 3 | X12: =SUM(H18:H21) -> 3 | Y12: =SUM(I18:I21) -> 33 | Z12: =SUM(J18:J21) -> 9 | ... AF12: =SUM(P18:P21) -> 726
B13: 07.45 - 08.00 | C13: 29 | D13: 40 | E13: 3 | F13: 33 | G13: 2 | H13: 0 | I13: 8 | J13: 2 | K13: 0 | L13: 0 | M13: 60 | N13: 0 | O13: =SUM(C13:L13,N13) -> 117 | P13: =SUM(C13:N13) -> 177 | R13: 1000-1100 | S13: =SUM(C22:C25) -> 114 | T13: =SUM(D22:D25) -> 138 | U13: =SUM(E22:E25) -> 9 | V13: =SUM(F22:F25) -> 164 | W13: =SUM(G22:G25) -> 1 | X13: =SUM(H22:H25) -> 3 | Y13: =SUM(I22:I25) -> 25 | Z13: =SUM(J22:J25) -> 4 | ... AF13: =SUM(P22:P25) -> 771
B14: 08.00 - 08.15 | C14: 22 | D14: 42 | E14: 3 | F14: 29 | G14: 1 | H14: 0 | I14: 6 | J14: 2 | K14: 0 | L14: 0 | M14: 47 | N14: 0 | O14: =SUM(C14:L14,N14) -> 105 | P14: =SUM(C14:N14) -> 152 | R14: 1100-1200 | S14: =SUM(C26:C29) -> 75 | T14: =SUM(D26:D29) -> 96 | U14: =SUM(E26:E29) -> 13 | V14: =SUM(F26:F29) -> 134 | W14: =SUM(G26:G29) -> 1 | X14: =SUM(H26:H29) -> 1 | Y14: =SUM(I26:I29) -> 23 | Z14: =SUM(J26:J29) -> 7 | ... AF14: =SUM(P26:P29) -> 666
B15: 08.15 - 08.30 | C15: 11 | D15: 37 | E15: 4 | F15: 22 | G15: 0 | H15: 0 | I15: 4 | J15: 0 | K15: 0 | L15: 1 | M15: 55 | N15: 0 | O15: =SUM(C15:L15,N15) -> 79 | P15: =SUM(C15:N15) -> 134 | R15: 1200-1300 | S15: =SUM(C30:C33) -> 111 | T15: =SUM(D30:D33) -> 83 | U15: =SUM(E30:E33) -> 13 | V15: =SUM(F30:F33) -> 126 | W15: =SUM(G30:G33) -> 1 | X15: =SUM(H30:H33) -> 0 | Y15: =SUM(I30:I33) -> 28 | Z15: =SUM(J30:J33) -> 8 | ... AF15: =SUM(P30:P33) -> 718
B16: 08.30 - 08.45 | C16: 17 | D16: 73 | E16: 4 | F16: 37 | G16: 1 | H16: 0 | I16: 8 | J16: 0 | K16: 0 | L16: 0 | M16: 90 | N16: 0 | O16: =SUM(C16:L16,N16) -> 140 | P16: =SUM(C16:N16) -> 230 | R16: 1300-1400 | S16: =SUM(C34:C37) -> 116 | T16: =SUM(D34:D37) -> 58 | U16: =SUM(E34:E37) -> 25 | V16: =SUM(F34:F37) -> 136 | W16: =SUM(G34:G37) -> 1 | X16: =SUM(H34:H37) -> 2 | Y16: =SUM(I34:I37) -> 62 | Z16: =SUM(J34:J37) -> 6 | ... AF16: =SUM(P34:P37) -> 720
B17: 08.45 - 9.00 | C17: 22 | D17: 40 | E17: 3 | F17: 30 | G17: 1 | H17: 0 | I17: 10 | J17: 0 | K17: 0 | L17: 0 | M17: 88 | N17: 0 | O17: =SUM(C17:L17,N17) -> 106 | P17: =SUM(C17:N17) -> 194 | R17: 1400-1500 | S17: =SUM(C38:C41) -> 230 | T17: =SUM(D38:D41) -> 149 | U17: =SUM(E38:E41) -> 56 | V17: =SUM(F38:F41) -> 194 | W17: =SUM(G38:G41) -> 11 | X17: =SUM(H38:H41) -> 0 | Y17: =SUM(I38:I41) -> 61 | Z17: =SUM(J38:J41) -> 8 | ... AF17: =SUM(P38:P41) -> 1056
B18: 09.00 - 09.15 | C18: 14 | D18: 60 | E18: 7 | F18: 33 | G18: 2 | H18: 0 | I18: 11 | J18: 4 | K18: 0 | L18: 1 | M18: 53 | N18: 0 | O18: =SUM(C18:L18,N18) -> 132 | P18: =SUM(C18:N18) -> 185 | R18: 1500-1600 | S18: =SUM(C42:C45) -> 165 | T18: =SUM(D42:D45) -> 145 | U18: =SUM(E42:E45) -> 62 | V18: =SUM(F42:F45) -> 230 | W18: =SUM(G42:G45) -> 5 | X18: =SUM(H42:H45) -> 10 | Y18: =SUM(I42:I45) -> 130 | Z18: =SUM(J42:J45) -> 11 | ... AF18: =SUM(P42:P45) -> 1066
B19: 09.15 - 09.30 | C19: 15 | D19: 47 | E19: 11 | F19: 1 | G19: 1 | H19: 2 | I19: 6 | J19: 2 | K19: 0 | L19: 0 | M19: 74 | N19: 0 | O19: =SUM(C19:L19,N19) -> 85 | P19: =SUM(C19:N19) -> 159 | R19: 1600-1700 | S19: =SUM(C46:C49) -> 184 | T19: =SUM(D46:D49) -> 98 | U19: =SUM(E46:E49) -> 42 | V19: =SUM(F46:F49) -> 184 | W19: =SUM(G46:G49) -> 11 | X19: =SUM(H46:H49) -> 2 | Y19: =SUM(I46:I49) -> 84 | Z19: =SUM(J46:J49) -> 10 | ... AF19: =SUM(P46:P49) -> 867
B20: 09.30 - 09.45 | C20: 20 | D20: 29 | E20: 2 | F20: 32 | G20: 0 | H20: 1 | I20: 9 | J20: 1 | K20: 0 | L20: 0 | M20: 57 | N20: 0 | O20: =SUM(C20:L20,N20) -> 94 | P20: =SUM(C20:N20) -> 151 | R20: 1700-1800 | S20: =SUM(C50:C53) -> 140 | T20: =SUM(D50:D53) -> 113 | U20: =SUM(E50:E53) -> 53 | V20: =SUM(F50:F53) -> 145 | W20: =SUM(G50:G53) -> 14 | X20: =SUM(H50:H53) -> 7 | Y20: =SUM(I50:I53) -> 60 | Z20: =SUM(J50:J53) -> 1 | ... AF20: =SUM(P50:P53) -> 822
B21: 09.45 - 10.00 | C21: 40 | D21: 40 | E21: 6 | F21: 41 | G21: 0 | H21: 0 | I21: 7 | J21: 2 | K21: 0 | L21: 0 | M21: 95 | N21: 0 | O21: =SUM(C21:L21,N21) -> 136 | P21: =SUM(C21:N21) -> 231 | R21: 1800-1900 | S21: =SUM(C54:C57) -> 113 | T21: =SUM(D54:D57) -> 57 | U21: =SUM(E54:E57) -> 8 | V21: =SUM(F54:F57) -> 125 | W21: =SUM(G54:G57) -> 4 | X21: =SUM(H54:H57) -> 3 | Y21: =SUM(I54:I57) -> 27 | Z21: =SUM(J54:J57) -> 3 | ... AF21: =SUM(P54:P57) -> 630
B22: 10.00 - 10.15 | C22: 43 | D22: 50 | E22: 3 | F22: 49 | G22: 1 | H22: 2 | I22: 7 | J22: 2 | K22: 0 | L22: 0 | M22: 76 | N22: 0 | O22: =SUM(C22:L22,N22) -> 157 | P22: =SUM(C22:N22) -> 233 | R22: AM Peak Hr | S22: =MAX(S10:S12) -> 89 | T22: =MAX(T10:T12) -> 192 | U22: =MAX(U10:U12) -> 26 | V22: =MAX(V10:V12) -> 118 | W22: =MAX(W10:W12) -> 3 | X22: =MAX(X10:X12) -> 3 | Y22: =MAX(Y10:Y12) -> 33 | Z22: =MAX(Z10:Z12) -> 9 | ... AF22: =MAX(AF10:AF12) -> 726
B23: 10.15 - 10.30 | C23: 22 | D23: 32 | E23: 5 | F23: 44 | G23: 0 | H23: 0 | I23: 5 | J23: 2 | K23: 0 | L23: 1 | M23: 75 | N23: 0 | O23: =SUM(C23:L23,N23) -> 111 | P23: =SUM(C23:N23) -> 186 | R23: IP Peak Hr | S23: =MAX(S13:S18) -> 230 | T23: =MAX(T13:T18) -> 149 | U23: =MAX(U13:U18) -> 62 | V23: =MAX(V13:V18) -> 230 | W23: =MAX(W13:W18) -> 11 | X23: =MAX(X13:X18) -> 10 | Y23: =MAX(Y13:Y18) -> 130 | Z23: =MAX(Z13:Z18) -> 11 | ... AF23: =MAX(AF13:AF18) -> 1066
B24: 10.30 - 10.45 | C24: 21 | D24: 25 | E24: 0 | F24: 37 | G24: 0 | H24: 1 | I24: 2 | J24: 0 | K24: 1 | L24: 0 | M24: 75 | N24: 0 | O24: =SUM(C24:L24,N24) -> 87 | P24: =SUM(C24:N24) -> 162 | R24: PM Peak Hr | S24: =MAX(S19:S21) -> 184 | T24: =MAX(T19:T21) -> 113 | U24: =MAX(U19:U21) -> 53 | V24: =MAX(V19:V21) -> 184 | W24: =MAX(W19:W21) -> 14 | X24: =MAX(X19:X21) -> 7 | Y24: =MAX(Y19:Y21) -> 84 | Z24: =MAX(Z19:Z21) -> 10 | ... AF24: =MAX(AF19:AF21) -> 867
B25: 10.45 - 11.00 | C25: 28 | D25: 31 | E25: 1 | F25: 34 | G25: 0 | H25: 0 | I25: 11 | J25: 0 | K25: 0 | L25: 0 | M25: 85 | N25: 0 | O25: =SUM(C25:L25,N25) -> 105 | P25: =SUM(C25:N25) -> 190 | R25: AM Period | S25: =SUM(S10:S12) -> 247 | T25: =SUM(T10:T12) -> 513 | U25: =SUM(U10:U12) -> 59 | V25: =SUM(V10:V12) -> 317 | W25: =SUM(W10:W12) -> 8 | X25: =SUM(X10:X12) -> 4 | Y25: =SUM(Y10:Y12) -> 78 | Z25: =SUM(Z10:Z12) -> 14 | ... AF25: =SUM(AF10:AF12) -> 2017
B26: 11.00 - 11.15 | C26: 23 | D26: 30 | E26: 5 | F26: 50 | G26: 0 | H26: 0 | I26: 6 | J26: 3 | K26: 0 | L26: 0 | M26: 92 | N26: 0 | O26: =SUM(C26:L26,N26) -> 117 | P26: =SUM(C26:N26) -> 209 | R26: IP Period | S26: =SUM(S13:S18) -> 811 | T26: =SUM(T13:T18) -> 669 | U26: =SUM(U13:U18) -> 178 | V26: =SUM(V13:V18) -> 984 | W26: =SUM(W13:W18) -> 20 | X26: =SUM(X13:X18) -> 16 | Y26: =SUM(Y13:Y18) -> 329 | Z26: =SUM(Z13:Z18) -> 44 | ... AF26: =SUM(AF13:AF18) -> 4997
B27: 11.15 - 11.30 | C27: 15 | D27: 21 | E27: 0 | F27: 13 | G27: 0 | H27: 0 | I27: 7 | J27: 0 | K27: 0 | L27: 1 | M27: 95 | N27: 0 | O27: =SUM(C27:L27,N27) -> 57 | P27: =SUM(C27:N27) -> 152 | R27: PM Period | S27: =SUM(S19:S21) -> 437 | T27: =SUM(T19:T21) -> 268 | U27: =SUM(U19:U21) -> 103 | V27: =SUM(V19:V21) -> 454 | W27: =SUM(W19:W21) -> 29 | X27: =SUM(X19:X21) -> 12 | Y27: =SUM(Y19:Y21) -> 171 | Z27: =SUM(Z19:Z21) -> 14 | ... AF27: =SUM(AF19:AF21) -> 2319
B28: 11.30 - 11.45 | C28: 17 | D28: 13 | E28: 1 | F28: 30 | G28: 1 | H28: 1 | I28: 7 | J28: 3 | K28: 0 | L28: 0 | M28: 47 | N28: 0 | O28: =SUM(C28:L28,N28) -> 73 | P28: =SUM(C28:N28) -> 120 | R28: 12 Hours | S28: =SUM(S10:S21) -> 1495 | T28: =SUM(T10:T21) -> 1450 | U28: =SUM(U10:U21) -> 340 | V28: =SUM(V10:V21) -> 1755 | W28: =SUM(W10:W21) -> 57 | X28: =SUM(X10:X21) -> 32 | Y28: =SUM(Y10:Y21) -> 578 | Z28: =SUM(Z10:Z21) -> 72 | ... AF28: =SUM(AF10:AF21) -> 9333
B29: 11.45 - 12.00 | C29: 20 | D29: 32 | E29: 7 | F29: 41 | G29: 0 | H29: 0 | I29: 3 | J29: 1 | K29: 1 | L29: 0 | M29: 80 | N29: 0 | O29: =SUM(C29:L29,N29) -> 105 | P29: =SUM(C29:N29) -> 185
B30: 12.00 - 12.15 | C30: 16 | D30: 27 | E30: 2 | F30: 34 | G30: 0 | H30: 0 | I30: 4 | J30: 1 | K30: 0 | L30: 0 | M30: 85 | N30: 0 | O30: =SUM(C30:L30,N30) -> 84 | P30: =SUM(C30:N30) -> 169
B31: 12.15 - 12.30 | C31: 39 | D31: 16 | E31: 3 | F31: 29 | G31: 0 | H31: 0 | I31: 4 | J31: 3 | K31: 0 | L31: 1 | M31: 83 | N31: 0 | O31: =SUM(C31:L31,N31) -> 95 | P31: =SUM(C31:N31) -> 178
B32: 12.30 - 12.45 | C32: 29 | D32: 22 | E32: 3 | F32: 26 | G32: 1 | H32: 0 | I32: 13 | J32: 2 | K32: 0 | L32: 0 | M32: 83 | N32: 0 | O32: =SUM(C32:L32,N32) -> 96 | P32: =SUM(C32:N32) -> 179
B33: 12.45 - 13.00 | C33: 27 | D33: 18 | E33: 5 | F33: 37 | G33: 0 | H33: 0 | I33: 7 | J33: 2 | K33: 1 | L33: 0 | M33: 95 | N33: 0 | O33: =SUM(C33:L33,N33) -> 97 | P33: =SUM(C33:N33) -> 192
B34: 13.00 - 13.15 | C34: 40 | D34: 12 | E34: 7 | F34: 33 | G34: 0 | H34: 0 | I34: 15 | J34: 5 | K34: 2 | L34: 0 | M34: 105 | N34: 0 | O34: =SUM(C34:L34,N34) -> 114 | P34: =SUM(C34:N34) -> 219
B35: 13.15 - 13.30 | C35: 19 | D35: 19 | E35: 2 | F35: 26 | G35: 0 | H35: 0 | I35: 3 | J35: 0 | K35: 0 | L35: 0 | M35: 65 | N35: 0 | O35: =SUM(C35:L35,N35) -> 69 | P35: =SUM(C35:N35) -> 134
B36: 13.30 - 13.45 | C36: 19 | D36: 12 | E36: 6 | F36: 31 | G36: 0 | H36: 1 | I36: 11 | J36: 0 | K36: 0 | L36: 0 | M36: 68 | N36: 0 | O36: =SUM(C36:L36,N36) -> 80 | P36: =SUM(C36:N36) -> 148
B37: 13.45 - 14.00 | C37: 38 | D37: 15 | E37: 10 | F37: 46 | G37: 1 | H37: 1 | I37: 33 | J37: 1 | K37: 0 | L37: 0 | M37: 74 | N37: 0 | O37: =SUM(C37:L37,N37) -> 145 | P37: =SUM(C37:N37) -> 219
B38: 14.00 - 14.15 | C38: 70 | D38: 5 | E38: 8 | F38: 39 | G38: 1 | H38: 0 | I38: 15 | J38: 0 | K38: 0 | L38: 2 | M38: 68 | N38: 0 | O38: =SUM(C38:L38,N38) -> 140 | P38: =SUM(C38:N38) -> 208
B39: 14.15 - 14.30 | C39: 38 | D39: 17 | E39: 8 | F39: 40 | G39: 2 | H39: 0 | I39: 9 | J39: 1 | K39: 0 | L39: 0 | M39: 85 | N39: 0 | O39: =SUM(C39:L39,N39) -> 115 | P39: =SUM(C39:N39) -> 200
B40: 14.30 - 14.45 | C40: 58 | D40: 72 | E40: 12 | F40: 45 | G40: 5 | H40: 0 | I40: 27 | J40: 5 | K40: 0 | L40: 0 | M40: 90 | N40: 0 | O40: =SUM(C40:L40,N40) -> 224 | P40: =SUM(C40:N40) -> 314
... B57: 18.45 - 19.00 | C57: 37 | D57: 9 | E57: 1 | F57: 42 | G57: 3 | H57: 0 | I57: 6 | J57: 1 | K57: 0 | L57: 0 | M57: 70 | N57: 0 | O57: =SUM(C57:L57,N57) -> 99 | P57: =SUM(C57:N57) -> 169
B58: Totals | C58: =SUM(C10:C57) -> 1495 | D58: =SUM(D10:D57) -> 1450 | E58: =SUM(E10:E57) -> 340 | F58: =SUM(F10:F57) -> 1755 | G58: =SUM(G10:G57) -> 57 | H58: =SUM(H10:H57) -> 32 | I58: =SUM(I10:I57) -> 578 | J58: =SUM(J10:J57) -> 72 | ... P58: =SUM(P10:P57) -> 9333
...

Sheet 22.07 Kampala-Kalerwe
B1: Consultancy services for Preparation of Expressway Development Master Plan (EDMP) for Uganda
B2: MANUAL CLASSIFIED COUNT (MCC)
B3: ROAD NAME: | C3: ='22.07 Kalerwe-Kampala'!C3:G3 -> MCC - C1 - STN24 GAYAZA ROAD
C5: Date | D5: ='22.07 Kalerwe-Kampala'!D5 -> 22.07.19 | F5: Location | G5: ='22.07 Kalerwe-Kampala'!G5:H5 -> Wandegeya | J5: Surveyor | K5: Beteth
C6: Dir. From | D6: Kampala | F6: Dir. To | G6: Kalerwe | J6: Supervisor | K6: Lawrence
B8: Time / Veh Type | R8: SUMMARY TRAFFIC VOLUMES
C9: 1. Car | D9: 2. Station Wagon | E9: 3. Pickups | F9: 4. Minibus, matatu | G9: 5. Medium bus | H9: 6. Large Bus | I9: 7. Light Truck | J9: 8. Medium Truck | K9: 9. Heavy truck | L9: 10. Truck Trailer | M9: 11. Motor cycles | N9: 12. Tractors | O9: Total Excl M/Cycles | P9: Total All | R9: Time | S9: 1. Car | T9: 2. Station Wagon | U9: 3. Pickups | V9: 4. Minibus, matatu | W9: 5. Medium bus | X9: 6. Large Bus | Y9: 7. Light Truck | Z9: 8. Medium Truck | AA9: 9. Heavy truck | AB9: 10. Truck Trailer | AC9: 11. Motorcycles | AD9: 12. Tractors, Graders | AE9: Total Excl M/ Cycles | AF9: Total All
B10: 07.00 - 07.15 | C10: 15 | D10: 7 | E10: 1 | F10: 50 | G10: 1 | H10: 1 | I10: 2 | J10: 0 | K10: 1 | L10: 0 | M10: 95 | N10: 0 | O10: =SUM(C10:L10,N10) -> 78 | P10: =SUM(C10:N10) -> 173 | R10: 0700-0800 | S10: =SUM(C10:C13) -> 116 | T10: =SUM(D10:D13) -> 28 | U10: =SUM(E10:E13) -> 8 | V10: =SUM(F10:F13) -> 207 | W10: =SUM(G10:G13) -> 3 | X10: =SUM(H10:H13) -> 2 | Y10: =SUM(I10:I13) -> 6 | Z10: =SUM(J10:J13) -> 8 | ... AF10: =SUM(P10:P13) -> 1000
B11: 07.15 - 07.30 | C11: 27 | D11: 6 | E11: 5 | F11: 41 | G11: 1 | H11: 0 | I11: 2 | J11: 4 | K11: 0 | L11: 0 | M11: 85 | N11: 0 | O11: =SUM(C11:L11,N11) -> 86 | P11: =SUM(C11:N11) -> 171 | R11: 0800-0900 | S11: =SUM(C14:C17) -> 82 | T11: =SUM(D14:D17) -> 12 | U11: =SUM(E14:E17) -> 18 | V11: =SUM(F14:F17) -> 245 | W11: =SUM(G14:G17) -> 5 | X11: =SUM(H14:H17) -> 1 | Y11: =SUM(I14:I17) -> 16 | Z11: =SUM(J14:J17) -> 3 | ... AF11: =SUM(P14:P17) -> 1220
B12: 07.30 - 07.45 | C12: 21 | D12: 6 | E12: 0 | F12: 68 | G12: 1 | H12: 1 | I12: 2 | J12: 0 | K12: 0 | L12: 0 | M12: 190 | N12: 0 | O12: =SUM(C12:L12,N12) -> 99 | P12: =SUM(C12:N12) -> 289 | R12: 0900-1000 | S12: =SUM(C18:C21) -> 69 | T12: =SUM(D18:D21) -> 20 | U12: =SUM(E18:E21) -> 12 | V12: =SUM(F18:F21) -> 217 | W12: =SUM(G18:G21) -> 7 | X12: =SUM(H18:H21) -> 0 | Y12: =SUM(I18:I21) -> 23 | Z12: =SUM(J18:J21) -> 22 | ... AF12: =SUM(P18:P21) -> 1366
B13: 07.45 - 08.00 | C13: 53 | D13: 9 | E13: 2 | F13: 48 | G13: 0 | H13: 0 | I13: 0 | J13: 4 | K13: 1 | L13: 0 | M13: 250 | N13: 0 | O13: =SUM(C13:L13,N13) -> 117 | P13: =SUM(C13:N13) -> 367 | R13: 1000-1100 | S13: =SUM(C22:C25) -> 80 | T13: =SUM(D22:D25) -> 24 | U13: =SUM(E22:E25) -> 7 | V13: =SUM(F22:F25) -> 200 | W13: =SUM(G22:G25) -> 0 | X13: =SUM(H22:H25) -> 3 | Y13: =SUM(I22:I25) -> 21 | Z13: =SUM(J22:J25) -> 17 | ... AF13: =SUM(P22:P25) -> 1226
B14: 08.00 - 08.15 | C14: 31 | D14: 4 | E14: 2 | F14: 51 | G14: 4 | H14: 0 | I14: 6 | J14: 2 | K14: 1 | L14: 1 | M14: 220 | N14: 0 | O14: =SUM(C14:L14,N14) -> 102 | P14: =SUM(C14:N14) -> 322 | R14: 1100-1200 | S14: =SUM(C26:C29) -> 81 | T14: =SUM(D26:D29) -> 51 | U14: =SUM(E26:E29) -> 16 | V14: =SUM(F26:F29) -> 124 | W14: =SUM(G26:G29) -> 1 | X14: =SUM(H26:H29) -> 1 | Y14: =SUM(I26:I29) -> 26 | Z14: =SUM(J26:J29) -> 12 | ... AF14: =SUM(P26:P29) -> 944
B15: 08.15 - 08.30 | C15: 6 | D15: 1 | E15: 0 | F15: 54 | G15: 0 | H15: 0 | I15: 1 | J15: 1 | K15: 0 | L15: 1 | M15: 235 | N15: 0 | O15: =SUM(C15:L15,N15) -> 64 | P15: =SUM(C15:N15) -> 299 | R15: 1200-1300 | S15: =SUM(C30:C33) -> 155 | T15: =SUM(D30:D33) -> 25 | U15: =SUM(E30:E33) -> 33 | V15: =SUM(F30:F33) -> 155 | W15: =SUM(G30:G33) -> 5 | X15: =SUM(H30:H33) -> 3 | Y15: =SUM(I30:I33) -> 27 | Z15: =SUM(J30:J33) -> 15 | ... AF15: =SUM(P30:P33) -> 863
B16: 08.30 - 08.45 | C16: 23 | D16: 4 | E16: 10 | F16: 70 | G16: 1 | H16: 0 | I16: 7 | J16: 0 | K16: 5 | L16: 0 | M16: 260 | N16: 0 | O16: =SUM(C16:L16,N16) -> 120 | P16: =SUM(C16:N16) -> 380 | R16: 1300-1400 | S16: =SUM(C34:C37) -> 129 | T16: =SUM(D34:D37) -> 26 | U16: =SUM(E34:E37) -> 14 | V16: =SUM(F34:F37) -> 123 | W16: =SUM(G34:G37) -> 0 | X16: =SUM(H34:H37) -> 2 | Y16: =SUM(I34:I37) -> 20 | Z16: =SUM(J34:J37) -> 10 | ... AF16: =SUM(P34:P37) -> 825
B17: 08.45 - 9.00 | C17: 22 | D17: 3 | E17: 6 | F17: 70 | G17: 0 | H17: 1 | I17: 2 | J17: 0 | K17: 0 | L17: 0 | M17: 115 | N17: 0 | O17: =SUM(C17:L17,N17) -> 104 | P17: =SUM(C17:N17) -> 219 | R17: 1400-1500 | S17: =SUM(C38:C41) -> 102 | T17: =SUM(D38:D41) -> 50 | U17: =SUM(E38:E41) -> 9 | V17: =SUM(F38:F41) -> 120 | W17: =SUM(G38:G41) -> 2 | X17: =SUM(H38:H41) -> 3 | Y17: =SUM(I38:I41) -> 34 | Z17: =SUM(J38:J41) -> 5 | ... AF17: =SUM(P38:P41) -> 921
B18: 09.00 - 09.15 | C18: 21 | D18: 6 | E18: 3 | F18: 42 | G18: 2 | H18: 0 | I18: 5 | J18: 4 | K18: 0 | L18: 2 | M18: 230 | N18: 0 | O18: =SUM(C18:L18,N18) -> 85 | P18: =SUM(C18:N18) -> 315 | R18: 1500-1600 | S18: =SUM(C42:C45) -> 115 | T18: =SUM(D42:D45) -> 66 | U18: =SUM(E42:E45) -> 32 | V18: =SUM(F42:F45) -> 105 | W18: =SUM(G42:G45) -> 4 | X18: =SUM(H42:H45) -> 0 | Y18: =SUM(I42:I45) -> 30 | Z18: =SUM(J42:J45) -> 12 | ... AF18: =SUM(P42:P45) -> 971
B19: 09.15 - 09.30 | C19: 15 | D19: 2 | E19: 3 | F19: 62 | G19: 3 | H19: 0 | I19: 3 | J19: 5 | K19: 0 | L19: 0 | M19: 305 | N19: 0 | O19: =SUM(C19:L19,N19) -> 93 | P19: =SUM(C19:N19) -> 398 | R19: 1600-1700 | S19: =SUM(C46:C49) -> 289 | T19: =SUM(D46:D49) -> 47 | U19: =SUM(E46:E49) -> 27 | V19: =SUM(F46:F49) -> 140 | W19: =SUM(G46:G49) -> 1 | X19: =SUM(H46:H49) -> 1 | Y19: =SUM(I46:I49) -> 56 | Z19: =SUM(J46:J49) -> 3 | ... AF19: =SUM(P46:P49) -> 1381
B20: 09.30 - 09.45 | C20: 13 | D20: 9 | E20: 1 | F20: 60 | G20: 1 | H20: 0 | I20: 7 | J20: 5 | K20: 0 | L20: 1 | M20: 190 | N20: 0 | O20: =SUM(C20:L20,N20) -> 97 | P20: =SUM(C20:N20) -> 287 | R20: 1700-1800 | S20: =SUM(C50:C53) -> 185 | T20: =SUM(D50:D53) -> 45 | U20: =SUM(E50:E53) -> 25 | V20: =SUM(F50:F53) -> 80 | W20: =SUM(G50:G53) -> 6 | X20: =SUM(H50:H53) -> 4 | Y20: =SUM(I50:I53) -> 28 | Z20: =SUM(J50:J53) -> 0 | ... AF20: =SUM(P50:P53) -> 995
B21: 09.45 - 10.00 | C21: 20 | D21: 3 | E21: 5 | F21: 53 | G21: 1 | H21: 0 | I21: 8 | J21: 8 | K21: 2 | L21: 1 | M21: 265 | N21: 0 | O21: =SUM(C21:L21,N21) -> 101 | P21: =SUM(C21:N21) -> 366 | R21: 1800-1900 | S21: =SUM(C54:C57) -> 264 | T21: =SUM(D54:D57) -> 40 | U21: =SUM(E54:E57) -> 28 | V21: =SUM(F54:F57) -> 85 | W21: =SUM(G54:G57) -> 1 | X21: =SUM(H54:H57) -> 2 | Y21: =SUM(I54:I57) -> 15 | Z21: =SUM(J54:J57) -> 11 | ... AF21: =SUM(P54:P57) -> 1268
B22: 10.00 - 10.15 | C22: 9 | D22: 7 | E22: 2 | F22: 35 | G22: 0 | H22: 2 | I22: 7 | J22: 9 | K22: 0 | L22: 0 | M22: 220 | N22: 0 | O22: =SUM(C22:L22,N22) -> 71 | P22: =SUM(C22:N22) -> 291 | R22: AM Peak Hr | S22: =MAX(S10:S12) -> 116 | T22: =MAX(T10:T12) -> 28 | U22: =MAX(U10:U12) -> 18 | V22: =MAX(V10:V12) -> 245 | W22: =MAX(W10:W12) -> 7 | X22: =MAX(X10:X12) -> 2 | Y22: =MAX(Y10:Y12) -> 23 | Z22: =MAX(Z10:Z12) -> 22 | ... AF22: =MAX(AF10:AF12) -> 1366
B23: 10.15 - 10.30 | C23: 21 | D23: 5 | E23: 1 | F23: 65 | G23: 0 | H23: 0 | I23: 5 | J23: 4 | K23: 2 | L23: 0 | M23: 225 | N23: 0 | O23: =SUM(C23:L23,N23) -> 103 | P23: =SUM(C23:N23) -> 328 | R23: IP Peak Hr | S23: =MAX(S13:S18) -> 155 | T23: =MAX(T13:T18) -> 66 | U23: =MAX(U13:U18) -> 33 | V23: =MAX(V13:V18) -> 200 | W23: =MAX(W13:W18) -> 5 | X23: =MAX(X13:X18) -> 3 | Y23: =MAX(Y13:Y18) -> 34 | Z23: =MAX(Z13:Z18) -> 17 | ... AF23: =MAX(AF13:AF18) -> 1226
B24: 10.30 - 10.45 | C24: 19 | D24: 6 | E24: 3 | F24: 40 | G24: 0 | H24: 1 | I24: 6 | J24: 3 | K24: 0 | L24: 1 | M24: 245 | N24: 0 | O24: =SUM(C24:L24,N24) -> 79 | P24: =SUM(C24:N24) -> 324 | R24: PM Peak Hr | S24: =MAX(S19:S21) -> 289 | T24: =MAX(T19:T21) -> 47 | U24: =MAX(U19:U21) -> 28 | V24: =MAX(V19:V21) -> 140 | W24: =MAX(W19:W21) -> 6 | X24: =MAX(X19:X21) -> 4 | Y24: =MAX(Y19:Y21) -> 56 | Z24: =MAX(Z19:Z21) -> 11 | ... AF24: =MAX(AF19:AF21) -> 1381
B25: 10.45 - 11.00 | C25: 31 | D25: 6 | E25: 1 | F25: 60 | G25: 0 | H25: 0 | I25: 3 | J25: 1 | K25: 0 | L25: 0 | M25: 181 | N25: 0 | O25: =SUM(C25:L25,N25) -> 102 | P25: =SUM(C25:N25) -> 283 | R25: AM Period | S25: =SUM(S10:S12) -> 267 | T25: =SUM(T10:T12) -> 60 | U25: =SUM(U10:U12) -> 38 | V25: =SUM(V10:V12) -> 669 | W25: =SUM(W10:W12) -> 15 | X25: =SUM(X10:X12) -> 3 | Y25: =SUM(Y10:Y12) -> 45 | Z25: =SUM(Z10:Z12) -> 33 | ... AF25: =SUM(AF10:AF12) -> 3586
B26: 11.00 - 11.15 | C26: 14 | D26: 12 | E26: 8 | F26: 33 | G26: 0 | H26: 0 | I26: 13 | J26: 3 | K26: 0 | L26: 0 | M26: 137 | N26: 0 | O26: =SUM(C26:L26,N26) -> 83 | P26: =SUM(C26:N26) -> 220 | R26: IP Period | S26: =SUM(S13:S18) -> 662 | T26: =SUM(T13:T18) -> 242 | U26: =SUM(U13:U18) -> 111 | V26: =SUM(V13:V18) -> 827 | W26: =SUM(W13:W18) -> 12 | X26: =SUM(X13:X18) -> 12 | Y26: =SUM(Y13:Y18) -> 158 | Z26: =SUM(Z13:Z18) -> 71 | ... AF26: =SUM(AF13:AF18) -> 5750
B27: 11.15 - 11.30 | C27: 22 | D27: 10 | E27: 2 | F27: 36 | G27: 1 | H27: 0 | I27: 2 | J27: 2 | K27: 0 | L27: 0 | M27: 150 | N27: 0 | O27: =SUM(C27:L27,N27) -> 75 | P27: =SUM(C27:N27) -> 225 | R27: PM Period | S27: =SUM(S19:S21) -> 738 | T27: =SUM(T19:T21) -> 132 | U27: =SUM(U19:U21) -> 80 | V27: =SUM(V19:V21) -> 305 | W27: =SUM(W19:W21) -> 8 | X27: =SUM(X19:X21) -> 7 | Y27: =SUM(Y19:Y21) -> 99 | Z27: =SUM(Z19:Z21) -> 14 | ... AF27: =SUM(AF19:AF21) -> 3644
B28: 11.30 - 11.45 | C28: 11 | D28: 20 | E28: 3 | F28: 26 | G28: 0 | H28: 0 | I28: 3 | J28: 3 | K28: 0 | L28: 0 | M28: 200 | N28: 0 | O28: =SUM(C28:L28,N28) -> 66 | P28: =SUM(C28:N28) -> 266 | R28: 12 Hours | S28: =SUM(S10:S21) -> 1667 | T28: =SUM(T10:T21) -> 434 | U28: =SUM(U10:U21) -> 229 | V28: =SUM(V10:V21) -> 1801 | W28: =SUM(W10:W21) -> 35 | X28: =SUM(X10:X21) -> 22 | Y28: =SUM(Y10:Y21) -> 302 | Z28: =SUM(Z10:Z21) -> 118 | ... AF28: =SUM(AF10:AF21) -> 12980
B29: 11.45 - 12.00 | C29: 34 | D29: 9 | E29: 3 | F29: 29 | G29: 0 | H29: 1 | I29: 8 | J29: 4 | K29: 0 | L29: 1 | M29: 144 | N29: 0 | O29: =SUM(C29:L29,N29) -> 89 | P29: =SUM(C29:N29) -> 233
B30: 12.00 - 12.15 | C30: 21 | D30: 3 | E30: 5 | F30: 22 | G30: 2 | H30: 1 | I30: 5 | J30: 4 | K30: 0 | L30: 0 | M30: 88 | N30: 0 | O30: =SUM(C30:L30,N30) -> 63 | P30: =SUM(C30:N30) -> 151
B31: 12.15 - 12.30 | C31: 31 | D31: 7 | E31: 8 | F31: 35 | G31: 2 | H31: 1 | I31: 5 | J31: 7 | K31: 0 | L31: 0 | M31: 98 | N31: 0 | O31: =SUM(C31:L31,N31) -> 96 | P31: =SUM(C31:N31) -> 194
B32: 12.30 - 12.45 | C32: 51 | D32: 8 | E32: 8 | F32: 38 | G32: 0 | H32: 1 | I32: 8 | J32: 0 | K32: 0 | L32: 0 | M32: 120 | N32: 0 | O32: =SUM(C32:L32,N32) -> 114 | P32: =SUM(C32:N32) -> 234
B33: 12.45 - 13.00 | C33: 52 | D33: 7 | E33: 12 | F33: 60 | G33: 1 | H33: 0 | I33: 9 | J33: 4 | K33: 1 | L33: 0 | M33: 138 | N33: 0 | O33: =SUM(C33:L33,N33) -> 146 | P33: =SUM(C33:N33) -> 284
B34: 13.00 - 13.15 | C34: 42 | D34: 9 | E34: 5 | F34: 40 | G34: 0 | H34: 0 | I34: 13 | J34: 1 | K34: 1 | L34: 0 | M34: 120 | N34: 0 | O34: =SUM(C34:L34,N34) -> 111 | P34: =SUM(C34:N34) -> 231
B35: 13.15 - 13.30 | C35: 21 | D35: 10 | E35: 6 | F35: 37 | G35: 0 | H35: 0 | I35: 2 | J35: 4 | K35: 0 | L35: 0 | M35: 125 | N35: 0 | O35: =SUM(C35:L35,N35) -> 80 | P35: =SUM(C35:N35) -> 205
B36: 13.30 - 13.45 | C36: 26 | D36: 7 | E36: 3 | F36: 21 | G36: 0 | H36: 2 | I36: 5 | J36: 5 | K36: 0 | L36: 0 | M36: 130 | N36: 0 | O36: =SUM(C36:L36,N36) -> 69 | P36: =SUM(C36:N36) -> 199
B37: 13.45 - 14.00 | C37: 40 | D37: 0 | E37: 0 | F37: 25 | G37: 0 | H37: 0 | I37: 0 | J37: 0 | K37: 0 | L37: 0 | M37: 125 | N37: 0 | O37: =SUM(C37:L37,N37) -> 65 | P37: =SUM(C37:N37) -> 190
B38: 14.00 - 14.15 | C38: 20 | D38: 15 | E38: 4 | F38: 35 | G38: 2 | H38: 0 | I38: 8 | J38: 3 | K38: 1 | L38: 0 | M38: 155 | N38: 0 | O38: =SUM(C38:L38,N38) -> 88 | P38: =SUM(C38:N38) -> 243
B39: 14.15 - 14.30 | C39: 25 | D39: 13 | E39: 5 | F39: 30 | G39: 0 | H39: 1 | I39: 10 | J39: 2 | K39: 1 | L39: 1 | M39: 200 | N39: 0 | O39: =SUM(C39:L39,N39) -> 88 | P39: =SUM(C39:N39) -> 288
B40: 14.30 - 14.45 | C40: 24 | D40: 5 | E40: 0 | F40: 30 | G40: 0 | H40: 0 | I40: 1 | J40: 0 | K40: 1 | L40: 0 | M40: 100 | N40: 0 | O40: =SUM(C40:L40,N40) -> 61 | P40: =SUM(C40:N40) -> 161
... B57: 18.45 - 19.00 | C57: 47 | D57: 7 | E57: 7 | F57: 16 | G57: 0 | H57: 0 | I57: 2 | J57: 2 | K57: 2 | L57: 0 | M57: 112 | N57: 0 | O57: =SUM(C57:L57,N57) -> 83 | P57: =SUM(C57:N57) -> 195
B58: Totals | C58: =SUM(C10:C57) -> 1667 | D58: =SUM(D10:D57) -> 434 | E58: =SUM(E10:E57) -> 229 | F58: =SUM(F10:F57) -> 1801 | G58: =SUM(G10:G57) -> 35 | H58: =SUM(H10:H57) -> 22 | I58: =SUM(I10:I57) -> 302 | J58: =SUM(J10:J57) -> 118 | ... P58: =SUM(P10:P57) -> 12980
...

Sheet 23.07 Kalerwe-Kampala
B1: Consultancy services for Preparation of Expressway Development Master Plan (EDMP) for Uganda
B2: MANUAL CLASSIFIED COUNT (MCC)
B3: ROAD NAME: | C3: MCC - C1 - STN24 GAYAZA ROAD
C5: Date | D5: 23.07.19 | F5: Location | G5: Wandegeya | J5: Surveyor | K5: Christine
C6: Dir. From | D6: Kalerwe | F6: Dir. To | G6: Kampala | J6: Supervisor | K6: Lawrence
B8: Time / Veh Type | R8: SUMMARY TRAFFIC VOLUMES
C9: 1. Car | D9: 2. Station Wagon | E9: 3. Pickups | F9: 4. Minibus, matatu | G9: 5. Medium bus | H9: 6. Large Bus | I9: 7. Light Truck | J9: 8. Medium Truck | K9: 9. Heavy truck | L9: 10. Truck Trailer | M9: 11. Motor cycles | N9: 12. Tractors | O9: Total Excl M/Cycles | P9: Total All | R9: Time | S9: 1. Car | T9: 2. Station Wagon | U9: 3. Pickups | V9: 4. Minibus, matatu | W9: 5. Medium bus | X9: 6. Large Bus | Y9: 7. Light Truck | Z9: 8. Medium Truck | AA9: 9. Heavy truck | AB9: 10. Truck Trailer | AC9: 11. Motorcycles | AD9: 12. Tractors, Graders | AE9: Total Excl M/ Cycles | AF9: Total All
B10: 07.00 - 07.15 | C10: 76 | D10: 23 | E10: 2 | F10: 39 | G10: 0 | H10: 0 | I10: 4 | J10: 0 | K10: 0 | L10: 0 | M10: 141 | N10: 0 | O10: =SUM(C10:L10,N10) -> 144 | P10: =SUM(C10:N10) -> 285 | R10: 0700-0800 | S10: =SUM(C10:C13) -> 248 | T10: =SUM(D10:D13) -> 87 | U10: =SUM(E10:E13) -> 14 | V10: =SUM(F10:F13) -> 160 | W10: =SUM(G10:G13) -> 6 | X10: =SUM(H10:H13) -> 0 | Y10: =SUM(I10:I13) -> 22 | Z10: =SUM(J10:J13) -> 0 | ... AF10: =SUM(P10:P13) -> 1210
B11: 07.15 - 07.30 | C11: 46 | D11: 31 | E11: 2 | F11: 29 | G11: 2 | H11: 0 | I11: 7 | J11: 0 | K11: 0 | L11: 0 | M11: 167 | N11: 0 | O11: =SUM(C11:L11,N11) -> 117 | P11: =SUM(C11:N11) -> 284 | R11: 0800-0900 | S11: =SUM(C14:C17) -> 187 | T11: =SUM(D14:D17) -> 57 | U11: =SUM(E14:E17) -> 19 | V11: =SUM(F14:F17) -> 151 | W11: =SUM(G14:G17) -> 1 | X11: =SUM(H14:H17) -> 0 | Y11: =SUM(I14:I17) -> 33 | Z11: =SUM(J14:J17) -> 2 | ... AF11: =SUM(P14:P17) -> 1057
B12: 07.30 - 07.45 | C12: 31 | D12: 7 | E12: 2 | F12: 15 | G12: 2 | H12: 0 | I12: 4 | J12: 0 | K12: 0 | L12: 0 | M12: 137 | N12: 0 | O12: =SUM(C12:L12,N12) -> 61 | P12: =SUM(C12:N12) -> 198 | R12: 0900-1000 | S12: =SUM(C18:C21) -> 173 | T12: =SUM(D18:D21) -> 61 | U12: =SUM(E18:E21) -> 26 | V12: =SUM(F18:F21) -> 158 | W12: =SUM(G18:G21) -> 3 | X12: =SUM(H18:H21) -> 1 | Y12: =SUM(I18:I21) -> 17 | Z12: =SUM(J18:J21) -> 5 | ... AF12: =SUM(P18:P21) -> 1139
B13: 07.45 - 08.00 | C13: 95 | D13: 26 | E13: 8 | F13: 77 | G13: 2 | H13: 0 | I13: 7 | J13: 0 | K13: 0 | L13: 0 | M13: 228 | N13: 0 | O13: =SUM(C13:L13,N13) -> 215 | P13: =SUM(C13:N13) -> 443 | R13: 1000-1100 | S13: =SUM(C22:C25) -> 256 | T13: =SUM(D22:D25) -> 54 | U13: =SUM(E22:E25) -> 19 | V13: =SUM(F22:F25) -> 247 | W13: =SUM(G22:G25) -> 2 | X13: =SUM(H22:H25) -> 1 | Y13: =SUM(I22:I25) -> 25 | Z13: =SUM(J22:J25) -> 4 | ... AF13: =SUM(P22:P25) -> 1097
B14: 08.00 - 08.15 | C14: 40 | D14: 12 | E14: 2 | F14: 11 | G14: 0 | H14: 0 | I14: 5 | J14: 0 | K14: 0 | L14: 0 | M14: 175 | N14: 0 | O14: =SUM(C14:L14,N14) -> 70 | P14: =SUM(C14:N14) -> 245 | R14: 1100-1200 | S14: =SUM(C26:C29) -> 242 | T14: =SUM(D26:D29) -> 92 | U14: =SUM(E26:E29) -> 16 | V14: =SUM(F26:F29) -> 185 | W14: =SUM(G26:G29) -> 2 | X14: =SUM(H26:H29) -> 0 | Y14: =SUM(I26:I29) -> 41 | Z14: =SUM(J26:J29) -> 1 | ... AF14: =SUM(P26:P29) -> 1155
B15: 08.15 - 08.30 | C15: 20 | D15: 3 | E15: 1 | F15: 11 | G15: 0 | H15: 0 | I15: 4 | J15: 2 | K15: 0 | L15: 0 | M15: 123 | N15: 0 | O15: =SUM(C15:L15,N15) -> 41 | P15: =SUM(C15:N15) -> 164 | R15: 1200-1300 | S15: =SUM(C30:C33) -> 235 | T15: =SUM(D30:D33) -> 141 | U15: =SUM(E30:E33) -> 22 | V15: =SUM(F30:F33) -> 168 | W15: =SUM(G30:G33) -> 4 | X15: =SUM(H30:H33) -> 1 | Y15: =SUM(I30:I33) -> 31 | Z15: =SUM(J30:J33) -> 5 | ... AF15: =SUM(P30:P33) -> 1028
B16: 08.30 - 08.45 | C16: 80 | D16: 29 | E16: 7 | F16: 71 | G16: 1 | H16: 0 | I16: 15 | J16: 0 | K16: 0 | L16: 0 | M16: 176 | N16: 0 | O16: =SUM(C16:L16,N16) -> 203 | P16: =SUM(C16:N16) -> 379 | R16: 1300-1400 | S16: =SUM(C34:C37) -> 154 | T16: =SUM(D34:D37) -> 59 | U16: =SUM(E34:E37) -> 22 | V16: =SUM(F34:F37) -> 151 | W16: =SUM(G34:G37) -> 5 | X16: =SUM(H34:H37) -> 0 | Y16: =SUM(I34:I37) -> 30 | Z16: =SUM(J34:J37) -> 5 | ... AF16: =SUM(P34:P37) -> 937
B17: 08.45 - 9.00 | C17: 47 | D17: 13 | E17: 9 | F17: 58 | G17: 0 | H17: 0 | I17: 9 | J17: 0 | K17: 0 | L17: 0 | M17: 133 | N17: 0 | O17: =SUM(C17:L17,N17) -> 136 | P17: =SUM(C17:N17) -> 269 | R17: 1400-1500 | S17: =SUM(C38:C41) -> 177 | T17: =SUM(D38:D41) -> 41 | U17: =SUM(E38:E41) -> 22 | V17: =SUM(F38:F41) -> 136 | W17: =SUM(G38:G41) -> 1 | X17: =SUM(H38:H41) -> 0 | Y17: =SUM(I38:I41) -> 41 | Z17: =SUM(J38:J41) -> 0 | ... AF17: =SUM(P38:P41) -> 873
B18: 09.00 - 09.15 | C18: 36 | D18: 20 | E18: 8 | F18: 43 | G18: 1 | H18: 0 | I18: 4 | J18: 0 | K18: 2 | L18: 0 | M18: 220 | N18: 0 | O18: =SUM(C18:L18,N18) -> 114 | P18: =SUM(C18:N18) -> 334 | R18: 1500-1600 | S18: =SUM(C42:C45) -> 152 | T18: =SUM(D42:D45) -> 51 | U18: =SUM(E42:E45) -> 20 | V18: =SUM(F42:F45) -> 134 | W18: =SUM(G42:G45) -> 2 | X18: =SUM(H42:H45) -> 1 | Y18: =SUM(I42:I45) -> 44 | Z18: =SUM(J42:J45) -> 1 | ... AF18: =SUM(P42:P45) -> 840
B19: 09.15 - 09.30 | C19: 47 | D19: 10 | E19: 2 | F19: 30 | G19: 0 | H19: 0 | I19: 3 | J19: 1 | K19: 1 | L19: 1 | M19: 145 | N19: 0 | O19: =SUM(C19:L19,N19) -> 95 | P19: =SUM(C19:N19) -> 240 | R19: 1600-1700 | S19: =SUM(C46:C49) -> 151 | T19: =SUM(D46:D49) -> 77 | U19: =SUM(E46:E49) -> 21 | V19: =SUM(F46:F49) -> 164 | W19: =SUM(G46:G49) -> 3 | X19: =SUM(H46:H49) -> 1 | Y19: =SUM(I46:I49) -> 17 | Z19: =SUM(J46:J49) -> 0 | ... AF19: =SUM(P46:P49) -> 879
B20: 09.30 - 09.45 | C20: 40 | D20: 15 | E20: 10 | F20: 25 | G20: 1 | H20: 1 | I20: 6 | J20: 0 | K20: 1 | L20: 0 | M20: 180 | N20: 0 | O20: =SUM(C20:L20,N20) -> 99 | P20: =SUM(C20:N20) -> 279 | R20: 1700-1800 | S20: =SUM(C50:C53) -> 255 | T20: =SUM(D50:D53) -> 129 | U20: =SUM(E50:E53) -> 10 | V20: =SUM(F50:F53) -> 220 | W20: =SUM(G50:G53) -> 5 | X20: =SUM(H50:H53) -> 4 | Y20: =SUM(I50:I53) -> 15 | Z20: =SUM(J50:J53) -> 3 | ... AF20: =SUM(P50:P53) -> 1142
B21: 09.45 - 10.00 | C21: 50 | D21: 16 | E21: 6 | F21: 60 | G21: 1 | H21: 0 | I21: 4 | J21: 4 | K21: 0 | L21: 0 | M21: 145 | N21: 0 | O21: =SUM(C21:L21,N21) -> 141 | P21: =SUM(C21:N21) -> 286 | R21: 1800-1900 | S21: =SUM(C54:C57) -> 176 | T21: =SUM(D54:D57) -> 44 | U21: =SUM(E54:E57) -> 31 | V21: =SUM(F54:F57) -> 196 | W21: =SUM(G54:G57) -> 4 | X21: =SUM(H54:H57) -> 4 | Y21: =SUM(I54:I57) -> 23 | Z21: =SUM(J54:J57) -> 5 | ... AF21: =SUM(P54:P57) -> 1190
B22: 10.00 - 10.15 | C22: 41 | D22: 14 | E22: 3 | F22: 37 | G22: 0 | H22: 1 | I22: 3 | J22: 0 | K22: 0 | L22: 0 | M22: 95 | N22: 0 | O22: =SUM(C22:L22,N22) -> 99 | P22: =SUM(C22:N22) -> 194 | R22: AM Peak Hr | S22: =MAX(S10:S12) -> 248 | T22: =MAX(T10:T12) -> 87 | U22: =MAX(U10:U12) -> 26 | V22: =MAX(V10:V12) -> 160 | W22: =MAX(W10:W12) -> 6 | X22: =MAX(X10:X12) -> 1 | Y22: =MAX(Y10:Y12) -> 33 | Z22: =MAX(Z10:Z12) -> 5 | ... AF22: =MAX(AF10:AF12) -> 1210
B23: 10.15 - 10.30 | C23: 85 | D23: 10 | E23: 3 | F23: 85 | G23: 0 | H23: 0 | I23: 3 | J23: 0 | K23: 0 | L23: 0 | M23: 132 | N23: 0 | O23: =SUM(C23:L23,N23) -> 186 | P23: =SUM(C23:N23) -> 318 | R23: IP Peak Hr | S23: =MAX(S13:S18) -> 256 | T23: =MAX(T13:T18) -> 141 | U23: =MAX(U13:U18) -> 22 | V23: =MAX(V13:V18) -> 247 | W23: =MAX(W13:W18) -> 5 | X23: =MAX(X13:X18) -> 1 | Y23: =MAX(Y13:Y18) -> 44 | Z23: =MAX(Z13:Z18) -> 5 | ... AF23: =MAX(AF13:AF18) -> 1155
B24: 10.30 - 10.45 | C24: 70 | D24: 15 | E24: 7 | F24: 40 | G24: 1 | H24: 0 | I24: 9 | J24: 4 | K24: 0 | L24: 0 | M24: 135 | N24: 0 | O24: =SUM(C24:L24,N24) -> 146 | P24: =SUM(C24:N24) -> 281 | R24: PM Peak Hr | S24: =MAX(S19:S21) -> 255 | T24: =MAX(T19:T21) -> 129 | U24: =MAX(U19:U21) -> 31 | V24: =MAX(V19:V21) -> 220 | W24: =MAX(W19:W21) -> 5 | X24: =MAX(X19:X21) -> 4 | Y24: =MAX(Y19:Y21) -> 23 | Z24: =MAX(Z19:Z21) -> 5 | ... AF24: =MAX(AF19:AF21) -> 1190
B25: 10.45 - 11.00 | C25: 60 | D25: 15 | E25: 6 | F25: 85 | G25: 1 | H25: 0 | I25: 10 | J25: 0 | K25: 0 | L25: 1 | M25: 126 | N25: 0 | O25: =SUM(C25:L25,N25) -> 178 | P25: =SUM(C25:N25) -> 304 | R25: AM Period | S25: =SUM(S10:S12) -> 608 | T25: =SUM(T10:T12) -> 205 | U25: =SUM(U10:U12) -> 59 | V25: =SUM(V10:V12) -> 469 | W25: =SUM(W10:W12) -> 10 | X25: =SUM(X10:X12) -> 1 | Y25: =SUM(Y10:Y12) -> 72 | Z25: =SUM(Z10:Z12) -> 7 | ... AF25: =SUM(AF10:AF12) -> 3406
B26: 11.00 - 11.15 | C26: 80 | D26: 30 | E26: 6 | F26: 80 | G26: 0 | H26: 0 | I26: 13 | J26: 0 | K26: 0 | L26: 0 | M26: 170 | N26: 0 | O26: =SUM(C26:L26,N26) -> 209 | P26: =SUM(C26:N26) -> 379 | R26: IP Period | S26: =SUM(S13:S18) -> 1216 | T26: =SUM(T13:T18) -> 438 | U26: =SUM(U13:U18) -> 121 | V26: =SUM(V13:V18) -> 1021 | W26: =SUM(W13:W18) -> 16 | X26: =SUM(X13:X18) -> 3 | Y26: =SUM(Y13:Y18) -> 212 | Z26: =SUM(Z13:Z18) -> 16 | ... AF26: =SUM(AF13:AF18) -> 5930
B27: 11.15 - 11.30 | C27: 42 | D27: 28 | E27: 5 | F27: 52 | G27: 2 | H27: 0 | I27: 7 | J27: 0 | K27: 0 | L27: 0 | M27: 131 | N27: 0 | O27: =SUM(C27:L27,N27) -> 136 | P27: =SUM(C27:N27) -> 267 | R27: PM Period | S27: =SUM(S19:S21) -> 582 | T27: =SUM(T19:T21) -> 250 | U27: =SUM(U19:U21) -> 62 | V27: =SUM(V19:V21) -> 580 | W27: =SUM(W19:W21) -> 12 | X27: =SUM(X19:X21) -> 9 | Y27: =SUM(Y19:Y21) -> 55 | Z27: =SUM(Z19:Z21) -> 8 | ... AF27: =SUM(AF19:AF21) -> 3211
B28: 11.30 - 11.45 | C28: 75 | D28: 15 | E28: 0 | F28: 25 | G28: 0 | H28: 0 | I28: 4 | J28: 0 | K28: 0 | L28: 0 | M28: 85 | N28: 0 | O28: =SUM(C28:L28,N28) -> 119 | P28: =SUM(C28:N28) -> 204 | R28: 12 Hours | S28: =SUM(S10:S21) -> 2406 | T28: =SUM(T10:T21) -> 893 | U28: =SUM(U10:U21) -> 242 | V28: =SUM(V10:V21) -> 2070 | W28: =SUM(W10:W21) -> 38 | X28: =SUM(X10:X21) -> 13 | Y28: =SUM(Y10:Y21) -> 339 | Z28: =SUM(Z10:Z21) -> 31 | ... AF28: =SUM(AF10:AF21) -> 12547
B29: 11.45 - 12.00 | C29: 45 | D29: 19 | E29: 5 | F29: 28 | G29: 0 | H29: 0 | I29: 17 | J29: 1 | K29: 0 | L29: 0 | M29: 190 | N29: 0 | O29: =SUM(C29:L29,N29) -> 115 | P29: =SUM(C29:N29) -> 305
B30: 12.00 - 12.15 | C30: 65 | D30: 65 | E30: 6 | F30: 10 | G30: 0 | H30: 0 | I30: 3 | J30: 0 | K30: 0 | L30: 0 | M30: 45 | N30: 0 | O30: =SUM(C30:L30,N30) -> 149 | P30: =SUM(C30:N30) -> 194
B31: 12.15 - 12.30 | C31: 70 | D31: 45 | E31: 2 | F31: 75 | G31: 2 | H31: 0 | I31: 6 | J31: 5 | K31: 0 | L31: 0 | M31: 148 | N31: 0 | O31: =SUM(C31:L31,N31) -> 205 | P31: =SUM(C31:N31) -> 353
B32: 12.30 - 12.45 | C32: 45 | D32: 20 | E32: 10 | F32: 29 | G32: 0 | H32: 0 | I32: 12 | J32: 0 | K32: 2 | L32: 0 | M32: 145 | N32: 0 | O32: =SUM(C32:L32,N32) -> 118 | P32: =SUM(C32:N32) -> 263
B33: 12.45 - 13.00 | C33: 55 | D33: 11 | E33: 4 | F33: 54 | G33: 2 | H33: 1 | I33: 10 | J33: 0 | K33: 1 | L33: 0 | M33: 80 | N33: 0 | O33: =SUM(C33:L33,N33) -> 138 | P33: =SUM(C33:N33) -> 218
B34: 13.00 - 13.15 | C34: 43 | D34: 16 | E34: 0 | F34: 47 | G34: 0 | H34: 0 | I34: 10 | J34: 2 | K34: `1 | L34: 2 | M34: 125 | N34: 0 | O34: =SUM(C34:L34,N34) -> 120 | P34: =SUM(C34:N34) -> 245
B35: 13.15 - 13.30 | C35: 60 | D35: 19 | E35: 12 | F35: 47 | G35: 4 | H35: 0 | I35: 6 | J35: 1 | K35: 1 | L35: 2 | M35: 86 | N35: 0 | O35: =SUM(C35:L35,N35) -> 152 | P35: =SUM(C35:N35) -> 238
B36: 13.30 - 13.45 | C36: 26 | D36: 11 | E36: 1 | F36: 36 | G36: 1 | H36: 0 | I36: 11 | J36: 0 | K36: 0 | L36: 0 | M36: 140 | N36: 0 | O36: =SUM(C36:L36,N36) -> 86 | P36: =SUM(C36:N36) -> 226
B37: 13.45 - 14.00 | C37: 25 | D37: 13 | E37: 9 | F37: 21 | G37: 0 | H37: 0 | I37: 3 | J37: 2 | K37: 0 | L37: 0 | M37: 155 | N37: 0 | O37: =SUM(C37:L37,N37) -> 73 | P37: =SUM(C37:N37) -> 228
B38: 14.00 - 14.15 | C38: 10 | D38: 4 | E38: 5 | F38: 11 | G38: 1 | H38: 0 | I38: 6 | J38: 0 | K38: 0 | L38: 0 | M38: 145 | N38: 0 | O38: =SUM(C38:L38,N38) -> 37 | P38: =SUM(C38:N38) -> 182
B39: 14.15 - 14.30 | C39: 20 | D39: 3 | E39: 4 | F39: 50 | G39: 0 | H39: 0 | I39: 20 | J39: 0 | K39: 0 | L39: 0 | M39: 130 | N39: 0 | O39: =SUM(C39:L39,N39) -> 97 | P39: =SUM(C39:N39) -> 227
B40: 14.30 - 14.45 | C40: 22 | D40: 4 | E40: 3 | F40: 45 | G40: 0 | H40: 0 | I40: 7 | J40: 0 | K40: 0 | L40: 0 | M40: 90 | N40: 0 | O40: =SUM(C40:L40,N40) -> 81 | P40: =SUM(C40:N40) -> 171
B41: 14.45 - 15.00 | C41: 125 | D41: 30 | E41: 10 | F41: 30 | G41: 0 | H41: 0 | I41: 8 | J41: 0 | K41: 0 | L41: 0 | M41: 90 | N41: 0 | O41: =SUM(C41:L41,N41) -> 203 | P41: =SUM(C41:N41) -> 293
B42: 15.00 - 15.15 | C42: 27 | D42: 5 | E42: 6 | F42: 25 | G42: 1 | H42: 1 | I42: 11 | J42: 0 | K42: 0 | L42: 0 | M42: 145 | N42: 0 | O42: =SUM(C42:L42,N42) -> 76 | P42: =SUM(C42:N42) -> 221
...

Sheet 23.07 Kampala-Kalerwe
B1: Consultancy services for Preparation of Expressway Development Master Plan (EDMP) for Uganda
B2: MANUAL CLASSIFIED COUNT (MCC)
B3: ROAD NAME: | C3: ='22.07 Kampala-Kalerwe'!C3:G3 -> MCC - C1 - STN24 GAYAZA ROAD
C5: Date | D5: ='23.07 Kalerwe-Kampala'!D5 -> 23.07.19 | F5: Location | G5: ='22.07 Kalerwe-Kampala'!G5:H5 -> Wandegeya | J5: Surveyor | K5: Beteth
C6: Dir. From | D6: ='22.07 Kampala-Kalerwe'!D6:E6 -> Kampala | F6: Dir. To | G6: ='22.07 Kampala-Kalerwe'!G6:H6 -> Kalerwe | J6: Supervisor | K6: Lawrence
B8: Time / Veh Type | R8: SUMMARY TRAFFIC VOLUMES
C9: 1. Car | D9: 2. Station Wagon | E9: 3. Pickups | F9: 4. Minibus, matatu | G9: 5. Medium bus | H9: 6. Large Bus | I9: 7. Light Truck | J9: 8. Medium Truck | K9: 9. Heavy truck | L9: 10. Truck Trailer | M9: 11. Motor cycles | N9: 12. Tractors | O9: Total Excl M/Cycles | P9: Total All | R9: Time | S9: 1. Car | T9: 2. Station Wagon | U9: 3. Pickups | V9: 4. Minibus, matatu | W9: 5. Medium bus | X9: 6. Large Bus | Y9: 7. Light Truck | Z9: 8. Medium Truck | AA9: 9. Heavy truck | AB9: 10. Truck Trailer | AC9: 11. Motorcycles | AD9: 12. Tractors, Graders | AE9: Total Excl M/ Cycles | AF9: Total All
B10: 07.00 - 07.15 | C10: 32 | D10: 8 | E10: 2 | F10: 73 | G10: 3 | H10: 2 | I10: 6 | J10: 0 | K10: 0 | L10: 0 | M10: 165 | N10: 0 | O10: =SUM(C10:L10,N10) -> 126 | P10: =SUM(C10:N10) -> 291 | R10: 0700-0800 | S10: =SUM(C10:C13) -> 98 | T10: =SUM(D10:D13) -> 28 | U10: =SUM(E10:E13) -> 12 | V10: =SUM(F10:F13) -> 225 | W10: =SUM(G10:G13) -> 6 | X10: =SUM(H10:H13) -> 4 | Y10: =SUM(I10:I13) -> 24 | Z10: =SUM(J10:J13) -> 1 | ... AF10: =SUM(P10:P13) -> 1209
B11: 07.15 - 07.30 | C11: 22 | D11: 6 | E11: 1 | F11: 45 | G11: 3 | H11: 0 | I11: 10 | J11: 0 | K11: 1 | L11: 0 | M11: 188 | N11: 0 | O11: =SUM(C11:L11,N11) -> 88 | P11: =SUM(C11:N11) -> 276 | R11: 0800-0900 | S11: =SUM(C14:C17) -> 84 | T11: =SUM(D14:D17) -> 13 | U11: =SUM(E14:E17) -> 9 | V11: =SUM(F14:F17) -> 226 | W11: =SUM(G14:G17) -> 3 | X11: =SUM(H14:H17) -> 0 | Y11: =SUM(I14:I17) -> 29 | Z11: =SUM(J14:J17) -> 3 | ... AF11: =SUM(P14:P17) -> 1622
B12: 07.30 - 07.45 | C12: 21 | D12: 5 | E12: 3 | F12: 49 | G12: 0 | H12: 2 | I12: 3 | J12: 0 | K12: 0 | L12: 0 | M12: 190 | N12: 0 | O12: =SUM(C12:L12,N12) -> 83 | P12: =SUM(C12:N12) -> 273 | R12: 0900-1000 | S12: =SUM(C18:C21) -> 74 | T12: =SUM(D18:D21) -> 34 | U12: =SUM(E18:E21) -> 17 | V12: =SUM(F18:F21) -> 236 | W12: =SUM(G18:G21) -> 5 | X12: =SUM(H18:H21) -> 1 | Y12: =SUM(I18:I21) -> 42 | Z12: =SUM(J18:J21) -> 2 | ... AF12: =SUM(P18:P21) -> 1413
B13: 07.45 - 08.00 | C13: 23 | D13: 9 | E13: 6 | F13: 58 | G13: 0 | H13: 0 | I13: 5 | J13: 1 | K13: 0 | L13: 0 | M13: 267 | N13: 0 | O13: =SUM(C13:L13,N13) -> 102 | P13: =SUM(C13:N13) -> 369 | R13: 1000-1100 | S13: =SUM(C22:C25) -> 93 | T13: =SUM(D22:D25) -> 33 | U13: =SUM(E22:E25) -> 18 | V13: =SUM(F22:F25) -> 170 | W13: =SUM(G22:G25) -> 3 | X13: =SUM(H22:H25) -> 3 | Y13: =SUM(I22:I25) -> 39 | Z13: =SUM(J22:J25) -> 4 | ... AF13: =SUM(P22:P25) -> 1242
B14: 08.00 - 08.15 | C14: 18 | D14: 4 | E14: 3 | F14: 50 | G14: 1 | H14: 0 | I14: 4 | J14: 0 | K14: 1 | L14: 1 | M14: 275 | N14: 0 | O14: =SUM(C14:L14,N14) -> 82 | P14: =SUM(C14:N14) -> 357 | R14: 1100-1200 | S14: =SUM(C26:C29) -> 102 | T14: =SUM(D26:D29) -> 34 | U14: =SUM(E26:E29) -> 25 | V14: =SUM(F26:F29) -> 147 | W14: =SUM(G26:G29) -> 1 | X14: =SUM(H26:H29) -> 6 | Y14: =SUM(I26:I29) -> 33 | Z14: =SUM(J26:J29) -> 3 | ... AF14: =SUM(P26:P29) -> 1214
B15: 08.15 - 08.30 | C15: 19 | D15: 2 | E15: 1 | F15: 55 | G15: 2 | H15: 0 | I15: 9 | J15: 2 | K15: 2 | L15: 0 | M15: 287 | N15: 0 | O15: =SUM(C15:L15,N15) -> 92 | P15: =SUM(C15:N15) -> 379 | R15: 1200-1300 | S15: =SUM(C30:C33) -> 105 | T15: =SUM(D30:D33) -> 37 | U15: =SUM(E30:E33) -> 20 | V15: =SUM(F30:F33) -> 132 | W15: =SUM(G30:G33) -> 17 | X15: =SUM(H30:H33) -> 3 | Y15: =SUM(I30:I33) -> 39 | Z15: =SUM(J30:J33) -> 4 | ... AF15: =SUM(P30:P33) -> 1092
B16: 08.30 - 08.45 | C16: 25 | D16: 6 | E16: 2 | F16: 64 | G16: 0 | H16: 0 | I16: 9 | J16: 0 | K16: 0 | L16: 1 | M16: 315 | N16: 0 | O16: =SUM(C16:L16,N16) -> 107 | P16: =SUM(C16:N16) -> 422 | R16: 1300-1400 | S16: =SUM(C34:C37) -> 97 | T16: =SUM(D34:D37) -> 37 | U16: =SUM(E34:E37) -> 30 | V16: =SUM(F34:F37) -> 109 | W16: =SUM(G34:G37) -> 3 | X16: =SUM(H34:H37) -> 1 | Y16: =SUM(I34:I37) -> 29 | Z16: =SUM(J34:J37) -> 3 | ... AF16: =SUM(P34:P37) -> 901
B17: 08.45 - 9.00 | C17: 22 | D17: 1 | E17: 3 | F17: 57 | G17: 0 | H17: 0 | I17: 7 | J17: 1 | K17: 1 | L17: 1 | M17: 371 | N17: 0 | O17: =SUM(C17:L17,N17) -> 93 | P17: =SUM(C17:N17) -> 464 | R17: 1400-1500 | S17: =SUM(C38:C41) -> 94 | T17: =SUM(D38:D41) -> 60 | U17: =SUM(E38:E41) -> 41 | V17: =SUM(F38:F41) -> 132 | W17: =SUM(G38:G41) -> 3 | X17: =SUM(H38:H41) -> 3 | Y17: =SUM(I38:I41) -> 55 | Z17: =SUM(J38:J41) -> 7 | ... AF17: =SUM(P38:P41) -> 944
B18: 09.00 - 09.15 | C18: 19 | D18: 6 | E18: 5 | F18: 55 | G18: 1 | H18: 1 | I18: 7 | J18: 0 | K18: 2 | L18: 0 | M18: 258 | N18: 0 | O18: =SUM(C18:L18,N18) -> 96 | P18: =SUM(C18:N18) -> 354 | R18: 1500-1600 | S18: =SUM(C42:C45) -> 138 | T18: =SUM(D42:D45) -> 73 | U18: =SUM(E42:E45) -> 33 | V18: =SUM(F42:F45) -> 147 | W18: =SUM(G42:G45) -> 4 | X18: =SUM(H42:H45) -> 3 | Y18: =SUM(I42:I45) -> 25 | Z18: =SUM(J42:J45) -> 6 | ... AF18: =SUM(P42:P45) -> 1023
B19: 09.15 - 09.30 | C19: 15 | D19: 13 | E19: 1 | F19: 66 | G19: 0 | H19: 0 | I19: 8 | J19: 0 | K19: 0 | L19: 0 | M19: 260 | N19: 0 | O19: =SUM(C19:L19,N19) -> 103 | P19: =SUM(C19:N19) -> 363 | R19: 1600-1700 | S19: =SUM(C46:C49) -> 155 | T19: =SUM(D46:D49) -> 71 | U19: =SUM(E46:E49) -> 14 | V19: =SUM(F46:F49) -> 170 | W19: =SUM(G46:G49) -> 4 | X19: =SUM(H46:H49) -> 1 | Y19: =SUM(I46:I49) -> 29 | Z19: =SUM(J46:J49) -> 2 | ... AF19: =SUM(P46:P49) -> 1045
B20: 09.30 - 09.45 | C20: 14 | D20: 9 | E20: 6 | F20: 59 | G20: 1 | H20: 0 | I20: 8 | J20: 2 | K20: 0 | L20: 1 | M20: 230 | N20: 0 | O20: =SUM(C20:L20,N20) -> 100 | P20: =SUM(C20:N20) -> 330 | R20: 1700-1800 | S20: =SUM(C50:C53) -> 251 | T20: =SUM(D50:D53) -> 50 | U20: =SUM(E50:E53) -> 19 | V20: =SUM(F50:F53) -> 119 | W20: =SUM(G50:G53) -> 5 | X20: =SUM(H50:H53) -> 4 | Y20: =SUM(I50:I53) -> 31 | Z20: =SUM(J50:J53) -> 4 | ... AF20: =SUM(P50:P53) -> 1068
B21: 09.45 - 10.00 | C21: 26 | D21: 6 | E21: 5 | F21: 56 | G21: 3 | H21: 0 | I21: 19 | J21: 0 | K21: 1 | L21: 0 | M21: 250 | N21: 0 | O21: =SUM(C21:L21,N21) -> 116 | P21: =SUM(C21:N21) -> 366 | R21: 1800-1900 | S21: =SUM(C54:C57) -> 316 | T21: =SUM(D54:D57) -> 148 | U21: =SUM(E54:E57) -> 20 | V21: =SUM(F54:F57) -> 218 | W21: =SUM(G54:G57) -> 6 | X21: =SUM(H54:H57) -> 5 | Y21: =SUM(I54:I57) -> 34 | Z21: =SUM(J54:J57) -> 8 | ... AF21: =SUM(P54:P57) -> 1828
B22: 10.00 - 10.15 | C22: 20 | D22: 4 | E22: 2 | F22: 40 | G22: 2 | H22: 2 | I22: 10 | J22: 0 | K22: 0 | L22: 0 | M22: 220 | N22: 0 | O22: =SUM(C22:L22,N22) -> 80 | P22: =SUM(C22:N22) -> 300 | R22: AM Peak Hr | S22: =MAX(S10:S12) -> 98 | T22: =MAX(T10:T12) -> 34 | U22: =MAX(U10:U12) -> 17 | V22: =MAX(V10:V12) -> 236 | W22: =MAX(W10:W12) -> 6 | X22: =MAX(X10:X12) -> 4 | Y22: =MAX(Y10:Y12) -> 42 | Z22: =MAX(Z10:Z12) -> 3 | ... AF22: =MAX(AF10:AF12) -> 1622
B23: 10.15 - 10.30 | C23: 28 | D23: 8 | E23: 6 | F23: 55 | G23: 1 | H23: 1 | I23: 7 | J23: 1 | K23: 1 | L23: 0 | M23: 250 | N23: 0 | O23: =SUM(C23:L23,N23) -> 108 | P23: =SUM(C23:N23) -> 358 | R23: IP Peak Hr | S23: =MAX(S13:S18) -> 138 | T23: =MAX(T13:T18) -> 73 | U23: =MAX(U13:U18) -> 41 | V23: =MAX(V13:V18) -> 170 | W23: =MAX(W13:W18) -> 17 | X23: =MAX(X13:X18) -> 6 | Y23: =MAX(Y13:Y18) -> 55 | Z23: =MAX(Z13:Z18) -> 7 | ... AF23: =MAX(AF13:AF18) -> 1242
B24: 10.30 - 10.45 | C24: 20 | D24: 7 | E24: 7 | F24: 38 | G24: 0 | H24: 0 | I24: 9 | J24: 0 | K24: 0 | L24: 2 | M24: 200 | N24: 0 | O24: =SUM(C24:L24,N24) -> 83 | P24: =SUM(C24:N24) -> 283 | R24: PM Peak Hr | S24: =MAX(S19:S21) -> 316 | T24: =MAX(T19:T21) -> 148 | U24: =MAX(U19:U21) -> 20 | V24: =MAX(V19:V21) -> 218 | W24: =MAX(W19:W21) -> 6 | X24: =MAX(X19:X21) -> 5 | Y24: =MAX(Y19:Y21) -> 34 | Z24: =MAX(Z19:Z21) -> 8 | ... AF24: =MAX(AF19:AF21) -> 1828
B25: 10.45 - 11.00 | C25: 25 | D25: 14 | E25: 3 | F25: 37 | G25: 0 | H25: 0 | I25: 13 | J25: 3 | K25: 2 | L25: 0 | M25: 204 | N25: 0 | O25: =SUM(C25:L25,N25) -> 97 | P25: =SUM(C25:N25) -> 301 | R25: AM Period | S25: =SUM(S10:S12) -> 256 | T25: =SUM(T10:T12) -> 75 | U25: =SUM(U10:U12) -> 38 | V25: =SUM(V10:V12) -> 687 | W25: =SUM(W10:W12) -> 14 | X25: =SUM(X10:X12) -> 5 | Y25: =SUM(Y10:Y12) -> 95 | Z25: =SUM(Z10:Z12) -> 6 | ... AF25: =SUM(AF10:AF12) -> 4244
B26: 11.00 - 11.15 | C26: 30 | D26: 11 | E26: 8 | F26: 43 | G26: 0 | H26: 2 | I26: 14 | J26: 1 | K26: 0 | L26: 1 | M26: 210 | N26: 0 | O26: =SUM(C26:L26,N26) -> 110 | P26: =SUM(C26:N26) -> 320 | R26: IP Period | S26: =SUM(S13:S18) -> 629 | T26: =SUM(T13:T18) -> 274 | U26: =SUM(U13:U18) -> 167 | V26: =SUM(V13:V18) -> 837 | W26: =SUM(W13:W18) -> 31 | X26: =SUM(X13:X18) -> 19 | Y26: =SUM(Y13:Y18) -> 220 | Z26: =SUM(Z13:Z18) -> 27 | ... AF26: =SUM(AF13:AF18) -> 6416
B27: 11.15 - 11.30 | C27: 19 | D27: 10 | E27: 5 | F27: 36 | G27: 0 | H27: 0 | I27: 7 | J27: 1 | K27: 1 | L27: 0 | M27: 240 | N27: 0 | O27: =SUM(C27:L27,N27) -> 79 | P27: =SUM(C27:N27) -> 319 | R27: PM Period | S27: =SUM(S19:S21) -> 722 | T27: =SUM(T19:T21) -> 269 | U27: =SUM(U19:U21) -> 53 | V27: =SUM(V19:V21) -> 507 | W27: =SUM(W19:W21) -> 15 | X27: =SUM(X19:X21) -> 10 | Y27: =SUM(Y19:Y21) -> 94 | Z27: =SUM(Z19:Z21) -> 14 | ... AF27: =SUM(AF19:AF21) -> 3941
B28: 11.30 - 11.45 | C28: 28 | D28: 7 | E28: 6 | F28: 42 | G28: 1 | H28: 1 | I28: 7 | J28: 1 | K28: 0 | L28: 1 | M28: 220 | N28: 0 | O28: =SUM(C28:L28,N28) -> 94 | P28: =SUM(C28:N28) -> 314 | R28: 12 Hours | S28: =SUM(S10:S21) -> 1607 | T28: =SUM(T10:T21) -> 618 | U28: =SUM(U10:U21) -> 258 | V28: =SUM(V10:V21) -> 2031 | W28: =SUM(W10:W21) -> 60 | X28: =SUM(X10:X21) -> 34 | Y28: =SUM(Y10:Y21) -> 409 | Z28: =SUM(Z10:Z21) -> 47 | ... AF28: =SUM(AF10:AF21) -> 14601
B29: 11.45 - 12.00 | C29: 25 | D29: 6 | E29: 6 | F29: 26 | G29: 0 | H29: 3 | I29: 5 | J29: 0 | K29: 0 | L29: 0 | M29: 190 | N29: 0 | O29: =SUM(C29:L29,N29) -> 71 | P29: =SUM(C29:N29) -> 261
B30: 12.00 - 12.15 | C30: 26 | D30: 10 | E30: 6 | F30: 39 | G30: 1 | H30: 1 | I30: 13 | J30: 4 | K30: 1 | L30: 2 | M30: 150 | N30: 0 | O30: =SUM(C30:L30,N30) -> 103 | P30: =SUM(C30:N30) -> 253
B31: 12.15 - 12.30 | C31: 30 | D31: 8 | E31: 3 | F31: 30 | G31: 0 | H31: 0 | I31: 4 | J31: 0 | K31: 2 | L31: 0 | M31: 178 | N31: 0 | O31: =SUM(C31:L31,N31) -> 77 | P31: =SUM(C31:N31) -> 255
B32: 12.30 - 12.45 | C32: 27 | D32: 12 | E32: 7 | F32: 39 | G32: 2 | H32: 2 | I32: 7 | J32: 0 | K32: 0 | L32: 1 | M32: 190 | N32: 0 | O32: =SUM(C32:L32,N32) -> 97 | P32: =SUM(C32:N32) -> 287
B33: 12.45 - 13.00 | C33: 22 | D33: 7 | E33: 4 | F33: 24 | G33: 14 | H33: 0 | I33: 15 | J33: 0 | K33: 1 | L33: 0 | M33: 210 | N33: 0 | O33: =SUM(C33:L33,N33) -> 87 | P33: =SUM(C33:N33) -> 297
B34: 13.00 - 13.15 | C34: 28 | D34: 13 | E34: 3 | F34: 45 | G34: 0 | H34: 1 | I34: 11 | J34: 1 | K34: 1 | L34: 1 | M34: 130 | N34: 0 | O34: =SUM(C34:L34,N34) -> 104 | P34: =SUM(C34:N34) -> 234
B35: 13.15 - 13.30 | C35: 11 | D35: 3 | E35: 3 | F35: 30 | G35: 1 | H35: 0 | I35: 6 | J35: 1 | K35: 0 | L35: 0 | M35: 150 | N35: 0 | O35: =SUM(C35:L35,N35) -> 55 | P35: =SUM(C35:N35) -> 205
B36: 13.30 - 13.45 | C36: 22 | D36: 5 | E36: 4 | F36: 24 | G36: 2 | H36: 0 | I36: 9 | J36: 0 | K36: 3 | L36: 0 | M36: 145 | N36: 0 | O36: =SUM(C36:L36,N36) -> 69 | P36: =SUM(C36:N36) -> 214
B37: 13.45 - 14.00 | C37: 36 | D37: 16 | E37: 20 | F37: 10 | G37: 0 | H37: 0 | I37: 3 | J37: 1 | K37: 2 | L37: 0 | M37: 160 | N37: 0 | O37: =SUM(C37:L37,N37) -> 88 | P37: =SUM(C37:N37) -> 248
B38: 14.00 - 14.15 | C38: 22 | D38: 7 | E38: 5 | F38: 30 | G38: 2 | H38: 1 | I38: 10 | J38: 3 | K38: 2 | L38: 0 | M38: 153 | N38: 0 | O38: =SUM(C38:L38,N38) -> 82 | P38: =SUM(C38:N38) -> 235
B39: 14.15 - 14.30 | C39: 22 | D39: 15 | E39: 10 | F39: 42 | G39: 0 | H39: 0 | I39: 26 | J39: 2 | K39: 1 | L39: 0 | M39: 140 | N39: 0 | O39: =SUM(C39:L39,N39) -> 118 | P39: =SUM(C39:N39) -> 258
B40: 14.30 - 14.45 | C40: 34 | D40: 24 | E40: 18 | F40: 48 | G40: 1 | H40: 1 | I40: 10 | J40: 1 | K40: 1 | L40: 0 | M40: 130 | N40: 0 | O40: =SUM(C40:L40,N40) -> 138 | P40: =SUM(C40:N40) -> 268
... B57: 18.45 - 19.00 | C57: 85 | D57: 50 | E57: 9 | F57: 70 | G57: 4 | H57: 3 | I57: 8 | J57: 3 | K57: 0 | L57: 1 | M57: 310 | N57: 0 | O57: =SUM(C57:L57,N57) -> 233 | P57: =SUM(C57:N57) -> 543
B58: Totals | C58: =SUM(C10:C57) -> 1607 | D58: =SUM(D10:D57) -> 618 | E58: =SUM(E10:E57) -> 258 | F58: =SUM(F10:F57) -> 2031 | G58: =SUM(G10:G57) -> 60 | H58: =SUM(H10:H57) -> 34 | I58: =SUM(I10:I57) -> 409 | J58: =SUM(J10:J57) -> 47 | ... P58: =SUM(P10:P57) -> 14601
...

Sheet 24.07 Kalewre-Kampala
B1: Consultancy services for Preparation of Expressway Development Master Plan (EDMP) for Uganda
B2: MANUAL CLASSIFIED COUNT (MCC)
B3: ROAD NAME: | C3: ='22.07 Kalerwe-Kampala'!C3:G3 -> MCC - C1 - STN24 GAYAZA ROAD
C5: Date | D5: 24.07.19 | F5: Location | G5: ='22.07 Kalerwe-Kampala'!G5:H5 -> Wandegeya | J5: Surveyor | K5: Mbabazi
C6: Dir. From | D6: ='22.07 Kalerwe-Kampala'!D6:E6 -> Kalewre | F6: Dir. To | G6: ='22.07 Kalerwe-Kampala'!G6:H6 -> Kampala | J6: Supervisor | K6: ='22.07 Kalerwe-Kampala'!K6:L6 -> Lawrence
B8: Time / Veh Type | R8: SUMMARY TRAFFIC VOLUMES
C9: 1. Car | D9: 2. Station Wagon | E9: 3. Pickups | F9: 4. Minibus, matatu | G9: 5. Medium bus | H9: 6. Large Bus | I9: 7. Light Truck | J9: 8. Medium Truck | K9: 9. Heavy truck | L9: 10. Truck Trailer | M9: 11. Motor cycles | N9: 12. Tractors | O9: Total Excl M/Cycles | P9: Total All | R9: Time | S9: 1. Car | T9: 2. Station Wagon | U9: 3. Pickups | V9: 4. Minibus, matatu | W9: 5. Medium bus | X9: 6. Large Bus | Y9: 7. Light Truck | Z9: 8. Medium Truck | AA9: 9. Heavy truck | AB9: 10. Truck Trailer | AC9: 11. Motorcycles | AD9: 12. Tractors, Graders | AE9: Total Excl M/ Cycles | AF9: Total All
B10: 07.00 - 07.15 | C10: 0 | D10: 2 | E10: 12 | F10: 55 | G10: 0 | H10: 0 | I10: 30 | J10: 0 | K10: 0 | L10: 0 | M10: 195 | N10: 0 | O10: =SUM(C10:L10,N10) -> 99 | P10: =SUM(C10:N10) -> 294 | R10: 0700-0800 | S10: =SUM(C10:C13) -> 62 | T10: =SUM(D10:D13) -> 23 | U10: =SUM(E10:E13) -> 39 | V10: =SUM(F10:F13) -> 205 | W10: =SUM(G10:G13) -> 0 | X10: =SUM(H10:H13) -> 1 | Y10: =SUM(I10:I13) -> 83 | Z10: =SUM(J10:J13) -> 2 | ... AF10: =SUM(P10:P13) -> 1146
B11: 07.15 - 07.30 | C11: 16 | D11: 7 | E11: 8 | F11: 60 | G11: 0 | H11: 0 | I11: 34 | J11: 0 | K11: 1 | L11: 0 | M11: 155 | N11: 0 | O11: =SUM(C11:L11,N11) -> 126 | P11: =SUM(C11:N11) -> 281 | R11: 0800-0900 | S11: =SUM(C14:C17) -> 255 | T11: =SUM(D14:D17) -> 30 | U11: =SUM(E14:E17) -> 24 | V11: =SUM(F14:F17) -> 175 | W11: =SUM(G14:G17) -> 0 | X11: =SUM(H14:H17) -> 2 | Y11: =SUM(I14:I17) -> 19 | Z11: =SUM(J14:J17) -> 8 | ... AF11: =SUM(P14:P17) -> 1485
B12: 07.30 - 07.45 | C12: 42 | D12: 5 | E12: 15 | F12: 65 | G12: 0 | H12: 0 | I12: 18 | J12: 0 | K12: 0 | L12: 0 | M12: 160 | N12: 0 | O12: =SUM(C12:L12,N12) -> 145 | P12: =SUM(C12:N12) -> 305 | R12: 0900-1000 | S12: =SUM(C18:C21) -> 187 | T12: =SUM(D18:D21) -> 18 | U12: =SUM(E18:E21) -> 35 | V12: =SUM(F18:F21) -> 155 | W12: =SUM(G18:G21) -> 2 | X12: =SUM(H18:H21) -> 1 | Y12: =SUM(I18:I21) -> 18 | Z12: =SUM(J18:J21) -> 6 | ... AF12: =SUM(P18:P21) -> 1190
B13: 07.45 - 08.00 | C13: 4 | D13: 9 | E13: 4 | F13: 25 | G13: 0 | H13: 1 | I13: 1 | J13: 2 | K13: 0 | L13: 0 | M13: 220 | N13: 0 | O13: =SUM(C13:L13,N13) -> 46 | P13: =SUM(C13:N13) -> 266 | R13: 1000-1100 | S13: =SUM(C22:C25) -> 130 | T13: =SUM(D22:D25) -> 113 | U13: =SUM(E22:E25) -> 43 | V13: =SUM(F22:F25) -> 147 | W13: =SUM(G22:G25) -> 7 | X13: =SUM(H22:H25) -> 1 | Y13: =SUM(I22:I25) -> 25 | Z13: =SUM(J22:J25) -> 1 | ... AF13: =SUM(P22:P25) -> 1353
B14: 08.00 - 08.15 | C14: 62 | D14: 10 | E14: 5 | F14: 47 | G14: 0 | H14: 0 | I14: 3 | J14: 1 | K14: 0 | L14: 0 | M14: 260 | N14: 0 | O14: =SUM(C14:L14,N14) -> 128 | P14: =SUM(C14:N14) -> 388 | R14: 1100-1200 | S14: =SUM(C26:C29) -> 241 | T14: =SUM(D26:D29) -> 54 | U14: =SUM(E26:E29) -> 35 | V14: =SUM(F26:F29) -> 163 | W14: =SUM(G26:G29) -> 1 | X14: =SUM(H26:H29) -> 4 | Y14: =SUM(I26:I29) -> 32 | Z14: =SUM(J26:J29) -> 7 | ... AF14: =SUM(P26:P29) -> 1038
B15: 08.15 - 08.30 | C15: 68 | D15: 6 | E15: 6 | F15: 47 | G15: 0 | H15: 2 | I15: 7 | J15: 2 | K15: 0 | L15: 0 | M15: 255 | N15: 0 | O15: =SUM(C15:L15,N15) -> 138 | P15: =SUM(C15:N15) -> 393 | R15: 1200-1300 | S15: =SUM(C30:C33) -> 114 | T15: =SUM(D30:D33) -> 155 | U15: =SUM(E30:E33) -> 73 | V15: =SUM(F30:F33) -> 152 | W15: =SUM(G30:G33) -> 1 | X15: =SUM(H30:H33) -> 1 | Y15: =SUM(I30:I33) -> 30 | Z15: =SUM(J30:J33) -> 3 | ... AF15: =SUM(P30:P33) -> 1131
B16: 08.30 - 08.45 | C16: 55 | D16: 8 | E16: 8 | F16: 41 | G16: 0 | H16: 0 | I16: 4 | J16: 2 | K16: 0 | L16: 1 | M16: 232 | N16: 0 | O16: =SUM(C16:L16,N16) -> 119 | P16: =SUM(C16:N16) -> 351 | R16: 1300-1400 | S16: =SUM(C34:C37) -> 78 | T16: =SUM(D34:D37) -> 137 | U16: =SUM(E34:E37) -> 63 | V16: =SUM(F34:F37) -> 155 | W16: =SUM(G34:G37) -> 1 | X16: =SUM(H34:H37) -> 0 | Y16: =SUM(I34:I37) -> 30 | Z16: =SUM(J34:J37) -> 9 | ... AF16: =SUM(P34:P37) -> 1087
B17: 08.45 - 9.00 | C17: 70 | D17: 6 | E17: 5 | F17: 40 | G17: 0 | H17: 0 | I17: 5 | J17: 3 | K17: 0 | L17: 0 | M17: 224 | N17: 0 | O17: =SUM(C17:L17,N17) -> 129 | P17: =SUM(C17:N17) -> 353 | R17: 1400-1500 | S17: =SUM(C38:C41) -> 87 | T17: =SUM(D38:D41) -> 134 | U17: =SUM(E38:E41) -> 24 | V17: =SUM(F38:F41) -> 118 | W17: =SUM(G38:G41) -> 4 | X17: =SUM(H38:H41) -> 1 | Y17: =SUM(I38:I41) -> 19 | Z17: =SUM(J38:J41) -> 5 | ... AF17: =SUM(P38:P41) -> 994
B18: 09.00 - 09.15 | C18: 58 | D18: 10 | E18: 9 | F18: 56 | G18: 0 | H18: 0 | I18: 7 | J18: 3 | K18: 0 | L18: 0 | M18: 195 | N18: 0 | O18: =SUM(C18:L18,N18) -> 143 | P18: =SUM(C18:N18) -> 338 | R18: 1500-1600 | S18: =SUM(C42:C45) -> 229 | T18: =SUM(D42:D45) -> 37 | U18: =SUM(E42:E45) -> 51 | V18: =SUM(F42:F45) -> 146 | W18: =SUM(G42:G45) -> 3 | X18: =SUM(H42:H45) -> 1 | Y18: =SUM(I42:I45) -> 50 | Z18: =SUM(J42:J45) -> 9 | ... AF18: =SUM(P42:P45) -> 1103
B19: 09.15 - 09.30 | C19: 27 | D19: 0 | E19: 7 | F19: 30 | G19: 0 | H19: 1 | I19: 5 | J19: 3 | K19: 0 | L19: 0 | M19: 140 | N19: 0 | O19: =SUM(C19:L19,N19) -> 73 | P19: =SUM(C19:N19) -> 213 | R19: 1600-1700 | S19: =SUM(C46:C49) -> 201 | T19: =SUM(D46:D49) -> 58 | U19: =SUM(E46:E49) -> 41 | V19: =SUM(F46:F49) -> 144 | W19: =SUM(G46:G49) -> 2 | X19: =SUM(H46:H49) -> 1 | Y19: =SUM(I46:I49) -> 32 | Z19: =SUM(J46:J49) -> 4 | ... AF19: =SUM(P46:P49) -> 1106
B20: 09.30 - 09.45 | C20: 70 | D20: 0 | E20: 12 | F20: 32 | G20: 2 | H20: 0 | I20: 1 | J20: 0 | K20: 0 | L20: 0 | M20: 220 | N20: 0 | O20: =SUM(C20:L20,N20) -> 117 | P20: =SUM(C20:N20) -> 337 | R20: 1700-1800 | S20: =SUM(C50:C53) -> 198 | T20: =SUM(D50:D53) -> 51 | U20: =SUM(E50:E53) -> 21 | V20: =SUM(F50:F53) -> 187 | W20: =SUM(G50:G53) -> 2 | X20: =SUM(H50:H53) -> 2 | Y20: =SUM(I50:I53) -> 35 | Z20: =SUM(J50:J53) -> 7 | ... AF20: =SUM(P50:P53) -> 1229
B21: 09.45 - 10.00 | C21: 32 | D21: 8 | E21: 7 | F21: 37 | G21: 0 | H21: 0 | I21: 5 | J21: 0 | K21: 3 | L21: 0 | M21: 210 | N21: 0 | O21: =SUM(C21:L21,N21) -> 92 | P21: =SUM(C21:N21) -> 302 | R21: 1800-1900 | S21: =SUM(C54:C57) -> 165 | T21: =SUM(D54:D57) -> 56 | U21: =SUM(E54:E57) -> 26 | V21: =SUM(F54:F57) -> 173 | W21: =SUM(G54:G57) -> 12 | X21: =SUM(H54:H57) -> 0 | Y21: =SUM(I54:I57) -> 29 | Z21: =SUM(J54:J57) -> 0 | ... AF21: =SUM(P54:P57) -> 1198
B22: 10.00 - 10.15 | C22: 31 | D22: 25 | E22: 10 | F22: 6 | G22: 5 | H22: 0 | I22: 6 | J22: 0 | K22: 2 | L22: 0 | M22: 265 | N22: 0 | O22: =SUM(C22:L22,N22) -> 85 | P22: =SUM(C22:N22) -> 350 | R22: AM Peak Hr | S22: =MAX(S10:S12) -> 255 | T22: =MAX(T10:T12) -> 30 | U22: =MAX(U10:U12) -> 39 | V22: =MAX(V10:V12) -> 205 | W22: =MAX(W10:W12) -> 2 | X22: =MAX(X10:X12) -> 2 | Y22: =MAX(Y10:Y12) -> 83 | Z22: =MAX(Z10:Z12) -> 8 | ... AF22: =MAX(AF10:AF12) -> 1485
B23: 10.15 - 10.30 | C23: 35 | D23: 27 | E23: 10 | F23: 36 | G23: 0 | H23: 1 | I23: 7 | J23: 1 | K23: 5 | L23: 1 | M23: 215 | N23: 0 | O23: =SUM(C23:L23,N23) -> 123 | P23: =SUM(C23:N23) -> 338 | R23: IP Peak Hr | S23: =MAX(S13:S18) -> 241 | T23: =MAX(T13:T18) -> 155 | U23: =MAX(U13:U18) -> 73 | V23: =MAX(V13:V18) -> 163 | W23: =MAX(W13:W18) -> 7 | X23: =MAX(X13:X18) -> 4 | Y23: =MAX(Y13:Y18) -> 50 | Z23: =MAX(Z13:Z18) -> 9 | ... AF23: =MAX(AF13:AF18) -> 1353
B24: 10.30 - 10.45 | C24: 27 | D24: 18 | E24: 11 | F24: 51 | G24: 2 | H24: 0 | I24: 9 | J24: 0 | K24: 0 | L24: 1 | M24: 185 | N24: 0 | O24: =SUM(C24:L24,N24) -> 119 | P24: =SUM(C24:N24) -> 304 | R24: PM Peak Hr | S24: =MAX(S19:S21) -> 201 | T24: =MAX(T19:T21) -> 58 | U24: =MAX(U19:U21) -> 41 | V24: =MAX(V19:V21) -> 187 | W24: =MAX(W19:W21) -> 12 | X24: =MAX(X19:X21) -> 2 | Y24: =MAX(Y19:Y21) -> 35 | Z24: =MAX(Z19:Z21) -> 7 | ... AF24: =MAX(AF19:AF21) -> 1229
B25: 10.45 - 11.00 | C25: 37 | D25: 43 | E25: 12 | F25: 54 | G25: 0 | H25: 0 | I25: 3 | J25: 0 | K25: 0 | L25: 2 | M25: 210 | N25: 0 | O25: =SUM(C25:L25,N25) -> 151 | P25: =SUM(C25:N25) -> 361 | R25: AM Period | S25: =SUM(S10:S12) -> 504 | T25: =SUM(T10:T12) -> 71 | U25: =SUM(U10:U12) -> 98 | V25: =SUM(V10:V12) -> 535 | W25: =SUM(W10:W12) -> 2 | X25: =SUM(X10:X12) -> 4 | Y25: =SUM(Y10:Y12) -> 120 | Z25: =SUM(Z10:Z12) -> 16 | ... AF25: =SUM(AF10:AF12) -> 3821
B26: 11.00 - 11.15 | C26: 16 | D26: 6 | E26: 5 | F26: 24 | G26: 0 | H26: 1 | I26: 4 | J26: 0 | K26: 0 | L26: 1 | M26: 65 | N26: 0 | O26: =SUM(C26:L26,N26) -> 57 | P26: =SUM(C26:N26) -> 122 | R26: IP Period | S26: =SUM(S13:S18) -> 879 | T26: =SUM(T13:T18) -> 630 | U26: =SUM(U13:U18) -> 289 | V26: =SUM(V13:V18) -> 881 | W26: =SUM(W13:W18) -> 17 | X26: =SUM(X13:X18) -> 8 | Y26: =SUM(Y13:Y18) -> 186 | Z26: =SUM(Z13:Z18) -> 34 | ... AF26: =SUM(AF13:AF18) -> 6706
B27: 11.15 - 11.30 | C27: 63 | D27: 23 | E27: 16 | F27: 45 | G27: 0 | H27: 1 | I27: 10 | J27: 0 | K27: 0 | L27: 0 | M27: 130 | N27: 0 | O27: =SUM(C27:L27,N27) -> 158 | P27: =SUM(C27:N27) -> 288 | R27: PM Period | S27: =SUM(S19:S21) -> 564 | T27: =SUM(T19:T21) -> 165 | U27: =SUM(U19:U21) -> 88 | V27: =SUM(V19:V21) -> 504 | W27: =SUM(W19:W21) -> 16 | X27: =SUM(X19:X21) -> 3 | Y27: =SUM(Y19:Y21) -> 96 | Z27: =SUM(Z19:Z21) -> 11 | ... AF27: =SUM(AF19:AF21) -> 3533
