Workbook

Sheet 23.09 Bukasa-Wakiso
B1: Consultancy services for Preparation of Expressway Development Master Plan (EDMP) for Uganda
B2: MANUAL CLASSIFIED COUNT (MCC)
B3: ROAD NAME: | C3: MCC - C2 - STN0-64- BUKASA-WAKISO ROAD
C5: Date | D5: 23.09.19 | F5: Location | G5: Wakiso Junior Sch. | J5: Surveyor | K5: Farida
C6: Dir. From | D6: Bukasa | F6: Dir. To | G6: Wakiso | J6: Supervisor | K6: Nusurah
B8: Time / Veh Type | R8: SUMMARY TRAFFIC VOLUMES
C9: 1. Car | D9: 2. Station Wagon | E9: 3. Pickups | F9: 4. Minibus, matatu | G9: 5. Medium bus | H9: 6. Large Bus | I9: 7. Light Truck | J9: 8. Medium Truck | K9: 9. Heavy truck | L9: 10. Truck Trailer | M9: 11. Motor cycles | N9: 12. Tractors | O9: Total Excl M/Cycles | P9: Total All | R9: Time | S9: 1. Car | T9: 2. Station Wagon | U9: 3. Pickups | V9: 4. Minibus, matatu | W9: 5. Medium bus | X9: 6. Large Bus | Y9: 7. Light Truck | Z9: 8. Medium Truck | AA9: 9. Heavy truck | AB9: 10. Truck Trailer | AC9: 11. Motorcycles | AD9: 12. Tractors, Graders | AE9: Total Excl M/ Cycles | AF9: Total All
B10: 07.00 - 07.15 | C10: 6 | D10: 5 | E10: 6 | F10: 0 | G10: 1 | H10: 0 | I10: 2 | J10: 0 | K10: 0 | L10: 0 | M10: 19 | N10: 0 | O10: =SUM(C10:L10,N10) -> 20 | P10: =SUM(C10:N10) -> 39 | R10: 0700-0800 | S10: =SUM(C10:C13) -> 24 | T10: =SUM(D10:D13) -> 16 | U10: =SUM(E10:E13) -> 11 | V10: =SUM(F10:F13) -> 3 | W10: =SUM(G10:G13) -> 2 | X10: =SUM(H10:H13) -> 0 | Y10: =SUM(I10:I13) -> 4 | Z10: =SUM(J10:J13) -> 2 | ... AF10: =SUM(P10:P13) -> 156
B11: 07.15 - 07.30 | C11: 4 | D11: 3 | E11: 2 | F11: 0 | G11: 0 | H11: 0 | I11: 0 | J11: 0 | K11: 0 | L11: 0 | M11: 17 | N11: 0 | O11: =SUM(C11:L11,N11) -> 9 | P11: =SUM(C11:N11) -> 26 | R11: 0800-0900 | S11: =SUM(C14:C17) -> 30 | T11: =SUM(D14:D17) -> 17 | U11: =SUM(E14:E17) -> 5 | V11: =SUM(F14:F17) -> 2 | W11: =SUM(G14:G17) -> 1 | X11: =SUM(H14:H17) -> 1 | Y11: =SUM(I14:I17) -> 2 | Z11: =SUM(J14:J17) -> 1 | ... AF11: =SUM(P14:P17) -> 144
B12: 07.30 - 07.45 | C12: 8 | D12: 2 | E12: 1 | F12: 2 | G12: 1 | H12: 0 | I12: 1 | J12: 2 | K12: 0 | L12: 0 | M12: 28 | N12: 0 | O12: =SUM(C12:L12,N12) -> 17 | P12: =SUM(C12:N12) -> 45 | R12: 0900-1000 | S12: =SUM(C18:C21) -> 18 | T12: =SUM(D18:D21) -> 20 | U12: =SUM(E18:E21) -> 1 | V12: =SUM(F18:F21) -> 3 | W12: =SUM(G18:G21) -> 0 | X12: =SUM(H18:H21) -> 0 | Y12: =SUM(I18:I21) -> 5 | Z12: =SUM(J18:J21) -> 0 | ... AF12: =SUM(P18:P21) -> 118
B13: 07.45 - 08.00 | C13: 6 | D13: 6 | E13: 2 | F13: 1 | G13: 0 | H13: 0 | I13: 1 | J13: 0 | K13: 0 | L13: 0 | M13: 30 | N13: 0 | O13: =SUM(C13:L13,N13) -> 16 | P13: =SUM(C13:N13) -> 46 | R13: 1000-1100 | S13: =SUM(C22:C25) -> 22 | T13: =SUM(D22:D25) -> 19 | U13: =SUM(E22:E25) -> 2 | V13: =SUM(F22:F25) -> 0 | W13: =SUM(G22:G25) -> 0 | X13: =SUM(H22:H25) -> 0 | Y13: =SUM(I22:I25) -> 6 | Z13: =SUM(J22:J25) -> 2 | ... AF13: =SUM(P22:P25) -> 110
B14: 08.00 - 08.15 | C14: 3 | D14: 4 | E14: 1 | F14: 0 | G14: 0 | H14: 0 | I14: 1 | J14: 0 | K14: 0 | L14: 0 | M14: 35 | N14: 0 | O14: =SUM(C14:L14,N14) -> 9 | P14: =SUM(C14:N14) -> 44 | R14: 1100-1200 | S14: =SUM(C26:C29) -> 22 | T14: =SUM(D26:D29) -> 13 | U14: =SUM(E26:E29) -> 2 | V14: =SUM(F26:F29) -> 3 | W14: =SUM(G26:G29) -> 0 | X14: =SUM(H26:H29) -> 0 | Y14: =SUM(I26:I29) -> 11 | Z14: =SUM(J26:J29) -> 0 | ... AF14: =SUM(P26:P29) -> 115
B15: 08.15 - 08.30 | C15: 4 | D15: 4 | E15: 2 | F15: 1 | G15: 0 | H15: 0 | I15: 0 | J15: 1 | K15: 0 | L15: 0 | M15: 13 | N15: 0 | O15: =SUM(C15:L15,N15) -> 12 | P15: =SUM(C15:N15) -> 25 | R15: 1200-1300 | S15: =SUM(C30:C33) -> 17 | T15: =SUM(D30:D33) -> 14 | U15: =SUM(E30:E33) -> 7 | V15: =SUM(F30:F33) -> 1 | W15: =SUM(G30:G33) -> 0 | X15: =SUM(H30:H33) -> 0 | Y15: =SUM(I30:I33) -> 5 | Z15: =SUM(J30:J33) -> 2 | ... AF15: =SUM(P30:P33) -> 105
B16: 08.30 - 08.45 | C16: 15 | D16: 4 | E16: 1 | F16: 0 | G16: 0 | H16: 0 | I16: 1 | J16: 0 | K16: 0 | L16: 0 | M16: 2 | N16: 0 | O16: =SUM(C16:L16,N16) -> 21 | P16: =SUM(C16:N16) -> 23 | R16: 1300-1400 | S16: =SUM(C34:C37) -> 16 | T16: =SUM(D34:D37) -> 11 | U16: =SUM(E34:E37) -> 6 | V16: =SUM(F34:F37) -> 0 | W16: =SUM(G34:G37) -> 0 | X16: =SUM(H34:H37) -> 0 | Y16: =SUM(I34:I37) -> 3 | Z16: =SUM(J34:J37) -> 2 | ... AF16: =SUM(P34:P37) -> 105
B17: 08.45 - 9.00 | C17: 8 | D17: 5 | E17: 1 | F17: 1 | G17: 1 | H17: 1 | I17: 0 | J17: 0 | K17: 0 | L17: 0 | M17: 35 | N17: 0 | O17: =SUM(C17:L17,N17) -> 17 | P17: =SUM(C17:N17) -> 52 | R17: 1400-1500 | S17: =SUM(C38:C41) -> 12 | T17: =SUM(D38:D41) -> 8 | U17: =SUM(E38:E41) -> 4 | V17: =SUM(F38:F41) -> 2 | W17: =SUM(G38:G41) -> 0 | X17: =SUM(H38:H41) -> 0 | Y17: =SUM(I38:I41) -> 9 | Z17: =SUM(J38:J41) -> 3 | ... AF17: =SUM(P38:P41) -> 98
B18: 09.00 - 09.15 | C18: 6 | D18: 6 | E18: 0 | F18: 1 | G18: 0 | H18: 0 | I18: 2 | J18: 0 | K18: 0 | L18: 0 | M18: 18 | N18: 0 | O18: =SUM(C18:L18,N18) -> 15 | P18: =SUM(C18:N18) -> 33 | R18: 1500-1600 | S18: =SUM(C42:C45) -> 17 | T18: =SUM(D42:D45) -> 10 | U18: =SUM(E42:E45) -> 5 | V18: =SUM(F42:F45) -> 1 | W18: =SUM(G42:G45) -> 0 | X18: =SUM(H42:H45) -> 0 | Y18: =SUM(I42:I45) -> 6 | Z18: =SUM(J42:J45) -> 1 | ... AF18: =SUM(P42:P45) -> 71
B19: 09.15 - 09.30 | C19: 6 | D19: 3 | E19: 0 | F19: 0 | G19: 0 | H19: 0 | I19: 2 | J19: 0 | K19: 0 | L19: 0 | M19: 18 | N19: 0 | O19: =SUM(C19:L19,N19) -> 11 | P19: =SUM(C19:N19) -> 29 | R19: 1600-1700 | S19: =SUM(C46:C49) -> 11 | T19: =SUM(D46:D49) -> 10 | U19: =SUM(E46:E49) -> 2 | V19: =SUM(F46:F49) -> 14 | W19: =SUM(G46:G49) -> 1 | X19: =SUM(H46:H49) -> 0 | Y19: =SUM(I46:I49) -> 5 | Z19: =SUM(J46:J49) -> 3 | ... AF19: =SUM(P46:P49) -> 113
B20: 09.30 - 09.45 | C20: 2 | D20: 3 | E20: 0 | F20: 1 | G20: 0 | H20: 0 | I20: 1 | J20: 0 | K20: 0 | L20: 0 | M20: 17 | N20: 0 | O20: =SUM(C20:L20,N20) -> 7 | P20: =SUM(C20:N20) -> 24 | R20: 1700-1800 | S20: =SUM(C50:C53) -> 15 | T20: =SUM(D50:D53) -> 13 | U20: =SUM(E50:E53) -> 4 | V20: =SUM(F50:F53) -> 6 | W20: =SUM(G50:G53) -> 3 | X20: =SUM(H50:H53) -> 0 | Y20: =SUM(I50:I53) -> 10 | Z20: =SUM(J50:J53) -> 0 | ... AF20: =SUM(P50:P53) -> 115
B21: 09.45 - 10.00 | C21: 4 | D21: 8 | E21: 1 | F21: 1 | G21: 0 | H21: 0 | I21: 0 | J21: 0 | K21: 0 | L21: 0 | M21: 18 | N21: 0 | O21: =SUM(C21:L21,N21) -> 14 | P21: =SUM(C21:N21) -> 32 | R21: 1800-1900 | S21: =SUM(C54:C57) -> 14 | T21: =SUM(D54:D57) -> 18 | U21: =SUM(E54:E57) -> 3 | V21: =SUM(F54:F57) -> 8 | W21: =SUM(G54:G57) -> 1 | X21: =SUM(H54:H57) -> 3 | Y21: =SUM(I54:I57) -> 8 | Z21: =SUM(J54:J57) -> 1 | ... AF21: =SUM(P54:P57) -> 102
B22: 10.00 - 10.15 | C22: 3 | D22: 5 | E22: 0 | F22: 0 | G22: 0 | H22: 0 | I22: 2 | J22: 0 | K22: 0 | L22: 0 | M22: 13 | N22: 0 | O22: =SUM(C22:L22,N22) -> 10 | P22: =SUM(C22:N22) -> 23 | R22: AM Peak Hr | S22: =MAX(S10:S12) -> 30 | T22: =MAX(T10:T12) -> 20 | U22: =MAX(U10:U12) -> 11 | V22: =MAX(V10:V12) -> 3 | W22: =MAX(W10:W12) -> 2 | X22: =MAX(X10:X12) -> 1 | Y22: =MAX(Y10:Y12) -> 5 | Z22: =MAX(Z10:Z12) -> 2 | ... AF22: =MAX(AF10:AF12) -> 156
B23: 10.15 - 10.30 | C23: 6 | D23: 0 | E23: 0 | F23: 0 | G23: 0 | H23: 0 | I23: 0 | J23: 1 | K23: 0 | L23: 0 | M23: 13 | N23: 0 | O23: =SUM(C23:L23,N23) -> 7 | P23: =SUM(C23:N23) -> 20 | R23: IP Peak Hr | S23: =MAX(S13:S18) -> 22 | T23: =MAX(T13:T18) -> 19 | U23: =MAX(U13:U18) -> 7 | V23: =MAX(V13:V18) -> 3 | W23: =MAX(W13:W18) -> 0 | X23: =MAX(X13:X18) -> 0 | Y23: =MAX(Y13:Y18) -> 11 | Z23: =MAX(Z13:Z18) -> 3 | ... AF23: =MAX(AF13:AF18) -> 115
B24: 10.30 - 10.45 | C24: 8 | D24: 8 | E24: 1 | F24: 0 | G24: 0 | H24: 0 | I24: 3 | J24: 1 | K24: 0 | L24: 0 | M24: 20 | N24: 0 | O24: =SUM(C24:L24,N24) -> 21 | P24: =SUM(C24:N24) -> 41 | R24: PM Peak Hr | S24: =MAX(S19:S21) -> 15 | T24: =MAX(T19:T21) -> 18 | U24: =MAX(U19:U21) -> 4 | V24: =MAX(V19:V21) -> 14 | W24: =MAX(W19:W21) -> 3 | X24: =MAX(X19:X21) -> 3 | Y24: =MAX(Y19:Y21) -> 10 | Z24: =MAX(Z19:Z21) -> 3 | ... AF24: =MAX(AF19:AF21) -> 115
B25: 10.45 - 11.00 | C25: 5 | D25: 6 | E25: 1 | F25: 0 | G25: 0 | H25: 0 | I25: 1 | J25: 0 | K25: 0 | L25: 0 | M25: 13 | N25: 0 | O25: =SUM(C25:L25,N25) -> 13 | P25: =SUM(C25:N25) -> 26 | R25: AM Period | S25: =SUM(S10:S12) -> 72 | T25: =SUM(T10:T12) -> 53 | U25: =SUM(U10:U12) -> 17 | V25: =SUM(V10:V12) -> 8 | W25: =SUM(W10:W12) -> 3 | X25: =SUM(X10:X12) -> 1 | Y25: =SUM(Y10:Y12) -> 11 | Z25: =SUM(Z10:Z12) -> 3 | ... AF25: =SUM(AF10:AF12) -> 418
B26: 11.00 - 11.15 | C26: 6 | D26: 3 | E26: 0 | F26: 2 | G26: 0 | H26: 0 | I26: 2 | J26: 0 | K26: 0 | L26: 0 | M26: 9 | N26: 0 | O26: =SUM(C26:L26,N26) -> 13 | P26: =SUM(C26:N26) -> 22 | R26: IP Period | S26: =SUM(S13:S18) -> 106 | T26: =SUM(T13:T18) -> 75 | U26: =SUM(U13:U18) -> 26 | V26: =SUM(V13:V18) -> 7 | W26: =SUM(W13:W18) -> 0 | X26: =SUM(X13:X18) -> 0 | Y26: =SUM(Y13:Y18) -> 40 | Z26: =SUM(Z13:Z18) -> 10 | ... AF26: =SUM(AF13:AF18) -> 604
B27: 11.15 - 11.30 | C27: 7 | D27: 1 | E27: 2 | F27: 0 | G27: 0 | H27: 0 | I27: 4 | J27: 0 | K27: 0 | L27: 0 | M27: 24 | N27: 0 | O27: =SUM(C27:L27,N27) -> 14 | P27: =SUM(C27:N27) -> 38 | R27: PM Period | S27: =SUM(S19:S21) -> 40 | T27: =SUM(T19:T21) -> 41 | U27: =SUM(U19:U21) -> 9 | V27: =SUM(V19:V21) -> 28 | W27: =SUM(W19:W21) -> 5 | X27: =SUM(X19:X21) -> 3 | Y27: =SUM(Y19:Y21) -> 23 | Z27: =SUM(Z19:Z21) -> 4 | ... AF27: =SUM(AF19:AF21) -> 330
B28: 11.30 - 11.45 | C28: 5 | D28: 3 | E28: 0 | F28: 0 | G28: 0 | H28: 0 | I28: 2 | J28: 0 | K28: 0 | L28: 0 | M28: 18 | N28: 0 | O28: =SUM(C28:L28,N28) -> 10 | P28: =SUM(C28:N28) -> 28 | R28: 12 Hours | S28: =SUM(S10:S21) -> 218 | T28: =SUM(T10:T21) -> 169 | U28: =SUM(U10:U21) -> 52 | V28: =SUM(V10:V21) -> 43 | W28: =SUM(W10:W21) -> 8 | X28: =SUM(X10:X21) -> 4 | Y28: =SUM(Y10:Y21) -> 74 | Z28: =SUM(Z10:Z21) -> 17 | ... AF28: =SUM(AF10:AF21) -> 1352
B29: 11.45 - 12.00 | C29: 4 | D29: 6 | E29: 0 | F29: 1 | G29: 0 | H29: 0 | I29: 3 | J29: 0 | K29: 0 | L29: 0 | M29: 13 | N29: 0 | O29: =SUM(C29:L29,N29) -> 14 | P29: =SUM(C29:N29) -> 27
B30: 12.00 - 12.15 | C30: 2 | D30: 3 | E30: 3 | F30: 1 | G30: 0 | H30: 0 | I30: 1 | J30: 1 | K30: 0 | L30: 0 | M30: 11 | N30: 0 | O30: =SUM(C30:L30,N30) -> 11 | P30: =SUM(C30:N30) -> 22
B31: 12.15 - 12.30 | C31: 6 | D31: 4 | E31: 3 | F31: 0 | G31: 0 | H31: 0 | I31: 0 | J31: 0 | K31: 0 | L31: 0 | M31: 22 | N31: 0 | O31: =SUM(C31:L31,N31) -> 13 | P31: =SUM(C31:N31) -> 35
B32: 12.30 - 12.45 | C32: 5 | D32: 4 | E32: 0 | F32: 0 | G32: 0 | H32: 0 | I32: 3 | J32: 1 | K32: 0 | L32: 0 | M32: 14 | N32: 0 | O32: =SUM(C32:L32,N32) -> 13 | P32: =SUM(C32:N32) -> 27
B33: 12.45 - 13.00 | C33: 4 | D33: 3 | E33: 1 | F33: 0 | G33: 0 | H33: 0 | I33: 1 | J33: 0 | K33: 0 | L33: 0 | M33: 12 | N33: 0 | O33: =SUM(C33:L33,N33) -> 9 | P33: =SUM(C33:N33) -> 21
B34: 13.00 - 13.15 | C34: 3 | D34: 2 | E34: 1 | F34: 0 | G34: 0 | H34: 0 | I34: 0 | J34: 0 | K34: 0 | L34: 0 | M34: 15 | N34: 0 | O34: =SUM(C34:L34,N34) -> 6 | P34: =SUM(C34:N34) -> 21
B35: 13.15 - 13.30 | C35: 3 | D35: 3 | E35: 2 | F35: 0 | G35: 0 | H35: 0 | I35: 2 | J35: 0 | K35: 0 | L35: 0 | M35: 13 | N35: 0 | O35: =SUM(C35:L35,N35) -> 10 | P35: =SUM(C35:N35) -> 23
B36: 13.30 - 13.45 | C36: 6 | D36: 3 | E36: 1 | F36: 0 | G36: 0 | H36: 0 | I36: 1 | J36: 2 | K36: 0 | L36: 0 | M36: 24 | N36: 0 | O36: =SUM(C36:L36,N36) -> 13 | P36: =SUM(C36:N36) -> 37
B37: 13.45 - 14.00 | C37: 4 | D37: 3 | E37: 2 | F37: 0 | G37: 0 | H37: 0 | I37: 0 | J37: 0 | K37: 0 | L37: 0 | M37: 15 | N37: 0 | O37: =SUM(C37:L37,N37) -> 9 | P37: =SUM(C37:N37) -> 24
B38: 14.00 - 14.15 | C38: 5 | D38: 3 | E38: 0 | F38: 0 | G38: 0 | H38: 0 | I38: 3 | J38: 1 | K38: 0 | L38: 0 | M38: 23 | N38: 0 | O38: =SUM(C38:L38,N38) -> 12 | P38: =SUM(C38:N38) -> 35
B39: 14.15 - 14.30 | C39: 3 | D39: 3 | E39: 0 | F39: 1 | G39: 0 | H39: 0 | I39: 1 | J39: 0 | K39: 0 | L39: 0 | M39: 10 | N39: 0 | O39: =SUM(C39:L39,N39) -> 8 | P39: =SUM(C39:N39) -> 18
B40: 14.30 - 14.45 | C40: 4 | D40: 0 | E40: 1 | F40: 1 | G40: 0 | H40: 0 | I40: 1 | J40: 2 | K40: 0 | L40: 0 | M40: 16 | N40: 0 | O40: =SUM(C40:L40,N40) -> 9 | P40: =SUM(C40:N40) -> 25
... B57: 18.45 - 19.00 | C57: 3 | D57: 5 | E57: 1 | F57: 1 | G57: 0 | H57: 0 | I57: 1 | J57: 0 | K57: 0 | L57: 0 | M57: 14 | N57: 0 | O57: =SUM(C57:L57,N57) -> 11 | P57: =SUM(C57:N57) -> 25
B58: Totals | C58: =SUM(C10:C57) -> 218 | D58: =SUM(D10:D57) -> 169 | E58: =SUM(E10:E57) -> 52 | F58: =SUM(F10:F57) -> 43 | G58: =SUM(G10:G57) -> 8 | H58: =SUM(H10:H57) -> 4 | I58: =SUM(I10:I57) -> 74 | J58: =SUM(J10:J57) -> 17 | ... P58: =SUM(P10:P57) -> 1352
...

Sheet 23.09 Wakiso-Bukasa
B1: Consultancy services for Preparation of Expressway Development Master Plan (EDMP) for Uganda
B2: MANUAL CLASSIFIED COUNT (MCC)
B3: ROAD NAME: | C3: ='23.09 Bukasa-Wakiso'!C3:G3 -> MCC - C2 - STN0-64- BUKASA-WAKISO ROAD
C5: Date | D5: ='23.09 Bukasa-Wakiso'!D5 -> 23.09.19 | F5: Location | G5: ='23.09 Bukasa-Wakiso'!G5:H5 -> Wakiso Junior Sch. | J5: Surveyor | K5: ='23.09 Bukasa-Wakiso'!K5:L5 -> Farida
C6: Dir. From | D6: Wakiso | F6: Dir. To | G6: Bukasa | J6: Supervisor | K6: ='23.09 Bukasa-Wakiso'!K6:L6 -> Nusurah
B8: Time / Veh Type | R8: SUMMARY TRAFFIC VOLUMES
C9: 1. Car | D9: 2. Station Wagon | E9: 3. Pickups | F9: 4. Minibus, matatu | G9: 5. Medium bus | H9: 6. Large Bus | I9: 7. Light Truck | J9: 8. Medium Truck | K9: 9. Heavy truck | L9: 10. Truck Trailer | M9: 11. Motor cycles | N9: 12. Tractors | O9: Total Excl M/Cycles | P9: Total All | R9: Time | S9: 1. Car | T9: 2. Station Wagon | U9: 3. Pickups | V9: 4. Minibus, matatu | W9: 5. Medium bus | X9: 6. Large Bus | Y9: 7. Light Truck | Z9: 8. Medium Truck | AA9: 9. Heavy truck | AB9: 10. Truck Trailer | AC9: 11. Motorcycles | AD9: 12. Tractors, Graders | AE9: Total Excl M/ Cycles | AF9: Total All
B10: 07.00 - 07.15 | C10: 9 | D10: 1 | E10: 1 | F10: 1 | G10: 1 | H10: 0 | I10: 2 | J10: 2 | K10: 0 | L10: 0 | M10: 25 | N10: 0 | O10: =SUM(C10:L10,N10) -> 17 | P10: =SUM(C10:N10) -> 42 | R10: 0700-0800 | S10: =SUM(C10:C13) -> 42 | T10: =SUM(D10:D13) -> 5 | U10: =SUM(E10:E13) -> 9 | V10: =SUM(F10:F13) -> 11 | W10: =SUM(G10:G13) -> 2 | X10: =SUM(H10:H13) -> 0 | Y10: =SUM(I10:I13) -> 11 | Z10: =SUM(J10:J13) -> 2 | ... AF10: =SUM(P10:P13) -> 188
B11: 07.15 - 07.30 | C11: 10 | D11: 0 | E11: 3 | F11: 4 | G11: 0 | H11: 0 | I11: 4 | J11: 0 | K11: 1 | L11: 0 | M11: 24 | N11: 0 | O11: =SUM(C11:L11,N11) -> 22 | P11: =SUM(C11:N11) -> 46 | R11: 0800-0900 | S11: =SUM(C14:C17) -> 28 | T11: =SUM(D14:D17) -> 4 | U11: =SUM(E14:E17) -> 7 | V11: =SUM(F14:F17) -> 9 | W11: =SUM(G14:G17) -> 0 | X11: =SUM(H14:H17) -> 0 | Y11: =SUM(I14:I17) -> 3 | Z11: =SUM(J14:J17) -> 7 | ... AF11: =SUM(P14:P17) -> 146
B12: 07.30 - 07.45 | C12: 10 | D12: 1 | E12: 2 | F12: 4 | G12: 1 | H12: 0 | I12: 2 | J12: 0 | K12: 0 | L12: 0 | M12: 27 | N12: 0 | O12: =SUM(C12:L12,N12) -> 20 | P12: =SUM(C12:N12) -> 47 | R12: 0900-1000 | S12: =SUM(C18:C21) -> 17 | T12: =SUM(D18:D21) -> 5 | U12: =SUM(E18:E21) -> 8 | V12: =SUM(F18:F21) -> 2 | W12: =SUM(G18:G21) -> 2 | X12: =SUM(H18:H21) -> 0 | Y12: =SUM(I18:I21) -> 7 | Z12: =SUM(J18:J21) -> 1 | ... AF12: =SUM(P18:P21) -> 114
B13: 07.45 - 08.00 | C13: 13 | D13: 3 | E13: 3 | F13: 2 | G13: 0 | H13: 0 | I13: 3 | J13: 0 | K13: 0 | L13: 0 | M13: 29 | N13: 0 | O13: =SUM(C13:L13,N13) -> 24 | P13: =SUM(C13:N13) -> 53 | R13: 1000-1100 | S13: =SUM(C22:C25) -> 16 | T13: =SUM(D22:D25) -> 6 | U13: =SUM(E22:E25) -> 4 | V13: =SUM(F22:F25) -> 7 | W13: =SUM(G22:G25) -> 0 | X13: =SUM(H22:H25) -> 0 | Y13: =SUM(I22:I25) -> 6 | Z13: =SUM(J22:J25) -> 5 | ... AF13: =SUM(P22:P25) -> 77
B14: 08.00 - 08.15 | C14: 12 | D14: 0 | E14: 3 | F14: 0 | G14: 0 | H14: 0 | I14: 0 | J14: 3 | K14: 0 | L14: 0 | M14: 22 | N14: 0 | O14: =SUM(C14:L14,N14) -> 18 | P14: =SUM(C14:N14) -> 40 | R14: 1100-1200 | S14: =SUM(C26:C29) -> 17 | T14: =SUM(D26:D29) -> 8 | U14: =SUM(E26:E29) -> 9 | V14: =SUM(F26:F29) -> 5 | W14: =SUM(G26:G29) -> 0 | X14: =SUM(H26:H29) -> 0 | Y14: =SUM(I26:I29) -> 6 | Z14: =SUM(J26:J29) -> 1 | ... AF14: =SUM(P26:P29) -> 122
B15: 08.15 - 08.30 | C15: 5 | D15: 1 | E15: 1 | F15: 2 | G15: 0 | H15: 0 | I15: 1 | J15: 2 | K15: 0 | L15: 0 | M15: 19 | N15: 0 | O15: =SUM(C15:L15,N15) -> 12 | P15: =SUM(C15:N15) -> 31 | R15: 1200-1300 | S15: =SUM(C30:C33) -> 25 | T15: =SUM(D30:D33) -> 4 | U15: =SUM(E30:E33) -> 2 | V15: =SUM(F30:F33) -> 4 | W15: =SUM(G30:G33) -> 0 | X15: =SUM(H30:H33) -> 0 | Y15: =SUM(I30:I33) -> 2 | Z15: =SUM(J30:J33) -> 2 | ... AF15: =SUM(P30:P33) -> 129
B16: 08.30 - 08.45 | C16: 7 | D16: 2 | E16: 1 | F16: 3 | G16: 0 | H16: 0 | I16: 2 | J16: 0 | K16: 0 | L16: 0 | M16: 28 | N16: 0 | O16: =SUM(C16:L16,N16) -> 15 | P16: =SUM(C16:N16) -> 43 | R16: 1300-1400 | S16: =SUM(C34:C37) -> 18 | T16: =SUM(D34:D37) -> 8 | U16: =SUM(E34:E37) -> 8 | V16: =SUM(F34:F37) -> 2 | W16: =SUM(G34:G37) -> 1 | X16: =SUM(H34:H37) -> 0 | Y16: =SUM(I34:I37) -> 5 | Z16: =SUM(J34:J37) -> 3 | ... AF16: =SUM(P34:P37) -> 115
B17: 08.45 - 9.00 | C17: 4 | D17: 1 | E17: 2 | F17: 4 | G17: 0 | H17: 0 | I17: 0 | J17: 2 | K17: 0 | L17: 0 | M17: 19 | N17: 0 | O17: =SUM(C17:L17,N17) -> 13 | P17: =SUM(C17:N17) -> 32 | R17: 1400-1500 | S17: =SUM(C38:C41) -> 14 | T17: =SUM(D38:D41) -> 4 | U17: =SUM(E38:E41) -> 3 | V17: =SUM(F38:F41) -> 5 | W17: =SUM(G38:G41) -> 0 | X17: =SUM(H38:H41) -> 0 | Y17: =SUM(I38:I41) -> 5 | Z17: =SUM(J38:J41) -> 2 | ... AF17: =SUM(P38:P41) -> 103
B18: 09.00 - 09.15 | C18: 3 | D18: 0 | E18: 3 | F18: 2 | G18: 0 | H18: 0 | I18: 1 | J18: 0 | K18: 0 | L18: 0 | M18: 18 | N18: 0 | O18: =SUM(C18:L18,N18) -> 9 | P18: =SUM(C18:N18) -> 27 | R18: 1500-1600 | S18: =SUM(C42:C45) -> 22 | T18: =SUM(D42:D45) -> 4 | U18: =SUM(E42:E45) -> 10 | V18: =SUM(F42:F45) -> 0 | W18: =SUM(G42:G45) -> 0 | X18: =SUM(H42:H45) -> 0 | Y18: =SUM(I42:I45) -> 7 | Z18: =SUM(J42:J45) -> 4 | ... AF18: =SUM(P42:P45) -> 139
B19: 09.15 - 09.30 | C19: 5 | D19: 1 | E19: 2 | F19: 0 | G19: 0 | H19: 0 | I19: 2 | J19: 0 | K19: 0 | L19: 0 | M19: 24 | N19: 0 | O19: =SUM(C19:L19,N19) -> 10 | P19: =SUM(C19:N19) -> 34 | R19: 1600-1700 | S19: =SUM(C46:C49) -> 19 | T19: =SUM(D46:D49) -> 5 | U19: =SUM(E46:E49) -> 4 | V19: =SUM(F46:F49) -> 4 | W19: =SUM(G46:G49) -> 0 | X19: =SUM(H46:H49) -> 0 | Y19: =SUM(I46:I49) -> 4 | Z19: =SUM(J46:J49) -> 1 | ... AF19: =SUM(P46:P49) -> 153
B20: 09.30 - 09.45 | C20: 4 | D20: 2 | E20: 3 | F20: 0 | G20: 2 | H20: 0 | I20: 4 | J20: 1 | K20: 1 | L20: 0 | M20: 15 | N20: 0 | O20: =SUM(C20:L20,N20) -> 17 | P20: =SUM(C20:N20) -> 32 | R20: 1700-1800 | S20: =SUM(C50:C53) -> 22 | T20: =SUM(D50:D53) -> 5 | U20: =SUM(E50:E53) -> 4 | V20: =SUM(F50:F53) -> 1 | W20: =SUM(G50:G53) -> 0 | X20: =SUM(H50:H53) -> 0 | Y20: =SUM(I50:I53) -> 0 | Z20: =SUM(J50:J53) -> 1 | ... AF20: =SUM(P50:P53) -> 135
B21: 09.45 - 10.00 | C21: 5 | D21: 2 | E21: 0 | F21: 0 | G21: 0 | H21: 0 | I21: 0 | J21: 0 | K21: 0 | L21: 0 | M21: 14 | N21: 0 | O21: =SUM(C21:L21,N21) -> 7 | P21: =SUM(C21:N21) -> 21 | R21: 1800-1900 | S21: =SUM(C54:C57) -> 28 | T21: =SUM(D54:D57) -> 3 | U21: =SUM(E54:E57) -> 5 | V21: =SUM(F54:F57) -> 5 | W21: =SUM(G54:G57) -> 0 | X21: =SUM(H54:H57) -> 0 | Y21: =SUM(I54:I57) -> 1 | Z21: =SUM(J54:J57) -> 3 | ... AF21: =SUM(P54:P57) -> 127
B22: 10.00 - 10.15 | C22: 4 | D22: 2 | E22: 0 | F22: 3 | G22: 0 | H22: 0 | I22: 3 | J22: 2 | K22: 1 | L22: 0 | M22: 14 | N22: 0 | O22: =SUM(C22:L22,N22) -> 15 | P22: =SUM(C22:N22) -> 29 | R22: AM Peak Hr | S22: =MAX(S10:S12) -> 42 | T22: =MAX(T10:T12) -> 5 | U22: =MAX(U10:U12) -> 9 | V22: =MAX(V10:V12) -> 11 | W22: =MAX(W10:W12) -> 2 | X22: =MAX(X10:X12) -> 0 | Y22: =MAX(Y10:Y12) -> 11 | Z22: =MAX(Z10:Z12) -> 7 | ... AF22: =MAX(AF10:AF12) -> 188
B23: 10.15 - 10.30 | C23: 6 | D23: 2 | E23: 2 | F23: 0 | G23: 0 | H23: 0 | I23: 1 | J23: 2 | K23: 0 | L23: 0 | M23: 5 | N23: 0 | O23: =SUM(C23:L23,N23) -> 13 | P23: =SUM(C23:N23) -> 18 | R23: IP Peak Hr | S23: =MAX(S13:S18) -> 25 | T23: =MAX(T13:T18) -> 8 | U23: =MAX(U13:U18) -> 10 | V23: =MAX(V13:V18) -> 7 | W23: =MAX(W13:W18) -> 1 | X23: =MAX(X13:X18) -> 0 | Y23: =MAX(Y13:Y18) -> 7 | Z23: =MAX(Z13:Z18) -> 5 | ... AF23: =MAX(AF13:AF18) -> 139
B24: 10.30 - 10.45 | C24: 4 | D24: 0 | E24: 1 | F24: 2 | G24: 0 | H24: 0 | I24: 0 | J24: 1 | K24: 0 | L24: 0 | M24: 4 | N24: 0 | O24: =SUM(C24:L24,N24) -> 8 | P24: =SUM(C24:N24) -> 12 | R24: PM Peak Hr | S24: =MAX(S19:S21) -> 28 | T24: =MAX(T19:T21) -> 5 | U24: =MAX(U19:U21) -> 5 | V24: =MAX(V19:V21) -> 5 | W24: =MAX(W19:W21) -> 0 | X24: =MAX(X19:X21) -> 0 | Y24: =MAX(Y19:Y21) -> 4 | Z24: =MAX(Z19:Z21) -> 3 | ... AF24: =MAX(AF19:AF21) -> 153
B25: 10.45 - 11.00 | C25: 2 | D25: 2 | E25: 1 | F25: 2 | G25: 0 | H25: 0 | I25: 2 | J25: 0 | K25: 0 | L25: 0 | M25: 9 | N25: 0 | O25: =SUM(C25:L25,N25) -> 9 | P25: =SUM(C25:N25) -> 18 | R25: AM Period | S25: =SUM(S10:S12) -> 87 | T25: =SUM(T10:T12) -> 14 | U25: =SUM(U10:U12) -> 24 | V25: =SUM(V10:V12) -> 22 | W25: =SUM(W10:W12) -> 4 | X25: =SUM(X10:X12) -> 0 | Y25: =SUM(Y10:Y12) -> 21 | Z25: =SUM(Z10:Z12) -> 10 | ... AF25: =SUM(AF10:AF12) -> 448
B26: 11.00 - 11.15 | C26: 1 | D26: 1 | E26: 2 | F26: 3 | G26: 0 | H26: 0 | I26: 1 | J26: 0 | K26: 1 | L26: 0 | M26: 12 | N26: 0 | O26: =SUM(C26:L26,N26) -> 9 | P26: =SUM(C26:N26) -> 21 | R26: IP Period | S26: =SUM(S13:S18) -> 112 | T26: =SUM(T13:T18) -> 34 | U26: =SUM(U13:U18) -> 36 | V26: =SUM(V13:V18) -> 23 | W26: =SUM(W13:W18) -> 1 | X26: =SUM(X13:X18) -> 0 | Y26: =SUM(Y13:Y18) -> 31 | Z26: =SUM(Z13:Z18) -> 17 | ... AF26: =SUM(AF13:AF18) -> 685
B27: 11.15 - 11.30 | C27: 6 | D27: 4 | E27: 0 | F27: 0 | G27: 0 | H27: 0 | I27: 1 | J27: 1 | K27: 1 | L27: 0 | M27: 25 | N27: 0 | O27: =SUM(C27:L27,N27) -> 13 | P27: =SUM(C27:N27) -> 38 | R27: PM Period | S27: =SUM(S19:S21) -> 69 | T27: =SUM(T19:T21) -> 13 | U27: =SUM(U19:U21) -> 13 | V27: =SUM(V19:V21) -> 10 | W27: =SUM(W19:W21) -> 0 | X27: =SUM(X19:X21) -> 0 | Y27: =SUM(Y19:Y21) -> 5 | Z27: =SUM(Z19:Z21) -> 5 | ... AF27: =SUM(AF19:AF21) -> 415
B28: 11.30 - 11.45 | C28: 8 | D28: 1 | E28: 3 | F28: 1 | G28: 0 | H28: 0 | I28: 2 | J28: 0 | K28: 0 | L28: 0 | M28: 15 | N28: 0 | O28: =SUM(C28:L28,N28) -> 15 | P28: =SUM(C28:N28) -> 30 | R28: 12 Hours | S28: =SUM(S10:S21) -> 268 | T28: =SUM(T10:T21) -> 61 | U28: =SUM(U10:U21) -> 73 | V28: =SUM(V10:V21) -> 55 | W28: =SUM(W10:W21) -> 5 | X28: =SUM(X10:X21) -> 0 | Y28: =SUM(Y10:Y21) -> 57 | Z28: =SUM(Z10:Z21) -> 32 | ... AF28: =SUM(AF10:AF21) -> 1548
B29: 11.45 - 12.00 | C29: 2 | D29: 2 | E29: 4 | F29: 1 | G29: 0 | H29: 0 | I29: 2 | J29: 0 | K29: 0 | L29: 0 | M29: 22 | N29: 0 | O29: =SUM(C29:L29,N29) -> 11 | P29: =SUM(C29:N29) -> 33
B30: 12.00 - 12.15 | C30: 7 | D30: 0 | E30: 1 | F30: 0 | G30: 0 | H30: 0 | I30: 0 | J30: 1 | K30: 0 | L30: 0 | M30: 16 | N30: 0 | O30: =SUM(C30:L30,N30) -> 9 | P30: =SUM(C30:N30) -> 25
B31: 12.15 - 12.30 | C31: 8 | D31: 1 | E31: 1 | F31: 1 | G31: 0 | H31: 0 | I31: 2 | J31: 1 | K31: 0 | L31: 0 | M31: 22 | N31: 0 | O31: =SUM(C31:L31,N31) -> 14 | P31: =SUM(C31:N31) -> 36
B32: 12.30 - 12.45 | C32: 5 | D32: 2 | E32: 0 | F32: 1 | G32: 0 | H32: 0 | I32: 0 | J32: 0 | K32: 0 | L32: 0 | M32: 18 | N32: 0 | O32: =SUM(C32:L32,N32) -> 8 | P32: =SUM(C32:N32) -> 26
B33: 12.45 - 13.00 | C33: 5 | D33: 1 | E33: 0 | F33: 2 | G33: 0 | H33: 0 | I33: 0 | J33: 0 | K33: 0 | L33: 0 | M33: 34 | N33: 0 | O33: =SUM(C33:L33,N33) -> 8 | P33: =SUM(C33:N33) -> 42
B34: 13.00 - 13.15 | C34: 6 | D34: 2 | E34: 0 | F34: 2 | G34: 1 | H34: 0 | I34: 0 | J34: 1 | K34: 0 | L34: 0 | M34: 16 | N34: 0 | O34: =SUM(C34:L34,N34) -> 12 | P34: =SUM(C34:N34) -> 28
B35: 13.15 - 13.30 | C35: 2 | D35: 1 | E35: 2 | F35: 0 | G35: 0 | H35: 0 | I35: 2 | J35: 1 | K35: 0 | L35: 0 | M35: 13 | N35: 0 | O35: =SUM(C35:L35,N35) -> 8 | P35: =SUM(C35:N35) -> 21
B36: 13.30 - 13.45 | C36: 5 | D36: 3 | E36: 2 | F36: 0 | G36: 0 | H36: 0 | I36: 2 | J36: 1 | K36: 0 | L36: 0 | M36: 22 | N36: 0 | O36: =SUM(C36:L36,N36) -> 13 | P36: =SUM(C36:N36) -> 35
B37: 13.45 - 14.00 | C37: 5 | D37: 2 | E37: 4 | F37: 0 | G37: 0 | H37: 0 | I37: 1 | J37: 0 | K37: 0 | L37: 0 | M37: 19 | N37: 0 | O37: =SUM(C37:L37,N37) -> 12 | P37: =SUM(C37:N37) -> 31
B38: 14.00 - 14.15 | C38: 1 | D38: 2 | E38: 2 | F38: 2 | G38: 0 | H38: 0 | I38: 0 | J38: 0 | K38: 0 | L38: 1 | M38: 11 | N38: 0 | O38: =SUM(C38:L38,N38) -> 8 | P38: =SUM(C38:N38) -> 19
B39: 14.15 - 14.30 | C39: 7 | D39: 2 | E39: 0 | F39: 2 | G39: 0 | H39: 0 | I39: 3 | J39: 0 | K39: 0 | L39: 0 | M39: 24 | N39: 0 | O39: =SUM(C39:L39,N39) -> 14 | P39: =SUM(C39:N39) -> 38
B40: 14.30 - 14.45 | C40: 3 | D40: 0 | E40: 0 | F40: 0 | G40: 0 | H40: 0 | I40: 1 | J40: 1 | K40: 0 | L40: 0 | M40: 21 | N40: 0 | O40: =SUM(C40:L40,N40) -> 5 | P40: =SUM(C40:N40) -> 26
... B57: 18.45 - 19.00 | C57: 8 | D57: 1 | E57: 3 | F57: 0 | G57: 0 | H57: 0 | I57: 0 | J57: 1 | K57: 1 | L57: 0 | M57: 29 | N57: 0 | O57: =SUM(C57:L57,N57) -> 14 | P57: =SUM(C57:N57) -> 43
B58: Totals | C58: =SUM(C10:C57) -> 268 | D58: =SUM(D10:D57) -> 61 | E58: =SUM(E10:E57) -> 73 | F58: =SUM(F10:F57) -> 55 | G58: =SUM(G10:G57) -> 5 | H58: =SUM(H10:H57) -> 0 | I58: =SUM(I10:I57) -> 57 | J58: =SUM(J10:J57) -> 32 | ... P58: =SUM(P10:P57) -> 1548
...

Sheet 24.09 Bukasa-Wakiso
B1: Consultancy services for Preparation of Expressway Development Master Plan (EDMP) for Uganda
B2: MANUAL CLASSIFIED COUNT (MCC)
B3: ROAD NAME: | C3: MCC-C2-STN-64-BUKASA-WAKISO
C5: Date | D5: 24.09.19 | F5: Location | G5: Wakiso Junior Sch. | J5: Surveyor | K5: FARIDAH
C6: Dir. From | D6: BUKASA | F6: Dir. To | G6: WAKISO | J6: Supervisor | K6: NUSURAH
B8: Time / Veh Type | R8: SUMMARY TRAFFIC VOLUMES
C9: 1. Car | D9: 2. Station Wagon | E9: 3. Pickups | F9: 4. Minibus, matatu | G9: 5. Medium bus | H9: 6. Large Bus | I9: 7. Light Truck | J9: 8. Medium Truck | K9: 9. Heavy truck | L9: 10. Truck Trailer | M9: 11. Motor cycles | N9: 12. Tractors | O9: Total Excl M/Cycles | P9: Total All | R9: Time | S9: 1. Car | T9: 2. Station Wagon | U9: 3. Pickups | V9: 4. Minibus, matatu | W9: 5. Medium bus | X9: 6. Large Bus | Y9: 7. Light Truck | Z9: 8. Medium Truck | AA9: 9. Heavy truck | AB9: 10. Truck Trailer | AC9: 11. Motorcycles | AD9: 12. Tractors, Graders | AE9: Total Excl M/ Cycles | AF9: Total All
B10: 07.00 - 07.15 | C10: 3 | D10: 0 | E10: 1 | F10: 0 | G10: 0 | H10: 0 | I10: 1 | J10: 0 | K10: 0 | L10: 0 | M10: 14 | N10: 0 | O10: =SUM(C10:L10,N10) -> 5 | P10: =SUM(C10:N10) -> 19 | R10: 0700-0800 | S10: =SUM(C10:C13) -> 15 | T10: =SUM(D10:D13) -> 6 | U10: =SUM(E10:E13) -> 5 | V10: =SUM(F10:F13) -> 2 | W10: =SUM(G10:G13) -> 0 | X10: =SUM(H10:H13) -> 0 | Y10: =SUM(I10:I13) -> 9 | Z10: =SUM(J10:J13) -> 0 | ... AF10: =SUM(P10:P13) -> 98
B11: 07.15 - 07.30 | C11: 3 | D11: 1 | E11: 0 | F11: 0 | G11: 0 | H11: 0 | I11: 5 | J11: 0 | K11: 0 | L11: 0 | M11: 12 | N11: 0 | O11: =SUM(C11:L11,N11) -> 9 | P11: =SUM(C11:N11) -> 21 | R11: 0800-0900 | S11: =SUM(C14:C17) -> 18 | T11: =SUM(D14:D17) -> 13 | U11: =SUM(E14:E17) -> 7 | V11: =SUM(F14:F17) -> 3 | W11: =SUM(G14:G17) -> 0 | X11: =SUM(H14:H17) -> 0 | Y11: =SUM(I14:I17) -> 12 | Z11: =SUM(J14:J17) -> 0 | ... AF11: =SUM(P14:P17) -> 106
B12: 07.30 - 07.45 | C12: 6 | D12: 4 | E12: 2 | F12: 2 | G12: 0 | H12: 0 | I12: 1 | J12: 0 | K12: 0 | L12: 0 | M12: 15 | N12: 0 | O12: =SUM(C12:L12,N12) -> 15 | P12: =SUM(C12:N12) -> 30 | R12: 0900-1000 | S12: =SUM(C18:C21) -> 20 | T12: =SUM(D18:D21) -> 13 | U12: =SUM(E18:E21) -> 3 | V12: =SUM(F18:F21) -> 0 | W12: =SUM(G18:G21) -> 0 | X12: =SUM(H18:H21) -> 0 | Y12: =SUM(I18:I21) -> 6 | Z12: =SUM(J18:J21) -> 0 | ... AF12: =SUM(P18:P21) -> 100
B13: 07.45 - 08.00 | C13: 3 | D13: 1 | E13: 2 | F13: 0 | G13: 0 | H13: 0 | I13: 2 | J13: 0 | K13: 0 | L13: 0 | M13: 20 | N13: 0 | O13: =SUM(C13:L13,N13) -> 8 | P13: =SUM(C13:N13) -> 28 | R13: 1000-1100 | S13: =SUM(C22:C25) -> 21 | T13: =SUM(D22:D25) -> 18 | U13: =SUM(E22:E25) -> 5 | V13: =SUM(F22:F25) -> 1 | W13: =SUM(G22:G25) -> 0 | X13: =SUM(H22:H25) -> 1 | Y13: =SUM(I22:I25) -> 7 | Z13: =SUM(J22:J25) -> 0 | ... AF13: =SUM(P22:P25) -> 104
B14: 08.00 - 08.15 | C14: 4 | D14: 3 | E14: 4 | F14: 3 | G14: 0 | H14: 0 | I14: 1 | J14: 0 | K14: 0 | L14: 0 | M14: 17 | N14: 0 | O14: =SUM(C14:L14,N14) -> 15 | P14: =SUM(C14:N14) -> 32 | R14: 1100-1200 | S14: =SUM(C26:C29) -> 15 | T14: =SUM(D26:D29) -> 15 | U14: =SUM(E26:E29) -> 4 | V14: =SUM(F26:F29) -> 1 | W14: =SUM(G26:G29) -> 0 | X14: =SUM(H26:H29) -> 0 | Y14: =SUM(I26:I29) -> 14 | Z14: =SUM(J26:J29) -> 2 | ... AF14: =SUM(P26:P29) -> 103
B15: 08.15 - 08.30 | C15: 3 | D15: 1 | E15: 1 | F15: 0 | G15: 0 | H15: 0 | I15: 3 | J15: 0 | K15: 0 | L15: 0 | M15: 10 | N15: 0 | O15: =SUM(C15:L15,N15) -> 8 | P15: =SUM(C15:N15) -> 18 | R15: 1200-1300 | S15: =SUM(C30:C33) -> 17 | T15: =SUM(D30:D33) -> 12 | U15: =SUM(E30:E33) -> 6 | V15: =SUM(F30:F33) -> 1 | W15: =SUM(G30:G33) -> 0 | X15: =SUM(H30:H33) -> 0 | Y15: =SUM(I30:I33) -> 15 | Z15: =SUM(J30:J33) -> 0 | ... AF15: =SUM(P30:P33) -> 111
B16: 08.30 - 08.45 | C16: 6 | D16: 4 | E16: 2 | F16: 0 | G16: 0 | H16: 0 | I16: 7 | J16: 0 | K16: 0 | L16: 0 | M16: 12 | N16: 0 | O16: =SUM(C16:L16,N16) -> 19 | P16: =SUM(C16:N16) -> 31 | R16: 1300-1400 | S16: =SUM(C34:C37) -> 14 | T16: =SUM(D34:D37) -> 15 | U16: =SUM(E34:E37) -> 1 | V16: =SUM(F34:F37) -> 3 | W16: =SUM(G34:G37) -> 0 | X16: =SUM(H34:H37) -> 0 | Y16: =SUM(I34:I37) -> 18 | Z16: =SUM(J34:J37) -> 0 | ... AF16: =SUM(P34:P37) -> 102
B17: 08.45 - 9.00 | C17: 5 | D17: 5 | E17: 0 | F17: 0 | G17: 0 | H17: 0 | I17: 1 | J17: 0 | K17: 0 | L17: 0 | M17: 14 | N17: 0 | O17: =SUM(C17:L17,N17) -> 11 | P17: =SUM(C17:N17) -> 25 | R17: 1400-1500 | S17: =SUM(C38:C41) -> 18 | T17: =SUM(D38:D41) -> 15 | U17: =SUM(E38:E41) -> 1 | V17: =SUM(F38:F41) -> 0 | W17: =SUM(G38:G41) -> 0 | X17: =SUM(H38:H41) -> 0 | Y17: =SUM(I38:I41) -> 22 | Z17: =SUM(J38:J41) -> 0 | ... AF17: =SUM(P38:P41) -> 134
B18: 09.00 - 09.15 | C18: 5 | D18: 4 | E18: 2 | F18: 0 | G18: 0 | H18: 0 | I18: 0 | J18: 0 | K18: 0 | L18: 0 | M18: 11 | N18: 0 | O18: =SUM(C18:L18,N18) -> 11 | P18: =SUM(C18:N18) -> 22 | R18: 1500-1600 | S18: =SUM(C42:C45) -> 11 | T18: =SUM(D42:D45) -> 12 | U18: =SUM(E42:E45) -> 2 | V18: =SUM(F42:F45) -> 1 | W18: =SUM(G42:G45) -> 0 | X18: =SUM(H42:H45) -> 0 | Y18: =SUM(I42:I45) -> 9 | Z18: =SUM(J42:J45) -> 2 | ... AF18: =SUM(P42:P45) -> 76
B19: 09.15 - 09.30 | C19: 4 | D19: 2 | E19: 0 | F19: 0 | G19: 0 | H19: 0 | I19: 2 | J19: 0 | K19: 0 | L19: 0 | M19: 12 | N19: 0 | O19: =SUM(C19:L19,N19) -> 8 | P19: =SUM(C19:N19) -> 20 | R19: 1600-1700 | S19: =SUM(C46:C49) -> 13 | T19: =SUM(D46:D49) -> 18 | U19: =SUM(E46:E49) -> 2 | V19: =SUM(F46:F49) -> 2 | W19: =SUM(G46:G49) -> 1 | X19: =SUM(H46:H49) -> 0 | Y19: =SUM(I46:I49) -> 6 | Z19: =SUM(J46:J49) -> 2 | ... AF19: =SUM(P46:P49) -> 96
B20: 09.30 - 09.45 | C20: 5 | D20: 3 | E20: 0 | F20: 0 | G20: 0 | H20: 0 | I20: 2 | J20: 0 | K20: 0 | L20: 0 | M20: 16 | N20: 0 | O20: =SUM(C20:L20,N20) -> 10 | P20: =SUM(C20:N20) -> 26 | R20: 1700-1800 | S20: =SUM(C50:C53) -> 17 | T20: =SUM(D50:D53) -> 17 | U20: =SUM(E50:E53) -> 2 | V20: =SUM(F50:F53) -> 7 | W20: =SUM(G50:G53) -> 1 | X20: =SUM(H50:H53) -> 0 | Y20: =SUM(I50:I53) -> 7 | Z20: =SUM(J50:J53) -> 2 | ... AF20: =SUM(P50:P53) -> 86
B21: 09.45 - 10.00 | C21: 6 | D21: 4 | E21: 1 | F21: 0 | G21: 0 | H21: 0 | I21: 2 | J21: 0 | K21: 0 | L21: 0 | M21: 19 | N21: 0 | O21: =SUM(C21:L21,N21) -> 13 | P21: =SUM(C21:N21) -> 32 | R21: 1800-1900 | S21: =SUM(C54:C57) -> 25 | T21: =SUM(D54:D57) -> 20 | U21: =SUM(E54:E57) -> 3 | V21: =SUM(F54:F57) -> 3 | W21: =SUM(G54:G57) -> 0 | X21: =SUM(H54:H57) -> 0 | Y21: =SUM(I54:I57) -> 6 | Z21: =SUM(J54:J57) -> 0 | ... AF21: =SUM(P54:P57) -> 104
B22: 10.00 - 10.15 | C22: 6 | D22: 5 | E22: 1 | F22: 0 | G22: 0 | H22: 0 | I22: 2 | J22: 0 | K22: 0 | L22: 0 | M22: 14 | N22: 0 | O22: =SUM(C22:L22,N22) -> 14 | P22: =SUM(C22:N22) -> 28 | R22: AM Peak Hr | S22: =MAX(S10:S12) -> 20 | T22: =MAX(T10:T12) -> 13 | U22: =MAX(U10:U12) -> 7 | V22: =MAX(V10:V12) -> 3 | W22: =MAX(W10:W12) -> 0 | X22: =MAX(X10:X12) -> 0 | Y22: =MAX(Y10:Y12) -> 12 | Z22: =MAX(Z10:Z12) -> 0 | ... AF22: =MAX(AF10:AF12) -> 106
B23: 10.15 - 10.30 | C23: 2 | D23: 3 | E23: 0 | F23: 0 | G23: 0 | H23: 0 | I23: 1 | J23: 0 | K23: 0 | L23: 0 | M23: 11 | N23: 0 | O23: =SUM(C23:L23,N23) -> 6 | P23: =SUM(C23:N23) -> 17 | R23: IP Peak Hr | S23: =MAX(S13:S18) -> 21 | T23: =MAX(T13:T18) -> 18 | U23: =MAX(U13:U18) -> 6 | V23: =MAX(V13:V18) -> 3 | W23: =MAX(W13:W18) -> 0 | X23: =MAX(X13:X18) -> 1 | Y23: =MAX(Y13:Y18) -> 22 | Z23: =MAX(Z13:Z18) -> 2 | ... AF23: =MAX(AF13:AF18) -> 134
B24: 10.30 - 10.45 | C24: 7 | D24: 3 | E24: 1 | F24: 0 | G24: 0 | H24: 0 | I24: 3 | J24: 0 | K24: 0 | L24: 0 | M24: 14 | N24: 0 | O24: =SUM(C24:L24,N24) -> 14 | P24: =SUM(C24:N24) -> 28 | R24: PM Peak Hr | S24: =MAX(S19:S21) -> 25 | T24: =MAX(T19:T21) -> 20 | U24: =MAX(U19:U21) -> 3 | V24: =MAX(V19:V21) -> 7 | W24: =MAX(W19:W21) -> 1 | X24: =MAX(X19:X21) -> 0 | Y24: =MAX(Y19:Y21) -> 7 | Z24: =MAX(Z19:Z21) -> 2 | ... AF24: =MAX(AF19:AF21) -> 104
B25: 10.45 - 11.00 | C25: 6 | D25: 7 | E25: 3 | F25: 1 | G25: 0 | H25: 1 | I25: 1 | J25: 0 | K25: 0 | L25: 0 | M25: 12 | N25: 0 | O25: =SUM(C25:L25,N25) -> 19 | P25: =SUM(C25:N25) -> 31 | R25: AM Period | S25: =SUM(S10:S12) -> 53 | T25: =SUM(T10:T12) -> 32 | U25: =SUM(U10:U12) -> 15 | V25: =SUM(V10:V12) -> 5 | W25: =SUM(W10:W12) -> 0 | X25: =SUM(X10:X12) -> 0 | Y25: =SUM(Y10:Y12) -> 27 | Z25: =SUM(Z10:Z12) -> 0 | ... AF25: =SUM(AF10:AF12) -> 304
B26: 11.00 - 11.15 | C26: 1 | D26: 3 | E26: 1 | F26: 1 | G26: 0 | H26: 0 | I26: 4 | J26: 1 | K26: 0 | L26: 0 | M26: 11 | N26: 0 | O26: =SUM(C26:L26,N26) -> 11 | P26: =SUM(C26:N26) -> 22 | R26: IP Period | S26: =SUM(S13:S18) -> 96 | T26: =SUM(T13:T18) -> 87 | U26: =SUM(U13:U18) -> 19 | V26: =SUM(V13:V18) -> 7 | W26: =SUM(W13:W18) -> 0 | X26: =SUM(X13:X18) -> 1 | Y26: =SUM(Y13:Y18) -> 85 | Z26: =SUM(Z13:Z18) -> 4 | ... AF26: =SUM(AF13:AF18) -> 630
B27: 11.15 - 11.30 | C27: 5 | D27: 3 | E27: 2 | F27: 0 | G27: 0 | H27: 0 | I27: 5 | J27: 0 | K27: 0 | L27: 0 | M27: 14 | N27: 0 | O27: =SUM(C27:L27,N27) -> 15 | P27: =SUM(C27:N27) -> 29 | R27: PM Period | S27: =SUM(S19:S21) -> 55 | T27: =SUM(T19:T21) -> 55 | U27: =SUM(U19:U21) -> 7 | V27: =SUM(V19:V21) -> 12 | W27: =SUM(W19:W21) -> 2 | X27: =SUM(X19:X21) -> 0 | Y27: =SUM(Y19:Y21) -> 19 | Z27: =SUM(Z19:Z21) -> 4 | ... AF27: =SUM(AF19:AF21) -> 286
B28: 11.30 - 11.45 | C28: 5 | D28: 4 | E28: 0 | F28: 0 | G28: 0 | H28: 0 | I28: 2 | J28: 0 | K28: 0 | L28: 0 | M28: 13 | N28: 0 | O28: =SUM(C28:L28,N28) -> 11 | P28: =SUM(C28:N28) -> 24 | R28: 12 Hours | S28: =SUM(S10:S21) -> 204 | T28: =SUM(T10:T21) -> 174 | U28: =SUM(U10:U21) -> 41 | V28: =SUM(V10:V21) -> 24 | W28: =SUM(W10:W21) -> 2 | X28: =SUM(X10:X21) -> 1 | Y28: =SUM(Y10:Y21) -> 131 | Z28: =SUM(Z10:Z21) -> 8 | ... AF28: =SUM(AF10:AF21) -> 1220
B29: 11.45 - 12.00 | C29: 4 | D29: 5 | E29: 1 | F29: 0 | G29: 0 | H29: 0 | I29: 3 | J29: 1 | K29: 0 | L29: 0 | M29: 14 | N29: 0 | O29: =SUM(C29:L29,N29) -> 14 | P29: =SUM(C29:N29) -> 28
B30: 12.00 - 12.15 | C30: 2 | D30: 2 | E30: 0 | F30: 0 | G30: 0 | H30: 0 | I30: 3 | J30: 0 | K30: 0 | L30: 0 | M30: 18 | N30: 0 | O30: =SUM(C30:L30,N30) -> 7 | P30: =SUM(C30:N30) -> 25
B31: 12.15 - 12.30 | C31: 5 | D31: 4 | E31: 2 | F31: 1 | G31: 0 | H31: 0 | I31: 3 | J31: 0 | K31: 0 | L31: 0 | M31: 16 | N31: 0 | O31: =SUM(C31:L31,N31) -> 15 | P31: =SUM(C31:N31) -> 31
B32: 12.30 - 12.45 | C32: 7 | D32: 4 | E32: 3 | F32: 0 | G32: 0 | H32: 0 | I32: 5 | J32: 0 | K32: 0 | L32: 0 | M32: 20 | N32: 0 | O32: =SUM(C32:L32,N32) -> 19 | P32: =SUM(C32:N32) -> 39
B33: 12.45 - 13.00 | C33: 3 | D33: 2 | E33: 1 | F33: 0 | G33: 0 | H33: 0 | I33: 4 | J33: 0 | K33: 0 | L33: 0 | M33: 6 | N33: 0 | O33: =SUM(C33:L33,N33) -> 10 | P33: =SUM(C33:N33) -> 16
B34: 13.00 - 13.15 | C34: 4 | D34: 4 | E34: 0 | F34: 3 | G34: 0 | H34: 0 | I34: 3 | J34: 0 | K34: 0 | L34: 0 | M34: 16 | N34: 0 | O34: =SUM(C34:L34,N34) -> 14 | P34: =SUM(C34:N34) -> 30
B35: 13.15 - 13.30 | C35: 3 | D35: 4 | E35: 0 | F35: 0 | G35: 0 | H35: 0 | I35: 6 | J35: 0 | K35: 0 | L35: 0 | M35: 13 | N35: 0 | O35: =SUM(C35:L35,N35) -> 13 | P35: =SUM(C35:N35) -> 26
B36: 13.30 - 13.45 | C36: 3 | D36: 3 | E36: 0 | F36: 0 | G36: 0 | H36: 0 | I36: 4 | J36: 0 | K36: 0 | L36: 0 | M36: 10 | N36: 0 | O36: =SUM(C36:L36,N36) -> 10 | P36: =SUM(C36:N36) -> 20
B37: 13.45 - 14.00 | C37: 4 | D37: 4 | E37: 1 | F37: 0 | G37: 0 | H37: 0 | I37: 5 | J37: 0 | K37: 0 | L37: 0 | M37: 12 | N37: 0 | O37: =SUM(C37:L37,N37) -> 14 | P37: =SUM(C37:N37) -> 26
B38: 14.00 - 14.15 | C38: 7 | D38: 5 | E38: 1 | F38: 0 | G38: 0 | H38: 0 | I38: 3 | J38: 0 | K38: 0 | L38: 0 | M38: 25 | N38: 0 | O38: =SUM(C38:L38,N38) -> 16 | P38: =SUM(C38:N38) -> 41
B39: 14.15 - 14.30 | C39: 5 | D39: 5 | E39: 0 | F39: 0 | G39: 0 | H39: 0 | I39: 4 | J39: 0 | K39: 0 | L39: 0 | M39: 21 | N39: 0 | O39: =SUM(C39:L39,N39) -> 14 | P39: =SUM(C39:N39) -> 35
B40: 14.30 - 14.45 | C40: 3 | D40: 3 | E40: 0 | F40: 0 | G40: 0 | H40: 0 | I40: 5 | J40: 0 | K40: 0 | L40: 0 | M40: 18 | N40: 0 | O40: =SUM(C40:L40,N40) -> 11 | P40: =SUM(C40:N40) -> 29
... B57: 18.45 - 19.00 | C57: 7 | D57: 4 | E57: 0 | F57: 0 | G57: 0 | H57: 0 | I57: 1 | J57: 0 | K57: 0 | L57: 0 | M57: 12 | N57: 0 | O57: =SUM(C57:L57,N57) -> 12 | P57: =SUM(C57:N57) -> 24
B58: Totals | C58: =SUM(C10:C57) -> 204 | D58: =SUM(D10:D57) -> 174 | E58: =SUM(E10:E57) -> 41 | F58: =SUM(F10:F57) -> 24 | G58: =SUM(G10:G57) -> 2 | H58: =SUM(H10:H57) -> 1 | I58: =SUM(I10:I57) -> 131 | J58: =SUM(J10:J57) -> 8 | ... P58: =SUM(P10:P57) -> 1220
...

Sheet 24.09 Wakiso-Bukasa
B1: Consultancy services for Preparation of Expressway Development Master Plan (EDMP) for Uganda
B2: MANUAL CLASSIFIED COUNT (MCC)
B3: ROAD NAME: | C3: ='24.09 Bukasa-Wakiso'!C3:G3 -> MCC-C2-STN-64-BUKASA-WAKISO
C5: Date | D5: ='[1]24.09.2019 BUKASA-WAKISO'!D5 -> 24.09.19 | F5: Location | G5: WAKISO JUNIOR SCH | J5: Surveyor | K5: LEAH TUSASIRWE
C6: Dir. From | D6: WAKISO | F6: Dir. To | G6: BUKASA | J6: Supervisor | K6: NUSURAH
B8: Time / Veh Type | R8: SUMMARY TRAFFIC VOLUMES
C9: 1. Car | D9: 2. Station Wagon | E9: 3. Pickups | F9: 4. Minibus, matatu | G9: 5. Medium bus | H9: 6. Large Bus | I9: 7. Light Truck | J9: 8. Medium Truck | K9: 9. Heavy truck | L9: 10. Truck Trailer | M9: 11. Motor cycles | N9: 12. Tractors | O9: Total Excl M/Cycles | P9: Total All | R9: Time | S9: 1. Car | T9: 2. Station Wagon | U9: 3. Pickups | V9: 4. Minibus, matatu | W9: 5. Medium bus | X9: 6. Large Bus | Y9: 7. Light Truck | Z9: 8. Medium Truck | AA9: 9. Heavy truck | AB9: 10. Truck Trailer | AC9: 11. Motorcycles | AD9: 12. Tractors, Graders | AE9: Total Excl M/ Cycles | AF9: Total All
B10: 07.00 - 07.15 | C10: 4 | D10: 0 | E10: 0 | F10: 1 | G10: 0 | H10: 0 | I10: 1 | J10: 0 | K10: 0 | L10: 0 | M10: 15 | N10: 0 | O10: =SUM(C10:L10,N10) -> 6 | P10: =SUM(C10:N10) -> 21 | R10: 0700-0800 | S10: =SUM(C10:C13) -> 15 | T10: =SUM(D10:D13) -> 2 | U10: =SUM(E10:E13) -> 4 | V10: =SUM(F10:F13) -> 8 | W10: =SUM(G10:G13) -> 1 | X10: =SUM(H10:H13) -> 0 | Y10: =SUM(I10:I13) -> 6 | Z10: =SUM(J10:J13) -> 1 | ... AF10: =SUM(P10:P13) -> 114
B11: 07.15 - 07.30 | C11: 3 | D11: 0 | E11: 0 | F11: 3 | G11: 0 | H11: 0 | I11: 2 | J11: 0 | K11: 0 | L11: 0 | M11: 19 | N11: 0 | O11: =SUM(C11:L11,N11) -> 8 | P11: =SUM(C11:N11) -> 27 | R11: 0800-0900 | S11: =SUM(C14:C17) -> 24 | T11: =SUM(D14:D17) -> 6 | U11: =SUM(E14:E17) -> 6 | V11: =SUM(F14:F17) -> 3 | W11: =SUM(G14:G17) -> 0 | X11: =SUM(H14:H17) -> 0 | Y11: =SUM(I14:I17) -> 7 | Z11: =SUM(J14:J17) -> 2 | ... AF11: =SUM(P14:P17) -> 121
B12: 07.30 - 07.45 | C12: 6 | D12: 1 | E12: 1 | F12: 2 | G12: 1 | H12: 0 | I12: 1 | J12: 0 | K12: 0 | L12: 0 | M12: 28 | N12: 0 | O12: =SUM(C12:L12,N12) -> 12 | P12: =SUM(C12:N12) -> 40 | R12: 0900-1000 | S12: =SUM(C18:C21) -> 16 | T12: =SUM(D18:D21) -> 2 | U12: =SUM(E18:E21) -> 5 | V12: =SUM(F18:F21) -> 1 | W12: =SUM(G18:G21) -> 0 | X12: =SUM(H18:H21) -> 0 | Y12: =SUM(I18:I21) -> 9 | Z12: =SUM(J18:J21) -> 1 | ... AF12: =SUM(P18:P21) -> 126
B13: 07.45 - 08.00 | C13: 2 | D13: 1 | E13: 3 | F13: 2 | G13: 0 | H13: 0 | I13: 2 | J13: 1 | K13: 0 | L13: 0 | M13: 15 | N13: 0 | O13: =SUM(C13:L13,N13) -> 11 | P13: =SUM(C13:N13) -> 26 | R13: 1000-1100 | S13: =SUM(C22:C25) -> 9 | T13: =SUM(D22:D25) -> 8 | U13: =SUM(E22:E25) -> 8 | V13: =SUM(F22:F25) -> 2 | W13: =SUM(G22:G25) -> 0 | X13: =SUM(H22:H25) -> 0 | Y13: =SUM(I22:I25) -> 8 | Z13: =SUM(J22:J25) -> 2 | ... AF13: =SUM(P22:P25) -> 106
B14: 08.00 - 08.15 | C14: 7 | D14: 1 | E14: 0 | F14: 1 | G14: 0 | H14: 0 | I14: 3 | J14: 0 | K14: 0 | L14: 0 | M14: 18 | N14: 0 | O14: =SUM(C14:L14,N14) -> 12 | P14: =SUM(C14:N14) -> 30 | R14: 1100-1200 | S14: =SUM(C26:C29) -> 20 | T14: =SUM(D26:D29) -> 9 | U14: =SUM(E26:E29) -> 6 | V14: =SUM(F26:F29) -> 1 | W14: =SUM(G26:G29) -> 0 | X14: =SUM(H26:H29) -> 0 | Y14: =SUM(I26:I29) -> 7 | Z14: =SUM(J26:J29) -> 1 | ... AF14: =SUM(P26:P29) -> 123
B15: 08.15 - 08.30 | C15: 6 | D15: 5 | E15: 4 | F15: 1 | G15: 0 | H15: 0 | I15: 3 | J15: 0 | K15: 0 | L15: 0 | M15: 17 | N15: 0 | O15: =SUM(C15:L15,N15) -> 19 | P15: =SUM(C15:N15) -> 36 | R15: 1200-1300 | S15: =SUM(C30:C33) -> 24 | T15: =SUM(D30:D33) -> 0 | U15: =SUM(E30:E33) -> 7 | V15: =SUM(F30:F33) -> 1 | W15: =SUM(G30:G33) -> 0 | X15: =SUM(H30:H33) -> 0 | Y15: =SUM(I30:I33) -> 14 | Z15: =SUM(J30:J33) -> 2 | ... AF15: =SUM(P30:P33) -> 124
B16: 08.30 - 08.45 | C16: 6 | D16: 0 | E16: 1 | F16: 0 | G16: 0 | H16: 0 | I16: 0 | J16: 1 | K16: 0 | L16: 0 | M16: 13 | N16: 0 | O16: =SUM(C16:L16,N16) -> 8 | P16: =SUM(C16:N16) -> 21 | R16: 1300-1400 | S16: =SUM(C34:C38) -> 26 | T16: =SUM(D34:D38) -> 2 | U16: =SUM(E34:E38) -> 4 | V16: =SUM(F34:F38) -> 3 | W16: =SUM(G34:G38) -> 1 | X16: =SUM(H34:H38) -> 0 | Y16: =SUM(I34:I38) -> 13 | Z16: =SUM(J34:J38) -> 5 | ... AC16: =SUM(M34:M38) -> 88 | AD16: =SUM(N34:N37) -> 0 | AE16: =SUM(O34:O37) -> 42 | AF16: =SUM(P34:P37) -> 115
B17: 08.45 - 9.00 | C17: 5 | D17: 0 | E17: 1 | F17: 1 | G17: 0 | H17: 0 | I17: 1 | J17: 1 | K17: 0 | L17: 0 | M17: 25 | N17: 0 | O17: =SUM(C17:L17,N17) -> 9 | P17: =SUM(C17:N17) -> 34 | R17: 1400-1500 | S17: =SUM(C39:C42) -> 18 | T17: =SUM(D39:D42) -> 1 | U17: =SUM(E39:E42) -> 3 | V17: =SUM(F39:F42) -> 0 | W17: =SUM(G39:G42) -> 0 | X17: =SUM(H39:H42) -> 0 | Y17: =SUM(I39:I42) -> 5 | Z17: =SUM(J39:J42) -> 3 | ... AC17: =SUM(M39:M42) -> 62 | AD17: =SUM(N38:N41) -> 0 | AE17: =SUM(O38:O41) -> 35 | AF17: =SUM(P38:P41) -> 95
B18: 09.00 - 09.15 | C18: 8 | D18: 0 | E18: 2 | F18: 0 | G18: 0 | H18: 0 | I18: 3 | J18: 0 | K18: 0 | L18: 0 | M18: 30 | N18: 0 | O18: =SUM(C18:L18,N18) -> 13 | P18: =SUM(C18:N18) -> 43 | R18: 1500-1600 | S18: =SUM(C43:C46) -> 21 | T18: =SUM(D43:D46) -> 2 | U18: =SUM(E43:E46) -> 8 | V18: =SUM(F43:F46) -> 3 | W18: =SUM(G43:G46) -> 0 | X18: =SUM(H43:H46) -> 0 | Y18: =SUM(I43:I46) -> 7 | Z18: =SUM(J43:J46) -> 3 | ... AC18: =SUM(M43:M46) -> 45 | AD18: =SUM(N42:N45) -> 1 | AE18: =SUM(O42:O45) -> 43 | AF18: =SUM(P42:P45) -> 104
B19: 09.15 - 09.30 | C19: 4 | D19: 2 | E19: 1 | F19: 1 | G19: 0 | H19: 0 | I19: 3 | J19: 0 | K19: 0 | L19: 0 | M19: 19 | N19: 0 | O19: =SUM(C19:L19,N19) -> 11 | P19: =SUM(C19:N19) -> 30 | R19: 1600-1700 | S19: =SUM(C47:C50) -> 17 | T19: =SUM(D47:D50) -> 4 | U19: =SUM(E47:E50) -> 3 | V19: =SUM(F47:F50) -> 5 | W19: =SUM(G47:G50) -> 2 | X19: =SUM(H47:H50) -> 0 | Y19: =SUM(I47:I50) -> 7 | Z19: =SUM(J47:J50) -> 2 | ... AC19: =SUM(M47:M50) -> 90 | AD19: =SUM(N46:N49) -> 0 | AE19: =SUM(O46:O49) -> 47 | AF19: =SUM(P46:P49) -> 111
B20: 09.30 - 09.45 | C20: 2 | D20: 0 | E20: 1 | F20: 0 | G20: 0 | H20: 0 | I20: 1 | J20: 1 | K20: 0 | L20: 0 | M20: 28 | N20: 0 | O20: =SUM(C20:L20,N20) -> 5 | P20: =SUM(C20:N20) -> 33 | R20: 1700-1800 | S20: =SUM(C51:C53) -> 27 | T20: =SUM(D51:D53) -> 3 | U20: =SUM(E51:E53) -> 4 | V20: =SUM(F51:F53) -> 4 | W20: =SUM(G51:G53) -> 0 | X20: =SUM(H51:H53) -> 0 | Y20: =SUM(I51:I53) -> 6 | Z20: =SUM(J51:J53) -> 5 | ... AC20: =SUM(M51:M53) -> 72 | AD20: =SUM(N50:N53) -> 0 | AE20: =SUM(O50:O53) -> 58 | AF20: =SUM(P50:P53) -> 157
B21: 09.45 - 10.00 | C21: 2 | D21: 0 | E21: 1 | F21: 0 | G21: 0 | H21: 0 | I21: 2 | J21: 0 | K21: 0 | L21: 0 | M21: 15 | N21: 0 | O21: =SUM(C21:L21,N21) -> 5 | P21: =SUM(C21:N21) -> 20 | R21: 1800-1900 | S21: =SUM(C54:C57) -> 26 | T21: =SUM(D54:D57) -> 8 | U21: =SUM(E54:E57) -> 8 | V21: =SUM(F54:F57) -> 8 | W21: =SUM(G54:G57) -> 1 | X21: =SUM(H54:H57) -> 0 | Y21: =SUM(I54:I57) -> 6 | Z21: =SUM(J54:J57) -> 7 | ... AF21: =SUM(P54:P57) -> 161
B22: 10.00 - 10.15 | C22: 3 | D22: 1 | E22: 2 | F22: 0 | G22: 0 | H22: 0 | I22: 3 | J22: 0 | K22: 1 | L22: 0 | M22: 24 | N22: 0 | O22: =SUM(C22:L22,N22) -> 10 | P22: =SUM(C22:N22) -> 34 | R22: AM Peak Hr | S22: =MAX(S10:S12) -> 24 | T22: =MAX(T10:T12) -> 6 | U22: =MAX(U10:U12) -> 6 | V22: =MAX(V10:V12) -> 8 | W22: =MAX(W10:W12) -> 1 | X22: =MAX(X10:X12) -> 0 | Y22: =MAX(Y10:Y12) -> 9 | Z22: =MAX(Z10:Z12) -> 2 | ... AF22: =MAX(AF10:AF12) -> 126
B23: 10.15 - 10.30 | C23: 1 | D23: 3 | E23: 0 | F23: 0 | G23: 0 | H23: 0 | I23: 2 | J23: 1 | K23: 0 | L23: 0 | M23: 18 | N23: 0 | O23: =SUM(C23:L23,N23) -> 7 | P23: =SUM(C23:N23) -> 25 | R23: IP Peak Hr | S23: =MAX(S13:S18) -> 26 | T23: =MAX(T13:T18) -> 9 | U23: =MAX(U13:U18) -> 8 | V23: =MAX(V13:V18) -> 3 | W23: =MAX(W13:W18) -> 1 | X23: =MAX(X13:X18) -> 0 | Y23: =MAX(Y13:Y18) -> 14 | Z23: =MAX(Z13:Z18) -> 5 | ... AF23: =MAX(AF13:AF18) -> 124
B24: 10.30 - 10.45 | C24: 4 | D24: 2 | E24: 3 | F24: 1 | G24: 0 | H24: 0 | I24: 2 | J24: 0 | K24: 0 | L24: 0 | M24: 11 | N24: 0 | O24: =SUM(C24:L24,N24) -> 12 | P24: =SUM(C24:N24) -> 23 | R24: PM Peak Hr | S24: =MAX(S19:S21) -> 27 | T24: =MAX(T19:T21) -> 8 | U24: =MAX(U19:U21) -> 8 | V24: =MAX(V19:V21) -> 8 | W24: =MAX(W19:W21) -> 2 | X24: =MAX(X19:X21) -> 0 | Y24: =MAX(Y19:Y21) -> 7 | Z24: =MAX(Z19:Z21) -> 7 | ... AF24: =MAX(AF19:AF21) -> 161
B25: 10.45 - 11.00 | C25: 1 | D25: 2 | E25: 3 | F25: 1 | G25: 0 | H25: 0 | I25: 1 | J25: 1 | K25: 0 | L25: 0 | M25: 15 | N25: 0 | O25: =SUM(C25:L25,N25) -> 9 | P25: =SUM(C25:N25) -> 24 | R25: AM Period | S25: =SUM(S10:S12) -> 55 | T25: =SUM(T10:T12) -> 10 | U25: =SUM(U10:U12) -> 15 | V25: =SUM(V10:V12) -> 12 | W25: =SUM(W10:W12) -> 1 | X25: =SUM(X10:X12) -> 0 | Y25: =SUM(Y10:Y12) -> 22 | Z25: =SUM(Z10:Z12) -> 4 | ... AF25: =SUM(AF10:AF12) -> 361
B26: 11.00 - 11.15 | C26: 6 | D26: 2 | E26: 1 | F26: 0 | G26: 0 | H26: 0 | I26: 1 | J26: 0 | K26: 0 | L26: 0 | M26: 18 | N26: 0 | O26: =SUM(C26:L26,N26) -> 10 | P26: =SUM(C26:N26) -> 28 | R26: IP Period | S26: =SUM(S13:S18) -> 118 | T26: =SUM(T13:T18) -> 22 | U26: =SUM(U13:U18) -> 36 | V26: =SUM(V13:V18) -> 10 | W26: =SUM(W13:W18) -> 1 | X26: =SUM(X13:X18) -> 0 | Y26: =SUM(Y13:Y18) -> 54 | Z26: =SUM(Z13:Z18) -> 16 | ... AF26: =SUM(AF13:AF18) -> 667
B27: 11.15 - 11.30 | C27: 1 | D27: 2 | E27: 0 | F27: 0 | G27: 0 | H27: 0 | I27: 4 | J27: 0 | K27: 0 | L27: 0 | M27: 7 | N27: 0 | O27: =SUM(C27:L27,N27) -> 7 | P27: =SUM(C27:N27) -> 14 | R27: PM Period | S27: =SUM(S19:S21) -> 70 | T27: =SUM(T19:T21) -> 15 | U27: =SUM(U19:U21) -> 15 | V27: =SUM(V19:V21) -> 17 | W27: =SUM(W19:W21) -> 3 | X27: =SUM(X19:X21) -> 0 | Y27: =SUM(Y19:Y21) -> 19 | Z27: =SUM(Z19:Z21) -> 14 | ... AF27: =SUM(AF19:AF21) -> 429
B28: 11.30 - 11.45 | C28: 7 | D28: 4 | E28: 2 | F28: 1 | G28: 0 | H28: 0 | I28: 2 | J28: 0 | K28: 1 | L28: 0 | M28: 32 | N28: 0 | O28: =SUM(C28:L28,N28) -> 17 | P28: =SUM(C28:N28) -> 49 | R28: 12 Hours | S28: =SUM(S10:S21) -> 243 | T28: =SUM(T10:T21) -> 47 | U28: =SUM(U10:U21) -> 66 | V28: =SUM(V10:V21) -> 39 | W28: =SUM(W10:W21) -> 5 | X28: =SUM(X10:X21) -> 0 | Y28: =SUM(Y10:Y21) -> 95 | Z28: =SUM(Z10:Z21) -> 34 | ... AF28: =SUM(AF10:AF21) -> 1457
B29: 11.45 - 12.00 | C29: 6 | D29: 1 | E29: 3 | F29: 0 | G29: 0 | H29: 0 | I29: 0 | J29: 1 | K29: 1 | L29: 0 | M29: 20 | N29: 0 | O29: =SUM(C29:L29,N29) -> 12 | P29: =SUM(C29:N29) -> 32
B30: 12.00 - 12.15 | C30: 4 | D30: 0 | E30: 0 | F30: 0 | G30: 0 | H30: 0 | I30: 4 | J30: 0 | K30: 0 | L30: 0 | M30: 21 | N30: 0 | O30: =SUM(C30:L30,N30) -> 8 | P30: =SUM(C30:N30) -> 29
B31: 12.15 - 12.30 | C31: 10 | D31: 0 | E31: 4 | F31: 0 | G31: 0 | H31: 0 | I31: 4 | J31: 0 | K31: 0 | L31: 0 | M31: 28 | N31: 0 | O31: =SUM(C31:L31,N31) -> 18 | P31: =SUM(C31:N31) -> 46
B32: 12.30 - 12.45 | C32: 8 | D32: 0 | E32: 2 | F32: 0 | G32: 0 | H32: 0 | I32: 4 | J32: 2 | K32: 0 | L32: 0 | M32: 19 | N32: 0 | O32: =SUM(C32:L32,N32) -> 16 | P32: =SUM(C32:N32) -> 35
B33: 12.45 - 13.00 | C33: 2 | D33: 0 | E33: 1 | F33: 1 | G33: 0 | H33: 0 | I33: 2 | J33: 0 | K33: 0 | L33: 0 | M33: 8 | N33: 0 | O33: =SUM(C33:L33,N33) -> 6 | P33: =SUM(C33:N33) -> 14
B34: 13.00 - 13.15 | C34: 6 | D34: 1 | E34: 0 | F34: 0 | G34: 0 | H34: 0 | I34: 3 | J34: 1 | K34: 0 | L34: 0 | M34: 13 | N34: 0 | O34: =SUM(C34:L34,N34) -> 11 | P34: =SUM(C34:N34) -> 24
B35: 13.15 - 13.30 | C35: 5 | D35: 0 | E35: 0 | F35: 0 | G35: 0 | H35: 0 | I35: 3 | J35: 0 | K35: 0 | L35: 0 | M35: 25 | N35: 0 | O35: =SUM(C35:L35,N35) -> 8 | P35: =SUM(C35:N35) -> 33
B36: 13.30 - 13.45 | C36: 5 | D36: 1 | E36: 1 | F36: 0 | G36: 0 | H36: 0 | I36: 2 | J36: 1 | K36: 0 | L36: 0 | M36: 14 | N36: 0 | O36: =SUM(C36:L36,N36) -> 10 | P36: =SUM(C36:N36) -> 24
B37: 13.45 - 14.00 | C37: 4 | D37: 0 | E37: 1 | F37: 2 | G37: 0 | H37: 0 | I37: 3 | J37: 2 | K37: 1 | L37: 0 | M37: 21 | N37: 0 | O37: =SUM(C37:L37,N37) -> 13 | P37: =SUM(C37:N37) -> 34
B38: 14.00 - 14.15 | C38: 6 | D38: 0 | E38: 2 | F38: 1 | G38: 1 | H38: 0 | I38: 2 | J38: 1 | K38: 0 | L38: 0 | M38: 15 | N38: 0 | O38: =SUM(C38:L38,N38) -> 13 | P38: =SUM(C38:N38) -> 28
B39: 14.15 - 14.30 | C39: 4 | D39: 0 | E39: 0 | F39: 0 | G39: 0 | H39: 0 | I39: 1 | J39: 1 | K39: 0 | L39: 0 | M39: 11 | N39: 0 | O39: =SUM(C39:L39,N39) -> 6 | P39: =SUM(C39:N39) -> 17
B40: 14.30 - 14.45 | C40: 3 | D40: 1 | E40: 0 | F40: 0 | G40: 0 | H40: 0 | I40: 2 | J40: 0 | K40: 0 | L40: 0 | M40: 15 | N40: 0 | O40: =SUM(C40:L40,N40) -> 6 | P40: =SUM(C40:N40) -> 21
... B57: 18.45 - 19.00 | C57: 3 | D57: 1 | E57: 4 | F57: 2 | G57: 0 | H57: 0 | I57: 1 | J57: 2 | K57: 0 | L57: 0 | M57: 22 | N57: 0 | O57: =SUM(C57:L57,N57) -> 13 | P57: =SUM(C57:N57) -> 35
B58: Totals | C58: =SUM(C10:C57) -> 243 | D58: =SUM(D10:D57) -> 47 | E58: =SUM(E10:E57) -> 66 | F58: =SUM(F10:F57) -> 39 | G58: =SUM(G10:G57) -> 5 | H58: =SUM(H10:H57) -> 0 | I58: =SUM(I10:I57) -> 95 | J58: =SUM(J10:J57) -> 34 | ... N58: =SUM(N10:N57) -> 1 | O58: =SUM(C58:L58,N58) -> 540 | P58: =SUM(P10:P57) -> 1457
...

Sheet 25.09 Bukasa-Wakiso
B1: Consultancy services for Preparation of Expressway Development Master Plan (EDMP) for Uganda
B2: MANUAL CLASSIFIED COUNT (MCC)
B3: ROAD NAME: | C3: ='23.09 Bukasa-Wakiso'!C3:G3 -> MCC - C2 - STN0-64- BUKASA-WAKISO ROAD
C5: Date | D5: 24.09.19 | F5: Location | G5: ='23.09 Bukasa-Wakiso'!G5:H5 -> Wakiso Junior Sch. | J5: Surveyor | K5: ='23.09 Bukasa-Wakiso'!K5:L5 -> Farida
C6: Dir. From | D6: ='23.09 Bukasa-Wakiso'!D6:E6 -> Bukasa | F6: Dir. To | G6: ='23.09 Bukasa-Wakiso'!G6:H6 -> Wakiso | J6: Supervisor | K6: ='23.09 Bukasa-Wakiso'!K6:L6 -> Nusurah
B8: Time / Veh Type | R8: SUMMARY TRAFFIC VOLUMES
C9: 1. Car | D9: 2. Station Wagon | E9: 3. Pickups | F9: 4. Minibus, matatu | G9: 5. Medium bus | H9: 6. Large Bus | I9: 7. Light Truck | J9: 8. Medium Truck | K9: 9. Heavy truck | L9: 10. Truck Trailer | M9: 11. Motor cycles | N9: 12. Tractors | O9: Total Excl M/Cycles | P9: Total All | R9: Time | S9: 1. Car | T9: 2. Station Wagon | U9: 3. Pickups | V9: 4. Minibus, matatu | W9: 5. Medium bus | X9: 6. Large Bus | Y9: 7. Light Truck | Z9: 8. Medium Truck | AA9: 9. Heavy truck | AB9: 10. Truck Trailer | AC9: 11. Motorcycles | AD9: 12. Tractors, Graders | AE9: Total Excl M/ Cycles | AF9: Total All
B10: 07.00 - 07.15 | C10: 10 | D10: 5 | E10: 1 | F10: 2 | G10: 1 | H10: 0 | I10: 3 | J10: 0 | K10: 0 | L10: 0 | M10: 15 | N10: 0 | O10: =SUM(C10:L10,N10) -> 22 | P10: =SUM(C10:N10) -> 37 | R10: 0700-0800 | S10: =SUM(C10:C13) -> 25 | T10: =SUM(D10:D13) -> 22 | U10: =SUM(E10:E13) -> 3 | V10: =SUM(F10:F13) -> 6 | W10: =SUM(G10:G13) -> 1 | X10: =SUM(H10:H13) -> 0 | Y10: =SUM(I10:I13) -> 12 | Z10: =SUM(J10:J13) -> 1 | ... AF10: =SUM(P10:P13) -> 120
B11: 07.15 - 07.30 | C11: 4 | D11: 4 | E11: 1 | F11: 1 | G11: 0 | H11: 0 | I11: 2 | J11: 0 | K11: 0 | L11: 0 | M11: 13 | N11: 0 | O11: =SUM(C11:L11,N11) -> 12 | P11: =SUM(C11:N11) -> 25 | R11: 0800-0900 | S11: =SUM(C14:C17) -> 32 | T11: =SUM(D14:D17) -> 25 | U11: =SUM(E14:E17) -> 3 | V11: =SUM(F14:F17) -> 7 | W11: =SUM(G14:G17) -> 0 | X11: =SUM(H14:H17) -> 0 | Y11: =SUM(I14:I17) -> 9 | Z11: =SUM(J14:J17) -> 0 | ... AF11: =SUM(P14:P17) -> 151
B12: 07.30 - 07.45 | C12: 4 | D12: 1 | E12: 1 | F12: 2 | G12: 0 | H12: 0 | I12: 4 | J12: 0 | K12: 0 | L12: 0 | M12: 8 | N12: 0 | O12: =SUM(C12:L12,N12) -> 12 | P12: =SUM(C12:N12) -> 20 | R12: 0900-1000 | S12: =SUM(C18:C21) -> 25 | T12: =SUM(D18:D21) -> 14 | U12: =SUM(E18:E21) -> 3 | V12: =SUM(F18:F21) -> 0 | W12: =SUM(G18:G21) -> 0 | X12: =SUM(H18:H21) -> 0 | Y12: =SUM(I18:I21) -> 13 | Z12: =SUM(J18:J21) -> 2 | ... AF12: =SUM(P18:P21) -> 120
B13: 07.45 - 08.00 | C13: 7 | D13: 12 | E13: 0 | F13: 1 | G13: 0 | H13: 0 | I13: 3 | J13: 1 | K13: 0 | L13: 0 | M13: 14 | N13: 0 | O13: =SUM(C13:L13,N13) -> 24 | P13: =SUM(C13:N13) -> 38 | R13: 1000-1100 | S13: =SUM(C22:C25) -> 20 | T13: =SUM(D22:D25) -> 15 | U13: =SUM(E22:E25) -> 4 | V13: =SUM(F22:F25) -> 2 | W13: =SUM(G22:G25) -> 0 | X13: =SUM(H22:H25) -> 0 | Y13: =SUM(I22:I25) -> 17 | Z13: =SUM(J22:J25) -> 5 | ... AF13: =SUM(P22:P25) -> 123
B14: 08.00 - 08.15 | C14: 8 | D14: 7 | E14: 1 | F14: 4 | G14: 0 | H14: 0 | I14: 0 | J14: 0 | K14: 0 | L14: 0 | M14: 18 | N14: 0 | O14: =SUM(C14:L14,N14) -> 20 | P14: =SUM(C14:N14) -> 38 | R14: 1100-1200 | S14: =SUM(C26:C29) -> 12 | T14: =SUM(D26:D29) -> 5 | U14: =SUM(E26:E29) -> 5 | V14: =SUM(F26:F29) -> 1 | W14: =SUM(G26:G29) -> 0 | X14: =SUM(H26:H29) -> 0 | Y14: =SUM(I26:I29) -> 11 | Z14: =SUM(J26:J29) -> 1 | ... AF14: =SUM(P26:P29) -> 91
B15: 08.15 - 08.30 | C15: 10 | D15: 5 | E15: 1 | F15: 0 | G15: 0 | H15: 0 | I15: 3 | J15: 0 | K15: 1 | L15: 0 | M15: 20 | N15: 0 | O15: =SUM(C15:L15,N15) -> 20 | P15: =SUM(C15:N15) -> 40 | R15: 1200-1300 | S15: =SUM(C30:C33) -> 14 | T15: =SUM(D30:D33) -> 13 | U15: =SUM(E30:E33) -> 2 | V15: =SUM(F30:F33) -> 2 | W15: =SUM(G30:G33) -> 0 | X15: =SUM(H30:H33) -> 0 | Y15: =SUM(I30:I33) -> 10 | Z15: =SUM(J30:J33) -> 2 | ... AF15: =SUM(P30:P33) -> 97
B16: 08.30 - 08.45 | C16: 8 | D16: 6 | E16: 1 | F16: 1 | G16: 0 | H16: 0 | I16: 2 | J16: 0 | K16: 0 | L16: 0 | M16: 21 | N16: 0 | O16: =SUM(C16:L16,N16) -> 18 | P16: =SUM(C16:N16) -> 39 | R16: 1300-1400 | S16: =SUM(C34:C37) -> 18 | T16: =SUM(D34:D37) -> 12 | U16: =SUM(E34:E37) -> 1 | V16: =SUM(F34:F37) -> 2 | W16: =SUM(G34:G37) -> 0 | X16: =SUM(H34:H37) -> 0 | Y16: =SUM(I34:I37) -> 8 | Z16: =SUM(J34:J37) -> 1 | ... AF16: =SUM(P34:P37) -> 76
B17: 08.45 - 9.00 | C17: 6 | D17: 7 | E17: 0 | F17: 2 | G17: 0 | H17: 0 | I17: 4 | J17: 0 | K17: 0 | L17: 0 | M17: 15 | N17: 0 | O17: =SUM(C17:L17,N17) -> 19 | P17: =SUM(C17:N17) -> 34 | R17: 1400-1500 | S17: =SUM(C38:C41) -> 23 | T17: =SUM(D38:D41) -> 22 | U17: =SUM(E38:E41) -> 4 | V17: =SUM(F38:F41) -> 2 | W17: =SUM(G38:G41) -> 0 | X17: =SUM(H38:H41) -> 0 | Y17: =SUM(I38:I41) -> 8 | Z17: =SUM(J38:J41) -> 0 | ... AF17: =SUM(P38:P41) -> 112
B18: 09.00 - 09.15 | C18: 7 | D18: 4 | E18: 0 | F18: 0 | G18: 0 | H18: 0 | I18: 5 | J18: 0 | K18: 0 | L18: 0 | M18: 13 | N18: 0 | O18: =SUM(C18:L18,N18) -> 16 | P18: =SUM(C18:N18) -> 29 | R18: 1500-1600 | S18: =SUM(C42:C45) -> 20 | T18: =SUM(D42:D45) -> 18 | U18: =SUM(E42:E45) -> 7 | V18: =SUM(F42:F45) -> 3 | W18: =SUM(G42:G45) -> 0 | X18: =SUM(H42:H45) -> 0 | Y18: =SUM(I42:I45) -> 10 | Z18: =SUM(J42:J45) -> 0 | ... AF18: =SUM(P42:P45) -> 118
B19: 09.15 - 09.30 | C19: 8 | D19: 5 | E19: 1 | F19: 0 | G19: 0 | H19: 0 | I19: 3 | J19: 1 | K19: 0 | L19: 0 | M19: 10 | N19: 0 | O19: =SUM(C19:L19,N19) -> 18 | P19: =SUM(C19:N19) -> 28 | R19: 1600-1700 | S19: =SUM(C46:C49) -> 17 | T19: =SUM(D46:D49) -> 12 | U19: =SUM(E46:E49) -> 4 | V19: =SUM(F46:F49) -> 4 | W19: =SUM(G46:G49) -> 0 | X19: =SUM(H46:H49) -> 0 | Y19: =SUM(I46:I49) -> 7 | Z19: =SUM(J46:J49) -> 0 | ... AF19: =SUM(P46:P49) -> 99
B20: 09.30 - 09.45 | C20: 4 | D20: 2 | E20: 0 | F20: 0 | G20: 0 | H20: 0 | I20: 2 | J20: 1 | K20: 0 | L20: 0 | M20: 22 | N20: 0 | O20: =SUM(C20:L20,N20) -> 9 | P20: =SUM(C20:N20) -> 31 | R20: 1700-1800 | S20: =SUM(C50:C53) -> 22 | T20: =SUM(D50:D53) -> 14 | U20: =SUM(E50:E53) -> 7 | V20: =SUM(F50:F53) -> 7 | W20: =SUM(G50:G53) -> 2 | X20: =SUM(H50:H53) -> 0 | Y20: =SUM(I50:I53) -> 7 | Z20: =SUM(J50:J53) -> 3 | ... AF20: =SUM(P50:P53) -> 123
B21: 09.45 - 10.00 | C21: 6 | D21: 3 | E21: 2 | F21: 0 | G21: 0 | H21: 0 | I21: 3 | J21: 0 | K21: 0 | L21: 0 | M21: 18 | N21: 0 | O21: =SUM(C21:L21,N21) -> 14 | P21: =SUM(C21:N21) -> 32 | R21: 1800-1900 | S21: =SUM(C54:C57) -> 18 | T21: =SUM(D54:D57) -> 17 | U21: =SUM(E54:E57) -> 3 | V21: =SUM(F54:F57) -> 3 | W21: =SUM(G54:G57) -> 0 | X21: =SUM(H54:H57) -> 0 | Y21: =SUM(I54:I57) -> 10 | Z21: =SUM(J54:J57) -> 1 | ... AF21: =SUM(P54:P57) -> 140
B22: 10.00 - 10.15 | C22: 4 | D22: 4 | E22: 2 | F22: 2 | G22: 0 | H22: 0 | I22: 8 | J22: 3 | K22: 0 | L22: 0 | M22: 22 | N22: 0 | O22: =SUM(C22:L22,N22) -> 23 | P22: =SUM(C22:N22) -> 45 | R22: AM Peak Hr | S22: =MAX(S10:S12) -> 32 | T22: =MAX(T10:T12) -> 25 | U22: =MAX(U10:U12) -> 3 | V22: =MAX(V10:V12) -> 7 | W22: =MAX(W10:W12) -> 1 | X22: =MAX(X10:X12) -> 0 | Y22: =MAX(Y10:Y12) -> 13 | Z22: =MAX(Z10:Z12) -> 2 | ... AF22: =MAX(AF10:AF12) -> 151
B23: 10.15 - 10.30 | C23: 5 | D23: 3 | E23: 2 | F23: 0 | G23: 0 | H23: 0 | I23: 5 | J23: 0 | K23: 0 | L23: 0 | M23: 17 | N23: 0 | O23: =SUM(C23:L23,N23) -> 15 | P23: =SUM(C23:N23) -> 32 | R23: IP Peak Hr | S23: =MAX(S13:S18) -> 23 | T23: =MAX(T13:T18) -> 22 | U23: =MAX(U13:U18) -> 7 | V23: =MAX(V13:V18) -> 3 | W23: =MAX(W13:W18) -> 0 | X23: =MAX(X13:X18) -> 0 | Y23: =MAX(Y13:Y18) -> 17 | Z23: =MAX(Z13:Z18) -> 5 | ... AF23: =MAX(AF13:AF18) -> 123
B24: 10.30 - 10.45 | C24: 5 | D24: 5 | E24: 0 | F24: 0 | G24: 0 | H24: 0 | I24: 3 | J24: 1 | K24: 0 | L24: 0 | M24: 12 | N24: 0 | O24: =SUM(C24:L24,N24) -> 14 | P24: =SUM(C24:N24) -> 26 | R24: PM Peak Hr | S24: =MAX(S19:S21) -> 22 | T24: =MAX(T19:T21) -> 17 | U24: =MAX(U19:U21) -> 7 | V24: =MAX(V19:V21) -> 7 | W24: =MAX(W19:W21) -> 2 | X24: =MAX(X19:X21) -> 0 | Y24: =MAX(Y19:Y21) -> 10 | Z24: =MAX(Z19:Z21) -> 3 | ... AF24: =MAX(AF19:AF21) -> 140
B25: 10.45 - 11.00 | C25: 6 | D25: 3 | E25: 0 | F25: 0 | G25: 0 | H25: 0 | I25: 1 | J25: 1 | K25: 0 | L25: 0 | M25: 9 | N25: 0 | O25: =SUM(C25:L25,N25) -> 11 | P25: =SUM(C25:N25) -> 20 | R25: AM Period | S25: =SUM(S10:S12) -> 82 | T25: =SUM(T10:T12) -> 61 | U25: =SUM(U10:U12) -> 9 | V25: =SUM(V10:V12) -> 13 | W25: =SUM(W10:W12) -> 1 | X25: =SUM(X10:X12) -> 0 | Y25: =SUM(Y10:Y12) -> 34 | Z25: =SUM(Z10:Z12) -> 3 | ... AF25: =SUM(AF10:AF12) -> 391
B26: 11.00 - 11.15 | C26: 4 | D26: 0 | E26: 1 | F26: 0 | G26: 0 | H26: 0 | I26: 1 | J26: 0 | K26: 0 | L26: 0 | M26: 12 | N26: 0 | O26: =SUM(C26:L26,N26) -> 6 | P26: =SUM(C26:N26) -> 18 | R26: IP Period | S26: =SUM(S13:S18) -> 107 | T26: =SUM(T13:T18) -> 85 | U26: =SUM(U13:U18) -> 23 | V26: =SUM(V13:V18) -> 12 | W26: =SUM(W13:W18) -> 0 | X26: =SUM(X13:X18) -> 0 | Y26: =SUM(Y13:Y18) -> 64 | Z26: =SUM(Z13:Z18) -> 9 | ... AF26: =SUM(AF13:AF18) -> 617
B27: 11.15 - 11.30 | C27: 1 | D27: 0 | E27: 2 | F27: 0 | G27: 0 | H27: 0 | I27: 1 | J27: 0 | K27: 0 | L27: 0 | M27: 16 | N27: 0 | O27: =SUM(C27:L27,N27) -> 4 | P27: =SUM(C27:N27) -> 20 | R27: PM Period | S27: =SUM(S19:S21) -> 57 | T27: =SUM(T19:T21) -> 43 | U27: =SUM(U19:U21) -> 14 | V27: =SUM(V19:V21) -> 14 | W27: =SUM(W19:W21) -> 2 | X27: =SUM(X19:X21) -> 0 | Y27: =SUM(Y19:Y21) -> 24 | Z27: =SUM(Z19:Z21) -> 4 | ... AF27: =SUM(AF19:AF21) -> 362
B28: 11.30 - 11.45 | C28: 3 | D28: 3 | E28: 1 | F28: 1 | G28: 0 | H28: 0 | I28: 6 | J28: 1 | K28: 0 | L28: 0 | M28: 15 | N28: 0 | O28: =SUM(C28:L28,N28) -> 15 | P28: =SUM(C28:N28) -> 30 | R28: 12 Hours | S28: =SUM(S10:S21) -> 246 | T28: =SUM(T10:T21) -> 189 | U28: =SUM(U10:U21) -> 46 | V28: =SUM(V10:V21) -> 39 | W28: =SUM(W10:W21) -> 3 | X28: =SUM(X10:X21) -> 0 | Y28: =SUM(Y10:Y21) -> 122 | Z28: =SUM(Z10:Z21) -> 16 | ... AF28: =SUM(AF10:AF21) -> 1370
B29: 11.45 - 12.00 | C29: 4 | D29: 2 | E29: 1 | F29: 0 | G29: 0 | H29: 0 | I29: 3 | J29: 0 | K29: 0 | L29: 0 | M29: 13 | N29: 0 | O29: =SUM(C29:L29,N29) -> 10 | P29: =SUM(C29:N29) -> 23
B30: 12.00 - 12.15 | C30: 4 | D30: 5 | E30: 0 | F30: 2 | G30: 0 | H30: 0 | I30: 1 | J30: 1 | K30: 0 | L30: 0 | M30: 13 | N30: 0 | O30: =SUM(C30:L30,N30) -> 13 | P30: =SUM(C30:N30) -> 26
B31: 12.15 - 12.30 | C31: 3 | D31: 1 | E31: 1 | F31: 0 | G31: 0 | H31: 0 | I31: 0 | J31: 0 | K31: 0 | L31: 0 | M31: 14 | N31: 0 | O31: =SUM(C31:L31,N31) -> 5 | P31: =SUM(C31:N31) -> 19
