Workbook

Sheet 29.10 Bujuko-Buloba
B1: Consultancy services for Preparation of Expressway Development Master Plan (EDMP) for Uganda
B2: MANUAL CLASSIFIED COUNT (MCC)
B3: ROAD NAME: | C3: MCC - C2 - STN62 - BUJUKO-BULOBA ROAD
C5: Date | D5: 29.10.19 | F5: Location | G5: Buloba Pop Oil | J5: Surveyor | K5: Nakiwuge A
C6: Dir. From | D6: Bujuko | F6: Dir. To | G6: Buloba | J6: Supervisor | K6: Godfrey
B8: Time / Veh Type | R8: SUMMARY TRAFFIC VOLUMES
C9: 1. Car | D9: 2. Station Wagon | E9: 3. Pickups | F9: 4. Minibus, matatu | G9: 5. Medium bus | H9: 6. Large Bus | I9: 7. Light Truck | J9: 8. Medium Truck | K9: 9. Heavy truck | L9: 10. Truck Trailer | M9: 11. Motor cycles | N9: 12. Tractors | O9: Total Excl M/Cycles | P9: Total All | R9: Time | S9: 1. Car | T9: 2. Station Wagon | U9: 3. Pickups | V9: 4. Minibus, matatu | W9: 5. Medium bus | X9: 6. Large Bus | Y9: 7. Light Truck | Z9: 8. Medium Truck | AA9: 9. Heavy truck | AB9: 10. Truck Trailer | AC9: 11. Motorcycles | AD9: 12. Tractors, Graders | AE9: Total Excl M/ Cycles | AF9: Total All
B10: 07.00 - 07.15 | C10: 26 | D10: 1 | E10: 3 | F10: 22 | G10: 1 | H10: 0 | I10: 4 | J10: 1 | K10: 0 | L10: 1 | M10: 38 | N10: 0 | O10: =SUM(C10:L10,N10) -> 59 | P10: =SUM(C10:N10) -> 97 | R10: 0700-0800 | S10: =SUM(C10:C13) -> 71 | T10: =SUM(D10:D13) -> 5 | U10: =SUM(E10:E13) -> 6 | V10: =SUM(F10:F13) -> 61 | W10: =SUM(G10:G13) -> 1 | X10: =SUM(H10:H13) -> 0 | Y10: =SUM(I10:I13) -> 11 | Z10: =SUM(J10:J13) -> 6 | ... AF10: =SUM(P10:P13) -> 256
B11: 07.15 - 07.30 | C11: 11 | D11: 3 | E11: 0 | F11: 16 | G11: 0 | H11: 0 | I11: 4 | J11: 3 | K11: 0 | L11: 0 | M11: 12 | N11: 0 | O11: =SUM(C11:L11,N11) -> 37 | P11: =SUM(C11:N11) -> 49 | R11: 0800-0900 | S11: =SUM(C14:C17) -> 72 | T11: =SUM(D14:D17) -> 8 | U11: =SUM(E14:E17) -> 7 | V11: =SUM(F14:F17) -> 58 | W11: =SUM(G14:G17) -> 0 | X11: =SUM(H14:H17) -> 0 | Y11: =SUM(I14:I17) -> 15 | Z11: =SUM(J14:J17) -> 8 | ... AF11: =SUM(P14:P17) -> 261
B12: 07.30 - 07.45 | C12: 23 | D12: 0 | E12: 3 | F12: 12 | G12: 0 | H12: 0 | I12: 2 | J12: 2 | K12: 0 | L12: 0 | M12: 21 | N12: 0 | O12: =SUM(C12:L12,N12) -> 42 | P12: =SUM(C12:N12) -> 63 | R12: 0900-1000 | S12: =SUM(C18:C21) -> 46 | T12: =SUM(D18:D21) -> 5 | U12: =SUM(E18:E21) -> 3 | V12: =SUM(F18:F21) -> 49 | W12: =SUM(G18:G21) -> 1 | X12: =SUM(H18:H21) -> 0 | Y12: =SUM(I18:I21) -> 13 | Z12: =SUM(J18:J21) -> 10 | ... AF12: =SUM(P18:P21) -> 215
B13: 07.45 - 08.00 | C13: 11 | D13: 1 | E13: 0 | F13: 11 | G13: 0 | H13: 0 | I13: 1 | J13: 0 | K13: 0 | L13: 0 | M13: 23 | N13: 0 | O13: =SUM(C13:L13,N13) -> 24 | P13: =SUM(C13:N13) -> 47 | R13: 1000-1100 | S13: =SUM(C22:C25) -> 56 | T13: =SUM(D22:D25) -> 5 | U13: =SUM(E22:E25) -> 7 | V13: =SUM(F22:F25) -> 51 | W13: =SUM(G22:G25) -> 1 | X13: =SUM(H22:H25) -> 1 | Y13: =SUM(I22:I25) -> 15 | Z13: =SUM(J22:J25) -> 6 | ... AF13: =SUM(P22:P25) -> 224
B14: 08.00 - 08.15 | C14: 7 | D14: 1 | E14: 0 | F14: 17 | G14: 0 | H14: 0 | I14: 1 | J14: 0 | K14: 0 | L14: 0 | M14: 24 | N14: 0 | O14: =SUM(C14:L14,N14) -> 26 | P14: =SUM(C14:N14) -> 50 | R14: 1100-1200 | S14: =SUM(C26:C29) -> 71 | T14: =SUM(D26:D29) -> 8 | U14: =SUM(E26:E29) -> 5 | V14: =SUM(F26:F29) -> 56 | W14: =SUM(G26:G29) -> 1 | X14: =SUM(H26:H29) -> 0 | Y14: =SUM(I26:I29) -> 25 | Z14: =SUM(J26:J29) -> 5 | ... AF14: =SUM(P26:P29) -> 256
B15: 08.15 - 08.30 | C15: 20 | D15: 4 | E15: 2 | F15: 14 | G15: 0 | H15: 0 | I15: 2 | J15: 2 | K15: 0 | L15: 1 | M15: 36 | N15: 0 | O15: =SUM(C15:L15,N15) -> 45 | P15: =SUM(C15:N15) -> 81 | R15: 1200-1300 | S15: =SUM(C30:C33) -> 36 | T15: =SUM(D30:D33) -> 8 | U15: =SUM(E30:E33) -> 6 | V15: =SUM(F30:F33) -> 55 | W15: =SUM(G30:G33) -> 1 | X15: =SUM(H30:H33) -> 1 | Y15: =SUM(I30:I33) -> 26 | Z15: =SUM(J30:J33) -> 8 | ... AF15: =SUM(P30:P33) -> 200
B16: 08.30 - 08.45 | C16: 22 | D16: 2 | E16: 5 | F16: 14 | G16: 0 | H16: 0 | I16: 2 | J16: 4 | K16: 0 | L16: 1 | M16: 8 | N16: 0 | O16: =SUM(C16:L16,N16) -> 50 | P16: =SUM(C16:N16) -> 58 | R16: 1300-1400 | S16: =SUM(C34:C37) -> 80 | T16: =SUM(D34:D37) -> 13 | U16: =SUM(E34:E37) -> 18 | V16: =SUM(F34:F37) -> 53 | W16: =SUM(G34:G37) -> 0 | X16: =SUM(H34:H37) -> 2 | Y16: =SUM(I34:I37) -> 24 | Z16: =SUM(J34:J37) -> 11 | ... AF16: =SUM(P34:P37) -> 276
B17: 08.45 - 9.00 | C17: 23 | D17: 1 | E17: 0 | F17: 13 | G17: 0 | H17: 0 | I17: 10 | J17: 2 | K17: 0 | L17: 0 | M17: 23 | N17: 0 | O17: =SUM(C17:L17,N17) -> 49 | P17: =SUM(C17:N17) -> 72 | R17: 1400-1500 | S17: =SUM(C38:C41) -> 59 | T17: =SUM(D38:D41) -> 9 | U17: =SUM(E38:E41) -> 14 | V17: =SUM(F38:F41) -> 56 | W17: =SUM(G38:G41) -> 0 | X17: =SUM(H38:H41) -> 2 | Y17: =SUM(I38:I41) -> 23 | Z17: =SUM(J38:J41) -> 14 | ... AF17: =SUM(P38:P41) -> 273
B18: 09.00 - 09.15 | C18: 6 | D18: 2 | E18: 0 | F18: 11 | G18: 0 | H18: 0 | I18: 2 | J18: 4 | K18: 0 | L18: 0 | M18: 22 | N18: 0 | O18: =SUM(C18:L18,N18) -> 25 | P18: =SUM(C18:N18) -> 47 | R18: 1500-1600 | S18: =SUM(C42:C45) -> 84 | T18: =SUM(D42:D45) -> 15 | U18: =SUM(E42:E45) -> 17 | V18: =SUM(F42:F45) -> 61 | W18: =SUM(G42:G45) -> 1 | X18: =SUM(H42:H45) -> 2 | Y18: =SUM(I42:I45) -> 25 | Z18: =SUM(J42:J45) -> 11 | ... AF18: =SUM(P42:P45) -> 309
B19: 09.15 - 09.30 | C19: 11 | D19: 2 | E19: 1 | F19: 14 | G19: 1 | H19: 0 | I19: 1 | J19: 2 | K19: 0 | L19: 0 | M19: 30 | N19: 0 | O19: =SUM(C19:L19,N19) -> 32 | P19: =SUM(C19:N19) -> 62 | R19: 1600-1700 | S19: =SUM(C46:C49) -> 91 | T19: =SUM(D46:D49) -> 20 | U19: =SUM(E46:E49) -> 13 | V19: =SUM(F46:F49) -> 58 | W19: =SUM(G46:G49) -> 1 | X19: =SUM(H46:H49) -> 7 | Y19: =SUM(I46:I49) -> 24 | Z19: =SUM(J46:J49) -> 11 | ... AF19: =SUM(P46:P49) -> 333
B20: 09.30 - 09.45 | C20: 12 | D20: 1 | E20: 2 | F20: 11 | G20: 0 | H20: 0 | I20: 6 | J20: 4 | K20: 0 | L20: 1 | M20: 21 | N20: 0 | O20: =SUM(C20:L20,N20) -> 37 | P20: =SUM(C20:N20) -> 58 | R20: 1700-1800 | S20: =SUM(C50:C53) -> 87 | T20: =SUM(D50:D53) -> 22 | U20: =SUM(E50:E53) -> 21 | V20: =SUM(F50:F53) -> 64 | W20: =SUM(G50:G53) -> 3 | X20: =SUM(H50:H53) -> 0 | Y20: =SUM(I50:I53) -> 27 | Z20: =SUM(J50:J53) -> 7 | ... AF20: =SUM(P50:P53) -> 320
B21: 09.45 - 10.00 | C21: 17 | D21: 0 | E21: 0 | F21: 13 | G21: 0 | H21: 0 | I21: 4 | J21: 0 | K21: 0 | L21: 0 | M21: 14 | N21: 0 | O21: =SUM(C21:L21,N21) -> 34 | P21: =SUM(C21:N21) -> 48 | R21: 1800-1900 | S21: =SUM(C54:C57) -> 102 | T21: =SUM(D54:D57) -> 14 | U21: =SUM(E54:E57) -> 24 | V21: =SUM(F54:F57) -> 101 | W21: =SUM(G54:G57) -> 4 | X21: =SUM(H54:H57) -> 3 | Y21: =SUM(I54:I57) -> 31 | Z21: =SUM(J54:J57) -> 11 | ... AF21: =SUM(P54:P57) -> 431
B22: 10.00 - 10.15 | C22: 11 | D22: 3 | E22: 2 | F22: 21 | G22: 0 | H22: 0 | I22: 3 | J22: 1 | K22: 1 | L22: 1 | M22: 28 | N22: 0 | O22: =SUM(C22:L22,N22) -> 43 | P22: =SUM(C22:N22) -> 71 | R22: AM Peak Hr | S22: =MAX(S10:S12) -> 72 | T22: =MAX(T10:T12) -> 8 | U22: =MAX(U10:U12) -> 7 | V22: =MAX(V10:V12) -> 61 | W22: =MAX(W10:W12) -> 1 | X22: =MAX(X10:X12) -> 0 | Y22: =MAX(Y10:Y12) -> 15 | Z22: =MAX(Z10:Z12) -> 10 | ... AF22: =MAX(AF10:AF12) -> 261
B23: 10.15 - 10.30 | C23: 13 | D23: 1 | E23: 1 | F23: 5 | G23: 0 | H23: 0 | I23: 2 | J23: 2 | K23: 0 | L23: 2 | M23: 17 | N23: 0 | O23: =SUM(C23:L23,N23) -> 26 | P23: =SUM(C23:N23) -> 43 | R23: IP Peak Hr | S23: =MAX(S13:S18) -> 84 | T23: =MAX(T13:T18) -> 15 | U23: =MAX(U13:U18) -> 18 | V23: =MAX(V13:V18) -> 61 | W23: =MAX(W13:W18) -> 1 | X23: =MAX(X13:X18) -> 2 | Y23: =MAX(Y13:Y18) -> 26 | Z23: =MAX(Z13:Z18) -> 14 | ... AF23: =MAX(AF13:AF18) -> 309
B24: 10.30 - 10.45 | C24: 20 | D24: 1 | E24: 4 | F24: 14 | G24: 0 | H24: 1 | I24: 5 | J24: 2 | K24: 0 | L24: 3 | M24: 20 | N24: 0 | O24: =SUM(C24:L24,N24) -> 50 | P24: =SUM(C24:N24) -> 70 | R24: PM Peak Hr | S24: =MAX(S19:S21) -> 102 | T24: =MAX(T19:T21) -> 22 | U24: =MAX(U19:U21) -> 24 | V24: =MAX(V19:V21) -> 101 | W24: =MAX(W19:W21) -> 4 | X24: =MAX(X19:X21) -> 7 | Y24: =MAX(Y19:Y21) -> 31 | Z24: =MAX(Z19:Z21) -> 11 | ... AF24: =MAX(AF19:AF21) -> 431
B25: 10.45 - 11.00 | C25: 12 | D25: 0 | E25: 0 | F25: 11 | G25: 1 | H25: 0 | I25: 5 | J25: 1 | K25: 0 | L25: 0 | M25: 10 | N25: 0 | O25: =SUM(C25:L25,N25) -> 30 | P25: =SUM(C25:N25) -> 40 | R25: AM Period | S25: =SUM(S10:S12) -> 189 | T25: =SUM(T10:T12) -> 18 | U25: =SUM(U10:U12) -> 16 | V25: =SUM(V10:V12) -> 168 | W25: =SUM(W10:W12) -> 2 | X25: =SUM(X10:X12) -> 0 | Y25: =SUM(Y10:Y12) -> 39 | Z25: =SUM(Z10:Z12) -> 24 | ... AF25: =SUM(AF10:AF12) -> 732
B26: 11.00 - 11.15 | C26: 10 | D26: 0 | E26: 1 | F26: 15 | G26: 0 | H26: 0 | I26: 8 | J26: 1 | K26: 0 | L26: 2 | M26: 24 | N26: 0 | O26: =SUM(C26:L26,N26) -> 37 | P26: =SUM(C26:N26) -> 61 | R26: IP Period | S26: =SUM(S13:S18) -> 386 | T26: =SUM(T13:T18) -> 58 | U26: =SUM(U13:U18) -> 67 | V26: =SUM(V13:V18) -> 332 | W26: =SUM(W13:W18) -> 4 | X26: =SUM(X13:X18) -> 8 | Y26: =SUM(Y13:Y18) -> 138 | Z26: =SUM(Z13:Z18) -> 55 | ... AF26: =SUM(AF13:AF18) -> 1538
B27: 11.15 - 11.30 | C27: 20 | D27: 4 | E27: 1 | F27: 15 | G27: 0 | H27: 0 | I27: 2 | J27: 0 | K27: 0 | L27: 1 | M27: 21 | N27: 0 | O27: =SUM(C27:L27,N27) -> 43 | P27: =SUM(C27:N27) -> 64 | R27: PM Period | S27: =SUM(S19:S21) -> 280 | T27: =SUM(T19:T21) -> 56 | U27: =SUM(U19:U21) -> 58 | V27: =SUM(V19:V21) -> 223 | W27: =SUM(W19:W21) -> 8 | X27: =SUM(X19:X21) -> 10 | Y27: =SUM(Y19:Y21) -> 82 | Z27: =SUM(Z19:Z21) -> 29 | ... AF27: =SUM(AF19:AF21) -> 1084
B28: 11.30 - 11.45 | C28: 14 | D28: 1 | E28: 2 | F28: 11 | G28: 0 | H28: 0 | I28: 6 | J28: 2 | K28: 0 | L28: 0 | M28: 17 | N28: 0 | O28: =SUM(C28:L28,N28) -> 36 | P28: =SUM(C28:N28) -> 53 | R28: 12 Hours | S28: =SUM(S10:S21) -> 855 | T28: =SUM(T10:T21) -> 132 | U28: =SUM(U10:U21) -> 141 | V28: =SUM(V10:V21) -> 723 | W28: =SUM(W10:W21) -> 14 | X28: =SUM(X10:X21) -> 18 | Y28: =SUM(Y10:Y21) -> 259 | Z28: =SUM(Z10:Z21) -> 108 | ... AF28: =SUM(AF10:AF21) -> 3354
B29: 11.45 - 12.00 | C29: 27 | D29: 3 | E29: 1 | F29: 15 | G29: 1 | H29: 0 | I29: 9 | J29: 2 | K29: 0 | L29: 0 | M29: 20 | N29: 0 | O29: =SUM(C29:L29,N29) -> 58 | P29: =SUM(C29:N29) -> 78
B30: 12.00 - 12.15 | C30: 6 | D30: 2 | E30: 3 | F30: 11 | G30: 0 | H30: 0 | I30: 4 | J30: 0 | K30: 0 | L30: 1 | M30: 16 | N30: 0 | O30: =SUM(C30:L30,N30) -> 27 | P30: =SUM(C30:N30) -> 43
B31: 12.15 - 12.30 | C31: 8 | D31: 2 | E31: 1 | F31: 13 | G31: 0 | H31: 0 | I31: 9 | J31: 3 | K31: 0 | L31: 1 | M31: 8 | N31: 0 | O31: =SUM(C31:L31,N31) -> 37 | P31: =SUM(C31:N31) -> 45
B32: 12.30 - 12.45 | C32: 17 | D32: 1 | E32: 2 | F32: 19 | G32: 0 | H32: 1 | I32: 9 | J32: 4 | K32: 1 | L32: 2 | M32: 14 | N32: 0 | O32: =SUM(C32:L32,N32) -> 56 | P32: =SUM(C32:N32) -> 70
B33: 12.45 - 13.00 | C33: 5 | D33: 3 | E33: 0 | F33: 12 | G33: 1 | H33: 0 | I33: 4 | J33: 1 | K33: 1 | L33: 0 | M33: 15 | N33: 0 | O33: =SUM(C33:L33,N33) -> 27 | P33: =SUM(C33:N33) -> 42
B34: 13.00 - 13.15 | C34: 22 | D34: 3 | E34: 6 | F34: 12 | G34: 0 | H34: 2 | I34: 11 | J34: 4 | K34: 1 | L34: 0 | M34: 20 | N34: 0 | O34: =SUM(C34:L34,N34) -> 61 | P34: =SUM(C34:N34) -> 81
B35: 13.15 - 13.30 | C35: 13 | D35: 3 | E35: 4 | F35: 15 | G35: 0 | H35: 0 | I35: 2 | J35: 1 | K35: 0 | L35: 0 | M35: 17 | N35: 0 | O35: =SUM(C35:L35,N35) -> 38 | P35: =SUM(C35:N35) -> 55
B36: 13.30 - 13.45 | C36: 15 | D36: 4 | E36: 6 | F36: 12 | G36: 0 | H36: 0 | I36: 7 | J36: 3 | K36: 0 | L36: 0 | M36: 19 | N36: 0 | O36: =SUM(C36:L36,N36) -> 47 | P36: =SUM(C36:N36) -> 66
B37: 13.45 - 14.00 | C37: 30 | D37: 3 | E37: 2 | F37: 14 | G37: 0 | H37: 0 | I37: 4 | J37: 3 | K37: 1 | L37: 1 | M37: 16 | N37: 0 | O37: =SUM(C37:L37,N37) -> 58 | P37: =SUM(C37:N37) -> 74
B38: 14.00 - 14.15 | C38: 14 | D38: 1 | E38: 3 | F38: 10 | G38: 0 | H38: 0 | I38: 9 | J38: 2 | K38: 0 | L38: 2 | M38: 21 | N38: 0 | O38: =SUM(C38:L38,N38) -> 41 | P38: =SUM(C38:N38) -> 62
B39: 14.15 - 14.30 | C39: 20 | D39: 5 | E39: 3 | F39: 19 | G39: 0 | H39: 1 | I39: 8 | J39: 8 | K39: 1 | L39: 1 | M39: 23 | N39: 0 | O39: =SUM(C39:L39,N39) -> 66 | P39: =SUM(C39:N39) -> 89
B40: 14.30 - 14.45 | C40: 13 | D40: 2 | E40: 4 | F40: 17 | G40: 0 | H40: 0 | I40: 2 | J40: 1 | K40: 0 | L40: 0 | M40: 26 | N40: 1 | O40: =SUM(C40:L40,N40) -> 40 | P40: =SUM(C40:N40) -> 66
... B57: 18.45 - 19.00 | C57: 31 | D57: 5 | E57: 7 | F57: 29 | G57: 2 | H57: 0 | I57: 11 | J57: 2 | K57: 2 | L57: 5 | M57: 40 | N57: 0 | O57: =SUM(C57:L57,N57) -> 94 | P57: =SUM(C57:N57) -> 134
B58: Totals | C58: =SUM(C10:C57) -> 855 | D58: =SUM(D10:D57) -> 132 | E58: =SUM(E10:E57) -> 141 | F58: =SUM(F10:F57) -> 723 | G58: =SUM(G10:G57) -> 14 | H58: =SUM(H10:H57) -> 18 | I58: =SUM(I10:I57) -> 259 | J58: =SUM(J10:J57) -> 108 | ... P58: =SUM(P10:P57) -> 3354
...

Sheet 29.10 Buloba-Bujuko
B1: Consultancy services for Preparation of Expressway Development Master Plan (EDMP) for Uganda
B2: MANUAL CLASSIFIED COUNT (MCC)
B3: ROAD NAME: | C3: ='29.10 Bujuko-Buloba'!C3:G3 -> MCC - C2 - STN62 - BUJUKO-BULOBA ROAD
C5: Date | D5: ='29.10 Bujuko-Buloba'!D5 -> 29.10.19 | F5: Location | G5: ='29.10 Bujuko-Buloba'!G5:H5 -> Buloba Pop Oil | J5: Surveyor | K5: Doreen
C6: Dir. From | D6: Buloba | F6: Dir. To | G6: Bujuko | J6: Supervisor | K6: ='29.10 Bujuko-Buloba'!K6:L6 -> Godfrey
B8: Time / Veh Type | R8: SUMMARY TRAFFIC VOLUMES
C9: 1. Car | D9: 2. Station Wagon | E9: 3. Pickups | F9: 4. Minibus, matatu | G9: 5. Medium bus | H9: 6. Large Bus | I9: 7. Light Truck | J9: 8. Medium Truck | K9: 9. Heavy truck | L9: 10. Truck Trailer | M9: 11. Motor cycles | N9: 12. Tractors | O9: Total Excl M/Cycles | P9: Total All | R9: Time | S9: 1. Car | T9: 2. Station Wagon | U9: 3. Pickups | V9: 4. Minibus, matatu | W9: 5. Medium bus | X9: 6. Large Bus | Y9: 7. Light Truck | Z9: 8. Medium Truck | AA9: 9. Heavy truck | AB9: 10. Truck Trailer | AC9: 11. Motorcycles | AD9: 12. Tractors, Graders | AE9: Total Excl M/ Cycles | AF9: Total All
B10: 07.00 - 07.15 | C10: 9 | D10: 3 | E10: 9 | F10: 13 | G10: 2 | H10: 1 | I10: 6 | J10: 2 | K10: 0 | L10: 3 | M10: 16 | N10: 0 | O10: =SUM(C10:L10,N10) -> 48 | P10: =SUM(C10:N10) -> 64 | R10: 0700-0800 | S10: =SUM(C10:C13) -> 41 | T10: =SUM(D10:D13) -> 14 | U10: =SUM(E10:E13) -> 16 | V10: =SUM(F10:F13) -> 37 | W10: =SUM(G10:G13) -> 2 | X10: =SUM(H10:H13) -> 2 | Y10: =SUM(I10:I13) -> 15 | Z10: =SUM(J10:J13) -> 3 | ... AF10: =SUM(P10:P13) -> 166
B11: 07.15 - 07.30 | C11: 10 | D11: 5 | E11: 3 | F11: 5 | G11: 0 | H11: 1 | I11: 3 | J11: 1 | K11: 0 | L11: 0 | M11: 6 | N11: 0 | O11: =SUM(C11:L11,N11) -> 28 | P11: =SUM(C11:N11) -> 34 | R11: 0800-0900 | S11: =SUM(C14:C17) -> 61 | T11: =SUM(D14:D17) -> 15 | U11: =SUM(E14:E17) -> 15 | V11: =SUM(F14:F17) -> 59 | W11: =SUM(G14:G17) -> 3 | X11: =SUM(H14:H17) -> 1 | Y11: =SUM(I14:I17) -> 17 | Z11: =SUM(J14:J17) -> 8 | ... AF11: =SUM(P14:P17) -> 239
B12: 07.30 - 07.45 | C12: 11 | D12: 3 | E12: 3 | F12: 6 | G12: 0 | H12: 0 | I12: 3 | J12: 0 | K12: 0 | L12: 0 | M12: 5 | N12: 0 | O12: =SUM(C12:L12,N12) -> 26 | P12: =SUM(C12:N12) -> 31 | R12: 0900-1000 | S12: =SUM(C18:C21) -> 76 | T12: =SUM(D18:D21) -> 13 | U12: =SUM(E18:E21) -> 9 | V12: =SUM(F18:F21) -> 52 | W12: =SUM(G18:G21) -> 0 | X12: =SUM(H18:H21) -> 2 | Y12: =SUM(I18:I21) -> 23 | Z12: =SUM(J18:J21) -> 6 | ... AF12: =SUM(P18:P21) -> 237
B13: 07.45 - 08.00 | C13: 11 | D13: 3 | E13: 1 | F13: 13 | G13: 0 | H13: 0 | I13: 3 | J13: 0 | K13: 0 | L13: 2 | M13: 4 | N13: 0 | O13: =SUM(C13:L13,N13) -> 33 | P13: =SUM(C13:N13) -> 37 | R13: 1000-1100 | S13: =SUM(C22:C25) -> 76 | T13: =SUM(D22:D25) -> 15 | U13: =SUM(E22:E25) -> 21 | V13: =SUM(F22:F25) -> 58 | W13: =SUM(G22:G25) -> 3 | X13: =SUM(H22:H25) -> 1 | Y13: =SUM(I22:I25) -> 26 | Z13: =SUM(J22:J25) -> 9 | ... AF13: =SUM(P22:P25) -> 292
B14: 08.00 - 08.15 | C14: 22 | D14: 3 | E14: 3 | F14: 19 | G14: 0 | H14: 0 | I14: 3 | J14: 4 | K14: 4 | L14: 0 | M14: 12 | N14: 0 | O14: =SUM(C14:L14,N14) -> 58 | P14: =SUM(C14:N14) -> 70 | R14: 1100-1200 | S14: =SUM(C26:C29) -> 61 | T14: =SUM(D26:D29) -> 33 | U14: =SUM(E26:E29) -> 26 | V14: =SUM(F26:F29) -> 68 | W14: =SUM(G26:G29) -> 1 | X14: =SUM(H26:H29) -> 4 | Y14: =SUM(I26:I29) -> 34 | Z14: =SUM(J26:J29) -> 3 | ... AF14: =SUM(P26:P29) -> 335
B15: 08.15 - 08.30 | C15: 12 | D15: 2 | E15: 4 | F15: 14 | G15: 0 | H15: 0 | I15: 3 | J15: 2 | K15: 0 | L15: 1 | M15: 13 | N15: 0 | O15: =SUM(C15:L15,N15) -> 38 | P15: =SUM(C15:N15) -> 51 | R15: 1200-1300 | S15: =SUM(C30:C33) -> 49 | T15: =SUM(D30:D33) -> 40 | U15: =SUM(E30:E33) -> 19 | V15: =SUM(F30:F33) -> 58 | W15: =SUM(G30:G33) -> 1 | X15: =SUM(H30:H33) -> 2 | Y15: =SUM(I30:I33) -> 28 | Z15: =SUM(J30:J33) -> 4 | ... AF15: =SUM(P30:P33) -> 300
B16: 08.30 - 08.45 | C16: 12 | D16: 3 | E16: 7 | F16: 17 | G16: 1 | H16: 1 | I16: 7 | J16: 0 | K16: 0 | L16: 0 | M16: 16 | N16: 0 | O16: =SUM(C16:L16,N16) -> 48 | P16: =SUM(C16:N16) -> 64 | R16: 1300-1400 | S16: =SUM(C34:C37) -> 54 | T16: =SUM(D34:D37) -> 25 | U16: =SUM(E34:E37) -> 25 | V16: =SUM(F34:F37) -> 68 | W16: =SUM(G34:G37) -> 2 | X16: =SUM(H34:H37) -> 0 | Y16: =SUM(I34:I37) -> 17 | Z16: =SUM(J34:J37) -> 3 | ... AF16: =SUM(P34:P37) -> 292
B17: 08.45 - 9.00 | C17: 15 | D17: 7 | E17: 1 | F17: 9 | G17: 2 | H17: 0 | I17: 4 | J17: 2 | K17: 1 | L17: 0 | M17: 13 | N17: 0 | O17: =SUM(C17:L17,N17) -> 41 | P17: =SUM(C17:N17) -> 54 | R17: 1400-1500 | S17: =SUM(C38:C41) -> 43 | T17: =SUM(D38:D41) -> 21 | U17: =SUM(E38:E41) -> 18 | V17: =SUM(F38:F41) -> 60 | W17: =SUM(G38:G41) -> 2 | X17: =SUM(H38:H41) -> 3 | Y17: =SUM(I38:I41) -> 38 | Z17: =SUM(J38:J41) -> 6 | ... AF17: =SUM(P38:P41) -> 296
B18: 09.00 - 09.15 | C18: 28 | D18: 3 | E18: 2 | F18: 15 | G18: 0 | H18: 1 | I18: 12 | J18: 0 | K18: 1 | L18: 1 | M18: 13 | N18: 0 | O18: =SUM(C18:L18,N18) -> 63 | P18: =SUM(C18:N18) -> 76 | R18: 1500-1600 | S18: =SUM(C42:C45) -> 39 | T18: =SUM(D42:D45) -> 22 | U18: =SUM(E42:E45) -> 11 | V18: =SUM(F42:F45) -> 69 | W18: =SUM(G42:G45) -> 2 | X18: =SUM(H42:H45) -> 1 | Y18: =SUM(I42:I45) -> 33 | Z18: =SUM(J42:J45) -> 3 | ... AF18: =SUM(P42:P45) -> 278
B19: 09.15 - 09.30 | C19: 23 | D19: 2 | E19: 1 | F19: 18 | G19: 0 | H19: 0 | I19: 4 | J19: 5 | K19: 1 | L19: 0 | M19: 13 | N19: 0 | O19: =SUM(C19:L19,N19) -> 54 | P19: =SUM(C19:N19) -> 67 | R19: 1600-1700 | S19: =SUM(C46:C49) -> 54 | T19: =SUM(D46:D49) -> 18 | U19: =SUM(E46:E49) -> 22 | V19: =SUM(F46:F49) -> 65 | W19: =SUM(G46:G49) -> 0 | X19: =SUM(H46:H49) -> 3 | Y19: =SUM(I46:I49) -> 32 | Z19: =SUM(J46:J49) -> 4 | ... AF19: =SUM(P46:P49) -> 266
B20: 09.30 - 09.45 | C20: 9 | D20: 1 | E20: 1 | F20: 11 | G20: 0 | H20: 0 | I20: 4 | J20: 1 | K20: 0 | L20: 0 | M20: 6 | N20: 0 | O20: =SUM(C20:L20,N20) -> 27 | P20: =SUM(C20:N20) -> 33 | R20: 1700-1800 | S20: =SUM(C50:C53) -> 35 | T20: =SUM(D50:D53) -> 26 | U20: =SUM(E50:E53) -> 10 | V20: =SUM(F50:F53) -> 55 | W20: =SUM(G50:G53) -> 5 | X20: =SUM(H50:H53) -> 1 | Y20: =SUM(I50:I53) -> 50 | Z20: =SUM(J50:J53) -> 3 | ... AF20: =SUM(P50:P53) -> 265
B21: 09.45 - 10.00 | C21: 16 | D21: 7 | E21: 5 | F21: 8 | G21: 0 | H21: 1 | I21: 3 | J21: 0 | K21: 0 | L21: 0 | M21: 21 | N21: 0 | O21: =SUM(C21:L21,N21) -> 40 | P21: =SUM(C21:N21) -> 61 | R21: 1800-1900 | S21: =SUM(C54:C57) -> 33 | T21: =SUM(D54:D57) -> 32 | U21: =SUM(E54:E57) -> 5 | V21: =SUM(F54:F57) -> 44 | W21: =SUM(G54:G57) -> 2 | X21: =SUM(H54:H57) -> 2 | Y21: =SUM(I54:I57) -> 51 | Z21: =SUM(J54:J57) -> 4 | ... AF21: =SUM(P54:P57) -> 234
B22: 10.00 - 10.15 | C22: 13 | D22: 3 | E22: 3 | F22: 15 | G22: 0 | H22: 0 | I22: 6 | J22: 2 | K22: 2 | L22: 1 | M22: 20 | N22: 0 | O22: =SUM(C22:L22,N22) -> 45 | P22: =SUM(C22:N22) -> 65 | R22: AM Peak Hr | S22: =MAX(S10:S12) -> 76 | T22: =MAX(T10:T12) -> 15 | U22: =MAX(U10:U12) -> 16 | V22: =MAX(V10:V12) -> 59 | W22: =MAX(W10:W12) -> 3 | X22: =MAX(X10:X12) -> 2 | Y22: =MAX(Y10:Y12) -> 23 | Z22: =MAX(Z10:Z12) -> 8 | ... AF22: =MAX(AF10:AF12) -> 239
B23: 10.15 - 10.30 | C23: 24 | D23: 0 | E23: 3 | F23: 12 | G23: 0 | H23: 1 | I23: 7 | J23: 3 | K23: 3 | L23: 0 | M23: 22 | N23: 0 | O23: =SUM(C23:L23,N23) -> 53 | P23: =SUM(C23:N23) -> 75 | R23: IP Peak Hr | S23: =MAX(S13:S18) -> 76 | T23: =MAX(T13:T18) -> 40 | U23: =MAX(U13:U18) -> 26 | V23: =MAX(V13:V18) -> 69 | W23: =MAX(W13:W18) -> 3 | X23: =MAX(X13:X18) -> 4 | Y23: =MAX(Y13:Y18) -> 38 | Z23: =MAX(Z13:Z18) -> 9 | ... AF23: =MAX(AF13:AF18) -> 335
B24: 10.30 - 10.45 | C24: 22 | D24: 5 | E24: 11 | F24: 17 | G24: 2 | H24: 0 | I24: 7 | J24: 2 | K24: 3 | L24: 0 | M24: 16 | N24: 1 | O24: =SUM(C24:L24,N24) -> 70 | P24: =SUM(C24:N24) -> 86 | R24: PM Peak Hr | S24: =MAX(S19:S21) -> 54 | T24: =MAX(T19:T21) -> 32 | U24: =MAX(U19:U21) -> 22 | V24: =MAX(V19:V21) -> 65 | W24: =MAX(W19:W21) -> 5 | X24: =MAX(X19:X21) -> 3 | Y24: =MAX(Y19:Y21) -> 51 | Z24: =MAX(Z19:Z21) -> 4 | ... AF24: =MAX(AF19:AF21) -> 266
B25: 10.45 - 11.00 | C25: 17 | D25: 7 | E25: 4 | F25: 14 | G25: 1 | H25: 0 | I25: 6 | J25: 2 | K25: 3 | L25: 0 | M25: 12 | N25: 0 | O25: =SUM(C25:L25,N25) -> 54 | P25: =SUM(C25:N25) -> 66 | R25: AM Period | S25: =SUM(S10:S12) -> 178 | T25: =SUM(T10:T12) -> 42 | U25: =SUM(U10:U12) -> 40 | V25: =SUM(V10:V12) -> 148 | W25: =SUM(W10:W12) -> 5 | X25: =SUM(X10:X12) -> 5 | Y25: =SUM(Y10:Y12) -> 55 | Z25: =SUM(Z10:Z12) -> 17 | ... AF25: =SUM(AF10:AF12) -> 642
B26: 11.00 - 11.15 | C26: 17 | D26: 10 | E26: 8 | F26: 18 | G26: 0 | H26: 1 | I26: 13 | J26: 2 | K26: 5 | L26: 1 | M26: 25 | N26: 0 | O26: =SUM(C26:L26,N26) -> 75 | P26: =SUM(C26:N26) -> 100 | R26: IP Period | S26: =SUM(S13:S18) -> 322 | T26: =SUM(T13:T18) -> 156 | U26: =SUM(U13:U18) -> 120 | V26: =SUM(V13:V18) -> 381 | W26: =SUM(W13:W18) -> 11 | X26: =SUM(X13:X18) -> 11 | Y26: =SUM(Y13:Y18) -> 176 | Z26: =SUM(Z13:Z18) -> 28 | ... AF26: =SUM(AF13:AF18) -> 1793
B27: 11.15 - 11.30 | C27: 14 | D27: 5 | E27: 5 | F27: 18 | G27: 1 | H27: 0 | I27: 4 | J27: 0 | K27: 3 | L27: 1 | M27: 20 | N27: 0 | O27: =SUM(C27:L27,N27) -> 51 | P27: =SUM(C27:N27) -> 71 | R27: PM Period | S27: =SUM(S19:S21) -> 122 | T27: =SUM(T19:T21) -> 76 | U27: =SUM(U19:U21) -> 37 | V27: =SUM(V19:V21) -> 164 | W27: =SUM(W19:W21) -> 7 | X27: =SUM(X19:X21) -> 6 | Y27: =SUM(Y19:Y21) -> 133 | Z27: =SUM(Z19:Z21) -> 11 | ... AF27: =SUM(AF19:AF21) -> 765
B28: 11.30 - 11.45 | C28: 15 | D28: 4 | E28: 2 | F28: 14 | G28: 0 | H28: 1 | I28: 8 | J28: 1 | K28: 1 | L28: 0 | M28: 21 | N28: 0 | O28: =SUM(C28:L28,N28) -> 46 | P28: =SUM(C28:N28) -> 67 | R28: 12 Hours | S28: =SUM(S10:S21) -> 622 | T28: =SUM(T10:T21) -> 274 | U28: =SUM(U10:U21) -> 197 | V28: =SUM(V10:V21) -> 693 | W28: =SUM(W10:W21) -> 23 | X28: =SUM(X10:X21) -> 22 | Y28: =SUM(Y10:Y21) -> 364 | Z28: =SUM(Z10:Z21) -> 56 | ... AF28: =SUM(AF10:AF21) -> 3200
B29: 11.45 - 12.00 | C29: 15 | D29: 14 | E29: 11 | F29: 18 | G29: 0 | H29: 2 | I29: 9 | J29: 0 | K29: 8 | L29: 0 | M29: 20 | N29: 0 | O29: =SUM(C29:L29,N29) -> 77 | P29: =SUM(C29:N29) -> 97
B30: 12.00 - 12.15 | C30: 10 | D30: 9 | E30: 2 | F30: 13 | G30: 0 | H30: 0 | I30: 7 | J30: 1 | K30: 1 | L30: 0 | M30: 15 | N30: 0 | O30: =SUM(C30:L30,N30) -> 43 | P30: =SUM(C30:N30) -> 58
B31: 12.15 - 12.30 | C31: 10 | D31: 9 | E31: 4 | F31: 10 | G31: 1 | H31: 1 | I31: 3 | J31: 1 | K31: 10 | L31: 0 | M31: 14 | N31: 0 | O31: =SUM(C31:L31,N31) -> 49 | P31: =SUM(C31:N31) -> 63
B32: 12.30 - 12.45 | C32: 11 | D32: 10 | E32: 4 | F32: 15 | G32: 0 | H32: 0 | I32: 12 | J32: 1 | K32: 6 | L32: 3 | M32: 15 | N32: 0 | O32: =SUM(C32:L32,N32) -> 62 | P32: =SUM(C32:N32) -> 77
B33: 12.45 - 13.00 | C33: 18 | D33: 12 | E33: 9 | F33: 20 | G33: 0 | H33: 1 | I33: 6 | J33: 1 | K33: 4 | L33: 6 | M33: 25 | N33: 0 | O33: =SUM(C33:L33,N33) -> 77 | P33: =SUM(C33:N33) -> 102
B34: 13.00 - 13.15 | C34: 14 | D34: 5 | E34: 9 | F34: 20 | G34: 1 | H34: 0 | I34: 5 | J34: 2 | K34: 9 | L34: 2 | M34: 23 | N34: 0 | O34: =SUM(C34:L34,N34) -> 67 | P34: =SUM(C34:N34) -> 90
B35: 13.15 - 13.30 | C35: 5 | D35: 2 | E35: 5 | F35: 14 | G35: 0 | H35: 0 | I35: 2 | J35: 1 | K35: 4 | L35: 0 | M35: 13 | N35: 0 | O35: =SUM(C35:L35,N35) -> 33 | P35: =SUM(C35:N35) -> 46
B36: 13.30 - 13.45 | C36: 13 | D36: 6 | E36: 4 | F36: 17 | G36: 1 | H36: 0 | I36: 6 | J36: 0 | K36: 6 | L36: 0 | M36: 20 | N36: 1 | O36: =SUM(C36:L36,N36) -> 54 | P36: =SUM(C36:N36) -> 74
B37: 13.45 - 14.00 | C37: 22 | D37: 12 | E37: 7 | F37: 17 | G37: 0 | H37: 0 | I37: 4 | J37: 0 | K37: 1 | L37: 1 | M37: 17 | N37: 1 | O37: =SUM(C37:L37,N37) -> 65 | P37: =SUM(C37:N37) -> 82
B38: 14.00 - 14.15 | C38: 16 | D38: 10 | E38: 4 | F38: 23 | G38: 1 | H38: 1 | I38: 10 | J38: 0 | K38: 8 | L38: 0 | M38: 24 | N38: 0 | O38: =SUM(C38:L38,N38) -> 73 | P38: =SUM(C38:N38) -> 97
B39: 14.15 - 14.30 | C39: 11 | D39: 5 | E39: 3 | F39: 10 | G39: 1 | H39: 1 | I39: 13 | J39: 0 | K39: 7 | L39: 3 | M39: 13 | N39: 0 | O39: =SUM(C39:L39,N39) -> 54 | P39: =SUM(C39:N39) -> 67
B40: 14.30 - 14.45 | C40: 8 | D40: 3 | E40: 3 | F40: 11 | G40: 0 | H40: 1 | I40: 9 | J40: 1 | K40: 4 | L40: 5 | M40: 17 | N40: 0 | O40: =SUM(C40:L40,N40) -> 45 | P40: =SUM(C40:N40) -> 62
... B57: 18.45 - 19.00 | C57: 6 | D57: 3 | E57: 0 | F57: 12 | G57: 0 | H57: 1 | I57: 11 | J57: 0 | K57: 0 | L57: 1 | M57: 13 | N57: 0 | O57: =SUM(C57:L57,N57) -> 34 | P57: =SUM(C57:N57) -> 47
B58: Totals | C58: =SUM(C10:C57) -> 622 | D58: =SUM(D10:D57) -> 274 | E58: =SUM(E10:E57) -> 197 | F58: =SUM(F10:F57) -> 693 | G58: =SUM(G10:G57) -> 23 | H58: =SUM(H10:H57) -> 22 | I58: =SUM(I10:I57) -> 364 | J58: =SUM(J10:J57) -> 56 | ... P58: =SUM(P10:P57) -> 3200
...

Sheet 30.10 Bujuko-Buloba
B1: Consultancy services for Preparation of Expressway Development Master Plan (EDMP) for Uganda
B2: MANUAL CLASSIFIED COUNT (MCC)
B3: ROAD NAME: | C3: ='29.10 Bujuko-Buloba'!C3:G3 -> MCC - C2 - STN62 - BUJUKO-BULOBA ROAD
C5: Date | D5: 30.10.19 | F5: Location | G5: ='29.10 Bujuko-Buloba'!G5:H5 -> Buloba Pop Oil | J5: Surveyor | K5: ='29.10 Bujuko-Buloba'!K5:L5 -> Nakiwuge A
C6: Dir. From | D6: ='29.10 Bujuko-Buloba'!D6:E6 -> Bujuko | F6: Dir. To | G6: ='29.10 Bujuko-Buloba'!G6:H6 -> Buloba | J6: Supervisor | K6: ='29.10 Bujuko-Buloba'!K6:L6 -> Godfrey
B8: Time / Veh Type | R8: SUMMARY TRAFFIC VOLUMES
C9: 1. Car | D9: 2. Station Wagon | E9: 3. Pickups | F9: 4. Minibus, matatu | G9: 5. Medium bus | H9: 6. Large Bus | I9: 7. Light Truck | J9: 8. Medium Truck | K9: 9. Heavy truck | L9: 10. Truck Trailer | M9: 11. Motor cycles | N9: 12. Tractors | O9: Total Excl M/Cycles | P9: Total All | R9: Time | S9: 1. Car | T9: 2. Station Wagon | U9: 3. Pickups | V9: 4. Minibus, matatu | W9: 5. Medium bus | X9: 6. Large Bus | Y9: 7. Light Truck | Z9: 8. Medium Truck | AA9: 9. Heavy truck | AB9: 10. Truck Trailer | AC9: 11. Motorcycles | AD9: 12. Tractors, Graders | AE9: Total Excl M/ Cycles | AF9: Total All
B10: 07.00 - 07.15 | C10: 23 | D10: 2 | E10: 1 | F10: 23 | G10: 1 | H10: 0 | I10: 4 | J10: 1 | K10: 0 | L10: 1 | M10: 15 | N10: 0 | O10: =SUM(C10:L10,N10) -> 56 | P10: =SUM(C10:N10) -> 71 | R10: 0700-0800 | S10: =SUM(C10:C13) -> 77 | T10: =SUM(D10:D13) -> 2 | U10: =SUM(E10:E13) -> 6 | V10: =SUM(F10:F13) -> 66 | W10: =SUM(G10:G13) -> 1 | X10: =SUM(H10:H13) -> 0 | Y10: =SUM(I10:I13) -> 10 | Z10: =SUM(J10:J13) -> 12 | ... AF10: =SUM(P10:P13) -> 267
B11: 07.15 - 07.30 | C11: 20 | D11: 0 | E11: 0 | F11: 18 | G11: 0 | H11: 0 | I11: 4 | J11: 3 | K11: 0 | L11: 3 | M11: 21 | N11: 0 | O11: =SUM(C11:L11,N11) -> 48 | P11: =SUM(C11:N11) -> 69 | R11: 0800-0900 | S11: =SUM(C14:C17) -> 71 | T11: =SUM(D14:D17) -> 5 | U11: =SUM(E14:E17) -> 10 | V11: =SUM(F14:F17) -> 65 | W11: =SUM(G14:G17) -> 1 | X11: =SUM(H14:H17) -> 0 | Y11: =SUM(I14:I17) -> 23 | Z11: =SUM(J14:J17) -> 8 | ... AF11: =SUM(P14:P17) -> 284
B12: 07.30 - 07.45 | C12: 19 | D12: 0 | E12: 1 | F12: 11 | G12: 0 | H12: 0 | I12: 1 | J12: 1 | K12: 0 | L12: 0 | M12: 18 | N12: 0 | O12: =SUM(C12:L12,N12) -> 33 | P12: =SUM(C12:N12) -> 51 | R12: 0900-1000 | S12: =SUM(C18:C21) -> 62 | T12: =SUM(D18:D21) -> 7 | U12: =SUM(E18:E21) -> 7 | V12: =SUM(F18:F21) -> 59 | W12: =SUM(G18:G21) -> 0 | X12: =SUM(H18:H21) -> 0 | Y12: =SUM(I18:I21) -> 5 | Z12: =SUM(J18:J21) -> 4 | ... AF12: =SUM(P18:P21) -> 225
B13: 07.45 - 08.00 | C13: 15 | D13: 0 | E13: 4 | F13: 14 | G13: 0 | H13: 0 | I13: 1 | J13: 7 | K13: 1 | L13: 2 | M13: 32 | N13: 0 | O13: =SUM(C13:L13,N13) -> 44 | P13: =SUM(C13:N13) -> 76 | R13: 1000-1100 | S13: =SUM(C22:C25) -> 63 | T13: =SUM(D22:D25) -> 8 | U13: =SUM(E22:E25) -> 12 | V13: =SUM(F22:F25) -> 57 | W13: =SUM(G22:G25) -> 0 | X13: =SUM(H22:H25) -> 0 | Y13: =SUM(I22:I25) -> 11 | Z13: =SUM(J22:J25) -> 10 | ... AF13: =SUM(P22:P25) -> 247
B14: 08.00 - 08.15 | C14: 20 | D14: 0 | E14: 1 | F14: 21 | G14: 0 | H14: 0 | I14: 4 | J14: 2 | K14: 0 | L14: 0 | M14: 20 | N14: 0 | O14: =SUM(C14:L14,N14) -> 48 | P14: =SUM(C14:N14) -> 68 | R14: 1100-1200 | S14: =SUM(C26:C29) -> 45 | T14: =SUM(D26:D29) -> 6 | U14: =SUM(E26:E29) -> 7 | V14: =SUM(F26:F29) -> 46 | W14: =SUM(G26:G29) -> 3 | X14: =SUM(H26:H29) -> 2 | Y14: =SUM(I26:I29) -> 21 | Z14: =SUM(J26:J29) -> 6 | ... AF14: =SUM(P26:P29) -> 206
B15: 08.15 - 08.30 | C15: 10 | D15: 1 | E15: 2 | F15: 14 | G15: 1 | H15: 0 | I15: 5 | J15: 3 | K15: 2 | L15: 0 | M15: 22 | N15: 0 | O15: =SUM(C15:L15,N15) -> 38 | P15: =SUM(C15:N15) -> 60 | R15: 1200-1300 | S15: =SUM(C30:C33) -> 69 | T15: =SUM(D30:D33) -> 8 | U15: =SUM(E30:E33) -> 9 | V15: =SUM(F30:F33) -> 46 | W15: =SUM(G30:G33) -> 0 | X15: =SUM(H30:H33) -> 2 | Y15: =SUM(I30:I33) -> 26 | Z15: =SUM(J30:J33) -> 12 | ... AF15: =SUM(P30:P33) -> 239
B16: 08.30 - 08.45 | C16: 14 | D16: 2 | E16: 4 | F16: 14 | G16: 0 | H16: 0 | I16: 8 | J16: 1 | K16: 0 | L16: 0 | M16: 22 | N16: 0 | O16: =SUM(C16:L16,N16) -> 43 | P16: =SUM(C16:N16) -> 65 | R16: 1300-1400 | S16: =SUM(C34:C37) -> 59 | T16: =SUM(D34:D37) -> 17 | U16: =SUM(E34:E37) -> 23 | V16: =SUM(F34:F37) -> 42 | W16: =SUM(G34:G37) -> 0 | X16: =SUM(H34:H37) -> 1 | Y16: =SUM(I34:I37) -> 13 | Z16: =SUM(J34:J37) -> 15 | ... AF16: =SUM(P34:P37) -> 261
B17: 08.45 - 9.00 | C17: 27 | D17: 2 | E17: 3 | F17: 16 | G17: 0 | H17: 0 | I17: 6 | J17: 2 | K17: 0 | L17: 2 | M17: 33 | N17: 0 | O17: =SUM(C17:L17,N17) -> 58 | P17: =SUM(C17:N17) -> 91 | R17: 1400-1500 | S17: =SUM(C38:C41) -> 66 | T17: =SUM(D38:D41) -> 14 | U17: =SUM(E38:E41) -> 14 | V17: =SUM(F38:F41) -> 53 | W17: =SUM(G38:G41) -> 0 | X17: =SUM(H38:H41) -> 1 | Y17: =SUM(I38:I41) -> 24 | Z17: =SUM(J38:J41) -> 17 | ... AF17: =SUM(P38:P41) -> 271
B18: 09.00 - 09.15 | C18: 21 | D18: 4 | E18: 2 | F18: 25 | G18: 0 | H18: 0 | I18: 2 | J18: 2 | K18: 0 | L18: 1 | M18: 29 | N18: 0 | O18: =SUM(C18:L18,N18) -> 57 | P18: =SUM(C18:N18) -> 86 | R18: 1500-1600 | S18: =SUM(C42:C45) -> 76 | T18: =SUM(D42:D45) -> 12 | U18: =SUM(E42:E45) -> 16 | V18: =SUM(F42:F45) -> 50 | W18: =SUM(G42:G45) -> 0 | X18: =SUM(H42:H45) -> 3 | Y18: =SUM(I42:I45) -> 23 | Z18: =SUM(J42:J45) -> 13 | ... AF18: =SUM(P42:P45) -> 262
B19: 09.15 - 09.30 | C19: 12 | D19: 2 | E19: 2 | F19: 11 | G19: 0 | H19: 0 | I19: 1 | J19: 1 | K19: 0 | L19: 0 | M19: 19 | N19: 0 | O19: =SUM(C19:L19,N19) -> 29 | P19: =SUM(C19:N19) -> 48 | R19: 1600-1700 | S19: =SUM(C46:C49) -> 98 | T19: =SUM(D46:D49) -> 20 | U19: =SUM(E46:E49) -> 24 | V19: =SUM(F46:F49) -> 54 | W19: =SUM(G46:G49) -> 2 | X19: =SUM(H46:H49) -> 2 | Y19: =SUM(I46:I49) -> 35 | Z19: =SUM(J46:J49) -> 20 | ... AF19: =SUM(P46:P49) -> 348
B20: 09.30 - 09.45 | C20: 19 | D20: 1 | E20: 0 | F20: 11 | G20: 0 | H20: 0 | I20: 0 | J20: 1 | K20: 0 | L20: 1 | M20: 23 | N20: 0 | O20: =SUM(C20:L20,N20) -> 33 | P20: =SUM(C20:N20) -> 56 | R20: 1700-1800 | S20: =SUM(C50:C53) -> 108 | T20: =SUM(D50:D53) -> 16 | U20: =SUM(E50:E53) -> 24 | V20: =SUM(F50:F53) -> 66 | W20: =SUM(G50:G53) -> 4 | X20: =SUM(H50:H53) -> 1 | Y20: =SUM(I50:I53) -> 30 | Z20: =SUM(J50:J53) -> 13 | ... AF20: =SUM(P50:P53) -> 379
B21: 09.45 - 10.00 | C21: 10 | D21: 0 | E21: 3 | F21: 12 | G21: 0 | H21: 0 | I21: 2 | J21: 0 | K21: 0 | L21: 0 | M21: 8 | N21: 0 | O21: =SUM(C21:L21,N21) -> 27 | P21: =SUM(C21:N21) -> 35 | R21: 1800-1900 | S21: =SUM(C54:C57) -> 113 | T21: =SUM(D54:D57) -> 19 | U21: =SUM(E54:E57) -> 23 | V21: =SUM(F54:F57) -> 88 | W21: =SUM(G54:G57) -> 9 | X21: =SUM(H54:H57) -> 3 | Y21: =SUM(I54:I57) -> 24 | Z21: =SUM(J54:J57) -> 16 | ... AF21: =SUM(P54:P57) -> 442
B22: 10.00 - 10.15 | C22: 16 | D22: 0 | E22: 6 | F22: 18 | G22: 0 | H22: 0 | I22: 0 | J22: 2 | K22: 0 | L22: 1 | M22: 23 | N22: 0 | O22: =SUM(C22:L22,N22) -> 43 | P22: =SUM(C22:N22) -> 66 | R22: AM Peak Hr | S22: =MAX(S10:S12) -> 77 | T22: =MAX(T10:T12) -> 7 | U22: =MAX(U10:U12) -> 10 | V22: =MAX(V10:V12) -> 66 | W22: =MAX(W10:W12) -> 1 | X22: =MAX(X10:X12) -> 0 | Y22: =MAX(Y10:Y12) -> 23 | Z22: =MAX(Z10:Z12) -> 12 | ... AF22: =MAX(AF10:AF12) -> 284
B23: 10.15 - 10.30 | C23: 14 | D23: 1 | E23: 1 | F23: 11 | G23: 0 | H23: 0 | I23: 1 | J23: 4 | K23: 0 | L23: 2 | M23: 19 | N23: 0 | O23: =SUM(C23:L23,N23) -> 34 | P23: =SUM(C23:N23) -> 53 | R23: IP Peak Hr | S23: =MAX(S13:S18) -> 76 | T23: =MAX(T13:T18) -> 17 | U23: =MAX(U13:U18) -> 23 | V23: =MAX(V13:V18) -> 57 | W23: =MAX(W13:W18) -> 3 | X23: =MAX(X13:X18) -> 3 | Y23: =MAX(Y13:Y18) -> 26 | Z23: =MAX(Z13:Z18) -> 17 | ... AF23: =MAX(AF13:AF18) -> 271
B24: 10.30 - 10.45 | C24: 17 | D24: 4 | E24: 4 | F24: 15 | G24: 0 | H24: 0 | I24: 5 | J24: 3 | K24: 0 | L24: 0 | M24: 22 | N24: 0 | O24: =SUM(C24:L24,N24) -> 48 | P24: =SUM(C24:N24) -> 70 | R24: PM Peak Hr | S24: =MAX(S19:S21) -> 113 | T24: =MAX(T19:T21) -> 20 | U24: =MAX(U19:U21) -> 24 | V24: =MAX(V19:V21) -> 88 | W24: =MAX(W19:W21) -> 9 | X24: =MAX(X19:X21) -> 3 | Y24: =MAX(Y19:Y21) -> 35 | Z24: =MAX(Z19:Z21) -> 20 | ... AF24: =MAX(AF19:AF21) -> 442
B25: 10.45 - 11.00 | C25: 16 | D25: 3 | E25: 1 | F25: 13 | G25: 0 | H25: 0 | I25: 5 | J25: 1 | K25: 0 | L25: 0 | M25: 19 | N25: 0 | O25: =SUM(C25:L25,N25) -> 39 | P25: =SUM(C25:N25) -> 58 | R25: AM Period | S25: =SUM(S10:S12) -> 210 | T25: =SUM(T10:T12) -> 14 | U25: =SUM(U10:U12) -> 23 | V25: =SUM(V10:V12) -> 190 | W25: =SUM(W10:W12) -> 2 | X25: =SUM(X10:X12) -> 0 | Y25: =SUM(Y10:Y12) -> 38 | Z25: =SUM(Z10:Z12) -> 24 | ... AF25: =SUM(AF10:AF12) -> 776
B26: 11.00 - 11.15 | C26: 8 | D26: 1 | E26: 2 | F26: 10 | G26: 0 | H26: 1 | I26: 4 | J26: 1 | K26: 1 | L26: 1 | M26: 17 | N26: 0 | O26: =SUM(C26:L26,N26) -> 29 | P26: =SUM(C26:N26) -> 46 | R26: IP Period | S26: =SUM(S13:S18) -> 378 | T26: =SUM(T13:T18) -> 65 | U26: =SUM(U13:U18) -> 81 | V26: =SUM(V13:V18) -> 294 | W26: =SUM(W13:W18) -> 3 | X26: =SUM(X13:X18) -> 9 | Y26: =SUM(Y13:Y18) -> 118 | Z26: =SUM(Z13:Z18) -> 73 | ... AF26: =SUM(AF13:AF18) -> 1486
B27: 11.15 - 11.30 | C27: 13 | D27: 4 | E27: 2 | F27: 11 | G27: 2 | H27: 0 | I27: 3 | J27: 2 | K27: 1 | L27: 1 | M27: 14 | N27: 0 | O27: =SUM(C27:L27,N27) -> 39 | P27: =SUM(C27:N27) -> 53 | R27: PM Period | S27: =SUM(S19:S21) -> 319 | T27: =SUM(T19:T21) -> 55 | U27: =SUM(U19:U21) -> 71 | V27: =SUM(V19:V21) -> 208 | W27: =SUM(W19:W21) -> 15 | X27: =SUM(X19:X21) -> 6 | Y27: =SUM(Y19:Y21) -> 89 | Z27: =SUM(Z19:Z21) -> 49 | ... AF27: =SUM(AF19:AF21) -> 1169
B28: 11.30 - 11.45 | C28: 10 | D28: 1 | E28: 1 | F28: 9 | G28: 1 | H28: 1 | I28: 8 | J28: 2 | K28: 0 | L28: 1 | M28: 17 | N28: 0 | O28: =SUM(C28:L28,N28) -> 34 | P28: =SUM(C28:N28) -> 51 | R28: 12 Hours | S28: =SUM(S10:S21) -> 907 | T28: =SUM(T10:T21) -> 134 | U28: =SUM(U10:U21) -> 175 | V28: =SUM(V10:V21) -> 692 | W28: =SUM(W10:W21) -> 20 | X28: =SUM(X10:X21) -> 15 | Y28: =SUM(Y10:Y21) -> 245 | Z28: =SUM(Z10:Z21) -> 146 | ... AF28: =SUM(AF10:AF21) -> 3431
B29: 11.45 - 12.00 | C29: 14 | D29: 0 | E29: 2 | F29: 16 | G29: 0 | H29: 0 | I29: 6 | J29: 1 | K29: 3 | L29: 1 | M29: 13 | N29: 0 | O29: =SUM(C29:L29,N29) -> 43 | P29: =SUM(C29:N29) -> 56
B30: 12.00 - 12.15 | C30: 18 | D30: 2 | E30: 3 | F30: 10 | G30: 0 | H30: 0 | I30: 8 | J30: 1 | K30: 0 | L30: 1 | M30: 13 | N30: 0 | O30: =SUM(C30:L30,N30) -> 43 | P30: =SUM(C30:N30) -> 56
B31: 12.15 - 12.30 | C31: 15 | D31: 2 | E31: 1 | F31: 12 | G31: 0 | H31: 0 | I31: 5 | J31: 3 | K31: 2 | L31: 2 | M31: 14 | N31: 0 | O31: =SUM(C31:L31,N31) -> 42 | P31: =SUM(C31:N31) -> 56
B32: 12.30 - 12.45 | C32: 22 | D32: 1 | E32: 4 | F32: 16 | G32: 0 | H32: 2 | I32: 9 | J32: 8 | K32: 1 | L32: 2 | M32: 24 | N32: 0 | O32: =SUM(C32:L32,N32) -> 65 | P32: =SUM(C32:N32) -> 89
B33: 12.45 - 13.00 | C33: 14 | D33: 3 | E33: 1 | F33: 8 | G33: 0 | H33: 0 | I33: 4 | J33: 0 | K33: 1 | L33: 1 | M33: 6 | N33: 0 | O33: =SUM(C33:L33,N33) -> 32 | P33: =SUM(C33:N33) -> 38
B34: 13.00 - 13.15 | C34: 15 | D34: 4 | E34: 4 | F34: 9 | G34: 0 | H34: 0 | I34: 2 | J34: 6 | K34: 0 | L34: 1 | M34: 24 | N34: 0 | O34: =SUM(C34:L34,N34) -> 41 | P34: =SUM(C34:N34) -> 65
B35: 13.15 - 13.30 | C35: 11 | D35: 3 | E35: 6 | F35: 9 | G35: 0 | H35: 0 | I35: 4 | J35: 1 | K35: 0 | L35: 0 | M35: 25 | N35: 0 | O35: =SUM(C35:L35,N35) -> 34 | P35: =SUM(C35:N35) -> 59
B36: 13.30 - 13.45 | C36: 14 | D36: 4 | E36: 7 | F36: 9 | G36: 0 | H36: 0 | I36: 4 | J36: 3 | K36: 1 | L36: 2 | M36: 15 | N36: 0 | O36: =SUM(C36:L36,N36) -> 44 | P36: =SUM(C36:N36) -> 59
B37: 13.45 - 14.00 | C37: 19 | D37: 6 | E37: 6 | F37: 15 | G37: 0 | H37: 1 | I37: 3 | J37: 5 | K37: 0 | L37: 1 | M37: 22 | N37: 0 | O37: =SUM(C37:L37,N37) -> 56 | P37: =SUM(C37:N37) -> 78
B38: 14.00 - 14.15 | C38: 16 | D38: 3 | E38: 1 | F38: 13 | G38: 0 | H38: 0 | I38: 5 | J38: 4 | K38: 0 | L38: 0 | M38: 29 | N38: 0 | O38: =SUM(C38:L38,N38) -> 42 | P38: =SUM(C38:N38) -> 71
B39: 14.15 - 14.30 | C39: 20 | D39: 2 | E39: 8 | F39: 18 | G39: 0 | H39: 0 | I39: 8 | J39: 2 | K39: 0 | L39: 0 | M39: 28 | N39: 0 | O39: =SUM(C39:L39,N39) -> 58 | P39: =SUM(C39:N39) -> 86
B40: 14.30 - 14.45 | C40: 21 | D40: 5 | E40: 3 | F40: 12 | G40: 0 | H40: 0 | I40: 9 | J40: 6 | K40: 1 | L40: 0 | M40: 11 | N40: 0 | O40: =SUM(C40:L40,N40) -> 57 | P40: =SUM(C40:N40) -> 68
... B57: 18.45 - 19.00 | C57: 25 | D57: 6 | E57: 6 | F57: 26 | G57: 3 | H57: 1 | I57: 6 | J57: 7 | K57: 1 | L57: 2 | M57: 18 | N57: 0 | O57: =SUM(C57:L57,N57) -> 83 | P57: =SUM(C57:N57) -> 101
B58: Totals | C58: =SUM(C10:C57) -> 907 | D58: =SUM(D10:D57) -> 134 | E58: =SUM(E10:E57) -> 175 | F58: =SUM(F10:F57) -> 692 | G58: =SUM(G10:G57) -> 20 | H58: =SUM(H10:H57) -> 15 | I58: =SUM(I10:I57) -> 245 | J58: =SUM(J10:J57) -> 146 | ... P58: =SUM(P10:P57) -> 3431
...

Sheet 30.10 Buloba-Bujuko
B1: Consultancy services for Preparation of Expressway Development Master Plan (EDMP) for Uganda
B2: MANUAL CLASSIFIED COUNT (MCC)
B3: ROAD NAME: | C3: ='29.10 Buloba-Bujuko'!C3:G3 -> MCC - C2 - STN62 - BUJUKO-BULOBA ROAD
C5: Date | D5: ='30.10 Bujuko-Buloba'!D5 -> 30.10.19 | F5: Location | G5: ='29.10 Bujuko-Buloba'!G5:H5 -> Buloba Pop Oil | J5: Surveyor | K5: Doreen
C6: Dir. From | D6: ='29.10 Buloba-Bujuko'!D6:E6 -> Buloba | F6: Dir. To | G6: ='29.10 Buloba-Bujuko'!G6:H6 -> Bujuko | J6: Supervisor | K6: ='29.10 Bujuko-Buloba'!K6:L6 -> Godfrey
B8: Time / Veh Type | R8: SUMMARY TRAFFIC VOLUMES
C9: 1. Car | D9: 2. Station Wagon | E9: 3. Pickups | F9: 4. Minibus, matatu | G9: 5. Medium bus | H9: 6. Large Bus | I9: 7. Light Truck | J9: 8. Medium Truck | K9: 9. Heavy truck | L9: 10. Truck Trailer | M9: 11. Motor cycles | N9: 12. Tractors | O9: Total Excl M/Cycles | P9: Total All | R9: Time | S9: 1. Car | T9: 2. Station Wagon | U9: 3. Pickups | V9: 4. Minibus, matatu | W9: 5. Medium bus | X9: 6. Large Bus | Y9: 7. Light Truck | Z9: 8. Medium Truck | AA9: 9. Heavy truck | AB9: 10. Truck Trailer | AC9: 11. Motorcycles | AD9: 12. Tractors, Graders | AE9: Total Excl M/ Cycles | AF9: Total All
B10: 07.00 - 07.15 | C10: 6 | D10: 1 | E10: 6 | F10: 15 | G10: 0 | H10: 0 | I10: 4 | J10: 1 | K10: 0 | L10: 1 | M10: 9 | N10: 0 | O10: =SUM(C10:L10,N10) -> 34 | P10: =SUM(C10:N10) -> 43 | R10: 0700-0800 | S10: =SUM(C10:C13) -> 62 | T10: =SUM(D10:D13) -> 8 | U10: =SUM(E10:E13) -> 13 | V10: =SUM(F10:F13) -> 47 | W10: =SUM(G10:G13) -> 1 | X10: =SUM(H10:H13) -> 1 | Y10: =SUM(I10:I13) -> 24 | Z10: =SUM(J10:J13) -> 14 | ... AF10: =SUM(P10:P13) -> 232
B11: 07.15 - 07.30 | C11: 26 | D11: 2 | E11: 4 | F11: 12 | G11: 1 | H11: 1 | I11: 5 | J11: 3 | K11: 0 | L11: 1 | M11: 19 | N11: 0 | O11: =SUM(C11:L11,N11) -> 55 | P11: =SUM(C11:N11) -> 74 | R11: 0800-0900 | S11: =SUM(C14:C17) -> 67 | T11: =SUM(D14:D17) -> 12 | U11: =SUM(E14:E17) -> 13 | V11: =SUM(F14:F17) -> 45 | W11: =SUM(G14:G17) -> 0 | X11: =SUM(H14:H17) -> 1 | Y11: =SUM(I14:I17) -> 31 | Z11: =SUM(J14:J17) -> 6 | ... AF11: =SUM(P14:P17) -> 252
B12: 07.30 - 07.45 | C12: 17 | D12: 2 | E12: 2 | F12: 10 | G12: 0 | H12: 0 | I12: 6 | J12: 7 | K12: 1 | L12: 1 | M12: 8 | N12: 0 | O12: =SUM(C12:L12,N12) -> 46 | P12: =SUM(C12:N12) -> 54 | R12: 0900-1000 | S12: =SUM(C18:C21) -> 33 | T12: =SUM(D18:D21) -> 29 | U12: =SUM(E18:E21) -> 18 | V12: =SUM(F18:F21) -> 53 | W12: =SUM(G18:G21) -> 0 | X12: =SUM(H18:H21) -> 2 | Y12: =SUM(I18:I21) -> 32 | Z12: =SUM(J18:J21) -> 12 | ... AF12: =SUM(P18:P21) -> 263
B13: 07.45 - 08.00 | C13: 13 | D13: 3 | E13: 1 | F13: 10 | G13: 0 | H13: 0 | I13: 9 | J13: 3 | K13: 0 | L13: 2 | M13: 20 | N13: 0 | O13: =SUM(C13:L13,N13) -> 41 | P13: =SUM(C13:N13) -> 61 | R13: 1000-1100 | S13: =SUM(C22:C25) -> 45 | T13: =SUM(D22:D25) -> 17 | U13: =SUM(E22:E25) -> 15 | V13: =SUM(F22:F25) -> 45 | W13: =SUM(G22:G25) -> 4 | X13: =SUM(H22:H25) -> 1 | Y13: =SUM(I22:I25) -> 22 | Z13: =SUM(J22:J25) -> 15 | ... AF13: =SUM(P22:P25) -> 209
B14: 08.00 - 08.15 | C14: 20 | D14: 6 | E14: 6 | F14: 18 | G14: 0 | H14: 0 | I14: 10 | J14: 1 | K14: 0 | L14: 0 | M14: 23 | N14: 0 | O14: =SUM(C14:L14,N14) -> 61 | P14: =SUM(C14:N14) -> 84 | R14: 1100-1200 | S14: =SUM(C26:C29) -> 90 | T14: =SUM(D26:D29) -> 13 | U14: =SUM(E26:E29) -> 16 | V14: =SUM(F26:F29) -> 68 | W14: =SUM(G26:G29) -> 3 | X14: =SUM(H26:H29) -> 3 | Y14: =SUM(I26:I29) -> 30 | Z14: =SUM(J26:J29) -> 17 | ... AF14: =SUM(P26:P29) -> 327
B15: 08.15 - 08.30 | C15: 21 | D15: 1 | E15: 2 | F15: 10 | G15: 0 | H15: 1 | I15: 4 | J15: 1 | K15: 2 | L15: 0 | M15: 17 | N15: 0 | O15: =SUM(C15:L15,N15) -> 42 | P15: =SUM(C15:N15) -> 59 | R15: 1200-1300 | S15: =SUM(C30:C33) -> 63 | T15: =SUM(D30:D33) -> 25 | U15: =SUM(E30:E33) -> 20 | V15: =SUM(F30:F33) -> 65 | W15: =SUM(G30:G33) -> 4 | X15: =SUM(H30:H33) -> 1 | Y15: =SUM(I30:I33) -> 21 | Z15: =SUM(J30:J33) -> 12 | ... AF15: =SUM(P30:P33) -> 277
B16: 08.30 - 08.45 | C16: 10 | D16: 2 | E16: 4 | F16: 7 | G16: 0 | H16: 0 | I16: 12 | J16: 4 | K16: 2 | L16: 0 | M16: 17 | N16: 0 | O16: =SUM(C16:L16,N16) -> 41 | P16: =SUM(C16:N16) -> 58 | R16: 1300-1400 | S16: =SUM(C34:C37) -> 63 | T16: =SUM(D34:D37) -> 14 | U16: =SUM(E34:E37) -> 14 | V16: =SUM(F34:F37) -> 47 | W16: =SUM(G34:G37) -> 5 | X16: =SUM(H34:H37) -> 3 | Y16: =SUM(I34:I37) -> 26 | Z16: =SUM(J34:J37) -> 11 | ... AF16: =SUM(P34:P37) -> 242
B17: 08.45 - 9.00 | C17: 16 | D17: 3 | E17: 1 | F17: 10 | G17: 0 | H17: 0 | I17: 5 | J17: 0 | K17: 1 | L17: 0 | M17: 15 | N17: 0 | O17: =SUM(C17:L17,N17) -> 36 | P17: =SUM(C17:N17) -> 51 | R17: 1400-1500 | S17: =SUM(C38:C41) -> 62 | T17: =SUM(D38:D41) -> 18 | U17: =SUM(E38:E41) -> 15 | V17: =SUM(F38:F41) -> 67 | W17: =SUM(G38:G41) -> 3 | X17: =SUM(H38:H41) -> 2 | Y17: =SUM(I38:I41) -> 20 | Z17: =SUM(J38:J41) -> 13 | ... AF17: =SUM(P38:P41) -> 259
B18: 09.00 - 09.15 | C18: 11 | D18: 5 | E18: 5 | F18: 14 | G18: 0 | H18: 0 | I18: 9 | J18: 4 | K18: 1 | L18: 0 | M18: 21 | N18: 0 | O18: =SUM(C18:L18,N18) -> 49 | P18: =SUM(C18:N18) -> 70 | R18: 1500-1600 | S18: =SUM(C42:C45) -> 73 | T18: =SUM(D42:D45) -> 8 | U18: =SUM(E42:E45) -> 10 | V18: =SUM(F42:F45) -> 65 | W18: =SUM(G42:G45) -> 0 | X18: =SUM(H42:H45) -> 2 | Y18: =SUM(I42:I45) -> 33 | Z18: =SUM(J42:J45) -> 21 | ... AF18: =SUM(P42:P45) -> 271
B19: 09.15 - 09.30 | C19: 6 | D19: 9 | E19: 1 | F19: 12 | G19: 0 | H19: 1 | I19: 5 | J19: 3 | K19: 0 | L19: 0 | M19: 15 | N19: 0 | O19: =SUM(C19:L19,N19) -> 37 | P19: =SUM(C19:N19) -> 52 | R19: 1600-1700 | S19: =SUM(C46:C49) -> 70 | T19: =SUM(D46:D49) -> 11 | U19: =SUM(E46:E49) -> 13 | V19: =SUM(F46:F49) -> 49 | W19: =SUM(G46:G49) -> 1 | X19: =SUM(H46:H49) -> 2 | Y19: =SUM(I46:I49) -> 30 | Z19: =SUM(J46:J49) -> 17 | ... AF19: =SUM(P46:P49) -> 270
B20: 09.30 - 09.45 | C20: 12 | D20: 12 | E20: 7 | F20: 14 | G20: 0 | H20: 0 | I20: 9 | J20: 1 | K20: 1 | L20: 0 | M20: 20 | N20: 0 | O20: =SUM(C20:L20,N20) -> 56 | P20: =SUM(C20:N20) -> 76 | R20: 1700-1800 | S20: =SUM(C50:C53) -> 54 | T20: =SUM(D50:D53) -> 13 | U20: =SUM(E50:E53) -> 14 | V20: =SUM(F50:F53) -> 56 | W20: =SUM(G50:G53) -> 0 | X20: =SUM(H50:H53) -> 1 | Y20: =SUM(I50:I53) -> 21 | Z20: =SUM(J50:J53) -> 13 | ... AF20: =SUM(P50:P53) -> 211
B21: 09.45 - 10.00 | C21: 4 | D21: 3 | E21: 5 | F21: 13 | G21: 0 | H21: 1 | I21: 9 | J21: 4 | K21: 1 | L21: 0 | M21: 25 | N21: 0 | O21: =SUM(C21:L21,N21) -> 40 | P21: =SUM(C21:N21) -> 65 | R21: 1800-1900 | S21: =SUM(C54:C57) -> 65 | T21: =SUM(D54:D57) -> 6 | U21: =SUM(E54:E57) -> 10 | V21: =SUM(F54:F57) -> 60 | W21: =SUM(G54:G57) -> 2 | X21: =SUM(H54:H57) -> 3 | Y21: =SUM(I54:I57) -> 23 | Z21: =SUM(J54:J57) -> 13 | ... AF21: =SUM(P54:P57) -> 232
B22: 10.00 - 10.15 | C22: 9 | D22: 1 | E22: 4 | F22: 7 | G22: 0 | H22: 0 | I22: 5 | J22: 2 | K22: 0 | L22: 1 | M22: 4 | N22: 0 | O22: =SUM(C22:L22,N22) -> 29 | P22: =SUM(C22:N22) -> 33 | R22: AM Peak Hr | S22: =MAX(S10:S12) -> 67 | T22: =MAX(T10:T12) -> 29 | U22: =MAX(U10:U12) -> 18 | V22: =MAX(V10:V12) -> 53 | W22: =MAX(W10:W12) -> 1 | X22: =MAX(X10:X12) -> 2 | Y22: =MAX(Y10:Y12) -> 32 | Z22: =MAX(Z10:Z12) -> 14 | ... AF22: =MAX(AF10:AF12) -> 263
B23: 10.15 - 10.30 | C23: 15 | D23: 5 | E23: 5 | F23: 13 | G23: 1 | H23: 0 | I23: 5 | J23: 2 | K23: 1 | L23: 1 | M23: 10 | N23: 0 | O23: =SUM(C23:L23,N23) -> 48 | P23: =SUM(C23:N23) -> 58 | R23: IP Peak Hr | S23: =MAX(S13:S18) -> 90 | T23: =MAX(T13:T18) -> 25 | U23: =MAX(U13:U18) -> 20 | V23: =MAX(V13:V18) -> 68 | W23: =MAX(W13:W18) -> 5 | X23: =MAX(X13:X18) -> 3 | Y23: =MAX(Y13:Y18) -> 33 | Z23: =MAX(Z13:Z18) -> 21 | ... AF23: =MAX(AF13:AF18) -> 327
B24: 10.30 - 10.45 | C24: 13 | D24: 5 | E24: 3 | F24: 9 | G24: 1 | H24: 0 | I24: 8 | J24: 5 | K24: 0 | L24: 1 | M24: 10 | N24: 0 | O24: =SUM(C24:L24,N24) -> 45 | P24: =SUM(C24:N24) -> 55 | R24: PM Peak Hr | S24: =MAX(S19:S21) -> 70 | T24: =MAX(T19:T21) -> 13 | U24: =MAX(U19:U21) -> 14 | V24: =MAX(V19:V21) -> 60 | W24: =MAX(W19:W21) -> 2 | X24: =MAX(X19:X21) -> 3 | Y24: =MAX(Y19:Y21) -> 30 | Z24: =MAX(Z19:Z21) -> 17 | ... AF24: =MAX(AF19:AF21) -> 270
B25: 10.45 - 11.00 | C25: 8 | D25: 6 | E25: 3 | F25: 16 | G25: 2 | H25: 1 | I25: 4 | J25: 6 | K25: 1 | L25: 1 | M25: 15 | N25: 0 | O25: =SUM(C25:L25,N25) -> 48 | P25: =SUM(C25:N25) -> 63 | R25: AM Period | S25: =SUM(S10:S12) -> 162 | T25: =SUM(T10:T12) -> 49 | U25: =SUM(U10:U12) -> 44 | V25: =SUM(V10:V12) -> 145 | W25: =SUM(W10:W12) -> 1 | X25: =SUM(X10:X12) -> 4 | Y25: =SUM(Y10:Y12) -> 87 | Z25: =SUM(Z10:Z12) -> 32 | ... AF25: =SUM(AF10:AF12) -> 747
B26: 11.00 - 11.15 | C26: 17 | D26: 3 | E26: 5 | F26: 16 | G26: 0 | H26: 1 | I26: 7 | J26: 4 | K26: 1 | L26: 3 | M26: 23 | N26: 0 | O26: =SUM(C26:L26,N26) -> 57 | P26: =SUM(C26:N26) -> 80 | R26: IP Period | S26: =SUM(S13:S18) -> 396 | T26: =SUM(T13:T18) -> 95 | U26: =SUM(U13:U18) -> 90 | V26: =SUM(V13:V18) -> 357 | W26: =SUM(W13:W18) -> 19 | X26: =SUM(X13:X18) -> 12 | Y26: =SUM(Y13:Y18) -> 152 | Z26: =SUM(Z13:Z18) -> 89 | ... AF26: =SUM(AF13:AF18) -> 1585
B27: 11.15 - 11.30 | C27: 25 | D27: 2 | E27: 3 | F27: 17 | G27: 2 | H27: 0 | I27: 8 | J27: 2 | K27: 0 | L27: 2 | M27: 25 | N27: 0 | O27: =SUM(C27:L27,N27) -> 61 | P27: =SUM(C27:N27) -> 86 | R27: PM Period | S27: =SUM(S19:S21) -> 189 | T27: =SUM(T19:T21) -> 30 | U27: =SUM(U19:U21) -> 37 | V27: =SUM(V19:V21) -> 165 | W27: =SUM(W19:W21) -> 3 | X27: =SUM(X19:X21) -> 6 | Y27: =SUM(Y19:Y21) -> 74 | Z27: =SUM(Z19:Z21) -> 43 | ... AF27: =SUM(AF19:AF21) -> 713
B28: 11.30 - 11.45 | C28: 22 | D28: 3 | E28: 3 | F28: 12 | G28: 0 | H28: 2 | I28: 7 | J28: 7 | K28: 1 | L28: 3 | M28: 14 | N28: 0 | O28: =SUM(C28:L28,N28) -> 60 | P28: =SUM(C28:N28) -> 74 | R28: 12 Hours | S28: =SUM(S10:S21) -> 747 | T28: =SUM(T10:T21) -> 174 | U28: =SUM(U10:U21) -> 171 | V28: =SUM(V10:V21) -> 667 | W28: =SUM(W10:W21) -> 23 | X28: =SUM(X10:X21) -> 22 | Y28: =SUM(Y10:Y21) -> 313 | Z28: =SUM(Z10:Z21) -> 164 | ... AF28: =SUM(AF10:AF21) -> 3045
B29: 11.45 - 12.00 | C29: 26 | D29: 5 | E29: 5 | F29: 23 | G29: 1 | H29: 0 | I29: 8 | J29: 4 | K29: 1 | L29: 0 | M29: 14 | N29: 0 | O29: =SUM(C29:L29,N29) -> 73 | P29: =SUM(C29:N29) -> 87
B30: 12.00 - 12.15 | C30: 23 | D30: 5 | E30: 4 | F30: 20 | G30: 1 | H30: 1 | I30: 8 | J30: 3 | K30: 2 | L30: 0 | M30: 13 | N30: 0 | O30: =SUM(C30:L30,N30) -> 67 | P30: =SUM(C30:N30) -> 80
B31: 12.15 - 12.30 | C31: 11 | D31: 11 | E31: 8 | F31: 19 | G31: 1 | H31: 0 | I31: 2 | J31: 2 | K31: 0 | L31: 1 | M31: 14 | N31: 0 | O31: =SUM(C31:L31,N31) -> 55 | P31: =SUM(C31:N31) -> 69
B32: 12.30 - 12.45 | C32: 21 | D32: 6 | E32: 5 | F32: 19 | G32: 2 | H32: 0 | I32: 8 | J32: 4 | K32: 0 | L32: 1 | M32: 21 | N32: 0 | O32: =SUM(C32:L32,N32) -> 66 | P32: =SUM(C32:N32) -> 87
B33: 12.45 - 13.00 | C33: 8 | D33: 3 | E33: 3 | F33: 7 | G33: 0 | H33: 0 | I33: 3 | J33: 3 | K33: 1 | L33: 0 | M33: 13 | N33: 0 | O33: =SUM(C33:L33,N33) -> 28 | P33: =SUM(C33:N33) -> 41
B34: 13.00 - 13.15 | C34: 17 | D34: 7 | E34: 5 | F34: 14 | G34: 2 | H34: 2 | I34: 6 | J34: 4 | K34: 2 | L34: 1 | M34: 14 | N34: 0 | O34: =SUM(C34:L34,N34) -> 60 | P34: =SUM(C34:N34) -> 74
B35: 13.15 - 13.30 | C35: 24 | D35: 5 | E35: 3 | F35: 13 | G35: 2 | H35: 0 | I35: 8 | J35: 1 | K35: 1 | L35: 0 | M35: 11 | N35: 0 | O35: =SUM(C35:L35,N35) -> 57 | P35: =SUM(C35:N35) -> 68
B36: 13.30 - 13.45 | C36: 8 | D36: 1 | E36: 2 | F36: 5 | G36: 1 | H36: 1 | I36: 5 | J36: 4 | K36: 1 | L36: 0 | M36: 9 | N36: 0 | O36: =SUM(C36:L36,N36) -> 28 | P36: =SUM(C36:N36) -> 37
B37: 13.45 - 14.00 | C37: 14 | D37: 1 | E37: 4 | F37: 15 | G37: 0 | H37: 0 | I37: 7 | J37: 2 | K37: 0 | L37: 5 | M37: 15 | N37: 0 | O37: =SUM(C37:L37,N37) -> 48 | P37: =SUM(C37:N37) -> 63
B38: 14.00 - 14.15 | C38: 19 | D38: 3 | E38: 8 | F38: 17 | G38: 1 | H38: 0 | I38: 9 | J38: 5 | K38: 1 | L38: 1 | M38: 20 | N38: 0 | O38: =SUM(C38:L38,N38) -> 64 | P38: =SUM(C38:N38) -> 84
B39: 14.15 - 14.30 | C39: 13 | D39: 3 | E39: 0 | F39: 10 | G39: 2 | H39: 1 | I39: 2 | J39: 1 | K39: 0 | L39: 1 | M39: 9 | N39: 0 | O39: =SUM(C39:L39,N39) -> 33 | P39: =SUM(C39:N39) -> 42
B40: 14.30 - 14.45 | C40: 15 | D40: 7 | E40: 3 | F40: 17 | G40: 0 | H40: 0 | I40: 3 | J40: 3 | K40: 1 | L40: 1 | M40: 10 | N40: 0 | O40: =SUM(C40:L40,N40) -> 50 | P40: =SUM(C40:N40) -> 60
... B57: 18.45 - 19.00 | C57: 11 | D57: 0 | E57: 3 | F57: 12 | G57: 0 | H57: 2 | I57: 6 | J57: 3 | K57: 0 | L57: 0 | M57: 16 | N57: 0 | O57: =SUM(C57:L57,N57) -> 37 | P57: =SUM(C57:N57) -> 53
B58: Totals | C58: =SUM(C10:C57) -> 747 | D58: =SUM(D10:D57) -> 174 | E58: =SUM(E10:E57) -> 171 | F58: =SUM(F10:F57) -> 667 | G58: =SUM(G10:G57) -> 23 | H58: =SUM(H10:H57) -> 22 | I58: =SUM(I10:I57) -> 313 | J58: =SUM(J10:J57) -> 164 | ... P58: =SUM(P10:P57) -> 3045
...

Sheet 31.10 Bujuko-Buloba-24h
B1: Consultancy services for Preparation of Expressway Development Master Plan (EDMP) for Uganda
B2: MANUAL CLASSIFIED COUNT (MCC)
B3: ROAD NAME: | C3: ='29.10 Bujuko-Buloba'!C3:G3 -> MCC - C2 - STN62 - BUJUKO-BULOBA ROAD
C5: Date | D5: 31.10.19 | F5: Location | G5: ='3.11 Buloba-Bujuko'!G5:H5 -> Buloba Pop Oil | J5: Surveyor | K5: Susan, Nakizito
C6: Dir. From | D6: ='29.10 Bujuko-Buloba'!D6:E6 -> Bujuko | F6: Dir. To | G6: ='29.10 Bujuko-Buloba'!G6:H6 -> Buloba | J6: Supervisor | K6: ='3.11 Buloba-Bujuko'!K6:L6 -> Godfrey
B8: Time / Veh Type | R8: SUMMARY TRAFFIC VOLUMES
C9: 1. Car | D9: 2. Station Wagon | E9: 3. Pickups | F9: 4. Minibus, matatu | G9: 5. Medium bus | H9: 6. Large Bus | I9: 7. Light Truck | J9: 8. Medium Truck | K9: 9. Heavy truck | L9: 10. Truck Trailer | M9: 11. Motor cycles | N9: 12. Tractors | O9: Total Excl M/Cycles | P9: Total All | R9: Time | S9: 1. Car | T9: 2. Station Wagon | U9: 3. Pickups | V9: 4. Minibus, matatu | W9: 5. Medium bus | X9: 6. Large Bus | Y9: 7. Light Truck | Z9: 8. Medium Truck | AA9: 9. Heavy truck | AB9: 10. Truck Trailer | AC9: 11. Motorcycles | AD9: 12. Tractors, Graders | AE9: Total Excl M/ Cycles | AF9: Total All
B10: 07.00 - 07.15 | C10: 8 | D10: 2 | E10: 1 | F10: 4 | G10: 1 | H10: 0 | I10: 0 | J10: 0 | K10: 1 | L10: 0 | M10: 6 | N10: 0 | O10: =SUM(C10:L10,N10) -> 17 | P10: =SUM(C10:N10) -> 23 | R10: 0700-0800 | S10: =SUM(C10:C13) -> 50 | T10: =SUM(D10:D13) -> 8 | U10: =SUM(E10:E13) -> 2 | V10: =SUM(F10:F13) -> 59 | W10: =SUM(G10:G13) -> 1 | X10: =SUM(H10:H13) -> 0 | Y10: =SUM(I10:I13) -> 10 | Z10: =SUM(J10:J13) -> 3 | ... AF10: =SUM(P10:P13) -> 215
B11: 07.15 - 07.30 | C11: 12 | D11: 2 | E11: 0 | F11: 23 | G11: 0 | H11: 0 | I11: 3 | J11: 2 | K11: 0 | L11: 0 | M11: 21 | N11: 0 | O11: =SUM(C11:L11,N11) -> 42 | P11: =SUM(C11:N11) -> 63 | R11: 0800-0900 | S11: =SUM(C14:C17) -> 56 | T11: =SUM(D14:D17) -> 18 | U11: =SUM(E14:E17) -> 1 | V11: =SUM(F14:F17) -> 61 | W11: =SUM(G14:G17) -> 0 | X11: =SUM(H14:H17) -> 0 | Y11: =SUM(I14:I17) -> 12 | Z11: =SUM(J14:J17) -> 5 | ... AF11: =SUM(P14:P17) -> 268
B12: 07.30 - 07.45 | C12: 14 | D12: 1 | E12: 0 | F12: 14 | G12: 0 | H12: 0 | I12: 3 | J12: 1 | K12: 1 | L12: 0 | M12: 34 | N12: 0 | O12: =SUM(C12:L12,N12) -> 34 | P12: =SUM(C12:N12) -> 68 | R12: 0900-1000 | S12: =SUM(C18:C21) -> 31 | T12: =SUM(D18:D21) -> 16 | U12: =SUM(E18:E21) -> 3 | V12: =SUM(F18:F21) -> 48 | W12: =SUM(G18:G21) -> 1 | X12: =SUM(H18:H21) -> 0 | Y12: =SUM(I18:I21) -> 8 | Z12: =SUM(J18:J21) -> 1 | ... AF12: =SUM(P18:P21) -> 179
B13: 07.45 - 08.00 | C13: 16 | D13: 3 | E13: 1 | F13: 18 | G13: 0 | H13: 0 | I13: 4 | J13: 0 | K13: 1 | L13: 0 | M13: 18 | N13: 0 | O13: =SUM(C13:L13,N13) -> 43 | P13: =SUM(C13:N13) -> 61 | R13: 1000-1100 | S13: =SUM(C22:C25) -> 37 | T13: =SUM(D22:D25) -> 12 | U13: =SUM(E22:E25) -> 5 | V13: =SUM(F22:F25) -> 51 | W13: =SUM(G22:G25) -> 0 | X13: =SUM(H22:H25) -> 0 | Y13: =SUM(I22:I25) -> 11 | Z13: =SUM(J22:J25) -> 5 | ... AF13: =SUM(P22:P25) -> 204
B14: 08.00 - 08.15 | C14: 13 | D14: 4 | E14: 0 | F14: 15 | G14: 0 | H14: 0 | I14: 1 | J14: 1 | K14: 1 | L14: 0 | M14: 29 | N14: 0 | O14: =SUM(C14:L14,N14) -> 35 | P14: =SUM(C14:N14) -> 64 | R14: 1100-1200 | S14: =SUM(C26:C29) -> 27 | T14: =SUM(D26:D29) -> 9 | U14: =SUM(E26:E29) -> 5 | V14: =SUM(F26:F29) -> 32 | W14: =SUM(G26:G29) -> 0 | X14: =SUM(H26:H29) -> 1 | Y14: =SUM(I26:I29) -> 14 | Z14: =SUM(J26:J29) -> 1 | ... AF14: =SUM(P26:P29) -> 119
B15: 08.15 - 08.30 | C15: 17 | D15: 6 | E15: 0 | F15: 17 | G15: 0 | H15: 0 | I15: 5 | J15: 4 | K15: 1 | L15: 1 | M15: 25 | N15: 0 | O15: =SUM(C15:L15,N15) -> 51 | P15: =SUM(C15:N15) -> 76 | R15: 1200-1300 | S15: =SUM(C30:C33) -> 31 | T15: =SUM(D30:D33) -> 8 | U15: =SUM(E30:E33) -> 4 | V15: =SUM(F30:F33) -> 35 | W15: =SUM(G30:G33) -> 2 | X15: =SUM(H30:H33) -> 1 | Y15: =SUM(I30:I33) -> 16 | Z15: =SUM(J30:J33) -> 6 | ... AF15: =SUM(P30:P33) -> 145
B16: 08.30 - 08.45 | C16: 15 | D16: 4 | E16: 1 | F16: 14 | G16: 0 | H16: 0 | I16: 1 | J16: 0 | K16: 1 | L16: 0 | M16: 32 | N16: 0 | O16: =SUM(C16:L16,N16) -> 36 | P16: =SUM(C16:N16) -> 68 | R16: 1300-1400 | S16: =SUM(C34:C37) -> 29 | T16: =SUM(D34:D37) -> 13 | U16: =SUM(E34:E37) -> 14 | V16: =SUM(F34:F37) -> 34 | W16: =SUM(G34:G37) -> 2 | X16: =SUM(H34:H37) -> 2 | Y16: =SUM(I34:I37) -> 11 | Z16: =SUM(J34:J37) -> 16 | ... AF16: =SUM(P34:P37) -> 166
B17: 08.45 - 9.00 | C17: 11 | D17: 4 | E17: 0 | F17: 15 | G17: 0 | H17: 0 | I17: 5 | J17: 0 | K17: 0 | L17: 0 | M17: 25 | N17: 0 | O17: =SUM(C17:L17,N17) -> 35 | P17: =SUM(C17:N17) -> 60 | R17: 1400-1500 | S17: =SUM(C38:C41) -> 46 | T17: =SUM(D38:D41) -> 20 | U17: =SUM(E38:E41) -> 7 | V17: =SUM(F38:F41) -> 47 | W17: =SUM(G38:G41) -> 0 | X17: =SUM(H38:H41) -> 1 | Y17: =SUM(I38:I41) -> 34 | Z17: =SUM(J38:J41) -> 10 | ... AF17: =SUM(P38:P41) -> 196
B18: 09.00 - 09.15 | C18: 12 | D18: 7 | E18: 0 | F18: 16 | G18: 0 | H18: 0 | I18: 1 | J18: 1 | K18: 1 | L18: 0 | M18: 15 | N18: 0 | O18: =SUM(C18:L18,N18) -> 38 | P18: =SUM(C18:N18) -> 53 | R18: 1500-1600 | S18: =SUM(C42:C45) -> 36 | T18: =SUM(D42:D45) -> 21 | U18: =SUM(E42:E45) -> 8 | V18: =SUM(F42:F45) -> 44 | W18: =SUM(G42:G45) -> 2 | X18: =SUM(H42:H45) -> 2 | Y18: =SUM(I42:I45) -> 25 | Z18: =SUM(J42:J45) -> 9 | ... AF18: =SUM(P42:P45) -> 206
B19: 09.15 - 09.30 | C19: 9 | D19: 4 | E19: 1 | F19: 10 | G19: 0 | H19: 0 | I19: 3 | J19: 0 | K19: 0 | L19: 0 | M19: 13 | N19: 0 | O19: =SUM(C19:L19,N19) -> 27 | P19: =SUM(C19:N19) -> 40 | R19: 1600-1700 | S19: =SUM(C46:C49) -> 53 | T19: =SUM(D46:D49) -> 27 | U19: =SUM(E46:E49) -> 14 | V19: =SUM(F46:F49) -> 43 | W19: =SUM(G46:G49) -> 3 | X19: =SUM(H46:H49) -> 2 | Y19: =SUM(I46:I49) -> 37 | Z19: =SUM(J46:J49) -> 13 | ... AF19: =SUM(P46:P49) -> 254
B20: 09.30 - 09.45 | C20: 6 | D20: 1 | E20: 0 | F20: 14 | G20: 1 | H20: 0 | I20: 2 | J20: 0 | K20: 0 | L20: 0 | M20: 16 | N20: 0 | O20: =SUM(C20:L20,N20) -> 24 | P20: =SUM(C20:N20) -> 40 | R20: 1700-1800 | S20: =SUM(C50:C53) -> 101 | T20: =SUM(D50:D53) -> 48 | U20: =SUM(E50:E53) -> 20 | V20: =SUM(F50:F53) -> 73 | W20: =SUM(G50:G53) -> 2 | X20: =SUM(H50:H53) -> 6 | Y20: =SUM(I50:I53) -> 35 | Z20: =SUM(J50:J53) -> 12 | ... AF20: =SUM(P50:P53) -> 381
B21: 09.45 - 10.00 | C21: 4 | D21: 4 | E21: 2 | F21: 8 | G21: 0 | H21: 0 | I21: 2 | J21: 0 | K21: 1 | L21: 1 | M21: 24 | N21: 0 | O21: =SUM(C21:L21,N21) -> 22 | P21: =SUM(C21:N21) -> 46 | R21: 1800-1900 | S21: =SUM(C54:C57) -> 50 | T21: =SUM(D54:D57) -> 38 | U21: =SUM(E54:E57) -> 22 | V21: =SUM(F54:F57) -> 50 | W21: =SUM(G54:G57) -> 2 | X21: =SUM(H54:H57) -> 2 | Y21: =SUM(I54:I57) -> 30 | Z21: =SUM(J54:J57) -> 10 | ... AF21: =SUM(P54:P57) -> 277
B22: 10.00 - 10.15 | C22: 10 | D22: 4 | E22: 2 | F22: 17 | G22: 0 | H22: 0 | I22: 1 | J22: 0 | K22: 2 | L22: 0 | M22: 20 | N22: 0 | O22: =SUM(C22:L22,N22) -> 36 | P22: =SUM(C22:N22) -> 56 | R22: 1900-2000 | S22: =SUM(C58:C61) -> 110 | T22: =SUM(D58:D61) -> 23 | U22: =SUM(E58:E61) -> 22 | V22: =SUM(F58:F61) -> 73 | W22: =SUM(G58:G61) -> 2 | X22: =SUM(H58:H61) -> 1 | Y22: =SUM(I58:I61) -> 33 | Z22: =SUM(J58:J61) -> 21 | ... AF22: =SUM(P58:P61) -> 399
B23: 10.15 - 10.30 | C23: 7 | D23: 4 | E23: 0 | F23: 15 | G23: 0 | H23: 0 | I23: 1 | J23: 2 | K23: 2 | L23: 1 | M23: 28 | N23: 0 | O23: =SUM(C23:L23,N23) -> 32 | P23: =SUM(C23:N23) -> 60 | R23: 2000-2100 | S23: =SUM(C62:C65) -> 63 | T23: =SUM(D62:D65) -> 9 | U23: =SUM(E62:E65) -> 13 | V23: =SUM(F62:F65) -> 42 | W23: =SUM(G62:G65) -> 1 | X23: =SUM(H62:H65) -> 0 | Y23: =SUM(I62:I65) -> 12 | Z23: =SUM(J62:J65) -> 15 | ... AF23: =SUM(P62:P65) -> 268
B24: 10.30 - 10.45 | C24: 10 | D24: 1 | E24: 2 | F24: 11 | G24: 0 | H24: 0 | I24: 5 | J24: 1 | K24: 0 | L24: 1 | M24: 17 | N24: 0 | O24: =SUM(C24:L24,N24) -> 31 | P24: =SUM(C24:N24) -> 48 | R24: 2100-2200 | S24: =SUM(C66:C69) -> 65 | T24: =SUM(D66:D69) -> 5 | U24: =SUM(E66:E69) -> 5 | V24: =SUM(F66:F69) -> 36 | W24: =SUM(G66:G69) -> 0 | X24: =SUM(H66:H69) -> 5 | Y24: =SUM(I66:I69) -> 23 | Z24: =SUM(J66:J69) -> 17 | ... AF24: =SUM(P66:P69) -> 225
B25: 10.45 - 11.00 | C25: 10 | D25: 3 | E25: 1 | F25: 8 | G25: 0 | H25: 0 | I25: 4 | J25: 2 | K25: 0 | L25: 0 | M25: 12 | N25: 0 | O25: =SUM(C25:L25,N25) -> 28 | P25: =SUM(C25:N25) -> 40 | R25: 2200-2300 | S25: =SUM(C70:C73) -> 50 | T25: =SUM(D70:D73) -> 7 | U25: =SUM(E70:E73) -> 3 | V25: =SUM(F70:F73) -> 30 | W25: =SUM(G70:G73) -> 0 | X25: =SUM(H70:H73) -> 2 | Y25: =SUM(I70:I73) -> 10 | Z25: =SUM(J70:J73) -> 11 | ... AF25: =SUM(P70:P73) -> 177
B26: 11.00 - 11.15 | C26: 4 | D26: 0 | E26: 0 | F26: 9 | G26: 0 | H26: 1 | I26: 6 | J26: 0 | K26: 1 | L26: 0 | M26: 9 | N26: 0 | O26: =SUM(C26:L26,N26) -> 21 | P26: =SUM(C26:N26) -> 30 | R26: 2300-0000 | S26: =SUM(C74:C77) -> 23 | T26: =SUM(D74:D77) -> 4 | U26: =SUM(E74:E77) -> 2 | V26: =SUM(F74:F77) -> 11 | W26: =SUM(G74:G77) -> 0 | X26: =SUM(H74:H77) -> 0 | Y26: =SUM(I74:I77) -> 8 | Z26: =SUM(J74:J77) -> 9 | ... AF26: =SUM(P74:P77) -> 92
B27: 11.15 - 11.30 | C27: 8 | D27: 3 | E27: 1 | F27: 8 | G27: 0 | H27: 0 | I27: 2 | J27: 1 | K27: 0 | L27: 0 | M27: 4 | N27: 0 | O27: =SUM(C27:L27,N27) -> 23 | P27: =SUM(C27:N27) -> 27 | R27: 0000-0100 | S27: =SUM(C78:C81) -> 9 | T27: =SUM(D78:D81) -> 3 | U27: =SUM(E78:E81) -> 5 | V27: =SUM(F78:F81) -> 6 | W27: =SUM(G78:G81) -> 0 | X27: =SUM(H78:H81) -> 0 | Y27: =SUM(I78:I81) -> 5 | Z27: =SUM(J78:J81) -> 12 | ... AF27: =SUM(P78:P81) -> 51
B28: 11.30 - 11.45 | C28: 7 | D28: 4 | E28: 2 | F28: 3 | G28: 0 | H28: 0 | I28: 3 | J28: 0 | K28: 0 | L28: 0 | M28: 8 | N28: 0 | O28: =SUM(C28:L28,N28) -> 19 | P28: =SUM(C28:N28) -> 27 | R28: 0100-0200 | S28: =SUM(C82:C85) -> 7 | T28: =SUM(D82:D85) -> 2 | U28: =SUM(E82:E85) -> 4 | V28: =SUM(F82:F85) -> 0 | W28: =SUM(G82:G85) -> 0 | X28: =SUM(H82:H85) -> 0 | Y28: =SUM(I82:I85) -> 4 | Z28: =SUM(J82:J85) -> 5 | ... AF28: =SUM(P82:P85) -> 36
