Workbook

Sheet 23.09 Sonde-Namugongo
B1: Consultancy services for Preparation of Expressway Development Master Plan (EDMP) for Uganda
B2: MANUAL CLASSIFIED COUNT (MCC)
B3: ROAD NAME: | C3: MCC-C2-STNO 73
C5: Date | D5: 23.09.19 | F5: Location | G5: ='[1] 23.09.19 Bukasa-Wakiso'!G5:H5 -> Bukasa | J5: Surveyor | K5: Kalebo Mark
C6: Dir. From | D6: SSONDE | F6: Dir. To | G6: NAMUGONGO | J6: Supervisor | K6: Tracy
B8: Time / Veh Type | R8: SUMMARY TRAFFIC VOLUMES
C9: 1. Car | D9: 2. Station Wagon | E9: 3. Pickups | F9: 4. Minibus, matatu | G9: 5. Medium bus | H9: 6. Large Bus | I9: 7. Light Truck | J9: 8. Medium Truck | K9: 9. Heavy truck | L9: 10. Truck Trailer | M9: 11. Motor cycles | N9: 12. Tractors | O9: Total Excl M/Cycles | P9: Total All | R9: Time | S9: 1. Car | T9: 2. Station Wagon | U9: 3. Pickups | V9: 4. Minibus, matatu | W9: 5. Medium bus | X9: 6. Large Bus | Y9: 7. Light Truck | Z9: 8. Medium Truck | AA9: 9. Heavy truck | AB9: 10. Truck Trailer | AC9: 11. Motorcycles | AD9: 12. Tractors, Graders | AE9: Total Excl M/ Cycles | AF9: Total All
B10: 07.00 - 07.15 | C10: 40 | D10: 12 | E10: 4 | F10: 14 | G10: 0 | H10: 0 | I10: 2 | J10: 1 | K10: 0 | L10: 0 | M10: 13 | N10: 0 | O10: =SUM(C10:L10,N10) -> 73 | P10: =SUM(C10:N10) -> 86 | R10: 0700-0800 | S10: =SUM(C10:C13) -> 186 | T10: =SUM(D10:D13) -> 61 | U10: =SUM(E10:E13) -> 26 | V10: =SUM(F10:F13) -> 51 | W10: =SUM(G10:G13) -> 0 | X10: =SUM(H10:H13) -> 3 | Y10: =SUM(I10:I13) -> 16 | Z10: =SUM(J10:J13) -> 5 | ... AF10: =SUM(P10:P13) -> 562
B11: 07.15 - 07.30 | C11: 45 | D11: 13 | E11: 7 | F11: 19 | G11: 0 | H11: 0 | I11: 4 | J11: 2 | K11: 0 | L11: 0 | M11: 72 | N11: 0 | O11: =SUM(C11:L11,N11) -> 90 | P11: =SUM(C11:N11) -> 162 | R11: 0800-0900 | S11: =SUM(C14:C17) -> 192 | T11: =SUM(D14:D17) -> 62 | U11: =SUM(E14:E17) -> 30 | V11: =SUM(F14:F17) -> 73 | W11: =SUM(G14:G17) -> 0 | X11: =SUM(H14:H17) -> 0 | Y11: =SUM(I14:I17) -> 10 | Z11: =SUM(J14:J17) -> 5 | ... AF11: =SUM(P14:P17) -> 629
B12: 07.30 - 07.45 | C12: 51 | D12: 13 | E12: 7 | F12: 18 | G12: 0 | H12: 0 | I12: 7 | J12: 2 | K12: 0 | L12: 0 | M12: 67 | N12: 0 | O12: =SUM(C12:L12,N12) -> 98 | P12: =SUM(C12:N12) -> 165 | R12: 0900-1000 | S12: =SUM(C18:C21) -> 141 | T12: =SUM(D18:D21) -> 32 | U12: =SUM(E18:E21) -> 27 | V12: =SUM(F18:F21) -> 56 | W12: =SUM(G18:G21) -> 0 | X12: =SUM(H18:H21) -> 1 | Y12: =SUM(I18:I21) -> 15 | Z12: =SUM(J18:J21) -> 7 | ... AF12: =SUM(P18:P21) -> 461
B13: 07.45 - 08.00 | C13: 50 | D13: 23 | E13: 8 | F13: 0 | G13: 0 | H13: 3 | I13: 3 | J13: 0 | K13: 0 | L13: 0 | M13: 62 | N13: 0 | O13: =SUM(C13:L13,N13) -> 87 | P13: =SUM(C13:N13) -> 149 | R13: 1000-1100 | S13: =SUM(C22:C25) -> 113 | T13: =SUM(D22:D25) -> 35 | U13: =SUM(E22:E25) -> 27 | V13: =SUM(F22:F25) -> 51 | W13: =SUM(G22:G25) -> 0 | X13: =SUM(H22:H25) -> 0 | Y13: =SUM(I22:I25) -> 23 | Z13: =SUM(J22:J25) -> 9 | ... AF13: =SUM(P22:P25) -> 404
B14: 08.00 - 08.15 | C14: 42 | D14: 15 | E14: 6 | F14: 14 | G14: 0 | H14: 0 | I14: 2 | J14: 2 | K14: 2 | L14: 0 | M14: 57 | N14: 0 | O14: =SUM(C14:L14,N14) -> 83 | P14: =SUM(C14:N14) -> 140 | R14: 1100-1200 | S14: =SUM(C26:C29) -> 117 | T14: =SUM(D26:D29) -> 36 | U14: =SUM(E26:E29) -> 27 | V14: =SUM(F26:F29) -> 61 | W14: =SUM(G26:G29) -> 0 | X14: =SUM(H26:H29) -> 0 | Y14: =SUM(I26:I29) -> 22 | Z14: =SUM(J26:J29) -> 7 | ... AF14: =SUM(P26:P29) -> 390
B15: 08.15 - 08.30 | C15: 47 | D15: 19 | E15: 9 | F15: 17 | G15: 0 | H15: 0 | I15: 2 | J15: 0 | K15: 0 | L15: 0 | M15: 73 | N15: 0 | O15: =SUM(C15:L15,N15) -> 94 | P15: =SUM(C15:N15) -> 167 | R15: 1200-1300 | S15: =SUM(C30:C33) -> 124 | T15: =SUM(D30:D33) -> 33 | U15: =SUM(E30:E33) -> 26 | V15: =SUM(F30:F33) -> 50 | W15: =SUM(G30:G33) -> 0 | X15: =SUM(H30:H33) -> 0 | Y15: =SUM(I30:I33) -> 25 | Z15: =SUM(J30:J33) -> 8 | ... AF15: =SUM(P30:P33) -> 365
B16: 08.30 - 08.45 | C16: 60 | D16: 12 | E16: 7 | F16: 18 | G16: 0 | H16: 0 | I16: 3 | J16: 1 | K16: 1 | L16: 0 | M16: 58 | N16: 0 | O16: =SUM(C16:L16,N16) -> 102 | P16: =SUM(C16:N16) -> 160 | R16: 1300-1400 | S16: =SUM(C34:C37) -> 86 | T16: =SUM(D34:D37) -> 34 | U16: =SUM(E34:E37) -> 22 | V16: =SUM(F34:F37) -> 53 | W16: =SUM(G34:G37) -> 1 | X16: =SUM(H34:H37) -> 0 | Y16: =SUM(I34:I37) -> 31 | Z16: =SUM(J34:J37) -> 7 | ... AF16: =SUM(P34:P37) -> 349
B17: 08.45 - 9.00 | C17: 43 | D17: 16 | E17: 8 | F17: 24 | G17: 0 | H17: 0 | I17: 3 | J17: 2 | K17: 1 | L17: 0 | M17: 65 | N17: 0 | O17: =SUM(C17:L17,N17) -> 97 | P17: =SUM(C17:N17) -> 162 | R17: 1400-1500 | S17: =SUM(C38:C41) -> 66 | T17: =SUM(D38:D41) -> 25 | U17: =SUM(E38:E41) -> 17 | V17: =SUM(F38:F41) -> 36 | W17: =SUM(G38:G41) -> 0 | X17: =SUM(H38:H41) -> 0 | Y17: =SUM(I38:I41) -> 22 | Z17: =SUM(J38:J41) -> 3 | ... AF17: =SUM(P38:P41) -> 246
B18: 09.00 - 09.15 | C18: 44 | D18: 6 | E18: 6 | F18: 13 | G18: 0 | H18: 1 | I18: 3 | J18: 1 | K18: 0 | L18: 0 | M18: 44 | N18: 0 | O18: =SUM(C18:L18,N18) -> 74 | P18: =SUM(C18:N18) -> 118 | R18: 1500-1600 | S18: =SUM(C42:C45) -> 137 | T18: =SUM(D42:D45) -> 42 | U18: =SUM(E42:E45) -> 25 | V18: =SUM(F42:F45) -> 59 | W18: =SUM(G42:G45) -> 0 | X18: =SUM(H42:H45) -> 0 | Y18: =SUM(I42:I45) -> 24 | Z18: =SUM(J42:J45) -> 10 | ... AF18: =SUM(P42:P45) -> 375
B19: 09.15 - 09.30 | C19: 34 | D19: 13 | E19: 6 | F19: 17 | G19: 0 | H19: 0 | I19: 4 | J19: 3 | K19: 0 | L19: 0 | M19: 57 | N19: 0 | O19: =SUM(C19:L19,N19) -> 77 | P19: =SUM(C19:N19) -> 134 | R19: 1600-1700 | S19: =SUM(C46:C49) -> 112 | T19: =SUM(D46:D49) -> 44 | U19: =SUM(E46:E49) -> 28 | V19: =SUM(F46:F49) -> 49 | W19: =SUM(G46:G49) -> 2 | X19: =SUM(H46:H49) -> 0 | Y19: =SUM(I46:I49) -> 20 | Z19: =SUM(J46:J49) -> 4 | ... AF19: =SUM(P46:P49) -> 384
B20: 09.30 - 09.45 | C20: 35 | D20: 5 | E20: 11 | F20: 12 | G20: 0 | H20: 0 | I20: 4 | J20: 1 | K20: 0 | L20: 0 | M20: 29 | N20: 0 | O20: =SUM(C20:L20,N20) -> 68 | P20: =SUM(C20:N20) -> 97 | R20: 1700-1800 | S20: =SUM(C50:C53) -> 131 | T20: =SUM(D50:D53) -> 44 | U20: =SUM(E50:E53) -> 24 | V20: =SUM(F50:F53) -> 59 | W20: =SUM(G50:G53) -> 3 | X20: =SUM(H50:H53) -> 0 | Y20: =SUM(I50:I53) -> 35 | Z20: =SUM(J50:J53) -> 9 | ... AF20: =SUM(P50:P53) -> 415
B21: 09.45 - 10.00 | C21: 28 | D21: 8 | E21: 4 | F21: 14 | G21: 0 | H21: 0 | I21: 4 | J21: 2 | K21: 4 | L21: 0 | M21: 48 | N21: 0 | O21: =SUM(C21:L21,N21) -> 64 | P21: =SUM(C21:N21) -> 112 | R21: 1800-1900 | S21: =SUM(C54:C57) -> 119 | T21: =SUM(D54:D57) -> 48 | U21: =SUM(E54:E57) -> 35 | V21: =SUM(F54:F57) -> 63 | W21: =SUM(G54:G57) -> 4 | X21: =SUM(H54:H57) -> 0 | Y21: =SUM(I54:I57) -> 25 | Z21: =SUM(J54:J57) -> 5 | ... AF21: =SUM(P54:P57) -> 419
B22: 10.00 - 10.15 | C22: 26 | D22: 9 | E22: 8 | F22: 14 | G22: 0 | H22: 0 | I22: 5 | J22: 1 | K22: 0 | L22: 0 | M22: 34 | N22: 0 | O22: =SUM(C22:L22,N22) -> 63 | P22: =SUM(C22:N22) -> 97 | R22: AM Peak Hr | S22: =MAX(S10:S12) -> 192 | T22: =MAX(T10:T12) -> 62 | U22: =MAX(U10:U12) -> 30 | V22: =MAX(V10:V12) -> 73 | W22: =MAX(W10:W12) -> 0 | X22: =MAX(X10:X12) -> 3 | Y22: =MAX(Y10:Y12) -> 16 | Z22: =MAX(Z10:Z12) -> 7 | ... AF22: =MAX(AF10:AF12) -> 629
B23: 10.15 - 10.30 | C23: 27 | D23: 4 | E23: 6 | F23: 12 | G23: 0 | H23: 0 | I23: 7 | J23: 0 | K23: 0 | L23: 0 | M23: 46 | N23: 0 | O23: =SUM(C23:L23,N23) -> 56 | P23: =SUM(C23:N23) -> 102 | R23: IP Peak Hr | S23: =MAX(S13:S18) -> 137 | T23: =MAX(T13:T18) -> 42 | U23: =MAX(U13:U18) -> 27 | V23: =MAX(V13:V18) -> 61 | W23: =MAX(W13:W18) -> 1 | X23: =MAX(X13:X18) -> 0 | Y23: =MAX(Y13:Y18) -> 31 | Z23: =MAX(Z13:Z18) -> 10 | ... AF23: =MAX(AF13:AF18) -> 404
B24: 10.30 - 10.45 | C24: 28 | D24: 12 | E24: 7 | F24: 15 | G24: 0 | H24: 0 | I24: 4 | J24: 4 | K24: 1 | L24: 0 | M24: 29 | N24: 0 | O24: =SUM(C24:L24,N24) -> 71 | P24: =SUM(C24:N24) -> 100 | R24: PM Peak Hr | S24: =MAX(S19:S21) -> 131 | T24: =MAX(T19:T21) -> 48 | U24: =MAX(U19:U21) -> 35 | V24: =MAX(V19:V21) -> 63 | W24: =MAX(W19:W21) -> 4 | X24: =MAX(X19:X21) -> 0 | Y24: =MAX(Y19:Y21) -> 35 | Z24: =MAX(Z19:Z21) -> 9 | ... AF24: =MAX(AF19:AF21) -> 419
B25: 10.45 - 11.00 | C25: 32 | D25: 10 | E25: 6 | F25: 10 | G25: 0 | H25: 0 | I25: 7 | J25: 4 | K25: 1 | L25: 0 | M25: 35 | N25: 0 | O25: =SUM(C25:L25,N25) -> 70 | P25: =SUM(C25:N25) -> 105 | R25: AM Period | S25: =SUM(S10:S12) -> 519 | T25: =SUM(T10:T12) -> 155 | U25: =SUM(U10:U12) -> 83 | V25: =SUM(V10:V12) -> 180 | W25: =SUM(W10:W12) -> 0 | X25: =SUM(X10:X12) -> 4 | Y25: =SUM(Y10:Y12) -> 41 | Z25: =SUM(Z10:Z12) -> 17 | ... AF25: =SUM(AF10:AF12) -> 1652
B26: 11.00 - 11.15 | C26: 28 | D26: 8 | E26: 5 | F26: 16 | G26: 0 | H26: 0 | I26: 6 | J26: 1 | K26: 1 | L26: 0 | M26: 23 | N26: 0 | O26: =SUM(C26:L26,N26) -> 65 | P26: =SUM(C26:N26) -> 88 | R26: IP Period | S26: =SUM(S13:S18) -> 643 | T26: =SUM(T13:T18) -> 205 | U26: =SUM(U13:U18) -> 144 | V26: =SUM(V13:V18) -> 310 | W26: =SUM(W13:W18) -> 1 | X26: =SUM(X13:X18) -> 0 | Y26: =SUM(Y13:Y18) -> 147 | Z26: =SUM(Z13:Z18) -> 44 | ... AF26: =SUM(AF13:AF18) -> 2129
B27: 11.15 - 11.30 | C27: 30 | D27: 16 | E27: 11 | F27: 18 | G27: 0 | H27: 0 | I27: 5 | J27: 4 | K27: 3 | L27: 0 | M27: 35 | N27: 0 | O27: =SUM(C27:L27,N27) -> 87 | P27: =SUM(C27:N27) -> 122 | R27: PM Period | S27: =SUM(S19:S21) -> 362 | T27: =SUM(T19:T21) -> 136 | U27: =SUM(U19:U21) -> 87 | V27: =SUM(V19:V21) -> 171 | W27: =SUM(W19:W21) -> 9 | X27: =SUM(X19:X21) -> 0 | Y27: =SUM(Y19:Y21) -> 80 | Z27: =SUM(Z19:Z21) -> 18 | ... AF27: =SUM(AF19:AF21) -> 1218
B28: 11.30 - 11.45 | C28: 33 | D28: 9 | E28: 6 | F28: 15 | G28: 0 | H28: 0 | I28: 5 | J28: 2 | K28: 2 | L28: 0 | M28: 38 | N28: 0 | O28: =SUM(C28:L28,N28) -> 72 | P28: =SUM(C28:N28) -> 110 | R28: 12 Hours | S28: =SUM(S10:S21) -> 1524 | T28: =SUM(T10:T21) -> 496 | U28: =SUM(U10:U21) -> 314 | V28: =SUM(V10:V21) -> 661 | W28: =SUM(W10:W21) -> 10 | X28: =SUM(X10:X21) -> 4 | Y28: =SUM(Y10:Y21) -> 268 | Z28: =SUM(Z10:Z21) -> 79 | ... AF28: =SUM(AF10:AF21) -> 4999
B29: 11.45 - 12.00 | C29: 26 | D29: 3 | E29: 5 | F29: 12 | G29: 0 | H29: 0 | I29: 6 | J29: 0 | K29: 2 | L29: 1 | M29: 15 | N29: 0 | O29: =SUM(C29:L29,N29) -> 55 | P29: =SUM(C29:N29) -> 70
B30: 12.00 - 12.15 | C30: 48 | D30: 11 | E30: 8 | F30: 17 | G30: 0 | H30: 0 | I30: 6 | J30: 3 | K30: 1 | L30: 0 | M30: 27 | N30: 0 | O30: =SUM(C30:L30,N30) -> 94 | P30: =SUM(C30:N30) -> 121
B31: 12.15 - 12.30 | C31: 21 | D31: 5 | E31: 4 | F31: 7 | G31: 0 | H31: 0 | I31: 8 | J31: 0 | K31: 1 | L31: 0 | M31: 20 | N31: 0 | O31: =SUM(C31:L31,N31) -> 46 | P31: =SUM(C31:N31) -> 66
B32: 12.30 - 12.45 | C32: 25 | D32: 6 | E32: 10 | F32: 16 | G32: 0 | H32: 0 | I32: 5 | J32: 4 | K32: 1 | L32: 0 | M32: 27 | N32: 0 | O32: =SUM(C32:L32,N32) -> 67 | P32: =SUM(C32:N32) -> 94
B33: 12.45 - 13.00 | C33: 30 | D33: 11 | E33: 4 | F33: 10 | G33: 0 | H33: 0 | I33: 6 | J33: 1 | K33: 1 | L33: 1 | M33: 20 | N33: 0 | O33: =SUM(C33:L33,N33) -> 64 | P33: =SUM(C33:N33) -> 84
B34: 13.00 - 13.15 | C34: 15 | D34: 6 | E34: 5 | F34: 10 | G34: 0 | H34: 0 | I34: 2 | J34: 3 | K34: 0 | L34: 0 | M34: 17 | N34: 0 | O34: =SUM(C34:L34,N34) -> 41 | P34: =SUM(C34:N34) -> 58
B35: 13.15 - 13.30 | C35: 25 | D35: 4 | E35: 7 | F35: 17 | G35: 0 | H35: 0 | I35: 11 | J35: 1 | K35: 2 | L35: 0 | M35: 28 | N35: 0 | O35: =SUM(C35:L35,N35) -> 67 | P35: =SUM(C35:N35) -> 95
B36: 13.30 - 13.45 | C36: 23 | D36: 12 | E36: 5 | F36: 11 | G36: 0 | H36: 0 | I36: 5 | J36: 2 | K36: 1 | L36: 0 | M36: 28 | N36: 0 | O36: =SUM(C36:L36,N36) -> 59 | P36: =SUM(C36:N36) -> 87
B37: 13.45 - 14.00 | C37: 23 | D37: 12 | E37: 5 | F37: 15 | G37: 1 | H37: 0 | I37: 13 | J37: 1 | K37: 1 | L37: 0 | M37: 38 | N37: 0 | O37: =SUM(C37:L37,N37) -> 71 | P37: =SUM(C37:N37) -> 109
B38: 14.00 - 14.15 | C38: 16 | D38: 2 | E38: 5 | F38: 4 | G38: 0 | H38: 0 | I38: 6 | J38: 0 | K38: 1 | L38: 0 | M38: 13 | N38: 0 | O38: =SUM(C38:L38,N38) -> 34 | P38: =SUM(C38:N38) -> 47
B39: 14.15 - 14.30 | C39: 14 | D39: 10 | E39: 5 | F39: 8 | G39: 0 | H39: 0 | I39: 4 | J39: 1 | K39: 1 | L39: 0 | M39: 12 | N39: 0 | O39: =SUM(C39:L39,N39) -> 43 | P39: =SUM(C39:N39) -> 55
B40: 14.30 - 14.45 | C40: 15 | D40: 12 | E40: 4 | F40: 10 | G40: 0 | H40: 0 | I40: 8 | J40: 2 | K40: 0 | L40: 0 | M40: 28 | N40: 0 | O40: =SUM(C40:L40,N40) -> 51 | P40: =SUM(C40:N40) -> 79
... B57: 18.45 - 19.00 | C57: 34 | D57: 8 | E57: 6 | F57: 14 | G57: 0 | H57: 0 | I57: 5 | J57: 1 | K57: 1 | L57: 0 | M57: 24 | N57: 0 | O57: =SUM(C57:L57,N57) -> 69 | P57: =SUM(C57:N57) -> 93
B58: Totals | C58: =SUM(C10:C57) -> 1524 | D58: =SUM(D10:D57) -> 496 | E58: =SUM(E10:E57) -> 314 | F58: =SUM(F10:F57) -> 661 | G58: =SUM(G10:G57) -> 10 | H58: =SUM(H10:H57) -> 4 | I58: =SUM(I10:I57) -> 268 | J58: =SUM(J10:J57) -> 79 | ... P58: =SUM(P10:P57) -> 4999
...

Sheet 23.09 Namugongo-Sonde
B1: Consultancy services for Preparation of Expressway Development Master Plan (EDMP) for Uganda
B2: MANUAL CLASSIFIED COUNT (MCC)
B3: ROAD NAME: | C3: MCC-C2-STNO 73
C5: Date | D5: ='[2]23.09.19-Ssonde-Namugongo'!D5 -> 23.09.19 | F5: Location | G5: Ssonde RD | J5: Surveyor | K5: Amony Jovana
C6: Dir. From | D6: NAMUGONGO | F6: Dir. To | G6: SSONDE | J6: Supervisor | K6: Tracy
B8: Time / Veh Type | R8: SUMMARY TRAFFIC VOLUMES
C9: 1. Car | D9: 2. Station Wagon | E9: 3. Pickups | F9: 4. Minibus, matatu | G9: 5. Medium bus | H9: 6. Large Bus | I9: 7. Light Truck | J9: 8. Medium Truck | K9: 9. Heavy truck | L9: 10. Truck Trailer | M9: 11. Motor cycles | N9: 12. Tractors | O9: Total Excl M/Cycles | P9: Total All | R9: Time | S9: 1. Car | T9: 2. Station Wagon | U9: 3. Pickups | V9: 4. Minibus, matatu | W9: 5. Medium bus | X9: 6. Large Bus | Y9: 7. Light Truck | Z9: 8. Medium Truck | AA9: 9. Heavy truck | AB9: 10. Truck Trailer | AC9: 11. Motorcycles | AD9: 12. Tractors, Graders | AE9: Total Excl M/ Cycles | AF9: Total All
B10: 07.00 - 07.15 | C10: 25 | D10: 25 | E10: 6 | F10: 9 | G10: 0 | H10: 0 | I10: 5 | J10: 2 | K10: 0 | L10: 0 | M10: 9 | N10: 0 | O10: =SUM(C10:L10,N10) -> 72 | P10: =SUM(C10:N10) -> 81 | R10: 0700-0800 | S10: =SUM(C10:C13) -> 108 | T10: =SUM(D10:D13) -> 106 | U10: =SUM(E10:E13) -> 46 | V10: =SUM(F10:F13) -> 42 | W10: =SUM(G10:G13) -> 2 | X10: =SUM(H10:H13) -> 0 | Y10: =SUM(I10:I13) -> 10 | Z10: =SUM(J10:J13) -> 7 | ... AF10: =SUM(P10:P13) -> 417
B11: 07.15 - 07.30 | C11: 23 | D11: 20 | E11: 15 | F11: 12 | G11: 1 | H11: 0 | I11: 1 | J11: 2 | K11: 0 | L11: 0 | M11: 19 | N11: 0 | O11: =SUM(C11:L11,N11) -> 74 | P11: =SUM(C11:N11) -> 93 | R11: 0800-0900 | S11: =SUM(C14:C17) -> 131 | T11: =SUM(D14:D17) -> 85 | U11: =SUM(E14:E17) -> 31 | V11: =SUM(F14:F17) -> 31 | W11: =SUM(G14:G17) -> 1 | X11: =SUM(H14:H17) -> 1 | Y11: =SUM(I14:I17) -> 16 | Z11: =SUM(J14:J17) -> 9 | ... AF11: =SUM(P14:P17) -> 453
B12: 07.30 - 07.45 | C12: 25 | D12: 32 | E12: 15 | F12: 11 | G12: 0 | H12: 0 | I12: 3 | J12: 2 | K12: 0 | L12: 0 | M12: 28 | N12: 0 | O12: =SUM(C12:L12,N12) -> 88 | P12: =SUM(C12:N12) -> 116 | R12: 0900-1000 | S12: =SUM(C18:C21) -> 113 | T12: =SUM(D18:D21) -> 95 | U12: =SUM(E18:E21) -> 41 | V12: =SUM(F18:F21) -> 44 | W12: =SUM(G18:G21) -> 2 | X12: =SUM(H18:H21) -> 0 | Y12: =SUM(I18:I21) -> 17 | Z12: =SUM(J18:J21) -> 12 | ... AF12: =SUM(P18:P21) -> 489
B13: 07.45 - 08.00 | C13: 35 | D13: 29 | E13: 10 | F13: 10 | G13: 1 | H13: 0 | I13: 1 | J13: 1 | K13: 0 | L13: 0 | M13: 40 | N13: 0 | O13: =SUM(C13:L13,N13) -> 87 | P13: =SUM(C13:N13) -> 127 | R13: 1000-1100 | S13: =SUM(C22:C25) -> 108 | T13: =SUM(D22:D25) -> 87 | U13: =SUM(E22:E25) -> 30 | V13: =SUM(F22:F25) -> 43 | W13: =SUM(G22:G25) -> 3 | X13: =SUM(H22:H25) -> 0 | Y13: =SUM(I22:I25) -> 41 | Z13: =SUM(J22:J25) -> 13 | ... AF13: =SUM(P22:P25) -> 456
B14: 08.00 - 08.15 | C14: 26 | D14: 8 | E14: 6 | F14: 5 | G14: 0 | H14: 0 | I14: 3 | J14: 0 | K14: 0 | L14: 0 | M14: 35 | N14: 0 | O14: =SUM(C14:L14,N14) -> 48 | P14: =SUM(C14:N14) -> 83 | R14: 1100-1200 | S14: =SUM(C26:C29) -> 81 | T14: =SUM(D26:D29) -> 61 | U14: =SUM(E26:E29) -> 25 | V14: =SUM(F26:F29) -> 33 | W14: =SUM(G26:G29) -> 0 | X14: =SUM(H26:H29) -> 0 | Y14: =SUM(I26:I29) -> 41 | Z14: =SUM(J26:J29) -> 10 | ... AF14: =SUM(P26:P29) -> 365
B15: 08.15 - 08.30 | C15: 35 | D15: 22 | E15: 12 | F15: 6 | G15: 0 | H15: 1 | I15: 3 | J15: 1 | K15: 0 | L15: 1 | M15: 40 | N15: 0 | O15: =SUM(C15:L15,N15) -> 81 | P15: =SUM(C15:N15) -> 121 | R15: 1200-1300 | S15: =SUM(C30:C33) -> 117 | T15: =SUM(D30:D33) -> 85 | U15: =SUM(E30:E33) -> 33 | V15: =SUM(F30:F33) -> 43 | W15: =SUM(G30:G33) -> 3 | X15: =SUM(H30:H33) -> 0 | Y15: =SUM(I30:I33) -> 47 | Z15: =SUM(J30:J33) -> 11 | ... AF15: =SUM(P30:P33) -> 457
B16: 08.30 - 08.45 | C16: 31 | D16: 22 | E16: 8 | F16: 8 | G16: 0 | H16: 0 | I16: 5 | J16: 2 | K16: 0 | L16: 0 | M16: 40 | N16: 0 | O16: =SUM(C16:L16,N16) -> 76 | P16: =SUM(C16:N16) -> 116 | R16: 1300-1400 | S16: =SUM(C34:C37) -> 84 | T16: =SUM(D34:D37) -> 62 | U16: =SUM(E34:E37) -> 39 | V16: =SUM(F34:F37) -> 40 | W16: =SUM(G34:G37) -> 1 | X16: =SUM(H34:H37) -> 0 | Y16: =SUM(I34:I37) -> 37 | Z16: =SUM(J34:J37) -> 16 | ... AF16: =SUM(P34:P37) -> 400
B17: 08.45 - 9.00 | C17: 39 | D17: 33 | E17: 5 | F17: 12 | G17: 1 | H17: 0 | I17: 5 | J17: 6 | K17: 0 | L17: 0 | M17: 32 | N17: 0 | O17: =SUM(C17:L17,N17) -> 101 | P17: =SUM(C17:N17) -> 133 | R17: 1400-1500 | S17: =SUM(C38:C41) -> 75 | T17: =SUM(D38:D41) -> 77 | U17: =SUM(E38:E41) -> 27 | V17: =SUM(F38:F41) -> 41 | W17: =SUM(G38:G41) -> 1 | X17: =SUM(H38:H41) -> 1 | Y17: =SUM(I38:I41) -> 32 | Z17: =SUM(J38:J41) -> 12 | ... AF17: =SUM(P38:P41) -> 368
B18: 09.00 - 09.15 | C18: 31 | D18: 29 | E18: 13 | F18: 11 | G18: 0 | H18: 0 | I18: 1 | J18: 2 | K18: 0 | L18: 0 | M18: 44 | N18: 0 | O18: =SUM(C18:L18,N18) -> 87 | P18: =SUM(C18:N18) -> 131 | R18: 1500-1600 | S18: =SUM(C42:C45) -> 73 | T18: =SUM(D42:D45) -> 76 | U18: =SUM(E42:E45) -> 35 | V18: =SUM(F42:F45) -> 34 | W18: =SUM(G42:G45) -> 1 | X18: =SUM(H42:H45) -> 0 | Y18: =SUM(I42:I45) -> 30 | Z18: =SUM(J42:J45) -> 21 | ... AF18: =SUM(P42:P45) -> 369
B19: 09.15 - 09.30 | C19: 29 | D19: 27 | E19: 9 | F19: 8 | G19: 0 | H19: 0 | I19: 5 | J19: 2 | K19: 0 | L19: 0 | M19: 53 | N19: 0 | O19: =SUM(C19:L19,N19) -> 80 | P19: =SUM(C19:N19) -> 133 | R19: 1600-1700 | S19: =SUM(C46:C49) -> 101 | T19: =SUM(D46:D49) -> 100 | U19: =SUM(E46:E49) -> 22 | V19: =SUM(F46:F49) -> 35 | W19: =SUM(G46:G49) -> 1 | X19: =SUM(H46:H49) -> 0 | Y19: =SUM(I46:I49) -> 28 | Z19: =SUM(J46:J49) -> 13 | ... AF19: =SUM(P46:P49) -> 394
B20: 09.30 - 09.45 | C20: 22 | D20: 17 | E20: 5 | F20: 13 | G20: 1 | H20: 0 | I20: 6 | J20: 3 | K20: 1 | L20: 1 | M20: 27 | N20: 0 | O20: =SUM(C20:L20,N20) -> 69 | P20: =SUM(C20:N20) -> 96 | R20: 1700-1800 | S20: =SUM(C50:C53) -> 124 | T20: =SUM(D50:D53) -> 123 | U20: =SUM(E50:E53) -> 31 | V20: =SUM(F50:F53) -> 32 | W20: =SUM(G50:G53) -> 2 | X20: =SUM(H50:H53) -> 0 | Y20: =SUM(I50:I53) -> 30 | Z20: =SUM(J50:J53) -> 14 | ... AF20: =SUM(P50:P53) -> 478
B21: 09.45 - 10.00 | C21: 31 | D21: 22 | E21: 14 | F21: 12 | G21: 1 | H21: 0 | I21: 5 | J21: 5 | K21: 0 | L21: 1 | M21: 35 | N21: 3 | O21: =SUM(C21:L21,N21) -> 94 | P21: =SUM(C21:N21) -> 129 | R21: 1800-1900 | S21: =SUM(C54:C57) -> 170 | T21: =SUM(D54:D57) -> 95 | U21: =SUM(E54:E57) -> 34 | V21: =SUM(F54:F57) -> 38 | W21: =SUM(G54:G57) -> 1 | X21: =SUM(H54:H57) -> 1 | Y21: =SUM(I54:I57) -> 20 | Z21: =SUM(J54:J57) -> 6 | ... AF21: =SUM(P54:P57) -> 547
B22: 10.00 - 10.15 | C22: 31 | D22: 26 | E22: 3 | F22: 8 | G22: 2 | H22: 0 | I22: 11 | J22: 8 | K22: 0 | L22: 0 | M22: 38 | N22: 0 | O22: =SUM(C22:L22,N22) -> 89 | P22: =SUM(C22:N22) -> 127 | R22: AM Peak Hr | S22: =MAX(S10:S12) -> 131 | T22: =MAX(T10:T12) -> 106 | U22: =MAX(U10:U12) -> 46 | V22: =MAX(V10:V12) -> 44 | W22: =MAX(W10:W12) -> 2 | X22: =MAX(X10:X12) -> 1 | Y22: =MAX(Y10:Y12) -> 17 | Z22: =MAX(Z10:Z12) -> 12 | ... AF22: =MAX(AF10:AF12) -> 489
B23: 10.15 - 10.30 | C23: 24 | D23: 21 | E23: 8 | F23: 14 | G23: 0 | H23: 0 | I23: 15 | J23: 2 | K23: 0 | L23: 1 | M23: 29 | N23: 0 | O23: =SUM(C23:L23,N23) -> 85 | P23: =SUM(C23:N23) -> 114 | R23: IP Peak Hr | S23: =MAX(S13:S18) -> 117 | T23: =MAX(T13:T18) -> 87 | U23: =MAX(U13:U18) -> 39 | V23: =MAX(V13:V18) -> 43 | W23: =MAX(W13:W18) -> 3 | X23: =MAX(X13:X18) -> 1 | Y23: =MAX(Y13:Y18) -> 47 | Z23: =MAX(Z13:Z18) -> 21 | ... AF23: =MAX(AF13:AF18) -> 457
B24: 10.30 - 10.45 | C24: 30 | D24: 23 | E24: 14 | F24: 7 | G24: 1 | H24: 0 | I24: 12 | J24: 2 | K24: 0 | L24: 0 | M24: 28 | N24: 0 | O24: =SUM(C24:L24,N24) -> 89 | P24: =SUM(C24:N24) -> 117 | R24: PM Peak Hr | S24: =MAX(S19:S21) -> 170 | T24: =MAX(T19:T21) -> 123 | U24: =MAX(U19:U21) -> 34 | V24: =MAX(V19:V21) -> 38 | W24: =MAX(W19:W21) -> 2 | X24: =MAX(X19:X21) -> 1 | Y24: =MAX(Y19:Y21) -> 30 | Z24: =MAX(Z19:Z21) -> 14 | ... AF24: =MAX(AF19:AF21) -> 547
B25: 10.45 - 11.00 | C25: 23 | D25: 17 | E25: 5 | F25: 14 | G25: 0 | H25: 0 | I25: 3 | J25: 1 | K25: 0 | L25: 0 | M25: 35 | N25: 0 | O25: =SUM(C25:L25,N25) -> 63 | P25: =SUM(C25:N25) -> 98 | R25: AM Period | S25: =SUM(S10:S12) -> 352 | T25: =SUM(T10:T12) -> 286 | U25: =SUM(U10:U12) -> 118 | V25: =SUM(V10:V12) -> 117 | W25: =SUM(W10:W12) -> 5 | X25: =SUM(X10:X12) -> 1 | Y25: =SUM(Y10:Y12) -> 43 | Z25: =SUM(Z10:Z12) -> 28 | ... AF25: =SUM(AF10:AF12) -> 1359
B26: 11.00 - 11.15 | C26: 27 | D26: 17 | E26: 6 | F26: 7 | G26: 0 | H26: 0 | I26: 8 | J26: 1 | K26: 0 | L26: 0 | M26: 30 | N26: 0 | O26: =SUM(C26:L26,N26) -> 66 | P26: =SUM(C26:N26) -> 96 | R26: IP Period | S26: =SUM(S13:S18) -> 538 | T26: =SUM(T13:T18) -> 448 | U26: =SUM(U13:U18) -> 189 | V26: =SUM(V13:V18) -> 234 | W26: =SUM(W13:W18) -> 9 | X26: =SUM(X13:X18) -> 1 | Y26: =SUM(Y13:Y18) -> 228 | Z26: =SUM(Z13:Z18) -> 83 | ... AF26: =SUM(AF13:AF18) -> 2415
B27: 11.15 - 11.30 | C27: 18 | D27: 14 | E27: 9 | F27: 8 | G27: 0 | H27: 0 | I27: 7 | J27: 4 | K27: 0 | L27: 0 | M27: 37 | N27: 0 | O27: =SUM(C27:L27,N27) -> 60 | P27: =SUM(C27:N27) -> 97 | R27: PM Period | S27: =SUM(S19:S21) -> 395 | T27: =SUM(T19:T21) -> 318 | U27: =SUM(U19:U21) -> 87 | V27: =SUM(V19:V21) -> 105 | W27: =SUM(W19:W21) -> 4 | X27: =SUM(X19:X21) -> 1 | Y27: =SUM(Y19:Y21) -> 78 | Z27: =SUM(Z19:Z21) -> 33 | ... AF27: =SUM(AF19:AF21) -> 1419
B28: 11.30 - 11.45 | C28: 23 | D28: 17 | E28: 5 | F28: 10 | G28: 0 | H28: 0 | I28: 13 | J28: 0 | K28: 0 | L28: 0 | M28: 19 | N28: 0 | O28: =SUM(C28:L28,N28) -> 68 | P28: =SUM(C28:N28) -> 87 | R28: 12 Hours | S28: =SUM(S10:S21) -> 1285 | T28: =SUM(T10:T21) -> 1052 | U28: =SUM(U10:U21) -> 394 | V28: =SUM(V10:V21) -> 456 | W28: =SUM(W10:W21) -> 18 | X28: =SUM(X10:X21) -> 3 | Y28: =SUM(Y10:Y21) -> 349 | Z28: =SUM(Z10:Z21) -> 144 | ... AF28: =SUM(AF10:AF21) -> 5193
B29: 11.45 - 12.00 | C29: 13 | D29: 13 | E29: 5 | F29: 8 | G29: 0 | H29: 0 | I29: 13 | J29: 5 | K29: 0 | L29: 0 | M29: 28 | N29: 0 | O29: =SUM(C29:L29,N29) -> 57 | P29: =SUM(C29:N29) -> 85
B30: 12.00 - 12.15 | C30: 35 | D30: 24 | E30: 9 | F30: 15 | G30: 0 | H30: 0 | I30: 9 | J30: 5 | K30: 0 | L30: 1 | M30: 29 | N30: 0 | O30: =SUM(C30:L30,N30) -> 98 | P30: =SUM(C30:N30) -> 127
B31: 12.15 - 12.30 | C31: 30 | D31: 24 | E31: 8 | F31: 7 | G31: 1 | H31: 0 | I31: 13 | J31: 4 | K31: 0 | L31: 0 | M31: 35 | N31: 0 | O31: =SUM(C31:L31,N31) -> 87 | P31: =SUM(C31:N31) -> 122
B32: 12.30 - 12.45 | C32: 24 | D32: 21 | E32: 7 | F32: 11 | G32: 2 | H32: 0 | I32: 14 | J32: 0 | K32: 0 | L32: 1 | M32: 32 | N32: 0 | O32: =SUM(C32:L32,N32) -> 80 | P32: =SUM(C32:N32) -> 112
B33: 12.45 - 13.00 | C33: 28 | D33: 16 | E33: 9 | F33: 10 | G33: 0 | H33: 0 | I33: 11 | J33: 2 | K33: 0 | L33: 0 | M33: 20 | N33: 0 | O33: =SUM(C33:L33,N33) -> 76 | P33: =SUM(C33:N33) -> 96
B34: 13.00 - 13.15 | C34: 27 | D34: 16 | E34: 7 | F34: 11 | G34: 1 | H34: 0 | I34: 11 | J34: 2 | K34: 1 | L34: 0 | M34: 27 | N34: 0 | O34: =SUM(C34:L34,N34) -> 76 | P34: =SUM(C34:N34) -> 103
B35: 13.15 - 13.30 | C35: 13 | D35: 12 | E35: 10 | F35: 8 | G35: 0 | H35: 0 | I35: 9 | J35: 3 | K35: 0 | L35: 2 | M35: 33 | N35: 0 | O35: =SUM(C35:L35,N35) -> 57 | P35: =SUM(C35:N35) -> 90
B36: 13.30 - 13.45 | C36: 22 | D36: 16 | E36: 17 | F36: 11 | G36: 0 | H36: 0 | I36: 10 | J36: 4 | K36: 0 | L36: 2 | M36: 32 | N36: 0 | O36: =SUM(C36:L36,N36) -> 82 | P36: =SUM(C36:N36) -> 114
B37: 13.45 - 14.00 | C37: 22 | D37: 18 | E37: 5 | F37: 10 | G37: 0 | H37: 0 | I37: 7 | J37: 7 | K37: 0 | L37: 0 | M37: 24 | N37: 0 | O37: =SUM(C37:L37,N37) -> 69 | P37: =SUM(C37:N37) -> 93
B38: 14.00 - 14.15 | C38: 17 | D38: 14 | E38: 6 | F38: 14 | G38: 0 | H38: 0 | I38: 8 | J38: 7 | K38: 1 | L38: 3 | M38: 24 | N38: 0 | O38: =SUM(C38:L38,N38) -> 70 | P38: =SUM(C38:N38) -> 94
B39: 14.15 - 14.30 | C39: 19 | D39: 26 | E39: 8 | F39: 10 | G39: 0 | H39: 0 | I39: 5 | J39: 1 | K39: 0 | L39: 2 | M39: 22 | N39: 0 | O39: =SUM(C39:L39,N39) -> 71 | P39: =SUM(C39:N39) -> 93
B40: 14.30 - 14.45 | C40: 16 | D40: 19 | E40: 9 | F40: 8 | G40: 1 | H40: 0 | I40: 12 | J40: 2 | K40: 1 | L40: 3 | M40: 26 | N40: 0 | O40: =SUM(C40:L40,N40) -> 71 | P40: =SUM(C40:N40) -> 97
... B57: 18.45 - 19.00 | C57: 47 | D57: 26 | E57: 9 | F57: 8 | G57: 0 | H57: 0 | I57: 9 | J57: 1 | K57: 0 | L57: 1 | M57: 37 | N57: 0 | O57: =SUM(C57:L57,N57) -> 101 | P57: =SUM(C57:N57) -> 138
B58: Totals | C58: =SUM(C10:C57) -> 1285 | D58: =SUM(D10:D57) -> 1052 | E58: =SUM(E10:E57) -> 394 | F58: =SUM(F10:F57) -> 456 | G58: =SUM(G10:G57) -> 18 | H58: =SUM(H10:H57) -> 3 | I58: =SUM(I10:I57) -> 349 | J58: =SUM(J10:J57) -> 144 | ... P58: =SUM(P10:P57) -> 5193
...

Sheet 24.09 Sonde-Namugongo
B1: Consultancy services for Preparation of Expressway Development Master Plan (EDMP) for Uganda
B2: MANUAL CLASSIFIED COUNT (MCC)
B3: ROAD NAME: | C3: ='[3]24.09.19 Namugongo-Ssonde '!C3:G3 -> MCC - C2 - STN073-SONDE ROAD
C5: Date | D5: ='[3]24.09.19 Namugongo-Ssonde '!D5 -> 24.09.19 | F5: Location | G5: ='[3]24.09.19 Namugongo-Ssonde '!G5:H5 -> SONDE STATION | J5: Surveyor | K5: ='[3]24.09.19 Namugongo-Ssonde '!K5:L5 -> Amony Bella
C6: Dir. From | D6: Sonde | F6: Dir. To | G6: Namugongo | J6: Supervisor | K6: ='[3]24.09.19 Namugongo-Ssonde '!K6:L6 -> Tracy
B8: Time / Veh Type | R8: SUMMARY TRAFFIC VOLUMES
C9: 1. Car | D9: 2. Station Wagon | E9: 3. Pickups | F9: 4. Minibus, matatu | G9: 5. Medium bus | H9: 6. Large Bus | I9: 7. Light Truck | J9: 8. Medium Truck | K9: 9. Heavy truck | L9: 10. Truck Trailer | M9: 11. Motor cycles | N9: 12. Tractors | O9: Total Excl M/Cycles | P9: Total All | R9: Time | S9: 1. Car | T9: 2. Station Wagon | U9: 3. Pickups | V9: 4. Minibus, matatu | W9: 5. Medium bus | X9: 6. Large Bus | Y9: 7. Light Truck | Z9: 8. Medium Truck | AA9: 9. Heavy truck | AB9: 10. Truck Trailer | AC9: 11. Motorcycles | AD9: 12. Tractors, Graders | AE9: Total Excl M/ Cycles | AF9: Total All
B10: 07.00 - 07.15 | C10: 44 | D10: 12 | E10: 11 | F10: 12 | G10: 1 | H10: 0 | I10: 6 | J10: 1 | K10: 1 | L10: 0 | M10: 32 | N10: 0 | O10: =SUM(C10:L10,N10) -> 88 | P10: =SUM(C10:N10) -> 120 | R10: 0700-0800 | S10: =SUM(C10:C13) -> 150 | T10: =SUM(D10:D13) -> 62 | U10: =SUM(E10:E13) -> 37 | V10: =SUM(F10:F13) -> 59 | W10: =SUM(G10:G13) -> 4 | X10: =SUM(H10:H13) -> 1 | Y10: =SUM(I10:I13) -> 16 | Z10: =SUM(J10:J13) -> 16 | ... AF10: =SUM(P10:P13) -> 499
B11: 07.15 - 07.30 | C11: 32 | D11: 20 | E11: 7 | F11: 10 | G11: 2 | H11: 0 | I11: 4 | J11: 2 | K11: 1 | L11: 0 | M11: 38 | N11: 0 | O11: =SUM(C11:L11,N11) -> 78 | P11: =SUM(C11:N11) -> 116 | R11: 0800-0900 | S11: =SUM(C14:C17) -> 148 | T11: =SUM(D14:D17) -> 71 | U11: =SUM(E14:E17) -> 30 | V11: =SUM(F14:F17) -> 36 | W11: =SUM(G14:G17) -> 1 | X11: =SUM(H14:H17) -> 0 | Y11: =SUM(I14:I17) -> 12 | Z11: =SUM(J14:J17) -> 5 | ... AF11: =SUM(P14:P17) -> 464
B12: 07.30 - 07.45 | C12: 35 | D12: 19 | E12: 10 | F12: 16 | G12: 1 | H12: 1 | I12: 3 | J12: 3 | K12: 1 | L12: 3 | M12: 27 | N12: 0 | O12: =SUM(C12:L12,N12) -> 92 | P12: =SUM(C12:N12) -> 119 | R12: 0900-1000 | S12: =SUM(C18:C21) -> 137 | T12: =SUM(D18:D21) -> 53 | U12: =SUM(E18:E21) -> 40 | V12: =SUM(F18:F21) -> 46 | W12: =SUM(G18:G21) -> 0 | X12: =SUM(H18:H21) -> 0 | Y12: =SUM(I18:I21) -> 19 | Z12: =SUM(J18:J21) -> 3 | ... AF12: =SUM(P18:P21) -> 458
B13: 07.45 - 08.00 | C13: 39 | D13: 11 | E13: 9 | F13: 21 | G13: 0 | H13: 0 | I13: 3 | J13: 10 | K13: 3 | L13: 0 | M13: 48 | N13: 0 | O13: =SUM(C13:L13,N13) -> 96 | P13: =SUM(C13:N13) -> 144 | R13: 1000-1100 | S13: =SUM(C22:C25) -> 97 | T13: =SUM(D22:D25) -> 46 | U13: =SUM(E22:E25) -> 28 | V13: =SUM(F22:F25) -> 40 | W13: =SUM(G22:G25) -> 1 | X13: =SUM(H22:H25) -> 0 | Y13: =SUM(I22:I25) -> 13 | Z13: =SUM(J22:J25) -> 6 | ... AF13: =SUM(P22:P25) -> 350
B14: 08.00 - 08.15 | C14: 35 | D14: 16 | E14: 13 | F14: 8 | G14: 0 | H14: 0 | I14: 0 | J14: 2 | K14: 0 | L14: 1 | M14: 42 | N14: 0 | O14: =SUM(C14:L14,N14) -> 75 | P14: =SUM(C14:N14) -> 117 | R14: 1100-1200 | S14: =SUM(C26:C29) -> 98 | T14: =SUM(D26:D29) -> 55 | U14: =SUM(E26:E29) -> 24 | V14: =SUM(F26:F29) -> 32 | W14: =SUM(G26:G29) -> 0 | X14: =SUM(H26:H29) -> 1 | Y14: =SUM(I26:I29) -> 32 | Z14: =SUM(J26:J29) -> 7 | ... AF14: =SUM(P26:P29) -> 378
B15: 08.15 - 08.30 | C15: 37 | D15: 21 | E15: 6 | F15: 9 | G15: 1 | H15: 0 | I15: 5 | J15: 1 | K15: 1 | L15: 0 | M15: 49 | N15: 0 | O15: =SUM(C15:L15,N15) -> 81 | P15: =SUM(C15:N15) -> 130 | R15: 1200-1300 | S15: =SUM(C30:C33) -> 107 | T15: =SUM(D30:D33) -> 38 | U15: =SUM(E30:E33) -> 28 | V15: =SUM(F30:F33) -> 31 | W15: =SUM(G30:G33) -> 0 | X15: =SUM(H30:H33) -> 0 | Y15: =SUM(I30:I33) -> 33 | Z15: =SUM(J30:J33) -> 6 | ... AF15: =SUM(P30:P33) -> 341
B16: 08.30 - 08.45 | C16: 31 | D16: 16 | E16: 6 | F16: 10 | G16: 0 | H16: 0 | I16: 5 | J16: 1 | K16: 1 | L16: 0 | M16: 34 | N16: 0 | O16: =SUM(C16:L16,N16) -> 70 | P16: =SUM(C16:N16) -> 104 | R16: 1300-1400 | S16: =SUM(C34:C37) -> 104 | T16: =SUM(D34:D37) -> 39 | U16: =SUM(E34:E37) -> 19 | V16: =SUM(F34:F37) -> 30 | W16: =SUM(G34:G37) -> 0 | X16: =SUM(H34:H37) -> 1 | Y16: =SUM(I34:I37) -> 29 | Z16: =SUM(J34:J37) -> 5 | ... AF16: =SUM(P34:P37) -> 305
B17: 08.45 - 9.00 | C17: 45 | D17: 18 | E17: 5 | F17: 9 | G17: 0 | H17: 0 | I17: 2 | J17: 1 | K17: 1 | L17: 0 | M17: 32 | N17: 0 | O17: =SUM(C17:L17,N17) -> 81 | P17: =SUM(C17:N17) -> 113 | R17: 1400-1500 | S17: =SUM(C38:C41) -> 87 | T17: =SUM(D38:D41) -> 47 | U17: =SUM(E38:E41) -> 17 | V17: =SUM(F38:F41) -> 33 | W17: =SUM(G38:G41) -> 0 | X17: =SUM(H38:H41) -> 0 | Y17: =SUM(I38:I41) -> 35 | Z17: =SUM(J38:J41) -> 2 | ... AF17: =SUM(P38:P41) -> 305
B18: 09.00 - 09.15 | C18: 35 | D18: 11 | E18: 9 | F18: 13 | G18: 0 | H18: 0 | I18: 1 | J18: 0 | K18: 0 | L18: 0 | M18: 43 | N18: 0 | O18: =SUM(C18:L18,N18) -> 69 | P18: =SUM(C18:N18) -> 112 | R18: 1500-1600 | S18: =SUM(C42:C45) -> 120 | T18: =SUM(D42:D45) -> 62 | U18: =SUM(E42:E45) -> 30 | V18: =SUM(F42:F45) -> 44 | W18: =SUM(G42:G45) -> 0 | X18: =SUM(H42:H45) -> 0 | Y18: =SUM(I42:I45) -> 24 | Z18: =SUM(J42:J45) -> 9 | ... AF18: =SUM(P42:P45) -> 408
B19: 09.15 - 09.30 | C19: 41 | D19: 18 | E19: 10 | F19: 12 | G19: 0 | H19: 0 | I19: 8 | J19: 1 | K19: 1 | L19: 0 | M19: 43 | N19: 0 | O19: =SUM(C19:L19,N19) -> 91 | P19: =SUM(C19:N19) -> 134 | R19: 1600-1700 | S19: =SUM(C46:C49) -> 128 | T19: =SUM(D46:D49) -> 78 | U19: =SUM(E46:E49) -> 49 | V19: =SUM(F46:F49) -> 50 | W19: =SUM(G46:G49) -> 7 | X19: =SUM(H46:H49) -> 0 | Y19: =SUM(I46:I49) -> 33 | Z19: =SUM(J46:J49) -> 13 | ... AF19: =SUM(P46:P49) -> 488
B20: 09.30 - 09.45 | C20: 26 | D20: 9 | E20: 10 | F20: 9 | G20: 0 | H20: 0 | I20: 7 | J20: 0 | K20: 2 | L20: 0 | M20: 30 | N20: 0 | O20: =SUM(C20:L20,N20) -> 63 | P20: =SUM(C20:N20) -> 93 | R20: 1700-1800 | S20: =SUM(C50:C53) -> 166 | T20: =SUM(D50:D53) -> 89 | U20: =SUM(E50:E53) -> 32 | V20: =SUM(F50:F53) -> 58 | W20: =SUM(G50:G53) -> 7 | X20: =SUM(H50:H53) -> 0 | Y20: =SUM(I50:I53) -> 37 | Z20: =SUM(J50:J53) -> 10 | ... AF20: =SUM(P50:P53) -> 560
B21: 09.45 - 10.00 | C21: 35 | D21: 15 | E21: 11 | F21: 12 | G21: 0 | H21: 0 | I21: 3 | J21: 2 | K21: 4 | L21: 0 | M21: 37 | N21: 0 | O21: =SUM(C21:L21,N21) -> 82 | P21: =SUM(C21:N21) -> 119 | R21: 1800-1900 | S21: =SUM(C54:C57) -> 162 | T21: =SUM(D54:D57) -> 51 | U21: =SUM(E54:E57) -> 28 | V21: =SUM(F54:F57) -> 60 | W21: =SUM(G54:G57) -> 1 | X21: =SUM(H54:H57) -> 0 | Y21: =SUM(I54:I57) -> 17 | Z21: =SUM(J54:J57) -> 5 | ... AF21: =SUM(P54:P57) -> 482
B22: 10.00 - 10.15 | C22: 28 | D22: 8 | E22: 7 | F22: 16 | G22: 1 | H22: 0 | I22: 1 | J22: 0 | K22: 1 | L22: 0 | M22: 30 | N22: 0 | O22: =SUM(C22:L22,N22) -> 62 | P22: =SUM(C22:N22) -> 92 | R22: AM Peak Hr | S22: =MAX(S10:S12) -> 150 | T22: =MAX(T10:T12) -> 71 | U22: =MAX(U10:U12) -> 40 | V22: =MAX(V10:V12) -> 59 | W22: =MAX(W10:W12) -> 4 | X22: =MAX(X10:X12) -> 1 | Y22: =MAX(Y10:Y12) -> 19 | Z22: =MAX(Z10:Z12) -> 16 | ... AF22: =MAX(AF10:AF12) -> 499
B23: 10.15 - 10.30 | C23: 14 | D23: 11 | E23: 9 | F23: 11 | G23: 0 | H23: 0 | I23: 5 | J23: 1 | K23: 1 | L23: 0 | M23: 26 | N23: 0 | O23: =SUM(C23:L23,N23) -> 52 | P23: =SUM(C23:N23) -> 78 | R23: IP Peak Hr | S23: =MAX(S13:S18) -> 120 | T23: =MAX(T13:T18) -> 62 | U23: =MAX(U13:U18) -> 30 | V23: =MAX(V13:V18) -> 44 | W23: =MAX(W13:W18) -> 1 | X23: =MAX(X13:X18) -> 1 | Y23: =MAX(Y13:Y18) -> 35 | Z23: =MAX(Z13:Z18) -> 9 | ... AF23: =MAX(AF13:AF18) -> 408
B24: 10.30 - 10.45 | C24: 38 | D24: 15 | E24: 4 | F24: 5 | G24: 0 | H24: 0 | I24: 4 | J24: 3 | K24: 0 | L24: 0 | M24: 23 | N24: 0 | O24: =SUM(C24:L24,N24) -> 69 | P24: =SUM(C24:N24) -> 92 | R24: PM Peak Hr | S24: =MAX(S19:S21) -> 166 | T24: =MAX(T19:T21) -> 89 | U24: =MAX(U19:U21) -> 49 | V24: =MAX(V19:V21) -> 60 | W24: =MAX(W19:W21) -> 7 | X24: =MAX(X19:X21) -> 0 | Y24: =MAX(Y19:Y21) -> 37 | Z24: =MAX(Z19:Z21) -> 13 | ... AF24: =MAX(AF19:AF21) -> 560
B25: 10.45 - 11.00 | C25: 17 | D25: 12 | E25: 8 | F25: 8 | G25: 0 | H25: 0 | I25: 3 | J25: 2 | K25: 3 | L25: 0 | M25: 35 | N25: 0 | O25: =SUM(C25:L25,N25) -> 53 | P25: =SUM(C25:N25) -> 88 | R25: AM Period | S25: =SUM(S10:S12) -> 435 | T25: =SUM(T10:T12) -> 186 | U25: =SUM(U10:U12) -> 107 | V25: =SUM(V10:V12) -> 141 | W25: =SUM(W10:W12) -> 5 | X25: =SUM(X10:X12) -> 1 | Y25: =SUM(Y10:Y12) -> 47 | Z25: =SUM(Z10:Z12) -> 24 | ... AF25: =SUM(AF10:AF12) -> 1421
B26: 11.00 - 11.15 | C26: 36 | D26: 17 | E26: 10 | F26: 6 | G26: 0 | H26: 0 | I26: 11 | J26: 5 | K26: 1 | L26: 0 | M26: 37 | N26: 0 | O26: =SUM(C26:L26,N26) -> 86 | P26: =SUM(C26:N26) -> 123 | R26: IP Period | S26: =SUM(S13:S18) -> 613 | T26: =SUM(T13:T18) -> 287 | U26: =SUM(U13:U18) -> 146 | V26: =SUM(V13:V18) -> 210 | W26: =SUM(W13:W18) -> 1 | X26: =SUM(X13:X18) -> 2 | Y26: =SUM(Y13:Y18) -> 166 | Z26: =SUM(Z13:Z18) -> 35 | ... AF26: =SUM(AF13:AF18) -> 2087
B27: 11.15 - 11.30 | C27: 19 | D27: 16 | E27: 4 | F27: 4 | G27: 0 | H27: 0 | I27: 6 | J27: 1 | K27: 0 | L27: 2 | M27: 18 | N27: 0 | O27: =SUM(C27:L27,N27) -> 52 | P27: =SUM(C27:N27) -> 70 | R27: PM Period | S27: =SUM(S19:S21) -> 456 | T27: =SUM(T19:T21) -> 218 | U27: =SUM(U19:U21) -> 109 | V27: =SUM(V19:V21) -> 168 | W27: =SUM(W19:W21) -> 15 | X27: =SUM(X19:X21) -> 0 | Y27: =SUM(Y19:Y21) -> 87 | Z27: =SUM(Z19:Z21) -> 28 | ... AF27: =SUM(AF19:AF21) -> 1530
B28: 11.30 - 11.45 | C28: 22 | D28: 10 | E28: 7 | F28: 16 | G28: 0 | H28: 1 | I28: 10 | J28: 1 | K28: 2 | L28: 0 | M28: 36 | N28: 0 | O28: =SUM(C28:L28,N28) -> 69 | P28: =SUM(C28:N28) -> 105 | R28: 12 Hours | S28: =SUM(S10:S21) -> 1504 | T28: =SUM(T10:T21) -> 691 | U28: =SUM(U10:U21) -> 362 | V28: =SUM(V10:V21) -> 519 | W28: =SUM(W10:W21) -> 21 | X28: =SUM(X10:X21) -> 3 | Y28: =SUM(Y10:Y21) -> 300 | Z28: =SUM(Z10:Z21) -> 87 | ... AF28: =SUM(AF10:AF21) -> 5038
B29: 11.45 - 12.00 | C29: 21 | D29: 12 | E29: 3 | F29: 6 | G29: 0 | H29: 0 | I29: 5 | J29: 0 | K29: 2 | L29: 0 | M29: 31 | N29: 0 | O29: =SUM(C29:L29,N29) -> 49 | P29: =SUM(C29:N29) -> 80
B30: 12.00 - 12.15 | C30: 30 | D30: 16 | E30: 4 | F30: 10 | G30: 0 | H30: 0 | I30: 9 | J30: 2 | K30: 2 | L30: 0 | M30: 26 | N30: 0 | O30: =SUM(C30:L30,N30) -> 73 | P30: =SUM(C30:N30) -> 99
B31: 12.15 - 12.30 | C31: 29 | D31: 10 | E31: 9 | F31: 8 | G31: 0 | H31: 0 | I31: 6 | J31: 1 | K31: 4 | L31: 0 | M31: 31 | N31: 0 | O31: =SUM(C31:L31,N31) -> 67 | P31: =SUM(C31:N31) -> 98
B32: 12.30 - 12.45 | C32: 20 | D32: 6 | E32: 8 | F32: 7 | G32: 0 | H32: 0 | I32: 12 | J32: 2 | K32: 1 | L32: 0 | M32: 16 | N32: 0 | O32: =SUM(C32:L32,N32) -> 56 | P32: =SUM(C32:N32) -> 72
B33: 12.45 - 13.00 | C33: 28 | D33: 6 | E33: 7 | F33: 6 | G33: 0 | H33: 0 | I33: 6 | J33: 1 | K33: 1 | L33: 0 | M33: 17 | N33: 0 | O33: =SUM(C33:L33,N33) -> 55 | P33: =SUM(C33:N33) -> 72
B34: 13.00 - 13.15 | C34: 23 | D34: 7 | E34: 5 | F34: 6 | G34: 0 | H34: 0 | I34: 3 | J34: 1 | K34: 3 | L34: 0 | M34: 11 | N34: 0 | O34: =SUM(C34:L34,N34) -> 48 | P34: =SUM(C34:N34) -> 59
B35: 13.15 - 13.30 | C35: 28 | D35: 15 | E35: 5 | F35: 8 | G35: 0 | H35: 0 | I35: 13 | J35: 1 | K35: 0 | L35: 1 | M35: 18 | N35: 0 | O35: =SUM(C35:L35,N35) -> 71 | P35: =SUM(C35:N35) -> 89
B36: 13.30 - 13.45 | C36: 26 | D36: 15 | E36: 5 | F36: 11 | G36: 0 | H36: 1 | I36: 7 | J36: 2 | K36: 1 | L36: 0 | M36: 28 | N36: 0 | O36: =SUM(C36:L36,N36) -> 68 | P36: =SUM(C36:N36) -> 96
B37: 13.45 - 14.00 | C37: 27 | D37: 2 | E37: 4 | F37: 5 | G37: 0 | H37: 0 | I37: 6 | J37: 1 | K37: 3 | L37: 0 | M37: 13 | N37: 0 | O37: =SUM(C37:L37,N37) -> 48 | P37: =SUM(C37:N37) -> 61
B38: 14.00 - 14.15 | C38: 20 | D38: 21 | E38: 7 | F38: 6 | G38: 0 | H38: 0 | I38: 11 | J38: 0 | K38: 2 | L38: 0 | M38: 21 | N38: 0 | O38: =SUM(C38:L38,N38) -> 67 | P38: =SUM(C38:N38) -> 88
B39: 14.15 - 14.30 | C39: 25 | D39: 3 | E39: 4 | F39: 9 | G39: 0 | H39: 0 | I39: 5 | J39: 2 | K39: 4 | L39: 0 | M39: 7 | N39: 0 | O39: =SUM(C39:L39,N39) -> 52 | P39: =SUM(C39:N39) -> 59
B40: 14.30 - 14.45 | C40: 19 | D40: 9 | E40: 2 | F40: 9 | G40: 0 | H40: 0 | I40: 12 | J40: 0 | K40: 1 | L40: 1 | M40: 20 | N40: 0 | O40: =SUM(C40:L40,N40) -> 53 | P40: =SUM(C40:N40) -> 73
... B57: 18.45 - 19.00 | C57: 41 | D57: 18 | E57: 7 | F57: 16 | G57: 1 | H57: 0 | I57: 10 | J57: 0 | K57: 0 | L57: 0 | M57: 32 | N57: 0 | O57: =SUM(C57:L57,N57) -> 93 | P57: =SUM(C57:N57) -> 125
B58: Totals | C58: =SUM(C10:C57) -> 1504 | D58: =SUM(D10:D57) -> 691 | E58: =SUM(E10:E57) -> 362 | F58: =SUM(F10:F57) -> 519 | G58: =SUM(G10:G57) -> 21 | H58: =SUM(H10:H57) -> 3 | I58: =SUM(I10:I57) -> 300 | J58: =SUM(J10:J57) -> 87 | ... P58: =SUM(P10:P57) -> 5038
...

Sheet 24.09 Namugongo-Sonde
B1: Consultancy services for Preparation of Expressway Development Master Plan (EDMP) for Uganda
B2: MANUAL CLASSIFIED COUNT (MCC)
B3: ROAD NAME: | C3: MCC - C2 - STN073-SONDE ROAD
C5: Date | D5: 24.09.19 | F5: Location | G5: SONDE STATION | J5: Surveyor | K5: Amony Bella
C6: Dir. From | D6: NAMUGONGO | F6: Dir. To | G6: SSONDE | J6: Supervisor | K6: Tracy
B8: Time / Veh Type | R8: SUMMARY TRAFFIC VOLUMES
C9: 1. Car | D9: 2. Station Wagon | E9: 3. Pickups | F9: 4. Minibus, matatu | G9: 5. Medium bus | H9: 6. Large Bus | I9: 7. Light Truck | J9: 8. Medium Truck | K9: 9. Heavy truck | L9: 10. Truck Trailer | M9: 11. Motor cycles | N9: 12. Tractors | O9: Total Excl M/Cycles | P9: Total All | R9: Time | S9: 1. Car | T9: 2. Station Wagon | U9: 3. Pickups | V9: 4. Minibus, matatu | W9: 5. Medium bus | X9: 6. Large Bus | Y9: 7. Light Truck | Z9: 8. Medium Truck | AA9: 9. Heavy truck | AB9: 10. Truck Trailer | AC9: 11. Motorcycles | AD9: 12. Tractors, Graders | AE9: Total Excl M/ Cycles | AF9: Total All
B10: 07.00 - 07.15 | C10: 17 | D10: 4 | E10: 4 | F10: 3 | G10: 1 | H10: 0 | I10: 1 | J10: 2 | K10: 0 | L10: 0 | M10: 19 | N10: 0 | O10: =SUM(C10:L10,N10) -> 32 | P10: =SUM(C10:N10) -> 51 | R10: 0700-0800 | S10: =SUM(C10:C13) -> 87 | T10: =SUM(D10:D13) -> 61 | U10: =SUM(E10:E13) -> 31 | V10: =SUM(F10:F13) -> 24 | W10: =SUM(G10:G13) -> 1 | X10: =SUM(H10:H13) -> 0 | Y10: =SUM(I10:I13) -> 12 | Z10: =SUM(J10:J13) -> 7 | ... AF10: =SUM(P10:P13) -> 319
B11: 07.15 - 07.30 | C11: 27 | D11: 23 | E11: 14 | F11: 8 | G11: 0 | H11: 0 | I11: 4 | J11: 3 | K11: 0 | L11: 0 | M11: 28 | N11: 0 | O11: =SUM(C11:L11,N11) -> 79 | P11: =SUM(C11:N11) -> 107 | R11: 0800-0900 | S11: =SUM(C14:C17) -> 113 | T11: =SUM(D14:D17) -> 105 | U11: =SUM(E14:E17) -> 41 | V11: =SUM(F14:F17) -> 49 | W11: =SUM(G14:G17) -> 0 | X11: =SUM(H14:H17) -> 0 | Y11: =SUM(I14:I17) -> 26 | Z11: =SUM(J14:J17) -> 6 | ... AF11: =SUM(P14:P17) -> 468
B12: 07.30 - 07.45 | C12: 25 | D12: 17 | E12: 8 | F12: 9 | G12: 0 | H12: 0 | I12: 4 | J12: 0 | K12: 0 | L12: 0 | M12: 23 | N12: 0 | O12: =SUM(C12:L12,N12) -> 63 | P12: =SUM(C12:N12) -> 86 | R12: 0900-1000 | S12: =SUM(C18:C21) -> 74 | T12: =SUM(D18:D21) -> 75 | U12: =SUM(E18:E21) -> 22 | V12: =SUM(F18:F21) -> 53 | W12: =SUM(G18:G21) -> 0 | X12: =SUM(H18:H21) -> 2 | Y12: =SUM(I18:I21) -> 14 | Z12: =SUM(J18:J21) -> 16 | ... AF12: =SUM(P18:P21) -> 386
B13: 07.45 - 08.00 | C13: 18 | D13: 17 | E13: 5 | F13: 4 | G13: 0 | H13: 0 | I13: 3 | J13: 2 | K13: 0 | L13: 0 | M13: 26 | N13: 0 | O13: =SUM(C13:L13,N13) -> 49 | P13: =SUM(C13:N13) -> 75 | R13: 1000-1100 | S13: =SUM(C22:C25) -> 99 | T13: =SUM(D22:D25) -> 58 | U13: =SUM(E22:E25) -> 34 | V13: =SUM(F22:F25) -> 34 | W13: =SUM(G22:G25) -> 1 | X13: =SUM(H22:H25) -> 0 | Y13: =SUM(I22:I25) -> 29 | Z13: =SUM(J22:J25) -> 6 | ... AF13: =SUM(P22:P25) -> 409
B14: 08.00 - 08.15 | C14: 25 | D14: 27 | E14: 7 | F14: 8 | G14: 0 | H14: 0 | I14: 4 | J14: 0 | K14: 0 | L14: 0 | M14: 24 | N14: 0 | O14: =SUM(C14:L14,N14) -> 71 | P14: =SUM(C14:N14) -> 95 | R14: 1100-1200 | S14: =SUM(C26:C29) -> 79 | T14: =SUM(D26:D29) -> 64 | U14: =SUM(E26:E29) -> 19 | V14: =SUM(F26:F29) -> 40 | W14: =SUM(G26:G29) -> 3 | X14: =SUM(H26:H29) -> 0 | Y14: =SUM(I26:I29) -> 27 | Z14: =SUM(J26:J29) -> 14 | ... AF14: =SUM(P26:P29) -> 407
B15: 08.15 - 08.30 | C15: 24 | D15: 25 | E15: 15 | F15: 16 | G15: 0 | H15: 0 | I15: 7 | J15: 3 | K15: 0 | L15: 0 | M15: 30 | N15: 0 | O15: =SUM(C15:L15,N15) -> 90 | P15: =SUM(C15:N15) -> 120 | R15: 1200-1300 | S15: =SUM(C30:C33) -> 73 | T15: =SUM(D30:D33) -> 87 | U15: =SUM(E30:E33) -> 34 | V15: =SUM(F30:F33) -> 49 | W15: =SUM(G30:G33) -> 6 | X15: =SUM(H30:H33) -> 0 | Y15: =SUM(I30:I33) -> 41 | Z15: =SUM(J30:J33) -> 23 | ... AF15: =SUM(P30:P33) -> 440
B16: 08.30 - 08.45 | C16: 30 | D16: 30 | E16: 10 | F16: 12 | G16: 0 | H16: 0 | I16: 9 | J16: 2 | K16: 0 | L16: 1 | M16: 41 | N16: 0 | O16: =SUM(C16:L16,N16) -> 94 | P16: =SUM(C16:N16) -> 135 | R16: 1300-1400 | S16: =SUM(C34:C37) -> 74 | T16: =SUM(D34:D37) -> 75 | U16: =SUM(E34:E37) -> 26 | V16: =SUM(F34:F37) -> 39 | W16: =SUM(G34:G37) -> 2 | X16: =SUM(H34:H37) -> 1 | Y16: =SUM(I34:I37) -> 31 | Z16: =SUM(J34:J37) -> 18 | ... AF16: =SUM(P34:P37) -> 382
B17: 08.45 - 9.00 | C17: 34 | D17: 23 | E17: 9 | F17: 13 | G17: 0 | H17: 0 | I17: 6 | J17: 1 | K17: 0 | L17: 0 | M17: 32 | N17: 0 | O17: =SUM(C17:L17,N17) -> 86 | P17: =SUM(C17:N17) -> 118 | R17: 1400-1500 | S17: =SUM(C38:C41) -> 78 | T17: =SUM(D38:D41) -> 58 | U17: =SUM(E38:E41) -> 35 | V17: =SUM(F38:F41) -> 40 | W17: =SUM(G38:G41) -> 0 | X17: =SUM(H38:H41) -> 0 | Y17: =SUM(I38:I41) -> 31 | Z17: =SUM(J38:J41) -> 19 | ... AF17: =SUM(P38:P41) -> 380
B18: 09.00 - 09.15 | C18: 20 | D18: 21 | E18: 10 | F18: 11 | G18: 0 | H18: 0 | I18: 6 | J18: 2 | K18: 0 | L18: 0 | M18: 40 | N18: 0 | O18: =SUM(C18:L18,N18) -> 70 | P18: =SUM(C18:N18) -> 110 | R18: 1500-1600 | S18: =SUM(C42:C45) -> 109 | T18: =SUM(D42:D45) -> 82 | U18: =SUM(E42:E45) -> 29 | V18: =SUM(F42:F45) -> 55 | W18: =SUM(G42:G45) -> 0 | X18: =SUM(H42:H45) -> 1 | Y18: =SUM(I42:I45) -> 32 | Z18: =SUM(J42:J45) -> 26 | ... AF18: =SUM(P42:P45) -> 455
B19: 09.15 - 09.30 | C19: 32 | D19: 16 | E19: 5 | F19: 16 | G19: 0 | H19: 1 | I19: 3 | J19: 4 | K19: 0 | L19: 0 | M19: 25 | N19: 0 | O19: =SUM(C19:L19,N19) -> 77 | P19: =SUM(C19:N19) -> 102 | R19: 1600-1700 | S19: =SUM(C46:C49) -> 120 | T19: =SUM(D46:D49) -> 82 | U19: =SUM(E46:E49) -> 27 | V19: =SUM(F46:F49) -> 37 | W19: =SUM(G46:G49) -> 0 | X19: =SUM(H46:H49) -> 1 | Y19: =SUM(I46:I49) -> 27 | Z19: =SUM(J46:J49) -> 10 | ... AF19: =SUM(P46:P49) -> 414
B20: 09.30 - 09.45 | C20: 10 | D20: 16 | E20: 2 | F20: 11 | G20: 0 | H20: 1 | I20: 3 | J20: 6 | K20: 2 | L20: 0 | M20: 40 | N20: 0 | O20: =SUM(C20:L20,N20) -> 51 | P20: =SUM(C20:N20) -> 91 | R20: 1700-1800 | S20: =SUM(C50:C53) -> 164 | T20: =SUM(D50:D53) -> 116 | U20: =SUM(E50:E53) -> 34 | V20: =SUM(F50:F53) -> 39 | W20: =SUM(G50:G53) -> 11 | X20: =SUM(H50:H53) -> 1 | Y20: =SUM(I50:I53) -> 22 | Z20: =SUM(J50:J53) -> 11 | ... AF20: =SUM(P50:P53) -> 568
B21: 09.45 - 10.00 | C21: 12 | D21: 22 | E21: 5 | F21: 15 | G21: 0 | H21: 0 | I21: 2 | J21: 4 | K21: 0 | L21: 0 | M21: 23 | N21: 0 | O21: =SUM(C21:L21,N21) -> 60 | P21: =SUM(C21:N21) -> 83 | R21: 1800-1900 | S21: =SUM(C54:C57) -> 152 | T21: =SUM(D54:D57) -> 112 | U21: =SUM(E54:E57) -> 32 | V21: =SUM(F54:F57) -> 45 | W21: =SUM(G54:G57) -> 1 | X21: =SUM(H54:H57) -> 0 | Y21: =SUM(I54:I57) -> 16 | Z21: =SUM(J54:J57) -> 9 | ... AF21: =SUM(P54:P57) -> 536
B22: 10.00 - 10.15 | C22: 25 | D22: 17 | E22: 8 | F22: 10 | G22: 0 | H22: 0 | I22: 4 | J22: 0 | K22: 0 | L22: 0 | M22: 31 | N22: 0 | O22: =SUM(C22:L22,N22) -> 64 | P22: =SUM(C22:N22) -> 95 | R22: AM Peak Hr | S22: =MAX(S10:S12) -> 113 | T22: =MAX(T10:T12) -> 105 | U22: =MAX(U10:U12) -> 41 | V22: =MAX(V10:V12) -> 53 | W22: =MAX(W10:W12) -> 1 | X22: =MAX(X10:X12) -> 2 | Y22: =MAX(Y10:Y12) -> 26 | Z22: =MAX(Z10:Z12) -> 16 | ... AF22: =MAX(AF10:AF12) -> 468
B23: 10.15 - 10.30 | C23: 28 | D23: 10 | E23: 10 | F23: 9 | G23: 0 | H23: 0 | I23: 5 | J23: 0 | K23: 0 | L23: 0 | M23: 41 | N23: 0 | O23: =SUM(C23:L23,N23) -> 62 | P23: =SUM(C23:N23) -> 103 | R23: IP Peak Hr | S23: =MAX(S13:S18) -> 109 | T23: =MAX(T13:T18) -> 87 | U23: =MAX(U13:U18) -> 35 | V23: =MAX(V13:V18) -> 55 | W23: =MAX(W13:W18) -> 6 | X23: =MAX(X13:X18) -> 1 | Y23: =MAX(Y13:Y18) -> 41 | Z23: =MAX(Z13:Z18) -> 26 | ... AF23: =MAX(AF13:AF18) -> 455
B24: 10.30 - 10.45 | C24: 19 | D24: 18 | E24: 12 | F24: 7 | G24: 0 | H24: 0 | I24: 6 | J24: 0 | K24: 0 | L24: 0 | M24: 49 | N24: 0 | O24: =SUM(C24:L24,N24) -> 62 | P24: =SUM(C24:N24) -> 111 | R24: PM Peak Hr | S24: =MAX(S19:S21) -> 164 | T24: =MAX(T19:T21) -> 116 | U24: =MAX(U19:U21) -> 34 | V24: =MAX(V19:V21) -> 45 | W24: =MAX(W19:W21) -> 11 | X24: =MAX(X19:X21) -> 1 | Y24: =MAX(Y19:Y21) -> 27 | Z24: =MAX(Z19:Z21) -> 11 | ... AF24: =MAX(AF19:AF21) -> 568
B25: 10.45 - 11.00 | C25: 27 | D25: 13 | E25: 4 | F25: 8 | G25: 1 | H25: 0 | I25: 14 | J25: 6 | K25: 0 | L25: 1 | M25: 26 | N25: 0 | O25: =SUM(C25:L25,N25) -> 74 | P25: =SUM(C25:N25) -> 100 | R25: AM Period | S25: =SUM(S10:S12) -> 274 | T25: =SUM(T10:T12) -> 241 | U25: =SUM(U10:U12) -> 94 | V25: =SUM(V10:V12) -> 126 | W25: =SUM(W10:W12) -> 1 | X25: =SUM(X10:X12) -> 2 | Y25: =SUM(Y10:Y12) -> 52 | Z25: =SUM(Z10:Z12) -> 29 | ... AF25: =SUM(AF10:AF12) -> 1173
B26: 11.00 - 11.15 | C26: 15 | D26: 20 | E26: 5 | F26: 6 | G26: 1 | H26: 0 | I26: 6 | J26: 3 | K26: 0 | L26: 0 | M26: 45 | N26: 0 | O26: =SUM(C26:L26,N26) -> 56 | P26: =SUM(C26:N26) -> 101 | R26: IP Period | S26: =SUM(S13:S18) -> 512 | T26: =SUM(T13:T18) -> 424 | U26: =SUM(U13:U18) -> 177 | V26: =SUM(V13:V18) -> 257 | W26: =SUM(W13:W18) -> 12 | X26: =SUM(X13:X18) -> 2 | Y26: =SUM(Y13:Y18) -> 191 | Z26: =SUM(Z13:Z18) -> 106 | ... AF26: =SUM(AF13:AF18) -> 2473
B27: 11.15 - 11.30 | C27: 18 | D27: 12 | E27: 3 | F27: 10 | G27: 1 | H27: 0 | I27: 3 | J27: 4 | K27: 0 | L27: 0 | M27: 26 | N27: 0 | O27: =SUM(C27:L27,N27) -> 51 | P27: =SUM(C27:N27) -> 77 | R27: PM Period | S27: =SUM(S19:S21) -> 436 | T27: =SUM(T19:T21) -> 310 | U27: =SUM(U19:U21) -> 93 | V27: =SUM(V19:V21) -> 121 | W27: =SUM(W19:W21) -> 12 | X27: =SUM(X19:X21) -> 2 | Y27: =SUM(Y19:Y21) -> 65 | Z27: =SUM(Z19:Z21) -> 30 | ... AF27: =SUM(AF19:AF21) -> 1518
B28: 11.30 - 11.45 | C28: 20 | D28: 18 | E28: 6 | F28: 12 | G28: 1 | H28: 0 | I28: 5 | J28: 3 | K28: 0 | L28: 0 | M28: 42 | N28: 0 | O28: =SUM(C28:L28,N28) -> 65 | P28: =SUM(C28:N28) -> 107 | R28: 12 Hours | S28: =SUM(S10:S21) -> 1222 | T28: =SUM(T10:T21) -> 975 | U28: =SUM(U10:U21) -> 364 | V28: =SUM(V10:V21) -> 504 | W28: =SUM(W10:W21) -> 25 | X28: =SUM(X10:X21) -> 6 | Y28: =SUM(Y10:Y21) -> 308 | Z28: =SUM(Z10:Z21) -> 165 | ... AF28: =SUM(AF10:AF21) -> 5164
B29: 11.45 - 12.00 | C29: 26 | D29: 14 | E29: 5 | F29: 12 | G29: 0 | H29: 0 | I29: 13 | J29: 4 | K29: 0 | L29: 0 | M29: 48 | N29: 0 | O29: =SUM(C29:L29,N29) -> 74 | P29: =SUM(C29:N29) -> 122
B30: 12.00 - 12.15 | C30: 24 | D30: 6 | E30: 6 | F30: 11 | G30: 1 | H30: 0 | I30: 11 | J30: 11 | K30: 0 | L30: 1 | M30: 40 | N30: 0 | O30: =SUM(C30:L30,N30) -> 71 | P30: =SUM(C30:N30) -> 111
B31: 12.15 - 12.30 | C31: 18 | D31: 22 | E31: 11 | F31: 13 | G31: 0 | H31: 0 | I31: 8 | J31: 2 | K31: 0 | L31: 0 | M31: 29 | N31: 0 | O31: =SUM(C31:L31,N31) -> 74 | P31: =SUM(C31:N31) -> 103
B32: 12.30 - 12.45 | C32: 12 | D32: 27 | E32: 8 | F32: 11 | G32: 3 | H32: 0 | I32: 11 | J32: 6 | K32: 0 | L32: 2 | M32: 20 | N32: 0 | O32: =SUM(C32:L32,N32) -> 80 | P32: =SUM(C32:N32) -> 100
B33: 12.45 - 13.00 | C33: 19 | D33: 32 | E33: 9 | F33: 14 | G33: 2 | H33: 0 | I33: 11 | J33: 4 | K33: 1 | L33: 1 | M33: 33 | N33: 0 | O33: =SUM(C33:L33,N33) -> 93 | P33: =SUM(C33:N33) -> 126
B34: 13.00 - 13.15 | C34: 20 | D34: 18 | E34: 4 | F34: 10 | G34: 0 | H34: 0 | I34: 6 | J34: 3 | K34: 0 | L34: 0 | M34: 28 | N34: 0 | O34: =SUM(C34:L34,N34) -> 61 | P34: =SUM(C34:N34) -> 89
B35: 13.15 - 13.30 | C35: 18 | D35: 18 | E35: 9 | F35: 10 | G35: 0 | H35: 1 | I35: 5 | J35: 6 | K35: 0 | L35: 0 | M35: 32 | N35: 0 | O35: =SUM(C35:L35,N35) -> 67 | P35: =SUM(C35:N35) -> 99
B36: 13.30 - 13.45 | C36: 20 | D36: 23 | E36: 6 | F36: 8 | G36: 2 | H36: 0 | I36: 14 | J36: 5 | K36: 0 | L36: 0 | M36: 32 | N36: 0 | O36: =SUM(C36:L36,N36) -> 78 | P36: =SUM(C36:N36) -> 110
B37: 13.45 - 14.00 | C37: 16 | D37: 16 | E37: 7 | F37: 11 | G37: 0 | H37: 0 | I37: 6 | J37: 4 | K37: 0 | L37: 0 | M37: 23 | N37: 1 | O37: =SUM(C37:L37,N37) -> 61 | P37: =SUM(C37:N37) -> 84
B38: 14.00 - 14.15 | C38: 12 | D38: 13 | E38: 12 | F38: 8 | G38: 0 | H38: 0 | I38: 7 | J38: 5 | K38: 0 | L38: 0 | M38: 29 | N38: 0 | O38: =SUM(C38:L38,N38) -> 57 | P38: =SUM(C38:N38) -> 86
B39: 14.15 - 14.30 | C39: 26 | D39: 18 | E39: 9 | F39: 13 | G39: 0 | H39: 0 | I39: 9 | J39: 2 | K39: 0 | L39: 1 | M39: 25 | N39: 0 | O39: =SUM(C39:L39,N39) -> 78 | P39: =SUM(C39:N39) -> 103
B40: 14.30 - 14.45 | C40: 13 | D40: 14 | E40: 6 | F40: 12 | G40: 0 | H40: 0 | I40: 7 | J40: 6 | K40: 0 | L40: 0 | M40: 34 | N40: 0 | O40: =SUM(C40:L40,N40) -> 58 | P40: =SUM(C40:N40) -> 92
... B57: 18.45 - 19.00 | C57: 40 | D57: 25 | E57: 4 | F57: 10 | G57: 0 | H57: 0 | I57: 2 | J57: 2 | K57: 0 | L57: 0 | M57: 41 | N57: 0 | O57: =SUM(C57:L57,N57) -> 83 | P57: =SUM(C57:N57) -> 124
B58: Totals | C58: =SUM(C10:C57) -> 1222 | D58: =SUM(D10:D57) -> 975 | E58: =SUM(E10:E57) -> 364 | F58: =SUM(F10:F57) -> 504 | G58: =SUM(G10:G57) -> 25 | H58: =SUM(H10:H57) -> 6 | I58: =SUM(I10:I57) -> 308 | J58: =SUM(J10:J57) -> 165 | ... P58: =SUM(P10:P57) -> 5164
...

Sheet 25.09 Sonde-Namugongo
B1: Consultancy services for Preparation of Expressway Development Master Plan (EDMP) for Uganda
B2: MANUAL CLASSIFIED COUNT (MCC)
B3: ROAD NAME: | C3: ='23.09 Sonde-Namugongo'!C3:G3 -> MCC-C2-STNO 73
C5: Date | D5: 25.09.19 | F5: Location | G5: ='23.09 Sonde-Namugongo'!G5:H5 -> Bukasa | J5: Surveyor | K5: ='23.09 Sonde-Namugongo'!K5:L5 -> Kalebo Mark
C6: Dir. From | D6: ='23.09 Sonde-Namugongo'!D6:E6 -> SSONDE | F6: Dir. To | G6: ='23.09 Sonde-Namugongo'!G6:H6 -> NAMUGONGO | J6: Supervisor | K6: ='23.09 Sonde-Namugongo'!K6:L6 -> Tracy
B8: Time / Veh Type | R8: SUMMARY TRAFFIC VOLUMES
C9: 1. Car | D9: 2. Station Wagon | E9: 3. Pickups | F9: 4. Minibus, matatu | G9: 5. Medium bus | H9: 6. Large Bus | I9: 7. Light Truck | J9: 8. Medium Truck | K9: 9. Heavy truck | L9: 10. Truck Trailer | M9: 11. Motor cycles | N9: 12. Tractors | O9: Total Excl M/Cycles | P9: Total All | R9: Time | S9: 1. Car | T9: 2. Station Wagon | U9: 3. Pickups | V9: 4. Minibus, matatu | W9: 5. Medium bus | X9: 6. Large Bus | Y9: 7. Light Truck | Z9: 8. Medium Truck | AA9: 9. Heavy truck | AB9: 10. Truck Trailer | AC9: 11. Motorcycles | AD9: 12. Tractors, Graders | AE9: Total Excl M/ Cycles | AF9: Total All
B10: 07.00 - 07.15 | C10: 35 | D10: 14 | E10: 0 | F10: 10 | G10: 0 | H10: 0 | I10: 2 | J10: 0 | K10: 0 | L10: 1 | M10: 33 | N10: 0 | O10: =SUM(C10:L10,N10) -> 62 | P10: =SUM(C10:N10) -> 95 | R10: 0700-0800 | S10: =SUM(C10:C13) -> 167 | T10: =SUM(D10:D13) -> 73 | U10: =SUM(E10:E13) -> 18 | V10: =SUM(F10:F13) -> 49 | W10: =SUM(G10:G13) -> 0 | X10: =SUM(H10:H13) -> 0 | Y10: =SUM(I10:I13) -> 15 | Z10: =SUM(J10:J13) -> 3 | ... AF10: =SUM(P10:P13) -> 509
B11: 07.15 - 07.30 | C11: 54 | D11: 18 | E11: 8 | F11: 12 | G11: 0 | H11: 0 | I11: 1 | J11: 0 | K11: 0 | L11: 0 | M11: 53 | N11: 0 | O11: =SUM(C11:L11,N11) -> 93 | P11: =SUM(C11:N11) -> 146 | R11: 0800-0900 | S11: =SUM(C14:C17) -> 156 | T11: =SUM(D14:D17) -> 72 | U11: =SUM(E14:E17) -> 18 | V11: =SUM(F14:F17) -> 45 | W11: =SUM(G14:G17) -> 0 | X11: =SUM(H14:H17) -> 0 | Y11: =SUM(I14:I17) -> 23 | Z11: =SUM(J14:J17) -> 12 | ... AF11: =SUM(P14:P17) -> 536
B12: 07.30 - 07.45 | C12: 42 | D12: 24 | E12: 5 | F12: 17 | G12: 0 | H12: 0 | I12: 3 | J12: 2 | K12: 0 | L12: 0 | M12: 61 | N12: 0 | O12: =SUM(C12:L12,N12) -> 93 | P12: =SUM(C12:N12) -> 154 | R12: 0900-1000 | S12: =SUM(C18:C21) -> 136 | T12: =SUM(D18:D21) -> 57 | U12: =SUM(E18:E21) -> 25 | V12: =SUM(F18:F21) -> 43 | W12: =SUM(G18:G21) -> 1 | X12: =SUM(H18:H21) -> 0 | Y12: =SUM(I18:I21) -> 18 | Z12: =SUM(J18:J21) -> 11 | ... AF12: =SUM(P18:P21) -> 420
B13: 07.45 - 08.00 | C13: 36 | D13: 17 | E13: 5 | F13: 10 | G13: 0 | H13: 0 | I13: 9 | J13: 1 | K13: 1 | L13: 1 | M13: 34 | N13: 0 | O13: =SUM(C13:L13,N13) -> 80 | P13: =SUM(C13:N13) -> 114 | R13: 1000-1100 | S13: =SUM(C22:C25) -> 120 | T13: =SUM(D22:D25) -> 49 | U13: =SUM(E22:E25) -> 26 | V13: =SUM(F22:F25) -> 34 | W13: =SUM(G22:G25) -> 0 | X13: =SUM(H22:H25) -> 0 | Y13: =SUM(I22:I25) -> 31 | Z13: =SUM(J22:J25) -> 4 | ... AF13: =SUM(P22:P25) -> 378
B14: 08.00 - 08.15 | C14: 43 | D14: 17 | E14: 4 | F14: 12 | G14: 0 | H14: 0 | I14: 4 | J14: 8 | K14: 1 | L14: 1 | M14: 52 | N14: 0 | O14: =SUM(C14:L14,N14) -> 90 | P14: =SUM(C14:N14) -> 142 | R14: 1100-1200 | S14: =SUM(C26:C29) -> 96 | T14: =SUM(D26:D29) -> 44 | U14: =SUM(E26:E29) -> 18 | V14: =SUM(F26:F29) -> 26 | W14: =SUM(G26:G29) -> 0 | X14: =SUM(H26:H29) -> 0 | Y14: =SUM(I26:I29) -> 25 | Z14: =SUM(J26:J29) -> 8 | ... AF14: =SUM(P26:P29) -> 329
B15: 08.15 - 08.30 | C15: 46 | D15: 14 | E15: 5 | F15: 12 | G15: 0 | H15: 0 | I15: 6 | J15: 1 | K15: 1 | L15: 1 | M15: 57 | N15: 0 | O15: =SUM(C15:L15,N15) -> 86 | P15: =SUM(C15:N15) -> 143 | R15: 1200-1300 | S15: =SUM(C30:C33) -> 124 | T15: =SUM(D30:D33) -> 46 | U15: =SUM(E30:E33) -> 38 | V15: =SUM(F30:F33) -> 27 | W15: =SUM(G30:G33) -> 0 | X15: =SUM(H30:H33) -> 0 | Y15: =SUM(I30:I33) -> 23 | Z15: =SUM(J30:J33) -> 7 | ... AF15: =SUM(P30:P33) -> 345
B16: 08.30 - 08.45 | C16: 35 | D16: 24 | E16: 4 | F16: 12 | G16: 0 | H16: 0 | I16: 12 | J16: 2 | K16: 2 | L16: 0 | M16: 38 | N16: 0 | O16: =SUM(C16:L16,N16) -> 91 | P16: =SUM(C16:N16) -> 129 | R16: 1300-1400 | S16: =SUM(C34:C37) -> 103 | T16: =SUM(D34:D37) -> 41 | U16: =SUM(E34:E37) -> 20 | V16: =SUM(F34:F37) -> 31 | W16: =SUM(G34:G37) -> 1 | X16: =SUM(H34:H37) -> 13 | Y16: =SUM(I34:I37) -> 15 | Z16: =SUM(J34:J37) -> 10 | ... AF16: =SUM(P34:P37) -> 316
B17: 08.45 - 9.00 | C17: 32 | D17: 17 | E17: 5 | F17: 9 | G17: 0 | H17: 0 | I17: 1 | J17: 1 | K17: 0 | L17: 0 | M17: 57 | N17: 0 | O17: =SUM(C17:L17,N17) -> 65 | P17: =SUM(C17:N17) -> 122 | R17: 1400-1500 | S17: =SUM(C38:C41) -> 103 | T17: =SUM(D38:D41) -> 51 | U17: =SUM(E38:E41) -> 24 | V17: =SUM(F38:F41) -> 36 | W17: =SUM(G38:G41) -> 0 | X17: =SUM(H38:H41) -> 0 | Y17: =SUM(I38:I41) -> 15 | Z17: =SUM(J38:J41) -> 6 | ... AF17: =SUM(P38:P41) -> 326
B18: 09.00 - 09.15 | C18: 55 | D18: 21 | E18: 6 | F18: 12 | G18: 0 | H18: 0 | I18: 3 | J18: 1 | K18: 5 | L18: 0 | M18: 28 | N18: 0 | O18: =SUM(C18:L18,N18) -> 103 | P18: =SUM(C18:N18) -> 131 | R18: 1500-1600 | S18: =SUM(C42:C45) -> 132 | T18: =SUM(D42:D45) -> 57 | U18: =SUM(E42:E45) -> 18 | V18: =SUM(F42:F45) -> 47 | W18: =SUM(G42:G45) -> 0 | X18: =SUM(H42:H45) -> 0 | Y18: =SUM(I42:I45) -> 27 | Z18: =SUM(J42:J45) -> 4 | ... AF18: =SUM(P42:P45) -> 396
B19: 09.15 - 09.30 | C19: 34 | D19: 12 | E19: 11 | F19: 11 | G19: 1 | H19: 0 | I19: 5 | J19: 5 | K19: 1 | L19: 1 | M19: 31 | N19: 0 | O19: =SUM(C19:L19,N19) -> 81 | P19: =SUM(C19:N19) -> 112 | R19: 1600-1700 | S19: =SUM(C46:C49) -> 159 | T19: =SUM(D46:D49) -> 69 | U19: =SUM(E46:E49) -> 31 | V19: =SUM(F46:F49) -> 38 | W19: =SUM(G46:G49) -> 1 | X19: =SUM(H46:H49) -> 0 | Y19: =SUM(I46:I49) -> 21 | Z19: =SUM(J46:J49) -> 17 | ... AF19: =SUM(P46:P49) -> 459
B20: 09.30 - 09.45 | C20: 25 | D20: 9 | E20: 4 | F20: 12 | G20: 0 | H20: 0 | I20: 5 | J20: 1 | K20: 1 | L20: 0 | M20: 27 | N20: 0 | O20: =SUM(C20:L20,N20) -> 57 | P20: =SUM(C20:N20) -> 84 | R20: 1700-1800 | S20: =SUM(C50:C53) -> 149 | T20: =SUM(D50:D53) -> 66 | U20: =SUM(E50:E53) -> 27 | V20: =SUM(F50:F53) -> 35 | W20: =SUM(G50:G53) -> 4 | X20: =SUM(H50:H53) -> 12 | Y20: =SUM(I50:I53) -> 33 | Z20: =SUM(J50:J53) -> 7 | ... AF20: =SUM(P50:P53) -> 451
B21: 09.45 - 10.00 | C21: 22 | D21: 15 | E21: 4 | F21: 8 | G21: 0 | H21: 0 | I21: 5 | J21: 4 | K21: 0 | L21: 0 | M21: 35 | N21: 0 | O21: =SUM(C21:L21,N21) -> 58 | P21: =SUM(C21:N21) -> 93 | R21: 1800-1900 | S21: =SUM(C54:C57) -> 98 | T21: =SUM(D54:D57) -> 46 | U21: =SUM(E54:E57) -> 35 | V21: =SUM(F54:F57) -> 29 | W21: =SUM(G54:G57) -> 1 | X21: =SUM(H54:H57) -> 9 | Y21: =SUM(I54:I57) -> 15 | Z21: =SUM(J54:J57) -> 16 | ... AF21: =SUM(P54:P57) -> 383
B22: 10.00 - 10.15 | C22: 23 | D22: 14 | E22: 6 | F22: 8 | G22: 0 | H22: 0 | I22: 11 | J22: 1 | K22: 1 | L22: 0 | M22: 27 | N22: 0 | O22: =SUM(C22:L22,N22) -> 64 | P22: =SUM(C22:N22) -> 91 | R22: AM Peak Hr | S22: =MAX(S10:S12) -> 167 | T22: =MAX(T10:T12) -> 73 | U22: =MAX(U10:U12) -> 25 | V22: =MAX(V10:V12) -> 49 | W22: =MAX(W10:W12) -> 1 | X22: =MAX(X10:X12) -> 0 | Y22: =MAX(Y10:Y12) -> 23 | Z22: =MAX(Z10:Z12) -> 12 | ... AF22: =MAX(AF10:AF12) -> 536
B23: 10.15 - 10.30 | C23: 31 | D23: 10 | E23: 9 | F23: 9 | G23: 0 | H23: 0 | I23: 5 | J23: 1 | K23: 0 | L23: 0 | M23: 31 | N23: 0 | O23: =SUM(C23:L23,N23) -> 65 | P23: =SUM(C23:N23) -> 96 | R23: IP Peak Hr | S23: =MAX(S13:S18) -> 132 | T23: =MAX(T13:T18) -> 57 | U23: =MAX(U13:U18) -> 38 | V23: =MAX(V13:V18) -> 47 | W23: =MAX(W13:W18) -> 1 | X23: =MAX(X13:X18) -> 13 | Y23: =MAX(Y13:Y18) -> 31 | Z23: =MAX(Z13:Z18) -> 10 | ... AF23: =MAX(AF13:AF18) -> 396
B24: 10.30 - 10.45 | C24: 39 | D24: 12 | E24: 6 | F24: 7 | G24: 0 | H24: 0 | I24: 5 | J24: 0 | K24: 0 | L24: 0 | M24: 35 | N24: 0 | O24: =SUM(C24:L24,N24) -> 69 | P24: =SUM(C24:N24) -> 104 | R24: PM Peak Hr | S24: =MAX(S19:S21) -> 159 | T24: =MAX(T19:T21) -> 69 | U24: =MAX(U19:U21) -> 35 | V24: =MAX(V19:V21) -> 38 | W24: =MAX(W19:W21) -> 4 | X24: =MAX(X19:X21) -> 12 | Y24: =MAX(Y19:Y21) -> 33 | Z24: =MAX(Z19:Z21) -> 17 | ... AF24: =MAX(AF19:AF21) -> 459
B25: 10.45 - 11.00 | C25: 27 | D25: 13 | E25: 5 | F25: 10 | G25: 0 | H25: 0 | I25: 10 | J25: 2 | K25: 0 | L25: 0 | M25: 20 | N25: 0 | O25: =SUM(C25:L25,N25) -> 67 | P25: =SUM(C25:N25) -> 87 | R25: AM Period | S25: =SUM(S10:S12) -> 459 | T25: =SUM(T10:T12) -> 202 | U25: =SUM(U10:U12) -> 61 | V25: =SUM(V10:V12) -> 137 | W25: =SUM(W10:W12) -> 1 | X25: =SUM(X10:X12) -> 0 | Y25: =SUM(Y10:Y12) -> 56 | Z25: =SUM(Z10:Z12) -> 26 | ... AF25: =SUM(AF10:AF12) -> 1465
B26: 11.00 - 11.15 | C26: 20 | D26: 12 | E26: 4 | F26: 6 | G26: 0 | H26: 0 | I26: 4 | J26: 2 | K26: 1 | L26: 0 | M26: 27 | N26: 0 | O26: =SUM(C26:L26,N26) -> 49 | P26: =SUM(C26:N26) -> 76 | R26: IP Period | S26: =SUM(S13:S18) -> 678 | T26: =SUM(T13:T18) -> 288 | U26: =SUM(U13:U18) -> 144 | V26: =SUM(V13:V18) -> 201 | W26: =SUM(W13:W18) -> 1 | X26: =SUM(X13:X18) -> 13 | Y26: =SUM(Y13:Y18) -> 136 | Z26: =SUM(Z13:Z18) -> 39 | ... AF26: =SUM(AF13:AF18) -> 2090
B27: 11.15 - 11.30 | C27: 32 | D27: 13 | E27: 4 | F27: 10 | G27: 0 | H27: 0 | I27: 5 | J27: 4 | K27: 2 | L27: 0 | M27: 28 | N27: 0 | O27: =SUM(C27:L27,N27) -> 70 | P27: =SUM(C27:N27) -> 98 | R27: PM Period | S27: =SUM(S19:S21) -> 406 | T27: =SUM(T19:T21) -> 181 | U27: =SUM(U19:U21) -> 93 | V27: =SUM(V19:V21) -> 102 | W27: =SUM(W19:W21) -> 6 | X27: =SUM(X19:X21) -> 21 | Y27: =SUM(Y19:Y21) -> 69 | Z27: =SUM(Z19:Z21) -> 40 | ... AF27: =SUM(AF19:AF21) -> 1293
B28: 11.30 - 11.45 | C28: 22 | D28: 6 | E28: 5 | F28: 10 | G28: 0 | H28: 0 | I28: 8 | J28: 0 | K28: 0 | L28: 0 | M28: 17 | N28: 0 | O28: =SUM(C28:L28,N28) -> 51 | P28: =SUM(C28:N28) -> 68 | R28: 12 Hours | S28: =SUM(S10:S21) -> 1543 | T28: =SUM(T10:T21) -> 671 | U28: =SUM(U10:U21) -> 298 | V28: =SUM(V10:V21) -> 440 | W28: =SUM(W10:W21) -> 8 | X28: =SUM(X10:X21) -> 34 | Y28: =SUM(Y10:Y21) -> 261 | Z28: =SUM(Z10:Z21) -> 105 | ... AF28: =SUM(AF10:AF21) -> 4848
