Workbook

Sheet 27.10 Mbarara-Kabale
B1: Consultancy services for Preparation of Expressway Development Master Plan (EDMP) for Uganda
B2: MANUAL CLASSIFIED COUNT (MCC)
B3: ROAD NAME: | C3: MCC - C4 - STN100 - MBARARA-NTUNGAMO ROAD
C5: Date | D5: 27.10.19 | F5: Location | G5: Nyeihanga traffic station | J5: Surveyor | K5: Norman
C6: Dir. From | D6: Mbarara | F6: Dir. To | G6: Kabale | J6: Supervisor | K6: Norman R
B8: Time / Veh Type | R8: SUMMARY TRAFFIC VOLUMES
C9: 1. Car | D9: 2. Station Wagon | E9: 3. Pickups | F9: 4. Minibus, matatu | G9: 5. Medium bus | H9: 6. Large Bus | I9: 7. Light Truck | J9: 8. Medium Truck | K9: 9. Heavy truck | L9: 10. Truck Trailer | M9: 11. Motor cycles | N9: 12. Tractors | O9: Total Excl M/Cycles | P9: Total All | R9: Time | S9: 1. Car | T9: 2. Station Wagon | U9: 3. Pickups | V9: 4. Minibus, matatu | W9: 5. Medium bus | X9: 6. Large Bus | Y9: 7. Light Truck | Z9: 8. Medium Truck | AA9: 9. Heavy truck | AB9: 10. Truck Trailer | AC9: 11. Motorcycles | AD9: 12. Tractors, Graders | AE9: Total Excl M/ Cycles | AF9: Total All
B10: 07.00 - 07.15 | C10: 4 | D10: 2 | E10: 0 | F10: 5 | G10: 0 | H10: 0 | I10: 0 | J10: 0 | K10: 7 | L10: 0 | M10: 11 | N10: 0 | O10: =SUM(C10:L10,N10) -> 18 | P10: =SUM(C10:N10) -> 29 | R10: 0700-0800 | S10: =SUM(C10:C13) -> 34 | T10: =SUM(D10:D13) -> 36 | U10: =SUM(E10:E13) -> 17 | V10: =SUM(F10:F13) -> 39 | W10: =SUM(G10:G13) -> 0 | X10: =SUM(H10:H13) -> 0 | Y10: =SUM(I10:I13) -> 3 | Z10: =SUM(J10:J13) -> 14 | ... AF10: =SUM(P10:P13) -> 257
B11: 07.15 - 07.30 | C11: 8 | D11: 4 | E11: 1 | F11: 11 | G11: 0 | H11: 0 | I11: 3 | J11: 0 | K11: 2 | L11: 6 | M11: 7 | N11: 0 | O11: =SUM(C11:L11,N11) -> 35 | P11: =SUM(C11:N11) -> 42 | R11: 0800-0900 | S11: =SUM(C14:C17) -> 30 | T11: =SUM(D14:D17) -> 8 | U11: =SUM(E14:E17) -> 6 | V11: =SUM(F14:F17) -> 12 | W11: =SUM(G14:G17) -> 0 | X11: =SUM(H14:H17) -> 0 | Y11: =SUM(I14:I17) -> 1 | Z11: =SUM(J14:J17) -> 7 | ... AF11: =SUM(P14:P17) -> 115
B12: 07.30 - 07.45 | C12: 17 | D12: 21 | E12: 13 | F12: 16 | G12: 0 | H12: 0 | I12: 0 | J12: 4 | K12: 14 | L12: 9 | M12: 24 | N12: 0 | O12: =SUM(C12:L12,N12) -> 94 | P12: =SUM(C12:N12) -> 118 | R12: 0900-1000 | S12: =SUM(C18:C21) -> 24 | T12: =SUM(D18:D21) -> 3 | U12: =SUM(E18:E21) -> 2 | V12: =SUM(F18:F21) -> 19 | W12: =SUM(G18:G21) -> 0 | X12: =SUM(H18:H21) -> 0 | Y12: =SUM(I18:I21) -> 2 | Z12: =SUM(J18:J21) -> 3 | ... AF12: =SUM(P18:P21) -> 114
B13: 07.45 - 08.00 | C13: 5 | D13: 9 | E13: 3 | F13: 7 | G13: 0 | H13: 0 | I13: 0 | J13: 10 | K13: 22 | L13: 4 | M13: 8 | N13: 0 | O13: =SUM(C13:L13,N13) -> 60 | P13: =SUM(C13:N13) -> 68 | R13: 1000-1100 | S13: =SUM(C22:C25) -> 43 | T13: =SUM(D22:D25) -> 4 | U13: =SUM(E22:E25) -> 2 | V13: =SUM(F22:F25) -> 17 | W13: =SUM(G22:G25) -> 0 | X13: =SUM(H22:H25) -> 1 | Y13: =SUM(I22:I25) -> 6 | Z13: =SUM(J22:J25) -> 4 | ... AF13: =SUM(P22:P25) -> 159
B14: 08.00 - 08.15 | C14: 4 | D14: 0 | E14: 1 | F14: 2 | G14: 0 | H14: 0 | I14: 1 | J14: 1 | K14: 1 | L14: 4 | M14: 7 | N14: 0 | O14: =SUM(C14:L14,N14) -> 14 | P14: =SUM(C14:N14) -> 21 | R14: 1100-1200 | S14: =SUM(C26:C29) -> 51 | T14: =SUM(D26:D29) -> 12 | U14: =SUM(E26:E29) -> 6 | V14: =SUM(F26:F29) -> 19 | W14: =SUM(G26:G29) -> 0 | X14: =SUM(H26:H29) -> 2 | Y14: =SUM(I26:I29) -> 5 | Z14: =SUM(J26:J29) -> 13 | ... AF14: =SUM(P26:P29) -> 173
B15: 08.15 - 08.30 | C15: 6 | D15: 1 | E15: 4 | F15: 9 | G15: 0 | H15: 0 | I15: 0 | J15: 4 | K15: 5 | L15: 6 | M15: 9 | N15: 0 | O15: =SUM(C15:L15,N15) -> 35 | P15: =SUM(C15:N15) -> 44 | R15: 1200-1300 | S15: =SUM(C30:C33) -> 24 | T15: =SUM(D30:D33) -> 7 | U15: =SUM(E30:E33) -> 6 | V15: =SUM(F30:F33) -> 36 | W15: =SUM(G30:G33) -> 0 | X15: =SUM(H30:H33) -> 1 | Y15: =SUM(I30:I33) -> 8 | Z15: =SUM(J30:J33) -> 1 | ... AF15: =SUM(P30:P33) -> 158
B16: 08.30 - 08.45 | C16: 15 | D16: 4 | E16: 0 | F16: 0 | G16: 0 | H16: 0 | I16: 0 | J16: 0 | K16: 0 | L16: 0 | M16: 5 | N16: 0 | O16: =SUM(C16:L16,N16) -> 19 | P16: =SUM(C16:N16) -> 24 | R16: 1300-1400 | S16: =SUM(C34:C37) -> 38 | T16: =SUM(D34:D37) -> 12 | U16: =SUM(E34:E37) -> 2 | V16: =SUM(F34:F37) -> 36 | W16: =SUM(G34:G37) -> 1 | X16: =SUM(H34:H37) -> 3 | Y16: =SUM(I34:I37) -> 4 | Z16: =SUM(J34:J37) -> 3 | ... AF16: =SUM(P34:P37) -> 162
B17: 08.45 - 9.00 | C17: 5 | D17: 3 | E17: 1 | F17: 1 | G17: 0 | H17: 0 | I17: 0 | J17: 2 | K17: 1 | L17: 2 | M17: 11 | N17: 0 | O17: =SUM(C17:L17,N17) -> 15 | P17: =SUM(C17:N17) -> 26 | R17: 1400-1500 | S17: =SUM(C38:C41) -> 43 | T17: =SUM(D38:D41) -> 0 | U17: =SUM(E38:E41) -> 8 | V17: =SUM(F38:F41) -> 39 | W17: =SUM(G38:G41) -> 0 | X17: =SUM(H38:H41) -> 0 | Y17: =SUM(I38:I41) -> 2 | Z17: =SUM(J38:J41) -> 4 | ... AF17: =SUM(P38:P41) -> 159
B18: 09.00 - 09.15 | C18: 3 | D18: 2 | E18: 1 | F18: 5 | G18: 0 | H18: 0 | I18: 0 | J18: 0 | K18: 2 | L18: 0 | M18: 10 | N18: 0 | O18: =SUM(C18:L18,N18) -> 13 | P18: =SUM(C18:N18) -> 23 | R18: 1500-1600 | S18: =SUM(C42:C45) -> 33 | T18: =SUM(D42:D45) -> 28 | U18: =SUM(E42:E45) -> 27 | V18: =SUM(F42:F45) -> 29 | W18: =SUM(G42:G45) -> 4 | X18: =SUM(H42:H45) -> 5 | Y18: =SUM(I42:I45) -> 11 | Z18: =SUM(J42:J45) -> 21 | ... AF18: =SUM(P42:P45) -> 275
B19: 09.15 - 09.30 | C19: 11 | D19: 0 | E19: 0 | F19: 7 | G19: 0 | H19: 0 | I19: 0 | J19: 0 | K19: 1 | L19: 0 | M19: 17 | N19: 0 | O19: =SUM(C19:L19,N19) -> 19 | P19: =SUM(C19:N19) -> 36 | R19: 1600-1700 | S19: =SUM(C46:C49) -> 26 | T19: =SUM(D46:D49) -> 16 | U19: =SUM(E46:E49) -> 4 | V19: =SUM(F46:F49) -> 14 | W19: =SUM(G46:G49) -> 0 | X19: =SUM(H46:H49) -> 6 | Y19: =SUM(I46:I49) -> 1 | Z19: =SUM(J46:J49) -> 14 | ... AF19: =SUM(P46:P49) -> 192
B20: 09.30 - 09.45 | C20: 7 | D20: 0 | E20: 1 | F20: 4 | G20: 0 | H20: 0 | I20: 2 | J20: 2 | K20: 2 | L20: 7 | M20: 3 | N20: 0 | O20: =SUM(C20:L20,N20) -> 25 | P20: =SUM(C20:N20) -> 28 | R20: 1700-1800 | S20: =SUM(C50:C53) -> 25 | T20: =SUM(D50:D53) -> 22 | U20: =SUM(E50:E53) -> 24 | V20: =SUM(F50:F53) -> 26 | W20: =SUM(G50:G53) -> 4 | X20: =SUM(H50:H53) -> 0 | Y20: =SUM(I50:I53) -> 2 | Z20: =SUM(J50:J53) -> 7 | ... AF20: =SUM(P50:P53) -> 240
B21: 09.45 - 10.00 | C21: 3 | D21: 1 | E21: 0 | F21: 3 | G21: 0 | H21: 0 | I21: 0 | J21: 1 | K21: 6 | L21: 0 | M21: 13 | N21: 0 | O21: =SUM(C21:L21,N21) -> 14 | P21: =SUM(C21:N21) -> 27 | R21: 1800-1900 | S21: =SUM(C54:C57) -> 17 | T21: =SUM(D54:D57) -> 13 | U21: =SUM(E54:E57) -> 16 | V21: =SUM(F54:F57) -> 7 | W21: =SUM(G54:G57) -> 3 | X21: =SUM(H54:H57) -> 6 | Y21: =SUM(I54:I57) -> 3 | Z21: =SUM(J54:J57) -> 10 | ... AF21: =SUM(P54:P57) -> 162
B22: 10.00 - 10.15 | C22: 4 | D22: 3 | E22: 1 | F22: 5 | G22: 0 | H22: 0 | I22: 2 | J22: 0 | K22: 0 | L22: 3 | M22: 13 | N22: 0 | O22: =SUM(C22:L22,N22) -> 18 | P22: =SUM(C22:N22) -> 31 | R22: AM Peak Hr | S22: =MAX(S10:S12) -> 34 | T22: =MAX(T10:T12) -> 36 | U22: =MAX(U10:U12) -> 17 | V22: =MAX(V10:V12) -> 39 | W22: =MAX(W10:W12) -> 0 | X22: =MAX(X10:X12) -> 0 | Y22: =MAX(Y10:Y12) -> 3 | Z22: =MAX(Z10:Z12) -> 14 | ... AF22: =MAX(AF10:AF12) -> 257
B23: 10.15 - 10.30 | C23: 6 | D23: 0 | E23: 1 | F23: 0 | G23: 0 | H23: 0 | I23: 1 | J23: 0 | K23: 0 | L23: 2 | M23: 15 | N23: 0 | O23: =SUM(C23:L23,N23) -> 10 | P23: =SUM(C23:N23) -> 25 | R23: IP Peak Hr | S23: =MAX(S13:S18) -> 51 | T23: =MAX(T13:T18) -> 28 | U23: =MAX(U13:U18) -> 27 | V23: =MAX(V13:V18) -> 39 | W23: =MAX(W13:W18) -> 4 | X23: =MAX(X13:X18) -> 5 | Y23: =MAX(Y13:Y18) -> 11 | Z23: =MAX(Z13:Z18) -> 21 | ... AF23: =MAX(AF13:AF18) -> 275
B24: 10.30 - 10.45 | C24: 12 | D24: 0 | E24: 0 | F24: 2 | G24: 0 | H24: 1 | I24: 0 | J24: 4 | K24: 0 | L24: 0 | M24: 23 | N24: 0 | O24: =SUM(C24:L24,N24) -> 19 | P24: =SUM(C24:N24) -> 42 | R24: PM Peak Hr | S24: =MAX(S19:S21) -> 26 | T24: =MAX(T19:T21) -> 22 | U24: =MAX(U19:U21) -> 24 | V24: =MAX(V19:V21) -> 26 | W24: =MAX(W19:W21) -> 4 | X24: =MAX(X19:X21) -> 6 | Y24: =MAX(Y19:Y21) -> 3 | Z24: =MAX(Z19:Z21) -> 14 | ... AF24: =MAX(AF19:AF21) -> 240
B25: 10.45 - 11.00 | C25: 21 | D25: 1 | E25: 0 | F25: 10 | G25: 0 | H25: 0 | I25: 3 | J25: 0 | K25: 6 | L25: 5 | M25: 15 | N25: 0 | O25: =SUM(C25:L25,N25) -> 46 | P25: =SUM(C25:N25) -> 61 | R25: AM Period | S25: =SUM(S10:S12) -> 88 | T25: =SUM(T10:T12) -> 47 | U25: =SUM(U10:U12) -> 25 | V25: =SUM(V10:V12) -> 70 | W25: =SUM(W10:W12) -> 0 | X25: =SUM(X10:X12) -> 0 | Y25: =SUM(Y10:Y12) -> 6 | Z25: =SUM(Z10:Z12) -> 24 | ... AF25: =SUM(AF10:AF12) -> 486
B26: 11.00 - 11.15 | C26: 12 | D26: 3 | E26: 2 | F26: 7 | G26: 0 | H26: 0 | I26: 1 | J26: 4 | K26: 0 | L26: 3 | M26: 16 | N26: 0 | O26: =SUM(C26:L26,N26) -> 32 | P26: =SUM(C26:N26) -> 48 | R26: IP Period | S26: =SUM(S13:S18) -> 232 | T26: =SUM(T13:T18) -> 63 | U26: =SUM(U13:U18) -> 51 | V26: =SUM(V13:V18) -> 176 | W26: =SUM(W13:W18) -> 5 | X26: =SUM(X13:X18) -> 12 | Y26: =SUM(Y13:Y18) -> 36 | Z26: =SUM(Z13:Z18) -> 46 | ... AF26: =SUM(AF13:AF18) -> 1086
B27: 11.15 - 11.30 | C27: 15 | D27: 6 | E27: 1 | F27: 2 | G27: 0 | H27: 1 | I27: 1 | J27: 2 | K27: 0 | L27: 3 | M27: 22 | N27: 0 | O27: =SUM(C27:L27,N27) -> 31 | P27: =SUM(C27:N27) -> 53 | R27: PM Period | S27: =SUM(S19:S21) -> 68 | T27: =SUM(T19:T21) -> 51 | U27: =SUM(U19:U21) -> 44 | V27: =SUM(V19:V21) -> 47 | W27: =SUM(W19:W21) -> 7 | X27: =SUM(X19:X21) -> 12 | Y27: =SUM(Y19:Y21) -> 6 | Z27: =SUM(Z19:Z21) -> 31 | ... AF27: =SUM(AF19:AF21) -> 594
B28: 11.30 - 11.45 | C28: 7 | D28: 3 | E28: 3 | F28: 7 | G28: 0 | H28: 0 | I28: 3 | J28: 0 | K28: 0 | L28: 0 | M28: 10 | N28: 0 | O28: =SUM(C28:L28,N28) -> 23 | P28: =SUM(C28:N28) -> 33 | R28: 12 Hours | S28: =SUM(S10:S21) -> 388 | T28: =SUM(T10:T21) -> 161 | U28: =SUM(U10:U21) -> 120 | V28: =SUM(V10:V21) -> 293 | W28: =SUM(W10:W21) -> 12 | X28: =SUM(X10:X21) -> 24 | Y28: =SUM(Y10:Y21) -> 48 | Z28: =SUM(Z10:Z21) -> 101 | ... AF28: =SUM(AF10:AF21) -> 2166
B29: 11.45 - 12.00 | C29: 17 | D29: 0 | E29: 0 | F29: 3 | G29: 0 | H29: 1 | I29: 0 | J29: 7 | K29: 0 | L29: 4 | M29: 7 | N29: 0 | O29: =SUM(C29:L29,N29) -> 32 | P29: =SUM(C29:N29) -> 39
B30: 12.00 - 12.15 | C30: 5 | D30: 2 | E30: 1 | F30: 10 | G30: 0 | H30: 0 | I30: 2 | J30: 0 | K30: 0 | L30: 1 | M30: 7 | N30: 0 | O30: =SUM(C30:L30,N30) -> 21 | P30: =SUM(C30:N30) -> 28
B31: 12.15 - 12.30 | C31: 11 | D31: 1 | E31: 1 | F31: 8 | G31: 0 | H31: 0 | I31: 4 | J31: 1 | K31: 1 | L31: 5 | M31: 21 | N31: 0 | O31: =SUM(C31:L31,N31) -> 32 | P31: =SUM(C31:N31) -> 53
B32: 12.30 - 12.45 | C32: 5 | D32: 2 | E32: 2 | F32: 13 | G32: 0 | H32: 1 | I32: 2 | J32: 0 | K32: 1 | L32: 7 | M32: 17 | N32: 0 | O32: =SUM(C32:L32,N32) -> 33 | P32: =SUM(C32:N32) -> 50
B33: 12.45 - 13.00 | C33: 3 | D33: 2 | E33: 2 | F33: 5 | G33: 0 | H33: 0 | I33: 0 | J33: 0 | K33: 0 | L33: 2 | M33: 13 | N33: 0 | O33: =SUM(C33:L33,N33) -> 14 | P33: =SUM(C33:N33) -> 27
B34: 13.00 - 13.15 | C34: 10 | D34: 0 | E34: 0 | F34: 11 | G34: 0 | H34: 0 | I34: 1 | J34: 1 | K34: 2 | L34: 3 | M34: 13 | N34: 0 | O34: =SUM(C34:L34,N34) -> 28 | P34: =SUM(C34:N34) -> 41
B35: 13.15 - 13.30 | C35: 8 | D35: 6 | E35: 1 | F35: 7 | G35: 0 | H35: 1 | I35: 2 | J35: 0 | K35: 0 | L35: 2 | M35: 11 | N35: 0 | O35: =SUM(C35:L35,N35) -> 27 | P35: =SUM(C35:N35) -> 38
B36: 13.30 - 13.45 | C36: 12 | D36: 6 | E36: 1 | F36: 16 | G36: 0 | H36: 1 | I36: 1 | J36: 2 | K36: 0 | L36: 0 | M36: 20 | N36: 0 | O36: =SUM(C36:L36,N36) -> 39 | P36: =SUM(C36:N36) -> 59
B37: 13.45 - 14.00 | C37: 8 | D37: 0 | E37: 0 | F37: 2 | G37: 1 | H37: 1 | I37: 0 | J37: 0 | K37: 0 | L37: 0 | M37: 12 | N37: 0 | O37: =SUM(C37:L37,N37) -> 12 | P37: =SUM(C37:N37) -> 24
B38: 14.00 - 14.15 | C38: 6 | D38: 0 | E38: 1 | F38: 8 | G38: 0 | H38: 0 | I38: 0 | J38: 1 | K38: 1 | L38: 2 | M38: 11 | N38: 0 | O38: =SUM(C38:L38,N38) -> 19 | P38: =SUM(C38:N38) -> 30
B39: 14.15 - 14.30 | C39: 4 | D39: 0 | E39: 6 | F39: 10 | G39: 0 | H39: 0 | I39: 2 | J39: 0 | K39: 0 | L39: 5 | M39: 17 | N39: 2 | O39: =SUM(C39:L39,N39) -> 29 | P39: =SUM(C39:N39) -> 46
B40: 14.30 - 14.45 | C40: 13 | D40: 0 | E40: 1 | F40: 15 | G40: 0 | H40: 0 | I40: 0 | J40: 1 | K40: 0 | L40: 1 | M40: 15 | N40: 0 | O40: =SUM(C40:L40,N40) -> 31 | P40: =SUM(C40:N40) -> 46
... B57: 18.45 - 19.00 | C57: 3 | D57: 8 | E57: 0 | F57: 0 | G57: 0 | H57: 0 | I57: 0 | J57: 0 | K57: 3 | L57: 5 | M57: 18 | N57: 0 | O57: =SUM(C57:L57,N57) -> 19 | P57: =SUM(C57:N57) -> 37
B58: Totals | C58: =SUM(C10:C57) -> 388 | D58: =SUM(D10:D57) -> 161 | E58: =SUM(E10:E57) -> 120 | F58: =SUM(F10:F57) -> 293 | G58: =SUM(G10:G57) -> 12 | H58: =SUM(H10:H57) -> 24 | I58: =SUM(I10:I57) -> 48 | J58: =SUM(J10:J57) -> 101 | ... P58: =SUM(P10:P57) -> 2166
...

Sheet 27.10 Kabale-Mbarara
B1: Consultancy services for Preparation of Expressway Development Master Plan (EDMP) for Uganda
B2: MANUAL CLASSIFIED COUNT (MCC)
B3: ROAD NAME: | C3: ='27.10 Mbarara-Kabale'!C3:G3 -> MCC - C4 - STN100 - MBARARA-NTUNGAMO ROAD
C5: Date | D5: ='27.10 Mbarara-Kabale'!D5 -> 27.10.19 | F5: Location | G5: ='27.10 Mbarara-Kabale'!G5:H5 -> Nyeihanga traffic station | J5: Surveyor | K5: Owomugisha B
C6: Dir. From | D6: Kabale | F6: Dir. To | G6: Mbarara | J6: Supervisor | K6: ='27.10 Mbarara-Kabale'!K6:L6 -> Norman R
B8: Time / Veh Type | R8: SUMMARY TRAFFIC VOLUMES
C9: 1. Car | D9: 2. Station Wagon | E9: 3. Pickups | F9: 4. Minibus, matatu | G9: 5. Medium bus | H9: 6. Large Bus | I9: 7. Light Truck | J9: 8. Medium Truck | K9: 9. Heavy truck | L9: 10. Truck Trailer | M9: 11. Motor cycles | N9: 12. Tractors | O9: Total Excl M/Cycles | P9: Total All | R9: Time | S9: 1. Car | T9: 2. Station Wagon | U9: 3. Pickups | V9: 4. Minibus, matatu | W9: 5. Medium bus | X9: 6. Large Bus | Y9: 7. Light Truck | Z9: 8. Medium Truck | AA9: 9. Heavy truck | AB9: 10. Truck Trailer | AC9: 11. Motorcycles | AD9: 12. Tractors, Graders | AE9: Total Excl M/ Cycles | AF9: Total All
B10: 07.00 - 07.15 | C10: 10 | D10: 11 | E10: 0 | F10: 18 | G10: 0 | H10: 0 | I10: 0 | J10: 0 | K10: 2 | L10: 7 | M10: 20 | N10: 0 | O10: =SUM(C10:L10,N10) -> 48 | P10: =SUM(C10:N10) -> 68 | R10: 0700-0800 | S10: =SUM(C10:C13) -> 56 | T10: =SUM(D10:D13) -> 28 | U10: =SUM(E10:E13) -> 14 | V10: =SUM(F10:F13) -> 60 | W10: =SUM(G10:G13) -> 0 | X10: =SUM(H10:H13) -> 0 | Y10: =SUM(I10:I13) -> 0 | Z10: =SUM(J10:J13) -> 10 | ... AF10: =SUM(P10:P13) -> 270
B11: 07.15 - 07.30 | C11: 17 | D11: 4 | E11: 8 | F11: 12 | G11: 0 | H11: 0 | I11: 0 | J11: 4 | K11: 0 | L11: 2 | M11: 30 | N11: 0 | O11: =SUM(C11:L11,N11) -> 47 | P11: =SUM(C11:N11) -> 77 | R11: 0800-0900 | S11: =SUM(C14:C17) -> 43 | T11: =SUM(D14:D17) -> 3 | U11: =SUM(E14:E17) -> 0 | V11: =SUM(F14:F17) -> 20 | W11: =SUM(G14:G17) -> 0 | X11: =SUM(H14:H17) -> 1 | Y11: =SUM(I14:I17) -> 4 | Z11: =SUM(J14:J17) -> 1 | ... AF11: =SUM(P14:P17) -> 119
B12: 07.30 - 07.45 | C12: 22 | D12: 7 | E12: 6 | F12: 20 | G12: 0 | H12: 0 | I12: 0 | J12: 0 | K12: 4 | L12: 0 | M12: 12 | N12: 0 | O12: =SUM(C12:L12,N12) -> 59 | P12: =SUM(C12:N12) -> 71 | R12: 0900-1000 | S12: =SUM(C18:C21) -> 17 | T12: =SUM(D18:D21) -> 4 | U12: =SUM(E18:E21) -> 0 | V12: =SUM(F18:F21) -> 14 | W12: =SUM(G18:G21) -> 0 | X12: =SUM(H18:H21) -> 1 | Y12: =SUM(I18:I21) -> 1 | Z12: =SUM(J18:J21) -> 2 | ... AF12: =SUM(P18:P21) -> 89
B13: 07.45 - 08.00 | C13: 7 | D13: 6 | E13: 0 | F13: 10 | G13: 0 | H13: 0 | I13: 0 | J13: 6 | K13: 0 | L13: 8 | M13: 17 | N13: 0 | O13: =SUM(C13:L13,N13) -> 37 | P13: =SUM(C13:N13) -> 54 | R13: 1000-1100 | S13: =SUM(C22:C25) -> 34 | T13: =SUM(D22:D25) -> 5 | U13: =SUM(E22:E25) -> 2 | V13: =SUM(F22:F25) -> 22 | W13: =SUM(G22:G25) -> 0 | X13: =SUM(H22:H25) -> 4 | Y13: =SUM(I22:I25) -> 2 | Z13: =SUM(J22:J25) -> 0 | ... AF13: =SUM(P22:P25) -> 145
B14: 08.00 - 08.15 | C14: 10 | D14: 0 | E14: 0 | F14: 7 | G14: 0 | H14: 0 | I14: 0 | J14: 0 | K14: 0 | L14: 1 | M14: 12 | N14: 0 | O14: =SUM(C14:L14,N14) -> 18 | P14: =SUM(C14:N14) -> 30 | R14: 1100-1200 | S14: =SUM(C26:C29) -> 43 | T14: =SUM(D26:D29) -> 10 | U14: =SUM(E26:E29) -> 3 | V14: =SUM(F26:F29) -> 18 | W14: =SUM(G26:G29) -> 1 | X14: =SUM(H26:H29) -> 3 | Y14: =SUM(I26:I29) -> 1 | Z14: =SUM(J26:J29) -> 3 | ... AF14: =SUM(P26:P29) -> 130
B15: 08.15 - 08.30 | C15: 14 | D15: 0 | E15: 0 | F15: 10 | G15: 0 | H15: 0 | I15: 0 | J15: 0 | K15: 0 | L15: 0 | M15: 15 | N15: 0 | O15: =SUM(C15:L15,N15) -> 24 | P15: =SUM(C15:N15) -> 39 | R15: 1200-1300 | S15: =SUM(C30:C33) -> 35 | T15: =SUM(D30:D33) -> 4 | U15: =SUM(E30:E33) -> 3 | V15: =SUM(F30:F33) -> 24 | W15: =SUM(G30:G33) -> 1 | X15: =SUM(H30:H33) -> 3 | Y15: =SUM(I30:I33) -> 6 | Z15: =SUM(J30:J33) -> 1 | ... AF15: =SUM(P30:P33) -> 153
B16: 08.30 - 08.45 | C16: 7 | D16: 3 | E16: 0 | F16: 3 | G16: 0 | H16: 1 | I16: 2 | J16: 0 | K16: 0 | L16: 3 | M16: 8 | N16: 0 | O16: =SUM(C16:L16,N16) -> 19 | P16: =SUM(C16:N16) -> 27 | R16: 1300-1400 | S16: =SUM(C34:C37) -> 25 | T16: =SUM(D34:D37) -> 4 | U16: =SUM(E34:E37) -> 3 | V16: =SUM(F34:F37) -> 18 | W16: =SUM(G34:G37) -> 0 | X16: =SUM(H34:H37) -> 1 | Y16: =SUM(I34:I37) -> 2 | Z16: =SUM(J34:J37) -> 1 | ... AF16: =SUM(P34:P37) -> 128
B17: 08.45 - 9.00 | C17: 12 | D17: 0 | E17: 0 | F17: 0 | G17: 0 | H17: 0 | I17: 2 | J17: 1 | K17: 0 | L17: 1 | M17: 7 | N17: 0 | O17: =SUM(C17:L17,N17) -> 16 | P17: =SUM(C17:N17) -> 23 | R17: 1400-1500 | S17: =SUM(C38:C41) -> 38 | T17: =SUM(D38:D41) -> 0 | U17: =SUM(E38:E41) -> 2 | V17: =SUM(F38:F41) -> 23 | W17: =SUM(G38:G41) -> 0 | X17: =SUM(H38:H41) -> 3 | Y17: =SUM(I38:I41) -> 8 | Z17: =SUM(J38:J41) -> 2 | ... AF17: =SUM(P38:P41) -> 139
B18: 09.00 - 09.15 | C18: 6 | D18: 0 | E18: 0 | F18: 5 | G18: 0 | H18: 0 | I18: 0 | J18: 0 | K18: 0 | L18: 4 | M18: 9 | N18: 0 | O18: =SUM(C18:L18,N18) -> 15 | P18: =SUM(C18:N18) -> 24 | R18: 1500-1600 | S18: =SUM(C42:C45) -> 24 | T18: =SUM(D42:D45) -> 2 | U18: =SUM(E42:E45) -> 2 | V18: =SUM(F42:F45) -> 45 | W18: =SUM(G42:G45) -> 1 | X18: =SUM(H42:H45) -> 0 | Y18: =SUM(I42:I45) -> 5 | Z18: =SUM(J42:J45) -> 2 | ... AF18: =SUM(P42:P45) -> 153
B19: 09.15 - 09.30 | C19: 4 | D19: 1 | E19: 0 | F19: 8 | G19: 0 | H19: 0 | I19: 0 | J19: 2 | K19: 0 | L19: 0 | M19: 13 | N19: 0 | O19: =SUM(C19:L19,N19) -> 15 | P19: =SUM(C19:N19) -> 28 | R19: 1600-1700 | S19: =SUM(C46:C49) -> 67 | T19: =SUM(D46:D49) -> 21 | U19: =SUM(E46:E49) -> 2 | V19: =SUM(F46:F49) -> 33 | W19: =SUM(G46:G49) -> 1 | X19: =SUM(H46:H49) -> 0 | Y19: =SUM(I46:I49) -> 0 | Z19: =SUM(J46:J49) -> 5 | ... AF19: =SUM(P46:P49) -> 206
B20: 09.30 - 09.45 | C20: 4 | D20: 0 | E20: 0 | F20: 0 | G20: 0 | H20: 1 | I20: 1 | J20: 0 | K20: 0 | L20: 0 | M20: 7 | N20: 0 | O20: =SUM(C20:L20,N20) -> 6 | P20: =SUM(C20:N20) -> 13 | R20: 1700-1800 | S20: =SUM(C50:C53) -> 40 | T20: =SUM(D50:D53) -> 2 | U20: =SUM(E50:E53) -> 4 | V20: =SUM(F50:F53) -> 26 | W20: =SUM(G50:G53) -> 1 | X20: =SUM(H50:H53) -> 0 | Y20: =SUM(I50:I53) -> 1 | Z20: =SUM(J50:J53) -> 5 | ... AF20: =SUM(P50:P53) -> 144
B21: 09.45 - 10.00 | C21: 3 | D21: 3 | E21: 0 | F21: 1 | G21: 0 | H21: 0 | I21: 0 | J21: 0 | K21: 0 | L21: 1 | M21: 16 | N21: 0 | O21: =SUM(C21:L21,N21) -> 8 | P21: =SUM(C21:N21) -> 24 | R21: 1800-1900 | S21: =SUM(C54:C57) -> 46 | T21: =SUM(D54:D57) -> 8 | U21: =SUM(E54:E57) -> 6 | V21: =SUM(F54:F57) -> 26 | W21: =SUM(G54:G57) -> 2 | X21: =SUM(H54:H57) -> 0 | Y21: =SUM(I54:I57) -> 0 | Z21: =SUM(J54:J57) -> 30 | ... AF21: =SUM(P54:P57) -> 191
B22: 10.00 - 10.15 | C22: 4 | D22: 4 | E22: 1 | F22: 6 | G22: 0 | H22: 3 | I22: 0 | J22: 0 | K22: 0 | L22: 3 | M22: 18 | N22: 0 | O22: =SUM(C22:L22,N22) -> 21 | P22: =SUM(C22:N22) -> 39 | R22: AM Peak Hr | S22: =MAX(S10:S12) -> 56 | T22: =MAX(T10:T12) -> 28 | U22: =MAX(U10:U12) -> 14 | V22: =MAX(V10:V12) -> 60 | W22: =MAX(W10:W12) -> 0 | X22: =MAX(X10:X12) -> 1 | Y22: =MAX(Y10:Y12) -> 4 | Z22: =MAX(Z10:Z12) -> 10 | ... AF22: =MAX(AF10:AF12) -> 270
B23: 10.15 - 10.30 | C23: 8 | D23: 0 | E23: 0 | F23: 12 | G23: 0 | H23: 0 | I23: 2 | J23: 0 | K23: 0 | L23: 2 | M23: 19 | N23: 0 | O23: =SUM(C23:L23,N23) -> 24 | P23: =SUM(C23:N23) -> 43 | R23: IP Peak Hr | S23: =MAX(S13:S18) -> 43 | T23: =MAX(T13:T18) -> 10 | U23: =MAX(U13:U18) -> 3 | V23: =MAX(V13:V18) -> 45 | W23: =MAX(W13:W18) -> 1 | X23: =MAX(X13:X18) -> 4 | Y23: =MAX(Y13:Y18) -> 8 | Z23: =MAX(Z13:Z18) -> 3 | ... AF23: =MAX(AF13:AF18) -> 153
B24: 10.30 - 10.45 | C24: 14 | D24: 1 | E24: 1 | F24: 0 | G24: 0 | H24: 1 | I24: 0 | J24: 0 | K24: 0 | L24: 1 | M24: 16 | N24: 0 | O24: =SUM(C24:L24,N24) -> 18 | P24: =SUM(C24:N24) -> 34 | R24: PM Peak Hr | S24: =MAX(S19:S21) -> 67 | T24: =MAX(T19:T21) -> 21 | U24: =MAX(U19:U21) -> 6 | V24: =MAX(V19:V21) -> 33 | W24: =MAX(W19:W21) -> 2 | X24: =MAX(X19:X21) -> 0 | Y24: =MAX(Y19:Y21) -> 1 | Z24: =MAX(Z19:Z21) -> 30 | ... AF24: =MAX(AF19:AF21) -> 206
B25: 10.45 - 11.00 | C25: 8 | D25: 0 | E25: 0 | F25: 4 | G25: 0 | H25: 0 | I25: 0 | J25: 0 | K25: 0 | L25: 7 | M25: 10 | N25: 0 | O25: =SUM(C25:L25,N25) -> 19 | P25: =SUM(C25:N25) -> 29 | R25: AM Period | S25: =SUM(S10:S12) -> 116 | T25: =SUM(T10:T12) -> 35 | U25: =SUM(U10:U12) -> 14 | V25: =SUM(V10:V12) -> 94 | W25: =SUM(W10:W12) -> 0 | X25: =SUM(X10:X12) -> 2 | Y25: =SUM(Y10:Y12) -> 5 | Z25: =SUM(Z10:Z12) -> 13 | ... AF25: =SUM(AF10:AF12) -> 478
B26: 11.00 - 11.15 | C26: 17 | D26: 3 | E26: 2 | F26: 6 | G26: 0 | H26: 0 | I26: 0 | J26: 0 | K26: 1 | L26: 3 | M26: 13 | N26: 0 | O26: =SUM(C26:L26,N26) -> 32 | P26: =SUM(C26:N26) -> 45 | R26: IP Period | S26: =SUM(S13:S18) -> 199 | T26: =SUM(T13:T18) -> 25 | U26: =SUM(U13:U18) -> 15 | V26: =SUM(V13:V18) -> 150 | W26: =SUM(W13:W18) -> 3 | X26: =SUM(X13:X18) -> 14 | Y26: =SUM(Y13:Y18) -> 24 | Z26: =SUM(Z13:Z18) -> 9 | ... AF26: =SUM(AF13:AF18) -> 848
B27: 11.15 - 11.30 | C27: 8 | D27: 6 | E27: 0 | F27: 3 | G27: 1 | H27: 2 | I27: 1 | J27: 0 | K27: 0 | L27: 1 | M27: 18 | N27: 0 | O27: =SUM(C27:L27,N27) -> 22 | P27: =SUM(C27:N27) -> 40 | R27: PM Period | S27: =SUM(S19:S21) -> 153 | T27: =SUM(T19:T21) -> 31 | U27: =SUM(U19:U21) -> 12 | V27: =SUM(V19:V21) -> 85 | W27: =SUM(W19:W21) -> 4 | X27: =SUM(X19:X21) -> 0 | Y27: =SUM(Y19:Y21) -> 1 | Z27: =SUM(Z19:Z21) -> 40 | ... AF27: =SUM(AF19:AF21) -> 541
B28: 11.30 - 11.45 | C28: 13 | D28: 1 | E28: 1 | F28: 6 | G28: 0 | H28: 1 | I28: 0 | J28: 0 | K28: 0 | L28: 0 | M28: 7 | N28: 0 | O28: =SUM(C28:L28,N28) -> 22 | P28: =SUM(C28:N28) -> 29 | R28: 12 Hours | S28: =SUM(S10:S21) -> 468 | T28: =SUM(T10:T21) -> 91 | U28: =SUM(U10:U21) -> 41 | V28: =SUM(V10:V21) -> 329 | W28: =SUM(W10:W21) -> 7 | X28: =SUM(X10:X21) -> 16 | Y28: =SUM(Y10:Y21) -> 30 | Z28: =SUM(Z10:Z21) -> 62 | ... AF28: =SUM(AF10:AF21) -> 1867
B29: 11.45 - 12.00 | C29: 5 | D29: 0 | E29: 0 | F29: 3 | G29: 0 | H29: 0 | I29: 0 | J29: 3 | K29: 0 | L29: 2 | M29: 3 | N29: 0 | O29: =SUM(C29:L29,N29) -> 13 | P29: =SUM(C29:N29) -> 16
B30: 12.00 - 12.15 | C30: 7 | D30: 0 | E30: 0 | F30: 12 | G30: 0 | H30: 0 | I30: 1 | J30: 0 | K30: 1 | L30: 2 | M30: 10 | N30: 0 | O30: =SUM(C30:L30,N30) -> 23 | P30: =SUM(C30:N30) -> 33
B31: 12.15 - 12.30 | C31: 9 | D31: 1 | E31: 1 | F31: 9 | G31: 0 | H31: 0 | I31: 3 | J31: 0 | K31: 0 | L31: 3 | M31: 19 | N31: 0 | O31: =SUM(C31:L31,N31) -> 26 | P31: =SUM(C31:N31) -> 45
B32: 12.30 - 12.45 | C32: 7 | D32: 3 | E32: 2 | F32: 0 | G32: 1 | H32: 3 | I32: 2 | J32: 1 | K32: 2 | L32: 3 | M32: 21 | N32: 0 | O32: =SUM(C32:L32,N32) -> 24 | P32: =SUM(C32:N32) -> 45
B33: 12.45 - 13.00 | C33: 12 | D33: 0 | E33: 0 | F33: 3 | G33: 0 | H33: 0 | I33: 0 | J33: 0 | K33: 0 | L33: 3 | M33: 12 | N33: 0 | O33: =SUM(C33:L33,N33) -> 18 | P33: =SUM(C33:N33) -> 30
B34: 13.00 - 13.15 | C34: 11 | D34: 1 | E34: 0 | F34: 4 | G34: 0 | H34: 0 | I34: 0 | J34: 0 | K34: 1 | L34: 1 | M34: 15 | N34: 0 | O34: =SUM(C34:L34,N34) -> 18 | P34: =SUM(C34:N34) -> 33
B35: 13.15 - 13.30 | C35: 3 | D35: 3 | E35: 1 | F35: 5 | G35: 0 | H35: 0 | I35: 1 | J35: 0 | K35: 0 | L35: 2 | M35: 12 | N35: 0 | O35: =SUM(C35:L35,N35) -> 15 | P35: =SUM(C35:N35) -> 27
B36: 13.30 - 13.45 | C36: 7 | D36: 0 | E36: 2 | F36: 8 | G36: 0 | H36: 0 | I36: 0 | J36: 1 | K36: 7 | L36: 1 | M36: 22 | N36: 0 | O36: =SUM(C36:L36,N36) -> 26 | P36: =SUM(C36:N36) -> 48
B37: 13.45 - 14.00 | C37: 4 | D37: 0 | E37: 0 | F37: 1 | G37: 0 | H37: 1 | I37: 1 | J37: 0 | K37: 0 | L37: 1 | M37: 10 | N37: 2 | O37: =SUM(C37:L37,N37) -> 10 | P37: =SUM(C37:N37) -> 20
B38: 14.00 - 14.15 | C38: 11 | D38: 0 | E38: 2 | F38: 1 | G38: 0 | H38: 2 | I38: 2 | J38: 0 | K38: 0 | L38: 4 | M38: 16 | N38: 0 | O38: =SUM(C38:L38,N38) -> 22 | P38: =SUM(C38:N38) -> 38
B39: 14.15 - 14.30 | C39: 8 | D39: 0 | E39: 0 | F39: 4 | G39: 0 | H39: 0 | I39: 1 | J39: 0 | K39: 0 | L39: 1 | M39: 20 | N39: 0 | O39: =SUM(C39:L39,N39) -> 14 | P39: =SUM(C39:N39) -> 34
B40: 14.30 - 14.45 | C40: 6 | D40: 0 | E40: 0 | F40: 11 | G40: 0 | H40: 0 | I40: 1 | J40: 2 | K40: 0 | L40: 3 | M40: 12 | N40: 0 | O40: =SUM(C40:L40,N40) -> 23 | P40: =SUM(C40:N40) -> 35
... B57: 18.45 - 19.00 | C57: 12 | D57: 2 | E57: 4 | F57: 5 | G57: 0 | H57: 0 | I57: 0 | J57: 3 | K57: 2 | L57: 2 | M57: 7 | N57: 0 | O57: =SUM(C57:L57,N57) -> 30 | P57: =SUM(C57:N57) -> 37
B58: Totals | C58: =SUM(C10:C57) -> 468 | D58: =SUM(D10:D57) -> 91 | E58: =SUM(E10:E57) -> 41 | F58: =SUM(F10:F57) -> 329 | G58: =SUM(G10:G57) -> 7 | H58: =SUM(H10:H57) -> 16 | I58: =SUM(I10:I57) -> 30 | J58: =SUM(J10:J57) -> 62 | ... P58: =SUM(P10:P57) -> 1867
...

Sheet 28.10 Mbarara-Kabale
B1: Consultancy services for Preparation of Expressway Development Master Plan (EDMP) for Uganda
B2: MANUAL CLASSIFIED COUNT (MCC)
B3: ROAD NAME: | C3: ='27.10 Mbarara-Kabale'!C3:G3 -> MCC - C4 - STN100 - MBARARA-NTUNGAMO ROAD
C5: Date | D5: 28.10.19 | F5: Location | G5: ='27.10 Mbarara-Kabale'!G5:H5 -> Nyeihanga traffic station | J5: Surveyor | K5: ='27.10 Mbarara-Kabale'!K5:L5 -> Norman
C6: Dir. From | D6: ='27.10 Mbarara-Kabale'!D6:E6 -> Mbarara | F6: Dir. To | G6: ='27.10 Mbarara-Kabale'!G6:H6 -> Kabale | J6: Supervisor | K6: ='27.10 Mbarara-Kabale'!K6:L6 -> Norman R
B8: Time / Veh Type | R8: SUMMARY TRAFFIC VOLUMES
C9: 1. Car | D9: 2. Station Wagon | E9: 3. Pickups | F9: 4. Minibus, matatu | G9: 5. Medium bus | H9: 6. Large Bus | I9: 7. Light Truck | J9: 8. Medium Truck | K9: 9. Heavy truck | L9: 10. Truck Trailer | M9: 11. Motor cycles | N9: 12. Tractors | O9: Total Excl M/Cycles | P9: Total All | R9: Time | S9: 1. Car | T9: 2. Station Wagon | U9: 3. Pickups | V9: 4. Minibus, matatu | W9: 5. Medium bus | X9: 6. Large Bus | Y9: 7. Light Truck | Z9: 8. Medium Truck | AA9: 9. Heavy truck | AB9: 10. Truck Trailer | AC9: 11. Motorcycles | AD9: 12. Tractors, Graders | AE9: Total Excl M/ Cycles | AF9: Total All
B10: 07.00 - 07.15 | C10: 6 | D10: 0 | E10: 1 | F10: 4 | G10: 0 | H10: 0 | I10: 0 | J10: 0 | K10: 2 | L10: 2 | M10: 14 | N10: 0 | O10: =SUM(C10:L10,N10) -> 15 | P10: =SUM(C10:N10) -> 29 | R10: 0700-0800 | S10: =SUM(C10:C13) -> 18 | T10: =SUM(D10:D13) -> 3 | U10: =SUM(E10:E13) -> 2 | V10: =SUM(F10:F13) -> 5 | W10: =SUM(G10:G13) -> 0 | X10: =SUM(H10:H13) -> 0 | Y10: =SUM(I10:I13) -> 5 | Z10: =SUM(J10:J13) -> 2 | ... AF10: =SUM(P10:P13) -> 99
B11: 07.15 - 07.30 | C11: 3 | D11: 1 | E11: 0 | F11: 0 | G11: 0 | H11: 0 | I11: 0 | J11: 1 | K11: 3 | L11: 2 | M11: 12 | N11: 0 | O11: =SUM(C11:L11,N11) -> 10 | P11: =SUM(C11:N11) -> 22 | R11: 0800-0900 | S11: =SUM(C14:C17) -> 26 | T11: =SUM(D14:D17) -> 6 | U11: =SUM(E14:E17) -> 7 | V11: =SUM(F14:F17) -> 16 | W11: =SUM(G14:G17) -> 0 | X11: =SUM(H14:H17) -> 0 | Y11: =SUM(I14:I17) -> 6 | Z11: =SUM(J14:J17) -> 4 | ... AF11: =SUM(P14:P17) -> 141
B12: 07.30 - 07.45 | C12: 4 | D12: 1 | E12: 0 | F12: 1 | G12: 0 | H12: 0 | I12: 2 | J12: 1 | K12: 2 | L12: 6 | M12: 13 | N12: 0 | O12: =SUM(C12:L12,N12) -> 17 | P12: =SUM(C12:N12) -> 30 | R12: 0900-1000 | S12: =SUM(C18:C21) -> 28 | T12: =SUM(D18:D21) -> 10 | U12: =SUM(E18:E21) -> 7 | V12: =SUM(F18:F21) -> 13 | W12: =SUM(G18:G21) -> 0 | X12: =SUM(H18:H21) -> 2 | Y12: =SUM(I18:I21) -> 12 | Z12: =SUM(J18:J21) -> 6 | ... AF12: =SUM(P18:P21) -> 191
B13: 07.45 - 08.00 | C13: 5 | D13: 1 | E13: 1 | F13: 0 | G13: 0 | H13: 0 | I13: 3 | J13: 0 | K13: 0 | L13: 0 | M13: 8 | N13: 0 | O13: =SUM(C13:L13,N13) -> 10 | P13: =SUM(C13:N13) -> 18 | R13: 1000-1100 | S13: =SUM(C22:C25) -> 27 | T13: =SUM(D22:D25) -> 10 | U13: =SUM(E22:E25) -> 10 | V13: =SUM(F22:F25) -> 23 | W13: =SUM(G22:G25) -> 0 | X13: =SUM(H22:H25) -> 3 | Y13: =SUM(I22:I25) -> 25 | Z13: =SUM(J22:J25) -> 5 | ... AF13: =SUM(P22:P25) -> 188
B14: 08.00 - 08.15 | C14: 10 | D14: 1 | E14: 2 | F14: 4 | G14: 0 | H14: 0 | I14: 1 | J14: 1 | K14: 1 | L14: 0 | M14: 11 | N14: 0 | O14: =SUM(C14:L14,N14) -> 20 | P14: =SUM(C14:N14) -> 31 | R14: 1100-1200 | S14: =SUM(C26:C29) -> 36 | T14: =SUM(D26:D29) -> 21 | U14: =SUM(E26:E29) -> 16 | V14: =SUM(F26:F29) -> 36 | W14: =SUM(G26:G29) -> 0 | X14: =SUM(H26:H29) -> 4 | Y14: =SUM(I26:I29) -> 15 | Z14: =SUM(J26:J29) -> 7 | ... AF14: =SUM(P26:P29) -> 238
B15: 08.15 - 08.30 | C15: 7 | D15: 2 | E15: 2 | F15: 6 | G15: 0 | H15: 0 | I15: 1 | J15: 1 | K15: 2 | L15: 3 | M15: 18 | N15: 0 | O15: =SUM(C15:L15,N15) -> 24 | P15: =SUM(C15:N15) -> 42 | R15: 1200-1300 | S15: =SUM(C30:C33) -> 35 | T15: =SUM(D30:D33) -> 3 | U15: =SUM(E30:E33) -> 12 | V15: =SUM(F30:F33) -> 28 | W15: =SUM(G30:G33) -> 0 | X15: =SUM(H30:H33) -> 3 | Y15: =SUM(I30:I33) -> 14 | Z15: =SUM(J30:J33) -> 13 | ... AF15: =SUM(P30:P33) -> 207
B16: 08.30 - 08.45 | C16: 1 | D16: 1 | E16: 3 | F16: 3 | G16: 0 | H16: 0 | I16: 2 | J16: 0 | K16: 0 | L16: 6 | M16: 26 | N16: 0 | O16: =SUM(C16:L16,N16) -> 16 | P16: =SUM(C16:N16) -> 42 | R16: 1300-1400 | S16: =SUM(C34:C37) -> 31 | T16: =SUM(D34:D37) -> 9 | U16: =SUM(E34:E37) -> 11 | V16: =SUM(F34:F37) -> 19 | W16: =SUM(G34:G37) -> 0 | X16: =SUM(H34:H37) -> 2 | Y16: =SUM(I34:I37) -> 5 | Z16: =SUM(J34:J37) -> 5 | ... AF16: =SUM(P34:P37) -> 119
B17: 08.45 - 9.00 | C17: 8 | D17: 2 | E17: 0 | F17: 3 | G17: 0 | H17: 0 | I17: 2 | J17: 2 | K17: 0 | L17: 3 | M17: 6 | N17: 0 | O17: =SUM(C17:L17,N17) -> 20 | P17: =SUM(C17:N17) -> 26 | R17: 1400-1500 | S17: =SUM(C38:C41) -> 21 | T17: =SUM(D38:D41) -> 12 | U17: =SUM(E38:E41) -> 1 | V17: =SUM(F38:F41) -> 17 | W17: =SUM(G38:G41) -> 0 | X17: =SUM(H38:H41) -> 6 | Y17: =SUM(I38:I41) -> 0 | Z17: =SUM(J38:J41) -> 0 | ... AF17: =SUM(P38:P41) -> 110
B18: 09.00 - 09.15 | C18: 4 | D18: 6 | E18: 2 | F18: 2 | G18: 0 | H18: 0 | I18: 2 | J18: 0 | K18: 2 | L18: 4 | M18: 19 | N18: 0 | O18: =SUM(C18:L18,N18) -> 22 | P18: =SUM(C18:N18) -> 41 | R18: 1500-1600 | S18: =SUM(C42:C45) -> 27 | T18: =SUM(D42:D45) -> 14 | U18: =SUM(E42:E45) -> 1 | V18: =SUM(F42:F45) -> 18 | W18: =SUM(G42:G45) -> 0 | X18: =SUM(H42:H45) -> 0 | Y18: =SUM(I42:I45) -> 2 | Z18: =SUM(J42:J45) -> 1 | ... AF18: =SUM(P42:P45) -> 101
B19: 09.15 - 09.30 | C19: 9 | D19: 2 | E19: 3 | F19: 6 | G19: 0 | H19: 0 | I19: 6 | J19: 4 | K19: 0 | L19: 11 | M19: 24 | N19: 0 | O19: =SUM(C19:L19,N19) -> 41 | P19: =SUM(C19:N19) -> 65 | R19: 1600-1700 | S19: =SUM(C46:C49) -> 19 | T19: =SUM(D46:D49) -> 20 | U19: =SUM(E46:E49) -> 9 | V19: =SUM(F46:F49) -> 36 | W19: =SUM(G46:G49) -> 0 | X19: =SUM(H46:H49) -> 7 | Y19: =SUM(I46:I49) -> 12 | Z19: =SUM(J46:J49) -> 4 | ... AF19: =SUM(P46:P49) -> 165
B20: 09.30 - 09.45 | C20: 12 | D20: 2 | E20: 1 | F20: 3 | G20: 0 | H20: 0 | I20: 4 | J20: 0 | K20: 0 | L20: 0 | M20: 23 | N20: 0 | O20: =SUM(C20:L20,N20) -> 22 | P20: =SUM(C20:N20) -> 45 | R20: 1700-1800 | S20: =SUM(C50:C53) -> 27 | T20: =SUM(D50:D53) -> 16 | U20: =SUM(E50:E53) -> 5 | V20: =SUM(F50:F53) -> 17 | W20: =SUM(G50:G53) -> 1 | X20: =SUM(H50:H53) -> 0 | Y20: =SUM(I50:I53) -> 4 | Z20: =SUM(J50:J53) -> 2 | ... AF20: =SUM(P50:P53) -> 159
B21: 09.45 - 10.00 | C21: 3 | D21: 0 | E21: 1 | F21: 2 | G21: 0 | H21: 2 | I21: 0 | J21: 2 | K21: 0 | L21: 6 | M21: 24 | N21: 0 | O21: =SUM(C21:L21,N21) -> 16 | P21: =SUM(C21:N21) -> 40 | R21: 1800-1900 | S21: =SUM(C54:C57) -> 38 | T21: =SUM(D54:D57) -> 14 | U21: =SUM(E54:E57) -> 10 | V21: =SUM(F54:F57) -> 15 | W21: =SUM(G54:G57) -> 1 | X21: =SUM(H54:H57) -> 0 | Y21: =SUM(I54:I57) -> 3 | Z21: =SUM(J54:J57) -> 1 | ... AF21: =SUM(P54:P57) -> 162
B22: 10.00 - 10.15 | C22: 2 | D22: 1 | E22: 0 | F22: 4 | G22: 0 | H22: 0 | I22: 0 | J22: 0 | K22: 3 | L22: 4 | M22: 9 | N22: 0 | O22: =SUM(C22:L22,N22) -> 14 | P22: =SUM(C22:N22) -> 23 | R22: AM Peak Hr | S22: =MAX(S10:S12) -> 28 | T22: =MAX(T10:T12) -> 10 | U22: =MAX(U10:U12) -> 7 | V22: =MAX(V10:V12) -> 16 | W22: =MAX(W10:W12) -> 0 | X22: =MAX(X10:X12) -> 2 | Y22: =MAX(Y10:Y12) -> 12 | Z22: =MAX(Z10:Z12) -> 6 | ... AF22: =MAX(AF10:AF12) -> 191
B23: 10.15 - 10.30 | C23: 3 | D23: 0 | E23: 5 | F23: 8 | G23: 0 | H23: 0 | I23: 3 | J23: 0 | K23: 0 | L23: 5 | M23: 8 | N23: 0 | O23: =SUM(C23:L23,N23) -> 24 | P23: =SUM(C23:N23) -> 32 | R23: IP Peak Hr | S23: =MAX(S13:S18) -> 36 | T23: =MAX(T13:T18) -> 21 | U23: =MAX(U13:U18) -> 16 | V23: =MAX(V13:V18) -> 36 | W23: =MAX(W13:W18) -> 0 | X23: =MAX(X13:X18) -> 6 | Y23: =MAX(Y13:Y18) -> 25 | Z23: =MAX(Z13:Z18) -> 13 | ... AF23: =MAX(AF13:AF18) -> 238
B24: 10.30 - 10.45 | C24: 9 | D24: 3 | E24: 0 | F24: 2 | G24: 0 | H24: 0 | I24: 7 | J24: 2 | K24: 5 | L24: 8 | M24: 26 | N24: 0 | O24: =SUM(C24:L24,N24) -> 36 | P24: =SUM(C24:N24) -> 62 | R24: PM Peak Hr | S24: =MAX(S19:S21) -> 38 | T24: =MAX(T19:T21) -> 20 | U24: =MAX(U19:U21) -> 10 | V24: =MAX(V19:V21) -> 36 | W24: =MAX(W19:W21) -> 1 | X24: =MAX(X19:X21) -> 7 | Y24: =MAX(Y19:Y21) -> 12 | Z24: =MAX(Z19:Z21) -> 4 | ... AF24: =MAX(AF19:AF21) -> 165
B25: 10.45 - 11.00 | C25: 13 | D25: 6 | E25: 5 | F25: 9 | G25: 0 | H25: 3 | I25: 15 | J25: 3 | K25: 0 | L25: 0 | M25: 17 | N25: 0 | O25: =SUM(C25:L25,N25) -> 54 | P25: =SUM(C25:N25) -> 71 | R25: AM Period | S25: =SUM(S10:S12) -> 72 | T25: =SUM(T10:T12) -> 19 | U25: =SUM(U10:U12) -> 16 | V25: =SUM(V10:V12) -> 34 | W25: =SUM(W10:W12) -> 0 | X25: =SUM(X10:X12) -> 2 | Y25: =SUM(Y10:Y12) -> 23 | Z25: =SUM(Z10:Z12) -> 12 | ... AF25: =SUM(AF10:AF12) -> 431
B26: 11.00 - 11.15 | C26: 3 | D26: 1 | E26: 3 | F26: 8 | G26: 0 | H26: 1 | I26: 2 | J26: 0 | K26: 0 | L26: 0 | M26: 14 | N26: 0 | O26: =SUM(C26:L26,N26) -> 18 | P26: =SUM(C26:N26) -> 32 | R26: IP Period | S26: =SUM(S13:S18) -> 177 | T26: =SUM(T13:T18) -> 69 | U26: =SUM(U13:U18) -> 51 | V26: =SUM(V13:V18) -> 141 | W26: =SUM(W13:W18) -> 0 | X26: =SUM(X13:X18) -> 18 | Y26: =SUM(Y13:Y18) -> 61 | Z26: =SUM(Z13:Z18) -> 31 | ... AF26: =SUM(AF13:AF18) -> 963
B27: 11.15 - 11.30 | C27: 8 | D27: 13 | E27: 3 | F27: 24 | G27: 0 | H27: 0 | I27: 1 | J27: 4 | K27: 0 | L27: 4 | M27: 18 | N27: 0 | O27: =SUM(C27:L27,N27) -> 57 | P27: =SUM(C27:N27) -> 75 | R27: PM Period | S27: =SUM(S19:S21) -> 84 | T27: =SUM(T19:T21) -> 50 | U27: =SUM(U19:U21) -> 24 | V27: =SUM(V19:V21) -> 68 | W27: =SUM(W19:W21) -> 2 | X27: =SUM(X19:X21) -> 7 | Y27: =SUM(Y19:Y21) -> 19 | Z27: =SUM(Z19:Z21) -> 7 | ... AF27: =SUM(AF19:AF21) -> 486
B28: 11.30 - 11.45 | C28: 15 | D28: 1 | E28: 7 | F28: 4 | G28: 0 | H28: 0 | I28: 8 | J28: 3 | K28: 6 | L28: 0 | M28: 36 | N28: 0 | O28: =SUM(C28:L28,N28) -> 44 | P28: =SUM(C28:N28) -> 80 | R28: 12 Hours | S28: =SUM(S10:S21) -> 333 | T28: =SUM(T10:T21) -> 138 | U28: =SUM(U10:U21) -> 91 | V28: =SUM(V10:V21) -> 243 | W28: =SUM(W10:W21) -> 2 | X28: =SUM(X10:X21) -> 27 | Y28: =SUM(Y10:Y21) -> 103 | Z28: =SUM(Z10:Z21) -> 50 | ... AF28: =SUM(AF10:AF21) -> 1880
B29: 11.45 - 12.00 | C29: 10 | D29: 6 | E29: 3 | F29: 0 | G29: 0 | H29: 3 | I29: 4 | J29: 0 | K29: 0 | L29: 10 | M29: 15 | N29: 0 | O29: =SUM(C29:L29,N29) -> 36 | P29: =SUM(C29:N29) -> 51
B30: 12.00 - 12.15 | C30: 14 | D30: 0 | E30: 9 | F30: 8 | G30: 0 | H30: 0 | I30: 3 | J30: 4 | K30: 14 | L30: 5 | M30: 14 | N30: 0 | O30: =SUM(C30:L30,N30) -> 57 | P30: =SUM(C30:N30) -> 71
B31: 12.15 - 12.30 | C31: 8 | D31: 0 | E31: 3 | F31: 8 | G31: 0 | H31: 3 | I31: 4 | J31: 5 | K31: 0 | L31: 0 | M31: 18 | N31: 0 | O31: =SUM(C31:L31,N31) -> 31 | P31: =SUM(C31:N31) -> 49
B32: 12.30 - 12.45 | C32: 9 | D32: 2 | E32: 0 | F32: 8 | G32: 0 | H32: 0 | I32: 3 | J32: 4 | K32: 2 | L32: 15 | M32: 23 | N32: 0 | O32: =SUM(C32:L32,N32) -> 43 | P32: =SUM(C32:N32) -> 66
B33: 12.45 - 13.00 | C33: 4 | D33: 1 | E33: 0 | F33: 4 | G33: 0 | H33: 0 | I33: 4 | J33: 0 | K33: 0 | L33: 5 | M33: 3 | N33: 0 | O33: =SUM(C33:L33,N33) -> 18 | P33: =SUM(C33:N33) -> 21
B34: 13.00 - 13.15 | C34: 10 | D34: 4 | E34: 5 | F34: 4 | G34: 0 | H34: 0 | I34: 0 | J34: 0 | K34: 0 | L34: 0 | M34: 7 | N34: 0 | O34: =SUM(C34:L34,N34) -> 23 | P34: =SUM(C34:N34) -> 30
B35: 13.15 - 13.30 | C35: 11 | D35: 0 | E35: 0 | F35: 4 | G35: 0 | H35: 1 | I35: 1 | J35: 2 | K35: 2 | L35: 0 | M35: 9 | N35: 0 | O35: =SUM(C35:L35,N35) -> 21 | P35: =SUM(C35:N35) -> 30
B36: 13.30 - 13.45 | C36: 7 | D36: 5 | E36: 6 | F36: 11 | G36: 0 | H36: 1 | I36: 4 | J36: 3 | K36: 3 | L36: 0 | M36: 6 | N36: 0 | O36: =SUM(C36:L36,N36) -> 40 | P36: =SUM(C36:N36) -> 46
B37: 13.45 - 14.00 | C37: 3 | D37: 0 | E37: 0 | F37: 0 | G37: 0 | H37: 0 | I37: 0 | J37: 0 | K37: 0 | L37: 0 | M37: 10 | N37: 0 | O37: =SUM(C37:L37,N37) -> 3 | P37: =SUM(C37:N37) -> 13
B38: 14.00 - 14.15 | C38: 2 | D38: 1 | E38: 0 | F38: 0 | G38: 0 | H38: 0 | I38: 0 | J38: 0 | K38: 1 | L38: 2 | M38: 2 | N38: 0 | O38: =SUM(C38:L38,N38) -> 6 | P38: =SUM(C38:N38) -> 8
B39: 14.15 - 14.30 | C39: 4 | D39: 1 | E39: 0 | F39: 5 | G39: 0 | H39: 0 | I39: 0 | J39: 0 | K39: 2 | L39: 1 | M39: 13 | N39: 0 | O39: =SUM(C39:L39,N39) -> 13 | P39: =SUM(C39:N39) -> 26
B40: 14.30 - 14.45 | C40: 5 | D40: 3 | E40: 0 | F40: 4 | G40: 0 | H40: 2 | I40: 0 | J40: 0 | K40: 5 | L40: 3 | M40: 6 | N40: 0 | O40: =SUM(C40:L40,N40) -> 22 | P40: =SUM(C40:N40) -> 28
... B57: 18.45 - 19.00 | C57: 14 | D57: 6 | E57: 5 | F57: 2 | G57: 0 | H57: 0 | I57: 0 | J57: 0 | K57: 4 | L57: 11 | M57: 11 | N57: 0 | O57: =SUM(C57:L57,N57) -> 42 | P57: =SUM(C57:N57) -> 53
B58: Totals | C58: =SUM(C10:C57) -> 333 | D58: =SUM(D10:D57) -> 138 | E58: =SUM(E10:E57) -> 91 | F58: =SUM(F10:F57) -> 243 | G58: =SUM(G10:G57) -> 2 | H58: =SUM(H10:H57) -> 27 | I58: =SUM(I10:I57) -> 103 | J58: =SUM(J10:J57) -> 50 | ... P58: =SUM(P10:P57) -> 1880
...

Sheet 28.10 Kabale-Mbarara
B1: Consultancy services for Preparation of Expressway Development Master Plan (EDMP) for Uganda
B2: MANUAL CLASSIFIED COUNT (MCC)
B3: ROAD NAME: | C3: ='27.10 Kabale-Mbarara'!C3:G3 -> MCC - C4 - STN100 - MBARARA-NTUNGAMO ROAD
C5: Date | D5: ='28.10 Mbarara-Kabale'!D5 -> 28.10.19 | F5: Location | G5: ='27.10 Mbarara-Kabale'!G5:H5 -> Nyeihanga traffic station | J5: Surveyor | K5: Owomugisha B
C6: Dir. From | D6: ='27.10 Kabale-Mbarara'!D6:E6 -> Kabale | F6: Dir. To | G6: ='27.10 Kabale-Mbarara'!G6:H6 -> Mbarara | J6: Supervisor | K6: ='27.10 Mbarara-Kabale'!K6:L6 -> Norman R
B8: Time / Veh Type | R8: SUMMARY TRAFFIC VOLUMES
C9: 1. Car | D9: 2. Station Wagon | E9: 3. Pickups | F9: 4. Minibus, matatu | G9: 5. Medium bus | H9: 6. Large Bus | I9: 7. Light Truck | J9: 8. Medium Truck | K9: 9. Heavy truck | L9: 10. Truck Trailer | M9: 11. Motor cycles | N9: 12. Tractors | O9: Total Excl M/Cycles | P9: Total All | R9: Time | S9: 1. Car | T9: 2. Station Wagon | U9: 3. Pickups | V9: 4. Minibus, matatu | W9: 5. Medium bus | X9: 6. Large Bus | Y9: 7. Light Truck | Z9: 8. Medium Truck | AA9: 9. Heavy truck | AB9: 10. Truck Trailer | AC9: 11. Motorcycles | AD9: 12. Tractors, Graders | AE9: Total Excl M/ Cycles | AF9: Total All
B10: 07.00 - 07.15 | C10: 6 | D10: 0 | E10: 0 | F10: 3 | G10: 0 | H10: 0 | I10: 2 | J10: 0 | K10: 0 | L10: 0 | M10: 18 | N10: 0 | O10: =SUM(C10:L10,N10) -> 11 | P10: =SUM(C10:N10) -> 29 | R10: 0700-0800 | S10: =SUM(C10:C13) -> 24 | T10: =SUM(D10:D13) -> 2 | U10: =SUM(E10:E13) -> 2 | V10: =SUM(F10:F13) -> 25 | W10: =SUM(G10:G13) -> 1 | X10: =SUM(H10:H13) -> 2 | Y10: =SUM(I10:I13) -> 8 | Z10: =SUM(J10:J13) -> 2 | ... AF10: =SUM(P10:P13) -> 127
B11: 07.15 - 07.30 | C11: 3 | D11: 0 | E11: 1 | F11: 6 | G11: 0 | H11: 0 | I11: 0 | J11: 0 | K11: 0 | L11: 0 | M11: 20 | N11: 0 | O11: =SUM(C11:L11,N11) -> 10 | P11: =SUM(C11:N11) -> 30 | R11: 0800-0900 | S11: =SUM(C14:C17) -> 35 | T11: =SUM(D14:D17) -> 7 | U11: =SUM(E14:E17) -> 4 | V11: =SUM(F14:F17) -> 32 | W11: =SUM(G14:G17) -> 0 | X11: =SUM(H14:H17) -> 0 | Y11: =SUM(I14:I17) -> 7 | Z11: =SUM(J14:J17) -> 6 | ... AF11: =SUM(P14:P17) -> 188
B12: 07.30 - 07.45 | C12: 6 | D12: 0 | E12: 0 | F12: 6 | G12: 1 | H12: 1 | I12: 0 | J12: 0 | K12: 0 | L12: 3 | M12: 7 | N12: 0 | O12: =SUM(C12:L12,N12) -> 17 | P12: =SUM(C12:N12) -> 24 | R12: 0900-1000 | S12: =SUM(C18:C21) -> 52 | T12: =SUM(D18:D21) -> 2 | U12: =SUM(E18:E21) -> 3 | V12: =SUM(F18:F21) -> 41 | W12: =SUM(G18:G21) -> 0 | X12: =SUM(H18:H21) -> 6 | Y12: =SUM(I18:I21) -> 7 | Z12: =SUM(J18:J21) -> 3 | ... AF12: =SUM(P18:P21) -> 220
B13: 07.45 - 08.00 | C13: 9 | D13: 2 | E13: 1 | F13: 10 | G13: 0 | H13: 1 | I13: 6 | J13: 2 | K13: 0 | L13: 0 | M13: 13 | N13: 0 | O13: =SUM(C13:L13,N13) -> 31 | P13: =SUM(C13:N13) -> 44 | R13: 1000-1100 | S13: =SUM(C22:C25) -> 32 | T13: =SUM(D22:D25) -> 3 | U13: =SUM(E22:E25) -> 5 | V13: =SUM(F22:F25) -> 29 | W13: =SUM(G22:G25) -> 0 | X13: =SUM(H22:H25) -> 3 | Y13: =SUM(I22:I25) -> 4 | Z13: =SUM(J22:J25) -> 9 | ... AF13: =SUM(P22:P25) -> 167
B14: 08.00 - 08.15 | C14: 10 | D14: 1 | E14: 1 | F14: 11 | G14: 0 | H14: 0 | I14: 0 | J14: 1 | K14: 1 | L14: 0 | M14: 20 | N14: 0 | O14: =SUM(C14:L14,N14) -> 25 | P14: =SUM(C14:N14) -> 45 | R14: 1100-1200 | S14: =SUM(C26:C29) -> 49 | T14: =SUM(D26:D29) -> 2 | U14: =SUM(E26:E29) -> 5 | V14: =SUM(F26:F29) -> 49 | W14: =SUM(G26:G29) -> 0 | X14: =SUM(H26:H29) -> 1 | Y14: =SUM(I26:I29) -> 8 | Z14: =SUM(J26:J29) -> 4 | ... AF14: =SUM(P26:P29) -> 188
B15: 08.15 - 08.30 | C15: 6 | D15: 1 | E15: 1 | F15: 5 | G15: 0 | H15: 0 | I15: 3 | J15: 0 | K15: 1 | L15: 0 | M15: 28 | N15: 0 | O15: =SUM(C15:L15,N15) -> 17 | P15: =SUM(C15:N15) -> 45 | R15: 1200-1300 | S15: =SUM(C30:C33) -> 22 | T15: =SUM(D30:D33) -> 3 | U15: =SUM(E30:E33) -> 0 | V15: =SUM(F30:F33) -> 30 | W15: =SUM(G30:G33) -> 0 | X15: =SUM(H30:H33) -> 3 | Y15: =SUM(I30:I33) -> 6 | Z15: =SUM(J30:J33) -> 0 | ... AF15: =SUM(P30:P33) -> 121
B16: 08.30 - 08.45 | C16: 3 | D16: 2 | E16: 2 | F16: 4 | G16: 0 | H16: 0 | I16: 1 | J16: 4 | K16: 0 | L16: 3 | M16: 23 | N16: 0 | O16: =SUM(C16:L16,N16) -> 19 | P16: =SUM(C16:N16) -> 42 | R16: 1300-1400 | S16: =SUM(C34:C37) -> 43 | T16: =SUM(D34:D37) -> 3 | U16: =SUM(E34:E37) -> 1 | V16: =SUM(F34:F37) -> 10 | W16: =SUM(G34:G37) -> 2 | X16: =SUM(H34:H37) -> 1 | Y16: =SUM(I34:I37) -> 6 | Z16: =SUM(J34:J37) -> 2 | ... AF16: =SUM(P34:P37) -> 113
B17: 08.45 - 9.00 | C17: 16 | D17: 3 | E17: 0 | F17: 12 | G17: 0 | H17: 0 | I17: 3 | J17: 1 | K17: 1 | L17: 0 | M17: 20 | N17: 0 | O17: =SUM(C17:L17,N17) -> 36 | P17: =SUM(C17:N17) -> 56 | R17: 1400-1500 | S17: =SUM(C38:C41) -> 18 | T17: =SUM(D38:D41) -> 8 | U17: =SUM(E38:E41) -> 5 | V17: =SUM(F38:F41) -> 9 | W17: =SUM(G38:G41) -> 0 | X17: =SUM(H38:H41) -> 5 | Y17: =SUM(I38:I41) -> 9 | Z17: =SUM(J38:J41) -> 1 | ... AF17: =SUM(P38:P41) -> 85
B18: 09.00 - 09.15 | C18: 15 | D18: 0 | E18: 1 | F18: 13 | G18: 0 | H18: 2 | I18: 3 | J18: 0 | K18: 0 | L18: 0 | M18: 13 | N18: 0 | O18: =SUM(C18:L18,N18) -> 34 | P18: =SUM(C18:N18) -> 47 | R18: 1500-1600 | S18: =SUM(C42:C45) -> 29 | T18: =SUM(D42:D45) -> 16 | U18: =SUM(E42:E45) -> 0 | V18: =SUM(F42:F45) -> 16 | W18: =SUM(G42:G45) -> 0 | X18: =SUM(H42:H45) -> 0 | Y18: =SUM(I42:I45) -> 5 | Z18: =SUM(J42:J45) -> 1 | ... AF18: =SUM(P42:P45) -> 92
B19: 09.15 - 09.30 | C19: 7 | D19: 0 | E19: 0 | F19: 11 | G19: 0 | H19: 1 | I19: 1 | J19: 2 | K19: 0 | L19: 0 | M19: 29 | N19: 0 | O19: =SUM(C19:L19,N19) -> 22 | P19: =SUM(C19:N19) -> 51 | R19: 1600-1700 | S19: =SUM(C46:C49) -> 26 | T19: =SUM(D46:D49) -> 8 | U19: =SUM(E46:E49) -> 13 | V19: =SUM(F46:F49) -> 28 | W19: =SUM(G46:G49) -> 0 | X19: =SUM(H46:H49) -> 1 | Y19: =SUM(I46:I49) -> 6 | Z19: =SUM(J46:J49) -> 7 | ... AF19: =SUM(P46:P49) -> 158
B20: 09.30 - 09.45 | C20: 10 | D20: 1 | E20: 1 | F20: 12 | G20: 0 | H20: 2 | I20: 3 | J20: 1 | K20: 0 | L20: 3 | M20: 25 | N20: 0 | O20: =SUM(C20:L20,N20) -> 33 | P20: =SUM(C20:N20) -> 58 | R20: 1700-1800 | S20: =SUM(C50:C53) -> 15 | T20: =SUM(D50:D53) -> 7 | U20: =SUM(E50:E53) -> 14 | V20: =SUM(F50:F53) -> 36 | W20: =SUM(G50:G53) -> 1 | X20: =SUM(H50:H53) -> 0 | Y20: =SUM(I50:I53) -> 4 | Z20: =SUM(J50:J53) -> 12 | ... AF20: =SUM(P50:P53) -> 171
B21: 09.45 - 10.00 | C21: 20 | D21: 1 | E21: 1 | F21: 5 | G21: 0 | H21: 1 | I21: 0 | J21: 0 | K21: 6 | L21: 2 | M21: 28 | N21: 0 | O21: =SUM(C21:L21,N21) -> 36 | P21: =SUM(C21:N21) -> 64 | R21: 1800-1900 | S21: =SUM(C54:C57) -> 36 | T21: =SUM(D54:D57) -> 4 | U21: =SUM(E54:E57) -> 3 | V21: =SUM(F54:F57) -> 31 | W21: =SUM(G54:G57) -> 1 | X21: =SUM(H54:H57) -> 1 | Y21: =SUM(I54:I57) -> 3 | Z21: =SUM(J54:J57) -> 4 | ... AF21: =SUM(P54:P57) -> 183
B22: 10.00 - 10.15 | C22: 3 | D22: 0 | E22: 0 | F22: 8 | G22: 0 | H22: 0 | I22: 3 | J22: 2 | K22: 0 | L22: 1 | M22: 25 | N22: 0 | O22: =SUM(C22:L22,N22) -> 17 | P22: =SUM(C22:N22) -> 42 | R22: AM Peak Hr | S22: =MAX(S10:S12) -> 52 | T22: =MAX(T10:T12) -> 7 | U22: =MAX(U10:U12) -> 4 | V22: =MAX(V10:V12) -> 41 | W22: =MAX(W10:W12) -> 1 | X22: =MAX(X10:X12) -> 6 | Y22: =MAX(Y10:Y12) -> 8 | Z22: =MAX(Z10:Z12) -> 6 | ... AF22: =MAX(AF10:AF12) -> 220
B23: 10.15 - 10.30 | C23: 10 | D23: 1 | E23: 1 | F23: 10 | G23: 0 | H23: 1 | I23: 1 | J23: 6 | K23: 1 | L23: 0 | M23: 23 | N23: 0 | O23: =SUM(C23:L23,N23) -> 31 | P23: =SUM(C23:N23) -> 54 | R23: IP Peak Hr | S23: =MAX(S13:S18) -> 49 | T23: =MAX(T13:T18) -> 16 | U23: =MAX(U13:U18) -> 5 | V23: =MAX(V13:V18) -> 49 | W23: =MAX(W13:W18) -> 2 | X23: =MAX(X13:X18) -> 5 | Y23: =MAX(Y13:Y18) -> 9 | Z23: =MAX(Z13:Z18) -> 9 | ... AF23: =MAX(AF13:AF18) -> 188
B24: 10.30 - 10.45 | C24: 6 | D24: 0 | E24: 1 | F24: 5 | G24: 0 | H24: 1 | I24: 0 | J24: 0 | K24: 0 | L24: 0 | M24: 19 | N24: 0 | O24: =SUM(C24:L24,N24) -> 13 | P24: =SUM(C24:N24) -> 32 | R24: PM Peak Hr | S24: =MAX(S19:S21) -> 36 | T24: =MAX(T19:T21) -> 8 | U24: =MAX(U19:U21) -> 14 | V24: =MAX(V19:V21) -> 36 | W24: =MAX(W19:W21) -> 1 | X24: =MAX(X19:X21) -> 1 | Y24: =MAX(Y19:Y21) -> 6 | Z24: =MAX(Z19:Z21) -> 12 | ... AF24: =MAX(AF19:AF21) -> 183
B25: 10.45 - 11.00 | C25: 13 | D25: 2 | E25: 3 | F25: 6 | G25: 0 | H25: 1 | I25: 0 | J25: 1 | K25: 2 | L25: 0 | M25: 11 | N25: 0 | O25: =SUM(C25:L25,N25) -> 28 | P25: =SUM(C25:N25) -> 39 | R25: AM Period | S25: =SUM(S10:S12) -> 111 | T25: =SUM(T10:T12) -> 11 | U25: =SUM(U10:U12) -> 9 | V25: =SUM(V10:V12) -> 98 | W25: =SUM(W10:W12) -> 1 | X25: =SUM(X10:X12) -> 8 | Y25: =SUM(Y10:Y12) -> 22 | Z25: =SUM(Z10:Z12) -> 11 | ... AF25: =SUM(AF10:AF12) -> 535
B26: 11.00 - 11.15 | C26: 16 | D26: 1 | E26: 2 | F26: 13 | G26: 0 | H26: 0 | I26: 2 | J26: 0 | K26: 0 | L26: 0 | M26: 12 | N26: 0 | O26: =SUM(C26:L26,N26) -> 34 | P26: =SUM(C26:N26) -> 46 | R26: IP Period | S26: =SUM(S13:S18) -> 193 | T26: =SUM(T13:T18) -> 35 | U26: =SUM(U13:U18) -> 16 | V26: =SUM(V13:V18) -> 143 | W26: =SUM(W13:W18) -> 2 | X26: =SUM(X13:X18) -> 13 | Y26: =SUM(Y13:Y18) -> 38 | Z26: =SUM(Z13:Z18) -> 17 | ... AF26: =SUM(AF13:AF18) -> 766
B27: 11.15 - 11.30 | C27: 10 | D27: 1 | E27: 0 | F27: 10 | G27: 0 | H27: 1 | I27: 2 | J27: 0 | K27: 0 | L27: 2 | M27: 17 | N27: 0 | O27: =SUM(C27:L27,N27) -> 26 | P27: =SUM(C27:N27) -> 43 | R27: PM Period | S27: =SUM(S19:S21) -> 77 | T27: =SUM(T19:T21) -> 19 | U27: =SUM(U19:U21) -> 30 | V27: =SUM(V19:V21) -> 95 | W27: =SUM(W19:W21) -> 2 | X27: =SUM(X19:X21) -> 2 | Y27: =SUM(Y19:Y21) -> 13 | Z27: =SUM(Z19:Z21) -> 23 | ... AF27: =SUM(AF19:AF21) -> 512
B28: 11.30 - 11.45 | C28: 17 | D28: 0 | E28: 2 | F28: 18 | G28: 0 | H28: 0 | I28: 2 | J28: 0 | K28: 1 | L28: 0 | M28: 23 | N28: 0 | O28: =SUM(C28:L28,N28) -> 40 | P28: =SUM(C28:N28) -> 63 | R28: 12 Hours | S28: =SUM(S10:S21) -> 381 | T28: =SUM(T10:T21) -> 65 | U28: =SUM(U10:U21) -> 55 | V28: =SUM(V10:V21) -> 336 | W28: =SUM(W10:W21) -> 5 | X28: =SUM(X10:X21) -> 23 | Y28: =SUM(Y10:Y21) -> 73 | Z28: =SUM(Z10:Z21) -> 51 | ... AF28: =SUM(AF10:AF21) -> 1813
B29: 11.45 - 12.00 | C29: 6 | D29: 0 | E29: 1 | F29: 8 | G29: 0 | H29: 0 | I29: 2 | J29: 4 | K29: 1 | L29: 0 | M29: 14 | N29: 0 | O29: =SUM(C29:L29,N29) -> 22 | P29: =SUM(C29:N29) -> 36
B30: 12.00 - 12.15 | C30: 8 | D30: 2 | E30: 0 | F30: 7 | G30: 0 | H30: 0 | I30: 3 | J30: 0 | K30: 0 | L30: 0 | M30: 13 | N30: 0 | O30: =SUM(C30:L30,N30) -> 20 | P30: =SUM(C30:N30) -> 33
B31: 12.15 - 12.30 | C31: 4 | D31: 0 | E31: 0 | F31: 9 | G31: 0 | H31: 2 | I31: 3 | J31: 0 | K31: 0 | L31: 0 | M31: 21 | N31: 0 | O31: =SUM(C31:L31,N31) -> 18 | P31: =SUM(C31:N31) -> 39
B32: 12.30 - 12.45 | C32: 3 | D32: 0 | E32: 0 | F32: 5 | G32: 0 | H32: 0 | I32: 0 | J32: 0 | K32: 0 | L32: 0 | M32: 12 | N32: 0 | O32: =SUM(C32:L32,N32) -> 8 | P32: =SUM(C32:N32) -> 20
B33: 12.45 - 13.00 | C33: 7 | D33: 1 | E33: 0 | F33: 9 | G33: 0 | H33: 1 | I33: 0 | J33: 0 | K33: 0 | L33: 2 | M33: 9 | N33: 0 | O33: =SUM(C33:L33,N33) -> 20 | P33: =SUM(C33:N33) -> 29
B34: 13.00 - 13.15 | C34: 7 | D34: 1 | E34: 0 | F34: 2 | G34: 0 | H34: 0 | I34: 6 | J34: 2 | K34: 0 | L34: 0 | M34: 10 | N34: 0 | O34: =SUM(C34:L34,N34) -> 18 | P34: =SUM(C34:N34) -> 28
B35: 13.15 - 13.30 | C35: 11 | D35: 0 | E35: 1 | F35: 2 | G35: 2 | H35: 1 | I35: 0 | J35: 0 | K35: 1 | L35: 0 | M35: 16 | N35: 0 | O35: =SUM(C35:L35,N35) -> 18 | P35: =SUM(C35:N35) -> 34
B36: 13.30 - 13.45 | C36: 10 | D36: 0 | E36: 0 | F36: 6 | G36: 0 | H36: 0 | I36: 0 | J36: 0 | K36: 0 | L36: 0 | M36: 12 | N36: 0 | O36: =SUM(C36:L36,N36) -> 16 | P36: =SUM(C36:N36) -> 28
B37: 13.45 - 14.00 | C37: 15 | D37: 2 | E37: 0 | F37: 0 | G37: 0 | H37: 0 | I37: 0 | J37: 0 | K37: 0 | L37: 0 | M37: 6 | N37: 0 | O37: =SUM(C37:L37,N37) -> 17 | P37: =SUM(C37:N37) -> 23
B38: 14.00 - 14.15 | C38: 3 | D38: 1 | E38: 2 | F38: 1 | G38: 0 | H38: 1 | I38: 2 | J38: 0 | K38: 0 | L38: 0 | M38: 3 | N38: 0 | O38: =SUM(C38:L38,N38) -> 10 | P38: =SUM(C38:N38) -> 13
B39: 14.15 - 14.30 | C39: 9 | D39: 1 | E39: 0 | F39: 3 | G39: 0 | H39: 4 | I39: 3 | J39: 0 | K39: 0 | L39: 4 | M39: 8 | N39: 0 | O39: =SUM(C39:L39,N39) -> 24 | P39: =SUM(C39:N39) -> 32
B40: 14.30 - 14.45 | C40: 4 | D40: 1 | E40: 3 | F40: 2 | G40: 0 | H40: 0 | I40: 2 | J40: 0 | K40: 0 | L40: 7 | M40: 4 | N40: 0 | O40: =SUM(C40:L40,N40) -> 19 | P40: =SUM(C40:N40) -> 23
... B57: 18.45 - 19.00 | C57: 7 | D57: 2 | E57: 0 | F57: 4 | G57: 0 | H57: 0 | I57: 0 | J57: 0 | K57: 6 | L57: 1 | M57: 22 | N57: 0 | O57: =SUM(C57:L57,N57) -> 20 | P57: =SUM(C57:N57) -> 42
B58: Totals | C58: =SUM(C10:C57) -> 381 | D58: =SUM(D10:D57) -> 65 | E58: =SUM(E10:E57) -> 55 | F58: =SUM(F10:F57) -> 336 | G58: =SUM(G10:G57) -> 5 | H58: =SUM(H10:H57) -> 23 | I58: =SUM(I10:I57) -> 73 | J58: =SUM(J10:J57) -> 51 | ... P58: =SUM(P10:P57) -> 1813
...

Sheet 29.10 Mbarara-Kabale
B1: Consultancy services for Preparation of Expressway Development Master Plan (EDMP) for Uganda
B2: MANUAL CLASSIFIED COUNT (MCC)
B3: ROAD NAME: | C3: ='27.10 Mbarara-Kabale'!C3:G3 -> MCC - C4 - STN100 - MBARARA-NTUNGAMO ROAD
C5: Date | D5: 29.10.19 | F5: Location | G5: ='27.10 Mbarara-Kabale'!G5:H5 -> Nyeihanga traffic station | J5: Surveyor | K5: ='27.10 Mbarara-Kabale'!K5:L5 -> Norman
C6: Dir. From | D6: ='27.10 Mbarara-Kabale'!D6:E6 -> Mbarara | F6: Dir. To | G6: ='27.10 Mbarara-Kabale'!G6:H6 -> Kabale | J6: Supervisor | K6: ='27.10 Mbarara-Kabale'!K6:L6 -> Norman R
B8: Time / Veh Type | R8: SUMMARY TRAFFIC VOLUMES
C9: 1. Car | D9: 2. Station Wagon | E9: 3. Pickups | F9: 4. Minibus, matatu | G9: 5. Medium bus | H9: 6. Large Bus | I9: 7. Light Truck | J9: 8. Medium Truck | K9: 9. Heavy truck | L9: 10. Truck Trailer | M9: 11. Motor cycles | N9: 12. Tractors | O9: Total Excl M/Cycles | P9: Total All | R9: Time | S9: 1. Car | T9: 2. Station Wagon | U9: 3. Pickups | V9: 4. Minibus, matatu | W9: 5. Medium bus | X9: 6. Large Bus | Y9: 7. Light Truck | Z9: 8. Medium Truck | AA9: 9. Heavy truck | AB9: 10. Truck Trailer | AC9: 11. Motorcycles | AD9: 12. Tractors, Graders | AE9: Total Excl M/ Cycles | AF9: Total All
B10: 07.00 - 07.15 | C10: 6 | D10: 2 | E10: 4 | F10: 4 | G10: 0 | H10: 0 | I10: 0 | J10: 7 | K10: 3 | L10: 13 | M10: 8 | N10: 0 | O10: =SUM(C10:L10,N10) -> 39 | P10: =SUM(C10:N10) -> 47 | R10: 0700-0800 | S10: =SUM(C10:C13) -> 20 | T10: =SUM(D10:D13) -> 24 | U10: =SUM(E10:E13) -> 18 | V10: =SUM(F10:F13) -> 29 | W10: =SUM(G10:G13) -> 2 | X10: =SUM(H10:H13) -> 4 | Y10: =SUM(I10:I13) -> 6 | Z10: =SUM(J10:J13) -> 14 | ... AF10: =SUM(P10:P13) -> 211
B11: 07.15 - 07.30 | C11: 4 | D11: 11 | E11: 2 | F11: 12 | G11: 0 | H11: 3 | I11: 6 | J11: 3 | K11: 9 | L11: 7 | M11: 11 | N11: 0 | O11: =SUM(C11:L11,N11) -> 57 | P11: =SUM(C11:N11) -> 68 | R11: 0800-0900 | S11: =SUM(C14:C17) -> 34 | T11: =SUM(D14:D17) -> 21 | U11: =SUM(E14:E17) -> 16 | V11: =SUM(F14:F17) -> 22 | W11: =SUM(G14:G17) -> 4 | X11: =SUM(H14:H17) -> 1 | Y11: =SUM(I14:I17) -> 18 | Z11: =SUM(J14:J17) -> 1 | ... AF11: =SUM(P14:P17) -> 214
B12: 07.30 - 07.45 | C12: 8 | D12: 4 | E12: 7 | F12: 9 | G12: 2 | H12: 1 | I12: 0 | J12: 0 | K12: 0 | L12: 3 | M12: 16 | N12: 0 | O12: =SUM(C12:L12,N12) -> 34 | P12: =SUM(C12:N12) -> 50 | R12: 0900-1000 | S12: =SUM(C18:C21) -> 27 | T12: =SUM(D18:D21) -> 11 | U12: =SUM(E18:E21) -> 17 | V12: =SUM(F18:F21) -> 36 | W12: =SUM(G18:G21) -> 0 | X12: =SUM(H18:H21) -> 7 | Y12: =SUM(I18:I21) -> 8 | Z12: =SUM(J18:J21) -> 2 | ... AF12: =SUM(P18:P21) -> 202
B13: 07.45 - 08.00 | C13: 2 | D13: 7 | E13: 5 | F13: 4 | G13: 0 | H13: 0 | I13: 0 | J13: 4 | K13: 3 | L13: 6 | M13: 15 | N13: 0 | O13: =SUM(C13:L13,N13) -> 31 | P13: =SUM(C13:N13) -> 46 | R13: 1000-1100 | S13: =SUM(C22:C25) -> 44 | T13: =SUM(D22:D25) -> 16 | U13: =SUM(E22:E25) -> 5 | V13: =SUM(F22:F25) -> 18 | W13: =SUM(G22:G25) -> 2 | X13: =SUM(H22:H25) -> 4 | Y13: =SUM(I22:I25) -> 5 | Z13: =SUM(J22:J25) -> 3 | ... AF13: =SUM(P22:P25) -> 170
B14: 08.00 - 08.15 | C14: 8 | D14: 4 | E14: 0 | F14: 2 | G14: 0 | H14: 1 | I14: 4 | J14: 0 | K14: 0 | L14: 3 | M14: 15 | N14: 0 | O14: =SUM(C14:L14,N14) -> 22 | P14: =SUM(C14:N14) -> 37 | R14: 1100-1200 | S14: =SUM(C26:C29) -> 21 | T14: =SUM(D26:D29) -> 8 | U14: =SUM(E26:E29) -> 4 | V14: =SUM(F26:F29) -> 19 | W14: =SUM(G26:G29) -> 0 | X14: =SUM(H26:H29) -> 3 | Y14: =SUM(I26:I29) -> 15 | Z14: =SUM(J26:J29) -> 5 | ... AF14: =SUM(P26:P29) -> 140
B15: 08.15 - 08.30 | C15: 13 | D15: 1 | E15: 0 | F15: 9 | G15: 0 | H15: 0 | I15: 4 | J15: 1 | K15: 4 | L15: 0 | M15: 25 | N15: 0 | O15: =SUM(C15:L15,N15) -> 32 | P15: =SUM(C15:N15) -> 57 | R15: 1200-1300 | S15: =SUM(C30:C33) -> 33 | T15: =SUM(D30:D33) -> 18 | U15: =SUM(E30:E33) -> 7 | V15: =SUM(F30:F33) -> 26 | W15: =SUM(G30:G33) -> 0 | X15: =SUM(H30:H33) -> 2 | Y15: =SUM(I30:I33) -> 9 | Z15: =SUM(J30:J33) -> 8 | ... AF15: =SUM(P30:P33) -> 154
B16: 08.30 - 08.45 | C16: 5 | D16: 5 | E16: 3 | F16: 7 | G16: 4 | H16: 0 | I16: 6 | J16: 0 | K16: 0 | L16: 3 | M16: 5 | N16: 1 | O16: =SUM(C16:L16,N16) -> 34 | P16: =SUM(C16:N16) -> 39 | R16: 1300-1400 | S16: =SUM(C34:C37) -> 29 | T16: =SUM(D34:D37) -> 12 | U16: =SUM(E34:E37) -> 9 | V16: =SUM(F34:F37) -> 25 | W16: =SUM(G34:G37) -> 0 | X16: =SUM(H34:H37) -> 2 | Y16: =SUM(I34:I37) -> 8 | Z16: =SUM(J34:J37) -> 2 | ... AF16: =SUM(P34:P37) -> 158
B17: 08.45 - 9.00 | C17: 8 | D17: 11 | E17: 13 | F17: 4 | G17: 0 | H17: 0 | I17: 4 | J17: 0 | K17: 0 | L17: 13 | M17: 25 | N17: 3 | O17: =SUM(C17:L17,N17) -> 56 | P17: =SUM(C17:N17) -> 81 | R17: 1400-1500 | S17: =SUM(C38:C41) -> 24 | T17: =SUM(D38:D41) -> 18 | U17: =SUM(E38:E41) -> 8 | V17: =SUM(F38:F41) -> 23 | W17: =SUM(G38:G41) -> 1 | X17: =SUM(H38:H41) -> 4 | Y17: =SUM(I38:I41) -> 13 | Z17: =SUM(J38:J41) -> 5 | ... AF17: =SUM(P38:P41) -> 172
B18: 09.00 - 09.15 | C18: 10 | D18: 4 | E18: 3 | F18: 19 | G18: 0 | H18: 2 | I18: 4 | J18: 0 | K18: 0 | L18: 19 | M18: 11 | N18: 0 | O18: =SUM(C18:L18,N18) -> 61 | P18: =SUM(C18:N18) -> 72 | R18: 1500-1600 | S18: =SUM(C42:C45) -> 26 | T18: =SUM(D42:D45) -> 11 | U18: =SUM(E42:E45) -> 15 | V18: =SUM(F42:F45) -> 18 | W18: =SUM(G42:G45) -> 0 | X18: =SUM(H42:H45) -> 0 | Y18: =SUM(I42:I45) -> 7 | Z18: =SUM(J42:J45) -> 3 | ... AF18: =SUM(P42:P45) -> 146
B19: 09.15 - 09.30 | C19: 8 | D19: 6 | E19: 14 | F19: 3 | G19: 0 | H19: 0 | I19: 0 | J19: 0 | K19: 0 | L19: 5 | M19: 9 | N19: 0 | O19: =SUM(C19:L19,N19) -> 36 | P19: =SUM(C19:N19) -> 45 | R19: 1600-1700 | S19: =SUM(C46:C49) -> 28 | T19: =SUM(D46:D49) -> 7 | U19: =SUM(E46:E49) -> 8 | V19: =SUM(F46:F49) -> 16 | W19: =SUM(G46:G49) -> 0 | X19: =SUM(H46:H49) -> 0 | Y19: =SUM(I46:I49) -> 10 | Z19: =SUM(J46:J49) -> 3 | ... AF19: =SUM(P46:P49) -> 130
B20: 09.30 - 09.45 | C20: 3 | D20: 0 | E20: 0 | F20: 7 | G20: 0 | H20: 4 | I20: 0 | J20: 0 | K20: 3 | L20: 11 | M20: 16 | N20: 0 | O20: =SUM(C20:L20,N20) -> 28 | P20: =SUM(C20:N20) -> 44 | R20: 1700-1800 | S20: =SUM(C50:C53) -> 16 | T20: =SUM(D50:D53) -> 10 | U20: =SUM(E50:E53) -> 7 | V20: =SUM(F50:F53) -> 11 | W20: =SUM(G50:G53) -> 3 | X20: =SUM(H50:H53) -> 0 | Y20: =SUM(I50:I53) -> 5 | Z20: =SUM(J50:J53) -> 0 | ... AF20: =SUM(P50:P53) -> 117
B21: 09.45 - 10.00 | C21: 6 | D21: 1 | E21: 0 | F21: 7 | G21: 0 | H21: 1 | I21: 4 | J21: 2 | K21: 0 | L21: 0 | M21: 20 | N21: 0 | O21: =SUM(C21:L21,N21) -> 21 | P21: =SUM(C21:N21) -> 41 | R21: 1800-1900 | S21: =SUM(C54:C57) -> 13 | T21: =SUM(D54:D57) -> 4 | U21: =SUM(E54:E57) -> 2 | V21: =SUM(F54:F57) -> 12 | W21: =SUM(G54:G57) -> 2 | X21: =SUM(H54:H57) -> 0 | Y21: =SUM(I54:I57) -> 6 | Z21: =SUM(J54:J57) -> 7 | ... AF21: =SUM(P54:P57) -> 90
B22: 10.00 - 10.15 | C22: 7 | D22: 0 | E22: 1 | F22: 4 | G22: 0 | H22: 0 | I22: 1 | J22: 1 | K22: 4 | L22: 0 | M22: 13 | N22: 0 | O22: =SUM(C22:L22,N22) -> 18 | P22: =SUM(C22:N22) -> 31 | R22: AM Peak Hr | S22: =MAX(S10:S12) -> 34 | T22: =MAX(T10:T12) -> 24 | U22: =MAX(U10:U12) -> 18 | V22: =MAX(V10:V12) -> 36 | W22: =MAX(W10:W12) -> 4 | X22: =MAX(X10:X12) -> 7 | Y22: =MAX(Y10:Y12) -> 18 | Z22: =MAX(Z10:Z12) -> 14 | ... AF22: =MAX(AF10:AF12) -> 214
B23: 10.15 - 10.30 | C23: 18 | D23: 0 | E23: 0 | F23: 0 | G23: 0 | H23: 1 | I23: 0 | J23: 2 | K23: 3 | L23: 0 | M23: 22 | N23: 0 | O23: =SUM(C23:L23,N23) -> 24 | P23: =SUM(C23:N23) -> 46 | R23: IP Peak Hr | S23: =MAX(S13:S18) -> 44 | T23: =MAX(T13:T18) -> 18 | U23: =MAX(U13:U18) -> 15 | V23: =MAX(V13:V18) -> 26 | W23: =MAX(W13:W18) -> 2 | X23: =MAX(X13:X18) -> 4 | Y23: =MAX(Y13:Y18) -> 15 | Z23: =MAX(Z13:Z18) -> 8 | ... AF23: =MAX(AF13:AF18) -> 172
B24: 10.30 - 10.45 | C24: 9 | D24: 11 | E24: 0 | F24: 8 | G24: 2 | H24: 3 | I24: 4 | J24: 0 | K24: 0 | L24: 0 | M24: 8 | N24: 0 | O24: =SUM(C24:L24,N24) -> 37 | P24: =SUM(C24:N24) -> 45 | R24: PM Peak Hr | S24: =MAX(S19:S21) -> 28 | T24: =MAX(T19:T21) -> 10 | U24: =MAX(U19:U21) -> 8 | V24: =MAX(V19:V21) -> 16 | W24: =MAX(W19:W21) -> 3 | X24: =MAX(X19:X21) -> 0 | Y24: =MAX(Y19:Y21) -> 10 | Z24: =MAX(Z19:Z21) -> 7 | ... AF24: =MAX(AF19:AF21) -> 130
B25: 10.45 - 11.00 | C25: 10 | D25: 5 | E25: 4 | F25: 6 | G25: 0 | H25: 0 | I25: 0 | J25: 0 | K25: 2 | L25: 8 | M25: 13 | N25: 0 | O25: =SUM(C25:L25,N25) -> 35 | P25: =SUM(C25:N25) -> 48 | R25: AM Period | S25: =SUM(S10:S12) -> 81 | T25: =SUM(T10:T12) -> 56 | U25: =SUM(U10:U12) -> 51 | V25: =SUM(V10:V12) -> 87 | W25: =SUM(W10:W12) -> 6 | X25: =SUM(X10:X12) -> 12 | Y25: =SUM(Y10:Y12) -> 32 | Z25: =SUM(Z10:Z12) -> 17 | ... AF25: =SUM(AF10:AF12) -> 627
B26: 11.00 - 11.15 | C26: 8 | D26: 2 | E26: 0 | F26: 7 | G26: 0 | H26: 0 | I26: 5 | J26: 0 | K26: 3 | L26: 8 | M26: 15 | N26: 0 | O26: =SUM(C26:L26,N26) -> 33 | P26: =SUM(C26:N26) -> 48 | R26: IP Period | S26: =SUM(S13:S18) -> 177 | T26: =SUM(T13:T18) -> 83 | U26: =SUM(U13:U18) -> 48 | V26: =SUM(V13:V18) -> 129 | W26: =SUM(W13:W18) -> 3 | X26: =SUM(X13:X18) -> 15 | Y26: =SUM(Y13:Y18) -> 57 | Z26: =SUM(Z13:Z18) -> 26 | ... AF26: =SUM(AF13:AF18) -> 940
B27: 11.15 - 11.30 | C27: 4 | D27: 2 | E27: 4 | F27: 6 | G27: 0 | H27: 0 | I27: 2 | J27: 1 | K27: 3 | L27: 2 | M27: 8 | N27: 0 | O27: =SUM(C27:L27,N27) -> 24 | P27: =SUM(C27:N27) -> 32 | R27: PM Period | S27: =SUM(S19:S21) -> 57 | T27: =SUM(T19:T21) -> 21 | U27: =SUM(U19:U21) -> 17 | V27: =SUM(V19:V21) -> 39 | W27: =SUM(W19:W21) -> 5 | X27: =SUM(X19:X21) -> 0 | Y27: =SUM(Y19:Y21) -> 21 | Z27: =SUM(Z19:Z21) -> 10 | ... AF27: =SUM(AF19:AF21) -> 337
B28: 11.30 - 11.45 | C28: 5 | D28: 1 | E28: 0 | F28: 5 | G28: 0 | H28: 3 | I28: 6 | J28: 1 | K28: 3 | L28: 0 | M28: 7 | N28: 0 | O28: =SUM(C28:L28,N28) -> 24 | P28: =SUM(C28:N28) -> 31 | R28: 12 Hours | S28: =SUM(S10:S21) -> 315 | T28: =SUM(T10:T21) -> 160 | U28: =SUM(U10:U21) -> 116 | V28: =SUM(V10:V21) -> 255 | W28: =SUM(W10:W21) -> 14 | X28: =SUM(X10:X21) -> 27 | Y28: =SUM(Y10:Y21) -> 110 | Z28: =SUM(Z10:Z21) -> 53 | ... AF28: =SUM(AF10:AF21) -> 1904
B29: 11.45 - 12.00 | C29: 4 | D29: 3 | E29: 0 | F29: 1 | G29: 0 | H29: 0 | I29: 2 | J29: 3 | K29: 1 | L29: 0 | M29: 15 | N29: 0 | O29: =SUM(C29:L29,N29) -> 14 | P29: =SUM(C29:N29) -> 29
B30: 12.00 - 12.15 | C30: 13 | D30: 1 | E30: 0 | F30: 8 | G30: 0 | H30: 0 | I30: 3 | J30: 0 | K30: 0 | L30: 0 | M30: 12 | N30: 0 | O30: =SUM(C30:L30,N30) -> 25 | P30: =SUM(C30:N30) -> 37
