Workbook

Sheet 23.08 Suam- Bukwo
B1: Consultancy services for Preparation of Expressway Development Master Plan (EDMP) for Uganda
B2: MANUAL CLASSIFIED COUNT (MCC)
B3: ROAD NAME: | C3: MCC-C5-ROAD 144 SUAM-BUKWO
C5: Date | D5: 23.08.19 | F5: Location | G5: KAMKAMBA | J5: Surveyor | K5: Kato
C6: Dir. From | D6: SUAM | F6: Dir. To | G6: BUKWO | J6: Supervisor | K6: IVAN
B8: Time / Veh Type | R8: SUMMARY TRAFFIC VOLUMES
C9: 1. Car | D9: 2. Station Wagon | E9: 3. Pickups | F9: 4. Minibus, matatu | G9: 5. Medium bus | H9: 6. Large Bus | I9: 7. Light Truck | J9: 8. Medium Truck | K9: 9. Heavy truck | L9: 10. Truck Trailer | M9: 11. Motor cycles | N9: 12. Tractors | O9: Total Excl M/Cycles | P9: Total All | R9: Time | S9: 1. Car | T9: 2. Station Wagon | U9: 3. Pickups | V9: 4. Minibus, matatu | W9: 5. Medium bus | X9: 6. Large Bus | Y9: 7. Light Truck | Z9: 8. Medium Truck | AA9: 9. Heavy truck | AB9: 10. Truck Trailer | AC9: 11. Motorcycles | AD9: 12. Tractors, Graders | AE9: Total Excl M/ Cycles | AF9: Total All
B10: 07.00 - 07.15 | C10: 1 | D10: 0 | E10: 0 | F10: 0 | G10: 0 | H10: 0 | I10: 0 | J10: 0 | K10: 0 | L10: 0 | M10: 4 | N10: 0 | O10: =SUM(C10:L10,N10) -> 1 | P10: =SUM(C10:N10) -> 5 | R10: 0700-0800 | S10: =SUM(C10:C13) -> 2 | T10: =SUM(D10:D13) -> 1 | U10: =SUM(E10:E13) -> 2 | V10: =SUM(F10:F13) -> 0 | W10: =SUM(G10:G13) -> 0 | X10: =SUM(H10:H13) -> 0 | Y10: =SUM(I10:I13) -> 0 | Z10: =SUM(J10:J13) -> 0 | ... AF10: =SUM(P10:P13) -> 20
B11: 07.15 - 07.30 | C11: 0 | D11: 0 | E11: 0 | F11: 0 | G11: 0 | H11: 0 | I11: 0 | J11: 0 | K11: 0 | L11: 0 | M11: 1 | N11: 0 | O11: =SUM(C11:L11,N11) -> 0 | P11: =SUM(C11:N11) -> 1 | R11: 0800-0900 | S11: =SUM(C14:C17) -> 0 | T11: =SUM(D14:D17) -> 1 | U11: =SUM(E14:E17) -> 1 | V11: =SUM(F14:F17) -> 0 | W11: =SUM(G14:G17) -> 0 | X11: =SUM(H14:H17) -> 0 | Y11: =SUM(I14:I17) -> 4 | Z11: =SUM(J14:J17) -> 0 | ... AF11: =SUM(P14:P17) -> 31
B12: 07.30 - 07.45 | C12: 0 | D12: 0 | E12: 0 | F12: 0 | G12: 0 | H12: 0 | I12: 0 | J12: 0 | K12: 0 | L12: 0 | M12: 6 | N12: 0 | O12: =SUM(C12:L12,N12) -> 0 | P12: =SUM(C12:N12) -> 6 | R12: 0900-1000 | S12: =SUM(C18:C21) -> 0 | T12: =SUM(D18:D21) -> 0 | U12: =SUM(E18:E21) -> 1 | V12: =SUM(F18:F21) -> 0 | W12: =SUM(G18:G21) -> 0 | X12: =SUM(H18:H21) -> 0 | Y12: =SUM(I18:I21) -> 0 | Z12: =SUM(J18:J21) -> 0 | ... AF12: =SUM(P18:P21) -> 53
B13: 07.45 - 08.00 | C13: 1 | D13: 1 | E13: 2 | F13: 0 | G13: 0 | H13: 0 | I13: 0 | J13: 0 | K13: 0 | L13: 0 | M13: 4 | N13: 0 | O13: =SUM(C13:L13,N13) -> 4 | P13: =SUM(C13:N13) -> 8 | R13: 1000-1100 | S13: =SUM(C22:C25) -> 0 | T13: =SUM(D22:D25) -> 1 | U13: =SUM(E22:E25) -> 1 | V13: =SUM(F22:F25) -> 0 | W13: =SUM(G22:G25) -> 0 | X13: =SUM(H22:H25) -> 0 | Y13: =SUM(I22:I25) -> 1 | Z13: =SUM(J22:J25) -> 0 | ... AF13: =SUM(P22:P25) -> 72
B14: 08.00 - 08.15 | C14: 0 | D14: 0 | E14: 0 | F14: 0 | G14: 0 | H14: 0 | I14: 0 | J14: 0 | K14: 0 | L14: 0 | M14: 3 | N14: 0 | O14: =SUM(C14:L14,N14) -> 0 | P14: =SUM(C14:N14) -> 3 | R14: 1100-1200 | S14: =SUM(C26:C29) -> 0 | T14: =SUM(D26:D29) -> 0 | U14: =SUM(E26:E29) -> 2 | V14: =SUM(F26:F29) -> 0 | W14: =SUM(G26:G29) -> 0 | X14: =SUM(H26:H29) -> 0 | Y14: =SUM(I26:I29) -> 4 | Z14: =SUM(J26:J29) -> 0 | ... AF14: =SUM(P26:P29) -> 73
B15: 08.15 - 08.30 | C15: 0 | D15: 0 | E15: 0 | F15: 0 | G15: 0 | H15: 0 | I15: 0 | J15: 0 | K15: 0 | L15: 0 | M15: 5 | N15: 0 | O15: =SUM(C15:L15,N15) -> 0 | P15: =SUM(C15:N15) -> 5 | R15: 1200-1300 | S15: =SUM(C30:C33) -> 0 | T15: =SUM(D30:D33) -> 0 | U15: =SUM(E30:E33) -> 1 | V15: =SUM(F30:F33) -> 0 | W15: =SUM(G30:G33) -> 0 | X15: =SUM(H30:H33) -> 0 | Y15: =SUM(I30:I33) -> 4 | Z15: =SUM(J30:J33) -> 0 | ... AF15: =SUM(P30:P33) -> 66
B16: 08.30 - 08.45 | C16: 0 | D16: 1 | E16: 0 | F16: 0 | G16: 0 | H16: 0 | I16: 3 | J16: 0 | K16: 0 | L16: 0 | M16: 9 | N16: 0 | O16: =SUM(C16:L16,N16) -> 4 | P16: =SUM(C16:N16) -> 13 | R16: 1300-1400 | S16: =SUM(C34:C37) -> 0 | T16: =SUM(D34:D37) -> 0 | U16: =SUM(E34:E37) -> 0 | V16: =SUM(F34:F37) -> 0 | W16: =SUM(G34:G37) -> 0 | X16: =SUM(H34:H37) -> 0 | Y16: =SUM(I34:I37) -> 3 | Z16: =SUM(J34:J37) -> 1 | ... AF16: =SUM(P34:P37) -> 70
B17: 08.45 - 9.00 | C17: 0 | D17: 0 | E17: 1 | F17: 0 | G17: 0 | H17: 0 | I17: 1 | J17: 0 | K17: 0 | L17: 0 | M17: 8 | N17: 0 | O17: =SUM(C17:L17,N17) -> 2 | P17: =SUM(C17:N17) -> 10 | R17: 1400-1500 | S17: =SUM(C38:C41) -> 0 | T17: =SUM(D38:D41) -> 3 | U17: =SUM(E38:E41) -> 1 | V17: =SUM(F38:F41) -> 0 | W17: =SUM(G38:G41) -> 0 | X17: =SUM(H38:H41) -> 0 | Y17: =SUM(I38:I41) -> 0 | Z17: =SUM(J38:J41) -> 0 | ... AF17: =SUM(P38:P41) -> 61
B18: 09.00 - 09.15 | C18: 0 | D18: 0 | E18: 1 | F18: 0 | G18: 0 | H18: 0 | I18: 0 | J18: 0 | K18: 0 | L18: 0 | M18: 12 | N18: 0 | O18: =SUM(C18:L18,N18) -> 1 | P18: =SUM(C18:N18) -> 13 | R18: 1500-1600 | S18: =SUM(C42:C45) -> 0 | T18: =SUM(D42:D45) -> 1 | U18: =SUM(E42:E45) -> 0 | V18: =SUM(F42:F45) -> 0 | W18: =SUM(G42:G45) -> 0 | X18: =SUM(H42:H45) -> 0 | Y18: =SUM(I42:I45) -> 2 | Z18: =SUM(J42:J45) -> 0 | ... AF18: =SUM(P42:P45) -> 41
B19: 09.15 - 09.30 | C19: 0 | D19: 0 | E19: 0 | F19: 0 | G19: 0 | H19: 0 | I19: 0 | J19: 0 | K19: 0 | L19: 0 | M19: 13 | N19: 0 | O19: =SUM(C19:L19,N19) -> 0 | P19: =SUM(C19:N19) -> 13 | R19: 1600-1700 | S19: =SUM(C46:C49) -> 0 | T19: =SUM(D46:D49) -> 0 | U19: =SUM(E46:E49) -> 0 | V19: =SUM(F46:F49) -> 0 | W19: =SUM(G46:G49) -> 0 | X19: =SUM(H46:H49) -> 0 | Y19: =SUM(I46:I49) -> 0 | Z19: =SUM(J46:J49) -> 0 | ... AF19: =SUM(P46:P49) -> 41
B20: 09.30 - 09.45 | C20: 0 | D20: 0 | E20: 0 | F20: 0 | G20: 0 | H20: 0 | I20: 0 | J20: 0 | K20: 0 | L20: 0 | M20: 10 | N20: 0 | O20: =SUM(C20:L20,N20) -> 0 | P20: =SUM(C20:N20) -> 10 | R20: 1700-1800 | S20: =SUM(C50:C53) -> 0 | T20: =SUM(D50:D53) -> 0 | U20: =SUM(E50:E53) -> 2 | V20: =SUM(F50:F53) -> 0 | W20: =SUM(G50:G53) -> 0 | X20: =SUM(H50:H53) -> 0 | Y20: =SUM(I50:I53) -> 0 | Z20: =SUM(J50:J53) -> 0 | ... AF20: =SUM(P50:P53) -> 54
B21: 09.45 - 10.00 | C21: 0 | D21: 0 | E21: 0 | F21: 0 | G21: 0 | H21: 0 | I21: 0 | J21: 0 | K21: 0 | L21: 0 | M21: 17 | N21: 0 | O21: =SUM(C21:L21,N21) -> 0 | P21: =SUM(C21:N21) -> 17 | R21: 1800-1900 | S21: =SUM(C54:C57) -> 1 | T21: =SUM(D54:D57) -> 0 | U21: =SUM(E54:E57) -> 2 | V21: =SUM(F54:F57) -> 0 | W21: =SUM(G54:G57) -> 0 | X21: =SUM(H54:H57) -> 0 | Y21: =SUM(I54:I57) -> 2 | Z21: =SUM(J54:J57) -> 0 | ... AF21: =SUM(P54:P57) -> 37
B22: 10.00 - 10.15 | C22: 0 | D22: 0 | E22: 1 | F22: 0 | G22: 0 | H22: 0 | I22: 0 | J22: 0 | K22: 0 | L22: 0 | M22: 20 | N22: 0 | O22: =SUM(C22:L22,N22) -> 1 | P22: =SUM(C22:N22) -> 21 | R22: AM Peak Hr | S22: =MAX(S10:S12) -> 2 | T22: =MAX(T10:T12) -> 1 | U22: =MAX(U10:U12) -> 2 | V22: =MAX(V10:V12) -> 0 | W22: =MAX(W10:W12) -> 0 | X22: =MAX(X10:X12) -> 0 | Y22: =MAX(Y10:Y12) -> 4 | Z22: =MAX(Z10:Z12) -> 0 | ... AF22: =MAX(AF10:AF12) -> 53
B23: 10.15 - 10.30 | C23: 0 | D23: 0 | E23: 0 | F23: 0 | G23: 0 | H23: 0 | I23: 1 | J23: 0 | K23: 0 | L23: 0 | M23: 15 | N23: 0 | O23: =SUM(C23:L23,N23) -> 1 | P23: =SUM(C23:N23) -> 16 | R23: IP Peak Hr | S23: =MAX(S13:S18) -> 0 | T23: =MAX(T13:T18) -> 3 | U23: =MAX(U13:U18) -> 2 | V23: =MAX(V13:V18) -> 0 | W23: =MAX(W13:W18) -> 0 | X23: =MAX(X13:X18) -> 0 | Y23: =MAX(Y13:Y18) -> 4 | Z23: =MAX(Z13:Z18) -> 1 | ... AF23: =MAX(AF13:AF18) -> 73
B24: 10.30 - 10.45 | C24: 0 | D24: 1 | E24: 0 | F24: 0 | G24: 0 | H24: 0 | I24: 0 | J24: 0 | K24: 0 | L24: 0 | M24: 12 | N24: 0 | O24: =SUM(C24:L24,N24) -> 1 | P24: =SUM(C24:N24) -> 13 | R24: PM Peak Hr | S24: =MAX(S19:S21) -> 1 | T24: =MAX(T19:T21) -> 0 | U24: =MAX(U19:U21) -> 2 | V24: =MAX(V19:V21) -> 0 | W24: =MAX(W19:W21) -> 0 | X24: =MAX(X19:X21) -> 0 | Y24: =MAX(Y19:Y21) -> 2 | Z24: =MAX(Z19:Z21) -> 0 | ... AF24: =MAX(AF19:AF21) -> 54
B25: 10.45 - 11.00 | C25: 0 | D25: 0 | E25: 0 | F25: 0 | G25: 0 | H25: 0 | I25: 0 | J25: 0 | K25: 0 | L25: 0 | M25: 22 | N25: 0 | O25: =SUM(C25:L25,N25) -> 0 | P25: =SUM(C25:N25) -> 22 | R25: AM Period | S25: =SUM(S10:S12) -> 2 | T25: =SUM(T10:T12) -> 2 | U25: =SUM(U10:U12) -> 4 | V25: =SUM(V10:V12) -> 0 | W25: =SUM(W10:W12) -> 0 | X25: =SUM(X10:X12) -> 0 | Y25: =SUM(Y10:Y12) -> 4 | Z25: =SUM(Z10:Z12) -> 0 | ... AF25: =SUM(AF10:AF12) -> 104
B26: 11.00 - 11.15 | C26: 0 | D26: 0 | E26: 1 | F26: 0 | G26: 0 | H26: 0 | I26: 1 | J26: 0 | K26: 0 | L26: 0 | M26: 19 | N26: 0 | O26: =SUM(C26:L26,N26) -> 2 | P26: =SUM(C26:N26) -> 21 | R26: IP Period | S26: =SUM(S13:S18) -> 0 | T26: =SUM(T13:T18) -> 5 | U26: =SUM(U13:U18) -> 5 | V26: =SUM(V13:V18) -> 0 | W26: =SUM(W13:W18) -> 0 | X26: =SUM(X13:X18) -> 0 | Y26: =SUM(Y13:Y18) -> 14 | Z26: =SUM(Z13:Z18) -> 1 | ... AF26: =SUM(AF13:AF18) -> 383
B27: 11.15 - 11.30 | C27: 0 | D27: 0 | E27: 0 | F27: 0 | G27: 0 | H27: 0 | I27: 0 | J27: 0 | K27: 0 | L27: 0 | M27: 21 | N27: 0 | O27: =SUM(C27:L27,N27) -> 0 | P27: =SUM(C27:N27) -> 21 | R27: PM Period | S27: =SUM(S19:S21) -> 1 | T27: =SUM(T19:T21) -> 0 | U27: =SUM(U19:U21) -> 4 | V27: =SUM(V19:V21) -> 0 | W27: =SUM(W19:W21) -> 0 | X27: =SUM(X19:X21) -> 0 | Y27: =SUM(Y19:Y21) -> 2 | Z27: =SUM(Z19:Z21) -> 0 | ... AF27: =SUM(AF19:AF21) -> 132
B28: 11.30 - 11.45 | C28: 0 | D28: 0 | E28: 0 | F28: 0 | G28: 0 | H28: 0 | I28: 0 | J28: 0 | K28: 0 | L28: 0 | M28: 14 | N28: 0 | O28: =SUM(C28:L28,N28) -> 0 | P28: =SUM(C28:N28) -> 14 | R28: 12 Hours | S28: =SUM(S10:S21) -> 3 | T28: =SUM(T10:T21) -> 7 | U28: =SUM(U10:U21) -> 13 | V28: =SUM(V10:V21) -> 0 | W28: =SUM(W10:W21) -> 0 | X28: =SUM(X10:X21) -> 0 | Y28: =SUM(Y10:Y21) -> 20 | Z28: =SUM(Z10:Z21) -> 1 | ... AF28: =SUM(AF10:AF21) -> 619
B29: 11.45 - 12.00 | C29: 0 | D29: 0 | E29: 1 | F29: 0 | G29: 0 | H29: 0 | I29: 3 | J29: 0 | K29: 0 | L29: 0 | M29: 13 | N29: 0 | O29: =SUM(C29:L29,N29) -> 4 | P29: =SUM(C29:N29) -> 17
B30: 12.00 - 12.15 | C30: 0 | D30: 0 | E30: 1 | F30: 0 | G30: 0 | H30: 0 | I30: 2 | J30: 0 | K30: 0 | L30: 0 | M30: 15 | N30: 0 | O30: =SUM(C30:L30,N30) -> 3 | P30: =SUM(C30:N30) -> 18
B31: 12.15 - 12.30 | C31: 0 | D31: 0 | E31: 0 | F31: 0 | G31: 0 | H31: 0 | I31: 0 | J31: 0 | K31: 0 | L31: 0 | M31: 15 | N31: 0 | O31: =SUM(C31:L31,N31) -> 0 | P31: =SUM(C31:N31) -> 15
B32: 12.30 - 12.45 | C32: 0 | D32: 0 | E32: 0 | F32: 0 | G32: 0 | H32: 0 | I32: 2 | J32: 0 | K32: 0 | L32: 0 | M32: 15 | N32: 0 | O32: =SUM(C32:L32,N32) -> 2 | P32: =SUM(C32:N32) -> 17
B33: 12.45 - 13.00 | C33: 0 | D33: 0 | E33: 0 | F33: 0 | G33: 0 | H33: 0 | I33: 0 | J33: 0 | K33: 0 | L33: 0 | M33: 16 | N33: 0 | O33: =SUM(C33:L33,N33) -> 0 | P33: =SUM(C33:N33) -> 16
B34: 13.00 - 13.15 | C34: 0 | D34: 0 | E34: 0 | F34: 0 | G34: 0 | H34: 0 | I34: 2 | J34: 1 | K34: 0 | L34: 0 | M34: 15 | N34: 0 | O34: =SUM(C34:L34,N34) -> 3 | P34: =SUM(C34:N34) -> 18
B35: 13.15 - 13.30 | C35: 0 | D35: 0 | E35: 0 | F35: 0 | G35: 0 | H35: 0 | I35: 0 | J35: 0 | K35: 0 | L35: 0 | M35: 21 | N35: 0 | O35: =SUM(C35:L35,N35) -> 0 | P35: =SUM(C35:N35) -> 21
B36: 13.30 - 13.45 | C36: 0 | D36: 0 | E36: 0 | F36: 0 | G36: 0 | H36: 0 | I36: 1 | J36: 0 | K36: 0 | L36: 0 | M36: 17 | N36: 0 | O36: =SUM(C36:L36,N36) -> 1 | P36: =SUM(C36:N36) -> 18
B37: 13.45 - 14.00 | C37: 0 | D37: 0 | E37: 0 | F37: 0 | G37: 0 | H37: 0 | I37: 0 | J37: 0 | K37: 0 | L37: 0 | M37: 13 | N37: 0 | O37: =SUM(C37:L37,N37) -> 0 | P37: =SUM(C37:N37) -> 13
B38: 14.00 - 14.15 | C38: 0 | D38: 2 | E38: 1 | F38: 0 | G38: 0 | H38: 0 | I38: 0 | J38: 0 | K38: 0 | L38: 0 | M38: 18 | N38: 0 | O38: =SUM(C38:L38,N38) -> 3 | P38: =SUM(C38:N38) -> 21
B39: 14.15 - 14.30 | C39: 0 | D39: 0 | E39: 0 | F39: 0 | G39: 0 | H39: 0 | I39: 0 | J39: 0 | K39: 0 | L39: 0 | M39: 10 | N39: 0 | O39: =SUM(C39:L39,N39) -> 0 | P39: =SUM(C39:N39) -> 10
B40: 14.30 - 14.45 | C40: 0 | D40: 1 | E40: 0 | F40: 0 | G40: 0 | H40: 0 | I40: 0 | J40: 0 | K40: 0 | L40: 0 | M40: 10 | N40: 0 | O40: =SUM(C40:L40,N40) -> 1 | P40: =SUM(C40:N40) -> 11
... B57: 18.45 - 19.00 | C57: 1 | D57: 0 | E57: 1 | F57: 0 | G57: 0 | H57: 0 | I57: 2 | J57: 0 | K57: 0 | L57: 0 | M57: 6 | N57: 0 | O57: =SUM(C57:L57,N57) -> 4 | P57: =SUM(C57:N57) -> 10
B58: Totals | C58: =SUM(C10:C57) -> 3 | D58: =SUM(D10:D57) -> 7 | E58: =SUM(E10:E57) -> 13 | F58: =SUM(F10:F57) -> 0 | G58: =SUM(G10:G57) -> 0 | H58: =SUM(H10:H57) -> 0 | I58: =SUM(I10:I57) -> 20 | J58: =SUM(J10:J57) -> 1 | ... P58: =SUM(P10:P57) -> 619
...

Sheet 23.08 Bukwo-Suam
B1: Consultancy services for Preparation of Expressway Development Master Plan (EDMP) for Uganda
B2: MANUAL CLASSIFIED COUNT (MCC)
B3: ROAD NAME: | C3: MCC-C5-STN144-SUAM-BUKWO
C5: Date | D5: ='23.08 Suam- Bukwo'!D5 -> 23.08.19 | F5: Location | G5: ='23.08 Suam- Bukwo'!G5:H5 -> KAMKAMBA | J5: Surveyor | K5: NORMAN
C6: Dir. From | D6: BUKWO | F6: Dir. To | G6: SUAM | J6: Supervisor | K6: ='23.08 Suam- Bukwo'!K6:L6 -> IVAN
B8: Time / Veh Type | R8: SUMMARY TRAFFIC VOLUMES
C9: 1. Car | D9: 2. Station Wagon | E9: 3. Pickups | F9: 4. Minibus, matatu | G9: 5. Medium bus | H9: 6. Large Bus | I9: 7. Light Truck | J9: 8. Medium Truck | K9: 9. Heavy truck | L9: 10. Truck Trailer | M9: 11. Motor cycles | N9: 12. Tractors | O9: Total Excl M/Cycles | P9: Total All | R9: Time | S9: 1. Car | T9: 2. Station Wagon | U9: 3. Pickups | V9: 4. Minibus, matatu | W9: 5. Medium bus | X9: 6. Large Bus | Y9: 7. Light Truck | Z9: 8. Medium Truck | AA9: 9. Heavy truck | AB9: 10. Truck Trailer | AC9: 11. Motorcycles | AD9: 12. Tractors, Graders | AE9: Total Excl M/ Cycles | AF9: Total All
B10: 07.00 - 07.15 | C10: 0 | D10: 1 | E10: 0 | F10: 0 | G10: 0 | H10: 0 | I10: 0 | J10: 0 | K10: 0 | L10: 0 | M10: 7 | N10: 0 | O10: =SUM(C10:L10,N10) -> 1 | P10: =SUM(C10:N10) -> 8 | R10: 0700-0800 | S10: =SUM(C10:C13) -> 0 | T10: =SUM(D10:D13) -> 1 | U10: =SUM(E10:E13) -> 1 | V10: =SUM(F10:F13) -> 0 | W10: =SUM(G10:G13) -> 0 | X10: =SUM(H10:H13) -> 0 | Y10: =SUM(I10:I13) -> 0 | Z10: =SUM(J10:J13) -> 0 | ... AF10: =SUM(P10:P13) -> 21
B11: 07.15 - 07.30 | C11: 0 | D11: 0 | E11: 0 | F11: 0 | G11: 0 | H11: 0 | I11: 0 | J11: 0 | K11: 0 | L11: 0 | M11: 2 | N11: 0 | O11: =SUM(C11:L11,N11) -> 0 | P11: =SUM(C11:N11) -> 2 | R11: 0800-0900 | S11: =SUM(C14:C17) -> 0 | T11: =SUM(D14:D17) -> 1 | U11: =SUM(E14:E17) -> 0 | V11: =SUM(F14:F17) -> 0 | W11: =SUM(G14:G17) -> 0 | X11: =SUM(H14:H17) -> 0 | Y11: =SUM(I14:I17) -> 0 | Z11: =SUM(J14:J17) -> 0 | ... AF11: =SUM(P14:P17) -> 19
B12: 07.30 - 07.45 | C12: 0 | D12: 0 | E12: 0 | F12: 0 | G12: 0 | H12: 0 | I12: 0 | J12: 0 | K12: 0 | L12: 0 | M12: 6 | N12: 0 | O12: =SUM(C12:L12,N12) -> 0 | P12: =SUM(C12:N12) -> 6 | R12: 0900-1000 | S12: =SUM(C18:C21) -> 0 | T12: =SUM(D18:D21) -> 0 | U12: =SUM(E18:E21) -> 0 | V12: =SUM(F18:F21) -> 0 | W12: =SUM(G18:G21) -> 0 | X12: =SUM(H18:H21) -> 0 | Y12: =SUM(I18:I21) -> 1 | Z12: =SUM(J18:J21) -> 0 | ... AF12: =SUM(P18:P21) -> 23
B13: 07.45 - 08.00 | C13: 0 | D13: 0 | E13: 1 | F13: 0 | G13: 0 | H13: 0 | I13: 0 | J13: 0 | K13: 0 | L13: 0 | M13: 4 | N13: 0 | O13: =SUM(C13:L13,N13) -> 1 | P13: =SUM(C13:N13) -> 5 | R13: 1000-1100 | S13: =SUM(C22:C25) -> 0 | T13: =SUM(D22:D25) -> 0 | U13: =SUM(E22:E25) -> 1 | V13: =SUM(F22:F25) -> 0 | W13: =SUM(G22:G25) -> 0 | X13: =SUM(H22:H25) -> 0 | Y13: =SUM(I22:I25) -> 1 | Z13: =SUM(J22:J25) -> 0 | ... AF13: =SUM(P22:P25) -> 25
B14: 08.00 - 08.15 | C14: 0 | D14: 0 | E14: 0 | F14: 0 | G14: 0 | H14: 0 | I14: 0 | J14: 0 | K14: 0 | L14: 0 | M14: 5 | N14: 0 | O14: =SUM(C14:L14,N14) -> 0 | P14: =SUM(C14:N14) -> 5 | R14: 1100-1200 | S14: =SUM(C26:C29) -> 1 | T14: =SUM(D26:D29) -> 0 | U14: =SUM(E26:E29) -> 1 | V14: =SUM(F26:F29) -> 0 | W14: =SUM(G26:G29) -> 0 | X14: =SUM(H26:H29) -> 0 | Y14: =SUM(I26:I29) -> 5 | Z14: =SUM(J26:J29) -> 0 | ... AF14: =SUM(P26:P29) -> 52
B15: 08.15 - 08.30 | C15: 0 | D15: 1 | E15: 0 | F15: 0 | G15: 0 | H15: 0 | I15: 0 | J15: 0 | K15: 0 | L15: 0 | M15: 8 | N15: 0 | O15: =SUM(C15:L15,N15) -> 1 | P15: =SUM(C15:N15) -> 9 | R15: 1200-1300 | S15: =SUM(C30:C33) -> 0 | T15: =SUM(D30:D33) -> 0 | U15: =SUM(E30:E33) -> 0 | V15: =SUM(F30:F33) -> 0 | W15: =SUM(G30:G33) -> 0 | X15: =SUM(H30:H33) -> 0 | Y15: =SUM(I30:I33) -> 2 | Z15: =SUM(J30:J33) -> 0 | ... AF15: =SUM(P30:P33) -> 33
B16: 08.30 - 08.45 | C16: 0 | D16: 0 | E16: 0 | F16: 0 | G16: 0 | H16: 0 | I16: 0 | J16: 0 | K16: 0 | L16: 0 | M16: 4 | N16: 0 | O16: =SUM(C16:L16,N16) -> 0 | P16: =SUM(C16:N16) -> 4 | R16: 1300-1400 | S16: =SUM(C34:C37) -> 3 | T16: =SUM(D34:D37) -> 0 | U16: =SUM(E34:E37) -> 0 | V16: =SUM(F34:F37) -> 0 | W16: =SUM(G34:G37) -> 0 | X16: =SUM(H34:H37) -> 0 | Y16: =SUM(I34:I37) -> 3 | Z16: =SUM(J34:J37) -> 0 | ... AF16: =SUM(P34:P37) -> 60
B17: 08.45 - 9.00 | C17: 0 | D17: 0 | E17: 0 | F17: 0 | G17: 0 | H17: 0 | I17: 0 | J17: 0 | K17: 0 | L17: 0 | M17: 1 | N17: 0 | O17: =SUM(C17:L17,N17) -> 0 | P17: =SUM(C17:N17) -> 1 | R17: 1400-1500 | S17: =SUM(C38:C41) -> 0 | T17: =SUM(D38:D41) -> 0 | U17: =SUM(E38:E41) -> 0 | V17: =SUM(F38:F41) -> 0 | W17: =SUM(G38:G41) -> 0 | X17: =SUM(H38:H41) -> 0 | Y17: =SUM(I38:I41) -> 1 | Z17: =SUM(J38:J41) -> 0 | ... AF17: =SUM(P38:P41) -> 35
B18: 09.00 - 09.15 | C18: 0 | D18: 0 | E18: 0 | F18: 0 | G18: 0 | H18: 0 | I18: 1 | J18: 0 | K18: 0 | L18: 0 | M18: 5 | N18: 0 | O18: =SUM(C18:L18,N18) -> 1 | P18: =SUM(C18:N18) -> 6 | R18: 1500-1600 | S18: =SUM(C42:C45) -> 0 | T18: =SUM(D42:D45) -> 1 | U18: =SUM(E42:E45) -> 2 | V18: =SUM(F42:F45) -> 0 | W18: =SUM(G42:G45) -> 0 | X18: =SUM(H42:H45) -> 0 | Y18: =SUM(I42:I45) -> 0 | Z18: =SUM(J42:J45) -> 0 | ... AF18: =SUM(P42:P45) -> 46
B19: 09.15 - 09.30 | C19: 0 | D19: 0 | E19: 0 | F19: 0 | G19: 0 | H19: 0 | I19: 0 | J19: 0 | K19: 0 | L19: 0 | M19: 4 | N19: 0 | O19: =SUM(C19:L19,N19) -> 0 | P19: =SUM(C19:N19) -> 4 | R19: 1600-1700 | S19: =SUM(C46:C49) -> 0 | T19: =SUM(D46:D49) -> 0 | U19: =SUM(E46:E49) -> 2 | V19: =SUM(F46:F49) -> 0 | W19: =SUM(G46:G49) -> 0 | X19: =SUM(H46:H49) -> 0 | Y19: =SUM(I46:I49) -> 2 | Z19: =SUM(J46:J49) -> 0 | ... AF19: =SUM(P46:P49) -> 43
B20: 09.30 - 09.45 | C20: 0 | D20: 0 | E20: 0 | F20: 0 | G20: 0 | H20: 0 | I20: 0 | J20: 0 | K20: 0 | L20: 0 | M20: 5 | N20: 0 | O20: =SUM(C20:L20,N20) -> 0 | P20: =SUM(C20:N20) -> 5 | R20: 1700-1800 | S20: =SUM(C50:C53) -> 0 | T20: =SUM(D50:D53) -> 0 | U20: =SUM(E50:E53) -> 0 | V20: =SUM(F50:F53) -> 0 | W20: =SUM(G50:G53) -> 0 | X20: =SUM(H50:H53) -> 0 | Y20: =SUM(I50:I53) -> 0 | Z20: =SUM(J50:J53) -> 0 | ... AF20: =SUM(P50:P53) -> 33
B21: 09.45 - 10.00 | C21: 0 | D21: 0 | E21: 0 | F21: 0 | G21: 0 | H21: 0 | I21: 0 | J21: 0 | K21: 0 | L21: 0 | M21: 8 | N21: 0 | O21: =SUM(C21:L21,N21) -> 0 | P21: =SUM(C21:N21) -> 8 | R21: 1800-1900 | S21: =SUM(C54:C57) -> 1 | T21: =SUM(D54:D57) -> 0 | U21: =SUM(E54:E57) -> 2 | V21: =SUM(F54:F57) -> 0 | W21: =SUM(G54:G57) -> 0 | X21: =SUM(H54:H57) -> 0 | Y21: =SUM(I54:I57) -> 1 | Z21: =SUM(J54:J57) -> 0 | ... AF21: =SUM(P54:P57) -> 43
B22: 10.00 - 10.15 | C22: 0 | D22: 0 | E22: 0 | F22: 0 | G22: 0 | H22: 0 | I22: 0 | J22: 0 | K22: 0 | L22: 0 | M22: 5 | N22: 0 | O22: =SUM(C22:L22,N22) -> 0 | P22: =SUM(C22:N22) -> 5 | R22: AM Peak Hr | S22: =MAX(S10:S12) -> 0 | T22: =MAX(T10:T12) -> 1 | U22: =MAX(U10:U12) -> 1 | V22: =MAX(V10:V12) -> 0 | W22: =MAX(W10:W12) -> 0 | X22: =MAX(X10:X12) -> 0 | Y22: =MAX(Y10:Y12) -> 1 | Z22: =MAX(Z10:Z12) -> 0 | ... AF22: =MAX(AF10:AF12) -> 23
B23: 10.15 - 10.30 | C23: 0 | D23: 0 | E23: 1 | F23: 0 | G23: 0 | H23: 0 | I23: 1 | J23: 0 | K23: 0 | L23: 0 | M23: 4 | N23: 0 | O23: =SUM(C23:L23,N23) -> 2 | P23: =SUM(C23:N23) -> 6 | R23: IP Peak Hr | S23: =MAX(S13:S18) -> 3 | T23: =MAX(T13:T18) -> 1 | U23: =MAX(U13:U18) -> 2 | V23: =MAX(V13:V18) -> 0 | W23: =MAX(W13:W18) -> 0 | X23: =MAX(X13:X18) -> 0 | Y23: =MAX(Y13:Y18) -> 5 | Z23: =MAX(Z13:Z18) -> 0 | ... AF23: =MAX(AF13:AF18) -> 60
B24: 10.30 - 10.45 | C24: 0 | D24: 0 | E24: 0 | F24: 0 | G24: 0 | H24: 0 | I24: 0 | J24: 0 | K24: 0 | L24: 0 | M24: 6 | N24: 0 | O24: =SUM(C24:L24,N24) -> 0 | P24: =SUM(C24:N24) -> 6 | R24: PM Peak Hr | S24: =MAX(S19:S21) -> 1 | T24: =MAX(T19:T21) -> 0 | U24: =MAX(U19:U21) -> 2 | V24: =MAX(V19:V21) -> 0 | W24: =MAX(W19:W21) -> 0 | X24: =MAX(X19:X21) -> 0 | Y24: =MAX(Y19:Y21) -> 2 | Z24: =MAX(Z19:Z21) -> 0 | ... AF24: =MAX(AF19:AF21) -> 43
B25: 10.45 - 11.00 | C25: 0 | D25: 0 | E25: 0 | F25: 0 | G25: 0 | H25: 0 | I25: 0 | J25: 0 | K25: 0 | L25: 0 | M25: 8 | N25: 0 | O25: =SUM(C25:L25,N25) -> 0 | P25: =SUM(C25:N25) -> 8 | R25: AM Period | S25: =SUM(S10:S12) -> 0 | T25: =SUM(T10:T12) -> 2 | U25: =SUM(U10:U12) -> 1 | V25: =SUM(V10:V12) -> 0 | W25: =SUM(W10:W12) -> 0 | X25: =SUM(X10:X12) -> 0 | Y25: =SUM(Y10:Y12) -> 1 | Z25: =SUM(Z10:Z12) -> 0 | ... AF25: =SUM(AF10:AF12) -> 63
B26: 11.00 - 11.15 | C26: 0 | D26: 0 | E26: 0 | F26: 0 | G26: 0 | H26: 0 | I26: 0 | J26: 0 | K26: 0 | L26: 0 | M26: 9 | N26: 0 | O26: =SUM(C26:L26,N26) -> 0 | P26: =SUM(C26:N26) -> 9 | R26: IP Period | S26: =SUM(S13:S18) -> 4 | T26: =SUM(T13:T18) -> 1 | U26: =SUM(U13:U18) -> 4 | V26: =SUM(V13:V18) -> 0 | W26: =SUM(W13:W18) -> 0 | X26: =SUM(X13:X18) -> 0 | Y26: =SUM(Y13:Y18) -> 12 | Z26: =SUM(Z13:Z18) -> 0 | ... AF26: =SUM(AF13:AF18) -> 251
B27: 11.15 - 11.30 | C27: 1 | D27: 0 | E27: 0 | F27: 0 | G27: 0 | H27: 0 | I27: 1 | J27: 0 | K27: 0 | L27: 0 | M27: 18 | N27: 0 | O27: =SUM(C27:L27,N27) -> 2 | P27: =SUM(C27:N27) -> 20 | R27: PM Period | S27: =SUM(S19:S21) -> 1 | T27: =SUM(T19:T21) -> 0 | U27: =SUM(U19:U21) -> 4 | V27: =SUM(V19:V21) -> 0 | W27: =SUM(W19:W21) -> 0 | X27: =SUM(X19:X21) -> 0 | Y27: =SUM(Y19:Y21) -> 3 | Z27: =SUM(Z19:Z21) -> 0 | ... AF27: =SUM(AF19:AF21) -> 119
B28: 11.30 - 11.45 | C28: 0 | D28: 0 | E28: 1 | F28: 0 | G28: 0 | H28: 0 | I28: 1 | J28: 0 | K28: 0 | L28: 0 | M28: 8 | N28: 0 | O28: =SUM(C28:L28,N28) -> 2 | P28: =SUM(C28:N28) -> 10 | R28: 12 Hours | S28: =SUM(S10:S21) -> 5 | T28: =SUM(T10:T21) -> 3 | U28: =SUM(U10:U21) -> 9 | V28: =SUM(V10:V21) -> 0 | W28: =SUM(W10:W21) -> 0 | X28: =SUM(X10:X21) -> 0 | Y28: =SUM(Y10:Y21) -> 16 | Z28: =SUM(Z10:Z21) -> 0 | ... AF28: =SUM(AF10:AF21) -> 433
B29: 11.45 - 12.00 | C29: 0 | D29: 0 | E29: 0 | F29: 0 | G29: 0 | H29: 0 | I29: 3 | J29: 0 | K29: 0 | L29: 0 | M29: 10 | N29: 0 | O29: =SUM(C29:L29,N29) -> 3 | P29: =SUM(C29:N29) -> 13
B30: 12.00 - 12.15 | C30: 0 | D30: 0 | E30: 0 | F30: 0 | G30: 0 | H30: 0 | I30: 1 | J30: 0 | K30: 0 | L30: 0 | M30: 8 | N30: 0 | O30: =SUM(C30:L30,N30) -> 1 | P30: =SUM(C30:N30) -> 9
B31: 12.15 - 12.30 | C31: 0 | D31: 0 | E31: 0 | F31: 0 | G31: 0 | H31: 0 | I31: 1 | J31: 0 | K31: 0 | L31: 0 | M31: 9 | N31: 0 | O31: =SUM(C31:L31,N31) -> 1 | P31: =SUM(C31:N31) -> 10
B32: 12.30 - 12.45 | C32: 0 | D32: 0 | E32: 0 | F32: 0 | G32: 0 | H32: 0 | I32: 0 | J32: 0 | K32: 0 | L32: 0 | M32: 6 | N32: 0 | O32: =SUM(C32:L32,N32) -> 0 | P32: =SUM(C32:N32) -> 6
B33: 12.45 - 13.00 | C33: 0 | D33: 0 | E33: 0 | F33: 0 | G33: 0 | H33: 0 | I33: 0 | J33: 0 | K33: 0 | L33: 0 | M33: 8 | N33: 0 | O33: =SUM(C33:L33,N33) -> 0 | P33: =SUM(C33:N33) -> 8
B34: 13.00 - 13.15 | C34: 2 | D34: 0 | E34: 0 | F34: 0 | G34: 0 | H34: 0 | I34: 0 | J34: 0 | K34: 0 | L34: 0 | M34: 14 | N34: 0 | O34: =SUM(C34:L34,N34) -> 2 | P34: =SUM(C34:N34) -> 16
B35: 13.15 - 13.30 | C35: 0 | D35: 0 | E35: 0 | F35: 0 | G35: 0 | H35: 0 | I35: 0 | J35: 0 | K35: 0 | L35: 0 | M35: 16 | N35: 0 | O35: =SUM(C35:L35,N35) -> 0 | P35: =SUM(C35:N35) -> 16
B36: 13.30 - 13.45 | C36: 0 | D36: 0 | E36: 0 | F36: 0 | G36: 0 | H36: 0 | I36: 2 | J36: 0 | K36: 0 | L36: 0 | M36: 14 | N36: 0 | O36: =SUM(C36:L36,N36) -> 2 | P36: =SUM(C36:N36) -> 16
B37: 13.45 - 14.00 | C37: 1 | D37: 0 | E37: 0 | F37: 0 | G37: 0 | H37: 0 | I37: 1 | J37: 0 | K37: 0 | L37: 0 | M37: 10 | N37: 0 | O37: =SUM(C37:L37,N37) -> 2 | P37: =SUM(C37:N37) -> 12
B38: 14.00 - 14.15 | C38: 0 | D38: 0 | E38: 0 | F38: 0 | G38: 0 | H38: 0 | I38: 0 | J38: 0 | K38: 0 | L38: 0 | M38: 6 | N38: 0 | O38: =SUM(C38:L38,N38) -> 0 | P38: =SUM(C38:N38) -> 6
B39: 14.15 - 14.30 | C39: 0 | D39: 0 | E39: 0 | F39: 0 | G39: 0 | H39: 0 | I39: 0 | J39: 0 | K39: 0 | L39: 0 | M39: 8 | N39: 0 | O39: =SUM(C39:L39,N39) -> 0 | P39: =SUM(C39:N39) -> 8
B40: 14.30 - 14.45 | C40: 0 | D40: 0 | E40: 0 | F40: 0 | G40: 0 | H40: 0 | I40: 0 | J40: 0 | K40: 0 | L40: 0 | M40: 12 | N40: 0 | O40: =SUM(C40:L40,N40) -> 0 | P40: =SUM(C40:N40) -> 12
... B57: 18.45 - 19.00 | C57: 0 | D57: 0 | E57: 0 | F57: 0 | G57: 0 | H57: 0 | I57: 0 | J57: 0 | K57: 0 | L57: 0 | M57: 13 | N57: 0 | O57: =SUM(C57:L57,N57) -> 0 | P57: =SUM(C57:N57) -> 13
B58: Totals | C58: =SUM(C10:C57) -> 5 | D58: =SUM(D10:D57) -> 3 | E58: =SUM(E10:E57) -> 9 | F58: =SUM(F10:F57) -> 0 | G58: =SUM(G10:G57) -> 0 | H58: =SUM(H10:H57) -> 0 | I58: =SUM(I10:I57) -> 16 | J58: =SUM(J10:J57) -> 0 | ... P58: =SUM(P10:P57) -> 433
...

Sheet 24.08 Suam-Bukwo-24h
B1: Consultancy services for Preparation of Expressway Development Master Plan (EDMP) for Uganda
B2: MANUAL CLASSIFIED COUNT (MCC)
B3: ROAD NAME: | C3: ='23.08 Suam- Bukwo'!C3:G3 -> MCC-C5-ROAD 144 SUAM-BUKWO
C5: Date | D5: 24.08.19 | F5: Location | G5: ='28.08 Bukwo-Suam'!G5:H5 -> KAMKAMBA | J5: Surveyor | K5: ='28.08 Bukwo-Suam'!K5:L5 -> NORMAN
C6: Dir. From | D6: ='23.08 Suam- Bukwo'!D6:E6 -> SUAM | F6: Dir. To | G6: ='23.08 Suam- Bukwo'!G6:H6 -> BUKWO | J6: Supervisor | K6: ='28.08 Bukwo-Suam'!K6:L6 -> IVAN
B8: Time / Veh Type | R8: SUMMARY TRAFFIC VOLUMES
C9: 1. Car | D9: 2. Station Wagon | E9: 3. Pickups | F9: 4. Minibus, matatu | G9: 5. Medium bus | H9: 6. Large Bus | I9: 7. Light Truck | J9: 8. Medium Truck | K9: 9. Heavy truck | L9: 10. Truck Trailer | M9: 11. Motor cycles | N9: 12. Tractors | O9: Total Excl M/Cycles | P9: Total All | R9: Time | S9: 1. Car | T9: 2. Station Wagon | U9: 3. Pickups | V9: 4. Minibus, matatu | W9: 5. Medium bus | X9: 6. Large Bus | Y9: 7. Light Truck | Z9: 8. Medium Truck | AA9: 9. Heavy truck | AB9: 10. Truck Trailer | AC9: 11. Motorcycles | AD9: 12. Tractors, Graders | AE9: Total Excl M/ Cycles | AF9: Total All
B10: 07.00 - 07.15 | C10: 0 | D10: 0 | E10: 0 | G10: 0 | H10: 0 | I10: 1 | J10: 0 | K10: 0 | L10: 0 | M10: 2 | N10: 0 | O10: =SUM(C10:L10,N10) -> 1 | P10: =SUM(C10:N10) -> 3 | R10: 0700-0800 | S10: =SUM(C10:C13) -> 1 | T10: =SUM(D10:D13) -> 0 | U10: =SUM(E10:E13) -> 0 | V10: =SUM(F10:F13) -> 0 | W10: =SUM(G10:G13) -> 0 | X10: =SUM(H10:H13) -> 0 | Y10: =SUM(I10:I13) -> 2 | Z10: =SUM(J10:J13) -> 0 | ... AF10: =SUM(P10:P13) -> 21
B11: 07.15 - 07.30 | C11: 0 | D11: 0 | E11: 0 | F11: 0 | G11: 0 | H11: 0 | I11: 0 | J11: 0 | K11: 0 | L11: 0 | M11: 2 | N11: 0 | O11: =SUM(C11:L11,N11) -> 0 | P11: =SUM(C11:N11) -> 2 | R11: 0800-0900 | S11: =SUM(C14:C17) -> 0 | T11: =SUM(D14:D17) -> 1 | U11: =SUM(E14:E17) -> 0 | V11: =SUM(F14:F17) -> 0 | W11: =SUM(G14:G17) -> 0 | X11: =SUM(H14:H17) -> 0 | Y11: =SUM(I14:I17) -> 0 | Z11: =SUM(J14:J17) -> 0 | ... AF11: =SUM(P14:P17) -> 33
B12: 07.30 - 07.45 | C12: 0 | D12: 0 | E12: 0 | F12: 0 | G12: 0 | H12: 0 | I12: 0 | J12: 0 | K12: 0 | L12: 0 | M12: 6 | N12: 0 | O12: =SUM(C12:L12,N12) -> 0 | P12: =SUM(C12:N12) -> 6 | R12: 0900-1000 | S12: =SUM(C18:C21) -> 0 | T12: =SUM(D18:D21) -> 2 | U12: =SUM(E18:E21) -> 0 | V12: =SUM(F18:F21) -> 0 | W12: =SUM(G18:G21) -> 0 | X12: =SUM(H18:H21) -> 0 | Y12: =SUM(I18:I21) -> 3 | Z12: =SUM(J18:J21) -> 0 | ... AF12: =SUM(P18:P21) -> 52
B13: 07.45 - 08.00 | C13: 1 | D13: 0 | E13: 0 | F13: 0 | G13: 0 | H13: 0 | I13: 1 | J13: 0 | K13: 0 | L13: 0 | M13: 8 | N13: 0 | O13: =SUM(C13:L13,N13) -> 2 | P13: =SUM(C13:N13) -> 10 | R13: 1000-1100 | S13: =SUM(C22:C25) -> 0 | T13: =SUM(D22:D25) -> 1 | U13: =SUM(E22:E25) -> 0 | V13: =SUM(F22:F25) -> 0 | W13: =SUM(G22:G25) -> 0 | X13: =SUM(H22:H25) -> 0 | Y13: =SUM(I22:I25) -> 1 | Z13: =SUM(J22:J25) -> 0 | ... AF13: =SUM(P22:P25) -> 59
B14: 08.00 - 08.15 | C14: 0 | D14: 0 | E14: 0 | F14: 0 | G14: 0 | H14: 0 | I14: 0 | J14: 0 | K14: 0 | L14: 0 | M14: 5 | N14: 0 | O14: =SUM(C14:L14,N14) -> 0 | P14: =SUM(C14:N14) -> 5 | R14: 1100-1200 | S14: =SUM(C26:C29) -> 1 | T14: =SUM(D26:D29) -> 0 | U14: =SUM(E26:E29) -> 1 | V14: =SUM(F26:F29) -> 0 | W14: =SUM(G26:G29) -> 0 | X14: =SUM(H26:H29) -> 0 | Y14: =SUM(I26:I29) -> 2 | Z14: =SUM(J26:J29) -> 0 | ... AF14: =SUM(P26:P29) -> 50
B15: 08.15 - 08.30 | C15: 0 | D15: 0 | E15: 0 | F15: 0 | G15: 0 | H15: 0 | I15: 0 | J15: 0 | K15: 0 | L15: 0 | M15: 9 | N15: 0 | O15: =SUM(C15:L15,N15) -> 0 | P15: =SUM(C15:N15) -> 9 | R15: 1200-1300 | S15: =SUM(C30:C33) -> 0 | T15: =SUM(D30:D33) -> 2 | U15: =SUM(E30:E33) -> 0 | V15: =SUM(F30:F33) -> 0 | W15: =SUM(G30:G33) -> 0 | X15: =SUM(H30:H33) -> 0 | Y15: =SUM(I30:I33) -> 0 | Z15: =SUM(J30:J33) -> 0 | ... AF15: =SUM(P30:P33) -> 50
B16: 08.30 - 08.45 | C16: 0 | D16: 0 | E16: 0 | F16: 0 | G16: 0 | H16: 0 | I16: 0 | J16: 0 | K16: 0 | L16: 0 | M16: 10 | N16: 0 | O16: =SUM(C16:L16,N16) -> 0 | P16: =SUM(C16:N16) -> 10 | R16: 1300-1400 | S16: =SUM(C34:C37) -> 0 | T16: =SUM(D34:D37) -> 0 | U16: =SUM(E34:E37) -> 0 | V16: =SUM(F34:F37) -> 0 | W16: =SUM(G34:G37) -> 0 | X16: =SUM(H34:H37) -> 0 | Y16: =SUM(I34:I37) -> 2 | Z16: =SUM(J34:J37) -> 0 | ... AF16: =SUM(P34:P37) -> 48
B17: 08.45 - 9.00 | C17: 0 | D17: 1 | E17: 0 | F17: 0 | G17: 0 | H17: 0 | I17: 0 | J17: 0 | K17: 0 | L17: 0 | M17: 8 | N17: 0 | O17: =SUM(C17:L17,N17) -> 1 | P17: =SUM(C17:N17) -> 9 | R17: 1400-1500 | S17: =SUM(C38:C41) -> 0 | T17: =SUM(D38:D41) -> 2 | U17: =SUM(E38:E41) -> 1 | V17: =SUM(F38:F41) -> 0 | W17: =SUM(G38:G41) -> 0 | X17: =SUM(H38:H41) -> 0 | Y17: =SUM(I38:I41) -> 5 | Z17: =SUM(J38:J41) -> 0 | ... AF17: =SUM(P38:P41) -> 55
B18: 09.00 - 09.15 | C18: 0 | D18: 1 | E18: 0 | F18: 0 | G18: 0 | H18: 0 | I18: 0 | J18: 0 | K18: 0 | L18: 0 | M18: 15 | N18: 0 | O18: =SUM(C18:L18,N18) -> 1 | P18: =SUM(C18:N18) -> 16 | R18: 1500-1600 | S18: =SUM(C42:C45) -> 1 | T18: =SUM(D42:D45) -> 0 | U18: =SUM(E42:E45) -> 0 | V18: =SUM(F42:F45) -> 0 | W18: =SUM(G42:G45) -> 0 | X18: =SUM(H42:H45) -> 0 | Y18: =SUM(I42:I45) -> 2 | Z18: =SUM(J42:J45) -> 0 | ... AF18: =SUM(P42:P45) -> 46
B19: 09.15 - 09.30 | C19: 0 | D19: 0 | E19: 0 | F19: 0 | G19: 0 | H19: 0 | I19: 2 | J19: 0 | K19: 0 | L19: 0 | M19: 13 | N19: 0 | O19: =SUM(C19:L19,N19) -> 2 | P19: =SUM(C19:N19) -> 15 | R19: 1600-1700 | S19: =SUM(C46:C49) -> 0 | T19: =SUM(D46:D49) -> 1 | U19: =SUM(E46:E49) -> 1 | V19: =SUM(F46:F49) -> 0 | W19: =SUM(G46:G49) -> 0 | X19: =SUM(H46:H49) -> 0 | Y19: =SUM(I46:I49) -> 0 | Z19: =SUM(J46:J49) -> 0 | ... AF19: =SUM(P46:P49) -> 43
B20: 09.30 - 09.45 | C20: 0 | D20: 1 | E20: 0 | F20: 0 | G20: 0 | H20: 0 | I20: 1 | J20: 0 | K20: 0 | L20: 0 | M20: 11 | N20: 1 | O20: =SUM(C20:L20,N20) -> 3 | P20: =SUM(C20:N20) -> 14 | R20: 1700-1800 | S20: =SUM(C50:C53) -> 0 | T20: =SUM(D50:D53) -> 1 | U20: =SUM(E50:E53) -> 0 | V20: =SUM(F50:F53) -> 0 | W20: =SUM(G50:G53) -> 0 | X20: =SUM(H50:H53) -> 0 | Y20: =SUM(I50:I53) -> 1 | Z20: =SUM(J50:J53) -> 0 | ... AF20: =SUM(P50:P53) -> 39
B21: 09.45 - 10.00 | C21: 0 | D21: 0 | E21: 0 | F21: 0 | G21: 0 | H21: 0 | I21: 0 | J21: 0 | K21: 0 | L21: 0 | M21: 7 | N21: 0 | O21: =SUM(C21:L21,N21) -> 0 | P21: =SUM(C21:N21) -> 7 | R21: 1800-1900 | S21: =SUM(C54:C57) -> 0 | T21: =SUM(D54:D57) -> 0 | U21: =SUM(E54:E57) -> 2 | V21: =SUM(F54:F57) -> 0 | W21: =SUM(G54:G57) -> 0 | X21: =SUM(H54:H57) -> 0 | Y21: =SUM(I54:I57) -> 3 | Z21: =SUM(J54:J57) -> 0 | ... AF21: =SUM(P54:P57) -> 42
B22: 10.00 - 10.15 | C22: 0 | D22: 1 | E22: 0 | F22: 0 | G22: 0 | H22: 0 | I22: 0 | J22: 0 | K22: 0 | L22: 0 | M22: 8 | N22: 0 | O22: =SUM(C22:L22,N22) -> 1 | P22: =SUM(C22:N22) -> 9 | R22: 1900-2000 | S22: =SUM(C58:C61) -> 0 | T22: =SUM(D58:D61) -> 1 | U22: =SUM(E58:E61) -> 2 | V22: =SUM(F58:F61) -> 0 | W22: =SUM(G58:G61) -> 0 | X22: =SUM(H58:H61) -> 0 | Y22: =SUM(I58:I61) -> 1 | Z22: =SUM(J58:J61) -> 0 | ... AF22: =SUM(P58:P61) -> 30
B23: 10.15 - 10.30 | C23: 0 | D23: 0 | E23: 0 | F23: 0 | G23: 0 | H23: 0 | I23: 0 | J23: 0 | K23: 0 | L23: 0 | M23: 13 | N23: 0 | O23: =SUM(C23:L23,N23) -> 0 | P23: =SUM(C23:N23) -> 13 | R23: 2000-2100 | S23: =SUM(C62:C65) -> 0 | T23: =SUM(D62:D65) -> 1 | U23: =SUM(E62:E65) -> 0 | V23: =SUM(F62:F65) -> 0 | W23: =SUM(G62:G65) -> 0 | X23: =SUM(H62:H65) -> 0 | Y23: =SUM(I62:I65) -> 5 | Z23: =SUM(J62:J65) -> 0 | ... AF23: =SUM(P62:P65) -> 35
B24: 10.30 - 10.45 | C24: 0 | D24: 0 | E24: 0 | F24: 0 | G24: 0 | H24: 0 | I24: 0 | J24: 0 | K24: 0 | L24: 0 | M24: 19 | N24: 0 | O24: =SUM(C24:L24,N24) -> 0 | P24: =SUM(C24:N24) -> 19 | R24: 2100-2200 | S24: =SUM(C66:C69) -> 0 | T24: =SUM(D66:D69) -> 0 | U24: =SUM(E66:E69) -> 0 | V24: =SUM(F66:F69) -> 0 | W24: =SUM(G66:G69) -> 0 | X24: =SUM(H66:H69) -> 0 | Y24: =SUM(I66:I69) -> 2 | Z24: =SUM(J66:J69) -> 0 | ... AF24: =SUM(P66:P69) -> 43
B25: 10.45 - 11.00 | C25: 0 | D25: 0 | E25: 0 | F25: 0 | G25: 0 | H25: 0 | I25: 1 | J25: 0 | K25: 0 | L25: 0 | M25: 17 | N25: 0 | O25: =SUM(C25:L25,N25) -> 1 | P25: =SUM(C25:N25) -> 18 | R25: 2200-2300 | S25: =SUM(C70:C73) -> 0 | T25: =SUM(D70:D73) -> 0 | U25: =SUM(E70:E73) -> 0 | V25: =SUM(F70:F73) -> 0 | W25: =SUM(G70:G73) -> 0 | X25: =SUM(H70:H73) -> 0 | Y25: =SUM(I70:I73) -> 0 | Z25: =SUM(J70:J73) -> 1 | ... AF25: =SUM(P70:P73) -> 32
B26: 11.00 - 11.15 | C26: 0 | D26: 0 | E26: 0 | F26: 0 | G26: 0 | H26: 0 | I26: 0 | J26: 0 | K26: 0 | L26: 0 | M26: 11 | N26: 0 | O26: =SUM(C26:L26,N26) -> 0 | P26: =SUM(C26:N26) -> 11 | R26: 2300-0000 | S26: =SUM(C74:C77) -> 0 | T26: =SUM(D74:D77) -> 0 | U26: =SUM(E74:E77) -> 0 | V26: =SUM(F74:F77) -> 0 | W26: =SUM(G74:G77) -> 0 | X26: =SUM(H74:H77) -> 0 | Y26: =SUM(I74:I77) -> 0 | Z26: =SUM(J74:J77) -> 0 | ... AF26: =SUM(P74:P77) -> 9
B27: 11.15 - 11.30 | C27: 1 | D27: 0 | E27: 0 | F27: 0 | G27: 0 | H27: 0 | I27: 0 | J27: 0 | K27: 0 | L27: 0 | M27: 14 | N27: 0 | O27: =SUM(C27:L27,N27) -> 1 | P27: =SUM(C27:N27) -> 15 | R27: 0000-0100 | S27: =SUM(C78:C81) -> 0 | T27: =SUM(D78:D81) -> 0 | U27: =SUM(E78:E81) -> 0 | V27: =SUM(F78:F81) -> 0 | W27: =SUM(G78:G81) -> 0 | X27: =SUM(H78:H81) -> 0 | Y27: =SUM(I78:I81) -> 0 | Z27: =SUM(J78:J81) -> 0 | ... AF27: =SUM(P78:P81) -> 3
B28: 11.30 - 11.45 | C28: 0 | D28: 0 | E28: 1 | F28: 0 | G28: 0 | H28: 0 | I28: 1 | J28: 0 | K28: 0 | L28: 0 | M28: 8 | N28: 0 | O28: =SUM(C28:L28,N28) -> 2 | P28: =SUM(C28:N28) -> 10 | R28: 0100-0200 | S28: =SUM(C82:C85) -> 0 | T28: =SUM(D82:D85) -> 0 | U28: =SUM(E82:E85) -> 1 | V28: =SUM(F82:F85) -> 0 | W28: =SUM(G82:G85) -> 0 | X28: =SUM(H82:H85) -> 0 | Y28: =SUM(I82:I85) -> 1 | Z28: =SUM(J82:J85) -> 0 | ... AF28: =SUM(P82:P85) -> 2
B29: 11.45 - 12.00 | C29: 0 | D29: 0 | E29: 0 | F29: 0 | G29: 0 | H29: 0 | I29: 1 | J29: 0 | K29: 0 | L29: 0 | M29: 13 | N29: 0 | O29: =SUM(C29:L29,N29) -> 1 | P29: =SUM(C29:N29) -> 14 | R29: 0200-0300 | S29: =SUM(C86:C89) -> 0 | T29: =SUM(D86:D89) -> 0 | U29: =SUM(E86:E89) -> 0 | V29: =SUM(F86:F89) -> 0 | W29: =SUM(G86:G89) -> 0 | X29: =SUM(H86:H89) -> 0 | Y29: =SUM(I86:I89) -> 0 | Z29: =SUM(J86:J89) -> 0 | ... AF29: =SUM(P86:P89) -> 0
B30: 12.00 - 12.15 | C30: 0 | D30: 0 | E30: 0 | F30: 0 | G30: 0 | H30: 0 | I30: 0 | J30: 0 | K30: 0 | L30: 0 | M30: 10 | N30: 0 | O30: 1 | P30: =SUM(C30:N30) -> 10 | R30: 0300-0400 | S30: =SUM(C90:C93) -> 0 | T30: =SUM(D90:D93) -> 0 | U30: =SUM(E90:E93) -> 0 | V30: =SUM(F90:F93) -> 0 | W30: =SUM(G90:G93) -> 0 | X30: =SUM(H90:H93) -> 0 | Y30: =SUM(I90:I93) -> 0 | Z30: =SUM(J90:J93) -> 0 | ... AF30: =SUM(P90:P93) -> 0
B31: 12.15 - 12.30 | C31: 0 | D31: 0 | E31: 0 | F31: 0 | G31: 0 | H31: 0 | I31: 0 | J31: 0 | K31: 0 | L31: 0 | M31: 13 | N31: 0 | O31: =SUM(C31:L31,N31) -> 0 | P31: =SUM(C31:N31) -> 13 | R31: 0400-0500 | S31: =SUM(C94:C97) -> 0 | T31: =SUM(D94:D97) -> 0 | U31: =SUM(E94:E97) -> 0 | V31: =SUM(F94:F97) -> 0 | W31: =SUM(G94:G97) -> 0 | X31: =SUM(H94:H97) -> 0 | Y31: =SUM(I94:I97) -> 0 | Z31: =SUM(J94:J97) -> 0 | ... AF31: =SUM(P94:P97) -> 0
B32: 12.30 - 12.45 | C32: 0 | D32: 1 | E32: 0 | F32: 0 | G32: 0 | H32: 0 | I32: 0 | J32: 0 | K32: 0 | L32: 0 | M32: 16 | N32: 0 | O32: =SUM(C32:L32,N32) -> 1 | P32: =SUM(C32:N32) -> 17 | R32: 0500-0600 | S32: =SUM(C98:C101) -> 1 | T32: =SUM(D98:D101) -> 0 | U32: =SUM(E98:E101) -> 0 | V32: =SUM(F98:F101) -> 0 | W32: =SUM(G98:G101) -> 0 | X32: =SUM(H98:H101) -> 0 | Y32: =SUM(I98:I101) -> 3 | Z32: =SUM(J98:J101) -> 0 | ... AF32: =SUM(P98:P101) -> 9
B33: 12.45 - 13.00 | C33: 0 | D33: 1 | E33: 0 | F33: 0 | G33: 0 | H33: 0 | I33: 0 | J33: 0 | K33: 0 | L33: 0 | M33: 9 | N33: 0 | O33: =SUM(C33:L33,N33) -> 1 | P33: =SUM(C33:N33) -> 10 | R33: 0600-0700 | S33: =SUM(C102:C105) -> 0 | T33: =SUM(D102:D105) -> 0 | U33: =SUM(E102:E105) -> 0 | V33: =SUM(F102:F105) -> 0 | W33: =SUM(G102:G105) -> 0 | X33: =SUM(H102:H105) -> 0 | Y33: =SUM(I102:I105) -> 0 | Z33: =SUM(J102:J105) -> 0 | ... AF33: =SUM(P102:P105) -> 0
B34: 13.00 - 13.15 | C34: 0 | D34: 0 | E34: 0 | F34: 0 | G34: 0 | H34: 0 | I34: 0 | J34: 0 | K34: 0 | L34: 0 | M34: 12 | N34: 0 | O34: =SUM(C34:L34,N34) -> 0 | P34: =SUM(C34:N34) -> 12 | R34: AM Peak Hr | S34: =MAX(S10:S12) -> 1 | T34: =MAX(T10:T12) -> 2 | U34: =MAX(U10:U12) -> 0 | V34: =MAX(V10:V12) -> 0 | W34: =MAX(W10:W12) -> 0 | X34: =MAX(X10:X12) -> 0 | Y34: =MAX(Y10:Y12) -> 3 | Z34: =MAX(Z10:Z12) -> 0 | ... AF34: =MAX(AF10:AF12) -> 52
B35: 13.15 - 13.30 | C35: 0 | D35: 0 | E35: 0 | F35: 0 | G35: 0 | H35: 0 | I35: 2 | J35: 0 | K35: 0 | L35: 0 | M35: 13 | N35: 0 | O35: =SUM(C35:L35,N35) -> 2 | P35: =SUM(C35:N35) -> 15 | R35: IP Peak Hr | S35: =MAX(S13:S18) -> 1 | T35: =MAX(T13:T18) -> 2 | U35: =MAX(U13:U18) -> 1 | V35: =MAX(V13:V18) -> 0 | W35: =MAX(W13:W18) -> 0 | X35: =MAX(X13:X18) -> 0 | Y35: =MAX(Y13:Y18) -> 5 | Z35: =MAX(Z13:Z18) -> 0 | ... AF35: =MAX(AF13:AF18) -> 59
B36: 13.30 - 13.45 | C36: 0 | D36: 0 | E36: 0 | F36: 0 | G36: 0 | H36: 0 | I36: 0 | J36: 0 | K36: 0 | L36: 0 | M36: 9 | N36: 0 | O36: =SUM(C36:L36,N36) -> 0 | P36: =SUM(C36:N36) -> 9 | R36: PM Peak Hr | S36: =MAX(S19:S21) -> 0 | T36: =MAX(T19:T21) -> 1 | U36: =MAX(U19:U21) -> 2 | V36: =MAX(V19:V21) -> 0 | W36: =MAX(W19:W21) -> 0 | X36: =MAX(X19:X21) -> 0 | Y36: =MAX(Y19:Y21) -> 3 | Z36: =MAX(Z19:Z21) -> 0 | ... AF36: =MAX(AF19:AF21) -> 43
B37: 13.45 - 14.00 | C37: 0 | D37: 0 | E37: 0 | F37: 0 | G37: 0 | H37: 0 | I37: 0 | J37: 0 | K37: 0 | L37: 0 | M37: 12 | N37: 0 | O37: =SUM(C37:L37,N37) -> 0 | P37: =SUM(C37:N37) -> 12 | R37: AM Period | S37: =SUM(S10:S12) -> 1 | T37: =SUM(T10:T12) -> 3 | U37: =SUM(U10:U12) -> 0 | V37: =SUM(V10:V12) -> 0 | W37: =SUM(W10:W12) -> 0 | X37: =SUM(X10:X12) -> 0 | Y37: =SUM(Y10:Y12) -> 5 | Z37: =SUM(Z10:Z12) -> 0 | ... AF37: =SUM(AF10:AF12) -> 106
B38: 14.00 - 14.15 | C38: 0 | D38: 1 | E38: 0 | F38: 0 | G38: 0 | H38: 0 | I38: 1 | J38: 0 | K38: 0 | L38: 0 | M38: 14 | N38: 0 | O38: =SUM(C38:L38,N38) -> 2 | P38: =SUM(C38:N38) -> 16 | R38: IP Period | S38: =SUM(S13:S18) -> 2 | T38: =SUM(T13:T18) -> 5 | U38: =SUM(U13:U18) -> 2 | V38: =SUM(V13:V18) -> 0 | W38: =SUM(W13:W18) -> 0 | X38: =SUM(X13:X18) -> 0 | Y38: =SUM(Y13:Y18) -> 12 | Z38: =SUM(Z13:Z18) -> 0 | ... AF38: =SUM(AF13:AF18) -> 308
B39: 14.15 - 14.30 | C39: 0 | D39: 0 | E39: 0 | F39: 0 | G39: 0 | H39: 0 | I39: 1 | J39: 0 | K39: 0 | L39: 0 | M39: 10 | N39: 0 | O39: =SUM(C39:L39,N39) -> 1 | P39: =SUM(C39:N39) -> 11 | R39: PM Period | S39: =SUM(S19:S21) -> 0 | T39: =SUM(T19:T21) -> 2 | U39: =SUM(U19:U21) -> 3 | V39: =SUM(V19:V21) -> 0 | W39: =SUM(W19:W21) -> 0 | X39: =SUM(X19:X21) -> 0 | Y39: =SUM(Y19:Y21) -> 4 | Z39: =SUM(Z19:Z21) -> 0 | ... AF39: =SUM(AF19:AF21) -> 124
B40: 14.30 - 14.45 | C40: 0 | D40: 0 | E40: 0 | F40: 0 | G40: 0 | H40: 0 | I40: 2 | J40: 0 | K40: 0 | L40: 0 | M40: 13 | N40: 0 | O40: =SUM(C40:L40,N40) -> 2 | P40: =SUM(C40:N40) -> 15 | R40: 12 Hours | S40: =SUM(S10:S21) -> 3 | T40: =SUM(T10:T21) -> 10 | U40: =SUM(U10:U21) -> 5 | V40: =SUM(V10:V21) -> 0 | W40: =SUM(W10:W21) -> 0 | X40: =SUM(X10:X21) -> 0 | Y40: =SUM(Y10:Y21) -> 21 | Z40: =SUM(Z10:Z21) -> 0 | ... AF40: =SUM(AF10:AF21) -> 538
B41: 14.45 - 15.00 | C41: 0 | D41: 1 | E41: 1 | F41: 0 | G41: 0 | H41: 0 | I41: 1 | J41: 0 | K41: 0 | L41: 0 | M41: 10 | N41: 0 | O41: =SUM(C41:L41,N41) -> 3 | P41: =SUM(C41:N41) -> 13 | R41: 24 Hrs/ADT | S41: =SUM(S10:S33) -> 4 | T41: =SUM(T10:T33) -> 12 | U41: =SUM(U10:U33) -> 8 | V41: =SUM(V10:V33) -> 0 | W41: =SUM(W10:W33) -> 0 | X41: =SUM(X10:X33) -> 0 | Y41: =SUM(Y10:Y33) -> 33 | Z41: =SUM(Z10:Z33) -> 1 | ... AF41: =SUM(AF10:AF33) -> 701
B42: 15.00 - 15.15 | C42: 0 | D42: 0 | E42: 0 | F42: 0 | G42: 0 | H42: 0 | I42: 1 | J42: 0 | K42: 0 | L42: 0 | M42: 9 | N42: 0 | O42: =SUM(C42:L42,N42) -> 1 | P42: =SUM(C42:N42) -> 10 | R42: NEF | S42: =S41/S40 -> 1.3333333 | T42: =T41/T40 -> 1.2 | U42: =U41/U40 -> 1.6 | V42: =V41/V40 -> #DIV/0! | W42: =W41/W40 -> #DIV/0! | X42: =X41/X40 -> #DIV/0! | Y42: =Y41/Y40 -> 1.5714286 | Z42: =Z41/Z40 -> #DIV/0! | ... AF42: =AF41/AF40 -> 1.302974
...

Sheet 24.08 Bukwo-Suam-24h
B1: Consultancy services for Preparation of Expressway Development Master Plan (EDMP) for Uganda
B2: MANUAL CLASSIFIED COUNT (MCC)
B3: ROAD NAME: | C3: ='23.08 Suam- Bukwo'!C3:G3 -> MCC-C5-ROAD 144 SUAM-BUKWO
C5: Date | D5: ='24.08 Suam-Bukwo-24h'!D5 -> 24.08.19 | F5: Location | G5: ='24.08 Suam-Bukwo-24h'!G5:H5 -> KAMKAMBA | J5: Surveyor | K5: ='24.08 Suam-Bukwo-24h'!K5:L5 -> NORMAN
C6: Dir. From | D6: ='23.08 Bukwo-Suam'!D6:E6 -> BUKWO | F6: Dir. To | G6: ='25.08 Bukwo-Suam'!G6:H6 -> SUAM | J6: Supervisor | K6: ='24.08 Suam-Bukwo-24h'!K6:L6 -> IVAN
B8: Time / Veh Type | R8: SUMMARY TRAFFIC VOLUMES
C9: 1. Car | D9: 2. Station Wagon | E9: 3. Pickups | F9: 4. Minibus, matatu | G9: 5. Medium bus | H9: 6. Large Bus | I9: 7. Light Truck | J9: 8. Medium Truck | K9: 9. Heavy truck | L9: 10. Truck Trailer | M9: 11. Motor cycles | N9: 12. Tractors | O9: Total Excl M/Cycles | P9: Total All | R9: Time | S9: 1. Car | T9: 2. Station Wagon | U9: 3. Pickups | V9: 4. Minibus, matatu | W9: 5. Medium bus | X9: 6. Large Bus | Y9: 7. Light Truck | Z9: 8. Medium Truck | AA9: 9. Heavy truck | AB9: 10. Truck Trailer | AC9: 11. Motorcycles | AD9: 12. Tractors, Graders | AE9: Total Excl M/ Cycles | AF9: Total All
B10: 07.00 - 07.15 | C10: 0 | D10: 0 | E10: 0 | F10: 0 | G10: 0 | H10: 0 | I10: 0 | J10: 0 | K10: 0 | L10: 0 | M10: 1 | N10: 0 | O10: =SUM(C10:L10,N10) -> 0 | P10: =SUM(C10:N10) -> 1 | R10: 0700-0800 | S10: =SUM(C10:C13) -> 0 | T10: =SUM(D10:D13) -> 0 | U10: =SUM(E10:E13) -> 0 | V10: =SUM(F10:F13) -> 0 | W10: =SUM(G10:G13) -> 0 | X10: =SUM(H10:H13) -> 0 | Y10: =SUM(I10:I13) -> 0 | Z10: =SUM(J10:J13) -> 0 | ... AF10: =SUM(P10:P13) -> 16
B11: 07.15 - 07.30 | C11: 0 | D11: 0 | E11: 0 | F11: 0 | G11: 0 | H11: 0 | I11: 0 | J11: 0 | K11: 0 | L11: 0 | M11: 4 | N11: 0 | O11: =SUM(C11:L11,N11) -> 0 | P11: =SUM(C11:N11) -> 4 | R11: 0800-0900 | S11: =SUM(C14:C17) -> 0 | T11: =SUM(D14:D17) -> 0 | U11: =SUM(E14:E17) -> 0 | V11: =SUM(F14:F17) -> 0 | W11: =SUM(G14:G17) -> 0 | X11: =SUM(H14:H17) -> 0 | Y11: =SUM(I14:I17) -> 0 | Z11: =SUM(J14:J17) -> 0 | ... AF11: =SUM(P14:P17) -> 22
B12: 07.30 - 07.45 | C12: 0 | D12: 0 | E12: 0 | F12: 0 | G12: 0 | H12: 0 | I12: 0 | J12: 0 | K12: 0 | L12: 0 | M12: 7 | N12: 0 | O12: =SUM(C12:L12,N12) -> 0 | P12: =SUM(C12:N12) -> 7 | R12: 0900-1000 | S12: =SUM(C18:C21) -> 0 | T12: =SUM(D18:D21) -> 2 | U12: =SUM(E18:E21) -> 0 | V12: =SUM(F18:F21) -> 0 | W12: =SUM(G18:G21) -> 0 | X12: =SUM(H18:H21) -> 0 | Y12: =SUM(I18:I21) -> 2 | Z12: =SUM(J18:J21) -> 0 | ... AF12: =SUM(P18:P21) -> 36
B13: 07.45 - 08.00 | C13: 0 | D13: 0 | E13: 0 | F13: 0 | G13: 0 | H13: 0 | I13: 0 | J13: 0 | K13: 0 | L13: 0 | M13: 4 | N13: 0 | O13: =SUM(C13:L13,N13) -> 0 | P13: =SUM(C13:N13) -> 4 | R13: 1000-1100 | S13: =SUM(C22:C25) -> 0 | T13: =SUM(D22:D25) -> 1 | U13: =SUM(E22:E25) -> 0 | V13: =SUM(F22:F25) -> 0 | W13: =SUM(G22:G25) -> 0 | X13: =SUM(H22:H25) -> 0 | Y13: =SUM(I22:I25) -> 3 | Z13: =SUM(J22:J25) -> 0 | ... AF13: =SUM(P22:P25) -> 46
B14: 08.00 - 08.15 | C14: 0 | D14: 0 | E14: 0 | F14: 0 | G14: 0 | H14: 0 | I14: 0 | J14: 0 | K14: 0 | L14: 0 | M14: 4 | N14: 0 | O14: =SUM(C14:L14,N14) -> 0 | P14: =SUM(C14:N14) -> 4 | R14: 1100-1200 | S14: =SUM(C26:C29) -> 0 | T14: =SUM(D26:D29) -> 1 | U14: =SUM(E26:E29) -> 0 | V14: =SUM(F26:F29) -> 0 | W14: =SUM(G26:G29) -> 0 | X14: =SUM(H26:H29) -> 0 | Y14: =SUM(I26:I29) -> 2 | Z14: =SUM(J26:J29) -> 0 | ... AF14: =SUM(P26:P29) -> 38
B15: 08.15 - 08.30 | C15: 0 | D15: 0 | E15: 0 | F15: 0 | G15: 0 | H15: 0 | I15: 0 | J15: 0 | K15: 0 | L15: 0 | M15: 4 | N15: 0 | O15: =SUM(C15:L15,N15) -> 0 | P15: =SUM(C15:N15) -> 4 | R15: 1200-1300 | S15: =SUM(C30:C33) -> 0 | T15: =SUM(D30:D33) -> 1 | U15: =SUM(E30:E33) -> 0 | V15: =SUM(F30:F33) -> 0 | W15: =SUM(G30:G33) -> 0 | X15: =SUM(H30:H33) -> 0 | Y15: =SUM(I30:I33) -> 5 | Z15: =SUM(J30:J33) -> 0 | ... AF15: =SUM(P30:P33) -> 6
B16: 08.30 - 08.45 | C16: 0 | D16: 0 | E16: 0 | F16: 0 | G16: 0 | H16: 0 | I16: 0 | J16: 0 | K16: 0 | L16: 0 | M16: 8 | N16: 0 | O16: =SUM(C16:L16,N16) -> 0 | P16: =SUM(C16:N16) -> 8 | R16: 1300-1400 | S16: =SUM(C34:C37) -> 0 | T16: =SUM(D34:D37) -> 1 | U16: =SUM(E34:E37) -> 0 | V16: =SUM(F34:F37) -> 0 | W16: =SUM(G34:G37) -> 0 | X16: =SUM(H34:H37) -> 0 | Y16: =SUM(I34:I37) -> 1 | Z16: =SUM(J34:J37) -> 0 | ... AF16: =SUM(P34:P37) -> 19
B17: 08.45 - 9.00 | C17: 0 | D17: 0 | E17: 0 | F17: 0 | G17: 0 | H17: 0 | I17: 0 | J17: 0 | K17: 0 | L17: 0 | M17: 6 | N17: 0 | O17: =SUM(C17:L17,N17) -> 0 | P17: =SUM(C17:N17) -> 6 | R17: 1400-1500 | S17: =SUM(C38:C41) -> 1 | T17: =SUM(D38:D41) -> 0 | U17: =SUM(E38:E41) -> 0 | V17: =SUM(F38:F41) -> 0 | W17: =SUM(G38:G41) -> 0 | X17: =SUM(H38:H41) -> 0 | Y17: =SUM(I38:I41) -> 1 | Z17: =SUM(J38:J41) -> 0 | ... AF17: =SUM(P38:P41) -> 53
B18: 09.00 - 09.15 | C18: 0 | D18: 1 | E18: 0 | F18: 0 | G18: 0 | H18: 0 | I18: 0 | J18: 0 | K18: 0 | L18: 0 | M18: 6 | N18: 0 | O18: =SUM(C18:L18,N18) -> 1 | P18: =SUM(C18:N18) -> 7 | R18: 1500-1600 | S18: =SUM(C42:C45) -> 0 | T18: =SUM(D42:D45) -> 0 | U18: =SUM(E42:E45) -> 1 | V18: =SUM(F42:F45) -> 0 | W18: =SUM(G42:G45) -> 0 | X18: =SUM(H42:H45) -> 0 | Y18: =SUM(I42:I45) -> 0 | Z18: =SUM(J42:J45) -> 1 | ... AF18: =SUM(P42:P45) -> 38
B19: 09.15 - 09.30 | C19: 0 | D19: 0 | E19: 0 | F19: 0 | G19: 0 | H19: 0 | I19: 1 | J19: 0 | K19: 0 | L19: 0 | M19: 9 | N19: 0 | O19: =SUM(C19:L19,N19) -> 1 | P19: =SUM(C19:N19) -> 10 | R19: 1600-1700 | S19: =SUM(C46:C49) -> 0 | T19: =SUM(D46:D49) -> 0 | U19: =SUM(E46:E49) -> 0 | V19: =SUM(F46:F49) -> 0 | W19: =SUM(G46:G49) -> 0 | X19: =SUM(H46:H49) -> 0 | Y19: =SUM(I46:I49) -> 3 | Z19: =SUM(J46:J49) -> 0 | ... AF19: =SUM(P46:P49) -> 52
B20: 09.30 - 09.45 | C20: 0 | D20: 1 | E20: 0 | F20: 0 | G20: 0 | H20: 0 | I20: 1 | J20: 0 | K20: 0 | L20: 0 | M20: 7 | N20: 0 | O20: =SUM(C20:L20,N20) -> 2 | P20: =SUM(C20:N20) -> 9 | R20: 1700-1800 | S20: =SUM(C50:C53) -> 0 | T20: =SUM(D50:D53) -> 1 | U20: =SUM(E50:E53) -> 2 | V20: =SUM(F50:F53) -> 0 | W20: =SUM(G50:G53) -> 0 | X20: =SUM(H50:H53) -> 0 | Y20: =SUM(I50:I53) -> 1 | Z20: =SUM(J50:J53) -> 0 | ... AF20: =SUM(P50:P53) -> 33
B21: 09.45 - 10.00 | C21: 0 | D21: 0 | E21: 0 | F21: 0 | G21: 0 | H21: 0 | I21: 0 | J21: 0 | K21: 0 | L21: 0 | M21: 10 | N21: 0 | O21: =SUM(C21:L21,N21) -> 0 | P21: =SUM(C21:N21) -> 10 | R21: 1800-1900 | S21: =SUM(C54:C57) -> 0 | T21: =SUM(D54:D57) -> 0 | U21: =SUM(E54:E57) -> 0 | V21: =SUM(F54:F57) -> 0 | W21: =SUM(G54:G57) -> 0 | X21: =SUM(H54:H57) -> 0 | Y21: =SUM(I54:I57) -> 1 | Z21: =SUM(J54:J57) -> 0 | ... AF21: =SUM(P54:P57) -> 50
B22: 10.00 - 10.15 | C22: 0 | D22: 1 | E22: 0 | F22: 0 | G22: 0 | H22: 0 | I22: 2 | J22: 0 | K22: 0 | L22: 0 | M22: 6 | N22: 0 | O22: =SUM(C22:L22,N22) -> 3 | P22: =SUM(C22:N22) -> 9 | R22: 1900-2000 | S22: =SUM(C58:C61) -> 1 | T22: =SUM(D58:D61) -> 0 | U22: =SUM(E58:E61) -> 1 | V22: =SUM(F58:F61) -> 0 | W22: =SUM(G58:G61) -> 0 | X22: =SUM(H58:H61) -> 0 | Y22: =SUM(I58:I61) -> 2 | Z22: =SUM(J58:J61) -> 0 | ... AF22: =SUM(P58:P61) -> 38
B23: 10.15 - 10.30 | C23: 0 | D23: 0 | E23: 0 | F23: 0 | G23: 0 | H23: 0 | I23: 1 | J23: 0 | K23: 0 | L23: 0 | M23: 14 | N23: 0 | O23: =SUM(C23:L23,N23) -> 1 | P23: =SUM(C23:N23) -> 15 | R23: 2000-2100 | S23: =SUM(C62:C65) -> 0 | T23: =SUM(D62:D65) -> 0 | U23: =SUM(E62:E65) -> 1 | V23: =SUM(F62:F65) -> 0 | W23: =SUM(G62:G65) -> 0 | X23: =SUM(H62:H65) -> 0 | Y23: =SUM(I62:I65) -> 1 | Z23: =SUM(J62:J65) -> 0 | ... AF23: =SUM(P62:P65) -> 31
B24: 10.30 - 10.45 | C24: 0 | D24: 0 | E24: 0 | F24: 0 | G24: 0 | H24: 0 | I24: 0 | J24: 0 | K24: 0 | L24: 0 | M24: 9 | N24: 0 | O24: =SUM(C24:L24,N24) -> 0 | P24: =SUM(C24:N24) -> 9 | R24: 2100-2200 | S24: =SUM(C66:C69) -> 0 | T24: =SUM(D66:D69) -> 0 | U24: =SUM(E66:E69) -> 2 | V24: =SUM(F66:F69) -> 0 | W24: =SUM(G66:G69) -> 0 | X24: =SUM(H66:H69) -> 0 | Y24: =SUM(I66:I69) -> 3 | Z24: =SUM(J66:J69) -> 0 | ... AF24: =SUM(P66:P69) -> 43
B25: 10.45 - 11.00 | C25: 0 | D25: 0 | E25: 0 | F25: 0 | G25: 0 | H25: 0 | I25: 0 | J25: 0 | K25: 0 | L25: 0 | M25: 13 | N25: 0 | O25: =SUM(C25:L25,N25) -> 0 | P25: =SUM(C25:N25) -> 13 | R25: 2200-2300 | S25: =SUM(C70:C73) -> 1 | T25: =SUM(D70:D73) -> 0 | U25: =SUM(E70:E73) -> 0 | V25: =SUM(F70:F73) -> 0 | W25: =SUM(G70:G73) -> 0 | X25: =SUM(H70:H73) -> 0 | Y25: =SUM(I70:I73) -> 0 | Z25: =SUM(J70:J73) -> 0 | ... AF25: =SUM(P70:P73) -> 38
B26: 11.00 - 11.15 | C26: 0 | D26: 0 | E26: 0 | F26: 0 | G26: 0 | H26: 0 | I26: 0 | J26: 0 | K26: 0 | L26: 0 | M26: 9 | N26: 0 | O26: =SUM(C26:L26,N26) -> 0 | P26: =SUM(C26:N26) -> 9 | R26: 2300-0000 | S26: =SUM(C74:C77) -> 0 | T26: =SUM(D74:D77) -> 0 | U26: =SUM(E74:E77) -> 0 | V26: =SUM(F74:F77) -> 0 | W26: =SUM(G74:G77) -> 0 | X26: =SUM(H74:H77) -> 0 | Y26: =SUM(I74:I77) -> 0 | Z26: =SUM(J74:J77) -> 0 | ... AF26: =SUM(P74:P77) -> 13
B27: 11.15 - 11.30 | C27: 0 | D27: 0 | E27: 0 | F27: 0 | G27: 0 | H27: 0 | I27: 0 | J27: 0 | K27: 0 | L27: 0 | M27: 8 | N27: 0 | O27: =SUM(C27:L27,N27) -> 0 | P27: =SUM(C27:N27) -> 8 | R27: 0000-0100 | S27: =SUM(C78:C81) -> 0 | T27: =SUM(D78:D81) -> 0 | U27: =SUM(E78:E81) -> 0 | V27: =SUM(F78:F81) -> 0 | W27: =SUM(G78:G81) -> 0 | X27: =SUM(H78:H81) -> 0 | Y27: =SUM(I78:I81) -> 0 | Z27: =SUM(J78:J81) -> 0 | ... AF27: =SUM(P78:P81) -> 3
B28: 11.30 - 11.45 | C28: 0 | D28: 0 | E28: 0 | F28: 0 | G28: 0 | H28: 0 | I28: 0 | J28: 0 | K28: 0 | L28: 0 | M28: 7 | N28: 0 | O28: =SUM(C28:L28,N28) -> 0 | P28: =SUM(C28:N28) -> 7 | R28: 0100-0200 | S28: =SUM(C82:C85) -> 0 | T28: =SUM(D82:D85) -> 0 | U28: =SUM(E82:E85) -> 0 | V28: =SUM(F82:F85) -> 0 | W28: =SUM(G82:G85) -> 0 | X28: =SUM(H82:H85) -> 0 | Y28: =SUM(I82:I85) -> 0 | Z28: =SUM(J82:J85) -> 0 | ... AF28: =SUM(P82:P85) -> 1
B29: 11.45 - 12.00 | C29: 0 | D29: 1 | E29: 0 | F29: 0 | G29: 0 | H29: 0 | I29: 2 | J29: 0 | K29: 0 | L29: 0 | M29: 11 | N29: 0 | O29: =SUM(C29:L29,N29) -> 3 | P29: =SUM(C29:N29) -> 14 | R29: 0200-0300 | S29: =SUM(C86:C89) -> 0 | T29: =SUM(D86:D89) -> 0 | U29: =SUM(E86:E89) -> 0 | V29: =SUM(F86:F89) -> 0 | W29: =SUM(G86:G89) -> 0 | X29: =SUM(H86:H89) -> 0 | Y29: =SUM(I86:I89) -> 0 | Z29: =SUM(J86:J89) -> 0 | ... AF29: =SUM(P86:P89) -> 0
B30: 12.00 - 12.15 | C30: 0 | D30: 0 | E30: 0 | F30: 0 | G30: 0 | H30: 0 | I30: 1 | J30: 0 | K30: 0 | L30: 0 | M30: 0 | N30: 0 | O30: =SUM(C30:L30,N30) -> 1 | P30: =SUM(C30:N30) -> 1 | R30: 0300-0400 | S30: =SUM(C90:C93) -> 0 | T30: =SUM(D90:D93) -> 0 | U30: =SUM(E90:E93) -> 0 | V30: =SUM(F90:F93) -> 0 | W30: =SUM(G90:G93) -> 0 | X30: =SUM(H90:H93) -> 0 | Y30: =SUM(I90:I93) -> 0 | Z30: =SUM(J90:J93) -> 0 | ... AF30: =SUM(P90:P93) -> 0
B31: 12.15 - 12.30 | C31: 0 | D31: 0 | E31: 0 | F31: 0 | G31: 0 | H31: 0 | I31: 1 | J31: 0 | K31: 0 | L31: 0 | M31: 0 | N31: 0 | O31: =SUM(C31:L31,N31) -> 1 | P31: =SUM(C31:N31) -> 1 | R31: 0400-0500 | S31: =SUM(C94:C97) -> 0 | T31: =SUM(D94:D97) -> 0 | U31: =SUM(E94:E97) -> 0 | V31: =SUM(F94:F97) -> 0 | W31: =SUM(G94:G97) -> 0 | X31: =SUM(H94:H97) -> 0 | Y31: =SUM(I94:I97) -> 2 | Z31: =SUM(J94:J97) -> 1 | ... AF31: =SUM(P94:P97) -> 3
B32: 12.30 - 12.45 | C32: 0 | D32: 1 | E32: 0 | F32: 0 | G32: 0 | H32: 0 | I32: 1 | J32: 0 | K32: 0 | L32: 0 | M32: 0 | N32: 0 | O32: =SUM(C32:L32,N32) -> 2 | P32: =SUM(C32:N32) -> 2 | R32: 0500-0600 | S32: =SUM(C98:C101) -> 0 | T32: =SUM(D98:D101) -> 0 | U32: =SUM(E98:E101) -> 0 | V32: =SUM(F98:F101) -> 0 | W32: =SUM(G98:G101) -> 0 | X32: =SUM(H98:H101) -> 0 | Y32: =SUM(I98:I101) -> 0 | Z32: =SUM(J98:J101) -> 0 | ... AF32: =SUM(P98:P101) -> 2
B33: 12.45 - 13.00 | C33: 0 | D33: 0 | E33: 0 | F33: 0 | G33: 0 | H33: 0 | I33: 2 | J33: 0 | K33: 0 | L33: 0 | M33: 0 | N33: 0 | O33: =SUM(C33:L33,N33) -> 2 | P33: =SUM(C33:N33) -> 2 | R33: 0600-0700 | S33: =SUM(C102:C105) -> 0 | T33: =SUM(D102:D105) -> 0 | U33: =SUM(E102:E105) -> 0 | V33: =SUM(F102:F105) -> 0 | W33: =SUM(G102:G105) -> 0 | X33: =SUM(H102:H105) -> 0 | Y33: =SUM(I102:I105) -> 1 | Z33: =SUM(J102:J105) -> 0 | ... AF33: =SUM(P102:P105) -> 13
B34: 13.00 - 13.15 | C34: 0 | D34: 0 | E34: 0 | F34: 0 | G34: 0 | H34: 0 | I34: 0 | J34: 0 | K34: 0 | L34: 0 | M34: 0 | O34: =SUM(C34:L34,N34) -> 0 | P34: =SUM(C34:N34) -> 0 | R34: AM Peak Hr | S34: =MAX(S10:S12) -> 0 | T34: =MAX(T10:T12) -> 2 | U34: =MAX(U10:U12) -> 0 | V34: =MAX(V10:V12) -> 0 | W34: =MAX(W10:W12) -> 0 | X34: =MAX(X10:X12) -> 0 | Y34: =MAX(Y10:Y12) -> 2 | Z34: =MAX(Z10:Z12) -> 0 | ... AF34: =MAX(AF10:AF12) -> 36
B35: 13.15 - 13.30 | C35: 0 | D35: 0 | E35: 0 | F35: 0 | G35: 0 | H35: 0 | I35: 1 | J35: 0 | K35: 0 | L35: 0 | M35: 0 | N35: 0 | O35: =SUM(C35:L35,N35) -> 1 | P35: =SUM(C35:N35) -> 1 | R35: IP Peak Hr | S35: =MAX(S13:S18) -> 1 | T35: =MAX(T13:T18) -> 1 | U35: =MAX(U13:U18) -> 1 | V35: =MAX(V13:V18) -> 0 | W35: =MAX(W13:W18) -> 0 | X35: =MAX(X13:X18) -> 0 | Y35: =MAX(Y13:Y18) -> 5 | Z35: =MAX(Z13:Z18) -> 1 | ... AF35: =MAX(AF13:AF18) -> 53
B36: 13.30 - 13.45 | C36: 0 | D36: 0 | E36: 0 | F36: 0 | G36: 0 | H36: 0 | I36: 0 | J36: 0 | K36: 0 | L36: 0 | M36: 0 | N36: 0 | O36: =SUM(C36:L36,N36) -> 0 | P36: =SUM(C36:N36) -> 0 | R36: PM Peak Hr | S36: =MAX(S19:S21) -> 0 | T36: =MAX(T19:T21) -> 1 | U36: =MAX(U19:U21) -> 2 | V36: =MAX(V19:V21) -> 0 | W36: =MAX(W19:W21) -> 0 | X36: =MAX(X19:X21) -> 0 | Y36: =MAX(Y19:Y21) -> 3 | Z36: =MAX(Z19:Z21) -> 0 | ... AF36: =MAX(AF19:AF21) -> 52
B37: 13.45 - 14.00 | C37: 0 | D37: 1 | E37: 0 | F37: 0 | G37: 0 | H37: 0 | I37: 0 | J37: 0 | K37: 0 | L37: 0 | M37: 17 | N37: 0 | O37: =SUM(C37:L37,N37) -> 1 | P37: =SUM(C37:N37) -> 18 | R37: AM Period | S37: =SUM(S10:S12) -> 0 | T37: =SUM(T10:T12) -> 2 | U37: =SUM(U10:U12) -> 0 | V37: =SUM(V10:V12) -> 0 | W37: =SUM(W10:W12) -> 0 | X37: =SUM(X10:X12) -> 0 | Y37: =SUM(Y10:Y12) -> 2 | Z37: =SUM(Z10:Z12) -> 0 | ... AF37: =SUM(AF10:AF12) -> 74
B38: 14.00 - 14.15 | C38: 0 | D38: 0 | E38: 0 | F38: 0 | G38: 0 | H38: 0 | I38: 0 | J38: 0 | K38: 0 | L38: 0 | M38: 10 | N38: 0 | O38: =SUM(C38:L38,N38) -> 0 | P38: =SUM(C38:N38) -> 10 | R38: IP Period | S38: =SUM(S13:S18) -> 1 | T38: =SUM(T13:T18) -> 4 | U38: =SUM(U13:U18) -> 1 | V38: =SUM(V13:V18) -> 0 | W38: =SUM(W13:W18) -> 0 | X38: =SUM(X13:X18) -> 0 | Y38: =SUM(Y13:Y18) -> 12 | Z38: =SUM(Z13:Z18) -> 1 | ... AF38: =SUM(AF13:AF18) -> 200
B39: 14.15 - 14.30 | C39: 0 | D39: 0 | E39: 0 | F39: 0 | G39: 0 | H39: 0 | I39: 0 | J39: 0 | K39: 0 | L39: 0 | M39: 9 | N39: 0 | O39: =SUM(C39:L39,N39) -> 0 | P39: =SUM(C39:N39) -> 9 | R39: PM Period | S39: =SUM(S19:S21) -> 0 | T39: =SUM(T19:T21) -> 1 | U39: =SUM(U19:U21) -> 2 | V39: =SUM(V19:V21) -> 0 | W39: =SUM(W19:W21) -> 0 | X39: =SUM(X19:X21) -> 0 | Y39: =SUM(Y19:Y21) -> 5 | Z39: =SUM(Z19:Z21) -> 0 | ... AF39: =SUM(AF19:AF21) -> 135
B40: 14.30 - 14.45 | C40: 1 | D40: 0 | E40: 0 | F40: 0 | G40: 0 | H40: 0 | I40: 1 | J40: 0 | K40: 0 | L40: 0 | M40: 21 | N40: 0 | O40: =SUM(C40:L40,N40) -> 2 | P40: =SUM(C40:N40) -> 23 | R40: 12 Hours | S40: =SUM(S10:S21) -> 1 | T40: =SUM(T10:T21) -> 7 | U40: =SUM(U10:U21) -> 3 | V40: =SUM(V10:V21) -> 0 | W40: =SUM(W10:W21) -> 0 | X40: =SUM(X10:X21) -> 0 | Y40: =SUM(Y10:Y21) -> 19 | Z40: =SUM(Z10:Z21) -> 1 | ... AF40: =SUM(AF10:AF21) -> 409
B41: 14.45 - 15.00 | C41: 0 | D41: 0 | E41: 0 | F41: 0 | G41: 0 | H41: 0 | I41: 0 | J41: 0 | K41: 0 | L41: 0 | M41: 11 | N41: 0 | O41: =SUM(C41:L41,N41) -> 0 | P41: =SUM(C41:N41) -> 11 | R41: 24 Hrs/ADT | S41: =SUM(S10:S33) -> 3 | T41: =SUM(T10:T33) -> 7 | U41: =SUM(U10:U33) -> 7 | V41: =SUM(V10:V33) -> 0 | W41: =SUM(W10:W33) -> 0 | X41: =SUM(X10:X33) -> 0 | Y41: =SUM(Y10:Y33) -> 28 | Z41: =SUM(Z10:Z33) -> 2 | ... AF41: =SUM(AF10:AF33) -> 594
B42: 15.00 - 15.15 | C42: 0 | D42: 0 | E42: 0 | F42: 0 | G42: 0 | H42: 0 | I42: 0 | J42: 0 | K42: 0 | L42: 0 | M42: 11 | N42: 0 | O42: =SUM(C42:L42,N42) -> 0 | P42: =SUM(C42:N42) -> 11 | R42: NEF | S42: =S41/S40 -> 3 | T42: =T41/T40 -> 1 | U42: =U41/U40 -> 2.3333333 | V42: =V41/V40 -> #DIV/0! | W42: =W41/W40 -> #DIV/0! | X42: =X41/X40 -> #DIV/0! | Y42: =Y41/Y40 -> 1.4736842 | Z42: =Z41/Z40 -> 2 | ... AF42: =AF41/AF40 -> 1.4523227
...

Sheet 25.08 Suam-Bukwo
B1: Consultancy services for Preparation of Expressway Development Master Plan (EDMP) for Uganda
B2: MANUAL CLASSIFIED COUNT (MCC)
B3: ROAD NAME: | C3: MCC-C5-STN 144-SUAM-BUKWO
C5: Date | D5: 25.08.19 | F5: Location | G5: KAMKAMBA | J5: Surveyor | K5: NORMAN
C6: Dir. From | D6: SUAM | F6: Dir. To | G6: BUKWO | J6: Supervisor | K6: IVAN
B8: Time / Veh Type | R8: SUMMARY TRAFFIC VOLUMES
C9: 1. Car | D9: 2. Station Wagon | E9: 3. Pickups | F9: 4. Minibus, matatu | G9: 5. Medium bus | H9: 6. Large Bus | I9: 7. Light Truck | J9: 8. Medium Truck | K9: 9. Heavy truck | L9: 10. Truck Trailer | M9: 11. Motor cycles | N9: 12. Tractors | O9: Total Excl M/Cycles | P9: Total All | R9: Time | S9: 1. Car | T9: 2. Station Wagon | U9: 3. Pickups | V9: 4. Minibus, matatu | W9: 5. Medium bus | X9: 6. Large Bus | Y9: 7. Light Truck | Z9: 8. Medium Truck | AA9: 9. Heavy truck | AB9: 10. Truck Trailer | AC9: 11. Motorcycles | AD9: 12. Tractors, Graders | AE9: Total Excl M/ Cycles | AF9: Total All
B10: 07.00 - 07.15 | C10: 0 | D10: 0 | E10: 0 | F10: 0 | G10: 0 | H10: 0 | I10: 0 | J10: 0 | K10: 0 | L10: 0 | M10: 4 | N10: 0 | O10: =SUM(C10:L10,N10) -> 0 | P10: =SUM(C10:N10) -> 4 | R10: 0700-0800 | S10: =SUM(C10:C13) -> 0 | T10: =SUM(D10:D13) -> 0 | U10: =SUM(E10:E13) -> 0 | V10: =SUM(F10:F13) -> 0 | W10: =SUM(G10:G13) -> 0 | X10: =SUM(H10:H13) -> 0 | Y10: =SUM(I10:I13) -> 0 | Z10: =SUM(J10:J13) -> 0 | ... AF10: =SUM(P10:P13) -> 26
B11: 07.15 - 07.30 | C11: 0 | D11: 0 | E11: 0 | F11: 0 | G11: 0 | H11: 0 | I11: 0 | J11: 0 | K11: 0 | L11: 0 | M11: 2 | N11: 0 | O11: =SUM(C11:L11,N11) -> 0 | P11: =SUM(C11:N11) -> 2 | R11: 0800-0900 | S11: =SUM(C14:C17) -> 0 | T11: =SUM(D14:D17) -> 0 | U11: =SUM(E14:E17) -> 0 | V11: =SUM(F14:F17) -> 0 | W11: =SUM(G14:G17) -> 0 | X11: =SUM(H14:H17) -> 0 | Y11: =SUM(I14:I17) -> 0 | Z11: =SUM(J14:J17) -> 0 | ... AF11: =SUM(P14:P17) -> 37
B12: 07.30 - 07.45 | C12: 0 | D12: 0 | E12: 0 | F12: 0 | G12: 0 | H12: 0 | I12: 0 | J12: 0 | K12: 0 | L12: 0 | M12: 7 | N12: 0 | O12: =SUM(C12:L12,N12) -> 0 | P12: =SUM(C12:N12) -> 7 | R12: 0900-1000 | S12: =SUM(C18:C21) -> 0 | T12: =SUM(D18:D21) -> 0 | U12: =SUM(E18:E21) -> 0 | V12: =SUM(F18:F21) -> 0 | W12: =SUM(G18:G21) -> 0 | X12: =SUM(H18:H21) -> 0 | Y12: =SUM(I18:I21) -> 0 | Z12: =SUM(J18:J21) -> 0 | ... AF12: =SUM(P18:P21) -> 29
B13: 07.45 - 08.00 | C13: 0 | D13: 0 | E13: 0 | F13: 0 | G13: 0 | H13: 0 | I13: 0 | J13: 0 | K13: 0 | L13: 0 | M13: 13 | N13: 0 | O13: =SUM(C13:L13,N13) -> 0 | P13: =SUM(C13:N13) -> 13 | R13: 1000-1100 | S13: =SUM(C22:C25) -> 0 | T13: =SUM(D22:D25) -> 0 | U13: =SUM(E22:E25) -> 0 | V13: =SUM(F22:F25) -> 0 | W13: =SUM(G22:G25) -> 0 | X13: =SUM(H22:H25) -> 0 | Y13: =SUM(I22:I25) -> 0 | Z13: =SUM(J22:J25) -> 0 | ... AF13: =SUM(P22:P25) -> 65
B14: 08.00 - 08.15 | C14: 0 | D14: 0 | E14: 0 | F14: 0 | G14: 0 | H14: 0 | I14: 0 | J14: 0 | K14: 0 | L14: 0 | M14: 3 | N14: 0 | O14: =SUM(C14:L14,N14) -> 0 | P14: =SUM(C14:N14) -> 3 | R14: 1100-1200 | S14: =SUM(C26:C29) -> 0 | T14: =SUM(D26:D29) -> 0 | U14: =SUM(E26:E29) -> 0 | V14: =SUM(F26:F29) -> 0 | W14: =SUM(G26:G29) -> 0 | X14: =SUM(H26:H29) -> 0 | Y14: =SUM(I26:I29) -> 1 | Z14: =SUM(J26:J29) -> 0 | ... AF14: =SUM(P26:P29) -> 48
B15: 08.15 - 08.30 | C15: 0 | D15: 0 | E15: 0 | F15: 0 | G15: 0 | H15: 0 | I15: 0 | J15: 0 | K15: 0 | L15: 0 | M15: 8 | N15: 0 | O15: =SUM(C15:L15,N15) -> 0 | P15: =SUM(C15:N15) -> 8 | R15: 1200-1300 | S15: =SUM(C30:C33) -> 0 | T15: =SUM(D30:D33) -> 0 | U15: =SUM(E30:E33) -> 0 | V15: =SUM(F30:F33) -> 0 | W15: =SUM(G30:G33) -> 0 | X15: =SUM(H30:H33) -> 0 | Y15: =SUM(I30:I33) -> 0 | Z15: =SUM(J30:J33) -> 0 | ... AF15: =SUM(P30:P33) -> 45
B16: 08.30 - 08.45 | C16: 0 | D16: 0 | E16: 0 | F16: 0 | G16: 0 | H16: 0 | I16: 0 | J16: 0 | K16: 0 | L16: 0 | M16: 9 | N16: 0 | O16: =SUM(C16:L16,N16) -> 0 | P16: =SUM(C16:N16) -> 9 | R16: 1300-1400 | S16: =SUM(C34:C37) -> 0 | T16: =SUM(D34:D37) -> 0 | U16: =SUM(E34:E37) -> 0 | V16: =SUM(F34:F37) -> 0 | W16: =SUM(G34:G37) -> 0 | X16: =SUM(H34:H37) -> 0 | Y16: =SUM(I34:I37) -> 0 | Z16: =SUM(J34:J37) -> 0 | ... AF16: =SUM(P34:P37) -> 8
