Workbook

Sheet 29.07 Ntinda-Naalya
B1: Consultancy services for Preparation of Expressway Development Master Plan (EDMP) for Uganda
B2: MANUAL CLASSIFIED COUNT (MCC)
B3: ROAD NAME: | C3: MCC - C1 - STN38 - NAALYA EAST ROAD
C5: Date | D5: 29.07.19 | F5: Location | G5: NAALYA ROUND ABOUT | J5: Surveyor | K5: HARRIET N/NASSIWA A/MUTE C/PHOEBY/KAZIBWE J/NAKAYE J.
C6: Dir. From | D6: NTINDA | F6: Dir. To | G6: NAALYA | J6: Supervisor | K6: STEVEN
B8: Time / Veh Type | R8: SUMMARY TRAFFIC VOLUMES
C9: 1. Car | D9: 2. Station Wagon | E9: 3. Pickups | F9: 4. Minibus, matatu | G9: 5. Medium bus | H9: 6. Large Bus | I9: 7. Light Truck | J9: 8. Medium Truck | K9: 9. Heavy truck | L9: 10. Truck Trailer | M9: 11. Motor cycles | N9: 12. Tractors | O9: Total Excl M/Cycles | P9: Total All | R9: Time | S9: 1. Car | T9: 2. Station Wagon | U9: 3. Pickups | V9: 4. Minibus, matatu | W9: 5. Medium bus | X9: 6. Large Bus | Y9: 7. Light Truck | Z9: 8. Medium Truck | AA9: 9. Heavy truck | AB9: 10. Truck Trailer | AC9: 11. Motorcycles | AD9: 12. Tractors, Graders | AE9: Total Excl M/ Cycles | AF9: Total All
B10: 07.00 - 07.15 | C10: 29 | D10: 9 | E10: 4 | F10: 0 | G10: 0 | H10: 1 | I10: 0 | J10: 0 | K10: 0 | L10: 0 | M10: 7 | N10: 0 | O10: =SUM(C10:L10,N10) -> 43 | P10: =SUM(C10:N10) -> 50 | R10: 0700-0800 | S10: =SUM(C10:C13) -> 369 | T10: =SUM(D10:D13) -> 74 | U10: =SUM(E10:E13) -> 12 | V10: =SUM(F10:F13) -> 0 | W10: =SUM(G10:G13) -> 0 | X10: =SUM(H10:H13) -> 1 | Y10: =SUM(I10:I13) -> 1 | Z10: =SUM(J10:J13) -> 2 | ... AF10: =SUM(P10:P13) -> 644
B11: 07.15 - 07.30 | C11: 97 | D11: 22 | E11: 1 | F11: 0 | G11: 0 | H11: 0 | I11: 0 | J11: 0 | K11: 0 | L11: 0 | M11: 31 | N11: 0 | O11: =SUM(C11:L11,N11) -> 120 | P11: =SUM(C11:N11) -> 151 | R11: 0800-0900 | S11: =SUM(C14:C17) -> 307 | T11: =SUM(D14:D17) -> 87 | U11: =SUM(E14:E17) -> 10 | V11: =SUM(F14:F17) -> 39 | W11: =SUM(G14:G17) -> 0 | X11: =SUM(H14:H17) -> 0 | Y11: =SUM(I14:I17) -> 0 | Z11: =SUM(J14:J17) -> 4 | ... AF11: =SUM(P14:P17) -> 759
B12: 07.30 - 07.45 | C12: 125 | D12: 18 | E12: 5 | F12: 0 | G12: 0 | H12: 0 | I12: 1 | J12: 2 | K12: 0 | L12: 0 | M12: 59 | N12: 0 | O12: =SUM(C12:L12,N12) -> 151 | P12: =SUM(C12:N12) -> 210 | R12: 0900-1000 | S12: =SUM(C18:C21) -> 234 | T12: =SUM(D18:D21) -> 71 | U12: =SUM(E18:E21) -> 22 | V12: =SUM(F18:F21) -> 37 | W12: =SUM(G18:G21) -> 0 | X12: =SUM(H18:H21) -> 0 | Y12: =SUM(I18:I21) -> 21 | Z12: =SUM(J18:J21) -> 8 | ... AF12: =SUM(P18:P21) -> 762
B13: 07.45 - 08.00 | C13: 118 | D13: 25 | E13: 2 | F13: 0 | G13: 0 | H13: 0 | I13: 0 | J13: 0 | K13: 0 | L13: 0 | M13: 88 | N13: 0 | O13: =SUM(C13:L13,N13) -> 145 | P13: =SUM(C13:N13) -> 233 | R13: 1000-1100 | S13: =SUM(C22:C25) -> 268 | T13: =SUM(D22:D25) -> 72 | U13: =SUM(E22:E25) -> 20 | V13: =SUM(F22:F25) -> 26 | W13: =SUM(G22:G25) -> 0 | X13: =SUM(H22:H25) -> 0 | Y13: =SUM(I22:I25) -> 30 | Z13: =SUM(J22:J25) -> 7 | ... AF13: =SUM(P22:P25) -> 746
B14: 08.00 - 08.15 | C14: 96 | D14: 27 | E14: 0 | F14: 15 | G14: 0 | H14: 0 | I14: 0 | J14: 2 | K14: 0 | L14: 0 | M14: 71 | N14: 0 | O14: =SUM(C14:L14,N14) -> 140 | P14: =SUM(C14:N14) -> 211 | R14: 1100-1200 | S14: =SUM(C26:C29) -> 233 | T14: =SUM(D26:D29) -> 82 | U14: =SUM(E26:E29) -> 18 | V14: =SUM(F26:F29) -> 19 | W14: =SUM(G26:G29) -> 1 | X14: =SUM(H26:H29) -> 1 | Y14: =SUM(I26:I29) -> 25 | Z14: =SUM(J26:J29) -> 5 | ... AF14: =SUM(P26:P29) -> 690
B15: 08.15 - 08.30 | C15: 71 | D15: 22 | E15: 1 | F15: 8 | G15: 0 | H15: 0 | I15: 0 | J15: 1 | K15: 0 | L15: 0 | M15: 50 | N15: 0 | O15: =SUM(C15:L15,N15) -> 103 | P15: =SUM(C15:N15) -> 153 | R15: 1200-1300 | S15: =SUM(C30:C33) -> 222 | T15: =SUM(D30:D33) -> 64 | U15: =SUM(E30:E33) -> 20 | V15: =SUM(F30:F33) -> 20 | W15: =SUM(G30:G33) -> 5 | X15: =SUM(H30:H33) -> 1 | Y15: =SUM(I30:I33) -> 17 | Z15: =SUM(J30:J33) -> 4 | ... AF15: =SUM(P30:P33) -> 637
B16: 08.30 - 08.45 | C16: 59 | D16: 23 | E16: 4 | F16: 9 | G16: 0 | H16: 0 | I16: 0 | J16: 0 | K16: 0 | L16: 0 | M16: 85 | N16: 0 | O16: =SUM(C16:L16,N16) -> 95 | P16: =SUM(C16:N16) -> 180 | R16: 1300-1400 | S16: =SUM(C34:C37) -> 281 | T16: =SUM(D34:D37) -> 71 | U16: =SUM(E34:E37) -> 26 | V16: =SUM(F34:F37) -> 19 | W16: =SUM(G34:G37) -> 2 | X16: =SUM(H34:H37) -> 1 | Y16: =SUM(I34:I37) -> 21 | Z16: =SUM(J34:J37) -> 6 | ... AF16: =SUM(P34:P37) -> 682
B17: 08.45 - 9.00 | C17: 81 | D17: 15 | E17: 5 | F17: 7 | G17: 0 | H17: 0 | I17: 0 | J17: 1 | K17: 0 | L17: 0 | M17: 106 | N17: 0 | O17: =SUM(C17:L17,N17) -> 109 | P17: =SUM(C17:N17) -> 215 | R17: 1400-1500 | S17: =SUM(C38:C41) -> 268 | T17: =SUM(D38:D41) -> 31 | U17: =SUM(E38:E41) -> 27 | V17: =SUM(F38:F41) -> 23 | W17: =SUM(G38:G41) -> 5 | X17: =SUM(H38:H41) -> 1 | Y17: =SUM(I38:I41) -> 17 | Z17: =SUM(J38:J41) -> 6 | ... AF17: =SUM(P38:P41) -> 643
B18: 09.00 - 09.15 | C18: 70 | D18: 20 | E18: 6 | F18: 8 | G18: 0 | H18: 0 | I18: 5 | J18: 1 | K18: 0 | L18: 0 | M18: 100 | N18: 0 | O18: =SUM(C18:L18,N18) -> 110 | P18: =SUM(C18:N18) -> 210 | R18: 1500-1600 | S18: =SUM(C42:C45) -> 379 | T18: =SUM(D42:D45) -> 81 | U18: =SUM(E42:E45) -> 30 | V18: =SUM(F42:F45) -> 75 | W18: =SUM(G42:G45) -> 5 | X18: =SUM(H42:H45) -> 0 | Y18: =SUM(I42:I45) -> 20 | Z18: =SUM(J42:J45) -> 6 | ... AF18: =SUM(P42:P45) -> 890
B19: 09.15 - 09.30 | C19: 71 | D19: 17 | E19: 7 | F19: 7 | G19: 0 | H19: 0 | I19: 6 | J19: 2 | K19: 0 | L19: 0 | M19: 109 | N19: 0 | O19: =SUM(C19:L19,N19) -> 110 | P19: =SUM(C19:N19) -> 219 | R19: 1600-1700 | S19: =SUM(C46:C49) -> 552 | T19: =SUM(D46:D49) -> 103 | U19: =SUM(E46:E49) -> 19 | V19: =SUM(F46:F49) -> 26 | W19: =SUM(G46:G49) -> 1 | X19: =SUM(H46:H49) -> 0 | Y19: =SUM(I46:I49) -> 19 | Z19: =SUM(J46:J49) -> 5 | ... AF19: =SUM(P46:P49) -> 994
B20: 09.30 - 09.45 | C20: 47 | D20: 20 | E20: 4 | F20: 12 | G20: 0 | H20: 0 | I20: 8 | J20: 2 | K20: 0 | L20: 0 | M20: 88 | N20: 0 | O20: =SUM(C20:L20,N20) -> 93 | P20: =SUM(C20:N20) -> 181 | R20: 1700-1800 | S20: =SUM(C50:C53) -> 628 | T20: =SUM(D50:D53) -> 103 | U20: =SUM(E50:E53) -> 26 | V20: =SUM(F50:F53) -> 31 | W20: =SUM(G50:G53) -> 1 | X20: =SUM(H50:H53) -> 0 | Y20: =SUM(I50:I53) -> 17 | Z20: =SUM(J50:J53) -> 3 | ... AF20: =SUM(P50:P53) -> 1124
B21: 09.45 - 10.00 | C21: 46 | D21: 14 | E21: 5 | F21: 10 | G21: 0 | H21: 0 | I21: 2 | J21: 3 | K21: 0 | L21: 0 | M21: 72 | N21: 0 | O21: =SUM(C21:L21,N21) -> 80 | P21: =SUM(C21:N21) -> 152 | R21: 1800-1900 | S21: =SUM(C54:C57) -> 565 | T21: =SUM(D54:D57) -> 105 | U21: =SUM(E54:E57) -> 17 | V21: =SUM(F54:F57) -> 46 | W21: =SUM(G54:G57) -> 2 | X21: =SUM(H54:H57) -> 1 | Y21: =SUM(I54:I57) -> 9 | Z21: =SUM(J54:J57) -> 2 | ... AF21: =SUM(P54:P57) -> 989
B22: 10.00 - 10.15 | C22: 56 | D22: 14 | E22: 4 | F22: 6 | G22: 0 | H22: 0 | I22: 6 | J22: 0 | K22: 0 | L22: 0 | M22: 85 | N22: 0 | O22: =SUM(C22:L22,N22) -> 86 | P22: =SUM(C22:N22) -> 171 | R22: AM Peak Hr | S22: =MAX(S10:S12) -> 369 | T22: =MAX(T10:T12) -> 87 | U22: =MAX(U10:U12) -> 22 | V22: =MAX(V10:V12) -> 39 | W22: =MAX(W10:W12) -> 0 | X22: =MAX(X10:X12) -> 1 | Y22: =MAX(Y10:Y12) -> 21 | Z22: =MAX(Z10:Z12) -> 8 | ... AF22: =MAX(AF10:AF12) -> 762
B23: 10.15 - 10.30 | C23: 78 | D23: 26 | E23: 5 | F23: 9 | G23: 0 | H23: 0 | I23: 5 | J23: 2 | K23: 0 | L23: 0 | M23: 86 | N23: 0 | O23: =SUM(C23:L23,N23) -> 125 | P23: =SUM(C23:N23) -> 211 | R23: IP Peak Hr | S23: =MAX(S13:S18) -> 379 | T23: =MAX(T13:T18) -> 82 | U23: =MAX(U13:U18) -> 30 | V23: =MAX(V13:V18) -> 75 | W23: =MAX(W13:W18) -> 5 | X23: =MAX(X13:X18) -> 1 | Y23: =MAX(Y13:Y18) -> 30 | Z23: =MAX(Z13:Z18) -> 7 | ... AF23: =MAX(AF13:AF18) -> 890
B24: 10.30 - 10.45 | C24: 76 | D24: 18 | E24: 4 | F24: 5 | G24: 0 | H24: 0 | I24: 8 | J24: 1 | K24: 0 | L24: 0 | M24: 73 | N24: 0 | O24: =SUM(C24:L24,N24) -> 112 | P24: =SUM(C24:N24) -> 185 | R24: PM Peak Hr | S24: =MAX(S19:S21) -> 628 | T24: =MAX(T19:T21) -> 105 | U24: =MAX(U19:U21) -> 26 | V24: =MAX(V19:V21) -> 46 | W24: =MAX(W19:W21) -> 2 | X24: =MAX(X19:X21) -> 1 | Y24: =MAX(Y19:Y21) -> 19 | Z24: =MAX(Z19:Z21) -> 5 | ... AF24: =MAX(AF19:AF21) -> 1124
B25: 10.45 - 11.00 | C25: 58 | D25: 14 | E25: 7 | F25: 6 | G25: 0 | H25: 0 | I25: 11 | J25: 4 | K25: 0 | L25: 0 | M25: 79 | N25: 0 | O25: =SUM(C25:L25,N25) -> 100 | P25: =SUM(C25:N25) -> 179 | R25: AM Period | S25: =SUM(S10:S12) -> 910 | T25: =SUM(T10:T12) -> 232 | U25: =SUM(U10:U12) -> 44 | V25: =SUM(V10:V12) -> 76 | W25: =SUM(W10:W12) -> 0 | X25: =SUM(X10:X12) -> 1 | Y25: =SUM(Y10:Y12) -> 22 | Z25: =SUM(Z10:Z12) -> 14 | ... AF25: =SUM(AF10:AF12) -> 2165
B26: 11.00 - 11.15 | C26: 61 | D26: 16 | E26: 6 | F26: 7 | G26: 0 | H26: 0 | I26: 7 | J26: 0 | K26: 0 | L26: 0 | M26: 68 | N26: 0 | O26: =SUM(C26:L26,N26) -> 97 | P26: =SUM(C26:N26) -> 165 | R26: IP Period | S26: =SUM(S13:S18) -> 1651 | T26: =SUM(T13:T18) -> 401 | U26: =SUM(U13:U18) -> 141 | V26: =SUM(V13:V18) -> 182 | W26: =SUM(W13:W18) -> 18 | X26: =SUM(X13:X18) -> 4 | Y26: =SUM(Y13:Y18) -> 130 | Z26: =SUM(Z13:Z18) -> 34 | ... AF26: =SUM(AF13:AF18) -> 4288
B27: 11.15 - 11.30 | C27: 61 | D27: 26 | E27: 5 | F27: 6 | G27: 0 | H27: 0 | I27: 4 | J27: 1 | K27: 0 | L27: 0 | M27: 93 | N27: 0 | O27: =SUM(C27:L27,N27) -> 103 | P27: =SUM(C27:N27) -> 196 | R27: PM Period | S27: =SUM(S19:S21) -> 1745 | T27: =SUM(T19:T21) -> 311 | U27: =SUM(U19:U21) -> 62 | V27: =SUM(V19:V21) -> 103 | W27: =SUM(W19:W21) -> 4 | X27: =SUM(X19:X21) -> 1 | Y27: =SUM(Y19:Y21) -> 45 | Z27: =SUM(Z19:Z21) -> 10 | ... AF27: =SUM(AF19:AF21) -> 3107
B28: 11.30 - 11.45 | C28: 59 | D28: 14 | E28: 4 | F28: 3 | G28: 0 | H28: 0 | I28: 10 | J28: 3 | K28: 0 | L28: 0 | M28: 66 | N28: 0 | O28: =SUM(C28:L28,N28) -> 93 | P28: =SUM(C28:N28) -> 159 | R28: 12 Hours | S28: =SUM(S10:S21) -> 4306 | T28: =SUM(T10:T21) -> 944 | U28: =SUM(U10:U21) -> 247 | V28: =SUM(V10:V21) -> 361 | W28: =SUM(W10:W21) -> 22 | X28: =SUM(X10:X21) -> 6 | Y28: =SUM(Y10:Y21) -> 197 | Z28: =SUM(Z10:Z21) -> 58 | ... AF28: =SUM(AF10:AF21) -> 9560
B29: 11.45 - 12.00 | C29: 52 | D29: 26 | E29: 3 | F29: 3 | G29: 1 | H29: 1 | I29: 4 | J29: 1 | K29: 1 | L29: 0 | M29: 78 | N29: 0 | O29: =SUM(C29:L29,N29) -> 92 | P29: =SUM(C29:N29) -> 170
B30: 12.00 - 12.15 | C30: 57 | D30: 22 | E30: 1 | F30: 8 | G30: 2 | H30: 1 | I30: 2 | J30: 2 | K30: 0 | L30: 0 | M30: 61 | N30: 0 | O30: =SUM(C30:L30,N30) -> 95 | P30: =SUM(C30:N30) -> 156
B31: 12.15 - 12.30 | C31: 58 | D31: 18 | E31: 4 | F31: 4 | G31: 3 | H31: 0 | I31: 3 | J31: 1 | K31: 2 | L31: 0 | M31: 74 | N31: 0 | O31: =SUM(C31:L31,N31) -> 93 | P31: =SUM(C31:N31) -> 167
B32: 12.30 - 12.45 | C32: 53 | D32: 16 | E32: 6 | F32: 3 | G32: 0 | H32: 0 | I32: 6 | J32: 0 | K32: 0 | L32: 0 | M32: 69 | N32: 0 | O32: =SUM(C32:L32,N32) -> 84 | P32: =SUM(C32:N32) -> 153
B33: 12.45 - 13.00 | C33: 54 | D33: 8 | E33: 9 | F33: 5 | G33: 0 | H33: 0 | I33: 6 | J33: 1 | K33: 0 | L33: 0 | M33: 78 | N33: 0 | O33: =SUM(C33:L33,N33) -> 83 | P33: =SUM(C33:N33) -> 161
B34: 13.00 - 13.15 | C34: 58 | D34: 15 | E34: 2 | F34: 6 | G34: 0 | H34: 0 | I34: 3 | J34: 4 | K34: 0 | L34: 0 | M34: 86 | N34: 0 | O34: =SUM(C34:L34,N34) -> 88 | P34: =SUM(C34:N34) -> 174
B35: 13.15 - 13.30 | C35: 65 | D35: 17 | E35: 4 | F35: 5 | G35: 0 | H35: 0 | I35: 5 | J35: 0 | K35: 2 | L35: 0 | M35: 67 | N35: 0 | O35: =SUM(C35:L35,N35) -> 98 | P35: =SUM(C35:N35) -> 165
B36: 13.30 - 13.45 | C36: 81 | D36: 17 | E36: 5 | F36: 2 | G36: 1 | H36: 0 | I36: 5 | J36: 0 | K36: 0 | L36: 1 | M36: 35 | N36: 0 | O36: =SUM(C36:L36,N36) -> 112 | P36: =SUM(C36:N36) -> 147
B37: 13.45 - 14.00 | C37: 77 | D37: 22 | E37: 15 | F37: 6 | G37: 1 | H37: 1 | I37: 8 | J37: 2 | K37: 1 | L37: 1 | M37: 62 | N37: 0 | O37: =SUM(C37:L37,N37) -> 134 | P37: =SUM(C37:N37) -> 196
B38: 14.00 - 14.15 | C38: 69 | D38: 4 | E38: 5 | F38: 2 | G38: 1 | H38: 1 | I38: 4 | J38: 0 | K38: 0 | L38: 0 | M38: 66 | N38: 0 | O38: =SUM(C38:L38,N38) -> 86 | P38: =SUM(C38:N38) -> 152
B39: 14.15 - 14.30 | C39: 61 | D39: 11 | E39: 7 | F39: 6 | G39: 0 | H39: 0 | I39: 4 | J39: 0 | K39: 0 | L39: 0 | M39: 69 | N39: 0 | O39: =SUM(C39:L39,N39) -> 89 | P39: =SUM(C39:N39) -> 158
B40: 14.30 - 14.45 | C40: 100 | D40: 9 | E40: 14 | F40: 11 | G40: 4 | H40: 0 | I40: 6 | J40: 4 | K40: 0 | L40: 0 | M40: 76 | N40: 0 | O40: =SUM(C40:L40,N40) -> 148 | P40: =SUM(C40:N40) -> 224
... B57: 18.45 - 19.00 | C57: 105 | D57: 19 | E57: 4 | F57: 7 | G57: 0 | H57: 0 | I57: 0 | J57: 1 | K57: 1 | L57: 0 | M57: 58 | N57: 0 | O57: =SUM(C57:L57,N57) -> 137 | P57: =SUM(C57:N57) -> 195
B58: Totals | C58: =SUM(C10:C57) -> 4306 | D58: =SUM(D10:D57) -> 944 | E58: =SUM(E10:E57) -> 247 | F58: =SUM(F10:F57) -> 361 | G58: =SUM(G10:G57) -> 22 | H58: =SUM(H10:H57) -> 6 | I58: =SUM(I10:I57) -> 197 | J58: =SUM(J10:J57) -> 58 | ... P58: =SUM(P10:P57) -> 9560
...

Sheet 29.07 Naalya-Ntinda
B1: Consultancy services for Preparation of Expressway Development Master Plan (EDMP) for Uganda
B2: MANUAL CLASSIFIED COUNT (MCC)
B3: ROAD NAME: | C3: ='29.07 Ntinda-Naalya'!C3:G3 -> MCC - C1 - STN38 - NAALYA EAST ROAD
C5: Date | D5: ='29.07 Ntinda-Naalya'!D5 -> 29.07.19 | F5: Location | G5: ='29.07 Ntinda-Naalya'!G5:H5 -> NAALYA ROUND ABOUT | J5: Surveyor | K5: ='29.07 Ntinda-Naalya'!K5:L5 -> HARRIET N/NASSIWA A/MUTE C/PHOEBY/KAZIBWE J/NAKAYE J.
C6: Dir. From | D6: NAALYA | F6: Dir. To | G6: NTINDA | J6: Supervisor | K6: ='29.07 Ntinda-Naalya'!K6:L6 -> STEVEN
B8: Time / Veh Type | R8: SUMMARY TRAFFIC VOLUMES
C9: 1. Car | D9: 2. Station Wagon | E9: 3. Pickups | F9: 4. Minibus, matatu | G9: 5. Medium bus | H9: 6. Large Bus | I9: 7. Light Truck | J9: 8. Medium Truck | K9: 9. Heavy truck | L9: 10. Truck Trailer | M9: 11. Motor cycles | N9: 12. Tractors | O9: Total Excl M/Cycles | P9: Total All | R9: Time | S9: 1. Car | T9: 2. Station Wagon | U9: 3. Pickups | V9: 4. Minibus, matatu | W9: 5. Medium bus | X9: 6. Large Bus | Y9: 7. Light Truck | Z9: 8. Medium Truck | AA9: 9. Heavy truck | AB9: 10. Truck Trailer | AC9: 11. Motorcycles | AD9: 12. Tractors, Graders | AE9: Total Excl M/ Cycles | AF9: Total All
B10: 07.00 - 07.15 | C10: 99 | D10: 53 | E10: 9 | F10: 4 | G10: 1 | H10: 0 | I10: 2 | J10: 2 | K10: 0 | L10: 0 | M10: 59 | N10: 0 | O10: =SUM(C10:L10,N10) -> 170 | P10: =SUM(C10:N10) -> 229 | R10: 0700-0800 | S10: =SUM(C10:C13) -> 507 | T10: =SUM(D10:D13) -> 309 | U10: =SUM(E10:E13) -> 57 | V10: =SUM(F10:F13) -> 21 | W10: =SUM(G10:G13) -> 2 | X10: =SUM(H10:H13) -> 0 | Y10: =SUM(I10:I13) -> 3 | Z10: =SUM(J10:J13) -> 3 | ... AF10: =SUM(P10:P13) -> 1232
B11: 07.15 - 07.30 | C11: 94 | D11: 75 | E11: 18 | F11: 5 | G11: 0 | H11: 0 | I11: 1 | J11: 0 | K11: 0 | L11: 0 | M11: 67 | N11: 0 | O11: =SUM(C11:L11,N11) -> 193 | P11: =SUM(C11:N11) -> 260 | R11: 0800-0900 | S11: =SUM(C14:C17) -> 410 | T11: =SUM(D14:D17) -> 245 | U11: =SUM(E14:E17) -> 54 | V11: =SUM(F14:F17) -> 35 | W11: =SUM(G14:G17) -> 1 | X11: =SUM(H14:H17) -> 0 | Y11: =SUM(I14:I17) -> 1 | Z11: =SUM(J14:J17) -> 1 | ... AF11: =SUM(P14:P17) -> 1276
B12: 07.30 - 07.45 | C12: 150 | D12: 85 | E12: 14 | F12: 4 | G12: 0 | H12: 0 | I12: 0 | J12: 0 | K12: 0 | L12: 0 | M12: 92 | N12: 0 | O12: =SUM(C12:L12,N12) -> 253 | P12: =SUM(C12:N12) -> 345 | R12: 0900-1000 | S12: =SUM(C18:C21) -> 334 | T12: =SUM(D18:D21) -> 176 | U12: =SUM(E18:E21) -> 52 | V12: =SUM(F18:F21) -> 37 | W12: =SUM(G18:G21) -> 0 | X12: =SUM(H18:H21) -> 0 | Y12: =SUM(I18:I21) -> 9 | Z12: =SUM(J18:J21) -> 9 | ... AF12: =SUM(P18:P21) -> 1004
B13: 07.45 - 08.00 | C13: 164 | D13: 96 | E13: 16 | F13: 8 | G13: 1 | H13: 0 | I13: 0 | J13: 1 | K13: 0 | L13: 0 | M13: 112 | N13: 0 | O13: =SUM(C13:L13,N13) -> 286 | P13: =SUM(C13:N13) -> 398 | R13: 1000-1100 | S13: =SUM(C22:C25) -> 298 | T13: =SUM(D22:D25) -> 170 | U13: =SUM(E22:E25) -> 43 | V13: =SUM(F22:F25) -> 32 | W13: =SUM(G22:G25) -> 3 | X13: =SUM(H22:H25) -> 0 | Y13: =SUM(I22:I25) -> 6 | Z13: =SUM(J22:J25) -> 12 | ... AF13: =SUM(P22:P25) -> 861
B14: 08.00 - 08.15 | C14: 146 | D14: 80 | E14: 18 | F14: 9 | G14: 0 | H14: 0 | I14: 0 | J14: 0 | K14: 0 | L14: 0 | M14: 129 | N14: 0 | O14: =SUM(C14:L14,N14) -> 253 | P14: =SUM(C14:N14) -> 382 | R14: 1100-1200 | S14: =SUM(C26:C29) -> 277 | T14: =SUM(D26:D29) -> 176 | U14: =SUM(E26:E29) -> 39 | V14: =SUM(F26:F29) -> 42 | W14: =SUM(G26:G29) -> 3 | X14: =SUM(H26:H29) -> 0 | Y14: =SUM(I26:I29) -> 11 | Z14: =SUM(J26:J29) -> 14 | ... AF14: =SUM(P26:P29) -> 887
B15: 08.15 - 08.30 | C15: 97 | D15: 58 | E15: 10 | F15: 10 | G15: 0 | H15: 0 | I15: 0 | J15: 1 | K15: 0 | L15: 0 | M15: 116 | N15: 0 | O15: =SUM(C15:L15,N15) -> 176 | P15: =SUM(C15:N15) -> 292 | R15: 1200-1300 | S15: =SUM(C30:C33) -> 249 | T15: =SUM(D30:D33) -> 0 | U15: =SUM(E30:E33) -> 0 | V15: =SUM(F30:F33) -> 0 | W15: =SUM(G30:G33) -> 0 | X15: =SUM(H30:H33) -> 2 | Y15: =SUM(I30:I33) -> 13 | Z15: =SUM(J30:J33) -> 12 | ... AF15: =SUM(P30:P33) -> 584
B16: 08.30 - 08.45 | C16: 92 | D16: 47 | E16: 15 | F16: 9 | G16: 0 | H16: 0 | I16: 0 | J16: 0 | K16: 0 | L16: 0 | M16: 136 | N16: 0 | O16: =SUM(C16:L16,N16) -> 163 | P16: =SUM(C16:N16) -> 299 | R16: 1300-1400 | S16: =SUM(C34:C37) -> 281 | T16: =SUM(D34:D37) -> 163 | U16: =SUM(E34:E37) -> 32 | V16: =SUM(F34:F37) -> 41 | W16: =SUM(G34:G37) -> 4 | X16: =SUM(H34:H37) -> 0 | Y16: =SUM(I34:I37) -> 9 | Z16: =SUM(J34:J37) -> 5 | ... AF16: =SUM(P34:P37) -> 775
B17: 08.45 - 9.00 | C17: 75 | D17: 60 | E17: 11 | F17: 7 | G17: 1 | H17: 0 | I17: 1 | J17: 0 | K17: 0 | L17: 0 | M17: 148 | N17: 0 | O17: =SUM(C17:L17,N17) -> 155 | P17: =SUM(C17:N17) -> 303 | R17: 1400-1500 | S17: =SUM(C38:C41) -> 199 | T17: =SUM(D38:D41) -> 108 | U17: =SUM(E38:E41) -> 28 | V17: =SUM(F38:F41) -> 34 | W17: =SUM(G38:G41) -> 4 | X17: =SUM(H38:H41) -> 0 | Y17: =SUM(I38:I41) -> 0 | Z17: =SUM(J38:J41) -> 10 | ... AF17: =SUM(P38:P41) -> 599
B18: 09.00 - 09.15 | C18: 81 | D18: 43 | E18: 15 | F18: 9 | G18: 0 | H18: 0 | I18: 2 | J18: 3 | K18: 0 | L18: 0 | M18: 106 | N18: 0 | O18: =SUM(C18:L18,N18) -> 153 | P18: =SUM(C18:N18) -> 259 | R18: 1500-1600 | S18: =SUM(C42:C45) -> 184 | T18: =SUM(D42:D45) -> 110 | U18: =SUM(E42:E45) -> 23 | V18: =SUM(F42:F45) -> 22 | W18: =SUM(G42:G45) -> 1 | X18: =SUM(H42:H45) -> 0 | Y18: =SUM(I42:I45) -> 12 | Z18: =SUM(J42:J45) -> 10 | ... AF18: =SUM(P42:P45) -> 668
B19: 09.15 - 09.30 | C19: 97 | D19: 63 | E19: 13 | F19: 9 | G19: 0 | H19: 0 | I19: 3 | J19: 3 | K19: 0 | L19: 0 | M19: 111 | N19: 0 | O19: =SUM(C19:L19,N19) -> 188 | P19: =SUM(C19:N19) -> 299 | R19: 1600-1700 | S19: =SUM(C46:C49) -> 244 | T19: =SUM(D46:D49) -> 148 | U19: =SUM(E46:E49) -> 33 | V19: =SUM(F46:F49) -> 41 | W19: =SUM(G46:G49) -> 8 | X19: =SUM(H46:H49) -> 0 | Y19: =SUM(I46:I49) -> 5 | Z19: =SUM(J46:J49) -> 7 | ... AF19: =SUM(P46:P49) -> 746
B20: 09.30 - 09.45 | C20: 81 | D20: 38 | E20: 10 | F20: 10 | G20: 0 | H20: 0 | I20: 3 | J20: 1 | K20: 0 | L20: 0 | M20: 77 | N20: 0 | O20: =SUM(C20:L20,N20) -> 143 | P20: =SUM(C20:N20) -> 220 | R20: 1700-1800 | S20: =SUM(C50:C53) -> 289 | T20: =SUM(D50:D53) -> 196 | U20: =SUM(E50:E53) -> 42 | V20: =SUM(F50:F53) -> 43 | W20: =SUM(G50:G53) -> 5 | X20: =SUM(H50:H53) -> 0 | Y20: =SUM(I50:I53) -> 5 | Z20: =SUM(J50:J53) -> 7 | ... AF20: =SUM(P50:P53) -> 847
B21: 09.45 - 10.00 | C21: 75 | D21: 32 | E21: 14 | F21: 9 | G21: 0 | H21: 0 | I21: 1 | J21: 2 | K21: 1 | L21: 0 | M21: 92 | N21: 0 | O21: =SUM(C21:L21,N21) -> 134 | P21: =SUM(C21:N21) -> 226 | R21: 1800-1900 | S21: =SUM(C54:C57) -> 203 | T21: =SUM(D54:D57) -> 115 | U21: =SUM(E54:E57) -> 31 | V21: =SUM(F54:F57) -> 35 | W21: =SUM(G54:G57) -> 2 | X21: =SUM(H54:H57) -> 6 | Y21: =SUM(I54:I57) -> 2 | Z21: =SUM(J54:J57) -> 1 | ... AF21: =SUM(P54:P57) -> 679
B22: 10.00 - 10.15 | C22: 85 | D22: 28 | E22: 7 | F22: 5 | G22: 0 | H22: 0 | I22: 1 | J22: 1 | K22: 0 | L22: 0 | M22: 61 | N22: 0 | O22: =SUM(C22:L22,N22) -> 127 | P22: =SUM(C22:N22) -> 188 | R22: AM Peak Hr | S22: =MAX(S10:S12) -> 507 | T22: =MAX(T10:T12) -> 309 | U22: =MAX(U10:U12) -> 57 | V22: =MAX(V10:V12) -> 37 | W22: =MAX(W10:W12) -> 2 | X22: =MAX(X10:X12) -> 0 | Y22: =MAX(Y10:Y12) -> 9 | Z22: =MAX(Z10:Z12) -> 9 | ... AF22: =MAX(AF10:AF12) -> 1276
B23: 10.15 - 10.30 | C23: 90 | D23: 57 | E23: 15 | F23: 11 | G23: 2 | H23: 0 | I23: 1 | J23: 4 | K23: 1 | L23: 0 | M23: 73 | N23: 0 | O23: =SUM(C23:L23,N23) -> 181 | P23: =SUM(C23:N23) -> 254 | R23: IP Peak Hr | S23: =MAX(S13:S18) -> 298 | T23: =MAX(T13:T18) -> 176 | U23: =MAX(U13:U18) -> 43 | V23: =MAX(V13:V18) -> 42 | W23: =MAX(W13:W18) -> 4 | X23: =MAX(X13:X18) -> 2 | Y23: =MAX(Y13:Y18) -> 13 | Z23: =MAX(Z13:Z18) -> 14 | ... AF23: =MAX(AF13:AF18) -> 887
B24: 10.30 - 10.45 | C24: 56 | D24: 44 | E24: 9 | F24: 6 | G24: 0 | H24: 0 | I24: 2 | J24: 5 | K24: 0 | L24: 0 | M24: 87 | N24: 0 | O24: =SUM(C24:L24,N24) -> 122 | P24: =SUM(C24:N24) -> 209 | R24: PM Peak Hr | S24: =MAX(S19:S21) -> 289 | T24: =MAX(T19:T21) -> 196 | U24: =MAX(U19:U21) -> 42 | V24: =MAX(V19:V21) -> 43 | W24: =MAX(W19:W21) -> 8 | X24: =MAX(X19:X21) -> 6 | Y24: =MAX(Y19:Y21) -> 5 | Z24: =MAX(Z19:Z21) -> 7 | ... AF24: =MAX(AF19:AF21) -> 847
B25: 10.45 - 11.00 | C25: 67 | D25: 41 | E25: 12 | F25: 10 | G25: 1 | H25: 0 | I25: 2 | J25: 2 | K25: 0 | L25: 0 | M25: 75 | N25: 0 | O25: =SUM(C25:L25,N25) -> 135 | P25: =SUM(C25:N25) -> 210 | R25: AM Period | S25: =SUM(S10:S12) -> 1251 | T25: =SUM(T10:T12) -> 730 | U25: =SUM(U10:U12) -> 163 | V25: =SUM(V10:V12) -> 93 | W25: =SUM(W10:W12) -> 3 | X25: =SUM(X10:X12) -> 0 | Y25: =SUM(Y10:Y12) -> 13 | Z25: =SUM(Z10:Z12) -> 13 | ... AF25: =SUM(AF10:AF12) -> 3512
B26: 11.00 - 11.15 | C26: 80 | D26: 37 | E26: 13 | F26: 15 | G26: 1 | H26: 0 | I26: 0 | J26: 1 | K26: 0 | L26: 0 | M26: 88 | N26: 0 | O26: =SUM(C26:L26,N26) -> 147 | P26: =SUM(C26:N26) -> 235 | R26: IP Period | S26: =SUM(S13:S18) -> 1488 | T26: =SUM(T13:T18) -> 727 | U26: =SUM(U13:U18) -> 165 | V26: =SUM(V13:V18) -> 171 | W26: =SUM(W13:W18) -> 15 | X26: =SUM(X13:X18) -> 2 | Y26: =SUM(Y13:Y18) -> 51 | Z26: =SUM(Z13:Z18) -> 63 | ... AF26: =SUM(AF13:AF18) -> 4374
B27: 11.15 - 11.30 | C27: 92 | D27: 65 | E27: 13 | F27: 17 | G27: 1 | H27: 0 | I27: 2 | J27: 4 | K27: 1 | L27: 0 | M27: 90 | N27: 0 | O27: =SUM(C27:L27,N27) -> 195 | P27: =SUM(C27:N27) -> 285 | R27: PM Period | S27: =SUM(S19:S21) -> 736 | T27: =SUM(T19:T21) -> 459 | U27: =SUM(U19:U21) -> 106 | V27: =SUM(V19:V21) -> 119 | W27: =SUM(W19:W21) -> 15 | X27: =SUM(X19:X21) -> 6 | Y27: =SUM(Y19:Y21) -> 12 | Z27: =SUM(Z19:Z21) -> 15 | ... AF27: =SUM(AF19:AF21) -> 2272
B28: 11.30 - 11.45 | C28: 49 | D28: 32 | E28: 6 | F28: 3 | G28: 0 | H28: 0 | I28: 6 | J28: 5 | K28: 1 | L28: 0 | M28: 77 | N28: 0 | O28: =SUM(C28:L28,N28) -> 102 | P28: =SUM(C28:N28) -> 179 | R28: 12 Hours | S28: =SUM(S10:S21) -> 3475 | T28: =SUM(T10:T21) -> 1916 | U28: =SUM(U10:U21) -> 434 | V28: =SUM(V10:V21) -> 383 | W28: =SUM(W10:W21) -> 33 | X28: =SUM(X10:X21) -> 8 | Y28: =SUM(Y10:Y21) -> 76 | Z28: =SUM(Z10:Z21) -> 91 | ... AF28: =SUM(AF10:AF21) -> 10158
B29: 11.45 - 12.00 | C29: 56 | D29: 42 | E29: 7 | F29: 7 | G29: 1 | H29: 0 | I29: 3 | J29: 4 | K29: 0 | L29: 0 | M29: 68 | N29: 0 | O29: =SUM(C29:L29,N29) -> 120 | P29: =SUM(C29:N29) -> 188
B30: 12.00 - 12.15 | C30: 49 | D30: 0 | E30: 0 | F30: 0 | G30: 0 | H30: 0 | I30: 1 | J30: 4 | K30: 1 | L30: 0 | M30: 88 | N30: 0 | O30: =SUM(C30:L30,N30) -> 55 | P30: =SUM(C30:N30) -> 143
B31: 12.15 - 12.30 | C31: 72 | D31: 0 | E31: 0 | F31: 0 | G31: 0 | H31: 1 | I31: 5 | J31: 4 | K31: 1 | L31: 0 | M31: 78 | N31: 0 | O31: =SUM(C31:L31,N31) -> 83 | P31: =SUM(C31:N31) -> 161
B32: 12.30 - 12.45 | C32: 58 | D32: 0 | E32: 0 | F32: 0 | G32: 0 | H32: 0 | I32: 3 | J32: 1 | K32: 0 | L32: 0 | M32: 70 | N32: 0 | O32: =SUM(C32:L32,N32) -> 62 | P32: =SUM(C32:N32) -> 132
B33: 12.45 - 13.00 | C33: 70 | D33: 0 | E33: 0 | F33: 0 | G33: 0 | H33: 1 | I33: 4 | J33: 3 | K33: 1 | L33: 0 | M33: 69 | N33: 0 | O33: =SUM(C33:L33,N33) -> 79 | P33: =SUM(C33:N33) -> 148
B34: 13.00 - 13.15 | C34: 69 | D34: 46 | E34: 8 | F34: 8 | G34: 0 | H34: 0 | I34: 4 | J34: 1 | K34: 0 | L34: 0 | M34: 64 | N34: 0 | O34: =SUM(C34:L34,N34) -> 136 | P34: =SUM(C34:N34) -> 200
B35: 13.15 - 13.30 | C35: 48 | D35: 41 | E35: 8 | F35: 11 | G35: 1 | H35: 0 | I35: 0 | J35: 2 | K35: 0 | L35: 0 | M35: 56 | N35: 0 | O35: =SUM(C35:L35,N35) -> 111 | P35: =SUM(C35:N35) -> 167
B36: 13.30 - 13.45 | C36: 64 | D36: 36 | E36: 6 | F36: 11 | G36: 2 | H36: 0 | I36: 1 | J36: 2 | K36: 1 | L36: 0 | M36: 60 | N36: 0 | O36: =SUM(C36:L36,N36) -> 123 | P36: =SUM(C36:N36) -> 183
B37: 13.45 - 14.00 | C37: 100 | D37: 40 | E37: 10 | F37: 11 | G37: 1 | H37: 0 | I37: 4 | J37: 0 | K37: 0 | L37: 0 | M37: 59 | N37: 0 | O37: =SUM(C37:L37,N37) -> 166 | P37: =SUM(C37:N37) -> 225
B38: 14.00 - 14.15 | C38: 45 | D38: 26 | E38: 13 | F38: 10 | G38: 0 | H38: 0 | I38: 0 | J38: 4 | K38: 3 | L38: 0 | M38: 49 | N38: 0 | O38: =SUM(C38:L38,N38) -> 101 | P38: =SUM(C38:N38) -> 150
B39: 14.15 - 14.30 | C39: 61 | D39: 37 | E39: 2 | F39: 11 | G39: 4 | H39: 0 | I39: 0 | J39: 3 | K39: 0 | L39: 0 | M39: 61 | N39: 0 | O39: =SUM(C39:L39,N39) -> 118 | P39: =SUM(C39:N39) -> 179
B40: 14.30 - 14.45 | C40: 48 | D40: 21 | E40: 4 | F40: 8 | G40: 0 | H40: 0 | I40: 0 | J40: 1 | K40: 3 | L40: 0 | M40: 45 | N40: 0 | O40: =SUM(C40:L40,N40) -> 85 | P40: =SUM(C40:N40) -> 130
... B57: 18.45 - 19.00 | C57: 46 | D57: 25 | E57: 5 | F57: 6 | G57: 1 | H57: 0 | I57: 1 | J57: 0 | K57: 0 | L57: 0 | M57: 72 | N57: 0 | O57: =SUM(C57:L57,N57) -> 84 | P57: =SUM(C57:N57) -> 156
B58: Totals | C58: =SUM(C10:C57) -> 3475 | D58: =SUM(D10:D57) -> 1916 | E58: =SUM(E10:E57) -> 434 | F58: =SUM(F10:F57) -> 383 | G58: =SUM(G10:G57) -> 33 | H58: =SUM(H10:H57) -> 8 | I58: =SUM(I10:I57) -> 76 | J58: =SUM(J10:J57) -> 91 | ... P58: =SUM(P10:P57) -> 10158
...

Sheet 30.07 Ntinda-Naalya
B1: Consultancy services for Preparation of Expressway Development Master Plan (EDMP) for Uganda
B2: MANUAL CLASSIFIED COUNT (MCC)
B3: ROAD NAME: | C3: ='29.07 Ntinda-Naalya'!C3:G3 -> MCC - C1 - STN38 - NAALYA EAST ROAD
C5: Date | D5: 30.07.19 | F5: Location | G5: ='29.07 Ntinda-Naalya'!G5:H5 -> NAALYA ROUND ABOUT | J5: Surveyor | K5: ='29.07 Ntinda-Naalya'!K5:L5 -> HARRIET N/NASSIWA A/MUTE C/PHOEBY/KAZIBWE J/NAKAYE J.
C6: Dir. From | D6: ='29.07 Ntinda-Naalya'!D6:E6 -> NTINDA | F6: Dir. To | G6: ='29.07 Ntinda-Naalya'!G6:H6 -> NAALYA | J6: Supervisor | K6: ='29.07 Ntinda-Naalya'!K6:L6 -> STEVEN
B8: Time / Veh Type | R8: SUMMARY TRAFFIC VOLUMES
C9: 1. Car | D9: 2. Station Wagon | E9: 3. Pickups | F9: 4. Minibus, matatu | G9: 5. Medium bus | H9: 6. Large Bus | I9: 7. Light Truck | J9: 8. Medium Truck | K9: 9. Heavy truck | L9: 10. Truck Trailer | M9: 11. Motor cycles | N9: 12. Tractors | O9: Total Excl M/Cycles | P9: Total All | R9: Time | S9: 1. Car | T9: 2. Station Wagon | U9: 3. Pickups | V9: 4. Minibus, matatu | W9: 5. Medium bus | X9: 6. Large Bus | Y9: 7. Light Truck | Z9: 8. Medium Truck | AA9: 9. Heavy truck | AB9: 10. Truck Trailer | AC9: 11. Motorcycles | AD9: 12. Tractors, Graders | AE9: Total Excl M/ Cycles | AF9: Total All
B10: 07.00 - 07.15 | C10: 98 | D10: 13 | E10: 0 | F10: 8 | G10: 0 | H10: 0 | I10: 0 | J10: 0 | K10: 1 | L10: 0 | M10: 34 | N10: 0 | O10: =SUM(C10:L10,N10) -> 120 | P10: =SUM(C10:N10) -> 154 | R10: 0700-0800 | S10: =SUM(C10:C13) -> 456 | T10: =SUM(D10:D13) -> 84 | U10: =SUM(E10:E13) -> 2 | V10: =SUM(F10:F13) -> 35 | W10: =SUM(G10:G13) -> 0 | X10: =SUM(H10:H13) -> 0 | Y10: =SUM(I10:I13) -> 2 | Z10: =SUM(J10:J13) -> 4 | ... AF10: =SUM(P10:P13) -> 799
B11: 07.15 - 07.30 | C11: 148 | D11: 25 | E11: 2 | F11: 9 | G11: 0 | H11: 0 | I11: 0 | J11: 2 | K11: 0 | L11: 0 | M11: 43 | N11: 0 | O11: =SUM(C11:L11,N11) -> 186 | P11: =SUM(C11:N11) -> 229 | R11: 0800-0900 | S11: =SUM(C14:C17) -> 288 | T11: =SUM(D14:D17) -> 127 | U11: =SUM(E14:E17) -> 15 | V11: =SUM(F14:F17) -> 35 | W11: =SUM(G14:G17) -> 0 | X11: =SUM(H14:H17) -> 1 | Y11: =SUM(I14:I17) -> 11 | Z11: =SUM(J14:J17) -> 4 | ... AF11: =SUM(P14:P17) -> 790
B12: 07.30 - 07.45 | C12: 98 | D12: 24 | E12: 0 | F12: 9 | G12: 0 | H12: 0 | I12: 0 | J12: 0 | K12: 0 | L12: 1 | M12: 57 | N12: 0 | O12: =SUM(C12:L12,N12) -> 132 | P12: =SUM(C12:N12) -> 189 | R12: 0900-1000 | S12: =SUM(C18:C21) -> 208 | T12: =SUM(D18:D21) -> 61 | U12: =SUM(E18:E21) -> 21 | V12: =SUM(F18:F21) -> 26 | W12: =SUM(G18:G21) -> 2 | X12: =SUM(H18:H21) -> 2 | Y12: =SUM(I18:I21) -> 25 | Z12: =SUM(J18:J21) -> 4 | ... AF12: =SUM(P18:P21) -> 678
B13: 07.45 - 08.00 | C13: 112 | D13: 22 | E13: 0 | F13: 9 | G13: 0 | H13: 0 | I13: 2 | J13: 2 | K13: 1 | L13: 1 | M13: 78 | N13: 0 | O13: =SUM(C13:L13,N13) -> 149 | P13: =SUM(C13:N13) -> 227 | R13: 1000-1100 | S13: =SUM(C22:C25) -> 218 | T13: =SUM(D22:D25) -> 58 | U13: =SUM(E22:E25) -> 24 | V13: =SUM(F22:F25) -> 29 | W13: =SUM(G22:G25) -> 1 | X13: =SUM(H22:H25) -> 2 | Y13: =SUM(I22:I25) -> 24 | Z13: =SUM(J22:J25) -> 8 | ... AF13: =SUM(P22:P25) -> 661
B14: 08.00 - 08.15 | C14: 79 | D14: 15 | E14: 1 | F14: 13 | G14: 0 | H14: 0 | I14: 4 | J14: 0 | K14: 0 | L14: 0 | M14: 72 | N14: 0 | O14: =SUM(C14:L14,N14) -> 112 | P14: =SUM(C14:N14) -> 184 | R14: 1100-1200 | S14: =SUM(C26:C29) -> 252 | T14: =SUM(D26:D29) -> 71 | U14: =SUM(E26:E29) -> 35 | V14: =SUM(F26:F29) -> 33 | W14: =SUM(G26:G29) -> 0 | X14: =SUM(H26:H29) -> 1 | Y14: =SUM(I26:I29) -> 14 | Z14: =SUM(J26:J29) -> 8 | ... AF14: =SUM(P26:P29) -> 693
B15: 08.15 - 08.30 | C15: 71 | D15: 81 | E15: 2 | F15: 7 | G15: 0 | H15: 0 | I15: 2 | J15: 1 | K15: 0 | L15: 0 | M15: 77 | N15: 0 | O15: =SUM(C15:L15,N15) -> 164 | P15: =SUM(C15:N15) -> 241 | R15: 1200-1300 | S15: =SUM(C30:C33) -> 241 | T15: =SUM(D30:D33) -> 74 | U15: =SUM(E30:E33) -> 22 | V15: =SUM(F30:F33) -> 22 | W15: =SUM(G30:G33) -> 5 | X15: =SUM(H30:H33) -> 4 | Y15: =SUM(I30:I33) -> 22 | Z15: =SUM(J30:J33) -> 7 | ... AF15: =SUM(P30:P33) -> 685
B16: 08.30 - 08.45 | C16: 73 | D16: 18 | E16: 5 | F16: 10 | G16: 0 | H16: 1 | I16: 2 | J16: 1 | K16: 0 | L16: 0 | M16: 63 | N16: 0 | O16: =SUM(C16:L16,N16) -> 110 | P16: =SUM(C16:N16) -> 173 | R16: 1300-1400 | S16: =SUM(C34:C37) -> 306 | T16: =SUM(D34:D37) -> 56 | U16: =SUM(E34:E37) -> 12 | V16: =SUM(F34:F37) -> 25 | W16: =SUM(G34:G37) -> 3 | X16: =SUM(H34:H37) -> 1 | Y16: =SUM(I34:I37) -> 20 | Z16: =SUM(J34:J37) -> 8 | ... AF16: =SUM(P34:P37) -> 758
B17: 08.45 - 9.00 | C17: 65 | D17: 13 | E17: 7 | F17: 5 | G17: 0 | H17: 0 | I17: 3 | J17: 2 | K17: 0 | L17: 0 | M17: 97 | N17: 0 | O17: =SUM(C17:L17,N17) -> 95 | P17: =SUM(C17:N17) -> 192 | R17: 1400-1500 | S17: =SUM(C38:C41) -> 282 | T17: =SUM(D38:D41) -> 57 | U17: =SUM(E38:E41) -> 28 | V17: =SUM(F38:F41) -> 26 | W17: =SUM(G38:G41) -> 0 | X17: =SUM(H38:H41) -> 3 | Y17: =SUM(I38:I41) -> 20 | Z17: =SUM(J38:J41) -> 6 | ... AF17: =SUM(P38:P41) -> 706
B18: 09.00 - 09.15 | C18: 60 | D18: 15 | E18: 4 | F18: 8 | G18: 0 | H18: 1 | I18: 7 | J18: 0 | K18: 1 | L18: 0 | M18: 91 | N18: 0 | O18: =SUM(C18:L18,N18) -> 96 | P18: =SUM(C18:N18) -> 187 | R18: 1500-1600 | S18: =SUM(C42:C45) -> 362 | T18: =SUM(D42:D45) -> 71 | U18: =SUM(E42:E45) -> 21 | V18: =SUM(F42:F45) -> 25 | W18: =SUM(G42:G45) -> 6 | X18: =SUM(H42:H45) -> 1 | Y18: =SUM(I42:I45) -> 25 | Z18: =SUM(J42:J45) -> 10 | ... AF18: =SUM(P42:P45) -> 738
B19: 09.15 - 09.30 | C19: 45 | D19: 12 | E19: 8 | F19: 5 | G19: 0 | H19: 0 | I19: 7 | J19: 1 | K19: 1 | L19: 0 | M19: 91 | N19: 0 | O19: =SUM(C19:L19,N19) -> 79 | P19: =SUM(C19:N19) -> 170 | R19: 1600-1700 | S19: =SUM(C46:C49) -> 516 | T19: =SUM(D46:D49) -> 113 | U19: =SUM(E46:E49) -> 14 | V19: =SUM(F46:F49) -> 37 | W19: =SUM(G46:G49) -> 4 | X19: =SUM(H46:H49) -> 7 | Y19: =SUM(I46:I49) -> 16 | Z19: =SUM(J46:J49) -> 13 | ... AF19: =SUM(P46:P49) -> 1071
B20: 09.30 - 09.45 | C20: 62 | D20: 19 | E20: 7 | F20: 4 | G20: 0 | H20: 1 | I20: 10 | J20: 2 | K20: 0 | L20: 0 | M20: 86 | N20: 0 | O20: =SUM(C20:L20,N20) -> 105 | P20: =SUM(C20:N20) -> 191 | R20: 1700-1800 | S20: =SUM(C50:C53) -> 657 | T20: =SUM(D50:D53) -> 123 | U20: =SUM(E50:E53) -> 17 | V20: =SUM(F50:F53) -> 37 | W20: =SUM(G50:G53) -> 2 | X20: =SUM(H50:H53) -> 1 | Y20: =SUM(I50:I53) -> 23 | Z20: =SUM(J50:J53) -> 5 | ... AF20: =SUM(P50:P53) -> 1253
B21: 09.45 - 10.00 | C21: 41 | D21: 15 | E21: 2 | F21: 9 | G21: 2 | H21: 0 | I21: 1 | J21: 1 | K21: 1 | L21: 0 | M21: 58 | N21: 0 | O21: =SUM(C21:L21,N21) -> 72 | P21: =SUM(C21:N21) -> 130 | R21: 1800-1900 | S21: =SUM(C54:C57) -> 541 | T21: =SUM(D54:D57) -> 117 | U21: =SUM(E54:E57) -> 12 | V21: =SUM(F54:F57) -> 21 | W21: =SUM(G54:G57) -> 2 | X21: =SUM(H54:H57) -> 2 | Y21: =SUM(I54:I57) -> 16 | Z21: =SUM(J54:J57) -> 12 | ... AF21: =SUM(P54:P57) -> 1027
B22: 10.00 - 10.15 | C22: 78 | D22: 16 | E22: 9 | F22: 13 | G22: 1 | H22: 1 | I22: 6 | J22: 0 | K22: 0 | L22: 0 | M22: 78 | N22: 0 | O22: =SUM(C22:L22,N22) -> 124 | P22: =SUM(C22:N22) -> 202 | R22: AM Peak Hr | S22: =MAX(S10:S12) -> 456 | T22: =MAX(T10:T12) -> 127 | U22: =MAX(U10:U12) -> 21 | V22: =MAX(V10:V12) -> 35 | W22: =MAX(W10:W12) -> 2 | X22: =MAX(X10:X12) -> 2 | Y22: =MAX(Y10:Y12) -> 25 | Z22: =MAX(Z10:Z12) -> 4 | ... AF22: =MAX(AF10:AF12) -> 799
B23: 10.15 - 10.30 | C23: 37 | D23: 11 | E23: 5 | F23: 6 | G23: 0 | H23: 0 | I23: 4 | J23: 4 | K23: 1 | L23: 1 | M23: 62 | N23: 0 | O23: =SUM(C23:L23,N23) -> 69 | P23: =SUM(C23:N23) -> 131 | R23: IP Peak Hr | S23: =MAX(S13:S18) -> 362 | T23: =MAX(T13:T18) -> 74 | U23: =MAX(U13:U18) -> 35 | V23: =MAX(V13:V18) -> 33 | W23: =MAX(W13:W18) -> 6 | X23: =MAX(X13:X18) -> 4 | Y23: =MAX(Y13:Y18) -> 25 | Z23: =MAX(Z13:Z18) -> 10 | ... AF23: =MAX(AF13:AF18) -> 758
B24: 10.30 - 10.45 | C24: 49 | D24: 17 | E24: 5 | F24: 4 | G24: 0 | H24: 1 | I24: 4 | J24: 3 | K24: 1 | L24: 1 | M24: 80 | N24: 0 | O24: =SUM(C24:L24,N24) -> 85 | P24: =SUM(C24:N24) -> 165 | R24: PM Peak Hr | S24: =MAX(S19:S21) -> 657 | T24: =MAX(T19:T21) -> 123 | U24: =MAX(U19:U21) -> 17 | V24: =MAX(V19:V21) -> 37 | W24: =MAX(W19:W21) -> 4 | X24: =MAX(X19:X21) -> 7 | Y24: =MAX(Y19:Y21) -> 23 | Z24: =MAX(Z19:Z21) -> 13 | ... AF24: =MAX(AF19:AF21) -> 1253
B25: 10.45 - 11.00 | C25: 54 | D25: 14 | E25: 5 | F25: 6 | G25: 0 | H25: 0 | I25: 10 | J25: 1 | K25: 1 | L25: 1 | M25: 71 | N25: 0 | O25: =SUM(C25:L25,N25) -> 92 | P25: =SUM(C25:N25) -> 163 | R25: AM Period | S25: =SUM(S10:S12) -> 952 | T25: =SUM(T10:T12) -> 272 | U25: =SUM(U10:U12) -> 38 | V25: =SUM(V10:V12) -> 96 | W25: =SUM(W10:W12) -> 2 | X25: =SUM(X10:X12) -> 3 | Y25: =SUM(Y10:Y12) -> 38 | Z25: =SUM(Z10:Z12) -> 12 | ... AF25: =SUM(AF10:AF12) -> 2267
B26: 11.00 - 11.15 | C26: 59 | D26: 19 | E26: 4 | F26: 8 | G26: 0 | H26: 0 | I26: 3 | J26: 4 | K26: 0 | L26: 0 | M26: 64 | N26: 0 | O26: =SUM(C26:L26,N26) -> 97 | P26: =SUM(C26:N26) -> 161 | R26: IP Period | S26: =SUM(S13:S18) -> 1661 | T26: =SUM(T13:T18) -> 387 | U26: =SUM(U13:U18) -> 142 | V26: =SUM(V13:V18) -> 160 | W26: =SUM(W13:W18) -> 15 | X26: =SUM(X13:X18) -> 12 | Y26: =SUM(Y13:Y18) -> 125 | Z26: =SUM(Z13:Z18) -> 47 | ... AF26: =SUM(AF13:AF18) -> 4241
B27: 11.15 - 11.30 | C27: 48 | D27: 14 | E27: 8 | F27: 9 | G27: 0 | H27: 1 | I27: 5 | J27: 2 | K27: 0 | L27: 0 | M27: 83 | N27: 0 | O27: =SUM(C27:L27,N27) -> 87 | P27: =SUM(C27:N27) -> 170 | R27: PM Period | S27: =SUM(S19:S21) -> 1714 | T27: =SUM(T19:T21) -> 353 | U27: =SUM(U19:U21) -> 43 | V27: =SUM(V19:V21) -> 95 | W27: =SUM(W19:W21) -> 8 | X27: =SUM(X19:X21) -> 10 | Y27: =SUM(Y19:Y21) -> 55 | Z27: =SUM(Z19:Z21) -> 30 | ... AF27: =SUM(AF19:AF21) -> 3351
B28: 11.30 - 11.45 | C28: 69 | D28: 13 | E28: 13 | F28: 8 | G28: 0 | H28: 0 | I28: 4 | J28: 0 | K28: 1 | L28: 1 | M28: 57 | N28: 0 | O28: =SUM(C28:L28,N28) -> 109 | P28: =SUM(C28:N28) -> 166 | R28: 12 Hours | S28: =SUM(S10:S21) -> 4327 | T28: =SUM(T10:T21) -> 1012 | U28: =SUM(U10:U21) -> 223 | V28: =SUM(V10:V21) -> 351 | W28: =SUM(W10:W21) -> 25 | X28: =SUM(X10:X21) -> 25 | Y28: =SUM(Y10:Y21) -> 218 | Z28: =SUM(Z10:Z21) -> 89 | ... AF28: =SUM(AF10:AF21) -> 9859
B29: 11.45 - 12.00 | C29: 76 | D29: 25 | E29: 10 | F29: 8 | G29: 0 | H29: 0 | I29: 2 | J29: 2 | K29: 0 | L29: 0 | M29: 73 | N29: 0 | O29: =SUM(C29:L29,N29) -> 123 | P29: =SUM(C29:N29) -> 196
B30: 12.00 - 12.15 | C30: 42 | D30: 17 | E30: 3 | F30: 2 | G30: 5 | H30: 3 | I30: 4 | J30: 2 | K30: 1 | L30: 0 | M30: 60 | N30: 0 | O30: =SUM(C30:L30,N30) -> 79 | P30: =SUM(C30:N30) -> 139
B31: 12.15 - 12.30 | C31: 71 | D31: 16 | E31: 5 | F31: 6 | G31: 0 | H31: 0 | I31: 5 | J31: 0 | K31: 0 | L31: 0 | M31: 87 | N31: 0 | O31: =SUM(C31:L31,N31) -> 103 | P31: =SUM(C31:N31) -> 190
B32: 12.30 - 12.45 | C32: 64 | D32: 13 | E32: 9 | F32: 9 | G32: 0 | H32: 1 | I32: 9 | J32: 3 | K32: 2 | L32: 2 | M32: 66 | N32: 0 | O32: =SUM(C32:L32,N32) -> 112 | P32: =SUM(C32:N32) -> 178
B33: 12.45 - 13.00 | C33: 64 | D33: 28 | E33: 5 | F33: 5 | G33: 0 | H33: 0 | I33: 4 | J33: 2 | K33: 1 | L33: 0 | M33: 69 | N33: 0 | O33: =SUM(C33:L33,N33) -> 109 | P33: =SUM(C33:N33) -> 178
B34: 13.00 - 13.15 | C34: 57 | D34: 13 | E34: 4 | F34: 6 | G34: 0 | H34: 1 | I34: 4 | J34: 4 | K34: 1 | L34: 0 | M34: 51 | N34: 0 | O34: =SUM(C34:L34,N34) -> 90 | P34: =SUM(C34:N34) -> 141
B35: 13.15 - 13.30 | C35: 55 | D35: 11 | E35: 2 | F35: 6 | G35: 0 | H35: 0 | I35: 6 | J35: 1 | K35: 0 | L35: 0 | M35: 49 | N35: 0 | O35: =SUM(C35:L35,N35) -> 81 | P35: =SUM(C35:N35) -> 130
B36: 13.30 - 13.45 | C36: 105 | D36: 15 | E36: 2 | F36: 8 | G36: 0 | H36: 0 | I36: 3 | J36: 1 | K36: 0 | L36: 0 | M36: 125 | N36: 0 | O36: =SUM(C36:L36,N36) -> 134 | P36: =SUM(C36:N36) -> 259
B37: 13.45 - 14.00 | C37: 89 | D37: 17 | E37: 4 | F37: 5 | G37: 3 | H37: 0 | I37: 7 | J37: 2 | K37: 0 | L37: 0 | M37: 101 | N37: 0 | O37: =SUM(C37:L37,N37) -> 127 | P37: =SUM(C37:N37) -> 228
B38: 14.00 - 14.15 | C38: 71 | D38: 13 | E38: 7 | F38: 7 | G38: 0 | H38: 2 | I38: 7 | J38: 1 | K38: 1 | L38: 1 | M38: 46 | N38: 0 | O38: =SUM(C38:L38,N38) -> 110 | P38: =SUM(C38:N38) -> 156
B39: 14.15 - 14.30 | C39: 64 | D39: 12 | E39: 10 | F39: 9 | G39: 0 | H39: 0 | I39: 5 | J39: 1 | K39: 2 | L39: 0 | M39: 90 | N39: 0 | O39: =SUM(C39:L39,N39) -> 103 | P39: =SUM(C39:N39) -> 193
B40: 14.30 - 14.45 | C40: 76 | D40: 13 | E40: 7 | F40: 6 | G40: 0 | H40: 0 | I40: 3 | J40: 0 | K40: 0 | L40: 0 | M40: 66 | N40: 0 | O40: =SUM(C40:L40,N40) -> 105 | P40: =SUM(C40:N40) -> 171
... B57: 18.45 - 19.00 | C57: 105 | D57: 31 | E57: 3 | F57: 2 | G57: 0 | H57: 1 | I57: 0 | J57: 5 | K57: 0 | L57: 0 | M57: 55 | N57: 0 | O57: =SUM(C57:L57,N57) -> 147 | P57: =SUM(C57:N57) -> 202
B58: Totals | C58: =SUM(C10:C57) -> 4327 | D58: =SUM(D10:D57) -> 1012 | E58: =SUM(E10:E57) -> 223 | F58: =SUM(F10:F57) -> 351 | G58: =SUM(G10:G57) -> 25 | H58: =SUM(H10:H57) -> 25 | I58: =SUM(I10:I57) -> 218 | J58: =SUM(J10:J57) -> 89 | ... P58: =SUM(P10:P57) -> 9859
...

Sheet 30.07 Naalya-Ntinda
B1: Consultancy services for Preparation of Expressway Development Master Plan (EDMP) for Uganda
B2: MANUAL CLASSIFIED COUNT (MCC)
B3: ROAD NAME: | C3: ='29.07 Naalya-Ntinda'!C3:G3 -> MCC - C1 - STN38 - NAALYA EAST ROAD
C5: Date | D5: ='30.07 Ntinda-Naalya'!D5 -> 30.07.19 | F5: Location | G5: ='29.07 Ntinda-Naalya'!G5:H5 -> NAALYA ROUND ABOUT | J5: Surveyor | K5: ='29.07 Ntinda-Naalya'!K5:L5 -> HARRIET N/NASSIWA A/MUTE C/PHOEBY/KAZIBWE J/NAKAYE J.
C6: Dir. From | D6: ='29.07 Naalya-Ntinda'!D6:E6 -> NAALYA | F6: Dir. To | G6: ='29.07 Naalya-Ntinda'!G6:H6 -> NTINDA | J6: Supervisor | K6: ='29.07 Ntinda-Naalya'!K6:L6 -> STEVEN
B8: Time / Veh Type | R8: SUMMARY TRAFFIC VOLUMES
C9: 1. Car | D9: 2. Station Wagon | E9: 3. Pickups | F9: 4. Minibus, matatu | G9: 5. Medium bus | H9: 6. Large Bus | I9: 7. Light Truck | J9: 8. Medium Truck | K9: 9. Heavy truck | L9: 10. Truck Trailer | M9: 11. Motor cycles | N9: 12. Tractors | O9: Total Excl M/Cycles | P9: Total All | R9: Time | S9: 1. Car | T9: 2. Station Wagon | U9: 3. Pickups | V9: 4. Minibus, matatu | W9: 5. Medium bus | X9: 6. Large Bus | Y9: 7. Light Truck | Z9: 8. Medium Truck | AA9: 9. Heavy truck | AB9: 10. Truck Trailer | AC9: 11. Motorcycles | AD9: 12. Tractors, Graders | AE9: Total Excl M/ Cycles | AF9: Total All
B10: 07.00 - 07.15 | C10: 43 | D10: 40 | E10: 6 | F10: 5 | G10: 0 | H10: 0 | I10: 1 | J10: 1 | K10: 0 | L10: 0 | M10: 40 | N10: 0 | O10: =SUM(C10:L10,N10) -> 96 | P10: =SUM(C10:N10) -> 136 | R10: 0700-0800 | S10: =SUM(C10:C13) -> 451 | T10: =SUM(D10:D13) -> 254 | U10: =SUM(E10:E13) -> 40 | V10: =SUM(F10:F13) -> 38 | W10: =SUM(G10:G13) -> 3 | X10: =SUM(H10:H13) -> 0 | Y10: =SUM(I10:I13) -> 9 | Z10: =SUM(J10:J13) -> 7 | ... AF10: =SUM(P10:P13) -> 1151
B11: 07.15 - 07.30 | C11: 125 | D11: 80 | E11: 13 | F11: 7 | G11: 0 | H11: 0 | I11: 1 | J11: 4 | K11: 0 | L11: 0 | M11: 73 | N11: 0 | O11: =SUM(C11:L11,N11) -> 230 | P11: =SUM(C11:N11) -> 303 | R11: 0800-0900 | S11: =SUM(C14:C17) -> 404 | T11: =SUM(D14:D17) -> 253 | U11: =SUM(E14:E17) -> 31 | V11: =SUM(F14:F17) -> 30 | W11: =SUM(G14:G17) -> 1 | X11: =SUM(H14:H17) -> 0 | Y11: =SUM(I14:I17) -> 8 | Z11: =SUM(J14:J17) -> 7 | ... AF11: =SUM(P14:P17) -> 1166
B12: 07.30 - 07.45 | C12: 140 | D12: 86 | E12: 13 | F12: 11 | G12: 3 | H12: 0 | I12: 4 | J12: 1 | K12: 0 | L12: 0 | M12: 104 | N12: 0 | O12: =SUM(C12:L12,N12) -> 258 | P12: =SUM(C12:N12) -> 362 | R12: 0900-1000 | S12: =SUM(C18:C21) -> 255 | T12: =SUM(D18:D21) -> 160 | U12: =SUM(E18:E21) -> 32 | V12: =SUM(F18:F21) -> 32 | W12: =SUM(G18:G21) -> 1 | X12: =SUM(H18:H21) -> 0 | Y12: =SUM(I18:I21) -> 8 | Z12: =SUM(J18:J21) -> 2 | ... AF12: =SUM(P18:P21) -> 887
B13: 07.45 - 08.00 | C13: 143 | D13: 48 | E13: 8 | F13: 15 | G13: 0 | H13: 0 | I13: 3 | J13: 1 | K13: 0 | L13: 0 | M13: 132 | N13: 0 | O13: =SUM(C13:L13,N13) -> 218 | P13: =SUM(C13:N13) -> 350 | R13: 1000-1100 | S13: =SUM(C22:C25) -> 210 | T13: =SUM(D22:D25) -> 126 | U13: =SUM(E22:E25) -> 25 | V13: =SUM(F22:F25) -> 55 | W13: =SUM(G22:G25) -> 7 | X13: =SUM(H22:H25) -> 0 | Y13: =SUM(I22:I25) -> 9 | Z13: =SUM(J22:J25) -> 10 | ... AF13: =SUM(P22:P25) -> 708
B14: 08.00 - 08.15 | C14: 115 | D14: 85 | E14: 12 | F14: 9 | G14: 0 | H14: 0 | I14: 1 | J14: 5 | K14: 1 | L14: 0 | M14: 127 | N14: 0 | O14: =SUM(C14:L14,N14) -> 228 | P14: =SUM(C14:N14) -> 355 | R14: 1100-1200 | S14: =SUM(C26:C29) -> 204 | T14: =SUM(D26:D29) -> 156 | U14: =SUM(E26:E29) -> 28 | V14: =SUM(F26:F29) -> 56 | W14: =SUM(G26:G29) -> 2 | X14: =SUM(H26:H29) -> 0 | Y14: =SUM(I26:I29) -> 17 | Z14: =SUM(J26:J29) -> 5 | ... AF14: =SUM(P26:P29) -> 777
B15: 08.15 - 08.30 | C15: 125 | D15: 62 | E15: 5 | F15: 9 | G15: 0 | H15: 0 | I15: 4 | J15: 2 | K15: 0 | L15: 0 | M15: 87 | N15: 0 | O15: =SUM(C15:L15,N15) -> 207 | P15: =SUM(C15:N15) -> 294 | R15: 1200-1300 | S15: =SUM(C30:C33) -> 191 | T15: =SUM(D30:D33) -> 110 | U15: =SUM(E30:E33) -> 31 | V15: =SUM(F30:F33) -> 29 | W15: =SUM(G30:G33) -> 2 | X15: =SUM(H30:H33) -> 1 | Y15: =SUM(I30:I33) -> 7 | Z15: =SUM(J30:J33) -> 6 | ... AF15: =SUM(P30:P33) -> 688
B16: 08.30 - 08.45 | C16: 103 | D16: 62 | E16: 5 | F16: 9 | G16: 0 | H16: 0 | I16: 2 | J16: 0 | K16: 0 | L16: 0 | M16: 105 | N16: 0 | O16: =SUM(C16:L16,N16) -> 181 | P16: =SUM(C16:N16) -> 286 | R16: 1300-1400 | S16: =SUM(C34:C37) -> 158 | T16: =SUM(D34:D37) -> 96 | U16: =SUM(E34:E37) -> 21 | V16: =SUM(F34:F37) -> 33 | W16: =SUM(G34:G37) -> 5 | X16: =SUM(H34:H37) -> 0 | Y16: =SUM(I34:I37) -> 7 | Z16: =SUM(J34:J37) -> 6 | ... AF16: =SUM(P34:P37) -> 578
B17: 08.45 - 9.00 | C17: 61 | D17: 44 | E17: 9 | F17: 3 | G17: 1 | H17: 0 | I17: 1 | J17: 0 | K17: 0 | L17: 0 | M17: 112 | N17: 0 | O17: =SUM(C17:L17,N17) -> 119 | P17: =SUM(C17:N17) -> 231 | R17: 1400-1500 | S17: =SUM(C38:C41) -> 174 | T17: =SUM(D38:D41) -> 123 | U17: =SUM(E38:E41) -> 28 | V17: =SUM(F38:F41) -> 36 | W17: =SUM(G38:G41) -> 7 | X17: =SUM(H38:H41) -> 0 | Y17: =SUM(I38:I41) -> 8 | Z17: =SUM(J38:J41) -> 12 | ... AF17: =SUM(P38:P41) -> 648
B18: 09.00 - 09.15 | C18: 61 | D18: 44 | E18: 5 | F18: 10 | G18: 0 | H18: 0 | I18: 2 | J18: 0 | K18: 0 | L18: 0 | M18: 111 | N18: 0 | O18: =SUM(C18:L18,N18) -> 122 | P18: =SUM(C18:N18) -> 233 | R18: 1500-1600 | S18: =SUM(C42:C45) -> 189 | T18: =SUM(D42:D45) -> 139 | U18: =SUM(E42:E45) -> 29 | V18: =SUM(F42:F45) -> 30 | W18: =SUM(G42:G45) -> 4 | X18: =SUM(H42:H45) -> 0 | Y18: =SUM(I42:I45) -> 10 | Z18: =SUM(J42:J45) -> 12 | ... AF18: =SUM(P42:P45) -> 683
B19: 09.15 - 09.30 | C19: 67 | D19: 40 | E19: 11 | F19: 5 | G19: 0 | H19: 0 | I19: 4 | J19: 0 | K19: 0 | L19: 0 | M19: 95 | N19: 0 | O19: =SUM(C19:L19,N19) -> 127 | P19: =SUM(C19:N19) -> 222 | R19: 1600-1700 | S19: =SUM(C46:C49) -> 281 | T19: =SUM(D46:D49) -> 187 | U19: =SUM(E46:E49) -> 43 | V19: =SUM(F46:F49) -> 38 | W19: =SUM(G46:G49) -> 7 | X19: =SUM(H46:H49) -> 0 | Y19: =SUM(I46:I49) -> 7 | Z19: =SUM(J46:J49) -> 4 | ... AF19: =SUM(P46:P49) -> 908
B20: 09.30 - 09.45 | C20: 73 | D20: 48 | E20: 11 | F20: 8 | G20: 1 | H20: 0 | I20: 1 | J20: 1 | K20: 0 | L20: 0 | M20: 98 | N20: 0 | O20: =SUM(C20:L20,N20) -> 143 | P20: =SUM(C20:N20) -> 241 | R20: 1700-1800 | S20: =SUM(C50:C53) -> 252 | T20: =SUM(D50:D53) -> 180 | U20: =SUM(E50:E53) -> 31 | V20: =SUM(F50:F53) -> 36 | W20: =SUM(G50:G53) -> 4 | X20: =SUM(H50:H53) -> 0 | Y20: =SUM(I50:I53) -> 14 | Z20: =SUM(J50:J53) -> 6 | ... AF20: =SUM(P50:P53) -> 843
B21: 09.45 - 10.00 | C21: 54 | D21: 28 | E21: 5 | F21: 9 | G21: 0 | H21: 0 | I21: 1 | J21: 1 | K21: 0 | L21: 0 | M21: 93 | N21: 0 | O21: =SUM(C21:L21,N21) -> 98 | P21: =SUM(C21:N21) -> 191 | R21: 1800-1900 | S21: =SUM(C54:C57) -> 169 | T21: =SUM(D54:D57) -> 104 | U21: =SUM(E54:E57) -> 30 | V21: =SUM(F54:F57) -> 33 | W21: =SUM(G54:G57) -> 1 | X21: =SUM(H54:H57) -> 5 | Y21: =SUM(I54:I57) -> 2 | Z21: =SUM(J54:J57) -> 0 | ... AF21: =SUM(P54:P57) -> 654
B22: 10.00 - 10.15 | C22: 60 | D22: 30 | E22: 9 | F22: 12 | G22: 0 | H22: 0 | I22: 1 | J22: 2 | K22: 0 | L22: 0 | M22: 65 | N22: 0 | O22: =SUM(C22:L22,N22) -> 114 | P22: =SUM(C22:N22) -> 179 | R22: AM Peak Hr | S22: =MAX(S10:S12) -> 451 | T22: =MAX(T10:T12) -> 254 | U22: =MAX(U10:U12) -> 40 | V22: =MAX(V10:V12) -> 38 | W22: =MAX(W10:W12) -> 3 | X22: =MAX(X10:X12) -> 0 | Y22: =MAX(Y10:Y12) -> 9 | Z22: =MAX(Z10:Z12) -> 7 | ... AF22: =MAX(AF10:AF12) -> 1166
B23: 10.15 - 10.30 | C23: 62 | D23: 45 | E23: 4 | F23: 17 | G23: 1 | H23: 0 | I23: 2 | J23: 3 | K23: 0 | L23: 0 | M23: 78 | N23: 0 | O23: =SUM(C23:L23,N23) -> 134 | P23: =SUM(C23:N23) -> 212 | R23: IP Peak Hr | S23: =MAX(S13:S18) -> 210 | T23: =MAX(T13:T18) -> 156 | U23: =MAX(U13:U18) -> 31 | V23: =MAX(V13:V18) -> 56 | W23: =MAX(W13:W18) -> 7 | X23: =MAX(X13:X18) -> 1 | Y23: =MAX(Y13:Y18) -> 17 | Z23: =MAX(Z13:Z18) -> 12 | ... AF23: =MAX(AF13:AF18) -> 777
B24: 10.30 - 10.45 | C24: 50 | D24: 28 | E24: 5 | F24: 13 | G24: 5 | H24: 0 | I24: 2 | J24: 4 | K24: 1 | L24: 1 | M24: 69 | N24: 0 | O24: =SUM(C24:L24,N24) -> 109 | P24: =SUM(C24:N24) -> 178 | R24: PM Peak Hr | S24: =MAX(S19:S21) -> 281 | T24: =MAX(T19:T21) -> 187 | U24: =MAX(U19:U21) -> 43 | V24: =MAX(V19:V21) -> 38 | W24: =MAX(W19:W21) -> 7 | X24: =MAX(X19:X21) -> 5 | Y24: =MAX(Y19:Y21) -> 14 | Z24: =MAX(Z19:Z21) -> 6 | ... AF24: =MAX(AF19:AF21) -> 908
B25: 10.45 - 11.00 | C25: 38 | D25: 23 | E25: 7 | F25: 13 | G25: 1 | H25: 0 | I25: 4 | J25: 1 | K25: 0 | L25: 0 | M25: 52 | N25: 0 | O25: =SUM(C25:L25,N25) -> 87 | P25: =SUM(C25:N25) -> 139 | R25: AM Period | S25: =SUM(S10:S12) -> 1110 | T25: =SUM(T10:T12) -> 667 | U25: =SUM(U10:U12) -> 103 | V25: =SUM(V10:V12) -> 100 | W25: =SUM(W10:W12) -> 5 | X25: =SUM(X10:X12) -> 0 | Y25: =SUM(Y10:Y12) -> 25 | Z25: =SUM(Z10:Z12) -> 16 | ... AF25: =SUM(AF10:AF12) -> 3204
B26: 11.00 - 11.15 | C26: 55 | D26: 44 | E26: 8 | F26: 15 | G26: 0 | H26: 0 | I26: 4 | J26: 0 | K26: 0 | L26: 0 | M26: 79 | N26: 0 | O26: =SUM(C26:L26,N26) -> 126 | P26: =SUM(C26:N26) -> 205 | R26: IP Period | S26: =SUM(S13:S18) -> 1126 | T26: =SUM(T13:T18) -> 750 | U26: =SUM(U13:U18) -> 162 | V26: =SUM(V13:V18) -> 239 | W26: =SUM(W13:W18) -> 27 | X26: =SUM(X13:X18) -> 1 | Y26: =SUM(Y13:Y18) -> 58 | Z26: =SUM(Z13:Z18) -> 51 | ... AF26: =SUM(AF13:AF18) -> 4082
B27: 11.15 - 11.30 | C27: 43 | D27: 50 | E27: 8 | F27: 19 | G27: 1 | H27: 0 | I27: 6 | J27: 1 | K27: 1 | L27: 1 | M27: 81 | N27: 0 | O27: =SUM(C27:L27,N27) -> 130 | P27: =SUM(C27:N27) -> 211 | R27: PM Period | S27: =SUM(S19:S21) -> 702 | T27: =SUM(T19:T21) -> 471 | U27: =SUM(U19:U21) -> 104 | V27: =SUM(V19:V21) -> 107 | W27: =SUM(W19:W21) -> 12 | X27: =SUM(X19:X21) -> 5 | Y27: =SUM(Y19:Y21) -> 23 | Z27: =SUM(Z19:Z21) -> 10 | ... AF27: =SUM(AF19:AF21) -> 2405
B28: 11.30 - 11.45 | C28: 70 | D28: 37 | E28: 8 | F28: 15 | G28: 0 | H28: 0 | I28: 5 | J28: 1 | K28: 0 | L28: 1 | M28: 74 | N28: 0 | O28: =SUM(C28:L28,N28) -> 137 | P28: =SUM(C28:N28) -> 211 | R28: 12 Hours | S28: =SUM(S10:S21) -> 2938 | T28: =SUM(T10:T21) -> 1888 | U28: =SUM(U10:U21) -> 369 | V28: =SUM(V10:V21) -> 446 | W28: =SUM(W10:W21) -> 44 | X28: =SUM(X10:X21) -> 6 | Y28: =SUM(Y10:Y21) -> 106 | Z28: =SUM(Z10:Z21) -> 77 | ... AF28: =SUM(AF10:AF21) -> 9691
B29: 11.45 - 12.00 | C29: 36 | D29: 25 | E29: 4 | F29: 7 | G29: 1 | H29: 0 | I29: 2 | J29: 3 | K29: 0 | L29: 0 | M29: 72 | N29: 0 | O29: =SUM(C29:L29,N29) -> 78 | P29: =SUM(C29:N29) -> 150
B30: 12.00 - 12.15 | C30: 53 | D30: 23 | E30: 12 | F30: 8 | G30: 0 | H30: 0 | I30: 2 | J30: 1 | K30: 0 | L30: 0 | M30: 81 | N30: 0 | O30: =SUM(C30:L30,N30) -> 99 | P30: =SUM(C30:N30) -> 180
B31: 12.15 - 12.30 | C31: 35 | D31: 24 | E31: 8 | F31: 5 | G31: 2 | H31: 0 | I31: 2 | J31: 2 | K31: 0 | L31: 0 | M31: 86 | N31: 0 | O31: =SUM(C31:L31,N31) -> 78 | P31: =SUM(C31:N31) -> 164
B32: 12.30 - 12.45 | C32: 55 | D32: 33 | E32: 5 | F32: 11 | G32: 0 | H32: 1 | I32: 0 | J32: 0 | K32: 0 | L32: 0 | M32: 77 | N32: 0 | O32: =SUM(C32:L32,N32) -> 105 | P32: =SUM(C32:N32) -> 182
B33: 12.45 - 13.00 | C33: 48 | D33: 30 | E33: 6 | F33: 5 | G33: 0 | H33: 0 | I33: 3 | J33: 3 | K33: 0 | L33: 1 | M33: 66 | N33: 0 | O33: =SUM(C33:L33,N33) -> 96 | P33: =SUM(C33:N33) -> 162
B34: 13.00 - 13.15 | C34: 44 | D34: 20 | E34: 6 | F34: 7 | G34: 1 | H34: 0 | I34: 2 | J34: 2 | K34: 0 | L34: 0 | M34: 59 | N34: 0 | O34: =SUM(C34:L34,N34) -> 82 | P34: =SUM(C34:N34) -> 141
B35: 13.15 - 13.30 | C35: 39 | D35: 17 | E35: 7 | F35: 7 | G35: 1 | H35: 0 | I35: 2 | J35: 3 | K35: 0 | L35: 0 | M35: 64 | N35: 0 | O35: =SUM(C35:L35,N35) -> 76 | P35: =SUM(C35:N35) -> 140
B36: 13.30 - 13.45 | C36: 46 | D36: 37 | E36: 5 | F36: 13 | G36: 3 | H36: 0 | I36: 0 | J36: 1 | K36: 0 | L36: 0 | M36: 71 | N36: 0 | O36: =SUM(C36:L36,N36) -> 105 | P36: =SUM(C36:N36) -> 176
B37: 13.45 - 14.00 | C37: 29 | D37: 22 | E37: 3 | F37: 6 | G37: 0 | H37: 0 | I37: 3 | J37: 0 | K37: 0 | L37: 0 | M37: 58 | N37: 0 | O37: =SUM(C37:L37,N37) -> 63 | P37: =SUM(C37:N37) -> 121
B38: 14.00 - 14.15 | C38: 38 | D38: 33 | E38: 5 | F38: 11 | G38: 0 | H38: 0 | I38: 2 | J38: 3 | K38: 0 | L38: 0 | M38: 67 | N38: 0 | O38: =SUM(C38:L38,N38) -> 92 | P38: =SUM(C38:N38) -> 159
B39: 14.15 - 14.30 | C39: 53 | D39: 33 | E39: 6 | F39: 7 | G39: 2 | H39: 0 | I39: 2 | J39: 2 | K39: 0 | L39: 0 | M39: 50 | N39: 0 | O39: =SUM(C39:L39,N39) -> 105 | P39: =SUM(C39:N39) -> 155
B40: 14.30 - 14.45 | C40: 30 | D40: 29 | E40: 7 | F40: 8 | G40: 3 | H40: 0 | I40: 2 | J40: 3 | K40: 0 | L40: 1 | M40: 79 | N40: 0 | O40: =SUM(C40:L40,N40) -> 83 | P40: =SUM(C40:N40) -> 162
... B57: 18.45 - 19.00 | C57: 50 | D57: 30 | E57: 3 | F57: 5 | G57: 1 | H57: 2 | I57: 0 | J57: 0 | K57: 0 | L57: 0 | M57: 82 | N57: 0 | O57: =SUM(C57:L57,N57) -> 91 | P57: =SUM(C57:N57) -> 173
B58: Totals | C58: =SUM(C10:C57) -> 2938 | D58: =SUM(D10:D57) -> 1888 | E58: =SUM(E10:E57) -> 369 | F58: =SUM(F10:F57) -> 446 | G58: =SUM(G10:G57) -> 44 | H58: =SUM(H10:H57) -> 6 | I58: =SUM(I10:I57) -> 106 | J58: =SUM(J10:J57) -> 77 | ... P58: =SUM(P10:P57) -> 9691
...

Sheet 31.07 Ntinda-Naalya
B1: Consultancy services for Preparation of Expressway Development Master Plan (EDMP) for Uganda
B2: MANUAL CLASSIFIED COUNT (MCC)
B3: ROAD NAME: | C3: ='29.07 Ntinda-Naalya'!C3:G3 -> MCC - C1 - STN38 - NAALYA EAST ROAD
C5: Date | D5: 31.07.19 | F5: Location | G5: ='29.07 Ntinda-Naalya'!G5:H5 -> NAALYA ROUND ABOUT | J5: Surveyor | K5: ='29.07 Ntinda-Naalya'!K5:L5 -> HARRIET N/NASSIWA A/MUTE C/PHOEBY/KAZIBWE J/NAKAYE J.
C6: Dir. From | D6: ='29.07 Ntinda-Naalya'!D6:E6 -> NTINDA | F6: Dir. To | G6: ='29.07 Ntinda-Naalya'!G6:H6 -> NAALYA | J6: Supervisor | K6: ='29.07 Ntinda-Naalya'!K6:L6 -> STEVEN
B8: Time / Veh Type | R8: SUMMARY TRAFFIC VOLUMES
C9: 1. Car | D9: 2. Station Wagon | E9: 3. Pickups | F9: 4. Minibus, matatu | G9: 5. Medium bus | H9: 6. Large Bus | I9: 7. Light Truck | J9: 8. Medium Truck | K9: 9. Heavy truck | L9: 10. Truck Trailer | M9: 11. Motor cycles | N9: 12. Tractors | O9: Total Excl M/Cycles | P9: Total All | R9: Time | S9: 1. Car | T9: 2. Station Wagon | U9: 3. Pickups | V9: 4. Minibus, matatu | W9: 5. Medium bus | X9: 6. Large Bus | Y9: 7. Light Truck | Z9: 8. Medium Truck | AA9: 9. Heavy truck | AB9: 10. Truck Trailer | AC9: 11. Motorcycles | AD9: 12. Tractors, Graders | AE9: Total Excl M/ Cycles | AF9: Total All
B10: 07.00 - 07.15 | C10: 102 | D10: 11 | E10: 12 | F10: 9 | G10: 0 | H10: 0 | I10: 0 | J10: 0 | K10: 0 | L10: 1 | M10: 59 | N10: 0 | O10: =SUM(C10:L10,N10) -> 135 | P10: =SUM(C10:N10) -> 194 | R10: 0700-0800 | S10: =SUM(C10:C13) -> 492 | T10: =SUM(D10:D13) -> 67 | U10: =SUM(E10:E13) -> 21 | V10: =SUM(F10:F13) -> 32 | W10: =SUM(G10:G13) -> 1 | X10: =SUM(H10:H13) -> 0 | Y10: =SUM(I10:I13) -> 15 | Z10: =SUM(J10:J13) -> 2 | ... AF10: =SUM(P10:P13) -> 848
B11: 07.15 - 07.30 | C11: 120 | D11: 16 | E11: 3 | F11: 11 | G11: 0 | H11: 0 | I11: 5 | J11: 1 | K11: 0 | L11: 0 | M11: 48 | N11: 0 | O11: =SUM(C11:L11,N11) -> 156 | P11: =SUM(C11:N11) -> 204 | R11: 0800-0900 | S11: =SUM(C14:C17) -> 318 | T11: =SUM(D14:D17) -> 85 | U11: =SUM(E14:E17) -> 12 | V11: =SUM(F14:F17) -> 50 | W11: =SUM(G14:G17) -> 1 | X11: =SUM(H14:H17) -> 2 | Y11: =SUM(I14:I17) -> 13 | Z11: =SUM(J14:J17) -> 4 | ... AF11: =SUM(P14:P17) -> 743
B12: 07.30 - 07.45 | C12: 161 | D12: 17 | E12: 0 | F12: 9 | G12: 0 | H12: 0 | I12: 4 | J12: 1 | K12: 0 | L12: 0 | M12: 52 | N12: 0 | O12: =SUM(C12:L12,N12) -> 192 | P12: =SUM(C12:N12) -> 244 | R12: 0900-1000 | S12: =SUM(C18:C21) -> 236 | T12: =SUM(D18:D21) -> 80 | U12: =SUM(E18:E21) -> 15 | V12: =SUM(F18:F21) -> 35 | W12: =SUM(G18:G21) -> 0 | X12: =SUM(H18:H21) -> 3 | Y12: =SUM(I18:I21) -> 14 | Z12: =SUM(J18:J21) -> 3 | ... AF12: =SUM(P18:P21) -> 629
B13: 07.45 - 08.00 | C13: 109 | D13: 23 | E13: 6 | F13: 3 | G13: 1 | H13: 0 | I13: 6 | J13: 0 | K13: 1 | L13: 0 | M13: 57 | N13: 0 | O13: =SUM(C13:L13,N13) -> 149 | P13: =SUM(C13:N13) -> 206 | R13: 1000-1100 | S13: =SUM(C22:C25) -> 224 | T13: =SUM(D22:D25) -> 51 | U13: =SUM(E22:E25) -> 18 | V13: =SUM(F22:F25) -> 24 | W13: =SUM(G22:G25) -> 0 | X13: =SUM(H22:H25) -> 1 | Y13: =SUM(I22:I25) -> 21 | Z13: =SUM(J22:J25) -> 9 | ... AF13: =SUM(P22:P25) -> 590
B14: 08.00 - 08.15 | C14: 92 | D14: 24 | E14: 2 | F14: 18 | G14: 1 | H14: 1 | I14: 2 | J14: 0 | K14: 2 | L14: 0 | M14: 48 | N14: 0 | O14: =SUM(C14:L14,N14) -> 142 | P14: =SUM(C14:N14) -> 190 | R14: 1100-1200 | S14: =SUM(C26:C29) -> 243 | T14: =SUM(D26:D29) -> 60 | U14: =SUM(E26:E29) -> 14 | V14: =SUM(F26:F29) -> 30 | W14: =SUM(G26:G29) -> 0 | X14: =SUM(H26:H29) -> 2 | Y14: =SUM(I26:I29) -> 23 | Z14: =SUM(J26:J29) -> 5 | ... AF14: =SUM(P26:P29) -> 584
B15: 08.15 - 08.30 | C15: 99 | D15: 15 | E15: 2 | F15: 9 | G15: 0 | H15: 0 | I15: 7 | J15: 3 | K15: 0 | L15: 0 | M15: 74 | N15: 0 | O15: =SUM(C15:L15,N15) -> 135 | P15: =SUM(C15:N15) -> 209 | R15: 1200-1300 | S15: =SUM(C30:C33) -> 228 | T15: =SUM(D30:D33) -> 72 | U15: =SUM(E30:E33) -> 15 | V15: =SUM(F30:F33) -> 37 | W15: =SUM(G30:G33) -> 1 | X15: =SUM(H30:H33) -> 1 | Y15: =SUM(I30:I33) -> 15 | Z15: =SUM(J30:J33) -> 10 | ... AF15: =SUM(P30:P33) -> 567
B16: 08.30 - 08.45 | C16: 56 | D16: 29 | E16: 1 | F16: 14 | G16: 0 | H16: 1 | I16: 2 | J16: 0 | K16: 0 | L16: 0 | M16: 87 | N16: 0 | O16: =SUM(C16:L16,N16) -> 103 | P16: =SUM(C16:N16) -> 190 | R16: 1300-1400 | S16: =SUM(C34:C37) -> 260 | T16: =SUM(D34:D37) -> 29 | U16: =SUM(E34:E37) -> 29 | V16: =SUM(F34:F37) -> 22 | W16: =SUM(G34:G37) -> 1 | X16: =SUM(H34:H37) -> 1 | Y16: =SUM(I34:I37) -> 20 | Z16: =SUM(J34:J37) -> 5 | ... AF16: =SUM(P34:P37) -> 622
B17: 08.45 - 9.00 | C17: 71 | D17: 17 | E17: 7 | F17: 9 | G17: 0 | H17: 0 | I17: 2 | J17: 1 | K17: 0 | L17: 0 | M17: 47 | N17: 0 | O17: =SUM(C17:L17,N17) -> 107 | P17: =SUM(C17:N17) -> 154 | R17: 1400-1500 | S17: =SUM(C38:C41) -> 307 | T17: =SUM(D38:D41) -> 91 | U17: =SUM(E38:E41) -> 24 | V17: =SUM(F38:F41) -> 34 | W17: =SUM(G38:G41) -> 6 | X17: =SUM(H38:H41) -> 2 | Y17: =SUM(I38:I41) -> 16 | Z17: =SUM(J38:J41) -> 4 | ... AF17: =SUM(P38:P41) -> 807
B18: 09.00 - 09.15 | C18: 61 | D18: 23 | E18: 1 | F18: 6 | G18: 0 | H18: 1 | I18: 1 | J18: 1 | K18: 1 | L18: 0 | M18: 60 | N18: 0 | O18: =SUM(C18:L18,N18) -> 95 | P18: =SUM(C18:N18) -> 155 | R18: 1500-1600 | S18: =SUM(C42:C45) -> 357 | T18: =SUM(D42:D45) -> 84 | U18: =SUM(E42:E45) -> 11 | V18: =SUM(F42:F45) -> 25 | W18: =SUM(G42:G45) -> 3 | X18: =SUM(H42:H45) -> 2 | Y18: =SUM(I42:I45) -> 6 | Z18: =SUM(J42:J45) -> 14 | ... AF18: =SUM(P42:P45) -> 748
B19: 09.15 - 09.30 | C19: 52 | D19: 26 | E19: 6 | F19: 13 | G19: 0 | H19: 0 | I19: 5 | J19: 0 | K19: 1 | L19: 0 | M19: 64 | N19: 0 | O19: =SUM(C19:L19,N19) -> 103 | P19: =SUM(C19:N19) -> 167 | R19: 1600-1700 | S19: =SUM(C46:C49) -> 562 | T19: =SUM(D46:D49) -> 109 | U19: =SUM(E46:E49) -> 11 | V19: =SUM(F46:F49) -> 36 | W19: =SUM(G46:G49) -> 2 | X19: =SUM(H46:H49) -> 0 | Y19: =SUM(I46:I49) -> 18 | Z19: =SUM(J46:J49) -> 7 | ... AF19: =SUM(P46:P49) -> 997
B20: 09.30 - 09.45 | C20: 58 | D20: 17 | E20: 4 | F20: 6 | G20: 0 | H20: 1 | I20: 4 | J20: 1 | K20: 0 | L20: 0 | M20: 63 | N20: 0 | O20: =SUM(C20:L20,N20) -> 91 | P20: =SUM(C20:N20) -> 154 | R20: 1700-1800 | S20: =SUM(C50:C53) -> 611 | T20: =SUM(D50:D53) -> 107 | U20: =SUM(E50:E53) -> 23 | V20: =SUM(F50:F53) -> 37 | W20: =SUM(G50:G53) -> 3 | X20: =SUM(H50:H53) -> 0 | Y20: =SUM(I50:I53) -> 8 | Z20: =SUM(J50:J53) -> 8 | ... AF20: =SUM(P50:P53) -> 1090
B21: 09.45 - 10.00 | C21: 65 | D21: 14 | E21: 4 | F21: 10 | G21: 0 | H21: 1 | I21: 4 | J21: 1 | K21: 1 | L21: 0 | M21: 53 | N21: 0 | O21: =SUM(C21:L21,N21) -> 100 | P21: =SUM(C21:N21) -> 153 | R21: 1800-1900 | S21: =SUM(C54:C57) -> 663 | T21: =SUM(D54:D57) -> 127 | U21: =SUM(E54:E57) -> 10 | V21: =SUM(F54:F57) -> 47 | W21: =SUM(G54:G57) -> 10 | X21: =SUM(H54:H57) -> 2 | Y21: =SUM(I54:I57) -> 21 | Z21: =SUM(J54:J57) -> 10 | ... AF21: =SUM(P54:P57) -> 1195
B22: 10.00 - 10.15 | C22: 70 | D22: 16 | E22: 5 | F22: 6 | G22: 0 | H22: 0 | I22: 6 | J22: 2 | K22: 0 | L22: 0 | M22: 49 | N22: 0 | O22: =SUM(C22:L22,N22) -> 105 | P22: =SUM(C22:N22) -> 154 | R22: AM Peak Hr | S22: =MAX(S10:S12) -> 492 | T22: =MAX(T10:T12) -> 85 | U22: =MAX(U10:U12) -> 21 | V22: =MAX(V10:V12) -> 50 | W22: =MAX(W10:W12) -> 1 | X22: =MAX(X10:X12) -> 3 | Y22: =MAX(Y10:Y12) -> 15 | Z22: =MAX(Z10:Z12) -> 4 | ... AF22: =MAX(AF10:AF12) -> 848
B23: 10.15 - 10.30 | C23: 71 | D23: 14 | E23: 9 | F23: 6 | G23: 0 | H23: 1 | I23: 0 | J23: 1 | K23: 0 | L23: 0 | M23: 55 | N23: 0 | O23: =SUM(C23:L23,N23) -> 102 | P23: =SUM(C23:N23) -> 157 | R23: IP Peak Hr | S23: =MAX(S13:S18) -> 357 | T23: =MAX(T13:T18) -> 91 | U23: =MAX(U13:U18) -> 29 | V23: =MAX(V13:V18) -> 37 | W23: =MAX(W13:W18) -> 6 | X23: =MAX(X13:X18) -> 2 | Y23: =MAX(Y13:Y18) -> 23 | Z23: =MAX(Z13:Z18) -> 14 | ... AF23: =MAX(AF13:AF18) -> 807
B24: 10.30 - 10.45 | C24: 43 | D24: 7 | E24: 4 | F24: 4 | G24: 0 | H24: 0 | I24: 10 | J24: 4 | K24: 0 | L24: 0 | M24: 71 | N24: 0 | O24: =SUM(C24:L24,N24) -> 72 | P24: =SUM(C24:N24) -> 143 | R24: PM Peak Hr | S24: =MAX(S19:S21) -> 663 | T24: =MAX(T19:T21) -> 127 | U24: =MAX(U19:U21) -> 23 | V24: =MAX(V19:V21) -> 47 | W24: =MAX(W19:W21) -> 10 | X24: =MAX(X19:X21) -> 2 | Y24: =MAX(Y19:Y21) -> 21 | Z24: =MAX(Z19:Z21) -> 10 | ... AF24: =MAX(AF19:AF21) -> 1195
B25: 10.45 - 11.00 | C25: 40 | D25: 14 | E25: 0 | F25: 8 | G25: 0 | H25: 0 | I25: 5 | J25: 2 | K25: 0 | L25: 0 | M25: 67 | N25: 0 | O25: =SUM(C25:L25,N25) -> 69 | P25: =SUM(C25:N25) -> 136 | R25: AM Period | S25: =SUM(S10:S12) -> 1046 | T25: =SUM(T10:T12) -> 232 | U25: =SUM(U10:U12) -> 48 | V25: =SUM(V10:V12) -> 117 | W25: =SUM(W10:W12) -> 2 | X25: =SUM(X10:X12) -> 5 | Y25: =SUM(Y10:Y12) -> 42 | Z25: =SUM(Z10:Z12) -> 9 | ... AF25: =SUM(AF10:AF12) -> 2220
B26: 11.00 - 11.15 | C26: 51 | D26: 15 | E26: 6 | F26: 11 | G26: 0 | H26: 1 | I26: 7 | J26: 2 | K26: 0 | L26: 0 | M26: 59 | N26: 0 | O26: =SUM(C26:L26,N26) -> 93 | P26: =SUM(C26:N26) -> 152 | R26: IP Period | S26: =SUM(S13:S18) -> 1619 | T26: =SUM(T13:T18) -> 387 | U26: =SUM(U13:U18) -> 111 | V26: =SUM(V13:V18) -> 172 | W26: =SUM(W13:W18) -> 11 | X26: =SUM(X13:X18) -> 9 | Y26: =SUM(Y13:Y18) -> 101 | Z26: =SUM(Z13:Z18) -> 47 | ... AF26: =SUM(AF13:AF18) -> 3918
