Workbook
Name Veh_Type: ENTEBBE!$H$8:$H$245
Name zones: #REF!
Name Zones_Ndeke: #REF!

Sheet ENTEBBE
C1: Consultancy services for Preparation of Expressway Development Master Plan (EDMP) for Uganda
C2: Stated Preferance Survey
D4: Town | E4: ENTEBBE | I4: Interviewer: | J4: DENIS,DOWMDA,CLAIRE,ANNA | N4: Supervisor: | O4: Dennis. | R4: Coded By: | S4: STEPHEN .N | W4: Chkd By: | X4: Deo B. M
B6: Date | C6: Time (24-h format) | D6: Veh_Reg_No. | E6: Driver or Passenger? D/P | F6: Mode No. | G6: Mode Description | H6: Veh_Type | I6: Veh_Type Desc | J6: Gender (M/F) | K6: Age Bracket No. | L6: Age Bracket Desc. | M6: Origin_Address | P6: Origin_Purpose | Q6: Origin-Purpose Desc | R6: Destination_Address | U6: Destination_Purpose | V6: Destination_Purpose Desc | W6: Journey_Purpose | X6: Cost of Trip (UGX) | Y6: Journey Dist (Km) | Z6: Journey Time (Hrs) | AA6: Profession No. | AB6: Profession Desc. | AC6: Monthly Income No. | AD6: Monthly Income | AE6: Rank of Issues NOT OK with Journey | AJ6: Would You Use Xpressways? Y/N | AK6: Pay How Much? (UGX) | AL6: Origin_Zone | AM6: Dest_Zone
M7: Village or Town | N7: District | O7: Country | R7: Village or Town | S7: District | T7: Country | AE7: Journey Time | AF7: Cost of Journey | AG7: Comfort | AH7: Safety | AI7: Reliability
B8: 43765 | C8: 0.64305556 | E8: D | F8: 2 | G8: =VLOOKUP(F8,Key!$A$17:$B$21,2,FALSE) -> Road Vehicle | H8: 1 | I8: =VLOOKUP(H8,Key!$A$2:$B$13,2,FALSE) -> Car | J8: F | K8: 1 | L8: =VLOOKUP(K8,Key!$A$24:$B$29,2,FALSE) -> 20-29 | M8: AIRPORT | N8: WAKISO | O8: UG | P8: 2 | Q8: =VLOOKUP(P8,Key!$E$2:$F$9,2,FALSE) -> Work | R8: KAJJANSI | S8: WAKISO | T8: UG | U8: 1 | V8: =VLOOKUP(U8,Key!$E$2:$F$9,2,FALSE) -> Home | W8: =Q8&"-"&V8 -> Work-Home | X8: 10000 | Y8: 31 | Z8: 0.5 | AA8: 4 | AB8: =VLOOKUP(AA8,Key!$C$20:$D$29,2,FALSE) -> Office Worker | AC8: 2 | AD8: =VLOOKUP(AC8,Key!$E$20:$F$24,2,FALSE) -> 300,000-500,000 | AE8: 1 | AF8: 1 | AG8: 1 | AH8: 1 | AI8: 1 | AJ8: Y | AK8: 3000
B9: 43765 | C9: 0.58333333 | E9: D | F9: 2 | G9: =VLOOKUP(F9,Key!$A$17:$B$21,2,FALSE) -> Road Vehicle | H9: 1 | I9: =VLOOKUP(H9,Key!$A$2:$B$13,2,FALSE) -> Car | J9: F | K9: 1 | L9: =VLOOKUP(K9,Key!$A$24:$B$29,2,FALSE) -> 20-29 | M9: KATWE | N9: KAMPALA | O9: UG | P9: 2 | Q9: =VLOOKUP(P9,Key!$E$2:$F$9,2,FALSE) -> Work | R9: KITORO | S9: WAKISO | T9: UG | U9: 2 | V9: =VLOOKUP(U9,Key!$E$2:$F$9,2,FALSE) -> Work | W9: =Q9&"-"&V9 -> Work-Work | X9: 25000 | Y9: 38 | Z9: 2 | AA9: 6 | AB9: =VLOOKUP(AA9,Key!$C$20:$D$29,2,FALSE) -> Businessman | AC9: 2 | AD9: =VLOOKUP(AC9,Key!$E$20:$F$24,2,FALSE) -> 300,000-500,000 | AE9: 1 | AF9: 1 | AG9: 1 | AH9: 2 | AI9: 1 | AJ9: Y | AK9: 5000
B10: 43765 | C10: 0.55833333 | E10: D | F10: 2 | G10: =VLOOKUP(F10,Key!$A$17:$B$21,2,FALSE) -> Road Vehicle | H10: 1 | I10: =VLOOKUP(H10,Key!$A$2:$B$13,2,FALSE) -> Car | J10: F | K10: 1 | L10: =VLOOKUP(K10,Key!$A$24:$B$29,2,FALSE) -> 20-29 | M10: MAKINDYE | N10: KAMPALA | O10: UG | P10: 1 | Q10: =VLOOKUP(P10,Key!$E$2:$F$9,2,FALSE) -> Home | R10: ERO BEACH | S10: WAKISO | T10: UG | U10: 6 | V10: =VLOOKUP(U10,Key!$E$2:$F$9,2,FALSE) -> Leisure/Social | W10: =Q10&"-"&V10 -> Home-Leisure/Social | X10: 40000 | Y10: 38 | Z10: 2 | AA10: 4 | AB10: =VLOOKUP(AA10,Key!$C$20:$D$29,2,FALSE) -> Office Worker | AC10: 3 | AD10: =VLOOKUP(AC10,Key!$E$20:$F$24,2,FALSE) -> 500,000-750,000 | AE10: 5 | AF10: 1 | AG10: 1 | AH10: 5 | AI10: 1 | AJ10: Y | AK10: 2000
B11: 43765 | C11: 0.52291667 | E11: D | F11: 2 | G11: =VLOOKUP(F11,Key!$A$17:$B$21,2,FALSE) -> Road Vehicle | H11: 1 | I11: =VLOOKUP(H11,Key!$A$2:$B$13,2,FALSE) -> Car | J11: F | K11: 1 | L11: =VLOOKUP(K11,Key!$A$24:$B$29,2,FALSE) -> 20-29 | M11: NSAMBYA | N11: KAMPALA | O11: UG | P11: 1 | Q11: =VLOOKUP(P11,Key!$E$2:$F$9,2,FALSE) -> Home | R11: KITORO | S11: WAKISO | T11: UG | U11: 1 | V11: =VLOOKUP(U11,Key!$E$2:$F$9,2,FALSE) -> Home | W11: =Q11&"-"&V11 -> Home-Home | X11: 33000 | Y11: 37 | Z11: 1 | AA11: 6 | AB11: =VLOOKUP(AA11,Key!$C$20:$D$29,2,FALSE) -> Businessman | AC11: 4 | AD11: =VLOOKUP(AC11,Key!$E$20:$F$24,2,FALSE) -> 750,000-1,000,000 | AE11: 1 | AF11: 4 | AG11: 1 | AH11: 1 | AI11: 1 | AJ11: Y
B12: 43765 | C12: 0.53125 | E12: D | F12: 2 | G12: =VLOOKUP(F12,Key!$A$17:$B$21,2,FALSE) -> Road Vehicle | H12: 1 | I12: =VLOOKUP(H12,Key!$A$2:$B$13,2,FALSE) -> Car | J12: F | K12: 1 | L12: =VLOOKUP(K12,Key!$A$24:$B$29,2,FALSE) -> 20-29 | M12: KIBULI | N12: KAMPALA | O12: UG | P12: 7 | Q12: =VLOOKUP(P12,Key!$E$2:$F$9,2,FALSE) -> Hospital | R12: ENTEBBE REFERAL HOSPITA | S12: WAKISO | T12: UG | U12: 7 | V12: =VLOOKUP(U12,Key!$E$2:$F$9,2,FALSE) -> Hospital | W12: =Q12&"-"&V12 -> Hospital-Hospital | X12: 100000 | Y12: 38 | Z12: 2.5 | AA12: 5 | AB12: =VLOOKUP(AA12,Key!$C$20:$D$29,2,FALSE) -> Professional | AC12: 3 | AD12: =VLOOKUP(AC12,Key!$E$20:$F$24,2,FALSE) -> 500,000-750,000 | AE12: 1 | AF12: 4 | AG12: 1 | AH12: 1 | AI12: 1 | AJ12: Y | AK12: 4000
B13: 43765 | C13: 0.49861111 | E13: D | F13: 2 | G13: =VLOOKUP(F13,Key!$A$17:$B$21,2,FALSE) -> Road Vehicle | H13: 1 | I13: =VLOOKUP(H13,Key!$A$2:$B$13,2,FALSE) -> Car | J13: F | K13: 1 | L13: =VLOOKUP(K13,Key!$A$24:$B$29,2,FALSE) -> 20-29 | M13: BUGOLOBI | N13: KAMPALA | O13: UG | P13: 1 | Q13: =VLOOKUP(P13,Key!$E$2:$F$9,2,FALSE) -> Home | R13: ENTEBBE STAGE | S13: WAKISO | T13: UG | U13: 6 | V13: =VLOOKUP(U13,Key!$E$2:$F$9,2,FALSE) -> Leisure/Social | W13: =Q13&"-"&V13 -> Home-Leisure/Social | X13: 60000 | Y13: 80 | Z13: 2 | AA13: 5 | AB13: =VLOOKUP(AA13,Key!$C$20:$D$29,2,FALSE) -> Professional | AC13: 2 | AD13: =VLOOKUP(AC13,Key!$E$20:$F$24,2,FALSE) -> 300,000-500,000 | AE13: 1 | AF13: 1 | AG13: 5 | AH13: 1 | AI13: 2 | AJ13: Y | AK13: 2000
B14: 43765 | C14: 0.48611111 | E14: D | F14: 2 | G14: =VLOOKUP(F14,Key!$A$17:$B$21,2,FALSE) -> Road Vehicle | H14: 1 | I14: =VLOOKUP(H14,Key!$A$2:$B$13,2,FALSE) -> Car | J14: F | K14: 1 | L14: =VLOOKUP(K14,Key!$A$24:$B$29,2,FALSE) -> 20-29 | M14: KAMPALA CITY | N14: KAMPALA | O14: UG | P14: 1 | Q14: =VLOOKUP(P14,Key!$E$2:$F$9,2,FALSE) -> Home | R14: ENTEBBE TOWN | S14: WAKISO | T14: UG | U14: 1 | V14: =VLOOKUP(U14,Key!$E$2:$F$9,2,FALSE) -> Home | W14: =Q14&"-"&V14 -> Home-Home | X14: 30000 | Y14: 36 | Z14: 1 | AA14: 6 | AB14: =VLOOKUP(AA14,Key!$C$20:$D$29,2,FALSE) -> Businessman | AC14: 3 | AD14: =VLOOKUP(AC14,Key!$E$20:$F$24,2,FALSE) -> 500,000-750,000 | AE14: 1 | AF14: 1 | AG14: 1 | AH14: 1 | AI14: 1 | AJ14: Y | AK14: 1000
B15: 43765 | C15: 0.48541667 | E15: D | F15: 2 | G15: =VLOOKUP(F15,Key!$A$17:$B$21,2,FALSE) -> Road Vehicle | H15: 1 | I15: =VLOOKUP(H15,Key!$A$2:$B$13,2,FALSE) -> Car | J15: F | K15: 1 | L15: =VLOOKUP(K15,Key!$A$24:$B$29,2,FALSE) -> 20-29 | M15: LUWEERO | N15: LUWEERO | O15: UG | P15: 1 | Q15: =VLOOKUP(P15,Key!$E$2:$F$9,2,FALSE) -> Home | R15: ENTEBBE TOWN | S15: WAKISO | T15: UG | U15: 1 | V15: =VLOOKUP(U15,Key!$E$2:$F$9,2,FALSE) -> Home | W15: =Q15&"-"&V15 -> Home-Home | X15: 100000 | Y15: 180 | Z15: 2 | AA15: 5 | AB15: =VLOOKUP(AA15,Key!$C$20:$D$29,2,FALSE) -> Professional | AC15: 3 | AD15: =VLOOKUP(AC15,Key!$E$20:$F$24,2,FALSE) -> 500,000-750,000 | AE15: 1 | AF15: 1 | AG15: 5 | AH15: 1 | AI15: 2 | AJ15: Y | AK15: 5000
B16: 43765 | C16: 0.45694444 | E16: D | F16: 2 | G16: =VLOOKUP(F16,Key!$A$17:$B$21,2,FALSE) -> Road Vehicle | H16: 1 | I16: =VLOOKUP(H16,Key!$A$2:$B$13,2,FALSE) -> Car | J16: F | K16: 1 | L16: =VLOOKUP(K16,Key!$A$24:$B$29,2,FALSE) -> 20-29 | M16: MITYANA | N16: MIYTANA | O16: UG | P16: 1 | Q16: =VLOOKUP(P16,Key!$E$2:$F$9,2,FALSE) -> Home | R16: ENTEBBE TOWN | S16: WAKISO | T16: UG | U16: 1 | V16: =VLOOKUP(U16,Key!$E$2:$F$9,2,FALSE) -> Home | W16: =Q16&"-"&V16 -> Home-Home | X16: 100000 | Y16: 50 | Z16: 2 | AA16: 5 | AB16: =VLOOKUP(AA16,Key!$C$20:$D$29,2,FALSE) -> Professional | AC16: 1 | AD16: =VLOOKUP(AC16,Key!$E$20:$F$24,2,FALSE) -> <300,000 | AE16: 1 | AF16: 2 | AG16: 1 | AH16: 1 | AI16: 1 | AJ16: Y
B17: 43765 | C17: 0.65347222 | E17: P | F17: 2 | G17: =VLOOKUP(F17,Key!$A$17:$B$21,2,FALSE) -> Road Vehicle | H17: 1 | I17: =VLOOKUP(H17,Key!$A$2:$B$13,2,FALSE) -> Car | J17: F | K17: 1 | L17: =VLOOKUP(K17,Key!$A$24:$B$29,2,FALSE) -> 20-29 | M17: NAKIWOGO | N17: WAKISO | O17: UG | P17: 1 | Q17: =VLOOKUP(P17,Key!$E$2:$F$9,2,FALSE) -> Home | R17: VICTORIA MALL | S17: WAKISO | T17: UG | U17: 6 | V17: =VLOOKUP(U17,Key!$E$2:$F$9,2,FALSE) -> Leisure/Social | W17: =Q17&"-"&V17 -> Home-Leisure/Social | X17: 2000 | Z17: 0.1 | AA17: 6 | AB17: =VLOOKUP(AA17,Key!$C$20:$D$29,2,FALSE) -> Businessman | AC17: 2 | AD17: =VLOOKUP(AC17,Key!$E$20:$F$24,2,FALSE) -> 300,000-500,000 | AE17: 3 | AF17: 2 | AG17: 1 | AH17: 1 | AI17: 5 | AJ17: Y | AK17: 1000
B18: 43765 | C18: 0.60555556 | E18: D | F18: 2 | G18: =VLOOKUP(F18,Key!$A$17:$B$21,2,FALSE) -> Road Vehicle | H18: 1 | I18: =VLOOKUP(H18,Key!$A$2:$B$13,2,FALSE) -> Car | J18: F | K18: 1 | L18: =VLOOKUP(K18,Key!$A$24:$B$29,2,FALSE) -> 20-29 | M18: GARENGE | N18: WAKISO | O18: UG | P18: 1 | Q18: =VLOOKUP(P18,Key!$E$2:$F$9,2,FALSE) -> Home | R18: ENTEBBE | S18: WAKISO | T18: UG | U18: 6 | V18: =VLOOKUP(U18,Key!$E$2:$F$9,2,FALSE) -> Leisure/Social | W18: =Q18&"-"&V18 -> Home-Leisure/Social | AA18: 8 | AB18: =VLOOKUP(AA18,Key!$C$20:$D$29,2,FALSE) -> Student | AC18: 1 | AD18: =VLOOKUP(AC18,Key!$E$20:$F$24,2,FALSE) -> <300,000 | AE18: 2 | AF18: 3 | AG18: 4 | AH18: 1 | AI18: 5 | AJ18: Y | AK18: 2000
B19: 43765 | C19: 0.39444444 | E19: D | F19: 2 | G19: =VLOOKUP(F19,Key!$A$17:$B$21,2,FALSE) -> Road Vehicle | H19: 1 | I19: =VLOOKUP(H19,Key!$A$2:$B$13,2,FALSE) -> Car | J19: M | K19: 1 | L19: =VLOOKUP(K19,Key!$A$24:$B$29,2,FALSE) -> 20-29 | M19: ZANA | N19: WAKISO | O19: UG | P19: 2 | Q19: =VLOOKUP(P19,Key!$E$2:$F$9,2,FALSE) -> Work | R19: AIRPORT | S19: WAKISO | T19: UG | U19: 2 | V19: =VLOOKUP(U19,Key!$E$2:$F$9,2,FALSE) -> Work | W19: =Q19&"-"&V19 -> Work-Work | X19: 25000 | Y19: 33 | Z19: 0.5 | AA19: 4 | AB19: =VLOOKUP(AA19,Key!$C$20:$D$29,2,FALSE) -> Office Worker | AC19: 4 | AD19: =VLOOKUP(AC19,Key!$E$20:$F$24,2,FALSE) -> 750,000-1,000,000 | AE19: 1 | AF19: 1 | AG19: 1 | AH19: 1 | AI19: 1 | AJ19: Y | AK19: 1000
B20: 43765 | C20: 0.36527778 | E20: D | F20: 2 | G20: =VLOOKUP(F20,Key!$A$17:$B$21,2,FALSE) -> Road Vehicle | H20: 1 | I20: =VLOOKUP(H20,Key!$A$2:$B$13,2,FALSE) -> Car | J20: M | K20: 1 | L20: =VLOOKUP(K20,Key!$A$24:$B$29,2,FALSE) -> 20-29 | M20: KITENDE | N20: WAKISO | O20: UG | P20: 1 | Q20: =VLOOKUP(P20,Key!$E$2:$F$9,2,FALSE) -> Home | R20: ENTEBBE TOWN | S20: WAKISO | T20: UG | U20: 1 | V20: =VLOOKUP(U20,Key!$E$2:$F$9,2,FALSE) -> Home | W20: =Q20&"-"&V20 -> Home-Home | X20: 10000 | Y20: 20 | Z20: 0.9 | AA20: 5 | AB20: =VLOOKUP(AA20,Key!$C$20:$D$29,2,FALSE) -> Professional | AC20: 2 | AD20: =VLOOKUP(AC20,Key!$E$20:$F$24,2,FALSE) -> 300,000-500,000 | AE20: 1 | AF20: 1 | AG20: 1 | AH20: 1 | AI20: 1 | AJ20: Y | AK20: 2000
B21: 43765 | C21: 0.34027778 | E21: D | F21: 2 | G21: =VLOOKUP(F21,Key!$A$17:$B$21,2,FALSE) -> Road Vehicle | H21: 1 | I21: =VLOOKUP(H21,Key!$A$2:$B$13,2,FALSE) -> Car | J21: M | K21: 1 | L21: =VLOOKUP(K21,Key!$A$24:$B$29,2,FALSE) -> 20-29 | M21: NSAMBYA | N21: KAMPALA | O21: UG | P21: 1 | Q21: =VLOOKUP(P21,Key!$E$2:$F$9,2,FALSE) -> Home | R21: KITALA | S21: WAKISO | T21: UG | U21: 1 | V21: =VLOOKUP(U21,Key!$E$2:$F$9,2,FALSE) -> Home | W21: =Q21&"-"&V21 -> Home-Home | X21: 20000 | Y21: 35 | Z21: 1 | AA21: 5 | AB21: =VLOOKUP(AA21,Key!$C$20:$D$29,2,FALSE) -> Professional | AC21: 2 | AD21: =VLOOKUP(AC21,Key!$E$20:$F$24,2,FALSE) -> 300,000-500,000 | AE21: 1 | AF21: 1 | AG21: 1 | AH21: 1 | AI21: 1 | AJ21: Y | AK21: 2000
B22: 43765 | C22: 0.65208333 | E22: D | F22: 2 | G22: =VLOOKUP(F22,Key!$A$17:$B$21,2,FALSE) -> Road Vehicle | H22: 1 | I22: =VLOOKUP(H22,Key!$A$2:$B$13,2,FALSE) -> Car | J22: M | K22: 1 | L22: =VLOOKUP(K22,Key!$A$24:$B$29,2,FALSE) -> 20-29 | M22: KIREKA | N22: WAKISO | O22: UG | P22: 1 | Q22: =VLOOKUP(P22,Key!$E$2:$F$9,2,FALSE) -> Home | R22: ENTEBBE TOWN | S22: WAKISO | T22: UG | U22: 1 | V22: =VLOOKUP(U22,Key!$E$2:$F$9,2,FALSE) -> Home | W22: =Q22&"-"&V22 -> Home-Home | X22: 130000 | Y22: 48 | Z22: 2 | AA22: 4 | AB22: =VLOOKUP(AA22,Key!$C$20:$D$29,2,FALSE) -> Office Worker | AC22: 2 | AD22: =VLOOKUP(AC22,Key!$E$20:$F$24,2,FALSE) -> 300,000-500,000 | AE22: 4 | AF22: 1 | AG22: 5 | AH22: 1 | AI22: 1 | AJ22: Y | AK22: 3000
B23: 43765 | C23: 0.62847222 | E23: D | F23: 2 | G23: =VLOOKUP(F23,Key!$A$17:$B$21,2,FALSE) -> Road Vehicle | H23: 1 | I23: =VLOOKUP(H23,Key!$A$2:$B$13,2,FALSE) -> Car | J23: M | K23: 1 | L23: =VLOOKUP(K23,Key!$A$24:$B$29,2,FALSE) -> 20-29 | M23: BULOBA | N23: WAKISO | O23: UG | P23: 1 | Q23: =VLOOKUP(P23,Key!$E$2:$F$9,2,FALSE) -> Home | R23: ENTEBBE TOWN | S23: WAKISO | T23: UG | U23: 1 | V23: =VLOOKUP(U23,Key!$E$2:$F$9,2,FALSE) -> Home | W23: =Q23&"-"&V23 -> Home-Home | X23: 100000 | Z23: 3 | AA23: 5 | AB23: =VLOOKUP(AA23,Key!$C$20:$D$29,2,FALSE) -> Professional | AC23: 2 | AD23: =VLOOKUP(AC23,Key!$E$20:$F$24,2,FALSE) -> 300,000-500,000 | AE23: 5 | AF23: 4 | AG23: 1 | AH23: 1 | AI23: 1 | AJ23: Y | AK23: 15000
B24: 43765 | C24: 0.61041667 | E24: D | F24: 2 | G24: =VLOOKUP(F24,Key!$A$17:$B$21,2,FALSE) -> Road Vehicle | H24: 1 | I24: =VLOOKUP(H24,Key!$A$2:$B$13,2,FALSE) -> Car | J24: M | K24: 1 | L24: =VLOOKUP(K24,Key!$A$24:$B$29,2,FALSE) -> 20-29 | M24: KIREKA | N24: WAKISO | O24: UG | P24: 1 | Q24: =VLOOKUP(P24,Key!$E$2:$F$9,2,FALSE) -> Home | R24: ENTEBBE TOWN | S24: WAKISO | T24: UG | U24: 1 | V24: =VLOOKUP(U24,Key!$E$2:$F$9,2,FALSE) -> Home | W24: =Q24&"-"&V24 -> Home-Home | X24: 130000 | Y24: 48 | Z24: 2 | AA24: 4 | AB24: =VLOOKUP(AA24,Key!$C$20:$D$29,2,FALSE) -> Office Worker | AC24: 2 | AD24: =VLOOKUP(AC24,Key!$E$20:$F$24,2,FALSE) -> 300,000-500,000 | AE24: 4 | AF24: 1 | AG24: 5 | AH24: 1 | AI24: 1 | AJ24: Y | AK24: 3000
B25: 43765 | C25: 0.56666667 | E25: D | F25: 2 | G25: =VLOOKUP(F25,Key!$A$17:$B$21,2,FALSE) -> Road Vehicle | H25: 1 | I25: =VLOOKUP(H25,Key!$A$2:$B$13,2,FALSE) -> Car | J25: M | K25: 1 | L25: =VLOOKUP(K25,Key!$A$24:$B$29,2,FALSE) -> 20-29 | M25: NATETE | N25: KAMPALA | O25: UG | P25: 1 | Q25: =VLOOKUP(P25,Key!$E$2:$F$9,2,FALSE) -> Home | R25: KITORO | S25: WAKISO | T25: UG | U25: 1 | V25: =VLOOKUP(U25,Key!$E$2:$F$9,2,FALSE) -> Home | W25: =Q25&"-"&V25 -> Home-Home | X25: 50000 | Y25: 39 | Z25: 1 | AA25: 5 | AB25: =VLOOKUP(AA25,Key!$C$20:$D$29,2,FALSE) -> Professional | AC25: 1 | AD25: =VLOOKUP(AC25,Key!$E$20:$F$24,2,FALSE) -> <300,000 | AE25: 1 | AF25: 1 | AG25: 1 | AH25: 1 | AI25: 1 | AJ25: Y | AK25: 1000
B26: 43765 | C26: 0.47222222 | E26: D | F26: 2 | G26: =VLOOKUP(F26,Key!$A$17:$B$21,2,FALSE) -> Road Vehicle | H26: 1 | I26: =VLOOKUP(H26,Key!$A$2:$B$13,2,FALSE) -> Car | J26: M | K26: 1 | L26: =VLOOKUP(K26,Key!$A$24:$B$29,2,FALSE) -> 20-29 | M26: NSAMBYA | N26: KAMPALA | O26: UG | P26: 2 | Q26: =VLOOKUP(P26,Key!$E$2:$F$9,2,FALSE) -> Work | R26: AIRPORT | S26: WAKISO | T26: UG | U26: 2 | V26: =VLOOKUP(U26,Key!$E$2:$F$9,2,FALSE) -> Work | W26: =Q26&"-"&V26 -> Work-Work | X26: 50000 | Y26: 45 | Z26: 1 | AA26: 6 | AB26: =VLOOKUP(AA26,Key!$C$20:$D$29,2,FALSE) -> Businessman | AC26: 5 | AD26: =VLOOKUP(AC26,Key!$E$20:$F$24,2,FALSE) -> >1,000,000 | AE26: 1 | AF26: 2 | AG26: 4 | AH26: 1 | AI26: 1 | AJ26: Y | AK26: 2000
B27: 43765 | C27: 0.45277778 | E27: D | F27: 2 | G27: =VLOOKUP(F27,Key!$A$17:$B$21,2,FALSE) -> Road Vehicle | H27: 1 | I27: =VLOOKUP(H27,Key!$A$2:$B$13,2,FALSE) -> Car | J27: M | K27: 1 | L27: =VLOOKUP(K27,Key!$A$24:$B$29,2,FALSE) -> 20-29 | M27: KIBUYE | N27: KAMPALA | O27: UG | P27: 1 | Q27: =VLOOKUP(P27,Key!$E$2:$F$9,2,FALSE) -> Home | R27: ENTEBBE TOWN | S27: WAKISO | T27: UG | U27: 7 | V27: =VLOOKUP(U27,Key!$E$2:$F$9,2,FALSE) -> Hospital | W27: =Q27&"-"&V27 -> Home-Hospital | X27: 20000 | Y27: 47 | Z27: 0.5 | AA27: 5 | AB27: =VLOOKUP(AA27,Key!$C$20:$D$29,2,FALSE) -> Professional | AC27: 3 | AD27: =VLOOKUP(AC27,Key!$E$20:$F$24,2,FALSE) -> 500,000-750,000 | AE27: 1 | AF27: 1 | AG27: 1 | AH27: 1 | AI27: 1 | AJ27: Y | AK27: 400
B28: 43765 | C28: 0.3125 | E28: D | F28: 2 | G28: =VLOOKUP(F28,Key!$A$17:$B$21,2,FALSE) -> Road Vehicle | H28: 1 | I28: =VLOOKUP(H28,Key!$A$2:$B$13,2,FALSE) -> Car | J28: M | K28: 1 | L28: =VLOOKUP(K28,Key!$A$24:$B$29,2,FALSE) -> 20-29 | M28: NANSANA | N28: WAKISO | O28: UG | P28: 1 | Q28: =VLOOKUP(P28,Key!$E$2:$F$9,2,FALSE) -> Home | R28: ENTEBBE TOWN | S28: WAKISO | T28: UG | U28: 1 | V28: =VLOOKUP(U28,Key!$E$2:$F$9,2,FALSE) -> Home | W28: =Q28&"-"&V28 -> Home-Home | X28: 30000 | Y28: 80 | Z28: 2 | AA28: 5 | AB28: =VLOOKUP(AA28,Key!$C$20:$D$29,2,FALSE) -> Professional | AC28: 4 | AD28: =VLOOKUP(AC28,Key!$E$20:$F$24,2,FALSE) -> 750,000-1,000,000 | AE28: 1 | AF28: 5 | AG28: 1 | AH28: 1 | AI28: 1 | AJ28: Y | AK28: 3000
B29: 43765 | C29: 0.33888889 | E29: D | F29: 2 | G29: =VLOOKUP(F29,Key!$A$17:$B$21,2,FALSE) -> Road Vehicle | H29: 1 | I29: =VLOOKUP(H29,Key!$A$2:$B$13,2,FALSE) -> Car | J29: M | K29: 1 | L29: =VLOOKUP(K29,Key!$A$24:$B$29,2,FALSE) -> 20-29 | M29: KISENYI | N29: WAKISO | O29: UG | P29: 4 | Q29: =VLOOKUP(P29,Key!$E$2:$F$9,2,FALSE) -> Commercial | R29: BATABATA | S29: WAKISO | T29: UG | U29: 6 | V29: =VLOOKUP(U29,Key!$E$2:$F$9,2,FALSE) -> Leisure/Social | W29: =Q29&"-"&V29 -> Commercial-Leisure/Social | X29: 25000 | Y29: 36 | Z29: 0.7 | AA29: 2 | AB29: =VLOOKUP(AA29,Key!$C$20:$D$29,2,FALSE) -> Manual Labour | AC29: 1 | AD29: =VLOOKUP(AC29,Key!$E$20:$F$24,2,FALSE) -> <300,000 | AE29: 1 | AF29: 4 | AG29: 3 | AH29: 2 | AI29: 5 | AJ29: Y | AK29: 2000
B30: 43765 | C30: 0.70833333 | E30: P | F30: 2 | G30: =VLOOKUP(F30,Key!$A$17:$B$21,2,FALSE) -> Road Vehicle | H30: 4 | I30: =VLOOKUP(H30,Key!$A$2:$B$13,2,FALSE) -> Minibus | J30: F | K30: 1 | L30: =VLOOKUP(K30,Key!$A$24:$B$29,2,FALSE) -> 20-29 | M30: MANALA | N30: WAKISO | O30: UG | P30: 2 | Q30: =VLOOKUP(P30,Key!$E$2:$F$9,2,FALSE) -> Work | R30: NAKIWOGO | S30: WAKISO | T30: UG | U30: 1 | V30: =VLOOKUP(U30,Key!$E$2:$F$9,2,FALSE) -> Home | W30: =Q30&"-"&V30 -> Work-Home | X30: 2000 | Z30: 0.2 | AA30: 2 | AB30: =VLOOKUP(AA30,Key!$C$20:$D$29,2,FALSE) -> Manual Labour | AC30: 1 | AD30: =VLOOKUP(AC30,Key!$E$20:$F$24,2,FALSE) -> <300,000 | AE30: 2 | AF30: 4 | AG30: 3 | AH30: 1 | AI30: 5 | AJ30: Y | AK30: 100
B31: 43765 | C31: 0.31805556 | E31: P | F31: 2 | G31: =VLOOKUP(F31,Key!$A$17:$B$21,2,FALSE) -> Road Vehicle | H31: 4 | I31: =VLOOKUP(H31,Key!$A$2:$B$13,2,FALSE) -> Minibus | J31: F | K31: 1 | L31: =VLOOKUP(K31,Key!$A$24:$B$29,2,FALSE) -> 20-29 | M31: FAITH MIRACLE CHURCH | N31: WAKISO | O31: UG | P31: 8 | Q31: =VLOOKUP(P31,Key!$E$2:$F$9,2,FALSE) -> Others | R31: KITALA | S31: WAKISO | T31: UG | U31: 1 | V31: =VLOOKUP(U31,Key!$E$2:$F$9,2,FALSE) -> Home | W31: =Q31&"-"&V31 -> Others-Home | X31: 2000 | Z31: 0.1 | AA31: 6 | AB31: =VLOOKUP(AA31,Key!$C$20:$D$29,2,FALSE) -> Businessman | AC31: 3 | AD31: =VLOOKUP(AC31,Key!$E$20:$F$24,2,FALSE) -> 500,000-750,000 | AE31: 4 | AF31: 5 | AG31: 2 | AH31: 1 | AI31: 3 | AJ31: Y | AK31: 500
B32: 43765 | C32: 0.55277778 | E32: P | F32: 2 | G32: =VLOOKUP(F32,Key!$A$17:$B$21,2,FALSE) -> Road Vehicle | H32: 4 | I32: =VLOOKUP(H32,Key!$A$2:$B$13,2,FALSE) -> Minibus | J32: F | K32: 1 | L32: =VLOOKUP(K32,Key!$A$24:$B$29,2,FALSE) -> 20-29 | M32: KITORO | N32: WAKISO | O32: UG | P32: 1 | Q32: =VLOOKUP(P32,Key!$E$2:$F$9,2,FALSE) -> Home | R32: NKUMBA | S32: WAKISO | T32: UG | U32: 3 | V32: =VLOOKUP(U32,Key!$E$2:$F$9,2,FALSE) -> Study | W32: =Q32&"-"&V32 -> Home-Study | X32: 100 | Y32: 10 | Z32: 0.3 | AA32: 8 | AB32: =VLOOKUP(AA32,Key!$C$20:$D$29,2,FALSE) -> Student | AC32: 1 | AD32: =VLOOKUP(AC32,Key!$E$20:$F$24,2,FALSE) -> <300,000 | AE32: 4 | AF32: 5 | AG32: 2 | AH32: 1 | AI32: 3 | AJ32: Y | AK32: 1000
B33: 43765 | C33: 0.48541667 | E33: P | F33: 2 | G33: =VLOOKUP(F33,Key!$A$17:$B$21,2,FALSE) -> Road Vehicle | H33: 4 | I33: =VLOOKUP(H33,Key!$A$2:$B$13,2,FALSE) -> Minibus | J33: F | K33: 1 | L33: =VLOOKUP(K33,Key!$A$24:$B$29,2,FALSE) -> 20-29 | M33: KITORO | N33: WAKISO | O33: UG | P33: 6 | Q33: =VLOOKUP(P33,Key!$E$2:$F$9,2,FALSE) -> Leisure/Social | R33: ZANA | S33: WAKISO | T33: UG | U33: 1 | V33: =VLOOKUP(U33,Key!$E$2:$F$9,2,FALSE) -> Home | W33: =Q33&"-"&V33 -> Leisure/Social-Home | X33: 2500 | Z33: 0.9 | AA33: 8 | AB33: =VLOOKUP(AA33,Key!$C$20:$D$29,2,FALSE) -> Student | AC33: 1 | AD33: =VLOOKUP(AC33,Key!$E$20:$F$24,2,FALSE) -> <300,000 | AE33: 2 | AF33: 4 | AG33: 3 | AH33: 1 | AI33: 5 | AJ33: Y | AK33: 500
B34: 43765 | C34: 0.45902778 | E34: P | F34: 2 | G34: =VLOOKUP(F34,Key!$A$17:$B$21,2,FALSE) -> Road Vehicle | H34: 4 | I34: =VLOOKUP(H34,Key!$A$2:$B$13,2,FALSE) -> Minibus | J34: F | K34: 1 | L34: =VLOOKUP(K34,Key!$A$24:$B$29,2,FALSE) -> 20-29 | M34: KITORO | N34: WAKISO | O34: UG | P34: 6 | Q34: =VLOOKUP(P34,Key!$E$2:$F$9,2,FALSE) -> Leisure/Social | R34: SEGUUKU | S34: WAKISO | T34: UG | U34: 1 | V34: =VLOOKUP(U34,Key!$E$2:$F$9,2,FALSE) -> Home | W34: =Q34&"-"&V34 -> Leisure/Social-Home | X34: 3000 | Y34: 20 | Z34: 0.8 | AA34: 1 | AB34: =VLOOKUP(AA34,Key!$C$20:$D$29,2,FALSE) -> Unemployed | AC34: 1 | AD34: =VLOOKUP(AC34,Key!$E$20:$F$24,2,FALSE) -> <300,000 | AE34: 5 | AF34: 2 | AG34: 4 | AH34: 1 | AI34: 3 | AJ34: Y | AK34: 200
B35: 43765 | C35: 0.46875 | E35: P | F35: 1 | G35: =VLOOKUP(F35,Key!$A$17:$B$21,2,FALSE) -> Walking/Cycling | H35: 4 | I35: =VLOOKUP(H35,Key!$A$2:$B$13,2,FALSE) -> Minibus | J35: F | K35: 1 | L35: =VLOOKUP(K35,Key!$A$24:$B$29,2,FALSE) -> 20-29 | M35: NAKIWOGO | N35: WAKISO | O35: UG | P35: 1 | Q35: =VLOOKUP(P35,Key!$E$2:$F$9,2,FALSE) -> Home | R35: LUNGUJJA | S35: KAMPALA | T35: UG | U35: 2 | V35: =VLOOKUP(U35,Key!$E$2:$F$9,2,FALSE) -> Work | W35: =Q35&"-"&V35 -> Home-Work | X35: 6000 | Z35: 2 | AA35: 3 | AB35: =VLOOKUP(AA35,Key!$C$20:$D$29,2,FALSE) -> Artisan/Domestic | AC35: 1 | AD35: =VLOOKUP(AC35,Key!$E$20:$F$24,2,FALSE) -> <300,000 | AE35: 4 | AF35: 3 | AG35: 2 | AH35: 1 | AI35: 5 | AJ35: Y
B36: 43765 | C36: 0.32291667 | E36: P | F36: 2 | G36: =VLOOKUP(F36,Key!$A$17:$B$21,2,FALSE) -> Road Vehicle | H36: 4 | I36: =VLOOKUP(H36,Key!$A$2:$B$13,2,FALSE) -> Minibus | J36: F | K36: 1 | L36: =VLOOKUP(K36,Key!$A$24:$B$29,2,FALSE) -> 20-29 | M36: KITORO | N36: WAKISO | O36: UG | P36: 1 | Q36: =VLOOKUP(P36,Key!$E$2:$F$9,2,FALSE) -> Home | R36: SEGUUKU | S36: WAKISO | T36: UG | U36: 6 | V36: =VLOOKUP(U36,Key!$E$2:$F$9,2,FALSE) -> Leisure/Social | W36: =Q36&"-"&V36 -> Home-Leisure/Social | X36: 2000 | Y36: 30 | Z36: 0.5 | AA36: 2 | AB36: =VLOOKUP(AA36,Key!$C$20:$D$29,2,FALSE) -> Manual Labour | AC36: 1 | AD36: =VLOOKUP(AC36,Key!$E$20:$F$24,2,FALSE) -> <300,000 | AE36: 1 | AF36: 3 | AG36: 4 | AH36: 2 | AI36: 5 | AJ36: Y | AK36: 1500
B37: 43765 | C37: 0.32777778 | E37: P | F37: 2 | G37: =VLOOKUP(F37,Key!$A$17:$B$21,2,FALSE) -> Road Vehicle | H37: 4 | I37: =VLOOKUP(H37,Key!$A$2:$B$13,2,FALSE) -> Minibus | J37: F | K37: 1 | L37: =VLOOKUP(K37,Key!$A$24:$B$29,2,FALSE) -> 20-29 | M37: ENTEBBE TOWN | N37: WAKISO | O37: UG | P37: 1 | Q37: =VLOOKUP(P37,Key!$E$2:$F$9,2,FALSE) -> Home | R37: ST. JUDE CHURCH | S37: WAKISO | T37: UG | U37: 8 | V37: =VLOOKUP(U37,Key!$E$2:$F$9,2,FALSE) -> Others | W37: =Q37&"-"&V37 -> Home-Others | X37: 1000 | Y37: 0.5 | Z37: 0.1 | AA37: 10 | AB37: =VLOOKUP(AA37,Key!$C$20:$D$29,2,FALSE) -> Other | AC37: 2 | AD37: =VLOOKUP(AC37,Key!$E$20:$F$24,2,FALSE) -> 300,000-500,000 | AE37: 1 | AF37: 5 | AG37: 4 | AH37: 2 | AI37: 3 | AJ37: Y | AK37: 2000
B38: 43765 | C38: 0.38194444 | E38: P | F38: 2 | G38: =VLOOKUP(F38,Key!$A$17:$B$21,2,FALSE) -> Road Vehicle | H38: 4 | I38: =VLOOKUP(H38,Key!$A$2:$B$13,2,FALSE) -> Minibus | J38: F | K38: 1 | L38: =VLOOKUP(K38,Key!$A$24:$B$29,2,FALSE) -> 20-29 | M38: KINYARWANDA | N38: WAKISO | O38: UG | P38: 1 | Q38: =VLOOKUP(P38,Key!$E$2:$F$9,2,FALSE) -> Home | R38: KASANGATI | S38: WAKISO | T38: UG | U38: 6 | V38: =VLOOKUP(U38,Key!$E$2:$F$9,2,FALSE) -> Leisure/Social | W38: =Q38&"-"&V38 -> Home-Leisure/Social | X38: 6000 | Z38: 3 | AA38: 2 | AB38: =VLOOKUP(AA38,Key!$C$20:$D$29,2,FALSE) -> Manual Labour | AC38: 1 | AD38: =VLOOKUP(AC38,Key!$E$20:$F$24,2,FALSE) -> <300,000 | AE38: 1 | AF38: 2 | AG38: 3 | AH38: 4 | AI38: 5 | AJ38: Y | AK38: 1000
B39: 43765 | C39: 0.38541667 | E39: P | F39: 2 | G39: =VLOOKUP(F39,Key!$A$17:$B$21,2,FALSE) -> Road Vehicle | H39: 4 | I39: =VLOOKUP(H39,Key!$A$2:$B$13,2,FALSE) -> Minibus | J39: F | K39: 1 | L39: =VLOOKUP(K39,Key!$A$24:$B$29,2,FALSE) -> 20-29 | M39: KASENYI | N39: WAKISO | O39: UG | P39: 4 | Q39: =VLOOKUP(P39,Key!$E$2:$F$9,2,FALSE) -> Commercial | R39: JINJA BEACH | S39: JINJA | T39: UG | U39: 6 | V39: =VLOOKUP(U39,Key!$E$2:$F$9,2,FALSE) -> Leisure/Social | W39: =Q39&"-"&V39 -> Commercial-Leisure/Social | X39: 10000 | Z39: 5 | AA39: 2 | AB39: =VLOOKUP(AA39,Key!$C$20:$D$29,2,FALSE) -> Manual Labour | AC39: 1 | AD39: =VLOOKUP(AC39,Key!$E$20:$F$24,2,FALSE) -> <300,000 | AE39: 1 | AF39: 1 | AG39: 2 | AH39: 5 | AI39: 4 | AJ39: Y | AK39: 2000
B40: 43765 | C40: 0.51041667 | E40: P | F40: 2 | G40: =VLOOKUP(F40,Key!$A$17:$B$21,2,FALSE) -> Road Vehicle | H40: 4 | I40: =VLOOKUP(H40,Key!$A$2:$B$13,2,FALSE) -> Minibus | J40: F | K40: 1 | L40: =VLOOKUP(K40,Key!$A$24:$B$29,2,FALSE) -> 20-29 | M40: ENTEBBE | N40: WAKISO | O40: UG | P40: 1 | Q40: =VLOOKUP(P40,Key!$E$2:$F$9,2,FALSE) -> Home | R40: NANSANA | S40: WAKISO | T40: UG | U40: 6 | V40: =VLOOKUP(U40,Key!$E$2:$F$9,2,FALSE) -> Leisure/Social | W40: =Q40&"-"&V40 -> Home-Leisure/Social | X40: 5500 | Y40: 52 | Z40: 1.5 | AA40: 2 | AB40: =VLOOKUP(AA40,Key!$C$20:$D$29,2,FALSE) -> Manual Labour | AC40: 1 | AD40: =VLOOKUP(AC40,Key!$E$20:$F$24,2,FALSE) -> <300,000 | AE40: 2 | AF40: 3 | AG40: 4 | AH40: 1 | AI40: 5 | AJ40: Y | AK40: 3000
B41: 43765 | C41: 0.52777778 | E41: P | F41: 2 | G41: =VLOOKUP(F41,Key!$A$17:$B$21,2,FALSE) -> Road Vehicle | H41: 4 | I41: =VLOOKUP(H41,Key!$A$2:$B$13,2,FALSE) -> Minibus | J41: F | K41: 1 | L41: =VLOOKUP(K41,Key!$A$24:$B$29,2,FALSE) -> 20-29 | M41: ENTEBBE | N41: WAKISO | O41: UG | P41: 1 | Q41: =VLOOKUP(P41,Key!$E$2:$F$9,2,FALSE) -> Home | R41: MUNYONYO | S41: WAKISO | T41: UG | U41: 6 | V41: =VLOOKUP(U41,Key!$E$2:$F$9,2,FALSE) -> Leisure/Social | W41: =Q41&"-"&V41 -> Home-Leisure/Social | X41: 8000 | Z41: 2 | AA41: 2 | AB41: =VLOOKUP(AA41,Key!$C$20:$D$29,2,FALSE) -> Manual Labour | AC41: 1 | AD41: =VLOOKUP(AC41,Key!$E$20:$F$24,2,FALSE) -> <300,000 | AE41: 2 | AF41: 5 | AG41: 4 | AH41: 1 | AI41: 3 | AJ41: Y | AK41: 1000
B42: 43765 | C42: 0.53611111 | E42: P | F42: 2 | G42: =VLOOKUP(F42,Key!$A$17:$B$21,2,FALSE) -> Road Vehicle | H42: 4 | I42: =VLOOKUP(H42,Key!$A$2:$B$13,2,FALSE) -> Minibus | J42: F | K42: 1 | L42: =VLOOKUP(K42,Key!$A$24:$B$29,2,FALSE) -> 20-29 | M42: ENTEBBE | N42: WAKISO | O42: UG | P42: 1 | Q42: =VLOOKUP(P42,Key!$E$2:$F$9,2,FALSE) -> Home | R42: NKUMBA | S42: WAKISO | T42: UG | U42: 6 | V42: =VLOOKUP(U42,Key!$E$2:$F$9,2,FALSE) -> Leisure/Social | W42: =Q42&"-"&V42 -> Home-Leisure/Social | X42: 1000 | Y42: 8 | Z42: 0.1 | AA42: 6 | AB42: =VLOOKUP(AA42,Key!$C$20:$D$29,2,FALSE) -> Businessman | AC42: 2 | AD42: =VLOOKUP(AC42,Key!$E$20:$F$24,2,FALSE) -> 300,000-500,000 | AE42: 2 | AF42: 1 | AG42: 3 | AH42: 4 | AI42: 5 | AJ42: Y | AK42: 1000
...

Sheet RSI FORM
B1: Feasibility Study and Detailed Design of Kampala - Jinja Highway
B2: Roadside OD Interview Survey
B4: Date: | C4: 40465 | D4: Interviewer: | G4: Survey Station: | H4: Bweyogerere | J4: Direction: | K4: Bweyogerere-Kireka | L4: Coded By: | N4: Chkd By:
B7: Time Period | C7: Veh_Type | D7: Veh_Other | E7: Occupancy | F7: Origin_Address | H7: Origin_Purpose | I7: Origin_other | J7: Destination_Address | L7: Destination_Purpose | M7: Destination_Other | N7: Origin_Zone | O7: Dest_Zone | P7: WTP
F8: Village/Town | G8: City/Country | J8: Village/Town | K8: City/Country
B9: AM | C9: 3 | E9: 2 | F9: Entebbe | G9: Kla, Ug | H9: 1 | J9: Kla | K9: Kla, Ug | L9: 2 | N9: Blank | O9: Blank | P9: Yes | Q9: 3000
B10: AM | C10: 1 | E10: 1 | F10: Kiwanga | G10: Kla, Ug | H10: 1 | J10: Kla | K10: Kla, Ug | L10: 2 | N10: Blank | O10: Blank | P10: Yes | Q10: 2000
B11: AM | E11: 1 | F11: Bukoto | G11: Kla, Ug | H11: 3 | J11: Kla | K11: Kla, Ug | L11: 1 | N11: Blank | O11: Blank
B12: AM
B13: AM
B14: AM
B15: AM
B16: AM
B17: AM
B18: AM
B19: AM
B20: AM
B21: AM
B22: AM
B23: AM
... B53: AM

Sheet Key
B1: Vehicle Type | D1: Establishment Type | F1: Origin / Destination Purpose | H1: Trip Frequency | J1: Goods Type
A2: 1 | B2: Car | C2: 1 | D2: Residential | E2: 1 | F2: Home | G2: 1 | H2: more than 2 times every day | I2: 1 | J2: Food crop (Maize,rice,wheat etc)
A3: 2 | B3: Station Wagon | C3: 2 | D3: Office | E3: 2 | F3: Work | G3: 2 | H3: Daily (Up and Down) | I3: 2 | J3: Cash Crops (coffee,tea etc)
A4: 3 | B4: Pickups | C4: 3 | D4: Factory | E4: 3 | F4: Study | G4: 3 | H4: 2/3 times a week | I4: 3 | J4: Perishable (fish,milk,tea etc)
A5: 4 | B5: Minibus | C5: 4 | D5: Educational Facility | E5: 4 | F5: Commercial | G5: 4 | H5: Once a week | I5: 4 | J5: Construction Material (cement, gravel,stones,gravel,pipes)
A6: 5 | B6: Medium bus | C6: 5 | D6: Hospital | E6: 5 | F6: Tourism | G6: 5 | H6: Once a month | I6: 5 | J6: Metal/machinery
A7: 6 | B7: Large Bus | C7: 6 | D7: Bus / Taxi Park | E7: 6 | F7: Leisure/Social | G7: 6 | H7: Once in a while | I7: 6 | J7: Forestry products (timber & charcoal)
A8: 7 | B8: Light Truck | C8: 7 | D8: Wholesale shopping | E8: 7 | F8: Hospital | I8: 7 | J8: Fuels (any petroleum products)
A9: 8 | B9: Medium Truck | C9: 8 | D9: Boda boda stage | E9: 8 | F9: Others | I9: 8 | J9: Chemical Products (fertilizer,paints)
A10: 9 | B10: Heavy truck | C10: 9 | D10: Farm | I10: 9 | J10: Livestock (cows,goats,camel etc)
A11: 10 | B11: Truck Trailer | C11: 10 | D11: Construction Site | I11: 10 | J11: Household retail products (beverage,oil,sugar,salt,flour)
A12: 11 | B12: Motor cycles | C12: 11 | D12: Retail Shop/Market | I12: 11 | J12: Empty
A13: 12 | B13: Tractors | C13: 12 | D13: Warehouse | I13: 12 | J13: Others (Pl specify)
C14: 13 | D14: Harbour
C15: 14 | D15: Timber Centre
B16: Mode Number | C16: 15 | D16: Quarry
A17: 1 | B17: Walking/Cycling | C17: 16 | D17: Others (to be specified)
A18: 2 | B18: Road Vehicle
A19: 3 | B19: Rail | D19: Profession | F19: Monthly Income
A20: 4 | B20: Water/Ferry | C20: 1 | D20: Unemployed | E20: 1 | F20: <300,000
A21: 5 | B21: Air | C21: 2 | D21: Manual Labour | E21: 2 | F21: 300,000-500,000
C22: 3 | D22: Artisan/Domestic | E22: 3 | F22: 500,000-750,000
B23: Age Bracket No. | C23: 4 | D23: Office Worker | E23: 4 | F23: 750,000-1,000,000
A24: 1 | B24: 20-29 | C24: 5 | D24: Professional | E24: 5 | F24: >1,000,000
A25: 2 | B25: 30-39 | C25: 6 | D25: Businessman
A26: 3 | B26: 40-49 | C26: 7 | D26: Farmer
A27: 4 | B27: 50-59 | C27: 8 | D27: Student
A28: 5 | B28: 60-69 | C28: 9 | D28: Retired
A29: 6 | B29: 70- | C29: 10 | D29: Other
