Workbook

Sheet 31.07 Koboko-Arua
B1: Consultancy services for Preparation of Expressway Development Master Plan (EDMP) for Uganda
B2: MANUAL CLASSIFIED COUNT (MCC)
B3: ROAD NAME: | C3: MCC - C5 - STN127 - KOBOKO-ARUA ROAD
C5: Date | D5: 31.07.19 | F5: Location | G5: xxx | J5: Surveyor | K5: xxx
C6: Dir. From | D6: Koboko | F6: Dir. To | G6: Arua | J6: Supervisor | K6: xxx
B8: Time / Veh Type | R8: SUMMARY TRAFFIC VOLUMES
C9: 1. Car | D9: 2. Station Wagon | E9: 3. Pickups | F9: 4. Minibus, matatu | G9: 5. Medium bus | H9: 6. Large Bus | I9: 7. Light Truck | J9: 8. Medium Truck | K9: 9. Heavy truck | L9: 10. Truck Trailer | M9: 11. Motor cycles | N9: 12. Tractors | O9: Total Excl M/Cycles | P9: Total All | R9: Time | S9: 1. Car | T9: 2. Station Wagon | U9: 3. Pickups | V9: 4. Minibus, matatu | W9: 5. Medium bus | X9: 6. Large Bus | Y9: 7. Light Truck | Z9: 8. Medium Truck | AA9: 9. Heavy truck | AB9: 10. Truck Trailer | AC9: 11. Motorcycles | AD9: 12. Tractors, Graders | AE9: Total Excl M/ Cycles | AF9: Total All
B10: 07.00 - 07.15 | C10: 2 | D10: 0 | E10: 0 | F10: 0 | G10: 0 | H10: 0 | I10: 0 | J10: 0 | K10: 0 | L10: 0 | M10: 8 | N10: 0 | O10: =SUM(C10:L10,N10) -> 2 | P10: =SUM(C10:N10) -> 10 | R10: 0700-0800 | S10: =SUM(C10:C13) -> 11 | T10: =SUM(D10:D13) -> 0 | U10: =SUM(E10:E13) -> 0 | V10: =SUM(F10:F13) -> 3 | W10: =SUM(G10:G13) -> 1 | X10: =SUM(H10:H13) -> 0 | Y10: =SUM(I10:I13) -> 0 | Z10: =SUM(J10:J13) -> 0 | ... AF10: =SUM(P10:P13) -> 87
B11: 07.15 - 07.30 | C11: 0 | D11: 0 | E11: 0 | F11: 0 | G11: 0 | H11: 0 | I11: 0 | J11: 0 | K11: 0 | L11: 0 | M11: 5 | N11: 0 | O11: =SUM(C11:L11,N11) -> 0 | P11: =SUM(C11:N11) -> 5 | R11: 0800-0900 | S11: =SUM(C14:C17) -> 24 | T11: =SUM(D14:D17) -> 1 | U11: =SUM(E14:E17) -> 2 | V11: =SUM(F14:F17) -> 7 | W11: =SUM(G14:G17) -> 0 | X11: =SUM(H14:H17) -> 0 | Y11: =SUM(I14:I17) -> 0 | Z11: =SUM(J14:J17) -> 0 | ... AF11: =SUM(P14:P17) -> 131
B12: 07.30 - 07.45 | C12: 5 | D12: 0 | E12: 0 | F12: 0 | G12: 0 | H12: 0 | I12: 0 | J12: 0 | K12: 0 | L12: 0 | M12: 30 | N12: 0 | O12: =SUM(C12:L12,N12) -> 5 | P12: =SUM(C12:N12) -> 35 | R12: 0900-1000 | S12: =SUM(C18:C21) -> 24 | T12: =SUM(D18:D21) -> 3 | U12: =SUM(E18:E21) -> 6 | V12: =SUM(F18:F21) -> 3 | W12: =SUM(G18:G21) -> 0 | X12: =SUM(H18:H21) -> 0 | Y12: =SUM(I18:I21) -> 6 | Z12: =SUM(J18:J21) -> 0 | ... AF12: =SUM(P18:P21) -> 102
B13: 07.45 - 08.00 | C13: 4 | D13: 0 | E13: 0 | F13: 3 | G13: 1 | H13: 0 | I13: 0 | J13: 0 | K13: 0 | L13: 0 | M13: 29 | N13: 0 | O13: =SUM(C13:L13,N13) -> 8 | P13: =SUM(C13:N13) -> 37 | R13: 1000-1100 | S13: =SUM(C22:C25) -> 25 | T13: =SUM(D22:D25) -> 5 | U13: =SUM(E22:E25) -> 7 | V13: =SUM(F22:F25) -> 4 | W13: =SUM(G22:G25) -> 0 | X13: =SUM(H22:H25) -> 0 | Y13: =SUM(I22:I25) -> 7 | Z13: =SUM(J22:J25) -> 2 | ... AF13: =SUM(P22:P25) -> 156
B14: 08.00 - 08.15 | C14: 3 | D14: 0 | E14: 0 | F14: 1 | G14: 0 | H14: 0 | I14: 0 | J14: 0 | K14: 0 | L14: 0 | M14: 26 | N14: 0 | O14: =SUM(C14:L14,N14) -> 4 | P14: =SUM(C14:N14) -> 30 | R14: 1100-1200 | S14: =SUM(C26:C29) -> 46 | T14: =SUM(D26:D29) -> 5 | U14: =SUM(E26:E29) -> 7 | V14: =SUM(F26:F29) -> 6 | W14: =SUM(G26:G29) -> 0 | X14: =SUM(H26:H29) -> 0 | Y14: =SUM(I26:I29) -> 11 | Z14: =SUM(J26:J29) -> 0 | ... AF14: =SUM(P26:P29) -> 171
B15: 08.15 - 08.30 | C15: 8 | D15: 0 | E15: 0 | F15: 1 | G15: 0 | H15: 0 | I15: 0 | J15: 0 | K15: 0 | L15: 0 | M15: 19 | N15: 0 | O15: =SUM(C15:L15,N15) -> 9 | P15: =SUM(C15:N15) -> 28 | R15: 1200-1300 | S15: =SUM(C30:C33) -> 44 | T15: =SUM(D30:D33) -> 5 | U15: =SUM(E30:E33) -> 6 | V15: =SUM(F30:F33) -> 6 | W15: =SUM(G30:G33) -> 0 | X15: =SUM(H30:H33) -> 0 | Y15: =SUM(I30:I33) -> 8 | Z15: =SUM(J30:J33) -> 3 | ... AF15: =SUM(P30:P33) -> 261
B16: 08.30 - 08.45 | C16: 6 | D16: 0 | E16: 0 | F16: 1 | G16: 0 | H16: 0 | I16: 0 | J16: 0 | K16: 0 | L16: 0 | M16: 30 | N16: 0 | O16: =SUM(C16:L16,N16) -> 7 | P16: =SUM(C16:N16) -> 37 | R16: 1300-1400 | S16: =SUM(C34:C37) -> 38 | T16: =SUM(D34:D37) -> 4 | U16: =SUM(E34:E37) -> 4 | V16: =SUM(F34:F37) -> 2 | W16: =SUM(G34:G37) -> 0 | X16: =SUM(H34:H37) -> 0 | Y16: =SUM(I34:I37) -> 16 | Z16: =SUM(J34:J37) -> 3 | ... AF16: =SUM(P34:P37) -> 205
B17: 08.45 - 9.00 | C17: 7 | D17: 1 | E17: 2 | F17: 4 | G17: 0 | H17: 0 | I17: 0 | J17: 0 | K17: 0 | L17: 0 | M17: 22 | N17: 0 | O17: =SUM(C17:L17,N17) -> 14 | P17: =SUM(C17:N17) -> 36 | R17: 1400-1500 | S17: =SUM(C38:C41) -> 37 | T17: =SUM(D38:D41) -> 4 | U17: =SUM(E38:E41) -> 6 | V17: =SUM(F38:F41) -> 5 | W17: =SUM(G38:G41) -> 0 | X17: =SUM(H38:H41) -> 0 | Y17: =SUM(I38:I41) -> 10 | Z17: =SUM(J38:J41) -> 0 | ... AF17: =SUM(P38:P41) -> 251
B18: 09.00 - 09.15 | C18: 6 | D18: 1 | E18: 2 | F18: 0 | G18: 0 | H18: 0 | I18: 0 | J18: 0 | K18: 0 | L18: 0 | M18: 9 | N18: 0 | O18: =SUM(C18:L18,N18) -> 9 | P18: =SUM(C18:N18) -> 18 | R18: 1500-1600 | S18: =SUM(C42:C45) -> 40 | T18: =SUM(D42:D45) -> 2 | U18: =SUM(E42:E45) -> 3 | V18: =SUM(F42:F45) -> 3 | W18: =SUM(G42:G45) -> 0 | X18: =SUM(H42:H45) -> 0 | Y18: =SUM(I42:I45) -> 7 | Z18: =SUM(J42:J45) -> 1 | ... AF18: =SUM(P42:P45) -> 188
B19: 09.15 - 09.30 | C19: 6 | D19: 1 | E19: 2 | F19: 1 | G19: 0 | H19: 0 | I19: 1 | J19: 0 | K19: 0 | L19: 0 | M19: 19 | N19: 0 | O19: =SUM(C19:L19,N19) -> 11 | P19: =SUM(C19:N19) -> 30 | R19: 1600-1700 | S19: =SUM(C46:C49) -> 37 | T19: =SUM(D46:D49) -> 4 | U19: =SUM(E46:E49) -> 4 | V19: =SUM(F46:F49) -> 4 | W19: =SUM(G46:G49) -> 0 | X19: =SUM(H46:H49) -> 1 | Y19: =SUM(I46:I49) -> 4 | Z19: =SUM(J46:J49) -> 13 | ... AF19: =SUM(P46:P49) -> 198
B20: 09.30 - 09.45 | C20: 5 | D20: 0 | E20: 0 | F20: 1 | G20: 0 | H20: 0 | I20: 2 | J20: 0 | K20: 0 | L20: 0 | M20: 15 | N20: 0 | O20: =SUM(C20:L20,N20) -> 8 | P20: =SUM(C20:N20) -> 23 | R20: 1700-1800 | S20: =SUM(C50:C53) -> 45 | T20: =SUM(D50:D53) -> 3 | U20: =SUM(E50:E53) -> 4 | V20: =SUM(F50:F53) -> 6 | W20: =SUM(G50:G53) -> 1 | X20: =SUM(H50:H53) -> 1 | Y20: =SUM(I50:I53) -> 3 | Z20: =SUM(J50:J53) -> 2 | ... AF20: =SUM(P50:P53) -> 168
B21: 09.45 - 10.00 | C21: 7 | D21: 1 | E21: 2 | F21: 1 | G21: 0 | H21: 0 | I21: 3 | J21: 0 | K21: 0 | L21: 0 | M21: 17 | N21: 0 | O21: =SUM(C21:L21,N21) -> 14 | P21: =SUM(C21:N21) -> 31 | R21: 1800-1900 | S21: =SUM(C54:C57) -> 22 | T21: =SUM(D54:D57) -> 5 | U21: =SUM(E54:E57) -> 5 | V21: =SUM(F54:F57) -> 9 | W21: =SUM(G54:G57) -> 0 | X21: =SUM(H54:H57) -> 1 | Y21: =SUM(I54:I57) -> 5 | Z21: =SUM(J54:J57) -> 6 | ... AF21: =SUM(P54:P57) -> 183
B22: 10.00 - 10.15 | C22: 5 | D22: 1 | E22: 2 | F22: 0 | G22: 0 | H22: 0 | I22: 3 | J22: 1 | K22: 0 | L22: 0 | M22: 18 | N22: 0 | O22: =SUM(C22:L22,N22) -> 12 | P22: =SUM(C22:N22) -> 30 | R22: AM Peak Hr | S22: =MAX(S10:S12) -> 24 | T22: =MAX(T10:T12) -> 3 | U22: =MAX(U10:U12) -> 6 | V22: =MAX(V10:V12) -> 7 | W22: =MAX(W10:W12) -> 1 | X22: =MAX(X10:X12) -> 0 | Y22: =MAX(Y10:Y12) -> 6 | Z22: =MAX(Z10:Z12) -> 0 | ... AF22: =MAX(AF10:AF12) -> 131
B23: 10.15 - 10.30 | C23: 1 | D23: 0 | E23: 0 | F23: 2 | G23: 0 | H23: 0 | I23: 1 | J23: 0 | K23: 0 | L23: 0 | M23: 15 | N23: 0 | O23: =SUM(C23:L23,N23) -> 4 | P23: =SUM(C23:N23) -> 19 | R23: IP Peak Hr | S23: =MAX(S13:S18) -> 46 | T23: =MAX(T13:T18) -> 5 | U23: =MAX(U13:U18) -> 7 | V23: =MAX(V13:V18) -> 6 | W23: =MAX(W13:W18) -> 0 | X23: =MAX(X13:X18) -> 0 | Y23: =MAX(Y13:Y18) -> 16 | Z23: =MAX(Z13:Z18) -> 3 | ... AF23: =MAX(AF13:AF18) -> 261
B24: 10.30 - 10.45 | C24: 5 | D24: 1 | E24: 2 | F24: 2 | G24: 0 | H24: 0 | I24: 1 | J24: 1 | K24: 0 | L24: 0 | M24: 43 | N24: 0 | O24: =SUM(C24:L24,N24) -> 12 | P24: =SUM(C24:N24) -> 55 | R24: PM Peak Hr | S24: =MAX(S19:S21) -> 45 | T24: =MAX(T19:T21) -> 5 | U24: =MAX(U19:U21) -> 5 | V24: =MAX(V19:V21) -> 9 | W24: =MAX(W19:W21) -> 1 | X24: =MAX(X19:X21) -> 1 | Y24: =MAX(Y19:Y21) -> 5 | Z24: =MAX(Z19:Z21) -> 13 | ... AF24: =MAX(AF19:AF21) -> 198
B25: 10.45 - 11.00 | C25: 14 | D25: 3 | E25: 3 | F25: 0 | G25: 0 | H25: 0 | I25: 2 | J25: 0 | K25: 0 | L25: 0 | M25: 30 | N25: 0 | O25: =SUM(C25:L25,N25) -> 22 | P25: =SUM(C25:N25) -> 52 | R25: AM Period | S25: =SUM(S10:S12) -> 59 | T25: =SUM(T10:T12) -> 4 | U25: =SUM(U10:U12) -> 8 | V25: =SUM(V10:V12) -> 13 | W25: =SUM(W10:W12) -> 1 | X25: =SUM(X10:X12) -> 0 | Y25: =SUM(Y10:Y12) -> 6 | Z25: =SUM(Z10:Z12) -> 0 | ... AF25: =SUM(AF10:AF12) -> 320
B26: 11.00 - 11.15 | C26: 16 | D26: 1 | E26: 1 | F26: 1 | G26: 0 | H26: 0 | I26: 3 | J26: 0 | K26: 1 | L26: 0 | M26: 0 | N26: 0 | O26: =SUM(C26:L26,N26) -> 23 | P26: =SUM(C26:N26) -> 23 | R26: IP Period | S26: =SUM(S13:S18) -> 230 | T26: =SUM(T13:T18) -> 25 | U26: =SUM(U13:U18) -> 33 | V26: =SUM(V13:V18) -> 26 | W26: =SUM(W13:W18) -> 0 | X26: =SUM(X13:X18) -> 0 | Y26: =SUM(Y13:Y18) -> 59 | Z26: =SUM(Z13:Z18) -> 9 | ... AF26: =SUM(AF13:AF18) -> 1232
B27: 11.15 - 11.30 | C27: 9 | D27: 1 | E27: 1 | F27: 2 | G27: 0 | H27: 0 | I27: 4 | J27: 0 | K27: 0 | L27: 0 | M27: 24 | N27: 0 | O27: =SUM(C27:L27,N27) -> 17 | P27: =SUM(C27:N27) -> 41 | R27: PM Period | S27: =SUM(S19:S21) -> 104 | T27: =SUM(T19:T21) -> 12 | U27: =SUM(U19:U21) -> 13 | V27: =SUM(V19:V21) -> 19 | W27: =SUM(W19:W21) -> 1 | X27: =SUM(X19:X21) -> 3 | Y27: =SUM(Y19:Y21) -> 12 | Z27: =SUM(Z19:Z21) -> 21 | ... AF27: =SUM(AF19:AF21) -> 549
B28: 11.30 - 11.45 | C28: 10 | D28: 1 | E28: 2 | F28: 2 | G28: 0 | H28: 0 | I28: 2 | J28: 0 | K28: 1 | L28: 0 | M28: 28 | N28: 0 | O28: =SUM(C28:L28,N28) -> 18 | P28: =SUM(C28:N28) -> 46 | R28: 12 Hours | S28: =SUM(S10:S21) -> 393 | T28: =SUM(T10:T21) -> 41 | U28: =SUM(U10:U21) -> 54 | V28: =SUM(V10:V21) -> 58 | W28: =SUM(W10:W21) -> 2 | X28: =SUM(X10:X21) -> 3 | Y28: =SUM(Y10:Y21) -> 77 | Z28: =SUM(Z10:Z21) -> 30 | ... AF28: =SUM(AF10:AF21) -> 2101
B29: 11.45 - 12.00 | C29: 11 | D29: 2 | E29: 3 | F29: 1 | G29: 0 | H29: 0 | I29: 2 | J29: 0 | K29: 0 | L29: 0 | M29: 42 | N29: 0 | O29: =SUM(C29:L29,N29) -> 19 | P29: =SUM(C29:N29) -> 61
B30: 12.00 - 12.15 | C30: 8 | D30: 0 | E30: 0 | F30: 1 | G30: 0 | H30: 0 | I30: 1 | J30: 1 | K30: 0 | L30: 0 | M30: 36 | N30: 0 | O30: =SUM(C30:L30,N30) -> 11 | P30: =SUM(C30:N30) -> 47
B31: 12.15 - 12.30 | C31: 16 | D31: 2 | E31: 3 | F31: 4 | G31: 0 | H31: 0 | I31: 2 | J31: 0 | K31: 0 | L31: 0 | M31: 60 | N31: 0 | O31: =SUM(C31:L31,N31) -> 27 | P31: =SUM(C31:N31) -> 87
B32: 12.30 - 12.45 | C32: 8 | D32: 2 | E32: 2 | F32: 0 | G32: 0 | H32: 0 | I32: 2 | J32: 1 | K32: 0 | L32: 0 | M32: 32 | N32: 0 | O32: =SUM(C32:L32,N32) -> 15 | P32: =SUM(C32:N32) -> 47
B33: 12.45 - 13.00 | C33: 12 | D33: 1 | E33: 1 | F33: 1 | G33: 0 | H33: 0 | I33: 3 | J33: 1 | K33: 0 | L33: 0 | M33: 61 | N33: 0 | O33: =SUM(C33:L33,N33) -> 19 | P33: =SUM(C33:N33) -> 80
B34: 13.00 - 13.15 | C34: 13 | D34: 1 | E34: 1 | F34: 0 | G34: 0 | H34: 0 | I34: 6 | J34: 2 | K34: 1 | L34: 0 | M34: 32 | N34: 0 | O34: =SUM(C34:L34,N34) -> 24 | P34: =SUM(C34:N34) -> 56
B35: 13.15 - 13.30 | C35: 5 | D35: 1 | E35: 1 | F35: 1 | G35: 0 | H35: 0 | I35: 2 | J35: 1 | K35: 0 | L35: 0 | M35: 20 | N35: 0 | O35: =SUM(C35:L35,N35) -> 11 | P35: =SUM(C35:N35) -> 31
B36: 13.30 - 13.45 | C36: 9 | D36: 1 | E36: 1 | F36: 1 | G36: 0 | H36: 0 | I36: 3 | J36: 0 | K36: 0 | L36: 0 | M36: 36 | N36: 0 | O36: =SUM(C36:L36,N36) -> 15 | P36: =SUM(C36:N36) -> 51
B37: 13.45 - 14.00 | C37: 11 | D37: 1 | E37: 1 | F37: 0 | G37: 0 | H37: 0 | I37: 5 | J37: 0 | K37: 0 | L37: 0 | M37: 49 | N37: 0 | O37: =SUM(C37:L37,N37) -> 18 | P37: =SUM(C37:N37) -> 67
B38: 14.00 - 14.15 | C38: 6 | D38: 1 | E38: 1 | F38: 2 | G38: 0 | H38: 0 | I38: 3 | J38: 0 | K38: 1 | L38: 0 | M38: 50 | N38: 0 | O38: =SUM(C38:L38,N38) -> 14 | P38: =SUM(C38:N38) -> 64
B39: 14.15 - 14.30 | C39: 8 | D39: 2 | E39: 3 | F39: 1 | G39: 0 | H39: 0 | I39: 3 | J39: 0 | K39: 0 | L39: 0 | M39: 31 | N39: 0 | O39: =SUM(C39:L39,N39) -> 17 | P39: =SUM(C39:N39) -> 48
B40: 14.30 - 14.45 | C40: 14 | D40: 1 | E40: 2 | F40: 0 | G40: 0 | H40: 0 | I40: 3 | J40: 0 | K40: 0 | L40: 0 | M40: 45 | N40: 0 | O40: =SUM(C40:L40,N40) -> 20 | P40: =SUM(C40:N40) -> 65
... B57: 18.45 - 19.00 | C57: 3 | D57: 2 | E57: 2 | F57: 2 | G57: 0 | H57: 0 | I57: 1 | J57: 2 | K57: 1 | L57: 0 | M57: 35 | N57: 0 | O57: =SUM(C57:L57,N57) -> 13 | P57: =SUM(C57:N57) -> 48
B58: Totals | C58: =SUM(C10:C57) -> 393 | D58: =SUM(D10:D57) -> 41 | E58: =SUM(E10:E57) -> 54 | F58: =SUM(F10:F57) -> 58 | G58: =SUM(G10:G57) -> 2 | H58: =SUM(H10:H57) -> 3 | I58: =SUM(I10:I57) -> 77 | J58: =SUM(J10:J57) -> 30 | ... P58: =SUM(P10:P57) -> 2101
...

Sheet 31.07 Arua-Koboko
B1: Consultancy services for Preparation of Expressway Development Master Plan (EDMP) for Uganda
B2: MANUAL CLASSIFIED COUNT (MCC)
B3: ROAD NAME: | C3: ='31.07 Koboko-Arua'!C3:G3 -> MCC - C5 - STN127 - KOBOKO-ARUA ROAD
C5: Date | D5: ='31.07 Koboko-Arua'!D5 -> 31.07.19 | F5: Location | G5: ='31.07 Koboko-Arua'!G5:H5 -> xxx | J5: Surveyor | K5: ='31.07 Koboko-Arua'!K5:L5 -> xxx
C6: Dir. From | D6: Arua | F6: Dir. To | G6: Koboko | J6: Supervisor | K6: ='31.07 Koboko-Arua'!K6:L6 -> xxx
B8: Time / Veh Type | R8: SUMMARY TRAFFIC VOLUMES
C9: 1. Car | D9: 2. Station Wagon | E9: 3. Pickups | F9: 4. Minibus, matatu | G9: 5. Medium bus | H9: 6. Large Bus | I9: 7. Light Truck | J9: 8. Medium Truck | K9: 9. Heavy truck | L9: 10. Truck Trailer | M9: 11. Motor cycles | N9: 12. Tractors | O9: Total Excl M/Cycles | P9: Total All | R9: Time | S9: 1. Car | T9: 2. Station Wagon | U9: 3. Pickups | V9: 4. Minibus, matatu | W9: 5. Medium bus | X9: 6. Large Bus | Y9: 7. Light Truck | Z9: 8. Medium Truck | AA9: 9. Heavy truck | AB9: 10. Truck Trailer | AC9: 11. Motorcycles | AD9: 12. Tractors, Graders | AE9: Total Excl M/ Cycles | AF9: Total All
B10: 07.00 - 07.15 | C10: 2 | D10: 0 | E10: 0 | F10: 0 | G10: 3 | H10: 1 | I10: 0 | J10: 0 | K10: 0 | L10: 3 | M10: 11 | N10: 0 | O10: =SUM(C10:L10,N10) -> 9 | P10: =SUM(C10:N10) -> 20 | R10: 0700-0800 | S10: =SUM(C10:C13) -> 12 | T10: =SUM(D10:D13) -> 0 | U10: =SUM(E10:E13) -> 0 | V10: =SUM(F10:F13) -> 4 | W10: =SUM(G10:G13) -> 5 | X10: =SUM(H10:H13) -> 1 | Y10: =SUM(I10:I13) -> 0 | Z10: =SUM(J10:J13) -> 2 | ... AF10: =SUM(P10:P13) -> 77
B11: 07.15 - 07.30 | C11: 1 | D11: 0 | E11: 0 | F11: 1 | G11: 0 | H11: 0 | I11: 0 | J11: 0 | K11: 0 | L11: 1 | M11: 6 | N11: 0 | O11: =SUM(C11:L11,N11) -> 3 | P11: =SUM(C11:N11) -> 9 | R11: 0800-0900 | S11: =SUM(C14:C17) -> 28 | T11: =SUM(D14:D17) -> 1 | U11: =SUM(E14:E17) -> 2 | V11: =SUM(F14:F17) -> 5 | W11: =SUM(G14:G17) -> 4 | X11: =SUM(H14:H17) -> 1 | Y11: =SUM(I14:I17) -> 2 | Z11: =SUM(J14:J17) -> 6 | ... AF11: =SUM(P14:P17) -> 110
B12: 07.30 - 07.45 | C12: 2 | D12: 0 | E12: 0 | F12: 1 | G12: 2 | H12: 0 | I12: 0 | J12: 2 | K12: 0 | L12: 3 | M12: 8 | N12: 0 | O12: =SUM(C12:L12,N12) -> 10 | P12: =SUM(C12:N12) -> 18 | R12: 0900-1000 | S12: =SUM(C18:C21) -> 34 | T12: =SUM(D18:D21) -> 0 | U12: =SUM(E18:E21) -> 0 | V12: =SUM(F18:F21) -> 4 | W12: =SUM(G18:G21) -> 0 | X12: =SUM(H18:H21) -> 0 | Y12: =SUM(I18:I21) -> 2 | Z12: =SUM(J18:J21) -> 3 | ... AF12: =SUM(P18:P21) -> 98
B13: 07.45 - 08.00 | C13: 7 | D13: 0 | E13: 0 | F13: 2 | G13: 0 | H13: 0 | I13: 0 | J13: 0 | K13: 0 | L13: 1 | M13: 20 | N13: 0 | O13: =SUM(C13:L13,N13) -> 10 | P13: =SUM(C13:N13) -> 30 | R13: 1000-1100 | S13: =SUM(C22:C25) -> 29 | T13: =SUM(D22:D25) -> 0 | U13: =SUM(E22:E25) -> 0 | V13: =SUM(F22:F25) -> 8 | W13: =SUM(G22:G25) -> 0 | X13: =SUM(H22:H25) -> 1 | Y13: =SUM(I22:I25) -> 7 | Z13: =SUM(J22:J25) -> 4 | ... AF13: =SUM(P22:P25) -> 200
B14: 08.00 - 08.15 | C14: 6 | D14: 0 | E14: 0 | F14: 3 | G14: 0 | H14: 1 | I14: 0 | J14: 0 | K14: 0 | L14: 0 | M14: 10 | N14: 0 | O14: =SUM(C14:L14,N14) -> 10 | P14: =SUM(C14:N14) -> 20 | R14: 1100-1200 | S14: =SUM(C26:C29) -> 46 | T14: =SUM(D26:D29) -> 1 | U14: =SUM(E26:E29) -> 2 | V14: =SUM(F26:F29) -> 4 | W14: =SUM(G26:G29) -> 0 | X14: =SUM(H26:H29) -> 1 | Y14: =SUM(I26:I29) -> 5 | Z14: =SUM(J26:J29) -> 1 | ... AF14: =SUM(P26:P29) -> 186
B15: 08.15 - 08.30 | C15: 8 | D15: 0 | E15: 0 | F15: 1 | G15: 3 | H15: 0 | I15: 0 | J15: 3 | K15: 0 | L15: 0 | M15: 12 | N15: 0 | O15: =SUM(C15:L15,N15) -> 15 | P15: =SUM(C15:N15) -> 27 | R15: 1200-1300 | S15: =SUM(C30:C33) -> 46 | T15: =SUM(D30:D33) -> 0 | U15: =SUM(E30:E33) -> 0 | V15: =SUM(F30:F33) -> 4 | W15: =SUM(G30:G33) -> 1 | X15: =SUM(H30:H33) -> 2 | Y15: =SUM(I30:I33) -> 5 | Z15: =SUM(J30:J33) -> 2 | ... AF15: =SUM(P30:P33) -> 190
B16: 08.30 - 08.45 | C16: 7 | D16: 0 | E16: 0 | F16: 1 | G16: 1 | H16: 0 | I16: 0 | J16: 1 | K16: 1 | L16: 0 | M16: 18 | N16: 0 | O16: =SUM(C16:L16,N16) -> 11 | P16: =SUM(C16:N16) -> 29 | R16: 1300-1400 | S16: =SUM(C34:C37) -> 38 | T16: =SUM(D34:D37) -> 0 | U16: =SUM(E34:E37) -> 0 | V16: =SUM(F34:F37) -> 3 | W16: =SUM(G34:G37) -> 0 | X16: =SUM(H34:H37) -> 1 | Y16: =SUM(I34:I37) -> 8 | Z16: =SUM(J34:J37) -> 2 | ... AF16: =SUM(P34:P37) -> 167
B17: 08.45 - 9.00 | C17: 7 | D17: 1 | E17: 2 | F17: 0 | G17: 0 | H17: 0 | I17: 2 | J17: 2 | K17: 0 | L17: 0 | M17: 20 | N17: 0 | O17: =SUM(C17:L17,N17) -> 14 | P17: =SUM(C17:N17) -> 34 | R17: 1400-1500 | S17: =SUM(C38:C41) -> 50 | T17: =SUM(D38:D41) -> 0 | U17: =SUM(E38:E41) -> 0 | V17: =SUM(F38:F41) -> 5 | W17: =SUM(G38:G41) -> 0 | X17: =SUM(H38:H41) -> 0 | Y17: =SUM(I38:I41) -> 3 | Z17: =SUM(J38:J41) -> 4 | ... AF17: =SUM(P38:P41) -> 259
B18: 09.00 - 09.15 | C18: 14 | D18: 0 | E18: 0 | F18: 2 | G18: 0 | H18: 0 | I18: 0 | J18: 0 | K18: 0 | L18: 0 | M18: 15 | N18: 0 | O18: =SUM(C18:L18,N18) -> 16 | P18: =SUM(C18:N18) -> 31 | R18: 1500-1600 | S18: =SUM(C42:C45) -> 24 | T18: =SUM(D42:D45) -> 0 | U18: =SUM(E42:E45) -> 0 | V18: =SUM(F42:F45) -> 1 | W18: =SUM(G42:G45) -> 0 | X18: =SUM(H42:H45) -> 0 | Y18: =SUM(I42:I45) -> 5 | Z18: =SUM(J42:J45) -> 4 | ... AF18: =SUM(P42:P45) -> 156
B19: 09.15 - 09.30 | C19: 7 | D19: 0 | E19: 0 | F19: 2 | G19: 0 | H19: 0 | I19: 1 | J19: 3 | K19: 0 | L19: 0 | M19: 17 | N19: 0 | O19: =SUM(C19:L19,N19) -> 13 | P19: =SUM(C19:N19) -> 30 | R19: 1600-1700 | S19: =SUM(C46:C49) -> 46 | T19: =SUM(D46:D49) -> 6 | U19: =SUM(E46:E49) -> 10 | V19: =SUM(F46:F49) -> 0 | W19: =SUM(G46:G49) -> 0 | X19: =SUM(H46:H49) -> 0 | Y19: =SUM(I46:I49) -> 1 | Z19: =SUM(J46:J49) -> 3 | ... AF19: =SUM(P46:P49) -> 181
B20: 09.30 - 09.45 | C20: 7 | D20: 0 | E20: 0 | F20: 0 | G20: 0 | H20: 0 | I20: 1 | J20: 0 | K20: 0 | L20: 0 | M20: 12 | N20: 0 | O20: =SUM(C20:L20,N20) -> 8 | P20: =SUM(C20:N20) -> 20 | R20: 1700-1800 | S20: =SUM(C50:C53) -> 41 | T20: =SUM(D50:D53) -> 5 | U20: =SUM(E50:E53) -> 9 | V20: =SUM(F50:F53) -> 7 | W20: =SUM(G50:G53) -> 0 | X20: =SUM(H50:H53) -> 0 | Y20: =SUM(I50:I53) -> 8 | Z20: =SUM(J50:J53) -> 7 | ... AF20: =SUM(P50:P53) -> 165
B21: 09.45 - 10.00 | C21: 6 | D21: 0 | E21: 0 | F21: 0 | G21: 0 | H21: 0 | I21: 0 | J21: 0 | K21: 0 | L21: 0 | M21: 11 | N21: 0 | O21: =SUM(C21:L21,N21) -> 6 | P21: =SUM(C21:N21) -> 17 | R21: 1800-1900 | S21: =SUM(C54:C57) -> 29 | T21: =SUM(D54:D57) -> 5 | U21: =SUM(E54:E57) -> 8 | V21: =SUM(F54:F57) -> 7 | W21: =SUM(G54:G57) -> 1 | X21: =SUM(H54:H57) -> 2 | Y21: =SUM(I54:I57) -> 4 | Z21: =SUM(J54:J57) -> 5 | ... AF21: =SUM(P54:P57) -> 123
B22: 10.00 - 10.15 | C22: 0 | D22: 0 | E22: 0 | F22: 0 | G22: 0 | H22: 0 | I22: 0 | J22: 0 | K22: 0 | L22: 0 | M22: 2 | N22: 0 | O22: =SUM(C22:L22,N22) -> 0 | P22: =SUM(C22:N22) -> 2 | R22: AM Peak Hr | S22: =MAX(S10:S12) -> 34 | T22: =MAX(T10:T12) -> 1 | U22: =MAX(U10:U12) -> 2 | V22: =MAX(V10:V12) -> 5 | W22: =MAX(W10:W12) -> 5 | X22: =MAX(X10:X12) -> 1 | Y22: =MAX(Y10:Y12) -> 2 | Z22: =MAX(Z10:Z12) -> 6 | ... AF22: =MAX(AF10:AF12) -> 110
B23: 10.15 - 10.30 | C23: 5 | D23: 0 | E23: 0 | F23: 0 | G23: 0 | H23: 0 | I23: 0 | J23: 0 | K23: 0 | L23: 0 | M23: 38 | N23: 0 | O23: =SUM(C23:L23,N23) -> 5 | P23: =SUM(C23:N23) -> 43 | R23: IP Peak Hr | S23: =MAX(S13:S18) -> 50 | T23: =MAX(T13:T18) -> 1 | U23: =MAX(U13:U18) -> 2 | V23: =MAX(V13:V18) -> 8 | W23: =MAX(W13:W18) -> 1 | X23: =MAX(X13:X18) -> 2 | Y23: =MAX(Y13:Y18) -> 8 | Z23: =MAX(Z13:Z18) -> 4 | ... AF23: =MAX(AF13:AF18) -> 259
B24: 10.30 - 10.45 | C24: 13 | D24: 0 | E24: 0 | F24: 3 | G24: 0 | H24: 1 | I24: 1 | J24: 1 | K24: 0 | L24: 0 | M24: 65 | N24: 0 | O24: =SUM(C24:L24,N24) -> 19 | P24: =SUM(C24:N24) -> 84 | R24: PM Peak Hr | S24: =MAX(S19:S21) -> 46 | T24: =MAX(T19:T21) -> 6 | U24: =MAX(U19:U21) -> 10 | V24: =MAX(V19:V21) -> 7 | W24: =MAX(W19:W21) -> 1 | X24: =MAX(X19:X21) -> 2 | Y24: =MAX(Y19:Y21) -> 8 | Z24: =MAX(Z19:Z21) -> 7 | ... AF24: =MAX(AF19:AF21) -> 181
B25: 10.45 - 11.00 | C25: 11 | D25: 0 | E25: 0 | F25: 5 | G25: 0 | H25: 0 | I25: 6 | J25: 3 | K25: 0 | L25: 0 | M25: 46 | N25: 0 | O25: =SUM(C25:L25,N25) -> 25 | P25: =SUM(C25:N25) -> 71 | R25: AM Period | S25: =SUM(S10:S12) -> 74 | T25: =SUM(T10:T12) -> 1 | U25: =SUM(U10:U12) -> 2 | V25: =SUM(V10:V12) -> 13 | W25: =SUM(W10:W12) -> 9 | X25: =SUM(X10:X12) -> 2 | Y25: =SUM(Y10:Y12) -> 4 | Z25: =SUM(Z10:Z12) -> 11 | ... AF25: =SUM(AF10:AF12) -> 285
B26: 11.00 - 11.15 | C26: 14 | D26: 0 | E26: 0 | F26: 2 | G26: 0 | H26: 0 | I26: 2 | J26: 0 | K26: 0 | L26: 0 | M26: 41 | N26: 0 | O26: =SUM(C26:L26,N26) -> 18 | P26: =SUM(C26:N26) -> 59 | R26: IP Period | S26: =SUM(S13:S18) -> 233 | T26: =SUM(T13:T18) -> 1 | U26: =SUM(U13:U18) -> 2 | V26: =SUM(V13:V18) -> 25 | W26: =SUM(W13:W18) -> 1 | X26: =SUM(X13:X18) -> 5 | Y26: =SUM(Y13:Y18) -> 33 | Z26: =SUM(Z13:Z18) -> 17 | ... AF26: =SUM(AF13:AF18) -> 1158
B27: 11.15 - 11.30 | C27: 9 | D27: 0 | E27: 0 | F27: 0 | G27: 0 | H27: 1 | I27: 1 | J27: 0 | K27: 0 | L27: 0 | M27: 28 | N27: 0 | O27: =SUM(C27:L27,N27) -> 11 | P27: =SUM(C27:N27) -> 39 | R27: PM Period | S27: =SUM(S19:S21) -> 116 | T27: =SUM(T19:T21) -> 16 | U27: =SUM(U19:U21) -> 27 | V27: =SUM(V19:V21) -> 14 | W27: =SUM(W19:W21) -> 1 | X27: =SUM(X19:X21) -> 2 | Y27: =SUM(Y19:Y21) -> 13 | Z27: =SUM(Z19:Z21) -> 15 | ... AF27: =SUM(AF19:AF21) -> 469
B28: 11.30 - 11.45 | C28: 5 | D28: 0 | E28: 0 | F28: 0 | G28: 0 | H28: 0 | I28: 0 | J28: 0 | K28: 0 | L28: 0 | M28: 16 | N28: 0 | O28: =SUM(C28:L28,N28) -> 5 | P28: =SUM(C28:N28) -> 21 | R28: 12 Hours | S28: =SUM(S10:S21) -> 423 | T28: =SUM(T10:T21) -> 18 | U28: =SUM(U10:U21) -> 31 | V28: =SUM(V10:V21) -> 52 | W28: =SUM(W10:W21) -> 11 | X28: =SUM(X10:X21) -> 9 | Y28: =SUM(Y10:Y21) -> 50 | Z28: =SUM(Z10:Z21) -> 43 | ... AF28: =SUM(AF10:AF21) -> 1912
B29: 11.45 - 12.00 | C29: 18 | D29: 1 | E29: 2 | F29: 2 | G29: 0 | H29: 0 | I29: 2 | J29: 1 | K29: 0 | L29: 0 | M29: 41 | N29: 0 | O29: =SUM(C29:L29,N29) -> 26 | P29: =SUM(C29:N29) -> 67
B30: 12.00 - 12.15 | C30: 11 | D30: 0 | E30: 0 | F30: 1 | G30: 0 | H30: 0 | I30: 1 | J30: 1 | K30: 0 | L30: 0 | M30: 32 | N30: 0 | O30: =SUM(C30:L30,N30) -> 14 | P30: =SUM(C30:N30) -> 46
B31: 12.15 - 12.30 | C31: 7 | D31: 0 | E31: 0 | F31: 0 | G31: 0 | H31: 2 | I31: 2 | J31: 1 | K31: 0 | L31: 0 | M31: 26 | N31: 1 | O31: =SUM(C31:L31,N31) -> 13 | P31: =SUM(C31:N31) -> 39
B32: 12.30 - 12.45 | C32: 14 | D32: 0 | E32: 0 | F32: 2 | G32: 0 | H32: 0 | I32: 1 | J32: 0 | K32: 0 | L32: 0 | M32: 26 | N32: 0 | O32: =SUM(C32:L32,N32) -> 17 | P32: =SUM(C32:N32) -> 43
B33: 12.45 - 13.00 | C33: 14 | D33: 0 | E33: 0 | F33: 1 | G33: 1 | H33: 0 | I33: 1 | J33: 0 | K33: 0 | L33: 0 | M33: 45 | N33: 0 | O33: =SUM(C33:L33,N33) -> 17 | P33: =SUM(C33:N33) -> 62
B34: 13.00 - 13.15 | C34: 7 | D34: 0 | E34: 0 | F34: 2 | G34: 0 | H34: 0 | I34: 2 | J34: 1 | K34: 1 | L34: 1 | M34: 33 | N34: 0 | O34: =SUM(C34:L34,N34) -> 14 | P34: =SUM(C34:N34) -> 47
B35: 13.15 - 13.30 | C35: 12 | D35: 0 | E35: 0 | F35: 0 | G35: 0 | H35: 0 | I35: 0 | J35: 0 | K35: 0 | L35: 0 | M35: 12 | N35: 0 | O35: =SUM(C35:L35,N35) -> 12 | P35: =SUM(C35:N35) -> 24
B36: 13.30 - 13.45 | C36: 10 | D36: 0 | E36: 0 | F36: 0 | G36: 0 | H36: 1 | I36: 3 | J36: 1 | K36: 0 | L36: 0 | M36: 30 | N36: 0 | O36: =SUM(C36:L36,N36) -> 15 | P36: =SUM(C36:N36) -> 45
B37: 13.45 - 14.00 | C37: 9 | D37: 0 | E37: 0 | F37: 1 | G37: 0 | H37: 0 | I37: 3 | J37: 0 | K37: 0 | L37: 0 | M37: 38 | N37: 0 | O37: =SUM(C37:L37,N37) -> 13 | P37: =SUM(C37:N37) -> 51
B38: 14.00 - 14.15 | C38: 15 | D38: 0 | E38: 0 | F38: 1 | G38: 0 | H38: 0 | I38: 0 | J38: 1 | K38: 0 | L38: 0 | M38: 43 | N38: 0 | O38: =SUM(C38:L38,N38) -> 17 | P38: =SUM(C38:N38) -> 60
B39: 14.15 - 14.30 | C39: 9 | D39: 0 | E39: 0 | F39: 1 | G39: 0 | H39: 0 | I39: 1 | J39: 1 | K39: 0 | L39: 0 | M39: 35 | N39: 0 | O39: =SUM(C39:L39,N39) -> 12 | P39: =SUM(C39:N39) -> 47
B40: 14.30 - 14.45 | C40: 10 | D40: 0 | E40: 0 | F40: 2 | G40: 0 | H40: 0 | I40: 2 | J40: 1 | K40: 0 | L40: 0 | M40: 72 | N40: 0 | O40: =SUM(C40:L40,N40) -> 15 | P40: =SUM(C40:N40) -> 87
... B57: 18.45 - 19.00 | C57: 5 | D57: 2 | E57: 3 | F57: 2 | G57: 1 | H57: 2 | I57: 2 | J57: 1 | K57: 2 | L57: 1 | M57: 16 | N57: 0 | O57: =SUM(C57:L57,N57) -> 21 | P57: =SUM(C57:N57) -> 37
B58: Totals | C58: =SUM(C10:C57) -> 423 | D58: =SUM(D10:D57) -> 18 | E58: =SUM(E10:E57) -> 31 | F58: =SUM(F10:F57) -> 52 | G58: =SUM(G10:G57) -> 11 | H58: =SUM(H10:H57) -> 9 | I58: =SUM(I10:I57) -> 50 | J58: =SUM(J10:J57) -> 43 | ... M58: =SUM(M10:M57) -> 1258 | N58: 0 | O58: =SUM(O10:O57) -> 654 | P58: =SUM(P10:P57) -> 1912
...

Sheet 01.08 Koboko-Arua
B1: Consultancy services for Preparation of Expressway Development Master Plan (EDMP) for Uganda
B2: MANUAL CLASSIFIED COUNT (MCC)
B3: ROAD NAME: | C3: ='31.07 Koboko-Arua'!C3:G3 -> MCC - C5 - STN127 - KOBOKO-ARUA ROAD
C5: Date | D5: 01.08.19 | F5: Location | G5: ='31.07 Koboko-Arua'!G5:H5 -> xxx | J5: Surveyor | K5: ='31.07 Koboko-Arua'!K5:L5 -> xxx
C6: Dir. From | D6: ='31.07 Koboko-Arua'!D6:E6 -> Koboko | F6: Dir. To | G6: ='31.07 Koboko-Arua'!G6:H6 -> Arua | J6: Supervisor | K6: ='31.07 Koboko-Arua'!K6:L6 -> xxx
B8: Time / Veh Type | R8: SUMMARY TRAFFIC VOLUMES
C9: 1. Car | D9: 2. Station Wagon | E9: 3. Pickups | F9: 4. Minibus, matatu | G9: 5. Medium bus | H9: 6. Large Bus | I9: 7. Light Truck | J9: 8. Medium Truck | K9: 9. Heavy truck | L9: 10. Truck Trailer | M9: 11. Motor cycles | N9: 12. Tractors | O9: Total Excl M/Cycles | P9: Total All | R9: Time | S9: 1. Car | T9: 2. Station Wagon | U9: 3. Pickups | V9: 4. Minibus, matatu | W9: 5. Medium bus | X9: 6. Large Bus | Y9: 7. Light Truck | Z9: 8. Medium Truck | AA9: 9. Heavy truck | AB9: 10. Truck Trailer | AC9: 11. Motorcycles | AD9: 12. Tractors, Graders | AE9: Total Excl M/ Cycles | AF9: Total All
B10: 07.00 - 07.15 | C10: 3 | D10: 0 | E10: 0 | F10: 0 | G10: 0 | H10: 0 | I10: 0 | J10: 0 | K10: 0 | L10: 0 | M10: 12 | N10: 0 | O10: =SUM(C10:L10,N10) -> 3 | P10: =SUM(C10:N10) -> 15 | R10: 0700-0800 | S10: =SUM(C10:C13) -> 18 | T10: =SUM(D10:D13) -> 1 | U10: =SUM(E10:E13) -> 4 | V10: =SUM(F10:F13) -> 5 | W10: =SUM(G10:G13) -> 1 | X10: =SUM(H10:H13) -> 1 | Y10: =SUM(I10:I13) -> 2 | Z10: =SUM(J10:J13) -> 0 | ... AF10: =SUM(P10:P13) -> 160
B11: 07.15 - 07.30 | C11: 3 | D11: 0 | E11: 0 | F11: 1 | G11: 0 | H11: 0 | I11: 0 | J11: 0 | K11: 0 | L11: 0 | M11: 33 | N11: 0 | O11: =SUM(C11:L11,N11) -> 4 | P11: =SUM(C11:N11) -> 37 | R11: 0800-0900 | S11: =SUM(C14:C17) -> 22 | T11: =SUM(D14:D17) -> 1 | U11: =SUM(E14:E17) -> 5 | V11: =SUM(F14:F17) -> 9 | W11: =SUM(G14:G17) -> 2 | X11: =SUM(H14:H17) -> 1 | Y11: =SUM(I14:I17) -> 3 | Z11: =SUM(J14:J17) -> 8 | ... AF11: =SUM(P14:P17) -> 234
B12: 07.30 - 07.45 | C12: 6 | D12: 0 | E12: 0 | F12: 1 | G12: 1 | H12: 0 | I12: 2 | J12: 0 | K12: 0 | L12: 0 | M12: 46 | N12: 0 | O12: =SUM(C12:L12,N12) -> 10 | P12: =SUM(C12:N12) -> 56 | R12: 0900-1000 | S12: =SUM(C18:C21) -> 22 | T12: =SUM(D18:D21) -> 8 | U12: =SUM(E18:E21) -> 24 | V12: =SUM(F18:F21) -> 4 | W12: =SUM(G18:G21) -> 1 | X12: =SUM(H18:H21) -> 0 | Y12: =SUM(I18:I21) -> 8 | Z12: =SUM(J18:J21) -> 5 | ... AF12: =SUM(P18:P21) -> 213
B13: 07.45 - 08.00 | C13: 6 | D13: 1 | E13: 4 | F13: 3 | G13: 0 | H13: 1 | I13: 0 | J13: 0 | K13: 0 | L13: 0 | M13: 37 | N13: 0 | O13: =SUM(C13:L13,N13) -> 15 | P13: =SUM(C13:N13) -> 52 | R13: 1000-1100 | S13: =SUM(C22:C25) -> 26 | T13: =SUM(D22:D25) -> 1 | U13: =SUM(E22:E25) -> 4 | V13: =SUM(F22:F25) -> 1 | W13: =SUM(G22:G25) -> 3 | X13: =SUM(H22:H25) -> 0 | Y13: =SUM(I22:I25) -> 2 | Z13: =SUM(J22:J25) -> 2 | ... AF13: =SUM(P22:P25) -> 167
B14: 08.00 - 08.15 | C14: 1 | D14: 1 | E14: 5 | F14: 1 | G14: 0 | H14: 0 | I14: 2 | J14: 1 | K14: 0 | L14: 0 | M14: 45 | N14: 0 | O14: =SUM(C14:L14,N14) -> 11 | P14: =SUM(C14:N14) -> 56 | R14: 1100-1200 | S14: =SUM(C26:C29) -> 17 | T14: =SUM(D26:D29) -> 4 | U14: =SUM(E26:E29) -> 12 | V14: =SUM(F26:F29) -> 2 | W14: =SUM(G26:G29) -> 0 | X14: =SUM(H26:H29) -> 2 | Y14: =SUM(I26:I29) -> 7 | Z14: =SUM(J26:J29) -> 1 | ... AF14: =SUM(P26:P29) -> 195
B15: 08.15 - 08.30 | C15: 5 | D15: 0 | E15: 0 | F15: 6 | G15: 1 | H15: 1 | I15: 0 | J15: 5 | K15: 0 | L15: 0 | M15: 51 | N15: 0 | O15: =SUM(C15:L15,N15) -> 18 | P15: =SUM(C15:N15) -> 69 | R15: 1200-1300 | S15: =SUM(C30:C33) -> 26 | T15: =SUM(D30:D33) -> 6 | U15: =SUM(E30:E33) -> 18 | V15: =SUM(F30:F33) -> 1 | W15: =SUM(G30:G33) -> 0 | X15: =SUM(H30:H33) -> 0 | Y15: =SUM(I30:I33) -> 12 | Z15: =SUM(J30:J33) -> 2 | ... AF15: =SUM(P30:P33) -> 189
B16: 08.30 - 08.45 | C16: 10 | D16: 0 | E16: 0 | F16: 1 | G16: 0 | H16: 0 | I16: 0 | J16: 0 | K16: 0 | L16: 0 | M16: 70 | N16: 0 | O16: =SUM(C16:L16,N16) -> 11 | P16: =SUM(C16:N16) -> 81 | R16: 1300-1400 | S16: =SUM(C34:C37) -> 21 | T16: =SUM(D34:D37) -> 10 | U16: =SUM(E34:E37) -> 32 | V16: =SUM(F34:F37) -> 3 | W16: =SUM(G34:G37) -> 0 | X16: =SUM(H34:H37) -> 1 | Y16: =SUM(I34:I37) -> 4 | Z16: =SUM(J34:J37) -> 6 | ... AF16: =SUM(P34:P37) -> 167
B17: 08.45 - 9.00 | C17: 6 | D17: 0 | E17: 0 | F17: 1 | G17: 1 | H17: 0 | I17: 1 | J17: 2 | K17: 0 | L17: 0 | M17: 17 | N17: 0 | O17: =SUM(C17:L17,N17) -> 11 | P17: =SUM(C17:N17) -> 28 | R17: 1400-1500 | S17: =SUM(C38:C41) -> 21 | T17: =SUM(D38:D41) -> 2 | U17: =SUM(E38:E41) -> 10 | V17: =SUM(F38:F41) -> 9 | W17: =SUM(G38:G41) -> 3 | X17: =SUM(H38:H41) -> 0 | Y17: =SUM(I38:I41) -> 11 | Z17: =SUM(J38:J41) -> 6 | ... AF17: =SUM(P38:P41) -> 156
B18: 09.00 - 09.15 | C18: 5 | D18: 3 | E18: 9 | F18: 3 | G18: 1 | H18: 0 | I18: 1 | J18: 1 | K18: 0 | L18: 0 | M18: 48 | N18: 0 | O18: =SUM(C18:L18,N18) -> 23 | P18: =SUM(C18:N18) -> 71 | R18: 1500-1600 | S18: =SUM(C42:C45) -> 16 | T18: =SUM(D42:D45) -> 5 | U18: =SUM(E42:E45) -> 17 | V18: =SUM(F42:F45) -> 3 | W18: =SUM(G42:G45) -> 1 | X18: =SUM(H42:H45) -> 2 | Y18: =SUM(I42:I45) -> 5 | Z18: =SUM(J42:J45) -> 5 | ... AF18: =SUM(P42:P45) -> 144
B19: 09.15 - 09.30 | C19: 5 | D19: 3 | E19: 9 | F19: 0 | G19: 0 | H19: 0 | I19: 2 | J19: 2 | K19: 0 | L19: 0 | M19: 25 | N19: 0 | O19: =SUM(C19:L19,N19) -> 21 | P19: =SUM(C19:N19) -> 46 | R19: 1600-1700 | S19: =SUM(C46:C49) -> 19 | T19: =SUM(D46:D49) -> 8 | U19: =SUM(E46:E49) -> 23 | V19: =SUM(F46:F49) -> 7 | W19: =SUM(G46:G49) -> 2 | X19: =SUM(H46:H49) -> 1 | Y19: =SUM(I46:I49) -> 2 | Z19: =SUM(J46:J49) -> 5 | ... AF19: =SUM(P46:P49) -> 151
B20: 09.30 - 09.45 | C20: 7 | D20: 2 | E20: 6 | F20: 1 | G20: 0 | H20: 0 | I20: 5 | J20: 2 | K20: 2 | L20: 0 | M20: 41 | N20: 0 | O20: =SUM(C20:L20,N20) -> 25 | P20: =SUM(C20:N20) -> 66 | R20: 1700-1800 | S20: =SUM(C50:C53) -> 31 | T20: =SUM(D50:D53) -> 7 | U20: =SUM(E50:E53) -> 23 | V20: =SUM(F50:F53) -> 6 | W20: =SUM(G50:G53) -> 1 | X20: =SUM(H50:H53) -> 0 | Y20: =SUM(I50:I53) -> 9 | Z20: =SUM(J50:J53) -> 5 | ... AF20: =SUM(P50:P53) -> 187
B21: 09.45 - 10.00 | C21: 5 | D21: 0 | E21: 0 | F21: 0 | G21: 0 | H21: 0 | I21: 0 | J21: 0 | K21: 0 | L21: 0 | M21: 25 | N21: 0 | O21: =SUM(C21:L21,N21) -> 5 | P21: =SUM(C21:N21) -> 30 | R21: 1800-1900 | S21: =SUM(C54:C57) -> 27 | T21: =SUM(D54:D57) -> 5 | U21: =SUM(E54:E57) -> 19 | V21: =SUM(F54:F57) -> 12 | W21: =SUM(G54:G57) -> 2 | X21: =SUM(H54:H57) -> 1 | Y21: =SUM(I54:I57) -> 8 | Z21: =SUM(J54:J57) -> 3 | ... AF21: =SUM(P54:P57) -> 149
B22: 10.00 - 10.15 | C22: 0 | D22: 0 | E22: 0 | F22: 0 | G22: 0 | H22: 0 | I22: 2 | K22: 0 | L22: 0 | M22: 36 | N22: 0 | O22: =SUM(C22:L22,N22) -> 2 | P22: =SUM(C22:N22) -> 38 | R22: AM Peak Hr | S22: =MAX(S10:S12) -> 22 | T22: =MAX(T10:T12) -> 8 | U22: =MAX(U10:U12) -> 24 | V22: =MAX(V10:V12) -> 9 | W22: =MAX(W10:W12) -> 2 | X22: =MAX(X10:X12) -> 1 | Y22: =MAX(Y10:Y12) -> 8 | Z22: =MAX(Z10:Z12) -> 8 | ... AF22: =MAX(AF10:AF12) -> 234
B23: 10.15 - 10.30 | C23: 15 | D23: 1 | E23: 4 | F23: 0 | G23: 3 | H23: 0 | I23: 0 | J23: 1 | K23: 0 | L23: 0 | M23: 41 | N23: 0 | O23: =SUM(C23:L23,N23) -> 24 | P23: =SUM(C23:N23) -> 65 | R23: IP Peak Hr | S23: =MAX(S13:S18) -> 26 | T23: =MAX(T13:T18) -> 10 | U23: =MAX(U13:U18) -> 32 | V23: =MAX(V13:V18) -> 9 | W23: =MAX(W13:W18) -> 3 | X23: =MAX(X13:X18) -> 2 | Y23: =MAX(Y13:Y18) -> 12 | Z23: =MAX(Z13:Z18) -> 6 | ... AF23: =MAX(AF13:AF18) -> 195
B24: 10.30 - 10.45 | C24: 5 | D24: 0 | E24: 0 | F24: 1 | G24: 0 | H24: 0 | I24: 0 | J24: 1 | K24: 0 | L24: 0 | M24: 35 | N24: 0 | O24: =SUM(C24:L24,N24) -> 7 | P24: =SUM(C24:N24) -> 42 | R24: PM Peak Hr | S24: =MAX(S19:S21) -> 31 | T24: =MAX(T19:T21) -> 8 | U24: =MAX(U19:U21) -> 23 | V24: =MAX(V19:V21) -> 12 | W24: =MAX(W19:W21) -> 2 | X24: =MAX(X19:X21) -> 1 | Y24: =MAX(Y19:Y21) -> 9 | Z24: =MAX(Z19:Z21) -> 5 | ... AF24: =MAX(AF19:AF21) -> 187
B25: 10.45 - 11.00 | C25: 6 | D25: 0 | E25: 0 | F25: 0 | G25: 0 | H25: 0 | I25: 0 | J25: 0 | K25: 0 | L25: 0 | M25: 16 | N25: 0 | O25: =SUM(C25:L25,N25) -> 6 | P25: =SUM(C25:N25) -> 22 | R25: AM Period | S25: =SUM(S10:S12) -> 62 | T25: =SUM(T10:T12) -> 10 | U25: =SUM(U10:U12) -> 33 | V25: =SUM(V10:V12) -> 18 | W25: =SUM(W10:W12) -> 4 | X25: =SUM(X10:X12) -> 2 | Y25: =SUM(Y10:Y12) -> 13 | Z25: =SUM(Z10:Z12) -> 13 | ... AF25: =SUM(AF10:AF12) -> 607
B26: 11.00 - 11.15 | C26: 7 | D26: 2 | E26: 6 | F26: 0 | G26: 0 | H26: 1 | I26: 0 | J26: 0 | K26: 0 | L26: 0 | M26: 61 | N26: 1 | O26: =SUM(C26:L26,N26) -> 17 | P26: =SUM(C26:N26) -> 78 | R26: IP Period | S26: =SUM(S13:S18) -> 127 | T26: =SUM(T13:T18) -> 28 | U26: =SUM(U13:U18) -> 93 | V26: =SUM(V13:V18) -> 19 | W26: =SUM(W13:W18) -> 7 | X26: =SUM(X13:X18) -> 5 | Y26: =SUM(Y13:Y18) -> 41 | Z26: =SUM(Z13:Z18) -> 22 | ... AF26: =SUM(AF13:AF18) -> 1018
B27: 11.15 - 11.30 | C27: 6 | D27: 0 | E27: 0 | F27: 1 | G27: 0 | H27: 0 | I27: 1 | J27: 0 | K27: 0 | L27: 0 | M27: 17 | N27: 0 | O27: =SUM(C27:L27,N27) -> 8 | P27: =SUM(C27:N27) -> 25 | R27: PM Period | S27: =SUM(S19:S21) -> 77 | T27: =SUM(T19:T21) -> 20 | U27: =SUM(U19:U21) -> 65 | V27: =SUM(V19:V21) -> 25 | W27: =SUM(W19:W21) -> 5 | X27: =SUM(X19:X21) -> 2 | Y27: =SUM(Y19:Y21) -> 19 | Z27: =SUM(Z19:Z21) -> 13 | ... AF27: =SUM(AF19:AF21) -> 487
B28: 11.30 - 11.45 | C28: 1 | D28: 0 | E28: 0 | F28: 1 | G28: 0 | H28: 0 | I28: 5 | J28: 0 | K28: 0 | L28: 0 | M28: 41 | N28: 0 | O28: =SUM(C28:L28,N28) -> 7 | P28: =SUM(C28:N28) -> 48 | R28: 12 Hours | S28: =SUM(S10:S21) -> 266 | T28: =SUM(T10:T21) -> 58 | U28: =SUM(U10:U21) -> 191 | V28: =SUM(V10:V21) -> 62 | W28: =SUM(W10:W21) -> 16 | X28: =SUM(X10:X21) -> 9 | Y28: =SUM(Y10:Y21) -> 73 | Z28: =SUM(Z10:Z21) -> 48 | ... AF28: =SUM(AF10:AF21) -> 2112
B29: 11.45 - 12.00 | C29: 3 | D29: 2 | E29: 6 | F29: 0 | G29: 0 | H29: 1 | I29: 1 | J29: 1 | K29: 0 | L29: 0 | M29: 30 | N29: 0 | O29: =SUM(C29:L29,N29) -> 14 | P29: =SUM(C29:N29) -> 44
B30: 12.00 - 12.15 | C30: 1 | D30: 0 | E30: 0 | F30: 0 | G30: 0 | H30: 0 | I30: 3 | J30: 0 | K30: 0 | L30: 0 | M30: 40 | N30: 0 | O30: =SUM(C30:L30,N30) -> 4 | P30: =SUM(C30:N30) -> 44
B31: 12.15 - 12.30 | C31: 13 | D31: 3 | E31: 8 | F31: 0 | G31: 0 | H31: 0 | I31: 3 | J31: 1 | K31: 0 | L31: 0 | M31: 42 | N31: 0 | O31: =SUM(C31:L31,N31) -> 28 | P31: =SUM(C31:N31) -> 70
B32: 12.30 - 12.45 | C32: 6 | D32: 3 | E32: 10 | F32: 1 | G32: 0 | H32: 0 | I32: 5 | J32: 1 | K32: 0 | L32: 0 | M32: 29 | N32: 0 | O32: =SUM(C32:L32,N32) -> 26 | P32: =SUM(C32:N32) -> 55
B33: 12.45 - 13.00 | C33: 6 | D33: 0 | E33: 0 | F33: 0 | G33: 0 | H33: 0 | I33: 1 | J33: 0 | K33: 0 | L33: 0 | M33: 13 | N33: 0 | O33: =SUM(C33:L33,N33) -> 7 | P33: =SUM(C33:N33) -> 20
B34: 13.00 - 13.15 | C34: 5 | D34: 3 | E34: 11 | F34: 1 | G34: 0 | H34: 1 | I34: 0 | J34: 3 | K34: 0 | L34: 0 | M34: 20 | N34: 0 | O34: =SUM(C34:L34,N34) -> 24 | P34: =SUM(C34:N34) -> 44
B35: 13.15 - 13.30 | C35: 7 | D35: 5 | E35: 12 | F35: 0 | G35: 0 | H35: 0 | I35: 0 | J35: 0 | K35: 0 | L35: 0 | M35: 10 | N35: 0 | O35: =SUM(C35:L35,N35) -> 24 | P35: =SUM(C35:N35) -> 34
B36: 13.30 - 13.45 | C36: 2 | D36: 1 | E36: 5 | F36: 1 | G36: 0 | H36: 0 | I36: 1 | J36: 0 | K36: 0 | L36: 0 | M36: 25 | N36: 0 | O36: =SUM(C36:L36,N36) -> 10 | P36: =SUM(C36:N36) -> 35
B37: 13.45 - 14.00 | C37: 7 | D37: 1 | E37: 4 | F37: 1 | G37: 0 | H37: 0 | I37: 3 | J37: 3 | K37: 0 | L37: 0 | M37: 35 | N37: 0 | O37: =SUM(C37:L37,N37) -> 19 | P37: =SUM(C37:N37) -> 54
B38: 14.00 - 14.15 | C38: 10 | D38: 0 | E38: 0 | F38: 5 | G38: 0 | H38: 0 | I38: 1 | J38: 0 | K38: 0 | L38: 0 | M38: 26 | N38: 0 | O38: =SUM(C38:L38,N38) -> 16 | P38: =SUM(C38:N38) -> 42
B39: 14.15 - 14.30 | C39: 0 | D39: 1 | E39: 5 | F39: 1 | G39: 0 | H39: 0 | I39: 0 | J39: 0 | K39: 0 | L39: 0 | M39: 12 | N39: 0 | O39: =SUM(C39:L39,N39) -> 7 | P39: =SUM(C39:N39) -> 19
B40: 14.30 - 14.45 | C40: 3 | D40: 0 | E40: 0 | F40: 2 | G40: 0 | H40: 0 | I40: 8 | J40: 5 | K40: 0 | L40: 0 | M40: 30 | N40: 0 | O40: =SUM(C40:L40,N40) -> 18 | P40: =SUM(C40:N40) -> 48
... B57: 18.45 - 19.00 | C57: 5 | D57: 1 | E57: 4 | F57: 5 | G57: 2 | H57: 1 | I57: 0 | J57: 2 | K57: 0 | L57: 4 | M57: 10 | N57: 0 | O57: =SUM(C57:L57,N57) -> 24 | P57: =SUM(C57:N57) -> 34
B58: Totals | C58: =SUM(C10:C57) -> 266 | D58: =SUM(D10:D57) -> 58 | E58: =SUM(E10:E57) -> 191 | F58: =SUM(F10:F57) -> 62 | G58: =SUM(G10:G57) -> 16 | H58: =SUM(H10:H57) -> 9 | I58: =SUM(I10:I57) -> 73 | J58: =SUM(J10:J57) -> 48 | ... P58: =SUM(P10:P57) -> 2112
...

Sheet 01.08 Arua-Koboko
B1: Consultancy services for Preparation of Expressway Development Master Plan (EDMP) for Uganda
B2: MANUAL CLASSIFIED COUNT (MCC)
B3: ROAD NAME: | C3: ='31.07 Arua-Koboko'!C3:G3 -> MCC - C5 - STN127 - KOBOKO-ARUA ROAD
C5: Date | D5: ='01.08 Koboko-Arua'!D5 -> 01.08.19 | F5: Location | G5: ='31.07 Koboko-Arua'!G5:H5 -> xxx | J5: Surveyor | K5: ='31.07 Koboko-Arua'!K5:L5 -> xxx
C6: Dir. From | D6: ='31.07 Arua-Koboko'!D6:E6 -> Arua | F6: Dir. To | G6: ='31.07 Arua-Koboko'!G6:H6 -> Koboko | J6: Supervisor | K6: ='31.07 Koboko-Arua'!K6:L6 -> xxx
B8: Time / Veh Type | R8: SUMMARY TRAFFIC VOLUMES
C9: 1. Car | D9: 2. Station Wagon | E9: 3. Pickups | F9: 4. Minibus, matatu | G9: 5. Medium bus | H9: 6. Large Bus | I9: 7. Light Truck | J9: 8. Medium Truck | K9: 9. Heavy truck | L9: 10. Truck Trailer | M9: 11. Motor cycles | N9: 12. Tractors | O9: Total Excl M/Cycles | P9: Total All | R9: Time | S9: 1. Car | T9: 2. Station Wagon | U9: 3. Pickups | V9: 4. Minibus, matatu | W9: 5. Medium bus | X9: 6. Large Bus | Y9: 7. Light Truck | Z9: 8. Medium Truck | AA9: 9. Heavy truck | AB9: 10. Truck Trailer | AC9: 11. Motorcycles | AD9: 12. Tractors, Graders | AE9: Total Excl M/ Cycles | AF9: Total All
B10: 07.00 - 07.15 | C10: 2 | D10: 0 | E10: 0 | F10: 0 | G10: 0 | H10: 0 | I10: 0 | J10: 0 | K10: 0 | L10: 0 | M10: 30 | N10: 0 | O10: =SUM(C10:L10,N10) -> 2 | P10: =SUM(C10:N10) -> 32 | R10: 0700-0800 | S10: =SUM(C10:C13) -> 16 | T10: =SUM(D10:D13) -> 6 | U10: =SUM(E10:E13) -> 8 | V10: =SUM(F10:F13) -> 2 | W10: =SUM(G10:G13) -> 3 | X10: =SUM(H10:H13) -> 31 | Y10: =SUM(I10:I13) -> 6 | Z10: =SUM(J10:J13) -> 1 | ... AF10: =SUM(P10:P13) -> 174
B11: 07.15 - 07.30 | C11: 5 | D11: 1 | E11: 2 | F11: 0 | G11: 0 | H11: 0 | I11: 1 | J11: 0 | K11: 0 | L11: 0 | M11: 22 | N11: 0 | O11: =SUM(C11:L11,N11) -> 9 | P11: =SUM(C11:N11) -> 31 | R11: 0800-0900 | S11: =SUM(C14:C17) -> 13 | T11: =SUM(D14:D17) -> 9 | U11: =SUM(E14:E17) -> 9 | V11: =SUM(F14:F17) -> 11 | W11: =SUM(G14:G17) -> 3 | X11: =SUM(H14:H17) -> 1 | Y11: =SUM(I14:I17) -> 6 | Z11: =SUM(J14:J17) -> 2 | ... AF11: =SUM(P14:P17) -> 175
B12: 07.30 - 07.45 | C12: 4 | D12: 3 | E12: 3 | F12: 1 | G12: 3 | H12: 0 | I12: 5 | J12: 1 | K12: 0 | L12: 0 | M12: 47 | N12: 0 | O12: =SUM(C12:L12,N12) -> 20 | P12: =SUM(C12:N12) -> 67 | R12: 0900-1000 | S12: =SUM(C18:C21) -> 29 | T12: =SUM(D18:D21) -> 15 | U12: =SUM(E18:E21) -> 18 | V12: =SUM(F18:F21) -> 9 | W12: =SUM(G18:G21) -> 2 | X12: =SUM(H18:H21) -> 0 | Y12: =SUM(I18:I21) -> 5 | Z12: =SUM(J18:J21) -> 1 | ... AF12: =SUM(P18:P21) -> 237
B13: 07.45 - 08.00 | C13: 5 | D13: 2 | E13: 3 | F13: 1 | G13: 0 | H13: 31 | I13: 0 | J13: 0 | K13: 0 | L13: 0 | M13: 0 | N13: 2 | O13: =SUM(C13:L13,N13) -> 44 | P13: =SUM(C13:N13) -> 44 | R13: 1000-1100 | S13: =SUM(C22:C25) -> 33 | T13: =SUM(D22:D25) -> 12 | U13: =SUM(E22:E25) -> 12 | V13: =SUM(F22:F25) -> 6 | W13: =SUM(G22:G25) -> 0 | X13: =SUM(H22:H25) -> 0 | Y13: =SUM(I22:I25) -> 8 | Z13: =SUM(J22:J25) -> 3 | ... AF13: =SUM(P22:P25) -> 204
B14: 08.00 - 08.15 | C14: 3 | D14: 0 | E14: 0 | F14: 5 | G14: 0 | H14: 1 | I14: 3 | J14: 1 | K14: 0 | L14: 0 | M14: 42 | N14: 0 | O14: =SUM(C14:L14,N14) -> 13 | P14: =SUM(C14:N14) -> 55 | R14: 1100-1200 | S14: =SUM(C26:C29) -> 37 | T14: =SUM(D26:D29) -> 8 | U14: =SUM(E26:E29) -> 11 | V14: =SUM(F26:F29) -> 6 | W14: =SUM(G26:G29) -> 0 | X14: =SUM(H26:H29) -> 0 | Y14: =SUM(I26:I29) -> 3 | Z14: =SUM(J26:J29) -> 3 | ... AF14: =SUM(P26:P29) -> 191
B15: 08.15 - 08.30 | C15: 3 | D15: 0 | E15: 0 | F15: 0 | G15: 0 | H15: 0 | I15: 0 | J15: 1 | K15: 0 | L15: 0 | M15: 12 | N15: 0 | O15: =SUM(C15:L15,N15) -> 4 | P15: =SUM(C15:N15) -> 16 | R15: 1200-1300 | S15: =SUM(C30:C33) -> 33 | T15: =SUM(D30:D33) -> 8 | U15: =SUM(E30:E33) -> 10 | V15: =SUM(F30:F33) -> 3 | W15: =SUM(G30:G33) -> 0 | X15: =SUM(H30:H33) -> 0 | Y15: =SUM(I30:I33) -> 3 | Z15: =SUM(J30:J33) -> 7 | ... AF15: =SUM(P30:P33) -> 203
B16: 08.30 - 08.45 | C16: 2 | D16: 5 | E16: 5 | F16: 4 | G16: 3 | H16: 0 | I16: 3 | J16: 0 | K16: 0 | L16: 11 | M16: 37 | N16: 0 | O16: =SUM(C16:L16,N16) -> 33 | P16: =SUM(C16:N16) -> 70 | R16: 1300-1400 | S16: =SUM(C34:C37) -> 25 | T16: =SUM(D34:D37) -> 7 | U16: =SUM(E34:E37) -> 9 | V16: =SUM(F34:F37) -> 3 | W16: =SUM(G34:G37) -> 0 | X16: =SUM(H34:H37) -> 2 | Y16: =SUM(I34:I37) -> 5 | Z16: =SUM(J34:J37) -> 3 | ... AF16: =SUM(P34:P37) -> 168
B17: 08.45 - 9.00 | C17: 5 | D17: 4 | E17: 4 | F17: 2 | G17: 0 | H17: 0 | I17: 0 | J17: 0 | K17: 0 | L17: 0 | M17: 19 | N17: 0 | O17: =SUM(C17:L17,N17) -> 15 | P17: =SUM(C17:N17) -> 34 | R17: 1400-1500 | S17: =SUM(C38:C41) -> 32 | T17: =SUM(D38:D41) -> 4 | U17: =SUM(E38:E41) -> 5 | V17: =SUM(F38:F41) -> 3 | W17: =SUM(G38:G41) -> 0 | X17: =SUM(H38:H41) -> 0 | Y17: =SUM(I38:I41) -> 12 | Z17: =SUM(J38:J41) -> 5 | ... AF17: =SUM(P38:P41) -> 186
B18: 09.00 - 09.15 | C18: 12 | D18: 4 | E18: 5 | F18: 1 | G18: 1 | H18: 0 | I18: 2 | J18: 0 | K18: 0 | L18: 1 | M18: 49 | N18: 0 | O18: =SUM(C18:L18,N18) -> 26 | P18: =SUM(C18:N18) -> 75 | R18: 1500-1600 | S18: =SUM(C42:C45) -> 37 | T18: =SUM(D42:D45) -> 5 | U18: =SUM(E42:E45) -> 8 | V18: =SUM(F42:F45) -> 2 | W18: =SUM(G42:G45) -> 0 | X18: =SUM(H42:H45) -> 0 | Y18: =SUM(I42:I45) -> 13 | Z18: =SUM(J42:J45) -> 8 | ... AF18: =SUM(P42:P45) -> 192
B19: 09.15 - 09.30 | C19: 5 | D19: 2 | E19: 2 | F19: 7 | G19: 0 | H19: 0 | I19: 1 | J19: 0 | K19: 0 | L19: 0 | M19: 35 | N19: 0 | O19: =SUM(C19:L19,N19) -> 17 | P19: =SUM(C19:N19) -> 52 | R19: 1600-1700 | S19: =SUM(C46:C49) -> 15 | T19: =SUM(D46:D49) -> 5 | U19: =SUM(E46:E49) -> 6 | V19: =SUM(F46:F49) -> 3 | W19: =SUM(G46:G49) -> 2 | X19: =SUM(H46:H49) -> 1 | Y19: =SUM(I46:I49) -> 13 | Z19: =SUM(J46:J49) -> 3 | ... AF19: =SUM(P46:P49) -> 139
B20: 09.30 - 09.45 | C20: 1 | D20: 3 | E20: 4 | F20: 1 | G20: 0 | H20: 0 | I20: 1 | J20: 0 | K20: 0 | L20: 1 | M20: 45 | N20: 0 | O20: =SUM(C20:L20,N20) -> 11 | P20: =SUM(C20:N20) -> 56 | R20: 1700-1800 | S20: =SUM(C50:C53) -> 58 | T20: =SUM(D50:D53) -> 6 | U20: =SUM(E50:E53) -> 8 | V20: =SUM(F50:F53) -> 11 | W20: =SUM(G50:G53) -> 3 | X20: =SUM(H50:H53) -> 0 | Y20: =SUM(I50:I53) -> 14 | Z20: =SUM(J50:J53) -> 50 | ... AF20: =SUM(P50:P53) -> 280
B21: 09.45 - 10.00 | C21: 11 | D21: 6 | E21: 7 | F21: 0 | G21: 1 | H21: 0 | I21: 1 | J21: 1 | K21: 0 | L21: 0 | M21: 27 | N21: 0 | O21: =SUM(C21:L21,N21) -> 27 | P21: =SUM(C21:N21) -> 54 | R21: 1800-1900 | S21: =SUM(C54:C57) -> 13 | T21: =SUM(D54:D57) -> 3 | U21: =SUM(E54:E57) -> 4 | V21: =SUM(F54:F57) -> 2 | W21: =SUM(G54:G57) -> 2 | X21: =SUM(H54:H57) -> 2 | Y21: =SUM(I54:I57) -> 11 | Z21: =SUM(J54:J57) -> 8 | ... AF21: =SUM(P54:P57) -> 206
B22: 10.00 - 10.15 | C22: 9 | D22: 1 | E22: 1 | F22: 2 | G22: 0 | H22: 0 | I22: 1 | J22: 2 | K22: 0 | L22: 0 | M22: 27 | N22: 0 | O22: =SUM(C22:L22,N22) -> 16 | P22: =SUM(C22:N22) -> 43 | R22: AM Peak Hr | S22: =MAX(S10:S12) -> 29 | T22: =MAX(T10:T12) -> 15 | U22: =MAX(U10:U12) -> 18 | V22: =MAX(V10:V12) -> 11 | W22: =MAX(W10:W12) -> 3 | X22: =MAX(X10:X12) -> 31 | Y22: =MAX(Y10:Y12) -> 6 | Z22: =MAX(Z10:Z12) -> 2 | ... AF22: =MAX(AF10:AF12) -> 237
B23: 10.15 - 10.30 | C23: 9 | D23: 5 | E23: 5 | F23: 2 | G23: 0 | H23: 0 | I23: 4 | J23: 1 | K23: 0 | L23: 0 | M23: 35 | N23: 0 | O23: =SUM(C23:L23,N23) -> 26 | P23: =SUM(C23:N23) -> 61 | R23: IP Peak Hr | S23: =MAX(S13:S18) -> 37 | T23: =MAX(T13:T18) -> 12 | U23: =MAX(U13:U18) -> 12 | V23: =MAX(V13:V18) -> 6 | W23: =MAX(W13:W18) -> 0 | X23: =MAX(X13:X18) -> 2 | Y23: =MAX(Y13:Y18) -> 13 | Z23: =MAX(Z13:Z18) -> 8 | ... AF23: =MAX(AF13:AF18) -> 204
B24: 10.30 - 10.45 | C24: 12 | D24: 4 | E24: 4 | F24: 2 | G24: 0 | H24: 0 | I24: 2 | J24: 0 | K24: 0 | L24: 0 | M24: 38 | N24: 0 | O24: =SUM(C24:L24,N24) -> 24 | P24: =SUM(C24:N24) -> 62 | R24: PM Peak Hr | S24: =MAX(S19:S21) -> 58 | T24: =MAX(T19:T21) -> 6 | U24: =MAX(U19:U21) -> 8 | V24: =MAX(V19:V21) -> 11 | W24: =MAX(W19:W21) -> 3 | X24: =MAX(X19:X21) -> 2 | Y24: =MAX(Y19:Y21) -> 14 | Z24: =MAX(Z19:Z21) -> 50 | ... AF24: =MAX(AF19:AF21) -> 280
B25: 10.45 - 11.00 | C25: 3 | D25: 2 | E25: 2 | F25: 0 | G25: 0 | H25: 0 | I25: 1 | J25: 0 | K25: 0 | L25: 0 | M25: 30 | N25: 0 | O25: =SUM(C25:L25,N25) -> 8 | P25: =SUM(C25:N25) -> 38 | R25: AM Period | S25: =SUM(S10:S12) -> 58 | T25: =SUM(T10:T12) -> 30 | U25: =SUM(U10:U12) -> 35 | V25: =SUM(V10:V12) -> 22 | W25: =SUM(W10:W12) -> 8 | X25: =SUM(X10:X12) -> 32 | Y25: =SUM(Y10:Y12) -> 17 | Z25: =SUM(Z10:Z12) -> 4 | ... AF25: =SUM(AF10:AF12) -> 586
B26: 11.00 - 11.15 | C26: 11 | D26: 3 | E26: 4 | F26: 2 | G26: 0 | H26: 0 | I26: 2 | J26: 0 | K26: 0 | L26: 2 | M26: 39 | N26: 0 | O26: =SUM(C26:L26,N26) -> 24 | P26: =SUM(C26:N26) -> 63 | R26: IP Period | S26: =SUM(S13:S18) -> 197 | T26: =SUM(T13:T18) -> 44 | U26: =SUM(U13:U18) -> 55 | V26: =SUM(V13:V18) -> 23 | W26: =SUM(W13:W18) -> 0 | X26: =SUM(X13:X18) -> 2 | Y26: =SUM(Y13:Y18) -> 44 | Z26: =SUM(Z13:Z18) -> 29 | ... AF26: =SUM(AF13:AF18) -> 1144
B27: 11.15 - 11.30 | C27: 10 | D27: 2 | E27: 2 | F27: 1 | G27: 0 | H27: 0 | I27: 0 | J27: 1 | K27: 0 | L27: 0 | M27: 32 | N27: 0 | O27: =SUM(C27:L27,N27) -> 16 | P27: =SUM(C27:N27) -> 48 | R27: PM Period | S27: =SUM(S19:S21) -> 86 | T27: =SUM(T19:T21) -> 14 | U27: =SUM(U19:U21) -> 18 | V27: =SUM(V19:V21) -> 16 | W27: =SUM(W19:W21) -> 7 | X27: =SUM(X19:X21) -> 3 | Y27: =SUM(Y19:Y21) -> 38 | Z27: =SUM(Z19:Z21) -> 61 | ... AF27: =SUM(AF19:AF21) -> 625
B28: 11.30 - 11.45 | C28: 8 | D28: 1 | E28: 2 | F28: 2 | G28: 0 | H28: 0 | I28: 1 | J28: 0 | K28: 0 | L28: 0 | M28: 24 | N28: 1 | O28: =SUM(C28:L28,N28) -> 15 | P28: =SUM(C28:N28) -> 39 | R28: 12 Hours | S28: =SUM(S10:S21) -> 341 | T28: =SUM(T10:T21) -> 88 | U28: =SUM(U10:U21) -> 108 | V28: =SUM(V10:V21) -> 61 | W28: =SUM(W10:W21) -> 15 | X28: =SUM(X10:X21) -> 37 | Y28: =SUM(Y10:Y21) -> 99 | Z28: =SUM(Z10:Z21) -> 94 | ... AF28: =SUM(AF10:AF21) -> 2355
B29: 11.45 - 12.00 | C29: 8 | D29: 2 | E29: 3 | F29: 1 | G29: 0 | H29: 0 | I29: 0 | J29: 2 | K29: 0 | L29: 0 | M29: 25 | N29: 0 | O29: =SUM(C29:L29,N29) -> 16 | P29: =SUM(C29:N29) -> 41
B30: 12.00 - 12.15 | C30: 7 | D30: 1 | E30: 2 | F30: 0 | G30: 0 | H30: 0 | I30: 0 | J30: 3 | K30: 0 | L30: 0 | M30: 39 | N30: 0 | O30: =SUM(C30:L30,N30) -> 13 | P30: =SUM(C30:N30) -> 52
B31: 12.15 - 12.30 | C31: 5 | D31: 4 | E31: 4 | F31: 0 | G31: 0 | H31: 0 | I31: 2 | J31: 1 | K31: 0 | L31: 0 | M31: 38 | N31: 0 | O31: =SUM(C31:L31,N31) -> 16 | P31: =SUM(C31:N31) -> 54
B32: 12.30 - 12.45 | C32: 16 | D32: 1 | E32: 2 | F32: 2 | G32: 0 | H32: 0 | I32: 0 | J32: 2 | K32: 0 | L32: 0 | M32: 38 | N32: 0 | O32: =SUM(C32:L32,N32) -> 23 | P32: =SUM(C32:N32) -> 61
B33: 12.45 - 13.00 | C33: 5 | D33: 2 | E33: 2 | F33: 1 | G33: 0 | H33: 0 | I33: 1 | J33: 1 | K33: 1 | L33: 0 | M33: 23 | N33: 0 | O33: =SUM(C33:L33,N33) -> 13 | P33: =SUM(C33:N33) -> 36
B34: 13.00 - 13.15 | C34: 3 | D34: 2 | E34: 3 | F34: 0 | G34: 0 | H34: 0 | I34: 1 | J34: 0 | K34: 0 | L34: 0 | M34: 36 | N34: 0 | O34: =SUM(C34:L34,N34) -> 9 | P34: =SUM(C34:N34) -> 45
B35: 13.15 - 13.30 | C35: 6 | D35: 1 | E35: 2 | F35: 0 | G35: 0 | H35: 0 | I35: 0 | J35: 0 | K35: 0 | L35: 2 | M35: 30 | N35: 0 | O35: =SUM(C35:L35,N35) -> 11 | P35: =SUM(C35:N35) -> 41
B36: 13.30 - 13.45 | C36: 13 | D36: 2 | E36: 2 | F36: 1 | G36: 0 | H36: 2 | I36: 1 | J36: 2 | K36: 0 | L36: 1 | M36: 33 | N36: 0 | O36: =SUM(C36:L36,N36) -> 24 | P36: =SUM(C36:N36) -> 57
B37: 13.45 - 14.00 | C37: 3 | D37: 2 | E37: 2 | F37: 2 | G37: 0 | H37: 0 | I37: 3 | J37: 1 | K37: 0 | L37: 0 | M37: 12 | N37: 0 | O37: =SUM(C37:L37,N37) -> 13 | P37: =SUM(C37:N37) -> 25
B38: 14.00 - 14.15 | C38: 6 | D38: 1 | E38: 1 | F38: 2 | G38: 0 | H38: 0 | I38: 3 | J38: 1 | K38: 0 | L38: 1 | M38: 25 | N38: 0 | O38: =SUM(C38:L38,N38) -> 15 | P38: =SUM(C38:N38) -> 40
B39: 14.15 - 14.30 | C39: 5 | D39: 2 | E39: 2 | F39: 0 | G39: 0 | H39: 0 | I39: 2 | J39: 0 | K39: 0 | L39: 0 | M39: 32 | N39: 0 | O39: =SUM(C39:L39,N39) -> 11 | P39: =SUM(C39:N39) -> 43
B40: 14.30 - 14.45 | C40: 11 | D40: 0 | E40: 0 | F40: 1 | G40: 0 | H40: 0 | I40: 4 | J40: 3 | K40: 0 | L40: 0 | M40: 32 | N40: 0 | O40: =SUM(C40:L40,N40) -> 19 | P40: =SUM(C40:N40) -> 51
... B57: 18.45 - 19.00 | C57: 1 | D57: 1 | E57: 2 | F57: 0 | G57: 2 | H57: 2 | I57: 3 | J57: 2 | K57: 1 | L57: 2 | M57: 45 | N57: 0 | O57: =SUM(C57:L57,N57) -> 16 | P57: =SUM(C57:N57) -> 61
B58: Totals | C58: =SUM(C10:C57) -> 341 | D58: =SUM(D10:D57) -> 88 | E58: =SUM(E10:E57) -> 108 | F58: =SUM(F10:F57) -> 61 | G58: =SUM(G10:G57) -> 15 | H58: =SUM(H10:H57) -> 37 | I58: =SUM(I10:I57) -> 99 | J58: =SUM(J10:J57) -> 94 | ... P58: =SUM(P10:P57) -> 2355
...

Sheet 02.08 Koboko-Arua-24h
B1: Consultancy services for Preparation of Expressway Development Master Plan (EDMP) for Uganda
B2: MANUAL CLASSIFIED COUNT (MCC)
B3: ROAD NAME: | C3: ='31.07 Koboko-Arua'!C3:G3 -> MCC - C5 - STN127 - KOBOKO-ARUA ROAD
C5: Date | D5: 26.07.19 | F5: Location | G5: ='05.08 Arua-Koboko'!G5:H5 -> xxx | J5: Surveyor | K5: ='05.08 Arua-Koboko'!K5:L5 -> xxx
C6: Dir. From | D6: ='31.07 Koboko-Arua'!D6:E6 -> Koboko | F6: Dir. To | G6: ='31.07 Koboko-Arua'!G6:H6 -> Arua | J6: Supervisor | K6: ='05.08 Arua-Koboko'!K6:L6 -> xxx
B8: Time / Veh Type | R8: SUMMARY TRAFFIC VOLUMES
C9: 1. Car | D9: 2. Station Wagon | E9: 3. Pickups | F9: 4. Minibus, matatu | G9: 5. Medium bus | H9: 6. Large Bus | I9: 7. Light Truck | J9: 8. Medium Truck | K9: 9. Heavy truck | L9: 10. Truck Trailer | M9: 11. Motor cycles | N9: 12. Tractors | O9: Total Excl M/Cycles | P9: Total All | R9: Time | S9: 1. Car | T9: 2. Station Wagon | U9: 3. Pickups | V9: 4. Minibus, matatu | W9: 5. Medium bus | X9: 6. Large Bus | Y9: 7. Light Truck | Z9: 8. Medium Truck | AA9: 9. Heavy truck | AB9: 10. Truck Trailer | AC9: 11. Motorcycles | AD9: 12. Tractors, Graders | AE9: Total Excl M/ Cycles | AF9: Total All
B10: 07.00 - 07.15 | C10: 8 | D10: 0 | E10: 0 | F10: 2 | G10: 2 | H10: 0 | I10: 2 | J10: 0 | K10: 0 | L10: 2 | M10: 16 | N10: 0 | O10: =SUM(C10:L10,N10) -> 16 | P10: =SUM(C10:N10) -> 32 | R10: 0700-0800 | S10: =SUM(C10:C13) -> 16 | T10: =SUM(D10:D13) -> 1 | U10: =SUM(E10:E13) -> 2 | V10: =SUM(F10:F13) -> 11 | W10: =SUM(G10:G13) -> 2 | X10: =SUM(H10:H13) -> 2 | Y10: =SUM(I10:I13) -> 3 | Z10: =SUM(J10:J13) -> 1 | ... AF10: =SUM(P10:P13) -> 160
B11: 07.15 - 07.30 | C11: 0 | D11: 0 | E11: 0 | F11: 1 | G11: 0 | H11: 0 | I11: 0 | J11: 0 | K11: 0 | L11: 0 | M11: 33 | N11: 0 | O11: =SUM(C11:L11,N11) -> 1 | P11: =SUM(C11:N11) -> 34 | R11: 0800-0900 | S11: =SUM(C14:C17) -> 26 | T11: =SUM(D14:D17) -> 7 | U11: =SUM(E14:E17) -> 13 | V11: =SUM(F14:F17) -> 4 | W11: =SUM(G14:G17) -> 2 | X11: =SUM(H14:H17) -> 0 | Y11: =SUM(I14:I17) -> 9 | Z11: =SUM(J14:J17) -> 1 | ... AF11: =SUM(P14:P17) -> 199
B12: 07.30 - 07.45 | C12: 2 | D12: 0 | E12: 0 | F12: 2 | G12: 0 | H12: 0 | I12: 0 | J12: 0 | K12: 0 | L12: 0 | M12: 46 | N12: 0 | O12: =SUM(C12:L12,N12) -> 4 | P12: =SUM(C12:N12) -> 50 | R12: 0900-1000 | S12: =SUM(C18:C21) -> 33 | T12: =SUM(D18:D21) -> 6 | U12: =SUM(E18:E21) -> 11 | V12: =SUM(F18:F21) -> 6 | W12: =SUM(G18:G21) -> 0 | X12: =SUM(H18:H21) -> 0 | Y12: =SUM(I18:I21) -> 10 | Z12: =SUM(J18:J21) -> 0 | ... AF12: =SUM(P18:P21) -> 167
B13: 07.45 - 08.00 | C13: 6 | D13: 1 | E13: 2 | F13: 6 | G13: 0 | H13: 2 | I13: 1 | J13: 1 | K13: 0 | L13: 0 | M13: 25 | N13: 0 | O13: =SUM(C13:L13,N13) -> 19 | P13: =SUM(C13:N13) -> 44 | R13: 1000-1100 | S13: =SUM(C22:C25) -> 34 | T13: =SUM(D22:D25) -> 11 | U13: =SUM(E22:E25) -> 20 | V13: =SUM(F22:F25) -> 4 | W13: =SUM(G22:G25) -> 2 | X13: =SUM(H22:H25) -> 0 | Y13: =SUM(I22:I25) -> 6 | Z13: =SUM(J22:J25) -> 0 | ... AF13: =SUM(P22:P25) -> 232
B14: 08.00 - 08.15 | C14: 8 | D14: 1 | E14: 2 | F14: 1 | G14: 0 | H14: 0 | I14: 2 | J14: 0 | K14: 0 | L14: 0 | M14: 50 | N14: 0 | O14: =SUM(C14:L14,N14) -> 14 | P14: =SUM(C14:N14) -> 64 | R14: 1100-1200 | S14: =SUM(C26:C29) -> 30 | T14: =SUM(D26:D29) -> 5 | U14: =SUM(E26:E29) -> 8 | V14: =SUM(F26:F29) -> 7 | W14: =SUM(G26:G29) -> 0 | X14: =SUM(H26:H29) -> 1 | Y14: =SUM(I26:I29) -> 12 | Z14: =SUM(J26:J29) -> 1 | ... AF14: =SUM(P26:P29) -> 198
B15: 08.15 - 08.30 | C15: 0 | D15: 1 | E15: 2 | F15: 1 | G15: 1 | H15: 0 | I15: 2 | J15: 1 | K15: 0 | L15: 0 | M15: 16 | N15: 0 | O15: =SUM(C15:L15,N15) -> 8 | P15: =SUM(C15:N15) -> 24 | R15: 1200-1300 | S15: =SUM(C30:C33) -> 28 | T15: =SUM(D30:D33) -> 10 | U15: =SUM(E30:E33) -> 17 | V15: =SUM(F30:F33) -> 15 | W15: =SUM(G30:G33) -> 1 | X15: =SUM(H30:H33) -> 0 | Y15: =SUM(I30:I33) -> 6 | Z15: =SUM(J30:J33) -> 0 | ... AF15: =SUM(P30:P33) -> 207
B16: 08.30 - 08.45 | C16: 13 | D16: 2 | E16: 4 | F16: 0 | G16: 0 | H16: 0 | I16: 3 | J16: 0 | K16: 0 | L16: 0 | M16: 36 | N16: 0 | O16: =SUM(C16:L16,N16) -> 22 | P16: =SUM(C16:N16) -> 58 | R16: 1300-1400 | S16: =SUM(C34:C37) -> 12 | T16: =SUM(D34:D37) -> 9 | U16: =SUM(E34:E37) -> 15 | V16: =SUM(F34:F37) -> 15 | W16: =SUM(G34:G37) -> 1 | X16: =SUM(H34:H37) -> 2 | Y16: =SUM(I34:I37) -> 8 | Z16: =SUM(J34:J37) -> 3 | ... AF16: =SUM(P34:P37) -> 122
B17: 08.45 - 9.00 | C17: 5 | D17: 3 | E17: 5 | F17: 2 | G17: 1 | H17: 0 | I17: 2 | J17: 0 | K17: 0 | L17: 0 | M17: 35 | N17: 0 | O17: =SUM(C17:L17,N17) -> 18 | P17: =SUM(C17:N17) -> 53 | R17: 1400-1500 | S17: =SUM(C38:C41) -> 11 | T17: =SUM(D38:D41) -> 7 | U17: =SUM(E38:E41) -> 13 | V17: =SUM(F38:F41) -> 0 | W17: =SUM(G38:G41) -> 2 | X17: =SUM(H38:H41) -> 0 | Y17: =SUM(I38:I41) -> 10 | Z17: =SUM(J38:J41) -> 0 | ... AF17: =SUM(P38:P41) -> 84
B18: 09.00 - 09.15 | C18: 15 | D18: 1 | E18: 2 | F18: 1 | G18: 0 | H18: 0 | I18: 1 | J18: 0 | K18: 0 | L18: 0 | M18: 35 | N18: 0 | O18: =SUM(C18:L18,N18) -> 20 | P18: =SUM(C18:N18) -> 55 | R18: 1500-1600 | S18: =SUM(C42:C45) -> 24 | T18: =SUM(D42:D45) -> 13 | U18: =SUM(E42:E45) -> 22 | V18: =SUM(F42:F45) -> 8 | W18: =SUM(G42:G45) -> 0 | X18: =SUM(H42:H45) -> 0 | Y18: =SUM(I42:I45) -> 16 | Z18: =SUM(J42:J45) -> 2 | ... AF18: =SUM(P42:P45) -> 214
B19: 09.15 - 09.30 | C19: 7 | D19: 0 | E19: 0 | F19: 0 | G19: 0 | H19: 0 | I19: 1 | J19: 0 | K19: 0 | L19: 5 | M19: 20 | N19: 0 | O19: =SUM(C19:L19,N19) -> 13 | P19: =SUM(C19:N19) -> 33 | R19: 1600-1700 | S19: =SUM(C46:C49) -> 36 | T19: =SUM(D46:D49) -> 17 | U19: =SUM(E46:E49) -> 28 | V19: =SUM(F46:F49) -> 8 | W19: =SUM(G46:G49) -> 0 | X19: =SUM(H46:H49) -> 0 | Y19: =SUM(I46:I49) -> 6 | Z19: =SUM(J46:J49) -> 0 | ... AF19: =SUM(P46:P49) -> 260
B20: 09.30 - 09.45 | C20: 8 | D20: 3 | E20: 5 | F20: 5 | G20: 0 | H20: 0 | I20: 5 | J20: 0 | K20: 0 | L20: 0 | M20: 20 | N20: 0 | O20: =SUM(C20:L20,N20) -> 26 | P20: =SUM(C20:N20) -> 46 | R20: 1700-1800 | S20: =SUM(C50:C53) -> 39 | T20: =SUM(D50:D53) -> 15 | U20: =SUM(E50:E53) -> 24 | V20: =SUM(F50:F53) -> 7 | W20: =SUM(G50:G53) -> 0 | X20: =SUM(H50:H53) -> 1 | Y20: =SUM(I50:I53) -> 11 | Z20: =SUM(J50:J53) -> 3 | ... AF20: =SUM(P50:P53) -> 294
B21: 09.45 - 10.00 | C21: 3 | D21: 2 | E21: 4 | F21: 0 | G21: 0 | H21: 0 | I21: 3 | J21: 0 | K21: 0 | L21: 0 | M21: 21 | N21: 0 | O21: =SUM(C21:L21,N21) -> 12 | P21: =SUM(C21:N21) -> 33 | R21: 1800-1900 | S21: =SUM(C54:C57) -> 13 | T21: =SUM(D54:D57) -> 8 | U21: =SUM(E54:E57) -> 14 | V21: =SUM(F54:F57) -> 2 | W21: =SUM(G54:G57) -> 0 | X21: =SUM(H54:H57) -> 0 | Y21: =SUM(I54:I57) -> 12 | Z21: =SUM(J54:J57) -> 9 | ... AF21: =SUM(P54:P57) -> 161
B22: 10.00 - 10.15 | C22: 6 | D22: 3 | E22: 5 | F22: 1 | G22: 1 | H22: 0 | I22: 3 | J22: 0 | K22: 0 | L22: 0 | M22: 32 | N22: 0 | O22: =SUM(C22:L22,N22) -> 19 | P22: =SUM(C22:N22) -> 51 | R22: 1900-2000 | S22: =SUM(C58:C61) -> 35 | T22: =SUM(D58:D61) -> 15 | U22: =SUM(E58:E61) -> 25 | V22: =SUM(F58:F61) -> 20 | W22: =SUM(G58:G61) -> 16 | X22: =SUM(H58:H61) -> 1 | Y22: =SUM(I58:I61) -> 3 | Z22: =SUM(J58:J61) -> 3 | ... AF22: =SUM(P58:P61) -> 332
B23: 10.15 - 10.30 | C23: 8 | D23: 4 | E23: 6 | F23: 2 | G23: 1 | H23: 0 | I23: 1 | J23: 0 | K23: 0 | L23: 0 | M23: 27 | N23: 0 | O23: =SUM(C23:L23,N23) -> 22 | P23: =SUM(C23:N23) -> 49 | R23: 2000-2100 | S23: =SUM(C62:C65) -> 23 | T23: =SUM(D62:D65) -> 8 | U23: =SUM(E62:E65) -> 21 | V23: =SUM(F62:F65) -> 7 | W23: =SUM(G62:G65) -> 11 | X23: =SUM(H62:H65) -> 4 | Y23: =SUM(I62:I65) -> 9 | Z23: =SUM(J62:J65) -> 4 | ... AF23: =SUM(P62:P65) -> 261
B24: 10.30 - 10.45 | C24: 15 | D24: 2 | E24: 4 | F24: 1 | G24: 0 | H24: 0 | I24: 1 | J24: 0 | K24: 0 | L24: 0 | M24: 51 | N24: 0 | O24: =SUM(C24:L24,N24) -> 23 | P24: =SUM(C24:N24) -> 74 | R24: 2100-2200 | S24: =SUM(C66:C69) -> 24 | T24: =SUM(D66:D69) -> 4 | U24: =SUM(E66:E69) -> 17 | V24: =SUM(F66:F69) -> 14 | W24: =SUM(G66:G69) -> 1 | X24: =SUM(H66:H69) -> 0 | Y24: =SUM(I66:I69) -> 3 | Z24: =SUM(J66:J69) -> 3 | ... AF24: =SUM(P66:P69) -> 152
B25: 10.45 - 11.00 | C25: 5 | D25: 2 | E25: 5 | F25: 0 | G25: 0 | H25: 0 | I25: 1 | J25: 0 | K25: 0 | L25: 0 | M25: 45 | N25: 0 | O25: =SUM(C25:L25,N25) -> 13 | P25: =SUM(C25:N25) -> 58 | R25: 2200-2300 | S25: =SUM(C70:C73) -> 2 | T25: =SUM(D70:D73) -> 1 | U25: =SUM(E70:E73) -> 5 | V25: =SUM(F70:F73) -> 6 | W25: =SUM(G70:G73) -> 0 | X25: =SUM(H70:H73) -> 0 | Y25: =SUM(I70:I73) -> 1 | Z25: =SUM(J70:J73) -> 2 | ... AF25: =SUM(P70:P73) -> 58
B26: 11.00 - 11.15 | C26: 15 | D26: 3 | E26: 5 | F26: 2 | G26: 0 | H26: 1 | I26: 5 | J26: 0 | K26: 0 | L26: 0 | M26: 30 | N26: 0 | O26: =SUM(C26:L26,N26) -> 31 | P26: =SUM(C26:N26) -> 61 | R26: 2300-0000 | S26: =SUM(C74:C77) -> 5 | T26: =SUM(D74:D77) -> 0 | U26: =SUM(E74:E77) -> 2 | V26: =SUM(F74:F77) -> 2 | W26: =SUM(G74:G77) -> 0 | X26: =SUM(H74:H77) -> 0 | Y26: =SUM(I74:I77) -> 1 | Z26: =SUM(J74:J77) -> 0 | ... AF26: =SUM(P74:P77) -> 32
B27: 11.15 - 11.30 | C27: 5 | D27: 2 | E27: 3 | F27: 0 | G27: 0 | H27: 0 | I27: 2 | J27: 0 | K27: 0 | L27: 0 | M27: 37 | N27: 0 | O27: =SUM(C27:L27,N27) -> 12 | P27: =SUM(C27:N27) -> 49 | R27: 0000-0100 | S27: =SUM(C78:C81) -> 0 | T27: =SUM(D78:D81) -> 0 | U27: =SUM(E78:E81) -> 4 | V27: =SUM(F78:F81) -> 0 | W27: =SUM(G78:G81) -> 0 | X27: =SUM(H78:H81) -> 0 | Y27: =SUM(I78:I81) -> 0 | Z27: =SUM(J78:J81) -> 0 | ... AF27: =SUM(P78:P81) -> 10
B28: 11.30 - 11.45 | C28: 3 | D28: 0 | E28: 0 | F28: 2 | G28: 0 | H28: 0 | I28: 2 | J28: 0 | K28: 0 | L28: 0 | M28: 22 | N28: 0 | O28: =SUM(C28:L28,N28) -> 7 | P28: =SUM(C28:N28) -> 29 | R28: 0100-0200 | S28: =SUM(C82:C85) -> 1 | T28: =SUM(D82:D85) -> 0 | U28: =SUM(E82:E85) -> 1 | V28: =SUM(F82:F85) -> 0 | W28: =SUM(G82:G85) -> 0 | X28: =SUM(H82:H85) -> 0 | Y28: =SUM(I82:I85) -> 1 | Z28: =SUM(J82:J85) -> 0 | ... AF28: =SUM(P82:P85) -> 12
B29: 11.45 - 12.00 | C29: 7 | D29: 0 | E29: 0 | F29: 3 | G29: 0 | H29: 0 | I29: 3 | J29: 1 | K29: 0 | L29: 0 | M29: 45 | N29: 0 | O29: =SUM(C29:L29,N29) -> 14 | P29: =SUM(C29:N29) -> 59 | R29: 0200-0300 | S29: =SUM(C86:C89) -> 0 | T29: =SUM(D86:D89) -> 0 | U29: =SUM(E86:E89) -> 1 | V29: =SUM(F86:F89) -> 2 | W29: =SUM(G86:G89) -> 0 | X29: =SUM(H86:H89) -> 0 | Y29: =SUM(I86:I89) -> 0 | Z29: =SUM(J86:J89) -> 0 | ... AF29: =SUM(P86:P89) -> 3
