Workbook

Sheet 17.10 MASAKA SEMBABULE
B1: Consultancy services for Preparation of Expressway Development Master Plan (EDMP) for Uganda
B2: MANUAL CLASSIFIED COUNT (MCC)
B3: ROAD NAME: | C3: ='17.10 SEMBABULE-MASAKA'!C3:G3 -> VIRA MARIA ROAD
C5: Date | D5: 17.10.2019 | F5: Location | G5: ='17.10 SEMBABULE-MASAKA'!G5:H5 -> KIWUULA TRADING CENTRE | J5: Surveyor | K5: ANTHONY
C6: Dir. From | D6: MASAKA | F6: Dir. To | G6: SEMBABULE | J6: Supervisor | K6: KIVUMBI
B8: Time / Veh Type | R8: SUMMARY TRAFFIC VOLUMES
C9: 1. Car | D9: 2. Station Wagon | E9: 3. Pickups | F9: 4. Minibus, matatu | G9: 5. Medium bus | H9: 6. Large Bus | I9: 7. Light Truck | J9: 8. Medium Truck | K9: 9. Heavy truck | L9: 10. Truck Trailer | M9: 11. Motor cycles | N9: 12. Tractors | O9: Total Excl M/Cycles | P9: Total All | R9: Time | S9: 1. Car | T9: 2. Station Wagon | U9: 3. Pickups | V9: 4. Minibus, matatu | W9: 5. Medium bus | X9: 6. Large Bus | Y9: 7. Light Truck | Z9: 8. Medium Truck | AA9: 9. Heavy truck | AB9: 10. Truck Trailer | AC9: 11. Motorcycles | AD9: 12. Tractors, Graders | AE9: Total Excl M/ Cycles | AF9: Total All
B10: 07.00 - 07.15 | C10: 1 | D10: 0 | E10: 0 | F10: 0 | G10: 1 | H10: 0 | I10: 0 | J10: 0 | K10: 0 | L10: 0 | M10: 7 | N10: 0 | O10: =SUM(C10:L10,N10) -> 2 | P10: =SUM(C10:N10) -> 9 | R10: 0700-0800 | S10: =SUM(C10:C13) -> 7 | T10: =SUM(D10:D13) -> 0 | U10: =SUM(E10:E13) -> 2 | V10: =SUM(F10:F13) -> 0 | W10: =SUM(G10:G13) -> 1 | X10: =SUM(H10:H13) -> 0 | Y10: =SUM(I10:I13) -> 2 | Z10: =SUM(J10:J13) -> 3 | ... AF10: =SUM(P10:P13) -> 43
B11: 07.15 - 07.30 | C11: 2 | D11: 0 | E11: 0 | F11: 0 | G11: 0 | H11: 0 | I11: 0 | J11: 1 | K11: 0 | L11: 0 | M11: 6 | N11: 0 | O11: =SUM(C11:L11,N11) -> 3 | P11: =SUM(C11:N11) -> 9 | R11: 0800-0900 | S11: =SUM(C14:C17) -> 6 | T11: =SUM(D14:D17) -> 3 | U11: =SUM(E14:E17) -> 5 | V11: =SUM(F14:F17) -> 2 | W11: =SUM(G14:G17) -> 0 | X11: =SUM(H14:H17) -> 0 | Y11: =SUM(I14:I17) -> 6 | Z11: =SUM(J14:J17) -> 2 | ... AF11: =SUM(P14:P17) -> 53
B12: 07.30 - 07.45 | C12: 1 | D12: 0 | E12: 1 | F12: 0 | G12: 0 | H12: 0 | I12: 1 | J12: 1 | K12: 0 | L12: 0 | M12: 6 | N12: 0 | O12: =SUM(C12:L12,N12) -> 4 | P12: =SUM(C12:N12) -> 10 | R12: 0900-1000 | S12: =SUM(C18:C21) -> 5 | T12: =SUM(D18:D21) -> 0 | U12: =SUM(E18:E21) -> 1 | V12: =SUM(F18:F21) -> 4 | W12: =SUM(G18:G21) -> 0 | X12: =SUM(H18:H21) -> 0 | Y12: =SUM(I18:I21) -> 3 | Z12: =SUM(J18:J21) -> 4 | ... AF12: =SUM(P18:P21) -> 39
B13: 07.45 - 08.00 | C13: 3 | D13: 0 | E13: 1 | F13: 0 | G13: 0 | H13: 0 | I13: 1 | J13: 1 | K13: 1 | L13: 0 | M13: 8 | N13: 0 | O13: =SUM(C13:L13,N13) -> 7 | P13: =SUM(C13:N13) -> 15 | R13: 1000-1100 | S13: =SUM(C22:C25) -> 9 | T13: =SUM(D22:D25) -> 2 | U13: =SUM(E22:E25) -> 4 | V13: =SUM(F22:F25) -> 1 | W13: =SUM(G22:G25) -> 0 | X13: =SUM(H22:H25) -> 0 | Y13: =SUM(I22:I25) -> 4 | Z13: =SUM(J22:J25) -> 0 | ... AF13: =SUM(P22:P25) -> 44
B14: 08.00 - 08.15 | C14: 4 | D14: 0 | E14: 2 | F14: 0 | G14: 0 | H14: 0 | I14: 1 | J14: 0 | K14: 0 | L14: 0 | M14: 8 | N14: 0 | O14: =SUM(C14:L14,N14) -> 7 | P14: =SUM(C14:N14) -> 15 | R14: 1100-1200 | S14: =SUM(C26:C29) -> 8 | T14: =SUM(D26:D29) -> 2 | U14: =SUM(E26:E29) -> 3 | V14: =SUM(F26:F29) -> 1 | W14: =SUM(G26:G29) -> 0 | X14: =SUM(H26:H29) -> 0 | Y14: =SUM(I26:I29) -> 4 | Z14: =SUM(J26:J29) -> 2 | ... AF14: =SUM(P26:P29) -> 54
B15: 08.15 - 08.30 | C15: 1 | D15: 1 | E15: 0 | F15: 0 | G15: 0 | H15: 0 | I15: 4 | J15: 0 | K15: 0 | L15: 0 | M15: 6 | N15: 0 | O15: =SUM(C15:L15,N15) -> 6 | P15: =SUM(C15:N15) -> 12 | R15: 1200-1300 | S15: =SUM(C30:C33) -> 7 | T15: =SUM(D30:D33) -> 1 | U15: =SUM(E30:E33) -> 10 | V15: =SUM(F30:F33) -> 2 | W15: =SUM(G30:G33) -> 0 | X15: =SUM(H30:H33) -> 0 | Y15: =SUM(I30:I33) -> 1 | Z15: =SUM(J30:J33) -> 0 | ... AF15: =SUM(P30:P33) -> 55
B16: 08.30 - 08.45 | C16: 0 | D16: 1 | E16: 0 | F16: 1 | G16: 0 | H16: 0 | I16: 0 | J16: 1 | K16: 0 | L16: 0 | M16: 9 | N16: 0 | O16: =SUM(C16:L16,N16) -> 3 | P16: =SUM(C16:N16) -> 12 | R16: 1300-1400 | S16: =SUM(C34:C37) -> 7 | T16: =SUM(D34:D37) -> 0 | U16: =SUM(E34:E37) -> 4 | V16: =SUM(F34:F37) -> 4 | W16: =SUM(G34:G37) -> 0 | X16: =SUM(H34:H37) -> 0 | Y16: =SUM(I34:I37) -> 4 | Z16: =SUM(J34:J37) -> 2 | ... AF16: =SUM(P34:P37) -> 52
B17: 08.45 - 9.00 | C17: 1 | D17: 1 | E17: 3 | F17: 1 | G17: 0 | H17: 0 | I17: 1 | J17: 1 | K17: 1 | L17: 0 | M17: 5 | N17: 0 | O17: =SUM(C17:L17,N17) -> 9 | P17: =SUM(C17:N17) -> 14 | R17: 1400-1500 | S17: =SUM(C38:C41) -> 8 | T17: =SUM(D38:D41) -> 0 | U17: =SUM(E38:E41) -> 5 | V17: =SUM(F38:F41) -> 3 | W17: =SUM(G38:G41) -> 0 | X17: =SUM(H38:H41) -> 0 | Y17: =SUM(I38:I41) -> 2 | Z17: =SUM(J38:J41) -> 1 | ... AF17: =SUM(P38:P41) -> 57
B18: 09.00 - 09.15 | C18: 1 | D18: 0 | E18: 0 | F18: 1 | G18: 0 | H18: 0 | I18: 0 | J18: 0 | K18: 1 | L18: 0 | M18: 6 | N18: 0 | O18: =SUM(C18:L18,N18) -> 3 | P18: =SUM(C18:N18) -> 9 | R18: 1500-1600 | S18: =SUM(C42:C45) -> 11 | T18: =SUM(D42:D45) -> 0 | U18: =SUM(E42:E45) -> 2 | V18: =SUM(F42:F45) -> 8 | W18: =SUM(G42:G45) -> 0 | X18: =SUM(H42:H45) -> 0 | Y18: =SUM(I42:I45) -> 1 | Z18: =SUM(J42:J45) -> 4 | ... AF18: =SUM(P42:P45) -> 58
B19: 09.15 - 09.30 | C19: 0 | D19: 0 | E19: 1 | F19: 1 | G19: 0 | H19: 0 | I19: 3 | J19: 1 | K19: 0 | L19: 0 | M19: 2 | N19: 0 | O19: =SUM(C19:L19,N19) -> 6 | P19: =SUM(C19:N19) -> 8 | R19: 1600-1700 | S19: =SUM(C46:C49) -> 5 | T19: =SUM(D46:D49) -> 2 | U19: =SUM(E46:E49) -> 5 | V19: =SUM(F46:F49) -> 4 | W19: =SUM(G46:G49) -> 0 | X19: =SUM(H46:H49) -> 0 | Y19: =SUM(I46:I49) -> 7 | Z19: =SUM(J46:J49) -> 2 | ... AF19: =SUM(P46:P49) -> 59
B20: 09.30 - 09.45 | C20: 2 | D20: 0 | E20: 0 | F20: 2 | G20: 0 | H20: 0 | I20: 0 | J20: 1 | K20: 0 | L20: 0 | M20: 3 | N20: 0 | O20: =SUM(C20:L20,N20) -> 5 | P20: =SUM(C20:N20) -> 8 | R20: 1700-1800 | S20: =SUM(C50:C53) -> 6 | T20: =SUM(D50:D53) -> 2 | U20: =SUM(E50:E53) -> 3 | V20: =SUM(F50:F53) -> 4 | W20: =SUM(G50:G53) -> 1 | X20: =SUM(H50:H53) -> 0 | Y20: =SUM(I50:I53) -> 4 | Z20: =SUM(J50:J53) -> 3 | ... AF20: =SUM(P50:P53) -> 56
B21: 09.45 - 10.00 | C21: 2 | D21: 0 | E21: 0 | F21: 0 | G21: 0 | H21: 0 | I21: 0 | J21: 2 | K21: 0 | L21: 0 | M21: 10 | N21: 0 | O21: =SUM(C21:L21,N21) -> 4 | P21: =SUM(C21:N21) -> 14 | R21: 1800-1900 | S21: =SUM(C54:C57) -> 6 | T21: =SUM(D54:D57) -> 0 | U21: =SUM(E54:E57) -> 3 | V21: =SUM(F54:F57) -> 6 | W21: =SUM(G54:G57) -> 1 | X21: =SUM(H54:H57) -> 0 | Y21: =SUM(I54:I57) -> 5 | Z21: =SUM(J54:J57) -> 6 | ... AF21: =SUM(P54:P57) -> 68
B22: 10.00 - 10.15 | C22: 5 | D22: 0 | E22: 1 | F22: 1 | G22: 0 | H22: 0 | I22: 2 | J22: 0 | K22: 1 | L22: 0 | M22: 3 | N22: 0 | O22: =SUM(C22:L22,N22) -> 10 | P22: =SUM(C22:N22) -> 13 | R22: AM Peak Hr | S22: =MAX(S10:S12) -> 7 | T22: =MAX(T10:T12) -> 3 | U22: =MAX(U10:U12) -> 5 | V22: =MAX(V10:V12) -> 4 | W22: =MAX(W10:W12) -> 1 | X22: =MAX(X10:X12) -> 0 | Y22: =MAX(Y10:Y12) -> 6 | Z22: =MAX(Z10:Z12) -> 4 | ... AF22: =MAX(AF10:AF12) -> 53
B23: 10.15 - 10.30 | C23: 2 | D23: 1 | E23: 2 | F23: 0 | G23: 0 | H23: 0 | I23: 2 | J23: 0 | K23: 0 | L23: 0 | M23: 8 | N23: 0 | O23: =SUM(C23:L23,N23) -> 7 | P23: =SUM(C23:N23) -> 15 | R23: IP Peak Hr | S23: =MAX(S13:S18) -> 11 | T23: =MAX(T13:T18) -> 2 | U23: =MAX(U13:U18) -> 10 | V23: =MAX(V13:V18) -> 8 | W23: =MAX(W13:W18) -> 0 | X23: =MAX(X13:X18) -> 0 | Y23: =MAX(Y13:Y18) -> 4 | Z23: =MAX(Z13:Z18) -> 4 | ... AF23: =MAX(AF13:AF18) -> 58
B24: 10.30 - 10.45 | C24: 1 | D24: 1 | E24: 0 | F24: 0 | G24: 0 | H24: 0 | I24: 0 | J24: 0 | K24: 0 | L24: 0 | M24: 7 | N24: 0 | O24: =SUM(C24:L24,N24) -> 2 | P24: =SUM(C24:N24) -> 9 | R24: PM Peak Hr | S24: =MAX(S19:S21) -> 6 | T24: =MAX(T19:T21) -> 2 | U24: =MAX(U19:U21) -> 5 | V24: =MAX(V19:V21) -> 6 | W24: =MAX(W19:W21) -> 1 | X24: =MAX(X19:X21) -> 0 | Y24: =MAX(Y19:Y21) -> 7 | Z24: =MAX(Z19:Z21) -> 6 | ... AF24: =MAX(AF19:AF21) -> 68
B25: 10.45 - 11.00 | C25: 1 | D25: 0 | E25: 1 | F25: 0 | G25: 0 | H25: 0 | I25: 0 | J25: 0 | K25: 0 | L25: 0 | M25: 5 | N25: 0 | O25: =SUM(C25:L25,N25) -> 2 | P25: =SUM(C25:N25) -> 7 | R25: AM Period | S25: =SUM(S10:S12) -> 18 | T25: =SUM(T10:T12) -> 3 | U25: =SUM(U10:U12) -> 8 | V25: =SUM(V10:V12) -> 6 | W25: =SUM(W10:W12) -> 1 | X25: =SUM(X10:X12) -> 0 | Y25: =SUM(Y10:Y12) -> 11 | Z25: =SUM(Z10:Z12) -> 9 | ... AF25: =SUM(AF10:AF12) -> 135
B26: 11.00 - 11.15 | C26: 2 | D26: 0 | E26: 1 | F26: 0 | G26: 0 | H26: 0 | I26: 1 | J26: 0 | K26: 0 | L26: 0 | M26: 10 | N26: 0 | O26: =SUM(C26:L26,N26) -> 4 | P26: =SUM(C26:N26) -> 14 | R26: IP Period | S26: =SUM(S13:S18) -> 50 | T26: =SUM(T13:T18) -> 5 | U26: =SUM(U13:U18) -> 28 | V26: =SUM(V13:V18) -> 19 | W26: =SUM(W13:W18) -> 0 | X26: =SUM(X13:X18) -> 0 | Y26: =SUM(Y13:Y18) -> 16 | Z26: =SUM(Z13:Z18) -> 9 | ... AF26: =SUM(AF13:AF18) -> 320
B27: 11.15 - 11.30 | C27: 2 | D27: 1 | E27: 0 | F27: 1 | G27: 0 | H27: 0 | I27: 0 | J27: 2 | K27: 2 | L27: 0 | M27: 6 | N27: 0 | O27: =SUM(C27:L27,N27) -> 8 | P27: =SUM(C27:N27) -> 14 | R27: PM Period | S27: =SUM(S19:S21) -> 17 | T27: =SUM(T19:T21) -> 4 | U27: =SUM(U19:U21) -> 11 | V27: =SUM(V19:V21) -> 14 | W27: =SUM(W19:W21) -> 2 | X27: =SUM(X19:X21) -> 0 | Y27: =SUM(Y19:Y21) -> 16 | Z27: =SUM(Z19:Z21) -> 11 | ... AF27: =SUM(AF19:AF21) -> 183
B28: 11.30 - 11.45 | C28: 4 | D28: 0 | E28: 1 | F28: 0 | G28: 0 | H28: 0 | I28: 1 | J28: 0 | K28: 0 | L28: 0 | M28: 5 | N28: 0 | O28: =SUM(C28:L28,N28) -> 6 | P28: =SUM(C28:N28) -> 11 | R28: 12 Hours | S28: =SUM(S10:S21) -> 85 | T28: =SUM(T10:T21) -> 12 | U28: =SUM(U10:U21) -> 47 | V28: =SUM(V10:V21) -> 39 | W28: =SUM(W10:W21) -> 3 | X28: =SUM(X10:X21) -> 0 | Y28: =SUM(Y10:Y21) -> 43 | Z28: =SUM(Z10:Z21) -> 29 | ... AF28: =SUM(AF10:AF21) -> 638
B29: 11.45 - 12.00 | C29: 0 | D29: 1 | E29: 1 | F29: 0 | G29: 0 | H29: 0 | I29: 2 | J29: 0 | K29: 0 | L29: 0 | M29: 11 | N29: 0 | O29: =SUM(C29:L29,N29) -> 4 | P29: =SUM(C29:N29) -> 15
B30: 12.00 - 12.15 | C30: 2 | D30: 1 | E30: 3 | F30: 0 | G30: 0 | H30: 0 | I30: 0 | J30: 0 | K30: 2 | L30: 0 | M30: 7 | N30: 0 | O30: =SUM(C30:L30,N30) -> 8 | P30: =SUM(C30:N30) -> 15
B31: 12.15 - 12.30 | C31: 4 | D31: 0 | E31: 3 | F31: 1 | G31: 0 | H31: 0 | I31: 1 | J31: 0 | K31: 1 | L31: 0 | M31: 6 | N31: 0 | O31: =SUM(C31:L31,N31) -> 10 | P31: =SUM(C31:N31) -> 16
B32: 12.30 - 12.45 | C32: 1 | D32: 0 | E32: 2 | F32: 0 | G32: 0 | H32: 0 | I32: 0 | J32: 0 | K32: 1 | L32: 0 | M32: 9 | N32: 0 | O32: =SUM(C32:L32,N32) -> 4 | P32: =SUM(C32:N32) -> 13
B33: 12.45 - 13.00 | C33: 0 | D33: 0 | E33: 2 | F33: 1 | G33: 0 | H33: 0 | I33: 0 | J33: 0 | K33: 1 | L33: 0 | M33: 7 | N33: 0 | O33: =SUM(C33:L33,N33) -> 4 | P33: =SUM(C33:N33) -> 11
B34: 13.00 - 13.15 | C34: 2 | D34: 0 | E34: 1 | F34: 2 | G34: 0 | H34: 0 | I34: 0 | J34: 0 | K34: 0 | L34: 0 | M34: 12 | N34: 0 | O34: =SUM(C34:L34,N34) -> 5 | P34: =SUM(C34:N34) -> 17
B35: 13.15 - 13.30 | C35: 2 | D35: 0 | E35: 1 | F35: 0 | G35: 0 | H35: 0 | I35: 2 | J35: 0 | K35: 0 | L35: 0 | M35: 8 | N35: 0 | O35: =SUM(C35:L35,N35) -> 5 | P35: =SUM(C35:N35) -> 13
B36: 13.30 - 13.45 | C36: 1 | D36: 0 | E36: 0 | F36: 1 | G36: 0 | H36: 0 | I36: 0 | J36: 0 | K36: 0 | L36: 0 | M36: 4 | N36: 0 | O36: =SUM(C36:L36,N36) -> 2 | P36: =SUM(C36:N36) -> 6
B37: 13.45 - 14.00 | C37: 2 | D37: 0 | E37: 2 | F37: 1 | G37: 0 | H37: 0 | I37: 2 | J37: 2 | K37: 0 | L37: 0 | M37: 7 | N37: 0 | O37: =SUM(C37:L37,N37) -> 9 | P37: =SUM(C37:N37) -> 16
B38: 14.00 - 14.15 | C38: 2 | D38: 0 | E38: 4 | F38: 0 | G38: 0 | H38: 0 | I38: 0 | J38: 0 | K38: 0 | L38: 0 | M38: 6 | N38: 0 | O38: =SUM(C38:L38,N38) -> 6 | P38: =SUM(C38:N38) -> 12
B39: 14.15 - 14.30 | C39: 2 | D39: 0 | E39: 0 | F39: 0 | G39: 0 | H39: 0 | I39: 0 | J39: 1 | K39: 0 | L39: 0 | M39: 3 | N39: 0 | O39: =SUM(C39:L39,N39) -> 3 | P39: =SUM(C39:N39) -> 6
B40: 14.30 - 14.45 | C40: 3 | D40: 0 | E40: 0 | F40: 1 | G40: 0 | H40: 0 | I40: 0 | J40: 0 | K40: 0 | L40: 0 | M40: 11 | N40: 0 | O40: =SUM(C40:L40,N40) -> 4 | P40: =SUM(C40:N40) -> 15
... B57: 18.45 - 19.00 | C57: 4 | D57: 0 | E57: 0 | F57: 1 | G57: 0 | H57: 0 | I57: 0 | J57: 2 | K57: 1 | L57: 0 | M57: 7 | N57: 0 | O57: =SUM(C57:L57,N57) -> 8 | P57: =SUM(C57:N57) -> 15
B58: Totals | C58: =SUM(C10:C57) -> 85 | D58: =SUM(D10:D57) -> 12 | E58: =SUM(E10:E57) -> 47 | F58: =SUM(F10:F57) -> 39 | G58: =SUM(G10:G57) -> 3 | H58: =SUM(H10:H57) -> 0 | I58: =SUM(I10:I57) -> 43 | J58: =SUM(J10:J57) -> 29 | ... P58: =SUM(P10:P57) -> 638
...

Sheet 17.10 SEMBABULE-MASAKA
B1: Consultancy services for Preparation of Expressway Development Master Plan (EDMP) for Uganda
B2: MANUAL CLASSIFIED COUNT (MCC)
B3: ROAD NAME: | C3: VIRA MARIA ROAD
C5: Date | D5: 17.10.2019 | F5: Location | G5: KIWUULA TRADING CENTRE | J5: Surveyor | K5: KIVUMBI GEORGE
C6: Dir. From | D6: SEMBABULE | F6: Dir. To | G6: MASAKA | J6: Supervisor | K6: GEORGE
B8: Time / Veh Type | R8: SUMMARY TRAFFIC VOLUMES
C9: 1. Car | D9: 2. Station Wagon | E9: 3. Pickups | F9: 4. Minibus, matatu | G9: 5. Medium bus | H9: 6. Large Bus | I9: 7. Light Truck | J9: 8. Medium Truck | K9: 9. Heavy truck | L9: 10. Truck Trailer | M9: 11. Motor cycles | N9: 12. Tractors | O9: Total Excl M/Cycles | P9: Total All | R9: Time | S9: 1. Car | T9: 2. Station Wagon | U9: 3. Pickups | V9: 4. Minibus, matatu | W9: 5. Medium bus | X9: 6. Large Bus | Y9: 7. Light Truck | Z9: 8. Medium Truck | AA9: 9. Heavy truck | AB9: 10. Truck Trailer | AC9: 11. Motorcycles | AD9: 12. Tractors, Graders | AE9: Total Excl M/ Cycles | AF9: Total All
B10: 07.00 - 07.15 | C10: 2 | D10: 0 | E10: 0 | F10: 1 | G10: 0 | H10: 0 | I10: 0 | J10: 0 | K10: 0 | L10: 0 | M10: 2 | N10: 0 | O10: 2 | P10: =SUM(C10:N10) -> 5 | R10: 0700-0800 | S10: =SUM(C10:C13) -> 8 | T10: =SUM(D10:D13) -> 0 | U10: =SUM(E10:E13) -> 2 | V10: =SUM(F10:F13) -> 1 | W10: =SUM(G10:G13) -> 0 | X10: =SUM(H10:H13) -> 0 | Y10: =SUM(I10:I13) -> 3 | Z10: =SUM(J10:J13) -> 0 | ... AF10: =SUM(P10:P13) -> 38
B11: 07.15 - 07.30 | C11: 1 | D11: 0 | E11: 0 | F11: 0 | G11: 0 | H11: 0 | I11: 0 | J11: 0 | K11: 0 | L11: 0 | M11: 9 | N11: 0 | O11: =SUM(C11:L11,N11) -> 1 | P11: =SUM(C11:N11) -> 10 | R11: 0800-0900 | S11: =SUM(C14:C17) -> 6 | T11: =SUM(D14:D17) -> 0 | U11: =SUM(E14:E17) -> 7 | V11: =SUM(F14:F17) -> 9 | W11: =SUM(G14:G17) -> 0 | X11: =SUM(H14:H17) -> 0 | Y11: =SUM(I14:I17) -> 6 | Z11: =SUM(J14:J17) -> 2 | ... AF11: =SUM(P14:P17) -> 52
B12: 07.30 - 07.45 | C12: 2 | D12: 0 | E12: 0 | F12: 0 | G12: 0 | H12: 0 | I12: 1 | J12: 0 | K12: 2 | L12: 0 | M12: 3 | N12: 0 | O12: =SUM(C12:L12,N12) -> 5 | P12: =SUM(C12:N12) -> 8 | R12: 0900-1000 | S12: =SUM(C18:C21) -> 13 | T12: =SUM(D18:D21) -> 1 | U12: =SUM(E18:E21) -> 2 | V12: =SUM(F18:F21) -> 5 | W12: =SUM(G18:G21) -> 0 | X12: =SUM(H18:H21) -> 0 | Y12: =SUM(I18:I21) -> 4 | Z12: =SUM(J18:J21) -> 0 | ... AF12: =SUM(P18:P21) -> 46
B13: 07.45 - 08.00 | C13: 3 | D13: 0 | E13: 2 | F13: 0 | G13: 0 | H13: 0 | I13: 2 | J13: 0 | K13: 1 | L13: 0 | M13: 7 | N13: 0 | O13: =SUM(C13:L13,N13) -> 8 | P13: =SUM(C13:N13) -> 15 | R13: 1000-1100 | S13: =SUM(C22:C25) -> 10 | T13: =SUM(D22:D25) -> 0 | U13: =SUM(E22:E25) -> 3 | V13: =SUM(F22:F25) -> 2 | W13: =SUM(G22:G25) -> 0 | X13: =SUM(H22:H25) -> 0 | Y13: =SUM(I22:I25) -> 2 | Z13: =SUM(J22:J25) -> 2 | ... AF13: =SUM(P22:P25) -> 54
B14: 08.00 - 08.15 | C14: 1 | D14: 0 | E14: 1 | F14: 1 | G14: 0 | H14: 0 | I14: 2 | J14: 0 | K14: 0 | L14: 0 | M14: 4 | N14: 0 | O14: =SUM(C14:L14,N14) -> 5 | P14: =SUM(C14:N14) -> 9 | R14: 1100-1200 | S14: =SUM(C26:C29) -> 10 | T14: =SUM(D26:D29) -> 3 | U14: =SUM(E26:E29) -> 1 | V14: =SUM(F26:F29) -> 2 | W14: =SUM(G26:G29) -> 0 | X14: =SUM(H26:H29) -> 0 | Y14: =SUM(I26:I29) -> 4 | Z14: =SUM(J26:J29) -> 2 | ... AF14: =SUM(P26:P29) -> 49
B15: 08.15 - 08.30 | C15: 3 | D15: 0 | E15: 0 | F15: 2 | G15: 0 | H15: 0 | I15: 3 | J15: 1 | K15: 1 | L15: 0 | M15: 7 | N15: 1 | O15: =SUM(C15:L15,N15) -> 11 | P15: =SUM(C15:N15) -> 18 | R15: 1200-1300 | S15: =SUM(C30:C33) -> 8 | T15: =SUM(D30:D33) -> 2 | U15: =SUM(E30:E33) -> 3 | V15: =SUM(F30:F33) -> 0 | W15: =SUM(G30:G33) -> 0 | X15: =SUM(H30:H33) -> 0 | Y15: =SUM(I30:I33) -> 1 | Z15: =SUM(J30:J33) -> 5 | ... AF15: =SUM(P30:P33) -> 45
B16: 08.30 - 08.45 | C16: 0 | D16: 0 | E16: 6 | F16: 4 | G16: 0 | H16: 0 | I16: 1 | J16: 1 | K16: 0 | L16: 0 | M16: 4 | N16: 0 | O16: =SUM(C16:L16,N16) -> 12 | P16: =SUM(C16:N16) -> 16 | R16: 1300-1400 | S16: =SUM(C34:C37) -> 8 | T16: =SUM(D34:D37) -> 2 | U16: =SUM(E34:E37) -> 4 | V16: =SUM(F34:F37) -> 1 | W16: =SUM(G34:G37) -> 0 | X16: =SUM(H34:H37) -> 0 | Y16: =SUM(I34:I37) -> 6 | Z16: =SUM(J34:J37) -> 2 | ... AF16: =SUM(P34:P37) -> 60
B17: 08.45 - 9.00 | C17: 2 | D17: 0 | E17: 0 | F17: 2 | G17: 0 | H17: 0 | I17: 0 | J17: 0 | K17: 0 | L17: 0 | M17: 5 | N17: 0 | O17: =SUM(C17:L17,N17) -> 4 | P17: =SUM(C17:N17) -> 9 | R17: 1400-1500 | S17: =SUM(C38:C41) -> 7 | T17: =SUM(D38:D41) -> 4 | U17: =SUM(E38:E41) -> 3 | V17: =SUM(F38:F41) -> 1 | W17: =SUM(G38:G41) -> 0 | X17: =SUM(H38:H41) -> 0 | Y17: =SUM(I38:I41) -> 2 | Z17: =SUM(J38:J41) -> 9 | ... AF17: =SUM(P38:P41) -> 61
B18: 09.00 - 09.15 | C18: 1 | D18: 0 | E18: 0 | F18: 2 | G18: 0 | H18: 0 | I18: 0 | J18: 0 | K18: 0 | L18: 0 | M18: 4 | N18: 0 | O18: =SUM(C18:L18,N18) -> 3 | P18: =SUM(C18:N18) -> 7 | R18: 1500-1600 | S18: =SUM(C42:C45) -> 9 | T18: =SUM(D42:D45) -> 2 | U18: =SUM(E42:E45) -> 4 | V18: =SUM(F42:F45) -> 3 | W18: =SUM(G42:G45) -> 0 | X18: =SUM(H42:H45) -> 0 | Y18: =SUM(I42:I45) -> 4 | Z18: =SUM(J42:J45) -> 1 | ... AF18: =SUM(P42:P45) -> 55
B19: 09.15 - 09.30 | C19: 4 | D19: 1 | E19: 1 | F19: 1 | G19: 0 | H19: 0 | I19: 2 | J19: 0 | K19: 0 | L19: 0 | M19: 1 | N19: 0 | O19: =SUM(C19:L19,N19) -> 9 | P19: =SUM(C19:N19) -> 10 | R19: 1600-1700 | S19: =SUM(C46:C49) -> 7 | T19: =SUM(D46:D49) -> 2 | U19: =SUM(E46:E49) -> 1 | V19: =SUM(F46:F49) -> 3 | W19: =SUM(G46:G49) -> 0 | X19: =SUM(H46:H49) -> 0 | Y19: =SUM(I46:I49) -> 2 | Z19: =SUM(J46:J49) -> 4 | ... AF19: =SUM(P46:P49) -> 57
B20: 09.30 - 09.45 | C20: 4 | D20: 0 | E20: 0 | F20: 2 | G20: 0 | H20: 0 | I20: 1 | J20: 0 | K20: 1 | L20: 0 | M20: 5 | N20: 0 | O20: =SUM(C20:L20,N20) -> 8 | P20: =SUM(C20:N20) -> 13 | R20: 1700-1800 | S20: =SUM(C50:C53) -> 16 | T20: =SUM(D50:D53) -> 0 | U20: =SUM(E50:E53) -> 8 | V20: =SUM(F50:F53) -> 1 | W20: =SUM(G50:G53) -> 1 | X20: =SUM(H50:H53) -> 0 | Y20: =SUM(I50:I53) -> 2 | Z20: =SUM(J50:J53) -> 8 | ... AF20: =SUM(P50:P53) -> 65
B21: 09.45 - 10.00 | C21: 4 | D21: 0 | E21: 1 | F21: 0 | G21: 0 | H21: 0 | I21: 1 | J21: 0 | K21: 2 | L21: 0 | M21: 8 | N21: 0 | O21: =SUM(C21:L21,N21) -> 8 | P21: =SUM(C21:N21) -> 16 | R21: 1800-1900 | S21: =SUM(C54:C57) -> 12 | T21: =SUM(D54:D57) -> 3 | U21: =SUM(E54:E57) -> 7 | V21: =SUM(F54:F57) -> 1 | W21: =SUM(G54:G57) -> 0 | X21: =SUM(H54:H57) -> 0 | Y21: =SUM(I54:I57) -> 3 | Z21: =SUM(J54:J57) -> 6 | ... AF21: =SUM(P54:P57) -> 76
B22: 10.00 - 10.15 | C22: 4 | D22: 0 | E22: 1 | F22: 0 | G22: 0 | H22: 0 | I22: 0 | J22: 0 | K22: 1 | L22: 0 | M22: 5 | N22: 0 | O22: =SUM(C22:L22,N22) -> 6 | P22: =SUM(C22:N22) -> 11 | R22: AM Peak Hr | S22: =MAX(S10:S12) -> 13 | T22: =MAX(T10:T12) -> 1 | U22: =MAX(U10:U12) -> 7 | V22: =MAX(V10:V12) -> 9 | W22: =MAX(W10:W12) -> 0 | X22: =MAX(X10:X12) -> 0 | Y22: =MAX(Y10:Y12) -> 6 | Z22: =MAX(Z10:Z12) -> 2 | ... AF22: =MAX(AF10:AF12) -> 52
B23: 10.15 - 10.30 | C23: 2 | D23: 0 | E23: 0 | F23: 1 | G23: 0 | H23: 0 | I23: 2 | J23: 1 | K23: 0 | L23: 0 | M23: 4 | N23: 0 | O23: =SUM(C23:L23,N23) -> 6 | P23: =SUM(C23:N23) -> 10 | R23: IP Peak Hr | S23: =MAX(S13:S18) -> 10 | T23: =MAX(T13:T18) -> 4 | U23: =MAX(U13:U18) -> 4 | V23: =MAX(V13:V18) -> 3 | W23: =MAX(W13:W18) -> 0 | X23: =MAX(X13:X18) -> 0 | Y23: =MAX(Y13:Y18) -> 6 | Z23: =MAX(Z13:Z18) -> 9 | ... AF23: =MAX(AF13:AF18) -> 61
B24: 10.30 - 10.45 | C24: 2 | D24: 0 | E24: 1 | F24: 0 | G24: 0 | H24: 0 | I24: 0 | J24: 1 | K24: 2 | L24: 0 | M24: 10 | N24: 0 | O24: =SUM(C24:L24,N24) -> 6 | P24: =SUM(C24:N24) -> 16 | R24: PM Peak Hr | S24: =MAX(S19:S21) -> 16 | T24: =MAX(T19:T21) -> 3 | U24: =MAX(U19:U21) -> 8 | V24: =MAX(V19:V21) -> 3 | W24: =MAX(W19:W21) -> 1 | X24: =MAX(X19:X21) -> 0 | Y24: =MAX(Y19:Y21) -> 3 | Z24: =MAX(Z19:Z21) -> 8 | ... AF24: =MAX(AF19:AF21) -> 76
B25: 10.45 - 11.00 | C25: 2 | D25: 0 | E25: 1 | F25: 1 | G25: 0 | H25: 0 | I25: 0 | J25: 0 | K25: 1 | L25: 0 | M25: 12 | N25: 0 | O25: =SUM(C25:L25,N25) -> 5 | P25: =SUM(C25:N25) -> 17 | R25: AM Period | S25: =SUM(S10:S12) -> 27 | T25: =SUM(T10:T12) -> 1 | U25: =SUM(U10:U12) -> 11 | V25: =SUM(V10:V12) -> 15 | W25: =SUM(W10:W12) -> 0 | X25: =SUM(X10:X12) -> 0 | Y25: =SUM(Y10:Y12) -> 13 | Z25: =SUM(Z10:Z12) -> 2 | ... AF25: =SUM(AF10:AF12) -> 136
B26: 11.00 - 11.15 | C26: 2 | D26: 3 | E26: 0 | F26: 2 | G26: 0 | H26: 0 | I26: 0 | J26: 0 | K26: 0 | L26: 0 | M26: 9 | N26: 0 | O26: =SUM(C26:L26,N26) -> 7 | P26: =SUM(C26:N26) -> 16 | R26: IP Period | S26: =SUM(S13:S18) -> 52 | T26: =SUM(T13:T18) -> 13 | U26: =SUM(U13:U18) -> 18 | V26: =SUM(V13:V18) -> 9 | W26: =SUM(W13:W18) -> 0 | X26: =SUM(X13:X18) -> 0 | Y26: =SUM(Y13:Y18) -> 19 | Z26: =SUM(Z13:Z18) -> 21 | ... AF26: =SUM(AF13:AF18) -> 324
B27: 11.15 - 11.30 | C27: 0 | D27: 0 | E27: 0 | F27: 0 | G27: 0 | H27: 0 | I27: 0 | J27: 2 | K27: 0 | L27: 0 | M27: 4 | N27: 0 | O27: =SUM(C27:L27,N27) -> 2 | P27: =SUM(C27:N27) -> 6 | R27: PM Period | S27: =SUM(S19:S21) -> 35 | T27: =SUM(T19:T21) -> 5 | U27: =SUM(U19:U21) -> 16 | V27: =SUM(V19:V21) -> 5 | W27: =SUM(W19:W21) -> 1 | X27: =SUM(X19:X21) -> 0 | Y27: =SUM(Y19:Y21) -> 7 | Z27: =SUM(Z19:Z21) -> 18 | ... AF27: =SUM(AF19:AF21) -> 198
B28: 11.30 - 11.45 | C28: 3 | D28: 0 | E28: 0 | F28: 0 | G28: 0 | H28: 0 | I28: 2 | J28: 0 | K28: 0 | L28: 0 | M28: 6 | N28: 0 | O28: =SUM(C28:L28,N28) -> 5 | P28: =SUM(C28:N28) -> 11 | R28: 12 Hours | S28: =SUM(S10:S21) -> 114 | T28: =SUM(T10:T21) -> 19 | U28: =SUM(U10:U21) -> 45 | V28: =SUM(V10:V21) -> 29 | W28: =SUM(W10:W21) -> 1 | X28: =SUM(X10:X21) -> 0 | Y28: =SUM(Y10:Y21) -> 39 | Z28: =SUM(Z10:Z21) -> 41 | ... AF28: =SUM(AF10:AF21) -> 658
B29: 11.45 - 12.00 | C29: 5 | D29: 0 | E29: 1 | F29: 0 | G29: 0 | H29: 0 | I29: 2 | J29: 0 | K29: 0 | L29: 0 | M29: 8 | N29: 0 | O29: =SUM(C29:L29,N29) -> 8 | P29: =SUM(C29:N29) -> 16
B30: 12.00 - 12.15 | C30: 3 | D30: 0 | E30: 1 | F30: 0 | G30: 0 | H30: 0 | I30: 0 | J30: 1 | K30: 0 | L30: 0 | M30: 2 | N30: 0 | O30: =SUM(C30:L30,N30) -> 5 | P30: =SUM(C30:N30) -> 7
B31: 12.15 - 12.30 | C31: 2 | D31: 1 | E31: 1 | F31: 0 | G31: 0 | H31: 0 | I31: 0 | J31: 0 | K31: 1 | L31: 0 | M31: 4 | N31: 0 | O31: =SUM(C31:L31,N31) -> 5 | P31: =SUM(C31:N31) -> 9
B32: 12.30 - 12.45 | C32: 0 | D32: 0 | E32: 1 | F32: 0 | G32: 0 | H32: 0 | I32: 1 | J32: 0 | K32: 1 | L32: 0 | M32: 11 | N32: 0 | O32: =SUM(C32:L32,N32) -> 3 | P32: =SUM(C32:N32) -> 14
B33: 12.45 - 13.00 | C33: 3 | D33: 1 | E33: 0 | F33: 0 | G33: 0 | H33: 0 | I33: 0 | J33: 4 | K33: 0 | L33: 0 | M33: 7 | N33: 0 | O33: =SUM(C33:L33,N33) -> 8 | P33: =SUM(C33:N33) -> 15
B34: 13.00 - 13.15 | C34: 2 | D34: 2 | E34: 2 | F34: 1 | G34: 0 | H34: 0 | I34: 2 | J34: 0 | K34: 0 | L34: 0 | M34: 10 | N34: 0 | O34: =SUM(C34:L34,N34) -> 9 | P34: =SUM(C34:N34) -> 19
B35: 13.15 - 13.30 | C35: 1 | D35: 0 | E35: 0 | F35: 0 | G35: 0 | H35: 0 | I35: 0 | J35: 0 | K35: 0 | L35: 0 | M35: 12 | N35: 0 | O35: =SUM(C35:L35,N35) -> 1 | P35: =SUM(C35:N35) -> 13
B36: 13.30 - 13.45 | C36: 2 | D36: 0 | E36: 0 | F36: 0 | G36: 0 | H36: 0 | I36: 0 | J36: 2 | K36: 0 | L36: 0 | M36: 7 | N36: 0 | O36: =SUM(C36:L36,N36) -> 4 | P36: =SUM(C36:N36) -> 11
B37: 13.45 - 14.00 | C37: 3 | D37: 0 | E37: 2 | F37: 0 | G37: 0 | H37: 0 | I37: 4 | J37: 0 | K37: 1 | L37: 0 | M37: 7 | N37: 0 | O37: =SUM(C37:L37,N37) -> 10 | P37: =SUM(C37:N37) -> 17
B38: 14.00 - 14.15 | C38: 4 | D38: 0 | E38: 1 | F38: 1 | G38: 0 | H38: 0 | I38: 0 | J38: 2 | K38: 0 | L38: 0 | M38: 5 | N38: 0 | O38: =SUM(C38:L38,N38) -> 8 | P38: =SUM(C38:N38) -> 13
B39: 14.15 - 14.30 | C39: 1 | D39: 2 | E39: 0 | F39: 0 | G39: 0 | H39: 0 | I39: 1 | J39: 0 | K39: 2 | L39: 0 | M39: 10 | N39: 0 | O39: =SUM(C39:L39,N39) -> 6 | P39: =SUM(C39:N39) -> 16
B40: 14.30 - 14.45 | C40: 1 | D40: 1 | E40: 1 | F40: 0 | G40: 0 | H40: 0 | I40: 0 | J40: 0 | K40: 0 | L40: 0 | M40: 8 | N40: 0 | O40: =SUM(C40:L40,N40) -> 3 | P40: =SUM(C40:N40) -> 11
... B57: 18.45 - 19.00 | C57: 4 | D57: 0 | E57: 1 | F57: 0 | G57: 0 | H57: 0 | I57: 0 | J57: 2 | K57: 0 | L57: 0 | M57: 8 | N57: 0 | O57: =SUM(C57:L57,N57) -> 7 | P57: =SUM(C57:N57) -> 15
B58: Totals | C58: =SUM(C10:C57) -> 114 | D58: =SUM(D10:D57) -> 19 | E58: =SUM(E10:E57) -> 45 | F58: =SUM(F10:F57) -> 29 | G58: =SUM(G10:G57) -> 1 | H58: =SUM(H10:H57) -> 0 | I58: =SUM(I10:I57) -> 39 | J58: =SUM(J10:J57) -> 41 | ... P58: =SUM(P10:P57) -> 658
...

Sheet 18.10 MASAKA-SEMBABULA-24HRS
B1: Consultancy services for Preparation of Expressway Development Master Plan (EDMP) for Uganda
B2: MANUAL CLASSIFIED COUNT (MCC)
B3: ROAD NAME: | C3: ='17.10 SEMBABULE-MASAKA'!C3:G3 -> VIRA MARIA ROAD
C5: Date | D5: 18.10.2019 | F5: Location | G5: ='19.10 SEMBABULE MASAKA-24HRS'!G5:H5 -> KIWUULA TC | J5: Surveyor | K5: NAGADDYA
C6: Dir. From | D6: MASAKA | F6: Dir. To | G6: SEMBABULA | J6: Supervisor | K6: KIVUMBI
B8: Time / Veh Type | R8: SUMMARY TRAFFIC VOLUMES
C9: 1. Car | D9: 2. Station Wagon | E9: 3. Pickups | F9: 4. Minibus, matatu | G9: 5. Medium bus | H9: 6. Large Bus | I9: 7. Light Truck | J9: 8. Medium Truck | K9: 9. Heavy truck | L9: 10. Truck Trailer | M9: 11. Motor cycles | N9: 12. Tractors | O9: Total Excl M/Cycles | P9: Total All | R9: Time | S9: 1. Car | T9: 2. Station Wagon | U9: 3. Pickups | V9: 4. Minibus, matatu | W9: 5. Medium bus | X9: 6. Large Bus | Y9: 7. Light Truck | Z9: 8. Medium Truck | AA9: 9. Heavy truck | AB9: 10. Truck Trailer | AC9: 11. Motorcycles | AD9: 12. Tractors, Graders | AE9: Total Excl M/ Cycles | AF9: Total All
B10: 07.00 - 07.15 | C10: 0 | D10: 0 | E10: 0 | F10: 0 | G10: 1 | H10: 0 | I10: 1 | J10: 0 | K10: 0 | L10: 0 | M10: 9 | N10: 0 | O10: =SUM(C10:L10,N10) -> 2 | P10: =SUM(C10:N10) -> 11 | R10: 0700-0800 | S10: =SUM(C10:C13) -> 2 | T10: =SUM(D10:D13) -> 2 | U10: =SUM(E10:E13) -> 0 | V10: =SUM(F10:F13) -> 1 | W10: =SUM(G10:G13) -> 1 | X10: =SUM(H10:H13) -> 0 | Y10: =SUM(I10:I13) -> 2 | Z10: =SUM(J10:J13) -> 0 | ... AF10: =SUM(P10:P13) -> 31
B11: 07.15 - 07.30 | C11: 1 | D11: 1 | E11: 0 | F11: 0 | G11: 0 | H11: 0 | I11: 0 | J11: 0 | K11: 1 | L11: 0 | M11: 6 | N11: 0 | O11: =SUM(C11:L11,N11) -> 3 | P11: =SUM(C11:N11) -> 9 | R11: 0800-0900 | S11: =SUM(C14:C17) -> 8 | T11: =SUM(D14:D17) -> 1 | U11: =SUM(E14:E17) -> 3 | V11: =SUM(F14:F17) -> 2 | W11: =SUM(G14:G17) -> 0 | X11: =SUM(H14:H17) -> 0 | Y11: =SUM(I14:I17) -> 3 | Z11: =SUM(J14:J17) -> 2 | ... AF11: =SUM(P14:P17) -> 53
B12: 07.30 - 07.45 | C12: 1 | D12: 0 | E12: 0 | F12: 0 | G12: 0 | H12: 0 | I12: 0 | J12: 0 | K12: 0 | L12: 0 | M12: 0 | N12: 0 | O12: =SUM(C12:L12,N12) -> 1 | P12: =SUM(C12:N12) -> 1 | R12: 0900-1000 | S12: =SUM(C18:C21) -> 9 | T12: =SUM(D18:D21) -> 3 | U12: =SUM(E18:E21) -> 2 | V12: =SUM(F18:F21) -> 2 | W12: =SUM(G18:G21) -> 0 | X12: =SUM(H18:H21) -> 0 | Y12: =SUM(I18:I21) -> 2 | Z12: =SUM(J18:J21) -> 1 | ... AF12: =SUM(P18:P21) -> 45
B13: 07.45 - 08.00 | C13: 0 | D13: 1 | E13: 0 | F13: 1 | G13: 0 | H13: 0 | I13: 1 | J13: 0 | K13: 0 | L13: 0 | M13: 7 | N13: 0 | O13: =SUM(C13:L13,N13) -> 3 | P13: =SUM(C13:N13) -> 10 | R13: 1000-1100 | S13: =SUM(C22:C25) -> 9 | T13: =SUM(D22:D25) -> 1 | U13: =SUM(E22:E25) -> 1 | V13: =SUM(F22:F25) -> 1 | W13: =SUM(G22:G25) -> 0 | X13: =SUM(H22:H25) -> 0 | Y13: =SUM(I22:I25) -> 3 | Z13: =SUM(J22:J25) -> 6 | ... AF13: =SUM(P22:P25) -> 42
B14: 08.00 - 08.15 | C14: 3 | D14: 0 | E14: 2 | F14: 0 | G14: 0 | H14: 0 | I14: 1 | J14: 0 | K14: 0 | L14: 0 | M14: 7 | N14: 0 | O14: =SUM(C14:L14,N14) -> 6 | P14: =SUM(C14:N14) -> 13 | R14: 1100-1200 | S14: =SUM(C26:C29) -> 14 | T14: =SUM(D26:D29) -> 2 | U14: =SUM(E26:E29) -> 5 | V14: =SUM(F26:F29) -> 0 | W14: =SUM(G26:G29) -> 0 | X14: =SUM(H26:H29) -> 0 | Y14: =SUM(I26:I29) -> 6 | Z14: =SUM(J26:J29) -> 0 | ... AF14: =SUM(P26:P29) -> 67
B15: 08.15 - 08.30 | C15: 3 | D15: 1 | E15: 1 | F15: 1 | G15: 0 | H15: 0 | I15: 1 | J15: 1 | K15: 0 | L15: 0 | M15: 9 | N15: 0 | O15: =SUM(C15:L15,N15) -> 8 | P15: =SUM(C15:N15) -> 17 | R15: 1200-1300 | S15: =SUM(C30:C33) -> 12 | T15: =SUM(D30:D33) -> 4 | U15: =SUM(E30:E33) -> 7 | V15: =SUM(F30:F33) -> 1 | W15: =SUM(G30:G33) -> 0 | X15: =SUM(H30:H33) -> 0 | Y15: =SUM(I30:I33) -> 3 | Z15: =SUM(J30:J33) -> 4 | ... AF15: =SUM(P30:P33) -> 62
B16: 08.30 - 08.45 | C16: 0 | D16: 0 | E16: 0 | F16: 0 | G16: 0 | H16: 0 | I16: 0 | J16: 1 | K16: 0 | L16: 0 | M16: 9 | N16: 0 | O16: =SUM(C16:L16,N16) -> 1 | P16: =SUM(C16:N16) -> 10 | R16: 1300-1400 | S16: =SUM(C34:C37) -> 10 | T16: =SUM(D34:D37) -> 0 | U16: =SUM(E34:E37) -> 6 | V16: =SUM(F34:F37) -> 0 | W16: =SUM(G34:G37) -> 0 | X16: =SUM(H34:H37) -> 0 | Y16: =SUM(I34:I37) -> 5 | Z16: =SUM(J34:J37) -> 0 | ... AF16: =SUM(P34:P37) -> 50
B17: 08.45 - 9.00 | C17: 2 | D17: 0 | E17: 0 | F17: 1 | G17: 0 | H17: 0 | I17: 1 | J17: 0 | K17: 0 | L17: 0 | M17: 9 | N17: 0 | O17: =SUM(C17:L17,N17) -> 4 | P17: =SUM(C17:N17) -> 13 | R17: 1400-1500 | S17: =SUM(C38:C41) -> 13 | T17: =SUM(D38:D41) -> 0 | U17: =SUM(E38:E41) -> 2 | V17: =SUM(F38:F41) -> 5 | W17: =SUM(G38:G41) -> 0 | X17: =SUM(H38:H41) -> 0 | Y17: =SUM(I38:I41) -> 4 | Z17: =SUM(J38:J41) -> 0 | ... AF17: =SUM(P38:P41) -> 63
B18: 09.00 - 09.15 | C18: 1 | D18: 0 | E18: 0 | F18: 1 | G18: 0 | H18: 0 | I18: 0 | J18: 0 | K18: 0 | L18: 0 | M18: 4 | N18: 0 | O18: =SUM(C18:L18,N18) -> 2 | P18: =SUM(C18:N18) -> 6 | R18: 1500-1600 | S18: =SUM(C42:C45) -> 10 | T18: =SUM(D42:D45) -> 1 | U18: =SUM(E42:E45) -> 0 | V18: =SUM(F42:F45) -> 4 | W18: =SUM(G42:G45) -> 0 | X18: =SUM(H42:H45) -> 0 | Y18: =SUM(I42:I45) -> 6 | Z18: =SUM(J42:J45) -> 1 | ... AF18: =SUM(P42:P45) -> 59
B19: 09.15 - 09.30 | C19: 1 | D19: 1 | E19: 2 | F19: 0 | G19: 0 | H19: 0 | I19: 1 | J19: 0 | K19: 0 | L19: 0 | M19: 7 | N19: 0 | O19: =SUM(C19:L19,N19) -> 5 | P19: =SUM(C19:N19) -> 12 | R19: 1600-1700 | S19: =SUM(C46:C49) -> 10 | T19: =SUM(D46:D49) -> 4 | U19: =SUM(E46:E49) -> 1 | V19: =SUM(F46:F49) -> 7 | W19: =SUM(G46:G49) -> 0 | X19: =SUM(H46:H49) -> 0 | Y19: =SUM(I46:I49) -> 9 | Z19: =SUM(J46:J49) -> 3 | ... AF19: =SUM(P46:P49) -> 64
B20: 09.30 - 09.45 | C20: 5 | D20: 0 | E20: 0 | F20: 1 | G20: 0 | H20: 0 | I20: 0 | J20: 0 | K20: 0 | L20: 0 | M20: 8 | N20: 0 | O20: =SUM(C20:L20,N20) -> 6 | P20: =SUM(C20:N20) -> 14 | R20: 1700-1800 | S20: =SUM(C50:C53) -> 10 | T20: =SUM(D50:D53) -> 1 | U20: =SUM(E50:E53) -> 5 | V20: =SUM(F50:F53) -> 19 | W20: =SUM(G50:G53) -> 0 | X20: =SUM(H50:H53) -> 1 | Y20: =SUM(I50:I53) -> 6 | Z20: =SUM(J50:J53) -> 4 | ... AF20: =SUM(P50:P53) -> 67
B21: 09.45 - 10.00 | C21: 2 | D21: 2 | E21: 0 | F21: 0 | G21: 0 | H21: 0 | I21: 1 | J21: 1 | K21: 0 | L21: 0 | M21: 7 | N21: 0 | O21: =SUM(C21:L21,N21) -> 6 | P21: =SUM(C21:N21) -> 13 | R21: 1800-1900 | S21: =SUM(C54:C57) -> 5 | T21: =SUM(D54:D57) -> 0 | U21: =SUM(E54:E57) -> 3 | V21: =SUM(F54:F57) -> 2 | W21: =SUM(G54:G57) -> 0 | X21: =SUM(H54:H57) -> 1 | Y21: =SUM(I54:I57) -> 9 | Z21: =SUM(J54:J57) -> 5 | ... AF21: =SUM(P54:P57) -> 58
B22: 10.00 - 10.15 | C22: 1 | D22: 0 | E22: 0 | F22: 1 | G22: 0 | H22: 0 | I22: 1 | J22: 1 | K22: 0 | L22: 0 | M22: 6 | N22: 0 | O22: =SUM(C22:L22,N22) -> 4 | P22: =SUM(C22:N22) -> 10 | R22: 1900-2000 | S22: =SUM(C58:C61) -> 5 | T22: =SUM(D58:D61) -> 2 | U22: =SUM(E58:E61) -> 1 | V22: =SUM(F58:F61) -> 3 | W22: =SUM(G58:G61) -> 0 | X22: =SUM(H58:H61) -> 0 | Y22: =SUM(I58:I61) -> 4 | Z22: =SUM(J58:J61) -> 2 | ... AF22: =SUM(P58:P61) -> 52
B23: 10.15 - 10.30 | C23: 4 | D23: 1 | E23: 1 | F23: 0 | G23: 0 | H23: 0 | I23: 0 | J23: 3 | K23: 0 | L23: 0 | M23: 4 | N23: 0 | O23: =SUM(C23:L23,N23) -> 9 | P23: =SUM(C23:N23) -> 13 | R23: 2000-2100 | S23: =SUM(C62:C65) -> 14 | T23: =SUM(D62:D65) -> 1 | U23: =SUM(E62:E65) -> 4 | V23: =SUM(F62:F65) -> 1 | W23: =SUM(G62:G65) -> 0 | X23: =SUM(H62:H65) -> 1 | Y23: =SUM(I62:I65) -> 4 | Z23: =SUM(J62:J65) -> 0 | ... AF23: =SUM(P62:P65) -> 60
B24: 10.30 - 10.45 | C24: 3 | D24: 0 | E24: 0 | F24: 0 | G24: 0 | H24: 0 | I24: 2 | J24: 1 | K24: 0 | L24: 0 | M24: 6 | N24: 1 | O24: =SUM(C24:L24,N24) -> 7 | P24: =SUM(C24:N24) -> 13 | R24: 2100-2200 | S24: =SUM(C66:C69) -> 6 | T24: =SUM(D66:D69) -> 1 | U24: =SUM(E66:E69) -> 1 | V24: =SUM(F66:F69) -> 0 | W24: =SUM(G66:G69) -> 0 | X24: =SUM(H66:H69) -> 0 | Y24: =SUM(I66:I69) -> 0 | Z24: =SUM(J66:J69) -> 10 | ... AF24: =SUM(P66:P69) -> 31
B25: 10.45 - 11.00 | C25: 1 | D25: 0 | E25: 0 | F25: 0 | G25: 0 | H25: 0 | I25: 0 | J25: 1 | K25: 0 | L25: 0 | M25: 4 | N25: 0 | O25: =SUM(C25:L25,N25) -> 2 | P25: =SUM(C25:N25) -> 6 | R25: 2200-2300 | S25: =SUM(C70:C73) -> 2 | T25: =SUM(D70:D73) -> 0 | U25: =SUM(E70:E73) -> 2 | V25: =SUM(F70:F73) -> 2 | W25: =SUM(G70:G73) -> 0 | X25: =SUM(H70:H73) -> 0 | Y25: =SUM(I70:I73) -> 1 | Z25: =SUM(J70:J73) -> 1 | ... AF25: =SUM(P70:P73) -> 19
B26: 11.00 - 11.15 | C26: 4 | D26: 0 | E26: 3 | F26: 0 | G26: 0 | H26: 0 | I26: 4 | J26: 0 | K26: 0 | L26: 0 | M26: 11 | N26: 0 | O26: =SUM(C26:L26,N26) -> 11 | P26: =SUM(C26:N26) -> 22 | R26: 2300-0000 | S26: =SUM(C74:C77) -> 10 | T26: =SUM(D74:D77) -> 0 | U26: =SUM(E74:E77) -> 0 | V26: =SUM(F74:F77) -> 3 | W26: =SUM(G74:G77) -> 0 | X26: =SUM(H74:H77) -> 0 | Y26: =SUM(I74:I77) -> 0 | Z26: =SUM(J74:J77) -> 1 | ... AF26: =SUM(P74:P77) -> 21
B27: 11.15 - 11.30 | C27: 3 | D27: 0 | E27: 0 | F27: 0 | G27: 0 | H27: 0 | I27: 1 | J27: 0 | K27: 0 | L27: 0 | M27: 11 | N27: 0 | O27: =SUM(C27:L27,N27) -> 4 | P27: =SUM(C27:N27) -> 15 | R27: 0000-0100 | S27: =SUM(C78:C81) -> 4 | T27: =SUM(D78:D81) -> 1 | U27: =SUM(E78:E81) -> 0 | V27: =SUM(F78:F81) -> 0 | W27: =SUM(G78:G81) -> 0 | X27: =SUM(H78:H81) -> 0 | Y27: =SUM(I78:I81) -> 2 | Z27: =SUM(J78:J81) -> 2 | ... AF27: =SUM(P78:P81) -> 15
B28: 11.30 - 11.45 | C28: 6 | D28: 0 | E28: 2 | F28: 0 | G28: 0 | H28: 0 | I28: 1 | J28: 0 | K28: 0 | L28: 0 | M28: 11 | N28: 0 | O28: =SUM(C28:L28,N28) -> 9 | P28: =SUM(C28:N28) -> 20 | R28: 0100-0200 | S28: =SUM(C82:C85) -> 1 | T28: =SUM(D82:D85) -> 0 | U28: =SUM(E82:E85) -> 0 | V28: =SUM(F82:F85) -> 0 | W28: =SUM(G82:G85) -> 1 | X28: =SUM(H82:H85) -> 0 | Y28: =SUM(I82:I85) -> 1 | Z28: =SUM(J82:J85) -> 1 | ... AF28: =SUM(P82:P85) -> 9
B29: 11.45 - 12.00 | C29: 1 | D29: 2 | E29: 0 | F29: 0 | G29: 0 | H29: 0 | I29: 0 | J29: 0 | K29: 0 | L29: 0 | M29: 7 | N29: 0 | O29: =SUM(C29:L29,N29) -> 3 | P29: =SUM(C29:N29) -> 10 | R29: 0200-0300 | S29: =SUM(C86:C89) -> 1 | T29: =SUM(D86:D89) -> 1 | U29: =SUM(E86:E89) -> 1 | V29: =SUM(F86:F89) -> 0 | W29: =SUM(G86:G89) -> 0 | X29: =SUM(H86:H89) -> 0 | Y29: =SUM(I86:I89) -> 2 | Z29: =SUM(J86:J89) -> 1 | ... AF29: =SUM(P86:P89) -> 6
B30: 12.00 - 12.15 | C30: 1 | D30: 0 | E30: 2 | F30: 0 | G30: 0 | H30: 0 | I30: 3 | J30: 1 | K30: 1 | L30: 0 | M30: 9 | N30: 0 | O30: =SUM(C30:L30,N30) -> 8 | P30: =SUM(C30:N30) -> 17 | R30: 0300-0400 | S30: =SUM(C90:C93) -> 2 | T30: =SUM(D90:D93) -> 1 | U30: =SUM(E90:E93) -> 1 | V30: =SUM(F90:F93) -> 0 | W30: =SUM(G90:G93) -> 0 | X30: =SUM(H90:H93) -> 0 | Y30: =SUM(I90:I93) -> 0 | Z30: =SUM(J90:J93) -> 3 | ... AF30: =SUM(P90:P93) -> 9
B31: 12.15 - 12.30 | C31: 3 | D31: 0 | E31: 2 | F31: 0 | G31: 0 | H31: 0 | I31: 0 | J31: 1 | K31: 0 | L31: 0 | M31: 8 | N31: 0 | O31: =SUM(C31:L31,N31) -> 6 | P31: =SUM(C31:N31) -> 14 | R31: 0400-0500 | S31: =SUM(C94:C97) -> 9 | T31: =SUM(D94:D97) -> 3 | U31: =SUM(E94:E97) -> 1 | V31: =SUM(F94:F97) -> 5 | W31: =SUM(G94:G97) -> 0 | X31: =SUM(H94:H97) -> 0 | Y31: =SUM(I94:I97) -> 4 | Z31: =SUM(J94:J97) -> 4 | ... AF31: =SUM(P94:P97) -> 41
B32: 12.30 - 12.45 | C32: 4 | D32: 1 | E32: 2 | F32: 0 | G32: 0 | H32: 0 | I32: 0 | J32: 1 | K32: 0 | L32: 0 | M32: 6 | N32: 0 | O32: =SUM(C32:L32,N32) -> 8 | P32: =SUM(C32:N32) -> 14 | R32: 0500-0600 | S32: =SUM(C98:C101) -> 3 | T32: =SUM(D98:D101) -> 2 | U32: =SUM(E98:E101) -> 1 | V32: =SUM(F98:F101) -> 2 | W32: =SUM(G98:G101) -> 0 | X32: =SUM(H98:H101) -> 0 | Y32: =SUM(I98:I101) -> 3 | Z32: =SUM(J98:J101) -> 0 | ... AF32: =SUM(P98:P101) -> 21
B33: 12.45 - 13.00 | C33: 4 | D33: 3 | E33: 1 | F33: 1 | G33: 0 | H33: 0 | I33: 0 | J33: 1 | K33: 0 | L33: 0 | M33: 7 | N33: 0 | O33: =SUM(C33:L33,N33) -> 10 | P33: =SUM(C33:N33) -> 17 | R33: 0600-0700 | S33: =SUM(C102:C105) -> 3 | T33: =SUM(D102:D105) -> 2 | U33: =SUM(E102:E105) -> 1 | V33: =SUM(F102:F105) -> 1 | W33: =SUM(G102:G105) -> 0 | X33: =SUM(H102:H105) -> 0 | Y33: =SUM(I102:I105) -> 1 | Z33: =SUM(J102:J105) -> 2 | ... AF33: =SUM(P102:P105) -> 21
B34: 13.00 - 13.15 | C34: 2 | D34: 0 | E34: 3 | F34: 0 | G34: 0 | H34: 0 | I34: 0 | J34: 0 | K34: 0 | L34: 0 | M34: 11 | N34: 0 | O34: =SUM(C34:L34,N34) -> 5 | P34: =SUM(C34:N34) -> 16 | R34: AM Peak Hr | S34: =MAX(S10:S12) -> 9 | T34: =MAX(T10:T12) -> 3 | U34: =MAX(U10:U12) -> 3 | V34: =MAX(V10:V12) -> 2 | W34: =MAX(W10:W12) -> 1 | X34: =MAX(X10:X12) -> 0 | Y34: =MAX(Y10:Y12) -> 3 | Z34: =MAX(Z10:Z12) -> 2 | ... AF34: =MAX(AF10:AF12) -> 53
B35: 13.15 - 13.30 | C35: 3 | D35: 0 | E35: 1 | F35: 0 | G35: 0 | H35: 0 | I35: 1 | J35: 0 | K35: 0 | L35: 0 | M35: 1 | N35: 0 | O35: =SUM(C35:L35,N35) -> 5 | P35: =SUM(C35:N35) -> 6 | R35: IP Peak Hr | S35: =MAX(S13:S18) -> 14 | T35: =MAX(T13:T18) -> 4 | U35: =MAX(U13:U18) -> 7 | V35: =MAX(V13:V18) -> 5 | W35: =MAX(W13:W18) -> 0 | X35: =MAX(X13:X18) -> 0 | Y35: =MAX(Y13:Y18) -> 6 | Z35: =MAX(Z13:Z18) -> 6 | ... AF35: =MAX(AF13:AF18) -> 67
B36: 13.30 - 13.45 | C36: 1 | D36: 0 | E36: 2 | F36: 0 | G36: 0 | H36: 0 | I36: 2 | J36: 0 | K36: 1 | L36: 0 | M36: 5 | N36: 0 | O36: =SUM(C36:L36,N36) -> 6 | P36: =SUM(C36:N36) -> 11 | R36: PM Peak Hr | S36: =MAX(S19:S21) -> 10 | T36: =MAX(T19:T21) -> 4 | U36: =MAX(U19:U21) -> 5 | V36: =MAX(V19:V21) -> 19 | W36: =MAX(W19:W21) -> 0 | X36: =MAX(X19:X21) -> 1 | Y36: =MAX(Y19:Y21) -> 9 | Z36: =MAX(Z19:Z21) -> 5 | ... AF36: =MAX(AF19:AF21) -> 67
B37: 13.45 - 14.00 | C37: 4 | D37: 0 | E37: 0 | F37: 0 | G37: 0 | H37: 0 | I37: 2 | J37: 0 | K37: 0 | L37: 0 | M37: 11 | N37: 0 | O37: =SUM(C37:L37,N37) -> 6 | P37: =SUM(C37:N37) -> 17 | R37: AM Period | S37: =SUM(S10:S12) -> 19 | T37: =SUM(T10:T12) -> 6 | U37: =SUM(U10:U12) -> 5 | V37: =SUM(V10:V12) -> 5 | W37: =SUM(W10:W12) -> 1 | X37: =SUM(X10:X12) -> 0 | Y37: =SUM(Y10:Y12) -> 7 | Z37: =SUM(Z10:Z12) -> 3 | ... AF37: =SUM(AF10:AF12) -> 129
B38: 14.00 - 14.15 | C38: 2 | D38: 0 | E38: 2 | F38: 1 | G38: 0 | H38: 0 | I38: 2 | J38: 0 | K38: 0 | L38: 0 | M38: 13 | N38: 0 | O38: =SUM(C38:L38,N38) -> 7 | P38: =SUM(C38:N38) -> 20 | R38: IP Period | S38: =SUM(S13:S18) -> 68 | T38: =SUM(T13:T18) -> 8 | U38: =SUM(U13:U18) -> 21 | V38: =SUM(V13:V18) -> 11 | W38: =SUM(W13:W18) -> 0 | X38: =SUM(X13:X18) -> 0 | Y38: =SUM(Y13:Y18) -> 27 | Z38: =SUM(Z13:Z18) -> 11 | ... AF38: =SUM(AF13:AF18) -> 343
B39: 14.15 - 14.30 | C39: 4 | D39: 0 | E39: 0 | F39: 0 | G39: 0 | H39: 0 | I39: 0 | J39: 0 | K39: 0 | L39: 0 | M39: 7 | N39: 0 | O39: =SUM(C39:L39,N39) -> 4 | P39: =SUM(C39:N39) -> 11 | R39: PM Period | S39: =SUM(S19:S21) -> 25 | T39: =SUM(T19:T21) -> 5 | U39: =SUM(U19:U21) -> 9 | V39: =SUM(V19:V21) -> 28 | W39: =SUM(W19:W21) -> 0 | X39: =SUM(X19:X21) -> 2 | Y39: =SUM(Y19:Y21) -> 24 | Z39: =SUM(Z19:Z21) -> 12 | ... AF39: =SUM(AF19:AF21) -> 189
B40: 14.30 - 14.45 | C40: 5 | D40: 0 | E40: 0 | F40: 2 | G40: 0 | H40: 0 | I40: 2 | J40: 0 | K40: 0 | L40: 0 | M40: 13 | N40: 0 | O40: =SUM(C40:L40,N40) -> 9 | P40: =SUM(C40:N40) -> 22 | R40: 12 Hours | S40: =SUM(S10:S21) -> 112 | T40: =SUM(T10:T21) -> 19 | U40: =SUM(U10:U21) -> 35 | V40: =SUM(V10:V21) -> 44 | W40: =SUM(W10:W21) -> 1 | X40: =SUM(X10:X21) -> 2 | Y40: =SUM(Y10:Y21) -> 58 | Z40: =SUM(Z10:Z21) -> 26 | ... AF40: =SUM(AF10:AF21) -> 661
B41: 14.45 - 15.00 | C41: 2 | D41: 0 | E41: 0 | F41: 2 | G41: 0 | H41: 0 | I41: 0 | J41: 0 | K41: 0 | L41: 0 | M41: 6 | N41: 0 | O41: =SUM(C41:L41,N41) -> 4 | P41: =SUM(C41:N41) -> 10 | R41: 24 Hrs/ADT | S41: =SUM(S10:S33) -> 172 | T41: =SUM(T10:T33) -> 33 | U41: =SUM(U10:U33) -> 48 | V41: =SUM(V10:V33) -> 61 | W41: =SUM(W10:W33) -> 2 | X41: =SUM(X10:X33) -> 3 | Y41: =SUM(Y10:Y33) -> 80 | Z41: =SUM(Z10:Z33) -> 53 | ... AF41: =SUM(AF10:AF33) -> 966
B42: 15.00 - 15.15 | C42: 4 | D42: 1 | E42: 0 | F42: 0 | G42: 0 | H42: 0 | I42: 4 | J42: 1 | K42: 0 | L42: 0 | M42: 6 | N42: 0 | O42: =SUM(C42:L42,N42) -> 10 | P42: =SUM(C42:N42) -> 16 | R42: NEF | S42: =S41/S40 -> 1.5357143 | T42: =T41/T40 -> 1.7368421 | U42: =U41/U40 -> 1.3714286 | V42: =V41/V40 -> 1.3863636 | W42: =W41/W40 -> 2 | X42: =X41/X40 -> 1.5 | Y42: =Y41/Y40 -> 1.3793103 | Z42: =Z41/Z40 -> 2.0384615 | ... AF42: =AF41/AF40 -> 1.4614221
...

Sheet 18.10 SEMBABULE-MASAKA-24 HRS
B1: Consultancy services for Preparation of Expressway Development Master Plan (EDMP) for Uganda
B2: MANUAL CLASSIFIED COUNT (MCC)
B3: ROAD NAME: | C3: ='17.10 SEMBABULE-MASAKA'!C3:G3 -> VIRA MARIA ROAD
C5: Date | D5: 18.10.2019 | F5: Location | G5: ='22.10 SEMBABULE-MASAKA'!G5:H5 -> KIWUULA TRADING CENTRE | J5: Surveyor | K5: SSEBSLIME IVAN
C6: Dir. From | D6: ='17.10 SEMBABULE-MASAKA'!D6:E6 -> SEMBABULE | F6: Dir. To | G6: ='17.10 SEMBABULE-MASAKA'!G6:H6 -> MASAKA | J6: Supervisor | K6: ='22.10 SEMBABULE-MASAKA'!K6:L6 -> GEORGE
B8: Time / Veh Type | R8: SUMMARY TRAFFIC VOLUMES
C9: 1. Car | D9: 2. Station Wagon | E9: 3. Pickups | F9: 4. Minibus, matatu | G9: 5. Medium bus | H9: 6. Large Bus | I9: 7. Light Truck | J9: 8. Medium Truck | K9: 9. Heavy truck | L9: 10. Truck Trailer | M9: 11. Motor cycles | N9: 12. Tractors | O9: Total Excl M/Cycles | P9: Total All | R9: Time | S9: 1. Car | T9: 2. Station Wagon | U9: 3. Pickups | V9: 4. Minibus, matatu | W9: 5. Medium bus | X9: 6. Large Bus | Y9: 7. Light Truck | Z9: 8. Medium Truck | AA9: 9. Heavy truck | AB9: 10. Truck Trailer | AC9: 11. Motorcycles | AD9: 12. Tractors, Graders | AE9: Total Excl M/ Cycles | AF9: Total All
B10: 07.00 - 07.15 | C10: 2 | D10: 0 | E10: 0 | F10: 3 | G10: 0 | H10: 0 | I10: 0 | J10: 0 | K10: 0 | L10: 0 | M10: 10 | N10: 0 | O10: =SUM(C10:L10,N10) -> 5 | P10: =SUM(C10:N10) -> 15 | R10: 0700-0800 | S10: =SUM(C10:C13) -> 5 | T10: =SUM(D10:D13) -> 0 | U10: =SUM(E10:E13) -> 1 | V10: =SUM(F10:F13) -> 3 | W10: =SUM(G10:G13) -> 0 | X10: =SUM(H10:H13) -> 0 | Y10: =SUM(I10:I13) -> 5 | Z10: =SUM(J10:J13) -> 0 | ... AF10: =SUM(P10:P13) -> 30
B11: 07.15 - 07.30 | C11: 0 | D11: 0 | E11: 0 | F11: 0 | G11: 0 | H11: 0 | I11: 2 | J11: 0 | K11: 0 | L11: 0 | M11: 0 | N11: 0 | O11: =SUM(C11:L11,N11) -> 2 | P11: =SUM(C11:N11) -> 2 | R11: 0800-0900 | S11: =SUM(C14:C17) -> 8 | T11: =SUM(D14:D17) -> 2 | U11: =SUM(E14:E17) -> 3 | V11: =SUM(F14:F17) -> 8 | W11: =SUM(G14:G17) -> 0 | X11: =SUM(H14:H17) -> 0 | Y11: =SUM(I14:I17) -> 6 | Z11: =SUM(J14:J17) -> 3 | ... AF11: =SUM(P14:P17) -> 57
B12: 07.30 - 07.45 | C12: 1 | D12: 0 | E12: 0 | F12: 0 | G12: 0 | H12: 0 | I12: 2 | J12: 0 | K12: 1 | L12: 0 | M12: 3 | N12: 0 | O12: =SUM(C12:L12,N12) -> 4 | P12: =SUM(C12:N12) -> 7 | R12: 0900-1000 | S12: =SUM(C18:C21) -> 12 | T12: =SUM(D18:D21) -> 3 | U12: =SUM(E18:E21) -> 1 | V12: =SUM(F18:F21) -> 5 | W12: =SUM(G18:G21) -> 0 | X12: =SUM(H18:H21) -> 0 | Y12: =SUM(I18:I21) -> 2 | Z12: =SUM(J18:J21) -> 2 | ... AF12: =SUM(P18:P21) -> 43
B13: 07.45 - 08.00 | C13: 2 | D13: 0 | E13: 1 | F13: 0 | G13: 0 | H13: 0 | I13: 1 | J13: 0 | K13: 0 | L13: 0 | M13: 2 | N13: 0 | O13: =SUM(C13:L13,N13) -> 4 | P13: =SUM(C13:N13) -> 6 | R13: 1000-1100 | S13: =SUM(C22:C25) -> 11 | T13: =SUM(D22:D25) -> 2 | U13: =SUM(E22:E25) -> 3 | V13: =SUM(F22:F25) -> 1 | W13: =SUM(G22:G25) -> 0 | X13: =SUM(H22:H25) -> 0 | Y13: =SUM(I22:I25) -> 5 | Z13: =SUM(J22:J25) -> 1 | ... AF13: =SUM(P22:P25) -> 42
B14: 08.00 - 08.15 | C14: 2 | D14: 1 | E14: 0 | F14: 2 | G14: 0 | H14: 0 | I14: 3 | J14: 0 | K14: 2 | L14: 0 | M14: 7 | N14: 0 | O14: =SUM(C14:L14,N14) -> 10 | P14: =SUM(C14:N14) -> 17 | R14: 1100-1200 | S14: =SUM(C26:C29) -> 11 | T14: =SUM(D26:D29) -> 1 | U14: =SUM(E26:E29) -> 4 | V14: =SUM(F26:F29) -> 0 | W14: =SUM(G26:G29) -> 0 | X14: =SUM(H26:H29) -> 0 | Y14: =SUM(I26:I29) -> 2 | Z14: =SUM(J26:J29) -> 2 | ... AF14: =SUM(P26:P29) -> 53
B15: 08.15 - 08.30 | C15: 1 | D15: 0 | E15: 2 | F15: 2 | G15: 0 | H15: 0 | I15: 1 | J15: 2 | K15: 1 | L15: 0 | M15: 5 | N15: 0 | O15: =SUM(C15:L15,N15) -> 9 | P15: =SUM(C15:N15) -> 14 | R15: 1200-1300 | S15: =SUM(C30:C33) -> 15 | T15: =SUM(D30:D33) -> 0 | U15: =SUM(E30:E33) -> 3 | V15: =SUM(F30:F33) -> 0 | W15: =SUM(G30:G33) -> 0 | X15: =SUM(H30:H33) -> 0 | Y15: =SUM(I30:I33) -> 2 | Z15: =SUM(J30:J33) -> 2 | ... AF15: =SUM(P30:P33) -> 42
B16: 08.30 - 08.45 | C16: 1 | D16: 0 | E16: 1 | F16: 2 | G16: 0 | H16: 0 | I16: 1 | J16: 0 | K16: 0 | L16: 0 | M16: 5 | N16: 0 | O16: =SUM(C16:L16,N16) -> 5 | P16: =SUM(C16:N16) -> 10 | R16: 1300-1400 | S16: =SUM(C34:C37) -> 5 | T16: =SUM(D34:D37) -> 2 | U16: =SUM(E34:E37) -> 3 | V16: =SUM(F34:F37) -> 1 | W16: =SUM(G34:G37) -> 0 | X16: =SUM(H34:H37) -> 0 | Y16: =SUM(I34:I37) -> 2 | Z16: =SUM(J34:J37) -> 0 | ... AF16: =SUM(P34:P37) -> 50
B17: 08.45 - 9.00 | C17: 4 | D17: 1 | E17: 0 | F17: 2 | G17: 0 | H17: 0 | I17: 1 | J17: 1 | K17: 2 | L17: 0 | M17: 5 | N17: 0 | O17: =SUM(C17:L17,N17) -> 11 | P17: =SUM(C17:N17) -> 16 | R17: 1400-1500 | S17: =SUM(C38:C41) -> 8 | T17: =SUM(D38:D41) -> 1 | U17: =SUM(E38:E41) -> 4 | V17: =SUM(F38:F41) -> 2 | W17: =SUM(G38:G41) -> 1 | X17: =SUM(H38:H41) -> 0 | Y17: =SUM(I38:I41) -> 5 | Z17: =SUM(J38:J41) -> 2 | ... AF17: =SUM(P38:P41) -> 47
B18: 09.00 - 09.15 | C18: 4 | D18: 1 | E18: 0 | F18: 1 | G18: 0 | H18: 0 | I18: 0 | J18: 1 | K18: 0 | L18: 0 | M18: 6 | N18: 0 | O18: =SUM(C18:L18,N18) -> 7 | P18: =SUM(C18:N18) -> 13 | R18: 1500-1600 | S18: =SUM(C42:C45) -> 15 | T18: =SUM(D42:D45) -> 1 | U18: =SUM(E42:E45) -> 5 | V18: =SUM(F42:F45) -> 1 | W18: =SUM(G42:G45) -> 0 | X18: =SUM(H42:H45) -> 0 | Y18: =SUM(I42:I45) -> 7 | Z18: =SUM(J42:J45) -> 3 | ... AF18: =SUM(P42:P45) -> 62
B19: 09.15 - 09.30 | C19: 1 | D19: 1 | E19: 1 | F19: 2 | G19: 0 | H19: 0 | I19: 1 | J19: 1 | K19: 0 | L19: 0 | M19: 1 | N19: 0 | O19: =SUM(C19:L19,N19) -> 7 | P19: =SUM(C19:N19) -> 8 | R19: 1600-1700 | S19: =SUM(C46:C49) -> 5 | T19: =SUM(D46:D49) -> 2 | U19: =SUM(E46:E49) -> 6 | V19: =SUM(F46:F49) -> 2 | W19: =SUM(G46:G49) -> 2 | X19: =SUM(H46:H49) -> 0 | Y19: =SUM(I46:I49) -> 8 | Z19: =SUM(J46:J49) -> 3 | ... AF19: =SUM(P46:P49) -> 60
B20: 09.30 - 09.45 | C20: 1 | D20: 1 | E20: 0 | F20: 1 | G20: 0 | H20: 0 | I20: 0 | J20: 0 | K20: 0 | L20: 0 | M20: 6 | N20: 0 | O20: =SUM(C20:L20,N20) -> 3 | P20: =SUM(C20:N20) -> 9 | R20: 1700-1800 | S20: =SUM(C50:C53) -> 18 | T20: =SUM(D50:D53) -> 2 | U20: =SUM(E50:E53) -> 3 | V20: =SUM(F50:F53) -> 2 | W20: =SUM(G50:G53) -> 0 | X20: =SUM(H50:H53) -> 0 | Y20: =SUM(I50:I53) -> 7 | Z20: =SUM(J50:J53) -> 1 | ... AF20: =SUM(P50:P53) -> 73
B21: 09.45 - 10.00 | C21: 6 | D21: 0 | E21: 0 | F21: 1 | G21: 0 | H21: 0 | I21: 1 | J21: 0 | K21: 0 | L21: 0 | M21: 5 | N21: 0 | O21: =SUM(C21:L21,N21) -> 8 | P21: =SUM(C21:N21) -> 13 | R21: 1800-1900 | S21: =SUM(C54:C57) -> 11 | T21: =SUM(D54:D57) -> 2 | U21: =SUM(E54:E57) -> 2 | V21: =SUM(F54:F57) -> 2 | W21: =SUM(G54:G57) -> 0 | X21: =SUM(H54:H57) -> 0 | Y21: =SUM(I54:I57) -> 4 | Z21: =SUM(J54:J57) -> 5 | ... AF21: =SUM(P54:P57) -> 75
B22: 10.00 - 10.15 | C22: 3 | D22: 0 | E22: 1 | F22: 1 | G22: 0 | H22: 0 | I22: 1 | J22: 1 | K22: 0 | L22: 0 | M22: 2 | N22: 0 | O22: =SUM(C22:L22,N22) -> 7 | P22: =SUM(C22:N22) -> 9 | R22: 1900-2000 | S22: =SUM(C58:C61) -> 11 | T22: =SUM(D58:D61) -> 1 | U22: =SUM(E58:E61) -> 2 | V22: =SUM(F58:F61) -> 4 | W22: =SUM(G58:G61) -> 1 | X22: =SUM(H58:H61) -> 0 | Y22: =SUM(I58:I61) -> 4 | Z22: =SUM(J58:J61) -> 1 | ... AF22: =SUM(P58:P61) -> 58
B23: 10.15 - 10.30 | C23: 2 | D23: 1 | E23: 0 | F23: 0 | G23: 0 | H23: 0 | I23: 1 | J23: 0 | K23: 0 | L23: 0 | M23: 4 | N23: 0 | O23: =SUM(C23:L23,N23) -> 4 | P23: =SUM(C23:N23) -> 8 | R23: 2000-2100 | S23: =SUM(C62:C65) -> 3 | T23: =SUM(D62:D65) -> 1 | U23: =SUM(E62:E65) -> 0 | V23: =SUM(F62:F65) -> 1 | W23: =SUM(G62:G65) -> 0 | X23: =SUM(H62:H65) -> 0 | Y23: =SUM(I62:I65) -> 3 | Z23: =SUM(J62:J65) -> 3 | ... AF23: =SUM(P62:P65) -> 41
B24: 10.30 - 10.45 | C24: 2 | D24: 1 | E24: 1 | F24: 0 | G24: 0 | H24: 0 | I24: 1 | J24: 0 | K24: 1 | L24: 0 | M24: 6 | N24: 0 | O24: =SUM(C24:L24,N24) -> 6 | P24: =SUM(C24:N24) -> 12 | R24: 2100-2200 | S24: =SUM(C66:C69) -> 8 | T24: =SUM(D66:D69) -> 1 | U24: =SUM(E66:E69) -> 1 | V24: =SUM(F66:F69) -> 0 | W24: =SUM(G66:G69) -> 0 | X24: =SUM(H66:H69) -> 0 | Y24: =SUM(I66:I69) -> 4 | Z24: =SUM(J66:J69) -> 2 | ... AF24: =SUM(P66:P69) -> 32
B25: 10.45 - 11.00 | C25: 4 | D25: 0 | E25: 1 | F25: 0 | G25: 0 | H25: 0 | I25: 2 | J25: 0 | K25: 0 | L25: 0 | M25: 6 | N25: 0 | O25: =SUM(C25:L25,N25) -> 7 | P25: =SUM(C25:N25) -> 13 | R25: 2200-2300 | S25: =SUM(C70:C73) -> 8 | T25: =SUM(D70:D73) -> 1 | U25: =SUM(E70:E73) -> 0 | V25: =SUM(F70:F73) -> 0 | W25: =SUM(G70:G73) -> 0 | X25: =SUM(H70:H73) -> 0 | Y25: =SUM(I70:I73) -> 0 | Z25: =SUM(J70:J73) -> 1 | ... AF25: =SUM(P70:P73) -> 24
B26: 11.00 - 11.15 | C26: 3 | D26: 0 | E26: 1 | F26: 0 | G26: 0 | H26: 0 | I26: 0 | J26: 0 | K26: 1 | L26: 0 | M26: 12 | N26: 0 | O26: =SUM(C26:L26,N26) -> 5 | P26: =SUM(C26:N26) -> 17 | R26: 2300-0000 | S26: =SUM(C74:C77) -> 2 | T26: =SUM(D74:D77) -> 2 | U26: =SUM(E74:E77) -> 0 | V26: =SUM(F74:F77) -> 1 | W26: =SUM(G74:G77) -> 0 | X26: =SUM(H74:H77) -> 0 | Y26: =SUM(I74:I77) -> 1 | Z26: =SUM(J74:J77) -> 3 | ... AF26: =SUM(P74:P77) -> 15
B27: 11.15 - 11.30 | C27: 4 | D27: 0 | E27: 1 | F27: 0 | G27: 0 | H27: 0 | I27: 2 | J27: 1 | K27: 0 | L27: 0 | M27: 11 | N27: 0 | O27: =SUM(C27:L27,N27) -> 8 | P27: =SUM(C27:N27) -> 19 | R27: 0000-0100 | S27: =SUM(C78:C81) -> 3 | T27: =SUM(D78:D81) -> 2 | U27: =SUM(E78:E81) -> 1 | V27: =SUM(F78:F81) -> 1 | W27: =SUM(G78:G81) -> 0 | X27: =SUM(H78:H81) -> 0 | Y27: =SUM(I78:I81) -> 1 | Z27: =SUM(J78:J81) -> 2 | ... AF27: =SUM(P78:P81) -> 15
B28: 11.30 - 11.45 | C28: 1 | D28: 0 | E28: 0 | F28: 0 | G28: 0 | H28: 0 | I28: 0 | J28: 0 | K28: 0 | L28: 0 | M28: 7 | N28: 0 | O28: =SUM(C28:L28,N28) -> 1 | P28: =SUM(C28:N28) -> 8 | R28: 0100-0200 | S28: =SUM(C82:C85) -> 1 | T28: =SUM(D82:D85) -> 0 | U28: =SUM(E82:E85) -> 0 | V28: =SUM(F82:F85) -> 0 | W28: =SUM(G82:G85) -> 0 | X28: =SUM(H82:H85) -> 0 | Y28: =SUM(I82:I85) -> 0 | Z28: =SUM(J82:J85) -> 1 | ... AF28: =SUM(P82:P85) -> 3
B29: 11.45 - 12.00 | C29: 3 | D29: 1 | E29: 2 | F29: 0 | G29: 0 | H29: 0 | I29: 0 | J29: 1 | K29: 0 | L29: 0 | M29: 2 | N29: 0 | O29: =SUM(C29:L29,N29) -> 7 | P29: =SUM(C29:N29) -> 9 | R29: 0200-0300 | S29: =SUM(C86:C89) -> 1 | T29: =SUM(D86:D89) -> 0 | U29: =SUM(E86:E89) -> 1 | V29: =SUM(F86:F89) -> 2 | W29: =SUM(G86:G89) -> 0 | X29: =SUM(H86:H89) -> 0 | Y29: =SUM(I86:I89) -> 2 | Z29: =SUM(J86:J89) -> 1 | ... AF29: =SUM(P86:P89) -> 7
B30: 12.00 - 12.15 | C30: 3 | D30: 0 | E30: 1 | F30: 0 | G30: 0 | H30: 0 | I30: 1 | J30: 0 | K30: 0 | L30: 0 | M30: 9 | N30: 0 | O30: =SUM(C30:L30,N30) -> 5 | P30: =SUM(C30:N30) -> 14 | R30: 0300-0400 | S30: =SUM(C90:C93) -> 1 | T30: =SUM(D90:D93) -> 0 | U30: =SUM(E90:E93) -> 0 | V30: =SUM(F90:F93) -> 0 | W30: =SUM(G90:G93) -> 0 | X30: =SUM(H90:H93) -> 0 | Y30: =SUM(I90:I93) -> 1 | Z30: =SUM(J90:J93) -> 0 | ... AF30: =SUM(P90:P93) -> 2
B31: 12.15 - 12.30 | C31: 3 | D31: 0 | E31: 1 | F31: 0 | G31: 0 | H31: 0 | I31: 0 | J31: 0 | K31: 1 | L31: 0 | M31: 5 | N31: 0 | O31: =SUM(C31:L31,N31) -> 5 | P31: =SUM(C31:N31) -> 10 | R31: 0400-0500 | S31: =SUM(C94:C97) -> 1 | T31: =SUM(D94:D97) -> 1 | U31: =SUM(E94:E97) -> 0 | V31: =SUM(F94:F97) -> 0 | W31: =SUM(G94:G97) -> 0 | X31: =SUM(H94:H97) -> 0 | Y31: =SUM(I94:I97) -> 2 | Z31: =SUM(J94:J97) -> 0 | ... AF31: =SUM(P94:P97) -> 6
B32: 12.30 - 12.45 | C32: 3 | D32: 0 | E32: 1 | F32: 0 | G32: 0 | H32: 0 | I32: 1 | J32: 1 | K32: 0 | L32: 0 | M32: 5 | N32: 0 | O32: =SUM(C32:L32,N32) -> 6 | P32: =SUM(C32:N32) -> 11 | R32: 0500-0600 | S32: =SUM(C98:C101) -> 0 | T32: =SUM(D98:D101) -> 0 | U32: =SUM(E98:E101) -> 0 | V32: =SUM(F98:F101) -> 0 | W32: =SUM(G98:G101) -> 0 | X32: =SUM(H98:H101) -> 0 | Y32: =SUM(I98:I101) -> 1 | Z32: =SUM(J98:J101) -> 0 | ... AF32: =SUM(P98:P101) -> 3
B33: 12.45 - 13.00 | C33: 6 | D33: 0 | E33: 0 | F33: 0 | G33: 0 | H33: 0 | I33: 0 | J33: 1 | K33: 0 | L33: 0 | M33: 0 | N33: 0 | O33: =SUM(C33:L33,N33) -> 7 | P33: =SUM(C33:N33) -> 7 | R33: 0600-0700 | S33: =SUM(C102:C105) -> 2 | T33: =SUM(D102:D105) -> 2 | U33: =SUM(E102:E105) -> 2 | V33: =SUM(F102:F105) -> 3 | W33: =SUM(G102:G105) -> 0 | X33: =SUM(H102:H105) -> 0 | Y33: =SUM(I102:I105) -> 2 | Z33: =SUM(J102:J105) -> 0 | ... AF33: =SUM(P102:P105) -> 15
B34: 13.00 - 13.15 | C34: 3 | D34: 0 | E34: 1 | F34: 1 | G34: 0 | H34: 0 | I34: 1 | J34: 0 | K34: 0 | L34: 0 | M34: 5 | N34: 5 | O34: =SUM(C34:L34,N34) -> 11 | P34: =SUM(C34:N34) -> 16 | R34: AM Peak Hr | S34: =MAX(S10:S12) -> 12 | T34: =MAX(T10:T12) -> 3 | U34: =MAX(U10:U12) -> 3 | V34: =MAX(V10:V12) -> 8 | W34: =MAX(W10:W12) -> 0 | X34: =MAX(X10:X12) -> 0 | Y34: =MAX(Y10:Y12) -> 6 | Z34: =MAX(Z10:Z12) -> 3 | ... AF34: =MAX(AF10:AF12) -> 57
B35: 13.15 - 13.30 | C35: 0 | D35: 1 | E35: 1 | F35: 0 | G35: 0 | H35: 0 | I35: 0 | J35: 0 | K35: 0 | L35: 0 | M35: 5 | N35: 5 | O35: =SUM(C35:L35,N35) -> 7 | P35: =SUM(C35:N35) -> 12 | R35: IP Peak Hr | S35: =MAX(S13:S18) -> 15 | T35: =MAX(T13:T18) -> 2 | U35: =MAX(U13:U18) -> 5 | V35: =MAX(V13:V18) -> 2 | W35: =MAX(W13:W18) -> 1 | X35: =MAX(X13:X18) -> 0 | Y35: =MAX(Y13:Y18) -> 7 | Z35: =MAX(Z13:Z18) -> 3 | ... AF35: =MAX(AF13:AF18) -> 62
B36: 13.30 - 13.45 | C36: 1 | D36: 1 | E36: 0 | F36: 0 | G36: 0 | H36: 0 | I36: 1 | J36: 0 | K36: 0 | L36: 0 | M36: 5 | N36: 0 | O36: =SUM(C36:L36,N36) -> 3 | P36: =SUM(C36:N36) -> 8 | R36: PM Peak Hr | S36: =MAX(S19:S21) -> 18 | T36: =MAX(T19:T21) -> 2 | U36: =MAX(U19:U21) -> 6 | V36: =MAX(V19:V21) -> 2 | W36: =MAX(W19:W21) -> 2 | X36: =MAX(X19:X21) -> 0 | Y36: =MAX(Y19:Y21) -> 8 | Z36: =MAX(Z19:Z21) -> 5 | ... AF36: =MAX(AF19:AF21) -> 75
B37: 13.45 - 14.00 | C37: 1 | D37: 0 | E37: 1 | F37: 0 | G37: 0 | H37: 0 | I37: 0 | J37: 0 | K37: 2 | L37: 0 | M37: 10 | N37: 0 | O37: =SUM(C37:L37,N37) -> 4 | P37: =SUM(C37:N37) -> 14 | R37: AM Period | S37: =SUM(S10:S12) -> 25 | T37: =SUM(T10:T12) -> 5 | U37: =SUM(U10:U12) -> 5 | V37: =SUM(V10:V12) -> 16 | W37: =SUM(W10:W12) -> 0 | X37: =SUM(X10:X12) -> 0 | Y37: =SUM(Y10:Y12) -> 13 | Z37: =SUM(Z10:Z12) -> 5 | ... AF37: =SUM(AF10:AF12) -> 130
B38: 14.00 - 14.15 | C38: 4 | D38: 1 | E38: 0 | F38: 0 | G38: 0 | H38: 0 | I38: 3 | J38: 0 | K38: 1 | L38: 0 | M38: 8 | N38: 0 | O38: =SUM(C38:L38,N38) -> 9 | P38: =SUM(C38:N38) -> 17 | R38: IP Period | S38: =SUM(S13:S18) -> 65 | T38: =SUM(T13:T18) -> 7 | U38: =SUM(U13:U18) -> 22 | V38: =SUM(V13:V18) -> 5 | W38: =SUM(W13:W18) -> 1 | X38: =SUM(X13:X18) -> 0 | Y38: =SUM(Y13:Y18) -> 23 | Z38: =SUM(Z13:Z18) -> 10 | ... AF38: =SUM(AF13:AF18) -> 296
B39: 14.15 - 14.30 | C39: 0 | D39: 0 | E39: 1 | F39: 1 | G39: 0 | H39: 0 | I39: 0 | J39: 2 | K39: 0 | L39: 0 | M39: 5 | N39: 0 | O39: =SUM(C39:L39,N39) -> 4 | P39: =SUM(C39:N39) -> 9 | R39: PM Period | S39: =SUM(S19:S21) -> 34 | T39: =SUM(T19:T21) -> 6 | U39: =SUM(U19:U21) -> 11 | V39: =SUM(V19:V21) -> 6 | W39: =SUM(W19:W21) -> 2 | X39: =SUM(X19:X21) -> 0 | Y39: =SUM(Y19:Y21) -> 19 | Z39: =SUM(Z19:Z21) -> 9 | ... AF39: =SUM(AF19:AF21) -> 208
B40: 14.30 - 14.45 | C40: 2 | D40: 0 | E40: 1 | F40: 1 | G40: 1 | H40: 0 | I40: 1 | J40: 0 | K40: 0 | L40: 0 | M40: 6 | N40: 0 | O40: =SUM(C40:L40,N40) -> 6 | P40: =SUM(C40:N40) -> 12 | R40: 12 Hours | S40: =SUM(S10:S21) -> 124 | T40: =SUM(T10:T21) -> 18 | U40: =SUM(U10:U21) -> 38 | V40: =SUM(V10:V21) -> 27 | W40: =SUM(W10:W21) -> 3 | X40: =SUM(X10:X21) -> 0 | Y40: =SUM(Y10:Y21) -> 55 | Z40: =SUM(Z10:Z21) -> 24 | ... AF40: =SUM(AF10:AF21) -> 634
B41: 14.45 - 15.00 | C41: 2 | D41: 0 | E41: 2 | F41: 0 | G41: 0 | H41: 0 | I41: 1 | J41: 0 | K41: 0 | L41: 0 | M41: 4 | N41: 0 | O41: =SUM(C41:L41,N41) -> 5 | P41: =SUM(C41:N41) -> 9 | R41: 24 Hrs/ADT | S41: =SUM(S10:S33) -> 165 | T41: =SUM(T10:T33) -> 29 | U41: =SUM(U10:U33) -> 45 | V41: =SUM(V10:V33) -> 39 | W41: =SUM(W10:W33) -> 4 | X41: =SUM(X10:X33) -> 0 | Y41: =SUM(Y10:Y33) -> 76 | Z41: =SUM(Z10:Z33) -> 38 | ... AF41: =SUM(AF10:AF33) -> 855
B42: 15.00 - 15.15 | C42: 6 | D42: 0 | E42: 2 | F42: 1 | G42: 0 | H42: 0 | I42: 0 | J42: 0 | K42: 0 | L42: 0 | M42: 11 | N42: 0 | O42: =SUM(C42:L42,N42) -> 9 | P42: =SUM(C42:N42) -> 20 | R42: NEF | S42: =S41/S40 -> 1.3306452 | T42: =T41/T40 -> 1.6111111 | U42: =U41/U40 -> 1.1842105 | V42: =V41/V40 -> 1.4444444 | W42: =W41/W40 -> 1.3333333 | X42: =X41/X40 -> #DIV/0! | Y42: =Y41/Y40 -> 1.3818182 | Z42: =Z41/Z40 -> 1.5833333 | ... AF42: =AF41/AF40 -> 1.3485804
...

Sheet 19.10 MASAKA-SEMBABULE-24HRS
B1: Consultancy services for Preparation of Expressway Development Master Plan (EDMP) for Uganda
B2: MANUAL CLASSIFIED COUNT (MCC)
B3: ROAD NAME: | C3: ='17.10 SEMBABULE-MASAKA'!C3:G3 -> VIRA MARIA ROAD
C5: Date | D5: 19.10.2019 | F5: Location | G5: ='18.10 MASAKA-SEMBABULA-24HRS'!G5:H5 -> KIWUULA TC | J5: Surveyor | K5: ='18.10 MASAKA-SEMBABULA-24HRS'!K5:L5 -> NAGADDYA
C6: Dir. From | D6: ='17.10 MASAKA SEMBABULE'!D6:E6 -> MASAKA | F6: Dir. To | G6: ='17.10 MASAKA SEMBABULE'!G6:H6 -> SEMBABULE | J6: Supervisor | K6: ='18.10 MASAKA-SEMBABULA-24HRS'!K6:L6 -> KIVUMBI
B8: Time / Veh Type | R8: SUMMARY TRAFFIC VOLUMES
C9: 1. Car | D9: 2. Station Wagon | E9: 3. Pickups | F9: 4. Minibus, matatu | G9: 5. Medium bus | H9: 6. Large Bus | I9: 7. Light Truck | J9: 8. Medium Truck | K9: 9. Heavy truck | L9: 10. Truck Trailer | M9: 11. Motor cycles | N9: 12. Tractors | O9: Total Excl M/Cycles | P9: Total All | R9: Time | S9: 1. Car | T9: 2. Station Wagon | U9: 3. Pickups | V9: 4. Minibus, matatu | W9: 5. Medium bus | X9: 6. Large Bus | Y9: 7. Light Truck | Z9: 8. Medium Truck | AA9: 9. Heavy truck | AB9: 10. Truck Trailer | AC9: 11. Motorcycles | AD9: 12. Tractors, Graders | AE9: Total Excl M/ Cycles | AF9: Total All
B10: 07.00 - 07.15 | C10: 1 | D10: 0 | E10: 0 | F10: 0 | G10: 0 | H10: 0 | I10: 0 | J10: 0 | K10: 0 | L10: 0 | M10: 1 | N10: 0 | O10: =SUM(C10:L10,N10) -> 1 | P10: =SUM(C10:N10) -> 2 | R10: 0700-0800 | S10: =SUM(C10:C13) -> 7 | T10: =SUM(D10:D13) -> 0 | U10: =SUM(E10:E13) -> 0 | V10: =SUM(F10:F13) -> 0 | W10: =SUM(G10:G13) -> 0 | X10: =SUM(H10:H13) -> 0 | Y10: =SUM(I10:I13) -> 2 | Z10: =SUM(J10:J13) -> 1 | ... AF10: =SUM(P10:P13) -> 31
B11: 07.15 - 07.30 | C11: 1 | D11: 0 | E11: 0 | F11: 0 | G11: 0 | H11: 0 | I11: 0 | J11: 1 | K11: 0 | L11: 0 | M11: 9 | N11: 0 | O11: =SUM(C11:L11,N11) -> 2 | P11: =SUM(C11:N11) -> 11 | R11: 0800-0900 | S11: =SUM(C14:C17) -> 5 | T11: =SUM(D14:D17) -> 1 | U11: =SUM(E14:E17) -> 0 | V11: =SUM(F14:F17) -> 1 | W11: =SUM(G14:G17) -> 0 | X11: =SUM(H14:H17) -> 0 | Y11: =SUM(I14:I17) -> 6 | Z11: =SUM(J14:J17) -> 0 | ... AF11: =SUM(P14:P17) -> 29
B12: 07.30 - 07.45 | C12: 0 | D12: 0 | E12: 0 | F12: 0 | G12: 0 | H12: 0 | I12: 0 | J12: 0 | K12: 1 | L12: 0 | M12: 6 | N12: 0 | O12: =SUM(C12:L12,N12) -> 1 | P12: =SUM(C12:N12) -> 7 | R12: 0900-1000 | S12: =SUM(C18:C21) -> 5 | T12: =SUM(D18:D21) -> 1 | U12: =SUM(E18:E21) -> 2 | V12: =SUM(F18:F21) -> 0 | W12: =SUM(G18:G21) -> 0 | X12: =SUM(H18:H21) -> 0 | Y12: =SUM(I18:I21) -> 6 | Z12: =SUM(J18:J21) -> 1 | ... AF12: =SUM(P18:P21) -> 35
B13: 07.45 - 08.00 | C13: 5 | D13: 0 | E13: 0 | F13: 0 | G13: 0 | H13: 0 | I13: 2 | J13: 0 | K13: 0 | L13: 0 | M13: 4 | N13: 0 | O13: =SUM(C13:L13,N13) -> 7 | P13: =SUM(C13:N13) -> 11 | R13: 1000-1100 | S13: =SUM(C22:C25) -> 6 | T13: =SUM(D22:D25) -> 2 | U13: =SUM(E22:E25) -> 2 | V13: =SUM(F22:F25) -> 0 | W13: =SUM(G22:G25) -> 0 | X13: =SUM(H22:H25) -> 0 | Y13: =SUM(I22:I25) -> 1 | Z13: =SUM(J22:J25) -> 1 | ... AF13: =SUM(P22:P25) -> 33
B14: 08.00 - 08.15 | C14: 2 | D14: 0 | E14: 0 | F14: 1 | G14: 0 | H14: 0 | I14: 0 | J14: 0 | K14: 0 | L14: 0 | M14: 2 | N14: 0 | O14: =SUM(C14:L14,N14) -> 3 | P14: =SUM(C14:N14) -> 5 | R14: 1100-1200 | S14: =SUM(C26:C29) -> 8 | T14: =SUM(D26:D29) -> 1 | U14: =SUM(E26:E29) -> 1 | V14: =SUM(F26:F29) -> 0 | W14: =SUM(G26:G29) -> 0 | X14: =SUM(H26:H29) -> 0 | Y14: =SUM(I26:I29) -> 6 | Z14: =SUM(J26:J29) -> 3 | ... AF14: =SUM(P26:P29) -> 49
B15: 08.15 - 08.30 | C15: 0 | D15: 0 | E15: 0 | F15: 0 | G15: 0 | H15: 0 | I15: 1 | J15: 0 | K15: 0 | L15: 0 | M15: 4 | N15: 0 | O15: =SUM(C15:L15,N15) -> 1 | P15: =SUM(C15:N15) -> 5 | R15: 1200-1300 | S15: =SUM(C30:C33) -> 14 | T15: =SUM(D30:D33) -> 0 | U15: =SUM(E30:E33) -> 3 | V15: =SUM(F30:F33) -> 0 | W15: =SUM(G30:G33) -> 0 | X15: =SUM(H30:H33) -> 0 | Y15: =SUM(I30:I33) -> 2 | Z15: =SUM(J30:J33) -> 3 | ... AF15: =SUM(P30:P33) -> 50
