Workbook

Sheet 17.10 KANONI-MADDU
B1: Consultancy services for Preparation of Expressway Development Master Plan (EDMP) for Uganda
B2: MANUAL CLASSIFIED COUNT (MCC)
B3: ROAD NAME: | C3: KANONI-MADDU ROAD
C5: Date | D5: 17.10.2019 | F5: Location | G5: KANONI | J5: Surveyor | K5: FELIX OLOYA
C6: Dir. From | D6: KANONI | F6: Dir. To | G6: MADDU | J6: Supervisor | K6: FELIX OLOYA
B8: Time / Veh Type | R8: SUMMARY TRAFFIC VOLUMES
C9: 1. Car | D9: 2. Station Wagon | E9: 3. Pickups | F9: 4. Minibus, matatu | G9: 5. Medium bus | H9: 6. Large Bus | I9: 7. Light Truck | J9: 8. Medium Truck | K9: 9. Heavy truck | L9: 10. Truck Trailer | M9: 11. Motor cycles | N9: 12. Tractors | O9: Total Excl M/Cycles | P9: Total All | R9: Time | S9: 1. Car | T9: 2. Station Wagon | U9: 3. Pickups | V9: 4. Minibus, matatu | W9: 5. Medium bus | X9: 6. Large Bus | Y9: 7. Light Truck | Z9: 8. Medium Truck | AA9: 9. Heavy truck | AB9: 10. Truck Trailer | AC9: 11. Motorcycles | AD9: 12. Tractors, Graders | AE9: Total Excl M/ Cycles | AF9: Total All
B10: 07.00 - 07.15 | C10: 1 | D10: 0 | E10: 0 | F10: 0 | G10: 0 | H10: 0 | I10: 0 | J10: 1 | K10: 0 | L10: 0 | M10: 4 | N10: 0 | O10: =SUM(C10:L10,N10) -> 2 | P10: =SUM(C10:N10) -> 6 | R10: 0700-0800 | S10: =SUM(C10:C13) -> 4 | T10: =SUM(D10:D13) -> 1 | U10: =SUM(E10:E13) -> 4 | V10: =SUM(F10:F13) -> 1 | W10: =SUM(G10:G13) -> 0 | X10: =SUM(H10:H13) -> 0 | Y10: =SUM(I10:I13) -> 8 | Z10: =SUM(J10:J13) -> 3 | ... AF10: =SUM(P10:P13) -> 41
B11: 07.15 - 07.30 | C11: 1 | D11: 0 | E11: 0 | F11: 0 | G11: 0 | H11: 0 | I11: 1 | J11: 0 | K11: 0 | L11: 0 | M11: 1 | N11: 0 | O11: =SUM(C11:L11,N11) -> 2 | P11: =SUM(C11:N11) -> 3 | R11: 0800-0900 | S11: =SUM(C14:C17) -> 13 | T11: =SUM(D14:D17) -> 10 | U11: =SUM(E14:E17) -> 3 | V11: =SUM(F14:F17) -> 4 | W11: =SUM(G14:G17) -> 0 | X11: =SUM(H14:H17) -> 0 | Y11: =SUM(I14:I17) -> 0 | Z11: =SUM(J14:J17) -> 2 | ... AF11: =SUM(P14:P17) -> 79
B12: 07.30 - 07.45 | C12: 1 | D12: 0 | E12: 0 | F12: 1 | G12: 0 | H12: 0 | I12: 4 | J12: 1 | K12: 0 | L12: 0 | M12: 8 | N12: 0 | O12: =SUM(C12:L12,N12) -> 7 | P12: =SUM(C12:N12) -> 15 | R12: 0900-1000 | S12: =SUM(C18:C21) -> 6 | T12: =SUM(D18:D21) -> 4 | U12: =SUM(E18:E21) -> 6 | V12: =SUM(F18:F21) -> 3 | W12: =SUM(G18:G21) -> 0 | X12: =SUM(H18:H21) -> 0 | Y12: =SUM(I18:I21) -> 3 | Z12: =SUM(J18:J21) -> 0 | ... AF12: =SUM(P18:P21) -> 79
B13: 07.45 - 08.00 | C13: 1 | D13: 1 | E13: 4 | F13: 0 | G13: 0 | H13: 0 | I13: 3 | J13: 1 | K13: 0 | L13: 0 | M13: 7 | N13: 0 | O13: =SUM(C13:L13,N13) -> 10 | P13: =SUM(C13:N13) -> 17 | R13: 1000-1100 | S13: =SUM(C22:C25) -> 18 | T13: =SUM(D22:D25) -> 8 | U13: =SUM(E22:E25) -> 6 | V13: =SUM(F22:F25) -> 7 | W13: =SUM(G22:G25) -> 0 | X13: =SUM(H22:H25) -> 0 | Y13: =SUM(I22:I25) -> 1 | Z13: =SUM(J22:J25) -> 1 | ... AF13: =SUM(P22:P25) -> 76
B14: 08.00 - 08.15 | C14: 2 | D14: 2 | E14: 0 | F14: 2 | G14: 0 | H14: 0 | I14: 0 | J14: 0 | K14: 1 | L14: 0 | M14: 11 | N14: 0 | O14: =SUM(C14:L14,N14) -> 7 | P14: =SUM(C14:N14) -> 18 | R14: 1100-1200 | S14: =SUM(C26:C29) -> 11 | T14: =SUM(D26:D29) -> 1 | U14: =SUM(E26:E29) -> 7 | V14: =SUM(F26:F29) -> 9 | W14: =SUM(G26:G29) -> 0 | X14: =SUM(H26:H29) -> 0 | Y14: =SUM(I26:I29) -> 2 | Z14: =SUM(J26:J29) -> 1 | ... AF14: =SUM(P26:P29) -> 64
B15: 08.15 - 08.30 | C15: 2 | D15: 1 | E15: 0 | F15: 0 | G15: 0 | H15: 0 | I15: 0 | J15: 0 | K15: 0 | L15: 0 | M15: 12 | N15: 0 | O15: =SUM(C15:L15,N15) -> 3 | P15: =SUM(C15:N15) -> 15 | R15: 1200-1300 | S15: =SUM(C30:C33) -> 9 | T15: =SUM(D30:D33) -> 2 | U15: =SUM(E30:E33) -> 2 | V15: =SUM(F30:F33) -> 6 | W15: =SUM(G30:G33) -> 0 | X15: =SUM(H30:H33) -> 0 | Y15: =SUM(I30:I33) -> 8 | Z15: =SUM(J30:J33) -> 2 | ... AF15: =SUM(P30:P33) -> 65
B16: 08.30 - 08.45 | C16: 6 | D16: 5 | E16: 2 | F16: 0 | G16: 0 | H16: 0 | I16: 0 | J16: 0 | K16: 1 | L16: 0 | M16: 15 | N16: 0 | O16: =SUM(C16:L16,N16) -> 14 | P16: =SUM(C16:N16) -> 29 | R16: 1300-1400 | S16: =SUM(C34:C37) -> 8 | T16: =SUM(D34:D37) -> 3 | U16: =SUM(E34:E37) -> 3 | V16: =SUM(F34:F37) -> 5 | W16: =SUM(G34:G37) -> 0 | X16: =SUM(H34:H37) -> 0 | Y16: =SUM(I34:I37) -> 2 | Z16: =SUM(J34:J37) -> 2 | ... AF16: =SUM(P34:P37) -> 58
B17: 08.45 - 9.00 | C17: 3 | D17: 2 | E17: 1 | F17: 2 | G17: 0 | H17: 0 | I17: 0 | J17: 2 | K17: 0 | L17: 0 | M17: 7 | N17: 0 | O17: =SUM(C17:L17,N17) -> 10 | P17: =SUM(C17:N17) -> 17 | R17: 1400-1500 | S17: =SUM(C38:C41) -> 14 | T17: =SUM(D38:D41) -> 3 | U17: =SUM(E38:E41) -> 2 | V17: =SUM(F38:F41) -> 7 | W17: =SUM(G38:G41) -> 0 | X17: =SUM(H38:H41) -> 0 | Y17: =SUM(I38:I41) -> 2 | Z17: =SUM(J38:J41) -> 1 | ... AF17: =SUM(P38:P41) -> 86
B18: 09.00 - 09.15 | C18: 2 | D18: 2 | E18: 0 | F18: 1 | G18: 0 | H18: 0 | I18: 1 | J18: 0 | K18: 0 | L18: 0 | M18: 12 | N18: 0 | O18: =SUM(C18:L18,N18) -> 6 | P18: =SUM(C18:N18) -> 18 | R18: 1500-1600 | S18: =SUM(C42:C45) -> 4 | T18: =SUM(D42:D45) -> 1 | U18: =SUM(E42:E45) -> 6 | V18: =SUM(F42:F45) -> 6 | W18: =SUM(G42:G45) -> 0 | X18: =SUM(H42:H45) -> 0 | Y18: =SUM(I42:I45) -> 1 | Z18: =SUM(J42:J45) -> 5 | ... AF18: =SUM(P42:P45) -> 62
B19: 09.15 - 09.30 | C19: 1 | D19: 0 | E19: 2 | F19: 1 | G19: 0 | H19: 0 | I19: 1 | J19: 0 | K19: 1 | L19: 0 | M19: 14 | N19: 0 | O19: =SUM(C19:L19,N19) -> 6 | P19: =SUM(C19:N19) -> 20 | R19: 1600-1700 | S19: =SUM(C46:C49) -> 5 | T19: =SUM(D46:D49) -> 1 | U19: =SUM(E46:E49) -> 2 | V19: =SUM(F46:F49) -> 7 | W19: =SUM(G46:G49) -> 0 | X19: =SUM(H46:H49) -> 0 | Y19: =SUM(I46:I49) -> 5 | Z19: =SUM(J46:J49) -> 4 | ... AF19: =SUM(P46:P49) -> 69
B20: 09.30 - 09.45 | C20: 2 | D20: 2 | E20: 4 | F20: 1 | G20: 0 | H20: 0 | I20: 1 | J20: 0 | K20: 1 | L20: 0 | M20: 22 | N20: 0 | O20: =SUM(C20:L20,N20) -> 11 | P20: =SUM(C20:N20) -> 33 | R20: 1700-1800 | S20: =SUM(C50:C53) -> 7 | T20: =SUM(D50:D53) -> 0 | U20: =SUM(E50:E53) -> 0 | V20: =SUM(F50:F53) -> 7 | W20: =SUM(G50:G53) -> 0 | X20: =SUM(H50:H53) -> 0 | Y20: =SUM(I50:I53) -> 1 | Z20: =SUM(J50:J53) -> 0 | ... AF20: =SUM(P50:P53) -> 58
B21: 09.45 - 10.00 | C21: 1 | D21: 0 | E21: 0 | F21: 0 | G21: 0 | H21: 0 | I21: 0 | J21: 0 | K21: 1 | L21: 0 | M21: 6 | N21: 0 | O21: =SUM(C21:L21,N21) -> 2 | P21: =SUM(C21:N21) -> 8 | R21: 1800-1900 | S21: =SUM(C54:C57) -> 5 | T21: =SUM(D54:D57) -> 0 | U21: =SUM(E54:E57) -> 0 | V21: =SUM(F54:F57) -> 8 | W21: =SUM(G54:G57) -> 0 | X21: =SUM(H54:H57) -> 0 | Y21: =SUM(I54:I57) -> 7 | Z21: =SUM(J54:J57) -> 2 | ... AF21: =SUM(P54:P57) -> 62
B22: 10.00 - 10.15 | C22: 9 | D22: 2 | E22: 2 | F22: 2 | G22: 0 | H22: 0 | I22: 0 | J22: 0 | K22: 0 | L22: 0 | M22: 10 | N22: 0 | O22: =SUM(C22:L22,N22) -> 15 | P22: =SUM(C22:N22) -> 25 | R22: AM Peak Hr | S22: =MAX(S10:S12) -> 13 | T22: =MAX(T10:T12) -> 10 | U22: =MAX(U10:U12) -> 6 | V22: =MAX(V10:V12) -> 4 | W22: =MAX(W10:W12) -> 0 | X22: =MAX(X10:X12) -> 0 | Y22: =MAX(Y10:Y12) -> 8 | Z22: =MAX(Z10:Z12) -> 3 | ... AF22: =MAX(AF10:AF12) -> 79
B23: 10.15 - 10.30 | C23: 6 | D23: 5 | E23: 1 | F23: 2 | G23: 0 | H23: 0 | I23: 0 | J23: 0 | K23: 0 | L23: 0 | M23: 8 | N23: 0 | O23: =SUM(C23:L23,N23) -> 14 | P23: =SUM(C23:N23) -> 22 | R23: IP Peak Hr | S23: =MAX(S13:S18) -> 18 | T23: =MAX(T13:T18) -> 8 | U23: =MAX(U13:U18) -> 7 | V23: =MAX(V13:V18) -> 9 | W23: =MAX(W13:W18) -> 0 | X23: =MAX(X13:X18) -> 0 | Y23: =MAX(Y13:Y18) -> 8 | Z23: =MAX(Z13:Z18) -> 5 | ... AF23: =MAX(AF13:AF18) -> 86
B24: 10.30 - 10.45 | C24: 2 | D24: 1 | E24: 1 | F24: 1 | G24: 0 | H24: 0 | I24: 1 | J24: 0 | K24: 0 | L24: 0 | M24: 14 | N24: 0 | O24: =SUM(C24:L24,N24) -> 6 | P24: =SUM(C24:N24) -> 20 | R24: PM Peak Hr | S24: =MAX(S19:S21) -> 7 | T24: =MAX(T19:T21) -> 1 | U24: =MAX(U19:U21) -> 2 | V24: =MAX(V19:V21) -> 8 | W24: =MAX(W19:W21) -> 0 | X24: =MAX(X19:X21) -> 0 | Y24: =MAX(Y19:Y21) -> 7 | Z24: =MAX(Z19:Z21) -> 4 | ... AF24: =MAX(AF19:AF21) -> 69
B25: 10.45 - 11.00 | C25: 1 | D25: 0 | E25: 2 | F25: 2 | G25: 0 | H25: 0 | I25: 0 | J25: 1 | K25: 0 | L25: 0 | M25: 3 | N25: 0 | O25: =SUM(C25:L25,N25) -> 6 | P25: =SUM(C25:N25) -> 9 | R25: AM Period | S25: =SUM(S10:S12) -> 23 | T25: =SUM(T10:T12) -> 15 | U25: =SUM(U10:U12) -> 13 | V25: =SUM(V10:V12) -> 8 | W25: =SUM(W10:W12) -> 0 | X25: =SUM(X10:X12) -> 0 | Y25: =SUM(Y10:Y12) -> 11 | Z25: =SUM(Z10:Z12) -> 5 | ... AF25: =SUM(AF10:AF12) -> 199
B26: 11.00 - 11.15 | C26: 4 | D26: 0 | E26: 2 | F26: 5 | G26: 0 | H26: 0 | I26: 1 | J26: 0 | K26: 0 | L26: 0 | M26: 14 | N26: 0 | O26: =SUM(C26:L26,N26) -> 12 | P26: =SUM(C26:N26) -> 26 | R26: IP Period | S26: =SUM(S13:S18) -> 64 | T26: =SUM(T13:T18) -> 18 | U26: =SUM(U13:U18) -> 26 | V26: =SUM(V13:V18) -> 40 | W26: =SUM(W13:W18) -> 0 | X26: =SUM(X13:X18) -> 0 | Y26: =SUM(Y13:Y18) -> 16 | Z26: =SUM(Z13:Z18) -> 12 | ... AF26: =SUM(AF13:AF18) -> 411
B27: 11.15 - 11.30 | C27: 2 | D27: 0 | E27: 0 | F27: 0 | G27: 0 | H27: 0 | I27: 0 | J27: 0 | K27: 0 | L27: 0 | M27: 7 | N27: 0 | O27: =SUM(C27:L27,N27) -> 2 | P27: =SUM(C27:N27) -> 9 | R27: PM Period | S27: =SUM(S19:S21) -> 17 | T27: =SUM(T19:T21) -> 1 | U27: =SUM(U19:U21) -> 2 | V27: =SUM(V19:V21) -> 22 | W27: =SUM(W19:W21) -> 0 | X27: =SUM(X19:X21) -> 0 | Y27: =SUM(Y19:Y21) -> 13 | Z27: =SUM(Z19:Z21) -> 6 | ... AF27: =SUM(AF19:AF21) -> 189
B28: 11.30 - 11.45 | C28: 3 | D28: 1 | E28: 4 | F28: 2 | G28: 0 | H28: 0 | I28: 0 | J28: 1 | K28: 0 | L28: 0 | M28: 7 | N28: 0 | O28: =SUM(C28:L28,N28) -> 11 | P28: =SUM(C28:N28) -> 18 | R28: 12 Hours | S28: =SUM(S10:S21) -> 104 | T28: =SUM(T10:T21) -> 34 | U28: =SUM(U10:U21) -> 41 | V28: =SUM(V10:V21) -> 70 | W28: =SUM(W10:W21) -> 0 | X28: =SUM(X10:X21) -> 0 | Y28: =SUM(Y10:Y21) -> 40 | Z28: =SUM(Z10:Z21) -> 23 | ... AF28: =SUM(AF10:AF21) -> 799
B29: 11.45 - 12.00 | C29: 2 | D29: 0 | E29: 1 | F29: 2 | G29: 0 | H29: 0 | I29: 1 | J29: 0 | K29: 1 | L29: 0 | M29: 4 | N29: 0 | O29: =SUM(C29:L29,N29) -> 7 | P29: =SUM(C29:N29) -> 11
B30: 12.00 - 12.15 | C30: 4 | D30: 1 | E30: 1 | F30: 1 | G30: 0 | H30: 0 | I30: 3 | J30: 1 | K30: 0 | L30: 0 | M30: 8 | N30: 0 | O30: =SUM(C30:L30,N30) -> 11 | P30: =SUM(C30:N30) -> 19
B31: 12.15 - 12.30 | C31: 4 | D31: 1 | E31: 1 | F31: 2 | G31: 0 | H31: 0 | I31: 2 | J31: 1 | K31: 0 | L31: 0 | M31: 11 | N31: 0 | O31: =SUM(C31:L31,N31) -> 11 | P31: =SUM(C31:N31) -> 22
B32: 12.30 - 12.45 | C32: 0 | D32: 0 | E32: 0 | F32: 0 | G32: 0 | H32: 0 | I32: 2 | J32: 0 | K32: 0 | L32: 0 | M32: 12 | N32: 0 | O32: =SUM(C32:L32,N32) -> 2 | P32: =SUM(C32:N32) -> 14
B33: 12.45 - 13.00 | C33: 1 | D33: 0 | E33: 0 | F33: 3 | G33: 0 | H33: 0 | I33: 1 | J33: 0 | K33: 0 | L33: 0 | M33: 5 | N33: 0 | O33: =SUM(C33:L33,N33) -> 5 | P33: =SUM(C33:N33) -> 10
B34: 13.00 - 13.15 | C34: 5 | D34: 1 | E34: 1 | F34: 1 | G34: 0 | H34: 0 | I34: 1 | J34: 1 | K34: 0 | L34: 0 | M34: 11 | N34: 0 | O34: =SUM(C34:L34,N34) -> 10 | P34: =SUM(C34:N34) -> 21
B35: 13.15 - 13.30 | C35: 1 | D35: 1 | E35: 2 | F35: 1 | G35: 0 | H35: 0 | I35: 1 | J35: 0 | K35: 0 | L35: 0 | M35: 5 | N35: 0 | O35: =SUM(C35:L35,N35) -> 6 | P35: =SUM(C35:N35) -> 11
B36: 13.30 - 13.45 | C36: 1 | D36: 0 | E36: 0 | F36: 2 | G36: 0 | H36: 0 | I36: 0 | J36: 0 | K36: 0 | L36: 0 | M36: 5 | N36: 0 | O36: =SUM(C36:L36,N36) -> 3 | P36: =SUM(C36:N36) -> 8
B37: 13.45 - 14.00 | C37: 1 | D37: 1 | E37: 0 | F37: 1 | G37: 0 | H37: 0 | I37: 0 | J37: 1 | K37: 1 | L37: 0 | M37: 13 | N37: 0 | O37: =SUM(C37:L37,N37) -> 5 | P37: =SUM(C37:N37) -> 18
B38: 14.00 - 14.15 | C38: 2 | D38: 0 | E38: 1 | F38: 3 | G38: 0 | H38: 0 | I38: 1 | J38: 1 | K38: 0 | L38: 0 | M38: 15 | N38: 0 | O38: =SUM(C38:L38,N38) -> 8 | P38: =SUM(C38:N38) -> 23
B39: 14.15 - 14.30 | C39: 2 | D39: 0 | E39: 0 | F39: 1 | G39: 0 | H39: 0 | I39: 0 | J39: 0 | K39: 2 | L39: 0 | M39: 8 | N39: 0 | O39: =SUM(C39:L39,N39) -> 5 | P39: =SUM(C39:N39) -> 13
B40: 14.30 - 14.45 | C40: 4 | D40: 2 | E40: 0 | F40: 0 | G40: 0 | H40: 0 | I40: 1 | J40: 0 | K40: 0 | L40: 0 | M40: 11 | N40: 0 | O40: =SUM(C40:L40,N40) -> 7 | P40: =SUM(C40:N40) -> 18
... B57: 18.45 - 19.00 | C57: 1 | D57: 0 | E57: 0 | F57: 0 | G57: 0 | H57: 0 | I57: 2 | J57: 2 | K57: 0 | L57: 0 | M57: 9 | N57: 0 | O57: =SUM(C57:L57,N57) -> 5 | P57: =SUM(C57:N57) -> 14
B58: Totals | C58: =SUM(C10:C57) -> 104 | D58: =SUM(D10:D57) -> 34 | E58: =SUM(E10:E57) -> 41 | F58: =SUM(F10:F57) -> 70 | G58: =SUM(G10:G57) -> 0 | H58: =SUM(H10:H57) -> 0 | I58: =SUM(I10:I57) -> 40 | J58: =SUM(J10:J57) -> 23 | ... P58: =SUM(P10:P57) -> 799
...

Sheet 17.10 MADDU-KANONI
B1: Consultancy services for Preparation of Expressway Development Master Plan (EDMP) for Uganda
B2: MANUAL CLASSIFIED COUNT (MCC)
B3: ROAD NAME: | C3: ='17.10 KANONI-MADDU'!C3:G3 -> KANONI-MADDU ROAD
C5: Date | D5: ='17.10 KANONI-MADDU'!D5 -> 17.10.2019 | F5: Location | G5: ='17.10 KANONI-MADDU'!G5:H5 -> KANONI | J5: Surveyor | K5: BABIRYE PHIONA
C6: Dir. From | D6: MADDU | F6: Dir. To | G6: KANONI | J6: Supervisor | K6: ='17.10 KANONI-MADDU'!K6:L6 -> FELIX OLOYA
B8: Time / Veh Type | R8: SUMMARY TRAFFIC VOLUMES
C9: 1. Car | D9: 2. Station Wagon | E9: 3. Pickups | F9: 4. Minibus, matatu | G9: 5. Medium bus | H9: 6. Large Bus | I9: 7. Light Truck | J9: 8. Medium Truck | K9: 9. Heavy truck | L9: 10. Truck Trailer | M9: 11. Motor cycles | N9: 12. Tractors | O9: Total Excl M/Cycles | P9: Total All | R9: Time | S9: 1. Car | T9: 2. Station Wagon | U9: 3. Pickups | V9: 4. Minibus, matatu | W9: 5. Medium bus | X9: 6. Large Bus | Y9: 7. Light Truck | Z9: 8. Medium Truck | AA9: 9. Heavy truck | AB9: 10. Truck Trailer | AC9: 11. Motorcycles | AD9: 12. Tractors, Graders | AE9: Total Excl M/ Cycles | AF9: Total All
B10: 07.00 - 07.15 | C10: 1 | D10: 0 | E10: 1 | F10: 2 | G10: 0 | H10: 0 | I10: 0 | J10: 0 | K10: 0 | L10: 0 | M10: 4 | N10: 0 | O10: =SUM(C10:L10,N10) -> 4 | P10: =SUM(C10:N10) -> 8 | R10: 0700-0800 | S10: =SUM(C10:C13) -> 3 | T10: =SUM(D10:D13) -> 0 | U10: =SUM(E10:E13) -> 2 | V10: =SUM(F10:F13) -> 5 | W10: =SUM(G10:G13) -> 0 | X10: =SUM(H10:H13) -> 0 | Y10: =SUM(I10:I13) -> 0 | Z10: =SUM(J10:J13) -> 0 | ... AF10: =SUM(P10:P13) -> 28
B11: 07.15 - 07.30 | C11: 1 | D11: 0 | E11: 0 | F11: 1 | G11: 0 | H11: 0 | I11: 0 | J11: 0 | K11: 0 | L11: 0 | M11: 1 | N11: 0 | O11: =SUM(C11:L11,N11) -> 2 | P11: =SUM(C11:N11) -> 3 | R11: 0800-0900 | S11: =SUM(C14:C17) -> 6 | T11: =SUM(D14:D17) -> 2 | U11: =SUM(E14:E17) -> 1 | V11: =SUM(F14:F17) -> 10 | W11: =SUM(G14:G17) -> 0 | X11: =SUM(H14:H17) -> 0 | Y11: =SUM(I14:I17) -> 0 | Z11: =SUM(J14:J17) -> 0 | ... AF11: =SUM(P14:P17) -> 65
B12: 07.30 - 07.45 | C12: 0 | D12: 0 | E12: 1 | F12: 0 | G12: 0 | H12: 0 | I12: 0 | J12: 0 | K12: 0 | L12: 0 | M12: 4 | N12: 0 | O12: =SUM(C12:L12,N12) -> 1 | P12: =SUM(C12:N12) -> 5 | R12: 0900-1000 | S12: =SUM(C18:C21) -> 4 | T12: =SUM(D18:D21) -> 2 | U12: =SUM(E18:E21) -> 5 | V12: =SUM(F18:F21) -> 9 | W12: =SUM(G18:G21) -> 0 | X12: =SUM(H18:H21) -> 0 | Y12: =SUM(I18:I21) -> 1 | Z12: =SUM(J18:J21) -> 1 | ... AF12: =SUM(P18:P21) -> 70
B13: 07.45 - 08.00 | C13: 1 | D13: 0 | E13: 0 | F13: 2 | G13: 0 | H13: 0 | I13: 0 | J13: 0 | K13: 0 | L13: 0 | M13: 9 | N13: 0 | O13: =SUM(C13:L13,N13) -> 3 | P13: =SUM(C13:N13) -> 12 | R13: 1000-1100 | S13: =SUM(C22:C25) -> 5 | T13: =SUM(D22:D25) -> 1 | U13: =SUM(E22:E25) -> 2 | V13: =SUM(F22:F25) -> 10 | W13: =SUM(G22:G25) -> 0 | X13: =SUM(H22:H25) -> 0 | Y13: =SUM(I22:I25) -> 0 | Z13: =SUM(J22:J25) -> 0 | ... AF13: =SUM(P22:P25) -> 54
B14: 08.00 - 08.15 | C14: 1 | D14: 1 | E14: 0 | F14: 3 | G14: 0 | H14: 0 | I14: 0 | J14: 0 | K14: 0 | L14: 0 | M14: 9 | N14: 0 | O14: =SUM(C14:L14,N14) -> 5 | P14: =SUM(C14:N14) -> 14 | R14: 1100-1200 | S14: =SUM(C26:C29) -> 10 | T14: =SUM(D26:D29) -> 3 | U14: =SUM(E26:E29) -> 6 | V14: =SUM(F26:F29) -> 4 | W14: =SUM(G26:G29) -> 0 | X14: =SUM(H26:H29) -> 0 | Y14: =SUM(I26:I29) -> 0 | Z14: =SUM(J26:J29) -> 2 | ... AF14: =SUM(P26:P29) -> 79
B15: 08.15 - 08.30 | C15: 2 | D15: 0 | E15: 0 | F15: 2 | G15: 0 | H15: 0 | I15: 0 | J15: 0 | K15: 1 | L15: 0 | M15: 7 | N15: 0 | O15: =SUM(C15:L15,N15) -> 5 | P15: =SUM(C15:N15) -> 12 | R15: 1200-1300 | S15: =SUM(C30:C33) -> 6 | T15: =SUM(D30:D33) -> 1 | U15: =SUM(E30:E33) -> 0 | V15: =SUM(F30:F33) -> 5 | W15: =SUM(G30:G33) -> 0 | X15: =SUM(H30:H33) -> 0 | Y15: =SUM(I30:I33) -> 1 | Z15: =SUM(J30:J33) -> 1 | ... AF15: =SUM(P30:P33) -> 52
B16: 08.30 - 08.45 | C16: 3 | D16: 1 | E16: 0 | F16: 3 | G16: 0 | H16: 0 | I16: 0 | J16: 0 | K16: 0 | L16: 0 | M16: 13 | N16: 0 | O16: =SUM(C16:L16,N16) -> 7 | P16: =SUM(C16:N16) -> 20 | R16: 1300-1400 | S16: =SUM(C34:C37) -> 11 | T16: =SUM(D34:D37) -> 2 | U16: =SUM(E34:E37) -> 3 | V16: =SUM(F34:F37) -> 5 | W16: =SUM(G34:G37) -> 0 | X16: =SUM(H34:H37) -> 0 | Y16: =SUM(I34:I37) -> 0 | Z16: =SUM(J34:J37) -> 1 | ... AF16: =SUM(P34:P37) -> 72
B17: 08.45 - 9.00 | C17: 0 | D17: 0 | E17: 1 | F17: 2 | G17: 0 | H17: 0 | I17: 0 | J17: 0 | K17: 0 | L17: 0 | M17: 16 | N17: 0 | O17: =SUM(C17:L17,N17) -> 3 | P17: =SUM(C17:N17) -> 19 | R17: 1400-1500 | S17: =SUM(C38:C41) -> 10 | T17: =SUM(D38:D41) -> 4 | U17: =SUM(E38:E41) -> 2 | V17: =SUM(F38:F41) -> 5 | W17: =SUM(G38:G41) -> 0 | X17: =SUM(H38:H41) -> 0 | Y17: =SUM(I38:I41) -> 1 | Z17: =SUM(J38:J41) -> 3 | ... AF17: =SUM(P38:P41) -> 77
B18: 09.00 - 09.15 | C18: 2 | D18: 2 | E18: 1 | F18: 2 | G18: 0 | H18: 0 | I18: 0 | J18: 0 | K18: 0 | L18: 0 | M18: 15 | N18: 0 | O18: =SUM(C18:L18,N18) -> 7 | P18: =SUM(C18:N18) -> 22 | R18: 1500-1600 | S18: =SUM(C42:C45) -> 9 | T18: =SUM(D42:D45) -> 0 | U18: =SUM(E42:E45) -> 1 | V18: =SUM(F42:F45) -> 9 | W18: =SUM(G42:G45) -> 0 | X18: =SUM(H42:H45) -> 0 | Y18: =SUM(I42:I45) -> 3 | Z18: =SUM(J42:J45) -> 0 | ... AF18: =SUM(P42:P45) -> 65
B19: 09.15 - 09.30 | C19: 2 | D19: 0 | E19: 1 | F19: 2 | G19: 0 | H19: 0 | I19: 1 | J19: 1 | K19: 0 | L19: 0 | M19: 20 | N19: 0 | O19: =SUM(C19:L19,N19) -> 7 | P19: =SUM(C19:N19) -> 27 | R19: 1600-1700 | S19: =SUM(C46:C49) -> 7 | T19: =SUM(D46:D49) -> 7 | U19: =SUM(E46:E49) -> 13 | V19: =SUM(F46:F49) -> 7 | W19: =SUM(G46:G49) -> 0 | X19: =SUM(H46:H49) -> 0 | Y19: =SUM(I46:I49) -> 3 | Z19: =SUM(J46:J49) -> 0 | ... AF19: =SUM(P46:P49) -> 84
B20: 09.30 - 09.45 | C20: 0 | D20: 0 | E20: 3 | F20: 3 | G20: 0 | H20: 0 | I20: 0 | J20: 0 | K20: 0 | L20: 0 | M20: 8 | N20: 0 | O20: =SUM(C20:L20,N20) -> 6 | P20: =SUM(C20:N20) -> 14 | R20: 1700-1800 | S20: =SUM(C50:C53) -> 7 | T20: =SUM(D50:D53) -> 2 | U20: =SUM(E50:E53) -> 1 | V20: =SUM(F50:F53) -> 5 | W20: =SUM(G50:G53) -> 0 | X20: =SUM(H50:H53) -> 0 | Y20: =SUM(I50:I53) -> 1 | Z20: =SUM(J50:J53) -> 0 | ... AF20: =SUM(P50:P53) -> 63
B21: 09.45 - 10.00 | C21: 0 | D21: 0 | E21: 0 | F21: 2 | G21: 0 | H21: 0 | I21: 0 | J21: 0 | K21: 0 | L21: 0 | M21: 5 | N21: 0 | O21: =SUM(C21:L21,N21) -> 2 | P21: =SUM(C21:N21) -> 7 | R21: 1800-1900 | S21: =SUM(C54:C57) -> 12 | T21: =SUM(D54:D57) -> 6 | U21: =SUM(E54:E57) -> 5 | V21: =SUM(F54:F57) -> 10 | W21: =SUM(G54:G57) -> 0 | X21: =SUM(H54:H57) -> 0 | Y21: =SUM(I54:I57) -> 4 | Z21: =SUM(J54:J57) -> 1 | ... AF21: =SUM(P54:P57) -> 78
B22: 10.00 - 10.15 | C22: 1 | D22: 1 | E22: 1 | F22: 1 | G22: 0 | H22: 0 | I22: 0 | J22: 0 | K22: 0 | L22: 0 | M22: 10 | N22: 0 | O22: =SUM(C22:L22,N22) -> 4 | P22: =SUM(C22:N22) -> 14 | R22: AM Peak Hr | S22: =MAX(S10:S12) -> 6 | T22: =MAX(T10:T12) -> 2 | U22: =MAX(U10:U12) -> 5 | V22: =MAX(V10:V12) -> 10 | W22: =MAX(W10:W12) -> 0 | X22: =MAX(X10:X12) -> 0 | Y22: =MAX(Y10:Y12) -> 1 | Z22: =MAX(Z10:Z12) -> 1 | ... AF22: =MAX(AF10:AF12) -> 70
B23: 10.15 - 10.30 | C23: 2 | D23: 0 | E23: 0 | F23: 3 | G23: 0 | H23: 0 | I23: 0 | J23: 0 | K23: 0 | L23: 0 | M23: 8 | N23: 0 | O23: =SUM(C23:L23,N23) -> 5 | P23: =SUM(C23:N23) -> 13 | R23: IP Peak Hr | S23: =MAX(S13:S18) -> 11 | T23: =MAX(T13:T18) -> 4 | U23: =MAX(U13:U18) -> 6 | V23: =MAX(V13:V18) -> 10 | W23: =MAX(W13:W18) -> 0 | X23: =MAX(X13:X18) -> 0 | Y23: =MAX(Y13:Y18) -> 3 | Z23: =MAX(Z13:Z18) -> 3 | ... AF23: =MAX(AF13:AF18) -> 79
B24: 10.30 - 10.45 | C24: 0 | D24: 0 | E24: 1 | F24: 2 | G24: 0 | H24: 0 | I24: 0 | J24: 0 | K24: 0 | L24: 0 | M24: 9 | N24: 0 | O24: =SUM(C24:L24,N24) -> 3 | P24: =SUM(C24:N24) -> 12 | R24: PM Peak Hr | S24: =MAX(S19:S21) -> 12 | T24: =MAX(T19:T21) -> 7 | U24: =MAX(U19:U21) -> 13 | V24: =MAX(V19:V21) -> 10 | W24: =MAX(W19:W21) -> 0 | X24: =MAX(X19:X21) -> 0 | Y24: =MAX(Y19:Y21) -> 4 | Z24: =MAX(Z19:Z21) -> 1 | ... AF24: =MAX(AF19:AF21) -> 84
B25: 10.45 - 11.00 | C25: 2 | D25: 0 | E25: 0 | F25: 4 | G25: 0 | H25: 0 | I25: 0 | J25: 0 | K25: 0 | L25: 0 | M25: 9 | N25: 0 | O25: =SUM(C25:L25,N25) -> 6 | P25: =SUM(C25:N25) -> 15 | R25: AM Period | S25: =SUM(S10:S12) -> 13 | T25: =SUM(T10:T12) -> 4 | U25: =SUM(U10:U12) -> 8 | V25: =SUM(V10:V12) -> 24 | W25: =SUM(W10:W12) -> 0 | X25: =SUM(X10:X12) -> 0 | Y25: =SUM(Y10:Y12) -> 1 | Z25: =SUM(Z10:Z12) -> 1 | ... AF25: =SUM(AF10:AF12) -> 163
B26: 11.00 - 11.15 | C26: 2 | D26: 1 | E26: 1 | F26: 1 | G26: 0 | H26: 0 | I26: 0 | J26: 2 | K26: 0 | L26: 0 | M26: 21 | N26: 0 | O26: =SUM(C26:L26,N26) -> 7 | P26: =SUM(C26:N26) -> 28 | R26: IP Period | S26: =SUM(S13:S18) -> 51 | T26: =SUM(T13:T18) -> 11 | U26: =SUM(U13:U18) -> 14 | V26: =SUM(V13:V18) -> 38 | W26: =SUM(W13:W18) -> 0 | X26: =SUM(X13:X18) -> 0 | Y26: =SUM(Y13:Y18) -> 5 | Z26: =SUM(Z13:Z18) -> 7 | ... AF26: =SUM(AF13:AF18) -> 399
B27: 11.15 - 11.30 | C27: 4 | D27: 1 | E27: 1 | F27: 3 | G27: 0 | H27: 0 | I27: 0 | J27: 0 | K27: 0 | L27: 0 | M27: 12 | N27: 0 | O27: =SUM(C27:L27,N27) -> 9 | P27: =SUM(C27:N27) -> 21 | R27: PM Period | S27: =SUM(S19:S21) -> 26 | T27: =SUM(T19:T21) -> 15 | U27: =SUM(U19:U21) -> 19 | V27: =SUM(V19:V21) -> 22 | W27: =SUM(W19:W21) -> 0 | X27: =SUM(X19:X21) -> 0 | Y27: =SUM(Y19:Y21) -> 8 | Z27: =SUM(Z19:Z21) -> 1 | ... AF27: =SUM(AF19:AF21) -> 225
B28: 11.30 - 11.45 | C28: 2 | D28: 0 | E28: 3 | F28: 0 | G28: 0 | H28: 0 | I28: 0 | J28: 0 | K28: 0 | L28: 0 | M28: 15 | N28: 0 | O28: =SUM(C28:L28,N28) -> 5 | P28: =SUM(C28:N28) -> 20 | R28: 12 Hours | S28: =SUM(S10:S21) -> 90 | T28: =SUM(T10:T21) -> 30 | U28: =SUM(U10:U21) -> 41 | V28: =SUM(V10:V21) -> 84 | W28: =SUM(W10:W21) -> 0 | X28: =SUM(X10:X21) -> 0 | Y28: =SUM(Y10:Y21) -> 14 | Z28: =SUM(Z10:Z21) -> 9 | ... AF28: =SUM(AF10:AF21) -> 787
B29: 11.45 - 12.00 | C29: 2 | D29: 1 | E29: 1 | F29: 0 | G29: 0 | H29: 0 | I29: 0 | J29: 0 | K29: 0 | L29: 0 | M29: 6 | N29: 0 | O29: =SUM(C29:L29,N29) -> 4 | P29: =SUM(C29:N29) -> 10
B30: 12.00 - 12.15 | C30: 2 | D30: 0 | E30: 0 | F30: 2 | G30: 0 | H30: 0 | I30: 0 | J30: 1 | K30: 0 | L30: 0 | M30: 13 | N30: 0 | O30: =SUM(C30:L30,N30) -> 5 | P30: =SUM(C30:N30) -> 18
B31: 12.15 - 12.30 | C31: 1 | D31: 0 | E31: 0 | F31: 2 | G31: 0 | H31: 0 | I31: 0 | J31: 0 | K31: 0 | L31: 0 | M31: 9 | N31: 0 | O31: =SUM(C31:L31,N31) -> 3 | P31: =SUM(C31:N31) -> 12
B32: 12.30 - 12.45 | C32: 2 | D32: 1 | E32: 0 | F32: 0 | G32: 0 | H32: 0 | I32: 1 | J32: 0 | K32: 0 | L32: 0 | M32: 11 | N32: 0 | O32: =SUM(C32:L32,N32) -> 4 | P32: =SUM(C32:N32) -> 15
B33: 12.45 - 13.00 | C33: 1 | D33: 0 | E33: 0 | F33: 1 | G33: 0 | H33: 0 | I33: 0 | J33: 0 | K33: 0 | L33: 0 | M33: 5 | N33: 0 | O33: =SUM(C33:L33,N33) -> 2 | P33: =SUM(C33:N33) -> 7
B34: 13.00 - 13.15 | C34: 0 | D34: 0 | E34: 1 | F34: 2 | G34: 0 | H34: 0 | I34: 0 | J34: 0 | K34: 1 | L34: 0 | M34: 9 | N34: 0 | O34: =SUM(C34:L34,N34) -> 4 | P34: =SUM(C34:N34) -> 13
B35: 13.15 - 13.30 | C35: 4 | D35: 1 | E35: 0 | F35: 1 | G35: 0 | H35: 0 | I35: 0 | J35: 0 | K35: 0 | L35: 0 | M35: 13 | N35: 0 | O35: =SUM(C35:L35,N35) -> 6 | P35: =SUM(C35:N35) -> 19
B36: 13.30 - 13.45 | C36: 3 | D36: 1 | E36: 0 | F36: 1 | G36: 0 | H36: 0 | I36: 0 | J36: 0 | K36: 1 | L36: 0 | M36: 13 | N36: 0 | O36: =SUM(C36:L36,N36) -> 6 | P36: =SUM(C36:N36) -> 19
B37: 13.45 - 14.00 | C37: 4 | D37: 0 | E37: 2 | F37: 1 | G37: 0 | H37: 0 | I37: 0 | J37: 1 | K37: 0 | L37: 0 | M37: 13 | N37: 0 | O37: =SUM(C37:L37,N37) -> 8 | P37: =SUM(C37:N37) -> 21
B38: 14.00 - 14.15 | C38: 2 | D38: 0 | E38: 0 | F38: 3 | G38: 0 | H38: 0 | I38: 1 | J38: 1 | K38: 0 | L38: 0 | M38: 9 | N38: 0 | O38: =SUM(C38:L38,N38) -> 7 | P38: =SUM(C38:N38) -> 16
B39: 14.15 - 14.30 | C39: 1 | D39: 3 | E39: 0 | F39: 0 | G39: 0 | H39: 0 | I39: 0 | J39: 1 | K39: 1 | L39: 0 | M39: 15 | N39: 0 | O39: =SUM(C39:L39,N39) -> 6 | P39: =SUM(C39:N39) -> 21
B40: 14.30 - 14.45 | C40: 3 | D40: 1 | E40: 1 | F40: 1 | G40: 0 | H40: 0 | I40: 0 | J40: 0 | K40: 0 | L40: 0 | M40: 15 | N40: 0 | O40: =SUM(C40:L40,N40) -> 6 | P40: =SUM(C40:N40) -> 21
... B57: 18.45 - 19.00 | C57: 6 | D57: 3 | E57: 1 | F57: 1 | G57: 0 | H57: 0 | I57: 1 | J57: 0 | K57: 0 | L57: 0 | M57: 12 | N57: 0 | O57: =SUM(C57:L57,N57) -> 12 | P57: =SUM(C57:N57) -> 24
B58: Totals | C58: =SUM(C10:C57) -> 90 | D58: =SUM(D10:D57) -> 30 | E58: =SUM(E10:E57) -> 41 | F58: =SUM(F10:F57) -> 84 | G58: =SUM(G10:G57) -> 0 | H58: =SUM(H10:H57) -> 0 | I58: =SUM(I10:I57) -> 14 | J58: =SUM(J10:J57) -> 9 | ... P58: =SUM(P10:P57) -> 787
...

Sheet 18.10 KANONI-MADDU-24h
B1: Consultancy services for Preparation of Expressway Development Master Plan (EDMP) for Uganda
B2: MANUAL CLASSIFIED COUNT (MCC)
B3: ROAD NAME: | C3: ='17.10 KANONI-MADDU'!C3:G3 -> KANONI-MADDU ROAD
C5: Date | D5: ='18.10 MADDU-KANONI-24h'!D5 -> 18.10.2019 | F5: Location | G5: ='18.10 MADDU-KANONI-24h'!G5:H5 -> KANONI | J5: Surveyor | K5: ZALWANGO S
C6: Dir. From | D6: KANONI | F6: Dir. To | G6: MADDU | J6: Supervisor | K6: ='18.10 MADDU-KANONI-24h'!K6:L6 -> FELIX OLOYA
B8: Time / Veh Type | R8: SUMMARY TRAFFIC VOLUMES
C9: 1. Car | D9: 2. Station Wagon | E9: 3. Pickups | F9: 4. Minibus, matatu | G9: 5. Medium bus | H9: 6. Large Bus | I9: 7. Light Truck | J9: 8. Medium Truck | K9: 9. Heavy truck | L9: 10. Truck Trailer | M9: 11. Motor cycles | N9: 12. Tractors | O9: Total Excl M/Cycles | P9: Total All | R9: Time | S9: 1. Car | T9: 2. Station Wagon | U9: 3. Pickups | V9: 4. Minibus, matatu | W9: 5. Medium bus | X9: 6. Large Bus | Y9: 7. Light Truck | Z9: 8. Medium Truck | AA9: 9. Heavy truck | AB9: 10. Truck Trailer | AC9: 11. Motorcycles | AD9: 12. Tractors, Graders | AE9: Total Excl M/ Cycles | AF9: Total All
B10: 07.00 - 07.15 | C10: 0 | D10: 0 | E10: 0 | F10: 1 | G10: 0 | H10: 0 | I10: 0 | J10: 0 | K10: 0 | L10: 0 | M10: 3 | N10: 0 | O10: =SUM(C10:L10,N10) -> 1 | P10: =SUM(C10:N10) -> 4 | R10: 0700-0800 | S10: =SUM(C10:C13) -> 2 | T10: =SUM(D10:D13) -> 4 | U10: =SUM(E10:E13) -> 0 | V10: =SUM(F10:F13) -> 2 | W10: =SUM(G10:G13) -> 1 | X10: =SUM(H10:H13) -> 0 | Y10: =SUM(I10:I13) -> 4 | Z10: =SUM(J10:J13) -> 1 | ... AF10: =SUM(P10:P13) -> 43
B11: 07.15 - 07.30 | C11: 0 | D11: 0 | E11: 0 | F11: 0 | G11: 0 | H11: 0 | I11: 1 | J11: 0 | K11: 0 | L11: 0 | M11: 10 | N11: 0 | O11: =SUM(C11:L11,N11) -> 1 | P11: =SUM(C11:N11) -> 11 | R11: 0800-0900 | S11: =SUM(C14:C17) -> 11 | T11: =SUM(D14:D17) -> 0 | U11: =SUM(E14:E17) -> 2 | V11: =SUM(F14:F17) -> 5 | W11: =SUM(G14:G17) -> 0 | X11: =SUM(H14:H17) -> 0 | Y11: =SUM(I14:I17) -> 5 | Z11: =SUM(J14:J17) -> 1 | ... AF11: =SUM(P14:P17) -> 59
B12: 07.30 - 07.45 | C12: 1 | D12: 2 | E12: 0 | F12: 1 | G12: 1 | H12: 0 | I12: 0 | J12: 1 | K12: 0 | L12: 0 | M12: 10 | N12: 0 | O12: =SUM(C12:L12,N12) -> 6 | P12: =SUM(C12:N12) -> 16 | R12: 0900-1000 | S12: =SUM(C18:C21) -> 11 | T12: =SUM(D18:D21) -> 2 | U12: =SUM(E18:E21) -> 2 | V12: =SUM(F18:F21) -> 7 | W12: =SUM(G18:G21) -> 0 | X12: =SUM(H18:H21) -> 0 | Y12: =SUM(I18:I21) -> 6 | Z12: =SUM(J18:J21) -> 1 | ... AF12: =SUM(P18:P21) -> 63
B13: 07.45 - 08.00 | C13: 1 | D13: 2 | E13: 0 | F13: 0 | G13: 0 | H13: 0 | I13: 3 | J13: 0 | K13: 0 | L13: 0 | M13: 6 | N13: 0 | O13: =SUM(C13:L13,N13) -> 6 | P13: =SUM(C13:N13) -> 12 | R13: 1000-1100 | S13: =SUM(C22:C25) -> 8 | T13: =SUM(D22:D25) -> 3 | U13: =SUM(E22:E25) -> 5 | V13: =SUM(F22:F25) -> 5 | W13: =SUM(G22:G25) -> 0 | X13: =SUM(H22:H25) -> 0 | Y13: =SUM(I22:I25) -> 1 | Z13: =SUM(J22:J25) -> 2 | ... AF13: =SUM(P22:P25) -> 48
B14: 08.00 - 08.15 | C14: 3 | D14: 0 | E14: 1 | F14: 1 | G14: 0 | H14: 0 | I14: 1 | J14: 0 | K14: 0 | L14: 0 | M14: 5 | N14: 0 | O14: =SUM(C14:L14,N14) -> 6 | P14: =SUM(C14:N14) -> 11 | R14: 1100-1200 | S14: =SUM(C26:C29) -> 4 | T14: =SUM(D26:D29) -> 4 | U14: =SUM(E26:E29) -> 0 | V14: =SUM(F26:F29) -> 6 | W14: =SUM(G26:G29) -> 0 | X14: =SUM(H26:H29) -> 0 | Y14: =SUM(I26:I29) -> 1 | Z14: =SUM(J26:J29) -> 1 | ... AF14: =SUM(P26:P29) -> 63
B15: 08.15 - 08.30 | C15: 1 | D15: 0 | E15: 1 | F15: 0 | G15: 0 | H15: 0 | I15: 1 | J15: 1 | K15: 0 | L15: 0 | M15: 10 | N15: 0 | O15: =SUM(C15:L15,N15) -> 4 | P15: =SUM(C15:N15) -> 14 | R15: 1200-1300 | S15: =SUM(C30:C33) -> 8 | T15: =SUM(D30:D33) -> 1 | U15: =SUM(E30:E33) -> 2 | V15: =SUM(F30:F33) -> 7 | W15: =SUM(G30:G33) -> 0 | X15: =SUM(H30:H33) -> 0 | Y15: =SUM(I30:I33) -> 4 | Z15: =SUM(J30:J33) -> 0 | ... AF15: =SUM(P30:P33) -> 65
B16: 08.30 - 08.45 | C16: 5 | D16: 0 | E16: 0 | F16: 2 | G16: 0 | H16: 0 | I16: 1 | J16: 0 | K16: 0 | L16: 0 | M16: 9 | N16: 0 | O16: =SUM(C16:L16,N16) -> 8 | P16: =SUM(C16:N16) -> 17 | R16: 1300-1400 | S16: =SUM(C34:C37) -> 5 | T16: =SUM(D34:D37) -> 7 | U16: =SUM(E34:E37) -> 1 | V16: =SUM(F34:F37) -> 4 | W16: =SUM(G34:G37) -> 0 | X16: =SUM(H34:H37) -> 0 | Y16: =SUM(I34:I37) -> 2 | Z16: =SUM(J34:J37) -> 0 | ... AF16: =SUM(P34:P37) -> 64
B17: 08.45 - 9.00 | C17: 2 | D17: 0 | E17: 0 | F17: 2 | G17: 0 | H17: 0 | I17: 2 | J17: 0 | K17: 0 | L17: 0 | M17: 11 | N17: 0 | O17: =SUM(C17:L17,N17) -> 6 | P17: =SUM(C17:N17) -> 17 | R17: 1400-1500 | S17: =SUM(C38:C41) -> 10 | T17: =SUM(D38:D41) -> 2 | U17: =SUM(E38:E41) -> 3 | V17: =SUM(F38:F41) -> 5 | W17: =SUM(G38:G41) -> 0 | X17: =SUM(H38:H41) -> 0 | Y17: =SUM(I38:I41) -> 1 | Z17: =SUM(J38:J41) -> 1 | ... AF17: =SUM(P38:P41) -> 58
B18: 09.00 - 09.15 | C18: 5 | D18: 0 | E18: 1 | F18: 1 | G18: 0 | H18: 0 | I18: 1 | J18: 0 | K18: 0 | L18: 0 | M18: 5 | N18: 0 | O18: =SUM(C18:L18,N18) -> 8 | P18: =SUM(C18:N18) -> 13 | R18: 1500-1600 | S18: =SUM(C42:C45) -> 7 | T18: =SUM(D42:D45) -> 11 | U18: =SUM(E42:E45) -> 3 | V18: =SUM(F42:F45) -> 4 | W18: =SUM(G42:G45) -> 0 | X18: =SUM(H42:H45) -> 0 | Y18: =SUM(I42:I45) -> 2 | Z18: =SUM(J42:J45) -> 0 | ... AF18: =SUM(P42:P45) -> 72
B19: 09.15 - 09.30 | C19: 2 | D19: 0 | E19: 0 | F19: 2 | G19: 0 | H19: 0 | I19: 2 | J19: 1 | K19: 0 | L19: 0 | M19: 10 | N19: 0 | O19: =SUM(C19:L19,N19) -> 7 | P19: =SUM(C19:N19) -> 17 | R19: 1600-1700 | S19: =SUM(C46:C49) -> 3 | T19: =SUM(D46:D49) -> 5 | U19: =SUM(E46:E49) -> 1 | V19: =SUM(F46:F49) -> 12 | W19: =SUM(G46:G49) -> 0 | X19: =SUM(H46:H49) -> 0 | Y19: =SUM(I46:I49) -> 3 | Z19: =SUM(J46:J49) -> 1 | ... AF19: =SUM(P46:P49) -> 62
B20: 09.30 - 09.45 | C20: 2 | D20: 0 | E20: 1 | F20: 2 | G20: 0 | H20: 0 | I20: 0 | J20: 0 | K20: 0 | L20: 0 | M20: 5 | N20: 0 | O20: =SUM(C20:L20,N20) -> 5 | P20: =SUM(C20:N20) -> 10 | R20: 1700-1800 | S20: =SUM(C50:C53) -> 9 | T20: =SUM(D50:D53) -> 4 | U20: =SUM(E50:E53) -> 4 | V20: =SUM(F50:F53) -> 7 | W20: =SUM(G50:G53) -> 0 | X20: =SUM(H50:H53) -> 0 | Y20: =SUM(I50:I53) -> 2 | Z20: =SUM(J50:J53) -> 0 | ... AF20: =SUM(P50:P53) -> 81
B21: 09.45 - 10.00 | C21: 2 | D21: 2 | E21: 0 | F21: 2 | G21: 0 | H21: 0 | I21: 3 | J21: 0 | K21: 0 | L21: 0 | M21: 14 | N21: 0 | O21: =SUM(C21:L21,N21) -> 9 | P21: =SUM(C21:N21) -> 23 | R21: 1800-1900 | S21: =SUM(C54:C57) -> 8 | T21: =SUM(D54:D57) -> 9 | U21: =SUM(E54:E57) -> 3 | V21: =SUM(F54:F57) -> 7 | W21: =SUM(G54:G57) -> 0 | X21: =SUM(H54:H57) -> 0 | Y21: =SUM(I54:I57) -> 2 | Z21: =SUM(J54:J57) -> 0 | ... AF21: =SUM(P54:P57) -> 70
B22: 10.00 - 10.15 | C22: 1 | D22: 1 | E22: 3 | F22: 1 | G22: s | H22: 0 | I22: 0 | J22: 0 | K22: 0 | L22: 0 | M22: 5 | N22: 0 | O22: =SUM(C22:L22,N22) -> 6 | P22: =SUM(C22:N22) -> 11 | R22: 1900-2000 | S22: =SUM(C58:C61) -> 6 | T22: =SUM(D58:D61) -> 2 | U22: =SUM(E58:E61) -> 1 | V22: =SUM(F58:F61) -> 10 | W22: =SUM(G58:G61) -> 0 | X22: =SUM(H58:H61) -> 0 | Y22: =SUM(I58:I61) -> 1 | Z22: =SUM(J58:J61) -> 3 | ... AF22: =SUM(P58:P61) -> 68
B23: 10.15 - 10.30 | C23: 4 | D23: 0 | E23: 0 | F23: 2 | G23: 0 | H23: 0 | I23: 0 | J23: 2 | K23: 0 | L23: 0 | M23: 9 | N23: 0 | O23: =SUM(C23:L23,N23) -> 8 | P23: =SUM(C23:N23) -> 17 | R23: 2000-2100 | S23: =SUM(C62:C65) -> 3 | T23: =SUM(D62:D65) -> 0 | U23: =SUM(E62:E65) -> 4 | V23: =SUM(F62:F65) -> 6 | W23: =SUM(G62:G65) -> 0 | X23: =SUM(H62:H65) -> 0 | Y23: =SUM(I62:I65) -> 1 | Z23: =SUM(J62:J65) -> 1 | ... AF23: =SUM(P62:P65) -> 42
B24: 10.30 - 10.45 | C24: 1 | D24: 1 | E24: 0 | F24: 0 | G24: 0 | H24: 0 | I24: 1 | J24: 0 | K24: 0 | L24: 0 | M24: 2 | N24: 0 | O24: =SUM(C24:L24,N24) -> 3 | P24: =SUM(C24:N24) -> 5 | R24: 2100-2200 | S24: =SUM(C66:C69) -> 3 | T24: =SUM(D66:D69) -> 1 | U24: =SUM(E66:E69) -> 2 | V24: =SUM(F66:F69) -> 2 | W24: =SUM(G66:G69) -> 0 | X24: =SUM(H66:H69) -> 0 | Y24: =SUM(I66:I69) -> 0 | Z24: =SUM(J66:J69) -> 1 | ... AF24: =SUM(P66:P69) -> 20
B25: 10.45 - 11.00 | C25: 2 | D25: 1 | E25: 2 | F25: 2 | G25: 0 | H25: 0 | I25: 0 | J25: 0 | K25: 0 | L25: 0 | M25: 8 | N25: 0 | O25: =SUM(C25:L25,N25) -> 7 | P25: =SUM(C25:N25) -> 15 | R25: 2200-2300 | S25: =SUM(C70:C73) -> 2 | T25: =SUM(D70:D73) -> 0 | U25: =SUM(E70:E73) -> 1 | V25: =SUM(F70:F73) -> 4 | W25: =SUM(G70:G73) -> 0 | X25: =SUM(H70:H73) -> 0 | Y25: =SUM(I70:I73) -> 4 | Z25: =SUM(J70:J73) -> 1 | ... AF25: =SUM(P70:P73) -> 17
B26: 11.00 - 11.15 | C26: 1 | D26: 0 | E26: 0 | F26: 1 | G26: 0 | H26: 0 | I26: 1 | J26: 1 | K26: 0 | L26: 0 | M26: 8 | N26: 0 | O26: =SUM(C26:L26,N26) -> 4 | P26: =SUM(C26:N26) -> 12 | R26: 2300-0000 | S26: =SUM(C74:C77) -> 0 | T26: =SUM(D74:D77) -> 0 | U26: =SUM(E74:E77) -> 1 | V26: =SUM(F74:F77) -> 2 | W26: =SUM(G74:G77) -> 0 | X26: =SUM(H74:H77) -> 0 | Y26: =SUM(I74:I77) -> 0 | Z26: =SUM(J74:J77) -> 5 | ... AF26: =SUM(P74:P77) -> 13
B27: 11.15 - 11.30 | C27: 2 | D27: 1 | E27: 0 | F27: 0 | G27: 0 | H27: 0 | I27: 0 | J27: 0 | K27: 0 | L27: 0 | M27: 18 | N27: 0 | O27: =SUM(C27:L27,N27) -> 3 | P27: =SUM(C27:N27) -> 21 | R27: 0000-0100 | S27: =SUM(C78:C81) -> 5 | T27: =SUM(D78:D81) -> 0 | U27: =SUM(E78:E81) -> 0 | V27: =SUM(F78:F81) -> 2 | W27: =SUM(G78:G81) -> 0 | X27: =SUM(H78:H81) -> 0 | Y27: =SUM(I78:I81) -> 1 | Z27: =SUM(J78:J81) -> 0 | ... AF27: =SUM(P78:P81) -> 10
B28: 11.30 - 11.45 | C28: 1 | D28: 0 | E28: 0 | F28: 4 | G28: 0 | H28: 0 | I28: 0 | J28: 0 | K28: 0 | L28: 0 | M28: 7 | N28: 0 | O28: =SUM(C28:L28,N28) -> 5 | P28: =SUM(C28:N28) -> 12 | R28: 0100-0200 | S28: =SUM(C82:C85) -> 0 | T28: =SUM(D82:D85) -> 0 | U28: =SUM(E82:E85) -> 0 | V28: =SUM(F82:F85) -> 0 | W28: =SUM(G82:G85) -> 0 | X28: =SUM(H82:H85) -> 0 | Y28: =SUM(I82:I85) -> 1 | Z28: =SUM(J82:J85) -> 0 | ... AF28: =SUM(P82:P85) -> 2
B29: 11.45 - 12.00 | C29: 0 | D29: 3 | E29: 0 | F29: 1 | G29: 0 | H29: 0 | I29: 0 | J29: 0 | K29: 0 | L29: 0 | M29: 14 | N29: 0 | O29: =SUM(C29:L29,N29) -> 4 | P29: =SUM(C29:N29) -> 18 | R29: 0200-0300 | S29: =SUM(C86:C89) -> 0 | T29: =SUM(D86:D89) -> 0 | U29: =SUM(E86:E89) -> 0 | V29: =SUM(F86:F89) -> 0 | W29: =SUM(G86:G89) -> 0 | X29: =SUM(H86:H89) -> 0 | Y29: =SUM(I86:I89) -> 1 | Z29: =SUM(J86:J89) -> 4 | ... AF29: =SUM(P86:P89) -> 5
B30: 12.00 - 12.15 | C30: 4 | D30: 0 | E30: 0 | F30: 4 | G30: 0 | H30: 0 | I30: 0 | J30: 0 | K30: 0 | L30: 0 | M30: 17 | N30: 0 | O30: =SUM(C30:L30,N30) -> 8 | P30: =SUM(C30:N30) -> 25 | R30: 0300-0400 | S30: =SUM(C90:C93) -> 1 | T30: =SUM(D90:D93) -> 1 | U30: =SUM(E90:E93) -> 0 | V30: =SUM(F90:F93) -> 0 | W30: =SUM(G90:G93) -> 0 | X30: =SUM(H90:H93) -> 0 | Y30: =SUM(I90:I93) -> 2 | Z30: =SUM(J90:J93) -> 2 | ... AF30: =SUM(P90:P93) -> 6
B31: 12.15 - 12.30 | C31: 0 | D31: 1 | E31: 2 | F31: 1 | G31: 0 | H31: 0 | I31: 3 | J31: 0 | K31: 0 | L31: 0 | M31: 8 | N31: 0 | O31: =SUM(C31:L31,N31) -> 7 | P31: =SUM(C31:N31) -> 15 | R31: 0400-0500 | S31: =SUM(C94:C97) -> 2 | T31: =SUM(D94:D97) -> 0 | U31: =SUM(E94:E97) -> 0 | V31: =SUM(F94:F97) -> 0 | W31: =SUM(G94:G97) -> 0 | X31: =SUM(H94:H97) -> 0 | Y31: =SUM(I94:I97) -> 1 | Z31: =SUM(J94:J97) -> 1 | ... AF31: =SUM(P94:P97) -> 5
B32: 12.30 - 12.45 | C32: 0 | D32: 0 | E32: 0 | F32: 2 | G32: 0 | H32: 0 | I32: 0 | J32: 0 | K32: 0 | L32: 0 | M32: 12 | N32: 0 | O32: =SUM(C32:L32,N32) -> 2 | P32: =SUM(C32:N32) -> 14 | R32: 0500-0600 | S32: =SUM(C98:C101) -> 0 | T32: =SUM(D98:D101) -> 0 | U32: =SUM(E98:E101) -> 0 | V32: =SUM(F98:F101) -> 0 | W32: =SUM(G98:G101) -> 0 | X32: =SUM(H98:H101) -> 0 | Y32: =SUM(I98:I101) -> 0 | Z32: =SUM(J98:J101) -> 1 | ... AF32: =SUM(P98:P101) -> 1
B33: 12.45 - 13.00 | C33: 4 | D33: 0 | E33: 0 | F33: 0 | G33: 0 | H33: 0 | I33: 1 | J33: 0 | K33: 0 | L33: 0 | M33: 6 | N33: 0 | O33: =SUM(C33:L33,N33) -> 5 | P33: =SUM(C33:N33) -> 11 | R33: 0600-0700 | S33: =SUM(C102:C105) -> 1 | T33: =SUM(D102:D105) -> 0 | U33: =SUM(E102:E105) -> 0 | V33: =SUM(F102:F105) -> 0 | W33: =SUM(G102:G105) -> 0 | X33: =SUM(H102:H105) -> 0 | Y33: =SUM(I102:I105) -> 0 | Z33: =SUM(J102:J105) -> 2 | ... AF33: =SUM(P102:P105) -> 6
B34: 13.00 - 13.15 | C34: 0 | D34: 3 | E34: 0 | F34: 1 | G34: 0 | H34: 0 | I34: 0 | J34: 0 | K34: 0 | L34: 0 | M34: 19 | N34: 0 | O34: =SUM(C34:L34,N34) -> 4 | P34: =SUM(C34:N34) -> 23 | R34: AM Peak Hr | S34: =MAX(S10:S12) -> 11 | T34: =MAX(T10:T12) -> 4 | U34: =MAX(U10:U12) -> 2 | V34: =MAX(V10:V12) -> 7 | W34: =MAX(W10:W12) -> 1 | X34: =MAX(X10:X12) -> 0 | Y34: =MAX(Y10:Y12) -> 6 | Z34: =MAX(Z10:Z12) -> 1 | ... AF34: =MAX(AF10:AF12) -> 63
B35: 13.15 - 13.30 | C35: 0 | D35: 1 | E35: 1 | F35: 1 | G35: 0 | H35: 0 | I35: 1 | J35: 0 | K35: 0 | L35: 0 | M35: 6 | N35: 0 | O35: =SUM(C35:L35,N35) -> 4 | P35: =SUM(C35:N35) -> 10 | R35: IP Peak Hr | S35: =MAX(S13:S18) -> 10 | T35: =MAX(T13:T18) -> 11 | U35: =MAX(U13:U18) -> 5 | V35: =MAX(V13:V18) -> 7 | W35: =MAX(W13:W18) -> 0 | X35: =MAX(X13:X18) -> 0 | Y35: =MAX(Y13:Y18) -> 4 | Z35: =MAX(Z13:Z18) -> 2 | ... AF35: =MAX(AF13:AF18) -> 72
B36: 13.30 - 13.45 | C36: 4 | D36: 1 | E36: 0 | F36: 1 | G36: 0 | H36: 0 | I36: 1 | J36: 0 | K36: 0 | L36: 0 | M36: 12 | N36: 0 | O36: =SUM(C36:L36,N36) -> 7 | P36: =SUM(C36:N36) -> 19 | R36: PM Peak Hr | S36: =MAX(S19:S21) -> 9 | T36: =MAX(T19:T21) -> 9 | U36: =MAX(U19:U21) -> 4 | V36: =MAX(V19:V21) -> 12 | W36: =MAX(W19:W21) -> 0 | X36: =MAX(X19:X21) -> 0 | Y36: =MAX(Y19:Y21) -> 3 | Z36: =MAX(Z19:Z21) -> 1 | ... AF36: =MAX(AF19:AF21) -> 81
B37: 13.45 - 14.00 | C37: 1 | D37: 2 | E37: 0 | F37: 1 | G37: 0 | H37: 0 | I37: 0 | J37: 0 | K37: 1 | L37: 0 | M37: 7 | N37: 0 | O37: =SUM(C37:L37,N37) -> 5 | P37: =SUM(C37:N37) -> 12 | R37: AM Period | S37: =SUM(S10:S12) -> 24 | T37: =SUM(T10:T12) -> 6 | U37: =SUM(U10:U12) -> 4 | V37: =SUM(V10:V12) -> 14 | W37: =SUM(W10:W12) -> 1 | X37: =SUM(X10:X12) -> 0 | Y37: =SUM(Y10:Y12) -> 15 | Z37: =SUM(Z10:Z12) -> 3 | ... AF37: =SUM(AF10:AF12) -> 165
B38: 14.00 - 14.15 | C38: 3 | D38: 1 | E38: 0 | F38: 1 | G38: 0 | H38: 0 | I38: 0 | J38: 1 | K38: 0 | L38: 0 | M38: 5 | N38: 0 | O38: =SUM(C38:L38,N38) -> 6 | P38: =SUM(C38:N38) -> 11 | R38: IP Period | S38: =SUM(S13:S18) -> 42 | T38: =SUM(T13:T18) -> 28 | U38: =SUM(U13:U18) -> 14 | V38: =SUM(V13:V18) -> 31 | W38: =SUM(W13:W18) -> 0 | X38: =SUM(X13:X18) -> 0 | Y38: =SUM(Y13:Y18) -> 11 | Z38: =SUM(Z13:Z18) -> 4 | ... AF38: =SUM(AF13:AF18) -> 370
B39: 14.15 - 14.30 | C39: 2 | D39: 0 | E39: 3 | F39: 0 | G39: 0 | H39: 0 | I39: 0 | J39: 0 | K39: 0 | L39: 0 | M39: 11 | N39: 0 | O39: =SUM(C39:L39,N39) -> 5 | P39: =SUM(C39:N39) -> 16 | R39: PM Period | S39: =SUM(S19:S21) -> 20 | T39: =SUM(T19:T21) -> 18 | U39: =SUM(U19:U21) -> 8 | V39: =SUM(V19:V21) -> 26 | W39: =SUM(W19:W21) -> 0 | X39: =SUM(X19:X21) -> 0 | Y39: =SUM(Y19:Y21) -> 7 | Z39: =SUM(Z19:Z21) -> 1 | ... AF39: =SUM(AF19:AF21) -> 213
B40: 14.30 - 14.45 | C40: 2 | D40: 0 | E40: 0 | F40: 2 | G40: 0 | H40: 0 | I40: 0 | J40: 0 | K40: 1 | L40: 0 | M40: 5 | N40: 0 | O40: =SUM(C40:L40,N40) -> 5 | P40: =SUM(C40:N40) -> 10 | R40: 12 Hours | S40: =SUM(S10:S21) -> 86 | T40: =SUM(T10:T21) -> 52 | U40: =SUM(U10:U21) -> 26 | V40: =SUM(V10:V21) -> 71 | W40: =SUM(W10:W21) -> 1 | X40: =SUM(X10:X21) -> 0 | Y40: =SUM(Y10:Y21) -> 33 | Z40: =SUM(Z10:Z21) -> 8 | ... AF40: =SUM(AF10:AF21) -> 748
B41: 14.45 - 15.00 | C41: 3 | D41: 1 | E41: 0 | F41: 2 | G41: 0 | H41: 0 | I41: 1 | J41: 0 | K41: 1 | L41: 0 | M41: 13 | N41: 0 | O41: =SUM(C41:L41,N41) -> 8 | P41: =SUM(C41:N41) -> 21 | R41: 24 Hrs/ADT | S41: =SUM(S10:S33) -> 109 | T41: =SUM(T10:T33) -> 56 | U41: =SUM(U10:U33) -> 35 | V41: =SUM(V10:V33) -> 97 | W41: =SUM(W10:W33) -> 1 | X41: =SUM(X10:X33) -> 0 | Y41: =SUM(Y10:Y33) -> 45 | Z41: =SUM(Z10:Z33) -> 29 | ... AF41: =SUM(AF10:AF33) -> 943
B42: 15.00 - 15.15 | C42: 2 | D42: 5 | E42: 2 | F42: 1 | G42: 0 | H42: 0 | I42: 1 | J42: 0 | K42: 1 | L42: 0 | M42: 10 | N42: 0 | O42: =SUM(C42:L42,N42) -> 12 | P42: =SUM(C42:N42) -> 22 | R42: NEF | S42: =S41/S40 -> 1.2674419 | T42: =T41/T40 -> 1.0769231 | U42: =U41/U40 -> 1.3461538 | V42: =V41/V40 -> 1.3661972 | W42: =W41/W40 -> 1 | X42: =X41/X40 -> #DIV/0! | Y42: =Y41/Y40 -> 1.3636364 | Z42: =Z41/Z40 -> 3.625 | ... AF42: =AF41/AF40 -> 1.2606952
...

Sheet 18.10 MADDU-KANONI-24h
B1: Consultancy services for Preparation of Expressway Development Master Plan (EDMP) for Uganda
B2: MANUAL CLASSIFIED COUNT (MCC)
B3: ROAD NAME: | C3: ='17.10 KANONI-MADDU'!C3:G3 -> KANONI-MADDU ROAD
C5: Date | D5: 18.10.2019 | F5: Location | G5: ='22.10 MADDU-KANONI'!G5:H5 -> KANONI | J5: Surveyor | K5: SSEMPIJJA FRED
C6: Dir. From | D6: MADDU | F6: Dir. To | G6: KANONI | J6: Supervisor | K6: ='22.10 MADDU-KANONI'!K6:L6 -> FELIX OLOYA
B8: Time / Veh Type | R8: SUMMARY TRAFFIC VOLUMES
C9: 1. Car | D9: 2. Station Wagon | E9: 3. Pickups | F9: 4. Minibus, matatu | G9: 5. Medium bus | H9: 6. Large Bus | I9: 7. Light Truck | J9: 8. Medium Truck | K9: 9. Heavy truck | L9: 10. Truck Trailer | M9: 11. Motor cycles | N9: 12. Tractors | O9: Total Excl M/Cycles | P9: Total All | R9: Time | S9: 1. Car | T9: 2. Station Wagon | U9: 3. Pickups | V9: 4. Minibus, matatu | W9: 5. Medium bus | X9: 6. Large Bus | Y9: 7. Light Truck | Z9: 8. Medium Truck | AA9: 9. Heavy truck | AB9: 10. Truck Trailer | AC9: 11. Motorcycles | AD9: 12. Tractors, Graders | AE9: Total Excl M/ Cycles | AF9: Total All
B10: 07.00 - 07.15 | C10: 3 | D10: 2 | E10: 1 | F10: 4 | G10: 0 | H10: 0 | I10: 0 | J10: 0 | K10: 0 | L10: 0 | M10: 5 | N10: 0 | O10: =SUM(C10:L10,N10) -> 10 | P10: =SUM(C10:N10) -> 15 | R10: 0700-0800 | S10: =SUM(C10:C13) -> 7 | T10: =SUM(D10:D13) -> 3 | U10: =SUM(E10:E13) -> 1 | V10: =SUM(F10:F13) -> 10 | W10: =SUM(G10:G13) -> 0 | X10: =SUM(H10:H13) -> 0 | Y10: =SUM(I10:I13) -> 0 | Z10: =SUM(J10:J13) -> 0 | ... AF10: =SUM(P10:P13) -> 40
B11: 07.15 - 07.30 | C11: 2 | D11: 1 | E11: 0 | F11: 1 | G11: 0 | H11: 0 | I11: 0 | J11: 0 | K11: 0 | L11: 0 | M11: 7 | N11: 0 | O11: =SUM(C11:L11,N11) -> 4 | P11: =SUM(C11:N11) -> 11 | R11: 0800-0900 | S11: =SUM(C14:C17) -> 8 | T11: =SUM(D14:D17) -> 1 | U11: =SUM(E14:E17) -> 1 | V11: =SUM(F14:F17) -> 9 | W11: =SUM(G14:G17) -> 0 | X11: =SUM(H14:H17) -> 0 | Y11: =SUM(I14:I17) -> 2 | Z11: =SUM(J14:J17) -> 0 | ... AF11: =SUM(P14:P17) -> 61
B12: 07.30 - 07.45 | C12: 1 | D12: 0 | E12: 0 | F12: 5 | G12: 0 | H12: 0 | I12: 0 | J12: 0 | K12: 0 | L12: 0 | M12: 4 | N12: 0 | O12: =SUM(C12:L12,N12) -> 6 | P12: =SUM(C12:N12) -> 10 | R12: 0900-1000 | S12: =SUM(C18:C21) -> 6 | T12: =SUM(D18:D21) -> 0 | U12: =SUM(E18:E21) -> 3 | V12: =SUM(F18:F21) -> 13 | W12: =SUM(G18:G21) -> 0 | X12: =SUM(H18:H21) -> 0 | Y12: =SUM(I18:I21) -> 0 | Z12: =SUM(J18:J21) -> 1 | ... AF12: =SUM(P18:P21) -> 49
B13: 07.45 - 08.00 | C13: 1 | D13: 0 | E13: 0 | F13: 0 | G13: 0 | H13: 0 | I13: 0 | J13: 0 | K13: 0 | L13: 0 | M13: 3 | N13: 0 | O13: =SUM(C13:L13,N13) -> 1 | P13: =SUM(C13:N13) -> 4 | R13: 1000-1100 | S13: =SUM(C22:C25) -> 4 | T13: =SUM(D22:D25) -> 2 | U13: =SUM(E22:E25) -> 5 | V13: =SUM(F22:F25) -> 7 | W13: =SUM(G22:G25) -> 0 | X13: =SUM(H22:H25) -> 0 | Y13: =SUM(I22:I25) -> 2 | Z13: =SUM(J22:J25) -> 1 | ... AF13: =SUM(P22:P25) -> 56
B14: 08.00 - 08.15 | C14: 1 | D14: 0 | E14: 0 | F14: 2 | G14: 0 | H14: 0 | I14: 0 | J14: 0 | K14: 0 | L14: 0 | M14: 8 | N14: 0 | O14: =SUM(C14:L14,N14) -> 3 | P14: =SUM(C14:N14) -> 11 | R14: 1100-1200 | S14: =SUM(C26:C29) -> 7 | T14: =SUM(D26:D29) -> 4 | U14: =SUM(E26:E29) -> 1 | V14: =SUM(F26:F29) -> 5 | W14: =SUM(G26:G29) -> 0 | X14: =SUM(H26:H29) -> 0 | Y14: =SUM(I26:I29) -> 5 | Z14: =SUM(J26:J29) -> 0 | ... AF14: =SUM(P26:P29) -> 59
B15: 08.15 - 08.30 | C15: 2 | D15: 1 | E15: 0 | F15: 3 | G15: 0 | H15: 0 | I15: 1 | J15: 0 | K15: 0 | L15: 0 | M15: 10 | N15: 0 | O15: =SUM(C15:L15,N15) -> 7 | P15: =SUM(C15:N15) -> 17 | R15: 1200-1300 | S15: =SUM(C30:C33) -> 6 | T15: =SUM(D30:D33) -> 1 | U15: =SUM(E30:E33) -> 4 | V15: =SUM(F30:F33) -> 5 | W15: =SUM(G30:G33) -> 0 | X15: =SUM(H30:H33) -> 0 | Y15: =SUM(I30:I33) -> 0 | Z15: =SUM(J30:J33) -> 0 | ... AF15: =SUM(P30:P33) -> 56
B16: 08.30 - 08.45 | C16: 3 | D16: 0 | E16: 1 | F16: 2 | G16: 0 | H16: 0 | I16: 0 | J16: 0 | K16: 0 | L16: 0 | M16: 8 | N16: 0 | O16: =SUM(C16:L16,N16) -> 6 | P16: =SUM(C16:N16) -> 14 | R16: 1300-1400 | S16: =SUM(C34:C37) -> 5 | T16: =SUM(D34:D37) -> 4 | U16: =SUM(E34:E37) -> 1 | V16: =SUM(F34:F37) -> 2 | W16: =SUM(G34:G37) -> 0 | X16: =SUM(H34:H37) -> 0 | Y16: =SUM(I34:I37) -> 2 | Z16: =SUM(J34:J37) -> 2 | ... AF16: =SUM(P34:P37) -> 65
B17: 08.45 - 9.00 | C17: 2 | D17: 0 | E17: 0 | F17: 2 | G17: 0 | H17: 0 | I17: 1 | J17: 0 | K17: 0 | L17: 0 | M17: 14 | N17: 0 | O17: =SUM(C17:L17,N17) -> 5 | P17: =SUM(C17:N17) -> 19 | R17: 1400-1500 | S17: =SUM(C38:C41) -> 13 | T17: =SUM(D38:D41) -> 1 | U17: =SUM(E38:E41) -> 4 | V17: =SUM(F38:F41) -> 5 | W17: =SUM(G38:G41) -> 0 | X17: =SUM(H38:H41) -> 0 | Y17: =SUM(I38:I41) -> 5 | Z17: =SUM(J38:J41) -> 0 | ... AF17: =SUM(P38:P41) -> 64
B18: 09.00 - 09.15 | C18: 1 | D18: 0 | E18: 0 | F18: 2 | G18: 0 | H18: 0 | I18: 0 | J18: 0 | K18: 0 | L18: 0 | M18: 7 | N18: 0 | O18: =SUM(C18:L18,N18) -> 3 | P18: =SUM(C18:N18) -> 10 | R18: 1500-1600 | S18: =SUM(C42:C45) -> 9 | T18: =SUM(D42:D45) -> 3 | U18: =SUM(E42:E45) -> 2 | V18: =SUM(F42:F45) -> 4 | W18: =SUM(G42:G45) -> 0 | X18: =SUM(H42:H45) -> 0 | Y18: =SUM(I42:I45) -> 3 | Z18: =SUM(J42:J45) -> 0 | ... AF18: =SUM(P42:P45) -> 54
B19: 09.15 - 09.30 | C19: 2 | D19: 0 | E19: 2 | F19: 2 | G19: 0 | H19: 0 | I19: 0 | J19: 0 | K19: 0 | L19: 0 | M19: 3 | N19: 0 | O19: =SUM(C19:L19,N19) -> 6 | P19: =SUM(C19:N19) -> 9 | R19: 1600-1700 | S19: =SUM(C46:C49) -> 12 | T19: =SUM(D46:D49) -> 2 | U19: =SUM(E46:E49) -> 1 | V19: =SUM(F46:F49) -> 6 | W19: =SUM(G46:G49) -> 0 | X19: =SUM(H46:H49) -> 0 | Y19: =SUM(I46:I49) -> 3 | Z19: =SUM(J46:J49) -> 1 | ... AF19: =SUM(P46:P49) -> 51
B20: 09.30 - 09.45 | C20: 1 | D20: 0 | E20: 0 | F20: 5 | G20: 0 | H20: 0 | I20: 0 | J20: 1 | K20: 0 | L20: 0 | M20: 7 | N20: 0 | O20: =SUM(C20:L20,N20) -> 7 | P20: =SUM(C20:N20) -> 14 | R20: 1700-1800 | S20: =SUM(C50:C53) -> 7 | T20: =SUM(D50:D53) -> 6 | U20: =SUM(E50:E53) -> 1 | V20: =SUM(F50:F53) -> 8 | W20: =SUM(G50:G53) -> 0 | X20: =SUM(H50:H53) -> 0 | Y20: =SUM(I50:I53) -> 3 | Z20: =SUM(J50:J53) -> 0 | ... AF20: =SUM(P50:P53) -> 74
B21: 09.45 - 10.00 | C21: 2 | D21: 0 | E21: 1 | F21: 4 | G21: 0 | H21: 0 | I21: 0 | J21: 0 | K21: 0 | L21: 0 | M21: 9 | N21: 0 | O21: =SUM(C21:L21,N21) -> 7 | P21: =SUM(C21:N21) -> 16 | R21: 1800-1900 | S21: =SUM(C54:C57) -> 11 | T21: =SUM(D54:D57) -> 4 | U21: =SUM(E54:E57) -> 11 | V21: =SUM(F54:F57) -> 10 | W21: =SUM(G54:G57) -> 0 | X21: =SUM(H54:H57) -> 0 | Y21: =SUM(I54:I57) -> 1 | Z21: =SUM(J54:J57) -> 1 | ... AF21: =SUM(P54:P57) -> 82
B22: 10.00 - 10.15 | C22: 1 | D22: 1 | E22: 0 | F22: 3 | G22: 0 | H22: 0 | I22: 1 | J22: 1 | K22: 0 | L22: 0 | M22: 5 | N22: 0 | O22: =SUM(C22:L22,N22) -> 7 | P22: =SUM(C22:N22) -> 12 | R22: 1900-2000 | S22: =SUM(C58:C61) -> 13 | T22: =SUM(D58:D61) -> 12 | U22: =SUM(E58:E61) -> 4 | V22: =SUM(F58:F61) -> 3 | W22: =SUM(G58:G61) -> 0 | X22: =SUM(H58:H61) -> 0 | Y22: =SUM(I58:I61) -> 5 | Z22: =SUM(J58:J61) -> 5 | ... AF22: =SUM(P58:P61) -> 86
B23: 10.15 - 10.30 | C23: 2 | D23: 0 | E23: 1 | F23: 3 | G23: 0 | H23: 0 | I23: 1 | J23: 0 | K23: 0 | L23: 0 | M23: 13 | N23: 0 | O23: =SUM(C23:L23,N23) -> 7 | P23: =SUM(C23:N23) -> 20 | R23: 2000-2100 | S23: =SUM(C62:C65) -> 6 | T23: =SUM(D62:D65) -> 0 | U23: =SUM(E62:E65) -> 1 | V23: =SUM(F62:F65) -> 2 | W23: =SUM(G62:G65) -> 0 | X23: =SUM(H62:H65) -> 0 | Y23: =SUM(I62:I65) -> 3 | Z23: =SUM(J62:J65) -> 6 | ... AF23: =SUM(P62:P65) -> 36
B24: 10.30 - 10.45 | C24: 1 | D24: 1 | E24: 1 | F24: 0 | G24: 0 | H24: 0 | I24: 0 | J24: 0 | K24: 0 | L24: 0 | M24: 6 | N24: 0 | O24: =SUM(C24:L24,N24) -> 3 | P24: =SUM(C24:N24) -> 9 | R24: 2100-2200 | S24: =SUM(C66:C69) -> 4 | T24: =SUM(D66:D69) -> 2 | U24: =SUM(E66:E69) -> 3 | V24: =SUM(F66:F69) -> 3 | W24: =SUM(G66:G69) -> 0 | X24: =SUM(H66:H69) -> 0 | Y24: =SUM(I66:I69) -> 2 | Z24: =SUM(J66:J69) -> 3 | ... AF24: =SUM(P66:P69) -> 23
B25: 10.45 - 11.00 | C25: 0 | D25: 0 | E25: 3 | F25: 1 | G25: 0 | H25: 0 | I25: 0 | J25: 0 | K25: 0 | L25: 0 | M25: 11 | N25: 0 | O25: =SUM(C25:L25,N25) -> 4 | P25: =SUM(C25:N25) -> 15 | R25: 2200-2300 | S25: =SUM(C70:C73) -> 3 | T25: =SUM(D70:D73) -> 2 | U25: =SUM(E70:E73) -> 0 | V25: =SUM(F70:F73) -> 0 | W25: =SUM(G70:G73) -> 0 | X25: =SUM(H70:H73) -> 0 | Y25: =SUM(I70:I73) -> 2 | Z25: =SUM(J70:J73) -> 3 | ... AF25: =SUM(P70:P73) -> 11
B26: 11.00 - 11.15 | C26: 1 | D26: 1 | E26: 0 | F26: 0 | G26: 0 | H26: 0 | I26: 2 | J26: 0 | K26: 0 | L26: 0 | M26: 13 | N26: 0 | O26: =SUM(C26:L26,N26) -> 4 | P26: =SUM(C26:N26) -> 17 | R26: 2300-0000 | S26: =SUM(C74:C77) -> 1 | T26: =SUM(D74:D77) -> 2 | U26: =SUM(E74:E77) -> 0 | V26: =SUM(F74:F77) -> 0 | W26: =SUM(G74:G77) -> 0 | X26: =SUM(H74:H77) -> 0 | Y26: =SUM(I74:I77) -> 3 | Z26: =SUM(J74:J77) -> 5 | ... AF26: =SUM(P74:P77) -> 13
B27: 11.15 - 11.30 | C27: 2 | D27: 0 | E27: 0 | F27: 3 | G27: 0 | H27: 0 | I27: 0 | J27: 0 | K27: 0 | L27: 0 | M27: 14 | N27: 0 | O27: =SUM(C27:L27,N27) -> 5 | P27: =SUM(C27:N27) -> 19 | R27: 0000-0100 | S27: =SUM(C78:C81) -> 0 | T27: =SUM(D78:D81) -> 1 | U27: =SUM(E78:E81) -> 0 | V27: =SUM(F78:F81) -> 0 | W27: =SUM(G78:G81) -> 0 | X27: =SUM(H78:H81) -> 0 | Y27: =SUM(I78:I81) -> 1 | Z27: =SUM(J78:J81) -> 3 | ... AF27: =SUM(P78:P81) -> 9
B28: 11.30 - 11.45 | C28: 4 | D28: 1 | E28: 0 | F28: 0 | G28: 0 | H28: 0 | I28: 1 | J28: 0 | K28: 0 | L28: 0 | M28: 5 | N28: 0 | O28: =SUM(C28:L28,N28) -> 6 | P28: =SUM(C28:N28) -> 11 | R28: 0100-0200 | S28: =SUM(C82:C85) -> 0 | T28: =SUM(D82:D85) -> 0 | U28: =SUM(E82:E85) -> 0 | V28: =SUM(F82:F85) -> 0 | W28: =SUM(G82:G85) -> 0 | X28: =SUM(H82:H85) -> 0 | Y28: =SUM(I82:I85) -> 1 | Z28: =SUM(J82:J85) -> 2 | ... AF28: =SUM(P82:P85) -> 3
B29: 11.45 - 12.00 | C29: 0 | D29: 2 | E29: 1 | F29: 2 | G29: 0 | H29: 0 | I29: 2 | J29: 0 | K29: 0 | L29: 0 | M29: 5 | N29: 0 | O29: =SUM(C29:L29,N29) -> 7 | P29: =SUM(C29:N29) -> 12 | R29: 0200-0300 | S29: =SUM(C86:C89) -> 0 | T29: =SUM(D86:D89) -> 0 | U29: =SUM(E86:E89) -> 0 | V29: =SUM(F86:F89) -> 0 | W29: =SUM(G86:G89) -> 0 | X29: =SUM(H86:H89) -> 0 | Y29: =SUM(I86:I89) -> 3 | Z29: =SUM(J86:J89) -> 3 | ... AF29: =SUM(P86:P89) -> 6
B30: 12.00 - 12.15 | C30: 1 | D30: 1 | E30: 0 | F30: 0 | G30: 0 | H30: 0 | I30: 0 | J30: 0 | K30: 0 | L30: 0 | M30: 14 | N30: 0 | O30: =SUM(C30:L30,N30) -> 2 | P30: =SUM(C30:N30) -> 16 | R30: 0300-0400 | S30: =SUM(C90:C93) -> 1 | T30: =SUM(D90:D93) -> 0 | U30: =SUM(E90:E93) -> 0 | V30: =SUM(F90:F93) -> 0 | W30: =SUM(G90:G93) -> 0 | X30: =SUM(H90:H93) -> 0 | Y30: =SUM(I90:I93) -> 2 | Z30: =SUM(J90:J93) -> 3 | ... AF30: =SUM(P90:P93) -> 6
B31: 12.15 - 12.30 | C31: 1 | D31: 0 | E31: 2 | F31: 2 | G31: 0 | H31: 0 | I31: 0 | J31: 0 | K31: 0 | L31: 0 | M31: 6 | N31: 0 | O31: =SUM(C31:L31,N31) -> 5 | P31: =SUM(C31:N31) -> 11 | R31: 0400-0500 | S31: =SUM(C94:C97) -> 0 | T31: =SUM(D94:D97) -> 0 | U31: =SUM(E94:E97) -> 0 | V31: =SUM(F94:F97) -> 0 | W31: =SUM(G94:G97) -> 0 | X31: =SUM(H94:H97) -> 0 | Y31: =SUM(I94:I97) -> 0 | Z31: =SUM(J94:J97) -> 0 | ... AF31: =SUM(P94:P97) -> 0
B32: 12.30 - 12.45 | C32: 2 | D32: 0 | E32: 1 | F32: 1 | G32: 0 | H32: 0 | I32: 0 | J32: 0 | K32: 0 | L32: 0 | M32: 4 | N32: 0 | O32: =SUM(C32:L32,N32) -> 4 | P32: =SUM(C32:N32) -> 8 | R32: 0500-0600 | S32: =SUM(C98:C101) -> 0 | T32: =SUM(D98:D101) -> 0 | U32: =SUM(E98:E101) -> 0 | V32: =SUM(F98:F101) -> 1 | W32: =SUM(G98:G101) -> 0 | X32: =SUM(H98:H101) -> 0 | Y32: =SUM(I98:I101) -> 0 | Z32: =SUM(J98:J101) -> 1 | ... AF32: =SUM(P98:P101) -> 2
B33: 12.45 - 13.00 | C33: 2 | D33: 0 | E33: 1 | F33: 2 | G33: 0 | H33: 0 | I33: 0 | J33: 0 | K33: 0 | L33: 0 | M33: 16 | N33: 0 | O33: =SUM(C33:L33,N33) -> 5 | P33: =SUM(C33:N33) -> 21 | R33: 0600-0700 | S33: =SUM(C102:C105) -> 1 | T33: =SUM(D102:D105) -> 1 | U33: =SUM(E102:E105) -> 0 | V33: =SUM(F102:F105) -> 1 | W33: =SUM(G102:G105) -> 0 | X33: =SUM(H102:H105) -> 0 | Y33: =SUM(I102:I105) -> 0 | Z33: =SUM(J102:J105) -> 0 | ... AF33: =SUM(P102:P105) -> 6
B34: 13.00 - 13.15 | C34: 3 | D34: 2 | E34: 0 | F34: 0 | G34: 0 | H34: 0 | I34: 1 | J34: 1 | K34: 0 | L34: 0 | M34: 15 | N34: 0 | O34: =SUM(C34:L34,N34) -> 7 | P34: =SUM(C34:N34) -> 22 | R34: AM Peak Hr | S34: =MAX(S10:S12) -> 8 | T34: =MAX(T10:T12) -> 3 | U34: =MAX(U10:U12) -> 3 | V34: =MAX(V10:V12) -> 13 | W34: =MAX(W10:W12) -> 0 | X34: =MAX(X10:X12) -> 0 | Y34: =MAX(Y10:Y12) -> 2 | Z34: =MAX(Z10:Z12) -> 1 | ... AF34: =MAX(AF10:AF12) -> 61
B35: 13.15 - 13.30 | C35: 0 | D35: 0 | E35: 0 | F35: 2 | G35: 0 | H35: 0 | I35: 0 | J35: 0 | K35: 0 | L35: 0 | M35: 12 | N35: 0 | O35: =SUM(C35:L35,N35) -> 2 | P35: =SUM(C35:N35) -> 14 | R35: IP Peak Hr | S35: =MAX(S13:S18) -> 13 | T35: =MAX(T13:T18) -> 4 | U35: =MAX(U13:U18) -> 5 | V35: =MAX(V13:V18) -> 7 | W35: =MAX(W13:W18) -> 0 | X35: =MAX(X13:X18) -> 0 | Y35: =MAX(Y13:Y18) -> 5 | Z35: =MAX(Z13:Z18) -> 2 | ... AF35: =MAX(AF13:AF18) -> 65
B36: 13.30 - 13.45 | C36: 1 | D36: 1 | E36: 0 | F36: 0 | G36: 0 | H36: 0 | I36: 1 | J36: 1 | K36: 0 | L36: 0 | M36: 11 | N36: 0 | O36: =SUM(C36:L36,N36) -> 4 | P36: =SUM(C36:N36) -> 15 | R36: PM Peak Hr | S36: =MAX(S19:S21) -> 12 | T36: =MAX(T19:T21) -> 6 | U36: =MAX(U19:U21) -> 11 | V36: =MAX(V19:V21) -> 10 | W36: =MAX(W19:W21) -> 0 | X36: =MAX(X19:X21) -> 0 | Y36: =MAX(Y19:Y21) -> 3 | Z36: =MAX(Z19:Z21) -> 1 | ... AF36: =MAX(AF19:AF21) -> 82
B37: 13.45 - 14.00 | C37: 1 | D37: 1 | E37: 1 | F37: 0 | G37: 0 | H37: 0 | I37: 0 | J37: 0 | K37: 0 | L37: 0 | M37: 11 | N37: 0 | O37: =SUM(C37:L37,N37) -> 3 | P37: =SUM(C37:N37) -> 14 | R37: AM Period | S37: =SUM(S10:S12) -> 21 | T37: =SUM(T10:T12) -> 4 | U37: =SUM(U10:U12) -> 5 | V37: =SUM(V10:V12) -> 32 | W37: =SUM(W10:W12) -> 0 | X37: =SUM(X10:X12) -> 0 | Y37: =SUM(Y10:Y12) -> 2 | Z37: =SUM(Z10:Z12) -> 1 | ... AF37: =SUM(AF10:AF12) -> 150
B38: 14.00 - 14.15 | C38: 2 | D38: 1 | E38: 2 | F38: 1 | G38: 0 | H38: 0 | I38: 0 | J38: 0 | K38: 0 | L38: 0 | M38: 6 | N38: 0 | O38: =SUM(C38:L38,N38) -> 6 | P38: =SUM(C38:N38) -> 12 | R38: IP Period | S38: =SUM(S13:S18) -> 44 | T38: =SUM(T13:T18) -> 15 | U38: =SUM(U13:U18) -> 17 | V38: =SUM(V13:V18) -> 28 | W38: =SUM(W13:W18) -> 0 | X38: =SUM(X13:X18) -> 0 | Y38: =SUM(Y13:Y18) -> 17 | Z38: =SUM(Z13:Z18) -> 3 | ... AF38: =SUM(AF13:AF18) -> 354
B39: 14.15 - 14.30 | C39: 4 | D39: 0 | E39: 1 | F39: 2 | G39: 0 | H39: 0 | I39: 3 | J39: 0 | K39: 0 | L39: 0 | M39: 15 | N39: 0 | O39: =SUM(C39:L39,N39) -> 10 | P39: =SUM(C39:N39) -> 25 | R39: PM Period | S39: =SUM(S19:S21) -> 30 | T39: =SUM(T19:T21) -> 12 | U39: =SUM(U19:U21) -> 13 | V39: =SUM(V19:V21) -> 24 | W39: =SUM(W19:W21) -> 0 | X39: =SUM(X19:X21) -> 0 | Y39: =SUM(Y19:Y21) -> 7 | Z39: =SUM(Z19:Z21) -> 2 | ... AF39: =SUM(AF19:AF21) -> 207
B40: 14.30 - 14.45 | C40: 6 | D40: 0 | E40: 0 | F40: 0 | G40: 0 | H40: 0 | I40: 2 | J40: 0 | K40: 0 | L40: 0 | M40: 7 | N40: 0 | O40: =SUM(C40:L40,N40) -> 8 | P40: =SUM(C40:N40) -> 15 | R40: 12 Hours | S40: =SUM(S10:S21) -> 95 | T40: =SUM(T10:T21) -> 31 | U40: =SUM(U10:U21) -> 35 | V40: =SUM(V10:V21) -> 84 | W40: =SUM(W10:W21) -> 0 | X40: =SUM(X10:X21) -> 0 | Y40: =SUM(Y10:Y21) -> 26 | Z40: =SUM(Z10:Z21) -> 6 | ... AF40: =SUM(AF10:AF21) -> 711
B41: 14.45 - 15.00 | C41: 1 | D41: 0 | E41: 1 | F41: 2 | G41: 0 | H41: 0 | I41: 0 | J41: 0 | K41: 0 | L41: 0 | M41: 8 | N41: 0 | O41: =SUM(C41:L41,N41) -> 4 | P41: =SUM(C41:N41) -> 12 | R41: 24 Hrs/ADT | S41: =SUM(S10:S33) -> 124 | T41: =SUM(T10:T33) -> 51 | U41: =SUM(U10:U33) -> 43 | V41: =SUM(V10:V33) -> 94 | W41: =SUM(W10:W33) -> 0 | X41: =SUM(X10:X33) -> 0 | Y41: =SUM(Y10:Y33) -> 48 | Z41: =SUM(Z10:Z33) -> 40 | ... AF41: =SUM(AF10:AF33) -> 912
B42: 15.00 - 15.15 | C42: 1 | D42: 2 | E42: 2 | F42: 2 | G42: 0 | H42: 0 | I42: 1 | J42: 0 | K42: 0 | L42: 0 | M42: 13 | N42: 0 | O42: =SUM(C42:L42,N42) -> 8 | P42: =SUM(C42:N42) -> 21 | R42: NEF | S42: =S41/S40 -> 1.3052632 | T42: =T41/T40 -> 1.6451613 | U42: =U41/U40 -> 1.2285714 | V42: =V41/V40 -> 1.1190476 | W42: =W41/W40 -> #DIV/0! | X42: =X41/X40 -> #DIV/0! | Y42: =Y41/Y40 -> 1.8461538 | Z42: =Z41/Z40 -> 6.6666667 | ... AF42: =AF41/AF40 -> 1.2827004
...

Sheet 19.10 KANONI-MADDU-24h
B1: Consultancy services for Preparation of Expressway Development Master Plan (EDMP) for Uganda
B2: MANUAL CLASSIFIED COUNT (MCC)
B3: ROAD NAME: | C3: ='17.10 KANONI-MADDU'!C3:G3 -> KANONI-MADDU ROAD
C5: Date | D5: ='19.10 MADDU-KANONI-24h'!D5 -> 19.10.2019 | F5: Location | G5: ='19.10 MADDU-KANONI-24h'!G5:H5 -> KANONI | J5: Surveyor | K5: BABIRYE PHIONA
C6: Dir. From | D6: KANONI | F6: Dir. To | G6: MADDU | J6: Supervisor | K6: ='19.10 MADDU-KANONI-24h'!K6:L6 -> FELIX OLOYA
B8: Time / Veh Type | R8: SUMMARY TRAFFIC VOLUMES
C9: 1. Car | D9: 2. Station Wagon | E9: 3. Pickups | F9: 4. Minibus, matatu | G9: 5. Medium bus | H9: 6. Large Bus | I9: 7. Light Truck | J9: 8. Medium Truck | K9: 9. Heavy truck | L9: 10. Truck Trailer | M9: 11. Motor cycles | N9: 12. Tractors | O9: Total Excl M/Cycles | P9: Total All | R9: Time | S9: 1. Car | T9: 2. Station Wagon | U9: 3. Pickups | V9: 4. Minibus, matatu | W9: 5. Medium bus | X9: 6. Large Bus | Y9: 7. Light Truck | Z9: 8. Medium Truck | AA9: 9. Heavy truck | AB9: 10. Truck Trailer | AC9: 11. Motorcycles | AD9: 12. Tractors, Graders | AE9: Total Excl M/ Cycles | AF9: Total All
B10: 07.00 - 07.15 | C10: 0 | D10: 0 | E10: 0 | F10: 0 | G10: 0 | H10: 0 | I10: 0 | J10: 1 | K10: 0 | L10: 0 | M10: 2 | N10: 0 | O10: =SUM(C10:L10,N10) -> 1 | P10: =SUM(C10:N10) -> 3 | R10: 0700-0800 | S10: =SUM(C10:C13) -> 1 | T10: =SUM(D10:D13) -> 2 | U10: =SUM(E10:E13) -> 3 | V10: =SUM(F10:F13) -> 3 | W10: =SUM(G10:G13) -> 0 | X10: =SUM(H10:H13) -> 0 | Y10: =SUM(I10:I13) -> 1 | Z10: =SUM(J10:J13) -> 4 | ... AF10: =SUM(P10:P13) -> 24
B11: 07.15 - 07.30 | C11: 0 | D11: 0 | E11: 0 | F11: 0 | G11: 0 | H11: 0 | I11: 0 | J11: 0 | K11: 0 | L11: 0 | M11: 0 | N11: 0 | O11: =SUM(C11:L11,N11) -> 0 | P11: =SUM(C11:N11) -> 0 | R11: 0800-0900 | S11: =SUM(C14:C17) -> 5 | T11: =SUM(D14:D17) -> 1 | U11: =SUM(E14:E17) -> 1 | V11: =SUM(F14:F17) -> 4 | W11: =SUM(G14:G17) -> 0 | X11: =SUM(H14:H17) -> 0 | Y11: =SUM(I14:I17) -> 2 | Z11: =SUM(J14:J17) -> 3 | ... AF11: =SUM(P14:P17) -> 29
B12: 07.30 - 07.45 | C12: 0 | D12: 2 | E12: 1 | F12: 3 | G12: 0 | H12: 0 | I12: 1 | J12: 1 | K12: 0 | L12: 0 | M12: 4 | N12: 0 | O12: =SUM(C12:L12,N12) -> 8 | P12: =SUM(C12:N12) -> 12 | R12: 0900-1000 | S12: =SUM(C18:C21) -> 4 | T12: =SUM(D18:D21) -> 7 | U12: =SUM(E18:E21) -> 4 | V12: =SUM(F18:F21) -> 4 | W12: =SUM(G18:G21) -> 0 | X12: =SUM(H18:H21) -> 0 | Y12: =SUM(I18:I21) -> 1 | Z12: =SUM(J18:J21) -> 6 | ... AF12: =SUM(P18:P21) -> 43
B13: 07.45 - 08.00 | C13: 1 | D13: 0 | E13: 2 | F13: 0 | G13: 0 | H13: 0 | I13: 0 | J13: 2 | K13: 1 | L13: 0 | M13: 3 | N13: 0 | O13: =SUM(C13:L13,N13) -> 6 | P13: =SUM(C13:N13) -> 9 | R13: 1000-1100 | S13: =SUM(C22:C25) -> 3 | T13: =SUM(D22:D25) -> 10 | U13: =SUM(E22:E25) -> 5 | V13: =SUM(F22:F25) -> 1 | W13: =SUM(G22:G25) -> 0 | X13: =SUM(H22:H25) -> 0 | Y13: =SUM(I22:I25) -> 0 | Z13: =SUM(J22:J25) -> 0 | ... AF13: =SUM(P22:P25) -> 44
B14: 08.00 - 08.15 | C14: 1 | D14: 1 | E14: 0 | F14: 0 | G14: 0 | H14: 0 | I14: 0 | J14: 0 | K14: 0 | L14: 0 | M14: 2 | N14: 0 | O14: =SUM(C14:L14,N14) -> 2 | P14: =SUM(C14:N14) -> 4 | R14: 1100-1200 | S14: =SUM(C26:C29) -> 10 | T14: =SUM(D26:D29) -> 4 | U14: =SUM(E26:E29) -> 4 | V14: =SUM(F26:F29) -> 8 | W14: =SUM(G26:G29) -> 0 | X14: =SUM(H26:H29) -> 0 | Y14: =SUM(I26:I29) -> 2 | Z14: =SUM(J26:J29) -> 1 | ... AF14: =SUM(P26:P29) -> 75
B15: 08.15 - 08.30 | C15: 0 | D15: 0 | E15: 0 | F15: 0 | G15: 0 | H15: 0 | I15: 1 | J15: 1 | K15: 0 | L15: 0 | M15: 5 | N15: 0 | O15: =SUM(C15:L15,N15) -> 2 | P15: =SUM(C15:N15) -> 7 | R15: 1200-1300 | S15: =SUM(C30:C33) -> 8 | T15: =SUM(D30:D33) -> 6 | U15: =SUM(E30:E33) -> 1 | V15: =SUM(F30:F33) -> 4 | W15: =SUM(G30:G33) -> 0 | X15: =SUM(H30:H33) -> 0 | Y15: =SUM(I30:I33) -> 1 | Z15: =SUM(J30:J33) -> 3 | ... AF15: =SUM(P30:P33) -> 46
