Workbook
Name Veh_Type: 'PT-01'!$C$10:$C$38
Name Veh_Type: #REF!
Name zones: #REF!
Name Zones_Ndeke: #REF!
Name Zones_Ndeke: #REF!

Sheet RSI FORM
B1: Feasibility Study and Detailed Design of Kampala - Jinja Highway
B2: Roadside OD Interview Survey
B4: Date: | C4: 40465 | D4: Interviewer: | G4: Survey Station: | H4: Bweyogerere | J4: Direction: | K4: Bweyogerere-Kireka | L4: Coded By: | N4: Chkd By:
B7: Time Period | C7: Veh_Type | D7: Veh_Other | E7: Occupancy | F7: Origin_Address | H7: Origin_Purpose | I7: Origin_other | J7: Destination_Address | L7: Destination_Purpose | M7: Destination_Other | N7: Origin_Zone | O7: Dest_Zone | P7: WTP
F8: Village/Town | G8: City/Country | J8: Village/Town | K8: City/Country
B9: AM | C9: 3 | E9: 2 | F9: Entebbe | G9: Kla, Ug | H9: 1 | J9: Kla | K9: Kla, Ug | L9: 2 | N9: Blank | O9: Blank | P9: Yes | Q9: 3000
B10: AM | C10: 1 | E10: 1 | F10: Kiwanga | G10: Kla, Ug | H10: 1 | J10: Kla | K10: Kla, Ug | L10: 2 | N10: Blank | O10: Blank | P10: Yes | Q10: 2000
B11: AM | E11: 1 | F11: Bukoto | G11: Kla, Ug | H11: 3 | J11: Kla | K11: Kla, Ug | L11: 1 | N11: Blank | O11: Blank
B12: AM
B13: AM
B14: AM
B15: AM
B16: AM
B17: AM
B18: AM
B19: AM
B20: AM
B21: AM
B22: AM
B23: AM
... B53: AM

Sheet PT-01
B1: Consultancy services for Preparation of Expressway Development Master Plan (EDMP) for Uganda
B2: Public Transport/Bus Surveys
B4: Date: | D4: 01.08.19 | G4: Location | J4: Coded By: | N4: Chkd By: | O4: Bakole. D.M
B5: Enumerator: | G5: Supervisor:
B7: Time | C7: Veh_Type | D7: Type of Veh. | E7: Veh_Reg_No. | F7: IN / OUT | G7: Origin_Address | J7: Destination_Address | M7: No. Passengers | N7: Cost of Trip (UGX) | O7: Approx_Journey Time (Hrs)
G8: Town | H8: District | I8: Country | J8: Town | K8: District | L8: Journey_Desc
B9: 13/08/2019 | E9: GLOBAL
B10: 0.71666667 | C10: 6 | D10: =IF(C10="", "",VLOOKUP(C10,Key!$A$5:$B$7,2,FALSE)) -> Large Bus | E10: GLOBAL | F10: IN | G10: MBARARA | H10: MBARARA | I10: UG | J10: KAMPALA | K10: KAMPALA | L10: =H10&"-"&K10 -> MBARARA-KAMPALA | M10: 65 | N10: 20000 | O10: 4.9
B11: 0.73819444 | C11: 6 | D11: =IF(C11="", "",VLOOKUP(C11,Key!$A$5:$B$7,2,FALSE)) -> Large Bus | E11: GLOBAL | F11: IN | G11: MBARARA | H11: MBARARA | I11: UG | J11: KAMPALA | K11: KAMPALA | L11: =H11&"-"&K11 -> MBARARA-KAMPALA | M11: 65 | N11: 20000 | O11: 4.9
B12: 0.74097222 | C12: 6 | D12: =IF(C12="", "",VLOOKUP(C12,Key!$A$5:$B$7,2,FALSE)) -> Large Bus | E12: GLOBAL | F12: IN | G12: MBARARA | H12: MBARARA | I12: UG | J12: KAMPALA | K12: KAMPALA | L12: =H12&"-"&K12 -> MBARARA-KAMPALA | M12: 67 | N12: 20000 | O12: 4.9
B13: 0.75625 | C13: 6 | D13: =IF(C13="", "",VLOOKUP(C13,Key!$A$5:$B$7,2,FALSE)) -> Large Bus | E13: GLOBAL | F13: IN | G13: MBARARA | H13: MBARARA | I13: UG | J13: KAMPALA | K13: KAMPALA | L13: =H13&"-"&K13 -> MBARARA-KAMPALA | M13: 67 | N13: 20000 | O13: 4.9
B14: 0.75833333 | C14: 6 | D14: =IF(C14="", "",VLOOKUP(C14,Key!$A$5:$B$7,2,FALSE)) -> Large Bus | E14: GLOBAL | F14: IN | G14: MBARARA | H14: MBARARA | I14: UG | J14: KAMPALA | K14: KAMPALA | L14: =H14&"-"&K14 -> MBARARA-KAMPALA | M14: 65 | N14: 20000 | O14: 4.9
B15: 0.75902778 | C15: 6 | D15: =IF(C15="", "",VLOOKUP(C15,Key!$A$5:$B$7,2,FALSE)) -> Large Bus | E15: GLOBAL | F15: IN | G15: MBARARA | H15: MBARARA | I15: UG | J15: KAMPALA | K15: KAMPALA | L15: =H15&"-"&K15 -> MBARARA-KAMPALA | M15: 65 | N15: 20000 | O15: 4.9
B16: 0.76388889 | C16: 6 | D16: =IF(C16="", "",VLOOKUP(C16,Key!$A$5:$B$7,2,FALSE)) -> Large Bus | E16: GLOBAL | F16: IN | G16: MBARARA | H16: MBARARA | I16: UG | J16: KAMPALA | K16: KAMPALA | L16: =H16&"-"&K16 -> MBARARA-KAMPALA | M16: 67 | N16: 20000 | O16: 4.9
B17: 0.76458333 | C17: 6 | D17: =IF(C17="", "",VLOOKUP(C17,Key!$A$5:$B$7,2,FALSE)) -> Large Bus | E17: GLOBAL | F17: IN | G17: MBARARA | H17: MBARARA | I17: UG | J17: KAMPALA | K17: KAMPALA | L17: =H17&"-"&K17 -> MBARARA-KAMPALA | M17: 67 | N17: 20000 | O17: 4.9
B18: 0.78263889 | C18: 6 | D18: =IF(C18="", "",VLOOKUP(C18,Key!$A$5:$B$7,2,FALSE)) -> Large Bus | E18: GLOBAL | F18: IN | G18: MBARARA | H18: MBARARA | I18: UG | J18: KAMPALA | K18: KAMPALA | L18: =H18&"-"&K18 -> MBARARA-KAMPALA | M18: 65 | N18: 20000 | O18: 4.9
B19: 0.78402778 | C19: 6 | D19: =IF(C19="", "",VLOOKUP(C19,Key!$A$5:$B$7,2,FALSE)) -> Large Bus | E19: GLOBAL | F19: IN | G19: MBARARA | H19: MBARARA | I19: UG | J19: KAMPALA | K19: KAMPALA | L19: =H19&"-"&K19 -> MBARARA-KAMPALA | M19: 67 | N19: 20000 | O19: 4.9
B20: 0.60763889 | C20: 6 | D20: =IF(C20="", "",VLOOKUP(C20,Key!$A$5:$B$7,2,FALSE)) -> Large Bus | E20: GLOBAL | F20: OUT | G20: KAMPALA | H20: KAMPALA | I20: UG | J20: MBARARA | K20: MBARARA | L20: =H20&"-"&K20 -> KAMPALA-MBARARA | M20: 67 | N20: 20000 | O20: 4.9
B21: 0.61180556 | C21: 6 | D21: =IF(C21="", "",VLOOKUP(C21,Key!$A$5:$B$7,2,FALSE)) -> Large Bus | E21: GLOBAL | F21: OUT | G21: KAMPALA | H21: KAMPALA | I21: UG | J21: MBARARA | K21: MBARARA | L21: =H21&"-"&K21 -> KAMPALA-MBARARA | M21: 67 | N21: 20000 | O21: 4.9
... B57: 0.20138889 | C57: 6 | D57: =IF(C57="", "",VLOOKUP(C57,Key!$A$5:$B$7,2,FALSE)) -> Large Bus | E57: GLOBAL | F57: IN | G57: MBARARA | H57: MBARARA | I57: UG | J57: CITY | K57: KAMPALA | L57: =H57&"-"&K57 -> MBARARA-KAMPALA | M57: 67 | N57: 20000 | O57: 4.9
B58: 14/08/2019 | E58: GLOBAL | I58: UG | L58: =H58&"-"&K58 -> -
B59: 0.82638889 | C59: 6 | D59: =IF(C59="", "",VLOOKUP(C59,Key!$A$5:$B$7,2,FALSE)) -> Large Bus | E59: GLOBAL | F59: OUT | G59: KAMPALA | H59: KAMPALA | I59: UG | J59: MBARARA | K59: MBARARA | L59: =H59&"-"&K59 -> KAMPALA-MBARARA | M59: 70 | N59: 20000 | O59: 4.9
B60: 0.86111111 | C60: 6 | D60: =IF(C60="", "",VLOOKUP(C60,Key!$A$5:$B$7,2,FALSE)) -> Large Bus | E60: GLOBAL | F60: OUT | G60: KAMPALA | H60: KAMPALA | I60: UG | J60: MBARARA | K60: MBARARA | L60: =H60&"-"&K60 -> KAMPALA-MBARARA | M60: 70 | N60: 20000 | O60: 4.9
B61: 0.87847222 | C61: 6 | D61: =IF(C61="", "",VLOOKUP(C61,Key!$A$5:$B$7,2,FALSE)) -> Large Bus | E61: GLOBAL | F61: OUT | G61: KAMPALA | H61: KAMPALA | I61: UG | J61: MBARARA | K61: MBARARA | L61: =H61&"-"&K61 -> KAMPALA-MBARARA | M61: 67 | N61: 20000 | O61: 4.9
B62: 0.91180556 | C62: 6 | D62: =IF(C62="", "",VLOOKUP(C62,Key!$A$5:$B$7,2,FALSE)) -> Large Bus | E62: GLOBAL | F62: OUT | G62: KAMPALA | H62: KAMPALA | I62: UG | J62: MBARARA | K62: MBARARA | L62: =H62&"-"&K62 -> KAMPALA-MBARARA | M62: 68 | N62: 20000 | O62: 4.9
B63: 0.97916667 | C63: 6 | D63: =IF(C63="", "",VLOOKUP(C63,Key!$A$5:$B$7,2,FALSE)) -> Large Bus | E63: GLOBAL | F63: OUT | G63: KAMPALA | H63: KAMPALA | I63: UG | J63: MBARARA | K63: MBARARA | L63: =H63&"-"&K63 -> KAMPALA-MBARARA | M63: 67 | N63: 20000 | O63: 4.9
B64: 0.029166667 | C64: 6 | D64: =IF(C64="", "",VLOOKUP(C64,Key!$A$5:$B$7,2,FALSE)) -> Large Bus | E64: GLOBAL | F64: OUT | G64: KAMPALA | H64: KAMPALA | I64: UG | J64: MBARARA | K64: MBARARA | L64: =H64&"-"&K64 -> KAMPALA-MBARARA | M64: 65 | N64: 20000 | O64: 4.9
B65: 0.077777778 | C65: 6 | D65: =IF(C65="", "",VLOOKUP(C65,Key!$A$5:$B$7,2,FALSE)) -> Large Bus | E65: GLOBAL | F65: OUT | G65: KAMPALA | H65: KAMPALA | I65: UG | J65: MBARARA | K65: MBARARA | L65: =H65&"-"&K65 -> KAMPALA-MBARARA | M65: 65 | N65: 20000 | O65: 4.9
B66: 0.12013889 | C66: 6 | D66: =IF(C66="", "",VLOOKUP(C66,Key!$A$5:$B$7,2,FALSE)) -> Large Bus | E66: GLOBAL | F66: OUT | G66: KAMPALA | H66: KAMPALA | I66: UG | J66: MBARARA | K66: MBARARA | L66: =H66&"-"&K66 -> KAMPALA-MBARARA | M66: 65 | N66: 20000 | O66: 4.9
B67: 0.15416667 | C67: 6 | D67: =IF(C67="", "",VLOOKUP(C67,Key!$A$5:$B$7,2,FALSE)) -> Large Bus | E67: GLOBAL | F67: OUT | G67: KAMPALA | H67: KAMPALA | I67: UG | J67: MBARARA | K67: MBARARA | L67: =H67&"-"&K67 -> KAMPALA-MBARARA | M67: 65 | N67: 20000 | O67: 4.9
B68: 0.1875 | C68: 6 | D68: =IF(C68="", "",VLOOKUP(C68,Key!$A$5:$B$7,2,FALSE)) -> Large Bus | E68: GLOBAL | F68: OUT | G68: KAMPALA | H68: KAMPALA | I68: UG | J68: MBARARA | K68: MBARARA | L68: =H68&"-"&K68 -> KAMPALA-MBARARA | M68: 65 | N68: 20000 | O68: 4.9
B69: 0.22222222 | C69: 6 | D69: =IF(C69="", "",VLOOKUP(C69,Key!$A$5:$B$7,2,FALSE)) -> Large Bus | E69: GLOBAL | F69: OUT | G69: KAMPALA | H69: KAMPALA | I69: UG | J69: MBARARA | K69: MBARARA | L69: =H69&"-"&K69 -> KAMPALA-MBARARA | M69: 67 | N69: 20000 | O69: 4.9
B70: 0.26041667 | C70: 6 | D70: =IF(C70="", "",VLOOKUP(C70,Key!$A$5:$B$7,2,FALSE)) -> Large Bus | E70: GLOBAL | F70: OUT | G70: KAMPALA | H70: KAMPALA | I70: UG | J70: MBARARA | K70: MBARARA | L70: =H70&"-"&K70 -> KAMPALA-MBARARA | M70: 67 | N70: 20000 | O70: 4.9
... B145: 0.71527778 | C145: 6 | D145: =IF(C145="", "",VLOOKUP(C145,Key!$A$5:$B$7,2,FALSE)) -> Large Bus | E145: GLOBAL | F145: IN | G145: MBARARA | H145: MBARARA | I145: UG | J145: KAMPALA | K145: KAMPALA | L145: =H145&"-"&K145 -> MBARARA-KAMPALA | M145: 65 | N145: 20000 | O145: 4.9
B146: 15/08/2019 | E146: GLOBAL | I146: UG | L146: =H146&"-"&K146 -> -
B147: 0.33055556 | C147: 6 | D147: =IF(C147="", "",VLOOKUP(C147,Key!$A$5:$B$7,2,FALSE)) -> Large Bus | E147: GLOBAL | F147: OUT | G147: KAMPALA | H147: KAMPALA | I147: UG | J147: MBARARA | K147: MBARARA | L147: =H147&"-"&K147 -> KAMPALA-MBARARA | M147: 67 | N147: 20000 | O147: 4.9
B148: 0.34513889 | C148: 6 | D148: =IF(C148="", "",VLOOKUP(C148,Key!$A$5:$B$7,2,FALSE)) -> Large Bus | E148: GLOBAL | F148: OUT | G148: KAMPALA | H148: KAMPALA | I148: UG | J148: MBARARA | K148: MBARARA | L148: =H148&"-"&K148 -> KAMPALA-MBARARA | M148: 65 | N148: 20000 | O148: 4.9
B149: 0.3625 | C149: 6 | D149: =IF(C149="", "",VLOOKUP(C149,Key!$A$5:$B$7,2,FALSE)) -> Large Bus | E149: GLOBAL | F149: OUT | G149: KAMPALA | H149: KAMPALA | I149: UG | J149: MBARARA | K149: MBARARA | L149: =H149&"-"&K149 -> KAMPALA-MBARARA | M149: 67 | N149: 20000 | O149: 4.9
B150: 0.38402778 | C150: 6 | D150: =IF(C150="", "",VLOOKUP(C150,Key!$A$5:$B$7,2,FALSE)) -> Large Bus | E150: GLOBAL | F150: OUT | G150: KAMPALA | H150: KAMPALA | I150: UG | J150: MBARARA | K150: MBARARA | L150: =H150&"-"&K150 -> KAMPALA-MBARARA | M150: 65 | N150: 20000 | O150: 4.9
B151: 0.40138889 | C151: 6 | D151: =IF(C151="", "",VLOOKUP(C151,Key!$A$5:$B$7,2,FALSE)) -> Large Bus | E151: GLOBAL | F151: OUT | G151: KAMPALA | H151: KAMPALA | I151: UG | J151: MBARARA | K151: MBARARA | L151: =H151&"-"&K151 -> KAMPALA-MBARARA | M151: 67 | N151: 20000 | O151: 4.9
...

Sheet Summary
B2: BUS OPERATIONS AT KAMPALA
B4: GLOBAL COACHES | D4: BUS JOURNEY | J4: PASSENGER DETAILS
B5: STATION | C5: DIRECTION | D5: ORIGIN | E5: DESTINATION | F5: ROUTE ID | G5: BUS TRIPS / DAY | H5: JOURNEY DISTANCE (KM) | I5: JOURNEY TIME/ TRIP (HRS) | J5: EST. PAX/ BUS | K5: AVERAGE PAX FARE (UGX)
B6: KAMPALA | C6: FROM KAMPALA | D6: KAMPALA | E6: MBARARA | F6: =D6&"-"&E6 -> KAMPALA-MBARARA | G6: =ROUNDUP(COUNTIF('PT-01'!$L$10:$L$466,Summary!F6)/5,0) -> 48 | H6: 270 | I6: =AVERAGEIF('PT-01'!$L$10:$L$466,Summary!F6,'PT-01'!$O$10:$O$466) -> 4.9 | J6: =AVERAGEIF('PT-01'!$L$10:$L$466,Summary!F6,'PT-01'!$M$10:$M$466) -> 65.058333 | K6: =AVERAGEIF('PT-01'!$L$10:$L$466,Summary!F6,'PT-01'!$N$10:$N$466) -> 20000
B7: KAMPALA | C7: TO KAMPALA | D7: MBARARA | E7: KAMPALA | F7: =D7&"-"&E7 -> MBARARA-KAMPALA | G7: =ROUNDUP(COUNTIF('PT-01'!$L$10:$L$466,Summary!F7)/5,0) -> 43 | H7: 270 | I7: =AVERAGEIF('PT-01'!$L$10:$L$466,Summary!F7,'PT-01'!$O$10:$O$466) -> 4.9 | J7: =AVERAGEIF('PT-01'!$L$10:$L$466,Summary!F7,'PT-01'!$M$10:$M$466) -> 65.924528 | K7: =AVERAGEIF('PT-01'!$L$10:$L$466,Summary!F7,'PT-01'!$N$10:$N$466) -> 20000
B10: BISMARKAN COACHES | D10: BUS JOURNEY | J10: PASSENGER DETAILS
B11: STATION | C11: DIRECTION | D11: ORIGIN | E11: DESTINATION | F11: ROUTE ID | G11: BUS TRIPS / DAY | H11: JOURNEY DISTANCE (KM) | I11: JOURNEY TIME/ TRIP (HRS) | J11: EST. PAX/ BUS | K11: AVERAGE PAX FARE (UGX)
B12: KAMPALA | C12: FROM KAMPALA | D12: KAMPALA | E12: BUSHENYI | F12: =D12&"-"&E12 -> KAMPALA-BUSHENYI | G12: =ROUNDUP(COUNTIF('PT-01'!$L$468:$L$609,Summary!F12)/5,0) -> 6 | H12: 331 | I12: =AVERAGEIF('PT-01'!$L$468:$L$609,Summary!F12,'PT-01'!$O$468:$O$609) -> 6 | J12: =AVERAGEIF('PT-01'!$L$468:$L$609,Summary!F12,'PT-01'!$M$468:$M$609) -> 57.466667 | K12: =AVERAGEIF('PT-01'!$L$468:$L$609,Summary!F12,'PT-01'!$N$468:$N$609) -> 25000
B13: KAMPALA | C13: FROM KAMPALA | D13: KAMPALA | E13: ISHAKA | F13: =D13&"-"&E13 -> KAMPALA-ISHAKA | G13: =ROUNDUP(COUNTIF('PT-01'!$L$468:$L$609,Summary!F13)/5,0) -> 3 | H13: 328 | I13: =AVERAGEIF('PT-01'!$L$468:$L$609,Summary!F13,'PT-01'!$O$468:$O$609) -> 5.45 | J13: =AVERAGEIF('PT-01'!$L$468:$L$609,Summary!F13,'PT-01'!$M$468:$M$609) -> 11.6 | K13: =AVERAGEIF('PT-01'!$L$468:$L$609,Summary!F13,'PT-01'!$N$468:$N$609) -> 25000
B14: KAMPALA | C14: FROM KAMPALA | D14: KAMPALA | E14: KATENDE-ISHAKA | F14: =D14&"-"&E14 -> KAMPALA-KATENDE-ISHAKA | G14: =ROUNDUP(COUNTIF('PT-01'!$L$468:$L$609,Summary!F14)/5,0) -> 1 | H14: 328 | I14: =AVERAGEIF('PT-01'!$L$468:$L$609,Summary!F14,'PT-01'!$O$468:$O$609) -> 5.45 | J14: =AVERAGEIF('PT-01'!$L$468:$L$609,Summary!F14,'PT-01'!$M$468:$M$609) -> 4 | K14: =AVERAGEIF('PT-01'!$L$468:$L$609,Summary!F14,'PT-01'!$N$468:$N$609) -> 25000
B15: KAMPALA | C15: FROM KAMPALA | D15: KAMPALA | E15: KISORO | F15: =D15&"-"&E15 -> KAMPALA-KISORO | G15: =ROUNDUP(COUNTIF('PT-01'!$L$468:$L$609,Summary!F15)/5,0) -> 5 | H15: 467 | I15: =AVERAGEIF('PT-01'!$L$468:$L$609,Summary!F15,'PT-01'!$O$468:$O$609) -> 9 | J15: =AVERAGEIF('PT-01'!$L$468:$L$609,Summary!F15,'PT-01'!$M$468:$M$609) -> 65.73913 | K15: =AVERAGEIF('PT-01'!$L$468:$L$609,Summary!F15,'PT-01'!$N$468:$N$609) -> 40000
B16: KAMPALA | C16: FROM KAMPALA | D16: KAMPALA | E16: MBARARA | F16: =D16&"-"&E16 -> KAMPALA-MBARARA | G16: =ROUNDUP(COUNTIF('PT-01'!$L$468:$L$609,Summary!F16)/5,0) -> 1 | H16: 270 | I16: =AVERAGEIF('PT-01'!$L$468:$L$609,Summary!F16,'PT-01'!$O$468:$O$609) -> 4.9 | J16: =AVERAGEIF('PT-01'!$L$468:$L$609,Summary!F16,'PT-01'!$M$468:$M$609) -> 3 | K16: =AVERAGEIF('PT-01'!$L$468:$L$609,Summary!F16,'PT-01'!$N$468:$N$609) -> 20000
B17: KAMPALA | C17: FROM KAMPALA | D17: KAMPALA | E17: RUBIRIZI | F17: =D17&"-"&E17 -> KAMPALA-RUBIRIZI | G17: =ROUNDUP(COUNTIF('PT-01'!$L$468:$L$609,Summary!F17)/5,0) -> 1 | H17: 365 | I17: =AVERAGEIF('PT-01'!$L$468:$L$609,Summary!F17,'PT-01'!$O$468:$O$609) -> 6.25 | J17: =AVERAGEIF('PT-01'!$L$468:$L$609,Summary!F17,'PT-01'!$M$468:$M$609) -> 66.666667 | K17: =AVERAGEIF('PT-01'!$L$468:$L$609,Summary!F17,'PT-01'!$N$468:$N$609) -> 25000
B18: KAMPALA | C18: TO KAMPALA | D18: BUSHENYI | E18: KAMPALA | F18: =D18&"-"&E18 -> BUSHENYI-KAMPALA | G18: =ROUNDUP(COUNTIF('PT-01'!$L$468:$L$609,Summary!F18)/5,0) -> 7 | H18: 331 | I18: =AVERAGEIF('PT-01'!$L$468:$L$609,Summary!F18,'PT-01'!$O$468:$O$609) -> 6 | J18: =AVERAGEIF('PT-01'!$L$468:$L$609,Summary!F18,'PT-01'!$M$468:$M$609) -> 36.647059 | K18: =AVERAGEIF('PT-01'!$L$468:$L$609,Summary!F18,'PT-01'!$N$468:$N$609) -> 25000
B19: KAMPALA | C19: TO KAMPALA | D19: KISORO | E19: KAMPALA | F19: =D19&"-"&E19 -> KISORO-KAMPALA | G19: =ROUNDUP(COUNTIF('PT-01'!$L$468:$L$609,Summary!F19)/5,0) -> 5 | H19: 467 | I19: =AVERAGEIF('PT-01'!$L$468:$L$609,Summary!F19,'PT-01'!$O$468:$O$609) -> 9 | J19: =AVERAGEIF('PT-01'!$L$468:$L$609,Summary!F19,'PT-01'!$M$468:$M$609) -> 62.04 | K19: =AVERAGEIF('PT-01'!$L$468:$L$609,Summary!F19,'PT-01'!$N$468:$N$609) -> 35000
B20: KAMPALA | C20: TO KAMPALA | D20: MBARARA | E20: KAMPALA | F20: =D20&"-"&E20 -> MBARARA-KAMPALA | G20: =ROUNDUP(COUNTIF('PT-01'!$L$468:$L$609,Summary!F20)/5,0) -> 1 | H20: 270 | I20: =AVERAGEIF('PT-01'!$L$468:$L$609,Summary!F20,'PT-01'!$O$468:$O$609) -> 4.9 | J20: =AVERAGEIF('PT-01'!$L$468:$L$609,Summary!F20,'PT-01'!$M$468:$M$609) -> 55 | K20: =AVERAGEIF('PT-01'!$L$468:$L$609,Summary!F20,'PT-01'!$N$468:$N$609) -> 20000
B21: KAMPALA | C21: TO KAMPALA | D21: RUBIRIZI | E21: KAMPALA | F21: =D21&"-"&E21 -> RUBIRIZI-KAMPALA | G21: =ROUNDUP(COUNTIF('PT-01'!$L$468:$L$609,Summary!F21)/5,0) -> 1 | H21: 365 | I21: =AVERAGEIF('PT-01'!$L$468:$L$609,Summary!F21,'PT-01'!$O$468:$O$609) -> 6.3 | J21: =AVERAGEIF('PT-01'!$L$468:$L$609,Summary!F21,'PT-01'!$M$468:$M$609) -> 39.5 | K21: =AVERAGEIF('PT-01'!$L$468:$L$609,Summary!F21,'PT-01'!$N$468:$N$609) -> 21500
B24: JAGUAR BUS SERVICES | D24: BUS JOURNEY | J24: PASSENGER DETAILS
B25: STATION | C25: DIRECTION | D25: ORIGIN | E25: DESTINATION | F25: ROUTE ID | G25: BUS TRIPS / DAY | H25: JOURNEY DISTANCE (KM) | I25: JOURNEY TIME/ TRIP (HRS) | J25: EST. PAX/ BUS | K25: AVERAGE PAX FARE (UGX)
B26: KAMPALA | C26: FROM KAMPALA | D26: KAMPALA | E26: DRC | F26: =D26&"-"&E26 -> KAMPALA-DRC | G26: =ROUNDUP(COUNTIF('PT-01'!$L$611:$L$699,Summary!F26)/5,0) -> 1 | H26: 570 | I26: =AVERAGEIF('PT-01'!$L$611:$L$699,Summary!F26,'PT-01'!$O$611:$O$699) -> 12 | J26: =AVERAGEIF('PT-01'!$L$611:$L$699,Summary!F26,'PT-01'!$M$611:$M$699) -> 64 | K26: =AVERAGEIF('PT-01'!$L$611:$L$699,Summary!F26,'PT-01'!$N$611:$N$699) -> 50000
B27: KAMPALA | C27: FROM KAMPALA | D27: KAMPALA | E27: KAMEMBE | F27: =D27&"-"&E27 -> KAMPALA-KAMEMBE | G27: =ROUNDUP(COUNTIF('PT-01'!$L$611:$L$699,Summary!F27)/5,0) -> 1 | H27: 744 | I27: =AVERAGEIF('PT-01'!$L$611:$L$699,Summary!F27,'PT-01'!$O$611:$O$699) -> 13.8 | J27: =AVERAGEIF('PT-01'!$L$611:$L$699,Summary!F27,'PT-01'!$M$611:$M$699) -> 55 | K27: =AVERAGEIF('PT-01'!$L$611:$L$699,Summary!F27,'PT-01'!$N$611:$N$699) -> 60000
B28: KAMPALA | C28: FROM KAMPALA | D28: KAMPALA | E28: KANYALU | F28: =D28&"-"&E28 -> KAMPALA-KANYALU | G28: =ROUNDUP(COUNTIF('PT-01'!$L$611:$L$699,Summary!F28)/5,0) -> 1 | H28: 617 | I28: =AVERAGEIF('PT-01'!$L$611:$L$699,Summary!F28,'PT-01'!$O$611:$O$699) -> 11 | J28: =AVERAGEIF('PT-01'!$L$611:$L$699,Summary!F28,'PT-01'!$M$611:$M$699) -> 45.5 | K28: =AVERAGEIF('PT-01'!$L$611:$L$699,Summary!F28,'PT-01'!$N$611:$N$699) -> 60000
B29: KAMPALA | C29: FROM KAMPALA | D29: KAMPALA | E29: KIGALI | F29: =D29&"-"&E29 -> KAMPALA-KIGALI | G29: =ROUNDUP(COUNTIF('PT-01'!$L$611:$L$699,Summary!F29)/5,0) -> 2 | H29: 510 | I29: =AVERAGEIF('PT-01'!$L$611:$L$699,Summary!F29,'PT-01'!$O$611:$O$699) -> 8.6 | J29: =AVERAGEIF('PT-01'!$L$611:$L$699,Summary!F29,'PT-01'!$M$611:$M$699) -> 48.333333 | K29: =AVERAGEIF('PT-01'!$L$611:$L$699,Summary!F29,'PT-01'!$N$611:$N$699) -> 50000
B30: KAMPALA | C30: FROM KAMPALA | D30: KAMPALA | E30: GOMA | F30: =D30&"-"&E30 -> KAMPALA-GOMA | G30: =ROUNDUP(COUNTIF('PT-01'!$L$611:$L$699,Summary!F30)/5,0) -> 1 | H30: 570 | I30: =AVERAGEIF('PT-01'!$L$611:$L$699,Summary!F30,'PT-01'!$O$611:$O$699) -> 12 | J30: =AVERAGEIF('PT-01'!$L$611:$L$699,Summary!F30,'PT-01'!$M$611:$M$699) -> 48 | K30: =AVERAGEIF('PT-01'!$L$611:$L$699,Summary!F30,'PT-01'!$N$611:$N$699) -> 50000
B31: KAMPALA | C31: FROM KAMPALA | D31: KAMPALA | E31: KISORO | F31: =D31&"-"&E31 -> KAMPALA-KISORO | G31: =ROUNDUP(COUNTIF('PT-01'!$L$611:$L$699,Summary!F31)/5,0) -> 5 | H31: 467 | I31: =AVERAGEIF('PT-01'!$L$611:$L$699,Summary!F31,'PT-01'!$O$611:$O$699) -> 8.5 | J31: =AVERAGEIF('PT-01'!$L$611:$L$699,Summary!F31,'PT-01'!$M$611:$M$699) -> 56.88 | K31: =AVERAGEIF('PT-01'!$L$611:$L$699,Summary!F31,'PT-01'!$N$611:$N$699) -> 40000
B32: KAMPALA | C32: FROM KAMPALA | D32: KAMPALA | E32: KIVU/KISENYI | F32: =D32&"-"&E32 -> KAMPALA-KIVU/KISENYI | G32: =ROUNDUP(COUNTIF('PT-01'!$L$611:$L$699,Summary!F32)/5,0) -> 1 | H32: 694 | I32: =AVERAGEIF('PT-01'!$L$611:$L$699,Summary!F32,'PT-01'!$O$611:$O$699) -> 13.25 | J32: =AVERAGEIF('PT-01'!$L$611:$L$699,Summary!F32,'PT-01'!$M$611:$M$699) -> 48 | K32: =AVERAGEIF('PT-01'!$L$611:$L$699,Summary!F32,'PT-01'!$N$611:$N$699) -> 50000
B33: KAMPALA | C33: FROM KAMPALA | D33: KAMPALA | E33: LUBAVU | F33: =D33&"-"&E33 -> KAMPALA-LUBAVU | G33: =ROUNDUP(COUNTIF('PT-01'!$L$611:$L$699,Summary!F33)/5,0) -> 1 | H33: 570 | I33: =AVERAGEIF('PT-01'!$L$611:$L$699,Summary!F33,'PT-01'!$O$611:$O$699) -> 12 | J33: =AVERAGEIF('PT-01'!$L$611:$L$699,Summary!F33,'PT-01'!$M$611:$M$699) -> 48 | K33: =AVERAGEIF('PT-01'!$L$611:$L$699,Summary!F33,'PT-01'!$N$611:$N$699) -> 50000
B34: KAMPALA | C34: TO KAMPALA | D34: GISENYI | E34: KAMPALA | F34: =D34&"-"&E34 -> GISENYI-KAMPALA | G34: =ROUNDUP(COUNTIF('PT-01'!$L$611:$L$699,Summary!F34)/5,0) -> 1 | H34: 669 | I34: =AVERAGEIF('PT-01'!$L$611:$L$699,Summary!F34,'PT-01'!$O$611:$O$699) -> 12.25 | J34: =AVERAGEIF('PT-01'!$L$611:$L$699,Summary!F34,'PT-01'!$M$611:$M$699) -> 46 | K34: =AVERAGEIF('PT-01'!$L$611:$L$699,Summary!F34,'PT-01'!$N$611:$N$699) -> 40000
B35: KAMPALA | C35: TO KAMPALA | D35: GOMA | E35: KAMPALA | F35: =D35&"-"&E35 -> GOMA-KAMPALA | G35: =ROUNDUP(COUNTIF('PT-01'!$L$611:$L$699,Summary!F35)/5,0) -> 1 | H35: 570 | I35: =AVERAGEIF('PT-01'!$L$611:$L$699,Summary!F35,'PT-01'!$O$611:$O$699) -> 12 | J35: =AVERAGEIF('PT-01'!$L$611:$L$699,Summary!F35,'PT-01'!$M$611:$M$699) -> 48.5 | K35: =AVERAGEIF('PT-01'!$L$611:$L$699,Summary!F35,'PT-01'!$N$611:$N$699) -> 46500
B36: KAMPALA | C36: TO KAMPALA | D36: KABALE | E36: KAMPALA | F36: =D36&"-"&E36 -> KABALE-KAMPALA | G36: =ROUNDUP(COUNTIF('PT-01'!$L$611:$L$699,Summary!F36)/5,0) -> 1 | H36: 410 | I36: =AVERAGEIF('PT-01'!$L$611:$L$699,Summary!F36,'PT-01'!$O$611:$O$699) -> 6.6 | J36: =AVERAGEIF('PT-01'!$L$611:$L$699,Summary!F36,'PT-01'!$M$611:$M$699) -> 50 | K36: =AVERAGEIF('PT-01'!$L$611:$L$699,Summary!F36,'PT-01'!$N$611:$N$699) -> 30000
B37: KAMPALA | C37: TO KAMPALA | D37: KIGALI | E37: KAMPALA | F37: =D37&"-"&E37 -> KIGALI-KAMPALA | G37: =ROUNDUP(COUNTIF('PT-01'!$L$611:$L$699,Summary!F37)/5,0) -> 2 | H37: 510 | I37: =AVERAGEIF('PT-01'!$L$611:$L$699,Summary!F37,'PT-01'!$O$611:$O$699) -> 8.6 | J37: =AVERAGEIF('PT-01'!$L$611:$L$699,Summary!F37,'PT-01'!$M$611:$M$699) -> 48.9 | K37: =AVERAGEIF('PT-01'!$L$611:$L$699,Summary!F37,'PT-01'!$N$611:$N$699) -> 50000
... B42: KAMPALA | C42: TO KAMPALA | D42: NARUKOKO | E42: KAMPALA | F42: =D42&"-"&E42 -> NARUKOKO-KAMPALA | G42: =ROUNDUP(COUNTIF('PT-01'!$L$611:$L$699,Summary!F42)/5,0) -> 1 | H42: 520 | I42: =AVERAGEIF('PT-01'!$L$611:$L$699,Summary!F42,'PT-01'!$O$611:$O$699) -> 11 | J42: =AVERAGEIF('PT-01'!$L$611:$L$699,Summary!F42,'PT-01'!$M$611:$M$699) -> 45 | K42: =AVERAGEIF('PT-01'!$L$611:$L$699,Summary!F42,'PT-01'!$N$611:$N$699) -> 40000
B45: EASY COACHES | D45: BUS JOURNEY | J45: PASSENGER DETAILS
B46: STATION | C46: DIRECTION | D46: ORIGIN | E46: DESTINATION | F46: ROUTE ID | G46: BUS TRIPS / DAY | H46: JOURNEY DISTANCE (KM) | I46: JOURNEY TIME/ TRIP (HRS) | J46: EST. PAX/ BUS | K46: AVERAGE PAX FARE (UGX)
B47: KAMPALA | C47: FROM KAMPALA | D47: KAMPALA | E47: NAIROBI | F47: =D47&"-"&E47 -> KAMPALA-NAIROBI | G47: =ROUNDUP(COUNTIF('PT-01'!$L$701:$L$735,Summary!F47)/5,0) -> 3 | H47: 664 | I47: =AVERAGEIF('PT-01'!$L$701:$L$735,Summary!F47,'PT-01'!$O$701:$O$735) -> 12.8 | J47: =AVERAGEIF('PT-01'!$L$701:$L$735,Summary!F47,'PT-01'!$M$701:$M$735) -> 30.230769 | K47: =AVERAGEIF('PT-01'!$L$701:$L$735,Summary!F47,'PT-01'!$N$701:$N$735) -> 70000
B48: KAMPALA | C48: TO KAMPALA | D48: NAIROBI | E48: KAMPALA | F48: =D48&"-"&E48 -> NAIROBI-KAMPALA | G48: =ROUNDUP(COUNTIF('PT-01'!$L$701:$L$735,Summary!F48)/5,0) -> 3 | H48: 664 | I48: =AVERAGEIF('PT-01'!$L$701:$L$735,Summary!F48,'PT-01'!$O$701:$O$735) -> 12.8 | J48: =AVERAGEIF('PT-01'!$L$701:$L$735,Summary!F48,'PT-01'!$M$701:$M$735) -> 32.923077 | K48: =AVERAGEIF('PT-01'!$L$701:$L$735,Summary!F48,'PT-01'!$N$701:$N$735) -> 73000
B49: KAMPALA | C49: TO KAMPALA | D49: KISUMU | E49: KAMPALA | F49: =D49&"-"&E49 -> KISUMU-KAMPALA | G49: =ROUNDUP(COUNTIF('PT-01'!$L$701:$L$735,Summary!F49)/5,0) -> 1 | H49: 316 | I49: =AVERAGEIF('PT-01'!$L$701:$L$735,Summary!F49,'PT-01'!$O$701:$O$735) -> 6.8 | J49: =AVERAGEIF('PT-01'!$L$701:$L$735,Summary!F49,'PT-01'!$M$701:$M$735) -> 32.25 | K49: =AVERAGEIF('PT-01'!$L$701:$L$735,Summary!F49,'PT-01'!$N$701:$N$735) -> 42000
B50: KAMPALA | C50: TO KAMPALA | D50: MAKUENI | E50: KAMPALA | F50: =D50&"-"&E50 -> MAKUENI-KAMPALA | G50: =ROUNDUP(COUNTIF('PT-01'!$L$701:$L$735,Summary!F50)/5,0) -> 1 | H50: 846 | I50: =AVERAGEIF('PT-01'!$L$701:$L$735,Summary!F50,'PT-01'!$O$701:$O$735) -> 15.5 | J50: =AVERAGEIF('PT-01'!$L$701:$L$735,Summary!F50,'PT-01'!$M$701:$M$735) -> 34 | K50: =AVERAGEIF('PT-01'!$L$701:$L$735,Summary!F50,'PT-01'!$N$701:$N$735) -> 76000
B53: KK BUS SERVICES | D53: BUS JOURNEY | J53: PASSENGER DETAILS
B54: STATION | C54: DIRECTION | D54: ORIGIN | E54: DESTINATION | F54: ROUTE ID | G54: BUS TRIPS / DAY | H54: JOURNEY DISTANCE (KM) | I54: JOURNEY TIME/ TRIP (HRS) | J54: EST. PAX/ BUS | K54: AVERAGE PAX FARE (UGX)
...

Sheet Key
B1: Vehicle Type
A2: 1 | B2: Car
A3: 2 | B3: Station Wagon
A4: 3 | B4: Pickups
A5: 4 | B5: Minibus, matatu
A6: 5 | B6: Medium bus
A7: 6 | B7: Large Bus
A8: 7 | B8: Light Truck
A9: 8 | B9: Medium Truck
A10: 9 | B10: Heavy truck
A11: 10 | B11: Truck Trailer
A12: 11 | B12: Motor cycles
A13: 12 | B13: Tractors
