Workbook

Sheet 29.07 Nalya-Bweyogerere
B1: Consultancy services for Preparation of Expressway Development Master Plan (EDMP) for Uganda
B2: MANUAL CLASSIFIED COUNT (MCC)
B3: ROAD NAME: | C3: MCC - C1 - STN40 - NORTHERN BYPASS
C5: Date | D5: 29.07.19 | F5: Location | G5: Signs and Symbols | J5: Surveyor | K5: Acema Vicent/Aseru Sherry/Mejje Mathias Trevor/Martin Anthony
C6: Dir. From | D6: Naalya | F6: Dir. To | G6: Bweyogerere | J6: Supervisor | K6: Steven
B8: Time / Veh Type | R8: SUMMARY TRAFFIC VOLUMES
C9: 1. Car | D9: 2. Station Wagon | E9: 3. Pickups | F9: 4. Minibus, matatu | G9: 5. Medium bus | H9: 6. Large Bus | I9: 7. Light Truck | J9: 8. Medium Truck | K9: 9. Heavy truck | L9: 10. Truck Trailer | M9: 11. Motor cycles | N9: 12. Tractors | O9: Total Excl M/Cycles | P9: Total All | R9: Time | S9: 1. Car | T9: 2. Station Wagon | U9: 3. Pickups | V9: 4. Minibus, matatu | W9: 5. Medium bus | X9: 6. Large Bus | Y9: 7. Light Truck | Z9: 8. Medium Truck | AA9: 9. Heavy truck | AB9: 10. Truck Trailer | AC9: 11. Motorcycles | AD9: 12. Tractors, Graders | AE9: Total Excl M/ Cycles | AF9: Total All
B10: 07.00 - 07.15 | C10: 0 | D10: 0 | E10: 0 | F10: 0 | G10: 0 | H10: 0 | I10: 0 | J10: 0 | K10: 0 | L10: 0 | M10: 0 | N10: 0 | O10: =SUM(C10:L10,N10) -> 0 | P10: =SUM(C10:N10) -> 0 | R10: 0700-0800 | S10: =SUM(C10:C13) -> 0 | T10: =SUM(D10:D13) -> 0 | U10: =SUM(E10:E13) -> 0 | V10: =SUM(F10:F13) -> 0 | W10: =SUM(G10:G13) -> 0 | X10: =SUM(H10:H13) -> 0 | Y10: =SUM(I10:I13) -> 0 | Z10: =SUM(J10:J13) -> 0 | ... AF10: =SUM(P10:P13) -> 0
B11: 07.15 - 07.30 | C11: 0 | D11: 0 | E11: 0 | F11: 0 | G11: 0 | H11: 0 | I11: 0 | J11: 0 | K11: 0 | L11: 0 | M11: 0 | N11: 0 | O11: =SUM(C11:L11,N11) -> 0 | P11: =SUM(C11:N11) -> 0 | R11: 0800-0900 | S11: =SUM(C14:C17) -> 0 | T11: =SUM(D14:D17) -> 0 | U11: =SUM(E14:E17) -> 0 | V11: =SUM(F14:F17) -> 0 | W11: =SUM(G14:G17) -> 0 | X11: =SUM(H14:H17) -> 0 | Y11: =SUM(I14:I17) -> 0 | Z11: =SUM(J14:J17) -> 0 | ... AF11: =SUM(P14:P17) -> 0
B12: 07.30 - 07.45 | C12: 0 | D12: 0 | E12: 0 | F12: 0 | G12: 0 | H12: 0 | I12: 0 | J12: 0 | K12: 0 | L12: 0 | M12: 0 | N12: 0 | O12: =SUM(C12:L12,N12) -> 0 | P12: =SUM(C12:N12) -> 0 | R12: 0900-1000 | S12: =SUM(C18:C21) -> 35 | T12: =SUM(D18:D21) -> 5 | U12: =SUM(E18:E21) -> 12 | V12: =SUM(F18:F21) -> 45 | W12: =SUM(G18:G21) -> 0 | X12: =SUM(H18:H21) -> 0 | Y12: =SUM(I18:I21) -> 6 | Z12: =SUM(J18:J21) -> 13 | ... AF12: =SUM(P18:P21) -> 206
B13: 07.45 - 08.00 | C13: 0 | D13: 0 | E13: 0 | F13: 0 | G13: 0 | H13: 0 | I13: 0 | J13: 0 | K13: 0 | L13: 0 | M13: 0 | N13: 0 | O13: =SUM(C13:L13,N13) -> 0 | P13: =SUM(C13:N13) -> 0 | R13: 1000-1100 | S13: =SUM(C22:C25) -> 86 | T13: =SUM(D22:D25) -> 9 | U13: =SUM(E22:E25) -> 17 | V13: =SUM(F22:F25) -> 97 | W13: =SUM(G22:G25) -> 2 | X13: =SUM(H22:H25) -> 0 | Y13: =SUM(I22:I25) -> 30 | Z13: =SUM(J22:J25) -> 17 | ... AF13: =SUM(P22:P25) -> 420
B14: 08.00 - 08.15 | C14: 0 | D14: 0 | E14: 0 | F14: 0 | G14: 0 | H14: 0 | I14: 0 | J14: 0 | K14: 0 | L14: 0 | M14: 0 | N14: 0 | O14: =SUM(C14:L14,N14) -> 0 | P14: =SUM(C14:N14) -> 0 | R14: 1100-1200 | S14: =SUM(C26:C29) -> 70 | T14: =SUM(D26:D29) -> 15 | U14: =SUM(E26:E29) -> 14 | V14: =SUM(F26:F29) -> 73 | W14: =SUM(G26:G29) -> 2 | X14: =SUM(H26:H29) -> 0 | Y14: =SUM(I26:I29) -> 36 | Z14: =SUM(J26:J29) -> 19 | ... AF14: =SUM(P26:P29) -> 395
B15: 08.15 - 08.30 | C15: 0 | D15: 0 | E15: 0 | F15: 0 | G15: 0 | H15: 0 | I15: 0 | J15: 0 | K15: 0 | L15: 0 | M15: 0 | N15: 0 | O15: =SUM(C15:L15,N15) -> 0 | P15: =SUM(C15:N15) -> 0 | R15: 1200-1300 | S15: =SUM(C30:C33) -> 79 | T15: =SUM(D30:D33) -> 14 | U15: =SUM(E30:E33) -> 5 | V15: =SUM(F30:F33) -> 85 | W15: =SUM(G30:G33) -> 1 | X15: =SUM(H30:H33) -> 1 | Y15: =SUM(I30:I33) -> 24 | Z15: =SUM(J30:J33) -> 12 | ... AF15: =SUM(P30:P33) -> 393
B16: 08.30 - 08.45 | C16: 0 | D16: 0 | E16: 0 | F16: 0 | G16: 0 | H16: 0 | I16: 0 | J16: 0 | K16: 0 | L16: 0 | M16: 0 | N16: 0 | O16: =SUM(C16:L16,N16) -> 0 | P16: =SUM(C16:N16) -> 0 | R16: 1300-1400 | S16: =SUM(C34:C37) -> 49 | T16: =SUM(D34:D37) -> 9 | U16: =SUM(E34:E37) -> 9 | V16: =SUM(F34:F37) -> 72 | W16: =SUM(G34:G37) -> 0 | X16: =SUM(H34:H37) -> 0 | Y16: =SUM(I34:I37) -> 28 | Z16: =SUM(J34:J37) -> 11 | ... AF16: =SUM(P34:P37) -> 348
B17: 08.45 - 9.00 | C17: 0 | D17: 0 | E17: 0 | F17: 0 | G17: 0 | H17: 0 | I17: 0 | J17: 0 | K17: 0 | L17: 0 | M17: 0 | N17: 0 | O17: =SUM(C17:L17,N17) -> 0 | P17: =SUM(C17:N17) -> 0 | R17: 1400-1500 | S17: =SUM(C38:C41) -> 44 | T17: =SUM(D38:D41) -> 15 | U17: =SUM(E38:E41) -> 16 | V17: =SUM(F38:F41) -> 56 | W17: =SUM(G38:G41) -> 0 | X17: =SUM(H38:H41) -> 0 | Y17: =SUM(I38:I41) -> 12 | Z17: =SUM(J38:J41) -> 11 | ... AF17: =SUM(P38:P41) -> 307
B18: 09.00 - 09.15 | C18: 0 | D18: 0 | E18: 0 | F18: 0 | G18: 0 | H18: 0 | I18: 0 | J18: 0 | K18: 0 | L18: 0 | M18: 0 | N18: 0 | O18: =SUM(C18:L18,N18) -> 0 | P18: =SUM(C18:N18) -> 0 | R18: 1500-1600 | S18: =SUM(C42:C45) -> 83 | T18: =SUM(D42:D45) -> 15 | U18: =SUM(E42:E45) -> 18 | V18: =SUM(F42:F45) -> 80 | W18: =SUM(G42:G45) -> 0 | X18: =SUM(H42:H45) -> 2 | Y18: =SUM(I42:I45) -> 25 | Z18: =SUM(J42:J45) -> 18 | ... AF18: =SUM(P42:P45) -> 480
B19: 09.15 - 09.30 | C19: 0 | D19: 0 | E19: 0 | F19: 0 | G19: 0 | H19: 0 | I19: 0 | J19: 0 | K19: 0 | L19: 0 | M19: 0 | N19: 0 | O19: =SUM(C19:L19,N19) -> 0 | P19: =SUM(C19:N19) -> 0 | R19: 1600-1700 | S19: =SUM(C46:C49) -> 89 | T19: =SUM(D46:D49) -> 29 | U19: =SUM(E46:E49) -> 29 | V19: =SUM(F46:F49) -> 79 | W19: =SUM(G46:G49) -> 0 | X19: =SUM(H46:H49) -> 0 | Y19: =SUM(I46:I49) -> 27 | Z19: =SUM(J46:J49) -> 17 | ... AF19: =SUM(P46:P49) -> 451
B20: 09.30 - 09.45 | C20: 10 | D20: 1 | E20: 6 | F20: 17 | G20: 0 | H20: 0 | I20: 4 | J20: 4 | K20: 11 | L20: 3 | M20: 28 | N20: 0 | O20: =SUM(C20:L20,N20) -> 56 | P20: =SUM(C20:N20) -> 84 | R20: 1700-1800 | S20: =SUM(C50:C53) -> 141 | T20: =SUM(D50:D53) -> 27 | U20: =SUM(E50:E53) -> 37 | V20: =SUM(F50:F53) -> 102 | W20: =SUM(G50:G53) -> 1 | X20: =SUM(H50:H53) -> 5 | Y20: =SUM(I50:I53) -> 26 | Z20: =SUM(J50:J53) -> 14 | ... AF20: =SUM(P50:P53) -> 550
B21: 09.45 - 10.00 | C21: 25 | D21: 4 | E21: 6 | F21: 28 | G21: 0 | H21: 0 | I21: 2 | J21: 9 | K21: 5 | L21: 6 | M21: 37 | N21: 0 | O21: =SUM(C21:L21,N21) -> 85 | P21: =SUM(C21:N21) -> 122 | R21: 1800-1900 | S21: =SUM(C54:C57) -> 184 | T21: =SUM(D54:D57) -> 35 | U21: =SUM(E54:E57) -> 26 | V21: =SUM(F54:F57) -> 121 | W21: =SUM(G54:G57) -> 4 | X21: =SUM(H54:H57) -> 0 | Y21: =SUM(I54:I57) -> 25 | Z21: =SUM(J54:J57) -> 17 | ... AF21: =SUM(P54:P57) -> 608
B22: 10.00 - 10.15 | C22: 27 | D22: 2 | E22: 4 | F22: 27 | G22: 0 | H22: 0 | I22: 11 | J22: 5 | K22: 6 | L22: 6 | M22: 29 | N22: 0 | O22: =SUM(C22:L22,N22) -> 88 | P22: =SUM(C22:N22) -> 117 | R22: AM Peak Hr | S22: =MAX(S10:S12) -> 35 | T22: =MAX(T10:T12) -> 5 | U22: =MAX(U10:U12) -> 12 | V22: =MAX(V10:V12) -> 45 | W22: =MAX(W10:W12) -> 0 | X22: =MAX(X10:X12) -> 0 | Y22: =MAX(Y10:Y12) -> 6 | Z22: =MAX(Z10:Z12) -> 13 | ... AF22: =MAX(AF10:AF12) -> 206
B23: 10.15 - 10.30 | C23: 18 | D23: 3 | E23: 6 | F23: 29 | G23: 1 | H23: 0 | I23: 6 | J23: 2 | K23: 6 | L23: 1 | M23: 30 | N23: 0 | O23: =SUM(C23:L23,N23) -> 72 | P23: =SUM(C23:N23) -> 102 | R23: IP Peak Hr | S23: =MAX(S13:S18) -> 86 | T23: =MAX(T13:T18) -> 15 | U23: =MAX(U13:U18) -> 18 | V23: =MAX(V13:V18) -> 97 | W23: =MAX(W13:W18) -> 2 | X23: =MAX(X13:X18) -> 2 | Y23: =MAX(Y13:Y18) -> 36 | Z23: =MAX(Z13:Z18) -> 19 | ... AF23: =MAX(AF13:AF18) -> 480
B24: 10.30 - 10.45 | C24: 19 | D24: 3 | E24: 4 | F24: 14 | G24: 1 | H24: 0 | I24: 7 | J24: 2 | K24: 2 | L24: 4 | M24: 21 | N24: 0 | O24: =SUM(C24:L24,N24) -> 56 | P24: =SUM(C24:N24) -> 77 | R24: PM Peak Hr | S24: =MAX(S19:S21) -> 184 | T24: =MAX(T19:T21) -> 35 | U24: =MAX(U19:U21) -> 37 | V24: =MAX(V19:V21) -> 121 | W24: =MAX(W19:W21) -> 4 | X24: =MAX(X19:X21) -> 5 | Y24: =MAX(Y19:Y21) -> 27 | Z24: =MAX(Z19:Z21) -> 17 | ... AF24: =MAX(AF19:AF21) -> 608
B25: 10.45 - 11.00 | C25: 22 | D25: 1 | E25: 3 | F25: 27 | G25: 0 | H25: 0 | I25: 6 | J25: 8 | K25: 6 | L25: 7 | M25: 44 | N25: 0 | O25: =SUM(C25:L25,N25) -> 80 | P25: =SUM(C25:N25) -> 124 | R25: AM Period | S25: =SUM(S10:S12) -> 35 | T25: =SUM(T10:T12) -> 5 | U25: =SUM(U10:U12) -> 12 | V25: =SUM(V10:V12) -> 45 | W25: =SUM(W10:W12) -> 0 | X25: =SUM(X10:X12) -> 0 | Y25: =SUM(Y10:Y12) -> 6 | Z25: =SUM(Z10:Z12) -> 13 | ... AF25: =SUM(AF10:AF12) -> 206
B26: 11.00 - 11.15 | C26: 11 | D26: 1 | E26: 0 | F26: 20 | G26: 2 | H26: 0 | I26: 6 | J26: 4 | K26: 2 | L26: 2 | M26: 24 | N26: 0 | O26: =SUM(C26:L26,N26) -> 48 | P26: =SUM(C26:N26) -> 72 | R26: IP Period | S26: =SUM(S13:S18) -> 411 | T26: =SUM(T13:T18) -> 77 | U26: =SUM(U13:U18) -> 79 | V26: =SUM(V13:V18) -> 463 | W26: =SUM(W13:W18) -> 5 | X26: =SUM(X13:X18) -> 3 | Y26: =SUM(Y13:Y18) -> 155 | Z26: =SUM(Z13:Z18) -> 88 | ... AF26: =SUM(AF13:AF18) -> 2343
B27: 11.15 - 11.30 | C27: 17 | D27: 5 | E27: 2 | F27: 13 | G27: 0 | H27: 0 | I27: 8 | J27: 8 | K27: 8 | L27: 5 | M27: 31 | N27: 0 | O27: =SUM(C27:L27,N27) -> 66 | P27: =SUM(C27:N27) -> 97 | R27: PM Period | S27: =SUM(S19:S21) -> 414 | T27: =SUM(T19:T21) -> 91 | U27: =SUM(U19:U21) -> 92 | V27: =SUM(V19:V21) -> 302 | W27: =SUM(W19:W21) -> 5 | X27: =SUM(X19:X21) -> 5 | Y27: =SUM(Y19:Y21) -> 78 | Z27: =SUM(Z19:Z21) -> 48 | ... AF27: =SUM(AF19:AF21) -> 1609
B28: 11.30 - 11.45 | C28: 22 | D28: 6 | E28: 6 | F28: 24 | G28: 0 | H28: 0 | I28: 15 | J28: 6 | K28: 8 | L28: 6 | M28: 29 | N28: 0 | O28: =SUM(C28:L28,N28) -> 93 | P28: =SUM(C28:N28) -> 122 | R28: 12 Hours | S28: =SUM(S10:S21) -> 860 | T28: =SUM(T10:T21) -> 173 | U28: =SUM(U10:U21) -> 183 | V28: =SUM(V10:V21) -> 810 | W28: =SUM(W10:W21) -> 10 | X28: =SUM(X10:X21) -> 8 | Y28: =SUM(Y10:Y21) -> 239 | Z28: =SUM(Z10:Z21) -> 149 | ... AF28: =SUM(AF10:AF21) -> 4158
B29: 11.45 - 12.00 | C29: 20 | D29: 3 | E29: 6 | F29: 16 | G29: 0 | H29: 0 | I29: 7 | J29: 1 | K29: 6 | L29: 6 | M29: 39 | N29: 0 | O29: =SUM(C29:L29,N29) -> 65 | P29: =SUM(C29:N29) -> 104
B30: 12.00 - 12.15 | C30: 20 | D30: 3 | E30: 2 | F30: 17 | G30: 0 | H30: 0 | I30: 6 | J30: 2 | K30: 1 | L30: 8 | M30: 35 | N30: 0 | O30: =SUM(C30:L30,N30) -> 59 | P30: =SUM(C30:N30) -> 94
B31: 12.15 - 12.30 | C31: 19 | D31: 2 | E31: 0 | F31: 20 | G31: 0 | H31: 1 | I31: 2 | J31: 3 | K31: 3 | L31: 8 | M31: 28 | N31: 0 | O31: =SUM(C31:L31,N31) -> 58 | P31: =SUM(C31:N31) -> 86
B32: 12.30 - 12.45 | C32: 17 | D32: 6 | E32: 0 | F32: 27 | G32: 1 | H32: 0 | I32: 6 | J32: 4 | K32: 2 | L32: 6 | M32: 36 | N32: 0 | O32: =SUM(C32:L32,N32) -> 69 | P32: =SUM(C32:N32) -> 105
B33: 12.45 - 13.00 | C33: 23 | D33: 3 | E33: 3 | F33: 21 | G33: 0 | H33: 0 | I33: 10 | J33: 3 | K33: 5 | L33: 6 | M33: 34 | N33: 0 | O33: =SUM(C33:L33,N33) -> 74 | P33: =SUM(C33:N33) -> 108
B34: 13.00 - 13.15 | C34: 14 | D34: 2 | E34: 1 | F34: 19 | G34: 0 | H34: 0 | I34: 4 | J34: 4 | K34: 1 | L34: 4 | M34: 43 | N34: 0 | O34: =SUM(C34:L34,N34) -> 49 | P34: =SUM(C34:N34) -> 92
B35: 13.15 - 13.30 | C35: 13 | D35: 0 | E35: 1 | F35: 22 | G35: 0 | H35: 0 | I35: 8 | J35: 1 | K35: 4 | L35: 3 | M35: 39 | N35: 0 | O35: =SUM(C35:L35,N35) -> 52 | P35: =SUM(C35:N35) -> 91
B36: 13.30 - 13.45 | C36: 9 | D36: 2 | E36: 2 | F36: 13 | G36: 0 | H36: 0 | I36: 8 | J36: 3 | K36: 5 | L36: 4 | M36: 28 | N36: 0 | O36: =SUM(C36:L36,N36) -> 46 | P36: =SUM(C36:N36) -> 74
B37: 13.45 - 14.00 | C37: 13 | D37: 5 | E37: 5 | F37: 18 | G37: 0 | H37: 0 | I37: 8 | J37: 3 | K37: 5 | L37: 11 | M37: 23 | N37: 0 | O37: =SUM(C37:L37,N37) -> 68 | P37: =SUM(C37:N37) -> 91
B38: 14.00 - 14.15 | C38: 20 | D38: 2 | E38: 8 | F38: 15 | G38: 0 | H38: 0 | I38: 4 | J38: 3 | K38: 6 | L38: 11 | M38: 34 | N38: 1 | O38: =SUM(C38:L38,N38) -> 70 | P38: =SUM(C38:N38) -> 104
B39: 14.15 - 14.30 | C39: 8 | D39: 4 | E39: 5 | F39: 15 | G39: 0 | H39: 0 | I39: 2 | J39: 3 | K39: 1 | L39: 1 | M39: 32 | N39: 0 | O39: =SUM(C39:L39,N39) -> 39 | P39: =SUM(C39:N39) -> 71
B40: 14.30 - 14.45 | C40: 5 | D40: 7 | E40: 2 | F40: 10 | G40: 0 | H40: 0 | I40: 2 | J40: 3 | K40: 7 | L40: 2 | M40: 25 | N40: 0 | O40: =SUM(C40:L40,N40) -> 38 | P40: =SUM(C40:N40) -> 63
... B57: 18.45 - 19.00 | C57: 47 | D57: 8 | E57: 9 | F57: 36 | G57: 0 | H57: 0 | I57: 2 | J57: 2 | K57: 2 | L57: 3 | M57: 48 | N57: 0 | O57: =SUM(C57:L57,N57) -> 109 | P57: =SUM(C57:N57) -> 157
B58: Totals | C58: =SUM(C10:C57) -> 860 | D58: =SUM(D10:D57) -> 173 | E58: =SUM(E10:E57) -> 183 | F58: =SUM(F10:F57) -> 810 | G58: =SUM(G10:G57) -> 10 | H58: =SUM(H10:H57) -> 8 | I58: =SUM(I10:I57) -> 239 | J58: =SUM(J10:J57) -> 149 | ... P58: =SUM(P10:P57) -> 4158
...

Sheet 29.07 Bweyogerere-Nalya
B1: Consultancy services for Preparation of Expressway Development Master Plan (EDMP) for Uganda
B2: MANUAL CLASSIFIED COUNT (MCC)
B3: ROAD NAME: | C3: ='29.07 Nalya-Bweyogerere'!C3:G3 -> MCC - C1 - STN40 - NORTHERN BYPASS
C5: Date | D5: ='29.07 Nalya-Bweyogerere'!D5 -> 29.07.19 | F5: Location | G5: ='29.07 Nalya-Bweyogerere'!G5:H5 -> Signs and Symbols | J5: Surveyor | K5: ='29.07 Nalya-Bweyogerere'!K5:L5 -> Acema Vicent/Aseru Sherry/Mejje Mathias Trevor/Martin Anthony
C6: Dir. From | D6: Bweyogerere | F6: Dir. To | G6: Nalya | J6: Supervisor | K6: ='29.07 Nalya-Bweyogerere'!K6:L6 -> Steven
B8: Time / Veh Type | R8: SUMMARY TRAFFIC VOLUMES
C9: 1. Car | D9: 2. Station Wagon | E9: 3. Pickups | F9: 4. Minibus, matatu | G9: 5. Medium bus | H9: 6. Large Bus | I9: 7. Light Truck | J9: 8. Medium Truck | K9: 9. Heavy truck | L9: 10. Truck Trailer | M9: 11. Motor cycles | N9: 12. Tractors | O9: Total Excl M/Cycles | P9: Total All | R9: Time | S9: 1. Car | T9: 2. Station Wagon | U9: 3. Pickups | V9: 4. Minibus, matatu | W9: 5. Medium bus | X9: 6. Large Bus | Y9: 7. Light Truck | Z9: 8. Medium Truck | AA9: 9. Heavy truck | AB9: 10. Truck Trailer | AC9: 11. Motorcycles | AD9: 12. Tractors, Graders | AE9: Total Excl M/ Cycles | AF9: Total All
B10: 07.00 - 07.15 | C10: 0 | D10: 0 | E10: 0 | F10: 0 | G10: 0 | H10: 0 | I10: 0 | J10: 0 | K10: 0 | L10: 0 | M10: 0 | N10: 0 | O10: =SUM(C10:L10,N10) -> 0 | P10: =SUM(C10:N10) -> 0 | R10: 0700-0800 | S10: =SUM(C10:C13) -> 0 | T10: =SUM(D10:D13) -> 0 | U10: =SUM(E10:E13) -> 0 | V10: =SUM(F10:F13) -> 0 | W10: =SUM(G10:G13) -> 0 | X10: =SUM(H10:H13) -> 0 | Y10: =SUM(I10:I13) -> 0 | Z10: =SUM(J10:J13) -> 0 | ... AF10: =SUM(P10:P13) -> 0
B11: 07.15 - 07.30 | C11: 0 | D11: 0 | E11: 0 | F11: 0 | G11: 0 | H11: 0 | I11: 0 | J11: 0 | K11: 0 | L11: 0 | M11: 0 | N11: 0 | O11: =SUM(C11:L11,N11) -> 0 | P11: =SUM(C11:N11) -> 0 | R11: 0800-0900 | S11: =SUM(C14:C17) -> 0 | T11: =SUM(D14:D17) -> 0 | U11: =SUM(E14:E17) -> 0 | V11: =SUM(F14:F17) -> 0 | W11: =SUM(G14:G17) -> 0 | X11: =SUM(H14:H17) -> 0 | Y11: =SUM(I14:I17) -> 0 | Z11: =SUM(J14:J17) -> 0 | ... AF11: =SUM(P14:P17) -> 0
B12: 07.30 - 07.45 | C12: 0 | D12: 0 | E12: 0 | F12: 0 | G12: 0 | H12: 0 | I12: 0 | J12: 0 | K12: 0 | L12: 0 | M12: 0 | N12: 0 | O12: =SUM(C12:L12,N12) -> 0 | P12: =SUM(C12:N12) -> 0 | R12: 0900-1000 | S12: =SUM(C18:C21) -> 34 | T12: =SUM(D18:D21) -> 19 | U12: =SUM(E18:E21) -> 5 | V12: =SUM(F18:F21) -> 31 | W12: =SUM(G18:G21) -> 1 | X12: =SUM(H18:H21) -> 0 | Y12: =SUM(I18:I21) -> 5 | Z12: =SUM(J18:J21) -> 13 | ... AF12: =SUM(P18:P21) -> 187
B13: 07.45 - 08.00 | C13: 0 | D13: 0 | E13: 0 | F13: 0 | G13: 0 | H13: 0 | I13: 0 | J13: 0 | K13: 0 | L13: 0 | M13: 0 | N13: 0 | O13: =SUM(C13:L13,N13) -> 0 | P13: =SUM(C13:N13) -> 0 | R13: 1000-1100 | S13: =SUM(C22:C25) -> 57 | T13: =SUM(D22:D25) -> 44 | U13: =SUM(E22:E25) -> 14 | V13: =SUM(F22:F25) -> 95 | W13: =SUM(G22:G25) -> 0 | X13: =SUM(H22:H25) -> 0 | Y13: =SUM(I22:I25) -> 10 | Z13: =SUM(J22:J25) -> 20 | ... AF13: =SUM(P22:P25) -> 395
B14: 08.00 - 08.15 | C14: 0 | D14: 0 | E14: 0 | F14: 0 | G14: 0 | H14: 0 | I14: 0 | J14: 0 | K14: 0 | L14: 0 | M14: 0 | N14: 0 | O14: =SUM(C14:L14,N14) -> 0 | P14: =SUM(C14:N14) -> 0 | R14: 1100-1200 | S14: =SUM(C26:C29) -> 65 | T14: =SUM(D26:D29) -> 48 | U14: =SUM(E26:E29) -> 14 | V14: =SUM(F26:F29) -> 76 | W14: =SUM(G26:G29) -> 3 | X14: =SUM(H26:H29) -> 0 | Y14: =SUM(I26:I29) -> 32 | Z14: =SUM(J26:J29) -> 21 | ... AF14: =SUM(P26:P29) -> 424
B15: 08.15 - 08.30 | C15: 0 | D15: 0 | E15: 0 | F15: 0 | G15: 0 | H15: 0 | I15: 0 | J15: 0 | K15: 0 | L15: 0 | M15: 0 | N15: 0 | O15: =SUM(C15:L15,N15) -> 0 | P15: =SUM(C15:N15) -> 0 | R15: 1200-1300 | S15: =SUM(C30:C33) -> 100 | T15: =SUM(D30:D33) -> 46 | U15: =SUM(E30:E33) -> 22 | V15: =SUM(F30:F33) -> 72 | W15: =SUM(G30:G33) -> 2 | X15: =SUM(H30:H33) -> 2 | Y15: =SUM(I30:I33) -> 13 | Z15: =SUM(J30:J33) -> 40 | ... AF15: =SUM(P30:P33) -> 483
B16: 08.30 - 08.45 | C16: 0 | D16: 0 | E16: 0 | F16: 0 | G16: 0 | H16: 0 | I16: 0 | J16: 0 | K16: 0 | L16: 0 | M16: 0 | N16: 0 | O16: =SUM(C16:L16,N16) -> 0 | P16: =SUM(C16:N16) -> 0 | R16: 1300-1400 | S16: =SUM(C34:C37) -> 71 | T16: =SUM(D34:D37) -> 36 | U16: =SUM(E34:E37) -> 19 | V16: =SUM(F34:F37) -> 69 | W16: =SUM(G34:G37) -> 0 | X16: =SUM(H34:H37) -> 0 | Y16: =SUM(I34:I37) -> 20 | Z16: =SUM(J34:J37) -> 34 | ... AF16: =SUM(P34:P37) -> 411
B17: 08.45 - 9.00 | C17: 0 | D17: 0 | E17: 0 | F17: 0 | G17: 0 | H17: 0 | I17: 0 | J17: 0 | K17: 0 | L17: 0 | M17: 0 | N17: 0 | O17: =SUM(C17:L17,N17) -> 0 | P17: =SUM(C17:N17) -> 0 | R17: 1400-1500 | S17: =SUM(C38:C41) -> 59 | T17: =SUM(D38:D41) -> 21 | U17: =SUM(E38:E41) -> 12 | V17: =SUM(F38:F41) -> 51 | W17: =SUM(G38:G41) -> 0 | X17: =SUM(H38:H41) -> 2 | Y17: =SUM(I38:I41) -> 11 | Z17: =SUM(J38:J41) -> 38 | ... AF17: =SUM(P38:P41) -> 354
B18: 09.00 - 09.15 | C18: 0 | D18: 0 | E18: 0 | F18: 0 | G18: 0 | H18: 0 | I18: 0 | J18: 0 | K18: 0 | L18: 0 | M18: 0 | N18: 0 | O18: =SUM(C18:L18,N18) -> 0 | P18: =SUM(C18:N18) -> 0 | R18: 1500-1600 | S18: =SUM(C42:C45) -> 71 | T18: =SUM(D42:D45) -> 38 | U18: =SUM(E42:E45) -> 14 | V18: =SUM(F42:F45) -> 82 | W18: =SUM(G42:G45) -> 0 | X18: =SUM(H42:H45) -> 0 | Y18: =SUM(I42:I45) -> 19 | Z18: =SUM(J42:J45) -> 35 | ... AF18: =SUM(P42:P45) -> 472
B19: 09.15 - 09.30 | C19: 0 | D19: 0 | E19: 0 | F19: 0 | G19: 0 | H19: 0 | I19: 0 | J19: 0 | K19: 0 | L19: 0 | M19: 0 | N19: 0 | O19: =SUM(C19:L19,N19) -> 0 | P19: =SUM(C19:N19) -> 0 | R19: 1600-1700 | S19: =SUM(C46:C49) -> 58 | T19: =SUM(D46:D49) -> 32 | U19: =SUM(E46:E49) -> 18 | V19: =SUM(F46:F49) -> 76 | W19: =SUM(G46:G49) -> 1 | X19: =SUM(H46:H49) -> 1 | Y19: =SUM(I46:I49) -> 16 | Z19: =SUM(J46:J49) -> 25 | ... AF19: =SUM(P46:P49) -> 417
B20: 09.30 - 09.45 | C20: 15 | D20: 5 | E20: 1 | F20: 11 | G20: 0 | H20: 0 | I20: 0 | J20: 4 | K20: 2 | L20: 5 | M20: 23 | N20: 0 | O20: =SUM(C20:L20,N20) -> 43 | P20: =SUM(C20:N20) -> 66 | R20: 1700-1800 | S20: =SUM(C50:C53) -> 103 | T20: =SUM(D50:D53) -> 34 | U20: =SUM(E50:E53) -> 12 | V20: =SUM(F50:F53) -> 100 | W20: =SUM(G50:G53) -> 0 | X20: =SUM(H50:H53) -> 0 | Y20: =SUM(I50:I53) -> 15 | Z20: =SUM(J50:J53) -> 48 | ... AF20: =SUM(P50:P53) -> 540
B21: 09.45 - 10.00 | C21: 19 | D21: 14 | E21: 4 | F21: 20 | G21: 1 | H21: 0 | I21: 5 | J21: 9 | K21: 7 | L21: 7 | M21: 35 | N21: 0 | O21: =SUM(C21:L21,N21) -> 86 | P21: =SUM(C21:N21) -> 121 | R21: 1800-1900 | S21: =SUM(C54:C57) -> 85 | T21: =SUM(D54:D57) -> 69 | U21: =SUM(E54:E57) -> 11 | V21: =SUM(F54:F57) -> 119 | W21: =SUM(G54:G57) -> 6 | X21: =SUM(H54:H57) -> 0 | Y21: =SUM(I54:I57) -> 7 | Z21: =SUM(J54:J57) -> 36 | ... AF21: =SUM(P54:P57) -> 528
B22: 10.00 - 10.15 | C22: 12 | D22: 13 | E22: 7 | F22: 26 | G22: 0 | H22: 0 | I22: 2 | J22: 4 | K22: 2 | L22: 3 | M22: 39 | N22: 0 | O22: =SUM(C22:L22,N22) -> 69 | P22: =SUM(C22:N22) -> 108 | R22: AM Peak Hr | S22: =MAX(S10:S12) -> 34 | T22: =MAX(T10:T12) -> 19 | U22: =MAX(U10:U12) -> 5 | V22: =MAX(V10:V12) -> 31 | W22: =MAX(W10:W12) -> 1 | X22: =MAX(X10:X12) -> 0 | Y22: =MAX(Y10:Y12) -> 5 | Z22: =MAX(Z10:Z12) -> 13 | ... AF22: =MAX(AF10:AF12) -> 187
B23: 10.15 - 10.30 | C23: 8 | D23: 12 | E23: 1 | F23: 17 | G23: 0 | H23: 0 | I23: 4 | J23: 5 | K23: 7 | L23: 3 | M23: 26 | N23: 0 | O23: =SUM(C23:L23,N23) -> 57 | P23: =SUM(C23:N23) -> 83 | R23: IP Peak Hr | S23: =MAX(S13:S18) -> 100 | T23: =MAX(T13:T18) -> 48 | U23: =MAX(U13:U18) -> 22 | V23: =MAX(V13:V18) -> 95 | W23: =MAX(W13:W18) -> 3 | X23: =MAX(X13:X18) -> 2 | Y23: =MAX(Y13:Y18) -> 32 | Z23: =MAX(Z13:Z18) -> 40 | ... AF23: =MAX(AF13:AF18) -> 483
B24: 10.30 - 10.45 | C24: 16 | D24: 7 | E24: 1 | F24: 17 | G24: 0 | H24: 0 | I24: 3 | J24: 5 | K24: 3 | L24: 1 | M24: 21 | N24: 0 | O24: =SUM(C24:L24,N24) -> 53 | P24: =SUM(C24:N24) -> 74 | R24: PM Peak Hr | S24: =MAX(S19:S21) -> 103 | T24: =MAX(T19:T21) -> 69 | U24: =MAX(U19:U21) -> 18 | V24: =MAX(V19:V21) -> 119 | W24: =MAX(W19:W21) -> 6 | X24: =MAX(X19:X21) -> 1 | Y24: =MAX(Y19:Y21) -> 16 | Z24: =MAX(Z19:Z21) -> 48 | ... AF24: =MAX(AF19:AF21) -> 540
B25: 10.45 - 11.00 | C25: 21 | D25: 12 | E25: 5 | F25: 35 | G25: 0 | H25: 0 | I25: 1 | J25: 6 | K25: 10 | L25: 4 | M25: 36 | N25: 0 | O25: =SUM(C25:L25,N25) -> 94 | P25: =SUM(C25:N25) -> 130 | R25: AM Period | S25: =SUM(S10:S12) -> 34 | T25: =SUM(T10:T12) -> 19 | U25: =SUM(U10:U12) -> 5 | V25: =SUM(V10:V12) -> 31 | W25: =SUM(W10:W12) -> 1 | X25: =SUM(X10:X12) -> 0 | Y25: =SUM(Y10:Y12) -> 5 | Z25: =SUM(Z10:Z12) -> 13 | ... AF25: =SUM(AF10:AF12) -> 187
B26: 11.00 - 11.15 | C26: 6 | D26: 11 | E26: 4 | F26: 18 | G26: 0 | H26: 0 | I26: 4 | J26: 5 | K26: 4 | L26: 4 | M26: 29 | N26: 0 | O26: =SUM(C26:L26,N26) -> 56 | P26: =SUM(C26:N26) -> 85 | R26: IP Period | S26: =SUM(S13:S18) -> 423 | T26: =SUM(T13:T18) -> 233 | U26: =SUM(U13:U18) -> 95 | V26: =SUM(V13:V18) -> 445 | W26: =SUM(W13:W18) -> 5 | X26: =SUM(X13:X18) -> 4 | Y26: =SUM(Y13:Y18) -> 105 | Z26: =SUM(Z13:Z18) -> 188 | ... AF26: =SUM(AF13:AF18) -> 2539
B27: 11.15 - 11.30 | C27: 20 | D27: 12 | E27: 2 | F27: 19 | G27: 0 | H27: 0 | I27: 13 | J27: 3 | K27: 6 | L27: 2 | M27: 22 | N27: 1 | O27: =SUM(C27:L27,N27) -> 78 | P27: =SUM(C27:N27) -> 100 | R27: PM Period | S27: =SUM(S19:S21) -> 246 | T27: =SUM(T19:T21) -> 135 | U27: =SUM(U19:U21) -> 41 | V27: =SUM(V19:V21) -> 295 | W27: =SUM(W19:W21) -> 7 | X27: =SUM(X19:X21) -> 1 | Y27: =SUM(Y19:Y21) -> 38 | Z27: =SUM(Z19:Z21) -> 109 | ... AF27: =SUM(AF19:AF21) -> 1485
B28: 11.30 - 11.45 | C28: 21 | D28: 10 | E28: 6 | F28: 16 | G28: 1 | H28: 0 | I28: 11 | J28: 7 | K28: 3 | L28: 7 | M28: 32 | N28: 0 | O28: =SUM(C28:L28,N28) -> 82 | P28: =SUM(C28:N28) -> 114 | R28: 12 Hours | S28: =SUM(S10:S21) -> 703 | T28: =SUM(T10:T21) -> 387 | U28: =SUM(U10:U21) -> 141 | V28: =SUM(V10:V21) -> 771 | W28: =SUM(W10:W21) -> 13 | X28: =SUM(X10:X21) -> 5 | Y28: =SUM(Y10:Y21) -> 148 | Z28: =SUM(Z10:Z21) -> 310 | ... AF28: =SUM(AF10:AF21) -> 4211
B29: 11.45 - 12.00 | C29: 18 | D29: 15 | E29: 2 | F29: 23 | G29: 2 | H29: 0 | I29: 4 | J29: 6 | K29: 2 | L29: 11 | M29: 42 | N29: 0 | O29: =SUM(C29:L29,N29) -> 83 | P29: =SUM(C29:N29) -> 125
B30: 12.00 - 12.15 | C30: 26 | D30: 16 | E30: 6 | F30: 18 | G30: 1 | H30: 1 | I30: 6 | J30: 11 | K30: 2 | L30: 6 | M30: 34 | N30: 0 | O30: =SUM(C30:L30,N30) -> 93 | P30: =SUM(C30:N30) -> 127
B31: 12.15 - 12.30 | C31: 24 | D31: 8 | E31: 4 | F31: 16 | G31: 0 | H31: 0 | I31: 0 | J31: 11 | K31: 5 | L31: 7 | M31: 22 | N31: 0 | O31: =SUM(C31:L31,N31) -> 75 | P31: =SUM(C31:N31) -> 97
B32: 12.30 - 12.45 | C32: 24 | D32: 6 | E32: 3 | F32: 22 | G32: 0 | H32: 1 | I32: 5 | J32: 7 | K32: 11 | L32: 12 | M32: 36 | N32: 0 | O32: =SUM(C32:L32,N32) -> 91 | P32: =SUM(C32:N32) -> 127
B33: 12.45 - 13.00 | C33: 26 | D33: 16 | E33: 9 | F33: 16 | G33: 1 | H33: 0 | I33: 2 | J33: 11 | K33: 1 | L33: 7 | M33: 43 | N33: 0 | O33: =SUM(C33:L33,N33) -> 89 | P33: =SUM(C33:N33) -> 132
B34: 13.00 - 13.15 | C34: 17 | D34: 12 | E34: 1 | F34: 18 | G34: 0 | H34: 0 | I34: 4 | J34: 7 | K34: 4 | L34: 3 | M34: 28 | N34: 0 | O34: =SUM(C34:L34,N34) -> 66 | P34: =SUM(C34:N34) -> 94
B35: 13.15 - 13.30 | C35: 13 | D35: 11 | E35: 1 | F35: 19 | G35: 0 | H35: 0 | I35: 5 | J35: 10 | K35: 0 | L35: 5 | M35: 32 | N35: 0 | O35: =SUM(C35:L35,N35) -> 64 | P35: =SUM(C35:N35) -> 96
B36: 13.30 - 13.45 | C36: 26 | D36: 4 | E36: 9 | F36: 17 | G36: 0 | H36: 0 | I36: 8 | J36: 9 | K36: 10 | L36: 10 | M36: 32 | N36: 0 | O36: =SUM(C36:L36,N36) -> 93 | P36: =SUM(C36:N36) -> 125
B37: 13.45 - 14.00 | C37: 15 | D37: 9 | E37: 8 | F37: 15 | G37: 0 | H37: 0 | I37: 3 | J37: 8 | K37: 2 | L37: 5 | M37: 31 | N37: 0 | O37: =SUM(C37:L37,N37) -> 65 | P37: =SUM(C37:N37) -> 96
B38: 14.00 - 14.15 | C38: 15 | D38: 10 | E38: 1 | F38: 14 | G38: 0 | H38: 1 | I38: 4 | J38: 8 | K38: 4 | L38: 3 | M38: 29 | N38: 0 | O38: =SUM(C38:L38,N38) -> 60 | P38: =SUM(C38:N38) -> 89
B39: 14.15 - 14.30 | C39: 19 | D39: 6 | E39: 5 | F39: 18 | G39: 0 | H39: 0 | I39: 4 | J39: 11 | K39: 5 | L39: 5 | M39: 35 | N39: 0 | O39: =SUM(C39:L39,N39) -> 73 | P39: =SUM(C39:N39) -> 108
B40: 14.30 - 14.45 | C40: 13 | D40: 0 | E40: 1 | F40: 8 | G40: 0 | H40: 1 | I40: 0 | J40: 7 | K40: 2 | L40: 6 | M40: 24 | N40: 0 | O40: =SUM(C40:L40,N40) -> 38 | P40: =SUM(C40:N40) -> 62
... B57: 18.45 - 19.00 | C57: 21 | D57: 19 | E57: 4 | F57: 19 | G57: 0 | H57: 0 | I57: 3 | J57: 11 | K57: 5 | L57: 2 | M57: 37 | N57: 0 | O57: =SUM(C57:L57,N57) -> 84 | P57: =SUM(C57:N57) -> 121
B58: Totals | C58: =SUM(C10:C57) -> 703 | D58: =SUM(D10:D57) -> 387 | E58: =SUM(E10:E57) -> 141 | F58: =SUM(F10:F57) -> 771 | G58: =SUM(G10:G57) -> 13 | H58: =SUM(H10:H57) -> 5 | I58: =SUM(I10:I57) -> 148 | J58: =SUM(J10:J57) -> 310 | ... P58: =SUM(P10:P57) -> 4211
...

Sheet 30.07 Nalya-Bweyogerere
B1: Consultancy services for Preparation of Expressway Development Master Plan (EDMP) for Uganda
B2: MANUAL CLASSIFIED COUNT (MCC)
B3: ROAD NAME: | C3: ='29.07 Nalya-Bweyogerere'!C3:G3 -> MCC - C1 - STN40 - NORTHERN BYPASS
C5: Date | D5: 30.07.19 | F5: Location | G5: ='29.07 Nalya-Bweyogerere'!G5:H5 -> Signs and Symbols | J5: Surveyor | K5: ='29.07 Nalya-Bweyogerere'!K5:L5 -> Acema Vicent/Aseru Sherry/Mejje Mathias Trevor/Martin Anthony
C6: Dir. From | D6: ='29.07 Nalya-Bweyogerere'!D6:E6 -> Naalya | F6: Dir. To | G6: ='29.07 Nalya-Bweyogerere'!G6:H6 -> Bweyogerere | J6: Supervisor | K6: ='29.07 Nalya-Bweyogerere'!K6:L6 -> Steven
B8: Time / Veh Type | R8: SUMMARY TRAFFIC VOLUMES
C9: 1. Car | D9: 2. Station Wagon | E9: 3. Pickups | F9: 4. Minibus, matatu | G9: 5. Medium bus | H9: 6. Large Bus | I9: 7. Light Truck | J9: 8. Medium Truck | K9: 9. Heavy truck | L9: 10. Truck Trailer | M9: 11. Motor cycles | N9: 12. Tractors | O9: Total Excl M/Cycles | P9: Total All | R9: Time | S9: 1. Car | T9: 2. Station Wagon | U9: 3. Pickups | V9: 4. Minibus, matatu | W9: 5. Medium bus | X9: 6. Large Bus | Y9: 7. Light Truck | Z9: 8. Medium Truck | AA9: 9. Heavy truck | AB9: 10. Truck Trailer | AC9: 11. Motorcycles | AD9: 12. Tractors, Graders | AE9: Total Excl M/ Cycles | AF9: Total All
B10: 07.00 - 07.15 | C10: 22 | D10: 11 | E10: 7 | F10: 30 | G10: 2 | H10: 0 | I10: 5 | J10: 4 | K10: 3 | L10: 2 | M10: 16 | N10: 0 | O10: =SUM(C10:L10,N10) -> 86 | P10: =SUM(C10:N10) -> 102 | R10: 0700-0800 | S10: =SUM(C10:C13) -> 105 | T10: =SUM(D10:D13) -> 35 | U10: =SUM(E10:E13) -> 25 | V10: =SUM(F10:F13) -> 143 | W10: =SUM(G10:G13) -> 10 | X10: =SUM(H10:H13) -> 0 | Y10: =SUM(I10:I13) -> 25 | Z10: =SUM(J10:J13) -> 17 | ... AF10: =SUM(P10:P13) -> 507
B11: 07.15 - 07.30 | C11: 18 | D11: 11 | E11: 6 | F11: 33 | G11: 5 | H11: 0 | I11: 3 | J11: 7 | K11: 3 | L11: 5 | M11: 33 | N11: 0 | O11: =SUM(C11:L11,N11) -> 91 | P11: =SUM(C11:N11) -> 124 | R11: 0800-0900 | S11: =SUM(C14:C17) -> 120 | T11: =SUM(D14:D17) -> 36 | U11: =SUM(E14:E17) -> 28 | V11: =SUM(F14:F17) -> 143 | W11: =SUM(G14:G17) -> 3 | X11: =SUM(H14:H17) -> 1 | Y11: =SUM(I14:I17) -> 18 | Z11: =SUM(J14:J17) -> 11 | ... AF11: =SUM(P14:P17) -> 544
B12: 07.30 - 07.45 | C12: 34 | D12: 6 | E12: 8 | F12: 36 | G12: 1 | H12: 0 | I12: 8 | J12: 3 | K12: 3 | L12: 0 | M12: 33 | N12: 0 | O12: =SUM(C12:L12,N12) -> 99 | P12: =SUM(C12:N12) -> 132 | R12: 0900-1000 | S12: =SUM(C18:C21) -> 74 | T12: =SUM(D18:D21) -> 39 | U12: =SUM(E18:E21) -> 16 | V12: =SUM(F18:F21) -> 134 | W12: =SUM(G18:G21) -> 2 | X12: =SUM(H18:H21) -> 0 | Y12: =SUM(I18:I21) -> 29 | Z12: =SUM(J18:J21) -> 17 | ... AF12: =SUM(P18:P21) -> 499
B13: 07.45 - 08.00 | C13: 31 | D13: 7 | E13: 4 | F13: 44 | G13: 2 | H13: 0 | I13: 9 | J13: 3 | K13: 6 | L13: 2 | M13: 41 | N13: 0 | O13: =SUM(C13:L13,N13) -> 108 | P13: =SUM(C13:N13) -> 149 | R13: 1000-1100 | S13: =SUM(C22:C25) -> 44 | T13: =SUM(D22:D25) -> 19 | U13: =SUM(E22:E25) -> 11 | V13: =SUM(F22:F25) -> 94 | W13: =SUM(G22:G25) -> 3 | X13: =SUM(H22:H25) -> 0 | Y13: =SUM(I22:I25) -> 28 | Z13: =SUM(J22:J25) -> 15 | ... AF13: =SUM(P22:P25) -> 391
B14: 08.00 - 08.15 | C14: 32 | D14: 10 | E14: 5 | F14: 39 | G14: 0 | H14: 0 | I14: 2 | J14: 1 | K14: 10 | L14: 5 | M14: 44 | N14: 0 | O14: =SUM(C14:L14,N14) -> 104 | P14: =SUM(C14:N14) -> 148 | R14: 1100-1200 | S14: =SUM(C26:C29) -> 56 | T14: =SUM(D26:D29) -> 21 | U14: =SUM(E26:E29) -> 10 | V14: =SUM(F26:F29) -> 74 | W14: =SUM(G26:G29) -> 1 | X14: =SUM(H26:H29) -> 0 | Y14: =SUM(I26:I29) -> 22 | Z14: =SUM(J26:J29) -> 16 | ... AF14: =SUM(P26:P29) -> 332
B15: 08.15 - 08.30 | C15: 39 | D15: 12 | E15: 14 | F15: 40 | G15: 2 | H15: 0 | I15: 6 | J15: 3 | K15: 3 | L15: 2 | M15: 35 | N15: 0 | O15: =SUM(C15:L15,N15) -> 121 | P15: =SUM(C15:N15) -> 156 | R15: 1200-1300 | S15: =SUM(C30:C33) -> 55 | T15: =SUM(D30:D33) -> 20 | U15: =SUM(E30:E33) -> 15 | V15: =SUM(F30:F33) -> 76 | W15: =SUM(G30:G33) -> 0 | X15: =SUM(H30:H33) -> 0 | Y15: =SUM(I30:I33) -> 16 | Z15: =SUM(J30:J33) -> 13 | ... AF15: =SUM(P30:P33) -> 337
B16: 08.30 - 08.45 | C16: 23 | D16: 8 | E16: 2 | F16: 30 | G16: 1 | H16: 0 | I16: 3 | J16: 1 | K16: 2 | L16: 2 | M16: 42 | N16: 0 | O16: =SUM(C16:L16,N16) -> 72 | P16: =SUM(C16:N16) -> 114 | R16: 1300-1400 | S16: =SUM(C34:C37) -> 49 | T16: =SUM(D34:D37) -> 14 | U16: =SUM(E34:E37) -> 8 | V16: =SUM(F34:F37) -> 76 | W16: =SUM(G34:G37) -> 1 | X16: =SUM(H34:H37) -> 0 | Y16: =SUM(I34:I37) -> 34 | Z16: =SUM(J34:J37) -> 22 | ... AF16: =SUM(P34:P37) -> 395
B17: 08.45 - 9.00 | C17: 26 | D17: 6 | E17: 7 | F17: 34 | G17: 0 | H17: 1 | I17: 7 | J17: 6 | K17: 6 | L17: 3 | M17: 30 | N17: 0 | O17: =SUM(C17:L17,N17) -> 96 | P17: =SUM(C17:N17) -> 126 | R17: 1400-1500 | S17: =SUM(C38:C41) -> 54 | T17: =SUM(D38:D41) -> 23 | U17: =SUM(E38:E41) -> 11 | V17: =SUM(F38:F41) -> 71 | W17: =SUM(G38:G41) -> 1 | X17: =SUM(H38:H41) -> 0 | Y17: =SUM(I38:I41) -> 39 | Z17: =SUM(J38:J41) -> 19 | ... AF17: =SUM(P38:P41) -> 410
B18: 09.00 - 09.15 | C18: 17 | D18: 18 | E18: 2 | F18: 37 | G18: 0 | H18: 0 | I18: 8 | J18: 4 | K18: 7 | L18: 1 | M18: 33 | N18: 0 | O18: =SUM(C18:L18,N18) -> 94 | P18: =SUM(C18:N18) -> 127 | R18: 1500-1600 | S18: =SUM(C42:C45) -> 54 | T18: =SUM(D42:D45) -> 22 | U18: =SUM(E42:E45) -> 17 | V18: =SUM(F42:F45) -> 64 | W18: =SUM(G42:G45) -> 1 | X18: =SUM(H42:H45) -> 0 | Y18: =SUM(I42:I45) -> 22 | Z18: =SUM(J42:J45) -> 11 | ... AF18: =SUM(P42:P45) -> 351
B19: 09.15 - 09.30 | C19: 15 | D19: 7 | E19: 5 | F19: 33 | G19: 0 | H19: 0 | I19: 9 | J19: 4 | K19: 5 | L19: 2 | M19: 48 | N19: 0 | O19: =SUM(C19:L19,N19) -> 80 | P19: =SUM(C19:N19) -> 128 | R19: 1600-1700 | S19: =SUM(C46:C49) -> 74 | T19: =SUM(D46:D49) -> 17 | U19: =SUM(E46:E49) -> 19 | V19: =SUM(F46:F49) -> 94 | W19: =SUM(G46:G49) -> 0 | X19: =SUM(H46:H49) -> 0 | Y19: =SUM(I46:I49) -> 21 | Z19: =SUM(J46:J49) -> 28 | ... AF19: =SUM(P46:P49) -> 454
B20: 09.30 - 09.45 | C20: 18 | D20: 4 | E20: 6 | F20: 30 | G20: 2 | H20: 0 | I20: 8 | J20: 4 | K20: 3 | L20: 5 | M20: 34 | N20: 0 | O20: =SUM(C20:L20,N20) -> 80 | P20: =SUM(C20:N20) -> 114 | R20: 1700-1800 | S20: =SUM(C50:C53) -> 132 | T20: =SUM(D50:D53) -> 56 | U20: =SUM(E50:E53) -> 23 | V20: =SUM(F50:F53) -> 105 | W20: =SUM(G50:G53) -> 4 | X20: =SUM(H50:H53) -> 0 | Y20: =SUM(I50:I53) -> 23 | Z20: =SUM(J50:J53) -> 9 | ... AF20: =SUM(P50:P53) -> 603
B21: 09.45 - 10.00 | C21: 24 | D21: 10 | E21: 3 | F21: 34 | G21: 0 | H21: 0 | I21: 4 | J21: 5 | K21: 4 | L21: 3 | M21: 43 | N21: 0 | O21: =SUM(C21:L21,N21) -> 87 | P21: =SUM(C21:N21) -> 130 | R21: 1800-1900 | S21: =SUM(C54:C57) -> 201 | T21: =SUM(D54:D57) -> 106 | U21: =SUM(E54:E57) -> 44 | V21: =SUM(F54:F57) -> 167 | W21: =SUM(G54:G57) -> 3 | X21: =SUM(H54:H57) -> 0 | Y21: =SUM(I54:I57) -> 25 | Z21: =SUM(J54:J57) -> 19 | ... AF21: =SUM(P54:P57) -> 783
B22: 10.00 - 10.15 | C22: 9 | D22: 6 | E22: 4 | F22: 37 | G22: 0 | H22: 0 | I22: 7 | J22: 3 | K22: 5 | L22: 6 | M22: 29 | N22: 0 | O22: =SUM(C22:L22,N22) -> 77 | P22: =SUM(C22:N22) -> 106 | R22: AM Peak Hr | S22: =MAX(S10:S12) -> 120 | T22: =MAX(T10:T12) -> 39 | U22: =MAX(U10:U12) -> 28 | V22: =MAX(V10:V12) -> 143 | W22: =MAX(W10:W12) -> 10 | X22: =MAX(X10:X12) -> 1 | Y22: =MAX(Y10:Y12) -> 29 | Z22: =MAX(Z10:Z12) -> 17 | ... AF22: =MAX(AF10:AF12) -> 544
B23: 10.15 - 10.30 | C23: 11 | D23: 1 | E23: 3 | F23: 16 | G23: 1 | H23: 0 | I23: 6 | J23: 1 | K23: 6 | L23: 5 | M23: 31 | N23: 0 | O23: =SUM(C23:L23,N23) -> 50 | P23: =SUM(C23:N23) -> 81 | R23: IP Peak Hr | S23: =MAX(S13:S18) -> 56 | T23: =MAX(T13:T18) -> 23 | U23: =MAX(U13:U18) -> 17 | V23: =MAX(V13:V18) -> 94 | W23: =MAX(W13:W18) -> 3 | X23: =MAX(X13:X18) -> 0 | Y23: =MAX(Y13:Y18) -> 39 | Z23: =MAX(Z13:Z18) -> 22 | ... AF23: =MAX(AF13:AF18) -> 410
B24: 10.30 - 10.45 | C24: 14 | D24: 7 | E24: 3 | F24: 23 | G24: 0 | H24: 0 | I24: 12 | J24: 6 | K24: 3 | L24: 2 | M24: 43 | N24: 0 | O24: =SUM(C24:L24,N24) -> 70 | P24: =SUM(C24:N24) -> 113 | R24: PM Peak Hr | S24: =MAX(S19:S21) -> 201 | T24: =MAX(T19:T21) -> 106 | U24: =MAX(U19:U21) -> 44 | V24: =MAX(V19:V21) -> 167 | W24: =MAX(W19:W21) -> 4 | X24: =MAX(X19:X21) -> 0 | Y24: =MAX(Y19:Y21) -> 25 | Z24: =MAX(Z19:Z21) -> 28 | ... AF24: =MAX(AF19:AF21) -> 783
B25: 10.45 - 11.00 | C25: 10 | D25: 5 | E25: 1 | F25: 18 | G25: 2 | H25: 0 | I25: 3 | J25: 5 | K25: 7 | L25: 2 | M25: 38 | N25: 0 | O25: =SUM(C25:L25,N25) -> 53 | P25: =SUM(C25:N25) -> 91 | R25: AM Period | S25: =SUM(S10:S12) -> 299 | T25: =SUM(T10:T12) -> 110 | U25: =SUM(U10:U12) -> 69 | V25: =SUM(V10:V12) -> 420 | W25: =SUM(W10:W12) -> 15 | X25: =SUM(X10:X12) -> 1 | Y25: =SUM(Y10:Y12) -> 72 | Z25: =SUM(Z10:Z12) -> 45 | ... AF25: =SUM(AF10:AF12) -> 1550
B26: 11.00 - 11.15 | C26: 12 | D26: 7 | E26: 3 | F26: 17 | G26: 1 | H26: 0 | I26: 10 | J26: 5 | K26: 7 | L26: 4 | M26: 21 | N26: 0 | O26: =SUM(C26:L26,N26) -> 66 | P26: =SUM(C26:N26) -> 87 | R26: IP Period | S26: =SUM(S13:S18) -> 312 | T26: =SUM(T13:T18) -> 119 | U26: =SUM(U13:U18) -> 72 | V26: =SUM(V13:V18) -> 455 | W26: =SUM(W13:W18) -> 7 | X26: =SUM(X13:X18) -> 0 | Y26: =SUM(Y13:Y18) -> 161 | Z26: =SUM(Z13:Z18) -> 96 | ... AF26: =SUM(AF13:AF18) -> 2216
B27: 11.15 - 11.30 | C27: 13 | D27: 3 | E27: 2 | F27: 22 | G27: 0 | H27: 0 | I27: 3 | J27: 4 | K27: 1 | L27: 2 | M27: 27 | N27: 0 | O27: =SUM(C27:L27,N27) -> 50 | P27: =SUM(C27:N27) -> 77 | R27: PM Period | S27: =SUM(S19:S21) -> 407 | T27: =SUM(T19:T21) -> 179 | U27: =SUM(U19:U21) -> 86 | V27: =SUM(V19:V21) -> 366 | W27: =SUM(W19:W21) -> 7 | X27: =SUM(X19:X21) -> 0 | Y27: =SUM(Y19:Y21) -> 69 | Z27: =SUM(Z19:Z21) -> 56 | ... AF27: =SUM(AF19:AF21) -> 1840
B28: 11.30 - 11.45 | C28: 20 | D28: 6 | E28: 2 | F28: 13 | G28: 0 | H28: 0 | I28: 3 | J28: 4 | K28: 8 | L28: 3 | M28: 30 | N28: 0 | O28: =SUM(C28:L28,N28) -> 59 | P28: =SUM(C28:N28) -> 89 | R28: 12 Hours | S28: =SUM(S10:S21) -> 1018 | T28: =SUM(T10:T21) -> 408 | U28: =SUM(U10:U21) -> 227 | V28: =SUM(V10:V21) -> 1241 | W28: =SUM(W10:W21) -> 29 | X28: =SUM(X10:X21) -> 1 | Y28: =SUM(Y10:Y21) -> 302 | Z28: =SUM(Z10:Z21) -> 197 | ... AF28: =SUM(AF10:AF21) -> 5606
B29: 11.45 - 12.00 | C29: 11 | D29: 5 | E29: 3 | F29: 22 | G29: 0 | H29: 0 | I29: 6 | J29: 3 | K29: 3 | L29: 5 | M29: 21 | N29: 0 | O29: =SUM(C29:L29,N29) -> 58 | P29: =SUM(C29:N29) -> 79
B30: 12.00 - 12.15 | C30: 13 | D30: 8 | E30: 5 | F30: 16 | G30: 0 | H30: 0 | I30: 4 | J30: 4 | K30: 7 | L30: 3 | M30: 27 | N30: 0 | O30: =SUM(C30:L30,N30) -> 60 | P30: =SUM(C30:N30) -> 87
B31: 12.15 - 12.30 | C31: 17 | D31: 3 | E31: 6 | F31: 23 | G31: 0 | H31: 0 | I31: 7 | J31: 3 | K31: 8 | L31: 2 | M31: 30 | N31: 0 | O31: =SUM(C31:L31,N31) -> 69 | P31: =SUM(C31:N31) -> 99
B32: 12.30 - 12.45 | C32: 12 | D32: 5 | E32: 1 | F32: 17 | G32: 0 | H32: 0 | I32: 4 | J32: 2 | K32: 4 | L32: 3 | M32: 13 | N32: 0 | O32: =SUM(C32:L32,N32) -> 48 | P32: =SUM(C32:N32) -> 61
B33: 12.45 - 13.00 | C33: 13 | D33: 4 | E33: 3 | F33: 20 | G33: 0 | H33: 0 | I33: 1 | J33: 4 | K33: 4 | L33: 6 | M33: 35 | N33: 0 | O33: =SUM(C33:L33,N33) -> 55 | P33: =SUM(C33:N33) -> 90
B34: 13.00 - 13.15 | C34: 11 | D34: 4 | E34: 1 | F34: 21 | G34: 0 | H34: 0 | I34: 9 | J34: 5 | K34: 2 | L34: 5 | M34: 33 | N34: 0 | O34: =SUM(C34:L34,N34) -> 58 | P34: =SUM(C34:N34) -> 91
B35: 13.15 - 13.30 | C35: 15 | D35: 1 | E35: 2 | F35: 15 | G35: 0 | H35: 0 | I35: 4 | J35: 7 | K35: 4 | L35: 2 | M35: 41 | N35: 0 | O35: =SUM(C35:L35,N35) -> 50 | P35: =SUM(C35:N35) -> 91
B36: 13.30 - 13.45 | C36: 12 | D36: 6 | E36: 2 | F36: 25 | G36: 0 | H36: 0 | I36: 11 | J36: 3 | K36: 11 | L36: 8 | M36: 38 | N36: 0 | O36: =SUM(C36:L36,N36) -> 78 | P36: =SUM(C36:N36) -> 116
B37: 13.45 - 14.00 | C37: 11 | D37: 3 | E37: 3 | F37: 15 | G37: 1 | H37: 0 | I37: 10 | J37: 7 | K37: 5 | L37: 4 | M37: 38 | N37: 0 | O37: =SUM(C37:L37,N37) -> 59 | P37: =SUM(C37:N37) -> 97
B38: 14.00 - 14.15 | C38: 17 | D38: 5 | E38: 3 | F38: 26 | G38: 0 | H38: 0 | I38: 11 | J38: 6 | K38: 13 | L38: 7 | M38: 31 | N38: 0 | O38: =SUM(C38:L38,N38) -> 88 | P38: =SUM(C38:N38) -> 119
B39: 14.15 - 14.30 | C39: 12 | D39: 3 | E39: 1 | F39: 13 | G39: 1 | H39: 0 | I39: 8 | J39: 4 | K39: 7 | L39: 6 | M39: 46 | N39: 0 | O39: =SUM(C39:L39,N39) -> 55 | P39: =SUM(C39:N39) -> 101
B40: 14.30 - 14.45 | C40: 15 | D40: 8 | E40: 6 | F40: 15 | G40: 0 | H40: 0 | I40: 8 | J40: 3 | K40: 5 | L40: 5 | M40: 35 | N40: 0 | O40: =SUM(C40:L40,N40) -> 65 | P40: =SUM(C40:N40) -> 100
... B57: 18.45 - 19.00 | C57: 59 | D57: 28 | E57: 9 | F57: 42 | G57: 0 | H57: 0 | I57: 1 | J57: 2 | K57: 1 | L57: 0 | M57: 47 | N57: 0 | O57: =SUM(C57:L57,N57) -> 142 | P57: =SUM(C57:N57) -> 189
B58: Totals | C58: =SUM(C10:C57) -> 1018 | D58: =SUM(D10:D57) -> 408 | E58: =SUM(E10:E57) -> 227 | F58: =SUM(F10:F57) -> 1241 | G58: =SUM(G10:G57) -> 29 | H58: =SUM(H10:H57) -> 1 | I58: =SUM(I10:I57) -> 302 | J58: =SUM(J10:J57) -> 197 | ... P58: =SUM(P10:P57) -> 5606
...

Sheet 30.07 Bweyogerere-Nalya
B1: Consultancy services for Preparation of Expressway Development Master Plan (EDMP) for Uganda
B2: MANUAL CLASSIFIED COUNT (MCC)
B3: ROAD NAME: | C3: ='29.07 Bweyogerere-Nalya'!C3:G3 -> MCC - C1 - STN40 - NORTHERN BYPASS
C5: Date | D5: ='30.07 Nalya-Bweyogerere'!D5 -> 30.07.19 | F5: Location | G5: ='29.07 Nalya-Bweyogerere'!G5:H5 -> Signs and Symbols | J5: Surveyor | K5: ='29.07 Nalya-Bweyogerere'!K5:L5 -> Acema Vicent/Aseru Sherry/Mejje Mathias Trevor/Martin Anthony
C6: Dir. From | D6: ='29.07 Bweyogerere-Nalya'!D6:E6 -> Bweyogerere | F6: Dir. To | G6: ='29.07 Bweyogerere-Nalya'!G6:H6 -> Nalya | J6: Supervisor | K6: ='29.07 Nalya-Bweyogerere'!K6:L6 -> Steven
B8: Time / Veh Type | R8: SUMMARY TRAFFIC VOLUMES
C9: 1. Car | D9: 2. Station Wagon | E9: 3. Pickups | F9: 4. Minibus, matatu | G9: 5. Medium bus | H9: 6. Large Bus | I9: 7. Light Truck | J9: 8. Medium Truck | K9: 9. Heavy truck | L9: 10. Truck Trailer | M9: 11. Motor cycles | N9: 12. Tractors | O9: Total Excl M/Cycles | P9: Total All | R9: Time | S9: 1. Car | T9: 2. Station Wagon | U9: 3. Pickups | V9: 4. Minibus, matatu | W9: 5. Medium bus | X9: 6. Large Bus | Y9: 7. Light Truck | Z9: 8. Medium Truck | AA9: 9. Heavy truck | AB9: 10. Truck Trailer | AC9: 11. Motorcycles | AD9: 12. Tractors, Graders | AE9: Total Excl M/ Cycles | AF9: Total All
B10: 07.00 - 07.15 | C10: 24 | D10: 22 | E10: 8 | F10: 15 | G10: 1 | H10: 1 | I10: 2 | J10: 4 | K10: 2 | L10: 0 | M10: 20 | N10: 0 | O10: =SUM(C10:L10,N10) -> 79 | P10: =SUM(C10:N10) -> 99 | R10: 0700-0800 | S10: =SUM(C10:C13) -> 157 | T10: =SUM(D10:D13) -> 88 | U10: =SUM(E10:E13) -> 32 | V10: =SUM(F10:F13) -> 113 | W10: =SUM(G10:G13) -> 2 | X10: =SUM(H10:H13) -> 2 | Y10: =SUM(I10:I13) -> 7 | Z10: =SUM(J10:J13) -> 21 | ... AF10: =SUM(P10:P13) -> 591
B11: 07.15 - 07.30 | C11: 49 | D11: 18 | E11: 9 | F11: 31 | G11: 1 | H11: 1 | I11: 3 | J11: 3 | K11: 1 | L11: 1 | M11: 34 | N11: 0 | O11: =SUM(C11:L11,N11) -> 117 | P11: =SUM(C11:N11) -> 151 | R11: 0800-0900 | S11: =SUM(C14:C17) -> 142 | T11: =SUM(D14:D17) -> 49 | U11: =SUM(E14:E17) -> 31 | V11: =SUM(F14:F17) -> 113 | W11: =SUM(G14:G17) -> 4 | X11: =SUM(H14:H17) -> 0 | Y11: =SUM(I14:I17) -> 10 | Z11: =SUM(J14:J17) -> 35 | ... AF11: =SUM(P14:P17) -> 575
B12: 07.30 - 07.45 | C12: 44 | D12: 33 | E12: 11 | F12: 39 | G12: 0 | H12: 0 | I12: 0 | J12: 9 | K12: 5 | L12: 4 | M12: 52 | N12: 1 | O12: =SUM(C12:L12,N12) -> 146 | P12: =SUM(C12:N12) -> 198 | R12: 0900-1000 | S12: =SUM(C18:C21) -> 102 | T12: =SUM(D18:D21) -> 17 | U12: =SUM(E18:E21) -> 15 | V12: =SUM(F18:F21) -> 83 | W12: =SUM(G18:G21) -> 3 | X12: =SUM(H18:H21) -> 0 | Y12: =SUM(I18:I21) -> 16 | Z12: =SUM(J18:J21) -> 37 | ... AF12: =SUM(P18:P21) -> 502
B13: 07.45 - 08.00 | C13: 40 | D13: 15 | E13: 4 | F13: 28 | G13: 0 | H13: 0 | I13: 2 | J13: 5 | K13: 2 | L13: 3 | M13: 44 | N13: 0 | O13: =SUM(C13:L13,N13) -> 99 | P13: =SUM(C13:N13) -> 143 | R13: 1000-1100 | S13: =SUM(C22:C25) -> 80 | T13: =SUM(D22:D25) -> 26 | U13: =SUM(E22:E25) -> 21 | V13: =SUM(F22:F25) -> 75 | W13: =SUM(G22:G25) -> 4 | X13: =SUM(H22:H25) -> 0 | Y13: =SUM(I22:I25) -> 7 | Z13: =SUM(J22:J25) -> 35 | ... AF13: =SUM(P22:P25) -> 463
B14: 08.00 - 08.15 | C14: 24 | D14: 15 | E14: 4 | F14: 31 | G14: 1 | H14: 0 | I14: 1 | J14: 9 | K14: 5 | L14: 3 | M14: 42 | N14: 0 | O14: =SUM(C14:L14,N14) -> 93 | P14: =SUM(C14:N14) -> 135 | R14: 1100-1200 | S14: =SUM(C26:C29) -> 78 | T14: =SUM(D26:D29) -> 23 | U14: =SUM(E26:E29) -> 9 | V14: =SUM(F26:F29) -> 63 | W14: =SUM(G26:G29) -> 2 | X14: =SUM(H26:H29) -> 0 | Y14: =SUM(I26:I29) -> 8 | Z14: =SUM(J26:J29) -> 35 | ... AF14: =SUM(P26:P29) -> 406
B15: 08.15 - 08.30 | C15: 53 | D15: 15 | E15: 12 | F15: 32 | G15: 0 | H15: 0 | I15: 5 | J15: 11 | K15: 3 | L15: 3 | M15: 33 | N15: 0 | O15: =SUM(C15:L15,N15) -> 134 | P15: =SUM(C15:N15) -> 167 | R15: 1200-1300 | S15: =SUM(C30:C33) -> 69 | T15: =SUM(D30:D33) -> 24 | U15: =SUM(E30:E33) -> 20 | V15: =SUM(F30:F33) -> 74 | W15: =SUM(G30:G33) -> 0 | X15: =SUM(H30:H33) -> 0 | Y15: =SUM(I30:I33) -> 6 | Z15: =SUM(J30:J33) -> 41 | ... AF15: =SUM(P30:P33) -> 393
B16: 08.30 - 08.45 | C16: 33 | D16: 14 | E16: 6 | F16: 23 | G16: 1 | H16: 0 | I16: 2 | J16: 13 | K16: 9 | L16: 2 | M16: 36 | N16: 0 | O16: =SUM(C16:L16,N16) -> 103 | P16: =SUM(C16:N16) -> 139 | R16: 1300-1400 | S16: =SUM(C34:C37) -> 72 | T16: =SUM(D34:D37) -> 21 | U16: =SUM(E34:E37) -> 21 | V16: =SUM(F34:F37) -> 55 | W16: =SUM(G34:G37) -> 1 | X16: =SUM(H34:H37) -> 1 | Y16: =SUM(I34:I37) -> 28 | Z16: =SUM(J34:J37) -> 12 | ... AF16: =SUM(P34:P37) -> 368
B17: 08.45 - 9.00 | C17: 32 | D17: 5 | E17: 9 | F17: 27 | G17: 2 | H17: 0 | I17: 2 | J17: 2 | K17: 4 | L17: 2 | M17: 49 | N17: 0 | O17: =SUM(C17:L17,N17) -> 85 | P17: =SUM(C17:N17) -> 134 | R17: 1400-1500 | S17: =SUM(C38:C41) -> 52 | T17: =SUM(D38:D41) -> 20 | U17: =SUM(E38:E41) -> 17 | V17: =SUM(F38:F41) -> 62 | W17: =SUM(G38:G41) -> 1 | X17: =SUM(H38:H41) -> 0 | Y17: =SUM(I38:I41) -> 27 | Z17: =SUM(J38:J41) -> 15 | ... AF17: =SUM(P38:P41) -> 387
B18: 09.00 - 09.15 | C18: 27 | D18: 5 | E18: 3 | F18: 23 | G18: 0 | H18: 0 | I18: 5 | J18: 10 | K18: 7 | L18: 5 | M18: 55 | N18: 0 | O18: =SUM(C18:L18,N18) -> 85 | P18: =SUM(C18:N18) -> 140 | R18: 1500-1600 | S18: =SUM(C42:C45) -> 66 | T18: =SUM(D42:D45) -> 19 | U18: =SUM(E42:E45) -> 6 | V18: =SUM(F42:F45) -> 80 | W18: =SUM(G42:G45) -> 1 | X18: =SUM(H42:H45) -> 0 | Y18: =SUM(I42:I45) -> 19 | Z18: =SUM(J42:J45) -> 19 | ... AF18: =SUM(P42:P45) -> 387
B19: 09.15 - 09.30 | C19: 23 | D19: 3 | E19: 4 | F19: 17 | G19: 1 | H19: 0 | I19: 2 | J19: 5 | K19: 3 | L19: 6 | M19: 33 | N19: 0 | O19: =SUM(C19:L19,N19) -> 64 | P19: =SUM(C19:N19) -> 97 | R19: 1600-1700 | S19: =SUM(C46:C49) -> 78 | T19: =SUM(D46:D49) -> 28 | U19: =SUM(E46:E49) -> 14 | V19: =SUM(F46:F49) -> 74 | W19: =SUM(G46:G49) -> 3 | X19: =SUM(H46:H49) -> 0 | Y19: =SUM(I46:I49) -> 8 | Z19: =SUM(J46:J49) -> 29 | ... AF19: =SUM(P46:P49) -> 425
B20: 09.30 - 09.45 | C20: 33 | D20: 4 | E20: 5 | F20: 19 | G20: 2 | H20: 0 | I20: 5 | J20: 11 | K20: 10 | L20: 13 | M20: 43 | N20: 1 | O20: =SUM(C20:L20,N20) -> 103 | P20: =SUM(C20:N20) -> 146 | R20: 1700-1800 | S20: =SUM(C50:C53) -> 97 | T20: =SUM(D50:D53) -> 21 | U20: =SUM(E50:E53) -> 10 | V20: =SUM(F50:F53) -> 102 | W20: =SUM(G50:G53) -> 0 | X20: =SUM(H50:H53) -> 0 | Y20: =SUM(I50:I53) -> 9 | Z20: =SUM(J50:J53) -> 48 | ... AF20: =SUM(P50:P53) -> 510
B21: 09.45 - 10.00 | C21: 19 | D21: 5 | E21: 3 | F21: 24 | G21: 0 | H21: 0 | I21: 4 | J21: 11 | K21: 2 | L21: 8 | M21: 43 | N21: 0 | O21: =SUM(C21:L21,N21) -> 76 | P21: =SUM(C21:N21) -> 119 | R21: 1800-1900 | S21: =SUM(C54:C57) -> 124 | T21: =SUM(D54:D57) -> 25 | U21: =SUM(E54:E57) -> 10 | V21: =SUM(F54:F57) -> 130 | W21: =SUM(G54:G57) -> 2 | X21: =SUM(H54:H57) -> 0 | Y21: =SUM(I54:I57) -> 9 | Z21: =SUM(J54:J57) -> 32 | ... AF21: =SUM(P54:P57) -> 610
B22: 10.00 - 10.15 | C22: 23 | D22: 13 | E22: 7 | F22: 25 | G22: 1 | H22: 0 | I22: 2 | J22: 7 | K22: 2 | L22: 6 | M22: 47 | N22: 0 | O22: =SUM(C22:L22,N22) -> 86 | P22: =SUM(C22:N22) -> 133 | R22: AM Peak Hr | S22: =MAX(S10:S12) -> 157 | T22: =MAX(T10:T12) -> 88 | U22: =MAX(U10:U12) -> 32 | V22: =MAX(V10:V12) -> 113 | W22: =MAX(W10:W12) -> 4 | X22: =MAX(X10:X12) -> 2 | Y22: =MAX(Y10:Y12) -> 16 | Z22: =MAX(Z10:Z12) -> 37 | ... AF22: =MAX(AF10:AF12) -> 591
B23: 10.15 - 10.30 | C23: 15 | D23: 4 | E23: 6 | F23: 12 | G23: 1 | H23: 0 | I23: 3 | J23: 8 | K23: 2 | L23: 15 | M23: 42 | N23: 0 | O23: =SUM(C23:L23,N23) -> 66 | P23: =SUM(C23:N23) -> 108 | R23: IP Peak Hr | S23: =MAX(S13:S18) -> 80 | T23: =MAX(T13:T18) -> 26 | U23: =MAX(U13:U18) -> 21 | V23: =MAX(V13:V18) -> 80 | W23: =MAX(W13:W18) -> 4 | X23: =MAX(X13:X18) -> 1 | Y23: =MAX(Y13:Y18) -> 28 | Z23: =MAX(Z13:Z18) -> 41 | ... AF23: =MAX(AF13:AF18) -> 463
B24: 10.30 - 10.45 | C24: 16 | D24: 7 | E24: 3 | F24: 18 | G24: 0 | H24: 0 | I24: 1 | J24: 7 | K24: 8 | L24: 7 | M24: 41 | N24: 0 | O24: =SUM(C24:L24,N24) -> 67 | P24: =SUM(C24:N24) -> 108 | R24: PM Peak Hr | S24: =MAX(S19:S21) -> 124 | T24: =MAX(T19:T21) -> 28 | U24: =MAX(U19:U21) -> 14 | V24: =MAX(V19:V21) -> 130 | W24: =MAX(W19:W21) -> 3 | X24: =MAX(X19:X21) -> 0 | Y24: =MAX(Y19:Y21) -> 9 | Z24: =MAX(Z19:Z21) -> 48 | ... AF24: =MAX(AF19:AF21) -> 610
B25: 10.45 - 11.00 | C25: 26 | D25: 2 | E25: 5 | F25: 20 | G25: 2 | H25: 0 | I25: 1 | J25: 13 | K25: 6 | L25: 5 | M25: 34 | N25: 0 | O25: =SUM(C25:L25,N25) -> 80 | P25: =SUM(C25:N25) -> 114 | R25: AM Period | S25: =SUM(S10:S12) -> 401 | T25: =SUM(T10:T12) -> 154 | U25: =SUM(U10:U12) -> 78 | V25: =SUM(V10:V12) -> 309 | W25: =SUM(W10:W12) -> 9 | X25: =SUM(X10:X12) -> 2 | Y25: =SUM(Y10:Y12) -> 33 | Z25: =SUM(Z10:Z12) -> 93 | ... AF25: =SUM(AF10:AF12) -> 1668
B26: 11.00 - 11.15 | C26: 22 | D26: 5 | E26: 2 | F26: 21 | G26: 1 | H26: 0 | I26: 2 | J26: 13 | K26: 3 | L26: 10 | M26: 47 | N26: 0 | O26: =SUM(C26:L26,N26) -> 79 | P26: =SUM(C26:N26) -> 126 | R26: IP Period | S26: =SUM(S13:S18) -> 417 | T26: =SUM(T13:T18) -> 133 | U26: =SUM(U13:U18) -> 94 | V26: =SUM(V13:V18) -> 409 | W26: =SUM(W13:W18) -> 9 | X26: =SUM(X13:X18) -> 1 | Y26: =SUM(Y13:Y18) -> 95 | Z26: =SUM(Z13:Z18) -> 157 | ... AF26: =SUM(AF13:AF18) -> 2404
B27: 11.15 - 11.30 | C27: 17 | D27: 7 | E27: 4 | F27: 13 | G27: 0 | H27: 0 | I27: 5 | J27: 7 | K27: 6 | L27: 6 | M27: 29 | N27: 0 | O27: =SUM(C27:L27,N27) -> 65 | P27: =SUM(C27:N27) -> 94 | R27: PM Period | S27: =SUM(S19:S21) -> 299 | T27: =SUM(T19:T21) -> 74 | U27: =SUM(U19:U21) -> 34 | V27: =SUM(V19:V21) -> 306 | W27: =SUM(W19:W21) -> 5 | X27: =SUM(X19:X21) -> 0 | Y27: =SUM(Y19:Y21) -> 26 | Z27: =SUM(Z19:Z21) -> 109 | ... AF27: =SUM(AF19:AF21) -> 1545
B28: 11.30 - 11.45 | C28: 18 | D28: 5 | E28: 1 | F28: 18 | G28: 0 | H28: 0 | I28: 1 | J28: 6 | K28: 6 | L28: 7 | M28: 41 | N28: 0 | O28: =SUM(C28:L28,N28) -> 62 | P28: =SUM(C28:N28) -> 103 | R28: 12 Hours | S28: =SUM(S10:S21) -> 1117 | T28: =SUM(T10:T21) -> 361 | U28: =SUM(U10:U21) -> 206 | V28: =SUM(V10:V21) -> 1024 | W28: =SUM(W10:W21) -> 23 | X28: =SUM(X10:X21) -> 3 | Y28: =SUM(Y10:Y21) -> 154 | Z28: =SUM(Z10:Z21) -> 359 | ... AF28: =SUM(AF10:AF21) -> 5617
B29: 11.45 - 12.00 | C29: 21 | D29: 6 | E29: 2 | F29: 11 | G29: 1 | H29: 0 | I29: 0 | J29: 9 | K29: 4 | L29: 5 | M29: 24 | N29: 0 | O29: =SUM(C29:L29,N29) -> 59 | P29: =SUM(C29:N29) -> 83
B30: 12.00 - 12.15 | C30: 23 | D30: 6 | E30: 2 | F30: 21 | G30: 0 | H30: 0 | I30: 0 | J30: 9 | K30: 2 | L30: 2 | M30: 28 | N30: 0 | O30: =SUM(C30:L30,N30) -> 65 | P30: =SUM(C30:N30) -> 93
B31: 12.15 - 12.30 | C31: 20 | D31: 11 | E31: 3 | F31: 16 | G31: 0 | H31: 0 | I31: 0 | J31: 10 | K31: 0 | L31: 11 | M31: 26 | N31: 0 | O31: =SUM(C31:L31,N31) -> 71 | P31: =SUM(C31:N31) -> 97
B32: 12.30 - 12.45 | C32: 12 | D32: 5 | E32: 5 | F32: 21 | G32: 0 | H32: 0 | I32: 1 | J32: 16 | K32: 6 | L32: 6 | M32: 30 | N32: 0 | O32: =SUM(C32:L32,N32) -> 72 | P32: =SUM(C32:N32) -> 102
B33: 12.45 - 13.00 | C33: 14 | D33: 2 | E33: 10 | F33: 16 | G33: 0 | H33: 0 | I33: 5 | J33: 6 | K33: 4 | L33: 1 | M33: 43 | N33: 0 | O33: =SUM(C33:L33,N33) -> 58 | P33: =SUM(C33:N33) -> 101
B34: 13.00 - 13.15 | C34: 16 | D34: 5 | E34: 8 | F34: 12 | G34: 0 | H34: 0 | I34: 7 | J34: 3 | K34: 5 | L34: 1 | M34: 35 | N34: 0 | O34: =SUM(C34:L34,N34) -> 57 | P34: =SUM(C34:N34) -> 92
B35: 13.15 - 13.30 | C35: 27 | D35: 4 | E35: 2 | F35: 17 | G35: 0 | H35: 0 | I35: 7 | J35: 0 | K35: 6 | L35: 4 | M35: 32 | N35: 0 | O35: =SUM(C35:L35,N35) -> 67 | P35: =SUM(C35:N35) -> 99
B36: 13.30 - 13.45 | C36: 17 | D36: 9 | E36: 4 | F36: 11 | G36: 1 | H36: 0 | I36: 10 | J36: 4 | K36: 4 | L36: 1 | M36: 20 | N36: 0 | O36: =SUM(C36:L36,N36) -> 61 | P36: =SUM(C36:N36) -> 81
B37: 13.45 - 14.00 | C37: 12 | D37: 3 | E37: 7 | F37: 15 | G37: 0 | H37: 1 | I37: 4 | J37: 5 | K37: 4 | L37: 8 | M37: 37 | N37: 0 | O37: =SUM(C37:L37,N37) -> 59 | P37: =SUM(C37:N37) -> 96
B38: 14.00 - 14.15 | C38: 15 | D38: 7 | E38: 7 | F38: 18 | G38: 1 | H38: 0 | I38: 6 | J38: 3 | K38: 7 | L38: 7 | M38: 39 | N38: 0 | O38: =SUM(C38:L38,N38) -> 71 | P38: =SUM(C38:N38) -> 110
B39: 14.15 - 14.30 | C39: 10 | D39: 7 | E39: 4 | F39: 13 | G39: 0 | H39: 0 | I39: 7 | J39: 4 | K39: 6 | L39: 8 | M39: 32 | N39: 0 | O39: =SUM(C39:L39,N39) -> 59 | P39: =SUM(C39:N39) -> 91
B40: 14.30 - 14.45 | C40: 15 | D40: 4 | E40: 3 | F40: 15 | G40: 0 | H40: 0 | I40: 11 | J40: 6 | K40: 7 | L40: 5 | M40: 42 | N40: 0 | O40: =SUM(C40:L40,N40) -> 66 | P40: =SUM(C40:N40) -> 108
... B57: 18.45 - 19.00 | C57: 22 | D57: 8 | E57: 2 | F57: 30 | G57: 0 | H57: 0 | I57: 2 | J57: 8 | K57: 2 | L57: 1 | M57: 64 | N57: 0 | O57: =SUM(C57:L57,N57) -> 75 | P57: =SUM(C57:N57) -> 139
B58: Totals | C58: =SUM(C10:C57) -> 1117 | D58: =SUM(D10:D57) -> 361 | E58: =SUM(E10:E57) -> 206 | F58: =SUM(F10:F57) -> 1024 | G58: =SUM(G10:G57) -> 23 | H58: =SUM(H10:H57) -> 3 | I58: =SUM(I10:I57) -> 154 | J58: =SUM(J10:J57) -> 359 | ... P58: =SUM(P10:P57) -> 5617
...

Sheet 31.07 Nalya-Bweyogerere
B1: Consultancy services for Preparation of Expressway Development Master Plan (EDMP) for Uganda
B2: MANUAL CLASSIFIED COUNT (MCC)
B3: ROAD NAME: | C3: ='29.07 Nalya-Bweyogerere'!C3:G3 -> MCC - C1 - STN40 - NORTHERN BYPASS
C5: Date | D5: 31.07.19 | F5: Location | G5: ='29.07 Nalya-Bweyogerere'!G5:H5 -> Signs and Symbols | J5: Surveyor | K5: ='29.07 Nalya-Bweyogerere'!K5:L5 -> Acema Vicent/Aseru Sherry/Mejje Mathias Trevor/Martin Anthony
C6: Dir. From | D6: ='29.07 Nalya-Bweyogerere'!D6:E6 -> Naalya | F6: Dir. To | G6: ='29.07 Nalya-Bweyogerere'!G6:H6 -> Bweyogerere | J6: Supervisor | K6: ='29.07 Nalya-Bweyogerere'!K6:L6 -> Steven
B8: Time / Veh Type | R8: SUMMARY TRAFFIC VOLUMES
C9: 1. Car | D9: 2. Station Wagon | E9: 3. Pickups | F9: 4. Minibus, matatu | G9: 5. Medium bus | H9: 6. Large Bus | I9: 7. Light Truck | J9: 8. Medium Truck | K9: 9. Heavy truck | L9: 10. Truck Trailer | M9: 11. Motor cycles | N9: 12. Tractors | O9: Total Excl M/Cycles | P9: Total All | R9: Time | S9: 1. Car | T9: 2. Station Wagon | U9: 3. Pickups | V9: 4. Minibus, matatu | W9: 5. Medium bus | X9: 6. Large Bus | Y9: 7. Light Truck | Z9: 8. Medium Truck | AA9: 9. Heavy truck | AB9: 10. Truck Trailer | AC9: 11. Motorcycles | AD9: 12. Tractors, Graders | AE9: Total Excl M/ Cycles | AF9: Total All
B10: 07.00 - 07.15 | C10: 23 | D10: 3 | E10: 4 | F10: 31 | G10: 1 | H10: 0 | I10: 4 | J10: 5 | K10: 4 | L10: 3 | M10: 26 | N10: 0 | O10: =SUM(C10:L10,N10) -> 78 | P10: =SUM(C10:N10) -> 104 | R10: 0700-0800 | S10: =SUM(C10:C13) -> 94 | T10: =SUM(D10:D13) -> 29 | U10: =SUM(E10:E13) -> 23 | V10: =SUM(F10:F13) -> 122 | W10: =SUM(G10:G13) -> 4 | X10: =SUM(H10:H13) -> 1 | Y10: =SUM(I10:I13) -> 21 | Z10: =SUM(J10:J13) -> 10 | ... AF10: =SUM(P10:P13) -> 445
B11: 07.15 - 07.30 | C11: 21 | D11: 8 | E11: 8 | F11: 33 | G11: 1 | H11: 0 | I11: 8 | J11: 1 | K11: 6 | L11: 2 | M11: 35 | N11: 0 | O11: =SUM(C11:L11,N11) -> 88 | P11: =SUM(C11:N11) -> 123 | R11: 0800-0900 | S11: =SUM(C14:C17) -> 107 | T11: =SUM(D14:D17) -> 70 | U11: =SUM(E14:E17) -> 17 | V11: =SUM(F14:F17) -> 153 | W11: =SUM(G14:G17) -> 1 | X11: =SUM(H14:H17) -> 0 | Y11: =SUM(I14:I17) -> 24 | Z11: =SUM(J14:J17) -> 16 | ... AF11: =SUM(P14:P17) -> 569
B12: 07.30 - 07.45 | C12: 30 | D12: 9 | E12: 3 | F12: 31 | G12: 2 | H12: 1 | I12: 6 | J12: 1 | K12: 4 | L12: 1 | M12: 23 | N12: 0 | O12: =SUM(C12:L12,N12) -> 88 | P12: =SUM(C12:N12) -> 111 | R12: 0900-1000 | S12: =SUM(C18:C21) -> 75 | T12: =SUM(D18:D21) -> 20 | U12: =SUM(E18:E21) -> 16 | V12: =SUM(F18:F21) -> 121 | W12: =SUM(G18:G21) -> 0 | X12: =SUM(H18:H21) -> 0 | Y12: =SUM(I18:I21) -> 25 | Z12: =SUM(J18:J21) -> 8 | ... AF12: =SUM(P18:P21) -> 468
B13: 07.45 - 08.00 | C13: 20 | D13: 9 | E13: 8 | F13: 27 | G13: 0 | H13: 0 | I13: 3 | J13: 3 | K13: 4 | L13: 1 | M13: 32 | N13: 0 | O13: =SUM(C13:L13,N13) -> 75 | P13: =SUM(C13:N13) -> 107 | R13: 1000-1100 | S13: =SUM(C22:C25) -> 81 | T13: =SUM(D22:D25) -> 17 | U13: =SUM(E22:E25) -> 11 | V13: =SUM(F22:F25) -> 91 | W13: =SUM(G22:G25) -> 1 | X13: =SUM(H22:H25) -> 1 | Y13: =SUM(I22:I25) -> 31 | Z13: =SUM(J22:J25) -> 6 | ... AF13: =SUM(P22:P25) -> 455
B14: 08.00 - 08.15 | C14: 41 | D14: 23 | E14: 9 | F14: 45 | G14: 1 | H14: 0 | I14: 6 | J14: 7 | K14: 5 | L14: 0 | M14: 44 | N14: 0 | O14: =SUM(C14:L14,N14) -> 137 | P14: =SUM(C14:N14) -> 181 | R14: 1100-1200 | S14: =SUM(C26:C29) -> 66 | T14: =SUM(D26:D29) -> 24 | U14: =SUM(E26:E29) -> 11 | V14: =SUM(F26:F29) -> 65 | W14: =SUM(G26:G29) -> 1 | X14: =SUM(H26:H29) -> 0 | Y14: =SUM(I26:I29) -> 17 | Z14: =SUM(J26:J29) -> 14 | ... AF14: =SUM(P26:P29) -> 382
B15: 08.15 - 08.30 | C15: 21 | D15: 13 | E15: 5 | F15: 31 | G15: 0 | H15: 0 | I15: 7 | J15: 2 | K15: 3 | L15: 1 | M15: 41 | N15: 0 | O15: =SUM(C15:L15,N15) -> 83 | P15: =SUM(C15:N15) -> 124 | R15: 1200-1300 | S15: =SUM(C30:C33) -> 57 | T15: =SUM(D30:D33) -> 24 | U15: =SUM(E30:E33) -> 18 | V15: =SUM(F30:F33) -> 77 | W15: =SUM(G30:G33) -> 0 | X15: =SUM(H30:H33) -> 0 | Y15: =SUM(I30:I33) -> 16 | Z15: =SUM(J30:J33) -> 7 | ... AF15: =SUM(P30:P33) -> 388
B16: 08.30 - 08.45 | C16: 23 | D16: 25 | E16: 2 | F16: 36 | G16: 0 | H16: 0 | I16: 6 | J16: 5 | K16: 5 | L16: 0 | M16: 32 | N16: 0 | O16: =SUM(C16:L16,N16) -> 102 | P16: =SUM(C16:N16) -> 134 | R16: 1300-1400 | S16: =SUM(C34:C37) -> 42 | T16: =SUM(D34:D37) -> 29 | U16: =SUM(E34:E37) -> 13 | V16: =SUM(F34:F37) -> 55 | W16: =SUM(G34:G37) -> 0 | X16: =SUM(H34:H37) -> 0 | Y16: =SUM(I34:I37) -> 19 | Z16: =SUM(J34:J37) -> 19 | ... AF16: =SUM(P34:P37) -> 363
B17: 08.45 - 9.00 | C17: 22 | D17: 9 | E17: 1 | F17: 41 | G17: 0 | H17: 0 | I17: 5 | J17: 2 | K17: 6 | L17: 1 | M17: 43 | N17: 0 | O17: =SUM(C17:L17,N17) -> 87 | P17: =SUM(C17:N17) -> 130 | R17: 1400-1500 | S17: =SUM(C38:C41) -> 44 | T17: =SUM(D38:D41) -> 24 | U17: =SUM(E38:E41) -> 18 | V17: =SUM(F38:F41) -> 74 | W17: =SUM(G38:G41) -> 0 | X17: =SUM(H38:H41) -> 0 | Y17: =SUM(I38:I41) -> 22 | Z17: =SUM(J38:J41) -> 16 | ... AF17: =SUM(P38:P41) -> 377
B18: 09.00 - 09.15 | C18: 21 | D18: 4 | E18: 5 | F18: 34 | G18: 0 | H18: 0 | I18: 7 | J18: 2 | K18: 7 | L18: 1 | M18: 60 | N18: 0 | O18: =SUM(C18:L18,N18) -> 81 | P18: =SUM(C18:N18) -> 141 | R18: 1500-1600 | S18: =SUM(C42:C45) -> 71 | T18: =SUM(D42:D45) -> 39 | U18: =SUM(E42:E45) -> 19 | V18: =SUM(F42:F45) -> 89 | W18: =SUM(G42:G45) -> 1 | X18: =SUM(H42:H45) -> 0 | Y18: =SUM(I42:I45) -> 32 | Z18: =SUM(J42:J45) -> 19 | ... AF18: =SUM(P42:P45) -> 439
B19: 09.15 - 09.30 | C19: 15 | D19: 6 | E19: 6 | F19: 36 | G19: 0 | H19: 0 | I19: 16 | J19: 3 | K19: 6 | L19: 2 | M19: 42 | N19: 0 | O19: =SUM(C19:L19,N19) -> 90 | P19: =SUM(C19:N19) -> 132 | R19: 1600-1700 | S19: =SUM(C46:C49) -> 76 | T19: =SUM(D46:D49) -> 50 | U19: =SUM(E46:E49) -> 24 | V19: =SUM(F46:F49) -> 65 | W19: =SUM(G46:G49) -> 0 | X19: =SUM(H46:H49) -> 0 | Y19: =SUM(I46:I49) -> 36 | Z19: =SUM(J46:J49) -> 22 | ... AF19: =SUM(P46:P49) -> 481
B20: 09.30 - 09.45 | C20: 33 | D20: 6 | E20: 2 | F20: 23 | G20: 0 | H20: 0 | I20: 0 | J20: 1 | K20: 11 | L20: 1 | M20: 47 | N20: 0 | O20: =SUM(C20:L20,N20) -> 77 | P20: =SUM(C20:N20) -> 124 | R20: 1700-1800 | S20: =SUM(C50:C53) -> 130 | T20: =SUM(D50:D53) -> 70 | U20: =SUM(E50:E53) -> 28 | V20: =SUM(F50:F53) -> 109 | W20: =SUM(G50:G53) -> 4 | X20: =SUM(H50:H53) -> 1 | Y20: =SUM(I50:I53) -> 33 | Z20: =SUM(J50:J53) -> 15 | ... AF20: =SUM(P50:P53) -> 594
B21: 09.45 - 10.00 | C21: 6 | D21: 4 | E21: 3 | F21: 28 | G21: 0 | H21: 0 | I21: 2 | J21: 2 | K21: 4 | L21: 1 | M21: 21 | N21: 0 | O21: =SUM(C21:L21,N21) -> 50 | P21: =SUM(C21:N21) -> 71 | R21: 1800-1900 | S21: =SUM(C54:C57) -> 152 | T21: =SUM(D54:D57) -> 109 | U21: =SUM(E54:E57) -> 43 | V21: =SUM(F54:F57) -> 131 | W21: =SUM(G54:G57) -> 1 | X21: =SUM(H54:H57) -> 0 | Y21: =SUM(I54:I57) -> 23 | Z21: =SUM(J54:J57) -> 10 | ... AF21: =SUM(P54:P57) -> 734
B22: 10.00 - 10.15 | C22: 20 | D22: 6 | E22: 1 | F22: 25 | G22: 0 | H22: 1 | I22: 8 | J22: 2 | K22: 10 | L22: 4 | M22: 39 | N22: 0 | O22: =SUM(C22:L22,N22) -> 77 | P22: =SUM(C22:N22) -> 116 | R22: AM Peak Hr | S22: =MAX(S10:S12) -> 107 | T22: =MAX(T10:T12) -> 70 | U22: =MAX(U10:U12) -> 23 | V22: =MAX(V10:V12) -> 153 | W22: =MAX(W10:W12) -> 4 | X22: =MAX(X10:X12) -> 1 | Y22: =MAX(Y10:Y12) -> 25 | Z22: =MAX(Z10:Z12) -> 16 | ... AF22: =MAX(AF10:AF12) -> 569
B23: 10.15 - 10.30 | C23: 23 | D23: 3 | E23: 5 | F23: 23 | G23: 1 | H23: 0 | I23: 7 | J23: 1 | K23: 15 | L23: 3 | M23: 37 | N23: 0 | O23: =SUM(C23:L23,N23) -> 81 | P23: =SUM(C23:N23) -> 118 | R23: IP Peak Hr | S23: =MAX(S13:S18) -> 81 | T23: =MAX(T13:T18) -> 39 | U23: =MAX(U13:U18) -> 19 | V23: =MAX(V13:V18) -> 91 | W23: =MAX(W13:W18) -> 1 | X23: =MAX(X13:X18) -> 1 | Y23: =MAX(Y13:Y18) -> 32 | Z23: =MAX(Z13:Z18) -> 19 | ... AF23: =MAX(AF13:AF18) -> 455
B24: 10.30 - 10.45 | C24: 18 | D24: 5 | E24: 2 | F24: 21 | G24: 0 | H24: 0 | I24: 12 | J24: 2 | K24: 7 | L24: 5 | M24: 43 | N24: 0 | O24: =SUM(C24:L24,N24) -> 72 | P24: =SUM(C24:N24) -> 115 | R24: PM Peak Hr | S24: =MAX(S19:S21) -> 152 | T24: =MAX(T19:T21) -> 109 | U24: =MAX(U19:U21) -> 43 | V24: =MAX(V19:V21) -> 131 | W24: =MAX(W19:W21) -> 4 | X24: =MAX(X19:X21) -> 1 | Y24: =MAX(Y19:Y21) -> 36 | Z24: =MAX(Z19:Z21) -> 22 | ... AF24: =MAX(AF19:AF21) -> 734
B25: 10.45 - 11.00 | C25: 20 | D25: 3 | E25: 3 | F25: 22 | G25: 0 | H25: 0 | I25: 4 | J25: 1 | K25: 8 | L25: 1 | M25: 44 | N25: 0 | O25: =SUM(C25:L25,N25) -> 62 | P25: =SUM(C25:N25) -> 106 | R25: AM Period | S25: =SUM(S10:S12) -> 276 | T25: =SUM(T10:T12) -> 119 | U25: =SUM(U10:U12) -> 56 | V25: =SUM(V10:V12) -> 396 | W25: =SUM(W10:W12) -> 5 | X25: =SUM(X10:X12) -> 1 | Y25: =SUM(Y10:Y12) -> 70 | Z25: =SUM(Z10:Z12) -> 34 | ... AF25: =SUM(AF10:AF12) -> 1482
B26: 11.00 - 11.15 | C26: 18 | D26: 5 | E26: 3 | F26: 18 | G26: 0 | H26: 0 | I26: 3 | J26: 3 | K26: 7 | L26: 6 | M26: 34 | N26: 0 | O26: =SUM(C26:L26,N26) -> 63 | P26: =SUM(C26:N26) -> 97 | R26: IP Period | S26: =SUM(S13:S18) -> 361 | T26: =SUM(T13:T18) -> 157 | U26: =SUM(U13:U18) -> 90 | V26: =SUM(V13:V18) -> 451 | W26: =SUM(W13:W18) -> 3 | X26: =SUM(X13:X18) -> 1 | Y26: =SUM(Y13:Y18) -> 137 | Z26: =SUM(Z13:Z18) -> 81 | ... AF26: =SUM(AF13:AF18) -> 2404
B27: 11.15 - 11.30 | C27: 23 | D27: 5 | E27: 3 | F27: 21 | G27: 1 | H27: 0 | I27: 9 | J27: 3 | K27: 4 | L27: 6 | M27: 30 | N27: 0 | O27: =SUM(C27:L27,N27) -> 75 | P27: =SUM(C27:N27) -> 105 | R27: PM Period | S27: =SUM(S19:S21) -> 358 | T27: =SUM(T19:T21) -> 229 | U27: =SUM(U19:U21) -> 95 | V27: =SUM(V19:V21) -> 305 | W27: =SUM(W19:W21) -> 5 | X27: =SUM(X19:X21) -> 1 | Y27: =SUM(Y19:Y21) -> 92 | Z27: =SUM(Z19:Z21) -> 47 | ... AF27: =SUM(AF19:AF21) -> 1809
