Workbook

Sheet 25.10 Katuna-Kabale 24hr
B1: Consultancy services for Preparation of Expressway Development Master Plan (EDMP) for Uganda
B2: MANUAL CLASSIFIED COUNT (MCC)
B3: ROAD NAME: | C3: ='26.10 Katuna-Kabale'!C3:G3 -> MCC - C1 - STN134 - KATUNA-KABALE ROAD
C5: Date | D5: 25.10.19 | F5: Location | G5: Katuba BP | J5: Surveyor | K5: Ainebyona E
C6: Dir. From | D6: Katuna | F6: Dir. To | G6: Kabale | J6: Supervisor | K6: Mbabazi
B8: Time / Veh Type | R8: SUMMARY TRAFFIC VOLUMES
C9: 1. Car | D9: 2. Station Wagon | E9: 3. Pickups | F9: 4. Minibus, matatu | G9: 5. Medium bus | H9: 6. Large Bus | I9: 7. Light Truck | J9: 8. Medium Truck | K9: 9. Heavy truck | L9: 10. Truck Trailer | M9: 11. Motor cycles | N9: 12. Tractors | O9: Total Excl M/Cycles | P9: Total All | R9: Time | S9: 1. Car | T9: 2. Station Wagon | U9: 3. Pickups | V9: 4. Minibus, matatu | W9: 5. Medium bus | X9: 6. Large Bus | Y9: 7. Light Truck | Z9: 8. Medium Truck | AA9: 9. Heavy truck | AB9: 10. Truck Trailer | AC9: 11. Motorcycles | AD9: 12. Tractors, Graders | AE9: Total Excl M/ Cycles | AF9: Total All
B10: 07.00 - 07.15 | C10: 1 | D10: 0 | E10: 0 | F10: 0 | G10: 0 | H10: 0 | I10: 0 | J10: 0 | K10: 0 | L10: 0 | M10: 4 | N10: 0 | O10: =SUM(C10:L10,N10) -> 1 | P10: =SUM(C10:N10) -> 5 | R10: 0700-0800 | S10: =SUM(C10:C13) -> 6 | T10: =SUM(D10:D13) -> 1 | U10: =SUM(E10:E13) -> 0 | V10: =SUM(F10:F13) -> 0 | W10: =SUM(G10:G13) -> 0 | X10: =SUM(H10:H13) -> 0 | Y10: =SUM(I10:I13) -> 0 | Z10: =SUM(J10:J13) -> 0 | ... AF10: =SUM(P10:P13) -> 20
B11: 07.15 - 07.30 | C11: 2 | D11: 0 | E11: 0 | F11: 0 | G11: 0 | H11: 0 | I11: 0 | J11: 0 | K11: 0 | L11: 0 | M11: 0 | N11: 0 | O11: =SUM(C11:L11,N11) -> 2 | P11: =SUM(C11:N11) -> 2 | R11: 0800-0900 | S11: =SUM(C14:C17) -> 21 | T11: =SUM(D14:D17) -> 1 | U11: =SUM(E14:E17) -> 1 | V11: =SUM(F14:F17) -> 0 | W11: =SUM(G14:G17) -> 0 | X11: =SUM(H14:H17) -> 0 | Y11: =SUM(I14:I17) -> 2 | Z11: =SUM(J14:J17) -> 0 | ... AF11: =SUM(P14:P17) -> 50
B12: 07.30 - 07.45 | C12: 2 | D12: 0 | E12: 0 | F12: 0 | G12: 0 | H12: 0 | I12: 0 | J12: 0 | K12: 0 | L12: 0 | M12: 4 | N12: 0 | O12: =SUM(C12:L12,N12) -> 2 | P12: =SUM(C12:N12) -> 6 | R12: 0900-1000 | S12: =SUM(C18:C21) -> 17 | T12: =SUM(D18:D21) -> 1 | U12: =SUM(E18:E21) -> 2 | V12: =SUM(F18:F21) -> 1 | W12: =SUM(G18:G21) -> 0 | X12: =SUM(H18:H21) -> 0 | Y12: =SUM(I18:I21) -> 8 | Z12: =SUM(J18:J21) -> 0 | ... AF12: =SUM(P18:P21) -> 62
B13: 07.45 - 08.00 | C13: 1 | D13: 1 | E13: 0 | F13: 0 | G13: 0 | H13: 0 | I13: 0 | J13: 0 | K13: 0 | L13: 0 | M13: 5 | N13: 0 | O13: =SUM(C13:L13,N13) -> 2 | P13: =SUM(C13:N13) -> 7 | R13: 1000-1100 | S13: =SUM(C22:C25) -> 15 | T13: =SUM(D22:D25) -> 0 | U13: =SUM(E22:E25) -> 2 | V13: =SUM(F22:F25) -> 0 | W13: =SUM(G22:G25) -> 0 | X13: =SUM(H22:H25) -> 0 | Y13: =SUM(I22:I25) -> 3 | Z13: =SUM(J22:J25) -> 0 | ... AF13: =SUM(P22:P25) -> 50
B14: 08.00 - 08.15 | C14: 5 | D14: 0 | E14: 1 | F14: 0 | G14: 0 | H14: 0 | I14: 0 | J14: 0 | K14: 0 | L14: 0 | M14: 5 | N14: 0 | O14: =SUM(C14:L14,N14) -> 6 | P14: =SUM(C14:N14) -> 11 | R14: 1100-1200 | S14: =SUM(C26:C29) -> 11 | T14: =SUM(D26:D29) -> 0 | U14: =SUM(E26:E29) -> 0 | V14: =SUM(F26:F29) -> 0 | W14: =SUM(G26:G29) -> 1 | X14: =SUM(H26:H29) -> 0 | Y14: =SUM(I26:I29) -> 1 | Z14: =SUM(J26:J29) -> 0 | ... AF14: =SUM(P26:P29) -> 37
B15: 08.15 - 08.30 | C15: 6 | D15: 1 | E15: 0 | F15: 0 | G15: 0 | H15: 0 | I15: 0 | J15: 0 | K15: 0 | L15: 0 | M15: 3 | N15: 0 | O15: =SUM(C15:L15,N15) -> 7 | P15: =SUM(C15:N15) -> 10 | R15: 1200-1300 | S15: =SUM(C30:C33) -> 16 | T15: =SUM(D30:D33) -> 10 | U15: =SUM(E30:E33) -> 0 | V15: =SUM(F30:F33) -> 0 | W15: =SUM(G30:G33) -> 0 | X15: =SUM(H30:H33) -> 2 | Y15: =SUM(I30:I33) -> 5 | Z15: =SUM(J30:J33) -> 0 | ... AF15: =SUM(P30:P33) -> 65
B16: 08.30 - 08.45 | C16: 2 | D16: 0 | E16: 0 | F16: 0 | G16: 0 | H16: 0 | I16: 0 | J16: 0 | K16: 0 | L16: 0 | M16: 7 | N16: 0 | O16: =SUM(C16:L16,N16) -> 2 | P16: =SUM(C16:N16) -> 9 | R16: 1300-1400 | S16: =SUM(C34:C37) -> 13 | T16: =SUM(D34:D37) -> 2 | U16: =SUM(E34:E37) -> 0 | V16: =SUM(F34:F37) -> 1 | W16: =SUM(G34:G37) -> 1 | X16: =SUM(H34:H37) -> 0 | Y16: =SUM(I34:I37) -> 0 | Z16: =SUM(J34:J37) -> 0 | ... AF16: =SUM(P34:P37) -> 47
B17: 08.45 - 9.00 | C17: 8 | D17: 0 | E17: 0 | F17: 0 | G17: 0 | H17: 0 | I17: 2 | J17: 0 | K17: 0 | L17: 0 | M17: 10 | N17: 0 | O17: =SUM(C17:L17,N17) -> 10 | P17: =SUM(C17:N17) -> 20 | R17: 1400-1500 | S17: =SUM(C38:C41) -> 11 | T17: =SUM(D38:D41) -> 1 | U17: =SUM(E38:E41) -> 1 | V17: =SUM(F38:F41) -> 0 | W17: =SUM(G38:G41) -> 0 | X17: =SUM(H38:H41) -> 0 | Y17: =SUM(I38:I41) -> 3 | Z17: =SUM(J38:J41) -> 0 | ... AF17: =SUM(P38:P41) -> 42
B18: 09.00 - 09.15 | C18: 5 | D18: 0 | E18: 1 | F18: 0 | G18: 0 | H18: 0 | I18: 3 | J18: 0 | K18: 0 | L18: 0 | M18: 6 | N18: 0 | O18: =SUM(C18:L18,N18) -> 9 | P18: =SUM(C18:N18) -> 15 | R18: 1500-1600 | S18: =SUM(C42:C45) -> 10 | T18: =SUM(D42:D45) -> 2 | U18: =SUM(E42:E45) -> 4 | V18: =SUM(F42:F45) -> 2 | W18: =SUM(G42:G45) -> 0 | X18: =SUM(H42:H45) -> 0 | Y18: =SUM(I42:I45) -> 3 | Z18: =SUM(J42:J45) -> 2 | ... AF18: =SUM(P42:P45) -> 43
B19: 09.15 - 09.30 | C19: 3 | D19: 0 | E19: 1 | F19: 1 | G19: 0 | H19: 0 | I19: 2 | J19: 0 | K19: 0 | L19: 0 | M19: 13 | N19: 0 | O19: =SUM(C19:L19,N19) -> 7 | P19: =SUM(C19:N19) -> 20 | R19: 1600-1700 | S19: =SUM(C46:C49) -> 8 | T19: =SUM(D46:D49) -> 0 | U19: =SUM(E46:E49) -> 2 | V19: =SUM(F46:F49) -> 1 | W19: =SUM(G46:G49) -> 0 | X19: =SUM(H46:H49) -> 0 | Y19: =SUM(I46:I49) -> 1 | Z19: =SUM(J46:J49) -> 0 | ... AF19: =SUM(P46:P49) -> 42
B20: 09.30 - 09.45 | C20: 3 | D20: 0 | E20: 0 | F20: 0 | G20: 0 | H20: 0 | I20: 1 | J20: 0 | K20: 0 | L20: 0 | M20: 5 | N20: 0 | O20: =SUM(C20:L20,N20) -> 4 | P20: =SUM(C20:N20) -> 9 | R20: 1700-1800 | S20: =SUM(C50:C53) -> 17 | T20: =SUM(D50:D53) -> 6 | U20: =SUM(E50:E53) -> 1 | V20: =SUM(F50:F53) -> 1 | W20: =SUM(G50:G53) -> 0 | X20: =SUM(H50:H53) -> 0 | Y20: =SUM(I50:I53) -> 1 | Z20: =SUM(J50:J53) -> 0 | ... AF20: =SUM(P50:P53) -> 64
B21: 09.45 - 10.00 | C21: 6 | D21: 1 | E21: 0 | F21: 0 | G21: 0 | H21: 0 | I21: 2 | J21: 0 | K21: 0 | L21: 0 | M21: 9 | N21: 0 | O21: =SUM(C21:L21,N21) -> 9 | P21: =SUM(C21:N21) -> 18 | R21: 1800-1900 | S21: =SUM(C54:C57) -> 21 | T21: =SUM(D54:D57) -> 7 | U21: =SUM(E54:E57) -> 4 | V21: =SUM(F54:F57) -> 0 | W21: =SUM(G54:G57) -> 0 | X21: =SUM(H54:H57) -> 0 | Y21: =SUM(I54:I57) -> 9 | Z21: =SUM(J54:J57) -> 0 | ... AF21: =SUM(P54:P57) -> 63
B22: 10.00 - 10.15 | C22: 1 | D22: 0 | E22: 0 | F22: 0 | G22: 0 | H22: 0 | I22: 1 | J22: 0 | K22: 0 | L22: 0 | M22: 6 | N22: 0 | O22: =SUM(C22:L22,N22) -> 2 | P22: =SUM(C22:N22) -> 8 | R22: 1900-2000 | S22: =SUM(C58:C61) -> 15 | T22: =SUM(D58:D61) -> 6 | U22: =SUM(E58:E61) -> 2 | V22: =SUM(F58:F61) -> 0 | W22: =SUM(G58:G61) -> 0 | X22: =SUM(H58:H61) -> 1 | Y22: =SUM(I58:I61) -> 0 | Z22: =SUM(J58:J61) -> 0 | ... AF22: =SUM(P58:P61) -> 35
B23: 10.15 - 10.30 | C23: 3 | D23: 0 | E23: 0 | F23: 0 | G23: 0 | H23: 0 | I23: 0 | J23: 0 | K23: 0 | L23: 0 | M23: 9 | N23: 0 | O23: =SUM(C23:L23,N23) -> 3 | P23: =SUM(C23:N23) -> 12 | R23: 2000-2100 | S23: =SUM(C62:C65) -> 15 | T23: =SUM(D62:D65) -> 7 | U23: =SUM(E62:E65) -> 3 | V23: =SUM(F62:F65) -> 4 | W23: =SUM(G62:G65) -> 1 | X23: =SUM(H62:H65) -> 0 | Y23: =SUM(I62:I65) -> 3 | Z23: =SUM(J62:J65) -> 0 | ... AF23: =SUM(P62:P65) -> 58
B24: 10.30 - 10.45 | C24: 5 | D24: 0 | E24: 0 | F24: 0 | G24: 0 | H24: 0 | I24: 1 | J24: 0 | K24: 0 | L24: 0 | M24: 7 | N24: 0 | O24: =SUM(C24:L24,N24) -> 6 | P24: =SUM(C24:N24) -> 13 | R24: 2100-2200 | S24: =SUM(C66:C69) -> 8 | T24: =SUM(D66:D69) -> 1 | U24: =SUM(E66:E69) -> 1 | V24: =SUM(F66:F69) -> 2 | W24: =SUM(G66:G69) -> 0 | X24: =SUM(H66:H69) -> 0 | Y24: =SUM(I66:I69) -> 2 | Z24: =SUM(J66:J69) -> 0 | ... AF24: =SUM(P66:P69) -> 24
B25: 10.45 - 11.00 | C25: 6 | D25: 0 | E25: 2 | F25: 0 | G25: 0 | H25: 0 | I25: 1 | J25: 0 | K25: 0 | L25: 0 | M25: 8 | N25: 0 | O25: =SUM(C25:L25,N25) -> 9 | P25: =SUM(C25:N25) -> 17 | R25: 2200-2300 | S25: =SUM(C70:C73) -> 4 | T25: =SUM(D70:D73) -> 0 | U25: =SUM(E70:E73) -> 0 | V25: =SUM(F70:F73) -> 0 | W25: =SUM(G70:G73) -> 0 | X25: =SUM(H70:H73) -> 0 | Y25: =SUM(I70:I73) -> 1 | Z25: =SUM(J70:J73) -> 0 | ... AF25: =SUM(P70:P73) -> 12
B26: 11.00 - 11.15 | C26: 3 | D26: 0 | E26: 0 | F26: 0 | G26: 0 | H26: 0 | I26: 1 | J26: 0 | K26: 0 | L26: 0 | M26: 5 | N26: 0 | O26: =SUM(C26:L26,N26) -> 4 | P26: =SUM(C26:N26) -> 9 | R26: 2300-0000 | S26: =SUM(C74:C77) -> 4 | T26: =SUM(D74:D77) -> 0 | U26: =SUM(E74:E77) -> 0 | V26: =SUM(F74:F77) -> 0 | W26: =SUM(G74:G77) -> 0 | X26: =SUM(H74:H77) -> 0 | Y26: =SUM(I74:I77) -> 1 | Z26: =SUM(J74:J77) -> 0 | ... AF26: =SUM(P74:P77) -> 7
B27: 11.15 - 11.30 | C27: 2 | D27: 0 | E27: 0 | F27: 0 | G27: 0 | H27: 0 | I27: 0 | J27: 0 | K27: 0 | L27: 0 | M27: 4 | N27: 0 | O27: =SUM(C27:L27,N27) -> 2 | P27: =SUM(C27:N27) -> 6 | R27: 0000-0100 | S27: =SUM(C78:C81) -> 4 | T27: =SUM(D78:D81) -> 2 | U27: =SUM(E78:E81) -> 1 | V27: =SUM(F78:F81) -> 0 | W27: =SUM(G78:G81) -> 0 | X27: =SUM(H78:H81) -> 0 | Y27: =SUM(I78:I81) -> 1 | Z27: =SUM(J78:J81) -> 0 | ... AF27: =SUM(P78:P81) -> 9
B28: 11.30 - 11.45 | C28: 1 | D28: 0 | E28: 0 | F28: 0 | G28: 1 | H28: 0 | I28: 0 | J28: 0 | K28: 0 | L28: 0 | M28: 9 | N28: 0 | O28: =SUM(C28:L28,N28) -> 2 | P28: =SUM(C28:N28) -> 11 | R28: 0100-0200 | S28: =SUM(C82:C85) -> 1 | T28: =SUM(D82:D85) -> 1 | U28: =SUM(E82:E85) -> 3 | V28: =SUM(F82:F85) -> 0 | W28: =SUM(G82:G85) -> 0 | X28: =SUM(H82:H85) -> 0 | Y28: =SUM(I82:I85) -> 0 | Z28: =SUM(J82:J85) -> 2 | ... AF28: =SUM(P82:P85) -> 10
B29: 11.45 - 12.00 | C29: 5 | D29: 0 | E29: 0 | F29: 0 | G29: 0 | H29: 0 | I29: 0 | J29: 0 | K29: 0 | L29: 0 | M29: 6 | N29: 0 | O29: =SUM(C29:L29,N29) -> 5 | P29: =SUM(C29:N29) -> 11 | R29: 0200-0300 | S29: =SUM(C86:C89) -> 6 | T29: =SUM(D86:D89) -> 2 | U29: =SUM(E86:E89) -> 2 | V29: =SUM(F86:F89) -> 0 | W29: =SUM(G86:G89) -> 1 | X29: =SUM(H86:H89) -> 0 | Y29: =SUM(I86:I89) -> 2 | Z29: =SUM(J86:J89) -> 0 | ... AF29: =SUM(P86:P89) -> 14
B30: 12.00 - 12.15 | C30: 1 | D30: 6 | E30: 0 | F30: 0 | G30: 0 | H30: 1 | I30: 0 | J30: 0 | K30: 0 | L30: 0 | M30: 8 | N30: 0 | O30: =SUM(C30:L30,N30) -> 8 | P30: =SUM(C30:N30) -> 16 | R30: 0300-0400 | S30: =SUM(C90:C93) -> 6 | T30: =SUM(D90:D93) -> 2 | U30: =SUM(E90:E93) -> 3 | V30: =SUM(F90:F93) -> 0 | W30: =SUM(G90:G93) -> 0 | X30: =SUM(H90:H93) -> 0 | Y30: =SUM(I90:I93) -> 2 | Z30: =SUM(J90:J93) -> 0 | ... AF30: =SUM(P90:P93) -> 14
B31: 12.15 - 12.30 | C31: 6 | D31: 2 | E31: 0 | F31: 0 | G31: 0 | H31: 0 | I31: 3 | J31: 0 | K31: 0 | L31: 0 | M31: 10 | N31: 0 | O31: =SUM(C31:L31,N31) -> 11 | P31: =SUM(C31:N31) -> 21 | R31: 0400-0500 | S31: =SUM(C94:C97) -> 1 | T31: =SUM(D94:D97) -> 1 | U31: =SUM(E94:E97) -> 2 | V31: =SUM(F94:F97) -> 0 | W31: =SUM(G94:G97) -> 2 | X31: =SUM(H94:H97) -> 0 | Y31: =SUM(I94:I97) -> 1 | Z31: =SUM(J94:J97) -> 0 | ... AF31: =SUM(P94:P97) -> 11
B32: 12.30 - 12.45 | C32: 5 | D32: 2 | E32: 0 | F32: 0 | G32: 0 | H32: 0 | I32: 0 | J32: 0 | K32: 0 | L32: 0 | M32: 6 | N32: 0 | O32: =SUM(C32:L32,N32) -> 7 | P32: =SUM(C32:N32) -> 13 | R32: 0500-0600 | S32: =SUM(C98:C101) -> 4 | T32: =SUM(D98:D101) -> 4 | U32: =SUM(E98:E101) -> 1 | V32: =SUM(F98:F101) -> 3 | W32: =SUM(G98:G101) -> 0 | X32: =SUM(H98:H101) -> 0 | Y32: =SUM(I98:I101) -> 6 | Z32: =SUM(J98:J101) -> 0 | ... AF32: =SUM(P98:P101) -> 25
B33: 12.45 - 13.00 | C33: 4 | D33: 0 | E33: 0 | F33: 0 | G33: 0 | H33: 1 | I33: 2 | J33: 0 | K33: 0 | L33: 0 | M33: 8 | N33: 0 | O33: =SUM(C33:L33,N33) -> 7 | P33: =SUM(C33:N33) -> 15 | R33: 0600-0700 | S33: =SUM(C102:C105) -> 6 | T33: =SUM(D102:D105) -> 6 | U33: =SUM(E102:E105) -> 3 | V33: =SUM(F102:F105) -> 3 | W33: =SUM(G102:G105) -> 2 | X33: =SUM(H102:H105) -> 0 | Y33: =SUM(I102:I105) -> 5 | Z33: =SUM(J102:J105) -> 0 | ... AF33: =SUM(P102:P105) -> 41
B34: 13.00 - 13.15 | C34: 5 | D34: 0 | E34: 0 | F34: 0 | G34: 0 | H34: 0 | I34: 0 | J34: 0 | K34: 0 | L34: 0 | M34: 6 | N34: 0 | O34: =SUM(C34:L34,N34) -> 5 | P34: =SUM(C34:N34) -> 11 | R34: AM Peak Hr | S34: =MAX(S10:S12) -> 21 | T34: =MAX(T10:T12) -> 1 | U34: =MAX(U10:U12) -> 2 | V34: =MAX(V10:V12) -> 1 | W34: =MAX(W10:W12) -> 0 | X34: =MAX(X10:X12) -> 0 | Y34: =MAX(Y10:Y12) -> 8 | Z34: =MAX(Z10:Z12) -> 0 | ... AF34: =MAX(AF10:AF12) -> 62
B35: 13.15 - 13.30 | C35: 2 | D35: 0 | E35: 0 | F35: 0 | G35: 0 | H35: 0 | I35: 0 | J35: 0 | K35: 0 | L35: 0 | M35: 5 | N35: 0 | O35: =SUM(C35:L35,N35) -> 2 | P35: =SUM(C35:N35) -> 7 | R35: IP Peak Hr | S35: =MAX(S13:S18) -> 16 | T35: =MAX(T13:T18) -> 10 | U35: =MAX(U13:U18) -> 4 | V35: =MAX(V13:V18) -> 2 | W35: =MAX(W13:W18) -> 1 | X35: =MAX(X13:X18) -> 2 | Y35: =MAX(Y13:Y18) -> 5 | Z35: =MAX(Z13:Z18) -> 2 | ... AF35: =MAX(AF13:AF18) -> 65
B36: 13.30 - 13.45 | C36: 4 | D36: 0 | E36: 0 | F36: 1 | G36: 1 | H36: 0 | I36: 0 | J36: 0 | K36: 0 | L36: 0 | M36: 10 | N36: 0 | O36: =SUM(C36:L36,N36) -> 6 | P36: =SUM(C36:N36) -> 16 | R36: PM Peak Hr | S36: =MAX(S19:S21) -> 21 | T36: =MAX(T19:T21) -> 7 | U36: =MAX(U19:U21) -> 4 | V36: =MAX(V19:V21) -> 1 | W36: =MAX(W19:W21) -> 0 | X36: =MAX(X19:X21) -> 0 | Y36: =MAX(Y19:Y21) -> 9 | Z36: =MAX(Z19:Z21) -> 0 | ... AF36: =MAX(AF19:AF21) -> 64
B37: 13.45 - 14.00 | C37: 2 | D37: 2 | E37: 0 | F37: 0 | G37: 0 | H37: 0 | I37: 0 | J37: 0 | K37: 0 | L37: 0 | M37: 9 | N37: 0 | O37: =SUM(C37:L37,N37) -> 4 | P37: =SUM(C37:N37) -> 13 | R37: AM Period | S37: =SUM(S10:S12) -> 44 | T37: =SUM(T10:T12) -> 3 | U37: =SUM(U10:U12) -> 3 | V37: =SUM(V10:V12) -> 1 | W37: =SUM(W10:W12) -> 0 | X37: =SUM(X10:X12) -> 0 | Y37: =SUM(Y10:Y12) -> 10 | Z37: =SUM(Z10:Z12) -> 0 | ... AF37: =SUM(AF10:AF12) -> 132
B38: 14.00 - 14.15 | C38: 3 | D38: 0 | E38: 1 | F38: 0 | G38: 0 | H38: 0 | I38: 2 | J38: 0 | K38: 0 | L38: 0 | M38: 6 | N38: 0 | O38: =SUM(C38:L38,N38) -> 6 | P38: =SUM(C38:N38) -> 12 | R38: IP Period | S38: =SUM(S13:S18) -> 76 | T38: =SUM(T13:T18) -> 15 | U38: =SUM(U13:U18) -> 7 | V38: =SUM(V13:V18) -> 3 | W38: =SUM(W13:W18) -> 2 | X38: =SUM(X13:X18) -> 2 | Y38: =SUM(Y13:Y18) -> 15 | Z38: =SUM(Z13:Z18) -> 2 | ... AF38: =SUM(AF13:AF18) -> 284
B39: 14.15 - 14.30 | C39: 3 | D39: 1 | E39: 0 | F39: 0 | G39: 0 | H39: 0 | I39: 0 | J39: 0 | K39: 0 | L39: 0 | M39: 10 | N39: 0 | O39: =SUM(C39:L39,N39) -> 4 | P39: =SUM(C39:N39) -> 14 | R39: PM Period | S39: =SUM(S19:S21) -> 46 | T39: =SUM(T19:T21) -> 13 | U39: =SUM(U19:U21) -> 7 | V39: =SUM(V19:V21) -> 2 | W39: =SUM(W19:W21) -> 0 | X39: =SUM(X19:X21) -> 0 | Y39: =SUM(Y19:Y21) -> 11 | Z39: =SUM(Z19:Z21) -> 0 | ... AF39: =SUM(AF19:AF21) -> 169
B40: 14.30 - 14.45 | C40: 5 | D40: 0 | E40: 0 | F40: 0 | G40: 0 | H40: 0 | I40: 0 | J40: 0 | K40: 0 | L40: 0 | M40: 6 | N40: 0 | O40: =SUM(C40:L40,N40) -> 5 | P40: =SUM(C40:N40) -> 11 | R40: 12 Hours | S40: =SUM(S10:S21) -> 166 | T40: =SUM(T10:T21) -> 31 | U40: =SUM(U10:U21) -> 17 | V40: =SUM(V10:V21) -> 6 | W40: =SUM(W10:W21) -> 2 | X40: =SUM(X10:X21) -> 2 | Y40: =SUM(Y10:Y21) -> 36 | Z40: =SUM(Z10:Z21) -> 2 | ... AF40: =SUM(AF10:AF21) -> 585
B41: 14.45 - 15.00 | C41: 0 | D41: 0 | E41: 0 | F41: 0 | G41: 0 | H41: 0 | I41: 1 | J41: 0 | K41: 0 | L41: 0 | M41: 4 | N41: 0 | O41: =SUM(C41:L41,N41) -> 1 | P41: =SUM(C41:N41) -> 5 | R41: 24 Hrs/ADT | S41: =SUM(S10:S33) -> 240 | T41: =SUM(T10:T33) -> 63 | U41: =SUM(U10:U33) -> 38 | V41: =SUM(V10:V33) -> 18 | W41: =SUM(W10:W33) -> 8 | X41: =SUM(X10:X33) -> 3 | Y41: =SUM(Y10:Y33) -> 60 | Z41: =SUM(Z10:Z33) -> 4 | ... AF41: =SUM(AF10:AF33) -> 845
B42: 15.00 - 15.15 | C42: 4 | D42: 1 | E42: 1 | F42: 0 | G42: 0 | H42: 0 | I42: 1 | J42: 1 | K42: 0 | L42: 0 | M42: 4 | N42: 0 | O42: =SUM(C42:L42,N42) -> 8 | P42: =SUM(C42:N42) -> 12 | R42: NEF | S42: =S41/S40 -> 1.4457831 | T42: =T41/T40 -> 2.0322581 | U42: =U41/U40 -> 2.2352941 | V42: =V41/V40 -> 3 | W42: =W41/W40 -> 4 | X42: =X41/X40 -> 1.5 | Y42: =Y41/Y40 -> 1.6666667 | Z42: =Z41/Z40 -> 2 | ... AF42: =AF41/AF40 -> 1.4444444
...

Sheet 25.10 Kabale-Katuna 24hr
B1: Consultancy services for Preparation of Expressway Development Master Plan (EDMP) for Uganda
B2: MANUAL CLASSIFIED COUNT (MCC)
B3: ROAD NAME: | C3: ='26.10 Katuna-Kabale'!C3:G3 -> MCC - C1 - STN134 - KATUNA-KABALE ROAD
C5: Date | D5: ='25.10 Katuna-Kabale 24hr'!D5 -> 25.10.19 | F5: Location | G5: Katuna BP | J5: Surveyor | K5: Kato Joseph
C6: Dir. From | D6: Kabale | F6: Dir. To | G6: Katuna | J6: Supervisor | K6: ='25.10 Katuna-Kabale 24hr'!K6:L6 -> Mbabazi
B8: Time / Veh Type | R8: SUMMARY TRAFFIC VOLUMES
C9: 1. Car | D9: 2. Station Wagon | E9: 3. Pickups | F9: 4. Minibus, matatu | G9: 5. Medium bus | H9: 6. Large Bus | I9: 7. Light Truck | J9: 8. Medium Truck | K9: 9. Heavy truck | L9: 10. Truck Trailer | M9: 11. Motor cycles | N9: 12. Tractors | O9: Total Excl M/Cycles | P9: Total All | R9: Time | S9: 1. Car | T9: 2. Station Wagon | U9: 3. Pickups | V9: 4. Minibus, matatu | W9: 5. Medium bus | X9: 6. Large Bus | Y9: 7. Light Truck | Z9: 8. Medium Truck | AA9: 9. Heavy truck | AB9: 10. Truck Trailer | AC9: 11. Motorcycles | AD9: 12. Tractors, Graders | AE9: Total Excl M/ Cycles | AF9: Total All
B10: 07.00 - 07.15 | C10: 2 | D10: 0 | E10: 0 | F10: 0 | G10: 0 | H10: 0 | I10: 0 | J10: 0 | K10: 0 | L10: 0 | M10: 4 | N10: 0 | O10: =SUM(C10:L10,N10) -> 2 | P10: =SUM(C10:N10) -> 6 | R10: 0700-0800 | S10: =SUM(C10:C13) -> 13 | T10: =SUM(D10:D13) -> 0 | U10: =SUM(E10:E13) -> 0 | V10: =SUM(F10:F13) -> 0 | W10: =SUM(G10:G13) -> 0 | X10: =SUM(H10:H13) -> 0 | Y10: =SUM(I10:I13) -> 2 | Z10: =SUM(J10:J13) -> 0 | ... AF10: =SUM(P10:P13) -> 28
B11: 07.15 - 07.30 | C11: 3 | D11: 0 | E11: 0 | F11: 0 | G11: 0 | H11: 0 | I11: 1 | J11: 0 | K11: 0 | L11: 0 | M11: 4 | N11: 0 | O11: =SUM(C11:L11,N11) -> 4 | P11: =SUM(C11:N11) -> 8 | R11: 0800-0900 | S11: =SUM(C14:C17) -> 5 | T11: =SUM(D14:D17) -> 0 | U11: =SUM(E14:E17) -> 2 | V11: =SUM(F14:F17) -> 0 | W11: =SUM(G14:G17) -> 0 | X11: =SUM(H14:H17) -> 0 | Y11: =SUM(I14:I17) -> 2 | Z11: =SUM(J14:J17) -> 1 | ... AF11: =SUM(P14:P17) -> 44
B12: 07.30 - 07.45 | C12: 7 | D12: 0 | E12: 0 | F12: 0 | G12: 0 | H12: 0 | I12: 1 | J12: 0 | K12: 0 | L12: 0 | M12: 3 | N12: 0 | O12: =SUM(C12:L12,N12) -> 8 | P12: =SUM(C12:N12) -> 11 | R12: 0900-1000 | S12: =SUM(C18:C21) -> 9 | T12: =SUM(D18:D21) -> 1 | U12: =SUM(E18:E21) -> 2 | V12: =SUM(F18:F21) -> 0 | W12: =SUM(G18:G21) -> 2 | X12: =SUM(H18:H21) -> 0 | Y12: =SUM(I18:I21) -> 2 | Z12: =SUM(J18:J21) -> 0 | ... AF12: =SUM(P18:P21) -> 47
B13: 07.45 - 08.00 | C13: 1 | D13: 0 | E13: 0 | F13: 0 | G13: 0 | H13: 0 | I13: 0 | J13: 0 | K13: 0 | L13: 0 | M13: 2 | N13: 0 | O13: =SUM(C13:L13,N13) -> 1 | P13: =SUM(C13:N13) -> 3 | R13: 1000-1100 | S13: =SUM(C22:C25) -> 8 | T13: =SUM(D22:D25) -> 1 | U13: =SUM(E22:E25) -> 1 | V13: =SUM(F22:F25) -> 3 | W13: =SUM(G22:G25) -> 1 | X13: =SUM(H22:H25) -> 0 | Y13: =SUM(I22:I25) -> 3 | Z13: =SUM(J22:J25) -> 0 | ... AF13: =SUM(P22:P25) -> 32
B14: 08.00 - 08.15 | C14: 1 | D14: 0 | E14: 1 | F14: 0 | G14: 0 | H14: 0 | I14: 0 | J14: 1 | K14: 0 | L14: 0 | M14: 8 | N14: 0 | O14: =SUM(C14:L14,N14) -> 3 | P14: =SUM(C14:N14) -> 11 | R14: 1100-1200 | S14: =SUM(C26:C29) -> 12 | T14: =SUM(D26:D29) -> 2 | U14: =SUM(E26:E29) -> 1 | V14: =SUM(F26:F29) -> 0 | W14: =SUM(G26:G29) -> 0 | X14: =SUM(H26:H29) -> 0 | Y14: =SUM(I26:I29) -> 2 | Z14: =SUM(J26:J29) -> 1 | ... AF14: =SUM(P26:P29) -> 45
B15: 08.15 - 08.30 | C15: 0 | D15: 0 | E15: 1 | F15: 0 | G15: 0 | H15: 0 | I15: 1 | J15: 0 | K15: 0 | L15: 0 | M15: 11 | N15: 0 | O15: =SUM(C15:L15,N15) -> 2 | P15: =SUM(C15:N15) -> 13 | R15: 1200-1300 | S15: =SUM(C30:C33) -> 12 | T15: =SUM(D30:D33) -> 2 | U15: =SUM(E30:E33) -> 2 | V15: =SUM(F30:F33) -> 0 | W15: =SUM(G30:G33) -> 0 | X15: =SUM(H30:H33) -> 1 | Y15: =SUM(I30:I33) -> 1 | Z15: =SUM(J30:J33) -> 2 | ... AF15: =SUM(P30:P33) -> 48
B16: 08.30 - 08.45 | C16: 4 | D16: 0 | E16: 0 | F16: 0 | G16: 0 | H16: 0 | I16: 0 | J16: 0 | K16: 0 | L16: 0 | M16: 10 | N16: 0 | O16: =SUM(C16:L16,N16) -> 4 | P16: =SUM(C16:N16) -> 14 | R16: 1300-1400 | S16: =SUM(C34:C37) -> 15 | T16: =SUM(D34:D37) -> 2 | U16: =SUM(E34:E37) -> 0 | V16: =SUM(F34:F37) -> 1 | W16: =SUM(G34:G37) -> 0 | X16: =SUM(H34:H37) -> 0 | Y16: =SUM(I34:I37) -> 3 | Z16: =SUM(J34:J37) -> 0 | ... AF16: =SUM(P34:P37) -> 53
B17: 08.45 - 9.00 | C17: 0 | D17: 0 | E17: 0 | F17: 0 | G17: 0 | H17: 0 | I17: 1 | J17: 0 | K17: 0 | L17: 0 | M17: 5 | N17: 0 | O17: =SUM(C17:L17,N17) -> 1 | P17: =SUM(C17:N17) -> 6 | R17: 1400-1500 | S17: =SUM(C38:C41) -> 25 | T17: =SUM(D38:D41) -> 2 | U17: =SUM(E38:E41) -> 5 | V17: =SUM(F38:F41) -> 0 | W17: =SUM(G38:G41) -> 0 | X17: =SUM(H38:H41) -> 0 | Y17: =SUM(I38:I41) -> 6 | Z17: =SUM(J38:J41) -> 0 | ... AF17: =SUM(P38:P41) -> 54
B18: 09.00 - 09.15 | C18: 1 | D18: 0 | E18: 0 | F18: 0 | G18: 0 | H18: 0 | I18: 0 | J18: 0 | K18: 0 | L18: 0 | M18: 9 | N18: 0 | O18: =SUM(C18:L18,N18) -> 1 | P18: =SUM(C18:N18) -> 10 | R18: 1500-1600 | S18: =SUM(C42:C45) -> 22 | T18: =SUM(D42:D45) -> 3 | U18: =SUM(E42:E45) -> 3 | V18: =SUM(F42:F45) -> 2 | W18: =SUM(G42:G45) -> 0 | X18: =SUM(H42:H45) -> 0 | Y18: =SUM(I42:I45) -> 2 | Z18: =SUM(J42:J45) -> 0 | ... AF18: =SUM(P42:P45) -> 57
B19: 09.15 - 09.30 | C19: 5 | D19: 0 | E19: 0 | F19: 0 | G19: 0 | H19: 0 | I19: 1 | J19: 0 | K19: 0 | L19: 0 | M19: 4 | N19: 0 | O19: =SUM(C19:L19,N19) -> 6 | P19: =SUM(C19:N19) -> 10 | R19: 1600-1700 | S19: =SUM(C46:C49) -> 5 | T19: =SUM(D46:D49) -> 0 | U19: =SUM(E46:E49) -> 0 | V19: =SUM(F46:F49) -> 1 | W19: =SUM(G46:G49) -> 0 | X19: =SUM(H46:H49) -> 0 | Y19: =SUM(I46:I49) -> 5 | Z19: =SUM(J46:J49) -> 0 | ... AF19: =SUM(P46:P49) -> 49
B20: 09.30 - 09.45 | C20: 1 | D20: 1 | E20: 2 | F20: 0 | G20: 1 | H20: 0 | I20: 1 | J20: 0 | K20: 0 | L20: 0 | M20: 5 | N20: 0 | O20: =SUM(C20:L20,N20) -> 6 | P20: =SUM(C20:N20) -> 11 | R20: 1700-1800 | S20: =SUM(C50:C53) -> 17 | T20: =SUM(D50:D53) -> 1 | U20: =SUM(E50:E53) -> 0 | V20: =SUM(F50:F53) -> 0 | W20: =SUM(G50:G53) -> 0 | X20: =SUM(H50:H53) -> 2 | Y20: =SUM(I50:I53) -> 4 | Z20: =SUM(J50:J53) -> 0 | ... AF20: =SUM(P50:P53) -> 66
B21: 09.45 - 10.00 | C21: 2 | D21: 0 | E21: 0 | F21: 0 | G21: 1 | H21: 0 | I21: 0 | J21: 0 | K21: 0 | L21: 0 | M21: 13 | N21: 0 | O21: =SUM(C21:L21,N21) -> 3 | P21: =SUM(C21:N21) -> 16 | R21: 1800-1900 | S21: =SUM(C54:C57) -> 17 | T21: =SUM(D54:D57) -> 1 | U21: =SUM(E54:E57) -> 1 | V21: =SUM(F54:F57) -> 0 | W21: =SUM(G54:G57) -> 0 | X21: =SUM(H54:H57) -> 0 | Y21: =SUM(I54:I57) -> 4 | Z21: =SUM(J54:J57) -> 0 | ... AF21: =SUM(P54:P57) -> 42
B22: 10.00 - 10.15 | C22: 1 | D22: 1 | E22: 0 | F22: 2 | G22: 0 | H22: 0 | I22: 1 | J22: 0 | K22: 0 | L22: 0 | M22: 3 | N22: 0 | O22: =SUM(C22:L22,N22) -> 5 | P22: =SUM(C22:N22) -> 8 | R22: 1900-2000 | S22: =SUM(C58:C61) -> 16 | T22: =SUM(D58:D61) -> 1 | U22: =SUM(E58:E61) -> 2 | V22: =SUM(F58:F61) -> 1 | W22: =SUM(G58:G61) -> 0 | X22: =SUM(H58:H61) -> 0 | Y22: =SUM(I58:I61) -> 1 | Z22: =SUM(J58:J61) -> 0 | ... AF22: =SUM(P58:P61) -> 41
B23: 10.15 - 10.30 | C23: 3 | D23: 0 | E23: 0 | F23: 0 | G23: 0 | H23: 0 | I23: 1 | J23: 0 | K23: 0 | L23: 0 | M23: 3 | N23: 0 | O23: =SUM(C23:L23,N23) -> 4 | P23: =SUM(C23:N23) -> 7 | R23: 2000-2100 | S23: =SUM(C62:C65) -> 10 | T23: =SUM(D62:D65) -> 1 | U23: =SUM(E62:E65) -> 0 | V23: =SUM(F62:F65) -> 1 | W23: =SUM(G62:G65) -> 0 | X23: =SUM(H62:H65) -> 0 | Y23: =SUM(I62:I65) -> 2 | Z23: =SUM(J62:J65) -> 0 | ... AF23: =SUM(P62:P65) -> 29
B24: 10.30 - 10.45 | C24: 3 | D24: 0 | E24: 0 | F24: 0 | G24: 1 | H24: 0 | I24: 0 | J24: 0 | K24: 0 | L24: 0 | M24: 6 | N24: 0 | O24: =SUM(C24:L24,N24) -> 4 | P24: =SUM(C24:N24) -> 10 | R24: 2100-2200 | S24: =SUM(C66:C69) -> 6 | T24: =SUM(D66:D69) -> 0 | U24: =SUM(E66:E69) -> 1 | V24: =SUM(F66:F69) -> 1 | W24: =SUM(G66:G69) -> 0 | X24: =SUM(H66:H69) -> 1 | Y24: =SUM(I66:I69) -> 0 | Z24: =SUM(J66:J69) -> 0 | ... AF24: =SUM(P66:P69) -> 14
B25: 10.45 - 11.00 | C25: 1 | D25: 0 | E25: 1 | F25: 1 | G25: 0 | H25: 0 | I25: 1 | J25: 0 | K25: 0 | L25: 0 | M25: 3 | N25: 0 | O25: =SUM(C25:L25,N25) -> 4 | P25: =SUM(C25:N25) -> 7 | R25: 2200-2300 | S25: =SUM(C70:C73) -> 5 | T25: =SUM(D70:D73) -> 1 | U25: =SUM(E70:E73) -> 0 | V25: =SUM(F70:F73) -> 0 | W25: =SUM(G70:G73) -> 0 | X25: =SUM(H70:H73) -> 0 | Y25: =SUM(I70:I73) -> 0 | Z25: =SUM(J70:J73) -> 0 | ... AF25: =SUM(P70:P73) -> 12
B26: 11.00 - 11.15 | C26: 1 | D26: 0 | E26: 1 | F26: 0 | G26: 0 | H26: 0 | I26: 0 | J26: 0 | K26: 0 | L26: 0 | M26: 6 | N26: 0 | O26: =SUM(C26:L26,N26) -> 2 | P26: =SUM(C26:N26) -> 8 | R26: 2300-0000 | S26: =SUM(C74:C77) -> 2 | T26: =SUM(D74:D77) -> 2 | U26: =SUM(E74:E77) -> 0 | V26: =SUM(F74:F77) -> 0 | W26: =SUM(G74:G77) -> 0 | X26: =SUM(H74:H77) -> 0 | Y26: =SUM(I74:I77) -> 1 | Z26: =SUM(J74:J77) -> 0 | ... AF26: =SUM(P74:P77) -> 11
B27: 11.15 - 11.30 | C27: 2 | D27: 0 | E27: 0 | F27: 0 | G27: 0 | H27: 0 | I27: 0 | J27: 0 | K27: 0 | L27: 0 | M27: 4 | N27: 0 | O27: =SUM(C27:L27,N27) -> 2 | P27: =SUM(C27:N27) -> 6 | R27: 0000-0100 | S27: =SUM(C78:C81) -> 5 | T27: =SUM(D78:D81) -> 1 | U27: =SUM(E78:E81) -> 0 | V27: =SUM(F78:F81) -> 0 | W27: =SUM(G78:G81) -> 0 | X27: =SUM(H78:H81) -> 0 | Y27: =SUM(I78:I81) -> 0 | Z27: =SUM(J78:J81) -> 0 | ... AF27: =SUM(P78:P81) -> 15
B28: 11.30 - 11.45 | C28: 4 | D28: 1 | E28: 0 | F28: 0 | G28: 0 | H28: 0 | I28: 2 | J28: 0 | K28: 0 | L28: 0 | M28: 10 | N28: 0 | O28: =SUM(C28:L28,N28) -> 7 | P28: =SUM(C28:N28) -> 17 | R28: 0100-0200 | S28: =SUM(C82:C85) -> 2 | T28: =SUM(D82:D85) -> 0 | U28: =SUM(E82:E85) -> 1 | V28: =SUM(F82:F85) -> 0 | W28: =SUM(G82:G85) -> 0 | X28: =SUM(H82:H85) -> 0 | Y28: =SUM(I82:I85) -> 1 | Z28: =SUM(J82:J85) -> 0 | ... AF28: =SUM(P82:P85) -> 7
B29: 11.45 - 12.00 | C29: 5 | D29: 1 | E29: 0 | F29: 0 | G29: 0 | H29: 0 | I29: 0 | J29: 1 | K29: 0 | L29: 0 | M29: 7 | N29: 0 | O29: =SUM(C29:L29,N29) -> 7 | P29: =SUM(C29:N29) -> 14 | R29: 0200-0300 | S29: =SUM(C86:C89) -> 1 | T29: =SUM(D86:D89) -> 0 | U29: =SUM(E86:E89) -> 0 | V29: =SUM(F86:F89) -> 0 | W29: =SUM(G86:G89) -> 0 | X29: =SUM(H86:H89) -> 1 | Y29: =SUM(I86:I89) -> 1 | Z29: =SUM(J86:J89) -> 0 | ... AF29: =SUM(P86:P89) -> 3
B30: 12.00 - 12.15 | C30: 1 | D30: 1 | E30: 0 | F30: 0 | G30: 0 | H30: 1 | I30: 0 | J30: 0 | K30: 0 | L30: 0 | M30: 4 | N30: 0 | O30: =SUM(C30:L30,N30) -> 3 | P30: =SUM(C30:N30) -> 7 | R30: 0300-0400 | S30: =SUM(C90:C93) -> 3 | T30: =SUM(D90:D93) -> 0 | U30: =SUM(E90:E93) -> 1 | V30: =SUM(F90:F93) -> 0 | W30: =SUM(G90:G93) -> 0 | X30: =SUM(H90:H93) -> 0 | Y30: =SUM(I90:I93) -> 1 | Z30: =SUM(J90:J93) -> 0 | ... AF30: =SUM(P90:P93) -> 7
B31: 12.15 - 12.30 | C31: 2 | D31: 0 | E31: 1 | F31: 0 | G31: 0 | H31: 0 | I31: 0 | J31: 0 | K31: 0 | L31: 0 | M31: 8 | N31: 0 | O31: =SUM(C31:L31,N31) -> 3 | P31: =SUM(C31:N31) -> 11 | R31: 0400-0500 | S31: =SUM(C94:C97) -> 0 | T31: =SUM(D94:D97) -> 0 | U31: =SUM(E94:E97) -> 0 | V31: =SUM(F94:F97) -> 0 | W31: =SUM(G94:G97) -> 0 | X31: =SUM(H94:H97) -> 0 | Y31: =SUM(I94:I97) -> 2 | Z31: =SUM(J94:J97) -> 0 | ... AF31: =SUM(P94:P97) -> 3
B32: 12.30 - 12.45 | C32: 6 | D32: 1 | E32: 1 | F32: 0 | G32: 0 | H32: 0 | I32: 0 | J32: 2 | K32: 0 | L32: 0 | M32: 11 | N32: 0 | O32: =SUM(C32:L32,N32) -> 10 | P32: =SUM(C32:N32) -> 21 | R32: 0500-0600 | S32: =SUM(C98:C101) -> 2 | T32: =SUM(D98:D101) -> 0 | U32: =SUM(E98:E101) -> 0 | V32: =SUM(F98:F101) -> 0 | W32: =SUM(G98:G101) -> 0 | X32: =SUM(H98:H101) -> 0 | Y32: =SUM(I98:I101) -> 1 | Z32: =SUM(J98:J101) -> 0 | ... AF32: =SUM(P98:P101) -> 3
B33: 12.45 - 13.00 | C33: 3 | D33: 0 | E33: 0 | F33: 0 | G33: 0 | H33: 0 | I33: 1 | J33: 0 | K33: 0 | L33: 0 | M33: 5 | N33: 0 | O33: =SUM(C33:L33,N33) -> 4 | P33: =SUM(C33:N33) -> 9 | R33: 0600-0700 | S33: =SUM(C102:C105) -> 2 | T33: =SUM(D102:D105) -> 0 | U33: =SUM(E102:E105) -> 1 | V33: =SUM(F102:F105) -> 0 | W33: =SUM(G102:G105) -> 0 | X33: =SUM(H102:H105) -> 0 | Y33: =SUM(I102:I105) -> 2 | Z33: =SUM(J102:J105) -> 0 | ... AF33: =SUM(P102:P105) -> 6
B34: 13.00 - 13.15 | C34: 5 | D34: 0 | E34: 0 | F34: 0 | G34: 0 | H34: 0 | I34: 0 | J34: 0 | K34: 0 | L34: 0 | M34: 7 | N34: 0 | O34: =SUM(C34:L34,N34) -> 5 | P34: =SUM(C34:N34) -> 12 | R34: AM Peak Hr | S34: =MAX(S10:S12) -> 13 | T34: =MAX(T10:T12) -> 1 | U34: =MAX(U10:U12) -> 2 | V34: =MAX(V10:V12) -> 0 | W34: =MAX(W10:W12) -> 2 | X34: =MAX(X10:X12) -> 0 | Y34: =MAX(Y10:Y12) -> 2 | Z34: =MAX(Z10:Z12) -> 1 | ... AF34: =MAX(AF10:AF12) -> 47
B35: 13.15 - 13.30 | C35: 6 | D35: 1 | E35: 0 | F35: 0 | G35: 0 | H35: 0 | I35: 1 | J35: 0 | K35: 0 | L35: 0 | M35: 7 | N35: 0 | O35: =SUM(C35:L35,N35) -> 8 | P35: =SUM(C35:N35) -> 15 | R35: IP Peak Hr | S35: =MAX(S13:S18) -> 25 | T35: =MAX(T13:T18) -> 3 | U35: =MAX(U13:U18) -> 5 | V35: =MAX(V13:V18) -> 3 | W35: =MAX(W13:W18) -> 1 | X35: =MAX(X13:X18) -> 1 | Y35: =MAX(Y13:Y18) -> 6 | Z35: =MAX(Z13:Z18) -> 2 | ... AF35: =MAX(AF13:AF18) -> 57
B36: 13.30 - 13.45 | C36: 3 | D36: 0 | E36: 0 | F36: 1 | G36: 0 | H36: 0 | I36: 0 | J36: 0 | K36: 0 | L36: 0 | M36: 12 | N36: 0 | O36: =SUM(C36:L36,N36) -> 4 | P36: =SUM(C36:N36) -> 16 | R36: PM Peak Hr | S36: =MAX(S19:S21) -> 17 | T36: =MAX(T19:T21) -> 1 | U36: =MAX(U19:U21) -> 1 | V36: =MAX(V19:V21) -> 1 | W36: =MAX(W19:W21) -> 0 | X36: =MAX(X19:X21) -> 2 | Y36: =MAX(Y19:Y21) -> 5 | Z36: =MAX(Z19:Z21) -> 0 | ... AF36: =MAX(AF19:AF21) -> 66
B37: 13.45 - 14.00 | C37: 1 | D37: 1 | E37: 0 | F37: 0 | G37: 0 | H37: 0 | I37: 2 | J37: 0 | K37: 0 | L37: 0 | M37: 6 | N37: 0 | O37: =SUM(C37:L37,N37) -> 4 | P37: =SUM(C37:N37) -> 10 | R37: AM Period | S37: =SUM(S10:S12) -> 27 | T37: =SUM(T10:T12) -> 1 | U37: =SUM(U10:U12) -> 4 | V37: =SUM(V10:V12) -> 0 | W37: =SUM(W10:W12) -> 2 | X37: =SUM(X10:X12) -> 0 | Y37: =SUM(Y10:Y12) -> 6 | Z37: =SUM(Z10:Z12) -> 1 | ... AF37: =SUM(AF10:AF12) -> 119
B38: 14.00 - 14.15 | C38: 4 | D38: 0 | E38: 1 | F38: 0 | G38: 0 | H38: 0 | I38: 2 | J38: 0 | K38: 0 | L38: 0 | M38: 6 | N38: 0 | O38: =SUM(C38:L38,N38) -> 7 | P38: =SUM(C38:N38) -> 13 | R38: IP Period | S38: =SUM(S13:S18) -> 94 | T38: =SUM(T13:T18) -> 12 | U38: =SUM(U13:U18) -> 12 | V38: =SUM(V13:V18) -> 6 | W38: =SUM(W13:W18) -> 1 | X38: =SUM(X13:X18) -> 1 | Y38: =SUM(Y13:Y18) -> 17 | Z38: =SUM(Z13:Z18) -> 3 | ... AF38: =SUM(AF13:AF18) -> 289
B39: 14.15 - 14.30 | C39: 8 | D39: 1 | E39: 2 | F39: 0 | G39: 0 | H39: 0 | I39: 0 | J39: 0 | K39: 0 | L39: 0 | M39: 4 | N39: 0 | O39: =SUM(C39:L39,N39) -> 11 | P39: =SUM(C39:N39) -> 15 | R39: PM Period | S39: =SUM(S19:S21) -> 39 | T39: =SUM(T19:T21) -> 2 | U39: =SUM(U19:U21) -> 1 | V39: =SUM(V19:V21) -> 1 | W39: =SUM(W19:W21) -> 0 | X39: =SUM(X19:X21) -> 2 | Y39: =SUM(Y19:Y21) -> 13 | Z39: =SUM(Z19:Z21) -> 0 | ... AF39: =SUM(AF19:AF21) -> 157
B40: 14.30 - 14.45 | C40: 8 | D40: 0 | E40: 0 | F40: 0 | G40: 0 | H40: 0 | I40: 3 | J40: 0 | K40: 0 | L40: 0 | M40: 5 | N40: 0 | O40: =SUM(C40:L40,N40) -> 11 | P40: =SUM(C40:N40) -> 16 | R40: 12 Hours | S40: =SUM(S10:S21) -> 160 | T40: =SUM(T10:T21) -> 15 | U40: =SUM(U10:U21) -> 17 | V40: =SUM(V10:V21) -> 7 | W40: =SUM(W10:W21) -> 3 | X40: =SUM(X10:X21) -> 3 | Y40: =SUM(Y10:Y21) -> 36 | Z40: =SUM(Z10:Z21) -> 4 | ... AF40: =SUM(AF10:AF21) -> 565
B41: 14.45 - 15.00 | C41: 5 | D41: 1 | E41: 2 | F41: 0 | G41: 0 | H41: 0 | I41: 1 | J41: 0 | K41: 0 | L41: 0 | M41: 1 | N41: 0 | O41: =SUM(C41:L41,N41) -> 9 | P41: =SUM(C41:N41) -> 10 | R41: 24 Hrs/ADT | S41: =SUM(S10:S33) -> 214 | T41: =SUM(T10:T33) -> 21 | U41: =SUM(U10:U33) -> 23 | V41: =SUM(V10:V33) -> 10 | W41: =SUM(W10:W33) -> 3 | X41: =SUM(X10:X33) -> 5 | Y41: =SUM(Y10:Y33) -> 48 | Z41: =SUM(Z10:Z33) -> 4 | ... AF41: =SUM(AF10:AF33) -> 716
B42: 15.00 - 15.15 | C42: 5 | D42: 1 | E42: 1 | F42: 1 | G42: 0 | H42: 0 | I42: 0 | J42: 0 | K42: 0 | L42: 0 | M42: 5 | N42: 0 | O42: =SUM(C42:L42,N42) -> 8 | P42: =SUM(C42:N42) -> 13 | R42: NEF | S42: =S41/S40 -> 1.3375 | T42: =T41/T40 -> 1.4 | U42: =U41/U40 -> 1.3529412 | V42: =V41/V40 -> 1.4285714 | W42: =W41/W40 -> 1 | X42: =X41/X40 -> 1.6666667 | Y42: =Y41/Y40 -> 1.3333333 | Z42: =Z41/Z40 -> 1 | ... AF42: =AF41/AF40 -> 1.2672566
...

Sheet 26.10 Katuna-Kabale
B1: Consultancy services for Preparation of Expressway Development Master Plan (EDMP) for Uganda
B2: MANUAL CLASSIFIED COUNT (MCC)
B3: ROAD NAME: | C3: MCC - C1 - STN134 - KATUNA-KABALE ROAD
C5: Date | D5: 26.10.19 | F5: Location | G5: Katuna BP | J5: Surveyor | K5: Florence
C6: Dir. From | D6: Katuna | F6: Dir. To | G6: Kabale | J6: Supervisor | K6: Mbabazi
B8: Time / Veh Type | R8: SUMMARY TRAFFIC VOLUMES
C9: 1. Car | D9: 2. Station Wagon | E9: 3. Pickups | F9: 4. Minibus, matatu | G9: 5. Medium bus | H9: 6. Large Bus | I9: 7. Light Truck | J9: 8. Medium Truck | K9: 9. Heavy truck | L9: 10. Truck Trailer | M9: 11. Motor cycles | N9: 12. Tractors | O9: Total Excl M/Cycles | P9: Total All | R9: Time | S9: 1. Car | T9: 2. Station Wagon | U9: 3. Pickups | V9: 4. Minibus, matatu | W9: 5. Medium bus | X9: 6. Large Bus | Y9: 7. Light Truck | Z9: 8. Medium Truck | AA9: 9. Heavy truck | AB9: 10. Truck Trailer | AC9: 11. Motorcycles | AD9: 12. Tractors, Graders | AE9: Total Excl M/ Cycles | AF9: Total All
B10: 07.00 - 07.15 | C10: 0 | D10: 0 | E10: 0 | F10: 0 | G10: 0 | H10: 0 | I10: 0 | J10: 0 | K10: 0 | L10: 0 | M10: 1 | N10: 0 | O10: =SUM(C10:L10,N10) -> 0 | P10: =SUM(C10:N10) -> 1 | R10: 0700-0800 | S10: =SUM(C10:C13) -> 2 | T10: =SUM(D10:D13) -> 0 | U10: =SUM(E10:E13) -> 0 | V10: =SUM(F10:F13) -> 0 | W10: =SUM(G10:G13) -> 0 | X10: =SUM(H10:H13) -> 0 | Y10: =SUM(I10:I13) -> 0 | Z10: =SUM(J10:J13) -> 0 | ... AF10: =SUM(P10:P13) -> 7
B11: 07.15 - 07.30 | C11: 0 | D11: 0 | E11: 0 | F11: 0 | G11: 0 | H11: 0 | I11: 0 | J11: 0 | K11: 0 | L11: 0 | M11: 1 | N11: 0 | O11: =SUM(C11:L11,N11) -> 0 | P11: =SUM(C11:N11) -> 1 | R11: 0800-0900 | S11: =SUM(C14:C17) -> 9 | T11: =SUM(D14:D17) -> 2 | U11: =SUM(E14:E17) -> 1 | V11: =SUM(F14:F17) -> 1 | W11: =SUM(G14:G17) -> 0 | X11: =SUM(H14:H17) -> 0 | Y11: =SUM(I14:I17) -> 2 | Z11: =SUM(J14:J17) -> 0 | ... AF11: =SUM(P14:P17) -> 25
B12: 07.30 - 07.45 | C12: 1 | D12: 0 | E12: 0 | F12: 0 | G12: 0 | H12: 0 | I12: 0 | J12: 0 | K12: 0 | L12: 0 | M12: 1 | N12: 0 | O12: =SUM(C12:L12,N12) -> 1 | P12: =SUM(C12:N12) -> 2 | R12: 0900-1000 | S12: =SUM(C18:C21) -> 9 | T12: =SUM(D18:D21) -> 0 | U12: =SUM(E18:E21) -> 4 | V12: =SUM(F18:F21) -> 0 | W12: =SUM(G18:G21) -> 0 | X12: =SUM(H18:H21) -> 0 | Y12: =SUM(I18:I21) -> 0 | Z12: =SUM(J18:J21) -> 0 | ... AF12: =SUM(P18:P21) -> 28
B13: 07.45 - 08.00 | C13: 1 | D13: 0 | E13: 0 | F13: 0 | G13: 0 | H13: 0 | I13: 0 | J13: 0 | K13: 0 | L13: 0 | M13: 2 | N13: 0 | O13: =SUM(C13:L13,N13) -> 1 | P13: =SUM(C13:N13) -> 3 | R13: 1000-1100 | S13: =SUM(C22:C25) -> 23 | T13: =SUM(D22:D25) -> 1 | U13: =SUM(E22:E25) -> 0 | V13: =SUM(F22:F25) -> 1 | W13: =SUM(G22:G25) -> 0 | X13: =SUM(H22:H25) -> 0 | Y13: =SUM(I22:I25) -> 7 | Z13: =SUM(J22:J25) -> 0 | ... AF13: =SUM(P22:P25) -> 59
B14: 08.00 - 08.15 | C14: 2 | D14: 0 | E14: 0 | F14: 0 | G14: 0 | H14: 0 | I14: 0 | J14: 0 | K14: 0 | L14: 0 | M14: 0 | N14: 0 | O14: =SUM(C14:L14,N14) -> 2 | P14: =SUM(C14:N14) -> 2 | R14: 1100-1200 | S14: =SUM(C26:C29) -> 23 | T14: =SUM(D26:D29) -> 6 | U14: =SUM(E26:E29) -> 1 | V14: =SUM(F26:F29) -> 1 | W14: =SUM(G26:G29) -> 0 | X14: =SUM(H26:H29) -> 1 | Y14: =SUM(I26:I29) -> 3 | Z14: =SUM(J26:J29) -> 0 | ... AF14: =SUM(P26:P29) -> 52
B15: 08.15 - 08.30 | C15: 1 | D15: 0 | E15: 0 | F15: 0 | G15: 0 | H15: 0 | I15: 0 | J15: 0 | K15: 0 | L15: 0 | M15: 3 | N15: 0 | O15: =SUM(C15:L15,N15) -> 1 | P15: =SUM(C15:N15) -> 4 | R15: 1200-1300 | S15: =SUM(C30:C33) -> 9 | T15: =SUM(D30:D33) -> 1 | U15: =SUM(E30:E33) -> 0 | V15: =SUM(F30:F33) -> 0 | W15: =SUM(G30:G33) -> 0 | X15: =SUM(H30:H33) -> 0 | Y15: =SUM(I30:I33) -> 2 | Z15: =SUM(J30:J33) -> 0 | ... AF15: =SUM(P30:P33) -> 31
B16: 08.30 - 08.45 | C16: 0 | D16: 1 | E16: 0 | F16: 0 | G16: 0 | H16: 0 | I16: 1 | J16: 0 | K16: 0 | L16: 0 | M16: 4 | N16: 0 | O16: =SUM(C16:L16,N16) -> 2 | P16: =SUM(C16:N16) -> 6 | R16: 1300-1400 | S16: =SUM(C34:C37) -> 11 | T16: =SUM(D34:D37) -> 0 | U16: =SUM(E34:E37) -> 1 | V16: =SUM(F34:F37) -> 0 | W16: =SUM(G34:G37) -> 1 | X16: =SUM(H34:H37) -> 0 | Y16: =SUM(I34:I37) -> 1 | Z16: =SUM(J34:J37) -> 0 | ... AF16: =SUM(P34:P37) -> 25
B17: 08.45 - 9.00 | C17: 6 | D17: 1 | E17: 1 | F17: 1 | G17: 0 | H17: 0 | I17: 1 | J17: 0 | K17: 0 | L17: 0 | M17: 3 | N17: 0 | O17: =SUM(C17:L17,N17) -> 10 | P17: =SUM(C17:N17) -> 13 | R17: 1400-1500 | S17: =SUM(C38:C41) -> 6 | T17: =SUM(D38:D41) -> 0 | U17: =SUM(E38:E41) -> 1 | V17: =SUM(F38:F41) -> 0 | W17: =SUM(G38:G41) -> 0 | X17: =SUM(H38:H41) -> 0 | Y17: =SUM(I38:I41) -> 1 | Z17: =SUM(J38:J41) -> 1 | ... AF17: =SUM(P38:P41) -> 25
B18: 09.00 - 09.15 | C18: 3 | D18: 0 | E18: 1 | F18: 0 | G18: 0 | H18: 0 | I18: 0 | J18: 0 | K18: 0 | L18: 0 | M18: 3 | N18: 0 | O18: =SUM(C18:L18,N18) -> 4 | P18: =SUM(C18:N18) -> 7 | R18: 1500-1600 | S18: =SUM(C42:C45) -> 11 | T18: =SUM(D42:D45) -> 0 | U18: =SUM(E42:E45) -> 0 | V18: =SUM(F42:F45) -> 0 | W18: =SUM(G42:G45) -> 0 | X18: =SUM(H42:H45) -> 1 | Y18: =SUM(I42:I45) -> 5 | Z18: =SUM(J42:J45) -> 0 | ... AF18: =SUM(P42:P45) -> 29
B19: 09.15 - 09.30 | C19: 3 | D19: 0 | E19: 1 | F19: 0 | G19: 0 | H19: 0 | I19: 0 | J19: 0 | K19: 0 | L19: 0 | M19: 6 | N19: 0 | O19: =SUM(C19:L19,N19) -> 4 | P19: =SUM(C19:N19) -> 10 | R19: 1600-1700 | S19: =SUM(C46:C49) -> 7 | T19: =SUM(D46:D49) -> 1 | U19: =SUM(E46:E49) -> 1 | V19: =SUM(F46:F49) -> 0 | W19: =SUM(G46:G49) -> 0 | X19: =SUM(H46:H49) -> 1 | Y19: =SUM(I46:I49) -> 0 | Z19: =SUM(J46:J49) -> 0 | ... AF19: =SUM(P46:P49) -> 28
B20: 09.30 - 09.45 | C20: 0 | D20: 0 | E20: 0 | F20: 0 | G20: 0 | H20: 0 | I20: 0 | J20: 0 | K20: 0 | L20: 0 | M20: 3 | N20: 0 | O20: =SUM(C20:L20,N20) -> 0 | P20: =SUM(C20:N20) -> 3 | R20: 1700-1800 | S20: =SUM(C50:C53) -> 10 | T20: =SUM(D50:D53) -> 1 | U20: =SUM(E50:E53) -> 0 | V20: =SUM(F50:F53) -> 0 | W20: =SUM(G50:G53) -> 0 | X20: =SUM(H50:H53) -> 0 | Y20: =SUM(I50:I53) -> 2 | Z20: =SUM(J50:J53) -> 0 | ... AF20: =SUM(P50:P53) -> 41
B21: 09.45 - 10.00 | C21: 3 | D21: 0 | E21: 2 | F21: 0 | G21: 0 | H21: 0 | I21: 0 | J21: 0 | K21: 0 | L21: 0 | M21: 3 | N21: 0 | O21: =SUM(C21:L21,N21) -> 5 | P21: =SUM(C21:N21) -> 8 | R21: 1800-1900 | S21: =SUM(C54:C57) -> 15 | T21: =SUM(D54:D57) -> 3 | U21: =SUM(E54:E57) -> 0 | V21: =SUM(F54:F57) -> 1 | W21: =SUM(G54:G57) -> 0 | X21: =SUM(H54:H57) -> 0 | Y21: =SUM(I54:I57) -> 2 | Z21: =SUM(J54:J57) -> 0 | ... AF21: =SUM(P54:P57) -> 48
B22: 10.00 - 10.15 | C22: 4 | D22: 0 | E22: 0 | F22: 1 | G22: 0 | H22: 0 | I22: 2 | J22: 0 | K22: 0 | L22: 0 | M22: 5 | N22: 0 | O22: =SUM(C22:L22,N22) -> 7 | P22: =SUM(C22:N22) -> 12 | R22: AM Peak Hr | S22: =MAX(S10:S12) -> 9 | T22: =MAX(T10:T12) -> 2 | U22: =MAX(U10:U12) -> 4 | V22: =MAX(V10:V12) -> 1 | W22: =MAX(W10:W12) -> 0 | X22: =MAX(X10:X12) -> 0 | Y22: =MAX(Y10:Y12) -> 2 | Z22: =MAX(Z10:Z12) -> 0 | ... AF22: =MAX(AF10:AF12) -> 28
B23: 10.15 - 10.30 | C23: 7 | D23: 0 | E23: 0 | F23: 0 | G23: 0 | H23: 0 | I23: 1 | J23: 0 | K23: 0 | L23: 0 | M23: 13 | N23: 0 | O23: =SUM(C23:L23,N23) -> 8 | P23: =SUM(C23:N23) -> 21 | R23: IP Peak Hr | S23: =MAX(S13:S18) -> 23 | T23: =MAX(T13:T18) -> 6 | U23: =MAX(U13:U18) -> 1 | V23: =MAX(V13:V18) -> 1 | W23: =MAX(W13:W18) -> 1 | X23: =MAX(X13:X18) -> 1 | Y23: =MAX(Y13:Y18) -> 7 | Z23: =MAX(Z13:Z18) -> 1 | ... AF23: =MAX(AF13:AF18) -> 59
B24: 10.30 - 10.45 | C24: 4 | D24: 1 | E24: 0 | F24: 0 | G24: 0 | H24: 0 | I24: 2 | J24: 0 | K24: 0 | L24: 0 | M24: 3 | N24: 0 | O24: =SUM(C24:L24,N24) -> 7 | P24: =SUM(C24:N24) -> 10 | R24: PM Peak Hr | S24: =MAX(S19:S21) -> 15 | T24: =MAX(T19:T21) -> 3 | U24: =MAX(U19:U21) -> 1 | V24: =MAX(V19:V21) -> 1 | W24: =MAX(W19:W21) -> 0 | X24: =MAX(X19:X21) -> 1 | Y24: =MAX(Y19:Y21) -> 2 | Z24: =MAX(Z19:Z21) -> 0 | ... AF24: =MAX(AF19:AF21) -> 48
B25: 10.45 - 11.00 | C25: 8 | D25: 0 | E25: 0 | F25: 0 | G25: 0 | H25: 0 | I25: 2 | J25: 0 | K25: 0 | L25: 0 | M25: 6 | N25: 0 | O25: =SUM(C25:L25,N25) -> 10 | P25: =SUM(C25:N25) -> 16 | R25: AM Period | S25: =SUM(S10:S12) -> 20 | T25: =SUM(T10:T12) -> 2 | U25: =SUM(U10:U12) -> 5 | V25: =SUM(V10:V12) -> 1 | W25: =SUM(W10:W12) -> 0 | X25: =SUM(X10:X12) -> 0 | Y25: =SUM(Y10:Y12) -> 2 | Z25: =SUM(Z10:Z12) -> 0 | ... AF25: =SUM(AF10:AF12) -> 60
B26: 11.00 - 11.15 | C26: 1 | D26: 1 | E26: 1 | F26: 0 | G26: 0 | H26: 1 | I26: 0 | J26: 0 | K26: 0 | L26: 0 | M26: 5 | N26: 0 | O26: =SUM(C26:L26,N26) -> 4 | P26: =SUM(C26:N26) -> 9 | R26: IP Period | S26: =SUM(S13:S18) -> 83 | T26: =SUM(T13:T18) -> 8 | U26: =SUM(U13:U18) -> 3 | V26: =SUM(V13:V18) -> 2 | W26: =SUM(W13:W18) -> 1 | X26: =SUM(X13:X18) -> 2 | Y26: =SUM(Y13:Y18) -> 19 | Z26: =SUM(Z13:Z18) -> 1 | ... AF26: =SUM(AF13:AF18) -> 221
B27: 11.15 - 11.30 | C27: 6 | D27: 3 | E27: 0 | F27: 0 | G27: 0 | H27: 0 | I27: 0 | J27: 0 | K27: 0 | L27: 0 | M27: 2 | N27: 0 | O27: =SUM(C27:L27,N27) -> 9 | P27: =SUM(C27:N27) -> 11 | R27: PM Period | S27: =SUM(S19:S21) -> 32 | T27: =SUM(T19:T21) -> 5 | U27: =SUM(U19:U21) -> 1 | V27: =SUM(V19:V21) -> 1 | W27: =SUM(W19:W21) -> 0 | X27: =SUM(X19:X21) -> 1 | Y27: =SUM(Y19:Y21) -> 4 | Z27: =SUM(Z19:Z21) -> 0 | ... AF27: =SUM(AF19:AF21) -> 117
B28: 11.30 - 11.45 | C28: 9 | D28: 1 | E28: 0 | F28: 1 | G28: 0 | H28: 0 | I28: 1 | J28: 0 | K28: 0 | L28: 0 | M28: 6 | N28: 0 | O28: =SUM(C28:L28,N28) -> 12 | P28: =SUM(C28:N28) -> 18 | R28: 12 Hours | S28: =SUM(S10:S21) -> 135 | T28: =SUM(T10:T21) -> 15 | U28: =SUM(U10:U21) -> 9 | V28: =SUM(V10:V21) -> 4 | W28: =SUM(W10:W21) -> 1 | X28: =SUM(X10:X21) -> 3 | Y28: =SUM(Y10:Y21) -> 25 | Z28: =SUM(Z10:Z21) -> 1 | ... AF28: =SUM(AF10:AF21) -> 398
B29: 11.45 - 12.00 | C29: 7 | D29: 1 | E29: 0 | F29: 0 | G29: 0 | H29: 0 | I29: 2 | J29: 0 | K29: 0 | L29: 0 | M29: 4 | N29: 0 | O29: =SUM(C29:L29,N29) -> 10 | P29: =SUM(C29:N29) -> 14
B30: 12.00 - 12.15 | C30: 4 | D30: 1 | E30: 0 | F30: 0 | G30: 0 | H30: 0 | I30: 1 | J30: 0 | K30: 0 | L30: 0 | M30: 5 | N30: 0 | O30: =SUM(C30:L30,N30) -> 6 | P30: =SUM(C30:N30) -> 11
B31: 12.15 - 12.30 | C31: 2 | D31: 0 | E31: 0 | F31: 0 | G31: 0 | H31: 0 | I31: 0 | J31: 0 | K31: 0 | L31: 0 | M31: 6 | N31: 0 | O31: =SUM(C31:L31,N31) -> 2 | P31: =SUM(C31:N31) -> 8
B32: 12.30 - 12.45 | C32: 2 | D32: 0 | E32: 0 | F32: 0 | G32: 0 | H32: 0 | I32: 1 | J32: 0 | K32: 0 | L32: 0 | M32: 1 | N32: 0 | O32: =SUM(C32:L32,N32) -> 3 | P32: =SUM(C32:N32) -> 4
B33: 12.45 - 13.00 | C33: 1 | D33: 0 | E33: 0 | F33: 0 | G33: 0 | H33: 0 | I33: 0 | J33: 0 | K33: 0 | L33: 0 | M33: 7 | N33: 0 | O33: =SUM(C33:L33,N33) -> 1 | P33: =SUM(C33:N33) -> 8
B34: 13.00 - 13.15 | C34: 2 | D34: 0 | E34: 0 | F34: 0 | G34: 0 | H34: 0 | I34: 0 | J34: 0 | K34: 0 | L34: 0 | M34: 3 | N34: 0 | O34: =SUM(C34:L34,N34) -> 2 | P34: =SUM(C34:N34) -> 5
B35: 13.15 - 13.30 | C35: 3 | D35: 0 | E35: 1 | F35: 0 | G35: 0 | H35: 0 | I35: 0 | J35: 0 | K35: 0 | L35: 0 | M35: 4 | N35: 0 | O35: =SUM(C35:L35,N35) -> 4 | P35: =SUM(C35:N35) -> 8
B36: 13.30 - 13.45 | C36: 4 | D36: 0 | E36: 0 | F36: 0 | G36: 1 | H36: 0 | I36: 0 | J36: 0 | K36: 0 | L36: 0 | M36: 2 | N36: 0 | O36: =SUM(C36:L36,N36) -> 5 | P36: =SUM(C36:N36) -> 7
B37: 13.45 - 14.00 | C37: 2 | D37: 0 | E37: 0 | F37: 0 | G37: 0 | H37: 0 | I37: 1 | J37: 0 | K37: 0 | L37: 0 | M37: 2 | N37: 0 | O37: =SUM(C37:L37,N37) -> 3 | P37: =SUM(C37:N37) -> 5
B38: 14.00 - 14.15 | C38: 1 | D38: 0 | E38: 1 | F38: 0 | G38: 0 | H38: 0 | I38: 1 | J38: 1 | K38: 0 | L38: 0 | M38: 6 | N38: 0 | O38: =SUM(C38:L38,N38) -> 4 | P38: =SUM(C38:N38) -> 10
B39: 14.15 - 14.30 | C39: 1 | D39: 0 | E39: 0 | F39: 0 | G39: 0 | H39: 0 | I39: 0 | J39: 0 | K39: 0 | L39: 0 | M39: 0 | N39: 0 | O39: =SUM(C39:L39,N39) -> 1 | P39: =SUM(C39:N39) -> 1
B40: 14.30 - 14.45 | C40: 2 | D40: 0 | E40: 0 | F40: 0 | G40: 0 | H40: 0 | I40: 0 | J40: 0 | K40: 0 | L40: 0 | M40: 7 | N40: 0 | O40: =SUM(C40:L40,N40) -> 2 | P40: =SUM(C40:N40) -> 9
... B57: 18.45 - 19.00 | C57: 3 | D57: 1 | E57: 0 | F57: 0 | G57: 0 | H57: 0 | I57: 1 | J57: 0 | K57: 0 | L57: 0 | M57: 5 | N57: 0 | O57: =SUM(C57:L57,N57) -> 5 | P57: =SUM(C57:N57) -> 10
B58: Totals | C58: =SUM(C10:C57) -> 135 | D58: =SUM(D10:D57) -> 15 | E58: =SUM(E10:E57) -> 9 | F58: =SUM(F10:F57) -> 4 | G58: =SUM(G10:G57) -> 1 | H58: =SUM(H10:H57) -> 3 | I58: =SUM(I10:I57) -> 25 | J58: =SUM(J10:J57) -> 1 | ... P58: =SUM(P10:P57) -> 398
...

Sheet 26.10  Kabale-Katuna
B1: Consultancy services for Preparation of Expressway Development Master Plan (EDMP) for Uganda
B2: MANUAL CLASSIFIED COUNT (MCC)
B3: ROAD NAME: | C3: ='26.10 Katuna-Kabale'!C3:G3 -> MCC - C1 - STN134 - KATUNA-KABALE ROAD
C5: Date | D5: ='26.10 Katuna-Kabale'!D5 -> 26.10.19 | F5: Location | G5: ='26.10 Katuna-Kabale'!G5:H5 -> Katuna BP | J5: Surveyor | K5: Kato Joseph
C6: Dir. From | D6: Kabale | F6: Dir. To | G6: Katuna | J6: Supervisor | K6: ='26.10 Katuna-Kabale'!K6:L6 -> Mbabazi
B8: Time / Veh Type | R8: SUMMARY TRAFFIC VOLUMES
C9: 1. Car | D9: 2. Station Wagon | E9: 3. Pickups | F9: 4. Minibus, matatu | G9: 5. Medium bus | H9: 6. Large Bus | I9: 7. Light Truck | J9: 8. Medium Truck | K9: 9. Heavy truck | L9: 10. Truck Trailer | M9: 11. Motor cycles | N9: 12. Tractors | O9: Total Excl M/Cycles | P9: Total All | R9: Time | S9: 1. Car | T9: 2. Station Wagon | U9: 3. Pickups | V9: 4. Minibus, matatu | W9: 5. Medium bus | X9: 6. Large Bus | Y9: 7. Light Truck | Z9: 8. Medium Truck | AA9: 9. Heavy truck | AB9: 10. Truck Trailer | AC9: 11. Motorcycles | AD9: 12. Tractors, Graders | AE9: Total Excl M/ Cycles | AF9: Total All
B10: 07.00 - 07.15 | C10: 0 | D10: 0 | E10: 1 | F10: 0 | G10: 1 | H10: 0 | I10: 0 | J10: 0 | K10: 0 | L10: 0 | M10: 1 | N10: 0 | O10: =SUM(C10:L10,N10) -> 2 | P10: =SUM(C10:N10) -> 3 | R10: 0700-0800 | S10: =SUM(C10:C13) -> 6 | T10: =SUM(D10:D13) -> 1 | U10: =SUM(E10:E13) -> 1 | V10: =SUM(F10:F13) -> 3 | W10: =SUM(G10:G13) -> 1 | X10: =SUM(H10:H13) -> 0 | Y10: =SUM(I10:I13) -> 1 | Z10: =SUM(J10:J13) -> 0 | ... AF10: =SUM(P10:P13) -> 21
B11: 07.15 - 07.30 | C11: 2 | D11: 1 | E11: 0 | F11: 0 | G11: 0 | H11: 0 | I11: 1 | J11: 0 | K11: 0 | L11: 0 | M11: 1 | N11: 0 | O11: =SUM(C11:L11,N11) -> 4 | P11: =SUM(C11:N11) -> 5 | R11: 0800-0900 | S11: =SUM(C14:C17) -> 8 | T11: =SUM(D14:D17) -> 0 | U11: =SUM(E14:E17) -> 1 | V11: =SUM(F14:F17) -> 0 | W11: =SUM(G14:G17) -> 0 | X11: =SUM(H14:H17) -> 1 | Y11: =SUM(I14:I17) -> 0 | Z11: =SUM(J14:J17) -> 0 | ... AF11: =SUM(P14:P17) -> 27
B12: 07.30 - 07.45 | C12: 2 | D12: 0 | E12: 0 | F12: 3 | G12: 0 | H12: 0 | I12: 0 | J12: 0 | K12: 0 | L12: 0 | M12: 6 | N12: 0 | O12: =SUM(C12:L12,N12) -> 5 | P12: =SUM(C12:N12) -> 11 | R12: 0900-1000 | S12: =SUM(C18:C21) -> 13 | T12: =SUM(D18:D21) -> 0 | U12: =SUM(E18:E21) -> 1 | V12: =SUM(F18:F21) -> 0 | W12: =SUM(G18:G21) -> 1 | X12: =SUM(H18:H21) -> 0 | Y12: =SUM(I18:I21) -> 5 | Z12: =SUM(J18:J21) -> 0 | ... AF12: =SUM(P18:P21) -> 52
B13: 07.45 - 08.00 | C13: 2 | D13: 0 | E13: 0 | F13: 0 | G13: 0 | H13: 0 | I13: 0 | J13: 0 | K13: 0 | L13: 0 | M13: 0 | N13: 0 | O13: =SUM(C13:L13,N13) -> 2 | P13: =SUM(C13:N13) -> 2 | R13: 1000-1100 | S13: =SUM(C22:C25) -> 13 | T13: =SUM(D22:D25) -> 3 | U13: =SUM(E22:E25) -> 2 | V13: =SUM(F22:F25) -> 0 | W13: =SUM(G22:G25) -> 0 | X13: =SUM(H22:H25) -> 0 | Y13: =SUM(I22:I25) -> 2 | Z13: =SUM(J22:J25) -> 0 | ... AF13: =SUM(P22:P25) -> 56
B14: 08.00 - 08.15 | C14: 1 | D14: 0 | E14: 0 | F14: 0 | G14: 0 | H14: 0 | I14: 0 | J14: 0 | K14: 0 | L14: 0 | M14: 1 | N14: 0 | O14: =SUM(C14:L14,N14) -> 1 | P14: =SUM(C14:N14) -> 2 | R14: 1100-1200 | S14: =SUM(C26:C29) -> 11 | T14: =SUM(D26:D29) -> 4 | U14: =SUM(E26:E29) -> 1 | V14: =SUM(F26:F29) -> 2 | W14: =SUM(G26:G29) -> 0 | X14: =SUM(H26:H29) -> 1 | Y14: =SUM(I26:I29) -> 0 | Z14: =SUM(J26:J29) -> 0 | ... AF14: =SUM(P26:P29) -> 36
B15: 08.15 - 08.30 | C15: 1 | D15: 0 | E15: 0 | F15: 0 | G15: 0 | H15: 0 | I15: 0 | J15: 0 | K15: 0 | L15: 0 | M15: 5 | N15: 0 | O15: =SUM(C15:L15,N15) -> 1 | P15: =SUM(C15:N15) -> 6 | R15: 1200-1300 | S15: =SUM(C30:C33) -> 13 | T15: =SUM(D30:D33) -> 1 | U15: =SUM(E30:E33) -> 0 | V15: =SUM(F30:F33) -> 0 | W15: =SUM(G30:G33) -> 0 | X15: =SUM(H30:H33) -> 1 | Y15: =SUM(I30:I33) -> 2 | Z15: =SUM(J30:J33) -> 0 | ... AF15: =SUM(P30:P33) -> 30
B16: 08.30 - 08.45 | C16: 3 | D16: 0 | E16: 1 | F16: 0 | G16: 0 | H16: 1 | I16: 0 | J16: 0 | K16: 0 | L16: 0 | M16: 7 | N16: 0 | O16: =SUM(C16:L16,N16) -> 5 | P16: =SUM(C16:N16) -> 12 | R16: 1300-1400 | S16: =SUM(C34:C37) -> 7 | T16: =SUM(D34:D37) -> 2 | U16: =SUM(E34:E37) -> 3 | V16: =SUM(F34:F37) -> 0 | W16: =SUM(G34:G37) -> 0 | X16: =SUM(H34:H37) -> 0 | Y16: =SUM(I34:I37) -> 2 | Z16: =SUM(J34:J37) -> 0 | ... AF16: =SUM(P34:P37) -> 37
B17: 08.45 - 9.00 | C17: 3 | D17: 0 | E17: 0 | F17: 0 | G17: 0 | H17: 0 | I17: 0 | J17: 0 | K17: 0 | L17: 0 | M17: 4 | N17: 0 | O17: =SUM(C17:L17,N17) -> 3 | P17: =SUM(C17:N17) -> 7 | R17: 1400-1500 | S17: =SUM(C38:C41) -> 13 | T17: =SUM(D38:D41) -> 0 | U17: =SUM(E38:E41) -> 0 | V17: =SUM(F38:F41) -> 2 | W17: =SUM(G38:G41) -> 0 | X17: =SUM(H38:H41) -> 0 | Y17: =SUM(I38:I41) -> 2 | Z17: =SUM(J38:J41) -> 0 | ... AF17: =SUM(P38:P41) -> 34
B18: 09.00 - 09.15 | C18: 3 | D18: 0 | E18: 0 | F18: 0 | G18: 0 | H18: 0 | I18: 1 | J18: 0 | K18: 0 | L18: 0 | M18: 4 | N18: 0 | O18: =SUM(C18:L18,N18) -> 4 | P18: =SUM(C18:N18) -> 8 | R18: 1500-1600 | S18: =SUM(C42:C45) -> 3 | T18: =SUM(D42:D45) -> 1 | U18: =SUM(E42:E45) -> 1 | V18: =SUM(F42:F45) -> 3 | W18: =SUM(G42:G45) -> 0 | X18: =SUM(H42:H45) -> 0 | Y18: =SUM(I42:I45) -> 1 | Z18: =SUM(J42:J45) -> 0 | ... AF18: =SUM(P42:P45) -> 25
B19: 09.15 - 09.30 | C19: 2 | D19: 0 | E19: 0 | F19: 0 | G19: 1 | H19: 0 | I19: 0 | J19: 0 | K19: 0 | L19: 0 | M19: 10 | N19: 0 | O19: =SUM(C19:L19,N19) -> 3 | P19: =SUM(C19:N19) -> 13 | R19: 1600-1700 | S19: =SUM(C46:C49) -> 12 | T19: =SUM(D46:D49) -> 2 | U19: =SUM(E46:E49) -> 0 | V19: =SUM(F46:F49) -> 2 | W19: =SUM(G46:G49) -> 0 | X19: =SUM(H46:H49) -> 2 | Y19: =SUM(I46:I49) -> 2 | Z19: =SUM(J46:J49) -> 0 | ... AF19: =SUM(P46:P49) -> 40
B20: 09.30 - 09.45 | C20: 3 | D20: 0 | E20: 0 | F20: 0 | G20: 0 | H20: 0 | I20: 2 | J20: 0 | K20: 0 | L20: 0 | M20: 8 | N20: 0 | O20: =SUM(C20:L20,N20) -> 5 | P20: =SUM(C20:N20) -> 13 | R20: 1700-1800 | S20: =SUM(C50:C53) -> 10 | T20: =SUM(D50:D53) -> 0 | U20: =SUM(E50:E53) -> 0 | V20: =SUM(F50:F53) -> 0 | W20: =SUM(G50:G53) -> 0 | X20: =SUM(H50:H53) -> 0 | Y20: =SUM(I50:I53) -> 6 | Z20: =SUM(J50:J53) -> 0 | ... AF20: =SUM(P50:P53) -> 43
B21: 09.45 - 10.00 | C21: 5 | D21: 0 | E21: 1 | F21: 0 | G21: 0 | H21: 0 | I21: 2 | J21: 0 | K21: 0 | L21: 0 | M21: 10 | N21: 0 | O21: =SUM(C21:L21,N21) -> 8 | P21: =SUM(C21:N21) -> 18 | R21: 1800-1900 | S21: =SUM(C54:C57) -> 17 | T21: =SUM(D54:D57) -> 0 | U21: =SUM(E54:E57) -> 0 | V21: =SUM(F54:F57) -> 0 | W21: =SUM(G54:G57) -> 0 | X21: =SUM(H54:H57) -> 0 | Y21: =SUM(I54:I57) -> 0 | Z21: =SUM(J54:J57) -> 0 | ... AF21: =SUM(P54:P57) -> 42
B22: 10.00 - 10.15 | C22: 5 | D22: 1 | E22: 1 | F22: 0 | G22: 0 | H22: 0 | I22: 0 | J22: 0 | K22: 0 | L22: 0 | M22: 13 | N22: 0 | O22: =SUM(C22:L22,N22) -> 7 | P22: =SUM(C22:N22) -> 20 | R22: AM Peak Hr | S22: =MAX(S10:S12) -> 13 | T22: =MAX(T10:T12) -> 1 | U22: =MAX(U10:U12) -> 1 | V22: =MAX(V10:V12) -> 3 | W22: =MAX(W10:W12) -> 1 | X22: =MAX(X10:X12) -> 1 | Y22: =MAX(Y10:Y12) -> 5 | Z22: =MAX(Z10:Z12) -> 0 | ... AF22: =MAX(AF10:AF12) -> 52
B23: 10.15 - 10.30 | C23: 3 | D23: 0 | E23: 1 | F23: 0 | G23: 0 | H23: 0 | I23: 1 | J23: 0 | K23: 0 | L23: 0 | M23: 6 | N23: 0 | O23: =SUM(C23:L23,N23) -> 5 | P23: =SUM(C23:N23) -> 11 | R23: IP Peak Hr | S23: =MAX(S13:S18) -> 13 | T23: =MAX(T13:T18) -> 4 | U23: =MAX(U13:U18) -> 3 | V23: =MAX(V13:V18) -> 3 | W23: =MAX(W13:W18) -> 0 | X23: =MAX(X13:X18) -> 1 | Y23: =MAX(Y13:Y18) -> 2 | Z23: =MAX(Z13:Z18) -> 0 | ... AF23: =MAX(AF13:AF18) -> 56
B24: 10.30 - 10.45 | C24: 4 | D24: 1 | E24: 0 | F24: 0 | G24: 0 | H24: 0 | I24: 1 | J24: 0 | K24: 0 | L24: 0 | M24: 9 | N24: 0 | O24: =SUM(C24:L24,N24) -> 6 | P24: =SUM(C24:N24) -> 15 | R24: PM Peak Hr | S24: =MAX(S19:S21) -> 17 | T24: =MAX(T19:T21) -> 2 | U24: =MAX(U19:U21) -> 0 | V24: =MAX(V19:V21) -> 2 | W24: =MAX(W19:W21) -> 0 | X24: =MAX(X19:X21) -> 2 | Y24: =MAX(Y19:Y21) -> 6 | Z24: =MAX(Z19:Z21) -> 0 | ... AF24: =MAX(AF19:AF21) -> 43
B25: 10.45 - 11.00 | C25: 1 | D25: 1 | E25: 0 | F25: 0 | G25: 0 | H25: 0 | I25: 0 | J25: 0 | K25: 0 | L25: 0 | M25: 8 | N25: 0 | O25: =SUM(C25:L25,N25) -> 2 | P25: =SUM(C25:N25) -> 10 | R25: AM Period | S25: =SUM(S10:S12) -> 27 | T25: =SUM(T10:T12) -> 1 | U25: =SUM(U10:U12) -> 3 | V25: =SUM(V10:V12) -> 3 | W25: =SUM(W10:W12) -> 2 | X25: =SUM(X10:X12) -> 1 | Y25: =SUM(Y10:Y12) -> 6 | Z25: =SUM(Z10:Z12) -> 0 | ... AF25: =SUM(AF10:AF12) -> 100
B26: 11.00 - 11.15 | C26: 3 | D26: 1 | E26: 0 | F26: 0 | G26: 0 | H26: 1 | I26: 0 | J26: 0 | K26: 0 | L26: 0 | M26: 4 | N26: 0 | O26: =SUM(C26:L26,N26) -> 5 | P26: =SUM(C26:N26) -> 9 | R26: IP Period | S26: =SUM(S13:S18) -> 60 | T26: =SUM(T13:T18) -> 11 | U26: =SUM(U13:U18) -> 7 | V26: =SUM(V13:V18) -> 7 | W26: =SUM(W13:W18) -> 0 | X26: =SUM(X13:X18) -> 2 | Y26: =SUM(Y13:Y18) -> 9 | Z26: =SUM(Z13:Z18) -> 0 | ... AF26: =SUM(AF13:AF18) -> 218
B27: 11.15 - 11.30 | C27: 2 | D27: 0 | E27: 0 | F27: 1 | G27: 0 | H27: 0 | I27: 0 | J27: 0 | K27: 0 | L27: 0 | M27: 7 | N27: 0 | O27: =SUM(C27:L27,N27) -> 3 | P27: =SUM(C27:N27) -> 10 | R27: PM Period | S27: =SUM(S19:S21) -> 39 | T27: =SUM(T19:T21) -> 2 | U27: =SUM(U19:U21) -> 0 | V27: =SUM(V19:V21) -> 2 | W27: =SUM(W19:W21) -> 0 | X27: =SUM(X19:X21) -> 2 | Y27: =SUM(Y19:Y21) -> 8 | Z27: =SUM(Z19:Z21) -> 0 | ... AF27: =SUM(AF19:AF21) -> 125
B28: 11.30 - 11.45 | C28: 2 | D28: 3 | E28: 1 | F28: 1 | G28: 0 | H28: 0 | I28: 0 | J28: 0 | K28: 0 | L28: 0 | M28: 4 | N28: 0 | O28: =SUM(C28:L28,N28) -> 7 | P28: =SUM(C28:N28) -> 11 | R28: 12 Hours | S28: =SUM(S10:S21) -> 126 | T28: =SUM(T10:T21) -> 14 | U28: =SUM(U10:U21) -> 10 | V28: =SUM(V10:V21) -> 12 | W28: =SUM(W10:W21) -> 2 | X28: =SUM(X10:X21) -> 5 | Y28: =SUM(Y10:Y21) -> 23 | Z28: =SUM(Z10:Z21) -> 0 | ... AF28: =SUM(AF10:AF21) -> 443
B29: 11.45 - 12.00 | C29: 4 | D29: 0 | E29: 0 | F29: 0 | G29: 0 | H29: 0 | I29: 0 | J29: 0 | K29: 0 | L29: 0 | M29: 2 | N29: 0 | O29: =SUM(C29:L29,N29) -> 4 | P29: =SUM(C29:N29) -> 6
B30: 12.00 - 12.15 | C30: 5 | D30: 0 | E30: 0 | F30: 0 | G30: 0 | H30: 0 | I30: 1 | J30: 0 | K30: 0 | L30: 0 | M30: 2 | N30: 0 | O30: =SUM(C30:L30,N30) -> 6 | P30: =SUM(C30:N30) -> 8
B31: 12.15 - 12.30 | C31: 3 | D31: 0 | E31: 0 | F31: 0 | G31: 0 | H31: 0 | I31: 0 | J31: 0 | K31: 0 | L31: 0 | M31: 7 | N31: 0 | O31: =SUM(C31:L31,N31) -> 3 | P31: =SUM(C31:N31) -> 10
B32: 12.30 - 12.45 | C32: 3 | D32: 1 | E32: 0 | F32: 0 | G32: 0 | H32: 0 | I32: 1 | J32: 0 | K32: 0 | L32: 0 | M32: 1 | N32: 0 | O32: =SUM(C32:L32,N32) -> 5 | P32: =SUM(C32:N32) -> 6
B33: 12.45 - 13.00 | C33: 2 | D33: 0 | E33: 0 | F33: 0 | G33: 0 | H33: 1 | I33: 0 | J33: 0 | K33: 0 | L33: 0 | M33: 3 | N33: 0 | O33: =SUM(C33:L33,N33) -> 3 | P33: =SUM(C33:N33) -> 6
B34: 13.00 - 13.15 | C34: 0 | D34: 1 | E34: 0 | F34: 0 | G34: 0 | H34: 0 | I34: 0 | J34: 0 | K34: 0 | L34: 0 | M34: 7 | N34: 0 | O34: =SUM(C34:L34,N34) -> 1 | P34: =SUM(C34:N34) -> 8
B35: 13.15 - 13.30 | C35: 3 | D35: 1 | E35: 0 | F35: 0 | G35: 0 | H35: 0 | I35: 1 | J35: 0 | K35: 0 | L35: 0 | M35: 6 | N35: 0 | O35: =SUM(C35:L35,N35) -> 5 | P35: =SUM(C35:N35) -> 11
B36: 13.30 - 13.45 | C36: 4 | D36: 0 | E36: 1 | F36: 0 | G36: 0 | H36: 0 | I36: 1 | J36: 0 | K36: 0 | L36: 0 | M36: 8 | N36: 0 | O36: =SUM(C36:L36,N36) -> 6 | P36: =SUM(C36:N36) -> 14
B37: 13.45 - 14.00 | C37: 0 | D37: 0 | E37: 2 | F37: 0 | G37: 0 | H37: 0 | I37: 0 | J37: 0 | K37: 0 | L37: 0 | M37: 2 | N37: 0 | O37: =SUM(C37:L37,N37) -> 2 | P37: =SUM(C37:N37) -> 4
B38: 14.00 - 14.15 | C38: 1 | D38: 0 | E38: 0 | F38: 1 | G38: 0 | H38: 0 | I38: 0 | J38: 0 | K38: 0 | L38: 0 | M38: 3 | N38: 0 | O38: =SUM(C38:L38,N38) -> 2 | P38: =SUM(C38:N38) -> 5
B39: 14.15 - 14.30 | C39: 3 | D39: 0 | E39: 0 | F39: 0 | G39: 0 | H39: 0 | I39: 0 | J39: 0 | K39: 0 | L39: 0 | M39: 3 | N39: 0 | O39: =SUM(C39:L39,N39) -> 3 | P39: =SUM(C39:N39) -> 6
B40: 14.30 - 14.45 | C40: 5 | D40: 0 | E40: 0 | F40: 0 | G40: 0 | H40: 0 | I40: 2 | J40: 0 | K40: 0 | L40: 0 | M40: 6 | N40: 0 | O40: =SUM(C40:L40,N40) -> 7 | P40: =SUM(C40:N40) -> 13
... B57: 18.45 - 19.00 | C57: 4 | D57: 0 | E57: 0 | F57: 0 | G57: 0 | H57: 0 | I57: 0 | J57: 0 | K57: 0 | L57: 0 | M57: 4 | N57: 0 | O57: =SUM(C57:L57,N57) -> 4 | P57: =SUM(C57:N57) -> 8
B58: Totals | C58: =SUM(C10:C57) -> 126 | D58: =SUM(D10:D57) -> 14 | E58: =SUM(E10:E57) -> 10 | F58: =SUM(F10:F57) -> 12 | G58: =SUM(G10:G57) -> 2 | H58: =SUM(H10:H57) -> 5 | I58: =SUM(I10:I57) -> 23 | J58: =SUM(J10:J57) -> 0 | ... P58: =SUM(P10:P57) -> 443
...

Sheet Avg Week Katuna-Kabale
B1: Consultancy services for Preparation of Expressway Development Master Plan (EDMP) for Uganda
B2: MANUAL CLASSIFIED COUNT (MCC)
B3: ROAD NAME: | C3: KATUNA B/P
C5: Date | D5: AVERAGE WEEK | F5: Location | G5: XXXXX | J5: Surveyor | K5: XXXXXX
C6: Dir. From | D6: KATUNA | F6: Dir. To | G6: KABALE | J6: Supervisor | K6: XXXXXXX
B8: Time / Veh Type | R8: SUMMARY TRAFFIC VOLUMES
C9: 1. Car | D9: 2. Station Wagon | E9: 3. Pickups | F9: 4. Minibus, matatu | G9: 5. Medium bus | H9: 6. Large Bus | I9: 7. Light Truck | J9: 8. Medium Truck | K9: 9. Heavy truck | L9: 10. Truck Trailer | M9: 11. Motor cycles | N9: 12. Tractors | O9: Total Excl M/Cycles | P9: Total All | R9: Time | S9: 1. Car | T9: 2. Station Wagon | U9: 3. Pickups | V9: 4. Minibus, matatu | W9: 5. Medium bus | X9: 6. Large Bus | Y9: 7. Light Truck | Z9: 8. Medium Truck | AA9: 9. Heavy truck | AB9: 10. Truck Trailer | AC9: 11. Motorcycles | AD9: 12. Tractors, Graders | AE9: Total Excl M/ Cycles | AF9: Total All
B10: 07.00 - 07.15 | C10: =AVERAGE('25.10 Katuna-Kabale 24hr'!C10,'26.10 Katuna-Kabale'!C10) -> 0.5 | D10: =AVERAGE('25.10 Katuna-Kabale 24hr'!D10,'26.10 Katuna-Kabale'!D10) -> 0 | E10: =AVERAGE('25.10 Katuna-Kabale 24hr'!E10,'26.10 Katuna-Kabale'!E10) -> 0 | F10: =AVERAGE('25.10 Katuna-Kabale 24hr'!F10,'26.10 Katuna-Kabale'!F10) -> 0 | G10: =AVERAGE('25.10 Katuna-Kabale 24hr'!G10,'26.10 Katuna-Kabale'!G10) -> 0 | H10: =AVERAGE('25.10 Katuna-Kabale 24hr'!H10,'26.10 Katuna-Kabale'!H10) -> 0 | I10: =AVERAGE('25.10 Katuna-Kabale 24hr'!I10,'26.10 Katuna-Kabale'!I10) -> 0 | J10: =AVERAGE('25.10 Katuna-Kabale 24hr'!J10,'26.10 Katuna-Kabale'!J10) -> 0 | ... N10: =AVERAGE('25.10 Katuna-Kabale 24hr'!N10,'26.10 Katuna-Kabale'!N10) -> 0 | O10: =SUM(C10:L10,N10) -> 0.5 | P10: =SUM(C10:N10) -> 3 | R10: 0700-0800 | S10: =SUM(C10:C13) -> 4 | T10: =SUM(D10:D13) -> 0.5 | U10: =SUM(E10:E13) -> 0 | V10: =SUM(F10:F13) -> 0 | W10: =SUM(G10:G13) -> 0 | X10: =SUM(H10:H13) -> 0 | Y10: =SUM(I10:I13) -> 0 | Z10: =SUM(J10:J13) -> 0 | ... AF10: =SUM(P10:P13) -> 13.5
B11: 07.15 - 07.30 | C11: =AVERAGE('25.10 Katuna-Kabale 24hr'!C11,'26.10 Katuna-Kabale'!C11) -> 1 | D11: =AVERAGE('25.10 Katuna-Kabale 24hr'!D11,'26.10 Katuna-Kabale'!D11) -> 0 | E11: =AVERAGE('25.10 Katuna-Kabale 24hr'!E11,'26.10 Katuna-Kabale'!E11) -> 0 | F11: =AVERAGE('25.10 Katuna-Kabale 24hr'!F11,'26.10 Katuna-Kabale'!F11) -> 0 | G11: =AVERAGE('25.10 Katuna-Kabale 24hr'!G11,'26.10 Katuna-Kabale'!G11) -> 0 | H11: =AVERAGE('25.10 Katuna-Kabale 24hr'!H11,'26.10 Katuna-Kabale'!H11) -> 0 | I11: =AVERAGE('25.10 Katuna-Kabale 24hr'!I11,'26.10 Katuna-Kabale'!I11) -> 0 | J11: =AVERAGE('25.10 Katuna-Kabale 24hr'!J11,'26.10 Katuna-Kabale'!J11) -> 0 | ... N11: =AVERAGE('25.10 Katuna-Kabale 24hr'!N11,'26.10 Katuna-Kabale'!N11) -> 0 | O11: =SUM(C11:L11,N11) -> 1 | P11: =SUM(C11:N11) -> 1.5 | R11: 0800-0900 | S11: =SUM(C14:C17) -> 15 | T11: =SUM(D14:D17) -> 1.5 | U11: =SUM(E14:E17) -> 1 | V11: =SUM(F14:F17) -> 0.5 | W11: =SUM(G14:G17) -> 0 | X11: =SUM(H14:H17) -> 0 | Y11: =SUM(I14:I17) -> 2 | Z11: =SUM(J14:J17) -> 0 | ... AF11: =SUM(P14:P17) -> 37.5
