Workbook

Sheet Summary
D2: To Arm
D3: Kibuye RBT | E3: Entebbe | F3: Ndeeba | G3: Katwe | H3: Queens Way | I3: Makindye | J3: TOTAL
B4: From Arm | C4: Kibuye RBT | D4: 0 | E4: ='Kibuye-Entebbe'!AB29*$D$12 -> 49695.697 | F4: ='KIBUYE-NDEEBA'!AB29*$D$12 -> 15804.105 | G4: ='Kibuye-Katwe'!AB29*$D$12 -> 50330.849 | H4: - | I4: ='Kibuye-makindye'!AB29*$D$12 -> 27620.208 | J4: =SUM(D4:I4) -> 143450.86
C5: Entebbe | D5: ='Entebbe-Kibuye'!AB29*$D$12 -> 44618.933 | J5: =SUM(D5:I5) -> 44618.933
C6: Ndeeba | D6: ='NDEEBA-KIBUYE'!AB29*$D$12 -> 17940.632 | J6: =SUM(D6:I6) -> 17940.632
C7: Katwe | D7: ='Katwe-Kibuye'!AB29*$D$12 -> 25186.943 | J7: =SUM(D7:I7) -> 25186.943
C8: Queens Way | D8: ='QUEEN''S WAY-KIBUYE'!AB29*$D$12 -> 38139.789 | J8: =SUM(D8:I8) -> 38139.789
C9: Makindye | D9: ='Makindye-kibuye'!AB29*$D$12 -> 31911.441 | J9: =SUM(D9:I9) -> 31911.441
C10: TOTAL | D10: =SUM(D4:D9) -> 157797.74 | E10: =SUM(E4:E9) -> 49695.697 | F10: =SUM(F4:F9) -> 15804.105 | G10: =SUM(G4:G9) -> 50330.849 | H10: =SUM(H4:H9) -> 0 | I10: =SUM(I4:I9) -> 27620.208
C12: NEF | D12: 1.484

Sheet Entebbe-Kibuye
B1: Consultancy services for Preparation of Expressway Development Master Plan (EDMP) for Uganda
B2: JUNCTION TURNING COUNT (JTC)
B3: ROAD NAME: | C3: KIBUYE JUNCTION (RBT)
C5: Date | D5: AVERAGE | E5: Location | F5: KIBUYE ROUNDABOUT | I5: Surveyor | J5: EO
C6: Dir. From | D6: Entebbe | E6: Dir. To | F6: KIBUYE | I6: Supervisor | J6: IO
B8: Time / Veh Type | P8: SUMMARY TRAFFIC VOLUMES
C9: 1. Private Car | D9: 3. Pickups/four wheel drive | E9: 4. Minibus, matatu | F9: 5. Medium bus/ coaster | G9: 6. Large Bus/coach | H9: 7. Light Truck | I9: 8. Medium Truck | J9: 9. Heavy truck | K9: 10. Truck Trailer | L9: 11. Motor cycles | M9: Total Excl M/Cycles | N9: Total All | P9: Time | Q9: 1. Car | R9: 3. Pickups | S9: 4. Minibus, matatu | T9: 5. Medium bus | U9: 6. Large Bus | V9: 7. Light Truck | W9: 8. Medium Truck | X9: 9. Heavy truck | Y9: 10. Truck Trailer | Z9: 11. Motorcycles | AA9: Total Excl M/ Cycles | AB9: Total All
B10: 06.00 - 06.15 | C10: 82.333333 | D10: 32 | E10: 84 | F10: 1.6666667 | G10: 1 | H10: 5 | I10: 4.6666667 | J10: 0.33333333 | K10: 0.33333333 | L10: 54.666667 | M10: =SUM(C10:K10) -> 211.33333 | N10: =SUM(C10:L10) -> 266 | P10: 06.00 - 0700 | Q10: =SUM(C10:C13) -> 313.66667 | R10: =SUM(D10:D13) -> 225.33333 | S10: =SUM(E10:E13) -> 442 | T10: =SUM(F10:F13) -> 5.6666667 | U10: =SUM(G10:G13) -> 3.6666667 | V10: =SUM(H10:H13) -> 22 | W10: =SUM(I10:I13) -> 17.666667 | X10: =SUM(J10:J13) -> 2 | ... AB10: =SUM(N10:N13) -> 1625.6667
B11: 06.15 - 06.30 | C11: 118 | D11: 60 | E11: 94.333333 | F11: 1.3333333 | G11: 0 | H11: 4.3333333 | I11: 3.3333333 | J11: 1 | K11: 0 | L11: 85.666667 | M11: =SUM(C11:K11) -> 282.33333 | N11: =SUM(C11:L11) -> 368 | P11: 0700-0800 | Q11: =SUM(C14:C17) -> 471.33333 | R11: =SUM(D14:D17) -> 216.66667 | S11: =SUM(E14:E17) -> 404 | T11: =SUM(F14:F17) -> 9.3333333 | U11: =SUM(G14:G17) -> 6 | V11: =SUM(H14:H17) -> 26 | W11: =SUM(I14:I17) -> 17.666667 | X11: =SUM(J14:J17) -> 1 | ... AB11: =SUM(N14:N17) -> 3051.3333
B12: 06.30 - 06.45 | C12: 0 | D12: 67.333333 | E12: 169.66667 | F12: 1.3333333 | G12: 2.3333333 | H12: 7 | I12: 6 | J12: 0 | K12: 0 | L12: 177.33333 | M12: =SUM(C12:K12) -> 253.66667 | N12: =SUM(C12:L12) -> 431 | P12: 0800-0900 | Q12: =SUM(C18:C21) -> 440.33333 | R12: =SUM(D18:D21) -> 233.66667 | S12: =SUM(E18:E21) -> 388 | T12: =SUM(F18:F21) -> 7.3333333 | U12: =SUM(G18:G21) -> 9.3333333 | V12: =SUM(H18:H21) -> 21 | W12: =SUM(I18:I21) -> 15.666667 | X12: =SUM(J18:J21) -> 2 | ... AB12: =SUM(N18:N21) -> 3576
B13: 06.45 - 07.00 | C13: 113.33333 | D13: 66 | E13: 94 | F13: 1.3333333 | G13: 0.33333333 | H13: 5.6666667 | I13: 3.6666667 | J13: 0.66666667 | K13: 0 | L13: 275.66667 | M13: =SUM(C13:K13) -> 285 | N13: =SUM(C13:L13) -> 560.66667 | P13: 0900-1000 | Q13: =SUM(C22:C25) -> 498 | R13: =SUM(D22:D25) -> 243 | S13: =SUM(E22:E25) -> 391 | T13: =SUM(F22:F25) -> 1.3333333 | U13: =SUM(G22:G25) -> 0 | V13: =SUM(H22:H25) -> 26.333333 | W13: =SUM(I22:I25) -> 18 | X13: =SUM(J22:J25) -> 1.3333333 | ... AB13: =SUM(N22:N25) -> 3408
B14: 07.00 - 07.15 | C14: 110.66667 | D14: 46.333333 | E14: 101 | F14: 1.3333333 | G14: 2.3333333 | H14: 6.6666667 | I14: 4 | J14: 0 | K14: 0.33333333 | L14: 328 | M14: =SUM(C14:K14) -> 272.66667 | N14: =SUM(C14:L14) -> 600.66667 | P14: 1000-1100 | Q14: =SUM(C26:C29) -> 468.66667 | R14: =SUM(D26:D29) -> 251 | S14: =SUM(E26:E29) -> 392.66667 | T14: =SUM(F26:F29) -> 1.3333333 | U14: =SUM(G26:G29) -> 4 | V14: =SUM(H26:H29) -> 35.333333 | W14: =SUM(I26:I29) -> 26.666667 | X14: =SUM(J26:J29) -> 3.6666667 | ... AB14: =SUM(N26:N29) -> 2839
B15: 07.15 - 07.30 | C15: 121 | D15: 56.333333 | E15: 95.333333 | F15: 2 | G15: 1.6666667 | H15: 5 | I15: 4.6666667 | J15: 1 | K15: 0 | L15: 468.33333 | M15: =SUM(C15:K15) -> 287 | N15: =SUM(C15:L15) -> 755.33333 | P15: 1100-1200 | Q15: =SUM(C30:C33) -> 428 | R15: =SUM(D30:D33) -> 217.33333 | S15: =SUM(E30:E33) -> 359.66667 | T15: =SUM(F30:F33) -> 4 | U15: =SUM(G30:G33) -> 1 | V15: =SUM(H30:H33) -> 39.666667 | W15: =SUM(I30:I33) -> 24.666667 | X15: =SUM(J30:J33) -> 2.6666667 | ... AB15: =SUM(N30:N33) -> 2527.3333
B16: 07.30 - 07.45 | C16: 127.33333 | D16: 52.333333 | E16: 93 | F16: 2.6666667 | G16: 1.6666667 | H16: 5.3333333 | I16: 5 | J16: 0 | K16: 0 | L16: 511.33333 | M16: =SUM(C16:K16) -> 287.33333 | N16: =SUM(C16:L16) -> 798.66667 | P16: 1200-1300 | Q16: =SUM(C34:C37) -> 376 | R16: =SUM(D34:D37) -> 202.66667 | S16: =SUM(E34:E37) -> 344 | T16: =SUM(F34:F37) -> 1.6666667 | U16: =SUM(G34:G37) -> 1 | V16: =SUM(H34:H37) -> 43.666667 | W16: =SUM(I34:I37) -> 33 | X16: =SUM(J34:J37) -> 3 | ... AB16: =SUM(N34:N37) -> 2357.3333
B17: 07.45 - 08.00 | C17: 112.33333 | D17: 61.666667 | E17: 114.66667 | F17: 3.3333333 | G17: 0.33333333 | H17: 9 | I17: 4 | J17: 0 | K17: 0 | L17: 591.33333 | M17: =SUM(C17:K17) -> 305.33333 | N17: =SUM(C17:L17) -> 896.66667 | P17: 1300-1400 | Q17: =SUM(C38:C41) -> 324.33333 | R17: =SUM(D38:D41) -> 147 | S17: =SUM(E38:E41) -> 292.66667 | T17: =SUM(F38:F41) -> 0 | U17: =SUM(G38:G41) -> 0.33333333 | V17: =SUM(H38:H41) -> 41.333333 | W17: =SUM(I38:I41) -> 31.666667 | X17: =SUM(J38:J41) -> 4 | ... AB17: =SUM(N38:N41) -> 2047
B18: 08.00 - 08.15 | C18: 100 | D18: 51.333333 | E18: 97.666667 | F18: 2.6666667 | G18: 1 | H18: 4.3333333 | I18: 5 | J18: 0.66666667 | K18: 0 | L18: 625 | M18: =SUM(C18:K18) -> 262.66667 | N18: =SUM(C18:L18) -> 887.66667 | P18: 1400-1500 | Q18: =SUM(C42:C45) -> 363.33333 | R18: =SUM(D42:D45) -> 122.33333 | S18: =SUM(E42:E45) -> 272 | T18: =SUM(F42:F45) -> 3 | U18: =SUM(G42:G45) -> 1.6666667 | V18: =SUM(H42:H45) -> 48 | W18: =SUM(I42:I45) -> 39 | X18: =SUM(J42:J45) -> 9.3333333 | ... AB18: =SUM(N42:N45) -> 1802.3333
B19: 08.15 - 08.30 | C19: 111 | D19: 63.666667 | E19: 87 | F19: 2 | G19: 2.3333333 | H19: 5 | I19: 3 | J19: 0.66666667 | K19: 0 | L19: 643.66667 | M19: =SUM(C19:K19) -> 274.66667 | N19: =SUM(C19:L19) -> 918.33333 | P19: 1500-1600 | Q19: =SUM(C46:C49) -> 388 | R19: =SUM(D46:D49) -> 149 | S19: =SUM(E46:E49) -> 294.33333 | T19: =SUM(F46:F49) -> 0.33333333 | U19: =SUM(G46:G49) -> 2.6666667 | V19: =SUM(H46:H49) -> 54.666667 | W19: =SUM(I46:I49) -> 44.666667 | X19: =SUM(J46:J49) -> 4.3333333 | ... AB19: =SUM(N46:N49) -> 2089.6667
B20: 08.30 - 08.45 | C20: 112.66667 | D20: 59 | E20: 102 | F20: 1 | G20: 4 | H20: 7 | I20: 3.3333333 | J20: 0.33333333 | K20: 1.3333333 | L20: 569 | M20: =SUM(C20:K20) -> 290.66667 | N20: =SUM(C20:L20) -> 859.66667 | P20: 1600-1700 | Q20: =SUM(C50:C53) -> 350.66667 | R20: =SUM(D50:D53) -> 155.33333 | S20: =SUM(E50:E53) -> 306.66667 | T20: =SUM(F50:F53) -> 3.6666667 | U20: =SUM(G50:G53) -> 5.3333333 | V20: =SUM(H50:H53) -> 43.333333 | W20: =SUM(I50:I53) -> 43 | X20: =SUM(J50:J53) -> 6 | ... AB20: =SUM(N50:N53) -> 2076
B21: 08.45 - 9.00 | C21: 116.66667 | D21: 59.666667 | E21: 101.33333 | F21: 1.6666667 | G21: 2 | H21: 4.6666667 | I21: 4.3333333 | J21: 0.33333333 | K21: 0.33333333 | L21: 619.33333 | M21: =SUM(C21:K21) -> 291 | N21: =SUM(C21:L21) -> 910.33333 | P21: 1700-1800 | Q21: =SUM(C54:C57) -> 361 | R21: =SUM(D54:D57) -> 143.33333 | S21: =SUM(E54:E57) -> 328.33333 | T21: =SUM(F54:F57) -> 4 | U21: =SUM(G54:G57) -> 4 | V21: =SUM(H54:H57) -> 48.666667 | W21: =SUM(I54:I57) -> 45 | X21: =SUM(J54:J57) -> 5 | ... AB21: =SUM(N54:N57) -> 2169
B22: 09.00 - 09.15 | C22: 119 | D22: 51.333333 | E22: 102 | F22: 0.66666667 | G22: 0 | H22: 6.3333333 | I22: 3.3333333 | J22: 0.33333333 | K22: 0 | L22: 625.66667 | M22: =SUM(C22:K22) -> 283 | N22: =SUM(C22:L22) -> 908.66667 | P22: 1800-1900 | Q22: =SUM(C58:C61) -> 284 | R22: =SUM(D58:D61) -> 106 | S22: =SUM(E58:E61) -> 357.33333 | T22: =SUM(F58:F61) -> 9 | U22: =SUM(G58:G61) -> 7 | V22: =SUM(H58:H61) -> 40 | W22: =SUM(I58:I61) -> 24.333333 | X22: =SUM(J58:J61) -> 5.3333333 | ... AB22: =SUM(N58:N61) -> 2123.6667
B23: 09.15 - 09.30 | C23: 130 | D23: 62.333333 | E23: 81.333333 | F23: 0.33333333 | G23: 0 | H23: 4.3333333 | I23: 4 | J23: 0 | K23: 0 | L23: 528.33333 | M23: =SUM(C23:K23) -> 282.33333 | N23: =SUM(C23:L23) -> 810.66667 | P23: AM Peak Hr | Q23: =MAX(Q10:Q13) -> 498 | R23: =MAX(R10:R13) -> 243 | S23: =MAX(S10:S13) -> 442 | T23: =MAX(T10:T13) -> 9.3333333 | U23: =MAX(U10:U13) -> 9.3333333 | V23: =MAX(V10:V13) -> 26.333333 | W23: =MAX(W10:W13) -> 18 | X23: =MAX(X10:X13) -> 2 | ... AB23: =MAX(AB10:AB13) -> 3576
B24: 09.30 - 09.45 | C24: 126.33333 | D24: 62 | E24: 93.666667 | F24: 0.33333333 | G24: 0 | H24: 6 | I24: 4.3333333 | J24: 0.66666667 | K24: 0 | L24: 548.66667 | M24: =SUM(C24:K24) -> 293.33333 | N24: =SUM(C24:L24) -> 842 | P24: IP Peak Hr | Q24: =MAX(Q14:Q19) -> 468.66667 | R24: =MAX(R14:R19) -> 251 | S24: =MAX(S14:S19) -> 392.66667 | T24: =MAX(T14:T19) -> 4 | U24: =MAX(U14:U19) -> 4 | V24: =MAX(V14:V19) -> 54.666667 | W24: =MAX(W14:W19) -> 44.666667 | X24: =MAX(X14:X19) -> 9.3333333 | ... AB24: =MAX(AB14:AB19) -> 2839
B25: 09.45 - 10.00 | C25: 122.66667 | D25: 67.333333 | E25: 114 | F25: 0 | G25: 0 | H25: 9.6666667 | I25: 6.3333333 | J25: 0.33333333 | K25: 0.33333333 | L25: 526 | M25: =SUM(C25:K25) -> 320.66667 | N25: =SUM(C25:L25) -> 846.66667 | P25: PM Peak Hr | Q25: =MAX(Q20:Q22) -> 361 | R25: =MAX(R20:R22) -> 155.33333 | S25: =MAX(S20:S22) -> 357.33333 | T25: =MAX(T20:T22) -> 9 | U25: =MAX(U20:U22) -> 7 | V25: =MAX(V20:V22) -> 48.666667 | W25: =MAX(W20:W22) -> 45 | X25: =MAX(X20:X22) -> 6 | ... AB25: =MAX(AB20:AB22) -> 2169
B26: 10.00 - 10.15 | C26: 123 | D26: 68.666667 | E26: 111.33333 | F26: 0.33333333 | G26: 1 | H26: 10.333333 | I26: 8 | J26: 0.66666667 | K26: 1 | L26: 490.66667 | M26: =SUM(C26:K26) -> 324.33333 | N26: =SUM(C26:L26) -> 815 | P26: AM Period | Q26: =SUM(Q10:Q13) -> 1723.3333 | R26: =SUM(R10:R13) -> 918.66667 | S26: =SUM(S10:S13) -> 1625 | T26: =SUM(T10:T13) -> 23.666667 | U26: =SUM(U10:U13) -> 19 | V26: =SUM(V10:V13) -> 95.333333 | W26: =SUM(W10:W13) -> 69 | X26: =SUM(X10:X13) -> 6.3333333 | ... AB26: =SUM(AB10:AB13) -> 11661
B27: 10.15 - 10.30 | C27: 120 | D27: 62 | E27: 106 | F27: 0.66666667 | G27: 2.3333333 | H27: 9.3333333 | I27: 6.3333333 | J27: 0.33333333 | K27: 1 | L27: 425.33333 | M27: =SUM(C27:K27) -> 308 | N27: =SUM(C27:L27) -> 733.33333 | P27: IP Period | Q27: =SUM(Q14:Q19) -> 2348.3333 | R27: =SUM(R14:R19) -> 1089.3333 | S27: =SUM(S14:S19) -> 1955.3333 | T27: =SUM(T14:T19) -> 10.333333 | U27: =SUM(U14:U19) -> 10.666667 | V27: =SUM(V14:V19) -> 262.66667 | W27: =SUM(W14:W19) -> 199.66667 | X27: =SUM(X14:X19) -> 27 | ... AB27: =SUM(AB14:AB19) -> 13662.667
B28: 10.30 - 10.45 | C28: 105 | D28: 68 | E28: 88.333333 | F28: 0 | G28: 0.33333333 | H28: 6.6666667 | I28: 4.6666667 | J28: 1 | K28: 0.33333333 | L28: 402.66667 | M28: =SUM(C28:K28) -> 274.33333 | N28: =SUM(C28:L28) -> 677 | P28: PM Period | Q28: =SUM(Q20:Q22) -> 995.66667 | R28: =SUM(R20:R22) -> 404.66667 | S28: =SUM(S20:S22) -> 992.33333 | T28: =SUM(T20:T22) -> 16.666667 | U28: =SUM(U20:U22) -> 16.333333 | V28: =SUM(V20:V22) -> 132 | W28: =SUM(W20:W22) -> 112.33333 | X28: =SUM(X20:X22) -> 16.333333 | ... AB28: =SUM(AB20:AB22) -> 6368.6667
B29: 10.45 - 11.00 | C29: 120.66667 | D29: 52.333333 | E29: 87 | F29: 0.33333333 | G29: 0.33333333 | H29: 9 | I29: 7.6666667 | J29: 1.6666667 | K29: 0.33333333 | L29: 334.33333 | M29: =SUM(C29:K29) -> 279.33333 | N29: =SUM(C29:L29) -> 613.66667 | P29: 12 Hours | Q29: =SUM(Q11:Q22) -> 4753.6667 | R29: =SUM(R11:R22) -> 2187.3333 | S29: =SUM(S11:S22) -> 4130.6667 | T29: =SUM(T11:T22) -> 45 | U29: =SUM(U11:U22) -> 42.333333 | V29: =SUM(V11:V22) -> 468 | W29: =SUM(W11:W22) -> 363.33333 | X29: =SUM(X11:X22) -> 47.666667 | ... AB29: =SUM(AB11:AB22) -> 30066.667
B30: 11.00 - 11.15 | C30: 87 | D30: 50.333333 | E30: 100 | F30: 1.6666667 | G30: 1 | H30: 10 | I30: 5.6666667 | J30: 0 | K30: 1 | L30: 360 | M30: =SUM(C30:K30) -> 256.66667 | N30: =SUM(C30:L30) -> 616.66667
B31: 11.15 - 11.30 | C31: 108.33333 | D31: 52.666667 | E31: 97 | F31: 0.66666667 | G31: 0 | H31: 12 | I31: 6 | J31: 1 | K31: 0.33333333 | L31: 406.33333 | M31: =SUM(C31:K31) -> 278 | N31: =SUM(C31:L31) -> 684.33333
B32: 11.30 - 11.45 | C32: 119.33333 | D32: 59 | E32: 74 | F32: 0.66666667 | G32: 0 | H32: 10 | I32: 5.3333333 | J32: 1.6666667 | K32: 2.3333333 | L32: 342.66667 | M32: =SUM(C32:K32) -> 272.33333 | N32: =SUM(C32:L32) -> 615
B33: 11.45 - 12.00 | C33: 113.33333 | D33: 55.333333 | E33: 88.666667 | F33: 1 | G33: 0 | H33: 7.6666667 | I33: 7.6666667 | J33: 0 | K33: 0.33333333 | L33: 337.33333 | M33: =SUM(C33:K33) -> 274 | N33: =SUM(C33:L33) -> 611.33333
B34: 12.00 - 12.15 | C34: 108.66667 | D34: 67.333333 | E34: 87 | F34: 0.66666667 | G34: 0.66666667 | H34: 11 | I34: 8.6666667 | J34: 2 | K34: 0 | L34: 338.33333 | M34: =SUM(C34:K34) -> 286 | N34: =SUM(C34:L34) -> 624.33333
B35: 12.15 - 12.30 | C35: 82.666667 | D35: 50.666667 | E35: 98 | F35: 0 | G35: 0.33333333 | H35: 10.666667 | I35: 9.3333333 | J35: 0.33333333 | K35: 1 | L35: 342.66667 | M35: =SUM(C35:K35) -> 253 | N35: =SUM(C35:L35) -> 595.66667
B36: 12.30 - 12.45 | C36: 93 | D36: 48.666667 | E36: 74.333333 | F36: 0.66666667 | G36: 0 | H36: 13.666667 | I36: 9.3333333 | J36: 0 | K36: 2 | L36: 336.33333 | M36: =SUM(C36:K36) -> 241.66667 | N36: =SUM(C36:L36) -> 578
B37: 12.45 - 13.00 | C37: 91.666667 | D37: 36 | E37: 84.666667 | F37: 0.33333333 | G37: 0 | H37: 8.3333333 | I37: 5.6666667 | J37: 0.66666667 | K37: 0.33333333 | L37: 331.66667 | M37: =SUM(C37:K37) -> 227.66667 | N37: =SUM(C37:L37) -> 559.33333
B38: 13.00 - 13.15 | C38: 94.666667 | D38: 33.666667 | E38: 75.333333 | F38: 0 | G38: 0.33333333 | H38: 11.666667 | I38: 8.3333333 | J38: 0.66666667 | K38: 2.3333333 | L38: 318.66667 | M38: =SUM(C38:K38) -> 227 | N38: =SUM(C38:L38) -> 545.66667
B39: 13.15 - 13.30 | C39: 48 | D39: 40 | E39: 71.666667 | F39: 0 | G39: 0 | H39: 8.6666667 | I39: 7.3333333 | J39: 0.33333333 | K39: 1 | L39: 315.66667 | M39: =SUM(C39:K39) -> 177 | N39: =SUM(C39:L39) -> 492.66667
B40: 13.30 - 13.45 | C40: 91.333333 | D40: 38.333333 | E40: 73.333333 | F40: 0 | G40: 0 | H40: 9.3333333 | I40: 9 | J40: 2 | K40: 1 | L40: 316.33333 | M40: =SUM(C40:K40) -> 224.33333 | N40: =SUM(C40:L40) -> 540.66667
B41: 13.45 - 14.00 | C41: 90.333333 | D41: 35 | E41: 72.333333 | F41: 0 | G41: 0 | H41: 11.666667 | I41: 7 | J41: 1 | K41: 0.33333333 | L41: 250.33333 | M41: =SUM(C41:K41) -> 217.66667 | N41: =SUM(C41:L41) -> 468
... B62: 19.00 - 19.15 | C62: 76.333333 | D62: 17 | E62: 88 | F62: 3 | G62: 0.66666667 | H62: 5.3333333 | I62: 4 | J62: 1.3333333 | K62: 0.66666667 | L62: 337.33333 | M62: =SUM(C62:K62) -> 196.33333 | N62: =SUM(C62:L62) -> 533.66667
...

Sheet Kibuye-Entebbe
B1: Consultancy services for Preparation of Expressway Development Master Plan (EDMP) for Uganda
B2: JUNCTION TURNING COUNT (JTC)
B3: ROAD NAME: | C3: KIBUYE JUNCTION (RBT)
C5: Date | D5: AVERAGE | E5: Location | F5: KIBUYE ROUNDABOUT | I5: Surveyor | J5: EO
C6: Dir. From | D6: kibuye | E6: Dir. To | F6: Entebbe | I6: Supervisor | J6: IO
B8: Time / Veh Type | P8: SUMMARY TRAFFIC VOLUMES
C9: 1. Private Car | D9: 3. Pickups/four wheel drive | E9: 4. Minibus, matatu | F9: 5. Medium bus/ coaster | G9: 6. Large Bus/coach | H9: 7. Light Truck | I9: 8. Medium Truck | J9: 9. Heavy truck | K9: 10. Truck Trailer | L9: 11. Motor cycles | M9: Total Excl M/Cycles | N9: Total All | P9: Time | Q9: 1. Car | R9: 3. Pickups | S9: 4. Minibus, matatu | T9: 5. Medium bus | U9: 6. Large Bus | V9: 7. Light Truck | W9: 8. Medium Truck | X9: 9. Heavy truck | Y9: 10. Truck Trailer | Z9: 11. Motorcycles | AA9: Total Excl M/ Cycles | AB9: Total All
B10: 06.00 - 06.15 | C10: 13.666667 | D10: 4.6666667 | E10: 48.666667 | F10: 2.3333333 | G10: 2 | H10: 1.6666667 | I10: 2.3333333 | J10: 1.3333333 | K10: 3 | L10: 74.666667 | M10: =SUM(C10:K10) -> 79.666667 | N10: =SUM(C10:L10) -> 154.33333 | P10: 06.00 - 06.15 | Q10: =SUM(C10:C13) -> 157.33333 | R10: =SUM(D10:D13) -> 70 | S10: =SUM(E10:E13) -> 396.66667 | T10: =SUM(F10:F13) -> 5.6666667 | U10: =SUM(G10:G13) -> 4.3333333 | V10: =SUM(H10:H13) -> 18.666667 | W10: =SUM(I10:I13) -> 21.666667 | X10: =SUM(J10:J13) -> 5.6666667 | ... AB10: =SUM(N10:N13) -> 1253.3333
B11: 06.15 - 06.30 | C11: 40.666667 | D11: 15.666667 | E11: 97.333333 | F11: 0.33333333 | G11: 0 | H11: 6 | I11: 9 | J11: 0.66666667 | K11: 2.6666667 | L11: 130.66667 | M11: =SUM(C11:K11) -> 172.33333 | N11: =SUM(C11:L11) -> 303 | P11: 0700-0800 | Q11: =SUM(C14:C17) -> 227 | R11: =SUM(D14:D17) -> 95.666667 | S11: =SUM(E14:E17) -> 516 | T11: =SUM(F14:F17) -> 11.333333 | U11: =SUM(G14:G17) -> 14 | V11: =SUM(H14:H17) -> 19.333333 | W11: =SUM(I14:I17) -> 14.666667 | X11: =SUM(J14:J17) -> 7.3333333 | ... AB11: =SUM(N14:N17) -> 2028
B12: 06.30 - 06.45 | C12: 51.333333 | D12: 30.666667 | E12: 144.33333 | F12: 1.6666667 | G12: 0.66666667 | H12: 4.3333333 | I12: 4 | J12: 1.6666667 | K12: 1.6666667 | L12: 164.33333 | M12: =SUM(C12:K12) -> 240.33333 | N12: =SUM(C12:L12) -> 404.66667 | P12: 0800-0900 | Q12: =SUM(C18:C21) -> 183.66667 | R12: =SUM(D18:D21) -> 98.333333 | S12: =SUM(E18:E21) -> 532 | T12: =SUM(F18:F21) -> 4 | U12: =SUM(G18:G21) -> 2.3333333 | V12: =SUM(H18:H21) -> 22 | W12: =SUM(I18:I21) -> 19.333333 | X12: =SUM(J18:J21) -> 2.6666667 | ... AB12: =SUM(N18:N21) -> 2475
B13: 06.45 - 07.00 | C13: 51.666667 | D13: 19 | E13: 106.33333 | F13: 1.3333333 | G13: 1.6666667 | H13: 6.6666667 | I13: 6.3333333 | J13: 2 | K13: 1 | L13: 195.33333 | M13: =SUM(C13:K13) -> 196 | N13: =SUM(C13:L13) -> 391.33333 | P13: 0900-1000 | Q13: =SUM(C22:C25) -> 190.33333 | R13: =SUM(D22:D25) -> 98 | S13: =SUM(E22:E25) -> 509.33333 | T13: =SUM(F22:F25) -> 2.3333333 | U13: =SUM(G22:G25) -> 1.3333333 | V13: =SUM(H22:H25) -> 36.333333 | W13: =SUM(I22:I25) -> 32.666667 | X13: =SUM(J22:J25) -> 2.3333333 | ... AB13: =SUM(N22:N25) -> 2758
B14: 07.00 - 07.15 | C14: 57.666667 | D14: 26 | E14: 98.333333 | F14: 4.3333333 | G14: 5 | H14: 3.6666667 | I14: 3 | J14: 1.3333333 | K14: 1.6666667 | L14: 213 | M14: =SUM(C14:K14) -> 201 | N14: =SUM(C14:L14) -> 414 | P14: 1000-1100 | Q14: =SUM(C26:C29) -> 243.66667 | R14: =SUM(D26:D29) -> 128.33333 | S14: =SUM(E26:E29) -> 498.33333 | T14: =SUM(F26:F29) -> 0.66666667 | U14: =SUM(G26:G29) -> 2 | V14: =SUM(H26:H29) -> 45 | W14: =SUM(I26:I29) -> 34.666667 | X14: =SUM(J26:J29) -> 7 | ... AB14: =SUM(N26:N29) -> 2794.3333
B15: 07.15 - 07.30 | C15: 54 | D15: 21.666667 | E15: 123.33333 | F15: 3.3333333 | G15: 6 | H15: 6.6666667 | I15: 4 | J15: 2 | K15: 1 | L15: 247.66667 | M15: =SUM(C15:K15) -> 222 | N15: =SUM(C15:L15) -> 469.66667 | P15: 1100-1200 | Q15: =SUM(C30:C33) -> 266 | R15: =SUM(D30:D33) -> 159.33333 | S15: =SUM(E30:E33) -> 391 | T15: =SUM(F30:F33) -> 2.3333333 | U15: =SUM(G30:G33) -> 0.33333333 | V15: =SUM(H30:H33) -> 53 | W15: =SUM(I30:I33) -> 26.333333 | X15: =SUM(J30:J33) -> 4.3333333 | ... AB15: =SUM(N30:N33) -> 2807.6667
B16: 07.30 - 07.45 | C16: 59.333333 | D16: 23.333333 | E16: 156.66667 | F16: 2.6666667 | G16: 2.3333333 | H16: 5 | I16: 3.3333333 | J16: 1.6666667 | K16: 0.66666667 | L16: 327 | M16: =SUM(C16:K16) -> 255 | N16: =SUM(C16:L16) -> 582 | P16: 1200-1300 | Q16: =SUM(C34:C37) -> 301.33333 | R16: =SUM(D34:D37) -> 172.66667 | S16: =SUM(E34:E37) -> 369.66667 | T16: =SUM(F34:F37) -> 2.6666667 | U16: =SUM(G34:G37) -> 0 | V16: =SUM(H34:H37) -> 51.333333 | W16: =SUM(I34:I37) -> 31 | X16: =SUM(J34:J37) -> 6 | ... AB16: =SUM(N34:N37) -> 2593.6667
B17: 07.45 - 08.00 | C17: 56 | D17: 24.666667 | E17: 137.66667 | F17: 1 | G17: 0.66666667 | H17: 4 | I17: 4.3333333 | J17: 2.3333333 | K17: 1.3333333 | L17: 330.33333 | M17: =SUM(C17:K17) -> 232 | N17: =SUM(C17:L17) -> 562.33333 | P17: 1300-1400 | Q17: =SUM(C38:C41) -> 321.33333 | R17: =SUM(D38:D41) -> 167.66667 | S17: =SUM(E38:E41) -> 369.33333 | T17: =SUM(F38:F41) -> 1.6666667 | U17: =SUM(G38:G41) -> 1.6666667 | V17: =SUM(H38:H41) -> 57 | W17: =SUM(I38:I41) -> 32.666667 | X17: =SUM(J38:J41) -> 3.6666667 | ... AB17: =SUM(N38:N41) -> 2766
B18: 08.00 - 08.15 | C18: 58 | D18: 26.333333 | E18: 137 | F18: 1.3333333 | G18: 0.33333333 | H18: 4 | I18: 4 | J18: 0.33333333 | K18: 0.66666667 | L18: 343 | M18: =SUM(C18:K18) -> 232 | N18: =SUM(C18:L18) -> 575 | P18: 1400-1500 | Q18: =SUM(C42:C45) -> 362 | R18: =SUM(D42:D45) -> 189.66667 | S18: =SUM(E42:E45) -> 313 | T18: =SUM(F42:F45) -> 96.333333 | U18: =SUM(G42:G45) -> 0.33333333 | V18: =SUM(H42:H45) -> 45.333333 | W18: =SUM(I42:I45) -> 22.333333 | X18: =SUM(J42:J45) -> 7 | ... AB18: =SUM(N42:N45) -> 2843
B19: 08.15 - 08.30 | C19: 41 | D19: 24.333333 | E19: 117.66667 | F19: 1 | G19: 0 | H19: 4.6666667 | I19: 5 | J19: 1 | K19: 0.66666667 | L19: 415 | M19: =SUM(C19:K19) -> 195.33333 | N19: =SUM(C19:L19) -> 610.33333 | P19: 1500-1600 | Q19: =SUM(C46:C49) -> 324.33333 | R19: =SUM(D46:D49) -> 194 | S19: =SUM(E46:E49) -> 286 | T19: =SUM(F46:F49) -> 95.333333 | U19: =SUM(G46:G49) -> 1 | V19: =SUM(H46:H49) -> 38 | W19: =SUM(I46:I49) -> 27 | X19: =SUM(J46:J49) -> 5.3333333 | ... AB19: =SUM(N46:N49) -> 2633.3333
B20: 08.30 - 08.45 | C20: 46 | D20: 23.333333 | E20: 140 | F20: 1 | G20: 0 | H20: 7.3333333 | I20: 6 | J20: 0.66666667 | K20: 1.6666667 | L20: 419.33333 | M20: =SUM(C20:K20) -> 226 | N20: =SUM(C20:L20) -> 645.33333 | P20: 1600-1700 | Q20: =SUM(C50:C53) -> 424 | R20: =SUM(D50:D53) -> 224.33333 | S20: =SUM(E50:E53) -> 326.33333 | T20: =SUM(F50:F53) -> 99.666667 | U20: =SUM(G50:G53) -> 3.3333333 | V20: =SUM(H50:H53) -> 37.333333 | W20: =SUM(I50:I53) -> 19.333333 | X20: =SUM(J50:J53) -> 4.6666667 | ... AB20: =SUM(N50:N53) -> 3047
B21: 08.45 - 9.00 | C21: 38.666667 | D21: 24.333333 | E21: 137.33333 | F21: 0.66666667 | G21: 2 | H21: 6 | I21: 4.3333333 | J21: 0.66666667 | K21: 2.3333333 | L21: 428 | M21: =SUM(C21:K21) -> 216.33333 | N21: =SUM(C21:L21) -> 644.33333 | P21: 1700-1800 | Q21: =SUM(C54:C57) -> 512.33333 | R21: =SUM(D54:D57) -> 240 | S21: =SUM(E54:E57) -> 307 | T21: =SUM(F54:F57) -> 143.33333 | U21: =SUM(G54:G57) -> 2.6666667 | V21: =SUM(H54:H57) -> 33 | W21: =SUM(I54:I57) -> 17 | X21: =SUM(J54:J57) -> 3 | ... AB21: =SUM(N54:N57) -> 3369.3333
B22: 09.00 - 09.15 | C22: 48.333333 | D22: 27.666667 | E22: 135 | F22: 1.3333333 | G22: 0.33333333 | H22: 5 | I22: 7.3333333 | J22: 1.3333333 | K22: 2.3333333 | L22: 489.66667 | M22: =SUM(C22:K22) -> 228.66667 | N22: =SUM(C22:L22) -> 718.33333 | P22: 1800-1900 | Q22: =SUM(C58:C61) -> 522.66667 | R22: =SUM(D58:D61) -> 253.33333 | S22: =SUM(E58:E61) -> 374 | T22: =SUM(F58:F61) -> 207 | U22: =SUM(G58:G61) -> 7.3333333 | V22: =SUM(H58:H61) -> 17.333333 | W22: =SUM(I58:I61) -> 11.666667 | X22: =SUM(J58:J61) -> 3.6666667 | ... AB22: =SUM(N58:N61) -> 3372.3333
B23: 09.15 - 09.30 | C23: 42.666667 | D23: 20 | E23: 124.33333 | F23: 0 | G23: 0 | H23: 8.6666667 | I23: 9 | J23: 0.33333333 | K23: 1 | L23: 491 | M23: =SUM(C23:K23) -> 206 | N23: =SUM(C23:L23) -> 697 | P23: AM Peak Hr | Q23: =MAX(Q10:Q13) -> 227 | R23: =MAX(R10:R13) -> 98.333333 | S23: =MAX(S10:S13) -> 532 | T23: =MAX(T10:T13) -> 11.333333 | U23: =MAX(U10:U13) -> 14 | V23: =MAX(V10:V13) -> 36.333333 | W23: =MAX(W10:W13) -> 32.666667 | X23: =MAX(X10:X13) -> 7.3333333 | ... AB23: =MAX(AB10:AB13) -> 2758
B24: 09.30 - 09.45 | C24: 50.333333 | D24: 25.333333 | E24: 129 | F24: 0.66666667 | G24: 0.33333333 | H24: 12.666667 | I24: 7.6666667 | J24: 0.33333333 | K24: 1 | L24: 437.66667 | M24: =SUM(C24:K24) -> 227.33333 | N24: =SUM(C24:L24) -> 665 | P24: IP Peak Hr | Q24: =MAX(Q14:Q19) -> 362 | R24: =MAX(R14:R19) -> 194 | S24: =MAX(S14:S19) -> 498.33333 | T24: =MAX(T14:T19) -> 96.333333 | U24: =MAX(U14:U19) -> 2 | V24: =MAX(V14:V19) -> 57 | W24: =MAX(W14:W19) -> 34.666667 | X24: =MAX(X14:X19) -> 7 | ... AB24: =MAX(AB14:AB19) -> 2843
B25: 09.45 - 10.00 | C25: 49 | D25: 25 | E25: 121 | F25: 0.33333333 | G25: 0.66666667 | H25: 10 | I25: 8.6666667 | J25: 0.33333333 | K25: 0.66666667 | L25: 462 | M25: =SUM(C25:K25) -> 215.66667 | N25: =SUM(C25:L25) -> 677.66667 | P25: PM Peak Hr | Q25: =MAX(Q20:Q22) -> 522.66667 | R25: =MAX(R20:R22) -> 253.33333 | S25: =MAX(S20:S22) -> 374 | T25: =MAX(T20:T22) -> 207 | U25: =MAX(U20:U22) -> 7.3333333 | V25: =MAX(V20:V22) -> 37.333333 | W25: =MAX(W20:W22) -> 19.333333 | X25: =MAX(X20:X22) -> 4.6666667 | ... AB25: =MAX(AB20:AB22) -> 3372.3333
B26: 10.00 - 10.15 | C26: 65 | D26: 26.666667 | E26: 133.66667 | F26: 0 | G26: 0 | H26: 10.333333 | I26: 8 | J26: 2.3333333 | K26: 1.3333333 | L26: 440.66667 | M26: =SUM(C26:K26) -> 247.33333 | N26: =SUM(C26:L26) -> 688 | P26: AM Period | Q26: =SUM(Q10:Q13) -> 758.33333 | R26: =SUM(R10:R13) -> 362 | S26: =SUM(S10:S13) -> 1954 | T26: =SUM(T10:T13) -> 23.333333 | U26: =SUM(U10:U13) -> 22 | V26: =SUM(V10:V13) -> 96.333333 | W26: =SUM(W10:W13) -> 88.333333 | X26: =SUM(X10:X13) -> 18 | ... AB26: =SUM(AB10:AB13) -> 8514.3333
B27: 10.15 - 10.30 | C27: 52.666667 | D27: 33 | E27: 145 | F27: 0.33333333 | G27: 1 | H27: 12.333333 | I27: 10.666667 | J27: 2.6666667 | K27: 2.6666667 | L27: 448.66667 | M27: =SUM(C27:K27) -> 260.33333 | N27: =SUM(C27:L27) -> 709 | P27: IP Period | Q27: =SUM(Q14:Q19) -> 1818.6667 | R27: =SUM(R14:R19) -> 1011.6667 | S27: =SUM(S14:S19) -> 2227.3333 | T27: =SUM(T14:T19) -> 199 | U27: =SUM(U14:U19) -> 5.3333333 | V27: =SUM(V14:V19) -> 289.66667 | W27: =SUM(W14:W19) -> 174 | X27: =SUM(X14:X19) -> 33.333333 | ... AB27: =SUM(AB14:AB19) -> 16438
B28: 10.30 - 10.45 | C28: 64.333333 | D28: 35 | E28: 115.33333 | F28: 0 | G28: 0.66666667 | H28: 12.333333 | I28: 8.3333333 | J28: 0.33333333 | K28: 0 | L28: 466 | M28: =SUM(C28:K28) -> 236.33333 | N28: =SUM(C28:L28) -> 702.33333 | P28: PM Period | Q28: =SUM(Q20:Q22) -> 1459 | R28: =SUM(R20:R22) -> 717.66667 | S28: =SUM(S20:S22) -> 1007.3333 | T28: =SUM(T20:T22) -> 450 | U28: =SUM(U20:U22) -> 13.333333 | V28: =SUM(V20:V22) -> 87.666667 | W28: =SUM(W20:W22) -> 48 | X28: =SUM(X20:X22) -> 11.333333 | ... AB28: =SUM(AB20:AB22) -> 9788.6667
B29: 10.45 - 11.00 | C29: 61.666667 | D29: 33.666667 | E29: 104.33333 | F29: 0.33333333 | G29: 0.33333333 | H29: 10 | I29: 7.6666667 | J29: 1.6666667 | K29: 1.3333333 | L29: 474 | M29: =SUM(C29:K29) -> 221 | N29: =SUM(C29:L29) -> 695 | P29: 12 Hours | Q29: =SUM(Q11:Q22) -> 3878.6667 | R29: =SUM(R11:R22) -> 2021.3333 | S29: =SUM(S11:S22) -> 4792 | T29: =SUM(T11:T22) -> 666.66667 | U29: =SUM(U11:U22) -> 36.333333 | V29: =SUM(V11:V22) -> 455 | W29: =SUM(W11:W22) -> 288.66667 | X29: =SUM(X11:X22) -> 57 | ... AB29: =SUM(AB11:AB22) -> 33487.667
B30: 11.00 - 11.15 | C30: 71.666667 | D30: 36.666667 | E30: 106.33333 | F30: 0.33333333 | G30: 0 | H30: 13.666667 | I30: 4.6666667 | J30: 1 | K30: 1.6666667 | L30: 465.33333 | M30: =SUM(C30:K30) -> 236 | N30: =SUM(C30:L30) -> 701.33333
B31: 11.15 - 11.30 | C31: 61.666667 | D31: 40.333333 | E31: 88.333333 | F31: 0.66666667 | G31: 0 | H31: 12.666667 | I31: 8.6666667 | J31: 0.33333333 | K31: 2 | L31: 472.33333 | M31: =SUM(C31:K31) -> 214.66667 | N31: =SUM(C31:L31) -> 687
B32: 11.30 - 11.45 | C32: 52.333333 | D32: 36.666667 | E32: 87.333333 | F32: 0.66666667 | G32: 0 | H32: 10 | I32: 9.3333333 | J32: 1.6666667 | K32: 0.66666667 | L32: 465 | M32: =SUM(C32:K32) -> 198.66667 | N32: =SUM(C32:L32) -> 663.66667
B33: 11.45 - 12.00 | C33: 80.333333 | D33: 45.666667 | E33: 109 | F33: 0.66666667 | G33: 0.33333333 | H33: 16.666667 | I33: 3.6666667 | J33: 1.3333333 | K33: 0.66666667 | L33: 497.33333 | M33: =SUM(C33:K33) -> 258.33333 | N33: =SUM(C33:L33) -> 755.66667
B34: 12.00 - 12.15 | C34: 69.666667 | D34: 44.333333 | E34: 106 | F34: 0.33333333 | G34: 0 | H34: 15.666667 | I34: 9.6666667 | J34: 2 | K34: 0.33333333 | L34: 473 | M34: =SUM(C34:K34) -> 248 | N34: =SUM(C34:L34) -> 721
B35: 12.15 - 12.30 | C35: 74 | D35: 44.666667 | E35: 86.666667 | F35: 1 | G35: 0 | H35: 11.666667 | I35: 6 | J35: 2.6666667 | K35: 0 | L35: 395 | M35: =SUM(C35:K35) -> 226.66667 | N35: =SUM(C35:L35) -> 621.66667
B36: 12.30 - 12.45 | C36: 75.666667 | D36: 33.333333 | E36: 88.666667 | F36: 0 | G36: 0 | H36: 13 | I36: 8 | J36: 0 | K36: 0.66666667 | L36: 392.66667 | M36: =SUM(C36:K36) -> 219.33333 | N36: =SUM(C36:L36) -> 612
B37: 12.45 - 13.00 | C37: 82 | D37: 50.333333 | E37: 88.333333 | F37: 1.3333333 | G37: 0 | H37: 11 | I37: 7.3333333 | J37: 1.3333333 | K37: 2 | L37: 395.33333 | M37: =SUM(C37:K37) -> 243.66667 | N37: =SUM(C37:L37) -> 639
B38: 13.00 - 13.15 | C38: 80.666667 | D38: 42.666667 | E38: 80 | F38: 0.66666667 | G38: 0 | H38: 15 | I38: 9 | J38: 1.3333333 | K38: 1.6666667 | L38: 445 | M38: =SUM(C38:K38) -> 231 | N38: =SUM(C38:L38) -> 676
B39: 13.15 - 13.30 | C39: 70 | D39: 37 | E39: 88.666667 | F39: 0 | G39: 0 | H39: 14.333333 | I39: 8.6666667 | J39: 1.6666667 | K39: 4 | L39: 463.66667 | M39: =SUM(C39:K39) -> 224.33333 | N39: =SUM(C39:L39) -> 688
B40: 13.30 - 13.45 | C40: 92.666667 | D40: 46.666667 | E40: 95.333333 | F40: 0 | G40: 0.66666667 | H40: 14 | I40: 6.6666667 | J40: 0.33333333 | K40: 1.6666667 | L40: 448 | M40: =SUM(C40:K40) -> 258 | N40: =SUM(C40:L40) -> 706
B41: 13.45 - 14.00 | C41: 78 | D41: 41.333333 | E41: 105.33333 | F41: 1 | G41: 1 | H41: 13.666667 | I41: 8.3333333 | J41: 0.33333333 | K41: 1.3333333 | L41: 445.66667 | M41: =SUM(C41:K41) -> 250.33333 | N41: =SUM(C41:L41) -> 696
... B61: 18.45 - 19.00 | C61: 139.33333 | D61: 72.666667 | E61: 106 | F61: 50.666667 | G61: 3.3333333 | H61: 3 | I61: 2 | J61: 0.33333333 | K61: 0.33333333 | L61: 487.33333 | M61: =SUM(C61:K61) -> 377.66667 | N61: =SUM(C61:L61) -> 865
...

Sheet Kibuye-Katwe
B1: Traffic Impact Assessment for Kikapu project
B2: MANUAL CLASSIFIED COUNT (MCC)
B3: ROAD NAME: | C3: KIBUYE JUNCTION (RBT)
C5: Date | D5: AVERAGE | E5: Location | F5: KIBUYE ROUNDABOUT | I5: Surveyor | J5: EO
C6: Dir. From | D6: kibuye | E6: Dir. To | F6: Katwe | I6: Supervisor | J6: IO
B8: Time / Veh Type | P8: SUMMARY TRAFFIC VOLUMES
C9: 1. Private Car | D9: 3. Pickups/four wheel drive | E9: 4. Minibus, matatu | F9: 5. Medium bus/ coaster | G9: 6. Large Bus/coach | H9: 7. Light Truck | I9: 8. Medium Truck | J9: 9. Heavy truck | K9: 10. Truck Trailer | L9: 11. Motor cycles | M9: Total Excl M/Cycles | N9: Total All | P9: Time | Q9: 1. Car | R9: 3. Pickups | S9: 4. Minibus, matatu | T9: 5. Medium bus | U9: 6. Large Bus | V9: 7. Light Truck | W9: 8. Medium Truck | X9: 9. Heavy truck | Y9: 10. Truck Trailer | Z9: 11. Motorcycles | AA9: Total Excl M/ Cycles | AB9: Total All
B10: 06.00 - 06.15 | C10: 62.333333 | D10: 29.666667 | E10: 75.333333 | F10: 1 | G10: 0 | H10: 1.3333333 | I10: 4 | J10: 1 | K10: 0.33333333 | L10: 145.33333 | M10: =SUM(C10:K10) -> 175 | N10: =SUM(C10:L10) -> 320.33333 | P10: 06.00 - 06.15 | Q10: =SUM(C10:C13) -> 471 | R10: =SUM(D10:D13) -> 195.33333 | S10: =SUM(E10:E13) -> 555.33333 | T10: =SUM(F10:F13) -> 3 | U10: =SUM(G10:G13) -> 0.66666667 | V10: =SUM(H10:H13) -> 15.333333 | W10: =SUM(I10:I13) -> 19.333333 | X10: =SUM(J10:J13) -> 7.6666667 | ... AB10: =SUM(N10:N13) -> 2035
B11: 06.15 - 06.30 | C11: 95.333333 | D11: 50.666667 | E11: 147 | F11: 1.3333333 | G11: 0 | H11: 4.3333333 | I11: 5.3333333 | J11: 3 | K11: 2 | L11: 190.66667 | M11: =SUM(C11:K11) -> 309 | N11: =SUM(C11:L11) -> 499.66667 | P11: 0700-0800 | Q11: =SUM(C14:C17) -> 634.66667 | R11: =SUM(D14:D17) -> 168.66667 | S11: =SUM(E14:E17) -> 609 | T11: =SUM(F14:F17) -> 5.3333333 | U11: =SUM(G14:G17) -> 3 | V11: =SUM(H14:H17) -> 12 | W11: =SUM(I14:I17) -> 7.3333333 | X11: =SUM(J14:J17) -> 4.3333333 | ... AB11: =SUM(N14:N17) -> 2970.3333
B12: 06.30 - 06.45 | C12: 136.66667 | D12: 69.333333 | E12: 168 | F12: 0.66666667 | G12: 0.66666667 | H12: 5.3333333 | I12: 5.6666667 | J12: 2.3333333 | K12: 1.6666667 | L12: 211.66667 | M12: =SUM(C12:K12) -> 390.33333 | N12: =SUM(C12:L12) -> 602 | P12: 0800-0900 | Q12: =SUM(C18:C21) -> 473.33333 | R12: =SUM(D18:D21) -> 176 | S12: =SUM(E18:E21) -> 602 | T12: =SUM(F18:F21) -> 4.3333333 | U12: =SUM(G18:G21) -> 2.3333333 | V12: =SUM(H18:H21) -> 13.333333 | W12: =SUM(I18:I21) -> 8.3333333 | X12: =SUM(J18:J21) -> 4.6666667 | ... AB12: =SUM(N18:N21) -> 3385.6667
B13: 06.45 - 07.00 | C13: 176.66667 | D13: 45.666667 | E13: 165 | F13: 0 | G13: 0 | H13: 4.3333333 | I13: 4.3333333 | J13: 1.3333333 | K13: 1.6666667 | L13: 214 | M13: =SUM(C13:K13) -> 399 | N13: =SUM(C13:L13) -> 613 | P13: 0900-1000 | Q13: =SUM(C22:C25) -> 427 | R13: =SUM(D22:D25) -> 172 | S13: =SUM(E22:E25) -> 662.66667 | T13: =SUM(F22:F25) -> 0.33333333 | U13: =SUM(G22:G25) -> 1.3333333 | V13: =SUM(H22:H25) -> 19.333333 | W13: =SUM(I22:I25) -> 12.666667 | X13: =SUM(J22:J25) -> 5.3333333 | ... AB13: =SUM(N22:N25) -> 3442.3333
B14: 07.00 - 07.15 | C14: 158.66667 | D14: 17.666667 | E14: 142 | F14: 1.3333333 | G14: 0.66666667 | H14: 3 | I14: 1.6666667 | J14: 0.33333333 | K14: 1.3333333 | L14: 321.66667 | M14: =SUM(C14:K14) -> 326.66667 | N14: =SUM(C14:L14) -> 648.33333 | P14: 1000-1100 | Q14: =SUM(C26:C29) -> 479.66667 | R14: =SUM(D26:D29) -> 214.66667 | S14: =SUM(E26:E29) -> 674 | T14: =SUM(F26:F29) -> 1.3333333 | U14: =SUM(G26:G29) -> 2.6666667 | V14: =SUM(H26:H29) -> 8.6666667 | W14: =SUM(I26:I29) -> 20 | X14: =SUM(J26:J29) -> 5 | ... AB14: =SUM(N26:N29) -> 3424.3333
B15: 07.15 - 07.30 | C15: 166.66667 | D15: 50 | E15: 149.33333 | F15: 0.33333333 | G15: 2 | H15: 3.3333333 | I15: 2.3333333 | J15: 1 | K15: 1.3333333 | L15: 358.66667 | M15: =SUM(C15:K15) -> 376.33333 | N15: =SUM(C15:L15) -> 735 | P15: 1100-1200 | Q15: =SUM(C30:C33) -> 444 | R15: =SUM(D30:D33) -> 211.66667 | S15: =SUM(E30:E33) -> 671.33333 | T15: =SUM(F30:F33) -> 3 | U15: =SUM(G30:G33) -> 1.3333333 | V15: =SUM(H30:H33) -> 16.333333 | W15: =SUM(I30:I33) -> 15 | X15: =SUM(J30:J33) -> 9 | ... AB15: =SUM(N30:N33) -> 2872.3333
B16: 07.30 - 07.45 | C16: 164.33333 | D16: 52.333333 | E16: 157.33333 | F16: 2 | G16: 0 | H16: 3.3333333 | I16: 2.6666667 | J16: 2.3333333 | K16: 1.3333333 | L16: 394.33333 | M16: =SUM(C16:K16) -> 385.66667 | N16: =SUM(C16:L16) -> 780 | P16: 1200-1300 | Q16: =SUM(C34:C37) -> 344.66667 | R16: =SUM(D34:D37) -> 176.66667 | S16: =SUM(E34:E37) -> 559 | T16: =SUM(F34:F37) -> 2 | U16: =SUM(G34:G37) -> 0.66666667 | V16: =SUM(H34:H37) -> 20 | W16: =SUM(I34:I37) -> 20 | X16: =SUM(J34:J37) -> 6.3333333 | ... AB16: =SUM(N34:N37) -> 2481.6667
B17: 07.45 - 08.00 | C17: 145 | D17: 48.666667 | E17: 160.33333 | F17: 1.6666667 | G17: 0.33333333 | H17: 2.3333333 | I17: 0.66666667 | J17: 0.66666667 | K17: 0.66666667 | L17: 446.66667 | M17: =SUM(C17:K17) -> 360.33333 | N17: =SUM(C17:L17) -> 807 | P17: 1300-1400 | Q17: =SUM(C38:C41) -> 345.33333 | R17: =SUM(D38:D41) -> 180.66667 | S17: =SUM(E38:E41) -> 522.66667 | T17: =SUM(F38:F41) -> 1.3333333 | U17: =SUM(G38:G41) -> 0 | V17: =SUM(H38:H41) -> 16.333333 | W17: =SUM(I38:I41) -> 32 | X17: =SUM(J38:J41) -> 6.6666667 | ... AB17: =SUM(N38:N41) -> 2260.6667
B18: 08.00 - 08.15 | C18: 126.66667 | D18: 44.666667 | E18: 141 | F18: 1 | G18: 0.66666667 | H18: 5.3333333 | I18: 1.6666667 | J18: 0.66666667 | K18: 0.33333333 | L18: 512.33333 | M18: =SUM(C18:K18) -> 322 | N18: =SUM(C18:L18) -> 834.33333 | P18: 1400-1500 | Q18: =SUM(C42:C45) -> 276.66667 | R18: =SUM(D42:D45) -> 195.66667 | S18: =SUM(E42:E45) -> 354.66667 | T18: =SUM(F42:F45) -> 1.6666667 | U18: =SUM(G42:G45) -> 1 | V18: =SUM(H42:H45) -> 20.333333 | W18: =SUM(I42:I45) -> 21.666667 | X18: =SUM(J42:J45) -> 11 | ... AB18: =SUM(N42:N45) -> 2291.6667
B19: 08.15 - 08.30 | C19: 149.33333 | D19: 48.333333 | E19: 166 | F19: 1 | G19: 0.66666667 | H19: 4.3333333 | I19: 4 | J19: 1.3333333 | K19: 0.33333333 | L19: 547 | M19: =SUM(C19:K19) -> 375.33333 | N19: =SUM(C19:L19) -> 922.33333 | P19: 1500-1600 | Q19: =SUM(C46:C49) -> 263.66667 | R19: =SUM(D46:D49) -> 190 | S19: =SUM(E46:E49) -> 436.66667 | T19: =SUM(F46:F49) -> 1 | U19: =SUM(G46:G49) -> 1 | V19: =SUM(H46:H49) -> 21.333333 | W19: =SUM(I46:I49) -> 18.333333 | X19: =SUM(J46:J49) -> 5.6666667 | ... AB19: =SUM(N46:N49) -> 2813.6667
B20: 08.30 - 08.45 | C20: 110.33333 | D20: 41.333333 | E20: 159 | F20: 2 | G20: 0.33333333 | H20: 2 | I20: 1 | J20: 1.6666667 | K20: 0.66666667 | L20: 507.33333 | M20: =SUM(C20:K20) -> 318.33333 | N20: =SUM(C20:L20) -> 825.66667 | P20: 1600-1700 | Q20: =SUM(C50:C53) -> 229.33333 | R20: =SUM(D50:D53) -> 171 | S20: =SUM(E50:E53) -> 445.33333 | T20: =SUM(F50:F53) -> 3 | U20: =SUM(G50:G53) -> 1.6666667 | V20: =SUM(H50:H53) -> 10 | W20: =SUM(I50:I53) -> 18.333333 | X20: =SUM(J50:J53) -> 10 | ... AB20: =SUM(N50:N53) -> 2907.6667
B21: 08.45 - 9.00 | C21: 87 | D21: 41.666667 | E21: 136 | F21: 0.33333333 | G21: 0.66666667 | H21: 1.6666667 | I21: 1.6666667 | J21: 1 | K21: 0.66666667 | L21: 532.66667 | M21: =SUM(C21:K21) -> 270.66667 | N21: =SUM(C21:L21) -> 803.33333 | P21: 1700-1800 | Q21: =SUM(C54:C57) -> 182 | R21: =SUM(D54:D57) -> 118.33333 | S21: =SUM(E54:E57) -> 331.33333 | T21: =SUM(F54:F57) -> 2.3333333 | U21: =SUM(G54:G57) -> 2.3333333 | V21: =SUM(H54:H57) -> 13 | W21: =SUM(I54:I57) -> 21 | X21: =SUM(J54:J57) -> 4 | ... AB21: =SUM(N54:N57) -> 2572.3333
B22: 09.00 - 09.15 | C22: 111.33333 | D22: 53.333333 | E22: 172 | F22: 0.33333333 | G22: 0 | H22: 2.6666667 | I22: 3.3333333 | J22: 1.3333333 | K22: 0.33333333 | L22: 569 | M22: =SUM(C22:K22) -> 344.66667 | N22: =SUM(C22:L22) -> 913.66667 | P22: 1800-1900 | Q22: =SUM(C58:C61) -> 165.33333 | R22: =SUM(D58:D61) -> 88.333333 | S22: =SUM(E58:E61) -> 369.33333 | T22: =SUM(F58:F61) -> 3.3333333 | U22: =SUM(G58:G61) -> 5 | V22: =SUM(H58:H61) -> 12.333333 | W22: =SUM(I58:I61) -> 10.333333 | X22: =SUM(J58:J61) -> 4.6666667 | ... AB22: =SUM(N58:N61) -> 2493
B23: 09.15 - 09.30 | C23: 103 | D23: 32.666667 | E23: 157.33333 | F23: 0 | G23: 0.33333333 | H23: 5.6666667 | I23: 1.3333333 | J23: 0.33333333 | K23: 0.33333333 | L23: 495 | M23: =SUM(C23:K23) -> 301 | N23: =SUM(C23:L23) -> 796 | P23: AM Peak Hr | Q23: =MAX(Q10:Q13) -> 634.66667 | R23: =MAX(R10:R13) -> 195.33333 | S23: =MAX(S10:S13) -> 662.66667 | T23: =MAX(T10:T13) -> 5.3333333 | U23: =MAX(U10:U13) -> 3 | V23: =MAX(V10:V13) -> 19.333333 | W23: =MAX(W10:W13) -> 19.333333 | X23: =MAX(X10:X13) -> 7.6666667 | ... AB23: =MAX(AB10:AB13) -> 3442.3333
B24: 09.30 - 09.45 | C24: 99.333333 | D24: 39.666667 | E24: 151.66667 | F24: 0 | G24: 0.66666667 | H24: 4.3333333 | I24: 3.6666667 | J24: 1.6666667 | K24: 2 | L24: 543.33333 | M24: =SUM(C24:K24) -> 303 | N24: =SUM(C24:L24) -> 846.33333 | P24: IP Peak Hr | Q24: =MAX(Q14:Q19) -> 479.66667 | R24: =MAX(R14:R19) -> 214.66667 | S24: =MAX(S14:S19) -> 674 | T24: =MAX(T14:T19) -> 3 | U24: =MAX(U14:U19) -> 2.6666667 | V24: =MAX(V14:V19) -> 21.333333 | W24: =MAX(W14:W19) -> 32 | X24: =MAX(X14:X19) -> 11 | ... AB24: =MAX(AB14:AB19) -> 3424.3333
B25: 09.45 - 10.00 | C25: 113.33333 | D25: 46.333333 | E25: 181.66667 | F25: 0 | G25: 0.33333333 | H25: 6.6666667 | I25: 4.3333333 | J25: 2 | K25: 1.6666667 | L25: 530 | M25: =SUM(C25:K25) -> 356.33333 | N25: =SUM(C25:L25) -> 886.33333 | P25: PM Peak Hr | Q25: =MAX(Q20:Q22) -> 229.33333 | R25: =MAX(R20:R22) -> 171 | S25: =MAX(S20:S22) -> 445.33333 | T25: =MAX(T20:T22) -> 3.3333333 | U25: =MAX(U20:U22) -> 5 | V25: =MAX(V20:V22) -> 13 | W25: =MAX(W20:W22) -> 21 | X25: =MAX(X20:X22) -> 10 | ... AB25: =MAX(AB20:AB22) -> 2907.6667
B26: 10.00 - 10.15 | C26: 136 | D26: 41.666667 | E26: 131.66667 | F26: 0 | G26: 0.66666667 | H26: 2.6666667 | I26: 6 | J26: 1.6666667 | K26: 1.3333333 | L26: 564.66667 | M26: =SUM(C26:K26) -> 321.66667 | N26: =SUM(C26:L26) -> 886.33333 | P26: AM Period | Q26: =SUM(Q10:Q13) -> 2006 | R26: =SUM(R10:R13) -> 712 | S26: =SUM(S10:S13) -> 2429 | T26: =SUM(T10:T13) -> 13 | U26: =SUM(U10:U13) -> 7.3333333 | V26: =SUM(V10:V13) -> 60 | W26: =SUM(W10:W13) -> 47.666667 | X26: =SUM(X10:X13) -> 22 | ... AB26: =SUM(AB10:AB13) -> 11833.333
B27: 10.15 - 10.30 | C27: 110.33333 | D27: 51.666667 | E27: 170 | F27: 0.33333333 | G27: 1 | H27: 1.6666667 | I27: 4 | J27: 1.3333333 | K27: 1.3333333 | L27: 488.33333 | M27: =SUM(C27:K27) -> 341.66667 | N27: =SUM(C27:L27) -> 830 | P27: IP Period | Q27: =SUM(Q14:Q19) -> 2154 | R27: =SUM(R14:R19) -> 1169.3333 | S27: =SUM(S14:S19) -> 3218.3333 | T27: =SUM(T14:T19) -> 10.333333 | U27: =SUM(U14:U19) -> 6.6666667 | V27: =SUM(V14:V19) -> 103 | W27: =SUM(W14:W19) -> 127 | X27: =SUM(X14:X19) -> 43.666667 | ... AB27: =SUM(AB14:AB19) -> 16144.333
B28: 10.30 - 10.45 | C28: 113 | D28: 56.333333 | E28: 186 | F28: 0.33333333 | G28: 0.66666667 | H28: 3.3333333 | I28: 6.6666667 | J28: 1 | K28: 2 | L28: 495.33333 | M28: =SUM(C28:K28) -> 369.33333 | N28: =SUM(C28:L28) -> 864.66667 | P28: PM Period | Q28: =SUM(Q20:Q22) -> 576.66667 | R28: =SUM(R20:R22) -> 377.66667 | S28: =SUM(S20:S22) -> 1146 | T28: =SUM(T20:T22) -> 8.6666667 | U28: =SUM(U20:U22) -> 9 | V28: =SUM(V20:V22) -> 35.333333 | W28: =SUM(W20:W22) -> 49.666667 | X28: =SUM(X20:X22) -> 18.666667 | ... AB28: =SUM(AB20:AB22) -> 7973
B29: 10.45 - 11.00 | C29: 120.33333 | D29: 65 | E29: 186.33333 | F29: 0.66666667 | G29: 0.33333333 | H29: 1 | I29: 3.3333333 | J29: 1 | K29: 1 | L29: 464.33333 | M29: =SUM(C29:K29) -> 379 | N29: =SUM(C29:L29) -> 843.33333 | P29: 12 Hours | Q29: =SUM(Q11:Q22) -> 4265.6667 | R29: =SUM(R11:R22) -> 2063.6667 | S29: =SUM(S11:S22) -> 6238 | T29: =SUM(T11:T22) -> 29 | U29: =SUM(U11:U22) -> 22.333333 | V29: =SUM(V11:V22) -> 183 | W29: =SUM(W11:W22) -> 205 | X29: =SUM(X11:X22) -> 76.666667 | ... AB29: =SUM(AB11:AB22) -> 33915.667
B30: 11.00 - 11.15 | C30: 118.66667 | D30: 56.333333 | E30: 163.33333 | F30: 1 | G30: 1 | H30: 3 | I30: 3.6666667 | J30: 2 | K30: 1.3333333 | L30: 344.33333 | M30: =SUM(C30:K30) -> 350.33333 | N30: =SUM(C30:L30) -> 694.66667
B31: 11.15 - 11.30 | C31: 115 | D31: 64.666667 | E31: 174.66667 | F31: 1 | G31: 0.33333333 | H31: 5.3333333 | I31: 5 | J31: 2.3333333 | K31: 0.33333333 | L31: 390.66667 | M31: =SUM(C31:K31) -> 368.66667 | N31: =SUM(C31:L31) -> 759.33333
B32: 11.30 - 11.45 | C32: 97.333333 | D32: 45.333333 | E32: 187.66667 | F32: 1 | G32: 0 | H32: 5 | I32: 3 | J32: 3.3333333 | K32: 1.6666667 | L32: 400 | M32: =SUM(C32:K32) -> 344.33333 | N32: =SUM(C32:L32) -> 744.33333
B33: 11.45 - 12.00 | C33: 113 | D33: 45.333333 | E33: 145.66667 | F33: 0 | G33: 0 | H33: 3 | I33: 3.3333333 | J33: 1.3333333 | K33: 3 | L33: 359.33333 | M33: =SUM(C33:K33) -> 314.66667 | N33: =SUM(C33:L33) -> 674
B34: 12.00 - 12.15 | C34: 73.333333 | D34: 48 | E34: 135 | F34: 0.66666667 | G34: 0.66666667 | H34: 5 | I34: 5.3333333 | J34: 1.6666667 | K34: 0.66666667 | L34: 342.33333 | M34: =SUM(C34:K34) -> 270.33333 | N34: =SUM(C34:L34) -> 612.66667
B35: 12.15 - 12.30 | C35: 104 | D35: 47.666667 | E35: 147.33333 | F35: 0.33333333 | G35: 0 | H35: 7.6666667 | I35: 6 | J35: 1.3333333 | K35: 1 | L35: 366.66667 | M35: =SUM(C35:K35) -> 315.33333 | N35: =SUM(C35:L35) -> 682
B36: 12.30 - 12.45 | C36: 72.333333 | D36: 37.333333 | E36: 143.33333 | F36: 0.66666667 | G36: 0 | H36: 4 | I36: 6 | J36: 1 | K36: 2.6666667 | L36: 288.33333 | M36: =SUM(C36:K36) -> 267.33333 | N36: =SUM(C36:L36) -> 555.66667
B37: 12.45 - 13.00 | C37: 95 | D37: 43.666667 | E37: 133.33333 | F37: 0.33333333 | G37: 0 | H37: 3.3333333 | I37: 2.6666667 | J37: 2.3333333 | K37: 4 | L37: 346.66667 | M37: =SUM(C37:K37) -> 284.66667 | N37: =SUM(C37:L37) -> 631.33333
B38: 13.00 - 13.15 | C38: 86 | D38: 40.666667 | E38: 132.66667 | F38: 0.66666667 | G38: 0 | H38: 6.6666667 | I38: 9 | J38: 2.3333333 | K38: 3 | L38: 296.66667 | M38: =SUM(C38:K38) -> 281 | N38: =SUM(C38:L38) -> 577.66667
B39: 13.15 - 13.30 | C39: 77.666667 | D39: 50.666667 | E39: 135.66667 | F39: 0 | G39: 0 | H39: 3.3333333 | I39: 8 | J39: 0.33333333 | K39: 2.3333333 | L39: 282.66667 | M39: =SUM(C39:K39) -> 278 | N39: =SUM(C39:L39) -> 560.66667
B40: 13.30 - 13.45 | C40: 86.666667 | D40: 38.333333 | E40: 117.66667 | F40: 0.66666667 | G40: 0 | H40: 3.3333333 | I40: 9 | J40: 1.3333333 | K40: 3 | L40: 285 | M40: =SUM(C40:K40) -> 260 | N40: =SUM(C40:L40) -> 545
B41: 13.45 - 14.00 | C41: 95 | D41: 51 | E41: 136.66667 | F41: 0 | G41: 0 | H41: 3 | I41: 6 | J41: 2.6666667 | K41: 1.3333333 | L41: 281.66667 | M41: =SUM(C41:K41) -> 295.66667 | N41: =SUM(C41:L41) -> 577.33333
... B61: 18.45 - 19.00 | C61: 49 | D61: 31 | E61: 106 | F61: 0.66666667 | G61: 0.66666667 | H61: 2.6666667 | I61: 2.3333333 | J61: 1.3333333 | K61: 0.66666667 | L61: 504.33333 | M61: =SUM(C61:K61) -> 194.33333 | N61: =SUM(C61:L61) -> 698.66667
...

Sheet Katwe-Kibuye
B1: Traffic Impact Assessment for Kikapu project
B2: MANUAL CLASSIFIED COUNT (MCC)
B3: ROAD NAME: | C3: KIBUYE JUNCTION (RBT)
C5: Date | D5: AVERAGE | E5: Location | F5: KIBUYE ROUNDABOUT | I5: Surveyor | J5: EO
C6: Dir. From | D6: Katwe | E6: Dir. To | F6: Kibuye | I6: Supervisor | J6: IO
B8: Time / Veh Type | P8: SUMMARY TRAFFIC VOLUMES
C9: 1. Private Car | D9: 3. Pickups/four wheel drive | E9: 4. Minibus, matatu | F9: 5. Medium bus/ coaster | G9: 6. Large Bus/coach | H9: 7. Light Truck | I9: 8. Medium Truck | J9: 9. Heavy truck | K9: 10. Truck Trailer | L9: 11. Motor cycles | M9: Total Excl M/Cycles | N9: Total All | P9: Time | Q9: 1. Car | R9: 3. Pickups | S9: 4. Minibus, matatu | T9: 5. Medium bus | U9: 6. Large Bus | V9: 7. Light Truck | W9: 8. Medium Truck | X9: 9. Heavy truck | Y9: 10. Truck Trailer | Z9: 11. Motorcycles | AA9: Total Excl M/ Cycles | AB9: Total All
B10: 06.00 - 06.15 | C10: 7 | D10: 2 | E10: 14.333333 | F10: 0.33333333 | G10: 0 | H10: 0.33333333 | I10: 0.33333333 | J10: 0 | K10: 0 | L10: 61 | M10: =SUM(C10:K10) -> 24.333333 | N10: =SUM(C10:L10) -> 85.333333 | P10: 06.00 - 06.15 | Q10: =SUM(C10:C13) -> 27.333333 | R10: =SUM(D10:D13) -> 23.333333 | S10: =SUM(E10:E13) -> 83 | T10: =SUM(F10:F13) -> 0.66666667 | U10: =SUM(G10:G13) -> 0.66666667 | V10: =SUM(H10:H13) -> 3.3333333 | W10: =SUM(I10:I13) -> 2.3333333 | X10: =SUM(J10:J13) -> 0 | ... AB10: =SUM(N10:N13) -> 566
B11: 06.15 - 06.30 | C11: 4 | D11: 3.3333333 | E11: 16.666667 | F11: 0.33333333 | G11: 0 | H11: 0.33333333 | I11: 1 | J11: 0 | K11: 0 | L11: 101.66667 | M11: =SUM(C11:K11) -> 25.666667 | N11: =SUM(C11:L11) -> 127.33333 | P11: 0700-0800 | Q11: =SUM(C14:C17) -> 34.666667 | R11: =SUM(D14:D17) -> 18.666667 | S11: =SUM(E14:E17) -> 177.33333 | T11: =SUM(F14:F17) -> 0.33333333 | U11: =SUM(G14:G17) -> 0 | V11: =SUM(H14:H17) -> 1.6666667 | W11: =SUM(I14:I17) -> 3.3333333 | X11: =SUM(J14:J17) -> 2.3333333 | ... AB11: =SUM(N14:N17) -> 1531.6667
B12: 06.30 - 06.45 | C12: 5.6666667 | D12: 8.3333333 | E12: 30 | F12: 0 | G12: 0.66666667 | H12: 1.3333333 | I12: 0.33333333 | J12: 0 | K12: 0 | L12: 110.33333 | M12: =SUM(C12:K12) -> 46.333333 | N12: =SUM(C12:L12) -> 156.66667 | P12: 0800-0900 | Q12: =SUM(C18:C21) -> 27.666667 | R12: =SUM(D18:D21) -> 21 | S12: =SUM(E18:E21) -> 243 | T12: =SUM(F18:F21) -> 1.3333333 | U12: =SUM(G18:G21) -> 0 | V12: =SUM(H18:H21) -> 5 | W12: =SUM(I18:I21) -> 4.6666667 | X12: =SUM(J18:J21) -> 1 | ... AB12: =SUM(N18:N21) -> 2160.3333
B13: 06.45 - 07.00 | C13: 10.666667 | D13: 9.6666667 | E13: 22 | F13: 0 | G13: 0 | H13: 1.3333333 | I13: 0.66666667 | J13: 0 | K13: 0 | L13: 152.33333 | M13: =SUM(C13:K13) -> 44.333333 | N13: =SUM(C13:L13) -> 196.66667 | P13: 0900-1000 | Q13: =SUM(C22:C25) -> 20 | R13: =SUM(D22:D25) -> 25.666667 | S13: =SUM(E22:E25) -> 187.33333 | T13: =SUM(F22:F25) -> 1 | U13: =SUM(G22:G25) -> 1.3333333 | V13: =SUM(H22:H25) -> 7.3333333 | W13: =SUM(I22:I25) -> 4 | X13: =SUM(J22:J25) -> 0.33333333 | ... AB13: =SUM(N22:N25) -> 2330
B14: 07.00 - 07.15 | C14: 9.6666667 | D14: 4.6666667 | E14: 40.333333 | F14: 0.33333333 | G14: 0 | H14: 0.33333333 | I14: 1 | J14: 0.33333333 | K14: 0 | L14: 234.33333 | M14: =SUM(C14:K14) -> 56.666667 | N14: =SUM(C14:L14) -> 291 | P14: 1000-1100 | Q14: =SUM(C26:C29) -> 19 | R14: =SUM(D26:D29) -> 24.333333 | S14: =SUM(E26:E29) -> 109.66667 | T14: =SUM(F26:F29) -> 3.6666667 | U14: =SUM(G26:G29) -> 0 | V14: =SUM(H26:H29) -> 8.3333333 | W14: =SUM(I26:I29) -> 4.3333333 | X14: =SUM(J26:J29) -> 3.3333333 | ... AB14: =SUM(N26:N29) -> 1684.3333
B15: 07.15 - 07.30 | C15: 10.333333 | D15: 5.3333333 | E15: 44 | F15: 0 | G15: 0 | H15: 0 | I15: 0.66666667 | J15: 0.66666667 | K15: 0 | L15: 323.33333 | M15: =SUM(C15:K15) -> 61 | N15: =SUM(C15:L15) -> 384.33333 | P15: 1100-1200 | Q15: =SUM(C30:C33) -> 32.666667 | R15: =SUM(D30:D33) -> 43 | S15: =SUM(E30:E33) -> 111 | T15: =SUM(F30:F33) -> 0.66666667 | U15: =SUM(G30:G33) -> 0 | V15: =SUM(H30:H33) -> 12.666667 | W15: =SUM(I30:I33) -> 2.6666667 | X15: =SUM(J30:J33) -> 3 | ... AB15: =SUM(N30:N33) -> 1177.3333
B16: 07.30 - 07.45 | C16: 9 | D16: 3.3333333 | E16: 44 | F16: 0 | G16: 0 | H16: 0.66666667 | I16: 0.66666667 | J16: 1.3333333 | K16: 0.66666667 | L16: 343.33333 | M16: =SUM(C16:K16) -> 59.666667 | N16: =SUM(C16:L16) -> 403 | P16: 1200-1300 | Q16: =SUM(C34:C37) -> 37.666667 | R16: =SUM(D34:D37) -> 47.333333 | S16: =SUM(E34:E37) -> 126.33333 | T16: =SUM(F34:F37) -> 0 | U16: =SUM(G34:G37) -> 0 | V16: =SUM(H34:H37) -> 9.3333333 | W16: =SUM(I34:I37) -> 3.6666667 | X16: =SUM(J34:J37) -> 5.3333333 | ... AB16: =SUM(N34:N37) -> 1110.6667
B17: 07.45 - 08.00 | C17: 5.6666667 | D17: 5.3333333 | E17: 49 | F17: 0 | G17: 0 | H17: 0.66666667 | I17: 1 | J17: 0 | K17: 0 | L17: 391.66667 | M17: =SUM(C17:K17) -> 61.666667 | N17: =SUM(C17:L17) -> 453.33333 | P17: 1300-1400 | Q17: =SUM(C38:C41) -> 43.666667 | R17: =SUM(D38:D41) -> 49.666667 | S17: =SUM(E38:E41) -> 140 | T17: =SUM(F38:F41) -> 0 | U17: =SUM(G38:G41) -> 0 | V17: =SUM(H38:H41) -> 11.333333 | W17: =SUM(I38:I41) -> 5 | X17: =SUM(J38:J41) -> 1.6666667 | ... AB17: =SUM(N38:N41) -> 1231
B18: 08.00 - 08.15 | C18: 5.6666667 | D18: 7.3333333 | E18: 59.666667 | F18: 0 | G18: 0 | H18: 1.6666667 | I18: 1 | J18: 0 | K18: 0 | L18: 415.66667 | M18: =SUM(C18:K18) -> 75.333333 | N18: =SUM(C18:L18) -> 491 | P18: 1400-1500 | Q18: =SUM(C42:C45) -> 63 | R18: =SUM(D42:D45) -> 26.333333 | S18: =SUM(E42:E45) -> 119.33333 | T18: =SUM(F42:F45) -> 0.33333333 | U18: =SUM(G42:G45) -> 0 | V18: =SUM(H42:H45) -> 17.666667 | W18: =SUM(I42:I45) -> 2 | X18: =SUM(J42:J45) -> 1 | ... AB18: =SUM(N42:N45) -> 1094.6667
B19: 08.15 - 08.30 | C19: 7.6666667 | D19: 2.3333333 | E19: 59 | F19: 0.66666667 | G19: 0 | H19: 1 | I19: 2.3333333 | J19: 0.33333333 | K19: 0 | L19: 418.33333 | M19: =SUM(C19:K19) -> 73.333333 | N19: =SUM(C19:L19) -> 491.66667 | P19: 1500-1600 | Q19: =SUM(C46:C49) -> 89 | R19: =SUM(D46:D49) -> 23.333333 | S19: =SUM(E46:E49) -> 146.33333 | T19: =SUM(F46:F49) -> 0.66666667 | U19: =SUM(G46:G49) -> 0 | V19: =SUM(H46:H49) -> 9.3333333 | W19: =SUM(I46:I49) -> 4 | X19: =SUM(J46:J49) -> 1 | ... AB19: =SUM(N46:N49) -> 1162.3333
B20: 08.30 - 08.45 | C20: 8 | D20: 7.3333333 | E20: 68.666667 | F20: 0.66666667 | G20: 0 | H20: 1.3333333 | I20: 0.66666667 | J20: 0 | K20: 0 | L20: 480.33333 | M20: =SUM(C20:K20) -> 86.666667 | N20: =SUM(C20:L20) -> 567 | P20: 1600-1700 | Q20: =SUM(C50:C53) -> 85.333333 | R20: =SUM(D50:D53) -> 30 | S20: =SUM(E50:E53) -> 137 | T20: =SUM(F50:F53) -> 0 | U20: =SUM(G50:G53) -> 0 | V20: =SUM(H50:H53) -> 5.6666667 | W20: =SUM(I50:I53) -> 2.6666667 | X20: =SUM(J50:J53) -> 0.33333333 | ... AB20: =SUM(N50:N53) -> 1172
B21: 08.45 - 9.00 | C21: 6.3333333 | D21: 4 | E21: 55.666667 | F21: 0 | G21: 0 | H21: 1 | I21: 0.66666667 | J21: 0.66666667 | K21: 0 | L21: 542.33333 | M21: =SUM(C21:K21) -> 68.333333 | N21: =SUM(C21:L21) -> 610.66667 | P21: 1700-1800 | Q21: =SUM(C54:C57) -> 92.333333 | R21: =SUM(D54:D57) -> 30.333333 | S21: =SUM(E54:E57) -> 152.66667 | T21: =SUM(F54:F57) -> 0 | U21: =SUM(G54:G57) -> 0 | V21: =SUM(H54:H57) -> 7.6666667 | W21: =SUM(I54:I57) -> 3.6666667 | X21: =SUM(J54:J57) -> 0.33333333 | ... AB21: =SUM(N54:N57) -> 1158
B22: 09.00 - 09.15 | C22: 6 | D22: 7.3333333 | E22: 58 | F22: 0.33333333 | G22: 0 | H22: 1.3333333 | I22: 1 | J22: 0 | K22: 0 | L22: 498 | M22: =SUM(C22:K22) -> 74 | N22: =SUM(C22:L22) -> 572 | P22: 1800-1900 | Q22: =SUM(C58:C61) -> 100.33333 | R22: =SUM(D58:D61) -> 35.333333 | S22: =SUM(E58:E61) -> 136.33333 | T22: =SUM(F58:F61) -> 0.33333333 | U22: =SUM(G58:G61) -> 0 | V22: =SUM(H58:H61) -> 12 | W22: =SUM(I58:I61) -> 2.6666667 | X22: =SUM(J58:J61) -> 0.33333333 | ... AB22: =SUM(N58:N61) -> 1160
B23: 09.15 - 09.30 | C23: 4 | D23: 5.6666667 | E23: 44 | F23: 0.66666667 | G23: 1 | H23: 1.6666667 | I23: 0.33333333 | J23: 0 | K23: 0 | L23: 524 | M23: =SUM(C23:K23) -> 57.333333 | N23: =SUM(C23:L23) -> 581.33333 | P23: AM Peak Hr | Q23: =MAX(Q10:Q13) -> 34.666667 | R23: =MAX(R10:R13) -> 25.666667 | S23: =MAX(S10:S13) -> 243 | T23: =MAX(T10:T13) -> 1.3333333 | U23: =MAX(U10:U13) -> 1.3333333 | V23: =MAX(V10:V13) -> 7.3333333 | W23: =MAX(W10:W13) -> 4.6666667 | X23: =MAX(X10:X13) -> 2.3333333 | ... AB23: =MAX(AB10:AB13) -> 2330
B24: 09.30 - 09.45 | C24: 6 | D24: 6 | E24: 44.333333 | F24: 0 | G24: 0.33333333 | H24: 2.6666667 | I24: 1.6666667 | J24: 0 | K24: 0 | L24: 560.66667 | M24: =SUM(C24:K24) -> 61 | N24: =SUM(C24:L24) -> 621.66667 | P24: IP Peak Hr | Q24: =MAX(Q14:Q19) -> 89 | R24: =MAX(R14:R19) -> 49.666667 | S24: =MAX(S14:S19) -> 146.33333 | T24: =MAX(T14:T19) -> 3.6666667 | U24: =MAX(U14:U19) -> 0 | V24: =MAX(V14:V19) -> 17.666667 | W24: =MAX(W14:W19) -> 5 | X24: =MAX(X14:X19) -> 5.3333333 | ... AB24: =MAX(AB14:AB19) -> 1684.3333
B25: 09.45 - 10.00 | C25: 4 | D25: 6.6666667 | E25: 41 | F25: 0 | G25: 0 | H25: 1.6666667 | I25: 1 | J25: 0.33333333 | K25: 0 | L25: 500.33333 | M25: =SUM(C25:K25) -> 54.666667 | N25: =SUM(C25:L25) -> 555 | P25: PM Peak Hr | Q25: =MAX(Q20:Q22) -> 100.33333 | R25: =MAX(R20:R22) -> 35.333333 | S25: =MAX(S20:S22) -> 152.66667 | T25: =MAX(T20:T22) -> 0.33333333 | U25: =MAX(U20:U22) -> 0 | V25: =MAX(V20:V22) -> 12 | W25: =MAX(W20:W22) -> 3.6666667 | X25: =MAX(X20:X22) -> 0.33333333 | ... AB25: =MAX(AB20:AB22) -> 1172
B26: 10.00 - 10.15 | C26: 4 | D26: 5.6666667 | E26: 27 | F26: 1.3333333 | G26: 0 | H26: 1.6666667 | I26: 1 | J26: 0.33333333 | K26: 0 | L26: 491 | M26: =SUM(C26:K26) -> 41 | N26: =SUM(C26:L26) -> 532 | P26: AM Period | Q26: =SUM(Q10:Q13) -> 109.66667 | R26: =SUM(R10:R13) -> 88.666667 | S26: =SUM(S10:S13) -> 690.66667 | T26: =SUM(T10:T13) -> 3.3333333 | U26: =SUM(U10:U13) -> 2 | V26: =SUM(V10:V13) -> 17.333333 | W26: =SUM(W10:W13) -> 14.333333 | X26: =SUM(X10:X13) -> 3.6666667 | ... AB26: =SUM(AB10:AB13) -> 6588
B27: 10.15 - 10.30 | C27: 2.6666667 | D27: 4.3333333 | E27: 20.666667 | F27: 1.6666667 | G27: 0 | H27: 0.33333333 | I27: 2.3333333 | J27: 1.6666667 | K27: 0.33333333 | L27: 518 | M27: =SUM(C27:K27) -> 34 | N27: =SUM(C27:L27) -> 552 | P27: IP Period | Q27: =SUM(Q14:Q19) -> 285 | R27: =SUM(R14:R19) -> 214 | S27: =SUM(S14:S19) -> 752.66667 | T27: =SUM(T14:T19) -> 5.3333333 | U27: =SUM(U14:U19) -> 0 | V27: =SUM(V14:V19) -> 68.666667 | W27: =SUM(W14:W19) -> 21.666667 | X27: =SUM(X14:X19) -> 15.333333 | ... AB27: =SUM(AB14:AB19) -> 7460.3333
B28: 10.30 - 10.45 | C28: 5.6666667 | D28: 6.6666667 | E28: 31.666667 | F28: 0.66666667 | G28: 0 | H28: 2.6666667 | I28: 0.66666667 | J28: 0.66666667 | K28: 0 | L28: 257.66667 | M28: =SUM(C28:K28) -> 48.666667 | N28: =SUM(C28:L28) -> 306.33333 | P28: PM Period | Q28: =SUM(Q20:Q22) -> 278 | R28: =SUM(R20:R22) -> 95.666667 | S28: =SUM(S20:S22) -> 426 | T28: =SUM(T20:T22) -> 0.33333333 | U28: =SUM(U20:U22) -> 0 | V28: =SUM(V20:V22) -> 25.333333 | W28: =SUM(W20:W22) -> 9 | X28: =SUM(X20:X22) -> 1 | ... AB28: =SUM(AB20:AB22) -> 3490
B29: 10.45 - 11.00 | C29: 6.6666667 | D29: 7.6666667 | E29: 30.333333 | F29: 0 | G29: 0 | H29: 3.6666667 | I29: 0.33333333 | J29: 0.66666667 | K29: 0 | L29: 244.66667 | M29: =SUM(C29:K29) -> 49.333333 | N29: =SUM(C29:L29) -> 294 | P29: 12 Hours | Q29: =SUM(Q11:Q22) -> 645.33333 | R29: =SUM(R11:R22) -> 375 | S29: =SUM(S11:S22) -> 1786.3333 | T29: =SUM(T11:T22) -> 8.3333333 | U29: =SUM(U11:U22) -> 1.3333333 | V29: =SUM(V11:V22) -> 108 | W29: =SUM(W11:W22) -> 42.666667 | X29: =SUM(X11:X22) -> 20 | ... AB29: =SUM(AB11:AB22) -> 16972.333
B30: 11.00 - 11.15 | C30: 8.3333333 | D30: 9 | E30: 27.666667 | F30: 0.33333333 | G30: 0 | H30: 2.3333333 | I30: 0.66666667 | J30: 1 | K30: 0 | L30: 282 | M30: =SUM(C30:K30) -> 49.333333 | N30: =SUM(C30:L30) -> 331.33333
B31: 11.15 - 11.30 | C31: 4.3333333 | D31: 7.3333333 | E31: 22 | F31: 0 | G31: 0 | H31: 3 | I31: 0.66666667 | J31: 0.33333333 | K31: 0 | L31: 231.33333 | M31: =SUM(C31:K31) -> 37.666667 | N31: =SUM(C31:L31) -> 269
B32: 11.30 - 11.45 | C32: 9.3333333 | D32: 12 | E32: 30.333333 | F32: 0 | G32: 0 | H32: 4.3333333 | I32: 0.33333333 | J32: 1.3333333 | K32: 0.33333333 | L32: 251 | M32: =SUM(C32:K32) -> 58 | N32: =SUM(C32:L32) -> 309
B33: 11.45 - 12.00 | C33: 10.666667 | D33: 14.666667 | E33: 31 | F33: 0.33333333 | G33: 0 | H33: 3 | I33: 1 | J33: 0.33333333 | K33: 0.33333333 | L33: 206.66667 | M33: =SUM(C33:K33) -> 61.333333 | N33: =SUM(C33:L33) -> 268
B34: 12.00 - 12.15 | C34: 11.333333 | D34: 13.333333 | E34: 32.333333 | F34: 0 | G34: 0 | H34: 4 | I34: 1.3333333 | J34: 2 | K34: 0.33333333 | L34: 220 | M34: =SUM(C34:K34) -> 64.666667 | N34: =SUM(C34:L34) -> 284.66667
B35: 12.15 - 12.30 | C35: 10 | D35: 11.333333 | E35: 36.666667 | F35: 0 | G35: 0 | H35: 1.3333333 | I35: 0.33333333 | J35: 0.66666667 | K35: 0 | L35: 220 | M35: =SUM(C35:K35) -> 60.333333 | N35: =SUM(C35:L35) -> 280.33333
B36: 12.30 - 12.45 | C36: 11.666667 | D36: 10 | E36: 25.333333 | F36: 0 | G36: 0 | H36: 2.6666667 | I36: 1.6666667 | J36: 1.6666667 | K36: 0 | L36: 254 | M36: =SUM(C36:K36) -> 53 | N36: =SUM(C36:L36) -> 307
B37: 12.45 - 13.00 | C37: 4.6666667 | D37: 12.666667 | E37: 32 | F37: 0 | G37: 0 | H37: 1.3333333 | I37: 0.33333333 | J37: 1 | K37: 0 | L37: 186.66667 | M37: =SUM(C37:K37) -> 52 | N37: =SUM(C37:L37) -> 238.66667
B38: 13.00 - 13.15 | C38: 13 | D38: 13.333333 | E38: 38.666667 | F38: 0 | G38: 0 | H38: 2.3333333 | I38: 2 | J38: 0.66666667 | K38: 0 | L38: 264.33333 | M38: =SUM(C38:K38) -> 70 | N38: =SUM(C38:L38) -> 334.33333
B39: 13.15 - 13.30 | C39: 9.6666667 | D39: 12.333333 | E39: 31.666667 | F39: 0 | G39: 0 | H39: 3 | I39: 1.6666667 | J39: 1 | K39: 0 | L39: 237.33333 | M39: =SUM(C39:K39) -> 59.333333 | N39: =SUM(C39:L39) -> 296.66667
B40: 13.30 - 13.45 | C40: 8.6666667 | D40: 13 | E40: 34 | F40: 0 | G40: 0 | H40: 2.6666667 | I40: 0.66666667 | J40: 0 | K40: 0 | L40: 214.66667 | M40: =SUM(C40:K40) -> 59 | N40: =SUM(C40:L40) -> 273.66667
B41: 13.45 - 14.00 | C41: 12.333333 | D41: 11 | E41: 35.666667 | F41: 0 | G41: 0 | H41: 3.3333333 | I41: 0.66666667 | J41: 0 | K41: 0 | L41: 263.33333 | M41: =SUM(C41:K41) -> 63 | N41: =SUM(C41:L41) -> 326.33333
... B61: 18.45 - 19.00 | C61: 29.666667 | D61: 6 | E61: 33.333333 | F61: 0 | G61: 0 | H61: 2 | I61: 0.33333333 | J61: 0 | K61: 0 | L61: 187.66667 | M61: =SUM(C61:K61) -> 71.333333 | N61: =SUM(C61:L61) -> 259
...

Sheet Makindye-kibuye
B1: Traffic Impact Assessment for Kikapu project
B2: MANUAL CLASSIFIED COUNT (MCC)
B3: ROAD NAME: | C3: KIBUYE JUNCTION (RBT)
C5: Date | D5: AVERAGE | E5: Location | F5: KIBUYE ROUNDABOUT | I5: Surveyor | J5: EO
C6: Dir. From | D6: makindye | E6: Dir. To | F6: KIBUYE | I6: Supervisor | J6: IO
B8: Time / Veh Type | P8: SUMMARY TRAFFIC VOLUMES
C9: 1. Private Car | D9: 3. Pickups/four wheel drive | E9: 4. Minibus, matatu | F9: 5. Medium bus/ coaster | G9: 6. Large Bus/coach | H9: 7. Light Truck | I9: 8. Medium Truck | J9: 9. Heavy truck | K9: 10. Truck Trailer | L9: 11. Motor cycles | M9: Total Excl M/Cycles | N9: Total All | P9: Time | Q9: 1. Car | R9: 3. Pickups | S9: 4. Minibus, matatu | T9: 5. Medium bus | U9: 6. Large Bus | V9: 7. Light Truck | W9: 8. Medium Truck | X9: 9. Heavy truck | Y9: 10. Truck Trailer | Z9: 11. Motorcycles | AA9: Total Excl M/ Cycles | AB9: Total All
