Workbook

Sheet 19.08 Sironko-Mbale
B1: Consultancy services for Preparation of Expressway Development Master Plan (EDMP) for Uganda
B2: MANUAL CLASSIFIED COUNT (MCC)
B3: ROAD NAME: | C3: MCC - C4 - STN120 - MBALE-SIRONKO ROAD
C5: Date | D5: 19.08.19 | F5: Location | G5: xxx | J5: Surveyor | K5: xxx
C6: Dir. From | D6: Sironko | F6: Dir. To | G6: Mbale | J6: Supervisor | K6: xxx
B8: Time / Veh Type | R8: SUMMARY TRAFFIC VOLUMES
C9: 1. Car | D9: 2. Station Wagon | E9: 3. Pickups | F9: 4. Minibus, matatu | G9: 5. Medium bus | H9: 6. Large Bus | I9: 7. Light Truck | J9: 8. Medium Truck | K9: 9. Heavy truck | L9: 10. Truck Trailer | M9: 11. Motor cycles | N9: 12. Tractors | O9: Total Excl M/Cycles | P9: Total All | R9: Time | S9: 1. Car | T9: 2. Station Wagon | U9: 3. Pickups | V9: 4. Minibus, matatu | W9: 5. Medium bus | X9: 6. Large Bus | Y9: 7. Light Truck | Z9: 8. Medium Truck | AA9: 9. Heavy truck | AB9: 10. Truck Trailer | AC9: 11. Motorcycles | AD9: 12. Tractors, Graders | AE9: Total Excl M/ Cycles | AF9: Total All
B10: 07.00 - 07.15 | C10: 0 | D10: 0 | E10: 0 | F10: 0 | G10: 0 | H10: 0 | I10: 0 | J10: 0 | K10: 0 | L10: 0 | M10: 0 | N10: 0 | O10: =SUM(C10:L10,N10) -> 0 | P10: =SUM(C10:N10) -> 0 | R10: 0700-0800 | S10: =SUM(C10:C13) -> 7 | T10: =SUM(D10:D13) -> 1 | U10: =SUM(E10:E13) -> 10 | V10: =SUM(F10:F13) -> 3 | W10: =SUM(G10:G13) -> 0 | X10: =SUM(H10:H13) -> 0 | Y10: =SUM(I10:I13) -> 9 | Z10: =SUM(J10:J13) -> 1 | ... AF10: =SUM(P10:P13) -> 74
B11: 07.15 - 07.30 | C11: 1 | D11: 0 | E11: 1 | F11: 1 | G11: 0 | H11: 0 | I11: 0 | J11: 0 | K11: 0 | L11: 0 | M11: 4 | N11: 0 | O11: =SUM(C11:L11,N11) -> 3 | P11: =SUM(C11:N11) -> 7 | R11: 0800-0900 | S11: =SUM(C14:C17) -> 18 | T11: =SUM(D14:D17) -> 6 | U11: =SUM(E14:E17) -> 28 | V11: =SUM(F14:F17) -> 11 | W11: =SUM(G14:G17) -> 0 | X11: =SUM(H14:H17) -> 0 | Y11: =SUM(I14:I17) -> 8 | Z11: =SUM(J14:J17) -> 0 | ... AF11: =SUM(P14:P17) -> 184
B12: 07.30 - 07.45 | C12: 4 | D12: 0 | E12: 3 | F12: 0 | G12: 0 | H12: 0 | I12: 7 | J12: 1 | K12: 0 | L12: 0 | M12: 5 | N12: 0 | O12: =SUM(C12:L12,N12) -> 15 | P12: =SUM(C12:N12) -> 20 | R12: 0900-1000 | S12: =SUM(C18:C21) -> 14 | T12: =SUM(D18:D21) -> 4 | U12: =SUM(E18:E21) -> 22 | V12: =SUM(F18:F21) -> 17 | W12: =SUM(G18:G21) -> 0 | X12: =SUM(H18:H21) -> 0 | Y12: =SUM(I18:I21) -> 10 | Z12: =SUM(J18:J21) -> 0 | ... AF12: =SUM(P18:P21) -> 195
B13: 07.45 - 08.00 | C13: 2 | D13: 1 | E13: 6 | F13: 2 | G13: 0 | H13: 0 | I13: 2 | J13: 0 | K13: 0 | L13: 0 | M13: 34 | N13: 0 | O13: =SUM(C13:L13,N13) -> 13 | P13: =SUM(C13:N13) -> 47 | R13: 1000-1100 | S13: =SUM(C22:C25) -> 17 | T13: =SUM(D22:D25) -> 6 | U13: =SUM(E22:E25) -> 26 | V13: =SUM(F22:F25) -> 16 | W13: =SUM(G22:G25) -> 0 | X13: =SUM(H22:H25) -> 0 | Y13: =SUM(I22:I25) -> 11 | Z13: =SUM(J22:J25) -> 0 | ... AF13: =SUM(P22:P25) -> 199
B14: 08.00 - 08.15 | C14: 8 | D14: 1 | E14: 6 | F14: 4 | G14: 0 | H14: 0 | I14: 1 | J14: 0 | K14: 0 | L14: 0 | M14: 30 | N14: 0 | O14: =SUM(C14:L14,N14) -> 20 | P14: =SUM(C14:N14) -> 50 | R14: 1100-1200 | S14: =SUM(C26:C29) -> 12 | T14: =SUM(D26:D29) -> 5 | U14: =SUM(E26:E29) -> 21 | V14: =SUM(F26:F29) -> 16 | W14: =SUM(G26:G29) -> 0 | X14: =SUM(H26:H29) -> 0 | Y14: =SUM(I26:I29) -> 5 | Z14: =SUM(J26:J29) -> 0 | ... AF14: =SUM(P26:P29) -> 183
B15: 08.15 - 08.30 | C15: 2 | D15: 3 | E15: 10 | F15: 1 | G15: 0 | H15: 0 | I15: 1 | J15: 0 | K15: 0 | L15: 0 | M15: 40 | N15: 0 | O15: =SUM(C15:L15,N15) -> 17 | P15: =SUM(C15:N15) -> 57 | R15: 1200-1300 | S15: =SUM(C30:C33) -> 11 | T15: =SUM(D30:D33) -> 3 | U15: =SUM(E30:E33) -> 15 | V15: =SUM(F30:F33) -> 16 | W15: =SUM(G30:G33) -> 0 | X15: =SUM(H30:H33) -> 0 | Y15: =SUM(I30:I33) -> 12 | Z15: =SUM(J30:J33) -> 1 | ... AF15: =SUM(P30:P33) -> 181
B16: 08.30 - 08.45 | C16: 5 | D16: 2 | E16: 9 | F16: 2 | G16: 0 | H16: 0 | I16: 4 | J16: 0 | K16: 0 | L16: 0 | M16: 19 | N16: 0 | O16: =SUM(C16:L16,N16) -> 22 | P16: =SUM(C16:N16) -> 41 | R16: 1300-1400 | S16: =SUM(C34:C37) -> 17 | T16: =SUM(D34:D37) -> 4 | U16: =SUM(E34:E37) -> 21 | V16: =SUM(F34:F37) -> 15 | W16: =SUM(G34:G37) -> 0 | X16: =SUM(H34:H37) -> 0 | Y16: =SUM(I34:I37) -> 13 | Z16: =SUM(J34:J37) -> 0 | ... AF16: =SUM(P34:P37) -> 205
B17: 08.45 - 9.00 | C17: 3 | D17: 0 | E17: 3 | F17: 4 | G17: 0 | H17: 0 | I17: 2 | J17: 0 | K17: 0 | L17: 0 | M17: 24 | N17: 0 | O17: =SUM(C17:L17,N17) -> 12 | P17: =SUM(C17:N17) -> 36 | R17: 1400-1500 | S17: =SUM(C38:C41) -> 10 | T17: =SUM(D38:D41) -> 4 | U17: =SUM(E38:E41) -> 21 | V17: =SUM(F38:F41) -> 15 | W17: =SUM(G38:G41) -> 0 | X17: =SUM(H38:H41) -> 0 | Y17: =SUM(I38:I41) -> 13 | Z17: =SUM(J38:J41) -> 0 | ... AF17: =SUM(P38:P41) -> 156
B18: 09.00 - 09.15 | C18: 3 | D18: 0 | E18: 3 | F18: 0 | G18: 0 | H18: 0 | I18: 3 | J18: 0 | K18: 0 | L18: 0 | M18: 26 | N18: 0 | O18: =SUM(C18:L18,N18) -> 9 | P18: =SUM(C18:N18) -> 35 | R18: 1500-1600 | S18: =SUM(C42:C45) -> 18 | T18: =SUM(D42:D45) -> 5 | U18: =SUM(E42:E45) -> 24 | V18: =SUM(F42:F45) -> 14 | W18: =SUM(G42:G45) -> 0 | X18: =SUM(H42:H45) -> 0 | Y18: =SUM(I42:I45) -> 10 | Z18: =SUM(J42:J45) -> 1 | ... AF18: =SUM(P42:P45) -> 182
B19: 09.15 - 09.30 | C19: 6 | D19: 1 | E19: 5 | F19: 6 | G19: 0 | H19: 0 | I19: 0 | J19: 0 | K19: 0 | L19: 0 | M19: 36 | N19: 0 | O19: =SUM(C19:L19,N19) -> 18 | P19: =SUM(C19:N19) -> 54 | R19: 1600-1700 | S19: =SUM(C46:C49) -> 18 | T19: =SUM(D46:D49) -> 7 | U19: =SUM(E46:E49) -> 29 | V19: =SUM(F46:F49) -> 7 | W19: =SUM(G46:G49) -> 1 | X19: =SUM(H46:H49) -> 0 | Y19: =SUM(I46:I49) -> 13 | Z19: =SUM(J46:J49) -> 0 | ... AF19: =SUM(P46:P49) -> 210
B20: 09.30 - 09.45 | C20: 3 | D20: 2 | E20: 8 | F20: 5 | G20: 0 | H20: 0 | I20: 6 | J20: 0 | K20: 0 | L20: 0 | M20: 31 | N20: 0 | O20: =SUM(C20:L20,N20) -> 24 | P20: =SUM(C20:N20) -> 55 | R20: 1700-1800 | S20: =SUM(C50:C53) -> 23 | T20: =SUM(D50:D53) -> 11 | U20: =SUM(E50:E53) -> 42 | V20: =SUM(F50:F53) -> 20 | W20: =SUM(G50:G53) -> 3 | X20: =SUM(H50:H53) -> 0 | Y20: =SUM(I50:I53) -> 9 | Z20: =SUM(J50:J53) -> 0 | ... AF20: =SUM(P50:P53) -> 258
B21: 09.45 - 10.00 | C21: 2 | D21: 1 | E21: 6 | F21: 6 | G21: 0 | H21: 0 | I21: 1 | J21: 0 | K21: 0 | L21: 0 | M21: 35 | N21: 0 | O21: =SUM(C21:L21,N21) -> 16 | P21: =SUM(C21:N21) -> 51 | R21: 1800-1900 | S21: =SUM(C54:C57) -> 20 | T21: =SUM(D54:D57) -> 7 | U21: =SUM(E54:E57) -> 29 | V21: =SUM(F54:F57) -> 23 | W21: =SUM(G54:G57) -> 0 | X21: =SUM(H54:H57) -> 0 | Y21: =SUM(I54:I57) -> 16 | Z21: =SUM(J54:J57) -> 1 | ... AF21: =SUM(P54:P57) -> 231
B22: 10.00 - 10.15 | C22: 7 | D22: 1 | E22: 4 | F22: 4 | G22: 0 | H22: 0 | I22: 3 | J22: 0 | K22: 0 | L22: 0 | M22: 36 | N22: 0 | O22: =SUM(C22:L22,N22) -> 19 | P22: =SUM(C22:N22) -> 55 | R22: AM Peak Hr | S22: =MAX(S10:S12) -> 18 | T22: =MAX(T10:T12) -> 6 | U22: =MAX(U10:U12) -> 28 | V22: =MAX(V10:V12) -> 17 | W22: =MAX(W10:W12) -> 0 | X22: =MAX(X10:X12) -> 0 | Y22: =MAX(Y10:Y12) -> 10 | Z22: =MAX(Z10:Z12) -> 1 | ... AF22: =MAX(AF10:AF12) -> 195
B23: 10.15 - 10.30 | C23: 5 | D23: 2 | E23: 9 | F23: 4 | G23: 0 | H23: 0 | I23: 3 | J23: 0 | K23: 0 | L23: 0 | M23: 19 | N23: 0 | O23: =SUM(C23:L23,N23) -> 23 | P23: =SUM(C23:N23) -> 42 | R23: IP Peak Hr | S23: =MAX(S13:S18) -> 18 | T23: =MAX(T13:T18) -> 6 | U23: =MAX(U13:U18) -> 26 | V23: =MAX(V13:V18) -> 16 | W23: =MAX(W13:W18) -> 0 | X23: =MAX(X13:X18) -> 0 | Y23: =MAX(Y13:Y18) -> 13 | Z23: =MAX(Z13:Z18) -> 1 | ... AF23: =MAX(AF13:AF18) -> 205
B24: 10.30 - 10.45 | C24: 3 | D24: 2 | E24: 8 | F24: 3 | G24: 0 | H24: 0 | I24: 5 | J24: 0 | K24: 0 | L24: 0 | M24: 39 | N24: 0 | O24: =SUM(C24:L24,N24) -> 21 | P24: =SUM(C24:N24) -> 60 | R24: PM Peak Hr | S24: =MAX(S19:S21) -> 23 | T24: =MAX(T19:T21) -> 11 | U24: =MAX(U19:U21) -> 42 | V24: =MAX(V19:V21) -> 23 | W24: =MAX(W19:W21) -> 3 | X24: =MAX(X19:X21) -> 0 | Y24: =MAX(Y19:Y21) -> 16 | Z24: =MAX(Z19:Z21) -> 1 | ... AF24: =MAX(AF19:AF21) -> 258
B25: 10.45 - 11.00 | C25: 2 | D25: 1 | E25: 5 | F25: 5 | G25: 0 | H25: 0 | I25: 0 | J25: 0 | K25: 0 | L25: 0 | M25: 29 | N25: 0 | O25: =SUM(C25:L25,N25) -> 13 | P25: =SUM(C25:N25) -> 42 | R25: AM Period | S25: =SUM(S10:S12) -> 39 | T25: =SUM(T10:T12) -> 11 | U25: =SUM(U10:U12) -> 60 | V25: =SUM(V10:V12) -> 31 | W25: =SUM(W10:W12) -> 0 | X25: =SUM(X10:X12) -> 0 | Y25: =SUM(Y10:Y12) -> 27 | Z25: =SUM(Z10:Z12) -> 1 | ... AF25: =SUM(AF10:AF12) -> 453
B26: 11.00 - 11.15 | C26: 2 | D26: 2 | E26: 8 | F26: 4 | G26: 0 | H26: 0 | I26: 1 | J26: 0 | K26: 0 | L26: 0 | M26: 29 | N26: 0 | O26: =SUM(C26:L26,N26) -> 17 | P26: =SUM(C26:N26) -> 46 | R26: IP Period | S26: =SUM(S13:S18) -> 85 | T26: =SUM(T13:T18) -> 27 | U26: =SUM(U13:U18) -> 128 | V26: =SUM(V13:V18) -> 92 | W26: =SUM(W13:W18) -> 0 | X26: =SUM(X13:X18) -> 0 | Y26: =SUM(Y13:Y18) -> 64 | Z26: =SUM(Z13:Z18) -> 2 | ... AF26: =SUM(AF13:AF18) -> 1106
B27: 11.15 - 11.30 | C27: 8 | D27: 1 | E27: 4 | F27: 2 | G27: 0 | H27: 0 | I27: 1 | J27: 0 | K27: 0 | L27: 0 | M27: 30 | N27: 0 | O27: =SUM(C27:L27,N27) -> 16 | P27: =SUM(C27:N27) -> 46 | R27: PM Period | S27: =SUM(S19:S21) -> 61 | T27: =SUM(T19:T21) -> 25 | U27: =SUM(U19:U21) -> 100 | V27: =SUM(V19:V21) -> 50 | W27: =SUM(W19:W21) -> 4 | X27: =SUM(X19:X21) -> 0 | Y27: =SUM(Y19:Y21) -> 38 | Z27: =SUM(Z19:Z21) -> 1 | ... AF27: =SUM(AF19:AF21) -> 699
B28: 11.30 - 11.45 | C28: 0 | D28: 1 | E28: 4 | F28: 8 | G28: 0 | H28: 0 | I28: 2 | J28: 0 | K28: 0 | L28: 0 | M28: 33 | N28: 0 | O28: =SUM(C28:L28,N28) -> 15 | P28: =SUM(C28:N28) -> 48 | R28: 12 Hours | S28: =SUM(S10:S21) -> 185 | T28: =SUM(T10:T21) -> 63 | U28: =SUM(U10:U21) -> 288 | V28: =SUM(V10:V21) -> 173 | W28: =SUM(W10:W21) -> 4 | X28: =SUM(X10:X21) -> 0 | Y28: =SUM(Y10:Y21) -> 129 | Z28: =SUM(Z10:Z21) -> 4 | ... AF28: =SUM(AF10:AF21) -> 2258
B29: 11.45 - 12.00 | C29: 2 | D29: 1 | E29: 5 | F29: 2 | G29: 0 | H29: 0 | I29: 1 | J29: 0 | K29: 0 | L29: 0 | M29: 32 | N29: 0 | O29: =SUM(C29:L29,N29) -> 11 | P29: =SUM(C29:N29) -> 43
B30: 12.00 - 12.15 | C30: 3 | D30: 1 | E30: 5 | F30: 8 | G30: 0 | H30: 0 | I30: 4 | J30: 0 | K30: 0 | L30: 0 | M30: 42 | N30: 0 | O30: =SUM(C30:L30,N30) -> 21 | P30: =SUM(C30:N30) -> 63
B31: 12.15 - 12.30 | C31: 1 | D31: 0 | E31: 2 | F31: 2 | G31: 0 | H31: 0 | I31: 2 | J31: 0 | K31: 0 | L31: 0 | M31: 33 | N31: 0 | O31: =SUM(C31:L31,N31) -> 7 | P31: =SUM(C31:N31) -> 40
B32: 12.30 - 12.45 | C32: 4 | D32: 0 | E32: 1 | F32: 4 | G32: 0 | H32: 0 | I32: 5 | J32: 0 | K32: 0 | L32: 0 | M32: 34 | N32: 0 | O32: =SUM(C32:L32,N32) -> 14 | P32: =SUM(C32:N32) -> 48
B33: 12.45 - 13.00 | C33: 3 | D33: 2 | E33: 7 | F33: 2 | G33: 0 | H33: 0 | I33: 1 | J33: 1 | K33: 0 | L33: 0 | M33: 14 | N33: 0 | O33: =SUM(C33:L33,N33) -> 16 | P33: =SUM(C33:N33) -> 30
B34: 13.00 - 13.15 | C34: 2 | D34: 2 | E34: 8 | F34: 3 | G34: 0 | H34: 0 | I34: 2 | J34: 0 | K34: 0 | L34: 0 | M34: 39 | N34: 0 | O34: =SUM(C34:L34,N34) -> 17 | P34: =SUM(C34:N34) -> 56
B35: 13.15 - 13.30 | C35: 3 | D35: 1 | E35: 5 | F35: 5 | G35: 0 | H35: 0 | I35: 5 | J35: 0 | K35: 0 | L35: 0 | M35: 32 | N35: 0 | O35: =SUM(C35:L35,N35) -> 19 | P35: =SUM(C35:N35) -> 51
B36: 13.30 - 13.45 | C36: 6 | D36: 1 | E36: 6 | F36: 6 | G36: 0 | H36: 0 | I36: 3 | J36: 0 | K36: 0 | L36: 0 | M36: 35 | N36: 0 | O36: =SUM(C36:L36,N36) -> 22 | P36: =SUM(C36:N36) -> 57
B37: 13.45 - 14.00 | C37: 6 | D37: 0 | E37: 2 | F37: 1 | G37: 0 | H37: 0 | I37: 3 | J37: 0 | K37: 0 | L37: 0 | M37: 29 | N37: 0 | O37: =SUM(C37:L37,N37) -> 12 | P37: =SUM(C37:N37) -> 41
B38: 14.00 - 14.15 | C38: 1 | D38: 1 | E38: 5 | F38: 5 | G38: 0 | H38: 0 | I38: 4 | J38: 0 | K38: 0 | L38: 0 | M38: 24 | N38: 0 | O38: =SUM(C38:L38,N38) -> 16 | P38: =SUM(C38:N38) -> 40
B39: 14.15 - 14.30 | C39: 2 | D39: 1 | E39: 4 | F39: 2 | G39: 0 | H39: 0 | I39: 1 | J39: 0 | K39: 0 | L39: 0 | M39: 24 | N39: 0 | O39: =SUM(C39:L39,N39) -> 10 | P39: =SUM(C39:N39) -> 34
B40: 14.30 - 14.45 | C40: 6 | D40: 1 | E40: 6 | F40: 5 | G40: 0 | H40: 0 | I40: 5 | J40: 0 | K40: 0 | L40: 0 | M40: 25 | N40: 0 | O40: =SUM(C40:L40,N40) -> 23 | P40: =SUM(C40:N40) -> 48
... B57: 18.45 - 19.00 | C57: 4 | D57: 0 | E57: 2 | F57: 6 | G57: 0 | H57: 0 | I57: 3 | J57: 0 | K57: 0 | L57: 0 | M57: 28 | N57: 0 | O57: =SUM(C57:L57,N57) -> 15 | P57: =SUM(C57:N57) -> 43
B58: Totals | C58: =SUM(C10:C57) -> 185 | D58: =SUM(D10:D57) -> 63 | E58: =SUM(E10:E57) -> 288 | F58: =SUM(F10:F57) -> 173 | G58: =SUM(G10:G57) -> 4 | H58: =SUM(H10:H57) -> 0 | I58: =SUM(I10:I57) -> 129 | J58: =SUM(J10:J57) -> 4 | ... P58: =SUM(P10:P57) -> 2258
...

Sheet 19.08 Mbale-Sironko
B1: Consultancy services for Preparation of Expressway Development Master Plan (EDMP) for Uganda
B2: MANUAL CLASSIFIED COUNT (MCC)
B3: ROAD NAME: | C3: ='19.08 Sironko-Mbale'!C3:G3 -> MCC - C4 - STN120 - MBALE-SIRONKO ROAD
C5: Date | D5: ='19.08 Sironko-Mbale'!D5 -> 19.08.19 | F5: Location | G5: ='19.08 Sironko-Mbale'!G5:H5 -> xxx | J5: Surveyor | K5: ='19.08 Sironko-Mbale'!K5:L5 -> xxx
C6: Dir. From | D6: Mbale | F6: Dir. To | G6: Sironko | J6: Supervisor | K6: ='19.08 Sironko-Mbale'!K6:L6 -> xxx
B8: Time / Veh Type | R8: SUMMARY TRAFFIC VOLUMES
C9: 1. Car | D9: 2. Station Wagon | E9: 3. Pickups | F9: 4. Minibus, matatu | G9: 5. Medium bus | H9: 6. Large Bus | I9: 7. Light Truck | J9: 8. Medium Truck | K9: 9. Heavy truck | L9: 10. Truck Trailer | M9: 11. Motor cycles | N9: 12. Tractors | O9: Total Excl M/Cycles | P9: Total All | R9: Time | S9: 1. Car | T9: 2. Station Wagon | U9: 3. Pickups | V9: 4. Minibus, matatu | W9: 5. Medium bus | X9: 6. Large Bus | Y9: 7. Light Truck | Z9: 8. Medium Truck | AA9: 9. Heavy truck | AB9: 10. Truck Trailer | AC9: 11. Motorcycles | AD9: 12. Tractors, Graders | AE9: Total Excl M/ Cycles | AF9: Total All
B10: 07.00 - 07.15 | C10: 0 | D10: =ROUNDDOWN((0.3*E10),0) -> 0 | E10: 0 | F10: 0 | G10: 0 | H10: 0 | I10: 0 | J10: 0 | K10: 0 | L10: =SUM('[1]RD4 MCC'!R54:U54) -> 0 | M10: 0 | N10: 0 | O10: =SUM(C10:L10,N10) -> 0 | P10: =SUM(C10:N10) -> 0 | R10: 0700-0800 | S10: =SUM(C10:C13) -> 7 | T10: =SUM(D10:D13) -> 1 | U10: =SUM(E10:E13) -> 10 | V10: =SUM(F10:F13) -> 4 | W10: =SUM(G10:G13) -> 0 | X10: =SUM(H10:H13) -> 0 | Y10: =SUM(I10:I13) -> 3 | Z10: =SUM(J10:J13) -> 0 | ... AF10: =SUM(P10:P13) -> 68
B11: 07.15 - 07.30 | C11: 1 | D11: =ROUNDDOWN((0.3*E11),0) -> 0 | E11: 1 | F11: 2 | G11: 0 | H11: 0 | I11: 0 | J11: 0 | K11: 0 | L11: =SUM('[1]RD4 MCC'!R55:U55) -> 0 | M11: 4 | N11: 0 | O11: =SUM(C11:L11,N11) -> 4 | P11: =SUM(C11:N11) -> 8 | R11: 0800-0900 | S11: =SUM(C14:C17) -> 18 | T11: =SUM(D14:D17) -> 4 | U11: =SUM(E14:E17) -> 22 | V11: =SUM(F14:F17) -> 11 | W11: =SUM(G14:G17) -> 1 | X11: =SUM(H14:H17) -> 0 | Y11: =SUM(I14:I17) -> 3 | Z11: =SUM(J14:J17) -> 0 | ... AF11: =SUM(P14:P17) -> 141
B12: 07.30 - 07.45 | C12: 4 | D12: =ROUNDDOWN((0.3*E12),0) -> 0 | E12: 3 | F12: 0 | G12: 0 | H12: 0 | I12: 0 | J12: 0 | K12: 0 | L12: =SUM('[1]RD4 MCC'!R56:U56) -> 0 | M12: 5 | N12: 0 | O12: =SUM(C12:L12,N12) -> 7 | P12: =SUM(C12:N12) -> 12 | R12: 0900-1000 | S12: =SUM(C18:C21) -> 13 | T12: =SUM(D18:D21) -> 6 | U12: =SUM(E18:E21) -> 25 | V12: =SUM(F18:F21) -> 13 | W12: =SUM(G18:G21) -> 1 | X12: =SUM(H18:H21) -> 0 | Y12: =SUM(I18:I21) -> 15 | Z12: =SUM(J18:J21) -> 0 | ... AF12: =SUM(P18:P21) -> 171
B13: 07.45 - 08.00 | C13: 2 | D13: =ROUNDDOWN((0.3*E13),0) -> 1 | E13: 6 | F13: 2 | G13: 0 | H13: 0 | I13: 3 | J13: 0 | K13: 0 | L13: =SUM('[1]RD4 MCC'!R57:U57) -> 0 | M13: 34 | N13: 0 | O13: =SUM(C13:L13,N13) -> 14 | P13: =SUM(C13:N13) -> 48 | R13: 1000-1100 | S13: =SUM(C22:C25) -> 20 | T13: =SUM(D22:D25) -> 8 | U13: =SUM(E22:E25) -> 29 | V13: =SUM(F22:F25) -> 10 | W13: =SUM(G22:G25) -> 1 | X13: =SUM(H22:H25) -> 0 | Y13: =SUM(I22:I25) -> 16 | Z13: =SUM(J22:J25) -> 1 | ... AF13: =SUM(P22:P25) -> 209
B14: 08.00 - 08.15 | C14: 5 | D14: =ROUNDDOWN((0.3*E14),0) -> 0 | E14: 3 | F14: 3 | G14: 1 | H14: 0 | I14: 0 | J14: 0 | K14: 0 | L14: =SUM('[1]RD4 MCC'!R58:U58) -> 0 | M14: 16 | N14: 0 | O14: =SUM(C14:L14,N14) -> 12 | P14: =SUM(C14:N14) -> 28 | R14: 1100-1200 | S14: =SUM(C26:C29) -> 13 | T14: =SUM(D26:D29) -> 6 | U14: =SUM(E26:E29) -> 25 | V14: =SUM(F26:F29) -> 21 | W14: =SUM(G26:G29) -> 0 | X14: =SUM(H26:H29) -> 0 | Y14: =SUM(I26:I29) -> 15 | Z14: =SUM(J26:J29) -> 2 | ... AF14: =SUM(P26:P29) -> 210
B15: 08.15 - 08.30 | C15: 3 | D15: =ROUNDDOWN((0.3*E15),0) -> 2 | E15: 8 | F15: 2 | G15: 0 | H15: 0 | I15: 3 | J15: 0 | K15: 0 | L15: =SUM('[1]RD4 MCC'!R59:U59) -> 0 | M15: 27 | N15: 0 | O15: =SUM(C15:L15,N15) -> 18 | P15: =SUM(C15:N15) -> 45 | R15: 1200-1300 | S15: =SUM(C30:C33) -> 12 | T15: =SUM(D30:D33) -> 7 | U15: =SUM(E30:E33) -> 29 | V15: =SUM(F30:F33) -> 17 | W15: =SUM(G30:G33) -> 0 | X15: =SUM(H30:H33) -> 0 | Y15: =SUM(I30:I33) -> 20 | Z15: =SUM(J30:J33) -> 0 | ... AF15: =SUM(P30:P33) -> 190
B16: 08.30 - 08.45 | C16: 5 | D16: =ROUNDDOWN((0.3*E16),0) -> 1 | E16: 5 | F16: 2 | G16: 0 | H16: 0 | I16: 0 | J16: 0 | K16: 0 | L16: =SUM('[1]RD4 MCC'!R60:U60) -> 0 | M16: 28 | N16: 0 | O16: =SUM(C16:L16,N16) -> 13 | P16: =SUM(C16:N16) -> 41 | R16: 1300-1400 | S16: =SUM(C34:C37) -> 14 | T16: =SUM(D34:D37) -> 9 | U16: =SUM(E34:E37) -> 34 | V16: =SUM(F34:F37) -> 18 | W16: =SUM(G34:G37) -> 0 | X16: =SUM(H34:H37) -> 0 | Y16: =SUM(I34:I37) -> 15 | Z16: =SUM(J34:J37) -> 0 | ... AF16: =SUM(P34:P37) -> 204
B17: 08.45 - 9.00 | C17: 5 | D17: =ROUNDDOWN((0.3*E17),0) -> 1 | E17: 6 | F17: 4 | G17: 0 | H17: 0 | I17: 0 | J17: 0 | K17: 0 | L17: =SUM('[1]RD4 MCC'!R61:U61) -> 0 | M17: 11 | N17: 0 | O17: =SUM(C17:L17,N17) -> 16 | P17: =SUM(C17:N17) -> 27 | R17: 1400-1500 | S17: =SUM(C38:C41) -> 18 | T17: =SUM(D38:D41) -> 8 | U17: =SUM(E38:E41) -> 31 | V17: =SUM(F38:F41) -> 17 | W17: =SUM(G38:G41) -> 0 | X17: =SUM(H38:H41) -> 0 | Y17: =SUM(I38:I41) -> 21 | Z17: =SUM(J38:J41) -> 2 | ... AF17: =SUM(P38:P41) -> 204
B18: 09.00 - 09.15 | C18: 2 | D18: =ROUNDDOWN((0.3*E18),0) -> 1 | E18: 4 | F18: 0 | G18: 0 | H18: 0 | I18: 5 | J18: 0 | K18: 0 | L18: =SUM('[1]RD4 MCC'!R62:U62) -> 0 | M18: 26 | N18: 0 | O18: =SUM(C18:L18,N18) -> 12 | P18: =SUM(C18:N18) -> 38 | R18: 1500-1600 | S18: =SUM(C42:C45) -> 15 | T18: =SUM(D42:D45) -> 6 | U18: =SUM(E42:E45) -> 29 | V18: =SUM(F42:F45) -> 18 | W18: =SUM(G42:G45) -> 0 | X18: =SUM(H42:H45) -> 0 | Y18: =SUM(I42:I45) -> 12 | Z18: =SUM(J42:J45) -> 1 | ... AF18: =SUM(P42:P45) -> 187
B19: 09.15 - 09.30 | C19: 6 | D19: =ROUNDDOWN((0.3*E19),0) -> 2 | E19: 7 | F19: 5 | G19: 1 | H19: 0 | I19: 4 | J19: 0 | K19: 0 | L19: =SUM('[1]RD4 MCC'!R63:U63) -> 0 | M19: 20 | N19: 0 | O19: =SUM(C19:L19,N19) -> 25 | P19: =SUM(C19:N19) -> 45 | R19: 1600-1700 | S19: =SUM(C46:C49) -> 18 | T19: =SUM(D46:D49) -> 0 | U19: =SUM(E46:E49) -> 10 | V19: =SUM(F46:F49) -> 20 | W19: =SUM(G46:G49) -> 0 | X19: =SUM(H46:H49) -> 0 | Y19: =SUM(I46:I49) -> 7 | Z19: =SUM(J46:J49) -> 1 | ... AF19: =SUM(P46:P49) -> 177
B20: 09.30 - 09.45 | C20: 3 | D20: =ROUNDDOWN((0.3*E20),0) -> 1 | E20: 6 | F20: 3 | G20: 0 | H20: 0 | I20: 4 | J20: 0 | K20: 0 | L20: =SUM('[1]RD4 MCC'!R64:U64) -> 0 | M20: 25 | N20: 0 | O20: =SUM(C20:L20,N20) -> 17 | P20: =SUM(C20:N20) -> 42 | R20: 1700-1800 | S20: =SUM(C50:C53) -> 14 | T20: =SUM(D50:D53) -> 8 | U20: =SUM(E50:E53) -> 30 | V20: =SUM(F50:F53) -> 16 | W20: =SUM(G50:G53) -> 0 | X20: =SUM(H50:H53) -> 0 | Y20: =SUM(I50:I53) -> 12 | Z20: =SUM(J50:J53) -> 2 | ... AF20: =SUM(P50:P53) -> 236
B21: 09.45 - 10.00 | C21: 2 | D21: =ROUNDDOWN((0.3*E21),0) -> 2 | E21: 8 | F21: 5 | G21: 0 | H21: 0 | I21: 2 | J21: 0 | K21: 0 | L21: =SUM('[1]RD4 MCC'!R65:U65) -> 0 | M21: 27 | N21: 0 | O21: =SUM(C21:L21,N21) -> 19 | P21: =SUM(C21:N21) -> 46 | R21: 1800-1900 | S21: =SUM(C54:C57) -> 26 | T21: =SUM(D54:D57) -> 8 | U21: =SUM(E54:E57) -> 35 | V21: =SUM(F54:F57) -> 13 | W21: =SUM(G54:G57) -> 0 | X21: =SUM(H54:H57) -> 0 | Y21: =SUM(I54:I57) -> 26 | Z21: =SUM(J54:J57) -> 2 | ... AF21: =SUM(P54:P57) -> 244
B22: 10.00 - 10.15 | C22: 2 | D22: =ROUNDDOWN((0.3*E22),0) -> 2 | E22: 8 | F22: 3 | G22: 0 | H22: 0 | I22: 4 | J22: 0 | K22: 0 | L22: =SUM('[1]RD4 MCC'!R66:U66) -> 0 | M22: 32 | N22: 0 | O22: =SUM(C22:L22,N22) -> 19 | P22: =SUM(C22:N22) -> 51 | R22: AM Peak Hr | S22: =MAX(S10:S12) -> 18 | T22: =MAX(T10:T12) -> 6 | U22: =MAX(U10:U12) -> 25 | V22: =MAX(V10:V12) -> 13 | W22: =MAX(W10:W12) -> 1 | X22: =MAX(X10:X12) -> 0 | Y22: =MAX(Y10:Y12) -> 15 | Z22: =MAX(Z10:Z12) -> 0 | ... AF22: =MAX(AF10:AF12) -> 171
B23: 10.15 - 10.30 | C23: 7 | D23: =ROUNDDOWN((0.3*E23),0) -> 2 | E23: 7 | F23: 4 | G23: 0 | H23: 0 | I23: 2 | J23: 1 | K23: 0 | L23: =SUM('[1]RD4 MCC'!R67:U67) -> 0 | M23: 40 | N23: 0 | O23: =SUM(C23:L23,N23) -> 23 | P23: =SUM(C23:N23) -> 63 | R23: IP Peak Hr | S23: =MAX(S13:S18) -> 20 | T23: =MAX(T13:T18) -> 9 | U23: =MAX(U13:U18) -> 34 | V23: =MAX(V13:V18) -> 21 | W23: =MAX(W13:W18) -> 1 | X23: =MAX(X13:X18) -> 0 | Y23: =MAX(Y13:Y18) -> 21 | Z23: =MAX(Z13:Z18) -> 2 | ... AF23: =MAX(AF13:AF18) -> 210
B24: 10.30 - 10.45 | C24: 4 | D24: =ROUNDDOWN((0.3*E24),0) -> 2 | E24: 7 | F24: 2 | G24: 0 | H24: 0 | I24: 3 | J24: 0 | K24: 0 | L24: =SUM('[1]RD4 MCC'!R68:U68) -> 0 | M24: 19 | N24: 0 | O24: =SUM(C24:L24,N24) -> 18 | P24: =SUM(C24:N24) -> 37 | R24: PM Peak Hr | S24: =MAX(S19:S21) -> 26 | T24: =MAX(T19:T21) -> 8 | U24: =MAX(U19:U21) -> 35 | V24: =MAX(V19:V21) -> 20 | W24: =MAX(W19:W21) -> 0 | X24: =MAX(X19:X21) -> 0 | Y24: =MAX(Y19:Y21) -> 26 | Z24: =MAX(Z19:Z21) -> 2 | ... AF24: =MAX(AF19:AF21) -> 244
B25: 10.45 - 11.00 | C25: 7 | D25: =ROUNDDOWN((0.3*E25),0) -> 2 | E25: 7 | F25: 1 | G25: 1 | H25: 0 | I25: 7 | J25: 0 | K25: 0 | L25: =SUM('[1]RD4 MCC'!R69:U69) -> 0 | M25: 33 | N25: 0 | O25: =SUM(C25:L25,N25) -> 25 | P25: =SUM(C25:N25) -> 58 | R25: AM Period | S25: =SUM(S10:S12) -> 38 | T25: =SUM(T10:T12) -> 11 | U25: =SUM(U10:U12) -> 57 | V25: =SUM(V10:V12) -> 28 | W25: =SUM(W10:W12) -> 2 | X25: =SUM(X10:X12) -> 0 | Y25: =SUM(Y10:Y12) -> 21 | Z25: =SUM(Z10:Z12) -> 0 | ... AF25: =SUM(AF10:AF12) -> 380
B26: 11.00 - 11.15 | C26: 4 | D26: =ROUNDDOWN((0.3*E26),0) -> 3 | E26: 11 | F26: 6 | G26: 0 | H26: 0 | I26: 2 | J26: 1 | K26: 0 | L26: =SUM('[1]RD4 MCC'!R70:U70) -> 0 | M26: 37 | N26: 0 | O26: =SUM(C26:L26,N26) -> 27 | P26: =SUM(C26:N26) -> 64 | R26: IP Period | S26: =SUM(S13:S18) -> 92 | T26: =SUM(T13:T18) -> 44 | U26: =SUM(U13:U18) -> 177 | V26: =SUM(V13:V18) -> 101 | W26: =SUM(W13:W18) -> 1 | X26: =SUM(X13:X18) -> 0 | Y26: =SUM(Y13:Y18) -> 99 | Z26: =SUM(Z13:Z18) -> 6 | ... AF26: =SUM(AF13:AF18) -> 1204
B27: 11.15 - 11.30 | C27: 3 | D27: =ROUNDDOWN((0.3*E27),0) -> 2 | E27: 8 | F27: 4 | G27: 0 | H27: 0 | I27: 4 | J27: 0 | K27: 0 | L27: =SUM('[1]RD4 MCC'!R71:U71) -> 0 | M27: 30 | N27: 0 | O27: =SUM(C27:L27,N27) -> 21 | P27: =SUM(C27:N27) -> 51 | R27: PM Period | S27: =SUM(S19:S21) -> 58 | T27: =SUM(T19:T21) -> 16 | U27: =SUM(U19:U21) -> 75 | V27: =SUM(V19:V21) -> 49 | W27: =SUM(W19:W21) -> 0 | X27: =SUM(X19:X21) -> 0 | Y27: =SUM(Y19:Y21) -> 45 | Z27: =SUM(Z19:Z21) -> 5 | ... AF27: =SUM(AF19:AF21) -> 657
B28: 11.30 - 11.45 | C28: 2 | D28: =ROUNDDOWN((0.3*E28),0) -> 0 | E28: 2 | F28: 3 | G28: 0 | H28: 0 | I28: 5 | J28: 0 | K28: 0 | L28: =SUM('[1]RD4 MCC'!R72:U72) -> 0 | M28: 26 | N28: 0 | O28: =SUM(C28:L28,N28) -> 12 | P28: =SUM(C28:N28) -> 38 | R28: 12 Hours | S28: =SUM(S10:S21) -> 188 | T28: =SUM(T10:T21) -> 71 | U28: =SUM(U10:U21) -> 309 | V28: =SUM(V10:V21) -> 178 | W28: =SUM(W10:W21) -> 3 | X28: =SUM(X10:X21) -> 0 | Y28: =SUM(Y10:Y21) -> 165 | Z28: =SUM(Z10:Z21) -> 11 | ... AF28: =SUM(AF10:AF21) -> 2241
B29: 11.45 - 12.00 | C29: 4 | D29: =ROUNDDOWN((0.3*E29),0) -> 1 | E29: 4 | F29: 8 | G29: 0 | H29: 0 | I29: 4 | J29: 1 | K29: 0 | L29: =SUM('[1]RD4 MCC'!R73:U73) -> 0 | M29: 35 | N29: 0 | O29: =SUM(C29:L29,N29) -> 22 | P29: =SUM(C29:N29) -> 57
B30: 12.00 - 12.15 | C30: 2 | D30: =ROUNDDOWN((0.3*E30),0) -> 2 | E30: 7 | F30: 5 | G30: 0 | H30: 0 | I30: 4 | J30: 0 | K30: 0 | L30: =SUM('[1]RD4 MCC'!R74:U74) -> 0 | M30: 34 | N30: 0 | O30: =SUM(C30:L30,N30) -> 20 | P30: =SUM(C30:N30) -> 54
B31: 12.15 - 12.30 | C31: 5 | D31: =ROUNDDOWN((0.3*E31),0) -> 1 | E31: 6 | F31: 7 | G31: 0 | H31: 0 | I31: 10 | J31: 0 | K31: 0 | L31: =SUM('[1]RD4 MCC'!R75:U75) -> 0 | M31: 27 | N31: 0 | O31: =SUM(C31:L31,N31) -> 29 | P31: =SUM(C31:N31) -> 56
B32: 12.30 - 12.45 | C32: 3 | D32: =ROUNDDOWN((0.3*E32),0) -> 2 | E32: 7 | F32: 1 | G32: 0 | H32: 0 | I32: 3 | J32: 0 | K32: 0 | L32: =SUM('[1]RD4 MCC'!R76:U76) -> 0 | M32: 14 | N32: 0 | O32: =SUM(C32:L32,N32) -> 16 | P32: =SUM(C32:N32) -> 30
B33: 12.45 - 13.00 | C33: 2 | D33: =ROUNDDOWN((0.3*E33),0) -> 2 | E33: 9 | F33: 4 | G33: 0 | H33: 0 | I33: 3 | J33: 0 | K33: 1 | L33: =SUM('[1]RD4 MCC'!R77:U77) -> 0 | M33: 29 | N33: 0 | O33: =SUM(C33:L33,N33) -> 21 | P33: =SUM(C33:N33) -> 50
B34: 13.00 - 13.15 | C34: 3 | D34: =ROUNDDOWN((0.3*E34),0) -> 3 | E34: 12 | F34: 2 | G34: 0 | H34: 0 | I34: 3 | J34: 0 | K34: 0 | L34: =SUM('[1]RD4 MCC'!R78:U78) -> 0 | M34: 29 | N34: 0 | O34: =SUM(C34:L34,N34) -> 23 | P34: =SUM(C34:N34) -> 52
B35: 13.15 - 13.30 | C35: 1 | D35: =ROUNDDOWN((0.3*E35),0) -> 2 | E35: 8 | F35: 7 | G35: 0 | H35: 0 | I35: 3 | J35: 0 | K35: 0 | L35: =SUM('[1]RD4 MCC'!R79:U79) -> 0 | M35: 30 | N35: 0 | O35: =SUM(C35:L35,N35) -> 21 | P35: =SUM(C35:N35) -> 51
B36: 13.30 - 13.45 | C36: 6 | D36: =ROUNDDOWN((0.3*E36),0) -> 2 | E36: 7 | F36: 5 | G36: 0 | H36: 0 | I36: 1 | J36: 0 | K36: 0 | L36: =SUM('[1]RD4 MCC'!R80:U80) -> 0 | M36: 26 | N36: 0 | O36: =SUM(C36:L36,N36) -> 21 | P36: =SUM(C36:N36) -> 47
B37: 13.45 - 14.00 | C37: 4 | D37: =ROUNDDOWN((0.3*E37),0) -> 2 | E37: 7 | F37: 4 | G37: 0 | H37: 0 | I37: 8 | J37: 0 | K37: 0 | L37: =SUM('[1]RD4 MCC'!R81:U81) -> 0 | M37: 29 | N37: 0 | O37: =SUM(C37:L37,N37) -> 25 | P37: =SUM(C37:N37) -> 54
B38: 14.00 - 14.15 | C38: 7 | D38: =ROUNDDOWN((0.3*E38),0) -> 2 | E38: 7 | F38: 6 | G38: 0 | H38: 0 | I38: 1 | J38: 1 | K38: 0 | L38: =SUM('[1]RD4 MCC'!R82:U82) -> 0 | M38: 24 | N38: 0 | O38: =SUM(C38:L38,N38) -> 24 | P38: =SUM(C38:N38) -> 48
B39: 14.15 - 14.30 | C39: 1 | D39: =ROUNDDOWN((0.3*E39),0) -> 2 | E39: 8 | F39: 3 | G39: 0 | H39: 0 | I39: 2 | J39: 0 | K39: 0 | L39: =SUM('[1]RD4 MCC'!R83:U83) -> 0 | M39: 25 | N39: 0 | O39: =SUM(C39:L39,N39) -> 16 | P39: =SUM(C39:N39) -> 41
B40: 14.30 - 14.45 | C40: 7 | D40: =ROUNDDOWN((0.3*E40),0) -> 2 | E40: 9 | F40: 3 | G40: 0 | H40: 0 | I40: 11 | J40: 1 | K40: 0 | L40: =SUM('[1]RD4 MCC'!R84:U84) -> 0 | M40: 28 | N40: 0 | O40: =SUM(C40:L40,N40) -> 33 | P40: =SUM(C40:N40) -> 61
... B57: 18.45 - 19.00 | C57: 7 | D57: =ROUNDDOWN((0.3*E57),0) -> 3 | E57: 13 | F57: 4 | G57: 0 | H57: 0 | I57: 9 | J57: 0 | K57: 0 | L57: =SUM('[1]RD4 MCC'!R101:U101) -> 0 | M57: 45 | N57: 0 | O57: =SUM(C57:L57,N57) -> 36 | P57: =SUM(C57:N57) -> 81
B58: Totals | C58: =SUM(C10:C57) -> 188 | D58: =SUM(D10:D57) -> 71 | E58: =SUM(E10:E57) -> 309 | F58: =SUM(F10:F57) -> 178 | G58: =SUM(G10:G57) -> 3 | H58: =SUM(H10:H57) -> 0 | I58: =SUM(I10:I57) -> 165 | J58: =SUM(J10:J57) -> 11 | ... P58: =SUM(P10:P57) -> 2241
...

Sheet 20.08 Sironko-Mbale
B1: Consultancy services for Preparation of Expressway Development Master Plan (EDMP) for Uganda
B2: MANUAL CLASSIFIED COUNT (MCC)
B3: ROAD NAME: | C3: ='19.08 Sironko-Mbale'!C3:G3 -> MCC - C4 - STN120 - MBALE-SIRONKO ROAD
C5: Date | D5: 20.08.19 | F5: Location | G5: ='19.08 Sironko-Mbale'!G5:H5 -> xxx | J5: Surveyor | K5: ='19.08 Sironko-Mbale'!K5:L5 -> xxx
C6: Dir. From | D6: ='19.08 Sironko-Mbale'!D6:E6 -> Sironko | F6: Dir. To | G6: ='19.08 Sironko-Mbale'!G6:H6 -> Mbale | J6: Supervisor | K6: ='19.08 Sironko-Mbale'!K6:L6 -> xxx
B8: Time / Veh Type | R8: SUMMARY TRAFFIC VOLUMES
C9: 1. Car | D9: 2. Station Wagon | E9: 3. Pickups | F9: 4. Minibus, matatu | G9: 5. Medium bus | H9: 6. Large Bus | I9: 7. Light Truck | J9: 8. Medium Truck | K9: 9. Heavy truck | L9: 10. Truck Trailer | M9: 11. Motor cycles | N9: 12. Tractors | O9: Total Excl M/Cycles | P9: Total All | R9: Time | S9: 1. Car | T9: 2. Station Wagon | U9: 3. Pickups | V9: 4. Minibus, matatu | W9: 5. Medium bus | X9: 6. Large Bus | Y9: 7. Light Truck | Z9: 8. Medium Truck | AA9: 9. Heavy truck | AB9: 10. Truck Trailer | AC9: 11. Motorcycles | AD9: 12. Tractors, Graders | AE9: Total Excl M/ Cycles | AF9: Total All
B10: 07.00 - 07.15 | C10: 0 | D10: 0 | E10: 0 | F10: 0 | G10: 0 | H10: 0 | I10: 0 | J10: 0 | K10: 0 | L10: 0 | M10: 6 | N10: 0 | O10: =SUM(C10:L10,N10) -> 0 | P10: =SUM(C10:N10) -> 6 | R10: 0700-0800 | S10: =SUM(C10:C13) -> 4 | T10: =SUM(D10:D13) -> 1 | U10: =SUM(E10:E13) -> 8 | V10: =SUM(F10:F13) -> 10 | W10: =SUM(G10:G13) -> 0 | X10: =SUM(H10:H13) -> 0 | Y10: =SUM(I10:I13) -> 3 | Z10: =SUM(J10:J13) -> 1 | ... AF10: =SUM(P10:P13) -> 152
B11: 07.15 - 07.30 | C11: 2 | D11: 0 | E11: 1 | F11: 3 | G11: 0 | H11: 0 | I11: 1 | J11: 1 | K11: 0 | L11: 0 | M11: 34 | N11: 0 | O11: =SUM(C11:L11,N11) -> 8 | P11: =SUM(C11:N11) -> 42 | R11: 0800-0900 | S11: =SUM(C14:C17) -> 6 | T11: =SUM(D14:D17) -> 5 | U11: =SUM(E14:E17) -> 21 | V11: =SUM(F14:F17) -> 12 | W11: =SUM(G14:G17) -> 0 | X11: =SUM(H14:H17) -> 0 | Y11: =SUM(I14:I17) -> 4 | Z11: =SUM(J14:J17) -> 0 | ... AF11: =SUM(P14:P17) -> 173
B12: 07.30 - 07.45 | C12: 0 | D12: 0 | E12: 2 | F12: 2 | G12: 0 | H12: 0 | I12: 0 | J12: 0 | K12: 0 | L12: 0 | M12: 44 | N12: 0 | O12: =SUM(C12:L12,N12) -> 4 | P12: =SUM(C12:N12) -> 48 | R12: 0900-1000 | S12: =SUM(C18:C21) -> 14 | T12: =SUM(D18:D21) -> 2 | U12: =SUM(E18:E21) -> 14 | V12: =SUM(F18:F21) -> 10 | W12: =SUM(G18:G21) -> 0 | X12: =SUM(H18:H21) -> 0 | Y12: =SUM(I18:I21) -> 1 | Z12: =SUM(J18:J21) -> 0 | ... AF12: =SUM(P18:P21) -> 160
B13: 07.45 - 08.00 | C13: 2 | D13: 1 | E13: 5 | F13: 5 | G13: 0 | H13: 0 | I13: 2 | J13: 0 | K13: 0 | L13: 0 | M13: 41 | N13: 0 | O13: =SUM(C13:L13,N13) -> 15 | P13: =SUM(C13:N13) -> 56 | R13: 1000-1100 | S13: =SUM(C22:C25) -> 15 | T13: =SUM(D22:D25) -> 1 | U13: =SUM(E22:E25) -> 10 | V13: =SUM(F22:F25) -> 11 | W13: =SUM(G22:G25) -> 0 | X13: =SUM(H22:H25) -> 0 | Y13: =SUM(I22:I25) -> 15 | Z13: =SUM(J22:J25) -> 0 | ... AF13: =SUM(P22:P25) -> 180
B14: 08.00 - 08.15 | C14: 1 | D14: 1 | E14: 4 | F14: 3 | G14: 0 | H14: 0 | I14: 0 | J14: 0 | K14: 0 | L14: 0 | M14: 24 | N14: 0 | O14: =SUM(C14:L14,N14) -> 9 | P14: =SUM(C14:N14) -> 33 | R14: 1100-1200 | S14: =SUM(C26:C29) -> 11 | T14: =SUM(D26:D29) -> 6 | U14: =SUM(E26:E29) -> 22 | V14: =SUM(F26:F29) -> 13 | W14: =SUM(G26:G29) -> 2 | X14: =SUM(H26:H29) -> 0 | Y14: =SUM(I26:I29) -> 2 | Z14: =SUM(J26:J29) -> 2 | ... AF14: =SUM(P26:P29) -> 157
B15: 08.15 - 08.30 | C15: 0 | D15: 2 | E15: 7 | F15: 3 | G15: 0 | H15: 0 | I15: 2 | J15: 0 | K15: 0 | L15: 0 | M15: 32 | N15: 0 | O15: =SUM(C15:L15,N15) -> 14 | P15: =SUM(C15:N15) -> 46 | R15: 1200-1300 | S15: =SUM(C30:C33) -> 7 | T15: =SUM(D30:D33) -> 3 | U15: =SUM(E30:E33) -> 19 | V15: =SUM(F30:F33) -> 7 | W15: =SUM(G30:G33) -> 0 | X15: =SUM(H30:H33) -> 1 | Y15: =SUM(I30:I33) -> 11 | Z15: =SUM(J30:J33) -> 0 | ... AF15: =SUM(P30:P33) -> 174
B16: 08.30 - 08.45 | C16: 4 | D16: 1 | E16: 6 | F16: 3 | G16: 0 | H16: 0 | I16: 2 | J16: 0 | K16: 0 | L16: 0 | M16: 28 | N16: 0 | O16: =SUM(C16:L16,N16) -> 16 | P16: =SUM(C16:N16) -> 44 | R16: 1300-1400 | S16: =SUM(C34:C37) -> 10 | T16: =SUM(D34:D37) -> 3 | U16: =SUM(E34:E37) -> 18 | V16: =SUM(F34:F37) -> 12 | W16: =SUM(G34:G37) -> 0 | X16: =SUM(H34:H37) -> 0 | Y16: =SUM(I34:I37) -> 18 | Z16: =SUM(J34:J37) -> 1 | ... AF16: =SUM(P34:P37) -> 169
B17: 08.45 - 9.00 | C17: 1 | D17: 1 | E17: 4 | F17: 3 | G17: 0 | H17: 0 | I17: 0 | J17: 0 | K17: 0 | L17: 0 | M17: 41 | N17: 0 | O17: =SUM(C17:L17,N17) -> 9 | P17: =SUM(C17:N17) -> 50 | R17: 1400-1500 | S17: =SUM(C38:C41) -> 11 | T17: =SUM(D38:D41) -> 6 | U17: =SUM(E38:E41) -> 28 | V17: =SUM(F38:F41) -> 9 | W17: =SUM(G38:G41) -> 0 | X17: =SUM(H38:H41) -> 0 | Y17: =SUM(I38:I41) -> 20 | Z17: =SUM(J38:J41) -> 1 | ... AF17: =SUM(P38:P41) -> 206
B18: 09.00 - 09.15 | C18: 2 | D18: 0 | E18: 2 | F18: 2 | G18: 0 | H18: 0 | I18: 0 | J18: 0 | K18: 0 | L18: 0 | M18: 25 | N18: 0 | O18: =SUM(C18:L18,N18) -> 6 | P18: =SUM(C18:N18) -> 31 | R18: 1500-1600 | S18: =SUM(C42:C45) -> 13 | T18: =SUM(D42:D45) -> 7 | U18: =SUM(E42:E45) -> 28 | V18: =SUM(F42:F45) -> 12 | W18: =SUM(G42:G45) -> 0 | X18: =SUM(H42:H45) -> 0 | Y18: =SUM(I42:I45) -> 15 | Z18: =SUM(J42:J45) -> 1 | ... AF18: =SUM(P42:P45) -> 202
B19: 09.15 - 09.30 | C19: 2 | D19: 1 | E19: 5 | F19: 2 | G19: 0 | H19: 0 | I19: 0 | J19: 0 | K19: 0 | L19: 0 | M19: 35 | N19: 0 | O19: =SUM(C19:L19,N19) -> 10 | P19: =SUM(C19:N19) -> 45 | R19: 1600-1700 | S19: =SUM(C46:C49) -> 17 | T19: =SUM(D46:D49) -> 4 | U19: =SUM(E46:E49) -> 20 | V19: =SUM(F46:F49) -> 9 | W19: =SUM(G46:G49) -> 0 | X19: =SUM(H46:H49) -> 1 | Y19: =SUM(I46:I49) -> 15 | Z19: =SUM(J46:J49) -> 0 | ... AF19: =SUM(P46:P49) -> 201
B20: 09.30 - 09.45 | C20: 6 | D20: 1 | E20: 5 | F20: 3 | G20: 0 | H20: 0 | I20: 0 | J20: 0 | K20: 0 | L20: 0 | M20: 24 | N20: 0 | O20: =SUM(C20:L20,N20) -> 15 | P20: =SUM(C20:N20) -> 39 | R20: 1700-1800 | S20: =SUM(C50:C53) -> 17 | T20: =SUM(D50:D53) -> 8 | U20: =SUM(E50:E53) -> 33 | V20: =SUM(F50:F53) -> 10 | W20: =SUM(G50:G53) -> 2 | X20: =SUM(H50:H53) -> 1 | Y20: =SUM(I50:I53) -> 16 | Z20: =SUM(J50:J53) -> 1 | ... AF20: =SUM(P50:P53) -> 248
B21: 09.45 - 10.00 | C21: 4 | D21: 0 | E21: 2 | F21: 3 | G21: 0 | H21: 0 | I21: 1 | J21: 0 | K21: 0 | L21: 0 | M21: 35 | N21: 0 | O21: =SUM(C21:L21,N21) -> 10 | P21: =SUM(C21:N21) -> 45 | R21: 1800-1900 | S21: =SUM(C54:C57) -> 19 | T21: =SUM(D54:D57) -> 8 | U21: =SUM(E54:E57) -> 33 | V21: =SUM(F54:F57) -> 11 | W21: =SUM(G54:G57) -> 0 | X21: =SUM(H54:H57) -> 0 | Y21: =SUM(I54:I57) -> 17 | Z21: =SUM(J54:J57) -> 2 | ... AF21: =SUM(P54:P57) -> 194
B22: 10.00 - 10.15 | C22: 1 | D22: 0 | E22: 1 | F22: 1 | G22: 0 | H22: 0 | I22: 5 | J22: 0 | K22: 0 | L22: 0 | M22: 35 | N22: 0 | O22: =SUM(C22:L22,N22) -> 8 | P22: =SUM(C22:N22) -> 43 | R22: AM Peak Hr | S22: =MAX(S10:S12) -> 14 | T22: =MAX(T10:T12) -> 5 | U22: =MAX(U10:U12) -> 21 | V22: =MAX(V10:V12) -> 12 | W22: =MAX(W10:W12) -> 0 | X22: =MAX(X10:X12) -> 0 | Y22: =MAX(Y10:Y12) -> 4 | Z22: =MAX(Z10:Z12) -> 1 | ... AF22: =MAX(AF10:AF12) -> 173
B23: 10.15 - 10.30 | C23: 7 | D23: 0 | E23: 2 | F23: 2 | G23: 0 | H23: 0 | I23: 5 | J23: 0 | K23: 0 | L23: 0 | M23: 30 | N23: 0 | O23: =SUM(C23:L23,N23) -> 16 | P23: =SUM(C23:N23) -> 46 | R23: IP Peak Hr | S23: =MAX(S13:S18) -> 15 | T23: =MAX(T13:T18) -> 7 | U23: =MAX(U13:U18) -> 28 | V23: =MAX(V13:V18) -> 13 | W23: =MAX(W13:W18) -> 2 | X23: =MAX(X13:X18) -> 1 | Y23: =MAX(Y13:Y18) -> 20 | Z23: =MAX(Z13:Z18) -> 2 | ... AF23: =MAX(AF13:AF18) -> 206
B24: 10.30 - 10.45 | C24: 6 | D24: 1 | E24: 5 | F24: 5 | G24: 0 | H24: 0 | I24: 2 | J24: 0 | K24: 0 | L24: 0 | M24: 41 | N24: 0 | O24: =SUM(C24:L24,N24) -> 19 | P24: =SUM(C24:N24) -> 60 | R24: PM Peak Hr | S24: =MAX(S19:S21) -> 19 | T24: =MAX(T19:T21) -> 8 | U24: =MAX(U19:U21) -> 33 | V24: =MAX(V19:V21) -> 11 | W24: =MAX(W19:W21) -> 2 | X24: =MAX(X19:X21) -> 1 | Y24: =MAX(Y19:Y21) -> 17 | Z24: =MAX(Z19:Z21) -> 2 | ... AF24: =MAX(AF19:AF21) -> 248
B25: 10.45 - 11.00 | C25: 1 | D25: 0 | E25: 2 | F25: 3 | G25: 0 | H25: 0 | I25: 3 | J25: 0 | K25: 0 | L25: 0 | M25: 22 | N25: 0 | O25: =SUM(C25:L25,N25) -> 9 | P25: =SUM(C25:N25) -> 31 | R25: AM Period | S25: =SUM(S10:S12) -> 24 | T25: =SUM(T10:T12) -> 8 | U25: =SUM(U10:U12) -> 43 | V25: =SUM(V10:V12) -> 32 | W25: =SUM(W10:W12) -> 0 | X25: =SUM(X10:X12) -> 0 | Y25: =SUM(Y10:Y12) -> 8 | Z25: =SUM(Z10:Z12) -> 1 | ... AF25: =SUM(AF10:AF12) -> 485
B26: 11.00 - 11.15 | C26: 2 | D26: 0 | E26: 0 | F26: 7 | G26: 2 | H26: 0 | I26: 1 | J26: 1 | K26: 0 | L26: 0 | M26: 23 | N26: 0 | O26: =SUM(C26:L26,N26) -> 13 | P26: =SUM(C26:N26) -> 36 | R26: IP Period | S26: =SUM(S13:S18) -> 67 | T26: =SUM(T13:T18) -> 26 | U26: =SUM(U13:U18) -> 125 | V26: =SUM(V13:V18) -> 64 | W26: =SUM(W13:W18) -> 2 | X26: =SUM(X13:X18) -> 1 | Y26: =SUM(Y13:Y18) -> 81 | Z26: =SUM(Z13:Z18) -> 5 | ... AF26: =SUM(AF13:AF18) -> 1088
B27: 11.15 - 11.30 | C27: 2 | D27: 3 | E27: 10 | F27: 5 | G27: 0 | H27: 0 | I27: 1 | J27: 0 | K27: 0 | L27: 0 | M27: 25 | N27: 0 | O27: =SUM(C27:L27,N27) -> 21 | P27: =SUM(C27:N27) -> 46 | R27: PM Period | S27: =SUM(S19:S21) -> 53 | T27: =SUM(T19:T21) -> 20 | U27: =SUM(U19:U21) -> 86 | V27: =SUM(V19:V21) -> 30 | W27: =SUM(W19:W21) -> 2 | X27: =SUM(X19:X21) -> 2 | Y27: =SUM(Y19:Y21) -> 48 | Z27: =SUM(Z19:Z21) -> 3 | ... AF27: =SUM(AF19:AF21) -> 643
B28: 11.30 - 11.45 | C28: 2 | D28: 2 | E28: 7 | F28: 1 | G28: 0 | H28: 0 | I28: 0 | J28: 1 | K28: 0 | L28: 0 | M28: 25 | N28: 0 | O28: =SUM(C28:L28,N28) -> 13 | P28: =SUM(C28:N28) -> 38 | R28: 12 Hours | S28: =SUM(S10:S21) -> 144 | T28: =SUM(T10:T21) -> 54 | U28: =SUM(U10:U21) -> 254 | V28: =SUM(V10:V21) -> 126 | W28: =SUM(W10:W21) -> 4 | X28: =SUM(X10:X21) -> 3 | Y28: =SUM(Y10:Y21) -> 137 | Z28: =SUM(Z10:Z21) -> 9 | ... AF28: =SUM(AF10:AF21) -> 2216
B29: 11.45 - 12.00 | C29: 5 | D29: 1 | E29: 5 | F29: 0 | G29: 0 | H29: 0 | I29: 0 | J29: 0 | K29: 0 | L29: 0 | M29: 26 | N29: 0 | O29: =SUM(C29:L29,N29) -> 11 | P29: =SUM(C29:N29) -> 37
B30: 12.00 - 12.15 | C30: 3 | D30: 2 | E30: 9 | F30: 2 | G30: 0 | H30: 0 | I30: 3 | J30: 0 | K30: 0 | L30: 0 | M30: 33 | N30: 0 | O30: =SUM(C30:L30,N30) -> 19 | P30: =SUM(C30:N30) -> 52
B31: 12.15 - 12.30 | C31: 1 | D31: 0 | E31: 3 | F31: 2 | G31: 0 | H31: 1 | I31: 1 | J31: 0 | K31: 0 | L31: 0 | M31: 39 | N31: 0 | O31: =SUM(C31:L31,N31) -> 8 | P31: =SUM(C31:N31) -> 47
B32: 12.30 - 12.45 | C32: 2 | D32: 0 | E32: 1 | F32: 2 | G32: 0 | H32: 0 | I32: 6 | J32: 0 | K32: 0 | L32: 0 | M32: 24 | N32: 0 | O32: =SUM(C32:L32,N32) -> 11 | P32: =SUM(C32:N32) -> 35
B33: 12.45 - 13.00 | C33: 1 | D33: 1 | E33: 6 | F33: 1 | G33: 0 | H33: 0 | I33: 1 | J33: 0 | K33: 0 | L33: 0 | M33: 30 | N33: 0 | O33: =SUM(C33:L33,N33) -> 10 | P33: =SUM(C33:N33) -> 40
B34: 13.00 - 13.15 | C34: 2 | D34: 2 | E34: 8 | F34: 3 | G34: 0 | H34: 0 | I34: 7 | J34: 0 | K34: 0 | L34: 0 | M34: 29 | N34: 0 | O34: =SUM(C34:L34,N34) -> 22 | P34: =SUM(C34:N34) -> 51
B35: 13.15 - 13.30 | C35: 3 | D35: 0 | E35: 3 | F35: 2 | G35: 0 | H35: 0 | I35: 2 | J35: 0 | K35: 0 | L35: 0 | M35: 26 | N35: 0 | O35: =SUM(C35:L35,N35) -> 10 | P35: =SUM(C35:N35) -> 36
B36: 13.30 - 13.45 | C36: 3 | D36: 1 | E36: 5 | F36: 3 | G36: 0 | H36: 0 | I36: 5 | J36: 1 | K36: 0 | L36: 0 | M36: 27 | N36: 0 | O36: =SUM(C36:L36,N36) -> 18 | P36: =SUM(C36:N36) -> 45
B37: 13.45 - 14.00 | C37: 2 | D37: 0 | E37: 2 | F37: 4 | G37: 0 | H37: 0 | I37: 4 | J37: 0 | K37: 0 | L37: 0 | M37: 25 | N37: 0 | O37: =SUM(C37:L37,N37) -> 12 | P37: =SUM(C37:N37) -> 37
B38: 14.00 - 14.15 | C38: 3 | D38: 1 | E38: 5 | F38: 1 | G38: 0 | H38: 0 | I38: 3 | J38: 0 | K38: 0 | L38: 0 | M38: 32 | N38: 0 | O38: =SUM(C38:L38,N38) -> 13 | P38: =SUM(C38:N38) -> 45
B39: 14.15 - 14.30 | C39: 2 | D39: 2 | E39: 9 | F39: 1 | G39: 0 | H39: 0 | I39: 3 | J39: 0 | K39: 0 | L39: 0 | M39: 44 | N39: 0 | O39: =SUM(C39:L39,N39) -> 17 | P39: =SUM(C39:N39) -> 61
B40: 14.30 - 14.45 | C40: 3 | D40: 3 | E40: 11 | F40: 4 | G40: 0 | H40: 0 | I40: 7 | J40: 1 | K40: 0 | L40: 0 | M40: 34 | N40: 0 | O40: =SUM(C40:L40,N40) -> 29 | P40: =SUM(C40:N40) -> 63
... B57: 18.45 - 19.00 | C57: 4 | D57: 1 | E57: 4 | F57: 2 | G57: 0 | H57: 0 | I57: 4 | J57: 0 | K57: 0 | L57: 0 | M57: 19 | N57: 0 | O57: =SUM(C57:L57,N57) -> 15 | P57: =SUM(C57:N57) -> 34
B58: Totals | C58: =SUM(C10:C57) -> 144 | D58: =SUM(D10:D57) -> 54 | E58: =SUM(E10:E57) -> 254 | F58: =SUM(F10:F57) -> 126 | G58: =SUM(G10:G57) -> 4 | H58: =SUM(H10:H57) -> 3 | I58: =SUM(I10:I57) -> 137 | J58: =SUM(J10:J57) -> 9 | ... P58: =SUM(P10:P57) -> 2216
...

Sheet 20.08 Mbale-Sironko
B1: Consultancy services for Preparation of Expressway Development Master Plan (EDMP) for Uganda
B2: MANUAL CLASSIFIED COUNT (MCC)
B3: ROAD NAME: | C3: ='19.08 Mbale-Sironko'!C3:G3 -> MCC - C4 - STN120 - MBALE-SIRONKO ROAD
C5: Date | D5: ='20.08 Sironko-Mbale'!D5 -> 20.08.19 | F5: Location | G5: ='19.08 Sironko-Mbale'!G5:H5 -> xxx | J5: Surveyor | K5: ='19.08 Sironko-Mbale'!K5:L5 -> xxx
C6: Dir. From | D6: ='19.08 Mbale-Sironko'!D6:E6 -> Mbale | F6: Dir. To | G6: ='19.08 Mbale-Sironko'!G6:H6 -> Sironko | J6: Supervisor | K6: ='19.08 Sironko-Mbale'!K6:L6 -> xxx
B8: Time / Veh Type | R8: SUMMARY TRAFFIC VOLUMES
C9: 1. Car | D9: 2. Station Wagon | E9: 3. Pickups | F9: 4. Minibus, matatu | G9: 5. Medium bus | H9: 6. Large Bus | I9: 7. Light Truck | J9: 8. Medium Truck | K9: 9. Heavy truck | L9: 10. Truck Trailer | M9: 11. Motor cycles | N9: 12. Tractors | O9: Total Excl M/Cycles | P9: Total All | R9: Time | S9: 1. Car | T9: 2. Station Wagon | U9: 3. Pickups | V9: 4. Minibus, matatu | W9: 5. Medium bus | X9: 6. Large Bus | Y9: 7. Light Truck | Z9: 8. Medium Truck | AA9: 9. Heavy truck | AB9: 10. Truck Trailer | AC9: 11. Motorcycles | AD9: 12. Tractors, Graders | AE9: Total Excl M/ Cycles | AF9: Total All
B10: 07.00 - 07.15 | C10: 1 | D10: 0 | E10: 0 | F10: 1 | G10: 0 | H10: 0 | I10: 0 | J10: 0 | K10: 0 | L10: 0 | M10: 2 | N10: 0 | O10: =SUM(C10:L10,N10) -> 2 | P10: =SUM(C10:N10) -> 4 | R10: 0700-0800 | S10: =SUM(C10:C13) -> 4 | T10: =SUM(D10:D13) -> 2 | U10: =SUM(E10:E13) -> 9 | V10: =SUM(F10:F13) -> 3 | W10: =SUM(G10:G13) -> 1 | X10: =SUM(H10:H13) -> 0 | Y10: =SUM(I10:I13) -> 9 | Z10: =SUM(J10:J13) -> 1 | ... AF10: =SUM(P10:P13) -> 82
B11: 07.15 - 07.30 | C11: 1 | D11: 0 | E11: 0 | F11: 1 | G11: 0 | H11: 0 | I11: 3 | J11: 0 | K11: 0 | L11: 0 | M11: 13 | N11: 0 | O11: =SUM(C11:L11,N11) -> 5 | P11: =SUM(C11:N11) -> 18 | R11: 0800-0900 | S11: =SUM(C14:C17) -> 13 | T11: =SUM(D14:D17) -> 4 | U11: =SUM(E14:E17) -> 20 | V11: =SUM(F14:F17) -> 13 | W11: =SUM(G14:G17) -> 0 | X11: =SUM(H14:H17) -> 2 | Y11: =SUM(I14:I17) -> 7 | Z11: =SUM(J14:J17) -> 0 | ... AF11: =SUM(P14:P17) -> 155
B12: 07.30 - 07.45 | C12: 1 | D12: 0 | E12: 2 | F12: 0 | G12: 1 | H12: 0 | I12: 3 | J12: 0 | K12: 0 | L12: 0 | M12: 15 | N12: 0 | O12: =SUM(C12:L12,N12) -> 7 | P12: =SUM(C12:N12) -> 22 | R12: 0900-1000 | S12: =SUM(C18:C21) -> 15 | T12: =SUM(D18:D21) -> 6 | U12: =SUM(E18:E21) -> 25 | V12: =SUM(F18:F21) -> 7 | W12: =SUM(G18:G21) -> 1 | X12: =SUM(H18:H21) -> 0 | Y12: =SUM(I18:I21) -> 9 | Z12: =SUM(J18:J21) -> 0 | ... AF12: =SUM(P18:P21) -> 189
B13: 07.45 - 08.00 | C13: 1 | D13: 2 | E13: 7 | F13: 1 | G13: 0 | H13: 0 | I13: 3 | J13: 1 | K13: 0 | L13: 0 | M13: 23 | N13: 0 | O13: =SUM(C13:L13,N13) -> 15 | P13: =SUM(C13:N13) -> 38 | R13: 1000-1100 | S13: =SUM(C22:C25) -> 22 | T13: =SUM(D22:D25) -> 6 | U13: =SUM(E22:E25) -> 25 | V13: =SUM(F22:F25) -> 2 | W13: =SUM(G22:G25) -> 0 | X13: =SUM(H22:H25) -> 0 | Y13: =SUM(I22:I25) -> 13 | Z13: =SUM(J22:J25) -> 0 | ... AF13: =SUM(P22:P25) -> 209
B14: 08.00 - 08.15 | C14: 1 | D14: 1 | E14: 6 | F14: 2 | G14: 0 | H14: 1 | I14: 2 | J14: 0 | K14: 0 | L14: 0 | M14: 20 | N14: 0 | O14: =SUM(C14:L14,N14) -> 13 | P14: =SUM(C14:N14) -> 33 | R14: 1100-1200 | S14: =SUM(C26:C29) -> 13 | T14: =SUM(D26:D29) -> 3 | U14: =SUM(E26:E29) -> 21 | V14: =SUM(F26:F29) -> 7 | W14: =SUM(G26:G29) -> 1 | X14: =SUM(H26:H29) -> 0 | Y14: =SUM(I26:I29) -> 5 | Z14: =SUM(J26:J29) -> 2 | ... AF14: =SUM(P26:P29) -> 179
B15: 08.15 - 08.30 | C15: 2 | D15: 1 | E15: 4 | F15: 3 | G15: 0 | H15: 1 | I15: 2 | J15: 0 | K15: 0 | L15: 0 | M15: 24 | N15: 0 | O15: =SUM(C15:L15,N15) -> 13 | P15: =SUM(C15:N15) -> 37 | R15: 1200-1300 | S15: =SUM(C30:C33) -> 17 | T15: =SUM(D30:D33) -> 5 | U15: =SUM(E30:E33) -> 23 | V15: =SUM(F30:F33) -> 12 | W15: =SUM(G30:G33) -> 1 | X15: =SUM(H30:H33) -> 1 | Y15: =SUM(I30:I33) -> 10 | Z15: =SUM(J30:J33) -> 0 | ... AF15: =SUM(P30:P33) -> 195
B16: 08.30 - 08.45 | C16: 7 | D16: 1 | E16: 5 | F16: 5 | G16: 0 | H16: 0 | I16: 1 | J16: 0 | K16: 0 | L16: 0 | M16: 26 | N16: 0 | O16: =SUM(C16:L16,N16) -> 19 | P16: =SUM(C16:N16) -> 45 | R16: 1300-1400 | S16: =SUM(C34:C37) -> 12 | T16: =SUM(D34:D37) -> 5 | U16: =SUM(E34:E37) -> 25 | V16: =SUM(F34:F37) -> 7 | W16: =SUM(G34:G37) -> 2 | X16: =SUM(H34:H37) -> 0 | Y16: =SUM(I34:I37) -> 12 | Z16: =SUM(J34:J37) -> 0 | ... AF16: =SUM(P34:P37) -> 186
B17: 08.45 - 9.00 | C17: 3 | D17: 1 | E17: 5 | F17: 3 | G17: 0 | H17: 0 | I17: 2 | J17: 0 | K17: 0 | L17: 0 | M17: 26 | N17: 0 | O17: =SUM(C17:L17,N17) -> 14 | P17: =SUM(C17:N17) -> 40 | R17: 1400-1500 | S17: =SUM(C38:C41) -> 5 | T17: =SUM(D38:D41) -> 8 | U17: =SUM(E38:E41) -> 29 | V17: =SUM(F38:F41) -> 8 | W17: =SUM(G38:G41) -> 0 | X17: =SUM(H38:H41) -> 0 | Y17: =SUM(I38:I41) -> 9 | Z17: =SUM(J38:J41) -> 1 | ... AF17: =SUM(P38:P41) -> 174
B18: 09.00 - 09.15 | C18: 4 | D18: 2 | E18: 8 | F18: 3 | G18: 0 | H18: 0 | I18: 2 | J18: 0 | K18: 0 | L18: 0 | M18: 36 | N18: 0 | O18: =SUM(C18:L18,N18) -> 19 | P18: =SUM(C18:N18) -> 55 | R18: 1500-1600 | S18: =SUM(C42:C45) -> 7 | T18: =SUM(D42:D45) -> 7 | U18: =SUM(E42:E45) -> 28 | V18: =SUM(F42:F45) -> 10 | W18: =SUM(G42:G45) -> 0 | X18: =SUM(H42:H45) -> 0 | Y18: =SUM(I42:I45) -> 9 | Z18: =SUM(J42:J45) -> 2 | ... AF18: =SUM(P42:P45) -> 165
B19: 09.15 - 09.30 | C19: 2 | D19: 1 | E19: 4 | F19: 1 | G19: 0 | H19: 0 | I19: 1 | J19: 0 | K19: 0 | L19: 0 | M19: 23 | N19: 0 | O19: =SUM(C19:L19,N19) -> 9 | P19: =SUM(C19:N19) -> 32 | R19: 1600-1700 | S19: =SUM(C46:C49) -> 21 | T19: =SUM(D46:D49) -> 2 | U19: =SUM(E46:E49) -> 13 | V19: =SUM(F46:F49) -> 8 | W19: =SUM(G46:G49) -> 0 | X19: =SUM(H46:H49) -> 0 | Y19: =SUM(I46:I49) -> 14 | Z19: =SUM(J46:J49) -> 1 | ... AF19: =SUM(P46:P49) -> 193
B20: 09.30 - 09.45 | C20: 6 | D20: 1 | E20: 4 | F20: 2 | G20: 0 | H20: 0 | I20: 3 | J20: 0 | K20: 0 | L20: 0 | M20: 39 | N20: 0 | O20: =SUM(C20:L20,N20) -> 16 | P20: =SUM(C20:N20) -> 55 | R20: 1700-1800 | S20: =SUM(C50:C53) -> 14 | T20: =SUM(D50:D53) -> 6 | U20: =SUM(E50:E53) -> 24 | V20: =SUM(F50:F53) -> 12 | W20: =SUM(G50:G53) -> 0 | X20: =SUM(H50:H53) -> 0 | Y20: =SUM(I50:I53) -> 13 | Z20: =SUM(J50:J53) -> 1 | ... AF20: =SUM(P50:P53) -> 211
B21: 09.45 - 10.00 | C21: 3 | D21: 2 | E21: 9 | F21: 1 | G21: 1 | H21: 0 | I21: 3 | J21: 0 | K21: 0 | L21: 0 | M21: 28 | N21: 0 | O21: =SUM(C21:L21,N21) -> 19 | P21: =SUM(C21:N21) -> 47 | R21: 1800-1900 | S21: =SUM(C54:C57) -> 15 | T21: =SUM(D54:D57) -> 7 | U21: =SUM(E54:E57) -> 29 | V21: =SUM(F54:F57) -> 10 | W21: =SUM(G54:G57) -> 0 | X21: =SUM(H54:H57) -> 0 | Y21: =SUM(I54:I57) -> 14 | Z21: =SUM(J54:J57) -> 1 | ... AF21: =SUM(P54:P57) -> 206
B22: 10.00 - 10.15 | C22: 5 | D22: 2 | E22: 8 | F22: 0 | G22: 0 | H22: 0 | I22: 4 | J22: 0 | K22: 0 | L22: 0 | M22: 31 | N22: 0 | O22: =SUM(C22:L22,N22) -> 19 | P22: =SUM(C22:N22) -> 50 | R22: AM Peak Hr | S22: =MAX(S10:S12) -> 15 | T22: =MAX(T10:T12) -> 6 | U22: =MAX(U10:U12) -> 25 | V22: =MAX(V10:V12) -> 13 | W22: =MAX(W10:W12) -> 1 | X22: =MAX(X10:X12) -> 2 | Y22: =MAX(Y10:Y12) -> 9 | Z22: =MAX(Z10:Z12) -> 1 | ... AF22: =MAX(AF10:AF12) -> 189
B23: 10.15 - 10.30 | C23: 2 | D23: 1 | E23: 6 | F23: 2 | G23: 0 | H23: 0 | I23: 1 | J23: 0 | K23: 0 | L23: 0 | M23: 34 | N23: 0 | O23: =SUM(C23:L23,N23) -> 12 | P23: =SUM(C23:N23) -> 46 | R23: IP Peak Hr | S23: =MAX(S13:S18) -> 22 | T23: =MAX(T13:T18) -> 8 | U23: =MAX(U13:U18) -> 29 | V23: =MAX(V13:V18) -> 12 | W23: =MAX(W13:W18) -> 2 | X23: =MAX(X13:X18) -> 1 | Y23: =MAX(Y13:Y18) -> 13 | Z23: =MAX(Z13:Z18) -> 2 | ... AF23: =MAX(AF13:AF18) -> 209
B24: 10.30 - 10.45 | C24: 4 | D24: 2 | E24: 7 | F24: 0 | G24: 0 | H24: 0 | I24: 4 | J24: 0 | K24: 0 | L24: 0 | M24: 50 | N24: 0 | O24: =SUM(C24:L24,N24) -> 17 | P24: =SUM(C24:N24) -> 67 | R24: PM Peak Hr | S24: =MAX(S19:S21) -> 21 | T24: =MAX(T19:T21) -> 7 | U24: =MAX(U19:U21) -> 29 | V24: =MAX(V19:V21) -> 12 | W24: =MAX(W19:W21) -> 0 | X24: =MAX(X19:X21) -> 0 | Y24: =MAX(Y19:Y21) -> 14 | Z24: =MAX(Z19:Z21) -> 1 | ... AF24: =MAX(AF19:AF21) -> 211
B25: 10.45 - 11.00 | C25: 11 | D25: 1 | E25: 4 | F25: 0 | G25: 0 | H25: 0 | I25: 4 | J25: 0 | K25: 0 | L25: 0 | M25: 26 | N25: 0 | O25: =SUM(C25:L25,N25) -> 20 | P25: =SUM(C25:N25) -> 46 | R25: AM Period | S25: =SUM(S10:S12) -> 32 | T25: =SUM(T10:T12) -> 12 | U25: =SUM(U10:U12) -> 54 | V25: =SUM(V10:V12) -> 23 | W25: =SUM(W10:W12) -> 2 | X25: =SUM(X10:X12) -> 2 | Y25: =SUM(Y10:Y12) -> 25 | Z25: =SUM(Z10:Z12) -> 1 | ... AF25: =SUM(AF10:AF12) -> 426
B26: 11.00 - 11.15 | C26: 3 | D26: 1 | E26: 6 | F26: 0 | G26: 0 | H26: 0 | I26: 2 | J26: 0 | K26: 0 | L26: 0 | M26: 32 | N26: 0 | O26: =SUM(C26:L26,N26) -> 12 | P26: =SUM(C26:N26) -> 44 | R26: IP Period | S26: =SUM(S13:S18) -> 76 | T26: =SUM(T13:T18) -> 34 | U26: =SUM(U13:U18) -> 151 | V26: =SUM(V13:V18) -> 46 | W26: =SUM(W13:W18) -> 4 | X26: =SUM(X13:X18) -> 1 | Y26: =SUM(Y13:Y18) -> 58 | Z26: =SUM(Z13:Z18) -> 5 | ... AF26: =SUM(AF13:AF18) -> 1108
B27: 11.15 - 11.30 | C27: 6 | D27: 1 | E27: 6 | F27: 4 | G27: 0 | H27: 0 | I27: 2 | J27: 0 | K27: 0 | L27: 0 | M27: 27 | N27: 0 | O27: =SUM(C27:L27,N27) -> 19 | P27: =SUM(C27:N27) -> 46 | R27: PM Period | S27: =SUM(S19:S21) -> 50 | T27: =SUM(T19:T21) -> 15 | U27: =SUM(U19:U21) -> 66 | V27: =SUM(V19:V21) -> 30 | W27: =SUM(W19:W21) -> 0 | X27: =SUM(X19:X21) -> 0 | Y27: =SUM(Y19:Y21) -> 41 | Z27: =SUM(Z19:Z21) -> 3 | ... AF27: =SUM(AF19:AF21) -> 610
B28: 11.30 - 11.45 | C28: 1 | D28: 1 | E28: 6 | F28: 3 | G28: 0 | H28: 0 | I28: 1 | J28: 2 | K28: 0 | L28: 0 | M28: 38 | N28: 0 | O28: =SUM(C28:L28,N28) -> 14 | P28: =SUM(C28:N28) -> 52 | R28: 12 Hours | S28: =SUM(S10:S21) -> 158 | T28: =SUM(T10:T21) -> 61 | U28: =SUM(U10:U21) -> 271 | V28: =SUM(V10:V21) -> 99 | W28: =SUM(W10:W21) -> 6 | X28: =SUM(X10:X21) -> 3 | Y28: =SUM(Y10:Y21) -> 124 | Z28: =SUM(Z10:Z21) -> 9 | ... AF28: =SUM(AF10:AF21) -> 2144
B29: 11.45 - 12.00 | C29: 3 | D29: 0 | E29: 3 | F29: 0 | G29: 1 | H29: 0 | I29: 0 | J29: 0 | K29: 0 | L29: 0 | M29: 30 | N29: 0 | O29: =SUM(C29:L29,N29) -> 7 | P29: =SUM(C29:N29) -> 37
B30: 12.00 - 12.15 | C30: 5 | D30: 0 | E30: 2 | F30: 3 | G30: 0 | H30: 0 | I30: 1 | J30: 0 | K30: 0 | L30: 0 | M30: 22 | N30: 0 | O30: =SUM(C30:L30,N30) -> 11 | P30: =SUM(C30:N30) -> 33
B31: 12.15 - 12.30 | C31: 5 | D31: 1 | E31: 5 | F31: 3 | G31: 0 | H31: 0 | I31: 2 | J31: 0 | K31: 0 | L31: 0 | M31: 34 | N31: 0 | O31: =SUM(C31:L31,N31) -> 16 | P31: =SUM(C31:N31) -> 50
B32: 12.30 - 12.45 | C32: 5 | D32: 3 | E32: 10 | F32: 4 | G32: 1 | H32: 1 | I32: 5 | J32: 0 | K32: 1 | L32: 0 | M32: 31 | N32: 0 | O32: =SUM(C32:L32,N32) -> 30 | P32: =SUM(C32:N32) -> 61
B33: 12.45 - 13.00 | C33: 2 | D33: 1 | E33: 6 | F33: 2 | G33: 0 | H33: 0 | I33: 2 | J33: 0 | K33: 1 | L33: 0 | M33: 37 | N33: 0 | O33: =SUM(C33:L33,N33) -> 14 | P33: =SUM(C33:N33) -> 51
B34: 13.00 - 13.15 | C34: 4 | D34: 3 | E34: 13 | F34: 1 | G34: 1 | H34: 0 | I34: 3 | J34: 0 | K34: 0 | L34: 0 | M34: 30 | N34: 0 | O34: =SUM(C34:L34,N34) -> 25 | P34: =SUM(C34:N34) -> 55
B35: 13.15 - 13.30 | C35: 1 | D35: 0 | E35: 1 | F35: 1 | G35: 1 | H35: 0 | I35: 2 | J35: 0 | K35: 0 | L35: 0 | M35: 28 | N35: 0 | O35: =SUM(C35:L35,N35) -> 6 | P35: =SUM(C35:N35) -> 34
B36: 13.30 - 13.45 | C36: 3 | D36: 1 | E36: 5 | F36: 1 | G36: 0 | H36: 0 | I36: 2 | J36: 0 | K36: 0 | L36: 0 | M36: 40 | N36: 0 | O36: =SUM(C36:L36,N36) -> 12 | P36: =SUM(C36:N36) -> 52
B37: 13.45 - 14.00 | C37: 4 | D37: 1 | E37: 6 | F37: 4 | G37: 0 | H37: 0 | I37: 5 | J37: 0 | K37: 0 | L37: 0 | M37: 25 | N37: 0 | O37: =SUM(C37:L37,N37) -> 20 | P37: =SUM(C37:N37) -> 45
B38: 14.00 - 14.15 | C38: 3 | D38: 2 | E38: 7 | F38: 2 | G38: 0 | H38: 0 | I38: 0 | J38: 0 | K38: 0 | L38: 0 | M38: 35 | N38: 0 | O38: =SUM(C38:L38,N38) -> 14 | P38: =SUM(C38:N38) -> 49
B39: 14.15 - 14.30 | C39: 0 | D39: 2 | E39: 7 | F39: 1 | G39: 0 | H39: 0 | I39: 3 | J39: 0 | K39: 0 | L39: 0 | M39: 25 | N39: 0 | O39: =SUM(C39:L39,N39) -> 13 | P39: =SUM(C39:N39) -> 38
B40: 14.30 - 14.45 | C40: 1 | D40: 2 | E40: 7 | F40: 2 | G40: 0 | H40: 0 | I40: 4 | J40: 1 | K40: 0 | L40: 0 | M40: 29 | N40: 0 | O40: =SUM(C40:L40,N40) -> 17 | P40: =SUM(C40:N40) -> 46
... B57: 18.45 - 19.00 | C57: 2 | D57: 0 | E57: 1 | F57: 1 | G57: 0 | H57: 0 | I57: 1 | J57: 1 | K57: 0 | L57: 0 | M57: 12 | N57: 0 | O57: =SUM(C57:L57,N57) -> 6 | P57: =SUM(C57:N57) -> 18
B58: Totals | C58: =SUM(C10:C57) -> 158 | D58: =SUM(D10:D57) -> 61 | E58: =SUM(E10:E57) -> 271 | F58: =SUM(F10:F57) -> 99 | G58: =SUM(G10:G57) -> 6 | H58: =SUM(H10:H57) -> 3 | I58: =SUM(I10:I57) -> 124 | J58: =SUM(J10:J57) -> 9 | ... P58: =SUM(P10:P57) -> 2144
...

Sheet 21.08 Sironko-Mbale
B1: Consultancy services for Preparation of Expressway Development Master Plan (EDMP) for Uganda
B2: MANUAL CLASSIFIED COUNT (MCC)
B3: ROAD NAME: | C3: ='19.08 Sironko-Mbale'!C3:G3 -> MCC - C4 - STN120 - MBALE-SIRONKO ROAD
C5: Date | D5: 21.08.19 | F5: Location | G5: ='19.08 Sironko-Mbale'!G5:H5 -> xxx | J5: Surveyor | K5: ='19.08 Sironko-Mbale'!K5:L5 -> xxx
C6: Dir. From | D6: ='19.08 Sironko-Mbale'!D6:E6 -> Sironko | F6: Dir. To | G6: ='19.08 Sironko-Mbale'!G6:H6 -> Mbale | J6: Supervisor | K6: ='19.08 Sironko-Mbale'!K6:L6 -> xxx
B8: Time / Veh Type | R8: SUMMARY TRAFFIC VOLUMES
C9: 1. Car | D9: 2. Station Wagon | E9: 3. Pickups | F9: 4. Minibus, matatu | G9: 5. Medium bus | H9: 6. Large Bus | I9: 7. Light Truck | J9: 8. Medium Truck | K9: 9. Heavy truck | L9: 10. Truck Trailer | M9: 11. Motor cycles | N9: 12. Tractors | O9: Total Excl M/Cycles | P9: Total All | R9: Time | S9: 1. Car | T9: 2. Station Wagon | U9: 3. Pickups | V9: 4. Minibus, matatu | W9: 5. Medium bus | X9: 6. Large Bus | Y9: 7. Light Truck | Z9: 8. Medium Truck | AA9: 9. Heavy truck | AB9: 10. Truck Trailer | AC9: 11. Motorcycles | AD9: 12. Tractors, Graders | AE9: Total Excl M/ Cycles | AF9: Total All
B10: 07.00 - 07.15 | C10: 2 | D10: 0 | E10: 1 | F10: 0 | G10: 0 | H10: 0 | I10: 2 | J10: 0 | K10: 0 | L10: 0 | M10: 13 | N10: 0 | O10: =SUM(C10:L10,N10) -> 5 | P10: =SUM(C10:N10) -> 18 | R10: 0700-0800 | S10: =SUM(C10:C13) -> 7 | T10: =SUM(D10:D13) -> 1 | U10: =SUM(E10:E13) -> 9 | V10: =SUM(F10:F13) -> 10 | W10: =SUM(G10:G13) -> 0 | X10: =SUM(H10:H13) -> 0 | Y10: =SUM(I10:I13) -> 4 | Z10: =SUM(J10:J13) -> 0 | ... AF10: =SUM(P10:P13) -> 127
B11: 07.15 - 07.30 | C11: 3 | D11: 1 | E11: 6 | F11: 7 | G11: 0 | H11: 0 | I11: 1 | J11: 0 | K11: 0 | L11: 0 | M11: 12 | N11: 0 | O11: =SUM(C11:L11,N11) -> 18 | P11: =SUM(C11:N11) -> 30 | R11: 0800-0900 | S11: =SUM(C14:C17) -> 15 | T11: =SUM(D14:D17) -> 6 | U11: =SUM(E14:E17) -> 25 | V11: =SUM(F14:F17) -> 13 | W11: =SUM(G14:G17) -> 0 | X11: =SUM(H14:H17) -> 0 | Y11: =SUM(I14:I17) -> 7 | Z11: =SUM(J14:J17) -> 0 | ... AF11: =SUM(P14:P17) -> 175
B12: 07.30 - 07.45 | C12: 0 | D12: 0 | E12: 0 | F12: 0 | G12: 0 | H12: 0 | I12: 1 | J12: 0 | K12: 0 | L12: 0 | M12: 33 | N12: 0 | O12: =SUM(C12:L12,N12) -> 1 | P12: =SUM(C12:N12) -> 34 | R12: 0900-1000 | S12: =SUM(C18:C21) -> 13 | T12: =SUM(D18:D21) -> 7 | U12: =SUM(E18:E21) -> 31 | V12: =SUM(F18:F21) -> 8 | W12: =SUM(G18:G21) -> 0 | X12: =SUM(H18:H21) -> 1 | Y12: =SUM(I18:I21) -> 4 | Z12: =SUM(J18:J21) -> 1 | ... AF12: =SUM(P18:P21) -> 176
B13: 07.45 - 08.00 | C13: 2 | D13: 0 | E13: 2 | F13: 3 | G13: 0 | H13: 0 | I13: 0 | J13: 0 | K13: 0 | L13: 0 | M13: 38 | N13: 0 | O13: =SUM(C13:L13,N13) -> 7 | P13: =SUM(C13:N13) -> 45 | R13: 1000-1100 | S13: =SUM(C22:C25) -> 15 | T13: =SUM(D22:D25) -> 6 | U13: =SUM(E22:E25) -> 25 | V13: =SUM(F22:F25) -> 14 | W13: =SUM(G22:G25) -> 1 | X13: =SUM(H22:H25) -> 0 | Y13: =SUM(I22:I25) -> 5 | Z13: =SUM(J22:J25) -> 0 | ... AF13: =SUM(P22:P25) -> 182
B14: 08.00 - 08.15 | C14: 2 | D14: 0 | E14: 1 | F14: 2 | G14: 0 | H14: 0 | I14: 1 | J14: 0 | K14: 0 | L14: 0 | M14: 38 | N14: 0 | O14: =SUM(C14:L14,N14) -> 6 | P14: =SUM(C14:N14) -> 44 | R14: 1100-1200 | S14: =SUM(C26:C29) -> 12 | T14: =SUM(D26:D29) -> 5 | U14: =SUM(E26:E29) -> 21 | V14: =SUM(F26:F29) -> 11 | W14: =SUM(G26:G29) -> 2 | X14: =SUM(H26:H29) -> 0 | Y14: =SUM(I26:I29) -> 5 | Z14: =SUM(J26:J29) -> 0 | ... AF14: =SUM(P26:P29) -> 165
B15: 08.15 - 08.30 | C15: 7 | D15: 1 | E15: 6 | F15: 1 | G15: 0 | H15: 0 | I15: 1 | J15: 0 | K15: 0 | L15: 0 | M15: 24 | N15: 0 | O15: =SUM(C15:L15,N15) -> 16 | P15: =SUM(C15:N15) -> 40 | R15: 1200-1300 | S15: =SUM(C30:C33) -> 13 | T15: =SUM(D30:D33) -> 9 | U15: =SUM(E30:E33) -> 34 | V15: =SUM(F30:F33) -> 15 | W15: =SUM(G30:G33) -> 0 | X15: =SUM(H30:H33) -> 1 | Y15: =SUM(I30:I33) -> 17 | Z15: =SUM(J30:J33) -> 0 | ... AF15: =SUM(P30:P33) -> 199
B16: 08.30 - 08.45 | C16: 2 | D16: 3 | E16: 11 | F16: 5 | G16: 0 | H16: 0 | I16: 2 | J16: 0 | K16: 0 | L16: 0 | M16: 27 | N16: 0 | O16: =SUM(C16:L16,N16) -> 23 | P16: =SUM(C16:N16) -> 50 | R16: 1300-1400 | S16: =SUM(C34:C37) -> 11 | T16: =SUM(D34:D37) -> 5 | U16: =SUM(E34:E37) -> 24 | V16: =SUM(F34:F37) -> 14 | W16: =SUM(G34:G37) -> 0 | X16: =SUM(H34:H37) -> 0 | Y16: =SUM(I34:I37) -> 14 | Z16: =SUM(J34:J37) -> 1 | ... AF16: =SUM(P34:P37) -> 172
B17: 08.45 - 9.00 | C17: 4 | D17: 2 | E17: 7 | F17: 5 | G17: 0 | H17: 0 | I17: 3 | J17: 0 | K17: 0 | L17: 0 | M17: 20 | N17: 0 | O17: =SUM(C17:L17,N17) -> 21 | P17: =SUM(C17:N17) -> 41 | R17: 1400-1500 | S17: =SUM(C38:C41) -> 10 | T17: =SUM(D38:D41) -> 9 | U17: =SUM(E38:E41) -> 36 | V17: =SUM(F38:F41) -> 15 | W17: =SUM(G38:G41) -> 0 | X17: =SUM(H38:H41) -> 0 | Y17: =SUM(I38:I41) -> 12 | Z17: =SUM(J38:J41) -> 2 | ... AF17: =SUM(P38:P41) -> 177
B18: 09.00 - 09.15 | C18: 3 | D18: 0 | E18: 3 | F18: 2 | G18: 0 | H18: 0 | I18: 2 | J18: 1 | K18: 0 | L18: 0 | M18: 24 | N18: 0 | O18: =SUM(C18:L18,N18) -> 11 | P18: =SUM(C18:N18) -> 35 | R18: 1500-1600 | S18: =SUM(C42:C45) -> 17 | T18: =SUM(D42:D45) -> 6 | U18: =SUM(E42:E45) -> 22 | V18: =SUM(F42:F45) -> 22 | W18: =SUM(G42:G45) -> 0 | X18: =SUM(H42:H45) -> 0 | Y18: =SUM(I42:I45) -> 16 | Z18: =SUM(J42:J45) -> 1 | ... AF18: =SUM(P42:P45) -> 174
B19: 09.15 - 09.30 | C19: 3 | D19: 1 | E19: 6 | F19: 2 | G19: 0 | H19: 0 | I19: 0 | J19: 0 | K19: 0 | L19: 0 | M19: 38 | N19: 0 | O19: =SUM(C19:L19,N19) -> 12 | P19: =SUM(C19:N19) -> 50 | R19: 1600-1700 | S19: =SUM(C46:C49) -> 24 | T19: =SUM(D46:D49) -> 6 | U19: =SUM(E46:E49) -> 27 | V19: =SUM(F46:F49) -> 22 | W19: =SUM(G46:G49) -> 4 | X19: =SUM(H46:H49) -> 0 | Y19: =SUM(I46:I49) -> 17 | Z19: =SUM(J46:J49) -> 4 | ... AF19: =SUM(P46:P49) -> 242
B20: 09.30 - 09.45 | C20: 2 | D20: 4 | E20: 14 | F20: 1 | G20: 0 | H20: 1 | I20: 1 | J20: 0 | K20: 0 | L20: 0 | M20: 17 | N20: 0 | O20: =SUM(C20:L20,N20) -> 23 | P20: =SUM(C20:N20) -> 40 | R20: 1700-1800 | S20: =SUM(C50:C53) -> 33 | T20: =SUM(D50:D53) -> 17 | U20: =SUM(E50:E53) -> 65 | V20: =SUM(F50:F53) -> 24 | W20: =SUM(G50:G53) -> 1 | X20: =SUM(H50:H53) -> 3 | Y20: =SUM(I50:I53) -> 23 | Z20: =SUM(J50:J53) -> 2 | ... AF20: =SUM(P50:P53) -> 315
B21: 09.45 - 10.00 | C21: 5 | D21: 2 | E21: 8 | F21: 3 | G21: 0 | H21: 0 | I21: 1 | J21: 0 | K21: 0 | L21: 0 | M21: 32 | N21: 0 | O21: =SUM(C21:L21,N21) -> 19 | P21: =SUM(C21:N21) -> 51 | R21: 1800-1900 | S21: =SUM(C54:C57) -> 30 | T21: =SUM(D54:D57) -> 10 | U21: =SUM(E54:E57) -> 40 | V21: =SUM(F54:F57) -> 14 | W21: =SUM(G54:G57) -> 0 | X21: =SUM(H54:H57) -> 0 | Y21: =SUM(I54:I57) -> 17 | Z21: =SUM(J54:J57) -> 4 | ... AF21: =SUM(P54:P57) -> 243
B22: 10.00 - 10.15 | C22: 3 | D22: 1 | E22: 5 | F22: 1 | G22: 1 | H22: 0 | I22: 0 | J22: 0 | K22: 0 | L22: 0 | M22: 14 | N22: 0 | O22: =SUM(C22:L22,N22) -> 11 | P22: =SUM(C22:N22) -> 25 | R22: AM Peak Hr | S22: =MAX(S10:S12) -> 15 | T22: =MAX(T10:T12) -> 7 | U22: =MAX(U10:U12) -> 31 | V22: =MAX(V10:V12) -> 13 | W22: =MAX(W10:W12) -> 0 | X22: =MAX(X10:X12) -> 1 | Y22: =MAX(Y10:Y12) -> 7 | Z22: =MAX(Z10:Z12) -> 1 | ... AF22: =MAX(AF10:AF12) -> 176
B23: 10.15 - 10.30 | C23: 4 | D23: 3 | E23: 11 | F23: 3 | G23: 0 | H23: 0 | I23: 2 | J23: 0 | K23: 0 | L23: 0 | M23: 39 | N23: 0 | O23: =SUM(C23:L23,N23) -> 23 | P23: =SUM(C23:N23) -> 62 | R23: IP Peak Hr | S23: =MAX(S13:S18) -> 17 | T23: =MAX(T13:T18) -> 9 | U23: =MAX(U13:U18) -> 36 | V23: =MAX(V13:V18) -> 22 | W23: =MAX(W13:W18) -> 2 | X23: =MAX(X13:X18) -> 1 | Y23: =MAX(Y13:Y18) -> 17 | Z23: =MAX(Z13:Z18) -> 2 | ... AF23: =MAX(AF13:AF18) -> 199
B24: 10.30 - 10.45 | C24: 3 | D24: 1 | E24: 5 | F24: 4 | G24: 0 | H24: 0 | I24: 1 | J24: 0 | K24: 0 | L24: 0 | M24: 34 | N24: 0 | O24: =SUM(C24:L24,N24) -> 14 | P24: =SUM(C24:N24) -> 48 | R24: PM Peak Hr | S24: =MAX(S19:S21) -> 33 | T24: =MAX(T19:T21) -> 17 | U24: =MAX(U19:U21) -> 65 | V24: =MAX(V19:V21) -> 24 | W24: =MAX(W19:W21) -> 4 | X24: =MAX(X19:X21) -> 3 | Y24: =MAX(Y19:Y21) -> 23 | Z24: =MAX(Z19:Z21) -> 4 | ... AF24: =MAX(AF19:AF21) -> 315
B25: 10.45 - 11.00 | C25: 5 | D25: 1 | E25: 4 | F25: 6 | G25: 0 | H25: 0 | I25: 2 | J25: 0 | K25: 0 | L25: 0 | M25: 29 | N25: 0 | O25: =SUM(C25:L25,N25) -> 18 | P25: =SUM(C25:N25) -> 47 | R25: AM Period | S25: =SUM(S10:S12) -> 35 | T25: =SUM(T10:T12) -> 14 | U25: =SUM(U10:U12) -> 65 | V25: =SUM(V10:V12) -> 31 | W25: =SUM(W10:W12) -> 0 | X25: =SUM(X10:X12) -> 1 | Y25: =SUM(Y10:Y12) -> 15 | Z25: =SUM(Z10:Z12) -> 1 | ... AF25: =SUM(AF10:AF12) -> 478
