Workbook
Name Dist: 'ALL DATA'!$S:$S
Name Jtime: 'ALL DATA'!$T:$T
Name Pay: 'ALL DATA'!$Z:$Z
Name Tripfreq: 'ALL DATA'!$U:$U
Name Veh: 'ALL DATA'!$D:$D
Name Veh_Type: '26.10 ISINGIRO-MBARARA'!$D$9:$D$37
Name Veh_Type: '28.10 ISINGIRO-MBARARA'!$D$9:$D$37
Name Veh_Type: 'ALL DATA'!$D$9:$D$37
Name Veh_Type: '[1]25.07 BUSEGA-NATEETE'!$D:$D
Name Veh_Type: '[1]25.07 BUSEGA-NATEETE'!$D:$D
Name Veh_Type: '28.10 MBARARA-ISINGIRO'!$D$9:$D$37
Name zones: #REF!
Name zones: #REF!
Name zones: #REF!
Name Zones_Ndeke: #REF!
Name Zones_Ndeke: #REF!
Name Zones_Ndeke: #REF!

Sheet Analysis
B3: Vehicle OD Sample Proportions | N3: Average Journey Time
B4: Vehicle Types | C4: OD Sample | D4: OD Sample, % | N4: Journey Time Range (Hrs) | O4: Cummu-lative | P4: No of Vehicles | Q4: No. of Vehicles, %
B5: Car | C5: =COUNTIF('ALL DATA'!$D$9:$D$5000,"1") -> 152 | D5: =C5/$C$17 -> 0.42105263 | N5: 0-0.25 | O5: =COUNTIF(Jtime,"<=0.25") -> 89 | P5: =O5 -> 89 | Q5: =P5/$O$15 -> 0.26176471
B6: Station Wagon | C6: =COUNTIF('ALL DATA'!$D$9:$D$5000,"2") -> 34 | D6: =C6/$C$17 -> 0.094182825 | N6: 0.25-0.50 | O6: =COUNTIF(Jtime,"<=0.5") -> 209 | P6: =O6-O5 -> 120 | Q6: =P6/$O$15 -> 0.35294118
B7: Pickups | C7: =COUNTIF('ALL DATA'!$D$9:$D$5000,"3") -> 23 | D7: =C7/$C$17 -> 0.063711911 | N7: 0.50-0.75 | O7: =COUNTIF(Jtime,"<=0.75") -> 221 | P7: =O7-O6 -> 12 | Q7: =P7/$O$15 -> 0.035294118
B8: Minibus, matatu | C8: =COUNTIF('ALL DATA'!$D$9:$D$5000,"4") -> 13 | D8: =C8/$C$17 -> 0.03601108 | N8: 0.75-1.00 | O8: =COUNTIF(Jtime,"<=1.0") -> 273 | P8: =O8-O7 -> 52 | Q8: =P8/$O$15 -> 0.15294118
B9: Medium bus | C9: =COUNTIF('ALL DATA'!$D$9:$D$5000,"5") -> 1 | D9: =C9/$C$17 -> 0.0027700831 | N9: 1.00-1.50 | O9: =COUNTIF(Jtime,"<=1.5") -> 293 | P9: =O9-O8 -> 20 | Q9: =P9/$O$15 -> 0.058823529
B10: Large Bus | C10: =COUNTIF('ALL DATA'!$D$9:$D$5000,"6") -> 0 | D10: =C10/$C$17 -> 0 | N10: 1.5-2.0 | O10: =COUNTIF(Jtime,"<=2") -> 319 | P10: =O10-O9 -> 26 | Q10: =P10/$O$15 -> 0.076470588
B11: Light Truck | C11: =COUNTIF('ALL DATA'!$D$9:$D$5000,"7") -> 36 | D11: =C11/$C$17 -> 0.099722992 | N11: 2.0-3.0 | O11: =COUNTIF(Jtime,"<=3") -> 325 | P11: =O11-O10 -> 6 | Q11: =P11/$O$15 -> 0.017647059
B12: Medium Truck | C12: =COUNTIF('ALL DATA'!$D$9:$D$5000,"8") -> 35 | D12: =C12/$C$17 -> 0.096952909 | N12: 3.0-5.0 | O12: =COUNTIF(Jtime,"<=5") -> 335 | P12: =O12-O11 -> 10 | Q12: =P12/$O$15 -> 0.029411765
B13: Heavy truck | C13: =COUNTIF('ALL DATA'!$D$9:$D$5000,"9") -> 2 | D13: =C13/$C$17 -> 0.0055401662 | N13: 5.0-7.5 | O13: =COUNTIF(Jtime,"<=7.5") -> 339 | P13: =O13-O12 -> 4 | Q13: =P13/$O$15 -> 0.011764706
B14: Truck Trailer | C14: =COUNTIF('ALL DATA'!$D$9:$D$5000,"10") -> 1 | D14: =C14/$C$17 -> 0.0027700831 | N14: 7.5-10 | O14: =COUNTIF(Jtime,"<=10") -> 339 | P14: =O14-O13 -> 0 | Q14: =P14/$O$15 -> 0
B15: Motor cycles | C15: =COUNTIF('ALL DATA'!$D$9:$D$5000,"11") -> 64 | D15: =C15/$C$17 -> 0.17728532 | N15: Over 10 | O15: =COUNTIF(Jtime,"<=15") -> 340 | P15: =O15-O14 -> 1 | Q15: =P15/$O$15 -> 0.0029411765
B16: Tractors | C16: =COUNTIF('ALL DATA'!$D$9:$D$5000,"12") -> 0 | D16: =C16/$C$17 -> 0
C17: =SUM(C5:C16) -> 361
N21: Trip Frequency
B22: Journey Purpose | N22: Trip Frequency | O22: No of Vehicles | P22: No. of Vehicles, %
B23: Purpose | C23: Respondents | D23: Percent | N23: More than 2 times every day | O23: =COUNTIF(Tripfreq,"=1") -> 74 | P23: =O23/$O$29 -> 0.2084507
B24: Home-Work | C24: =COUNTIF('ALL DATA'!$R$9:$R$5000,"Home-Work") -> 52 | D24: =C24/$C$29 -> 0.14404432 | N24: Daily (Up and Down) | O24: =COUNTIF(Tripfreq,"=2") -> 129 | P24: =O24/$O$29 -> 0.36338028
B25: Home-Study | C25: =COUNTIF('ALL DATA'!$R$9:$R$369,"Home-Study") -> 18 | D25: =C25/$C$29 -> 0.049861496 | N25: 2/3 times a week | O25: =COUNTIF(Tripfreq,"=3") -> 84 | P25: =O25/$O$29 -> 0.23661972
B26: Work-Home | C26: =COUNTIF('ALL DATA'!$R$9:$R$369,"Work-Home") -> 69 | D26: =C26/$C$29 -> 0.19113573 | N26: Once a week | O26: =COUNTIF(Tripfreq,"=4") -> 44 | P26: =O26/$O$29 -> 0.12394366
B27: Work-Work | C27: =COUNTIF('ALL DATA'!$R$9:$R$369,"Work-Work") -> 47 | D27: =C27/$C$29 -> 0.13019391 | N27: Once a month | O27: =COUNTIF(Tripfreq,"=5") -> 9 | P27: =O27/$O$29 -> 0.025352113
B28: Others | C28: =C29-SUM(C24:C27) -> 175 | D28: =C28/$C$29 -> 0.48476454 | N28: Once in a while | O28: =COUNTIF(Tripfreq,"=6") -> 15 | P28: =O28/$O$29 -> 0.042253521
B29: Total | C29: =C17 -> 361 | O29: =SUM(O23:O28) -> 355
B40: Expressway Use
B41: Response | C41: Number | D41: Percent
B42: Yes | C42: =COUNTIF('ALL DATA'!$Y$9:$Y$5000,"Y") -> 361 | D42: =C42/$C$44 -> 1
B43: No | C43: =C44-C42 -> 0 | D43: =C43/$C$44 -> 0
B44: Total | C44: =C29 -> 361
R47: Home | S47: Work | T47: Study | U47: Commercial | V47: Tourism | W47: Leisure/Social | X47: Hospital | Y47: Others
P48: 1 | Q48: Home | R48: =R59/SUM($R$59:$Y$66) -> 0.04735376 | S48: =S59/SUM($R$59:$Y$66) -> 0.1448468 | T48: =T59/SUM($R$59:$Y$66) -> 0.050139276 | U48: =U59/SUM($R$59:$Y$66) -> 0.044568245 | V48: =V59/SUM($R$59:$Y$66) -> 0 | W48: =W59/SUM($R$59:$Y$66) -> 0.008356546 | X48: =X59/SUM($R$59:$Y$66) -> 0.019498607 | Y48: =Y59/SUM($R$59:$Y$66) -> 0.050139276
P49: 2 | Q49: Work | R49: =R60/SUM($R$59:$Y$66) -> 0.19220056 | S49: =S60/SUM($R$59:$Y$66) -> 0.13091922 | T49: =T60/SUM($R$59:$Y$66) -> 0.0055710306 | U49: =U60/SUM($R$59:$Y$66) -> 0.066852368 | V49: =V60/SUM($R$59:$Y$66) -> 0 | W49: =W60/SUM($R$59:$Y$66) -> 0 | X49: =X60/SUM($R$59:$Y$66) -> 0 | Y49: =Y60/SUM($R$59:$Y$66) -> 0.0055710306
P50: 3 | Q50: Study | R50: =R61/SUM($R$59:$Y$66) -> 0.052924791 | S50: =S61/SUM($R$59:$Y$66) -> 0.0027855153 | T50: =T61/SUM($R$59:$Y$66) -> 0.0055710306 | U50: =U61/SUM($R$59:$Y$66) -> 0.0027855153 | V50: =V61/SUM($R$59:$Y$66) -> 0.0027855153 | W50: =W61/SUM($R$59:$Y$66) -> 0 | X50: =X61/SUM($R$59:$Y$66) -> 0 | Y50: =Y61/SUM($R$59:$Y$66) -> 0.0055710306
P51: 4 | Q51: Commercial | R51: =R62/SUM($R$59:$Y$66) -> 0.033426184 | S51: =S62/SUM($R$59:$Y$66) -> 0.025069638 | T51: =T62/SUM($R$59:$Y$66) -> 0.0027855153 | U51: =U62/SUM($R$59:$Y$66) -> 0.033426184 | V51: =V62/SUM($R$59:$Y$66) -> 0 | W51: =W62/SUM($R$59:$Y$66) -> 0 | X51: =X62/SUM($R$59:$Y$66) -> 0 | Y51: =Y62/SUM($R$59:$Y$66) -> 0
P52: 5 | Q52: Tourism | R52: =R63/SUM($R$59:$Y$66) -> 0 | S52: =S63/SUM($R$59:$Y$66) -> 0 | T52: =T63/SUM($R$59:$Y$66) -> 0 | U52: =U63/SUM($R$59:$Y$66) -> 0 | V52: =V63/SUM($R$59:$Y$66) -> 0 | W52: =W63/SUM($R$59:$Y$66) -> 0 | X52: =X63/SUM($R$59:$Y$66) -> 0 | Y52: =Y63/SUM($R$59:$Y$66) -> 0
P53: 6 | Q53: Leisure/Social | R53: =R64/SUM($R$59:$Y$66) -> 0.013927577 | S53: =S64/SUM($R$59:$Y$66) -> 0 | T53: =T64/SUM($R$59:$Y$66) -> 0 | U53: =U64/SUM($R$59:$Y$66) -> 0 | V53: =V64/SUM($R$59:$Y$66) -> 0 | W53: =W64/SUM($R$59:$Y$66) -> 0 | X53: =X64/SUM($R$59:$Y$66) -> 0 | Y53: =Y64/SUM($R$59:$Y$66) -> 0.0027855153
P54: 7 | Q54: Hospital | R54: =R65/SUM($R$59:$Y$66) -> 0.0055710306 | S54: =S65/SUM($R$59:$Y$66) -> 0 | T54: =T65/SUM($R$59:$Y$66) -> 0 | U54: =U65/SUM($R$59:$Y$66) -> 0 | V54: =V65/SUM($R$59:$Y$66) -> 0 | W54: =W65/SUM($R$59:$Y$66) -> 0 | X54: =X65/SUM($R$59:$Y$66) -> 0.008356546 | Y54: =Y65/SUM($R$59:$Y$66) -> 0
P55: 8 | Q55: Others | R55: =R66/SUM($R$59:$Y$66) -> 0.019498607 | S55: =S66/SUM($R$59:$Y$66) -> 0.0027855153 | T55: =T66/SUM($R$59:$Y$66) -> 0 | U55: =U66/SUM($R$59:$Y$66) -> 0.0027855153 | V55: =V66/SUM($R$59:$Y$66) -> 0 | W55: =W66/SUM($R$59:$Y$66) -> 0 | X55: =X66/SUM($R$59:$Y$66) -> 0 | Y55: =Y66/SUM($R$59:$Y$66) -> 0.011142061
R57: 1 | S57: 2 | T57: 3 | U57: 4 | V57: 5 | W57: 6 | X57: 7 | Y57: 8
B58: Willingness to Pay | R58: Home | S58: Work | T58: Study | U58: Commercial | V58: Tourism | W58: Leisure/Social | X58: Hospital | Y58: Others
...

Sheet ALL DATA
B1: Consultancy services for Preparation of Expressway Development Master Plan (EDMP) for Uganda
B2: Roadside OD Interview Survey
B4: Date: | C4: 26.10.2019 | E4: Road Name: | F4: ='26.10 MBARARA-ISINGIRO'!F4:G4 -> MBARARA-NTUNGAMO ROAD | I4: Direction From: | L4: ISINGIRO | N4: Interviewers: | O4: AMOS.A, TUMUKUNDE DEVIS | V4: Supervisor: | W4: ='26.10 MBARARA-ISINGIRO'!W4 -> MIREMBE RUTH | Y4: Coded By: | Z4: ='26.10 MBARARA-ISINGIRO'!Z4 -> AJOK EMILY | AA4: Chkd By: | AB4: ='26.10 MBARARA-ISINGIRO'!AB4 -> 0
I5: Direction To: | L5: MBARARA
B7: Time | C7: Veh_Reg_No. | D7: Veh_Type | E7: No. Occupants | F7: Origin_Address | I7: Origin_Establish | J7: Origin_Purpose | K7: Origin-Purpose Desc | L7: Destination_Address | O7: Destination_Establish | P7: Destination_Purpose | Q7: Destination_Purpose Desc | R7: Journey_Purpose | S7: Approx_Distance (Km) | T7: Approx_Journey Time (Hrs) | U7: Trip_Frequency | V7: GOODS VEHICLES ONLY | Y7: Would You Use Xpressways? | Z7: Pay How Much? (UGX) | AA7: Origin_Zone | AB7: Dest_Zone
F8: Village or Town | G8: District | H8: Country | L8: Village or Town | M8: District | N8: Country | V8: Goods_Type | W8: Goods_Quantity (Ton) | X8: Goods_Value (UGXm)
B9: 0.7625 | C9: UAU 995A | D9: 4 | E9: 2 | F9: KABEREBERE | G9: ISINGIRO | H9: UG | I9: 6 | J9: 2 | K9: =VLOOKUP(J9,Key!$E$2:$F$9,2,FALSE) -> Work | L9: MBARARA TOWN | M9: MBARARA | N9: UG | O9: 6 | P9: 2 | Q9: =VLOOKUP(P9,Key!$E$2:$F$9,2,FALSE) -> Work | R9: =K9&"-"&Q9 -> Work-Work | S9: 15 | T9: 0.5 | U9: 4 | Y9: Y | AA9: =VLOOKUP(F9,'Zones (3)'!$A$2:$F$15913,6,FALSE) -> 380 | AB9: =VLOOKUP(L9,'Zones (3)'!$A$1:$F$15616,6,FALSE) -> 987
B10: 0.75902778 | C10: UAY 487N | D10: 2 | E10: 2 | F10: KABALE | G10: KABALE | H10: UG | I10: 1 | J10: 1 | K10: =VLOOKUP(J10,Key!$E$2:$F$9,2,FALSE) -> Home | L10: MBARARA TOWN | M10: MBARARA | N10: UG | O10: 2 | P10: 2 | Q10: =VLOOKUP(P10,Key!$E$2:$F$9,2,FALSE) -> Work | R10: =K10&"-"&Q10 -> Home-Work | S10: 5 | T10: 0.2 | U10: 5 | Y10: Y | AA10: =VLOOKUP(F10,'Zones (3)'!$A$2:$F$15913,6,FALSE) -> 422 | AB10: =VLOOKUP(L10,'Zones (3)'!$A$1:$F$15616,6,FALSE) -> 987
B11: 0.75416667 | C11: UAY 682D | D11: 1 | E11: 2 | F11: RWENZIRINGIRO | G11: ISINGIRO | H11: UG | I11: 4 | J11: 3 | K11: =VLOOKUP(J11,Key!$E$2:$F$9,2,FALSE) -> Study | L11: MBARARA TOWN | M11: MBARARA | N11: UG | O11: 1 | P11: 1 | Q11: =VLOOKUP(P11,Key!$E$2:$F$9,2,FALSE) -> Home | R11: =K11&"-"&Q11 -> Study-Home | T11: 0.3 | U11: 3 | Y11: Y | AA11: =VLOOKUP(F11,'Zones (3)'!$A$2:$F$15913,6,FALSE) -> 1439 | AB11: =VLOOKUP(L11,'Zones (3)'!$A$1:$F$15616,6,FALSE) -> 987
B12: 0.75208333 | C12: UAP 980K | D12: 2 | E12: 1 | F12: KABALE | G12: KABALE | H12: UG | I12: 1 | J12: 1 | K12: =VLOOKUP(J12,Key!$E$2:$F$9,2,FALSE) -> Home | L12: MBARARA TOWN | M12: MBARARA | N12: UG | O12: 2 | P12: 2 | Q12: =VLOOKUP(P12,Key!$E$2:$F$9,2,FALSE) -> Work | R12: =K12&"-"&Q12 -> Home-Work | S12: 4 | T12: 0.2 | U12: 3 | Y12: Y | AA12: =VLOOKUP(F12,'Zones (3)'!$A$2:$F$15913,6,FALSE) -> 422 | AB12: =VLOOKUP(L12,'Zones (3)'!$A$1:$F$15616,6,FALSE) -> 987
B13: 0.74861111 | C13: UAQ 168G | D13: 1 | E13: 1 | F13: KABALE | G13: KABALE | H13: UG | I13: 16 | J13: 8 | K13: =VLOOKUP(J13,Key!$E$2:$F$9,2,FALSE) -> Others | L13: MBARARA TOWN | M13: MBARARA | N13: UG | O13: 16 | P13: 8 | Q13: =VLOOKUP(P13,Key!$E$2:$F$9,2,FALSE) -> Others | R13: =K13&"-"&Q13 -> Others-Others | S13: 10 | T13: 0.2 | U13: 6 | Y13: Y | AA13: =VLOOKUP(F13,'Zones (3)'!$A$2:$F$15913,6,FALSE) -> 422 | AB13: =VLOOKUP(L13,'Zones (3)'!$A$1:$F$15616,6,FALSE) -> 987
B14: 0.74513889 | C14: UAF 911X | D14: 1 | E14: 1 | F14: KABEREBERE | G14: ISINGIRO | H14: UG | I14: 2 | J14: 2 | K14: Work | L14: NYAMITANGA | M14: MBARARA | N14: UG | O14: 1 | P14: 1 | Q14: =VLOOKUP(P14,Key!$E$2:$F$9,2,FALSE) -> Home | R14: =K14&"-"&Q14 -> Work-Home | S14: 13 | T14: 0.3 | U14: 3 | Y14: Y | AA14: =VLOOKUP(F14,'Zones (3)'!$A$2:$F$15913,6,FALSE) -> 380 | AB14: =VLOOKUP(L14,'Zones (3)'!$A$1:$F$15616,6,FALSE) -> 987
B15: 0.74166667 | C15: CD 103 62U | D15: 2 | E15: 2 | F15: ISINGIRO TOWN | G15: ISINGIRO | H15: UG | I15: 2 | J15: 2 | K15: =VLOOKUP(J15,Key!$E$2:$F$9,2,FALSE) -> Work | L15: MBARARA TOWN | M15: MBARARA | N15: UG | O15: 16 | P15: 8 | Q15: =VLOOKUP(P15,Key!$E$2:$F$9,2,FALSE) -> Others | R15: =K15&"-"&Q15 -> Work-Others | S15: 31 | T15: 0.8 | U15: 2 | Y15: Y | AA15: =VLOOKUP(F15,'Zones (3)'!$A$2:$F$15913,6,FALSE) -> 379 | AB15: =VLOOKUP(L15,'Zones (3)'!$A$1:$F$15616,6,FALSE) -> 987
B16: 0.7375 | C16: UAX 388M | D16: 8 | E16: 1 | F16: KABINGO | G16: ISINGIRO | H16: UG | I16: 15 | J16: 4 | K16: =VLOOKUP(J16,Key!$E$2:$F$9,2,FALSE) -> Commercial | L16: MBARARA TOWN | M16: MBARARA | N16: UG | O16: 10 | P16: 2 | Q16: =VLOOKUP(P16,Key!$E$2:$F$9,2,FALSE) -> Work | R16: =K16&"-"&Q16 -> Commercial-Work | S16: 12 | T16: 0.5 | U16: 3 | V16: 4 | W16: 6 | X16: 220000 | Y16: Y | AA16: =VLOOKUP(F16,'Zones (3)'!$A$2:$F$15913,6,FALSE) -> 381 | AB16: =VLOOKUP(L16,'Zones (3)'!$A$1:$F$15616,6,FALSE) -> 987
B17: 0.73333333 | C17: UAS 880K | D17: 1 | E17: 3 | F17: KABALE | G17: ISINGIRO | H17: UG | I17: 4 | J17: 3 | K17: =VLOOKUP(J17,Key!$E$2:$F$9,2,FALSE) -> Study | L17: MBARARA TOWN | M17: MBARARA | N17: UG | O17: 1 | P17: 1 | Q17: =VLOOKUP(P17,Key!$E$2:$F$9,2,FALSE) -> Home | R17: =K17&"-"&Q17 -> Study-Home | S17: 5 | T17: 0.5 | U17: 5 | Y17: Y | AA17: =VLOOKUP(F17,'Zones (3)'!$A$2:$F$15913,6,FALSE) -> 422 | AB17: =VLOOKUP(L17,'Zones (3)'!$A$1:$F$15616,6,FALSE) -> 987
B18: 0.72916667 | C18: UAR 880V | D18: 1 | E18: 1 | F18: KABEREBERE | G18: ISINGIRO | H18: UG | I18: 2 | J18: 2 | K18: =VLOOKUP(J18,Key!$E$2:$F$9,2,FALSE) -> Work | L18: MBARARA TOWN | M18: MBARARA | N18: UG | O18: 2 | P18: 2 | Q18: =VLOOKUP(P18,Key!$E$2:$F$9,2,FALSE) -> Work | R18: =K18&"-"&Q18 -> Work-Work | S18: 35 | T18: 0.4 | U18: 4 | Y18: Y | AA18: =VLOOKUP(F18,'Zones (3)'!$A$2:$F$15913,6,FALSE) -> 380 | AB18: =VLOOKUP(L18,'Zones (3)'!$A$1:$F$15616,6,FALSE) -> 987
B19: 0.725 | C19: UAY 304Y | D19: 8 | E19: 3 | F19: KABEREBERE | G19: ISINGIRO | H19: UG | I19: 3 | J19: 4 | K19: =VLOOKUP(J19,Key!$E$2:$F$9,2,FALSE) -> Commercial | L19: MBARARA TOWN | M19: MBARARA | N19: UG | O19: 4 | P19: 3 | Q19: =VLOOKUP(P19,Key!$E$2:$F$9,2,FALSE) -> Study | R19: =K19&"-"&Q19 -> Commercial-Study | S19: 10 | T19: 0.2 | U19: 2 | V19: 10 | W19: 4 | X19: 4500000 | Y19: Y | AA19: =VLOOKUP(F19,'Zones (3)'!$A$2:$F$15913,6,FALSE) -> 380 | AB19: =VLOOKUP(L19,'Zones (3)'!$A$1:$F$15616,6,FALSE) -> 987
B20: 0.72083333 | C20: UBB 721A | D20: 1 | E20: 2 | F20: KABEREBERE | G20: ISINGIRO | H20: UG | I20: 3 | J20: 4 | K20: =VLOOKUP(J20,Key!$E$2:$F$9,2,FALSE) -> Commercial | L20: MBARARA TOWN | M20: MBARARA | N20: UG | O20: 1 | P20: 1 | Q20: =VLOOKUP(P20,Key!$E$2:$F$9,2,FALSE) -> Home | R20: =K20&"-"&Q20 -> Commercial-Home | S20: 25 | T20: 0.3 | U20: 3 | Y20: Y | AA20: =VLOOKUP(F20,'Zones (3)'!$A$2:$F$15913,6,FALSE) -> 380 | AB20: =VLOOKUP(L20,'Zones (3)'!$A$1:$F$15616,6,FALSE) -> 987
B21: 0.71666667 | C21: UAL 702Y | D21: 1 | E21: 3 | F21: KABEREBERE | G21: ISINGIRO | H21: UG | I21: 1 | J21: 1 | K21: =VLOOKUP(J21,Key!$E$2:$F$9,2,FALSE) -> Home | L21: MBARARA TOWN | M21: MBARARA | N21: UG | O21: 16 | P21: 8 | Q21: =VLOOKUP(P21,Key!$E$2:$F$9,2,FALSE) -> Others | R21: =K21&"-"&Q21 -> Home-Others | S21: 35 | T21: 1 | U21: 4 | V21: 11 | Y21: Y | AA21: =VLOOKUP(F21,'Zones (3)'!$A$2:$F$15913,6,FALSE) -> 380 | AB21: =VLOOKUP(L21,'Zones (3)'!$A$1:$F$15616,6,FALSE) -> 987
B22: 0.71458333 | C22: UAX 390W | D22: 1 | E22: 12 | F22: KABALE | G22: ISINGIRO | H22: UG | I22: 1 | J22: 1 | K22: =VLOOKUP(J22,Key!$E$2:$F$9,2,FALSE) -> Home | L22: MBARARA TOWN | M22: MBARARA | N22: UG | O22: 16 | P22: 8 | Q22: =VLOOKUP(P22,Key!$E$2:$F$9,2,FALSE) -> Others | R22: =K22&"-"&Q22 -> Home-Others | S22: 5 | T22: 0.2 | U22: 2 | Y22: Y | AA22: =VLOOKUP(F22,'Zones (3)'!$A$2:$F$15913,6,FALSE) -> 422 | AB22: =VLOOKUP(L22,'Zones (3)'!$A$1:$F$15616,6,FALSE) -> 987
B23: 0.71111111 | C23: UAY 249B | D23: 1 | E23: 1 | F23: KASENYI | G23: ISINGIRO | H23: UG | I23: 16 | J23: 8 | K23: =VLOOKUP(J23,Key!$E$2:$F$9,2,FALSE) -> Others | L23: MBARARA TOWN | M23: MBARARA | N23: UG | O23: 1 | P23: 1 | Q23: =VLOOKUP(P23,Key!$E$2:$F$9,2,FALSE) -> Home | R23: =K23&"-"&Q23 -> Others-Home | S23: 6 | T23: 0 | U23: 3 | Y23: Y | AA23: =VLOOKUP(F23,'Zones (3)'!$A$2:$F$15913,6,FALSE) -> 538 | AB23: =VLOOKUP(L23,'Zones (3)'!$A$1:$F$15616,6,FALSE) -> 987
B24: 0.70833333 | C24: UAS 808H | D24: 1 | E24: 2 | F24: KASENYI | G24: ISINGIRO | H24: UG | I24: 16 | J24: 8 | K24: =VLOOKUP(J24,Key!$E$2:$F$9,2,FALSE) -> Others | L24: MBARARA TOWN | M24: MBARARA | N24: UG | O24: 1 | P24: 1 | Q24: =VLOOKUP(P24,Key!$E$2:$F$9,2,FALSE) -> Home | R24: =K24&"-"&Q24 -> Others-Home | S24: 5 | T24: 0.3 | U24: 4 | Y24: Y | AA24: =VLOOKUP(F24,'Zones (3)'!$A$2:$F$15913,6,FALSE) -> 538 | AB24: =VLOOKUP(L24,'Zones (3)'!$A$1:$F$15616,6,FALSE) -> 987
B25: 0.70416667 | C25: T487 BFH | D25: 10 | E25: 3 | F25: KABINGO | G25: ISINGIRO | H25: UG | I25: 13 | J25: 4 | K25: =VLOOKUP(J25,Key!$E$2:$F$9,2,FALSE) -> Commercial | L25: MBARARA TOWN | M25: MBARARA | N25: UG | O25: 16 | P25: 8 | Q25: =VLOOKUP(P25,Key!$E$2:$F$9,2,FALSE) -> Others | R25: Work-Others | S25: 32 | T25: 0.7 | U25: 4 | V25: 11 | Y25: Y | AA25: =VLOOKUP(F25,'Zones (3)'!$A$2:$F$15913,6,FALSE) -> 381 | AB25: =VLOOKUP(L25,'Zones (3)'!$A$1:$F$15616,6,FALSE) -> 987
B26: 0.70138889 | C26: UAT 089N | D26: 3 | E26: 4 | F26: KIKAGATI | G26: ISINGIRO | H26: UG | I26: 2 | J26: 2 | K26: =VLOOKUP(J26,Key!$E$2:$F$9,2,FALSE) -> Work | L26: MBARARA TOWN | M26: MBARARA | N26: UG | O26: 1 | P26: 1 | Q26: =VLOOKUP(P26,Key!$E$2:$F$9,2,FALSE) -> Home | R26: =K26&"-"&Q26 -> Work-Home | S26: 40 | T26: 1.5 | U26: 6 | Y26: Y | AA26: =VLOOKUP(F26,'Zones (3)'!$A$2:$F$15913,6,FALSE) -> 379 | AB26: =VLOOKUP(L26,'Zones (3)'!$A$1:$F$15616,6,FALSE) -> 987
B27: 0.69791667 | C27: UAM 124K | D27: 1 | E27: 8 | F27: KABINGO | G27: ISINGIRO | H27: UG | I27: 1 | J27: 1 | K27: =VLOOKUP(J27,Key!$E$2:$F$9,2,FALSE) -> Home | L27: MBARARA TOWN | M27: MBARARA | N27: UG | O27: 1 | P27: 1 | Q27: =VLOOKUP(P27,Key!$E$2:$F$9,2,FALSE) -> Home | R27: =K27&"-"&Q27 -> Home-Home | T27: 0.7 | U27: 3 | Y27: Y | AA27: =VLOOKUP(F27,'Zones (3)'!$A$2:$F$15913,6,FALSE) -> 381 | AB27: =VLOOKUP(L27,'Zones (3)'!$A$1:$F$15616,6,FALSE) -> 987
B28: 0.69444444 | C28: UAQ 705F | D28: 1 | E28: 2 | F28: RWENJELU | G28: ISINGIRO | H28: UG | I28: 4 | J28: 3 | K28: =VLOOKUP(J28,Key!$E$2:$F$9,2,FALSE) -> Study | L28: MBARARA TOWN | M28: MBARARA | N28: UG | O28: 1 | P28: 1 | Q28: =VLOOKUP(P28,Key!$E$2:$F$9,2,FALSE) -> Home | R28: =K28&"-"&Q28 -> Study-Home | S28: 4 | T28: 0.5 | U28: 3 | Y28: Y | AA28: =VLOOKUP(F28,'Zones (3)'!$A$2:$F$15913,6,FALSE) -> 379 | AB28: =VLOOKUP(L28,'Zones (3)'!$A$1:$F$15616,6,FALSE) -> 987
B29: 0.69027778 | C29: UAT 319R | D29: 1 | E29: 1 | F29: KASENYI | G29: ISINGIRO | H29: UG | I29: 4 | J29: 3 | K29: =VLOOKUP(J29,Key!$E$2:$F$9,2,FALSE) -> Study | L29: MBARARA TOWN | M29: MBARARA | N29: UG | O29: 1 | P29: 1 | Q29: =VLOOKUP(P29,Key!$E$2:$F$9,2,FALSE) -> Home | R29: =K29&"-"&Q29 -> Study-Home | S29: 10 | T29: 0.3 | U29: 3 | Y29: Y | AA29: =VLOOKUP(F29,'Zones (3)'!$A$2:$F$15913,6,FALSE) -> 538 | AB29: =VLOOKUP(L29,'Zones (3)'!$A$1:$F$15616,6,FALSE) -> 987
B30: 0.68541667 | C30: UAN 083G | D30: 1 | E30: 2 | F30: NAKIVALA | G30: ISINGIRO | H30: UG | I30: 7 | J30: 2 | K30: =VLOOKUP(J30,Key!$E$2:$F$9,2,FALSE) -> Work | L30: MBARARA TOWN | M30: MBARARA | N30: UG | O30: 1 | P30: 1 | Q30: =VLOOKUP(P30,Key!$E$2:$F$9,2,FALSE) -> Home | R30: =K30&"-"&Q30 -> Work-Home | S30: 30 | T30: 2 | U30: 4 | V30: 10 | Y30: Y | AA30: =VLOOKUP(F30,'Zones (3)'!$A$2:$F$15913,6,FALSE) -> 388 | AB30: =VLOOKUP(L30,'Zones (3)'!$A$1:$F$15616,6,FALSE) -> 987
B31: 0.53472222 | C31: UAZ 098F | D31: 2 | E31: 7 | F31: KIKAGATI | G31: ISINGIRO | H31: UG | I31: 1 | J31: 1 | K31: =VLOOKUP(J31,Key!$E$2:$F$9,2,FALSE) -> Home | L31: MBARARA TOWN | M31: MBARARA | N31: UG | O31: 1 | P31: 1 | Q31: =VLOOKUP(P31,Key!$E$2:$F$9,2,FALSE) -> Home | R31: =K31&"-"&Q31 -> Home-Home | S31: 69 | T31: 1 | U31: 4 | Y31: Y | AA31: =VLOOKUP(F31,'Zones (3)'!$A$2:$F$15913,6,FALSE) -> 379 | AB31: =VLOOKUP(L31,'Zones (3)'!$A$1:$F$15616,6,FALSE) -> 987
B32: 0.53055556 | C32: UAJ 803W | D32: 1 | E32: 1 | F32: KABEREBERE | G32: ISINGIRO | H32: UG | I32: 1 | J32: 1 | K32: =VLOOKUP(J32,Key!$E$2:$F$9,2,FALSE) -> Home | L32: MBARARA TOWN | M32: MBARARA | N32: UG | O32: 2 | P32: 2 | Q32: =VLOOKUP(P32,Key!$E$2:$F$9,2,FALSE) -> Work | R32: =K32&"-"&Q32 -> Home-Work | S32: 9 | T32: 0.5 | U32: 2 | Y32: Y | AA32: =VLOOKUP(F32,'Zones (3)'!$A$2:$F$15913,6,FALSE) -> 380 | AB32: =VLOOKUP(L32,'Zones (3)'!$A$1:$F$15616,6,FALSE) -> 987
B33: 0.52777778 | C33: UBE 386H | D33: 1 | E33: 4 | F33: KABEREBERE | G33: ISINGIRO | H33: UG | I33: 4 | J33: 3 | K33: =VLOOKUP(J33,Key!$E$2:$F$9,2,FALSE) -> Study | L33: MBARARA TOWN | M33: MBARARA | N33: UG | O33: 1 | P33: 1 | Q33: =VLOOKUP(P33,Key!$E$2:$F$9,2,FALSE) -> Home | R33: =K33&"-"&Q33 -> Study-Home | S33: 52 | T33: 1 | U33: 3 | Y33: Y | AA33: =VLOOKUP(F33,'Zones (3)'!$A$2:$F$15913,6,FALSE) -> 380 | AB33: =VLOOKUP(L33,'Zones (3)'!$A$1:$F$15616,6,FALSE) -> 987
B34: 0.525 | C34: UBE 561U | D34: 2 | E34: 1 | F34: KIRUMBA | G34: KYOTERA | H34: UG | I34: 16 | J34: 8 | K34: =VLOOKUP(J34,Key!$E$2:$F$9,2,FALSE) -> Others | L34: KAMPALA CITY | M34: KAMPALA | N34: UG | O34: 1 | P34: 1 | Q34: =VLOOKUP(P34,Key!$E$2:$F$9,2,FALSE) -> Home | R34: =K34&"-"&Q34 -> Others-Home | T34: 3 | U34: 6 | Y34: Y | AA34: =VLOOKUP(F34,'Zones (3)'!$A$2:$F$15913,6,FALSE) -> 850 | AB34: =VLOOKUP(L34,'Zones (3)'!$A$1:$F$15616,6,FALSE) -> 521
B35: 0.52083333 | C35: UBD 114B | D35: 1 | E35: 3 | F35: KASENYI | G35: ISINGIRO | H35: UG | I35: 1 | J35: 1 | K35: =VLOOKUP(J35,Key!$E$2:$F$9,2,FALSE) -> Home | L35: MBARARA TOWN | M35: MBARARA | N35: UG | O35: 2 | P35: 2 | Q35: =VLOOKUP(P35,Key!$E$2:$F$9,2,FALSE) -> Work | R35: =K35&"-"&Q35 -> Home-Work | S35: 4 | T35: 0.3 | U35: 1 | Y35: Y | AA35: =VLOOKUP(F35,'Zones (3)'!$A$2:$F$15913,6,FALSE) -> 538 | AB35: =VLOOKUP(L35,'Zones (3)'!$A$1:$F$15616,6,FALSE) -> 987
B36: 0.51736111 | C36: UAD 009J | D36: 3 | E36: 2 | F36: KABEREBERE | G36: ISINGIRO | H36: UG | I36: 1 | J36: 1 | K36: =VLOOKUP(J36,Key!$E$2:$F$9,2,FALSE) -> Home | L36: MBARARA TOWN | M36: MBARARA | N36: UG | O36: 1 | P36: 1 | Q36: =VLOOKUP(P36,Key!$E$2:$F$9,2,FALSE) -> Home | R36: =K36&"-"&Q36 -> Home-Home | S36: 13 | T36: 0.5 | U36: 4 | V36: 10 | Y36: Y | AA36: =VLOOKUP(F36,'Zones (3)'!$A$2:$F$15913,6,FALSE) -> 380 | AB36: =VLOOKUP(L36,'Zones (3)'!$A$1:$F$15616,6,FALSE) -> 987
B37: 0.51527778 | C37: UAP 660M | D37: 1 | E37: 4 | F37: KABEREBERE | G37: ISINGIRO | H37: UG | I37: 1 | J37: 1 | K37: =VLOOKUP(J37,Key!$E$2:$F$9,2,FALSE) -> Home | L37: MBARARA TOWN | M37: MBARARA | N37: UG | O37: 16 | P37: 8 | Q37: =VLOOKUP(P37,Key!$E$2:$F$9,2,FALSE) -> Others | R37: =K37&"-"&Q37 -> Home-Others | S37: 35 | T37: 2 | U37: 6 | Y37: Y | AA37: =VLOOKUP(F37,'Zones (3)'!$A$2:$F$15913,6,FALSE) -> 380 | AB37: =VLOOKUP(L37,'Zones (3)'!$A$1:$F$15616,6,FALSE) -> 987
B38: 0.51319444 | C38: UAL 863M | D38: 2 | E38: 3 | F38: KABINGO | G38: ISINGIRO | H38: UG | I38: 1 | J38: 1 | K38: =VLOOKUP(J38,Key!$E$2:$F$9,2,FALSE) -> Home | L38: MBARARA TOWN | M38: MBARARA | N38: UG | O38: 5 | P38: 7 | Q38: =VLOOKUP(P38,Key!$E$2:$F$9,2,FALSE) -> Hospital | R38: =K38&"-"&Q38 -> Home-Hospital | S38: 36 | T38: 0.5 | U38: 3 | Y38: Y | AA38: =VLOOKUP(F38,'Zones (3)'!$A$2:$F$15913,6,FALSE) -> 381 | AB38: =VLOOKUP(L38,'Zones (3)'!$A$1:$F$15616,6,FALSE) -> 987
B39: 0.51041667 | C39: UAW 625J | D39: 8 | E39: 2 | F39: KABEREBERE | G39: ISINGIRO | H39: UG | I39: 13 | J39: 4 | K39: =VLOOKUP(J39,Key!$E$2:$F$9,2,FALSE) -> Commercial | L39: MBARARA TOWN | M39: MBARARA | N39: UG | O39: 10 | P39: 2 | Q39: =VLOOKUP(P39,Key!$E$2:$F$9,2,FALSE) -> Work | R39: =K39&"-"&Q39 -> Commercial-Work | S39: 37 | T39: 1.5 | U39: 2 | V39: 4 | W39: 6 | X39: 40000 | Y39: Y | AA39: =VLOOKUP(F39,'Zones (3)'!$A$2:$F$15913,6,FALSE) -> 380 | AB39: =VLOOKUP(L39,'Zones (3)'!$A$1:$F$15616,6,FALSE) -> 987
B40: 0.50763889 | C40: UAE 190G | D40: 1 | E40: 1 | F40: KASENYI | G40: ISINGIRO | H40: UG | I40: 4 | J40: 3 | K40: =VLOOKUP(J40,Key!$E$2:$F$9,2,FALSE) -> Study | L40: MBARARA TOWN | M40: MBARARA | N40: UG | O40: 1 | P40: 1 | Q40: =VLOOKUP(P40,Key!$E$2:$F$9,2,FALSE) -> Home | R40: =K40&"-"&Q40 -> Study-Home | S40: 2 | T40: 0.2 | U40: 2 | Y40: Y | AA40: =VLOOKUP(F40,'Zones (3)'!$A$2:$F$15913,6,FALSE) -> 538 | AB40: =VLOOKUP(L40,'Zones (3)'!$A$1:$F$15616,6,FALSE) -> 987
B41: 0.44097222 | C41: UBA 760C | D41: 2 | E41: 2 | F41: ISINGIRO TOWN | G41: ISINGIRO | H41: UG | I41: 1 | J41: 1 | K41: =VLOOKUP(J41,Key!$E$2:$F$9,2,FALSE) -> Home | L41: MBARARA TOWN | M41: MBARARA | N41: UG | O41: 4 | P41: 3 | Q41: =VLOOKUP(P41,Key!$E$2:$F$9,2,FALSE) -> Study | R41: =K41&"-"&Q41 -> Home-Study | S41: 44 | T41: 1 | U41: 4 | Y41: Y | AA41: =VLOOKUP(F41,'Zones (3)'!$A$2:$F$15913,6,FALSE) -> 379 | AB41: =VLOOKUP(L41,'Zones (3)'!$A$1:$F$15616,6,FALSE) -> 987
B42: 0.4375 | C42: UAQ 147X | D42: 2 | E42: 1 | F42: NGALAMA | G42: ISINGIRO | H42: UG | I42: 1 | J42: 1 | K42: =VLOOKUP(J42,Key!$E$2:$F$9,2,FALSE) -> Home | L42: MBARARA TOWN | M42: MBARARA | N42: UG | O42: 16 | P42: 8 | Q42: =VLOOKUP(P42,Key!$E$2:$F$9,2,FALSE) -> Others | R42: =K42&"-"&Q42 -> Home-Others | S42: 33 | T42: 1 | U42: 4 | Y42: Y | AA42: =VLOOKUP(F42,'Zones (3)'!$A$2:$F$15913,6,FALSE) -> 987 | AB42: =VLOOKUP(L42,'Zones (3)'!$A$1:$F$15616,6,FALSE) -> 987
...

Sheet Zones (3)
A1: ZONE NAME | B1: DISTRICT | C1: COUNTY | D1: SUBCOUNTY | E1: Parish | F1: ZONE No.
A2: Abim | B2: Abim | C2: Labwor | D2: =A2 -> Abim | F2: 1
A3: Abim Town Council | B3: Abim | C3: Labwor | D3: =A3 -> Abim Town Council | F3: 2
A4: Alerek | B4: Abim | C4: Labwor | D4: =A4 -> Alerek | F4: 3
A5: Lotukei | B5: Abim | C5: Labwor | D5: =A5 -> Lotukei | F5: 4
A6: Morulem | B6: Abim | C6: Labwor | D6: =A6 -> Morulem | F6: 5
A7: Nyakwae | B7: Abim | C7: Labwor | D7: =A7 -> Nyakwae | F7: 6
A8: Adjumani Town Council | B8: Adjumani | C8: East Moyo | D8: =A8 -> Adjumani Town Council | F8: 7
A9: Adropi | B9: Adjumani | C9: East Moyo | D9: =A9 -> Adropi | F9: 8
A10: Arinyapi | B10: Adjumani | C10: East Moyo | D10: =A10 -> Arinyapi | F10: 9
A11: Ciforo | B11: Adjumani | C11: East Moyo | D11: =A11 -> Ciforo | F11: 10
A12: Dzaipi | B12: Adjumani | C12: East Moyo | D12: =A12 -> Dzaipi | F12: 11
A13: Itirikwa | B13: Adjumani | C13: East Moyo | D13: =A13 -> Itirikwa | F13: 12
... A75: Amuru Town Council | B75: Amuru | C75: Kilak | D75: =A75 -> Amuru Town Council | F75: 74
A76: Amur town | D76: =A76 -> Amur town | F76: 74
A77: Attiak | B77: Amuru | C77: Kilak | D77: =A77 -> Attiak | F77: 75
A78: Lamogi | B78: Amuru | C78: Kilak | D78: =A78 -> Lamogi | F78: 76
A79: Pabo | B79: Amuru | C79: Kilak | D79: =A79 -> Pabo | F79: 77
A80: Abongomola | B80: Apac | C80: Kwania | D80: =A80 -> Abongomola | F80: 78
A81: Aduku | B81: Apac | C81: Kwania | D81: =A81 -> Aduku | F81: 79
A82: Aduku Town Council | B82: Apac | C82: Kwania | D82: =A82 -> Aduku Town Council | F82: 80
A83: Akokoro | B83: Apac | C83: Maruzi | D83: =A83 -> Akokoro | F83: 81
A84: Apac Muicipality | B84: Apac | C84: Apac Municipality | D84: =A84 -> Apac Muicipality | F84: 82
A85: Apac | D85: =A85 -> Apac | F85: 82
A86: Chawente | B86: Apac | C86: Kwania | D86: =A86 -> Chawente | F86: 83
A87: Chegere | B87: Apac | C87: Maruzi | D87: =A87 -> Chegere | F87: 84
A88: Ibuje | B88: Apac | C88: Maruzi | D88: =A88 -> Ibuje | F88: 85
A89: Inomo | B89: Apac | C89: Kwania | D89: =A89 -> Inomo | F89: 86
A90: Nambieso | B90: Apac | C90: Kwania | D90: =A90 -> Nambieso | F90: 87
A91: Adumi | B91: Arua | C91: Ayivu | D91: =A91 -> Adumi | F91: 88
A92: Aii-Vu | B92: Arua | C92: Terego | D92: =A92 -> Aii-Vu | F92: 89
A93: Ajia | B93: Arua | C93: Vurra | D93: =A93 -> Ajia | F93: 90
A94: Anyiribu | B94: Arua | C94: Madi Okollo | D94: =A94 -> Anyiribu | F94: 91
A95: Arivu | B95: Arua | C95: Vurra | D95: =A95 -> Arivu | F95: 92
A96: Aroi | B96: Arua | C96: Ayivu | D96: =A96 -> Aroi | F96: 93
A97: Arua Municipality | B97: Arua | C97: Arua Municipality | D97: =A97 -> Arua Municipality | F97: 94
A98: Arua | D98: =A98 -> Arua | F98: 94
A99: Ayivuni | B99: Arua | C99: Ayivu | D99: =A99 -> Ayivuni | F99: 95
A100: Bileafe | B100: Arua | C100: Terego | D100: =A100 -> Bileafe | F100: 96
A101: Dadamu | B101: Arua | C101: Ayivu | D101: =A101 -> Dadamu | F101: 97
...

Sheet Zone analysis
A1: Zone | B1: District | C1: County | D1: Subcounty | E1: Parish | F1: DRAFT FINAL ZONE LIST | G1: DISTRICT | H1: Subcounty
A2: 243 | B2: Alebtong | C2: Moroto | D2: Abako | F2: =D2 -> Abako | G2: =B2 -> Alebtong | H2: Abako
A3: 295 | B3: Zombo | C3: Okoro | D3: Abanga | F3: =D3 -> Abanga | G3: =B3 -> Zombo | H3: Abanga
A4: 886 | B4: Amuria | C4: Amuria | D4: Abarilela | F4: =D4 -> Abarilela | G4: =B4 -> Amuria | H4: Abarilela
A5: 215 | B5: Oyam | C5: Oyam | D5: Aber | F5: =D5 -> Aber | G5: =B5 -> Oyam | H5: Aber
A6: 244 | B6: Alebtong | C6: Moroto | D6: Abia | F6: =D6 -> Abia | G6: =B6 -> Alebtong | H6: Abia
A7: 151 | B7: Abim | C7: Labwor | D7: Abim | F7: =D7 -> Abim | G7: =B7 -> Abim | H7: Abim
A8: 152 | B8: Abim | C8: Labwor | D8: Abim Town Council | F8: =D8 -> Abim Town Council | G8: =B8 -> Abim | H8: Abim Town Council
A9: 107 | B9: Nebbi | C9: Nebbi Municipality | D9: Abindu Division | F9: =VLOOKUP(C9,[2]Municipalities!$C$9:$F$1522,4,FALSE) -> Nebbi Municipality | G9: =B9 -> Nebbi | H9: Abindu Division
A10: 216 | B10: Oyam | C10: Oyam | D10: Abok | F10: =D10 -> Abok | G10: =B10 -> Oyam | H10: Abok
A11: 256 | B11: Kole | C11: Kole | D11: Aboke | F11: =D11 -> Aboke | G11: =B11 -> Kole | H11: Aboke
A12: 11 | B12: Apac | C12: Kwania | D12: Abongomola | F12: =D12 -> Abongomola | G12: =B12 -> Apac | H12: Abongomola
A13: 198 | B13: Koboko | C13: Koboko | D13: Abuku | F13: =D13 -> Abuku | G13: =B13 -> Koboko | H13: Abuku
A14: 217 | B14: Oyam | C14: Oyam | D14: Acaba | F14: =D14 -> Acaba | G14: =B14 -> Oyam | H14: Acaba
A15: 126 | B15: Pader | C15: Aruu | D15: Acholibur | F15: =D15 -> Acholibur | G15: =B15 -> Pader | H15: Acholibur
A16: 897 | B16: Amuria | C16: Kapelebyong | D16: Acowa | F16: =D16 -> Acowa | G16: =B16 -> Amuria | H16: Acowa
A17: 173 | B17: Dokolo | C17: Dokolo | D17: Adeknino | F17: =D17 -> Adeknino | G17: =B17 -> Dokolo | H17: Adeknino
A18: 79 | B18: Lira | C18: Erute | D18: Adekokwok | F18: =D18 -> Adekokwok | G18: =B18 -> Lira | H18: Adekokwok
A19: 227 | B19: Agago | C19: Agago | D19: Adilang | F19: =D19 -> Adilang | G19: =B19 -> Agago | H19: Adilang
A20: 1 | B20: Adjumani | C20: East Moyo | D20: Adjumani Town Council | F20: =D20 -> Adjumani Town Council | G20: =B20 -> Adjumani | H20: Adjumani Town Council
A21: 174 | B21: Dokolo | C21: Dokolo | D21: Adok | F21: =D21 -> Adok | G21: =B21 -> Dokolo | H21: Adok
... A26: 287 | B26: Otuke | C26: Otuke | D26: Adwari | F26: =D26 -> Adwari | G26: =B26 -> Otuke | H26: Adwari
A27: 88 | B27: Lira | C27: Lira Municipality | D27: Adyel Division | F27: =VLOOKUP(C27,[2]Municipalities!$C$9:$F$1522,4,FALSE) -> Lira Municipality | G27: =B27 -> Lira | H27: Adyel Division
A28: 228 | B28: Agago | C28: Agago | D28: Agago Town Council | F28: =D28 -> Agago Town Council | G28: =B28 -> Agago | H28: Agago Town Council
A29: 80 | B29: Lira | C29: Erute | D29: Agali | F29: =D29 -> Agali | G29: =B29 -> Lira | H29: Agali
A30: 157 | B30: Amolatar | C30: Kioga | D30: Agikdak | F30: =D30 -> Agikdak | G30: =B30 -> Amolatar | H30: Agikdak
A31: 263 | B31: Lamwo | C31: Lamwo | D31: Agoro | F31: =D31 -> Agoro | G31: =B31 -> Lamwo | H31: Agoro
A32: 802 | B32: Pallisa | C32: Agule | D32: Agule | F32: =D32 -> Agule | G32: =B32 -> Pallisa | H32: Agule
A33: 175 | B33: Dokolo | C33: Dokolo | D33: Agwata | F33: =D33 -> Agwata | G33: =B33 -> Dokolo | H33: Agwata
A34: 81 | B34: Lira | C34: Erute | D34: Agweng | F34: =D34 -> Agweng | G34: =B34 -> Lira | H34: Agweng
A35: 158 | B35: Amolatar | C35: Kioga | D35: Agwingiri | F35: =D35 -> Agwingiri | G35: =B35 -> Amolatar | H35: Agwingiri
A36: 40 | B36: Arua | C36: Terego | D36: Aii-Vu | F36: =D36 -> Aii-Vu | G36: =B36 -> Arua | H36: Aii-Vu
A37: 46 | B37: Arua | C37: Vurra | D37: Ajia | F37: =D37 -> Ajia | G37: =B37 -> Arua | H37: Ajia
A38: 257 | B38: Kole | C38: Kole | D38: Akalo | F38: =D38 -> Akalo | G38: =B38 -> Kole | H38: Akalo
A39: 887 | B39: Amuria | C39: Amuria | D39: Akeriau | F39: =D39 -> Akeriau | G39: =B39 -> Amuria | H39: Akeriau
... A70: 31 | B70: Arua | C70: Madi Okollo | D70: Anyiribu | F70: =D70 -> Anyiribu | G70: =B70 -> Arua | H70: Anyiribu
A71: 20 | B71: Apac | C71: Apac Municipality | D71: Apac | F71: =VLOOKUP(C71,[2]Municipalities!$C$9:$F$1522,4,FALSE) -> Apac Muicipality | G71: =B71 -> Apac | H71: Apac
A72: 21 | B72: Apac | C72: Apac Municipality | D72: Apac Town Council | F72: =VLOOKUP(C72,[2]Municipalities!$C$9:$F$1522,4,FALSE) -> Apac Muicipality | G72: =B72 -> Apac | H72: Apac Town Council
A73: 249 | B73: Alebtong | C73: Moroto | D73: Apala | F73: =D73 -> Apala | G73: =B73 -> Alebtong | H73: Apala
A74: 846 | B74: Kaberamaido | C74: Kalaki | D74: Apapai | F74: =D74 -> Apapai | G74: =B74 -> Kaberamaido | H74: Apapai
...

Sheet 26.10 ISINGIRO-MBARARA
B1: Consultancy services for Preparation of Expressway Development Master Plan (EDMP) for Uganda
B2: Roadside OD Interview Survey
B4: Date: | C4: 26.10.2019 | E4: Road Name: | F4: ='26.10 MBARARA-ISINGIRO'!F4:G4 -> MBARARA-NTUNGAMO ROAD | I4: Direction From: | L4: ISINGIRO | N4: Interviewers: | O4: AMOS.A, TUMUKUNDE DEVIS | V4: Supervisor: | W4: ='26.10 MBARARA-ISINGIRO'!W4 -> MIREMBE RUTH | Y4: Coded By: | Z4: ='26.10 MBARARA-ISINGIRO'!Z4 -> AJOK EMILY | AA4: Chkd By: | AB4: ='26.10 MBARARA-ISINGIRO'!AB4 -> 0
I5: Direction To: | L5: MBARARA
B7: Time | C7: Veh_Reg_No. | D7: Veh_Type | E7: No. Occupants | F7: Origin_Address | I7: Origin_Establish | J7: Origin_Purpose | K7: Origin-Purpose Desc | L7: Destination_Address | O7: Destination_Establish | P7: Destination_Purpose | Q7: Destination_Purpose Desc | R7: Journey_Purpose | S7: Approx_Distance (Km) | T7: Approx_Journey Time (Hrs) | U7: Trip_Frequency | V7: GOODS VEHICLES ONLY | Y7: Would You Use Xpressways? | Z7: Pay How Much? (UGX) | AA7: Origin_Zone | AB7: Dest_Zone
F8: Village or Town | G8: District | H8: Country | L8: Village or Town | M8: District | N8: Country | V8: Goods_Type | W8: Goods_Quantity (Ton) | X8: Goods_Value (UGXm)
B9: 0.7625 | C9: UAU 995A | D9: 4 | E9: 2 | F9: KABEREBERE | G9: ISINGIRO | H9: UG | I9: 6 | J9: 2 | K9: =VLOOKUP(J9,Key!$E$2:$F$9,2,FALSE) -> Work | L9: MBARARA TOWN | M9: MBARARA | N9: UG | O9: 6 | P9: 2 | Q9: =VLOOKUP(P9,Key!$E$2:$F$9,2,FALSE) -> Work | R9: =K9&"-"&Q9 -> Work-Work | S9: 15 | T9: 0.5 | U9: 4 | Y9: Y
B10: 0.75902778 | C10: UAY 487N | D10: 2 | E10: 2 | F10: KABALE | G10: ISINGIRO | H10: UG | I10: 1 | J10: 1 | K10: =VLOOKUP(J10,Key!$E$2:$F$9,2,FALSE) -> Home | L10: MBARARA TOWN | M10: MBARARA | N10: UG | O10: 2 | P10: 2 | Q10: =VLOOKUP(P10,Key!$E$2:$F$9,2,FALSE) -> Work | R10: =K10&"-"&Q10 -> Home-Work | S10: 5 | T10: 0.2 | U10: 5 | Y10: Y
B11: 0.75416667 | C11: UAY 682D | D11: 1 | E11: 2 | F11: RWENZIRINGIRO | G11: ISINGIRO | H11: UG | I11: 4 | J11: 3 | K11: =VLOOKUP(J11,Key!$E$2:$F$9,2,FALSE) -> Study | L11: MBARARA TOWN | M11: MBARARA | N11: UG | O11: 1 | P11: 1 | Q11: =VLOOKUP(P11,Key!$E$2:$F$9,2,FALSE) -> Home | R11: =K11&"-"&Q11 -> Study-Home | T11: 0.3 | U11: 3 | Y11: Y
B12: 0.75208333 | C12: UAP 980K | D12: 2 | E12: 1 | F12: KABALE | G12: ISINGIRO | H12: UG | I12: 1 | J12: 1 | K12: =VLOOKUP(J12,Key!$E$2:$F$9,2,FALSE) -> Home | L12: MBARARA TOWN | M12: MBARARA | N12: UG | O12: 2 | P12: 2 | Q12: =VLOOKUP(P12,Key!$E$2:$F$9,2,FALSE) -> Work | R12: =K12&"-"&Q12 -> Home-Work | S12: 4 | T12: 0.2 | U12: 3 | Y12: Y
B13: 0.74861111 | C13: UAQ 168G | D13: 1 | E13: 1 | F13: KABALE | G13: ISINGIRO | H13: UG | I13: 16 | J13: 8 | K13: =VLOOKUP(J13,Key!$E$2:$F$9,2,FALSE) -> Others | L13: MBARARA TOWN | M13: MBARARA | N13: UG | O13: 16 | P13: 8 | Q13: =VLOOKUP(P13,Key!$E$2:$F$9,2,FALSE) -> Others | R13: =K13&"-"&Q13 -> Others-Others | S13: 10 | T13: 0.2 | U13: 6 | Y13: Y
B14: 0.74513889 | C14: UAF 911X | D14: 1 | E14: 1 | F14: KABEREBERE | G14: ISINGIRO | H14: UG | I14: 2 | J14: 2 | K14: Work | L14: NYAMITANGA | M14: MBARARA | N14: UG | O14: 1 | P14: 1 | Q14: =VLOOKUP(P14,Key!$E$2:$F$9,2,FALSE) -> Home | R14: =K14&"-"&Q14 -> Work-Home | S14: 13 | T14: 0.3 | U14: 3 | Y14: Y
B15: 0.74166667 | C15: CD 103 62U | D15: 2 | E15: 2 | F15: ISINGIRO TOWN | G15: ISINGIRO | H15: UG | I15: 2 | J15: 2 | K15: =VLOOKUP(J15,Key!$E$2:$F$9,2,FALSE) -> Work | L15: MBARARA TOWN | M15: MBARARA | N15: UG | O15: 16 | P15: 8 | Q15: =VLOOKUP(P15,Key!$E$2:$F$9,2,FALSE) -> Others | R15: =K15&"-"&Q15 -> Work-Others | S15: 31 | T15: 0.8 | U15: 2 | Y15: Y
B16: 0.7375 | C16: UAX 388M | D16: 8 | E16: 1 | F16: KABINGO | G16: ISINGIRO | H16: UG | I16: 15 | J16: 4 | K16: =VLOOKUP(J16,Key!$E$2:$F$9,2,FALSE) -> Commercial | L16: MBARARA TOWN | M16: MBARARA | N16: UG | O16: 10 | P16: 2 | Q16: =VLOOKUP(P16,Key!$E$2:$F$9,2,FALSE) -> Work | R16: =K16&"-"&Q16 -> Commercial-Work | S16: 12 | T16: 0.5 | U16: 3 | V16: 4 | W16: 6 | X16: 220000 | Y16: Y
B17: 0.73333333 | C17: UAS 880K | D17: 1 | E17: 3 | F17: KABALE | G17: ISINGIRO | H17: UG | I17: 4 | J17: 3 | K17: =VLOOKUP(J17,Key!$E$2:$F$9,2,FALSE) -> Study | L17: MBARARA TOWN | M17: MBARARA | N17: UG | O17: 1 | P17: 1 | Q17: =VLOOKUP(P17,Key!$E$2:$F$9,2,FALSE) -> Home | R17: =K17&"-"&Q17 -> Study-Home | S17: 5 | T17: 0.5 | U17: 5 | Y17: Y
B18: 0.72916667 | C18: UAR 880V | D18: 1 | E18: 1 | F18: KABEREBERE | G18: ISINGIRO | H18: UG | I18: 2 | J18: 2 | K18: =VLOOKUP(J18,Key!$E$2:$F$9,2,FALSE) -> Work | L18: MBARARA TOWN | M18: MBARARA | N18: UG | O18: 2 | P18: 2 | Q18: =VLOOKUP(P18,Key!$E$2:$F$9,2,FALSE) -> Work | R18: =K18&"-"&Q18 -> Work-Work | S18: 35 | T18: 0.4 | U18: 4 | Y18: Y
B19: 0.725 | C19: UAY 304Y | D19: 8 | E19: 3 | F19: KABEREBERE | G19: ISINGIRO | H19: UG | I19: 3 | J19: 4 | K19: =VLOOKUP(J19,Key!$E$2:$F$9,2,FALSE) -> Commercial | L19: MBARARA TOWN | M19: MBARARA | N19: UG | O19: 4 | P19: 3 | Q19: =VLOOKUP(P19,Key!$E$2:$F$9,2,FALSE) -> Study | R19: =K19&"-"&Q19 -> Commercial-Study | S19: 10 | T19: 0.2 | U19: 2 | V19: 10 | W19: 4 | X19: 4500000 | Y19: Y
B20: 0.72083333 | C20: UBB 721A | D20: 1 | E20: 2 | F20: KABEREBERE | G20: ISINGIRO | H20: UG | I20: 3 | J20: 4 | K20: =VLOOKUP(J20,Key!$E$2:$F$9,2,FALSE) -> Commercial | L20: MBARARA TOWN | M20: MBARARA | N20: UG | O20: 1 | P20: 1 | Q20: =VLOOKUP(P20,Key!$E$2:$F$9,2,FALSE) -> Home | R20: =K20&"-"&Q20 -> Commercial-Home | S20: 25 | T20: 0.3 | U20: 3 | Y20: Y
B21: 0.71666667 | C21: UAL 702Y | D21: 1 | E21: 3 | F21: KABEREBERE | G21: ISINGIRO | H21: UG | I21: 1 | J21: 1 | K21: =VLOOKUP(J21,Key!$E$2:$F$9,2,FALSE) -> Home | L21: MBARARA TOWN | M21: MBARARA | N21: UG | O21: 16 | P21: 8 | Q21: =VLOOKUP(P21,Key!$E$2:$F$9,2,FALSE) -> Others | R21: =K21&"-"&Q21 -> Home-Others | S21: 35 | T21: 1 | U21: 4 | V21: 11 | Y21: Y
B22: 0.71458333 | C22: UAX 390W | D22: 1 | E22: 12 | F22: KABALE | G22: ISINGIRO | H22: UG | I22: 1 | J22: 1 | K22: =VLOOKUP(J22,Key!$E$2:$F$9,2,FALSE) -> Home | L22: MBARARA TOWN | M22: MBARARA | N22: UG | O22: 16 | P22: 8 | Q22: =VLOOKUP(P22,Key!$E$2:$F$9,2,FALSE) -> Others | R22: =K22&"-"&Q22 -> Home-Others | S22: 5 | T22: 0.2 | U22: 2 | Y22: Y
B23: 0.71111111 | C23: UAY 249B | D23: 1 | E23: 1 | F23: KASENYI | G23: ISINGIRO | H23: UG | I23: 16 | J23: 8 | K23: =VLOOKUP(J23,Key!$E$2:$F$9,2,FALSE) -> Others | L23: MBARARA TOWN | M23: MBARARA | N23: UG | O23: 1 | P23: 1 | Q23: =VLOOKUP(P23,Key!$E$2:$F$9,2,FALSE) -> Home | R23: =K23&"-"&Q23 -> Others-Home | S23: 6 | T23: 0 | U23: 3 | Y23: Y
B24: 0.70833333 | C24: UAS 808H | D24: 1 | E24: 2 | F24: KASENYI | G24: ISINGIRO | H24: UG | I24: 16 | J24: 8 | K24: =VLOOKUP(J24,Key!$E$2:$F$9,2,FALSE) -> Others | L24: MBARARA TOWN | M24: MBARARA | N24: UG | O24: 1 | P24: 1 | Q24: =VLOOKUP(P24,Key!$E$2:$F$9,2,FALSE) -> Home | R24: =K24&"-"&Q24 -> Others-Home | S24: 5 | T24: 0.3 | U24: 4 | Y24: Y
B25: 0.70416667 | C25: T487 BFH | D25: 10 | E25: 3 | F25: KABINGO | G25: ISINGIRO | H25: UG | I25: 13 | J25: 4 | K25: =VLOOKUP(J25,Key!$E$2:$F$9,2,FALSE) -> Commercial | L25: MBARARA TOWN | M25: MBARARA | N25: UG | O25: 16 | P25: 8 | Q25: =VLOOKUP(P25,Key!$E$2:$F$9,2,FALSE) -> Others | R25: Work-Others | S25: 32 | T25: 0.7 | U25: 4 | V25: 11 | Y25: Y
B26: 0.70138889 | C26: UAT 089N | D26: 3 | E26: 4 | F26: KIKAGATI | G26: ISINGIRO | H26: UG | I26: 2 | J26: 2 | K26: =VLOOKUP(J26,Key!$E$2:$F$9,2,FALSE) -> Work | L26: MBARARA TOWN | M26: MBARARA | N26: UG | O26: 1 | P26: 1 | Q26: =VLOOKUP(P26,Key!$E$2:$F$9,2,FALSE) -> Home | R26: =K26&"-"&Q26 -> Work-Home | S26: 40 | T26: 1.5 | U26: 6 | Y26: Y
B27: 0.69791667 | C27: UAM 124K | D27: 1 | E27: 8 | F27: KABINGO | G27: ISINGIRO | H27: UG | I27: 1 | J27: 1 | K27: =VLOOKUP(J27,Key!$E$2:$F$9,2,FALSE) -> Home | L27: MBARARA TOWN | M27: MBARARA | N27: UG | O27: 1 | P27: 1 | Q27: =VLOOKUP(P27,Key!$E$2:$F$9,2,FALSE) -> Home | R27: =K27&"-"&Q27 -> Home-Home | T27: 0.7 | U27: 3 | Y27: Y
B28: 0.69444444 | C28: UAQ 705F | D28: 1 | E28: 2 | F28: RWENJELU | G28: ISINGIRO | H28: UG | I28: 4 | J28: 3 | K28: =VLOOKUP(J28,Key!$E$2:$F$9,2,FALSE) -> Study | L28: MBARARA TOWN | M28: MBARARA | N28: UG | O28: 1 | P28: 1 | Q28: =VLOOKUP(P28,Key!$E$2:$F$9,2,FALSE) -> Home | R28: =K28&"-"&Q28 -> Study-Home | S28: 4 | T28: 0.5 | U28: 3 | Y28: Y
B29: 0.69027778 | C29: UAT 319R | D29: 1 | E29: 1 | F29: KASENYI | G29: ISINGIRO | H29: UG | I29: 4 | J29: 3 | K29: =VLOOKUP(J29,Key!$E$2:$F$9,2,FALSE) -> Study | L29: MBARARA TOWN | M29: MBARARA | N29: UG | O29: 1 | P29: 1 | Q29: =VLOOKUP(P29,Key!$E$2:$F$9,2,FALSE) -> Home | R29: =K29&"-"&Q29 -> Study-Home | S29: 10 | T29: 0.3 | U29: 3 | Y29: Y
B30: 0.68541667 | C30: UAN 083G | D30: 1 | E30: 2 | F30: NAKIVALA | G30: ISINGIRO | H30: UG | I30: 7 | J30: 2 | K30: =VLOOKUP(J30,Key!$E$2:$F$9,2,FALSE) -> Work | L30: MBARARA TOWN | M30: MBARARA | N30: UG | O30: 1 | P30: 1 | Q30: =VLOOKUP(P30,Key!$E$2:$F$9,2,FALSE) -> Home | R30: =K30&"-"&Q30 -> Work-Home | S30: 30 | T30: 2 | U30: 4 | V30: 10 | Y30: Y
B31: 0.53472222 | C31: UAZ 098F | D31: 2 | E31: 7 | F31: KIKAGATI | G31: ISINGIRO | H31: UG | I31: 1 | J31: 1 | K31: =VLOOKUP(J31,Key!$E$2:$F$9,2,FALSE) -> Home | L31: MBARARA TOWN | M31: MBARARA | N31: UG | O31: 1 | P31: 1 | Q31: =VLOOKUP(P31,Key!$E$2:$F$9,2,FALSE) -> Home | R31: =K31&"-"&Q31 -> Home-Home | S31: 69 | T31: 1 | U31: 4 | Y31: Y
B32: 0.53055556 | C32: UAJ 803W | D32: 1 | E32: 1 | F32: KABEREBERE | G32: ISINGIRO | H32: UG | I32: 1 | J32: 1 | K32: =VLOOKUP(J32,Key!$E$2:$F$9,2,FALSE) -> Home | L32: MBARARA TOWN | M32: MBARARA | N32: UG | O32: 2 | P32: 2 | Q32: =VLOOKUP(P32,Key!$E$2:$F$9,2,FALSE) -> Work | R32: =K32&"-"&Q32 -> Home-Work | S32: 9 | T32: 0.5 | U32: 2 | Y32: Y
B33: 0.52777778 | C33: UBE 386H | D33: 1 | E33: 4 | F33: KABEREBERE | G33: ISINGIRO | H33: UG | I33: 4 | J33: 3 | K33: =VLOOKUP(J33,Key!$E$2:$F$9,2,FALSE) -> Study | L33: MBARARA TOWN | M33: MBARARA | N33: UG | O33: 1 | P33: 1 | Q33: =VLOOKUP(P33,Key!$E$2:$F$9,2,FALSE) -> Home | R33: =K33&"-"&Q33 -> Study-Home | S33: 52 | T33: 1 | U33: 3 | Y33: Y
B34: 0.525 | C34: UBE 561U | D34: 2 | E34: 1 | F34: KIRUMBA | G34: ISINGIRO | H34: UG | I34: 16 | J34: 8 | K34: =VLOOKUP(J34,Key!$E$2:$F$9,2,FALSE) -> Others | L34: KAMPALA TOWN | M34: KAMPALA | N34: UG | O34: 1 | P34: 1 | Q34: =VLOOKUP(P34,Key!$E$2:$F$9,2,FALSE) -> Home | R34: =K34&"-"&Q34 -> Others-Home | T34: 3 | U34: 6 | Y34: Y
B35: 0.52083333 | C35: UBD 114B | D35: 1 | E35: 3 | F35: KASENYI | G35: ISINGIRO | H35: UG | I35: 1 | J35: 1 | K35: =VLOOKUP(J35,Key!$E$2:$F$9,2,FALSE) -> Home | L35: MBARARA TOWN | M35: MBARARA | N35: UG | O35: 2 | P35: 2 | Q35: =VLOOKUP(P35,Key!$E$2:$F$9,2,FALSE) -> Work | R35: =K35&"-"&Q35 -> Home-Work | S35: 4 | T35: 0.3 | U35: 1 | Y35: Y
B36: 0.51736111 | C36: UAD 009J | D36: 3 | E36: 2 | F36: KABEREBERE | G36: ISINGIRO | H36: UG | I36: 1 | J36: 1 | K36: =VLOOKUP(J36,Key!$E$2:$F$9,2,FALSE) -> Home | L36: MBARARA TOWN | M36: MBARARA | N36: UG | O36: 1 | P36: 1 | Q36: =VLOOKUP(P36,Key!$E$2:$F$9,2,FALSE) -> Home | R36: =K36&"-"&Q36 -> Home-Home | S36: 13 | T36: 0.5 | U36: 4 | V36: 10 | Y36: Y
B37: 0.51527778 | C37: UAP 660M | D37: 1 | E37: 4 | F37: KABEREBERE | G37: ISINGIRO | H37: UG | I37: 1 | J37: 1 | K37: =VLOOKUP(J37,Key!$E$2:$F$9,2,FALSE) -> Home | L37: MBARARA TOWN | M37: MBARARA | N37: UG | O37: 16 | P37: 8 | Q37: =VLOOKUP(P37,Key!$E$2:$F$9,2,FALSE) -> Others | R37: =K37&"-"&Q37 -> Home-Others | S37: 35 | T37: 2 | U37: 6 | Y37: Y
B38: 0.51319444 | C38: UAL 863M | D38: 2 | E38: 3 | F38: KABINGO | G38: ISINGIRO | H38: UG | I38: 1 | J38: 1 | K38: =VLOOKUP(J38,Key!$E$2:$F$9,2,FALSE) -> Home | L38: MBARARA TOWN | M38: MBARARA | N38: UG | O38: 5 | P38: 7 | Q38: =VLOOKUP(P38,Key!$E$2:$F$9,2,FALSE) -> Hospital | R38: =K38&"-"&Q38 -> Home-Hospital | S38: 36 | T38: 0.5 | U38: 3 | Y38: Y
B39: 0.51041667 | C39: UAW 625J | D39: 8 | E39: 2 | F39: KABEREBERE | G39: ISINGIRO | H39: UG | I39: 13 | J39: 4 | K39: =VLOOKUP(J39,Key!$E$2:$F$9,2,FALSE) -> Commercial | L39: MBARARA TOWN | M39: MBARARA | N39: UG | O39: 10 | P39: 2 | Q39: =VLOOKUP(P39,Key!$E$2:$F$9,2,FALSE) -> Work | R39: =K39&"-"&Q39 -> Commercial-Work | S39: 37 | T39: 1.5 | U39: 2 | V39: 4 | W39: 6 | X39: 40000 | Y39: Y
B40: 0.50763889 | C40: UAE 190G | D40: 1 | E40: 1 | F40: KASENYI | G40: ISINGIRO | H40: UG | I40: 4 | J40: 3 | K40: =VLOOKUP(J40,Key!$E$2:$F$9,2,FALSE) -> Study | L40: MBARARA TOWN | M40: MBARARA | N40: UG | O40: 1 | P40: 1 | Q40: =VLOOKUP(P40,Key!$E$2:$F$9,2,FALSE) -> Home | R40: =K40&"-"&Q40 -> Study-Home | S40: 2 | T40: 0.2 | U40: 2 | Y40: Y
B41: 0.44097222 | C41: UBA 760C | D41: 2 | E41: 2 | F41: ISINGIRO TOWN | G41: ISINGIRO | H41: UG | I41: 1 | J41: 1 | K41: =VLOOKUP(J41,Key!$E$2:$F$9,2,FALSE) -> Home | L41: MBARARA TOWN | M41: MBARARA | N41: UG | O41: 4 | P41: 3 | Q41: =VLOOKUP(P41,Key!$E$2:$F$9,2,FALSE) -> Study | R41: =K41&"-"&Q41 -> Home-Study | S41: 44 | T41: 1 | U41: 4 | Y41: Y
B42: 0.4375 | C42: UAQ 147X | D42: 2 | E42: 1 | F42: NGALAMA | G42: ISINGIRO | H42: UG | I42: 1 | J42: 1 | K42: =VLOOKUP(J42,Key!$E$2:$F$9,2,FALSE) -> Home | L42: MBARARA TOWN | M42: MBARARA | N42: UG | O42: 16 | P42: 8 | Q42: =VLOOKUP(P42,Key!$E$2:$F$9,2,FALSE) -> Others | R42: =K42&"-"&Q42 -> Home-Others | S42: 33 | T42: 1 | U42: 4 | Y42: Y
...

Sheet 26.10 MBARARA-ISINGIRO
B1: Consultancy services for Preparation of Expressway Development Master Plan (EDMP) for Uganda
B2: Roadside OD Interview Survey
B4: Date: | C4: 26.10.2019 | E4: Road Name: | F4: ='28.10 MBARARA-ISINGIRO'!F4:G4 -> MBARARA-NTUNGAMO ROAD | I4: Direction From: | L4: MBARARA | N4: Interviewers: | O4: MIREMBE RUTH, NIWAMANYA SAVIOR | V4: Supervisor: | W4: ='28.10 MBARARA-ISINGIRO'!W4 -> MIREMBE RUTH | Y4: Coded By: | Z4: ='28.10 MBARARA-ISINGIRO'!Z4 -> AJOK EMILY | AA4: Chkd By: | AB4: ='28.10 MBARARA-ISINGIRO'!AB4 -> 0
I5: Direction To: | L5: ISINGIRO
B7: Time | C7: Veh_Reg_No. | D7: Veh_Type | E7: No. Occupants | F7: Origin_Address | I7: Origin_Establish | J7: Origin_Purpose | K7: Origin-Purpose Desc | L7: Destination_Address | O7: Destination_Establish | P7: Destination_Purpose | Q7: Destination_Purpose Desc | R7: Journey_Purpose | S7: Approx_Distance (Km) | T7: Approx_Journey Time (Hrs) | U7: Trip_Frequency | V7: GOODS VEHICLES ONLY | Y7: Would You Use Xpressways? | Z7: Pay How Much? (UGX) | AA7: Origin_Zone | AB7: Dest_Zone
F8: Village or Town | G8: District | H8: Country | L8: Village or Town | M8: District | N8: Country | V8: Goods_Type | W8: Goods_Quantity (Ton) | X8: Goods_Value (UGXm)
B9: 0.48611111 | C9: UAR 466V | D9: 8 | E9: 2 | F9: MBARARA TOWN | G9: MBARARA | H9: UG | I9: 7 | J9: 4 | K9: =VLOOKUP(J9,Key!$E$2:$F$9,2,FALSE) -> Commercial | L9: WAKIRURI | M9: ISINGIRO | N9: UG | O9: 10 | P9: 2 | Q9: =VLOOKUP(P9,Key!$E$2:$F$9,2,FALSE) -> Work | R9: =K9&"-"&Q9 -> Commercial-Work | U9: 1 | Y9: Y
B10: 0.5 | C10: UEJ 256N | D10: 11 | E10: 2 | F10: KASENYI | G10: ISINGIRO | H10: UG | I10: 8 | J10: 2 | K10: =VLOOKUP(J10,Key!$E$2:$F$9,2,FALSE) -> Work | L10: MUKIWOGA | M10: ISINGIRO | N10: UG | O10: 8 | P10: 4 | Q10: =VLOOKUP(P10,Key!$E$2:$F$9,2,FALSE) -> Commercial | R10: =K10&"-"&Q10 -> Work-Commercial | S10: 2 | T10: 0.2 | U10: 1 | Y10: Y
B11: 0.50347222 | C11: UBD 241T | D11: 8 | E11: 1 | F11: KASENYI | G11: ISINGIRO | H11: UG | I11: 10 | J11: 2 | K11: =VLOOKUP(J11,Key!$E$2:$F$9,2,FALSE) -> Work | L11: KABALE | M11: ISINGIRO | N11: UG | O11: 15 | P11: 4 | Q11: =VLOOKUP(P11,Key!$E$2:$F$9,2,FALSE) -> Commercial | R11: =K11&"-"&Q11 -> Work-Commercial | S11: 1 | T11: 0 | U11: 1 | V11: 11 | Y11: Y
B12: 0.50694444 | C12: UAU 338H | D12: 1 | E12: 1 | F12: MBARARA TOWN | G12: MBARARA | H12: UG | I12: 1 | J12: 1 | K12: =VLOOKUP(J12,Key!$E$2:$F$9,2,FALSE) -> Home | L12: ISINGIRO TOWN | M12: ISINGIRO | N12: UG | O12: 1 | P12: 1 | Q12: =VLOOKUP(P12,Key!$E$2:$F$9,2,FALSE) -> Home | R12: =K12&"-"&Q12 -> Home-Home | S12: 31 | T12: 2 | U12: 2 | Y12: Y
B13: 0.51041667 | C13: UBE 962L | D13: 2 | E13: 2 | F13: MBARARA TOWN | G13: MBARARA | H13: UG | I13: 4 | J13: 3 | K13: =VLOOKUP(J13,Key!$E$2:$F$9,2,FALSE) -> Study | L13: KIRUMBA | M13: ISINGIRO | N13: UG | O13: 1 | P13: 1 | Q13: =VLOOKUP(P13,Key!$E$2:$F$9,2,FALSE) -> Home | R13: =K13&"-"&Q13 -> Study-Home | S13: 15 | T13: 0.3 | U13: 1 | Y13: Y
B14: 0.51388889 | C14: UAP 691R | D14: 1 | E14: 2 | F14: MBARARA TOWN | G14: MBARARA | H14: UG | I14: 1 | J14: 1 | K14: =VLOOKUP(J14,Key!$E$2:$F$9,2,FALSE) -> Home | L14: KIKAGATI | M14: ISINGIRO | N14: UG | O14: 2 | P14: 2 | Q14: =VLOOKUP(P14,Key!$E$2:$F$9,2,FALSE) -> Work | R14: =K14&"-"&Q14 -> Home-Work | U14: 1 | Y14: Y
B15: 0.51944444 | C15: UAM 835Z | D15: 2 | E15: 1 | F15: MBARARA TOWN | G15: MBARARA | H15: UG | I15: 1 | J15: 1 | K15: =VLOOKUP(J15,Key!$E$2:$F$9,2,FALSE) -> Home | L15: ISINGIRO TOWN | M15: ISINGIRO | N15: UG | O15: 1 | P15: 1 | Q15: =VLOOKUP(P15,Key!$E$2:$F$9,2,FALSE) -> Home | R15: =K15&"-"&Q15 -> Home-Home | S15: 40 | T15: 0.5 | U15: 1 | Y15: Y
B16: 0.52430556 | C16: UEQ 325M | D16: 11 | E16: 1 | F16: KASENYI | G16: ISINGIRO | H16: UG | I16: 8 | J16: 2 | K16: =VLOOKUP(J16,Key!$E$2:$F$9,2,FALSE) -> Work | L16: KABEREBERE | M16: ISINGIRO | N16: UG | O16: 8 | P16: 2 | Q16: =VLOOKUP(P16,Key!$E$2:$F$9,2,FALSE) -> Work | R16: =K16&"-"&Q16 -> Work-Work | S16: 10 | T16: 0.5 | U16: 1 | Y16: Y
B17: 0.68055556 | C17: UDG 462S | D17: 11 | E17: 1 | F17: MBARARA TOWN | G17: MBARARA | H17: UG | I17: 8 | J17: 2 | K17: =VLOOKUP(J17,Key!$E$2:$F$9,2,FALSE) -> Work | L17: ISINGIRO TOWN | M17: ISINGIRO | N17: UG | O17: 8 | P17: 2 | Q17: =VLOOKUP(P17,Key!$E$2:$F$9,2,FALSE) -> Work | R17: =K17&"-"&Q17 -> Work-Work | S17: 40 | T17: 1 | U17: 1 | Y17: Y
B18: 0.54513889 | C18: UBE 052G | D18: 8 | E18: 2 | F18: IGANGA TOWN | G18: IGANGA | H18: UG | I18: 2 | J18: 2 | K18: =VLOOKUP(J18,Key!$E$2:$F$9,2,FALSE) -> Work | L18: ISINGIRO TOWN | M18: ISINGIRO | N18: UG | O18: 2 | P18: 2 | Q18: =VLOOKUP(P18,Key!$E$2:$F$9,2,FALSE) -> Work | R18: =K18&"-"&Q18 -> Work-Work | S18: 260 | T18: 0.4 | U18: 1 | V18: 11 | Y18: Y
B19: 0.51388889 | C19: UAN 475M | D19: 1 | E19: 1 | F19: MBARARA TOWN | G19: MBARARA | H19: UG | I19: 4 | J19: 3 | K19: =VLOOKUP(J19,Key!$E$2:$F$9,2,FALSE) -> Study | L19: ISINGIRO TOWN | M19: ISINGIRO | N19: UG | O19: 1 | P19: 1 | Q19: =VLOOKUP(P19,Key!$E$2:$F$9,2,FALSE) -> Home | R19: =K19&"-"&Q19 -> Study-Home | S19: 20 | T19: 2 | U19: 4 | Y19: Y
B20: 0.50763889 | C20: UPE 240E | D20: 1 | E20: 2 | F20: MBARARA TOWN | G20: MBARARA | H20: UG | I20: 2 | J20: 2 | K20: =VLOOKUP(J20,Key!$E$2:$F$9,2,FALSE) -> Work | L20: NYAMITANGA | M20: ISINGIRO | N20: UG | O20: 1 | P20: 1 | Q20: =VLOOKUP(P20,Key!$E$2:$F$9,2,FALSE) -> Home | R20: =K20&"-"&Q20 -> Work-Home | T20: 2 | U20: 1 | Y20: Y
B21: 0.52916667 | C21: UAV 143P | D21: 11 | E21: 2 | F21: MBARARA TOWN | G21: MBARARA | H21: UG | I21: 1 | J21: 1 | K21: =VLOOKUP(J21,Key!$E$2:$F$9,2,FALSE) -> Home | L21: KABEREBERE | M21: ISINGIRO | N21: UG | O21: 8 | P21: 2 | Q21: =VLOOKUP(P21,Key!$E$2:$F$9,2,FALSE) -> Work | R21: =K21&"-"&Q21 -> Home-Work | S21: 40 | T21: 2 | U21: 1 | Y21: Y
B22: 0.52638889 | C22: UET 325G | D22: 1 | E22: 2 | F22: MBARARA TOWN | G22: MBARARA | H22: UG | I22: 2 | J22: 2 | K22: Work | L22: ISINGIRO TOWN | M22: ISINGIRO | N22: UG | O22: 1 | P22: 1 | Q22: Home | R22: =K22&"-"&Q22 -> Work-Home | S22: 12 | T22: 2 | U22: 1 | Y22: Y
B23: 0.6875 | C23: UAR 049L | D23: 1 | E23: 1 | F23: KATETE | G23: MBARARA | H23: UG | I23: 3 | J23: 4 | K23: =VLOOKUP(J23,Key!$E$2:$F$9,2,FALSE) -> Commercial | L23: KABEREBERE | M23: ISINGIRO | N23: UG | O23: 1 | P23: 1 | Q23: =VLOOKUP(P23,Key!$E$2:$F$9,2,FALSE) -> Home | R23: =K23&"-"&Q23 -> Commercial-Home | S23: 3 | T23: 0.5 | U23: 2 | Y23: Y
B24: 0.69791667 | C24: UAX 096P | D24: 7 | E24: 3 | F24: MBARARA TOWN | G24: MBARARA | H24: UG | I24: 10 | J24: 4 | K24: =VLOOKUP(J24,Key!$E$2:$F$9,2,FALSE) -> Commercial | L24: KABEREBERE | M24: ISINGIRO | N24: UG | O24: 10 | P24: 4 | Q24: =VLOOKUP(P24,Key!$E$2:$F$9,2,FALSE) -> Commercial | R24: =K24&"-"&Q24 -> Commercial-Commercial | S24: 8 | T24: 0.3 | U24: 2 | V24: 4 | W24: 6 | Y24: Y
B25: 0.69930556 | C25: UEE 491 | D25: 3 | E25: 2 | F25: MBARARA TOWN | G25: MBARARA | H25: UG | I25: 1 | J25: 1 | K25: =VLOOKUP(J25,Key!$E$2:$F$9,2,FALSE) -> Home | L25: KABEREBERE | M25: ISINGIRO | N25: UG | O25: 2 | P25: 2 | Q25: =VLOOKUP(P25,Key!$E$2:$F$9,2,FALSE) -> Work | R25: =K25&"-"&Q25 -> Home-Work | S25: 4 | T25: 0.2 | U25: 1 | Y25: Y
B26: 0.70486111 | C26: UAX 589Q | D26: 1 | E26: 2 | F26: BUSHENYI TOWN | G26: BUSHENYI | H26: UG | I26: 4 | J26: 3 | K26: =VLOOKUP(J26,Key!$E$2:$F$9,2,FALSE) -> Study | L26: ISINGIRO TOWN | M26: ISINGIRO | N26: UG | O26: 4 | P26: 2 | Q26: =VLOOKUP(P26,Key!$E$2:$F$9,2,FALSE) -> Work | R26: =K26&"-"&Q26 -> Study-Work | S26: 80 | T26: 1 | U26: 1 | Y26: Y
B27: 0.71111111 | C27: LG 018,035 | D27: 3 | E27: 1 | F27: JINJA TOWN | G27: JINJA | H27: UG | I27: 2 | J27: 2 | K27: =VLOOKUP(J27,Key!$E$2:$F$9,2,FALSE) -> Work | L27: KABEREBERE | M27: ISINGIRO | N27: UG | O27: 1 | P27: 1 | Q27: =VLOOKUP(P27,Key!$E$2:$F$9,2,FALSE) -> Home | R27: =K27&"-"&Q27 -> Work-Home | S27: 350 | T27: 0.2 | U27: 1 | Y27: Y
B28: 0.67361111 | C28: UAV 933R | D28: 3 | E28: 1 | F28: MBARARA TOWN | G28: MBARARA | H28: UG | I28: 2 | J28: 2 | K28: =VLOOKUP(J28,Key!$E$2:$F$9,2,FALSE) -> Work | L28: KIKAGATI | M28: ISINGIRO | N28: UG | O28: 1 | P28: 1 | Q28: =VLOOKUP(P28,Key!$E$2:$F$9,2,FALSE) -> Home | R28: =K28&"-"&Q28 -> Work-Home | U28: 1 | Y28: Y
B29: 0.71875 | C29: T612 DFH | D29: 1 | E29: 4 | F29: MBARARA TOWN | G29: MBARARA | H29: UG | I29: 2 | J29: 2 | K29: =VLOOKUP(J29,Key!$E$2:$F$9,2,FALSE) -> Work | L29: KIGAGATI | M29: ISINGIRO | N29: UG | O29: 1 | P29: 1 | Q29: =VLOOKUP(P29,Key!$E$2:$F$9,2,FALSE) -> Home | R29: =K29&"-"&Q29 -> Work-Home | S29: 58 | T29: 1 | U29: 1 | Y29: Y
B30: 0.73125 | C30: UAP 245X | D30: 7 | E30: 2 | F30: MBARARA TOWN | G30: MBARARA | H30: UG | I30: 10 | J30: 2 | K30: =VLOOKUP(J30,Key!$E$2:$F$9,2,FALSE) -> Work | L30: ISINGIRO TOWN | M30: ISINGIRO | N30: UG | O30: 1 | P30: 1 | Q30: =VLOOKUP(P30,Key!$E$2:$F$9,2,FALSE) -> Home | R30: =K30&"-"&Q30 -> Work-Home | S30: 17 | T30: 0.2 | U30: 1 | V30: 11 | Y30: Y
B31: 0.74583333 | C31: UBA 700H | D31: 1 | E31: 1 | F31: MBARARA TOWN | G31: MBARARA | H31: UG | I31: 2 | J31: 2 | K31: =VLOOKUP(J31,Key!$E$2:$F$9,2,FALSE) -> Work | L31: KABEREBERE | M31: ISINGIRO | N31: UG | O31: 1 | P31: 1 | Q31: =VLOOKUP(P31,Key!$E$2:$F$9,2,FALSE) -> Home | R31: =K31&"-"&Q31 -> Work-Home | S31: 7 | T31: 0.2 | U31: 1 | Y31: Y
B32: 0.75 | C32: UAS 056W | D32: 1 | E32: 3 | F32: KASENYI | G32: ISINGIRO | H32: UG | I32: 1 | J32: 1 | K32: =VLOOKUP(J32,Key!$E$2:$F$9,2,FALSE) -> Home | L32: MASHA | M32: ISINGIRO | N32: UG | O32: 9 | P32: 4 | Q32: =VLOOKUP(P32,Key!$E$2:$F$9,2,FALSE) -> Commercial | R32: =K32&"-"&Q32 -> Home-Commercial | S32: 2 | T32: 0 | U32: 1 | Y32: Y
B33: 0.76527778 | C33: UBB 249C | D33: 2 | E33: 1 | F33: MBARARA TOWN | G33: MBARARA | H33: UG | I33: 2 | J33: 2 | K33: =VLOOKUP(J33,Key!$E$2:$F$9,2,FALSE) -> Work | L33: NTUNGU | M33: ISINGIRO | N33: UG | O33: 1 | P33: 1 | Q33: =VLOOKUP(P33,Key!$E$2:$F$9,2,FALSE) -> Home | R33: =K33&"-"&Q33 -> Work-Home | S33: 25 | T33: 0 | U33: 1 | Y33: Y
B34: 0.76736111 | C34: UAZ 934U | D34: 1 | E34: 1 | F34: MBARARA TOWN | G34: MBARARA | H34: UG | I34: 2 | J34: 2 | K34: =VLOOKUP(J34,Key!$E$2:$F$9,2,FALSE) -> Work | L34: KABALE | M34: ISINGIRO | N34: UG | O34: 1 | P34: 1 | Q34: =VLOOKUP(P34,Key!$E$2:$F$9,2,FALSE) -> Home | R34: =K34&"-"&Q34 -> Work-Home | S34: 6 | T34: 0.2 | U34: 2 | Y34: Y
B35: 0.78125 | C35: UBE 125F | D35: 1 | E35: 3 | F35: NYAMITANGA | G35: MBARARA | H35: UG | I35: 11 | J35: 6 | K35: =VLOOKUP(J35,Key!$E$2:$F$9,2,FALSE) -> Leisure/Social | L35: ISINGIRO TOWN | M35: ISINGIRO | N35: UG | O35: 1 | P35: 1 | Q35: =VLOOKUP(P35,Key!$E$2:$F$9,2,FALSE) -> Home | R35: =K35&"-"&Q35 -> Leisure/Social-Home | S35: 31 | T35: 1.5 | U35: 3 | Y35: Y
B36: 0.77152778 | C36: UBE 359F | D36: 2 | E36: 1 | F36: MBARARA TOWN | G36: MBARARA | H36: UG | I36: 2 | J36: 2 | K36: =VLOOKUP(J36,Key!$E$2:$F$9,2,FALSE) -> Work | L36: KIRUMBA | M36: ISINGIRO | N36: UG | O36: 1 | P36: 1 | Q36: =VLOOKUP(P36,Key!$E$2:$F$9,2,FALSE) -> Home | R36: =K36&"-"&Q36 -> Work-Home | S36: 15 | T36: 0.5 | U36: 1 | Y36: Y
B37: 0.76736111 | C37: UAT 156X | D37: 2 | E37: 4 | F37: MBARARA TOWN | G37: MBARARA | H37: UG | I37: 16 | J37: 6 | K37: =VLOOKUP(J37,Key!$E$2:$F$9,2,FALSE) -> Leisure/Social | L37: NAKIVALE | M37: ISINGIRO | N37: UG | O37: 1 | P37: 1 | Q37: =VLOOKUP(P37,Key!$E$2:$F$9,2,FALSE) -> Home | R37: =K37&"-"&Q37 -> Leisure/Social-Home | S37: 6 | T37: 0.1 | U37: 3 | Y37: Y
B38: 0.76388889 | C38: UAQ 562Q | D38: 3 | E38: 3 | F38: KASENYI | G38: ISINGIRO | H38: UG | I38: 9 | J38: 2 | K38: =VLOOKUP(J38,Key!$E$2:$F$9,2,FALSE) -> Work | L38: KABEREBERE | M38: ISINGIRO | N38: UG | O38: 1 | P38: 1 | Q38: =VLOOKUP(P38,Key!$E$2:$F$9,2,FALSE) -> Home | R38: =K38&"-"&Q38 -> Work-Home | U38: 3 | Y38: Y
B39: 0.75763889 | C39: UAE 227Y | D39: 7 | E39: 3 | F39: MBARARA TOWN | G39: MBARARA | H39: UG | I39: 11 | J39: 4 | K39: =VLOOKUP(J39,Key!$E$2:$F$9,2,FALSE) -> Commercial | L39: KIKAGATI | M39: ISINGIRO | N39: UG | O39: 11 | P39: 4 | Q39: =VLOOKUP(P39,Key!$E$2:$F$9,2,FALSE) -> Commercial | R39: =K39&"-"&Q39 -> Commercial-Commercial | T39: 1.5 | U39: 3 | V39: 4 | W39: 5 | Y39: Y
B40: 0.75 | C40: UAY 513E | D40: 8 | E40: 1 | F40: KASESE TOWN | G40: KASESE | H40: UG | I40: 3 | J40: 2 | K40: =VLOOKUP(J40,Key!$E$2:$F$9,2,FALSE) -> Work | L40: RWEZIRINGIRO | M40: ISINGIRO | N40: UG | O40: 11 | P40: 4 | Q40: =VLOOKUP(P40,Key!$E$2:$F$9,2,FALSE) -> Commercial | R40: =K40&"-"&Q40 -> Work-Commercial | S40: 100 | U40: 3 | V40: 11 | Y40: Y
B41: 0.75138889 | C41: UG 162E | D41: 3 | E41: 1 | F41: KABINGO | G41: MBARARA | H41: UG | I41: 2 | J41: 2 | K41: =VLOOKUP(J41,Key!$E$2:$F$9,2,FALSE) -> Work | L41: MIROTWELVE | M41: ISINGIRO | N41: UG | O41: 1 | P41: 1 | Q41: =VLOOKUP(P41,Key!$E$2:$F$9,2,FALSE) -> Home | R41: =K41&"-"&Q41 -> Work-Home | T41: 0.3 | U41: 1 | Y41: Y
B42: 0.71875 | C42: UAZ 936G | D42: 1 | E42: 4 | F42: MBARARA TOWN | G42: MBARARA | H42: UG | I42: 11 | J42: 6 | K42: =VLOOKUP(J42,Key!$E$2:$F$9,2,FALSE) -> Leisure/Social | L42: KABUYANDA | M42: ISINGIRO | N42: UG | O42: 1 | P42: 1 | Q42: =VLOOKUP(P42,Key!$E$2:$F$9,2,FALSE) -> Home | R42: =K42&"-"&Q42 -> Leisure/Social-Home | T42: 1.5 | U42: 3 | Y42: Y
...

Sheet 28.10 MBARARA-ISINGIRO
B1: Consultancy services for Preparation of Expressway Development Master Plan (EDMP) for Uganda
B2: Roadside OD Interview Survey
B4: Date: | C4: 28.10.2019 | E4: Road Name: | F4: MBARARA-NTUNGAMO ROAD | I4: Direction From: | L4: MBARARA | N4: Interviewers: | O4: MIREMBE RUTH, NIWAMANYA SAVIOR | V4: Supervisor: | W4: MIREMBE RUTH | Y4: Coded By: | Z4: AJOK EMILY | AA4: Chkd By:
I5: Direction To: | L5: ISINGIRO
B7: Time | C7: Veh_Reg_No. | D7: Veh_Type | E7: No. Occupants | F7: Origin_Address | I7: Origin_Establish | J7: Origin_Purpose | K7: Origin-Purpose Desc | L7: Destination_Address | O7: Destination_Establish | P7: Destination_Purpose | Q7: Destination_Purpose Desc | R7: Journey_Purpose | S7: Approx_Distance (Km) | T7: Approx_Journey Time (Hrs) | U7: Trip_Frequency | V7: GOODS VEHICLES ONLY | Y7: Would You Use Xpressways? | Z7: Pay How Much? (UGX) | AA7: Origin_Zone | AB7: Dest_Zone
