Workbook

Sheet JT data
B2: Consultancy services for Preparation of Expressway Development Master Plan (EDMP) for Uganda
B3: JOURNEY TIME TRAFFIC SURVEY (October 2019) | CR3: NOTE: 5 graphs to be plotted also for JT18, JT20, JT21, JT23, JT24, JT30
Y4: From Kampala | AB4: Towards Kampala | AE4: From Kampala | AH4: Towards Kampala | AK4: From Kampala | AL4: Twds Kampala | CR4: The remainder, only 3 graphs are adequate
E5: Timing Points | G5: Distance Km | H5: AM (0700-1000) | K5: IP (1000-1600) | N5: PM (1600-2000) | Y5: Average Journey Time (min) | AB5: Average Journey Time (min) | AE5: Average Journey Time/Km (min/Km) | AH5: Average Journey Time/Km (min/Km) | AK5: Max JT/Km | AL5: Max JT/Km
B6: Ref | C6: Route | D6: Pass | E6: From | F6: To | H6: Start Time | I6: Arrival Time | J6: J/Time (min) | K6: Start Time | L6: Arrival Time | M6: J/Time (min) | N6: Start Time | O6: Arrival Time | P6: J/Time (min) | W6: Road Condition | X6: Distance (Km) | Y6: AM | Z6: IP | AA6: PM | AB6: AM | AC6: IP | AD6: PM | AE6: AM | AF6: IP | AG6: PM | AH6: AM | AI6: IP | AJ6: PM | AK6: From Kampala | AL6: Twds Kampala
B7: JT1 | C7: Kampala - Jinja | D7: 1 | E7: Spear Junction | F7: Bweyogerere | G7: 5.6 | H7: 0.29861111 | I7: 0.30902778 | J7: 15 | K7: 0.47430556 | L7: 0.48402778 | M7: 14 | N7: 0.66875 | O7: 0.68125 | P7: 18 | R7: JT1 | S7: Kampala - Jinja | T7: Spear Junction | U7: Bweyogerere | V7: =T7&"-"&U7 -> Spear Junction-Bweyogerere | W7: Tarmac-good | X7: =G7 -> 5.6 | Y7: =AVERAGE(J7:J9) -> 16.666667 | Z7: =AVERAGE(M7:M9) -> 13.666667 | AA7: =AVERAGE(P7:P9) -> 21 | AB7: =AVERAGE(J10:J12) -> 17 | AC7: =AVERAGE(M10:M12) -> 13.333333 | AD7: =AVERAGE(P10:P12) -> 15.333333 | AE7: =Y7/$X7 -> 2.9761905 | AF7: =Z7/$X7 -> 2.4404762 | AG7: =AA7/$X7 -> 3.75 | AH7: =AB7/$X7 -> 3.0357143 | AI7: =AC7/$X7 -> 2.3809524 | AJ7: =AD7/$X7 -> 2.7380952 | AK7: =MAX(AE7:AG7) -> 3.75 | AL7: =MAX(AH7:AJ7) -> 3.0357143 | AM7: =$X7/(AVERAGE(Y7,AB7)/60) -> 19.960396 | AN7: =$X7/(AVERAGE(Z7,AC7)/60) -> 24.888889 | AO7: =$X7/(AVERAGE(AA7,AD7)/60) -> 18.495413
D8: 2 | E8: Spear Junction | F8: Bweyogerere | G8: 5.6 | H8: 0.36944444 | I8: 0.38333333 | J8: 20 | K8: 0.61875 | L8: 0.62847222 | M8: 14 | N8: 0.70833333 | O8: 0.72222222 | P8: 20 | T8: Bweyogerere | U8: Mukono | V8: =T8&"-"&U8 -> Bweyogerere-Mukono | W8: Tarmac-good | X8: =G13 -> 11 | Y8: =AVERAGE(J13:J15) -> 24.666667 | Z8: =AVERAGE(M13:M15) -> 28.666667 | AA8: =AVERAGE(P13:P15) -> 37.666667 | AB8: =AVERAGE(J16:J18) -> 40.333333 | AC8: =AVERAGE(M16:M18) -> 34 | AD8: =AVERAGE(P16:P18) -> 40.666667 | AE8: =Y8/$X8 -> 2.2424242 | AF8: =Z8/$X8 -> 2.6060606 | AG8: =AA8/$X8 -> 3.4242424 | AH8: =AB8/$X8 -> 3.6666667 | AI8: =AC8/$X8 -> 3.0909091 | AJ8: =AD8/$X8 -> 3.6969697 | AK8: =MAX(AE8:AG8) -> 3.4242424 | AL8: =MAX(AH8:AJ8) -> 3.6969697
D9: 3 | E9: Spear Junction | F9: Bweyogerere | G9: 5.6 | H9: 0.32361111 | I9: 0.33402778 | J9: 15 | K9: 0.44097222 | L9: 0.45 | M9: 13 | N9: 0.6875 | O9: 0.70486111 | P9: 25 | T9: Mukono | U9: Lugazi | V9: =T9&"-"&U9 -> Mukono-Lugazi | W9: Tarmac-good | X9: =G19 -> 24 | Y9: =AVERAGE(J19:J21) -> 33.333333 | Z9: =AVERAGE(M19:M21) -> 34.333333 | AA9: =AVERAGE(P19:P21) -> 36 | AB9: =AVERAGE(J22:J24) -> 34.666667 | AC9: =AVERAGE(M22:M24) -> 37.666667 | AD9: =AVERAGE(P22:P24) -> 40 | AE9: =Y9/$X9 -> 1.3888889 | AF9: =Z9/$X9 -> 1.4305556 | AG9: =AA9/$X9 -> 1.5 | AH9: =AB9/$X9 -> 1.4444444 | AI9: =AC9/$X9 -> 1.5694444 | AJ9: =AD9/$X9 -> 1.6666667 | AK9: =MAX(AE9:AG9) -> 1.5 | AL9: =MAX(AH9:AJ9) -> 1.6666667
D10: 1 | E10: Bweyogerere | F10: Spear Junction | G10: 5.6 | H10: 0.37083333 | I10: 0.33958333 | J10: 15 | K10: 0.47430556 | L10: 0.48263889 | M10: 12 | N10: 0.70833333 | O10: 0.71944444 | P10: 16 | T10: Lugazi | U10: Jinja Java House | V10: =T10&"-"&U10 -> Lugazi-Jinja Java House | W10: Tarmac-good | X10: =G25 -> 37 | Y10: =AVERAGE(J25:J27) -> 39 | Z10: =AVERAGE(M25:M27) -> 39.333333 | AA10: =AVERAGE(P25:P27) -> 46 | AB10: =AVERAGE(J28:J30) -> 36 | AC10: =AVERAGE(M28:M30) -> 38 | AD10: =AVERAGE(P28:P30) -> 41 | AE10: =Y10/$X10 -> 1.0540541 | AF10: =Z10/$X10 -> 1.0630631 | AG10: =AA10/$X10 -> 1.2432432 | AH10: =AB10/$X10 -> 0.97297297 | AI10: =AC10/$X10 -> 1.027027 | AJ10: =AD10/$X10 -> 1.1081081 | AK10: =MAX(AE10:AG10) -> 1.2432432 | AL10: =MAX(AH10:AJ10) -> 1.1081081
D11: 2 | E11: Bweyogerere | F11: Spear Junction | G11: 5.6 | H11: 0.32291667 | I11: 0.33541667 | J11: 18 | K11: 0.61875 | L11: 0.62847222 | M11: 14 | N11: 0.75 | O11: 0.76041667 | P11: 15 | T11: Spear Junction | U11: Jinja Java House | V11: =T11&"-"&U11 -> Spear Junction-Jinja Java House | W11: Tarmac-good | X11: =SUM(X7:X10) -> 77.6 | Y11: =SUM(Y7:Y10) -> 113.66667 | Z11: =SUM(Z7:Z10) -> 116 | AA11: =SUM(AA7:AA10) -> 140.66667 | AB11: =SUM(AB7:AB10) -> 128 | AC11: =SUM(AC7:AC10) -> 123 | AD11: =SUM(AD7:AD10) -> 137 | AE11: =Y11/$X11 -> 1.4647766 | AF11: =Z11/$X11 -> 1.4948454 | AG11: =AA11/$X11 -> 1.8127148 | AH11: =AB11/$X11 -> 1.6494845 | AI11: =AC11/$X11 -> 1.5850515 | AJ11: =AD11/$X11 -> 1.7654639 | AK11: =MAX(AE11:AG11) -> 1.8127148 | AL11: =MAX(AH11:AJ11) -> 1.7654639
D12: 3 | E12: Bweyogerere | F12: Spear Junction | G12: 5.6 | H12: 0.32361111 | I12: 0.33611111 | J12: 18 | K12: 0.44097222 | L12: 0.45069444 | M12: 14 | N12: 0.68055556 | O12: 0.69097222 | P12: 15 | R12: JT2 | S12: Jinja - Tororo - Mbale | T12: Jinja Java House | U12: Iganga | V12: =T12&"-"&U12 -> Jinja Java House-Iganga | W12: Tarmac-good | X12: =G31 -> 40 | Y12: =AVERAGE(J31:J33) -> 45 | Z12: =AVERAGE(M31:M33) -> 47.333333 | AA12: =AVERAGE(P31:P33) -> 48.333333 | AB12: =AVERAGE(J34:J36) -> 45 | AC12: =AVERAGE(M34:M36) -> 48.333333 | AD12: =AVERAGE(P34:P36) -> 48.333333 | AE12: =Y12/$X12 -> 1.125 | AF12: =Z12/$X12 -> 1.1833333 | AG12: =AA12/$X12 -> 1.2083333 | AH12: =AB12/$X12 -> 1.125 | AI12: =AC12/$X12 -> 1.2083333 | AJ12: =AD12/$X12 -> 1.2083333 | AK12: =MAX(AE12:AG12) -> 1.2083333 | AL12: =MAX(AH12:AJ12) -> 1.2083333
D13: 1 | E13: Bweyogerere | F13: Mukono | G13: 11 | H13: 0.32430556 | I13: 0.34166667 | J13: 25 | K13: 0.47638889 | L13: 0.49583333 | M13: 28 | N13: 0.70972222 | O13: 0.73402778 | P13: 35 | T13: Iganga | U13: Bugiri | V13: =T13&"-"&U13 -> Iganga-Bugiri | W13: Tarmac-good | X13: =G37 -> 34 | Y13: =AVERAGE(J37:J39) -> 41 | Z13: =AVERAGE(M37:M39) -> 41.666667 | AA13: =AVERAGE(P37:P39) -> 42 | AB13: =AVERAGE(J40:J42) -> 42 | AC13: =AVERAGE(M40:M42) -> 41 | AD13: =AVERAGE(P40:P42) -> 41 | AE13: =Y13/$X13 -> 1.2058824 | AF13: =Z13/$X13 -> 1.2254902 | AG13: =AA13/$X13 -> 1.2352941 | AH13: =AB13/$X13 -> 1.2352941 | AI13: =AC13/$X13 -> 1.2058824 | AJ13: =AD13/$X13 -> 1.2058824 | AK13: =MAX(AE13:AG13) -> 1.2352941 | AL13: =MAX(AH13:AJ13) -> 1.2352941
D14: 2 | E14: Bweyogerere | F14: Mukono | G14: 11 | H14: 0.35625 | I14: 0.37291667 | J14: 24 | K14: 0.61944444 | L14: 0.64027778 | M14: 30 | N14: 0.75416667 | O14: 0.78194444 | P14: 40 | T14: Bugiri | U14: Busia | V14: =T14&"-"&U14 -> Bugiri-Busia | W14: Tarmac-good | X14: =G43 -> 45 | Y14: =AVERAGE(J43:J45) -> 47 | Z14: =AVERAGE(M43:M45) -> 46.666667 | AA14: =AVERAGE(P43:P45) -> 47 | AB14: =AVERAGE(J46:J48) -> 47 | AC14: =AVERAGE(M46:M48) -> 46.666667 | AD14: =AVERAGE(P46:P48) -> 47 | AE14: =Y14/$X14 -> 1.0444444 | AF14: =Z14/$X14 -> 1.037037 | AG14: =AA14/$X14 -> 1.0444444 | AH14: =AB14/$X14 -> 1.0444444 | AI14: =AC14/$X14 -> 1.037037 | AJ14: =AD14/$X14 -> 1.0444444 | AK14: =MAX(AE14:AG14) -> 1.0444444 | AL14: =MAX(AH14:AJ14) -> 1.0444444
D15: 3 | E15: Bweyogerere | F15: Mukono | G15: 11 | H15: 0.30555556 | I15: 0.32986111 | J15: 25 | K15: 0.44166667 | L15: 0.46111111 | M15: 28 | N15: 0.68125 | O15: 0.70694444 | P15: 38 | T15: Busia | U15: Tororo | V15: =T15&"-"&U15 -> Busia-Tororo | W15: Tarmac-good | X15: =G49 -> 48 | Y15: =AVERAGE(J49:J51) -> 52 | Z15: =AVERAGE(M49:M51) -> 52 | AA15: =AVERAGE(P49:P51) -> 52 | AB15: =AVERAGE(J52:J54) -> 52 | AC15: =AVERAGE(M52:M54) -> 52 | AD15: =AVERAGE(P52:P54) -> 52 | AE15: =Y15/$X15 -> 1.0833333 | AF15: =Z15/$X15 -> 1.0833333 | AG15: =AA15/$X15 -> 1.0833333 | AH15: =AB15/$X15 -> 1.0833333 | AI15: =AC15/$X15 -> 1.0833333 | AJ15: =AD15/$X15 -> 1.0833333 | AK15: =MAX(AE15:AG15) -> 1.0833333 | AL15: =MAX(AH15:AJ15) -> 1.0833333
D16: 1 | E16: Mukono | F16: Bweyogerere | G16: 11 | H16: 0.32430556 | I16: 0.34930556 | J16: 36 | K16: 0.47569444 | L16: 0.49791667 | M16: 32 | N16: 0.71041667 | O16: 0.7375 | P16: 39 | T16: Tororo | U16: Mbale | V16: =T16&"-"&U16 -> Tororo-Mbale | W16: Tarmac-good | X16: =G55 -> 51 | Y16: =AVERAGE(J55:J57) -> 61 | Z16: =AVERAGE(M55:M57) -> 61 | AA16: =AVERAGE(P55:P57) -> 61 | AB16: =AVERAGE(J58:J60) -> 60 | AC16: =AVERAGE(M58:M60) -> 61 | AD16: =AVERAGE(P58:P60) -> 61 | AE16: =Y16/$X16 -> 1.1960784 | AF16: =Z16/$X16 -> 1.1960784 | AG16: =AA16/$X16 -> 1.1960784 | AH16: =AB16/$X16 -> 1.1764706 | AI16: =AC16/$X16 -> 1.1960784 | AJ16: =AD16/$X16 -> 1.1960784 | AK16: =MAX(AE16:AG16) -> 1.1960784 | AL16: =MAX(AH16:AJ16) -> 1.1960784
D17: 2 | E17: Mukono | F17: Bweyogerere | G17: 11 | H17: 0.31875 | I17: 0.34791667 | J17: 42 | K17: 0.61944444 | L17: 0.64513889 | M17: 37 | N17: 0.75555556 | O17: 0.78541667 | P17: 43 | T17: Jinja Java House | U17: Mbale | V17: =T17&"-"&U17 -> Jinja Java House-Mbale | W17: Tarmac-good | X17: =SUM(X12:X16) -> 218 | Y17: =SUM(Y12:Y16) -> 246 | Z17: =SUM(Z12:Z16) -> 248.66667 | AA17: =SUM(AA12:AA16) -> 250.33333 | AB17: =SUM(AB12:AB16) -> 246 | AC17: =SUM(AC12:AC16) -> 249 | AD17: =SUM(AD12:AD16) -> 249.33333 | AE17: =Y17/$X17 -> 1.1284404 | AF17: =Z17/$X17 -> 1.1406728 | AG17: =AA17/$X17 -> 1.148318 | AH17: =AB17/$X17 -> 1.1284404 | AI17: =AC17/$X17 -> 1.1422018 | AJ17: =AD17/$X17 -> 1.1437309 | AK17: =MAX(AE17:AG17) -> 1.148318 | AL17: =MAX(AH17:AJ17) -> 1.1437309
D18: 3 | E18: Mukono | F18: Bweyogerere | G18: 11 | H18: 0.30625 | I18: 0.33611111 | J18: 43 | K18: 0.44166667 | L18: 0.46458333 | M18: 33 | N18: 0.68194444 | O18: 0.70972222 | P18: 40 | R18: JT3 | S18: Jinja - Kamuli - Bukungu | T18: Jinja | U18: Buwenge | V18: =T18&"-"&U18 -> Jinja-Buwenge | W18: Tarmac-good | X18: =G61 -> 28 | Y18: =AVERAGE(J61:J63) -> 33.666667 | Z18: =AVERAGE(M61:M63) -> 34 | AA18: =AVERAGE(P61:P63) -> 33 | AB18: =AVERAGE(J64:J66) -> 36 | AC18: =AVERAGE(M64:M66) -> 35 | AD18: =AVERAGE(P64:P66) -> 34 | AE18: =Y18/$X18 -> 1.202381 | AF18: =Z18/$X18 -> 1.2142857 | AG18: =AA18/$X18 -> 1.1785714 | AH18: =AB18/$X18 -> 1.2857143 | AI18: =AC18/$X18 -> 1.25 | AJ18: =AD18/$X18 -> 1.2142857 | AK18: =MAX(AE18:AG18) -> 1.2142857 | AL18: =MAX(AH18:AJ18) -> 1.2857143
D19: 1 | E19: Mukono | F19: Lugazi | G19: 24 | H19: 0.325 | I19: 0.34791667 | J19: 33 | K19: 0.61944444 | L19: 0.64375 | M19: 35 | N19: 0.79166667 | O19: 0.81666667 | P19: 36 | T19: Buwenge | U19: Kamuli | V19: =T19&"-"&U19 -> Buwenge-Kamuli | W19: Tarmac-good | X19: =G67 -> 36 | Y19: =AVERAGE(J67:J69) -> 36.666667 | Z19: =AVERAGE(M67:M69) -> 37 | AA19: =AVERAGE(P70:P72) -> 37 | AB19: =AVERAGE(J67:J69) -> 36.666667 | AC19: =AVERAGE(M67:M69) -> 37 | AD19: =AVERAGE(P67:P69) -> 38 | AE19: =Y19/$X19 -> 1.0185185 | AF19: =Z19/$X19 -> 1.0277778 | AG19: =AA19/$X19 -> 1.0277778 | AH19: =AB19/$X19 -> 1.0185185 | AI19: =AC19/$X19 -> 1.0277778 | AJ19: =AD19/$X19 -> 1.0555556 | AK19: =MAX(AE19:AG19) -> 1.0277778 | AL19: =MAX(AH19:AJ19) -> 1.0555556
D20: 2 | E20: Mukono | F20: Lugazi | G20: 24 | H20: 0.35763889 | I20: 0.38055556 | J20: 33 | K20: 0.44236111 | L20: 0.46597222 | M20: 34 | N20: 0.79513889 | O20: 0.82013889 | P20: 36 | T20: Kamuli | U20: Bukungu | V20: =T20&"-"&U20 -> Kamuli-Bukungu | W20: Gravel | X20: =G73 -> 68 | Y20: =AVERAGE(J73:J75) -> 82.666667 | Z20: =AVERAGE(M73:M75) -> 83 | AA20: =AVERAGE(P73:P75) -> 83 | AB20: =AVERAGE(J76:J78) -> 82.333333 | AC20: =AVERAGE(M76:M78) -> 82.666667 | AD20: =AVERAGE(P76:P78) -> 83 | AE20: =Y20/$X20 -> 1.2156863 | AF20: =Z20/$X20 -> 1.2205882 | AG20: =AA20/$X20 -> 1.2205882 | AH20: =AB20/$X20 -> 1.2107843 | AI20: =AC20/$X20 -> 1.2156863 | AJ20: =AD20/$X20 -> 1.2205882 | AK20: =MAX(AE20:AG20) -> 1.2205882 | AL20: =MAX(AH20:AJ20) -> 1.2205882
D21: 3 | E21: Mukono | F21: Lugazi | G21: 24 | H21: 0.38541667 | I21: 0.40902778 | J21: 34 | K21: 0.5 | L21: 0.52361111 | M21: 34 | N21: 0.75 | O21: 0.775 | P21: 36 | T21: Jinja | U21: Bukungu | V21: =T21&"-"&U21 -> Jinja-Bukungu | W21: Tarmac/Gravel | X21: =SUM(X18:X20) -> 132 | Y21: =SUM(Y18:Y20) -> 153 | Z21: =SUM(Z18:Z20) -> 154 | AA21: =SUM(AA18:AA20) -> 153 | AB21: =SUM(AB18:AB20) -> 155 | AC21: =SUM(AC18:AC20) -> 154.66667 | AD21: =SUM(AD18:AD20) -> 155 | AE21: =Y21/$X21 -> 1.1590909 | AF21: =Z21/$X21 -> 1.1666667 | AG21: =AA21/$X21 -> 1.1590909 | AH21: =AB21/$X21 -> 1.1742424 | AI21: =AC21/$X21 -> 1.1717172 | AJ21: =AD21/$X21 -> 1.1742424 | AK21: =MAX(AE21:AG21) -> 1.1666667 | AL21: =MAX(AH21:AJ21) -> 1.1742424
D22: 1 | E22: Lugazi | F22: Mukono | G22: 24 | H22: 0.32569444 | I22: 0.35 | J22: 35 | K22: 0.61944444 | L22: 0.64583333 | M22: 38 | N22: 0.75694444 | O22: 0.78472222 | P22: 40 | V22: =T22&"-"&U22 -> - | X22: =SUM(X18:X21) -> 264
D23: 2 | E23: Lugazi | F23: Mukono | G23: 24 | H23: 0.31944444 | I23: 0.34305556 | J23: 34 | K23: 0.44305556 | L23: 0.46875 | M23: 37 | N23: 0.79166667 | O23: 0.81944444 | P23: 40
D24: 3 | E24: Lugazi | F24: Mukono | G24: 24 | H24: 0.36111111 | I24: 0.34375 | J24: 35 | K24: 0.50138889 | L24: 0.52777778 | M24: 38 | N24: 0.70833333 | O24: 0.73611111 | P24: 40
D25: 1 | E25: Lugazi | F25: Jinja Java House | G25: 37 | H25: 0.32638889 | I25: 0.35347222 | J25: 39 | K25: 0.62291667 | L25: 0.65208333 | M25: 42 | N25: 0.6875 | O25: 0.71944444 | P25: 46 | R25: JT18 | S25: Northern Bypass - Entebbe (Old) | T25: Busega | U25: Kibuye | V25: =T25&"-"&U25 -> Busega-Kibuye | W25: Tarmac-good | X25: =G319 -> 7.2 | Y25: =AVERAGE(J319:J321) -> 23 | Z25: =AVERAGE(M319:M321) -> 29 | AA25: =AVERAGE(P319:P321) -> 25 | AB25: =AVERAGE(J322:J324) -> 19.333333 | AC25: =AVERAGE(M322:M324) -> 18.666667 | AD25: =AVERAGE(P322:P324) -> 29 | AE25: =Y25/$X25 -> 3.1944444 | AF25: =Z25/$X25 -> 4.0277778 | AG25: =AA25/$X25 -> 3.4722222 | AH25: =AB25/$X25 -> 2.6851852 | AI25: =AC25/$X25 -> 2.5925926 | AJ25: =AD25/$X25 -> 4.0277778
D26: 2 | E26: Lugazi | F26: Jinja Java House | G26: 37 | H26: 0.32013889 | I26: 0.34722222 | J26: 39 | K26: 0.44305556 | L26: 0.46944444 | M26: 38 | N26: 0.68055556 | O26: 0.7125 | P26: 46 | T26: Kibuye | U26: Zzana | V26: =T26&"-"&U26 -> Kibuye-Zzana | W26: Tarmac-good | X26: =G325 -> 5.1 | Y26: =AVERAGE(J325:J327) -> 10.333333 | Z26: =AVERAGE(M325:M327) -> 10.666667 | AA26: =AVERAGE(P325:P327) -> 13 | AB26: =AVERAGE(J328:J330) -> 25.333333 | AC26: =AVERAGE(M328:M330) -> 15.666667 | AD26: =AVERAGE(P328:P330) -> 12 | AE26: =Y26/$X26 -> 2.0261438 | AF26: =Z26/$X26 -> 2.0915033 | AG26: =AA26/$X26 -> 2.5490196 | AH26: =AB26/$X26 -> 4.9673203 | AI26: =AC26/$X26 -> 3.0718954 | AJ26: =AD26/$X26 -> 2.3529412
D27: 3 | E27: Lugazi | F27: Jinja Java House | G27: 37 | H27: 0.38611111 | I27: 0.41319444 | J27: 39 | K27: 0.50208333 | L27: 0.52847222 | M27: 38 | N27: 0.66666667 | O27: 0.69861111 | P27: 46 | T27: Zzana | U27: Kajjansi | V27: =T27&"-"&U27 -> Zzana-Kajjansi | W27: Tarmac-good | X27: =G331 -> 5.8 | Y27: =AVERAGE(J331:J333) -> 11.666667 | Z27: =AVERAGE(M331:M333) -> 12 | AA27: =AVERAGE(P331:P333) -> 11 | AB27: =AVERAGE(J334:J336) -> 13.666667 | AC27: =AVERAGE(M334:M336) -> 12 | AD27: =AVERAGE(P334:P336) -> 12 | AE27: =Y27/$X27 -> 2.0114943 | AF27: =Z27/$X27 -> 2.0689655 | AG27: =AA27/$X27 -> 1.8965517 | AH27: =AB27/$X27 -> 2.3563218 | AI27: =AC27/$X27 -> 2.0689655 | AJ27: =AD27/$X27 -> 2.0689655
D28: 1 | E28: Jinja Java House | F28: Lugazi | G28: 37 | H28: 0.32638889 | I28: 0.35138889 | J28: 36 | K28: 0.62291667 | L28: 0.65138889 | M28: 38 | N28: 0.71527778 | O28: 0.74375 | P28: 41 | T28: Kajjansi | U28: Mpala | V28: =T28&"-"&U28 -> Kajjansi-Mpala | W28: Tarmac-good | X28: =G337 -> 14 | Y28: =AVERAGE(J337:J339) -> 21.666667 | Z28: =AVERAGE(M337:M339) -> 20.333333 | AA28: =AVERAGE(P337:P339) -> 23 | AB28: =AVERAGE(J340:J342) -> 22 | AC28: =AVERAGE(M340:M342) -> 25 | AD28: =AVERAGE(P340:P342) -> 28 | AE28: =Y28/$X28 -> 1.547619 | AF28: =Z28/$X28 -> 1.452381 | AG28: =AA28/$X28 -> 1.6428571 | AH28: =AB28/$X28 -> 1.5714286 | AI28: =AC28/$X28 -> 1.7857143 | AJ28: =AD28/$X28 -> 2
D29: 2 | E29: Jinja Java House | F29: Lugazi | G29: 37 | H29: 0.32013889 | I29: 0.34513889 | J29: 36 | K29: 0.44375 | L29: 0.47013889 | M29: 38 | N29: 0.6875 | O29: 0.71597222 | P29: 41 | T29: Mpala | U29: Entebbe Kitooro | V29: =T29&"-"&U29 -> Mpala-Entebbe Kitooro | W29: Tarmac-good | X29: =G343 -> 7.9 | Y29: =AVERAGE(J343:J345) -> 13.666667 | Z29: =AVERAGE(M343:M345) -> 10 | AA29: =AVERAGE(P343:P345) -> 13 | AB29: =AVERAGE(J346:J348) -> 15 | AC29: =AVERAGE(M346:M348) -> 13 | AD29: =AVERAGE(P346:P348) -> 17 | AE29: =Y29/$X29 -> 1.7299578 | AF29: =Z29/$X29 -> 1.2658228 | AG29: =AA29/$X29 -> 1.6455696 | AH29: =AB29/$X29 -> 1.8987342 | AI29: =AC29/$X29 -> 1.6455696 | AJ29: =AD29/$X29 -> 2.1518987
D30: 3 | E30: Jinja Java House | F30: Lugazi | G30: 37 | H30: 0.38680556 | I30: 0.41180556 | J30: 36 | K30: 0.50208333 | L30: 0.52847222 | M30: 38 | N30: 0.7 | O30: 0.72430556 | P30: 41 | T30: Busega | U30: Entebbe Kitooro | V30: =T30&"-"&U30 -> Busega-Entebbe Kitooro | W30: Tarmac-good | X30: =SUM(X25:X29) -> 40 | Y30: =SUM(Y25:Y29) -> 80.333333 | Z30: =SUM(Z25:Z29) -> 82 | AA30: =SUM(AA25:AA29) -> 85 | AB30: =SUM(AB25:AB29) -> 95.333333 | AC30: =SUM(AC25:AC29) -> 84.333333 | AD30: =SUM(AD25:AD29) -> 98 | AE30: =Y30/$X30 -> 2.0083333 | AF30: =Z30/$X30 -> 2.05 | AG30: =AA30/$X30 -> 2.125 | AH30: =AB30/$X30 -> 2.3833333 | AI30: =AC30/$X30 -> 2.1083333 | AJ30: =AD30/$X30 -> 2.45
B31: JT2 | C31: Jinja - Tororo - Mbale | D31: 1 | E31: Jinja Java House | F31: Iganga | G31: 40 | H31: 0.32708333 | I31: 0.35833333 | J31: 45 | K31: 0.625 | L31: 0.65833333 | M31: 48 | N31: 0.76388889 | O31: 0.79861111 | P31: 50 | R31: JT19 | S31: Northern Bypass - Entebbe (KEE) | T31: Busega | U31: Kajjansi | V31: =T31&"-"&U31 -> Busega-Kajjansi | W31: Tarmac-good | X31: =G350 -> 12 | Y31: =AVERAGE(J350:J352) -> 12.666667 | Z31: =AVERAGE(M350:M352) -> 15 | AA31: =AVERAGE(P350:P352) -> 11 | AB31: =AVERAGE(J352:J354) -> 12.666667 | AC31: =AVERAGE(M352:M354) -> 15 | AD31: =AVERAGE(P352:P354) -> 11 | AE31: =Y31/$X31 -> 1.0555556 | AF31: =Z31/$X31 -> 1.25 | AG31: =AA31/$X31 -> 0.91666667 | AH31: =AB31/$X31 -> 1.0555556 | AI31: =AC31/$X31 -> 1.25 | AJ31: =AD31/$X31 -> 0.91666667
D32: 2 | E32: Jinja Java House | F32: Iganga | G32: 40 | H32: 0.32152778 | I32: 0.35277778 | J32: 45 | K32: 0.44375 | L32: 0.47638889 | M32: 47 | N32: 0.70972222 | O32: 0.74305556 | P32: 48 | T32: Kajjansi | U32: Mpala | V32: =T32&"-"&U32 -> Kajjansi-Mpala | W32: Tarmac-good | X32: =G356 -> 15 | Y32: =AVERAGE(J356:J358) -> 19 | Z32: =AVERAGE(M356:M358) -> 13 | AA32: =AVERAGE(P356:P358) -> 12.333333 | AB32: =AVERAGE(J358:J360) -> 12.666667 | AC32: =AVERAGE(M358:M360) -> 13 | AD32: =AVERAGE(P358:P360) -> 15 | AE32: =Y32/$X32 -> 1.2666667 | AF32: =Z32/$X32 -> 0.86666667 | AG32: =AA32/$X32 -> 0.82222222 | AH32: =AB32/$X32 -> 0.84444444 | AI32: =AC32/$X32 -> 0.86666667 | AJ32: =AD32/$X32 -> 1
D33: 3 | E33: Jinja Java House | F33: Iganga | G33: 40 | H33: 0.3875 | I33: 0.41875 | J33: 45 | K33: 0.50277778 | L33: 0.53541667 | M33: 47 | N33: 0.80555556 | O33: 0.83819444 | P33: 47 | T33: Mpala | U33: Entebbe Kitooro | V33: =T33&"-"&U33 -> Mpala-Entebbe Kitooro | W33: Tarmac-good | X33: =G362 -> 7.9 | Y33: =AVERAGE(J362:J364) -> 12 | Z33: =AVERAGE(M362:M364) -> 11 | AA33: =AVERAGE(P362:P364) -> 9.3333333 | AB33: =AVERAGE(J364:J366) -> 15 | AC33: =AVERAGE(M364:M366) -> 13 | AD33: =AVERAGE(P364:P366) -> 10 | AE33: =Y33/$X33 -> 1.5189873 | AF33: =Z33/$X33 -> 1.3924051 | AG33: =AA33/$X33 -> 1.1814346 | AH33: =AB33/$X33 -> 1.8987342 | AI33: =AC33/$X33 -> 1.6455696 | AJ33: =AD33/$X33 -> 1.2658228
D34: 1 | E34: Iganga | F34: Jinja Java House | G34: 40 | H34: 0.32708333 | I34: 0.35833333 | J34: 45 | K34: 0.625 | L34: 0.65763889 | M34: 47 | N34: 0.76458333 | O34: 0.79722222 | P34: 47 | T34: Busega | U34: Entebbe Kitooro | V34: =T34&"-"&U34 -> Busega-Entebbe Kitooro | W34: Tarmac-good | X34: =SUM(X31:X33) -> 34.9 | Y34: =SUM(Y31:Y33) -> 43.666667 | Z34: =SUM(Z31:Z33) -> 39 | AA34: =SUM(AA31:AA33) -> 32.666667 | AB34: =SUM(AB31:AB33) -> 40.333333 | AC34: =SUM(AC31:AC33) -> 41 | AD34: =SUM(AD31:AD33) -> 36 | AE34: =Y34/$X34 -> 1.2511939 | AF34: =Z34/$X34 -> 1.1174785 | AG34: =AA34/$X34 -> 0.93600764 | AH34: =AB34/$X34 -> 1.1556829 | AI34: =AC34/$X34 -> 1.1747851 | AJ34: =AD34/$X34 -> 1.0315186
D35: 2 | E35: Iganga | F35: Jinja Java House | G35: 40 | H35: 0.32152778 | I35: 0.35277778 | J35: 45 | K35: 0.44375 | L35: 0.47777778 | M35: 49 | N35: 0.71180556 | O35: 0.74583333 | P35: 49 | R35: JT20 | S35: NBP - Luwero - Nakasongola - Kigumba - Karuma | T35: NBP | U35: Kawempe | V35: =T35&"-"&U35 -> NBP-Kawempe | W35: Tarmac-good | X35: =G368 -> 3.4 | Y35: =AVERAGE(J368:J370) -> 13.333333 | Z35: =AVERAGE(M368:M370) -> 13.333333 | AA35: =AVERAGE(P368:P370) -> 15.333333 | AB35: =AVERAGE(J370:J372) -> 15 | AC35: =AVERAGE(M370:M372) -> 15.333333 | AD35: =AVERAGE(P370:P372) -> 15.666667 | AE35: =Y35/$X35 -> 3.9215686 | AF35: =Z35/$X35 -> 3.9215686 | AG35: =AA35/$X35 -> 4.5098039 | AH35: =AB35/$X35 -> 4.4117647 | AI35: =AC35/$X35 -> 4.5098039 | AJ35: =AD35/$X35 -> 4.6078431
D36: 3 | E36: Iganga | F36: Jinja Java House | G36: 40 | H36: 0.38888889 | I36: 0.42013889 | J36: 45 | K36: 0.50277778 | L36: 0.53680556 | M36: 49 | N36: 0.80625 | O36: 0.84027778 | P36: 49 | T36: Kawempe | U36: Matugga | V36: =T36&"-"&U36 -> Kawempe-Matugga | W36: Tarmac-good | X36: =G374 -> 10 | Y36: =AVERAGE(J374:J376) -> 20 | Z36: =AVERAGE(M374:M376) -> 20.333333 | AA36: =AVERAGE(P374:P376) -> 21.666667 | AB36: =AVERAGE(J376:J378) -> 21.333333 | AC36: =AVERAGE(M376:M378) -> 23.333333 | AD36: =AVERAGE(P376:P378) -> 25 | AE36: =Y36/$X36 -> 2 | AF36: =Z36/$X36 -> 2.0333333 | AG36: =AA36/$X36 -> 2.1666667 | AH36: =AB36/$X36 -> 2.1333333 | AI36: =AC36/$X36 -> 2.3333333 | AJ36: =AD36/$X36 -> 2.5
D37: 1 | E37: Iganga | F37: Bugiri | G37: 34 | H37: 0.32777778 | I37: 0.35625 | J37: 41 | K37: 0.62569444 | L37: 0.65416667 | M37: 41 | N37: 0.76597222 | O37: 0.79513889 | P37: 42 | T37: Matugga | U37: Luweero | V37: =T37&"-"&U37 -> Matugga-Luweero | W37: Tarmac-good | X37: =G380 -> 45 | Y37: =AVERAGE(J380:J382) -> 50 | Z37: =AVERAGE(M380:M382) -> 50.666667 | AA37: =AVERAGE(P380:P382) -> 50.666667 | AB37: =AVERAGE(J382:J384) -> 52 | AC37: =AVERAGE(M382:M384) -> 52 | AD37: =AVERAGE(P382:P384) -> 52 | AE37: =Y37/$X37 -> 1.1111111 | AF37: =Z37/$X37 -> 1.1259259 | AG37: =AA37/$X37 -> 1.1259259 | AH37: =AB37/$X37 -> 1.1555556 | AI37: =AC37/$X37 -> 1.1555556 | AJ37: =AD37/$X37 -> 1.1555556
D38: 2 | E38: Iganga | F38: Bugiri | G38: 34 | H38: 0.32222222 | I38: 0.35069444 | J38: 41 | K38: 0.44444444 | L38: 0.47361111 | M38: 42 | N38: 0.7125 | O38: 0.74166667 | P38: 42 | T38: Luweero | U38: Nakasongola | V38: =T38&"-"&U38 -> Luweero-Nakasongola | X38: =G386 -> 47 | Y38: =AVERAGE(J386:J388) -> 36 | Z38: =AVERAGE(M386:M388) -> 36 | AA38: =AVERAGE(P386:P388) -> 36 | AB38: =AVERAGE(J388:J390) -> 36 | AC38: =AVERAGE(M388:M390) -> 36 | AD38: =AVERAGE(P388:P390) -> 36 | AE38: =Y38/$X38 -> 0.76595745 | AF38: =Z38/$X38 -> 0.76595745 | AG38: =AA38/$X38 -> 0.76595745 | AH38: =AB38/$X38 -> 0.76595745 | AI38: =AC38/$X38 -> 0.76595745 | AJ38: =AD38/$X38 -> 0.76595745
D39: 3 | E39: Iganga | F39: Bugiri | G39: 34 | H39: 0.38958333 | I39: 0.41805556 | J39: 41 | K39: 0.50347222 | L39: 0.53263889 | M39: 42 | N39: 0.80763889 | O39: 0.83680556 | P39: 42 | T39: Nakasongola | U39: Kigumba | V39: =T39&"-"&U39 -> Nakasongola-Kigumba | X39: =G392 -> 93 | Y39: =AVERAGE(J392:J394) -> 62.666667 | Z39: =AVERAGE(M392:M394) -> 62.666667 | AA39: =AVERAGE(P392:P394) -> 63 | AB39: =AVERAGE(J394:J396) -> 64 | AC39: =AVERAGE(M394:M396) -> 64 | AD39: =AVERAGE(P394:P396) -> 64.333333 | AE39: =Y39/$X39 -> 0.67383513 | AF39: =Z39/$X39 -> 0.67383513 | AG39: =AA39/$X39 -> 0.67741935 | AH39: =AB39/$X39 -> 0.68817204 | AI39: =AC39/$X39 -> 0.68817204 | AJ39: =AD39/$X39 -> 0.69175627
D40: 1 | E40: Bugiri | F40: Iganga | G40: 34 | H40: 0.32777778 | I40: 0.35694444 | J40: 42 | K40: 0.62638889 | L40: 0.65486111 | M40: 41 | N40: 0.76666667 | O40: 0.79513889 | P40: 41 | T40: Kigumba | U40: Karuma | V40: =T40&"-"&U40 -> Kigumba-Karuma | X40: =G398 -> 59 | Y40: =AVERAGE(J398:J400) -> 48.666667 | Z40: =AVERAGE(M398:M400) -> 48.333333 | AA40: =AVERAGE(P398:P400) -> 48.666667 | AB40: =AVERAGE(J400:J402) -> 50 | AC40: =AVERAGE(M400:M402) -> 50.333333 | AD40: =AVERAGE(P400:P402) -> 50 | AE40: =Y40/$X40 -> 0.82485876 | AF40: =Z40/$X40 -> 0.81920904 | AG40: =AA40/$X40 -> 0.82485876 | AH40: =AB40/$X40 -> 0.84745763 | AI40: =AC40/$X40 -> 0.85310734 | AJ40: =AD40/$X40 -> 0.84745763
D41: 2 | E41: Bugiri | F41: Iganga | G41: 34 | H41: 0.32222222 | I41: 0.35138889 | J41: 42 | K41: 0.44444444 | L41: 0.47291667 | M41: 41 | N41: 0.7125 | O41: 0.74097222 | P41: 41 | T41: NBP | U41: Karuma | V41: =T41&"-"&U41 -> NBP-Karuma | X41: =SUM(X35:X40) -> 257.4 | Y41: =SUM(Y35:Y40) -> 230.66667 | Z41: =SUM(Z35:Z40) -> 231.33333 | AA41: =SUM(AA35:AA40) -> 235.33333 | AB41: =SUM(AB35:AB40) -> 238.33333 | AC41: =SUM(AC35:AC40) -> 241 | AD41: =SUM(AD35:AD40) -> 243 | AE41: =Y41/$X41 -> 0.8961409 | AF41: =Z41/$X41 -> 0.8987309 | AG41: =AA41/$X41 -> 0.91427091 | AH41: =AB41/$X41 -> 0.92592593 | AI41: =AC41/$X41 -> 0.93628594 | AJ41: =AD41/$X41 -> 0.94405594
...

Sheet JT var
B1: Distance from Kampala Central (Km) | C1: JT Per Km (Min/Km) | D1: Speed (Kph)
B2: 0 - 5 | C2: =AVERAGE('JT data'!AJ7,'JT data'!AJ25,'JT data'!AJ35) -> 3.7912387 | D2: =60/C2 -> 15.825962
B3: 6 - 20 | C3: =AVERAGE('JT data'!AJ8,'JT data'!AJ26,'JT data'!AJ36,'JT data'!AJ49,'JT data'!AJ54,'JT data'!AJ84:AJ85) -> 2.6009677 | D3: =60/C3 -> 23.068338
B4: 21 - 40 | C4: =AVERAGE('JT data'!AJ9,'JT data'!AJ28,'JT data'!AJ37,'JT data'!AJ50,'JT data'!AJ55) -> 1.375741 | D4: =60/C4 -> 43.612861
B5: 41 - 100 | C5: =AVERAGE('JT data'!AJ10,'JT data'!AJ38,'JT data'!AJ51,'JT data'!AJ56,'JT data'!AJ87) -> 0.9796431 | D5: =60/C5 -> 61.246795
B6: Over 100Km | C6: =AVERAGE('JT data'!AJ40,'JT data'!AJ52,'JT data'!AJ58,'JT data'!AJ87) -> 0.97783 | D6: =60/C6 -> 61.360359

Sheet Timing pts
A2: TIMING POINTS
A3: Ref | B3: Route | C3: From | D3: To
A4: JT1 | B4: Kampala - Jinja | C4: Spear Junction | D4: Bweyogerere
C5: Bweyogerere | D5: Mukono
C6: Mukono | D6: Lugazi
C7: Lugazi | D7: Jinja Java House
A8: JT2 | B8: Jinja-Tororo-Mbale

Sheet Sheet1
