Workbook

Sheet 29.10-MUKONO-KATOSI
B1: Consultancy services for Preparation of Expressway Development Master Plan (EDMP) for Uganda
B2: MANUAL CLASSIFIED COUNT (MCC)
B3: ROAD NAME: | C3: MCC - C2 - STN077 - KATOSI ROAD
C5: Date | D5: 29.10.2019 | F5: Location | G5: LUV GUEST HOUSE | J5: Surveyor | K5: KIRABO DAN
C6: Dir. From | D6: MUKONO | F6: Dir. To | G6: KATOSI | J6: Supervisor | K6: VICTOR M
B8: Time / Veh Type | R8: SUMMARY TRAFFIC VOLUMES
C9: 1. Car | D9: 2. Station Wagon | E9: 3. Pickups | F9: 4. Minibus, matatu | G9: 5. Medium bus | H9: 6. Large Bus | I9: 7. Light Truck | J9: 8. Medium Truck | K9: 9. Heavy truck | L9: 10. Truck Trailer | M9: 11. Motor cycles | N9: 12. Tractors | O9: Total Excl M/Cycles | P9: Total All | R9: Time | S9: 1. Car | T9: 2. Station Wagon | U9: 3. Pickups | V9: 4. Minibus, matatu | W9: 5. Medium bus | X9: 6. Large Bus | Y9: 7. Light Truck | Z9: 8. Medium Truck | AA9: 9. Heavy truck | AB9: 10. Truck Trailer | AC9: 11. Motorcycles | AD9: 12. Tractors, Graders | AE9: Total Excl M/ Cycles | AF9: Total All
B10: 07.00 - 07.15 | C10: 3 | D10: 2 | E10: 1 | F10: 6 | G10: 1 | H10: 0 | I10: 3 | J10: 2 | K10: 0 | L10: 1 | M10: 39 | N10: 0 | O10: =SUM(C10:L10,N10) -> 19 | P10: =SUM(C10:N10) -> 58 | R10: 0700-0800 | S10: =SUM(C10:C13) -> 41 | T10: =SUM(D10:D13) -> 18 | U10: =SUM(E10:E13) -> 10 | V10: =SUM(F10:F13) -> 25 | W10: =SUM(G10:G13) -> 3 | X10: =SUM(H10:H13) -> 0 | Y10: =SUM(I10:I13) -> 25 | Z10: =SUM(J10:J13) -> 3 | ... AF10: =SUM(P10:P13) -> 446
B11: 07.15 - 07.30 | C11: 10 | D11: 3 | E11: 1 | F11: 5 | G11: 0 | H11: 0 | I11: 4 | J11: 0 | K11: 1 | L11: 0 | M11: 85 | N11: 0 | O11: =SUM(C11:L11,N11) -> 24 | P11: =SUM(C11:N11) -> 109 | R11: 0800-0900 | S11: =SUM(C14:C17) -> 57 | T11: =SUM(D14:D17) -> 18 | U11: =SUM(E14:E17) -> 14 | V11: =SUM(F14:F17) -> 24 | W11: =SUM(G14:G17) -> 1 | X11: =SUM(H14:H17) -> 0 | Y11: =SUM(I14:I17) -> 19 | Z11: =SUM(J14:J17) -> 2 | ... AF11: =SUM(P14:P17) -> 606
B12: 07.30 - 07.45 | C12: 11 | D12: 5 | E12: 4 | F12: 8 | G12: 1 | H12: 0 | I12: 8 | J12: 0 | K12: 0 | L12: 1 | M12: 101 | N12: 0 | O12: =SUM(C12:L12,N12) -> 38 | P12: =SUM(C12:N12) -> 139 | R12: 0900-1000 | S12: =SUM(C18:C21) -> 58 | T12: =SUM(D18:D21) -> 28 | U12: =SUM(E18:E21) -> 19 | V12: =SUM(F18:F21) -> 30 | W12: =SUM(G18:G21) -> 2 | X12: =SUM(H18:H21) -> 0 | Y12: =SUM(I18:I21) -> 23 | Z12: =SUM(J18:J21) -> 6 | ... AF12: =SUM(P18:P21) -> 654
B13: 07.45 - 08.00 | C13: 17 | D13: 8 | E13: 4 | F13: 6 | G13: 1 | H13: 0 | I13: 10 | J13: 1 | K13: 0 | L13: 5 | M13: 88 | N13: 0 | O13: =SUM(C13:L13,N13) -> 52 | P13: =SUM(C13:N13) -> 140 | R13: 1000-1100 | S13: =SUM(C22:C25) -> 62 | T13: =SUM(D22:D25) -> 21 | U13: =SUM(E22:E25) -> 13 | V13: =SUM(F22:F25) -> 33 | W13: =SUM(G22:G25) -> 3 | X13: =SUM(H22:H25) -> 0 | Y13: =SUM(I22:I25) -> 32 | Z13: =SUM(J22:J25) -> 5 | ... AF13: =SUM(P22:P25) -> 627
B14: 08.00 - 08.15 | C14: 12 | D14: 4 | E14: 3 | F14: 7 | G14: 1 | H14: 0 | I14: 8 | J14: 2 | K14: 0 | L14: 1 | M14: 105 | N14: 0 | O14: =SUM(C14:L14,N14) -> 38 | P14: =SUM(C14:N14) -> 143 | R14: 1100-1200 | S14: =SUM(C26:C29) -> 53 | T14: =SUM(D26:D29) -> 28 | U14: =SUM(E26:E29) -> 23 | V14: =SUM(F26:F29) -> 35 | W14: =SUM(G26:G29) -> 2 | X14: =SUM(H26:H29) -> 0 | Y14: =SUM(I26:I29) -> 40 | Z14: =SUM(J26:J29) -> 4 | ... AF14: =SUM(P26:P29) -> 557
B15: 08.15 - 08.30 | C15: 8 | D15: 3 | E15: 5 | F15: 2 | G15: 0 | H15: 0 | I15: 3 | J15: 0 | K15: 0 | L15: 2 | M15: 127 | N15: 0 | O15: =SUM(C15:L15,N15) -> 23 | P15: =SUM(C15:N15) -> 150 | R15: 1200-1300 | S15: =SUM(C30:C33) -> 36 | T15: =SUM(D30:D33) -> 16 | U15: =SUM(E30:E33) -> 15 | V15: =SUM(F30:F33) -> 32 | W15: =SUM(G30:G33) -> 1 | X15: =SUM(H30:H33) -> 0 | Y15: =SUM(I30:I33) -> 18 | Z15: =SUM(J30:J33) -> 10 | ... AF15: =SUM(P30:P33) -> 514
B16: 08.30 - 08.45 | C16: 22 | D16: 6 | E16: 3 | F16: 8 | G16: 0 | H16: 0 | I16: 6 | J16: 0 | K16: 0 | L16: 0 | M16: 123 | N16: 0 | O16: =SUM(C16:L16,N16) -> 45 | P16: =SUM(C16:N16) -> 168 | R16: 1300-1400 | S16: =SUM(C34:C37) -> 60 | T16: =SUM(D34:D37) -> 11 | U16: =SUM(E34:E37) -> 13 | V16: =SUM(F34:F37) -> 32 | W16: =SUM(G34:G37) -> 5 | X16: =SUM(H34:H37) -> 0 | Y16: =SUM(I34:I37) -> 32 | Z16: =SUM(J34:J37) -> 2 | ... AF16: =SUM(P34:P37) -> 581
B17: 08.45 - 9.00 | C17: 15 | D17: 5 | E17: 3 | F17: 7 | G17: 0 | H17: 0 | I17: 2 | J17: 0 | K17: 0 | L17: 1 | M17: 112 | N17: 0 | O17: =SUM(C17:L17,N17) -> 33 | P17: =SUM(C17:N17) -> 145 | R17: 1400-1500 | S17: =SUM(C38:C41) -> 63 | T17: =SUM(D38:D41) -> 19 | U17: =SUM(E38:E41) -> 21 | V17: =SUM(F38:F41) -> 32 | W17: =SUM(G38:G41) -> 4 | X17: =SUM(H38:H41) -> 0 | Y17: =SUM(I38:I41) -> 38 | Z17: =SUM(J38:J41) -> 3 | ... AF17: =SUM(P38:P41) -> 543
B18: 09.00 - 09.15 | C18: 18 | D18: 1 | E18: 2 | F18: 7 | G18: 1 | H18: 0 | I18: 10 | J18: 0 | K18: 0 | L18: 1 | M18: 128 | N18: 0 | O18: =SUM(C18:L18,N18) -> 40 | P18: =SUM(C18:N18) -> 168 | R18: 1500-1600 | S18: =SUM(C42:C45) -> 51 | T18: =SUM(D42:D45) -> 17 | U18: =SUM(E42:E45) -> 11 | V18: =SUM(F42:F45) -> 29 | W18: =SUM(G42:G45) -> 3 | X18: =SUM(H42:H45) -> 0 | Y18: =SUM(I42:I45) -> 31 | Z18: =SUM(J42:J45) -> 3 | ... AF18: =SUM(P42:P45) -> 504
B19: 09.15 - 09.30 | C19: 14 | D19: 10 | E19: 7 | F19: 9 | G19: 0 | H19: 0 | I19: 5 | J19: 1 | K19: 2 | L19: 0 | M19: 124 | N19: 0 | O19: =SUM(C19:L19,N19) -> 48 | P19: =SUM(C19:N19) -> 172 | R19: 1600-1700 | S19: =SUM(C46:C49) -> 39 | T19: =SUM(D46:D49) -> 19 | U19: =SUM(E46:E49) -> 12 | V19: =SUM(F46:F49) -> 26 | W19: =SUM(G46:G49) -> 3 | X19: =SUM(H46:H49) -> 0 | Y19: =SUM(I46:I49) -> 25 | Z19: =SUM(J46:J49) -> 7 | ... AF19: =SUM(P46:P49) -> 525
B20: 09.30 - 09.45 | C20: 12 | D20: 12 | E20: 4 | F20: 7 | G20: 1 | H20: 0 | I20: 6 | J20: 3 | K20: 2 | L20: 0 | M20: 123 | N20: 0 | O20: =SUM(C20:L20,N20) -> 47 | P20: =SUM(C20:N20) -> 170 | R20: 1700-1800 | S20: =SUM(C50:C53) -> 57 | T20: =SUM(D50:D53) -> 8 | U20: =SUM(E50:E53) -> 10 | V20: =SUM(F50:F53) -> 40 | W20: =SUM(G50:G53) -> 2 | X20: =SUM(H50:H53) -> 0 | Y20: =SUM(I50:I53) -> 11 | Z20: =SUM(J50:J53) -> 13 | ... AF20: =SUM(P50:P53) -> 546
B21: 09.45 - 10.00 | C21: 14 | D21: 5 | E21: 6 | F21: 7 | G21: 0 | H21: 0 | I21: 2 | J21: 2 | K21: 1 | L21: 0 | M21: 107 | N21: 0 | O21: =SUM(C21:L21,N21) -> 37 | P21: =SUM(C21:N21) -> 144 | R21: 1800-1900 | S21: =SUM(C54:C57) -> 35 | T21: =SUM(D54:D57) -> 13 | U21: =SUM(E54:E57) -> 10 | V21: =SUM(F54:F57) -> 28 | W21: =SUM(G54:G57) -> 4 | X21: =SUM(H54:H57) -> 0 | Y21: =SUM(I54:I57) -> 17 | Z21: =SUM(J54:J57) -> 7 | ... AF21: =SUM(P54:P57) -> 612
B22: 10.00 - 10.15 | C22: 17 | D22: 4 | E22: 2 | F22: 12 | G22: 2 | H22: 0 | I22: 7 | J22: 1 | K22: 3 | L22: 0 | M22: 98 | N22: 0 | O22: =SUM(C22:L22,N22) -> 48 | P22: =SUM(C22:N22) -> 146 | R22: AM Peak Hr | S22: =MAX(S10:S12) -> 58 | T22: =MAX(T10:T12) -> 28 | U22: =MAX(U10:U12) -> 19 | V22: =MAX(V10:V12) -> 30 | W22: =MAX(W10:W12) -> 3 | X22: =MAX(X10:X12) -> 0 | Y22: =MAX(Y10:Y12) -> 25 | Z22: =MAX(Z10:Z12) -> 6 | ... AF22: =MAX(AF10:AF12) -> 654
B23: 10.15 - 10.30 | C23: 11 | D23: 5 | E23: 6 | F23: 9 | G23: 1 | H23: 0 | I23: 7 | J23: 1 | K23: 0 | L23: 2 | M23: 103 | N23: 0 | O23: =SUM(C23:L23,N23) -> 42 | P23: =SUM(C23:N23) -> 145 | R23: IP Peak Hr | S23: =MAX(S13:S18) -> 63 | T23: =MAX(T13:T18) -> 28 | U23: =MAX(U13:U18) -> 23 | V23: =MAX(V13:V18) -> 35 | W23: =MAX(W13:W18) -> 5 | X23: =MAX(X13:X18) -> 0 | Y23: =MAX(Y13:Y18) -> 40 | Z23: =MAX(Z13:Z18) -> 10 | ... AF23: =MAX(AF13:AF18) -> 627
B24: 10.30 - 10.45 | C24: 21 | D24: 5 | E24: 3 | F24: 9 | G24: 0 | H24: 0 | I24: 11 | J24: 2 | K24: 0 | L24: 1 | M24: 123 | N24: 0 | O24: =SUM(C24:L24,N24) -> 52 | P24: =SUM(C24:N24) -> 175 | R24: PM Peak Hr | S24: =MAX(S19:S21) -> 57 | T24: =MAX(T19:T21) -> 19 | U24: =MAX(U19:U21) -> 12 | V24: =MAX(V19:V21) -> 40 | W24: =MAX(W19:W21) -> 4 | X24: =MAX(X19:X21) -> 0 | Y24: =MAX(Y19:Y21) -> 25 | Z24: =MAX(Z19:Z21) -> 13 | ... AF24: =MAX(AF19:AF21) -> 612
B25: 10.45 - 11.00 | C25: 13 | D25: 7 | E25: 2 | F25: 3 | G25: 0 | H25: 0 | I25: 7 | J25: 1 | K25: 0 | L25: 1 | M25: 127 | N25: 0 | O25: =SUM(C25:L25,N25) -> 34 | P25: =SUM(C25:N25) -> 161 | R25: AM Period | S25: =SUM(S10:S12) -> 156 | T25: =SUM(T10:T12) -> 64 | U25: =SUM(U10:U12) -> 43 | V25: =SUM(V10:V12) -> 79 | W25: =SUM(W10:W12) -> 6 | X25: =SUM(X10:X12) -> 0 | Y25: =SUM(Y10:Y12) -> 67 | Z25: =SUM(Z10:Z12) -> 11 | ... AF25: =SUM(AF10:AF12) -> 1706
B26: 11.00 - 11.15 | C26: 13 | D26: 6 | E26: 5 | F26: 10 | G26: 0 | H26: 0 | I26: 6 | J26: 3 | K26: 2 | L26: 0 | M26: 100 | N26: 0 | O26: =SUM(C26:L26,N26) -> 45 | P26: =SUM(C26:N26) -> 145 | R26: IP Period | S26: =SUM(S13:S18) -> 325 | T26: =SUM(T13:T18) -> 112 | U26: =SUM(U13:U18) -> 96 | V26: =SUM(V13:V18) -> 193 | W26: =SUM(W13:W18) -> 18 | X26: =SUM(X13:X18) -> 0 | Y26: =SUM(Y13:Y18) -> 191 | Z26: =SUM(Z13:Z18) -> 27 | ... AF26: =SUM(AF13:AF18) -> 3326
B27: 11.15 - 11.30 | C27: 19 | D27: 8 | E27: 10 | F27: 8 | G27: 1 | H27: 0 | I27: 11 | J27: 0 | K27: 0 | L27: 1 | M27: 115 | N27: 0 | O27: =SUM(C27:L27,N27) -> 58 | P27: =SUM(C27:N27) -> 173 | R27: PM Period | S27: =SUM(S19:S21) -> 131 | T27: =SUM(T19:T21) -> 40 | U27: =SUM(U19:U21) -> 32 | V27: =SUM(V19:V21) -> 94 | W27: =SUM(W19:W21) -> 9 | X27: =SUM(X19:X21) -> 0 | Y27: =SUM(Y19:Y21) -> 53 | Z27: =SUM(Z19:Z21) -> 27 | ... AF27: =SUM(AF19:AF21) -> 1683
B28: 11.30 - 11.45 | C28: 11 | D28: 8 | E28: 2 | F28: 7 | G28: 0 | H28: 0 | I28: 10 | J28: 0 | K28: 0 | L28: 0 | M28: 57 | N28: 0 | O28: =SUM(C28:L28,N28) -> 38 | P28: =SUM(C28:N28) -> 95 | R28: 12 Hours | S28: =SUM(S10:S21) -> 612 | T28: =SUM(T10:T21) -> 216 | U28: =SUM(U10:U21) -> 171 | V28: =SUM(V10:V21) -> 366 | W28: =SUM(W10:W21) -> 33 | X28: =SUM(X10:X21) -> 0 | Y28: =SUM(Y10:Y21) -> 311 | Z28: =SUM(Z10:Z21) -> 65 | ... AF28: =SUM(AF10:AF21) -> 6715
B29: 11.45 - 12.00 | C29: 10 | D29: 6 | E29: 6 | F29: 10 | G29: 1 | H29: 0 | I29: 13 | J29: 1 | K29: 0 | L29: 1 | M29: 96 | N29: 0 | O29: =SUM(C29:L29,N29) -> 48 | P29: =SUM(C29:N29) -> 144
B30: 12.00 - 12.15 | C30: 11 | D30: 4 | E30: 4 | F30: 9 | G30: 0 | H30: 0 | I30: 3 | J30: 2 | K30: 0 | L30: 2 | M30: 93 | N30: 0 | O30: =SUM(C30:L30,N30) -> 35 | P30: =SUM(C30:N30) -> 128
B31: 12.15 - 12.30 | C31: 1 | D31: 2 | E31: 2 | F31: 6 | G31: 0 | H31: 0 | I31: 3 | J31: 5 | K31: 0 | L31: 0 | M31: 88 | N31: 0 | O31: =SUM(C31:L31,N31) -> 19 | P31: =SUM(C31:N31) -> 107
B32: 12.30 - 12.45 | C32: 10 | D32: 3 | E32: 2 | F32: 9 | G32: 0 | H32: 0 | I32: 4 | J32: 1 | K32: 0 | L32: 0 | M32: 110 | N32: 0 | O32: =SUM(C32:L32,N32) -> 29 | P32: =SUM(C32:N32) -> 139
B33: 12.45 - 13.00 | C33: 14 | D33: 7 | E33: 7 | F33: 8 | G33: 1 | H33: 0 | I33: 8 | J33: 2 | K33: 0 | L33: 1 | M33: 92 | N33: 0 | O33: =SUM(C33:L33,N33) -> 48 | P33: =SUM(C33:N33) -> 140
B34: 13.00 - 13.15 | C34: 14 | D34: 1 | E34: 2 | F34: 7 | G34: 1 | H34: 0 | I34: 8 | J34: 0 | K34: 0 | L34: 0 | M34: 100 | N34: 0 | O34: =SUM(C34:L34,N34) -> 33 | P34: =SUM(C34:N34) -> 133
B35: 13.15 - 13.30 | C35: 17 | D35: 3 | E35: 9 | F35: 9 | G35: 2 | H35: 0 | I35: 9 | J35: 0 | K35: 1 | L35: 1 | M35: 110 | N35: 0 | O35: =SUM(C35:L35,N35) -> 51 | P35: =SUM(C35:N35) -> 161
B36: 13.30 - 13.45 | C36: 16 | D36: 1 | E36: 1 | F36: 6 | G36: 1 | H36: 0 | I36: 11 | J36: 1 | K36: 1 | L36: 0 | M36: 102 | N36: 0 | O36: =SUM(C36:L36,N36) -> 38 | P36: =SUM(C36:N36) -> 140
B37: 13.45 - 14.00 | C37: 13 | D37: 6 | E37: 1 | F37: 10 | G37: 1 | H37: 0 | I37: 4 | J37: 1 | K37: 0 | L37: 0 | M37: 111 | N37: 0 | O37: =SUM(C37:L37,N37) -> 36 | P37: =SUM(C37:N37) -> 147
B38: 14.00 - 14.15 | C38: 11 | D38: 2 | E38: 5 | F38: 11 | G38: 1 | H38: 0 | I38: 8 | J38: 0 | K38: 0 | L38: 1 | M38: 84 | N38: 0 | O38: =SUM(C38:L38,N38) -> 39 | P38: =SUM(C38:N38) -> 123
B39: 14.15 - 14.30 | C39: 18 | D39: 4 | E39: 6 | F39: 4 | G39: 2 | H39: 0 | I39: 9 | J39: 0 | K39: 0 | L39: 2 | M39: 103 | N39: 1 | O39: =SUM(C39:L39,N39) -> 46 | P39: =SUM(C39:N39) -> 149
B40: 14.30 - 14.45 | C40: 17 | D40: 5 | E40: 2 | F40: 9 | G40: 0 | H40: 0 | I40: 7 | J40: 2 | K40: 0 | L40: 1 | M40: 86 | N40: 0 | O40: =SUM(C40:L40,N40) -> 43 | P40: =SUM(C40:N40) -> 129
... B57: 18.45 - 19.00 | C57: 1 | D57: 7 | E57: 4 | F57: 5 | G57: 1 | H57: 0 | I57: 5 | J57: 0 | K57: 0 | L57: 1 | M57: 125 | N57: 0 | O57: =SUM(C57:L57,N57) -> 24 | P57: =SUM(C57:N57) -> 149
B58: Totals | C58: =SUM(C10:C57) -> 612 | D58: =SUM(D10:D57) -> 216 | E58: =SUM(E10:E57) -> 171 | F58: =SUM(F10:F57) -> 366 | G58: =SUM(G10:G57) -> 33 | H58: =SUM(H10:H57) -> 0 | I58: =SUM(I10:I57) -> 311 | J58: =SUM(J10:J57) -> 65 | ... P58: =SUM(P10:P57) -> 6715
...

Sheet 29.10 KATOSI-MUKONO
B1: Consultancy services for Preparation of Expressway Development Master Plan (EDMP) for Uganda
B2: MANUAL CLASSIFIED COUNT (MCC)
B3: ROAD NAME: | C3: ='29.10-MUKONO-KATOSI'!C3:G3 -> MCC - C2 - STN077 - KATOSI ROAD
C5: Date | D5: ='29.10-MUKONO-KATOSI'!D5 -> 29.10.2019 | F5: Location | G5: ='29.10-MUKONO-KATOSI'!G5:H5 -> LUV GUEST HOUSE | J5: Surveyor | K5: MOSES
C6: Dir. From | D6: KATOSI | F6: Dir. To | G6: MUKONO | J6: Supervisor | K6: ='29.10-MUKONO-KATOSI'!K6:L6 -> VICTOR M
B8: Time / Veh Type | R8: SUMMARY TRAFFIC VOLUMES
C9: 1. Car | D9: 2. Station Wagon | E9: 3. Pickups | F9: 4. Minibus, matatu | G9: 5. Medium bus | H9: 6. Large Bus | I9: 7. Light Truck | J9: 8. Medium Truck | K9: 9. Heavy truck | L9: 10. Truck Trailer | M9: 11. Motor cycles | N9: 12. Tractors | O9: Total Excl M/Cycles | P9: Total All | R9: Time | S9: 1. Car | T9: 2. Station Wagon | U9: 3. Pickups | V9: 4. Minibus, matatu | W9: 5. Medium bus | X9: 6. Large Bus | Y9: 7. Light Truck | Z9: 8. Medium Truck | AA9: 9. Heavy truck | AB9: 10. Truck Trailer | AC9: 11. Motorcycles | AD9: 12. Tractors, Graders | AE9: Total Excl M/ Cycles | AF9: Total All
B10: 07.00 - 07.15 | C10: 3 | D10: 5 | E10: 0 | F10: 2 | G10: 1 | H10: 0 | I10: 0 | J10: 0 | K10: 0 | L10: 0 | M10: 45 | N10: 0 | O10: =SUM(C10:L10,N10) -> 11 | P10: =SUM(C10:N10) -> 56 | R10: 0700-0800 | S10: =SUM(C10:C13) -> 94 | T10: =SUM(D10:D13) -> 37 | U10: =SUM(E10:E13) -> 14 | V10: =SUM(F10:F13) -> 100 | W10: =SUM(G10:G13) -> 8 | X10: =SUM(H10:H13) -> 0 | Y10: =SUM(I10:I13) -> 32 | Z10: =SUM(J10:J13) -> 1 | ... AF10: =SUM(P10:P13) -> 671
B11: 07.15 - 07.30 | C11: 20 | D11: 7 | E11: 2 | F11: 3 | G11: 0 | H11: 0 | I11: 6 | J11: 0 | K11: 0 | L11: 0 | M11: 110 | N11: 0 | O11: =SUM(C11:L11,N11) -> 38 | P11: =SUM(C11:N11) -> 148 | R11: 0800-0900 | S11: =SUM(C14:C17) -> 93 | T11: =SUM(D14:D17) -> 49 | U11: =SUM(E14:E17) -> 28 | V11: =SUM(F14:F17) -> 117 | W11: =SUM(G14:G17) -> 9 | X11: =SUM(H14:H17) -> 1 | Y11: =SUM(I14:I17) -> 28 | Z11: =SUM(J14:J17) -> 3 | ... AF11: =SUM(P14:P17) -> 752
B12: 07.30 - 07.45 | C12: 36 | D12: 20 | E12: 5 | F12: 35 | G12: 1 | H12: 0 | I12: 1 | J12: 1 | K12: 0 | L12: 0 | M12: 120 | N12: 0 | O12: =SUM(C12:L12,N12) -> 99 | P12: =SUM(C12:N12) -> 219 | R12: 0900-1000 | S12: =SUM(C18:C21) -> 55 | T12: =SUM(D18:D21) -> 18 | U12: =SUM(E18:E21) -> 18 | V12: =SUM(F18:F21) -> 74 | W12: =SUM(G18:G21) -> 5 | X12: =SUM(H18:H21) -> 0 | Y12: =SUM(I18:I21) -> 23 | Z12: =SUM(J18:J21) -> 2 | ... AF12: =SUM(P18:P21) -> 593
B13: 07.45 - 08.00 | C13: 35 | D13: 5 | E13: 7 | F13: 60 | G13: 6 | H13: 0 | I13: 25 | J13: 0 | K13: 0 | L13: 0 | M13: 110 | N13: 0 | O13: =SUM(C13:L13,N13) -> 138 | P13: =SUM(C13:N13) -> 248 | R13: 1000-1100 | S13: =SUM(C22:C25) -> 36 | T13: =SUM(D22:D25) -> 18 | U13: =SUM(E22:E25) -> 4 | V13: =SUM(F22:F25) -> 57 | W13: =SUM(G22:G25) -> 0 | X13: =SUM(H22:H25) -> 0 | Y13: =SUM(I22:I25) -> 36 | Z13: =SUM(J22:J25) -> 3 | ... AF13: =SUM(P22:P25) -> 399
B14: 08.00 - 08.15 | C14: 37 | D14: 27 | E14: 11 | F14: 47 | G14: 7 | H14: 1 | I14: 15 | J14: 2 | K14: 3 | L14: 0 | M14: 107 | N14: 0 | O14: =SUM(C14:L14,N14) -> 150 | P14: =SUM(C14:N14) -> 257 | R14: 1100-1200 | S14: =SUM(C26:C29) -> 28 | T14: =SUM(D26:D29) -> 14 | U14: =SUM(E26:E29) -> 4 | V14: =SUM(F26:F29) -> 45 | W14: =SUM(G26:G29) -> 0 | X14: =SUM(H26:H29) -> 0 | Y14: =SUM(I26:I29) -> 13 | Z14: =SUM(J26:J29) -> 2 | ... AF14: =SUM(P26:P29) -> 395
B15: 08.15 - 08.30 | C15: 20 | D15: 10 | E15: 6 | F15: 16 | G15: 0 | H15: 0 | I15: 6 | J15: 0 | K15: 2 | L15: 0 | M15: 80 | N15: 0 | O15: =SUM(C15:L15,N15) -> 60 | P15: =SUM(C15:N15) -> 140 | R15: 1200-1300 | S15: =SUM(C30:C33) -> 41 | T15: =SUM(D30:D33) -> 16 | U15: =SUM(E30:E33) -> 18 | V15: =SUM(F30:F33) -> 54 | W15: =SUM(G30:G33) -> 2 | X15: =SUM(H30:H33) -> 0 | Y15: =SUM(I30:I33) -> 18 | Z15: =SUM(J30:J33) -> 6 | ... AF15: =SUM(P30:P33) -> 541
B16: 08.30 - 08.45 | C16: 21 | D16: 10 | E16: 1 | F16: 28 | G16: 2 | H16: 0 | I16: 7 | J16: 0 | K16: 0 | L16: 0 | M16: 127 | N16: 0 | O16: =SUM(C16:L16,N16) -> 69 | P16: =SUM(C16:N16) -> 196 | R16: 1300-1400 | S16: =SUM(C34:C37) -> 27 | T16: =SUM(D34:D37) -> 13 | U16: =SUM(E34:E37) -> 14 | V16: =SUM(F34:F37) -> 24 | W16: =SUM(G34:G37) -> 1 | X16: =SUM(H34:H37) -> 0 | Y16: =SUM(I34:I37) -> 36 | Z16: =SUM(J34:J37) -> 3 | ... AF16: =SUM(P34:P37) -> 542
B17: 08.45 - 9.00 | C17: 15 | D17: 2 | E17: 10 | F17: 26 | G17: 0 | H17: 0 | I17: 0 | J17: 1 | K17: 0 | L17: 0 | M17: 105 | N17: 0 | O17: =SUM(C17:L17,N17) -> 54 | P17: =SUM(C17:N17) -> 159 | R17: 1400-1500 | S17: =SUM(C38:C41) -> 35 | T17: =SUM(D38:D41) -> 24 | U17: =SUM(E38:E41) -> 12 | V17: =SUM(F38:F41) -> 36 | W17: =SUM(G38:G41) -> 4 | X17: =SUM(H38:H41) -> 2 | Y17: =SUM(I38:I41) -> 40 | Z17: =SUM(J38:J41) -> 7 | ... AF17: =SUM(P38:P41) -> 493
B18: 09.00 - 09.15 | C18: 30 | D18: 12 | E18: 16 | F18: 37 | G18: 2 | H18: 0 | I18: 7 | J18: 0 | K18: 0 | L18: 1 | M18: 140 | N18: 0 | O18: =SUM(C18:L18,N18) -> 105 | P18: =SUM(C18:N18) -> 245 | R18: 1500-1600 | S18: =SUM(C42:C45) -> 52 | T18: =SUM(D42:D45) -> 26 | U18: =SUM(E42:E45) -> 12 | V18: =SUM(F42:F45) -> 69 | W18: =SUM(G42:G45) -> 3 | X18: =SUM(H42:H45) -> 0 | Y18: =SUM(I42:I45) -> 38 | Z18: =SUM(J42:J45) -> 9 | ... AF18: =SUM(P42:P45) -> 623
B19: 09.15 - 09.30 | C19: 17 | D19: 1 | E19: 0 | F19: 15 | G19: 0 | H19: 0 | I19: 6 | J19: 0 | K19: 2 | L19: 2 | M19: 50 | N19: 0 | O19: =SUM(C19:L19,N19) -> 43 | P19: =SUM(C19:N19) -> 93 | R19: 1600-1700 | S19: =SUM(C46:C49) -> 60 | T19: =SUM(D46:D49) -> 20 | U19: =SUM(E46:E49) -> 20 | V19: =SUM(F46:F49) -> 50 | W19: =SUM(G46:G49) -> 6 | X19: =SUM(H46:H49) -> 0 | Y19: =SUM(I46:I49) -> 41 | Z19: =SUM(J46:J49) -> 10 | ... AF19: =SUM(P46:P49) -> 594
B20: 09.30 - 09.45 | C20: 1 | D20: 1 | E20: 1 | F20: 17 | G20: 2 | H20: 0 | I20: 5 | J20: 1 | K20: 0 | L20: 0 | M20: 98 | N20: 0 | O20: =SUM(C20:L20,N20) -> 28 | P20: =SUM(C20:N20) -> 126 | R20: 1700-1800 | S20: =SUM(C50:C53) -> 55 | T20: =SUM(D50:D53) -> 33 | U20: =SUM(E50:E53) -> 14 | V20: =SUM(F50:F53) -> 39 | W20: =SUM(G50:G53) -> 4 | X20: =SUM(H50:H53) -> 0 | Y20: =SUM(I50:I53) -> 26 | Z20: =SUM(J50:J53) -> 6 | ... AF20: =SUM(P50:P53) -> 656
B21: 09.45 - 10.00 | C21: 7 | D21: 4 | E21: 1 | F21: 5 | G21: 1 | H21: 0 | I21: 5 | J21: 1 | K21: 0 | L21: 0 | M21: 105 | N21: 0 | O21: =SUM(C21:L21,N21) -> 24 | P21: =SUM(C21:N21) -> 129 | R21: 1800-1900 | S21: =SUM(C54:C57) -> 49 | T21: =SUM(D54:D57) -> 36 | U21: =SUM(E54:E57) -> 11 | V21: =SUM(F54:F57) -> 40 | W21: =SUM(G54:G57) -> 5 | X21: =SUM(H54:H57) -> 0 | Y21: =SUM(I54:I57) -> 34 | Z21: =SUM(J54:J57) -> 5 | ... AF21: =SUM(P54:P57) -> 581
B22: 10.00 - 10.15 | C22: 6 | D22: 2 | E22: 0 | F22: 6 | G22: 0 | H22: 0 | I22: 3 | J22: 0 | K22: 0 | L22: 0 | M22: 40 | N22: 0 | O22: =SUM(C22:L22,N22) -> 17 | P22: =SUM(C22:N22) -> 57 | R22: AM Peak Hr | S22: =MAX(S10:S12) -> 94 | T22: =MAX(T10:T12) -> 49 | U22: =MAX(U10:U12) -> 28 | V22: =MAX(V10:V12) -> 117 | W22: =MAX(W10:W12) -> 9 | X22: =MAX(X10:X12) -> 1 | Y22: =MAX(Y10:Y12) -> 32 | Z22: =MAX(Z10:Z12) -> 3 | ... AF22: =MAX(AF10:AF12) -> 752
B23: 10.15 - 10.30 | C23: 8 | D23: 1 | E23: 2 | F23: 10 | G23: 0 | H23: 0 | I23: 15 | J23: 1 | K23: 0 | L23: 1 | M23: 72 | N23: 0 | O23: =SUM(C23:L23,N23) -> 38 | P23: =SUM(C23:N23) -> 110 | R23: IP Peak Hr | S23: =MAX(S13:S18) -> 52 | T23: =MAX(T13:T18) -> 26 | U23: =MAX(U13:U18) -> 18 | V23: =MAX(V13:V18) -> 69 | W23: =MAX(W13:W18) -> 4 | X23: =MAX(X13:X18) -> 2 | Y23: =MAX(Y13:Y18) -> 40 | Z23: =MAX(Z13:Z18) -> 9 | ... AF23: =MAX(AF13:AF18) -> 623
B24: 10.30 - 10.45 | C24: 10 | D24: 5 | E24: 0 | F24: 25 | G24: 0 | H24: 0 | I24: 3 | J24: 1 | K24: 0 | L24: 0 | M24: 36 | N24: 0 | O24: =SUM(C24:L24,N24) -> 44 | P24: =SUM(C24:N24) -> 80 | R24: PM Peak Hr | S24: =MAX(S19:S21) -> 60 | T24: =MAX(T19:T21) -> 36 | U24: =MAX(U19:U21) -> 20 | V24: =MAX(V19:V21) -> 50 | W24: =MAX(W19:W21) -> 6 | X24: =MAX(X19:X21) -> 0 | Y24: =MAX(Y19:Y21) -> 41 | Z24: =MAX(Z19:Z21) -> 10 | ... AF24: =MAX(AF19:AF21) -> 656
B25: 10.45 - 11.00 | C25: 12 | D25: 10 | E25: 2 | F25: 16 | G25: 0 | H25: 0 | I25: 15 | J25: 1 | K25: 0 | L25: 1 | M25: 95 | N25: 0 | O25: =SUM(C25:L25,N25) -> 57 | P25: =SUM(C25:N25) -> 152 | R25: AM Period | S25: =SUM(S10:S12) -> 242 | T25: =SUM(T10:T12) -> 104 | U25: =SUM(U10:U12) -> 60 | V25: =SUM(V10:V12) -> 291 | W25: =SUM(W10:W12) -> 22 | X25: =SUM(X10:X12) -> 1 | Y25: =SUM(Y10:Y12) -> 83 | Z25: =SUM(Z10:Z12) -> 6 | ... AF25: =SUM(AF10:AF12) -> 2016
B26: 11.00 - 11.15 | C26: 3 | D26: 2 | E26: 0 | F26: 12 | G26: 0 | H26: 0 | I26: 2 | J26: 2 | K26: 0 | L26: 1 | M26: 65 | N26: 0 | O26: =SUM(C26:L26,N26) -> 22 | P26: =SUM(C26:N26) -> 87 | R26: IP Period | S26: =SUM(S13:S18) -> 219 | T26: =SUM(T13:T18) -> 111 | U26: =SUM(U13:U18) -> 64 | V26: =SUM(V13:V18) -> 285 | W26: =SUM(W13:W18) -> 10 | X26: =SUM(X13:X18) -> 2 | Y26: =SUM(Y13:Y18) -> 181 | Z26: =SUM(Z13:Z18) -> 30 | ... AF26: =SUM(AF13:AF18) -> 2993
B27: 11.15 - 11.30 | C27: 6 | D27: 5 | E27: 2 | F27: 6 | G27: 0 | H27: 0 | I27: 4 | J27: 0 | K27: 1 | L27: 1 | M27: 72 | N27: 0 | O27: =SUM(C27:L27,N27) -> 25 | P27: =SUM(C27:N27) -> 97 | R27: PM Period | S27: =SUM(S19:S21) -> 164 | T27: =SUM(T19:T21) -> 89 | U27: =SUM(U19:U21) -> 45 | V27: =SUM(V19:V21) -> 129 | W27: =SUM(W19:W21) -> 15 | X27: =SUM(X19:X21) -> 0 | Y27: =SUM(Y19:Y21) -> 101 | Z27: =SUM(Z19:Z21) -> 21 | ... AF27: =SUM(AF19:AF21) -> 1831
B28: 11.30 - 11.45 | C28: 6 | D28: 2 | E28: 0 | F28: 7 | G28: 0 | H28: 0 | I28: 1 | J28: 0 | K28: 1 | L28: 0 | M28: 45 | N28: 0 | O28: =SUM(C28:L28,N28) -> 17 | P28: =SUM(C28:N28) -> 62 | R28: 12 Hours | S28: =SUM(S10:S21) -> 625 | T28: =SUM(T10:T21) -> 304 | U28: =SUM(U10:U21) -> 169 | V28: =SUM(V10:V21) -> 705 | W28: =SUM(W10:W21) -> 47 | X28: =SUM(X10:X21) -> 3 | Y28: =SUM(Y10:Y21) -> 365 | Z28: =SUM(Z10:Z21) -> 57 | ... AF28: =SUM(AF10:AF21) -> 6840
B29: 11.45 - 12.00 | C29: 13 | D29: 5 | E29: 2 | F29: 20 | G29: 0 | H29: 0 | I29: 6 | J29: 0 | K29: 0 | L29: 1 | M29: 102 | N29: 0 | O29: =SUM(C29:L29,N29) -> 47 | P29: =SUM(C29:N29) -> 149
B30: 12.00 - 12.15 | C30: 8 | D30: 5 | E30: 3 | F30: 7 | G30: 0 | H30: 0 | I30: 5 | J30: 1 | K30: 0 | L30: 0 | M30: 91 | N30: 0 | O30: =SUM(C30:L30,N30) -> 29 | P30: =SUM(C30:N30) -> 120
B31: 12.15 - 12.30 | C31: 10 | D31: 2 | E31: 7 | F31: 11 | G31: 1 | H31: 0 | I31: 10 | J31: 3 | K31: 1 | L31: 1 | M31: 85 | N31: 0 | O31: =SUM(C31:L31,N31) -> 46 | P31: =SUM(C31:N31) -> 131
B32: 12.30 - 12.45 | C32: 12 | D32: 7 | E32: 8 | F32: 15 | G32: 0 | H32: 0 | I32: 1 | J32: 2 | K32: 1 | L32: 1 | M32: 105 | N32: 0 | O32: =SUM(C32:L32,N32) -> 47 | P32: =SUM(C32:N32) -> 152
B33: 12.45 - 13.00 | C33: 11 | D33: 2 | E33: 0 | F33: 21 | G33: 1 | H33: 0 | I33: 2 | J33: 0 | K33: 0 | L33: 1 | M33: 100 | N33: 0 | O33: =SUM(C33:L33,N33) -> 38 | P33: =SUM(C33:N33) -> 138
B34: 13.00 - 13.15 | C34: 4 | D34: 1 | E34: 5 | F34: 8 | G34: 1 | H34: 0 | I34: 11 | J34: 1 | K34: 0 | L34: 2 | M34: 144 | N34: 0 | O34: =SUM(C34:L34,N34) -> 33 | P34: =SUM(C34:N34) -> 177
B35: 13.15 - 13.30 | C35: 8 | D35: 1 | E35: 2 | F35: 5 | G35: 0 | H35: 0 | I35: 12 | J35: 0 | K35: 0 | L35: 0 | M35: 115 | N35: 0 | O35: =SUM(C35:L35,N35) -> 28 | P35: =SUM(C35:N35) -> 143
B36: 13.30 - 13.45 | C36: 10 | D36: 10 | E36: 7 | F36: 10 | G36: 0 | H36: 0 | I36: 13 | J36: 2 | K36: 3 | L36: 1 | M36: 139 | N36: 0 | O36: =SUM(C36:L36,N36) -> 56 | P36: =SUM(C36:N36) -> 195
B37: 13.45 - 14.00 | C37: 5 | D37: 1 | E37: 0 | F37: 1 | G37: 0 | H37: 0 | I37: 0 | J37: 0 | K37: 0 | L37: 0 | M37: 20 | N37: 0 | O37: =SUM(C37:L37,N37) -> 7 | P37: =SUM(C37:N37) -> 27
B38: 14.00 - 14.15 | C38: 10 | D38: 9 | E38: 3 | F38: 8 | G38: 1 | H38: 1 | I38: 14 | J38: 2 | K38: 0 | L38: 1 | M38: 66 | N38: 0 | O38: =SUM(C38:L38,N38) -> 49 | P38: =SUM(C38:N38) -> 115
B39: 14.15 - 14.30 | C39: 8 | D39: 5 | E39: 4 | F39: 14 | G39: 1 | H39: 1 | I39: 7 | J39: 1 | K39: 0 | L39: 0 | M39: 72 | N39: 0 | O39: =SUM(C39:L39,N39) -> 41 | P39: =SUM(C39:N39) -> 113
B40: 14.30 - 14.45 | C40: 5 | D40: 5 | E40: 3 | F40: 6 | G40: 1 | H40: 0 | I40: 4 | J40: 1 | K40: 0 | L40: 1 | M40: 91 | N40: 0 | O40: =SUM(C40:L40,N40) -> 26 | P40: =SUM(C40:N40) -> 117
... B57: 18.45 - 19.00 | C57: 9 | D57: 6 | E57: 1 | F57: 10 | G57: 0 | H57: 0 | I57: 7 | J57: 1 | K57: 1 | L57: 0 | M57: 101 | N57: 0 | O57: =SUM(C57:L57,N57) -> 35 | P57: =SUM(C57:N57) -> 136
B58: Totals | C58: =SUM(C10:C57) -> 625 | D58: =SUM(D10:D57) -> 304 | E58: =SUM(E10:E57) -> 169 | F58: =SUM(F10:F57) -> 705 | G58: =SUM(G10:G57) -> 47 | H58: =SUM(H10:H57) -> 3 | I58: =SUM(I10:I57) -> 365 | J58: =SUM(J10:J57) -> 57 | ... P58: =SUM(P10:P57) -> 6840
...

Sheet 30.10 MUKONO-KATOSI
B1: Consultancy services for Preparation of Expressway Development Master Plan (EDMP) for Uganda
B2: MANUAL CLASSIFIED COUNT (MCC)
B3: ROAD NAME: | C3: ='29.10 KATOSI-MUKONO'!C3:G3 -> MCC - C2 - STN077 - KATOSI ROAD
C5: Date | D5: ='30.10 KATOSI-MUKONO'!D5 -> 30.10.2019 | F5: Location | G5: ='29.10-MUKONO-KATOSI'!G5:H5 -> LUV GUEST HOUSE | J5: Surveyor | K5: ='29.10-MUKONO-KATOSI'!K5:L5 -> KIRABO DAN
C6: Dir. From | D6: MUKONO | F6: Dir. To | G6: KATOSI | J6: Supervisor | K6: ='29.10-MUKONO-KATOSI'!K6:L6 -> VICTOR M
B8: Time / Veh Type | R8: SUMMARY TRAFFIC VOLUMES
C9: 1. Car | D9: 2. Station Wagon | E9: 3. Pickups | F9: 4. Minibus, matatu | G9: 5. Medium bus | H9: 6. Large Bus | I9: 7. Light Truck | J9: 8. Medium Truck | K9: 9. Heavy truck | L9: 10. Truck Trailer | M9: 11. Motor cycles | N9: 12. Tractors | O9: Total Excl M/Cycles | P9: Total All | R9: Time | S9: 1. Car | T9: 2. Station Wagon | U9: 3. Pickups | V9: 4. Minibus, matatu | W9: 5. Medium bus | X9: 6. Large Bus | Y9: 7. Light Truck | Z9: 8. Medium Truck | AA9: 9. Heavy truck | AB9: 10. Truck Trailer | AC9: 11. Motorcycles | AD9: 12. Tractors, Graders | AE9: Total Excl M/ Cycles | AF9: Total All
B10: 07.00 - 07.15 | C10: 8 | D10: 2 | E10: 2 | F10: 5 | G10: 0 | H10: 0 | I10: 3 | J10: 2 | K10: 0 | L10: 0 | M10: 42 | N10: 0 | O10: =SUM(C10:L10,N10) -> 22 | P10: =SUM(C10:N10) -> 64 | R10: 0700-0800 | S10: =SUM(C10:C13) -> 31 | T10: =SUM(D10:D13) -> 19 | U10: =SUM(E10:E13) -> 8 | V10: =SUM(F10:F13) -> 25 | W10: =SUM(G10:G13) -> 2 | X10: =SUM(H10:H13) -> 0 | Y10: =SUM(I10:I13) -> 17 | Z10: =SUM(J10:J13) -> 7 | ... AF10: =SUM(P10:P13) -> 434
B11: 07.15 - 07.30 | C11: 2 | D11: 3 | E11: 2 | F11: 3 | G11: 1 | H11: 0 | I11: 3 | J11: 1 | K11: 0 | L11: 0 | M11: 36 | N11: 36 | O11: =SUM(C11:L11,N11) -> 51 | P11: =SUM(C11:N11) -> 87 | R11: 0800-0900 | S11: =SUM(C14:C17) -> 50 | T11: =SUM(D14:D17) -> 34 | U11: =SUM(E14:E17) -> 12 | V11: =SUM(F14:F17) -> 29 | W11: =SUM(G14:G17) -> 14 | X11: =SUM(H14:H17) -> 0 | Y11: =SUM(I14:I17) -> 28 | Z11: =SUM(J14:J17) -> 7 | ... AF11: =SUM(P14:P17) -> 660
B12: 07.30 - 07.45 | C12: 11 | D12: 7 | E12: 1 | F12: 8 | G12: 1 | H12: 0 | I12: 5 | J12: 1 | K12: 0 | L12: 0 | M12: 100 | N12: 0 | O12: =SUM(C12:L12,N12) -> 34 | P12: =SUM(C12:N12) -> 134 | R12: 0900-1000 | S12: =SUM(C18:C21) -> 42 | T12: =SUM(D18:D21) -> 24 | U12: =SUM(E18:E21) -> 22 | V12: =SUM(F18:F21) -> 30 | W12: =SUM(G18:G21) -> 1 | X12: =SUM(H18:H21) -> 0 | Y12: =SUM(I18:I21) -> 46 | Z12: =SUM(J18:J21) -> 5 | ... AF12: =SUM(P18:P21) -> 684
B13: 07.45 - 08.00 | C13: 10 | D13: 7 | E13: 3 | F13: 9 | G13: 0 | H13: 0 | I13: 6 | J13: 3 | K13: 0 | L13: 0 | M13: 111 | N13: 0 | O13: =SUM(C13:L13,N13) -> 38 | P13: =SUM(C13:N13) -> 149 | R13: 1000-1100 | S13: =SUM(C22:C25) -> 42 | T13: =SUM(D22:D25) -> 29 | U13: =SUM(E22:E25) -> 12 | V13: =SUM(F22:F25) -> 30 | W13: =SUM(G22:G25) -> 1 | X13: =SUM(H22:H25) -> 1 | Y13: =SUM(I22:I25) -> 31 | Z13: =SUM(J22:J25) -> 4 | ... AF13: =SUM(P22:P25) -> 595
B14: 08.00 - 08.15 | C14: 12 | D14: 8 | E14: 2 | F14: 4 | G14: 12 | H14: 0 | I14: 4 | J14: 2 | K14: 1 | L14: 5 | M14: 124 | N14: 0 | O14: =SUM(C14:L14,N14) -> 50 | P14: =SUM(C14:N14) -> 174 | R14: 1100-1200 | S14: =SUM(C26:C29) -> 57 | T14: =SUM(D26:D29) -> 27 | U14: =SUM(E26:E29) -> 14 | V14: =SUM(F26:F29) -> 28 | W14: =SUM(G26:G29) -> 0 | X14: =SUM(H26:H29) -> 0 | Y14: =SUM(I26:I29) -> 44 | Z14: =SUM(J26:J29) -> 9 | ... AF14: =SUM(P26:P29) -> 619
B15: 08.15 - 08.30 | C15: 11 | D15: 8 | E15: 3 | F15: 8 | G15: 1 | H15: 0 | I15: 7 | J15: 0 | K15: 0 | L15: 1 | M15: 121 | N15: 0 | O15: =SUM(C15:L15,N15) -> 39 | P15: =SUM(C15:N15) -> 160 | R15: 1200-1300 | S15: =SUM(C30:C33) -> 34 | T15: =SUM(D30:D33) -> 26 | U15: =SUM(E30:E33) -> 17 | V15: =SUM(F30:F33) -> 33 | W15: =SUM(G30:G33) -> 0 | X15: =SUM(H30:H33) -> 0 | Y15: =SUM(I30:I33) -> 39 | Z15: =SUM(J30:J33) -> 1 | ... AF15: =SUM(P30:P33) -> 586
B16: 08.30 - 08.45 | C16: 10 | D16: 7 | E16: 5 | F16: 7 | G16: 0 | H16: 0 | I16: 8 | J16: 2 | K16: 1 | L16: 1 | M16: 112 | N16: 0 | O16: =SUM(C16:L16,N16) -> 41 | P16: =SUM(C16:N16) -> 153 | R16: 1300-1400 | S16: =SUM(C34:C37) -> 38 | T16: =SUM(D34:D37) -> 35 | U16: =SUM(E34:E37) -> 12 | V16: =SUM(F34:F37) -> 31 | W16: =SUM(G34:G37) -> 3 | X16: =SUM(H34:H37) -> 0 | Y16: =SUM(I34:I37) -> 33 | Z16: =SUM(J34:J37) -> 4 | ... AF16: =SUM(P34:P37) -> 552
B17: 08.45 - 9.00 | C17: 17 | D17: 11 | E17: 2 | F17: 10 | G17: 1 | H17: 0 | I17: 9 | J17: 3 | K17: 0 | L17: 0 | M17: 120 | N17: 0 | O17: =SUM(C17:L17,N17) -> 53 | P17: =SUM(C17:N17) -> 173 | R17: 1400-1500 | S17: =SUM(C38:C41) -> 34 | T17: =SUM(D38:D41) -> 28 | U17: =SUM(E38:E41) -> 19 | V17: =SUM(F38:F41) -> 34 | W17: =SUM(G38:G41) -> 0 | X17: =SUM(H38:H41) -> 1 | Y17: =SUM(I38:I41) -> 31 | Z17: =SUM(J38:J41) -> 5 | ... AF17: =SUM(P38:P41) -> 449
B18: 09.00 - 09.15 | C18: 12 | D18: 8 | E18: 3 | F18: 3 | G18: 0 | H18: 0 | I18: 11 | J18: 2 | K18: 0 | L18: 0 | M18: 134 | N18: 0 | O18: =SUM(C18:L18,N18) -> 39 | P18: =SUM(C18:N18) -> 173 | R18: 1500-1600 | S18: =SUM(C42:C45) -> 23 | T18: =SUM(D42:D45) -> 18 | U18: =SUM(E42:E45) -> 9 | V18: =SUM(F42:F45) -> 25 | W18: =SUM(G42:G45) -> 3 | X18: =SUM(H42:H45) -> 0 | Y18: =SUM(I42:I45) -> 25 | Z18: =SUM(J42:J45) -> 11 | ... AF18: =SUM(P42:P45) -> 424
B19: 09.15 - 09.30 | C19: 12 | D19: 6 | E19: 8 | F19: 12 | G19: 0 | H19: 0 | I19: 10 | J19: 0 | K19: 3 | L19: 1 | M19: 138 | N19: 0 | O19: =SUM(C19:L19,N19) -> 52 | P19: =SUM(C19:N19) -> 190 | R19: 1600-1700 | S19: =SUM(C46:C49) -> 41 | T19: =SUM(D46:D49) -> 31 | U19: =SUM(E46:E49) -> 19 | V19: =SUM(F46:F49) -> 33 | W19: =SUM(G46:G49) -> 5 | X19: =SUM(H46:H49) -> 0 | Y19: =SUM(I46:I49) -> 24 | Z19: =SUM(J46:J49) -> 3 | ... AF19: =SUM(P46:P49) -> 490
B20: 09.30 - 09.45 | C20: 10 | D20: 4 | E20: 8 | F20: 6 | G20: 0 | H20: 0 | I20: 15 | J20: 1 | K20: 0 | L20: 1 | M20: 134 | N20: 0 | O20: =SUM(C20:L20,N20) -> 45 | P20: =SUM(C20:N20) -> 179 | R20: 1700-1800 | S20: =SUM(C50:C53) -> 39 | T20: =SUM(D50:D53) -> 22 | U20: =SUM(E50:E53) -> 14 | V20: =SUM(F50:F53) -> 31 | W20: =SUM(G50:G53) -> 4 | X20: =SUM(H50:H53) -> 0 | Y20: =SUM(I50:I53) -> 32 | Z20: =SUM(J50:J53) -> 10 | ... AF20: =SUM(P50:P53) -> 455
B21: 09.45 - 10.00 | C21: 8 | D21: 6 | E21: 3 | F21: 9 | G21: 1 | H21: 0 | I21: 10 | J21: 2 | K21: 0 | L21: 0 | M21: 103 | N21: 0 | O21: =SUM(C21:L21,N21) -> 39 | P21: =SUM(C21:N21) -> 142 | R21: 1800-1900 | S21: =SUM(C54:C57) -> 62 | T21: =SUM(D54:D57) -> 31 | U21: =SUM(E54:E57) -> 14 | V21: =SUM(F54:F57) -> 41 | W21: =SUM(G54:G57) -> 2 | X21: =SUM(H54:H57) -> 0 | Y21: =SUM(I54:I57) -> 23 | Z21: =SUM(J54:J57) -> 2 | ... AF21: =SUM(P54:P57) -> 617
B22: 10.00 - 10.15 | C22: 11 | D22: 8 | E22: 0 | F22: 4 | G22: 1 | H22: 0 | I22: 8 | J22: 0 | K22: 1 | L22: 0 | M22: 95 | N22: 0 | O22: =SUM(C22:L22,N22) -> 33 | P22: =SUM(C22:N22) -> 128 | R22: AM Peak Hr | S22: =MAX(S10:S12) -> 50 | T22: =MAX(T10:T12) -> 34 | U22: =MAX(U10:U12) -> 22 | V22: =MAX(V10:V12) -> 30 | W22: =MAX(W10:W12) -> 14 | X22: =MAX(X10:X12) -> 0 | Y22: =MAX(Y10:Y12) -> 46 | Z22: =MAX(Z10:Z12) -> 7 | ... AF22: =MAX(AF10:AF12) -> 684
B23: 10.15 - 10.30 | C23: 9 | D23: 10 | E23: 1 | F23: 9 | G23: 0 | H23: 0 | I23: 7 | J23: 1 | K23: 0 | L23: 1 | M23: 123 | N23: 0 | O23: =SUM(C23:L23,N23) -> 38 | P23: =SUM(C23:N23) -> 161 | R23: IP Peak Hr | S23: =MAX(S13:S18) -> 57 | T23: =MAX(T13:T18) -> 35 | U23: =MAX(U13:U18) -> 19 | V23: =MAX(V13:V18) -> 34 | W23: =MAX(W13:W18) -> 3 | X23: =MAX(X13:X18) -> 1 | Y23: =MAX(Y13:Y18) -> 44 | Z23: =MAX(Z13:Z18) -> 11 | ... AF23: =MAX(AF13:AF18) -> 619
B24: 10.30 - 10.45 | C24: 14 | D24: 8 | E24: 4 | F24: 8 | G24: 0 | H24: 0 | I24: 8 | J24: 2 | K24: 0 | L24: 1 | M24: 127 | N24: 0 | O24: =SUM(C24:L24,N24) -> 45 | P24: =SUM(C24:N24) -> 172 | R24: PM Peak Hr | S24: =MAX(S19:S21) -> 62 | T24: =MAX(T19:T21) -> 31 | U24: =MAX(U19:U21) -> 19 | V24: =MAX(V19:V21) -> 41 | W24: =MAX(W19:W21) -> 5 | X24: =MAX(X19:X21) -> 0 | Y24: =MAX(Y19:Y21) -> 32 | Z24: =MAX(Z19:Z21) -> 10 | ... AF24: =MAX(AF19:AF21) -> 617
B25: 10.45 - 11.00 | C25: 8 | D25: 3 | E25: 7 | F25: 9 | G25: 0 | H25: 1 | I25: 8 | J25: 1 | K25: 1 | L25: 1 | M25: 95 | N25: 0 | O25: =SUM(C25:L25,N25) -> 39 | P25: =SUM(C25:N25) -> 134 | R25: AM Period | S25: =SUM(S10:S12) -> 123 | T25: =SUM(T10:T12) -> 77 | U25: =SUM(U10:U12) -> 42 | V25: =SUM(V10:V12) -> 84 | W25: =SUM(W10:W12) -> 17 | X25: =SUM(X10:X12) -> 0 | Y25: =SUM(Y10:Y12) -> 91 | Z25: =SUM(Z10:Z12) -> 19 | ... AF25: =SUM(AF10:AF12) -> 1778
B26: 11.00 - 11.15 | C26: 19 | D26: 7 | E26: 2 | F26: 10 | G26: 0 | H26: 0 | I26: 5 | J26: 1 | K26: 0 | L26: 1 | M26: 121 | N26: 0 | O26: =SUM(C26:L26,N26) -> 45 | P26: =SUM(C26:N26) -> 166 | R26: IP Period | S26: =SUM(S13:S18) -> 228 | T26: =SUM(T13:T18) -> 163 | U26: =SUM(U13:U18) -> 83 | V26: =SUM(V13:V18) -> 181 | W26: =SUM(W13:W18) -> 7 | X26: =SUM(X13:X18) -> 2 | Y26: =SUM(Y13:Y18) -> 203 | Z26: =SUM(Z13:Z18) -> 34 | ... AF26: =SUM(AF13:AF18) -> 3225
B27: 11.15 - 11.30 | C27: 11 | D27: 6 | E27: 6 | F27: 7 | G27: 0 | H27: 0 | I27: 13 | J27: 1 | K27: 1 | L27: 1 | M27: 101 | N27: 0 | O27: =SUM(C27:L27,N27) -> 46 | P27: =SUM(C27:N27) -> 147 | R27: PM Period | S27: =SUM(S19:S21) -> 142 | T27: =SUM(T19:T21) -> 84 | U27: =SUM(U19:U21) -> 47 | V27: =SUM(V19:V21) -> 105 | W27: =SUM(W19:W21) -> 11 | X27: =SUM(X19:X21) -> 0 | Y27: =SUM(Y19:Y21) -> 79 | Z27: =SUM(Z19:Z21) -> 15 | ... AF27: =SUM(AF19:AF21) -> 1562
B28: 11.30 - 11.45 | C28: 11 | D28: 9 | E28: 3 | F28: 6 | G28: 0 | H28: 0 | I28: 13 | J28: 2 | K28: 0 | L28: 0 | M28: 103 | N28: 0 | O28: =SUM(C28:L28,N28) -> 44 | P28: =SUM(C28:N28) -> 147 | R28: 12 Hours | S28: =SUM(S10:S21) -> 493 | T28: =SUM(T10:T21) -> 324 | U28: =SUM(U10:U21) -> 172 | V28: =SUM(V10:V21) -> 370 | W28: =SUM(W10:W21) -> 35 | X28: =SUM(X10:X21) -> 2 | Y28: =SUM(Y10:Y21) -> 373 | Z28: =SUM(Z10:Z21) -> 68 | ... AF28: =SUM(AF10:AF21) -> 6565
B29: 11.45 - 12.00 | C29: 16 | D29: 5 | E29: 3 | F29: 5 | G29: 0 | H29: 0 | I29: 13 | J29: 5 | K29: 0 | L29: 1 | M29: 111 | N29: 0 | O29: =SUM(C29:L29,N29) -> 48 | P29: =SUM(C29:N29) -> 159
B30: 12.00 - 12.15 | C30: 11 | D30: 6 | E30: 6 | F30: 9 | G30: 0 | H30: 0 | I30: 10 | J30: 1 | K30: 1 | L30: 0 | M30: 110 | N30: 0 | O30: =SUM(C30:L30,N30) -> 44 | P30: =SUM(C30:N30) -> 154
B31: 12.15 - 12.30 | C31: 8 | D31: 8 | E31: 4 | F31: 6 | G31: 0 | H31: 0 | I31: 9 | J31: 0 | K31: 0 | L31: 0 | M31: 122 | N31: 0 | O31: =SUM(C31:L31,N31) -> 35 | P31: =SUM(C31:N31) -> 157
B32: 12.30 - 12.45 | C32: 7 | D32: 3 | E32: 4 | F32: 7 | G32: 0 | H32: 0 | I32: 11 | J32: 0 | K32: 1 | L32: 0 | M32: 87 | N32: 0 | O32: =SUM(C32:L32,N32) -> 33 | P32: =SUM(C32:N32) -> 120
B33: 12.45 - 13.00 | C33: 8 | D33: 9 | E33: 3 | F33: 11 | G33: 0 | H33: 0 | I33: 9 | J33: 0 | K33: 1 | L33: 2 | M33: 112 | N33: 0 | O33: =SUM(C33:L33,N33) -> 43 | P33: =SUM(C33:N33) -> 155
B34: 13.00 - 13.15 | C34: 10 | D34: 6 | E34: 3 | F34: 10 | G34: 2 | H34: 0 | I34: 6 | J34: 0 | K34: 0 | L34: 1 | M34: 97 | N34: 0 | O34: =SUM(C34:L34,N34) -> 38 | P34: =SUM(C34:N34) -> 135
B35: 13.15 - 13.30 | C35: 8 | D35: 10 | E35: 4 | F35: 8 | G35: 1 | H35: 0 | I35: 12 | J35: 3 | K35: 0 | L35: 2 | M35: 107 | N35: 0 | O35: =SUM(C35:L35,N35) -> 48 | P35: =SUM(C35:N35) -> 155
B36: 13.30 - 13.45 | C36: 12 | D36: 7 | E36: 1 | F36: 5 | G36: 0 | H36: 0 | I36: 6 | J36: 0 | K36: 1 | L36: 0 | M36: 91 | N36: 1 | O36: =SUM(C36:L36,N36) -> 33 | P36: =SUM(C36:N36) -> 124
B37: 13.45 - 14.00 | C37: 8 | D37: 12 | E37: 4 | F37: 8 | G37: 0 | H37: 0 | I37: 9 | J37: 1 | K37: 0 | L37: 1 | M37: 95 | N37: 0 | O37: =SUM(C37:L37,N37) -> 43 | P37: =SUM(C37:N37) -> 138
B38: 14.00 - 14.15 | C38: 9 | D38: 8 | E38: 5 | F38: 9 | G38: 0 | H38: 0 | I38: 12 | J38: 2 | K38: 0 | L38: 1 | M38: 67 | N38: 0 | O38: =SUM(C38:L38,N38) -> 46 | P38: =SUM(C38:N38) -> 113
B39: 14.15 - 14.30 | C39: 8 | D39: 5 | E39: 5 | F39: 9 | G39: 0 | H39: 0 | I39: 7 | J39: 1 | K39: 0 | L39: 0 | M39: 83 | N39: 0 | O39: =SUM(C39:L39,N39) -> 35 | P39: =SUM(C39:N39) -> 118
B40: 14.30 - 14.45 | C40: 12 | D40: 10 | E40: 6 | F40: 9 | G40: 0 | H40: 0 | I40: 5 | J40: 0 | K40: 0 | L40: 0 | M40: 90 | N40: 0 | O40: =SUM(C40:L40,N40) -> 42 | P40: =SUM(C40:N40) -> 132
... B57: 18.45 - 19.00 | C57: 13 | D57: 6 | E57: 5 | F57: 6 | G57: 1 | H57: 0 | I57: 7 | J57: 0 | K57: 0 | L57: 0 | M57: 120 | N57: 0 | O57: =SUM(C57:L57,N57) -> 38 | P57: =SUM(C57:N57) -> 158
B58: Totals | C58: =SUM(C10:C57) -> 493 | D58: =SUM(D10:D57) -> 324 | E58: =SUM(E10:E57) -> 172 | F58: =SUM(F10:F57) -> 370 | G58: =SUM(G10:G57) -> 35 | H58: =SUM(H10:H57) -> 2 | I58: =SUM(I10:I57) -> 373 | J58: =SUM(J10:J57) -> 68 | ... P58: =SUM(P10:P57) -> 6565
...

Sheet 30.10 KATOSI-MUKONO
B1: Consultancy services for Preparation of Expressway Development Master Plan (EDMP) for Uganda
B2: MANUAL CLASSIFIED COUNT (MCC)
B3: ROAD NAME: | C3: ='29.10-MUKONO-KATOSI'!C3:G3 -> MCC - C2 - STN077 - KATOSI ROAD
C5: Date | D5: 30.10.2019 | F5: Location | G5: ='29.10-MUKONO-KATOSI'!G5:H5 -> LUV GUEST HOUSE | J5: Surveyor | K5: MOSES
C6: Dir. From | D6: KATOSI | F6: Dir. To | G6: MUKONO | J6: Supervisor | K6: ='29.10-MUKONO-KATOSI'!K6:L6 -> VICTOR M
B8: Time / Veh Type | R8: SUMMARY TRAFFIC VOLUMES
C9: 1. Car | D9: 2. Station Wagon | E9: 3. Pickups | F9: 4. Minibus, matatu | G9: 5. Medium bus | H9: 6. Large Bus | I9: 7. Light Truck | J9: 8. Medium Truck | K9: 9. Heavy truck | L9: 10. Truck Trailer | M9: 11. Motor cycles | N9: 12. Tractors | O9: Total Excl M/Cycles | P9: Total All | R9: Time | S9: 1. Car | T9: 2. Station Wagon | U9: 3. Pickups | V9: 4. Minibus, matatu | W9: 5. Medium bus | X9: 6. Large Bus | Y9: 7. Light Truck | Z9: 8. Medium Truck | AA9: 9. Heavy truck | AB9: 10. Truck Trailer | AC9: 11. Motorcycles | AD9: 12. Tractors, Graders | AE9: Total Excl M/ Cycles | AF9: Total All
B10: 07.00 - 07.15 | C10: 4 | D10: 10 | E10: 0 | F10: 13 | G10: 0 | H10: 0 | I10: 2 | J10: 0 | K10: 0 | L10: 0 | M10: 210 | N10: 0 | O10: =SUM(C10:L10,N10) -> 29 | P10: =SUM(C10:N10) -> 239 | R10: 0700-0800 | S10: =SUM(C10:C13) -> 54 | T10: =SUM(D10:D13) -> 37 | U10: =SUM(E10:E13) -> 18 | V10: =SUM(F10:F13) -> 107 | W10: =SUM(G10:G13) -> 8 | X10: =SUM(H10:H13) -> 0 | Y10: =SUM(I10:I13) -> 51 | Z10: =SUM(J10:J13) -> 1 | ... AF10: =SUM(P10:P13) -> 970
B11: 07.15 - 07.30 | C11: 20 | D11: 15 | E11: 0 | F11: 42 | G11: 0 | H11: 0 | I11: 20 | J11: 0 | K11: 0 | L11: 0 | M11: 150 | N11: 0 | O11: =SUM(C11:L11,N11) -> 97 | P11: =SUM(C11:N11) -> 247 | R11: 0800-0900 | S11: =SUM(C14:C17) -> 46 | T11: =SUM(D14:D17) -> 25 | U11: =SUM(E14:E17) -> 10 | V11: =SUM(F14:F17) -> 23 | W11: =SUM(G14:G17) -> 11 | X11: =SUM(H14:H17) -> 0 | Y11: =SUM(I14:I17) -> 28 | Z11: =SUM(J14:J17) -> 0 | ... AF11: =SUM(P14:P17) -> 715
B12: 07.30 - 07.45 | C12: 10 | D12: 3 | E12: 9 | F12: 21 | G12: 0 | H12: 0 | I12: 24 | J12: 1 | K12: 0 | L12: 0 | M12: 120 | N12: 0 | O12: =SUM(C12:L12,N12) -> 68 | P12: =SUM(C12:N12) -> 188 | R12: 0900-1000 | S12: =SUM(C18:C21) -> 34 | T12: =SUM(D18:D21) -> 14 | U12: =SUM(E18:E21) -> 5 | V12: =SUM(F18:F21) -> 27 | W12: =SUM(G18:G21) -> 1 | X12: =SUM(H18:H21) -> 0 | Y12: =SUM(I18:I21) -> 13 | Z12: =SUM(J18:J21) -> 1 | ... AF12: =SUM(P18:P21) -> 837
B13: 07.45 - 08.00 | C13: 20 | D13: 9 | E13: 9 | F13: 31 | G13: 8 | H13: 0 | I13: 5 | J13: 0 | K13: 0 | L13: 0 | M13: 214 | N13: 0 | O13: =SUM(C13:L13,N13) -> 82 | P13: =SUM(C13:N13) -> 296 | R13: 1000-1100 | S13: =SUM(C22:C25) -> 32 | T13: =SUM(D22:D25) -> 12 | U13: =SUM(E22:E25) -> 4 | V13: =SUM(F22:F25) -> 28 | W13: =SUM(G22:G25) -> 2 | X13: =SUM(H22:H25) -> 0 | Y13: =SUM(I22:I25) -> 22 | Z13: =SUM(J22:J25) -> 7 | ... AF13: =SUM(P22:P25) -> 805
B14: 08.00 - 08.15 | C14: 21 | D14: 10 | E14: 4 | F14: 0 | G14: 3 | H14: 0 | I14: 12 | J14: 0 | K14: 0 | L14: 0 | M14: 166 | N14: 0 | O14: =SUM(C14:L14,N14) -> 50 | P14: =SUM(C14:N14) -> 216 | R14: 1100-1200 | S14: =SUM(C26:C29) -> 22 | T14: =SUM(D26:D29) -> 13 | U14: =SUM(E26:E29) -> 4 | V14: =SUM(F26:F29) -> 23 | W14: =SUM(G26:G29) -> 1 | X14: =SUM(H26:H29) -> 0 | Y14: =SUM(I26:I29) -> 19 | Z14: =SUM(J26:J29) -> 6 | ... AF14: =SUM(P26:P29) -> 823
B15: 08.15 - 08.30 | C15: 6 | D15: 4 | E15: 2 | F15: 10 | G15: 6 | H15: 0 | I15: 5 | J15: 0 | K15: 0 | L15: 0 | M15: 134 | N15: 0 | O15: =SUM(C15:L15,N15) -> 33 | P15: =SUM(C15:N15) -> 167 | R15: 1200-1300 | S15: =SUM(C30:C33) -> 22 | T15: =SUM(D30:D33) -> 17 | U15: =SUM(E30:E33) -> 10 | V15: =SUM(F30:F33) -> 18 | W15: =SUM(G30:G33) -> 4 | X15: =SUM(H30:H33) -> 0 | Y15: =SUM(I30:I33) -> 28 | Z15: =SUM(J30:J33) -> 2 | ... AF15: =SUM(P30:P33) -> 855
B16: 08.30 - 08.45 | C16: 13 | D16: 6 | E16: 1 | F16: 8 | G16: 0 | H16: 0 | I16: 5 | J16: 0 | K16: 0 | L16: 0 | M16: 146 | N16: 0 | O16: =SUM(C16:L16,N16) -> 33 | P16: =SUM(C16:N16) -> 179 | R16: 1300-1400 | S16: =SUM(C34:C37) -> 24 | T16: =SUM(D34:D37) -> 8 | U16: =SUM(E34:E37) -> 7 | V16: =SUM(F34:F37) -> 32 | W16: =SUM(G34:G37) -> 3 | X16: =SUM(H34:H37) -> 0 | Y16: =SUM(I34:I37) -> 33 | Z16: =SUM(J34:J37) -> 6 | ... AF16: =SUM(P34:P37) -> 898
B17: 08.45 - 9.00 | C17: 6 | D17: 5 | E17: 3 | F17: 5 | G17: 2 | H17: 0 | I17: 6 | J17: 0 | K17: 1 | L17: 0 | M17: 125 | N17: 0 | O17: =SUM(C17:L17,N17) -> 28 | P17: =SUM(C17:N17) -> 153 | R17: 1400-1500 | S17: =SUM(C38:C41) -> 33 | T17: =SUM(D38:D41) -> 15 | U17: =SUM(E38:E41) -> 8 | V17: =SUM(F38:F41) -> 35 | W17: =SUM(G38:G41) -> 0 | X17: =SUM(H38:H41) -> 1 | Y17: =SUM(I38:I41) -> 38 | Z17: =SUM(J38:J41) -> 3 | ... AF17: =SUM(P38:P41) -> 614
B18: 09.00 - 09.15 | C18: 12 | D18: 6 | E18: 0 | F18: 3 | G18: 0 | H18: 0 | I18: 0 | J18: 0 | K18: 0 | L18: 0 | M18: 135 | N18: 0 | O18: =SUM(C18:L18,N18) -> 21 | P18: =SUM(C18:N18) -> 156 | R18: 1500-1600 | S18: =SUM(C42:C45) -> 27 | T18: =SUM(D42:D45) -> 14 | U18: =SUM(E42:E45) -> 12 | V18: =SUM(F42:F45) -> 23 | W18: =SUM(G42:G45) -> 0 | X18: =SUM(H42:H45) -> 0 | Y18: =SUM(I42:I45) -> 24 | Z18: =SUM(J42:J45) -> 1 | ... AF18: =SUM(P42:P45) -> 642
B19: 09.15 - 09.30 | C19: 7 | D19: 4 | E19: 2 | F19: 8 | G19: 0 | H19: 0 | I19: 1 | J19: 1 | K19: 0 | L19: 0 | M19: 174 | N19: 0 | O19: =SUM(C19:L19,N19) -> 23 | P19: =SUM(C19:N19) -> 197 | R19: 1600-1700 | S19: =SUM(C46:C49) -> 35 | T19: =SUM(D46:D49) -> 19 | U19: =SUM(E46:E49) -> 12 | V19: =SUM(F46:F49) -> 34 | W19: =SUM(G46:G49) -> 7 | X19: =SUM(H46:H49) -> 0 | Y19: =SUM(I46:I49) -> 27 | Z19: =SUM(J46:J49) -> 2 | ... AF19: =SUM(P46:P49) -> 648
B20: 09.30 - 09.45 | C20: 5 | D20: 3 | E20: 0 | F20: 3 | G20: 0 | H20: 0 | I20: 4 | J20: 0 | K20: 1 | L20: 0 | M20: 321 | N20: 0 | O20: =SUM(C20:L20,N20) -> 16 | P20: =SUM(C20:N20) -> 337 | R20: 1700-1800 | S20: =SUM(C50:C53) -> 33 | T20: =SUM(D50:D53) -> 9 | U20: =SUM(E50:E53) -> 10 | V20: =SUM(F50:F53) -> 25 | W20: =SUM(G50:G53) -> 3 | X20: =SUM(H50:H53) -> 0 | Y20: =SUM(I50:I53) -> 15 | Z20: =SUM(J50:J53) -> 5 | ... AF20: =SUM(P50:P53) -> 588
B21: 09.45 - 10.00 | C21: 10 | D21: 1 | E21: 3 | F21: 13 | G21: 1 | H21: 0 | I21: 8 | J21: 0 | K21: 1 | L21: 0 | M21: 110 | N21: 0 | O21: =SUM(C21:L21,N21) -> 37 | P21: =SUM(C21:N21) -> 147 | R21: 1800-1900 | S21: =SUM(C54:C57) -> 38 | T21: =SUM(D54:D57) -> 19 | U21: =SUM(E54:E57) -> 11 | V21: =SUM(F54:F57) -> 16 | W21: =SUM(G54:G57) -> 0 | X21: =SUM(H54:H57) -> 0 | Y21: =SUM(I54:I57) -> 17 | Z21: =SUM(J54:J57) -> 5 | ... AF21: =SUM(P54:P57) -> 734
B22: 10.00 - 10.15 | C22: 8 | D22: 2 | E22: 0 | F22: 7 | G22: 1 | H22: 0 | I22: 4 | J22: 1 | K22: 0 | L22: 0 | M22: 130 | N22: 0 | O22: =SUM(C22:L22,N22) -> 23 | P22: =SUM(C22:N22) -> 153 | R22: AM Peak Hr | S22: =MAX(S10:S12) -> 54 | T22: =MAX(T10:T12) -> 37 | U22: =MAX(U10:U12) -> 18 | V22: =MAX(V10:V12) -> 107 | W22: =MAX(W10:W12) -> 11 | X22: =MAX(X10:X12) -> 0 | Y22: =MAX(Y10:Y12) -> 51 | Z22: =MAX(Z10:Z12) -> 1 | ... AF22: =MAX(AF10:AF12) -> 970
B23: 10.15 - 10.30 | C23: 5 | D23: 1 | E23: 1 | F23: 6 | G23: 0 | H23: 0 | I23: 9 | J23: 1 | K23: 0 | L23: 0 | M23: 183 | N23: 0 | O23: =SUM(C23:L23,N23) -> 23 | P23: =SUM(C23:N23) -> 206 | R23: IP Peak Hr | S23: =MAX(S13:S18) -> 33 | T23: =MAX(T13:T18) -> 17 | U23: =MAX(U13:U18) -> 12 | V23: =MAX(V13:V18) -> 35 | W23: =MAX(W13:W18) -> 4 | X23: =MAX(X13:X18) -> 1 | Y23: =MAX(Y13:Y18) -> 38 | Z23: =MAX(Z13:Z18) -> 7 | ... AF23: =MAX(AF13:AF18) -> 898
B24: 10.30 - 10.45 | C24: 7 | D24: 5 | E24: 0 | F24: 3 | G24: 0 | H24: 0 | I24: 3 | J24: 4 | K24: 0 | L24: 0 | M24: 203 | N24: 0 | O24: =SUM(C24:L24,N24) -> 22 | P24: =SUM(C24:N24) -> 225 | R24: PM Peak Hr | S24: =MAX(S19:S21) -> 38 | T24: =MAX(T19:T21) -> 19 | U24: =MAX(U19:U21) -> 12 | V24: =MAX(V19:V21) -> 34 | W24: =MAX(W19:W21) -> 7 | X24: =MAX(X19:X21) -> 0 | Y24: =MAX(Y19:Y21) -> 27 | Z24: =MAX(Z19:Z21) -> 5 | ... AF24: =MAX(AF19:AF21) -> 734
B25: 10.45 - 11.00 | C25: 12 | D25: 4 | E25: 3 | F25: 12 | G25: 1 | H25: 0 | I25: 6 | J25: 1 | K25: 0 | L25: 0 | M25: 182 | N25: 0 | O25: =SUM(C25:L25,N25) -> 39 | P25: =SUM(C25:N25) -> 221 | R25: AM Period | S25: =SUM(S10:S12) -> 134 | T25: =SUM(T10:T12) -> 76 | U25: =SUM(U10:U12) -> 33 | V25: =SUM(V10:V12) -> 157 | W25: =SUM(W10:W12) -> 20 | X25: =SUM(X10:X12) -> 0 | Y25: =SUM(Y10:Y12) -> 92 | Z25: =SUM(Z10:Z12) -> 2 | ... AF25: =SUM(AF10:AF12) -> 2522
B26: 11.00 - 11.15 | C26: 2 | D26: 2 | E26: 1 | F26: 7 | G26: 1 | H26: 0 | I26: 9 | J26: 1 | K26: 0 | L26: 1 | M26: 164 | N26: 0 | O26: =SUM(C26:L26,N26) -> 24 | P26: =SUM(C26:N26) -> 188 | R26: IP Period | S26: =SUM(S13:S18) -> 160 | T26: =SUM(T13:T18) -> 79 | U26: =SUM(U13:U18) -> 45 | V26: =SUM(V13:V18) -> 159 | W26: =SUM(W13:W18) -> 10 | X26: =SUM(X13:X18) -> 1 | Y26: =SUM(Y13:Y18) -> 164 | Z26: =SUM(Z13:Z18) -> 25 | ... AF26: =SUM(AF13:AF18) -> 4637
B27: 11.15 - 11.30 | C27: 8 | D27: 0 | E27: 1 | F27: 1 | G27: 0 | H27: 0 | I27: 1 | J27: 2 | K27: 0 | L27: 0 | M27: 183 | N27: 0 | O27: =SUM(C27:L27,N27) -> 13 | P27: =SUM(C27:N27) -> 196 | R27: PM Period | S27: =SUM(S19:S21) -> 106 | T27: =SUM(T19:T21) -> 47 | U27: =SUM(U19:U21) -> 33 | V27: =SUM(V19:V21) -> 75 | W27: =SUM(W19:W21) -> 10 | X27: =SUM(X19:X21) -> 0 | Y27: =SUM(Y19:Y21) -> 59 | Z27: =SUM(Z19:Z21) -> 12 | ... AF27: =SUM(AF19:AF21) -> 1970
B28: 11.30 - 11.45 | C28: 5 | D28: 4 | E28: 0 | F28: 6 | G28: 0 | H28: 0 | I28: 5 | J28: 2 | K28: 0 | L28: 0 | M28: 214 | N28: 0 | O28: =SUM(C28:L28,N28) -> 22 | P28: =SUM(C28:N28) -> 236 | R28: 12 Hours | S28: =SUM(S10:S21) -> 400 | T28: =SUM(T10:T21) -> 202 | U28: =SUM(U10:U21) -> 111 | V28: =SUM(V10:V21) -> 391 | W28: =SUM(W10:W21) -> 40 | X28: =SUM(X10:X21) -> 1 | Y28: =SUM(Y10:Y21) -> 315 | Z28: =SUM(Z10:Z21) -> 39 | ... AF28: =SUM(AF10:AF21) -> 9129
B29: 11.45 - 12.00 | C29: 7 | D29: 7 | E29: 2 | F29: 9 | G29: 0 | H29: 0 | I29: 4 | J29: 1 | K29: 2 | L29: 0 | M29: 171 | N29: 0 | O29: =SUM(C29:L29,N29) -> 32 | P29: =SUM(C29:N29) -> 203
B30: 12.00 - 12.15 | C30: 6 | D30: 2 | E30: 3 | F30: 6 | G30: 0 | H30: 0 | I30: 4 | J30: 0 | K30: 1 | L30: 0 | M30: 202 | N30: 0 | O30: =SUM(C30:L30,N30) -> 22 | P30: =SUM(C30:N30) -> 224
B31: 12.15 - 12.30 | C31: 4 | D31: 4 | E31: 0 | F31: 2 | G31: 2 | H31: 0 | I31: 2 | J31: 2 | K31: 0 | L31: 2 | M31: 181 | N31: 0 | O31: =SUM(C31:L31,N31) -> 18 | P31: =SUM(C31:N31) -> 199
B32: 12.30 - 12.45 | C32: 6 | D32: 8 | E32: 4 | F32: 5 | G32: 2 | H32: 0 | I32: 8 | J32: 0 | K32: 0 | L32: 0 | M32: 163 | N32: 0 | O32: =SUM(C32:L32,N32) -> 33 | P32: =SUM(C32:N32) -> 196
B33: 12.45 - 13.00 | C33: 6 | D33: 3 | E33: 3 | F33: 5 | G33: 0 | H33: 0 | I33: 14 | J33: 0 | K33: 1 | L33: 0 | M33: 204 | N33: 0 | O33: =SUM(C33:L33,N33) -> 32 | P33: =SUM(C33:N33) -> 236
B34: 13.00 - 13.15 | C34: 7 | D34: 0 | E34: 4 | F34: 10 | G34: 1 | H34: 0 | I34: 11 | J34: 3 | K34: 1 | L34: 1 | M34: 165 | N34: 0 | O34: =SUM(C34:L34,N34) -> 38 | P34: =SUM(C34:N34) -> 203
B35: 13.15 - 13.30 | C35: 6 | D35: 2 | E35: 3 | F35: 7 | G35: 2 | H35: 0 | I35: 8 | J35: 2 | K35: 0 | L35: 0 | M35: 220 | N35: 0 | O35: =SUM(C35:L35,N35) -> 30 | P35: =SUM(C35:N35) -> 250
B36: 13.30 - 13.45 | C36: 8 | D36: 3 | E36: 0 | F36: 8 | G36: 0 | H36: 0 | I36: 10 | J36: 1 | K36: 0 | L36: 0 | M36: 215 | N36: 0 | O36: =SUM(C36:L36,N36) -> 30 | P36: =SUM(C36:N36) -> 245
B37: 13.45 - 14.00 | C37: 3 | D37: 3 | E37: 0 | F37: 7 | G37: 0 | H37: 0 | I37: 4 | J37: 0 | K37: 0 | L37: 0 | M37: 183 | N37: 0 | O37: =SUM(C37:L37,N37) -> 17 | P37: =SUM(C37:N37) -> 200
B38: 14.00 - 14.15 | C38: 11 | D38: 4 | E38: 2 | F38: 9 | G38: 0 | H38: 0 | I38: 14 | J38: 1 | K38: 0 | L38: 2 | M38: 132 | N38: 0 | O38: =SUM(C38:L38,N38) -> 43 | P38: =SUM(C38:N38) -> 175
B39: 14.15 - 14.30 | C39: 3 | D39: 3 | E39: 2 | F39: 10 | G39: 0 | H39: 1 | I39: 8 | J39: 1 | K39: 0 | L39: 0 | M39: 104 | N39: 0 | O39: =SUM(C39:L39,N39) -> 28 | P39: =SUM(C39:N39) -> 132
B40: 14.30 - 14.45 | C40: 9 | D40: 4 | E40: 3 | F40: 9 | G40: 0 | H40: 0 | I40: 6 | J40: 1 | K40: 0 | L40: 0 | M40: 111 | N40: 0 | O40: =SUM(C40:L40,N40) -> 32 | P40: =SUM(C40:N40) -> 143
... B57: 18.45 - 19.00 | C57: 6 | D57: 5 | E57: 1 | F57: 2 | G57: 0 | H57: 0 | I57: 4 | J57: 0 | K57: 0 | L57: 0 | M57: 174 | N57: 0 | O57: =SUM(C57:L57,N57) -> 18 | P57: =SUM(C57:N57) -> 192
B58: Totals | C58: =SUM(C10:C57) -> 400 | D58: =SUM(D10:D57) -> 202 | E58: =SUM(E10:E57) -> 111 | F58: =SUM(F10:F57) -> 391 | G58: =SUM(G10:G57) -> 40 | H58: =SUM(H10:H57) -> 1 | I58: =SUM(I10:I57) -> 315 | J58: =SUM(J10:J57) -> 39 | ... P58: =SUM(P10:P57) -> 9129
...

Sheet 31.10 MUKONO-KATOSI
B1: Consultancy services for Preparation of Expressway Development Master Plan (EDMP) for Uganda
B2: MANUAL CLASSIFIED COUNT (MCC)
B3: ROAD NAME: | C3: ='29.10-MUKONO-KATOSI'!C3:G3 -> MCC - C2 - STN077 - KATOSI ROAD
C5: Date | D5: 31.10.2019 | F5: Location | G5: ='29.10-MUKONO-KATOSI'!G5:H5 -> LUV GUEST HOUSE | J5: Surveyor | K5: HAMUZA
C6: Dir. From | D6: ='29.10-MUKONO-KATOSI'!D6:E6 -> MUKONO | F6: Dir. To | G6: ='29.10-MUKONO-KATOSI'!G6:H6 -> KATOSI | J6: Supervisor | K6: ='29.10-MUKONO-KATOSI'!K6:L6 -> VICTOR M
B8: Time / Veh Type | R8: SUMMARY TRAFFIC VOLUMES
C9: 1. Car | D9: 2. Station Wagon | E9: 3. Pickups | F9: 4. Minibus, matatu | G9: 5. Medium bus | H9: 6. Large Bus | I9: 7. Light Truck | J9: 8. Medium Truck | K9: 9. Heavy truck | L9: 10. Truck Trailer | M9: 11. Motor cycles | N9: 12. Tractors | O9: Total Excl M/Cycles | P9: Total All | R9: Time | S9: 1. Car | T9: 2. Station Wagon | U9: 3. Pickups | V9: 4. Minibus, matatu | W9: 5. Medium bus | X9: 6. Large Bus | Y9: 7. Light Truck | Z9: 8. Medium Truck | AA9: 9. Heavy truck | AB9: 10. Truck Trailer | AC9: 11. Motorcycles | AD9: 12. Tractors, Graders | AE9: Total Excl M/ Cycles | AF9: Total All
B10: 07.00 - 07.15 | C10: 7 | D10: 4 | E10: 4 | F10: 7 | G10: 8 | H10: 4 | I10: 0 | J10: 6 | K10: 0 | L10: 1 | M10: 59 | N10: 0 | O10: =SUM(C10:L10,N10) -> 41 | P10: =SUM(C10:N10) -> 100 | R10: 0700-0800 | S10: =SUM(C10:C13) -> 99 | T10: =SUM(D10:D13) -> 17 | U10: =SUM(E10:E13) -> 19 | V10: =SUM(F10:F13) -> 21 | W10: =SUM(G10:G13) -> 10 | X10: =SUM(H10:H13) -> 4 | Y10: =SUM(I10:I13) -> 18 | Z10: =SUM(J10:J13) -> 12 | ... AF10: =SUM(P10:P13) -> 554
B11: 07.15 - 07.30 | C11: 68 | D11: 9 | E11: 4 | F11: 3 | G11: 2 | H11: 0 | I11: 6 | J11: 6 | K11: 0 | L11: 0 | M11: 92 | N11: 0 | O11: =SUM(C11:L11,N11) -> 98 | P11: =SUM(C11:N11) -> 190 | R11: 0800-0900 | S11: =SUM(C14:C17) -> 114 | T11: =SUM(D14:D17) -> 11 | U11: =SUM(E14:E17) -> 14 | V11: =SUM(F14:F17) -> 31 | W11: =SUM(G14:G17) -> 4 | X11: =SUM(H14:H17) -> 0 | Y11: =SUM(I14:I17) -> 30 | Z11: =SUM(J14:J17) -> 0 | ... AF11: =SUM(P14:P17) -> 553
B12: 07.30 - 07.45 | C12: 11 | D12: 1 | E12: 2 | F12: 0 | G12: 0 | H12: 0 | I12: 5 | J12: 0 | K12: 0 | L12: 3 | M12: 93 | N12: 0 | O12: =SUM(C12:L12,N12) -> 22 | P12: =SUM(C12:N12) -> 115 | R12: 0900-1000 | S12: =SUM(C18:C21) -> 108 | T12: =SUM(D18:D21) -> 14 | U12: =SUM(E18:E21) -> 22 | V12: =SUM(F18:F21) -> 27 | W12: =SUM(G18:G21) -> 1 | X12: =SUM(H18:H21) -> 0 | Y12: =SUM(I18:I21) -> 21 | Z12: =SUM(J18:J21) -> 10 | ... AF12: =SUM(P18:P21) -> 567
B13: 07.45 - 08.00 | C13: 13 | D13: 3 | E13: 9 | F13: 11 | G13: 0 | H13: 0 | I13: 7 | J13: 0 | K13: 0 | L13: 2 | M13: 104 | N13: 0 | O13: =SUM(C13:L13,N13) -> 45 | P13: =SUM(C13:N13) -> 149 | R13: 1000-1100 | S13: =SUM(C22:C25) -> 47 | T13: =SUM(D22:D25) -> 12 | U13: =SUM(E22:E25) -> 14 | V13: =SUM(F22:F25) -> 27 | W13: =SUM(G22:G25) -> 1 | X13: =SUM(H22:H25) -> 0 | Y13: =SUM(I22:I25) -> 33 | Z13: =SUM(J22:J25) -> 8 | ... AF13: =SUM(P22:P25) -> 416
B14: 08.00 - 08.15 | C14: 27 | D14: 4 | E14: 7 | F14: 17 | G14: 1 | H14: 0 | I14: 6 | J14: 0 | K14: 1 | L14: 2 | M14: 58 | N14: 0 | O14: =SUM(C14:L14,N14) -> 65 | P14: =SUM(C14:N14) -> 123 | R14: 1100-1200 | S14: =SUM(C26:C29) -> 73 | T14: =SUM(D26:D29) -> 8 | U14: =SUM(E26:E29) -> 18 | V14: =SUM(F26:F29) -> 32 | W14: =SUM(G26:G29) -> 1 | X14: =SUM(H26:H29) -> 0 | Y14: =SUM(I26:I29) -> 37 | Z14: =SUM(J26:J29) -> 6 | ... AF14: =SUM(P26:P29) -> 474
B15: 08.15 - 08.30 | C15: 37 | D15: 3 | E15: 4 | F15: 3 | G15: 1 | H15: 0 | I15: 9 | J15: 0 | K15: 0 | L15: 1 | M15: 103 | N15: 0 | O15: =SUM(C15:L15,N15) -> 58 | P15: =SUM(C15:N15) -> 161 | R15: 1200-1300 | S15: =SUM(C30:C33) -> 77 | T15: =SUM(D30:D33) -> 11 | U15: =SUM(E30:E33) -> 19 | V15: =SUM(F30:F33) -> 38 | W15: =SUM(G30:G33) -> 5 | X15: =SUM(H30:H33) -> 0 | Y15: =SUM(I30:I33) -> 23 | Z15: =SUM(J30:J33) -> 7 | ... AF15: =SUM(P30:P33) -> 521
B16: 08.30 - 08.45 | C16: 26 | D16: 0 | E16: 1 | F16: 2 | G16: 2 | H16: 0 | I16: 5 | J16: 0 | K16: 0 | L16: 3 | M16: 94 | N16: 0 | O16: =SUM(C16:L16,N16) -> 39 | P16: =SUM(C16:N16) -> 133 | R16: 1300-1400 | S16: =SUM(C34:C37) -> 76 | T16: =SUM(D34:D37) -> 10 | U16: =SUM(E34:E37) -> 17 | V16: =SUM(F34:F37) -> 21 | W16: =SUM(G34:G37) -> 3 | X16: =SUM(H34:H37) -> 0 | Y16: =SUM(I34:I37) -> 19 | Z16: =SUM(J34:J37) -> 8 | ... AF16: =SUM(P34:P37) -> 444
B17: 08.45 - 9.00 | C17: 24 | D17: 4 | E17: 2 | F17: 9 | G17: 0 | H17: 0 | I17: 10 | J17: 0 | K17: 0 | L17: 2 | M17: 84 | N17: 1 | O17: =SUM(C17:L17,N17) -> 52 | P17: =SUM(C17:N17) -> 136 | R17: 1400-1500 | S17: =SUM(C38:C41) -> 57 | T17: =SUM(D38:D41) -> 9 | U17: =SUM(E38:E41) -> 15 | V17: =SUM(F38:F41) -> 39 | W17: =SUM(G38:G41) -> 2 | X17: =SUM(H38:H41) -> 0 | Y17: =SUM(I38:I41) -> 20 | Z17: =SUM(J38:J41) -> 8 | ... AF17: =SUM(P38:P41) -> 298
B18: 09.00 - 09.15 | C18: 21 | D18: 3 | E18: 4 | F18: 7 | G18: 1 | H18: 0 | I18: 5 | J18: 4 | K18: 0 | L18: 0 | M18: 81 | N18: 0 | O18: =SUM(C18:L18,N18) -> 45 | P18: =SUM(C18:N18) -> 126 | R18: 1500-1600 | S18: =SUM(C42:C45) -> 61 | T18: =SUM(D42:D45) -> 4 | U18: =SUM(E42:E45) -> 18 | V18: =SUM(F42:F45) -> 24 | W18: =SUM(G42:G45) -> 0 | X18: =SUM(H42:H45) -> 0 | Y18: =SUM(I42:I45) -> 15 | Z18: =SUM(J42:J45) -> 4 | ... AF18: =SUM(P42:P45) -> 393
B19: 09.15 - 09.30 | C19: 28 | D19: 6 | E19: 7 | F19: 8 | G19: 0 | H19: 0 | I19: 3 | J19: 3 | K19: 1 | L19: 0 | M19: 86 | N19: 0 | O19: =SUM(C19:L19,N19) -> 56 | P19: =SUM(C19:N19) -> 142 | R19: 1600-1700 | S19: =SUM(C46:C49) -> 51 | T19: =SUM(D46:D49) -> 8 | U19: =SUM(E46:E49) -> 11 | V19: =SUM(F46:F49) -> 31 | W19: =SUM(G46:G49) -> 4 | X19: =SUM(H46:H49) -> 0 | Y19: =SUM(I46:I49) -> 19 | Z19: =SUM(J46:J49) -> 5 | ... AF19: =SUM(P46:P49) -> 508
B20: 09.30 - 09.45 | C20: 35 | D20: 2 | E20: 3 | F20: 4 | G20: 0 | H20: 0 | I20: 8 | J20: 2 | K20: 2 | L20: 1 | M20: 75 | N20: 0 | O20: =SUM(C20:L20,N20) -> 57 | P20: =SUM(C20:N20) -> 132 | R20: 1700-1800 | S20: =SUM(C50:C53) -> 72 | T20: =SUM(D50:D53) -> 6 | U20: =SUM(E50:E53) -> 13 | V20: =SUM(F50:F53) -> 36 | W20: =SUM(G50:G53) -> 3 | X20: =SUM(H50:H53) -> 0 | Y20: =SUM(I50:I53) -> 22 | Z20: =SUM(J50:J53) -> 4 | ... AF20: =SUM(P50:P53) -> 480
B21: 09.45 - 10.00 | C21: 24 | D21: 3 | E21: 8 | F21: 8 | G21: 0 | H21: 0 | I21: 5 | J21: 1 | K21: 0 | L21: 0 | M21: 118 | N21: 0 | O21: =SUM(C21:L21,N21) -> 49 | P21: =SUM(C21:N21) -> 167 | R21: 1800-1900 | S21: =SUM(C54:C57) -> 58 | T21: =SUM(D54:D57) -> 9 | U21: =SUM(E54:E57) -> 14 | V21: =SUM(F54:F57) -> 36 | W21: =SUM(G54:G57) -> 3 | X21: =SUM(H54:H57) -> 1 | Y21: =SUM(I54:I57) -> 19 | Z21: =SUM(J54:J57) -> 4 | ... AF21: =SUM(P54:P57) -> 496
B22: 10.00 - 10.15 | C22: 8 | D22: 3 | E22: 1 | F22: 6 | G22: 0 | H22: 0 | I22: 5 | J22: 3 | K22: 0 | L22: 0 | M22: 45 | N22: 0 | O22: =SUM(C22:L22,N22) -> 26 | P22: =SUM(C22:N22) -> 71 | R22: AM Peak Hr | S22: =MAX(S10:S12) -> 114 | T22: =MAX(T10:T12) -> 17 | U22: =MAX(U10:U12) -> 22 | V22: =MAX(V10:V12) -> 31 | W22: =MAX(W10:W12) -> 10 | X22: =MAX(X10:X12) -> 4 | Y22: =MAX(Y10:Y12) -> 30 | Z22: =MAX(Z10:Z12) -> 12 | ... AF22: =MAX(AF10:AF12) -> 567
B23: 10.15 - 10.30 | C23: 17 | D23: 1 | E23: 3 | F23: 10 | G23: 0 | H23: 0 | I23: 9 | J23: 2 | K23: 1 | L23: 1 | M23: 73 | N23: 0 | O23: =SUM(C23:L23,N23) -> 44 | P23: =SUM(C23:N23) -> 117 | R23: IP Peak Hr | S23: =MAX(S13:S18) -> 77 | T23: =MAX(T13:T18) -> 12 | U23: =MAX(U13:U18) -> 19 | V23: =MAX(V13:V18) -> 39 | W23: =MAX(W13:W18) -> 5 | X23: =MAX(X13:X18) -> 0 | Y23: =MAX(Y13:Y18) -> 37 | Z23: =MAX(Z13:Z18) -> 8 | ... AF23: =MAX(AF13:AF18) -> 521
B24: 10.30 - 10.45 | C24: 9 | D24: 5 | E24: 6 | F24: 4 | G24: 0 | H24: 0 | I24: 10 | J24: 1 | K24: 0 | L24: 0 | M24: 67 | N24: 0 | O24: =SUM(C24:L24,N24) -> 35 | P24: =SUM(C24:N24) -> 102 | R24: PM Peak Hr | S24: =MAX(S19:S21) -> 72 | T24: =MAX(T19:T21) -> 9 | U24: =MAX(U19:U21) -> 14 | V24: =MAX(V19:V21) -> 36 | W24: =MAX(W19:W21) -> 4 | X24: =MAX(X19:X21) -> 1 | Y24: =MAX(Y19:Y21) -> 22 | Z24: =MAX(Z19:Z21) -> 5 | ... AF24: =MAX(AF19:AF21) -> 508
B25: 10.45 - 11.00 | C25: 13 | D25: 3 | E25: 4 | F25: 7 | G25: 1 | H25: 0 | I25: 9 | J25: 2 | K25: 0 | L25: 0 | M25: 87 | N25: 0 | O25: =SUM(C25:L25,N25) -> 39 | P25: =SUM(C25:N25) -> 126 | R25: AM Period | S25: =SUM(S10:S12) -> 321 | T25: =SUM(T10:T12) -> 42 | U25: =SUM(U10:U12) -> 55 | V25: =SUM(V10:V12) -> 79 | W25: =SUM(W10:W12) -> 15 | X25: =SUM(X10:X12) -> 4 | Y25: =SUM(Y10:Y12) -> 69 | Z25: =SUM(Z10:Z12) -> 22 | ... AF25: =SUM(AF10:AF12) -> 1674
B26: 11.00 - 11.15 | C26: 11 | D26: 2 | E26: 6 | F26: 12 | G26: 0 | H26: 0 | I26: 6 | J26: 1 | K26: 1 | L26: 0 | M26: 64 | N26: 0 | O26: =SUM(C26:L26,N26) -> 39 | P26: =SUM(C26:N26) -> 103 | R26: IP Period | S26: =SUM(S13:S18) -> 391 | T26: =SUM(T13:T18) -> 54 | U26: =SUM(U13:U18) -> 101 | V26: =SUM(V13:V18) -> 181 | W26: =SUM(W13:W18) -> 12 | X26: =SUM(X13:X18) -> 0 | Y26: =SUM(Y13:Y18) -> 147 | Z26: =SUM(Z13:Z18) -> 41 | ... AF26: =SUM(AF13:AF18) -> 2546
B27: 11.15 - 11.30 | C27: 23 | D27: 1 | E27: 7 | F27: 11 | G27: 0 | H27: 0 | I27: 14 | J27: 1 | K27: 0 | L27: 1 | M27: 67 | N27: 0 | O27: =SUM(C27:L27,N27) -> 58 | P27: =SUM(C27:N27) -> 125 | R27: PM Period | S27: =SUM(S19:S21) -> 181 | T27: =SUM(T19:T21) -> 23 | U27: =SUM(U19:U21) -> 38 | V27: =SUM(V19:V21) -> 103 | W27: =SUM(W19:W21) -> 10 | X27: =SUM(X19:X21) -> 1 | Y27: =SUM(Y19:Y21) -> 60 | Z27: =SUM(Z19:Z21) -> 13 | ... AF27: =SUM(AF19:AF21) -> 1484
B28: 11.30 - 11.45 | C28: 16 | D28: 2 | E28: 1 | F28: 4 | G28: 0 | H28: 0 | I28: 9 | J28: 2 | K28: 0 | L28: 81 | M28: 0 | N28: 0 | O28: =SUM(C28:L28,N28) -> 115 | P28: =SUM(C28:N28) -> 115 | R28: 12 Hours | S28: =SUM(S10:S21) -> 893 | T28: =SUM(T10:T21) -> 119 | U28: =SUM(U10:U21) -> 194 | V28: =SUM(V10:V21) -> 363 | W28: =SUM(W10:W21) -> 37 | X28: =SUM(X10:X21) -> 5 | Y28: =SUM(Y10:Y21) -> 276 | Z28: =SUM(Z10:Z21) -> 76 | ... AF28: =SUM(AF10:AF21) -> 5704
B29: 11.45 - 12.00 | C29: 23 | D29: 3 | E29: 4 | F29: 5 | G29: 1 | H29: 0 | I29: 8 | J29: 2 | K29: 0 | L29: 0 | M29: 85 | N29: 0 | O29: =SUM(C29:L29,N29) -> 46 | P29: =SUM(C29:N29) -> 131
