Workbook

Sheet 1.10. Nakivubo-ShopriteC1 L1
B1: Traffic Impact Assessment for Kikapu project
B2: MANUAL CLASSIFIED COUNT (MCC)
B3: ROAD NAME: | C3: TURN C1-C2-C3
C5: Date | D5: 1.10.19 | E5: Location | F5: CLOCK TOWER JUNCTION | I5: Surveyor | J5: Babirye P,Muganga S,
C6: Dir. From | D6: NAKIVUBO | E6: Dir. To | F6: SHOPRITE | I6: Supervisor | J6: Lawrence
B8: Time / Veh Type | P8: SUMMARY TRAFFIC VOLUMES
C9: 1. Private Car | D9: 3. Pickups/four wheel drive | E9: 4. Minibus, matatu | F9: 5. Medium bus/ coaster | G9: 6. Large Bus/coach | H9: 7. Light Truck | I9: 8. Medium Truck | J9: 9. Heavy truck | K9: 10. Truck Trailer | L9: 11. Motor cycles | M9: Total Excl M/Cycles | N9: Total All | P9: Time | Q9: 1. Car | R9: 3. Pickups | S9: 4. Minibus, matatu | T9: 5. Medium bus | U9: 6. Large Bus | V9: 7. Light Truck | W9: 8. Medium Truck | X9: 9. Heavy truck | Y9: 10. Truck Trailer | Z9: 11. Motorcycles | AA9: Total Excl M/ Cycles | AB9: Total All
B10: 06.00 - 06.15 | C10: 67 | D10: 42 | E10: 32 | F10: 3 | G10: 0 | H10: 2 | I10: 0 | J10: 0 | K10: 0 | L10: 108 | M10: =SUM(C10:K10) -> 146 | N10: =SUM(C10:L10) -> 254 | P10: 06.00 - 06.15 | Q10: =SUM(C10:C13) -> 292 | R10: =SUM(D10:D13) -> 145 | S10: =SUM(E10:E13) -> 156 | T10: =SUM(F10:F13) -> 4 | U10: =SUM(G10:G13) -> 0 | V10: =SUM(H10:H13) -> 14 | W10: =SUM(I10:I13) -> 9 | X10: =SUM(J10:J13) -> 3 | ... AB10: =SUM(N10:N13) -> 1352
B11: 06.15 - 06.30 | C11: 60 | D11: 26 | E11: 43 | F11: 1 | G11: 0 | H11: 4 | I11: 7 | J11: 2 | K11: 0 | L11: 153 | M11: =SUM(C11:K11) -> 143 | N11: =SUM(C11:L11) -> 296 | P11: 0700-0800 | Q11: =SUM(C14:C17) -> 255 | R11: =SUM(D14:D17) -> 195 | S11: =SUM(E14:E17) -> 15 | T11: =SUM(F14:F17) -> 1 | U11: =SUM(G14:G17) -> 4 | V11: =SUM(H14:H17) -> 5 | W11: =SUM(I14:I17) -> 3 | X11: =SUM(J14:J17) -> 2 | ... AB11: =SUM(N14:N17) -> 1507
B12: 06.30 - 06.45 | C12: 60 | D12: 28 | E12: 24 | F12: 0 | G12: 0 | H12: 5 | I12: 1 | J12: 1 | K12: 0 | L12: 213 | M12: =SUM(C12:K12) -> 119 | N12: =SUM(C12:L12) -> 332 | P12: 0800-0900 | Q12: =SUM(C18:C21) -> 299 | R12: =SUM(D18:D21) -> 218 | S12: =SUM(E18:E21) -> 43 | T12: =SUM(F18:F21) -> 2 | U12: =SUM(G18:G21) -> 1 | V12: =SUM(H18:H21) -> 8 | W12: =SUM(I18:I21) -> 0 | X12: =SUM(J18:J21) -> 2 | ... AB12: =SUM(N18:N21) -> 1794
B13: 06.45 - 07.00 | C13: 105 | D13: 49 | E13: 57 | F13: 0 | G13: 0 | H13: 3 | I13: 1 | J13: 0 | K13: 0 | L13: 255 | M13: =SUM(C13:K13) -> 215 | N13: =SUM(C13:L13) -> 470 | P13: 0900-1000 | Q13: =SUM(C22:C25) -> 157 | R13: =SUM(D22:D25) -> 136 | S13: =SUM(E22:E25) -> 75 | T13: =SUM(F22:F25) -> 1 | U13: =SUM(G22:G25) -> 2 | V13: =SUM(H22:H25) -> 15 | W13: =SUM(I22:I25) -> 5 | X13: =SUM(J22:J25) -> 4 | ... AB13: =SUM(N22:N25) -> 1556
B14: 07.00 - 07.15 | C14: 75 | D14: 54 | E14: 6 | F14: 1 | G14: 1 | H14: 1 | I14: 0 | J14: 1 | K14: 0 | L14: 230 | M14: =SUM(C14:K14) -> 139 | N14: =SUM(C14:L14) -> 369 | P14: 1000-1100 | Q14: =SUM(C26:C29) -> 125 | R14: =SUM(D26:D29) -> 118 | S14: =SUM(E26:E29) -> 111 | T14: =SUM(F26:F29) -> 1 | U14: =SUM(G26:G29) -> 2 | V14: =SUM(H26:H29) -> 27 | W14: =SUM(I26:I29) -> 16 | X14: =SUM(J26:J29) -> 10 | ... AB14: =SUM(N26:N29) -> 1448
B15: 07.15 - 07.30 | C15: 66 | D15: 54 | E15: 1 | F15: 0 | G15: 0 | H15: 0 | I15: 2 | J15: 1 | K15: 0 | L15: 248 | M15: =SUM(C15:K15) -> 124 | N15: =SUM(C15:L15) -> 372 | P15: 1100-1200 | Q15: =SUM(C30:C33) -> 128 | R15: =SUM(D30:D33) -> 115 | S15: =SUM(E30:E33) -> 159 | T15: =SUM(F30:F33) -> 1 | U15: =SUM(G30:G33) -> 1 | V15: =SUM(H30:H33) -> 29 | W15: =SUM(I30:I33) -> 25 | X15: =SUM(J30:J33) -> 4 | ... AB15: =SUM(N30:N33) -> 1396
B16: 07.30 - 07.45 | C16: 45 | D16: 42 | E16: 2 | F16: 0 | G16: 2 | H16: 1 | I16: 1 | J16: 0 | K16: 0 | L16: 275 | M16: =SUM(C16:K16) -> 93 | N16: =SUM(C16:L16) -> 368 | P16: 1200-1300 | Q16: =SUM(C34:C37) -> 108 | R16: =SUM(D34:D37) -> 117 | S16: =SUM(E34:E37) -> 92 | T16: =SUM(F34:F37) -> 0 | U16: =SUM(G34:G37) -> 0 | V16: =SUM(H34:H37) -> 26 | W16: =SUM(I34:I37) -> 17 | X16: =SUM(J34:J37) -> 4 | ... AB16: =SUM(N34:N37) -> 1232
B17: 07.45 - 08.00 | C17: 69 | D17: 45 | E17: 6 | F17: 0 | G17: 1 | H17: 3 | I17: 0 | J17: 0 | K17: 1 | L17: 273 | M17: =SUM(C17:K17) -> 125 | N17: =SUM(C17:L17) -> 398 | P17: 1300-1400 | Q17: =SUM(C38:C41) -> 120 | R17: =SUM(D38:D41) -> 71 | S17: =SUM(E38:E41) -> 70 | T17: =SUM(F38:F41) -> 1 | U17: =SUM(G38:G41) -> 1 | V17: =SUM(H38:H41) -> 62 | W17: =SUM(I38:I41) -> 11 | X17: =SUM(J38:J41) -> 5 | ... AB17: =SUM(N38:N41) -> 1204
B18: 08.00 - 08.15 | C18: 111 | D18: 53 | E18: 25 | F18: 1 | G18: 0 | H18: 0 | I18: 0 | J18: 2 | K18: 0 | L18: 298 | M18: =SUM(C18:K18) -> 192 | N18: =SUM(C18:L18) -> 490 | P18: 1400-1500 | Q18: =SUM(C42:C45) -> 201 | R18: =SUM(D42:D45) -> 100 | S18: =SUM(E42:E45) -> 114 | T18: =SUM(F42:F45) -> 0 | U18: =SUM(G42:G45) -> 2 | V18: =SUM(H42:H45) -> 40 | W18: =SUM(I42:I45) -> 11 | X18: =SUM(J42:J45) -> 2 | ... AB18: =SUM(N42:N45) -> 1375
B19: 08.15 - 08.30 | C19: 66 | D19: 65 | E19: 7 | F19: 0 | G19: 0 | H19: 2 | I19: 0 | J19: 0 | K19: 0 | L19: 310 | M19: =SUM(C19:K19) -> 140 | N19: =SUM(C19:L19) -> 450 | P19: 1500-1600 | Q19: =SUM(C46:C49) -> 125 | R19: =SUM(D46:D49) -> 75 | S19: =SUM(E46:E49) -> 67 | T19: =SUM(F46:F49) -> 0 | U19: =SUM(G46:G49) -> 0 | V19: =SUM(H46:H49) -> 29 | W19: =SUM(I46:I49) -> 6 | X19: =SUM(J46:J49) -> 0 | ... AB19: =SUM(N46:N49) -> 787
B20: 08.30 - 08.45 | C20: 63 | D20: 54 | E20: 7 | F20: 0 | G20: 1 | H20: 3 | I20: 0 | J20: 0 | K20: 0 | L20: 285 | M20: =SUM(C20:K20) -> 128 | N20: =SUM(C20:L20) -> 413 | P20: 1600-1700 | Q20: =SUM(C50:C53) -> 158 | R20: =SUM(D50:D53) -> 85 | S20: =SUM(E50:E53) -> 127 | T20: =SUM(F50:F53) -> 0 | U20: =SUM(G50:G53) -> 2 | V20: =SUM(H50:H53) -> 31 | W20: =SUM(I50:I53) -> 9 | X20: =SUM(J50:J53) -> 2 | ... AB20: =SUM(N50:N53) -> 1377
B21: 08.45 - 9.00 | C21: 59 | D21: 46 | E21: 4 | F21: 1 | G21: 0 | H21: 3 | I21: 0 | J21: 0 | K21: 0 | L21: 328 | M21: =SUM(C21:K21) -> 113 | N21: =SUM(C21:L21) -> 441 | P21: 1700-1800 | Q21: =SUM(C54:C57) -> 130 | R21: =SUM(D54:D57) -> 66 | S21: =SUM(E54:E57) -> 112 | T21: =SUM(F54:F57) -> 5 | U21: =SUM(G54:G57) -> 0 | V21: =SUM(H54:H57) -> 32 | W21: =SUM(I54:I57) -> 10 | X21: =SUM(J54:J57) -> 1 | ... AB21: =SUM(N54:N57) -> 1422
B22: 09.00 - 09.15 | C22: 32 | D22: 39 | E22: 10 | F22: 1 | G22: 0 | H22: 2 | I22: 1 | J22: 1 | K22: 0 | L22: 233 | M22: =SUM(C22:K22) -> 86 | N22: =SUM(C22:L22) -> 319 | P22: 1800-1900 | Q22: =SUM(C58:C61) -> 81 | R22: =SUM(D58:D61) -> 42 | S22: =SUM(E58:E61) -> 92 | T22: =SUM(F58:F61) -> 3 | U22: =SUM(G58:G61) -> 6 | V22: =SUM(H58:H61) -> 17 | W22: =SUM(I58:I61) -> 5 | X22: =SUM(J58:J61) -> 1 | ... AB22: =SUM(N58:N61) -> 1189
B23: 09.15 - 09.30 | C23: 42 | D23: 32 | E23: 30 | F23: 0 | G23: 1 | H23: 3 | I23: 1 | J23: 0 | K23: 0 | L23: 310 | M23: =SUM(C23:K23) -> 109 | N23: =SUM(C23:L23) -> 419 | P23: 1900-2000 | Q23: =SUM(C62:C65) -> 107 | R23: =SUM(D62:D65) -> 61 | S23: =SUM(E62:E65) -> 115 | T23: =SUM(F62:F65) -> 4 | U23: =SUM(G62:G65) -> 3 | V23: =SUM(H62:H65) -> 18 | W23: =SUM(I62:I65) -> 7 | X23: =SUM(J62:J65) -> 3 | ... AB23: =SUM(N62:N65) -> 1377
B24: 09.30 - 09.45 | C24: 43 | D24: 25 | E24: 18 | F24: 0 | G24: 0 | H24: 8 | I24: 0 | J24: 2 | K24: 0 | L24: 338 | M24: =SUM(C24:K24) -> 96 | N24: =SUM(C24:L24) -> 434 | P24: 2000-2100 | Q24: =SUM(C66:C69) -> 88 | R24: =SUM(D66:D69) -> 51 | S24: =SUM(E66:E69) -> 152 | T24: =SUM(F66:F69) -> 3 | U24: =SUM(G66:G69) -> 0 | V24: =SUM(H66:H69) -> 19 | W24: =SUM(I66:I69) -> 4 | X24: =SUM(J66:J69) -> 2 | ... AB24: =SUM(N66:N69) -> 1202
B25: 09.45 - 10.00 | C25: 40 | D25: 40 | E25: 17 | F25: 0 | G25: 1 | H25: 2 | I25: 3 | J25: 1 | K25: 0 | L25: 280 | M25: =SUM(C25:K25) -> 104 | N25: =SUM(C25:L25) -> 384 | P25: 2100-2200 | Q25: =SUM(C70:C73) -> 98 | R25: =SUM(D70:D73) -> 72 | S25: =SUM(E70:E73) -> 121 | T25: =SUM(F70:F73) -> 3 | U25: =SUM(G70:G73) -> 0 | V25: =SUM(H70:H73) -> 18 | W25: =SUM(I70:I73) -> 2 | X25: =SUM(J70:J73) -> 1 | ... AB25: =SUM(N70:N73) -> 820
B26: 10.00 - 10.15 | C26: 32 | D26: 35 | E26: 35 | F26: 1 | G26: 1 | H26: 5 | I26: 4 | J26: 1 | K26: 0 | L26: 253 | M26: =SUM(C26:K26) -> 114 | N26: =SUM(C26:L26) -> 367 | P26: AM Peak Hr | Q26: =MAX(Q10:Q13) -> 299 | R26: =MAX(R10:R13) -> 218 | S26: =MAX(S10:S13) -> 156 | T26: =MAX(T10:T13) -> 4 | U26: =MAX(U10:U13) -> 4 | V26: =MAX(V10:V13) -> 15 | W26: =MAX(W10:W13) -> 9 | X26: =MAX(X10:X13) -> 4 | ... AB26: =MAX(AB10:AB13) -> 1794
B27: 10.15 - 10.30 | C27: 43 | D27: 39 | E27: 33 | F27: 0 | G27: 1 | H27: 5 | I27: 2 | J27: 0 | K27: 0 | L27: 250 | M27: =SUM(C27:K27) -> 123 | N27: =SUM(C27:L27) -> 373 | P27: IP Peak Hr | Q27: =MAX(Q14:Q19) -> 201 | R27: =MAX(R14:R19) -> 118 | S27: =MAX(S14:S19) -> 159 | T27: =MAX(T14:T19) -> 1 | U27: =MAX(U14:U19) -> 2 | V27: =MAX(V14:V19) -> 62 | W27: =MAX(W14:W19) -> 25 | X27: =MAX(X14:X19) -> 10 | ... AB27: =MAX(AB14:AB19) -> 1448
B28: 10.30 - 10.45 | C28: 20 | D28: 29 | E28: 23 | F28: 0 | G28: 0 | H28: 11 | I28: 6 | J28: 6 | K28: 0 | L28: 250 | M28: =SUM(C28:K28) -> 95 | N28: =SUM(C28:L28) -> 345 | P28: PM Peak Hr | Q28: =MAX(Q20:Q22) -> 158 | R28: =MAX(R20:R22) -> 85 | S28: =MAX(S20:S22) -> 127 | T28: =MAX(T20:T22) -> 5 | U28: =MAX(U20:U22) -> 6 | V28: =MAX(V20:V22) -> 32 | W28: =MAX(W20:W22) -> 10 | X28: =MAX(X20:X22) -> 2 | ... AB28: =MAX(AB20:AB22) -> 1422
B29: 10.45 - 11.00 | C29: 30 | D29: 15 | E29: 20 | F29: 0 | G29: 0 | H29: 6 | I29: 4 | J29: 3 | K29: 0 | L29: 285 | M29: =SUM(C29:K29) -> 78 | N29: =SUM(C29:L29) -> 363 | P29: AM Period | Q29: =SUM(Q10:Q13) -> 1003 | R29: =SUM(R10:R13) -> 694 | S29: =SUM(S10:S13) -> 289 | T29: =SUM(T10:T13) -> 8 | U29: =SUM(U10:U13) -> 7 | V29: =SUM(V10:V13) -> 42 | W29: =SUM(W10:W13) -> 17 | X29: =SUM(X10:X13) -> 11 | ... AB29: =SUM(AB10:AB13) -> 6209
B30: 11.00 - 11.15 | C30: 32 | D30: 19 | E30: 50 | F30: 0 | G30: 0 | H30: 5 | I30: 5 | J30: 0 | K30: 0 | L30: 253 | M30: =SUM(C30:K30) -> 111 | N30: =SUM(C30:L30) -> 364 | P30: IP Period | Q30: =SUM(Q14:Q19) -> 807 | R30: =SUM(R14:R19) -> 596 | S30: =SUM(S14:S19) -> 613 | T30: =SUM(T14:T19) -> 3 | U30: =SUM(U14:U19) -> 6 | V30: =SUM(V14:V19) -> 213 | W30: =SUM(W14:W19) -> 86 | X30: =SUM(X14:X19) -> 25 | ... AB30: =SUM(AB14:AB19) -> 7442
B31: 11.15 - 11.30 | C31: 37 | D31: 27 | E31: 30 | F31: 0 | G31: 1 | H31: 2 | I31: 4 | J31: 0 | K31: 0 | L31: 248 | M31: =SUM(C31:K31) -> 101 | N31: =SUM(C31:L31) -> 349 | P31: PM Period | Q31: =SUM(Q20:Q22) -> 369 | R31: =SUM(R20:R22) -> 193 | S31: =SUM(S20:S22) -> 331 | T31: =SUM(T20:T22) -> 8 | U31: =SUM(U20:U22) -> 8 | V31: =SUM(V20:V22) -> 80 | W31: =SUM(W20:W22) -> 24 | X31: =SUM(X20:X22) -> 4 | ... AB31: =SUM(AB20:AB22) -> 3988
B32: 11.30 - 11.45 | C32: 30 | D32: 46 | E32: 43 | F32: 0 | G32: 0 | H32: 14 | I32: 10 | J32: 2 | K32: 0 | L32: 185 | M32: =SUM(C32:K32) -> 145 | N32: =SUM(C32:L32) -> 330 | P32: 12 Hours | Q32: =SUM(Q11:Q22) -> 1887 | R32: =SUM(R11:R22) -> 1338 | S32: =SUM(S11:S22) -> 1077 | T32: =SUM(T11:T22) -> 15 | U32: =SUM(U11:U22) -> 21 | V32: =SUM(V11:V22) -> 321 | W32: =SUM(W11:W22) -> 118 | X32: =SUM(X11:X22) -> 37 | ... AB32: =SUM(AB11:AB22) -> 16287
B33: 11.45 - 12.00 | C33: 29 | D33: 23 | E33: 36 | F33: 1 | G33: 0 | H33: 8 | I33: 6 | J33: 2 | K33: 0 | L33: 248 | M33: =SUM(C33:K33) -> 105 | N33: =SUM(C33:L33) -> 353 | P33: 16 Hrs/ADT | Q33: =SUM(Q10:Q25) -> 2472 | R33: =SUM(R10:R25) -> 1667 | S33: =SUM(S10:S25) -> 1621 | T33: =SUM(T10:T25) -> 29 | U33: =SUM(U10:U25) -> 24 | V33: =SUM(V10:V25) -> 390 | W33: =SUM(W10:W25) -> 140 | X33: =SUM(X10:X25) -> 46 | ... AB33: =SUM(AB10:AB25) -> 21038
B34: 12.00 - 12.15 | C34: 31 | D34: 27 | E34: 13 | F34: 0 | G34: 0 | H34: 4 | I34: 4 | J34: 2 | K34: 0 | L34: 250 | M34: =SUM(C34:K34) -> 81 | N34: =SUM(C34:L34) -> 331 | P34: NEF | Q34: =Q33/Q32 -> 1.3100159 | R34: =R33/R32 -> 1.2458894 | S34: =S33/S32 -> 1.5051068 | T34: =T33/T32 -> 1.9333333 | U34: =U33/U32 -> 1.1428571 | V34: =V33/V32 -> 1.2149533 | W34: =W33/W32 -> 1.1864407 | X34: =X33/X32 -> 1.2432432 | ... AB34: =AB33/AB32 -> 1.291705
B35: 12.15 - 12.30 | C35: 27 | D35: 30 | E35: 23 | F35: 0 | G35: 0 | H35: 8 | I35: 7 | J35: 1 | K35: 0 | L35: 210 | M35: =SUM(C35:K35) -> 96 | N35: =SUM(C35:L35) -> 306
B36: 12.30 - 12.45 | C36: 20 | D36: 29 | E36: 31 | F36: 0 | G36: 0 | H36: 9 | I36: 5 | J36: 1 | K36: 0 | L36: 205 | M36: =SUM(C36:K36) -> 95 | N36: =SUM(C36:L36) -> 300
B37: 12.45 - 13.00 | C37: 30 | D37: 31 | E37: 25 | F37: 0 | G37: 0 | H37: 5 | I37: 1 | J37: 0 | K37: 0 | L37: 203 | M37: =SUM(C37:K37) -> 92 | N37: =SUM(C37:L37) -> 295
B38: 13.00 - 13.15 | C38: 32 | D38: 22 | E38: 17 | F38: 1 | G38: 1 | H38: 9 | I38: 3 | J38: 0 | K38: 0 | L38: 185 | M38: =SUM(C38:K38) -> 85 | N38: =SUM(C38:L38) -> 270
B39: 13.15 - 13.30 | C39: 19 | D39: 13 | E39: 19 | F39: 0 | G39: 0 | H39: 29 | I39: 2 | J39: 1 | K39: 0 | L39: 218 | M39: =SUM(C39:K39) -> 83 | N39: =SUM(C39:L39) -> 301
B40: 13.30 - 13.45 | C40: 29 | D40: 13 | E40: 13 | F40: 0 | G40: 0 | H40: 14 | I40: 3 | J40: 3 | K40: 0 | L40: 240 | M40: =SUM(C40:K40) -> 75 | N40: =SUM(C40:L40) -> 315
B41: 13.45 - 14.00 | C41: 40 | D41: 23 | E41: 21 | F41: 0 | G41: 0 | H41: 10 | I41: 3 | J41: 1 | K41: 0 | L41: 220 | M41: =SUM(C41:K41) -> 98 | N41: =SUM(C41:L41) -> 318
B42: 14.00 - 14.15 | C42: 23 | D42: 17 | E42: 14 | F42: 0 | G42: 0 | H42: 6 | I42: 2 | J42: 0 | K42: 0 | L42: 110 | M42: =SUM(C42:K42) -> 62 | N42: =SUM(C42:L42) -> 172
...

Sheet 2.10.Nakivubo-ShopriteC1 L1
B1: Traffic Impact Assessment for Kikapu project
B2: MANUAL CLASSIFIED COUNT (MCC)
B3: ROAD NAME: | C3: SHOPRITE-QUEENSWAY
C5: Date | D5: 2.10.19 | E5: Location | F5: CLOCK TOWER JUNCTION | I5: Surveyor | J5: Jerome
C6: Dir. From | D6: NAKIVUBO | E6: Dir. To | F6: SHOPRITE | I6: Supervisor | J6: Lawrence
B8: Time / Veh Type | P8: SUMMARY TRAFFIC VOLUMES
C9: 1. Private Car | D9: 3. Pickups/four wheel drive | E9: 4. Minibus, matatu | F9: 5. Medium bus/ coaster | G9: 6. Large Bus/coach | H9: 7. Light Truck | I9: 8. Medium Truck | J9: 9. Heavy truck | K9: 10. Truck Trailer | L9: 11. Motor cycles | M9: Total Excl M/Cycles | N9: Total All | P9: Time | Q9: 1. Car | R9: 3. Pickups | S9: 4. Minibus, matatu | T9: 5. Medium bus | U9: 6. Large Bus | V9: 7. Light Truck | W9: 8. Medium Truck | X9: 9. Heavy truck | Y9: 10. Truck Trailer | Z9: 11. Motorcycles | AA9: Total Excl M/ Cycles | AB9: Total All
B10: 06.00 - 06.15 | C10: 15 | D10: 8 | E10: 40 | F10: 0 | G10: 0 | H10: 0 | I10: 0 | J10: 0 | K10: 0 | L10: 35 | M10: =SUM(C10:K10) -> 63 | N10: =SUM(C10:L10) -> 98 | P10: 06.00 - 06.15 | Q10: =SUM(C10:C13) -> 100 | R10: =SUM(D10:D13) -> 80 | S10: =SUM(E10:E13) -> 272 | T10: =SUM(F10:F13) -> 4 | U10: =SUM(G10:G13) -> 1 | V10: =SUM(H10:H13) -> 4 | W10: =SUM(I10:I13) -> 3 | X10: =SUM(J10:J13) -> 1 | ... AB10: =SUM(N10:N13) -> 965
B11: 06.15 - 06.30 | C11: 13 | D11: 9 | E11: 44 | F11: 2 | G11: 1 | H11: 1 | I11: 1 | J11: 1 | K11: 0 | L11: 89 | M11: =SUM(C11:K11) -> 72 | N11: =SUM(C11:L11) -> 161 | P11: 0700-0800 | Q11: =SUM(C14:C17) -> 174 | R11: =SUM(D14:D17) -> 191 | S11: =SUM(E14:E17) -> 274 | T11: =SUM(F14:F17) -> 4 | U11: =SUM(G14:G17) -> 3 | V11: =SUM(H14:H17) -> 21 | W11: =SUM(I14:I17) -> 10 | X11: =SUM(J14:J17) -> 5 | ... AB11: =SUM(N14:N17) -> 1886
B12: 06.30 - 06.45 | C12: 41 | D12: 23 | E12: 106 | F12: 2 | G12: 0 | H12: 1 | I12: 2 | J12: 0 | K12: 1 | L12: 150 | M12: =SUM(C12:K12) -> 176 | N12: =SUM(C12:L12) -> 326 | P12: 0800-0900 | Q12: =SUM(C18:C21) -> 152 | R12: =SUM(D18:D21) -> 139 | S12: =SUM(E18:E21) -> 232 | T12: =SUM(F18:F21) -> 9 | U12: =SUM(G18:G21) -> 0 | V12: =SUM(H18:H21) -> 15 | W12: =SUM(I18:I21) -> 12 | X12: =SUM(J18:J21) -> 10 | ... AB12: =SUM(N18:N21) -> 2017
B13: 06.45 - 07.00 | C13: 31 | D13: 40 | E13: 82 | F13: 0 | G13: 0 | H13: 2 | I13: 0 | J13: 0 | K13: 0 | L13: 225 | M13: =SUM(C13:K13) -> 155 | N13: =SUM(C13:L13) -> 380 | P13: 0900-1000 | Q13: =SUM(C22:C25) -> 156 | R13: =SUM(D22:D25) -> 111 | S13: =SUM(E22:E25) -> 293 | T13: =SUM(F22:F25) -> 3 | U13: =SUM(G22:G25) -> 2 | V13: =SUM(H22:H25) -> 16 | W13: =SUM(I22:I25) -> 12 | X13: =SUM(J22:J25) -> 8 | ... AB13: =SUM(N22:N25) -> 1780
B14: 07.00 - 07.15 | C14: 35 | D14: 40 | E14: 68 | F14: 0 | G14: 0 | H14: 4 | I14: 2 | J14: 0 | K14: 0 | L14: 205 | M14: =SUM(C14:K14) -> 149 | N14: =SUM(C14:L14) -> 354 | P14: 1000-1100 | Q14: =SUM(C26:C29) -> 97 | R14: =SUM(D26:D29) -> 77 | S14: =SUM(E26:E29) -> 304 | T14: =SUM(F26:F29) -> 0 | U14: =SUM(G26:G29) -> 1 | V14: =SUM(H26:H29) -> 17 | W14: =SUM(I26:I29) -> 12 | X14: =SUM(J26:J29) -> 9 | ... AB14: =SUM(N26:N29) -> 1701
B15: 07.15 - 07.30 | C15: 51 | D15: 48 | E15: 61 | F15: 2 | G15: 2 | H15: 3 | I15: 1 | J15: 2 | K15: 0 | L15: 275 | M15: =SUM(C15:K15) -> 170 | N15: =SUM(C15:L15) -> 445 | P15: 1100-1200 | Q15: =SUM(C30:C33) -> 69 | R15: =SUM(D30:D33) -> 71 | S15: =SUM(E30:E33) -> 311 | T15: =SUM(F30:F33) -> 1 | U15: =SUM(G30:G33) -> 0 | V15: =SUM(H30:H33) -> 16 | W15: =SUM(I30:I33) -> 18 | X15: =SUM(J30:J33) -> 7 | ... AB15: =SUM(N30:N33) -> 1667
B16: 07.30 - 07.45 | C16: 38 | D16: 50 | E16: 80 | F16: 1 | G16: 1 | H16: 3 | I16: 1 | J16: 1 | K16: 0 | L16: 348 | M16: =SUM(C16:K16) -> 175 | N16: =SUM(C16:L16) -> 523 | P16: 1200-1300 | Q16: =SUM(C34:C37) -> 54 | R16: =SUM(D34:D37) -> 77 | S16: =SUM(E34:E37) -> 265 | T16: =SUM(F34:F37) -> 1 | U16: =SUM(G34:G37) -> 1 | V16: =SUM(H34:H37) -> 14 | W16: =SUM(I34:I37) -> 10 | X16: =SUM(J34:J37) -> 14 | ... AB16: =SUM(N34:N37) -> 1850
B17: 07.45 - 08.00 | C17: 50 | D17: 53 | E17: 65 | F17: 1 | G17: 0 | H17: 11 | I17: 6 | J17: 2 | K17: 1 | L17: 375 | M17: =SUM(C17:K17) -> 189 | N17: =SUM(C17:L17) -> 564 | P17: 1300-1400 | Q17: =SUM(C38:C41) -> 62 | R17: =SUM(D38:D41) -> 75 | S17: =SUM(E38:E41) -> 251 | T17: =SUM(F38:F41) -> 1 | U17: =SUM(G38:G41) -> 0 | V17: =SUM(H38:H41) -> 22 | W17: =SUM(I38:I41) -> 19 | X17: =SUM(J38:J41) -> 9 | ... AB17: =SUM(N38:N41) -> 1780
B18: 08.00 - 08.15 | C18: 34 | D18: 40 | E18: 41 | F18: 1 | G18: 0 | H18: 6 | I18: 1 | J18: 2 | K18: 0 | L18: 325 | M18: =SUM(C18:K18) -> 125 | N18: =SUM(C18:L18) -> 450 | P18: 1400-1500 | Q18: =SUM(C42:C45) -> 98 | R18: =SUM(D42:D45) -> 79 | S18: =SUM(E42:E45) -> 280 | T18: =SUM(F42:F45) -> 4 | U18: =SUM(G42:G45) -> 0 | V18: =SUM(H42:H45) -> 21 | W18: =SUM(I42:I45) -> 5 | X18: =SUM(J42:J45) -> 3 | ... AB18: =SUM(N42:N45) -> 1849
B19: 08.15 - 08.30 | C19: 52 | D19: 30 | E19: 73 | F19: 2 | G19: 0 | H19: 3 | I19: 3 | J19: 3 | K19: 0 | L19: 360 | M19: =SUM(C19:K19) -> 166 | N19: =SUM(C19:L19) -> 526 | P19: 1500-1600 | Q19: =SUM(C46:C49) -> 127 | R19: =SUM(D46:D49) -> 97 | S19: =SUM(E46:E49) -> 409 | T19: =SUM(F46:F49) -> 1 | U19: =SUM(G46:G49) -> 0 | V19: =SUM(H46:H49) -> 22 | W19: =SUM(I46:I49) -> 5 | X19: =SUM(J46:J49) -> 1 | ... AB19: =SUM(N46:N49) -> 2114
B20: 08.30 - 08.45 | C20: 35 | D20: 46 | E20: 68 | F20: 2 | G20: 0 | H20: 3 | I20: 4 | J20: 0 | K20: 0 | L20: 380 | M20: =SUM(C20:K20) -> 158 | N20: =SUM(C20:L20) -> 538 | P20: 1600-1700 | Q20: =SUM(C50:C53) -> 62 | R20: =SUM(D50:D53) -> 59 | S20: =SUM(E50:E53) -> 295 | T20: =SUM(F50:F53) -> 0 | U20: =SUM(G50:G53) -> 0 | V20: =SUM(H50:H53) -> 17 | W20: =SUM(I50:I53) -> 6 | X20: =SUM(J50:J53) -> 1 | ... AB20: =SUM(N50:N53) -> 1743
B21: 08.45 - 9.00 | C21: 31 | D21: 23 | E21: 50 | F21: 4 | G21: 0 | H21: 3 | I21: 4 | J21: 5 | K21: 0 | L21: 383 | M21: =SUM(C21:K21) -> 120 | N21: =SUM(C21:L21) -> 503 | P21: 1700-1800 | Q21: =SUM(C54:C57) -> 44 | R21: =SUM(D54:D57) -> 48 | S21: =SUM(E54:E57) -> 222 | T21: =SUM(F54:F57) -> 0 | U21: =SUM(G54:G57) -> 1 | V21: =SUM(H54:H57) -> 19 | W21: =SUM(I54:I57) -> 5 | X21: =SUM(J54:J57) -> 1 | ... AB21: =SUM(N54:N57) -> 1543
B22: 09.00 - 09.15 | C22: 39 | D22: 16 | E22: 72 | F22: 2 | G22: 0 | H22: 4 | I22: 1 | J22: 3 | K22: 0 | L22: 310 | M22: =SUM(C22:K22) -> 137 | N22: =SUM(C22:L22) -> 447 | P22: 1800-1900 | Q22: =SUM(C58:C61) -> 37 | R22: =SUM(D58:D61) -> 39 | S22: =SUM(E58:E61) -> 311 | T22: =SUM(F58:F61) -> 4 | U22: =SUM(G58:G61) -> 3 | V22: =SUM(H58:H61) -> 7 | W22: =SUM(I58:I61) -> 0 | X22: =SUM(J58:J61) -> 2 | ... AB22: =SUM(N58:N61) -> 1672
B23: 09.15 - 09.30 | C23: 46 | D23: 37 | E23: 65 | F23: 0 | G23: 0 | H23: 5 | I23: 3 | J23: 3 | K23: 0 | L23: 353 | M23: =SUM(C23:K23) -> 159 | N23: =SUM(C23:L23) -> 512 | P23: 1900-2000 | Q23: =SUM(C62:C65) -> 32 | R23: =SUM(D62:D65) -> 26 | S23: =SUM(E62:E65) -> 181 | T23: =SUM(F62:F65) -> 2 | U23: =SUM(G62:G65) -> 0 | V23: =SUM(H62:H65) -> 10 | W23: =SUM(I62:I65) -> 0 | X23: =SUM(J62:J65) -> 0 | ... AB23: =SUM(N62:N65) -> 1679
B24: 09.30 - 09.45 | C24: 46 | D24: 26 | E24: 73 | F24: 0 | G24: 1 | H24: 3 | I24: 4 | J24: 0 | K24: 0 | L24: 268 | M24: =SUM(C24:K24) -> 153 | N24: =SUM(C24:L24) -> 421 | P24: 2000-2100 | Q24: =SUM(C66:C69) -> 42 | R24: =SUM(D66:D69) -> 28 | S24: =SUM(E66:E69) -> 303 | T24: =SUM(F66:F69) -> 5 | U24: =SUM(G66:G69) -> 1 | V24: =SUM(H66:H69) -> 3 | W24: =SUM(I66:I69) -> 7 | X24: =SUM(J66:J69) -> 2 | ... AB24: =SUM(N66:N69) -> 1718
B25: 09.45 - 10.00 | C25: 25 | D25: 32 | E25: 83 | F25: 1 | G25: 1 | H25: 4 | I25: 4 | J25: 2 | K25: 0 | L25: 248 | M25: =SUM(C25:K25) -> 152 | N25: =SUM(C25:L25) -> 400 | P25: 2100-2200 | Q25: =SUM(C70:C73) -> 38 | R25: =SUM(D70:D73) -> 28 | S25: =SUM(E70:E73) -> 217 | T25: =SUM(F70:F73) -> 2 | U25: =SUM(G70:G73) -> 0 | V25: =SUM(H70:H73) -> 8 | W25: =SUM(I70:I73) -> 6 | X25: =SUM(J70:J73) -> 2 | ... AB25: =SUM(N70:N73) -> 800
B26: 10.00 - 10.15 | C26: 24 | D26: 15 | E26: 68 | F26: 0 | G26: 0 | H26: 2 | I26: 3 | J26: 2 | K26: 0 | L26: 263 | M26: =SUM(C26:K26) -> 114 | N26: =SUM(C26:L26) -> 377 | P26: AM Peak Hr | Q26: =MAX(Q10:Q13) -> 174 | R26: =MAX(R10:R13) -> 191 | S26: =MAX(S10:S13) -> 293 | T26: =MAX(T10:T13) -> 9 | U26: =MAX(U10:U13) -> 3 | V26: =MAX(V10:V13) -> 21 | W26: =MAX(W10:W13) -> 12 | X26: =MAX(X10:X13) -> 10 | ... AB26: =MAX(AB10:AB13) -> 2017
B27: 10.15 - 10.30 | C27: 30 | D27: 20 | E27: 85 | F27: 0 | G27: 1 | H27: 5 | I27: 4 | J27: 5 | K27: 0 | L27: 308 | M27: =SUM(C27:K27) -> 150 | N27: =SUM(C27:L27) -> 458 | P27: IP Peak Hr | Q27: =MAX(Q14:Q19) -> 127 | R27: =MAX(R14:R19) -> 97 | S27: =MAX(S14:S19) -> 409 | T27: =MAX(T14:T19) -> 4 | U27: =MAX(U14:U19) -> 1 | V27: =MAX(V14:V19) -> 22 | W27: =MAX(W14:W19) -> 19 | X27: =MAX(X14:X19) -> 14 | ... AB27: =MAX(AB14:AB19) -> 2114
B28: 10.30 - 10.45 | C28: 31 | D28: 23 | E28: 83 | F28: 0 | G28: 0 | H28: 5 | I28: 3 | J28: 1 | K28: 0 | L28: 318 | M28: =SUM(C28:K28) -> 146 | N28: =SUM(C28:L28) -> 464 | P28: PM Peak Hr | Q28: =MAX(Q20:Q22) -> 62 | R28: =MAX(R20:R22) -> 59 | S28: =MAX(S20:S22) -> 311 | T28: =MAX(T20:T22) -> 4 | U28: =MAX(U20:U22) -> 3 | V28: =MAX(V20:V22) -> 19 | W28: =MAX(W20:W22) -> 6 | X28: =MAX(X20:X22) -> 2 | ... AB28: =MAX(AB20:AB22) -> 1743
B29: 10.45 - 11.00 | C29: 12 | D29: 19 | E29: 68 | F29: 0 | G29: 0 | H29: 5 | I29: 2 | J29: 1 | K29: 0 | L29: 295 | M29: =SUM(C29:K29) -> 107 | N29: =SUM(C29:L29) -> 402 | P29: AM Period | Q29: =SUM(Q10:Q13) -> 582 | R29: =SUM(R10:R13) -> 521 | S29: =SUM(S10:S13) -> 1071 | T29: =SUM(T10:T13) -> 20 | U29: =SUM(U10:U13) -> 6 | V29: =SUM(V10:V13) -> 56 | W29: =SUM(W10:W13) -> 37 | X29: =SUM(X10:X13) -> 24 | ... AB29: =SUM(AB10:AB13) -> 6648
B30: 11.00 - 11.15 | C30: 26 | D30: 30 | E30: 85 | F30: 0 | G30: 0 | H30: 7 | I30: 6 | J30: 4 | K30: 1 | L30: 250 | M30: =SUM(C30:K30) -> 159 | N30: =SUM(C30:L30) -> 409 | P30: IP Period | Q30: =SUM(Q14:Q19) -> 507 | R30: =SUM(R14:R19) -> 476 | S30: =SUM(S14:S19) -> 1820 | T30: =SUM(T14:T19) -> 8 | U30: =SUM(U14:U19) -> 2 | V30: =SUM(V14:V19) -> 112 | W30: =SUM(W14:W19) -> 69 | X30: =SUM(X14:X19) -> 43 | ... AB30: =SUM(AB14:AB19) -> 10961
B31: 11.15 - 11.30 | C31: 10 | D31: 12 | E31: 72 | F31: 0 | G31: 0 | H31: 1 | I31: 1 | J31: 0 | K31: 0 | L31: 315 | M31: =SUM(C31:K31) -> 96 | N31: =SUM(C31:L31) -> 411 | P31: PM Period | Q31: =SUM(Q20:Q22) -> 143 | R31: =SUM(R20:R22) -> 146 | S31: =SUM(S20:S22) -> 828 | T31: =SUM(T20:T22) -> 4 | U31: =SUM(U20:U22) -> 4 | V31: =SUM(V20:V22) -> 43 | W31: =SUM(W20:W22) -> 11 | X31: =SUM(X20:X22) -> 4 | ... AB31: =SUM(AB20:AB22) -> 4958
B32: 11.30 - 11.45 | C32: 19 | D32: 20 | E32: 64 | F32: 0 | G32: 0 | H32: 2 | I32: 2 | J32: 2 | K32: 0 | L32: 303 | M32: =SUM(C32:K32) -> 109 | N32: =SUM(C32:L32) -> 412 | P32: 12 Hours | Q32: =SUM(Q11:Q22) -> 1132 | R32: =SUM(R11:R22) -> 1063 | S32: =SUM(S11:S22) -> 3447 | T32: =SUM(T11:T22) -> 28 | U32: =SUM(U11:U22) -> 11 | V32: =SUM(V11:V22) -> 207 | W32: =SUM(W11:W22) -> 114 | X32: =SUM(X11:X22) -> 70 | ... AB32: =SUM(AB11:AB22) -> 21602
B33: 11.45 - 12.00 | C33: 14 | D33: 9 | E33: 90 | F33: 1 | G33: 0 | H33: 6 | I33: 9 | J33: 1 | K33: 0 | L33: 305 | M33: =SUM(C33:K33) -> 130 | N33: =SUM(C33:L33) -> 435 | P33: 16 Hrs/ADT | Q33: =SUM(Q10:Q25) -> 1344 | R33: =SUM(R10:R25) -> 1225 | S33: =SUM(S10:S25) -> 4420 | T33: =SUM(T10:T25) -> 41 | U33: =SUM(U10:U25) -> 13 | V33: =SUM(V10:V25) -> 232 | W33: =SUM(W10:W25) -> 130 | X33: =SUM(X10:X25) -> 75 | ... AB33: =SUM(AB10:AB25) -> 26764
B34: 12.00 - 12.15 | C34: 12 | D34: 23 | E34: 56 | F34: 1 | G34: 0 | H34: 2 | I34: 2 | J34: 6 | K34: 0 | L34: 323 | M34: =SUM(C34:K34) -> 102 | N34: =SUM(C34:L34) -> 425 | P34: NEF | Q34: =Q33/Q32 -> 1.1872792 | R34: =R33/R32 -> 1.1523989 | S34: =S33/S32 -> 1.2822744 | T34: =T33/T32 -> 1.4642857 | U34: =U33/U32 -> 1.1818182 | V34: =V33/V32 -> 1.1207729 | W34: =W33/W32 -> 1.1403509 | X34: =X33/X32 -> 1.0714286 | ... AB34: =AB33/AB32 -> 1.2389594
B35: 12.15 - 12.30 | C35: 22 | D35: 24 | E35: 110 | F35: 0 | G35: 1 | H35: 3 | I35: 3 | J35: 3 | K35: 0 | L35: 335 | M35: =SUM(C35:K35) -> 166 | N35: =SUM(C35:L35) -> 501
B36: 12.30 - 12.45 | C36: 17 | D36: 30 | E36: 85 | F36: 0 | G36: 0 | H36: 8 | I36: 4 | J36: 4 | K36: 0 | L36: 383 | M36: =SUM(C36:K36) -> 148 | N36: =SUM(C36:L36) -> 531
B37: 12.45 - 13.00 | C37: 3 | D37: 0 | E37: 14 | F37: 0 | G37: 0 | H37: 1 | I37: 1 | J37: 1 | K37: 0 | L37: 373 | M37: =SUM(C37:K37) -> 20 | N37: =SUM(C37:L37) -> 393
B38: 13.00 - 13.15 | C38: 21 | D38: 22 | E38: 47 | F38: 0 | G38: 0 | H38: 9 | I38: 7 | J38: 1 | K38: 0 | L38: 410 | M38: =SUM(C38:K38) -> 107 | N38: =SUM(C38:L38) -> 517
B39: 13.15 - 13.30 | C39: 8 | D39: 10 | E39: 4 | F39: 0 | G39: 0 | H39: 1 | I39: 2 | J39: 2 | K39: 0 | L39: 300 | M39: =SUM(C39:K39) -> 27 | N39: =SUM(C39:L39) -> 327
B40: 13.30 - 13.45 | C40: 21 | D40: 25 | E40: 110 | F40: 0 | G40: 0 | H40: 7 | I40: 6 | J40: 5 | K40: 1 | L40: 315 | M40: =SUM(C40:K40) -> 175 | N40: =SUM(C40:L40) -> 490
B41: 13.45 - 14.00 | C41: 12 | D41: 18 | E41: 90 | F41: 1 | G41: 0 | H41: 5 | I41: 4 | J41: 1 | K41: 0 | L41: 315 | M41: =SUM(C41:K41) -> 131 | N41: =SUM(C41:L41) -> 446
B42: 14.00 - 14.15 | C42: 34 | D42: 19 | E42: 73 | F42: 0 | G42: 0 | H42: 6 | I42: 1 | J42: 0 | K42: 0 | L42: 348 | M42: =SUM(C42:K42) -> 133 | N42: =SUM(C42:L42) -> 481
...

Sheet 05.10.Nakivubo-ShopriteC1 L1
B1: Traffic Impact Assessment for Kikapu project
B2: MANUAL CLASSIFIED COUNT (MCC)
B3: ROAD NAME: | C3: SHOPRITE-QUEENSWAY
C5: Date | D5: 5.10.19 | E5: Location | F5: CLOCK TOWER JUNCTION | I5: Surveyor | J5: Kasoma JP, Nakiwuge A.
C6: Dir. From | D6: NAKIVUBO | E6: Dir. To | F6: SHOPRITE | I6: Supervisor | J6: Lawrence
B8: Time / Veh Type | P8: SUMMARY TRAFFIC VOLUMES
C9: 1. Private Car | D9: 3. Pickups/four wheel drive | E9: 4. Minibus, matatu | F9: 5. Medium bus/ coaster | G9: 6. Large Bus/coach | H9: 7. Light Truck | I9: 8. Medium Truck | J9: 9. Heavy truck | K9: 10. Truck Trailer | L9: 11. Motor cycles | M9: Total Excl M/Cycles | N9: Total All | P9: Time | Q9: 1. Car | R9: 3. Pickups | S9: 4. Minibus, matatu | T9: 5. Medium bus | U9: 6. Large Bus | V9: 7. Light Truck | W9: 8. Medium Truck | X9: 9. Heavy truck | Y9: 10. Truck Trailer | Z9: 11. Motorcycles | AA9: Total Excl M/ Cycles | AB9: Total All
B10: 06.00 - 06.15 | C10: 14 | D10: 17 | E10: 22 | F10: 0 | G10: 0 | H10: 5 | I10: 2 | J10: 1 | K10: 1 | L10: 118 | M10: =SUM(C10:K10) -> 62 | N10: =SUM(C10:L10) -> 180 | P10: 06.00 - 06.15 | Q10: =SUM(C10:C13) -> 115 | R10: =SUM(D10:D13) -> 62 | S10: =SUM(E10:E13) -> 259 | T10: =SUM(F10:F13) -> 3 | U10: =SUM(G10:G13) -> 1 | V10: =SUM(H10:H13) -> 35 | W10: =SUM(I10:I13) -> 16 | X10: =SUM(J10:J13) -> 2 | ... AB10: =SUM(N10:N13) -> 1127
B11: 06.15 - 06.30 | C11: 29 | D11: 16 | E11: 37 | F11: 1 | G11: 0 | H11: 11 | I11: 8 | J11: 0 | K11: 0 | L11: 218 | M11: =SUM(C11:K11) -> 102 | N11: =SUM(C11:L11) -> 320 | P11: 0700-0800 | Q11: =SUM(C14:C17) -> 129 | R11: =SUM(D14:D17) -> 80 | S11: =SUM(E14:E17) -> 525 | T11: =SUM(F14:F17) -> 3 | U11: =SUM(G14:G17) -> 0 | V11: =SUM(H14:H17) -> 27 | W11: =SUM(I14:I17) -> 5 | X11: =SUM(J14:J17) -> 4 | ... AB11: =SUM(N14:N17) -> 1950
B12: 06.30 - 06.45 | C12: 37 | D12: 16 | E12: 80 | F12: 2 | G12: 1 | H12: 12 | I12: 6 | J12: 1 | K12: 1 | L12: 203 | M12: =SUM(C12:K12) -> 156 | N12: =SUM(C12:L12) -> 359 | P12: 0800-0900 | Q12: =SUM(C18:C21) -> 201 | R12: =SUM(D18:D21) -> 111 | S12: =SUM(E18:E21) -> 445 | T12: =SUM(F18:F21) -> 3 | U12: =SUM(G18:G21) -> 1 | V12: =SUM(H18:H21) -> 24 | W12: =SUM(I18:I21) -> 5 | X12: =SUM(J18:J21) -> 4 | ... AB12: =SUM(N18:N21) -> 2481
B13: 06.45 - 07.00 | C13: 35 | D13: 13 | E13: 120 | F13: 0 | G13: 0 | H13: 7 | I13: 0 | J13: 0 | K13: 0 | L13: 93 | M13: =SUM(C13:K13) -> 175 | N13: =SUM(C13:L13) -> 268 | P13: 0900-1000 | Q13: =SUM(C22:C25) -> 177 | R13: =SUM(D22:D25) -> 96 | S13: =SUM(E22:E25) -> 477 | T13: =SUM(F22:F25) -> 2 | U13: =SUM(G22:G25) -> 0 | V13: =SUM(H22:H25) -> 25 | W13: =SUM(I22:I25) -> 5 | X13: =SUM(J22:J25) -> 0 | ... AB13: =SUM(N22:N25) -> 1788
B14: 07.00 - 07.15 | C14: 38 | D14: 18 | E14: 154 | F14: 0 | G14: 0 | H14: 5 | I14: 1 | J14: 0 | K14: 0 | L14: 223 | M14: =SUM(C14:K14) -> 216 | N14: =SUM(C14:L14) -> 439 | P14: 1000-1100 | Q14: =SUM(C26:C29) -> 149 | R14: =SUM(D26:D29) -> 94 | S14: =SUM(E26:E29) -> 314 | T14: =SUM(F26:F29) -> 3 | U14: =SUM(G26:G29) -> 3 | V14: =SUM(H26:H29) -> 32 | W14: =SUM(I26:I29) -> 14 | X14: =SUM(J26:J29) -> 0 | ... AB14: =SUM(N26:N29) -> 1448
B15: 07.15 - 07.30 | C15: 34 | D15: 26 | E15: 152 | F15: 1 | G15: 0 | H15: 10 | I15: 2 | J15: 0 | K15: 0 | L15: 265 | M15: =SUM(C15:K15) -> 225 | N15: =SUM(C15:L15) -> 490 | P15: 1100-1200 | Q15: =SUM(C30:C33) -> 232 | R15: =SUM(D30:D33) -> 144 | S15: =SUM(E30:E33) -> 132 | T15: =SUM(F30:F33) -> 2 | U15: =SUM(G30:G33) -> 1 | V15: =SUM(H30:H33) -> 43 | W15: =SUM(I30:I33) -> 9 | X15: =SUM(J30:J33) -> 6 | ... AB15: =SUM(N30:N33) -> 1654
B16: 07.30 - 07.45 | C16: 26 | D16: 17 | E16: 115 | F16: 0 | G16: 0 | H16: 4 | I16: 1 | J16: 1 | K16: 0 | L16: 375 | M16: =SUM(C16:K16) -> 164 | N16: =SUM(C16:L16) -> 539 | P16: 1200-1300 | Q16: =SUM(C34:C37) -> 299 | R16: =SUM(D34:D37) -> 143 | S16: =SUM(E34:E37) -> 141 | T16: =SUM(F34:F37) -> 1 | U16: =SUM(G34:G37) -> 0 | V16: =SUM(H34:H37) -> 32 | W16: =SUM(I34:I37) -> 10 | X16: =SUM(J34:J37) -> 3 | ... AB16: =SUM(N34:N37) -> 1656
B17: 07.45 - 08.00 | C17: 31 | D17: 19 | E17: 104 | F17: 2 | G17: 0 | H17: 8 | I17: 1 | J17: 3 | K17: 1 | L17: 313 | M17: =SUM(C17:K17) -> 169 | N17: =SUM(C17:L17) -> 482 | P17: 1300-1400 | Q17: =SUM(C38:C41) -> 264 | R17: =SUM(D38:D41) -> 125 | S17: =SUM(E38:E41) -> 110 | T17: =SUM(F38:F41) -> 0 | U17: =SUM(G38:G41) -> 0 | V17: =SUM(H38:H41) -> 32 | W17: =SUM(I38:I41) -> 8 | X17: =SUM(J38:J41) -> 1 | ... AB17: =SUM(N38:N41) -> 1501
B18: 08.00 - 08.15 | C18: 43 | D18: 19 | E18: 127 | F18: 1 | G18: 0 | H18: 6 | I18: 1 | J18: 1 | K18: 0 | L18: 418 | M18: =SUM(C18:K18) -> 198 | N18: =SUM(C18:L18) -> 616 | P18: 1400-1500 | Q18: =SUM(C42:C45) -> 205 | R18: =SUM(D42:D45) -> 52 | S18: =SUM(E42:E45) -> 60 | T18: =SUM(F42:F45) -> 0 | U18: =SUM(G42:G45) -> 0 | V18: =SUM(H42:H45) -> 28 | W18: =SUM(I42:I45) -> 9 | X18: =SUM(J42:J45) -> 3 | ... AB18: =SUM(N42:N45) -> 1332
B19: 08.15 - 08.30 | C19: 64 | D19: 31 | E19: 100 | F19: 0 | G19: 0 | H19: 2 | I19: 0 | J19: 1 | K19: 0 | L19: 505 | M19: =SUM(C19:K19) -> 198 | N19: =SUM(C19:L19) -> 703 | P19: 1500-1600 | Q19: =SUM(C46:C49) -> 220 | R19: =SUM(D46:D49) -> 81 | S19: =SUM(E46:E49) -> 96 | T19: =SUM(F46:F49) -> 0 | U19: =SUM(G46:G49) -> 1 | V19: =SUM(H46:H49) -> 17 | W19: =SUM(I46:I49) -> 13 | X19: =SUM(J46:J49) -> 5 | ... AB19: =SUM(N46:N49) -> 1594
B20: 08.30 - 08.45 | C20: 44 | D20: 31 | E20: 108 | F20: 1 | G20: 1 | H20: 8 | I20: 1 | J20: 1 | K20: 0 | L20: 493 | M20: =SUM(C20:K20) -> 195 | N20: =SUM(C20:L20) -> 688 | P20: 1600-1700 | Q20: =SUM(C50:C53) -> 168 | R20: =SUM(D50:D53) -> 81 | S20: =SUM(E50:E53) -> 134 | T20: =SUM(F50:F53) -> 1 | U20: =SUM(G50:G53) -> 1 | V20: =SUM(H50:H53) -> 18 | W20: =SUM(I50:I53) -> 18 | X20: =SUM(J50:J53) -> 3 | ... AB20: =SUM(N50:N53) -> 1633
B21: 08.45 - 9.00 | C21: 50 | D21: 30 | E21: 110 | F21: 1 | G21: 0 | H21: 8 | I21: 3 | J21: 1 | K21: 0 | L21: 271 | M21: =SUM(C21:K21) -> 203 | N21: =SUM(C21:L21) -> 474 | P21: 1700-1800 | Q21: =SUM(C54:C57) -> 183 | R21: =SUM(D54:D57) -> 111 | S21: =SUM(E54:E57) -> 105 | T21: =SUM(F54:F57) -> 2 | U21: =SUM(G54:G57) -> 1 | V21: =SUM(H54:H57) -> 13 | W21: =SUM(I54:I57) -> 8 | X21: =SUM(J54:J57) -> 5 | ... AB21: =SUM(N54:N57) -> 1506
B22: 09.00 - 09.15 | C22: 57 | D22: 26 | E22: 81 | F22: 0 | G22: 0 | H22: 6 | I22: 1 | J22: 0 | K22: 0 | L22: 221 | M22: =SUM(C22:K22) -> 171 | N22: =SUM(C22:L22) -> 392 | P22: 1800-1900 | Q22: =SUM(C58:C61) -> 154 | R22: =SUM(D58:D61) -> 76 | S22: =SUM(E58:E61) -> 103 | T22: =SUM(F58:F61) -> 2 | U22: =SUM(G58:G61) -> 2 | V22: =SUM(H58:H61) -> 16 | W22: =SUM(I58:I61) -> 6 | X22: =SUM(J58:J61) -> 1 | ... AB22: =SUM(N58:N61) -> 1533
B23: 09.15 - 09.30 | C23: 39 | D23: 14 | E23: 129 | F23: 0 | G23: 0 | H23: 3 | I23: 1 | J23: 0 | K23: 0 | L23: 214 | M23: =SUM(C23:K23) -> 186 | N23: =SUM(C23:L23) -> 400 | P23: 1900-2000 | Q23: =SUM(C62:C65) -> 112 | R23: =SUM(D62:D65) -> 104 | S23: =SUM(E62:E65) -> 117 | T23: =SUM(F62:F65) -> 2 | U23: =SUM(G62:G65) -> 1 | V23: =SUM(H62:H65) -> 10 | W23: =SUM(I62:I65) -> 10 | X23: =SUM(J62:J65) -> 3 | ... AB23: =SUM(N62:N65) -> 1516
B24: 09.30 - 09.45 | C24: 44 | D24: 37 | E24: 154 | F24: 1 | G24: 0 | H24: 6 | I24: 1 | J24: 0 | K24: 0 | L24: 260 | M24: =SUM(C24:K24) -> 243 | N24: =SUM(C24:L24) -> 503 | P24: 2000-2100 | Q24: =SUM(C66:C69) -> 169 | R24: =SUM(D66:D69) -> 58 | S24: =SUM(E66:E69) -> 118 | T24: =SUM(F66:F69) -> 5 | U24: =SUM(G66:G69) -> 1 | V24: =SUM(H66:H69) -> 13 | W24: =SUM(I66:I69) -> 5 | X24: =SUM(J66:J69) -> 6 | ... AB24: =SUM(N66:N69) -> 1522
B25: 09.45 - 10.00 | C25: 37 | D25: 19 | E25: 113 | F25: 1 | G25: 0 | H25: 10 | I25: 2 | J25: 0 | K25: 0 | L25: 311 | M25: =SUM(C25:K25) -> 182 | N25: =SUM(C25:L25) -> 493 | P25: 2100-2200 | Q25: =SUM(C70:C73) -> 67 | R25: =SUM(D70:D73) -> 28 | S25: =SUM(E70:E73) -> 56 | T25: =SUM(F70:F73) -> 1 | U25: =SUM(G70:G73) -> 0 | V25: =SUM(H70:H73) -> 6 | W25: =SUM(I70:I73) -> 3 | X25: =SUM(J70:J73) -> 0 | ... AB25: =SUM(N70:N73) -> 960
B26: 10.00 - 10.15 | C26: 41 | D26: 12 | E26: 109 | F26: 2 | G26: 1 | H26: 11 | I26: 4 | J26: 0 | K26: 0 | L26: 295 | M26: =SUM(C26:K26) -> 180 | N26: =SUM(C26:L26) -> 475 | P26: AM Peak Hr | Q26: =MAX(Q10:Q13) -> 201 | R26: =MAX(R10:R13) -> 111 | S26: =MAX(S10:S13) -> 525 | T26: =MAX(T10:T13) -> 3 | U26: =MAX(U10:U13) -> 1 | V26: =MAX(V10:V13) -> 35 | W26: =MAX(W10:W13) -> 16 | X26: =MAX(X10:X13) -> 4 | ... AB26: =MAX(AB10:AB13) -> 2481
B27: 10.15 - 10.30 | C27: 34 | D27: 17 | E27: 93 | F27: 1 | G27: 2 | H27: 6 | I27: 2 | J27: 0 | K27: 0 | L27: 205 | M27: =SUM(C27:K27) -> 155 | N27: =SUM(C27:L27) -> 360 | P27: IP Peak Hr | Q27: =MAX(Q14:Q19) -> 299 | R27: =MAX(R14:R19) -> 144 | S27: =MAX(S14:S19) -> 314 | T27: =MAX(T14:T19) -> 3 | U27: =MAX(U14:U19) -> 3 | V27: =MAX(V14:V19) -> 43 | W27: =MAX(W14:W19) -> 14 | X27: =MAX(X14:X19) -> 6 | ... AB27: =MAX(AB14:AB19) -> 1656
B28: 10.30 - 10.45 | C28: 23 | D28: 27 | E28: 83 | F28: 0 | G28: 0 | H28: 7 | I28: 5 | J28: 0 | K28: 1 | L28: 180 | M28: =SUM(C28:K28) -> 146 | N28: =SUM(C28:L28) -> 326 | P28: PM Peak Hr | Q28: =MAX(Q20:Q22) -> 183 | R28: =MAX(R20:R22) -> 111 | S28: =MAX(S20:S22) -> 134 | T28: =MAX(T20:T22) -> 2 | U28: =MAX(U20:U22) -> 2 | V28: =MAX(V20:V22) -> 18 | W28: =MAX(W20:W22) -> 18 | X28: =MAX(X20:X22) -> 5 | ... AB28: =MAX(AB20:AB22) -> 1633
B29: 10.45 - 11.00 | C29: 51 | D29: 38 | E29: 29 | F29: 0 | G29: 0 | H29: 8 | I29: 3 | J29: 0 | K29: 0 | L29: 158 | M29: =SUM(C29:K29) -> 129 | N29: =SUM(C29:L29) -> 287 | P29: AM Period | Q29: =SUM(Q10:Q13) -> 622 | R29: =SUM(R10:R13) -> 349 | S29: =SUM(S10:S13) -> 1706 | T29: =SUM(T10:T13) -> 11 | U29: =SUM(U10:U13) -> 2 | V29: =SUM(V10:V13) -> 111 | W29: =SUM(W10:W13) -> 31 | X29: =SUM(X10:X13) -> 10 | ... AB29: =SUM(AB10:AB13) -> 7346
B30: 11.00 - 11.15 | C30: 52 | D30: 39 | E30: 32 | F30: 1 | G30: 0 | H30: 10 | I30: 3 | J30: 0 | K30: 0 | L30: 245 | M30: =SUM(C30:K30) -> 137 | N30: =SUM(C30:L30) -> 382 | P30: IP Period | Q30: =SUM(Q14:Q19) -> 1369 | R30: =SUM(R14:R19) -> 639 | S30: =SUM(S14:S19) -> 853 | T30: =SUM(T14:T19) -> 6 | U30: =SUM(U14:U19) -> 5 | V30: =SUM(V14:V19) -> 184 | W30: =SUM(W14:W19) -> 63 | X30: =SUM(X14:X19) -> 18 | ... AB30: =SUM(AB14:AB19) -> 9185
B31: 11.15 - 11.30 | C31: 62 | D31: 32 | E31: 27 | F31: 0 | G31: 1 | H31: 14 | I31: 3 | J31: 1 | K31: 0 | L31: 260 | M31: =SUM(C31:K31) -> 140 | N31: =SUM(C31:L31) -> 400 | P31: PM Period | Q31: =SUM(Q20:Q22) -> 505 | R31: =SUM(R20:R22) -> 268 | S31: =SUM(S20:S22) -> 342 | T31: =SUM(T20:T22) -> 5 | U31: =SUM(U20:U22) -> 4 | V31: =SUM(V20:V22) -> 47 | W31: =SUM(W20:W22) -> 32 | X31: =SUM(X20:X22) -> 9 | ... AB31: =SUM(AB20:AB22) -> 4672
B32: 11.30 - 11.45 | C32: 59 | D32: 48 | E32: 47 | F32: 0 | G32: 0 | H32: 12 | I32: 1 | J32: 1 | K32: 1 | L32: 272 | M32: =SUM(C32:K32) -> 169 | N32: =SUM(C32:L32) -> 441 | P32: 12 Hours | Q32: =SUM(Q11:Q22) -> 2381 | R32: =SUM(R11:R22) -> 1194 | S32: =SUM(S11:S22) -> 2642 | T32: =SUM(T11:T22) -> 19 | U32: =SUM(U11:U22) -> 10 | V32: =SUM(V11:V22) -> 307 | W32: =SUM(W11:W22) -> 110 | X32: =SUM(X11:X22) -> 35 | ... AB32: =SUM(AB11:AB22) -> 20076
B33: 11.45 - 12.00 | C33: 59 | D33: 25 | E33: 26 | F33: 1 | G33: 0 | H33: 7 | I33: 2 | J33: 4 | K33: 0 | L33: 307 | M33: =SUM(C33:K33) -> 124 | N33: =SUM(C33:L33) -> 431 | P33: 16 Hrs/ADT | Q33: =SUM(Q10:Q25) -> 2844 | R33: =SUM(R10:R25) -> 1446 | S33: =SUM(S10:S25) -> 3192 | T33: =SUM(T10:T25) -> 30 | U33: =SUM(U10:U25) -> 13 | V33: =SUM(V10:V25) -> 371 | W33: =SUM(W10:W25) -> 144 | X33: =SUM(X10:X25) -> 46 | ... AB33: =SUM(AB10:AB25) -> 25201
B34: 12.00 - 12.15 | C34: 81 | D34: 40 | E34: 43 | F34: 1 | G34: 0 | H34: 12 | I34: 3 | J34: 1 | K34: 0 | L34: 280 | M34: =SUM(C34:K34) -> 181 | N34: =SUM(C34:L34) -> 461 | P34: NEF | Q34: =Q33/Q32 -> 1.1944561 | R34: =R33/R32 -> 1.2110553 | S34: =S33/S32 -> 1.2081756 | T34: =T33/T32 -> 1.5789474 | U34: =U33/U32 -> 1.3 | V34: =V33/V32 -> 1.2084691 | W34: =W33/W32 -> 1.3090909 | X34: =X33/X32 -> 1.3142857 | ... AB34: =AB33/AB32 -> 1.2552799
B35: 12.15 - 12.30 | C35: 73 | D35: 18 | E35: 29 | F35: 0 | G35: 0 | H35: 3 | I35: 2 | J35: 0 | K35: 0 | L35: 280 | M35: =SUM(C35:K35) -> 125 | N35: =SUM(C35:L35) -> 405
B36: 12.30 - 12.45 | C36: 64 | D36: 41 | E36: 34 | F36: 0 | G36: 0 | H36: 10 | I36: 4 | J36: 1 | K36: 0 | L36: 315 | M36: =SUM(C36:K36) -> 154 | N36: =SUM(C36:L36) -> 469
B37: 12.45 - 13.00 | C37: 81 | D37: 44 | E37: 35 | F37: 0 | G37: 0 | H37: 7 | I37: 1 | J37: 1 | K37: 0 | L37: 152 | M37: =SUM(C37:K37) -> 169 | N37: =SUM(C37:L37) -> 321
B38: 13.00 - 13.15 | C38: 50 | D38: 24 | E38: 18 | F38: 0 | G38: 0 | H38: 4 | I38: 1 | J38: 0 | K38: 0 | L38: 175 | M38: =SUM(C38:K38) -> 97 | N38: =SUM(C38:L38) -> 272
B39: 13.15 - 13.30 | C39: 88 | D39: 31 | E39: 34 | F39: 0 | G39: 0 | H39: 12 | I39: 2 | J39: 0 | K39: 0 | L39: 216 | M39: =SUM(C39:K39) -> 167 | N39: =SUM(C39:L39) -> 383
B40: 13.30 - 13.45 | C40: 73 | D40: 50 | E40: 33 | F40: 0 | G40: 0 | H40: 8 | I40: 3 | J40: 1 | K40: 0 | L40: 305 | M40: =SUM(C40:K40) -> 168 | N40: =SUM(C40:L40) -> 473
B41: 13.45 - 14.00 | C41: 53 | D41: 20 | E41: 25 | F41: 0 | G41: 0 | H41: 8 | I41: 2 | J41: 0 | K41: 0 | L41: 265 | M41: =SUM(C41:K41) -> 108 | N41: =SUM(C41:L41) -> 373
B42: 14.00 - 14.15 | C42: 21 | D42: 3 | E42: 11 | F42: 0 | G42: 0 | H42: 4 | I42: 1 | J42: 1 | K42: 1 | L42: 130 | M42: =SUM(C42:K42) -> 42 | N42: =SUM(C42:L42) -> 172
...

Sheet 1.10. Nakivubo-ShopriteC1 L2
B1: Traffic Impact Assessment for Kikapu project
B2: MANUAL CLASSIFIED COUNT (MCC)
B3: ROAD NAME: | C3: SHOPRITE-QUEENSWAY
C5: Date | D5: 1.10.19 | E5: Location | F5: CLOCK TOWER JUNCTION | I5: Surveyor | J5: Babirye P,Muganga S,
C6: Dir. From | D6: NAKIVUBO | E6: Dir. To | F6: SHOPRITE | I6: Supervisor | J6: Lawrence
B8: Time / Veh Type | P8: SUMMARY TRAFFIC VOLUMES
C9: 1. Private Car | D9: 3. Pickups/four wheel drive | E9: 4. Minibus, matatu | F9: 5. Medium bus/ coaster | G9: 6. Large Bus/coach | H9: 7. Light Truck | I9: 8. Medium Truck | J9: 9. Heavy truck | K9: 10. Truck Trailer | L9: 11. Motor cycles | M9: Total Excl M/Cycles | N9: Total All | P9: Time | Q9: 1. Car | R9: 3. Pickups | S9: 4. Minibus, matatu | T9: 5. Medium bus | U9: 6. Large Bus | V9: 7. Light Truck | W9: 8. Medium Truck | X9: 9. Heavy truck | Y9: 10. Truck Trailer | Z9: 11. Motorcycles | AA9: Total Excl M/ Cycles | AB9: Total All
B10: 06.00 - 06.15 | C10: 16 | D10: 10 | E10: 50 | F10: 1 | G10: 1 | H10: 2 | I10: 3 | J10: 0 | K10: 0 | L10: 107 | M10: 305 | N10: =SUM(C10:L10) -> 190 | P10: 06.00 - 06.15 | Q10: =SUM(C10:C13) -> 125 | R10: =SUM(D10:D13) -> 75 | S10: =SUM(E10:E13) -> 238 | T10: =SUM(F10:F13) -> 4 | U10: =SUM(G10:G13) -> 4 | V10: =SUM(H10:H13) -> 13 | W10: =SUM(I10:I13) -> 8 | X10: =SUM(J10:J13) -> 0 | ... AB10: =SUM(N10:N13) -> 1193
B11: 06.15 - 06.30 | C11: 20 | D11: 15 | E11: 40 | F11: 1 | G11: 1 | H11: 3 | I11: 2 | J11: 0 | K11: 0 | L11: 152 | M11: =SUM(C11:K11) -> 82 | N11: =SUM(C11:L11) -> 234 | P11: 0700-0800 | Q11: =SUM(C14:C17) -> 216 | R11: =SUM(D14:D17) -> 104 | S11: =SUM(E14:E17) -> 272 | T11: =SUM(F14:F17) -> 6 | U11: =SUM(G14:G17) -> 2 | V11: =SUM(H14:H17) -> 14 | W11: =SUM(I14:I17) -> 5 | X11: =SUM(J14:J17) -> 4 | ... AB11: =SUM(N14:N17) -> 1648
B12: 06.30 - 06.45 | C12: 27 | D12: 17 | E12: 73 | F12: 1 | G12: 2 | H12: 2 | I12: 1 | J12: 0 | K12: 0 | L12: 212 | M12: =SUM(C12:K12) -> 123 | N12: =SUM(C12:L12) -> 335 | P12: 0800-0900 | Q12: =SUM(C18:C21) -> 128 | R12: =SUM(D18:D21) -> 101 | S12: =SUM(E18:E21) -> 350 | T12: =SUM(F18:F21) -> 5 | U12: =SUM(G18:G21) -> 1 | V12: =SUM(H18:H21) -> 20 | W12: =SUM(I18:I21) -> 8 | X12: =SUM(J18:J21) -> 7 | ... AB12: =SUM(N18:N21) -> 1840
B13: 06.45 - 07.00 | C13: 62 | D13: 33 | E13: 75 | F13: 1 | G13: 0 | H13: 6 | I13: 2 | J13: 0 | K13: 0 | L13: 255 | M13: =SUM(C13:K13) -> 179 | N13: =SUM(C13:L13) -> 434 | P13: 0900-1000 | Q13: =SUM(C22:C25) -> 117 | R13: =SUM(D22:D25) -> 103 | S13: =SUM(E22:E25) -> 316 | T13: =SUM(F22:F25) -> 2 | U13: =SUM(G22:G25) -> 2 | V13: =SUM(H22:H25) -> 16 | W13: =SUM(I22:I25) -> 10 | X13: =SUM(J22:J25) -> 10 | ... AB13: =SUM(N22:N25) -> 1735
B14: 07.00 - 07.15 | C14: 50 | D14: 36 | E14: 68 | F14: 0 | G14: 1 | H14: 4 | I14: 2 | J14: 0 | K14: 0 | L14: 230 | M14: =SUM(C14:K14) -> 161 | N14: =SUM(C14:L14) -> 391 | P14: 1000-1100 | Q14: =SUM(C26:C29) -> 100 | R14: =SUM(D26:D29) -> 73 | S14: =SUM(E26:E29) -> 357 | T14: =SUM(F26:F29) -> 2 | U14: =SUM(G26:G29) -> 1 | V14: =SUM(H26:H29) -> 22 | W14: =SUM(I26:I29) -> 11 | X14: =SUM(J26:J29) -> 11 | ... AB14: =SUM(N26:N29) -> 1614
B15: 07.15 - 07.30 | C15: 52 | D15: 32 | E15: 84 | F15: 3 | G15: 0 | H15: 5 | I15: 1 | J15: 3 | K15: 0 | L15: 247 | M15: =SUM(C15:K15) -> 180 | N15: =SUM(C15:L15) -> 427 | P15: 1100-1200 | Q15: =SUM(C30:C33) -> 50 | R15: =SUM(D30:D33) -> 48 | S15: =SUM(E30:E33) -> 383 | T15: =SUM(F30:F33) -> 1 | U15: =SUM(G30:G33) -> 1 | V15: =SUM(H30:H33) -> 79 | W15: =SUM(I30:I33) -> 10 | X15: =SUM(J30:J33) -> 5 | ... AB15: =SUM(N30:N33) -> 1508
B16: 07.30 - 07.45 | C16: 55 | D16: 16 | E16: 75 | F16: 1 | G16: 1 | H16: 3 | I16: 1 | J16: 0 | K16: 0 | L16: 275 | M16: =SUM(C16:K16) -> 152 | N16: =SUM(C16:L16) -> 427 | P16: 1200-1300 | Q16: =SUM(C34:C37) -> 53 | R16: =SUM(D34:D37) -> 33 | S16: =SUM(E34:E37) -> 342 | T16: =SUM(F34:F37) -> 1 | U16: =SUM(G34:G37) -> 1 | V16: =SUM(H34:H37) -> 12 | W16: =SUM(I34:I37) -> 12 | X16: =SUM(J34:J37) -> 15 | ... AB16: =SUM(N34:N37) -> 1338
B17: 07.45 - 08.00 | C17: 59 | D17: 20 | E17: 45 | F17: 2 | G17: 0 | H17: 2 | I17: 1 | J17: 1 | K17: 0 | L17: 273 | M17: =SUM(C17:K17) -> 130 | N17: =SUM(C17:L17) -> 403 | P17: 1300-1400 | Q17: =SUM(C38:C41) -> 49 | R17: =SUM(D38:D41) -> 37 | S17: =SUM(E38:E41) -> 331 | T17: =SUM(F38:F41) -> 1 | U17: =SUM(G38:G41) -> 0 | V17: =SUM(H38:H41) -> 15 | W17: =SUM(I38:I41) -> 12 | X17: =SUM(J38:J41) -> 10 | ... AB17: =SUM(N38:N41) -> 1319
B18: 08.00 - 08.15 | C18: 43 | D18: 28 | E18: 96 | F18: 0 | G18: 0 | H18: 4 | I18: 1 | J18: 1 | K18: 0 | L18: 298 | M18: =SUM(C18:K18) -> 173 | N18: =SUM(C18:L18) -> 471 | P18: 1400-1500 | Q18: =SUM(C42:C45) -> 69 | R18: =SUM(D42:D45) -> 56 | S18: =SUM(E42:E45) -> 269 | T18: =SUM(F42:F45) -> 1 | U18: =SUM(G42:G45) -> 0 | V18: =SUM(H42:H45) -> 20 | W18: =SUM(I42:I45) -> 8 | X18: =SUM(J42:J45) -> 4 | ... AB18: =SUM(N42:N45) -> 1333
B19: 08.15 - 08.30 | C19: 30 | D19: 22 | E19: 80 | F19: 2 | G19: 0 | H19: 4 | I19: 1 | J19: 2 | K19: 0 | L19: 310 | M19: =SUM(C19:K19) -> 141 | N19: =SUM(C19:L19) -> 451 | P19: 1500-1600 | Q19: =SUM(C46:C49) -> 40 | R19: =SUM(D46:D49) -> 54 | S19: =SUM(E46:E49) -> 218 | T19: =SUM(F46:F49) -> 0 | U19: =SUM(G46:G49) -> 0 | V19: =SUM(H46:H49) -> 12 | W19: =SUM(I46:I49) -> 6 | X19: =SUM(J46:J49) -> 1 | ... AB19: =SUM(N46:N49) -> 817
B20: 08.30 - 08.45 | C20: 28 | D20: 28 | E20: 71 | F20: 2 | G20: 1 | H20: 5 | I20: 4 | J20: 1 | K20: 0 | L20: 285 | M20: =SUM(C20:K20) -> 140 | N20: =SUM(C20:L20) -> 425 | P20: 1600-1700 | Q20: =SUM(C50:C53) -> 77 | R20: =SUM(D50:D53) -> 58 | S20: =SUM(E50:E53) -> 267 | T20: =SUM(F50:F53) -> 3 | U20: =SUM(G50:G53) -> 2 | V20: =SUM(H50:H53) -> 17 | W20: =SUM(I50:I53) -> 6 | X20: =SUM(J50:J53) -> 3 | ... AB20: =SUM(N50:N53) -> 1393
B21: 08.45 - 9.00 | C21: 27 | D21: 23 | E21: 103 | F21: 1 | G21: 0 | H21: 7 | I21: 2 | J21: 3 | K21: 0 | L21: 327 | M21: =SUM(C21:K21) -> 166 | N21: =SUM(C21:L21) -> 493 | P21: 1700-1800 | Q21: =SUM(C54:C57) -> 43 | R21: =SUM(D54:D57) -> 37 | S21: =SUM(E54:E57) -> 262 | T21: =SUM(F54:F57) -> 2 | U21: =SUM(G54:G57) -> 0 | V21: =SUM(H54:H57) -> 12 | W21: =SUM(I54:I57) -> 1 | X21: =SUM(J54:J57) -> 0 | ... AB21: =SUM(N54:N57) -> 1421
B22: 09.00 - 09.15 | C22: 18 | D22: 30 | E22: 60 | F22: 1 | G22: 0 | H22: 6 | I22: 4 | J22: 0 | K22: 0 | L22: 232 | M22: =SUM(C22:K22) -> 119 | N22: =SUM(C22:L22) -> 351 | P22: 1800-1900 | Q22: =SUM(C58:C61) -> 1922 | R22: =SUM(D58:D61) -> 21 | S22: =SUM(E58:E61) -> 192 | T22: =SUM(F58:F61) -> 2 | U22: =SUM(G58:G61) -> 0 | V22: =SUM(H58:H61) -> 7 | W22: =SUM(I58:I61) -> 2 | X22: =SUM(J58:J61) -> 2 | ... AB22: =SUM(N58:N61) -> 3090
B23: 09.15 - 09.30 | C23: 30 | D23: 28 | E23: 77 | F23: 1 | G23: 0 | H23: 3 | I23: 3 | J23: 2 | K23: 0 | L23: 310 | M23: =SUM(C23:K23) -> 144 | N23: =SUM(C23:L23) -> 454 | P23: 1900-2000 | Q23: =SUM(C62:C65) -> 40 | R23: =SUM(D62:D65) -> 36 | S23: =SUM(E62:E65) -> 310 | T23: =SUM(F62:F65) -> 2 | U23: =SUM(G62:G65) -> 2 | V23: =SUM(H62:H65) -> 9 | W23: =SUM(I62:I65) -> 6 | X23: =SUM(J62:J65) -> 0 | ... AB23: =SUM(N62:N65) -> 1462
B24: 09.30 - 09.45 | C24: 29 | D24: 25 | E24: 86 | F24: 0 | G24: 2 | H24: 3 | I24: 2 | J24: 5 | K24: 0 | L24: 337 | M24: =SUM(C24:K24) -> 152 | N24: =SUM(C24:L24) -> 489 | P24: 2000-2100 | Q24: =SUM(C66:C69) -> 58 | R24: =SUM(D66:D69) -> 36 | S24: =SUM(E66:E69) -> 396 | T24: =SUM(F66:F69) -> 5 | U24: =SUM(G66:G69) -> 1 | V24: =SUM(H66:H69) -> 13 | W24: =SUM(I66:I69) -> 4 | X24: =SUM(J66:J69) -> 2 | ... AB24: =SUM(N66:N69) -> 1396
B25: 09.45 - 10.00 | C25: 40 | D25: 20 | E25: 93 | F25: 0 | G25: 0 | H25: 4 | I25: 1 | J25: 3 | K25: 0 | L25: 280 | M25: =SUM(C25:K25) -> 161 | N25: =SUM(C25:L25) -> 441 | P25: 2100-2200 | Q25: =SUM(C70:C73) -> 80 | R25: =SUM(D70:D73) -> 63 | S25: =SUM(E70:E73) -> 323 | T25: =SUM(F70:F73) -> 2 | U25: =SUM(G70:G73) -> 1 | V25: =SUM(H70:H73) -> 15 | W25: =SUM(I70:I73) -> 1 | X25: =SUM(J70:J73) -> 0 | ... AB25: =SUM(N70:N73) -> 990
B26: 10.00 - 10.15 | C26: 21 | D26: 18 | E26: 75 | F26: 1 | G26: 0 | H26: 3 | I26: 3 | J26: 1 | K26: 0 | L26: 252 | M26: =SUM(C26:K26) -> 122 | N26: =SUM(C26:L26) -> 374 | P26: AM Peak Hr | Q26: =MAX(Q10:Q13) -> 216 | R26: =MAX(R10:R13) -> 104 | S26: =MAX(S10:S13) -> 350 | T26: =MAX(T10:T13) -> 6 | U26: =MAX(U10:U13) -> 4 | V26: =MAX(V10:V13) -> 20 | W26: =MAX(W10:W13) -> 10 | X26: =MAX(X10:X13) -> 10 | ... AB26: =MAX(AB10:AB13) -> 1840
B27: 10.15 - 10.30 | C27: 28 | D27: 16 | E27: 90 | F27: 1 | G27: 1 | H27: 6 | I27: 3 | J27: 6 | K27: 0 | L27: 250 | M27: =SUM(C27:K27) -> 151 | N27: =SUM(C27:L27) -> 401 | P27: IP Peak Hr | Q27: =MAX(Q14:Q19) -> 100 | R27: =MAX(R14:R19) -> 73 | S27: =MAX(S14:S19) -> 383 | T27: =MAX(T14:T19) -> 2 | U27: =MAX(U14:U19) -> 1 | V27: =MAX(V14:V19) -> 79 | W27: =MAX(W14:W19) -> 12 | X27: =MAX(X14:X19) -> 15 | ... AB27: =MAX(AB14:AB19) -> 1614
B28: 10.30 - 10.45 | C28: 28 | D28: 14 | E28: 100 | F28: 0 | G28: 0 | H28: 10 | I28: 3 | J28: 4 | K28: 0 | L28: 250 | M28: =SUM(C28:K28) -> 159 | N28: =SUM(C28:L28) -> 409 | P28: PM Peak Hr | Q28: =MAX(Q20:Q22) -> 1922 | R28: =MAX(R20:R22) -> 58 | S28: =MAX(S20:S22) -> 267 | T28: =MAX(T20:T22) -> 3 | U28: =MAX(U20:U22) -> 2 | V28: =MAX(V20:V22) -> 17 | W28: =MAX(W20:W22) -> 6 | X28: =MAX(X20:X22) -> 3 | ... AB28: =MAX(AB20:AB22) -> 3090
B29: 10.45 - 11.00 | C29: 23 | D29: 25 | E29: 92 | F29: 0 | G29: 0 | H29: 3 | I29: 2 | J29: 0 | K29: 0 | L29: 285 | M29: =SUM(C29:K29) -> 145 | N29: =SUM(C29:L29) -> 430 | P29: AM Period | Q29: =SUM(Q10:Q13) -> 586 | R29: =SUM(R10:R13) -> 383 | S29: =SUM(S10:S13) -> 1176 | T29: =SUM(T10:T13) -> 17 | U29: =SUM(U10:U13) -> 9 | V29: =SUM(V10:V13) -> 63 | W29: =SUM(W10:W13) -> 31 | X29: =SUM(X10:X13) -> 21 | ... AB29: =SUM(AB10:AB13) -> 6416
B30: 11.00 - 11.15 | C30: 12 | D30: 14 | E30: 165 | F30: 0 | G30: 0 | H30: 66 | I30: 0 | J30: 0 | K30: 0 | L30: 252 | M30: =SUM(C30:K30) -> 257 | N30: =SUM(C30:L30) -> 509 | P30: IP Period | Q30: =SUM(Q14:Q19) -> 361 | R30: =SUM(R14:R19) -> 301 | S30: =SUM(S14:S19) -> 1900 | T30: =SUM(T14:T19) -> 6 | U30: =SUM(U14:U19) -> 3 | V30: =SUM(V14:V19) -> 160 | W30: =SUM(W14:W19) -> 59 | X30: =SUM(X14:X19) -> 46 | ... AB30: =SUM(AB14:AB19) -> 7929
B31: 11.15 - 11.30 | C31: 13 | D31: 20 | E31: 110 | F31: 0 | G31: 0 | H31: 6 | I31: 5 | J31: 2 | K31: 0 | L31: 247 | M31: =SUM(C31:K31) -> 156 | N31: =SUM(C31:L31) -> 403 | P31: PM Period | Q31: =SUM(Q20:Q22) -> 2042 | R31: =SUM(R20:R22) -> 116 | S31: =SUM(S20:S22) -> 721 | T31: =SUM(T20:T22) -> 7 | U31: =SUM(U20:U22) -> 2 | V31: =SUM(V20:V22) -> 36 | W31: =SUM(W20:W22) -> 9 | X31: =SUM(X20:X22) -> 5 | ... AB31: =SUM(AB20:AB22) -> 5904
B32: 11.30 - 11.45 | C32: 17 | D32: 9 | E32: 50 | F32: 0 | G32: 0 | H32: 5 | I32: 3 | J32: 2 | K32: 0 | L32: 185 | M32: =SUM(C32:K32) -> 86 | N32: =SUM(C32:L32) -> 271 | P32: 12 Hours | Q32: =SUM(Q11:Q22) -> 2864 | R32: =SUM(R11:R22) -> 725 | S32: =SUM(S11:S22) -> 3559 | T32: =SUM(T11:T22) -> 26 | U32: =SUM(U11:U22) -> 10 | V32: =SUM(V11:V22) -> 246 | W32: =SUM(W11:W22) -> 91 | X32: =SUM(X11:X22) -> 72 | ... AB32: =SUM(AB11:AB22) -> 19056
B33: 11.45 - 12.00 | C33: 8 | D33: 5 | E33: 58 | F33: 1 | G33: 1 | H33: 2 | I33: 2 | J33: 1 | K33: 0 | L33: 247 | M33: =SUM(C33:K33) -> 78 | N33: =SUM(C33:L33) -> 325 | P33: 16 Hrs/ADT | Q33: =SUM(Q10:Q25) -> 3167 | R33: =SUM(R10:R25) -> 935 | S33: =SUM(S10:S25) -> 4826 | T33: =SUM(T10:T25) -> 39 | U33: =SUM(U10:U25) -> 18 | V33: =SUM(V10:V25) -> 296 | W33: =SUM(W10:W25) -> 110 | X33: =SUM(X10:X25) -> 74 | ... AB33: =SUM(AB10:AB25) -> 24097
B34: 12.00 - 12.15 | C34: 9 | D34: 7 | E34: 76 | F34: 1 | G34: 1 | H34: 1 | I34: 1 | J34: 0 | K34: 0 | L34: 250 | M34: =SUM(C34:K34) -> 96 | N34: =SUM(C34:L34) -> 346 | P34: NEF | Q34: =Q33/Q32 -> 1.1057961 | R34: =R33/R32 -> 1.2896552 | S34: =S33/S32 -> 1.3559989 | T34: =T33/T32 -> 1.5 | U34: =U33/U32 -> 1.8 | V34: =V33/V32 -> 1.203252 | W34: =W33/W32 -> 1.2087912 | X34: =X33/X32 -> 1.0277778 | ... AB34: =AB33/AB32 -> 1.2645361
B35: 12.15 - 12.30 | C35: 20 | D35: 9 | E35: 91 | F35: 0 | G35: 0 | H35: 4 | I35: 2 | J35: 6 | K35: 0 | L35: 210 | M35: =SUM(C35:K35) -> 132 | N35: =SUM(C35:L35) -> 342
B36: 12.30 - 12.45 | C36: 9 | D36: 7 | E36: 75 | F36: 0 | G36: 0 | H36: 4 | I36: 4 | J36: 4 | K36: 2 | L36: 205 | M36: =SUM(C36:K36) -> 105 | N36: =SUM(C36:L36) -> 310
B37: 12.45 - 13.00 | C37: 15 | D37: 10 | E37: 100 | F37: 0 | G37: 0 | H37: 3 | I37: 5 | J37: 5 | K37: 0 | L37: 202 | M37: =SUM(C37:K37) -> 138 | N37: =SUM(C37:L37) -> 340
B38: 13.00 - 13.15 | C38: 13 | D38: 9 | E38: 77 | F38: 1 | G38: 0 | H38: 2 | I38: 2 | J38: 1 | K38: 0 | L38: 185 | M38: =SUM(C38:K38) -> 105 | N38: =SUM(C38:L38) -> 290
B39: 13.15 - 13.30 | C39: 20 | D39: 11 | E39: 100 | F39: 0 | G39: 0 | H39: 8 | I39: 2 | J39: 4 | K39: 1 | L39: 217 | M39: =SUM(C39:K39) -> 146 | N39: =SUM(C39:L39) -> 363
B40: 13.30 - 13.45 | C40: 10 | D40: 10 | E40: 73 | F40: 0 | G40: 0 | H40: 4 | I40: 5 | J40: 1 | K40: 1 | L40: 240 | M40: =SUM(C40:K40) -> 104 | N40: =SUM(C40:L40) -> 344
B41: 13.45 - 14.00 | C41: 6 | D41: 7 | E41: 81 | F41: 0 | G41: 0 | H41: 1 | I41: 3 | J41: 4 | K41: 0 | L41: 220 | M41: =SUM(C41:K41) -> 102 | N41: =SUM(C41:L41) -> 322
B42: 14.00 - 14.15 | C42: 20 | D42: 10 | E42: 60 | F42: 0 | G42: 0 | H42: 3 | I42: 3 | J42: 2 | K42: 0 | L42: 110 | M42: =SUM(C42:K42) -> 98 | N42: =SUM(C42:L42) -> 208
...

Sheet 2.10. Nakivubo-ShopriteC1 L2
B1: Traffic Impact Assessment for Kikapu project
B2: MANUAL CLASSIFIED COUNT (MCC)
B3: ROAD NAME: | C3: SHOPRITE-QUEENSWAY
C5: Date | D5: 2.10.19 | E5: Location | F5: CLOCK TOWER JUNCTION | I5: Surveyor | J5: XX
C6: Dir. From | D6: NAKIVUBO | E6: Dir. To | F6: SHOPRITE | I6: Supervisor | J6: Lawrence
B8: Time / Veh Type | P8: SUMMARY TRAFFIC VOLUMES
C9: 1. Private Car | D9: 3. Pickups/four wheel drive | E9: 4. Minibus, matatu | F9: 5. Medium bus/ coaster | G9: 6. Large Bus/coach | H9: 7. Light Truck | I9: 8. Medium Truck | J9: 9. Heavy truck | K9: 10. Truck Trailer | L9: 11. Motor cycles | M9: Total Excl M/Cycles | N9: Total All | P9: Time | Q9: 1. Car | R9: 3. Pickups | S9: 4. Minibus, matatu | T9: 5. Medium bus | U9: 6. Large Bus | V9: 7. Light Truck | W9: 8. Medium Truck | X9: 9. Heavy truck | Y9: 10. Truck Trailer | Z9: 11. Motorcycles | AA9: Total Excl M/ Cycles | AB9: Total All
B10: 06.00 - 06.15 | C10: 10 | D10: 10 | E10: 3 | F10: 1 | G10: 0 | H10: 3 | I10: 0 | J10: 0 | K10: 0 | L10: 35 | M10: =SUM(C10:K10) -> 27 | N10: =SUM(C10:L10) -> 62 | P10: 06.00 - 06.15 | Q10: =SUM(C10:C13) -> 351 | R10: =SUM(D10:D13) -> 81 | S10: =SUM(E10:E13) -> 99 | T10: =SUM(F10:F13) -> 2 | U10: =SUM(G10:G13) -> 0 | V10: =SUM(H10:H13) -> 17 | W10: =SUM(I10:I13) -> 7 | X10: =SUM(J10:J13) -> 1 | ... AB10: =SUM(N10:N13) -> 1057
B11: 06.15 - 06.30 | C11: 60 | D11: 7 | E11: 16 | F11: 0 | G11: 0 | H11: 2 | I11: 2 | J11: 0 | K11: 0 | L11: 89 | M11: =SUM(C11:K11) -> 87 | N11: =SUM(C11:L11) -> 176 | P11: 0700-0800 | Q11: =SUM(C14:C17) -> 481 | R11: =SUM(D14:D17) -> 207 | S11: =SUM(E14:E17) -> 100 | T11: =SUM(F14:F17) -> 1 | U11: =SUM(G14:G17) -> 0 | V11: =SUM(H14:H17) -> 17 | W11: =SUM(I14:I17) -> 4 | X11: =SUM(J14:J17) -> 1 | ... AB11: =SUM(N14:N17) -> 2015
B12: 06.30 - 06.45 | C12: 130 | D12: 27 | E12: 47 | F12: 0 | G12: 0 | H12: 6 | I12: 3 | J12: 0 | K12: 0 | L12: 150 | M12: =SUM(C12:K12) -> 213 | N12: =SUM(C12:L12) -> 363 | P12: 0800-0900 | Q12: =SUM(C18:C21) -> 418 | R12: =SUM(D18:D21) -> 218 | S12: =SUM(E18:E21) -> 114 | T12: =SUM(F18:F21) -> 4 | U12: =SUM(G18:G21) -> 0 | V12: =SUM(H18:H21) -> 18 | W12: =SUM(I18:I21) -> 6 | X12: =SUM(J18:J21) -> 0 | ... AB12: =SUM(N18:N21) -> 2226
B13: 06.45 - 07.00 | C13: 151 | D13: 37 | E13: 33 | F13: 1 | G13: 0 | H13: 6 | I13: 2 | J13: 1 | K13: 0 | L13: 225 | M13: =SUM(C13:K13) -> 231 | N13: =SUM(C13:L13) -> 456 | P13: 0900-1000 | Q13: =SUM(C22:C25) -> 326 | R13: =SUM(D22:D25) -> 136 | S13: =SUM(E22:E25) -> 82 | T13: =SUM(F22:F25) -> 3 | U13: =SUM(G22:G25) -> 0 | V13: =SUM(H22:H25) -> 12 | W13: =SUM(I22:I25) -> 5 | X13: =SUM(J22:J25) -> 2 | ... AB13: =SUM(N22:N25) -> 1746
B14: 07.00 - 07.15 | C14: 142 | D14: 26 | E14: 22 | F14: 0 | G14: 0 | H14: 3 | I14: 1 | J14: 0 | K14: 0 | L14: 205 | M14: =SUM(C14:K14) -> 194 | N14: =SUM(C14:L14) -> 399 | P14: 1000-1100 | Q14: =SUM(C26:C29) -> 285 | R14: =SUM(D26:D29) -> 95 | S14: =SUM(E26:E29) -> 130 | T14: =SUM(F26:F29) -> 0 | U14: =SUM(G26:G29) -> 2 | V14: =SUM(H26:H29) -> 17 | W14: =SUM(I26:I29) -> 8 | X14: =SUM(J26:J29) -> 1 | ... AB14: =SUM(N26:N29) -> 1722
B15: 07.15 - 07.30 | C15: 165 | D15: 25 | E15: 20 | F15: 0 | G15: 0 | H15: 1 | I15: 1 | J15: 1 | K15: 0 | L15: 275 | M15: =SUM(C15:K15) -> 213 | N15: =SUM(C15:L15) -> 488 | P15: 1100-1200 | Q15: =SUM(C30:C33) -> 247 | R15: =SUM(D30:D33) -> 111 | S15: =SUM(E30:E33) -> 103 | T15: =SUM(F30:F33) -> 0 | U15: =SUM(G30:G33) -> 1 | V15: =SUM(H30:H33) -> 25 | W15: =SUM(I30:I33) -> 8 | X15: =SUM(J30:J33) -> 4 | ... AB15: =SUM(N30:N33) -> 1676
B16: 07.30 - 07.45 | C16: 90 | D16: 59 | E16: 33 | F16: 0 | G16: 0 | H16: 4 | I16: 2 | J16: 0 | K16: 1 | L16: 348 | M16: =SUM(C16:K16) -> 189 | N16: =SUM(C16:L16) -> 537 | P16: 1200-1300 | Q16: =SUM(C34:C37) -> 260 | R16: =SUM(D34:D37) -> 74 | S16: =SUM(E34:E37) -> 63 | T16: =SUM(F34:F37) -> 0 | U16: =SUM(G34:G37) -> 0 | V16: =SUM(H34:H37) -> 25 | W16: =SUM(I34:I37) -> 7 | X16: =SUM(J34:J37) -> 4 | ... AB16: =SUM(N34:N37) -> 1848
B17: 07.45 - 08.00 | C17: 84 | D17: 97 | E17: 25 | F17: 1 | G17: 0 | H17: 9 | I17: 0 | J17: 0 | K17: 0 | L17: 375 | M17: =SUM(C17:K17) -> 216 | N17: =SUM(C17:L17) -> 591 | P17: 1300-1400 | Q17: =SUM(C38:C41) -> 313 | R17: =SUM(D38:D41) -> 94 | S17: =SUM(E38:E41) -> 106 | T17: =SUM(F38:F41) -> 0 | U17: =SUM(G38:G41) -> 0 | V17: =SUM(H38:H41) -> 25 | W17: =SUM(I38:I41) -> 9 | X17: =SUM(J38:J41) -> 3 | ... AB17: =SUM(N38:N41) -> 1891
B18: 08.00 - 08.15 | C18: 117 | D18: 60 | E18: 19 | F18: 2 | G18: 0 | H18: 4 | I18: 0 | J18: 0 | K18: 0 | L18: 325 | M18: =SUM(C18:K18) -> 202 | N18: =SUM(C18:L18) -> 527 | P18: 1400-1500 | Q18: =SUM(C42:C45) -> 203 | R18: =SUM(D42:D45) -> 54 | S18: =SUM(E42:E45) -> 170 | T18: =SUM(F42:F45) -> 1 | U18: =SUM(G42:G45) -> 1 | V18: =SUM(H42:H45) -> 16 | W18: =SUM(I42:I45) -> 6 | X18: =SUM(J42:J45) -> 3 | ... AB18: =SUM(N42:N45) -> 1813
B19: 08.15 - 08.30 | C19: 88 | D19: 47 | E19: 30 | F19: 1 | G19: 0 | H19: 7 | I19: 0 | J19: 0 | K19: 0 | L19: 360 | M19: =SUM(C19:K19) -> 173 | N19: =SUM(C19:L19) -> 533 | P19: 1500-1600 | Q19: =SUM(C46:C49) -> 180 | R19: =SUM(D46:D49) -> 149 | S19: =SUM(E46:E49) -> 88 | T19: =SUM(F46:F49) -> 0 | U19: =SUM(G46:G49) -> 1 | V19: =SUM(H46:H49) -> 18 | W19: =SUM(I46:I49) -> 14 | X19: =SUM(J46:J49) -> 6 | ... AB19: =SUM(N46:N49) -> 1907
B20: 08.30 - 08.45 | C20: 93 | D20: 63 | E20: 35 | F20: 1 | G20: 0 | H20: 2 | I20: 2 | J20: 0 | K20: 0 | L20: 380 | M20: =SUM(C20:K20) -> 196 | N20: =SUM(C20:L20) -> 576 | P20: 1600-1700 | Q20: =SUM(C50:C53) -> 148 | R20: =SUM(D50:D53) -> 121 | S20: =SUM(E50:E53) -> 83 | T20: =SUM(F50:F53) -> 0 | U20: =SUM(G50:G53) -> 2 | V20: =SUM(H50:H53) -> 31 | W20: =SUM(I50:I53) -> 2 | X20: =SUM(J50:J53) -> 0 | ... AB20: =SUM(N50:N53) -> 1690
B21: 08.45 - 9.00 | C21: 120 | D21: 48 | E21: 30 | F21: 0 | G21: 0 | H21: 5 | I21: 4 | J21: 0 | K21: 0 | L21: 383 | M21: =SUM(C21:K21) -> 207 | N21: =SUM(C21:L21) -> 590 | P21: 1700-1800 | Q21: =SUM(C54:C57) -> 98 | R21: =SUM(D54:D57) -> 105 | S21: =SUM(E54:E57) -> 86 | T21: =SUM(F54:F57) -> 0 | U21: =SUM(G54:G57) -> 1 | V21: =SUM(H54:H57) -> 23 | W21: =SUM(I54:I57) -> 11 | X21: =SUM(J54:J57) -> 1 | ... AB21: =SUM(N54:N57) -> 1529
B22: 09.00 - 09.15 | C22: 64 | D22: 20 | E22: 10 | F22: 2 | G22: 0 | H22: 2 | I22: 0 | J22: 0 | K22: 0 | L22: 310 | M22: =SUM(C22:K22) -> 98 | N22: =SUM(C22:L22) -> 408 | P22: 1800-1900 | Q22: =SUM(C58:C61) -> 71 | R22: =SUM(D58:D61) -> 66 | S22: =SUM(E58:E61) -> 125 | T22: =SUM(F58:F61) -> 1 | U22: =SUM(G58:G61) -> 5 | V22: =SUM(H58:H61) -> 24 | W22: =SUM(I58:I61) -> 2 | X22: =SUM(J58:J61) -> 2 | ... AB22: =SUM(N58:N61) -> 1565
