Workbook

Sheet 23.09.19 Bweya- Kajansi
B1: Consultancy services for Preparation of Expressway Development Master Plan (EDMP) for Uganda
B2: MANUAL CLASSIFIED COUNT (MCC)
B3: ROAD NAME: | C3: MCC-C2-STNO 56 -Munyonyo spur
C5: Date | D5: 23.09.19 | F5: Location | G5: Munyonyo Spur RD | J5: Surveyor | K5: Kasoma John Paul
C6: Dir. From | D6: BWEYA | F6: Dir. To | G6: KAJANSI | J6: Supervisor | K6: Beatrice
B8: Time / Veh Type | R8: SUMMARY TRAFFIC VOLUMES
C9: 1. Car | D9: 2. Station Wagon | E9: 3. Pickups | F9: 4. Minibus, matatu | G9: 5. Medium bus | H9: 6. Large Bus | I9: 7. Light Truck | J9: 8. Medium Truck | K9: 9. Heavy truck | L9: 10. Truck Trailer | M9: 11. Motor cycles | N9: 12. Tractors | O9: Total Excl M/Cycles | P9: Total All | R9: Time | S9: 1. Car | T9: 2. Station Wagon | U9: 3. Pickups | V9: 4. Minibus, matatu | W9: 5. Medium bus | X9: 6. Large Bus | Y9: 7. Light Truck | Z9: 8. Medium Truck | AA9: 9. Heavy truck | AB9: 10. Truck Trailer | AC9: 11. Motorcycles | AD9: 12. Tractors, Graders | AE9: Total Excl M/ Cycles | AF9: Total All
B10: 07.00 - 07.15 | C10: 11 | D10: 3 | E10: 0 | F10: 2 | G10: 0 | H10: 0 | I10: 3 | J10: 0 | K10: 0 | L10: 0 | M10: 22 | N10: 0 | O10: =SUM(C10:L10,N10) -> 19 | P10: =SUM(C10:N10) -> 41 | R10: 0700-0800 | S10: =SUM(C10:C13) -> 34 | T10: =SUM(D10:D13) -> 7 | U10: =SUM(E10:E13) -> 3 | V10: =SUM(F10:F13) -> 5 | W10: =SUM(G10:G13) -> 1 | X10: =SUM(H10:H13) -> 0 | Y10: =SUM(I10:I13) -> 11 | Z10: =SUM(J10:J13) -> 0 | ... AF10: =SUM(P10:P13) -> 158
B11: 07.15 - 07.30 | C11: 9 | D11: 1 | E11: 2 | F11: 3 | G11: 0 | H11: 0 | I11: 2 | J11: 0 | K11: 0 | L11: 0 | M11: 29 | N11: 0 | O11: =SUM(C11:L11,N11) -> 17 | P11: =SUM(C11:N11) -> 46 | R11: 0800-0900 | S11: =SUM(C14:C17) -> 29 | T11: =SUM(D14:D17) -> 4 | U11: =SUM(E14:E17) -> 3 | V11: =SUM(F14:F17) -> 2 | W11: =SUM(G14:G17) -> 0 | X11: =SUM(H14:H17) -> 0 | Y11: =SUM(I14:I17) -> 9 | Z11: =SUM(J14:J17) -> 4 | ... AF11: =SUM(P14:P17) -> 240
B12: 07.30 - 07.45 | C12: 8 | D12: 2 | E12: 0 | F12: 0 | G12: 1 | H12: 0 | I12: 5 | J12: 0 | K12: 0 | L12: 0 | M12: 22 | N12: 0 | O12: =SUM(C12:L12,N12) -> 16 | P12: =SUM(C12:N12) -> 38 | R12: 0900-1000 | S12: =SUM(C18:C21) -> 23 | T12: =SUM(D18:D21) -> 7 | U12: =SUM(E18:E21) -> 3 | V12: =SUM(F18:F21) -> 5 | W12: =SUM(G18:G21) -> 0 | X12: =SUM(H18:H21) -> 0 | Y12: =SUM(I18:I21) -> 11 | Z12: =SUM(J18:J21) -> 2 | ... AF12: =SUM(P18:P21) -> 206
B13: 07.45 - 08.00 | C13: 6 | D13: 1 | E13: 1 | F13: 0 | G13: 0 | H13: 0 | I13: 1 | J13: 0 | K13: 0 | L13: 0 | M13: 24 | N13: 0 | O13: =SUM(C13:L13,N13) -> 9 | P13: =SUM(C13:N13) -> 33 | R13: 1000-1100 | S13: =SUM(C22:C25) -> 21 | T13: =SUM(D22:D25) -> 10 | U13: =SUM(E22:E25) -> 4 | V13: =SUM(F22:F25) -> 4 | W13: =SUM(G22:G25) -> 0 | X13: =SUM(H22:H25) -> 0 | Y13: =SUM(I22:I25) -> 11 | Z13: =SUM(J22:J25) -> 1 | ... AF13: =SUM(P22:P25) -> 216
B14: 08.00 - 08.15 | C14: 7 | D14: 0 | E14: 1 | F14: 0 | G14: 0 | H14: 0 | I14: 5 | J14: 2 | K14: 0 | L14: 0 | M14: 50 | N14: 0 | O14: =SUM(C14:L14,N14) -> 15 | P14: =SUM(C14:N14) -> 65 | R14: 1100-1200 | S14: =SUM(C26:C29) -> 23 | T14: =SUM(D26:D29) -> 5 | U14: =SUM(E26:E29) -> 2 | V14: =SUM(F26:F29) -> 2 | W14: =SUM(G26:G29) -> 0 | X14: =SUM(H26:H29) -> 0 | Y14: =SUM(I26:I29) -> 14 | Z14: =SUM(J26:J29) -> 0 | ... AF14: =SUM(P26:P29) -> 176
B15: 08.15 - 08.30 | C15: 14 | D15: 2 | E15: 1 | F15: 1 | G15: 0 | H15: 0 | I15: 2 | J15: 0 | K15: 0 | L15: 0 | M15: 42 | N15: 0 | O15: =SUM(C15:L15,N15) -> 20 | P15: =SUM(C15:N15) -> 62 | R15: 1200-1300 | S15: =SUM(C30:C33) -> 24 | T15: =SUM(D30:D33) -> 9 | U15: =SUM(E30:E33) -> 2 | V15: =SUM(F30:F33) -> 2 | W15: =SUM(G30:G33) -> 0 | X15: =SUM(H30:H33) -> 0 | Y15: =SUM(I30:I33) -> 10 | Z15: =SUM(J30:J33) -> 2 | ... AF15: =SUM(P30:P33) -> 169
B16: 08.30 - 08.45 | C16: 0 | D16: 1 | E16: 0 | F16: 1 | G16: 0 | H16: 0 | I16: 2 | J16: 2 | K16: 0 | L16: 0 | M16: 59 | N16: 0 | O16: =SUM(C16:L16,N16) -> 6 | P16: =SUM(C16:N16) -> 65 | R16: 1300-1400 | S16: =SUM(C34:C37) -> 19 | T16: =SUM(D34:D37) -> 14 | U16: =SUM(E34:E37) -> 3 | V16: =SUM(F34:F37) -> 2 | W16: =SUM(G34:G37) -> 0 | X16: =SUM(H34:H37) -> 0 | Y16: =SUM(I34:I37) -> 13 | Z16: =SUM(J34:J37) -> 1 | ... AF16: =SUM(P34:P37) -> 134
B17: 08.45 - 9.00 | C17: 8 | D17: 1 | E17: 1 | F17: 0 | G17: 0 | H17: 0 | I17: 0 | J17: 0 | K17: 0 | L17: 0 | M17: 38 | N17: 0 | O17: =SUM(C17:L17,N17) -> 10 | P17: =SUM(C17:N17) -> 48 | R17: 1400-1500 | S17: =SUM(C38:C41) -> 17 | T17: =SUM(D38:D41) -> 6 | U17: =SUM(E38:E41) -> 3 | V17: =SUM(F38:F41) -> 0 | W17: =SUM(G38:G41) -> 0 | X17: =SUM(H38:H41) -> 0 | Y17: =SUM(I38:I41) -> 9 | Z17: =SUM(J38:J41) -> 0 | ... AF17: =SUM(P38:P41) -> 104
B18: 09.00 - 09.15 | C18: 9 | D18: 3 | E18: 1 | F18: 1 | G18: 0 | H18: 0 | I18: 5 | J18: 0 | K18: 0 | L18: 0 | M18: 36 | N18: 0 | O18: =SUM(C18:L18,N18) -> 19 | P18: =SUM(C18:N18) -> 55 | R18: 1500-1600 | S18: =SUM(C42:C45) -> 18 | T18: =SUM(D42:D45) -> 5 | U18: =SUM(E42:E45) -> 3 | V18: =SUM(F42:F45) -> 3 | W18: =SUM(G42:G45) -> 0 | X18: =SUM(H42:H45) -> 0 | Y18: =SUM(I42:I45) -> 6 | Z18: =SUM(J42:J45) -> 0 | ... AF18: =SUM(P42:P45) -> 133
B19: 09.15 - 09.30 | C19: 4 | D19: 2 | E19: 0 | F19: 0 | G19: 0 | H19: 0 | I19: 3 | J19: 0 | K19: 0 | L19: 0 | M19: 42 | N19: 0 | O19: =SUM(C19:L19,N19) -> 9 | P19: =SUM(C19:N19) -> 51 | R19: 1600-1700 | S19: =SUM(C46:C49) -> 19 | T19: =SUM(D46:D49) -> 5 | U19: =SUM(E46:E49) -> 1 | V19: =SUM(F46:F49) -> 10 | W19: =SUM(G46:G49) -> 1 | X19: =SUM(H46:H49) -> 0 | Y19: =SUM(I46:I49) -> 12 | Z19: =SUM(J46:J49) -> 0 | ... AF19: =SUM(P46:P49) -> 105
B20: 09.30 - 09.45 | C20: 5 | D20: 0 | E20: 2 | F20: 2 | G20: 0 | H20: 0 | I20: 1 | J20: 0 | K20: 0 | L20: 0 | M20: 42 | N20: 0 | O20: =SUM(C20:L20,N20) -> 10 | P20: =SUM(C20:N20) -> 52 | R20: 1700-1800 | S20: =SUM(C50:C53) -> 8 | T20: =SUM(D50:D53) -> 9 | U20: =SUM(E50:E53) -> 1 | V20: =SUM(F50:F53) -> 4 | W20: =SUM(G50:G53) -> 1 | X20: =SUM(H50:H53) -> 0 | Y20: =SUM(I50:I53) -> 7 | Z20: =SUM(J50:J53) -> 2 | ... AF20: =SUM(P50:P53) -> 130
B21: 09.45 - 10.00 | C21: 5 | D21: 2 | E21: 0 | F21: 2 | G21: 0 | H21: 0 | I21: 2 | J21: 2 | K21: 0 | L21: 0 | M21: 35 | N21: 0 | O21: =SUM(C21:L21,N21) -> 13 | P21: =SUM(C21:N21) -> 48 | R21: 1800-1900 | S21: =SUM(C54:C57) -> 25 | T21: =SUM(D54:D57) -> 3 | U21: =SUM(E54:E57) -> 0 | V21: =SUM(F54:F57) -> 2 | W21: =SUM(G54:G57) -> 1 | X21: =SUM(H54:H57) -> 1 | Y21: =SUM(I54:I57) -> 8 | Z21: =SUM(J54:J57) -> 1 | ... AF21: =SUM(P54:P57) -> 166
B22: 10.00 - 10.15 | C22: 5 | D22: 2 | E22: 0 | F22: 1 | G22: 0 | H22: 0 | I22: 2 | J22: 1 | K22: 0 | L22: 0 | M22: 36 | N22: 0 | O22: =SUM(C22:L22,N22) -> 11 | P22: =SUM(C22:N22) -> 47 | R22: AM Peak Hr | S22: =MAX(S10:S12) -> 34 | T22: =MAX(T10:T12) -> 7 | U22: =MAX(U10:U12) -> 3 | V22: =MAX(V10:V12) -> 5 | W22: =MAX(W10:W12) -> 1 | X22: =MAX(X10:X12) -> 0 | Y22: =MAX(Y10:Y12) -> 11 | Z22: =MAX(Z10:Z12) -> 4 | ... AF22: =MAX(AF10:AF12) -> 240
B23: 10.15 - 10.30 | C23: 6 | D23: 3 | E23: 2 | F23: 1 | G23: 0 | H23: 0 | I23: 1 | J23: 0 | K23: 0 | L23: 0 | M23: 33 | N23: 0 | O23: =SUM(C23:L23,N23) -> 13 | P23: =SUM(C23:N23) -> 46 | R23: IP Peak Hr | S23: =MAX(S13:S18) -> 24 | T23: =MAX(T13:T18) -> 14 | U23: =MAX(U13:U18) -> 4 | V23: =MAX(V13:V18) -> 4 | W23: =MAX(W13:W18) -> 0 | X23: =MAX(X13:X18) -> 0 | Y23: =MAX(Y13:Y18) -> 14 | Z23: =MAX(Z13:Z18) -> 2 | ... AF23: =MAX(AF13:AF18) -> 216
B24: 10.30 - 10.45 | C24: 4 | D24: 5 | E24: 1 | F24: 1 | G24: 0 | H24: 0 | I24: 1 | J24: 0 | K24: 0 | L24: 0 | M24: 41 | N24: 0 | O24: =SUM(C24:L24,N24) -> 12 | P24: =SUM(C24:N24) -> 53 | R24: PM Peak Hr | S24: =MAX(S19:S21) -> 25 | T24: =MAX(T19:T21) -> 9 | U24: =MAX(U19:U21) -> 1 | V24: =MAX(V19:V21) -> 10 | W24: =MAX(W19:W21) -> 1 | X24: =MAX(X19:X21) -> 1 | Y24: =MAX(Y19:Y21) -> 12 | Z24: =MAX(Z19:Z21) -> 2 | ... AF24: =MAX(AF19:AF21) -> 166
B25: 10.45 - 11.00 | C25: 6 | D25: 0 | E25: 1 | F25: 1 | G25: 0 | H25: 0 | I25: 7 | J25: 0 | K25: 0 | L25: 0 | M25: 55 | N25: 0 | O25: =SUM(C25:L25,N25) -> 15 | P25: =SUM(C25:N25) -> 70 | R25: AM Period | S25: =SUM(S10:S12) -> 86 | T25: =SUM(T10:T12) -> 18 | U25: =SUM(U10:U12) -> 9 | V25: =SUM(V10:V12) -> 12 | W25: =SUM(W10:W12) -> 1 | X25: =SUM(X10:X12) -> 0 | Y25: =SUM(Y10:Y12) -> 31 | Z25: =SUM(Z10:Z12) -> 6 | ... AF25: =SUM(AF10:AF12) -> 604
B26: 11.00 - 11.15 | C26: 4 | D26: 1 | E26: 1 | F26: 0 | G26: 0 | H26: 0 | I26: 2 | J26: 0 | K26: 1 | L26: 0 | M26: 35 | N26: 0 | O26: =SUM(C26:L26,N26) -> 9 | P26: =SUM(C26:N26) -> 44 | R26: IP Period | S26: =SUM(S13:S18) -> 122 | T26: =SUM(T13:T18) -> 49 | U26: =SUM(U13:U18) -> 17 | V26: =SUM(V13:V18) -> 13 | W26: =SUM(W13:W18) -> 0 | X26: =SUM(X13:X18) -> 0 | Y26: =SUM(Y13:Y18) -> 63 | Z26: =SUM(Z13:Z18) -> 4 | ... AF26: =SUM(AF13:AF18) -> 932
B27: 11.15 - 11.30 | C27: 8 | D27: 2 | E27: 0 | F27: 0 | G27: 0 | H27: 0 | I27: 2 | J27: 0 | K27: 0 | L27: 0 | M27: 24 | N27: 0 | O27: =SUM(C27:L27,N27) -> 12 | P27: =SUM(C27:N27) -> 36 | R27: PM Period | S27: =SUM(S19:S21) -> 52 | T27: =SUM(T19:T21) -> 17 | U27: =SUM(U19:U21) -> 2 | V27: =SUM(V19:V21) -> 16 | W27: =SUM(W19:W21) -> 3 | X27: =SUM(X19:X21) -> 1 | Y27: =SUM(Y19:Y21) -> 27 | Z27: =SUM(Z19:Z21) -> 3 | ... AF27: =SUM(AF19:AF21) -> 401
B28: 11.30 - 11.45 | C28: 6 | D28: 2 | E28: 1 | F28: 1 | G28: 0 | H28: 0 | I28: 5 | J28: 0 | K28: 0 | L28: 0 | M28: 42 | N28: 0 | O28: =SUM(C28:L28,N28) -> 15 | P28: =SUM(C28:N28) -> 57 | R28: 12 Hours | S28: =SUM(S10:S21) -> 260 | T28: =SUM(T10:T21) -> 84 | U28: =SUM(U10:U21) -> 28 | V28: =SUM(V10:V21) -> 41 | W28: =SUM(W10:W21) -> 4 | X28: =SUM(X10:X21) -> 1 | Y28: =SUM(Y10:Y21) -> 121 | Z28: =SUM(Z10:Z21) -> 13 | ... AF28: =SUM(AF10:AF21) -> 1937
B29: 11.45 - 12.00 | C29: 5 | D29: 0 | E29: 0 | F29: 1 | G29: 0 | H29: 0 | I29: 5 | J29: 0 | K29: 0 | L29: 0 | M29: 28 | N29: 0 | O29: =SUM(C29:L29,N29) -> 11 | P29: =SUM(C29:N29) -> 39
B30: 12.00 - 12.15 | C30: 8 | D30: 1 | E30: 0 | F30: 1 | G30: 0 | H30: 0 | I30: 3 | J30: 0 | K30: 0 | L30: 0 | M30: 25 | N30: 0 | O30: =SUM(C30:L30,N30) -> 13 | P30: =SUM(C30:N30) -> 38
B31: 12.15 - 12.30 | C31: 5 | D31: 2 | E31: 0 | F31: 0 | G31: 0 | H31: 0 | I31: 1 | J31: 0 | K31: 0 | L31: 0 | M31: 37 | N31: 0 | O31: =SUM(C31:L31,N31) -> 8 | P31: =SUM(C31:N31) -> 45
B32: 12.30 - 12.45 | C32: 5 | D32: 4 | E32: 0 | F32: 0 | G32: 0 | H32: 0 | I32: 2 | J32: 1 | K32: 0 | L32: 0 | M32: 27 | N32: 0 | O32: =SUM(C32:L32,N32) -> 12 | P32: =SUM(C32:N32) -> 39
B33: 12.45 - 13.00 | C33: 6 | D33: 2 | E33: 2 | F33: 1 | G33: 0 | H33: 0 | I33: 4 | J33: 1 | K33: 0 | L33: 0 | M33: 31 | N33: 0 | O33: =SUM(C33:L33,N33) -> 16 | P33: =SUM(C33:N33) -> 47
B34: 13.00 - 13.15 | C34: 8 | D34: 8 | E34: 0 | F34: 0 | G34: 0 | H34: 0 | I34: 8 | J34: 0 | K34: 0 | L34: 0 | M34: 21 | N34: 0 | O34: =SUM(C34:L34,N34) -> 24 | P34: =SUM(C34:N34) -> 45
B35: 13.15 - 13.30 | C35: 4 | D35: 1 | E35: 0 | F35: 0 | G35: 0 | H35: 0 | I35: 0 | J35: 0 | K35: 0 | L35: 0 | M35: 14 | N35: 0 | O35: =SUM(C35:L35,N35) -> 5 | P35: =SUM(C35:N35) -> 19
B36: 13.30 - 13.45 | C36: 2 | D36: 0 | E36: 2 | F36: 2 | G36: 0 | H36: 0 | I36: 2 | J36: 1 | K36: 0 | L36: 0 | M36: 33 | N36: 0 | O36: =SUM(C36:L36,N36) -> 9 | P36: =SUM(C36:N36) -> 42
B37: 13.45 - 14.00 | C37: 5 | D37: 5 | E37: 1 | F37: 0 | G37: 0 | H37: 0 | I37: 3 | J37: 0 | K37: 0 | L37: 0 | M37: 14 | N37: 0 | O37: =SUM(C37:L37,N37) -> 14 | P37: =SUM(C37:N37) -> 28
B38: 14.00 - 14.15 | C38: 1 | D38: 0 | E38: 2 | F38: 0 | G38: 0 | H38: 0 | I38: 2 | J38: 0 | K38: 0 | L38: 0 | M38: 16 | N38: 0 | O38: =SUM(C38:L38,N38) -> 5 | P38: =SUM(C38:N38) -> 21
B39: 14.15 - 14.30 | C39: 2 | D39: 5 | E39: 1 | F39: 0 | G39: 0 | H39: 0 | I39: 2 | J39: 0 | K39: 0 | L39: 0 | M39: 15 | N39: 0 | O39: =SUM(C39:L39,N39) -> 10 | P39: =SUM(C39:N39) -> 25
B40: 14.30 - 14.45 | C40: 8 | D40: 1 | E40: 0 | F40: 0 | G40: 0 | H40: 0 | I40: 1 | J40: 0 | K40: 0 | L40: 0 | M40: 16 | N40: 0 | O40: =SUM(C40:L40,N40) -> 10 | P40: =SUM(C40:N40) -> 26
... B57: 18.45 - 19.00 | C57: 4 | D57: 0 | E57: 0 | F57: 0 | G57: 0 | H57: 0 | I57: 3 | J57: 0 | K57: 0 | L57: 0 | M57: 17 | N57: 0 | O57: =SUM(C57:L57,N57) -> 7 | P57: =SUM(C57:N57) -> 24
B58: Totals | C58: =SUM(C10:C57) -> 260 | D58: =SUM(D10:D57) -> 84 | E58: =SUM(E10:E57) -> 28 | F58: =SUM(F10:F57) -> 41 | G58: =SUM(G10:G57) -> 4 | H58: =SUM(H10:H57) -> 1 | I58: =SUM(I10:I57) -> 121 | J58: =SUM(J10:J57) -> 13 | ... P58: =SUM(P10:P57) -> 1937
...

Sheet 23.09.19 Kajansi -Bweya
B1: Consultancy services for Preparation of Expressway Development Master Plan (EDMP) for Uganda
B2: MANUAL CLASSIFIED COUNT (MCC)
B3: ROAD NAME: | C3: ='23.09.19 Bweya- Kajansi'!C3:G3 -> MCC-C2-STNO 56 -Munyonyo spur
C5: Date | D5: ='23.09.19 Bweya- Kajansi'!D5 -> 23.09.19 | F5: Location | G5: ='23.09.19 Bweya- Kajansi'!G5:H5 -> Munyonyo Spur RD | J5: Surveyor | K5: Kasajja Laston
C6: Dir. From | D6: KAJANSI | F6: Dir. To | G6: BWEYA | J6: Supervisor | K6: ='23.09.19 Bweya- Kajansi'!K6:L6 -> Beatrice
B8: Time / Veh Type | R8: SUMMARY TRAFFIC VOLUMES
C9: 1. Car | D9: 2. Station Wagon | E9: 3. Pickups | F9: 4. Minibus, matatu | G9: 5. Medium bus | H9: 6. Large Bus | I9: 7. Light Truck | J9: 8. Medium Truck | K9: 9. Heavy truck | L9: 10. Truck Trailer | M9: 11. Motor cycles | N9: 12. Tractors | O9: Total Excl M/Cycles | P9: Total All | R9: Time | S9: 1. Car | T9: 2. Station Wagon | U9: 3. Pickups | V9: 4. Minibus, matatu | W9: 5. Medium bus | X9: 6. Large Bus | Y9: 7. Light Truck | Z9: 8. Medium Truck | AA9: 9. Heavy truck | AB9: 10. Truck Trailer | AC9: 11. Motorcycles | AD9: 12. Tractors, Graders | AE9: Total Excl M/ Cycles | AF9: Total All
B10: 07.00 - 07.15 | C10: 4 | D10: 1 | E10: 0 | F10: 1 | G10: 0 | H10: 0 | I10: 0 | J10: 0 | K10: 0 | L10: 0 | M10: 11 | N10: 0 | O10: =SUM(C10:L10,N10) -> 6 | P10: =SUM(C10:N10) -> 17 | R10: 0700-0800 | S10: =SUM(C10:C13) -> 18 | T10: =SUM(D10:D13) -> 5 | U10: =SUM(E10:E13) -> 1 | V10: =SUM(F10:F13) -> 1 | W10: =SUM(G10:G13) -> 0 | X10: =SUM(H10:H13) -> 0 | Y10: =SUM(I10:I13) -> 0 | Z10: =SUM(J10:J13) -> 0 | ... AF10: =SUM(P10:P13) -> 93
B11: 07.15 - 07.30 | C11: 3 | D11: 2 | E11: 0 | F11: 0 | G11: 0 | H11: 0 | I11: 0 | J11: 0 | K11: 0 | L11: 0 | M11: 16 | N11: 0 | O11: =SUM(C11:L11,N11) -> 5 | P11: =SUM(C11:N11) -> 21 | R11: 0800-0900 | S11: =SUM(C14:C17) -> 10 | T11: =SUM(D14:D17) -> 3 | U11: =SUM(E14:E17) -> 3 | V11: =SUM(F14:F17) -> 0 | W11: =SUM(G14:G17) -> 0 | X11: =SUM(H14:H17) -> 0 | Y11: =SUM(I14:I17) -> 10 | Z11: =SUM(J14:J17) -> 2 | ... AF11: =SUM(P14:P17) -> 180
B12: 07.30 - 07.45 | C12: 6 | D12: 1 | E12: 1 | F12: 0 | G12: 0 | H12: 0 | I12: 0 | J12: 0 | K12: 0 | L12: 0 | M12: 14 | N12: 0 | O12: =SUM(C12:L12,N12) -> 8 | P12: =SUM(C12:N12) -> 22 | R12: 0900-1000 | S12: =SUM(C18:C21) -> 8 | T12: =SUM(D18:D21) -> 5 | U12: =SUM(E18:E21) -> 3 | V12: =SUM(F18:F21) -> 0 | W12: =SUM(G18:G21) -> 0 | X12: =SUM(H18:H21) -> 0 | Y12: =SUM(I18:I21) -> 4 | Z12: =SUM(J18:J21) -> 1 | ... AF12: =SUM(P18:P21) -> 150
B13: 07.45 - 08.00 | C13: 5 | D13: 1 | E13: 0 | F13: 0 | G13: 0 | H13: 0 | I13: 0 | J13: 0 | K13: 0 | L13: 0 | M13: 27 | N13: 0 | O13: =SUM(C13:L13,N13) -> 6 | P13: =SUM(C13:N13) -> 33 | R13: 1000-1100 | S13: =SUM(C22:C25) -> 11 | T13: =SUM(D22:D25) -> 2 | U13: =SUM(E22:E25) -> 2 | V13: =SUM(F22:F25) -> 3 | W13: =SUM(G22:G25) -> 0 | X13: =SUM(H22:H25) -> 0 | Y13: =SUM(I22:I25) -> 8 | Z13: =SUM(J22:J25) -> 0 | ... AF13: =SUM(P22:P25) -> 148
B14: 08.00 - 08.15 | C14: 2 | D14: 1 | E14: 2 | F14: 0 | G14: 0 | H14: 0 | I14: 3 | J14: 0 | K14: 0 | L14: 0 | M14: 38 | N14: 0 | O14: =SUM(C14:L14,N14) -> 8 | P14: =SUM(C14:N14) -> 46 | R14: 1100-1200 | S14: =SUM(C26:C29) -> 14 | T14: =SUM(D26:D29) -> 6 | U14: =SUM(E26:E29) -> 2 | V14: =SUM(F26:F29) -> 2 | W14: =SUM(G26:G29) -> 0 | X14: =SUM(H26:H29) -> 0 | Y14: =SUM(I26:I29) -> 18 | Z14: =SUM(J26:J29) -> 0 | ... AF14: =SUM(P26:P29) -> 182
B15: 08.15 - 08.30 | C15: 5 | D15: 1 | E15: 0 | F15: 0 | G15: 0 | H15: 0 | I15: 0 | J15: 1 | K15: 0 | L15: 0 | M15: 36 | N15: 0 | O15: =SUM(C15:L15,N15) -> 7 | P15: =SUM(C15:N15) -> 43 | R15: 1200-1300 | S15: =SUM(C30:C33) -> 16 | T15: =SUM(D30:D33) -> 3 | U15: =SUM(E30:E33) -> 1 | V15: =SUM(F30:F33) -> 1 | W15: =SUM(G30:G33) -> 0 | X15: =SUM(H30:H33) -> 0 | Y15: =SUM(I30:I33) -> 10 | Z15: =SUM(J30:J33) -> 3 | ... AF15: =SUM(P30:P33) -> 153
B16: 08.30 - 08.45 | C16: 1 | D16: 1 | E16: 0 | F16: 0 | G16: 0 | H16: 0 | I16: 5 | J16: 1 | K16: 0 | L16: 0 | M16: 53 | N16: 0 | O16: =SUM(C16:L16,N16) -> 8 | P16: =SUM(C16:N16) -> 61 | R16: 1300-1400 | S16: =SUM(C34:C37) -> 23 | T16: =SUM(D34:D37) -> 2 | U16: =SUM(E34:E37) -> 1 | V16: =SUM(F34:F37) -> 1 | W16: =SUM(G34:G37) -> 1 | X16: =SUM(H34:H37) -> 0 | Y16: =SUM(I34:I37) -> 10 | Z16: =SUM(J34:J37) -> 1 | ... AF16: =SUM(P34:P37) -> 139
B17: 08.45 - 9.00 | C17: 2 | D17: 0 | E17: 1 | F17: 0 | G17: 0 | H17: 0 | I17: 2 | J17: 0 | K17: 0 | L17: 0 | M17: 25 | N17: 0 | O17: =SUM(C17:L17,N17) -> 5 | P17: =SUM(C17:N17) -> 30 | R17: 1400-1500 | S17: =SUM(C38:C41) -> 23 | T17: =SUM(D38:D41) -> 2 | U17: =SUM(E38:E41) -> 2 | V17: =SUM(F38:F41) -> 1 | W17: =SUM(G38:G41) -> 0 | X17: =SUM(H38:H41) -> 0 | Y17: =SUM(I38:I41) -> 11 | Z17: =SUM(J38:J41) -> 3 | ... AF17: =SUM(P38:P41) -> 176
B18: 09.00 - 09.15 | C18: 0 | D18: 0 | E18: 1 | F18: 0 | G18: 0 | H18: 0 | I18: 3 | J18: 0 | K18: 0 | L18: 0 | M18: 42 | N18: 0 | O18: =SUM(C18:L18,N18) -> 4 | P18: =SUM(C18:N18) -> 46 | R18: 1500-1600 | S18: =SUM(C42:C45) -> 15 | T18: =SUM(D42:D45) -> 1 | U18: =SUM(E42:E45) -> 0 | V18: =SUM(F42:F45) -> 0 | W18: =SUM(G42:G45) -> 0 | X18: =SUM(H42:H45) -> 0 | Y18: =SUM(I42:I45) -> 7 | Z18: =SUM(J42:J45) -> 3 | ... AF18: =SUM(P42:P45) -> 154
B19: 09.15 - 09.30 | C19: 3 | D19: 1 | E19: 1 | F19: 0 | G19: 0 | H19: 0 | I19: 1 | J19: 1 | K19: 0 | L19: 0 | M19: 34 | N19: 0 | O19: =SUM(C19:L19,N19) -> 7 | P19: =SUM(C19:N19) -> 41 | R19: 1600-1700 | S19: =SUM(C46:C49) -> 30 | T19: =SUM(D46:D49) -> 1 | U19: =SUM(E46:E49) -> 0 | V19: =SUM(F46:F49) -> 1 | W19: =SUM(G46:G49) -> 0 | X19: =SUM(H46:H49) -> 0 | Y19: =SUM(I46:I49) -> 5 | Z19: =SUM(J46:J49) -> 1 | ... AF19: =SUM(P46:P49) -> 126
B20: 09.30 - 09.45 | C20: 1 | D20: 4 | E20: 0 | F20: 0 | G20: 0 | H20: 0 | I20: 0 | J20: 0 | K20: 0 | L20: 0 | M20: 44 | N20: 0 | O20: =SUM(C20:L20,N20) -> 5 | P20: =SUM(C20:N20) -> 49 | R20: 1700-1800 | S20: =SUM(C50:C53) -> 20 | T20: =SUM(D50:D53) -> 0 | U20: =SUM(E50:E53) -> 0 | V20: =SUM(F50:F53) -> 0 | W20: =SUM(G50:G53) -> 0 | X20: =SUM(H50:H53) -> 0 | Y20: =SUM(I50:I53) -> 4 | Z20: =SUM(J50:J53) -> 1 | ... AF20: =SUM(P50:P53) -> 98
B21: 09.45 - 10.00 | C21: 4 | D21: 0 | E21: 1 | F21: 0 | G21: 0 | H21: 0 | I21: 0 | J21: 0 | K21: 0 | L21: 0 | M21: 9 | N21: 0 | O21: =SUM(C21:L21,N21) -> 5 | P21: =SUM(C21:N21) -> 14 | R21: 1800-1900 | S21: =SUM(C54:C57) -> 19 | T21: =SUM(D54:D57) -> 0 | U21: =SUM(E54:E57) -> 1 | V21: =SUM(F54:F57) -> 1 | W21: =SUM(G54:G57) -> 1 | X21: =SUM(H54:H57) -> 0 | Y21: =SUM(I54:I57) -> 4 | Z21: =SUM(J54:J57) -> 3 | ... AF21: =SUM(P54:P57) -> 143
B22: 10.00 - 10.15 | C22: 3 | D22: 1 | E22: 0 | F22: 1 | G22: 0 | H22: 0 | I22: 4 | J22: 0 | K22: 0 | L22: 0 | M22: 40 | N22: 0 | O22: =SUM(C22:L22,N22) -> 9 | P22: =SUM(C22:N22) -> 49 | R22: AM Peak Hr | S22: =MAX(S10:S12) -> 18 | T22: =MAX(T10:T12) -> 5 | U22: =MAX(U10:U12) -> 3 | V22: =MAX(V10:V12) -> 1 | W22: =MAX(W10:W12) -> 0 | X22: =MAX(X10:X12) -> 0 | Y22: =MAX(Y10:Y12) -> 10 | Z22: =MAX(Z10:Z12) -> 2 | ... AF22: =MAX(AF10:AF12) -> 180
B23: 10.15 - 10.30 | C23: 2 | D23: 0 | E23: 1 | F23: 2 | G23: 0 | H23: 0 | I23: 2 | J23: 0 | K23: 0 | L23: 0 | M23: 16 | N23: 0 | O23: =SUM(C23:L23,N23) -> 7 | P23: =SUM(C23:N23) -> 23 | R23: IP Peak Hr | S23: =MAX(S13:S18) -> 23 | T23: =MAX(T13:T18) -> 6 | U23: =MAX(U13:U18) -> 2 | V23: =MAX(V13:V18) -> 3 | W23: =MAX(W13:W18) -> 1 | X23: =MAX(X13:X18) -> 0 | Y23: =MAX(Y13:Y18) -> 18 | Z23: =MAX(Z13:Z18) -> 3 | ... AF23: =MAX(AF13:AF18) -> 182
B24: 10.30 - 10.45 | C24: 3 | D24: 1 | E24: 1 | F24: 0 | G24: 0 | H24: 0 | I24: 2 | J24: 0 | K24: 0 | L24: 0 | M24: 27 | N24: 0 | O24: =SUM(C24:L24,N24) -> 7 | P24: =SUM(C24:N24) -> 34 | R24: PM Peak Hr | S24: =MAX(S19:S21) -> 30 | T24: =MAX(T19:T21) -> 1 | U24: =MAX(U19:U21) -> 1 | V24: =MAX(V19:V21) -> 1 | W24: =MAX(W19:W21) -> 1 | X24: =MAX(X19:X21) -> 0 | Y24: =MAX(Y19:Y21) -> 5 | Z24: =MAX(Z19:Z21) -> 3 | ... AF24: =MAX(AF19:AF21) -> 143
B25: 10.45 - 11.00 | C25: 3 | D25: 0 | E25: 0 | F25: 0 | G25: 0 | H25: 0 | I25: 0 | J25: 0 | K25: 0 | L25: 0 | M25: 39 | N25: 0 | O25: =SUM(C25:L25,N25) -> 3 | P25: =SUM(C25:N25) -> 42 | R25: AM Period | S25: =SUM(S10:S12) -> 36 | T25: =SUM(T10:T12) -> 13 | U25: =SUM(U10:U12) -> 7 | V25: =SUM(V10:V12) -> 1 | W25: =SUM(W10:W12) -> 0 | X25: =SUM(X10:X12) -> 0 | Y25: =SUM(Y10:Y12) -> 14 | Z25: =SUM(Z10:Z12) -> 3 | ... AF25: =SUM(AF10:AF12) -> 423
B26: 11.00 - 11.15 | C26: 1 | D26: 0 | E26: 0 | F26: 0 | G26: 0 | H26: 0 | I26: 3 | J26: 0 | K26: 0 | L26: 0 | M26: 27 | N26: 0 | O26: =SUM(C26:L26,N26) -> 4 | P26: =SUM(C26:N26) -> 31 | R26: IP Period | S26: =SUM(S13:S18) -> 102 | T26: =SUM(T13:T18) -> 16 | U26: =SUM(U13:U18) -> 8 | V26: =SUM(V13:V18) -> 8 | W26: =SUM(W13:W18) -> 1 | X26: =SUM(X13:X18) -> 0 | Y26: =SUM(Y13:Y18) -> 64 | Z26: =SUM(Z13:Z18) -> 10 | ... AF26: =SUM(AF13:AF18) -> 952
B27: 11.15 - 11.30 | C27: 6 | D27: 1 | E27: 0 | F27: 2 | G27: 0 | H27: 0 | I27: 6 | J27: 0 | K27: 0 | L27: 0 | M27: 40 | N27: 0 | O27: =SUM(C27:L27,N27) -> 15 | P27: =SUM(C27:N27) -> 55 | R27: PM Period | S27: =SUM(S19:S21) -> 69 | T27: =SUM(T19:T21) -> 1 | U27: =SUM(U19:U21) -> 1 | V27: =SUM(V19:V21) -> 2 | W27: =SUM(W19:W21) -> 1 | X27: =SUM(X19:X21) -> 0 | Y27: =SUM(Y19:Y21) -> 13 | Z27: =SUM(Z19:Z21) -> 5 | ... AF27: =SUM(AF19:AF21) -> 367
B28: 11.30 - 11.45 | C28: 5 | D28: 2 | E28: 0 | F28: 0 | G28: 0 | H28: 0 | I28: 4 | J28: 0 | K28: 0 | L28: 0 | M28: 37 | N28: 0 | O28: =SUM(C28:L28,N28) -> 11 | P28: =SUM(C28:N28) -> 48 | R28: 12 Hours | S28: =SUM(S10:S21) -> 207 | T28: =SUM(T10:T21) -> 30 | U28: =SUM(U10:U21) -> 16 | V28: =SUM(V10:V21) -> 11 | W28: =SUM(W10:W21) -> 2 | X28: =SUM(X10:X21) -> 0 | Y28: =SUM(Y10:Y21) -> 91 | Z28: =SUM(Z10:Z21) -> 18 | ... AF28: =SUM(AF10:AF21) -> 1742
B29: 11.45 - 12.00 | C29: 2 | D29: 3 | E29: 2 | F29: 0 | G29: 0 | H29: 0 | I29: 5 | J29: 0 | K29: 0 | L29: 0 | M29: 36 | N29: 0 | O29: =SUM(C29:L29,N29) -> 12 | P29: =SUM(C29:N29) -> 48
B30: 12.00 - 12.15 | C30: 6 | D30: 1 | E30: 0 | F30: 0 | G30: 0 | H30: 0 | I30: 1 | J30: 0 | K30: 0 | L30: 0 | M30: 25 | N30: 0 | O30: =SUM(C30:L30,N30) -> 8 | P30: =SUM(C30:N30) -> 33
B31: 12.15 - 12.30 | C31: 4 | D31: 0 | E31: 0 | F31: 0 | G31: 0 | H31: 0 | I31: 2 | J31: 0 | K31: 1 | L31: 1 | M31: 37 | N31: 0 | O31: =SUM(C31:L31,N31) -> 8 | P31: =SUM(C31:N31) -> 45
B32: 12.30 - 12.45 | C32: 2 | D32: 0 | E32: 1 | F32: 0 | G32: 0 | H32: 0 | I32: 2 | J32: 3 | K32: 0 | L32: 0 | M32: 25 | N32: 0 | O32: =SUM(C32:L32,N32) -> 8 | P32: =SUM(C32:N32) -> 33
B33: 12.45 - 13.00 | C33: 4 | D33: 2 | E33: 0 | F33: 1 | G33: 0 | H33: 0 | I33: 5 | J33: 0 | K33: 0 | L33: 0 | M33: 30 | N33: 0 | O33: =SUM(C33:L33,N33) -> 12 | P33: =SUM(C33:N33) -> 42
B34: 13.00 - 13.15 | C34: 3 | D34: 0 | E34: 0 | F34: 1 | G34: 0 | H34: 0 | I34: 5 | J34: 0 | K34: 0 | L34: 0 | M34: 24 | N34: 0 | O34: =SUM(C34:L34,N34) -> 9 | P34: =SUM(C34:N34) -> 33
B35: 13.15 - 13.30 | C35: 9 | D35: 0 | E35: 1 | F35: 0 | G35: 1 | H35: 0 | I35: 1 | J35: 1 | K35: 0 | L35: 0 | M35: 14 | N35: 0 | O35: =SUM(C35:L35,N35) -> 13 | P35: =SUM(C35:N35) -> 27
B36: 13.30 - 13.45 | C36: 6 | D36: 1 | E36: 0 | F36: 0 | G36: 0 | H36: 0 | I36: 2 | J36: 0 | K36: 0 | L36: 0 | M36: 29 | N36: 0 | O36: =SUM(C36:L36,N36) -> 9 | P36: =SUM(C36:N36) -> 38
B37: 13.45 - 14.00 | C37: 5 | D37: 1 | E37: 0 | F37: 0 | G37: 0 | H37: 0 | I37: 2 | J37: 0 | K37: 0 | L37: 0 | M37: 33 | N37: 0 | O37: =SUM(C37:L37,N37) -> 8 | P37: =SUM(C37:N37) -> 41
B38: 14.00 - 14.15 | C38: 3 | D38: 1 | E38: 0 | F38: 0 | G38: 0 | H38: 0 | I38: 4 | J38: 0 | K38: 0 | L38: 0 | M38: 30 | N38: 0 | O38: =SUM(C38:L38,N38) -> 8 | P38: =SUM(C38:N38) -> 38
B39: 14.15 - 14.30 | C39: 7 | D39: 0 | E39: 0 | F39: 1 | G39: 0 | H39: 0 | I39: 2 | J39: 0 | K39: 0 | L39: 0 | M39: 37 | N39: 0 | O39: =SUM(C39:L39,N39) -> 10 | P39: =SUM(C39:N39) -> 47
B40: 14.30 - 14.45 | C40: 5 | D40: 1 | E40: 1 | F40: 0 | G40: 0 | H40: 0 | I40: 1 | J40: 2 | K40: 0 | L40: 0 | M40: 40 | N40: 0 | O40: =SUM(C40:L40,N40) -> 10 | P40: =SUM(C40:N40) -> 50
... B57: 18.45 - 19.00 | C57: 3 | D57: 0 | E57: 0 | F57: 0 | G57: 0 | H57: 0 | I57: 1 | J57: 0 | K57: 1 | L57: 0 | M57: 40 | N57: 0 | O57: =SUM(C57:L57,N57) -> 5 | P57: =SUM(C57:N57) -> 45
B58: Totals | C58: =SUM(C10:C57) -> 207 | D58: =SUM(D10:D57) -> 30 | E58: =SUM(E10:E57) -> 16 | F58: =SUM(F10:F57) -> 11 | G58: =SUM(G10:G57) -> 2 | H58: =SUM(H10:H57) -> 0 | I58: =SUM(I10:I57) -> 91 | J58: =SUM(J10:J57) -> 18 | ... P58: =SUM(P10:P57) -> 1742
...

Sheet 24.09 Bweya-Kajansi
B1: Consultancy services for Preparation of Expressway Development Master Plan (EDMP) for Uganda
B2: MANUAL CLASSIFIED COUNT (MCC)
B3: ROAD NAME: | C3: MCC - C2- STN56- MUNYONYO SPUR
C5: Date | D5: 24.09.19 | F5: Location | G5: KAWALI (56) | J5: Surveyor | K5: KASOMA JOHN
C6: Dir. From | D6: MUNYONYO | F6: Dir. To | G6: KAJJANSI | J6: Supervisor | K6: BEATRICE
B8: Time / Veh Type | R8: SUMMARY TRAFFIC VOLUMES
C9: 1. Car | D9: 2. Station Wagon | E9: 3. Pickups | F9: 4. Minibus, matatu | G9: 5. Medium bus | H9: 6. Large Bus | I9: 7. Light Truck | J9: 8. Medium Truck | K9: 9. Heavy truck | L9: 10. Truck Trailer | M9: 11. Motor cycles | N9: 12. Tractors | O9: Total Excl M/Cycles | P9: Total All | R9: Time | S9: 1. Car | T9: 2. Station Wagon | U9: 3. Pickups | V9: 4. Minibus, matatu | W9: 5. Medium bus | X9: 6. Large Bus | Y9: 7. Light Truck | Z9: 8. Medium Truck | AA9: 9. Heavy truck | AB9: 10. Truck Trailer | AC9: 11. Motorcycles | AD9: 12. Tractors, Graders | AE9: Total Excl M/ Cycles | AF9: Total All
B10: 07.00 - 07.15 | C10: 36 | D10: 7 | E10: 4 | F10: 3 | G10: 0 | H10: 0 | I10: 2 | J10: 0 | K10: 0 | L10: 0 | M10: 41 | N10: 0 | O10: =SUM(C10:L10,N10) -> 52 | P10: =SUM(C10:N10) -> 93 | R10: 0700-0800 | S10: =SUM(C10:C13) -> 138 | T10: =SUM(D10:D13) -> 37 | U10: =SUM(E10:E13) -> 10 | V10: =SUM(F10:F13) -> 13 | W10: =SUM(G10:G13) -> 0 | X10: =SUM(H10:H13) -> 1 | Y10: =SUM(I10:I13) -> 6 | Z10: =SUM(J10:J13) -> 0 | ... AF10: =SUM(P10:P13) -> 382
B11: 07.15 - 07.30 | C11: 36 | D11: 11 | E11: 1 | F11: 4 | G11: 0 | H11: 0 | I11: 2 | J11: 0 | K11: 0 | L11: 0 | M11: 44 | N11: 0 | O11: =SUM(C11:L11,N11) -> 54 | P11: =SUM(C11:N11) -> 98 | R11: 0800-0900 | S11: =SUM(C14:C17) -> 124 | T11: =SUM(D14:D17) -> 29 | U11: =SUM(E14:E17) -> 17 | V11: =SUM(F14:F17) -> 6 | W11: =SUM(G14:G17) -> 1 | X11: =SUM(H14:H17) -> 2 | Y11: =SUM(I14:I17) -> 4 | Z11: =SUM(J14:J17) -> 1 | ... AF11: =SUM(P14:P17) -> 367
B12: 07.30 - 07.45 | C12: 26 | D12: 11 | E12: 2 | F12: 1 | G12: 0 | H12: 0 | I12: 0 | J12: 0 | K12: 0 | L12: 0 | M12: 40 | N12: 0 | O12: =SUM(C12:L12,N12) -> 40 | P12: =SUM(C12:N12) -> 80 | R12: 0900-1000 | S12: =SUM(C18:C21) -> 95 | T12: =SUM(D18:D21) -> 44 | U12: =SUM(E18:E21) -> 25 | V12: =SUM(F18:F21) -> 6 | W12: =SUM(G18:G21) -> 3 | X12: =SUM(H18:H21) -> 1 | Y12: =SUM(I18:I21) -> 13 | Z12: =SUM(J18:J21) -> 1 | ... AF12: =SUM(P18:P21) -> 318
B13: 07.45 - 08.00 | C13: 40 | D13: 8 | E13: 3 | F13: 5 | G13: 0 | H13: 1 | I13: 2 | J13: 0 | K13: 0 | L13: 0 | M13: 52 | N13: 0 | O13: =SUM(C13:L13,N13) -> 59 | P13: =SUM(C13:N13) -> 111 | R13: 1000-1100 | S13: =SUM(C22:C25) -> 91 | T13: =SUM(D22:D25) -> 39 | U13: =SUM(E22:E25) -> 21 | V13: =SUM(F22:F25) -> 10 | W13: =SUM(G22:G25) -> 1 | X13: =SUM(H22:H25) -> 0 | Y13: =SUM(I22:I25) -> 19 | Z13: =SUM(J22:J25) -> 1 | ... AF13: =SUM(P22:P25) -> 305
B14: 08.00 - 08.15 | C14: 33 | D14: 5 | E14: 3 | F14: 1 | G14: 1 | H14: 0 | I14: 0 | J14: 0 | K14: 0 | L14: 0 | M14: 52 | N14: 0 | O14: =SUM(C14:L14,N14) -> 43 | P14: =SUM(C14:N14) -> 95 | R14: 1100-1200 | S14: =SUM(C26:C29) -> 92 | T14: =SUM(D26:D29) -> 22 | U14: =SUM(E26:E29) -> 13 | V14: =SUM(F26:F29) -> 5 | W14: =SUM(G26:G29) -> 2 | X14: =SUM(H26:H29) -> 0 | Y14: =SUM(I26:I29) -> 17 | Z14: =SUM(J26:J29) -> 4 | ... AF14: =SUM(P26:P29) -> 265
B15: 08.15 - 08.30 | C15: 38 | D15: 6 | E15: 6 | F15: 3 | G15: 0 | H15: 1 | I15: 0 | J15: 0 | K15: 0 | L15: 0 | M15: 41 | N15: 0 | O15: =SUM(C15:L15,N15) -> 54 | P15: =SUM(C15:N15) -> 95 | R15: 1200-1300 | S15: =SUM(C30:C33) -> 104 | T15: =SUM(D30:D33) -> 16 | U15: =SUM(E30:E33) -> 15 | V15: =SUM(F30:F33) -> 2 | W15: =SUM(G30:G33) -> 0 | X15: =SUM(H30:H33) -> 0 | Y15: =SUM(I30:I33) -> 8 | Z15: =SUM(J30:J33) -> 10 | ... AF15: =SUM(P30:P33) -> 269
B16: 08.30 - 08.45 | C16: 20 | D16: 12 | E16: 3 | F16: 1 | G16: 0 | H16: 1 | I16: 2 | J16: 1 | K16: 0 | L16: 0 | M16: 51 | N16: 0 | O16: =SUM(C16:L16,N16) -> 40 | P16: =SUM(C16:N16) -> 91 | R16: 1300-1400 | S16: =SUM(C34:C37) -> 102 | T16: =SUM(D34:D37) -> 38 | U16: =SUM(E34:E37) -> 11 | V16: =SUM(F34:F37) -> 5 | W16: =SUM(G34:G37) -> 3 | X16: =SUM(H34:H37) -> 0 | Y16: =SUM(I34:I37) -> 33 | Z16: =SUM(J34:J37) -> 2 | ... AF16: =SUM(P34:P37) -> 323
B17: 08.45 - 9.00 | C17: 33 | D17: 6 | E17: 5 | F17: 1 | G17: 0 | H17: 0 | I17: 2 | J17: 0 | K17: 0 | L17: 0 | M17: 39 | N17: 0 | O17: =SUM(C17:L17,N17) -> 47 | P17: =SUM(C17:N17) -> 86 | R17: 1400-1500 | S17: =SUM(C38:C41) -> 67 | T17: =SUM(D38:D41) -> 22 | U17: =SUM(E38:E41) -> 16 | V17: =SUM(F38:F41) -> 3 | W17: =SUM(G38:G41) -> 1 | X17: =SUM(H38:H41) -> 1 | Y17: =SUM(I38:I41) -> 19 | Z17: =SUM(J38:J41) -> 0 | ... AF17: =SUM(P38:P41) -> 246
B18: 09.00 - 09.15 | C18: 20 | D18: 15 | E18: 9 | F18: 3 | G18: 0 | H18: 0 | I18: 4 | J18: 0 | K18: 0 | L18: 0 | M18: 36 | N18: 0 | O18: =SUM(C18:L18,N18) -> 51 | P18: =SUM(C18:N18) -> 87 | R18: 1500-1600 | S18: =SUM(C42:C45) -> 75 | T18: =SUM(D42:D45) -> 22 | U18: =SUM(E42:E45) -> 9 | V18: =SUM(F42:F45) -> 15 | W18: =SUM(G42:G45) -> 1 | X18: =SUM(H42:H45) -> 0 | Y18: =SUM(I42:I45) -> 24 | Z18: =SUM(J42:J45) -> 2 | ... AF18: =SUM(P42:P45) -> 283
B19: 09.15 - 09.30 | C19: 24 | D19: 10 | E19: 10 | F19: 1 | G19: 2 | H19: 0 | I19: 2 | J19: 1 | K19: 0 | L19: 0 | M19: 32 | N19: 0 | O19: =SUM(C19:L19,N19) -> 50 | P19: =SUM(C19:N19) -> 82 | R19: 1600-1700 | S19: =SUM(C46:C49) -> 93 | T19: =SUM(D46:D49) -> 33 | U19: =SUM(E46:E49) -> 8 | V19: =SUM(F46:F49) -> 10 | W19: =SUM(G46:G49) -> 3 | X19: =SUM(H46:H49) -> 0 | Y19: =SUM(I46:I49) -> 21 | Z19: =SUM(J46:J49) -> 6 | ... AF19: =SUM(P46:P49) -> 294
B20: 09.30 - 09.45 | C20: 30 | D20: 11 | E20: 4 | F20: 1 | G20: 1 | H20: 0 | I20: 4 | J20: 0 | K20: 0 | L20: 0 | M20: 30 | N20: 0 | O20: =SUM(C20:L20,N20) -> 51 | P20: =SUM(C20:N20) -> 81 | R20: 1700-1800 | S20: =SUM(C50:C53) -> 194 | T20: =SUM(D50:D53) -> 20 | U20: =SUM(E50:E53) -> 20 | V20: =SUM(F50:F53) -> 8 | W20: =SUM(G50:G53) -> 8 | X20: =SUM(H50:H53) -> 7 | Y20: =SUM(I50:I53) -> 17 | Z20: =SUM(J50:J53) -> 10 | ... AF20: =SUM(P50:P53) -> 491
B21: 09.45 - 10.00 | C21: 21 | D21: 8 | E21: 2 | F21: 1 | G21: 0 | H21: 1 | I21: 3 | J21: 0 | K21: 0 | L21: 0 | M21: 32 | N21: 0 | O21: =SUM(C21:L21,N21) -> 36 | P21: =SUM(C21:N21) -> 68 | R21: 1800-1900 | S21: =SUM(C54:C57) -> 123 | T21: =SUM(D54:D57) -> 24 | U21: =SUM(E54:E57) -> 22 | V21: =SUM(F54:F57) -> 13 | W21: =SUM(G54:G57) -> 1 | X21: =SUM(H54:H57) -> 0 | Y21: =SUM(I54:I57) -> 10 | Z21: =SUM(J54:J57) -> 1 | ... AF21: =SUM(P54:P57) -> 292
B22: 10.00 - 10.15 | C22: 22 | D22: 12 | E22: 3 | F22: 2 | G22: 1 | H22: 0 | I22: 6 | J22: 0 | K22: 0 | L22: 0 | M22: 40 | N22: 0 | O22: =SUM(C22:L22,N22) -> 46 | P22: =SUM(C22:N22) -> 86 | R22: AM Peak Hr | S22: =MAX(S10:S12) -> 138 | T22: =MAX(T10:T12) -> 44 | U22: =MAX(U10:U12) -> 25 | V22: =MAX(V10:V12) -> 13 | W22: =MAX(W10:W12) -> 3 | X22: =MAX(X10:X12) -> 2 | Y22: =MAX(Y10:Y12) -> 13 | Z22: =MAX(Z10:Z12) -> 1 | ... AF22: =MAX(AF10:AF12) -> 382
B23: 10.15 - 10.30 | C23: 27 | D23: 14 | E23: 5 | F23: 3 | G23: 0 | H23: 0 | I23: 1 | J23: 1 | K23: 0 | L23: 0 | M23: 37 | N23: 0 | O23: =SUM(C23:L23,N23) -> 51 | P23: =SUM(C23:N23) -> 88 | R23: IP Peak Hr | S23: =MAX(S13:S18) -> 104 | T23: =MAX(T13:T18) -> 39 | U23: =MAX(U13:U18) -> 21 | V23: =MAX(V13:V18) -> 15 | W23: =MAX(W13:W18) -> 3 | X23: =MAX(X13:X18) -> 1 | Y23: =MAX(Y13:Y18) -> 33 | Z23: =MAX(Z13:Z18) -> 10 | ... AF23: =MAX(AF13:AF18) -> 323
B24: 10.30 - 10.45 | C24: 13 | D24: 7 | E24: 8 | F24: 0 | G24: 0 | H24: 0 | I24: 5 | J24: 0 | K24: 0 | L24: 0 | M24: 28 | N24: 0 | O24: =SUM(C24:L24,N24) -> 33 | P24: =SUM(C24:N24) -> 61 | R24: PM Peak Hr | S24: =MAX(S19:S21) -> 194 | T24: =MAX(T19:T21) -> 33 | U24: =MAX(U19:U21) -> 22 | V24: =MAX(V19:V21) -> 13 | W24: =MAX(W19:W21) -> 8 | X24: =MAX(X19:X21) -> 7 | Y24: =MAX(Y19:Y21) -> 21 | Z24: =MAX(Z19:Z21) -> 10 | ... AF24: =MAX(AF19:AF21) -> 491
B25: 10.45 - 11.00 | C25: 29 | D25: 6 | E25: 5 | F25: 5 | G25: 0 | H25: 0 | I25: 7 | J25: 0 | K25: 0 | L25: 0 | M25: 18 | N25: 0 | O25: =SUM(C25:L25,N25) -> 52 | P25: =SUM(C25:N25) -> 70 | R25: AM Period | S25: =SUM(S10:S12) -> 357 | T25: =SUM(T10:T12) -> 110 | U25: =SUM(U10:U12) -> 52 | V25: =SUM(V10:V12) -> 25 | W25: =SUM(W10:W12) -> 4 | X25: =SUM(X10:X12) -> 4 | Y25: =SUM(Y10:Y12) -> 23 | Z25: =SUM(Z10:Z12) -> 2 | ... AF25: =SUM(AF10:AF12) -> 1067
B26: 11.00 - 11.15 | C26: 14 | D26: 4 | E26: 4 | F26: 1 | G26: 0 | H26: 0 | I26: 6 | J26: 1 | K26: 0 | L26: 0 | M26: 28 | N26: 0 | O26: =SUM(C26:L26,N26) -> 30 | P26: =SUM(C26:N26) -> 58 | R26: IP Period | S26: =SUM(S13:S18) -> 531 | T26: =SUM(T13:T18) -> 159 | U26: =SUM(U13:U18) -> 85 | V26: =SUM(V13:V18) -> 40 | W26: =SUM(W13:W18) -> 8 | X26: =SUM(X13:X18) -> 1 | Y26: =SUM(Y13:Y18) -> 120 | Z26: =SUM(Z13:Z18) -> 19 | ... AF26: =SUM(AF13:AF18) -> 1691
B27: 11.15 - 11.30 | C27: 32 | D27: 2 | E27: 1 | F27: 2 | G27: 0 | H27: 0 | I27: 6 | J27: 0 | K27: 0 | L27: 0 | M27: 30 | N27: 0 | O27: =SUM(C27:L27,N27) -> 43 | P27: =SUM(C27:N27) -> 73 | R27: PM Period | S27: =SUM(S19:S21) -> 410 | T27: =SUM(T19:T21) -> 77 | U27: =SUM(U19:U21) -> 50 | V27: =SUM(V19:V21) -> 31 | W27: =SUM(W19:W21) -> 12 | X27: =SUM(X19:X21) -> 7 | Y27: =SUM(Y19:Y21) -> 48 | Z27: =SUM(Z19:Z21) -> 17 | ... AF27: =SUM(AF19:AF21) -> 1077
B28: 11.30 - 11.45 | C28: 25 | D28: 13 | E28: 1 | F28: 0 | G28: 0 | H28: 0 | I28: 2 | J28: 1 | K28: 0 | L28: 0 | M28: 31 | N28: 0 | O28: =SUM(C28:L28,N28) -> 42 | P28: =SUM(C28:N28) -> 73 | R28: 12 Hours | S28: =SUM(S10:S21) -> 1298 | T28: =SUM(T10:T21) -> 346 | U28: =SUM(U10:U21) -> 187 | V28: =SUM(V10:V21) -> 96 | W28: =SUM(W10:W21) -> 24 | X28: =SUM(X10:X21) -> 12 | Y28: =SUM(Y10:Y21) -> 191 | Z28: =SUM(Z10:Z21) -> 38 | ... AF28: =SUM(AF10:AF21) -> 3835
B29: 11.45 - 12.00 | C29: 21 | D29: 3 | E29: 7 | F29: 2 | G29: 2 | H29: 0 | I29: 3 | J29: 2 | K29: 0 | L29: 0 | M29: 21 | N29: 0 | O29: =SUM(C29:L29,N29) -> 40 | P29: =SUM(C29:N29) -> 61
B30: 12.00 - 12.15 | C30: 29 | D30: 2 | E30: 6 | F30: 0 | G30: 0 | H30: 0 | I30: 2 | J30: 4 | K30: 1 | L30: 1 | M30: 33 | N30: 0 | O30: =SUM(C30:L30,N30) -> 45 | P30: =SUM(C30:N30) -> 78
B31: 12.15 - 12.30 | C31: 33 | D31: 2 | E31: 2 | F31: 0 | G31: 0 | H31: 0 | I31: 3 | J31: 3 | K31: 0 | L31: 0 | M31: 27 | N31: 0 | O31: =SUM(C31:L31,N31) -> 43 | P31: =SUM(C31:N31) -> 70
B32: 12.30 - 12.45 | C32: 13 | D32: 1 | E32: 6 | F32: 0 | G32: 0 | H32: 0 | I32: 1 | J32: 2 | K32: 0 | L32: 0 | M32: 22 | N32: 0 | O32: =SUM(C32:L32,N32) -> 23 | P32: =SUM(C32:N32) -> 45
B33: 12.45 - 13.00 | C33: 29 | D33: 11 | E33: 1 | F33: 2 | G33: 0 | H33: 0 | I33: 2 | J33: 1 | K33: 0 | L33: 0 | M33: 30 | N33: 0 | O33: =SUM(C33:L33,N33) -> 46 | P33: =SUM(C33:N33) -> 76
B34: 13.00 - 13.15 | C34: 31 | D34: 12 | E34: 4 | F34: 1 | G34: 2 | H34: 0 | I34: 6 | J34: 1 | K34: 0 | L34: 0 | M34: 34 | N34: 0 | O34: =SUM(C34:L34,N34) -> 57 | P34: =SUM(C34:N34) -> 91
B35: 13.15 - 13.30 | C35: 25 | D35: 10 | E35: 3 | F35: 1 | G35: 0 | H35: 0 | I35: 7 | J35: 1 | K35: 0 | L35: 0 | M35: 35 | N35: 0 | O35: =SUM(C35:L35,N35) -> 47 | P35: =SUM(C35:N35) -> 82
B36: 13.30 - 13.45 | C36: 22 | D36: 6 | E36: 2 | F36: 3 | G36: 1 | H36: 0 | I36: 5 | J36: 0 | K36: 0 | L36: 0 | M36: 21 | N36: 0 | O36: =SUM(C36:L36,N36) -> 39 | P36: =SUM(C36:N36) -> 60
B37: 13.45 - 14.00 | C37: 24 | D37: 10 | E37: 2 | F37: 0 | G37: 0 | H37: 0 | I37: 15 | J37: 0 | K37: 0 | L37: 0 | M37: 39 | N37: 0 | O37: =SUM(C37:L37,N37) -> 51 | P37: =SUM(C37:N37) -> 90
B38: 14.00 - 14.15 | C38: 24 | D38: 8 | E38: 4 | F38: 0 | G38: 1 | H38: 0 | I38: 4 | J38: 0 | K38: 0 | L38: 0 | M38: 23 | N38: 0 | O38: =SUM(C38:L38,N38) -> 41 | P38: =SUM(C38:N38) -> 64
B39: 14.15 - 14.30 | C39: 11 | D39: 1 | E39: 1 | F39: 1 | G39: 0 | H39: 1 | I39: 5 | J39: 0 | K39: 0 | L39: 0 | M39: 31 | N39: 0 | O39: =SUM(C39:L39,N39) -> 20 | P39: =SUM(C39:N39) -> 51
B40: 14.30 - 14.45 | C40: 17 | D40: 5 | E40: 7 | F40: 0 | G40: 0 | H40: 0 | I40: 5 | J40: 0 | K40: 0 | L40: 0 | M40: 31 | N40: 0 | O40: =SUM(C40:L40,N40) -> 34 | P40: =SUM(C40:N40) -> 65
... B57: 18.45 - 19.00 | C57: 42 | D57: 10 | E57: 5 | F57: 2 | G57: 1 | H57: 0 | I57: 4 | J57: 0 | K57: 0 | L57: 0 | M57: 31 | N57: 0 | O57: =SUM(C57:L57,N57) -> 64 | P57: =SUM(C57:N57) -> 95
B58: Totals | C58: =SUM(C10:C57) -> 1298 | D58: =SUM(D10:D57) -> 346 | E58: =SUM(E10:E57) -> 187 | F58: =SUM(F10:F57) -> 96 | G58: =SUM(G10:G57) -> 24 | H58: =SUM(H10:H57) -> 12 | I58: =SUM(I10:I57) -> 191 | J58: =SUM(J10:J57) -> 38 | ... P58: =SUM(P10:P57) -> 3835
...

Sheet 24.09 Kajansi-Bweya
B1: Consultancy services for Preparation of Expressway Development Master Plan (EDMP) for Uganda
B2: MANUAL CLASSIFIED COUNT (MCC)
B3: ROAD NAME: | C3: ='[1]24.09.2019 MUNYONYO-KAJJANSI'!C3:G3 -> MCC - C2- STN56- MUNYONYO SPUR
C5: Date | D5: ='[1]24.09.2019 MUNYONYO-KAJJANSI'!D5 -> 24.09.19 | F5: Location | G5: ='[1]24.09.2019 MUNYONYO-KAJJANSI'!G5:H5 -> KAWALI (56) | J5: Surveyor | K5: ='[1]24.09.2019 MUNYONYO-KAJJANSI'!K5:L5 -> KASOMA JOHN
C6: Dir. From | D6: KAJJANSI | F6: Dir. To | G6: MUNYONYO | J6: Supervisor | K6: ='[1]24.09.2019 MUNYONYO-KAJJANSI'!K6:L6 -> BEATRICE
B8: Time / Veh Type | R8: SUMMARY TRAFFIC VOLUMES
C9: 1. Car | D9: 2. Station Wagon | E9: 3. Pickups | F9: 4. Minibus, matatu | G9: 5. Medium bus | H9: 6. Large Bus | I9: 7. Light Truck | J9: 8. Medium Truck | K9: 9. Heavy truck | L9: 10. Truck Trailer | M9: 11. Motor cycles | N9: 12. Tractors | O9: Total Excl M/Cycles | P9: Total All | R9: Time | S9: 1. Car | T9: 2. Station Wagon | U9: 3. Pickups | V9: 4. Minibus, matatu | W9: 5. Medium bus | X9: 6. Large Bus | Y9: 7. Light Truck | Z9: 8. Medium Truck | AA9: 9. Heavy truck | AB9: 10. Truck Trailer | AC9: 11. Motorcycles | AD9: 12. Tractors, Graders | AE9: Total Excl M/ Cycles | AF9: Total All
B10: 07.00 - 07.15 | C10: 35 | D10: 9 | E10: 4 | F10: 1 | G10: 0 | H10: 0 | I10: 4 | J10: 0 | K10: 0 | L10: 0 | M10: 25 | N10: 0 | O10: =SUM(C10:L10,N10) -> 53 | P10: =SUM(C10:N10) -> 78 | R10: 0700-0800 | S10: =SUM(C10:C13) -> 179 | T10: =SUM(D10:D13) -> 47 | U10: =SUM(E10:E13) -> 23 | V10: =SUM(F10:F13) -> 11 | W10: =SUM(G10:G13) -> 1 | X10: =SUM(H10:H13) -> 0 | Y10: =SUM(I10:I13) -> 14 | Z10: =SUM(J10:J13) -> 0 | ... AF10: =SUM(P10:P13) -> 414
B11: 07.15 - 07.30 | C11: 47 | D11: 14 | E11: 9 | F11: 4 | G11: 0 | H11: 0 | I11: 5 | J11: 0 | K11: 0 | L11: 0 | M11: 38 | N11: 0 | O11: =SUM(C11:L11,N11) -> 79 | P11: =SUM(C11:N11) -> 117 | R11: 0800-0900 | S11: =SUM(C14:C17) -> 116 | T11: =SUM(D14:D17) -> 17 | U11: =SUM(E14:E17) -> 23 | V11: =SUM(F14:F17) -> 5 | W11: =SUM(G14:G17) -> 0 | X11: =SUM(H14:H17) -> 0 | Y11: =SUM(I14:I17) -> 13 | Z11: =SUM(J14:J17) -> 3 | ... AF11: =SUM(P14:P17) -> 283
B12: 07.30 - 07.45 | C12: 53 | D12: 14 | E12: 3 | F12: 5 | G12: 1 | H12: 0 | I12: 1 | J12: 0 | K12: 0 | L12: 0 | M12: 39 | N12: 0 | O12: =SUM(C12:L12,N12) -> 77 | P12: =SUM(C12:N12) -> 116 | R12: 0900-1000 | S12: =SUM(C18:C21) -> 93 | T12: =SUM(D18:D21) -> 8 | U12: =SUM(E18:E21) -> 12 | V12: =SUM(F18:F21) -> 4 | W12: =SUM(G18:G21) -> 0 | X12: =SUM(H18:H21) -> 0 | Y12: =SUM(I18:I21) -> 12 | Z12: =SUM(J18:J21) -> 2 | ... AF12: =SUM(P18:P21) -> 245
B13: 07.45 - 08.00 | C13: 44 | D13: 10 | E13: 7 | F13: 1 | G13: 0 | H13: 0 | I13: 4 | J13: 0 | K13: 0 | L13: 0 | M13: 37 | N13: 0 | O13: =SUM(C13:L13,N13) -> 66 | P13: =SUM(C13:N13) -> 103 | R13: 1000-1100 | S13: =SUM(C22:C25) -> 117 | T13: =SUM(D22:D25) -> 7 | U13: =SUM(E22:E25) -> 19 | V13: =SUM(F22:F25) -> 1 | W13: =SUM(G22:G25) -> 1 | X13: =SUM(H22:H25) -> 0 | Y13: =SUM(I22:I25) -> 13 | Z13: =SUM(J22:J25) -> 8 | ... AF13: =SUM(P22:P25) -> 259
B14: 08.00 - 08.15 | C14: 41 | D14: 13 | E14: 9 | F14: 2 | G14: 0 | H14: 0 | I14: 4 | J14: 0 | K14: 0 | L14: 0 | M14: 47 | N14: 0 | O14: =SUM(C14:L14,N14) -> 69 | P14: =SUM(C14:N14) -> 116 | R14: 1100-1200 | S14: =SUM(C26:C29) -> 110 | T14: =SUM(D26:D29) -> 8 | U14: =SUM(E26:E29) -> 13 | V14: =SUM(F26:F29) -> 1 | W14: =SUM(G26:G29) -> 0 | X14: =SUM(H26:H29) -> 0 | Y14: =SUM(I26:I29) -> 13 | Z14: =SUM(J26:J29) -> 13 | ... AF14: =SUM(P26:P29) -> 278
B15: 08.15 - 08.30 | C15: 25 | D15: 2 | E15: 4 | F15: 1 | G15: 0 | H15: 0 | I15: 5 | J15: 0 | K15: 0 | L15: 0 | M15: 21 | N15: 0 | O15: =SUM(C15:L15,N15) -> 37 | P15: =SUM(C15:N15) -> 58 | R15: 1200-1300 | S15: =SUM(C30:C33) -> 79 | T15: =SUM(D30:D33) -> 8 | U15: =SUM(E30:E33) -> 9 | V15: =SUM(F30:F33) -> 1 | W15: =SUM(G30:G33) -> 0 | X15: =SUM(H30:H33) -> 0 | Y15: =SUM(I30:I33) -> 11 | Z15: =SUM(J30:J33) -> 9 | ... AF15: =SUM(P30:P33) -> 190
B16: 08.30 - 08.45 | C16: 22 | D16: 2 | E16: 6 | F16: 2 | G16: 0 | H16: 0 | I16: 2 | J16: 0 | K16: 0 | L16: 0 | M16: 19 | N16: 0 | O16: =SUM(C16:L16,N16) -> 34 | P16: =SUM(C16:N16) -> 53 | R16: 1300-1400 | S16: =SUM(C34:C37) -> 119 | T16: =SUM(D34:D37) -> 10 | U16: =SUM(E34:E37) -> 14 | V16: =SUM(F34:F37) -> 2 | W16: =SUM(G34:G37) -> 1 | X16: =SUM(H34:H37) -> 0 | Y16: =SUM(I34:I37) -> 19 | Z16: =SUM(J34:J37) -> 4 | ... AF16: =SUM(P34:P37) -> 268
B17: 08.45 - 9.00 | C17: 28 | D17: 0 | E17: 4 | F17: 0 | G17: 0 | H17: 0 | I17: 2 | J17: 3 | K17: 0 | L17: 0 | M17: 19 | N17: 0 | O17: =SUM(C17:L17,N17) -> 37 | P17: =SUM(C17:N17) -> 56 | R17: 1400-1500 | S17: =SUM(C38:C41) -> 79 | T17: =SUM(D38:D41) -> 24 | U17: =SUM(E38:E41) -> 15 | V17: =SUM(F38:F41) -> 4 | W17: =SUM(G38:G41) -> 3 | X17: =SUM(H38:H41) -> 0 | Y17: =SUM(I38:I41) -> 15 | Z17: =SUM(J38:J41) -> 5 | ... AF17: =SUM(P38:P41) -> 236
B18: 09.00 - 09.15 | C18: 26 | D18: 3 | E18: 4 | F18: 0 | G18: 0 | H18: 0 | I18: 3 | J18: 0 | K18: 1 | L18: 0 | M18: 36 | N18: 0 | O18: =SUM(C18:L18,N18) -> 37 | P18: =SUM(C18:N18) -> 73 | R18: 1500-1600 | S18: =SUM(C42:C45) -> 179 | T18: =SUM(D42:D45) -> 18 | U18: =SUM(E42:E45) -> 24 | V18: =SUM(F42:F45) -> 2 | W18: =SUM(G42:G45) -> 4 | X18: =SUM(H42:H45) -> 0 | Y18: =SUM(I42:I45) -> 11 | Z18: =SUM(J42:J45) -> 20 | ... AF18: =SUM(P42:P45) -> 447
B19: 09.15 - 09.30 | C19: 22 | D19: 4 | E19: 3 | F19: 4 | G19: 0 | H19: 0 | I19: 6 | J19: 1 | K19: 0 | L19: 0 | M19: 19 | N19: 0 | O19: =SUM(C19:L19,N19) -> 40 | P19: =SUM(C19:N19) -> 59 | R19: 1600-1700 | S19: =SUM(C46:C49) -> 169 | T19: =SUM(D46:D49) -> 4 | U19: =SUM(E46:E49) -> 21 | V19: =SUM(F46:F49) -> 2 | W19: =SUM(G46:G49) -> 1 | X19: =SUM(H46:H49) -> 0 | Y19: =SUM(I46:I49) -> 13 | Z19: =SUM(J46:J49) -> 8 | ... AF19: =SUM(P46:P49) -> 357
B20: 09.30 - 09.45 | C20: 23 | D20: 0 | E20: 4 | F20: 0 | G20: 0 | H20: 0 | I20: 1 | J20: 1 | K20: 0 | L20: 0 | M20: 27 | N20: 0 | O20: =SUM(C20:L20,N20) -> 29 | P20: =SUM(C20:N20) -> 56 | R20: 1700-1800 | S20: =SUM(C50:C53) -> 193 | T20: =SUM(D50:D53) -> 13 | U20: =SUM(E50:E53) -> 20 | V20: =SUM(F50:F53) -> 2 | W20: =SUM(G50:G53) -> 4 | X20: =SUM(H50:H53) -> 0 | Y20: =SUM(I50:I53) -> 7 | Z20: =SUM(J50:J53) -> 6 | ... AF20: =SUM(P50:P53) -> 398
B21: 09.45 - 10.00 | C21: 22 | D21: 1 | E21: 1 | F21: 0 | G21: 0 | H21: 0 | I21: 2 | J21: 0 | K21: 0 | L21: 0 | M21: 31 | N21: 0 | O21: =SUM(C21:L21,N21) -> 26 | P21: =SUM(C21:N21) -> 57 | R21: 1800-1900 | S21: =SUM(C54:C57) -> 164 | T21: =SUM(D54:D57) -> 3 | U21: =SUM(E54:E57) -> 12 | V21: =SUM(F54:F57) -> 1 | W21: =SUM(G54:G57) -> 1 | X21: =SUM(H54:H57) -> 0 | Y21: =SUM(I54:I57) -> 9 | Z21: =SUM(J54:J57) -> 3 | ... AF21: =SUM(P54:P57) -> 276
B22: 10.00 - 10.15 | C22: 35 | D22: 0 | E22: 7 | F22: 0 | G22: 1 | H22: 0 | I22: 2 | J22: 2 | K22: 0 | L22: 0 | M22: 30 | N22: 0 | O22: =SUM(C22:L22,N22) -> 47 | P22: =SUM(C22:N22) -> 77 | R22: AM Peak Hr | S22: =MAX(S10:S12) -> 179 | T22: =MAX(T10:T12) -> 47 | U22: =MAX(U10:U12) -> 23 | V22: =MAX(V10:V12) -> 11 | W22: =MAX(W10:W12) -> 1 | X22: =MAX(X10:X12) -> 0 | Y22: =MAX(Y10:Y12) -> 14 | Z22: =MAX(Z10:Z12) -> 3 | ... AF22: =MAX(AF10:AF12) -> 414
B23: 10.15 - 10.30 | C23: 33 | D23: 1 | E23: 4 | F23: 1 | G23: 0 | H23: 0 | I23: 4 | J23: 1 | K23: 0 | L23: 0 | M23: 23 | N23: 0 | O23: =SUM(C23:L23,N23) -> 44 | P23: =SUM(C23:N23) -> 67 | R23: IP Peak Hr | S23: =MAX(S13:S18) -> 179 | T23: =MAX(T13:T18) -> 24 | U23: =MAX(U13:U18) -> 24 | V23: =MAX(V13:V18) -> 4 | W23: =MAX(W13:W18) -> 4 | X23: =MAX(X13:X18) -> 0 | Y23: =MAX(Y13:Y18) -> 19 | Z23: =MAX(Z13:Z18) -> 20 | ... AF23: =MAX(AF13:AF18) -> 447
B24: 10.30 - 10.45 | C24: 25 | D24: 5 | E24: 6 | F24: 0 | G24: 0 | H24: 0 | I24: 3 | J24: 5 | K24: 0 | L24: 0 | M24: 24 | N24: 0 | O24: =SUM(C24:L24,N24) -> 44 | P24: =SUM(C24:N24) -> 68 | R24: PM Peak Hr | S24: =MAX(S19:S21) -> 193 | T24: =MAX(T19:T21) -> 13 | U24: =MAX(U19:U21) -> 21 | V24: =MAX(V19:V21) -> 2 | W24: =MAX(W19:W21) -> 4 | X24: =MAX(X19:X21) -> 0 | Y24: =MAX(Y19:Y21) -> 13 | Z24: =MAX(Z19:Z21) -> 8 | ... AF24: =MAX(AF19:AF21) -> 398
B25: 10.45 - 11.00 | C25: 24 | D25: 1 | E25: 2 | F25: 0 | G25: 0 | H25: 0 | I25: 4 | J25: 0 | K25: 0 | L25: 0 | M25: 16 | N25: 0 | O25: =SUM(C25:L25,N25) -> 31 | P25: =SUM(C25:N25) -> 47 | R25: AM Period | S25: =SUM(S10:S12) -> 388 | T25: =SUM(T10:T12) -> 72 | U25: =SUM(U10:U12) -> 58 | V25: =SUM(V10:V12) -> 20 | W25: =SUM(W10:W12) -> 1 | X25: =SUM(X10:X12) -> 0 | Y25: =SUM(Y10:Y12) -> 39 | Z25: =SUM(Z10:Z12) -> 5 | ... AF25: =SUM(AF10:AF12) -> 942
B26: 11.00 - 11.15 | C26: 31 | D26: 0 | E26: 1 | F26: 0 | G26: 0 | H26: 0 | I26: 6 | J26: 3 | K26: 0 | L26: 0 | M26: 30 | N26: 0 | O26: =SUM(C26:L26,N26) -> 41 | P26: =SUM(C26:N26) -> 71 | R26: IP Period | S26: =SUM(S13:S18) -> 683 | T26: =SUM(T13:T18) -> 75 | U26: =SUM(U13:U18) -> 94 | V26: =SUM(V13:V18) -> 11 | W26: =SUM(W13:W18) -> 9 | X26: =SUM(X13:X18) -> 0 | Y26: =SUM(Y13:Y18) -> 82 | Z26: =SUM(Z13:Z18) -> 59 | ... AF26: =SUM(AF13:AF18) -> 1678
B27: 11.15 - 11.30 | C27: 25 | D27: 0 | E27: 2 | F27: 0 | G27: 0 | H27: 0 | I27: 1 | J27: 4 | K27: 1 | L27: 0 | M27: 38 | N27: 0 | O27: =SUM(C27:L27,N27) -> 33 | P27: =SUM(C27:N27) -> 71 | R27: PM Period | S27: =SUM(S19:S21) -> 526 | T27: =SUM(T19:T21) -> 20 | U27: =SUM(U19:U21) -> 53 | V27: =SUM(V19:V21) -> 5 | W27: =SUM(W19:W21) -> 6 | X27: =SUM(X19:X21) -> 0 | Y27: =SUM(Y19:Y21) -> 29 | Z27: =SUM(Z19:Z21) -> 17 | ... AF27: =SUM(AF19:AF21) -> 1031
B28: 11.30 - 11.45 | C28: 33 | D28: 2 | E28: 6 | F28: 0 | G28: 0 | H28: 0 | I28: 4 | J28: 2 | K28: 0 | L28: 0 | M28: 31 | N28: 0 | O28: =SUM(C28:L28,N28) -> 47 | P28: =SUM(C28:N28) -> 78 | R28: 12 Hours | S28: =SUM(S10:S21) -> 1597 | T28: =SUM(T10:T21) -> 167 | U28: =SUM(U10:U21) -> 205 | V28: =SUM(V10:V21) -> 36 | W28: =SUM(W10:W21) -> 16 | X28: =SUM(X10:X21) -> 0 | Y28: =SUM(Y10:Y21) -> 150 | Z28: =SUM(Z10:Z21) -> 81 | ... AF28: =SUM(AF10:AF21) -> 3651
B29: 11.45 - 12.00 | C29: 21 | D29: 6 | E29: 4 | F29: 1 | G29: 0 | H29: 0 | I29: 2 | J29: 4 | K29: 0 | L29: 1 | M29: 19 | N29: 0 | O29: =SUM(C29:L29,N29) -> 39 | P29: =SUM(C29:N29) -> 58
B30: 12.00 - 12.15 | C30: 17 | D30: 1 | E30: 4 | F30: 0 | G30: 0 | H30: 0 | I30: 2 | J30: 2 | K30: 0 | L30: 0 | M30: 25 | N30: 0 | O30: =SUM(C30:L30,N30) -> 26 | P30: =SUM(C30:N30) -> 51
B31: 12.15 - 12.30 | C31: 20 | D31: 0 | E31: 0 | F31: 0 | G31: 0 | H31: 0 | I31: 3 | J31: 4 | K31: 0 | L31: 0 | M31: 17 | N31: 0 | O31: =SUM(C31:L31,N31) -> 27 | P31: =SUM(C31:N31) -> 44
B32: 12.30 - 12.45 | C32: 20 | D32: 0 | E32: 0 | F32: 0 | G32: 0 | H32: 0 | I32: 2 | J32: 1 | K32: 0 | L32: 0 | M32: 12 | N32: 0 | O32: =SUM(C32:L32,N32) -> 23 | P32: =SUM(C32:N32) -> 35
B33: 12.45 - 13.00 | C33: 22 | D33: 7 | E33: 5 | F33: 1 | G33: 0 | H33: 0 | I33: 4 | J33: 2 | K33: 0 | L33: 0 | M33: 19 | N33: 0 | O33: =SUM(C33:L33,N33) -> 41 | P33: =SUM(C33:N33) -> 60
B34: 13.00 - 13.15 | C34: 24 | D34: 4 | E34: 5 | F34: 1 | G34: 0 | H34: 0 | I34: 3 | J34: 1 | K34: 0 | L34: 0 | M34: 43 | N34: 0 | O34: =SUM(C34:L34,N34) -> 38 | P34: =SUM(C34:N34) -> 81
B35: 13.15 - 13.30 | C35: 24 | D35: 3 | E35: 1 | F35: 1 | G35: 0 | H35: 0 | I35: 5 | J35: 0 | K35: 0 | L35: 0 | M35: 20 | N35: 0 | O35: =SUM(C35:L35,N35) -> 34 | P35: =SUM(C35:N35) -> 54
B36: 13.30 - 13.45 | C36: 37 | D36: 1 | E36: 6 | F36: 0 | G36: 0 | H36: 0 | I36: 8 | J36: 2 | K36: 0 | L36: 0 | M36: 19 | N36: 0 | O36: =SUM(C36:L36,N36) -> 54 | P36: =SUM(C36:N36) -> 73
B37: 13.45 - 14.00 | C37: 34 | D37: 2 | E37: 2 | F37: 0 | G37: 1 | H37: 0 | I37: 3 | J37: 1 | K37: 0 | L37: 0 | M37: 17 | N37: 0 | O37: =SUM(C37:L37,N37) -> 43 | P37: =SUM(C37:N37) -> 60
B38: 14.00 - 14.15 | C38: 25 | D38: 3 | E38: 2 | F38: 0 | G38: 0 | H38: 0 | I38: 3 | J38: 2 | K38: 0 | L38: 0 | M38: 18 | N38: 0 | O38: =SUM(C38:L38,N38) -> 35 | P38: =SUM(C38:N38) -> 53
B39: 14.15 - 14.30 | C39: 13 | D39: 1 | E39: 2 | F39: 0 | G39: 0 | H39: 0 | I39: 1 | J39: 2 | K39: 0 | L39: 0 | M39: 15 | N39: 0 | O39: =SUM(C39:L39,N39) -> 19 | P39: =SUM(C39:N39) -> 34
B40: 14.30 - 14.45 | C40: 12 | D40: 13 | E40: 6 | F40: 4 | G40: 2 | H40: 0 | I40: 5 | J40: 0 | K40: 1 | L40: 0 | M40: 30 | N40: 0 | O40: =SUM(C40:L40,N40) -> 43 | P40: =SUM(C40:N40) -> 73
... B57: 18.45 - 19.00 | C57: 55 | D57: 1 | E57: 5 | F57: 1 | G57: 1 | H57: 0 | I57: 4 | J57: 1 | K57: 0 | L57: 0 | M57: 26 | N57: 0 | O57: =SUM(C57:L57,N57) -> 68 | P57: =SUM(C57:N57) -> 94
B58: Totals | C58: =SUM(C10:C57) -> 1597 | D58: =SUM(D10:D57) -> 167 | E58: =SUM(E10:E57) -> 205 | F58: =SUM(F10:F57) -> 36 | G58: =SUM(G10:G57) -> 16 | H58: =SUM(H10:H57) -> 0 | I58: =SUM(I10:I57) -> 150 | J58: =SUM(J10:J57) -> 81 | ... P58: =SUM(P10:P57) -> 3651
...

Sheet 25.09 Bweya-Kajansi
B1: Consultancy services for Preparation of Expressway Development Master Plan (EDMP) for Uganda
B2: MANUAL CLASSIFIED COUNT (MCC)
B3: ROAD NAME: | C3: ='23.09.19 Bweya- Kajansi'!C3:G3 -> MCC-C2-STNO 56 -Munyonyo spur
C5: Date | D5: 25.09.19 | F5: Location | G5: ='23.09.19 Bweya- Kajansi'!G5:H5 -> Munyonyo Spur RD | J5: Surveyor | K5: ='23.09.19 Bweya- Kajansi'!K5:L5 -> Kasoma John Paul
C6: Dir. From | D6: ='23.09.19 Bweya- Kajansi'!D6:E6 -> BWEYA | F6: Dir. To | G6: ='23.09.19 Bweya- Kajansi'!G6:H6 -> KAJANSI | J6: Supervisor | K6: ='23.09.19 Bweya- Kajansi'!K6:L6 -> Beatrice
B8: Time / Veh Type | R8: SUMMARY TRAFFIC VOLUMES
C9: 1. Car | D9: 2. Station Wagon | E9: 3. Pickups | F9: 4. Minibus, matatu | G9: 5. Medium bus | H9: 6. Large Bus | I9: 7. Light Truck | J9: 8. Medium Truck | K9: 9. Heavy truck | L9: 10. Truck Trailer | M9: 11. Motor cycles | N9: 12. Tractors | O9: Total Excl M/Cycles | P9: Total All | R9: Time | S9: 1. Car | T9: 2. Station Wagon | U9: 3. Pickups | V9: 4. Minibus, matatu | W9: 5. Medium bus | X9: 6. Large Bus | Y9: 7. Light Truck | Z9: 8. Medium Truck | AA9: 9. Heavy truck | AB9: 10. Truck Trailer | AC9: 11. Motorcycles | AD9: 12. Tractors, Graders | AE9: Total Excl M/ Cycles | AF9: Total All
B10: 07.00 - 07.15 | C10: 42 | D10: 12 | E10: 2 | F10: 2 | G10: 0 | H10: 0 | I10: 2 | J10: 0 | K10: 0 | L10: 0 | M10: 39 | N10: 0 | O10: =SUM(C10:L10,N10) -> 60 | P10: =SUM(C10:N10) -> 99 | R10: 0700-0800 | S10: =SUM(C10:C13) -> 133 | T10: =SUM(D10:D13) -> 39 | U10: =SUM(E10:E13) -> 7 | V10: =SUM(F10:F13) -> 14 | W10: =SUM(G10:G13) -> 0 | X10: =SUM(H10:H13) -> 0 | Y10: =SUM(I10:I13) -> 9 | Z10: =SUM(J10:J13) -> 1 | ... AF10: =SUM(P10:P13) -> 384
B11: 07.15 - 07.30 | C11: 32 | D11: 8 | E11: 3 | F11: 2 | G11: 0 | H11: 0 | I11: 2 | J11: 0 | K11: 0 | L11: 0 | M11: 35 | N11: 0 | O11: =SUM(C11:L11,N11) -> 47 | P11: =SUM(C11:N11) -> 82 | R11: 0800-0900 | S11: =SUM(C14:C17) -> 114 | T11: =SUM(D14:D17) -> 35 | U11: =SUM(E14:E17) -> 15 | V11: =SUM(F14:F17) -> 7 | W11: =SUM(G14:G17) -> 1 | X11: =SUM(H14:H17) -> 2 | Y11: =SUM(I14:I17) -> 14 | Z11: =SUM(J14:J17) -> 2 | ... AF11: =SUM(P14:P17) -> 393
B12: 07.30 - 07.45 | C12: 28 | D12: 14 | E12: 1 | F12: 5 | G12: 0 | H12: 0 | I12: 2 | J12: 0 | K12: 0 | L12: 0 | M12: 60 | N12: 0 | O12: =SUM(C12:L12,N12) -> 50 | P12: =SUM(C12:N12) -> 110 | R12: 0900-1000 | S12: =SUM(C18:C21) -> 94 | T12: =SUM(D18:D21) -> 27 | U12: =SUM(E18:E21) -> 17 | V12: =SUM(F18:F21) -> 4 | W12: =SUM(G18:G21) -> 0 | X12: =SUM(H18:H21) -> 0 | Y12: =SUM(I18:I21) -> 14 | Z12: =SUM(J18:J21) -> 2 | ... AF12: =SUM(P18:P21) -> 278
B13: 07.45 - 08.00 | C13: 31 | D13: 5 | E13: 1 | F13: 5 | G13: 0 | H13: 0 | I13: 3 | J13: 1 | K13: 0 | L13: 0 | M13: 47 | N13: 0 | O13: =SUM(C13:L13,N13) -> 46 | P13: =SUM(C13:N13) -> 93 | R13: 1000-1100 | S13: =SUM(C22:C25) -> 82 | T13: =SUM(D22:D25) -> 29 | U13: =SUM(E22:E25) -> 17 | V13: =SUM(F22:F25) -> 6 | W13: =SUM(G22:G25) -> 0 | X13: =SUM(H22:H25) -> 0 | Y13: =SUM(I22:I25) -> 15 | Z13: =SUM(J22:J25) -> 3 | ... AF13: =SUM(P22:P25) -> 292
B14: 08.00 - 08.15 | C14: 27 | D14: 6 | E14: 2 | F14: 5 | G14: 0 | H14: 2 | I14: 8 | J14: 1 | K14: 0 | L14: 0 | M14: 47 | N14: 0 | O14: =SUM(C14:L14,N14) -> 51 | P14: =SUM(C14:N14) -> 98 | R14: 1100-1200 | S14: =SUM(C26:C29) -> 89 | T14: =SUM(D26:D29) -> 16 | U14: =SUM(E26:E29) -> 19 | V14: =SUM(F26:F29) -> 6 | W14: =SUM(G26:G29) -> 2 | X14: =SUM(H26:H29) -> 0 | Y14: =SUM(I26:I29) -> 15 | Z14: =SUM(J26:J29) -> 3 | ... AF14: =SUM(P26:P29) -> 280
B15: 08.15 - 08.30 | C15: 25 | D15: 13 | E15: 5 | F15: 0 | G15: 0 | H15: 0 | I15: 2 | J15: 0 | K15: 0 | L15: 0 | M15: 48 | N15: 0 | O15: =SUM(C15:L15,N15) -> 45 | P15: =SUM(C15:N15) -> 93 | R15: 1200-1300 | S15: =SUM(C30:C33) -> 86 | T15: =SUM(D30:D33) -> 33 | U15: =SUM(E30:E33) -> 15 | V15: =SUM(F30:F33) -> 4 | W15: =SUM(G30:G33) -> 0 | X15: =SUM(H30:H33) -> 0 | Y15: =SUM(I30:I33) -> 28 | Z15: =SUM(J30:J33) -> 2 | ... AF15: =SUM(P30:P33) -> 284
B16: 08.30 - 08.45 | C16: 30 | D16: 11 | E16: 6 | F16: 2 | G16: 1 | H16: 0 | I16: 3 | J16: 1 | K16: 0 | L16: 0 | M16: 56 | N16: 0 | O16: =SUM(C16:L16,N16) -> 54 | P16: =SUM(C16:N16) -> 110 | R16: 1300-1400 | S16: =SUM(C34:C37) -> 95 | T16: =SUM(D34:D37) -> 46 | U16: =SUM(E34:E37) -> 18 | V16: =SUM(F34:F37) -> 7 | W16: =SUM(G34:G37) -> 3 | X16: =SUM(H34:H37) -> 0 | Y16: =SUM(I34:I37) -> 28 | Z16: =SUM(J34:J37) -> 4 | ... AF16: =SUM(P34:P37) -> 308
B17: 08.45 - 9.00 | C17: 32 | D17: 5 | E17: 2 | F17: 0 | G17: 0 | H17: 0 | I17: 1 | J17: 0 | K17: 1 | L17: 0 | M17: 51 | N17: 0 | O17: =SUM(C17:L17,N17) -> 41 | P17: =SUM(C17:N17) -> 92 | R17: 1400-1500 | S17: =SUM(C38:C41) -> 105 | T17: =SUM(D38:D41) -> 29 | U17: =SUM(E38:E41) -> 12 | V17: =SUM(F38:F41) -> 2 | W17: =SUM(G38:G41) -> 0 | X17: =SUM(H38:H41) -> 0 | Y17: =SUM(I38:I41) -> 21 | Z17: =SUM(J38:J41) -> 1 | ... AF17: =SUM(P38:P41) -> 280
B18: 09.00 - 09.15 | C18: 20 | D18: 5 | E18: 6 | F18: 2 | G18: 0 | H18: 0 | I18: 3 | J18: 0 | K18: 0 | L18: 0 | M18: 27 | N18: 0 | O18: =SUM(C18:L18,N18) -> 36 | P18: =SUM(C18:N18) -> 63 | R18: 1500-1600 | S18: =SUM(C42:C45) -> 96 | T18: =SUM(D42:D45) -> 30 | U18: =SUM(E42:E45) -> 13 | V18: =SUM(F42:F45) -> 10 | W18: =SUM(G42:G45) -> 0 | X18: =SUM(H42:H45) -> 0 | Y18: =SUM(I42:I45) -> 13 | Z18: =SUM(J42:J45) -> 2 | ... AF18: =SUM(P42:P45) -> 272
B19: 09.15 - 09.30 | C19: 13 | D19: 6 | E19: 4 | F19: 0 | G19: 0 | H19: 0 | I19: 2 | J19: 0 | K19: 0 | L19: 0 | M19: 33 | N19: 0 | O19: =SUM(C19:L19,N19) -> 25 | P19: =SUM(C19:N19) -> 58 | R19: 1600-1700 | S19: =SUM(C46:C49) -> 116 | T19: =SUM(D46:D49) -> 35 | U19: =SUM(E46:E49) -> 16 | V19: =SUM(F46:F49) -> 11 | W19: =SUM(G46:G49) -> 1 | X19: =SUM(H46:H49) -> 1 | Y19: =SUM(I46:I49) -> 18 | Z19: =SUM(J46:J49) -> 4 | ... AF19: =SUM(P46:P49) -> 340
B20: 09.30 - 09.45 | C20: 32 | D20: 7 | E20: 4 | F20: 0 | G20: 0 | H20: 0 | I20: 5 | J20: 0 | K20: 0 | L20: 0 | M20: 29 | N20: 0 | O20: =SUM(C20:L20,N20) -> 48 | P20: =SUM(C20:N20) -> 77 | R20: 1700-1800 | S20: =SUM(C50:C53) -> 123 | T20: =SUM(D50:D53) -> 52 | U20: =SUM(E50:E53) -> 15 | V20: =SUM(F50:F53) -> 11 | W20: =SUM(G50:G53) -> 3 | X20: =SUM(H50:H53) -> 2 | Y20: =SUM(I50:I53) -> 17 | Z20: =SUM(J50:J53) -> 0 | ... AF20: =SUM(P50:P53) -> 375
B21: 09.45 - 10.00 | C21: 29 | D21: 9 | E21: 3 | F21: 2 | G21: 0 | H21: 0 | I21: 4 | J21: 2 | K21: 0 | L21: 0 | M21: 31 | N21: 0 | O21: =SUM(C21:L21,N21) -> 49 | P21: =SUM(C21:N21) -> 80 | R21: 1800-1900 | S21: =SUM(C54:C57) -> 178 | T21: =SUM(D54:D57) -> 42 | U21: =SUM(E54:E57) -> 22 | V21: =SUM(F54:F57) -> 12 | W21: =SUM(G54:G57) -> 3 | X21: =SUM(H54:H57) -> 0 | Y21: =SUM(I54:I57) -> 18 | Z21: =SUM(J54:J57) -> 1 | ... AF21: =SUM(P54:P57) -> 473
B22: 10.00 - 10.15 | C22: 22 | D22: 3 | E22: 3 | F22: 4 | G22: 0 | H22: 0 | I22: 6 | J22: 1 | K22: 0 | L22: 0 | M22: 28 | N22: 0 | O22: =SUM(C22:L22,N22) -> 39 | P22: =SUM(C22:N22) -> 67 | R22: AM Peak Hr | S22: =MAX(S10:S12) -> 133 | T22: =MAX(T10:T12) -> 39 | U22: =MAX(U10:U12) -> 17 | V22: =MAX(V10:V12) -> 14 | W22: =MAX(W10:W12) -> 1 | X22: =MAX(X10:X12) -> 2 | Y22: =MAX(Y10:Y12) -> 14 | Z22: =MAX(Z10:Z12) -> 2 | ... AF22: =MAX(AF10:AF12) -> 393
B23: 10.15 - 10.30 | C23: 18 | D23: 14 | E23: 4 | F23: 1 | G23: 0 | H23: 0 | I23: 1 | J23: 0 | K23: 0 | L23: 0 | M23: 41 | N23: 0 | O23: =SUM(C23:L23,N23) -> 38 | P23: =SUM(C23:N23) -> 79 | R23: IP Peak Hr | S23: =MAX(S13:S18) -> 105 | T23: =MAX(T13:T18) -> 46 | U23: =MAX(U13:U18) -> 19 | V23: =MAX(V13:V18) -> 10 | W23: =MAX(W13:W18) -> 3 | X23: =MAX(X13:X18) -> 0 | Y23: =MAX(Y13:Y18) -> 28 | Z23: =MAX(Z13:Z18) -> 4 | ... AF23: =MAX(AF13:AF18) -> 308
B24: 10.30 - 10.45 | C24: 24 | D24: 5 | E24: 9 | F24: 1 | G24: 0 | H24: 0 | I24: 4 | J24: 1 | K24: 0 | L24: 0 | M24: 41 | N24: 0 | O24: =SUM(C24:L24,N24) -> 44 | P24: =SUM(C24:N24) -> 85 | R24: PM Peak Hr | S24: =MAX(S19:S21) -> 178 | T24: =MAX(T19:T21) -> 52 | U24: =MAX(U19:U21) -> 22 | V24: =MAX(V19:V21) -> 12 | W24: =MAX(W19:W21) -> 3 | X24: =MAX(X19:X21) -> 2 | Y24: =MAX(Y19:Y21) -> 18 | Z24: =MAX(Z19:Z21) -> 4 | ... AF24: =MAX(AF19:AF21) -> 473
B25: 10.45 - 11.00 | C25: 18 | D25: 7 | E25: 1 | F25: 0 | G25: 0 | H25: 0 | I25: 4 | J25: 1 | K25: 0 | L25: 0 | M25: 30 | N25: 0 | O25: =SUM(C25:L25,N25) -> 31 | P25: =SUM(C25:N25) -> 61 | R25: AM Period | S25: =SUM(S10:S12) -> 341 | T25: =SUM(T10:T12) -> 101 | U25: =SUM(U10:U12) -> 39 | V25: =SUM(V10:V12) -> 25 | W25: =SUM(W10:W12) -> 1 | X25: =SUM(X10:X12) -> 2 | Y25: =SUM(Y10:Y12) -> 37 | Z25: =SUM(Z10:Z12) -> 5 | ... AF25: =SUM(AF10:AF12) -> 1055
B26: 11.00 - 11.15 | C26: 19 | D26: 4 | E26: 5 | F26: 1 | G26: 2 | H26: 0 | I26: 1 | J26: 0 | K26: 0 | L26: 0 | M26: 30 | N26: 0 | O26: =SUM(C26:L26,N26) -> 32 | P26: =SUM(C26:N26) -> 62 | R26: IP Period | S26: =SUM(S13:S18) -> 553 | T26: =SUM(T13:T18) -> 183 | U26: =SUM(U13:U18) -> 94 | V26: =SUM(V13:V18) -> 35 | W26: =SUM(W13:W18) -> 5 | X26: =SUM(X13:X18) -> 0 | Y26: =SUM(Y13:Y18) -> 120 | Z26: =SUM(Z13:Z18) -> 15 | ... AF26: =SUM(AF13:AF18) -> 1716
B27: 11.15 - 11.30 | C27: 36 | D27: 7 | E27: 4 | F27: 0 | G27: 0 | H27: 0 | I27: 3 | J27: 1 | K27: 0 | L27: 0 | M27: 45 | N27: 0 | O27: =SUM(C27:L27,N27) -> 51 | P27: =SUM(C27:N27) -> 96 | R27: PM Period | S27: =SUM(S19:S21) -> 417 | T27: =SUM(T19:T21) -> 129 | U27: =SUM(U19:U21) -> 53 | V27: =SUM(V19:V21) -> 34 | W27: =SUM(W19:W21) -> 7 | X27: =SUM(X19:X21) -> 3 | Y27: =SUM(Y19:Y21) -> 53 | Z27: =SUM(Z19:Z21) -> 5 | ... AF27: =SUM(AF19:AF21) -> 1188
B28: 11.30 - 11.45 | C28: 9 | D28: 2 | E28: 4 | F28: 1 | G28: 0 | H28: 0 | I28: 1 | J28: 2 | K28: 0 | L28: 0 | M28: 33 | N28: 0 | O28: =SUM(C28:L28,N28) -> 19 | P28: =SUM(C28:N28) -> 52 | R28: 12 Hours | S28: =SUM(S10:S21) -> 1311 | T28: =SUM(T10:T21) -> 413 | U28: =SUM(U10:U21) -> 186 | V28: =SUM(V10:V21) -> 94 | W28: =SUM(W10:W21) -> 13 | X28: =SUM(X10:X21) -> 5 | Y28: =SUM(Y10:Y21) -> 210 | Z28: =SUM(Z10:Z21) -> 25 | ... AF28: =SUM(AF10:AF21) -> 3959
B29: 11.45 - 12.00 | C29: 25 | D29: 3 | E29: 6 | F29: 4 | G29: 0 | H29: 0 | I29: 10 | J29: 0 | K29: 0 | L29: 0 | M29: 22 | N29: 0 | O29: =SUM(C29:L29,N29) -> 48 | P29: =SUM(C29:N29) -> 70
B30: 12.00 - 12.15 | C30: 22 | D30: 10 | E30: 5 | F30: 1 | G30: 0 | H30: 0 | I30: 6 | J30: 0 | K30: 0 | L30: 0 | M30: 38 | N30: 0 | O30: =SUM(C30:L30,N30) -> 44 | P30: =SUM(C30:N30) -> 82
B31: 12.15 - 12.30 | C31: 15 | D31: 3 | E31: 2 | F31: 0 | G31: 0 | H31: 0 | I31: 5 | J31: 0 | K31: 0 | L31: 0 | M31: 17 | N31: 0 | O31: =SUM(C31:L31,N31) -> 25 | P31: =SUM(C31:N31) -> 42
