Workbook

Sheet 23.09-BULOBA- NSANGI
B1: Consultancy services for Preparation of Expressway Development Master Plan (EDMP) for Uganda
B2: MANUAL CLASSIFIED COUNT (MCC)
B3: ROAD NAME: | C3: MCC - C2 - STN-61-NSANGI-BULOBA ROAD
C5: Date | D5: 23.09.19 | F5: Location | G5: HANA international school | J5: Surveyor | K5: nakawala justine
C6: Dir. From | D6: BULOBA | F6: Dir. To | G6: NSANGI | J6: Supervisor | K6: Dennis
B8: Time / Veh Type | R8: SUMMARY TRAFFIC VOLUMES
C9: 1. Car | D9: 2. Station Wagon | E9: 3. Pickups | F9: 4. Minibus, matatu | G9: 5. Medium bus | H9: 6. Large Bus | I9: 7. Light Truck | J9: 8. Medium Truck | K9: 9. Heavy truck | L9: 10. Truck Trailer | M9: 11. Motor cycles | N9: 12. Tractors | O9: Total Excl M/Cycles | P9: Total All | R9: Time | S9: 1. Car | T9: 2. Station Wagon | U9: 3. Pickups | V9: 4. Minibus, matatu | W9: 5. Medium bus | X9: 6. Large Bus | Y9: 7. Light Truck | Z9: 8. Medium Truck | AA9: 9. Heavy truck | AB9: 10. Truck Trailer | AC9: 11. Motorcycles | AD9: 12. Tractors, Graders | AE9: Total Excl M/ Cycles | AF9: Total All
B10: 07.00 - 07.15 | C10: 3 | D10: 2 | E10: 0 | F10: 0 | G10: 0 | H10: 0 | I10: 2 | J10: 0 | K10: 0 | L10: 0 | M10: 28 | N10: 0 | O10: =SUM(C10:L10,N10) -> 7 | P10: =SUM(C10:N10) -> 35 | R10: 0700-0800 | S10: =SUM(C10:C13) -> 16 | T10: =SUM(D10:D13) -> 3 | U10: =SUM(E10:E13) -> 3 | V10: =SUM(F10:F13) -> 3 | W10: =SUM(G10:G13) -> 0 | X10: =SUM(H10:H13) -> 0 | Y10: =SUM(I10:I13) -> 4 | Z10: =SUM(J10:J13) -> 0 | ... AF10: =SUM(P10:P13) -> 141
B11: 07.15 - 07.30 | C11: 3 | D11: 1 | E11: 1 | F11: 0 | G11: 0 | H11: 0 | I11: 0 | J11: 0 | K11: 0 | L11: 0 | M11: 31 | N11: 0 | O11: =SUM(C11:L11,N11) -> 5 | P11: =SUM(C11:N11) -> 36 | R11: 0800-0900 | S11: =SUM(C14:C17) -> 17 | T11: =SUM(D14:D17) -> 1 | U11: =SUM(E14:E17) -> 4 | V11: =SUM(F14:F17) -> 0 | W11: =SUM(G14:G17) -> 0 | X11: =SUM(H14:H17) -> 0 | Y11: =SUM(I14:I17) -> 3 | Z11: =SUM(J14:J17) -> 0 | ... AF11: =SUM(P14:P17) -> 139
B12: 07.30 - 07.45 | C12: 4 | D12: 0 | E12: 1 | F12: 0 | G12: 0 | H12: 0 | I12: 0 | J12: 0 | K12: 0 | L12: 0 | M12: 27 | N12: 0 | O12: =SUM(C12:L12,N12) -> 5 | P12: =SUM(C12:N12) -> 32 | R12: 0900-1000 | S12: =SUM(C18:C21) -> 15 | T12: =SUM(D18:D21) -> 7 | U12: =SUM(E18:E21) -> 2 | V12: =SUM(F18:F21) -> 1 | W12: =SUM(G18:G21) -> 0 | X12: =SUM(H18:H21) -> 0 | Y12: =SUM(I18:I21) -> 6 | Z12: =SUM(J18:J21) -> 0 | ... AF12: =SUM(P18:P21) -> 126
B13: 07.45 - 08.00 | C13: 6 | D13: 0 | E13: 1 | F13: 3 | G13: 0 | H13: 0 | I13: 2 | J13: 0 | K13: 0 | L13: 0 | M13: 26 | N13: 0 | O13: =SUM(C13:L13,N13) -> 12 | P13: =SUM(C13:N13) -> 38 | R13: 1000-1100 | S13: =SUM(C22:C25) -> 16 | T13: =SUM(D22:D25) -> 5 | U13: =SUM(E22:E25) -> 3 | V13: =SUM(F22:F25) -> 0 | W13: =SUM(G22:G25) -> 0 | X13: =SUM(H22:H25) -> 0 | Y13: =SUM(I22:I25) -> 3 | Z13: =SUM(J22:J25) -> 1 | ... AF13: =SUM(P22:P25) -> 104
B14: 08.00 - 08.15 | C14: 8 | D14: 1 | E14: 0 | F14: 0 | G14: 0 | H14: 0 | I14: 0 | J14: 0 | K14: 0 | L14: 0 | M14: 34 | N14: 0 | O14: =SUM(C14:L14,N14) -> 9 | P14: =SUM(C14:N14) -> 43 | R14: 1100-1200 | S14: =SUM(C26:C29) -> 22 | T14: =SUM(D26:D29) -> 3 | U14: =SUM(E26:E29) -> 2 | V14: =SUM(F26:F29) -> 2 | W14: =SUM(G26:G29) -> 0 | X14: =SUM(H26:H29) -> 0 | Y14: =SUM(I26:I29) -> 7 | Z14: =SUM(J26:J29) -> 1 | ... AF14: =SUM(P26:P29) -> 107
B15: 08.15 - 08.30 | C15: 4 | D15: 0 | E15: 1 | F15: 0 | G15: 0 | H15: 0 | I15: 0 | J15: 0 | K15: 0 | L15: 0 | M15: 21 | N15: 0 | O15: =SUM(C15:L15,N15) -> 5 | P15: =SUM(C15:N15) -> 26 | R15: 1200-1300 | S15: =SUM(C30:C33) -> 11 | T15: =SUM(D30:D33) -> 1 | U15: =SUM(E30:E33) -> 3 | V15: =SUM(F30:F33) -> 3 | W15: =SUM(G30:G33) -> 4 | X15: =SUM(H30:H33) -> 0 | Y15: =SUM(I30:I33) -> 4 | Z15: =SUM(J30:J33) -> 2 | ... AF15: =SUM(P30:P33) -> 91
B16: 08.30 - 08.45 | C16: 3 | D16: 0 | E16: 3 | F16: 0 | G16: 0 | H16: 0 | I16: 2 | J16: 0 | K16: 0 | L16: 0 | M16: 30 | N16: 0 | O16: =SUM(C16:L16,N16) -> 8 | P16: =SUM(C16:N16) -> 38 | R16: 1300-1400 | S16: =SUM(C34:C37) -> 10 | T16: =SUM(D34:D37) -> 5 | U16: =SUM(E34:E37) -> 0 | V16: =SUM(F34:F37) -> 0 | W16: =SUM(G34:G37) -> 0 | X16: =SUM(H34:H37) -> 0 | Y16: =SUM(I34:I37) -> 4 | Z16: =SUM(J34:J37) -> 0 | ... AF16: =SUM(P34:P37) -> 92
B17: 08.45 - 9.00 | C17: 2 | D17: 0 | E17: 0 | F17: 0 | G17: 0 | H17: 0 | I17: 1 | J17: 0 | K17: 0 | L17: 0 | M17: 29 | N17: 0 | O17: =SUM(C17:L17,N17) -> 3 | P17: =SUM(C17:N17) -> 32 | R17: 1400-1500 | S17: =SUM(C38:C41) -> 15 | T17: =SUM(D38:D41) -> 2 | U17: =SUM(E38:E41) -> 2 | V17: =SUM(F38:F41) -> 3 | W17: =SUM(G38:G41) -> 0 | X17: =SUM(H38:H41) -> 0 | Y17: =SUM(I38:I41) -> 4 | Z17: =SUM(J38:J41) -> 2 | ... AF17: =SUM(P38:P41) -> 105
B18: 09.00 - 09.15 | C18: 4 | D18: 2 | E18: 1 | F18: 0 | G18: 0 | H18: 0 | I18: 1 | J18: 0 | K18: 0 | L18: 0 | M18: 25 | N18: 0 | O18: =SUM(C18:L18,N18) -> 8 | P18: =SUM(C18:N18) -> 33 | R18: 1500-1600 | S18: =SUM(C42:C45) -> 15 | T18: =SUM(D42:D45) -> 5 | U18: =SUM(E42:E45) -> 5 | V18: =SUM(F42:F45) -> 5 | W18: =SUM(G42:G45) -> 0 | X18: =SUM(H42:H45) -> 0 | Y18: =SUM(I42:I45) -> 6 | Z18: =SUM(J42:J45) -> 0 | ... AF18: =SUM(P42:P45) -> 97
B19: 09.15 - 09.30 | C19: 2 | D19: 2 | E19: 0 | F19: 1 | G19: 0 | H19: 0 | I19: 2 | J19: 0 | K19: 0 | L19: 0 | M19: 22 | N19: 0 | O19: =SUM(C19:L19,N19) -> 7 | P19: =SUM(C19:N19) -> 29 | R19: 1600-1700 | S19: =SUM(C46:C49) -> 10 | T19: =SUM(D46:D49) -> 4 | U19: =SUM(E46:E49) -> 6 | V19: =SUM(F46:F49) -> 5 | W19: =SUM(G46:G49) -> 1 | X19: =SUM(H46:H49) -> 0 | Y19: =SUM(I46:I49) -> 11 | Z19: =SUM(J46:J49) -> 1 | ... AF19: =SUM(P46:P49) -> 102
B20: 09.30 - 09.45 | C20: 6 | D20: 2 | E20: 0 | F20: 0 | G20: 0 | H20: 0 | I20: 1 | J20: 0 | K20: 0 | L20: 0 | M20: 27 | N20: 0 | O20: =SUM(C20:L20,N20) -> 9 | P20: =SUM(C20:N20) -> 36 | R20: 1700-1800 | S20: =SUM(C50:C53) -> 28 | T20: =SUM(D50:D53) -> 4 | U20: =SUM(E50:E53) -> 3 | V20: =SUM(F50:F53) -> 6 | W20: =SUM(G50:G53) -> 2 | X20: =SUM(H50:H53) -> 0 | Y20: =SUM(I50:I53) -> 7 | Z20: =SUM(J50:J53) -> 0 | ... AF20: =SUM(P50:P53) -> 136
B21: 09.45 - 10.00 | C21: 3 | D21: 1 | E21: 1 | F21: 0 | G21: 0 | H21: 0 | I21: 2 | J21: 0 | K21: 0 | L21: 0 | M21: 21 | N21: 0 | O21: =SUM(C21:L21,N21) -> 7 | P21: =SUM(C21:N21) -> 28 | R21: 1800-1900 | S21: =SUM(C54:C57) -> 24 | T21: =SUM(D54:D57) -> 4 | U21: =SUM(E54:E57) -> 7 | V21: =SUM(F54:F57) -> 4 | W21: =SUM(G54:G57) -> 1 | X21: =SUM(H54:H57) -> 2 | Y21: =SUM(I54:I57) -> 9 | Z21: =SUM(J54:J57) -> 2 | ... AF21: =SUM(P54:P57) -> 142
B22: 10.00 - 10.15 | C22: 3 | D22: 2 | E22: 1 | F22: 0 | G22: 0 | H22: 0 | I22: 2 | J22: 0 | K22: 0 | L22: 0 | M22: 20 | N22: 0 | O22: =SUM(C22:L22,N22) -> 8 | P22: =SUM(C22:N22) -> 28 | R22: AM Peak Hr | S22: =MAX(S10:S12) -> 17 | T22: =MAX(T10:T12) -> 7 | U22: =MAX(U10:U12) -> 4 | V22: =MAX(V10:V12) -> 3 | W22: =MAX(W10:W12) -> 0 | X22: =MAX(X10:X12) -> 0 | Y22: =MAX(Y10:Y12) -> 6 | Z22: =MAX(Z10:Z12) -> 0 | ... AF22: =MAX(AF10:AF12) -> 141
B23: 10.15 - 10.30 | C23: 1 | D23: 1 | E23: 0 | F23: 0 | G23: 0 | H23: 0 | I23: 0 | J23: 0 | K23: 1 | L23: 0 | M23: 17 | N23: 0 | O23: =SUM(C23:L23,N23) -> 3 | P23: =SUM(C23:N23) -> 20 | R23: IP Peak Hr | S23: =MAX(S13:S18) -> 22 | T23: =MAX(T13:T18) -> 5 | U23: =MAX(U13:U18) -> 5 | V23: =MAX(V13:V18) -> 5 | W23: =MAX(W13:W18) -> 4 | X23: =MAX(X13:X18) -> 0 | Y23: =MAX(Y13:Y18) -> 7 | Z23: =MAX(Z13:Z18) -> 2 | ... AF23: =MAX(AF13:AF18) -> 107
B24: 10.30 - 10.45 | C24: 8 | D24: 1 | E24: 1 | F24: 0 | G24: 0 | H24: 0 | I24: 0 | J24: 0 | K24: 0 | L24: 0 | M24: 20 | N24: 0 | O24: =SUM(C24:L24,N24) -> 10 | P24: =SUM(C24:N24) -> 30 | R24: PM Peak Hr | S24: =MAX(S19:S21) -> 28 | T24: =MAX(T19:T21) -> 4 | U24: =MAX(U19:U21) -> 7 | V24: =MAX(V19:V21) -> 6 | W24: =MAX(W19:W21) -> 2 | X24: =MAX(X19:X21) -> 2 | Y24: =MAX(Y19:Y21) -> 11 | Z24: =MAX(Z19:Z21) -> 2 | ... AF24: =MAX(AF19:AF21) -> 142
B25: 10.45 - 11.00 | C25: 4 | D25: 1 | E25: 1 | F25: 0 | G25: 0 | H25: 0 | I25: 1 | J25: 1 | K25: 0 | L25: 0 | M25: 18 | N25: 0 | O25: =SUM(C25:L25,N25) -> 8 | P25: =SUM(C25:N25) -> 26 | R25: AM Period | S25: =SUM(S10:S12) -> 48 | T25: =SUM(T10:T12) -> 11 | U25: =SUM(U10:U12) -> 9 | V25: =SUM(V10:V12) -> 4 | W25: =SUM(W10:W12) -> 0 | X25: =SUM(X10:X12) -> 0 | Y25: =SUM(Y10:Y12) -> 13 | Z25: =SUM(Z10:Z12) -> 0 | ... AF25: =SUM(AF10:AF12) -> 406
B26: 11.00 - 11.15 | C26: 7 | D26: 1 | E26: 0 | F26: 0 | G26: 0 | H26: 0 | I26: 2 | J26: 0 | K26: 0 | L26: 0 | M26: 20 | N26: 0 | O26: =SUM(C26:L26,N26) -> 10 | P26: =SUM(C26:N26) -> 30 | R26: IP Period | S26: =SUM(S13:S18) -> 89 | T26: =SUM(T13:T18) -> 21 | U26: =SUM(U13:U18) -> 15 | V26: =SUM(V13:V18) -> 13 | W26: =SUM(W13:W18) -> 4 | X26: =SUM(X13:X18) -> 0 | Y26: =SUM(Y13:Y18) -> 28 | Z26: =SUM(Z13:Z18) -> 6 | ... AF26: =SUM(AF13:AF18) -> 596
B27: 11.15 - 11.30 | C27: 5 | D27: 1 | E27: 1 | F27: 0 | G27: 0 | H27: 0 | I27: 0 | J27: 0 | K27: 0 | L27: 0 | M27: 14 | N27: 0 | O27: =SUM(C27:L27,N27) -> 7 | P27: =SUM(C27:N27) -> 21 | R27: PM Period | S27: =SUM(S19:S21) -> 62 | T27: =SUM(T19:T21) -> 12 | U27: =SUM(U19:U21) -> 16 | V27: =SUM(V19:V21) -> 15 | W27: =SUM(W19:W21) -> 4 | X27: =SUM(X19:X21) -> 2 | Y27: =SUM(Y19:Y21) -> 27 | Z27: =SUM(Z19:Z21) -> 3 | ... AF27: =SUM(AF19:AF21) -> 380
B28: 11.30 - 11.45 | C28: 6 | D28: 0 | E28: 0 | F28: 0 | G28: 0 | H28: 0 | I28: 1 | J28: 1 | K28: 0 | L28: 0 | M28: 16 | N28: 0 | O28: =SUM(C28:L28,N28) -> 8 | P28: =SUM(C28:N28) -> 24 | R28: 12 Hours | S28: =SUM(S10:S21) -> 199 | T28: =SUM(T10:T21) -> 44 | U28: =SUM(U10:U21) -> 40 | V28: =SUM(V10:V21) -> 32 | W28: =SUM(W10:W21) -> 8 | X28: =SUM(X10:X21) -> 2 | Y28: =SUM(Y10:Y21) -> 68 | Z28: =SUM(Z10:Z21) -> 9 | ... AF28: =SUM(AF10:AF21) -> 1382
B29: 11.45 - 12.00 | C29: 4 | D29: 1 | E29: 1 | F29: 2 | G29: 0 | H29: 0 | I29: 4 | J29: 0 | K29: 0 | L29: 0 | M29: 20 | N29: 0 | O29: =SUM(C29:L29,N29) -> 12 | P29: =SUM(C29:N29) -> 32
B30: 12.00 - 12.15 | C30: 3 | D30: 0 | E30: 1 | F30: 0 | G30: 2 | H30: 0 | I30: 2 | J30: 0 | K30: 0 | L30: 0 | M30: 13 | N30: 0 | O30: =SUM(C30:L30,N30) -> 8 | P30: =SUM(C30:N30) -> 21
B31: 12.15 - 12.30 | C31: 1 | D31: 0 | E31: 2 | F31: 1 | G31: 0 | H31: 0 | I31: 0 | J31: 2 | K31: 0 | L31: 0 | M31: 14 | N31: 0 | O31: =SUM(C31:L31,N31) -> 6 | P31: =SUM(C31:N31) -> 20
B32: 12.30 - 12.45 | C32: 5 | D32: 0 | E32: 0 | F32: 2 | G32: 0 | H32: 0 | I32: 0 | J32: 0 | K32: 0 | L32: 0 | M32: 20 | N32: 0 | O32: =SUM(C32:L32,N32) -> 7 | P32: =SUM(C32:N32) -> 27
B33: 12.45 - 13.00 | C33: 2 | D33: 1 | E33: 0 | F33: 0 | G33: 2 | H33: 0 | I33: 2 | J33: 0 | K33: 0 | L33: 0 | M33: 16 | N33: 0 | O33: =SUM(C33:L33,N33) -> 7 | P33: =SUM(C33:N33) -> 23
B34: 13.00 - 13.15 | C34: 3 | D34: 2 | E34: 0 | F34: 0 | G34: 0 | H34: 0 | I34: 0 | J34: 0 | K34: 0 | L34: 0 | M34: 18 | N34: 0 | O34: =SUM(C34:L34,N34) -> 5 | P34: =SUM(C34:N34) -> 23
B35: 13.15 - 13.30 | C35: 0 | D35: 0 | E35: 0 | F35: 0 | G35: 0 | H35: 0 | I35: 0 | J35: 0 | K35: 0 | L35: 0 | M35: 13 | N35: 0 | O35: =SUM(C35:L35,N35) -> 0 | P35: =SUM(C35:N35) -> 13
B36: 13.30 - 13.45 | C36: 3 | D36: 1 | E36: 0 | F36: 0 | G36: 0 | H36: 0 | I36: 1 | J36: 0 | K36: 0 | L36: 0 | M36: 22 | N36: 0 | O36: =SUM(C36:L36,N36) -> 5 | P36: =SUM(C36:N36) -> 27
B37: 13.45 - 14.00 | C37: 4 | D37: 2 | E37: 0 | F37: 0 | G37: 0 | H37: 0 | I37: 3 | J37: 0 | K37: 0 | L37: 0 | M37: 20 | N37: 0 | O37: =SUM(C37:L37,N37) -> 9 | P37: =SUM(C37:N37) -> 29
B38: 14.00 - 14.15 | C38: 7 | D38: 0 | E38: 0 | F38: 2 | G38: 0 | H38: 0 | I38: 0 | J38: 2 | K38: 0 | L38: 0 | M38: 24 | N38: 0 | O38: =SUM(C38:L38,N38) -> 11 | P38: =SUM(C38:N38) -> 35
B39: 14.15 - 14.30 | C39: 3 | D39: 2 | E39: 0 | F39: 0 | G39: 0 | H39: 0 | I39: 2 | J39: 0 | K39: 0 | L39: 0 | M39: 18 | N39: 0 | O39: =SUM(C39:L39,N39) -> 7 | P39: =SUM(C39:N39) -> 25
B40: 14.30 - 14.45 | C40: 4 | D40: 0 | E40: 2 | F40: 1 | G40: 0 | H40: 0 | I40: 1 | J40: 0 | K40: 0 | L40: 0 | M40: 21 | N40: 0 | O40: =SUM(C40:L40,N40) -> 8 | P40: =SUM(C40:N40) -> 29
... B57: 18.45 - 19.00 | C57: 2 | D57: 0 | E57: 1 | F57: 1 | G57: 0 | H57: 1 | I57: 0 | J57: 0 | K57: 0 | L57: 0 | M57: 19 | N57: 0 | O57: =SUM(C57:L57,N57) -> 5 | P57: =SUM(C57:N57) -> 24
B58: Totals | C58: =SUM(C10:C57) -> 199 | D58: =SUM(D10:D57) -> 44 | E58: =SUM(E10:E57) -> 40 | F58: =SUM(F10:F57) -> 32 | G58: =SUM(G10:G57) -> 8 | H58: =SUM(H10:H57) -> 2 | I58: =SUM(I10:I57) -> 68 | J58: =SUM(J10:J57) -> 9 | ... P58: =SUM(P10:P57) -> 1382
...

Sheet 23.09- NSANGI-BULOBA
B1: Consultancy services for Preparation of Expressway Development Master Plan (EDMP) for Uganda
B2: MANUAL CLASSIFIED COUNT (MCC)
B3: ROAD NAME: | C3: ='23.09-BULOBA- NSANGI'!C3:G3 -> MCC - C2 - STN-61-NSANGI-BULOBA ROAD
C5: Date | D5: ='23.09-BULOBA- NSANGI'!D5 -> 23.09.19 | F5: Location | G5: ='23.09-BULOBA- NSANGI'!G5:H5 -> HANA international school | J5: Surveyor | K5: MIREMBE-RUTH
C6: Dir. From | D6: NSANGI | F6: Dir. To | G6: BULOBA | J6: Supervisor | K6: ='23.09-BULOBA- NSANGI'!K6:L6 -> Dennis
B8: Time / Veh Type | R8: SUMMARY TRAFFIC VOLUMES
C9: 1. Car | D9: 2. Station Wagon | E9: 3. Pickups | F9: 4. Minibus, matatu | G9: 5. Medium bus | H9: 6. Large Bus | I9: 7. Light Truck | J9: 8. Medium Truck | K9: 9. Heavy truck | L9: 10. Truck Trailer | M9: 11. Motor cycles | N9: 12. Tractors | O9: Total Excl M/Cycles | P9: Total All | R9: Time | S9: 1. Car | T9: 2. Station Wagon | U9: 3. Pickups | V9: 4. Minibus, matatu | W9: 5. Medium bus | X9: 6. Large Bus | Y9: 7. Light Truck | Z9: 8. Medium Truck | AA9: 9. Heavy truck | AB9: 10. Truck Trailer | AC9: 11. Motorcycles | AD9: 12. Tractors, Graders | AE9: Total Excl M/ Cycles | AF9: Total All
B10: 07.00 - 07.15 | C10: 3 | D10: 0 | E10: 0 | F10: 1 | G10: 1 | H10: 0 | I10: 2 | J10: 0 | K10: 0 | L10: 0 | M10: 18 | N10: 0 | O10: =SUM(C10:L10,N10) -> 7 | P10: =SUM(C10:N10) -> 25 | R10: 0700-0800 | S10: =SUM(C10:C13) -> 14 | T10: =SUM(D10:D13) -> 2 | U10: =SUM(E10:E13) -> 3 | V10: =SUM(F10:F13) -> 3 | W10: =SUM(G10:G13) -> 1 | X10: =SUM(H10:H13) -> 0 | Y10: =SUM(I10:I13) -> 5 | Z10: =SUM(J10:J13) -> 0 | ... AF10: =SUM(P10:P13) -> 135
B11: 07.15 - 07.30 | C11: 3 | D11: 1 | E11: 1 | F11: 0 | G11: 0 | H11: 0 | I11: 0 | J11: 0 | K11: 0 | L11: 0 | M11: 26 | N11: 0 | O11: =SUM(C11:L11,N11) -> 5 | P11: =SUM(C11:N11) -> 31 | R11: 0800-0900 | S11: =SUM(C14:C17) -> 17 | T11: =SUM(D14:D17) -> 3 | U11: =SUM(E14:E17) -> 1 | V11: =SUM(F14:F17) -> 2 | W11: =SUM(G14:G17) -> 0 | X11: =SUM(H14:H17) -> 0 | Y11: =SUM(I14:I17) -> 2 | Z11: =SUM(J14:J17) -> 0 | ... AF11: =SUM(P14:P17) -> 123
B12: 07.30 - 07.45 | C12: 4 | D12: 1 | E12: 0 | F12: 1 | G12: 0 | H12: 0 | I12: 2 | J12: 0 | K12: 0 | L12: 0 | M12: 28 | N12: 0 | O12: =SUM(C12:L12,N12) -> 8 | P12: =SUM(C12:N12) -> 36 | R12: 0900-1000 | S12: =SUM(C18:C21) -> 11 | T12: =SUM(D18:D21) -> 5 | U12: =SUM(E18:E21) -> 3 | V12: =SUM(F18:F21) -> 0 | W12: =SUM(G18:G21) -> 0 | X12: =SUM(H18:H21) -> 0 | Y12: =SUM(I18:I21) -> 6 | Z12: =SUM(J18:J21) -> 1 | ... AF12: =SUM(P18:P21) -> 117
B13: 07.45 - 08.00 | C13: 4 | D13: 0 | E13: 2 | F13: 1 | G13: 0 | H13: 0 | I13: 1 | J13: 0 | K13: 0 | L13: 0 | M13: 35 | N13: 0 | O13: =SUM(C13:L13,N13) -> 8 | P13: =SUM(C13:N13) -> 43 | R13: 1000-1100 | S13: =SUM(C22:C25) -> 11 | T13: =SUM(D22:D25) -> 3 | U13: =SUM(E22:E25) -> 3 | V13: =SUM(F22:F25) -> 0 | W13: =SUM(G22:G25) -> 0 | X13: =SUM(H22:H25) -> 0 | Y13: =SUM(I22:I25) -> 6 | Z13: =SUM(J22:J25) -> 1 | ... AF13: =SUM(P22:P25) -> 103
B14: 08.00 - 08.15 | C14: 5 | D14: 2 | E14: 0 | F14: 1 | G14: 0 | H14: 0 | I14: 0 | J14: 0 | K14: 0 | L14: 0 | M14: 30 | N14: 0 | O14: =SUM(C14:L14,N14) -> 8 | P14: =SUM(C14:N14) -> 38 | R14: 1100-1200 | S14: =SUM(C26:C29) -> 13 | T14: =SUM(D26:D29) -> 0 | U14: =SUM(E26:E29) -> 4 | V14: =SUM(F26:F29) -> 1 | W14: =SUM(G26:G29) -> 0 | X14: =SUM(H26:H29) -> 0 | Y14: =SUM(I26:I29) -> 5 | Z14: =SUM(J26:J29) -> 0 | ... AF14: =SUM(P26:P29) -> 90
B15: 08.15 - 08.30 | C15: 5 | D15: 0 | E15: 0 | F15: 0 | G15: 0 | H15: 0 | I15: 1 | J15: 0 | K15: 0 | L15: 0 | M15: 24 | N15: 0 | O15: =SUM(C15:L15,N15) -> 6 | P15: =SUM(C15:N15) -> 30 | R15: 1200-1300 | S15: =SUM(C30:C33) -> 14 | T15: =SUM(D30:D33) -> 1 | U15: =SUM(E30:E33) -> 2 | V15: =SUM(F30:F33) -> 3 | W15: =SUM(G30:G33) -> 0 | X15: =SUM(H30:H33) -> 0 | Y15: =SUM(I30:I33) -> 1 | Z15: =SUM(J30:J33) -> 0 | ... AF15: =SUM(P30:P33) -> 93
B16: 08.30 - 08.45 | C16: 3 | D16: 0 | E16: 0 | F16: 1 | G16: 0 | H16: 0 | I16: 0 | J16: 0 | K16: 0 | L16: 0 | M16: 18 | N16: 0 | O16: =SUM(C16:L16,N16) -> 4 | P16: =SUM(C16:N16) -> 22 | R16: 1300-1400 | S16: =SUM(C34:C37) -> 15 | T16: =SUM(D34:D37) -> 2 | U16: =SUM(E34:E37) -> 2 | V16: =SUM(F34:F37) -> 0 | W16: =SUM(G34:G37) -> 0 | X16: =SUM(H34:H37) -> 1 | Y16: =SUM(I34:I37) -> 6 | Z16: =SUM(J34:J37) -> 1 | ... AF16: =SUM(P34:P37) -> 94
B17: 08.45 - 9.00 | C17: 4 | D17: 1 | E17: 1 | F17: 0 | G17: 0 | H17: 0 | I17: 1 | J17: 0 | K17: 0 | L17: 0 | M17: 26 | N17: 0 | O17: =SUM(C17:L17,N17) -> 7 | P17: =SUM(C17:N17) -> 33 | R17: 1400-1500 | S17: =SUM(C38:C41) -> 17 | T17: =SUM(D38:D41) -> 3 | U17: =SUM(E38:E41) -> 3 | V17: =SUM(F38:F41) -> 2 | W17: =SUM(G38:G41) -> 0 | X17: =SUM(H38:H41) -> 0 | Y17: =SUM(I38:I41) -> 4 | Z17: =SUM(J38:J41) -> 0 | ... AF17: =SUM(P38:P41) -> 99
B18: 09.00 - 09.15 | C18: 4 | D18: 0 | E18: 1 | F18: 0 | G18: 0 | H18: 0 | I18: 1 | J18: 1 | K18: 0 | L18: 0 | M18: 21 | N18: 0 | O18: =SUM(C18:L18,N18) -> 7 | P18: =SUM(C18:N18) -> 28 | R18: 1500-1600 | S18: =SUM(C42:C45) -> 14 | T18: =SUM(D42:D45) -> 6 | U18: =SUM(E42:E45) -> 2 | V18: =SUM(F42:F45) -> 1 | W18: =SUM(G42:G45) -> 0 | X18: =SUM(H42:H45) -> 0 | Y18: =SUM(I42:I45) -> 7 | Z18: =SUM(J42:J45) -> 0 | ... AF18: =SUM(P42:P45) -> 78
B19: 09.15 - 09.30 | C19: 4 | D19: 1 | E19: 1 | F19: 0 | G19: 0 | H19: 0 | I19: 1 | J19: 0 | K19: 0 | L19: 0 | M19: 23 | N19: 0 | O19: =SUM(C19:L19,N19) -> 7 | P19: =SUM(C19:N19) -> 30 | R19: 1600-1700 | S19: =SUM(C46:C49) -> 21 | T19: =SUM(D46:D49) -> 6 | U19: =SUM(E46:E49) -> 4 | V19: =SUM(F46:F49) -> 3 | W19: =SUM(G46:G49) -> 3 | X19: =SUM(H46:H49) -> 1 | Y19: =SUM(I46:I49) -> 4 | Z19: =SUM(J46:J49) -> 0 | ... AF19: =SUM(P46:P49) -> 110
B20: 09.30 - 09.45 | C20: 1 | D20: 4 | E20: 1 | F20: 0 | G20: 0 | H20: 0 | I20: 2 | J20: 0 | K20: 0 | L20: 0 | M20: 27 | N20: 0 | O20: =SUM(C20:L20,N20) -> 8 | P20: =SUM(C20:N20) -> 35 | R20: 1700-1800 | S20: =SUM(C50:C53) -> 41 | T20: =SUM(D50:D53) -> 3 | U20: =SUM(E50:E53) -> 5 | V20: =SUM(F50:F53) -> 1 | W20: =SUM(G50:G53) -> 3 | X20: =SUM(H50:H53) -> 0 | Y20: =SUM(I50:I53) -> 11 | Z20: =SUM(J50:J53) -> 0 | ... AF20: =SUM(P50:P53) -> 156
B21: 09.45 - 10.00 | C21: 2 | D21: 0 | E21: 0 | F21: 0 | G21: 0 | H21: 0 | I21: 2 | J21: 0 | K21: 0 | L21: 0 | M21: 20 | N21: 0 | O21: =SUM(C21:L21,N21) -> 4 | P21: =SUM(C21:N21) -> 24 | R21: 1800-1900 | S21: =SUM(C54:C57) -> 17 | T21: =SUM(D54:D57) -> 0 | U21: =SUM(E54:E57) -> 3 | V21: =SUM(F54:F57) -> 5 | W21: =SUM(G54:G57) -> 1 | X21: =SUM(H54:H57) -> 0 | Y21: =SUM(I54:I57) -> 5 | Z21: =SUM(J54:J57) -> 0 | ... AF21: =SUM(P54:P57) -> 93
B22: 10.00 - 10.15 | C22: 1 | D22: 1 | E22: 1 | F22: 0 | G22: 0 | H22: 0 | I22: 2 | J22: 1 | K22: 0 | L22: 0 | M22: 22 | N22: 0 | O22: =SUM(C22:L22,N22) -> 6 | P22: =SUM(C22:N22) -> 28 | R22: AM Peak Hr | S22: =MAX(S10:S12) -> 17 | T22: =MAX(T10:T12) -> 5 | U22: =MAX(U10:U12) -> 3 | V22: =MAX(V10:V12) -> 3 | W22: =MAX(W10:W12) -> 1 | X22: =MAX(X10:X12) -> 0 | Y22: =MAX(Y10:Y12) -> 6 | Z22: =MAX(Z10:Z12) -> 1 | ... AF22: =MAX(AF10:AF12) -> 135
B23: 10.15 - 10.30 | C23: 4 | D23: 1 | E23: 2 | F23: 0 | G23: 0 | H23: 0 | I23: 1 | J23: 0 | K23: 0 | L23: 0 | M23: 19 | N23: 0 | O23: =SUM(C23:L23,N23) -> 8 | P23: =SUM(C23:N23) -> 27 | R23: IP Peak Hr | S23: =MAX(S13:S18) -> 17 | T23: =MAX(T13:T18) -> 6 | U23: =MAX(U13:U18) -> 4 | V23: =MAX(V13:V18) -> 3 | W23: =MAX(W13:W18) -> 0 | X23: =MAX(X13:X18) -> 1 | Y23: =MAX(Y13:Y18) -> 7 | Z23: =MAX(Z13:Z18) -> 1 | ... AF23: =MAX(AF13:AF18) -> 103
B24: 10.30 - 10.45 | C24: 5 | D24: 1 | E24: 0 | F24: 0 | G24: 0 | H24: 0 | I24: 1 | J24: 0 | K24: 0 | L24: 0 | M24: 22 | N24: 0 | O24: =SUM(C24:L24,N24) -> 7 | P24: =SUM(C24:N24) -> 29 | R24: PM Peak Hr | S24: =MAX(S19:S21) -> 41 | T24: =MAX(T19:T21) -> 6 | U24: =MAX(U19:U21) -> 5 | V24: =MAX(V19:V21) -> 5 | W24: =MAX(W19:W21) -> 3 | X24: =MAX(X19:X21) -> 1 | Y24: =MAX(Y19:Y21) -> 11 | Z24: =MAX(Z19:Z21) -> 0 | ... AF24: =MAX(AF19:AF21) -> 156
B25: 10.45 - 11.00 | C25: 1 | D25: 0 | E25: 0 | F25: 0 | G25: 0 | H25: 0 | I25: 2 | J25: 0 | K25: 0 | L25: 0 | M25: 16 | N25: 0 | O25: =SUM(C25:L25,N25) -> 3 | P25: =SUM(C25:N25) -> 19 | R25: AM Period | S25: =SUM(S10:S12) -> 42 | T25: =SUM(T10:T12) -> 10 | U25: =SUM(U10:U12) -> 7 | V25: =SUM(V10:V12) -> 5 | W25: =SUM(W10:W12) -> 1 | X25: =SUM(X10:X12) -> 0 | Y25: =SUM(Y10:Y12) -> 13 | Z25: =SUM(Z10:Z12) -> 1 | ... AF25: =SUM(AF10:AF12) -> 375
B26: 11.00 - 11.15 | C26: 6 | D26: 0 | E26: 1 | F26: 0 | G26: 0 | H26: 0 | I26: 1 | J26: 0 | K26: 0 | L26: 0 | M26: 11 | N26: 0 | O26: =SUM(C26:L26,N26) -> 8 | P26: =SUM(C26:N26) -> 19 | R26: IP Period | S26: =SUM(S13:S18) -> 84 | T26: =SUM(T13:T18) -> 15 | U26: =SUM(U13:U18) -> 16 | V26: =SUM(V13:V18) -> 7 | W26: =SUM(W13:W18) -> 0 | X26: =SUM(X13:X18) -> 1 | Y26: =SUM(Y13:Y18) -> 29 | Z26: =SUM(Z13:Z18) -> 2 | ... AF26: =SUM(AF13:AF18) -> 557
B27: 11.15 - 11.30 | C27: 2 | D27: 0 | E27: 1 | F27: 1 | G27: 0 | H27: 0 | I27: 0 | J27: 0 | K27: 0 | L27: 0 | M27: 20 | N27: 0 | O27: =SUM(C27:L27,N27) -> 4 | P27: =SUM(C27:N27) -> 24 | R27: PM Period | S27: =SUM(S19:S21) -> 79 | T27: =SUM(T19:T21) -> 9 | U27: =SUM(U19:U21) -> 12 | V27: =SUM(V19:V21) -> 9 | W27: =SUM(W19:W21) -> 7 | X27: =SUM(X19:X21) -> 1 | Y27: =SUM(Y19:Y21) -> 20 | Z27: =SUM(Z19:Z21) -> 0 | ... AF27: =SUM(AF19:AF21) -> 359
B28: 11.30 - 11.45 | C28: 2 | D28: 0 | E28: 2 | F28: 0 | G28: 0 | H28: 0 | I28: 2 | J28: 0 | K28: 0 | L28: 0 | M28: 17 | N28: 0 | O28: =SUM(C28:L28,N28) -> 6 | P28: =SUM(C28:N28) -> 23 | R28: 12 Hours | S28: =SUM(S10:S21) -> 205 | T28: =SUM(T10:T21) -> 34 | U28: =SUM(U10:U21) -> 35 | V28: =SUM(V10:V21) -> 21 | W28: =SUM(W10:W21) -> 8 | X28: =SUM(X10:X21) -> 2 | Y28: =SUM(Y10:Y21) -> 62 | Z28: =SUM(Z10:Z21) -> 3 | ... AF28: =SUM(AF10:AF21) -> 1291
B29: 11.45 - 12.00 | C29: 3 | D29: 0 | E29: 0 | F29: 0 | G29: 0 | H29: 0 | I29: 2 | J29: 0 | K29: 0 | L29: 0 | M29: 19 | N29: 0 | O29: =SUM(C29:L29,N29) -> 5 | P29: =SUM(C29:N29) -> 24
B30: 12.00 - 12.15 | C30: 4 | D30: 0 | E30: 1 | F30: 1 | G30: 0 | H30: 0 | I30: 1 | J30: 0 | K30: 0 | L30: 0 | M30: 18 | N30: 0 | O30: =SUM(C30:L30,N30) -> 7 | P30: =SUM(C30:N30) -> 25
B31: 12.15 - 12.30 | C31: 1 | D31: 0 | E31: 0 | F31: 1 | G31: 0 | H31: 0 | I31: 0 | J31: 0 | K31: 1 | L31: 0 | M31: 18 | N31: 0 | O31: =SUM(C31:L31,N31) -> 3 | P31: =SUM(C31:N31) -> 21
B32: 12.30 - 12.45 | C32: 6 | D32: 0 | E32: 1 | F32: 0 | G32: 0 | H32: 0 | I32: 0 | J32: 0 | K32: 0 | L32: 0 | M32: 15 | N32: 0 | O32: =SUM(C32:L32,N32) -> 7 | P32: =SUM(C32:N32) -> 22
B33: 12.45 - 13.00 | C33: 3 | D33: 1 | E33: 0 | F33: 1 | G33: 0 | H33: 0 | I33: 0 | J33: 0 | K33: 0 | L33: 0 | M33: 20 | N33: 0 | O33: =SUM(C33:L33,N33) -> 5 | P33: =SUM(C33:N33) -> 25
B34: 13.00 - 13.15 | C34: 4 | D34: 0 | E34: 1 | F34: 0 | G34: 0 | H34: 0 | I34: 1 | J34: 1 | K34: 0 | L34: 0 | M34: 20 | N34: 0 | O34: =SUM(C34:L34,N34) -> 7 | P34: =SUM(C34:N34) -> 27
B35: 13.15 - 13.30 | C35: 6 | D35: 1 | E35: 0 | F35: 0 | G35: 0 | H35: 0 | I35: 5 | J35: 0 | K35: 0 | L35: 0 | M35: 15 | N35: 0 | O35: =SUM(C35:L35,N35) -> 12 | P35: =SUM(C35:N35) -> 27
B36: 13.30 - 13.45 | C36: 2 | D36: 0 | E36: 1 | F36: 0 | G36: 0 | H36: 1 | I36: 0 | J36: 0 | K36: 0 | L36: 0 | M36: 16 | N36: 0 | O36: =SUM(C36:L36,N36) -> 4 | P36: =SUM(C36:N36) -> 20
B37: 13.45 - 14.00 | C37: 3 | D37: 1 | E37: 0 | F37: 0 | G37: 0 | H37: 0 | I37: 0 | J37: 0 | K37: 0 | L37: 0 | M37: 16 | N37: 0 | O37: =SUM(C37:L37,N37) -> 4 | P37: =SUM(C37:N37) -> 20
B38: 14.00 - 14.15 | C38: 7 | D38: 1 | E38: 2 | F38: 0 | G38: 0 | H38: 0 | I38: 0 | J38: 0 | K38: 0 | L38: 0 | M38: 14 | N38: 0 | O38: =SUM(C38:L38,N38) -> 10 | P38: =SUM(C38:N38) -> 24
B39: 14.15 - 14.30 | C39: 4 | D39: 0 | E39: 0 | F39: 1 | G39: 0 | H39: 0 | I39: 2 | J39: 0 | K39: 0 | L39: 0 | M39: 19 | N39: 0 | O39: =SUM(C39:L39,N39) -> 7 | P39: =SUM(C39:N39) -> 26
B40: 14.30 - 14.45 | C40: 5 | D40: 1 | E40: 1 | F40: 1 | G40: 0 | H40: 0 | I40: 1 | J40: 0 | K40: 0 | L40: 0 | M40: 18 | N40: 0 | O40: =SUM(C40:L40,N40) -> 9 | P40: =SUM(C40:N40) -> 27
... B57: 18.45 - 19.00 | C57: 3 | D57: 0 | E57: 1 | F57: 0 | G57: 0 | H57: 0 | I57: 2 | J57: 0 | K57: 0 | L57: 0 | M57: 19 | N57: 0 | O57: =SUM(C57:L57,N57) -> 6 | P57: =SUM(C57:N57) -> 25
B58: Totals | C58: =SUM(C10:C57) -> 205 | D58: =SUM(D10:D57) -> 34 | E58: =SUM(E10:E57) -> 35 | F58: =SUM(F10:F57) -> 21 | G58: =SUM(G10:G57) -> 8 | H58: =SUM(H10:H57) -> 2 | I58: =SUM(I10:I57) -> 62 | J58: =SUM(J10:J57) -> 3 | ... P58: =SUM(P10:P57) -> 1291
...

Sheet 24.09 Buloba-Nsangi
B1: Consultancy services for Preparation of Expressway Development Master Plan (EDMP) for Uganda
B2: MANUAL CLASSIFIED COUNT (MCC)
B3: ROAD NAME: | C3: ='[1]24.09.2019 NSANGI-BULOBA'!C3:G3 -> MCC-C2-STN61-NSANGI-BULOBA
C5: Date | D5: ='[1]24.09.2019 NSANGI-BULOBA'!D5 -> 24.09.19 | F5: Location | G5: HANA INT. SCHOOL | J5: Surveyor | K5: NAKIWALA JUSTINE
C6: Dir. From | D6: BULOBA | F6: Dir. To | G6: NSANGI | J6: Supervisor | K6: DENIS
B8: Time / Veh Type | R8: SUMMARY TRAFFIC VOLUMES
C9: 1. Car | D9: 2. Station Wagon | E9: 3. Pickups | F9: 4. Minibus, matatu | G9: 5. Medium bus | H9: 6. Large Bus | I9: 7. Light Truck | J9: 8. Medium Truck | K9: 9. Heavy truck | L9: 10. Truck Trailer | M9: 11. Motor cycles | N9: 12. Tractors | O9: Total Excl M/Cycles | P9: Total All | R9: Time | S9: 1. Car | T9: 2. Station Wagon | U9: 3. Pickups | V9: 4. Minibus, matatu | W9: 5. Medium bus | X9: 6. Large Bus | Y9: 7. Light Truck | Z9: 8. Medium Truck | AA9: 9. Heavy truck | AB9: 10. Truck Trailer | AC9: 11. Motorcycles | AD9: 12. Tractors, Graders | AE9: Total Excl M/ Cycles | AF9: Total All
B10: 07.00 - 07.15 | C10: 8 | D10: 1 | E10: 0 | F10: 0 | G10: 0 | H10: 0 | I10: 0 | J10: 0 | K10: 0 | L10: 0 | M10: 21 | N10: 0 | O10: =SUM(C10:L10,N10) -> 9 | P10: =SUM(C10:N10) -> 30 | R10: 0700-0800 | S10: =SUM(C10:C13) -> 20 | T10: =SUM(D10:D13) -> 5 | U10: =SUM(E10:E13) -> 2 | V10: =SUM(F10:F13) -> 2 | W10: =SUM(G10:G13) -> 0 | X10: =SUM(H10:H13) -> 0 | Y10: =SUM(I10:I13) -> 1 | Z10: =SUM(J10:J13) -> 0 | ... AF10: =SUM(P10:P13) -> 136
B11: 07.15 - 07.30 | C11: 4 | D11: 0 | E11: 1 | F11: 1 | G11: 0 | H11: 0 | I11: 1 | J11: 0 | K11: 0 | L11: 0 | M11: 34 | N11: 0 | O11: =SUM(C11:L11,N11) -> 7 | P11: =SUM(C11:N11) -> 41 | R11: 0800-0900 | S11: =SUM(C14:C17) -> 14 | T11: =SUM(D14:D17) -> 3 | U11: =SUM(E14:E17) -> 2 | V11: =SUM(F14:F17) -> 2 | W11: =SUM(G14:G17) -> 0 | X11: =SUM(H14:H17) -> 0 | Y11: =SUM(I14:I17) -> 8 | Z11: =SUM(J14:J17) -> 0 | ... AF11: =SUM(P14:P17) -> 119
B12: 07.30 - 07.45 | C12: 5 | D12: 3 | E12: 1 | F12: 0 | G12: 0 | H12: 0 | I12: 0 | J12: 0 | K12: 0 | L12: 0 | M12: 26 | N12: 0 | O12: =SUM(C12:L12,N12) -> 9 | P12: =SUM(C12:N12) -> 35 | R12: 0900-1000 | S12: =SUM(C18:C21) -> 22 | T12: =SUM(D18:D21) -> 1 | U12: =SUM(E18:E21) -> 3 | V12: =SUM(F18:F21) -> 1 | W12: =SUM(G18:G21) -> 0 | X12: =SUM(H18:H21) -> 0 | Y12: =SUM(I18:I21) -> 9 | Z12: =SUM(J18:J21) -> 0 | ... AF12: =SUM(P18:P21) -> 131
B13: 07.45 - 08.00 | C13: 3 | D13: 1 | E13: 0 | F13: 1 | G13: 0 | H13: 0 | I13: 0 | J13: 0 | K13: 0 | L13: 0 | M13: 25 | N13: 0 | O13: =SUM(C13:L13,N13) -> 5 | P13: =SUM(C13:N13) -> 30 | R13: 1000-1100 | S13: =SUM(C22:C25) -> 18 | T13: =SUM(D22:D25) -> 4 | U13: =SUM(E22:E25) -> 0 | V13: =SUM(F22:F25) -> 0 | W13: =SUM(G22:G25) -> 0 | X13: =SUM(H22:H25) -> 0 | Y13: =SUM(I22:I25) -> 6 | Z13: =SUM(J22:J25) -> 1 | ... AF13: =SUM(P22:P25) -> 112
B14: 08.00 - 08.15 | C14: 5 | D14: 0 | E14: 1 | F14: 0 | G14: 0 | H14: 0 | I14: 1 | J14: 0 | K14: 0 | L14: 0 | M14: 20 | N14: 0 | O14: =SUM(C14:L14,N14) -> 7 | P14: =SUM(C14:N14) -> 27 | R14: 1100-1200 | S14: =SUM(C26:C29) -> 15 | T14: =SUM(D26:D29) -> 1 | U14: =SUM(E26:E29) -> 4 | V14: =SUM(F26:F29) -> 3 | W14: =SUM(G26:G29) -> 0 | X14: =SUM(H26:H29) -> 0 | Y14: =SUM(I26:I29) -> 6 | Z14: =SUM(J26:J29) -> 0 | ... AF14: =SUM(P26:P29) -> 111
B15: 08.15 - 08.30 | C15: 1 | D15: 0 | E15: 1 | F15: 1 | G15: 0 | H15: 0 | I15: 2 | J15: 0 | K15: 0 | L15: 0 | M15: 25 | N15: 0 | O15: =SUM(C15:L15,N15) -> 5 | P15: =SUM(C15:N15) -> 30 | R15: 1200-1300 | S15: =SUM(C30:C33) -> 14 | T15: =SUM(D30:D33) -> 3 | U15: =SUM(E30:E33) -> 2 | V15: =SUM(F30:F33) -> 1 | W15: =SUM(G30:G33) -> 0 | X15: =SUM(H30:H33) -> 0 | Y15: =SUM(I30:I33) -> 6 | Z15: =SUM(J30:J33) -> 0 | ... AF15: =SUM(P30:P33) -> 101
B16: 08.30 - 08.45 | C16: 2 | D16: 0 | E16: 0 | F16: 1 | G16: 0 | H16: 0 | I16: 3 | J16: 0 | K16: 0 | L16: 0 | M16: 20 | N16: 0 | O16: =SUM(C16:L16,N16) -> 6 | P16: =SUM(C16:N16) -> 26 | R16: 1300-1400 | S16: =SUM(C34:C38) -> 19 | T16: =SUM(D34:D38) -> 1 | U16: =SUM(E34:E38) -> 5 | V16: =SUM(F34:F38) -> 5 | W16: =SUM(G34:G38) -> 0 | X16: =SUM(H34:H38) -> 0 | Y16: =SUM(I34:I38) -> 8 | Z16: =SUM(J34:J38) -> 2 | ... AC16: =SUM(M34:M38) -> 91 | AD16: =SUM(N34:N37) -> 0 | AE16: =SUM(O34:O37) -> 32 | AF16: =SUM(P34:P37) -> 109
B17: 08.45 - 9.00 | C17: 6 | D17: 3 | E17: 0 | F17: 0 | G17: 0 | H17: 0 | I17: 2 | J17: 0 | K17: 0 | L17: 0 | M17: 25 | N17: 0 | O17: =SUM(C17:L17,N17) -> 11 | P17: =SUM(C17:N17) -> 36 | R17: 1400-1500 | S17: =SUM(C39:C42) -> 5 | T17: =SUM(D39:D42) -> 1 | U17: =SUM(E39:E42) -> 3 | V17: =SUM(F39:F42) -> 2 | W17: =SUM(G39:G42) -> 0 | X17: =SUM(H39:H42) -> 0 | Y17: =SUM(I39:I42) -> 3 | Z17: =SUM(J39:J42) -> 1 | ... AC17: =SUM(M39:M42) -> 67 | AD17: =SUM(N38:N41) -> 0 | AE17: =SUM(O38:O41) -> 20 | AF17: =SUM(P38:P41) -> 86
B18: 09.00 - 09.15 | C18: 1 | D18: 0 | E18: 0 | F18: 0 | G18: 0 | H18: 0 | I18: 1 | J18: 0 | K18: 0 | L18: 0 | M18: 26 | N18: 0 | O18: =SUM(C18:L18,N18) -> 2 | P18: =SUM(C18:N18) -> 28 | R18: 1500-1600 | S18: =SUM(C43:C46) -> 10 | T18: =SUM(D43:D46) -> 4 | U18: =SUM(E43:E46) -> 7 | V18: =SUM(F43:F46) -> 0 | W18: =SUM(G43:G46) -> 0 | X18: =SUM(H43:H46) -> 0 | Y18: =SUM(I43:I46) -> 3 | Z18: =SUM(J43:J46) -> 1 | ... AC18: =SUM(M43:M46) -> 51 | AD18: =SUM(N42:N45) -> 0 | AE18: =SUM(O42:O45) -> 24 | AF18: =SUM(P42:P45) -> 78
B19: 09.15 - 09.30 | C19: 6 | D19: 0 | E19: 1 | F19: 0 | G19: 0 | H19: 0 | I19: 3 | J19: 0 | K19: 0 | L19: 0 | M19: 19 | N19: 0 | O19: =SUM(C19:L19,N19) -> 10 | P19: =SUM(C19:N19) -> 29 | R19: 1600-1700 | S19: =SUM(C47:C50) -> 17 | T19: =SUM(D47:D50) -> 1 | U19: =SUM(E47:E50) -> 2 | V19: =SUM(F47:F50) -> 2 | W19: =SUM(G47:G50) -> 1 | X19: =SUM(H47:H50) -> 0 | Y19: =SUM(I47:I50) -> 7 | Z19: =SUM(J47:J50) -> 0 | ... AC19: =SUM(M47:M50) -> 73 | AD19: =SUM(N46:N49) -> 0 | AE19: =SUM(O46:O49) -> 28 | AF19: =SUM(P46:P49) -> 92
B20: 09.30 - 09.45 | C20: 8 | D20: 0 | E20: 2 | F20: 0 | G20: 0 | H20: 0 | I20: 3 | J20: 0 | K20: 0 | L20: 0 | M20: 26 | N20: 0 | O20: =SUM(C20:L20,N20) -> 13 | P20: =SUM(C20:N20) -> 39 | R20: 1700-1800 | S20: =SUM(C51:C53) -> 11 | T20: =SUM(D51:D53) -> 1 | U20: =SUM(E51:E53) -> 4 | V20: =SUM(F51:F53) -> 5 | W20: =SUM(G51:G53) -> 3 | X20: =SUM(H51:H53) -> 0 | Y20: =SUM(I51:I53) -> 4 | Z20: =SUM(J51:J53) -> 2 | ... AC20: =SUM(M51:M53) -> 67 | AD20: =SUM(N50:N53) -> 0 | AE20: =SUM(O50:O53) -> 38 | AF20: =SUM(P50:P53) -> 126
B21: 09.45 - 10.00 | C21: 7 | D21: 1 | E21: 0 | F21: 1 | G21: 0 | H21: 0 | I21: 2 | J21: 0 | K21: 0 | L21: 0 | M21: 24 | N21: 0 | O21: =SUM(C21:L21,N21) -> 11 | P21: =SUM(C21:N21) -> 35 | R21: 1800-1900 | S21: =SUM(C54:C57) -> 14 | T21: =SUM(D54:D57) -> 3 | U21: =SUM(E54:E57) -> 1 | V21: =SUM(F54:F57) -> 6 | W21: =SUM(G54:G57) -> 1 | X21: =SUM(H54:H57) -> 0 | Y21: =SUM(I54:I57) -> 8 | Z21: =SUM(J54:J57) -> 2 | ... AF21: =SUM(P54:P57) -> 131
B22: 10.00 - 10.15 | C22: 4 | D22: 1 | E22: 0 | F22: 0 | G22: 0 | H22: 0 | I22: 2 | J22: 1 | K22: 0 | L22: 0 | M22: 24 | N22: 0 | O22: =SUM(C22:L22,N22) -> 8 | P22: =SUM(C22:N22) -> 32 | R22: AM Peak Hr | S22: =MAX(S10:S12) -> 22 | T22: =MAX(T10:T12) -> 5 | U22: =MAX(U10:U12) -> 3 | V22: =MAX(V10:V12) -> 2 | W22: =MAX(W10:W12) -> 0 | X22: =MAX(X10:X12) -> 0 | Y22: =MAX(Y10:Y12) -> 9 | Z22: =MAX(Z10:Z12) -> 0 | ... AF22: =MAX(AF10:AF12) -> 136
B23: 10.15 - 10.30 | C23: 3 | D23: 0 | E23: 0 | F23: 0 | G23: 0 | H23: 0 | I23: 2 | J23: 0 | K23: 0 | L23: 0 | M23: 18 | N23: 0 | O23: =SUM(C23:L23,N23) -> 5 | P23: =SUM(C23:N23) -> 23 | R23: IP Peak Hr | S23: =MAX(S13:S18) -> 19 | T23: =MAX(T13:T18) -> 4 | U23: =MAX(U13:U18) -> 7 | V23: =MAX(V13:V18) -> 5 | W23: =MAX(W13:W18) -> 0 | X23: =MAX(X13:X18) -> 0 | Y23: =MAX(Y13:Y18) -> 8 | Z23: =MAX(Z13:Z18) -> 2 | ... AF23: =MAX(AF13:AF18) -> 112
B24: 10.30 - 10.45 | C24: 7 | D24: 3 | E24: 0 | F24: 0 | G24: 0 | H24: 0 | I24: 1 | J24: 0 | K24: 1 | L24: 0 | M24: 30 | N24: 0 | O24: =SUM(C24:L24,N24) -> 12 | P24: =SUM(C24:N24) -> 42 | R24: PM Peak Hr | S24: =MAX(S19:S21) -> 17 | T24: =MAX(T19:T21) -> 3 | U24: =MAX(U19:U21) -> 4 | V24: =MAX(V19:V21) -> 6 | W24: =MAX(W19:W21) -> 3 | X24: =MAX(X19:X21) -> 0 | Y24: =MAX(Y19:Y21) -> 8 | Z24: =MAX(Z19:Z21) -> 2 | ... AF24: =MAX(AF19:AF21) -> 131
B25: 10.45 - 11.00 | C25: 4 | D25: 0 | E25: 0 | F25: 0 | G25: 0 | H25: 0 | I25: 1 | J25: 0 | K25: 0 | L25: 0 | M25: 10 | N25: 0 | O25: =SUM(C25:L25,N25) -> 5 | P25: =SUM(C25:N25) -> 15 | R25: AM Period | S25: =SUM(S10:S12) -> 56 | T25: =SUM(T10:T12) -> 9 | U25: =SUM(U10:U12) -> 7 | V25: =SUM(V10:V12) -> 5 | W25: =SUM(W10:W12) -> 0 | X25: =SUM(X10:X12) -> 0 | Y25: =SUM(Y10:Y12) -> 18 | Z25: =SUM(Z10:Z12) -> 0 | ... AF25: =SUM(AF10:AF12) -> 386
B26: 11.00 - 11.15 | C26: 3 | D26: 0 | E26: 0 | F26: 0 | G26: 0 | H26: 0 | I26: 1 | J26: 0 | K26: 0 | L26: 0 | M26: 21 | N26: 0 | O26: =SUM(C26:L26,N26) -> 4 | P26: =SUM(C26:N26) -> 25 | R26: IP Period | S26: =SUM(S13:S18) -> 81 | T26: =SUM(T13:T18) -> 14 | U26: =SUM(U13:U18) -> 21 | V26: =SUM(V13:V18) -> 11 | W26: =SUM(W13:W18) -> 0 | X26: =SUM(X13:X18) -> 0 | Y26: =SUM(Y13:Y18) -> 32 | Z26: =SUM(Z13:Z18) -> 5 | ... AF26: =SUM(AF13:AF18) -> 597
B27: 11.15 - 11.30 | C27: 2 | D27: 1 | E27: 1 | F27: 1 | G27: 0 | H27: 0 | I27: 0 | J27: 0 | K27: 0 | L27: 0 | M27: 19 | N27: 0 | O27: =SUM(C27:L27,N27) -> 5 | P27: =SUM(C27:N27) -> 24 | R27: PM Period | S27: =SUM(S19:S21) -> 42 | T27: =SUM(T19:T21) -> 5 | U27: =SUM(U19:U21) -> 7 | V27: =SUM(V19:V21) -> 13 | W27: =SUM(W19:W21) -> 5 | X27: =SUM(X19:X21) -> 0 | Y27: =SUM(Y19:Y21) -> 19 | Z27: =SUM(Z19:Z21) -> 4 | ... AF27: =SUM(AF19:AF21) -> 349
B28: 11.30 - 11.45 | C28: 3 | D28: 0 | E28: 2 | F28: 0 | G28: 0 | H28: 0 | I28: 3 | J28: 0 | K28: 0 | L28: 0 | M28: 13 | N28: 0 | O28: =SUM(C28:L28,N28) -> 8 | P28: =SUM(C28:N28) -> 21 | R28: 12 Hours | S28: =SUM(S10:S21) -> 179 | T28: =SUM(T10:T21) -> 28 | U28: =SUM(U10:U21) -> 35 | V28: =SUM(V10:V21) -> 29 | W28: =SUM(W10:W21) -> 5 | X28: =SUM(X10:X21) -> 0 | Y28: =SUM(Y10:Y21) -> 69 | Z28: =SUM(Z10:Z21) -> 9 | ... AF28: =SUM(AF10:AF21) -> 1332
B29: 11.45 - 12.00 | C29: 7 | D29: 0 | E29: 1 | F29: 2 | G29: 0 | H29: 0 | I29: 2 | J29: 0 | K29: 0 | L29: 0 | M29: 29 | N29: 0 | O29: =SUM(C29:L29,N29) -> 12 | P29: =SUM(C29:N29) -> 41
B30: 12.00 - 12.15 | C30: 2 | D30: 1 | E30: 0 | F30: 0 | G30: 0 | H30: 0 | I30: 1 | J30: 0 | K30: 0 | L30: 0 | M30: 16 | N30: 0 | O30: =SUM(C30:L30,N30) -> 4 | P30: =SUM(C30:N30) -> 20
B31: 12.15 - 12.30 | C31: 4 | D31: 1 | E31: 0 | F31: 0 | G31: 0 | H31: 0 | I31: 3 | J31: 0 | K31: 0 | L31: 0 | M31: 22 | N31: 0 | O31: =SUM(C31:L31,N31) -> 8 | P31: =SUM(C31:N31) -> 30
B32: 12.30 - 12.45 | C32: 4 | D32: 1 | E32: 2 | F32: 0 | G32: 0 | H32: 0 | I32: 2 | J32: 0 | K32: 0 | L32: 0 | M32: 15 | N32: 0 | O32: =SUM(C32:L32,N32) -> 9 | P32: =SUM(C32:N32) -> 24
B33: 12.45 - 13.00 | C33: 4 | D33: 0 | E33: 0 | F33: 1 | G33: 0 | H33: 0 | I33: 0 | J33: 0 | K33: 0 | L33: 0 | M33: 22 | N33: 0 | O33: =SUM(C33:L33,N33) -> 5 | P33: =SUM(C33:N33) -> 27
B34: 13.00 - 13.15 | C34: 4 | D34: 0 | E34: 1 | F34: 2 | G34: 0 | H34: 0 | I34: 2 | J34: 0 | K34: 0 | L34: 0 | M34: 23 | N34: 0 | O34: =SUM(C34:L34,N34) -> 9 | P34: =SUM(C34:N34) -> 32
B35: 13.15 - 13.30 | C35: 2 | D35: 0 | E35: 1 | F35: 2 | G35: 0 | H35: 0 | I35: 1 | J35: 1 | K35: 0 | L35: 0 | M35: 19 | N35: 0 | O35: =SUM(C35:L35,N35) -> 7 | P35: =SUM(C35:N35) -> 26
B36: 13.30 - 13.45 | C36: 6 | D36: 0 | E36: 1 | F36: 0 | G36: 0 | H36: 0 | I36: 0 | J36: 0 | K36: 0 | L36: 0 | M36: 18 | N36: 0 | O36: =SUM(C36:L36,N36) -> 7 | P36: =SUM(C36:N36) -> 25
B37: 13.45 - 14.00 | C37: 3 | D37: 0 | E37: 1 | F37: 1 | G37: 0 | H37: 0 | I37: 3 | J37: 1 | K37: 0 | L37: 0 | M37: 17 | N37: 0 | O37: =SUM(C37:L37,N37) -> 9 | P37: =SUM(C37:N37) -> 26
B38: 14.00 - 14.15 | C38: 4 | D38: 1 | E38: 1 | F38: 0 | G38: 0 | H38: 0 | I38: 2 | J38: 0 | K38: 0 | L38: 0 | M38: 14 | N38: 0 | O38: =SUM(C38:L38,N38) -> 8 | P38: =SUM(C38:N38) -> 22
B39: 14.15 - 14.30 | C39: 1 | D39: 0 | E39: 1 | F39: 1 | G39: 0 | H39: 0 | I39: 2 | J39: 0 | K39: 0 | L39: 0 | M39: 16 | N39: 0 | O39: =SUM(C39:L39,N39) -> 5 | P39: =SUM(C39:N39) -> 21
B40: 14.30 - 14.45 | C40: 1 | D40: 0 | E40: 1 | F40: 0 | G40: 0 | H40: 0 | I40: 0 | J40: 0 | K40: 0 | L40: 0 | M40: 13 | N40: 0 | O40: =SUM(C40:L40,N40) -> 2 | P40: =SUM(C40:N40) -> 15
... B57: 18.45 - 19.00 | C57: 1 | D57: 1 | E57: 0 | F57: 1 | G57: 0 | H57: 0 | I57: 3 | J57: 1 | K57: 0 | L57: 0 | M57: 22 | N57: 0 | O57: =SUM(C57:L57,N57) -> 7 | P57: =SUM(C57:N57) -> 29
B58: Totals | C58: =SUM(C10:C57) -> 179 | D58: =SUM(D10:D57) -> 28 | E58: =SUM(E10:E57) -> 35 | F58: =SUM(F10:F57) -> 29 | G58: =SUM(G10:G57) -> 5 | H58: =SUM(H10:H57) -> 0 | I58: =SUM(I10:I57) -> 69 | J58: =SUM(J10:J57) -> 9 | ... N58: =SUM(N10:N57) -> 0 | O58: =SUM(C58:L58,N58) -> 357 | P58: =SUM(P10:P57) -> 1332
...

Sheet 24.09 Nsangi-Buloba
B1: Consultancy services for Preparation of Expressway Development Master Plan (EDMP) for Uganda
B2: MANUAL CLASSIFIED COUNT (MCC)
B3: ROAD NAME: | C3: MCC-C2-STN61-NSANGI-BULOBA
C5: Date | D5: 24.09.19 | F5: Location | G5: HANA INT. SCHOOL | J5: Surveyor | K5: MIREMBE RUTH
C6: Dir. From | D6: NSANGI | F6: Dir. To | G6: BULOBA | J6: Supervisor | K6: DENIS
B8: Time / Veh Type | R8: SUMMARY TRAFFIC VOLUMES
C9: 1. Car | D9: 2. Station Wagon | E9: 3. Pickups | F9: 4. Minibus, matatu | G9: 5. Medium bus | H9: 6. Large Bus | I9: 7. Light Truck | J9: 8. Medium Truck | K9: 9. Heavy truck | L9: 10. Truck Trailer | M9: 11. Motor cycles | N9: 12. Tractors | O9: Total Excl M/Cycles | P9: Total All | R9: Time | S9: 1. Car | T9: 2. Station Wagon | U9: 3. Pickups | V9: 4. Minibus, matatu | W9: 5. Medium bus | X9: 6. Large Bus | Y9: 7. Light Truck | Z9: 8. Medium Truck | AA9: 9. Heavy truck | AB9: 10. Truck Trailer | AC9: 11. Motorcycles | AD9: 12. Tractors, Graders | AE9: Total Excl M/ Cycles | AF9: Total All
B10: 07.00 - 07.15 | C10: 4 | D10: 0 | E10: 0 | F10: 0 | G10: 1 | H10: 0 | I10: 0 | J10: 0 | K10: 0 | L10: 0 | M10: 16 | N10: 0 | O10: =SUM(C10:L10,N10) -> 5 | P10: =SUM(C10:N10) -> 21 | R10: 0700-0800 | S10: =SUM(C10:C13) -> 19 | T10: =SUM(D10:D13) -> 1 | U10: =SUM(E10:E13) -> 0 | V10: =SUM(F10:F13) -> 3 | W10: =SUM(G10:G13) -> 2 | X10: =SUM(H10:H13) -> 0 | Y10: =SUM(I10:I13) -> 2 | Z10: =SUM(J10:J13) -> 1 | ... AF10: =SUM(P10:P13) -> 117
B11: 07.15 - 07.30 | C11: 8 | D11: 0 | E11: 0 | F11: 1 | G11: 1 | H11: 0 | I11: 2 | J11: 0 | K11: 0 | L11: 0 | M11: 31 | N11: 0 | O11: =SUM(C11:L11,N11) -> 12 | P11: =SUM(C11:N11) -> 43 | R11: 0800-0900 | S11: =SUM(C14:C17) -> 15 | T11: =SUM(D14:D17) -> 3 | U11: =SUM(E14:E17) -> 1 | V11: =SUM(F14:F17) -> 1 | W11: =SUM(G14:G17) -> 0 | X11: =SUM(H14:H17) -> 0 | Y11: =SUM(I14:I17) -> 4 | Z11: =SUM(J14:J17) -> 0 | ... AF11: =SUM(P14:P17) -> 110
B12: 07.30 - 07.45 | C12: 4 | D12: 0 | E12: 0 | F12: 0 | G12: 0 | H12: 0 | I12: 0 | J12: 1 | K12: 1 | L12: 0 | M12: 24 | N12: 0 | O12: =SUM(C12:L12,N12) -> 6 | P12: =SUM(C12:N12) -> 30 | R12: 0900-1000 | S12: =SUM(C18:C21) -> 15 | T12: =SUM(D18:D21) -> 0 | U12: =SUM(E18:E21) -> 1 | V12: =SUM(F18:F21) -> 0 | W12: =SUM(G18:G21) -> 0 | X12: =SUM(H18:H21) -> 0 | Y12: =SUM(I18:I21) -> 14 | Z12: =SUM(J18:J21) -> 0 | ... AF12: =SUM(P18:P21) -> 136
B13: 07.45 - 08.00 | C13: 3 | D13: 1 | E13: 0 | F13: 2 | G13: 0 | H13: 0 | I13: 0 | J13: 0 | K13: 1 | L13: 0 | M13: 16 | N13: 0 | O13: =SUM(C13:L13,N13) -> 7 | P13: =SUM(C13:N13) -> 23 | R13: 1000-1100 | S13: =SUM(C22:C25) -> 12 | T13: =SUM(D22:D25) -> 1 | U13: =SUM(E22:E25) -> 1 | V13: =SUM(F22:F25) -> 0 | W13: =SUM(G22:G25) -> 0 | X13: =SUM(H22:H25) -> 0 | Y13: =SUM(I22:I25) -> 6 | Z13: =SUM(J22:J25) -> 1 | ... AF13: =SUM(P22:P25) -> 96
B14: 08.00 - 08.15 | C14: 5 | D14: 1 | E14: 0 | F14: 1 | G14: 0 | H14: 0 | I14: 1 | J14: 0 | K14: 0 | L14: 0 | M14: 22 | N14: 0 | O14: =SUM(C14:L14,N14) -> 8 | P14: =SUM(C14:N14) -> 30 | R14: 1100-1200 | S14: =SUM(C26:C29) -> 15 | T14: =SUM(D26:D29) -> 2 | U14: =SUM(E26:E29) -> 4 | V14: =SUM(F26:F29) -> 1 | W14: =SUM(G26:G29) -> 0 | X14: =SUM(H26:H29) -> 0 | Y14: =SUM(I26:I29) -> 9 | Z14: =SUM(J26:J29) -> 1 | ... AF14: =SUM(P26:P29) -> 110
B15: 08.15 - 08.30 | C15: 3 | D15: 0 | E15: 0 | F15: 0 | G15: 0 | H15: 0 | I15: 1 | J15: 0 | K15: 0 | L15: 0 | M15: 28 | N15: 0 | O15: =SUM(C15:L15,N15) -> 4 | P15: =SUM(C15:N15) -> 32 | R15: 1200-1300 | S15: =SUM(C30:C33) -> 10 | T15: =SUM(D30:D33) -> 1 | U15: =SUM(E30:E33) -> 2 | V15: =SUM(F30:F33) -> 1 | W15: =SUM(G30:G33) -> 0 | X15: =SUM(H30:H33) -> 0 | Y15: =SUM(I30:I33) -> 3 | Z15: =SUM(J30:J33) -> 1 | ... AF15: =SUM(P30:P33) -> 89
B16: 08.30 - 08.45 | C16: 3 | D16: 1 | E16: 0 | F16: 0 | G16: 0 | H16: 0 | I16: 1 | J16: 0 | K16: 0 | L16: 0 | M16: 13 | N16: 0 | O16: =SUM(C16:L16,N16) -> 5 | P16: =SUM(C16:N16) -> 18 | R16: 1300-1400 | S16: =SUM(C34:C37) -> 12 | T16: =SUM(D34:D37) -> 2 | U16: =SUM(E34:E37) -> 5 | V16: =SUM(F34:F37) -> 4 | W16: =SUM(G34:G37) -> 0 | X16: =SUM(H34:H37) -> 0 | Y16: =SUM(I34:I37) -> 2 | Z16: =SUM(J34:J37) -> 1 | ... AF16: =SUM(P34:P37) -> 89
B17: 08.45 - 9.00 | C17: 4 | D17: 1 | E17: 1 | F17: 0 | G17: 0 | H17: 0 | I17: 1 | J17: 0 | K17: 0 | L17: 1 | M17: 22 | N17: 0 | O17: =SUM(C17:L17,N17) -> 8 | P17: =SUM(C17:N17) -> 30 | R17: 1400-1500 | S17: =SUM(C38:C41) -> 6 | T17: =SUM(D38:D41) -> 1 | U17: =SUM(E38:E41) -> 4 | V17: =SUM(F38:F41) -> 2 | W17: =SUM(G38:G41) -> 0 | X17: =SUM(H38:H41) -> 0 | Y17: =SUM(I38:I41) -> 6 | Z17: =SUM(J38:J41) -> 2 | ... AF17: =SUM(P38:P41) -> 82
B18: 09.00 - 09.15 | C18: 4 | D18: 0 | E18: 0 | F18: 0 | G18: 0 | H18: 0 | I18: 2 | J18: 0 | K18: 0 | L18: 0 | M18: 24 | N18: 0 | O18: =SUM(C18:L18,N18) -> 6 | P18: =SUM(C18:N18) -> 30 | R18: 1500-1600 | S18: =SUM(C42:C45) -> 10 | T18: =SUM(D42:D45) -> 0 | U18: =SUM(E42:E45) -> 3 | V18: =SUM(F42:F45) -> 1 | W18: =SUM(G42:G45) -> 0 | X18: =SUM(H42:H45) -> 0 | Y18: =SUM(I42:I45) -> 5 | Z18: =SUM(J42:J45) -> 1 | ... AF18: =SUM(P42:P45) -> 56
B19: 09.15 - 09.30 | C19: 2 | D19: 0 | E19: 0 | F19: 0 | G19: 0 | H19: 0 | I19: 3 | J19: 0 | K19: 0 | L19: 0 | M19: 27 | N19: 0 | O19: =SUM(C19:L19,N19) -> 5 | P19: =SUM(C19:N19) -> 32 | R19: 1600-1700 | S19: =SUM(C46:C49) -> 18 | T19: =SUM(D46:D49) -> 2 | U19: =SUM(E46:E49) -> 1 | V19: =SUM(F46:F49) -> 4 | W19: =SUM(G46:G49) -> 0 | X19: =SUM(H46:H49) -> 0 | Y19: =SUM(I46:I49) -> 6 | Z19: =SUM(J46:J49) -> 1 | ... AF19: =SUM(P46:P49) -> 96
B20: 09.30 - 09.45 | C20: 5 | D20: 0 | E20: 1 | F20: 0 | G20: 0 | H20: 0 | I20: 4 | J20: 0 | K20: 0 | L20: 0 | M20: 24 | N20: 0 | O20: =SUM(C20:L20,N20) -> 10 | P20: =SUM(C20:N20) -> 34 | R20: 1700-1800 | S20: =SUM(C50:C53) -> 17 | T20: =SUM(D50:D53) -> 2 | U20: =SUM(E50:E53) -> 4 | V20: =SUM(F50:F53) -> 1 | W20: =SUM(G50:G53) -> 5 | X20: =SUM(H50:H53) -> 0 | Y20: =SUM(I50:I53) -> 3 | Z20: =SUM(J50:J53) -> 1 | ... AF20: =SUM(P50:P53) -> 115
B21: 09.45 - 10.00 | C21: 4 | D21: 0 | E21: 0 | F21: 0 | G21: 0 | H21: 0 | I21: 5 | J21: 0 | K21: 0 | L21: 0 | M21: 31 | N21: 0 | O21: =SUM(C21:L21,N21) -> 9 | P21: =SUM(C21:N21) -> 40 | R21: 1800-1900 | S21: =SUM(C54:C57) -> 26 | T21: =SUM(D54:D57) -> 3 | U21: =SUM(E54:E57) -> 5 | V21: =SUM(F54:F57) -> 6 | W21: =SUM(G54:G57) -> 0 | X21: =SUM(H54:H57) -> 0 | Y21: =SUM(I54:I57) -> 7 | Z21: =SUM(J54:J57) -> 0 | ... AF21: =SUM(P54:P57) -> 146
B22: 10.00 - 10.15 | C22: 3 | D22: 0 | E22: 1 | F22: 0 | G22: 0 | H22: 0 | I22: 0 | J22: 0 | K22: 0 | L22: 0 | M22: 19 | N22: 0 | O22: =SUM(C22:L22,N22) -> 4 | P22: =SUM(C22:N22) -> 23 | R22: AM Peak Hr | S22: =MAX(S10:S12) -> 19 | T22: =MAX(T10:T12) -> 3 | U22: =MAX(U10:U12) -> 1 | V22: =MAX(V10:V12) -> 3 | W22: =MAX(W10:W12) -> 2 | X22: =MAX(X10:X12) -> 0 | Y22: =MAX(Y10:Y12) -> 14 | Z22: =MAX(Z10:Z12) -> 1 | ... AF22: =MAX(AF10:AF12) -> 136
B23: 10.15 - 10.30 | C23: 5 | D23: 0 | E23: 0 | F23: 0 | G23: 0 | H23: 0 | I23: 1 | J23: 1 | K23: 0 | L23: 0 | M23: 19 | N23: 0 | O23: =SUM(C23:L23,N23) -> 7 | P23: =SUM(C23:N23) -> 26 | R23: IP Peak Hr | S23: =MAX(S13:S18) -> 15 | T23: =MAX(T13:T18) -> 2 | U23: =MAX(U13:U18) -> 5 | V23: =MAX(V13:V18) -> 4 | W23: =MAX(W13:W18) -> 0 | X23: =MAX(X13:X18) -> 0 | Y23: =MAX(Y13:Y18) -> 9 | Z23: =MAX(Z13:Z18) -> 2 | ... AF23: =MAX(AF13:AF18) -> 110
B24: 10.30 - 10.45 | C24: 3 | D24: 1 | E24: 0 | F24: 0 | G24: 0 | H24: 0 | I24: 2 | J24: 0 | K24: 0 | L24: 0 | M24: 25 | N24: 0 | O24: =SUM(C24:L24,N24) -> 6 | P24: =SUM(C24:N24) -> 31 | R24: PM Peak Hr | S24: =MAX(S19:S21) -> 26 | T24: =MAX(T19:T21) -> 3 | U24: =MAX(U19:U21) -> 5 | V24: =MAX(V19:V21) -> 6 | W24: =MAX(W19:W21) -> 5 | X24: =MAX(X19:X21) -> 0 | Y24: =MAX(Y19:Y21) -> 7 | Z24: =MAX(Z19:Z21) -> 1 | ... AF24: =MAX(AF19:AF21) -> 146
B25: 10.45 - 11.00 | C25: 1 | D25: 0 | E25: 0 | F25: 0 | G25: 0 | H25: 0 | I25: 3 | J25: 0 | K25: 0 | L25: 0 | M25: 12 | N25: 0 | O25: =SUM(C25:L25,N25) -> 4 | P25: =SUM(C25:N25) -> 16 | R25: AM Period | S25: =SUM(S10:S12) -> 49 | T25: =SUM(T10:T12) -> 4 | U25: =SUM(U10:U12) -> 2 | V25: =SUM(V10:V12) -> 4 | W25: =SUM(W10:W12) -> 2 | X25: =SUM(X10:X12) -> 0 | Y25: =SUM(Y10:Y12) -> 20 | Z25: =SUM(Z10:Z12) -> 1 | ... AF25: =SUM(AF10:AF12) -> 363
B26: 11.00 - 11.15 | C26: 4 | D26: 0 | E26: 1 | F26: 0 | G26: 0 | H26: 0 | I26: 3 | J26: 0 | K26: 0 | L26: 0 | M26: 18 | N26: 0 | O26: =SUM(C26:L26,N26) -> 8 | P26: =SUM(C26:N26) -> 26 | R26: IP Period | S26: =SUM(S13:S18) -> 65 | T26: =SUM(T13:T18) -> 7 | U26: =SUM(U13:U18) -> 19 | V26: =SUM(V13:V18) -> 9 | W26: =SUM(W13:W18) -> 0 | X26: =SUM(X13:X18) -> 0 | Y26: =SUM(Y13:Y18) -> 31 | Z26: =SUM(Z13:Z18) -> 7 | ... AF26: =SUM(AF13:AF18) -> 522
B27: 11.15 - 11.30 | C27: 2 | D27: 0 | E27: 0 | F27: 0 | G27: 0 | H27: 0 | I27: 3 | J27: 0 | K27: 0 | L27: 0 | M27: 20 | N27: 0 | O27: =SUM(C27:L27,N27) -> 5 | P27: =SUM(C27:N27) -> 25 | R27: PM Period | S27: =SUM(S19:S21) -> 61 | T27: =SUM(T19:T21) -> 7 | U27: =SUM(U19:U21) -> 10 | V27: =SUM(V19:V21) -> 11 | W27: =SUM(W19:W21) -> 5 | X27: =SUM(X19:X21) -> 0 | Y27: =SUM(Y19:Y21) -> 16 | Z27: =SUM(Z19:Z21) -> 2 | ... AF27: =SUM(AF19:AF21) -> 357
B28: 11.30 - 11.45 | C28: 6 | D28: 1 | E28: 1 | F28: 0 | G28: 0 | H28: 0 | I28: 1 | J28: 1 | K28: 1 | L28: 0 | M28: 28 | N28: 0 | O28: =SUM(C28:L28,N28) -> 11 | P28: =SUM(C28:N28) -> 39 | R28: 12 Hours | S28: =SUM(S10:S21) -> 175 | T28: =SUM(T10:T21) -> 18 | U28: =SUM(U10:U21) -> 31 | V28: =SUM(V10:V21) -> 24 | W28: =SUM(W10:W21) -> 7 | X28: =SUM(X10:X21) -> 0 | Y28: =SUM(Y10:Y21) -> 67 | Z28: =SUM(Z10:Z21) -> 10 | ... AF28: =SUM(AF10:AF21) -> 1242
B29: 11.45 - 12.00 | C29: 3 | D29: 1 | E29: 2 | F29: 1 | G29: 0 | H29: 0 | I29: 2 | J29: 0 | K29: 0 | L29: 0 | M29: 11 | N29: 0 | O29: =SUM(C29:L29,N29) -> 9 | P29: =SUM(C29:N29) -> 20
B30: 12.00 - 12.15 | C30: 2 | D30: 0 | E30: 0 | F30: 0 | G30: 0 | H30: 0 | I30: 1 | J30: 0 | K30: 0 | L30: 0 | M30: 17 | N30: 0 | O30: =SUM(C30:L30,N30) -> 3 | P30: =SUM(C30:N30) -> 20
B31: 12.15 - 12.30 | C31: 5 | D31: 0 | E31: 0 | F31: 1 | G31: 0 | H31: 0 | I31: 1 | J31: 0 | K31: 0 | L31: 0 | M31: 19 | N31: 0 | O31: =SUM(C31:L31,N31) -> 7 | P31: =SUM(C31:N31) -> 26
B32: 12.30 - 12.45 | C32: 1 | D32: 0 | E32: 2 | F32: 0 | G32: 0 | H32: 0 | I32: 0 | J32: 1 | K32: 1 | L32: 0 | M32: 11 | N32: 0 | O32: =SUM(C32:L32,N32) -> 5 | P32: =SUM(C32:N32) -> 16
B33: 12.45 - 13.00 | C33: 2 | D33: 1 | E33: 0 | F33: 0 | G33: 0 | H33: 0 | I33: 1 | J33: 0 | K33: 0 | L33: 0 | M33: 23 | N33: 0 | O33: =SUM(C33:L33,N33) -> 4 | P33: =SUM(C33:N33) -> 27
B34: 13.00 - 13.15 | C34: 4 | D34: 0 | E34: 0 | F34: 1 | G34: 0 | H34: 0 | I34: 0 | J34: 1 | K34: 0 | L34: 0 | M34: 14 | N34: 0 | O34: =SUM(C34:L34,N34) -> 6 | P34: =SUM(C34:N34) -> 20
B35: 13.15 - 13.30 | C35: 3 | D35: 1 | E35: 2 | F35: 2 | G35: 0 | H35: 0 | I35: 0 | J35: 0 | K35: 0 | L35: 0 | M35: 17 | N35: 0 | O35: =SUM(C35:L35,N35) -> 8 | P35: =SUM(C35:N35) -> 25
B36: 13.30 - 13.45 | C36: 3 | D36: 0 | E36: 2 | F36: 0 | G36: 0 | H36: 0 | I36: 2 | J36: 0 | K36: 0 | L36: 0 | M36: 21 | N36: 0 | O36: =SUM(C36:L36,N36) -> 7 | P36: =SUM(C36:N36) -> 28
B37: 13.45 - 14.00 | C37: 2 | D37: 1 | E37: 1 | F37: 1 | G37: 0 | H37: 0 | I37: 0 | J37: 0 | K37: 0 | L37: 0 | M37: 11 | N37: 0 | O37: =SUM(C37:L37,N37) -> 5 | P37: =SUM(C37:N37) -> 16
B38: 14.00 - 14.15 | C38: 1 | D38: 0 | E38: 1 | F38: 1 | G38: 0 | H38: 0 | I38: 1 | J38: 2 | K38: 0 | L38: 0 | M38: 18 | N38: 0 | O38: =SUM(C38:L38,N38) -> 6 | P38: =SUM(C38:N38) -> 24
B39: 14.15 - 14.30 | C39: 3 | D39: 0 | E39: 0 | F39: 0 | G39: 0 | H39: 0 | I39: 2 | J39: 0 | K39: 0 | L39: 0 | M39: 17 | N39: 0 | O39: =SUM(C39:L39,N39) -> 5 | P39: =SUM(C39:N39) -> 22
B40: 14.30 - 14.45 | C40: 0 | D40: 0 | E40: 2 | F40: 1 | G40: 0 | H40: 0 | I40: 1 | J40: 0 | K40: 0 | L40: 0 | M40: 15 | N40: 0 | O40: =SUM(C40:L40,N40) -> 4 | P40: =SUM(C40:N40) -> 19
... B57: 18.45 - 19.00 | C57: 9 | D57: 0 | E57: 2 | F57: 0 | G57: 0 | H57: 0 | I57: 1 | J57: 0 | K57: 0 | L57: 0 | M57: 25 | N57: 0 | O57: =SUM(C57:L57,N57) -> 12 | P57: =SUM(C57:N57) -> 37
B58: Totals | C58: =SUM(C10:C57) -> 175 | D58: =SUM(D10:D57) -> 18 | E58: =SUM(E10:E57) -> 31 | F58: =SUM(F10:F57) -> 24 | G58: =SUM(G10:G57) -> 7 | H58: =SUM(H10:H57) -> 0 | I58: =SUM(I10:I57) -> 67 | J58: =SUM(J10:J57) -> 10 | ... P58: =SUM(P10:P57) -> 1242
...

Sheet 25.09 Buloba-Nsangi
B1: Consultancy services for Preparation of Expressway Development Master Plan (EDMP) for Uganda
B2: MANUAL CLASSIFIED COUNT (MCC)
B3: ROAD NAME: | C3: ='23.09-BULOBA- NSANGI'!C3:G3 -> MCC - C2 - STN-61-NSANGI-BULOBA ROAD
C5: Date | D5: 25.09.19 | F5: Location | G5: ='23.09-BULOBA- NSANGI'!G5:H5 -> HANA international school | J5: Surveyor | K5: ='23.09-BULOBA- NSANGI'!K5:L5 -> nakawala justine
C6: Dir. From | D6: ='23.09-BULOBA- NSANGI'!D6:E6 -> BULOBA | F6: Dir. To | G6: ='23.09-BULOBA- NSANGI'!G6:H6 -> NSANGI | J6: Supervisor | K6: Denis
B8: Time / Veh Type | R8: SUMMARY TRAFFIC VOLUMES
C9: 1. Car | D9: 2. Station Wagon | E9: 3. Pickups | F9: 4. Minibus, matatu | G9: 5. Medium bus | H9: 6. Large Bus | I9: 7. Light Truck | J9: 8. Medium Truck | K9: 9. Heavy truck | L9: 10. Truck Trailer | M9: 11. Motor cycles | N9: 12. Tractors | O9: Total Excl M/Cycles | P9: Total All | R9: Time | S9: 1. Car | T9: 2. Station Wagon | U9: 3. Pickups | V9: 4. Minibus, matatu | W9: 5. Medium bus | X9: 6. Large Bus | Y9: 7. Light Truck | Z9: 8. Medium Truck | AA9: 9. Heavy truck | AB9: 10. Truck Trailer | AC9: 11. Motorcycles | AD9: 12. Tractors, Graders | AE9: Total Excl M/ Cycles | AF9: Total All
B10: 07.00 - 07.15 | C10: 3 | D10: 2 | E10: 1 | F10: 0 | G10: 0 | H10: 0 | I10: 1 | J10: 0 | K10: 0 | L10: 0 | M10: 27 | N10: 0 | O10: =SUM(C10:L10,N10) -> 7 | P10: =SUM(C10:N10) -> 34 | R10: 0700-0800 | S10: =SUM(C10:C13) -> 17 | T10: =SUM(D10:D13) -> 8 | U10: =SUM(E10:E13) -> 3 | V10: =SUM(F10:F13) -> 3 | W10: =SUM(G10:G13) -> 0 | X10: =SUM(H10:H13) -> 0 | Y10: =SUM(I10:I13) -> 3 | Z10: =SUM(J10:J13) -> 0 | ... AF10: =SUM(P10:P13) -> 159
B11: 07.15 - 07.30 | C11: 2 | D11: 2 | E11: 1 | F11: 0 | G11: 0 | H11: 0 | I11: 1 | J11: 0 | K11: 0 | L11: 0 | M11: 38 | N11: 0 | O11: =SUM(C11:L11,N11) -> 6 | P11: =SUM(C11:N11) -> 44 | R11: 0800-0900 | S11: =SUM(C14:C17) -> 14 | T11: =SUM(D14:D17) -> 4 | U11: =SUM(E14:E17) -> 4 | V11: =SUM(F14:F17) -> 0 | W11: =SUM(G14:G17) -> 0 | X11: =SUM(H14:H17) -> 0 | Y11: =SUM(I14:I17) -> 4 | Z11: =SUM(J14:J17) -> 2 | ... AF11: =SUM(P14:P17) -> 126
B12: 07.30 - 07.45 | C12: 5 | D12: 3 | E12: 0 | F12: 1 | G12: 0 | H12: 0 | I12: 0 | J12: 0 | K12: 0 | L12: 0 | M12: 29 | N12: 0 | O12: =SUM(C12:L12,N12) -> 9 | P12: =SUM(C12:N12) -> 38 | R12: 0900-1000 | S12: =SUM(C18:C21) -> 16 | T12: =SUM(D18:D21) -> 4 | U12: =SUM(E18:E21) -> 2 | V12: =SUM(F18:F21) -> 3 | W12: =SUM(G18:G21) -> 0 | X12: =SUM(H18:H21) -> 0 | Y12: =SUM(I18:I21) -> 1 | Z12: =SUM(J18:J21) -> 1 | ... AF12: =SUM(P18:P21) -> 131
B13: 07.45 - 08.00 | C13: 7 | D13: 1 | E13: 1 | F13: 2 | G13: 0 | H13: 0 | I13: 1 | J13: 0 | K13: 0 | L13: 0 | M13: 31 | N13: 0 | O13: =SUM(C13:L13,N13) -> 12 | P13: =SUM(C13:N13) -> 43 | R13: 1000-1100 | S13: =SUM(C22:C25) -> 14 | T13: =SUM(D22:D25) -> 3 | U13: =SUM(E22:E25) -> 0 | V13: =SUM(F22:F25) -> 1 | W13: =SUM(G22:G25) -> 0 | X13: =SUM(H22:H25) -> 0 | Y13: =SUM(I22:I25) -> 2 | Z13: =SUM(J22:J25) -> 0 | ... AF13: =SUM(P22:P25) -> 116
B14: 08.00 - 08.15 | C14: 8 | D14: 1 | E14: 2 | F14: 0 | G14: 0 | H14: 0 | I14: 1 | J14: 0 | K14: 0 | L14: 0 | M14: 33 | N14: 0 | O14: =SUM(C14:L14,N14) -> 12 | P14: =SUM(C14:N14) -> 45 | R14: 1100-1200 | S14: =SUM(C26:C29) -> 12 | T14: =SUM(D26:D29) -> 3 | U14: =SUM(E26:E29) -> 2 | V14: =SUM(F26:F29) -> 3 | W14: =SUM(G26:G29) -> 0 | X14: =SUM(H26:H29) -> 0 | Y14: =SUM(I26:I29) -> 6 | Z14: =SUM(J26:J29) -> 3 | ... AF14: =SUM(P26:P29) -> 99
B15: 08.15 - 08.30 | C15: 1 | D15: 0 | E15: 0 | F15: 0 | G15: 0 | H15: 0 | I15: 0 | J15: 0 | K15: 1 | L15: 0 | M15: 20 | N15: 0 | O15: =SUM(C15:L15,N15) -> 2 | P15: =SUM(C15:N15) -> 22 | R15: 1200-1300 | S15: =SUM(C30:C33) -> 9 | T15: =SUM(D30:D33) -> 4 | U15: =SUM(E30:E33) -> 1 | V15: =SUM(F30:F33) -> 0 | W15: =SUM(G30:G33) -> 0 | X15: =SUM(H30:H33) -> 0 | Y15: =SUM(I30:I33) -> 6 | Z15: =SUM(J30:J33) -> 4 | ... AF15: =SUM(P30:P33) -> 86
B16: 08.30 - 08.45 | C16: 3 | D16: 1 | E16: 0 | F16: 0 | G16: 0 | H16: 0 | I16: 2 | J16: 0 | K16: 1 | L16: 0 | M16: 28 | N16: 0 | O16: =SUM(C16:L16,N16) -> 7 | P16: =SUM(C16:N16) -> 35 | R16: 1300-1400 | S16: =SUM(C34:C37) -> 20 | T16: =SUM(D34:D37) -> 3 | U16: =SUM(E34:E37) -> 3 | V16: =SUM(F34:F37) -> 5 | W16: =SUM(G34:G37) -> 1 | X16: =SUM(H34:H37) -> 0 | Y16: =SUM(I34:I37) -> 7 | Z16: =SUM(J34:J37) -> 0 | ... AF16: =SUM(P34:P37) -> 96
B17: 08.45 - 9.00 | C17: 2 | D17: 2 | E17: 2 | F17: 0 | G17: 0 | H17: 0 | I17: 1 | J17: 2 | K17: 0 | L17: 0 | M17: 15 | N17: 0 | O17: =SUM(C17:L17,N17) -> 9 | P17: =SUM(C17:N17) -> 24 | R17: 1400-1500 | S17: =SUM(C38:C41) -> 16 | T17: =SUM(D38:D41) -> 1 | U17: =SUM(E38:E41) -> 2 | V17: =SUM(F38:F41) -> 3 | W17: =SUM(G38:G41) -> 0 | X17: =SUM(H38:H41) -> 0 | Y17: =SUM(I38:I41) -> 8 | Z17: =SUM(J38:J41) -> 0 | ... AF17: =SUM(P38:P41) -> 89
B18: 09.00 - 09.15 | C18: 6 | D18: 3 | E18: 0 | F18: 1 | G18: 0 | H18: 0 | I18: 0 | J18: 0 | K18: 0 | L18: 0 | M18: 27 | N18: 0 | O18: =SUM(C18:L18,N18) -> 10 | P18: =SUM(C18:N18) -> 37 | R18: 1500-1600 | S18: =SUM(C42:C45) -> 11 | T18: =SUM(D42:D45) -> 3 | U18: =SUM(E42:E45) -> 2 | V18: =SUM(F42:F45) -> 2 | W18: =SUM(G42:G45) -> 0 | X18: =SUM(H42:H45) -> 0 | Y18: =SUM(I42:I45) -> 5 | Z18: =SUM(J42:J45) -> 0 | ... AF18: =SUM(P42:P45) -> 78
B19: 09.15 - 09.30 | C19: 5 | D19: 0 | E19: 0 | F19: 0 | G19: 0 | H19: 0 | I19: 0 | J19: 0 | K19: 0 | L19: 0 | M19: 24 | N19: 0 | O19: =SUM(C19:L19,N19) -> 5 | P19: =SUM(C19:N19) -> 29 | R19: 1600-1700 | S19: =SUM(C46:C49) -> 13 | T19: =SUM(D46:D49) -> 2 | U19: =SUM(E46:E49) -> 3 | V19: =SUM(F46:F49) -> 2 | W19: =SUM(G46:G49) -> 0 | X19: =SUM(H46:H49) -> 0 | Y19: =SUM(I46:I49) -> 8 | Z19: =SUM(J46:J49) -> 0 | ... AF19: =SUM(P46:P49) -> 101
B20: 09.30 - 09.45 | C20: 2 | D20: 0 | E20: 1 | F20: 1 | G20: 0 | H20: 0 | I20: 0 | J20: 0 | K20: 0 | L20: 0 | M20: 26 | N20: 0 | O20: =SUM(C20:L20,N20) -> 4 | P20: =SUM(C20:N20) -> 30 | R20: 1700-1800 | S20: =SUM(C50:C53) -> 18 | T20: =SUM(D50:D53) -> 4 | U20: =SUM(E50:E53) -> 1 | V20: =SUM(F50:F53) -> 6 | W20: =SUM(G50:G53) -> 5 | X20: =SUM(H50:H53) -> 0 | Y20: =SUM(I50:I53) -> 9 | Z20: =SUM(J50:J53) -> 0 | ... AF20: =SUM(P50:P53) -> 134
B21: 09.45 - 10.00 | C21: 3 | D21: 1 | E21: 1 | F21: 1 | G21: 0 | H21: 0 | I21: 1 | J21: 1 | K21: 0 | L21: 0 | M21: 27 | N21: 0 | O21: =SUM(C21:L21,N21) -> 8 | P21: =SUM(C21:N21) -> 35 | R21: 1800-1900 | S21: =SUM(C54:C57) -> 13 | T21: =SUM(D54:D57) -> 6 | U21: =SUM(E54:E57) -> 4 | V21: =SUM(F54:F57) -> 4 | W21: =SUM(G54:G57) -> 2 | X21: =SUM(H54:H57) -> 0 | Y21: =SUM(I54:I57) -> 10 | Z21: =SUM(J54:J57) -> 0 | ... AF21: =SUM(P54:P57) -> 126
B22: 10.00 - 10.15 | C22: 1 | D22: 1 | E22: 0 | F22: 0 | G22: 0 | H22: 0 | I22: 1 | J22: 0 | K22: 0 | L22: 0 | M22: 25 | N22: 0 | O22: =SUM(C22:L22,N22) -> 3 | P22: =SUM(C22:N22) -> 28 | R22: AM Peak Hr | S22: =MAX(S10:S12) -> 17 | T22: =MAX(T10:T12) -> 8 | U22: =MAX(U10:U12) -> 4 | V22: =MAX(V10:V12) -> 3 | W22: =MAX(W10:W12) -> 0 | X22: =MAX(X10:X12) -> 0 | Y22: =MAX(Y10:Y12) -> 4 | Z22: =MAX(Z10:Z12) -> 2 | ... AF22: =MAX(AF10:AF12) -> 159
B23: 10.15 - 10.30 | C23: 5 | D23: 0 | E23: 0 | F23: 0 | G23: 0 | H23: 0 | I23: 1 | J23: 0 | K23: 0 | L23: 0 | M23: 29 | N23: 0 | O23: =SUM(C23:L23,N23) -> 6 | P23: =SUM(C23:N23) -> 35 | R23: IP Peak Hr | S23: =MAX(S13:S18) -> 20 | T23: =MAX(T13:T18) -> 4 | U23: =MAX(U13:U18) -> 3 | V23: =MAX(V13:V18) -> 5 | W23: =MAX(W13:W18) -> 1 | X23: =MAX(X13:X18) -> 0 | Y23: =MAX(Y13:Y18) -> 8 | Z23: =MAX(Z13:Z18) -> 4 | ... AF23: =MAX(AF13:AF18) -> 116
B24: 10.30 - 10.45 | C24: 5 | D24: 0 | E24: 0 | F24: 1 | G24: 0 | H24: 0 | I24: 0 | J24: 0 | K24: 1 | L24: 0 | M24: 22 | N24: 0 | O24: =SUM(C24:L24,N24) -> 7 | P24: =SUM(C24:N24) -> 29 | R24: PM Peak Hr | S24: =MAX(S19:S21) -> 18 | T24: =MAX(T19:T21) -> 6 | U24: =MAX(U19:U21) -> 4 | V24: =MAX(V19:V21) -> 6 | W24: =MAX(W19:W21) -> 5 | X24: =MAX(X19:X21) -> 0 | Y24: =MAX(Y19:Y21) -> 10 | Z24: =MAX(Z19:Z21) -> 0 | ... AF24: =MAX(AF19:AF21) -> 134
B25: 10.45 - 11.00 | C25: 3 | D25: 2 | E25: 0 | F25: 0 | G25: 0 | H25: 0 | I25: 0 | J25: 0 | K25: 0 | L25: 1 | M25: 18 | N25: 0 | O25: =SUM(C25:L25,N25) -> 6 | P25: =SUM(C25:N25) -> 24 | R25: AM Period | S25: =SUM(S10:S12) -> 47 | T25: =SUM(T10:T12) -> 16 | U25: =SUM(U10:U12) -> 9 | V25: =SUM(V10:V12) -> 6 | W25: =SUM(W10:W12) -> 0 | X25: =SUM(X10:X12) -> 0 | Y25: =SUM(Y10:Y12) -> 8 | Z25: =SUM(Z10:Z12) -> 3 | ... AF25: =SUM(AF10:AF12) -> 416
B26: 11.00 - 11.15 | C26: 4 | D26: 0 | E26: 1 | F26: 0 | G26: 0 | H26: 0 | I26: 3 | J26: 1 | K26: 0 | L26: 0 | M26: 17 | N26: 0 | O26: =SUM(C26:L26,N26) -> 9 | P26: =SUM(C26:N26) -> 26 | R26: IP Period | S26: =SUM(S13:S18) -> 82 | T26: =SUM(T13:T18) -> 17 | U26: =SUM(U13:U18) -> 10 | V26: =SUM(V13:V18) -> 14 | W26: =SUM(W13:W18) -> 1 | X26: =SUM(X13:X18) -> 0 | Y26: =SUM(Y13:Y18) -> 34 | Z26: =SUM(Z13:Z18) -> 7 | ... AF26: =SUM(AF13:AF18) -> 564
B27: 11.15 - 11.30 | C27: 2 | D27: 1 | E27: 1 | F27: 2 | G27: 0 | H27: 0 | I27: 2 | J27: 1 | K27: 0 | L27: 0 | M27: 16 | N27: 0 | O27: =SUM(C27:L27,N27) -> 9 | P27: =SUM(C27:N27) -> 25 | R27: PM Period | S27: =SUM(S19:S21) -> 44 | T27: =SUM(T19:T21) -> 12 | U27: =SUM(U19:U21) -> 8 | V27: =SUM(V19:V21) -> 12 | W27: =SUM(W19:W21) -> 7 | X27: =SUM(X19:X21) -> 0 | Y27: =SUM(Y19:Y21) -> 27 | Z27: =SUM(Z19:Z21) -> 0 | ... AF27: =SUM(AF19:AF21) -> 361
B28: 11.30 - 11.45 | C28: 2 | D28: 2 | E28: 0 | F28: 1 | G28: 0 | H28: 0 | I28: 0 | J28: 1 | K28: 0 | L28: 0 | M28: 20 | N28: 0 | O28: =SUM(C28:L28,N28) -> 6 | P28: =SUM(C28:N28) -> 26 | R28: 12 Hours | S28: =SUM(S10:S21) -> 173 | T28: =SUM(T10:T21) -> 45 | U28: =SUM(U10:U21) -> 27 | V28: =SUM(V10:V21) -> 32 | W28: =SUM(W10:W21) -> 8 | X28: =SUM(X10:X21) -> 0 | Y28: =SUM(Y10:Y21) -> 69 | Z28: =SUM(Z10:Z21) -> 10 | ... AF28: =SUM(AF10:AF21) -> 1341
B29: 11.45 - 12.00 | C29: 4 | D29: 0 | E29: 0 | F29: 0 | G29: 0 | H29: 0 | I29: 1 | J29: 0 | K29: 0 | L29: 0 | M29: 17 | N29: 0 | O29: =SUM(C29:L29,N29) -> 5 | P29: =SUM(C29:N29) -> 22
B30: 12.00 - 12.15 | C30: 0 | D30: 0 | E30: 0 | F30: 0 | G30: 0 | H30: 0 | I30: 0 | J30: 3 | K30: 0 | L30: 0 | M30: 13 | N30: 0 | O30: =SUM(C30:L30,N30) -> 3 | P30: =SUM(C30:N30) -> 16
B31: 12.15 - 12.30 | C31: 4 | D31: 1 | E31: 0 | F31: 0 | G31: 0 | H31: 0 | I31: 1 | J31: 1 | K31: 0 | L31: 0 | M31: 12 | N31: 0 | O31: =SUM(C31:L31,N31) -> 7 | P31: =SUM(C31:N31) -> 19
B32: 12.30 - 12.45 | C32: 1 | D32: 2 | E32: 1 | F32: 0 | G32: 0 | H32: 0 | I32: 4 | J32: 0 | K32: 1 | L32: 0 | M32: 20 | N32: 0 | O32: =SUM(C32:L32,N32) -> 9 | P32: =SUM(C32:N32) -> 29
